{"op":"mcm","clk":"11536380657","pt":1719425245600,"mc":[{"id":"1.230178323","marketDefinition":{"bspMarket":true,"turnInPlayEnabled":false,"persistenceEnabled":false,"marketBaseRate":5.0,"eventId":"33376062","eventTypeId":"4339","numberOfWinners":2,"bettingType":"ODDS","marketType":"PLACE","marketTime":"2024-06-27T16:06:00.000Z","suspendTime":"2024-06-27T16:06:00.000Z","bspReconciled":false,"complete":true,"inPlay":false,"crossMatching":false,"runnersVoidable":false,"numberOfActiveRunners":6,"betDelay":0,"status":"OPEN","runners":[{"status":"ACTIVE","sortPriority":1,"id":70681333,"name":"1. Request"},{"status":"ACTIVE","sortPriority":2,"id":51569790,"name":"2. Jaxx Casparon"},{"status":"ACTIVE","sortPriority":3,"id":63650892,"name":"3. Brosna Summer"},{"status":"ACTIVE","sortPriority":4,"id":47885365,"name":"4. Springwell Zoey"},{"status":"ACTIVE","sortPriority":5,"id":68274051,"name":"5. Drumdoit Loret"},{"status":"ACTIVE","sortPriority":6,"id":60192591,"name":"6. Corruptor"}],"regulators":["MR_INT"],"venue":"Kinsley","countryCode":"GB","discountAllowed":false,"timezone":"Europe/London","openDate":"2024-06-27T13:36:00.000Z","version":5994643763,"name":"To Be Placed","eventName":"Kinsley 27th Jun"},"rc":[],"con":true,"img":false}]}
{"op":"mcm","clk":"11536381017","pt":1719425248523,"mc":[{"id":"1.230178323","marketDefinition":{"bspMarket":true,"turnInPlayEnabled":false,"persistenceEnabled":false,"marketBaseRate":5.0,"eventId":"33376062","eventTypeId":"4339","numberOfWinners":2,"bettingType":"ODDS","marketType":"PLACE","marketTime":"2024-06-27T16:06:00.000Z","suspendTime":"2024-06-27T16:06:00.000Z","bspReconciled":false,"complete":true,"inPlay":false,"crossMatching":false,"runnersVoidable":false,"numberOfActiveRunners":6,"betDelay":0,"status":"OPEN","runners":[{"status":"ACTIVE","sortPriority":1,"id":70681333,"name":"1. Request"},{"status":"ACTIVE","sortPriority":2,"id":51569790,"name":"2. Jaxx Casparon"},{"status":"ACTIVE","sortPriority":3,"id":63650892,"name":"3. Brosna Summer"},{"status":"ACTIVE","sortPriority":4,"id":47885365,"name":"4. Springwell Zoey"},{"status":"ACTIVE","sortPriority":5,"id":68274051,"name":"5. Drumdoit Loret"},{"status":"ACTIVE","sortPriority":6,"id":60192591,"name":"6. Corruptor"}],"regulators":["MR_INT"],"venue":"Kinsley","countryCode":"GB","discountAllowed":true,"timezone":"Europe/London","openDate":"2024-06-27T13:36:00.000Z","version":5994643763,"name":"To Be Placed","eventName":"Kinsley 27th Jun"},"rc":[],"con":true,"img":false}]}
{"op":"mcm","clk":"11536615541","pt":1719428250731,"mc":[{"id":"1.230178323","rc":[{"atb":[[1.02,22.63]],"id":70681333},{"atl":[[990,0.84]],"id":70681333},{"spn":495.51,"spf":"NaN","id":70681333},{"atb":[[1.02,22.63]],"id":47885365},{"atl":[[990,0.84]],"id":47885365},{"spn":495.51,"spf":"NaN","id":47885365},{"atb":[[1.02,22.63]],"id":63650892},{"atl":[[1000,0.84]],"id":63650892},{"spn":500.51,"spf":"NaN","id":63650892},{"atb":[[1.01,45.27]],"id":68274051},{"atl":[[990,0.84]],"id":68274051},{"spn":495.5,"spf":"NaN","id":68274051},{"atb":[[1.01,45.27]],"id":51569790},{"atl":[[990,0.84]],"id":51569790},{"spn":495.5,"spf":"NaN","id":51569790},{"atb":[[1.03,15.09]],"id":60192591},{"atl":[[990,0.84]],"id":60192591},{"spn":495.51,"spf":"NaN","id":60192591}],"con":true,"img":false}]}
{"op":"mcm","clk":"11536837540","pt":1719431862763,"mc":[{"id":"1.230178323","rc":[{"atb":[[1.02,22.64]],"id":70681333},{"atl":[[990,0.26]],"id":70681333},{"atb":[[1.02,22.64]],"id":47885365},{"atl":[[990,0.26]],"id":47885365},{"atb":[[1.02,22.64]],"id":63650892},{"atl":[[1000,0.26]],"id":63650892},{"atb":[[1.01,45.28]],"id":68274051},{"atl":[[990,0.26]],"id":68274051},{"atb":[[1.01,45.28]],"id":51569790},{"atl":[[990,0.26]],"id":51569790},{"atb":[[1.03,15.09]],"id":60192591},{"atl":[[990,0.26]],"id":60192591}],"con":true,"img":false}]}
{"op":"mcm","clk":"11537232269","pt":1719437882522,"mc":[{"id":"1.230178323","marketDefinition":{"bspMarket":true,"turnInPlayEnabled":false,"persistenceEnabled":false,"marketBaseRate":5.0,"eventId":"33376062","eventTypeId":"4339","numberOfWinners":2,"bettingType":"ODDS","marketType":"PLACE","marketTime":"2024-06-27T16:06:00.000Z","suspendTime":"2024-06-27T16:06:00.000Z","bspReconciled":false,"complete":true,"inPlay":false,"crossMatching":false,"runnersVoidable":false,"numberOfActiveRunners":6,"betDelay":0,"status":"OPEN","runners":[{"status":"ACTIVE","sortPriority":1,"id":70681333,"name":"1. Request"},{"status":"ACTIVE","sortPriority":2,"id":51569790,"name":"2. Jaxx Casparon"},{"status":"ACTIVE","sortPriority":3,"id":63650892,"name":"3. Brosna Summer"},{"status":"ACTIVE","sortPriority":4,"id":47885365,"name":"4. Springwell Zoey"},{"status":"ACTIVE","sortPriority":5,"id":68274051,"name":"5. Drumdoit Loret"},{"status":"ACTIVE","sortPriority":6,"id":60192591,"name":"6. Corruptor"}],"regulators":["MR_INT"],"venue":"Kinsley","countryCode":"GB","discountAllowed":true,"timezone":"Europe/London","openDate":"2024-06-27T13:36:00.000Z","version":5994643763,"name":"To Be Placed","eventName":"Kinsley 27th Jun"},"rc":[{"atb":[[1.02,22.64]],"id":70681333},{"atl":[[990,0.26]],"id":70681333},{"spn":495.51,"spf":"NaN","id":70681333},{"atb":[[1.02,22.64]],"id":47885365},{"atl":[[990,0.26]],"id":47885365},{"spn":495.51,"spf":"NaN","id":47885365},{"atb":[[1.02,22.64]],"id":63650892},{"atl":[[1000,0.26]],"id":63650892},{"spn":500.51,"spf":"NaN","id":63650892},{"atb":[[1.01,45.28]],"id":68274051},{"atl":[[990,0.26]],"id":68274051},{"spn":495.5,"spf":"NaN","id":68274051},{"atb":[[1.01,45.28]],"id":51569790},{"atl":[[990,0.26]],"id":51569790},{"spn":495.5,"spf":"NaN","id":51569790},{"atb":[[1.03,15.09]],"id":60192591},{"atl":[[990,0.26]],"id":60192591},{"spn":495.51,"spf":"NaN","id":60192591}],"con":true,"img":true}]}
{"op":"mcm","clk":"11537573396","pt":1719443282540,"mc":[{"id":"1.230178323","marketDefinition":{"bspMarket":true,"turnInPlayEnabled":false,"persistenceEnabled":false,"marketBaseRate":5.0,"eventId":"33376062","eventTypeId":"4339","numberOfWinners":2,"bettingType":"ODDS","marketType":"PLACE","marketTime":"2024-06-27T16:06:00.000Z","suspendTime":"2024-06-27T16:06:00.000Z","bspReconciled":false,"complete":true,"inPlay":false,"crossMatching":false,"runnersVoidable":false,"numberOfActiveRunners":6,"betDelay":0,"status":"OPEN","runners":[{"status":"ACTIVE","sortPriority":1,"id":70681333,"name":"1. Request"},{"status":"ACTIVE","sortPriority":2,"id":51569790,"name":"2. Jaxx Casparon"},{"status":"ACTIVE","sortPriority":3,"id":63650892,"name":"3. Brosna Summer"},{"status":"ACTIVE","sortPriority":4,"id":47885365,"name":"4. Springwell Zoey"},{"status":"ACTIVE","sortPriority":5,"id":68274051,"name":"5. Drumdoit Loret"},{"status":"ACTIVE","sortPriority":6,"id":60192591,"name":"6. Corruptor"}],"regulators":["MR_INT"],"venue":"Kinsley","countryCode":"GB","discountAllowed":true,"timezone":"Europe/London","openDate":"2024-06-27T13:36:00.000Z","version":5994643763,"name":"To Be Placed","eventName":"Kinsley 27th Jun"},"rc":[{"atb":[[1.02,22.64]],"id":70681333},{"atl":[[990,0.26]],"id":70681333},{"spn":495.51,"spf":"NaN","id":70681333},{"atb":[[1.02,22.64]],"id":47885365},{"atl":[[990,0.26]],"id":47885365},{"spn":495.51,"spf":"NaN","id":47885365},{"atb":[[1.02,22.64]],"id":63650892},{"atl":[[1000,0.26]],"id":63650892},{"spn":500.51,"spf":"NaN","id":63650892},{"atb":[[1.01,45.29]],"id":68274051},{"atl":[[990,0.26]],"id":68274051},{"spn":495.5,"spf":"NaN","id":68274051},{"atb":[[1.01,45.29]],"id":51569790},{"atl":[[990,0.26]],"id":51569790},{"spn":495.5,"spf":"NaN","id":51569790},{"atb":[[1.03,15.09]],"id":60192591},{"atl":[[990,0.26]],"id":60192591},{"spn":495.51,"spf":"NaN","id":60192591}],"con":true,"img":true}]}
{"op":"mcm","clk":"11537954956","pt":1719448682565,"mc":[{"id":"1.230178323","marketDefinition":{"bspMarket":true,"turnInPlayEnabled":false,"persistenceEnabled":false,"marketBaseRate":5.0,"eventId":"33376062","eventTypeId":"4339","numberOfWinners":2,"bettingType":"ODDS","marketType":"PLACE","marketTime":"2024-06-27T16:06:00.000Z","suspendTime":"2024-06-27T16:06:00.000Z","bspReconciled":false,"complete":true,"inPlay":false,"crossMatching":false,"runnersVoidable":false,"numberOfActiveRunners":6,"betDelay":0,"status":"OPEN","runners":[{"status":"ACTIVE","sortPriority":1,"id":70681333,"name":"1. Request"},{"status":"ACTIVE","sortPriority":2,"id":51569790,"name":"2. Jaxx Casparon"},{"status":"ACTIVE","sortPriority":3,"id":63650892,"name":"3. Brosna Summer"},{"status":"ACTIVE","sortPriority":4,"id":47885365,"name":"4. Springwell Zoey"},{"status":"ACTIVE","sortPriority":5,"id":68274051,"name":"5. Drumdoit Loret"},{"status":"ACTIVE","sortPriority":6,"id":60192591,"name":"6. Corruptor"}],"regulators":["MR_INT"],"venue":"Kinsley","countryCode":"GB","discountAllowed":true,"timezone":"Europe/London","openDate":"2024-06-27T13:36:00.000Z","version":5994643763,"name":"To Be Placed","eventName":"Kinsley 27th Jun"},"rc":[{"atb":[[1.02,22.64]],"id":70681333},{"atl":[[990,0.26]],"id":70681333},{"spn":495.51,"spf":"NaN","id":70681333},{"atb":[[1.02,22.64]],"id":47885365},{"atl":[[990,0.26]],"id":47885365},{"spn":495.51,"spf":"NaN","id":47885365},{"atb":[[1.02,22.64]],"id":63650892},{"atl":[[1000,0.26]],"id":63650892},{"spn":500.51,"spf":"NaN","id":63650892},{"atb":[[1.01,45.28]],"id":68274051},{"atl":[[990,0.26]],"id":68274051},{"spn":495.5,"spf":"NaN","id":68274051},{"atb":[[1.01,45.28]],"id":51569790},{"atl":[[990,0.26]],"id":51569790},{"spn":495.5,"spf":"NaN","id":51569790},{"atb":[[1.03,15.09]],"id":60192591},{"atl":[[990,0.26]],"id":60192591},{"spn":495.51,"spf":"NaN","id":60192591}],"con":true,"img":true}]}
{"op":"mcm","clk":"11538170619","pt":1719454082547,"mc":[{"id":"1.230178323","marketDefinition":{"bspMarket":true,"turnInPlayEnabled":false,"persistenceEnabled":false,"marketBaseRate":5.0,"eventId":"33376062","eventTypeId":"4339","numberOfWinners":2,"bettingType":"ODDS","marketType":"PLACE","marketTime":"2024-06-27T16:06:00.000Z","suspendTime":"2024-06-27T16:06:00.000Z","bspReconciled":false,"complete":true,"inPlay":false,"crossMatching":false,"runnersVoidable":false,"numberOfActiveRunners":6,"betDelay":0,"status":"OPEN","runners":[{"status":"ACTIVE","sortPriority":1,"id":70681333,"name":"1. Request"},{"status":"ACTIVE","sortPriority":2,"id":51569790,"name":"2. Jaxx Casparon"},{"status":"ACTIVE","sortPriority":3,"id":63650892,"name":"3. Brosna Summer"},{"status":"ACTIVE","sortPriority":4,"id":47885365,"name":"4. Springwell Zoey"},{"status":"ACTIVE","sortPriority":5,"id":68274051,"name":"5. Drumdoit Loret"},{"status":"ACTIVE","sortPriority":6,"id":60192591,"name":"6. Corruptor"}],"regulators":["MR_INT"],"venue":"Kinsley","countryCode":"GB","discountAllowed":true,"timezone":"Europe/London","openDate":"2024-06-27T13:36:00.000Z","version":5994643763,"name":"To Be Placed","eventName":"Kinsley 27th Jun"},"rc":[{"atb":[[1.02,22.64]],"id":70681333},{"atl":[[990,0.26]],"id":70681333},{"spn":495.51,"spf":"NaN","id":70681333},{"atb":[[1.02,22.64]],"id":47885365},{"atl":[[990,0.26]],"id":47885365},{"spn":495.51,"spf":"NaN","id":47885365},{"atb":[[1.02,22.64]],"id":63650892},{"atl":[[1000,0.26]],"id":63650892},{"spn":500.51,"spf":"NaN","id":63650892},{"atb":[[1.01,45.29]],"id":68274051},{"atl":[[990,0.26]],"id":68274051},{"spn":495.5,"spf":"NaN","id":68274051},{"atb":[[1.01,45.29]],"id":51569790},{"atl":[[990,0.26]],"id":51569790},{"spn":495.5,"spf":"NaN","id":51569790},{"atb":[[1.03,15.09]],"id":60192591},{"atl":[[990,0.26]],"id":60192591},{"spn":495.51,"spf":"NaN","id":60192591}],"con":true,"img":true}]}
{"op":"mcm","clk":"11538368277","pt":1719459482597,"mc":[{"id":"1.230178323","marketDefinition":{"bspMarket":true,"turnInPlayEnabled":false,"persistenceEnabled":false,"marketBaseRate":5.0,"eventId":"33376062","eventTypeId":"4339","numberOfWinners":2,"bettingType":"ODDS","marketType":"PLACE","marketTime":"2024-06-27T16:06:00.000Z","suspendTime":"2024-06-27T16:06:00.000Z","bspReconciled":false,"complete":true,"inPlay":false,"crossMatching":false,"runnersVoidable":false,"numberOfActiveRunners":6,"betDelay":0,"status":"OPEN","runners":[{"status":"ACTIVE","sortPriority":1,"id":70681333,"name":"1. Request"},{"status":"ACTIVE","sortPriority":2,"id":51569790,"name":"2. Jaxx Casparon"},{"status":"ACTIVE","sortPriority":3,"id":63650892,"name":"3. Brosna Summer"},{"status":"ACTIVE","sortPriority":4,"id":47885365,"name":"4. Springwell Zoey"},{"status":"ACTIVE","sortPriority":5,"id":68274051,"name":"5. Drumdoit Loret"},{"status":"ACTIVE","sortPriority":6,"id":60192591,"name":"6. Corruptor"}],"regulators":["MR_INT"],"venue":"Kinsley","countryCode":"GB","discountAllowed":true,"timezone":"Europe/London","openDate":"2024-06-27T13:36:00.000Z","version":5994643763,"name":"To Be Placed","eventName":"Kinsley 27th Jun"},"rc":[{"atb":[[1.02,22.65]],"id":70681333},{"atl":[[990,0.26]],"id":70681333},{"spn":495.51,"spf":"NaN","id":70681333},{"atb":[[1.02,22.65]],"id":47885365},{"atl":[[990,0.26]],"id":47885365},{"spn":495.51,"spf":"NaN","id":47885365},{"atb":[[1.02,22.65]],"id":63650892},{"atl":[[1000,0.26]],"id":63650892},{"spn":500.51,"spf":"NaN","id":63650892},{"atb":[[1.01,45.3]],"id":68274051},{"atl":[[990,0.26]],"id":68274051},{"spn":495.5,"spf":"NaN","id":68274051},{"atb":[[1.01,45.3]],"id":51569790},{"atl":[[990,0.26]],"id":51569790},{"spn":495.5,"spf":"NaN","id":51569790},{"atb":[[1.03,15.1]],"id":60192591},{"atl":[[990,0.26]],"id":60192591},{"spn":495.51,"spf":"NaN","id":60192591}],"con":true,"img":true}]}
{"op":"mcm","clk":"11538595403","pt":1719464882546,"mc":[{"id":"1.230178323","marketDefinition":{"bspMarket":true,"turnInPlayEnabled":false,"persistenceEnabled":false,"marketBaseRate":5.0,"eventId":"33376062","eventTypeId":"4339","numberOfWinners":2,"bettingType":"ODDS","marketType":"PLACE","marketTime":"2024-06-27T16:06:00.000Z","suspendTime":"2024-06-27T16:06:00.000Z","bspReconciled":false,"complete":true,"inPlay":false,"crossMatching":false,"runnersVoidable":false,"numberOfActiveRunners":6,"betDelay":0,"status":"OPEN","runners":[{"status":"ACTIVE","sortPriority":1,"id":70681333,"name":"1. Request"},{"status":"ACTIVE","sortPriority":2,"id":51569790,"name":"2. Jaxx Casparon"},{"status":"ACTIVE","sortPriority":3,"id":63650892,"name":"3. Brosna Summer"},{"status":"ACTIVE","sortPriority":4,"id":47885365,"name":"4. Springwell Zoey"},{"status":"ACTIVE","sortPriority":5,"id":68274051,"name":"5. Drumdoit Loret"},{"status":"ACTIVE","sortPriority":6,"id":60192591,"name":"6. Corruptor"}],"regulators":["MR_INT"],"venue":"Kinsley","countryCode":"GB","discountAllowed":true,"timezone":"Europe/London","openDate":"2024-06-27T13:36:00.000Z","version":5994643763,"name":"To Be Placed","eventName":"Kinsley 27th Jun"},"rc":[{"atb":[[1.02,22.64]],"id":70681333},{"atl":[[990,0.26]],"id":70681333},{"spn":495.51,"spf":"NaN","id":70681333},{"atb":[[1.02,22.64]],"id":47885365},{"atl":[[990,0.26]],"id":47885365},{"spn":495.51,"spf":"NaN","id":47885365},{"atb":[[1.02,22.64]],"id":63650892},{"atl":[[1000,0.26]],"id":63650892},{"spn":500.51,"spf":"NaN","id":63650892},{"atb":[[1.01,45.29]],"id":68274051},{"atl":[[990,0.26]],"id":68274051},{"spn":495.5,"spf":"NaN","id":68274051},{"atb":[[1.01,45.29]],"id":51569790},{"atl":[[990,0.26]],"id":51569790},{"spn":495.5,"spf":"NaN","id":51569790},{"atb":[[1.03,15.09]],"id":60192591},{"atl":[[990,0.26]],"id":60192591},{"spn":495.51,"spf":"NaN","id":60192591}],"con":true,"img":true}]}
{"op":"mcm","clk":"11538905593","pt":1719471475928,"mc":[{"id":"1.230178323","rc":[{"atb":[[1.02,22.64]],"id":70681333},{"atl":[[990,0.16]],"id":70681333},{"atb":[[1.02,22.64]],"id":47885365},{"atl":[[990,0.16]],"id":47885365},{"atb":[[1.02,22.64]],"id":63650892},{"atl":[[1000,0.16]],"id":63650892},{"atb":[[1.01,45.29]],"id":68274051},{"atl":[[990,0.16]],"id":68274051},{"atb":[[1.01,45.29]],"id":51569790},{"atl":[[990,0.16]],"id":51569790},{"atb":[[1.03,15.09]],"id":60192591},{"atl":[[990,0.16]],"id":60192591}],"con":true,"img":false}]}
{"op":"mcm","clk":"11538907323","pt":1719471508471,"mc":[{"id":"1.230178323","rc":[{"atb":[[1.07,2.48]],"id":70681333},{"atb":[[1.07,2.48]],"id":47885365},{"atb":[[1.07,2.48]],"id":63650892},{"atb":[[1.07,2.48]],"id":68274051},{"atb":[[1.07,2.48]],"id":51569790},{"atb":[[1.07,2.48]],"id":60192591}],"con":true,"img":false}]}
{"op":"mcm","clk":"11538907326","pt":1719471508570,"mc":[{"id":"1.230178323","rc":[{"atl":[[1000,1]],"id":70681333},{"atl":[[1000,1]],"id":47885365},{"atl":[[1000,1.16]],"id":63650892},{"atl":[[1000,1]],"id":68274051},{"atl":[[1000,1]],"id":51569790},{"atl":[[1000,1]],"id":60192591}],"con":true,"img":false}]}
{"op":"mcm","clk":"11538907336","pt":1719471508775,"mc":[{"id":"1.230178323","rc":[{"atl":[[1000,0.48]],"id":70681333},{"atl":[[1000,0.48]],"id":47885365},{"atl":[[1000,0.64]],"id":63650892},{"atl":[[1000,0.48]],"id":68274051},{"atl":[[1000,0.48]],"id":51569790},{"atl":[[1000,0.48]],"id":60192591}],"con":true,"img":false}]}
{"op":"mcm","clk":"11538907348","pt":1719471508981,"mc":[{"id":"1.230178323","rc":[{"atl":[[1000,0]],"id":70681333},{"atl":[[1000,0]],"id":47885365},{"atl":[[1000,0.16]],"id":63650892},{"atl":[[1000,0]],"id":68274051},{"atl":[[1000,0]],"id":51569790},{"atl":[[1000,0]],"id":60192591}],"con":true,"img":false}]}
{"op":"mcm","clk":"11538907355","pt":1719471509086,"mc":[{"id":"1.230178323","rc":[{"atl":[[75,0.48]],"id":70681333},{"atl":[[75,0.48]],"id":47885365},{"atl":[[75,0.48]],"id":63650892},{"atl":[[75,0.48]],"id":68274051},{"atl":[[75,0.48]],"id":51569790},{"atl":[[75,0.48]],"id":60192591}],"con":true,"img":false}]}
{"op":"mcm","clk":"11539122550","pt":1719475682553,"mc":[{"id":"1.230178323","marketDefinition":{"bspMarket":true,"turnInPlayEnabled":false,"persistenceEnabled":false,"marketBaseRate":5.0,"eventId":"33376062","eventTypeId":"4339","numberOfWinners":2,"bettingType":"ODDS","marketType":"PLACE","marketTime":"2024-06-27T16:06:00.000Z","suspendTime":"2024-06-27T16:06:00.000Z","bspReconciled":false,"complete":true,"inPlay":false,"crossMatching":false,"runnersVoidable":false,"numberOfActiveRunners":6,"betDelay":0,"status":"OPEN","runners":[{"status":"ACTIVE","sortPriority":1,"id":70681333,"name":"1. Request"},{"status":"ACTIVE","sortPriority":2,"id":51569790,"name":"2. Jaxx Casparon"},{"status":"ACTIVE","sortPriority":3,"id":63650892,"name":"3. Brosna Summer"},{"status":"ACTIVE","sortPriority":4,"id":47885365,"name":"4. Springwell Zoey"},{"status":"ACTIVE","sortPriority":5,"id":68274051,"name":"5. Drumdoit Loret"},{"status":"ACTIVE","sortPriority":6,"id":60192591,"name":"6. Corruptor"}],"regulators":["MR_INT"],"venue":"Kinsley","countryCode":"GB","discountAllowed":true,"timezone":"Europe/London","openDate":"2024-06-27T13:36:00.000Z","version":5994643763,"name":"To Be Placed","eventName":"Kinsley 27th Jun"},"rc":[{"atb":[[1.02,22.64],[1.07,2.48]],"id":70681333},{"atl":[[75,0.48],[990,0.16]],"id":70681333},{"spn":38.03,"spf":"NaN","id":70681333},{"atb":[[1.02,22.64],[1.07,2.48]],"id":47885365},{"atl":[[75,0.48],[990,0.16]],"id":47885365},{"spn":38.03,"spf":"NaN","id":47885365},{"atb":[[1.02,22.64],[1.07,2.48]],"id":63650892},{"atl":[[75,0.48],[1000,0.16]],"id":63650892},{"spn":38.03,"spf":"NaN","id":63650892},{"atb":[[1.01,45.28],[1.07,2.48]],"id":68274051},{"atl":[[75,0.48],[990,0.16]],"id":68274051},{"spn":38.03,"spf":"NaN","id":68274051},{"atb":[[1.01,45.28],[1.07,2.48]],"id":51569790},{"atl":[[75,0.48],[990,0.16]],"id":51569790},{"spn":38.03,"spf":"NaN","id":51569790},{"atb":[[1.03,15.09],[1.07,2.48]],"id":60192591},{"atl":[[75,0.48],[990,0.16]],"id":60192591},{"spn":38.03,"spf":"NaN","id":60192591}],"con":true,"img":true}]}
{"op":"mcm","clk":"11539438526","pt":1719481082548,"mc":[{"id":"1.230178323","marketDefinition":{"bspMarket":true,"turnInPlayEnabled":false,"persistenceEnabled":false,"marketBaseRate":5.0,"eventId":"33376062","eventTypeId":"4339","numberOfWinners":2,"bettingType":"ODDS","marketType":"PLACE","marketTime":"2024-06-27T16:06:00.000Z","suspendTime":"2024-06-27T16:06:00.000Z","bspReconciled":false,"complete":true,"inPlay":false,"crossMatching":false,"runnersVoidable":false,"numberOfActiveRunners":6,"betDelay":0,"status":"OPEN","runners":[{"status":"ACTIVE","sortPriority":1,"id":70681333,"name":"1. Request"},{"status":"ACTIVE","sortPriority":2,"id":51569790,"name":"2. Jaxx Casparon"},{"status":"ACTIVE","sortPriority":3,"id":63650892,"name":"3. Brosna Summer"},{"status":"ACTIVE","sortPriority":4,"id":47885365,"name":"4. Springwell Zoey"},{"status":"ACTIVE","sortPriority":5,"id":68274051,"name":"5. Drumdoit Loret"},{"status":"ACTIVE","sortPriority":6,"id":60192591,"name":"6. Corruptor"}],"regulators":["MR_INT"],"venue":"Kinsley","countryCode":"GB","discountAllowed":true,"timezone":"Europe/London","openDate":"2024-06-27T13:36:00.000Z","version":5994643763,"name":"To Be Placed","eventName":"Kinsley 27th Jun"},"rc":[{"atb":[[1.02,22.63],[1.07,2.48]],"id":70681333},{"atl":[[75,0.48],[990,0.16]],"id":70681333},{"spn":38.03,"spf":"NaN","id":70681333},{"atb":[[1.02,22.63],[1.07,2.48]],"id":47885365},{"atl":[[75,0.48],[990,0.16]],"id":47885365},{"spn":38.03,"spf":"NaN","id":47885365},{"atb":[[1.02,22.63],[1.07,2.48]],"id":63650892},{"atl":[[75,0.48],[1000,0.16]],"id":63650892},{"spn":38.03,"spf":"NaN","id":63650892},{"atb":[[1.01,45.27],[1.07,2.48]],"id":68274051},{"atl":[[75,0.48],[990,0.16]],"id":68274051},{"spn":38.03,"spf":"NaN","id":68274051},{"atb":[[1.01,45.27],[1.07,2.48]],"id":51569790},{"atl":[[75,0.48],[990,0.16]],"id":51569790},{"spn":38.03,"spf":"NaN","id":51569790},{"atb":[[1.03,15.09],[1.07,2.48]],"id":60192591},{"atl":[[75,0.48],[990,0.16]],"id":60192591},{"spn":38.03,"spf":"NaN","id":60192591}],"con":true,"img":true}]}
{"op":"mcm","clk":"11540640033","pt":1719496773415,"mc":[{"id":"1.230178323","rc":[{"atb":[[1.02,22.66]],"id":70681333},{"atl":[[990,0.16],[960,0.84]],"id":70681333},{"spn":38.03,"spf":"NaN","id":70681333},{"atb":[[1.02,22.66]],"id":47885365},{"atl":[[990,0.16],[960,1.26]],"id":47885365},{"spn":38.03,"spf":"NaN","id":47885365},{"atb":[[1.02,22.66]],"id":63650892},{"atl":[[970,0.84],[1000,0.16]],"id":63650892},{"spn":38.03,"spf":"NaN","id":63650892},{"atb":[[1.01,45.32]],"id":68274051},{"atl":[[990,0.16],[960,0.84]],"id":68274051},{"spn":38.03,"spf":"NaN","id":68274051},{"atb":[[1.01,45.32]],"id":51569790},{"atl":[[990,0.16],[970,1.27]],"id":51569790},{"spn":38.03,"spf":"NaN","id":51569790},{"atb":[[1.03,15.1]],"id":60192591},{"atl":[[990,0.16],[970,0.84]],"id":60192591},{"spn":38.03,"spf":"NaN","id":60192591}],"con":true,"img":false}]}
{"op":"mcm","clk":"11540683360","pt":1719497282514,"mc":[{"id":"1.230178323","marketDefinition":{"bspMarket":true,"turnInPlayEnabled":false,"persistenceEnabled":false,"marketBaseRate":5.0,"eventId":"33376062","eventTypeId":"4339","numberOfWinners":2,"bettingType":"ODDS","marketType":"PLACE","marketTime":"2024-06-27T16:06:00.000Z","suspendTime":"2024-06-27T16:06:00.000Z","bspReconciled":false,"complete":true,"inPlay":false,"crossMatching":false,"runnersVoidable":false,"numberOfActiveRunners":6,"betDelay":0,"status":"OPEN","runners":[{"status":"ACTIVE","sortPriority":1,"id":70681333,"name":"1. Request"},{"status":"ACTIVE","sortPriority":2,"id":51569790,"name":"2. Jaxx Casparon"},{"status":"ACTIVE","sortPriority":3,"id":63650892,"name":"3. Brosna Summer"},{"status":"ACTIVE","sortPriority":4,"id":47885365,"name":"4. Springwell Zoey"},{"status":"ACTIVE","sortPriority":5,"id":68274051,"name":"5. Drumdoit Loret"},{"status":"ACTIVE","sortPriority":6,"id":60192591,"name":"6. Corruptor"}],"regulators":["MR_INT"],"venue":"Kinsley","countryCode":"GB","discountAllowed":true,"timezone":"Europe/London","openDate":"2024-06-27T13:36:00.000Z","version":5994643763,"name":"To Be Placed","eventName":"Kinsley 27th Jun"},"rc":[{"atb":[[1.02,22.65],[1.07,2.48]],"id":70681333},{"atl":[[75,0.48],[960,0.84],[990,0.16]],"id":70681333},{"spn":38.03,"spf":"NaN","id":70681333},{"atb":[[1.02,22.65],[1.07,2.48]],"id":47885365},{"atl":[[75,0.48],[960,1.26],[990,0.16]],"id":47885365},{"spn":38.03,"spf":"NaN","id":47885365},{"atb":[[1.02,22.65],[1.07,2.48]],"id":63650892},{"atl":[[75,0.48],[970,0.84],[1000,0.16]],"id":63650892},{"spn":38.03,"spf":"NaN","id":63650892},{"atb":[[1.01,45.3],[1.07,2.48]],"id":68274051},{"atl":[[75,0.48],[960,0.84],[990,0.16]],"id":68274051},{"spn":38.03,"spf":"NaN","id":68274051},{"atb":[[1.01,45.3],[1.07,2.48]],"id":51569790},{"atl":[[75,0.48],[970,1.26],[990,0.16]],"id":51569790},{"spn":38.03,"spf":"NaN","id":51569790},{"atb":[[1.03,15.1],[1.07,2.48]],"id":60192591},{"atl":[[75,0.48],[970,0.84],[990,0.16]],"id":60192591},{"spn":38.03,"spf":"NaN","id":60192591}],"con":true,"img":true}]}
{"op":"mcm","clk":"11541105726","pt":1719502262324,"mc":[{"id":"1.230178323","rc":[{"atb":[[1.02,22.65],[1.04,1]],"id":70681333},{"atl":[[960,0.84]],"id":70681333},{"atb":[[1.02,22.65],[1.04,1]],"id":47885365},{"atl":[[960,1.26]],"id":47885365},{"atb":[[1.02,22.65],[1.04,1]],"id":63650892},{"atl":[[970,0.84]],"id":63650892},{"atb":[[1.01,45.31],[1.04,1]],"id":68274051},{"atl":[[960,0.84]],"id":68274051},{"atb":[[1.01,45.31],[1.04,1]],"id":51569790},{"atl":[[970,1.27]],"id":51569790},{"atb":[[1.03,15.1],[1.04,1]],"id":60192591},{"atl":[[970,0.84]],"id":60192591}],"con":true,"img":false}]}
{"op":"mcm","clk":"11541105742","pt":1719502262477,"mc":[{"id":"1.230178323","rc":[{"atb":[[1.04,0.25]],"id":70681333},{"atb":[[1.04,0.25]],"id":47885365},{"atb":[[1.04,0.25]],"id":63650892},{"atb":[[1.04,0.25]],"id":68274051},{"atb":[[1.04,0.25]],"id":51569790},{"atb":[[1.04,0.25]],"id":60192591}],"con":true,"img":false}]}
{"op":"mcm","clk":"11541105761","pt":1719502262679,"mc":[{"id":"1.230178323","rc":[{"atb":[[1.04,0]],"id":70681333},{"atb":[[1.04,0]],"id":47885365},{"atb":[[1.04,0]],"id":63650892},{"atb":[[1.04,0]],"id":68274051},{"atb":[[1.04,0]],"id":51569790},{"atb":[[1.04,0]],"id":60192591}],"con":true,"img":false}]}
{"op":"mcm","clk":"11541105771","pt":1719502262783,"mc":[{"id":"1.230178323","rc":[{"atb":[[1.2,0.25]],"id":70681333},{"atb":[[1.2,0.25]],"id":47885365},{"atb":[[1.2,0.25]],"id":63650892},{"atb":[[1.2,0.25]],"id":68274051},{"atb":[[1.2,0.25]],"id":51569790},{"atb":[[1.2,0.25]],"id":60192591}],"con":true,"img":false}]}
{"op":"mcm","clk":"11541139071","pt":1719502682530,"mc":[{"id":"1.230178323","marketDefinition":{"bspMarket":true,"turnInPlayEnabled":false,"persistenceEnabled":false,"marketBaseRate":5.0,"eventId":"33376062","eventTypeId":"4339","numberOfWinners":2,"bettingType":"ODDS","marketType":"PLACE","marketTime":"2024-06-27T16:06:00.000Z","suspendTime":"2024-06-27T16:06:00.000Z","bspReconciled":false,"complete":true,"inPlay":false,"crossMatching":false,"runnersVoidable":false,"numberOfActiveRunners":6,"betDelay":0,"status":"OPEN","runners":[{"status":"ACTIVE","sortPriority":1,"id":70681333,"name":"1. Request"},{"status":"ACTIVE","sortPriority":2,"id":51569790,"name":"2. Jaxx Casparon"},{"status":"ACTIVE","sortPriority":3,"id":63650892,"name":"3. Brosna Summer"},{"status":"ACTIVE","sortPriority":4,"id":47885365,"name":"4. Springwell Zoey"},{"status":"ACTIVE","sortPriority":5,"id":68274051,"name":"5. Drumdoit Loret"},{"status":"ACTIVE","sortPriority":6,"id":60192591,"name":"6. Corruptor"}],"regulators":["MR_INT"],"venue":"Kinsley","countryCode":"GB","discountAllowed":true,"timezone":"Europe/London","openDate":"2024-06-27T13:36:00.000Z","version":5994643763,"name":"To Be Placed","eventName":"Kinsley 27th Jun"},"rc":[{"atb":[[1.2,0.25],[1.02,22.65],[1.07,2.48]],"id":70681333},{"atl":[[75,0.48],[960,0.84],[990,0.16]],"id":70681333},{"spn":38.1,"spf":"NaN","id":70681333},{"atb":[[1.2,0.25],[1.02,22.65],[1.07,2.48]],"id":47885365},{"atl":[[75,0.48],[960,1.26],[990,0.16]],"id":47885365},{"spn":38.1,"spf":"NaN","id":47885365},{"atb":[[1.2,0.25],[1.02,22.65],[1.07,2.48]],"id":63650892},{"atl":[[75,0.48],[970,0.84],[1000,0.16]],"id":63650892},{"spn":38.1,"spf":"NaN","id":63650892},{"atb":[[1.2,0.25],[1.01,45.31],[1.07,2.48]],"id":68274051},{"atl":[[75,0.48],[960,0.84],[990,0.16]],"id":68274051},{"spn":38.1,"spf":"NaN","id":68274051},{"atb":[[1.2,0.25],[1.01,45.31],[1.07,2.48]],"id":51569790},{"atl":[[75,0.48],[970,1.27],[990,0.16]],"id":51569790},{"spn":38.1,"spf":"NaN","id":51569790},{"atb":[[1.2,0.25],[1.03,15.1],[1.07,2.48]],"id":60192591},{"atl":[[75,0.48],[970,0.84],[990,0.16]],"id":60192591},{"spn":38.1,"spf":"NaN","id":60192591}],"con":true,"img":true}]}
{"op":"mcm","clk":"11541145938","pt":1719502715193,"mc":[{"id":"1.230178323","rc":[{"spn":38.1,"spf":"NaN","id":70681333},{"atb":[[1.09,47.04]],"id":47885365},{"spn":38.1,"spf":"NaN","id":47885365},{"spn":38.1,"spf":"NaN","id":63650892},{"spn":38.1,"spf":"NaN","id":68274051},{"spn":38.1,"spf":"NaN","id":51569790},{"spn":38.1,"spf":"NaN","id":60192591}],"con":true,"img":false}]}
{"op":"mcm","clk":"11541145955","pt":1719502715398,"mc":[{"id":"1.230178323","rc":[{"atb":[[1.09,47.04]],"id":60192591}],"con":true,"img":false}]}
{"op":"mcm","clk":"11541146481","pt":1719502722006,"mc":[{"id":"1.230178323","marketDefinition":{"bspMarket":true,"turnInPlayEnabled":false,"persistenceEnabled":false,"marketBaseRate":5.0,"eventId":"33376062","eventTypeId":"4339","numberOfWinners":2,"bettingType":"ODDS","marketType":"PLACE","marketTime":"2024-06-27T16:06:00.000Z","suspendTime":"2024-06-27T16:06:00.000Z","bspReconciled":false,"complete":true,"inPlay":false,"crossMatching":true,"runnersVoidable":false,"numberOfActiveRunners":6,"betDelay":0,"status":"OPEN","runners":[{"status":"ACTIVE","sortPriority":1,"id":70681333,"name":"1. Request"},{"status":"ACTIVE","sortPriority":2,"id":51569790,"name":"2. Jaxx Casparon"},{"status":"ACTIVE","sortPriority":3,"id":63650892,"name":"3. Brosna Summer"},{"status":"ACTIVE","sortPriority":4,"id":47885365,"name":"4. Springwell Zoey"},{"status":"ACTIVE","sortPriority":5,"id":68274051,"name":"5. Drumdoit Loret"},{"status":"ACTIVE","sortPriority":6,"id":60192591,"name":"6. Corruptor"}],"regulators":["MR_INT"],"venue":"Kinsley","countryCode":"GB","discountAllowed":true,"timezone":"Europe/London","openDate":"2024-06-27T13:36:00.000Z","version":5994643763,"name":"To Be Placed","eventName":"Kinsley 27th Jun"},"rc":[],"con":true,"img":false}]}
{"op":"mcm","clk":"11541151048","pt":1719502771183,"mc":[{"id":"1.230178323","rc":[{"atb":[[1.11,35.93]],"id":60192591}],"con":true,"img":false}]}
{"op":"mcm","clk":"11541151057","pt":1719502771238,"mc":[{"id":"1.230178323","rc":[{"atb":[[1.11,35.93]],"id":47885365}],"con":true,"img":false}]}
{"op":"mcm","clk":"11541152249","pt":1719502785159,"mc":[{"id":"1.230178323","rc":[{"atb":[[1.09,0]],"id":60192591}],"con":true,"img":false}]}
{"op":"mcm","clk":"11541152263","pt":1719502785368,"mc":[{"id":"1.230178323","rc":[{"atb":[[1.09,0]],"id":47885365}],"con":true,"img":false}]}
{"op":"mcm","clk":"11541152418","pt":1719502786983,"mc":[{"id":"1.230178323","rc":[{"atb":[[1.13,32.56]],"id":60192591}],"con":true,"img":false}]}
{"op":"mcm","clk":"11541152477","pt":1719502787454,"mc":[{"id":"1.230178323","rc":[{"atb":[[1.13,32.56]],"id":47885365}],"con":true,"img":false}]}
{"op":"mcm","clk":"11541152808","pt":1719502790889,"mc":[{"id":"1.230178323","rc":[{"atb":[[1.11,0]],"id":47885365},{"atb":[[1.11,0]],"id":60192591}],"con":true,"img":false}]}
{"op":"mcm","clk":"11541152905","pt":1719502791878,"mc":[{"id":"1.230178323","rc":[{"atb":[[1.15,26.34]],"id":47885365}],"con":true,"img":false}]}
{"op":"mcm","clk":"11541152959","pt":1719502792502,"mc":[{"id":"1.230178323","rc":[{"atb":[[1.15,26.34]],"id":60192591}],"con":true,"img":false}]}
{"op":"mcm","clk":"11541155720","pt":1719502819800,"mc":[{"id":"1.230178323","rc":[{"atb":[[1.13,0]],"id":47885365},{"atb":[[1.13,0]],"id":60192591}],"con":true,"img":false}]}
{"op":"mcm","clk":"11541155847","pt":1719502820991,"mc":[{"id":"1.230178323","rc":[{"atb":[[1.17,24.9]],"id":60192591}],"con":true,"img":false}]}
{"op":"mcm","clk":"11541155962","pt":1719502821919,"mc":[{"id":"1.230178323","rc":[{"atb":[[1.17,24.9]],"id":47885365}],"con":true,"img":false}]}
{"op":"mcm","clk":"11541156563","pt":1719502829394,"mc":[{"id":"1.230178323","rc":[{"atb":[[1.15,0]],"id":60192591}],"con":true,"img":false}]}
{"op":"mcm","clk":"11541156573","pt":1719502829497,"mc":[{"id":"1.230178323","rc":[{"atb":[[1.15,0]],"id":47885365}],"con":true,"img":false}]}
{"op":"mcm","clk":"11541156676","pt":1719502830808,"mc":[{"id":"1.230178323","rc":[{"atb":[[1.19,20.8]],"id":47885365}],"con":true,"img":false}]}
{"op":"mcm","clk":"11541156691","pt":1719502831016,"mc":[{"id":"1.230178323","rc":[{"atb":[[1.19,20.8]],"id":60192591}],"con":true,"img":false}]}
{"op":"mcm","clk":"11541158771","pt":1719502855044,"mc":[{"id":"1.230178323","rc":[{"atb":[[1.17,0]],"id":47885365}],"con":true,"img":false}]}
{"op":"mcm","clk":"11541158817","pt":1719502855458,"mc":[{"id":"1.230178323","rc":[{"atb":[[1.17,0]],"id":60192591}],"con":true,"img":false}]}
{"op":"mcm","clk":"11541158972","pt":1719502856933,"mc":[{"id":"1.230178323","rc":[{"atb":[[1.21,20.16]],"id":60192591}],"con":true,"img":false}]}
{"op":"mcm","clk":"11541159061","pt":1719502857863,"mc":[{"id":"1.230178323","rc":[{"atb":[[1.21,20.16]],"id":47885365}],"con":true,"img":false}]}
{"op":"mcm","clk":"11541159764","pt":1719502864466,"mc":[{"id":"1.230178323","rc":[{"atb":[[1.19,0]],"id":47885365},{"atb":[[1.19,0]],"id":60192591}],"con":true,"img":false}]}
{"op":"mcm","clk":"11541159841","pt":1719502865348,"mc":[{"id":"1.230178323","rc":[{"atb":[[1.23,17.18]],"id":47885365}],"con":true,"img":false}]}
{"op":"mcm","clk":"11541159881","pt":1719502865760,"mc":[{"id":"1.230178323","rc":[{"atb":[[1.23,17.18]],"id":60192591}],"con":true,"img":false}]}
{"op":"mcm","clk":"11541161854","pt":1719502889272,"mc":[{"id":"1.230178323","rc":[{"atb":[[1.21,0]],"id":47885365},{"atb":[[1.21,0]],"id":60192591}],"con":true,"img":false}]}
{"op":"mcm","clk":"11541162003","pt":1719502891188,"mc":[{"id":"1.230178323","rc":[{"atb":[[1.25,16.93]],"id":60192591}],"con":true,"img":false}]}
{"op":"mcm","clk":"11541162026","pt":1719502891496,"mc":[{"id":"1.230178323","rc":[{"atb":[[1.25,16.93]],"id":47885365}],"con":true,"img":false}]}
{"op":"mcm","clk":"11541162671","pt":1719502899698,"mc":[{"id":"1.230178323","rc":[{"atb":[[1.23,0]],"id":47885365}],"con":true,"img":false}]}
{"op":"mcm","clk":"11541162689","pt":1719502899900,"mc":[{"id":"1.230178323","rc":[{"atb":[[1.23,0]],"id":60192591}],"con":true,"img":false}]}
{"op":"mcm","clk":"11541162803","pt":1719502901191,"mc":[{"id":"1.230178323","rc":[{"atb":[[1.27,14.64]],"id":47885365},{"atb":[[1.27,14.64]],"id":60192591}],"con":true,"img":false}]}
{"op":"mcm","clk":"11541164555","pt":1719502924002,"mc":[{"id":"1.230178323","rc":[{"atb":[[1.25,0]],"id":47885365},{"spn":38.13,"spf":"NaN","id":47885365},{"spn":38.13,"spf":"NaN","id":60192591}],"con":true,"img":false}]}
{"op":"mcm","clk":"11541164571","pt":1719502924206,"mc":[{"id":"1.230178323","rc":[{"atb":[[1.25,0]],"id":60192591}],"con":true,"img":false}]}
{"op":"mcm","clk":"11541164652","pt":1719502925234,"mc":[{"id":"1.230178323","rc":[{"atb":[[1.29,14.59]],"id":47885365}],"con":true,"img":false}]}
{"op":"mcm","clk":"11541164660","pt":1719502925338,"mc":[{"id":"1.230178323","rc":[{"atb":[[1.29,14.59]],"id":60192591}],"con":true,"img":false}]}
{"op":"mcm","clk":"11541165685","pt":1719502937209,"mc":[{"id":"1.230178323","rc":[{"atb":[[1.27,0]],"id":47885365}],"con":true,"img":false}]}
{"op":"mcm","clk":"11541165746","pt":1719502938030,"mc":[{"id":"1.230178323","rc":[{"atb":[[1.27,0]],"id":60192591}],"con":true,"img":false}]}
{"op":"mcm","clk":"11541165776","pt":1719502938546,"mc":[{"id":"1.230178323","rc":[{"atb":[[1.31,12.75]],"id":47885365}],"con":true,"img":false}]}
{"op":"mcm","clk":"11541165808","pt":1719502938906,"mc":[{"id":"1.230178323","rc":[{"atb":[[1.31,12.75]],"id":60192591}],"con":true,"img":false}]}
{"op":"mcm","clk":"11541167410","pt":1719502956259,"mc":[{"id":"1.230178323","rc":[{"atb":[[1.29,0]],"id":47885365},{"atb":[[1.29,0]],"id":60192591}],"con":true,"img":false}]}
{"op":"mcm","clk":"11541167533","pt":1719502957438,"mc":[{"id":"1.230178323","rc":[{"atb":[[1.33,12.82]],"id":60192591}],"con":true,"img":false}]}
{"op":"mcm","clk":"11541167555","pt":1719502957648,"mc":[{"id":"1.230178323","rc":[{"atb":[[1.33,12.82]],"id":47885365}],"con":true,"img":false}]}
{"op":"mcm","clk":"11541167710","pt":1719502959348,"mc":[{"id":"1.230178323","rc":[{"atb":[[1.31,0]],"id":47885365}],"con":true,"img":false}]}
{"op":"mcm","clk":"11541167728","pt":1719502959554,"mc":[{"id":"1.230178323","rc":[{"atb":[[1.31,0]],"id":60192591}],"con":true,"img":false}]}
{"op":"mcm","clk":"11541167742","pt":1719502959759,"mc":[{"id":"1.230178323","rc":[{"atb":[[1.35,11.29]],"id":47885365}],"con":true,"img":false}]}
{"op":"mcm","clk":"11541167782","pt":1719502960125,"mc":[{"id":"1.230178323","rc":[{"atb":[[1.35,11.29]],"id":60192591}],"con":true,"img":false}]}
{"op":"mcm","clk":"11541170830","pt":1719502992224,"mc":[{"id":"1.230178323","rc":[{"atb":[[1.33,0]],"id":47885365},{"spn":38.17,"spf":"NaN","id":47885365},{"spn":38.17,"spf":"NaN","id":60192591}],"con":true,"img":false}]}
{"op":"mcm","clk":"11541170869","pt":1719502992566,"mc":[{"id":"1.230178323","rc":[{"atb":[[1.33,0]],"id":60192591}],"con":true,"img":false}]}
{"op":"mcm","clk":"11541170967","pt":1719502993708,"mc":[{"id":"1.230178323","rc":[{"atb":[[1.37,11.43]],"id":47885365}],"con":true,"img":false}]}
{"op":"mcm","clk":"11541171003","pt":1719502993972,"mc":[{"id":"1.230178323","rc":[{"atb":[[1.37,11.43]],"id":60192591}],"con":true,"img":false}]}
{"op":"mcm","clk":"11541171189","pt":1719502995789,"mc":[{"id":"1.230178323","rc":[{"atb":[[1.35,0]],"id":47885365}],"con":true,"img":false}]}
{"op":"mcm","clk":"11541171205","pt":1719502995997,"mc":[{"id":"1.230178323","rc":[{"atb":[[1.35,0]],"id":60192591}],"con":true,"img":false}]}
{"op":"mcm","clk":"11541171244","pt":1719502996367,"mc":[{"id":"1.230178323","rc":[{"atb":[[1.39,10.13]],"id":47885365}],"con":true,"img":false}]}
{"op":"mcm","clk":"11541171259","pt":1719502996575,"mc":[{"id":"1.230178323","rc":[{"atb":[[1.39,10.13]],"id":60192591}],"con":true,"img":false}]}
{"op":"mcm","clk":"11541173939","pt":1719503026243,"mc":[{"id":"1.230178323","rc":[{"atb":[[1.37,0]],"id":47885365},{"atb":[[1.37,0]],"id":60192591}],"con":true,"img":false}]}
{"op":"mcm","clk":"11541174021","pt":1719503027123,"mc":[{"id":"1.230178323","rc":[{"atb":[[1.41,10.33]],"id":47885365}],"con":true,"img":false}]}
{"op":"mcm","clk":"11541174064","pt":1719503027539,"mc":[{"id":"1.230178323","rc":[{"atb":[[1.41,10.33]],"id":60192591}],"con":true,"img":false}]}
{"op":"mcm","clk":"11541174541","pt":1719503032544,"mc":[{"id":"1.230178323","rc":[{"atb":[[1.39,0]],"id":60192591}],"con":true,"img":false}]}
{"op":"mcm","clk":"11541174581","pt":1719503032907,"mc":[{"id":"1.230178323","rc":[{"atb":[[1.39,0]],"id":47885365}],"con":true,"img":false}]}
{"op":"mcm","clk":"11541174629","pt":1719503033325,"mc":[{"id":"1.230178323","rc":[{"atb":[[1.43,9.19]],"id":47885365}],"con":true,"img":false}]}
{"op":"mcm","clk":"11541174650","pt":1719503033533,"mc":[{"id":"1.230178323","rc":[{"atb":[[1.43,9.19]],"id":60192591}],"con":true,"img":false}]}
{"op":"mcm","clk":"11541177325","pt":1719503060674,"mc":[{"id":"1.230178323","rc":[{"spn":38.21,"spf":"NaN","id":47885365},{"atb":[[1.41,0]],"id":60192591},{"spn":38.21,"spf":"NaN","id":60192591}],"con":true,"img":false}]}
{"op":"mcm","clk":"11541177363","pt":1719503061040,"mc":[{"id":"1.230178323","rc":[{"atb":[[1.41,0]],"id":47885365}],"con":true,"img":false}]}
{"op":"mcm","clk":"11541177509","pt":1719503062559,"mc":[{"id":"1.230178323","rc":[{"atb":[[1.45,9.4]],"id":60192591}],"con":true,"img":false}]}
{"op":"mcm","clk":"11541177540","pt":1719503062873,"mc":[{"id":"1.230178323","rc":[{"atb":[[1.45,9.4]],"id":47885365}],"con":true,"img":false}]}
{"op":"mcm","clk":"11541178166","pt":1719503069386,"mc":[{"id":"1.230178323","rc":[{"atb":[[1.43,0]],"id":47885365}],"con":true,"img":false}]}
{"op":"mcm","clk":"11541178181","pt":1719503069490,"mc":[{"id":"1.230178323","rc":[{"atb":[[1.43,0]],"id":60192591}],"con":true,"img":false}]}
{"op":"mcm","clk":"11541178291","pt":1719503070480,"mc":[{"id":"1.230178323","rc":[{"atb":[[1.47,8.41]],"id":60192591}],"con":true,"img":false}]}
{"op":"mcm","clk":"11541178357","pt":1719503071051,"mc":[{"id":"1.230178323","rc":[{"atb":[[1.47,8.41]],"id":47885365}],"con":true,"img":false}]}
{"op":"mcm","clk":"11541180785","pt":1719503095715,"mc":[{"id":"1.230178323","rc":[{"atb":[[1.45,0]],"id":60192591}],"con":true,"img":false}]}
{"op":"mcm","clk":"11541180789","pt":1719503095767,"mc":[{"id":"1.230178323","rc":[{"atb":[[1.45,0]],"id":47885365}],"con":true,"img":false}]}
{"op":"mcm","clk":"11541180946","pt":1719503097667,"mc":[{"id":"1.230178323","rc":[{"atb":[[1.49,8.63]],"id":47885365},{"atb":[[1.49,8.63]],"id":60192591}],"con":true,"img":false}]}
{"op":"mcm","clk":"11541181710","pt":1719503105608,"mc":[{"id":"1.230178323","rc":[{"atb":[[1.47,0]],"id":47885365}],"con":true,"img":false}]}
{"op":"mcm","clk":"11541181730","pt":1719503105815,"mc":[{"id":"1.230178323","rc":[{"atb":[[1.47,0]],"id":60192591}],"con":true,"img":false}]}
{"op":"mcm","clk":"11541181899","pt":1719503107524,"mc":[{"id":"1.230178323","rc":[{"atb":[[1.51,7.74]],"id":47885365}],"con":true,"img":false}]}
{"op":"mcm","clk":"11541181911","pt":1719503107678,"mc":[{"id":"1.230178323","rc":[{"atb":[[1.51,7.74]],"id":60192591}],"con":true,"img":false}]}
{"op":"mcm","clk":"11541184168","pt":1719503131223,"mc":[{"id":"1.230178323","rc":[{"atb":[[1.49,0]],"id":47885365},{"spn":38.25,"spf":"NaN","id":47885365},{"spn":38.25,"spf":"NaN","id":60192591}],"con":true,"img":false}]}
{"op":"mcm","clk":"11541184295","pt":1719503132314,"mc":[{"id":"1.230178323","rc":[{"atb":[[1.49,0]],"id":60192591}],"con":true,"img":false}]}
{"op":"mcm","clk":"11541184402","pt":1719503133299,"mc":[{"id":"1.230178323","rc":[{"atb":[[1.53,7.98]],"id":47885365}],"con":true,"img":false}]}
{"op":"mcm","clk":"11541184527","pt":1719503134438,"mc":[{"id":"1.230178323","rc":[{"atb":[[1.53,7.98]],"id":60192591}],"con":true,"img":false}]}
{"op":"mcm","clk":"11541185305","pt":1719503142047,"mc":[{"id":"1.230178323","rc":[{"atb":[[1.51,0]],"id":60192591}],"con":true,"img":false}]}
{"op":"mcm","clk":"11541185341","pt":1719503142461,"mc":[{"id":"1.230178323","rc":[{"atb":[[1.51,0]],"id":47885365}],"con":true,"img":false}]}
{"op":"mcm","clk":"11541185402","pt":1719503143133,"mc":[{"id":"1.230178323","rc":[{"atb":[[1.55,7.18]],"id":60192591}],"con":true,"img":false}]}
{"op":"mcm","clk":"11541185434","pt":1719503143443,"mc":[{"id":"1.230178323","rc":[{"atb":[[1.55,7.18]],"id":47885365}],"con":true,"img":false}]}
{"op":"mcm","clk":"11541187200","pt":1719503161898,"mc":[{"id":"1.230178323","rc":[{"atb":[[1.56,2.11]],"id":47885365},{"atb":[[1.56,2.11]],"id":60192591}],"con":true,"img":false}]}
{"op":"mcm","clk":"11541187771","pt":1719503167589,"mc":[{"id":"1.230178323","rc":[{"atb":[[1.53,0]],"id":47885365}],"con":true,"img":false}]}
{"op":"mcm","clk":"11541187794","pt":1719503167795,"mc":[{"id":"1.230178323","rc":[{"atb":[[1.53,0]],"id":60192591}],"con":true,"img":false}]}
{"op":"mcm","clk":"11541188083","pt":1719503170181,"mc":[{"id":"1.230178323","rc":[{"atb":[[1.58,7.29]],"id":47885365}],"con":true,"img":false}]}
{"op":"mcm","clk":"11541188133","pt":1719503170596,"mc":[{"id":"1.230178323","rc":[{"atb":[[1.58,7.29]],"id":60192591}],"con":true,"img":false}]}
{"op":"mcm","clk":"11541188911","pt":1719503177513,"mc":[{"id":"1.230178323","rc":[{"atb":[[1.55,0]],"id":47885365}],"con":true,"img":false}]}
{"op":"mcm","clk":"11541188940","pt":1719503177776,"mc":[{"id":"1.230178323","rc":[{"atb":[[1.55,0]],"id":60192591}],"con":true,"img":false}]}
{"op":"mcm","clk":"11541189026","pt":1719503178502,"mc":[{"id":"1.230178323","rc":[{"atb":[[1.6,6.58]],"id":47885365}],"con":true,"img":false}]}
{"op":"mcm","clk":"11541189049","pt":1719503178711,"mc":[{"id":"1.230178323","rc":[{"atb":[[1.6,6.58]],"id":60192591}],"con":true,"img":false}]}
{"op":"mcm","clk":"11541190981","pt":1719503195115,"mc":[{"id":"1.230178323","rc":[{"spn":38.3,"spf":"NaN","id":47885365},{"atb":[[1.09,43.92]],"id":51569790},{"spn":38.3,"spf":"NaN","id":60192591}],"con":true,"img":false}]}
{"op":"mcm","clk":"11541191761","pt":1719503201349,"mc":[{"id":"1.230178323","rc":[{"atb":[[1.58,0]],"id":60192591}],"con":true,"img":false}]}
{"op":"mcm","clk":"11541191789","pt":1719503201506,"mc":[{"id":"1.230178323","rc":[{"atb":[[1.58,0]],"id":47885365}],"con":true,"img":false}]}
{"op":"mcm","clk":"11541191988","pt":1719503203110,"mc":[{"id":"1.230178323","rc":[{"atb":[[1.62,6.82]],"id":60192591}],"con":true,"img":false}]}
{"op":"mcm","clk":"11541192057","pt":1719503203734,"mc":[{"id":"1.230178323","rc":[{"atb":[[1.62,6.82]],"id":47885365}],"con":true,"img":false}]}
{"op":"mcm","clk":"11541193366","pt":1719503215839,"mc":[{"id":"1.230178323","rc":[{"atb":[[1.6,0]],"id":60192591}],"con":true,"img":false}]}
{"op":"mcm","clk":"11541193406","pt":1719503216254,"mc":[{"id":"1.230178323","rc":[{"atb":[[1.6,0]],"id":47885365}],"con":true,"img":false}]}
{"op":"mcm","clk":"11541193443","pt":1719503216617,"mc":[{"id":"1.230178323","rc":[{"atb":[[1.64,6.17]],"id":60192591}],"con":true,"img":false}]}
{"op":"mcm","clk":"11541193462","pt":1719503216825,"mc":[{"id":"1.230178323","rc":[{"atb":[[1.64,6.17]],"id":47885365}],"con":true,"img":false}]}
{"op":"mcm","clk":"11541195352","pt":1719503235264,"mc":[{"id":"1.230178323","rc":[{"atb":[[1.62,0]],"id":47885365},{"atb":[[1.62,0]],"id":60192591}],"con":true,"img":false}]}
{"op":"mcm","clk":"11541195384","pt":1719503235548,"mc":[{"id":"1.230178323","rc":[{"atb":[[1.11,38.48]],"id":51569790}],"con":true,"img":false}]}
{"op":"mcm","clk":"11541195506","pt":1719503236737,"mc":[{"id":"1.230178323","rc":[{"atb":[[1.66,6.41]],"id":47885365}],"con":true,"img":false}]}
{"op":"mcm","clk":"11541195532","pt":1719503236943,"mc":[{"id":"1.230178323","rc":[{"atb":[[1.66,6.41]],"id":60192591}],"con":true,"img":false}]}
{"op":"mcm","clk":"11541196905","pt":1719503251254,"mc":[{"id":"1.230178323","rc":[{"atb":[[1.09,0]],"id":51569790}],"con":true,"img":false}]}
{"op":"mcm","clk":"11541196971","pt":1719503251866,"mc":[{"id":"1.230178323","rc":[{"atb":[[1.64,0]],"id":60192591}],"con":true,"img":false}]}
{"op":"mcm","clk":"11541196984","pt":1719503251973,"mc":[{"id":"1.230178323","rc":[{"atb":[[1.64,0]],"id":47885365}],"con":true,"img":false}]}
{"op":"mcm","clk":"11541197031","pt":1719503252389,"mc":[{"id":"1.230178323","rc":[{"atb":[[1.13,30.4]],"id":51569790}],"con":true,"img":false}]}
{"op":"mcm","clk":"11541197052","pt":1719503252556,"mc":[{"id":"1.230178323","rc":[{"atb":[[1.68,5.81]],"id":47885365}],"con":true,"img":false}]}
{"op":"mcm","clk":"11541197077","pt":1719503252756,"mc":[{"id":"1.230178323","rc":[{"atb":[[1.68,5.81]],"id":60192591}],"con":true,"img":false}]}
{"op":"mcm","clk":"11541198526","pt":1719503268265,"mc":[{"id":"1.230178323","rc":[{"spn":38.34,"spf":"NaN","id":47885365},{"atb":[[1.11,0]],"id":51569790},{"spn":38.34,"spf":"NaN","id":60192591}],"con":true,"img":false}]}
{"op":"mcm","clk":"11541198584","pt":1719503268980,"mc":[{"id":"1.230178323","rc":[{"atb":[[1.66,0]],"id":47885365},{"atb":[[1.66,0]],"id":60192591}],"con":true,"img":false}]}
{"op":"mcm","clk":"11541198690","pt":1719503269872,"mc":[{"id":"1.230178323","rc":[{"atb":[[1.15,28.22]],"id":51569790}],"con":true,"img":false}]}
{"op":"mcm","clk":"11541198733","pt":1719503270277,"mc":[{"id":"1.230178323","rc":[{"atb":[[1.7,6.04]],"id":47885365}],"con":true,"img":false}]}
{"op":"mcm","clk":"11541198756","pt":1719503270486,"mc":[{"id":"1.230178323","rc":[{"atb":[[1.7,6.04]],"id":60192591}],"con":true,"img":false}]}
{"op":"mcm","clk":"11541200644","pt":1719503290109,"mc":[{"id":"1.230178323","rc":[{"atb":[[1.13,0]],"id":51569790}],"con":true,"img":false}]}
{"op":"mcm","clk":"11541200686","pt":1719503290423,"mc":[{"id":"1.230178323","rc":[{"atb":[[1.68,0]],"id":60192591}],"con":true,"img":false}]}
{"op":"mcm","clk":"11541200724","pt":1719503290699,"mc":[{"id":"1.230178323","rc":[{"atb":[[1.68,0]],"id":47885365}],"con":true,"img":false}]}
{"op":"mcm","clk":"11541200764","pt":1719503291107,"mc":[{"id":"1.230178323","rc":[{"atb":[[1.72,5.48]],"id":60192591}],"con":true,"img":false}]}
{"op":"mcm","clk":"11541200787","pt":1719503291315,"mc":[{"id":"1.230178323","rc":[{"atb":[[1.72,5.48]],"id":47885365},{"atb":[[1.17,23.25]],"id":51569790}],"con":true,"img":false}]}
{"op":"mcm","clk":"11541202261","pt":1719503307316,"mc":[{"id":"1.230178323","rc":[{"atb":[[1.15,0]],"id":51569790}],"con":true,"img":false}]}
{"op":"mcm","clk":"11541202329","pt":1719503308035,"mc":[{"id":"1.230178323","rc":[{"atb":[[1.7,0]],"id":60192591}],"con":true,"img":false}]}
{"op":"mcm","clk":"11541202347","pt":1719503308244,"mc":[{"id":"1.230178323","rc":[{"atb":[[1.7,0]],"id":47885365}],"con":true,"img":false}]}
{"op":"mcm","clk":"11541202396","pt":1719503308743,"mc":[{"id":"1.230178323","rc":[{"atb":[[1.19,22.28]],"id":51569790}],"con":true,"img":false}]}
{"op":"mcm","clk":"11541202447","pt":1719503309230,"mc":[{"id":"1.230178323","rc":[{"atb":[[1.74,5.72]],"id":47885365}],"con":true,"img":false}]}
{"op":"mcm","clk":"11541202457","pt":1719503309333,"mc":[{"id":"1.230178323","rc":[{"atb":[[1.74,5.72]],"id":60192591}],"con":true,"img":false}]}
{"op":"mcm","clk":"11541203958","pt":1719503325243,"mc":[{"id":"1.230178323","rc":[{"atb":[[1.17,0]],"id":51569790}],"con":true,"img":false}]}
{"op":"mcm","clk":"11541203987","pt":1719503325545,"mc":[{"id":"1.230178323","rc":[{"atb":[[1.72,0]],"id":47885365}],"con":true,"img":false}]}
{"op":"mcm","clk":"11541204021","pt":1719503325855,"mc":[{"id":"1.230178323","rc":[{"atb":[[1.72,0]],"id":60192591}],"con":true,"img":false}]}
{"op":"mcm","clk":"11541204046","pt":1719503326164,"mc":[{"id":"1.230178323","rc":[{"atb":[[1.21,18.82]],"id":51569790}],"con":true,"img":false}]}
{"op":"mcm","clk":"11541204068","pt":1719503326428,"mc":[{"id":"1.230178323","rc":[{"atb":[[1.76,5.2]],"id":47885365}],"con":true,"img":false}]}
{"op":"mcm","clk":"11541204082","pt":1719503326635,"mc":[{"id":"1.230178323","rc":[{"atb":[[1.76,5.2]],"id":60192591}],"con":true,"img":false}]}
{"op":"mcm","clk":"11541205710","pt":1719503343579,"mc":[{"id":"1.230178323","rc":[{"spn":38.38,"spf":"NaN","id":47885365},{"atb":[[1.19,0]],"id":51569790},{"spn":38.1,"spf":"NaN","id":51569790},{"spn":38.38,"spf":"NaN","id":60192591}],"con":true,"img":false}]}
{"op":"mcm","clk":"11541205722","pt":1719503343682,"mc":[{"id":"1.230178323","rc":[{"atb":[[1.74,0]],"id":60192591}],"con":true,"img":false}]}
{"op":"mcm","clk":"11541205775","pt":1719503344262,"mc":[{"id":"1.230178323","rc":[{"atb":[[1.78,5.42]],"id":60192591}],"con":true,"img":false}]}
{"op":"mcm","clk":"11541205787","pt":1719503344365,"mc":[{"id":"1.230178323","rc":[{"atb":[[1.23,18.4]],"id":51569790}],"con":true,"img":false}]}
{"op":"mcm","clk":"11541205861","pt":1719503345187,"mc":[{"id":"1.230178323","rc":[{"atb":[[1.76,0]],"id":60192591}],"con":true,"img":false}]}
{"op":"mcm","clk":"11541205905","pt":1719503345562,"mc":[{"id":"1.230178323","rc":[{"atb":[[1.8,4.94]],"id":60192591}],"con":true,"img":false}]}
{"op":"mcm","clk":"11541205919","pt":1719503345668,"mc":[{"id":"1.230178323","rc":[{"atb":[[1.21,0]],"id":51569790}],"con":true,"img":false}]}
{"op":"mcm","clk":"11541205934","pt":1719503345873,"mc":[{"id":"1.230178323","rc":[{"atb":[[1.25,15.81]],"id":51569790}],"con":true,"img":false}]}
{"op":"mcm","clk":"11541207650","pt":1719503365195,"mc":[{"id":"1.230178323","rc":[{"atb":[[1.09,43.92]],"id":63650892}],"con":true,"img":false}]}
{"op":"mcm","clk":"11541207671","pt":1719503365404,"mc":[{"id":"1.230178323","rc":[{"atb":[[1.25,0]],"id":51569790}],"con":true,"img":false}]}
{"op":"mcm","clk":"11541209565","pt":1719503378508,"mc":[{"id":"1.230178323","rc":[{"atb":[[1.78,0]],"id":60192591}],"con":true,"img":false}]}
{"op":"mcm","clk":"11541209610","pt":1719503379029,"mc":[{"id":"1.230178323","rc":[{"atb":[[1.82,5.16]],"id":60192591}],"con":true,"img":false}]}
{"op":"mcm","clk":"11541210000","pt":1719503382517,"mc":[{"id":"1.230178323","rc":[{"atb":[[1.8,0]],"id":60192591}],"con":true,"img":false}]}
{"op":"mcm","clk":"11541210025","pt":1719503382828,"mc":[{"id":"1.230178323","rc":[{"atb":[[1.25,15.81]],"id":51569790}],"con":true,"img":false}]}
{"op":"mcm","clk":"11541210058","pt":1719503383232,"mc":[{"id":"1.230178323","rc":[{"atb":[[1.84,4.7]],"id":60192591}],"con":true,"img":false}]}
{"op":"mcm","clk":"11541211782","pt":1719503400910,"mc":[{"id":"1.230178323","rc":[{"atb":[[1.25,0]],"id":51569790}],"con":true,"img":false}]}
{"op":"mcm","clk":"11541213025","pt":1719503413135,"mc":[{"id":"1.230178323","rc":[{"spn":38.11,"spf":"NaN","id":51569790},{"atb":[[1.82,0]],"id":60192591},{"spn":38.42,"spf":"NaN","id":60192591}],"con":true,"img":false}]}
{"op":"mcm","clk":"11541213084","pt":1719503413755,"mc":[{"id":"1.230178323","rc":[{"atb":[[1.86,4.91]],"id":60192591}],"con":true,"img":false}]}
{"op":"mcm","clk":"11541213525","pt":1719503418871,"mc":[{"id":"1.230178323","rc":[{"atb":[[1.84,0]],"id":60192591}],"con":true,"img":false}]}
{"op":"mcm","clk":"11541213554","pt":1719503419234,"mc":[{"id":"1.230178323","rc":[{"atb":[[1.88,4.49]],"id":60192591}],"con":true,"img":false}]}
{"op":"mcm","clk":"11541213591","pt":1719503419646,"mc":[{"id":"1.230178323","rc":[{"atb":[[1.25,15.81]],"id":51569790}],"con":true,"img":false}]}
{"op":"mcm","clk":"11541215103","pt":1719503436584,"mc":[{"id":"1.230178323","rc":[{"atb":[[1.25,0]],"id":51569790}],"con":true,"img":false}]}
{"op":"mcm","clk":"11541215843","pt":1719503445480,"mc":[{"id":"1.230178323","rc":[{"atb":[[1.23,0]],"id":51569790}],"con":true,"img":false}]}
{"op":"mcm","clk":"11541216049","pt":1719503447914,"mc":[{"id":"1.230178323","rc":[{"atb":[[1.86,0]],"id":60192591}],"con":true,"img":false}]}
{"op":"mcm","clk":"11541216073","pt":1719503448183,"mc":[{"id":"1.230178323","rc":[{"atb":[[1.09,47.04]],"id":51569790}],"con":true,"img":false}]}
{"op":"mcm","clk":"11541216141","pt":1719503449006,"mc":[{"id":"1.230178323","rc":[{"atb":[[1.9,4.7]],"id":60192591}],"con":true,"img":false}]}
{"op":"mcm","clk":"11541216784","pt":1719503457197,"mc":[{"id":"1.230178323","rc":[{"atb":[[1.88,0]],"id":60192591}],"con":true,"img":false}]}
{"op":"mcm","clk":"11541216801","pt":1719503457403,"mc":[{"id":"1.230178323","rc":[{"atb":[[1.11,35.93]],"id":51569790}],"con":true,"img":false}]}
{"op":"mcm","clk":"11541216815","pt":1719503457610,"mc":[{"id":"1.230178323","rc":[{"atb":[[1.92,4.29]],"id":60192591}],"con":true,"img":false}]}
{"op":"mcm","clk":"11541217048","pt":1719503460405,"mc":[{"id":"1.230178323","rc":[{"atb":[[1.77,5.2]],"id":47885365},{"atl":[[18,2]],"id":47885365}],"con":true,"img":false}]}
{"op":"mcm","clk":"11541217052","pt":1719503460510,"mc":[{"id":"1.230178323","rc":[{"atb":[[1.07,26.38]],"id":68274051},{"atl":[[5.5,2]],"id":68274051},{"atb":[[2.46,1],[1.93,4.29]],"id":60192591},{"atl":[[7.4,1],[23,2]],"id":60192591}],"con":true,"img":false}]}
{"op":"mcm","clk":"11541217058","pt":1719503460611,"mc":[{"id":"1.230178323","rc":[{"atb":[[2.02,1],[1.67,2.48]],"id":70681333},{"atl":[[16.5,2],[5.4,1]],"id":70681333},{"atb":[[2.46,1]],"id":47885365},{"atl":[[7.8,1]],"id":47885365},{"atb":[[1.74,1],[1.47,2.48]],"id":63650892},{"atl":[[4.5,1],[9,2]],"id":63650892},{"atb":[[1.51,1]],"id":68274051},{"atl":[[3.7,1]],"id":68274051},{"atb":[[1.36,35.93],[1.62,1]],"id":51569790},{"atl":[[7.2,2],[3.9,1]],"id":51569790}],"con":true,"img":false}]}
{"op":"mcm","clk":"11541217092","pt":1719503461132,"mc":[{"id":"1.230178323","rc":[{"atb":[[1.67,0],[1.76,2.48]],"id":70681333},{"atl":[[16.5,0],[24,3]],"id":70681333},{"atl":[[18,0],[26,3]],"id":47885365},{"atb":[[1.59,2.48],[1.47,0]],"id":63650892},{"atl":[[9,0],[13,3]],"id":63650892},{"atl":[[8.6,3],[5.5,0]],"id":68274051},{"atb":[[1.36,0],[1.46,35.93]],"id":51569790},{"atl":[[7.2,0],[9.8,3]],"id":51569790},{"atl":[[36,2.86],[23,0]],"id":60192591}],"con":true,"img":false}]}
{"op":"mcm","clk":"11541217157","pt":1719503462012,"mc":[{"id":"1.230178323","rc":[{"atb":[[1.01,1.7]],"id":70681333},{"atl":[[1000,1.7]],"id":70681333},{"atb":[[1.01,1.7]],"id":63650892},{"atl":[[1000,1.87]],"id":63650892},{"atb":[[1.01,47.02]],"id":51569790},{"atl":[[1000,1.7]],"id":51569790}],"con":true,"img":false}]}
{"op":"mcm","clk":"11541217183","pt":1719503462323,"mc":[{"id":"1.230178323","rc":[{"atb":[[1.01,0.41]],"id":70681333},{"atl":[[1000,0.01]],"id":70681333},{"atb":[[1.01,0.53]],"id":63650892},{"atl":[[1000,0.19]],"id":63650892},{"atb":[[1.01,45.99]],"id":51569790},{"atl":[[1000,0.03]],"id":51569790}],"con":true,"img":false}]}
{"op":"mcm","clk":"11541217197","pt":1719503462427,"mc":[{"id":"1.230178323","rc":[{"atl":[[1000,0.16]],"id":63650892}],"con":true,"img":false}]}
{"op":"mcm","clk":"11541217208","pt":1719503462531,"mc":[{"id":"1.230178323","rc":[{"atb":[[1.01,0]],"id":70681333},{"atl":[[1000,0]],"id":70681333},{"atb":[[1.01,0]],"id":63650892},{"atl":[[12.5,0.02]],"id":63650892},{"atb":[[1.01,45.31]],"id":51569790},{"atl":[[1000,0]],"id":51569790}],"con":true,"img":false}]}
{"op":"mcm","clk":"11541217222","pt":1719503462638,"mc":[{"id":"1.230178323","rc":[{"atb":[[1.77,0.41]],"id":70681333},{"atl":[[23,0.01]],"id":70681333},{"atb":[[1.6,0.53]],"id":63650892},{"atb":[[1.47,0.67]],"id":51569790},{"atl":[[9.6,0.03]],"id":51569790}],"con":true,"img":false}]}
{"op":"mcm","clk":"11541217296","pt":1719503463317,"mc":[{"id":"1.230178323","rc":[{"atb":[[1.49,2.11]],"id":51569790}],"con":true,"img":false}]}
{"op":"mcm","clk":"11541217307","pt":1719503463422,"mc":[{"id":"1.230178323","rc":[{"atb":[[1.46,0],[1.49,4.23]],"id":51569790}],"con":true,"img":false}]}
{"op":"mcm","clk":"11541218464","pt":1719503476198,"mc":[{"id":"1.230178323","rc":[{"spn":3.71,"spf":"NaN","id":70681333},{"spn":5.13,"spf":"NaN","id":47885365},{"atb":[[1.09,0]],"id":63650892},{"spn":3.12,"spf":"NaN","id":63650892},{"spn":2.6,"spf":"NaN","id":68274051},{"spn":2.76,"spf":"NaN","id":51569790},{"spn":4.93,"spf":"NaN","id":60192591}],"con":true,"img":false}]}
{"op":"mcm","clk":"11541218477","pt":1719503476405,"mc":[{"id":"1.230178323","rc":[{"atb":[[1.61,6.48]],"id":63650892}],"con":true,"img":false}]}
{"op":"mcm","clk":"11541218484","pt":1719503476509,"mc":[{"id":"1.230178323","rc":[{"atb":[[1.59,0],[1.62,2.48]],"id":63650892}],"con":true,"img":false}]}
{"op":"mcm","clk":"11541218735","pt":1719503479618,"mc":[{"id":"1.230178323","rc":[{"atb":[[1.63,2.11]],"id":63650892}],"con":true,"img":false}]}
{"op":"mcm","clk":"11541220016","pt":1719503494736,"mc":[{"id":"1.230178323","rc":[{"atb":[[1.11,0]],"id":51569790}],"con":true,"img":false}]}
{"op":"mcm","clk":"11541220025","pt":1719503494883,"mc":[{"id":"1.230178323","rc":[{"atb":[[1.61,0]],"id":63650892}],"con":true,"img":false}]}
{"op":"mcm","clk":"11541220058","pt":1719503495143,"mc":[{"id":"1.230178323","rc":[{"atb":[[1.51,7.74]],"id":51569790}],"con":true,"img":false}]}
{"op":"mcm","clk":"11541220075","pt":1719503495347,"mc":[{"id":"1.230178323","rc":[{"atb":[[1.49,2.11],[1.52,4.24]],"id":51569790}],"con":true,"img":false}]}
{"op":"mcm","clk":"11541220998","pt":1719503505089,"mc":[{"id":"1.230178323","rc":[{"atb":[[1.77,0]],"id":70681333},{"atl":[[23,0]],"id":70681333},{"atb":[[1.6,0]],"id":63650892},{"atl":[[12.5,0]],"id":63650892},{"atb":[[1.47,0]],"id":51569790},{"atl":[[9.6,0]],"id":51569790}],"con":true,"img":false}]}
{"op":"mcm","clk":"11541222038","pt":1719503515678,"mc":[{"id":"1.230178323","rc":[{"atb":[[1.02,24.65]],"id":70681333}],"con":true,"img":false}]}
{"op":"mcm","clk":"11541222075","pt":1719503516086,"mc":[{"id":"1.230178323","rc":[{"atb":[[1.53,2]],"id":51569790}],"con":true,"img":false}]}
{"op":"mcm","clk":"11541222108","pt":1719503516394,"mc":[{"id":"1.230178323","rc":[{"atb":[[1.02,24.65]],"id":63650892}],"con":true,"img":false}]}
{"op":"mcm","clk":"11541222165","pt":1719503516864,"mc":[{"id":"1.230178323","rc":[{"atb":[[1.78,2]],"id":47885365}],"con":true,"img":false}]}
{"op":"mcm","clk":"11541222213","pt":1719503517279,"mc":[{"id":"1.230178323","rc":[{"atb":[[1.08,2]],"id":68274051}],"con":true,"img":false}]}
{"op":"mcm","clk":"11541222244","pt":1719503517695,"mc":[{"id":"1.230178323","rc":[{"atb":[[1.94,2]],"id":60192591}],"con":true,"img":false}]}
{"op":"mcm","clk":"11541224545","pt":1719503539601,"mc":[{"id":"1.230178323","rc":[{"atb":[[1.76,0]],"id":47885365},{"atb":[[1.92,0]],"id":60192591}],"con":true,"img":false}]}
{"op":"mcm","clk":"11541225335","pt":1719503547792,"mc":[{"id":"1.230178323","rc":[{"atb":[[1.74,0]],"id":47885365},{"atb":[[1.09,0]],"id":51569790},{"atb":[[1.9,0]],"id":60192591}],"con":true,"img":false}]}
{"op":"mcm","clk":"11541225468","pt":1719503549229,"mc":[{"id":"1.230178323","rc":[{"atb":[[1.94,0]],"id":60192591}],"con":true,"img":false}]}
{"op":"mcm","clk":"11541225478","pt":1719503549285,"mc":[{"id":"1.230178323","rc":[{"atb":[[1.02,2]],"id":60192591}],"con":true,"img":false}]}
{"op":"mcm","clk":"11541226124","pt":1719503556397,"mc":[{"id":"1.230178323","rc":[{"atb":[[1.9,3.9]],"id":60192591}],"con":true,"img":false}]}
{"op":"mcm","clk":"11541226369","pt":1719503559134,"mc":[{"id":"1.230178323","rc":[{"atb":[[1.9,0]],"id":60192591}],"con":true,"img":false}]}
{"op":"mcm","clk":"11541227014","pt":1719503565353,"mc":[{"id":"1.230178323","rc":[{"atb":[[1.65,6.07]],"id":63650892}],"con":true,"img":false}]}
{"op":"mcm","clk":"11541227032","pt":1719503565546,"mc":[{"id":"1.230178323","rc":[{"atb":[[1.62,0],[1.66,2.48]],"id":63650892}],"con":true,"img":false}]}
{"op":"mcm","clk":"11541227149","pt":1719503566632,"mc":[{"id":"1.230178323","rc":[{"atb":[[1.02,22.65]],"id":63650892}],"con":true,"img":false}]}
{"op":"mcm","clk":"11541227158","pt":1719503566735,"mc":[{"id":"1.230178323","rc":[{"atb":[[1.67,2]],"id":63650892}],"con":true,"img":false}]}
{"op":"mcm","clk":"11541228246","pt":1719503577110,"mc":[{"id":"1.230178323","rc":[{"atb":[[1.51,0]],"id":51569790}],"con":true,"img":false}]}
{"op":"mcm","clk":"11541228527","pt":1719503580320,"mc":[{"id":"1.230178323","rc":[{"atl":[[1000,1.7]],"id":70681333},{"atl":[[1000,1.87]],"id":63650892},{"atl":[[1000,1.7]],"id":51569790}],"con":true,"img":false}]}
{"op":"mcm","clk":"11541228537","pt":1719503580423,"mc":[{"id":"1.230178323","rc":[{"atb":[[1.01,1.7]],"id":70681333},{"atb":[[1.01,1.7]],"id":63650892},{"atb":[[1.01,47.02]],"id":51569790}],"con":true,"img":false}]}
{"op":"mcm","clk":"11541228547","pt":1719503580527,"mc":[{"id":"1.230178323","rc":[{"atl":[[1000,0.01]],"id":70681333},{"atl":[[1000,0.19]],"id":63650892},{"atl":[[1000,0.03]],"id":51569790}],"con":true,"img":false}]}
{"op":"mcm","clk":"11541228557","pt":1719503580633,"mc":[{"id":"1.230178323","rc":[{"atb":[[1.01,0.39]],"id":70681333},{"atb":[[1.01,0.45]],"id":63650892},{"atb":[[1.01,45.88]],"id":51569790}],"con":true,"img":false}]}
{"op":"mcm","clk":"11541228567","pt":1719503580734,"mc":[{"id":"1.230178323","rc":[{"atl":[[1000,0]],"id":70681333},{"atl":[[1000,0.16]],"id":63650892},{"atl":[[1000,0]],"id":51569790}],"con":true,"img":false}]}
{"op":"mcm","clk":"11541228581","pt":1719503580838,"mc":[{"id":"1.230178323","rc":[{"atb":[[1.01,0]],"id":70681333},{"atl":[[23,0.01]],"id":70681333},{"atb":[[1.01,0]],"id":63650892},{"atl":[[12.5,0.02]],"id":63650892},{"atb":[[1.01,45.31]],"id":51569790},{"atl":[[9.6,0.03]],"id":51569790}],"con":true,"img":false}]}
{"op":"mcm","clk":"11541228589","pt":1719503580942,"mc":[{"id":"1.230178323","rc":[{"atb":[[1.77,0.39]],"id":70681333},{"atb":[[1.68,0.45]],"id":63650892},{"atb":[[1.54,0.56]],"id":51569790}],"con":true,"img":false}]}
{"op":"mcm","clk":"11541228604","pt":1719503581049,"mc":[{"id":"1.230178323","rc":[{"atb":[[1.68,2.45],[1.66,0]],"id":63650892},{"atb":[[1.54,2.56],[1.52,0]],"id":51569790}],"con":true,"img":false}]}
{"op":"mcm","clk":"11541228687","pt":1719503581823,"mc":[{"id":"1.230178323","rc":[{"atb":[[1.53,0]],"id":51569790}],"con":true,"img":false}]}
{"op":"mcm","clk":"11541228699","pt":1719503581926,"mc":[{"id":"1.230178323","rc":[{"atb":[[1.55,2],[1.5,3.57]],"id":51569790}],"con":true,"img":false}]}
{"op":"mcm","clk":"11541228713","pt":1719503582031,"mc":[{"id":"1.230178323","rc":[{"atb":[[1.54,0.56]],"id":51569790}],"con":true,"img":false}]}
{"op":"mcm","clk":"11541228722","pt":1719503582132,"mc":[{"id":"1.230178323","rc":[{"atb":[[1.55,4.57],[1.5,0]],"id":51569790}],"con":true,"img":false}]}
{"op":"mcm","clk":"11541228774","pt":1719503582549,"mc":[{"id":"1.230178323","rc":[{"atb":[[1.67,0]],"id":63650892}],"con":true,"img":false}]}
{"op":"mcm","clk":"11541228813","pt":1719503582856,"mc":[{"id":"1.230178323","rc":[{"atb":[[1.69,2]],"id":63650892}],"con":true,"img":false}]}
{"op":"mcm","clk":"11541228961","pt":1719503584258,"mc":[{"id":"1.230178323","rc":[{"atb":[[1.55,2.57],[1.5,2.5]],"id":51569790}],"con":true,"img":false}]}
{"op":"mcm","clk":"11541228974","pt":1719503584361,"mc":[{"id":"1.230178323","rc":[{"atb":[[1.02,2]],"id":51569790}],"con":true,"img":false}]}
{"op":"mcm","clk":"11541229102","pt":1719503585546,"mc":[{"id":"1.230178323","rc":[{"atb":[[1.5,0]],"id":51569790}],"con":true,"img":false}]}
{"op":"mcm","clk":"11541229139","pt":1719503585960,"mc":[{"id":"1.230178323","rc":[{"atb":[[1.02,0]],"id":51569790}],"con":true,"img":false}]}
{"op":"mcm","clk":"11541229150","pt":1719503586061,"mc":[{"id":"1.230178323","rc":[{"atb":[[1.56,2]],"id":51569790}],"con":true,"img":false}]}
{"op":"mcm","clk":"11541229264","pt":1719503587150,"mc":[{"id":"1.230178323","rc":[{"atb":[[1.58,3.75]],"id":63650892}],"con":true,"img":false}]}
{"op":"mcm","clk":"11541229285","pt":1719503587355,"mc":[{"id":"1.230178323","rc":[{"atb":[[1.58,0]],"id":63650892}],"con":true,"img":false}]}
{"op":"mcm","clk":"11541230729","pt":1719503602476,"mc":[{"id":"1.230178323","rc":[{"atb":[[1.58,6.81]],"id":51569790}],"con":true,"img":false}]}
{"op":"mcm","clk":"11541230740","pt":1719503602579,"mc":[{"id":"1.230178323","rc":[{"atb":[[1.59,2.57],[1.55,0]],"id":51569790}],"con":true,"img":false}]}
{"op":"mcm","clk":"11541230857","pt":1719503603461,"mc":[{"id":"1.230178323","rc":[{"atb":[[1.56,0]],"id":51569790}],"con":true,"img":false}]}
{"op":"mcm","clk":"11541230870","pt":1719503603564,"mc":[{"id":"1.230178323","rc":[{"atb":[[1.6,2]],"id":51569790}],"con":true,"img":false}]}
{"op":"mcm","clk":"11541232550","pt":1719503621176,"mc":[{"id":"1.230178323","rc":[{"atb":[[1.77,0]],"id":70681333},{"atl":[[23,0]],"id":70681333},{"atb":[[1.68,2]],"id":63650892},{"atl":[[12.5,0]],"id":63650892},{"atb":[[1.54,0]],"id":51569790},{"atl":[[9.6,0]],"id":51569790}],"con":true,"img":false}]}
{"op":"mcm","clk":"11541232602","pt":1719503621691,"mc":[{"id":"1.230178323","rc":[{"atb":[[1.65,0]],"id":63650892}],"con":true,"img":false}]}
{"op":"mcm","clk":"11541233372","pt":1719503630807,"mc":[{"id":"1.230178323","rc":[{"atb":[[1.82,2.48],[1.76,0]],"id":70681333},{"atb":[[1.86,2.12],[1.77,0]],"id":47885365},{"atb":[[1.15,26.38],[1.07,2.48]],"id":68274051},{"atl":[[9.8,0],[8.8,2]],"id":51569790}],"con":true,"img":false}]}
{"op":"mcm","clk":"11541233468","pt":1719503631581,"mc":[{"id":"1.230178323","rc":[{"atb":[[1.78,0]],"id":47885365}],"con":true,"img":false}]}
{"op":"mcm","clk":"11541233479","pt":1719503631688,"mc":[{"id":"1.230178323","rc":[{"atb":[[1.87,2]],"id":47885365}],"con":true,"img":false}]}
{"op":"mcm","clk":"11541233504","pt":1719503631998,"mc":[{"id":"1.230178323","rc":[{"atb":[[1.08,0]],"id":68274051}],"con":true,"img":false}]}
{"op":"mcm","clk":"11541233514","pt":1719503632102,"mc":[{"id":"1.230178323","rc":[{"atb":[[1.16,2]],"id":68274051}],"con":true,"img":false}]}
{"op":"mcm","clk":"11541234357","pt":1719503640825,"mc":[{"id":"1.230178323","rc":[{"atb":[[2.54,2.5],[2.38,10],[2.04,1.5],[2.46,5]],"id":70681333},{"atl":[[8,10],[7.2,5],[6.4,2.5],[5.3,1.5]],"id":70681333},{"atb":[[2.6,10],[2.68,5],[2.48,2.25],[2.76,2.5]],"id":47885365},{"atl":[[6.8,2.5],[7.6,7.25],[8.4,10]],"id":47885365},{"atb":[[2.28,2.5],[2.12,10],[2.2,5],[1.75,2.25]],"id":63650892},{"atl":[[5.6,5],[6,10],[5.2,2.5],[4.4,2.25]],"id":63650892},{"atb":[[1.59,10],[1.63,5],[1.67,2.5],[1.51,2.5]],"id":68274051},{"atl":[[4.6,5],[5,10],[4.2,2.5],[3.65,1.5]],"id":68274051},{"atb":[[1.67,10],[1.62,3.25],[1.75,2.5],[1.71,5]],"id":51569790},{"atl":[[4.3,2.5],[5.1,10],[3.85,2.25],[4.7,5]],"id":51569790},{"atb":[[2.92,2.5],[2.84,5],[2.48,1.5],[2.76,10]],"id":60192591},{"atl":[[7.2,1.5],[8.6,5],[7.8,2.5],[9.4,10]],"id":60192591}],"con":true,"img":false}]}
{"op":"mcm","clk":"11541234368","pt":1719503640878,"mc":[{"id":"1.230178323","rc":[{"atb":[[2.52,2]],"id":47885365},{"atl":[[7.8,3]],"id":47885365},{"atb":[[2.08,2]],"id":63650892},{"atl":[[5.2,4.5]],"id":63650892},{"atb":[[1.67,12]],"id":51569790},{"atl":[[4.3,4.5]],"id":51569790}],"con":true,"img":false}]}
{"op":"mcm","clk":"11541234380","pt":1719503640982,"mc":[{"id":"1.230178323","rc":[{"atb":[[1.82,0],[2.38,12]],"id":70681333},{"atl":[[6.4,4.5],[24,0]],"id":70681333},{"atb":[[1.86,0]],"id":47885365},{"atl":[[26,0]],"id":47885365},{"atb":[[1.68,0]],"id":63650892},{"atl":[[13,0]],"id":63650892},{"atb":[[1.15,0],[1.55,2]],"id":68274051},{"atl":[[8.6,0],[4.2,4.5]],"id":68274051},{"atb":[[1.59,0]],"id":51569790},{"atl":[[8.8,0],[3.65,2.84]],"id":51569790},{"atb":[[2.74,2.12],[1.93,0]],"id":60192591},{"atl":[[36,0],[8.2,2]],"id":60192591}],"con":true,"img":false}]}
{"op":"mcm","clk":"11541234405","pt":1719503641192,"mc":[{"id":"1.230178323","rc":[{"atl":[[4.3,2.5],[3.7,5.68]],"id":51569790}],"con":true,"img":false}]}
{"op":"mcm","clk":"11541234419","pt":1719503641295,"mc":[{"id":"1.230178323","rc":[{"atl":[[6.6,0.84]],"id":47885365},{"atl":[[4.3,0.84]],"id":63650892},{"atl":[[3.6,0.84]],"id":51569790}],"con":true,"img":false}]}
{"op":"mcm","clk":"11541234429","pt":1719503641397,"mc":[{"id":"1.230178323","rc":[{"atl":[[4.5,5.5],[5.2,2.5]],"id":63650892}],"con":true,"img":false}]}
{"op":"mcm","clk":"11541234477","pt":1719503641811,"mc":[{"id":"1.230178323","rc":[{"atb":[[1.02,22.65]],"id":70681333}],"con":true,"img":false}]}
{"op":"mcm","clk":"11541234492","pt":1719503641914,"mc":[{"id":"1.230178323","rc":[{"atb":[[2.56,2]],"id":70681333}],"con":true,"img":false}]}
{"op":"mcm","clk":"11541234508","pt":1719503642122,"mc":[{"id":"1.230178323","rc":[{"atb":[[2.38,10],[2.44,5]],"id":70681333}],"con":true,"img":false}]}
{"op":"mcm","clk":"11541234519","pt":1719503642176,"mc":[{"id":"1.230178323","rc":[{"atb":[[1.6,0]],"id":51569790}],"con":true,"img":false}]}
{"op":"mcm","clk":"11541234532","pt":1719503642280,"mc":[{"id":"1.230178323","rc":[{"atb":[[2.44,7.11]],"id":70681333},{"atb":[[1.62,2.11]],"id":68274051},{"atb":[[1.76,2]],"id":51569790}],"con":true,"img":false}]}
{"op":"mcm","clk":"11541234544","pt":1719503642384,"mc":[{"id":"1.230178323","rc":[{"atb":[[1.76,4.5]],"id":51569790}],"con":true,"img":false}]}
{"op":"mcm","clk":"11541234555","pt":1719503642486,"mc":[{"id":"1.230178323","rc":[{"atb":[[1.69,0]],"id":63650892},{"atb":[[1.67,10],[1.71,10],[1.76,2]],"id":51569790}],"con":true,"img":false}]}
{"op":"mcm","clk":"11541234566","pt":1719503642593,"mc":[{"id":"1.230178323","rc":[{"atb":[[2.3,2]],"id":63650892}],"con":true,"img":false}]}
{"op":"mcm","clk":"11541234617","pt":1719503643108,"mc":[{"id":"1.230178323","rc":[{"atb":[[1.87,0]],"id":47885365}],"con":true,"img":false}]}
{"op":"mcm","clk":"11541234627","pt":1719503643211,"mc":[{"id":"1.230178323","rc":[{"atb":[[1.02,24.65]],"id":47885365}],"con":true,"img":false}]}
{"op":"mcm","clk":"11541234662","pt":1719503643622,"mc":[{"id":"1.230178323","rc":[{"atb":[[1.16,0]],"id":68274051}],"con":true,"img":false}]}
{"op":"mcm","clk":"11541234670","pt":1719503643675,"mc":[{"id":"1.230178323","rc":[{"atb":[[1.68,2]],"id":68274051}],"con":true,"img":false}]}
{"op":"mcm","clk":"11541234705","pt":1719503644092,"mc":[{"id":"1.230178323","rc":[{"atb":[[1.02,0]],"id":60192591}],"con":true,"img":false}]}
{"op":"mcm","clk":"11541234721","pt":1719503644251,"mc":[{"id":"1.230178323","rc":[{"atb":[[2.94,2]],"id":60192591}],"con":true,"img":false}]}
{"op":"mcm","clk":"11541235194","pt":1719503649219,"mc":[{"id":"1.230178323","rc":[{"atl":[[8.2,0],[7.8,5]],"id":60192591}],"con":true,"img":false}]}
{"op":"mcm","clk":"11541235210","pt":1719503649323,"mc":[{"id":"1.230178323","rc":[{"atl":[[3.65,0]],"id":51569790}],"con":true,"img":false}]}
{"op":"mcm","clk":"11541235219","pt":1719503649424,"mc":[{"id":"1.230178323","rc":[{"atb":[[1.71,5],[1.76,4.5]],"id":51569790},{"atl":[[3.85,8.78],[3.7,0]],"id":51569790}],"con":true,"img":false}]}
{"op":"mcm","clk":"11541235250","pt":1719503649681,"mc":[{"id":"1.230178323","rc":[{"atl":[[3.6,2.32]],"id":51569790}],"con":true,"img":false}]}
{"op":"mcm","clk":"11541235262","pt":1719503649786,"mc":[{"id":"1.230178323","rc":[{"atl":[[3.6,3.81]],"id":51569790}],"con":true,"img":false}]}
{"op":"mcm","clk":"11541235273","pt":1719503649888,"mc":[{"id":"1.230178323","rc":[{"atl":[[3.6,1.48],[3.9,12.11]],"id":51569790}],"con":true,"img":false}]}
{"op":"mcm","clk":"11541235281","pt":1719503649991,"mc":[{"id":"1.230178323","rc":[{"atl":[[3.6,5.29],[3.9,1]],"id":51569790}],"con":true,"img":false}]}
{"op":"mcm","clk":"11541235291","pt":1719503650094,"mc":[{"id":"1.230178323","rc":[{"atl":[[3.6,1.48],[3.85,2.25],[3.9,11.26]],"id":51569790}],"con":true,"img":false}]}
{"op":"mcm","clk":"11541235301","pt":1719503650201,"mc":[{"id":"1.230178323","rc":[{"atl":[[3.6,6.77],[3.9,1]],"id":51569790}],"con":true,"img":false}]}
{"op":"mcm","clk":"11541235311","pt":1719503650303,"mc":[{"id":"1.230178323","rc":[{"atl":[[3.55,0.84]],"id":51569790}],"con":true,"img":false}]}
{"op":"mcm","clk":"11541236146","pt":1719503658307,"mc":[{"id":"1.230178323","rc":[{"atb":[[2.56,5.38]],"id":70681333},{"atb":[[2.76,8.12]],"id":47885365},{"atl":[[6.6,6.46]],"id":47885365},{"atb":[[2.3,5.56]],"id":63650892},{"atl":[[4.3,4.4]],"id":63650892},{"atb":[[1.68,5.38]],"id":68274051},{"atb":[[1.76,9.75]],"id":51569790},{"atl":[[3.55,6.09]],"id":51569790},{"atb":[[2.98,3.38]],"id":60192591}],"con":true,"img":false}]}
{"op":"mcm","clk":"11541236162","pt":1719503658410,"mc":[{"id":"1.230178323","rc":[{"atb":[[2.04,0]],"id":70681333},{"atb":[[2.48,0]],"id":47885365},{"atl":[[7.6,5]],"id":47885365},{"atb":[[1.75,0]],"id":63650892},{"atl":[[4.4,0]],"id":63650892},{"atb":[[1.51,1]],"id":68274051},{"atb":[[1.62,1],[1.71,12],[1.76,7.25]],"id":51569790},{"atl":[[3.85,0]],"id":51569790},{"atb":[[2.48,0]],"id":60192591}],"con":true,"img":false}]}
{"op":"mcm","clk":"11541236172","pt":1719503658515,"mc":[{"id":"1.230178323","rc":[{"atl":[[5.2,12.41]],"id":63650892},{"atb":[[1.71,5],[1.76,12.25]],"id":51569790}],"con":true,"img":false}]}
{"op":"mcm","clk":"11541236183","pt":1719503658618,"mc":[{"id":"1.230178323","rc":[{"atl":[[4.5,1]],"id":63650892},{"atb":[[1.71,15],[1.76,7.25]],"id":51569790}],"con":true,"img":false}]}
{"op":"mcm","clk":"11541236195","pt":1719503658724,"mc":[{"id":"1.230178323","rc":[{"atb":[[1.71,5],[1.76,12.25]],"id":51569790}],"con":true,"img":false}]}
{"op":"mcm","clk":"11541236208","pt":1719503658826,"mc":[{"id":"1.230178323","rc":[{"atb":[[1.71,15],[1.76,7.25]],"id":51569790}],"con":true,"img":false}]}
{"op":"mcm","clk":"11541236278","pt":1719503659494,"mc":[{"id":"1.230178323","rc":[{"atb":[[2.94,0]],"id":60192591}],"con":true,"img":false}]}
{"op":"mcm","clk":"11541236288","pt":1719503659596,"mc":[{"id":"1.230178323","rc":[{"atb":[[3,2]],"id":60192591}],"con":true,"img":false}]}
{"op":"mcm","clk":"11541236580","pt":1719503662446,"mc":[{"id":"1.230178323","rc":[{"atb":[[2.52,2.11]],"id":70681333},{"atb":[[2.26,2.11]],"id":63650892},{"atb":[[1.66,2.11]],"id":68274051}],"con":true,"img":false}]}
{"op":"mcm","clk":"11541236590","pt":1719503662502,"mc":[{"id":"1.230178323","rc":[{"atb":[[2.44,5]],"id":70681333},{"spn":3.93,"spf":"NaN","id":70681333},{"spn":4.68,"spf":"NaN","id":47885365},{"atb":[[1.63,0]],"id":63650892},{"spn":3.3,"spf":"NaN","id":63650892},{"atb":[[1.62,0]],"id":68274051},{"spn":2.66,"spf":"NaN","id":68274051},{"spn":2.65,"spf":"NaN","id":51569790},{"spn":5.1,"spf":"NaN","id":60192591}],"con":true,"img":false}]}
{"op":"mcm","clk":"11541236829","pt":1719503664723,"mc":[{"id":"1.230178323","rc":[{"atl":[[3.6,5.29]],"id":51569790}],"con":true,"img":false}]}
{"op":"mcm","clk":"11541236838","pt":1719503664825,"mc":[{"id":"1.230178323","rc":[{"atb":[[1.76,14.5]],"id":51569790},{"atl":[[3.9,12.39]],"id":51569790}],"con":true,"img":false}]}
{"op":"mcm","clk":"11541236850","pt":1719503664929,"mc":[{"id":"1.230178323","rc":[{"atb":[[1.71,5]],"id":51569790},{"atl":[[3.6,0]],"id":51569790}],"con":true,"img":false}]}
{"op":"mcm","clk":"11541236859","pt":1719503665033,"mc":[{"id":"1.230178323","rc":[{"atl":[[4.3,20.99],[3.9,1],[3.65,2.84]],"id":51569790}],"con":true,"img":false}]}
{"op":"mcm","clk":"11541236869","pt":1719503665137,"mc":[{"id":"1.230178323","rc":[{"atl":[[4.3,2.5],[3.65,15.04]],"id":51569790}],"con":true,"img":false}]}
{"op":"mcm","clk":"11541236880","pt":1719503665238,"mc":[{"id":"1.230178323","rc":[{"atl":[[3.9,9.94],[3.65,2.84]],"id":51569790}],"con":true,"img":false}]}
{"op":"mcm","clk":"11541236891","pt":1719503665344,"mc":[{"id":"1.230178323","rc":[{"atl":[[3.9,1],[3.65,15.04]],"id":51569790}],"con":true,"img":false}]}
{"op":"mcm","clk":"11541236902","pt":1719503665444,"mc":[{"id":"1.230178323","rc":[{"atl":[[3.9,9.94],[3.65,2.84]],"id":51569790}],"con":true,"img":false}]}
{"op":"mcm","clk":"11541236909","pt":1719503665547,"mc":[{"id":"1.230178323","rc":[{"atl":[[3.9,1],[3.65,12.2]],"id":51569790}],"con":true,"img":false}]}
{"op":"mcm","clk":"11541236920","pt":1719503665602,"mc":[{"id":"1.230178323","rc":[{"atl":[[3.9,9.94],[3.65,0]],"id":51569790}],"con":true,"img":false}]}
{"op":"mcm","clk":"11541236940","pt":1719503665806,"mc":[{"id":"1.230178323","rc":[{"atl":[[3.6,1.48],[4.3,18.54],[3.9,1]],"id":51569790}],"con":true,"img":false}]}
{"op":"mcm","clk":"11541237086","pt":1719503667349,"mc":[{"id":"1.230178323","rc":[{"atl":[[3.6,0]],"id":51569790}],"con":true,"img":false}]}
{"op":"mcm","clk":"11541237114","pt":1719503667606,"mc":[{"id":"1.230178323","rc":[{"atl":[[3.35,1.99]],"id":51569790}],"con":true,"img":false}]}
{"op":"mcm","clk":"11541237169","pt":1719503668224,"mc":[{"id":"1.230178323","rc":[{"atl":[[3.55,5.25],[3.3,0.84]],"id":51569790}],"con":true,"img":false}]}
{"op":"mcm","clk":"11541237701","pt":1719503673949,"mc":[{"id":"1.230178323","rc":[{"atl":[[4.3,2.5],[3.4,5.25]],"id":51569790}],"con":true,"img":false}]}
{"op":"mcm","clk":"11541237852","pt":1719503675442,"mc":[{"id":"1.230178323","rc":[{"atl":[[6.4,8.6]],"id":47885365},{"atb":[[3,5.38]],"id":60192591}],"con":true,"img":false}]}
{"op":"mcm","clk":"11541237861","pt":1719503675545,"mc":[{"id":"1.230178323","rc":[{"atl":[[6.2,6.47],[7.8,1]],"id":47885365},{"atl":[[3.3,6.46]],"id":51569790},{"atb":[[2.98,0]],"id":60192591}],"con":true,"img":false}]}
{"op":"mcm","clk":"11541237871","pt":1719503675648,"mc":[{"id":"1.230178323","rc":[{"atl":[[6.2,0],[6.6,15.91]],"id":47885365},{"atl":[[3.55,0]],"id":51569790}],"con":true,"img":false}]}
{"op":"mcm","clk":"11541237879","pt":1719503675752,"mc":[{"id":"1.230178323","rc":[{"atl":[[6.2,0.84]],"id":47885365}],"con":true,"img":false}]}
{"op":"mcm","clk":"11541239490","pt":1719503692265,"mc":[{"id":"1.230178323","rc":[{"atl":[[6.2,13.38]],"id":47885365}],"con":true,"img":false}]}
{"op":"mcm","clk":"11541239501","pt":1719503692368,"mc":[{"id":"1.230178323","rc":[{"atl":[[6.4,0]],"id":47885365}],"con":true,"img":false}]}
{"op":"mcm","clk":"11541239508","pt":1719503692471,"mc":[{"id":"1.230178323","rc":[{"atl":[[6.8,19.74],[6.6,0.84]],"id":47885365}],"con":true,"img":false}]}
{"op":"mcm","clk":"11541239549","pt":1719503692833,"mc":[{"id":"1.230178323","rc":[{"atl":[[6.6,0]],"id":47885365}],"con":true,"img":false}]}
{"op":"mcm","clk":"11541239724","pt":1719503694739,"mc":[{"id":"1.230178323","rc":[{"atb":[[1.58,0]],"id":51569790}],"con":true,"img":false}]}
{"op":"mcm","clk":"11541239733","pt":1719503694841,"mc":[{"id":"1.230178323","rc":[{"atl":[[3.35,0]],"id":51569790}],"con":true,"img":false}]}
{"op":"mcm","clk":"11541239744","pt":1719503694944,"mc":[{"id":"1.230178323","rc":[{"atl":[[3.4,0],[3.9,12.72]],"id":51569790}],"con":true,"img":false}]}
{"op":"mcm","clk":"11541239766","pt":1719503695151,"mc":[{"id":"1.230178323","rc":[{"atl":[[3.3,7.94]],"id":51569790}],"con":true,"img":false}]}
{"op":"mcm","clk":"11541239776","pt":1719503695254,"mc":[{"id":"1.230178323","rc":[{"atl":[[3.4,15.9],[3.9,1]],"id":51569790}],"con":true,"img":false}]}
{"op":"mcm","clk":"11541240028","pt":1719503697570,"mc":[{"id":"1.230178323","rc":[{"atl":[[7.6,20.15]],"id":47885365}],"con":true,"img":false}]}
{"op":"mcm","clk":"11541240040","pt":1719503697674,"mc":[{"id":"1.230178323","rc":[{"atl":[[6.8,2.5]],"id":47885365}],"con":true,"img":false}]}
{"op":"mcm","clk":"11541240206","pt":1719503699583,"mc":[{"id":"1.230178323","rc":[{"atl":[[5.3,2.5],[5.2,1],[5.4,0]],"id":70681333},{"atl":[[7.2,1],[7.8,0]],"id":47885365},{"atl":[[4.5,0],[4.4,1],[4.2,1]],"id":63650892},{"atb":[[1.55,0],[1.58,10]],"id":68274051},{"atl":[[3.7,0],[3.35,1],[3.65,2.5]],"id":68274051},{"atl":[[3.9,0]],"id":51569790},{"atl":[[7.2,2.5],[7.4,0],[6.6,1]],"id":60192591}],"con":true,"img":false}]}
{"op":"mcm","clk":"11541240217","pt":1719503699686,"mc":[{"id":"1.230178323","rc":[{"atl":[[5.6,5],[6.4,2.5],[5.2,3.72]],"id":70681333},{"atl":[[5.2,2.5],[4.4,9.82],[4.2,4.46]],"id":63650892},{"atl":[[3.6,2.72],[3.7,4.5],[4.2,2.5]],"id":68274051},{"atl":[[7.4,5],[7.8,2.5],[7,3]],"id":60192591}],"con":true,"img":false}]}
{"op":"mcm","clk":"11541240231","pt":1719503699739,"mc":[{"id":"1.230178323","rc":[{"atl":[[6.4,7.5],[5.3,0]],"id":70681333},{"atl":[[4.4,8.82]],"id":63650892},{"atl":[[4.2,7.5],[3.65,1.5]],"id":68274051},{"atl":[[7.2,1.5],[7.4,0],[7.8,7.5]],"id":60192591}],"con":true,"img":false}]}
{"op":"mcm","clk":"11541240237","pt":1719503699845,"mc":[{"id":"1.230178323","rc":[{"atl":[[5.6,0]],"id":70681333},{"atl":[[4.3,0.84]],"id":63650892},{"atl":[[3.7,0],[4.2,2.5],[3.65,3.72]],"id":68274051},{"atl":[[7.2,4],[7.8,2.5]],"id":60192591}],"con":true,"img":false}]}
{"op":"mcm","clk":"11541240256","pt":1719503700050,"mc":[{"id":"1.230178323","rc":[{"atl":[[7.2,16.22],[6.4,2.5]],"id":70681333}],"con":true,"img":false}]}
{"op":"mcm","clk":"11541240274","pt":1719503700255,"mc":[{"id":"1.230178323","rc":[{"atl":[[5.1,0.84]],"id":70681333},{"atl":[[7.2,16.89],[7.6,5]],"id":47885365},{"atl":[[4.1,0.84]],"id":63650892}],"con":true,"img":false}]}
{"op":"mcm","clk":"11541240285","pt":1719503700358,"mc":[{"id":"1.230178323","rc":[{"atl":[[7.2,5],[6.4,12.5]],"id":70681333}],"con":true,"img":false}]}
{"op":"mcm","clk":"11541240892","pt":1719503706765,"mc":[{"id":"1.230178323","rc":[{"atb":[[2.38,0],[2.62,2.5]],"id":70681333},{"atb":[[1.59,0],[1.63,0],[1.67,0],[1.7,2.5],[1.66,7.11]],"id":68274051},{"atb":[[3,7.88],[2.76,0]],"id":60192591}],"con":true,"img":false}]}
{"op":"mcm","clk":"11541240914","pt":1719503706973,"mc":[{"id":"1.230178323","rc":[{"atb":[[2.62,7.17]],"id":70681333},{"atb":[[1.7,7.33]],"id":68274051}],"con":true,"img":false}]}
{"op":"mcm","clk":"11541240926","pt":1719503707075,"mc":[{"id":"1.230178323","rc":[{"atb":[[3.05,5.25]],"id":60192591}],"con":true,"img":false}]}
{"op":"mcm","clk":"11541240934","pt":1719503707178,"mc":[{"id":"1.230178323","rc":[{"atb":[[2.56,2]],"id":70681333},{"atb":[[1.68,2]],"id":68274051}],"con":true,"img":false}]}
{"op":"mcm","clk":"11541240943","pt":1719503707283,"mc":[{"id":"1.230178323","rc":[{"atb":[[2.52,0],[2.6,2.11]],"id":70681333},{"atb":[[3,4.5]],"id":60192591}],"con":true,"img":false}]}
{"op":"mcm","clk":"11541241037","pt":1719503708259,"mc":[{"id":"1.230178323","rc":[{"atb":[[2.56,0]],"id":70681333}],"con":true,"img":false}]}
{"op":"mcm","clk":"11541241044","pt":1719503708361,"mc":[{"id":"1.230178323","rc":[{"atb":[[2.64,2]],"id":70681333}],"con":true,"img":false}]}
{"op":"mcm","clk":"11541241076","pt":1719503708671,"mc":[{"id":"1.230178323","rc":[{"atb":[[1.68,0]],"id":68274051}],"con":true,"img":false}]}
{"op":"mcm","clk":"11541241086","pt":1719503708774,"mc":[{"id":"1.230178323","rc":[{"atb":[[1.71,2]],"id":68274051}],"con":true,"img":false}]}
{"op":"mcm","clk":"11541241112","pt":1719503708979,"mc":[{"id":"1.230178323","rc":[{"atb":[[1.02,24.36]],"id":70681333},{"atl":[[1000,1.7]],"id":70681333},{"atb":[[1.02,24.36]],"id":63650892},{"atl":[[1000,1.87]],"id":63650892},{"atb":[[1.01,47.02]],"id":51569790},{"atl":[[1000,1.7]],"id":51569790}],"con":true,"img":false}]}
{"op":"mcm","clk":"11541241125","pt":1719503709084,"mc":[{"id":"1.230178323","rc":[{"atb":[[3,2.5]],"id":60192591}],"con":true,"img":false}]}
{"op":"mcm","clk":"11541241135","pt":1719503709187,"mc":[{"id":"1.230178323","rc":[{"atb":[[1.02,22.83]],"id":70681333},{"atl":[[1000,0.07]],"id":70681333},{"atb":[[1.02,22.88]],"id":63650892},{"atl":[[1000,0.26]],"id":63650892},{"atb":[[1.01,45.7]],"id":51569790},{"atl":[[1000,0.13]],"id":51569790},{"atb":[[3.1,2]],"id":60192591}],"con":true,"img":false}]}
{"op":"mcm","clk":"11541241154","pt":1719503709393,"mc":[{"id":"1.230178323","rc":[{"atb":[[1.02,22.65]],"id":70681333},{"atl":[[1000,0]],"id":70681333},{"atb":[[1.02,22.65]],"id":63650892},{"atl":[[1000,0.16]],"id":63650892},{"atb":[[1.01,45.31]],"id":51569790},{"atl":[[1000,0]],"id":51569790}],"con":true,"img":false}]}
{"op":"mcm","clk":"11541241163","pt":1719503709495,"mc":[{"id":"1.230178323","rc":[{"atb":[[2.66,0.17]],"id":70681333},{"atl":[[5.1,0.91]],"id":70681333},{"atb":[[2.32,0.22]],"id":63650892},{"atl":[[4.1,0.94]],"id":63650892},{"atb":[[1.77,0.38]],"id":51569790},{"atl":[[3.25,0.13]],"id":51569790}],"con":true,"img":false}]}
{"op":"mcm","clk":"11541241172","pt":1719503709597,"mc":[{"id":"1.230178323","rc":[{"atl":[[3.25,7.97]],"id":51569790}],"con":true,"img":false}]}
{"op":"mcm","clk":"11541241182","pt":1719503709700,"mc":[{"id":"1.230178323","rc":[{"atl":[[3.3,2.32]],"id":51569790}],"con":true,"img":false}]}
{"op":"mcm","clk":"11541241216","pt":1719503710166,"mc":[{"id":"1.230178323","rc":[{"atl":[[3.3,0.84]],"id":51569790}],"con":true,"img":false}]}
{"op":"mcm","clk":"11541241225","pt":1719503710267,"mc":[{"id":"1.230178323","rc":[{"atl":[[3.2,0.84]],"id":51569790}],"con":true,"img":false}]}
{"op":"mcm","clk":"11541241256","pt":1719503710578,"mc":[{"id":"1.230178323","rc":[{"atl":[[3.35,2.89]],"id":51569790}],"con":true,"img":false}]}
{"op":"mcm","clk":"11541241329","pt":1719503711402,"mc":[{"id":"1.230178323","rc":[{"atb":[[2.5,5]],"id":70681333},{"atb":[[2.52,0],[2.58,16.24]],"id":47885365},{"atb":[[2.82,5],[2.74,0]],"id":60192591}],"con":true,"img":false}]}
{"op":"mcm","clk":"11541241337","pt":1719503711505,"mc":[{"id":"1.230178323","rc":[{"atb":[[2.44,0]],"id":70681333}],"con":true,"img":false}]}
{"op":"mcm","clk":"11541241839","pt":1719503715996,"mc":[{"id":"1.230178323","rc":[{"atl":[[5.1,5.2]],"id":70681333},{"atl":[[4.1,3.52]],"id":63650892},{"atl":[[3.3,4.83]],"id":68274051},{"atl":[[6.4,4.12]],"id":60192591}],"con":true,"img":false}]}
{"op":"mcm","clk":"11541241851","pt":1719503716100,"mc":[{"id":"1.230178323","rc":[{"atl":[[5.6,10],[6.4,2.5],[5.2,1]],"id":70681333},{"atl":[[4,3.52],[4.4,0],[4.2,1]],"id":63650892},{"atl":[[3.25,2.72],[3.65,0]],"id":68274051},{"atl":[[7,0]],"id":60192591}],"con":true,"img":false}]}
{"op":"mcm","clk":"11541241865","pt":1719503716202,"mc":[{"id":"1.230178323","rc":[{"atl":[[3.6,0]],"id":68274051}],"con":true,"img":false}]}
{"op":"mcm","clk":"11541241878","pt":1719503716303,"mc":[{"id":"1.230178323","rc":[{"atl":[[4.3,0]],"id":63650892},{"atl":[[3.25,3.56]],"id":68274051},{"atl":[[6.2,0.84]],"id":60192591}],"con":true,"img":false}]}
{"op":"mcm","clk":"11541241939","pt":1719503716870,"mc":[{"id":"1.230178323","rc":[{"atl":[[3.95,0.84]],"id":63650892}],"con":true,"img":false}]}
{"op":"mcm","clk":"11541242350","pt":1719503720583,"mc":[{"id":"1.230178323","rc":[{"atl":[[3.35,0]],"id":51569790}],"con":true,"img":false}]}
{"op":"mcm","clk":"11541242380","pt":1719503720893,"mc":[{"id":"1.230178323","rc":[{"atl":[[3.05,1.99]],"id":51569790}],"con":true,"img":false}]}
{"op":"mcm","clk":"11541242400","pt":1719503721098,"mc":[{"id":"1.230178323","rc":[{"atb":[[3.1,0]],"id":60192591},{"trd":[[3.1,4]],"ltp":3.1,"tv":4.0,"id":60192591}],"con":true,"img":false}]}
{"op":"mcm","clk":"11541242425","pt":1719503721308,"mc":[{"id":"1.230178323","rc":[{"atl":[[4,0],[4.1,7.89]],"id":63650892},{"atl":[[3.35,9.4],[3.25,0.84]],"id":68274051},{"atl":[[3.2,0],[3,0.84],[3.3,0]],"id":51569790}],"con":true,"img":false}]}
{"op":"mcm","clk":"11541242437","pt":1719503721362,"mc":[{"id":"1.230178323","rc":[{"atl":[[4.2,9.74]],"id":63650892}],"con":true,"img":false}]}
{"op":"mcm","clk":"11541242445","pt":1719503721464,"mc":[{"id":"1.230178323","rc":[{"atl":[[4.1,3.52]],"id":63650892}],"con":true,"img":false}]}
{"op":"mcm","clk":"11541242493","pt":1719503721879,"mc":[{"id":"1.230178323","rc":[{"atb":[[2.66,2.71]],"id":70681333},{"atb":[[2.32,2.76]],"id":63650892},{"atl":[[3.95,0]],"id":63650892},{"atb":[[1.72,2.54]],"id":68274051},{"atb":[[1.77,2.92]],"id":51569790},{"atb":[[3.1,2.54]],"id":60192591}],"con":true,"img":false}]}
{"op":"mcm","clk":"11541242518","pt":1719503722086,"mc":[{"id":"1.230178323","rc":[{"atb":[[2.32,7.47]],"id":63650892},{"atb":[[1.77,6.98]],"id":51569790}],"con":true,"img":false}]}
{"op":"mcm","clk":"11541242531","pt":1719503722191,"mc":[{"id":"1.230178323","rc":[{"atb":[[1.78,6.98],[1.76,7.25]],"id":51569790}],"con":true,"img":false}]}
{"op":"mcm","clk":"11541242541","pt":1719503722296,"mc":[{"id":"1.230178323","rc":[{"atb":[[2.3,2]],"id":63650892},{"atb":[[1.76,2]],"id":51569790}],"con":true,"img":false}]}
{"op":"mcm","clk":"11541242573","pt":1719503722706,"mc":[{"id":"1.230178323","rc":[{"atb":[[2.64,0]],"id":70681333},{"spn":3.88,"spf":"NaN","id":70681333},{"spn":4.48,"spf":"NaN","id":47885365},{"spn":3.21,"spf":"NaN","id":63650892},{"spn":2.48,"spf":"NaN","id":68274051},{"spn":2.39,"spf":"NaN","id":51569790},{"spn":4.65,"spf":"NaN","id":60192591}],"con":true,"img":false}]}
{"op":"mcm","clk":"11541242588","pt":1719503722811,"mc":[{"id":"1.230178323","rc":[{"atb":[[2.68,2]],"id":70681333}],"con":true,"img":false}]}
{"op":"mcm","clk":"11541242611","pt":1719503722979,"mc":[{"id":"1.230178323","rc":[{"atb":[[2.68,3.94]],"id":70681333},{"atb":[[2.78,1.94]],"id":47885365},{"atb":[[2.34,1.94]],"id":63650892},{"atb":[[3.15,1.94]],"id":60192591}],"con":true,"img":false}]}
{"op":"mcm","clk":"11541242626","pt":1719503723078,"mc":[{"id":"1.230178323","rc":[{"atb":[[2.78,11.78]],"id":47885365},{"atb":[[1.76,0]],"id":51569790}],"con":true,"img":false}]}
{"op":"mcm","clk":"11541242640","pt":1719503723182,"mc":[{"id":"1.230178323","rc":[{"atb":[[2.68,10.81]],"id":70681333},{"atb":[[2.76,2.5]],"id":47885365},{"atb":[[1.72,8.07]],"id":68274051},{"atb":[[1.79,2]],"id":51569790}],"con":true,"img":false}]}
{"op":"mcm","clk":"11541242650","pt":1719503723288,"mc":[{"id":"1.230178323","rc":[{"atb":[[2.62,2.5]],"id":70681333},{"atb":[[1.7,2.5]],"id":68274051},{"atb":[[1.77,4.44]],"id":51569790},{"atb":[[3.15,5.31]],"id":60192591}],"con":true,"img":false}]}
{"op":"mcm","clk":"11541242671","pt":1719503723484,"mc":[{"id":"1.230178323","rc":[{"atb":[[2.3,0]],"id":63650892},{"atb":[[3.05,0]],"id":60192591}],"con":true,"img":false}]}
{"op":"mcm","clk":"11541242678","pt":1719503723589,"mc":[{"id":"1.230178323","rc":[{"atb":[[2.34,3.94]],"id":63650892}],"con":true,"img":false}]}
{"op":"mcm","clk":"11541242718","pt":1719503724000,"mc":[{"id":"1.230178323","rc":[{"atb":[[1.71,0]],"id":68274051}],"con":true,"img":false}]}
{"op":"mcm","clk":"11541242733","pt":1719503724104,"mc":[{"id":"1.230178323","rc":[{"atb":[[1.73,2]],"id":68274051},{"atl":[[3.05,0]],"id":51569790}],"con":true,"img":false}]}
{"op":"mcm","clk":"11541242743","pt":1719503724207,"mc":[{"id":"1.230178323","rc":[{"atb":[[2.28,8.12]],"id":63650892}],"con":true,"img":false}]}
{"op":"mcm","clk":"11541242754","pt":1719503724311,"mc":[{"id":"1.230178323","rc":[{"atb":[[2.28,2.5]],"id":63650892},{"atl":[[3,2.32]],"id":51569790}],"con":true,"img":false}]}
{"op":"mcm","clk":"11541242775","pt":1719503724467,"mc":[{"id":"1.230178323","rc":[{"atb":[[2.8,2.54]],"id":47885365}],"con":true,"img":false}]}
{"op":"mcm","clk":"11541242790","pt":1719503724572,"mc":[{"id":"1.230178323","rc":[{"atb":[[2.66,0.17]],"id":70681333},{"atb":[[2.32,4.93]],"id":63650892},{"atb":[[3.1,0]],"id":60192591}],"con":true,"img":false}]}
{"op":"mcm","clk":"11541242876","pt":1719503725495,"mc":[{"id":"1.230178323","rc":[{"atb":[[2.78,9.84]],"id":47885365}],"con":true,"img":false}]}
{"op":"mcm","clk":"11541242891","pt":1719503725719,"mc":[{"id":"1.230178323","rc":[{"atb":[[2.82,1.94],[2.66,10]],"id":47885365},{"atl":[[3,10.89]],"id":51569790}],"con":true,"img":false}]}
{"op":"mcm","clk":"11541242900","pt":1719503725780,"mc":[{"id":"1.230178323","rc":[{"atb":[[2.58,0]],"id":47885365},{"atl":[[3.25,0.13]],"id":51569790}],"con":true,"img":false}]}
{"op":"mcm","clk":"11541242919","pt":1719503725984,"mc":[{"id":"1.230178323","rc":[{"atb":[[1.72,5.53]],"id":68274051}],"con":true,"img":false}]}
{"op":"mcm","clk":"11541242968","pt":1719503726492,"mc":[{"id":"1.230178323","rc":[{"atl":[[5.2,15.76],[4.2,1]],"id":63650892}],"con":true,"img":false}]}
{"op":"mcm","clk":"11541243010","pt":1719503727005,"mc":[{"id":"1.230178323","rc":[{"atb":[[2.7,2.54]],"id":70681333},{"atb":[[2.36,2.54]],"id":63650892},{"atb":[[1.8,2.54]],"id":51569790},{"atb":[[3.2,2.54]],"id":60192591}],"con":true,"img":false}]}
{"op":"mcm","clk":"11541243067","pt":1719503727681,"mc":[{"id":"1.230178323","rc":[{"atb":[[2.68,8.81]],"id":70681333},{"atb":[[1.81,2.11],[1.49,0]],"id":51569790}],"con":true,"img":false}]}
{"op":"mcm","clk":"11541243079","pt":1719503727792,"mc":[{"id":"1.230178323","rc":[{"atb":[[2.72,2]],"id":70681333}],"con":true,"img":false}]}
{"op":"mcm","clk":"11541243107","pt":1719503728086,"mc":[{"id":"1.230178323","rc":[{"atb":[[2.68,6.87]],"id":70681333},{"atb":[[2.82,0]],"id":47885365},{"atb":[[2.34,2]],"id":63650892},{"atb":[[3.15,3.37]],"id":60192591}],"con":true,"img":false}]}
{"op":"mcm","clk":"11541243116","pt":1719503728191,"mc":[{"id":"1.230178323","rc":[{"atb":[[2.72,3.94]],"id":70681333},{"atb":[[2.82,1.94]],"id":47885365},{"atb":[[2.38,1.94]],"id":63650892},{"atb":[[1.79,0]],"id":51569790},{"atb":[[3.25,1.94]],"id":60192591}],"con":true,"img":false}]}
{"op":"mcm","clk":"11541243124","pt":1719503728293,"mc":[{"id":"1.230178323","rc":[{"atb":[[1.81,4.11]],"id":51569790}],"con":true,"img":false}]}
{"op":"mcm","clk":"11541243134","pt":1719503728397,"mc":[{"id":"1.230178323","rc":[{"atb":[[2.8,0]],"id":47885365},{"atl":[[3.25,3.38]],"id":68274051}],"con":true,"img":false}]}
{"op":"mcm","clk":"11541243140","pt":1719503728499,"mc":[{"id":"1.230178323","rc":[{"atl":[[3.2,4.83],[3.35,1]],"id":68274051}],"con":true,"img":false}]}
{"op":"mcm","clk":"11541243160","pt":1719503728705,"mc":[{"id":"1.230178323","rc":[{"atb":[[2.34,0]],"id":63650892}],"con":true,"img":false}]}
{"op":"mcm","clk":"11541243170","pt":1719503728811,"mc":[{"id":"1.230178323","rc":[{"atb":[[2.38,3.94]],"id":63650892},{"atl":[[3.15,0.84]],"id":68274051}],"con":true,"img":false}]}
{"op":"mcm","clk":"11541243193","pt":1719503729017,"mc":[{"id":"1.230178323","rc":[{"atl":[[5.1,6.2]],"id":70681333},{"atl":[[4.3,1],[4.1,4.52]],"id":63650892},{"atl":[[3.35,0],[3.45,1],[3.4,1]],"id":68274051}],"con":true,"img":false}]}
{"op":"mcm","clk":"11541243205","pt":1719503729121,"mc":[{"id":"1.230178323","rc":[{"atl":[[5.2,0]],"id":70681333},{"atl":[[4.2,0]],"id":63650892}],"con":true,"img":false}]}
{"op":"mcm","clk":"11541243217","pt":1719503729224,"mc":[{"id":"1.230178323","rc":[{"atl":[[5.6,0]],"id":70681333}],"con":true,"img":false}]}
{"op":"mcm","clk":"11541243229","pt":1719503729283,"mc":[{"id":"1.230178323","rc":[{"atl":[[6.4,18.71]],"id":70681333}],"con":true,"img":false}]}
{"op":"mcm","clk":"11541243241","pt":1719503729389,"mc":[{"id":"1.230178323","rc":[{"atl":[[7.2,21.13],[6.4,2.5]],"id":70681333},{"atl":[[4.3,0],[4.1,3.52]],"id":63650892},{"atl":[[3.45,0]],"id":68274051},{"atl":[[4.2,2.5]],"id":51569790}],"con":true,"img":false}]}
{"op":"mcm","clk":"11541243253","pt":1719503729486,"mc":[{"id":"1.230178323","rc":[{"atl":[[4.3,0],[5.1,0],[4.7,0]],"id":51569790}],"con":true,"img":false}]}
{"op":"mcm","clk":"11541243262","pt":1719503729588,"mc":[{"id":"1.230178323","rc":[{"atb":[[2.7,0]],"id":70681333},{"atb":[[2.36,0]],"id":63650892},{"atl":[[4.6,0],[5,0],[4.2,0]],"id":68274051},{"atb":[[1.8,0]],"id":51569790},{"atb":[[3.2,0]],"id":60192591}],"con":true,"img":false}]}
{"op":"mcm","clk":"11541243275","pt":1719503729692,"mc":[{"id":"1.230178323","rc":[{"atb":[[1.82,4.12],[1.78,0]],"id":51569790}],"con":true,"img":false}]}
{"op":"mcm","clk":"11541243298","pt":1719503729899,"mc":[{"id":"1.230178323","rc":[{"atb":[[2.72,1.94]],"id":70681333}],"con":true,"img":false}]}
{"op":"mcm","clk":"11541243306","pt":1719503730002,"mc":[{"id":"1.230178323","rc":[{"atb":[[2.7,2]],"id":70681333}],"con":true,"img":false}]}
{"op":"mcm","clk":"11541243355","pt":1719503730515,"mc":[{"id":"1.230178323","rc":[{"atb":[[2.38,1.94]],"id":63650892}],"con":true,"img":false}]}
{"op":"mcm","clk":"11541243364","pt":1719503730617,"mc":[{"id":"1.230178323","rc":[{"atb":[[2.72,0]],"id":70681333},{"atb":[[2.82,0]],"id":47885365},{"atb":[[2.34,2]],"id":63650892},{"atb":[[3.25,0]],"id":60192591}],"con":true,"img":false}]}
{"op":"mcm","clk":"11541243375","pt":1719503730719,"mc":[{"id":"1.230178323","rc":[{"atb":[[2.7,3.94]],"id":70681333},{"atb":[[2.8,1.94]],"id":47885365},{"atb":[[3.2,1.94],[3.15,0]],"id":60192591}],"con":true,"img":false}]}
{"op":"mcm","clk":"11541243387","pt":1719503730824,"mc":[{"id":"1.230178323","rc":[{"atl":[[3.25,0.84]],"id":68274051},{"atb":[[3.1,3.75]],"id":60192591}],"con":true,"img":false}]}
{"op":"mcm","clk":"11541243407","pt":1719503730987,"mc":[{"id":"1.230178323","rc":[{"atl":[[3.2,0],[3.25,6.52]],"id":68274051}],"con":true,"img":false}]}
{"op":"mcm","clk":"11541243417","pt":1719503731087,"mc":[{"id":"1.230178323","rc":[{"atl":[[3.25,0.84],[3.3,12.21]],"id":68274051}],"con":true,"img":false}]}
{"op":"mcm","clk":"11541243452","pt":1719503731393,"mc":[{"id":"1.230178323","rc":[{"atl":[[3.15,0]],"id":68274051}],"con":true,"img":false}]}
{"op":"mcm","clk":"11541243463","pt":1719503731496,"mc":[{"id":"1.230178323","rc":[{"atl":[[4.5,5],[4.1,2.5],[3.4,14.06],[4.9,10],[3.3,4.83]],"id":68274051}],"con":true,"img":false}]}
{"op":"mcm","clk":"11541243473","pt":1719503731600,"mc":[{"id":"1.230178323","rc":[{"atl":[[5.6,24.28],[5.2,2.5]],"id":63650892},{"atb":[[1.81,2.11]],"id":51569790}],"con":true,"img":false}]}
{"op":"mcm","clk":"11541243486","pt":1719503731702,"mc":[{"id":"1.230178323","rc":[{"atb":[[1.82,0],[1.83,2],[1.81,10.35]],"id":51569790}],"con":true,"img":false}]}
{"op":"mcm","clk":"11541243515","pt":1719503732011,"mc":[{"id":"1.230178323","rc":[{"atl":[[3.25,6.34]],"id":68274051},{"atl":[[6.2,4.18]],"id":60192591}],"con":true,"img":false}]}
{"op":"mcm","clk":"11541243529","pt":1719503732115,"mc":[{"id":"1.230178323","rc":[{"atl":[[3.3,0]],"id":68274051},{"atl":[[6.4,0]],"id":60192591}],"con":true,"img":false}]}
{"op":"mcm","clk":"11541243589","pt":1719503732691,"mc":[{"id":"1.230178323","rc":[{"atb":[[1.83,0]],"id":51569790}],"con":true,"img":false}]}
{"op":"mcm","clk":"11541243600","pt":1719503732796,"mc":[{"id":"1.230178323","rc":[{"atb":[[1.82,2]],"id":51569790}],"con":true,"img":false}]}
{"op":"mcm","clk":"11541243630","pt":1719503733102,"mc":[{"id":"1.230178323","rc":[{"atb":[[2.8,0]],"id":47885365},{"atb":[[2.38,0]],"id":63650892},{"atb":[[3.2,0]],"id":60192591}],"con":true,"img":false}]}
{"op":"mcm","clk":"11541243639","pt":1719503733205,"mc":[{"id":"1.230178323","rc":[{"atb":[[2.8,1.94]],"id":47885365},{"atb":[[2.34,3.94]],"id":63650892},{"atl":[[3.2,2.54]],"id":68274051},{"atb":[[3.15,1.94]],"id":60192591}],"con":true,"img":false}]}
{"op":"mcm","clk":"11541243749","pt":1719503734499,"mc":[{"id":"1.230178323","rc":[{"atb":[[2.72,2.54]],"id":70681333},{"atb":[[2.82,2.54]],"id":47885365},{"atb":[[2.36,2.54]],"id":63650892},{"atb":[[1.74,2.54]],"id":68274051},{"atb":[[1.83,2.54]],"id":51569790},{"atb":[[3.2,2.54]],"id":60192591}],"con":true,"img":false}]}
{"op":"mcm","clk":"11541243841","pt":1719503735429,"mc":[{"id":"1.230178323","rc":[{"atb":[[2.7,1.94]],"id":70681333}],"con":true,"img":false}]}
{"op":"mcm","clk":"11541243859","pt":1719503735528,"mc":[{"id":"1.230178323","rc":[{"atb":[[2.74,2],[2.7,0]],"id":70681333},{"atb":[[2.8,0]],"id":47885365},{"atb":[[2.34,2]],"id":63650892},{"atb":[[3.15,0]],"id":60192591}],"con":true,"img":false}]}
{"op":"mcm","clk":"11541243877","pt":1719503735688,"mc":[{"id":"1.230178323","rc":[{"atb":[[2.74,3.94]],"id":70681333},{"atb":[[2.84,1.94]],"id":47885365},{"atb":[[2.38,1.94]],"id":63650892},{"atl":[[3.15,0.84]],"id":68274051},{"atb":[[3.25,1.94]],"id":60192591}],"con":true,"img":false}]}
{"op":"mcm","clk":"11541243913","pt":1719503736099,"mc":[{"id":"1.230178323","rc":[{"atb":[[1.82,0]],"id":51569790}],"con":true,"img":false}]}
{"op":"mcm","clk":"11541243923","pt":1719503736201,"mc":[{"id":"1.230178323","rc":[{"atb":[[1.84,2]],"id":51569790}],"con":true,"img":false}]}
{"op":"mcm","clk":"11541243950","pt":1719503736511,"mc":[{"id":"1.230178323","rc":[{"atb":[[2.34,0]],"id":63650892},{"atl":[[4.3,1]],"id":63650892}],"con":true,"img":false}]}
{"op":"mcm","clk":"11541243963","pt":1719503736614,"mc":[{"id":"1.230178323","rc":[{"atb":[[2.38,3.94]],"id":63650892},{"atl":[[5.6,5],[5.2,12.5]],"id":63650892}],"con":true,"img":false}]}
{"op":"mcm","clk":"11541243988","pt":1719503736922,"mc":[{"id":"1.230178323","rc":[{"atb":[[2.72,0]],"id":70681333},{"atb":[[2.82,0]],"id":47885365},{"atb":[[2.36,0]],"id":63650892},{"atb":[[1.73,0]],"id":68274051},{"atb":[[3.2,0]],"id":60192591}],"con":true,"img":false}]}
{"op":"mcm","clk":"11541243999","pt":1719503737025,"mc":[{"id":"1.230178323","rc":[{"atb":[[1.75,2]],"id":68274051}],"con":true,"img":false}]}
{"op":"mcm","clk":"11541244025","pt":1719503737234,"mc":[{"id":"1.230178323","rc":[{"atb":[[2.74,10],[2.66,0]],"id":47885365},{"atb":[[1.79,5.08],[1.81,2.11]],"id":51569790},{"atb":[[2.82,0],[2.9,5]],"id":60192591},{"atl":[[7.2,0],[7.4,8]],"id":60192591}],"con":true,"img":false}]}
{"op":"mcm","clk":"11541244066","pt":1719503737604,"mc":[{"id":"1.230178323","rc":[{"atb":[[2.74,1.94]],"id":70681333}],"con":true,"img":false}]}
{"op":"mcm","clk":"11541244077","pt":1719503737705,"mc":[{"id":"1.230178323","rc":[{"atb":[[2.7,2]],"id":70681333}],"con":true,"img":false}]}
{"op":"mcm","clk":"11541244108","pt":1719503738010,"mc":[{"id":"1.230178323","rc":[{"atb":[[2.74,0]],"id":70681333},{"atb":[[2.84,0]],"id":47885365},{"atb":[[2.38,7.54]],"id":63650892},{"atb":[[1.84,5.5]],"id":51569790},{"atb":[[3.25,0]],"id":60192591}],"con":true,"img":false}]}
{"op":"mcm","clk":"11541244119","pt":1719503738113,"mc":[{"id":"1.230178323","rc":[{"atb":[[2.7,3.94]],"id":70681333},{"atb":[[2.8,1.94]],"id":47885365},{"atb":[[2.32,0.22],[2.34,2]],"id":63650892},{"atb":[[1.77,0.38]],"id":51569790},{"atb":[[3.15,1.94]],"id":60192591}],"con":true,"img":false}]}
{"op":"mcm","clk":"11541244191","pt":1719503738691,"mc":[{"id":"1.230178323","rc":[{"atb":[[1.74,0]],"id":68274051},{"atb":[[1.83,0]],"id":51569790}],"con":true,"img":false}]}
{"op":"mcm","clk":"11541244201","pt":1719503738792,"mc":[{"id":"1.230178323","rc":[{"atb":[[2.34,0]],"id":63650892}],"con":true,"img":false}]}
{"op":"mcm","clk":"11541244212","pt":1719503738896,"mc":[{"id":"1.230178323","rc":[{"atb":[[2.4,2]],"id":63650892},{"atl":[[3.2,8.89],[3.4,1]],"id":68274051}],"con":true,"img":false}]}
{"op":"mcm","clk":"11541244220","pt":1719503738996,"mc":[{"id":"1.230178323","rc":[{"atb":[[2.7,11.56]],"id":70681333},{"atb":[[2.8,11.19]],"id":47885365},{"atl":[[3.2,2.54],[3.25,12.69]],"id":68274051}],"con":true,"img":false}]}
{"op":"mcm","clk":"11541244232","pt":1719503739100,"mc":[{"id":"1.230178323","rc":[{"atb":[[1.75,8.02]],"id":68274051}],"con":true,"img":false}]}
{"op":"mcm","clk":"11541244243","pt":1719503739204,"mc":[{"id":"1.230178323","rc":[{"atb":[[2.68,0]],"id":70681333},{"atb":[[2.78,0]],"id":47885365},{"atb":[[3.15,6.63]],"id":60192591}],"con":true,"img":false}]}
{"op":"mcm","clk":"11541244252","pt":1719503739304,"mc":[{"id":"1.230178323","rc":[{"atb":[[1.72,0]],"id":68274051}],"con":true,"img":false}]}
{"op":"mcm","clk":"11541244259","pt":1719503739410,"mc":[{"id":"1.230178323","rc":[{"atl":[[3,9.41]],"id":51569790},{"atb":[[3.1,0]],"id":60192591}],"con":true,"img":false}]}
{"op":"mcm","clk":"11541244275","pt":1719503739612,"mc":[{"id":"1.230178323","rc":[{"atl":[[3.05,2.84]],"id":51569790}],"con":true,"img":false}]}
{"op":"mcm","clk":"11541244330","pt":1719503740231,"mc":[{"id":"1.230178323","rc":[{"atl":[[3.05,0]],"id":51569790}],"con":true,"img":false}]}
{"op":"mcm","clk":"11541244363","pt":1719503740489,"mc":[{"id":"1.230178323","rc":[{"atl":[[3.9,1]],"id":51569790}],"con":true,"img":false}]}
{"op":"mcm","clk":"11541244409","pt":1719503741006,"mc":[{"id":"1.230178323","rc":[{"atl":[[5.6,0],[5.1,2.5],[5.5,5],[6,0],[5.2,10]],"id":63650892}],"con":true,"img":false}]}
{"op":"mcm","clk":"11541244514","pt":1719503742293,"mc":[{"id":"1.230178323","rc":[{"atb":[[2.46,0],[2.62,1]],"id":47885365}],"con":true,"img":false}]}
{"op":"mcm","clk":"11541245057","pt":1719503747718,"mc":[{"id":"1.230178323","rc":[{"atl":[[3.15,4.62]],"id":68274051}],"con":true,"img":false}]}
{"op":"mcm","clk":"11541245076","pt":1719503747926,"mc":[{"id":"1.230178323","rc":[{"atl":[[3.25,7.19]],"id":68274051}],"con":true,"img":false}]}
{"op":"mcm","clk":"11541245083","pt":1719503748031,"mc":[{"id":"1.230178323","rc":[{"atb":[[2.66,0]],"id":70681333},{"atl":[[5.1,6.13]],"id":70681333},{"atb":[[2.32,0]],"id":63650892},{"atl":[[4.1,3.42]],"id":63650892},{"atb":[[1.77,0]],"id":51569790},{"atl":[[3.25,0]],"id":51569790}],"con":true,"img":false}]}
{"op":"mcm","clk":"11541245096","pt":1719503748135,"mc":[{"id":"1.230178323","rc":[{"atl":[[3.4,0],[3.9,26.32]],"id":51569790}],"con":true,"img":false}]}
{"op":"mcm","clk":"11541245122","pt":1719503748396,"mc":[{"id":"1.230178323","rc":[{"atl":[[3.25,6.35]],"id":68274051}],"con":true,"img":false}]}
{"op":"mcm","clk":"11541245234","pt":1719503749838,"mc":[{"id":"1.230178323","rc":[{"atl":[[3.2,0]],"id":68274051}],"con":true,"img":false}]}
{"op":"mcm","clk":"11541245242","pt":1719503749939,"mc":[{"id":"1.230178323","rc":[{"atl":[[3.4,11.98],[3.25,0]],"id":68274051}],"con":true,"img":false}]}
{"op":"mcm","clk":"11541245450","pt":1719503752116,"mc":[{"id":"1.230178323","rc":[{"atl":[[5.1,5.13],[5.2,1]],"id":70681333}],"con":true,"img":false}]}
{"op":"mcm","clk":"11541245464","pt":1719503752216,"mc":[{"id":"1.230178323","rc":[{"atl":[[7.2,5],[6.4,14.78]],"id":70681333}],"con":true,"img":false}]}
{"op":"mcm","clk":"11541245490","pt":1719503752420,"mc":[{"id":"1.230178323","rc":[{"atl":[[5.3,1],[5.2,0]],"id":70681333}],"con":true,"img":false}]}
{"op":"mcm","clk":"11541245502","pt":1719503752525,"mc":[{"id":"1.230178323","rc":[{"atl":[[6.4,2.5],[5.4,10]],"id":70681333}],"con":true,"img":false}]}
{"op":"mcm","clk":"11541245608","pt":1719503753616,"mc":[{"id":"1.230178323","rc":[{"atb":[[2.4,5.75]],"id":63650892}],"con":true,"img":false}]}
{"op":"mcm","clk":"11541245625","pt":1719503753821,"mc":[{"id":"1.230178323","rc":[{"atb":[[2.38,1.94]],"id":63650892}],"con":true,"img":false}]}
{"op":"mcm","clk":"11541245814","pt":1719503755627,"mc":[{"id":"1.230178323","rc":[{"atb":[[2.38,0]],"id":63650892}],"con":true,"img":false}]}
{"op":"mcm","clk":"11541245830","pt":1719503755833,"mc":[{"id":"1.230178323","rc":[{"atb":[[2.42,1.94]],"id":63650892}],"con":true,"img":false}]}
{"op":"mcm","clk":"11541245977","pt":1719503757327,"mc":[{"id":"1.230178323","rc":[{"atb":[[3.15,0]],"id":60192591},{"trd":[[3.15,13.27]],"ltp":3.15,"tv":13.27,"id":60192591}],"con":true,"img":false}]}
{"op":"mcm","clk":"11541245986","pt":1719503757532,"mc":[{"id":"1.230178323","rc":[{"atb":[[3.1,5.02]],"id":60192591},{"atl":[[6,3.34]],"id":60192591}],"con":true,"img":false}]}
{"op":"mcm","clk":"11541245996","pt":1719503757638,"mc":[{"id":"1.230178323","rc":[{"atl":[[6,5.96]],"id":60192591}],"con":true,"img":false}]}
{"op":"mcm","clk":"11541246007","pt":1719503757742,"mc":[{"id":"1.230178323","rc":[{"atl":[[6.2,0.84],[5.9,0.84]],"id":60192591}],"con":true,"img":false}]}
{"op":"mcm","clk":"11541246058","pt":1719503758205,"mc":[{"id":"1.230178323","rc":[{"atb":[[2.42,0]],"id":63650892}],"con":true,"img":false}]}
{"op":"mcm","clk":"11541246080","pt":1719503758416,"mc":[{"id":"1.230178323","rc":[{"atb":[[2.42,1.94]],"id":63650892}],"con":true,"img":false}]}
{"op":"mcm","clk":"11541246323","pt":1719503760839,"mc":[{"id":"1.230178323","rc":[{"atb":[[2.42,0]],"id":63650892}],"con":true,"img":false}]}
{"op":"mcm","clk":"11541246343","pt":1719503761042,"mc":[{"id":"1.230178323","rc":[{"atb":[[2.42,1.94]],"id":63650892}],"con":true,"img":false}]}
{"op":"mcm","clk":"11541246451","pt":1719503762132,"mc":[{"id":"1.230178323","rc":[{"atb":[[2.82,2.54]],"id":47885365},{"atb":[[1.85,2.54]],"id":51569790},{"atb":[[3.15,2.54]],"id":60192591}],"con":true,"img":false}]}
{"op":"mcm","clk":"11541246471","pt":1719503762336,"mc":[{"id":"1.230178323","rc":[{"atl":[[5.3,0],[5.4,11]],"id":70681333},{"atb":[[2.82,12.84]],"id":47885365},{"atb":[[1.85,8.57]],"id":51569790}],"con":true,"img":false}]}
{"op":"mcm","clk":"11541246505","pt":1719503762756,"mc":[{"id":"1.230178323","rc":[{"atb":[[2.8,1.94]],"id":47885365},{"atb":[[1.84,2]],"id":51569790}],"con":true,"img":false}]}
{"op":"mcm","clk":"11541246514","pt":1719503762858,"mc":[{"id":"1.230178323","rc":[{"atb":[[1.84,0]],"id":51569790}],"con":true,"img":false}]}
{"op":"mcm","clk":"11541246522","pt":1719503762963,"mc":[{"id":"1.230178323","rc":[{"atb":[[1.86,2]],"id":51569790}],"con":true,"img":false}]}
{"op":"mcm","clk":"11541246533","pt":1719503763067,"mc":[{"id":"1.230178323","rc":[{"atl":[[5.3,1]],"id":70681333}],"con":true,"img":false}]}
{"op":"mcm","clk":"11541246544","pt":1719503763170,"mc":[{"id":"1.230178323","rc":[{"atl":[[5.4,10]],"id":70681333}],"con":true,"img":false}]}
{"op":"mcm","clk":"11541246563","pt":1719503763378,"mc":[{"id":"1.230178323","rc":[{"atl":[[5.3,0],[5.4,11]],"id":70681333},{"atb":[[2.8,0]],"id":47885365},{"atb":[[2.42,0]],"id":63650892}],"con":true,"img":false}]}
{"op":"mcm","clk":"11541246574","pt":1719503763438,"mc":[{"id":"1.230178323","rc":[{"atl":[[6.4,18.64],[5.4,1]],"id":70681333},{"atb":[[2.84,1.94]],"id":47885365},{"atb":[[2.42,1.94]],"id":63650892}],"con":true,"img":false}]}
{"op":"mcm","clk":"11541246584","pt":1719503763534,"mc":[{"id":"1.230178323","rc":[{"atl":[[5.3,1]],"id":70681333}],"con":true,"img":false}]}
{"op":"mcm","clk":"11541246591","pt":1719503763640,"mc":[{"id":"1.230178323","rc":[{"atl":[[5.4,0]],"id":70681333}],"con":true,"img":false}]}
{"op":"mcm","clk":"11541246601","pt":1719503763743,"mc":[{"id":"1.230178323","rc":[{"atl":[[5.3,0]],"id":70681333}],"con":true,"img":false}]}
{"op":"mcm","clk":"11541246619","pt":1719503763951,"mc":[{"id":"1.230178323","rc":[{"atl":[[5.3,1]],"id":70681333}],"con":true,"img":false}]}
{"op":"mcm","clk":"11541246638","pt":1719503764155,"mc":[{"id":"1.230178323","rc":[{"atl":[[5.3,0],[5.4,1]],"id":70681333}],"con":true,"img":false}]}
{"op":"mcm","clk":"11541246658","pt":1719503764359,"mc":[{"id":"1.230178323","rc":[{"atl":[[5.3,1]],"id":70681333}],"con":true,"img":false}]}
{"op":"mcm","clk":"11541246668","pt":1719503764462,"mc":[{"id":"1.230178323","rc":[{"atl":[[5.4,0]],"id":70681333}],"con":true,"img":false}]}
{"op":"mcm","clk":"11541246678","pt":1719503764567,"mc":[{"id":"1.230178323","rc":[{"atb":[[1.85,6.03]],"id":51569790}],"con":true,"img":false}]}
{"op":"mcm","clk":"11541246741","pt":1719503765241,"mc":[{"id":"1.230178323","rc":[{"atl":[[5.9,1.37]],"id":60192591}],"con":true,"img":false}]}
{"op":"mcm","clk":"11541246795","pt":1719503765756,"mc":[{"id":"1.230178323","rc":[{"atb":[[2.82,10.3]],"id":47885365}],"con":true,"img":false}]}
{"op":"mcm","clk":"11541246857","pt":1719503766373,"mc":[{"id":"1.230178323","rc":[{"atb":[[2.84,0]],"id":47885365},{"atb":[[2.42,0]],"id":63650892}],"con":true,"img":false}]}
{"op":"mcm","clk":"11541246879","pt":1719503766535,"mc":[{"id":"1.230178323","rc":[{"atb":[[2.84,1.94]],"id":47885365},{"atb":[[2.42,1.94]],"id":63650892}],"con":true,"img":false}]}
{"op":"mcm","clk":"11541246930","pt":1719503767054,"mc":[{"id":"1.230178323","rc":[{"atl":[[5.3,0],[5.4,1]],"id":70681333}],"con":true,"img":false}]}
{"op":"mcm","clk":"11541247010","pt":1719503767865,"mc":[{"id":"1.230178323","rc":[{"atl":[[5.5,1],[5.4,0]],"id":70681333}],"con":true,"img":false}]}
{"op":"mcm","clk":"11541247047","pt":1719503768175,"mc":[{"id":"1.230178323","rc":[{"atl":[[5.5,0],[5.4,1]],"id":70681333}],"con":true,"img":false}]}
{"op":"mcm","clk":"11541247083","pt":1719503768541,"mc":[{"id":"1.230178323","rc":[{"atl":[[5.5,1],[5.4,0]],"id":70681333}],"con":true,"img":false}]}
{"op":"mcm","clk":"11541247097","pt":1719503768645,"mc":[{"id":"1.230178323","rc":[{"atb":[[1.08,50]],"id":70681333},{"atb":[[1.08,50]],"id":47885365},{"atb":[[1.08,50]],"id":63650892},{"atb":[[1.08,50]],"id":68274051},{"atb":[[1.08,50]],"id":51569790},{"atb":[[1.08,50]],"id":60192591}],"con":true,"img":false}]}
{"op":"mcm","clk":"11541247106","pt":1719503768748,"mc":[{"id":"1.230178323","rc":[{"atl":[[4.1,19.11]],"id":68274051},{"atl":[[5.8,2.33]],"id":60192591}],"con":true,"img":false}]}
{"op":"mcm","clk":"11541247117","pt":1719503768851,"mc":[{"id":"1.230178323","rc":[{"atb":[[2.42,5.69]],"id":63650892},{"atl":[[3.4,1]],"id":68274051}],"con":true,"img":false}]}
{"op":"mcm","clk":"11541247137","pt":1719503769058,"mc":[{"id":"1.230178323","rc":[{"atl":[[5.5,0],[5.4,1]],"id":70681333},{"atb":[[2.4,2]],"id":63650892}],"con":true,"img":false}]}
{"op":"mcm","clk":"11541247157","pt":1719503769264,"mc":[{"id":"1.230178323","rc":[{"atl":[[5.5,1],[5.4,0]],"id":70681333},{"atl":[[6.2,0],[5.7,0.84]],"id":60192591}],"con":true,"img":false}]}
{"op":"mcm","clk":"11541247162","pt":1719503769366,"mc":[{"id":"1.230178323","rc":[{"atb":[[2.84,0]],"id":47885365}],"con":true,"img":false}]}
{"op":"mcm","clk":"11541247172","pt":1719503769469,"mc":[{"id":"1.230178323","rc":[{"atb":[[2.54,0],[2.64,2.5],[2.62,0],[2.56,5],[2.46,0]],"id":70681333},{"atl":[[5.5,0],[5.4,1]],"id":70681333}],"con":true,"img":false}]}
{"op":"mcm","clk":"11541247183","pt":1719503769571,"mc":[{"id":"1.230178323","rc":[{"atb":[[2.82,0],[2.84,1.94]],"id":47885365}],"con":true,"img":false}]}
{"op":"mcm","clk":"11541247192","pt":1719503769676,"mc":[{"id":"1.230178323","rc":[{"atb":[[2.84,5.69]],"id":47885365}],"con":true,"img":false}]}
{"op":"mcm","clk":"11541247222","pt":1719503769934,"mc":[{"id":"1.230178323","rc":[{"atl":[[5.5,1],[5.4,0]],"id":70681333}],"con":true,"img":false}]}
{"op":"mcm","clk":"11541247238","pt":1719503770142,"mc":[{"id":"1.230178323","rc":[{"atb":[[2.4,0]],"id":63650892}],"con":true,"img":false}]}
{"op":"mcm","clk":"11541247251","pt":1719503770245,"mc":[{"id":"1.230178323","rc":[{"atb":[[2.44,2]],"id":63650892}],"con":true,"img":false}]}
{"op":"mcm","clk":"11541247468","pt":1719503772664,"mc":[{"id":"1.230178323","rc":[{"atb":[[3.15,6.16]],"id":60192591},{"atl":[[5.6,2.42]],"id":60192591}],"con":true,"img":false}]}
{"op":"mcm","clk":"11541247481","pt":1719503772767,"mc":[{"id":"1.230178323","rc":[{"atl":[[5.5,0],[5.4,1]],"id":70681333},{"atl":[[5.5,3.69]],"id":60192591}],"con":true,"img":false}]}
{"op":"mcm","clk":"11541247491","pt":1719503772870,"mc":[{"id":"1.230178323","rc":[{"atl":[[6.4,2.5],[5.5,10]],"id":70681333},{"atb":[[3.1,0]],"id":60192591},{"atl":[[6,2.62]],"id":60192591}],"con":true,"img":false}]}
{"op":"mcm","clk":"11541247502","pt":1719503772973,"mc":[{"id":"1.230178323","rc":[{"atl":[[5.5,11],[5.4,0]],"id":70681333},{"atl":[[6,0]],"id":60192591}],"con":true,"img":false}]}
{"op":"mcm","clk":"11541247534","pt":1719503773338,"mc":[{"id":"1.230178323","rc":[{"atl":[[5.5,10],[5.4,1]],"id":70681333},{"atl":[[5.9,0.52],[5.7,0]],"id":60192591}],"con":true,"img":false}]}
{"op":"mcm","clk":"11541247548","pt":1719503773540,"mc":[{"id":"1.230178323","rc":[{"atl":[[5.5,11],[5.4,0]],"id":70681333}],"con":true,"img":false}]}
{"op":"mcm","clk":"11541247555","pt":1719503773642,"mc":[{"id":"1.230178323","rc":[{"atl":[[6.4,18.64],[5.5,1]],"id":70681333}],"con":true,"img":false}]}
{"op":"mcm","clk":"11541247567","pt":1719503773746,"mc":[{"id":"1.230178323","rc":[{"atb":[[2.74,0],[2.76,13.9]],"id":47885365},{"atl":[[5.8,0]],"id":60192591}],"con":true,"img":false}]}
{"op":"mcm","clk":"11541247598","pt":1719503774157,"mc":[{"id":"1.230178323","rc":[{"atl":[[5.5,0],[5.4,1]],"id":70681333}],"con":true,"img":false}]}
{"op":"mcm","clk":"11541247606","pt":1719503774261,"mc":[{"id":"1.230178323","rc":[{"atl":[[6.4,2.5],[5.5,10.28]],"id":70681333}],"con":true,"img":false}]}
{"op":"mcm","clk":"11541247623","pt":1719503774466,"mc":[{"id":"1.230178323","rc":[{"atl":[[6.4,12.5],[5.5,0]],"id":70681333}],"con":true,"img":false}]}
{"op":"mcm","clk":"11541247646","pt":1719503774672,"mc":[{"id":"1.230178323","rc":[{"atl":[[5.5,1],[5.4,0]],"id":70681333}],"con":true,"img":false}]}
{"op":"mcm","clk":"11541247694","pt":1719503775144,"mc":[{"id":"1.230178323","rc":[{"atl":[[5.5,0],[5.4,1]],"id":70681333}],"con":true,"img":false}]}
{"op":"mcm","clk":"11541247721","pt":1719503775448,"mc":[{"id":"1.230178323","rc":[{"atl":[[5.5,1],[5.4,0]],"id":70681333}],"con":true,"img":false}]}
{"op":"mcm","clk":"11541247741","pt":1719503775655,"mc":[{"id":"1.230178323","rc":[{"atl":[[5.5,0],[5.4,1]],"id":70681333}],"con":true,"img":false}]}
{"op":"mcm","clk":"11541247756","pt":1719503775861,"mc":[{"id":"1.230178323","rc":[{"atl":[[5.5,1],[5.4,0]],"id":70681333}],"con":true,"img":false}]}
{"op":"mcm","clk":"11541247790","pt":1719503776275,"mc":[{"id":"1.230178323","rc":[{"atl":[[5.5,0],[5.4,1]],"id":70681333},{"atl":[[5.4,0.84]],"id":60192591}],"con":true,"img":false}]}
{"op":"mcm","clk":"11541247807","pt":1719503776480,"mc":[{"id":"1.230178323","rc":[{"atl":[[5.5,1],[5.4,0]],"id":70681333}],"con":true,"img":false}]}
{"op":"mcm","clk":"11541247821","pt":1719503776646,"mc":[{"id":"1.230178323","rc":[{"atl":[[5.5,0],[5.4,1]],"id":70681333}],"con":true,"img":false}]}
{"op":"mcm","clk":"11541247872","pt":1719503777458,"mc":[{"id":"1.230178323","rc":[{"atb":[[1.86,8.4]],"id":51569790}],"con":true,"img":false}]}
{"op":"mcm","clk":"11541247889","pt":1719503777665,"mc":[{"id":"1.230178323","rc":[{"atb":[[1.85,0]],"id":51569790}],"con":true,"img":false}]}
{"op":"mcm","clk":"11541248054","pt":1719503779366,"mc":[{"id":"1.230178323","rc":[{"atl":[[5.5,1],[5.4,0]],"id":70681333}],"con":true,"img":false}]}
{"op":"mcm","clk":"11541248096","pt":1719503779778,"mc":[{"id":"1.230178323","rc":[{"atl":[[5.5,0],[5.4,1]],"id":70681333}],"con":true,"img":false}]}
{"op":"mcm","clk":"11541248106","pt":1719503779882,"mc":[{"id":"1.230178323","rc":[{"atl":[[5.5,1],[5.4,0]],"id":70681333}],"con":true,"img":false}]}
{"op":"mcm","clk":"11541248166","pt":1719503780554,"mc":[{"id":"1.230178323","rc":[{"atl":[[5.9,0]],"id":60192591}],"con":true,"img":false}]}
{"op":"mcm","clk":"11541248206","pt":1719503780966,"mc":[{"id":"1.230178323","rc":[{"atl":[[5.5,0],[5.4,1]],"id":70681333},{"atl":[[5.4,1.37]],"id":60192591}],"con":true,"img":false}]}
{"op":"mcm","clk":"11541248261","pt":1719503781583,"mc":[{"id":"1.230178323","rc":[{"atl":[[5.5,1],[5.4,0]],"id":70681333}],"con":true,"img":false}]}
{"op":"mcm","clk":"11541248276","pt":1719503781686,"mc":[{"id":"1.230178323","rc":[{"atl":[[5.5,11]],"id":70681333}],"con":true,"img":false}]}
{"op":"mcm","clk":"11541248281","pt":1719503781743,"mc":[{"id":"1.230178323","rc":[{"atl":[[6.4,2.5],[5.5,10],[5.4,1]],"id":70681333}],"con":true,"img":false}]}
{"op":"mcm","clk":"11541248292","pt":1719503781950,"mc":[{"id":"1.230178323","rc":[{"atl":[[5.5,11],[5.4,0]],"id":70681333}],"con":true,"img":false}]}
{"op":"mcm","clk":"11541248338","pt":1719503782461,"mc":[{"id":"1.230178323","rc":[{"atl":[[3.35,1],[3.4,0]],"id":68274051},{"atl":[[3.85,1],[3.9,25.32]],"id":51569790}],"con":true,"img":false}]}
{"op":"mcm","clk":"11541248346","pt":1719503782563,"mc":[{"id":"1.230178323","rc":[{"atl":[[3.4,10]],"id":68274051}],"con":true,"img":false}]}
{"op":"mcm","clk":"11541248365","pt":1719503782668,"mc":[{"id":"1.230178323","rc":[{"atl":[[4.1,2.5]],"id":68274051}],"con":true,"img":false}]}
{"op":"mcm","clk":"11541248376","pt":1719503782770,"mc":[{"id":"1.230178323","rc":[{"spn":3.9,"spf":"NaN","id":70681333},{"spn":4.52,"spf":"NaN","id":47885365},{"atl":[[4.3,0],[4.1,4.42]],"id":63650892},{"spn":3.27,"spf":"NaN","id":63650892},{"atl":[[3.35,0],[3.3,1]],"id":68274051},{"spn":2.45,"spf":"NaN","id":68274051},{"spn":2.43,"spf":"NaN","id":51569790},{"atl":[[6.6,0]],"id":60192591},{"spn":4.27,"spf":"NaN","id":60192591}],"con":true,"img":false}]}
{"op":"mcm","clk":"11541248438","pt":1719503783289,"mc":[{"id":"1.230178323","rc":[{"atl":[[5.5,10],[5.4,1]],"id":70681333}],"con":true,"img":false}]}
{"op":"mcm","clk":"11541248459","pt":1719503783451,"mc":[{"id":"1.230178323","rc":[{"atl":[[5.5,11],[5.4,0]],"id":70681333}],"con":true,"img":false}]}
{"op":"mcm","clk":"11541248481","pt":1719503783660,"mc":[{"id":"1.230178323","rc":[{"atl":[[5.4,1]],"id":70681333},{"atl":[[5.3,2.33]],"id":60192591}],"con":true,"img":false}]}
{"op":"mcm","clk":"11541248492","pt":1719503783757,"mc":[{"id":"1.230178323","rc":[{"atl":[[5.5,10]],"id":70681333},{"atb":[[2.44,7.2]],"id":63650892}],"con":true,"img":false}]}
{"op":"mcm","clk":"11541248515","pt":1719503783964,"mc":[{"id":"1.230178323","rc":[{"atb":[[2.42,1.94]],"id":63650892}],"con":true,"img":false}]}
{"op":"mcm","clk":"11541248548","pt":1719503784274,"mc":[{"id":"1.230178323","rc":[{"atl":[[5.5,11]],"id":70681333}],"con":true,"img":false}]}
{"op":"mcm","clk":"11541248560","pt":1719503784375,"mc":[{"id":"1.230178323","rc":[{"atl":[[5.4,0]],"id":70681333},{"atl":[[5.2,0.84]],"id":60192591}],"con":true,"img":false}]}
{"op":"mcm","clk":"11541248573","pt":1719503784479,"mc":[{"id":"1.230178323","rc":[{"atb":[[2.42,0]],"id":63650892}],"con":true,"img":false}]}
{"op":"mcm","clk":"11541248591","pt":1719503784685,"mc":[{"id":"1.230178323","rc":[{"atb":[[2.46,1.94]],"id":63650892}],"con":true,"img":false}]}
{"op":"mcm","clk":"11541248713","pt":1719503785873,"mc":[{"id":"1.230178323","rc":[{"atl":[[5.5,10],[5.4,1]],"id":70681333}],"con":true,"img":false}]}
{"op":"mcm","clk":"11541248746","pt":1719503786185,"mc":[{"id":"1.230178323","rc":[{"atl":[[5.5,11],[5.4,0]],"id":70681333}],"con":true,"img":false}]}
{"op":"mcm","clk":"11541248810","pt":1719503786759,"mc":[{"id":"1.230178323","rc":[{"atl":[[5.5,10],[5.4,1]],"id":70681333}],"con":true,"img":false}]}
{"op":"mcm","clk":"11541248830","pt":1719503786965,"mc":[{"id":"1.230178323","rc":[{"atl":[[5.5,11],[5.4,0]],"id":70681333}],"con":true,"img":false}]}
{"op":"mcm","clk":"11541248856","pt":1719503787166,"mc":[{"id":"1.230178323","rc":[{"atl":[[5.5,10],[5.4,1]],"id":70681333}],"con":true,"img":false}]}
{"op":"mcm","clk":"11541248894","pt":1719503787475,"mc":[{"id":"1.230178323","rc":[{"atl":[[5.5,11],[5.4,0]],"id":70681333},{"atb":[[2.46,0]],"id":63650892}],"con":true,"img":false}]}
{"op":"mcm","clk":"11541248904","pt":1719503787579,"mc":[{"id":"1.230178323","rc":[{"atl":[[5.1,2.42]],"id":60192591}],"con":true,"img":false}]}
{"op":"mcm","clk":"11541248916","pt":1719503787682,"mc":[{"id":"1.230178323","rc":[{"atb":[[2.46,1.94]],"id":63650892},{"atl":[[5.3,5.95]],"id":60192591}],"con":true,"img":false}]}
{"op":"mcm","clk":"11541248929","pt":1719503787786,"mc":[{"id":"1.230178323","rc":[{"atl":[[5.5,10],[5.4,1]],"id":70681333},{"atl":[[5.6,0]],"id":60192591}],"con":true,"img":false}]}
{"op":"mcm","clk":"11541248942","pt":1719503787890,"mc":[{"id":"1.230178323","rc":[{"atl":[[5.5,0]],"id":60192591}],"con":true,"img":false}]}
{"op":"mcm","clk":"11541248953","pt":1719503787991,"mc":[{"id":"1.230178323","rc":[{"atl":[[5.5,11],[5.4,0]],"id":70681333}],"con":true,"img":false}]}
{"op":"mcm","clk":"11541248966","pt":1719503788095,"mc":[{"id":"1.230178323","rc":[{"atl":[[6.4,18.64]],"id":70681333}],"con":true,"img":false}]}
{"op":"mcm","clk":"11541248976","pt":1719503788155,"mc":[{"id":"1.230178323","rc":[{"atl":[[5.5,1]],"id":70681333}],"con":true,"img":false}]}
{"op":"mcm","clk":"11541248986","pt":1719503788259,"mc":[{"id":"1.230178323","rc":[{"atl":[[5.5,0],[5.4,1]],"id":70681333},{"atl":[[5.4,0.52]],"id":60192591}],"con":true,"img":false}]}
{"op":"mcm","clk":"11541249010","pt":1719503788460,"mc":[{"id":"1.230178323","rc":[{"atl":[[5.5,1],[5.4,0]],"id":70681333}],"con":true,"img":false}]}
{"op":"mcm","clk":"11541249031","pt":1719503788664,"mc":[{"id":"1.230178323","rc":[{"atl":[[5.5,0],[5.4,1]],"id":70681333}],"con":true,"img":false}]}
{"op":"mcm","clk":"11541249048","pt":1719503788869,"mc":[{"id":"1.230178323","rc":[{"atl":[[5.5,1],[5.4,0]],"id":70681333}],"con":true,"img":false}]}
{"op":"mcm","clk":"11541249058","pt":1719503788973,"mc":[{"id":"1.230178323","rc":[{"atb":[[2.72,2.54]],"id":70681333},{"atb":[[2.48,2.54]],"id":63650892}],"con":true,"img":false}]}
{"op":"mcm","clk":"11541249068","pt":1719503789075,"mc":[{"id":"1.230178323","rc":[{"atb":[[2.72,8.3]],"id":70681333},{"atl":[[5.3,3.62]],"id":60192591}],"con":true,"img":false}]}
{"op":"mcm","clk":"11541249076","pt":1719503789178,"mc":[{"id":"1.230178323","rc":[{"atl":[[5.5,0],[5.4,1]],"id":70681333}],"con":true,"img":false}]}
{"op":"mcm","clk":"11541249088","pt":1719503789281,"mc":[{"id":"1.230178323","rc":[{"atb":[[2.7,3.94]],"id":70681333}],"con":true,"img":false}]}
{"op":"mcm","clk":"11541249109","pt":1719503789486,"mc":[{"id":"1.230178323","rc":[{"atl":[[5.5,1],[5.4,0]],"id":70681333}],"con":true,"img":false}]}
{"op":"mcm","clk":"11541249139","pt":1719503789795,"mc":[{"id":"1.230178323","rc":[{"atb":[[2.7,1.94]],"id":70681333}],"con":true,"img":false}]}
{"op":"mcm","clk":"11541249148","pt":1719503789898,"mc":[{"id":"1.230178323","rc":[{"atb":[[2.74,2]],"id":70681333},{"atl":[[5.5,0],[5.4,1]],"id":70681333}],"con":true,"img":false}]}
{"op":"mcm","clk":"11541249178","pt":1719503790166,"mc":[{"id":"1.230178323","rc":[{"atb":[[2.44,5.2]],"id":63650892}],"con":true,"img":false}]}
{"op":"mcm","clk":"11541249188","pt":1719503790266,"mc":[{"id":"1.230178323","rc":[{"atb":[[2.5,2]],"id":63650892}],"con":true,"img":false}]}
{"op":"mcm","clk":"11541249198","pt":1719503790366,"mc":[{"id":"1.230178323","rc":[{"atl":[[5.5,1],[5.4,0]],"id":70681333}],"con":true,"img":false}]}
{"op":"mcm","clk":"11541249209","pt":1719503790467,"mc":[{"id":"1.230178323","rc":[{"atb":[[2.7,0]],"id":70681333},{"atb":[[2.46,0]],"id":63650892}],"con":true,"img":false}]}
{"op":"mcm","clk":"11541249220","pt":1719503790571,"mc":[{"id":"1.230178323","rc":[{"atl":[[5.5,0],[5.4,1]],"id":70681333}],"con":true,"img":false}]}
{"op":"mcm","clk":"11541249237","pt":1719503790776,"mc":[{"id":"1.230178323","rc":[{"atb":[[2.74,3.94]],"id":70681333},{"atb":[[2.5,3.94]],"id":63650892}],"con":true,"img":false}]}
{"op":"mcm","clk":"11541249252","pt":1719503790985,"mc":[{"id":"1.230178323","rc":[{"atl":[[4.1,2.5],[4.2,0]],"id":51569790}],"con":true,"img":false}]}
{"op":"mcm","clk":"11541249261","pt":1719503791089,"mc":[{"id":"1.230178323","rc":[{"atb":[[2.68,4.39]],"id":70681333}],"con":true,"img":false}]}
{"op":"mcm","clk":"11541249284","pt":1719503791295,"mc":[{"id":"1.230178323","rc":[{"atb":[[2.68,0]],"id":70681333}],"con":true,"img":false}]}
{"op":"mcm","clk":"11541249308","pt":1719503791502,"mc":[{"id":"1.230178323","rc":[{"atb":[[2.72,5.76]],"id":70681333},{"atb":[[2.48,0]],"id":63650892}],"con":true,"img":false}]}
{"op":"mcm","clk":"11541249329","pt":1719503791669,"mc":[{"id":"1.230178323","rc":[{"atl":[[5.5,1],[5.4,0]],"id":70681333}],"con":true,"img":false}]}
{"op":"mcm","clk":"11541249339","pt":1719503791769,"mc":[{"id":"1.230178323","rc":[{"atl":[[5,0.84]],"id":60192591}],"con":true,"img":false}]}
{"op":"mcm","clk":"11541249355","pt":1719503791969,"mc":[{"id":"1.230178323","rc":[{"atl":[[5.5,0],[5.4,1]],"id":70681333}],"con":true,"img":false}]}
{"op":"mcm","clk":"11541249369","pt":1719503792177,"mc":[{"id":"1.230178323","rc":[{"atb":[[2.5,1.94]],"id":63650892}],"con":true,"img":false}]}
{"op":"mcm","clk":"11541249378","pt":1719503792283,"mc":[{"id":"1.230178323","rc":[{"atb":[[2.46,2]],"id":63650892}],"con":true,"img":false}]}
{"op":"mcm","clk":"11541249399","pt":1719503792486,"mc":[{"id":"1.230178323","rc":[{"atl":[[5.5,1],[5.4,0]],"id":70681333}],"con":true,"img":false}]}
{"op":"mcm","clk":"11541249431","pt":1719503792798,"mc":[{"id":"1.230178323","rc":[{"atl":[[5.5,0],[5.4,1]],"id":70681333}],"con":true,"img":false}]}
{"op":"mcm","clk":"11541249456","pt":1719503793005,"mc":[{"id":"1.230178323","rc":[{"atl":[[4,2.5]],"id":68274051}],"con":true,"img":false}]}
{"op":"mcm","clk":"11541249471","pt":1719503793108,"mc":[{"id":"1.230178323","rc":[{"atl":[[4.5,0],[4.1,0],[4.9,0]],"id":68274051}],"con":true,"img":false}]}
{"op":"mcm","clk":"11541249476","pt":1719503793161,"mc":[{"id":"1.230178323","rc":[{"atl":[[5.3,1],[5.4,0]],"id":70681333},{"atb":[[2.6,0],[2.62,11],[2.78,2.5],[2.68,0],[2.76,11.4],[2.7,5]],"id":47885365}],"con":true,"img":false}]}
{"op":"mcm","clk":"11541249489","pt":1719503793273,"mc":[{"id":"1.230178323","rc":[{"atl":[[5.3,0],[5.4,1]],"id":70681333}],"con":true,"img":false}]}
{"op":"mcm","clk":"11541249528","pt":1719503793590,"mc":[{"id":"1.230178323","rc":[{"atb":[[2.5,0]],"id":63650892}],"con":true,"img":false}]}
{"op":"mcm","clk":"11541249547","pt":1719503793784,"mc":[{"id":"1.230178323","rc":[{"atb":[[2.46,3.94]],"id":63650892}],"con":true,"img":false}]}
{"op":"mcm","clk":"11541249671","pt":1719503795083,"mc":[{"id":"1.230178323","rc":[{"spl":[[1.01,1]],"id":63650892}],"con":true,"img":false}]}
{"op":"mcm","clk":"11541249716","pt":1719503795597,"mc":[{"id":"1.230178323","rc":[{"atl":[[5.5,1]],"id":70681333}],"con":true,"img":false}]}
{"op":"mcm","clk":"11541249726","pt":1719503795701,"mc":[{"id":"1.230178323","rc":[{"atl":[[6.4,2.5],[5.5,7.14],[5.4,0]],"id":70681333}],"con":true,"img":false}]}
{"op":"mcm","clk":"11541249782","pt":1719503796273,"mc":[{"id":"1.230178323","rc":[{"atl":[[5.4,0]],"id":60192591}],"con":true,"img":false}]}
{"op":"mcm","clk":"11541249979","pt":1719503798384,"mc":[{"id":"1.230178323","rc":[{"atb":[[2.46,10.22]],"id":63650892}],"con":true,"img":false}]}
{"op":"mcm","clk":"11541249989","pt":1719503798488,"mc":[{"id":"1.230178323","rc":[{"atb":[[2.44,0]],"id":63650892}],"con":true,"img":false}]}
{"op":"mcm","clk":"11541250013","pt":1719503798693,"mc":[{"id":"1.230178323","rc":[{"atb":[[1.86,6.4]],"id":51569790},{"trd":[[1.86,4]],"ltp":1.86,"tv":4.0,"id":51569790}],"con":true,"img":false}]}
{"op":"mcm","clk":"11541250031","pt":1719503798898,"mc":[{"id":"1.230178323","rc":[{"atb":[[1.86,0]],"id":51569790},{"atl":[[1.86,2]],"id":51569790}],"con":true,"img":false}]}
{"op":"mcm","clk":"11541250041","pt":1719503799002,"mc":[{"id":"1.230178323","rc":[{"atb":[[1.79,0],[1.85,3.09],[1.78,7.2]],"id":51569790},{"atl":[[1.86,0],[3.9,0],[3.3,11.42]],"id":51569790},{"trd":[[1.86,8]],"ltp":1.86,"tv":8.0,"id":51569790}],"con":true,"img":false}]}
{"op":"mcm","clk":"11541250063","pt":1719503799208,"mc":[{"id":"1.230178323","rc":[{"atl":[[3.85,21.84],[2.98,2],[3.3,0]],"id":51569790}],"con":true,"img":false}]}
{"op":"mcm","clk":"11541250074","pt":1719503799310,"mc":[{"id":"1.230178323","rc":[{"atl":[[3.85,1],[2.98,9.72],[3.3,18.84]],"id":51569790}],"con":true,"img":false}]}
{"op":"mcm","clk":"11541250083","pt":1719503799417,"mc":[{"id":"1.230178323","rc":[{"atl":[[3,0.84]],"id":51569790}],"con":true,"img":false}]}
{"op":"mcm","clk":"11541250124","pt":1719503799780,"mc":[{"id":"1.230178323","rc":[{"atl":[[2.96,0.84]],"id":51569790}],"con":true,"img":false}]}
{"op":"mcm","clk":"11541250131","pt":1719503799882,"mc":[{"id":"1.230178323","rc":[{"atb":[[2.76,2.54]],"id":70681333},{"atb":[[2.86,2.54]],"id":47885365}],"con":true,"img":false}]}
{"op":"mcm","clk":"11541250142","pt":1719503799983,"mc":[{"id":"1.230178323","rc":[{"atl":[[6.4,14.78]],"id":70681333},{"atb":[[2.86,8.72]],"id":47885365}],"con":true,"img":false}]}
{"op":"mcm","clk":"11541250153","pt":1719503800086,"mc":[{"id":"1.230178323","rc":[{"atl":[[5.5,1]],"id":70681333}],"con":true,"img":false}]}
{"op":"mcm","clk":"11541250167","pt":1719503800189,"mc":[{"id":"1.230178323","rc":[{"atb":[[2.84,1.94]],"id":47885365}],"con":true,"img":false}]}
{"op":"mcm","clk":"11541250200","pt":1719503800500,"mc":[{"id":"1.230178323","rc":[{"atb":[[2.74,1.94]],"id":70681333}],"con":true,"img":false}]}
{"op":"mcm","clk":"11541250213","pt":1719503800604,"mc":[{"id":"1.230178323","rc":[{"atb":[[2.78,2]],"id":70681333}],"con":true,"img":false}]}
{"op":"mcm","clk":"11541250350","pt":1719503801996,"mc":[{"id":"1.230178323","rc":[{"atl":[[5.6,1],[5.5,0]],"id":70681333}],"con":true,"img":false}]}
{"op":"mcm","clk":"11541250369","pt":1719503802202,"mc":[{"id":"1.230178323","rc":[{"atl":[[4.9,2.46]],"id":60192591}],"con":true,"img":false}]}
{"op":"mcm","clk":"11541250379","pt":1719503802306,"mc":[{"id":"1.230178323","rc":[{"atl":[[5.1,3.69]],"id":60192591}],"con":true,"img":false}]}
{"op":"mcm","clk":"11541250384","pt":1719503802409,"mc":[{"id":"1.230178323","rc":[{"atb":[[2.76,0]],"id":70681333}],"con":true,"img":false}]}
{"op":"mcm","clk":"11541250392","pt":1719503802512,"mc":[{"id":"1.230178323","rc":[{"atl":[[5.3,0]],"id":60192591}],"con":true,"img":false}]}
{"op":"mcm","clk":"11541250433","pt":1719503802777,"mc":[{"id":"1.230178323","rc":[{"atl":[[4.8,0.84],[5.2,0]],"id":60192591}],"con":true,"img":false}]}
{"op":"mcm","clk":"11541250515","pt":1719503803705,"mc":[{"id":"1.230178323","rc":[{"atb":[[2.78,5.36]],"id":70681333}],"con":true,"img":false}]}
{"op":"mcm","clk":"11541250523","pt":1719503803806,"mc":[{"id":"1.230178323","rc":[{"atb":[[2.74,3.94]],"id":70681333}],"con":true,"img":false}]}
{"op":"mcm","clk":"11541250532","pt":1719503803909,"mc":[{"id":"1.230178323","rc":[{"atb":[[2.72,0]],"id":70681333}],"con":true,"img":false}]}
{"op":"mcm","clk":"11541250539","pt":1719503804013,"mc":[{"id":"1.230178323","rc":[{"atb":[[2.78,0]],"id":70681333}],"con":true,"img":false}]}
{"op":"mcm","clk":"11541250545","pt":1719503804115,"mc":[{"id":"1.230178323","rc":[{"atb":[[2.76,6.82]],"id":70681333}],"con":true,"img":false}]}
{"op":"mcm","clk":"11541250554","pt":1719503804175,"mc":[{"id":"1.230178323","rc":[{"atl":[[3.35,1],[3.3,0]],"id":68274051}],"con":true,"img":false}]}
{"op":"mcm","clk":"11541250567","pt":1719503804279,"mc":[{"id":"1.230178323","rc":[{"atl":[[4.1,3.42],[4.2,1]],"id":63650892},{"atl":[[3.3,9.26]],"id":68274051}],"con":true,"img":false}]}
{"op":"mcm","clk":"11541250578","pt":1719503804381,"mc":[{"id":"1.230178323","rc":[{"atl":[[3.35,10.26],[3.4,0],[3.3,0]],"id":68274051}],"con":true,"img":false}]}
{"op":"mcm","clk":"11541250588","pt":1719503804502,"mc":[{"id":"1.230178323","rc":[{"atb":[[2.74,1.94]],"id":70681333}],"con":true,"img":false}]}
{"op":"mcm","clk":"11541250600","pt":1719503804588,"mc":[{"id":"1.230178323","rc":[{"atb":[[2.78,2]],"id":70681333}],"con":true,"img":false}]}
{"op":"mcm","clk":"11541250657","pt":1719503805098,"mc":[{"id":"1.230178323","rc":[{"atb":[[2.8,2.54]],"id":70681333}],"con":true,"img":false}]}
{"op":"mcm","clk":"11541250725","pt":1719503805720,"mc":[{"id":"1.230178323","rc":[{"atb":[[2.78,0]],"id":70681333},{"atb":[[3.15,0]],"id":60192591},{"trd":[[3.15,25.59]],"ltp":3.15,"tv":25.59,"id":60192591}],"con":true,"img":false}]}
{"op":"mcm","clk":"11541250735","pt":1719503805824,"mc":[{"id":"1.230178323","rc":[{"atb":[[2.82,2]],"id":70681333},{"atb":[[3.2,3.72]],"id":60192591}],"con":true,"img":false}]}
{"op":"mcm","clk":"11541250755","pt":1719503805988,"mc":[{"id":"1.230178323","rc":[{"atb":[[3.2,0],[1.09,1.5]],"id":60192591}],"con":true,"img":false}]}
{"op":"mcm","clk":"11541250763","pt":1719503806087,"mc":[{"id":"1.230178323","rc":[{"atb":[[3.1,2.48]],"id":60192591}],"con":true,"img":false}]}
{"op":"mcm","clk":"11541250878","pt":1719503807420,"mc":[{"id":"1.230178323","rc":[{"atl":[[2.96,1.37]],"id":51569790},{"atl":[[4.8,1.37]],"id":60192591}],"con":true,"img":false}]}
{"op":"mcm","clk":"11541250888","pt":1719503807524,"mc":[{"id":"1.230178323","rc":[{"atb":[[1.86,0.61]],"id":51569790}],"con":true,"img":false}]}
{"op":"mcm","clk":"11541250895","pt":1719503807578,"mc":[{"id":"1.230178323","rc":[{"atb":[[1.05,0.52]],"id":60192591}],"con":true,"img":false}]}
{"op":"mcm","clk":"11541250908","pt":1719503807682,"mc":[{"id":"1.230178323","rc":[{"atb":[[2.8,0]],"id":70681333}],"con":true,"img":false}]}
{"op":"mcm","clk":"11541250922","pt":1719503807890,"mc":[{"id":"1.230178323","rc":[{"atb":[[1.05,0.24]],"id":60192591}],"con":true,"img":false}]}
{"op":"mcm","clk":"11541250942","pt":1719503808090,"mc":[{"id":"1.230178323","rc":[{"atb":[[1.05,0]],"id":60192591}],"con":true,"img":false}]}
{"op":"mcm","clk":"11541250949","pt":1719503808194,"mc":[{"id":"1.230178323","rc":[{"atb":[[3.15,0.24]],"id":60192591}],"con":true,"img":false}]}
{"op":"mcm","clk":"11541250959","pt":1719503808295,"mc":[{"id":"1.230178323","rc":[{"atb":[[2.82,0]],"id":70681333}],"con":true,"img":false}]}
{"op":"mcm","clk":"11541250968","pt":1719503808401,"mc":[{"id":"1.230178323","rc":[{"atb":[[2.78,2]],"id":70681333}],"con":true,"img":false}]}
{"op":"mcm","clk":"11541250991","pt":1719503808607,"mc":[{"id":"1.230178323","rc":[{"atb":[[2.74,0]],"id":70681333},{"atb":[[2.84,0]],"id":47885365}],"con":true,"img":false}]}
{"op":"mcm","clk":"11541251001","pt":1719503808707,"mc":[{"id":"1.230178323","rc":[{"atb":[[2.78,3.94]],"id":70681333},{"atb":[[2.88,1.94]],"id":47885365}],"con":true,"img":false}]}
{"op":"mcm","clk":"11541251093","pt":1719503809529,"mc":[{"id":"1.230178323","rc":[{"atl":[[4,17.39],[3.35,1]],"id":68274051}],"con":true,"img":false}]}
{"op":"mcm","clk":"11541251142","pt":1719503810098,"mc":[{"id":"1.230178323","rc":[{"atb":[[2.8,2.54]],"id":70681333},{"atl":[[7.2,15.89],[7.8,1]],"id":47885365},{"atl":[[4.4,1]],"id":63650892},{"atl":[[3.6,1],[3.35,0]],"id":68274051}],"con":true,"img":false}]}
{"op":"mcm","clk":"11541251153","pt":1719503810200,"mc":[{"id":"1.230178323","rc":[{"atl":[[4.3,4.43],[5.2,0],[4.2,0]],"id":63650892}],"con":true,"img":false}]}
{"op":"mcm","clk":"11541251163","pt":1719503810302,"mc":[{"id":"1.230178323","rc":[{"atl":[[3,2.76]],"id":51569790}],"con":true,"img":false}]}
{"op":"mcm","clk":"11541251210","pt":1719503810817,"mc":[{"id":"1.230178323","rc":[{"atl":[[3,0.84]],"id":51569790}],"con":true,"img":false}]}
{"op":"mcm","clk":"11541251238","pt":1719503811128,"mc":[{"id":"1.230178323","rc":[{"atb":[[2.78,1.94]],"id":70681333},{"atl":[[4,2.5],[3.6,10.26]],"id":68274051},{"atl":[[3,2.76]],"id":51569790}],"con":true,"img":false}]}
{"op":"mcm","clk":"11541251251","pt":1719503811230,"mc":[{"id":"1.230178323","rc":[{"atb":[[2.82,2]],"id":70681333},{"atl":[[4,17.39],[3.6,1]],"id":68274051}],"con":true,"img":false}]}
{"op":"mcm","clk":"11541251271","pt":1719503811396,"mc":[{"id":"1.230178323","rc":[{"atb":[[2.86,6.18]],"id":47885365}],"con":true,"img":false}]}
{"op":"mcm","clk":"11541251296","pt":1719503811597,"mc":[{"id":"1.230178323","rc":[{"atl":[[3,0.84]],"id":51569790}],"con":true,"img":false}]}
{"op":"mcm","clk":"11541251310","pt":1719503811701,"mc":[{"id":"1.230178323","rc":[{"atb":[[2.78,0]],"id":70681333},{"atb":[[2.88,0]],"id":47885365}],"con":true,"img":false}]}
{"op":"mcm","clk":"11541251336","pt":1719503811907,"mc":[{"id":"1.230178323","rc":[{"atb":[[2.82,3.94]],"id":70681333},{"atb":[[2.88,1.94]],"id":47885365},{"atl":[[2.98,11.2]],"id":51569790}],"con":true,"img":false}]}
{"op":"mcm","clk":"11541251354","pt":1719503812114,"mc":[{"id":"1.230178323","rc":[{"atl":[[2.98,9.72]],"id":51569790}],"con":true,"img":false}]}
{"op":"mcm","clk":"11541251391","pt":1719503812425,"mc":[{"id":"1.230178323","rc":[{"atl":[[4.7,2]],"id":60192591}],"con":true,"img":false}]}
{"op":"mcm","clk":"11541251415","pt":1719503812628,"mc":[{"id":"1.230178323","rc":[{"atb":[[2.9,2.54]],"id":47885365}],"con":true,"img":false}]}
{"op":"mcm","clk":"11541251425","pt":1719503812731,"mc":[{"id":"1.230178323","rc":[{"atb":[[2.8,0]],"id":70681333},{"atl":[[4.6,0.84]],"id":60192591}],"con":true,"img":false}]}
{"op":"mcm","clk":"11541251446","pt":1719503812894,"mc":[{"id":"1.230178323","rc":[{"atl":[[5,0]],"id":60192591}],"con":true,"img":false}]}
{"op":"mcm","clk":"11541251517","pt":1719503813506,"mc":[{"id":"1.230178323","rc":[{"atl":[[2.94,1.74]],"id":51569790}],"con":true,"img":false}]}
{"op":"mcm","clk":"11541251528","pt":1719503813611,"mc":[{"id":"1.230178323","rc":[{"atl":[[2.96,3.99]],"id":51569790}],"con":true,"img":false}]}
{"op":"mcm","clk":"11541251541","pt":1719503813712,"mc":[{"id":"1.230178323","rc":[{"atl":[[2.98,0]],"id":51569790}],"con":true,"img":false}]}
{"op":"mcm","clk":"11541251551","pt":1719503813815,"mc":[{"id":"1.230178323","rc":[{"atl":[[2.92,0.84],[3,0]],"id":51569790}],"con":true,"img":false}]}
{"op":"mcm","clk":"11541251570","pt":1719503814023,"mc":[{"id":"1.230178323","rc":[{"atb":[[2.82,1.94]],"id":70681333}],"con":true,"img":false}]}
{"op":"mcm","clk":"11541251581","pt":1719503814124,"mc":[{"id":"1.230178323","rc":[{"atb":[[2.78,2]],"id":70681333}],"con":true,"img":false}]}
{"op":"mcm","clk":"11541251598","pt":1719503814329,"mc":[{"id":"1.230178323","rc":[{"atb":[[2.9,9.08]],"id":47885365}],"con":true,"img":false}]}
{"op":"mcm","clk":"11541251621","pt":1719503814534,"mc":[{"id":"1.230178323","rc":[{"atb":[[2.86,0]],"id":47885365}],"con":true,"img":false}]}
{"op":"mcm","clk":"11541251635","pt":1719503814637,"mc":[{"id":"1.230178323","rc":[{"atb":[[2.92,0.84]],"id":47885365}],"con":true,"img":false}]}
{"op":"mcm","clk":"11541251648","pt":1719503814741,"mc":[{"id":"1.230178323","rc":[{"atb":[[2.82,0]],"id":70681333},{"atb":[[2.88,0]],"id":47885365}],"con":true,"img":false}]}
{"op":"mcm","clk":"11541251661","pt":1719503814800,"mc":[{"id":"1.230178323","rc":[{"atb":[[2.84,2.54]],"id":70681333}],"con":true,"img":false}]}
{"op":"mcm","clk":"11541251670","pt":1719503814898,"mc":[{"id":"1.230178323","rc":[{"atb":[[2.78,3.94]],"id":70681333},{"atb":[[2.92,2.79]],"id":47885365}],"con":true,"img":false}]}
{"op":"mcm","clk":"11541251757","pt":1719503815723,"mc":[{"id":"1.230178323","rc":[{"atb":[[2.78,1.94]],"id":70681333}],"con":true,"img":false}]}
{"op":"mcm","clk":"11541251766","pt":1719503815829,"mc":[{"id":"1.230178323","rc":[{"atb":[[2.86,2]],"id":70681333}],"con":true,"img":false}]}
{"op":"mcm","clk":"11541251792","pt":1719503816137,"mc":[{"id":"1.230178323","rc":[{"atb":[[2.92,1.94],[2.9,6.54]],"id":47885365}],"con":true,"img":false}]}
{"op":"mcm","clk":"11541251829","pt":1719503816603,"mc":[{"id":"1.230178323","rc":[{"atl":[[4.7,4.53]],"id":60192591}],"con":true,"img":false}]}
{"op":"mcm","clk":"11541251844","pt":1719503816707,"mc":[{"id":"1.230178323","rc":[{"atl":[[5.1,0]],"id":60192591}],"con":true,"img":false}]}
{"op":"mcm","clk":"11541251881","pt":1719503817220,"mc":[{"id":"1.230178323","rc":[{"atb":[[2.88,2.54]],"id":70681333},{"atb":[[3.15,0]],"id":60192591},{"trd":[[3.15,26.09]],"ltp":3.15,"tv":26.09,"id":60192591}],"con":true,"img":false}]}
{"op":"mcm","clk":"11541251923","pt":1719503817732,"mc":[{"id":"1.230178323","rc":[{"atb":[[2.78,0]],"id":70681333},{"atb":[[2.92,0]],"id":47885365}],"con":true,"img":false}]}
{"op":"mcm","clk":"11541251937","pt":1719503817938,"mc":[{"id":"1.230178323","rc":[{"atb":[[2.88,6.35],[2.9,1.94]],"id":70681333},{"atb":[[2.92,1.94],[2.9,0]],"id":47885365}],"con":true,"img":false}]}
{"op":"mcm","clk":"11541251947","pt":1719503818042,"mc":[{"id":"1.230178323","rc":[{"atb":[[2.86,0]],"id":70681333}],"con":true,"img":false}]}
{"op":"mcm","clk":"11541251957","pt":1719503818098,"mc":[{"id":"1.230178323","rc":[{"atb":[[2.76,0],[2.9,3.94]],"id":70681333},{"atb":[[2.88,13.46]],"id":47885365}],"con":true,"img":false}]}
{"op":"mcm","clk":"11541251974","pt":1719503818301,"mc":[{"id":"1.230178323","rc":[{"atb":[[2.9,10.76]],"id":70681333}],"con":true,"img":false}]}
{"op":"mcm","clk":"11541251993","pt":1719503818506,"mc":[{"id":"1.230178323","rc":[{"atb":[[2.88,2.54],[2.84,0]],"id":70681333}],"con":true,"img":false}]}
{"op":"mcm","clk":"11541252004","pt":1719503818608,"mc":[{"id":"1.230178323","rc":[{"atb":[[2.9,1.6]],"id":47885365}],"con":true,"img":false}]}
{"op":"mcm","clk":"11541252028","pt":1719503818914,"mc":[{"id":"1.230178323","rc":[{"atb":[[2.9,2.45]],"id":47885365}],"con":true,"img":false}]}
{"op":"mcm","clk":"11541252094","pt":1719503819641,"mc":[{"id":"1.230178323","rc":[{"atl":[[2.92,3.38]],"id":51569790}],"con":true,"img":false}]}
{"op":"mcm","clk":"11541252108","pt":1719503819741,"mc":[{"id":"1.230178323","rc":[{"atb":[[2.88,0]],"id":70681333}],"con":true,"img":false}]}
{"op":"mcm","clk":"11541252158","pt":1719503820206,"mc":[{"id":"1.230178323","rc":[{"atl":[[2.96,3.14]],"id":51569790}],"con":true,"img":false}]}
{"op":"mcm","clk":"11541252182","pt":1719503820413,"mc":[{"id":"1.230178323","rc":[{"atb":[[2.9,1.87]],"id":47885365}],"con":true,"img":false}]}
{"op":"mcm","clk":"11541252193","pt":1719503820516,"mc":[{"id":"1.230178323","rc":[{"atl":[[3.05,9.26]],"id":51569790}],"con":true,"img":false}]}
{"op":"mcm","clk":"11541252210","pt":1719503820721,"mc":[{"id":"1.230178323","rc":[{"atl":[[3.05,0]],"id":51569790}],"con":true,"img":false}]}
{"op":"mcm","clk":"11541252224","pt":1719503820826,"mc":[{"id":"1.230178323","rc":[{"atb":[[2.94,2.54]],"id":47885365}],"con":true,"img":false}]}
{"op":"mcm","clk":"11541252236","pt":1719503820931,"mc":[{"id":"1.230178323","rc":[{"atl":[[3,2.76]],"id":51569790}],"con":true,"img":false}]}
{"op":"mcm","clk":"11541252247","pt":1719503821032,"mc":[{"id":"1.230178323","rc":[{"atb":[[2.92,0]],"id":47885365}],"con":true,"img":false}]}
{"op":"mcm","clk":"11541252258","pt":1719503821134,"mc":[{"id":"1.230178323","rc":[{"atl":[[3,0]],"id":51569790}],"con":true,"img":false}]}
{"op":"mcm","clk":"11541252270","pt":1719503821237,"mc":[{"id":"1.230178323","rc":[{"atb":[[2.9,3.81]],"id":47885365}],"con":true,"img":false}]}
{"op":"mcm","clk":"11541252309","pt":1719503821546,"mc":[{"id":"1.230178323","rc":[{"atl":[[2.98,10.34]],"id":51569790},{"atb":[[2.62,1],[2.46,0]],"id":60192591}],"con":true,"img":false}]}
{"op":"mcm","clk":"11541252447","pt":1719503822835,"mc":[{"id":"1.230178323","rc":[{"atb":[[1.86,0]],"id":51569790}],"con":true,"img":false}]}
{"op":"mcm","clk":"11541252460","pt":1719503822938,"mc":[{"id":"1.230178323","rc":[{"atl":[[5.6,0],[5.7,1]],"id":70681333}],"con":true,"img":false}]}
{"op":"mcm","clk":"11541252469","pt":1719503823042,"mc":[{"id":"1.230178323","rc":[{"atl":[[6.4,2.5],[5.7,11]],"id":70681333},{"atl":[[2.96,2.62]],"id":51569790}],"con":true,"img":false}]}
{"op":"mcm","clk":"11541252478","pt":1719503823143,"mc":[{"id":"1.230178323","rc":[{"atl":[[6.4,12.5],[5.7,1],[1000,6.81]],"id":70681333},{"atb":[[1.02,24.36]],"id":63650892},{"atl":[[1000,1.87]],"id":63650892},{"atb":[[1.01,47.02]],"id":51569790},{"atl":[[1000,1.7]],"id":51569790}],"con":true,"img":false}]}
{"op":"mcm","clk":"11541252486","pt":1719503823203,"mc":[{"id":"1.230178323","rc":[{"atb":[[1.03,6.81]],"id":70681333},{"atl":[[4.3,0],[4.4,8.86]],"id":63650892},{"atl":[[4.8,0.84]],"id":60192591}],"con":true,"img":false}]}
{"op":"mcm","clk":"11541252495","pt":1719503823303,"mc":[{"id":"1.230178323","rc":[{"atl":[[1000,0.18]],"id":70681333},{"atb":[[1.02,22.85]],"id":63650892},{"atl":[[5.1,14.79],[4.4,1],[1000,0.26]],"id":63650892},{"atb":[[1.01,45.64]],"id":51569790},{"atl":[[1000,0.14]],"id":51569790}],"con":true,"img":false}]}
{"op":"mcm","clk":"11541252503","pt":1719503823408,"mc":[{"id":"1.230178323","rc":[{"atb":[[1.03,0.39]],"id":70681333},{"atl":[[2.9,0.52]],"id":51569790}],"con":true,"img":false}]}
{"op":"mcm","clk":"11541252510","pt":1719503823510,"mc":[{"id":"1.230178323","rc":[{"atl":[[1000,0.04]],"id":70681333},{"atl":[[1000,0.16]],"id":63650892},{"atb":[[1.01,45.31],[1.86,0.61]],"id":51569790}],"con":true,"img":false}]}
{"op":"mcm","clk":"11541252519","pt":1719503823608,"mc":[{"id":"1.230178323","rc":[{"atb":[[1.03,0]],"id":70681333},{"atl":[[5,0.13],[1000,0]],"id":70681333},{"atb":[[1.02,22.65]],"id":63650892},{"atl":[[4,0.09]],"id":63650892},{"atb":[[1.86,0.94]],"id":51569790},{"atl":[[1000,0]],"id":51569790}],"con":true,"img":false}]}
{"op":"mcm","clk":"11541252527","pt":1719503823711,"mc":[{"id":"1.230178323","rc":[{"atb":[[2.92,0.39]],"id":70681333},{"atl":[[6.4,2.5],[5,3.64],[5.7,6.28]],"id":70681333},{"atb":[[2.48,0.19]],"id":63650892},{"atl":[[4,3.55],[5.1,2.5],[4.4,6]],"id":63650892},{"atl":[[2.9,0.67]],"id":51569790}],"con":true,"img":false}]}
{"op":"mcm","clk":"11541252537","pt":1719503823814,"mc":[{"id":"1.230178323","rc":[{"atl":[[5.1,0.84]],"id":70681333},{"atl":[[4.1,0.84]],"id":63650892}],"con":true,"img":false}]}
{"op":"mcm","clk":"11541252556","pt":1719503824123,"mc":[{"id":"1.230178323","rc":[{"atb":[[2.9,1.87]],"id":47885365}],"con":true,"img":false}]}
{"op":"mcm","clk":"11541252575","pt":1719503824328,"mc":[{"id":"1.230178323","rc":[{"atl":[[4.9,0.84]],"id":70681333},{"atb":[[2.96,1.94]],"id":47885365},{"atl":[[3.95,0.84]],"id":63650892}],"con":true,"img":false}]}
{"op":"mcm","clk":"11541252657","pt":1719503825109,"mc":[{"id":"1.230178323","rc":[{"atl":[[5.8,1],[5.7,5.28]],"id":70681333}],"con":true,"img":false}]}
{"op":"mcm","clk":"11541252732","pt":1719503825821,"mc":[{"id":"1.230178323","rc":[{"atb":[[2.94,0]],"id":47885365}],"con":true,"img":false}]}
{"op":"mcm","clk":"11541252817","pt":1719503826544,"mc":[{"id":"1.230178323","rc":[{"atl":[[5.8,0],[5.9,1]],"id":70681333}],"con":true,"img":false}]}
{"op":"mcm","clk":"11541252874","pt":1719503827215,"mc":[{"id":"1.230178323","rc":[{"atb":[[2.96,0]],"id":47885365}],"con":true,"img":false}]}
{"op":"mcm","clk":"11541252879","pt":1719503827316,"mc":[{"id":"1.230178323","rc":[{"atb":[[2.9,3.81]],"id":47885365}],"con":true,"img":false}]}
{"op":"mcm","clk":"11541252898","pt":1719503827624,"mc":[{"id":"1.230178323","rc":[{"atl":[[5.9,0]],"id":70681333},{"atl":[[2.88,1.93]],"id":51569790}],"con":true,"img":false}]}
{"op":"mcm","clk":"11541252907","pt":1719503827729,"mc":[{"id":"1.230178323","rc":[{"atl":[[2.92,6.28],[2.94,0]],"id":51569790}],"con":true,"img":false}]}
{"op":"mcm","clk":"11541252927","pt":1719503827932,"mc":[{"id":"1.230178323","rc":[{"atl":[[2.96,0]],"id":51569790}],"con":true,"img":false}]}
{"op":"mcm","clk":"11541252944","pt":1719503828139,"mc":[{"id":"1.230178323","rc":[{"atl":[[5,0.18]],"id":70681333}],"con":true,"img":false}]}
{"op":"mcm","clk":"11541252956","pt":1719503828243,"mc":[{"id":"1.230178323","rc":[{"atb":[[2.98,2.54]],"id":47885365},{"atl":[[2.86,0.84]],"id":51569790}],"con":true,"img":false}]}
{"op":"mcm","clk":"11541252966","pt":1719503828346,"mc":[{"id":"1.230178323","rc":[{"atb":[[2.9,16.72]],"id":47885365},{"atl":[[2.92,5.44]],"id":51569790}],"con":true,"img":false}]}
{"op":"mcm","clk":"11541252986","pt":1719503828508,"mc":[{"id":"1.230178323","rc":[{"atb":[[2.88,0]],"id":47885365}],"con":true,"img":false}]}
{"op":"mcm","clk":"11541253018","pt":1719503828818,"mc":[{"id":"1.230178323","rc":[{"atl":[[4.9,0]],"id":70681333},{"atb":[[2.9,15.11]],"id":47885365}],"con":true,"img":false}]}
{"op":"mcm","clk":"11541253030","pt":1719503828915,"mc":[{"id":"1.230178323","rc":[{"atl":[[5.1,3.35]],"id":70681333}],"con":true,"img":false}]}
{"op":"mcm","clk":"11541253043","pt":1719503829073,"mc":[{"id":"1.230178323","rc":[{"atb":[[2.56,0],[2.64,0],[2.66,2.5]],"id":70681333}],"con":true,"img":false}]}
{"op":"mcm","clk":"11541253063","pt":1719503829230,"mc":[{"id":"1.230178323","rc":[{"atb":[[2.9,14.85]],"id":47885365}],"con":true,"img":false}]}
{"op":"mcm","clk":"11541253075","pt":1719503829334,"mc":[{"id":"1.230178323","rc":[{"atb":[[1.13,0.26]],"id":47885365}],"con":true,"img":false}]}
{"op":"mcm","clk":"11541253089","pt":1719503829436,"mc":[{"id":"1.230178323","rc":[{"atl":[[5.1,0.84]],"id":70681333},{"atl":[[2.92,2.9]],"id":51569790}],"con":true,"img":false}]}
{"op":"mcm","clk":"11541253102","pt":1719503829561,"mc":[{"id":"1.230178323","rc":[{"atl":[[5.6,2.51]],"id":70681333}],"con":true,"img":false}]}
{"op":"mcm","clk":"11541253149","pt":1719503829923,"mc":[{"id":"1.230178323","rc":[{"atl":[[5.1,0]],"id":70681333}],"con":true,"img":false}]}
{"op":"mcm","clk":"11541253175","pt":1719503830230,"mc":[{"id":"1.230178323","rc":[{"atb":[[2.9,12.91]],"id":47885365},{"atl":[[4.1,5.24]],"id":63650892}],"con":true,"img":false}]}
{"op":"mcm","clk":"11541253185","pt":1719503830333,"mc":[{"id":"1.230178323","rc":[{"atl":[[4.4,1]],"id":63650892}],"con":true,"img":false}]}
{"op":"mcm","clk":"11541253197","pt":1719503830436,"mc":[{"id":"1.230178323","rc":[{"atl":[[6.4,3.5]],"id":70681333}],"con":true,"img":false}]}
{"op":"mcm","clk":"11541253214","pt":1719503830642,"mc":[{"id":"1.230178323","rc":[{"atb":[[1.61,9.72]],"id":68274051}],"con":true,"img":false}]}
{"op":"mcm","clk":"11541253324","pt":1719503831722,"mc":[{"id":"1.230178323","rc":[{"atl":[[5.5,0.84]],"id":70681333}],"con":true,"img":false}]}
{"op":"mcm","clk":"11541253334","pt":1719503831828,"mc":[{"id":"1.230178323","rc":[{"atl":[[2.86,3.38]],"id":51569790}],"con":true,"img":false}]}
{"op":"mcm","clk":"11541253355","pt":1719503832033,"mc":[{"id":"1.230178323","rc":[{"atb":[[2.98,14.13]],"id":47885365}],"con":true,"img":false}]}
{"op":"mcm","clk":"11541253373","pt":1719503832239,"mc":[{"id":"1.230178323","rc":[{"atb":[[2.9,0]],"id":47885365}],"con":true,"img":false}]}
{"op":"mcm","clk":"11541253514","pt":1719503833840,"mc":[{"id":"1.230178323","rc":[{"atb":[[1.02,24.36]],"id":70681333},{"atl":[[1000,1.7]],"id":70681333}],"con":true,"img":false}]}
{"op":"mcm","clk":"11541253537","pt":1719503834049,"mc":[{"id":"1.230178323","rc":[{"atb":[[1.02,22.8]],"id":70681333},{"atl":[[1000,0.06]],"id":70681333}],"con":true,"img":false}]}
{"op":"mcm","clk":"11541253567","pt":1719503834357,"mc":[{"id":"1.230178323","rc":[{"atb":[[1.02,22.65]],"id":70681333},{"atl":[[1000,0]],"id":70681333}],"con":true,"img":false}]}
{"op":"mcm","clk":"11541253580","pt":1719503834460,"mc":[{"id":"1.230178323","rc":[{"atb":[[2.92,0.53]],"id":70681333},{"atl":[[5.5,0.91]],"id":70681333}],"con":true,"img":false}]}
{"op":"mcm","clk":"11541253662","pt":1719503835244,"mc":[{"id":"1.230178323","rc":[{"atl":[[2.98,0]],"id":51569790}],"con":true,"img":false}]}
{"op":"mcm","clk":"11541253693","pt":1719503835556,"mc":[{"id":"1.230178323","rc":[{"atl":[[2.88,4.77]],"id":51569790}],"con":true,"img":false}]}
{"op":"mcm","clk":"11541253728","pt":1719503836074,"mc":[{"id":"1.230178323","rc":[{"atl":[[1000,0.24]],"id":60192591}],"con":true,"img":false}]}
{"op":"mcm","clk":"11541253746","pt":1719503836230,"mc":[{"id":"1.230178323","rc":[{"atl":[[1000,0]],"id":60192591}],"con":true,"img":false}]}
{"op":"mcm","clk":"11541253758","pt":1719503836352,"mc":[{"id":"1.230178323","rc":[{"atl":[[4.6,1.09]],"id":60192591}],"con":true,"img":false}]}
{"op":"mcm","clk":"11541253765","pt":1719503836455,"mc":[{"id":"1.230178323","rc":[{"atl":[[4.6,2.49]],"id":60192591}],"con":true,"img":false}]}
{"op":"mcm","clk":"11541253776","pt":1719503836559,"mc":[{"id":"1.230178323","rc":[{"atl":[[6.2,1]],"id":70681333},{"atl":[[4.7,0]],"id":60192591}],"con":true,"img":false}]}
{"op":"mcm","clk":"11541253782","pt":1719503836661,"mc":[{"id":"1.230178323","rc":[{"atl":[[6.4,2.5]],"id":70681333},{"atl":[[5.1,0],[5.5,0]],"id":63650892},{"atl":[[2.88,1.93]],"id":51569790}],"con":true,"img":false}]}
{"op":"mcm","clk":"11541253793","pt":1719503836763,"mc":[{"id":"1.230178323","rc":[{"atl":[[4.8,0]],"id":60192591}],"con":true,"img":false}]}
{"op":"mcm","clk":"11541253810","pt":1719503836968,"mc":[{"id":"1.230178323","rc":[{"atl":[[2.86,14.46]],"id":51569790}],"con":true,"img":false}]}
{"op":"mcm","clk":"11541253872","pt":1719503837544,"mc":[{"id":"1.230178323","rc":[{"atl":[[5.1,2.56]],"id":70681333},{"atl":[[3.95,5.38]],"id":63650892}],"con":true,"img":false}]}
{"op":"mcm","clk":"11541253888","pt":1719503837646,"mc":[{"id":"1.230178323","rc":[{"atl":[[5.6,0],[5.5,3.66],[5.7,0]],"id":70681333},{"atl":[[4,0.09],[4.1,0.84],[3.9,5.25]],"id":63650892}],"con":true,"img":false}]}
{"op":"mcm","clk":"11541253902","pt":1719503837751,"mc":[{"id":"1.230178323","rc":[{"atl":[[4.1,9.78],[3.9,0]],"id":63650892}],"con":true,"img":false}]}
{"op":"mcm","clk":"11541253914","pt":1719503837854,"mc":[{"id":"1.230178323","rc":[{"atl":[[5.5,2.81]],"id":70681333},{"atl":[[4.1,8.94]],"id":63650892}],"con":true,"img":false}]}
{"op":"mcm","clk":"11541254003","pt":1719503838631,"mc":[{"id":"1.230178323","rc":[{"atl":[[2.9,0.14]],"id":51569790}],"con":true,"img":false}]}
{"op":"mcm","clk":"11541254011","pt":1719503838734,"mc":[{"id":"1.230178323","rc":[{"atl":[[5,1.03]],"id":70681333}],"con":true,"img":false}]}
{"op":"mcm","clk":"11541254019","pt":1719503838835,"mc":[{"id":"1.230178323","rc":[{"atb":[[1.86,0.33]],"id":51569790}],"con":true,"img":false}]}
{"op":"mcm","clk":"11541254064","pt":1719503839348,"mc":[{"id":"1.230178323","rc":[{"atb":[[1.78,0],[1.74,5]],"id":51569790}],"con":true,"img":false}]}
{"op":"mcm","clk":"11541254307","pt":1719503841363,"mc":[{"id":"1.230178323","rc":[{"atl":[[2.84,2]],"id":51569790}],"con":true,"img":false}]}
{"op":"mcm","clk":"11541254321","pt":1719503841467,"mc":[{"id":"1.230178323","rc":[{"atl":[[2.88,0],[2.84,5.09]],"id":51569790}],"con":true,"img":false}]}
{"op":"mcm","clk":"11541254352","pt":1719503841673,"mc":[{"id":"1.230178323","rc":[{"atb":[[1.81,0],[1.77,2.11]],"id":51569790},{"atl":[[2.92,0]],"id":51569790}],"con":true,"img":false}]}
{"op":"mcm","clk":"11541254357","pt":1719503841774,"mc":[{"id":"1.230178323","rc":[{"atl":[[2.82,0.84]],"id":51569790}],"con":true,"img":false}]}
{"op":"mcm","clk":"11541254387","pt":1719503842036,"mc":[{"id":"1.230178323","rc":[{"atb":[[3,1.94]],"id":47885365}],"con":true,"img":false}]}
{"op":"mcm","clk":"11541254395","pt":1719503842140,"mc":[{"id":"1.230178323","rc":[{"atb":[[3,13.86]],"id":47885365}],"con":true,"img":false}]}
{"op":"mcm","clk":"11541254409","pt":1719503842243,"mc":[{"id":"1.230178323","rc":[{"atb":[[2.98,2.54]],"id":47885365}],"con":true,"img":false}]}
{"op":"mcm","clk":"11541254420","pt":1719503842348,"mc":[{"id":"1.230178323","rc":[{"atb":[[1.13,0]],"id":47885365}],"con":true,"img":false}]}
{"op":"mcm","clk":"11541254430","pt":1719503842450,"mc":[{"id":"1.230178323","rc":[{"atb":[[3.05,0.26]],"id":47885365}],"con":true,"img":false}]}
{"op":"mcm","clk":"11541254442","pt":1719503842554,"mc":[{"id":"1.230178323","rc":[{"atl":[[2.86,11.92]],"id":51569790}],"con":true,"img":false}]}
{"op":"mcm","clk":"11541254454","pt":1719503842657,"mc":[{"id":"1.230178323","rc":[{"atl":[[5,4.83]],"id":70681333},{"atb":[[3.05,1.87]],"id":47885365}],"con":true,"img":false}]}
{"op":"mcm","clk":"11541254477","pt":1719503842868,"mc":[{"id":"1.230178323","rc":[{"atl":[[5.1,0]],"id":70681333},{"spn":3.96,"spf":"NaN","id":70681333},{"spn":4.62,"spf":"NaN","id":47885365},{"spn":2.46,"spf":1.0,"id":63650892},{"spn":2.34,"spf":"NaN","id":51569790},{"spn":3.85,"spf":"NaN","id":60192591}],"con":true,"img":false}]}
{"op":"mcm","clk":"11541254617","pt":1719503844061,"mc":[{"id":"1.230178323","rc":[{"atl":[[6.2,0],[5.9,1]],"id":70681333},{"atb":[[2.98,0]],"id":47885365}],"con":true,"img":false}]}
{"op":"mcm","clk":"11541254660","pt":1719503844474,"mc":[{"id":"1.230178323","rc":[{"atb":[[3.05,0.26]],"id":47885365}],"con":true,"img":false}]}
{"op":"mcm","clk":"11541254762","pt":1719503845349,"mc":[{"id":"1.230178323","rc":[{"atb":[[3.05,0]],"id":47885365}],"con":true,"img":false}]}
{"op":"mcm","clk":"11541254773","pt":1719503845452,"mc":[{"id":"1.230178323","rc":[{"atb":[[1.13,0.26]],"id":47885365}],"con":true,"img":false}]}
{"op":"mcm","clk":"11541255071","pt":1719503848199,"mc":[{"id":"1.230178323","rc":[{"atl":[[5.9,0]],"id":70681333}],"con":true,"img":false}]}
{"op":"mcm","clk":"11541255100","pt":1719503848455,"mc":[{"id":"1.230178323","rc":[{"atl":[[5.9,1]],"id":70681333}],"con":true,"img":false}]}
{"op":"mcm","clk":"11541255161","pt":1719503849082,"mc":[{"id":"1.230178323","rc":[{"atl":[[5,1.03],[5.9,0]],"id":70681333}],"con":true,"img":false}]}
{"op":"mcm","clk":"11541255200","pt":1719503849404,"mc":[{"id":"1.230178323","rc":[{"atl":[[5,4.78]],"id":70681333}],"con":true,"img":false}]}
{"op":"mcm","clk":"11541255217","pt":1719503849453,"mc":[{"id":"1.230178323","rc":[{"atl":[[6.4,7.5],[5.5,0.06]],"id":70681333}],"con":true,"img":false}]}
{"op":"mcm","clk":"11541255272","pt":1719503849863,"mc":[{"id":"1.230178323","rc":[{"atl":[[5,1.03]],"id":70681333}],"con":true,"img":false}]}
{"op":"mcm","clk":"11541255337","pt":1719503850280,"mc":[{"id":"1.230178323","rc":[{"atl":[[5,0.18]],"id":70681333}],"con":true,"img":false}]}
{"op":"mcm","clk":"11541255353","pt":1719503850385,"mc":[{"id":"1.230178323","rc":[{"atl":[[6.2,2.28]],"id":70681333}],"con":true,"img":false}]}
{"op":"mcm","clk":"11541255363","pt":1719503850484,"mc":[{"id":"1.230178323","rc":[{"atl":[[6.4,8.5]],"id":70681333}],"con":true,"img":false}]}
{"op":"mcm","clk":"11541255403","pt":1719503850797,"mc":[{"id":"1.230178323","rc":[{"atb":[[2.92,2.64],[2.5,0],[1.1,22.66]],"id":70681333},{"atl":[[8,1],[7.2,0],[6.4,0],[6,0.84]],"id":70681333},{"atb":[[2.54,22],[2.76,0]],"id":47885365},{"atb":[[2.32,2.5],[2.12,0],[1.93,5],[2.08,0],[2.28,0],[2.2,0]],"id":63650892},{"atl":[[4.5,6.39],[4.1,0]],"id":63650892},{"atb":[[1.83,2.5],[1.58,0],[1.7,0],[1.79,5],[1.67,10.52],[1.75,18.02],[1.66,2.11]],"id":68274051},{"atb":[[1.44,5.59],[1.85,0],[1.71,0],[1.74,0],[1.67,0],[1.75,0]],"id":51569790},{"atl":[[2.86,23.85],[4.1,0],[3.3,0]],"id":51569790},{"atb":[[2.5,5],[2.9,0]],"id":60192591},{"atl":[[8.6,0],[4.5,4.5],[7.4,5],[7.8,0],[6.6,2.5],[5.9,5],[9.4,0]],"id":60192591}],"con":true,"img":false}]}
{"op":"mcm","clk":"11541255417","pt":1719503850850,"mc":[{"id":"1.230178323","rc":[{"atb":[[1.85,8.81]],"id":68274051}],"con":true,"img":false}]}
{"op":"mcm","clk":"11541255432","pt":1719503850960,"mc":[{"id":"1.230178323","rc":[{"atb":[[1.45,5],[1.49,2.5]],"id":51569790},{"atl":[[2.82,1.37]],"id":51569790},{"atl":[[4.4,3.74]],"id":60192591}],"con":true,"img":false}]}
{"op":"mcm","clk":"11541255450","pt":1719503851065,"mc":[{"id":"1.230178323","rc":[{"atl":[[9,2]],"id":70681333},{"atb":[[1.75,12]],"id":68274051},{"atb":[[1.44,7.82],[1.86,0.94]],"id":51569790},{"atl":[[2.82,3.91]],"id":51569790},{"atl":[[4.6,1.09],[4.9,0]],"id":60192591}],"con":true,"img":false}]}
{"op":"mcm","clk":"11541255458","pt":1719503851168,"mc":[{"id":"1.230178323","rc":[{"atb":[[2.9,2]],"id":70681333},{"atl":[[6,2.98]],"id":70681333}],"con":true,"img":false}]}
{"op":"mcm","clk":"11541255473","pt":1719503851270,"mc":[{"id":"1.230178323","rc":[{"atl":[[4.3,0.84],[4.6,0.24]],"id":60192591}],"con":true,"img":false}]}
{"op":"mcm","clk":"11541255495","pt":1719503851380,"mc":[{"id":"1.230178323","rc":[{"atb":[[2.9,0],[2.94,1.94]],"id":70681333},{"atl":[[6.2,0]],"id":70681333}],"con":true,"img":false}]}
{"op":"mcm","clk":"11541255504","pt":1719503851478,"mc":[{"id":"1.230178323","rc":[{"atb":[[2.94,3.94]],"id":70681333}],"con":true,"img":false}]}
{"op":"mcm","clk":"11541255530","pt":1719503851686,"mc":[{"id":"1.230178323","rc":[{"atb":[[1.75,10]],"id":68274051},{"atl":[[4.6,0]],"id":60192591}],"con":true,"img":false}]}
{"op":"mcm","clk":"11541255543","pt":1719503851789,"mc":[{"id":"1.230178323","rc":[{"atb":[[1.11,1.47]],"id":70681333},{"atb":[[1.86,2]],"id":68274051},{"atl":[[2.86,23.01]],"id":51569790}],"con":true,"img":false}]}
{"op":"mcm","clk":"11541255562","pt":1719503851948,"mc":[{"id":"1.230178323","rc":[{"atb":[[2.96,2.52]],"id":70681333},{"atb":[[3.05,3]],"id":47885365},{"atl":[[7.6,6]],"id":47885365},{"atl":[[4.3,1],[4.4,0]],"id":63650892},{"atb":[[1.86,4.68]],"id":68274051},{"atl":[[3.65,1]],"id":68274051},{"atb":[[1.63,2.5]],"id":51569790},{"atb":[[3.1,4.62]],"id":60192591},{"atl":[[7.2,1]],"id":60192591}],"con":true,"img":false}]}
{"op":"mcm","clk":"11541255568","pt":1719503852052,"mc":[{"id":"1.230178323","rc":[{"atb":[[3.05,15.29]],"id":47885365},{"atl":[[7.2,16.89],[7.8,0]],"id":47885365},{"atl":[[4.2,1]],"id":63650892},{"atl":[[4,2.5],[3.6,9.26],[3.4,1]],"id":68274051}],"con":true,"img":false}]}
{"op":"mcm","clk":"11541255581","pt":1719503852158,"mc":[{"id":"1.230178323","rc":[{"atb":[[3,1.94]],"id":47885365},{"atl":[[4.5,2.5]],"id":60192591}],"con":true,"img":false}]}
{"op":"mcm","clk":"11541255593","pt":1719503852256,"mc":[{"id":"1.230178323","rc":[{"atb":[[3.1,1.6]],"id":47885365}],"con":true,"img":false}]}
{"op":"mcm","clk":"11541255631","pt":1719503852669,"mc":[{"id":"1.230178323","rc":[{"atl":[[7.6,5]],"id":47885365},{"atl":[[4.3,0]],"id":63650892},{"atl":[[3.65,0]],"id":68274051}],"con":true,"img":false}]}
{"op":"mcm","clk":"11541255667","pt":1719503853083,"mc":[{"id":"1.230178323","rc":[{"atb":[[2.94,1.94]],"id":70681333}],"con":true,"img":false}]}
{"op":"mcm","clk":"11541255677","pt":1719503853186,"mc":[{"id":"1.230178323","rc":[{"atb":[[2.98,2]],"id":70681333}],"con":true,"img":false}]}
{"op":"mcm","clk":"11541255799","pt":1719503854279,"mc":[{"id":"1.230178323","rc":[{"atb":[[2.94,0]],"id":70681333},{"atb":[[3,0]],"id":47885365}],"con":true,"img":false}]}
{"op":"mcm","clk":"11541255821","pt":1719503854485,"mc":[{"id":"1.230178323","rc":[{"atb":[[2.98,3.94]],"id":70681333},{"atb":[[3.1,3.55]],"id":47885365}],"con":true,"img":false}]}
{"op":"mcm","clk":"11541255852","pt":1719503854746,"mc":[{"id":"1.230178323","rc":[{"atb":[[3.1,1.94]],"id":47885365}],"con":true,"img":false}]}
{"op":"mcm","clk":"11541255863","pt":1719503854848,"mc":[{"id":"1.230178323","rc":[{"atl":[[2.8,2]],"id":51569790}],"con":true,"img":false}]}
{"op":"mcm","clk":"11541255876","pt":1719503854954,"mc":[{"id":"1.230178323","rc":[{"atl":[[2.8,5.46]],"id":51569790}],"con":true,"img":false}]}
{"op":"mcm","clk":"11541255885","pt":1719503855056,"mc":[{"id":"1.230178323","rc":[{"atl":[[2.84,0]],"id":51569790}],"con":true,"img":false}]}
{"op":"mcm","clk":"11541255906","pt":1719503855261,"mc":[{"id":"1.230178323","rc":[{"atl":[[2.78,0.84]],"id":51569790}],"con":true,"img":false}]}
{"op":"mcm","clk":"11541255951","pt":1719503855677,"mc":[{"id":"1.230178323","rc":[{"atb":[[3.1,13.86]],"id":47885365}],"con":true,"img":false}]}
{"op":"mcm","clk":"11541255965","pt":1719503855882,"mc":[{"id":"1.230178323","rc":[{"atl":[[8,0]],"id":70681333},{"atb":[[3.05,3],[3.15,1.6]],"id":47885365}],"con":true,"img":false}]}
{"op":"mcm","clk":"11541255994","pt":1719503856192,"mc":[{"id":"1.230178323","rc":[{"atl":[[2.82,1.37]],"id":51569790}],"con":true,"img":false}]}
{"op":"mcm","clk":"11541256076","pt":1719503856969,"mc":[{"id":"1.230178323","rc":[{"atb":[[2.72,11]],"id":47885365}],"con":true,"img":false}]}
{"op":"mcm","clk":"11541256086","pt":1719503857072,"mc":[{"id":"1.230178323","rc":[{"atb":[[1.1,0],[1.25,5.02]],"id":70681333},{"atb":[[2.54,0]],"id":47885365},{"atb":[[1.93,0],[2.14,4.62]],"id":63650892},{"atl":[[4.5,0],[4.2,6.48]],"id":63650892},{"atb":[[1.44,2.23],[1.51,5]],"id":51569790},{"atl":[[2.82,7.68],[2.86,11.08]],"id":51569790},{"atb":[[2.5,0],[2.78,7.12]],"id":60192591}],"con":true,"img":false}]}
{"op":"mcm","clk":"11541256099","pt":1719503857176,"mc":[{"id":"1.230178323","rc":[{"atl":[[5.1,2.5],[5.5,5],[5.9,10]],"id":63650892}],"con":true,"img":false}]}
{"op":"mcm","clk":"11541256154","pt":1719503857692,"mc":[{"id":"1.230178323","rc":[{"atb":[[1.09,1.6]],"id":51569790}],"con":true,"img":false}]}
{"op":"mcm","clk":"11541256165","pt":1719503857751,"mc":[{"id":"1.230178323","rc":[{"atb":[[1.11,0]],"id":70681333}],"con":true,"img":false}]}
{"op":"mcm","clk":"11541256175","pt":1719503857847,"mc":[{"id":"1.230178323","rc":[{"atb":[[1.09,1.47]],"id":70681333}],"con":true,"img":false}]}
{"op":"mcm","clk":"11541256236","pt":1719503858467,"mc":[{"id":"1.230178323","rc":[{"atl":[[2.78,3.38]],"id":51569790}],"con":true,"img":false}]}
{"op":"mcm","clk":"11541256275","pt":1719503858879,"mc":[{"id":"1.230178323","rc":[{"atl":[[2.82,6.83]],"id":51569790}],"con":true,"img":false}]}
{"op":"mcm","clk":"11541256529","pt":1719503860962,"mc":[{"id":"1.230178323","rc":[{"atb":[[1.14,5.02],[1.25,0]],"id":70681333},{"atl":[[9,0],[10.5,2.19]],"id":70681333}],"con":true,"img":false}]}
{"op":"mcm","clk":"11541256811","pt":1719503863491,"mc":[{"id":"1.230178323","rc":[{"atl":[[5,0]],"id":70681333},{"trd":[[5,0.37]],"ltp":5.0,"tv":0.37,"id":70681333}],"con":true,"img":false}]}
{"op":"mcm","clk":"11541256825","pt":1719503863594,"mc":[{"id":"1.230178323","rc":[{"atl":[[11.5,2.5],[13.5,5],[15.5,10]],"id":70681333}],"con":true,"img":false}]}
{"op":"mcm","clk":"11541256883","pt":1719503864074,"mc":[{"id":"1.230178323","rc":[{"atl":[[4.2,2.5]],"id":60192591}],"con":true,"img":false}]}
{"op":"mcm","clk":"11541256894","pt":1719503864174,"mc":[{"id":"1.230178323","rc":[{"atb":[[3,3.88]],"id":70681333},{"atb":[[1.86,11.66]],"id":68274051}],"con":true,"img":false}]}
{"op":"mcm","clk":"11541256903","pt":1719503864281,"mc":[{"id":"1.230178323","rc":[{"atl":[[4.5,0],[4.2,6.25]],"id":60192591}],"con":true,"img":false}]}
{"op":"mcm","clk":"11541256915","pt":1719503864381,"mc":[{"id":"1.230178323","rc":[{"atb":[[2.92,0.53]],"id":70681333},{"atb":[[1.85,0]],"id":68274051},{"atl":[[4.4,0]],"id":60192591}],"con":true,"img":false}]}
{"op":"mcm","clk":"11541256967","pt":1719503864790,"mc":[{"id":"1.230178323","rc":[{"atb":[[2.98,1.94]],"id":70681333},{"atl":[[4.1,0.84]],"id":60192591}],"con":true,"img":false}]}
{"op":"mcm","clk":"11541256980","pt":1719503864894,"mc":[{"id":"1.230178323","rc":[{"atb":[[3.05,2]],"id":70681333}],"con":true,"img":false}]}
{"op":"mcm","clk":"11541257039","pt":1719503865368,"mc":[{"id":"1.230178323","rc":[{"atb":[[3.15,13.89]],"id":47885365}],"con":true,"img":false}]}
{"op":"mcm","clk":"11541257050","pt":1719503865475,"mc":[{"id":"1.230178323","rc":[{"atl":[[1000,0.24]],"id":60192591}],"con":true,"img":false}]}
{"op":"mcm","clk":"11541257057","pt":1719503865577,"mc":[{"id":"1.230178323","rc":[{"atb":[[3.1,1.94]],"id":47885365}],"con":true,"img":false}]}
{"op":"mcm","clk":"11541257067","pt":1719503865678,"mc":[{"id":"1.230178323","rc":[{"atl":[[9,1]],"id":70681333},{"atl":[[3.45,1],[3.4,0]],"id":68274051},{"atl":[[1000,0]],"id":60192591}],"con":true,"img":false}]}
{"op":"mcm","clk":"11541257079","pt":1719503865782,"mc":[{"id":"1.230178323","rc":[{"atl":[[7.2,15.89],[7.4,1],[7.6,6]],"id":47885365},{"atl":[[4.1,1],[4.2,5.48]],"id":63650892},{"atl":[[3.3,1]],"id":68274051},{"atb":[[1.62,0]],"id":51569790},{"atl":[[4.1,1.09]],"id":60192591}],"con":true,"img":false}]}
{"op":"mcm","clk":"11541257089","pt":1719503865878,"mc":[{"id":"1.230178323","rc":[{"atl":[[3.6,0],[3.4,9.26]],"id":68274051}],"con":true,"img":false}]}
{"op":"mcm","clk":"11541257104","pt":1719503865981,"mc":[{"id":"1.230178323","rc":[{"atb":[[2.92,0]],"id":70681333},{"atl":[[9,0],[9.2,1],[5.5,0],[6,0.84]],"id":70681333},{"atl":[[7.6,5]],"id":47885365},{"atb":[[2.48,0]],"id":63650892},{"atl":[[4,0]],"id":63650892},{"atl":[[4,0],[3.45,5.63],[3.4,0]],"id":68274051},{"atb":[[1.86,0.61]],"id":51569790},{"atl":[[2.9,0]],"id":51569790},{"atl":[[4,2]],"id":60192591}],"con":true,"img":false}]}
{"op":"mcm","clk":"11541257119","pt":1719503866082,"mc":[{"id":"1.230178323","rc":[{"atb":[[1.14,0],[1.08,72.66]],"id":70681333},{"atl":[[9,2.96]],"id":70681333}],"con":true,"img":false}]}
{"op":"mcm","clk":"11541257132","pt":1719503866186,"mc":[{"id":"1.230178323","rc":[{"atb":[[2.96,0]],"id":70681333},{"atb":[[3.05,0]],"id":47885365},{"atb":[[1.86,8.98]],"id":68274051},{"atl":[[4.3,5],[3.95,2.5],[4.7,10]],"id":68274051}],"con":true,"img":false}]}
{"op":"mcm","clk":"11541257144","pt":1719503866289,"mc":[{"id":"1.230178323","rc":[{"atb":[[2.98,0]],"id":70681333},{"atb":[[3.1,0]],"id":47885365},{"atl":[[7.4,0],[7.6,6]],"id":47885365},{"atl":[[4.2,6.48]],"id":63650892},{"atl":[[2.82,6.31]],"id":51569790}],"con":true,"img":false}]}
{"op":"mcm","clk":"11541257157","pt":1719503866394,"mc":[{"id":"1.230178323","rc":[{"atb":[[3.05,5]],"id":70681333},{"atl":[[6,0]],"id":70681333},{"atb":[[3.2,3.4]],"id":47885365},{"atl":[[4.1,0]],"id":63650892},{"atb":[[1.87,3.98]],"id":68274051},{"atl":[[2.82,0],[2.78,8.84]],"id":51569790},{"atl":[[4.3,0]],"id":60192591}],"con":true,"img":false}]}
{"op":"mcm","clk":"11541257170","pt":1719503866496,"mc":[{"id":"1.230178323","rc":[{"atb":[[3.15,12.29]],"id":47885365},{"atb":[[1.86,0]],"id":51569790},{"atl":[[2.82,8.85]],"id":51569790}],"con":true,"img":false}]}
{"op":"mcm","clk":"11541257183","pt":1719503866558,"mc":[{"id":"1.230178323","rc":[{"atl":[[5.1,14.37],[4.2,1]],"id":63650892},{"atl":[[3.7,5],[2.78,3.38],[3.5,2.5]],"id":51569790}],"con":true,"img":false}]}
{"op":"mcm","clk":"11541257206","pt":1719503866764,"mc":[{"id":"1.230178323","rc":[{"atb":[[3.05,6.94]],"id":70681333},{"atb":[[3.2,5.34]],"id":47885365},{"atl":[[2.76,0.52]],"id":51569790}],"con":true,"img":false}]}
{"op":"mcm","clk":"11541257218","pt":1719503866868,"mc":[{"id":"1.230178323","rc":[{"atl":[[8.8,0.84]],"id":70681333},{"atb":[[1.86,6.98]],"id":68274051},{"atb":[[1.78,0.67]],"id":51569790}],"con":true,"img":false}]}
{"op":"mcm","clk":"11541257231","pt":1719503866980,"mc":[{"id":"1.230178323","rc":[{"atb":[[1.88,2]],"id":68274051}],"con":true,"img":false}]}
{"op":"mcm","clk":"11541257250","pt":1719503867078,"mc":[{"id":"1.230178323","rc":[{"atb":[[1.09,0]],"id":70681333}],"con":true,"img":false}]}
{"op":"mcm","clk":"11541257264","pt":1719503867175,"mc":[{"id":"1.230178323","rc":[{"atb":[[3.1,2.32]],"id":70681333}],"con":true,"img":false}]}
{"op":"mcm","clk":"11541257366","pt":1719503868093,"mc":[{"id":"1.230178323","rc":[{"atl":[[2.74,2]],"id":51569790}],"con":true,"img":false}]}
{"op":"mcm","clk":"11541257375","pt":1719503868195,"mc":[{"id":"1.230178323","rc":[{"atl":[[2.8,3.46],[2.76,2.61]],"id":51569790}],"con":true,"img":false}]}
{"op":"mcm","clk":"11541257387","pt":1719503868297,"mc":[{"id":"1.230178323","rc":[{"atl":[[2.8,0]],"id":51569790}],"con":true,"img":false}]}
{"op":"mcm","clk":"11541257430","pt":1719503868669,"mc":[{"id":"1.230178323","rc":[{"atb":[[3.1,1.73]],"id":70681333}],"con":true,"img":false}]}
{"op":"mcm","clk":"11541257448","pt":1719503868875,"mc":[{"id":"1.230178323","rc":[{"atb":[[3.2,18.57]],"id":47885365},{"atl":[[2.72,0.85],[2.78,2.54]],"id":51569790}],"con":true,"img":false}]}
{"op":"mcm","clk":"11541257458","pt":1719503868976,"mc":[{"id":"1.230178323","rc":[{"atb":[[3.15,0]],"id":47885365}],"con":true,"img":false}]}
{"op":"mcm","clk":"11541257566","pt":1719503870063,"mc":[{"id":"1.230178323","rc":[{"atl":[[2.78,0]],"id":51569790}],"con":true,"img":false}]}
{"op":"mcm","clk":"11541257735","pt":1719503871862,"mc":[{"id":"1.230178323","rc":[{"atl":[[3.95,0.84]],"id":60192591}],"con":true,"img":false}]}
{"op":"mcm","clk":"11541257799","pt":1719503872484,"mc":[{"id":"1.230178323","rc":[{"atl":[[2.72,3.39]],"id":51569790}],"con":true,"img":false}]}
{"op":"mcm","clk":"11541257813","pt":1719503872590,"mc":[{"id":"1.230178323","rc":[{"atl":[[2.78,8.85]],"id":51569790}],"con":true,"img":false}]}
{"op":"mcm","clk":"11541257824","pt":1719503872695,"mc":[{"id":"1.230178323","rc":[{"atl":[[2.82,0]],"id":51569790}],"con":true,"img":false}]}
{"op":"mcm","clk":"11541258103","pt":1719503875595,"mc":[{"id":"1.230178323","rc":[{"atl":[[2.86,0]],"id":51569790}],"con":true,"img":false}]}
{"op":"mcm","clk":"11541258132","pt":1719503875896,"mc":[{"id":"1.230178323","rc":[{"atl":[[2.76,4.6]],"id":51569790}],"con":true,"img":false}]}
{"op":"mcm","clk":"11541258153","pt":1719503876101,"mc":[{"id":"1.230178323","rc":[{"atl":[[2.78,0],[2.76,10]],"id":51569790}],"con":true,"img":false}]}
{"op":"mcm","clk":"11541258252","pt":1719503877195,"mc":[{"id":"1.230178323","rc":[{"atl":[[3.9,2.25]],"id":60192591}],"con":true,"img":false}]}
{"op":"mcm","clk":"11541258262","pt":1719503877290,"mc":[{"id":"1.230178323","rc":[{"atb":[[3.15,3.53]],"id":70681333},{"atb":[[1.88,8.46]],"id":68274051},{"atl":[[4.2,3.75]],"id":60192591}],"con":true,"img":false}]}
{"op":"mcm","clk":"11541258268","pt":1719503877391,"mc":[{"id":"1.230178323","rc":[{"atb":[[3,0]],"id":70681333},{"atb":[[1.89,1.54]],"id":68274051},{"atl":[[3.9,5.81]],"id":60192591}],"con":true,"img":false}]}
{"op":"mcm","clk":"11541258277","pt":1719503877492,"mc":[{"id":"1.230178323","rc":[{"atb":[[1.86,0]],"id":68274051},{"atl":[[4.2,0]],"id":60192591}],"con":true,"img":false}]}
{"op":"mcm","clk":"11541258302","pt":1719503877803,"mc":[{"id":"1.230178323","rc":[{"atb":[[3.05,4.94]],"id":70681333}],"con":true,"img":false}]}
{"op":"mcm","clk":"11541258311","pt":1719503877907,"mc":[{"id":"1.230178323","rc":[{"atb":[[3.2,2]],"id":70681333},{"atl":[[4.1,0.24]],"id":60192591}],"con":true,"img":false}]}
{"op":"mcm","clk":"11541258330","pt":1719503878068,"mc":[{"id":"1.230178323","rc":[{"atb":[[3.1,0.26]],"id":70681333},{"atb":[[1.89,0]],"id":68274051}],"con":true,"img":false}]}
{"op":"mcm","clk":"11541258338","pt":1719503878173,"mc":[{"id":"1.230178323","rc":[{"atb":[[1.09,1.47]],"id":70681333}],"con":true,"img":false}]}
{"op":"mcm","clk":"11541258389","pt":1719503878691,"mc":[{"id":"1.230178323","rc":[{"atb":[[3.05,3]],"id":70681333}],"con":true,"img":false}]}
{"op":"mcm","clk":"11541258412","pt":1719503878898,"mc":[{"id":"1.230178323","rc":[{"atb":[[3.1,0]],"id":70681333},{"atl":[[3.85,0.84]],"id":60192591}],"con":true,"img":false}]}
{"op":"mcm","clk":"11541258422","pt":1719503878994,"mc":[{"id":"1.230178323","rc":[{"atb":[[3.2,3.94]],"id":70681333}],"con":true,"img":false}]}
{"op":"mcm","clk":"11541258436","pt":1719503879097,"mc":[{"id":"1.230178323","rc":[{"atl":[[8.8,4.56]],"id":70681333}],"con":true,"img":false}]}
{"op":"mcm","clk":"11541258461","pt":1719503879304,"mc":[{"id":"1.230178323","rc":[{"atl":[[9,0]],"id":70681333}],"con":true,"img":false}]}
{"op":"mcm","clk":"11541258564","pt":1719503880298,"mc":[{"id":"1.230178323","rc":[{"atb":[[2.94,11.8]],"id":60192591},{"atl":[[3.85,8.83]],"id":60192591}],"con":true,"img":false}]}
{"op":"mcm","clk":"11541258574","pt":1719503880399,"mc":[{"id":"1.230178323","rc":[{"atb":[[3.25,1]],"id":70681333},{"atl":[[8.6,1]],"id":70681333},{"atl":[[2.7,1]],"id":51569790}],"con":true,"img":false}]}
{"op":"mcm","clk":"11541258611","pt":1719503880706,"mc":[{"id":"1.230178323","rc":[{"atb":[[3.05,0]],"id":70681333},{"atb":[[1.87,0]],"id":68274051},{"atb":[[3.1,2.48]],"id":60192591}],"con":true,"img":false}]}
{"op":"mcm","clk":"11541258625","pt":1719503880809,"mc":[{"id":"1.230178323","rc":[{"atb":[[3.25,3.3]],"id":70681333},{"atb":[[1.89,2.9]],"id":68274051}],"con":true,"img":false}]}
{"op":"mcm","clk":"11541258646","pt":1719503881014,"mc":[{"id":"1.230178323","rc":[{"atl":[[3.95,0]],"id":60192591}],"con":true,"img":false}]}
{"op":"mcm","clk":"11541258657","pt":1719503881120,"mc":[{"id":"1.230178323","rc":[{"atl":[[2.68,5.09]],"id":51569790},{"atl":[[4.1,0]],"id":60192591}],"con":true,"img":false}]}
{"op":"mcm","clk":"11541258683","pt":1719503881284,"mc":[{"id":"1.230178323","rc":[{"atl":[[2.74,0],[2.7,0],[2.76,7.91]],"id":51569790}],"con":true,"img":false}]}
{"op":"mcm","clk":"11541258695","pt":1719503881389,"mc":[{"id":"1.230178323","rc":[{"atl":[[3.8,5.48]],"id":60192591}],"con":true,"img":false}]}
{"op":"mcm","clk":"11541258708","pt":1719503881494,"mc":[{"id":"1.230178323","rc":[{"atb":[[3.2,1.94]],"id":70681333},{"atl":[[4,0]],"id":60192591}],"con":true,"img":false}]}
{"op":"mcm","clk":"11541258722","pt":1719503881598,"mc":[{"id":"1.230178323","rc":[{"atb":[[3.3,2]],"id":70681333}],"con":true,"img":false}]}
{"op":"mcm","clk":"11541258747","pt":1719503881802,"mc":[{"id":"1.230178323","rc":[{"atb":[[3.2,0],[3.25,2.3]],"id":70681333}],"con":true,"img":false}]}
{"op":"mcm","clk":"11541258760","pt":1719503881908,"mc":[{"id":"1.230178323","rc":[{"atl":[[2.72,2.54],[2.66,0.84]],"id":51569790}],"con":true,"img":false}]}
{"op":"mcm","clk":"11541258778","pt":1719503882103,"mc":[{"id":"1.230178323","rc":[{"atb":[[3.3,3.94]],"id":70681333},{"atb":[[1.88,6.46]],"id":68274051},{"atl":[[3.85,0.84]],"id":60192591}],"con":true,"img":false}]}
{"op":"mcm","clk":"11541258792","pt":1719503882208,"mc":[{"id":"1.230178323","rc":[{"atb":[[1.9,2]],"id":68274051},{"atl":[[2.76,7.39]],"id":51569790}],"con":true,"img":false}]}
{"op":"mcm","clk":"11541258852","pt":1719503882684,"mc":[{"id":"1.230178323","rc":[{"atb":[[1.78,0]],"id":51569790}],"con":true,"img":false}]}
{"op":"mcm","clk":"11541258875","pt":1719503882891,"mc":[{"id":"1.230178323","rc":[{"atl":[[3.8,13.76]],"id":60192591}],"con":true,"img":false}]}
{"op":"mcm","clk":"11541258905","pt":1719503883203,"mc":[{"id":"1.230178323","rc":[{"atl":[[2.72,0]],"id":51569790}],"con":true,"img":false}]}
{"op":"mcm","clk":"11541258915","pt":1719503883310,"mc":[{"id":"1.230178323","rc":[{"atl":[[2.64,1]],"id":51569790}],"con":true,"img":false}]}
{"op":"mcm","clk":"11541258982","pt":1719503883977,"mc":[{"id":"1.230178323","rc":[{"atb":[[2.76,3.75]],"id":47885365}],"con":true,"img":false}]}
{"op":"mcm","clk":"11541258995","pt":1719503884079,"mc":[{"id":"1.230178323","rc":[{"atb":[[3.35,1]],"id":70681333}],"con":true,"img":false}]}
{"op":"mcm","clk":"11541259057","pt":1719503884693,"mc":[{"id":"1.230178323","rc":[{"atb":[[2.76,0]],"id":47885365}],"con":true,"img":false}]}
{"op":"mcm","clk":"11541259169","pt":1719503885613,"mc":[{"id":"1.230178323","rc":[{"atb":[[3.6,5],[3.8,2.5],[3.4,10],[2.66,0]],"id":70681333}],"con":true,"img":false}]}
{"op":"mcm","clk":"11541259182","pt":1719503885682,"mc":[{"id":"1.230178323","rc":[{"atl":[[2.64,3.54]],"id":51569790}],"con":true,"img":false}]}
{"op":"mcm","clk":"11541259191","pt":1719503885778,"mc":[{"id":"1.230178323","rc":[{"atb":[[3.35,0],[1.09,0]],"id":70681333}],"con":true,"img":false}]}
{"op":"mcm","clk":"11541259207","pt":1719503885885,"mc":[{"id":"1.230178323","rc":[{"atb":[[3.45,1.47]],"id":70681333}],"con":true,"img":false}]}
{"op":"mcm","clk":"11541259262","pt":1719503886397,"mc":[{"id":"1.230178323","rc":[{"atl":[[3.75,0.84]],"id":60192591}],"con":true,"img":false}]}
{"op":"mcm","clk":"11541259273","pt":1719503886522,"mc":[{"id":"1.230178323","rc":[{"atb":[[3.3,1.94]],"id":70681333},{"atl":[[8.6,3.98]],"id":70681333},{"atl":[[7.6,5],[7.8,1]],"id":47885365},{"atl":[[4.4,1],[4.2,0]],"id":63650892},{"atl":[[3.6,1],[3.3,0]],"id":68274051}],"con":true,"img":false}]}
{"op":"mcm","clk":"11541259281","pt":1719503886600,"mc":[{"id":"1.230178323","rc":[{"atb":[[3.85,2]],"id":70681333},{"atl":[[5.1,2.5],[4.3,10.78]],"id":63650892}],"con":true,"img":false}]}
{"op":"mcm","clk":"11541259312","pt":1719503886906,"mc":[{"id":"1.230178323","rc":[{"atl":[[8.4,0.84]],"id":70681333}],"con":true,"img":false}]}
{"op":"mcm","clk":"11541259322","pt":1719503887008,"mc":[{"id":"1.230178323","rc":[{"atl":[[8.6,2.98]],"id":70681333}],"con":true,"img":false}]}
{"op":"mcm","clk":"11541259331","pt":1719503887112,"mc":[{"id":"1.230178323","rc":[{"atb":[[3.85,10.35]],"id":70681333}],"con":true,"img":false}]}
{"op":"mcm","clk":"11541259385","pt":1719503887685,"mc":[{"id":"1.230178323","rc":[{"atb":[[3.45,0]],"id":70681333}],"con":true,"img":false}]}
{"op":"mcm","clk":"11541259394","pt":1719503887784,"mc":[{"id":"1.230178323","rc":[{"atb":[[3.9,1.47]],"id":70681333}],"con":true,"img":false}]}
{"op":"mcm","clk":"11541259409","pt":1719503887990,"mc":[{"id":"1.230178323","rc":[{"atb":[[3.3,0]],"id":70681333}],"con":true,"img":false}]}
{"op":"mcm","clk":"11541259432","pt":1719503888205,"mc":[{"id":"1.230178323","rc":[{"atb":[[3.9,3.42]],"id":70681333}],"con":true,"img":false}]}
{"op":"mcm","clk":"11541259495","pt":1719503888814,"mc":[{"id":"1.230178323","rc":[{"atb":[[3.85,8.35]],"id":70681333}],"con":true,"img":false}]}
{"op":"mcm","clk":"11541259506","pt":1719503888917,"mc":[{"id":"1.230178323","rc":[{"atb":[[3.95,2]],"id":70681333}],"con":true,"img":false}]}
{"op":"mcm","clk":"11541259519","pt":1719503889020,"mc":[{"id":"1.230178323","rc":[{"atb":[[4,1]],"id":70681333},{"atl":[[8.2,1]],"id":70681333},{"atl":[[2.72,7.08],[2.76,1.99]],"id":51569790}],"con":true,"img":false}]}
{"op":"mcm","clk":"11541259534","pt":1719503889090,"mc":[{"id":"1.230178323","rc":[{"atb":[[3.85,7.29]],"id":70681333}],"con":true,"img":false}]}
{"op":"mcm","clk":"11541259560","pt":1719503889289,"mc":[{"id":"1.230178323","rc":[{"atb":[[3.85,0]],"id":70681333}],"con":true,"img":false}]}
{"op":"mcm","clk":"11541259575","pt":1719503889391,"mc":[{"id":"1.230178323","rc":[{"atb":[[3.9,10.71]],"id":70681333},{"atl":[[8.8,3.72]],"id":70681333},{"atl":[[2.62,0.84]],"id":51569790}],"con":true,"img":false}]}
{"op":"mcm","clk":"11541259590","pt":1719503889514,"mc":[{"id":"1.230178323","rc":[{"atb":[[3.9,9.23]],"id":70681333}],"con":true,"img":false}]}
{"op":"mcm","clk":"11541259601","pt":1719503889598,"mc":[{"id":"1.230178323","rc":[{"atb":[[3.9,1.94]],"id":70681333},{"atl":[[2.64,2.54]],"id":51569790}],"con":true,"img":false}]}
{"op":"mcm","clk":"11541259649","pt":1719503890008,"mc":[{"id":"1.230178323","rc":[{"atb":[[3.45,1.47]],"id":70681333}],"con":true,"img":false}]}
{"op":"mcm","clk":"11541259665","pt":1719503890122,"mc":[{"id":"1.230178323","rc":[{"atb":[[4.1,2.21]],"id":70681333},{"atb":[[1.9,7.65]],"id":68274051}],"con":true,"img":false}]}
{"op":"mcm","clk":"11541259680","pt":1719503890225,"mc":[{"id":"1.230178323","rc":[{"atb":[[4,0]],"id":70681333},{"atl":[[3.45,0],[3.6,11.26]],"id":68274051},{"atl":[[3.75,2.56]],"id":60192591}],"con":true,"img":false}]}
{"op":"mcm","clk":"11541259692","pt":1719503890313,"mc":[{"id":"1.230178323","rc":[{"atb":[[4.1,0],[3.15,0]],"id":70681333},{"atb":[[1.88,0]],"id":68274051}],"con":true,"img":false}]}
{"op":"mcm","clk":"11541259710","pt":1719503890417,"mc":[{"id":"1.230178323","rc":[{"atb":[[4,2.96]],"id":70681333},{"atl":[[3.6,1],[3.95,18.39]],"id":68274051},{"atl":[[3.8,5.48],[3.9,2.25]],"id":60192591}],"con":true,"img":false}]}
{"op":"mcm","clk":"11541259736","pt":1719503890582,"mc":[{"id":"1.230178323","rc":[{"atb":[[4.1,8.28]],"id":70681333}],"con":true,"img":false}]}
{"op":"mcm","clk":"11541259748","pt":1719503890692,"mc":[{"id":"1.230178323","rc":[{"atb":[[3.95,0]],"id":70681333}],"con":true,"img":false}]}
{"op":"mcm","clk":"11541259765","pt":1719503890793,"mc":[{"id":"1.230178323","rc":[{"atb":[[1.02,24.65]],"id":70681333}],"con":true,"img":false}]}
{"op":"mcm","clk":"11541259789","pt":1719503890995,"mc":[{"id":"1.230178323","rc":[{"atl":[[3.85,0]],"id":60192591}],"con":true,"img":false}]}
{"op":"mcm","clk":"11541259800","pt":1719503891102,"mc":[{"id":"1.230178323","rc":[{"atb":[[3.9,0]],"id":70681333}],"con":true,"img":false}]}
{"op":"mcm","clk":"11541259815","pt":1719503891209,"mc":[{"id":"1.230178323","rc":[{"atl":[[3.75,10.52]],"id":60192591}],"con":true,"img":false}]}
{"op":"mcm","clk":"11541259830","pt":1719503891315,"mc":[{"id":"1.230178323","rc":[{"atb":[[4.2,1.94]],"id":70681333}],"con":true,"img":false}]}
{"op":"mcm","clk":"11541259885","pt":1719503891713,"mc":[{"id":"1.230178323","rc":[{"atl":[[4.3,0],[4.4,17.17]],"id":63650892}],"con":true,"img":false}]}
{"op":"mcm","clk":"11541259900","pt":1719503891817,"mc":[{"id":"1.230178323","rc":[{"atl":[[8.2,4.68]],"id":70681333},{"atl":[[2.6,1]],"id":51569790}],"con":true,"img":false}]}
{"op":"mcm","clk":"11541259924","pt":1719503891995,"mc":[{"id":"1.230178323","rc":[{"atb":[[4.1,6.51]],"id":70681333},{"atl":[[8.6,2.9],[8.8,0]],"id":70681333}],"con":true,"img":false}]}
{"op":"mcm","clk":"11541259955","pt":1719503892197,"mc":[{"id":"1.230178323","rc":[{"atb":[[4.1,0]],"id":70681333},{"atl":[[8.6,0]],"id":70681333}],"con":true,"img":false}]}
{"op":"mcm","clk":"11541259970","pt":1719503892304,"mc":[{"id":"1.230178323","rc":[{"atb":[[4.2,8.46]],"id":70681333},{"atl":[[8.2,7.58]],"id":70681333},{"atl":[[2.66,0]],"id":51569790}],"con":true,"img":false}]}
{"op":"mcm","clk":"11541259993","pt":1719503892504,"mc":[{"id":"1.230178323","rc":[{"atb":[[3.45,0]],"id":70681333}],"con":true,"img":false}]}
{"op":"mcm","clk":"11541260021","pt":1719503892713,"mc":[{"id":"1.230178323","rc":[{"atb":[[3.2,5.34]],"id":47885365},{"atl":[[3.7,3.99],[3.8,0]],"id":60192591}],"con":true,"img":false}]}
{"op":"mcm","clk":"11541260036","pt":1719503892824,"mc":[{"id":"1.230178323","rc":[{"atl":[[3.9,0]],"id":60192591}],"con":true,"img":false}]}
{"op":"mcm","clk":"11541260064","pt":1719503893025,"mc":[{"id":"1.230178323","rc":[{"atb":[[2.74,1.6]],"id":47885365}],"con":true,"img":false}]}
{"op":"mcm","clk":"11541260101","pt":1719503893325,"mc":[{"id":"1.230178323","rc":[{"atl":[[2.64,0]],"id":51569790}],"con":true,"img":false}]}
{"op":"mcm","clk":"11541260149","pt":1719503893697,"mc":[{"id":"1.230178323","rc":[{"atl":[[3.75,2.56]],"id":60192591}],"con":true,"img":false}]}
{"op":"mcm","clk":"11541260158","pt":1719503893796,"mc":[{"id":"1.230178323","rc":[{"atl":[[2.58,5.46]],"id":51569790},{"atl":[[3.65,0.84]],"id":60192591}],"con":true,"img":false}]}
{"op":"mcm","clk":"11541260181","pt":1719503894007,"mc":[{"id":"1.230178323","rc":[{"atl":[[2.6,0],[2.68,0]],"id":51569790}],"con":true,"img":false}]}
{"op":"mcm","clk":"11541260234","pt":1719503894417,"mc":[{"id":"1.230178323","rc":[{"atl":[[8,0.84]],"id":70681333},{"atl":[[2.62,0]],"id":51569790}],"con":true,"img":false}]}
{"op":"mcm","clk":"11541260251","pt":1719503894527,"mc":[{"id":"1.230178323","rc":[{"atl":[[3.65,8.78]],"id":60192591}],"con":true,"img":false}]}
{"op":"mcm","clk":"11541260261","pt":1719503894622,"mc":[{"id":"1.230178323","rc":[{"atl":[[8.2,6.58]],"id":70681333}],"con":true,"img":false}]}
{"op":"mcm","clk":"11541260288","pt":1719503894822,"mc":[{"id":"1.230178323","rc":[{"atb":[[3.25,0]],"id":70681333},{"atb":[[1.89,0]],"id":68274051},{"atl":[[2.6,2.54]],"id":51569790}],"con":true,"img":false}]}
{"op":"mcm","clk":"11541260304","pt":1719503894890,"mc":[{"id":"1.230178323","rc":[{"atb":[[1.91,3.71]],"id":68274051},{"atl":[[3.75,1.72]],"id":60192591}],"con":true,"img":false}]}
{"op":"mcm","clk":"11541260354","pt":1719503895304,"mc":[{"id":"1.230178323","rc":[{"atb":[[3.2,11.23]],"id":47885365},{"atl":[[2.74,4]],"id":51569790}],"con":true,"img":false}]}
{"op":"mcm","clk":"11541260380","pt":1719503895509,"mc":[{"id":"1.230178323","rc":[{"atl":[[2.74,0]],"id":51569790}],"con":true,"img":false}]}
{"op":"mcm","clk":"11541260391","pt":1719503895609,"mc":[{"id":"1.230178323","rc":[{"atl":[[2.56,0.52]],"id":51569790}],"con":true,"img":false}]}
{"op":"mcm","clk":"11541260403","pt":1719503895717,"mc":[{"id":"1.230178323","rc":[{"atb":[[1.78,0.67]],"id":51569790},{"atl":[[1000,0.24]],"id":60192591}],"con":true,"img":false}]}
{"op":"mcm","clk":"11541260427","pt":1719503895918,"mc":[{"id":"1.230178323","rc":[{"atb":[[1.9,5.65]],"id":68274051},{"atl":[[1000,0]],"id":60192591}],"con":true,"img":false}]}
{"op":"mcm","clk":"11541260440","pt":1719503896023,"mc":[{"id":"1.230178323","rc":[{"atb":[[1.92,2]],"id":68274051},{"atl":[[3.6,0.24]],"id":60192591}],"con":true,"img":false}]}
{"op":"mcm","clk":"11541260452","pt":1719503896119,"mc":[{"id":"1.230178323","rc":[{"atl":[[2.54,1]],"id":51569790}],"con":true,"img":false}]}
{"op":"mcm","clk":"11541260532","pt":1719503896821,"mc":[{"id":"1.230178323","rc":[{"atl":[[5.1,25.06],[4.4,1]],"id":63650892}],"con":true,"img":false}]}
{"op":"mcm","clk":"11541260541","pt":1719503896896,"mc":[{"id":"1.230178323","rc":[{"atl":[[7.8,1]],"id":70681333}],"con":true,"img":false}]}
{"op":"mcm","clk":"11541260583","pt":1719503897314,"mc":[{"id":"1.230178323","rc":[{"atb":[[1.14,24.66],[1.08,50]],"id":70681333},{"atb":[[2.2,5],[2.14,0]],"id":63650892},{"atb":[[1.51,0]],"id":68274051},{"atl":[[3.65,10.57]],"id":60192591}],"con":true,"img":false}]}
{"op":"mcm","clk":"11541260594","pt":1719503897416,"mc":[{"id":"1.230178323","rc":[{"atl":[[8.4,0]],"id":70681333},{"atl":[[2.6,0]],"id":51569790}],"con":true,"img":false}]}
{"op":"mcm","clk":"11541260668","pt":1719503898094,"mc":[{"id":"1.230178323","rc":[{"atl":[[3.6,0],[3.5,1]],"id":68274051},{"atl":[[7.2,0]],"id":60192591}],"con":true,"img":false}]}
{"op":"mcm","clk":"11541260680","pt":1719503898192,"mc":[{"id":"1.230178323","rc":[{"atl":[[3.6,9.26],[3.95,2.5]],"id":68274051}],"con":true,"img":false}]}
{"op":"mcm","clk":"11541260691","pt":1719503898299,"mc":[{"id":"1.230178323","rc":[{"atl":[[3.6,0],[3.95,12.5]],"id":68274051}],"con":true,"img":false}]}
{"op":"mcm","clk":"11541260702","pt":1719503898397,"mc":[{"id":"1.230178323","rc":[{"atb":[[1.61,0]],"id":68274051},{"atl":[[3.6,5.63],[3.95,2.5]],"id":68274051}],"con":true,"img":false}]}
{"op":"mcm","clk":"11541260714","pt":1719503898505,"mc":[{"id":"1.230178323","rc":[{"atl":[[3.6,0],[3.95,12.5]],"id":68274051}],"con":true,"img":false}]}
{"op":"mcm","clk":"11541260724","pt":1719503898611,"mc":[{"id":"1.230178323","rc":[{"atl":[[3.6,5.63]],"id":68274051},{"atl":[[2.56,3.06]],"id":51569790}],"con":true,"img":false}]}
{"op":"mcm","clk":"11541260734","pt":1719503898708,"mc":[{"id":"1.230178323","rc":[{"atb":[[1.8,6.91]],"id":68274051},{"atl":[[3.95,2.5]],"id":68274051}],"con":true,"img":false}]}
{"op":"mcm","clk":"11541260858","pt":1719503899896,"mc":[{"id":"1.230178323","rc":[{"atb":[[1.8,14.32]],"id":68274051}],"con":true,"img":false}]}
{"op":"mcm","clk":"11541261006","pt":1719503901392,"mc":[{"id":"1.230178323","rc":[{"atb":[[3.1,2.17]],"id":60192591},{"trd":[[3.1,4.62]],"ltp":3.1,"tv":4.62,"id":60192591}],"con":true,"img":false}]}
{"op":"mcm","clk":"11541261055","pt":1719503901911,"mc":[{"id":"1.230178323","rc":[{"atl":[[3.6,6.63],[3.5,0]],"id":68274051}],"con":true,"img":false}]}
{"op":"mcm","clk":"11541261138","pt":1719503902627,"mc":[{"id":"1.230178323","rc":[{"atb":[[1.92,8.26]],"id":68274051}],"con":true,"img":false}]}
{"op":"mcm","clk":"11541261150","pt":1719503902728,"mc":[{"id":"1.230178323","rc":[{"atb":[[4.3,4.1]],"id":70681333},{"atb":[[1.9,0]],"id":68274051},{"atl":[[3.6,1.24]],"id":60192591}],"con":true,"img":false}]}
{"op":"mcm","clk":"11541261159","pt":1719503902829,"mc":[{"id":"1.230178323","rc":[{"atl":[[3.6,1],[3.95,13.76]],"id":68274051}],"con":true,"img":false}]}
{"op":"mcm","clk":"11541261170","pt":1719503902933,"mc":[{"id":"1.230178323","rc":[{"atb":[[4,0]],"id":70681333},{"spn":6.05,"spf":"NaN","id":70681333},{"spn":4.7,"spf":"NaN","id":47885365},{"spn":2.46,"spf":1.0,"id":63650892},{"spn":2.53,"spf":"NaN","id":68274051},{"spn":2.16,"spf":"NaN","id":51569790},{"atl":[[3.75,0]],"id":60192591},{"spn":3.35,"spf":"NaN","id":60192591}],"con":true,"img":false}]}
{"op":"mcm","clk":"11541261183","pt":1719503902993,"mc":[{"id":"1.230178323","rc":[{"atb":[[4.2,1.94]],"id":70681333},{"atl":[[3.65,2.63]],"id":60192591}],"con":true,"img":false}]}
{"op":"mcm","clk":"11541261205","pt":1719503903202,"mc":[{"id":"1.230178323","rc":[{"atb":[[2.72,0],[2.78,24.98]],"id":47885365}],"con":true,"img":false}]}
{"op":"mcm","clk":"11541261228","pt":1719503903406,"mc":[{"id":"1.230178323","rc":[{"atb":[[4.2,0]],"id":70681333}],"con":true,"img":false}]}
{"op":"mcm","clk":"11541261248","pt":1719503903611,"mc":[{"id":"1.230178323","rc":[{"atb":[[4.3,0],[4.4,1.94]],"id":70681333}],"con":true,"img":false}]}
{"op":"mcm","clk":"11541261258","pt":1719503903715,"mc":[{"id":"1.230178323","rc":[{"atb":[[4.4,4.15]],"id":70681333},{"atb":[[3.1,0]],"id":60192591}],"con":true,"img":false}]}
{"op":"mcm","clk":"11541261273","pt":1719503903818,"mc":[{"id":"1.230178323","rc":[{"atb":[[3.05,3.86],[2.7,7.5]],"id":60192591}],"con":true,"img":false}]}
{"op":"mcm","clk":"11541261286","pt":1719503903919,"mc":[{"id":"1.230178323","rc":[{"atb":[[1.02,22.65]],"id":70681333},{"atb":[[1.91,0]],"id":68274051},{"atb":[[2.78,0]],"id":60192591},{"atl":[[3.6,9.14]],"id":60192591}],"con":true,"img":false}]}
{"op":"mcm","clk":"11541261297","pt":1719503904024,"mc":[{"id":"1.230178323","rc":[{"atb":[[4.4,6.15]],"id":70681333},{"atb":[[1.93,2.62]],"id":68274051}],"con":true,"img":false}]}
{"op":"mcm","clk":"11541261328","pt":1719503904326,"mc":[{"id":"1.230178323","rc":[{"atl":[[7.8,6.62]],"id":70681333}],"con":true,"img":false}]}
{"op":"mcm","clk":"11541261340","pt":1719503904429,"mc":[{"id":"1.230178323","rc":[{"atl":[[3.55,0.84]],"id":60192591}],"con":true,"img":false}]}
{"op":"mcm","clk":"11541261352","pt":1719503904533,"mc":[{"id":"1.230178323","rc":[{"atl":[[8.2,2.9]],"id":70681333}],"con":true,"img":false}]}
{"op":"mcm","clk":"11541261370","pt":1719503904698,"mc":[{"id":"1.230178323","rc":[{"atl":[[8.2,0]],"id":70681333}],"con":true,"img":false}]}
{"op":"mcm","clk":"11541261392","pt":1719503904906,"mc":[{"id":"1.230178323","rc":[{"atl":[[7.6,0.84]],"id":70681333}],"con":true,"img":false}]}
{"op":"mcm","clk":"11541261408","pt":1719503905109,"mc":[{"id":"1.230178323","rc":[{"atl":[[7.8,5.62]],"id":70681333}],"con":true,"img":false}]}
{"op":"mcm","clk":"11541261429","pt":1719503905314,"mc":[{"id":"1.230178323","rc":[{"atl":[[7.6,4.16]],"id":70681333},{"atb":[[1.92,6.26]],"id":68274051}],"con":true,"img":false}]}
{"op":"mcm","clk":"11541261439","pt":1719503905420,"mc":[{"id":"1.230178323","rc":[{"atb":[[1.94,2]],"id":68274051}],"con":true,"img":false}]}
{"op":"mcm","clk":"11541261489","pt":1719503905929,"mc":[{"id":"1.230178323","rc":[{"atl":[[8,0]],"id":70681333}],"con":true,"img":false}]}
{"op":"mcm","clk":"11541261502","pt":1719503906033,"mc":[{"id":"1.230178323","rc":[{"atb":[[2.44,3.71]],"id":63650892},{"atb":[[1.88,5.56]],"id":68274051},{"atb":[[1.62,5.24]],"id":51569790},{"atl":[[2.62,3.74]],"id":51569790}],"con":true,"img":false}]}
{"op":"mcm","clk":"11541261525","pt":1719503906237,"mc":[{"id":"1.230178323","rc":[{"atb":[[1.83,0],[1.79,0],[1.88,4.63],[1.75,0]],"id":68274051},{"atl":[[2.62,0],[2.52,5.46]],"id":51569790},{"atl":[[7.4,0],[6.6,0]],"id":60192591}],"con":true,"img":false}]}
{"op":"mcm","clk":"11541261553","pt":1719503906415,"mc":[{"id":"1.230178323","rc":[{"atl":[[2.54,0],[2.58,0]],"id":51569790}],"con":true,"img":false}]}
{"op":"mcm","clk":"11541261563","pt":1719503906511,"mc":[{"id":"1.230178323","rc":[{"atl":[[3.7,0],[3.5,0]],"id":51569790}],"con":true,"img":false}]}
{"op":"mcm","clk":"11541261573","pt":1719503906606,"mc":[{"id":"1.230178323","rc":[{"atb":[[1.88,0]],"id":68274051}],"con":true,"img":false}]}
{"op":"mcm","clk":"11541261585","pt":1719503906713,"mc":[{"id":"1.230178323","rc":[{"atb":[[1.81,5],[1.85,2.5]],"id":68274051}],"con":true,"img":false}]}
{"op":"mcm","clk":"11541261604","pt":1719503906920,"mc":[{"id":"1.230178323","rc":[{"atl":[[2.5,0.84]],"id":51569790}],"con":true,"img":false}]}
{"op":"mcm","clk":"11541261614","pt":1719503907022,"mc":[{"id":"1.230178323","rc":[{"atl":[[7.4,1]],"id":70681333}],"con":true,"img":false}]}
{"op":"mcm","clk":"11541261728","pt":1719503908221,"mc":[{"id":"1.230178323","rc":[{"atl":[[9,1],[9.2,0]],"id":70681333},{"atb":[[2.86,2.5],[2.62,1]],"id":47885365},{"atl":[[5.1,22.56],[5,2.5],[5.5,0],[5.9,0],[5.4,5]],"id":63650892},{"atl":[[3.6,14.28],[3.65,0.84]],"id":60192591}],"con":true,"img":false}]}
{"op":"mcm","clk":"11541261801","pt":1719503908856,"mc":[{"id":"1.230178323","rc":[{"atb":[[2.76,10.96]],"id":47885365}],"con":true,"img":false}]}
{"op":"mcm","clk":"11541261812","pt":1719503908942,"mc":[{"id":"1.230178323","rc":[{"atb":[[2.88,22.48],[2.78,2.5]],"id":47885365}],"con":true,"img":false}]}
{"op":"mcm","clk":"11541261822","pt":1719503909036,"mc":[{"id":"1.230178323","rc":[{"atl":[[2.56,0.52],[2.48,1]],"id":51569790}],"con":true,"img":false}]}
{"op":"mcm","clk":"11541261915","pt":1719503909820,"mc":[{"id":"1.230178323","rc":[{"atb":[[2.76,0]],"id":47885365}],"con":true,"img":false}]}
{"op":"mcm","clk":"11541262042","pt":1719503911044,"mc":[{"id":"1.230178323","rc":[{"atb":[[1.78,0]],"id":51569790}],"con":true,"img":false}]}
{"op":"mcm","clk":"11541262078","pt":1719503911311,"mc":[{"id":"1.230178323","rc":[{"atl":[[2.56,0]],"id":51569790}],"con":true,"img":false}]}
{"op":"mcm","clk":"11541262109","pt":1719503911627,"mc":[{"id":"1.230178323","rc":[{"atl":[[2.48,3.54]],"id":51569790},{"atl":[[3.6,14.04]],"id":60192591}],"con":true,"img":false}]}
{"op":"mcm","clk":"11541262126","pt":1719503911829,"mc":[{"id":"1.230178323","rc":[{"atl":[[2.46,0.52]],"id":51569790}],"con":true,"img":false}]}
{"op":"mcm","clk":"11541262138","pt":1719503911936,"mc":[{"id":"1.230178323","rc":[{"atb":[[1.78,0.67]],"id":51569790}],"con":true,"img":false}]}
