{"op":"mcm","clk":"11536380646","pt":1719425245582,"mc":[{"id":"1.230178310","marketDefinition":{"bspMarket":true,"turnInPlayEnabled":false,"persistenceEnabled":false,"marketBaseRate":5.0,"eventId":"33376062","eventTypeId":"4339","numberOfWinners":1,"bettingType":"ODDS","marketType":"WIN","marketTime":"2024-06-27T14:13:00.000Z","suspendTime":"2024-06-27T14:13:00.000Z","bspReconciled":false,"complete":true,"inPlay":false,"crossMatching":false,"runnersVoidable":false,"numberOfActiveRunners":6,"betDelay":0,"status":"OPEN","runners":[{"status":"ACTIVE","sortPriority":1,"id":57087188,"name":"1. Ballymac Boomer"},{"status":"ACTIVE","sortPriority":2,"id":57088863,"name":"2. Ferryfort Native"},{"status":"ACTIVE","sortPriority":3,"id":55302014,"name":"3. Blue The Woofoff"},{"status":"ACTIVE","sortPriority":4,"id":65436514,"name":"4. Leticias Pride"},{"status":"ACTIVE","sortPriority":5,"id":68392143,"name":"5. Springfield Best"},{"status":"ACTIVE","sortPriority":6,"id":69142441,"name":"6. Ferndale Tok"}],"regulators":["MR_INT"],"venue":"Kinsley","countryCode":"GB","discountAllowed":false,"timezone":"Europe/London","openDate":"2024-06-27T13:36:00.000Z","version":5994643747,"name":"A3 462m","eventName":"Kinsley 27th Jun"},"rc":[],"con":true,"img":false}]}
{"op":"mcm","clk":"11536381014","pt":1719425248523,"mc":[{"id":"1.230178310","marketDefinition":{"bspMarket":true,"turnInPlayEnabled":false,"persistenceEnabled":false,"marketBaseRate":5.0,"eventId":"33376062","eventTypeId":"4339","numberOfWinners":1,"bettingType":"ODDS","marketType":"WIN","marketTime":"2024-06-27T14:13:00.000Z","suspendTime":"2024-06-27T14:13:00.000Z","bspReconciled":false,"complete":true,"inPlay":false,"crossMatching":false,"runnersVoidable":false,"numberOfActiveRunners":6,"betDelay":0,"status":"OPEN","runners":[{"status":"ACTIVE","sortPriority":1,"id":57087188,"name":"1. Ballymac Boomer"},{"status":"ACTIVE","sortPriority":2,"id":57088863,"name":"2. Ferryfort Native"},{"status":"ACTIVE","sortPriority":3,"id":55302014,"name":"3. Blue The Woofoff"},{"status":"ACTIVE","sortPriority":4,"id":65436514,"name":"4. Leticias Pride"},{"status":"ACTIVE","sortPriority":5,"id":68392143,"name":"5. Springfield Best"},{"status":"ACTIVE","sortPriority":6,"id":69142441,"name":"6. Ferndale Tok"}],"regulators":["MR_INT"],"venue":"Kinsley","countryCode":"GB","discountAllowed":true,"timezone":"Europe/London","openDate":"2024-06-27T13:36:00.000Z","version":5994643747,"name":"A3 462m","eventName":"Kinsley 27th Jun"},"rc":[],"con":true,"img":false}]}
{"op":"mcm","clk":"11536614533","pt":1719428235795,"mc":[{"id":"1.230178310","rc":[{"atb":[[1.01,23.65]],"id":57087188},{"atl":[[990,0.84]],"id":57087188},{"spn":495.5,"spf":"NaN","id":57087188},{"atb":[[1.03,7.88]],"id":65436514},{"atl":[[990,0.84]],"id":65436514},{"spn":495.51,"spf":"NaN","id":65436514},{"atb":[[1.01,23.65]],"id":69142441},{"atl":[[990,0.84]],"id":69142441},{"spn":495.5,"spf":"NaN","id":69142441},{"atb":[[1.03,7.88]],"id":55302014},{"atl":[[990,0.84]],"id":55302014},{"spn":495.51,"spf":"NaN","id":55302014},{"atb":[[1.02,11.82]],"id":68392143},{"atl":[[1000,0.84]],"id":68392143},{"spn":500.51,"spf":"NaN","id":68392143},{"atb":[[1.03,7.88]],"id":57088863},{"atl":[[990,0.84]],"id":57088863},{"spn":495.51,"spf":"NaN","id":57088863}],"con":true,"img":false}]}
{"op":"mcm","clk":"11536836681","pt":1719431846828,"mc":[{"id":"1.230178310","rc":[{"atb":[[1.01,23.66]],"id":57087188},{"atl":[[990,0.22]],"id":57087188},{"atb":[[1.03,7.88]],"id":65436514},{"atl":[[990,0.22]],"id":65436514},{"atb":[[1.01,23.66]],"id":69142441},{"atl":[[990,0.22]],"id":69142441},{"atb":[[1.03,7.88]],"id":55302014},{"atl":[[990,0.22]],"id":55302014},{"atb":[[1.02,11.82]],"id":68392143},{"atl":[[1000,0.22]],"id":68392143},{"atb":[[1.03,7.88]],"id":57088863},{"atl":[[990,0.22]],"id":57088863}],"con":true,"img":false}]}
{"op":"mcm","clk":"11537232248","pt":1719437882517,"mc":[{"id":"1.230178310","marketDefinition":{"bspMarket":true,"turnInPlayEnabled":false,"persistenceEnabled":false,"marketBaseRate":5.0,"eventId":"33376062","eventTypeId":"4339","numberOfWinners":1,"bettingType":"ODDS","marketType":"WIN","marketTime":"2024-06-27T14:13:00.000Z","suspendTime":"2024-06-27T14:13:00.000Z","bspReconciled":false,"complete":true,"inPlay":false,"crossMatching":false,"runnersVoidable":false,"numberOfActiveRunners":6,"betDelay":0,"status":"OPEN","runners":[{"status":"ACTIVE","sortPriority":1,"id":57087188,"name":"1. Ballymac Boomer"},{"status":"ACTIVE","sortPriority":2,"id":57088863,"name":"2. Ferryfort Native"},{"status":"ACTIVE","sortPriority":3,"id":55302014,"name":"3. Blue The Woofoff"},{"status":"ACTIVE","sortPriority":4,"id":65436514,"name":"4. Leticias Pride"},{"status":"ACTIVE","sortPriority":5,"id":68392143,"name":"5. Springfield Best"},{"status":"ACTIVE","sortPriority":6,"id":69142441,"name":"6. Ferndale Tok"}],"regulators":["MR_INT"],"venue":"Kinsley","countryCode":"GB","discountAllowed":true,"timezone":"Europe/London","openDate":"2024-06-27T13:36:00.000Z","version":5994643747,"name":"A3 462m","eventName":"Kinsley 27th Jun"},"rc":[{"atb":[[1.01,23.66]],"id":57087188},{"atl":[[990,0.22]],"id":57087188},{"spn":495.5,"spf":"NaN","id":57087188},{"atb":[[1.03,7.88]],"id":65436514},{"atl":[[990,0.22]],"id":65436514},{"spn":495.51,"spf":"NaN","id":65436514},{"atb":[[1.01,23.66]],"id":69142441},{"atl":[[990,0.22]],"id":69142441},{"spn":495.5,"spf":"NaN","id":69142441},{"atb":[[1.03,7.88]],"id":55302014},{"atl":[[990,0.22]],"id":55302014},{"spn":495.51,"spf":"NaN","id":55302014},{"atb":[[1.02,11.82]],"id":68392143},{"atl":[[1000,0.22]],"id":68392143},{"spn":500.51,"spf":"NaN","id":68392143},{"atb":[[1.03,7.88]],"id":57088863},{"atl":[[990,0.22]],"id":57088863},{"spn":495.51,"spf":"NaN","id":57088863}],"con":true,"img":true}]}
{"op":"mcm","clk":"11537573375","pt":1719443282536,"mc":[{"id":"1.230178310","marketDefinition":{"bspMarket":true,"turnInPlayEnabled":false,"persistenceEnabled":false,"marketBaseRate":5.0,"eventId":"33376062","eventTypeId":"4339","numberOfWinners":1,"bettingType":"ODDS","marketType":"WIN","marketTime":"2024-06-27T14:13:00.000Z","suspendTime":"2024-06-27T14:13:00.000Z","bspReconciled":false,"complete":true,"inPlay":false,"crossMatching":false,"runnersVoidable":false,"numberOfActiveRunners":6,"betDelay":0,"status":"OPEN","runners":[{"status":"ACTIVE","sortPriority":1,"id":57087188,"name":"1. Ballymac Boomer"},{"status":"ACTIVE","sortPriority":2,"id":57088863,"name":"2. Ferryfort Native"},{"status":"ACTIVE","sortPriority":3,"id":55302014,"name":"3. Blue The Woofoff"},{"status":"ACTIVE","sortPriority":4,"id":65436514,"name":"4. Leticias Pride"},{"status":"ACTIVE","sortPriority":5,"id":68392143,"name":"5. Springfield Best"},{"status":"ACTIVE","sortPriority":6,"id":69142441,"name":"6. Ferndale Tok"}],"regulators":["MR_INT"],"venue":"Kinsley","countryCode":"GB","discountAllowed":true,"timezone":"Europe/London","openDate":"2024-06-27T13:36:00.000Z","version":5994643747,"name":"A3 462m","eventName":"Kinsley 27th Jun"},"rc":[{"atb":[[1.01,23.66]],"id":57087188},{"atl":[[990,0.22]],"id":57087188},{"spn":495.5,"spf":"NaN","id":57087188},{"atb":[[1.03,7.88]],"id":65436514},{"atl":[[990,0.22]],"id":65436514},{"spn":495.51,"spf":"NaN","id":65436514},{"atb":[[1.01,23.66]],"id":69142441},{"atl":[[990,0.22]],"id":69142441},{"spn":495.5,"spf":"NaN","id":69142441},{"atb":[[1.03,7.88]],"id":55302014},{"atl":[[990,0.22]],"id":55302014},{"spn":495.51,"spf":"NaN","id":55302014},{"atb":[[1.02,11.83]],"id":68392143},{"atl":[[1000,0.22]],"id":68392143},{"spn":500.51,"spf":"NaN","id":68392143},{"atb":[[1.03,7.88]],"id":57088863},{"atl":[[990,0.22]],"id":57088863},{"spn":495.51,"spf":"NaN","id":57088863}],"con":true,"img":true}]}
{"op":"mcm","clk":"11537954935","pt":1719448682560,"mc":[{"id":"1.230178310","marketDefinition":{"bspMarket":true,"turnInPlayEnabled":false,"persistenceEnabled":false,"marketBaseRate":5.0,"eventId":"33376062","eventTypeId":"4339","numberOfWinners":1,"bettingType":"ODDS","marketType":"WIN","marketTime":"2024-06-27T14:13:00.000Z","suspendTime":"2024-06-27T14:13:00.000Z","bspReconciled":false,"complete":true,"inPlay":false,"crossMatching":false,"runnersVoidable":false,"numberOfActiveRunners":6,"betDelay":0,"status":"OPEN","runners":[{"status":"ACTIVE","sortPriority":1,"id":57087188,"name":"1. Ballymac Boomer"},{"status":"ACTIVE","sortPriority":2,"id":57088863,"name":"2. Ferryfort Native"},{"status":"ACTIVE","sortPriority":3,"id":55302014,"name":"3. Blue The Woofoff"},{"status":"ACTIVE","sortPriority":4,"id":65436514,"name":"4. Leticias Pride"},{"status":"ACTIVE","sortPriority":5,"id":68392143,"name":"5. Springfield Best"},{"status":"ACTIVE","sortPriority":6,"id":69142441,"name":"6. Ferndale Tok"}],"regulators":["MR_INT"],"venue":"Kinsley","countryCode":"GB","discountAllowed":true,"timezone":"Europe/London","openDate":"2024-06-27T13:36:00.000Z","version":5994643747,"name":"A3 462m","eventName":"Kinsley 27th Jun"},"rc":[{"atb":[[1.01,23.66]],"id":57087188},{"atl":[[990,0.22]],"id":57087188},{"spn":495.5,"spf":"NaN","id":57087188},{"atb":[[1.03,7.88]],"id":65436514},{"atl":[[990,0.22]],"id":65436514},{"spn":495.51,"spf":"NaN","id":65436514},{"atb":[[1.01,23.66]],"id":69142441},{"atl":[[990,0.22]],"id":69142441},{"spn":495.5,"spf":"NaN","id":69142441},{"atb":[[1.03,7.88]],"id":55302014},{"atl":[[990,0.22]],"id":55302014},{"spn":495.51,"spf":"NaN","id":55302014},{"atb":[[1.02,11.82]],"id":68392143},{"atl":[[1000,0.22]],"id":68392143},{"spn":500.51,"spf":"NaN","id":68392143},{"atb":[[1.03,7.88]],"id":57088863},{"atl":[[990,0.22]],"id":57088863},{"spn":495.51,"spf":"NaN","id":57088863}],"con":true,"img":true}]}
{"op":"mcm","clk":"11538170598","pt":1719454082543,"mc":[{"id":"1.230178310","marketDefinition":{"bspMarket":true,"turnInPlayEnabled":false,"persistenceEnabled":false,"marketBaseRate":5.0,"eventId":"33376062","eventTypeId":"4339","numberOfWinners":1,"bettingType":"ODDS","marketType":"WIN","marketTime":"2024-06-27T14:13:00.000Z","suspendTime":"2024-06-27T14:13:00.000Z","bspReconciled":false,"complete":true,"inPlay":false,"crossMatching":false,"runnersVoidable":false,"numberOfActiveRunners":6,"betDelay":0,"status":"OPEN","runners":[{"status":"ACTIVE","sortPriority":1,"id":57087188,"name":"1. Ballymac Boomer"},{"status":"ACTIVE","sortPriority":2,"id":57088863,"name":"2. Ferryfort Native"},{"status":"ACTIVE","sortPriority":3,"id":55302014,"name":"3. Blue The Woofoff"},{"status":"ACTIVE","sortPriority":4,"id":65436514,"name":"4. Leticias Pride"},{"status":"ACTIVE","sortPriority":5,"id":68392143,"name":"5. Springfield Best"},{"status":"ACTIVE","sortPriority":6,"id":69142441,"name":"6. Ferndale Tok"}],"regulators":["MR_INT"],"venue":"Kinsley","countryCode":"GB","discountAllowed":true,"timezone":"Europe/London","openDate":"2024-06-27T13:36:00.000Z","version":5994643747,"name":"A3 462m","eventName":"Kinsley 27th Jun"},"rc":[{"atb":[[1.01,23.67]],"id":57087188},{"atl":[[990,0.22]],"id":57087188},{"spn":495.5,"spf":"NaN","id":57087188},{"atb":[[1.03,7.88]],"id":65436514},{"atl":[[990,0.22]],"id":65436514},{"spn":495.51,"spf":"NaN","id":65436514},{"atb":[[1.01,23.67]],"id":69142441},{"atl":[[990,0.22]],"id":69142441},{"spn":495.5,"spf":"NaN","id":69142441},{"atb":[[1.03,7.88]],"id":55302014},{"atl":[[990,0.22]],"id":55302014},{"spn":495.51,"spf":"NaN","id":55302014},{"atb":[[1.02,11.83]],"id":68392143},{"atl":[[1000,0.22]],"id":68392143},{"spn":500.51,"spf":"NaN","id":68392143},{"atb":[[1.03,7.88]],"id":57088863},{"atl":[[990,0.22]],"id":57088863},{"spn":495.51,"spf":"NaN","id":57088863}],"con":true,"img":true}]}
{"op":"mcm","clk":"11538368256","pt":1719459482572,"mc":[{"id":"1.230178310","marketDefinition":{"bspMarket":true,"turnInPlayEnabled":false,"persistenceEnabled":false,"marketBaseRate":5.0,"eventId":"33376062","eventTypeId":"4339","numberOfWinners":1,"bettingType":"ODDS","marketType":"WIN","marketTime":"2024-06-27T14:13:00.000Z","suspendTime":"2024-06-27T14:13:00.000Z","bspReconciled":false,"complete":true,"inPlay":false,"crossMatching":false,"runnersVoidable":false,"numberOfActiveRunners":6,"betDelay":0,"status":"OPEN","runners":[{"status":"ACTIVE","sortPriority":1,"id":57087188,"name":"1. Ballymac Boomer"},{"status":"ACTIVE","sortPriority":2,"id":57088863,"name":"2. Ferryfort Native"},{"status":"ACTIVE","sortPriority":3,"id":55302014,"name":"3. Blue The Woofoff"},{"status":"ACTIVE","sortPriority":4,"id":65436514,"name":"4. Leticias Pride"},{"status":"ACTIVE","sortPriority":5,"id":68392143,"name":"5. Springfield Best"},{"status":"ACTIVE","sortPriority":6,"id":69142441,"name":"6. Ferndale Tok"}],"regulators":["MR_INT"],"venue":"Kinsley","countryCode":"GB","discountAllowed":true,"timezone":"Europe/London","openDate":"2024-06-27T13:36:00.000Z","version":5994643747,"name":"A3 462m","eventName":"Kinsley 27th Jun"},"rc":[{"atb":[[1.01,23.67]],"id":57087188},{"atl":[[990,0.22]],"id":57087188},{"spn":495.5,"spf":"NaN","id":57087188},{"atb":[[1.03,7.88]],"id":65436514},{"atl":[[990,0.22]],"id":65436514},{"spn":495.51,"spf":"NaN","id":65436514},{"atb":[[1.01,23.67]],"id":69142441},{"atl":[[990,0.22]],"id":69142441},{"spn":495.5,"spf":"NaN","id":69142441},{"atb":[[1.03,7.88]],"id":55302014},{"atl":[[990,0.22]],"id":55302014},{"spn":495.51,"spf":"NaN","id":55302014},{"atb":[[1.02,11.83]],"id":68392143},{"atl":[[1000,0.22]],"id":68392143},{"spn":500.51,"spf":"NaN","id":68392143},{"atb":[[1.03,7.88]],"id":57088863},{"atl":[[990,0.22]],"id":57088863},{"spn":495.51,"spf":"NaN","id":57088863}],"con":true,"img":true}]}
{"op":"mcm","clk":"11538595382","pt":1719464882542,"mc":[{"id":"1.230178310","marketDefinition":{"bspMarket":true,"turnInPlayEnabled":false,"persistenceEnabled":false,"marketBaseRate":5.0,"eventId":"33376062","eventTypeId":"4339","numberOfWinners":1,"bettingType":"ODDS","marketType":"WIN","marketTime":"2024-06-27T14:13:00.000Z","suspendTime":"2024-06-27T14:13:00.000Z","bspReconciled":false,"complete":true,"inPlay":false,"crossMatching":false,"runnersVoidable":false,"numberOfActiveRunners":6,"betDelay":0,"status":"OPEN","runners":[{"status":"ACTIVE","sortPriority":1,"id":57087188,"name":"1. Ballymac Boomer"},{"status":"ACTIVE","sortPriority":2,"id":57088863,"name":"2. Ferryfort Native"},{"status":"ACTIVE","sortPriority":3,"id":55302014,"name":"3. Blue The Woofoff"},{"status":"ACTIVE","sortPriority":4,"id":65436514,"name":"4. Leticias Pride"},{"status":"ACTIVE","sortPriority":5,"id":68392143,"name":"5. Springfield Best"},{"status":"ACTIVE","sortPriority":6,"id":69142441,"name":"6. Ferndale Tok"}],"regulators":["MR_INT"],"venue":"Kinsley","countryCode":"GB","discountAllowed":true,"timezone":"Europe/London","openDate":"2024-06-27T13:36:00.000Z","version":5994643747,"name":"A3 462m","eventName":"Kinsley 27th Jun"},"rc":[{"atb":[[1.01,23.67]],"id":57087188},{"atl":[[990,0.22]],"id":57087188},{"spn":495.5,"spf":"NaN","id":57087188},{"atb":[[1.03,7.88]],"id":65436514},{"atl":[[990,0.22]],"id":65436514},{"spn":495.51,"spf":"NaN","id":65436514},{"atb":[[1.01,23.67]],"id":69142441},{"atl":[[990,0.22]],"id":69142441},{"spn":495.5,"spf":"NaN","id":69142441},{"atb":[[1.03,7.88]],"id":55302014},{"atl":[[990,0.22]],"id":55302014},{"spn":495.51,"spf":"NaN","id":55302014},{"atb":[[1.02,11.83]],"id":68392143},{"atl":[[1000,0.22]],"id":68392143},{"spn":500.51,"spf":"NaN","id":68392143},{"atb":[[1.03,7.88]],"id":57088863},{"atl":[[990,0.22]],"id":57088863},{"spn":495.51,"spf":"NaN","id":57088863}],"con":true,"img":true}]}
{"op":"mcm","clk":"11538613501","pt":1719465193439,"mc":[{"id":"1.230178310","rc":[{"atb":[[1.01,23.67]],"id":57087188},{"atl":[[150,4]],"id":57087188},{"spn":75.5,"spf":"NaN","id":57087188},{"atb":[[1.03,7.88]],"id":65436514},{"atb":[[1.01,23.67]],"id":69142441},{"atb":[[1.03,7.88]],"id":55302014},{"atl":[[150,4]],"id":55302014},{"spn":75.51,"spf":"NaN","id":55302014},{"atb":[[1.02,11.83]],"id":68392143},{"atb":[[1.03,7.88]],"id":57088863},{"atl":[[150,4]],"id":57088863},{"spn":75.51,"spf":"NaN","id":57088863}],"con":true,"img":false}]}
{"op":"mcm","clk":"11538613507","pt":1719465193543,"mc":[{"id":"1.230178310","rc":[{"atl":[[150,4]],"id":65436514},{"atl":[[150,4]],"id":69142441},{"atl":[[150,4]],"id":68392143}],"con":true,"img":false}]}
{"op":"mcm","clk":"11538748508","pt":1719468202703,"mc":[{"id":"1.230178310","rc":[{"atb":[[2.08,11.55]],"id":57087188},{"spn":76.04,"spf":"NaN","id":57087188},{"atb":[[2.02,8.63]],"id":65436514},{"spn":76.01,"spf":"NaN","id":65436514},{"atb":[[2.08,9.77]],"id":69142441},{"spn":76.04,"spf":"NaN","id":69142441},{"atb":[[2.04,11.33]],"id":55302014},{"spn":76.02,"spf":"NaN","id":55302014},{"atb":[[2,10.25]],"id":68392143},{"spn":76.0,"spf":"NaN","id":68392143},{"atb":[[2.1,13.45]],"id":57088863},{"spn":76.05,"spf":"NaN","id":57088863}],"con":true,"img":false}]}
{"op":"mcm","clk":"11538751083","pt":1719468255050,"mc":[{"id":"1.230178310","rc":[{"atb":[[2.1,3.16]],"id":57087188}],"con":true,"img":false}]}
{"op":"mcm","clk":"11538751093","pt":1719468255255,"mc":[{"id":"1.230178310","rc":[{"atb":[[2.06,3.16]],"id":55302014}],"con":true,"img":false}]}
{"op":"mcm","clk":"11538751101","pt":1719468255459,"mc":[{"id":"1.230178310","rc":[{"atb":[[2.1,3.16]],"id":69142441}],"con":true,"img":false}]}
{"op":"mcm","clk":"11538751128","pt":1719468255967,"mc":[{"id":"1.230178310","rc":[{"atb":[[2.12,3.16]],"id":57088863}],"con":true,"img":false}]}
{"op":"mcm","clk":"11538751153","pt":1719468256484,"mc":[{"id":"1.230178310","rc":[{"atb":[[2.04,3.16]],"id":65436514},{"atb":[[2.02,3.16]],"id":68392143}],"con":true,"img":false}]}
{"op":"mcm","clk":"11538752370","pt":1719468281732,"mc":[{"id":"1.230178310","marketDefinition":{"bspMarket":true,"turnInPlayEnabled":false,"persistenceEnabled":false,"marketBaseRate":5.0,"eventId":"33376062","eventTypeId":"4339","numberOfWinners":1,"bettingType":"ODDS","marketType":"WIN","marketTime":"2024-06-27T14:13:00.000Z","suspendTime":"2024-06-27T14:13:00.000Z","bspReconciled":false,"complete":true,"inPlay":false,"crossMatching":true,"runnersVoidable":false,"numberOfActiveRunners":6,"betDelay":0,"status":"OPEN","runners":[{"status":"ACTIVE","sortPriority":1,"id":57087188,"name":"1. Ballymac Boomer"},{"status":"ACTIVE","sortPriority":2,"id":57088863,"name":"2. Ferryfort Native"},{"status":"ACTIVE","sortPriority":3,"id":55302014,"name":"3. Blue The Woofoff"},{"status":"ACTIVE","sortPriority":4,"id":65436514,"name":"4. Leticias Pride"},{"status":"ACTIVE","sortPriority":5,"id":68392143,"name":"5. Springfield Best"},{"status":"ACTIVE","sortPriority":6,"id":69142441,"name":"6. Ferndale Tok"}],"regulators":["MR_INT"],"venue":"Kinsley","countryCode":"GB","discountAllowed":true,"timezone":"Europe/London","openDate":"2024-06-27T13:36:00.000Z","version":5994643747,"name":"A3 462m","eventName":"Kinsley 27th Jun"},"rc":[],"con":true,"img":false}]}
{"op":"mcm","clk":"11538753319","pt":1719468298803,"mc":[{"id":"1.230178310","rc":[{"atb":[[2.1,6.55]],"id":57087188},{"spn":76.05,"spf":"NaN","id":57087188},{"atb":[[2.04,6.55]],"id":65436514},{"spn":76.02,"spf":"NaN","id":65436514},{"spn":76.05,"spf":"NaN","id":69142441},{"spn":76.03,"spf":"NaN","id":55302014},{"spn":76.01,"spf":"NaN","id":68392143},{"spn":76.06,"spf":"NaN","id":57088863}],"con":true,"img":false}]}
{"op":"mcm","clk":"11538753333","pt":1719468299110,"mc":[{"id":"1.230178310","rc":[{"atb":[[2.1,6.55]],"id":69142441},{"atb":[[2.06,6.55]],"id":55302014}],"con":true,"img":false}]}
{"op":"mcm","clk":"11538753374","pt":1719468299733,"mc":[{"id":"1.230178310","rc":[{"atb":[[2.02,6.55]],"id":68392143}],"con":true,"img":false}]}
{"op":"mcm","clk":"11538753394","pt":1719468300040,"mc":[{"id":"1.230178310","rc":[{"atb":[[2.12,6.55]],"id":57088863}],"con":true,"img":false}]}
{"op":"mcm","clk":"11538937099","pt":1719472045987,"mc":[{"id":"1.230178310","rc":[{"atb":[[1.01,23.65],[2.1,6.54],[2.08,11.54]],"id":57087188},{"atl":[[32,0.6],[990,0.22]],"id":57087188},{"spn":17.05,"spf":"NaN","id":57087188},{"atb":[[2.02,8.62],[1.03,7.88],[2.04,6.54]],"id":65436514},{"atl":[[990,0.22]],"id":65436514},{"atb":[[1.01,23.65],[2.1,6.54],[2.08,9.76]],"id":69142441},{"atl":[[990,0.22]],"id":69142441},{"atb":[[2.06,6.54],[1.03,7.88],[2.04,11.32]],"id":55302014},{"atl":[[990,0.22]],"id":55302014},{"atb":[[2,10.25],[2.02,6.54],[1.02,11.82]],"id":68392143},{"atl":[[1000,0.22]],"id":68392143},{"atb":[[1.03,7.88],[2.12,6.54],[2.1,13.44]],"id":57088863},{"atl":[[990,0.22]],"id":57088863}],"con":true,"img":false}]}
{"op":"mcm","clk":"11538940393","pt":1719472107834,"mc":[{"id":"1.230178310","rc":[{"atb":[[2.08,0]],"id":57087188},{"atb":[[2.02,0]],"id":65436514},{"atb":[[2.08,0]],"id":69142441},{"atb":[[2.04,0]],"id":55302014},{"atb":[[2,0]],"id":68392143},{"atb":[[2.1,0]],"id":57088863}],"con":true,"img":false}]}
{"op":"mcm","clk":"11538940401","pt":1719472107937,"mc":[{"id":"1.230178310","rc":[{"atb":[[2.12,11.54]],"id":57087188},{"atb":[[2.06,8.62]],"id":65436514},{"atb":[[2.12,9.76]],"id":69142441},{"atb":[[2.08,11.32]],"id":55302014},{"atb":[[2.04,10.25]],"id":68392143},{"atb":[[2.14,13.44]],"id":57088863}],"con":true,"img":false}]}
{"op":"mcm","clk":"11538944229","pt":1719472169120,"mc":[{"id":"1.230178310","rc":[{"spn":17.06,"spf":"NaN","id":57087188},{"spn":76.03,"spf":"NaN","id":65436514},{"spn":76.06,"spf":"NaN","id":69142441},{"atb":[[2.06,3.38]],"id":55302014},{"spn":76.04,"spf":"NaN","id":55302014},{"spn":76.02,"spf":"NaN","id":68392143},{"spn":76.07,"spf":"NaN","id":57088863}],"con":true,"img":false}]}
{"op":"mcm","clk":"11538944250","pt":1719472169526,"mc":[{"id":"1.230178310","rc":[{"atb":[[2.12,3.38]],"id":57088863}],"con":true,"img":false}]}
{"op":"mcm","clk":"11538944265","pt":1719472169731,"mc":[{"id":"1.230178310","rc":[{"atb":[[2.1,3.38]],"id":69142441}],"con":true,"img":false}]}
{"op":"mcm","clk":"11538944291","pt":1719472170242,"mc":[{"id":"1.230178310","rc":[{"atb":[[2.02,3.38]],"id":68392143}],"con":true,"img":false}]}
{"op":"mcm","clk":"11538944331","pt":1719472170856,"mc":[{"id":"1.230178310","rc":[{"atb":[[2.1,3.38]],"id":57087188}],"con":true,"img":false}]}
{"op":"mcm","clk":"11538944381","pt":1719472171611,"mc":[{"id":"1.230178310","rc":[{"atb":[[2.14,3.16]],"id":57087188}],"con":true,"img":false}]}
{"op":"mcm","clk":"11538944393","pt":1719472171765,"mc":[{"id":"1.230178310","rc":[{"atb":[[2.1,3.16]],"id":55302014}],"con":true,"img":false}]}
{"op":"mcm","clk":"11538944398","pt":1719472171821,"mc":[{"id":"1.230178310","rc":[{"atb":[[2.16,3.16]],"id":57088863}],"con":true,"img":false}]}
{"op":"mcm","clk":"11538944416","pt":1719472172229,"mc":[{"id":"1.230178310","rc":[{"atb":[[2.04,3.38]],"id":65436514}],"con":true,"img":false}]}
{"op":"mcm","clk":"11538944491","pt":1719472173456,"mc":[{"id":"1.230178310","rc":[{"atb":[[2.14,3.16]],"id":69142441}],"con":true,"img":false}]}
{"op":"mcm","clk":"11538944508","pt":1719472173662,"mc":[{"id":"1.230178310","rc":[{"atb":[[2.08,3.16]],"id":65436514}],"con":true,"img":false}]}
{"op":"mcm","clk":"11538944740","pt":1719472177449,"mc":[{"id":"1.230178310","rc":[{"atb":[[2.06,3.16]],"id":68392143}],"con":true,"img":false}]}
{"op":"mcm","clk":"11538945636","pt":1719472192554,"mc":[{"id":"1.230178310","rc":[{"atb":[[2.02,0]],"id":68392143}],"con":true,"img":false}]}
{"op":"mcm","clk":"11538945650","pt":1719472192856,"mc":[{"id":"1.230178310","rc":[{"atb":[[2.12,0]],"id":57088863}],"con":true,"img":false}]}
{"op":"mcm","clk":"11538945690","pt":1719472193372,"mc":[{"id":"1.230178310","rc":[{"atb":[[2.04,0]],"id":65436514}],"con":true,"img":false}]}
{"op":"mcm","clk":"11538945724","pt":1719472193889,"mc":[{"id":"1.230178310","rc":[{"atb":[[2.1,0]],"id":69142441}],"con":true,"img":false}]}
{"op":"mcm","clk":"11538945780","pt":1719472194664,"mc":[{"id":"1.230178310","rc":[{"atb":[[2.06,0]],"id":55302014}],"con":true,"img":false}]}
{"op":"mcm","clk":"11538945809","pt":1719472195075,"mc":[{"id":"1.230178310","rc":[{"atb":[[2.1,0]],"id":57087188}],"con":true,"img":false}]}
{"op":"mcm","clk":"11538946822","pt":1719472211376,"mc":[{"id":"1.230178310","rc":[{"atb":[[2.06,6.54]],"id":68392143}],"con":true,"img":false}]}
{"op":"mcm","clk":"11538946836","pt":1719472211682,"mc":[{"id":"1.230178310","rc":[{"atb":[[2.08,6.54]],"id":65436514}],"con":true,"img":false}]}
{"op":"mcm","clk":"11538946856","pt":1719472211989,"mc":[{"id":"1.230178310","rc":[{"atb":[[2.16,6.54]],"id":57088863}],"con":true,"img":false}]}
{"op":"mcm","clk":"11538946959","pt":1719472213784,"mc":[{"id":"1.230178310","rc":[{"atb":[[2.14,6.54]],"id":69142441}],"con":true,"img":false}]}
{"op":"mcm","clk":"11538946977","pt":1719472214090,"mc":[{"id":"1.230178310","rc":[{"atb":[[2.1,6.54]],"id":55302014}],"con":true,"img":false}]}
{"op":"mcm","clk":"11538946992","pt":1719472214394,"mc":[{"id":"1.230178310","rc":[{"atb":[[2.14,6.54]],"id":57087188}],"con":true,"img":false}]}
{"op":"mcm","clk":"11539122529","pt":1719475682548,"mc":[{"id":"1.230178310","marketDefinition":{"bspMarket":true,"turnInPlayEnabled":false,"persistenceEnabled":false,"marketBaseRate":5.0,"eventId":"33376062","eventTypeId":"4339","numberOfWinners":1,"bettingType":"ODDS","marketType":"WIN","marketTime":"2024-06-27T14:13:00.000Z","suspendTime":"2024-06-27T14:13:00.000Z","bspReconciled":false,"complete":true,"inPlay":false,"crossMatching":true,"runnersVoidable":false,"numberOfActiveRunners":6,"betDelay":0,"status":"OPEN","runners":[{"status":"ACTIVE","sortPriority":1,"id":57087188,"name":"1. Ballymac Boomer"},{"status":"ACTIVE","sortPriority":2,"id":57088863,"name":"2. Ferryfort Native"},{"status":"ACTIVE","sortPriority":3,"id":55302014,"name":"3. Blue The Woofoff"},{"status":"ACTIVE","sortPriority":4,"id":65436514,"name":"4. Leticias Pride"},{"status":"ACTIVE","sortPriority":5,"id":68392143,"name":"5. Springfield Best"},{"status":"ACTIVE","sortPriority":6,"id":69142441,"name":"6. Ferndale Tok"}],"regulators":["MR_INT"],"venue":"Kinsley","countryCode":"GB","discountAllowed":true,"timezone":"Europe/London","openDate":"2024-06-27T13:36:00.000Z","version":5994643747,"name":"A3 462m","eventName":"Kinsley 27th Jun"},"rc":[{"atb":[[1.01,23.66],[2.12,11.54],[2.14,6.55]],"id":57087188},{"atl":[[32,0.6],[150,4],[990,0.22]],"id":57087188},{"spn":17.07,"spf":"NaN","id":57087188},{"atb":[[2.06,8.63],[1.03,7.88],[2.08,6.55]],"id":65436514},{"atl":[[150,4],[990,0.22]],"id":65436514},{"spn":76.04,"spf":"NaN","id":65436514},{"atb":[[1.01,23.66],[2.12,9.77],[2.14,6.55]],"id":69142441},{"atl":[[150,4],[990,0.22]],"id":69142441},{"spn":76.07,"spf":"NaN","id":69142441},{"atb":[[1.03,7.88],[2.1,6.55],[2.08,11.32]],"id":55302014},{"atl":[[150,4],[990,0.22]],"id":55302014},{"spn":76.05,"spf":"NaN","id":55302014},{"atb":[[2.06,6.55],[2.04,10.25],[1.02,11.82]],"id":68392143},{"atl":[[150,4],[1000,0.22]],"id":68392143},{"spn":76.03,"spf":"NaN","id":68392143},{"atb":[[1.03,7.88],[2.16,6.55],[2.14,13.45]],"id":57088863},{"atl":[[150,4],[990,0.22]],"id":57088863},{"spn":76.08,"spf":"NaN","id":57088863}],"con":true,"img":true}]}
{"op":"mcm","clk":"11539127715","pt":1719475708169,"mc":[{"id":"1.230178310","rc":[{"atb":[[1.01,23.66],[2.12,0],[2.14,6.55]],"id":57087188},{"spn":17.07,"spf":"NaN","id":57087188},{"atb":[[2.06,0],[1.03,7.88],[2.08,6.55]],"id":65436514},{"spn":76.04,"spf":"NaN","id":65436514},{"atb":[[1.01,23.66],[2.12,0],[2.14,6.55]],"id":69142441},{"spn":76.07,"spf":"NaN","id":69142441},{"atb":[[1.03,7.88],[2.1,6.55],[2.08,0]],"id":55302014},{"spn":76.05,"spf":"NaN","id":55302014},{"atb":[[2.06,6.55],[2.04,0],[1.02,11.82]],"id":68392143},{"spn":76.03,"spf":"NaN","id":68392143},{"atb":[[1.03,7.88],[2.16,6.55],[2.14,0]],"id":57088863},{"spn":76.08,"spf":"NaN","id":57088863}],"con":true,"img":false}]}
{"op":"mcm","clk":"11539127724","pt":1719475708323,"mc":[{"id":"1.230178310","rc":[{"atb":[[2.16,11.54]],"id":57087188},{"atb":[[2.1,8.63]],"id":65436514},{"atb":[[2.16,9.77]],"id":69142441},{"atb":[[2.12,11.32]],"id":55302014},{"atb":[[2.08,10.25]],"id":68392143},{"atb":[[2.18,13.45]],"id":57088863}],"con":true,"img":false}]}
{"op":"mcm","clk":"11539128463","pt":1719475718421,"mc":[{"id":"1.230178310","rc":[{"atb":[[2.08,3.38]],"id":65436514}],"con":true,"img":false}]}
{"op":"mcm","clk":"11539128504","pt":1719475719090,"mc":[{"id":"1.230178310","rc":[{"atb":[[2.14,3.38]],"id":57087188}],"con":true,"img":false}]}
{"op":"mcm","clk":"11539128597","pt":1719475720729,"mc":[{"id":"1.230178310","rc":[{"atb":[[2.1,3.38]],"id":55302014}],"con":true,"img":false}]}
{"op":"mcm","clk":"11539128611","pt":1719475720932,"mc":[{"id":"1.230178310","rc":[{"atb":[[2.18,3.16]],"id":57087188}],"con":true,"img":false}]}
{"op":"mcm","clk":"11539128628","pt":1719475721242,"mc":[{"id":"1.230178310","rc":[{"atb":[[2.14,3.38]],"id":69142441}],"con":true,"img":false}]}
{"op":"mcm","clk":"11539128686","pt":1719475722233,"mc":[{"id":"1.230178310","rc":[{"atb":[[2.12,3.16]],"id":65436514}],"con":true,"img":false}]}
{"op":"mcm","clk":"11539128731","pt":1719475722910,"mc":[{"id":"1.230178310","rc":[{"atb":[[2.06,3.38]],"id":68392143}],"con":true,"img":false}]}
{"op":"mcm","clk":"11539128759","pt":1719475723218,"mc":[{"id":"1.230178310","rc":[{"atb":[[2.18,3.16]],"id":69142441}],"con":true,"img":false}]}
{"op":"mcm","clk":"11539128767","pt":1719475723421,"mc":[{"id":"1.230178310","rc":[{"atb":[[2.14,3.16]],"id":55302014}],"con":true,"img":false}]}
{"op":"mcm","clk":"11539128796","pt":1719475723931,"mc":[{"id":"1.230178310","rc":[{"atb":[[2.1,3.16]],"id":68392143}],"con":true,"img":false}]}
{"op":"mcm","clk":"11539128804","pt":1719475724137,"mc":[{"id":"1.230178310","rc":[{"atb":[[2.16,3.38]],"id":57088863}],"con":true,"img":false}]}
{"op":"mcm","clk":"11539128825","pt":1719475724399,"mc":[{"id":"1.230178310","rc":[{"atb":[[2.2,3.16]],"id":57088863}],"con":true,"img":false}]}
{"op":"mcm","clk":"11539135732","pt":1719475831833,"mc":[{"id":"1.230178310","rc":[{"atb":[[2.14,0]],"id":57087188},{"spn":17.09,"spf":"NaN","id":57087188},{"spn":76.06,"spf":"NaN","id":65436514},{"spn":76.09,"spf":"NaN","id":69142441},{"spn":76.07,"spf":"NaN","id":55302014},{"spn":76.05,"spf":"NaN","id":68392143},{"spn":76.1,"spf":"NaN","id":57088863}],"con":true,"img":false}]}
{"op":"mcm","clk":"11539135739","pt":1719475831937,"mc":[{"id":"1.230178310","rc":[{"atb":[[2.08,0]],"id":65436514}],"con":true,"img":false}]}
{"op":"mcm","clk":"11539135753","pt":1719475832145,"mc":[{"id":"1.230178310","rc":[{"atb":[[2.1,0]],"id":55302014}],"con":true,"img":false}]}
{"op":"mcm","clk":"11539135767","pt":1719475832350,"mc":[{"id":"1.230178310","rc":[{"atb":[[2.16,0]],"id":57088863}],"con":true,"img":false}]}
{"op":"mcm","clk":"11539135785","pt":1719475832618,"mc":[{"id":"1.230178310","rc":[{"atb":[[2.14,0]],"id":69142441}],"con":true,"img":false}]}
{"op":"mcm","clk":"11539135792","pt":1719475832822,"mc":[{"id":"1.230178310","rc":[{"atb":[[2.06,0]],"id":68392143}],"con":true,"img":false}]}
{"op":"mcm","clk":"11539135863","pt":1719475833845,"mc":[{"id":"1.230178310","rc":[{"atb":[[2.14,6.55]],"id":55302014}],"con":true,"img":false}]}
{"op":"mcm","clk":"11539135878","pt":1719475834150,"mc":[{"id":"1.230178310","rc":[{"atb":[[2.12,6.55]],"id":65436514}],"con":true,"img":false}]}
{"op":"mcm","clk":"11539135891","pt":1719475834308,"mc":[{"id":"1.230178310","rc":[{"atb":[[2.1,6.55]],"id":68392143}],"con":true,"img":false}]}
{"op":"mcm","clk":"11539135911","pt":1719475834617,"mc":[{"id":"1.230178310","rc":[{"atb":[[2.18,6.55]],"id":57087188}],"con":true,"img":false}]}
{"op":"mcm","clk":"11539135934","pt":1719475834924,"mc":[{"id":"1.230178310","rc":[{"atb":[[2.2,6.55]],"id":57088863}],"con":true,"img":false}]}
{"op":"mcm","clk":"11539135952","pt":1719475835232,"mc":[{"id":"1.230178310","rc":[{"atb":[[2.18,6.55]],"id":69142441}],"con":true,"img":false}]}
{"op":"mcm","clk":"11539147111","pt":1719476020265,"mc":[{"id":"1.230178310","rc":[{"atb":[[2.76,2]],"id":69142441},{"spn":76.38,"spf":"NaN","id":69142441}],"con":true,"img":false}]}
{"op":"mcm","clk":"11539341185","pt":1719479307147,"mc":[{"id":"1.230178310","rc":[{"atb":[[1.01,23.66],[2.18,6.54],[2.16,0]],"id":57087188},{"atb":[[1.03,7.88],[2.12,6.54],[2.1,0]],"id":65436514},{"atb":[[1.01,23.66],[2.18,6.54],[2.16,0]],"id":69142441},{"atb":[[1.03,7.88],[2.12,0],[2.14,6.54]],"id":55302014},{"atb":[[1.02,11.82],[2.1,6.54],[2.08,0]],"id":68392143},{"atb":[[1.03,7.88],[2.18,0],[2.2,6.54]],"id":57088863}],"con":true,"img":false}]}
{"op":"mcm","clk":"11539341193","pt":1719479307250,"mc":[{"id":"1.230178310","rc":[{"atb":[[2.2,11.54]],"id":57087188},{"atb":[[2.14,8.62]],"id":65436514},{"atb":[[2.2,9.77]],"id":69142441},{"atb":[[2.16,11.32]],"id":55302014},{"atb":[[2.12,10.25]],"id":68392143},{"atb":[[2.22,13.45]],"id":57088863}],"con":true,"img":false}]}
{"op":"mcm","clk":"11539347646","pt":1719479409584,"mc":[{"id":"1.230178310","rc":[{"spn":17.1,"spf":"NaN","id":57087188},{"atb":[[2.12,3.38]],"id":65436514},{"spn":76.07,"spf":"NaN","id":65436514},{"spn":76.08,"spf":"NaN","id":55302014},{"spn":76.06,"spf":"NaN","id":68392143},{"atb":[[2.2,3.38]],"id":57088863},{"spn":76.11,"spf":"NaN","id":57088863}],"con":true,"img":false}]}
{"op":"mcm","clk":"11539347657","pt":1719479409789,"mc":[{"id":"1.230178310","rc":[{"atb":[[2.18,3.38]],"id":69142441}],"con":true,"img":false}]}
{"op":"mcm","clk":"11539347728","pt":1719479410767,"mc":[{"id":"1.230178310","rc":[{"atb":[[2.1,3.38]],"id":68392143}],"con":true,"img":false}]}
{"op":"mcm","clk":"11539347743","pt":1719479410978,"mc":[{"id":"1.230178310","rc":[{"atb":[[2.18,3.38]],"id":57087188}],"con":true,"img":false}]}
{"op":"mcm","clk":"11539347763","pt":1719479411280,"mc":[{"id":"1.230178310","rc":[{"atb":[[2.14,3.38]],"id":55302014}],"con":true,"img":false}]}
{"op":"mcm","clk":"11539350798","pt":1719479458144,"mc":[{"id":"1.230178310","rc":[{"atb":[[2.18,0]],"id":57087188},{"atb":[[2.12,0]],"id":65436514},{"atb":[[2.18,0]],"id":69142441},{"atb":[[2.14,0]],"id":55302014},{"atb":[[2.1,0]],"id":68392143},{"atb":[[2.2,0]],"id":57088863}],"con":true,"img":false}]}
{"op":"mcm","clk":"11539360395","pt":1719479603805,"mc":[{"id":"1.230178310","rc":[{"atl":[[48,12],[28,8]],"id":57087188},{"spn":15.1,"spf":"NaN","id":57087188},{"atl":[[48,12],[28,8]],"id":65436514},{"spn":15.07,"spf":"NaN","id":65436514},{"atl":[[36,12],[21,8]],"id":55302014},{"spn":11.58,"spf":"NaN","id":55302014},{"atl":[[48,12],[28,8]],"id":68392143},{"spn":15.06,"spf":"NaN","id":68392143}],"con":true,"img":false}]}
{"op":"mcm","clk":"11539368527","pt":1719479717521,"mc":[{"id":"1.230178310","rc":[{"atb":[[2.18,3.16]],"id":55302014},{"spn":11.59,"spf":"NaN","id":55302014}],"con":true,"img":false}]}
{"op":"mcm","clk":"11539368535","pt":1719479717576,"mc":[{"id":"1.230178310","rc":[{"atb":[[2.14,3.16]],"id":68392143}],"con":true,"img":false}]}
{"op":"mcm","clk":"11539368554","pt":1719479717882,"mc":[{"id":"1.230178310","rc":[{"atb":[[2.22,3.16]],"id":57087188}],"con":true,"img":false}]}
{"op":"mcm","clk":"11539368593","pt":1719479718297,"mc":[{"id":"1.230178310","rc":[{"atb":[[2.16,3.16]],"id":65436514}],"con":true,"img":false}]}
{"op":"mcm","clk":"11539368630","pt":1719479718808,"mc":[{"id":"1.230178310","rc":[{"atb":[[2.22,3.16]],"id":69142441}],"con":true,"img":false}]}
{"op":"mcm","clk":"11539368639","pt":1719479718912,"mc":[{"id":"1.230178310","rc":[{"atb":[[2.24,3.16]],"id":57088863}],"con":true,"img":false}]}
{"op":"mcm","clk":"11539370162","pt":1719479738711,"mc":[{"id":"1.230178310","rc":[{"atb":[[2.18,6.54]],"id":55302014}],"con":true,"img":false}]}
{"op":"mcm","clk":"11539370182","pt":1719479739020,"mc":[{"id":"1.230178310","rc":[{"atb":[[2.16,6.54]],"id":65436514},{"atb":[[2.22,6.54]],"id":69142441}],"con":true,"img":false}]}
{"op":"mcm","clk":"11539370205","pt":1719479739329,"mc":[{"id":"1.230178310","rc":[{"atb":[[2.22,6.54]],"id":57087188}],"con":true,"img":false}]}
{"op":"mcm","clk":"11539370227","pt":1719479739638,"mc":[{"id":"1.230178310","rc":[{"atb":[[2.14,6.54]],"id":68392143},{"atb":[[2.24,6.54]],"id":57088863}],"con":true,"img":false}]}
{"op":"mcm","clk":"11539438505","pt":1719481082545,"mc":[{"id":"1.230178310","marketDefinition":{"bspMarket":true,"turnInPlayEnabled":false,"persistenceEnabled":false,"marketBaseRate":5.0,"eventId":"33376062","eventTypeId":"4339","numberOfWinners":1,"bettingType":"ODDS","marketType":"WIN","marketTime":"2024-06-27T14:13:00.000Z","suspendTime":"2024-06-27T14:13:00.000Z","bspReconciled":false,"complete":true,"inPlay":false,"crossMatching":true,"runnersVoidable":false,"numberOfActiveRunners":6,"betDelay":0,"status":"OPEN","runners":[{"status":"ACTIVE","sortPriority":1,"id":57087188,"name":"1. Ballymac Boomer"},{"status":"ACTIVE","sortPriority":2,"id":57088863,"name":"2. Ferryfort Native"},{"status":"ACTIVE","sortPriority":3,"id":55302014,"name":"3. Blue The Woofoff"},{"status":"ACTIVE","sortPriority":4,"id":65436514,"name":"4. Leticias Pride"},{"status":"ACTIVE","sortPriority":5,"id":68392143,"name":"5. Springfield Best"},{"status":"ACTIVE","sortPriority":6,"id":69142441,"name":"6. Ferndale Tok"}],"regulators":["MR_INT"],"venue":"Kinsley","countryCode":"GB","discountAllowed":true,"timezone":"Europe/London","openDate":"2024-06-27T13:36:00.000Z","version":5994643747,"name":"A3 462m","eventName":"Kinsley 27th Jun"},"rc":[{"atb":[[1.01,23.66],[2.22,6.54],[2.2,11.54]],"id":57087188},{"atl":[[32,0.6],[150,4],[48,12],[28,8],[990,0.22]],"id":57087188},{"spn":15.11,"spf":"NaN","id":57087188},{"atb":[[1.03,7.88],[2.16,6.54],[2.14,8.62]],"id":65436514},{"atl":[[150,4],[48,12],[28,8],[990,0.22]],"id":65436514},{"spn":15.08,"spf":"NaN","id":65436514},{"atb":[[1.01,23.66],[2.22,6.54],[2.2,9.77],[2.76,2]],"id":69142441},{"atl":[[150,4],[990,0.22]],"id":69142441},{"spn":76.38,"spf":"NaN","id":69142441},{"atb":[[1.03,7.88],[2.18,6.54],[2.16,11.32]],"id":55302014},{"atl":[[36,12],[150,4],[21,8],[990,0.22]],"id":55302014},{"spn":11.59,"spf":"NaN","id":55302014},{"atb":[[1.02,11.82],[2.12,10.25],[2.14,6.54]],"id":68392143},{"atl":[[150,4],[48,12],[28,8],[1000,0.22]],"id":68392143},{"spn":15.07,"spf":"NaN","id":68392143},{"atb":[[2.24,6.54],[1.03,7.88],[2.22,13.45]],"id":57088863},{"atl":[[150,4],[990,0.22]],"id":57088863},{"spn":76.12,"spf":"NaN","id":57088863}],"con":true,"img":true}]}
{"op":"mcm","clk":"11539545165","pt":1719482906758,"mc":[{"id":"1.230178310","rc":[{"atb":[[1.01,23.65],[2.22,6.54],[2.2,0]],"id":57087188},{"spn":15.11,"spf":"NaN","id":57087188},{"atb":[[1.03,7.88],[2.16,6.54],[2.14,0]],"id":65436514},{"spn":15.08,"spf":"NaN","id":65436514},{"atb":[[1.01,23.65],[2.22,6.54],[2.2,0]],"id":69142441},{"atb":[[1.03,7.88],[2.18,6.54],[2.16,0]],"id":55302014},{"atb":[[1.02,11.82],[2.12,0],[2.14,6.54]],"id":68392143},{"spn":15.07,"spf":"NaN","id":68392143},{"atb":[[2.24,6.54],[1.03,7.88],[2.22,0]],"id":57088863},{"spn":76.12,"spf":"NaN","id":57088863}],"con":true,"img":false}]}
{"op":"mcm","clk":"11539545173","pt":1719482906861,"mc":[{"id":"1.230178310","rc":[{"atb":[[2.24,11.54]],"id":57087188},{"atb":[[2.18,8.62]],"id":65436514},{"atb":[[2.24,9.76]],"id":69142441},{"atb":[[2.2,11.32]],"id":55302014},{"atb":[[2.16,10.25]],"id":68392143},{"atb":[[2.26,13.44]],"id":57088863}],"con":true,"img":false}]}
{"op":"mcm","clk":"11539545466","pt":1719482910788,"mc":[{"id":"1.230178310","rc":[{"atb":[[2.22,3.38]],"id":57087188}],"con":true,"img":false}]}
{"op":"mcm","clk":"11539545473","pt":1719482910893,"mc":[{"id":"1.230178310","rc":[{"atb":[[2.18,3.38]],"id":55302014}],"con":true,"img":false}]}
{"op":"mcm","clk":"11539545485","pt":1719482911100,"mc":[{"id":"1.230178310","rc":[{"atb":[[2.16,3.38]],"id":65436514}],"con":true,"img":false}]}
{"op":"mcm","clk":"11539545499","pt":1719482911307,"mc":[{"id":"1.230178310","rc":[{"atb":[[2.22,3.38]],"id":69142441},{"atb":[[2.24,3.38]],"id":57088863}],"con":true,"img":false}]}
{"op":"mcm","clk":"11539545525","pt":1719482911799,"mc":[{"id":"1.230178310","rc":[{"atb":[[2.26,3.16]],"id":57087188},{"atb":[[2.14,3.38]],"id":68392143}],"con":true,"img":false}]}
{"op":"mcm","clk":"11539545554","pt":1719482912307,"mc":[{"id":"1.230178310","rc":[{"atb":[[2.22,3.16]],"id":55302014}],"con":true,"img":false}]}
{"op":"mcm","clk":"11539545704","pt":1719482914013,"mc":[{"id":"1.230178310","rc":[{"atb":[[2.26,3.16]],"id":69142441}],"con":true,"img":false}]}
{"op":"mcm","clk":"11539545713","pt":1719482914172,"mc":[{"id":"1.230178310","rc":[{"atb":[[2.28,3.16]],"id":57088863}],"con":true,"img":false}]}
{"op":"mcm","clk":"11539545725","pt":1719482914377,"mc":[{"id":"1.230178310","rc":[{"atb":[[2.18,3.16]],"id":68392143}],"con":true,"img":false}]}
{"op":"mcm","clk":"11539545748","pt":1719482914686,"mc":[{"id":"1.230178310","rc":[{"atb":[[2.2,3.16]],"id":65436514}],"con":true,"img":false}]}
{"op":"mcm","clk":"11539550465","pt":1719482987852,"mc":[{"id":"1.230178310","rc":[{"atb":[[2.22,0]],"id":57087188},{"spn":15.13,"spf":"NaN","id":57087188},{"spn":15.1,"spf":"NaN","id":65436514},{"spn":11.61,"spf":"NaN","id":55302014},{"spn":15.09,"spf":"NaN","id":68392143},{"spn":76.14,"spf":"NaN","id":57088863}],"con":true,"img":false}]}
{"op":"mcm","clk":"11539550479","pt":1719482988163,"mc":[{"id":"1.230178310","rc":[{"atb":[[2.16,0]],"id":65436514}],"con":true,"img":false}]}
{"op":"mcm","clk":"11539550503","pt":1719482988473,"mc":[{"id":"1.230178310","rc":[{"atb":[[2.18,0]],"id":55302014}],"con":true,"img":false}]}
{"op":"mcm","clk":"11539550536","pt":1719482989050,"mc":[{"id":"1.230178310","rc":[{"atb":[[2.22,0]],"id":69142441}],"con":true,"img":false}]}
{"op":"mcm","clk":"11539550582","pt":1719482989774,"mc":[{"id":"1.230178310","rc":[{"atb":[[2.24,0]],"id":57088863}],"con":true,"img":false}]}
{"op":"mcm","clk":"11539550587","pt":1719482989876,"mc":[{"id":"1.230178310","rc":[{"atb":[[2.14,0]],"id":68392143}],"con":true,"img":false}]}
{"op":"mcm","clk":"11539550673","pt":1719482991063,"mc":[{"id":"1.230178310","rc":[{"atb":[[2.2,6.54]],"id":65436514}],"con":true,"img":false}]}
{"op":"mcm","clk":"11539550690","pt":1719482991375,"mc":[{"id":"1.230178310","rc":[{"atb":[[2.22,6.54]],"id":55302014}],"con":true,"img":false}]}
{"op":"mcm","clk":"11539550732","pt":1719482991790,"mc":[{"id":"1.230178310","rc":[{"atb":[[2.18,6.54]],"id":68392143}],"con":true,"img":false}]}
{"op":"mcm","clk":"11539550751","pt":1719482992063,"mc":[{"id":"1.230178310","rc":[{"atb":[[2.26,6.54]],"id":57087188}],"con":true,"img":false}]}
{"op":"mcm","clk":"11539550797","pt":1719482992752,"mc":[{"id":"1.230178310","rc":[{"atb":[[2.28,6.54]],"id":57088863}],"con":true,"img":false}]}
{"op":"mcm","clk":"11539550816","pt":1719482993167,"mc":[{"id":"1.230178310","rc":[{"atb":[[2.26,6.54]],"id":69142441}],"con":true,"img":false}]}
{"op":"mcm","clk":"11539563110","pt":1719483180515,"mc":[{"id":"1.230178310","rc":[{"atb":[[4.3,1]],"id":57087188},{"spn":16.15,"spf":"NaN","id":57087188},{"atb":[[3.75,1]],"id":65436514},{"spn":15.87,"spf":"NaN","id":65436514},{"atb":[[5,1]],"id":69142441},{"spn":77.5,"spf":"NaN","id":69142441},{"atb":[[3.35,1]],"id":55302014},{"spn":12.17,"spf":"NaN","id":55302014},{"atb":[[5,1]],"id":68392143},{"spn":16.5,"spf":"NaN","id":68392143},{"atb":[[5,1]],"id":57088863},{"spn":77.5,"spf":"NaN","id":57088863}],"con":true,"img":false}]}
{"op":"mcm","clk":"11539634523","pt":1719484139668,"mc":[{"id":"1.230178310","rc":[{"atb":[[1.51,196.08]],"id":57087188},{"atb":[[1.51,196.08]],"id":65436514},{"atb":[[1.51,196.08]],"id":69142441},{"atb":[[1.51,196.08]],"id":55302014},{"atb":[[1.51,196.08]],"id":68392143},{"atb":[[1.51,196.08]],"id":57088863}],"con":true,"img":false}]}
{"op":"mcm","clk":"11539673862","pt":1719484681299,"mc":[{"id":"1.230178310","rc":[{"atb":[[2.72,6]],"id":57087188},{"atb":[[3.1,6]],"id":65436514},{"atb":[[4.7,6]],"id":69142441},{"atb":[[2.58,6]],"id":55302014},{"atb":[[2.86,6]],"id":68392143},{"atb":[[3.75,6]],"id":57088863}],"con":true,"img":false}]}
{"op":"mcm","clk":"11539674830","pt":1719484695607,"mc":[{"id":"1.230178310","rc":[{"atb":[[2.12,89.29]],"id":69142441},{"atb":[[2.12,89.29]],"id":57088863}],"con":true,"img":false}]}
{"op":"mcm","clk":"11539676037","pt":1719484714158,"mc":[{"id":"1.230178310","rc":[{"atb":[[2.26,3.38]],"id":57087188}],"con":true,"img":false}]}
{"op":"mcm","clk":"11539676042","pt":1719484714263,"mc":[{"id":"1.230178310","rc":[{"atb":[[2.2,3.38]],"id":65436514},{"atb":[[2.26,3.38]],"id":69142441},{"atb":[[2.28,3.38]],"id":57088863}],"con":true,"img":false}]}
{"op":"mcm","clk":"11539676051","pt":1719484714365,"mc":[{"id":"1.230178310","rc":[{"atb":[[2.18,3.38]],"id":68392143}],"con":true,"img":false}]}
{"op":"mcm","clk":"11539676064","pt":1719484714571,"mc":[{"id":"1.230178310","rc":[{"atb":[[2.74,3.16]],"id":57087188}],"con":true,"img":false}]}
{"op":"mcm","clk":"11539676074","pt":1719484714727,"mc":[{"id":"1.230178310","rc":[{"atb":[[2.88,3.16]],"id":68392143}],"con":true,"img":false}]}
{"op":"mcm","clk":"11539676372","pt":1719484719549,"mc":[{"id":"1.230178310","rc":[{"atb":[[2.18,0]],"id":68392143}],"con":true,"img":false}]}
{"op":"mcm","clk":"11539676398","pt":1719484719857,"mc":[{"id":"1.230178310","rc":[{"atb":[[2.2,0]],"id":65436514},{"atb":[[2.26,0]],"id":69142441},{"atb":[[2.28,0]],"id":57088863}],"con":true,"img":false}]}
{"op":"mcm","clk":"11539676463","pt":1719484720636,"mc":[{"id":"1.230178310","rc":[{"atb":[[2.88,6.54]],"id":68392143}],"con":true,"img":false}]}
{"op":"mcm","clk":"11539810802","pt":1719486482536,"mc":[{"id":"1.230178310","marketDefinition":{"bspMarket":true,"turnInPlayEnabled":false,"persistenceEnabled":false,"marketBaseRate":5.0,"eventId":"33376062","eventTypeId":"4339","numberOfWinners":1,"bettingType":"ODDS","marketType":"WIN","marketTime":"2024-06-27T14:13:00.000Z","suspendTime":"2024-06-27T14:13:00.000Z","bspReconciled":false,"complete":true,"inPlay":false,"crossMatching":true,"runnersVoidable":false,"numberOfActiveRunners":6,"betDelay":0,"status":"OPEN","runners":[{"status":"ACTIVE","sortPriority":1,"id":57087188,"name":"1. Ballymac Boomer"},{"status":"ACTIVE","sortPriority":2,"id":57088863,"name":"2. Ferryfort Native"},{"status":"ACTIVE","sortPriority":3,"id":55302014,"name":"3. Blue The Woofoff"},{"status":"ACTIVE","sortPriority":4,"id":65436514,"name":"4. Leticias Pride"},{"status":"ACTIVE","sortPriority":5,"id":68392143,"name":"5. Springfield Best"},{"status":"ACTIVE","sortPriority":6,"id":69142441,"name":"6. Ferndale Tok"}],"regulators":["MR_INT"],"venue":"Kinsley","countryCode":"GB","discountAllowed":true,"timezone":"Europe/London","openDate":"2024-06-27T13:36:00.000Z","version":5994643747,"name":"A3 462m","eventName":"Kinsley 27th Jun"},"rc":[{"atb":[[2.24,11.54],[2.72,6],[4.3,1],[1.01,23.66],[2.74,3.16],[2.26,3.38],[1.51,196.08]],"id":57087188},{"atl":[[32,0.6],[150,4],[48,12],[28,8],[990,0.22]],"id":57087188},{"spn":16.15,"spf":"NaN","id":57087188},{"atb":[[1.03,7.88],[3.1,6],[2.18,8.62],[1.51,196.08],[3.75,1]],"id":65436514},{"atl":[[150,4],[48,12],[28,8],[990,0.22]],"id":65436514},{"spn":15.87,"spf":"NaN","id":65436514},{"atb":[[2.24,9.77],[1.01,23.66],[5,1],[2.12,89.29],[1.51,196.08],[4.7,6],[2.76,2]],"id":69142441},{"atl":[[150,4],[990,0.22]],"id":69142441},{"spn":77.5,"spf":"NaN","id":69142441},{"atb":[[1.03,7.88],[2.22,6.54],[3.35,1],[2.58,6],[2.2,11.32],[1.51,196.08]],"id":55302014},{"atl":[[36,12],[150,4],[21,8],[990,0.22]],"id":55302014},{"spn":12.17,"spf":"NaN","id":55302014},{"atb":[[2.88,6.54],[5,1],[2.86,6],[1.02,11.82],[1.51,196.08],[2.16,10.25]],"id":68392143},{"atl":[[150,4],[48,12],[28,8],[1000,0.22]],"id":68392143},{"spn":16.5,"spf":"NaN","id":68392143},{"atb":[[5,1],[1.03,7.88],[2.12,89.29],[2.26,13.45],[1.51,196.08],[3.75,6]],"id":57088863},{"atl":[[150,4],[990,0.22]],"id":57088863},{"spn":77.5,"spf":"NaN","id":57088863}],"con":true,"img":true}]}
{"op":"mcm","clk":"11539817058","pt":1719486503347,"mc":[{"id":"1.230178310","rc":[{"atb":[[2.24,11.54],[1.01,23.66],[2.74,3.16],[2.26,3.38]],"id":57087188},{"atb":[[1.03,7.88],[2.18,8.62]],"id":65436514},{"atb":[[2.24,9.77],[1.01,23.66]],"id":69142441},{"atb":[[1.03,7.88],[2.22,6.54],[2.2,0]],"id":55302014},{"atb":[[2.88,6.54],[1.02,11.82],[2.16,10.25]],"id":68392143},{"atb":[[1.03,7.88],[2.26,13.45]],"id":57088863}],"con":true,"img":false}]}
{"op":"mcm","clk":"11539817071","pt":1719486503451,"mc":[{"id":"1.230178310","rc":[{"atb":[[2.24,11.32]],"id":55302014}],"con":true,"img":false}]}
{"op":"mcm","clk":"11539819194","pt":1719486526680,"mc":[{"id":"1.230178310","rc":[{"atb":[[2.22,3.38]],"id":55302014}],"con":true,"img":false}]}
{"op":"mcm","clk":"11539819270","pt":1719486527466,"mc":[{"id":"1.230178310","rc":[{"atb":[[2.26,3.16]],"id":55302014}],"con":true,"img":false}]}
{"op":"mcm","clk":"11539825720","pt":1719486604323,"mc":[{"id":"1.230178310","rc":[{"atb":[[2.22,0]],"id":55302014}],"con":true,"img":false}]}
{"op":"mcm","clk":"11539826064","pt":1719486608852,"mc":[{"id":"1.230178310","rc":[{"atb":[[2.26,6.54]],"id":55302014}],"con":true,"img":false}]}
{"op":"mcm","clk":"11539840396","pt":1719486802940,"mc":[{"id":"1.230178310","rc":[{"atb":[[2.24,0]],"id":55302014}],"con":true,"img":false}]}
{"op":"mcm","clk":"11539840401","pt":1719486803042,"mc":[{"id":"1.230178310","rc":[{"atb":[[2.28,11.32]],"id":55302014}],"con":true,"img":false}]}
{"op":"mcm","clk":"11539841615","pt":1719486823168,"mc":[{"id":"1.230178310","rc":[{"atb":[[2.26,3.38]],"id":55302014}],"con":true,"img":false}]}
{"op":"mcm","clk":"11539843328","pt":1719486848274,"mc":[{"id":"1.230178310","rc":[{"atb":[[2.26,0]],"id":55302014}],"con":true,"img":false}]}
{"op":"mcm","clk":"11539849125","pt":1719486929855,"mc":[{"id":"1.230178310","rc":[{"atb":[[2.3,3.38]],"id":55302014}],"con":true,"img":false}]}
{"op":"mcm","clk":"11539850509","pt":1719486947000,"mc":[{"id":"1.230178310","rc":[{"atb":[[2.3,6.54]],"id":55302014}],"con":true,"img":false}]}
{"op":"mcm","clk":"11540014253","pt":1719488997811,"mc":[{"id":"1.230178310","rc":[{"atl":[[370,2]],"id":57087188},{"atl":[[270,2]],"id":65436514},{"atl":[[500,2]],"id":69142441},{"atl":[[550,2]],"id":55302014},{"atl":[[560,2]],"id":68392143},{"atl":[[390,2]],"id":57088863}],"con":true,"img":false}]}
{"op":"mcm","clk":"11540014263","pt":1719488997917,"mc":[{"id":"1.230178310","rc":[{"atb":[[1.16,150]],"id":57087188},{"atb":[[1.16,150]],"id":65436514},{"atb":[[1.16,150]],"id":69142441},{"atb":[[1.16,150]],"id":55302014},{"atb":[[1.16,150]],"id":57088863}],"con":true,"img":false}]}
{"op":"mcm","clk":"11540014275","pt":1719488998015,"mc":[{"id":"1.230178310","rc":[{"atb":[[1.16,150]],"id":68392143}],"con":true,"img":false}]}
{"op":"mcm","clk":"11540136118","pt":1719490398316,"mc":[{"id":"1.230178310","rc":[{"atb":[[2.74,3.16]],"id":57087188},{"atb":[[2.3,6.54],[2.28,0]],"id":55302014},{"atb":[[2.88,6.54]],"id":68392143}],"con":true,"img":false}]}
{"op":"mcm","clk":"11540136128","pt":1719490398418,"mc":[{"id":"1.230178310","rc":[{"atb":[[2.32,11.32]],"id":55302014}],"con":true,"img":false}]}
{"op":"mcm","clk":"11540142029","pt":1719490456245,"mc":[{"id":"1.230178310","rc":[{"atb":[[2.3,3.16]],"id":55302014}],"con":true,"img":false}]}
{"op":"mcm","clk":"11540142147","pt":1719490457190,"mc":[{"id":"1.230178310","rc":[{"atb":[[2.34,3.38]],"id":55302014}],"con":true,"img":false}]}
{"op":"mcm","clk":"11540144804","pt":1719490482725,"mc":[{"id":"1.230178310","rc":[{"atb":[[2.3,0]],"id":55302014}],"con":true,"img":false}]}
{"op":"mcm","clk":"11540145559","pt":1719490490026,"mc":[{"id":"1.230178310","rc":[{"atb":[[2.34,6.54]],"id":55302014}],"con":true,"img":false}]}
{"op":"mcm","clk":"11540164581","pt":1719490696593,"mc":[{"id":"1.230178310","rc":[{"atb":[[2.32,0]],"id":55302014}],"con":true,"img":false}]}
{"op":"mcm","clk":"11540164588","pt":1719490696696,"mc":[{"id":"1.230178310","rc":[{"atb":[[2.36,11.32]],"id":55302014}],"con":true,"img":false}]}
{"op":"mcm","clk":"11540168824","pt":1719490749962,"mc":[{"id":"1.230178310","rc":[{"atb":[[2.34,3.38]],"id":55302014}],"con":true,"img":false}]}
{"op":"mcm","clk":"11540168849","pt":1719490750164,"mc":[{"id":"1.230178310","rc":[{"atb":[[2.38,3.16]],"id":55302014}],"con":true,"img":false}]}
{"op":"mcm","clk":"11540171491","pt":1719490789583,"mc":[{"id":"1.230178310","rc":[{"atb":[[2.34,0]],"id":55302014}],"con":true,"img":false}]}
{"op":"mcm","clk":"11540173359","pt":1719490812821,"mc":[{"id":"1.230178310","rc":[{"atb":[[2.38,6.54]],"id":55302014}],"con":true,"img":false}]}
{"op":"mcm","clk":"11540283714","pt":1719492438052,"mc":[{"id":"1.230178310","rc":[{"atb":[[5,0]],"id":68392143},{"atl":[[5,1]],"id":68392143},{"trd":[[5,2]],"ltp":5.0,"tv":2.0,"id":68392143},{"spn":3.94,"spf":"NaN","id":68392143}],"con":true,"img":false}]}
{"op":"mcm","clk":"11540283791","pt":1719492439944,"mc":[{"id":"1.230178310","rc":[{"atb":[[4.5,1]],"id":68392143}],"con":true,"img":false}]}
{"op":"mcm","clk":"11540351801","pt":1719493412884,"mc":[{"id":"1.230178310","rc":[{"atb":[[2.24,11.56],[1.01,23.68],[2.74,3.16],[2.26,3.38]],"id":57087188},{"atl":[[990,0.22]],"id":57087188},{"atb":[[1.03,7.89],[2.18,8.63]],"id":65436514},{"atl":[[990,0.22]],"id":65436514},{"atb":[[2.24,9.78],[1.01,23.68]],"id":69142441},{"atl":[[990,0.22]],"id":69142441},{"atb":[[2.36,11.34],[1.03,7.89],[2.38,6.54]],"id":55302014},{"atl":[[990,0.22]],"id":55302014},{"atb":[[2.88,6.54],[1.02,11.84],[2.16,10.26]],"id":68392143},{"atl":[[34,18],[1000,0.22]],"id":68392143},{"spn":4.75,"spf":"NaN","id":68392143},{"atb":[[1.03,7.89],[2.26,13.46]],"id":57088863},{"atl":[[990,0.22]],"id":57088863}],"con":true,"img":false}]}
{"op":"mcm","clk":"11540496320","pt":1719495176641,"mc":[{"id":"1.230178310","rc":[{"spl":[[1.01,1]],"id":55302014},{"spn":3.35,"spf":1.0,"id":55302014}],"con":true,"img":false}]}
{"op":"mcm","clk":"11540520466","pt":1719495455589,"mc":[{"id":"1.230178310","rc":[{"atl":[[27,1.72]],"id":65436514},{"spn":15.37,"spf":"NaN","id":65436514}],"con":true,"img":false}]}
{"op":"mcm","clk":"11540520495","pt":1719495455849,"mc":[{"id":"1.230178310","rc":[{"atl":[[20,1.73]],"id":55302014}],"con":true,"img":false}]}
{"op":"mcm","clk":"11540520523","pt":1719495456164,"mc":[{"id":"1.230178310","rc":[{"atl":[[27,1.6]],"id":57087188}],"con":true,"img":false}]}
{"op":"mcm","clk":"11540573235","pt":1719496044115,"mc":[{"id":"1.230178310","rc":[{"atb":[[3.7,1]],"id":57087188},{"spn":15.65,"spf":"NaN","id":57087188},{"atb":[[3.8,1]],"id":65436514},{"spn":15.4,"spf":"NaN","id":65436514},{"atb":[[10,1]],"id":69142441},{"spn":80.0,"spf":"NaN","id":69142441},{"atb":[[3.4,1]],"id":55302014},{"spn":3.4,"spf":1.0,"id":55302014},{"atb":[[4.4,1]],"id":68392143},{"atb":[[6.4,1]],"id":57088863},{"spn":78.2,"spf":"NaN","id":57088863}],"con":true,"img":false}]}
{"op":"mcm","clk":"11540575123","pt":1719496064407,"mc":[{"id":"1.230178310","rc":[{"atb":[[2.12,89.29]],"id":68392143}],"con":true,"img":false}]}
{"op":"mcm","clk":"11540577210","pt":1719496085228,"mc":[{"id":"1.230178310","rc":[{"atl":[[190,4]],"id":57087188},{"atl":[[190,4]],"id":65436514},{"atl":[[190,4]],"id":69142441},{"atl":[[190,4]],"id":55302014},{"atl":[[190,4]],"id":68392143},{"atl":[[190,4]],"id":57088863}],"con":true,"img":false}]}
{"op":"mcm","clk":"11540577382","pt":1719496086839,"mc":[{"id":"1.230178310","rc":[{"atb":[[1.02,2]],"id":57087188}],"con":true,"img":false}]}
{"op":"mcm","clk":"11540577421","pt":1719496087145,"mc":[{"id":"1.230178310","rc":[{"atb":[[1.02,2]],"id":57088863}],"con":true,"img":false}]}
{"op":"mcm","clk":"11540577448","pt":1719496087358,"mc":[{"id":"1.230178310","rc":[{"atb":[[1.02,2]],"id":55302014}],"con":true,"img":false}]}
{"op":"mcm","clk":"11540577490","pt":1719496087720,"mc":[{"id":"1.230178310","rc":[{"atb":[[1.02,2]],"id":65436514}],"con":true,"img":false}]}
{"op":"mcm","clk":"11540577508","pt":1719496087926,"mc":[{"id":"1.230178310","rc":[{"atb":[[1.02,13.84]],"id":68392143}],"con":true,"img":false}]}
{"op":"mcm","clk":"11540577527","pt":1719496088140,"mc":[{"id":"1.230178310","rc":[{"atb":[[1.02,2]],"id":69142441}],"con":true,"img":false}]}
{"op":"mcm","clk":"11540619925","pt":1719496526396,"mc":[{"id":"1.230178310","rc":[{"atl":[[26,0.84]],"id":57087188},{"spn":15.15,"spf":"NaN","id":57087188},{"atl":[[26,0.84]],"id":65436514},{"spn":14.9,"spf":"NaN","id":65436514},{"atl":[[19.5,0.84]],"id":55302014}],"con":true,"img":false}]}
{"op":"mcm","clk":"11540620730","pt":1719496537406,"mc":[{"id":"1.230178310","rc":[{"atl":[[5,0]],"id":68392143},{"trd":[[5,4]],"ltp":5.0,"tv":4.0,"id":68392143}],"con":true,"img":false}]}
{"op":"mcm","clk":"11540620757","pt":1719496537815,"mc":[{"id":"1.230178310","rc":[{"atl":[[1000,0.26]],"id":68392143}],"con":true,"img":false}]}
{"op":"mcm","clk":"11540620769","pt":1719496538021,"mc":[{"id":"1.230178310","rc":[{"atl":[[1000,0.22]],"id":68392143}],"con":true,"img":false}]}
{"op":"mcm","clk":"11540620778","pt":1719496538078,"mc":[{"id":"1.230178310","rc":[{"atl":[[27,0.04]],"id":68392143}],"con":true,"img":false}]}
{"op":"mcm","clk":"11540621205","pt":1719496543403,"mc":[{"id":"1.230178310","rc":[{"atb":[[5,25.6]],"id":68392143}],"con":true,"img":false}]}
{"op":"mcm","clk":"11540621490","pt":1719496546810,"mc":[{"id":"1.230178310","rc":[{"atb":[[4.5,0]],"id":68392143}],"con":true,"img":false}]}
{"op":"mcm","clk":"11540622018","pt":1719496553341,"mc":[{"id":"1.230178310","rc":[{"atl":[[27,0]],"id":68392143}],"con":true,"img":false}]}
{"op":"mcm","clk":"11540622118","pt":1719496554525,"mc":[{"id":"1.230178310","rc":[{"atl":[[1000,0.26]],"id":68392143}],"con":true,"img":false}]}
{"op":"mcm","clk":"11540622135","pt":1719496554732,"mc":[{"id":"1.230178310","rc":[{"atl":[[1000,0.22]],"id":68392143}],"con":true,"img":false}]}
{"op":"mcm","clk":"11540622145","pt":1719496554834,"mc":[{"id":"1.230178310","rc":[{"atl":[[27,0.04]],"id":68392143}],"con":true,"img":false}]}
{"op":"mcm","clk":"11540622294","pt":1719496556814,"mc":[{"id":"1.230178310","rc":[{"atb":[[2.88,3.38]],"id":68392143},{"atb":[[2.28,9.25]],"id":57088863}],"con":true,"img":false}]}
{"op":"mcm","clk":"11540622314","pt":1719496557018,"mc":[{"id":"1.230178310","rc":[{"atb":[[2.74,9.97]],"id":57087188},{"atb":[[2.2,9.87]],"id":65436514}],"con":true,"img":false}]}
{"op":"mcm","clk":"11540622336","pt":1719496557226,"mc":[{"id":"1.230178310","rc":[{"atb":[[2.6,7.41]],"id":55302014}],"con":true,"img":false}]}
{"op":"mcm","clk":"11540623414","pt":1719496570132,"mc":[{"id":"1.230178310","rc":[{"atl":[[27,0]],"id":68392143}],"con":true,"img":false}]}
{"op":"mcm","clk":"11540623449","pt":1719496570436,"mc":[{"id":"1.230178310","rc":[{"atl":[[1000,0.26]],"id":68392143}],"con":true,"img":false}]}
{"op":"mcm","clk":"11540623477","pt":1719496570642,"mc":[{"id":"1.230178310","rc":[{"atl":[[1000,0.22]],"id":68392143}],"con":true,"img":false}]}
{"op":"mcm","clk":"11540623491","pt":1719496570749,"mc":[{"id":"1.230178310","rc":[{"atl":[[27,0.04]],"id":68392143}],"con":true,"img":false}]}
{"op":"mcm","clk":"11540623605","pt":1719496571837,"mc":[{"id":"1.230178310","rc":[{"atb":[[2.38,3.16]],"id":55302014}],"con":true,"img":false}]}
{"op":"mcm","clk":"11540623620","pt":1719496571939,"mc":[{"id":"1.230178310","rc":[{"atb":[[2.26,0]],"id":57087188}],"con":true,"img":false}]}
{"op":"mcm","clk":"11540623647","pt":1719496572347,"mc":[{"id":"1.230178310","rc":[{"atb":[[2.88,0]],"id":68392143}],"con":true,"img":false}]}
{"op":"mcm","clk":"11540623707","pt":1719496573120,"mc":[{"id":"1.230178310","rc":[{"atb":[[2.62,3.38]],"id":55302014}],"con":true,"img":false}]}
{"op":"mcm","clk":"11540623781","pt":1719496574049,"mc":[{"id":"1.230178310","rc":[{"atb":[[2.76,3.38]],"id":57087188}],"con":true,"img":false}]}
{"op":"mcm","clk":"11540623912","pt":1719496575438,"mc":[{"id":"1.230178310","rc":[{"atb":[[2.88,6.3]],"id":68392143}],"con":true,"img":false}]}
{"op":"mcm","clk":"11540624842","pt":1719496585965,"mc":[{"id":"1.230178310","rc":[{"atl":[[27,0]],"id":68392143}],"con":true,"img":false}]}
{"op":"mcm","clk":"11540624864","pt":1719496586171,"mc":[{"id":"1.230178310","rc":[{"atl":[[1000,0.26]],"id":68392143}],"con":true,"img":false}]}
{"op":"mcm","clk":"11540624874","pt":1719496586273,"mc":[{"id":"1.230178310","rc":[{"atl":[[1000,0.22]],"id":68392143}],"con":true,"img":false}]}
{"op":"mcm","clk":"11540624885","pt":1719496586371,"mc":[{"id":"1.230178310","rc":[{"atl":[[27,0.04]],"id":68392143}],"con":true,"img":false}]}
{"op":"mcm","clk":"11540626184","pt":1719496601576,"mc":[{"id":"1.230178310","rc":[{"atl":[[27,0]],"id":68392143},{"spn":16.5,"spf":"NaN","id":68392143}],"con":true,"img":false}]}
{"op":"mcm","clk":"11540626302","pt":1719496602649,"mc":[{"id":"1.230178310","rc":[{"atl":[[1000,0.26]],"id":68392143}],"con":true,"img":false}]}
{"op":"mcm","clk":"11540626318","pt":1719496602856,"mc":[{"id":"1.230178310","rc":[{"atl":[[1000,0.22]],"id":68392143}],"con":true,"img":false}]}
{"op":"mcm","clk":"11540626328","pt":1719496602971,"mc":[{"id":"1.230178310","rc":[{"atl":[[27,0.04]],"id":68392143}],"con":true,"img":false}]}
{"op":"mcm","clk":"11540626520","pt":1719496605486,"mc":[{"id":"1.230178310","rc":[{"atb":[[2.74,3.16]],"id":57087188}],"con":true,"img":false}]}
{"op":"mcm","clk":"11540626566","pt":1719496605964,"mc":[{"id":"1.230178310","rc":[{"atb":[[3.7,17.88]],"id":68392143}],"con":true,"img":false}]}
{"op":"mcm","clk":"11540626584","pt":1719496606162,"mc":[{"id":"1.230178310","rc":[{"atb":[[3.7,0]],"id":68392143}],"con":true,"img":false}]}
{"op":"mcm","clk":"11540626855","pt":1719496609467,"mc":[{"id":"1.230178310","rc":[{"atb":[[2.76,0]],"id":57087188}],"con":true,"img":false}]}
{"op":"mcm","clk":"11540626871","pt":1719496609672,"mc":[{"id":"1.230178310","rc":[{"atb":[[2.3,10.74]],"id":57088863}],"con":true,"img":false}]}
{"op":"mcm","clk":"11540626878","pt":1719496609774,"mc":[{"id":"1.230178310","rc":[{"atb":[[2.62,12.01]],"id":55302014}],"con":true,"img":false}]}
{"op":"mcm","clk":"11540626919","pt":1719496610186,"mc":[{"id":"1.230178310","rc":[{"atb":[[2.22,11.45]],"id":65436514}],"con":true,"img":false}]}
{"op":"mcm","clk":"11540627032","pt":1719496611474,"mc":[{"id":"1.230178310","rc":[{"atb":[[2.38,0]],"id":55302014}],"con":true,"img":false}]}
{"op":"mcm","clk":"11540627052","pt":1719496611679,"mc":[{"id":"1.230178310","rc":[{"atb":[[2.64,3.16]],"id":55302014}],"con":true,"img":false}]}
{"op":"mcm","clk":"11540627216","pt":1719496613674,"mc":[{"id":"1.230178310","rc":[{"atb":[[2.34,3.41]],"id":55302014}],"con":true,"img":false}]}
{"op":"mcm","clk":"11540627262","pt":1719496614293,"mc":[{"id":"1.230178310","rc":[{"atb":[[2.34,0]],"id":55302014}],"con":true,"img":false}]}
{"op":"mcm","clk":"11540627541","pt":1719496618165,"mc":[{"id":"1.230178310","rc":[{"atl":[[27,0]],"id":68392143}],"con":true,"img":false}]}
{"op":"mcm","clk":"11540627574","pt":1719496618576,"mc":[{"id":"1.230178310","rc":[{"atl":[[1000,0.26]],"id":68392143}],"con":true,"img":false}]}
{"op":"mcm","clk":"11540627601","pt":1719496618885,"mc":[{"id":"1.230178310","rc":[{"atl":[[1000,0.22]],"id":68392143}],"con":true,"img":false}]}
{"op":"mcm","clk":"11540627611","pt":1719496618988,"mc":[{"id":"1.230178310","rc":[{"atl":[[27,0.04]],"id":68392143}],"con":true,"img":false}]}
{"op":"mcm","clk":"11540628423","pt":1719496628501,"mc":[{"id":"1.230178310","rc":[{"atb":[[2.74,9.97]],"id":57087188}],"con":true,"img":false}]}
{"op":"mcm","clk":"11540628841","pt":1719496633611,"mc":[{"id":"1.230178310","rc":[{"atb":[[2.2,0]],"id":65436514},{"atb":[[2.28,0]],"id":57088863}],"con":true,"img":false}]}
{"op":"mcm","clk":"11540628881","pt":1719496634183,"mc":[{"id":"1.230178310","rc":[{"atl":[[27,0]],"id":68392143}],"con":true,"img":false}]}
{"op":"mcm","clk":"11540628895","pt":1719496634392,"mc":[{"id":"1.230178310","rc":[{"atl":[[1000,0.26]],"id":68392143}],"con":true,"img":false}]}
{"op":"mcm","clk":"11540628924","pt":1719496634706,"mc":[{"id":"1.230178310","rc":[{"atl":[[1000,0.22]],"id":68392143}],"con":true,"img":false}]}
{"op":"mcm","clk":"11540628934","pt":1719496634810,"mc":[{"id":"1.230178310","rc":[{"atl":[[27,0.04]],"id":68392143}],"con":true,"img":false}]}
{"op":"mcm","clk":"11540629957","pt":1719496647921,"mc":[{"id":"1.230178310","rc":[{"atb":[[2.24,9.55]],"id":65436514},{"atb":[[2.32,8.97]],"id":57088863}],"con":true,"img":false}]}
{"op":"mcm","clk":"11540629993","pt":1719496648492,"mc":[{"id":"1.230178310","rc":[{"atb":[[2.9,7.35]],"id":68392143}],"con":true,"img":false}]}
{"op":"mcm","clk":"11540630013","pt":1719496648698,"mc":[{"id":"1.230178310","rc":[{"atb":[[2.4,2.1]],"id":57088863}],"con":true,"img":false}]}
{"op":"mcm","clk":"11540630123","pt":1719496650000,"mc":[{"id":"1.230178310","rc":[{"atl":[[27,0]],"id":68392143}],"con":true,"img":false}]}
{"op":"mcm","clk":"11540630153","pt":1719496650298,"mc":[{"id":"1.230178310","rc":[{"atl":[[1000,0.26]],"id":68392143}],"con":true,"img":false}]}
{"op":"mcm","clk":"11540630168","pt":1719496650506,"mc":[{"id":"1.230178310","rc":[{"atl":[[1000,0.22]],"id":68392143}],"con":true,"img":false}]}
{"op":"mcm","clk":"11540630182","pt":1719496650605,"mc":[{"id":"1.230178310","rc":[{"atl":[[27,0.04]],"id":68392143}],"con":true,"img":false}]}
{"op":"mcm","clk":"11540631412","pt":1719496665906,"mc":[{"id":"1.230178310","rc":[{"atl":[[27,0]],"id":68392143}],"con":true,"img":false}]}
{"op":"mcm","clk":"11540631464","pt":1719496666525,"mc":[{"id":"1.230178310","rc":[{"atl":[[1000,0.26]],"id":68392143}],"con":true,"img":false}]}
{"op":"mcm","clk":"11540631493","pt":1719496666832,"mc":[{"id":"1.230178310","rc":[{"atl":[[1000,0.22]],"id":68392143}],"con":true,"img":false}]}
{"op":"mcm","clk":"11540631500","pt":1719496666953,"mc":[{"id":"1.230178310","rc":[{"atl":[[27,0.04]],"id":68392143}],"con":true,"img":false}]}
{"op":"mcm","clk":"11540632383","pt":1719496678334,"mc":[{"id":"1.230178310","rc":[{"atb":[[1.1,1.69]],"id":57087188}],"con":true,"img":false}]}
{"op":"mcm","clk":"11540632394","pt":1719496678432,"mc":[{"id":"1.230178310","rc":[{"atb":[[1.08,1.69]],"id":55302014}],"con":true,"img":false}]}
{"op":"mcm","clk":"11540632400","pt":1719496678539,"mc":[{"id":"1.230178310","rc":[{"atb":[[1.16,151.69]],"id":57088863}],"con":true,"img":false}]}
{"op":"mcm","clk":"11540632416","pt":1719496678745,"mc":[{"id":"1.230178310","rc":[{"atb":[[1.1,0.06]],"id":57087188}],"con":true,"img":false}]}
{"op":"mcm","clk":"11540632426","pt":1719496678852,"mc":[{"id":"1.230178310","rc":[{"atb":[[1.09,1.69]],"id":65436514}],"con":true,"img":false}]}
{"op":"mcm","clk":"11540632439","pt":1719496679013,"mc":[{"id":"1.230178310","rc":[{"atb":[[1.27,1.69]],"id":69142441},{"atb":[[1.12,1.69]],"id":68392143}],"con":true,"img":false}]}
{"op":"mcm","clk":"11540632464","pt":1719496679319,"mc":[{"id":"1.230178310","rc":[{"atb":[[1.09,0.07]],"id":65436514},{"atb":[[1.16,150.04]],"id":57088863}],"con":true,"img":false}]}
{"op":"mcm","clk":"11540632484","pt":1719496679632,"mc":[{"id":"1.230178310","rc":[{"atb":[[1.1,0]],"id":57087188},{"atb":[[1.08,0.08]],"id":55302014}],"con":true,"img":false}]}
{"op":"mcm","clk":"11540632494","pt":1719496679737,"mc":[{"id":"1.230178310","rc":[{"atb":[[4.4,0.06]],"id":57087188}],"con":true,"img":false}]}
{"op":"mcm","clk":"11540632524","pt":1719496680050,"mc":[{"id":"1.230178310","rc":[{"atb":[[1.12,0.05]],"id":68392143}],"con":true,"img":false}]}
{"op":"mcm","clk":"11540632536","pt":1719496680154,"mc":[{"id":"1.230178310","rc":[{"atb":[[1.27,0.02]],"id":69142441},{"atb":[[3.65,26.6]],"id":68392143},{"atl":[[27,3.89]],"id":68392143}],"con":true,"img":false}]}
{"op":"mcm","clk":"11540632549","pt":1719496680259,"mc":[{"id":"1.230178310","rc":[{"atb":[[2.96,9.97]],"id":57087188},{"atl":[[27,3.6]],"id":57087188},{"atb":[[1.16,150]],"id":57088863}],"con":true,"img":false}]}
{"op":"mcm","clk":"11540632557","pt":1719496680312,"mc":[{"id":"1.230178310","rc":[{"atb":[[2.22,0]],"id":65436514},{"atb":[[4.8,6]],"id":69142441},{"atl":[[140,2]],"id":69142441},{"atl":[[19.5,2.84]],"id":55302014},{"atb":[[2.3,0],[3.8,6],[6.6,0.04]],"id":57088863},{"atl":[[140,2]],"id":57088863}],"con":true,"img":false}]}
{"op":"mcm","clk":"11540632567","pt":1719496680418,"mc":[{"id":"1.230178310","rc":[{"atb":[[2.72,9.56]],"id":65436514},{"atl":[[27,5.57]],"id":65436514}],"con":true,"img":false}]}
{"op":"mcm","clk":"11540632577","pt":1719496680523,"mc":[{"id":"1.230178310","rc":[{"atb":[[2.32,75.76]],"id":55302014},{"atl":[[17.5,2]],"id":55302014},{"atb":[[4.1,6]],"id":57088863}],"con":true,"img":false}]}
{"op":"mcm","clk":"11540632585","pt":1719496680628,"mc":[{"id":"1.230178310","rc":[{"atb":[[1.09,0]],"id":65436514},{"atb":[[3.8,0]],"id":57088863}],"con":true,"img":false}]}
{"op":"mcm","clk":"11540632595","pt":1719496680735,"mc":[{"id":"1.230178310","rc":[{"atb":[[3.85,0.07]],"id":65436514}],"con":true,"img":false}]}
{"op":"mcm","clk":"11540632620","pt":1719496681047,"mc":[{"id":"1.230178310","rc":[{"atb":[[1.08,0]],"id":55302014}],"con":true,"img":false}]}
{"op":"mcm","clk":"11540632631","pt":1719496681152,"mc":[{"id":"1.230178310","rc":[{"atb":[[3.45,0.08]],"id":55302014}],"con":true,"img":false}]}
{"op":"mcm","clk":"11540632648","pt":1719496681316,"mc":[{"id":"1.230178310","rc":[{"atl":[[19.5,0.84]],"id":55302014}],"con":true,"img":false}]}
{"op":"mcm","clk":"11540632656","pt":1719496681419,"mc":[{"id":"1.230178310","rc":[{"atb":[[1.12,0],[5,0]],"id":68392143}],"con":true,"img":false}]}
{"op":"mcm","clk":"11540632665","pt":1719496681530,"mc":[{"id":"1.230178310","rc":[{"atb":[[5.1,0.05]],"id":68392143}],"con":true,"img":false}]}
{"op":"mcm","clk":"11540632707","pt":1719496682152,"mc":[{"id":"1.230178310","rc":[{"atl":[[27,3.85]],"id":68392143}],"con":true,"img":false}]}
{"op":"mcm","clk":"11540632715","pt":1719496682257,"mc":[{"id":"1.230178310","rc":[{"atb":[[1.27,0]],"id":69142441}],"con":true,"img":false}]}
{"op":"mcm","clk":"11540632721","pt":1719496682311,"mc":[{"id":"1.230178310","rc":[{"atb":[[10.5,0.02]],"id":69142441},{"atl":[[1000,0.26]],"id":68392143}],"con":true,"img":false}]}
{"op":"mcm","clk":"11540632727","pt":1719496682466,"mc":[{"id":"1.230178310","rc":[{"atl":[[1000,0.22]],"id":68392143}],"con":true,"img":false}]}
{"op":"mcm","clk":"11540632737","pt":1719496682520,"mc":[{"id":"1.230178310","rc":[{"atl":[[26,0.04]],"id":68392143}],"con":true,"img":false}]}
{"op":"mcm","clk":"11540632745","pt":1719496682625,"mc":[{"id":"1.230178310","rc":[{"atb":[[4.5,1]],"id":68392143}],"con":true,"img":false}]}
{"op":"mcm","clk":"11540632764","pt":1719496682942,"mc":[{"id":"1.230178310","rc":[{"atl":[[20,0]],"id":55302014}],"con":true,"img":false}]}
{"op":"mcm","clk":"11540632864","pt":1719496684247,"mc":[{"id":"1.230178310","rc":[{"atb":[[2.74,6.81]],"id":57087188}],"con":true,"img":false}]}
{"op":"mcm","clk":"11540632883","pt":1719496684461,"mc":[{"id":"1.230178310","rc":[{"atb":[[2.98,3.16]],"id":57087188}],"con":true,"img":false}]}
{"op":"mcm","clk":"11540632939","pt":1719496685037,"mc":[{"id":"1.230178310","rc":[{"atb":[[2.76,7.93]],"id":57087188}],"con":true,"img":false}]}
{"op":"mcm","clk":"11540633087","pt":1719496686761,"mc":[{"id":"1.230178310","rc":[{"atl":[[1000,1.7]],"id":57087188},{"atl":[[1000,1.7]],"id":55302014},{"atl":[[1000,1.7]],"id":57088863}],"con":true,"img":false}]}
{"op":"mcm","clk":"11540633103","pt":1719496686864,"mc":[{"id":"1.230178310","rc":[{"atb":[[1.02,3.7]],"id":57087188},{"atb":[[1.02,3.7]],"id":55302014},{"atb":[[1.03,9.59]],"id":57088863}],"con":true,"img":false}]}
{"op":"mcm","clk":"11540633114","pt":1719496686922,"mc":[{"id":"1.230178310","rc":[{"atl":[[1000,0.01]],"id":57087188},{"atl":[[1000,0.02]],"id":55302014},{"atl":[[1000,0]],"id":57088863}],"con":true,"img":false}]}
{"op":"mcm","clk":"11540633130","pt":1719496687031,"mc":[{"id":"1.230178310","rc":[{"atb":[[1.02,2.11]],"id":57087188},{"atb":[[1.02,2.13]],"id":55302014},{"atb":[[1.03,7.97]],"id":57088863}],"con":true,"img":false}]}
{"op":"mcm","clk":"11540633141","pt":1719496687130,"mc":[{"id":"1.230178310","rc":[{"atl":[[1000,0]],"id":57087188},{"atl":[[1000,0]],"id":55302014}],"con":true,"img":false}]}
{"op":"mcm","clk":"11540633149","pt":1719496687234,"mc":[{"id":"1.230178310","rc":[{"atl":[[26,0.85]],"id":57087188},{"atl":[[17,0.02]],"id":55302014}],"con":true,"img":false}]}
{"op":"mcm","clk":"11540633157","pt":1719496687337,"mc":[{"id":"1.230178310","rc":[{"atb":[[1.02,2]],"id":57087188},{"atb":[[1.02,2]],"id":55302014},{"atb":[[1.03,7.89]],"id":57088863}],"con":true,"img":false}]}
{"op":"mcm","clk":"11540633170","pt":1719496687444,"mc":[{"id":"1.230178310","rc":[{"atb":[[3.75,0.11]],"id":57087188},{"atb":[[3.4,1.13]],"id":55302014},{"atb":[[5.1,0.07]],"id":57088863}],"con":true,"img":false}]}
{"op":"mcm","clk":"11540633292","pt":1719496688958,"mc":[{"id":"1.230178310","rc":[{"atl":[[17,1.67]],"id":55302014}],"con":true,"img":false}]}
{"op":"mcm","clk":"11540633441","pt":1719496690731,"mc":[{"id":"1.230178310","rc":[{"atb":[[3.45,0]],"id":55302014},{"trd":[[3.45,0.16]],"ltp":3.45,"tv":0.16,"id":55302014}],"con":true,"img":false}]}
{"op":"mcm","clk":"11540633464","pt":1719496691140,"mc":[{"id":"1.230178310","rc":[{"atb":[[4.4,0]],"id":57087188},{"atb":[[3.85,0]],"id":65436514},{"atb":[[10.5,0]],"id":69142441},{"atb":[[5.1,0]],"id":68392143},{"atb":[[6.6,0]],"id":57088863}],"con":true,"img":false}]}
{"op":"mcm","clk":"11540633592","pt":1719496692860,"mc":[{"id":"1.230178310","rc":[{"atl":[[16.5,2]],"id":55302014}],"con":true,"img":false}]}
{"op":"mcm","clk":"11540633598","pt":1719496692962,"mc":[{"id":"1.230178310","rc":[{"atl":[[16.5,4],[17.5,0]],"id":55302014}],"con":true,"img":false}]}
{"op":"mcm","clk":"11540633606","pt":1719496693066,"mc":[{"id":"1.230178310","rc":[{"atl":[[16.5,2],[17,5.67]],"id":55302014}],"con":true,"img":false}]}
{"op":"mcm","clk":"11540633612","pt":1719496693168,"mc":[{"id":"1.230178310","rc":[{"atl":[[1000,0.07]],"id":55302014}],"con":true,"img":false}]}
{"op":"mcm","clk":"11540633627","pt":1719496693336,"mc":[{"id":"1.230178310","rc":[{"atl":[[1000,0]],"id":55302014}],"con":true,"img":false}]}
{"op":"mcm","clk":"11540633634","pt":1719496693431,"mc":[{"id":"1.230178310","rc":[{"atl":[[16,0.07]],"id":55302014}],"con":true,"img":false}]}
{"op":"mcm","clk":"11540633728","pt":1719496694742,"mc":[{"id":"1.230178310","rc":[{"atl":[[17,4.02]],"id":55302014}],"con":true,"img":false}]}
{"op":"mcm","clk":"11540633834","pt":1719496696255,"mc":[{"id":"1.230178310","rc":[{"atb":[[2.88,0]],"id":68392143}],"con":true,"img":false}]}
{"op":"mcm","clk":"11540633942","pt":1719496697769,"mc":[{"id":"1.230178310","rc":[{"atl":[[26,0]],"id":68392143}],"con":true,"img":false}]}
{"op":"mcm","clk":"11540633964","pt":1719496697980,"mc":[{"id":"1.230178310","rc":[{"atl":[[1000,0.26]],"id":68392143}],"con":true,"img":false}]}
{"op":"mcm","clk":"11540633978","pt":1719496698036,"mc":[{"id":"1.230178310","rc":[{"atl":[[16,1.7],[16.5,0]],"id":55302014}],"con":true,"img":false}]}
{"op":"mcm","clk":"11540633986","pt":1719496698136,"mc":[{"id":"1.230178310","rc":[{"atl":[[16,3.7],[17,0.02]],"id":55302014},{"atl":[[1000,0.22]],"id":68392143}],"con":true,"img":false}]}
{"op":"mcm","clk":"11540633995","pt":1719496698239,"mc":[{"id":"1.230178310","rc":[{"atl":[[26,0.04]],"id":68392143}],"con":true,"img":false}]}
{"op":"mcm","clk":"11540634168","pt":1719496700536,"mc":[{"id":"1.230178310","rc":[{"atl":[[15.5,2]],"id":55302014}],"con":true,"img":false}]}
{"op":"mcm","clk":"11540634270","pt":1719496701678,"mc":[{"id":"1.230178310","rc":[{"atb":[[3.4,0]],"id":55302014},{"trd":[[3.4,2.26]],"ltp":3.4,"tv":2.26,"id":55302014}],"con":true,"img":false}]}
{"op":"mcm","clk":"11540634302","pt":1719496702049,"mc":[{"id":"1.230178310","rc":[{"atb":[[2.92,6.17]],"id":68392143}],"con":true,"img":false}]}
{"op":"mcm","clk":"11540634423","pt":1719496703776,"mc":[{"id":"1.230178310","rc":[{"atl":[[26,1.01]],"id":68392143}],"con":true,"img":false}]}
{"op":"mcm","clk":"11540634473","pt":1719496704290,"mc":[{"id":"1.230178310","rc":[{"atb":[[2.84,6.81],[2.96,0]],"id":57087188},{"atl":[[7.6,1]],"id":57087188},{"atb":[[2.72,0],[2.92,9.56]],"id":65436514},{"atl":[[7,1]],"id":65436514},{"atb":[[6.8,1]],"id":69142441},{"atl":[[32,1]],"id":69142441},{"atb":[[2.32,0],[2.46,68.49],[2.62,13.01]],"id":55302014},{"atl":[[6.6,1]],"id":55302014},{"atl":[[12.5,1]],"id":68392143},{"atb":[[4.9,1]],"id":57088863},{"atl":[[16,1]],"id":57088863}],"con":true,"img":false}]}
{"op":"mcm","clk":"11540634492","pt":1719496704449,"mc":[{"id":"1.230178310","rc":[{"atl":[[16,2.07]],"id":55302014}],"con":true,"img":false}]}
{"op":"mcm","clk":"11540634523","pt":1719496704763,"mc":[{"id":"1.230178310","rc":[{"atl":[[26,0.04]],"id":68392143}],"con":true,"img":false}]}
{"op":"mcm","clk":"11540634583","pt":1719496705387,"mc":[{"id":"1.230178310","rc":[{"atl":[[15.5,0]],"id":55302014}],"con":true,"img":false}]}
{"op":"mcm","clk":"11540634819","pt":1719496708260,"mc":[{"id":"1.230178310","rc":[{"atl":[[6.4,2]],"id":55302014}],"con":true,"img":false}]}
{"op":"mcm","clk":"11540634834","pt":1719496708454,"mc":[{"id":"1.230178310","rc":[{"atl":[[16,0.07],[6.4,4]],"id":55302014}],"con":true,"img":false}]}
{"op":"mcm","clk":"11540634852","pt":1719496708659,"mc":[{"id":"1.230178310","rc":[{"atl":[[16,0]],"id":55302014}],"con":true,"img":false}]}
{"op":"mcm","clk":"11540634913","pt":1719496709286,"mc":[{"id":"1.230178310","rc":[{"atl":[[1000,0.19]],"id":55302014}],"con":true,"img":false}]}
{"op":"mcm","clk":"11540634923","pt":1719496709343,"mc":[{"id":"1.230178310","rc":[{"atb":[[2.74,0]],"id":57087188},{"atb":[[2.24,0]],"id":65436514},{"atl":[[1000,0]],"id":55302014},{"atb":[[2.32,0]],"id":57088863}],"con":true,"img":false}]}
{"op":"mcm","clk":"11540634930","pt":1719496709443,"mc":[{"id":"1.230178310","rc":[{"atl":[[6.2,0.19]],"id":55302014}],"con":true,"img":false}]}
{"op":"mcm","clk":"11540635172","pt":1719496712572,"mc":[{"id":"1.230178310","rc":[{"atb":[[3.35,0]],"id":55302014},{"trd":[[3.35,2]],"ltp":3.35,"tv":2.0,"id":55302014}],"con":true,"img":false}]}
{"op":"mcm","clk":"11540635215","pt":1719496713089,"mc":[{"id":"1.230178310","rc":[{"atb":[[3.1,1.07]],"id":55302014}],"con":true,"img":false}]}
{"op":"mcm","clk":"11540635238","pt":1719496713350,"mc":[{"id":"1.230178310","rc":[{"atl":[[26,0]],"id":68392143}],"con":true,"img":false}]}
{"op":"mcm","clk":"11540635247","pt":1719496713452,"mc":[{"id":"1.230178310","rc":[{"atl":[[6.4,2]],"id":55302014}],"con":true,"img":false}]}
{"op":"mcm","clk":"11540635255","pt":1719496713555,"mc":[{"id":"1.230178310","rc":[{"atl":[[6.4,0],[6.6,3.19]],"id":55302014},{"atl":[[1000,0.31]],"id":68392143}],"con":true,"img":false}]}
{"op":"mcm","clk":"11540635270","pt":1719496713765,"mc":[{"id":"1.230178310","rc":[{"atl":[[17,3.4],[6.6,1]],"id":55302014},{"atl":[[1000,0.22]],"id":68392143}],"con":true,"img":false}]}
{"op":"mcm","clk":"11540635285","pt":1719496713869,"mc":[{"id":"1.230178310","rc":[{"atl":[[12,0.09]],"id":68392143}],"con":true,"img":false}]}
{"op":"mcm","clk":"11540635306","pt":1719496714184,"mc":[{"id":"1.230178310","rc":[{"atb":[[3.1,6.81],[2.84,0]],"id":57087188}],"con":true,"img":false}]}
{"op":"mcm","clk":"11540635323","pt":1719496714388,"mc":[{"id":"1.230178310","rc":[{"atb":[[3.1,14.64]],"id":65436514}],"con":true,"img":false}]}
{"op":"mcm","clk":"11540635333","pt":1719496714492,"mc":[{"id":"1.230178310","rc":[{"atb":[[2.92,0]],"id":65436514},{"atb":[[2.46,0],[2.58,17.34]],"id":55302014},{"atb":[[4.9,7],[4.1,0]],"id":57088863}],"con":true,"img":false}]}
{"op":"mcm","clk":"11540635490","pt":1719496716153,"mc":[{"id":"1.230178310","rc":[{"atl":[[6.4,2]],"id":55302014}],"con":true,"img":false}]}
{"op":"mcm","clk":"11540635501","pt":1719496716261,"mc":[{"id":"1.230178310","rc":[{"atl":[[17,0.02],[6.4,4]],"id":55302014}],"con":true,"img":false}]}
{"op":"mcm","clk":"11540635695","pt":1719496718963,"mc":[{"id":"1.230178310","rc":[{"atb":[[2.98,0]],"id":57087188}],"con":true,"img":false}]}
{"op":"mcm","clk":"11540635717","pt":1719496719262,"mc":[{"id":"1.230178310","rc":[{"atb":[[2.78,6.66]],"id":57087188},{"atb":[[2.6,0]],"id":55302014}],"con":true,"img":false}]}
{"op":"mcm","clk":"11540635737","pt":1719496719471,"mc":[{"id":"1.230178310","rc":[{"atb":[[2.28,9.25]],"id":57088863}],"con":true,"img":false}]}
{"op":"mcm","clk":"11540635833","pt":1719496720664,"mc":[{"id":"1.230178310","rc":[{"atb":[[2.62,9.63]],"id":55302014}],"con":true,"img":false}]}
{"op":"mcm","clk":"11540635887","pt":1719496721491,"mc":[{"id":"1.230178310","rc":[{"atl":[[6.4,2]],"id":55302014}],"con":true,"img":false}]}
{"op":"mcm","clk":"11540635893","pt":1719496721597,"mc":[{"id":"1.230178310","rc":[{"atl":[[6.4,0],[6.6,3.19]],"id":55302014}],"con":true,"img":false}]}
{"op":"mcm","clk":"11540636056","pt":1719496723207,"mc":[{"id":"1.230178310","rc":[{"atl":[[6.4,2]],"id":55302014}],"con":true,"img":false}]}
{"op":"mcm","clk":"11540636104","pt":1719496723673,"mc":[{"id":"1.230178310","rc":[{"atb":[[3.1,0]],"id":55302014},{"trd":[[3.1,2.13]],"ltp":3.1,"tv":2.13,"id":55302014}],"con":true,"img":false}]}
{"op":"mcm","clk":"11540636181","pt":1719496724708,"mc":[{"id":"1.230178310","rc":[{"atl":[[6.2,0]],"id":55302014}],"con":true,"img":false}]}
{"op":"mcm","clk":"11540636214","pt":1719496725075,"mc":[{"id":"1.230178310","rc":[{"atb":[[3.75,0]],"id":57087188},{"atl":[[26,0.84]],"id":57087188},{"atl":[[17,0]],"id":55302014},{"atb":[[5.1,0]],"id":57088863}],"con":true,"img":false}]}
{"op":"mcm","clk":"11540636269","pt":1719496726007,"mc":[{"id":"1.230178310","rc":[{"spn":5.95,"spf":"NaN","id":57087188},{"spn":5.4,"spf":"NaN","id":65436514},{"spn":21.0,"spf":"NaN","id":69142441},{"atl":[[1000,0.19]],"id":55302014},{"spn":2.64,"spf":1.0,"id":55302014},{"spn":8.25,"spf":"NaN","id":68392143},{"spn":11.2,"spf":"NaN","id":57088863}],"con":true,"img":false}]}
{"op":"mcm","clk":"11540636280","pt":1719496726106,"mc":[{"id":"1.230178310","rc":[{"atl":[[1000,0]],"id":55302014}],"con":true,"img":false}]}
{"op":"mcm","clk":"11540636286","pt":1719496726170,"mc":[{"id":"1.230178310","rc":[{"atl":[[6.2,0.19]],"id":55302014}],"con":true,"img":false}]}
{"op":"mcm","clk":"11540636446","pt":1719496728086,"mc":[{"id":"1.230178310","rc":[{"atb":[[2.94,1.16]],"id":55302014}],"con":true,"img":false}]}
{"op":"mcm","clk":"11540636478","pt":1719496728397,"mc":[{"id":"1.230178310","rc":[{"atl":[[6.4,0]],"id":55302014}],"con":true,"img":false}]}
{"op":"mcm","clk":"11540636496","pt":1719496728607,"mc":[{"id":"1.230178310","rc":[{"atl":[[17,6.25],[6.6,1]],"id":55302014}],"con":true,"img":false}]}
{"op":"mcm","clk":"11540636552","pt":1719496729184,"mc":[{"id":"1.230178310","rc":[{"atl":[[12,0]],"id":68392143}],"con":true,"img":false}]}
{"op":"mcm","clk":"11540636624","pt":1719496730013,"mc":[{"id":"1.230178310","rc":[{"atl":[[1000,0.31]],"id":68392143}],"con":true,"img":false}]}
{"op":"mcm","clk":"11540636646","pt":1719496730169,"mc":[{"id":"1.230178310","rc":[{"atl":[[6.4,2]],"id":55302014},{"atl":[[1000,0.22]],"id":68392143}],"con":true,"img":false}]}
{"op":"mcm","clk":"11540636654","pt":1719496730275,"mc":[{"id":"1.230178310","rc":[{"atl":[[17,0],[6.4,4]],"id":55302014},{"atl":[[12,0.09]],"id":68392143}],"con":true,"img":false}]}
{"op":"mcm","clk":"11540637091","pt":1719496735477,"mc":[{"id":"1.230178310","rc":[{"atl":[[6.4,2]],"id":55302014}],"con":true,"img":false}]}
{"op":"mcm","clk":"11540637109","pt":1719496735674,"mc":[{"id":"1.230178310","rc":[{"atl":[[6.4,0],[6.6,3.19]],"id":55302014}],"con":true,"img":false}]}
{"op":"mcm","clk":"11540637240","pt":1719496737382,"mc":[{"id":"1.230178310","rc":[{"atb":[[2.38,8.58]],"id":55302014}],"con":true,"img":false}]}
{"op":"mcm","clk":"11540637252","pt":1719496737598,"mc":[{"id":"1.230178310","rc":[{"atb":[[2.2,9.87]],"id":65436514}],"con":true,"img":false}]}
{"op":"mcm","clk":"11540637282","pt":1719496738340,"mc":[{"id":"1.230178310","rc":[{"atl":[[6.4,2]],"id":55302014}],"con":true,"img":false}]}
{"op":"mcm","clk":"11540637506","pt":1719496741417,"mc":[{"id":"1.230178310","rc":[{"atl":[[6.2,0]],"id":55302014}],"con":true,"img":false}]}
{"op":"mcm","clk":"11540637548","pt":1719496741887,"mc":[{"id":"1.230178310","rc":[{"atl":[[1000,0.19]],"id":55302014}],"con":true,"img":false}]}
{"op":"mcm","clk":"11540637566","pt":1719496742097,"mc":[{"id":"1.230178310","rc":[{"atl":[[1000,0]],"id":55302014}],"con":true,"img":false}]}
{"op":"mcm","clk":"11540637572","pt":1719496742200,"mc":[{"id":"1.230178310","rc":[{"atl":[[6.2,0.19]],"id":55302014}],"con":true,"img":false}]}
{"op":"mcm","clk":"11540637642","pt":1719496743083,"mc":[{"id":"1.230178310","rc":[{"atb":[[2.76,0]],"id":57087188},{"atb":[[2.62,1]],"id":55302014},{"atb":[[2.9,0]],"id":68392143}],"con":true,"img":false}]}
{"op":"mcm","clk":"11540637648","pt":1719496743185,"mc":[{"id":"1.230178310","rc":[{"atl":[[6.4,0]],"id":55302014}],"con":true,"img":false}]}
{"op":"mcm","clk":"11540637657","pt":1719496743288,"mc":[{"id":"1.230178310","rc":[{"atl":[[6.6,1]],"id":55302014}],"con":true,"img":false}]}
{"op":"mcm","clk":"11540637666","pt":1719496743394,"mc":[{"id":"1.230178310","rc":[{"atl":[[17,6.25]],"id":55302014}],"con":true,"img":false}]}
{"op":"mcm","clk":"11540637825","pt":1719496745102,"mc":[{"id":"1.230178310","rc":[{"atl":[[6.4,2]],"id":55302014}],"con":true,"img":false}]}
{"op":"mcm","clk":"11540637860","pt":1719496745514,"mc":[{"id":"1.230178310","rc":[{"atl":[[12,0]],"id":68392143}],"con":true,"img":false}]}
{"op":"mcm","clk":"11540637898","pt":1719496745982,"mc":[{"id":"1.230178310","rc":[{"atl":[[1000,0.31]],"id":68392143}],"con":true,"img":false}]}
{"op":"mcm","clk":"11540637916","pt":1719496746189,"mc":[{"id":"1.230178310","rc":[{"atl":[[1000,0.22]],"id":68392143}],"con":true,"img":false}]}
{"op":"mcm","clk":"11540637928","pt":1719496746296,"mc":[{"id":"1.230178310","rc":[{"atl":[[12,0.09]],"id":68392143}],"con":true,"img":false}]}
{"op":"mcm","clk":"11540638027","pt":1719496747483,"mc":[{"id":"1.230178310","rc":[{"spl":[[1.01,4]],"id":68392143}],"con":true,"img":false}]}
{"op":"mcm","clk":"11540638282","pt":1719496750287,"mc":[{"id":"1.230178310","rc":[{"atl":[[6.4,0]],"id":55302014}],"con":true,"img":false}]}
{"op":"mcm","clk":"11540638525","pt":1719496753616,"mc":[{"id":"1.230178310","rc":[{"atl":[[6.4,2]],"id":55302014}],"con":true,"img":false}]}
{"op":"mcm","clk":"11540638534","pt":1719496753719,"mc":[{"id":"1.230178310","rc":[{"atl":[[17,0],[6.4,4]],"id":55302014}],"con":true,"img":false}]}
{"op":"mcm","clk":"11540638639","pt":1719496755329,"mc":[{"id":"1.230178310","rc":[{"atb":[[2.6,3.38]],"id":55302014}],"con":true,"img":false}]}
{"op":"mcm","clk":"11540638653","pt":1719496755528,"mc":[{"id":"1.230178310","rc":[{"atb":[[2.94,7.19]],"id":68392143}],"con":true,"img":false}]}
{"op":"mcm","clk":"11540638666","pt":1719496755589,"mc":[{"id":"1.230178310","rc":[{"atb":[[2.3,10.74]],"id":57088863}],"con":true,"img":false}]}
{"op":"mcm","clk":"11540638699","pt":1719496756106,"mc":[{"id":"1.230178310","rc":[{"atb":[[2.64,0]],"id":55302014}],"con":true,"img":false}]}
{"op":"mcm","clk":"11540638721","pt":1719496756320,"mc":[{"id":"1.230178310","rc":[{"atb":[[2.8,7.75]],"id":57087188}],"con":true,"img":false}]}
{"op":"mcm","clk":"11540638812","pt":1719496757402,"mc":[{"id":"1.230178310","rc":[{"atl":[[6.2,0]],"id":55302014}],"con":true,"img":false}]}
{"op":"mcm","clk":"11540638834","pt":1719496757832,"mc":[{"id":"1.230178310","rc":[{"atl":[[1000,0.19]],"id":55302014}],"con":true,"img":false}]}
{"op":"mcm","clk":"11540638841","pt":1719496757917,"mc":[{"id":"1.230178310","rc":[{"atl":[[1000,0]],"id":55302014}],"con":true,"img":false}]}
{"op":"mcm","clk":"11540638845","pt":1719496758018,"mc":[{"id":"1.230178310","rc":[{"atl":[[6.2,0.19]],"id":55302014}],"con":true,"img":false}]}
{"op":"mcm","clk":"11540638900","pt":1719496758802,"mc":[{"id":"1.230178310","rc":[{"atl":[[6.4,2]],"id":55302014}],"con":true,"img":false}]}
{"op":"mcm","clk":"11540638917","pt":1719496759017,"mc":[{"id":"1.230178310","rc":[{"atl":[[6.4,0],[6.6,3.19]],"id":55302014}],"con":true,"img":false}]}
{"op":"mcm","clk":"11540639008","pt":1719496760023,"mc":[{"id":"1.230178310","rc":[{"atb":[[3.1,1]],"id":55302014}],"con":true,"img":false}]}
{"op":"mcm","clk":"11540639112","pt":1719496761434,"mc":[{"id":"1.230178310","rc":[{"atl":[[6.4,2]],"id":55302014}],"con":true,"img":false}]}
{"op":"mcm","clk":"11540639119","pt":1719496761527,"mc":[{"id":"1.230178310","rc":[{"atl":[[12,0]],"id":68392143}],"con":true,"img":false}]}
{"op":"mcm","clk":"11540639136","pt":1719496761828,"mc":[{"id":"1.230178310","rc":[{"atl":[[1000,0.31]],"id":68392143}],"con":true,"img":false}]}
{"op":"mcm","clk":"11540639141","pt":1719496761931,"mc":[{"id":"1.230178310","rc":[{"atl":[[1000,0.22]],"id":68392143}],"con":true,"img":false}]}
{"op":"mcm","clk":"11540639156","pt":1719496762034,"mc":[{"id":"1.230178310","rc":[{"atl":[[12,0.09]],"id":68392143}],"con":true,"img":false}]}
{"op":"mcm","clk":"11540639513","pt":1719496766645,"mc":[{"id":"1.230178310","rc":[{"atl":[[6.4,0]],"id":55302014}],"con":true,"img":false}]}
{"op":"mcm","clk":"11540639536","pt":1719496766804,"mc":[{"id":"1.230178310","rc":[{"atl":[[17,6.25],[6.6,1]],"id":55302014}],"con":true,"img":false}]}
{"op":"mcm","clk":"11540639645","pt":1719496768422,"mc":[{"id":"1.230178310","rc":[{"atb":[[3.1,0]],"id":55302014},{"trd":[[3.1,4.13]],"ltp":3.1,"tv":4.13,"id":55302014}],"con":true,"img":false}]}
{"op":"mcm","clk":"11540639716","pt":1719496769311,"mc":[{"id":"1.230178310","rc":[{"atl":[[6.4,2]],"id":55302014}],"con":true,"img":false}]}
{"op":"mcm","clk":"11540639726","pt":1719496769416,"mc":[{"id":"1.230178310","rc":[{"atl":[[17,0],[6.4,4]],"id":55302014}],"con":true,"img":false}]}
{"op":"mcm","clk":"11540639742","pt":1719496769624,"mc":[{"id":"1.230178310","rc":[{"atl":[[6.2,4.28]],"id":55302014}],"con":true,"img":false}]}
{"op":"mcm","clk":"11540639753","pt":1719496769736,"mc":[{"id":"1.230178310","rc":[{"atl":[[6.4,2],[6,4]],"id":55302014}],"con":true,"img":false}]}
{"op":"mcm","clk":"11540639794","pt":1719496770231,"mc":[{"id":"1.230178310","rc":[{"atl":[[6.2,0.19]],"id":55302014}],"con":true,"img":false}]}
{"op":"mcm","clk":"11540639799","pt":1719496770335,"mc":[{"id":"1.230178310","rc":[{"atl":[[6.4,0]],"id":55302014}],"con":true,"img":false}]}
{"op":"mcm","clk":"11540639809","pt":1719496770440,"mc":[{"id":"1.230178310","rc":[{"atl":[[5.9,4.3]],"id":55302014}],"con":true,"img":false}]}
{"op":"mcm","clk":"11540640010","pt":1719496773106,"mc":[{"id":"1.230178310","rc":[{"atl":[[6.2,0]],"id":55302014}],"con":true,"img":false}]}
{"op":"mcm","clk":"11540640040","pt":1719496773520,"mc":[{"id":"1.230178310","rc":[{"atl":[[1000,0.21]],"id":55302014}],"con":true,"img":false}]}
{"op":"mcm","clk":"11540640056","pt":1719496773729,"mc":[{"id":"1.230178310","rc":[{"atl":[[1000,0]],"id":55302014}],"con":true,"img":false}]}
{"op":"mcm","clk":"11540640060","pt":1719496773831,"mc":[{"id":"1.230178310","rc":[{"atl":[[5.8,0.21]],"id":55302014}],"con":true,"img":false}]}
{"op":"mcm","clk":"11540640178","pt":1719496775240,"mc":[{"id":"1.230178310","rc":[{"atb":[[2.6,6.54]],"id":55302014}],"con":true,"img":false}]}
{"op":"mcm","clk":"11540640274","pt":1719496776327,"mc":[{"id":"1.230178310","rc":[{"atl":[[5.8,2.21]],"id":55302014}],"con":true,"img":false}]}
{"op":"mcm","clk":"11540640347","pt":1719496777252,"mc":[{"id":"1.230178310","rc":[{"atl":[[12,0]],"id":68392143}],"con":true,"img":false}]}
{"op":"mcm","clk":"11540640357","pt":1719496777307,"mc":[{"id":"1.230178310","rc":[{"atl":[[5.9,0]],"id":55302014}],"con":true,"img":false}]}
{"op":"mcm","clk":"11540640369","pt":1719496777410,"mc":[{"id":"1.230178310","rc":[{"atl":[[1000,0.31]],"id":68392143}],"con":true,"img":false}]}
{"op":"mcm","clk":"11540640374","pt":1719496777512,"mc":[{"id":"1.230178310","rc":[{"atl":[[5.7,4.45]],"id":55302014}],"con":true,"img":false}]}
{"op":"mcm","clk":"11540640384","pt":1719496777617,"mc":[{"id":"1.230178310","rc":[{"atl":[[1000,0.22]],"id":68392143}],"con":true,"img":false}]}
{"op":"mcm","clk":"11540640393","pt":1719496777720,"mc":[{"id":"1.230178310","rc":[{"atl":[[12,0.09]],"id":68392143}],"con":true,"img":false}]}
{"op":"mcm","clk":"11540640487","pt":1719496779015,"mc":[{"id":"1.230178310","rc":[{"atl":[[5.6,4],[6,0]],"id":55302014}],"con":true,"img":false}]}
{"op":"mcm","clk":"11540640519","pt":1719496779434,"mc":[{"id":"1.230178310","rc":[{"atl":[[5.7,0]],"id":55302014}],"con":true,"img":false}]}
{"op":"mcm","clk":"11540640537","pt":1719496779644,"mc":[{"id":"1.230178310","rc":[{"atl":[[5.5,4.61]],"id":55302014}],"con":true,"img":false}]}
{"op":"mcm","clk":"11540640601","pt":1719496780428,"mc":[{"id":"1.230178310","rc":[{"atl":[[5.8,0.21]],"id":55302014}],"con":true,"img":false}]}
{"op":"mcm","clk":"11540640834","pt":1719496783428,"mc":[{"id":"1.230178310","rc":[{"atl":[[5.4,2]],"id":55302014}],"con":true,"img":false}]}
{"op":"mcm","clk":"11540640887","pt":1719496783959,"mc":[{"id":"1.230178310","rc":[{"atl":[[5.5,0]],"id":55302014}],"con":true,"img":false}]}
{"op":"mcm","clk":"11540640907","pt":1719496784168,"mc":[{"id":"1.230178310","rc":[{"atl":[[5.3,4.79]],"id":55302014}],"con":true,"img":false}]}
{"op":"mcm","clk":"11540641004","pt":1719496785157,"mc":[{"id":"1.230178310","rc":[{"atl":[[5.4,0]],"id":55302014}],"con":true,"img":false}]}
{"op":"mcm","clk":"11540641038","pt":1719496785570,"mc":[{"id":"1.230178310","rc":[{"atl":[[5.3,0],[5.2,0.84]],"id":55302014}],"con":true,"img":false}]}
{"op":"mcm","clk":"11540641045","pt":1719496785624,"mc":[{"id":"1.230178310","rc":[{"atl":[[5.6,0]],"id":55302014}],"con":true,"img":false}]}
{"op":"mcm","clk":"11540641053","pt":1719496785729,"mc":[{"id":"1.230178310","rc":[{"atl":[[5.8,5.06]],"id":55302014}],"con":true,"img":false}]}
{"op":"mcm","clk":"11540641077","pt":1719496786041,"mc":[{"id":"1.230178310","rc":[{"atl":[[5.2,0]],"id":55302014},{"spn":2.94,"spf":1.0,"id":55302014},{"spn":4.05,"spf":1.0,"id":68392143}],"con":true,"img":false}]}
{"op":"mcm","clk":"11540641128","pt":1719496786561,"mc":[{"id":"1.230178310","rc":[{"atl":[[5.7,4.45]],"id":55302014}],"con":true,"img":false}]}
{"op":"mcm","clk":"11540641347","pt":1719496789053,"mc":[{"id":"1.230178310","rc":[{"atl":[[5.8,4.85]],"id":55302014}],"con":true,"img":false}]}
{"op":"mcm","clk":"11540641366","pt":1719496789258,"mc":[{"id":"1.230178310","rc":[{"atl":[[1000,0.22]],"id":55302014}],"con":true,"img":false}]}
{"op":"mcm","clk":"11540641374","pt":1719496789370,"mc":[{"id":"1.230178310","rc":[{"atb":[[2.78,0]],"id":57087188},{"atb":[[2.92,0]],"id":68392143}],"con":true,"img":false}]}
{"op":"mcm","clk":"11540641381","pt":1719496789464,"mc":[{"id":"1.230178310","rc":[{"atl":[[1000,0]],"id":55302014}],"con":true,"img":false}]}
{"op":"mcm","clk":"11540641391","pt":1719496789567,"mc":[{"id":"1.230178310","rc":[{"atl":[[5.6,0.22]],"id":55302014}],"con":true,"img":false}]}
{"op":"mcm","clk":"11540641456","pt":1719496790460,"mc":[{"id":"1.230178310","rc":[{"atl":[[5.6,2.22]],"id":55302014}],"con":true,"img":false}]}
{"op":"mcm","clk":"11540641482","pt":1719496790765,"mc":[{"id":"1.230178310","rc":[{"atl":[[5.7,0]],"id":55302014}],"con":true,"img":false}]}
{"op":"mcm","clk":"11540641498","pt":1719496790968,"mc":[{"id":"1.230178310","rc":[{"atl":[[5.5,4.61]],"id":55302014}],"con":true,"img":false}]}
{"op":"mcm","clk":"11540641539","pt":1719496791436,"mc":[{"id":"1.230178310","rc":[{"atl":[[5.6,0.22]],"id":55302014}],"con":true,"img":false}]}
{"op":"mcm","clk":"11540641600","pt":1719496792170,"mc":[{"id":"1.230178310","rc":[{"atl":[[5.5,0]],"id":55302014}],"con":true,"img":false}]}
{"op":"mcm","clk":"11540641619","pt":1719496792382,"mc":[{"id":"1.230178310","rc":[{"atl":[[5.8,0],[5.7,4.45],[6.6,6.07]],"id":55302014}],"con":true,"img":false}]}
{"op":"mcm","clk":"11540641638","pt":1719496792581,"mc":[{"id":"1.230178310","rc":[{"atl":[[5.7,5.3]],"id":55302014}],"con":true,"img":false}]}
{"op":"mcm","clk":"11540641659","pt":1719496792844,"mc":[{"id":"1.230178310","rc":[{"atl":[[12,0]],"id":68392143}],"con":true,"img":false}]}
{"op":"mcm","clk":"11540641682","pt":1719496793051,"mc":[{"id":"1.230178310","rc":[{"atl":[[1000,0.31]],"id":68392143}],"con":true,"img":false}]}
{"op":"mcm","clk":"11540641691","pt":1719496793159,"mc":[{"id":"1.230178310","rc":[{"atl":[[1000,0.22]],"id":68392143}],"con":true,"img":false}]}
{"op":"mcm","clk":"11540641699","pt":1719496793258,"mc":[{"id":"1.230178310","rc":[{"atl":[[12,0.09]],"id":68392143}],"con":true,"img":false}]}
{"op":"mcm","clk":"11540641711","pt":1719496793464,"mc":[{"id":"1.230178310","rc":[{"atb":[[2.4,9.97]],"id":55302014}],"con":true,"img":false}]}
{"op":"mcm","clk":"11540641722","pt":1719496793670,"mc":[{"id":"1.230178310","rc":[{"atb":[[2.22,11.45]],"id":65436514}],"con":true,"img":false}]}
{"op":"mcm","clk":"11540641796","pt":1719496794858,"mc":[{"id":"1.230178310","rc":[{"atl":[[5.6,5.52],[6.6,1]],"id":55302014}],"con":true,"img":false}]}
{"op":"mcm","clk":"11540641835","pt":1719496795375,"mc":[{"id":"1.230178310","rc":[{"atb":[[2.6,3.38]],"id":55302014},{"atl":[[5.7,0.84]],"id":55302014}],"con":true,"img":false}]}
{"op":"mcm","clk":"11540641851","pt":1719496795583,"mc":[{"id":"1.230178310","rc":[{"atb":[[2.38,15.46]],"id":55302014},{"atl":[[5.5,4.61]],"id":55302014}],"con":true,"img":false}]}
{"op":"mcm","clk":"11540641856","pt":1719496795689,"mc":[{"id":"1.230178310","rc":[{"atb":[[2.28,0]],"id":57088863}],"con":true,"img":false}]}
{"op":"mcm","clk":"11540641864","pt":1719496795741,"mc":[{"id":"1.230178310","rc":[{"atb":[[2.82,6.51]],"id":57087188}],"con":true,"img":false}]}
{"op":"mcm","clk":"11540641872","pt":1719496795845,"mc":[{"id":"1.230178310","rc":[{"atb":[[2.96,6.04]],"id":68392143}],"con":true,"img":false}]}
{"op":"mcm","clk":"11540641888","pt":1719496796055,"mc":[{"id":"1.230178310","rc":[{"atl":[[5.7,0]],"id":55302014}],"con":true,"img":false}]}
{"op":"mcm","clk":"11540642036","pt":1719496798181,"mc":[{"id":"1.230178310","rc":[{"atl":[[5.4,2]],"id":55302014}],"con":true,"img":false}]}
{"op":"mcm","clk":"11540642059","pt":1719496798442,"mc":[{"id":"1.230178310","rc":[{"atl":[[5.5,0]],"id":55302014}],"con":true,"img":false}]}
{"op":"mcm","clk":"11540642077","pt":1719496798659,"mc":[{"id":"1.230178310","rc":[{"atl":[[5.3,4.79]],"id":55302014}],"con":true,"img":false}]}
{"op":"mcm","clk":"11540642110","pt":1719496799168,"mc":[{"id":"1.230178310","rc":[{"atl":[[5.4,0]],"id":55302014}],"con":true,"img":false}]}
{"op":"mcm","clk":"11540642142","pt":1719496799684,"mc":[{"id":"1.230178310","rc":[{"atl":[[5.3,0]],"id":55302014}],"con":true,"img":false}]}
{"op":"mcm","clk":"11540642161","pt":1719496799947,"mc":[{"id":"1.230178310","rc":[{"atl":[[5.6,0.22],[17,6.25]],"id":55302014}],"con":true,"img":false}]}
{"op":"mcm","clk":"11540642167","pt":1719496800050,"mc":[{"id":"1.230178310","rc":[{"atl":[[5.5,0.84]],"id":55302014}],"con":true,"img":false}]}
{"op":"mcm","clk":"11540642219","pt":1719496800581,"mc":[{"id":"1.230178310","rc":[{"atl":[[5.5,0]],"id":55302014}],"con":true,"img":false}]}
{"op":"mcm","clk":"11540642336","pt":1719496801689,"mc":[{"id":"1.230178310","rc":[{"atb":[[1.03,1.7]],"id":57087188},{"atl":[[1000,1.7]],"id":57087188},{"atb":[[1.02,3.7]],"id":55302014},{"atl":[[1000,1.7]],"id":55302014},{"atb":[[1.04,1.7]],"id":57088863},{"atl":[[1000,1.7]],"id":57088863}],"con":true,"img":false}]}
{"op":"mcm","clk":"11540642361","pt":1719496801847,"mc":[{"id":"1.230178310","rc":[{"atb":[[1.03,0.11]],"id":57087188},{"atl":[[1000,0.01]],"id":57087188},{"atb":[[1.04,0.07]],"id":57088863}],"con":true,"img":false}]}
{"op":"mcm","clk":"11540642373","pt":1719496801952,"mc":[{"id":"1.230178310","rc":[{"atb":[[1.02,2.18]],"id":55302014},{"atl":[[1000,0.01]],"id":55302014},{"atl":[[1000,0]],"id":57088863}],"con":true,"img":false}]}
{"op":"mcm","clk":"11540642381","pt":1719496802054,"mc":[{"id":"1.230178310","rc":[{"atb":[[1.03,0]],"id":57087188},{"atl":[[1000,0]],"id":57087188},{"atb":[[1.04,0]],"id":57088863}],"con":true,"img":false}]}
{"op":"mcm","clk":"11540642393","pt":1719496802159,"mc":[{"id":"1.230178310","rc":[{"atb":[[3.75,0.11]],"id":57087188},{"atl":[[25,0.01]],"id":57087188},{"atb":[[1.02,2]],"id":55302014},{"atl":[[1000,0]],"id":55302014},{"atb":[[5.1,0.07]],"id":57088863}],"con":true,"img":false}]}
{"op":"mcm","clk":"11540642397","pt":1719496802261,"mc":[{"id":"1.230178310","rc":[{"atb":[[2.64,0.18]],"id":55302014},{"atl":[[16.5,0.01]],"id":55302014}],"con":true,"img":false}]}
{"op":"mcm","clk":"11540642600","pt":1719496804795,"mc":[{"id":"1.230178310","rc":[{"atb":[[2.82,6.5],[2.8,7.75],[2.24,11.55],[1.01,23.67]],"id":57087188},{"atl":[[26,0.84]],"id":57087188},{"atb":[[1.03,7.89],[2.22,11.45],[2.18,8.63],[2.2,9.87]],"id":65436514},{"atl":[[26,0.84]],"id":65436514},{"atb":[[2.24,9.77],[1.01,23.67]],"id":69142441},{"atb":[[2.4,9.97],[2.36,11.33],[1.03,7.89],[2.38,15.45],[2.6,3.38]],"id":55302014},{"atl":[[5.6,0],[19.5,0.84]],"id":55302014},{"trd":[[3.1,4.13],[3.45,0.16],[3.35,1.99],[3.4,2.26]],"ltp":3.1,"tv":8.54,"id":55302014},{"atb":[[1.02,13.83],[2.96,6.04],[2.94,7.19],[2.16,10.26]],"id":68392143},{"trd":[[5,3.99]],"ltp":5.0,"tv":3.99,"id":68392143},{"atb":[[2.3,10.74],[1.03,7.89],[2.26,13.46],[2.4,2.09]],"id":57088863}],"con":true,"img":false}]}
{"op":"mcm","clk":"11540642629","pt":1719496805100,"mc":[{"id":"1.230178310","rc":[{"atl":[[1000,0.19]],"id":55302014}],"con":true,"img":false}]}
{"op":"mcm","clk":"11540642656","pt":1719496805302,"mc":[{"id":"1.230178310","rc":[{"atl":[[1000,0]],"id":55302014}],"con":true,"img":false}]}
{"op":"mcm","clk":"11540642670","pt":1719496805375,"mc":[{"id":"1.230178310","rc":[{"atl":[[6.4,0.19]],"id":55302014}],"con":true,"img":false}]}
{"op":"mcm","clk":"11540642731","pt":1719496805985,"mc":[{"id":"1.230178310","rc":[{"atl":[[6.4,2.19]],"id":55302014}],"con":true,"img":false}]}
{"op":"mcm","clk":"11540642744","pt":1719496806195,"mc":[{"id":"1.230178310","rc":[{"atl":[[6.2,4.09]],"id":55302014}],"con":true,"img":false}]}
{"op":"mcm","clk":"11540642792","pt":1719496806864,"mc":[{"id":"1.230178310","rc":[{"atl":[[6.4,0.19]],"id":55302014}],"con":true,"img":false}]}
{"op":"mcm","clk":"11540642837","pt":1719496807595,"mc":[{"id":"1.230178310","rc":[{"atl":[[6,0.84]],"id":55302014}],"con":true,"img":false}]}
{"op":"mcm","clk":"11540642908","pt":1719496808376,"mc":[{"id":"1.230178310","rc":[{"atl":[[12,0]],"id":68392143}],"con":true,"img":false}]}
{"op":"mcm","clk":"11540642955","pt":1719496808894,"mc":[{"id":"1.230178310","rc":[{"atl":[[17,0],[6,2.84]],"id":55302014}],"con":true,"img":false}]}
{"op":"mcm","clk":"11540642968","pt":1719496808991,"mc":[{"id":"1.230178310","rc":[{"atl":[[1000,0.31]],"id":68392143}],"con":true,"img":false}]}
{"op":"mcm","clk":"11540642989","pt":1719496809197,"mc":[{"id":"1.230178310","rc":[{"atl":[[6.2,0]],"id":55302014},{"atl":[[1000,0.22]],"id":68392143}],"con":true,"img":false}]}
{"op":"mcm","clk":"11540643001","pt":1719496809299,"mc":[{"id":"1.230178310","rc":[{"atl":[[12,0.09]],"id":68392143}],"con":true,"img":false}]}
{"op":"mcm","clk":"11540643010","pt":1719496809361,"mc":[{"id":"1.230178310","rc":[{"atl":[[5.9,4.3]],"id":55302014}],"con":true,"img":false}]}
{"op":"mcm","clk":"11540643331","pt":1719496812989,"mc":[{"id":"1.230178310","rc":[{"atl":[[5.8,2]],"id":55302014}],"con":true,"img":false}]}
{"op":"mcm","clk":"11540643347","pt":1719496813196,"mc":[{"id":"1.230178310","rc":[{"atl":[[5.9,0]],"id":55302014}],"con":true,"img":false}]}
{"op":"mcm","clk":"11540643361","pt":1719496813407,"mc":[{"id":"1.230178310","rc":[{"atl":[[5.7,4.45]],"id":55302014}],"con":true,"img":false}]}
{"op":"mcm","clk":"11540643374","pt":1719496813598,"mc":[{"id":"1.230178310","rc":[{"atl":[[6,2]],"id":55302014}],"con":true,"img":false}]}
{"op":"mcm","clk":"11540643399","pt":1719496813870,"mc":[{"id":"1.230178310","rc":[{"atl":[[5.8,0]],"id":55302014}],"con":true,"img":false}]}
{"op":"mcm","clk":"11540643443","pt":1719496814486,"mc":[{"id":"1.230178310","rc":[{"atl":[[5.7,0]],"id":55302014}],"con":true,"img":false}]}
{"op":"mcm","clk":"11540643457","pt":1719496814593,"mc":[{"id":"1.230178310","rc":[{"atl":[[5.6,0.84],[6,0],[6.6,3.19]],"id":55302014}],"con":true,"img":false}]}
{"op":"mcm","clk":"11540643495","pt":1719496815108,"mc":[{"id":"1.230178310","rc":[{"atl":[[5.6,0]],"id":55302014}],"con":true,"img":false}]}
{"op":"mcm","clk":"11540643511","pt":1719496815305,"mc":[{"id":"1.230178310","rc":[{"atl":[[16.5,3.39],[6.6,1]],"id":55302014}],"con":true,"img":false}]}
{"op":"mcm","clk":"11540643585","pt":1719496816104,"mc":[{"id":"1.230178310","rc":[{"atb":[[2.6,6.54]],"id":55302014}],"con":true,"img":false}]}
{"op":"mcm","clk":"11540643601","pt":1719496816300,"mc":[{"id":"1.230178310","rc":[{"atb":[[2.2,0]],"id":65436514}],"con":true,"img":false}]}
{"op":"mcm","clk":"11540643625","pt":1719496816469,"mc":[{"id":"1.230178310","rc":[{"atb":[[2.32,8.97]],"id":57088863}],"con":true,"img":false}]}
{"op":"mcm","clk":"11540643964","pt":1719496820301,"mc":[{"id":"1.230178310","rc":[{"atl":[[6.4,2.19]],"id":55302014}],"con":true,"img":false}]}
{"op":"mcm","clk":"11540643977","pt":1719496820408,"mc":[{"id":"1.230178310","rc":[{"atl":[[16.5,0.01]],"id":55302014}],"con":true,"img":false}]}
{"op":"mcm","clk":"11540643982","pt":1719496820504,"mc":[{"id":"1.230178310","rc":[{"atl":[[6.4,4.38]],"id":55302014}],"con":true,"img":false}]}
{"op":"mcm","clk":"11540643990","pt":1719496820602,"mc":[{"id":"1.230178310","rc":[{"atl":[[6.4,4.19],[6.2,4.09]],"id":55302014}],"con":true,"img":false}]}
{"op":"mcm","clk":"11540643998","pt":1719496820703,"mc":[{"id":"1.230178310","rc":[{"atb":[[2.8,0]],"id":57087188},{"atb":[[2.94,0]],"id":68392143}],"con":true,"img":false}]}
{"op":"mcm","clk":"11540644007","pt":1719496820805,"mc":[{"id":"1.230178310","rc":[{"atl":[[1000,0.19]],"id":55302014}],"con":true,"img":false}]}
{"op":"mcm","clk":"11540644015","pt":1719496820909,"mc":[{"id":"1.230178310","rc":[{"atl":[[1000,0]],"id":55302014}],"con":true,"img":false}]}
{"op":"mcm","clk":"11540644023","pt":1719496821012,"mc":[{"id":"1.230178310","rc":[{"atl":[[6.2,4.28]],"id":55302014}],"con":true,"img":false}]}
{"op":"mcm","clk":"11540644047","pt":1719496821286,"mc":[{"id":"1.230178310","rc":[{"atl":[[6.4,2.19]],"id":55302014}],"con":true,"img":false}]}
{"op":"mcm","clk":"11540644106","pt":1719496822110,"mc":[{"id":"1.230178310","rc":[{"atl":[[6,0.84]],"id":55302014}],"con":true,"img":false}]}
{"op":"mcm","clk":"11540644290","pt":1719496824411,"mc":[{"id":"1.230178310","rc":[{"atl":[[12,0]],"id":68392143}],"con":true,"img":false}]}
{"op":"mcm","clk":"11540644327","pt":1719496824823,"mc":[{"id":"1.230178310","rc":[{"atl":[[1000,0.31]],"id":68392143}],"con":true,"img":false}]}
{"op":"mcm","clk":"11540644341","pt":1719496824981,"mc":[{"id":"1.230178310","rc":[{"atl":[[1000,0.22]],"id":68392143}],"con":true,"img":false}]}
{"op":"mcm","clk":"11540644351","pt":1719496825091,"mc":[{"id":"1.230178310","rc":[{"atl":[[12,0.09]],"id":68392143}],"con":true,"img":false}]}
{"op":"mcm","clk":"11540644534","pt":1719496827415,"mc":[{"id":"1.230178310","rc":[{"atl":[[6,2.84]],"id":55302014}],"con":true,"img":false}]}
{"op":"mcm","clk":"11540644557","pt":1719496827720,"mc":[{"id":"1.230178310","rc":[{"atl":[[6.2,0.19]],"id":55302014}],"con":true,"img":false}]}
{"op":"mcm","clk":"11540644575","pt":1719496827885,"mc":[{"id":"1.230178310","rc":[{"atl":[[5.9,4.3]],"id":55302014}],"con":true,"img":false}]}
{"op":"mcm","clk":"11540644619","pt":1719496828401,"mc":[{"id":"1.230178310","rc":[{"atl":[[6,0.84]],"id":55302014}],"con":true,"img":false}]}
{"op":"mcm","clk":"11540644636","pt":1719496828709,"mc":[{"id":"1.230178310","rc":[{"atl":[[26,0]],"id":57087188},{"atl":[[26,0]],"id":65436514},{"atl":[[19.5,0]],"id":55302014}],"con":true,"img":false}]}
{"op":"mcm","clk":"11540644661","pt":1719496829217,"mc":[{"id":"1.230178310","rc":[{"atl":[[6.4,0],[5.8,2]],"id":55302014}],"con":true,"img":false}]}
{"op":"mcm","clk":"11540644692","pt":1719496829596,"mc":[{"id":"1.230178310","rc":[{"atl":[[6,0],[5.7,0.84]],"id":55302014}],"con":true,"img":false}]}
{"op":"mcm","clk":"11540644700","pt":1719496829700,"mc":[{"id":"1.230178310","rc":[{"atl":[[5.9,0]],"id":55302014}],"con":true,"img":false}]}
{"op":"mcm","clk":"11540644714","pt":1719496829907,"mc":[{"id":"1.230178310","rc":[{"atl":[[5.7,5.29]],"id":55302014}],"con":true,"img":false}]}
{"op":"mcm","clk":"11540644920","pt":1719496832304,"mc":[{"id":"1.230178310","rc":[{"atb":[[2.88,7.43]],"id":68392143}],"con":true,"img":false}]}
{"op":"mcm","clk":"11540644954","pt":1719496832707,"mc":[{"id":"1.230178310","rc":[{"atb":[[2.38,23.55]],"id":55302014}],"con":true,"img":false}]}
{"op":"mcm","clk":"11540645034","pt":1719496833631,"mc":[{"id":"1.230178310","rc":[{"atb":[[6.8,0],[7.2,1]],"id":69142441}],"con":true,"img":false}]}
{"op":"mcm","clk":"11540645047","pt":1719496833695,"mc":[{"id":"1.230178310","rc":[{"atb":[[6,6]],"id":69142441}],"con":true,"img":false}]}
{"op":"mcm","clk":"11540645058","pt":1719496833808,"mc":[{"id":"1.230178310","rc":[{"atl":[[8,1],[7.6,0]],"id":57087188},{"atl":[[7.6,1],[7,0]],"id":65436514},{"atb":[[4.8,0]],"id":69142441},{"atb":[[2.62,0]],"id":55302014},{"atl":[[6.4,1],[6.6,0]],"id":55302014},{"atb":[[3.85,1]],"id":68392143}],"con":true,"img":false}]}
{"op":"mcm","clk":"11540645068","pt":1719496833904,"mc":[{"id":"1.230178310","rc":[{"atb":[[3.1,0],[3.35,6.51]],"id":57087188},{"atl":[[8,1]],"id":65436514},{"atl":[[5.9,1]],"id":55302014},{"atl":[[16,0],[17.5,1]],"id":57088863}],"con":true,"img":false}]}
{"op":"mcm","clk":"11540645077","pt":1719496834015,"mc":[{"id":"1.230178310","rc":[{"atl":[[25,3.61],[27,1.6]],"id":57087188},{"atb":[[3.85,8.43],[3.65,0]],"id":68392143}],"con":true,"img":false}]}
{"op":"mcm","clk":"11540645109","pt":1719496834420,"mc":[{"id":"1.230178310","rc":[{"atl":[[5.6,2]],"id":55302014}],"con":true,"img":false}]}
{"op":"mcm","clk":"11540645141","pt":1719496834720,"mc":[{"id":"1.230178310","rc":[{"atl":[[5.7,0.84]],"id":55302014}],"con":true,"img":false}]}
{"op":"mcm","clk":"11540645152","pt":1719496834923,"mc":[{"id":"1.230178310","rc":[{"atl":[[5.5,4.61]],"id":55302014}],"con":true,"img":false}]}
{"op":"mcm","clk":"11540645179","pt":1719496835090,"mc":[{"id":"1.230178310","rc":[{"atb":[[2.24,9.55]],"id":65436514}],"con":true,"img":false}]}
{"op":"mcm","clk":"11540645188","pt":1719496835194,"mc":[{"id":"1.230178310","rc":[{"atb":[[2.92,2.5]],"id":57087188},{"atb":[[2.48,3.95]],"id":55302014}],"con":true,"img":false}]}
{"op":"mcm","clk":"11540645208","pt":1719496835406,"mc":[{"id":"1.230178310","rc":[{"atl":[[5.6,0]],"id":55302014}],"con":true,"img":false}]}
{"op":"mcm","clk":"11540645236","pt":1719496835712,"mc":[{"id":"1.230178310","rc":[{"atb":[[2.92,0]],"id":57087188},{"atb":[[2.48,0]],"id":55302014},{"atl":[[5.7,0]],"id":55302014}],"con":true,"img":false}]}
{"op":"mcm","clk":"11540645254","pt":1719496836024,"mc":[{"id":"1.230178310","rc":[{"atl":[[5.5,0]],"id":55302014}],"con":true,"img":false}]}
{"op":"mcm","clk":"11540645261","pt":1719496836120,"mc":[{"id":"1.230178310","rc":[{"atl":[[6.2,0]],"id":55302014}],"con":true,"img":false}]}
{"op":"mcm","clk":"11540645267","pt":1719496836221,"mc":[{"id":"1.230178310","rc":[{"atl":[[5.8,0],[6.2,3],[5.7,4.45]],"id":55302014}],"con":true,"img":false}]}
{"op":"mcm","clk":"11540645275","pt":1719496836325,"mc":[{"id":"1.230178310","rc":[{"atl":[[6.2,0]],"id":55302014}],"con":true,"img":false}]}
{"op":"mcm","clk":"11540645284","pt":1719496836422,"mc":[{"id":"1.230178310","rc":[{"atl":[[6.4,4]],"id":55302014}],"con":true,"img":false}]}
{"op":"mcm","clk":"11540645299","pt":1719496836627,"mc":[{"id":"1.230178310","rc":[{"atl":[[5.6,0.84]],"id":55302014},{"atb":[[3.35,2.5]],"id":68392143}],"con":true,"img":false}]}
{"op":"mcm","clk":"11540645311","pt":1719496836812,"mc":[{"id":"1.230178310","rc":[{"atl":[[1000,0.22]],"id":55302014}],"con":true,"img":false}]}
{"op":"mcm","clk":"11540645319","pt":1719496836896,"mc":[{"id":"1.230178310","rc":[{"atl":[[1000,0]],"id":55302014}],"con":true,"img":false}]}
{"op":"mcm","clk":"11540645329","pt":1719496837002,"mc":[{"id":"1.230178310","rc":[{"atl":[[5.6,1.06]],"id":55302014}],"con":true,"img":false}]}
{"op":"mcm","clk":"11540645356","pt":1719496837305,"mc":[{"id":"1.230178310","rc":[{"atl":[[5.7,0]],"id":55302014}],"con":true,"img":false}]}
{"op":"mcm","clk":"11540645385","pt":1719496837625,"mc":[{"id":"1.230178310","rc":[{"atl":[[5.6,0.22]],"id":55302014}],"con":true,"img":false}]}
{"op":"mcm","clk":"11540645537","pt":1719496839629,"mc":[{"id":"1.230178310","rc":[{"atb":[[3.35,0]],"id":68392143}],"con":true,"img":false}]}
{"op":"mcm","clk":"11540645592","pt":1719496840315,"mc":[{"id":"1.230178310","rc":[{"atl":[[12,0]],"id":68392143}],"con":true,"img":false}]}
{"op":"mcm","clk":"11540645653","pt":1719496841035,"mc":[{"id":"1.230178310","rc":[{"atl":[[8,0],[7.8,1]],"id":57087188},{"atl":[[8,0],[7.6,0],[7.8,1]],"id":65436514},{"atb":[[6.8,1],[7.2,0]],"id":69142441},{"atl":[[6.4,3]],"id":55302014},{"atb":[[3.85,7.43]],"id":68392143},{"atl":[[1000,0.31]],"id":68392143},{"atl":[[17.5,0],[17,1]],"id":57088863}],"con":true,"img":false}]}
{"op":"mcm","clk":"11540645665","pt":1719496841140,"mc":[{"id":"1.230178310","rc":[{"atl":[[7.6,1],[25,0.01],[26,4]],"id":57087188},{"atl":[[8,5.57],[7.4,1],[27,1.72]],"id":65436514},{"atl":[[5.9,0]],"id":55302014},{"atl":[[1000,0.22]],"id":68392143},{"atl":[[16,1]],"id":57088863}],"con":true,"img":false}]}
{"op":"mcm","clk":"11540645675","pt":1719496841208,"mc":[{"id":"1.230178310","rc":[{"atl":[[12,0.09]],"id":68392143}],"con":true,"img":false}]}
{"op":"mcm","clk":"11540645687","pt":1719496841309,"mc":[{"id":"1.230178310","rc":[{"atl":[[16.5,6.46],[6.4,0]],"id":55302014}],"con":true,"img":false}]}
{"op":"mcm","clk":"11540645695","pt":1719496841418,"mc":[{"id":"1.230178310","rc":[{"atl":[[6.2,2]],"id":55302014}],"con":true,"img":false}]}
{"op":"mcm","clk":"11540645722","pt":1719496841725,"mc":[{"id":"1.230178310","rc":[{"atl":[[6,4.23]],"id":55302014}],"con":true,"img":false}]}
{"op":"mcm","clk":"11540645783","pt":1719496842337,"mc":[{"id":"1.230178310","rc":[{"atl":[[6.2,0]],"id":55302014}],"con":true,"img":false}]}
{"op":"mcm","clk":"11540645842","pt":1719496843121,"mc":[{"id":"1.230178310","rc":[{"atl":[[6,0]],"id":55302014}],"con":true,"img":false}]}
{"op":"mcm","clk":"11540645852","pt":1719496843333,"mc":[{"id":"1.230178310","rc":[{"atl":[[16,1.59]],"id":55302014}],"con":true,"img":false}]}
{"op":"mcm","clk":"11540645897","pt":1719496843838,"mc":[{"id":"1.230178310","rc":[{"atb":[[7.2,1]],"id":69142441}],"con":true,"img":false}]}
{"op":"mcm","clk":"11540645909","pt":1719496843943,"mc":[{"id":"1.230178310","rc":[{"atb":[[6.8,0]],"id":69142441},{"atl":[[6.4,1]],"id":55302014}],"con":true,"img":false}]}
{"op":"mcm","clk":"11540645920","pt":1719496844007,"mc":[{"id":"1.230178310","rc":[{"atl":[[15.5,0.84]],"id":55302014},{"atb":[[4,1]],"id":68392143}],"con":true,"img":false}]}
{"op":"mcm","clk":"11540645930","pt":1719496844106,"mc":[{"id":"1.230178310","rc":[{"atl":[[8,1],[8.2,1],[7.8,0],[7.6,0]],"id":57087188},{"atl":[[8.2,1],[7.4,0],[7.8,0],[8.4,1]],"id":65436514},{"atl":[[32,0],[36,1]],"id":69142441},{"atl":[[6.4,0],[5.9,1]],"id":55302014},{"atb":[[3.85,0],[4.1,6.04]],"id":68392143},{"atl":[[16,0],[17,0],[17.5,1]],"id":57088863}],"con":true,"img":false}]}
{"op":"mcm","clk":"11540645938","pt":1719496844211,"mc":[{"id":"1.230178310","rc":[{"atl":[[7.6,1]],"id":65436514},{"atb":[[4,0]],"id":68392143},{"atl":[[140,0],[21,4]],"id":57088863}],"con":true,"img":false}]}
{"op":"mcm","clk":"11540645946","pt":1719496844314,"mc":[{"id":"1.230178310","rc":[{"atl":[[8.2,0]],"id":57087188},{"atl":[[8,6.57],[8.2,0],[8.4,0]],"id":65436514},{"atl":[[32,1],[36,0]],"id":69142441},{"atb":[[3.85,1]],"id":68392143}],"con":true,"img":false}]}
{"op":"mcm","clk":"11540645956","pt":1719496844424,"mc":[{"id":"1.230178310","rc":[{"atl":[[7.6,0]],"id":65436514},{"atl":[[16,0]],"id":55302014}],"con":true,"img":false}]}
{"op":"mcm","clk":"11540646001","pt":1719496845033,"mc":[{"id":"1.230178310","rc":[{"atl":[[7.8,0.84]],"id":65436514},{"atl":[[15.5,0]],"id":55302014}],"con":true,"img":false}]}
{"op":"mcm","clk":"11540646064","pt":1719496845614,"mc":[{"id":"1.230178310","rc":[{"atl":[[27,0]],"id":65436514}],"con":true,"img":false}]}
{"op":"mcm","clk":"11540646107","pt":1719496846231,"mc":[{"id":"1.230178310","rc":[{"spn":6.15,"spf":"NaN","id":57087188},{"atl":[[8,1],[27,3.85]],"id":65436514},{"spn":5.8,"spf":"NaN","id":65436514},{"spn":4.27,"spf":1.0,"id":68392143},{"spn":11.95,"spf":"NaN","id":57088863}],"con":true,"img":false}]}
{"op":"mcm","clk":"11540646114","pt":1719496846337,"mc":[{"id":"1.230178310","rc":[{"spl":[[1.01,4]],"id":57087188},{"spb":[[1000,11]],"id":65436514},{"spl":[[1.01,2]],"id":69142441},{"spl":[[1.01,5]],"id":55302014},{"spb":[[1000,22]],"id":68392143},{"spl":[[1.01,2]],"id":57088863}],"con":true,"img":false}]}
{"op":"mcm","clk":"11540646152","pt":1719496846744,"mc":[{"id":"1.230178310","rc":[{"atl":[[8,0],[7.8,1],[7.6,1]],"id":57087188},{"atl":[[8,0],[7.4,1],[7.8,1.84]],"id":65436514},{"atb":[[6.8,1],[7.2,0]],"id":69142441},{"atl":[[6.4,1],[5.9,0]],"id":55302014},{"atb":[[3.85,0]],"id":68392143},{"atl":[[16,1],[17.5,0],[17,1]],"id":57088863}],"con":true,"img":false}]}
{"op":"mcm","clk":"11540646303","pt":1719496848513,"mc":[{"id":"1.230178310","rc":[{"atl":[[6.2,2]],"id":55302014}],"con":true,"img":false}]}
{"op":"mcm","clk":"11540646320","pt":1719496848718,"mc":[{"id":"1.230178310","rc":[{"atl":[[6,4.23]],"id":55302014}],"con":true,"img":false}]}
{"op":"mcm","clk":"11540646378","pt":1719496849444,"mc":[{"id":"1.230178310","rc":[{"atl":[[6.2,0]],"id":55302014}],"con":true,"img":false}]}
{"op":"mcm","clk":"11540646409","pt":1719496849810,"mc":[{"id":"1.230178310","rc":[{"atl":[[16.5,0.01],[5.9,4.23]],"id":55302014}],"con":true,"img":false}]}
{"op":"mcm","clk":"11540646438","pt":1719496850220,"mc":[{"id":"1.230178310","rc":[{"atl":[[6,0]],"id":55302014}],"con":true,"img":false}]}
{"op":"mcm","clk":"11540646447","pt":1719496850322,"mc":[{"id":"1.230178310","rc":[{"atl":[[6.4,5.45],[5.9,0]],"id":55302014}],"con":true,"img":false}]}
{"op":"mcm","clk":"11540646454","pt":1719496850427,"mc":[{"id":"1.230178310","rc":[{"atl":[[5.8,4.37]],"id":55302014}],"con":true,"img":false}]}
{"op":"mcm","clk":"11540646461","pt":1719496850531,"mc":[{"id":"1.230178310","rc":[{"atl":[[6.4,1],[5.7,4.38]],"id":55302014}],"con":true,"img":false}]}
{"op":"mcm","clk":"11540646467","pt":1719496850629,"mc":[{"id":"1.230178310","rc":[{"atb":[[3.75,0],[1.04,3.4]],"id":57087188},{"atl":[[1000,3.4],[25,0]],"id":57087188},{"atb":[[2.64,0]],"id":55302014},{"atl":[[16.5,0]],"id":55302014},{"atb":[[5.1,0]],"id":57088863}],"con":true,"img":false}]}
{"op":"mcm","clk":"11540646480","pt":1719496850842,"mc":[{"id":"1.230178310","rc":[{"atb":[[1.04,0.14]],"id":57087188},{"atl":[[1000,0.06]],"id":57087188}],"con":true,"img":false}]}
{"op":"mcm","clk":"11540646500","pt":1719496851042,"mc":[{"id":"1.230178310","rc":[{"atb":[[1.04,0]],"id":57087188},{"atl":[[1000,0]],"id":57087188},{"atl":[[5.6,1.06]],"id":55302014}],"con":true,"img":false}]}
{"op":"mcm","clk":"11540646512","pt":1719496851144,"mc":[{"id":"1.230178310","rc":[{"atb":[[3.75,0.14]],"id":57087188},{"atl":[[7.6,1.06]],"id":57087188}],"con":true,"img":false}]}
{"op":"mcm","clk":"11540646521","pt":1719496851243,"mc":[{"id":"1.230178310","rc":[{"atl":[[5.8,0]],"id":55302014}],"con":true,"img":false}]}
{"op":"mcm","clk":"11540646611","pt":1719496852220,"mc":[{"id":"1.230178310","rc":[{"atl":[[5.6,0.84]],"id":55302014}],"con":true,"img":false}]}
{"op":"mcm","clk":"11540646632","pt":1719496852434,"mc":[{"id":"1.230178310","rc":[{"atl":[[6.4,9],[5.7,0]],"id":55302014}],"con":true,"img":false}]}
{"op":"mcm","clk":"11540646680","pt":1719496852852,"mc":[{"id":"1.230178310","rc":[{"atl":[[1000,0.19]],"id":55302014}],"con":true,"img":false}]}
{"op":"mcm","clk":"11540646685","pt":1719496852939,"mc":[{"id":"1.230178310","rc":[{"atb":[[2.22,0]],"id":65436514},{"atb":[[2.3,0]],"id":57088863}],"con":true,"img":false}]}
{"op":"mcm","clk":"11540646699","pt":1719496853048,"mc":[{"id":"1.230178310","rc":[{"atl":[[5.6,0],[1000,0]],"id":55302014}],"con":true,"img":false}]}
{"op":"mcm","clk":"11540646708","pt":1719496853145,"mc":[{"id":"1.230178310","rc":[{"atl":[[6.2,0.19]],"id":55302014}],"con":true,"img":false}]}
{"op":"mcm","clk":"11540646716","pt":1719496853211,"mc":[{"id":"1.230178310","rc":[{"atl":[[6.2,4.28]],"id":55302014}],"con":true,"img":false}]}
{"op":"mcm","clk":"11540646915","pt":1719496855553,"mc":[{"id":"1.230178310","rc":[{"atl":[[6,2]],"id":55302014}],"con":true,"img":false}]}
{"op":"mcm","clk":"11540647002","pt":1719496856436,"mc":[{"id":"1.230178310","rc":[{"atl":[[6.2,0.19]],"id":55302014},{"atl":[[12,0]],"id":68392143}],"con":true,"img":false}]}
{"op":"mcm","clk":"11540647020","pt":1719496856641,"mc":[{"id":"1.230178310","rc":[{"atl":[[5.9,4.3]],"id":55302014}],"con":true,"img":false}]}
{"op":"mcm","clk":"11540647029","pt":1719496856744,"mc":[{"id":"1.230178310","rc":[{"atl":[[7.8,0]],"id":57087188},{"atl":[[1000,0.31]],"id":68392143}],"con":true,"img":false}]}
{"op":"mcm","clk":"11540647039","pt":1719496856845,"mc":[{"id":"1.230178310","rc":[{"atl":[[7.8,0.84]],"id":65436514},{"atl":[[17,0]],"id":57088863}],"con":true,"img":false}]}
{"op":"mcm","clk":"11540647049","pt":1719496856943,"mc":[{"id":"1.230178310","rc":[{"atl":[[1000,0.22]],"id":68392143},{"atl":[[140,2],[21,0]],"id":57088863}],"con":true,"img":false}]}
{"op":"mcm","clk":"11540647059","pt":1719496857047,"mc":[{"id":"1.230178310","rc":[{"atl":[[7.8,0]],"id":65436514},{"atl":[[12,0.09]],"id":68392143}],"con":true,"img":false}]}
{"op":"mcm","clk":"11540647087","pt":1719496857316,"mc":[{"id":"1.230178310","rc":[{"atl":[[6,0]],"id":55302014}],"con":true,"img":false}]}
{"op":"mcm","clk":"11540647108","pt":1719496857627,"mc":[{"id":"1.230178310","rc":[{"atl":[[5.9,0]],"id":55302014}],"con":true,"img":false}]}
{"op":"mcm","clk":"11540647112","pt":1719496857732,"mc":[{"id":"1.230178310","rc":[{"atl":[[6.4,1]],"id":55302014}],"con":true,"img":false}]}
{"op":"mcm","clk":"11540647121","pt":1719496857835,"mc":[{"id":"1.230178310","rc":[{"atl":[[17,6.25],[6.2,4.28]],"id":55302014}],"con":true,"img":false}]}
{"op":"mcm","clk":"11540647177","pt":1719496858655,"mc":[{"id":"1.230178310","rc":[{"atl":[[6,0.84]],"id":55302014}],"con":true,"img":false}]}
{"op":"mcm","clk":"11540647305","pt":1719496860058,"mc":[{"id":"1.230178310","rc":[{"atb":[[3,6.83]],"id":55302014}],"con":true,"img":false}]}
{"op":"mcm","clk":"11540647361","pt":1719496860544,"mc":[{"id":"1.230178310","rc":[{"atb":[[3.05,0.84]],"id":55302014}],"con":true,"img":false}]}
{"op":"mcm","clk":"11540647397","pt":1719496860856,"mc":[{"id":"1.230178310","rc":[{"atl":[[17,0],[6,2.84]],"id":55302014}],"con":true,"img":false}]}
{"op":"mcm","clk":"11540647440","pt":1719496861426,"mc":[{"id":"1.230178310","rc":[{"atl":[[6.2,0.19]],"id":55302014}],"con":true,"img":false}]}
{"op":"mcm","clk":"11540647448","pt":1719496861532,"mc":[{"id":"1.230178310","rc":[{"atl":[[6.4,9],[6,0.84]],"id":55302014}],"con":true,"img":false}]}
{"op":"mcm","clk":"11540647488","pt":1719496862051,"mc":[{"id":"1.230178310","rc":[{"atl":[[6,0]],"id":55302014}],"con":true,"img":false}]}
{"op":"mcm","clk":"11540647505","pt":1719496862251,"mc":[{"id":"1.230178310","rc":[{"atl":[[17,6.25],[6.4,1]],"id":55302014}],"con":true,"img":false}]}
{"op":"mcm","clk":"11540647516","pt":1719496862354,"mc":[{"id":"1.230178310","rc":[{"atl":[[7.6,0.06],[7.8,1]],"id":57087188},{"atl":[[7.4,0],[7.6,1]],"id":65436514},{"atl":[[6.2,4.28]],"id":55302014},{"atl":[[16,0],[15.5,1]],"id":57088863}],"con":true,"img":false}]}
{"op":"mcm","clk":"11540647531","pt":1719496862558,"mc":[{"id":"1.230178310","rc":[{"atl":[[6,2]],"id":55302014}],"con":true,"img":false}]}
{"op":"mcm","clk":"11540647539","pt":1719496862670,"mc":[{"id":"1.230178310","rc":[{"atl":[[7.6,1.06],[7.8,0]],"id":57087188},{"atl":[[7.4,1],[7.6,0]],"id":65436514},{"atb":[[4.1,0],[3.75,6.04]],"id":68392143}],"con":true,"img":false}]}
{"op":"mcm","clk":"11540647546","pt":1719496862766,"mc":[{"id":"1.230178310","rc":[{"atl":[[26,0],[8.8,4]],"id":57087188},{"atb":[[4.1,6.04],[3.75,0]],"id":68392143}],"con":true,"img":false}]}
{"op":"mcm","clk":"11540647556","pt":1719496862825,"mc":[{"id":"1.230178310","rc":[{"atl":[[26,4],[8.8,0]],"id":57087188}],"con":true,"img":false}]}
{"op":"mcm","clk":"11540647573","pt":1719496863040,"mc":[{"id":"1.230178310","rc":[{"atl":[[6.2,0.19]],"id":55302014}],"con":true,"img":false}]}
{"op":"mcm","clk":"11540647713","pt":1719496864652,"mc":[{"id":"1.230178310","rc":[{"atb":[[6.8,0],[7.2,1]],"id":69142441},{"atb":[[3.85,1],[4,1]],"id":68392143}],"con":true,"img":false}]}
{"op":"mcm","clk":"11540647806","pt":1719496865833,"mc":[{"id":"1.230178310","rc":[{"atb":[[6.8,1],[7.2,0]],"id":69142441},{"atl":[[32,0],[34,1]],"id":69142441},{"atl":[[6.4,0],[5.8,1]],"id":55302014},{"atb":[[3.85,0],[4,0]],"id":68392143}],"con":true,"img":false}]}
{"op":"mcm","clk":"11540647830","pt":1719496866045,"mc":[{"id":"1.230178310","rc":[{"atl":[[5.9,0.84]],"id":55302014}],"con":true,"img":false}]}
{"op":"mcm","clk":"11540647902","pt":1719496866662,"mc":[{"id":"1.230178310","rc":[{"atl":[[6,0]],"id":55302014}],"con":true,"img":false}]}
{"op":"mcm","clk":"11540647940","pt":1719496867037,"mc":[{"id":"1.230178310","rc":[{"atl":[[5.9,0]],"id":55302014}],"con":true,"img":false}]}
{"op":"mcm","clk":"11540648019","pt":1719496867869,"mc":[{"id":"1.230178310","rc":[{"atb":[[2.82,0]],"id":57087188},{"atb":[[2.38,14.97]],"id":55302014},{"atb":[[2.96,0]],"id":68392143}],"con":true,"img":false}]}
{"op":"mcm","clk":"11540648069","pt":1719496868442,"mc":[{"id":"1.230178310","rc":[{"atl":[[6.2,0]],"id":55302014}],"con":true,"img":false}]}
{"op":"mcm","clk":"11540648099","pt":1719496868755,"mc":[{"id":"1.230178310","rc":[{"atl":[[1000,0.21]],"id":55302014}],"con":true,"img":false}]}
{"op":"mcm","clk":"11540648110","pt":1719496868855,"mc":[{"id":"1.230178310","rc":[{"atl":[[1000,0]],"id":55302014}],"con":true,"img":false}]}
{"op":"mcm","clk":"11540648121","pt":1719496868955,"mc":[{"id":"1.230178310","rc":[{"atl":[[5.7,0.21]],"id":55302014}],"con":true,"img":false}]}
{"op":"mcm","clk":"11540648169","pt":1719496869366,"mc":[{"id":"1.230178310","rc":[{"atl":[[7.4,0],[7,1]],"id":65436514},{"atl":[[32,1],[34,0]],"id":69142441},{"atl":[[5.8,0],[6.6,1]],"id":55302014}],"con":true,"img":false}]}
{"op":"mcm","clk":"11540648178","pt":1719496869442,"mc":[{"id":"1.230178310","rc":[{"atl":[[27,0],[7.8,8]],"id":65436514}],"con":true,"img":false}]}
{"op":"mcm","clk":"11540648186","pt":1719496869534,"mc":[{"id":"1.230178310","rc":[{"atl":[[6.4,2]],"id":55302014}],"con":true,"img":false}]}
{"op":"mcm","clk":"11540648193","pt":1719496869638,"mc":[{"id":"1.230178310","rc":[{"atl":[[27,3.85],[7.8,0]],"id":65436514}],"con":true,"img":false}]}
{"op":"mcm","clk":"11540648209","pt":1719496869845,"mc":[{"id":"1.230178310","rc":[{"atl":[[6.2,4.09]],"id":55302014},{"atb":[[2.34,10.42]],"id":57088863}],"con":true,"img":false}]}
{"op":"mcm","clk":"11540648216","pt":1719496869948,"mc":[{"id":"1.230178310","rc":[{"atb":[[2.6,3.15]],"id":55302014}],"con":true,"img":false}]}
{"op":"mcm","clk":"11540648256","pt":1719496870544,"mc":[{"id":"1.230178310","rc":[{"atl":[[17,0],[6.4,0],[6,2]],"id":55302014}],"con":true,"img":false}]}
{"op":"mcm","clk":"11540648289","pt":1719496870954,"mc":[{"id":"1.230178310","rc":[{"atl":[[6.2,0]],"id":55302014}],"con":true,"img":false}]}
{"op":"mcm","clk":"11540648296","pt":1719496871060,"mc":[{"id":"1.230178310","rc":[{"atb":[[3.05,4.23]],"id":55302014}],"con":true,"img":false}]}
{"op":"mcm","clk":"11540648379","pt":1719496872046,"mc":[{"id":"1.230178310","rc":[{"atb":[[1.03,11.29]],"id":55302014},{"atl":[[1000,3.4]],"id":55302014}],"con":true,"img":false}]}
{"op":"mcm","clk":"11540648388","pt":1719496872138,"mc":[{"id":"1.230178310","rc":[{"atl":[[12,0]],"id":68392143}],"con":true,"img":false}]}
{"op":"mcm","clk":"11540648398","pt":1719496872254,"mc":[{"id":"1.230178310","rc":[{"atb":[[1.03,8.07]],"id":55302014},{"atl":[[1000,0.08]],"id":55302014}],"con":true,"img":false}]}
{"op":"mcm","clk":"11540648412","pt":1719496872459,"mc":[{"id":"1.230178310","rc":[{"atl":[[1000,0.31]],"id":68392143}],"con":true,"img":false}]}
{"op":"mcm","clk":"11540648420","pt":1719496872564,"mc":[{"id":"1.230178310","rc":[{"atb":[[1.03,7.89]],"id":55302014},{"atl":[[1000,0]],"id":55302014}],"con":true,"img":false}]}
{"op":"mcm","clk":"11540648427","pt":1719496872667,"mc":[{"id":"1.230178310","rc":[{"atb":[[3.1,0.18]],"id":55302014},{"atl":[[5.9,0.08]],"id":55302014},{"atl":[[1000,0.22]],"id":68392143}],"con":true,"img":false}]}
{"op":"mcm","clk":"11540648433","pt":1719496872770,"mc":[{"id":"1.230178310","rc":[{"atl":[[12,0.09]],"id":68392143}],"con":true,"img":false}]}
{"op":"mcm","clk":"11540648448","pt":1719496873034,"mc":[{"id":"1.230178310","rc":[{"atl":[[5.9,0.92]],"id":55302014}],"con":true,"img":false}]}
{"op":"mcm","clk":"11540648518","pt":1719496873971,"mc":[{"id":"1.230178310","rc":[{"atb":[[2.24,0]],"id":65436514},{"atb":[[2.32,0]],"id":57088863}],"con":true,"img":false}]}
{"op":"mcm","clk":"11540648525","pt":1719496874061,"mc":[{"id":"1.230178310","rc":[{"atb":[[2.9,6.23]],"id":68392143}],"con":true,"img":false}]}
{"op":"mcm","clk":"11540648546","pt":1719496874377,"mc":[{"id":"1.230178310","rc":[{"atb":[[2.6,0]],"id":55302014}],"con":true,"img":false}]}
{"op":"mcm","clk":"11540648556","pt":1719496874530,"mc":[{"id":"1.230178310","rc":[{"atb":[[2.74,6.8]],"id":57087188}],"con":true,"img":false}]}
{"op":"mcm","clk":"11540648566","pt":1719496874639,"mc":[{"id":"1.230178310","rc":[{"atb":[[3.05,7.39]],"id":55302014}],"con":true,"img":false}]}
{"op":"mcm","clk":"11540648714","pt":1719496876562,"mc":[{"id":"1.230178310","rc":[{"atl":[[5.8,2]],"id":55302014}],"con":true,"img":false}]}
{"op":"mcm","clk":"11540648750","pt":1719496876971,"mc":[{"id":"1.230178310","rc":[{"atl":[[1000,1.07]],"id":68392143},{"atb":[[6.6,1.28]],"id":57088863}],"con":true,"img":false}]}
{"op":"mcm","clk":"11540648763","pt":1719496877078,"mc":[{"id":"1.230178310","rc":[{"atl":[[5.7,4.66]],"id":55302014}],"con":true,"img":false}]}
{"op":"mcm","clk":"11540648778","pt":1719496877283,"mc":[{"id":"1.230178310","rc":[{"atl":[[1000,0.84]],"id":69142441}],"con":true,"img":false}]}
{"op":"mcm","clk":"11540648783","pt":1719496877288,"mc":[{"id":"1.230178310","rc":[{"atl":[[1000,0.96]],"id":68392143}],"con":true,"img":false}]}
{"op":"mcm","clk":"11540648812","pt":1719496877587,"mc":[{"id":"1.230178310","rc":[{"atl":[[1000,0.27]],"id":69142441},{"atl":[[5.8,0],[5.9,0.08]],"id":55302014},{"atl":[[1000,0.22]],"id":68392143}],"con":true,"img":false}]}
{"op":"mcm","clk":"11540648820","pt":1719496877691,"mc":[{"id":"1.230178310","rc":[{"atl":[[11.5,0.73]],"id":68392143}],"con":true,"img":false}]}
{"op":"mcm","clk":"11540648831","pt":1719496877794,"mc":[{"id":"1.230178310","rc":[{"atl":[[16.5,6.45]],"id":68392143}],"con":true,"img":false}]}
{"op":"mcm","clk":"11540648841","pt":1719496877895,"mc":[{"id":"1.230178310","rc":[{"atl":[[1000,0]],"id":69142441},{"atl":[[27,0]],"id":68392143}],"con":true,"img":false}]}
{"op":"mcm","clk":"11540648853","pt":1719496877999,"mc":[{"id":"1.230178310","rc":[{"atl":[[30,0.27]],"id":69142441}],"con":true,"img":false}]}
{"op":"mcm","clk":"11540648867","pt":1719496878103,"mc":[{"id":"1.230178310","rc":[{"atl":[[5.7,0.21]],"id":55302014},{"atl":[[12,0.93]],"id":68392143}],"con":true,"img":false}]}
{"op":"mcm","clk":"11540649046","pt":1719496880173,"mc":[{"id":"1.230178310","rc":[{"atl":[[5.9,0.92]],"id":55302014}],"con":true,"img":false}]}
{"op":"mcm","clk":"11540649065","pt":1719496880388,"mc":[{"id":"1.230178310","rc":[{"atb":[[3,0]],"id":55302014}],"con":true,"img":false}]}
{"op":"mcm","clk":"11540649071","pt":1719496880484,"mc":[{"id":"1.230178310","rc":[{"atb":[[3.1,7.02]],"id":55302014}],"con":true,"img":false}]}
{"op":"mcm","clk":"11540649119","pt":1719496881307,"mc":[{"id":"1.230178310","rc":[{"atb":[[5.2,3.25]],"id":69142441}],"con":true,"img":false}]}
{"op":"mcm","clk":"11540649231","pt":1719496882704,"mc":[{"id":"1.230178310","rc":[{"atb":[[5.2,0]],"id":69142441}],"con":true,"img":false}]}
{"op":"mcm","clk":"11540649252","pt":1719496882873,"mc":[{"id":"1.230178310","rc":[{"atb":[[5.3,1.43]],"id":69142441}],"con":true,"img":false}]}
{"op":"mcm","clk":"11540649325","pt":1719496883845,"mc":[{"id":"1.230178310","rc":[{"atl":[[5.8,2]],"id":55302014}],"con":true,"img":false}]}
{"op":"mcm","clk":"11540649333","pt":1719496884002,"mc":[{"id":"1.230178310","rc":[{"atl":[[5.8,4],[6,0]],"id":55302014}],"con":true,"img":false}]}
{"op":"mcm","clk":"11540649343","pt":1719496884209,"mc":[{"id":"1.230178310","rc":[{"atl":[[5.7,0]],"id":55302014}],"con":true,"img":false}]}
{"op":"mcm","clk":"11540649375","pt":1719496884476,"mc":[{"id":"1.230178310","rc":[{"atl":[[5.7,4.45],[1000,0.21]],"id":55302014}],"con":true,"img":false}]}
{"op":"mcm","clk":"11540649383","pt":1719496884579,"mc":[{"id":"1.230178310","rc":[{"atl":[[5.6,4]],"id":55302014}],"con":true,"img":false}]}
{"op":"mcm","clk":"11540649393","pt":1719496884675,"mc":[{"id":"1.230178310","rc":[{"atl":[[5.8,2]],"id":55302014}],"con":true,"img":false}]}
{"op":"mcm","clk":"11540649401","pt":1719496884798,"mc":[{"id":"1.230178310","rc":[{"atl":[[1000,0]],"id":55302014}],"con":true,"img":false}]}
{"op":"mcm","clk":"11540649408","pt":1719496884882,"mc":[{"id":"1.230178310","rc":[{"atl":[[5.7,4.66]],"id":55302014}],"con":true,"img":false}]}
{"op":"mcm","clk":"11540649423","pt":1719496885190,"mc":[{"id":"1.230178310","rc":[{"atb":[[5.3,0]],"id":69142441},{"atl":[[5.7,0.21],[5.9,0.08]],"id":55302014}],"con":true,"img":false}]}
{"op":"mcm","clk":"11540649428","pt":1719496885292,"mc":[{"id":"1.230178310","rc":[{"atl":[[5.6,0],[5.7,8.21]],"id":55302014}],"con":true,"img":false}]}
{"op":"mcm","clk":"11540649445","pt":1719496885606,"mc":[{"id":"1.230178310","rc":[{"atl":[[5.8,0]],"id":55302014}],"con":true,"img":false}]}
{"op":"mcm","clk":"11540649552","pt":1719496887203,"mc":[{"id":"1.230178310","rc":[{"atl":[[5.6,0.84]],"id":55302014}],"con":true,"img":false}]}
{"op":"mcm","clk":"11540649566","pt":1719496887307,"mc":[{"id":"1.230178310","rc":[{"atl":[[5.6,5.38]],"id":55302014}],"con":true,"img":false}]}
{"op":"mcm","clk":"11540649623","pt":1719496887989,"mc":[{"id":"1.230178310","rc":[{"atl":[[12,0.84]],"id":68392143}],"con":true,"img":false}]}
{"op":"mcm","clk":"11540649640","pt":1719496888290,"mc":[{"id":"1.230178310","rc":[{"atl":[[1000,0.32]],"id":68392143}],"con":true,"img":false}]}
{"op":"mcm","clk":"11540649651","pt":1719496888495,"mc":[{"id":"1.230178310","rc":[{"atl":[[1000,0.22]],"id":68392143}],"con":true,"img":false}]}
{"op":"mcm","clk":"11540649660","pt":1719496888597,"mc":[{"id":"1.230178310","rc":[{"atl":[[11.5,0.83]],"id":68392143}],"con":true,"img":false}]}
{"op":"mcm","clk":"11540649799","pt":1719496890785,"mc":[{"id":"1.230178310","rc":[{"atl":[[5.5,2]],"id":55302014}],"con":true,"img":false}]}
{"op":"mcm","clk":"11540649840","pt":1719496891295,"mc":[{"id":"1.230178310","rc":[{"atl":[[5.6,0.84]],"id":55302014}],"con":true,"img":false}]}
{"op":"mcm","clk":"11540649886","pt":1719496891881,"mc":[{"id":"1.230178310","rc":[{"atb":[[2.42,8.33]],"id":55302014}],"con":true,"img":false}]}
{"op":"mcm","clk":"11540649897","pt":1719496892083,"mc":[{"id":"1.230178310","rc":[{"atb":[[3.05,4.23]],"id":55302014}],"con":true,"img":false}]}
{"op":"mcm","clk":"11540649979","pt":1719496893378,"mc":[{"id":"1.230178310","rc":[{"atl":[[5.5,4],[5.7,0.21]],"id":55302014}],"con":true,"img":false}]}
{"op":"mcm","clk":"11540649994","pt":1719496893588,"mc":[{"id":"1.230178310","rc":[{"atl":[[5.5,2],[5.7,3.06]],"id":55302014}],"con":true,"img":false}]}
{"op":"mcm","clk":"11540650061","pt":1719496894611,"mc":[{"id":"1.230178310","rc":[{"atl":[[5.4,0.84]],"id":55302014}],"con":true,"img":false}]}
{"op":"mcm","clk":"11540650167","pt":1719496896112,"mc":[{"id":"1.230178310","rc":[{"atl":[[5.5,0]],"id":55302014}],"con":true,"img":false}]}
{"op":"mcm","clk":"11540650208","pt":1719496896687,"mc":[{"id":"1.230178310","rc":[{"atl":[[5.5,4.61],[5.4,0]],"id":55302014}],"con":true,"img":false}]}
{"op":"mcm","clk":"11540650285","pt":1719496897812,"mc":[{"id":"1.230178310","rc":[{"atl":[[5.4,2]],"id":55302014}],"con":true,"img":false}]}
{"op":"mcm","clk":"11540650307","pt":1719496898119,"mc":[{"id":"1.230178310","rc":[{"atl":[[5.6,0],[5.5,0]],"id":55302014}],"con":true,"img":false}]}
{"op":"mcm","clk":"11540650347","pt":1719496898594,"mc":[{"id":"1.230178310","rc":[{"atb":[[5.2,1.44]],"id":69142441}],"con":true,"img":false}]}
{"op":"mcm","clk":"11540650420","pt":1719496899989,"mc":[{"id":"1.230178310","rc":[{"atb":[[5.2,0]],"id":69142441}],"con":true,"img":false}]}
{"op":"mcm","clk":"11540650427","pt":1719496900190,"mc":[{"id":"1.230178310","rc":[{"atb":[[5.3,2.69]],"id":69142441},{"atl":[[5.7,2.85]],"id":55302014}],"con":true,"img":false}]}
{"op":"mcm","clk":"11540650448","pt":1719496900499,"mc":[{"id":"1.230178310","rc":[{"atl":[[1000,0.23]],"id":55302014}],"con":true,"img":false}]}
{"op":"mcm","clk":"11540650465","pt":1719496900705,"mc":[{"id":"1.230178310","rc":[{"atl":[[1000,0]],"id":55302014}],"con":true,"img":false}]}
{"op":"mcm","clk":"11540650469","pt":1719496900809,"mc":[{"id":"1.230178310","rc":[{"atb":[[5.3,0]],"id":69142441},{"atl":[[5.3,0.23]],"id":55302014}],"con":true,"img":false}]}
{"op":"mcm","clk":"11540650488","pt":1719496901014,"mc":[{"id":"1.230178310","rc":[{"atb":[[5.4,1.42]],"id":69142441}],"con":true,"img":false}]}
{"op":"mcm","clk":"11540650530","pt":1719496901594,"mc":[{"id":"1.230178310","rc":[{"atl":[[5.3,1.07],[5.4,4]],"id":55302014}],"con":true,"img":false}]}
{"op":"mcm","clk":"11540650540","pt":1719496901696,"mc":[{"id":"1.230178310","rc":[{"atl":[[5.7,0]],"id":55302014}],"con":true,"img":false}]}
{"op":"mcm","clk":"11540650636","pt":1719496903107,"mc":[{"id":"1.230178310","rc":[{"atl":[[5.4,2]],"id":55302014}],"con":true,"img":false}]}
{"op":"mcm","clk":"11540650659","pt":1719496903414,"mc":[{"id":"1.230178310","rc":[{"atb":[[5.4,0]],"id":69142441}],"con":true,"img":false}]}
{"op":"mcm","clk":"11540650683","pt":1719496903806,"mc":[{"id":"1.230178310","rc":[{"atb":[[5.2,2.7]],"id":69142441}],"con":true,"img":false}]}
{"op":"mcm","clk":"11540650692","pt":1719496903907,"mc":[{"id":"1.230178310","rc":[{"atl":[[11.5,0.73]],"id":68392143}],"con":true,"img":false}]}
{"op":"mcm","clk":"11540650734","pt":1719496904423,"mc":[{"id":"1.230178310","rc":[{"atl":[[1000,0.32]],"id":68392143}],"con":true,"img":false}]}
{"op":"mcm","clk":"11540650748","pt":1719496904630,"mc":[{"id":"1.230178310","rc":[{"atl":[[1000,0.22]],"id":68392143}],"con":true,"img":false}]}
{"op":"mcm","clk":"11540650757","pt":1719496904693,"mc":[{"id":"1.230178310","rc":[{"atl":[[11.5,0.83]],"id":68392143}],"con":true,"img":false}]}
{"op":"mcm","clk":"11540650764","pt":1719496904793,"mc":[{"id":"1.230178310","rc":[{"atl":[[5.2,2]],"id":55302014}],"con":true,"img":false}]}
{"op":"mcm","clk":"11540650776","pt":1719496904999,"mc":[{"id":"1.230178310","rc":[{"atl":[[5.2,4],[5.4,0]],"id":55302014}],"con":true,"img":false}]}
{"op":"mcm","clk":"11540650783","pt":1719496905103,"mc":[{"id":"1.230178310","rc":[{"atl":[[5.1,4.97],[5.3,5.07],[5.2,2]],"id":55302014}],"con":true,"img":false}]}
{"op":"mcm","clk":"11540650794","pt":1719496905303,"mc":[{"id":"1.230178310","rc":[{"atl":[[5.1,9.95],[5.3,1.07]],"id":55302014}],"con":true,"img":false}]}
{"op":"mcm","clk":"11540650799","pt":1719496905406,"mc":[{"id":"1.230178310","rc":[{"atb":[[5.2,0]],"id":69142441},{"atl":[[5.2,11.96]],"id":55302014}],"con":true,"img":false}]}
{"op":"mcm","clk":"11540650806","pt":1719496905511,"mc":[{"id":"1.230178310","rc":[{"atl":[[5.1,4.97]],"id":55302014}],"con":true,"img":false}]}
{"op":"mcm","clk":"11540650810","pt":1719496905611,"mc":[{"id":"1.230178310","rc":[{"atb":[[5.4,2.67]],"id":69142441},{"atl":[[5.1,14.93],[5.3,0.23],[5.2,1.99]],"id":55302014}],"con":true,"img":false}]}
{"op":"mcm","clk":"11540650829","pt":1719496905818,"mc":[{"id":"1.230178310","rc":[{"atl":[[5.2,0]],"id":55302014}],"con":true,"img":false}]}
{"op":"mcm","clk":"11540650909","pt":1719496906828,"mc":[{"id":"1.230178310","rc":[{"spn":3.68,"spf":1.0,"id":57087188},{"spn":10.22,"spf":"Infinity","id":65436514},{"atb":[[5.4,0]],"id":69142441},{"spn":8.4,"spf":1.0,"id":69142441},{"spn":3.1,"spf":1.0,"id":55302014},{"spn":6.5,"spf":6.5,"id":68392143},{"spn":6.52,"spf":1.0,"id":57088863}],"con":true,"img":false}]}
{"op":"mcm","clk":"11540650936","pt":1719496907206,"mc":[{"id":"1.230178310","rc":[{"atb":[[5.5,2.42]],"id":69142441}],"con":true,"img":false}]}
{"op":"mcm","clk":"11540651083","pt":1719496909115,"mc":[{"id":"1.230178310","rc":[{"atb":[[5.5,0]],"id":69142441},{"atl":[[5,0.84]],"id":55302014}],"con":true,"img":false}]}
{"op":"mcm","clk":"11540651105","pt":1719496909424,"mc":[{"id":"1.230178310","rc":[{"atb":[[5.9,3.09]],"id":69142441}],"con":true,"img":false}]}
{"op":"mcm","clk":"11540651123","pt":1719496909732,"mc":[{"id":"1.230178310","rc":[{"atb":[[3.05,0.84]],"id":55302014}],"con":true,"img":false}]}
{"op":"mcm","clk":"11540651169","pt":1719496910309,"mc":[{"id":"1.230178310","rc":[{"atb":[[2.2,9.87]],"id":65436514}],"con":true,"img":false}]}
{"op":"mcm","clk":"11540651204","pt":1719496910722,"mc":[{"id":"1.230178310","rc":[{"atb":[[5.9,0]],"id":69142441}],"con":true,"img":false}]}
{"op":"mcm","clk":"11540651296","pt":1719496911916,"mc":[{"id":"1.230178310","rc":[{"atl":[[5,2.84]],"id":55302014}],"con":true,"img":false}]}
{"op":"mcm","clk":"11540651349","pt":1719496912637,"mc":[{"id":"1.230178310","rc":[{"atl":[[5.1,9.96]],"id":55302014}],"con":true,"img":false}]}
{"op":"mcm","clk":"11540651360","pt":1719496912739,"mc":[{"id":"1.230178310","rc":[{"atl":[[4.9,5.18]],"id":55302014}],"con":true,"img":false}]}
{"op":"mcm","clk":"11540651444","pt":1719496913721,"mc":[{"id":"1.230178310","rc":[{"atl":[[5,0.84]],"id":55302014}],"con":true,"img":false}]}
{"op":"mcm","clk":"11540651573","pt":1719496915425,"mc":[{"id":"1.230178310","rc":[{"atb":[[5.2,1.44]],"id":69142441}],"con":true,"img":false}]}
{"op":"mcm","clk":"11540651587","pt":1719496915632,"mc":[{"id":"1.230178310","rc":[{"atb":[[5.2,0]],"id":69142441}],"con":true,"img":false}]}
{"op":"mcm","clk":"11540651596","pt":1719496915837,"mc":[{"id":"1.230178310","rc":[{"atb":[[5.3,3.81]],"id":69142441}],"con":true,"img":false}]}
{"op":"mcm","clk":"11540651611","pt":1719496916042,"mc":[{"id":"1.230178310","rc":[{"atl":[[5.3,0]],"id":55302014}],"con":true,"img":false}]}
{"op":"mcm","clk":"11540651649","pt":1719496916522,"mc":[{"id":"1.230178310","rc":[{"atl":[[4.8,0.84],[1000,0.26]],"id":55302014}],"con":true,"img":false}]}
{"op":"mcm","clk":"11540651659","pt":1719496916621,"mc":[{"id":"1.230178310","rc":[{"atl":[[1000,0]],"id":55302014}],"con":true,"img":false}]}
{"op":"mcm","clk":"11540651666","pt":1719496916710,"mc":[{"id":"1.230178310","rc":[{"atl":[[4.8,1.1]],"id":55302014}],"con":true,"img":false}]}
{"op":"mcm","clk":"11540651691","pt":1719496917125,"mc":[{"id":"1.230178310","rc":[{"atl":[[4.9,0]],"id":55302014}],"con":true,"img":false}]}
{"op":"mcm","clk":"11540651730","pt":1719496917639,"mc":[{"id":"1.230178310","rc":[{"atl":[[4.8,0.26]],"id":55302014}],"con":true,"img":false}]}
{"op":"mcm","clk":"11540651738","pt":1719496917742,"mc":[{"id":"1.230178310","rc":[{"atb":[[5.3,0]],"id":69142441}],"con":true,"img":false}]}
{"op":"mcm","clk":"11540651762","pt":1719496918009,"mc":[{"id":"1.230178310","rc":[{"atb":[[5.5,2.39]],"id":69142441}],"con":true,"img":false}]}
{"op":"mcm","clk":"11540651881","pt":1719496919615,"mc":[{"id":"1.230178310","rc":[{"atb":[[5.5,0]],"id":69142441}],"con":true,"img":false}]}
{"op":"mcm","clk":"11540651886","pt":1719496919723,"mc":[{"id":"1.230178310","rc":[{"atl":[[4.9,2]],"id":55302014}],"con":true,"img":false}]}
{"op":"mcm","clk":"11540651893","pt":1719496919819,"mc":[{"id":"1.230178310","rc":[{"atb":[[5.5,1.43]],"id":69142441},{"atl":[[11.5,0.73]],"id":68392143}],"con":true,"img":false}]}
{"op":"mcm","clk":"11540651938","pt":1719496920435,"mc":[{"id":"1.230178310","rc":[{"atb":[[5.5,0]],"id":69142441},{"atl":[[1000,0.32]],"id":68392143}],"con":true,"img":false}]}
{"op":"mcm","clk":"11540651948","pt":1719496920642,"mc":[{"id":"1.230178310","rc":[{"atl":[[1000,0.22]],"id":68392143}],"con":true,"img":false}]}
{"op":"mcm","clk":"11540651956","pt":1719496920746,"mc":[{"id":"1.230178310","rc":[{"atl":[[11.5,0.83]],"id":68392143}],"con":true,"img":false}]}
{"op":"mcm","clk":"11540651962","pt":1719496920850,"mc":[{"id":"1.230178310","rc":[{"atb":[[5.7,2.66]],"id":69142441}],"con":true,"img":false}]}
{"op":"mcm","clk":"11540652131","pt":1719496923027,"mc":[{"id":"1.230178310","rc":[{"atb":[[5.7,0]],"id":69142441}],"con":true,"img":false}]}
{"op":"mcm","clk":"11540652145","pt":1719496923226,"mc":[{"id":"1.230178310","rc":[{"atb":[[5.5,3.32]],"id":69142441}],"con":true,"img":false}]}
{"op":"mcm","clk":"11540652166","pt":1719496923534,"mc":[{"id":"1.230178310","rc":[{"atb":[[5.5,0]],"id":69142441},{"atl":[[4.8,1.1]],"id":55302014}],"con":true,"img":false}]}
{"op":"mcm","clk":"11540652198","pt":1719496924050,"mc":[{"id":"1.230178310","rc":[{"atb":[[3.7,0]],"id":57087188},{"atb":[[3.8,0]],"id":65436514},{"atb":[[10,0]],"id":69142441},{"atb":[[4.4,0]],"id":68392143},{"atb":[[6.4,0]],"id":57088863}],"con":true,"img":false}]}
{"op":"mcm","clk":"11540652207","pt":1719496924153,"mc":[{"id":"1.230178310","rc":[{"atb":[[4,1]],"id":57087188},{"atb":[[4.2,1]],"id":65436514},{"atb":[[12,1],[5.1,7],[6,0]],"id":69142441},{"atb":[[5,1],[4.1,0]],"id":68392143},{"atb":[[7,1]],"id":57088863}],"con":true,"img":false}]}
{"op":"mcm","clk":"11540652217","pt":1719496924226,"mc":[{"id":"1.230178310","rc":[{"atb":[[2.92,7.04]],"id":68392143}],"con":true,"img":false}]}
{"op":"mcm","clk":"11540652226","pt":1719496924321,"mc":[{"id":"1.230178310","rc":[{"atb":[[5.1,1.28],[6.6,0]],"id":57088863}],"con":true,"img":false}]}
{"op":"mcm","clk":"11540652253","pt":1719496924630,"mc":[{"id":"1.230178310","rc":[{"atb":[[7.2,1.17]],"id":57088863}],"con":true,"img":false}]}
{"op":"mcm","clk":"11540652263","pt":1719496924730,"mc":[{"id":"1.230178310","rc":[{"atb":[[5.1,0]],"id":57088863}],"con":true,"img":false}]}
{"op":"mcm","clk":"11540652279","pt":1719496925030,"mc":[{"id":"1.230178310","rc":[{"atl":[[4.9,0]],"id":55302014}],"con":true,"img":false}]}
{"op":"mcm","clk":"11540652334","pt":1719496925646,"mc":[{"id":"1.230178310","rc":[{"atl":[[4.8,0.26]],"id":55302014}],"con":true,"img":false}]}
{"op":"mcm","clk":"11540652418","pt":1719496926733,"mc":[{"id":"1.230178310","rc":[{"atl":[[4.9,2]],"id":55302014}],"con":true,"img":false}]}
{"op":"mcm","clk":"11540652485","pt":1719496927453,"mc":[{"id":"1.230178310","rc":[{"atb":[[5.3,5.17]],"id":69142441}],"con":true,"img":false}]}
{"op":"mcm","clk":"11540652554","pt":1719496928537,"mc":[{"id":"1.230178310","rc":[{"atb":[[1.03,1.7]],"id":57087188},{"atl":[[1000,1.7]],"id":57087188},{"atl":[[1000,1.7]],"id":55302014},{"atb":[[1.08,1.7],[1.05,1.7]],"id":57088863},{"atl":[[1000,1.7]],"id":57088863}],"con":true,"img":false}]}
{"op":"mcm","clk":"11540652570","pt":1719496928747,"mc":[{"id":"1.230178310","rc":[{"atb":[[1.03,0.09]],"id":57087188},{"atl":[[1000,0.01]],"id":57087188},{"atb":[[1.08,0.02],[1.05,0.04]],"id":57088863},{"atl":[[1000,0]],"id":57088863}],"con":true,"img":false}]}
{"op":"mcm","clk":"11540652584","pt":1719496928952,"mc":[{"id":"1.230178310","rc":[{"atb":[[1.03,0]],"id":57087188},{"atl":[[1000,0]],"id":57087188},{"atl":[[1000,0.04]],"id":55302014},{"atb":[[1.08,0],[1.05,0]],"id":57088863}],"con":true,"img":false}]}
{"op":"mcm","clk":"11540652588","pt":1719496929056,"mc":[{"id":"1.230178310","rc":[{"atb":[[4.1,0.09]],"id":57087188},{"atl":[[25,0.01]],"id":57087188},{"atb":[[7.2,1.25]],"id":57088863}],"con":true,"img":false}]}
{"op":"mcm","clk":"11540652602","pt":1719496929223,"mc":[{"id":"1.230178310","rc":[{"atl":[[1000,0]],"id":55302014}],"con":true,"img":false}]}
{"op":"mcm","clk":"11540652608","pt":1719496929325,"mc":[{"id":"1.230178310","rc":[{"atl":[[4.8,0.3]],"id":55302014}],"con":true,"img":false}]}
{"op":"mcm","clk":"11540652627","pt":1719496929633,"mc":[{"id":"1.230178310","rc":[{"atb":[[5.3,0]],"id":69142441}],"con":true,"img":false}]}
{"op":"mcm","clk":"11540652641","pt":1719496929841,"mc":[{"id":"1.230178310","rc":[{"atb":[[5.5,4.3]],"id":69142441}],"con":true,"img":false}]}
{"op":"mcm","clk":"11540652739","pt":1719496931028,"mc":[{"id":"1.230178310","rc":[{"atl":[[4.8,1.15]],"id":55302014}],"con":true,"img":false}]}
{"op":"mcm","clk":"11540652766","pt":1719496931341,"mc":[{"id":"1.230178310","rc":[{"atl":[[5.1,0],[4.9,4.3]],"id":55302014}],"con":true,"img":false}]}
{"op":"mcm","clk":"11540652811","pt":1719496931848,"mc":[{"id":"1.230178310","rc":[{"atb":[[5.6,4.3],[5.1,0]],"id":69142441}],"con":true,"img":false}]}
{"op":"mcm","clk":"11540652825","pt":1719496932054,"mc":[{"id":"1.230178310","rc":[{"atl":[[4.8,0.89],[4.9,2.3]],"id":55302014}],"con":true,"img":false}]}
{"op":"mcm","clk":"11540652845","pt":1719496932261,"mc":[{"id":"1.230178310","rc":[{"atl":[[5,4.03],[4.9,0],[1000,0.26]],"id":55302014}],"con":true,"img":false}]}
{"op":"mcm","clk":"11540652870","pt":1719496932534,"mc":[{"id":"1.230178310","rc":[{"atl":[[1000,0]],"id":55302014}],"con":true,"img":false}]}
{"op":"mcm","clk":"11540652875","pt":1719496932630,"mc":[{"id":"1.230178310","rc":[{"atl":[[4.8,0.3]],"id":55302014}],"con":true,"img":false}]}
{"op":"mcm","clk":"11540652889","pt":1719496932859,"mc":[{"id":"1.230178310","rc":[{"atb":[[2.4,0]],"id":55302014},{"atb":[[2.88,0]],"id":68392143},{"atb":[[2.34,0]],"id":57088863}],"con":true,"img":false}]}
{"op":"mcm","clk":"11540652968","pt":1719496933863,"mc":[{"id":"1.230178310","rc":[{"atl":[[4.9,2]],"id":55302014}],"con":true,"img":false}]}
{"op":"mcm","clk":"11540652977","pt":1719496933929,"mc":[{"id":"1.230178310","rc":[{"atl":[[4.8,5.59]],"id":55302014}],"con":true,"img":false}]}
{"op":"mcm","clk":"11540652998","pt":1719496934142,"mc":[{"id":"1.230178310","rc":[{"atb":[[5.5,0]],"id":69142441}],"con":true,"img":false}]}
{"op":"mcm","clk":"11540653024","pt":1719496934442,"mc":[{"id":"1.230178310","rc":[{"atb":[[5.5,1.43]],"id":69142441}],"con":true,"img":false}]}
{"op":"mcm","clk":"11540653041","pt":1719496934648,"mc":[{"id":"1.230178310","rc":[{"atl":[[5,3.19]],"id":55302014}],"con":true,"img":false}]}
{"op":"mcm","clk":"11540653052","pt":1719496934846,"mc":[{"id":"1.230178310","rc":[{"atl":[[4.9,0]],"id":55302014}],"con":true,"img":false}]}
{"op":"mcm","clk":"11540653120","pt":1719496935933,"mc":[{"id":"1.230178310","rc":[{"atl":[[11.5,0.73]],"id":68392143}],"con":true,"img":false}]}
{"op":"mcm","clk":"11540653128","pt":1719496936037,"mc":[{"id":"1.230178310","rc":[{"atb":[[5.5,0]],"id":69142441}],"con":true,"img":false}]}
{"op":"mcm","clk":"11540653136","pt":1719496936135,"mc":[{"id":"1.230178310","rc":[{"atl":[[1000,0.32]],"id":68392143}],"con":true,"img":false}]}
{"op":"mcm","clk":"11540653143","pt":1719496936243,"mc":[{"id":"1.230178310","rc":[{"atb":[[5.7,4.31]],"id":69142441}],"con":true,"img":false}]}
{"op":"mcm","clk":"11540653149","pt":1719496936344,"mc":[{"id":"1.230178310","rc":[{"atl":[[1000,0.22]],"id":68392143}],"con":true,"img":false}]}
{"op":"mcm","clk":"11540653159","pt":1719496936450,"mc":[{"id":"1.230178310","rc":[{"atl":[[11.5,0.83]],"id":68392143}],"con":true,"img":false}]}
{"op":"mcm","clk":"11540653290","pt":1719496938553,"mc":[{"id":"1.230178310","rc":[{"atb":[[5.7,0]],"id":69142441},{"atl":[[4.7,0.84]],"id":55302014}],"con":true,"img":false}]}
{"op":"mcm","clk":"11540653351","pt":1719496939437,"mc":[{"id":"1.230178310","rc":[{"atb":[[5.2,5.2]],"id":69142441}],"con":true,"img":false}]}
{"op":"mcm","clk":"11540653369","pt":1719496939843,"mc":[{"id":"1.230178310","rc":[{"atl":[[5,0],[4.9,6.45]],"id":55302014}],"con":true,"img":false}]}
{"op":"mcm","clk":"11540653421","pt":1719496940871,"mc":[{"id":"1.230178310","rc":[{"atl":[[4.7,2.84]],"id":55302014}],"con":true,"img":false}]}
{"op":"mcm","clk":"11540653449","pt":1719496941338,"mc":[{"id":"1.230178310","rc":[{"atl":[[4.8,0.3]],"id":55302014}],"con":true,"img":false}]}
{"op":"mcm","clk":"11540653469","pt":1719496941647,"mc":[{"id":"1.230178310","rc":[{"atb":[[5.2,0]],"id":69142441}],"con":true,"img":false}]}
{"op":"mcm","clk":"11540653494","pt":1719496942056,"mc":[{"id":"1.230178310","rc":[{"atb":[[5.4,4.33]],"id":69142441}],"con":true,"img":false}]}
{"op":"mcm","clk":"11540653629","pt":1719496944271,"mc":[{"id":"1.230178310","rc":[{"atb":[[5.4,0]],"id":69142441}],"con":true,"img":false}]}
{"op":"mcm","clk":"11540653644","pt":1719496944476,"mc":[{"id":"1.230178310","rc":[{"atb":[[5.5,3.23]],"id":69142441}],"con":true,"img":false}]}
{"op":"mcm","clk":"11540653752","pt":1719496945869,"mc":[{"id":"1.230178310","rc":[{"atb":[[5.5,0]],"id":69142441}],"con":true,"img":false}]}
{"op":"mcm","clk":"11540653762","pt":1719496945972,"mc":[{"id":"1.230178310","rc":[{"atb":[[2.94,3.15]],"id":68392143}],"con":true,"img":false}]}
{"op":"mcm","clk":"11540653769","pt":1719496946075,"mc":[{"id":"1.230178310","rc":[{"atl":[[4.7,0.84]],"id":55302014}],"con":true,"img":false}]}
{"op":"mcm","clk":"11540653784","pt":1719496946245,"mc":[{"id":"1.230178310","rc":[{"atb":[[2.76,7.93]],"id":57087188},{"atb":[[5.9,4.21]],"id":69142441},{"atb":[[2.44,9.7]],"id":55302014}],"con":true,"img":false}]}
{"op":"mcm","clk":"11540653823","pt":1719496946857,"mc":[{"id":"1.230178310","rc":[{"atl":[[4.7,0]],"id":55302014}],"con":true,"img":false}]}
{"op":"mcm","clk":"11540653838","pt":1719496947059,"mc":[{"id":"1.230178310","rc":[{"atl":[[4.9,0],[5.9,6.84]],"id":55302014}],"con":true,"img":false}]}
{"op":"mcm","clk":"11540653845","pt":1719496947164,"mc":[{"id":"1.230178310","rc":[{"atl":[[6.6,9]],"id":55302014}],"con":true,"img":false}]}
{"op":"mcm","clk":"11540653853","pt":1719496947266,"mc":[{"id":"1.230178310","rc":[{"atb":[[5.9,0]],"id":69142441},{"atl":[[5.9,0.08]],"id":55302014}],"con":true,"img":false}]}
{"op":"mcm","clk":"11540653876","pt":1719496947573,"mc":[{"id":"1.230178310","rc":[{"atl":[[6.4,0.84]],"id":55302014}],"con":true,"img":false}]}
{"op":"mcm","clk":"11540653883","pt":1719496947674,"mc":[{"id":"1.230178310","rc":[{"atb":[[5.2,5.2]],"id":69142441},{"atl":[[6.4,4.81]],"id":55302014}],"con":true,"img":false}]}
{"op":"mcm","clk":"11540653898","pt":1719496947841,"mc":[{"id":"1.230178310","rc":[{"atl":[[4.8,0.04],[6.2,2]],"id":55302014}],"con":true,"img":false}]}
{"op":"mcm","clk":"11540653911","pt":1719496948050,"mc":[{"id":"1.230178310","rc":[{"atl":[[6,4.82],[6.6,1]],"id":55302014}],"con":true,"img":false}]}
{"op":"mcm","clk":"11540653921","pt":1719496948253,"mc":[{"id":"1.230178310","rc":[{"atl":[[6.4,0.84],[1000,0.2]],"id":55302014}],"con":true,"img":false}]}
{"op":"mcm","clk":"11540653939","pt":1719496948559,"mc":[{"id":"1.230178310","rc":[{"atl":[[5.9,4.38],[1000,0]],"id":55302014}],"con":true,"img":false}]}
{"op":"mcm","clk":"11540653948","pt":1719496948661,"mc":[{"id":"1.230178310","rc":[{"atl":[[6.4,0],[5.9,4.58]],"id":55302014}],"con":true,"img":false}]}
{"op":"mcm","clk":"11540653962","pt":1719496948866,"mc":[{"id":"1.230178310","rc":[{"atl":[[6.2,0]],"id":55302014}],"con":true,"img":false}]}
{"op":"mcm","clk":"11540654018","pt":1719496949874,"mc":[{"id":"1.230178310","rc":[{"atb":[[5.2,0]],"id":69142441}],"con":true,"img":false}]}
{"op":"mcm","clk":"11540654050","pt":1719496950265,"mc":[{"id":"1.230178310","rc":[{"atb":[[5.3,1.43]],"id":69142441}],"con":true,"img":false}]}
{"op":"mcm","clk":"11540654075","pt":1719496950567,"mc":[{"id":"1.230178310","rc":[{"atb":[[5.3,0]],"id":69142441}],"con":true,"img":false}]}
{"op":"mcm","clk":"11540654091","pt":1719496950879,"mc":[{"id":"1.230178310","rc":[{"atb":[[5.4,4.33]],"id":69142441}],"con":true,"img":false}]}
{"op":"mcm","clk":"11540654104","pt":1719496951049,"mc":[{"id":"1.230178310","rc":[{"atb":[[3.1,13.86]],"id":55302014}],"con":true,"img":false}]}
{"op":"mcm","clk":"11540654145","pt":1719496951676,"mc":[{"id":"1.230178310","rc":[{"atl":[[11.5,0.73]],"id":68392143}],"con":true,"img":false}]}
{"op":"mcm","clk":"11540654192","pt":1719496952452,"mc":[{"id":"1.230178310","rc":[{"atl":[[1000,0.32]],"id":68392143}],"con":true,"img":false}]}
{"op":"mcm","clk":"11540654208","pt":1719496952654,"mc":[{"id":"1.230178310","rc":[{"atl":[[1000,0.22]],"id":68392143}],"con":true,"img":false}]}
{"op":"mcm","clk":"11540654214","pt":1719496952753,"mc":[{"id":"1.230178310","rc":[{"atl":[[11.5,0.83]],"id":68392143}],"con":true,"img":false}]}
{"op":"mcm","clk":"11540654217","pt":1719496952858,"mc":[{"id":"1.230178310","rc":[{"atb":[[5.4,0]],"id":69142441}],"con":true,"img":false}]}
{"op":"mcm","clk":"11540654237","pt":1719496953167,"mc":[{"id":"1.230178310","rc":[{"atb":[[2.9,0]],"id":68392143}],"con":true,"img":false}]}
{"op":"mcm","clk":"11540654247","pt":1719496953269,"mc":[{"id":"1.230178310","rc":[{"atb":[[5.5,4.36]],"id":69142441}],"con":true,"img":false}]}
{"op":"mcm","clk":"11540654336","pt":1719496954710,"mc":[{"id":"1.230178310","rc":[{"atl":[[5.8,0.84]],"id":55302014}],"con":true,"img":false}]}
{"op":"mcm","clk":"11540654363","pt":1719496954997,"mc":[{"id":"1.230178310","rc":[{"atl":[[5.8,2.84],[5.9,0.28]],"id":55302014}],"con":true,"img":false}]}
{"op":"mcm","clk":"11540654379","pt":1719496955191,"mc":[{"id":"1.230178310","rc":[{"atb":[[5.5,0]],"id":69142441}],"con":true,"img":false}]}
{"op":"mcm","clk":"11540654403","pt":1719496955464,"mc":[{"id":"1.230178310","rc":[{"atb":[[5.9,4.26]],"id":69142441}],"con":true,"img":false}]}
{"op":"mcm","clk":"11540654412","pt":1719496955567,"mc":[{"id":"1.230178310","rc":[{"atl":[[5.8,5.69],[6,0]],"id":55302014}],"con":true,"img":false}]}
{"op":"mcm","clk":"11540654730","pt":1719496960277,"mc":[{"id":"1.230178310","rc":[{"atl":[[5.8,3.69]],"id":55302014}],"con":true,"img":false}]}
{"op":"mcm","clk":"11540654749","pt":1719496960580,"mc":[{"id":"1.230178310","rc":[{"atb":[[5.9,0]],"id":69142441}],"con":true,"img":false}]}
{"op":"mcm","clk":"11540654778","pt":1719496961082,"mc":[{"id":"1.230178310","rc":[{"atb":[[5.2,5.2]],"id":69142441}],"con":true,"img":false}]}
{"op":"mcm","clk":"11540654846","pt":1719496962073,"mc":[{"id":"1.230178310","rc":[{"atl":[[5.7,2]],"id":55302014}],"con":true,"img":false}]}
{"op":"mcm","clk":"11540654872","pt":1719496962487,"mc":[{"id":"1.230178310","rc":[{"atl":[[5.6,4.53]],"id":55302014}],"con":true,"img":false}]}
{"op":"mcm","clk":"11540654883","pt":1719496962584,"mc":[{"id":"1.230178310","rc":[{"atl":[[5.6,5.38]],"id":55302014}],"con":true,"img":false}]}
{"op":"mcm","clk":"11540654911","pt":1719496962990,"mc":[{"id":"1.230178310","rc":[{"atl":[[5.8,0.84],[5.5,3.7]],"id":55302014},{"atb":[[2.94,9.26]],"id":68392143}],"con":true,"img":false}]}
{"op":"mcm","clk":"11540654916","pt":1719496963093,"mc":[{"id":"1.230178310","rc":[{"atl":[[5.7,0]],"id":55302014}],"con":true,"img":false}]}
{"op":"mcm","clk":"11540654923","pt":1719496963153,"mc":[{"id":"1.230178310","rc":[{"atl":[[5.8,0]],"id":55302014}],"con":true,"img":false}]}
{"op":"mcm","clk":"11540654954","pt":1719496963575,"mc":[{"id":"1.230178310","rc":[{"atl":[[5.6,0.84]],"id":55302014}],"con":true,"img":false}]}
{"op":"mcm","clk":"11540654964","pt":1719496963775,"mc":[{"id":"1.230178310","rc":[{"atb":[[5.2,0]],"id":69142441}],"con":true,"img":false}]}
{"op":"mcm","clk":"11540654976","pt":1719496963979,"mc":[{"id":"1.230178310","rc":[{"atl":[[5.9,0.08]],"id":55302014}],"con":true,"img":false}]}
{"op":"mcm","clk":"11540654980","pt":1719496964086,"mc":[{"id":"1.230178310","rc":[{"atb":[[5.4,4.33]],"id":69142441}],"con":true,"img":false}]}
{"op":"mcm","clk":"11540655002","pt":1719496964385,"mc":[{"id":"1.230178310","rc":[{"atl":[[1000,0.23]],"id":55302014}],"con":true,"img":false}]}
{"op":"mcm","clk":"11540655018","pt":1719496964589,"mc":[{"id":"1.230178310","rc":[{"atl":[[1000,0]],"id":55302014}],"con":true,"img":false}]}
{"op":"mcm","clk":"11540655028","pt":1719496964698,"mc":[{"id":"1.230178310","rc":[{"atl":[[5.4,0.23]],"id":55302014}],"con":true,"img":false}]}
{"op":"mcm","clk":"11540655193","pt":1719496967079,"mc":[{"id":"1.230178310","rc":[{"spn":3.78,"spf":1.0,"id":57087188},{"atb":[[1.01,24.52]],"id":69142441},{"spn":9.4,"spf":1.0,"id":69142441},{"spn":7.12,"spf":1.0,"id":57088863}],"con":true,"img":false}]}
{"op":"mcm","clk":"11540655213","pt":1719496967287,"mc":[{"id":"1.230178310","rc":[{"atb":[[3.75,0],[4.1,0]],"id":57087188},{"atl":[[7.6,1],[25,0]],"id":57087188},{"atb":[[3.1,13.67]],"id":55302014},{"atl":[[4.8,0],[5.9,0]],"id":55302014},{"atb":[[7.2,1.17]],"id":57088863}],"con":true,"img":false}]}
{"op":"mcm","clk":"11540655235","pt":1719496967489,"mc":[{"id":"1.230178310","rc":[{"atb":[[5.4,0]],"id":69142441},{"atl":[[5.6,4.77],[5.5,0]],"id":55302014}],"con":true,"img":false}]}
{"op":"mcm","clk":"11540655244","pt":1719496967592,"mc":[{"id":"1.230178310","rc":[{"atl":[[5.6,0.84],[6.6,9]],"id":55302014}],"con":true,"img":false}]}
{"op":"mcm","clk":"11540655254","pt":1719496967693,"mc":[{"id":"1.230178310","rc":[{"atb":[[1.01,24.35],[5.5,4.36]],"id":69142441}],"con":true,"img":false}]}
{"op":"mcm","clk":"11540655286","pt":1719496967960,"mc":[{"id":"1.230178310","rc":[{"atl":[[11.5,0.73]],"id":68392143}],"con":true,"img":false}]}
{"op":"mcm","clk":"11540655294","pt":1719496968064,"mc":[{"id":"1.230178310","rc":[{"atl":[[5.6,0]],"id":55302014}],"con":true,"img":false}]}
{"op":"mcm","clk":"11540655312","pt":1719496968272,"mc":[{"id":"1.230178310","rc":[{"atl":[[6.6,1],[14.5,7.41]],"id":55302014}],"con":true,"img":false}]}
{"op":"mcm","clk":"11540655321","pt":1719496968371,"mc":[{"id":"1.230178310","rc":[{"atb":[[1.01,23.67]],"id":69142441},{"atl":[[1000,0.32]],"id":68392143}],"con":true,"img":false}]}
{"op":"mcm","clk":"11540655329","pt":1719496968473,"mc":[{"id":"1.230178310","rc":[{"atb":[[12.5,0.67]],"id":69142441},{"atl":[[1000,0.22]],"id":68392143}],"con":true,"img":false}]}
{"op":"mcm","clk":"11540655336","pt":1719496968583,"mc":[{"id":"1.230178310","rc":[{"atb":[[6.4,4.3],[5.6,0]],"id":69142441},{"atl":[[11.5,0.83]],"id":68392143}],"con":true,"img":false}]}
{"op":"mcm","clk":"11540655414","pt":1719496969767,"mc":[{"id":"1.230178310","rc":[{"atl":[[6.4,2]],"id":55302014}],"con":true,"img":false}]}
{"op":"mcm","clk":"11540655428","pt":1719496970015,"mc":[{"id":"1.230178310","rc":[{"atl":[[6.4,4],[14.5,0]],"id":55302014}],"con":true,"img":false}]}
{"op":"mcm","clk":"11540655435","pt":1719496970073,"mc":[{"id":"1.230178310","rc":[{"atl":[[6.2,4.94]],"id":55302014}],"con":true,"img":false}]}
{"op":"mcm","clk":"11540655494","pt":1719496970786,"mc":[{"id":"1.230178310","rc":[{"atb":[[5.5,0]],"id":69142441},{"atl":[[6.4,2]],"id":55302014}],"con":true,"img":false}]}
{"op":"mcm","clk":"11540655531","pt":1719496971361,"mc":[{"id":"1.230178310","rc":[{"atb":[[2.42,0]],"id":55302014}],"con":true,"img":false}]}
{"op":"mcm","clk":"11540656005","pt":1719496976799,"mc":[{"id":"1.230178310","rc":[{"atb":[[3.1,0.67]],"id":55302014},{"trd":[[3.1,30.13]],"ltp":3.1,"tv":30.13,"id":55302014}],"con":true,"img":false}]}
{"op":"mcm","clk":"11540656011","pt":1719496976901,"mc":[{"id":"1.230178310","rc":[{"atl":[[6,2]],"id":55302014}],"con":true,"img":false}]}
{"op":"mcm","clk":"11540656019","pt":1719496977003,"mc":[{"id":"1.230178310","rc":[{"atb":[[2.96,1.71]],"id":68392143}],"con":true,"img":false}]}
{"op":"mcm","clk":"11540656033","pt":1719496977107,"mc":[{"id":"1.230178310","rc":[{"atb":[[3.05,0]],"id":55302014}],"con":true,"img":false}]}
{"op":"mcm","clk":"11540656045","pt":1719496977209,"mc":[{"id":"1.230178310","rc":[{"atb":[[2.6,0.84]],"id":55302014},{"atl":[[6.4,0],[6.2,0.84],[6,4]],"id":55302014},{"atb":[[2.96,2.55]],"id":68392143}],"con":true,"img":false}]}
{"op":"mcm","clk":"11540656061","pt":1719496977373,"mc":[{"id":"1.230178310","rc":[{"atl":[[25,0.78]],"id":57087188},{"atl":[[26,0.78]],"id":65436514}],"con":true,"img":false}]}
{"op":"mcm","clk":"11540656084","pt":1719496977583,"mc":[{"id":"1.230178310","rc":[{"atb":[[2.96,0.84]],"id":55302014},{"atl":[[5.9,0.84],[1000,0.78]],"id":55302014}],"con":true,"img":false}]}
{"op":"mcm","clk":"11540656128","pt":1719496978093,"mc":[{"id":"1.230178310","rc":[{"atl":[[25,0.48]],"id":57087188},{"atl":[[26,0.47]],"id":65436514},{"atb":[[1.02,3.7]],"id":55302014},{"atl":[[1000,2.49]],"id":55302014}],"con":true,"img":false}]}
{"op":"mcm","clk":"11540656144","pt":1719496978300,"mc":[{"id":"1.230178310","rc":[{"atb":[[1.02,2.15]],"id":55302014},{"atl":[[1000,0.84]],"id":55302014}],"con":true,"img":false}]}
{"op":"mcm","clk":"11540656164","pt":1719496978498,"mc":[{"id":"1.230178310","rc":[{"atb":[[1.02,2]],"id":55302014},{"atl":[[1000,0.78]],"id":55302014}],"con":true,"img":false}]}
{"op":"mcm","clk":"11540656174","pt":1719496978600,"mc":[{"id":"1.230178310","rc":[{"atb":[[2.96,0.99]],"id":55302014},{"atl":[[5.9,0.9]],"id":55302014}],"con":true,"img":false}]}
{"op":"mcm","clk":"11540656183","pt":1719496978704,"mc":[{"id":"1.230178310","rc":[{"atl":[[6,5.6]],"id":55302014}],"con":true,"img":false}]}
{"op":"mcm","clk":"11540656200","pt":1719496978976,"mc":[{"id":"1.230178310","rc":[{"atl":[[5.8,1.05]],"id":55302014}],"con":true,"img":false}]}
{"op":"mcm","clk":"11540656208","pt":1719496979072,"mc":[{"id":"1.230178310","rc":[{"atb":[[2.98,0.79]],"id":55302014}],"con":true,"img":false}]}
{"op":"mcm","clk":"11540656240","pt":1719496979584,"mc":[{"id":"1.230178310","rc":[{"atl":[[6.2,0]],"id":55302014}],"con":true,"img":false}]}
{"op":"mcm","clk":"11540656258","pt":1719496979790,"mc":[{"id":"1.230178310","rc":[{"atb":[[2.6,0.27]],"id":55302014},{"atb":[[2.96,1.98]],"id":68392143}],"con":true,"img":false}]}
{"op":"mcm","clk":"11540656266","pt":1719496979894,"mc":[{"id":"1.230178310","rc":[{"atl":[[5.4,0]],"id":55302014}],"con":true,"img":false}]}
{"op":"mcm","clk":"11540656312","pt":1719496980505,"mc":[{"id":"1.230178310","rc":[{"atl":[[1000,0.99]],"id":55302014}],"con":true,"img":false}]}
{"op":"mcm","clk":"11540656342","pt":1719496980775,"mc":[{"id":"1.230178310","rc":[{"atl":[[1000,0.78]],"id":55302014}],"con":true,"img":false}]}
{"op":"mcm","clk":"11540656354","pt":1719496980878,"mc":[{"id":"1.230178310","rc":[{"atl":[[5.7,0.21]],"id":55302014}],"con":true,"img":false}]}
{"op":"mcm","clk":"11540656377","pt":1719496981084,"mc":[{"id":"1.230178310","rc":[{"atl":[[7.4,1]],"id":57087188},{"atb":[[3.15,1]],"id":65436514},{"atl":[[130,1]],"id":69142441},{"atl":[[15,1]],"id":57088863}],"con":true,"img":false}]}
{"op":"mcm","clk":"11540656407","pt":1719496981395,"mc":[{"id":"1.230178310","rc":[{"atl":[[120,0.27]],"id":69142441}],"con":true,"img":false}]}
{"op":"mcm","clk":"11540656415","pt":1719496981494,"mc":[{"id":"1.230178310","rc":[{"atl":[[30,0]],"id":69142441},{"atb":[[2.46,8.11]],"id":55302014}],"con":true,"img":false}]}
{"op":"mcm","clk":"11540656468","pt":1719496982113,"mc":[{"id":"1.230178310","rc":[{"atl":[[6,3.6]],"id":55302014}],"con":true,"img":false}]}
{"op":"mcm","clk":"11540656507","pt":1719496982494,"mc":[{"id":"1.230178310","rc":[{"atb":[[2.22,11.45]],"id":65436514}],"con":true,"img":false}]}
{"op":"mcm","clk":"11540656626","pt":1719496983780,"mc":[{"id":"1.230178310","rc":[{"atl":[[11.5,0.73]],"id":68392143}],"con":true,"img":false}]}
{"op":"mcm","clk":"11540656635","pt":1719496983879,"mc":[{"id":"1.230178310","rc":[{"atl":[[5.7,2.21]],"id":55302014}],"con":true,"img":false}]}
{"op":"mcm","clk":"11540656682","pt":1719496984400,"mc":[{"id":"1.230178310","rc":[{"atl":[[6,1.6],[5.7,4.21]],"id":55302014}],"con":true,"img":false}]}
{"op":"mcm","clk":"11540656689","pt":1719496984499,"mc":[{"id":"1.230178310","rc":[{"atl":[[1000,0.32]],"id":68392143}],"con":true,"img":false}]}
{"op":"mcm","clk":"11540656694","pt":1719496984596,"mc":[{"id":"1.230178310","rc":[{"atl":[[5.9,0.06]],"id":55302014}],"con":true,"img":false}]}
{"op":"mcm","clk":"11540656711","pt":1719496984805,"mc":[{"id":"1.230178310","rc":[{"atl":[[1000,0.22]],"id":68392143}],"con":true,"img":false}]}
{"op":"mcm","clk":"11540656720","pt":1719496984859,"mc":[{"id":"1.230178310","rc":[{"atl":[[11.5,0.83]],"id":68392143}],"con":true,"img":false}]}
{"op":"mcm","clk":"11540656738","pt":1719496985071,"mc":[{"id":"1.230178310","rc":[{"atl":[[5.6,0.84]],"id":55302014}],"con":true,"img":false}]}
{"op":"mcm","clk":"11540657111","pt":1719496988910,"mc":[{"id":"1.230178310","rc":[{"atb":[[1.04,1.7]],"id":57087188},{"atl":[[1000,1.7]],"id":57087188}],"con":true,"img":false}]}
{"op":"mcm","clk":"11540657137","pt":1719496989176,"mc":[{"id":"1.230178310","rc":[{"atb":[[1.04,0.05]],"id":57087188},{"atl":[[1000,0.02]],"id":57087188},{"atl":[[5.7,2.21]],"id":55302014}],"con":true,"img":false}]}
{"op":"mcm","clk":"11540657159","pt":1719496989383,"mc":[{"id":"1.230178310","rc":[{"atb":[[1.04,0]],"id":57087188},{"atl":[[1000,0]],"id":57087188}],"con":true,"img":false}]}
{"op":"mcm","clk":"11540657169","pt":1719496989493,"mc":[{"id":"1.230178310","rc":[{"atb":[[4.1,0.05]],"id":57087188},{"atl":[[7.4,1.02]],"id":57087188},{"atb":[[2.44,21.04],[2.58,6]],"id":55302014}],"con":true,"img":false}]}
{"op":"mcm","clk":"11540657177","pt":1719496989590,"mc":[{"id":"1.230178310","rc":[{"atl":[[9,2.03],[26,0]],"id":57087188}],"con":true,"img":false}]}
{"op":"mcm","clk":"11540657184","pt":1719496989693,"mc":[{"id":"1.230178310","rc":[{"atb":[[2.6,0]],"id":55302014}],"con":true,"img":false}]}
{"op":"mcm","clk":"11540657192","pt":1719496989797,"mc":[{"id":"1.230178310","rc":[{"atb":[[1.13,0.27]],"id":55302014}],"con":true,"img":false}]}
{"op":"mcm","clk":"11540657224","pt":1719496990107,"mc":[{"id":"1.230178310","rc":[{"atl":[[25,0]],"id":57087188}],"con":true,"img":false}]}
{"op":"mcm","clk":"11540657237","pt":1719496990210,"mc":[{"id":"1.230178310","rc":[{"atb":[[2.74,0]],"id":57087188},{"atl":[[1000,0.48]],"id":57087188}],"con":true,"img":false}]}
{"op":"mcm","clk":"11540657275","pt":1719496990593,"mc":[{"id":"1.230178310","rc":[{"atb":[[2.54,2.09]],"id":55302014}],"con":true,"img":false}]}
{"op":"mcm","clk":"11540657297","pt":1719496990784,"mc":[{"id":"1.230178310","rc":[{"atl":[[5.7,3.91]],"id":55302014}],"con":true,"img":false}]}
{"op":"mcm","clk":"11540657309","pt":1719496990893,"mc":[{"id":"1.230178310","rc":[{"atl":[[5.6,2.84]],"id":55302014}],"con":true,"img":false}]}
{"op":"mcm","clk":"11540657379","pt":1719496991612,"mc":[{"id":"1.230178310","rc":[{"atb":[[1.25,20]],"id":57087188},{"atb":[[1.25,20]],"id":65436514},{"atb":[[1.25,20]],"id":69142441},{"atb":[[1.25,20]],"id":55302014},{"atb":[[1.25,20]],"id":68392143},{"atb":[[1.25,20]],"id":57088863}],"con":true,"img":false}]}
{"op":"mcm","clk":"11540657530","pt":1719496993285,"mc":[{"id":"1.230178310","rc":[{"atb":[[4.3,1]],"id":68392143}],"con":true,"img":false}]}
{"op":"mcm","clk":"11540657537","pt":1719496993393,"mc":[{"id":"1.230178310","rc":[{"atb":[[4.3,3],[2.92,0]],"id":68392143}],"con":true,"img":false}]}
{"op":"mcm","clk":"11540657618","pt":1719496994302,"mc":[{"id":"1.230178310","rc":[{"atl":[[5.8,0]],"id":55302014}],"con":true,"img":false}]}
{"op":"mcm","clk":"11540657643","pt":1719496994654,"mc":[{"id":"1.230178310","rc":[{"atb":[[2.98,0]],"id":55302014}],"con":true,"img":false}]}
{"op":"mcm","clk":"11540657670","pt":1719496994875,"mc":[{"id":"1.230178310","rc":[{"atl":[[5.5,1.05]],"id":55302014}],"con":true,"img":false}]}
{"op":"mcm","clk":"11540657683","pt":1719496994979,"mc":[{"id":"1.230178310","rc":[{"atb":[[3,0.78]],"id":55302014},{"atl":[[5.5,3.9]],"id":55302014}],"con":true,"img":false}]}
{"op":"mcm","clk":"11540657694","pt":1719496995084,"mc":[{"id":"1.230178310","rc":[{"atl":[[5.6,5.69],[5.5,1.05],[5.7,1.91]],"id":55302014}],"con":true,"img":false}]}
{"op":"mcm","clk":"11540657795","pt":1719496996177,"mc":[{"id":"1.230178310","rc":[{"atl":[[5.6,3.69],[5.7,1.7]],"id":55302014}],"con":true,"img":false}]}
{"op":"mcm","clk":"11540657815","pt":1719496996390,"mc":[{"id":"1.230178310","rc":[{"atl":[[1000,1.01]],"id":55302014}],"con":true,"img":false}]}
{"op":"mcm","clk":"11540657829","pt":1719496996594,"mc":[{"id":"1.230178310","rc":[{"atl":[[1000,0.78]],"id":55302014}],"con":true,"img":false}]}
{"op":"mcm","clk":"11540657837","pt":1719496996700,"mc":[{"id":"1.230178310","rc":[{"atl":[[5.4,0.23]],"id":55302014}],"con":true,"img":false}]}
{"op":"mcm","clk":"11540657964","pt":1719496997902,"mc":[{"id":"1.230178310","rc":[{"atl":[[5.4,2.23]],"id":55302014}],"con":true,"img":false}]}
{"op":"mcm","clk":"11540657975","pt":1719496998008,"mc":[{"id":"1.230178310","rc":[{"atl":[[5.4,4.46],[5.6,0.84]],"id":55302014}],"con":true,"img":false}]}
{"op":"mcm","clk":"11540657989","pt":1719496998111,"mc":[{"id":"1.230178310","rc":[{"atl":[[5.5,5.51]],"id":55302014}],"con":true,"img":false}]}
{"op":"mcm","clk":"11540657997","pt":1719496998217,"mc":[{"id":"1.230178310","rc":[{"atl":[[5.3,4.79],[5.4,2.23]],"id":55302014}],"con":true,"img":false}]}
{"op":"mcm","clk":"11540658021","pt":1719496998375,"mc":[{"id":"1.230178310","rc":[{"atl":[[5.5,1.05],[5.2,5.57]],"id":55302014}],"con":true,"img":false}]}
{"op":"mcm","clk":"11540658039","pt":1719496998583,"mc":[{"id":"1.230178310","rc":[{"atl":[[5.6,0],[5.2,6.42]],"id":55302014}],"con":true,"img":false}]}
{"op":"mcm","clk":"11540658069","pt":1719496998897,"mc":[{"id":"1.230178310","rc":[{"atl":[[5.3,0],[5.4,0.23]],"id":55302014}],"con":true,"img":false}]}
{"op":"mcm","clk":"11540658089","pt":1719496999113,"mc":[{"id":"1.230178310","rc":[{"atl":[[5.2,6.12]],"id":55302014}],"con":true,"img":false}]}
{"op":"mcm","clk":"11540658137","pt":1719496999688,"mc":[{"id":"1.230178310","rc":[{"atl":[[5.2,5.63]],"id":55302014}],"con":true,"img":false}]}
{"op":"mcm","clk":"11540658150","pt":1719496999794,"mc":[{"id":"1.230178310","rc":[{"atl":[[5.4,2.05],[1000,1.27],[5.1,4.97]],"id":55302014}],"con":true,"img":false}]}
{"op":"mcm","clk":"11540658178","pt":1719497000104,"mc":[{"id":"1.230178310","rc":[{"atl":[[11.5,0.73]],"id":68392143}],"con":true,"img":false}]}
{"op":"mcm","clk":"11540658195","pt":1719497000316,"mc":[{"id":"1.230178310","rc":[{"atl":[[1000,0.78]],"id":55302014}],"con":true,"img":false}]}
{"op":"mcm","clk":"11540658205","pt":1719497000420,"mc":[{"id":"1.230178310","rc":[{"atl":[[5,0.48]],"id":55302014},{"atb":[[2.94,6.1]],"id":68392143}],"con":true,"img":false}]}
{"op":"mcm","clk":"11540658212","pt":1719497000512,"mc":[{"id":"1.230178310","rc":[{"atl":[[1000,0.32]],"id":68392143}],"con":true,"img":false}]}
{"op":"mcm","clk":"11540658219","pt":1719497000617,"mc":[{"id":"1.230178310","rc":[{"atb":[[2.78,6.65]],"id":57087188},{"atb":[[2.16,15.7]],"id":68392143}],"con":true,"img":false}]}
{"op":"mcm","clk":"11540658238","pt":1719497000827,"mc":[{"id":"1.230178310","rc":[{"atb":[[2.46,14.05]],"id":55302014},{"atl":[[1000,0.22]],"id":68392143}],"con":true,"img":false}]}
{"op":"mcm","clk":"11540658249","pt":1719497000880,"mc":[{"id":"1.230178310","rc":[{"atl":[[11.5,0.83]],"id":68392143},{"atb":[[2.16,5.44]],"id":57088863}],"con":true,"img":false}]}
{"op":"mcm","clk":"11540658479","pt":1719497003302,"mc":[{"id":"1.230178310","rc":[{"atb":[[2.44,11.34]],"id":55302014}],"con":true,"img":false}]}
{"op":"mcm","clk":"11540658701","pt":1719497005830,"mc":[{"id":"1.230178310","rc":[{"atl":[[5,2.48]],"id":55302014}],"con":true,"img":false}]}
{"op":"mcm","clk":"11540658743","pt":1719497006167,"mc":[{"id":"1.230178310","rc":[{"atl":[[4.9,0.84],[5.1,0],[5.2,4.79]],"id":55302014}],"con":true,"img":false}]}
{"op":"mcm","clk":"11540658759","pt":1719497006318,"mc":[{"id":"1.230178310","rc":[{"atl":[[4.9,6.02]],"id":55302014}],"con":true,"img":false}]}
{"op":"mcm","clk":"11540659064","pt":1719497010199,"mc":[{"id":"1.230178310","rc":[{"atl":[[5.5,0]],"id":55302014}],"con":true,"img":false}]}
{"op":"mcm","clk":"11540659073","pt":1719497010301,"mc":[{"id":"1.230178310","rc":[{"atl":[[5.1,1.95]],"id":55302014}],"con":true,"img":false}]}
{"op":"mcm","clk":"11540659081","pt":1719497010405,"mc":[{"id":"1.230178310","rc":[{"atl":[[5.6,1],[6.6,0]],"id":55302014},{"atb":[[4.3,2],[4,1]],"id":68392143}],"con":true,"img":false}]}
{"op":"mcm","clk":"11540659087","pt":1719497010509,"mc":[{"id":"1.230178310","rc":[{"atl":[[5,2]],"id":55302014}],"con":true,"img":false}]}
{"op":"mcm","clk":"11540659096","pt":1719497010614,"mc":[{"id":"1.230178310","rc":[{"atb":[[3,0]],"id":55302014},{"atl":[[4.8,0.48]],"id":55302014}],"con":true,"img":false}]}
{"op":"mcm","clk":"11540659111","pt":1719497010825,"mc":[{"id":"1.230178310","rc":[{"atl":[[5,0]],"id":55302014}],"con":true,"img":false}]}
{"op":"mcm","clk":"11540659137","pt":1719497011140,"mc":[{"id":"1.230178310","rc":[{"atl":[[4.8,0]],"id":55302014}],"con":true,"img":false}]}
{"op":"mcm","clk":"11540659145","pt":1719497011190,"mc":[{"id":"1.230178310","rc":[{"atl":[[1000,1.27]],"id":55302014}],"con":true,"img":false}]}
{"op":"mcm","clk":"11540659157","pt":1719497011303,"mc":[{"id":"1.230178310","rc":[{"atl":[[4.8,1.05]],"id":55302014}],"con":true,"img":false}]}
{"op":"mcm","clk":"11540659168","pt":1719497011399,"mc":[{"id":"1.230178310","rc":[{"atb":[[3.05,0.76]],"id":55302014}],"con":true,"img":false}]}
{"op":"mcm","clk":"11540659212","pt":1719497012019,"mc":[{"id":"1.230178310","rc":[{"atl":[[5.4,1.82]],"id":55302014}],"con":true,"img":false}]}
{"op":"mcm","clk":"11540659220","pt":1719497012123,"mc":[{"id":"1.230178310","rc":[{"atl":[[4.9,0.84]],"id":55302014}],"con":true,"img":false}]}
{"op":"mcm","clk":"11540659234","pt":1719497012390,"mc":[{"id":"1.230178310","rc":[{"atl":[[1000,1.53]],"id":55302014}],"con":true,"img":false}]}
{"op":"mcm","clk":"11540659251","pt":1719497012694,"mc":[{"id":"1.230178310","rc":[{"atl":[[4.9,0]],"id":55302014}],"con":true,"img":false}]}
{"op":"mcm","clk":"11540659261","pt":1719497012803,"mc":[{"id":"1.230178310","rc":[{"atl":[[1000,1.27]],"id":55302014}],"con":true,"img":false}]}
{"op":"mcm","clk":"11540659266","pt":1719497012901,"mc":[{"id":"1.230178310","rc":[{"atl":[[4.8,1.31]],"id":55302014}],"con":true,"img":false}]}
{"op":"mcm","clk":"11540659323","pt":1719497013891,"mc":[{"id":"1.230178310","rc":[{"atl":[[4.7,2]],"id":55302014}],"con":true,"img":false}]}
{"op":"mcm","clk":"11540659376","pt":1719497014612,"mc":[{"id":"1.230178310","rc":[{"atl":[[4.6,0.84]],"id":55302014}],"con":true,"img":false}]}
{"op":"mcm","clk":"11540659403","pt":1719497015027,"mc":[{"id":"1.230178310","rc":[{"atb":[[4.3,3],[4,0]],"id":68392143}],"con":true,"img":false}]}
{"op":"mcm","clk":"11540659479","pt":1719497016011,"mc":[{"id":"1.230178310","rc":[{"atl":[[11.5,0.73]],"id":68392143}],"con":true,"img":false}]}
{"op":"mcm","clk":"11540659513","pt":1719497016423,"mc":[{"id":"1.230178310","rc":[{"atl":[[1000,0.32]],"id":68392143}],"con":true,"img":false}]}
{"op":"mcm","clk":"11540659535","pt":1719497016689,"mc":[{"id":"1.230178310","rc":[{"atl":[[1000,0.22]],"id":68392143}],"con":true,"img":false}]}
{"op":"mcm","clk":"11540659541","pt":1719497016791,"mc":[{"id":"1.230178310","rc":[{"atl":[[11.5,0.83]],"id":68392143}],"con":true,"img":false}]}
{"op":"mcm","clk":"11540659549","pt":1719497016890,"mc":[{"id":"1.230178310","rc":[{"atb":[[4.3,2],[4,1]],"id":68392143}],"con":true,"img":false}]}
{"op":"mcm","clk":"11540659704","pt":1719497018908,"mc":[{"id":"1.230178310","rc":[{"atb":[[2.96,5.37]],"id":68392143}],"con":true,"img":false}]}
{"op":"mcm","clk":"11540659709","pt":1719497019012,"mc":[{"id":"1.230178310","rc":[{"atb":[[2.16,22.13]],"id":68392143}],"con":true,"img":false}]}
{"op":"mcm","clk":"11540659718","pt":1719497019115,"mc":[{"id":"1.230178310","rc":[{"atl":[[4.7,0]],"id":55302014}],"con":true,"img":false}]}
{"op":"mcm","clk":"11540659721","pt":1719497019218,"mc":[{"id":"1.230178310","rc":[{"atb":[[2.16,11.87]],"id":57088863}],"con":true,"img":false}]}
{"op":"mcm","clk":"11540659727","pt":1719497019321,"mc":[{"id":"1.230178310","rc":[{"atb":[[2.96,12.5]],"id":68392143}],"con":true,"img":false}]}
{"op":"mcm","clk":"11540659743","pt":1719497019635,"mc":[{"id":"1.230178310","rc":[{"atl":[[4.6,0],[4.7,5.4]],"id":55302014}],"con":true,"img":false}]}
{"op":"mcm","clk":"11540659761","pt":1719497019788,"mc":[{"id":"1.230178310","rc":[{"atb":[[2.46,21.06]],"id":55302014}],"con":true,"img":false}]}
{"op":"mcm","clk":"11540659776","pt":1719497019995,"mc":[{"id":"1.230178310","rc":[{"atb":[[2.46,24.22]],"id":55302014}],"con":true,"img":false}]}
{"op":"mcm","clk":"11540659784","pt":1719497020100,"mc":[{"id":"1.230178310","rc":[{"atb":[[2.48,9.43]],"id":55302014}],"con":true,"img":false}]}
{"op":"mcm","clk":"11540659800","pt":1719497020306,"mc":[{"id":"1.230178310","rc":[{"atb":[[2.6,1.8]],"id":55302014}],"con":true,"img":false}]}
{"op":"mcm","clk":"11540659859","pt":1719497021139,"mc":[{"id":"1.230178310","rc":[{"atb":[[4.3,3],[4,0]],"id":68392143}],"con":true,"img":false}]}
{"op":"mcm","clk":"11540659891","pt":1719497021400,"mc":[{"id":"1.230178310","rc":[{"atb":[[2.54,0],[2.66,2.09]],"id":55302014},{"atl":[[4.6,2]],"id":55302014}],"con":true,"img":false}]}
{"op":"mcm","clk":"11540659902","pt":1719497021510,"mc":[{"id":"1.230178310","rc":[{"atl":[[4.7,7.56]],"id":55302014}],"con":true,"img":false}]}
{"op":"mcm","clk":"11540659945","pt":1719497021940,"mc":[{"id":"1.230178310","rc":[{"atl":[[4.7,2.16]],"id":55302014}],"con":true,"img":false}]}
{"op":"mcm","clk":"11540659970","pt":1719497022103,"mc":[{"id":"1.230178310","rc":[{"atb":[[2.6,0]],"id":55302014},{"atl":[[4.5,0.84]],"id":55302014}],"con":true,"img":false}]}
{"op":"mcm","clk":"11540660054","pt":1719497022939,"mc":[{"id":"1.230178310","rc":[{"atb":[[4,1]],"id":68392143}],"con":true,"img":false}]}
{"op":"mcm","clk":"11540660065","pt":1719497023032,"mc":[{"id":"1.230178310","rc":[{"atb":[[4.3,2]],"id":68392143}],"con":true,"img":false}]}
{"op":"mcm","clk":"11540660086","pt":1719497023194,"mc":[{"id":"1.230178310","rc":[{"atb":[[4,0]],"id":68392143}],"con":true,"img":false}]}
{"op":"mcm","clk":"11540660236","pt":1719497024901,"mc":[{"id":"1.230178310","rc":[{"atb":[[4,1]],"id":68392143}],"con":true,"img":false}]}
{"op":"mcm","clk":"11540660364","pt":1719497026613,"mc":[{"id":"1.230178310","rc":[{"atb":[[3.05,0]],"id":55302014},{"atl":[[4.6,0]],"id":55302014}],"con":true,"img":false}]}
{"op":"mcm","clk":"11540660384","pt":1719497026821,"mc":[{"id":"1.230178310","rc":[{"atl":[[4.8,0.26]],"id":55302014}],"con":true,"img":false}]}
{"op":"mcm","clk":"11540660403","pt":1719497027130,"mc":[{"id":"1.230178310","rc":[{"spn":3.76,"spf":1.0,"id":57087188},{"spn":10.16,"spf":"Infinity","id":65436514},{"spn":11.33,"spf":1.0,"id":69142441},{"atl":[[4.5,0],[4.6,5.51]],"id":55302014},{"spn":2.84,"spf":1.0,"id":55302014},{"spn":7.11,"spf":1.0,"id":57088863}],"con":true,"img":false}]}
{"op":"mcm","clk":"11540660411","pt":1719497027234,"mc":[{"id":"1.230178310","rc":[{"atb":[[3.1,1.43]],"id":55302014},{"atl":[[4.5,1.05]],"id":55302014}],"con":true,"img":false}]}
{"op":"mcm","clk":"11540660418","pt":1719497027337,"mc":[{"id":"1.230178310","rc":[{"atb":[[4.3,3],[4,0]],"id":68392143}],"con":true,"img":false}]}
{"op":"mcm","clk":"11540660446","pt":1719497027708,"mc":[{"id":"1.230178310","rc":[{"atl":[[4.6,0]],"id":55302014}],"con":true,"img":false}]}
{"op":"mcm","clk":"11540660475","pt":1719497028117,"mc":[{"id":"1.230178310","rc":[{"atb":[[3.1,0]],"id":55302014},{"atl":[[4.8,0]],"id":55302014},{"trd":[[3.1,32.99]],"ltp":3.1,"tv":32.99,"id":55302014}],"con":true,"img":false}]}
{"op":"mcm","clk":"11540660492","pt":1719497028323,"mc":[{"id":"1.230178310","rc":[{"atl":[[1000,1.55]],"id":55302014}],"con":true,"img":false}]}
{"op":"mcm","clk":"11540660511","pt":1719497028530,"mc":[{"id":"1.230178310","rc":[{"atl":[[1000,1.27]],"id":55302014}],"con":true,"img":false}]}
{"op":"mcm","clk":"11540660519","pt":1719497028633,"mc":[{"id":"1.230178310","rc":[{"atl":[[4.6,0.28]],"id":55302014},{"atb":[[4,1]],"id":68392143}],"con":true,"img":false}]}
{"op":"mcm","clk":"11540660526","pt":1719497028736,"mc":[{"id":"1.230178310","rc":[{"atb":[[4.3,2]],"id":68392143}],"con":true,"img":false}]}
{"op":"mcm","clk":"11540660534","pt":1719497028840,"mc":[{"id":"1.230178310","rc":[{"atb":[[2.2,0]],"id":65436514},{"atb":[[2.94,0]],"id":68392143}],"con":true,"img":false}]}
{"op":"mcm","clk":"11540660588","pt":1719497029729,"mc":[{"id":"1.230178310","rc":[{"atl":[[4.4,2]],"id":55302014}],"con":true,"img":false}]}
{"op":"mcm","clk":"11540660610","pt":1719497030031,"mc":[{"id":"1.230178310","rc":[{"atl":[[4.3,0.84]],"id":55302014}],"con":true,"img":false}]}
{"op":"mcm","clk":"11540660679","pt":1719497030712,"mc":[{"id":"1.230178310","rc":[{"atl":[[32,0],[34,1]],"id":69142441},{"atb":[[4,0]],"id":68392143}],"con":true,"img":false}]}
{"op":"mcm","clk":"11540660688","pt":1719497030815,"mc":[{"id":"1.230178310","rc":[{"atl":[[140,0],[120,2.27]],"id":69142441}],"con":true,"img":false}]}
{"op":"mcm","clk":"11540660708","pt":1719497031023,"mc":[{"id":"1.230178310","rc":[{"atl":[[130,0]],"id":69142441}],"con":true,"img":false}]}
{"op":"mcm","clk":"11540660716","pt":1719497031127,"mc":[{"id":"1.230178310","rc":[{"atl":[[110,1]],"id":69142441}],"con":true,"img":false}]}
{"op":"mcm","clk":"11540660755","pt":1719497031536,"mc":[{"id":"1.230178310","rc":[{"atl":[[5.6,0]],"id":55302014}],"con":true,"img":false}]}
{"op":"mcm","clk":"11540660802","pt":1719497032016,"mc":[{"id":"1.230178310","rc":[{"atl":[[11.5,0.73]],"id":68392143}],"con":true,"img":false}]}
{"op":"mcm","clk":"11540660821","pt":1719497032224,"mc":[{"id":"1.230178310","rc":[{"atl":[[1000,0.32]],"id":68392143}],"con":true,"img":false}]}
{"op":"mcm","clk":"11540660831","pt":1719497032430,"mc":[{"id":"1.230178310","rc":[{"atl":[[1000,0.22]],"id":68392143}],"con":true,"img":false}]}
{"op":"mcm","clk":"11540660839","pt":1719497032543,"mc":[{"id":"1.230178310","rc":[{"atl":[[11.5,0.83]],"id":68392143}],"con":true,"img":false}]}
{"op":"mcm","clk":"11540661021","pt":1719497034926,"mc":[{"id":"1.230178310","rc":[{"atl":[[4.4,0]],"id":55302014}],"con":true,"img":false}]}
{"op":"mcm","clk":"11540661039","pt":1719497035119,"mc":[{"id":"1.230178310","rc":[{"atb":[[2.46,21.06]],"id":55302014},{"atb":[[2.98,3.15]],"id":68392143}],"con":true,"img":false}]}
{"op":"mcm","clk":"11540661057","pt":1719497035422,"mc":[{"id":"1.230178310","rc":[{"atb":[[2.98,9.14]],"id":68392143}],"con":true,"img":false}]}
{"op":"mcm","clk":"11540661083","pt":1719497035734,"mc":[{"id":"1.230178310","rc":[{"atl":[[4.3,0]],"id":55302014}],"con":true,"img":false}]}
{"op":"mcm","clk":"11540661094","pt":1719497035943,"mc":[{"id":"1.230178310","rc":[{"atb":[[2.24,9.55]],"id":65436514},{"atb":[[2.5,3.15]],"id":55302014}],"con":true,"img":false}]}
{"op":"mcm","clk":"11540661167","pt":1719497037239,"mc":[{"id":"1.230178310","rc":[{"atl":[[4.4,2]],"id":55302014}],"con":true,"img":false}]}
{"op":"mcm","clk":"11540661188","pt":1719497037552,"mc":[{"id":"1.230178310","rc":[{"atl":[[4.3,0.84]],"id":55302014}],"con":true,"img":false}]}
{"op":"mcm","clk":"11540661441","pt":1719497040956,"mc":[{"id":"1.230178310","rc":[{"atl":[[32,1],[34,0]],"id":69142441}],"con":true,"img":false}]}
{"op":"mcm","clk":"11540661453","pt":1719497041060,"mc":[{"id":"1.230178310","rc":[{"atb":[[2.52,14.8]],"id":55302014},{"atl":[[4.3,8.41]],"id":55302014}],"con":true,"img":false}]}
{"op":"mcm","clk":"11540661555","pt":1719497042466,"mc":[{"id":"1.230178310","rc":[{"atb":[[1.05,1.7]],"id":57087188},{"atl":[[1000,2.18]],"id":57087188},{"atb":[[1.03,9.59]],"id":55302014},{"atl":[[4.4,0],[1000,2.98]],"id":55302014}],"con":true,"img":false}]}
{"op":"mcm","clk":"11540661573","pt":1719497042627,"mc":[{"id":"1.230178310","rc":[{"atb":[[1.05,0.05]],"id":57087188},{"atl":[[1000,0.5]],"id":57087188},{"atb":[[2.22,13.95]],"id":65436514},{"atb":[[1.03,7.97]],"id":55302014},{"atl":[[4.4,2.35],[1000,1.33],[4.5,0]],"id":55302014}],"con":true,"img":false}]}
{"op":"mcm","clk":"11540661591","pt":1719497042830,"mc":[{"id":"1.230178310","rc":[{"atb":[[1.05,0]],"id":57087188},{"atl":[[1000,0.48]],"id":57087188},{"atb":[[1.03,7.89]],"id":55302014},{"atl":[[1000,1.27]],"id":55302014}],"con":true,"img":false}]}
{"op":"mcm","clk":"11540661596","pt":1719497042935,"mc":[{"id":"1.230178310","rc":[{"atb":[[4.1,0.11]],"id":57087188},{"atl":[[7.4,1.05]],"id":57087188},{"atb":[[2.96,1.08]],"id":55302014},{"atl":[[4.2,0.05]],"id":55302014}],"con":true,"img":false}]}
{"op":"mcm","clk":"11540661602","pt":1719497043045,"mc":[{"id":"1.230178310","rc":[{"atl":[[4.2,0.8]],"id":55302014}],"con":true,"img":false}]}
{"op":"mcm","clk":"11540661632","pt":1719497043458,"mc":[{"id":"1.230178310","rc":[{"atb":[[3.4,9.46]],"id":57087188},{"atl":[[8.8,3.33]],"id":57087188}],"con":true,"img":false}]}
{"op":"mcm","clk":"11540661643","pt":1719497043523,"mc":[{"id":"1.230178310","rc":[{"atl":[[1000,0.78]],"id":55302014}],"con":true,"img":false}]}
{"op":"mcm","clk":"11540661649","pt":1719497043618,"mc":[{"id":"1.230178310","rc":[{"atl":[[4.2,1.29]],"id":55302014}],"con":true,"img":false}]}
{"op":"mcm","clk":"11540661660","pt":1719497043721,"mc":[{"id":"1.230178310","rc":[{"atb":[[3.45,1.61]],"id":57087188}],"con":true,"img":false}]}
{"op":"mcm","clk":"11540661669","pt":1719497043825,"mc":[{"id":"1.230178310","rc":[{"atb":[[2.76,0]],"id":57087188},{"atl":[[4.6,0]],"id":55302014}],"con":true,"img":false}]}
{"op":"mcm","clk":"11540661674","pt":1719497043927,"mc":[{"id":"1.230178310","rc":[{"atl":[[4.2,3.79]],"id":55302014}],"con":true,"img":false}]}
{"op":"mcm","clk":"11540661693","pt":1719497044140,"mc":[{"id":"1.230178310","rc":[{"atl":[[4.2,3.3]],"id":55302014}],"con":true,"img":false}]}
{"op":"mcm","clk":"11540661703","pt":1719497044247,"mc":[{"id":"1.230178310","rc":[{"atb":[[3.5,9.77]],"id":57087188},{"atl":[[1000,1.27],[4.2,10.9]],"id":55302014}],"con":true,"img":false}]}
{"op":"mcm","clk":"11540661712","pt":1719497044349,"mc":[{"id":"1.230178310","rc":[{"atl":[[4.1,6.19]],"id":55302014}],"con":true,"img":false}]}
{"op":"mcm","clk":"11540661747","pt":1719497044862,"mc":[{"id":"1.230178310","rc":[{"atl":[[1000,0.78]],"id":55302014}],"con":true,"img":false}]}
{"op":"mcm","clk":"11540661757","pt":1719497044965,"mc":[{"id":"1.230178310","rc":[{"atb":[[3.45,0]],"id":57087188},{"atl":[[4,0.48]],"id":55302014}],"con":true,"img":false}]}
{"op":"mcm","clk":"11540661766","pt":1719497045027,"mc":[{"id":"1.230178310","rc":[{"atb":[[3.55,1.61]],"id":57087188},{"atl":[[4.3,7.57],[4,1.33]],"id":55302014}],"con":true,"img":false}]}
{"op":"mcm","clk":"11540661776","pt":1719497045122,"mc":[{"id":"1.230178310","rc":[{"atl":[[4.1,14.49]],"id":55302014}],"con":true,"img":false}]}
{"op":"mcm","clk":"11540661812","pt":1719497045434,"mc":[{"id":"1.230178310","rc":[{"atl":[[4.1,8.3]],"id":55302014}],"con":true,"img":false}]}
{"op":"mcm","clk":"11540661821","pt":1719497045546,"mc":[{"id":"1.230178310","rc":[{"atl":[[3.95,2]],"id":55302014}],"con":true,"img":false}]}
{"op":"mcm","clk":"11540661882","pt":1719497046263,"mc":[{"id":"1.230178310","rc":[{"atl":[[3.9,6.34]],"id":55302014}],"con":true,"img":false}]}
{"op":"mcm","clk":"11540661894","pt":1719497046420,"mc":[{"id":"1.230178310","rc":[{"atb":[[3.6,10.02]],"id":57087188},{"atl":[[3.95,10.49]],"id":55302014}],"con":true,"img":false}]}
{"op":"mcm","clk":"11540661903","pt":1719497046524,"mc":[{"id":"1.230178310","rc":[{"atl":[[4,0.84]],"id":55302014}],"con":true,"img":false}]}
{"op":"mcm","clk":"11540661913","pt":1719497046639,"mc":[{"id":"1.230178310","rc":[{"atl":[[3.85,0.48],[4,0]],"id":55302014}],"con":true,"img":false}]}
{"op":"mcm","clk":"11540661922","pt":1719497046737,"mc":[{"id":"1.230178310","rc":[{"atb":[[3.55,0]],"id":57087188}],"con":true,"img":false}]}
{"op":"mcm","clk":"11540661930","pt":1719497046836,"mc":[{"id":"1.230178310","rc":[{"atb":[[3.65,1.61]],"id":57087188}],"con":true,"img":false}]}
{"op":"mcm","clk":"11540661970","pt":1719497047354,"mc":[{"id":"1.230178310","rc":[{"atl":[[3.95,8.49]],"id":55302014}],"con":true,"img":false}]}
{"op":"mcm","clk":"11540661978","pt":1719497047457,"mc":[{"id":"1.230178310","rc":[{"atl":[[4.3,0]],"id":55302014}],"con":true,"img":false}]}
{"op":"mcm","clk":"11540661987","pt":1719497047562,"mc":[{"id":"1.230178310","rc":[{"atb":[[3.7,9.22]],"id":57087188},{"atl":[[3.85,9.62]],"id":55302014}],"con":true,"img":false}]}
{"op":"mcm","clk":"11540662000","pt":1719497047719,"mc":[{"id":"1.230178310","rc":[{"atb":[[3,6.68]],"id":55302014},{"atl":[[11.5,0.73]],"id":68392143}],"con":true,"img":false}]}
{"op":"mcm","clk":"11540662007","pt":1719497047827,"mc":[{"id":"1.230178310","rc":[{"atl":[[3.9,0]],"id":55302014}],"con":true,"img":false}]}
{"op":"mcm","clk":"11540662011","pt":1719497047929,"mc":[{"id":"1.230178310","rc":[{"atb":[[3.65,0]],"id":57087188},{"atl":[[3.8,6.34]],"id":55302014}],"con":true,"img":false}]}
{"op":"mcm","clk":"11540662020","pt":1719497048040,"mc":[{"id":"1.230178310","rc":[{"atb":[[3.75,1.61]],"id":57087188},{"atb":[[3.05,0.84],[2.96,0.23]],"id":55302014},{"atl":[[1000,0.32]],"id":68392143}],"con":true,"img":false}]}
{"op":"mcm","clk":"11540662033","pt":1719497048245,"mc":[{"id":"1.230178310","rc":[{"atl":[[1000,0.22]],"id":68392143}],"con":true,"img":false}]}
{"op":"mcm","clk":"11540662039","pt":1719497048346,"mc":[{"id":"1.230178310","rc":[{"atl":[[3.85,9.14]],"id":55302014},{"atl":[[11.5,0.83]],"id":68392143}],"con":true,"img":false}]}
{"op":"mcm","clk":"11540662048","pt":1719497048450,"mc":[{"id":"1.230178310","rc":[{"atl":[[3.75,0.48]],"id":55302014}],"con":true,"img":false}]}
{"op":"mcm","clk":"11540662098","pt":1719497048922,"mc":[{"id":"1.230178310","rc":[{"atb":[[3.4,0]],"id":57087188},{"atl":[[4.2,3.3]],"id":55302014}],"con":true,"img":false}]}
{"op":"mcm","clk":"11540662116","pt":1719497049130,"mc":[{"id":"1.230178310","rc":[{"atb":[[3.8,8.83]],"id":57087188},{"atl":[[3.75,9.1]],"id":55302014}],"con":true,"img":false}]}
{"op":"mcm","clk":"11540662121","pt":1719497049228,"mc":[{"id":"1.230178310","rc":[{"atl":[[3.75,12.01]],"id":55302014}],"con":true,"img":false}]}
{"op":"mcm","clk":"11540662143","pt":1719497049544,"mc":[{"id":"1.230178310","rc":[{"atl":[[3.8,0]],"id":55302014}],"con":true,"img":false}]}
{"op":"mcm","clk":"11540662154","pt":1719497049645,"mc":[{"id":"1.230178310","rc":[{"atl":[[3.85,0],[3.75,3.39],[3.95,0],[4.1,8.05]],"id":55302014}],"con":true,"img":false}]}
{"op":"mcm","clk":"11540662160","pt":1719497049747,"mc":[{"id":"1.230178310","rc":[{"atb":[[3.75,0]],"id":57087188},{"atl":[[3.7,6.34]],"id":55302014}],"con":true,"img":false}]}
{"op":"mcm","clk":"11540662168","pt":1719497049850,"mc":[{"id":"1.230178310","rc":[{"atb":[[3.85,1.61]],"id":57087188},{"atb":[[3,5.67],[3.05,0]],"id":55302014},{"trd":[[3,2.02],[3.05,1.69]],"ltp":3.0,"tv":3.71,"id":55302014}],"con":true,"img":false}]}
{"op":"mcm","clk":"11540662186","pt":1719497050162,"mc":[{"id":"1.230178310","rc":[{"atl":[[3.75,2.91]],"id":55302014}],"con":true,"img":false}]}
{"op":"mcm","clk":"11540662192","pt":1719497050223,"mc":[{"id":"1.230178310","rc":[{"atb":[[3.8,10.05]],"id":57087188},{"atl":[[1000,1.27]],"id":55302014},{"atb":[[2.98,10.26]],"id":68392143}],"con":true,"img":false}]}
{"op":"mcm","clk":"11540662212","pt":1719497050528,"mc":[{"id":"1.230178310","rc":[{"atb":[[3.5,0]],"id":57087188}],"con":true,"img":false}]}
{"op":"mcm","clk":"11540662229","pt":1719497050737,"mc":[{"id":"1.230178310","rc":[{"atb":[[3.9,8.89]],"id":57087188},{"atl":[[3.7,16.52]],"id":55302014}],"con":true,"img":false}]}
{"op":"mcm","clk":"11540662245","pt":1719497050943,"mc":[{"id":"1.230178310","rc":[{"atb":[[3.85,0],[3.8,8.83]],"id":57087188}],"con":true,"img":false}]}
{"op":"mcm","clk":"11540662253","pt":1719497051048,"mc":[{"id":"1.230178310","rc":[{"atb":[[3.95,1.61],[3.9,10.11]],"id":57087188}],"con":true,"img":false}]}
{"op":"mcm","clk":"11540662280","pt":1719497051360,"mc":[{"id":"1.230178310","rc":[{"atl":[[1000,0.78]],"id":55302014}],"con":true,"img":false}]}
{"op":"mcm","clk":"11540662289","pt":1719497051464,"mc":[{"id":"1.230178310","rc":[{"atl":[[3.65,0.48]],"id":55302014}],"con":true,"img":false}]}
{"op":"mcm","clk":"11540662320","pt":1719497051834,"mc":[{"id":"1.230178310","rc":[{"atb":[[1.54,11.69]],"id":55302014}],"con":true,"img":false}]}
{"op":"mcm","clk":"11540662327","pt":1719497051932,"mc":[{"id":"1.230178310","rc":[{"atb":[[2.5,0]],"id":55302014}],"con":true,"img":false}]}
{"op":"mcm","clk":"11540662334","pt":1719497052035,"mc":[{"id":"1.230178310","rc":[{"atl":[[3.65,1.33]],"id":55302014}],"con":true,"img":false}]}
{"op":"mcm","clk":"11540662351","pt":1719497052242,"mc":[{"id":"1.230178310","rc":[{"atl":[[3.7,10.18],[3.65,10.58]],"id":55302014}],"con":true,"img":false}]}
{"op":"mcm","clk":"11540662369","pt":1719497052451,"mc":[{"id":"1.230178310","rc":[{"atl":[[3.6,6.34]],"id":55302014}],"con":true,"img":false}]}
{"op":"mcm","clk":"11540662420","pt":1719497053072,"mc":[{"id":"1.230178310","rc":[{"atl":[[3.6,15.65]],"id":55302014}],"con":true,"img":false}]}
{"op":"mcm","clk":"11540662432","pt":1719497053133,"mc":[{"id":"1.230178310","rc":[{"atl":[[3.65,10.09]],"id":55302014}],"con":true,"img":false}]}
{"op":"mcm","clk":"11540662443","pt":1719497053230,"mc":[{"id":"1.230178310","rc":[{"atl":[[3.55,0.48]],"id":55302014}],"con":true,"img":false}]}
{"op":"mcm","clk":"11540662583","pt":1719497054944,"mc":[{"id":"1.230178310","rc":[{"atb":[[2.96,9.11]],"id":68392143}],"con":true,"img":false}]}
{"op":"mcm","clk":"11540662661","pt":1719497055832,"mc":[{"id":"1.230178310","rc":[{"atb":[[2.8,7.75]],"id":57087188}],"con":true,"img":false}]}
{"op":"mcm","clk":"11540662703","pt":1719497056148,"mc":[{"id":"1.230178310","rc":[{"atb":[[3,3.38]],"id":68392143}],"con":true,"img":false}]}
{"op":"mcm","clk":"11540662778","pt":1719497056972,"mc":[{"id":"1.230178310","rc":[{"atb":[[2.98,9.14]],"id":68392143}],"con":true,"img":false}]}
{"op":"mcm","clk":"11540662786","pt":1719497057076,"mc":[{"id":"1.230178310","rc":[{"atb":[[3,4.5]],"id":68392143}],"con":true,"img":false}]}
{"op":"mcm","clk":"11540662914","pt":1719497058435,"mc":[{"id":"1.230178310","rc":[{"atl":[[4.2,2.55]],"id":55302014}],"con":true,"img":false}]}
{"op":"mcm","clk":"11540662961","pt":1719497059051,"mc":[{"id":"1.230178310","rc":[{"atl":[[3.55,1.24]],"id":55302014}],"con":true,"img":false}]}
{"op":"mcm","clk":"11540662972","pt":1719497059155,"mc":[{"id":"1.230178310","rc":[{"atl":[[3.55,4.38]],"id":55302014}],"con":true,"img":false}]}
{"op":"mcm","clk":"11540662979","pt":1719497059259,"mc":[{"id":"1.230178310","rc":[{"atl":[[3.6,9.31]],"id":55302014}],"con":true,"img":false}]}
{"op":"mcm","clk":"11540662985","pt":1719497059362,"mc":[{"id":"1.230178310","rc":[{"atl":[[3.5,6.34]],"id":55302014}],"con":true,"img":false}]}
{"op":"mcm","clk":"11540663005","pt":1719497059570,"mc":[{"id":"1.230178310","rc":[{"atl":[[3.45,0.84]],"id":55302014}],"con":true,"img":false}]}
{"op":"mcm","clk":"11540663016","pt":1719497059673,"mc":[{"id":"1.230178310","rc":[{"atl":[[3.65,9.25]],"id":55302014}],"con":true,"img":false}]}
{"op":"mcm","clk":"11540663030","pt":1719497059728,"mc":[{"id":"1.230178310","rc":[{"atl":[[3.55,3.89],[4.1,0]],"id":55302014}],"con":true,"img":false}]}
{"op":"mcm","clk":"11540663040","pt":1719497059831,"mc":[{"id":"1.230178310","rc":[{"atl":[[1000,1.27]],"id":55302014}],"con":true,"img":false}]}
{"op":"mcm","clk":"11540663055","pt":1719497059933,"mc":[{"id":"1.230178310","rc":[{"atl":[[3.45,10.94]],"id":55302014}],"con":true,"img":false}]}
{"op":"mcm","clk":"11540663079","pt":1719497060349,"mc":[{"id":"1.230178310","rc":[{"atl":[[3.5,0]],"id":55302014}],"con":true,"img":false}]}
{"op":"mcm","clk":"11540663091","pt":1719497060503,"mc":[{"id":"1.230178310","rc":[{"atl":[[3.4,6.34]],"id":55302014}],"con":true,"img":false}]}
{"op":"mcm","clk":"11540663102","pt":1719497060660,"mc":[{"id":"1.230178310","rc":[{"atl":[[3.7,0]],"id":55302014}],"con":true,"img":false}]}
{"op":"mcm","clk":"11540663113","pt":1719497060763,"mc":[{"id":"1.230178310","rc":[{"atl":[[3.4,16.81]],"id":55302014}],"con":true,"img":false}]}
{"op":"mcm","clk":"11540663209","pt":1719497062056,"mc":[{"id":"1.230178310","rc":[{"atl":[[3.65,0]],"id":55302014}],"con":true,"img":false}]}
{"op":"mcm","clk":"11540663216","pt":1719497062161,"mc":[{"id":"1.230178310","rc":[{"atb":[[3,0]],"id":55302014},{"trd":[[3,13.36]],"ltp":3.0,"tv":13.36,"id":55302014}],"con":true,"img":false}]}
{"op":"mcm","clk":"11540663225","pt":1719497062265,"mc":[{"id":"1.230178310","rc":[{"atb":[[2.58,7.17]],"id":55302014},{"atl":[[3.35,3.4]],"id":55302014}],"con":true,"img":false}]}
{"op":"mcm","clk":"11540663248","pt":1719497062474,"mc":[{"id":"1.230178310","rc":[{"atl":[[3.35,12.97]],"id":55302014}],"con":true,"img":false}]}
{"op":"mcm","clk":"11540663260","pt":1719497062531,"mc":[{"id":"1.230178310","rc":[{"atl":[[3.45,10.1]],"id":55302014}],"con":true,"img":false}]}
