{"op":"mcm","clk":"11536380639","pt":1719425245572,"mc":[{"id":"1.230178312","marketDefinition":{"bspMarket":true,"turnInPlayEnabled":false,"persistenceEnabled":false,"marketBaseRate":5.0,"eventId":"33376062","eventTypeId":"4339","numberOfWinners":1,"bettingType":"ODDS","marketType":"WIN","marketTime":"2024-06-27T14:32:00.000Z","suspendTime":"2024-06-27T14:32:00.000Z","bspReconciled":false,"complete":true,"inPlay":false,"crossMatching":false,"runnersVoidable":false,"numberOfActiveRunners":6,"betDelay":0,"status":"OPEN","runners":[{"status":"ACTIVE","sortPriority":1,"id":39100893,"name":"1. Sheriffs Rose"},{"status":"ACTIVE","sortPriority":2,"id":52951653,"name":"2. Grumpy Wazock"},{"status":"ACTIVE","sortPriority":3,"id":51441055,"name":"3. Pounda Prisna"},{"status":"ACTIVE","sortPriority":4,"id":68462283,"name":"4. Tober Glory"},{"status":"ACTIVE","sortPriority":5,"id":70681331,"name":"5. Shelone Luna"},{"status":"ACTIVE","sortPriority":6,"id":56913144,"name":"6. Knotmor Best"}],"regulators":["MR_INT"],"venue":"Kinsley","countryCode":"GB","discountAllowed":false,"timezone":"Europe/London","openDate":"2024-06-27T13:36:00.000Z","version":5994643751,"name":"A5 462m","eventName":"Kinsley 27th Jun"},"rc":[],"con":true,"img":false}]}
{"op":"mcm","clk":"11536381013","pt":1719425248523,"mc":[{"id":"1.230178312","marketDefinition":{"bspMarket":true,"turnInPlayEnabled":false,"persistenceEnabled":false,"marketBaseRate":5.0,"eventId":"33376062","eventTypeId":"4339","numberOfWinners":1,"bettingType":"ODDS","marketType":"WIN","marketTime":"2024-06-27T14:32:00.000Z","suspendTime":"2024-06-27T14:32:00.000Z","bspReconciled":false,"complete":true,"inPlay":false,"crossMatching":false,"runnersVoidable":false,"numberOfActiveRunners":6,"betDelay":0,"status":"OPEN","runners":[{"status":"ACTIVE","sortPriority":1,"id":39100893,"name":"1. Sheriffs Rose"},{"status":"ACTIVE","sortPriority":2,"id":52951653,"name":"2. Grumpy Wazock"},{"status":"ACTIVE","sortPriority":3,"id":51441055,"name":"3. Pounda Prisna"},{"status":"ACTIVE","sortPriority":4,"id":68462283,"name":"4. Tober Glory"},{"status":"ACTIVE","sortPriority":5,"id":70681331,"name":"5. Shelone Luna"},{"status":"ACTIVE","sortPriority":6,"id":56913144,"name":"6. Knotmor Best"}],"regulators":["MR_INT"],"venue":"Kinsley","countryCode":"GB","discountAllowed":true,"timezone":"Europe/London","openDate":"2024-06-27T13:36:00.000Z","version":5994643751,"name":"A5 462m","eventName":"Kinsley 27th Jun"},"rc":[],"con":true,"img":false}]}
{"op":"mcm","clk":"11536615236","pt":1719428245416,"mc":[{"id":"1.230178312","rc":[{"atb":[[1.02,22.63]],"id":56913144},{"atl":[[990,0.84]],"id":56913144},{"spn":495.51,"spf":"NaN","id":56913144},{"atb":[[1.02,22.63]],"id":68462283},{"atl":[[990,0.84]],"id":68462283},{"spn":495.51,"spf":"NaN","id":68462283},{"atb":[[1.01,45.27]],"id":70681331},{"atl":[[1000,0.84]],"id":70681331},{"spn":500.5,"spf":"NaN","id":70681331},{"atb":[[1.01,45.27]],"id":39100893},{"atl":[[990,0.84]],"id":39100893},{"spn":495.5,"spf":"NaN","id":39100893},{"atb":[[1.03,15.09]],"id":52951653},{"atl":[[1000,0.84]],"id":52951653},{"spn":500.51,"spf":"NaN","id":52951653},{"atb":[[1.02,22.63]],"id":51441055},{"atl":[[1000,0.84]],"id":51441055},{"spn":500.51,"spf":"NaN","id":51441055}],"con":true,"img":false}]}
{"op":"mcm","clk":"11536837015","pt":1719431852912,"mc":[{"id":"1.230178312","rc":[{"atb":[[1.02,22.64]],"id":56913144},{"atl":[[990,0.26]],"id":56913144},{"atb":[[1.02,22.64]],"id":68462283},{"atl":[[990,0.26]],"id":68462283},{"atb":[[1.01,45.28]],"id":70681331},{"atl":[[1000,0.26]],"id":70681331},{"atb":[[1.01,45.28]],"id":39100893},{"atl":[[990,0.26]],"id":39100893},{"atb":[[1.03,15.09]],"id":52951653},{"atl":[[1000,0.26]],"id":52951653},{"atb":[[1.02,22.64]],"id":51441055},{"atl":[[1000,0.26]],"id":51441055}],"con":true,"img":false}]}
{"op":"mcm","clk":"11536863480","pt":1719432266252,"mc":[{"id":"1.230178312","rc":[{"spl":[[1.01,1]],"id":56913144},{"spn":1.02,"spf":1.0,"id":56913144}],"con":true,"img":false}]}
{"op":"mcm","clk":"11537232244","pt":1719437882515,"mc":[{"id":"1.230178312","marketDefinition":{"bspMarket":true,"turnInPlayEnabled":false,"persistenceEnabled":false,"marketBaseRate":5.0,"eventId":"33376062","eventTypeId":"4339","numberOfWinners":1,"bettingType":"ODDS","marketType":"WIN","marketTime":"2024-06-27T14:32:00.000Z","suspendTime":"2024-06-27T14:32:00.000Z","bspReconciled":false,"complete":true,"inPlay":false,"crossMatching":false,"runnersVoidable":false,"numberOfActiveRunners":6,"betDelay":0,"status":"OPEN","runners":[{"status":"ACTIVE","sortPriority":1,"id":39100893,"name":"1. Sheriffs Rose"},{"status":"ACTIVE","sortPriority":2,"id":52951653,"name":"2. Grumpy Wazock"},{"status":"ACTIVE","sortPriority":3,"id":51441055,"name":"3. Pounda Prisna"},{"status":"ACTIVE","sortPriority":4,"id":68462283,"name":"4. Tober Glory"},{"status":"ACTIVE","sortPriority":5,"id":70681331,"name":"5. Shelone Luna"},{"status":"ACTIVE","sortPriority":6,"id":56913144,"name":"6. Knotmor Best"}],"regulators":["MR_INT"],"venue":"Kinsley","countryCode":"GB","discountAllowed":true,"timezone":"Europe/London","openDate":"2024-06-27T13:36:00.000Z","version":5994643751,"name":"A5 462m","eventName":"Kinsley 27th Jun"},"rc":[{"spl":[[1.01,1]],"id":56913144},{"atb":[[1.02,22.64]],"id":56913144},{"atl":[[990,0.26]],"id":56913144},{"spn":1.02,"spf":1.0,"id":56913144},{"atb":[[1.02,22.64]],"id":68462283},{"atl":[[990,0.26]],"id":68462283},{"spn":495.51,"spf":"NaN","id":68462283},{"atb":[[1.01,45.28]],"id":70681331},{"atl":[[1000,0.26]],"id":70681331},{"spn":500.5,"spf":"NaN","id":70681331},{"atb":[[1.01,45.28]],"id":39100893},{"atl":[[990,0.26]],"id":39100893},{"spn":495.5,"spf":"NaN","id":39100893},{"atb":[[1.03,15.09]],"id":52951653},{"atl":[[1000,0.26]],"id":52951653},{"spn":500.51,"spf":"NaN","id":52951653},{"atb":[[1.02,22.64]],"id":51441055},{"atl":[[1000,0.26]],"id":51441055},{"spn":500.51,"spf":"NaN","id":51441055}],"con":true,"img":true}]}
{"op":"mcm","clk":"11537573371","pt":1719443282536,"mc":[{"id":"1.230178312","marketDefinition":{"bspMarket":true,"turnInPlayEnabled":false,"persistenceEnabled":false,"marketBaseRate":5.0,"eventId":"33376062","eventTypeId":"4339","numberOfWinners":1,"bettingType":"ODDS","marketType":"WIN","marketTime":"2024-06-27T14:32:00.000Z","suspendTime":"2024-06-27T14:32:00.000Z","bspReconciled":false,"complete":true,"inPlay":false,"crossMatching":false,"runnersVoidable":false,"numberOfActiveRunners":6,"betDelay":0,"status":"OPEN","runners":[{"status":"ACTIVE","sortPriority":1,"id":39100893,"name":"1. Sheriffs Rose"},{"status":"ACTIVE","sortPriority":2,"id":52951653,"name":"2. Grumpy Wazock"},{"status":"ACTIVE","sortPriority":3,"id":51441055,"name":"3. Pounda Prisna"},{"status":"ACTIVE","sortPriority":4,"id":68462283,"name":"4. Tober Glory"},{"status":"ACTIVE","sortPriority":5,"id":70681331,"name":"5. Shelone Luna"},{"status":"ACTIVE","sortPriority":6,"id":56913144,"name":"6. Knotmor Best"}],"regulators":["MR_INT"],"venue":"Kinsley","countryCode":"GB","discountAllowed":true,"timezone":"Europe/London","openDate":"2024-06-27T13:36:00.000Z","version":5994643751,"name":"A5 462m","eventName":"Kinsley 27th Jun"},"rc":[{"spl":[[1.01,1]],"id":56913144},{"atb":[[1.02,22.64]],"id":56913144},{"atl":[[990,0.26]],"id":56913144},{"spn":1.02,"spf":1.0,"id":56913144},{"atb":[[1.02,22.64]],"id":68462283},{"atl":[[990,0.26]],"id":68462283},{"spn":495.51,"spf":"NaN","id":68462283},{"atb":[[1.01,45.29]],"id":70681331},{"atl":[[1000,0.26]],"id":70681331},{"spn":500.5,"spf":"NaN","id":70681331},{"atb":[[1.01,45.29]],"id":39100893},{"atl":[[990,0.26]],"id":39100893},{"spn":495.5,"spf":"NaN","id":39100893},{"atb":[[1.03,15.09]],"id":52951653},{"atl":[[1000,0.26]],"id":52951653},{"spn":500.51,"spf":"NaN","id":52951653},{"atb":[[1.02,22.64]],"id":51441055},{"atl":[[1000,0.26]],"id":51441055},{"spn":500.51,"spf":"NaN","id":51441055}],"con":true,"img":true}]}
{"op":"mcm","clk":"11537954931","pt":1719448682557,"mc":[{"id":"1.230178312","marketDefinition":{"bspMarket":true,"turnInPlayEnabled":false,"persistenceEnabled":false,"marketBaseRate":5.0,"eventId":"33376062","eventTypeId":"4339","numberOfWinners":1,"bettingType":"ODDS","marketType":"WIN","marketTime":"2024-06-27T14:32:00.000Z","suspendTime":"2024-06-27T14:32:00.000Z","bspReconciled":false,"complete":true,"inPlay":false,"crossMatching":false,"runnersVoidable":false,"numberOfActiveRunners":6,"betDelay":0,"status":"OPEN","runners":[{"status":"ACTIVE","sortPriority":1,"id":39100893,"name":"1. Sheriffs Rose"},{"status":"ACTIVE","sortPriority":2,"id":52951653,"name":"2. Grumpy Wazock"},{"status":"ACTIVE","sortPriority":3,"id":51441055,"name":"3. Pounda Prisna"},{"status":"ACTIVE","sortPriority":4,"id":68462283,"name":"4. Tober Glory"},{"status":"ACTIVE","sortPriority":5,"id":70681331,"name":"5. Shelone Luna"},{"status":"ACTIVE","sortPriority":6,"id":56913144,"name":"6. Knotmor Best"}],"regulators":["MR_INT"],"venue":"Kinsley","countryCode":"GB","discountAllowed":true,"timezone":"Europe/London","openDate":"2024-06-27T13:36:00.000Z","version":5994643751,"name":"A5 462m","eventName":"Kinsley 27th Jun"},"rc":[{"spl":[[1.01,1]],"id":56913144},{"atb":[[1.02,22.64]],"id":56913144},{"atl":[[990,0.26]],"id":56913144},{"spn":1.02,"spf":1.0,"id":56913144},{"atb":[[1.02,22.64]],"id":68462283},{"atl":[[990,0.26]],"id":68462283},{"spn":495.51,"spf":"NaN","id":68462283},{"atb":[[1.01,45.28]],"id":70681331},{"atl":[[1000,0.26]],"id":70681331},{"spn":500.5,"spf":"NaN","id":70681331},{"atb":[[1.01,45.28]],"id":39100893},{"atl":[[990,0.26]],"id":39100893},{"spn":495.5,"spf":"NaN","id":39100893},{"atb":[[1.03,15.09]],"id":52951653},{"atl":[[1000,0.26]],"id":52951653},{"spn":500.51,"spf":"NaN","id":52951653},{"atb":[[1.02,22.64]],"id":51441055},{"atl":[[1000,0.26]],"id":51441055},{"spn":500.51,"spf":"NaN","id":51441055}],"con":true,"img":true}]}
{"op":"mcm","clk":"11538170594","pt":1719454082540,"mc":[{"id":"1.230178312","marketDefinition":{"bspMarket":true,"turnInPlayEnabled":false,"persistenceEnabled":false,"marketBaseRate":5.0,"eventId":"33376062","eventTypeId":"4339","numberOfWinners":1,"bettingType":"ODDS","marketType":"WIN","marketTime":"2024-06-27T14:32:00.000Z","suspendTime":"2024-06-27T14:32:00.000Z","bspReconciled":false,"complete":true,"inPlay":false,"crossMatching":false,"runnersVoidable":false,"numberOfActiveRunners":6,"betDelay":0,"status":"OPEN","runners":[{"status":"ACTIVE","sortPriority":1,"id":39100893,"name":"1. Sheriffs Rose"},{"status":"ACTIVE","sortPriority":2,"id":52951653,"name":"2. Grumpy Wazock"},{"status":"ACTIVE","sortPriority":3,"id":51441055,"name":"3. Pounda Prisna"},{"status":"ACTIVE","sortPriority":4,"id":68462283,"name":"4. Tober Glory"},{"status":"ACTIVE","sortPriority":5,"id":70681331,"name":"5. Shelone Luna"},{"status":"ACTIVE","sortPriority":6,"id":56913144,"name":"6. Knotmor Best"}],"regulators":["MR_INT"],"venue":"Kinsley","countryCode":"GB","discountAllowed":true,"timezone":"Europe/London","openDate":"2024-06-27T13:36:00.000Z","version":5994643751,"name":"A5 462m","eventName":"Kinsley 27th Jun"},"rc":[{"spl":[[1.01,1]],"id":56913144},{"atb":[[1.02,22.64]],"id":56913144},{"atl":[[990,0.26]],"id":56913144},{"spn":1.02,"spf":1.0,"id":56913144},{"atb":[[1.02,22.64]],"id":68462283},{"atl":[[990,0.26]],"id":68462283},{"spn":495.51,"spf":"NaN","id":68462283},{"atb":[[1.01,45.29]],"id":70681331},{"atl":[[1000,0.26]],"id":70681331},{"spn":500.5,"spf":"NaN","id":70681331},{"atb":[[1.01,45.29]],"id":39100893},{"atl":[[990,0.26]],"id":39100893},{"spn":495.5,"spf":"NaN","id":39100893},{"atb":[[1.03,15.09]],"id":52951653},{"atl":[[1000,0.26]],"id":52951653},{"spn":500.51,"spf":"NaN","id":52951653},{"atb":[[1.02,22.64]],"id":51441055},{"atl":[[1000,0.26]],"id":51441055},{"spn":500.51,"spf":"NaN","id":51441055}],"con":true,"img":true}]}
{"op":"mcm","clk":"11538368252","pt":1719459482568,"mc":[{"id":"1.230178312","marketDefinition":{"bspMarket":true,"turnInPlayEnabled":false,"persistenceEnabled":false,"marketBaseRate":5.0,"eventId":"33376062","eventTypeId":"4339","numberOfWinners":1,"bettingType":"ODDS","marketType":"WIN","marketTime":"2024-06-27T14:32:00.000Z","suspendTime":"2024-06-27T14:32:00.000Z","bspReconciled":false,"complete":true,"inPlay":false,"crossMatching":false,"runnersVoidable":false,"numberOfActiveRunners":6,"betDelay":0,"status":"OPEN","runners":[{"status":"ACTIVE","sortPriority":1,"id":39100893,"name":"1. Sheriffs Rose"},{"status":"ACTIVE","sortPriority":2,"id":52951653,"name":"2. Grumpy Wazock"},{"status":"ACTIVE","sortPriority":3,"id":51441055,"name":"3. Pounda Prisna"},{"status":"ACTIVE","sortPriority":4,"id":68462283,"name":"4. Tober Glory"},{"status":"ACTIVE","sortPriority":5,"id":70681331,"name":"5. Shelone Luna"},{"status":"ACTIVE","sortPriority":6,"id":56913144,"name":"6. Knotmor Best"}],"regulators":["MR_INT"],"venue":"Kinsley","countryCode":"GB","discountAllowed":true,"timezone":"Europe/London","openDate":"2024-06-27T13:36:00.000Z","version":5994643751,"name":"A5 462m","eventName":"Kinsley 27th Jun"},"rc":[{"spl":[[1.01,1]],"id":56913144},{"atb":[[1.02,22.65]],"id":56913144},{"atl":[[990,0.26]],"id":56913144},{"spn":1.02,"spf":1.0,"id":56913144},{"atb":[[1.02,22.65]],"id":68462283},{"atl":[[990,0.26]],"id":68462283},{"spn":495.51,"spf":"NaN","id":68462283},{"atb":[[1.01,45.3]],"id":70681331},{"atl":[[1000,0.26]],"id":70681331},{"spn":500.5,"spf":"NaN","id":70681331},{"atb":[[1.01,45.3]],"id":39100893},{"atl":[[990,0.26]],"id":39100893},{"spn":495.5,"spf":"NaN","id":39100893},{"atb":[[1.03,15.1]],"id":52951653},{"atl":[[1000,0.26]],"id":52951653},{"spn":500.51,"spf":"NaN","id":52951653},{"atb":[[1.02,22.65]],"id":51441055},{"atl":[[1000,0.26]],"id":51441055},{"spn":500.51,"spf":"NaN","id":51441055}],"con":true,"img":true}]}
{"op":"mcm","clk":"11538595378","pt":1719464882538,"mc":[{"id":"1.230178312","marketDefinition":{"bspMarket":true,"turnInPlayEnabled":false,"persistenceEnabled":false,"marketBaseRate":5.0,"eventId":"33376062","eventTypeId":"4339","numberOfWinners":1,"bettingType":"ODDS","marketType":"WIN","marketTime":"2024-06-27T14:32:00.000Z","suspendTime":"2024-06-27T14:32:00.000Z","bspReconciled":false,"complete":true,"inPlay":false,"crossMatching":false,"runnersVoidable":false,"numberOfActiveRunners":6,"betDelay":0,"status":"OPEN","runners":[{"status":"ACTIVE","sortPriority":1,"id":39100893,"name":"1. Sheriffs Rose"},{"status":"ACTIVE","sortPriority":2,"id":52951653,"name":"2. Grumpy Wazock"},{"status":"ACTIVE","sortPriority":3,"id":51441055,"name":"3. Pounda Prisna"},{"status":"ACTIVE","sortPriority":4,"id":68462283,"name":"4. Tober Glory"},{"status":"ACTIVE","sortPriority":5,"id":70681331,"name":"5. Shelone Luna"},{"status":"ACTIVE","sortPriority":6,"id":56913144,"name":"6. Knotmor Best"}],"regulators":["MR_INT"],"venue":"Kinsley","countryCode":"GB","discountAllowed":true,"timezone":"Europe/London","openDate":"2024-06-27T13:36:00.000Z","version":5994643751,"name":"A5 462m","eventName":"Kinsley 27th Jun"},"rc":[{"spl":[[1.01,1]],"id":56913144},{"atb":[[1.02,22.64]],"id":56913144},{"atl":[[990,0.26]],"id":56913144},{"spn":1.02,"spf":1.0,"id":56913144},{"atb":[[1.02,22.64]],"id":68462283},{"atl":[[990,0.26]],"id":68462283},{"spn":495.51,"spf":"NaN","id":68462283},{"atb":[[1.01,45.29]],"id":70681331},{"atl":[[1000,0.26]],"id":70681331},{"spn":500.5,"spf":"NaN","id":70681331},{"atb":[[1.01,45.29]],"id":39100893},{"atl":[[990,0.26]],"id":39100893},{"spn":495.5,"spf":"NaN","id":39100893},{"atb":[[1.03,15.09]],"id":52951653},{"atl":[[1000,0.26]],"id":52951653},{"spn":500.51,"spf":"NaN","id":52951653},{"atb":[[1.02,22.64]],"id":51441055},{"atl":[[1000,0.26]],"id":51441055},{"spn":500.51,"spf":"NaN","id":51441055}],"con":true,"img":true}]}
{"op":"mcm","clk":"11538669691","pt":1719466335213,"mc":[{"id":"1.230178312","rc":[{"atb":[[1.02,22.64]],"id":56913144},{"atb":[[1.02,22.64]],"id":68462283},{"atl":[[150,4]],"id":68462283},{"spn":75.51,"spf":"NaN","id":68462283},{"atb":[[1.01,45.29]],"id":70681331},{"atb":[[1.01,45.29]],"id":39100893},{"atl":[[150,4]],"id":39100893},{"spn":75.5,"spf":"NaN","id":39100893},{"atb":[[1.03,15.09]],"id":52951653},{"atl":[[150,4]],"id":52951653},{"spn":75.51,"spf":"NaN","id":52951653},{"atb":[[1.02,22.64]],"id":51441055},{"atl":[[150,4]],"id":51441055},{"spn":75.51,"spf":"NaN","id":51441055}],"con":true,"img":false}]}
{"op":"mcm","clk":"11538669698","pt":1719466335317,"mc":[{"id":"1.230178312","rc":[{"atl":[[150,4]],"id":56913144},{"atl":[[150,4]],"id":70681331}],"con":true,"img":false}]}
{"op":"mcm","clk":"11538748518","pt":1719468202906,"mc":[{"id":"1.230178312","rc":[{"atb":[[2.08,13.32]],"id":56913144},{"spn":2.08,"spf":1.0,"id":56913144},{"atb":[[2,9.4]],"id":68462283},{"spn":76.0,"spf":"NaN","id":68462283},{"atb":[[2.06,8.8]],"id":70681331},{"spn":76.03,"spf":"NaN","id":70681331},{"atb":[[2.1,9.86]],"id":39100893},{"spn":76.05,"spf":"NaN","id":39100893},{"atb":[[2.08,11.55]],"id":52951653},{"spn":76.04,"spf":"NaN","id":52951653},{"atb":[[2.1,11.66]],"id":51441055},{"spn":76.05,"spf":"NaN","id":51441055}],"con":true,"img":false}]}
{"op":"mcm","clk":"11538750974","pt":1719468253055,"mc":[{"id":"1.230178312","rc":[{"atb":[[2.12,3.16]],"id":39100893},{"atb":[[2.1,3.16]],"id":52951653}],"con":true,"img":false}]}
{"op":"mcm","clk":"11538750990","pt":1719468253277,"mc":[{"id":"1.230178312","rc":[{"atb":[[2.02,3.16]],"id":68462283}],"con":true,"img":false}]}
{"op":"mcm","clk":"11538751055","pt":1719468254486,"mc":[{"id":"1.230178312","rc":[{"atb":[[2.1,3.16]],"id":56913144}],"con":true,"img":false}]}
{"op":"mcm","clk":"11538751075","pt":1719468254849,"mc":[{"id":"1.230178312","rc":[{"atb":[[2.08,3.16]],"id":70681331}],"con":true,"img":false}]}
{"op":"mcm","clk":"11538751112","pt":1719468255662,"mc":[{"id":"1.230178312","rc":[{"atb":[[2.12,3.16]],"id":51441055}],"con":true,"img":false}]}
{"op":"mcm","clk":"11538752367","pt":1719468281724,"mc":[{"id":"1.230178312","marketDefinition":{"bspMarket":true,"turnInPlayEnabled":false,"persistenceEnabled":false,"marketBaseRate":5.0,"eventId":"33376062","eventTypeId":"4339","numberOfWinners":1,"bettingType":"ODDS","marketType":"WIN","marketTime":"2024-06-27T14:32:00.000Z","suspendTime":"2024-06-27T14:32:00.000Z","bspReconciled":false,"complete":true,"inPlay":false,"crossMatching":true,"runnersVoidable":false,"numberOfActiveRunners":6,"betDelay":0,"status":"OPEN","runners":[{"status":"ACTIVE","sortPriority":1,"id":39100893,"name":"1. Sheriffs Rose"},{"status":"ACTIVE","sortPriority":2,"id":52951653,"name":"2. Grumpy Wazock"},{"status":"ACTIVE","sortPriority":3,"id":51441055,"name":"3. Pounda Prisna"},{"status":"ACTIVE","sortPriority":4,"id":68462283,"name":"4. Tober Glory"},{"status":"ACTIVE","sortPriority":5,"id":70681331,"name":"5. Shelone Luna"},{"status":"ACTIVE","sortPriority":6,"id":56913144,"name":"6. Knotmor Best"}],"regulators":["MR_INT"],"venue":"Kinsley","countryCode":"GB","discountAllowed":true,"timezone":"Europe/London","openDate":"2024-06-27T13:36:00.000Z","version":5994643751,"name":"A5 462m","eventName":"Kinsley 27th Jun"},"rc":[],"con":true,"img":false}]}
{"op":"mcm","clk":"11538753117","pt":1719468294911,"mc":[{"id":"1.230178312","rc":[{"spn":2.1,"spf":1.0,"id":56913144},{"spn":76.01,"spf":"NaN","id":68462283},{"spn":76.04,"spf":"NaN","id":70681331},{"spn":76.06,"spf":"NaN","id":39100893},{"spn":76.05,"spf":"NaN","id":52951653},{"atb":[[2.12,6.55]],"id":51441055},{"spn":76.06,"spf":"NaN","id":51441055}],"con":true,"img":false}]}
{"op":"mcm","clk":"11538753152","pt":1719468295733,"mc":[{"id":"1.230178312","rc":[{"atb":[[2.02,6.55]],"id":68462283}],"con":true,"img":false}]}
{"op":"mcm","clk":"11538753157","pt":1719468295836,"mc":[{"id":"1.230178312","rc":[{"atb":[[2.08,6.55]],"id":70681331}],"con":true,"img":false}]}
{"op":"mcm","clk":"11538753173","pt":1719468296101,"mc":[{"id":"1.230178312","rc":[{"atb":[[2.1,6.55]],"id":52951653}],"con":true,"img":false}]}
{"op":"mcm","clk":"11538753183","pt":1719468296320,"mc":[{"id":"1.230178312","rc":[{"atb":[[2.12,6.55]],"id":39100893}],"con":true,"img":false}]}
{"op":"mcm","clk":"11538753257","pt":1719468297614,"mc":[{"id":"1.230178312","rc":[{"atb":[[2.1,6.55]],"id":56913144}],"con":true,"img":false}]}
{"op":"mcm","clk":"11538905046","pt":1719471465293,"mc":[{"id":"1.230178312","rc":[{"atl":[[990,0.16]],"id":56913144},{"atl":[[990,0.16]],"id":68462283},{"atl":[[1000,0.16]],"id":70681331},{"atl":[[990,0.16]],"id":39100893},{"atl":[[1000,0.16]],"id":52951653},{"atl":[[1000,0.16]],"id":51441055}],"con":true,"img":false}]}
{"op":"mcm","clk":"11538937140","pt":1719472046807,"mc":[{"id":"1.230178312","rc":[{"atb":[[1.02,22.63],[2.1,6.54],[2.08,13.32]],"id":56913144},{"atl":[[990,0.16]],"id":56913144},{"atb":[[2,9.39],[2.02,6.54],[1.02,22.63]],"id":68462283},{"atl":[[990,0.16]],"id":68462283},{"atb":[[1.01,45.26],[2.06,8.79],[2.08,6.54]],"id":70681331},{"atl":[[1000,0.16]],"id":70681331},{"atb":[[1.01,45.26],[2.12,6.54],[2.1,9.86]],"id":39100893},{"atl":[[990,0.16]],"id":39100893},{"atb":[[1.03,15.08],[2.1,6.54],[2.08,11.54]],"id":52951653},{"atl":[[32,0.6],[1000,0.16]],"id":52951653},{"spn":17.05,"spf":"NaN","id":52951653},{"atb":[[1.02,22.63],[2.12,6.54],[2.1,11.65]],"id":51441055},{"atl":[[1000,0.16]],"id":51441055}],"con":true,"img":false}]}
{"op":"mcm","clk":"11538940414","pt":1719472108241,"mc":[{"id":"1.230178312","rc":[{"atb":[[2.08,0]],"id":56913144},{"atb":[[2,0]],"id":68462283},{"atb":[[2.06,0]],"id":70681331},{"atb":[[2.1,0]],"id":39100893},{"atb":[[2.08,0]],"id":52951653},{"atb":[[2.1,0]],"id":51441055}],"con":true,"img":false}]}
{"op":"mcm","clk":"11538940422","pt":1719472108343,"mc":[{"id":"1.230178312","rc":[{"atb":[[2.12,13.32]],"id":56913144},{"atb":[[2.04,9.39]],"id":68462283},{"atb":[[2.1,8.79]],"id":70681331},{"atb":[[2.14,9.86]],"id":39100893},{"atb":[[2.12,11.54]],"id":52951653},{"atb":[[2.14,11.65]],"id":51441055}],"con":true,"img":false}]}
{"op":"mcm","clk":"11538944154","pt":1719472167735,"mc":[{"id":"1.230178312","rc":[{"atb":[[2.12,3.38]],"id":39100893}],"con":true,"img":false}]}
{"op":"mcm","clk":"11538944170","pt":1719472168041,"mc":[{"id":"1.230178312","rc":[{"atb":[[2.1,3.38]],"id":56913144}],"con":true,"img":false}]}
{"op":"mcm","clk":"11538944183","pt":1719472168346,"mc":[{"id":"1.230178312","rc":[{"spn":2.12,"spf":1.0,"id":56913144},{"spn":76.02,"spf":"NaN","id":68462283},{"spn":76.05,"spf":"NaN","id":70681331},{"spn":76.07,"spf":"NaN","id":39100893},{"atb":[[2.1,3.38]],"id":52951653},{"spn":17.06,"spf":"NaN","id":52951653},{"spn":76.07,"spf":"NaN","id":51441055}],"con":true,"img":false}]}
{"op":"mcm","clk":"11538944197","pt":1719472168557,"mc":[{"id":"1.230178312","rc":[{"atb":[[2.12,3.38]],"id":51441055}],"con":true,"img":false}]}
{"op":"mcm","clk":"11538944213","pt":1719472168813,"mc":[{"id":"1.230178312","rc":[{"atb":[[2.08,3.38]],"id":70681331}],"con":true,"img":false}]}
{"op":"mcm","clk":"11538944271","pt":1719472169832,"mc":[{"id":"1.230178312","rc":[{"atb":[[2.02,3.38]],"id":68462283}],"con":true,"img":false}]}
{"op":"mcm","clk":"11538944297","pt":1719472170345,"mc":[{"id":"1.230178312","rc":[{"atb":[[2.12,3.16]],"id":70681331}],"con":true,"img":false}]}
{"op":"mcm","clk":"11538944322","pt":1719472170755,"mc":[{"id":"1.230178312","rc":[{"atb":[[2.06,3.16]],"id":68462283}],"con":true,"img":false}]}
{"op":"mcm","clk":"11538944346","pt":1719472171060,"mc":[{"id":"1.230178312","rc":[{"atb":[[2.16,3.16]],"id":51441055}],"con":true,"img":false}]}
{"op":"mcm","clk":"11538944426","pt":1719472172436,"mc":[{"id":"1.230178312","rc":[{"atb":[[2.14,3.16]],"id":56913144}],"con":true,"img":false}]}
{"op":"mcm","clk":"11538944431","pt":1719472172539,"mc":[{"id":"1.230178312","rc":[{"atb":[[2.16,3.16]],"id":39100893}],"con":true,"img":false}]}
{"op":"mcm","clk":"11538944593","pt":1719472175042,"mc":[{"id":"1.230178312","rc":[{"atb":[[2.14,3.16]],"id":52951653}],"con":true,"img":false}]}
{"op":"mcm","clk":"11538945132","pt":1719472183864,"mc":[{"id":"1.230178312","rc":[{"atb":[[2.12,0]],"id":39100893}],"con":true,"img":false}]}
{"op":"mcm","clk":"11538945141","pt":1719472184071,"mc":[{"id":"1.230178312","rc":[{"atb":[[2.08,0]],"id":70681331}],"con":true,"img":false}]}
{"op":"mcm","clk":"11538945164","pt":1719472184586,"mc":[{"id":"1.230178312","rc":[{"atb":[[2.12,0]],"id":51441055}],"con":true,"img":false}]}
{"op":"mcm","clk":"11538945295","pt":1719472186791,"mc":[{"id":"1.230178312","rc":[{"atb":[[2.1,0]],"id":52951653}],"con":true,"img":false}]}
{"op":"mcm","clk":"11538945353","pt":1719472187870,"mc":[{"id":"1.230178312","rc":[{"atb":[[2.1,0]],"id":56913144}],"con":true,"img":false}]}
{"op":"mcm","clk":"11538945466","pt":1719472189872,"mc":[{"id":"1.230178312","rc":[{"atb":[[2.02,0]],"id":68462283}],"con":true,"img":false}]}
{"op":"mcm","clk":"11538946317","pt":1719472203198,"mc":[{"id":"1.230178312","rc":[{"atb":[[2.16,6.54]],"id":51441055}],"con":true,"img":false}]}
{"op":"mcm","clk":"11538946396","pt":1719472204482,"mc":[{"id":"1.230178312","rc":[{"atb":[[2.12,6.54]],"id":70681331}],"con":true,"img":false}]}
{"op":"mcm","clk":"11538946419","pt":1719472204788,"mc":[{"id":"1.230178312","rc":[{"atb":[[2.16,6.54]],"id":39100893}],"con":true,"img":false}]}
{"op":"mcm","clk":"11538946468","pt":1719472205872,"mc":[{"id":"1.230178312","rc":[{"atb":[[2.14,6.54]],"id":52951653}],"con":true,"img":false}]}
{"op":"mcm","clk":"11538946587","pt":1719472207684,"mc":[{"id":"1.230178312","rc":[{"atb":[[2.14,6.54]],"id":56913144}],"con":true,"img":false}]}
{"op":"mcm","clk":"11538946796","pt":1719472210917,"mc":[{"id":"1.230178312","rc":[{"atb":[[2.06,6.54]],"id":68462283}],"con":true,"img":false}]}
{"op":"mcm","clk":"11539122525","pt":1719475682545,"mc":[{"id":"1.230178312","marketDefinition":{"bspMarket":true,"turnInPlayEnabled":false,"persistenceEnabled":false,"marketBaseRate":5.0,"eventId":"33376062","eventTypeId":"4339","numberOfWinners":1,"bettingType":"ODDS","marketType":"WIN","marketTime":"2024-06-27T14:32:00.000Z","suspendTime":"2024-06-27T14:32:00.000Z","bspReconciled":false,"complete":true,"inPlay":false,"crossMatching":true,"runnersVoidable":false,"numberOfActiveRunners":6,"betDelay":0,"status":"OPEN","runners":[{"status":"ACTIVE","sortPriority":1,"id":39100893,"name":"1. Sheriffs Rose"},{"status":"ACTIVE","sortPriority":2,"id":52951653,"name":"2. Grumpy Wazock"},{"status":"ACTIVE","sortPriority":3,"id":51441055,"name":"3. Pounda Prisna"},{"status":"ACTIVE","sortPriority":4,"id":68462283,"name":"4. Tober Glory"},{"status":"ACTIVE","sortPriority":5,"id":70681331,"name":"5. Shelone Luna"},{"status":"ACTIVE","sortPriority":6,"id":56913144,"name":"6. Knotmor Best"}],"regulators":["MR_INT"],"venue":"Kinsley","countryCode":"GB","discountAllowed":true,"timezone":"Europe/London","openDate":"2024-06-27T13:36:00.000Z","version":5994643751,"name":"A5 462m","eventName":"Kinsley 27th Jun"},"rc":[{"spl":[[1.01,1]],"id":56913144},{"atb":[[1.02,22.64],[2.12,13.32],[2.14,6.55]],"id":56913144},{"atl":[[150,4],[990,0.16]],"id":56913144},{"spn":2.14,"spf":1.0,"id":56913144},{"atb":[[2.06,6.55],[2.04,9.4],[1.02,22.64]],"id":68462283},{"atl":[[150,4],[990,0.16]],"id":68462283},{"spn":76.03,"spf":"NaN","id":68462283},{"atb":[[1.01,45.28],[2.12,6.55],[2.1,8.79]],"id":70681331},{"atl":[[150,4],[1000,0.16]],"id":70681331},{"spn":76.06,"spf":"NaN","id":70681331},{"atb":[[1.01,45.28],[2.16,6.55],[2.14,9.86]],"id":39100893},{"atl":[[150,4],[990,0.16]],"id":39100893},{"spn":76.08,"spf":"NaN","id":39100893},{"atb":[[1.03,15.09],[2.12,11.54],[2.14,6.55]],"id":52951653},{"atl":[[32,0.6],[150,4],[1000,0.16]],"id":52951653},{"spn":17.07,"spf":"NaN","id":52951653},{"atb":[[1.02,22.64],[2.16,6.55],[2.14,11.65]],"id":51441055},{"atl":[[150,4],[1000,0.16]],"id":51441055},{"spn":76.08,"spf":"NaN","id":51441055}],"con":true,"img":true}]}
{"op":"mcm","clk":"11539127732","pt":1719475708480,"mc":[{"id":"1.230178312","rc":[{"atb":[[1.02,22.64],[2.12,0],[2.14,6.55]],"id":56913144},{"spn":2.14,"spf":1.0,"id":56913144},{"atb":[[2.06,6.55],[2.04,0],[1.02,22.64]],"id":68462283},{"spn":76.03,"spf":"NaN","id":68462283},{"atb":[[1.01,45.28],[2.12,6.55],[2.1,0]],"id":70681331},{"spn":76.06,"spf":"NaN","id":70681331},{"atb":[[1.01,45.28],[2.16,6.55],[2.14,0]],"id":39100893},{"spn":76.08,"spf":"NaN","id":39100893},{"atb":[[1.03,15.09],[2.12,0],[2.14,6.55]],"id":52951653},{"spn":17.07,"spf":"NaN","id":52951653},{"atb":[[1.02,22.64],[2.16,6.55],[2.14,0]],"id":51441055},{"spn":76.08,"spf":"NaN","id":51441055}],"con":true,"img":false}]}
{"op":"mcm","clk":"11539127736","pt":1719475708580,"mc":[{"id":"1.230178312","rc":[{"atb":[[2.16,13.32]],"id":56913144},{"atb":[[2.08,9.4]],"id":68462283},{"atb":[[2.14,8.79]],"id":70681331},{"atb":[[2.18,9.86]],"id":39100893},{"atb":[[2.16,11.54]],"id":52951653},{"atb":[[2.18,11.65]],"id":51441055}],"con":true,"img":false}]}
{"op":"mcm","clk":"11539128121","pt":1719475713692,"mc":[{"id":"1.230178312","rc":[{"atb":[[2.12,3.38]],"id":70681331}],"con":true,"img":false}]}
{"op":"mcm","clk":"11539128183","pt":1719475714617,"mc":[{"id":"1.230178312","rc":[{"atb":[[2.14,3.38]],"id":52951653}],"con":true,"img":false}]}
{"op":"mcm","clk":"11539128234","pt":1719475715390,"mc":[{"id":"1.230178312","rc":[{"atb":[[2.16,3.16]],"id":70681331}],"con":true,"img":false}]}
{"op":"mcm","clk":"11539128329","pt":1719475716009,"mc":[{"id":"1.230178312","rc":[{"atb":[[2.18,3.16]],"id":52951653}],"con":true,"img":false}]}
{"op":"mcm","clk":"11539128340","pt":1719475716210,"mc":[{"id":"1.230178312","rc":[{"atb":[[2.06,3.38]],"id":68462283}],"con":true,"img":false}]}
{"op":"mcm","clk":"11539128387","pt":1719475717083,"mc":[{"id":"1.230178312","rc":[{"atb":[[2.16,3.38]],"id":39100893}],"con":true,"img":false}]}
{"op":"mcm","clk":"11539128408","pt":1719475717543,"mc":[{"id":"1.230178312","rc":[{"atb":[[2.1,3.16]],"id":68462283}],"con":true,"img":false}]}
{"op":"mcm","clk":"11539128492","pt":1719475718930,"mc":[{"id":"1.230178312","rc":[{"atb":[[2.14,3.38]],"id":56913144}],"con":true,"img":false}]}
{"op":"mcm","clk":"11539128584","pt":1719475720521,"mc":[{"id":"1.230178312","rc":[{"atb":[[2.2,3.16]],"id":39100893}],"con":true,"img":false}]}
{"op":"mcm","clk":"11539128655","pt":1719475721711,"mc":[{"id":"1.230178312","rc":[{"atb":[[2.18,3.16]],"id":56913144}],"con":true,"img":false}]}
{"op":"mcm","clk":"11539128767","pt":1719475723421,"mc":[{"id":"1.230178312","rc":[{"atb":[[2.16,3.38]],"id":51441055}],"con":true,"img":false}]}
{"op":"mcm","clk":"11539128779","pt":1719475723626,"mc":[{"id":"1.230178312","rc":[{"atb":[[2.2,3.16]],"id":51441055}],"con":true,"img":false}]}
{"op":"mcm","clk":"11539135158","pt":1719475823404,"mc":[{"id":"1.230178312","rc":[{"spn":2.18,"spf":1.0,"id":56913144},{"spn":76.05,"spf":"NaN","id":68462283},{"spn":76.08,"spf":"NaN","id":70681331},{"spn":76.1,"spf":"NaN","id":39100893},{"atb":[[2.14,0]],"id":52951653},{"spn":17.09,"spf":"NaN","id":52951653},{"spn":76.1,"spf":"NaN","id":51441055}],"con":true,"img":false}]}
{"op":"mcm","clk":"11539135167","pt":1719475823509,"mc":[{"id":"1.230178312","rc":[{"atb":[[2.16,0]],"id":39100893}],"con":true,"img":false}]}
{"op":"mcm","clk":"11539135186","pt":1719475823820,"mc":[{"id":"1.230178312","rc":[{"atb":[[2.06,0]],"id":68462283},{"atb":[[2.12,0]],"id":70681331}],"con":true,"img":false}]}
{"op":"mcm","clk":"11539135206","pt":1719475824127,"mc":[{"id":"1.230178312","rc":[{"atb":[[2.14,0]],"id":56913144}],"con":true,"img":false}]}
{"op":"mcm","clk":"11539135243","pt":1719475824635,"mc":[{"id":"1.230178312","rc":[{"atb":[[2.16,0]],"id":51441055}],"con":true,"img":false}]}
{"op":"mcm","clk":"11539135471","pt":1719475827412,"mc":[{"id":"1.230178312","rc":[{"atb":[[2.18,6.55]],"id":52951653}],"con":true,"img":false}]}
{"op":"mcm","clk":"11539135512","pt":1719475828031,"mc":[{"id":"1.230178312","rc":[{"atb":[[2.2,6.55]],"id":51441055}],"con":true,"img":false}]}
{"op":"mcm","clk":"11539135534","pt":1719475828438,"mc":[{"id":"1.230178312","rc":[{"atb":[[2.2,6.55]],"id":39100893}],"con":true,"img":false}]}
{"op":"mcm","clk":"11539135605","pt":1719475829519,"mc":[{"id":"1.230178312","rc":[{"atb":[[2.18,6.55]],"id":56913144}],"con":true,"img":false}]}
{"op":"mcm","clk":"11539135611","pt":1719475829620,"mc":[{"id":"1.230178312","rc":[{"atb":[[2.16,6.55]],"id":70681331}],"con":true,"img":false}]}
{"op":"mcm","clk":"11539135653","pt":1719475830338,"mc":[{"id":"1.230178312","rc":[{"atb":[[2.1,6.55]],"id":68462283}],"con":true,"img":false}]}
{"op":"mcm","clk":"11539210087","pt":1719477171692,"mc":[{"id":"1.230178312","rc":[{"atb":[[2.22,2]],"id":39100893},{"spn":76.11,"spf":"NaN","id":39100893}],"con":true,"img":false}]}
{"op":"mcm","clk":"11539341208","pt":1719479307456,"mc":[{"id":"1.230178312","rc":[{"atb":[[1.02,22.63],[2.18,6.54],[2.16,0]],"id":56913144},{"atb":[[1.02,22.63],[2.1,6.54],[2.08,0]],"id":68462283},{"atb":[[1.01,45.27],[2.16,6.54],[2.14,0]],"id":70681331},{"atb":[[1.01,45.27],[2.18,0],[2.2,6.54]],"id":39100893},{"atb":[[1.03,15.09],[2.18,6.54],[2.16,0]],"id":52951653},{"atb":[[1.02,22.63],[2.18,0],[2.2,6.54]],"id":51441055}],"con":true,"img":false}]}
{"op":"mcm","clk":"11539341216","pt":1719479307559,"mc":[{"id":"1.230178312","rc":[{"atb":[[2.2,13.32]],"id":56913144},{"atb":[[2.12,9.39]],"id":68462283},{"atb":[[2.18,8.79]],"id":70681331},{"atb":[[2.22,11.86]],"id":39100893},{"atb":[[2.2,11.54]],"id":52951653},{"atb":[[2.22,11.65]],"id":51441055}],"con":true,"img":false}]}
{"op":"mcm","clk":"11539347323","pt":1719479404881,"mc":[{"id":"1.230178312","rc":[{"spn":2.2,"spf":1.0,"id":56913144},{"spn":76.06,"spf":"NaN","id":68462283},{"spn":76.09,"spf":"NaN","id":70681331},{"atb":[[2.2,3.38]],"id":39100893},{"spn":17.1,"spf":"NaN","id":52951653},{"spn":76.11,"spf":"NaN","id":51441055}],"con":true,"img":false}]}
{"op":"mcm","clk":"11539347334","pt":1719479405085,"mc":[{"id":"1.230178312","rc":[{"atb":[[2.16,3.38]],"id":70681331}],"con":true,"img":false}]}
{"op":"mcm","clk":"11539347430","pt":1719479406486,"mc":[{"id":"1.230178312","rc":[{"atb":[[2.2,3.38]],"id":51441055}],"con":true,"img":false}]}
{"op":"mcm","clk":"11539347553","pt":1719479408083,"mc":[{"id":"1.230178312","rc":[{"atb":[[2.1,3.38]],"id":68462283}],"con":true,"img":false}]}
{"op":"mcm","clk":"11539347657","pt":1719479409789,"mc":[{"id":"1.230178312","rc":[{"atb":[[2.18,3.38]],"id":56913144}],"con":true,"img":false}]}
{"op":"mcm","clk":"11539347709","pt":1719479410609,"mc":[{"id":"1.230178312","rc":[{"atb":[[2.18,3.38]],"id":52951653}],"con":true,"img":false}]}
{"op":"mcm","clk":"11539350741","pt":1719479457324,"mc":[{"id":"1.230178312","rc":[{"atb":[[2.18,0]],"id":56913144},{"atb":[[2.1,0]],"id":68462283},{"atb":[[2.16,0]],"id":70681331},{"atb":[[2.2,0]],"id":39100893},{"atb":[[2.18,0]],"id":52951653},{"atb":[[2.2,0]],"id":51441055}],"con":true,"img":false}]}
{"op":"mcm","clk":"11539368393","pt":1719479715672,"mc":[{"id":"1.230178312","rc":[{"atb":[[2.22,3.16]],"id":52951653},{"spn":17.11,"spf":"NaN","id":52951653},{"atb":[[2.24,3.16]],"id":51441055},{"spn":76.12,"spf":"NaN","id":51441055}],"con":true,"img":false}]}
{"op":"mcm","clk":"11539368445","pt":1719479716290,"mc":[{"id":"1.230178312","rc":[{"atb":[[2.24,3.16]],"id":39100893}],"con":true,"img":false}]}
{"op":"mcm","clk":"11539368489","pt":1719479716906,"mc":[{"id":"1.230178312","rc":[{"atb":[[2.14,3.16]],"id":68462283}],"con":true,"img":false}]}
{"op":"mcm","clk":"11539368507","pt":1719479717215,"mc":[{"id":"1.230178312","rc":[{"atb":[[2.2,3.16]],"id":70681331}],"con":true,"img":false}]}
{"op":"mcm","clk":"11539368583","pt":1719479718194,"mc":[{"id":"1.230178312","rc":[{"atb":[[2.22,3.16]],"id":56913144}],"con":true,"img":false}]}
{"op":"mcm","clk":"11539370004","pt":1719479736207,"mc":[{"id":"1.230178312","rc":[{"atb":[[2.24,6.54]],"id":39100893}],"con":true,"img":false}]}
{"op":"mcm","clk":"11539370009","pt":1719479736305,"mc":[{"id":"1.230178312","rc":[{"atb":[[2.22,6.54]],"id":52951653}],"con":true,"img":false}]}
{"op":"mcm","clk":"11539370023","pt":1719479736513,"mc":[{"id":"1.230178312","rc":[{"atb":[[2.24,6.54]],"id":51441055}],"con":true,"img":false}]}
{"op":"mcm","clk":"11539370029","pt":1719479736611,"mc":[{"id":"1.230178312","rc":[{"atb":[[2.22,6.54]],"id":56913144}],"con":true,"img":false}]}
{"op":"mcm","clk":"11539370046","pt":1719479736923,"mc":[{"id":"1.230178312","rc":[{"atb":[[2.14,6.54]],"id":68462283}],"con":true,"img":false}]}
{"op":"mcm","clk":"11539370118","pt":1719479738139,"mc":[{"id":"1.230178312","rc":[{"atb":[[2.2,6.54]],"id":70681331}],"con":true,"img":false}]}
{"op":"mcm","clk":"11539417408","pt":1719480721708,"mc":[{"id":"1.230178312","rc":[{"spn":2.22,"spf":1.0,"id":56913144},{"atl":[[25,8]],"id":68462283},{"spn":13.57,"spf":"NaN","id":68462283},{"spn":76.1,"spf":"NaN","id":70681331},{"spn":76.12,"spf":"NaN","id":39100893},{"atl":[[28,8]],"id":52951653},{"spn":15.11,"spf":"NaN","id":52951653},{"atl":[[32,8]],"id":51441055},{"spn":17.12,"spf":"NaN","id":51441055}],"con":true,"img":false}]}
{"op":"mcm","clk":"11539417414","pt":1719480721812,"mc":[{"id":"1.230178312","rc":[{"atl":[[32,8],[55,12]],"id":56913144},{"atl":[[42,12]],"id":68462283},{"atl":[[48,12]],"id":52951653},{"atl":[[55,12]],"id":51441055}],"con":true,"img":false}]}
{"op":"mcm","clk":"11539545189","pt":1719482907071,"mc":[{"id":"1.230178312","rc":[{"atb":[[2.22,6.54],[1.02,22.63],[2.2,0]],"id":56913144},{"atb":[[1.02,22.63],[2.12,0],[2.14,6.54]],"id":68462283},{"atb":[[1.01,45.26],[2.18,0],[2.2,6.54]],"id":70681331},{"atb":[[2.24,6.54],[1.01,45.26],[2.22,2]],"id":39100893},{"atb":[[1.03,15.08],[2.22,6.54],[2.2,0]],"id":52951653},{"atb":[[2.24,6.54],[2.22,0],[1.02,22.63]],"id":51441055}],"con":true,"img":false}]}
{"op":"mcm","clk":"11539545195","pt":1719482907172,"mc":[{"id":"1.230178312","rc":[{"atb":[[2.24,13.32]],"id":56913144},{"atb":[[2.16,9.39]],"id":68462283},{"atb":[[2.22,8.79]],"id":70681331},{"atb":[[2.26,9.86]],"id":39100893},{"atb":[[2.24,11.54]],"id":52951653},{"atb":[[2.26,11.65]],"id":51441055}],"con":true,"img":false}]}
{"op":"mcm","clk":"11539550116","pt":1719482982929,"mc":[{"id":"1.230178312","rc":[{"atb":[[2.22,3.16]],"id":56913144},{"spn":2.24,"spf":1.0,"id":56913144},{"spn":13.58,"spf":"NaN","id":68462283},{"spn":76.11,"spf":"NaN","id":70681331},{"spn":76.13,"spf":"NaN","id":39100893},{"spn":15.12,"spf":"NaN","id":52951653},{"spn":17.13,"spf":"NaN","id":51441055}],"con":true,"img":false}]}
{"op":"mcm","clk":"11539550131","pt":1719482983189,"mc":[{"id":"1.230178312","rc":[{"atb":[[2.2,3.16]],"id":70681331}],"con":true,"img":false}]}
{"op":"mcm","clk":"11539550192","pt":1719482983969,"mc":[{"id":"1.230178312","rc":[{"atb":[[2.24,3.16]],"id":51441055}],"con":true,"img":false}]}
{"op":"mcm","clk":"11539550212","pt":1719482984228,"mc":[{"id":"1.230178312","rc":[{"atb":[[2.14,3.16]],"id":68462283}],"con":true,"img":false}]}
{"op":"mcm","clk":"11539550233","pt":1719482984540,"mc":[{"id":"1.230178312","rc":[{"atb":[[2.24,3.16]],"id":39100893}],"con":true,"img":false}]}
{"op":"mcm","clk":"11539550251","pt":1719482984950,"mc":[{"id":"1.230178312","rc":[{"atb":[[2.22,3.16]],"id":52951653}],"con":true,"img":false}]}
{"op":"mcm","clk":"11539550303","pt":1719482985836,"mc":[{"id":"1.230178312","rc":[{"atb":[[2.26,3.38]],"id":56913144}],"con":true,"img":false}]}
{"op":"mcm","clk":"11539550323","pt":1719482986141,"mc":[{"id":"1.230178312","rc":[{"atb":[[2.24,3.38]],"id":70681331}],"con":true,"img":false}]}
{"op":"mcm","clk":"11539550352","pt":1719482986452,"mc":[{"id":"1.230178312","rc":[{"atb":[[2.28,3.38]],"id":51441055}],"con":true,"img":false}]}
{"op":"mcm","clk":"11539550361","pt":1719482986553,"mc":[{"id":"1.230178312","rc":[{"atb":[[2.26,3.38]],"id":52951653}],"con":true,"img":false}]}
{"op":"mcm","clk":"11539550382","pt":1719482986763,"mc":[{"id":"1.230178312","rc":[{"atb":[[2.18,3.38]],"id":68462283}],"con":true,"img":false}]}
{"op":"mcm","clk":"11539550406","pt":1719482987071,"mc":[{"id":"1.230178312","rc":[{"atb":[[2.28,3.38]],"id":39100893}],"con":true,"img":false}]}
{"op":"mcm","clk":"11539553471","pt":1719483030196,"mc":[{"id":"1.230178312","rc":[{"atb":[[2.22,0]],"id":56913144},{"atb":[[2.14,0]],"id":68462283},{"atb":[[2.2,0]],"id":70681331},{"atb":[[2.24,0]],"id":39100893},{"atb":[[2.22,0]],"id":52951653},{"atb":[[2.24,0]],"id":51441055}],"con":true,"img":false}]}
{"op":"mcm","clk":"11539573571","pt":1719483329481,"mc":[{"id":"1.230178312","rc":[{"spn":2.26,"spf":1.0,"id":56913144},{"atb":[[2.18,6.54]],"id":68462283},{"spn":13.59,"spf":"NaN","id":68462283},{"spn":76.12,"spf":"NaN","id":70681331},{"spn":76.14,"spf":"NaN","id":39100893},{"spn":15.13,"spf":"NaN","id":52951653},{"spn":17.14,"spf":"NaN","id":51441055}],"con":true,"img":false}]}
{"op":"mcm","clk":"11539573589","pt":1719483329642,"mc":[{"id":"1.230178312","rc":[{"atb":[[2.26,6.54]],"id":56913144}],"con":true,"img":false}]}
{"op":"mcm","clk":"11539573614","pt":1719483329951,"mc":[{"id":"1.230178312","rc":[{"atb":[[2.24,6.54]],"id":70681331}],"con":true,"img":false}]}
{"op":"mcm","clk":"11539573627","pt":1719483330152,"mc":[{"id":"1.230178312","rc":[{"atb":[[2.26,6.54]],"id":52951653}],"con":true,"img":false}]}
{"op":"mcm","clk":"11539573634","pt":1719483330257,"mc":[{"id":"1.230178312","rc":[{"atb":[[2.28,6.54]],"id":51441055}],"con":true,"img":false}]}
{"op":"mcm","clk":"11539573687","pt":1719483331079,"mc":[{"id":"1.230178312","rc":[{"atb":[[2.28,6.54]],"id":39100893}],"con":true,"img":false}]}
{"op":"mcm","clk":"11539622312","pt":1719483951168,"mc":[{"id":"1.230178312","rc":[{"spl":[[1.01,0.71]],"id":51441055},{"spn":2.28,"spf":1.0,"id":51441055}],"con":true,"img":false}]}
{"op":"mcm","clk":"11539647299","pt":1719484322506,"mc":[{"id":"1.230178312","rc":[{"atb":[[3.65,1]],"id":56913144},{"spn":3.65,"spf":1.0,"id":56913144},{"atb":[[5,1]],"id":68462283},{"spn":15.0,"spf":"NaN","id":68462283},{"atb":[[5,1]],"id":70681331},{"spn":77.5,"spf":"NaN","id":70681331},{"atb":[[5,1]],"id":39100893},{"spn":77.5,"spf":"NaN","id":39100893},{"atb":[[5,1]],"id":52951653},{"spn":16.5,"spf":"NaN","id":52951653},{"atb":[[5,1]],"id":51441055},{"spn":5.0,"spf":1.0,"id":51441055}],"con":true,"img":false}]}
{"op":"mcm","clk":"11539691178","pt":1719484915976,"mc":[{"id":"1.230178312","rc":[{"atb":[[3.1,6]],"id":56913144},{"atb":[[3.1,6]],"id":68462283},{"atb":[[3.55,6]],"id":70681331},{"atb":[[3.1,6]],"id":39100893},{"atb":[[2.86,6]],"id":52951653}],"con":true,"img":false}]}
{"op":"mcm","clk":"11539691186","pt":1719484916080,"mc":[{"id":"1.230178312","rc":[{"atb":[[3.3,6]],"id":51441055}],"con":true,"img":false}]}
{"op":"mcm","clk":"11539691670","pt":1719484922186,"mc":[{"id":"1.230178312","rc":[{"atb":[[2.26,3.38]],"id":52951653}],"con":true,"img":false}]}
{"op":"mcm","clk":"11539691685","pt":1719484922391,"mc":[{"id":"1.230178312","rc":[{"atb":[[2.26,3.38]],"id":56913144},{"atb":[[2.18,3.38]],"id":68462283},{"atb":[[2.24,3.38]],"id":70681331},{"atb":[[2.28,3.38]],"id":39100893},{"atb":[[2.28,3.38]],"id":51441055}],"con":true,"img":false}]}
{"op":"mcm","clk":"11539691698","pt":1719484922596,"mc":[{"id":"1.230178312","rc":[{"atb":[[2.88,3.16]],"id":52951653}],"con":true,"img":false}]}
{"op":"mcm","clk":"11539692699","pt":1719484935204,"mc":[{"id":"1.230178312","rc":[{"atb":[[2.26,0]],"id":52951653}],"con":true,"img":false}]}
{"op":"mcm","clk":"11539692726","pt":1719484935616,"mc":[{"id":"1.230178312","rc":[{"atb":[[2.26,0]],"id":56913144},{"atb":[[2.18,0]],"id":68462283},{"atb":[[2.24,0]],"id":70681331},{"atb":[[2.28,0]],"id":39100893},{"atb":[[2.28,0]],"id":51441055}],"con":true,"img":false}]}
{"op":"mcm","clk":"11539692733","pt":1719484935721,"mc":[{"id":"1.230178312","rc":[{"atb":[[2.88,6.54]],"id":52951653}],"con":true,"img":false}]}
{"op":"mcm","clk":"11539722741","pt":1719485300039,"mc":[{"id":"1.230178312","rc":[{"atb":[[2.12,89.29]],"id":70681331},{"atb":[[2.12,89.29]],"id":51441055}],"con":true,"img":false}]}
{"op":"mcm","clk":"11539722751","pt":1719485300190,"mc":[{"id":"1.230178312","rc":[{"atb":[[1.51,196.08]],"id":56913144},{"atb":[[1.51,196.08]],"id":68462283},{"atb":[[1.51,196.08]],"id":70681331},{"atb":[[1.51,196.08]],"id":39100893},{"atb":[[1.51,196.08]],"id":52951653},{"atb":[[1.51,196.08]],"id":51441055}],"con":true,"img":false}]}
{"op":"mcm","clk":"11539810798","pt":1719486482533,"mc":[{"id":"1.230178312","marketDefinition":{"bspMarket":true,"turnInPlayEnabled":false,"persistenceEnabled":false,"marketBaseRate":5.0,"eventId":"33376062","eventTypeId":"4339","numberOfWinners":1,"bettingType":"ODDS","marketType":"WIN","marketTime":"2024-06-27T14:32:00.000Z","suspendTime":"2024-06-27T14:32:00.000Z","bspReconciled":false,"complete":true,"inPlay":false,"crossMatching":true,"runnersVoidable":false,"numberOfActiveRunners":6,"betDelay":0,"status":"OPEN","runners":[{"status":"ACTIVE","sortPriority":1,"id":39100893,"name":"1. Sheriffs Rose"},{"status":"ACTIVE","sortPriority":2,"id":52951653,"name":"2. Grumpy Wazock"},{"status":"ACTIVE","sortPriority":3,"id":51441055,"name":"3. Pounda Prisna"},{"status":"ACTIVE","sortPriority":4,"id":68462283,"name":"4. Tober Glory"},{"status":"ACTIVE","sortPriority":5,"id":70681331,"name":"5. Shelone Luna"},{"status":"ACTIVE","sortPriority":6,"id":56913144,"name":"6. Knotmor Best"}],"regulators":["MR_INT"],"venue":"Kinsley","countryCode":"GB","discountAllowed":true,"timezone":"Europe/London","openDate":"2024-06-27T13:36:00.000Z","version":5994643751,"name":"A5 462m","eventName":"Kinsley 27th Jun"},"rc":[{"spl":[[1.01,1]],"id":56913144},{"atb":[[2.24,13.32],[3.1,6],[1.02,22.63],[1.51,196.08],[3.65,1]],"id":56913144},{"atl":[[32,8],[150,4],[55,12],[990,0.16]],"id":56913144},{"spn":3.65,"spf":1.0,"id":56913144},{"atb":[[5,1],[3.1,6],[1.02,22.63],[1.51,196.08],[2.16,9.39]],"id":68462283},{"atl":[[150,4],[42,12],[25,8],[990,0.16]],"id":68462283},{"spn":15.0,"spf":"NaN","id":68462283},{"atb":[[1.01,45.27],[5,1],[2.22,8.79],[2.12,89.29],[3.55,6],[1.51,196.08]],"id":70681331},{"atl":[[150,4],[1000,0.16]],"id":70681331},{"spn":77.5,"spf":"NaN","id":70681331},{"atb":[[1.01,45.27],[5,1],[3.1,6],[2.22,2],[2.26,9.86],[1.51,196.08]],"id":39100893},{"atl":[[150,4],[990,0.16]],"id":39100893},{"spn":77.5,"spf":"NaN","id":39100893},{"atb":[[2.24,11.54],[2.88,6.54],[5,1],[2.86,6],[1.03,15.09],[1.51,196.08]],"id":52951653},{"atl":[[32,0.6],[150,4],[48,12],[28,8],[1000,0.16]],"id":52951653},{"spn":16.5,"spf":"NaN","id":52951653},{"spl":[[1.01,0.71]],"id":51441055},{"atb":[[5,1],[1.02,22.63],[2.12,89.29],[2.26,11.65],[1.51,196.08],[3.3,6]],"id":51441055},{"atl":[[32,8],[150,4],[55,12],[1000,0.16]],"id":51441055},{"spn":5.0,"spf":1.0,"id":51441055}],"con":true,"img":true}]}
{"op":"mcm","clk":"11539947669","pt":1719488175341,"mc":[{"id":"1.230178312","rc":[{"atb":[[2.24,13.32],[1.02,22.63]],"id":56913144},{"atb":[[1.02,22.63],[2.16,9.39]],"id":68462283},{"atb":[[1.01,45.27],[2.22,8.79]],"id":70681331},{"atb":[[1.01,45.27],[2.26,9.86]],"id":39100893},{"atb":[[2.24,11.54],[2.88,6.54],[1.03,15.09],[3.7,1]],"id":52951653},{"spl":[[1.01,0.71]],"id":51441055},{"atb":[[1.02,22.63],[2.26,11.65]],"id":51441055}],"con":true,"img":false}]}
{"op":"mcm","clk":"11539948230","pt":1719488183044,"mc":[{"id":"1.230178312","rc":[{"atb":[[3.7,1]],"id":51441055}],"con":true,"img":false}]}
{"op":"mcm","clk":"11539948891","pt":1719488192674,"mc":[{"id":"1.230178312","rc":[{"atb":[[3.7,1]],"id":70681331}],"con":true,"img":false}]}
{"op":"mcm","clk":"11539949165","pt":1719488196953,"mc":[{"id":"1.230178312","rc":[{"atb":[[2.12,89.29]],"id":52951653}],"con":true,"img":false}]}
{"op":"mcm","clk":"11540014287","pt":1719488998220,"mc":[{"id":"1.230178312","rc":[{"atl":[[270,2]],"id":68462283},{"atl":[[560,2]],"id":70681331},{"atb":[[1.16,150]],"id":39100893},{"atl":[[390,2]],"id":52951653}],"con":true,"img":false}]}
{"op":"mcm","clk":"11540014295","pt":1719488998322,"mc":[{"id":"1.230178312","rc":[{"atb":[[1.16,150]],"id":56913144},{"atl":[[500,2]],"id":56913144},{"atb":[[1.16,150]],"id":68462283},{"atb":[[1.16,150]],"id":70681331},{"atl":[[370,2]],"id":39100893},{"atb":[[1.16,150]],"id":52951653},{"atb":[[1.16,150]],"id":51441055},{"atl":[[550,2]],"id":51441055}],"con":true,"img":false}]}
{"op":"mcm","clk":"11540247715","pt":1719491882543,"mc":[{"id":"1.230178312","marketDefinition":{"bspMarket":true,"turnInPlayEnabled":false,"persistenceEnabled":false,"marketBaseRate":5.0,"eventId":"33376062","eventTypeId":"4339","numberOfWinners":1,"bettingType":"ODDS","marketType":"WIN","marketTime":"2024-06-27T14:32:00.000Z","suspendTime":"2024-06-27T14:32:00.000Z","bspReconciled":false,"complete":true,"inPlay":false,"crossMatching":true,"runnersVoidable":false,"numberOfActiveRunners":6,"betDelay":0,"status":"OPEN","runners":[{"status":"ACTIVE","sortPriority":1,"id":39100893,"name":"1. Sheriffs Rose"},{"status":"ACTIVE","sortPriority":2,"id":52951653,"name":"2. Grumpy Wazock"},{"status":"ACTIVE","sortPriority":3,"id":51441055,"name":"3. Pounda Prisna"},{"status":"ACTIVE","sortPriority":4,"id":68462283,"name":"4. Tober Glory"},{"status":"ACTIVE","sortPriority":5,"id":70681331,"name":"5. Shelone Luna"},{"status":"ACTIVE","sortPriority":6,"id":56913144,"name":"6. Knotmor Best"}],"regulators":["MR_INT"],"venue":"Kinsley","countryCode":"GB","discountAllowed":true,"timezone":"Europe/London","openDate":"2024-06-27T13:36:00.000Z","version":5994643751,"name":"A5 462m","eventName":"Kinsley 27th Jun"},"rc":[{"spl":[[1.01,1]],"id":56913144},{"atb":[[2.24,13.32],[1.16,150],[3.1,6],[1.02,22.63],[1.51,196.08],[3.65,1]],"id":56913144},{"atl":[[32,8],[150,4],[55,12],[990,0.16],[500,2]],"id":56913144},{"spn":3.65,"spf":1.0,"id":56913144},{"atb":[[5,1],[1.16,150],[3.1,6],[1.02,22.63],[1.51,196.08],[2.16,9.39]],"id":68462283},{"atl":[[270,2],[150,4],[42,12],[25,8],[990,0.16]],"id":68462283},{"spn":15.0,"spf":"NaN","id":68462283},{"atb":[[1.01,45.27],[5,1],[1.16,150],[2.22,8.79],[3.7,1],[2.12,89.29],[3.55,6],[1.51,196.08]],"id":70681331},{"atl":[[560,2],[150,4],[1000,0.16]],"id":70681331},{"spn":77.5,"spf":"NaN","id":70681331},{"atb":[[1.01,45.27],[5,1],[1.16,150],[3.1,6],[2.22,2],[2.26,9.86],[1.51,196.08]],"id":39100893},{"atl":[[150,4],[370,2],[990,0.16]],"id":39100893},{"spn":77.5,"spf":"NaN","id":39100893},{"atb":[[2.24,11.54],[2.88,6.54],[5,1],[2.86,6],[1.16,150],[1.03,15.09],[3.7,1],[2.12,89.29],[1.51,196.08]],"id":52951653},{"atl":[[32,0.6],[150,4],[48,12],[390,2],[28,8],[1000,0.16]],"id":52951653},{"spn":16.5,"spf":"NaN","id":52951653},{"spl":[[1.01,0.71]],"id":51441055},{"atb":[[5,1],[1.16,150],[3.7,1],[1.02,22.63],[2.12,89.29],[2.26,11.65],[1.51,196.08],[3.3,6]],"id":51441055},{"atl":[[32,8],[550,2],[150,4],[55,12],[1000,0.16]],"id":51441055},{"spn":5.0,"spf":1.0,"id":51441055}],"con":true,"img":true}]}
{"op":"mcm","clk":"11540497609","pt":1719495189458,"mc":[{"id":"1.230178312","rc":[{"atb":[[2.24,13.33],[1.02,22.66]],"id":56913144},{"atl":[[990,0.16]],"id":56913144},{"spl":[[1.01,1]],"id":68462283},{"atb":[[1.02,22.66],[2.16,9.4]],"id":68462283},{"atl":[[990,0.16]],"id":68462283},{"spn":5.0,"spf":1.0,"id":68462283},{"atb":[[1.01,45.32],[2.22,8.8]],"id":70681331},{"atl":[[1000,0.16]],"id":70681331},{"atb":[[1.01,45.32],[2.26,9.87]],"id":39100893},{"atl":[[990,0.16]],"id":39100893},{"atb":[[2.24,11.56],[2.88,6.54],[1.03,15.1]],"id":52951653},{"atl":[[1000,0.16]],"id":52951653},{"spl":[[1.01,0.71]],"id":51441055},{"atb":[[1.02,22.66],[2.26,11.67]],"id":51441055},{"atl":[[1000,0.16]],"id":51441055}],"con":true,"img":false}]}
{"op":"mcm","clk":"11540566915","pt":1719495972918,"mc":[{"id":"1.230178312","rc":[{"spl":[[3,2.5]],"id":56913144},{"spn":3.25,"spf":1.0,"id":56913144},{"spl":[[3,2.5]],"id":68462283},{"spn":3.64,"spf":1.0,"id":68462283},{"spl":[[3,2.5]],"id":70681331},{"spn":4.19,"spf":1.0,"id":70681331}],"con":true,"img":false}]}
{"op":"mcm","clk":"11540574986","pt":1719496063043,"mc":[{"id":"1.230178312","rc":[{"atb":[[3.8,1]],"id":56913144},{"spn":3.45,"spf":1.0,"id":56913144},{"atb":[[5,2]],"id":68462283},{"spn":4.18,"spf":1.0,"id":68462283},{"atb":[[5.5,1]],"id":70681331},{"spn":4.94,"spf":1.0,"id":70681331},{"atb":[[4.4,1]],"id":39100893},{"atb":[[4.2,1]],"id":52951653},{"atb":[[5,2]],"id":51441055}],"con":true,"img":false}]}
{"op":"mcm","clk":"11540575202","pt":1719496065227,"mc":[{"id":"1.230178312","rc":[{"atb":[[2.12,89.29]],"id":39100893}],"con":true,"img":false}]}
{"op":"mcm","clk":"11540576494","pt":1719496078547,"mc":[{"id":"1.230178312","rc":[{"spl":[[1.01,11]],"id":56913144}],"con":true,"img":false}]}
{"op":"mcm","clk":"11540578139","pt":1719496094251,"mc":[{"id":"1.230178312","rc":[{"spl":[[1.01,36]],"id":56913144}],"con":true,"img":false}]}
{"op":"mcm","clk":"11540582156","pt":1719496137371,"mc":[{"id":"1.230178312","rc":[{"atb":[[2,210.67]],"id":56913144},{"spn":2.36,"spf":1.0,"id":56913144}],"con":true,"img":false}]}
{"op":"mcm","clk":"11540604319","pt":1719496355279,"mc":[{"id":"1.230178312","rc":[{"atl":[[30,1.69]],"id":56913144}],"con":true,"img":false}]}
{"op":"mcm","clk":"11540604349","pt":1719496355587,"mc":[{"id":"1.230178312","rc":[{"atl":[[24,1.66]],"id":68462283}],"con":true,"img":false}]}
{"op":"mcm","clk":"11540604380","pt":1719496355891,"mc":[{"id":"1.230178312","rc":[{"atl":[[30,1.73]],"id":51441055}],"con":true,"img":false}]}
{"op":"mcm","clk":"11540604417","pt":1719496356307,"mc":[{"id":"1.230178312","rc":[{"atl":[[27,1.63]],"id":52951653}],"con":true,"img":false}]}
{"op":"mcm","clk":"11540627493","pt":1719496617596,"mc":[{"id":"1.230178312","rc":[{"spl":[[1.01,37.71]],"id":56913144},{"spn":2.35,"spf":1.0,"id":56913144},{"spn":16.0,"spf":"NaN","id":52951653}],"con":true,"img":false}]}
{"op":"mcm","clk":"11540652334","pt":1719496925646,"mc":[{"id":"1.230178312","rc":[{"atb":[[2.24,13.33],[2,210.42],[1.02,22.65]],"id":56913144},{"atb":[[1.02,22.65],[2.16,9.4]],"id":68462283},{"spl":[[1.01,4]],"id":70681331},{"atb":[[1.01,45.3],[2.22,8.8]],"id":70681331},{"spn":4.09,"spf":1.0,"id":70681331},{"atb":[[1.01,45.3],[2.26,9.87]],"id":39100893},{"atb":[[2.24,11.55],[2.88,6.54],[1.03,15.1]],"id":52951653},{"spl":[[1.01,0.71]],"id":51441055},{"atb":[[1.02,22.65],[2.26,11.66]],"id":51441055}],"con":true,"img":false}]}
{"op":"mcm","clk":"11540661422","pt":1719497040747,"mc":[{"id":"1.230178312","rc":[{"spl":[[1.01,54.64]],"id":56913144},{"spn":2.24,"spf":1.0,"id":56913144}],"con":true,"img":false}]}
{"op":"mcm","clk":"11540677604","pt":1719497228710,"mc":[{"id":"1.230178312","rc":[{"atl":[[190,4]],"id":70681331},{"atl":[[190,4]],"id":39100893},{"atl":[[190,4]],"id":52951653},{"atl":[[190,4]],"id":51441055}],"con":true,"img":false}]}
{"op":"mcm","clk":"11540677610","pt":1719497228811,"mc":[{"id":"1.230178312","rc":[{"atl":[[190,4]],"id":56913144},{"atl":[[190,4]],"id":68462283}],"con":true,"img":false}]}
{"op":"mcm","clk":"11540678962","pt":1719497244717,"mc":[{"id":"1.230178312","rc":[{"atb":[[1.02,2]],"id":39100893}],"con":true,"img":false}]}
{"op":"mcm","clk":"11540678993","pt":1719497245027,"mc":[{"id":"1.230178312","rc":[{"atb":[[1.02,2]],"id":52951653}],"con":true,"img":false}]}
{"op":"mcm","clk":"11540679030","pt":1719497245438,"mc":[{"id":"1.230178312","rc":[{"atb":[[1.02,24.65]],"id":51441055}],"con":true,"img":false}]}
{"op":"mcm","clk":"11540679046","pt":1719497245643,"mc":[{"id":"1.230178312","rc":[{"atb":[[1.02,24.65]],"id":68462283}],"con":true,"img":false}]}
{"op":"mcm","clk":"11540679057","pt":1719497245847,"mc":[{"id":"1.230178312","rc":[{"atb":[[1.02,2]],"id":70681331}],"con":true,"img":false}]}
{"op":"mcm","clk":"11540679074","pt":1719497246009,"mc":[{"id":"1.230178312","rc":[{"atb":[[3.85,2]],"id":56913144}],"con":true,"img":false}]}
{"op":"mcm","clk":"11540702228","pt":1719497442734,"mc":[{"id":"1.230178312","rc":[{"spn":2.31,"spf":1.0,"id":56913144},{"atb":[[2.5,21.48]],"id":68462283}],"con":true,"img":false}]}
{"op":"mcm","clk":"11540706668","pt":1719497488851,"mc":[{"id":"1.230178312","rc":[{"atb":[[2.5,28.65]],"id":68462283}],"con":true,"img":false}]}
{"op":"mcm","clk":"11540724067","pt":1719497693483,"mc":[{"id":"1.230178312","rc":[{"spb":[[1000,11]],"id":56913144},{"spn":2.36,"spf":1.2,"id":56913144},{"spl":[[1.01,5]],"id":68462283},{"spn":3.6,"spf":1.0,"id":68462283},{"spl":[[1.01,6]],"id":70681331},{"spn":3.96,"spf":1.0,"id":70681331},{"spl":[[1.01,4]],"id":39100893},{"spn":3.9,"spf":1.0,"id":39100893},{"spl":[[1.01,2]],"id":52951653},{"spn":4.6,"spf":1.0,"id":52951653},{"spb":[[1000,22]],"id":51441055},{"spn":30.0,"spf":31.71,"id":51441055}],"con":true,"img":false}]}
{"op":"mcm","clk":"11540730291","pt":1719497762232,"mc":[{"id":"1.230178312","rc":[{"atl":[[29,0.84]],"id":56913144},{"atl":[[23,0.84]],"id":68462283},{"atl":[[26,0.84]],"id":52951653},{"atl":[[29,0.84]],"id":51441055},{"spn":29.0,"spf":31.71,"id":51441055}],"con":true,"img":false}]}
{"op":"mcm","clk":"11540733982","pt":1719497803681,"mc":[{"id":"1.230178312","rc":[{"atl":[[1000,1]],"id":56913144}],"con":true,"img":false}]}
{"op":"mcm","clk":"11540733996","pt":1719497803887,"mc":[{"id":"1.230178312","rc":[{"atl":[[1000,0.02]],"id":56913144}],"con":true,"img":false}]}
{"op":"mcm","clk":"11540734009","pt":1719497804089,"mc":[{"id":"1.230178312","rc":[{"atl":[[1000,0]],"id":56913144}],"con":true,"img":false}]}
{"op":"mcm","clk":"11540734019","pt":1719497804191,"mc":[{"id":"1.230178312","rc":[{"atl":[[28,0.02]],"id":56913144}],"con":true,"img":false}]}
{"op":"mcm","clk":"11540734119","pt":1719497805070,"mc":[{"id":"1.230178312","rc":[{"spl":[[1.01,6.69]],"id":68462283}],"con":true,"img":false}]}
{"op":"mcm","clk":"11540735186","pt":1719497817663,"mc":[{"id":"1.230178312","rc":[{"spl":[[1.01,8]],"id":39100893}],"con":true,"img":false}]}
{"op":"mcm","clk":"11540735426","pt":1719497820402,"mc":[{"id":"1.230178312","rc":[{"atl":[[29,2.84]],"id":56913144}],"con":true,"img":false}]}
{"op":"mcm","clk":"11540735438","pt":1719497820511,"mc":[{"id":"1.230178312","rc":[{"atb":[[3.2,13.33]],"id":56913144},{"atl":[[29,4.84]],"id":56913144}],"con":true,"img":false}]}
{"op":"mcm","clk":"11540735450","pt":1719497820607,"mc":[{"id":"1.230178312","rc":[{"atb":[[1.12,1.69]],"id":39100893},{"atb":[[1.12,1.69]],"id":52951653}],"con":true,"img":false}]}
{"op":"mcm","clk":"11540735459","pt":1719497820711,"mc":[{"id":"1.230178312","rc":[{"atb":[[3.15,6]],"id":39100893},{"atl":[[60,2]],"id":39100893},{"atb":[[3.05,6.55]],"id":52951653},{"atl":[[27,3.63]],"id":52951653}],"con":true,"img":false}]}
{"op":"mcm","clk":"11540735465","pt":1719497820814,"mc":[{"id":"1.230178312","rc":[{"atb":[[4.5,9.41]],"id":68462283},{"atl":[[24,6.01]],"id":68462283},{"atb":[[3.75,6]],"id":70681331},{"atl":[[90,2]],"id":70681331},{"atb":[[3.65,11.67]],"id":51441055},{"atl":[[30,5.18]],"id":51441055}],"con":true,"img":false}]}
{"op":"mcm","clk":"11540735481","pt":1719497820917,"mc":[{"id":"1.230178312","rc":[{"atb":[[1.14,1.69]],"id":70681331},{"atb":[[1.12,0.05]],"id":39100893}],"con":true,"img":false}]}
{"op":"mcm","clk":"11540735511","pt":1719497821175,"mc":[{"id":"1.230178312","rc":[{"atb":[[1.09,1.69]],"id":56913144}],"con":true,"img":false}]}
{"op":"mcm","clk":"11540735530","pt":1719497821380,"mc":[{"id":"1.230178312","rc":[{"atb":[[1.12,1.69]],"id":68462283},{"atb":[[1.12,1.69]],"id":51441055}],"con":true,"img":false}]}
{"op":"mcm","clk":"11540735553","pt":1719497821692,"mc":[{"id":"1.230178312","rc":[{"atb":[[1.12,0]],"id":39100893},{"atb":[[1.12,0.05]],"id":52951653}],"con":true,"img":false}]}
{"op":"mcm","clk":"11540735560","pt":1719497821794,"mc":[{"id":"1.230178312","rc":[{"atb":[[5.1,0.05]],"id":39100893}],"con":true,"img":false}]}
{"op":"mcm","clk":"11540735582","pt":1719497822001,"mc":[{"id":"1.230178312","rc":[{"atb":[[1.14,0.05]],"id":70681331}],"con":true,"img":false}]}
{"op":"mcm","clk":"11540735590","pt":1719497822105,"mc":[{"id":"1.230178312","rc":[{"atb":[[1.09,0.07]],"id":56913144}],"con":true,"img":false}]}
{"op":"mcm","clk":"11540735612","pt":1719497822313,"mc":[{"id":"1.230178312","rc":[{"spn":2.68,"spf":1.2,"id":56913144},{"spn":4.6,"spf":1.0,"id":68462283},{"spn":4.1,"spf":1.0,"id":70681331},{"spn":3.55,"spf":1.0,"id":39100893},{"atb":[[1.12,0]],"id":52951653}],"con":true,"img":false}]}
{"op":"mcm","clk":"11540735623","pt":1719497822416,"mc":[{"id":"1.230178312","rc":[{"atb":[[1.12,0.05]],"id":68462283},{"atb":[[5.1,0.05]],"id":52951653}],"con":true,"img":false}]}
{"op":"mcm","clk":"11540735654","pt":1719497822675,"mc":[{"id":"1.230178312","rc":[{"atb":[[1.12,0.05]],"id":51441055}],"con":true,"img":false}]}
{"op":"mcm","clk":"11540735662","pt":1719497822779,"mc":[{"id":"1.230178312","rc":[{"atl":[[30,0]],"id":56913144},{"atb":[[1.14,0]],"id":70681331}],"con":true,"img":false}]}
{"op":"mcm","clk":"11540735669","pt":1719497822882,"mc":[{"id":"1.230178312","rc":[{"atb":[[5.6,0.05]],"id":70681331}],"con":true,"img":false}]}
{"op":"mcm","clk":"11540735687","pt":1719497823088,"mc":[{"id":"1.230178312","rc":[{"atb":[[1.09,0]],"id":56913144}],"con":true,"img":false}]}
{"op":"mcm","clk":"11540735698","pt":1719497823192,"mc":[{"id":"1.230178312","rc":[{"atb":[[3.9,0.07]],"id":56913144},{"atb":[[1.02,0]],"id":52951653}],"con":true,"img":false}]}
{"op":"mcm","clk":"11540735705","pt":1719497823302,"mc":[{"id":"1.230178312","rc":[{"atb":[[5.1,2.05]],"id":52951653}],"con":true,"img":false}]}
{"op":"mcm","clk":"11540735725","pt":1719497823506,"mc":[{"id":"1.230178312","rc":[{"atb":[[1.12,0]],"id":68462283}],"con":true,"img":false}]}
{"op":"mcm","clk":"11540735733","pt":1719497823610,"mc":[{"id":"1.230178312","rc":[{"atb":[[5.1,0.05]],"id":68462283}],"con":true,"img":false}]}
{"op":"mcm","clk":"11540735766","pt":1719497823916,"mc":[{"id":"1.230178312","rc":[{"atb":[[1.12,0]],"id":51441055}],"con":true,"img":false}]}
{"op":"mcm","clk":"11540735775","pt":1719497824019,"mc":[{"id":"1.230178312","rc":[{"atb":[[5.1,0.05]],"id":51441055}],"con":true,"img":false}]}
{"op":"mcm","clk":"11540735825","pt":1719497824589,"mc":[{"id":"1.230178312","rc":[{"atb":[[2.88,3.38]],"id":52951653}],"con":true,"img":false}]}
{"op":"mcm","clk":"11540735922","pt":1719497825518,"mc":[{"id":"1.230178312","rc":[{"atl":[[29,2.84]],"id":56913144}],"con":true,"img":false}]}
{"op":"mcm","clk":"11540735931","pt":1719497825580,"mc":[{"id":"1.230178312","rc":[{"atl":[[29,0.84],[30,3.45]],"id":56913144},{"atb":[[1.03,1.7]],"id":39100893},{"atl":[[1000,1.7]],"id":39100893},{"atb":[[1.03,16.8]],"id":52951653},{"atl":[[1000,1.87]],"id":52951653},{"atb":[[1.03,1.7]],"id":51441055},{"atl":[[1000,1.87]],"id":51441055}],"con":true,"img":false}]}
{"op":"mcm","clk":"11540735953","pt":1719497825780,"mc":[{"id":"1.230178312","rc":[{"atb":[[1.03,0.09]],"id":39100893},{"atl":[[1000,0]],"id":39100893},{"atb":[[1.03,15.17]],"id":52951653},{"atl":[[1000,0.18]],"id":52951653},{"atb":[[1.03,0.07]],"id":51441055},{"atl":[[1000,0.18]],"id":51441055}],"con":true,"img":false}]}
{"op":"mcm","clk":"11540735963","pt":1719497825884,"mc":[{"id":"1.230178312","rc":[{"atl":[[28,1.54]],"id":56913144}],"con":true,"img":false}]}
{"op":"mcm","clk":"11540735974","pt":1719497825987,"mc":[{"id":"1.230178312","rc":[{"atb":[[1.03,0]],"id":39100893},{"atl":[[1000,0]],"id":39100893},{"atb":[[1.03,15.1]],"id":52951653},{"atl":[[1000,0.16]],"id":52951653},{"atb":[[1.03,0]],"id":51441055},{"atl":[[1000,0.16]],"id":51441055}],"con":true,"img":false}]}
{"op":"mcm","clk":"11540735984","pt":1719497826091,"mc":[{"id":"1.230178312","rc":[{"atb":[[4.5,0.09]],"id":39100893},{"atl":[[55,0]],"id":39100893},{"atb":[[5.2,0.07]],"id":52951653},{"atl":[[26,0.85]],"id":52951653},{"atb":[[5.1,0.13]],"id":51441055},{"atl":[[29,0.85]],"id":51441055}],"con":true,"img":false}]}
{"op":"mcm","clk":"11540736422","pt":1719497830797,"mc":[{"id":"1.230178312","rc":[{"atb":[[3.45,6],[3.15,0]],"id":39100893}],"con":true,"img":false}]}
{"op":"mcm","clk":"11540736606","pt":1719497832611,"mc":[{"id":"1.230178312","rc":[{"atl":[[27,2]],"id":56913144}],"con":true,"img":false}]}
{"op":"mcm","clk":"11540736675","pt":1719497833235,"mc":[{"id":"1.230178312","rc":[{"atl":[[28,1.52]],"id":56913144}],"con":true,"img":false}]}
{"op":"mcm","clk":"11540736687","pt":1719497833335,"mc":[{"id":"1.230178312","rc":[{"atl":[[26,0.02]],"id":56913144}],"con":true,"img":false}]}
{"op":"mcm","clk":"11540736853","pt":1719497834887,"mc":[{"id":"1.230178312","rc":[{"atl":[[28,0]],"id":56913144}],"con":true,"img":false}]}
{"op":"mcm","clk":"11540736935","pt":1719497835713,"mc":[{"id":"1.230178312","rc":[{"atl":[[27,4],[30,0]],"id":56913144}],"con":true,"img":false}]}
{"op":"mcm","clk":"11540737116","pt":1719497837828,"mc":[{"id":"1.230178312","rc":[{"atl":[[27,2]],"id":56913144}],"con":true,"img":false}]}
{"op":"mcm","clk":"11540737127","pt":1719497837930,"mc":[{"id":"1.230178312","rc":[{"atl":[[26,1.73]],"id":56913144}],"con":true,"img":false}]}
{"op":"mcm","clk":"11540737291","pt":1719497839791,"mc":[{"id":"1.230178312","rc":[{"atl":[[25,2]],"id":56913144},{"atb":[[2.88,0]],"id":52951653}],"con":true,"img":false}]}
{"op":"mcm","clk":"11540737339","pt":1719497840309,"mc":[{"id":"1.230178312","rc":[{"atl":[[26,1.71]],"id":56913144}],"con":true,"img":false}]}
{"op":"mcm","clk":"11540737353","pt":1719497840418,"mc":[{"id":"1.230178312","rc":[{"atl":[[24,0.02]],"id":56913144}],"con":true,"img":false}]}
{"op":"mcm","clk":"11540737401","pt":1719497840930,"mc":[{"id":"1.230178312","rc":[{"atl":[[26,0]],"id":56913144}],"con":true,"img":false}]}
{"op":"mcm","clk":"11540737493","pt":1719497842230,"mc":[{"id":"1.230178312","rc":[{"atl":[[14.5,1]],"id":70681331},{"atl":[[8.8,1]],"id":39100893},{"atl":[[8.8,1]],"id":52951653}],"con":true,"img":false}]}
{"op":"mcm","clk":"11540737502","pt":1719497842331,"mc":[{"id":"1.230178312","rc":[{"atb":[[3.45,13.33],[3.2,0]],"id":56913144},{"atl":[[7.6,1]],"id":56913144},{"atb":[[4.5,0],[4.6,1],[4.7,9.41]],"id":68462283},{"atl":[[18.5,1]],"id":68462283},{"atb":[[3.75,0],[4,6]],"id":70681331},{"atl":[[80,2],[90,0]],"id":70681331},{"atl":[[50,2]],"id":39100893},{"atl":[[10.5,1]],"id":51441055}],"con":true,"img":false}]}
{"op":"mcm","clk":"11540737517","pt":1719497842442,"mc":[{"id":"1.230178312","rc":[{"atl":[[60,0]],"id":39100893}],"con":true,"img":false}]}
{"op":"mcm","clk":"11540737556","pt":1719497842797,"mc":[{"id":"1.230178312","rc":[{"atl":[[25,0]],"id":56913144}],"con":true,"img":false}]}
{"op":"mcm","clk":"11540737596","pt":1719497843313,"mc":[{"id":"1.230178312","rc":[{"atl":[[24,0]],"id":56913144}],"con":true,"img":false}]}
{"op":"mcm","clk":"11540737605","pt":1719497843417,"mc":[{"id":"1.230178312","rc":[{"atl":[[7.4,0.02]],"id":56913144}],"con":true,"img":false}]}
{"op":"mcm","clk":"11540737903","pt":1719497847028,"mc":[{"id":"1.230178312","rc":[{"atl":[[7.4,2.02]],"id":56913144}],"con":true,"img":false}]}
{"op":"mcm","clk":"11540737908","pt":1719497847131,"mc":[{"id":"1.230178312","rc":[{"atl":[[27,0]],"id":56913144}],"con":true,"img":false}]}
{"op":"mcm","clk":"11540737913","pt":1719497847236,"mc":[{"id":"1.230178312","rc":[{"atl":[[9,3.02]],"id":56913144}],"con":true,"img":false}]}
{"op":"mcm","clk":"11540738305","pt":1719497852254,"mc":[{"id":"1.230178312","rc":[{"atl":[[7.4,0.02]],"id":56913144}],"con":true,"img":false}]}
{"op":"mcm","clk":"11540738514","pt":1719497854937,"mc":[{"id":"1.230178312","rc":[{"atl":[[7.4,2.02]],"id":56913144}],"con":true,"img":false}]}
{"op":"mcm","clk":"11540738922","pt":1719497860147,"mc":[{"id":"1.230178312","rc":[{"atl":[[7.4,0.02]],"id":56913144}],"con":true,"img":false}]}
{"op":"mcm","clk":"11540739109","pt":1719497862115,"mc":[{"id":"1.230178312","rc":[{"atl":[[7.4,2.02]],"id":56913144}],"con":true,"img":false}]}
{"op":"mcm","clk":"11540739607","pt":1719497867333,"mc":[{"id":"1.230178312","rc":[{"atl":[[7.4,0.02]],"id":56913144}],"con":true,"img":false}]}
{"op":"mcm","clk":"11540739724","pt":1719497868522,"mc":[{"id":"1.230178312","rc":[{"atb":[[4.5,0]],"id":39100893},{"atl":[[55,0]],"id":39100893},{"atb":[[5.2,0]],"id":52951653},{"atl":[[26,0.84]],"id":52951653},{"atb":[[5.1,0.05]],"id":51441055},{"atl":[[29,0.84]],"id":51441055}],"con":true,"img":false}]}
{"op":"mcm","clk":"11540739786","pt":1719497869346,"mc":[{"id":"1.230178312","rc":[{"atl":[[7.4,2.02]],"id":56913144}],"con":true,"img":false}]}
{"op":"mcm","clk":"11540740204","pt":1719497874544,"mc":[{"id":"1.230178312","rc":[{"atl":[[7.4,0.02]],"id":56913144}],"con":true,"img":false}]}
{"op":"mcm","clk":"11540740383","pt":1719497876551,"mc":[{"id":"1.230178312","rc":[{"atl":[[7.4,2.02]],"id":56913144}],"con":true,"img":false}]}
{"op":"mcm","clk":"11540740874","pt":1719497881849,"mc":[{"id":"1.230178312","rc":[{"atl":[[7.4,0.02]],"id":56913144}],"con":true,"img":false}]}
{"op":"mcm","clk":"11540741052","pt":1719497883869,"mc":[{"id":"1.230178312","rc":[{"atl":[[7.4,2.02]],"id":56913144},{"spn":2.75,"spf":1.2,"id":56913144},{"spn":4.76,"spf":1.0,"id":68462283},{"spn":4.28,"spf":1.0,"id":70681331},{"spn":3.77,"spf":1.0,"id":39100893},{"spn":5.1,"spf":1.0,"id":52951653},{"spn":12.82,"spf":31.71,"id":51441055}],"con":true,"img":false}]}
{"op":"mcm","clk":"11540741546","pt":1719497889093,"mc":[{"id":"1.230178312","rc":[{"atl":[[7.4,0.02]],"id":56913144}],"con":true,"img":false}]}
{"op":"mcm","clk":"11540741762","pt":1719497891067,"mc":[{"id":"1.230178312","rc":[{"atl":[[7.4,2.02]],"id":56913144}],"con":true,"img":false}]}
{"op":"mcm","clk":"11540742062","pt":1719497894187,"mc":[{"id":"1.230178312","rc":[{"atb":[[5.1,3.07]],"id":52951653}],"con":true,"img":false}]}
{"op":"mcm","clk":"11540742269","pt":1719497896299,"mc":[{"id":"1.230178312","rc":[{"atl":[[7.4,0.02]],"id":56913144}],"con":true,"img":false}]}
{"op":"mcm","clk":"11540742303","pt":1719497896559,"mc":[{"id":"1.230178312","rc":[{"atb":[[6,3.15]],"id":68462283}],"con":true,"img":false}]}
{"op":"mcm","clk":"11540742563","pt":1719497898986,"mc":[{"id":"1.230178312","rc":[{"atl":[[7.4,2.02]],"id":56913144}],"con":true,"img":false}]}
{"op":"mcm","clk":"11540743071","pt":1719497904170,"mc":[{"id":"1.230178312","rc":[{"atl":[[7.4,0.02]],"id":56913144}],"con":true,"img":false}]}
{"op":"mcm","clk":"11540743293","pt":1719497906387,"mc":[{"id":"1.230178312","rc":[{"atl":[[7.4,2.02]],"id":56913144}],"con":true,"img":false}]}
{"op":"mcm","clk":"11540743508","pt":1719497908913,"mc":[{"id":"1.230178312","rc":[{"atl":[[9,0],[8.4,3.02]],"id":56913144},{"atl":[[40,2.56],[50,0]],"id":39100893}],"con":true,"img":false}]}
{"op":"mcm","clk":"11540743752","pt":1719497911599,"mc":[{"id":"1.230178312","rc":[{"atl":[[7.4,0.02]],"id":56913144}],"con":true,"img":false}]}
{"op":"mcm","clk":"11540743926","pt":1719497913517,"mc":[{"id":"1.230178312","rc":[{"atl":[[7.4,2.02]],"id":56913144}],"con":true,"img":false}]}
{"op":"mcm","clk":"11540744380","pt":1719497918677,"mc":[{"id":"1.230178312","rc":[{"atl":[[7.4,0.02]],"id":56913144}],"con":true,"img":false}]}
{"op":"mcm","clk":"11540744565","pt":1719497920788,"mc":[{"id":"1.230178312","rc":[{"atl":[[7.4,2.02]],"id":56913144}],"con":true,"img":false}]}
{"op":"mcm","clk":"11540744977","pt":1719497925586,"mc":[{"id":"1.230178312","rc":[{"atb":[[3.9,0.92]],"id":56913144},{"atl":[[7.2,0.84]],"id":56913144},{"atb":[[6.2,0.84]],"id":68462283},{"atb":[[5.2,0.84]],"id":52951653},{"atb":[[5.1,0.9]],"id":51441055}],"con":true,"img":false}]}
{"op":"mcm","clk":"11540745017","pt":1719497925997,"mc":[{"id":"1.230178312","rc":[{"atl":[[7.4,0.02]],"id":56913144}],"con":true,"img":false}]}
{"op":"mcm","clk":"11540745052","pt":1719497926510,"mc":[{"id":"1.230178312","rc":[{"atl":[[7.4,0]],"id":56913144}],"con":true,"img":false}]}
{"op":"mcm","clk":"11540745060","pt":1719497926614,"mc":[{"id":"1.230178312","rc":[{"atl":[[7.2,0],[7,0.02]],"id":56913144}],"con":true,"img":false}]}
{"op":"mcm","clk":"11540745186","pt":1719497928008,"mc":[{"id":"1.230178312","rc":[{"atl":[[7.4,2]],"id":56913144}],"con":true,"img":false}]}
{"op":"mcm","clk":"11540745609","pt":1719497932608,"mc":[{"id":"1.230178312","rc":[{"atb":[[3.55,2.5]],"id":51441055}],"con":true,"img":false}]}
{"op":"mcm","clk":"11540745630","pt":1719497932813,"mc":[{"id":"1.230178312","rc":[{"atb":[[3.55,0]],"id":51441055}],"con":true,"img":false}]}
{"op":"mcm","clk":"11540745665","pt":1719497933121,"mc":[{"id":"1.230178312","rc":[{"atl":[[7.2,0.84]],"id":56913144}],"con":true,"img":false}]}
{"op":"mcm","clk":"11540745675","pt":1719497933226,"mc":[{"id":"1.230178312","rc":[{"atl":[[7.4,0]],"id":56913144}],"con":true,"img":false}]}
{"op":"mcm","clk":"11540745711","pt":1719497933585,"mc":[{"id":"1.230178312","rc":[{"atl":[[7.2,0]],"id":56913144}],"con":true,"img":false}]}
{"op":"mcm","clk":"11540745951","pt":1719497936005,"mc":[{"id":"1.230178312","rc":[{"atl":[[7.4,2]],"id":56913144}],"con":true,"img":false}]}
{"op":"mcm","clk":"11540746319","pt":1719497940647,"mc":[{"id":"1.230178312","rc":[{"atl":[[7.2,0.84]],"id":56913144}],"con":true,"img":false}]}
{"op":"mcm","clk":"11540746344","pt":1719497940906,"mc":[{"id":"1.230178312","rc":[{"atb":[[5.1,0]],"id":39100893}],"con":true,"img":false}]}
{"op":"mcm","clk":"11540746372","pt":1719497941215,"mc":[{"id":"1.230178312","rc":[{"atl":[[7.4,0]],"id":56913144},{"atb":[[5.1,3.02]],"id":52951653}],"con":true,"img":false}]}
{"op":"mcm","clk":"11540746394","pt":1719497941525,"mc":[{"id":"1.230178312","rc":[{"atb":[[5.6,0]],"id":70681331}],"con":true,"img":false}]}
{"op":"mcm","clk":"11540746404","pt":1719497941627,"mc":[{"id":"1.230178312","rc":[{"atl":[[7.2,0]],"id":56913144}],"con":true,"img":false}]}
{"op":"mcm","clk":"11540746421","pt":1719497941832,"mc":[{"id":"1.230178312","rc":[{"atb":[[1.12,1.69]],"id":39100893},{"atb":[[1.12,1.69]],"id":52951653}],"con":true,"img":false}]}
{"op":"mcm","clk":"11540746443","pt":1719497942142,"mc":[{"id":"1.230178312","rc":[{"atb":[[1.14,1.69]],"id":70681331},{"atb":[[5.1,0.84]],"id":51441055}],"con":true,"img":false}]}
{"op":"mcm","clk":"11540746466","pt":1719497942402,"mc":[{"id":"1.230178312","rc":[{"atb":[[1.12,0.05]],"id":39100893},{"atb":[[1.12,0.05]],"id":52951653}],"con":true,"img":false}]}
{"op":"mcm","clk":"11540746496","pt":1719497942713,"mc":[{"id":"1.230178312","rc":[{"atb":[[1.14,0.05]],"id":70681331},{"atb":[[1.12,0]],"id":52951653}],"con":true,"img":false}]}
{"op":"mcm","clk":"11540746503","pt":1719497942815,"mc":[{"id":"1.230178312","rc":[{"atb":[[5.2,0.9]],"id":52951653}],"con":true,"img":false}]}
{"op":"mcm","clk":"11540746530","pt":1719497943127,"mc":[{"id":"1.230178312","rc":[{"atb":[[5.1,0]],"id":68462283}],"con":true,"img":false}]}
{"op":"mcm","clk":"11540746548","pt":1719497943334,"mc":[{"id":"1.230178312","rc":[{"atb":[[1.12,0]],"id":39100893}],"con":true,"img":false}]}
{"op":"mcm","clk":"11540746556","pt":1719497943437,"mc":[{"id":"1.230178312","rc":[{"atl":[[7.4,2]],"id":56913144},{"atb":[[5.1,0.05]],"id":39100893}],"con":true,"img":false}]}
{"op":"mcm","clk":"11540746584","pt":1719497943810,"mc":[{"id":"1.230178312","rc":[{"atb":[[3.9,0.84]],"id":56913144},{"atb":[[1.12,1.69]],"id":51441055}],"con":true,"img":false}]}
{"op":"mcm","clk":"11540746613","pt":1719497944111,"mc":[{"id":"1.230178312","rc":[{"spn":2.78,"spf":1.2,"id":56913144},{"spn":5.34,"spf":1.0,"id":68462283},{"atb":[[1.14,0]],"id":70681331},{"spn":4.27,"spf":1.0,"id":70681331},{"spn":5.14,"spf":1.0,"id":52951653}],"con":true,"img":false}]}
{"op":"mcm","clk":"11540746623","pt":1719497944213,"mc":[{"id":"1.230178312","rc":[{"atb":[[5.6,0.05]],"id":70681331}],"con":true,"img":false}]}
{"op":"mcm","clk":"11540746655","pt":1719497944522,"mc":[{"id":"1.230178312","rc":[{"atb":[[1.14,1.69]],"id":68462283}],"con":true,"img":false}]}
{"op":"mcm","clk":"11540746665","pt":1719497944625,"mc":[{"id":"1.230178312","rc":[{"atb":[[1.12,0.05]],"id":51441055}],"con":true,"img":false}]}
{"op":"mcm","clk":"11540746682","pt":1719497944830,"mc":[{"id":"1.230178312","rc":[{"atb":[[1.09,1.69]],"id":56913144}],"con":true,"img":false}]}
{"op":"mcm","clk":"11540746697","pt":1719497945035,"mc":[{"id":"1.230178312","rc":[{"atb":[[1.12,0]],"id":51441055}],"con":true,"img":false}]}
{"op":"mcm","clk":"11540746708","pt":1719497945139,"mc":[{"id":"1.230178312","rc":[{"atb":[[1.14,0.05]],"id":68462283},{"atb":[[5.1,0.9]],"id":51441055}],"con":true,"img":false}]}
{"op":"mcm","clk":"11540746736","pt":1719497945405,"mc":[{"id":"1.230178312","rc":[{"atb":[[1.09,0.07]],"id":56913144},{"atb":[[1.14,0]],"id":68462283}],"con":true,"img":false}]}
{"op":"mcm","clk":"11540746744","pt":1719497945513,"mc":[{"id":"1.230178312","rc":[{"atb":[[6.4,0.05]],"id":68462283}],"con":true,"img":false}]}
{"op":"mcm","clk":"11540746776","pt":1719497945812,"mc":[{"id":"1.230178312","rc":[{"atb":[[1.09,0]],"id":56913144}],"con":true,"img":false}]}
{"op":"mcm","clk":"11540746786","pt":1719497945916,"mc":[{"id":"1.230178312","rc":[{"atb":[[3.9,0.92]],"id":56913144}],"con":true,"img":false}]}
{"op":"mcm","clk":"11540746917","pt":1719497947625,"mc":[{"id":"1.230178312","rc":[{"atl":[[7.2,0.84]],"id":56913144}],"con":true,"img":false}]}
{"op":"mcm","clk":"11540746997","pt":1719497948611,"mc":[{"id":"1.230178312","rc":[{"atl":[[7.4,0]],"id":56913144}],"con":true,"img":false}]}
{"op":"mcm","clk":"11540747042","pt":1719497949128,"mc":[{"id":"1.230178312","rc":[{"atl":[[7.2,0]],"id":56913144}],"con":true,"img":false}]}
{"op":"mcm","clk":"11540747169","pt":1719497950730,"mc":[{"id":"1.230178312","rc":[{"atl":[[7.4,2]],"id":56913144}],"con":true,"img":false}]}
{"op":"mcm","clk":"11540747272","pt":1719497951821,"mc":[{"id":"1.230178312","rc":[{"atb":[[1.03,1.7]],"id":39100893},{"atl":[[1000,1.7]],"id":39100893},{"atb":[[1.04,1.7]],"id":52951653},{"atl":[[1000,1.87]],"id":52951653},{"atb":[[1.04,1.7]],"id":51441055},{"atl":[[1000,1.87]],"id":51441055}],"con":true,"img":false}]}
{"op":"mcm","clk":"11540747291","pt":1719497952028,"mc":[{"id":"1.230178312","rc":[{"atb":[[1.03,0.08]],"id":39100893},{"atl":[[1000,0]],"id":39100893},{"atb":[[1.04,0.07]],"id":52951653},{"atl":[[1000,0.18]],"id":52951653},{"atb":[[1.04,0.07]],"id":51441055},{"atl":[[1000,0.18]],"id":51441055}],"con":true,"img":false}]}
{"op":"mcm","clk":"11540747315","pt":1719497952236,"mc":[{"id":"1.230178312","rc":[{"atb":[[1.03,0]],"id":39100893},{"atl":[[1000,0]],"id":39100893},{"atb":[[1.04,0]],"id":52951653},{"atl":[[1000,0.16]],"id":52951653},{"atb":[[1.04,0]],"id":51441055},{"atl":[[1000,0.16]],"id":51441055}],"con":true,"img":false}]}
{"op":"mcm","clk":"11540747328","pt":1719497952337,"mc":[{"id":"1.230178312","rc":[{"atb":[[4.5,0.08]],"id":39100893},{"atl":[[38,0]],"id":39100893},{"atb":[[5.2,0.97]],"id":52951653},{"atl":[[25,0.01]],"id":52951653},{"atb":[[5.1,0.98]],"id":51441055},{"atl":[[28,0.01]],"id":51441055}],"con":true,"img":false}]}
{"op":"mcm","clk":"11540747518","pt":1719497954618,"mc":[{"id":"1.230178312","rc":[{"atl":[[7.2,0.84]],"id":56913144}],"con":true,"img":false}]}
{"op":"mcm","clk":"11540747631","pt":1719497956055,"mc":[{"id":"1.230178312","rc":[{"atl":[[7.4,0]],"id":56913144}],"con":true,"img":false}]}
{"op":"mcm","clk":"11540747691","pt":1719497956627,"mc":[{"id":"1.230178312","rc":[{"atl":[[7.2,0]],"id":56913144}],"con":true,"img":false}]}
{"op":"mcm","clk":"11540747828","pt":1719497958130,"mc":[{"id":"1.230178312","rc":[{"atl":[[7.4,2]],"id":56913144}],"con":true,"img":false}]}
{"op":"mcm","clk":"11540748108","pt":1719497962148,"mc":[{"id":"1.230178312","rc":[{"atl":[[7.2,0.84]],"id":56913144}],"con":true,"img":false}]}
{"op":"mcm","clk":"11540748200","pt":1719497963341,"mc":[{"id":"1.230178312","rc":[{"atl":[[7.4,0]],"id":56913144}],"con":true,"img":false}]}
{"op":"mcm","clk":"11540748226","pt":1719497963751,"mc":[{"id":"1.230178312","rc":[{"atl":[[7.2,0]],"id":56913144}],"con":true,"img":false}]}
{"op":"mcm","clk":"11540748417","pt":1719497966137,"mc":[{"id":"1.230178312","rc":[{"atl":[[7.4,2]],"id":56913144}],"con":true,"img":false}]}
{"op":"mcm","clk":"11540748707","pt":1719497969225,"mc":[{"id":"1.230178312","rc":[{"atl":[[7.2,0.84]],"id":56913144}],"con":true,"img":false}]}
{"op":"mcm","clk":"11540748849","pt":1719497971351,"mc":[{"id":"1.230178312","rc":[{"atl":[[7.4,0]],"id":56913144}],"con":true,"img":false}]}
{"op":"mcm","clk":"11540748871","pt":1719497971639,"mc":[{"id":"1.230178312","rc":[{"atl":[[7.2,0]],"id":56913144}],"con":true,"img":false}]}
{"op":"mcm","clk":"11540748976","pt":1719497973443,"mc":[{"id":"1.230178312","rc":[{"atl":[[7.4,2]],"id":56913144}],"con":true,"img":false}]}
{"op":"mcm","clk":"11540749199","pt":1719497976525,"mc":[{"id":"1.230178312","rc":[{"atl":[[7.2,0.84]],"id":56913144}],"con":true,"img":false}]}
{"op":"mcm","clk":"11540749342","pt":1719497978535,"mc":[{"id":"1.230178312","rc":[{"atb":[[3.9,1.75]],"id":56913144},{"atb":[[6.4,0.84]],"id":68462283},{"atb":[[5.1,0.84]],"id":39100893},{"atb":[[5.2,1.86]],"id":52951653},{"atb":[[3.7,3.54]],"id":51441055}],"con":true,"img":false}]}
{"op":"mcm","clk":"11540749358","pt":1719497978738,"mc":[{"id":"1.230178312","rc":[{"atl":[[7.4,0]],"id":56913144}],"con":true,"img":false}]}
{"op":"mcm","clk":"11540749381","pt":1719497979153,"mc":[{"id":"1.230178312","rc":[{"atl":[[7.2,0]],"id":56913144}],"con":true,"img":false}]}
{"op":"mcm","clk":"11540749464","pt":1719497980432,"mc":[{"id":"1.230178312","rc":[{"atb":[[5.1,1.02]],"id":52951653}],"con":true,"img":false}]}
{"op":"mcm","clk":"11540749469","pt":1719497980536,"mc":[{"id":"1.230178312","rc":[{"atb":[[1.02,2]],"id":52951653}],"con":true,"img":false}]}
{"op":"mcm","clk":"11540749476","pt":1719497980638,"mc":[{"id":"1.230178312","rc":[{"atl":[[7.4,2]],"id":56913144}],"con":true,"img":false}]}
{"op":"mcm","clk":"11540749481","pt":1719497980741,"mc":[{"id":"1.230178312","rc":[{"atb":[[3.85,0]],"id":56913144}],"con":true,"img":false}]}
{"op":"mcm","clk":"11540749487","pt":1719497980845,"mc":[{"id":"1.230178312","rc":[{"atb":[[3.95,2]],"id":56913144}],"con":true,"img":false}]}
{"op":"mcm","clk":"11540749555","pt":1719497981568,"mc":[{"id":"1.230178312","rc":[{"atb":[[4,0.84]],"id":56913144}],"con":true,"img":false}]}
{"op":"mcm","clk":"11540749720","pt":1719497984044,"mc":[{"id":"1.230178312","rc":[{"atl":[[7.2,0.84]],"id":56913144}],"con":true,"img":false}]}
{"op":"mcm","clk":"11540749873","pt":1719497985941,"mc":[{"id":"1.230178312","rc":[{"atl":[[7.4,0]],"id":56913144}],"con":true,"img":false}]}
{"op":"mcm","clk":"11540749892","pt":1719497986146,"mc":[{"id":"1.230178312","rc":[{"atb":[[4.5,0]],"id":39100893},{"atl":[[38,0]],"id":39100893},{"atb":[[5.2,1.79]],"id":52951653},{"atl":[[25,0]],"id":52951653},{"atb":[[5.1,0.9]],"id":51441055},{"atl":[[28,0]],"id":51441055}],"con":true,"img":false}]}
{"op":"mcm","clk":"11540749942","pt":1719497986666,"mc":[{"id":"1.230178312","rc":[{"atl":[[7.2,0]],"id":56913144}],"con":true,"img":false}]}
{"op":"mcm","clk":"11540750082","pt":1719497987862,"mc":[{"id":"1.230178312","rc":[{"atl":[[7.4,2]],"id":56913144}],"con":true,"img":false}]}
{"op":"mcm","clk":"11540750355","pt":1719497991052,"mc":[{"id":"1.230178312","rc":[{"atl":[[7.2,0.84]],"id":56913144}],"con":true,"img":false}]}
{"op":"mcm","clk":"11540750541","pt":1719497993163,"mc":[{"id":"1.230178312","rc":[{"atl":[[7.4,0]],"id":56913144}],"con":true,"img":false}]}
{"op":"mcm","clk":"11540750581","pt":1719497993678,"mc":[{"id":"1.230178312","rc":[{"atl":[[7.2,0]],"id":56913144}],"con":true,"img":false}]}
{"op":"mcm","clk":"11540750689","pt":1719497995065,"mc":[{"id":"1.230178312","rc":[{"atl":[[7.4,2]],"id":56913144}],"con":true,"img":false}]}
{"op":"mcm","clk":"11540750977","pt":1719497998554,"mc":[{"id":"1.230178312","rc":[{"atl":[[7.2,0.84]],"id":56913144}],"con":true,"img":false}]}
{"op":"mcm","clk":"11540751138","pt":1719498000358,"mc":[{"id":"1.230178312","rc":[{"atl":[[7.4,0]],"id":56913144}],"con":true,"img":false}]}
{"op":"mcm","clk":"11540751216","pt":1719498001187,"mc":[{"id":"1.230178312","rc":[{"atl":[[7.2,0]],"id":56913144}],"con":true,"img":false}]}
{"op":"mcm","clk":"11540751371","pt":1719498002958,"mc":[{"id":"1.230178312","rc":[{"atl":[[7.4,2]],"id":56913144}],"con":true,"img":false}]}
{"op":"mcm","clk":"11540751502","pt":1719498004258,"mc":[{"id":"1.230178312","rc":[{"atb":[[3.9,0.92]],"id":56913144},{"spn":2.82,"spf":1.2,"id":56913144},{"spn":5.5,"spf":1.0,"id":68462283},{"spn":4.28,"spf":1.0,"id":70681331},{"atb":[[5.1,0.05]],"id":39100893},{"spn":5.18,"spf":1.0,"id":52951653}],"con":true,"img":false}]}
{"op":"mcm","clk":"11540751624","pt":1719498005604,"mc":[{"id":"1.230178312","rc":[{"atb":[[3.95,0]],"id":56913144},{"atl":[[7.2,0.84]],"id":56913144}],"con":true,"img":false}]}
{"op":"mcm","clk":"11540751633","pt":1719498005656,"mc":[{"id":"1.230178312","rc":[{"atb":[[3.85,2]],"id":56913144}],"con":true,"img":false}]}
{"op":"mcm","clk":"11540751670","pt":1719498006070,"mc":[{"id":"1.230178312","rc":[{"atb":[[4,0]],"id":56913144}],"con":true,"img":false}]}
{"op":"mcm","clk":"11540751891","pt":1719498008301,"mc":[{"id":"1.230178312","rc":[{"atl":[[7.4,0]],"id":56913144}],"con":true,"img":false}]}
{"op":"mcm","clk":"11540751935","pt":1719498008665,"mc":[{"id":"1.230178312","rc":[{"atl":[[7.2,0]],"id":56913144}],"con":true,"img":false}]}
{"op":"mcm","clk":"11540752067","pt":1719498010166,"mc":[{"id":"1.230178312","rc":[{"atl":[[7.4,2]],"id":56913144}],"con":true,"img":false}]}
{"op":"mcm","clk":"11540752323","pt":1719498012700,"mc":[{"id":"1.230178312","rc":[{"atl":[[7.2,0.84]],"id":56913144}],"con":true,"img":false}]}
{"op":"mcm","clk":"11540752571","pt":1719498015385,"mc":[{"id":"1.230178312","rc":[{"atl":[[7.4,0]],"id":56913144}],"con":true,"img":false}]}
{"op":"mcm","clk":"11540752593","pt":1719498015693,"mc":[{"id":"1.230178312","rc":[{"atl":[[7.2,0]],"id":56913144}],"con":true,"img":false}]}
{"op":"mcm","clk":"11540752747","pt":1719498017602,"mc":[{"id":"1.230178312","rc":[{"atl":[[7.4,2]],"id":56913144}],"con":true,"img":false}]}
{"op":"mcm","clk":"11540752955","pt":1719498020079,"mc":[{"id":"1.230178312","rc":[{"atl":[[7.2,0.84]],"id":56913144}],"con":true,"img":false}]}
{"op":"mcm","clk":"11540753120","pt":1719498021992,"mc":[{"id":"1.230178312","rc":[{"atb":[[6,0]],"id":68462283}],"con":true,"img":false}]}
{"op":"mcm","clk":"11540753175","pt":1719498022715,"mc":[{"id":"1.230178312","rc":[{"atb":[[6.2,0]],"id":68462283}],"con":true,"img":false}]}
{"op":"mcm","clk":"11540753184","pt":1719498022820,"mc":[{"id":"1.230178312","rc":[{"atl":[[7.4,0]],"id":56913144}],"con":true,"img":false}]}
{"op":"mcm","clk":"11540753200","pt":1719498022975,"mc":[{"id":"1.230178312","rc":[{"atl":[[1000,0.84]],"id":68462283},{"atl":[[10,0.84]],"id":51441055}],"con":true,"img":false}]}
{"op":"mcm","clk":"11540753210","pt":1719498023079,"mc":[{"id":"1.230178312","rc":[{"atb":[[5.1,0.84]],"id":68462283}],"con":true,"img":false}]}
{"op":"mcm","clk":"11540753222","pt":1719498023183,"mc":[{"id":"1.230178312","rc":[{"atl":[[7.2,0]],"id":56913144}],"con":true,"img":false}]}
{"op":"mcm","clk":"11540753231","pt":1719498023285,"mc":[{"id":"1.230178312","rc":[{"atl":[[7.2,1.17]],"id":56913144},{"atl":[[1000,1.01]],"id":70681331}],"con":true,"img":false}]}
{"op":"mcm","clk":"11540753257","pt":1719498023594,"mc":[{"id":"1.230178312","rc":[{"atb":[[5.7,1.48]],"id":70681331},{"atl":[[10,1.69]],"id":51441055}],"con":true,"img":false}]}
{"op":"mcm","clk":"11540753266","pt":1719498023698,"mc":[{"id":"1.230178312","rc":[{"atl":[[1000,0.47]],"id":68462283},{"atl":[[10.5,4.38],[30,1.73]],"id":51441055}],"con":true,"img":false}]}
{"op":"mcm","clk":"11540753286","pt":1719498023904,"mc":[{"id":"1.230178312","rc":[{"atl":[[7.4,1.17]],"id":56913144}],"con":true,"img":false}]}
{"op":"mcm","clk":"11540753304","pt":1719498024112,"mc":[{"id":"1.230178312","rc":[{"atl":[[7.2,0]],"id":56913144}],"con":true,"img":false}]}
{"op":"mcm","clk":"11540753312","pt":1719498024215,"mc":[{"id":"1.230178312","rc":[{"atl":[[1000,0.77]],"id":70681331},{"atb":[[1.02,0]],"id":52951653}],"con":true,"img":false}]}
{"op":"mcm","clk":"11540753319","pt":1719498024268,"mc":[{"id":"1.230178312","rc":[{"atb":[[5.3,2]],"id":52951653}],"con":true,"img":false}]}
{"op":"mcm","clk":"11540753328","pt":1719498024371,"mc":[{"id":"1.230178312","rc":[{"atb":[[5.7,0]],"id":70681331}],"con":true,"img":false}]}
{"op":"mcm","clk":"11540753336","pt":1719498024473,"mc":[{"id":"1.230178312","rc":[{"atb":[[5.6,1.53]],"id":70681331}],"con":true,"img":false}]}
{"op":"mcm","clk":"11540753344","pt":1719498024578,"mc":[{"id":"1.230178312","rc":[{"atb":[[5.4,0.84]],"id":52951653}],"con":true,"img":false}]}
{"op":"mcm","clk":"11540753354","pt":1719498024680,"mc":[{"id":"1.230178312","rc":[{"atl":[[1000,0]],"id":68462283}],"con":true,"img":false}]}
{"op":"mcm","clk":"11540753361","pt":1719498024783,"mc":[{"id":"1.230178312","rc":[{"atl":[[7.2,2]],"id":56913144},{"atl":[[18,0.47]],"id":68462283}],"con":true,"img":false}]}
{"op":"mcm","clk":"11540753392","pt":1719498025195,"mc":[{"id":"1.230178312","rc":[{"atl":[[1000,0.16]],"id":70681331}],"con":true,"img":false}]}
{"op":"mcm","clk":"11540753398","pt":1719498025299,"mc":[{"id":"1.230178312","rc":[{"atl":[[14,0.6]],"id":70681331}],"con":true,"img":false}]}
{"op":"mcm","clk":"11540753605","pt":1719498027619,"mc":[{"id":"1.230178312","rc":[{"atl":[[7,0.86]],"id":56913144}],"con":true,"img":false}]}
{"op":"mcm","clk":"11540753747","pt":1719498029316,"mc":[{"id":"1.230178312","rc":[{"atb":[[1.05,1.7]],"id":51441055},{"atl":[[1000,3.57]],"id":51441055}],"con":true,"img":false}]}
{"op":"mcm","clk":"11540753758","pt":1719498029421,"mc":[{"id":"1.230178312","rc":[{"atb":[[1.05,3.4]],"id":51441055}],"con":true,"img":false}]}
{"op":"mcm","clk":"11540753774","pt":1719498029470,"mc":[{"id":"1.230178312","rc":[{"atb":[[1.05,1.75]],"id":51441055}],"con":true,"img":false}]}
{"op":"mcm","clk":"11540753779","pt":1719498029573,"mc":[{"id":"1.230178312","rc":[{"atl":[[1000,1.89]],"id":51441055}],"con":true,"img":false}]}
{"op":"mcm","clk":"11540753792","pt":1719498029678,"mc":[{"id":"1.230178312","rc":[{"atb":[[1.05,0.09]],"id":51441055},{"atl":[[1000,0.21]],"id":51441055}],"con":true,"img":false}]}
{"op":"mcm","clk":"11540753802","pt":1719498029780,"mc":[{"id":"1.230178312","rc":[{"atb":[[1.05,0.04]],"id":51441055},{"atl":[[1000,0.19]],"id":51441055}],"con":true,"img":false}]}
{"op":"mcm","clk":"11540753813","pt":1719498029883,"mc":[{"id":"1.230178312","rc":[{"atb":[[5.1,0.95]],"id":51441055},{"atl":[[10,1.71]],"id":51441055}],"con":true,"img":false}]}
{"op":"mcm","clk":"11540753824","pt":1719498029986,"mc":[{"id":"1.230178312","rc":[{"atb":[[1.05,0]],"id":51441055},{"atl":[[1000,0.16]],"id":51441055}],"con":true,"img":false}]}
{"op":"mcm","clk":"11540753830","pt":1719498030091,"mc":[{"id":"1.230178312","rc":[{"atl":[[7.2,0]],"id":56913144},{"atb":[[5.1,1]],"id":51441055},{"atl":[[10,1.73]],"id":51441055}],"con":true,"img":false}]}
{"op":"mcm","clk":"11540753882","pt":1719498030710,"mc":[{"id":"1.230178312","rc":[{"atl":[[7,0.02]],"id":56913144}],"con":true,"img":false}]}
{"op":"mcm","clk":"11540753920","pt":1719498031123,"mc":[{"id":"1.230178312","rc":[{"atl":[[30,0]],"id":51441055}],"con":true,"img":false}]}
{"op":"mcm","clk":"11540754076","pt":1719498032784,"mc":[{"id":"1.230178312","rc":[{"atl":[[7.2,2]],"id":56913144}],"con":true,"img":false}]}
{"op":"mcm","clk":"11540754243","pt":1719498035206,"mc":[{"id":"1.230178312","rc":[{"atl":[[7,0.86]],"id":56913144}],"con":true,"img":false}]}
{"op":"mcm","clk":"11540754495","pt":1719498038038,"mc":[{"id":"1.230178312","rc":[{"atl":[[7.2,0]],"id":56913144}],"con":true,"img":false}]}
{"op":"mcm","clk":"11540754549","pt":1719498038605,"mc":[{"id":"1.230178312","rc":[{"atl":[[7,0.02]],"id":56913144}],"con":true,"img":false}]}
{"op":"mcm","clk":"11540754683","pt":1719498040104,"mc":[{"id":"1.230178312","rc":[{"atl":[[7.2,2]],"id":56913144}],"con":true,"img":false}]}
{"op":"mcm","clk":"11540754789","pt":1719498041235,"mc":[{"id":"1.230178312","rc":[{"atb":[[6.4,0.05]],"id":68462283},{"atb":[[5.2,0.9]],"id":52951653}],"con":true,"img":false}]}
{"op":"mcm","clk":"11540754840","pt":1719498041701,"mc":[{"id":"1.230178312","rc":[{"atb":[[5.3,0]],"id":52951653}],"con":true,"img":false}]}
{"op":"mcm","clk":"11540754850","pt":1719498041804,"mc":[{"id":"1.230178312","rc":[{"atb":[[5.2,2.9]],"id":52951653}],"con":true,"img":false}]}
{"op":"mcm","clk":"11540754891","pt":1719498042218,"mc":[{"id":"1.230178312","rc":[{"atb":[[5.4,0]],"id":52951653}],"con":true,"img":false}]}
{"op":"mcm","clk":"11540754932","pt":1719498042630,"mc":[{"id":"1.230178312","rc":[{"atl":[[7,0.86]],"id":56913144}],"con":true,"img":false}]}
{"op":"mcm","clk":"11540755187","pt":1719498045306,"mc":[{"id":"1.230178312","rc":[{"atl":[[7.2,0]],"id":56913144}],"con":true,"img":false}]}
{"op":"mcm","clk":"11540755226","pt":1719498045716,"mc":[{"id":"1.230178312","rc":[{"atl":[[7,0.02]],"id":56913144}],"con":true,"img":false}]}
{"op":"mcm","clk":"11540755354","pt":1719498047312,"mc":[{"id":"1.230178312","rc":[{"atl":[[7.2,2]],"id":56913144}],"con":true,"img":false}]}
{"op":"mcm","clk":"11540755575","pt":1719498050147,"mc":[{"id":"1.230178312","rc":[{"atl":[[7,0.86]],"id":56913144}],"con":true,"img":false}]}
{"op":"mcm","clk":"11540755789","pt":1719498052627,"mc":[{"id":"1.230178312","rc":[{"atl":[[7.2,0]],"id":56913144}],"con":true,"img":false}]}
{"op":"mcm","clk":"11540755833","pt":1719498053144,"mc":[{"id":"1.230178312","rc":[{"atl":[[7,0.02]],"id":56913144}],"con":true,"img":false}]}
{"op":"mcm","clk":"11540755960","pt":1719498054543,"mc":[{"id":"1.230178312","rc":[{"atl":[[7.2,2]],"id":56913144}],"con":true,"img":false}]}
{"op":"mcm","clk":"11540756220","pt":1719498057634,"mc":[{"id":"1.230178312","rc":[{"atl":[[7,0.86]],"id":56913144}],"con":true,"img":false}]}
{"op":"mcm","clk":"11540756425","pt":1719498059742,"mc":[{"id":"1.230178312","rc":[{"atl":[[7.2,0]],"id":56913144}],"con":true,"img":false}]}
{"op":"mcm","clk":"11540756451","pt":1719498060152,"mc":[{"id":"1.230178312","rc":[{"atl":[[7,0.02]],"id":56913144}],"con":true,"img":false}]}
{"op":"mcm","clk":"11540756562","pt":1719498061339,"mc":[{"id":"1.230178312","rc":[{"atb":[[1.03,1.7]],"id":39100893},{"atl":[[1000,1.7]],"id":39100893},{"atb":[[1.06,1.7],[1.04,1.7]],"id":52951653},{"atl":[[1000,1.87]],"id":52951653},{"atl":[[1000,1.87]],"id":51441055}],"con":true,"img":false}]}
{"op":"mcm","clk":"11540756590","pt":1719498061647,"mc":[{"id":"1.230178312","rc":[{"atb":[[1.03,0.08]],"id":39100893},{"atl":[[1000,0]],"id":39100893},{"atb":[[1.06,0.04],[1.04,0.06]],"id":52951653},{"atl":[[1000,0.18]],"id":52951653},{"atl":[[1000,0.18]],"id":51441055}],"con":true,"img":false}]}
{"op":"mcm","clk":"11540756610","pt":1719498061853,"mc":[{"id":"1.230178312","rc":[{"atl":[[7.2,2]],"id":56913144},{"atb":[[1.03,0]],"id":39100893},{"atl":[[1000,0]],"id":39100893}],"con":true,"img":false}]}
{"op":"mcm","clk":"11540756619","pt":1719498061956,"mc":[{"id":"1.230178312","rc":[{"atb":[[4.5,0.08]],"id":39100893},{"atl":[[38,0]],"id":39100893},{"atb":[[1.06,0],[1.04,0]],"id":52951653},{"atl":[[1000,0.16]],"id":52951653},{"atl":[[1000,0.16]],"id":51441055}],"con":true,"img":false}]}
{"op":"mcm","clk":"11540756631","pt":1719498062059,"mc":[{"id":"1.230178312","rc":[{"atb":[[5.3,0.11]],"id":52951653},{"atl":[[25,0.01]],"id":52951653},{"atl":[[9.8,0.02]],"id":51441055}],"con":true,"img":false}]}
{"op":"mcm","clk":"11540756650","pt":1719498062215,"mc":[{"id":"1.230178312","rc":[{"atb":[[5.1,0]],"id":39100893}],"con":true,"img":false}]}
{"op":"mcm","clk":"11540756662","pt":1719498062319,"mc":[{"id":"1.230178312","rc":[{"atb":[[5.2,2.84]],"id":52951653}],"con":true,"img":false}]}
{"op":"mcm","clk":"11540756684","pt":1719498062627,"mc":[{"id":"1.230178312","rc":[{"atb":[[5.6,1.48]],"id":70681331},{"atb":[[1.12,1.69]],"id":39100893}],"con":true,"img":false}]}
{"op":"mcm","clk":"11540756702","pt":1719498062937,"mc":[{"id":"1.230178312","rc":[{"atb":[[1.14,1.69]],"id":70681331}],"con":true,"img":false}]}
{"op":"mcm","clk":"11540756724","pt":1719498063143,"mc":[{"id":"1.230178312","rc":[{"atb":[[1.12,0.05]],"id":39100893},{"atb":[[1.12,1.69]],"id":52951653}],"con":true,"img":false}]}
{"op":"mcm","clk":"11540756755","pt":1719498063463,"mc":[{"id":"1.230178312","rc":[{"atb":[[1.14,0.05]],"id":70681331},{"atb":[[1.12,0]],"id":39100893}],"con":true,"img":false}]}
{"op":"mcm","clk":"11540756763","pt":1719498063554,"mc":[{"id":"1.230178312","rc":[{"atb":[[5.1,0.05]],"id":39100893}],"con":true,"img":false}]}
{"op":"mcm","clk":"11540756784","pt":1719498063874,"mc":[{"id":"1.230178312","rc":[{"atb":[[1.14,0]],"id":70681331}],"con":true,"img":false}]}
{"op":"mcm","clk":"11540756793","pt":1719498063968,"mc":[{"id":"1.230178312","rc":[{"atb":[[5.7,0.05]],"id":70681331},{"atb":[[1.12,0.05]],"id":52951653}],"con":true,"img":false}]}
{"op":"mcm","clk":"11540756830","pt":1719498064331,"mc":[{"id":"1.230178312","rc":[{"spn":2.78,"spf":1.2,"id":56913144},{"spn":4.81,"spf":1.0,"id":68462283},{"spn":4.58,"spf":1.0,"id":70681331},{"spn":3.78,"spf":1.0,"id":39100893},{"atb":[[1.12,0]],"id":52951653},{"spn":5.2,"spf":1.0,"id":52951653},{"spn":9.99,"spf":31.71,"id":51441055}],"con":true,"img":false}]}
{"op":"mcm","clk":"11540756844","pt":1719498064436,"mc":[{"id":"1.230178312","rc":[{"atb":[[5.3,0.16]],"id":52951653}],"con":true,"img":false}]}
{"op":"mcm","clk":"11540756881","pt":1719498064847,"mc":[{"id":"1.230178312","rc":[{"atb":[[5.1,0.94]],"id":51441055}],"con":true,"img":false}]}
{"op":"mcm","clk":"11540756904","pt":1719498065054,"mc":[{"id":"1.230178312","rc":[{"atl":[[7,0.86]],"id":56913144}],"con":true,"img":false}]}
{"op":"mcm","clk":"11540756914","pt":1719498065158,"mc":[{"id":"1.230178312","rc":[{"atb":[[6.4,0]],"id":68462283}],"con":true,"img":false}]}
{"op":"mcm","clk":"11540756937","pt":1719498065364,"mc":[{"id":"1.230178312","rc":[{"atb":[[4.4,9.41],[4.7,0]],"id":68462283},{"atb":[[1.12,1.69]],"id":51441055}],"con":true,"img":false}]}
{"op":"mcm","clk":"11540756950","pt":1719498065466,"mc":[{"id":"1.230178312","rc":[{"atb":[[3.9,0.84]],"id":56913144}],"con":true,"img":false}]}
{"op":"mcm","clk":"11540756975","pt":1719498065726,"mc":[{"id":"1.230178312","rc":[{"atb":[[1.12,1.69]],"id":68462283}],"con":true,"img":false}]}
{"op":"mcm","clk":"11540756984","pt":1719498065828,"mc":[{"id":"1.230178312","rc":[{"atb":[[1.12,0.05]],"id":51441055}],"con":true,"img":false}]}
{"op":"mcm","clk":"11540757001","pt":1719498066035,"mc":[{"id":"1.230178312","rc":[{"atb":[[1.09,1.69]],"id":56913144}],"con":true,"img":false}]}
{"op":"mcm","clk":"11540757025","pt":1719498066344,"mc":[{"id":"1.230178312","rc":[{"atb":[[1.12,0]],"id":51441055}],"con":true,"img":false}]}
{"op":"mcm","clk":"11540757036","pt":1719498066447,"mc":[{"id":"1.230178312","rc":[{"atb":[[1.12,0.05]],"id":68462283},{"atb":[[5.1,1]],"id":51441055}],"con":true,"img":false}]}
{"op":"mcm","clk":"11540757063","pt":1719498066758,"mc":[{"id":"1.230178312","rc":[{"atb":[[1.09,0.07]],"id":56913144}],"con":true,"img":false}]}
{"op":"mcm","clk":"11540757084","pt":1719498066965,"mc":[{"id":"1.230178312","rc":[{"atb":[[1.12,0]],"id":68462283}],"con":true,"img":false}]}
{"op":"mcm","clk":"11540757095","pt":1719498067068,"mc":[{"id":"1.230178312","rc":[{"atl":[[7.2,0]],"id":56913144},{"atb":[[5.1,0.9]],"id":68462283}],"con":true,"img":false}]}
{"op":"mcm","clk":"11540757157","pt":1719498067536,"mc":[{"id":"1.230178312","rc":[{"atb":[[1.09,0]],"id":56913144}],"con":true,"img":false}]}
{"op":"mcm","clk":"11540757169","pt":1719498067638,"mc":[{"id":"1.230178312","rc":[{"atb":[[3.9,0.92]],"id":56913144},{"atl":[[7,0.02]],"id":56913144}],"con":true,"img":false}]}
{"op":"mcm","clk":"11540757338","pt":1719498069552,"mc":[{"id":"1.230178312","rc":[{"atl":[[26,0]],"id":52951653},{"atl":[[29,0]],"id":51441055}],"con":true,"img":false}]}
{"op":"mcm","clk":"11540757345","pt":1719498069656,"mc":[{"id":"1.230178312","rc":[{"atl":[[29,0]],"id":56913144},{"atl":[[23,0]],"id":68462283}],"con":true,"img":false}]}
{"op":"mcm","clk":"11540757354","pt":1719498069760,"mc":[{"id":"1.230178312","rc":[{"atl":[[7.2,2]],"id":56913144}],"con":true,"img":false}]}
{"op":"mcm","clk":"11540757370","pt":1719498069966,"mc":[{"id":"1.230178312","rc":[{"atl":[[18,0],[1000,0.84]],"id":68462283}],"con":true,"img":false}]}
{"op":"mcm","clk":"11540757405","pt":1719498070328,"mc":[{"id":"1.230178312","rc":[{"atl":[[1000,0.47]],"id":68462283}],"con":true,"img":false}]}
{"op":"mcm","clk":"11540757445","pt":1719498070741,"mc":[{"id":"1.230178312","rc":[{"atl":[[1000,0]],"id":68462283}],"con":true,"img":false}]}
{"op":"mcm","clk":"11540757457","pt":1719498070843,"mc":[{"id":"1.230178312","rc":[{"atl":[[23,0.47]],"id":68462283}],"con":true,"img":false}]}
{"op":"mcm","clk":"11540757567","pt":1719498072034,"mc":[{"id":"1.230178312","rc":[{"atl":[[7,0.86]],"id":56913144}],"con":true,"img":false}]}
{"op":"mcm","clk":"11540757601","pt":1719498072342,"mc":[{"id":"1.230178312","rc":[{"atl":[[23,0],[1000,0.84]],"id":68462283}],"con":true,"img":false}]}
{"op":"mcm","clk":"11540757640","pt":1719498072754,"mc":[{"id":"1.230178312","rc":[{"atl":[[1000,0.47]],"id":68462283}],"con":true,"img":false}]}
{"op":"mcm","clk":"11540757674","pt":1719498073171,"mc":[{"id":"1.230178312","rc":[{"atl":[[1000,0]],"id":68462283}],"con":true,"img":false}]}
{"op":"mcm","clk":"11540757684","pt":1719498073275,"mc":[{"id":"1.230178312","rc":[{"atl":[[18,0.47]],"id":68462283}],"con":true,"img":false}]}
{"op":"mcm","clk":"11540757864","pt":1719498075038,"mc":[{"id":"1.230178312","rc":[{"atl":[[7.2,0]],"id":56913144}],"con":true,"img":false}]}
{"op":"mcm","clk":"11540757927","pt":1719498075657,"mc":[{"id":"1.230178312","rc":[{"atl":[[7,0.02]],"id":56913144}],"con":true,"img":false}]}
{"op":"mcm","clk":"11540758028","pt":1719498076533,"mc":[{"id":"1.230178312","rc":[{"atl":[[9.6,0.88]],"id":51441055}],"con":true,"img":false}]}
{"op":"mcm","clk":"11540758037","pt":1719498076636,"mc":[{"id":"1.230178312","rc":[{"atb":[[5.6,0]],"id":70681331}],"con":true,"img":false}]}
{"op":"mcm","clk":"11540758055","pt":1719498076844,"mc":[{"id":"1.230178312","rc":[{"atb":[[5.8,1.45]],"id":70681331},{"atl":[[10,0.89]],"id":51441055}],"con":true,"img":false}]}
{"op":"mcm","clk":"11540758087","pt":1719498077153,"mc":[{"id":"1.230178312","rc":[{"atl":[[7.2,2]],"id":56913144},{"atb":[[5.8,0]],"id":70681331}],"con":true,"img":false}]}
{"op":"mcm","clk":"11540758110","pt":1719498077358,"mc":[{"id":"1.230178312","rc":[{"atb":[[5.6,1.45]],"id":70681331}],"con":true,"img":false}]}
{"op":"mcm","clk":"11540758319","pt":1719498079371,"mc":[{"id":"1.230178312","rc":[{"atb":[[6,2.14]],"id":68462283}],"con":true,"img":false}]}
{"op":"mcm","clk":"11540758341","pt":1719498079577,"mc":[{"id":"1.230178312","rc":[{"atl":[[7,0.86]],"id":56913144},{"atb":[[6.2,0.84]],"id":68462283}],"con":true,"img":false}]}
{"op":"mcm","clk":"11540758353","pt":1719498079630,"mc":[{"id":"1.230178312","rc":[{"atl":[[7.4,0],[7,2.07]],"id":56913144},{"atb":[[5.1,0.05]],"id":68462283}],"con":true,"img":false}]}
{"op":"mcm","clk":"11540758620","pt":1719498082433,"mc":[{"id":"1.230178312","rc":[{"atl":[[7.2,0]],"id":56913144}],"con":true,"img":false}]}
{"op":"mcm","clk":"11540758689","pt":1719498083267,"mc":[{"id":"1.230178312","rc":[{"atb":[[6,0]],"id":68462283}],"con":true,"img":false}]}
{"op":"mcm","clk":"11540758738","pt":1719498083681,"mc":[{"id":"1.230178312","rc":[{"atb":[[6.2,0]],"id":68462283}],"con":true,"img":false}]}
{"op":"mcm","clk":"11540758796","pt":1719498084354,"mc":[{"id":"1.230178312","rc":[{"atl":[[6.8,2]],"id":56913144}],"con":true,"img":false}]}
{"op":"mcm","clk":"11540758885","pt":1719498085279,"mc":[{"id":"1.230178312","rc":[{"atl":[[7,2.05]],"id":56913144}],"con":true,"img":false}]}
{"op":"mcm","clk":"11540758896","pt":1719498085381,"mc":[{"id":"1.230178312","rc":[{"atl":[[6.6,0.02]],"id":56913144}],"con":true,"img":false}]}
{"op":"mcm","clk":"11540759029","pt":1719498087084,"mc":[{"id":"1.230178312","rc":[{"atl":[[6.6,0.86]],"id":56913144},{"atb":[[5.1,0.9]],"id":68462283}],"con":true,"img":false}]}
{"op":"mcm","clk":"11540759243","pt":1719498089567,"mc":[{"id":"1.230178312","rc":[{"atl":[[6.8,0]],"id":56913144}],"con":true,"img":false}]}
{"op":"mcm","clk":"11540759290","pt":1719498090186,"mc":[{"id":"1.230178312","rc":[{"atl":[[6.6,0.02]],"id":56913144}],"con":true,"img":false}]}
{"op":"mcm","clk":"11540759393","pt":1719498091578,"mc":[{"id":"1.230178312","rc":[{"atl":[[6.8,2]],"id":56913144}],"con":true,"img":false}]}
{"op":"mcm","clk":"11540759619","pt":1719498094055,"mc":[{"id":"1.230178312","rc":[{"atl":[[6.6,0.86]],"id":56913144}],"con":true,"img":false}]}
{"op":"mcm","clk":"11540759860","pt":1719498096801,"mc":[{"id":"1.230178312","rc":[{"atl":[[6.8,0]],"id":56913144}],"con":true,"img":false}]}
{"op":"mcm","clk":"11540759891","pt":1719498097059,"mc":[{"id":"1.230178312","rc":[{"atl":[[6.6,0.02]],"id":56913144}],"con":true,"img":false}]}
{"op":"mcm","clk":"11540760047","pt":1719498098762,"mc":[{"id":"1.230178312","rc":[{"atl":[[6.8,2]],"id":56913144}],"con":true,"img":false}]}
{"op":"mcm","clk":"11540760305","pt":1719498101192,"mc":[{"id":"1.230178312","rc":[{"atl":[[6.6,0.86]],"id":56913144}],"con":true,"img":false}]}
{"op":"mcm","clk":"11540760578","pt":1719498104050,"mc":[{"id":"1.230178312","rc":[{"atl":[[6.8,0]],"id":56913144}],"con":true,"img":false}]}
{"op":"mcm","clk":"11540760634","pt":1719498104669,"mc":[{"id":"1.230178312","rc":[{"atl":[[6.6,0.02]],"id":56913144}],"con":true,"img":false}]}
{"op":"mcm","clk":"11540760795","pt":1719498106581,"mc":[{"id":"1.230178312","rc":[{"atb":[[5.8,1.45],[5.6,0]],"id":70681331}],"con":true,"img":false}]}
{"op":"mcm","clk":"11540760817","pt":1719498106790,"mc":[{"id":"1.230178312","rc":[{"atl":[[6.8,2]],"id":56913144}],"con":true,"img":false}]}
{"op":"mcm","clk":"11540760854","pt":1719498107207,"mc":[{"id":"1.230178312","rc":[{"atb":[[5.8,0],[5.6,1.45]],"id":70681331}],"con":true,"img":false}]}
{"op":"mcm","clk":"11540760952","pt":1719498108398,"mc":[{"id":"1.230178312","rc":[{"atb":[[4.5,0]],"id":39100893},{"atl":[[38,0]],"id":39100893},{"atb":[[5.3,0.05]],"id":52951653},{"atl":[[25,0]],"id":52951653},{"atb":[[5.1,0.9]],"id":51441055},{"atl":[[10,0.84],[9.8,0]],"id":51441055}],"con":true,"img":false}]}
{"op":"mcm","clk":"11540760981","pt":1719498108604,"mc":[{"id":"1.230178312","rc":[{"atl":[[6.6,0.86]],"id":56913144}],"con":true,"img":false}]}
{"op":"mcm","clk":"11540761300","pt":1719498111985,"mc":[{"id":"1.230178312","rc":[{"atl":[[6.8,0]],"id":56913144}],"con":true,"img":false}]}
{"op":"mcm","clk":"11540761372","pt":1719498112709,"mc":[{"id":"1.230178312","rc":[{"atl":[[6.6,0.02]],"id":56913144}],"con":true,"img":false}]}
{"op":"mcm","clk":"11540761495","pt":1719498114101,"mc":[{"id":"1.230178312","rc":[{"atl":[[6.8,2]],"id":56913144}],"con":true,"img":false}]}
{"op":"mcm","clk":"11540761631","pt":1719498115595,"mc":[{"id":"1.230178312","rc":[{"atl":[[6.6,0.86]],"id":56913144}],"con":true,"img":false}]}
{"op":"mcm","clk":"11540761926","pt":1719498119301,"mc":[{"id":"1.230178312","rc":[{"atl":[[6.8,0]],"id":56913144}],"con":true,"img":false}]}
{"op":"mcm","clk":"11540761947","pt":1719498119611,"mc":[{"id":"1.230178312","rc":[{"atl":[[6.6,0.02]],"id":56913144}],"con":true,"img":false}]}
{"op":"mcm","clk":"11540761972","pt":1719498119918,"mc":[{"id":"1.230178312","rc":[{"atb":[[5.1,1.71]],"id":68462283},{"atb":[[5.7,0.84]],"id":70681331},{"atb":[[5.1,0.84]],"id":39100893},{"atb":[[5.3,0.84]],"id":52951653}],"con":true,"img":false}]}
{"op":"mcm","clk":"11540762030","pt":1719498120589,"mc":[{"id":"1.230178312","rc":[{"atb":[[5.7,1.68]],"id":70681331}],"con":true,"img":false}]}
{"op":"mcm","clk":"11540762059","pt":1719498120898,"mc":[{"id":"1.230178312","rc":[{"atb":[[5.8,1.45],[5.6,0]],"id":70681331}],"con":true,"img":false}]}
{"op":"mcm","clk":"11540762104","pt":1719498121623,"mc":[{"id":"1.230178312","rc":[{"atl":[[6.8,2]],"id":56913144}],"con":true,"img":false}]}
{"op":"mcm","clk":"11540762240","pt":1719498123235,"mc":[{"id":"1.230178312","rc":[{"atl":[[6.6,0.86]],"id":56913144}],"con":true,"img":false}]}
{"op":"mcm","clk":"11540762578","pt":1719498126496,"mc":[{"id":"1.230178312","rc":[{"atl":[[9.8,8],[8.4,0]],"id":56913144},{"atb":[[4.6,0]],"id":68462283},{"spn":4.66,"spf":1.0,"id":68462283},{"spn":4.93,"spf":1.0,"id":70681331},{"atl":[[40,0],[60,2]],"id":39100893},{"spn":3.93,"spf":1.0,"id":39100893},{"spn":5.24,"spf":1.0,"id":52951653},{"atl":[[10.5,1],[12,8]],"id":51441055},{"spn":9.81,"spf":31.71,"id":51441055}],"con":true,"img":false}]}
{"op":"mcm","clk":"11540762590","pt":1719498126599,"mc":[{"id":"1.230178312","rc":[{"atb":[[4,1]],"id":56913144},{"atb":[[5.2,1]],"id":68462283},{"atl":[[46,1]],"id":52951653}],"con":true,"img":false}]}
{"op":"mcm","clk":"11540762616","pt":1719498126805,"mc":[{"id":"1.230178312","rc":[{"atl":[[6.8,0]],"id":56913144}],"con":true,"img":false}]}
{"op":"mcm","clk":"11540762643","pt":1719498127113,"mc":[{"id":"1.230178312","rc":[{"atl":[[6.6,0.02]],"id":56913144}],"con":true,"img":false}]}
{"op":"mcm","clk":"11540762701","pt":1719498127733,"mc":[{"id":"1.230178312","rc":[{"atb":[[1.25,20]],"id":56913144},{"atb":[[1.25,20]],"id":68462283},{"atb":[[1.25,20]],"id":70681331},{"atb":[[1.25,20]],"id":39100893},{"atb":[[1.25,20]],"id":52951653},{"atb":[[1.25,20]],"id":51441055}],"con":true,"img":false}]}
{"op":"mcm","clk":"11540762799","pt":1719498128814,"mc":[{"id":"1.230178312","rc":[{"atb":[[3.85,0]],"id":56913144}],"con":true,"img":false}]}
{"op":"mcm","clk":"11540762809","pt":1719498128917,"mc":[{"id":"1.230178312","rc":[{"atb":[[4.1,2]],"id":56913144},{"atl":[[6.8,2]],"id":56913144}],"con":true,"img":false}]}
{"op":"mcm","clk":"11540762886","pt":1719498129639,"mc":[{"id":"1.230178312","rc":[{"atb":[[3.9,0.07],[4.2,0.84]],"id":56913144}],"con":true,"img":false}]}
{"op":"mcm","clk":"11540762964","pt":1719498130616,"mc":[{"id":"1.230178312","rc":[{"atl":[[6.6,0.86]],"id":56913144}],"con":true,"img":false}]}
{"op":"mcm","clk":"11540763269","pt":1719498134228,"mc":[{"id":"1.230178312","rc":[{"atl":[[6.8,0]],"id":56913144}],"con":true,"img":false}]}
{"op":"mcm","clk":"11540763304","pt":1719498134638,"mc":[{"id":"1.230178312","rc":[{"atl":[[6.6,0.02]],"id":56913144}],"con":true,"img":false}]}
{"op":"mcm","clk":"11540763490","pt":1719498136644,"mc":[{"id":"1.230178312","rc":[{"atl":[[9.8,0.88]],"id":51441055}],"con":true,"img":false}]}
{"op":"mcm","clk":"11540763507","pt":1719498136696,"mc":[{"id":"1.230178312","rc":[{"atl":[[9.6,0]],"id":51441055}],"con":true,"img":false}]}
{"op":"mcm","clk":"11540763518","pt":1719498136800,"mc":[{"id":"1.230178312","rc":[{"atl":[[6.8,2]],"id":56913144}],"con":true,"img":false}]}
{"op":"mcm","clk":"11540763574","pt":1719498137417,"mc":[{"id":"1.230178312","rc":[{"atl":[[18.5,0],[15,1]],"id":68462283}],"con":true,"img":false}]}
{"op":"mcm","clk":"11540763581","pt":1719498137518,"mc":[{"id":"1.230178312","rc":[{"atl":[[19.5,5.41],[24,1.66]],"id":68462283}],"con":true,"img":false}]}
{"op":"mcm","clk":"11540763594","pt":1719498137724,"mc":[{"id":"1.230178312","rc":[{"atl":[[18,0],[1000,0.84]],"id":68462283}],"con":true,"img":false}]}
{"op":"mcm","clk":"11540763626","pt":1719498138032,"mc":[{"id":"1.230178312","rc":[{"atb":[[5.3,1.6]],"id":68462283},{"atl":[[8.6,0.98]],"id":52951653}],"con":true,"img":false}]}
{"op":"mcm","clk":"11540763631","pt":1719498138136,"mc":[{"id":"1.230178312","rc":[{"atl":[[6.6,0.86]],"id":56913144}],"con":true,"img":false}]}
{"op":"mcm","clk":"11540763651","pt":1719498138343,"mc":[{"id":"1.230178312","rc":[{"atl":[[1000,0.47]],"id":68462283},{"atl":[[8.6,0.98]],"id":39100893}],"con":true,"img":false}]}
{"op":"mcm","clk":"11540763680","pt":1719498138601,"mc":[{"id":"1.230178312","rc":[{"atl":[[1000,0]],"id":68462283}],"con":true,"img":false}]}
{"op":"mcm","clk":"11540763690","pt":1719498138704,"mc":[{"id":"1.230178312","rc":[{"atl":[[23,0.47]],"id":68462283}],"con":true,"img":false}]}
{"op":"mcm","clk":"11540763759","pt":1719498139532,"mc":[{"id":"1.230178312","rc":[{"atl":[[27,2]],"id":52951653}],"con":true,"img":false}]}
{"op":"mcm","clk":"11540763897","pt":1719498140827,"mc":[{"id":"1.230178312","rc":[{"atl":[[8.6,8],[9.8,0]],"id":56913144},{"atl":[[44,2.33],[60,0]],"id":39100893},{"atl":[[10.5,9],[12,0]],"id":51441055}],"con":true,"img":false}]}
{"op":"mcm","clk":"11540764016","pt":1719498142016,"mc":[{"id":"1.230178312","rc":[{"atl":[[6.8,0]],"id":56913144},{"atb":[[5.1,0.9]],"id":68462283},{"atb":[[5.7,0.89]],"id":70681331},{"atb":[[5.1,0.05]],"id":39100893}],"con":true,"img":false}]}
{"op":"mcm","clk":"11540764046","pt":1719498142326,"mc":[{"id":"1.230178312","rc":[{"atb":[[5.8,0]],"id":70681331}],"con":true,"img":false}]}
{"op":"mcm","clk":"11540764073","pt":1719498142635,"mc":[{"id":"1.230178312","rc":[{"atl":[[6.6,0.02]],"id":56913144},{"atl":[[23,5.02]],"id":68462283},{"atb":[[5.7,0.05]],"id":70681331}],"con":true,"img":false}]}
{"op":"mcm","clk":"11540764083","pt":1719498142737,"mc":[{"id":"1.230178312","rc":[{"atl":[[19.5,0]],"id":68462283}],"con":true,"img":false}]}
{"op":"mcm","clk":"11540764207","pt":1719498144031,"mc":[{"id":"1.230178312","rc":[{"atl":[[6.8,2]],"id":56913144}],"con":true,"img":false}]}
{"op":"mcm","clk":"11540764352","pt":1719498145629,"mc":[{"id":"1.230178312","rc":[{"atl":[[6.6,0.86]],"id":56913144}],"con":true,"img":false}]}
{"op":"mcm","clk":"11540764434","pt":1719498146554,"mc":[{"id":"1.230178312","rc":[{"atl":[[1000,1.7]],"id":39100893}],"con":true,"img":false}]}
{"op":"mcm","clk":"11540764444","pt":1719498146606,"mc":[{"id":"1.230178312","rc":[{"atb":[[1.04,1.7]],"id":39100893},{"atl":[[1000,5.1]],"id":39100893},{"atl":[[1000,5.27]],"id":52951653}],"con":true,"img":false}]}
{"op":"mcm","clk":"11540764455","pt":1719498146709,"mc":[{"id":"1.230178312","rc":[{"atb":[[1.05,3.4]],"id":39100893},{"atl":[[1000,3.43]],"id":39100893},{"atb":[[1.06,1.7],[1.05,3.4]],"id":52951653}],"con":true,"img":false}]}
{"op":"mcm","clk":"11540764466","pt":1719498146918,"mc":[{"id":"1.230178312","rc":[{"atb":[[1.04,0.05]],"id":39100893},{"atl":[[1000,0.07]],"id":39100893},{"atl":[[1000,0.24]],"id":52951653}],"con":true,"img":false}]}
{"op":"mcm","clk":"11540764472","pt":1719498147022,"mc":[{"id":"1.230178312","rc":[{"atb":[[1.05,0.1]],"id":39100893},{"atl":[[1000,0.04]],"id":39100893},{"atb":[[1.06,0.04],[1.05,0.09]],"id":52951653}],"con":true,"img":false}]}
{"op":"mcm","clk":"11540764484","pt":1719498147126,"mc":[{"id":"1.230178312","rc":[{"atb":[[1.04,0]],"id":39100893},{"atl":[[8.6,1],[1000,0]],"id":39100893},{"atl":[[1000,0.16]],"id":52951653}],"con":true,"img":false}]}
{"op":"mcm","clk":"11540764494","pt":1719498147229,"mc":[{"id":"1.230178312","rc":[{"atb":[[4.5,0.05],[1.05,0]],"id":39100893},{"atl":[[8.6,1.05],[9.4,4]],"id":39100893},{"atb":[[1.06,0],[1.05,0]],"id":52951653},{"atl":[[8.6,1.05]],"id":52951653}],"con":true,"img":false}]}
{"op":"mcm","clk":"11540764506","pt":1719498147334,"mc":[{"id":"1.230178312","rc":[{"atb":[[4.5,0.16]],"id":39100893},{"atl":[[44,0]],"id":39100893},{"atb":[[5.3,0.98]],"id":52951653},{"atl":[[8.6,3.05]],"id":52951653}],"con":true,"img":false}]}
{"op":"mcm","clk":"11540764516","pt":1719498147435,"mc":[{"id":"1.230178312","rc":[{"atl":[[46,0],[27,0]],"id":52951653}],"con":true,"img":false}]}
{"op":"mcm","clk":"11540764529","pt":1719498147640,"mc":[{"id":"1.230178312","rc":[{"atl":[[8.4,0.84]],"id":52951653}],"con":true,"img":false}]}
{"op":"mcm","clk":"11540764538","pt":1719498147742,"mc":[{"id":"1.230178312","rc":[{"atl":[[27,1]],"id":52951653}],"con":true,"img":false}]}
{"op":"mcm","clk":"11540764667","pt":1719498149341,"mc":[{"id":"1.230178312","rc":[{"atl":[[6.8,0]],"id":56913144}],"con":true,"img":false}]}
{"op":"mcm","clk":"11540764701","pt":1719498149754,"mc":[{"id":"1.230178312","rc":[{"atl":[[6.6,0.02]],"id":56913144}],"con":true,"img":false}]}
{"op":"mcm","clk":"11540764836","pt":1719498151246,"mc":[{"id":"1.230178312","rc":[{"atl":[[6.8,2]],"id":56913144}],"con":true,"img":false}]}
{"op":"mcm","clk":"11540764952","pt":1719498152639,"mc":[{"id":"1.230178312","rc":[{"spl":[[1.01,104.64]],"id":56913144},{"atl":[[6.6,0.86]],"id":56913144}],"con":true,"img":false}]}
{"op":"mcm","clk":"11540765102","pt":1719498154339,"mc":[{"id":"1.230178312","rc":[{"atb":[[5.3,0.19]],"id":52951653}],"con":true,"img":false}]}
{"op":"mcm","clk":"11540765314","pt":1719498156457,"mc":[{"id":"1.230178312","rc":[{"atl":[[6.8,0]],"id":56913144}],"con":true,"img":false}]}
{"op":"mcm","clk":"11540765373","pt":1719498157130,"mc":[{"id":"1.230178312","rc":[{"atl":[[6.6,0.02]],"id":56913144}],"con":true,"img":false}]}
{"op":"mcm","clk":"11540765386","pt":1719498157336,"mc":[{"id":"1.230178312","rc":[{"atb":[[4.6,1]],"id":68462283},{"atl":[[18.5,1],[15,0]],"id":68462283}],"con":true,"img":false}]}
{"op":"mcm","clk":"11540765396","pt":1719498157442,"mc":[{"id":"1.230178312","rc":[{"atl":[[19.5,5.02],[23,0.47]],"id":68462283}],"con":true,"img":false}]}
{"op":"mcm","clk":"11540765416","pt":1719498157646,"mc":[{"id":"1.230178312","rc":[{"atb":[[5.6,1.51]],"id":70681331}],"con":true,"img":false}]}
{"op":"mcm","clk":"11540765458","pt":1719498158061,"mc":[{"id":"1.230178312","rc":[{"atl":[[18.5,0],[15,1]],"id":68462283}],"con":true,"img":false}]}
{"op":"mcm","clk":"11540765473","pt":1719498158166,"mc":[{"id":"1.230178312","rc":[{"atb":[[4.6,0]],"id":68462283}],"con":true,"img":false}]}
{"op":"mcm","clk":"11540765505","pt":1719498158474,"mc":[{"id":"1.230178312","rc":[{"atl":[[6.8,2]],"id":56913144}],"con":true,"img":false}]}
{"op":"mcm","clk":"11540765612","pt":1719498159659,"mc":[{"id":"1.230178312","rc":[{"atl":[[6.6,0.86]],"id":56913144}],"con":true,"img":false}]}
{"op":"mcm","clk":"11540765910","pt":1719498162551,"mc":[{"id":"1.230178312","rc":[{"atl":[[19.5,0],[23,5.02]],"id":68462283}],"con":true,"img":false}]}
{"op":"mcm","clk":"11540765995","pt":1719498163736,"mc":[{"id":"1.230178312","rc":[{"atl":[[6.8,0]],"id":56913144}],"con":true,"img":false}]}
{"op":"mcm","clk":"11540766030","pt":1719498164147,"mc":[{"id":"1.230178312","rc":[{"atl":[[6.6,0.02]],"id":56913144}],"con":true,"img":false}]}
{"op":"mcm","clk":"11540766169","pt":1719498165754,"mc":[{"id":"1.230178312","rc":[{"atl":[[6.8,2]],"id":56913144}],"con":true,"img":false}]}
{"op":"mcm","clk":"11540766249","pt":1719498166676,"mc":[{"id":"1.230178312","rc":[{"atl":[[6.6,0.86]],"id":56913144}],"con":true,"img":false}]}
{"op":"mcm","clk":"11540766651","pt":1719498171065,"mc":[{"id":"1.230178312","rc":[{"atl":[[6.8,0]],"id":56913144}],"con":true,"img":false}]}
{"op":"mcm","clk":"11540766714","pt":1719498171686,"mc":[{"id":"1.230178312","rc":[{"atl":[[6.6,0.02]],"id":56913144}],"con":true,"img":false}]}
{"op":"mcm","clk":"11540766913","pt":1719498173648,"mc":[{"id":"1.230178312","rc":[{"atl":[[6.8,2]],"id":56913144}],"con":true,"img":false}]}
{"op":"mcm","clk":"11540766955","pt":1719498174065,"mc":[{"id":"1.230178312","rc":[{"atl":[[6.6,0.86]],"id":56913144}],"con":true,"img":false}]}
{"op":"mcm","clk":"11540767352","pt":1719498178475,"mc":[{"id":"1.230178312","rc":[{"atb":[[4.6,1]],"id":68462283}],"con":true,"img":false}]}
{"op":"mcm","clk":"11540767382","pt":1719498178881,"mc":[{"id":"1.230178312","rc":[{"atl":[[6.8,0]],"id":56913144}],"con":true,"img":false}]}
{"op":"mcm","clk":"11540767442","pt":1719498179658,"mc":[{"id":"1.230178312","rc":[{"atl":[[6.6,0.02]],"id":56913144}],"con":true,"img":false}]}
{"op":"mcm","clk":"11540767492","pt":1719498180292,"mc":[{"id":"1.230178312","rc":[{"atl":[[18.5,1]],"id":68462283}],"con":true,"img":false}]}
{"op":"mcm","clk":"11540767500","pt":1719498180385,"mc":[{"id":"1.230178312","rc":[{"atb":[[4.6,0]],"id":68462283},{"atl":[[15,0]],"id":68462283}],"con":true,"img":false}]}
{"op":"mcm","clk":"11540767526","pt":1719498180597,"mc":[{"id":"1.230178312","rc":[{"atb":[[4.2,7.75]],"id":56913144},{"atl":[[6.8,4.58]],"id":56913144},{"atb":[[5.3,6.8]],"id":68462283},{"atl":[[22,1.2]],"id":68462283},{"atb":[[5.7,5.38]],"id":70681331},{"atl":[[75,0.34]],"id":70681331},{"atb":[[3.5,10.27]],"id":39100893},{"atl":[[9.2,3.13]],"id":39100893},{"atl":[[8.4,3.94]],"id":52951653},{"atb":[[5.1,6.97]],"id":51441055},{"atl":[[10,3.78]],"id":51441055}],"con":true,"img":false}]}
{"op":"mcm","clk":"11540767540","pt":1719498180664,"mc":[{"id":"1.230178312","rc":[{"atb":[[5.8,1.45],[5.6,0]],"id":70681331},{"atl":[[8.2,3.06]],"id":52951653}],"con":true,"img":false}]}
{"op":"mcm","clk":"11540767553","pt":1719498180772,"mc":[{"id":"1.230178312","rc":[{"atb":[[4,0]],"id":56913144},{"atl":[[6.6,2.02]],"id":56913144},{"atb":[[5.2,0]],"id":68462283},{"atl":[[8.6,1.05]],"id":52951653}],"con":true,"img":false}]}
{"op":"mcm","clk":"11540767561","pt":1719498180864,"mc":[{"id":"1.230178312","rc":[{"atb":[[4.3,1]],"id":56913144},{"atb":[[5.4,1]],"id":68462283},{"atl":[[75,0.94]],"id":70681331},{"atl":[[27,0]],"id":52951653}],"con":true,"img":false}]}
{"op":"mcm","clk":"11540767576","pt":1719498180978,"mc":[{"id":"1.230178312","rc":[{"atl":[[14,0]],"id":70681331}],"con":true,"img":false}]}
{"op":"mcm","clk":"11540767583","pt":1719498181074,"mc":[{"id":"1.230178312","rc":[{"atl":[[8,1.84]],"id":52951653}],"con":true,"img":false}]}
{"op":"mcm","clk":"11540767598","pt":1719498181190,"mc":[{"id":"1.230178312","rc":[{"atl":[[6.6,6.79],[7,1.21]],"id":56913144},{"atb":[[5.1,0.05]],"id":68462283},{"atb":[[5.8,6.76]],"id":70681331},{"atl":[[8,5.14]],"id":52951653}],"con":true,"img":false}]}
{"op":"mcm","clk":"11540767616","pt":1719498181397,"mc":[{"id":"1.230178312","rc":[{"atl":[[6.4,3.97]],"id":56913144},{"atb":[[5.9,4.3]],"id":70681331}],"con":true,"img":false}]}
{"op":"mcm","clk":"11540767622","pt":1719498181493,"mc":[{"id":"1.230178312","rc":[{"atl":[[75,0.34]],"id":70681331}],"con":true,"img":false}]}
{"op":"mcm","clk":"11540767642","pt":1719498181664,"mc":[{"id":"1.230178312","rc":[{"atl":[[6.4,4.81]],"id":56913144},{"atb":[[5.9,5.14]],"id":70681331},{"atb":[[5.2,0.84]],"id":52951653}],"con":true,"img":false}]}
{"op":"mcm","clk":"11540767652","pt":1719498181767,"mc":[{"id":"1.230178312","rc":[{"atl":[[1000,1.01]],"id":70681331},{"atb":[[1.02,2]],"id":52951653},{"atl":[[8.4,3.1]],"id":52951653}],"con":true,"img":false}]}
{"op":"mcm","clk":"11540767662","pt":1719498181876,"mc":[{"id":"1.230178312","rc":[{"atb":[[5.8,5.31]],"id":70681331}],"con":true,"img":false}]}
{"op":"mcm","clk":"11540767672","pt":1719498181981,"mc":[{"id":"1.230178312","rc":[{"atl":[[6.4,9.77],[6.6,6.77]],"id":56913144},{"atb":[[5.9,10.15]],"id":70681331},{"atb":[[3.1,10.68]],"id":52951653}],"con":true,"img":false}]}
{"op":"mcm","clk":"11540767683","pt":1719498182083,"mc":[{"id":"1.230178312","rc":[{"atb":[[4.1,0]],"id":56913144},{"atl":[[6.2,0.02]],"id":56913144},{"atl":[[7.8,3.25]],"id":52951653}],"con":true,"img":false}]}
{"op":"mcm","clk":"11540767694","pt":1719498182187,"mc":[{"id":"1.230178312","rc":[{"atb":[[1.02,24.65]],"id":56913144},{"atb":[[6,1.41]],"id":70681331}],"con":true,"img":false}]}
{"op":"mcm","clk":"11540767713","pt":1719498182395,"mc":[{"id":"1.230178312","rc":[{"atl":[[6.6,4.77]],"id":56913144},{"atl":[[1000,0.77]],"id":70681331}],"con":true,"img":false}]}
{"op":"mcm","clk":"11540767758","pt":1719498182799,"mc":[{"id":"1.230178312","rc":[{"atb":[[5.9,5.85]],"id":70681331}],"con":true,"img":false}]}
{"op":"mcm","clk":"11540767796","pt":1719498183074,"mc":[{"id":"1.230178312","rc":[{"atl":[[1000,0.16]],"id":70681331}],"con":true,"img":false}]}
{"op":"mcm","clk":"11540767809","pt":1719498183180,"mc":[{"id":"1.230178312","rc":[{"atl":[[14,0.6]],"id":70681331}],"con":true,"img":false}]}
{"op":"mcm","clk":"11540767836","pt":1719498183383,"mc":[{"id":"1.230178312","rc":[{"atb":[[6,5.86]],"id":70681331},{"atl":[[7.8,7.33]],"id":52951653}],"con":true,"img":false}]}
{"op":"mcm","clk":"11540767859","pt":1719498183593,"mc":[{"id":"1.230178312","rc":[{"atb":[[6.2,4.09],[5.7,5.33]],"id":70681331},{"atb":[[5.1,0]],"id":39100893},{"atl":[[8,4.14]],"id":52951653}],"con":true,"img":false}]}
{"op":"mcm","clk":"11540767882","pt":1719498183790,"mc":[{"id":"1.230178312","rc":[{"atl":[[7.6,1]],"id":52951653}],"con":true,"img":false}]}
{"op":"mcm","clk":"11540767916","pt":1719498184165,"mc":[{"id":"1.230178312","rc":[{"atb":[[5.9,5.01]],"id":70681331}],"con":true,"img":false}]}
{"op":"mcm","clk":"11540767933","pt":1719498184374,"mc":[{"id":"1.230178312","rc":[{"atl":[[7.8,4.08]],"id":52951653}],"con":true,"img":false}]}
{"op":"mcm","clk":"11540767971","pt":1719498184793,"mc":[{"id":"1.230178312","rc":[{"atb":[[1.14,1.69]],"id":70681331},{"atb":[[5.3,0.13]],"id":52951653}],"con":true,"img":false}]}
{"op":"mcm","clk":"11540767981","pt":1719498184895,"mc":[{"id":"1.230178312","rc":[{"atb":[[5,0]],"id":70681331},{"atb":[[1.05,1.7]],"id":39100893},{"atl":[[1000,1.7]],"id":39100893},{"atb":[[1.06,1.7]],"id":52951653},{"atl":[[1000,1.87]],"id":52951653},{"atb":[[1.06,1.7]],"id":51441055},{"atl":[[1000,1.87]],"id":51441055}],"con":true,"img":false}]}
{"op":"mcm","clk":"11540768004","pt":1719498185099,"mc":[{"id":"1.230178312","rc":[{"atb":[[1.14,0.05]],"id":70681331},{"atb":[[1.12,1.69],[1.05,0.04]],"id":39100893},{"atl":[[1000,0.02]],"id":39100893},{"atb":[[1.06,0.04]],"id":52951653},{"atl":[[1000,0.19]],"id":52951653},{"atb":[[1.06,0.04]],"id":51441055},{"atl":[[1000,0.18]],"id":51441055}],"con":true,"img":false}]}
{"op":"mcm","clk":"11540768024","pt":1719498185264,"mc":[{"id":"1.230178312","rc":[{"atl":[[1000,0.16]],"id":52951653}],"con":true,"img":false}]}
{"op":"mcm","clk":"11540768038","pt":1719498185369,"mc":[{"id":"1.230178312","rc":[{"atb":[[1.14,0]],"id":70681331},{"atb":[[1.12,0.05],[1.05,0]],"id":39100893},{"atl":[[1000,0]],"id":39100893},{"atb":[[1.06,0]],"id":52951653},{"atl":[[7.6,1.02]],"id":52951653},{"atb":[[1.06,0]],"id":51441055},{"atl":[[1000,0.16]],"id":51441055}],"con":true,"img":false}]}
{"op":"mcm","clk":"11540768049","pt":1719498185477,"mc":[{"id":"1.230178312","rc":[{"atb":[[6.4,0.05]],"id":70681331},{"atb":[[4.5,0.21]],"id":39100893},{"atl":[[8.6,1.08]],"id":39100893},{"atb":[[5.2,0.88]],"id":52951653},{"atb":[[5.2,0.04]],"id":51441055},{"atl":[[9.8,0.89]],"id":51441055}],"con":true,"img":false}]}
{"op":"mcm","clk":"11540768085","pt":1719498185776,"mc":[{"id":"1.230178312","rc":[{"atb":[[1.12,0]],"id":39100893}],"con":true,"img":false}]}
{"op":"mcm","clk":"11540768099","pt":1719498185882,"mc":[{"id":"1.230178312","rc":[{"atb":[[5.1,0.05]],"id":39100893}],"con":true,"img":false}]}
{"op":"mcm","clk":"11540768140","pt":1719498186210,"mc":[{"id":"1.230178312","rc":[{"atb":[[5.1,0]],"id":68462283},{"atb":[[5.1,6.91]],"id":51441055}],"con":true,"img":false}]}
{"op":"mcm","clk":"11540768173","pt":1719498186467,"mc":[{"id":"1.230178312","rc":[{"atb":[[1.12,1.69]],"id":51441055}],"con":true,"img":false}]}
{"op":"mcm","clk":"11540768191","pt":1719498186671,"mc":[{"id":"1.230178312","rc":[{"spn":2.53,"spf":1.1,"id":56913144},{"atb":[[1.12,1.69]],"id":68462283},{"spn":5.26,"spf":1.0,"id":68462283},{"spn":6.09,"spf":1.0,"id":70681331},{"spn":3.83,"spf":1.0,"id":39100893},{"spn":5.15,"spf":1.0,"id":52951653},{"spn":9.89,"spf":31.71,"id":51441055}],"con":true,"img":false}]}
{"op":"mcm","clk":"11540768212","pt":1719498186883,"mc":[{"id":"1.230178312","rc":[{"atb":[[1.12,0.05]],"id":51441055}],"con":true,"img":false}]}
{"op":"mcm","clk":"11540768236","pt":1719498187088,"mc":[{"id":"1.230178312","rc":[{"atb":[[1.12,0.05]],"id":68462283}],"con":true,"img":false}]}
{"op":"mcm","clk":"11540768252","pt":1719498187194,"mc":[{"id":"1.230178312","rc":[{"atl":[[8.2,0],[7.6,5.1]],"id":52951653}],"con":true,"img":false}]}
{"op":"mcm","clk":"11540768291","pt":1719498187495,"mc":[{"id":"1.230178312","rc":[{"atb":[[1.12,0]],"id":51441055}],"con":true,"img":false}]}
{"op":"mcm","clk":"11540768304","pt":1719498187601,"mc":[{"id":"1.230178312","rc":[{"atl":[[8,3.3]],"id":52951653},{"atb":[[5.2,0.1]],"id":51441055}],"con":true,"img":false}]}
{"op":"mcm","clk":"11540768340","pt":1719498187872,"mc":[{"id":"1.230178312","rc":[{"atb":[[3.9,0]],"id":56913144},{"atl":[[7.4,3.42]],"id":52951653}],"con":true,"img":false}]}
{"op":"mcm","clk":"11540768353","pt":1719498187973,"mc":[{"id":"1.230178312","rc":[{"atb":[[4.6,1]],"id":68462283},{"atl":[[18.5,0],[15,1]],"id":68462283},{"atl":[[7.6,1.02]],"id":52951653}],"con":true,"img":false}]}
{"op":"mcm","clk":"11540768363","pt":1719498188076,"mc":[{"id":"1.230178312","rc":[{"atl":[[6.2,2.02]],"id":56913144},{"atl":[[21,2],[23,0.47]],"id":68462283},{"atl":[[7.4,12.35]],"id":52951653}],"con":true,"img":false}]}
{"op":"mcm","clk":"11540768374","pt":1719498188180,"mc":[{"id":"1.230178312","rc":[{"atb":[[1.12,0]],"id":68462283}],"con":true,"img":false}]}
{"op":"mcm","clk":"11540768385","pt":1719498188288,"mc":[{"id":"1.230178312","rc":[{"atb":[[5.3,5.2],[5.4,1.05],[5.5,1.54]],"id":68462283},{"atl":[[7.6,0.02]],"id":52951653}],"con":true,"img":false}]}
{"op":"mcm","clk":"11540768411","pt":1719498188496,"mc":[{"id":"1.230178312","rc":[{"atl":[[7.2,1]],"id":52951653}],"con":true,"img":false}]}
{"op":"mcm","clk":"11540768425","pt":1719498188590,"mc":[{"id":"1.230178312","rc":[{"atl":[[6.4,5.8]],"id":56913144}],"con":true,"img":false}]}
{"op":"mcm","clk":"11540768450","pt":1719498188797,"mc":[{"id":"1.230178312","rc":[{"atl":[[6,4.23]],"id":56913144}],"con":true,"img":false}]}
{"op":"mcm","clk":"11540768471","pt":1719498188967,"mc":[{"id":"1.230178312","rc":[{"atb":[[5.7,0]],"id":70681331}],"con":true,"img":false}]}
{"op":"mcm","clk":"11540768479","pt":1719498189069,"mc":[{"id":"1.230178312","rc":[{"atl":[[6.4,4.96],[5.9,0.84]],"id":56913144},{"atb":[[6.4,0.89]],"id":70681331}],"con":true,"img":false}]}
{"op":"mcm","clk":"11540768506","pt":1719498189380,"mc":[{"id":"1.230178312","rc":[{"atl":[[6,9.76]],"id":56913144},{"atb":[[5.5,7.75]],"id":68462283},{"atl":[[20,1.38]],"id":68462283},{"atb":[[6.2,8.89]],"id":70681331}],"con":true,"img":false}]}
{"op":"mcm","clk":"11540768525","pt":1719498189587,"mc":[{"id":"1.230178312","rc":[{"atb":[[5.4,0.05]],"id":68462283}],"con":true,"img":false}]}
{"op":"mcm","clk":"11540768546","pt":1719498189795,"mc":[{"id":"1.230178312","rc":[{"atb":[[6.2,4.8]],"id":70681331},{"atl":[[7.4,8.92]],"id":52951653}],"con":true,"img":false}]}
{"op":"mcm","clk":"11540768559","pt":1719498189895,"mc":[{"id":"1.230178312","rc":[{"atb":[[5.6,1]],"id":68462283}],"con":true,"img":false}]}
{"op":"mcm","clk":"11540768580","pt":1719498190098,"mc":[{"id":"1.230178312","rc":[{"atl":[[6.2,2]],"id":56913144}],"con":true,"img":false}]}
{"op":"mcm","clk":"11540768595","pt":1719498190202,"mc":[{"id":"1.230178312","rc":[{"atl":[[5.8,0.02]],"id":56913144}],"con":true,"img":false}]}
{"op":"mcm","clk":"11540768640","pt":1719498190577,"mc":[{"id":"1.230178312","rc":[{"atl":[[6,5.53]],"id":56913144}],"con":true,"img":false}]}
{"op":"mcm","clk":"11540768694","pt":1719498191104,"mc":[{"id":"1.230178312","rc":[{"atb":[[4.6,0]],"id":68462283},{"atl":[[15,0],[18.5,1]],"id":68462283}],"con":true,"img":false}]}
{"op":"mcm","clk":"11540768708","pt":1719498191205,"mc":[{"id":"1.230178312","rc":[{"atl":[[19.5,2],[21,0]],"id":68462283}],"con":true,"img":false}]}
{"op":"mcm","clk":"11540768943","pt":1719498193301,"mc":[{"id":"1.230178312","rc":[{"atl":[[6.2,0]],"id":56913144}],"con":true,"img":false}]}
{"op":"mcm","clk":"11540769172","pt":1719498195285,"mc":[{"id":"1.230178312","rc":[{"atl":[[5.9,2.84]],"id":56913144}],"con":true,"img":false}]}
{"op":"mcm","clk":"11540769254","pt":1719498196105,"mc":[{"id":"1.230178312","rc":[{"atl":[[6.8,0]],"id":56913144}],"con":true,"img":false}]}
{"op":"mcm","clk":"11540769283","pt":1719498196376,"mc":[{"id":"1.230178312","rc":[{"atl":[[5.8,4.72]],"id":56913144}],"con":true,"img":false}]}
{"op":"mcm","clk":"11540769348","pt":1719498196989,"mc":[{"id":"1.230178312","rc":[{"atl":[[5.7,4.45]],"id":56913144}],"con":true,"img":false}]}
{"op":"mcm","clk":"11540769362","pt":1719498197097,"mc":[{"id":"1.230178312","rc":[{"atl":[[5.7,5.29]],"id":56913144}],"con":true,"img":false}]}
{"op":"mcm","clk":"11540769385","pt":1719498197300,"mc":[{"id":"1.230178312","rc":[{"atl":[[5.8,0],[5.9,2.58],[5.7,0]],"id":56913144},{"trd":[[5.9,0.52],[5.8,9.43],[5.7,10.59]],"ltp":5.9,"tv":20.54,"id":56913144}],"con":true,"img":false}]}
{"op":"mcm","clk":"11540769431","pt":1719498197723,"mc":[{"id":"1.230178312","rc":[{"atb":[[4.4,5.76]],"id":56913144}],"con":true,"img":false}]}
{"op":"mcm","clk":"11540769473","pt":1719498198087,"mc":[{"id":"1.230178312","rc":[{"atb":[[4.5,0.84],[4.2,6.91]],"id":56913144}],"con":true,"img":false}]}
{"op":"mcm","clk":"11540769615","pt":1719498199387,"mc":[{"id":"1.230178312","rc":[{"atb":[[4.5,7.69]],"id":56913144}],"con":true,"img":false}]}
{"op":"mcm","clk":"11540769669","pt":1719498199896,"mc":[{"id":"1.230178312","rc":[{"atb":[[4.4,0]],"id":56913144}],"con":true,"img":false}]}
{"op":"mcm","clk":"11540769690","pt":1719498200109,"mc":[{"id":"1.230178312","rc":[{"atb":[[4.6,5.51]],"id":56913144}],"con":true,"img":false}]}
{"op":"mcm","clk":"11540769733","pt":1719498200512,"mc":[{"id":"1.230178312","rc":[{"atl":[[5.9,0.58]],"id":56913144}],"con":true,"img":false}]}
{"op":"mcm","clk":"11540769771","pt":1719498200886,"mc":[{"id":"1.230178312","rc":[{"atl":[[15,1],[18.5,0]],"id":68462283}],"con":true,"img":false}]}
{"op":"mcm","clk":"11540769784","pt":1719498200991,"mc":[{"id":"1.230178312","rc":[{"atl":[[19,1.42]],"id":68462283}],"con":true,"img":false}]}
{"op":"mcm","clk":"11540769809","pt":1719498201200,"mc":[{"id":"1.230178312","rc":[{"atb":[[4.6,1]],"id":68462283}],"con":true,"img":false}]}
{"op":"mcm","clk":"11540769845","pt":1719498201518,"mc":[{"id":"1.230178312","rc":[{"atb":[[3.7,1]],"id":51441055}],"con":true,"img":false}]}
{"op":"mcm","clk":"11540769893","pt":1719498201886,"mc":[{"id":"1.230178312","rc":[{"atl":[[18.5,1]],"id":68462283}],"con":true,"img":false}]}
{"op":"mcm","clk":"11540769905","pt":1719498201985,"mc":[{"id":"1.230178312","rc":[{"atb":[[4.6,0]],"id":68462283},{"atl":[[15,0],[18.5,3],[19.5,0]],"id":68462283}],"con":true,"img":false}]}
{"op":"mcm","clk":"11540769924","pt":1719498202187,"mc":[{"id":"1.230178312","rc":[{"atb":[[6,3.15]],"id":68462283}],"con":true,"img":false}]}
{"op":"mcm","clk":"11540769980","pt":1719498202609,"mc":[{"id":"1.230178312","rc":[{"atb":[[6.2,0.84]],"id":68462283},{"atl":[[18,0.84]],"id":68462283}],"con":true,"img":false}]}
{"op":"mcm","clk":"11540770021","pt":1719498203016,"mc":[{"id":"1.230178312","rc":[{"atl":[[24,0]],"id":68462283}],"con":true,"img":false}]}
{"op":"mcm","clk":"11540770087","pt":1719498203807,"mc":[{"id":"1.230178312","rc":[{"atb":[[6.2,5.29]],"id":68462283},{"atl":[[18,2.33]],"id":68462283}],"con":true,"img":false}]}
{"op":"mcm","clk":"11540770210","pt":1719498205001,"mc":[{"id":"1.230178312","rc":[{"atb":[[5,1]],"id":68462283}],"con":true,"img":false}]}
{"op":"mcm","clk":"11540770268","pt":1719498205611,"mc":[{"id":"1.230178312","rc":[{"atb":[[4.7,0.84]],"id":56913144}],"con":true,"img":false}]}
{"op":"mcm","clk":"11540770589","pt":1719498208890,"mc":[{"id":"1.230178312","rc":[{"atl":[[17.5,1.53]],"id":68462283}],"con":true,"img":false}]}
{"op":"mcm","clk":"11540770598","pt":1719498208996,"mc":[{"id":"1.230178312","rc":[{"atl":[[17.5,3.87],[18.5,1]],"id":68462283}],"con":true,"img":false}]}
{"op":"mcm","clk":"11540770635","pt":1719498209513,"mc":[{"id":"1.230178312","rc":[{"atl":[[22,0]],"id":68462283}],"con":true,"img":false}]}
{"op":"mcm","clk":"11540770641","pt":1719498209613,"mc":[{"id":"1.230178312","rc":[{"atl":[[17.5,5.47]],"id":68462283}],"con":true,"img":false}]}
{"op":"mcm","clk":"11540770685","pt":1719498210122,"mc":[{"id":"1.230178312","rc":[{"atl":[[17,0.84]],"id":68462283}],"con":true,"img":false}]}
{"op":"mcm","clk":"11540770832","pt":1719498211630,"mc":[{"id":"1.230178312","rc":[{"atl":[[15,1],[18.5,0]],"id":68462283}],"con":true,"img":false}]}
{"op":"mcm","clk":"11540770857","pt":1719498211794,"mc":[{"id":"1.230178312","rc":[{"atb":[[4.6,12.37]],"id":56913144}],"con":true,"img":false}]}
{"op":"mcm","clk":"11540770880","pt":1719498212004,"mc":[{"id":"1.230178312","rc":[{"atb":[[4.3,0]],"id":56913144}],"con":true,"img":false}]}
{"op":"mcm","clk":"11540770936","pt":1719498212514,"mc":[{"id":"1.230178312","rc":[{"atb":[[4.7,1.84]],"id":56913144}],"con":true,"img":false}]}
{"op":"mcm","clk":"11540770956","pt":1719498212731,"mc":[{"id":"1.230178312","rc":[{"atl":[[15,0],[18.5,1]],"id":68462283}],"con":true,"img":false}]}
{"op":"mcm","clk":"11540771005","pt":1719498213190,"mc":[{"id":"1.230178312","rc":[{"atb":[[4.5,6.85],[4.6,6.86]],"id":56913144}],"con":true,"img":false}]}
{"op":"mcm","clk":"11540771029","pt":1719498213408,"mc":[{"id":"1.230178312","rc":[{"atb":[[4.8,5.29]],"id":56913144}],"con":true,"img":false}]}
{"op":"mcm","clk":"11540771038","pt":1719498213511,"mc":[{"id":"1.230178312","rc":[{"atb":[[4.7,4]],"id":56913144}],"con":true,"img":false}]}
{"op":"mcm","clk":"11540771088","pt":1719498214126,"mc":[{"id":"1.230178312","rc":[{"atb":[[4.9,0.84]],"id":56913144}],"con":true,"img":false}]}
{"op":"mcm","clk":"11540771198","pt":1719498215100,"mc":[{"id":"1.230178312","rc":[{"atb":[[3.65,0]],"id":56913144}],"con":true,"img":false}]}
{"op":"mcm","clk":"11540771265","pt":1719498215725,"mc":[{"id":"1.230178312","rc":[{"atl":[[15,1],[18.5,0]],"id":68462283}],"con":true,"img":false}]}
{"op":"mcm","clk":"11540771327","pt":1719498216187,"mc":[{"id":"1.230178312","rc":[{"atl":[[18,1.49]],"id":68462283}],"con":true,"img":false}]}
{"op":"mcm","clk":"11540771481","pt":1719498217594,"mc":[{"id":"1.230178312","rc":[{"atl":[[15,0],[18.5,1]],"id":68462283}],"con":true,"img":false}]}
{"op":"mcm","clk":"11540771563","pt":1719498218520,"mc":[{"id":"1.230178312","rc":[{"atb":[[5.3,0]],"id":52951653},{"trd":[[5.3,0.27]],"ltp":5.3,"tv":0.27,"id":52951653}],"con":true,"img":false}]}
{"op":"mcm","clk":"11540771726","pt":1719498220337,"mc":[{"id":"1.230178312","rc":[{"atb":[[3.55,2.11]],"id":39100893},{"atb":[[4.3,1.74]],"id":52951653},{"atb":[[3.75,2]],"id":51441055}],"con":true,"img":false}]}
{"op":"mcm","clk":"11540771748","pt":1719498220498,"mc":[{"id":"1.230178312","rc":[{"atb":[[3.6,8.53]],"id":39100893},{"atb":[[3.85,7.8]],"id":52951653}],"con":true,"img":false}]}
{"op":"mcm","clk":"11540771984","pt":1719498223024,"mc":[{"id":"1.230178312","rc":[{"atb":[[4.5,0]],"id":39100893},{"atl":[[8.6,0.98]],"id":39100893},{"atb":[[5.2,0.84]],"id":52951653},{"atl":[[8.6,0.98],[7.6,0]],"id":52951653},{"atb":[[5.2,0.05]],"id":51441055},{"atl":[[9.8,0.88]],"id":51441055}],"con":true,"img":false}]}
{"op":"mcm","clk":"11540772388","pt":1719498226792,"mc":[{"id":"1.230178312","rc":[{"atl":[[8.6,0],[7,1.21]],"id":52951653}],"con":true,"img":false}]}
{"op":"mcm","clk":"11540772401","pt":1719498226908,"mc":[{"id":"1.230178312","rc":[{"atl":[[15,1],[18.5,0]],"id":68462283},{"atl":[[8.4,0]],"id":52951653}],"con":true,"img":false}]}
{"op":"mcm","clk":"11540772414","pt":1719498227001,"mc":[{"id":"1.230178312","rc":[{"atl":[[7,5.66]],"id":52951653}],"con":true,"img":false}]}
{"op":"mcm","clk":"11540772430","pt":1719498227116,"mc":[{"id":"1.230178312","rc":[{"atb":[[6.4,1.32],[5.5,6.21]],"id":68462283}],"con":true,"img":false}]}
{"op":"mcm","clk":"11540772440","pt":1719498227209,"mc":[{"id":"1.230178312","rc":[{"atl":[[6.8,3.73]],"id":52951653}],"con":true,"img":false}]}
{"op":"mcm","clk":"11540772481","pt":1719498227622,"mc":[{"id":"1.230178312","rc":[{"atl":[[7.4,8.08],[6.6,0.84]],"id":52951653}],"con":true,"img":false}]}
{"op":"mcm","clk":"11540772498","pt":1719498227829,"mc":[{"id":"1.230178312","rc":[{"atl":[[8,0]],"id":52951653}],"con":true,"img":false}]}
{"op":"mcm","clk":"11540772521","pt":1719498228045,"mc":[{"id":"1.230178312","rc":[{"atl":[[6.6,5.56]],"id":52951653}],"con":true,"img":false}]}
{"op":"mcm","clk":"11540772561","pt":1719498228504,"mc":[{"id":"1.230178312","rc":[{"atl":[[6.8,0]],"id":52951653}],"con":true,"img":false}]}
{"op":"mcm","clk":"11540773762","pt":1719498240436,"mc":[{"id":"1.230178312","rc":[{"atl":[[1000,0.34]],"id":68462283},{"atl":[[1000,0.51]],"id":70681331},{"atl":[[1000,0.58]],"id":39100893}],"con":true,"img":false}]}
{"op":"mcm","clk":"11540773779","pt":1719498240643,"mc":[{"id":"1.230178312","rc":[{"atl":[[1000,0]],"id":68462283},{"atl":[[1000,0]],"id":39100893}],"con":true,"img":false}]}
{"op":"mcm","clk":"11540773792","pt":1719498240748,"mc":[{"id":"1.230178312","rc":[{"atl":[[15,1.34]],"id":68462283},{"atl":[[1000,0.16]],"id":70681331},{"atl":[[8.8,1.58]],"id":39100893}],"con":true,"img":false}]}
{"op":"mcm","clk":"11540773804","pt":1719498240805,"mc":[{"id":"1.230178312","rc":[{"atl":[[14.5,1.35]],"id":70681331}],"con":true,"img":false}]}
{"op":"mcm","clk":"11540773815","pt":1719498240909,"mc":[{"id":"1.230178312","rc":[{"atl":[[8.8,4.85]],"id":39100893}],"con":true,"img":false}]}
{"op":"mcm","clk":"11540773836","pt":1719498241114,"mc":[{"id":"1.230178312","rc":[{"atl":[[14,1.44]],"id":70681331}],"con":true,"img":false}]}
{"op":"mcm","clk":"11540773854","pt":1719498241320,"mc":[{"id":"1.230178312","rc":[{"atl":[[80,0],[14,3.44]],"id":70681331}],"con":true,"img":false}]}
{"op":"mcm","clk":"11540773968","pt":1719498242520,"mc":[{"id":"1.230178312","rc":[{"atl":[[14,5.36]],"id":70681331}],"con":true,"img":false}]}
{"op":"mcm","clk":"11540774306","pt":1719498245735,"mc":[{"id":"1.230178312","rc":[{"atb":[[6.2,0.84],[5.5,6.17]],"id":68462283}],"con":true,"img":false}]}
{"op":"mcm","clk":"11540774339","pt":1719498246046,"mc":[{"id":"1.230178312","rc":[{"atb":[[6.4,0],[6.2,2.16]],"id":68462283}],"con":true,"img":false}]}
{"op":"mcm","clk":"11540774374","pt":1719498246411,"mc":[{"id":"1.230178312","rc":[{"atb":[[6.2,6.95]],"id":68462283}],"con":true,"img":false}]}
{"op":"mcm","clk":"11540774407","pt":1719498246839,"mc":[{"id":"1.230178312","rc":[{"spn":3.07,"spf":1.1,"id":56913144},{"atb":[[6.4,3.97],[3.15,5.51]],"id":68462283},{"spn":6.28,"spf":1.0,"id":68462283},{"spn":6.15,"spf":1.0,"id":70681331},{"spn":3.88,"spf":1.0,"id":39100893},{"spn":5.13,"spf":1.0,"id":52951653},{"spn":9.89,"spf":31.71,"id":51441055}],"con":true,"img":false}]}
{"op":"mcm","clk":"11540774430","pt":1719498247043,"mc":[{"id":"1.230178312","rc":[{"atb":[[3.15,5.51]],"id":39100893}],"con":true,"img":false}]}
{"op":"mcm","clk":"11540774440","pt":1719498247138,"mc":[{"id":"1.230178312","rc":[{"atb":[[6.6,0.84]],"id":68462283}],"con":true,"img":false}]}
{"op":"mcm","clk":"11540774469","pt":1719498247449,"mc":[{"id":"1.230178312","rc":[{"atb":[[3.15,5.51]],"id":52951653}],"con":true,"img":false}]}
{"op":"mcm","clk":"11540774511","pt":1719498247917,"mc":[{"id":"1.230178312","rc":[{"atb":[[2.26,9.39]],"id":56913144}],"con":true,"img":false}]}
{"op":"mcm","clk":"11540774522","pt":1719498248020,"mc":[{"id":"1.230178312","rc":[{"atb":[[3.6,4.55]],"id":70681331}],"con":true,"img":false}]}
{"op":"mcm","clk":"11540775051","pt":1719498252944,"mc":[{"id":"1.230178312","rc":[{"atb":[[6.4,5.15]],"id":68462283},{"atb":[[6.4,1.71]],"id":70681331},{"atb":[[5.2,0.84]],"id":51441055}],"con":true,"img":false}]}
{"op":"mcm","clk":"11540775072","pt":1719498253150,"mc":[{"id":"1.230178312","rc":[{"atb":[[6.6,3.85]],"id":70681331}],"con":true,"img":false}]}
{"op":"mcm","clk":"11540775127","pt":1719498253617,"mc":[{"id":"1.230178312","rc":[{"atb":[[6.8,0.84]],"id":70681331}],"con":true,"img":false}]}
{"op":"mcm","clk":"11540775274","pt":1719498255032,"mc":[{"id":"1.230178312","rc":[{"atl":[[15,1]],"id":68462283},{"atl":[[14.5,1]],"id":70681331},{"atl":[[8.8,4.27]],"id":39100893}],"con":true,"img":false}]}
{"op":"mcm","clk":"11540775828","pt":1719498260460,"mc":[{"id":"1.230178312","rc":[{"atl":[[1000,0.34]],"id":68462283},{"atb":[[3.65,2.05]],"id":39100893},{"atl":[[1000,0.58]],"id":39100893}],"con":true,"img":false}]}
{"op":"mcm","clk":"11540775853","pt":1719498260666,"mc":[{"id":"1.230178312","rc":[{"atl":[[1000,0]],"id":68462283},{"atl":[[1000,0]],"id":39100893}],"con":true,"img":false}]}
{"op":"mcm","clk":"11540775864","pt":1719498260720,"mc":[{"id":"1.230178312","rc":[{"atl":[[15,1.34]],"id":68462283},{"atl":[[8.8,4.85]],"id":39100893}],"con":true,"img":false}]}
{"op":"mcm","clk":"11540776126","pt":1719498263568,"mc":[{"id":"1.230178312","rc":[{"atb":[[6.4,3.97]],"id":68462283}],"con":true,"img":false}]}
{"op":"mcm","clk":"11540776263","pt":1719498265067,"mc":[{"id":"1.230178312","rc":[{"atb":[[2.34,8.83]],"id":51441055}],"con":true,"img":false}]}
{"op":"mcm","clk":"11540776576","pt":1719498268374,"mc":[{"id":"1.230178312","rc":[{"atb":[[5.1,0],[5,0.06]],"id":39100893},{"trd":[[5,1.88],[5.1,0.11]],"ltp":5.0,"tv":1.99,"id":39100893}],"con":true,"img":false}]}
{"op":"mcm","clk":"11540776628","pt":1719498268840,"mc":[{"id":"1.230178312","rc":[{"atb":[[3.7,8.68]],"id":39100893}],"con":true,"img":false}]}
{"op":"mcm","clk":"11540776664","pt":1719498269158,"mc":[{"id":"1.230178312","rc":[{"atb":[[5.4,0]],"id":68462283},{"atb":[[6.4,1.65]],"id":70681331},{"atb":[[5.2,0.78]],"id":51441055}],"con":true,"img":false}]}
{"op":"mcm","clk":"11540776750","pt":1719498269931,"mc":[{"id":"1.230178312","rc":[{"atl":[[1000,0.13]],"id":39100893}],"con":true,"img":false}]}
{"op":"mcm","clk":"11540776775","pt":1719498270139,"mc":[{"id":"1.230178312","rc":[{"atl":[[1000,0]],"id":39100893}],"con":true,"img":false}]}
{"op":"mcm","clk":"11540776789","pt":1719498270243,"mc":[{"id":"1.230178312","rc":[{"atl":[[8.6,1.11]],"id":39100893}],"con":true,"img":false}]}
{"op":"mcm","clk":"11540776813","pt":1719498270450,"mc":[{"id":"1.230178312","rc":[{"atb":[[4.5,1]],"id":39100893}],"con":true,"img":false}]}
{"op":"mcm","clk":"11540776824","pt":1719498270553,"mc":[{"id":"1.230178312","rc":[{"atb":[[5,0]],"id":39100893}],"con":true,"img":false}]}
{"op":"mcm","clk":"11540776835","pt":1719498270656,"mc":[{"id":"1.230178312","rc":[{"atl":[[8.6,4.6]],"id":39100893}],"con":true,"img":false}]}
{"op":"mcm","clk":"11540776891","pt":1719498271275,"mc":[{"id":"1.230178312","rc":[{"atl":[[8.4,0.84]],"id":39100893}],"con":true,"img":false}]}
{"op":"mcm","clk":"11540776930","pt":1719498271535,"mc":[{"id":"1.230178312","rc":[{"atl":[[8.4,3.86]],"id":39100893}],"con":true,"img":false}]}
{"op":"mcm","clk":"11540776964","pt":1719498271849,"mc":[{"id":"1.230178312","rc":[{"atl":[[8.6,3.62],[8.2,3.03]],"id":39100893}],"con":true,"img":false}]}
{"op":"mcm","clk":"11540777046","pt":1719498272633,"mc":[{"id":"1.230178312","rc":[{"atl":[[8.4,0.84]],"id":39100893}],"con":true,"img":false}]}
{"op":"mcm","clk":"11540777067","pt":1719498272841,"mc":[{"id":"1.230178312","rc":[{"atl":[[8,3.17]],"id":39100893}],"con":true,"img":false}]}
{"op":"mcm","clk":"11540777078","pt":1719498272945,"mc":[{"id":"1.230178312","rc":[{"atl":[[8.4,3.97]],"id":39100893}],"con":true,"img":false}]}
{"op":"mcm","clk":"11540777101","pt":1719498273154,"mc":[{"id":"1.230178312","rc":[{"atl":[[8.2,2],[7.8,1.08],[8.4,3.13]],"id":39100893}],"con":true,"img":false}]}
{"op":"mcm","clk":"11540777116","pt":1719498273258,"mc":[{"id":"1.230178312","rc":[{"atb":[[3.75,1]],"id":39100893}],"con":true,"img":false}]}
{"op":"mcm","clk":"11540777139","pt":1719498273466,"mc":[{"id":"1.230178312","rc":[{"atl":[[8.2,0]],"id":39100893}],"con":true,"img":false}]}
{"op":"mcm","clk":"11540777159","pt":1719498273675,"mc":[{"id":"1.230178312","rc":[{"atl":[[8,0]],"id":39100893}],"con":true,"img":false}]}
{"op":"mcm","clk":"11540777194","pt":1719498273937,"mc":[{"id":"1.230178312","rc":[{"atl":[[8.2,1.08]],"id":39100893}],"con":true,"img":false}]}
{"op":"mcm","clk":"11540777206","pt":1719498274040,"mc":[{"id":"1.230178312","rc":[{"atl":[[7.8,0]],"id":39100893}],"con":true,"img":false}]}
{"op":"mcm","clk":"11540777218","pt":1719498274146,"mc":[{"id":"1.230178312","rc":[{"atb":[[6.4,0.84]],"id":70681331}],"con":true,"img":false}]}
{"op":"mcm","clk":"11540777286","pt":1719498274869,"mc":[{"id":"1.230178312","rc":[{"atl":[[15,1]],"id":68462283}],"con":true,"img":false}]}
{"op":"mcm","clk":"11540777305","pt":1719498275075,"mc":[{"id":"1.230178312","rc":[{"atl":[[8.8,4.27]],"id":39100893}],"con":true,"img":false}]}
{"op":"mcm","clk":"11540777660","pt":1719498278547,"mc":[{"id":"1.230178312","rc":[{"atb":[[6,0]],"id":68462283}],"con":true,"img":false}]}
{"op":"mcm","clk":"11540777709","pt":1719498278861,"mc":[{"id":"1.230178312","rc":[{"atl":[[8,2]],"id":39100893}],"con":true,"img":false}]}
{"op":"mcm","clk":"11540777757","pt":1719498279375,"mc":[{"id":"1.230178312","rc":[{"atl":[[7.8,3.25]],"id":39100893}],"con":true,"img":false}]}
{"op":"mcm","clk":"11540777778","pt":1719498279582,"mc":[{"id":"1.230178312","rc":[{"atl":[[7.6,0.84]],"id":39100893}],"con":true,"img":false}]}
{"op":"mcm","clk":"11540777819","pt":1719498279844,"mc":[{"id":"1.230178312","rc":[{"atl":[[8,0]],"id":39100893}],"con":true,"img":false}]}
{"op":"mcm","clk":"11540777853","pt":1719498280049,"mc":[{"id":"1.230178312","rc":[{"atl":[[9.2,0]],"id":39100893}],"con":true,"img":false}]}
{"op":"mcm","clk":"11540777874","pt":1719498280260,"mc":[{"id":"1.230178312","rc":[{"atl":[[8.2,4.37]],"id":39100893}],"con":true,"img":false}]}
{"op":"mcm","clk":"11540777912","pt":1719498280568,"mc":[{"id":"1.230178312","rc":[{"atl":[[1000,0.34]],"id":68462283},{"atb":[[3.55,0]],"id":39100893},{"atb":[[4.3,0]],"id":52951653},{"atb":[[3.75,0]],"id":51441055}],"con":true,"img":false}]}
{"op":"mcm","clk":"11540777931","pt":1719498280779,"mc":[{"id":"1.230178312","rc":[{"atl":[[1000,0]],"id":68462283}],"con":true,"img":false}]}
{"op":"mcm","clk":"11540777965","pt":1719498280881,"mc":[{"id":"1.230178312","rc":[{"atl":[[15,1.34]],"id":68462283}],"con":true,"img":false}]}
{"op":"mcm","clk":"11540777996","pt":1719498281040,"mc":[{"id":"1.230178312","rc":[{"atb":[[4.3,1.74]],"id":52951653},{"atb":[[3.75,2]],"id":51441055}],"con":true,"img":false}]}
{"op":"mcm","clk":"11540778469","pt":1719498285452,"mc":[{"id":"1.230178312","rc":[{"atl":[[8.6,3.49]],"id":39100893}],"con":true,"img":false}]}
{"op":"mcm","clk":"11540778590","pt":1719498286566,"mc":[{"id":"1.230178312","rc":[{"atl":[[7.6,2.84]],"id":39100893}],"con":true,"img":false}]}
{"op":"mcm","clk":"11540778629","pt":1719498286879,"mc":[{"id":"1.230178312","rc":[{"atl":[[7.8,0]],"id":39100893}],"con":true,"img":false}]}
{"op":"mcm","clk":"11540778645","pt":1719498286983,"mc":[{"id":"1.230178312","rc":[{"atl":[[1000,0.84],[23,0]],"id":68462283}],"con":true,"img":false}]}
{"op":"mcm","clk":"11540778660","pt":1719498287088,"mc":[{"id":"1.230178312","rc":[{"atl":[[7.4,3.42]],"id":39100893},{"atb":[[3.2,6.34]],"id":52951653}],"con":true,"img":false}]}
{"op":"mcm","clk":"11540778693","pt":1719498287251,"mc":[{"id":"1.230178312","rc":[{"atl":[[1000,0.58]],"id":68462283}],"con":true,"img":false}]}
{"op":"mcm","clk":"11540778708","pt":1719498287352,"mc":[{"id":"1.230178312","rc":[{"atb":[[2.28,10.91]],"id":56913144}],"con":true,"img":false}]}
{"op":"mcm","clk":"11540778732","pt":1719498287572,"mc":[{"id":"1.230178312","rc":[{"atl":[[1000,0]],"id":68462283},{"atl":[[7.2,0.84]],"id":39100893}],"con":true,"img":false}]}
{"op":"mcm","clk":"11540778746","pt":1719498287666,"mc":[{"id":"1.230178312","rc":[{"atb":[[3.2,6.34]],"id":68462283},{"atl":[[14.5,0.58]],"id":68462283}],"con":true,"img":false}]}
{"op":"mcm","clk":"11540778780","pt":1719498287984,"mc":[{"id":"1.230178312","rc":[{"atl":[[20,0]],"id":68462283}],"con":true,"img":false}]}
{"op":"mcm","clk":"11540778795","pt":1719498288088,"mc":[{"id":"1.230178312","rc":[{"atl":[[17,0],[14.5,1.43]],"id":68462283},{"atl":[[7.6,0.84]],"id":39100893}],"con":true,"img":false}]}
{"op":"mcm","clk":"11540778807","pt":1719498288146,"mc":[{"id":"1.230178312","rc":[{"atl":[[17,2.77],[14.5,3.3]],"id":68462283}],"con":true,"img":false}]}
{"op":"mcm","clk":"11540778818","pt":1719498288251,"mc":[{"id":"1.230178312","rc":[{"atl":[[17.5,3.13]],"id":68462283}],"con":true,"img":false}]}
{"op":"mcm","clk":"11540778850","pt":1719498288667,"mc":[{"id":"1.230178312","rc":[{"atl":[[7.6,0]],"id":56913144}],"con":true,"img":false}]}
{"op":"mcm","clk":"11540778857","pt":1719498288771,"mc":[{"id":"1.230178312","rc":[{"atl":[[7.2,1]],"id":56913144},{"atl":[[15,0.34],[15.5,1]],"id":68462283},{"atl":[[12.5,1],[14.5,0]],"id":70681331},{"atl":[[8.6,4.49],[8.8,3.27]],"id":39100893},{"atl":[[8.8,0]],"id":52951653}],"con":true,"img":false}]}
{"op":"mcm","clk":"11540778868","pt":1719498288877,"mc":[{"id":"1.230178312","rc":[{"atl":[[7.8,9.54],[8.6,0],[7,2.21]],"id":56913144},{"atb":[[4.9,7.94],[4.4,0]],"id":68462283},{"atl":[[15.5,5.64],[17,0]],"id":68462283},{"atb":[[3.45,0],[3.7,17.21]],"id":39100893},{"atl":[[8.8,9.83],[9.4,0]],"id":39100893},{"atb":[[3.3,6.35],[3.05,0]],"id":52951653},{"atl":[[7.4,4],[7,16.8]],"id":52951653},{"atb":[[3.9,4]],"id":51441055},{"atl":[[9.8,4.67]],"id":51441055}],"con":true,"img":false}]}
{"op":"mcm","clk":"11540778878","pt":1719498288979,"mc":[{"id":"1.230178312","rc":[{"atb":[[3.65,0]],"id":51441055},{"atl":[[10.5,1]],"id":51441055}],"con":true,"img":false}]}
{"op":"mcm","clk":"11540778892","pt":1719498289085,"mc":[{"id":"1.230178312","rc":[{"atl":[[7.2,0]],"id":52951653},{"atl":[[9.6,0.84]],"id":51441055}],"con":true,"img":false}]}
{"op":"mcm","clk":"11540778916","pt":1719498289245,"mc":[{"id":"1.230178312","rc":[{"atl":[[9.6,3.48]],"id":51441055}],"con":true,"img":false}]}
{"op":"mcm","clk":"11540778927","pt":1719498289349,"mc":[{"id":"1.230178312","rc":[{"atl":[[6.8,1]],"id":52951653},{"atl":[[1000,0.68]],"id":51441055}],"con":true,"img":false}]}
{"op":"mcm","clk":"11540778953","pt":1719498289553,"mc":[{"id":"1.230178312","rc":[{"atl":[[1000,0.16]],"id":51441055}],"con":true,"img":false}]}
{"op":"mcm","clk":"11540778964","pt":1719498289665,"mc":[{"id":"1.230178312","rc":[{"atl":[[9.6,6.5],[10,2.94],[9.8,5.19]],"id":51441055}],"con":true,"img":false}]}
{"op":"mcm","clk":"11540778992","pt":1719498289872,"mc":[{"id":"1.230178312","rc":[{"atl":[[6.4,3.97]],"id":52951653}],"con":true,"img":false}]}
{"op":"mcm","clk":"11540779020","pt":1719498290067,"mc":[{"id":"1.230178312","rc":[{"atl":[[6.2,0.84]],"id":52951653}],"con":true,"img":false}]}
{"op":"mcm","clk":"11540779066","pt":1719498290480,"mc":[{"id":"1.230178312","rc":[{"atl":[[17.5,1.6]],"id":68462283}],"con":true,"img":false}]}
{"op":"mcm","clk":"11540779078","pt":1719498290584,"mc":[{"id":"1.230178312","rc":[{"atl":[[7.8,0]],"id":52951653}],"con":true,"img":false}]}
{"op":"mcm","clk":"11540779091","pt":1719498290687,"mc":[{"id":"1.230178312","rc":[{"atl":[[6.2,5.16]],"id":52951653}],"con":true,"img":false}]}
{"op":"mcm","clk":"11540779162","pt":1719498291161,"mc":[{"id":"1.230178312","rc":[{"atl":[[6.4,0],[6.6,4.72]],"id":52951653}],"con":true,"img":false}]}
{"op":"mcm","clk":"11540779400","pt":1719498293558,"mc":[{"id":"1.230178312","rc":[{"atl":[[14,1.64]],"id":68462283}],"con":true,"img":false}]}
{"op":"mcm","clk":"11540779447","pt":1719498294079,"mc":[{"id":"1.230178312","rc":[{"atl":[[7.2,2.84]],"id":39100893}],"con":true,"img":false}]}
{"op":"mcm","clk":"11540779476","pt":1719498294390,"mc":[{"id":"1.230178312","rc":[{"atl":[[19,0]],"id":68462283},{"atl":[[7.4,0]],"id":39100893},{"atl":[[9.6,11.69],[9.8,1.4]],"id":51441055}],"con":true,"img":false}]}
{"op":"mcm","clk":"11540779484","pt":1719498294492,"mc":[{"id":"1.230178312","rc":[{"atl":[[14,3.72]],"id":68462283}],"con":true,"img":false}]}
{"op":"mcm","clk":"11540779490","pt":1719498294548,"mc":[{"id":"1.230178312","rc":[{"atl":[[7,3.63]],"id":39100893}],"con":true,"img":false}]}
{"op":"mcm","clk":"11540779499","pt":1719498294652,"mc":[{"id":"1.230178312","rc":[{"atl":[[7.6,0]],"id":39100893}],"con":true,"img":false}]}
{"op":"mcm","clk":"11540779534","pt":1719498295065,"mc":[{"id":"1.230178312","rc":[{"atl":[[13.5,0.84],[15,0]],"id":68462283},{"atb":[[4,0.47]],"id":39100893},{"atl":[[7.2,0.84],[6.8,0.84]],"id":39100893}],"con":true,"img":false}]}
{"op":"mcm","clk":"11540779629","pt":1719498296099,"mc":[{"id":"1.230178312","rc":[{"atb":[[4.8,11.86]],"id":56913144}],"con":true,"img":false}]}
{"op":"mcm","clk":"11540779652","pt":1719498296257,"mc":[{"id":"1.230178312","rc":[{"atb":[[4.7,3]],"id":56913144}],"con":true,"img":false}]}
{"op":"mcm","clk":"11540779747","pt":1719498297187,"mc":[{"id":"1.230178312","rc":[{"atl":[[7.2,0]],"id":56913144}],"con":true,"img":false}]}
{"op":"mcm","clk":"11540779755","pt":1719498297291,"mc":[{"id":"1.230178312","rc":[{"atb":[[4.9,1.84]],"id":56913144}],"con":true,"img":false}]}
{"op":"mcm","clk":"11540779786","pt":1719498297653,"mc":[{"id":"1.230178312","rc":[{"atb":[[4.7,2.16]],"id":56913144}],"con":true,"img":false}]}
{"op":"mcm","clk":"11540779804","pt":1719498297863,"mc":[{"id":"1.230178312","rc":[{"atb":[[4.8,6.57]],"id":56913144}],"con":true,"img":false}]}
{"op":"mcm","clk":"11540779812","pt":1719498297963,"mc":[{"id":"1.230178312","rc":[{"atb":[[5,5.07]],"id":56913144}],"con":true,"img":false}]}
{"op":"mcm","clk":"11540779859","pt":1719498298582,"mc":[{"id":"1.230178312","rc":[{"atb":[[5.1,0.84]],"id":56913144}],"con":true,"img":false}]}
{"op":"mcm","clk":"11540780082","pt":1719498300875,"mc":[{"id":"1.230178312","rc":[{"atl":[[1000,0.36]],"id":68462283}],"con":true,"img":false}]}
{"op":"mcm","clk":"11540780105","pt":1719498301085,"mc":[{"id":"1.230178312","rc":[{"atl":[[1000,0]],"id":68462283}],"con":true,"img":false}]}
{"op":"mcm","clk":"11540780118","pt":1719498301188,"mc":[{"id":"1.230178312","rc":[{"atl":[[14,4.08]],"id":68462283}],"con":true,"img":false}]}
{"op":"mcm","clk":"11540780190","pt":1719498301763,"mc":[{"id":"1.230178312","rc":[{"atl":[[6.8,2.84]],"id":39100893}],"con":true,"img":false}]}
{"op":"mcm","clk":"11540780213","pt":1719498301970,"mc":[{"id":"1.230178312","rc":[{"atl":[[7,0]],"id":39100893}],"con":true,"img":false}]}
{"op":"mcm","clk":"11540780239","pt":1719498302178,"mc":[{"id":"1.230178312","rc":[{"atl":[[7.2,0],[6.6,3.85]],"id":39100893}],"con":true,"img":false}]}
{"op":"mcm","clk":"11540780277","pt":1719498302592,"mc":[{"id":"1.230178312","rc":[{"atl":[[6.4,0.84]],"id":39100893}],"con":true,"img":false}]}
{"op":"mcm","clk":"11540780286","pt":1719498302696,"mc":[{"id":"1.230178312","rc":[{"atb":[[4.9,3.89]],"id":56913144}],"con":true,"img":false}]}
{"op":"mcm","clk":"11540780300","pt":1719498302799,"mc":[{"id":"1.230178312","rc":[{"atl":[[6.8,0.84]],"id":39100893}],"con":true,"img":false}]}
{"op":"mcm","clk":"11540780307","pt":1719498302902,"mc":[{"id":"1.230178312","rc":[{"atl":[[6.4,0]],"id":39100893},{"trd":[[6.4,1.69]],"ltp":6.4,"tv":1.69,"id":39100893}],"con":true,"img":false}]}
{"op":"mcm","clk":"11540780347","pt":1719498303272,"mc":[{"id":"1.230178312","rc":[{"atl":[[6.6,0]],"id":39100893}],"con":true,"img":false}]}
{"op":"mcm","clk":"11540780368","pt":1719498303474,"mc":[{"id":"1.230178312","rc":[{"atl":[[8,3.17]],"id":39100893}],"con":true,"img":false}]}
{"op":"mcm","clk":"11540780379","pt":1719498303577,"mc":[{"id":"1.230178312","rc":[{"atl":[[6.8,0]],"id":39100893}],"con":true,"img":false}]}
{"op":"mcm","clk":"11540780404","pt":1719498303888,"mc":[{"id":"1.230178312","rc":[{"atl":[[9.8,0.88]],"id":51441055}],"con":true,"img":false}]}
{"op":"mcm","clk":"11540780527","pt":1719498305190,"mc":[{"id":"1.230178312","rc":[{"atl":[[8.2,1.08],[8.4,3.03]],"id":39100893}],"con":true,"img":false}]}
{"op":"mcm","clk":"11540780568","pt":1719498305606,"mc":[{"id":"1.230178312","rc":[{"atb":[[3.15,0]],"id":39100893},{"atb":[[2.34,0]],"id":51441055}],"con":true,"img":false}]}
{"op":"mcm","clk":"11540780970","pt":1719498309481,"mc":[{"id":"1.230178312","rc":[{"spn":3.36,"spf":1.1,"id":56913144},{"spn":6.32,"spf":1.0,"id":68462283},{"spn":6.46,"spf":1.0,"id":70681331},{"atl":[[7.8,2]],"id":39100893},{"spn":3.91,"spf":1.0,"id":39100893},{"spn":9.6,"spf":31.71,"id":51441055}],"con":true,"img":false}]}
{"op":"mcm","clk":"11540780980","pt":1719498309582,"mc":[{"id":"1.230178312","rc":[{"atl":[[1000,0.69]],"id":51441055}],"con":true,"img":false}]}
{"op":"mcm","clk":"11540781001","pt":1719498309790,"mc":[{"id":"1.230178312","rc":[{"atl":[[8,0]],"id":39100893},{"atl":[[1000,0.16]],"id":51441055}],"con":true,"img":false}]}
{"op":"mcm","clk":"11540781009","pt":1719498309893,"mc":[{"id":"1.230178312","rc":[{"atl":[[9.6,12.22]],"id":51441055}],"con":true,"img":false}]}
{"op":"mcm","clk":"11540781031","pt":1719498310099,"mc":[{"id":"1.230178312","rc":[{"atl":[[7.6,0.84]],"id":39100893}],"con":true,"img":false}]}
{"op":"mcm","clk":"11540781059","pt":1719498310409,"mc":[{"id":"1.230178312","rc":[{"atl":[[7.6,4.19]],"id":39100893}],"con":true,"img":false}]}
{"op":"mcm","clk":"11540781124","pt":1719498310980,"mc":[{"id":"1.230178312","rc":[{"atl":[[7.8,0]],"id":39100893}],"con":true,"img":false}]}
{"op":"mcm","clk":"11540781142","pt":1719498311186,"mc":[{"id":"1.230178312","rc":[{"atb":[[5,3]],"id":39100893}],"con":true,"img":false}]}
{"op":"mcm","clk":"11540781184","pt":1719498311602,"mc":[{"id":"1.230178312","rc":[{"atb":[[5.1,0.84]],"id":39100893}],"con":true,"img":false}]}
{"op":"mcm","clk":"11540781247","pt":1719498312176,"mc":[{"id":"1.230178312","rc":[{"atl":[[8.6,1],[8.4,0]],"id":39100893}],"con":true,"img":false}]}
{"op":"mcm","clk":"11540781272","pt":1719498312387,"mc":[{"id":"1.230178312","rc":[{"atb":[[5.1,7.64]],"id":39100893}],"con":true,"img":false}]}
{"op":"mcm","clk":"11540781298","pt":1719498312595,"mc":[{"id":"1.230178312","rc":[{"atb":[[3.75,0],[5.2,4.88]],"id":39100893}],"con":true,"img":false}]}
{"op":"mcm","clk":"11540781312","pt":1719498312700,"mc":[{"id":"1.230178312","rc":[{"atb":[[5.3,1]],"id":39100893}],"con":true,"img":false}]}
{"op":"mcm","clk":"11540781382","pt":1719498313272,"mc":[{"id":"1.230178312","rc":[{"atb":[[3.5,0],[5.2,0]],"id":39100893}],"con":true,"img":false}]}
{"op":"mcm","clk":"11540781391","pt":1719498313374,"mc":[{"id":"1.230178312","rc":[{"atb":[[5.3,7.16]],"id":39100893}],"con":true,"img":false}]}
{"op":"mcm","clk":"11540781472","pt":1719498314303,"mc":[{"id":"1.230178312","rc":[{"atb":[[5.1,6.8]],"id":39100893}],"con":true,"img":false}]}
{"op":"mcm","clk":"11540781557","pt":1719498315394,"mc":[{"id":"1.230178312","rc":[{"atl":[[14,3.72]],"id":68462283}],"con":true,"img":false}]}
{"op":"mcm","clk":"11540781867","pt":1719498318613,"mc":[{"id":"1.230178312","rc":[{"atb":[[5.4,0.84]],"id":39100893}],"con":true,"img":false}]}
{"op":"mcm","clk":"11540781892","pt":1719498318818,"mc":[{"id":"1.230178312","rc":[{"atb":[[5.3,6.16]],"id":39100893}],"con":true,"img":false}]}
{"op":"mcm","clk":"11540782008","pt":1719498320011,"mc":[{"id":"1.230178312","rc":[{"atb":[[5.2,0]],"id":51441055}],"con":true,"img":false}]}
{"op":"mcm","clk":"11540782019","pt":1719498320113,"mc":[{"id":"1.230178312","rc":[{"atb":[[5.4,1.84]],"id":39100893}],"con":true,"img":false}]}
{"op":"mcm","clk":"11540782050","pt":1719498320380,"mc":[{"id":"1.230178312","rc":[{"atb":[[5.5,4.61]],"id":39100893}],"con":true,"img":false}]}
{"op":"mcm","clk":"11540782070","pt":1719498320586,"mc":[{"id":"1.230178312","rc":[{"atb":[[3.65,0]],"id":39100893}],"con":true,"img":false}]}
{"op":"mcm","clk":"11540782100","pt":1719498320894,"mc":[{"id":"1.230178312","rc":[{"atl":[[1000,0.36]],"id":68462283}],"con":true,"img":false}]}
{"op":"mcm","clk":"11540782110","pt":1719498320999,"mc":[{"id":"1.230178312","rc":[{"atb":[[3.6,0]],"id":39100893}],"con":true,"img":false}]}
{"op":"mcm","clk":"11540782123","pt":1719498321101,"mc":[{"id":"1.230178312","rc":[{"atl":[[1000,0]],"id":68462283}],"con":true,"img":false}]}
{"op":"mcm","clk":"11540782135","pt":1719498321206,"mc":[{"id":"1.230178312","rc":[{"atl":[[14,4.08]],"id":68462283},{"atb":[[5.5,9.59]],"id":39100893}],"con":true,"img":false}]}
{"op":"mcm","clk":"11540782146","pt":1719498321309,"mc":[{"id":"1.230178312","rc":[{"atb":[[3.95,1.9]],"id":51441055}],"con":true,"img":false}]}
{"op":"mcm","clk":"11540782155","pt":1719498321412,"mc":[{"id":"1.230178312","rc":[{"atb":[[5.4,0.84]],"id":39100893}],"con":true,"img":false}]}
{"op":"mcm","clk":"11540782185","pt":1719498321678,"mc":[{"id":"1.230178312","rc":[{"atb":[[5.6,1]],"id":39100893}],"con":true,"img":false}]}
{"op":"mcm","clk":"11540782207","pt":1719498321887,"mc":[{"id":"1.230178312","rc":[{"atb":[[5.5,4.98]],"id":39100893}],"con":true,"img":false}]}
{"op":"mcm","clk":"11540782437","pt":1719498324121,"mc":[{"id":"1.230178312","rc":[{"atl":[[9.6,11.69]],"id":51441055}],"con":true,"img":false}]}
{"op":"mcm","clk":"11540782624","pt":1719498325783,"mc":[{"id":"1.230178312","rc":[{"atb":[[2.26,0]],"id":56913144},{"atb":[[3.15,0]],"id":68462283},{"atb":[[3.15,0]],"id":52951653}],"con":true,"img":false}]}
{"op":"mcm","clk":"11540782738","pt":1719498326713,"mc":[{"id":"1.230178312","rc":[{"atb":[[3.25,5.26]],"id":68462283}],"con":true,"img":false}]}
{"op":"mcm","clk":"11540783077","pt":1719498329825,"mc":[{"id":"1.230178312","rc":[{"atl":[[1000,0.69]],"id":51441055}],"con":true,"img":false}]}
{"op":"mcm","clk":"11540783097","pt":1719498329981,"mc":[{"id":"1.230178312","rc":[{"atl":[[1000,0.16]],"id":51441055}],"con":true,"img":false}]}
{"op":"mcm","clk":"11540783107","pt":1719498330086,"mc":[{"id":"1.230178312","rc":[{"atl":[[9.6,12.22]],"id":51441055}],"con":true,"img":false}]}
{"op":"mcm","clk":"11540783593","pt":1719498335388,"mc":[{"id":"1.230178312","rc":[{"atl":[[14,3.72]],"id":68462283}],"con":true,"img":false}]}
{"op":"mcm","clk":"11540784139","pt":1719498341030,"mc":[{"id":"1.230178312","rc":[{"atl":[[1000,0.36]],"id":68462283}],"con":true,"img":false}]}
{"op":"mcm","clk":"11540784157","pt":1719498341236,"mc":[{"id":"1.230178312","rc":[{"atl":[[1000,0]],"id":68462283}],"con":true,"img":false}]}
{"op":"mcm","clk":"11540784169","pt":1719498341295,"mc":[{"id":"1.230178312","rc":[{"atl":[[14,4.08]],"id":68462283},{"atb":[[4.3,0]],"id":52951653},{"atb":[[3.75,0]],"id":51441055}],"con":true,"img":false}]}
{"op":"mcm","clk":"11540784225","pt":1719498341912,"mc":[{"id":"1.230178312","rc":[{"atb":[[4.3,1.74]],"id":52951653}],"con":true,"img":false}]}
{"op":"mcm","clk":"11540784459","pt":1719498344296,"mc":[{"id":"1.230178312","rc":[{"atl":[[15,1],[15.5,4.64]],"id":68462283},{"atb":[[2.6,7.4]],"id":51441055},{"atl":[[9.6,11.69]],"id":51441055}],"con":true,"img":false}]}
{"op":"mcm","clk":"11540784471","pt":1719498344416,"mc":[{"id":"1.230178312","rc":[{"atl":[[7.4,1],[7,1.21]],"id":56913144},{"atb":[[4.9,0],[4.2,9.17]],"id":68462283},{"atl":[[13.5,4.14],[15.5,0]],"id":68462283},{"atl":[[8.8,10.83]],"id":39100893}],"con":true,"img":false}]}
{"op":"mcm","clk":"11540784484","pt":1719498344503,"mc":[{"id":"1.230178312","rc":[{"atb":[[4.2,0],[4.7,9.17]],"id":68462283},{"atb":[[3.15,5.51]],"id":39100893},{"atl":[[8.6,0]],"id":39100893}],"con":true,"img":false}]}
{"op":"mcm","clk":"11540784541","pt":1719498345120,"mc":[{"id":"1.230178312","rc":[{"atl":[[14.5,2.45]],"id":68462283}],"con":true,"img":false}]}
{"op":"mcm","clk":"11540784551","pt":1719498345222,"mc":[{"id":"1.230178312","rc":[{"atl":[[18,0]],"id":68462283}],"con":true,"img":false}]}
{"op":"mcm","clk":"11540784561","pt":1719498345326,"mc":[{"id":"1.230178312","rc":[{"atl":[[13.5,5.92]],"id":68462283}],"con":true,"img":false}]}
{"op":"mcm","clk":"11540784787","pt":1719498347811,"mc":[{"id":"1.230178312","rc":[{"atl":[[14,2.44]],"id":68462283}],"con":true,"img":false}]}
{"op":"mcm","clk":"11540784991","pt":1719498350029,"mc":[{"id":"1.230178312","rc":[{"atl":[[1000,0.69]],"id":51441055}],"con":true,"img":false}]}
{"op":"mcm","clk":"11540785011","pt":1719498350235,"mc":[{"id":"1.230178312","rc":[{"atl":[[1000,0.16]],"id":51441055}],"con":true,"img":false}]}
{"op":"mcm","clk":"11540785023","pt":1719498350340,"mc":[{"id":"1.230178312","rc":[{"atl":[[9.6,12.22]],"id":51441055}],"con":true,"img":false}]}
{"op":"mcm","clk":"11540785048","pt":1719498350603,"mc":[{"id":"1.230178312","rc":[{"atl":[[7.4,0],[7.2,1]],"id":56913144},{"atl":[[13.5,2.62],[15,5.9]],"id":68462283},{"atl":[[8.6,5.27],[8.8,4.27]],"id":39100893},{"atl":[[6.8,10.89],[7,5.66]],"id":52951653}],"con":true,"img":false}]}
{"op":"mcm","clk":"11540785068","pt":1719498350807,"mc":[{"id":"1.230178312","rc":[{"atl":[[13,1.65]],"id":68462283},{"atl":[[6.8,9.89]],"id":52951653}],"con":true,"img":false}]}
{"op":"mcm","clk":"11540785074","pt":1719498350912,"mc":[{"id":"1.230178312","rc":[{"atl":[[8.6,8.93]],"id":39100893},{"atl":[[6.6,5.72]],"id":52951653}],"con":true,"img":false}]}
{"op":"mcm","clk":"11540785092","pt":1719498351123,"mc":[{"id":"1.230178312","rc":[{"atl":[[12.5,0.84]],"id":68462283}],"con":true,"img":false}]}
{"op":"mcm","clk":"11540785166","pt":1719498352010,"mc":[{"id":"1.230178312","rc":[{"atb":[[6.2,2.16]],"id":68462283},{"atl":[[17.5,0]],"id":68462283}],"con":true,"img":false}]}
{"op":"mcm","clk":"11540785176","pt":1719498352115,"mc":[{"id":"1.230178312","rc":[{"atb":[[5.9,5.3]],"id":68462283},{"atl":[[12.5,2.84]],"id":68462283}],"con":true,"img":false}]}
{"op":"mcm","clk":"11540785195","pt":1719498352322,"mc":[{"id":"1.230178312","rc":[{"atb":[[5.6,0]],"id":68462283}],"con":true,"img":false}]}
{"op":"mcm","clk":"11540785217","pt":1719498352528,"mc":[{"id":"1.230178312","rc":[{"atb":[[6.6,1.84]],"id":68462283}],"con":true,"img":false}]}
{"op":"mcm","clk":"11540785226","pt":1719498352633,"mc":[{"id":"1.230178312","rc":[{"atl":[[13.5,1.78]],"id":68462283}],"con":true,"img":false}]}
{"op":"mcm","clk":"11540785253","pt":1719498352943,"mc":[{"id":"1.230178312","rc":[{"atb":[[6.4,0]],"id":68462283}],"con":true,"img":false}]}
{"op":"mcm","clk":"11540785275","pt":1719498353106,"mc":[{"id":"1.230178312","rc":[{"atb":[[6.2,1.32]],"id":68462283}],"con":true,"img":false}]}
{"op":"mcm","clk":"11540785345","pt":1719498353936,"mc":[{"id":"1.230178312","rc":[{"atl":[[13,0]],"id":68462283}],"con":true,"img":false}]}
{"op":"mcm","clk":"11540785352","pt":1719498354040,"mc":[{"id":"1.230178312","rc":[{"atb":[[6.6,3.99]],"id":68462283}],"con":true,"img":false}]}
{"op":"mcm","clk":"11540785484","pt":1719498355542,"mc":[{"id":"1.230178312","rc":[{"atl":[[14,2.08]],"id":68462283}],"con":true,"img":false}]}
{"op":"mcm","clk":"11540785518","pt":1719498355909,"mc":[{"id":"1.230178312","rc":[{"atl":[[12.5,0.84],[13.5,0],[14,0],[14.5,0.58]],"id":68462283}],"con":true,"img":false}]}
{"op":"mcm","clk":"11540785580","pt":1719498356634,"mc":[{"id":"1.230178312","rc":[{"atl":[[12.5,0]],"id":68462283}],"con":true,"img":false}]}
{"op":"mcm","clk":"11540785607","pt":1719498356840,"mc":[{"id":"1.230178312","rc":[{"atl":[[24,4.35],[14.5,2.47],[15,0.99]],"id":68462283}],"con":true,"img":false}]}
{"op":"mcm","clk":"11540785618","pt":1719498356943,"mc":[{"id":"1.230178312","rc":[{"atl":[[14,1.57]],"id":68462283}],"con":true,"img":false}]}
{"op":"mcm","clk":"11540785687","pt":1719498357622,"mc":[{"id":"1.230178312","rc":[{"atb":[[2.28,0]],"id":56913144},{"atb":[[3.2,0]],"id":68462283},{"atb":[[3.2,0]],"id":52951653}],"con":true,"img":false}]}
{"op":"mcm","clk":"11540785707","pt":1719498357826,"mc":[{"id":"1.230178312","rc":[{"atl":[[7.2,0]],"id":56913144}],"con":true,"img":false}]}
{"op":"mcm","clk":"11540785716","pt":1719498357929,"mc":[{"id":"1.230178312","rc":[{"atl":[[14,3.29]],"id":68462283}],"con":true,"img":false}]}
{"op":"mcm","clk":"11540785798","pt":1719498358613,"mc":[{"id":"1.230178312","rc":[{"atl":[[13.5,0.84]],"id":68462283}],"con":true,"img":false}]}
{"op":"mcm","clk":"11540786090","pt":1719498361937,"mc":[{"id":"1.230178312","rc":[{"atl":[[15,5.94]],"id":68462283}],"con":true,"img":false}]}
{"op":"mcm","clk":"11540786103","pt":1719498362039,"mc":[{"id":"1.230178312","rc":[{"atl":[[24,0]],"id":68462283}],"con":true,"img":false}]}
{"op":"mcm","clk":"11540786307","pt":1719498363854,"mc":[{"id":"1.230178312","rc":[{"atl":[[13.5,2.72]],"id":68462283}],"con":true,"img":false}]}
{"op":"mcm","clk":"11540786359","pt":1719498364429,"mc":[{"id":"1.230178312","rc":[{"atl":[[9.6,11.69]],"id":51441055}],"con":true,"img":false}]}
{"op":"mcm","clk":"11540786366","pt":1719498364533,"mc":[{"id":"1.230178312","rc":[{"atl":[[13.5,4.65]],"id":68462283}],"con":true,"img":false}]}
{"op":"mcm","clk":"11540786528","pt":1719498366229,"mc":[{"id":"1.230178312","rc":[{"atl":[[14,1.72]],"id":68462283}],"con":true,"img":false}]}
{"op":"mcm","clk":"11540786886","pt":1719498370128,"mc":[{"id":"1.230178312","rc":[{"spn":3.31,"spf":1.1,"id":56913144},{"spn":6.24,"spf":1.0,"id":68462283},{"spn":5.47,"spf":1.0,"id":39100893},{"atl":[[1000,0.69]],"id":51441055}],"con":true,"img":false}]}
{"op":"mcm","clk":"11540786900","pt":1719498370334,"mc":[{"id":"1.230178312","rc":[{"atl":[[1000,0.16]],"id":51441055}],"con":true,"img":false}]}
{"op":"mcm","clk":"11540786906","pt":1719498370434,"mc":[{"id":"1.230178312","rc":[{"atl":[[9.6,12.22]],"id":51441055}],"con":true,"img":false}]}
{"op":"mcm","clk":"11540787030","pt":1719498372040,"mc":[{"id":"1.230178312","rc":[{"atl":[[13,1.66]],"id":68462283}],"con":true,"img":false}]}
{"op":"mcm","clk":"11540787068","pt":1719498372553,"mc":[{"id":"1.230178312","rc":[{"atl":[[13.5,2.77]],"id":68462283}],"con":true,"img":false}]}
{"op":"mcm","clk":"11540787078","pt":1719498372657,"mc":[{"id":"1.230178312","rc":[{"atl":[[12.5,0.84],[13,3.92]],"id":68462283}],"con":true,"img":false}]}
{"op":"mcm","clk":"11540787134","pt":1719498373231,"mc":[{"id":"1.230178312","rc":[{"atl":[[12.5,2.87]],"id":68462283}],"con":true,"img":false}]}
{"op":"mcm","clk":"11540787171","pt":1719498373539,"mc":[{"id":"1.230178312","rc":[{"atl":[[14.5,0.58]],"id":68462283}],"con":true,"img":false}]}
{"op":"mcm","clk":"11540787181","pt":1719498373642,"mc":[{"id":"1.230178312","rc":[{"atl":[[13.5,1.93]],"id":68462283}],"con":true,"img":false}]}
{"op":"mcm","clk":"11540787191","pt":1719498373745,"mc":[{"id":"1.230178312","rc":[{"atl":[[12.5,5.07]],"id":68462283}],"con":true,"img":false}]}
{"op":"mcm","clk":"11540787300","pt":1719498375040,"mc":[{"id":"1.230178312","rc":[{"atl":[[13,2.26]],"id":68462283}],"con":true,"img":false}]}
{"op":"mcm","clk":"11540787399","pt":1719498376334,"mc":[{"id":"1.230178312","rc":[{"atl":[[12.5,2.87],[13,0],[13.5,0],[14,0]],"id":68462283}],"con":true,"img":false}]}
{"op":"mcm","clk":"11540787595","pt":1719498378041,"mc":[{"id":"1.230178312","rc":[{"atl":[[12,1.66]],"id":68462283}],"con":true,"img":false}]}
{"op":"mcm","clk":"11540787646","pt":1719498378657,"mc":[{"id":"1.230178312","rc":[{"atl":[[12.5,0.84]],"id":68462283}],"con":true,"img":false}]}
{"op":"mcm","clk":"11540787654","pt":1719498378759,"mc":[{"id":"1.230178312","rc":[{"atl":[[12,4.03]],"id":68462283}],"con":true,"img":false}]}
{"op":"mcm","clk":"11540787730","pt":1719498379650,"mc":[{"id":"1.230178312","rc":[{"atl":[[11.5,0.84]],"id":68462283}],"con":true,"img":false}]}
{"op":"mcm","clk":"11540787798","pt":1719498380643,"mc":[{"id":"1.230178312","rc":[{"atb":[[4.7,3.28]],"id":56913144},{"atb":[[1.03,2]],"id":68462283},{"atb":[[1.03,1]],"id":70681331},{"atb":[[1.03,1]],"id":39100893},{"atb":[[4.8,2.18]],"id":52951653},{"atb":[[4.8,1.09]],"id":51441055}],"con":true,"img":false}]}
{"op":"mcm","clk":"11540787805","pt":1719498380747,"mc":[{"id":"1.230178312","rc":[{"atb":[[4.7,4.4]],"id":56913144},{"atb":[[1.03,2]],"id":70681331},{"atb":[[1.03,2]],"id":39100893},{"atb":[[4.8,2.18]],"id":51441055}],"con":true,"img":false}]}
{"op":"mcm","clk":"11540787811","pt":1719498380846,"mc":[{"id":"1.230178312","rc":[{"atb":[[1.03,1.7]],"id":68462283},{"atb":[[1.03,1.85]],"id":70681331},{"atb":[[1.03,1.99]],"id":39100893}],"con":true,"img":false}]}
{"op":"mcm","clk":"11540787816","pt":1719498380950,"mc":[{"id":"1.230178312","rc":[{"atb":[[1.03,1.7]],"id":70681331},{"atb":[[1.03,1.98]],"id":39100893}],"con":true,"img":false}]}
{"op":"mcm","clk":"11540787825","pt":1719498381074,"mc":[{"id":"1.230178312","rc":[{"atl":[[7.6,1]],"id":56913144},{"atb":[[1.03,0]],"id":68462283},{"atl":[[15,4.94],[15.5,1]],"id":68462283},{"atb":[[1.03,0]],"id":70681331},{"atb":[[1.03,0]],"id":39100893},{"atl":[[8.8,11.65]],"id":39100893},{"atl":[[10,3.94]],"id":51441055}],"con":true,"img":false}]}
{"op":"mcm","clk":"11540787835","pt":1719498381158,"mc":[{"id":"1.230178312","rc":[{"atb":[[6.2,3.02]],"id":68462283},{"atb":[[6.2,6.5]],"id":70681331},{"atb":[[5.3,8.14]],"id":39100893},{"atl":[[8.6,3.66]],"id":39100893},{"atl":[[10.5,0]],"id":51441055}],"con":true,"img":false}]}
{"op":"mcm","clk":"11540787850","pt":1719498381363,"mc":[{"id":"1.230178312","rc":[{"atb":[[5.6,0]],"id":39100893}],"con":true,"img":false}]}
{"op":"mcm","clk":"11540787863","pt":1719498381570,"mc":[{"id":"1.230178312","rc":[{"atb":[[4.5,0]],"id":39100893},{"atl":[[7.4,1.14]],"id":39100893},{"atb":[[3.95,0]],"id":51441055}],"con":true,"img":false}]}
{"op":"mcm","clk":"11540787874","pt":1719498381677,"mc":[{"id":"1.230178312","rc":[{"atb":[[5.4,1.84],[5.6,0.84]],"id":39100893},{"atl":[[8.2,0]],"id":39100893}],"con":true,"img":false}]}
{"op":"mcm","clk":"11540787911","pt":1719498382039,"mc":[{"id":"1.230178312","rc":[{"atl":[[7.6,0.84]],"id":39100893}],"con":true,"img":false}]}
{"op":"mcm","clk":"11540787927","pt":1719498382153,"mc":[{"id":"1.230178312","rc":[{"atb":[[5.6,5.38]],"id":39100893}],"con":true,"img":false}]}
{"op":"mcm","clk":"11540787939","pt":1719498382360,"mc":[{"id":"1.230178312","rc":[{"atl":[[7.4,0],[8.4,1.14]],"id":39100893}],"con":true,"img":false}]}
{"op":"mcm","clk":"11540787962","pt":1719498382661,"mc":[{"id":"1.230178312","rc":[{"atb":[[5.4,1]],"id":39100893},{"atl":[[8.2,0.84],[7.6,0]],"id":39100893},{"atl":[[9.6,11.38]],"id":51441055}],"con":true,"img":false}]}
{"op":"mcm","clk":"11540787972","pt":1719498382764,"mc":[{"id":"1.230178312","rc":[{"atl":[[8.2,3.94]],"id":39100893}],"con":true,"img":false}]}
{"op":"mcm","clk":"11540787986","pt":1719498382970,"mc":[{"id":"1.230178312","rc":[{"atb":[[3.7,8.53]],"id":39100893},{"atl":[[1000,0.61]],"id":39100893}],"con":true,"img":false}]}
{"op":"mcm","clk":"11540787996","pt":1719498383074,"mc":[{"id":"1.230178312","rc":[{"atb":[[5.6,11.28]],"id":39100893},{"atl":[[1000,0]],"id":39100893}],"con":true,"img":false}]}
{"op":"mcm","clk":"11540788003","pt":1719498383139,"mc":[{"id":"1.230178312","rc":[{"atl":[[8.4,1.75]],"id":39100893}],"con":true,"img":false}]}
{"op":"mcm","clk":"11540788008","pt":1719498383240,"mc":[{"id":"1.230178312","rc":[{"atb":[[5.4,0]],"id":39100893}],"con":true,"img":false}]}
{"op":"mcm","clk":"11540788022","pt":1719498383446,"mc":[{"id":"1.230178312","rc":[{"atb":[[5.7,1]],"id":39100893}],"con":true,"img":false}]}
{"op":"mcm","clk":"11540788063","pt":1719498384063,"mc":[{"id":"1.230178312","rc":[{"atb":[[5.6,6.74]],"id":39100893}],"con":true,"img":false}]}
{"op":"mcm","clk":"11540788117","pt":1719498384657,"mc":[{"id":"1.230178312","rc":[{"atl":[[9.6,10.85]],"id":51441055}],"con":true,"img":false}]}
{"op":"mcm","clk":"11540788169","pt":1719498385263,"mc":[{"id":"1.230178312","rc":[{"atl":[[5.9,1.58]],"id":56913144},{"atb":[[3.25,0]],"id":68462283},{"atl":[[11.5,1.84]],"id":68462283},{"atl":[[13.5,1]],"id":70681331},{"atl":[[8,1]],"id":39100893},{"atl":[[6,1]],"id":52951653},{"atl":[[9.4,1]],"id":51441055}],"con":true,"img":false}]}
{"op":"mcm","clk":"11540788187","pt":1719498385574,"mc":[{"id":"1.230178312","rc":[{"atl":[[6.6,4.72]],"id":52951653}],"con":true,"img":false}]}
{"op":"mcm","clk":"11540788194","pt":1719498385636,"mc":[{"id":"1.230178312","rc":[{"atl":[[12.5,0]],"id":68462283}],"con":true,"img":false}]}
{"op":"mcm","clk":"11540788203","pt":1719498385742,"mc":[{"id":"1.230178312","rc":[{"atl":[[6,2]],"id":52951653}],"con":true,"img":false}]}
{"op":"mcm","clk":"11540788212","pt":1719498385844,"mc":[{"id":"1.230178312","rc":[{"atl":[[8.2,0.84]],"id":39100893},{"atl":[[9.6,8.21]],"id":51441055}],"con":true,"img":false}]}
{"op":"mcm","clk":"11540788223","pt":1719498386041,"mc":[{"id":"1.230178312","rc":[{"atl":[[5.9,0.84]],"id":52951653}],"con":true,"img":false}]}
{"op":"mcm","clk":"11540788231","pt":1719498386145,"mc":[{"id":"1.230178312","rc":[{"atl":[[6.2,1.54]],"id":56913144},{"atl":[[7.4,0]],"id":52951653}],"con":true,"img":false}]}
{"op":"mcm","clk":"11540788237","pt":1719498386247,"mc":[{"id":"1.230178312","rc":[{"atl":[[11.5,4.43]],"id":68462283},{"atb":[[5.7,0]],"id":39100893},{"atb":[[5.2,0]],"id":52951653},{"trd":[[5.2,1.69]],"ltp":5.2,"tv":1.69,"id":52951653}],"con":true,"img":false}]}
{"op":"mcm","clk":"11540788245","pt":1719498386353,"mc":[{"id":"1.230178312","rc":[{"atl":[[8,0]],"id":39100893}],"con":true,"img":false}]}
{"op":"mcm","clk":"11540788251","pt":1719498386451,"mc":[{"id":"1.230178312","rc":[{"atl":[[8.2,1.84]],"id":39100893}],"con":true,"img":false}]}
{"op":"mcm","clk":"11540788258","pt":1719498386554,"mc":[{"id":"1.230178312","rc":[{"atl":[[11,2.31]],"id":68462283},{"atl":[[8.2,4.94]],"id":39100893}],"con":true,"img":false}]}
{"op":"mcm","clk":"11540788292","pt":1719498387072,"mc":[{"id":"1.230178312","rc":[{"atl":[[7.6,0]],"id":56913144},{"atl":[[15,5.94],[15.5,0]],"id":68462283},{"atl":[[9.2,1]],"id":39100893},{"atb":[[3.85,0]],"id":52951653},{"atl":[[10,2.94],[10.5,1]],"id":51441055}],"con":true,"img":false}]}
{"op":"mcm","clk":"11540788300","pt":1719498387175,"mc":[{"id":"1.230178312","rc":[{"atl":[[10.5,0.84],[12,2.37],[13.5,8],[15,0.99]],"id":68462283},{"atl":[[6.8,0],[7,15.1]],"id":52951653}],"con":true,"img":false}]}
{"op":"mcm","clk":"11540788308","pt":1719498387238,"mc":[{"id":"1.230178312","rc":[{"atl":[[11,4.85]],"id":68462283},{"atb":[[3.8,8.22]],"id":52951653},{"atl":[[5.9,6.37]],"id":52951653}],"con":true,"img":false}]}
{"op":"mcm","clk":"11540788315","pt":1719498387343,"mc":[{"id":"1.230178312","rc":[{"atl":[[11.5,3.43]],"id":68462283},{"atl":[[6,1]],"id":52951653}],"con":true,"img":false}]}
{"op":"mcm","clk":"11540788328","pt":1719498387541,"mc":[{"id":"1.230178312","rc":[{"atl":[[10.5,1.84]],"id":68462283}],"con":true,"img":false}]}
{"op":"mcm","clk":"11540788337","pt":1719498387655,"mc":[{"id":"1.230178312","rc":[{"atl":[[5.8,1],[6.2,4.32]],"id":52951653}],"con":true,"img":false}]}
{"op":"mcm","clk":"11540788351","pt":1719498387847,"mc":[{"id":"1.230178312","rc":[{"atb":[[1.05,1],[1.04,1]],"id":56913144},{"atb":[[1.07,1],[1.05,1]],"id":68462283},{"atl":[[11,2.54]],"id":68462283},{"atb":[[1.05,1]],"id":70681331},{"atb":[[1.06,1],[1.04,1]],"id":39100893},{"atl":[[8.6,0],[8.8,8.38]],"id":39100893},{"atb":[[1.05,1],[1.04,1]],"id":52951653},{"atb":[[1.04,1]],"id":51441055}],"con":true,"img":false}]}
{"op":"mcm","clk":"11540788359","pt":1719498387959,"mc":[{"id":"1.230178312","rc":[{"atb":[[1.05,0.43],[1.04,0.64]],"id":56913144},{"atb":[[1.07,0.32],[1.05,0.48]],"id":68462283},{"atl":[[10.5,4.71]],"id":68462283},{"atb":[[1.05,0.48],[1.07,1]],"id":70681331},{"atb":[[1.06,0.38],[1.04,0.57]],"id":39100893},{"atl":[[9,3.3]],"id":39100893},{"atb":[[1.05,0.42],[1.04,0.62]],"id":52951653},{"atb":[[1.05,1],[1.04,0.62]],"id":51441055}],"con":true,"img":false}]}
{"op":"mcm","clk":"11540788368","pt":1719498388157,"mc":[{"id":"1.230178312","rc":[{"atb":[[1.05,0],[1.04,0]],"id":56913144},{"atb":[[1.07,0],[1.05,0]],"id":68462283},{"atl":[[11.5,2.59]],"id":68462283},{"atb":[[1.07,0.32],[1.05,0]],"id":70681331},{"atb":[[1.06,0],[1.04,0]],"id":39100893},{"atb":[[1.05,0],[1.04,0]],"id":52951653},{"atb":[[1.05,0.42],[1.04,0]],"id":51441055}],"con":true,"img":false}]}
{"op":"mcm","clk":"11540788376","pt":1719498388261,"mc":[{"id":"1.230178312","rc":[{"atb":[[4.7,5.47]],"id":56913144},{"atb":[[6.2,3.82]],"id":68462283},{"atb":[[6.2,6.98],[1.07,0]],"id":70681331},{"atb":[[5.3,9.09]],"id":39100893},{"atb":[[4.8,3.22]],"id":52951653},{"atb":[[4.8,2.8],[1.05,0]],"id":51441055}],"con":true,"img":false}]}
{"op":"mcm","clk":"11540788382","pt":1719498388363,"mc":[{"id":"1.230178312","rc":[{"atb":[[6.2,7.3]],"id":70681331},{"atl":[[6,0]],"id":52951653},{"atb":[[4.8,3.22]],"id":51441055}],"con":true,"img":false}]}
{"op":"mcm","clk":"11540788390","pt":1719498388469,"mc":[{"id":"1.230178312","rc":[{"atl":[[5.8,2]],"id":52951653}],"con":true,"img":false}]}
{"op":"mcm","clk":"11540788401","pt":1719498388571,"mc":[{"id":"1.230178312","rc":[{"atl":[[10,2.53]],"id":68462283}],"con":true,"img":false}]}
{"op":"mcm","clk":"11540788409","pt":1719498388674,"mc":[{"id":"1.230178312","rc":[{"atb":[[3.45,0],[3.7,13.33]],"id":56913144},{"atl":[[10.5,1.84],[11,0],[11.5,0],[12,0]],"id":68462283},{"atl":[[7,10.65]],"id":52951653}],"con":true,"img":false}]}
{"op":"mcm","clk":"11540788415","pt":1719498388779,"mc":[{"id":"1.230178312","rc":[{"atb":[[3.7,0]],"id":56913144},{"atl":[[7.8,0]],"id":56913144},{"atl":[[13,1.98],[15,0]],"id":68462283},{"atl":[[12.5,0],[13,1]],"id":70681331},{"atb":[[3.7,0]],"id":39100893},{"atl":[[9.2,0],[10,1],[8.8,0]],"id":39100893},{"atb":[[3.3,0]],"id":52951653},{"atl":[[5.8,7.57],[6.8,1],[7,1.21]],"id":52951653},{"atb":[[3.6,7.41],[3.9,0]],"id":51441055}],"con":true,"img":false}]}
{"op":"mcm","clk":"11540788425","pt":1719498388847,"mc":[{"id":"1.230178312","rc":[{"atb":[[2.94,51.55]],"id":56913144},{"atl":[[11,9.54]],"id":56913144},{"atl":[[13,3],[14,3.36]],"id":70681331},{"atb":[[3.25,11.73]],"id":39100893},{"atl":[[10.5,6.6]],"id":39100893},{"atb":[[2.78,56.18]],"id":52951653},{"atl":[[6.2,12.7]],"id":52951653}],"con":true,"img":false}]}
{"op":"mcm","clk":"11540788434","pt":1719498388949,"mc":[{"id":"1.230178312","rc":[{"atb":[[2.94,0]],"id":56913144},{"atl":[[13,1],[13.5,7]],"id":70681331},{"atb":[[3.25,0],[4.1,11.73]],"id":39100893},{"atl":[[5.8,6.57],[5.7,7.57]],"id":52951653}],"con":true,"img":false}]}
{"op":"mcm","clk":"11540788444","pt":1719498389049,"mc":[{"id":"1.230178312","rc":[{"atb":[[4.2,17.85]],"id":56913144},{"atl":[[12.5,0.84]],"id":70681331},{"atl":[[6.2,4.31]],"id":52951653}],"con":true,"img":false}]}
{"op":"mcm","clk":"11540788452","pt":1719498389154,"mc":[{"id":"1.230178312","rc":[{"atl":[[14,2.52]],"id":70681331},{"atl":[[5.6,1]],"id":52951653}],"con":true,"img":false}]}
{"op":"mcm","clk":"11540788476","pt":1719498389452,"mc":[{"id":"1.230178312","rc":[{"atl":[[10.5,0.84]],"id":68462283},{"atl":[[5.8,5.57],[6.6,0]],"id":52951653}],"con":true,"img":false}]}
{"op":"mcm","clk":"11540788486","pt":1719498389554,"mc":[{"id":"1.230178312","rc":[{"atl":[[9.8,1]],"id":68462283},{"atl":[[5.9,5.53],[5.6,2]],"id":52951653}],"con":true,"img":false}]}
{"op":"mcm","clk":"11540788493","pt":1719498389658,"mc":[{"id":"1.230178312","rc":[{"atl":[[10,5.49]],"id":68462283},{"atl":[[13,3.08]],"id":70681331},{"atl":[[5.6,7.43]],"id":52951653}],"con":true,"img":false}]}
{"op":"mcm","clk":"11540788504","pt":1719498389761,"mc":[{"id":"1.230178312","rc":[{"atl":[[10,2.96]],"id":68462283},{"atl":[[5.5,7.43],[5.7,0]],"id":52951653}],"con":true,"img":false}]}
{"op":"mcm","clk":"11540788569","pt":1719498390451,"mc":[{"id":"1.230178312","rc":[{"atl":[[13.5,6]],"id":70681331},{"atl":[[5.6,6.43],[6.2,0]],"id":52951653}],"con":true,"img":false}]}
{"op":"mcm","clk":"11540788575","pt":1719498390543,"mc":[{"id":"1.230178312","rc":[{"atl":[[12.5,1.84]],"id":70681331},{"atl":[[5.4,1]],"id":52951653},{"atl":[[1000,0.7]],"id":51441055}],"con":true,"img":false}]}
{"op":"mcm","clk":"11540788583","pt":1719498390658,"mc":[{"id":"1.230178312","rc":[{"atl":[[12.5,4.92],[13.5,0]],"id":70681331},{"atb":[[5.1,0]],"id":52951653},{"atl":[[5.5,12.9]],"id":52951653},{"trd":[[5.1,2.04]],"ltp":5.1,"tv":2.04,"id":52951653},{"atl":[[1000,0.16]],"id":51441055}],"con":true,"img":false}]}
{"op":"mcm","clk":"11540788591","pt":1719498390762,"mc":[{"id":"1.230178312","rc":[{"atl":[[9.4,1.54]],"id":51441055}],"con":true,"img":false}]}
{"op":"mcm","clk":"11540788602","pt":1719498390852,"mc":[{"id":"1.230178312","rc":[{"atl":[[5.6,5.43]],"id":52951653}],"con":true,"img":false}]}
{"op":"mcm","clk":"11540788609","pt":1719498390964,"mc":[{"id":"1.230178312","rc":[{"atl":[[5.4,2]],"id":52951653}],"con":true,"img":false}]}
{"op":"mcm","clk":"11540788617","pt":1719498391058,"mc":[{"id":"1.230178312","rc":[{"atl":[[12.5,6.97]],"id":70681331},{"atl":[[9.4,4.44]],"id":51441055}],"con":true,"img":false}]}
{"op":"mcm","clk":"11540788623","pt":1719498391166,"mc":[{"id":"1.230178312","rc":[{"atl":[[9,0.84],[9.2,4.44],[9.6,3.02]],"id":51441055}],"con":true,"img":false}]}
{"op":"mcm","clk":"11540788673","pt":1719498391643,"mc":[{"id":"1.230178312","rc":[{"atb":[[4.9,4.89]],"id":56913144},{"atb":[[5.7,4.45]],"id":39100893},{"atb":[[3.8,9.22],[5,0]],"id":52951653},{"atb":[[4.9,1],[5,1]],"id":51441055},{"atl":[[9,3.66]],"id":51441055}],"con":true,"img":false}]}
{"op":"mcm","clk":"11540788685","pt":1719498391750,"mc":[{"id":"1.230178312","rc":[{"atl":[[9.2,0],[8.8,4.44]],"id":51441055}],"con":true,"img":false}]}
{"op":"mcm","clk":"11540788706","pt":1719498391951,"mc":[{"id":"1.230178312","rc":[{"atb":[[3.9,12.04],[4.2,6.91]],"id":56913144},{"atb":[[2.44,69.44],[2.78,0]],"id":52951653},{"atl":[[6.4,11.06],[5.5,5.47]],"id":52951653},{"atl":[[10.5,0],[9.8,1.88]],"id":51441055}],"con":true,"img":false}]}
{"op":"mcm","clk":"11540788717","pt":1719498392057,"mc":[{"id":"1.230178312","rc":[{"atb":[[5.8,0.84],[5.1,0]],"id":39100893},{"atb":[[4.9,0.84]],"id":52951653},{"atl":[[5.9,0]],"id":52951653}],"con":true,"img":false}]}
{"op":"mcm","clk":"11540788738","pt":1719498392267,"mc":[{"id":"1.230178312","rc":[{"atb":[[5.7,10.32]],"id":39100893},{"atl":[[5.4,7.02]],"id":52951653},{"atl":[[9,7.01]],"id":51441055}],"con":true,"img":false}]}
{"op":"mcm","clk":"11540788749","pt":1719498392368,"mc":[{"id":"1.230178312","rc":[{"atl":[[9.4,3.44]],"id":51441055}],"con":true,"img":false}]}
{"op":"mcm","clk":"11540788762","pt":1719498392471,"mc":[{"id":"1.230178312","rc":[{"atl":[[8.6,1]],"id":51441055}],"con":true,"img":false}]}
{"op":"mcm","clk":"11540788790","pt":1719498392782,"mc":[{"id":"1.230178312","rc":[{"atl":[[9,4.19]],"id":51441055}],"con":true,"img":false}]}
{"op":"mcm","clk":"11540788812","pt":1719498392947,"mc":[{"id":"1.230178312","rc":[{"atl":[[5.8,0],[5.4,2],[5.6,0],[5.5,0]],"id":52951653},{"atl":[[10,0],[8.6,1.78]],"id":51441055}],"con":true,"img":false}]}
{"op":"mcm","clk":"11540788826","pt":1719498393152,"mc":[{"id":"1.230178312","rc":[{"atl":[[6.2,4.47]],"id":52951653},{"atl":[[8.8,7.81]],"id":51441055}],"con":true,"img":false}]}
{"op":"mcm","clk":"11540788838","pt":1719498393253,"mc":[{"id":"1.230178312","rc":[{"atl":[[5.3,0.84]],"id":52951653},{"atl":[[9,3.35]],"id":51441055}],"con":true,"img":false}]}
{"op":"mcm","clk":"11540788849","pt":1719498393465,"mc":[{"id":"1.230178312","rc":[{"atb":[[4.2,0]],"id":56913144},{"atl":[[5.4,1]],"id":52951653},{"atl":[[8.4,3.02],[9.6,0]],"id":51441055}],"con":true,"img":false}]}
{"op":"mcm","clk":"11540788863","pt":1719498393578,"mc":[{"id":"1.230178312","rc":[{"atl":[[6,1.78]],"id":52951653},{"atl":[[8.2,3.02],[8.6,1.45]],"id":51441055}],"con":true,"img":false}]}
{"op":"mcm","clk":"11540788872","pt":1719498393688,"mc":[{"id":"1.230178312","rc":[{"atl":[[8.8,3.36]],"id":51441055}],"con":true,"img":false}]}
{"op":"mcm","clk":"11540788900","pt":1719498394054,"mc":[{"id":"1.230178312","rc":[{"atb":[[4.9,11.3]],"id":56913144},{"atl":[[8.6,4.93]],"id":51441055}],"con":true,"img":false}]}
{"op":"mcm","clk":"11540788908","pt":1719498394145,"mc":[{"id":"1.230178312","rc":[{"atl":[[6,1.49]],"id":52951653},{"atl":[[8.4,0],[8.6,4.48]],"id":51441055}],"con":true,"img":false}]}
{"op":"mcm","clk":"11540788914","pt":1719498394250,"mc":[{"id":"1.230178312","rc":[{"atl":[[1000,0.61]],"id":51441055}],"con":true,"img":false}]}
{"op":"mcm","clk":"11540788930","pt":1719498394459,"mc":[{"id":"1.230178312","rc":[{"atl":[[8.6,3.48]],"id":51441055}],"con":true,"img":false}]}
{"op":"mcm","clk":"11540788941","pt":1719498394564,"mc":[{"id":"1.230178312","rc":[{"atl":[[5.9,5]],"id":52951653},{"atl":[[8,1]],"id":51441055}],"con":true,"img":false}]}
{"op":"mcm","clk":"11540788958","pt":1719498394772,"mc":[{"id":"1.230178312","rc":[{"atl":[[6,1]],"id":52951653}],"con":true,"img":false}]}
{"op":"mcm","clk":"11540788968","pt":1719498394872,"mc":[{"id":"1.230178312","rc":[{"atl":[[1000,0.66]],"id":52951653}],"con":true,"img":false}]}
{"op":"mcm","clk":"11540788986","pt":1719498395043,"mc":[{"id":"1.230178312","rc":[{"atl":[[9.4,0.54]],"id":51441055}],"con":true,"img":false}]}
{"op":"mcm","clk":"11540789009","pt":1719498395445,"mc":[{"id":"1.230178312","rc":[{"atl":[[6,0]],"id":52951653}],"con":true,"img":false}]}
{"op":"mcm","clk":"11540789018","pt":1719498395547,"mc":[{"id":"1.230178312","rc":[{"atb":[[3.15,5.51]],"id":68462283},{"atl":[[5.8,1]],"id":52951653}],"con":true,"img":false}]}
{"op":"mcm","clk":"11540789056","pt":1719498395959,"mc":[{"id":"1.230178312","rc":[{"atl":[[8,4.51]],"id":51441055}],"con":true,"img":false}]}
{"op":"mcm","clk":"11540789175","pt":1719498397360,"mc":[{"id":"1.230178312","rc":[{"atl":[[8.4,1.14]],"id":39100893}],"con":true,"img":false}]}
{"op":"mcm","clk":"11540789235","pt":1719498398044,"mc":[{"id":"1.230178312","rc":[{"atl":[[7.8,0.84]],"id":51441055}],"con":true,"img":false}]}
{"op":"mcm","clk":"11540789241","pt":1719498398155,"mc":[{"id":"1.230178312","rc":[{"atb":[[4.9,0]],"id":52951653},{"trd":[[4.9,1.69]],"ltp":4.9,"tv":1.69,"id":52951653}],"con":true,"img":false}]}
{"op":"mcm","clk":"11540789258","pt":1719498398359,"mc":[{"id":"1.230178312","rc":[{"atl":[[8,3.78]],"id":68462283}],"con":true,"img":false}]}
{"op":"mcm","clk":"11540789267","pt":1719498398459,"mc":[{"id":"1.230178312","rc":[{"atl":[[8.2,3.94]],"id":39100893}],"con":true,"img":false}]}
{"op":"mcm","clk":"11540789276","pt":1719498398561,"mc":[{"id":"1.230178312","rc":[{"atl":[[7.8,0.84]],"id":68462283},{"atb":[[3.2,6.34]],"id":39100893},{"atl":[[8.8,1]],"id":39100893}],"con":true,"img":false}]}
{"op":"mcm","clk":"11540789285","pt":1719498398662,"mc":[{"id":"1.230178312","rc":[{"atl":[[10.5,0]],"id":68462283},{"atb":[[6.8,2.48]],"id":70681331},{"atb":[[4.8,5.26],[5.8,2.53],[4.9,5.13]],"id":39100893},{"atb":[[4.3,7.8]],"id":52951653},{"atl":[[8,7.99],[8.2,0]],"id":51441055}],"con":true,"img":false}]}
{"op":"mcm","clk":"11540789295","pt":1719498398767,"mc":[{"id":"1.230178312","rc":[{"atb":[[4.3,6.06],[4.4,5.88],[4.2,6.25]],"id":56913144},{"atb":[[4.1,6.45],[4.2,7.25]],"id":52951653},{"atb":[[4.3,6.06],[4.4,5.88],[4.5,5.71]],"id":51441055}],"con":true,"img":false}]}
{"op":"mcm","clk":"11540789329","pt":1719498399076,"mc":[{"id":"1.230178312","rc":[{"atb":[[6.6,0]],"id":70681331},{"atb":[[5.7,5.87]],"id":39100893}],"con":true,"img":false}]}
{"op":"mcm","clk":"11540789336","pt":1719498399180,"mc":[{"id":"1.230178312","rc":[{"atb":[[6.4,0]],"id":70681331},{"atb":[[5.6,5.9]],"id":39100893}],"con":true,"img":false}]}
{"op":"mcm","clk":"11540789345","pt":1719498399285,"mc":[{"id":"1.230178312","rc":[{"atb":[[6.8,0.84]],"id":70681331},{"atl":[[12,2.11]],"id":70681331},{"atb":[[5.3,2.93],[5.9,4.3]],"id":39100893}],"con":true,"img":false}]}
{"op":"mcm","clk":"11540789356","pt":1719498399346,"mc":[{"id":"1.230178312","rc":[{"atb":[[6.4,1.64]],"id":70681331}],"con":true,"img":false}]}
{"op":"mcm","clk":"11540789366","pt":1719498399451,"mc":[{"id":"1.230178312","rc":[{"atl":[[7.8,4.89],[9.8,0]],"id":68462283},{"atb":[[5.8,7.18]],"id":39100893},{"atl":[[8.8,0]],"id":39100893},{"atl":[[8,6.99]],"id":51441055}],"con":true,"img":false}]}
{"op":"mcm","clk":"11540789375","pt":1719498399567,"mc":[{"id":"1.230178312","rc":[{"atl":[[7.8,5.89]],"id":68462283},{"atl":[[8,1]],"id":39100893},{"atl":[[8.4,1]],"id":51441055}],"con":true,"img":false}]}
{"op":"mcm","clk":"11540789383","pt":1719498399661,"mc":[{"id":"1.230178312","rc":[{"atb":[[6.4,2.48],[6.8,0]],"id":70681331},{"atl":[[11.5,0.84]],"id":70681331},{"atb":[[6,0.84]],"id":39100893}],"con":true,"img":false}]}
{"op":"mcm","clk":"11540789401","pt":1719498399883,"mc":[{"id":"1.230178312","rc":[{"atl":[[75,0],[1000,0.58]],"id":70681331},{"atb":[[5.8,5.49],[5.5,0]],"id":39100893},{"atb":[[4.8,2.13]],"id":52951653}],"con":true,"img":false}]}
{"op":"mcm","clk":"11540789411","pt":1719498399967,"mc":[{"id":"1.230178312","rc":[{"atl":[[1000,0.16]],"id":70681331},{"atb":[[6,2.53]],"id":39100893},{"atl":[[8.2,0.84]],"id":39100893},{"atb":[[4.8,2.13]],"id":51441055}],"con":true,"img":false}]}
{"op":"mcm","clk":"11540789422","pt":1719498400069,"mc":[{"id":"1.230178312","rc":[{"atb":[[6.6,1.83]],"id":68462283},{"trd":[[6.6,4.31]],"ltp":6.6,"tv":4.31,"id":68462283},{"atl":[[12,4.65]],"id":70681331},{"atb":[[5.9,9.48]],"id":39100893}],"con":true,"img":false}]}
{"op":"mcm","clk":"11540789431","pt":1719498400173,"mc":[{"id":"1.230178312","rc":[{"atl":[[12,9.31],[12.5,3.89]],"id":70681331},{"atb":[[4.8,1.03]],"id":52951653},{"atl":[[5.4,0]],"id":52951653}],"con":true,"img":false}]}
{"op":"mcm","clk":"11540789451","pt":1719498400380,"mc":[{"id":"1.230178312","rc":[{"atb":[[4.7,4.35]],"id":56913144}],"con":true,"img":false}]}
{"op":"mcm","clk":"11540789464","pt":1719498400485,"mc":[{"id":"1.230178312","rc":[{"atb":[[4.4,1.69]],"id":52951653}],"con":true,"img":false}]}
{"op":"mcm","clk":"11540789476","pt":1719498400590,"mc":[{"id":"1.230178312","rc":[{"atb":[[6.2,6.45]],"id":70681331},{"atl":[[12.5,2.89]],"id":70681331},{"atl":[[8,0]],"id":39100893},{"atl":[[8.4,0]],"id":51441055}],"con":true,"img":false}]}
{"op":"mcm","clk":"11540789487","pt":1719498400693,"mc":[{"id":"1.230178312","rc":[{"atb":[[4.5,0]],"id":56913144},{"atl":[[6.4,4.39],[6,0]],"id":56913144},{"atl":[[11.5,1.84]],"id":70681331},{"atb":[[5.6,0]],"id":39100893},{"atl":[[9,0],[8.8,1]],"id":39100893},{"atl":[[7.8,1.84]],"id":51441055}],"con":true,"img":false}]}
{"op":"mcm","clk":"11540789495","pt":1719498400755,"mc":[{"id":"1.230178312","rc":[{"atb":[[4.5,5.71]],"id":56913144},{"atl":[[11.5,2.63]],"id":70681331},{"atb":[[5.8,4.65],[5.3,1.94],[5.9,5.18]],"id":39100893},{"atl":[[5.3,0],[5.7,0.84]],"id":52951653}],"con":true,"img":false}]}
{"op":"mcm","clk":"11540789505","pt":1719498400864,"mc":[{"id":"1.230178312","rc":[{"atb":[[4.7,6.59]],"id":56913144},{"atb":[[1.03,2]],"id":68462283},{"atb":[[1.03,2]],"id":70681331},{"atb":[[1.03,2]],"id":39100893},{"atb":[[4.5,2.34]],"id":52951653},{"atb":[[4.8,4.31]],"id":51441055}],"con":true,"img":false}]}
{"op":"mcm","clk":"11540789516","pt":1719498400964,"mc":[{"id":"1.230178312","rc":[{"atb":[[1.03,1.7]],"id":68462283},{"atb":[[1.03,1.76]],"id":70681331},{"atb":[[1.03,1.84],[5.3,0.95],[6.2,4.09]],"id":39100893}],"con":true,"img":false}]}
{"op":"mcm","clk":"11540789523","pt":1719498401069,"mc":[{"id":"1.230178312","rc":[{"atb":[[5,12.06]],"id":56913144},{"atb":[[6,7.05]],"id":39100893},{"atl":[[9.4,2.88]],"id":39100893},{"atb":[[4.4,0]],"id":52951653}],"con":true,"img":false}]}
{"op":"mcm","clk":"11540789534","pt":1719498401171,"mc":[{"id":"1.230178312","rc":[{"atb":[[4.9,10.3]],"id":56913144},{"atl":[[5.9,1]],"id":56913144},{"atb":[[1.03,0]],"id":68462283},{"atb":[[1.03,0],[6.2,5.6]],"id":70681331},{"atl":[[12.5,2.05]],"id":70681331},{"atb":[[1.03,0]],"id":39100893}],"con":true,"img":false}]}
{"op":"mcm","clk":"11540789542","pt":1719498401270,"mc":[{"id":"1.230178312","rc":[{"atb":[[6.2,4.67]],"id":68462283},{"atb":[[6,7.62]],"id":70681331},{"atb":[[5.7,7.71]],"id":39100893}],"con":true,"img":false}]}
{"op":"mcm","clk":"11540789552","pt":1719498401372,"mc":[{"id":"1.230178312","rc":[{"atb":[[4.9,9.78],[5.1,1.84],[5,5.07]],"id":56913144},{"atb":[[6.2,3.82]],"id":68462283},{"atl":[[11.5,2.28],[14,0.6]],"id":70681331},{"atb":[[5.7,1.84]],"id":39100893},{"atl":[[9,0]],"id":51441055}],"con":true,"img":false}]}
{"op":"mcm","clk":"11540789562","pt":1719498401474,"mc":[{"id":"1.230178312","rc":[{"atl":[[5.9,0]],"id":56913144},{"atl":[[11.5,4.8]],"id":70681331},{"atb":[[6.2,8.57]],"id":39100893},{"atl":[[8.8,0]],"id":39100893},{"atb":[[4.8,3.22]],"id":51441055},{"atl":[[7.8,5.58]],"id":51441055}],"con":true,"img":false}]}
{"op":"mcm","clk":"11540789575","pt":1719498401578,"mc":[{"id":"1.230178312","rc":[{"atb":[[4.7,5.47]],"id":56913144},{"atl":[[6,1]],"id":56913144},{"atl":[[9.2,1]],"id":39100893}],"con":true,"img":false}]}
{"op":"mcm","clk":"11540789588","pt":1719498401682,"mc":[{"id":"1.230178312","rc":[{"atb":[[5,0]],"id":56913144},{"atl":[[12,7.2]],"id":70681331},{"atb":[[6,5.36]],"id":39100893}],"con":true,"img":false}]}
{"op":"mcm","clk":"11540789600","pt":1719498401787,"mc":[{"id":"1.230178312","rc":[{"atb":[[6.4,1.69]],"id":39100893},{"atb":[[3.8,8.22]],"id":52951653}],"con":true,"img":false}]}
{"op":"mcm","clk":"11540789639","pt":1719498402200,"mc":[{"id":"1.230178312","rc":[{"atb":[[4.9,8.94]],"id":56913144},{"atb":[[6,4.52]],"id":39100893},{"atb":[[4.3,6.06]],"id":52951653}],"con":true,"img":false}]}
{"op":"mcm","clk":"11540789666","pt":1719498402477,"mc":[{"id":"1.230178312","rc":[{"atb":[[5.8,0],[6.2,4.48]],"id":39100893}],"con":true,"img":false}]}
{"op":"mcm","clk":"11540789687","pt":1719498402675,"mc":[{"id":"1.230178312","rc":[{"atb":[[5.2,4.88]],"id":56913144},{"atb":[[4.7,0]],"id":68462283},{"atl":[[11.5,9.61]],"id":70681331},{"atl":[[6.8,0],[6.6,9.94]],"id":52951653},{"atl":[[7.6,3.34],[9.8,0.88]],"id":51441055}],"con":true,"img":false}]}
{"op":"mcm","clk":"11540789697","pt":1719498402775,"mc":[{"id":"1.230178312","rc":[{"atb":[[4.2,10.4]],"id":68462283},{"atl":[[12,2.54]],"id":70681331},{"atl":[[6.4,0]],"id":52951653}],"con":true,"img":false}]}
