{"op":"mcm","clk":"11536380675","pt":1719425245619,"mc":[{"id":"1.230178327","marketDefinition":{"bspMarket":true,"turnInPlayEnabled":false,"persistenceEnabled":false,"marketBaseRate":5.0,"eventId":"33376062","eventTypeId":"4339","numberOfWinners":2,"bettingType":"ODDS","marketType":"PLACE","marketTime":"2024-06-27T16:43:00.000Z","suspendTime":"2024-06-27T16:43:00.000Z","bspReconciled":false,"complete":true,"inPlay":false,"crossMatching":false,"runnersVoidable":false,"numberOfActiveRunners":6,"betDelay":0,"status":"OPEN","runners":[{"status":"ACTIVE","sortPriority":1,"id":58221357,"name":"1. Ballymac Wynett"},{"status":"ACTIVE","sortPriority":2,"id":62600242,"name":"2. Swanley Petunia"},{"status":"ACTIVE","sortPriority":3,"id":60748118,"name":"3. Ballymac Dom"},{"status":"ACTIVE","sortPriority":4,"id":67674431,"name":"4. Fairyhill Daisy"},{"status":"ACTIVE","sortPriority":5,"id":68687941,"name":"5. Killieford Negri"},{"status":"ACTIVE","sortPriority":6,"id":65710029,"name":"6. Da Man Joey"}],"regulators":["MR_INT"],"venue":"Kinsley","countryCode":"GB","discountAllowed":false,"timezone":"Europe/London","openDate":"2024-06-27T13:36:00.000Z","version":5994643811,"name":"To Be Placed","eventName":"Kinsley 27th Jun"},"rc":[],"con":true,"img":false}]}
{"op":"mcm","clk":"11536381052","pt":1719425248547,"mc":[{"id":"1.230178327","marketDefinition":{"bspMarket":true,"turnInPlayEnabled":false,"persistenceEnabled":false,"marketBaseRate":5.0,"eventId":"33376062","eventTypeId":"4339","numberOfWinners":2,"bettingType":"ODDS","marketType":"PLACE","marketTime":"2024-06-27T16:43:00.000Z","suspendTime":"2024-06-27T16:43:00.000Z","bspReconciled":false,"complete":true,"inPlay":false,"crossMatching":false,"runnersVoidable":false,"numberOfActiveRunners":6,"betDelay":0,"status":"OPEN","runners":[{"status":"ACTIVE","sortPriority":1,"id":58221357,"name":"1. Ballymac Wynett"},{"status":"ACTIVE","sortPriority":2,"id":62600242,"name":"2. Swanley Petunia"},{"status":"ACTIVE","sortPriority":3,"id":60748118,"name":"3. Ballymac Dom"},{"status":"ACTIVE","sortPriority":4,"id":67674431,"name":"4. Fairyhill Daisy"},{"status":"ACTIVE","sortPriority":5,"id":68687941,"name":"5. Killieford Negri"},{"status":"ACTIVE","sortPriority":6,"id":65710029,"name":"6. Da Man Joey"}],"regulators":["MR_INT"],"venue":"Kinsley","countryCode":"GB","discountAllowed":true,"timezone":"Europe/London","openDate":"2024-06-27T13:36:00.000Z","version":5994643811,"name":"To Be Placed","eventName":"Kinsley 27th Jun"},"rc":[],"con":true,"img":false}]}
{"op":"mcm","clk":"11536837098","pt":1719431854621,"mc":[{"id":"1.230178327","rc":[{"atb":[[1.02,11.22]],"id":58221357},{"atl":[[1000,0.84]],"id":58221357},{"spn":500.51,"spf":"NaN","id":58221357},{"atb":[[1.03,7.48]],"id":60748118},{"atl":[[990,0.84]],"id":60748118},{"spn":495.51,"spf":"NaN","id":60748118},{"atb":[[1.01,22.45]],"id":62600242},{"atl":[[1000,0.84]],"id":62600242},{"spn":500.5,"spf":"NaN","id":62600242},{"atb":[[1.03,7.48]],"id":68687941},{"atl":[[990,0.84]],"id":68687941},{"spn":495.51,"spf":"NaN","id":68687941},{"atb":[[1.01,22.45]],"id":67674431},{"atl":[[1000,0.84]],"id":67674431},{"spn":500.5,"spf":"NaN","id":67674431},{"atb":[[1.02,11.22]],"id":65710029},{"atl":[[1000,0.84]],"id":65710029},{"spn":500.51,"spf":"NaN","id":65710029}],"con":true,"img":false}]}
{"op":"mcm","clk":"11537083850","pt":1719435432690,"mc":[{"id":"1.230178327","rc":[{"atl":[[1000,0.32]],"id":58221357},{"atl":[[990,0.32]],"id":60748118},{"atl":[[1000,0.32]],"id":62600242},{"atl":[[990,0.32]],"id":68687941},{"atl":[[1000,0.32]],"id":67674431},{"atl":[[1000,0.32]],"id":65710029}],"con":true,"img":false}]}
{"op":"mcm","clk":"11537232261","pt":1719437882519,"mc":[{"id":"1.230178327","marketDefinition":{"bspMarket":true,"turnInPlayEnabled":false,"persistenceEnabled":false,"marketBaseRate":5.0,"eventId":"33376062","eventTypeId":"4339","numberOfWinners":2,"bettingType":"ODDS","marketType":"PLACE","marketTime":"2024-06-27T16:43:00.000Z","suspendTime":"2024-06-27T16:43:00.000Z","bspReconciled":false,"complete":true,"inPlay":false,"crossMatching":false,"runnersVoidable":false,"numberOfActiveRunners":6,"betDelay":0,"status":"OPEN","runners":[{"status":"ACTIVE","sortPriority":1,"id":58221357,"name":"1. Ballymac Wynett"},{"status":"ACTIVE","sortPriority":2,"id":62600242,"name":"2. Swanley Petunia"},{"status":"ACTIVE","sortPriority":3,"id":60748118,"name":"3. Ballymac Dom"},{"status":"ACTIVE","sortPriority":4,"id":67674431,"name":"4. Fairyhill Daisy"},{"status":"ACTIVE","sortPriority":5,"id":68687941,"name":"5. Killieford Negri"},{"status":"ACTIVE","sortPriority":6,"id":65710029,"name":"6. Da Man Joey"}],"regulators":["MR_INT"],"venue":"Kinsley","countryCode":"GB","discountAllowed":true,"timezone":"Europe/London","openDate":"2024-06-27T13:36:00.000Z","version":5994643811,"name":"To Be Placed","eventName":"Kinsley 27th Jun"},"rc":[{"atb":[[1.02,11.22]],"id":58221357},{"atl":[[1000,0.33]],"id":58221357},{"spn":500.51,"spf":"NaN","id":58221357},{"atb":[[1.01,22.45]],"id":62600242},{"atl":[[1000,0.33]],"id":62600242},{"spn":500.5,"spf":"NaN","id":62600242},{"atb":[[1.03,7.48]],"id":60748118},{"atl":[[990,0.33]],"id":60748118},{"spn":495.51,"spf":"NaN","id":60748118},{"atb":[[1.03,7.48]],"id":68687941},{"atl":[[990,0.33]],"id":68687941},{"spn":495.51,"spf":"NaN","id":68687941},{"atb":[[1.01,22.45]],"id":67674431},{"atl":[[1000,0.33]],"id":67674431},{"spn":500.5,"spf":"NaN","id":67674431},{"atb":[[1.02,11.22]],"id":65710029},{"atl":[[1000,0.33]],"id":65710029},{"spn":500.51,"spf":"NaN","id":65710029}],"con":true,"img":true}]}
{"op":"mcm","clk":"11537302144","pt":1719439030483,"mc":[{"id":"1.230178327","rc":[{"atb":[[1.02,11.22]],"id":58221357},{"atl":[[1000,0.17]],"id":58221357},{"atb":[[1.01,22.45]],"id":62600242},{"atl":[[1000,0.17]],"id":62600242},{"atb":[[1.03,7.48]],"id":60748118},{"atl":[[990,0.17]],"id":60748118},{"atb":[[1.03,7.48]],"id":68687941},{"atl":[[990,0.17]],"id":68687941},{"atb":[[1.01,22.45]],"id":67674431},{"atl":[[1000,0.17]],"id":67674431},{"atb":[[1.02,11.22]],"id":65710029},{"atl":[[1000,0.17]],"id":65710029}],"con":true,"img":false}]}
{"op":"mcm","clk":"11537573388","pt":1719443282537,"mc":[{"id":"1.230178327","marketDefinition":{"bspMarket":true,"turnInPlayEnabled":false,"persistenceEnabled":false,"marketBaseRate":5.0,"eventId":"33376062","eventTypeId":"4339","numberOfWinners":2,"bettingType":"ODDS","marketType":"PLACE","marketTime":"2024-06-27T16:43:00.000Z","suspendTime":"2024-06-27T16:43:00.000Z","bspReconciled":false,"complete":true,"inPlay":false,"crossMatching":false,"runnersVoidable":false,"numberOfActiveRunners":6,"betDelay":0,"status":"OPEN","runners":[{"status":"ACTIVE","sortPriority":1,"id":58221357,"name":"1. Ballymac Wynett"},{"status":"ACTIVE","sortPriority":2,"id":62600242,"name":"2. Swanley Petunia"},{"status":"ACTIVE","sortPriority":3,"id":60748118,"name":"3. Ballymac Dom"},{"status":"ACTIVE","sortPriority":4,"id":67674431,"name":"4. Fairyhill Daisy"},{"status":"ACTIVE","sortPriority":5,"id":68687941,"name":"5. Killieford Negri"},{"status":"ACTIVE","sortPriority":6,"id":65710029,"name":"6. Da Man Joey"}],"regulators":["MR_INT"],"venue":"Kinsley","countryCode":"GB","discountAllowed":true,"timezone":"Europe/London","openDate":"2024-06-27T13:36:00.000Z","version":5994643811,"name":"To Be Placed","eventName":"Kinsley 27th Jun"},"rc":[{"atb":[[1.02,11.22]],"id":58221357},{"atl":[[1000,0.17]],"id":58221357},{"spn":500.51,"spf":"NaN","id":58221357},{"atb":[[1.03,7.48]],"id":60748118},{"atl":[[990,0.17]],"id":60748118},{"spn":495.51,"spf":"NaN","id":60748118},{"atb":[[1.01,22.45]],"id":62600242},{"atl":[[1000,0.17]],"id":62600242},{"spn":500.5,"spf":"NaN","id":62600242},{"atb":[[1.03,7.48]],"id":68687941},{"atl":[[990,0.17]],"id":68687941},{"spn":495.51,"spf":"NaN","id":68687941},{"atb":[[1.01,22.45]],"id":67674431},{"atl":[[1000,0.17]],"id":67674431},{"spn":500.5,"spf":"NaN","id":67674431},{"atb":[[1.02,11.22]],"id":65710029},{"atl":[[1000,0.17]],"id":65710029},{"spn":500.51,"spf":"NaN","id":65710029}],"con":true,"img":true}]}
{"op":"mcm","clk":"11537954948","pt":1719448682562,"mc":[{"id":"1.230178327","marketDefinition":{"bspMarket":true,"turnInPlayEnabled":false,"persistenceEnabled":false,"marketBaseRate":5.0,"eventId":"33376062","eventTypeId":"4339","numberOfWinners":2,"bettingType":"ODDS","marketType":"PLACE","marketTime":"2024-06-27T16:43:00.000Z","suspendTime":"2024-06-27T16:43:00.000Z","bspReconciled":false,"complete":true,"inPlay":false,"crossMatching":false,"runnersVoidable":false,"numberOfActiveRunners":6,"betDelay":0,"status":"OPEN","runners":[{"status":"ACTIVE","sortPriority":1,"id":58221357,"name":"1. Ballymac Wynett"},{"status":"ACTIVE","sortPriority":2,"id":62600242,"name":"2. Swanley Petunia"},{"status":"ACTIVE","sortPriority":3,"id":60748118,"name":"3. Ballymac Dom"},{"status":"ACTIVE","sortPriority":4,"id":67674431,"name":"4. Fairyhill Daisy"},{"status":"ACTIVE","sortPriority":5,"id":68687941,"name":"5. Killieford Negri"},{"status":"ACTIVE","sortPriority":6,"id":65710029,"name":"6. Da Man Joey"}],"regulators":["MR_INT"],"venue":"Kinsley","countryCode":"GB","discountAllowed":true,"timezone":"Europe/London","openDate":"2024-06-27T13:36:00.000Z","version":5994643811,"name":"To Be Placed","eventName":"Kinsley 27th Jun"},"rc":[{"atb":[[1.02,11.22]],"id":58221357},{"atl":[[1000,0.17]],"id":58221357},{"spn":500.51,"spf":"NaN","id":58221357},{"atb":[[1.03,7.48]],"id":60748118},{"atl":[[990,0.17]],"id":60748118},{"spn":495.51,"spf":"NaN","id":60748118},{"atb":[[1.01,22.45]],"id":62600242},{"atl":[[1000,0.17]],"id":62600242},{"spn":500.5,"spf":"NaN","id":62600242},{"atb":[[1.03,7.48]],"id":68687941},{"atl":[[990,0.17]],"id":68687941},{"spn":495.51,"spf":"NaN","id":68687941},{"atb":[[1.01,22.45]],"id":67674431},{"atl":[[1000,0.17]],"id":67674431},{"spn":500.5,"spf":"NaN","id":67674431},{"atb":[[1.02,11.22]],"id":65710029},{"atl":[[1000,0.17]],"id":65710029},{"spn":500.51,"spf":"NaN","id":65710029}],"con":true,"img":true}]}
{"op":"mcm","clk":"11538170611","pt":1719454082545,"mc":[{"id":"1.230178327","marketDefinition":{"bspMarket":true,"turnInPlayEnabled":false,"persistenceEnabled":false,"marketBaseRate":5.0,"eventId":"33376062","eventTypeId":"4339","numberOfWinners":2,"bettingType":"ODDS","marketType":"PLACE","marketTime":"2024-06-27T16:43:00.000Z","suspendTime":"2024-06-27T16:43:00.000Z","bspReconciled":false,"complete":true,"inPlay":false,"crossMatching":false,"runnersVoidable":false,"numberOfActiveRunners":6,"betDelay":0,"status":"OPEN","runners":[{"status":"ACTIVE","sortPriority":1,"id":58221357,"name":"1. Ballymac Wynett"},{"status":"ACTIVE","sortPriority":2,"id":62600242,"name":"2. Swanley Petunia"},{"status":"ACTIVE","sortPriority":3,"id":60748118,"name":"3. Ballymac Dom"},{"status":"ACTIVE","sortPriority":4,"id":67674431,"name":"4. Fairyhill Daisy"},{"status":"ACTIVE","sortPriority":5,"id":68687941,"name":"5. Killieford Negri"},{"status":"ACTIVE","sortPriority":6,"id":65710029,"name":"6. Da Man Joey"}],"regulators":["MR_INT"],"venue":"Kinsley","countryCode":"GB","discountAllowed":true,"timezone":"Europe/London","openDate":"2024-06-27T13:36:00.000Z","version":5994643811,"name":"To Be Placed","eventName":"Kinsley 27th Jun"},"rc":[{"atb":[[1.02,11.23]],"id":58221357},{"atl":[[1000,0.17]],"id":58221357},{"spn":500.51,"spf":"NaN","id":58221357},{"atb":[[1.03,7.49]],"id":60748118},{"atl":[[990,0.17]],"id":60748118},{"spn":495.51,"spf":"NaN","id":60748118},{"atb":[[1.01,22.46]],"id":62600242},{"atl":[[1000,0.17]],"id":62600242},{"spn":500.5,"spf":"NaN","id":62600242},{"atb":[[1.03,7.49]],"id":68687941},{"atl":[[990,0.17]],"id":68687941},{"spn":495.51,"spf":"NaN","id":68687941},{"atb":[[1.01,22.46]],"id":67674431},{"atl":[[1000,0.17]],"id":67674431},{"spn":500.5,"spf":"NaN","id":67674431},{"atb":[[1.02,11.23]],"id":65710029},{"atl":[[1000,0.17]],"id":65710029},{"spn":500.51,"spf":"NaN","id":65710029}],"con":true,"img":true}]}
{"op":"mcm","clk":"11538368269","pt":1719459482594,"mc":[{"id":"1.230178327","marketDefinition":{"bspMarket":true,"turnInPlayEnabled":false,"persistenceEnabled":false,"marketBaseRate":5.0,"eventId":"33376062","eventTypeId":"4339","numberOfWinners":2,"bettingType":"ODDS","marketType":"PLACE","marketTime":"2024-06-27T16:43:00.000Z","suspendTime":"2024-06-27T16:43:00.000Z","bspReconciled":false,"complete":true,"inPlay":false,"crossMatching":false,"runnersVoidable":false,"numberOfActiveRunners":6,"betDelay":0,"status":"OPEN","runners":[{"status":"ACTIVE","sortPriority":1,"id":58221357,"name":"1. Ballymac Wynett"},{"status":"ACTIVE","sortPriority":2,"id":62600242,"name":"2. Swanley Petunia"},{"status":"ACTIVE","sortPriority":3,"id":60748118,"name":"3. Ballymac Dom"},{"status":"ACTIVE","sortPriority":4,"id":67674431,"name":"4. Fairyhill Daisy"},{"status":"ACTIVE","sortPriority":5,"id":68687941,"name":"5. Killieford Negri"},{"status":"ACTIVE","sortPriority":6,"id":65710029,"name":"6. Da Man Joey"}],"regulators":["MR_INT"],"venue":"Kinsley","countryCode":"GB","discountAllowed":true,"timezone":"Europe/London","openDate":"2024-06-27T13:36:00.000Z","version":5994643811,"name":"To Be Placed","eventName":"Kinsley 27th Jun"},"rc":[{"atb":[[1.02,11.23]],"id":58221357},{"atl":[[1000,0.17]],"id":58221357},{"spn":500.51,"spf":"NaN","id":58221357},{"atb":[[1.03,7.49]],"id":60748118},{"atl":[[990,0.17]],"id":60748118},{"spn":495.51,"spf":"NaN","id":60748118},{"atb":[[1.01,22.46]],"id":62600242},{"atl":[[1000,0.17]],"id":62600242},{"spn":500.5,"spf":"NaN","id":62600242},{"atb":[[1.03,7.49]],"id":68687941},{"atl":[[990,0.17]],"id":68687941},{"spn":495.51,"spf":"NaN","id":68687941},{"atb":[[1.01,22.46]],"id":67674431},{"atl":[[1000,0.17]],"id":67674431},{"spn":500.5,"spf":"NaN","id":67674431},{"atb":[[1.02,11.23]],"id":65710029},{"atl":[[1000,0.17]],"id":65710029},{"spn":500.51,"spf":"NaN","id":65710029}],"con":true,"img":true}]}
{"op":"mcm","clk":"11538595395","pt":1719464882543,"mc":[{"id":"1.230178327","marketDefinition":{"bspMarket":true,"turnInPlayEnabled":false,"persistenceEnabled":false,"marketBaseRate":5.0,"eventId":"33376062","eventTypeId":"4339","numberOfWinners":2,"bettingType":"ODDS","marketType":"PLACE","marketTime":"2024-06-27T16:43:00.000Z","suspendTime":"2024-06-27T16:43:00.000Z","bspReconciled":false,"complete":true,"inPlay":false,"crossMatching":false,"runnersVoidable":false,"numberOfActiveRunners":6,"betDelay":0,"status":"OPEN","runners":[{"status":"ACTIVE","sortPriority":1,"id":58221357,"name":"1. Ballymac Wynett"},{"status":"ACTIVE","sortPriority":2,"id":62600242,"name":"2. Swanley Petunia"},{"status":"ACTIVE","sortPriority":3,"id":60748118,"name":"3. Ballymac Dom"},{"status":"ACTIVE","sortPriority":4,"id":67674431,"name":"4. Fairyhill Daisy"},{"status":"ACTIVE","sortPriority":5,"id":68687941,"name":"5. Killieford Negri"},{"status":"ACTIVE","sortPriority":6,"id":65710029,"name":"6. Da Man Joey"}],"regulators":["MR_INT"],"venue":"Kinsley","countryCode":"GB","discountAllowed":true,"timezone":"Europe/London","openDate":"2024-06-27T13:36:00.000Z","version":5994643811,"name":"To Be Placed","eventName":"Kinsley 27th Jun"},"rc":[{"atb":[[1.02,11.23]],"id":58221357},{"atl":[[1000,0.17]],"id":58221357},{"spn":500.51,"spf":"NaN","id":58221357},{"atb":[[1.03,7.48]],"id":60748118},{"atl":[[990,0.17]],"id":60748118},{"spn":495.51,"spf":"NaN","id":60748118},{"atb":[[1.01,22.46]],"id":62600242},{"atl":[[1000,0.17]],"id":62600242},{"spn":500.5,"spf":"NaN","id":62600242},{"atb":[[1.03,7.48]],"id":68687941},{"atl":[[990,0.17]],"id":68687941},{"spn":495.51,"spf":"NaN","id":68687941},{"atb":[[1.01,22.46]],"id":67674431},{"atl":[[1000,0.17]],"id":67674431},{"spn":500.5,"spf":"NaN","id":67674431},{"atb":[[1.02,11.23]],"id":65710029},{"atl":[[1000,0.17]],"id":65710029},{"spn":500.51,"spf":"NaN","id":65710029}],"con":true,"img":true}]}
{"op":"mcm","clk":"11538907311","pt":1719471508267,"mc":[{"id":"1.230178327","rc":[{"atb":[[1.02,11.23]],"id":58221357},{"atl":[[1000,1.17]],"id":58221357},{"atb":[[1.03,7.48]],"id":60748118},{"atl":[[1000,1]],"id":60748118},{"atb":[[1.01,22.46]],"id":62600242},{"atl":[[1000,1.17]],"id":62600242},{"atb":[[1.03,7.48]],"id":68687941},{"atl":[[1000,1]],"id":68687941},{"atb":[[1.01,22.46]],"id":67674431},{"atl":[[1000,1.17]],"id":67674431},{"atb":[[1.02,11.23]],"id":65710029},{"atl":[[1000,1.17]],"id":65710029}],"con":true,"img":false}]}
{"op":"mcm","clk":"11538907317","pt":1719471508370,"mc":[{"id":"1.230178327","rc":[{"atb":[[1.07,2.48]],"id":58221357},{"atb":[[1.07,2.48]],"id":60748118},{"atb":[[1.07,2.48]],"id":62600242},{"atb":[[1.07,2.48]],"id":68687941},{"atb":[[1.07,2.48]],"id":67674431},{"atb":[[1.07,2.48]],"id":65710029}],"con":true,"img":false}]}
{"op":"mcm","clk":"11538907323","pt":1719471508471,"mc":[{"id":"1.230178327","rc":[{"atl":[[1000,0.65]],"id":58221357},{"atl":[[1000,0.65]],"id":62600242},{"atl":[[1000,0.48]],"id":60748118},{"atl":[[1000,0.48]],"id":68687941},{"atl":[[1000,0.65]],"id":67674431},{"atl":[[1000,0.65]],"id":65710029}],"con":true,"img":false}]}
{"op":"mcm","clk":"11538907330","pt":1719471508675,"mc":[{"id":"1.230178327","rc":[{"atl":[[1000,0.17]],"id":58221357},{"atl":[[1000,0]],"id":60748118},{"atl":[[1000,0.17]],"id":62600242},{"atl":[[1000,0]],"id":68687941},{"atl":[[1000,0.17]],"id":67674431},{"atl":[[1000,0.17]],"id":65710029}],"con":true,"img":false}]}
{"op":"mcm","clk":"11538907336","pt":1719471508775,"mc":[{"id":"1.230178327","rc":[{"atl":[[75,0.48]],"id":58221357},{"atl":[[75,0.48]],"id":60748118},{"atl":[[75,0.48]],"id":62600242},{"atl":[[75,0.48]],"id":68687941},{"atl":[[75,0.48]],"id":67674431},{"atl":[[75,0.48]],"id":65710029}],"con":true,"img":false}]}
{"op":"mcm","clk":"11539122542","pt":1719475682550,"mc":[{"id":"1.230178327","marketDefinition":{"bspMarket":true,"turnInPlayEnabled":false,"persistenceEnabled":false,"marketBaseRate":5.0,"eventId":"33376062","eventTypeId":"4339","numberOfWinners":2,"bettingType":"ODDS","marketType":"PLACE","marketTime":"2024-06-27T16:43:00.000Z","suspendTime":"2024-06-27T16:43:00.000Z","bspReconciled":false,"complete":true,"inPlay":false,"crossMatching":false,"runnersVoidable":false,"numberOfActiveRunners":6,"betDelay":0,"status":"OPEN","runners":[{"status":"ACTIVE","sortPriority":1,"id":58221357,"name":"1. Ballymac Wynett"},{"status":"ACTIVE","sortPriority":2,"id":62600242,"name":"2. Swanley Petunia"},{"status":"ACTIVE","sortPriority":3,"id":60748118,"name":"3. Ballymac Dom"},{"status":"ACTIVE","sortPriority":4,"id":67674431,"name":"4. Fairyhill Daisy"},{"status":"ACTIVE","sortPriority":5,"id":68687941,"name":"5. Killieford Negri"},{"status":"ACTIVE","sortPriority":6,"id":65710029,"name":"6. Da Man Joey"}],"regulators":["MR_INT"],"venue":"Kinsley","countryCode":"GB","discountAllowed":true,"timezone":"Europe/London","openDate":"2024-06-27T13:36:00.000Z","version":5994643811,"name":"To Be Placed","eventName":"Kinsley 27th Jun"},"rc":[{"atb":[[1.02,11.22],[1.07,2.48]],"id":58221357},{"atl":[[75,0.48],[1000,0.17]],"id":58221357},{"spn":38.03,"spf":"NaN","id":58221357},{"atb":[[1.03,7.48],[1.07,2.48]],"id":60748118},{"atl":[[75,0.48],[990,0.17]],"id":60748118},{"spn":38.03,"spf":"NaN","id":60748118},{"atb":[[1.01,22.45],[1.07,2.48]],"id":62600242},{"atl":[[75,0.48],[1000,0.17]],"id":62600242},{"spn":38.03,"spf":"NaN","id":62600242},{"atb":[[1.03,7.48],[1.07,2.48]],"id":68687941},{"atl":[[75,0.48],[990,0.17]],"id":68687941},{"spn":38.03,"spf":"NaN","id":68687941},{"atb":[[1.01,22.45],[1.07,2.48]],"id":67674431},{"atl":[[75,0.48],[1000,0.17]],"id":67674431},{"spn":38.03,"spf":"NaN","id":67674431},{"atb":[[1.02,11.22],[1.07,2.48]],"id":65710029},{"atl":[[75,0.48],[1000,0.17]],"id":65710029},{"spn":38.03,"spf":"NaN","id":65710029}],"con":true,"img":true}]}
{"op":"mcm","clk":"11539356902","pt":1719479553361,"mc":[{"id":"1.230178327","rc":[{"atb":[[1.02,11.22]],"id":58221357},{"spn":38.03,"spf":"NaN","id":58221357},{"atb":[[1.03,7.48]],"id":60748118},{"spn":38.03,"spf":"NaN","id":60748118},{"atb":[[1.01,22.45]],"id":62600242},{"spn":38.03,"spf":"NaN","id":62600242},{"spl":[[1.71,6]],"id":68687941},{"atb":[[1.03,7.48]],"id":68687941},{"spn":1.39,"spf":1.0,"id":68687941},{"atb":[[1.01,22.45]],"id":67674431},{"spn":38.03,"spf":"NaN","id":67674431},{"atb":[[1.02,11.22]],"id":65710029},{"spn":38.03,"spf":"NaN","id":65710029}],"con":true,"img":false}]}
{"op":"mcm","clk":"11540683352","pt":1719497282514,"mc":[{"id":"1.230178327","marketDefinition":{"bspMarket":true,"turnInPlayEnabled":false,"persistenceEnabled":false,"marketBaseRate":5.0,"eventId":"33376062","eventTypeId":"4339","numberOfWinners":2,"bettingType":"ODDS","marketType":"PLACE","marketTime":"2024-06-27T16:43:00.000Z","suspendTime":"2024-06-27T16:43:00.000Z","bspReconciled":false,"complete":true,"inPlay":false,"crossMatching":false,"runnersVoidable":false,"numberOfActiveRunners":6,"betDelay":0,"status":"OPEN","runners":[{"status":"ACTIVE","sortPriority":1,"id":58221357,"name":"1. Ballymac Wynett"},{"status":"ACTIVE","sortPriority":2,"id":62600242,"name":"2. Swanley Petunia"},{"status":"ACTIVE","sortPriority":3,"id":60748118,"name":"3. Ballymac Dom"},{"status":"ACTIVE","sortPriority":4,"id":67674431,"name":"4. Fairyhill Daisy"},{"status":"ACTIVE","sortPriority":5,"id":68687941,"name":"5. Killieford Negri"},{"status":"ACTIVE","sortPriority":6,"id":65710029,"name":"6. Da Man Joey"}],"regulators":["MR_INT"],"venue":"Kinsley","countryCode":"GB","discountAllowed":true,"timezone":"Europe/London","openDate":"2024-06-27T13:36:00.000Z","version":5994643811,"name":"To Be Placed","eventName":"Kinsley 27th Jun"},"rc":[{"atb":[[1.02,11.23],[1.07,2.48]],"id":58221357},{"atl":[[75,0.48],[1000,0.17]],"id":58221357},{"spn":38.03,"spf":"NaN","id":58221357},{"atb":[[1.03,7.49],[1.07,2.48]],"id":60748118},{"atl":[[75,0.48],[990,0.17]],"id":60748118},{"spn":38.03,"spf":"NaN","id":60748118},{"atb":[[1.01,22.46],[1.07,2.48]],"id":62600242},{"atl":[[75,0.48],[1000,0.17]],"id":62600242},{"spn":38.03,"spf":"NaN","id":62600242},{"spl":[[1.71,6]],"id":68687941},{"atb":[[1.03,7.49],[1.07,2.48]],"id":68687941},{"atl":[[75,0.48],[990,0.17]],"id":68687941},{"spn":1.39,"spf":1.0,"id":68687941},{"atb":[[1.01,22.46],[1.07,2.48]],"id":67674431},{"atl":[[75,0.48],[1000,0.17]],"id":67674431},{"spn":38.03,"spf":"NaN","id":67674431},{"atb":[[1.02,11.23],[1.07,2.48]],"id":65710029},{"atl":[[75,0.48],[1000,0.17]],"id":65710029},{"spn":38.03,"spf":"NaN","id":65710029}],"con":true,"img":true}]}
{"op":"mcm","clk":"11541139063","pt":1719502682530,"mc":[{"id":"1.230178327","marketDefinition":{"bspMarket":true,"turnInPlayEnabled":false,"persistenceEnabled":false,"marketBaseRate":5.0,"eventId":"33376062","eventTypeId":"4339","numberOfWinners":2,"bettingType":"ODDS","marketType":"PLACE","marketTime":"2024-06-27T16:43:00.000Z","suspendTime":"2024-06-27T16:43:00.000Z","bspReconciled":false,"complete":true,"inPlay":false,"crossMatching":false,"runnersVoidable":false,"numberOfActiveRunners":6,"betDelay":0,"status":"OPEN","runners":[{"status":"ACTIVE","sortPriority":1,"id":58221357,"name":"1. Ballymac Wynett"},{"status":"ACTIVE","sortPriority":2,"id":62600242,"name":"2. Swanley Petunia"},{"status":"ACTIVE","sortPriority":3,"id":60748118,"name":"3. Ballymac Dom"},{"status":"ACTIVE","sortPriority":4,"id":67674431,"name":"4. Fairyhill Daisy"},{"status":"ACTIVE","sortPriority":5,"id":68687941,"name":"5. Killieford Negri"},{"status":"ACTIVE","sortPriority":6,"id":65710029,"name":"6. Da Man Joey"}],"regulators":["MR_INT"],"venue":"Kinsley","countryCode":"GB","discountAllowed":true,"timezone":"Europe/London","openDate":"2024-06-27T13:36:00.000Z","version":5994643811,"name":"To Be Placed","eventName":"Kinsley 27th Jun"},"rc":[{"atb":[[1.02,11.23],[1.07,2.48]],"id":58221357},{"atl":[[75,0.48],[1000,0.17]],"id":58221357},{"spn":38.03,"spf":"NaN","id":58221357},{"atb":[[1.03,7.49],[1.07,2.48]],"id":60748118},{"atl":[[75,0.48],[990,0.17]],"id":60748118},{"spn":38.03,"spf":"NaN","id":60748118},{"atb":[[1.01,22.47],[1.07,2.48]],"id":62600242},{"atl":[[75,0.48],[1000,0.17]],"id":62600242},{"spn":38.03,"spf":"NaN","id":62600242},{"spl":[[1.71,6]],"id":68687941},{"atb":[[1.03,7.49],[1.07,2.48]],"id":68687941},{"atl":[[75,0.48],[990,0.17]],"id":68687941},{"spn":1.39,"spf":1.0,"id":68687941},{"atb":[[1.01,22.47],[1.07,2.48]],"id":67674431},{"atl":[[75,0.48],[1000,0.17]],"id":67674431},{"spn":38.03,"spf":"NaN","id":67674431},{"atb":[[1.02,11.23],[1.07,2.48]],"id":65710029},{"atl":[[75,0.48],[1000,0.17]],"id":65710029},{"spn":38.03,"spf":"NaN","id":65710029}],"con":true,"img":true}]}
{"op":"mcm","clk":"11541320629","pt":1719504482214,"mc":[{"id":"1.230178327","rc":[{"atb":[[1.02,11.23],[1.04,1]],"id":58221357},{"atb":[[1.03,7.48],[1.04,1]],"id":60748118},{"atb":[[1.01,22.46],[1.04,1]],"id":62600242},{"atb":[[1.03,7.48],[1.04,1]],"id":68687941},{"atb":[[1.01,22.46],[1.04,1]],"id":67674431},{"atb":[[1.02,11.23],[1.04,1]],"id":65710029}],"con":true,"img":false}]}
{"op":"mcm","clk":"11541320646","pt":1719504482683,"mc":[{"id":"1.230178327","rc":[{"atb":[[1.04,0.25]],"id":58221357},{"atb":[[1.04,0.25]],"id":62600242},{"atb":[[1.04,0.25]],"id":60748118},{"atb":[[1.04,0.25]],"id":68687941},{"atb":[[1.04,0.25]],"id":67674431},{"atb":[[1.04,0.25]],"id":65710029}],"con":true,"img":false}]}
{"op":"mcm","clk":"11541320666","pt":1719504482718,"mc":[{"id":"1.230178327","rc":[{"atb":[[1.04,0]],"id":58221357},{"atb":[[1.04,0]],"id":62600242},{"atb":[[1.04,0]],"id":60748118},{"atb":[[1.04,0]],"id":68687941},{"atb":[[1.04,0]],"id":67674431},{"atb":[[1.04,0]],"id":65710029}],"con":true,"img":false}]}
{"op":"mcm","clk":"11541320675","pt":1719504482739,"mc":[{"id":"1.230178327","rc":[{"atb":[[1.2,0.25]],"id":58221357},{"atb":[[1.2,0.25]],"id":60748118},{"atb":[[1.2,0.25]],"id":62600242},{"atb":[[1.2,0.25]],"id":68687941},{"atb":[[1.2,0.25]],"id":67674431},{"atb":[[1.2,0.25]],"id":65710029}],"con":true,"img":false}]}
{"op":"mcm","clk":"11541354608","pt":1719504885727,"mc":[{"id":"1.230178327","rc":[{"spn":38.1,"spf":"NaN","id":58221357},{"spn":38.1,"spf":"NaN","id":62600242},{"atb":[[1.09,43.91]],"id":60748118},{"spn":38.1,"spf":"NaN","id":60748118},{"spn":1.45,"spf":1.0,"id":68687941},{"atb":[[1.09,43.91]],"id":67674431},{"spn":38.1,"spf":"NaN","id":67674431},{"spn":38.1,"spf":"NaN","id":65710029}],"con":true,"img":false}]}
{"op":"mcm","clk":"11541363337","pt":1719504983030,"mc":[{"id":"1.230178327","rc":[{"atb":[[1.02,1]],"id":60748118}],"con":true,"img":false}]}
{"op":"mcm","clk":"11541363356","pt":1719504983237,"mc":[{"id":"1.230178327","rc":[{"atb":[[1.02,0.48]],"id":60748118}],"con":true,"img":false}]}
{"op":"mcm","clk":"11541363374","pt":1719504983447,"mc":[{"id":"1.230178327","rc":[{"atb":[[1.02,0]],"id":60748118}],"con":true,"img":false}]}
{"op":"mcm","clk":"11541363389","pt":1719504983552,"mc":[{"id":"1.230178327","rc":[{"atb":[[1.09,44.39]],"id":60748118}],"con":true,"img":false}]}
{"op":"mcm","clk":"11541363422","pt":1719504983829,"mc":[{"id":"1.230178327","rc":[{"atb":[[1.02,1]],"id":67674431}],"con":true,"img":false}]}
{"op":"mcm","clk":"11541363451","pt":1719504984129,"mc":[{"id":"1.230178327","rc":[{"atb":[[1.02,0.48]],"id":67674431}],"con":true,"img":false}]}
{"op":"mcm","clk":"11541363468","pt":1719504984334,"mc":[{"id":"1.230178327","rc":[{"atb":[[1.02,0]],"id":67674431}],"con":true,"img":false}]}
{"op":"mcm","clk":"11541363479","pt":1719504984439,"mc":[{"id":"1.230178327","rc":[{"atb":[[1.09,44.39]],"id":67674431}],"con":true,"img":false}]}
{"op":"mcm","clk":"11541363678","pt":1719504986254,"mc":[{"id":"1.230178327","rc":[{"atb":[[1.09,43.91]],"id":60748118}],"con":true,"img":false}]}
{"op":"mcm","clk":"11541363689","pt":1719504986322,"mc":[{"id":"1.230178327","rc":[{"atb":[[1.11,0.48]],"id":60748118}],"con":true,"img":false}]}
{"op":"mcm","clk":"11541363884","pt":1719504988444,"mc":[{"id":"1.230178327","rc":[{"atb":[[1.09,43.91]],"id":67674431}],"con":true,"img":false}]}
{"op":"mcm","clk":"11541363895","pt":1719504988548,"mc":[{"id":"1.230178327","rc":[{"atb":[[1.11,0.48]],"id":67674431}],"con":true,"img":false}]}
{"op":"mcm","clk":"11541377142","pt":1719505123883,"mc":[{"id":"1.230178327","rc":[{"atb":[[1.11,38.94]],"id":60748118}],"con":true,"img":false}]}
{"op":"mcm","clk":"11541377155","pt":1719505124086,"mc":[{"id":"1.230178327","rc":[{"atb":[[1.11,38.94]],"id":67674431}],"con":true,"img":false}]}
{"op":"mcm","clk":"11541378593","pt":1719505140310,"mc":[{"id":"1.230178327","rc":[{"atb":[[1.09,0]],"id":60748118}],"con":true,"img":false}]}
{"op":"mcm","clk":"11541378608","pt":1719505140509,"mc":[{"id":"1.230178327","rc":[{"atb":[[1.09,0]],"id":67674431}],"con":true,"img":false}]}
{"op":"mcm","clk":"11541378642","pt":1719505140884,"mc":[{"id":"1.230178327","rc":[{"atb":[[1.13,30.39]],"id":60748118}],"con":true,"img":false}]}
{"op":"mcm","clk":"11541378661","pt":1719505141086,"mc":[{"id":"1.230178327","rc":[{"atb":[[1.13,30.39]],"id":67674431}],"con":true,"img":false}]}
{"op":"mcm","clk":"11541379889","pt":1719505153423,"mc":[{"id":"1.230178327","marketDefinition":{"bspMarket":true,"turnInPlayEnabled":false,"persistenceEnabled":false,"marketBaseRate":5.0,"eventId":"33376062","eventTypeId":"4339","numberOfWinners":2,"bettingType":"ODDS","marketType":"PLACE","marketTime":"2024-06-27T16:43:00.000Z","suspendTime":"2024-06-27T16:43:00.000Z","bspReconciled":false,"complete":true,"inPlay":false,"crossMatching":true,"runnersVoidable":false,"numberOfActiveRunners":6,"betDelay":0,"status":"OPEN","runners":[{"status":"ACTIVE","sortPriority":1,"id":58221357,"name":"1. Ballymac Wynett"},{"status":"ACTIVE","sortPriority":2,"id":62600242,"name":"2. Swanley Petunia"},{"status":"ACTIVE","sortPriority":3,"id":60748118,"name":"3. Ballymac Dom"},{"status":"ACTIVE","sortPriority":4,"id":67674431,"name":"4. Fairyhill Daisy"},{"status":"ACTIVE","sortPriority":5,"id":68687941,"name":"5. Killieford Negri"},{"status":"ACTIVE","sortPriority":6,"id":65710029,"name":"6. Da Man Joey"}],"regulators":["MR_INT"],"venue":"Kinsley","countryCode":"GB","discountAllowed":true,"timezone":"Europe/London","openDate":"2024-06-27T13:36:00.000Z","version":5994643811,"name":"To Be Placed","eventName":"Kinsley 27th Jun"},"rc":[],"con":true,"img":false}]}
{"op":"mcm","clk":"11541380430","pt":1719505158632,"mc":[{"id":"1.230178327","rc":[{"atb":[[1.11,0.48]],"id":60748118}],"con":true,"img":false}]}
{"op":"mcm","clk":"11541380496","pt":1719505159319,"mc":[{"id":"1.230178327","rc":[{"atb":[[1.11,0.48]],"id":67674431}],"con":true,"img":false}]}
{"op":"mcm","clk":"11541380593","pt":1719505160343,"mc":[{"id":"1.230178327","rc":[{"atb":[[1.15,28.2]],"id":60748118}],"con":true,"img":false}]}
{"op":"mcm","clk":"11541380634","pt":1719505160859,"mc":[{"id":"1.230178327","rc":[{"atb":[[1.15,28.2]],"id":67674431}],"con":true,"img":false}]}
{"op":"mcm","clk":"11541382106","pt":1719505174787,"mc":[{"id":"1.230178327","rc":[{"atb":[[1.13,0]],"id":60748118},{"atb":[[1.13,0]],"id":67674431}],"con":true,"img":false}]}
{"op":"mcm","clk":"11541382140","pt":1719505175055,"mc":[{"id":"1.230178327","rc":[{"atb":[[1.17,23.24]],"id":67674431}],"con":true,"img":false}]}
{"op":"mcm","clk":"11541382152","pt":1719505175154,"mc":[{"id":"1.230178327","rc":[{"atb":[[1.17,23.24]],"id":60748118}],"con":true,"img":false}]}
{"op":"mcm","clk":"11541384084","pt":1719505192275,"mc":[{"id":"1.230178327","rc":[{"atb":[[1.15,0]],"id":60748118},{"atb":[[1.15,0]],"id":67674431}],"con":true,"img":false}]}
{"op":"mcm","clk":"11541384203","pt":1719505193360,"mc":[{"id":"1.230178327","rc":[{"atb":[[1.19,22.27]],"id":60748118},{"atb":[[1.19,22.27]],"id":67674431}],"con":true,"img":false}]}
{"op":"mcm","clk":"11541386219","pt":1719505211820,"mc":[{"id":"1.230178327","rc":[{"atb":[[1.17,0]],"id":60748118}],"con":true,"img":false}]}
{"op":"mcm","clk":"11541386241","pt":1719505211987,"mc":[{"id":"1.230178327","rc":[{"atb":[[1.09,43.91]],"id":65710029}],"con":true,"img":false}]}
{"op":"mcm","clk":"11541386253","pt":1719505212099,"mc":[{"id":"1.230178327","rc":[{"atb":[[1.17,0]],"id":67674431}],"con":true,"img":false}]}
{"op":"mcm","clk":"11541386264","pt":1719505212187,"mc":[{"id":"1.230178327","rc":[{"atb":[[1.21,18.81]],"id":60748118}],"con":true,"img":false}]}
{"op":"mcm","clk":"11541386284","pt":1719505212397,"mc":[{"id":"1.230178327","rc":[{"atb":[[1.21,18.81]],"id":67674431}],"con":true,"img":false}]}
{"op":"mcm","clk":"11541387556","pt":1719505225111,"mc":[{"id":"1.230178327","rc":[{"atb":[[1.19,0]],"id":60748118}],"con":true,"img":false}]}
{"op":"mcm","clk":"11541387580","pt":1719505225319,"mc":[{"id":"1.230178327","rc":[{"atb":[[1.19,0]],"id":67674431}],"con":true,"img":false}]}
{"op":"mcm","clk":"11541387690","pt":1719505226309,"mc":[{"id":"1.230178327","rc":[{"atb":[[1.23,18.39]],"id":60748118}],"con":true,"img":false}]}
{"op":"mcm","clk":"11541387801","pt":1719505227444,"mc":[{"id":"1.230178327","rc":[{"atb":[[1.23,18.39]],"id":67674431}],"con":true,"img":false}]}
{"op":"mcm","clk":"11541387982","pt":1719505229307,"mc":[{"id":"1.230178327","rc":[{"atb":[[1.09,0]],"id":65710029}],"con":true,"img":false}]}
{"op":"mcm","clk":"11541388054","pt":1719505230022,"mc":[{"id":"1.230178327","rc":[{"atb":[[1.21,0]],"id":60748118}],"con":true,"img":false}]}
{"op":"mcm","clk":"11541388078","pt":1719505230233,"mc":[{"id":"1.230178327","rc":[{"atb":[[1.21,0]],"id":67674431}],"con":true,"img":false}]}
{"op":"mcm","clk":"11541388144","pt":1719505230749,"mc":[{"id":"1.230178327","rc":[{"atb":[[1.25,15.8]],"id":67674431}],"con":true,"img":false}]}
{"op":"mcm","clk":"11541388194","pt":1719505231217,"mc":[{"id":"1.230178327","rc":[{"atb":[[1.25,15.8]],"id":60748118}],"con":true,"img":false}]}
{"op":"mcm","clk":"11541391398","pt":1719505260668,"mc":[{"id":"1.230178327","rc":[{"atb":[[1.23,0]],"id":60748118},{"spn":38.12,"spf":"NaN","id":60748118},{"atb":[[1.23,0]],"id":67674431},{"spn":38.12,"spf":"NaN","id":67674431}],"con":true,"img":false}]}
{"op":"mcm","clk":"11541391505","pt":1719505261556,"mc":[{"id":"1.230178327","rc":[{"atb":[[1.27,15.67]],"id":60748118}],"con":true,"img":false}]}
{"op":"mcm","clk":"11541391622","pt":1719505262649,"mc":[{"id":"1.230178327","rc":[{"atb":[[1.27,15.67]],"id":67674431}],"con":true,"img":false}]}
{"op":"mcm","clk":"11541391906","pt":1719505265566,"mc":[{"id":"1.230178327","rc":[{"atb":[[1.25,0]],"id":60748118}],"con":true,"img":false}]}
{"op":"mcm","clk":"11541391925","pt":1719505265772,"mc":[{"id":"1.230178327","rc":[{"atb":[[1.25,0]],"id":67674431}],"con":true,"img":false}]}
{"op":"mcm","clk":"11541391981","pt":1719505266263,"mc":[{"id":"1.230178327","rc":[{"atb":[[1.29,13.62]],"id":60748118}],"con":true,"img":false}]}
{"op":"mcm","clk":"11541392001","pt":1719505266467,"mc":[{"id":"1.230178327","rc":[{"atb":[[1.29,13.62]],"id":67674431}],"con":true,"img":false}]}
{"op":"mcm","clk":"11541394545","pt":1719505294595,"mc":[{"id":"1.230178327","rc":[{"atb":[[1.27,0]],"id":60748118}],"con":true,"img":false}]}
{"op":"mcm","clk":"11541394572","pt":1719505294902,"mc":[{"id":"1.230178327","rc":[{"atb":[[1.31,13.65]],"id":60748118},{"atb":[[1.27,0]],"id":67674431}],"con":true,"img":false}]}
{"op":"mcm","clk":"11541394595","pt":1719505295210,"mc":[{"id":"1.230178327","rc":[{"atb":[[1.31,13.65]],"id":67674431}],"con":true,"img":false}]}
{"op":"mcm","clk":"11541395295","pt":1719505304007,"mc":[{"id":"1.230178327","rc":[{"atb":[[1.29,0]],"id":60748118}],"con":true,"img":false}]}
{"op":"mcm","clk":"11541395314","pt":1719505304203,"mc":[{"id":"1.230178327","rc":[{"atb":[[1.29,0]],"id":67674431}],"con":true,"img":false}]}
{"op":"mcm","clk":"11541395348","pt":1719505304609,"mc":[{"id":"1.230178327","rc":[{"atb":[[1.33,11.97]],"id":60748118}],"con":true,"img":false}]}
{"op":"mcm","clk":"11541395398","pt":1719505305225,"mc":[{"id":"1.230178327","rc":[{"atb":[[1.33,11.97]],"id":67674431}],"con":true,"img":false}]}
{"op":"mcm","clk":"11541397659","pt":1719505327428,"mc":[{"id":"1.230178327","rc":[{"atb":[[1.31,0]],"id":60748118},{"spn":38.16,"spf":"NaN","id":60748118},{"atb":[[1.31,0]],"id":67674431},{"spn":38.16,"spf":"NaN","id":67674431}],"con":true,"img":false}]}
{"op":"mcm","clk":"11541397714","pt":1719505327939,"mc":[{"id":"1.230178327","rc":[{"atb":[[1.35,12.09]],"id":67674431}],"con":true,"img":false}]}
{"op":"mcm","clk":"11541397725","pt":1719505328041,"mc":[{"id":"1.230178327","rc":[{"atb":[[1.35,12.09]],"id":60748118}],"con":true,"img":false}]}
{"op":"mcm","clk":"11541399030","pt":1719505341752,"mc":[{"id":"1.230178327","rc":[{"atb":[[1.33,0]],"id":60748118},{"atb":[[1.33,0]],"id":67674431}],"con":true,"img":false}]}
{"op":"mcm","clk":"11541399073","pt":1719505342267,"mc":[{"id":"1.230178327","rc":[{"atb":[[1.37,10.67]],"id":67674431}],"con":true,"img":false}]}
{"op":"mcm","clk":"11541399143","pt":1719505342983,"mc":[{"id":"1.230178327","rc":[{"atb":[[1.37,10.67]],"id":60748118}],"con":true,"img":false}]}
{"op":"mcm","clk":"11541401343","pt":1719505364172,"mc":[{"id":"1.230178327","rc":[{"atb":[[1.35,0]],"id":60748118},{"atb":[[1.35,0]],"id":67674431}],"con":true,"img":false}]}
{"op":"mcm","clk":"11541401443","pt":1719505365196,"mc":[{"id":"1.230178327","rc":[{"atb":[[1.39,10.84]],"id":60748118}],"con":true,"img":false}]}
{"op":"mcm","clk":"11541401486","pt":1719505365612,"mc":[{"id":"1.230178327","rc":[{"atb":[[1.39,10.84]],"id":67674431}],"con":true,"img":false}]}
{"op":"mcm","clk":"11541402719","pt":1719505377819,"mc":[{"id":"1.230178327","rc":[{"atb":[[1.37,0]],"id":60748118}],"con":true,"img":false}]}
{"op":"mcm","clk":"11541402734","pt":1719505377920,"mc":[{"id":"1.230178327","rc":[{"atb":[[1.37,0]],"id":67674431}],"con":true,"img":false}]}
{"op":"mcm","clk":"11541402792","pt":1719505378491,"mc":[{"id":"1.230178327","rc":[{"atb":[[1.41,9.64]],"id":67674431}],"con":true,"img":false}]}
{"op":"mcm","clk":"11541402826","pt":1719505378804,"mc":[{"id":"1.230178327","rc":[{"atb":[[1.41,9.64]],"id":60748118}],"con":true,"img":false}]}
{"op":"mcm","clk":"11541405155","pt":1719505400241,"mc":[{"id":"1.230178327","rc":[{"atb":[[1.39,0]],"id":60748118},{"spn":38.2,"spf":"NaN","id":60748118},{"atb":[[1.39,0]],"id":67674431},{"spn":38.2,"spf":"NaN","id":67674431}],"con":true,"img":false}]}
{"op":"mcm","clk":"11541405282","pt":1719505401551,"mc":[{"id":"1.230178327","rc":[{"atb":[[1.43,9.84]],"id":67674431}],"con":true,"img":false}]}
{"op":"mcm","clk":"11541405293","pt":1719505401644,"mc":[{"id":"1.230178327","rc":[{"atb":[[1.43,9.84]],"id":60748118}],"con":true,"img":false}]}
{"op":"mcm","clk":"11541406649","pt":1719505414574,"mc":[{"id":"1.230178327","rc":[{"atb":[[1.41,0]],"id":60748118}],"con":true,"img":false}]}
{"op":"mcm","clk":"11541406671","pt":1719505414780,"mc":[{"id":"1.230178327","rc":[{"atb":[[1.41,0]],"id":67674431}],"con":true,"img":false}]}
{"op":"mcm","clk":"11541406689","pt":1719505414984,"mc":[{"id":"1.230178327","rc":[{"atb":[[1.45,8.78]],"id":60748118}],"con":true,"img":false}]}
{"op":"mcm","clk":"11541406770","pt":1719505415658,"mc":[{"id":"1.230178327","rc":[{"atb":[[1.45,8.78]],"id":67674431}],"con":true,"img":false}]}
{"op":"mcm","clk":"11541409032","pt":1719505437488,"mc":[{"id":"1.230178327","rc":[{"atb":[[1.43,0]],"id":60748118}],"con":true,"img":false}]}
{"op":"mcm","clk":"11541409112","pt":1719505438209,"mc":[{"id":"1.230178327","rc":[{"atb":[[1.43,0]],"id":67674431}],"con":true,"img":false}]}
{"op":"mcm","clk":"11541409250","pt":1719505439505,"mc":[{"id":"1.230178327","rc":[{"atb":[[1.47,9]],"id":67674431}],"con":true,"img":false}]}
{"op":"mcm","clk":"11541409260","pt":1719505439608,"mc":[{"id":"1.230178327","rc":[{"atb":[[1.47,9]],"id":60748118}],"con":true,"img":false}]}
{"op":"mcm","clk":"11541410321","pt":1719505449713,"mc":[{"id":"1.230178327","rc":[{"atb":[[1.45,0]],"id":67674431}],"con":true,"img":false}]}
{"op":"mcm","clk":"11541410351","pt":1719505450021,"mc":[{"id":"1.230178327","rc":[{"atb":[[1.45,0]],"id":60748118}],"con":true,"img":false}]}
{"op":"mcm","clk":"11541410361","pt":1719505450127,"mc":[{"id":"1.230178327","rc":[{"atb":[[1.49,8.06]],"id":67674431}],"con":true,"img":false}]}
{"op":"mcm","clk":"11541410400","pt":1719505450562,"mc":[{"id":"1.230178327","rc":[{"atb":[[1.49,8.06]],"id":60748118}],"con":true,"img":false}]}
{"op":"mcm","clk":"11541412606","pt":1719505476439,"mc":[{"id":"1.230178327","rc":[{"atb":[[1.47,0]],"id":60748118},{"spn":38.24,"spf":"NaN","id":60748118},{"atb":[[1.47,0]],"id":67674431},{"spn":38.24,"spf":"NaN","id":67674431}],"con":true,"img":false}]}
{"op":"mcm","clk":"11541412635","pt":1719505476745,"mc":[{"id":"1.230178327","rc":[{"atb":[[1.51,8.29]],"id":60748118},{"atb":[[1.51,8.29]],"id":67674431}],"con":true,"img":false}]}
{"op":"mcm","clk":"11541413489","pt":1719505485923,"mc":[{"id":"1.230178327","rc":[{"atb":[[1.49,0]],"id":60748118}],"con":true,"img":false}]}
{"op":"mcm","clk":"11541413502","pt":1719505486131,"mc":[{"id":"1.230178327","rc":[{"atb":[[1.53,7.45]],"id":60748118},{"atb":[[1.49,0]],"id":67674431}],"con":true,"img":false}]}
{"op":"mcm","clk":"11541413519","pt":1719505486336,"mc":[{"id":"1.230178327","rc":[{"atb":[[1.53,7.45]],"id":67674431}],"con":true,"img":false}]}
{"op":"mcm","clk":"11541415484","pt":1719505508962,"mc":[{"id":"1.230178327","rc":[{"atb":[[1.51,0]],"id":60748118},{"atb":[[1.51,0]],"id":67674431}],"con":true,"img":false}]}
{"op":"mcm","clk":"11541415515","pt":1719505509270,"mc":[{"id":"1.230178327","rc":[{"atb":[[1.55,7.69]],"id":60748118},{"atb":[[1.55,7.69]],"id":67674431}],"con":true,"img":false}]}
{"op":"mcm","clk":"11541416719","pt":1719505523671,"mc":[{"id":"1.230178327","rc":[{"atb":[[1.53,0]],"id":60748118},{"atb":[[1.53,0]],"id":67674431}],"con":true,"img":false}]}
{"op":"mcm","clk":"11541416736","pt":1719505523876,"mc":[{"id":"1.230178327","rc":[{"atb":[[1.57,6.93]],"id":60748118},{"atb":[[1.57,6.93]],"id":67674431}],"con":true,"img":false}]}
{"op":"mcm","clk":"11541418216","pt":1719505541294,"mc":[{"id":"1.230178327","rc":[{"atb":[[1.55,0]],"id":60748118},{"spn":38.28,"spf":"NaN","id":60748118},{"spn":38.28,"spf":"NaN","id":67674431}],"con":true,"img":false}]}
{"op":"mcm","clk":"11541418238","pt":1719505541502,"mc":[{"id":"1.230178327","rc":[{"atb":[[1.55,0]],"id":67674431}],"con":true,"img":false}]}
{"op":"mcm","clk":"11541418266","pt":1719505541809,"mc":[{"id":"1.230178327","rc":[{"atb":[[1.59,7.16]],"id":60748118}],"con":true,"img":false}]}
{"op":"mcm","clk":"11541418283","pt":1719505542013,"mc":[{"id":"1.230178327","rc":[{"atb":[[1.59,7.16]],"id":67674431}],"con":true,"img":false}]}
{"op":"mcm","clk":"11541420005","pt":1719505561210,"mc":[{"id":"1.230178327","rc":[{"atb":[[1.57,0]],"id":60748118},{"atb":[[1.57,0]],"id":67674431}],"con":true,"img":false}]}
{"op":"mcm","clk":"11541420022","pt":1719505561416,"mc":[{"id":"1.230178327","rc":[{"atb":[[1.61,6.48]],"id":60748118},{"atb":[[1.61,6.48]],"id":67674431}],"con":true,"img":false}]}
{"op":"mcm","clk":"11541421982","pt":1719505579366,"mc":[{"id":"1.230178327","rc":[{"atb":[[1.59,0]],"id":60748118}],"con":true,"img":false}]}
{"op":"mcm","clk":"11541422005","pt":1719505579673,"mc":[{"id":"1.230178327","rc":[{"atb":[[1.63,6.71]],"id":60748118},{"atb":[[1.59,0]],"id":67674431}],"con":true,"img":false}]}
{"op":"mcm","clk":"11541422030","pt":1719505579982,"mc":[{"id":"1.230178327","rc":[{"atb":[[1.63,6.71]],"id":67674431}],"con":true,"img":false}]}
{"op":"mcm","clk":"11541423651","pt":1719505598588,"mc":[{"id":"1.230178327","rc":[{"atb":[[1.61,0]],"id":60748118},{"atb":[[1.61,0]],"id":67674431}],"con":true,"img":false}]}
{"op":"mcm","clk":"11541423668","pt":1719505598798,"mc":[{"id":"1.230178327","rc":[{"atb":[[1.65,6.07]],"id":60748118},{"atb":[[1.65,6.07]],"id":67674431}],"con":true,"img":false}]}
{"op":"mcm","clk":"11541424773","pt":1719505612124,"mc":[{"id":"1.230178327","rc":[{"spn":38.32,"spf":"NaN","id":60748118},{"atb":[[1.63,0]],"id":67674431},{"spn":38.32,"spf":"NaN","id":67674431}],"con":true,"img":false}]}
{"op":"mcm","clk":"11541424794","pt":1719505612332,"mc":[{"id":"1.230178327","rc":[{"atb":[[1.63,0]],"id":60748118}],"con":true,"img":false}]}
{"op":"mcm","clk":"11541424828","pt":1719505612693,"mc":[{"id":"1.230178327","rc":[{"atb":[[1.67,6.31]],"id":67674431}],"con":true,"img":false}]}
{"op":"mcm","clk":"11541424891","pt":1719505613213,"mc":[{"id":"1.230178327","rc":[{"atb":[[1.67,6.31]],"id":60748118}],"con":true,"img":false}]}
{"op":"mcm","clk":"11541427717","pt":1719505643781,"mc":[{"id":"1.230178327","rc":[{"atl":[[2.28,5.01]],"id":65710029}],"con":true,"img":false}]}
{"op":"mcm","clk":"11541428463","pt":1719505651848,"mc":[{"id":"1.230178327","rc":[{"atl":[[2.28,0]],"id":65710029},{"trd":[[2.28,10.03]],"ltp":2.28,"tv":10.03,"id":65710029}],"con":true,"img":false}]}
{"op":"mcm","clk":"11541428481","pt":1719505652056,"mc":[{"id":"1.230178327","rc":[{"atl":[[1000,0.18]],"id":65710029}],"con":true,"img":false}]}
{"op":"mcm","clk":"11541430074","pt":1719505669483,"mc":[{"id":"1.230178327","rc":[{"atl":[[1000,0.18]],"id":58221357}],"con":true,"img":false}]}
{"op":"mcm","clk":"11541431061","pt":1719505680205,"mc":[{"id":"1.230178327","rc":[{"atb":[[1.78,1],[1.52,2.48]],"id":58221357},{"atl":[[5,1],[14.5,2]],"id":58221357},{"spn":3.39,"spf":"NaN","id":58221357},{"atb":[[1.97,1],[1.68,6.08]],"id":60748118},{"atl":[[5.6,1],[18.5,2]],"id":60748118},{"spn":3.78,"spf":"NaN","id":60748118},{"atb":[[1.78,1],[1.47,2.48]],"id":62600242},{"atl":[[5,1],[13,2],[1000,0.18]],"id":62600242},{"spn":3.39,"spf":"NaN","id":62600242},{"atb":[[1.43,2.48],[1.7,1]],"id":68687941},{"atl":[[12,2],[4.2,1]],"id":68687941},{"spn":1.7,"spf":1.0,"id":68687941},{"atb":[[1.73,6.08],[2.32,1]],"id":67674431},{"atl":[[6.2,1],[29,2]],"id":67674431},{"spn":4.26,"spf":"NaN","id":67674431},{"atb":[[1.41,2.48],[1.78,1]],"id":65710029},{"atl":[[4.5,1],[11.5,2]],"id":65710029},{"spn":3.14,"spf":"NaN","id":65710029}],"con":true,"img":false}]}
{"op":"mcm","clk":"11541431084","pt":1719505680425,"mc":[{"id":"1.230178327","rc":[{"atl":[[1000,0.17]],"id":58221357},{"atl":[[1000,0.17]],"id":62600242}],"con":true,"img":false}]}
{"op":"mcm","clk":"11541431360","pt":1719505683203,"mc":[{"id":"1.230178327","rc":[{"atb":[[1.7,2.11]],"id":60748118},{"atb":[[1.7,2.11]],"id":67674431}],"con":true,"img":false}]}
{"op":"mcm","clk":"11541431704","pt":1719505686405,"mc":[{"id":"1.230178327","rc":[{"atb":[[1.01,1.7]],"id":58221357},{"atl":[[1000,1.87]],"id":58221357},{"atb":[[1.01,1.7]],"id":60748118},{"atl":[[1000,1.7]],"id":60748118},{"atb":[[1.01,24.16]],"id":62600242},{"atl":[[1000,1.87]],"id":62600242}],"con":true,"img":false}]}
{"op":"mcm","clk":"11541431725","pt":1719505686610,"mc":[{"id":"1.230178327","rc":[{"atl":[[1000,0.2]],"id":62600242}],"con":true,"img":false}]}
{"op":"mcm","clk":"11541431735","pt":1719505686715,"mc":[{"id":"1.230178327","rc":[{"atb":[[1.01,0.59]],"id":58221357},{"atl":[[1000,0.2]],"id":58221357},{"atb":[[1.01,23.12]],"id":62600242},{"atb":[[1.01,0.44]],"id":60748118},{"atl":[[1000,0.01]],"id":60748118}],"con":true,"img":false}]}
{"op":"mcm","clk":"11541431752","pt":1719505686922,"mc":[{"id":"1.230178327","rc":[{"atl":[[1000,0.17]],"id":62600242}],"con":true,"img":false}]}
{"op":"mcm","clk":"11541431765","pt":1719505687026,"mc":[{"id":"1.230178327","rc":[{"atb":[[1.01,0]],"id":58221357},{"atl":[[1000,0.17]],"id":58221357},{"atb":[[1.01,22.46]],"id":62600242},{"atl":[[12.5,0.02]],"id":62600242},{"atb":[[1.01,0]],"id":60748118},{"atl":[[1000,0]],"id":60748118}],"con":true,"img":false}]}
{"op":"mcm","clk":"11541431775","pt":1719505687087,"mc":[{"id":"1.230178327","rc":[{"atb":[[1.53,0.59]],"id":58221357},{"atl":[[14,0.02]],"id":58221357},{"atb":[[1.48,0.66]],"id":62600242},{"atb":[[1.71,0.44]],"id":60748118},{"atl":[[18,0.01]],"id":60748118}],"con":true,"img":false}]}
{"op":"mcm","clk":"11541432108","pt":1719505690507,"mc":[{"id":"1.230178327","rc":[{"atb":[[1.62,2],[1.52,0]],"id":58221357},{"atl":[[5,0],[4.9,1]],"id":58221357},{"atl":[[5.6,0],[5.5,1]],"id":60748118},{"atb":[[1.59,2],[1.47,0]],"id":62600242},{"atl":[[5,0],[4.9,1]],"id":62600242},{"atb":[[1.43,0],[1.74,1],[1.54,2.48],[1.7,0]],"id":68687941},{"atb":[[1.73,0],[1.83,6.08]],"id":67674431},{"atl":[[6.2,0],[6,1]],"id":67674431},{"atb":[[1.41,0],[1.83,1],[1.78,0],[1.52,2.48]],"id":65710029}],"con":true,"img":false}]}
{"op":"mcm","clk":"11541432119","pt":1719505690613,"mc":[{"id":"1.230178327","rc":[{"atb":[[1.73,2.12],[1.68,0]],"id":60748118},{"atl":[[4.3,1],[4.2,0]],"id":68687941},{"atl":[[4.5,0],[4.7,1]],"id":65710029}],"con":true,"img":false}]}
{"op":"mcm","clk":"11541432130","pt":1719505690704,"mc":[{"id":"1.230178327","rc":[{"atb":[[1.62,0],[1.65,2]],"id":58221357},{"atb":[[1.64,2],[1.59,0]],"id":62600242},{"atb":[[1.6,2.48],[1.54,0]],"id":68687941},{"atb":[[1.83,0],[1.88,6.08]],"id":67674431},{"atb":[[1.6,2.48],[1.52,0]],"id":65710029}],"con":true,"img":false}]}
{"op":"mcm","clk":"11541432144","pt":1719505690808,"mc":[{"id":"1.230178327","rc":[{"atl":[[11,2],[11.5,0]],"id":65710029}],"con":true,"img":false}]}
{"op":"mcm","clk":"11541432212","pt":1719505691488,"mc":[{"id":"1.230178327","rc":[{"atb":[[1.74,0],[1.7,1]],"id":68687941},{"atb":[[1.83,0],[1.78,1]],"id":65710029}],"con":true,"img":false}]}
{"op":"mcm","clk":"11541432719","pt":1719505696920,"mc":[{"id":"1.230178327","rc":[{"atb":[[1.74,1],[1.7,0]],"id":68687941},{"atb":[[1.83,1]],"id":65710029}],"con":true,"img":false}]}
{"op":"mcm","clk":"11541432729","pt":1719505697024,"mc":[{"id":"1.230178327","rc":[{"atb":[[1.78,0]],"id":65710029}],"con":true,"img":false}]}
{"op":"mcm","clk":"11541432905","pt":1719505698932,"mc":[{"id":"1.230178327","rc":[{"atb":[[1.74,0],[1.7,1]],"id":68687941},{"atb":[[1.83,0],[1.78,1]],"id":65710029}],"con":true,"img":false}]}
{"op":"mcm","clk":"11541433058","pt":1719505700536,"mc":[{"id":"1.230178327","rc":[{"atl":[[4.5,1],[4.9,0]],"id":58221357},{"atl":[[4.5,1]],"id":62600242},{"atl":[[5.1,1],[5.5,0]],"id":60748118},{"atl":[[6.2,1]],"id":67674431}],"con":true,"img":false}]}
{"op":"mcm","clk":"11541433065","pt":1719505700637,"mc":[{"id":"1.230178327","rc":[{"atl":[[13,2],[14.5,0]],"id":58221357},{"atl":[[16.5,2],[18.5,0]],"id":60748118},{"atl":[[4.9,0]],"id":62600242},{"atl":[[6,0]],"id":67674431}],"con":true,"img":false}]}
{"op":"mcm","clk":"11541433393","pt":1719505704327,"mc":[{"id":"1.230178327","rc":[{"atb":[[1.74,1]],"id":68687941},{"atb":[[1.78,0]],"id":65710029}],"con":true,"img":false}]}
{"op":"mcm","clk":"11541433401","pt":1719505704420,"mc":[{"id":"1.230178327","rc":[{"atb":[[1.83,1]],"id":65710029}],"con":true,"img":false}]}
{"op":"mcm","clk":"11541433410","pt":1719505704528,"mc":[{"id":"1.230178327","rc":[{"atb":[[1.7,0]],"id":68687941}],"con":true,"img":false}]}
{"op":"mcm","clk":"11541433595","pt":1719505706335,"mc":[{"id":"1.230178327","rc":[{"atb":[[1.74,0],[1.7,1]],"id":68687941},{"atb":[[1.83,0],[1.78,1]],"id":65710029}],"con":true,"img":false}]}
{"op":"mcm","clk":"11541433709","pt":1719505707437,"mc":[{"id":"1.230178327","rc":[{"atb":[[1.02,13.23]],"id":58221357}],"con":true,"img":false}]}
{"op":"mcm","clk":"11541433734","pt":1719505707642,"mc":[{"id":"1.230178327","rc":[{"atb":[[1.02,2]],"id":62600242}],"con":true,"img":false}]}
{"op":"mcm","clk":"11541433770","pt":1719505708012,"mc":[{"id":"1.230178327","rc":[{"atb":[[1.74,2]],"id":60748118}],"con":true,"img":false}]}
{"op":"mcm","clk":"11541433784","pt":1719505708218,"mc":[{"id":"1.230178327","rc":[{"atb":[[1.89,2]],"id":67674431}],"con":true,"img":false}]}
{"op":"mcm","clk":"11541433812","pt":1719505708530,"mc":[{"id":"1.230178327","rc":[{"atb":[[1.02,2]],"id":68687941}],"con":true,"img":false}]}
{"op":"mcm","clk":"11541433842","pt":1719505708831,"mc":[{"id":"1.230178327","rc":[{"atb":[[1.02,13.23]],"id":65710029}],"con":true,"img":false}]}
{"op":"mcm","clk":"11541434105","pt":1719505711726,"mc":[{"id":"1.230178327","rc":[{"atb":[[1.74,1],[1.7,0]],"id":68687941},{"atb":[[1.83,1]],"id":65710029}],"con":true,"img":false}]}
{"op":"mcm","clk":"11541434117","pt":1719505711825,"mc":[{"id":"1.230178327","rc":[{"atb":[[1.78,0]],"id":65710029}],"con":true,"img":false}]}
{"op":"mcm","clk":"11541434292","pt":1719505713738,"mc":[{"id":"1.230178327","rc":[{"atb":[[1.74,0],[1.7,1]],"id":68687941},{"atb":[[1.78,1]],"id":65710029}],"con":true,"img":false}]}
{"op":"mcm","clk":"11541434305","pt":1719505713839,"mc":[{"id":"1.230178327","rc":[{"atb":[[1.83,0]],"id":65710029}],"con":true,"img":false}]}
{"op":"mcm","clk":"11541435440","pt":1719505726623,"mc":[{"id":"1.230178327","rc":[{"atl":[[6.2,0],[6,1]],"id":67674431}],"con":true,"img":false}]}
{"op":"mcm","clk":"11541435449","pt":1719505726728,"mc":[{"id":"1.230178327","rc":[{"atl":[[26,2],[29,0]],"id":67674431}],"con":true,"img":false}]}
{"op":"mcm","clk":"11541435628","pt":1719505728650,"mc":[{"id":"1.230178327","rc":[{"atb":[[1.53,0]],"id":58221357},{"atl":[[14,0]],"id":58221357},{"atb":[[1.71,0]],"id":60748118},{"atl":[[18,0]],"id":60748118},{"atb":[[1.48,0]],"id":62600242},{"atl":[[12.5,0]],"id":62600242}],"con":true,"img":false}]}
{"op":"mcm","clk":"11541435997","pt":1719505733045,"mc":[{"id":"1.230178327","rc":[{"atl":[[6.2,1],[6,0]],"id":67674431}],"con":true,"img":false}]}
{"op":"mcm","clk":"11541436976","pt":1719505742856,"mc":[{"id":"1.230178327","rc":[{"spn":3.14,"spf":"NaN","id":58221357},{"spn":3.14,"spf":"NaN","id":62600242},{"spn":3.53,"spf":"NaN","id":60748118},{"atl":[[4.3,0],[4.2,1]],"id":68687941},{"atl":[[6.2,0],[6,1]],"id":67674431},{"spn":4.16,"spf":"NaN","id":67674431},{"atl":[[4.5,1],[4.7,0]],"id":65710029}],"con":true,"img":false}]}
{"op":"mcm","clk":"11541437074","pt":1719505743887,"mc":[{"id":"1.230178327","rc":[{"atl":[[4.3,1],[4.2,0]],"id":68687941},{"atl":[[6.2,1],[6,0]],"id":67674431},{"atl":[[4.5,0],[4.7,1]],"id":65710029}],"con":true,"img":false}]}
{"op":"mcm","clk":"11541437083","pt":1719505743942,"mc":[{"id":"1.230178327","rc":[{"atl":[[11,2]],"id":68687941}],"con":true,"img":false}]}
{"op":"mcm","clk":"11541437096","pt":1719505744045,"mc":[{"id":"1.230178327","rc":[{"atl":[[12,0]],"id":68687941}],"con":true,"img":false}]}
{"op":"mcm","clk":"11541437558","pt":1719505748807,"mc":[{"id":"1.230178327","rc":[{"atl":[[4.3,0],[4.2,1]],"id":68687941},{"atl":[[6.2,0],[6,1]],"id":67674431},{"atl":[[4.5,1],[4.7,0]],"id":65710029}],"con":true,"img":false}]}
{"op":"mcm","clk":"11541438438","pt":1719505757987,"mc":[{"id":"1.230178327","rc":[{"atb":[[1.65,0]],"id":60748118},{"atb":[[1.65,0]],"id":67674431}],"con":true,"img":false}]}
{"op":"mcm","clk":"11541440521","pt":1719505781098,"mc":[{"id":"1.230178327","rc":[{"atb":[[1.67,0]],"id":60748118},{"atb":[[1.67,0]],"id":67674431}],"con":true,"img":false}]}
{"op":"mcm","clk":"11541440948","pt":1719505785817,"mc":[{"id":"1.230178327","rc":[{"atb":[[1.64,3.75]],"id":67674431}],"con":true,"img":false}]}
{"op":"mcm","clk":"11541441068","pt":1719505787211,"mc":[{"id":"1.230178327","rc":[{"atb":[[1.64,0]],"id":67674431}],"con":true,"img":false}]}
{"op":"mcm","clk":"11541442710","pt":1719505804314,"mc":[{"id":"1.230178327","rc":[{"atb":[[1.01,1.7]],"id":58221357},{"atl":[[1000,1.87]],"id":58221357},{"atb":[[1.01,1.7]],"id":60748118},{"atl":[[1000,1.7]],"id":60748118},{"atb":[[1.01,24.16]],"id":62600242},{"atl":[[1000,1.87]],"id":62600242}],"con":true,"img":false}]}
{"op":"mcm","clk":"11541442730","pt":1719505804519,"mc":[{"id":"1.230178327","rc":[{"atb":[[1.01,0.46]],"id":58221357},{"atl":[[1000,0.2]],"id":58221357},{"atb":[[1.01,0.4]],"id":60748118},{"atl":[[1000,0.02]],"id":60748118},{"atb":[[1.01,22.93]],"id":62600242},{"atl":[[1000,0.2]],"id":62600242}],"con":true,"img":false}]}
{"op":"mcm","clk":"11541442753","pt":1719505804727,"mc":[{"id":"1.230178327","rc":[{"atb":[[1.01,0]],"id":58221357},{"atl":[[1000,0.17]],"id":58221357},{"atb":[[1.01,0]],"id":60748118},{"atl":[[1000,0]],"id":60748118},{"atb":[[1.01,22.46]],"id":62600242},{"atl":[[1000,0.17]],"id":62600242}],"con":true,"img":false}]}
{"op":"mcm","clk":"11541442766","pt":1719505804835,"mc":[{"id":"1.230178327","rc":[{"atb":[[1.66,0.46]],"id":58221357},{"atl":[[12.5,0.02]],"id":58221357},{"atb":[[1.65,0.47]],"id":62600242},{"atl":[[12.5,0.02]],"id":62600242},{"atb":[[1.75,0.4]],"id":60748118},{"atl":[[16,0.02]],"id":60748118}],"con":true,"img":false}]}
{"op":"mcm","clk":"11541443393","pt":1719505810659,"mc":[{"id":"1.230178327","rc":[{"atb":[[1.6,0],[1.54,3.48]],"id":68687941},{"atb":[[1.6,0],[1.54,3.48]],"id":65710029}],"con":true,"img":false}]}
{"op":"mcm","clk":"11541445987","pt":1719505837676,"mc":[{"id":"1.230178327","rc":[{"atl":[[4.3,1],[4.2,0]],"id":68687941},{"atl":[[6.2,1],[6,0]],"id":67674431},{"atl":[[4.5,0],[4.7,1]],"id":65710029}],"con":true,"img":false}]}
{"op":"mcm","clk":"11541446000","pt":1719505837779,"mc":[{"id":"1.230178327","rc":[{"atl":[[11,0],[12,3]],"id":68687941}],"con":true,"img":false}]}
{"op":"mcm","clk":"11541446587","pt":1719505843372,"mc":[{"id":"1.230178327","rc":[{"atl":[[4.3,0],[4.2,1]],"id":68687941},{"atl":[[6.2,0],[6,1]],"id":67674431},{"atl":[[4.5,1],[4.7,0]],"id":65710029}],"con":true,"img":false}]}
{"op":"mcm","clk":"11541446597","pt":1719505843477,"mc":[{"id":"1.230178327","rc":[{"atl":[[11,2],[12,0]],"id":68687941}],"con":true,"img":false}]}
{"op":"mcm","clk":"11541446654","pt":1719505844001,"mc":[{"id":"1.230178327","rc":[{"atl":[[4.5,0],[4.9,1]],"id":58221357},{"atl":[[5.1,0],[5.5,1]],"id":60748118},{"atl":[[4.5,0],[4.9,1]],"id":62600242}],"con":true,"img":false}]}
{"op":"mcm","clk":"11541447049","pt":1719505847568,"mc":[{"id":"1.230178327","rc":[{"atb":[[1.66,0]],"id":58221357},{"atl":[[12.5,0]],"id":58221357},{"atb":[[1.75,0]],"id":60748118},{"atl":[[16,0]],"id":60748118},{"atb":[[1.65,0]],"id":62600242},{"atl":[[12.5,0]],"id":62600242}],"con":true,"img":false}]}
{"op":"mcm","clk":"11541449782","pt":1719505875001,"mc":[{"id":"1.230178327","rc":[{"spn":3.34,"spf":"NaN","id":58221357},{"spn":3.73,"spf":"NaN","id":60748118},{"spn":3.34,"spf":"NaN","id":62600242},{"atl":[[4.7,1]],"id":65710029}],"con":true,"img":false}]}
{"op":"mcm","clk":"11541449791","pt":1719505875105,"mc":[{"id":"1.230178327","rc":[{"atl":[[4.5,1],[4.9,0]],"id":58221357},{"atl":[[5.1,1],[5.5,0]],"id":60748118},{"atl":[[4.5,1],[4.9,0]],"id":62600242},{"atl":[[4.3,1],[4.2,0]],"id":68687941},{"atl":[[6.2,1],[6,0]],"id":67674431},{"atl":[[4.5,0]],"id":65710029}],"con":true,"img":false}]}
{"op":"mcm","clk":"11541451025","pt":1719505888525,"mc":[{"id":"1.230178327","rc":[{"atb":[[1.74,1],[1.7,0]],"id":68687941},{"atb":[[1.83,1],[1.78,0]],"id":65710029}],"con":true,"img":false}]}
{"op":"mcm","clk":"11541451243","pt":1719505890848,"mc":[{"id":"1.230178327","rc":[{"atb":[[1.7,1]],"id":68687941},{"atb":[[1.83,0],[1.78,1]],"id":65710029}],"con":true,"img":false}]}
{"op":"mcm","clk":"11541451254","pt":1719505890911,"mc":[{"id":"1.230178327","rc":[{"atb":[[1.74,0]],"id":68687941}],"con":true,"img":false}]}
{"op":"mcm","clk":"11541451510","pt":1719505893829,"mc":[{"id":"1.230178327","rc":[{"atb":[[1.74,1],[1.7,0]],"id":68687941},{"atb":[[1.83,1],[1.78,0]],"id":65710029}],"con":true,"img":false}]}
{"op":"mcm","clk":"11541451908","pt":1719505898720,"mc":[{"id":"1.230178327","rc":[{"atb":[[1.74,0],[1.7,1]],"id":68687941},{"atl":[[4.3,0],[4.2,1]],"id":68687941},{"atb":[[1.83,0],[1.78,1]],"id":65710029},{"atl":[[4.5,1],[4.7,0]],"id":65710029}],"con":true,"img":false}]}
{"op":"mcm","clk":"11541452273","pt":1719505903123,"mc":[{"id":"1.230178327","rc":[{"atl":[[4.4,2.02]],"id":58221357},{"atl":[[5.1,0],[5.5,1]],"id":60748118},{"atl":[[4.5,0],[4.9,1],[4.4,3.27]],"id":62600242},{"atl":[[6.2,0],[6,1]],"id":67674431},{"atl":[[4.4,2.15]],"id":65710029}],"con":true,"img":false}]}
{"op":"mcm","clk":"11541452282","pt":1719505903226,"mc":[{"id":"1.230178327","rc":[{"atl":[[4.8,3.02],[4.5,0],[4.9,1],[13,0]],"id":58221357},{"atl":[[13,0],[14,3]],"id":62600242},{"atl":[[16.5,0],[18,3]],"id":60748118},{"atl":[[26,0],[28,3]],"id":67674431},{"atl":[[4.4,4.15]],"id":65710029}],"con":true,"img":false}]}
{"op":"mcm","clk":"11541452289","pt":1719505903329,"mc":[{"id":"1.230178327","rc":[{"atl":[[4.4,0]],"id":62600242},{"atl":[[11,0]],"id":65710029}],"con":true,"img":false}]}
{"op":"mcm","clk":"11541452296","pt":1719505903432,"mc":[{"id":"1.230178327","rc":[{"atl":[[4.4,0]],"id":58221357}],"con":true,"img":false}]}
{"op":"mcm","clk":"11541452332","pt":1719505903849,"mc":[{"id":"1.230178327","rc":[{"atl":[[4.7,0.84]],"id":58221357},{"atl":[[4.3,0.84]],"id":65710029}],"con":true,"img":false}]}
{"op":"mcm","clk":"11541452706","pt":1719505907355,"mc":[{"id":"1.230178327","rc":[{"atb":[[2.24,5],[1.79,1.5],[2.32,2.5],[2.16,10]],"id":58221357},{"atl":[[4.5,1],[6.2,2.5],[4.9,0],[7,5],[7.8,10],[4.7,2.34]],"id":58221357},{"atb":[[1.79,1.5],[2.18,5],[2.26,2.5],[2.1,10]],"id":62600242},{"atl":[[4.8,1.5],[7.2,10],[4.5,1],[6.4,5],[5.8,2.5],[4.9,0]],"id":62600242},{"atb":[[2.4,5],[2.32,10],[1.98,2.25],[2.48,2.5]],"id":60748118},{"atl":[[8,10],[7.2,5],[5.1,1],[6.4,2.5],[5.5,0],[5.4,2.25]],"id":60748118},{"atb":[[1.79,2.5],[1.55,1.5],[1.54,0],[1.75,5],[1.71,10],[1.61,2.48]],"id":68687941},{"atl":[[4.3,1],[4.1,1.5],[5.3,5],[4.9,2.5],[5.7,10],[4.2,0]],"id":68687941},{"atb":[[2.92,2.5],[2.84,5],[2.34,2.25],[2.76,10]],"id":67674431},{"atl":[[9,10],[6.2,1],[8.2,5],[7.4,2.5],[6,0],[5.9,2.25]],"id":67674431},{"atb":[[1.64,5],[1.6,10],[1.54,0],[1.78,2.5],[1.68,2.5],[1.47,4.48]],"id":65710029},{"atl":[[4.3,2.34],[4.5,0],[4.6,2.5],[5,5],[4.7,1],[5.4,10]],"id":65710029}],"con":true,"img":false}]}
{"op":"mcm","clk":"11541452723","pt":1719505907425,"mc":[{"id":"1.230178327","rc":[{"atb":[[1.65,0],[2.1,10]],"id":58221357},{"atb":[[1.73,0],[2.26,10]],"id":60748118},{"atb":[[1.64,0],[2.1,17.5]],"id":62600242},{"atl":[[11,0],[4.2,3]],"id":68687941},{"atb":[[2.58,10],[1.88,0]],"id":67674431}],"con":true,"img":false}]}
{"op":"mcm","clk":"11541452729","pt":1719505907524,"mc":[{"id":"1.230178327","rc":[{"atb":[[1.79,7.5]],"id":68687941},{"atb":[[1.78,5]],"id":65710029}],"con":true,"img":false}]}
{"op":"mcm","clk":"11541452749","pt":1719505907632,"mc":[{"id":"1.230178327","rc":[{"atb":[[1.61,0]],"id":68687941},{"atl":[[5.9,0]],"id":67674431},{"atb":[[1.47,0]],"id":65710029}],"con":true,"img":false}]}
{"op":"mcm","clk":"11541452762","pt":1719505907735,"mc":[{"id":"1.230178327","rc":[{"atb":[[1.79,2.5],[1.71,17.5]],"id":68687941},{"atl":[[6,3.75]],"id":67674431},{"atb":[[1.64,10],[1.78,2.5]],"id":65710029}],"con":true,"img":false}]}
{"op":"mcm","clk":"11541452776","pt":1719505907834,"mc":[{"id":"1.230178327","rc":[{"atl":[[5.8,0.84]],"id":67674431}],"con":true,"img":false}]}
{"op":"mcm","clk":"11541452823","pt":1719505908351,"mc":[{"id":"1.230178327","rc":[{"atl":[[5.8,0]],"id":67674431}],"con":true,"img":false}]}
{"op":"mcm","clk":"11541452858","pt":1719505908732,"mc":[{"id":"1.230178327","rc":[{"atb":[[1.02,11.23]],"id":58221357}],"con":true,"img":false}]}
{"op":"mcm","clk":"11541452868","pt":1719505908824,"mc":[{"id":"1.230178327","rc":[{"atb":[[2.34,2]],"id":58221357}],"con":true,"img":false}]}
{"op":"mcm","clk":"11541452889","pt":1719505909032,"mc":[{"id":"1.230178327","rc":[{"atb":[[2.34,3.94]],"id":58221357},{"atb":[[2.28,1.94]],"id":62600242},{"atb":[[2.5,1.94]],"id":60748118},{"atb":[[2.94,1.94]],"id":67674431}],"con":true,"img":false}]}
{"op":"mcm","clk":"11541452910","pt":1719505909232,"mc":[{"id":"1.230178327","rc":[{"atb":[[1.02,0]],"id":62600242}],"con":true,"img":false}]}
{"op":"mcm","clk":"11541452923","pt":1719505909328,"mc":[{"id":"1.230178327","rc":[{"atb":[[2.28,3.94]],"id":62600242}],"con":true,"img":false}]}
{"op":"mcm","clk":"11541452946","pt":1719505909652,"mc":[{"id":"1.230178327","rc":[{"atb":[[1.74,0]],"id":60748118}],"con":true,"img":false}]}
{"op":"mcm","clk":"11541452954","pt":1719505909743,"mc":[{"id":"1.230178327","rc":[{"atb":[[2.5,3.94]],"id":60748118}],"con":true,"img":false}]}
{"op":"mcm","clk":"11541452989","pt":1719505910257,"mc":[{"id":"1.230178327","rc":[{"atb":[[1.89,0]],"id":67674431}],"con":true,"img":false}]}
{"op":"mcm","clk":"11541452998","pt":1719505910317,"mc":[{"id":"1.230178327","rc":[{"atb":[[2.94,3.94]],"id":67674431}],"con":true,"img":false}]}
{"op":"mcm","clk":"11541453019","pt":1719505910633,"mc":[{"id":"1.230178327","rc":[{"atb":[[1.02,11.23]],"id":65710029}],"con":true,"img":false}]}
{"op":"mcm","clk":"11541453027","pt":1719505910726,"mc":[{"id":"1.230178327","rc":[{"atb":[[1.79,2]],"id":65710029}],"con":true,"img":false}]}
{"op":"mcm","clk":"11541453041","pt":1719505910930,"mc":[{"id":"1.230178327","rc":[{"atb":[[1.64,5],[1.79,4.5]],"id":65710029}],"con":true,"img":false}]}
{"op":"mcm","clk":"11541453048","pt":1719505911031,"mc":[{"id":"1.230178327","rc":[{"atb":[[2.3,2.11]],"id":58221357},{"atb":[[1.7,0],[2.46,2.11]],"id":60748118},{"atb":[[2.24,2.11]],"id":62600242},{"atb":[[1.74,2.11]],"id":68687941},{"atb":[[1.79,2],[1.67,2.11],[1.68,12.5]],"id":65710029}],"con":true,"img":false}]}
{"op":"mcm","clk":"11541453060","pt":1719505911141,"mc":[{"id":"1.230178327","rc":[{"atl":[[18,0],[6.4,7.5]],"id":60748118},{"atl":[[5.8,7.5],[14,0]],"id":62600242},{"atl":[[7.4,7.5],[28,0]],"id":67674431},{"atb":[[1.79,4.5],[1.68,2.5]],"id":65710029}],"con":true,"img":false}]}
{"op":"mcm","clk":"11541453071","pt":1719505911240,"mc":[{"id":"1.230178327","rc":[{"atb":[[1.75,10],[1.71,10]],"id":68687941},{"atb":[[1.79,2],[1.68,7.5]],"id":65710029}],"con":true,"img":false}]}
{"op":"mcm","clk":"11541453138","pt":1719505912137,"mc":[{"id":"1.230178327","rc":[{"atl":[[5,1]],"id":60748118},{"atl":[[4.3,0],[4.2,4]],"id":68687941},{"atl":[[6.2,0],[6.8,1]],"id":67674431},{"atl":[[4.5,1],[4.7,0]],"id":65710029}],"con":true,"img":false}]}
{"op":"mcm","clk":"11541453148","pt":1719505912251,"mc":[{"id":"1.230178327","rc":[{"atl":[[5.1,0],[6.4,2.5],[5.4,7.25]],"id":60748118},{"atl":[[7.2,7.5],[7.4,2.5]],"id":67674431},{"atb":[[1.79,4.5]],"id":65710029}],"con":true,"img":false}]}
{"op":"mcm","clk":"11541453161","pt":1719505912335,"mc":[{"id":"1.230178327","rc":[{"atl":[[5,0],[4.9,1]],"id":60748118},{"atl":[[6,0]],"id":67674431},{"atb":[[1.68,2.5]],"id":65710029}],"con":true,"img":false}]}
{"op":"mcm","clk":"11541453172","pt":1719505912447,"mc":[{"id":"1.230178327","rc":[{"atl":[[6.4,10.75],[5.4,2.25]],"id":60748118},{"atl":[[8,6.25],[7.2,0],[6.6,5.78]],"id":67674431}],"con":true,"img":false}]}
{"op":"mcm","clk":"11541453183","pt":1719505912549,"mc":[{"id":"1.230178327","rc":[{"atl":[[4.9,8]],"id":68687941}],"con":true,"img":false}]}
{"op":"mcm","clk":"11541453195","pt":1719505912653,"mc":[{"id":"1.230178327","rc":[{"atl":[[4.2,1]],"id":68687941}],"con":true,"img":false}]}
{"op":"mcm","clk":"11541453385","pt":1719505914867,"mc":[{"id":"1.230178327","rc":[{"atl":[[6.4,0.84]],"id":67674431}],"con":true,"img":false}]}
{"op":"mcm","clk":"11541453439","pt":1719505915364,"mc":[{"id":"1.230178327","rc":[{"atb":[[2.58,0],[2.68,8.95]],"id":67674431}],"con":true,"img":false}]}
{"op":"mcm","clk":"11541454091","pt":1719505923168,"mc":[{"id":"1.230178327","rc":[{"atb":[[1.78,2.11]],"id":68687941}],"con":true,"img":false}]}
{"op":"mcm","clk":"11541454103","pt":1719505923278,"mc":[{"id":"1.230178327","rc":[{"atb":[[1.74,0]],"id":68687941}],"con":true,"img":false}]}
{"op":"mcm","clk":"11541454111","pt":1719505923373,"mc":[{"id":"1.230178327","rc":[{"atb":[[1.78,7.11],[1.75,5]],"id":68687941}],"con":true,"img":false}]}
{"op":"mcm","clk":"11541454117","pt":1719505923436,"mc":[{"id":"1.230178327","rc":[{"atb":[[1.75,15]],"id":68687941}],"con":true,"img":false}]}
{"op":"mcm","clk":"11541454125","pt":1719505923540,"mc":[{"id":"1.230178327","rc":[{"atb":[[1.78,2.11]],"id":68687941}],"con":true,"img":false}]}
{"op":"mcm","clk":"11541454135","pt":1719505923653,"mc":[{"id":"1.230178327","rc":[{"atb":[[1.78,12.11],[1.75,5]],"id":68687941}],"con":true,"img":false}]}
{"op":"mcm","clk":"11541454146","pt":1719505923745,"mc":[{"id":"1.230178327","rc":[{"atb":[[1.78,2.11],[1.75,15]],"id":68687941}],"con":true,"img":false}]}
{"op":"mcm","clk":"11541454167","pt":1719505923948,"mc":[{"id":"1.230178327","rc":[{"atb":[[2.34,7.58]],"id":58221357},{"atl":[[4.4,3.64]],"id":58221357},{"atb":[[2.5,7.5]],"id":60748118},{"atl":[[4.8,3.56]],"id":60748118},{"atb":[[2.28,7.4]],"id":62600242},{"atl":[[4.4,3.46]],"id":62600242},{"atb":[[1.83,3.46]],"id":68687941},{"atb":[[2.94,8.78]],"id":67674431},{"atl":[[6.4,5.68]],"id":67674431},{"atb":[[1.79,8.25]],"id":65710029}],"con":true,"img":false}]}
{"op":"mcm","clk":"11541454183","pt":1719505924051,"mc":[{"id":"1.230178327","rc":[{"atb":[[1.79,0]],"id":58221357},{"atl":[[4.7,0.84]],"id":58221357},{"atb":[[1.98,0]],"id":60748118},{"atl":[[6.4,2.5],[5.4,5]],"id":60748118},{"atb":[[1.79,0]],"id":62600242},{"atl":[[4.8,5],[5.8,2.5]],"id":62600242},{"atb":[[1.55,0]],"id":68687941},{"atb":[[2.34,0]],"id":67674431},{"atl":[[6.6,0]],"id":67674431},{"atb":[[1.79,5.75],[1.78,1],[1.68,9.5]],"id":65710029}],"con":true,"img":false}]}
{"op":"mcm","clk":"11541454209","pt":1719505924361,"mc":[{"id":"1.230178327","rc":[{"atl":[[4.3,0.84],[4.7,0]],"id":58221357},{"atl":[[4.3,0.84]],"id":62600242},{"atl":[[4.7,0.84]],"id":60748118}],"con":true,"img":false}]}
{"op":"mcm","clk":"11541454222","pt":1719505924468,"mc":[{"id":"1.230178327","rc":[{"atl":[[4.8,0],[4.6,3.02]],"id":58221357}],"con":true,"img":false}]}
{"op":"mcm","clk":"11541454234","pt":1719505924575,"mc":[{"id":"1.230178327","rc":[{"atb":[[1.02,12.93]],"id":58221357},{"atl":[[1000,1.87]],"id":58221357},{"atb":[[1.02,1.7]],"id":60748118},{"atl":[[1000,1.7]],"id":60748118},{"atb":[[1.01,24.16]],"id":62600242},{"atl":[[1000,1.87]],"id":62600242}],"con":true,"img":false}]}
{"op":"mcm","clk":"11541454271","pt":1719505924848,"mc":[{"id":"1.230178327","rc":[{"atb":[[1.02,11.44]],"id":58221357},{"atl":[[1000,0.26]],"id":58221357},{"atb":[[1.01,22.68]],"id":62600242},{"atl":[[1000,0.26]],"id":62600242},{"atb":[[1.02,0.19]],"id":60748118},{"atl":[[1000,0.07]],"id":60748118}],"con":true,"img":false}]}
{"op":"mcm","clk":"11541454298","pt":1719505925039,"mc":[{"id":"1.230178327","rc":[{"atb":[[1.02,11.23],[2.1,0],[2.14,10]],"id":58221357},{"atl":[[1000,0.17]],"id":58221357},{"atb":[[2.3,10],[2.26,0],[1.02,0]],"id":60748118},{"atl":[[1000,0]],"id":60748118},{"atb":[[1.01,22.46],[2.1,10],[2.14,7.5]],"id":62600242},{"atl":[[1000,0.17]],"id":62600242},{"atb":[[2.78,10],[2.68,0]],"id":67674431}],"con":true,"img":false}]}
{"op":"mcm","clk":"11541454309","pt":1719505925142,"mc":[{"id":"1.230178327","rc":[{"atb":[[2.36,0.21]],"id":58221357},{"atl":[[4.3,0.93]],"id":58221357},{"atb":[[2.52,0.19]],"id":60748118},{"atl":[[4.7,0.92]],"id":60748118},{"atb":[[2.3,0.22],[2.14,0],[2.16,7.5]],"id":62600242},{"atl":[[4.3,0.93]],"id":62600242}],"con":true,"img":false}]}
{"op":"mcm","clk":"11541454396","pt":1719505925981,"mc":[{"id":"1.230178327","rc":[{"atb":[[2.36,2.75]],"id":58221357},{"atb":[[2.3,2.76]],"id":62600242},{"atb":[[2.52,2.73]],"id":60748118},{"atb":[[2.96,2.53]],"id":67674431}],"con":true,"img":false}]}
{"op":"mcm","clk":"11541454589","pt":1719505927877,"mc":[{"id":"1.230178327","rc":[{"atb":[[2.34,5.58]],"id":58221357}],"con":true,"img":false}]}
{"op":"mcm","clk":"11541454599","pt":1719505927979,"mc":[{"id":"1.230178327","rc":[{"atb":[[2.38,2]],"id":58221357}],"con":true,"img":false}]}
{"op":"mcm","clk":"11541454625","pt":1719505928243,"mc":[{"id":"1.230178327","rc":[{"atb":[[2.28,5.4]],"id":62600242}],"con":true,"img":false}]}
{"op":"mcm","clk":"11541454633","pt":1719505928344,"mc":[{"id":"1.230178327","rc":[{"atb":[[2.32,2]],"id":62600242}],"con":true,"img":false}]}
{"op":"mcm","clk":"11541454658","pt":1719505928650,"mc":[{"id":"1.230178327","rc":[{"atb":[[2.5,5.5]],"id":60748118}],"con":true,"img":false}]}
{"op":"mcm","clk":"11541454666","pt":1719505928753,"mc":[{"id":"1.230178327","rc":[{"atb":[[2.54,2]],"id":60748118}],"con":true,"img":false}]}
{"op":"mcm","clk":"11541454689","pt":1719505929063,"mc":[{"id":"1.230178327","rc":[{"atb":[[2.94,6.78]],"id":67674431}],"con":true,"img":false}]}
{"op":"mcm","clk":"11541454701","pt":1719505929168,"mc":[{"id":"1.230178327","rc":[{"atb":[[2.98,2]],"id":67674431}],"con":true,"img":false}]}
{"op":"mcm","clk":"11541454746","pt":1719505929677,"mc":[{"id":"1.230178327","rc":[{"atl":[[4.6,0],[4.7,5]],"id":58221357}],"con":true,"img":false}]}
{"op":"mcm","clk":"11541454808","pt":1719505930278,"mc":[{"id":"1.230178327","rc":[{"atb":[[2.36,0.21]],"id":58221357},{"atb":[[2.52,0.19]],"id":60748118},{"atb":[[2.3,0.22]],"id":62600242}],"con":true,"img":false}]}
{"op":"mcm","clk":"11541454909","pt":1719505931381,"mc":[{"id":"1.230178327","rc":[{"atl":[[4.5,0],[4.4,4.64]],"id":58221357},{"atl":[[4.5,0],[4.4,4.46]],"id":62600242},{"atl":[[4.1,2.5],[4.2,0]],"id":68687941},{"atl":[[8,0],[7.4,9.19]],"id":67674431},{"atb":[[1.78,0],[1.7,1]],"id":65710029},{"atl":[[4.5,0],[4.4,5.15]],"id":65710029}],"con":true,"img":false}]}
{"op":"mcm","clk":"11541454915","pt":1719505931485,"mc":[{"id":"1.230178327","rc":[{"atb":[[1.79,9.42],[1.75,5]],"id":68687941},{"atl":[[5.3,15.5]],"id":68687941}],"con":true,"img":false}]}
{"op":"mcm","clk":"11541454927","pt":1719505931543,"mc":[{"id":"1.230178327","rc":[{"atl":[[4.9,2.5]],"id":68687941}],"con":true,"img":false}]}
{"op":"mcm","clk":"11541454943","pt":1719505931747,"mc":[{"id":"1.230178327","rc":[{"atl":[[4.9,5.49],[5.4,0]],"id":60748118},{"atb":[[1.79,11.5],[1.68,2.5]],"id":65710029}],"con":true,"img":false}]}
{"op":"mcm","clk":"11541454950","pt":1719505931848,"mc":[{"id":"1.230178327","rc":[{"atl":[[4,0.84]],"id":68687941}],"con":true,"img":false}]}
{"op":"mcm","clk":"11541454961","pt":1719505931963,"mc":[{"id":"1.230178327","rc":[{"atl":[[4,4.59]],"id":68687941},{"atb":[[2.96,0]],"id":67674431}],"con":true,"img":false}]}
{"op":"mcm","clk":"11541454972","pt":1719505932065,"mc":[{"id":"1.230178327","rc":[{"atl":[[5.3,5],[4.9,12.5]],"id":68687941}],"con":true,"img":false}]}
{"op":"mcm","clk":"11541454981","pt":1719505932160,"mc":[{"id":"1.230178327","rc":[{"atl":[[4.1,1]],"id":68687941}],"con":true,"img":false}]}
{"op":"mcm","clk":"11541455463","pt":1719505936981,"mc":[{"id":"1.230178327","rc":[{"atb":[[2.38,0]],"id":58221357},{"spn":3.33,"spf":"NaN","id":58221357},{"spn":3.62,"spf":"NaN","id":60748118},{"spn":3.31,"spf":"NaN","id":62600242},{"spn":1.81,"spf":1.0,"id":68687941},{"spn":4.69,"spf":"NaN","id":67674431},{"spn":3.04,"spf":"NaN","id":65710029}],"con":true,"img":false}]}
{"op":"mcm","clk":"11541455480","pt":1719505937086,"mc":[{"id":"1.230178327","rc":[{"atb":[[2.36,2.21]],"id":58221357}],"con":true,"img":false}]}
{"op":"mcm","clk":"11541455550","pt":1719505937760,"mc":[{"id":"1.230178327","rc":[{"atb":[[2.32,0]],"id":62600242}],"con":true,"img":false}]}
{"op":"mcm","clk":"11541455560","pt":1719505937860,"mc":[{"id":"1.230178327","rc":[{"atb":[[2.3,2.22]],"id":62600242}],"con":true,"img":false}]}
{"op":"mcm","clk":"11541455625","pt":1719505938480,"mc":[{"id":"1.230178327","rc":[{"atb":[[2.54,0]],"id":60748118}],"con":true,"img":false}]}
{"op":"mcm","clk":"11541455634","pt":1719505938583,"mc":[{"id":"1.230178327","rc":[{"atb":[[2.52,2.19]],"id":60748118}],"con":true,"img":false}]}
{"op":"mcm","clk":"11541455667","pt":1719505938892,"mc":[{"id":"1.230178327","rc":[{"atb":[[2.98,0]],"id":67674431}],"con":true,"img":false}]}
{"op":"mcm","clk":"11541455680","pt":1719505938997,"mc":[{"id":"1.230178327","rc":[{"atb":[[2.96,2]],"id":67674431}],"con":true,"img":false}]}
{"op":"mcm","clk":"11541455705","pt":1719505939168,"mc":[{"id":"1.230178327","rc":[{"atb":[[2.34,3.64]],"id":58221357},{"atb":[[2.5,3.56]],"id":60748118},{"atb":[[2.28,3.46]],"id":62600242}],"con":true,"img":false}]}
{"op":"mcm","clk":"11541455725","pt":1719505939371,"mc":[{"id":"1.230178327","rc":[{"atb":[[2.38,1.94]],"id":58221357},{"atb":[[2.54,1.94]],"id":60748118},{"atb":[[2.32,1.94]],"id":62600242}],"con":true,"img":false}]}
{"op":"mcm","clk":"11541455800","pt":1719505940188,"mc":[{"id":"1.230178327","rc":[{"atb":[[2.38,6.34]],"id":58221357},{"atl":[[4.3,5.33]],"id":58221357},{"atb":[[2.54,6.25]],"id":60748118},{"atl":[[4.7,5.23]],"id":60748118},{"atb":[[2.32,6.21]],"id":62600242},{"atl":[[4.3,5.2]],"id":62600242},{"atb":[[2.96,8.14]],"id":67674431}],"con":true,"img":false}]}
{"op":"mcm","clk":"11541455817","pt":1719505940390,"mc":[{"id":"1.230178327","rc":[{"atb":[[2.34,0]],"id":58221357},{"atl":[[4.4,1]],"id":58221357},{"atb":[[2.28,0]],"id":62600242},{"atl":[[4.4,1]],"id":62600242},{"atb":[[2.5,0]],"id":60748118},{"atl":[[4.8,0]],"id":60748118},{"atb":[[2.94,1.94]],"id":67674431}],"con":true,"img":false}]}
{"op":"mcm","clk":"11541455841","pt":1719505940556,"mc":[{"id":"1.230178327","rc":[{"atl":[[6.4,13.23],[4.9,1]],"id":60748118}],"con":true,"img":false}]}
{"op":"mcm","clk":"11541455973","pt":1719505941988,"mc":[{"id":"1.230178327","rc":[{"atb":[[2.4,2.53]],"id":58221357},{"atb":[[2.56,2.53]],"id":60748118},{"atb":[[2.34,2.53]],"id":62600242},{"atb":[[2.98,2.53]],"id":67674431}],"con":true,"img":false}]}
{"op":"mcm","clk":"11541455999","pt":1719505942295,"mc":[{"id":"1.230178327","rc":[{"atb":[[2.94,0]],"id":67674431}],"con":true,"img":false}]}
{"op":"mcm","clk":"11541456018","pt":1719505942459,"mc":[{"id":"1.230178327","rc":[{"atb":[[2.98,4.48]],"id":67674431}],"con":true,"img":false}]}
{"op":"mcm","clk":"11541456036","pt":1719505942657,"mc":[{"id":"1.230178327","rc":[{"atb":[[2.36,0.21]],"id":58221357}],"con":true,"img":false}]}
{"op":"mcm","clk":"11541456045","pt":1719505942761,"mc":[{"id":"1.230178327","rc":[{"atb":[[2.42,2]],"id":58221357}],"con":true,"img":false}]}
{"op":"mcm","clk":"11541456083","pt":1719505943172,"mc":[{"id":"1.230178327","rc":[{"atb":[[2.3,0.22]],"id":62600242}],"con":true,"img":false}]}
{"op":"mcm","clk":"11541456098","pt":1719505943282,"mc":[{"id":"1.230178327","rc":[{"atb":[[2.36,2]],"id":62600242}],"con":true,"img":false}]}
{"op":"mcm","clk":"11541456123","pt":1719505943482,"mc":[{"id":"1.230178327","rc":[{"atb":[[2.32,8.33],[2.24,0]],"id":62600242},{"atb":[[2.52,0.19]],"id":60748118}],"con":true,"img":false}]}
{"op":"mcm","clk":"11541456132","pt":1719505943586,"mc":[{"id":"1.230178327","rc":[{"atb":[[1.02,2]],"id":60748118}],"con":true,"img":false}]}
{"op":"mcm","clk":"11541456159","pt":1719505943899,"mc":[{"id":"1.230178327","rc":[{"atb":[[2.96,6.14]],"id":67674431}],"con":true,"img":false}]}
{"op":"mcm","clk":"11541456172","pt":1719505944004,"mc":[{"id":"1.230178327","rc":[{"atb":[[3,2]],"id":67674431}],"con":true,"img":false}]}
{"op":"mcm","clk":"11541456270","pt":1719505944988,"mc":[{"id":"1.230178327","rc":[{"atb":[[2.4,0]],"id":58221357},{"atb":[[2.34,0]],"id":62600242}],"con":true,"img":false}]}
{"op":"mcm","clk":"11541456299","pt":1719505945295,"mc":[{"id":"1.230178327","rc":[{"atb":[[2.38,4.4]],"id":58221357},{"atb":[[2.32,6.38]],"id":62600242},{"atb":[[2.54,4.31]],"id":60748118}],"con":true,"img":false}]}
{"op":"mcm","clk":"11541456324","pt":1719505945501,"mc":[{"id":"1.230178327","rc":[{"atb":[[2.42,3.94]],"id":58221357},{"atb":[[2.36,3.94]],"id":62600242},{"atb":[[2.58,1.94]],"id":60748118}],"con":true,"img":false}]}
{"op":"mcm","clk":"11541456391","pt":1719505946284,"mc":[{"id":"1.230178327","rc":[{"atb":[[2.98,1.94]],"id":67674431}],"con":true,"img":false}]}
{"op":"mcm","clk":"11541456554","pt":1719505948191,"mc":[{"id":"1.230178327","rc":[{"atb":[[2.42,1.94]],"id":58221357}],"con":true,"img":false}]}
{"op":"mcm","clk":"11541456563","pt":1719505948294,"mc":[{"id":"1.230178327","rc":[{"atb":[[2.4,2]],"id":58221357}],"con":true,"img":false}]}
{"op":"mcm","clk":"11541456609","pt":1719505948707,"mc":[{"id":"1.230178327","rc":[{"atb":[[2.36,1.94]],"id":62600242}],"con":true,"img":false}]}
{"op":"mcm","clk":"11541456620","pt":1719505948802,"mc":[{"id":"1.230178327","rc":[{"atb":[[2.34,2]],"id":62600242}],"con":true,"img":false}]}
{"op":"mcm","clk":"11541456647","pt":1719505949123,"mc":[{"id":"1.230178327","rc":[{"atb":[[3,0]],"id":67674431}],"con":true,"img":false}]}
{"op":"mcm","clk":"11541456658","pt":1719505949179,"mc":[{"id":"1.230178327","rc":[{"atb":[[2.98,3.94]],"id":67674431}],"con":true,"img":false}]}
{"op":"mcm","clk":"11541456690","pt":1719505949485,"mc":[{"id":"1.230178327","rc":[{"atb":[[2.56,0]],"id":60748118}],"con":true,"img":false}]}
{"op":"mcm","clk":"11541456958","pt":1719505952286,"mc":[{"id":"1.230178327","rc":[{"atb":[[1.02,0]],"id":60748118}],"con":true,"img":false}]}
{"op":"mcm","clk":"11541456971","pt":1719505952389,"mc":[{"id":"1.230178327","rc":[{"atb":[[2.56,2]],"id":60748118}],"con":true,"img":false}]}
{"op":"mcm","clk":"11541457309","pt":1719505956111,"mc":[{"id":"1.230178327","rc":[{"atb":[[2.42,6.74]],"id":58221357},{"atb":[[2.58,6.67]],"id":60748118},{"atb":[[2.36,7.19]],"id":62600242},{"atb":[[2.98,11.17]],"id":67674431}],"con":true,"img":false}]}
{"op":"mcm","clk":"11541457320","pt":1719505956215,"mc":[{"id":"1.230178327","rc":[{"atb":[[2.38,0]],"id":58221357},{"atb":[[2.32,2.11]],"id":62600242},{"atb":[[2.54,0]],"id":60748118},{"atb":[[2.96,0]],"id":67674431}],"con":true,"img":false}]}
{"op":"mcm","clk":"11541457422","pt":1719505957298,"mc":[{"id":"1.230178327","rc":[{"atb":[[2.4,0]],"id":58221357}],"con":true,"img":false}]}
{"op":"mcm","clk":"11541457429","pt":1719505957401,"mc":[{"id":"1.230178327","rc":[{"atb":[[2.44,2]],"id":58221357}],"con":true,"img":false}]}
{"op":"mcm","clk":"11541457458","pt":1719505957775,"mc":[{"id":"1.230178327","rc":[{"atb":[[2.34,0]],"id":62600242}],"con":true,"img":false}]}
{"op":"mcm","clk":"11541457466","pt":1719505957877,"mc":[{"id":"1.230178327","rc":[{"atb":[[2.38,2]],"id":62600242}],"con":true,"img":false}]}
{"op":"mcm","clk":"11541457507","pt":1719505958281,"mc":[{"id":"1.230178327","rc":[{"atb":[[2.56,0]],"id":60748118}],"con":true,"img":false}]}
{"op":"mcm","clk":"11541457517","pt":1719505958383,"mc":[{"id":"1.230178327","rc":[{"atb":[[1.02,2]],"id":60748118}],"con":true,"img":false}]}
{"op":"mcm","clk":"11541457551","pt":1719505958799,"mc":[{"id":"1.230178327","rc":[{"atl":[[4.9,1],[4.4,0]],"id":58221357},{"atl":[[4.8,1],[4.9,0],[5.2,1]],"id":60748118},{"atl":[[4.9,1],[4.4,0]],"id":62600242},{"atl":[[4.1,0],[4.2,1]],"id":68687941},{"atl":[[6.8,0],[7,1]],"id":67674431}],"con":true,"img":false}]}
{"op":"mcm","clk":"11541457561","pt":1719505958901,"mc":[{"id":"1.230178327","rc":[{"atl":[[4.7,6]],"id":58221357},{"atl":[[6.4,2.5],[4.9,6.24]],"id":60748118},{"atl":[[4.1,9.2],[4.9,2.5],[4.2,0]],"id":68687941},{"atl":[[7.4,2.5],[7,12.38]],"id":67674431},{"atl":[[4.4,4.15],[4.2,1]],"id":65710029}],"con":true,"img":false}]}
{"op":"mcm","clk":"11541457571","pt":1719505959004,"mc":[{"id":"1.230178327","rc":[{"atl":[[4.9,11.34],[4.7,1]],"id":58221357},{"atl":[[4.8,0],[5.3,1],[5.2,0]],"id":60748118},{"atl":[[4.1,0],[4.4,1],[4.2,9.2]],"id":68687941},{"atl":[[7.4,18.12],[7,1]],"id":67674431},{"atl":[[4.2,4.64]],"id":65710029}],"con":true,"img":false}]}
{"op":"mcm","clk":"11541457580","pt":1719505959112,"mc":[{"id":"1.230178327","rc":[{"atl":[[4.7,0]],"id":58221357},{"atl":[[5.3,12.48],[5.5,1],[4.9,0],[5.4,1]],"id":60748118},{"atl":[[4.9,16.3],[4.2,1]],"id":68687941},{"atl":[[7,0],[6.6,1]],"id":67674431},{"atl":[[4.3,0.84]],"id":65710029}],"con":true,"img":false}]}
{"op":"mcm","clk":"11541457591","pt":1719505959213,"mc":[{"id":"1.230178327","rc":[{"atl":[[6.2,19.18],[4.9,0]],"id":58221357},{"atl":[[4.9,2.5],[4.4,14.8]],"id":68687941},{"atl":[[7.2,10],[7.4,2.5]],"id":67674431}],"con":true,"img":false}]}
{"op":"mcm","clk":"11541457606","pt":1719505959316,"mc":[{"id":"1.230178327","rc":[{"atl":[[7.2,0],[7.4,12.5]],"id":67674431},{"atl":[[4.1,0.84]],"id":65710029}],"con":true,"img":false}]}
{"op":"mcm","clk":"11541457620","pt":1719505959420,"mc":[{"id":"1.230178327","rc":[{"atl":[[4.6,1]],"id":58221357},{"atl":[[5.3,11.48],[5.5,0],[5.2,1],[5.4,0]],"id":60748118},{"atl":[[4.8,6],[4.9,0]],"id":62600242},{"atl":[[4.3,1],[4.4,13.8],[4.2,0]],"id":68687941},{"atl":[[6.8,1],[6.6,0]],"id":67674431},{"atl":[[4.4,5.15],[4.2,3.64]],"id":65710029}],"con":true,"img":false}]}
{"op":"mcm","clk":"11541457632","pt":1719505959483,"mc":[{"id":"1.230178327","rc":[{"atl":[[7.2,10],[7.4,2.5]],"id":67674431}],"con":true,"img":false}]}
{"op":"mcm","clk":"11541457643","pt":1719505959595,"mc":[{"id":"1.230178327","rc":[{"atl":[[4.8,1],[4.6,0],[4.9,1]],"id":58221357},{"atl":[[4.8,0],[5.8,13.71],[4.9,1]],"id":62600242},{"atl":[[4.3,0],[4.1,1],[4.2,1]],"id":68687941},{"atl":[[6.8,0],[7,1]],"id":67674431}],"con":true,"img":false}]}
{"op":"mcm","clk":"11541457653","pt":1719505959700,"mc":[{"id":"1.230178327","rc":[{"atl":[[4.8,11],[6.2,2.5]],"id":58221357},{"atl":[[4.2,10.2]],"id":68687941}],"con":true,"img":false}]}
{"op":"mcm","clk":"11541457664","pt":1719505959802,"mc":[{"id":"1.230178327","rc":[{"atl":[[4.8,10],[4.9,0],[4.7,1]],"id":58221357},{"atl":[[4.1,0],[4.4,1],[4.2,9.2]],"id":68687941},{"atl":[[4.4,4.15],[4.2,4.64]],"id":65710029}],"con":true,"img":false}]}
{"op":"mcm","clk":"11541457739","pt":1719505960610,"mc":[{"id":"1.230178327","rc":[{"atl":[[4.6,1],[4.7,0]],"id":58221357},{"atl":[[4.8,1],[4.9,0]],"id":62600242},{"atl":[[6.8,1],[7,0]],"id":67674431},{"atl":[[4.4,5.15],[4.2,3.64]],"id":65710029}],"con":true,"img":false}]}
{"op":"mcm","clk":"11541457752","pt":1719505960713,"mc":[{"id":"1.230178327","rc":[{"atl":[[4.4,1]],"id":58221357},{"atl":[[4.4,1]],"id":62600242},{"atl":[[5.2,0],[4.9,1]],"id":60748118},{"atl":[[4.1,1],[4.4,0]],"id":68687941}],"con":true,"img":false}]}
{"op":"mcm","clk":"11541457858","pt":1719505961803,"mc":[{"id":"1.230178327","rc":[{"atb":[[2.36,0]],"id":58221357},{"atl":[[4.3,5.24]],"id":58221357},{"atb":[[2.52,0]],"id":60748118},{"atl":[[4.7,5.15]],"id":60748118},{"atb":[[2.3,0]],"id":62600242},{"atl":[[4.3,5.11]],"id":62600242}],"con":true,"img":false}]}
{"op":"mcm","clk":"11541457897","pt":1719505962318,"mc":[{"id":"1.230178327","rc":[{"atl":[[4.6,0]],"id":58221357},{"atl":[[4.8,0]],"id":62600242},{"atb":[[1.74,1],[1.7,0]],"id":65710029}],"con":true,"img":false}]}
{"op":"mcm","clk":"11541458289","pt":1719505967198,"mc":[{"id":"1.230178327","rc":[{"atl":[[4.5,1],[4.4,0]],"id":58221357},{"atl":[[4.5,1],[4.6,1],[4.4,0]],"id":62600242},{"atl":[[4.8,1],[5,1],[4.9,0]],"id":60748118},{"atl":[[4.2,10.2]],"id":68687941},{"atl":[[6.8,0],[6.6,1]],"id":67674431}],"con":true,"img":false}]}
{"op":"mcm","clk":"11541458302","pt":1719505967305,"mc":[{"id":"1.230178327","rc":[{"atl":[[4.8,0],[4.5,7.25]],"id":58221357},{"atl":[[4.6,11],[5.8,2.5]],"id":62600242},{"atl":[[5,7.16],[5.3,0]],"id":60748118},{"atl":[[4.1,0]],"id":68687941},{"atl":[[7.2,0],[7,6.69]],"id":67674431},{"atl":[[4.3,1.84],[4.4,4.15]],"id":65710029}],"con":true,"img":false}]}
{"op":"mcm","clk":"11541458310","pt":1719505967388,"mc":[{"id":"1.230178327","rc":[{"atl":[[4.9,17.3],[4.2,1]],"id":68687941}],"con":true,"img":false}]}
{"op":"mcm","clk":"11541458351","pt":1719505967903,"mc":[{"id":"1.230178327","rc":[{"atl":[[4.6,10]],"id":62600242},{"atl":[[6.8,1]],"id":67674431}],"con":true,"img":false}]}
{"op":"mcm","clk":"11541458363","pt":1719505968007,"mc":[{"id":"1.230178327","rc":[{"atl":[[4.8,0],[5,6.16]],"id":60748118},{"atl":[[6.6,0]],"id":67674431}],"con":true,"img":false}]}
{"op":"mcm","clk":"11541458434","pt":1719505968697,"mc":[{"id":"1.230178327","rc":[{"atb":[[1.74,1],[1.7,0]],"id":68687941},{"atb":[[1.74,0],[1.78,1]],"id":65710029}],"con":true,"img":false}]}
{"op":"mcm","clk":"11541458618","pt":1719505970700,"mc":[{"id":"1.230178327","rc":[{"atl":[[4.8,1],[4.5,6.25]],"id":58221357},{"atl":[[5.4,1]],"id":60748118},{"atl":[[4.8,1],[4.5,0]],"id":62600242},{"atl":[[4.3,0.84],[4.4,5.15]],"id":65710029}],"con":true,"img":false}]}
{"op":"mcm","clk":"11541458645","pt":1719505971016,"mc":[{"id":"1.230178327","rc":[{"atl":[[6.2,0],[5.5,2.5],[7,0],[7.8,0],[5.9,5]],"id":58221357},{"atl":[[8,0],[5.8,2.5]],"id":60748118},{"atl":[[7.2,0],[5.1,2.5],[6.4,0],[5.8,0],[5.5,5]],"id":62600242},{"atb":[[1.98,10],[2.04,5],[2.12,2.5]],"id":68687941},{"atb":[[1.64,0],[1.6,0],[1.98,5],[2.04,2.5],[1.68,0],[1.94,10]],"id":65710029}],"con":true,"img":false}]}
{"op":"mcm","clk":"11541458656","pt":1719505971114,"mc":[{"id":"1.230178327","rc":[{"atb":[[1.98,13.46],[2.12,9.7],[1.71,0],[1.79,0],[1.75,0]],"id":68687941},{"atb":[[1.79,5.75],[1.94,12.5]],"id":65710029}],"con":true,"img":false}]}
{"op":"mcm","clk":"11541458662","pt":1719505971215,"mc":[{"id":"1.230178327","rc":[{"atb":[[2.04,7.11]],"id":65710029}],"con":true,"img":false}]}
{"op":"mcm","clk":"11541458677","pt":1719505971319,"mc":[{"id":"1.230178327","rc":[{"atb":[[1.83,0]],"id":68687941}],"con":true,"img":false}]}
{"op":"mcm","clk":"11541458685","pt":1719505971420,"mc":[{"id":"1.230178327","rc":[{"atb":[[1.79,2]],"id":65710029}],"con":true,"img":false}]}
{"op":"mcm","clk":"11541458724","pt":1719505971731,"mc":[{"id":"1.230178327","rc":[{"atb":[[2.44,7.81]],"id":58221357},{"atb":[[2.38,7.43]],"id":62600242}],"con":true,"img":false}]}
{"op":"mcm","clk":"11541458749","pt":1719505971917,"mc":[{"id":"1.230178327","rc":[{"atb":[[2.42,1.94]],"id":58221357},{"atb":[[2.36,1.94]],"id":62600242},{"atb":[[2.1,2.11]],"id":68687941},{"atb":[[2.02,2.11]],"id":65710029}],"con":true,"img":false}]}
{"op":"mcm","clk":"11541458758","pt":1719505971994,"mc":[{"id":"1.230178327","rc":[{"atb":[[1.98,10],[2.04,16.82],[1.78,0]],"id":68687941},{"atb":[[1.67,0]],"id":65710029}],"con":true,"img":false}]}
{"op":"mcm","clk":"11541458778","pt":1719505972196,"mc":[{"id":"1.230178327","rc":[{"atb":[[1.79,0]],"id":65710029}],"con":true,"img":false}]}
{"op":"mcm","clk":"11541458786","pt":1719505972299,"mc":[{"id":"1.230178327","rc":[{"atb":[[2.42,0]],"id":58221357},{"atb":[[2.36,0]],"id":62600242},{"atb":[[2.06,2]],"id":65710029}],"con":true,"img":false}]}
{"op":"mcm","clk":"11541458791","pt":1719505972402,"mc":[{"id":"1.230178327","rc":[{"atl":[[4.8,12.5],[4.5,0]],"id":58221357},{"atl":[[4.8,16.12]],"id":62600242},{"atl":[[5,0],[5.4,12.32]],"id":60748118}],"con":true,"img":false}]}
{"op":"mcm","clk":"11541458797","pt":1719505972505,"mc":[{"id":"1.230178327","rc":[{"atb":[[2.46,1.94]],"id":58221357},{"atb":[[2.4,1.94]],"id":62600242},{"atl":[[4.6,0]],"id":62600242},{"atb":[[2.14,1.94]],"id":68687941},{"atb":[[2.06,3.94]],"id":65710029}],"con":true,"img":false}]}
{"op":"mcm","clk":"11541458806","pt":1719505972608,"mc":[{"id":"1.230178327","rc":[{"atl":[[4.8,1],[5.5,20.25]],"id":58221357},{"atl":[[5.8,19.98],[5.4,1]],"id":60748118}],"con":true,"img":false}]}
{"op":"mcm","clk":"11541458811","pt":1719505972710,"mc":[{"id":"1.230178327","rc":[{"atl":[[4.8,1],[5.1,23.74]],"id":62600242}],"con":true,"img":false}]}
{"op":"mcm","clk":"11541458989","pt":1719505974632,"mc":[{"id":"1.230178327","rc":[{"atl":[[4.1,5.16]],"id":65710029}],"con":true,"img":false}]}
{"op":"mcm","clk":"11541459000","pt":1719505974734,"mc":[{"id":"1.230178327","rc":[{"atl":[[4.4,3.15]],"id":65710029}],"con":true,"img":false}]}
{"op":"mcm","clk":"11541459026","pt":1719505974898,"mc":[{"id":"1.230178327","rc":[{"atl":[[4,3.64]],"id":65710029}],"con":true,"img":false}]}
{"op":"mcm","clk":"11541459038","pt":1719505975044,"mc":[{"id":"1.230178327","rc":[{"atl":[[4.3,9.65],[4.2,0]],"id":65710029}],"con":true,"img":false}]}
{"op":"mcm","clk":"11541459051","pt":1719505975139,"mc":[{"id":"1.230178327","rc":[{"atl":[[4,0]],"id":65710029}],"con":true,"img":false}]}
{"op":"mcm","clk":"11541459073","pt":1719505975315,"mc":[{"id":"1.230178327","rc":[{"atb":[[2.46,0]],"id":58221357},{"atb":[[2.4,0]],"id":62600242},{"atb":[[2.14,0]],"id":68687941},{"atl":[[4.3,8.81],[3.95,0.84]],"id":65710029}],"con":true,"img":false}]}
{"op":"mcm","clk":"11541459094","pt":1719505975508,"mc":[{"id":"1.230178327","rc":[{"atb":[[2.46,1.94]],"id":58221357},{"atb":[[2.4,1.94]],"id":62600242},{"atb":[[2.14,1.94]],"id":68687941}],"con":true,"img":false}]}
{"op":"mcm","clk":"11541459141","pt":1719505975921,"mc":[{"id":"1.230178327","rc":[{"atl":[[3.95,0]],"id":65710029}],"con":true,"img":false}]}
{"op":"mcm","clk":"11541459395","pt":1719505978400,"mc":[{"id":"1.230178327","rc":[{"atb":[[2.46,0]],"id":58221357},{"atb":[[2.4,0]],"id":62600242},{"atb":[[2.14,0]],"id":68687941}],"con":true,"img":false}]}
{"op":"mcm","clk":"11541459413","pt":1719505978603,"mc":[{"id":"1.230178327","rc":[{"atb":[[2.46,1.94]],"id":58221357},{"atb":[[2.4,1.94]],"id":62600242},{"atb":[[2.14,1.94]],"id":68687941}],"con":true,"img":false}]}
{"op":"mcm","clk":"11541459694","pt":1719505981510,"mc":[{"id":"1.230178327","rc":[{"atb":[[2.46,0]],"id":58221357},{"atb":[[2.4,0]],"id":62600242},{"atb":[[2.14,0]],"id":68687941}],"con":true,"img":false}]}
{"op":"mcm","clk":"11541459714","pt":1719505981713,"mc":[{"id":"1.230178327","rc":[{"atb":[[2.46,1.94]],"id":58221357},{"atb":[[2.4,1.94]],"id":62600242},{"atb":[[2.14,1.94]],"id":68687941}],"con":true,"img":false}]}
{"op":"mcm","clk":"11541459735","pt":1719505981922,"mc":[{"id":"1.230178327","rc":[{"atl":[[5.6,7.05]],"id":58221357},{"atl":[[5.6,5.55]],"id":62600242},{"atl":[[5.9,6.25]],"id":60748118},{"atl":[[4.3,8.4]],"id":68687941}],"con":true,"img":false}]}
{"op":"mcm","clk":"11541459756","pt":1719505982126,"mc":[{"id":"1.230178327","rc":[{"atl":[[4.9,2.5],[4.2,10.2]],"id":68687941}],"con":true,"img":false}]}
{"op":"mcm","clk":"11541459767","pt":1719505982231,"mc":[{"id":"1.230178327","rc":[{"atl":[[5.6,0]],"id":58221357},{"atl":[[5.6,0]],"id":62600242},{"atl":[[5.9,0]],"id":60748118},{"atl":[[4.3,14.8],[4.2,1]],"id":68687941}],"con":true,"img":false}]}
{"op":"mcm","clk":"11541459821","pt":1719505982750,"mc":[{"id":"1.230178327","rc":[{"atb":[[2.28,2.5],[2.18,0],[2.26,0],[2.1,0]],"id":62600242},{"atb":[[2.02,11.82]],"id":68687941}],"con":true,"img":false}]}
{"op":"mcm","clk":"11541459834","pt":1719505982805,"mc":[{"id":"1.230178327","rc":[{"atb":[[2.24,0],[2.32,0],[2.16,0],[2.34,2.5]],"id":58221357},{"atb":[[2.04,5]],"id":68687941},{"atb":[[1.88,10],[1.94,10]],"id":65710029}],"con":true,"img":false}]}
{"op":"mcm","clk":"11541459853","pt":1719505983015,"mc":[{"id":"1.230178327","rc":[{"atb":[[1.78,0]],"id":65710029},{"atl":[[4.3,9.81]],"id":65710029}],"con":true,"img":false}]}
{"op":"mcm","clk":"11541459865","pt":1719505983117,"mc":[{"id":"1.230178327","rc":[{"atl":[[4.8,0],[4.6,1]],"id":58221357},{"atl":[[5.1,1],[5.4,0]],"id":60748118},{"atl":[[4.3,15.8],[4.2,0]],"id":68687941},{"atl":[[4.4,2.15],[4.2,1]],"id":65710029}],"con":true,"img":false}]}
{"op":"mcm","clk":"11541459873","pt":1719505983219,"mc":[{"id":"1.230178327","rc":[{"atl":[[4.8,6.25]],"id":58221357},{"atl":[[5.8,2.5]],"id":60748118}],"con":true,"img":false}]}
{"op":"mcm","clk":"11541459883","pt":1719505983322,"mc":[{"id":"1.230178327","rc":[{"atl":[[5.5,2.5]],"id":58221357},{"atl":[[5.4,6.16]],"id":60748118}],"con":true,"img":false}]}
{"op":"mcm","clk":"11541459892","pt":1719505983424,"mc":[{"id":"1.230178327","rc":[{"atl":[[5.8,8.66],[5.4,0]],"id":60748118},{"atl":[[4.3,8.81]],"id":65710029}],"con":true,"img":false}]}
{"op":"mcm","clk":"11541459979","pt":1719505984215,"mc":[{"id":"1.230178327","rc":[{"atb":[[2.18,2.11],[2.1,0]],"id":68687941}],"con":true,"img":false}]}
{"op":"mcm","clk":"11541460194","pt":1719505986118,"mc":[{"id":"1.230178327","rc":[{"atl":[[5.1,0],[5.2,1]],"id":60748118},{"atl":[[4.3,9.81],[4.2,0]],"id":65710029}],"con":true,"img":false}]}
{"op":"mcm","clk":"11541460231","pt":1719505986438,"mc":[{"id":"1.230178327","rc":[{"atb":[[2.18,7.43]],"id":68687941}],"con":true,"img":false}]}
{"op":"mcm","clk":"11541460243","pt":1719505986535,"mc":[{"id":"1.230178327","rc":[{"atb":[[2.06,10.78]],"id":65710029}],"con":true,"img":false}]}
{"op":"mcm","clk":"11541460253","pt":1719505986644,"mc":[{"id":"1.230178327","rc":[{"atb":[[2.12,2.5]],"id":68687941}],"con":true,"img":false}]}
{"op":"mcm","clk":"11541460265","pt":1719505986749,"mc":[{"id":"1.230178327","rc":[{"atb":[[2.04,2.49]],"id":65710029}],"con":true,"img":false}]}
{"op":"mcm","clk":"11541460288","pt":1719505986919,"mc":[{"id":"1.230178327","rc":[{"atl":[[4.8,7.25],[4.6,0]],"id":58221357},{"atl":[[5.4,1]],"id":60748118},{"atl":[[4.3,14.8],[4.2,1]],"id":68687941}],"con":true,"img":false}]}
{"op":"mcm","clk":"11541460298","pt":1719505987017,"mc":[{"id":"1.230178327","rc":[{"atb":[[2.46,7.75]],"id":58221357},{"atl":[[5.2,0]],"id":60748118},{"atb":[[2.4,7.37]],"id":62600242}],"con":true,"img":false}]}
{"op":"mcm","clk":"11541460319","pt":1719505987218,"mc":[{"id":"1.230178327","rc":[{"atb":[[2.44,2]],"id":58221357},{"atb":[[2.38,2]],"id":62600242}],"con":true,"img":false}]}
{"op":"mcm","clk":"11541460357","pt":1719505987627,"mc":[{"id":"1.230178327","rc":[{"atl":[[4.8,6.25]],"id":58221357},{"atl":[[5.1,1],[5.4,0]],"id":60748118},{"atl":[[4.3,15.8],[4.2,0]],"id":68687941},{"atl":[[4.2,1]],"id":65710029}],"con":true,"img":false}]}
{"op":"mcm","clk":"11541460369","pt":1719505987734,"mc":[{"id":"1.230178327","rc":[{"atl":[[4.6,1]],"id":58221357},{"atl":[[4.3,8.81]],"id":65710029}],"con":true,"img":false}]}
{"op":"mcm","clk":"11541460414","pt":1719505988309,"mc":[{"id":"1.230178327","rc":[{"atb":[[2.44,0]],"id":58221357}],"con":true,"img":false}]}
{"op":"mcm","clk":"11541460419","pt":1719505988403,"mc":[{"id":"1.230178327","rc":[{"atb":[[2.48,2]],"id":58221357}],"con":true,"img":false}]}
{"op":"mcm","clk":"11541460435","pt":1719505988613,"mc":[{"id":"1.230178327","rc":[{"atb":[[2.38,0]],"id":62600242}],"con":true,"img":false}]}
{"op":"mcm","clk":"11541460448","pt":1719505988716,"mc":[{"id":"1.230178327","rc":[{"atb":[[2.42,2]],"id":62600242}],"con":true,"img":false}]}
{"op":"mcm","clk":"11541460635","pt":1719505990526,"mc":[{"id":"1.230178327","rc":[{"atl":[[5.8,2.5],[5.4,6.16]],"id":60748118}],"con":true,"img":false}]}
{"op":"mcm","clk":"11541460742","pt":1719505991618,"mc":[{"id":"1.230178327","rc":[{"atl":[[4,0.52]],"id":65710029}],"con":true,"img":false}]}
{"op":"mcm","clk":"11541460762","pt":1719505991832,"mc":[{"id":"1.230178327","rc":[{"atb":[[1.03,0.52]],"id":65710029},{"atl":[[4,3.98]],"id":65710029}],"con":true,"img":false}]}
{"op":"mcm","clk":"11541460782","pt":1719505992026,"mc":[{"id":"1.230178327","rc":[{"atb":[[1.03,0.48]],"id":65710029},{"atl":[[4.1,0.84]],"id":65710029}],"con":true,"img":false}]}
{"op":"mcm","clk":"11541460804","pt":1719505992234,"mc":[{"id":"1.230178327","rc":[{"atb":[[1.03,0]],"id":65710029}],"con":true,"img":false}]}
{"op":"mcm","clk":"11541460816","pt":1719505992340,"mc":[{"id":"1.230178327","rc":[{"atb":[[2.08,0.48]],"id":65710029},{"atl":[[3.95,0.84]],"id":65710029}],"con":true,"img":false}]}
{"op":"mcm","clk":"11541460825","pt":1719505992442,"mc":[{"id":"1.230178327","rc":[{"atl":[[4.3,0],[4.1,5.68]],"id":65710029}],"con":true,"img":false}]}
{"op":"mcm","clk":"11541460922","pt":1719505993225,"mc":[{"id":"1.230178327","rc":[{"atb":[[1.74,0]],"id":68687941}],"con":true,"img":false}]}
{"op":"mcm","clk":"11541460936","pt":1719505993325,"mc":[{"id":"1.230178327","rc":[{"atb":[[2.64,20],[2.78,0]],"id":67674431},{"atl":[[7.4,13.88],[6.8,0],[7,1]],"id":67674431},{"atl":[[4.1,6.68],[4.2,0]],"id":65710029}],"con":true,"img":false}]}
{"op":"mcm","clk":"11541460949","pt":1719505993428,"mc":[{"id":"1.230178327","rc":[{"atl":[[4.3,1],[4.9,22.9]],"id":68687941},{"atb":[[2.92,24.86],[2.64,0]],"id":67674431}],"con":true,"img":false}]}
{"op":"mcm","clk":"11541461062","pt":1719505994527,"mc":[{"id":"1.230178327","rc":[{"atb":[[1.08,50]],"id":58221357},{"atb":[[1.08,50]],"id":60748118},{"atb":[[1.08,50]],"id":62600242},{"atb":[[1.08,50]],"id":68687941},{"atb":[[1.08,50]],"id":67674431},{"atb":[[1.08,50]],"id":65710029}],"con":true,"img":false}]}
{"op":"mcm","clk":"11541461357","pt":1719505997537,"mc":[{"id":"1.230178327","rc":[{"atl":[[4.5,1]],"id":58221357},{"spn":3.39,"spf":"NaN","id":58221357},{"spn":3.36,"spf":"NaN","id":62600242},{"atl":[[5,1]],"id":60748118},{"spn":3.64,"spf":"NaN","id":60748118},{"atl":[[4.3,0],[4.1,1]],"id":68687941},{"spn":2.18,"spf":1.0,"id":68687941},{"spn":3.01,"spf":"NaN","id":65710029}],"con":true,"img":false}]}
{"op":"mcm","clk":"11541461364","pt":1719505997623,"mc":[{"id":"1.230178327","rc":[{"atl":[[4.8,0],[4.6,10.5]],"id":58221357},{"atl":[[5.1,10.32],[4.9,1],[5.4,0]],"id":60748118},{"atl":[[4.8,0],[4.5,1],[4.6,1]],"id":62600242},{"atl":[[4.3,9.2],[4.9,2.5],[4.2,1]],"id":68687941}],"con":true,"img":false}]}
{"op":"mcm","clk":"11541461374","pt":1719505997730,"mc":[{"id":"1.230178327","rc":[{"atl":[[4.6,11.24]],"id":62600242},{"atl":[[4.9,12.5]],"id":68687941}],"con":true,"img":false}]}
{"op":"mcm","clk":"11541461389","pt":1719505997831,"mc":[{"id":"1.230178327","rc":[{"atl":[[5.1,2.5],[4.6,10.24]],"id":62600242},{"atl":[[4.8,1],[5,0],[4.9,0]],"id":60748118},{"atl":[[4.3,0],[4.9,2.5],[4.2,5.6]],"id":68687941},{"atl":[[7.2,1],[7,0]],"id":67674431}],"con":true,"img":false}]}
{"op":"mcm","clk":"11541461397","pt":1719505997932,"mc":[{"id":"1.230178327","rc":[{"atl":[[5.1,0],[4.9,10.32]],"id":60748118}],"con":true,"img":false}]}
{"op":"mcm","clk":"11541461807","pt":1719506002060,"mc":[{"id":"1.230178327","rc":[{"atb":[[2.48,7.81]],"id":58221357},{"atb":[[2.42,7.43]],"id":62600242}],"con":true,"img":false}]}
{"op":"mcm","clk":"11541461831","pt":1719506002264,"mc":[{"id":"1.230178327","rc":[{"atb":[[2.46,1.94]],"id":58221357},{"atb":[[2.4,1.94]],"id":62600242}],"con":true,"img":false}]}
{"op":"mcm","clk":"11541462295","pt":1719506006803,"mc":[{"id":"1.230178327","rc":[{"atl":[[3.95,5.71]],"id":65710029}],"con":true,"img":false}]}
{"op":"mcm","clk":"11541462314","pt":1719506006931,"mc":[{"id":"1.230178327","rc":[{"atl":[[4,0]],"id":65710029}],"con":true,"img":false}]}
{"op":"mcm","clk":"11541462327","pt":1719506007034,"mc":[{"id":"1.230178327","rc":[{"atl":[[4.3,12.41],[4.1,1.84]],"id":65710029}],"con":true,"img":false}]}
{"op":"mcm","clk":"11541462358","pt":1719506007341,"mc":[{"id":"1.230178327","rc":[{"atl":[[4.1,1]],"id":65710029}],"con":true,"img":false}]}
{"op":"mcm","clk":"11541462397","pt":1719506007755,"mc":[{"id":"1.230178327","rc":[{"atb":[[2.08,0]],"id":65710029}],"con":true,"img":false}]}
{"op":"mcm","clk":"11541463357","pt":1719506017658,"mc":[{"id":"1.230178327","rc":[{"atb":[[2.46,0]],"id":58221357},{"atb":[[2.4,0]],"id":62600242},{"atb":[[2.14,0]],"id":68687941}],"con":true,"img":false}]}
{"op":"mcm","clk":"11541463372","pt":1719506017866,"mc":[{"id":"1.230178327","rc":[{"atb":[[2.5,1.94]],"id":58221357},{"atb":[[2.44,1.94]],"id":62600242},{"atb":[[2.2,1.94]],"id":68687941}],"con":true,"img":false}]}
{"op":"mcm","clk":"11541463384","pt":1719506017969,"mc":[{"id":"1.230178327","rc":[{"atb":[[2.5,7.75]],"id":58221357},{"atb":[[2.2,7.26]],"id":68687941},{"atl":[[3.9,0.52]],"id":65710029}],"con":true,"img":false}]}
{"op":"mcm","clk":"11541463390","pt":1719506018072,"mc":[{"id":"1.230178327","rc":[{"atb":[[2.48,2]],"id":58221357},{"atb":[[2.44,7.37]],"id":62600242},{"atb":[[2.18,2.11]],"id":68687941},{"atb":[[1.03,0.52]],"id":65710029}],"con":true,"img":false}]}
{"op":"mcm","clk":"11541463397","pt":1719506018134,"mc":[{"id":"1.230178327","rc":[{"atl":[[4.3,0],[4.1,7.25]],"id":65710029}],"con":true,"img":false}]}
{"op":"mcm","clk":"11541463405","pt":1719506018243,"mc":[{"id":"1.230178327","rc":[{"atb":[[2.42,2]],"id":62600242}],"con":true,"img":false}]}
{"op":"mcm","clk":"11541463416","pt":1719506018341,"mc":[{"id":"1.230178327","rc":[{"atb":[[1.03,0.48]],"id":65710029}],"con":true,"img":false}]}
{"op":"mcm","clk":"11541463430","pt":1719506018541,"mc":[{"id":"1.230178327","rc":[{"atb":[[1.03,0]],"id":65710029}],"con":true,"img":false}]}
{"op":"mcm","clk":"11541463442","pt":1719506018643,"mc":[{"id":"1.230178327","rc":[{"atb":[[2.08,0.48]],"id":65710029}],"con":true,"img":false}]}
{"op":"mcm","clk":"11541463483","pt":1719506019060,"mc":[{"id":"1.230178327","rc":[{"atl":[[4.5,0]],"id":58221357},{"atl":[[5.1,1]],"id":60748118}],"con":true,"img":false}]}
{"op":"mcm","clk":"11541463495","pt":1719506019162,"mc":[{"id":"1.230178327","rc":[{"atl":[[4.6,11.5]],"id":58221357},{"atl":[[4.8,0]],"id":60748118},{"atl":[[4.8,1],[4.5,0]],"id":62600242}],"con":true,"img":false}]}
{"op":"mcm","clk":"11541463502","pt":1719506019265,"mc":[{"id":"1.230178327","rc":[{"atl":[[5.5,19.25]],"id":58221357},{"atl":[[4.8,16.36],[4.6,0]],"id":62600242},{"atl":[[5.1,16.48],[4.9,0]],"id":60748118}],"con":true,"img":false}]}
{"op":"mcm","clk":"11541463510","pt":1719506019371,"mc":[{"id":"1.230178327","rc":[{"atl":[[4.6,1]],"id":58221357},{"atl":[[5.1,1],[5.8,23.33]],"id":60748118},{"atl":[[4.8,1],[5.1,23.98]],"id":62600242}],"con":true,"img":false}]}
{"op":"mcm","clk":"11541463528","pt":1719506019538,"mc":[{"id":"1.230178327","rc":[{"atl":[[4.3,1],[4.1,0]],"id":68687941}],"con":true,"img":false}]}
{"op":"mcm","clk":"11541463539","pt":1719506019634,"mc":[{"id":"1.230178327","rc":[{"atb":[[2.48,0]],"id":58221357},{"atl":[[4.5,1],[4.6,0]],"id":58221357},{"atl":[[4.8,0],[4.5,1]],"id":62600242},{"atl":[[4.8,1],[5.1,0]],"id":60748118}],"con":true,"img":false}]}
{"op":"mcm","clk":"11541463547","pt":1719506019739,"mc":[{"id":"1.230178327","rc":[{"atb":[[2.52,2]],"id":58221357},{"atl":[[4.6,10.5],[5.5,2.5]],"id":58221357},{"atl":[[5.1,10.32],[5.8,2.5]],"id":60748118},{"atl":[[4.8,10.24],[5.1,2.5]],"id":62600242},{"atl":[[4.3,11.2],[4.2,0]],"id":68687941}],"con":true,"img":false}]}
{"op":"mcm","clk":"11541463590","pt":1719506020149,"mc":[{"id":"1.230178327","rc":[{"atb":[[2.42,0]],"id":62600242}],"con":true,"img":false}]}
{"op":"mcm","clk":"11541463600","pt":1719506020255,"mc":[{"id":"1.230178327","rc":[{"atb":[[2.46,2]],"id":62600242}],"con":true,"img":false}]}
{"op":"mcm","clk":"11541463611","pt":1719506020354,"mc":[{"id":"1.230178327","rc":[{"atl":[[4.3,10.2],[4.1,1]],"id":68687941}],"con":true,"img":false}]}
{"op":"mcm","clk":"11541463719","pt":1719506021338,"mc":[{"id":"1.230178327","rc":[{"atl":[[4.5,0],[4.6,11.5]],"id":58221357},{"atl":[[4.8,11.24],[4.5,0]],"id":62600242},{"atl":[[4.3,11.2],[4.1,0]],"id":68687941},{"atl":[[3.9,6.68]],"id":65710029}],"con":true,"img":false}]}
{"op":"mcm","clk":"11541463738","pt":1719506021543,"mc":[{"id":"1.230178327","rc":[{"atl":[[3.95,0.84]],"id":65710029}],"con":true,"img":false}]}
{"op":"mcm","clk":"11541463768","pt":1719506021854,"mc":[{"id":"1.230178327","rc":[{"atl":[[3.85,0.84]],"id":65710029}],"con":true,"img":false}]}
{"op":"mcm","clk":"11541463782","pt":1719506021956,"mc":[{"id":"1.230178327","rc":[{"atl":[[3.95,8.38],[4.1,1]],"id":65710029}],"con":true,"img":false}]}
{"op":"mcm","clk":"11541463818","pt":1719506022373,"mc":[{"id":"1.230178327","rc":[{"atl":[[4.5,1],[4.6,10.5]],"id":58221357},{"atl":[[4.8,10.24],[4.5,1]],"id":62600242},{"atl":[[4.3,10.2],[4.1,1]],"id":68687941}],"con":true,"img":false}]}
{"op":"mcm","clk":"11541463970","pt":1719506023975,"mc":[{"id":"1.230178327","rc":[{"atl":[[4.5,0],[4.6,11.5]],"id":58221357},{"atl":[[4.8,11.24],[4.5,0]],"id":62600242},{"atl":[[4.3,11.2],[4.1,0]],"id":68687941}],"con":true,"img":false}]}
{"op":"mcm","clk":"11541464056","pt":1719506024853,"mc":[{"id":"1.230178327","rc":[{"atl":[[4.6,1],[5.5,19.25]],"id":58221357},{"atl":[[5.1,18.86]],"id":62600242},{"atl":[[4.3,1],[4.9,18.3]],"id":68687941}],"con":true,"img":false}]}
{"op":"mcm","clk":"11541464069","pt":1719506024956,"mc":[{"id":"1.230178327","rc":[{"atl":[[4.8,1]],"id":62600242}],"con":true,"img":false}]}
{"op":"mcm","clk":"11541464536","pt":1719506029971,"mc":[{"id":"1.230178327","rc":[{"atl":[[4.8,0],[5.1,11.32]],"id":60748118}],"con":true,"img":false}]}
{"op":"mcm","clk":"11541464691","pt":1719506031486,"mc":[{"id":"1.230178327","rc":[{"atl":[[5.8,5],[5.5,16.75],[5.9,0],[5.4,2.5]],"id":58221357},{"atl":[[5,2.5],[5.4,5]],"id":62600242}],"con":true,"img":false}]}
{"op":"mcm","clk":"11541464700","pt":1719506031589,"mc":[{"id":"1.230178327","rc":[{"atl":[[5.3,6.25]],"id":58221357},{"atl":[[5.1,16.36],[5.5,0],[4.9,6.12]],"id":62600242}],"con":true,"img":false}]}
{"op":"mcm","clk":"11541464709","pt":1719506031692,"mc":[{"id":"1.230178327","rc":[{"atl":[[5.5,0]],"id":58221357},{"atl":[[5.1,0]],"id":62600242}],"con":true,"img":false}]}
{"op":"mcm","clk":"11541464777","pt":1719506032268,"mc":[{"id":"1.230178327","rc":[{"atb":[[2.52,7.81]],"id":58221357}],"con":true,"img":false}]}
{"op":"mcm","clk":"11541464788","pt":1719506032370,"mc":[{"id":"1.230178327","rc":[{"atb":[[2.5,1.94]],"id":58221357},{"atb":[[2.46,7.43]],"id":62600242}],"con":true,"img":false}]}
{"op":"mcm","clk":"11541464806","pt":1719506032575,"mc":[{"id":"1.230178327","rc":[{"atb":[[2.44,1.94]],"id":62600242}],"con":true,"img":false}]}
{"op":"mcm","clk":"11541464824","pt":1719506032785,"mc":[{"id":"1.230178327","rc":[{"atb":[[2.5,0]],"id":58221357},{"atb":[[2.44,0]],"id":62600242}],"con":true,"img":false}]}
{"op":"mcm","clk":"11541464843","pt":1719506032989,"mc":[{"id":"1.230178327","rc":[{"atb":[[2.54,1.94]],"id":58221357}],"con":true,"img":false}]}
{"op":"mcm","clk":"11541464866","pt":1719506033196,"mc":[{"id":"1.230178327","rc":[{"atl":[[3.9,6.16]],"id":65710029}],"con":true,"img":false}]}
{"op":"mcm","clk":"11541464876","pt":1719506033252,"mc":[{"id":"1.230178327","rc":[{"atl":[[4.8,1],[4.6,0]],"id":58221357}],"con":true,"img":false}]}
{"op":"mcm","clk":"11541464952","pt":1719506034076,"mc":[{"id":"1.230178327","rc":[{"atb":[[2.08,0]],"id":65710029}],"con":true,"img":false}]}
{"op":"mcm","clk":"11541465035","pt":1719506034852,"mc":[{"id":"1.230178327","rc":[{"atl":[[4.8,0],[4.6,1]],"id":58221357}],"con":true,"img":false}]}
{"op":"mcm","clk":"11541465113","pt":1719506035676,"mc":[{"id":"1.230178327","rc":[{"atl":[[3.85,7.34]],"id":65710029}],"con":true,"img":false}]}
{"op":"mcm","clk":"11541465141","pt":1719506035882,"mc":[{"id":"1.230178327","rc":[{"atb":[[2.54,0]],"id":58221357},{"atl":[[3.9,0]],"id":65710029}],"con":true,"img":false}]}
{"op":"mcm","clk":"11541465151","pt":1719506035983,"mc":[{"id":"1.230178327","rc":[{"atb":[[2.54,1.94]],"id":58221357},{"atl":[[3.95,0.84],[4.1,16.74]],"id":65710029}],"con":true,"img":false}]}
{"op":"mcm","clk":"11541465183","pt":1719506036396,"mc":[{"id":"1.230178327","rc":[{"atl":[[3.95,0]],"id":65710029}],"con":true,"img":false}]}
{"op":"mcm","clk":"11541465214","pt":1719506036779,"mc":[{"id":"1.230178327","rc":[{"atl":[[7.2,0],[7.4,14.88]],"id":67674431}],"con":true,"img":false}]}
{"op":"mcm","clk":"11541465384","pt":1719506038867,"mc":[{"id":"1.230178327","rc":[{"atb":[[2.54,0]],"id":58221357}],"con":true,"img":false}]}
{"op":"mcm","clk":"11541465407","pt":1719506039074,"mc":[{"id":"1.230178327","rc":[{"atb":[[2.54,1.94]],"id":58221357}],"con":true,"img":false}]}
{"op":"mcm","clk":"11541465589","pt":1719506041092,"mc":[{"id":"1.230178327","rc":[{"atl":[[4.3,24.09],[4.1,1]],"id":65710029}],"con":true,"img":false}]}
{"op":"mcm","clk":"11541465673","pt":1719506041970,"mc":[{"id":"1.230178327","rc":[{"atb":[[2.54,0]],"id":58221357}],"con":true,"img":false}]}
{"op":"mcm","clk":"11541465690","pt":1719506042175,"mc":[{"id":"1.230178327","rc":[{"atb":[[2.54,1.94]],"id":58221357}],"con":true,"img":false}]}
{"op":"mcm","clk":"11541465926","pt":1719506044505,"mc":[{"id":"1.230178327","rc":[{"atb":[[1.03,0.52]],"id":65710029},{"atl":[[3.8,0.52]],"id":65710029}],"con":true,"img":false}]}
{"op":"mcm","clk":"11541465944","pt":1719506044667,"mc":[{"id":"1.230178327","rc":[{"atb":[[1.03,0.48]],"id":65710029}],"con":true,"img":false}]}
{"op":"mcm","clk":"11541465981","pt":1719506044975,"mc":[{"id":"1.230178327","rc":[{"atb":[[1.03,0]],"id":65710029}],"con":true,"img":false}]}
{"op":"mcm","clk":"11541465990","pt":1719506045078,"mc":[{"id":"1.230178327","rc":[{"atb":[[2.54,0]],"id":58221357},{"atb":[[2.08,0.48]],"id":65710029}],"con":true,"img":false}]}
{"op":"mcm","clk":"11541466007","pt":1719506045286,"mc":[{"id":"1.230178327","rc":[{"atb":[[2.54,1.94]],"id":58221357},{"atb":[[2.48,1.94]],"id":62600242}],"con":true,"img":false}]}
{"op":"mcm","clk":"11541466103","pt":1719506046375,"mc":[{"id":"1.230178327","rc":[{"atb":[[2.54,7.75]],"id":58221357}],"con":true,"img":false}]}
{"op":"mcm","clk":"11541466116","pt":1719506046479,"mc":[{"id":"1.230178327","rc":[{"atb":[[2.48,7.37]],"id":62600242}],"con":true,"img":false}]}
{"op":"mcm","clk":"11541466125","pt":1719506046583,"mc":[{"id":"1.230178327","rc":[{"atb":[[2.52,2]],"id":58221357}],"con":true,"img":false}]}
{"op":"mcm","clk":"11541466137","pt":1719506046683,"mc":[{"id":"1.230178327","rc":[{"atb":[[2.46,2]],"id":62600242}],"con":true,"img":false}]}
{"op":"mcm","clk":"11541466230","pt":1719506047709,"mc":[{"id":"1.230178327","rc":[{"atl":[[4.3,0],[4.1,8.88]],"id":65710029}],"con":true,"img":false}]}
{"op":"mcm","clk":"11541466269","pt":1719506048081,"mc":[{"id":"1.230178327","rc":[{"atb":[[2.52,0]],"id":58221357}],"con":true,"img":false}]}
{"op":"mcm","clk":"11541466278","pt":1719506048183,"mc":[{"id":"1.230178327","rc":[{"atb":[[2.56,2]],"id":58221357}],"con":true,"img":false}]}
{"op":"mcm","clk":"11541466350","pt":1719506048905,"mc":[{"id":"1.230178327","rc":[{"atb":[[2.46,0]],"id":62600242}],"con":true,"img":false}]}
{"op":"mcm","clk":"11541466359","pt":1719506049012,"mc":[{"id":"1.230178327","rc":[{"atb":[[2.5,2]],"id":62600242}],"con":true,"img":false}]}
{"op":"mcm","clk":"11541466440","pt":1719506049696,"mc":[{"id":"1.230178327","rc":[{"atl":[[3.8,7.91]],"id":65710029}],"con":true,"img":false}]}
{"op":"mcm","clk":"11541466462","pt":1719506049900,"mc":[{"id":"1.230178327","rc":[{"atl":[[4.1,1],[3.75,7.92]],"id":65710029}],"con":true,"img":false}]}
{"op":"mcm","clk":"11541466475","pt":1719506049992,"mc":[{"id":"1.230178327","rc":[{"atl":[[3.85,0.84]],"id":65710029}],"con":true,"img":false}]}
{"op":"mcm","clk":"11541466511","pt":1719506050305,"mc":[{"id":"1.230178327","rc":[{"atb":[[1.02,12.93]],"id":58221357},{"atl":[[1000,1.87]],"id":58221357},{"atb":[[1.02,1.7]],"id":62600242},{"atl":[[1000,1.87]],"id":62600242},{"atb":[[1.02,3.7]],"id":60748118},{"atl":[[1000,1.7]],"id":60748118},{"atl":[[3.85,0],[3.7,0.84]],"id":65710029}],"con":true,"img":false}]}
{"op":"mcm","clk":"11541466536","pt":1719506050513,"mc":[{"id":"1.230178327","rc":[{"atb":[[1.02,11.4]],"id":58221357},{"atl":[[1000,0.26]],"id":58221357},{"atb":[[1.02,2.17]],"id":60748118},{"atl":[[5.8,18.98],[1000,0.07]],"id":60748118},{"atb":[[1.02,0.18]],"id":62600242},{"atl":[[1000,0.26]],"id":62600242}],"con":true,"img":false}]}
{"op":"mcm","clk":"11541466546","pt":1719506050584,"mc":[{"id":"1.230178327","rc":[{"atl":[[5.1,1]],"id":60748118}],"con":true,"img":false}]}
{"op":"mcm","clk":"11541466556","pt":1719506050674,"mc":[{"id":"1.230178327","rc":[{"atb":[[1.02,11.23]],"id":58221357},{"atl":[[1000,0.17]],"id":58221357},{"atb":[[1.02,2]],"id":60748118},{"atl":[[1000,0]],"id":60748118},{"atb":[[1.02,0]],"id":62600242},{"atl":[[1000,0.17]],"id":62600242}],"con":true,"img":false}]}
{"op":"mcm","clk":"11541466564","pt":1719506050821,"mc":[{"id":"1.230178327","rc":[{"atb":[[2.58,0.17]],"id":58221357},{"atl":[[4.2,0.08]],"id":58221357},{"atb":[[2.6,0.17]],"id":60748118},{"atl":[[4.6,0.07]],"id":60748118},{"atb":[[2.52,0.18]],"id":62600242},{"atl":[[4.2,0.08]],"id":62600242}],"con":true,"img":false}]}
{"op":"mcm","clk":"11541466573","pt":1719506050884,"mc":[{"id":"1.230178327","rc":[{"atl":[[4.6,6.34],[5.3,0],[4.2,2.33]],"id":58221357},{"atl":[[4.2,2.33]],"id":62600242},{"atl":[[4.6,2.69]],"id":60748118}],"con":true,"img":false}]}
{"op":"mcm","clk":"11541466582","pt":1719506050977,"mc":[{"id":"1.230178327","rc":[{"atl":[[4.9,0],[4.2,4.67]],"id":62600242}],"con":true,"img":false}]}
{"op":"mcm","clk":"11541466592","pt":1719506051098,"mc":[{"id":"1.230178327","rc":[{"atl":[[4.3,0.84]],"id":58221357},{"atl":[[4.3,0.84]],"id":62600242},{"atl":[[4.7,0.84]],"id":60748118}],"con":true,"img":false}]}
{"op":"mcm","clk":"11541466601","pt":1719506051197,"mc":[{"id":"1.230178327","rc":[{"atb":[[2.54,5.81]],"id":58221357},{"atb":[[2.48,5.43]],"id":62600242}],"con":true,"img":false}]}
{"op":"mcm","clk":"11541466612","pt":1719506051293,"mc":[{"id":"1.230178327","rc":[{"atl":[[4.1,0.84]],"id":58221357},{"atl":[[4.1,0.84]],"id":62600242},{"atl":[[4.5,0.84]],"id":60748118}],"con":true,"img":false}]}
{"op":"mcm","clk":"11541466624","pt":1719506051389,"mc":[{"id":"1.230178327","rc":[{"atb":[[2.58,2.12]],"id":58221357},{"atl":[[4.3,4.03],[4.6,1]],"id":58221357},{"atb":[[2.52,2.13]],"id":62600242}],"con":true,"img":false}]}
{"op":"mcm","clk":"11541466903","pt":1719506054097,"mc":[{"id":"1.230178327","rc":[{"atb":[[2.56,0]],"id":58221357}],"con":true,"img":false}]}
{"op":"mcm","clk":"11541466913","pt":1719506054202,"mc":[{"id":"1.230178327","rc":[{"atb":[[2.6,2]],"id":58221357}],"con":true,"img":false}]}
{"op":"mcm","clk":"11541466950","pt":1719506054512,"mc":[{"id":"1.230178327","rc":[{"atb":[[2.5,0]],"id":62600242}],"con":true,"img":false}]}
{"op":"mcm","clk":"11541466963","pt":1719506054613,"mc":[{"id":"1.230178327","rc":[{"atb":[[2.54,2]],"id":62600242}],"con":true,"img":false}]}
{"op":"mcm","clk":"11541467010","pt":1719506054981,"mc":[{"id":"1.230178327","rc":[{"atl":[[3.8,16.68],[3.75,0]],"id":65710029}],"con":true,"img":false}]}
{"op":"mcm","clk":"11541467050","pt":1719506055393,"mc":[{"id":"1.230178327","rc":[{"atl":[[3.7,0]],"id":65710029}],"con":true,"img":false}]}
{"op":"mcm","clk":"11541467058","pt":1719506055497,"mc":[{"id":"1.230178327","rc":[{"atl":[[4.3,17.69],[3.8,7.91]],"id":65710029}],"con":true,"img":false}]}
{"op":"mcm","clk":"11541467081","pt":1719506055700,"mc":[{"id":"1.230178327","rc":[{"atl":[[4.8,1],[4.6,0]],"id":58221357}],"con":true,"img":false}]}
{"op":"mcm","clk":"11541467128","pt":1719506056219,"mc":[{"id":"1.230178327","rc":[{"atl":[[4.3,6.37]],"id":62600242}],"con":true,"img":false}]}
{"op":"mcm","clk":"11541467140","pt":1719506056320,"mc":[{"id":"1.230178327","rc":[{"atl":[[4.2,2.33]],"id":62600242}],"con":true,"img":false}]}
{"op":"mcm","clk":"11541467213","pt":1719506056895,"mc":[{"id":"1.230178327","rc":[{"atl":[[4.8,0],[4.6,1]],"id":58221357},{"atl":[[5.8,2.5],[4.7,4.39]],"id":60748118},{"atl":[[7.4,13.88],[7,1]],"id":67674431}],"con":true,"img":false}]}
{"op":"mcm","clk":"11541467261","pt":1719506057310,"mc":[{"id":"1.230178327","rc":[{"atl":[[3.75,0.84]],"id":65710029}],"con":true,"img":false}]}
{"op":"mcm","clk":"11541467277","pt":1719506057415,"mc":[{"id":"1.230178327","rc":[{"atl":[[4.3,0],[4.1,9.77]],"id":65710029}],"con":true,"img":false}]}
{"op":"mcm","clk":"11541467482","pt":1719506059386,"mc":[{"id":"1.230178327","rc":[{"atl":[[4.8,1],[4.6,0]],"id":58221357},{"spn":3.35,"spf":"NaN","id":58221357},{"spn":3.55,"spf":"NaN","id":60748118},{"spn":3.32,"spf":"NaN","id":62600242},{"spn":2.2,"spf":1.0,"id":68687941},{"spn":2.91,"spf":"NaN","id":65710029}],"con":true,"img":false}]}
{"op":"mcm","clk":"11541467526","pt":1719506059800,"mc":[{"id":"1.230178327","rc":[{"atl":[[3.8,7.39]],"id":65710029}],"con":true,"img":false}]}
{"op":"mcm","clk":"11541467569","pt":1719506060212,"mc":[{"id":"1.230178327","rc":[{"atb":[[2.6,5.35]],"id":58221357}],"con":true,"img":false}]}
{"op":"mcm","clk":"11541467578","pt":1719506060316,"mc":[{"id":"1.230178327","rc":[{"atb":[[2.54,5.35]],"id":62600242}],"con":true,"img":false}]}
{"op":"mcm","clk":"11541467591","pt":1719506060419,"mc":[{"id":"1.230178327","rc":[{"atb":[[2.54,0]],"id":58221357}],"con":true,"img":false}]}
{"op":"mcm","clk":"11541467602","pt":1719506060523,"mc":[{"id":"1.230178327","rc":[{"atb":[[2.48,0]],"id":62600242}],"con":true,"img":false}]}
{"op":"mcm","clk":"11541467613","pt":1719506060576,"mc":[{"id":"1.230178327","rc":[{"atb":[[2.08,0]],"id":65710029}],"con":true,"img":false}]}
{"op":"mcm","clk":"11541467774","pt":1719506062290,"mc":[{"id":"1.230178327","rc":[{"atl":[[4.8,0],[4.6,1]],"id":58221357}],"con":true,"img":false}]}
{"op":"mcm","clk":"11541467872","pt":1719506063219,"mc":[{"id":"1.230178327","rc":[{"atb":[[2.58,0.17]],"id":58221357},{"atl":[[4.8,1],[4.6,0]],"id":58221357},{"atb":[[2.52,0.18]],"id":62600242}],"con":true,"img":false}]}
{"op":"mcm","clk":"11541467883","pt":1719506063327,"mc":[{"id":"1.230178327","rc":[{"atb":[[2.62,1.94]],"id":58221357},{"atb":[[2.56,1.94]],"id":62600242}],"con":true,"img":false}]}
{"op":"mcm","clk":"11541467904","pt":1719506063483,"mc":[{"id":"1.230178327","rc":[{"atl":[[3.75,8.26]],"id":65710029}],"con":true,"img":false}]}
{"op":"mcm","clk":"11541467922","pt":1719506063691,"mc":[{"id":"1.230178327","rc":[{"atl":[[3.8,0]],"id":65710029}],"con":true,"img":false}]}
{"op":"mcm","clk":"11541468011","pt":1719506064619,"mc":[{"id":"1.230178327","rc":[{"atl":[[4.1,4.06]],"id":58221357},{"atl":[[4.1,4.06]],"id":62600242},{"atl":[[4.5,4.74]],"id":60748118}],"con":true,"img":false}]}
{"op":"mcm","clk":"11541468019","pt":1719506064718,"mc":[{"id":"1.230178327","rc":[{"atl":[[4.2,0.08]],"id":58221357},{"atl":[[4.6,0.07]],"id":60748118},{"atl":[[4.2,0.08]],"id":62600242}],"con":true,"img":false}]}
{"op":"mcm","clk":"11541468088","pt":1719506065394,"mc":[{"id":"1.230178327","rc":[{"atl":[[4.3,3.19]],"id":58221357},{"atl":[[4.3,5.53]],"id":62600242},{"atl":[[4.7,3.55]],"id":60748118}],"con":true,"img":false}]}
{"op":"mcm","clk":"11541468181","pt":1719506066218,"mc":[{"id":"1.230178327","rc":[{"atb":[[2.62,0]],"id":58221357},{"atb":[[2.56,0]],"id":62600242}],"con":true,"img":false}]}
{"op":"mcm","clk":"11541468191","pt":1719506066320,"mc":[{"id":"1.230178327","rc":[{"atb":[[2.62,1.94]],"id":58221357},{"atb":[[2.56,1.94]],"id":62600242}],"con":true,"img":false}]}
{"op":"mcm","clk":"11541468319","pt":1719506067508,"mc":[{"id":"1.230178327","rc":[{"atb":[[2.84,0],[2.94,2.5],[2.76,0],[2.92,22.36],[2.86,5],[2.78,10]],"id":67674431}],"con":true,"img":false}]}
{"op":"mcm","clk":"11541468421","pt":1719506068490,"mc":[{"id":"1.230178327","rc":[{"atl":[[4.5,6.42]],"id":58221357}],"con":true,"img":false}]}
{"op":"mcm","clk":"11541468444","pt":1719506068699,"mc":[{"id":"1.230178327","rc":[{"atl":[[4.5,0]],"id":58221357}],"con":true,"img":false}]}
{"op":"mcm","clk":"11541468511","pt":1719506069521,"mc":[{"id":"1.230178327","rc":[{"atb":[[2.62,0]],"id":58221357},{"atb":[[2.56,0]],"id":62600242}],"con":true,"img":false}]}
{"op":"mcm","clk":"11541468521","pt":1719506069627,"mc":[{"id":"1.230178327","rc":[{"atb":[[2.62,1.94]],"id":58221357}],"con":true,"img":false}]}
{"op":"mcm","clk":"11541468702","pt":1719506071438,"mc":[{"id":"1.230178327","rc":[{"atl":[[3.7,0.52]],"id":65710029}],"con":true,"img":false}]}
{"op":"mcm","clk":"11541468714","pt":1719506071493,"mc":[{"id":"1.230178327","rc":[{"atb":[[1.03,0.52]],"id":65710029}],"con":true,"img":false}]}
{"op":"mcm","clk":"11541468725","pt":1719506071598,"mc":[{"id":"1.230178327","rc":[{"atb":[[1.03,0.48]],"id":65710029}],"con":true,"img":false}]}
{"op":"mcm","clk":"11541468747","pt":1719506071805,"mc":[{"id":"1.230178327","rc":[{"atb":[[1.03,0]],"id":65710029}],"con":true,"img":false}]}
{"op":"mcm","clk":"11541468760","pt":1719506071907,"mc":[{"id":"1.230178327","rc":[{"atb":[[2.08,0.48]],"id":65710029}],"con":true,"img":false}]}
{"op":"mcm","clk":"11541468811","pt":1719506072424,"mc":[{"id":"1.230178327","rc":[{"atb":[[2.62,0]],"id":58221357}],"con":true,"img":false}]}
{"op":"mcm","clk":"11541468827","pt":1719506072629,"mc":[{"id":"1.230178327","rc":[{"atb":[[2.62,1.94]],"id":58221357}],"con":true,"img":false}]}
{"op":"mcm","clk":"11541468914","pt":1719506073409,"mc":[{"id":"1.230178327","rc":[{"atb":[[2.56,3]],"id":62600242},{"atb":[[2.6,3.16]],"id":60748118},{"atb":[[2.22,3]],"id":68687941},{"atb":[[3,3.3]],"id":67674431},{"atb":[[2.08,3.38]],"id":65710029}],"con":true,"img":false}]}
{"op":"mcm","clk":"11541468928","pt":1719506073513,"mc":[{"id":"1.230178327","rc":[{"atb":[[2.6,8.2]],"id":60748118},{"atb":[[2.22,8.7]],"id":68687941},{"atb":[[3,10.04]],"id":67674431},{"atb":[[2.08,12.13]],"id":65710029}],"con":true,"img":false}]}
{"op":"mcm","clk":"11541468948","pt":1719506073721,"mc":[{"id":"1.230178327","rc":[{"atb":[[2.58,1.94]],"id":60748118},{"atb":[[2.2,1.94]],"id":68687941},{"atb":[[2.98,3.94]],"id":67674431},{"atb":[[2.06,3.94]],"id":65710029}],"con":true,"img":false}]}
{"op":"mcm","clk":"11541468961","pt":1719506073822,"mc":[{"id":"1.230178327","rc":[{"atb":[[2.56,8.3]],"id":62600242}],"con":true,"img":false}]}
{"op":"mcm","clk":"11541468982","pt":1719506074028,"mc":[{"id":"1.230178327","rc":[{"atb":[[2.54,2]],"id":62600242}],"con":true,"img":false}]}
{"op":"mcm","clk":"11541469029","pt":1719506074444,"mc":[{"id":"1.230178327","rc":[{"atb":[[2.54,0]],"id":62600242}],"con":true,"img":false}]}
{"op":"mcm","clk":"11541469039","pt":1719506074549,"mc":[{"id":"1.230178327","rc":[{"atb":[[1.02,2]],"id":62600242}],"con":true,"img":false}]}
{"op":"mcm","clk":"11541469081","pt":1719506074919,"mc":[{"id":"1.230178327","rc":[{"atb":[[2.98,1.94]],"id":67674431}],"con":true,"img":false}]}
{"op":"mcm","clk":"11541469094","pt":1719506075021,"mc":[{"id":"1.230178327","rc":[{"atl":[[4.5,1]],"id":58221357},{"atl":[[4.8,0],[4.5,1]],"id":62600242},{"atl":[[4.8,1]],"id":60748118},{"atl":[[4.2,1]],"id":68687941},{"atb":[[3.05,2]],"id":67674431}],"con":true,"img":false}]}
{"op":"mcm","clk":"11541469108","pt":1719506075125,"mc":[{"id":"1.230178327","rc":[{"atl":[[4.8,0]],"id":58221357},{"atl":[[5.1,0]],"id":60748118},{"atl":[[4.3,9.2],[4.9,2.5]],"id":68687941}],"con":true,"img":false}]}
{"op":"mcm","clk":"11541469119","pt":1719506075230,"mc":[{"id":"1.230178327","rc":[{"atb":[[2.06,1.94]],"id":65710029}],"con":true,"img":false}]}
{"op":"mcm","clk":"11541469130","pt":1719506075331,"mc":[{"id":"1.230178327","rc":[{"atb":[[2.1,2]],"id":65710029}],"con":true,"img":false}]}
{"op":"mcm","clk":"11541469140","pt":1719506075433,"mc":[{"id":"1.230178327","rc":[{"atb":[[2.62,0]],"id":58221357},{"atb":[[2.58,0]],"id":60748118},{"atb":[[2.2,0]],"id":68687941},{"atb":[[2.98,0]],"id":67674431},{"atb":[[2.06,0]],"id":65710029}],"con":true,"img":false}]}
{"op":"mcm","clk":"11541469161","pt":1719506075640,"mc":[{"id":"1.230178327","rc":[{"atb":[[2.62,1.94]],"id":58221357},{"atb":[[2.62,1.94]],"id":60748118},{"atb":[[3.05,3.94]],"id":67674431},{"atb":[[2.1,3.94]],"id":65710029}],"con":true,"img":false}]}
{"op":"mcm","clk":"11541469291","pt":1719506076934,"mc":[{"id":"1.230178327","rc":[{"atl":[[3.7,9.68]],"id":65710029}],"con":true,"img":false}]}
{"op":"mcm","clk":"11541469298","pt":1719506077037,"mc":[{"id":"1.230178327","rc":[{"atl":[[4.1,1],[4.4,0],[3.65,9.69]],"id":65710029}],"con":true,"img":false}]}
{"op":"mcm","clk":"11541469311","pt":1719506077248,"mc":[{"id":"1.230178327","rc":[{"atl":[[3.65,0],[3.75,20.22]],"id":65710029}],"con":true,"img":false}]}
{"op":"mcm","clk":"11541469334","pt":1719506077455,"mc":[{"id":"1.230178327","rc":[{"atl":[[3.6,0.84]],"id":65710029}],"con":true,"img":false}]}
{"op":"mcm","clk":"11541469345","pt":1719506077507,"mc":[{"id":"1.230178327","rc":[{"atl":[[3.75,19.38]],"id":65710029}],"con":true,"img":false}]}
{"op":"mcm","clk":"11541469402","pt":1719506078026,"mc":[{"id":"1.230178327","rc":[{"atl":[[3.6,0]],"id":65710029}],"con":true,"img":false}]}
{"op":"mcm","clk":"11541469442","pt":1719506078130,"mc":[{"id":"1.230178327","rc":[{"atl":[[4.1,30.07],[3.75,0]],"id":65710029}],"con":true,"img":false}]}
{"op":"mcm","clk":"11541469484","pt":1719506078653,"mc":[{"id":"1.230178327","rc":[{"atb":[[2.62,0]],"id":58221357},{"atb":[[2.62,0]],"id":60748118}],"con":true,"img":false}]}
{"op":"mcm","clk":"11541469502","pt":1719506078815,"mc":[{"id":"1.230178327","rc":[{"atb":[[2.62,1.94]],"id":58221357},{"atb":[[2.62,1.94]],"id":60748118}],"con":true,"img":false}]}
{"op":"mcm","clk":"11541469740","pt":1719506081461,"mc":[{"id":"1.230178327","rc":[{"atb":[[2.6,2],[2.34,0]],"id":58221357},{"atl":[[5.8,0],[4.1,0.84],[5.4,0]],"id":58221357},{"atb":[[2.32,0],[2.6,3.16],[2.48,0],[2.4,0]],"id":60748118},{"atl":[[7.2,0],[4.5,0.84],[6.4,0],[5.8,0]],"id":60748118},{"atb":[[2.56,3],[2.28,0]],"id":62600242},{"atl":[[5,0],[4.1,0.84],[5.4,0]],"id":62600242},{"atb":[[1.98,0],[2.22,3],[2.04,0],[2.12,0]],"id":68687941},{"atl":[[4,0.84],[5.3,0],[4.9,0],[5.7,0]],"id":68687941},{"atb":[[3,3.3],[2.94,0],[2.86,0],[2.78,0]],"id":67674431},{"atl":[[9,0],[6.4,0.84],[8.2,0],[7.4,11.38]],"id":67674431},{"atb":[[1.98,0],[2.04,0],[1.94,0],[2.08,3.38]],"id":65710029},{"atl":[[4.6,0],[5,0],[3.7,0.52],[5.4,0]],"id":65710029}],"con":true,"img":false}]}
{"op":"mcm","clk":"11541469764","pt":1719506081725,"mc":[{"id":"1.230178327","rc":[{"atb":[[2.62,0]],"id":58221357},{"atb":[[2.62,0]],"id":60748118}],"con":true,"img":false}]}
{"op":"mcm","clk":"11541469776","pt":1719506081830,"mc":[{"id":"1.230178327","rc":[{"atb":[[2.62,1.94]],"id":58221357},{"atb":[[2.62,1.94]],"id":60748118}],"con":true,"img":false}]}
{"op":"mcm","clk":"11541469787","pt":1719506081933,"mc":[{"id":"1.230178327","rc":[{"atl":[[4.1,0]],"id":58221357},{"atl":[[4.5,0]],"id":60748118},{"atl":[[4.1,0]],"id":62600242},{"atl":[[4,0]],"id":68687941},{"atl":[[6.4,0]],"id":67674431}],"con":true,"img":false}]}
{"op":"mcm","clk":"11541469796","pt":1719506082037,"mc":[{"id":"1.230178327","rc":[{"atl":[[4.3,0],[4.5,4.28]],"id":58221357},{"atl":[[4.8,4.63]],"id":60748118},{"atl":[[4.3,0],[4.5,6.62]],"id":62600242},{"atl":[[4.3,0],[8.6,10.2]],"id":68687941},{"atl":[[7.4,0],[27,3.85]],"id":67674431}],"con":true,"img":false}]}
{"op":"mcm","clk":"11541469812","pt":1719506082142,"mc":[{"id":"1.230178327","rc":[{"atl":[[4.7,0]],"id":60748118}],"con":true,"img":false}]}
{"op":"mcm","clk":"11541469833","pt":1719506082348,"mc":[{"id":"1.230178327","rc":[{"atb":[[2.58,0]],"id":58221357},{"atl":[[4.2,0]],"id":58221357},{"atb":[[2.6,2.99]],"id":60748118},{"atl":[[4.6,0]],"id":60748118},{"atb":[[2.52,0]],"id":62600242},{"atl":[[4.2,0]],"id":62600242}],"con":true,"img":false}]}
{"op":"mcm","clk":"11541469844","pt":1719506082451,"mc":[{"id":"1.230178327","rc":[{"atl":[[4.5,1],[10.5,8.56],[4.4,0.84]],"id":58221357},{"atl":[[4.5,1],[10.5,10.53],[4.4,0.84]],"id":62600242},{"atl":[[4.8,1],[4.6,0.84],[13.5,8]],"id":60748118}],"con":true,"img":false}]}
{"op":"mcm","clk":"11541469886","pt":1719506082818,"mc":[{"id":"1.230178327","rc":[{"atb":[[2.6,0]],"id":58221357}],"con":true,"img":false}]}
{"op":"mcm","clk":"11541469895","pt":1719506082921,"mc":[{"id":"1.230178327","rc":[{"atb":[[2.32,2]],"id":58221357}],"con":true,"img":false}]}
{"op":"mcm","clk":"11541469902","pt":1719506083024,"mc":[{"id":"1.230178327","rc":[{"atl":[[4.8,1]],"id":58221357},{"atl":[[4.8,1]],"id":62600242},{"atl":[[5.1,1],[4.6,0]],"id":60748118},{"atl":[[4.3,1],[4.2,0]],"id":68687941}],"con":true,"img":false}]}
{"op":"mcm","clk":"11541469911","pt":1719506083126,"mc":[{"id":"1.230178327","rc":[{"atl":[[4.5,0]],"id":58221357},{"atl":[[4.8,0]],"id":60748118},{"atl":[[4.5,0]],"id":62600242}],"con":true,"img":false}]}
{"op":"mcm","clk":"11541469931","pt":1719506083337,"mc":[{"id":"1.230178327","rc":[{"atl":[[4.6,27.78],[4.1,1]],"id":65710029}],"con":true,"img":false}]}
{"op":"mcm","clk":"11541469998","pt":1719506083955,"mc":[{"id":"1.230178327","rc":[{"atl":[[4.4,0]],"id":58221357},{"atl":[[4.4,0]],"id":62600242}],"con":true,"img":false}]}
{"op":"mcm","clk":"11541470070","pt":1719506084629,"mc":[{"id":"1.230178327","rc":[{"atb":[[2.62,0]],"id":58221357},{"atb":[[2.62,0]],"id":60748118}],"con":true,"img":false}]}
{"op":"mcm","clk":"11541470080","pt":1719506084733,"mc":[{"id":"1.230178327","rc":[{"atb":[[2.32,3.94]],"id":58221357},{"atb":[[2.62,1.94]],"id":60748118}],"con":true,"img":false}]}
{"op":"mcm","clk":"11541470239","pt":1719506086339,"mc":[{"id":"1.230178327","rc":[{"atb":[[2.82,7.9],[2.92,0]],"id":67674431}],"con":true,"img":false}]}
{"op":"mcm","clk":"11541470308","pt":1719506087015,"mc":[{"id":"1.230178327","rc":[{"atl":[[3.7,0]],"id":65710029}],"con":true,"img":false}]}
{"op":"mcm","clk":"11541470338","pt":1719506087328,"mc":[{"id":"1.230178327","rc":[{"atb":[[2.08,2.9]],"id":65710029}],"con":true,"img":false}]}
{"op":"mcm","clk":"11541470352","pt":1719506087431,"mc":[{"id":"1.230178327","rc":[{"atb":[[2.6,0]],"id":60748118},{"atb":[[2.56,0]],"id":62600242},{"atl":[[4.7,10.9]],"id":65710029}],"con":true,"img":false}]}
{"op":"mcm","clk":"11541470366","pt":1719506087535,"mc":[{"id":"1.230178327","rc":[{"atb":[[2.34,3.4]],"id":58221357},{"atb":[[2.56,2.07]],"id":60748118},{"atb":[[2.34,2]],"id":62600242}],"con":true,"img":false}]}
{"op":"mcm","clk":"11541470394","pt":1719506087740,"mc":[{"id":"1.230178327","rc":[{"atb":[[2.62,0]],"id":60748118}],"con":true,"img":false}]}
{"op":"mcm","clk":"11541470404","pt":1719506087844,"mc":[{"id":"1.230178327","rc":[{"atb":[[2.62,1.94]],"id":60748118}],"con":true,"img":false}]}
{"op":"mcm","clk":"11541470515","pt":1719506088931,"mc":[{"id":"1.230178327","rc":[{"atb":[[2.32,1.94]],"id":58221357}],"con":true,"img":false}]}
{"op":"mcm","clk":"11541470524","pt":1719506089034,"mc":[{"id":"1.230178327","rc":[{"atb":[[2.36,2]],"id":58221357}],"con":true,"img":false}]}
{"op":"mcm","clk":"11541470549","pt":1719506089342,"mc":[{"id":"1.230178327","rc":[{"atb":[[1.02,0]],"id":62600242}],"con":true,"img":false}]}
{"op":"mcm","clk":"11541470557","pt":1719506089447,"mc":[{"id":"1.230178327","rc":[{"atb":[[2.36,2]],"id":62600242}],"con":true,"img":false}]}
{"op":"mcm","clk":"11541470685","pt":1719506090739,"mc":[{"id":"1.230178327","rc":[{"atb":[[2.32,0]],"id":58221357},{"atb":[[2.62,0]],"id":60748118}],"con":true,"img":false}]}
{"op":"mcm","clk":"11541470706","pt":1719506090948,"mc":[{"id":"1.230178327","rc":[{"atb":[[2.36,3.94]],"id":58221357},{"atb":[[2.58,1.94]],"id":60748118},{"atb":[[2.34,3.94]],"id":62600242}],"con":true,"img":false}]}
{"op":"mcm","clk":"11541470954","pt":1719506093847,"mc":[{"id":"1.230178327","rc":[{"atb":[[2.58,0]],"id":60748118}],"con":true,"img":false}]}
{"op":"mcm","clk":"11541470964","pt":1719506093950,"mc":[{"id":"1.230178327","rc":[{"atb":[[1.93,6.37]],"id":65710029}],"con":true,"img":false}]}
{"op":"mcm","clk":"11541470975","pt":1719506094052,"mc":[{"id":"1.230178327","rc":[{"atb":[[2.58,1.94]],"id":60748118}],"con":true,"img":false}]}
{"op":"mcm","clk":"11541471218","pt":1719506096848,"mc":[{"id":"1.230178327","rc":[{"atb":[[2.58,0]],"id":60748118}],"con":true,"img":false}]}
{"op":"mcm","clk":"11541471236","pt":1719506097047,"mc":[{"id":"1.230178327","rc":[{"atb":[[2.58,1.94]],"id":60748118}],"con":true,"img":false}]}
{"op":"mcm","clk":"11541471370","pt":1719506098748,"mc":[{"id":"1.230178327","rc":[{"atl":[[4,0.52]],"id":65710029}],"con":true,"img":false}]}
{"op":"mcm","clk":"11541471383","pt":1719506098949,"mc":[{"id":"1.230178327","rc":[{"atb":[[1.03,0.52]],"id":65710029}],"con":true,"img":false}]}
{"op":"mcm","clk":"11541471389","pt":1719506099052,"mc":[{"id":"1.230178327","rc":[{"atb":[[1.03,0.46]],"id":65710029}],"con":true,"img":false}]}
{"op":"mcm","clk":"11541471399","pt":1719506099257,"mc":[{"id":"1.230178327","rc":[{"atb":[[1.03,0]],"id":65710029}],"con":true,"img":false}]}
{"op":"mcm","clk":"11541471404","pt":1719506099312,"mc":[{"id":"1.230178327","rc":[{"atb":[[2.12,0.46]],"id":65710029}],"con":true,"img":false}]}
{"op":"mcm","clk":"11541471444","pt":1719506099828,"mc":[{"id":"1.230178327","rc":[{"atb":[[2.58,0]],"id":60748118}],"con":true,"img":false}]}
{"op":"mcm","clk":"11541471461","pt":1719506100033,"mc":[{"id":"1.230178327","rc":[{"atb":[[2.58,1.94]],"id":60748118}],"con":true,"img":false}]}
{"op":"mcm","clk":"11541471474","pt":1719506100140,"mc":[{"id":"1.230178327","rc":[{"atl":[[3.95,1]],"id":65710029}],"con":true,"img":false}]}
{"op":"mcm","clk":"11541471484","pt":1719506100243,"mc":[{"id":"1.230178327","rc":[{"atl":[[4.6,0],[4.1,11.9]],"id":65710029}],"con":true,"img":false}]}
{"op":"mcm","clk":"11541471648","pt":1719506101924,"mc":[{"id":"1.230178327","rc":[{"atb":[[2.34,0]],"id":58221357},{"atb":[[2.34,1.94]],"id":62600242}],"con":true,"img":false}]}
{"op":"mcm","clk":"11541471672","pt":1719506102125,"mc":[{"id":"1.230178327","rc":[{"atb":[[2.36,4]],"id":62600242}],"con":true,"img":false}]}
{"op":"mcm","clk":"11541471725","pt":1719506102747,"mc":[{"id":"1.230178327","rc":[{"atb":[[2.36,1.94]],"id":58221357}],"con":true,"img":false}]}
{"op":"mcm","clk":"11541471736","pt":1719506102849,"mc":[{"id":"1.230178327","rc":[{"atb":[[2.32,2]],"id":58221357},{"atb":[[2.34,0]],"id":62600242},{"atb":[[2.58,0]],"id":60748118}],"con":true,"img":false}]}
{"op":"mcm","clk":"11541471754","pt":1719506103056,"mc":[{"id":"1.230178327","rc":[{"atb":[[2.38,1.94]],"id":62600242},{"atb":[[2.58,1.94]],"id":60748118}],"con":true,"img":false}]}
{"op":"mcm","clk":"11541472042","pt":1719506105861,"mc":[{"id":"1.230178327","rc":[{"atb":[[2.36,0]],"id":58221357},{"atb":[[2.58,0]],"id":60748118},{"atb":[[2.38,0]],"id":62600242}],"con":true,"img":false}]}
{"op":"mcm","clk":"11541472052","pt":1719506105965,"mc":[{"id":"1.230178327","rc":[{"atb":[[2.32,3.94]],"id":58221357},{"atb":[[2.58,1.94]],"id":60748118},{"atb":[[2.38,1.94]],"id":62600242}],"con":true,"img":false}]}
{"op":"mcm","clk":"11541472381","pt":1719506108564,"mc":[{"id":"1.230178327","rc":[{"atb":[[2.06,4.88]],"id":65710029}],"con":true,"img":false}]}
{"op":"mcm","clk":"11541472411","pt":1719506108877,"mc":[{"id":"1.230178327","rc":[{"atb":[[2.38,0]],"id":62600242},{"atb":[[2.58,0]],"id":60748118}],"con":true,"img":false}]}
{"op":"mcm","clk":"11541472431","pt":1719506109083,"mc":[{"id":"1.230178327","rc":[{"atb":[[2.38,1.94],[2.14,4.39]],"id":62600242},{"atb":[[2.58,1.94]],"id":60748118}],"con":true,"img":false}]}
{"op":"mcm","clk":"11541472715","pt":1719506111949,"mc":[{"id":"1.230178327","rc":[{"atb":[[2.38,0]],"id":62600242},{"atb":[[2.58,0]],"id":60748118}],"con":true,"img":false}]}
{"op":"mcm","clk":"11541472733","pt":1719506112155,"mc":[{"id":"1.230178327","rc":[{"atb":[[2.58,1.94]],"id":60748118},{"atb":[[2.38,1.94]],"id":62600242}],"con":true,"img":false}]}
{"op":"mcm","clk":"11541472807","pt":1719506112884,"mc":[{"id":"1.230178327","rc":[{"atb":[[2,5.06]],"id":68687941}],"con":true,"img":false}]}
{"op":"mcm","clk":"11541472866","pt":1719506113358,"mc":[{"id":"1.230178327","rc":[{"atb":[[2.04,7.9],[2.14,0]],"id":58221357},{"atb":[[2.3,0],[2.16,4.19]],"id":60748118},{"atb":[[2.02,8],[2.16,0],[2.14,0]],"id":62600242},{"atb":[[2,0],[2.02,0],[1.93,8.06]],"id":68687941},{"atb":[[2.82,0],[2.68,7.9]],"id":67674431},{"atb":[[1.88,0],[1.77,7.9]],"id":65710029}],"con":true,"img":false}]}
{"op":"mcm","clk":"11541472949","pt":1719506114086,"mc":[{"id":"1.230178327","rc":[{"atl":[[4,0]],"id":65710029}],"con":true,"img":false}]}
{"op":"mcm","clk":"11541472976","pt":1719506114243,"mc":[{"id":"1.230178327","rc":[{"atl":[[4.6,12.9],[3.95,0],[4.1,1]],"id":65710029}],"con":true,"img":false}]}
{"op":"mcm","clk":"11541473027","pt":1719506114761,"mc":[{"id":"1.230178327","rc":[{"atb":[[2.12,0]],"id":65710029}],"con":true,"img":false}]}
{"op":"mcm","clk":"11541473052","pt":1719506114971,"mc":[{"id":"1.230178327","rc":[{"atb":[[2.38,0]],"id":62600242},{"atb":[[2.58,0]],"id":60748118}],"con":true,"img":false}]}
{"op":"mcm","clk":"11541473072","pt":1719506115176,"mc":[{"id":"1.230178327","rc":[{"atb":[[2.58,1.94]],"id":60748118},{"atb":[[2.38,1.94]],"id":62600242},{"atb":[[2.24,1.94]],"id":68687941}],"con":true,"img":false}]}
{"op":"mcm","clk":"11541473165","pt":1719506116054,"mc":[{"id":"1.230178327","rc":[{"atb":[[2.36,2]],"id":62600242},{"atb":[[3,0]],"id":67674431},{"atb":[[2.08,0]],"id":65710029}],"con":true,"img":false}]}
{"op":"mcm","clk":"11541473175","pt":1719506116179,"mc":[{"id":"1.230178327","rc":[{"atb":[[2.34,2.93]],"id":58221357},{"atb":[[2.38,4.94]],"id":62600242},{"atb":[[3.1,2.23]],"id":67674431},{"atb":[[2.12,2.1]],"id":65710029}],"con":true,"img":false}]}
{"op":"mcm","clk":"11541473185","pt":1719506116282,"mc":[{"id":"1.230178327","rc":[{"atl":[[4,1]],"id":65710029}],"con":true,"img":false}]}
{"op":"mcm","clk":"11541473220","pt":1719506116539,"mc":[{"id":"1.230178327","rc":[{"atb":[[2.32,1.94]],"id":58221357}],"con":true,"img":false}]}
{"op":"mcm","clk":"11541473229","pt":1719506116645,"mc":[{"id":"1.230178327","rc":[{"atb":[[2.36,2]],"id":58221357}],"con":true,"img":false}]}
{"op":"mcm","clk":"11541473265","pt":1719506117058,"mc":[{"id":"1.230178327","rc":[{"atb":[[2.36,0]],"id":62600242}],"con":true,"img":false}]}
{"op":"mcm","clk":"11541473278","pt":1719506117165,"mc":[{"id":"1.230178327","rc":[{"atb":[[2.4,2]],"id":62600242}],"con":true,"img":false}]}
{"op":"mcm","clk":"11541473313","pt":1719506117576,"mc":[{"id":"1.230178327","rc":[{"atb":[[3.05,1.94]],"id":67674431}],"con":true,"img":false}]}
{"op":"mcm","clk":"11541473323","pt":1719506117678,"mc":[{"id":"1.230178327","rc":[{"atb":[[3.15,2]],"id":67674431}],"con":true,"img":false}]}
{"op":"mcm","clk":"11541473362","pt":1719506118040,"mc":[{"id":"1.230178327","rc":[{"atb":[[2.1,1.94]],"id":65710029}],"con":true,"img":false}]}
{"op":"mcm","clk":"11541473370","pt":1719506118146,"mc":[{"id":"1.230178327","rc":[{"atb":[[2.14,2]],"id":65710029}],"con":true,"img":false}]}
{"op":"mcm","clk":"11541473633","pt":1719506120691,"mc":[{"id":"1.230178327","rc":[{"atb":[[2.36,4.96],[2.32,4.44],[2.04,0],[2.1,4.12]],"id":58221357},{"atl":[[4.8,0],[4.6,1],[5,2.5],[5.8,10],[4.7,2.96],[5.4,5]],"id":58221357},{"spn":3.48,"spf":"NaN","id":58221357},{"atb":[[2.22,2.5],[2.14,5],[2.1,4.24],[2.4,5.09],[2.02,0],[2.06,10]],"id":62600242},{"atl":[[5.3,5],[4.9,2.5],[5.7,10],[4.7,3.09]],"id":62600242},{"spn":3.55,"spf":"NaN","id":62600242},{"atb":[[2.58,4.95],[2.26,4.14],[2.36,2.5],[2.28,5],[2.2,10],[2.16,0]],"id":60748118},{"atl":[[7.2,10],[6.4,5],[5,3.01],[5.8,2.5]],"id":60748118},{"spn":3.79,"spf":"NaN","id":60748118},{"atb":[[1.93,0],[2.14,2.5],[2.24,4.99],[1.99,10],[2.02,8.06],[2.06,5]],"id":68687941},{"atl":[[5,2.5],[5.8,10],[4.2,3.05],[5.4,5]],"id":68687941},{"spn":2.23,"spf":1.0,"id":68687941},{"atb":[[2.82,4],[2.94,5],[3.05,4.44],[2.86,10],[3.15,4.96],[2.68,0]],"id":67674431},{"atl":[[8,2.5],[9.6,10],[6.8,2.96],[8.8,5]],"id":67674431},{"spn":4.97,"spf":"NaN","id":67674431},{"atb":[[1.83,7.9],[1.77,0],[2.14,4.96]],"id":65710029},{"atl":[[4.6,15.4],[3.95,2.96]],"id":65710029},{"spn":3.04,"spf":"NaN","id":65710029}],"con":true,"img":false}]}
{"op":"mcm","clk":"11541473647","pt":1719506120744,"mc":[{"id":"1.230178327","rc":[{"atl":[[10.5,0],[4.7,5.92]],"id":58221357},{"atl":[[4.6,2.5]],"id":62600242},{"atl":[[4.9,2.5],[13.5,0]],"id":60748118},{"atl":[[8.6,0],[4.1,2.5]],"id":68687941},{"atl":[[7.4,5],[27,0]],"id":67674431},{"atl":[[4,0],[4.6,2.5],[3.95,4.96]],"id":65710029}],"con":true,"img":false}]}
{"op":"mcm","clk":"11541473660","pt":1719506120850,"mc":[{"id":"1.230178327","rc":[{"atl":[[4.6,3.5],[10.5,0]],"id":62600242},{"atl":[[4.3,0],[4.5,1]],"id":68687941}],"con":true,"img":false}]}
{"op":"mcm","clk":"11541473671","pt":1719506120951,"mc":[{"id":"1.230178327","rc":[{"atb":[[2.32,2.5]],"id":58221357},{"atb":[[2.38,3]],"id":62600242},{"atl":[[4.8,0]],"id":62600242},{"atb":[[3.05,2.5]],"id":67674431},{"atb":[[2.1,0]],"id":65710029}],"con":true,"img":false}]}
{"op":"mcm","clk":"11541473680","pt":1719506121052,"mc":[{"id":"1.230178327","rc":[{"atb":[[2.38,1.94]],"id":58221357},{"atb":[[2.42,1.94]],"id":62600242},{"atb":[[3.2,1.94]],"id":67674431},{"atb":[[2.16,1.94]],"id":65710029}],"con":true,"img":false}]}
{"op":"mcm","clk":"11541473690","pt":1719506121159,"mc":[{"id":"1.230178327","rc":[{"atl":[[5.2,1.68]],"id":58221357}],"con":true,"img":false}]}
{"op":"mcm","clk":"11541473707","pt":1719506121368,"mc":[{"id":"1.230178327","rc":[{"atl":[[5.2,0]],"id":58221357},{"atl":[[4.8,1],[4.6,2.5]],"id":62600242},{"atl":[[4.5,0],[4.3,1]],"id":68687941},{"atb":[[2.06,0]],"id":65710029}],"con":true,"img":false}]}
{"op":"mcm","clk":"11541473718","pt":1719506121467,"mc":[{"id":"1.230178327","rc":[{"atl":[[4.8,1],[4.6,0]],"id":58221357},{"atl":[[4.5,0.84]],"id":62600242},{"atl":[[4.8,0.84]],"id":60748118},{"atl":[[4,0.84]],"id":68687941},{"atl":[[6.6,0.84]],"id":67674431},{"atl":[[3.9,0.84]],"id":65710029}],"con":true,"img":false}]}
{"op":"mcm","clk":"11541473745","pt":1719506121781,"mc":[{"id":"1.230178327","rc":[{"atl":[[5,11.06]],"id":58221357}],"con":true,"img":false}]}
{"op":"mcm","clk":"11541473764","pt":1719506121989,"mc":[{"id":"1.230178327","rc":[{"atl":[[4.6,0.84]],"id":58221357}],"con":true,"img":false}]}
{"op":"mcm","clk":"11541473774","pt":1719506122090,"mc":[{"id":"1.230178327","rc":[{"atl":[[5,2.5]],"id":58221357}],"con":true,"img":false}]}
{"op":"mcm","clk":"11541473805","pt":1719506122351,"mc":[{"id":"1.230178327","rc":[{"atl":[[4.9,1.84]],"id":58221357}],"con":true,"img":false}]}
{"op":"mcm","clk":"11541473840","pt":1719506122663,"mc":[{"id":"1.230178327","rc":[{"atl":[[4.9,0]],"id":58221357}],"con":true,"img":false}]}
{"op":"mcm","clk":"11541473848","pt":1719506122768,"mc":[{"id":"1.230178327","rc":[{"atl":[[3.85,1]],"id":65710029}],"con":true,"img":false}]}
{"op":"mcm","clk":"11541473866","pt":1719506122975,"mc":[{"id":"1.230178327","rc":[{"atl":[[4.8,4.72]],"id":58221357}],"con":true,"img":false}]}
{"op":"mcm","clk":"11541473972","pt":1719506124066,"mc":[{"id":"1.230178327","rc":[{"atb":[[2.38,0]],"id":58221357},{"atb":[[2.42,0]],"id":62600242},{"atb":[[3.2,0]],"id":67674431},{"atb":[[2.16,0]],"id":65710029}],"con":true,"img":false}]}
{"op":"mcm","clk":"11541473994","pt":1719506124168,"mc":[{"id":"1.230178327","rc":[{"atb":[[2.38,1.94]],"id":58221357},{"atl":[[4.8,1]],"id":58221357},{"atb":[[2.42,1.94]],"id":62600242},{"atb":[[3.2,1.94]],"id":67674431},{"atb":[[1.96,2.5],[2.16,1.94]],"id":65710029}],"con":true,"img":false}]}
{"op":"mcm","clk":"11541474026","pt":1719506124377,"mc":[{"id":"1.230178327","rc":[{"atl":[[4.7,7.4]],"id":58221357}],"con":true,"img":false}]}
{"op":"mcm","clk":"11541474059","pt":1719506124690,"mc":[{"id":"1.230178327","rc":[{"atb":[[2.34,0]],"id":58221357},{"atl":[[4.7,5.92]],"id":58221357},{"atb":[[2.38,0]],"id":62600242},{"atb":[[2.56,0]],"id":60748118},{"atb":[[2.22,0]],"id":68687941},{"atb":[[3.1,0]],"id":67674431},{"atb":[[2.12,0]],"id":65710029}],"con":true,"img":false}]}
{"op":"mcm","clk":"11541474082","pt":1719506124848,"mc":[{"id":"1.230178327","rc":[{"atb":[[2.6,2]],"id":60748118},{"atb":[[2.42,4.04]],"id":62600242},{"atb":[[2.26,2]],"id":68687941},{"atb":[[3.2,4.12]],"id":67674431}],"con":true,"img":false}]}
{"op":"mcm","clk":"11541474096","pt":1719506124950,"mc":[{"id":"1.230178327","rc":[{"atl":[[4.8,6.38]],"id":58221357}],"con":true,"img":false}]}
{"op":"mcm","clk":"11541474106","pt":1719506125051,"mc":[{"id":"1.230178327","rc":[{"atl":[[3.8,0.52]],"id":65710029}],"con":true,"img":false}]}
{"op":"mcm","clk":"11541474120","pt":1719506125154,"mc":[{"id":"1.230178327","rc":[{"atb":[[1.03,0.52]],"id":65710029},{"atl":[[3.85,0]],"id":65710029}],"con":true,"img":false}]}
{"op":"mcm","clk":"11541474140","pt":1719506125360,"mc":[{"id":"1.230178327","rc":[{"atb":[[1.03,0.44]],"id":65710029}],"con":true,"img":false}]}
{"op":"mcm","clk":"11541474159","pt":1719506125566,"mc":[{"id":"1.230178327","rc":[{"atb":[[1.03,0]],"id":65710029}],"con":true,"img":false}]}
{"op":"mcm","clk":"11541474172","pt":1719506125671,"mc":[{"id":"1.230178327","rc":[{"atb":[[2.18,0.44]],"id":65710029}],"con":true,"img":false}]}
{"op":"mcm","clk":"11541474183","pt":1719506125778,"mc":[{"id":"1.230178327","rc":[{"atb":[[2.12,4.87]],"id":58221357},{"atb":[[2.38,3.62]],"id":60748118}],"con":true,"img":false}]}
{"op":"mcm","clk":"11541474195","pt":1719506125877,"mc":[{"id":"1.230178327","rc":[{"atl":[[5,6.36]],"id":60748118},{"atl":[[4.6,0],[4.7,6.44]],"id":62600242},{"atl":[[4.2,6.4]],"id":68687941}],"con":true,"img":false}]}
{"op":"mcm","clk":"11541474204","pt":1719506125981,"mc":[{"id":"1.230178327","rc":[{"atl":[[4.9,0]],"id":60748118},{"atl":[[4.1,0]],"id":68687941}],"con":true,"img":false}]}
{"op":"mcm","clk":"11541474213","pt":1719506126085,"mc":[{"id":"1.230178327","rc":[{"atl":[[4.8,8.29],[4.7,3.09]],"id":62600242}],"con":true,"img":false}]}
{"op":"mcm","clk":"11541474225","pt":1719506126191,"mc":[{"id":"1.230178327","rc":[{"atb":[[2.4,3.09]],"id":62600242},{"atl":[[5.1,8.21],[5,3.01]],"id":60748118},{"atl":[[4.3,8.25],[4.2,3.05]],"id":68687941}],"con":true,"img":false}]}
{"op":"mcm","clk":"11541474238","pt":1719506126248,"mc":[{"id":"1.230178327","rc":[{"atb":[[2.44,2]],"id":62600242}],"con":true,"img":false}]}
{"op":"mcm","clk":"11541474248","pt":1719506126350,"mc":[{"id":"1.230178327","rc":[{"atl":[[4.5,0]],"id":62600242},{"atl":[[4.8,0]],"id":60748118},{"atl":[[4,0]],"id":68687941}],"con":true,"img":false}]}
{"op":"mcm","clk":"11541474261","pt":1719506126453,"mc":[{"id":"1.230178327","rc":[{"atl":[[5.1,1],[5.8,13.72]],"id":60748118},{"atl":[[4.8,1],[4.9,13.88]],"id":62600242},{"atl":[[4.3,1],[5,13.8]],"id":68687941}],"con":true,"img":false}]}
{"op":"mcm","clk":"11541474271","pt":1719506126556,"mc":[{"id":"1.230178327","rc":[{"atb":[[3.15,2.96]],"id":67674431}],"con":true,"img":false}]}
{"op":"mcm","clk":"11541474282","pt":1719506126659,"mc":[{"id":"1.230178327","rc":[{"atb":[[3.25,2]],"id":67674431}],"con":true,"img":false}]}
{"op":"mcm","clk":"11541474313","pt":1719506126972,"mc":[{"id":"1.230178327","rc":[{"atb":[[2.38,0]],"id":58221357}],"con":true,"img":false}]}
{"op":"mcm","clk":"11541474336","pt":1719506127178,"mc":[{"id":"1.230178327","rc":[{"atb":[[2.38,1.94]],"id":58221357},{"atb":[[2.14,2.96]],"id":65710029}],"con":true,"img":false}]}
{"op":"mcm","clk":"11541474346","pt":1719506127280,"mc":[{"id":"1.230178327","rc":[{"atb":[[2.18,2.44]],"id":65710029},{"atl":[[3.75,1]],"id":65710029}],"con":true,"img":false}]}
{"op":"mcm","clk":"11541474353","pt":1719506127383,"mc":[{"id":"1.230178327","rc":[{"atb":[[3.25,12.03]],"id":67674431},{"atl":[[6.6,4.99]],"id":67674431}],"con":true,"img":false}]}
{"op":"mcm","clk":"11541474402","pt":1719506127954,"mc":[{"id":"1.230178327","rc":[{"atl":[[4.8,5.38],[4.6,1.84]],"id":58221357},{"atl":[[4.8,0],[4.6,1]],"id":62600242},{"atl":[[4.3,0],[4.5,1]],"id":68687941}],"con":true,"img":false}]}
{"op":"mcm","clk":"11541474441","pt":1719506128469,"mc":[{"id":"1.230178327","rc":[{"atb":[[2.12,0]],"id":58221357},{"atl":[[4.9,0.84]],"id":60748118},{"atl":[[4.1,0.84]],"id":68687941},{"atb":[[2.18,0.44]],"id":65710029}],"con":true,"img":false}]}
{"op":"mcm","clk":"11541474453","pt":1719506128573,"mc":[{"id":"1.230178327","rc":[{"atb":[[2.16,3.94]],"id":65710029}],"con":true,"img":false}]}
{"op":"mcm","clk":"11541474538","pt":1719506129558,"mc":[{"id":"1.230178327","rc":[{"atb":[[2.38,0]],"id":60748118},{"atb":[[2.06,13.06]],"id":68687941},{"atb":[[2.82,0],[2.9,8.26]],"id":67674431}],"con":true,"img":false}]}
{"op":"mcm","clk":"11541474547","pt":1719506129659,"mc":[{"id":"1.230178327","rc":[{"atb":[[2.02,0]],"id":68687941}],"con":true,"img":false}]}
{"op":"mcm","clk":"11541474578","pt":1719506130070,"mc":[{"id":"1.230178327","rc":[{"atb":[[2.38,0]],"id":58221357},{"atb":[[3.2,2.18]],"id":67674431}],"con":true,"img":false}]}
{"op":"mcm","clk":"11541474595","pt":1719506130278,"mc":[{"id":"1.230178327","rc":[{"atb":[[2.38,1.94]],"id":58221357},{"atb":[[3.3,1.94]],"id":67674431}],"con":true,"img":false}]}
{"op":"mcm","clk":"11541474629","pt":1719506130690,"mc":[{"id":"1.230178327","rc":[{"atb":[[3.25,11.11]],"id":67674431}],"con":true,"img":false}]}
{"op":"mcm","clk":"11541474662","pt":1719506130979,"mc":[{"id":"1.230178327","rc":[{"atl":[[4.8,6.38],[4.6,0.84]],"id":58221357},{"atl":[[4.5,0],[4.3,1]],"id":68687941}],"con":true,"img":false}]}
{"op":"mcm","clk":"11541474675","pt":1719506131070,"mc":[{"id":"1.230178327","rc":[{"atl":[[4.8,1]],"id":62600242}],"con":true,"img":false}]}
{"op":"mcm","clk":"11541474687","pt":1719506131173,"mc":[{"id":"1.230178327","rc":[{"atl":[[4.6,0]],"id":62600242},{"atb":[[3.25,2]],"id":67674431}],"con":true,"img":false}]}
{"op":"mcm","clk":"11541474701","pt":1719506131284,"mc":[{"id":"1.230178327","rc":[{"atb":[[3.3,11.05]],"id":67674431}],"con":true,"img":false}]}
{"op":"mcm","clk":"11541474762","pt":1719506131753,"mc":[{"id":"1.230178327","rc":[{"atb":[[3.25,0]],"id":67674431}],"con":true,"img":false}]}
{"op":"mcm","clk":"11541474769","pt":1719506131857,"mc":[{"id":"1.230178327","rc":[{"atb":[[3.35,2]],"id":67674431}],"con":true,"img":false}]}
{"op":"mcm","clk":"11541474781","pt":1719506131964,"mc":[{"id":"1.230178327","rc":[{"atl":[[4.6,0.84]],"id":62600242},{"atb":[[2.82,10],[2.9,0]],"id":67674431}],"con":true,"img":false}]}
{"op":"mcm","clk":"11541474802","pt":1719506132172,"mc":[{"id":"1.230178327","rc":[{"atl":[[5.1,6],[5.8,2.5]],"id":60748118},{"atl":[[4.3,6],[5,2.5]],"id":68687941},{"atb":[[3.3,10.94]],"id":67674431}],"con":true,"img":false}]}
{"op":"mcm","clk":"11541474830","pt":1719506132487,"mc":[{"id":"1.230178327","rc":[{"atb":[[3.3,1.94]],"id":67674431}],"con":true,"img":false}]}
{"op":"mcm","clk":"11541474840","pt":1719506132591,"mc":[{"id":"1.230178327","rc":[{"atb":[[3.35,11]],"id":67674431}],"con":true,"img":false}]}
{"op":"mcm","clk":"11541474892","pt":1719506133004,"mc":[{"id":"1.230178327","rc":[{"atb":[[2.38,7.54]],"id":58221357},{"atl":[[4.6,6.44]],"id":58221357},{"atb":[[2.6,5.85]],"id":60748118},{"atl":[[4.9,4.69]],"id":60748118},{"atb":[[2.44,5.82]],"id":62600242},{"atl":[[4.6,4.66]],"id":62600242},{"atb":[[2.26,5.88]],"id":68687941},{"atl":[[4.1,4.72]],"id":68687941},{"atb":[[3.4,3.86]],"id":67674431},{"atl":[[6.4,3.86]],"id":67674431},{"atb":[[2.16,5.33]],"id":65710029},{"atl":[[3.7,1.39]],"id":65710029}],"con":true,"img":false}]}
{"op":"mcm","clk":"11541474909","pt":1719506133060,"mc":[{"id":"1.230178327","rc":[{"atb":[[2.38,5.6]],"id":58221357},{"atl":[[4.7,2.96]],"id":58221357},{"atl":[[4.7,0]],"id":62600242},{"atb":[[2.58,1.94]],"id":60748118},{"atl":[[5,0]],"id":60748118},{"atb":[[2.24,1.94]],"id":68687941},{"atb":[[3.3,0],[3.15,0]],"id":67674431},{"atl":[[6.8,0]],"id":67674431},{"atb":[[2.14,0]],"id":65710029},{"atl":[[3.95,0],[3.8,2.52]],"id":65710029}],"con":true,"img":false}]}
{"op":"mcm","clk":"11541474920","pt":1719506133163,"mc":[{"id":"1.230178327","rc":[{"atb":[[2.36,2],[2.38,7.54]],"id":58221357},{"atb":[[2.4,0]],"id":62600242},{"atl":[[4.2,0]],"id":68687941},{"atb":[[3.4,5.8]],"id":67674431},{"atb":[[2.08,2.99]],"id":65710029},{"atl":[[3.75,0]],"id":65710029}],"con":true,"img":false}]}
{"op":"mcm","clk":"11541474970","pt":1719506133267,"mc":[{"id":"1.230178327","rc":[{"atb":[[2.36,0]],"id":58221357},{"atl":[[5.1,1],[5.8,13.2]],"id":60748118},{"atl":[[3.7,0]],"id":65710029}],"con":true,"img":false}]}
{"op":"mcm","clk":"11541474980","pt":1719506133371,"mc":[{"id":"1.230178327","rc":[{"atb":[[2.4,2]],"id":58221357},{"atl":[[3.75,2.54]],"id":65710029}],"con":true,"img":false}]}
{"op":"mcm","clk":"11541474993","pt":1719506133474,"mc":[{"id":"1.230178327","rc":[{"atl":[[6.2,0.84]],"id":67674431},{"atl":[[3.9,0]],"id":65710029}],"con":true,"img":false}]}
{"op":"mcm","clk":"11541475018","pt":1719506133685,"mc":[{"id":"1.230178327","rc":[{"atb":[[2.42,1.94],[2.22,6.61]],"id":62600242},{"atb":[[3.35,0],[3.2,0]],"id":67674431},{"atl":[[6.6,4.65]],"id":67674431}],"con":true,"img":false}]}
{"op":"mcm","clk":"11541475028","pt":1719506133786,"mc":[{"id":"1.230178327","rc":[{"atb":[[2.46,2.85]],"id":62600242},{"atb":[[3.45,4.4]],"id":67674431}],"con":true,"img":false}]}
{"op":"mcm","clk":"11541475040","pt":1719506133889,"mc":[{"id":"1.230178327","rc":[{"atl":[[6.6,0.84]],"id":67674431}],"con":true,"img":false}]}
{"op":"mcm","clk":"11541475053","pt":1719506133993,"mc":[{"id":"1.230178327","rc":[{"atb":[[2.22,2.49]],"id":62600242},{"atl":[[6.4,7.67]],"id":67674431},{"atb":[[2.08,0]],"id":65710029},{"atl":[[3.7,0.84]],"id":65710029}],"con":true,"img":false}]}
{"op":"mcm","clk":"11541475095","pt":1719506134458,"mc":[{"id":"1.230178327","rc":[{"atb":[[3.45,12.73]],"id":67674431}],"con":true,"img":false}]}
{"op":"mcm","clk":"11541475139","pt":1719506134871,"mc":[{"id":"1.230178327","rc":[{"atb":[[2.44,3.82]],"id":62600242}],"con":true,"img":false}]}
{"op":"mcm","clk":"11541475148","pt":1719506134977,"mc":[{"id":"1.230178327","rc":[{"atb":[[2.48,2]],"id":62600242},{"atl":[[6.6,9.36]],"id":67674431}],"con":true,"img":false}]}
{"op":"mcm","clk":"11541475160","pt":1719506135079,"mc":[{"id":"1.230178327","rc":[{"atl":[[7.4,0]],"id":67674431}],"con":true,"img":false}]}
{"op":"mcm","clk":"11541475171","pt":1719506135188,"mc":[{"id":"1.230178327","rc":[{"atl":[[3.65,1]],"id":65710029}],"con":true,"img":false}]}
{"op":"mcm","clk":"11541475262","pt":1719506136067,"mc":[{"id":"1.230178327","rc":[{"atb":[[2.42,0]],"id":62600242},{"atb":[[2.58,0]],"id":60748118},{"atb":[[2.24,0]],"id":68687941},{"atb":[[3.4,3.86]],"id":67674431}],"con":true,"img":false}]}
{"op":"mcm","clk":"11541475273","pt":1719506136174,"mc":[{"id":"1.230178327","rc":[{"atl":[[4.3,1],[5,13.23]],"id":68687941}],"con":true,"img":false}]}
{"op":"mcm","clk":"11541475282","pt":1719506136276,"mc":[{"id":"1.230178327","rc":[{"atb":[[2.48,3.94]],"id":62600242},{"atb":[[2.62,1.94]],"id":60748118},{"atb":[[2.28,1.94]],"id":68687941},{"atb":[[3.5,1.94]],"id":67674431}],"con":true,"img":false}]}
{"op":"mcm","clk":"11541475371","pt":1719506137210,"mc":[{"id":"1.230178327","rc":[{"atb":[[2.24,4.13]],"id":68687941}],"con":true,"img":false}]}
{"op":"mcm","clk":"11541475387","pt":1719506137370,"mc":[{"id":"1.230178327","rc":[{"atb":[[3.45,4.4]],"id":67674431}],"con":true,"img":false}]}
{"op":"mcm","clk":"11541475411","pt":1719506137575,"mc":[{"id":"1.230178327","rc":[{"atb":[[2.9,10]],"id":67674431}],"con":true,"img":false}]}
{"op":"mcm","clk":"11541475420","pt":1719506137682,"mc":[{"id":"1.230178327","rc":[{"atb":[[2.82,0]],"id":67674431}],"con":true,"img":false}]}
{"op":"mcm","clk":"11541475450","pt":1719506137991,"mc":[{"id":"1.230178327","rc":[{"atb":[[3.5,10.18]],"id":67674431}],"con":true,"img":false}]}
{"op":"mcm","clk":"11541475582","pt":1719506139183,"mc":[{"id":"1.230178327","rc":[{"atb":[[2.62,0]],"id":60748118},{"atb":[[2.28,0]],"id":68687941}],"con":true,"img":false}]}
{"op":"mcm","clk":"11541475590","pt":1719506139287,"mc":[{"id":"1.230178327","rc":[{"atb":[[3.45,2.4]],"id":67674431}],"con":true,"img":false}]}
{"op":"mcm","clk":"11541475598","pt":1719506139391,"mc":[{"id":"1.230178327","rc":[{"atb":[[2.62,1.94]],"id":60748118},{"atb":[[2.28,1.94]],"id":68687941},{"atb":[[3.55,2]],"id":67674431}],"con":true,"img":false}]}
{"op":"mcm","clk":"11541475614","pt":1719506139598,"mc":[{"id":"1.230178327","rc":[{"atl":[[4.6,7.44]],"id":58221357},{"atl":[[4.8,0],[4.6,5.66]],"id":62600242},{"atl":[[4.3,0],[4.5,1]],"id":68687941}],"con":true,"img":false}]}
{"op":"mcm","clk":"11541475624","pt":1719506139702,"mc":[{"id":"1.230178327","rc":[{"atl":[[4.8,5.38]],"id":58221357},{"atl":[[4.6,11.33],[4.9,2.5]],"id":62600242}],"con":true,"img":false}]}
{"op":"mcm","clk":"11541475643","pt":1719506139868,"mc":[{"id":"1.230178327","rc":[{"atb":[[3.5,1.94]],"id":67674431}],"con":true,"img":false}]}
{"op":"mcm","clk":"11541475690","pt":1719506140277,"mc":[{"id":"1.230178327","rc":[{"atl":[[3.8,2]],"id":65710029}],"con":true,"img":false}]}
{"op":"mcm","clk":"11541475719","pt":1719506140589,"mc":[{"id":"1.230178327","rc":[{"atb":[[3.55,0]],"id":67674431}],"con":true,"img":false}]}
{"op":"mcm","clk":"11541475731","pt":1719506140690,"mc":[{"id":"1.230178327","rc":[{"atb":[[3.55,9.04],[3.5,3.94]],"id":67674431}],"con":true,"img":false}]}
{"op":"mcm","clk":"11541475774","pt":1719506141104,"mc":[{"id":"1.230178327","rc":[{"atb":[[2.18,0]],"id":65710029}],"con":true,"img":false}]}
{"op":"mcm","clk":"11541475835","pt":1719506141794,"mc":[{"id":"1.230178327","rc":[{"atl":[[4.5,10.46]],"id":68687941}],"con":true,"img":false}]}
{"op":"mcm","clk":"11541475845","pt":1719506141883,"mc":[{"id":"1.230178327","rc":[{"atl":[[5,2.5]],"id":68687941}],"con":true,"img":false}]}
{"op":"mcm","clk":"11541475873","pt":1719506142197,"mc":[{"id":"1.230178327","rc":[{"atb":[[2.62,0]],"id":60748118},{"atb":[[2.28,0]],"id":68687941},{"atb":[[3.5,0]],"id":67674431}],"con":true,"img":false}]}
{"op":"mcm","clk":"11541475886","pt":1719506142300,"mc":[{"id":"1.230178327","rc":[{"atb":[[2.6,3.85]],"id":60748118},{"atb":[[2.46,0]],"id":62600242},{"atb":[[2.26,3.88]],"id":68687941},{"atb":[[3.6,2],[3.45,0]],"id":67674431}],"con":true,"img":false}]}
{"op":"mcm","clk":"11541475896","pt":1719506142404,"mc":[{"id":"1.230178327","rc":[{"atb":[[2.62,1.94]],"id":60748118},{"atb":[[2.28,1.94]],"id":68687941},{"atb":[[3.6,3.94]],"id":67674431}],"con":true,"img":false}]}
{"op":"mcm","clk":"11541475907","pt":1719506142470,"mc":[{"id":"1.230178327","rc":[{"atb":[[2.62,4.44]],"id":60748118},{"atb":[[2.5,2]],"id":62600242},{"atb":[[2.28,4.14]],"id":68687941},{"atb":[[3.6,6.04]],"id":67674431}],"con":true,"img":false}]}
{"op":"mcm","clk":"11541475987","pt":1719506143394,"mc":[{"id":"1.230178327","rc":[{"atb":[[2.48,1.94]],"id":62600242}],"con":true,"img":false}]}
{"op":"mcm","clk":"11541475998","pt":1719506143496,"mc":[{"id":"1.230178327","rc":[{"atb":[[2.52,2]],"id":62600242}],"con":true,"img":false}]}
{"op":"mcm","clk":"11541476146","pt":1719506144899,"mc":[{"id":"1.230178327","rc":[{"atl":[[4.6,5.66],[5.3,18.84]],"id":62600242}],"con":true,"img":false}]}
{"op":"mcm","clk":"11541476169","pt":1719506145104,"mc":[{"id":"1.230178327","rc":[{"atb":[[2.4,8.26]],"id":58221357},{"atb":[[2.52,5.38]],"id":62600242},{"atb":[[2.62,10.66]],"id":60748118},{"atb":[[2.28,10.35]],"id":68687941},{"atb":[[3.65,10.29]],"id":67674431},{"atl":[[6.2,11.13]],"id":67674431},{"atl":[[3.6,3.46]],"id":65710029}],"con":true,"img":false}]}
{"op":"mcm","clk":"11541476181","pt":1719506145209,"mc":[{"id":"1.230178327","rc":[{"atb":[[2.38,0]],"id":58221357},{"atb":[[2.62,8.72]],"id":60748118},{"atb":[[2.44,0]],"id":62600242},{"atb":[[2.28,8.41],[2.26,0]],"id":68687941},{"atb":[[3.6,4.1],[3.4,0]],"id":67674431},{"atl":[[6.4,3.81]],"id":67674431},{"atb":[[2.16,3.39]],"id":65710029},{"atl":[[3.8,0],[3.55,2],[3.65,0],[3.75,0]],"id":65710029}],"con":true,"img":false}]}
{"op":"mcm","clk":"11541476193","pt":1719506145313,"mc":[{"id":"1.230178327","rc":[{"atb":[[2.6,0]],"id":60748118},{"atb":[[3.55,8.24]],"id":67674431},{"atl":[[6.4,0]],"id":67674431},{"atl":[[3.7,6.3],[3.55,0]],"id":65710029}],"con":true,"img":false}]}
{"op":"mcm","clk":"11541476207","pt":1719506145376,"mc":[{"id":"1.230178327","rc":[{"atl":[[6.6,0.84],[7,17.67]],"id":67674431}],"con":true,"img":false}]}
{"op":"mcm","clk":"11541476217","pt":1719506145478,"mc":[{"id":"1.230178327","rc":[{"atb":[[3.55,0]],"id":67674431},{"atl":[[3.55,4.42]],"id":65710029}],"con":true,"img":false}]}
{"op":"mcm","clk":"11541476229","pt":1719506145598,"mc":[{"id":"1.230178327","rc":[{"atb":[[2.24,0]],"id":68687941},{"atb":[[3.6,2.1],[3.65,18.54]],"id":67674431},{"atl":[[3.6,0]],"id":65710029}],"con":true,"img":false}]}
{"op":"mcm","clk":"11541476243","pt":1719506145689,"mc":[{"id":"1.230178327","rc":[{"atb":[[1.02,2]],"id":67674431},{"atl":[[4.1,11.73],[3.7,0.84],[3.55,0]],"id":65710029}],"con":true,"img":false}]}
{"op":"mcm","clk":"11541476254","pt":1719506145793,"mc":[{"id":"1.230178327","rc":[{"atl":[[3.6,4.42]],"id":65710029}],"con":true,"img":false}]}
{"op":"mcm","clk":"11541476277","pt":1719506145988,"mc":[{"id":"1.230178327","rc":[{"atl":[[6.6,0]],"id":67674431},{"atb":[[2.16,1.39]],"id":65710029},{"atl":[[3.7,0],[3.5,0.84]],"id":65710029}],"con":true,"img":false}]}
{"op":"mcm","clk":"11541476289","pt":1719506146092,"mc":[{"id":"1.230178327","rc":[{"atl":[[8,16.79],[7,1]],"id":67674431},{"atb":[[2.04,2]],"id":65710029}],"con":true,"img":false}]}
{"op":"mcm","clk":"11541476302","pt":1719506146196,"mc":[{"id":"1.230178327","rc":[{"atl":[[6.2,15.44]],"id":67674431}],"con":true,"img":false}]}
{"op":"mcm","clk":"11541476348","pt":1719506146299,"mc":[{"id":"1.230178327","rc":[{"atl":[[8,2.5],[6.6,17.86]],"id":67674431}],"con":true,"img":false}]}
{"op":"mcm","clk":"11541476357","pt":1719506146402,"mc":[{"id":"1.230178327","rc":[{"atl":[[3.55,2.53]],"id":65710029}],"con":true,"img":false}]}
{"op":"mcm","clk":"11541476369","pt":1719506146505,"mc":[{"id":"1.230178327","rc":[{"atl":[[3.5,0]],"id":65710029}],"con":true,"img":false}]}
{"op":"mcm","clk":"11541476411","pt":1719506146991,"mc":[{"id":"1.230178327","rc":[{"atl":[[4.5,0.99],[5,17.69]],"id":68687941}],"con":true,"img":false}]}
{"op":"mcm","clk":"11541476540","pt":1719506148276,"mc":[{"id":"1.230178327","rc":[{"atb":[[2.48,0]],"id":62600242}],"con":true,"img":false}]}
{"op":"mcm","clk":"11541476552","pt":1719506148422,"mc":[{"id":"1.230178327","rc":[{"atl":[[3.5,1]],"id":65710029}],"con":true,"img":false}]}
{"op":"mcm","clk":"11541476561","pt":1719506148484,"mc":[{"id":"1.230178327","rc":[{"atb":[[2.54,1.94]],"id":62600242},{"atb":[[2.64,1.94]],"id":60748118},{"atb":[[3.7,1.94]],"id":67674431},{"atb":[[2.04,3.94]],"id":65710029}],"con":true,"img":false}]}
{"op":"mcm","clk":"11541476688","pt":1719506149510,"mc":[{"id":"1.230178327","rc":[{"atb":[[2.6,3.13]],"id":60748118},{"atb":[[3.65,18.06]],"id":67674431}],"con":true,"img":false}]}
{"op":"mcm","clk":"11541476708","pt":1719506149682,"mc":[{"id":"1.230178327","rc":[{"atb":[[3.65,10.29]],"id":67674431}],"con":true,"img":false}]}
{"op":"mcm","clk":"11541476719","pt":1719506149780,"mc":[{"id":"1.230178327","rc":[{"atb":[[3.7,9.71]],"id":67674431}],"con":true,"img":false}]}
{"op":"mcm","clk":"11541476814","pt":1719506151009,"mc":[{"id":"1.230178327","rc":[{"atb":[[2.62,6.22]],"id":60748118},{"atb":[[2.5,0]],"id":62600242},{"atb":[[2.28,6.21]],"id":68687941},{"atb":[[3.6,0]],"id":67674431}],"con":true,"img":false}]}
{"op":"mcm","clk":"11541476823","pt":1719506151114,"mc":[{"id":"1.230178327","rc":[{"atb":[[2.64,3.94]],"id":60748118},{"atb":[[2.54,4.94]],"id":62600242},{"atb":[[2.3,2.2],[2.28,0]],"id":68687941},{"atb":[[3.75,2.8]],"id":67674431},{"atb":[[2.06,2.04]],"id":65710029}],"con":true,"img":false}]}
{"op":"mcm","clk":"11541476833","pt":1719506151182,"mc":[{"id":"1.230178327","rc":[{"atb":[[2.3,5.44]],"id":68687941},{"atl":[[4.1,1],[3.55,6.95]],"id":65710029}],"con":true,"img":false}]}
{"op":"mcm","clk":"11541476851","pt":1719506151389,"mc":[{"id":"1.230178327","rc":[{"atb":[[2.64,2]],"id":60748118},{"atb":[[2.54,3]],"id":62600242}],"con":true,"img":false}]}
{"op":"mcm","clk":"11541476870","pt":1719506151593,"mc":[{"id":"1.230178327","rc":[{"atb":[[2.54,4.94]],"id":62600242},{"atb":[[2.64,3.94]],"id":60748118},{"atb":[[3.7,1.94]],"id":67674431}],"con":true,"img":false}]}
{"op":"mcm","clk":"11541476911","pt":1719506152100,"mc":[{"id":"1.230178327","rc":[{"atl":[[3.45,0.52]],"id":65710029}],"con":true,"img":false}]}
{"op":"mcm","clk":"11541476921","pt":1719506152204,"mc":[{"id":"1.230178327","rc":[{"atb":[[2.52,3.38]],"id":62600242}],"con":true,"img":false}]}
{"op":"mcm","clk":"11541476933","pt":1719506152308,"mc":[{"id":"1.230178327","rc":[{"atb":[[2.56,2]],"id":62600242},{"atb":[[1.03,0.52]],"id":65710029},{"atl":[[3.5,0]],"id":65710029}],"con":true,"img":false}]}
{"op":"mcm","clk":"11541476942","pt":1719506152411,"mc":[{"id":"1.230178327","rc":[{"atb":[[3.75,11.41]],"id":67674431}],"con":true,"img":false}]}
{"op":"mcm","clk":"11541476952","pt":1719506152471,"mc":[{"id":"1.230178327","rc":[{"atb":[[1.03,0.44]],"id":65710029}],"con":true,"img":false}]}
{"op":"mcm","clk":"11541476974","pt":1719506152685,"mc":[{"id":"1.230178327","rc":[{"atb":[[1.03,0],[2.04,1.94]],"id":65710029}],"con":true,"img":false}]}
{"op":"mcm","clk":"11541476982","pt":1719506152805,"mc":[{"id":"1.230178327","rc":[{"atb":[[2.08,2],[2.18,0.44]],"id":65710029}],"con":true,"img":false}]}
{"op":"mcm","clk":"11541477048","pt":1719506153504,"mc":[{"id":"1.230178327","rc":[{"atl":[[3.5,0.84]],"id":65710029}],"con":true,"img":false}]}
{"op":"mcm","clk":"11541477101","pt":1719506154091,"mc":[{"id":"1.230178327","rc":[{"atb":[[3.1,2.5]],"id":67674431}],"con":true,"img":false}]}
{"op":"mcm","clk":"11541477110","pt":1719506154199,"mc":[{"id":"1.230178327","rc":[{"atb":[[2.94,0],[3.05,0],[2.86,0]],"id":67674431}],"con":true,"img":false}]}
{"op":"mcm","clk":"11541477130","pt":1719506154397,"mc":[{"id":"1.230178327","rc":[{"atb":[[3.7,0]],"id":67674431},{"atb":[[2.04,0]],"id":65710029},{"atl":[[3.4,1]],"id":65710029}],"con":true,"img":false}]}
{"op":"mcm","clk":"11541477140","pt":1719506154500,"mc":[{"id":"1.230178327","rc":[{"atb":[[3.8,1.94]],"id":67674431},{"atb":[[2.08,3.94]],"id":65710029}],"con":true,"img":false}]}
{"op":"mcm","clk":"11541477223","pt":1719506155397,"mc":[{"id":"1.230178327","rc":[{"atb":[[3.75,11.01]],"id":67674431}],"con":true,"img":false}]}
{"op":"mcm","clk":"11541477242","pt":1719506155592,"mc":[{"id":"1.230178327","rc":[{"atb":[[3.75,2.79]],"id":67674431}],"con":true,"img":false}]}
{"op":"mcm","clk":"11541477252","pt":1719506155691,"mc":[{"id":"1.230178327","rc":[{"atb":[[3.8,10.15]],"id":67674431}],"con":true,"img":false}]}
{"op":"mcm","clk":"11541477322","pt":1719506156416,"mc":[{"id":"1.230178327","rc":[{"atl":[[3.55,4.42]],"id":65710029}],"con":true,"img":false}]}
{"op":"mcm","clk":"11541477341","pt":1719506156578,"mc":[{"id":"1.230178327","rc":[{"atb":[[2.16,3.7]],"id":65710029}],"con":true,"img":false}]}
{"op":"mcm","clk":"11541477370","pt":1719506156890,"mc":[{"id":"1.230178327","rc":[{"atb":[[2.56,8.25]],"id":62600242},{"atb":[[2.64,10.43]],"id":60748118},{"atb":[[3.85,15.34]],"id":67674431},{"atl":[[3.35,1.39]],"id":65710029}],"con":true,"img":false}]}
{"op":"mcm","clk":"11541477382","pt":1719506156992,"mc":[{"id":"1.230178327","rc":[{"atb":[[2.5,4.82],[2.52,0]],"id":62600242},{"atb":[[3.65,0]],"id":67674431},{"atl":[[3.45,2.52],[3.6,0],[3.4,0],[3.55,0]],"id":65710029}],"con":true,"img":false}]}
{"op":"mcm","clk":"11541477392","pt":1719506157104,"mc":[{"id":"1.230178327","rc":[{"atb":[[2.5,3.38]],"id":62600242},{"atb":[[2.62,0]],"id":60748118},{"atl":[[3.35,0]],"id":65710029}],"con":true,"img":false}]}
{"op":"mcm","clk":"11541477403","pt":1719506157194,"mc":[{"id":"1.230178327","rc":[{"atl":[[3.4,2.54]],"id":65710029}],"con":true,"img":false}]}
{"op":"mcm","clk":"11541477426","pt":1719506157401,"mc":[{"id":"1.230178327","rc":[{"atb":[[2.54,3]],"id":62600242},{"atb":[[3.8,0]],"id":67674431},{"atb":[[2.08,2]],"id":65710029}],"con":true,"img":false}]}
{"op":"mcm","clk":"11541477441","pt":1719506157608,"mc":[{"id":"1.230178327","rc":[{"atb":[[2.58,1.94]],"id":62600242},{"atb":[[3.85,0]],"id":67674431},{"atb":[[2.18,2.39]],"id":65710029}],"con":true,"img":false}]}
{"op":"mcm","clk":"11541477449","pt":1719506157712,"mc":[{"id":"1.230178327","rc":[{"atb":[[2.5,0]],"id":62600242},{"atb":[[2.6,0]],"id":60748118},{"atb":[[3.8,13.6]],"id":67674431},{"atb":[[2.18,6.08]],"id":65710029}],"con":true,"img":false}]}
{"op":"mcm","clk":"11541477458","pt":1719506157814,"mc":[{"id":"1.230178327","rc":[{"atb":[[2.08,0]],"id":65710029}],"con":true,"img":false}]}
{"op":"mcm","clk":"11541477468","pt":1719506157919,"mc":[{"id":"1.230178327","rc":[{"atb":[[2.18,8.08],[2.16,2.31]],"id":65710029}],"con":true,"img":false}]}
{"op":"mcm","clk":"11541477476","pt":1719506157980,"mc":[{"id":"1.230178327","rc":[{"atl":[[3.5,0]],"id":65710029}],"con":true,"img":false}]}
{"op":"mcm","clk":"11541477492","pt":1719506158194,"mc":[{"id":"1.230178327","rc":[{"atb":[[3.8,20.87]],"id":67674431}],"con":true,"img":false}]}
{"op":"mcm","clk":"11541477589","pt":1719506159322,"mc":[{"id":"1.230178327","rc":[{"atl":[[3.35,2.53]],"id":65710029}],"con":true,"img":false}]}
{"op":"mcm","clk":"11541477598","pt":1719506159428,"mc":[{"id":"1.230178327","rc":[{"atl":[[3.3,3.8]],"id":65710029}],"con":true,"img":false}]}
{"op":"mcm","clk":"11541477609","pt":1719506159490,"mc":[{"id":"1.230178327","rc":[{"atl":[[3.3,4.8]],"id":65710029}],"con":true,"img":false}]}
{"op":"mcm","clk":"11541477621","pt":1719506159590,"mc":[{"id":"1.230178327","rc":[{"atl":[[3.4,0]],"id":65710029}],"con":true,"img":false}]}
{"op":"mcm","clk":"11541477642","pt":1719506159795,"mc":[{"id":"1.230178327","rc":[{"atb":[[2.54,0]],"id":62600242},{"atb":[[2.64,8.43]],"id":60748118},{"atb":[[3.75,0]],"id":67674431},{"atb":[[2.06,0]],"id":65710029}],"con":true,"img":false}]}
{"op":"mcm","clk":"11541477661","pt":1719506160001,"mc":[{"id":"1.230178327","rc":[{"atb":[[2.66,3]],"id":60748118},{"atb":[[2.58,4.74]],"id":62600242},{"atb":[[3.85,2.44]],"id":67674431},{"atb":[[2.2,2.3]],"id":65710029}],"con":true,"img":false}]}
{"op":"mcm","clk":"11541477681","pt":1719506160206,"mc":[{"id":"1.230178327","rc":[{"atb":[[2.16,0]],"id":65710029}],"con":true,"img":false}]}
{"op":"mcm","clk":"11541477700","pt":1719506160414,"mc":[{"id":"1.230178327","rc":[{"atb":[[2.64,6.49]],"id":60748118},{"atb":[[2.28,4]],"id":68687941},{"atb":[[2.18,6.13]],"id":65710029}],"con":true,"img":false}]}
{"op":"mcm","clk":"11541477717","pt":1719506160619,"mc":[{"id":"1.230178327","rc":[{"atb":[[2.68,1.94]],"id":60748118},{"atb":[[3.8,20.77]],"id":67674431},{"atb":[[2.22,1.94]],"id":65710029}],"con":true,"img":false}]}
{"op":"mcm","clk":"11541477742","pt":1719506160889,"mc":[{"id":"1.230178327","rc":[{"atb":[[3.8,13.6]],"id":67674431},{"atl":[[3.25,0.84]],"id":65710029}],"con":true,"img":false}]}
{"op":"mcm","clk":"11541477750","pt":1719506160998,"mc":[{"id":"1.230178327","rc":[{"atb":[[3.85,9.61]],"id":67674431}],"con":true,"img":false}]}
{"op":"mcm","clk":"11541477758","pt":1719506161101,"mc":[{"id":"1.230178327","rc":[{"atl":[[3.3,3.8]],"id":65710029}],"con":true,"img":false}]}
{"op":"mcm","clk":"11541477859","pt":1719506162096,"mc":[{"id":"1.230178327","rc":[{"atl":[[3.35,0]],"id":65710029}],"con":true,"img":false}]}
{"op":"mcm","clk":"11541477872","pt":1719506162202,"mc":[{"id":"1.230178327","rc":[{"atb":[[2.56,6.25]],"id":62600242}],"con":true,"img":false}]}
{"op":"mcm","clk":"11541477887","pt":1719506162306,"mc":[{"id":"1.230178327","rc":[{"atb":[[1.02,2]],"id":62600242}],"con":true,"img":false}]}
{"op":"mcm","clk":"11541477948","pt":1719506162719,"mc":[{"id":"1.230178327","rc":[{"atb":[[2.18,4.13]],"id":65710029}],"con":true,"img":false}]}
{"op":"mcm","clk":"11541477961","pt":1719506162814,"mc":[{"id":"1.230178327","rc":[{"atb":[[2.22,3.94]],"id":65710029}],"con":true,"img":false}]}
{"op":"mcm","clk":"11541478039","pt":1719506163504,"mc":[{"id":"1.230178327","rc":[{"atb":[[2.68,0]],"id":60748118}],"con":true,"img":false}]}
{"op":"mcm","clk":"11541478050","pt":1719506163604,"mc":[{"id":"1.230178327","rc":[{"atl":[[3.2,1]],"id":65710029}],"con":true,"img":false}]}
{"op":"mcm","clk":"11541478059","pt":1719506163709,"mc":[{"id":"1.230178327","rc":[{"atb":[[2.68,1.94]],"id":60748118},{"atl":[[3.45,0.52],[3.3,6.33]],"id":65710029}],"con":true,"img":false}]}
{"op":"mcm","clk":"11541478107","pt":1719506164217,"mc":[{"id":"1.230178327","rc":[{"atb":[[2.28,0]],"id":68687941}],"con":true,"img":false}]}
{"op":"mcm","clk":"11541478218","pt":1719506165311,"mc":[{"id":"1.230178327","rc":[{"atl":[[3.2,3.53]],"id":65710029}],"con":true,"img":false}]}
{"op":"mcm","clk":"11541478230","pt":1719506165408,"mc":[{"id":"1.230178327","rc":[{"atl":[[3.15,3.54],[3.3,3.8]],"id":65710029}],"con":true,"img":false}]}
{"op":"mcm","clk":"11541478247","pt":1719506165614,"mc":[{"id":"1.230178327","rc":[{"atl":[[3.2,2.53]],"id":65710029}],"con":true,"img":false}]}
{"op":"mcm","clk":"11541478259","pt":1719506165719,"mc":[{"id":"1.230178327","rc":[{"atl":[[3.2,9.61],[3.15,0]],"id":65710029}],"con":true,"img":false}]}
{"op":"mcm","clk":"11541478285","pt":1719506165986,"mc":[{"id":"1.230178327","rc":[{"atl":[[3.25,0]],"id":65710029}],"con":true,"img":false}]}
{"op":"mcm","clk":"11541478333","pt":1719506166601,"mc":[{"id":"1.230178327","rc":[{"atb":[[2.68,0]],"id":60748118}],"con":true,"img":false}]}
{"op":"mcm","clk":"11541478352","pt":1719506166810,"mc":[{"id":"1.230178327","rc":[{"atb":[[2.68,1.94]],"id":60748118}],"con":true,"img":false}]}
{"op":"mcm","clk":"11541478410","pt":1719506167491,"mc":[{"id":"1.230178327","rc":[{"atl":[[3.45,0]],"id":65710029}],"con":true,"img":false}]}
{"op":"mcm","clk":"11541478420","pt":1719506167594,"mc":[{"id":"1.230178327","rc":[{"atl":[[3.15,1]],"id":65710029}],"con":true,"img":false}]}
{"op":"mcm","clk":"11541478446","pt":1719506167903,"mc":[{"id":"1.230178327","rc":[{"atl":[[3.15,1.84]],"id":65710029}],"con":true,"img":false}]}
{"op":"mcm","clk":"11541478459","pt":1719506168006,"mc":[{"id":"1.230178327","rc":[{"atb":[[2.18,3.69]],"id":65710029}],"con":true,"img":false}]}
{"op":"mcm","clk":"11541478536","pt":1719506168521,"mc":[{"id":"1.230178327","rc":[{"atb":[[2.66,0],[2.68,7.72]],"id":60748118},{"atb":[[2.58,12.56]],"id":62600242},{"atb":[[3.9,16.76]],"id":67674431},{"atb":[[2.2,0]],"id":65710029},{"atl":[[3.15,7.46]],"id":65710029}],"con":true,"img":false}]}
{"op":"mcm","clk":"11541478547","pt":1719506168626,"mc":[{"id":"1.230178327","rc":[{"atb":[[2.64,0]],"id":60748118},{"atb":[[2.56,0]],"id":62600242},{"atb":[[3.8,0]],"id":67674431},{"atl":[[3.2,2.53],[3.1,7.47],[3.3,0]],"id":65710029}],"con":true,"img":false}]}
{"op":"mcm","clk":"11541478558","pt":1719506168731,"mc":[{"id":"1.230178327","rc":[{"atb":[[2.68,10.36]],"id":60748118}],"con":true,"img":false}]}
{"op":"mcm","clk":"11541478570","pt":1719506168797,"mc":[{"id":"1.230178327","rc":[{"atl":[[3.1,5.73],[3.15,13.93]],"id":65710029}],"con":true,"img":false}]}
{"op":"mcm","clk":"11541478590","pt":1719506168999,"mc":[{"id":"1.230178327","rc":[{"atl":[[3.15,8.31]],"id":65710029}],"con":true,"img":false}]}
{"op":"mcm","clk":"11541478611","pt":1719506169203,"mc":[{"id":"1.230178327","rc":[{"atb":[[2.54,3.06]],"id":62600242}],"con":true,"img":false}]}
{"op":"mcm","clk":"11541478625","pt":1719506169317,"mc":[{"id":"1.230178327","rc":[{"atb":[[2.22,9.67]],"id":65710029}],"con":true,"img":false}]}
{"op":"mcm","clk":"11541478634","pt":1719506169408,"mc":[{"id":"1.230178327","rc":[{"atb":[[2.54,0]],"id":62600242},{"atb":[[3.85,2.44]],"id":67674431}],"con":true,"img":false}]}
{"op":"mcm","clk":"11541478643","pt":1719506169521,"mc":[{"id":"1.230178327","rc":[{"atb":[[2.18,0]],"id":65710029}],"con":true,"img":false}]}
{"op":"mcm","clk":"11541478653","pt":1719506169615,"mc":[{"id":"1.230178327","rc":[{"atl":[[3.2,0]],"id":65710029}],"con":true,"img":false}]}
{"op":"mcm","clk":"11541478717","pt":1719506170201,"mc":[{"id":"1.230178327","rc":[{"atb":[[3.9,24.58]],"id":67674431}],"con":true,"img":false}]}
{"op":"mcm","clk":"11541478909","pt":1719506172121,"mc":[{"id":"1.230178327","rc":[{"atb":[[2.66,3.02]],"id":60748118}],"con":true,"img":false}]}
{"op":"mcm","clk":"11541478930","pt":1719506172325,"mc":[{"id":"1.230178327","rc":[{"atl":[[3.05,3.53]],"id":65710029}],"con":true,"img":false}]}
{"op":"mcm","clk":"11541478951","pt":1719506172535,"mc":[{"id":"1.230178327","rc":[{"atl":[[3.05,10.48]],"id":65710029}],"con":true,"img":false}]}
{"op":"mcm","clk":"11541478971","pt":1719506172702,"mc":[{"id":"1.230178327","rc":[{"atl":[[3.1,0]],"id":65710029}],"con":true,"img":false}]}
{"op":"mcm","clk":"11541479005","pt":1719506173015,"mc":[{"id":"1.230178327","rc":[{"atl":[[3.15,7.47]],"id":65710029}],"con":true,"img":false}]}
{"op":"mcm","clk":"11541479018","pt":1719506173112,"mc":[{"id":"1.230178327","rc":[{"atl":[[3.05,9.48]],"id":65710029}],"con":true,"img":false}]}
{"op":"mcm","clk":"11541479120","pt":1719506174010,"mc":[{"id":"1.230178327","rc":[{"atl":[[3.15,0],[3.05,16.95]],"id":65710029}],"con":true,"img":false}]}
{"op":"mcm","clk":"11541479233","pt":1719506174930,"mc":[{"id":"1.230178327","rc":[{"atl":[[3,0.84]],"id":65710029}],"con":true,"img":false}]}
{"op":"mcm","clk":"11541479304","pt":1719506175611,"mc":[{"id":"1.230178327","rc":[{"atb":[[3.95,1.94]],"id":67674431}],"con":true,"img":false}]}
{"op":"mcm","clk":"11541479312","pt":1719506175717,"mc":[{"id":"1.230178327","rc":[{"atl":[[2.98,1]],"id":65710029}],"con":true,"img":false}]}
{"op":"mcm","clk":"11541479407","pt":1719506176644,"mc":[{"id":"1.230178327","rc":[{"atl":[[4.5,1],[4.6,6.44],[5,0],[5.8,0],[4.9,2.5],[5.4,0]],"id":58221357},{"atb":[[1.97,0]],"id":60748118},{"atl":[[4.8,1],[7.2,0],[5.1,0],[6.4,0],[5.8,10.7],[6.2,5],[5.7,2.5]],"id":60748118},{"atb":[[1.78,0],[2.58,4.74]],"id":62600242},{"atl":[[4.8,2.5],[5.6,10],[5.3,13.84],[4.9,0],[5.2,5],[5.7,0]],"id":62600242},{"atl":[[4.5,0],[4.2,1]],"id":68687941},{"atb":[[2.9,0],[3.95,15.36],[3.15,4.88]],"id":67674431},{"atl":[[7.2,16.13],[6.6,0],[7,0],[7.8,1]],"id":67674431},{"atb":[[2.22,3.94]],"id":65710029}],"con":true,"img":false}]}
{"op":"mcm","clk":"11541479421","pt":1719506176707,"mc":[{"id":"1.230178327","rc":[{"atl":[[4.5,5.1]],"id":58221357},{"atl":[[4.8,4.86],[5.1,9.4],[5.8,0]],"id":60748118},{"atl":[[4.9,11.34]],"id":62600242},{"atl":[[4.5,9.46],[5,2.5]],"id":68687941},{"atb":[[3.9,16.76]],"id":67674431}],"con":true,"img":false}]}
{"op":"mcm","clk":"11541479433","pt":1719506176805,"mc":[{"id":"1.230178327","rc":[{"atl":[[4.6,0.84]],"id":58221357},{"atl":[[5.1,0],[4.9,0.84],[5.7,8.2]],"id":60748118},{"atl":[[5.3,0],[4.9,0],[5.2,15]],"id":62600242},{"atl":[[4.5,0],[5,12.5]],"id":68687941},{"atb":[[3.9,0]],"id":67674431},{"atl":[[3,13.64]],"id":65710029}],"con":true,"img":false}]}
{"op":"mcm","clk":"11541479446","pt":1719506176909,"mc":[{"id":"1.230178327","rc":[{"atl":[[5.2,5],[4.9,11.34]],"id":62600242},{"atl":[[5.1,9.56],[5.7,2.5]],"id":60748118},{"atl":[[4.5,5.73],[5,2.5]],"id":68687941}],"con":true,"img":false}]}
{"op":"mcm","clk":"11541479473","pt":1719506177221,"mc":[{"id":"1.230178327","rc":[{"atb":[[2.68,7.72]],"id":60748118},{"atb":[[3.85,0]],"id":67674431}],"con":true,"img":false}]}
{"op":"mcm","clk":"11541479484","pt":1719506177319,"mc":[{"id":"1.230178327","rc":[{"atb":[[2.7,2.71]],"id":60748118}],"con":true,"img":false}]}
{"op":"mcm","clk":"11541479495","pt":1719506177422,"mc":[{"id":"1.230178327","rc":[{"atl":[[4.4,0.84]],"id":58221357},{"atl":[[4.7,0.84]],"id":60748118}],"con":true,"img":false}]}
{"op":"mcm","clk":"11541479504","pt":1719506177527,"mc":[{"id":"1.230178327","rc":[{"atl":[[5.1,0],[4.9,6.55]],"id":60748118},{"atl":[[6.2,14.73]],"id":67674431}],"con":true,"img":false}]}
{"op":"mcm","clk":"11541479525","pt":1719506177734,"mc":[{"id":"1.230178327","rc":[{"atl":[[6.2,11.13]],"id":67674431}],"con":true,"img":false}]}
{"op":"mcm","clk":"11541479535","pt":1719506177837,"mc":[{"id":"1.230178327","rc":[{"atl":[[7.8,15.71],[7,3.6]],"id":67674431}],"con":true,"img":false}]}
{"op":"mcm","clk":"11541479550","pt":1719506178045,"mc":[{"id":"1.230178327","rc":[{"atl":[[7.2,0]],"id":67674431}],"con":true,"img":false}]}
{"op":"mcm","clk":"11541479572","pt":1719506178255,"mc":[{"id":"1.230178327","rc":[{"atb":[[2.22,1.94]],"id":65710029},{"atl":[[3.05,14.42]],"id":65710029}],"con":true,"img":false}]}
{"op":"mcm","clk":"11541479584","pt":1719506178313,"mc":[{"id":"1.230178327","rc":[{"atb":[[2.04,2]],"id":65710029},{"atl":[[3.1,4.25]],"id":65710029}],"con":true,"img":false}]}
{"op":"mcm","clk":"11541479609","pt":1719506178624,"mc":[{"id":"1.230178327","rc":[{"atb":[[2.68,5.78]],"id":60748118},{"atb":[[2.22,0]],"id":65710029}],"con":true,"img":false}]}
{"op":"mcm","clk":"11541479620","pt":1719506178728,"mc":[{"id":"1.230178327","rc":[{"atb":[[2.06,1],[2.2,3.46],[2.16,4.84]],"id":65710029}],"con":true,"img":false}]}
{"op":"mcm","clk":"11541479630","pt":1719506178834,"mc":[{"id":"1.230178327","rc":[{"atb":[[2.72,1.94]],"id":60748118},{"atb":[[2.2,2.11]],"id":62600242},{"atb":[[2.04,3.94]],"id":65710029}],"con":true,"img":false}]}
{"op":"mcm","clk":"11541479642","pt":1719506178930,"mc":[{"id":"1.230178327","rc":[{"atb":[[2.32,0]],"id":62600242},{"atb":[[2.2,0]],"id":65710029}],"con":true,"img":false}]}
{"op":"mcm","clk":"11541479650","pt":1719506179033,"mc":[{"id":"1.230178327","rc":[{"atb":[[2.16,11.06]],"id":65710029}],"con":true,"img":false}]}
{"op":"mcm","clk":"11541479673","pt":1719506179242,"mc":[{"id":"1.230178327","rc":[{"atb":[[2.56,3.25]],"id":62600242}],"con":true,"img":false}]}
{"op":"mcm","clk":"11541479693","pt":1719506179434,"mc":[{"id":"1.230178327","rc":[{"atl":[[3.1,0]],"id":65710029}],"con":true,"img":false}]}
{"op":"mcm","clk":"11541479713","pt":1719506179618,"mc":[{"id":"1.230178327","rc":[{"atb":[[2.06,0]],"id":65710029}],"con":true,"img":false}]}
{"op":"mcm","clk":"11541479746","pt":1719506179917,"mc":[{"id":"1.230178327","rc":[{"atb":[[2.72,7.62]],"id":60748118},{"atb":[[2.04,1.94]],"id":65710029},{"atl":[[2.98,12.26]],"id":65710029}],"con":true,"img":false}]}
{"op":"mcm","clk":"11541479755","pt":1719506180022,"mc":[{"id":"1.230178327","rc":[{"atb":[[2.18,2]],"id":65710029},{"atl":[[3.05,7.47]],"id":65710029}],"con":true,"img":false}]}
{"op":"mcm","clk":"11541479766","pt":1719506180124,"mc":[{"id":"1.230178327","rc":[{"atb":[[2.68,0]],"id":60748118}],"con":true,"img":false}]}
{"op":"mcm","clk":"11541479782","pt":1719506180334,"mc":[{"id":"1.230178327","rc":[{"atb":[[2.66,0]],"id":60748118},{"atb":[[2.16,6.22]],"id":65710029},{"atl":[[2.98,14.79]],"id":65710029}],"con":true,"img":false}]}
{"op":"mcm","clk":"11541479792","pt":1719506180436,"mc":[{"id":"1.230178327","rc":[{"atb":[[1.03,0.52]],"id":65710029},{"atl":[[2.96,0.52]],"id":65710029}],"con":true,"img":false}]}
{"op":"mcm","clk":"11541479808","pt":1719506180642,"mc":[{"id":"1.230178327","rc":[{"atb":[[1.03,0.43]],"id":65710029},{"atl":[[2.98,13.79]],"id":65710029}],"con":true,"img":false}]}
{"op":"mcm","clk":"11541479819","pt":1719506180747,"mc":[{"id":"1.230178327","rc":[{"spn":3.4,"spf":"NaN","id":58221357},{"spn":3.71,"spf":"NaN","id":60748118},{"spn":3.59,"spf":"NaN","id":62600242},{"spn":2.28,"spf":1.0,"id":68687941},{"spn":5.07,"spf":"NaN","id":67674431},{"atb":[[2.18,8.16]],"id":65710029},{"spn":2.57,"spf":"NaN","id":65710029}],"con":true,"img":false}]}
{"op":"mcm","clk":"11541479826","pt":1719506180807,"mc":[{"id":"1.230178327","rc":[{"atb":[[1.03,0]],"id":65710029}],"con":true,"img":false}]}
{"op":"mcm","clk":"11541479837","pt":1719506180909,"mc":[{"id":"1.230178327","rc":[{"atb":[[2.2,0.43],[2.16,0]],"id":65710029}],"con":true,"img":false}]}
{"op":"mcm","clk":"11541479880","pt":1719506181420,"mc":[{"id":"1.230178327","rc":[{"atb":[[2.28,4]],"id":68687941}],"con":true,"img":false}]}
{"op":"mcm","clk":"11541479903","pt":1719506181732,"mc":[{"id":"1.230178327","rc":[{"atb":[[2.04,0]],"id":65710029}],"con":true,"img":false}]}
{"op":"mcm","clk":"11541479922","pt":1719506181938,"mc":[{"id":"1.230178327","rc":[{"atb":[[2.2,2.38]],"id":65710029},{"atl":[[2.96,1.37]],"id":65710029}],"con":true,"img":false}]}
{"op":"mcm","clk":"11541479931","pt":1719506182040,"mc":[{"id":"1.230178327","rc":[{"atl":[[2.96,9.27]],"id":65710029}],"con":true,"img":false}]}
{"op":"mcm","clk":"11541479953","pt":1719506182246,"mc":[{"id":"1.230178327","rc":[{"atl":[[2.98,2.53]],"id":65710029}],"con":true,"img":false}]}
{"op":"mcm","clk":"11541479977","pt":1719506182429,"mc":[{"id":"1.230178327","rc":[{"atl":[[3,12.2]],"id":65710029}],"con":true,"img":false}]}
{"op":"mcm","clk":"11541479985","pt":1719506182515,"mc":[{"id":"1.230178327","rc":[{"atl":[[3,11.36],[2.94,1]],"id":65710029}],"con":true,"img":false}]}
{"op":"mcm","clk":"11541480025","pt":1719506182926,"mc":[{"id":"1.230178327","rc":[{"atl":[[3,0]],"id":65710029}],"con":true,"img":false}]}
{"op":"mcm","clk":"11541480037","pt":1719506183030,"mc":[{"id":"1.230178327","rc":[{"atl":[[2.96,20.63]],"id":65710029}],"con":true,"img":false}]}
{"op":"mcm","clk":"11541480071","pt":1719506183340,"mc":[{"id":"1.230178327","rc":[{"atb":[[2.18,6.16]],"id":65710029}],"con":true,"img":false}]}
{"op":"mcm","clk":"11541480082","pt":1719506183444,"mc":[{"id":"1.230178327","rc":[{"atb":[[2.22,2]],"id":65710029}],"con":true,"img":false}]}
{"op":"mcm","clk":"11541480122","pt":1719506183817,"mc":[{"id":"1.230178327","rc":[{"atl":[[2.98,0],[2.94,4.69]],"id":65710029}],"con":true,"img":false}]}
{"op":"mcm","clk":"11541480142","pt":1719506184021,"mc":[{"id":"1.230178327","rc":[{"atl":[[2.96,1.37]],"id":65710029}],"con":true,"img":false}]}
{"op":"mcm","clk":"11541480219","pt":1719506184746,"mc":[{"id":"1.230178327","rc":[{"atl":[[2.94,16.52]],"id":65710029}],"con":true,"img":false}]}
{"op":"mcm","clk":"11541480368","pt":1719506186048,"mc":[{"id":"1.230178327","rc":[{"atb":[[2.7,0]],"id":60748118}],"con":true,"img":false}]}
{"op":"mcm","clk":"11541480379","pt":1719506186151,"mc":[{"id":"1.230178327","rc":[{"atb":[[2.74,2]],"id":60748118},{"atb":[[4,2.68]],"id":67674431}],"con":true,"img":false}]}
{"op":"mcm","clk":"11541480389","pt":1719506186210,"mc":[{"id":"1.230178327","rc":[{"atb":[[4,14.7]],"id":67674431}],"con":true,"img":false}]}
{"op":"mcm","clk":"11541480400","pt":1719506186322,"mc":[{"id":"1.230178327","rc":[{"atb":[[3.95,1.94]],"id":67674431}],"con":true,"img":false}]}
{"op":"mcm","clk":"11541480491","pt":1719506187346,"mc":[{"id":"1.230178327","rc":[{"atb":[[4,21.91]],"id":67674431}],"con":true,"img":false}]}
{"op":"mcm","clk":"11541480530","pt":1719506187722,"mc":[{"id":"1.230178327","rc":[{"atb":[[3.95,0]],"id":67674431}],"con":true,"img":false}]}
{"op":"mcm","clk":"11541480551","pt":1719506187927,"mc":[{"id":"1.230178327","rc":[{"atl":[[4.4,4.3]],"id":58221357},{"atl":[[4.7,6.08]],"id":60748118}],"con":true,"img":false}]}
{"op":"mcm","clk":"11541480559","pt":1719506188029,"mc":[{"id":"1.230178327","rc":[{"atl":[[4.3,4.31],[4.7,0]],"id":58221357},{"atl":[[4.8,1],[4.6,6.09]],"id":60748118}],"con":true,"img":false}]}
{"op":"mcm","clk":"11541480570","pt":1719506188127,"mc":[{"id":"1.230178327","rc":[{"atl":[[4.9,0.84]],"id":60748118}],"con":true,"img":false}]}
{"op":"mcm","clk":"11541480581","pt":1719506188231,"mc":[{"id":"1.230178327","rc":[{"atl":[[4.5,1]],"id":58221357}],"con":true,"img":false}]}
{"op":"mcm","clk":"11541480593","pt":1719506188334,"mc":[{"id":"1.230178327","rc":[{"atb":[[4,14.7]],"id":67674431}],"con":true,"img":false}]}
{"op":"mcm","clk":"11541480602","pt":1719506188437,"mc":[{"id":"1.230178327","rc":[{"atl":[[4.2,0.84]],"id":58221357},{"atl":[[4.5,0.84]],"id":60748118}],"con":true,"img":false}]}
{"op":"mcm","clk":"11541480617","pt":1719506188541,"mc":[{"id":"1.230178327","rc":[{"atl":[[4.6,0]],"id":58221357},{"atl":[[4.9,0]],"id":60748118}],"con":true,"img":false}]}
{"op":"mcm","clk":"11541480669","pt":1719506189061,"mc":[{"id":"1.230178327","rc":[{"atb":[[2.74,15.67]],"id":60748118},{"atl":[[4.5,7.53]],"id":60748118}],"con":true,"img":false}]}
{"op":"mcm","clk":"11541480709","pt":1719506189430,"mc":[{"id":"1.230178327","rc":[{"atl":[[4.7,5.24]],"id":60748118},{"atl":[[2.92,0.84]],"id":65710029}],"con":true,"img":false}]}
{"op":"mcm","clk":"11541480733","pt":1719506189633,"mc":[{"id":"1.230178327","rc":[{"atl":[[2.94,15.52]],"id":65710029}],"con":true,"img":false}]}
{"op":"mcm","clk":"11541480768","pt":1719506189947,"mc":[{"id":"1.230178327","rc":[{"atb":[[3.1,6]],"id":67674431}],"con":true,"img":false}]}
{"op":"mcm","clk":"11541480841","pt":1719506190628,"mc":[{"id":"1.230178327","rc":[{"atb":[[3.1,2.5]],"id":67674431}],"con":true,"img":false}]}
{"op":"mcm","clk":"11541480852","pt":1719506190727,"mc":[{"id":"1.230178327","rc":[{"atb":[[2.72,5.68]],"id":60748118}],"con":true,"img":false}]}
{"op":"mcm","clk":"11541480873","pt":1719506190935,"mc":[{"id":"1.230178327","rc":[{"atb":[[2.76,1.94]],"id":60748118}],"con":true,"img":false}]}
{"op":"mcm","clk":"11541480888","pt":1719506191041,"mc":[{"id":"1.230178327","rc":[{"atb":[[2.76,10.77]],"id":60748118},{"atl":[[2.92,4.12]],"id":65710029}],"con":true,"img":false}]}
{"op":"mcm","clk":"11541480902","pt":1719506191143,"mc":[{"id":"1.230178327","rc":[{"atb":[[2.28,2.11],[2.2,0]],"id":62600242}],"con":true,"img":false}]}
{"op":"mcm","clk":"11541480915","pt":1719506191248,"mc":[{"id":"1.230178327","rc":[{"atb":[[2.72,0]],"id":60748118},{"atl":[[2.94,11.83]],"id":65710029}],"con":true,"img":false}]}
{"op":"mcm","clk":"11541480948","pt":1719506191515,"mc":[{"id":"1.230178327","rc":[{"atb":[[2.74,13.56]],"id":60748118},{"atl":[[2.96,0.52],[2.94,11.8]],"id":65710029}],"con":true,"img":false}]}
{"op":"mcm","clk":"11541480959","pt":1719506191623,"mc":[{"id":"1.230178327","rc":[{"atl":[[2.9,1]],"id":65710029}],"con":true,"img":false}]}
{"op":"mcm","clk":"11541480999","pt":1719506192037,"mc":[{"id":"1.230178327","rc":[{"atb":[[2.74,2]],"id":60748118},{"atl":[[2.94,0]],"id":65710029}],"con":true,"img":false}]}
{"op":"mcm","clk":"11541481010","pt":1719506192137,"mc":[{"id":"1.230178327","rc":[{"atb":[[2.76,22.33]],"id":60748118},{"atl":[[2.92,15.92]],"id":65710029}],"con":true,"img":false}]}
{"op":"mcm","clk":"11541481124","pt":1719506193181,"mc":[{"id":"1.230178327","rc":[{"atl":[[4.3,0],[4.4,9.46]],"id":58221357},{"atl":[[4.6,0]],"id":60748118},{"atl":[[2.9,4.28]],"id":65710029}],"con":true,"img":false}]}
{"op":"mcm","clk":"11541481134","pt":1719506193237,"mc":[{"id":"1.230178327","rc":[{"atl":[[4.5,11.32],[4.4,4.3]],"id":58221357},{"atl":[[4.4,6.09]],"id":60748118}],"con":true,"img":false}]}
{"op":"mcm","clk":"11541481148","pt":1719506193335,"mc":[{"id":"1.230178327","rc":[{"atl":[[2.92,12.35]],"id":65710029}],"con":true,"img":false}]}
{"op":"mcm","clk":"11541481182","pt":1719506193647,"mc":[{"id":"1.230178327","rc":[{"atl":[[2.92,0.84]],"id":65710029}],"con":true,"img":false}]}
{"op":"mcm","clk":"11541481193","pt":1719506193751,"mc":[{"id":"1.230178327","rc":[{"atl":[[2.9,15.79]],"id":65710029}],"con":true,"img":false}]}
{"op":"mcm","clk":"11541481222","pt":1719506194062,"mc":[{"id":"1.230178327","rc":[{"atl":[[4.2,0]],"id":58221357},{"atb":[[1.93,0]],"id":65710029}],"con":true,"img":false}]}
{"op":"mcm","clk":"11541481233","pt":1719506194121,"mc":[{"id":"1.230178327","rc":[{"atl":[[4.5,1],[4.7,15.63]],"id":58221357}],"con":true,"img":false}]}
{"op":"mcm","clk":"11541481247","pt":1719506194226,"mc":[{"id":"1.230178327","rc":[{"atl":[[4.5,0.84]],"id":60748118}],"con":true,"img":false}]}
{"op":"mcm","clk":"11541481259","pt":1719506194324,"mc":[{"id":"1.230178327","rc":[{"atl":[[4.7,12.18]],"id":60748118}],"con":true,"img":false}]}
{"op":"mcm","clk":"11541481273","pt":1719506194437,"mc":[{"id":"1.230178327","rc":[{"atl":[[4.4,0]],"id":60748118}],"con":true,"img":false}]}
{"op":"mcm","clk":"11541481308","pt":1719506194741,"mc":[{"id":"1.230178327","rc":[{"atb":[[2.74,0]],"id":60748118}],"con":true,"img":false}]}
{"op":"mcm","clk":"11541481321","pt":1719506194845,"mc":[{"id":"1.230178327","rc":[{"atl":[[2.88,2.53]],"id":65710029}],"con":true,"img":false}]}
{"op":"mcm","clk":"11541481333","pt":1719506194948,"mc":[{"id":"1.230178327","rc":[{"atb":[[2.76,10.77],[2.78,3]],"id":60748118},{"atl":[[4.8,14.03],[4.5,0],[4.7,5.24]],"id":60748118},{"atl":[[2.88,6.22]],"id":65710029}],"con":true,"img":false}]}
{"op":"mcm","clk":"11541481343","pt":1719506195052,"mc":[{"id":"1.230178327","rc":[{"atl":[[4.6,6.14]],"id":60748118},{"atl":[[2.9,14.79]],"id":65710029}],"con":true,"img":false}]}
{"op":"mcm","clk":"11541481353","pt":1719506195155,"mc":[{"id":"1.230178327","rc":[{"atl":[[2.9,11.51]],"id":65710029}],"con":true,"img":false}]}
{"op":"mcm","clk":"11541481384","pt":1719506195422,"mc":[{"id":"1.230178327","rc":[{"atl":[[4.5,0.84]],"id":60748118}],"con":true,"img":false}]}
{"op":"mcm","clk":"11541481396","pt":1719506195524,"mc":[{"id":"1.230178327","rc":[{"atl":[[2.92,0]],"id":65710029}],"con":true,"img":false}]}
{"op":"mcm","clk":"11541481417","pt":1719506195733,"mc":[{"id":"1.230178327","rc":[{"atl":[[2.96,0]],"id":65710029}],"con":true,"img":false}]}
{"op":"mcm","clk":"11541481440","pt":1719506195933,"mc":[{"id":"1.230178327","rc":[{"atb":[[2.78,16.76]],"id":60748118}],"con":true,"img":false}]}
{"op":"mcm","clk":"11541481466","pt":1719506196140,"mc":[{"id":"1.230178327","rc":[{"atb":[[2.2,1.94]],"id":65710029}],"con":true,"img":false}]}
{"op":"mcm","clk":"11541481536","pt":1719506196868,"mc":[{"id":"1.230178327","rc":[{"atb":[[2.76,8.83]],"id":60748118},{"atb":[[2.2,0]],"id":65710029}],"con":true,"img":false}]}
{"op":"mcm","clk":"11541481551","pt":1719506196923,"mc":[{"id":"1.230178327","rc":[{"atl":[[2.86,0.84]],"id":65710029}],"con":true,"img":false}]}
{"op":"mcm","clk":"11541481561","pt":1719506197077,"mc":[{"id":"1.230178327","rc":[{"atb":[[2.8,1.94]],"id":60748118},{"atb":[[2.22,0],[2.2,1.94]],"id":65710029},{"atl":[[2.86,1.84]],"id":65710029}],"con":true,"img":false}]}
{"op":"mcm","clk":"11541481571","pt":1719506197133,"mc":[{"id":"1.230178327","rc":[{"atb":[[2.2,3.94]],"id":65710029}],"con":true,"img":false}]}
{"op":"mcm","clk":"11541481585","pt":1719506197231,"mc":[{"id":"1.230178327","rc":[{"atb":[[2.2,10.15]],"id":65710029}],"con":true,"img":false}]}
{"op":"mcm","clk":"11541481596","pt":1719506197334,"mc":[{"id":"1.230178327","rc":[{"atb":[[2.74,3.5]],"id":60748118}],"con":true,"img":false}]}
{"op":"mcm","clk":"11541481609","pt":1719506197439,"mc":[{"id":"1.230178327","rc":[{"atb":[[2.18,0]],"id":65710029}],"con":true,"img":false}]}
{"op":"mcm","clk":"11541481620","pt":1719506197545,"mc":[{"id":"1.230178327","rc":[{"atb":[[2.74,0],[2.78,3]],"id":60748118},{"atl":[[2.9,0]],"id":65710029}],"con":true,"img":false}]}
{"op":"mcm","clk":"11541481752","pt":1719506198640,"mc":[{"id":"1.230178327","rc":[{"atb":[[2.8,13.9]],"id":60748118},{"atl":[[2.86,13.3]],"id":65710029}],"con":true,"img":false}]}
{"op":"mcm","clk":"11541481788","pt":1719506198951,"mc":[{"id":"1.230178327","rc":[{"atl":[[4.5,9.38]],"id":60748118}],"con":true,"img":false}]}
{"op":"mcm","clk":"11541481799","pt":1719506199056,"mc":[{"id":"1.230178327","rc":[{"atl":[[2.88,3.69]],"id":65710029}],"con":true,"img":false}]}
{"op":"mcm","clk":"11541481810","pt":1719506199159,"mc":[{"id":"1.230178327","rc":[{"atl":[[4.7,0]],"id":60748118}],"con":true,"img":false}]}
{"op":"mcm","clk":"11541481832","pt":1719506199325,"mc":[{"id":"1.230178327","rc":[{"atl":[[4.3,5.11]],"id":58221357}],"con":true,"img":false}]}
{"op":"mcm","clk":"11541481844","pt":1719506199429,"mc":[{"id":"1.230178327","rc":[{"atl":[[4.2,4.31],[4.7,0]],"id":58221357},{"atl":[[4.6,0]],"id":60748118}],"con":true,"img":false}]}
{"op":"mcm","clk":"11541481856","pt":1719506199531,"mc":[{"id":"1.230178327","rc":[{"atl":[[4.4,10.26],[4.2,0]],"id":58221357}],"con":true,"img":false}]}
{"op":"mcm","clk":"11541481888","pt":1719506199837,"mc":[{"id":"1.230178327","rc":[{"atb":[[2.16,4.88]],"id":65710029}],"con":true,"img":false}]}
{"op":"mcm","clk":"11541481906","pt":1719506199941,"mc":[{"id":"1.230178327","rc":[{"atl":[[4.2,0.84]],"id":58221357},{"atl":[[4.8,1],[5.7,23.78]],"id":60748118}],"con":true,"img":false}]}
{"op":"mcm","clk":"11541481942","pt":1719506200255,"mc":[{"id":"1.230178327","rc":[{"atl":[[4.5,16.54]],"id":60748118}],"con":true,"img":false}]}
{"op":"mcm","clk":"11541481968","pt":1719506200466,"mc":[{"id":"1.230178327","rc":[{"atl":[[2.86,12.3]],"id":65710029}],"con":true,"img":false}]}
{"op":"mcm","clk":"11541482119","pt":1719506201825,"mc":[{"id":"1.230178327","rc":[{"atl":[[2.84,2.53]],"id":65710029}],"con":true,"img":false}]}
{"op":"mcm","clk":"11541482130","pt":1719506201927,"mc":[{"id":"1.230178327","rc":[{"atb":[[2.82,17.06]],"id":60748118},{"atl":[[2.84,11.79]],"id":65710029}],"con":true,"img":false}]}
{"op":"mcm","clk":"11541482149","pt":1719506202129,"mc":[{"id":"1.230178327","rc":[{"atl":[[2.88,0]],"id":65710029}],"con":true,"img":false}]}
{"op":"mcm","clk":"11541482160","pt":1719506202241,"mc":[{"id":"1.230178327","rc":[{"atb":[[2.76,0]],"id":60748118}],"con":true,"img":false}]}
{"op":"mcm","clk":"11541482215","pt":1719506202750,"mc":[{"id":"1.230178327","rc":[{"atb":[[2.8,13.12]],"id":60748118},{"atl":[[2.86,0.84]],"id":65710029}],"con":true,"img":false}]}
{"op":"mcm","clk":"11541482239","pt":1719506202960,"mc":[{"id":"1.230178327","rc":[{"atb":[[2.8,0]],"id":60748118}],"con":true,"img":false}]}
{"op":"mcm","clk":"11541482251","pt":1719506203060,"mc":[{"id":"1.230178327","rc":[{"atb":[[2.82,28.24],[1.03,9.19]],"id":60748118},{"atl":[[1000,6.8]],"id":60748118}],"con":true,"img":false}]}
{"op":"mcm","clk":"11541482261","pt":1719506203164,"mc":[{"id":"1.230178327","rc":[{"atb":[[2.82,11.18],[1.03,12.59],[2.84,1.94]],"id":60748118}],"con":true,"img":false}]}
{"op":"mcm","clk":"11541482279","pt":1719506203269,"mc":[{"id":"1.230178327","rc":[{"atb":[[1.03,11],[2.84,12.58]],"id":60748118},{"atl":[[1000,0.22]],"id":60748118}],"con":true,"img":false}]}
{"op":"mcm","clk":"11541482296","pt":1719506203434,"mc":[{"id":"1.230178327","rc":[{"atb":[[1.03,7.68]],"id":60748118},{"atl":[[1000,0.11]],"id":60748118}],"con":true,"img":false}]}
{"op":"mcm","clk":"11541482307","pt":1719506203534,"mc":[{"id":"1.230178327","rc":[{"atb":[[2.84,12.69],[2.78,0]],"id":60748118},{"atl":[[4.4,0.1],[1000,0]],"id":60748118}],"con":true,"img":false}]}
{"op":"mcm","clk":"11541482316","pt":1719506203641,"mc":[{"id":"1.230178327","rc":[{"atb":[[2.82,0],[1.03,7.48]],"id":60748118},{"atl":[[4.4,0.22]],"id":60748118},{"atb":[[2.22,2.5]],"id":65710029}],"con":true,"img":false}]}
{"op":"mcm","clk":"11541482323","pt":1719506203735,"mc":[{"id":"1.230178327","rc":[{"atb":[[2.84,12.89]],"id":60748118}],"con":true,"img":false}]}
{"op":"mcm","clk":"11541482331","pt":1719506203838,"mc":[{"id":"1.230178327","rc":[{"atl":[[2.84,22.87]],"id":65710029}],"con":true,"img":false}]}
{"op":"mcm","clk":"11541482340","pt":1719506203943,"mc":[{"id":"1.230178327","rc":[{"atl":[[2.82,0.84]],"id":65710029}],"con":true,"img":false}]}
