{"op":"mcm","clk":"11536380645","pt":1719425245582,"mc":[{"id":"1.230178319","marketDefinition":{"bspMarket":true,"turnInPlayEnabled":false,"persistenceEnabled":false,"marketBaseRate":5.0,"eventId":"33376062","eventTypeId":"4339","numberOfWinners":2,"bettingType":"ODDS","marketType":"PLACE","marketTime":"2024-06-27T15:28:00.000Z","suspendTime":"2024-06-27T15:28:00.000Z","bspReconciled":false,"complete":true,"inPlay":false,"crossMatching":false,"runnersVoidable":false,"numberOfActiveRunners":6,"betDelay":0,"status":"OPEN","runners":[{"status":"ACTIVE","sortPriority":1,"id":40214683,"name":"1. Corner Zoom"},{"status":"ACTIVE","sortPriority":2,"id":39959056,"name":"2. Endova Zoey"},{"status":"ACTIVE","sortPriority":3,"id":62766534,"name":"3. Glenvale Beau"},{"status":"ACTIVE","sortPriority":4,"id":69261147,"name":"4. Madam Tiger"},{"status":"ACTIVE","sortPriority":5,"id":70642246,"name":"5. Burgess Lana"},{"status":"ACTIVE","sortPriority":6,"id":56418091,"name":"6. Strike It Josie"}],"regulators":["MR_INT"],"venue":"Kinsley","countryCode":"GB","discountAllowed":false,"timezone":"Europe/London","openDate":"2024-06-27T13:36:00.000Z","version":5994643759,"name":"To Be Placed","eventName":"Kinsley 27th Jun"},"rc":[],"con":true,"img":false}]}
{"op":"mcm","clk":"11536381015","pt":1719425248523,"mc":[{"id":"1.230178319","marketDefinition":{"bspMarket":true,"turnInPlayEnabled":false,"persistenceEnabled":false,"marketBaseRate":5.0,"eventId":"33376062","eventTypeId":"4339","numberOfWinners":2,"bettingType":"ODDS","marketType":"PLACE","marketTime":"2024-06-27T15:28:00.000Z","suspendTime":"2024-06-27T15:28:00.000Z","bspReconciled":false,"complete":true,"inPlay":false,"crossMatching":false,"runnersVoidable":false,"numberOfActiveRunners":6,"betDelay":0,"status":"OPEN","runners":[{"status":"ACTIVE","sortPriority":1,"id":40214683,"name":"1. Corner Zoom"},{"status":"ACTIVE","sortPriority":2,"id":39959056,"name":"2. Endova Zoey"},{"status":"ACTIVE","sortPriority":3,"id":62766534,"name":"3. Glenvale Beau"},{"status":"ACTIVE","sortPriority":4,"id":69261147,"name":"4. Madam Tiger"},{"status":"ACTIVE","sortPriority":5,"id":70642246,"name":"5. Burgess Lana"},{"status":"ACTIVE","sortPriority":6,"id":56418091,"name":"6. Strike It Josie"}],"regulators":["MR_INT"],"venue":"Kinsley","countryCode":"GB","discountAllowed":true,"timezone":"Europe/London","openDate":"2024-06-27T13:36:00.000Z","version":5994643759,"name":"To Be Placed","eventName":"Kinsley 27th Jun"},"rc":[],"con":true,"img":false}]}
{"op":"mcm","clk":"11536837154","pt":1719431855434,"mc":[{"id":"1.230178319","rc":[{"atb":[[1.01,22.45]],"id":62766534},{"atl":[[1000,0.84]],"id":62766534},{"spn":500.5,"spf":"NaN","id":62766534},{"atb":[[1.03,7.48]],"id":39959056},{"atl":[[990,0.84]],"id":39959056},{"spn":495.51,"spf":"NaN","id":39959056},{"atb":[[1.02,11.22]],"id":40214683},{"atl":[[990,0.84]],"id":40214683},{"spn":495.51,"spf":"NaN","id":40214683},{"atb":[[1.02,11.22]],"id":56418091},{"atl":[[990,0.84]],"id":56418091},{"spn":495.51,"spf":"NaN","id":56418091},{"atb":[[1.03,7.48]],"id":69261147},{"atl":[[990,0.84]],"id":69261147},{"spn":495.51,"spf":"NaN","id":69261147},{"atb":[[1.02,11.22]],"id":70642246},{"atl":[[990,0.84]],"id":70642246},{"spn":495.51,"spf":"NaN","id":70642246}],"con":true,"img":false}]}
{"op":"mcm","clk":"11537083917","pt":1719435433776,"mc":[{"id":"1.230178319","rc":[{"atl":[[1000,0.32]],"id":62766534},{"atl":[[990,0.32]],"id":39959056},{"atl":[[990,0.32]],"id":40214683},{"atl":[[990,0.32]],"id":56418091},{"atl":[[990,0.32]],"id":69261147},{"atl":[[990,0.32]],"id":70642246}],"con":true,"img":false}]}
{"op":"mcm","clk":"11537232242","pt":1719437882515,"mc":[{"id":"1.230178319","marketDefinition":{"bspMarket":true,"turnInPlayEnabled":false,"persistenceEnabled":false,"marketBaseRate":5.0,"eventId":"33376062","eventTypeId":"4339","numberOfWinners":2,"bettingType":"ODDS","marketType":"PLACE","marketTime":"2024-06-27T15:28:00.000Z","suspendTime":"2024-06-27T15:28:00.000Z","bspReconciled":false,"complete":true,"inPlay":false,"crossMatching":false,"runnersVoidable":false,"numberOfActiveRunners":6,"betDelay":0,"status":"OPEN","runners":[{"status":"ACTIVE","sortPriority":1,"id":40214683,"name":"1. Corner Zoom"},{"status":"ACTIVE","sortPriority":2,"id":39959056,"name":"2. Endova Zoey"},{"status":"ACTIVE","sortPriority":3,"id":62766534,"name":"3. Glenvale Beau"},{"status":"ACTIVE","sortPriority":4,"id":69261147,"name":"4. Madam Tiger"},{"status":"ACTIVE","sortPriority":5,"id":70642246,"name":"5. Burgess Lana"},{"status":"ACTIVE","sortPriority":6,"id":56418091,"name":"6. Strike It Josie"}],"regulators":["MR_INT"],"venue":"Kinsley","countryCode":"GB","discountAllowed":true,"timezone":"Europe/London","openDate":"2024-06-27T13:36:00.000Z","version":5994643759,"name":"To Be Placed","eventName":"Kinsley 27th Jun"},"rc":[{"atb":[[1.01,22.45]],"id":62766534},{"atl":[[1000,0.33]],"id":62766534},{"spn":500.5,"spf":"NaN","id":62766534},{"atb":[[1.03,7.48]],"id":39959056},{"atl":[[990,0.33]],"id":39959056},{"spn":495.51,"spf":"NaN","id":39959056},{"atb":[[1.02,11.22]],"id":40214683},{"atl":[[990,0.33]],"id":40214683},{"spn":495.51,"spf":"NaN","id":40214683},{"atb":[[1.02,11.22]],"id":56418091},{"atl":[[990,0.33]],"id":56418091},{"spn":495.51,"spf":"NaN","id":56418091},{"atb":[[1.03,7.48]],"id":69261147},{"atl":[[990,0.33]],"id":69261147},{"spn":495.51,"spf":"NaN","id":69261147},{"atb":[[1.02,11.22]],"id":70642246},{"atl":[[990,0.33]],"id":70642246},{"spn":495.51,"spf":"NaN","id":70642246}],"con":true,"img":true}]}
{"op":"mcm","clk":"11537302203","pt":1719439031971,"mc":[{"id":"1.230178319","rc":[{"atb":[[1.01,22.45]],"id":62766534},{"atl":[[1000,0.17]],"id":62766534},{"atb":[[1.03,7.48]],"id":39959056},{"atl":[[990,0.17]],"id":39959056},{"atb":[[1.02,11.22]],"id":40214683},{"atl":[[990,0.17]],"id":40214683},{"atb":[[1.02,11.22]],"id":56418091},{"atl":[[990,0.17]],"id":56418091},{"atb":[[1.03,7.48]],"id":69261147},{"atl":[[990,0.17]],"id":69261147},{"atb":[[1.02,11.22]],"id":70642246},{"atl":[[990,0.17]],"id":70642246}],"con":true,"img":false}]}
{"op":"mcm","clk":"11537573369","pt":1719443282536,"mc":[{"id":"1.230178319","marketDefinition":{"bspMarket":true,"turnInPlayEnabled":false,"persistenceEnabled":false,"marketBaseRate":5.0,"eventId":"33376062","eventTypeId":"4339","numberOfWinners":2,"bettingType":"ODDS","marketType":"PLACE","marketTime":"2024-06-27T15:28:00.000Z","suspendTime":"2024-06-27T15:28:00.000Z","bspReconciled":false,"complete":true,"inPlay":false,"crossMatching":false,"runnersVoidable":false,"numberOfActiveRunners":6,"betDelay":0,"status":"OPEN","runners":[{"status":"ACTIVE","sortPriority":1,"id":40214683,"name":"1. Corner Zoom"},{"status":"ACTIVE","sortPriority":2,"id":39959056,"name":"2. Endova Zoey"},{"status":"ACTIVE","sortPriority":3,"id":62766534,"name":"3. Glenvale Beau"},{"status":"ACTIVE","sortPriority":4,"id":69261147,"name":"4. Madam Tiger"},{"status":"ACTIVE","sortPriority":5,"id":70642246,"name":"5. Burgess Lana"},{"status":"ACTIVE","sortPriority":6,"id":56418091,"name":"6. Strike It Josie"}],"regulators":["MR_INT"],"venue":"Kinsley","countryCode":"GB","discountAllowed":true,"timezone":"Europe/London","openDate":"2024-06-27T13:36:00.000Z","version":5994643759,"name":"To Be Placed","eventName":"Kinsley 27th Jun"},"rc":[{"atb":[[1.01,22.45]],"id":62766534},{"atl":[[1000,0.17]],"id":62766534},{"spn":500.5,"spf":"NaN","id":62766534},{"atb":[[1.03,7.48]],"id":39959056},{"atl":[[990,0.17]],"id":39959056},{"spn":495.51,"spf":"NaN","id":39959056},{"atb":[[1.02,11.22]],"id":40214683},{"atl":[[990,0.17]],"id":40214683},{"spn":495.51,"spf":"NaN","id":40214683},{"atb":[[1.02,11.22]],"id":56418091},{"atl":[[990,0.17]],"id":56418091},{"spn":495.51,"spf":"NaN","id":56418091},{"atb":[[1.03,7.48]],"id":69261147},{"atl":[[990,0.17]],"id":69261147},{"spn":495.51,"spf":"NaN","id":69261147},{"atb":[[1.02,11.22]],"id":70642246},{"atl":[[990,0.17]],"id":70642246},{"spn":495.51,"spf":"NaN","id":70642246}],"con":true,"img":true}]}
{"op":"mcm","clk":"11537954929","pt":1719448682556,"mc":[{"id":"1.230178319","marketDefinition":{"bspMarket":true,"turnInPlayEnabled":false,"persistenceEnabled":false,"marketBaseRate":5.0,"eventId":"33376062","eventTypeId":"4339","numberOfWinners":2,"bettingType":"ODDS","marketType":"PLACE","marketTime":"2024-06-27T15:28:00.000Z","suspendTime":"2024-06-27T15:28:00.000Z","bspReconciled":false,"complete":true,"inPlay":false,"crossMatching":false,"runnersVoidable":false,"numberOfActiveRunners":6,"betDelay":0,"status":"OPEN","runners":[{"status":"ACTIVE","sortPriority":1,"id":40214683,"name":"1. Corner Zoom"},{"status":"ACTIVE","sortPriority":2,"id":39959056,"name":"2. Endova Zoey"},{"status":"ACTIVE","sortPriority":3,"id":62766534,"name":"3. Glenvale Beau"},{"status":"ACTIVE","sortPriority":4,"id":69261147,"name":"4. Madam Tiger"},{"status":"ACTIVE","sortPriority":5,"id":70642246,"name":"5. Burgess Lana"},{"status":"ACTIVE","sortPriority":6,"id":56418091,"name":"6. Strike It Josie"}],"regulators":["MR_INT"],"venue":"Kinsley","countryCode":"GB","discountAllowed":true,"timezone":"Europe/London","openDate":"2024-06-27T13:36:00.000Z","version":5994643759,"name":"To Be Placed","eventName":"Kinsley 27th Jun"},"rc":[{"atb":[[1.01,22.45]],"id":62766534},{"atl":[[1000,0.17]],"id":62766534},{"spn":500.5,"spf":"NaN","id":62766534},{"atb":[[1.03,7.48]],"id":39959056},{"atl":[[990,0.17]],"id":39959056},{"spn":495.51,"spf":"NaN","id":39959056},{"atb":[[1.02,11.22]],"id":40214683},{"atl":[[990,0.17]],"id":40214683},{"spn":495.51,"spf":"NaN","id":40214683},{"atb":[[1.02,11.22]],"id":56418091},{"atl":[[990,0.17]],"id":56418091},{"spn":495.51,"spf":"NaN","id":56418091},{"atb":[[1.03,7.48]],"id":69261147},{"atl":[[990,0.17]],"id":69261147},{"spn":495.51,"spf":"NaN","id":69261147},{"atb":[[1.02,11.22]],"id":70642246},{"atl":[[990,0.17]],"id":70642246},{"spn":495.51,"spf":"NaN","id":70642246}],"con":true,"img":true}]}
{"op":"mcm","clk":"11538170592","pt":1719454082539,"mc":[{"id":"1.230178319","marketDefinition":{"bspMarket":true,"turnInPlayEnabled":false,"persistenceEnabled":false,"marketBaseRate":5.0,"eventId":"33376062","eventTypeId":"4339","numberOfWinners":2,"bettingType":"ODDS","marketType":"PLACE","marketTime":"2024-06-27T15:28:00.000Z","suspendTime":"2024-06-27T15:28:00.000Z","bspReconciled":false,"complete":true,"inPlay":false,"crossMatching":false,"runnersVoidable":false,"numberOfActiveRunners":6,"betDelay":0,"status":"OPEN","runners":[{"status":"ACTIVE","sortPriority":1,"id":40214683,"name":"1. Corner Zoom"},{"status":"ACTIVE","sortPriority":2,"id":39959056,"name":"2. Endova Zoey"},{"status":"ACTIVE","sortPriority":3,"id":62766534,"name":"3. Glenvale Beau"},{"status":"ACTIVE","sortPriority":4,"id":69261147,"name":"4. Madam Tiger"},{"status":"ACTIVE","sortPriority":5,"id":70642246,"name":"5. Burgess Lana"},{"status":"ACTIVE","sortPriority":6,"id":56418091,"name":"6. Strike It Josie"}],"regulators":["MR_INT"],"venue":"Kinsley","countryCode":"GB","discountAllowed":true,"timezone":"Europe/London","openDate":"2024-06-27T13:36:00.000Z","version":5994643759,"name":"To Be Placed","eventName":"Kinsley 27th Jun"},"rc":[{"atb":[[1.01,22.46]],"id":62766534},{"atl":[[1000,0.17]],"id":62766534},{"spn":500.5,"spf":"NaN","id":62766534},{"atb":[[1.03,7.49]],"id":39959056},{"atl":[[990,0.17]],"id":39959056},{"spn":495.51,"spf":"NaN","id":39959056},{"atb":[[1.02,11.23]],"id":40214683},{"atl":[[990,0.17]],"id":40214683},{"spn":495.51,"spf":"NaN","id":40214683},{"atb":[[1.02,11.23]],"id":56418091},{"atl":[[990,0.17]],"id":56418091},{"spn":495.51,"spf":"NaN","id":56418091},{"atb":[[1.03,7.49]],"id":69261147},{"atl":[[990,0.17]],"id":69261147},{"spn":495.51,"spf":"NaN","id":69261147},{"atb":[[1.02,11.23]],"id":70642246},{"atl":[[990,0.17]],"id":70642246},{"spn":495.51,"spf":"NaN","id":70642246}],"con":true,"img":true}]}
{"op":"mcm","clk":"11538368250","pt":1719459482567,"mc":[{"id":"1.230178319","marketDefinition":{"bspMarket":true,"turnInPlayEnabled":false,"persistenceEnabled":false,"marketBaseRate":5.0,"eventId":"33376062","eventTypeId":"4339","numberOfWinners":2,"bettingType":"ODDS","marketType":"PLACE","marketTime":"2024-06-27T15:28:00.000Z","suspendTime":"2024-06-27T15:28:00.000Z","bspReconciled":false,"complete":true,"inPlay":false,"crossMatching":false,"runnersVoidable":false,"numberOfActiveRunners":6,"betDelay":0,"status":"OPEN","runners":[{"status":"ACTIVE","sortPriority":1,"id":40214683,"name":"1. Corner Zoom"},{"status":"ACTIVE","sortPriority":2,"id":39959056,"name":"2. Endova Zoey"},{"status":"ACTIVE","sortPriority":3,"id":62766534,"name":"3. Glenvale Beau"},{"status":"ACTIVE","sortPriority":4,"id":69261147,"name":"4. Madam Tiger"},{"status":"ACTIVE","sortPriority":5,"id":70642246,"name":"5. Burgess Lana"},{"status":"ACTIVE","sortPriority":6,"id":56418091,"name":"6. Strike It Josie"}],"regulators":["MR_INT"],"venue":"Kinsley","countryCode":"GB","discountAllowed":true,"timezone":"Europe/London","openDate":"2024-06-27T13:36:00.000Z","version":5994643759,"name":"To Be Placed","eventName":"Kinsley 27th Jun"},"rc":[{"atb":[[1.01,22.46]],"id":62766534},{"atl":[[1000,0.17]],"id":62766534},{"spn":500.5,"spf":"NaN","id":62766534},{"atb":[[1.03,7.49]],"id":39959056},{"atl":[[990,0.17]],"id":39959056},{"spn":495.51,"spf":"NaN","id":39959056},{"atb":[[1.02,11.23]],"id":40214683},{"atl":[[990,0.17]],"id":40214683},{"spn":495.51,"spf":"NaN","id":40214683},{"atb":[[1.02,11.23]],"id":56418091},{"atl":[[990,0.17]],"id":56418091},{"spn":495.51,"spf":"NaN","id":56418091},{"atb":[[1.03,7.49]],"id":69261147},{"atl":[[990,0.17]],"id":69261147},{"spn":495.51,"spf":"NaN","id":69261147},{"atb":[[1.02,11.23]],"id":70642246},{"atl":[[990,0.17]],"id":70642246},{"spn":495.51,"spf":"NaN","id":70642246}],"con":true,"img":true}]}
{"op":"mcm","clk":"11538595376","pt":1719464882537,"mc":[{"id":"1.230178319","marketDefinition":{"bspMarket":true,"turnInPlayEnabled":false,"persistenceEnabled":false,"marketBaseRate":5.0,"eventId":"33376062","eventTypeId":"4339","numberOfWinners":2,"bettingType":"ODDS","marketType":"PLACE","marketTime":"2024-06-27T15:28:00.000Z","suspendTime":"2024-06-27T15:28:00.000Z","bspReconciled":false,"complete":true,"inPlay":false,"crossMatching":false,"runnersVoidable":false,"numberOfActiveRunners":6,"betDelay":0,"status":"OPEN","runners":[{"status":"ACTIVE","sortPriority":1,"id":40214683,"name":"1. Corner Zoom"},{"status":"ACTIVE","sortPriority":2,"id":39959056,"name":"2. Endova Zoey"},{"status":"ACTIVE","sortPriority":3,"id":62766534,"name":"3. Glenvale Beau"},{"status":"ACTIVE","sortPriority":4,"id":69261147,"name":"4. Madam Tiger"},{"status":"ACTIVE","sortPriority":5,"id":70642246,"name":"5. Burgess Lana"},{"status":"ACTIVE","sortPriority":6,"id":56418091,"name":"6. Strike It Josie"}],"regulators":["MR_INT"],"venue":"Kinsley","countryCode":"GB","discountAllowed":true,"timezone":"Europe/London","openDate":"2024-06-27T13:36:00.000Z","version":5994643759,"name":"To Be Placed","eventName":"Kinsley 27th Jun"},"rc":[{"atb":[[1.01,22.46]],"id":62766534},{"atl":[[1000,0.17]],"id":62766534},{"spn":500.5,"spf":"NaN","id":62766534},{"atb":[[1.03,7.48]],"id":39959056},{"atl":[[990,0.17]],"id":39959056},{"spn":495.51,"spf":"NaN","id":39959056},{"atb":[[1.02,11.23]],"id":40214683},{"atl":[[990,0.17]],"id":40214683},{"spn":495.51,"spf":"NaN","id":40214683},{"atb":[[1.02,11.23]],"id":56418091},{"atl":[[990,0.17]],"id":56418091},{"spn":495.51,"spf":"NaN","id":56418091},{"atb":[[1.03,7.48]],"id":69261147},{"atl":[[990,0.17]],"id":69261147},{"spn":495.51,"spf":"NaN","id":69261147},{"atb":[[1.02,11.23]],"id":70642246},{"atl":[[990,0.17]],"id":70642246},{"spn":495.51,"spf":"NaN","id":70642246}],"con":true,"img":true}]}
{"op":"mcm","clk":"11538907330","pt":1719471508675,"mc":[{"id":"1.230178319","rc":[{"atb":[[1.01,22.46]],"id":62766534},{"atl":[[1000,1.17]],"id":62766534},{"atb":[[1.03,7.48]],"id":39959056},{"atl":[[1000,1]],"id":39959056},{"atb":[[1.02,11.23]],"id":40214683},{"atl":[[1000,1]],"id":40214683},{"atb":[[1.02,11.23]],"id":56418091},{"atl":[[1000,1]],"id":56418091},{"atb":[[1.03,7.48]],"id":69261147},{"atl":[[1000,1]],"id":69261147},{"atb":[[1.02,11.23]],"id":70642246},{"atl":[[1000,1]],"id":70642246}],"con":true,"img":false}]}
{"op":"mcm","clk":"11538907336","pt":1719471508775,"mc":[{"id":"1.230178319","rc":[{"atb":[[1.07,2.48]],"id":62766534},{"atb":[[1.07,2.48]],"id":39959056},{"atb":[[1.07,2.48]],"id":40214683},{"atb":[[1.07,2.48]],"id":56418091},{"atb":[[1.07,2.48]],"id":69261147},{"atb":[[1.07,2.48]],"id":70642246}],"con":true,"img":false}]}
{"op":"mcm","clk":"11538907343","pt":1719471508878,"mc":[{"id":"1.230178319","rc":[{"atl":[[1000,0.65]],"id":62766534},{"atl":[[1000,0.48]],"id":39959056},{"atl":[[1000,0.48]],"id":40214683},{"atl":[[1000,0.48]],"id":56418091},{"atl":[[1000,0.48]],"id":69261147},{"atl":[[1000,0.48]],"id":70642246}],"con":true,"img":false}]}
{"op":"mcm","clk":"11538907355","pt":1719471509086,"mc":[{"id":"1.230178319","rc":[{"atl":[[1000,0.17]],"id":62766534},{"atl":[[1000,0]],"id":39959056},{"atl":[[1000,0]],"id":40214683},{"atl":[[1000,0]],"id":56418091},{"atl":[[1000,0]],"id":69261147},{"atl":[[1000,0]],"id":70642246}],"con":true,"img":false}]}
{"op":"mcm","clk":"11538907362","pt":1719471509188,"mc":[{"id":"1.230178319","rc":[{"atl":[[75,0.48]],"id":62766534},{"atl":[[75,0.48]],"id":39959056},{"atl":[[75,0.48]],"id":40214683},{"atl":[[75,0.48]],"id":56418091},{"atl":[[75,0.48]],"id":69261147},{"atl":[[75,0.48]],"id":70642246}],"con":true,"img":false}]}
{"op":"mcm","clk":"11539122523","pt":1719475682544,"mc":[{"id":"1.230178319","marketDefinition":{"bspMarket":true,"turnInPlayEnabled":false,"persistenceEnabled":false,"marketBaseRate":5.0,"eventId":"33376062","eventTypeId":"4339","numberOfWinners":2,"bettingType":"ODDS","marketType":"PLACE","marketTime":"2024-06-27T15:28:00.000Z","suspendTime":"2024-06-27T15:28:00.000Z","bspReconciled":false,"complete":true,"inPlay":false,"crossMatching":false,"runnersVoidable":false,"numberOfActiveRunners":6,"betDelay":0,"status":"OPEN","runners":[{"status":"ACTIVE","sortPriority":1,"id":40214683,"name":"1. Corner Zoom"},{"status":"ACTIVE","sortPriority":2,"id":39959056,"name":"2. Endova Zoey"},{"status":"ACTIVE","sortPriority":3,"id":62766534,"name":"3. Glenvale Beau"},{"status":"ACTIVE","sortPriority":4,"id":69261147,"name":"4. Madam Tiger"},{"status":"ACTIVE","sortPriority":5,"id":70642246,"name":"5. Burgess Lana"},{"status":"ACTIVE","sortPriority":6,"id":56418091,"name":"6. Strike It Josie"}],"regulators":["MR_INT"],"venue":"Kinsley","countryCode":"GB","discountAllowed":true,"timezone":"Europe/London","openDate":"2024-06-27T13:36:00.000Z","version":5994643759,"name":"To Be Placed","eventName":"Kinsley 27th Jun"},"rc":[{"atb":[[1.01,22.45],[1.07,2.48]],"id":62766534},{"atl":[[75,0.48],[1000,0.17]],"id":62766534},{"spn":38.03,"spf":"NaN","id":62766534},{"atb":[[1.03,7.48],[1.07,2.48]],"id":39959056},{"atl":[[75,0.48],[990,0.17]],"id":39959056},{"spn":38.03,"spf":"NaN","id":39959056},{"atb":[[1.02,11.22],[1.07,2.48]],"id":40214683},{"atl":[[75,0.48],[990,0.17]],"id":40214683},{"spn":38.03,"spf":"NaN","id":40214683},{"atb":[[1.02,11.22],[1.07,2.48]],"id":56418091},{"atl":[[75,0.48],[990,0.17]],"id":56418091},{"spn":38.03,"spf":"NaN","id":56418091},{"atb":[[1.03,7.48],[1.07,2.48]],"id":69261147},{"atl":[[75,0.48],[990,0.17]],"id":69261147},{"spn":38.03,"spf":"NaN","id":69261147},{"atb":[[1.02,11.22],[1.07,2.48]],"id":70642246},{"atl":[[75,0.48],[990,0.17]],"id":70642246},{"spn":38.03,"spf":"NaN","id":70642246}],"con":true,"img":true}]}
{"op":"mcm","clk":"11539438499","pt":1719481082545,"mc":[{"id":"1.230178319","marketDefinition":{"bspMarket":true,"turnInPlayEnabled":false,"persistenceEnabled":false,"marketBaseRate":5.0,"eventId":"33376062","eventTypeId":"4339","numberOfWinners":2,"bettingType":"ODDS","marketType":"PLACE","marketTime":"2024-06-27T15:28:00.000Z","suspendTime":"2024-06-27T15:28:00.000Z","bspReconciled":false,"complete":true,"inPlay":false,"crossMatching":false,"runnersVoidable":false,"numberOfActiveRunners":6,"betDelay":0,"status":"OPEN","runners":[{"status":"ACTIVE","sortPriority":1,"id":40214683,"name":"1. Corner Zoom"},{"status":"ACTIVE","sortPriority":2,"id":39959056,"name":"2. Endova Zoey"},{"status":"ACTIVE","sortPriority":3,"id":62766534,"name":"3. Glenvale Beau"},{"status":"ACTIVE","sortPriority":4,"id":69261147,"name":"4. Madam Tiger"},{"status":"ACTIVE","sortPriority":5,"id":70642246,"name":"5. Burgess Lana"},{"status":"ACTIVE","sortPriority":6,"id":56418091,"name":"6. Strike It Josie"}],"regulators":["MR_INT"],"venue":"Kinsley","countryCode":"GB","discountAllowed":true,"timezone":"Europe/London","openDate":"2024-06-27T13:36:00.000Z","version":5994643759,"name":"To Be Placed","eventName":"Kinsley 27th Jun"},"rc":[{"atb":[[1.01,22.45],[1.07,2.48]],"id":62766534},{"atl":[[75,0.48],[1000,0.17]],"id":62766534},{"spn":38.03,"spf":"NaN","id":62766534},{"atb":[[1.03,7.48],[1.07,2.48]],"id":39959056},{"atl":[[75,0.48],[990,0.17]],"id":39959056},{"spn":38.03,"spf":"NaN","id":39959056},{"atb":[[1.02,11.22],[1.07,2.48]],"id":40214683},{"atl":[[75,0.48],[990,0.17]],"id":40214683},{"spn":38.03,"spf":"NaN","id":40214683},{"atb":[[1.02,11.22],[1.07,2.48]],"id":56418091},{"atl":[[75,0.48],[990,0.17]],"id":56418091},{"spn":38.03,"spf":"NaN","id":56418091},{"atb":[[1.03,7.48],[1.07,2.48]],"id":69261147},{"atl":[[75,0.48],[990,0.17]],"id":69261147},{"spn":38.03,"spf":"NaN","id":69261147},{"atb":[[1.02,11.22],[1.07,2.48]],"id":70642246},{"atl":[[75,0.48],[990,0.17]],"id":70642246},{"spn":38.03,"spf":"NaN","id":70642246}],"con":true,"img":true}]}
{"op":"mcm","clk":"11540620720","pt":1719496537201,"mc":[{"id":"1.230178319","rc":[{"atb":[[1.01,22.47]],"id":62766534},{"atl":[[960,0.86],[1000,0.17]],"id":62766534},{"spn":38.03,"spf":"NaN","id":62766534},{"atb":[[1.03,7.49]],"id":39959056},{"atl":[[990,0.17],[970,0.86]],"id":39959056},{"spn":38.03,"spf":"NaN","id":39959056},{"atb":[[1.02,11.23]],"id":40214683},{"atl":[[990,0.17],[980,1.03]],"id":40214683},{"spn":38.03,"spf":"NaN","id":40214683},{"atb":[[1.02,11.23]],"id":56418091},{"atl":[[990,0.17],[980,0.86]],"id":56418091},{"spn":38.03,"spf":"NaN","id":56418091},{"atb":[[1.03,7.49]],"id":69261147},{"atl":[[990,2.28]],"id":69261147},{"spn":38.03,"spf":"NaN","id":69261147},{"atb":[[1.02,11.23]],"id":70642246},{"atl":[[990,2.21]],"id":70642246},{"spn":38.03,"spf":"NaN","id":70642246}],"con":true,"img":false}]}
{"op":"mcm","clk":"11540683334","pt":1719497282514,"mc":[{"id":"1.230178319","marketDefinition":{"bspMarket":true,"turnInPlayEnabled":false,"persistenceEnabled":false,"marketBaseRate":5.0,"eventId":"33376062","eventTypeId":"4339","numberOfWinners":2,"bettingType":"ODDS","marketType":"PLACE","marketTime":"2024-06-27T15:28:00.000Z","suspendTime":"2024-06-27T15:28:00.000Z","bspReconciled":false,"complete":true,"inPlay":false,"crossMatching":false,"runnersVoidable":false,"numberOfActiveRunners":6,"betDelay":0,"status":"OPEN","runners":[{"status":"ACTIVE","sortPriority":1,"id":40214683,"name":"1. Corner Zoom"},{"status":"ACTIVE","sortPriority":2,"id":39959056,"name":"2. Endova Zoey"},{"status":"ACTIVE","sortPriority":3,"id":62766534,"name":"3. Glenvale Beau"},{"status":"ACTIVE","sortPriority":4,"id":69261147,"name":"4. Madam Tiger"},{"status":"ACTIVE","sortPriority":5,"id":70642246,"name":"5. Burgess Lana"},{"status":"ACTIVE","sortPriority":6,"id":56418091,"name":"6. Strike It Josie"}],"regulators":["MR_INT"],"venue":"Kinsley","countryCode":"GB","discountAllowed":true,"timezone":"Europe/London","openDate":"2024-06-27T13:36:00.000Z","version":5994643759,"name":"To Be Placed","eventName":"Kinsley 27th Jun"},"rc":[{"atb":[[1.01,22.46],[1.07,2.48]],"id":62766534},{"atl":[[75,0.48],[960,0.86],[1000,0.17]],"id":62766534},{"spn":38.03,"spf":"NaN","id":62766534},{"atb":[[1.03,7.49],[1.07,2.48]],"id":39959056},{"atl":[[75,0.48],[970,0.86],[990,0.17]],"id":39959056},{"spn":38.03,"spf":"NaN","id":39959056},{"atb":[[1.02,11.23],[1.07,2.48]],"id":40214683},{"atl":[[75,0.48],[980,1.03],[990,0.17]],"id":40214683},{"spn":38.03,"spf":"NaN","id":40214683},{"atb":[[1.02,11.23],[1.07,2.48]],"id":56418091},{"atl":[[75,0.48],[980,0.86],[990,0.17]],"id":56418091},{"spn":38.03,"spf":"NaN","id":56418091},{"atb":[[1.03,7.49],[1.07,2.48]],"id":69261147},{"atl":[[75,0.48],[990,2.28]],"id":69261147},{"spn":38.03,"spf":"NaN","id":69261147},{"atb":[[1.02,11.23],[1.07,2.48]],"id":70642246},{"atl":[[75,0.48],[990,2.21]],"id":70642246},{"spn":38.03,"spf":"NaN","id":70642246}],"con":true,"img":true}]}
{"op":"mcm","clk":"11540920687","pt":1719499983341,"mc":[{"id":"1.230178319","rc":[{"atb":[[1.01,22.46],[1.04,1]],"id":62766534},{"atl":[[960,0.86]],"id":62766534},{"atb":[[1.03,7.49],[1.04,1]],"id":39959056},{"atl":[[970,0.86]],"id":39959056},{"atb":[[1.02,11.23],[1.04,1]],"id":40214683},{"atl":[[980,1.03]],"id":40214683},{"atb":[[1.02,11.23],[1.04,1]],"id":56418091},{"atl":[[980,0.86]],"id":56418091},{"atb":[[1.03,7.49],[1.04,1]],"id":69261147},{"atl":[[990,2.28]],"id":69261147},{"atb":[[1.02,11.23],[1.04,1]],"id":70642246},{"atl":[[990,2.21]],"id":70642246}],"con":true,"img":false}]}
{"op":"mcm","clk":"11540920700","pt":1719499983546,"mc":[{"id":"1.230178319","rc":[{"atb":[[1.04,0.25]],"id":62766534},{"atb":[[1.04,0.25]],"id":39959056},{"atb":[[1.04,0.25]],"id":40214683},{"atb":[[1.04,0.25]],"id":56418091},{"atb":[[1.04,0.25]],"id":69261147},{"atb":[[1.04,0.25]],"id":70642246}],"con":true,"img":false}]}
{"op":"mcm","clk":"11540920727","pt":1719499983858,"mc":[{"id":"1.230178319","rc":[{"atb":[[1.04,0]],"id":62766534},{"atb":[[1.04,0]],"id":39959056},{"atb":[[1.04,0]],"id":40214683},{"atb":[[1.04,0]],"id":56418091},{"atb":[[1.04,0]],"id":69261147},{"atb":[[1.04,0]],"id":70642246}],"con":true,"img":false}]}
{"op":"mcm","clk":"11540920737","pt":1719499983961,"mc":[{"id":"1.230178319","rc":[{"atb":[[1.2,0.25]],"id":62766534},{"atb":[[1.2,0.25]],"id":39959056},{"atb":[[1.2,0.25]],"id":40214683},{"atb":[[1.2,0.25]],"id":56418091},{"atb":[[1.2,0.25]],"id":69261147},{"atb":[[1.2,0.25]],"id":70642246}],"con":true,"img":false}]}
{"op":"mcm","clk":"11540951962","pt":1719500379707,"mc":[{"id":"1.230178319","rc":[{"spn":38.1,"spf":"NaN","id":62766534},{"atb":[[1.09,43.87]],"id":39959056},{"spn":38.1,"spf":"NaN","id":39959056},{"spn":38.1,"spf":"NaN","id":40214683},{"spn":38.1,"spf":"NaN","id":56418091},{"spn":38.1,"spf":"NaN","id":69261147},{"spn":38.1,"spf":"NaN","id":70642246}],"con":true,"img":false}]}
{"op":"mcm","clk":"11540951987","pt":1719500380021,"mc":[{"id":"1.230178319","rc":[{"atb":[[1.09,43.87]],"id":70642246}],"con":true,"img":false}]}
{"op":"mcm","clk":"11540952005","pt":1719500380224,"mc":[{"id":"1.230178319","rc":[{"atb":[[1.09,43.87]],"id":69261147}],"con":true,"img":false}]}
{"op":"mcm","clk":"11540952177","pt":1719500382111,"mc":[{"id":"1.230178319","marketDefinition":{"bspMarket":true,"turnInPlayEnabled":false,"persistenceEnabled":false,"marketBaseRate":5.0,"eventId":"33376062","eventTypeId":"4339","numberOfWinners":2,"bettingType":"ODDS","marketType":"PLACE","marketTime":"2024-06-27T15:28:00.000Z","suspendTime":"2024-06-27T15:28:00.000Z","bspReconciled":false,"complete":true,"inPlay":false,"crossMatching":true,"runnersVoidable":false,"numberOfActiveRunners":6,"betDelay":0,"status":"OPEN","runners":[{"status":"ACTIVE","sortPriority":1,"id":40214683,"name":"1. Corner Zoom"},{"status":"ACTIVE","sortPriority":2,"id":39959056,"name":"2. Endova Zoey"},{"status":"ACTIVE","sortPriority":3,"id":62766534,"name":"3. Glenvale Beau"},{"status":"ACTIVE","sortPriority":4,"id":69261147,"name":"4. Madam Tiger"},{"status":"ACTIVE","sortPriority":5,"id":70642246,"name":"5. Burgess Lana"},{"status":"ACTIVE","sortPriority":6,"id":56418091,"name":"6. Strike It Josie"}],"regulators":["MR_INT"],"venue":"Kinsley","countryCode":"GB","discountAllowed":true,"timezone":"Europe/London","openDate":"2024-06-27T13:36:00.000Z","version":5994643759,"name":"To Be Placed","eventName":"Kinsley 27th Jun"},"rc":[],"con":true,"img":false}]}
{"op":"mcm","clk":"11540970906","pt":1719500614977,"mc":[{"id":"1.230178319","rc":[{"atb":[[1.01,22.47]],"id":62766534},{"atl":[[960,0.86]],"id":62766534},{"atb":[[1.03,7.49],[1.09,43.92]],"id":39959056},{"atl":[[970,0.86]],"id":39959056},{"atb":[[1.02,11.23]],"id":40214683},{"atl":[[980,1.03]],"id":40214683},{"atb":[[1.02,11.23]],"id":56418091},{"atl":[[980,0.86]],"id":56418091},{"atb":[[1.03,7.49],[1.11,38.48],[1.09,43.92]],"id":69261147},{"atl":[[990,2.28]],"id":69261147},{"atb":[[1.02,11.23],[1.09,43.92]],"id":70642246},{"atl":[[990,2.21]],"id":70642246}],"con":true,"img":false}]}
{"op":"mcm","clk":"11540970924","pt":1719500615180,"mc":[{"id":"1.230178319","rc":[{"atb":[[1.11,38.48]],"id":39959056}],"con":true,"img":false}]}
{"op":"mcm","clk":"11540970983","pt":1719500615759,"mc":[{"id":"1.230178319","rc":[{"atb":[[1.11,38.48]],"id":70642246}],"con":true,"img":false}]}
{"op":"mcm","clk":"11540972388","pt":1719500631986,"mc":[{"id":"1.230178319","rc":[{"atb":[[1.09,0]],"id":39959056},{"atb":[[1.09,0]],"id":69261147}],"con":true,"img":false}]}
{"op":"mcm","clk":"11540972402","pt":1719500632194,"mc":[{"id":"1.230178319","rc":[{"atb":[[1.13,30.4]],"id":69261147}],"con":true,"img":false}]}
{"op":"mcm","clk":"11540972418","pt":1719500632386,"mc":[{"id":"1.230178319","rc":[{"atb":[[1.13,30.4]],"id":39959056}],"con":true,"img":false}]}
{"op":"mcm","clk":"11540972426","pt":1719500632491,"mc":[{"id":"1.230178319","rc":[{"atb":[[1.09,0]],"id":70642246}],"con":true,"img":false}]}
{"op":"mcm","clk":"11540972453","pt":1719500632697,"mc":[{"id":"1.230178319","rc":[{"atb":[[1.13,30.4]],"id":70642246}],"con":true,"img":false}]}
{"op":"mcm","clk":"11540974310","pt":1719500654425,"mc":[{"id":"1.230178319","rc":[{"atb":[[1.11,0]],"id":39959056}],"con":true,"img":false}]}
{"op":"mcm","clk":"11540974319","pt":1719500654528,"mc":[{"id":"1.230178319","rc":[{"atb":[[1.11,0]],"id":69261147}],"con":true,"img":false}]}
{"op":"mcm","clk":"11540974337","pt":1719500654732,"mc":[{"id":"1.230178319","rc":[{"atb":[[1.11,0]],"id":70642246}],"con":true,"img":false}]}
{"op":"mcm","clk":"11540974395","pt":1719500655201,"mc":[{"id":"1.230178319","rc":[{"atb":[[1.15,28.22]],"id":39959056}],"con":true,"img":false}]}
{"op":"mcm","clk":"11540974425","pt":1719500655508,"mc":[{"id":"1.230178319","rc":[{"atb":[[1.15,28.22]],"id":69261147}],"con":true,"img":false}]}
{"op":"mcm","clk":"11540974456","pt":1719500655925,"mc":[{"id":"1.230178319","rc":[{"atb":[[1.15,28.22]],"id":70642246}],"con":true,"img":false}]}
{"op":"mcm","clk":"11540975625","pt":1719500669237,"mc":[{"id":"1.230178319","rc":[{"atb":[[1.13,0]],"id":69261147}],"con":true,"img":false}]}
{"op":"mcm","clk":"11540975634","pt":1719500669340,"mc":[{"id":"1.230178319","rc":[{"atb":[[1.13,0]],"id":70642246}],"con":true,"img":false}]}
{"op":"mcm","clk":"11540975677","pt":1719500669915,"mc":[{"id":"1.230178319","rc":[{"atb":[[1.13,0]],"id":39959056}],"con":true,"img":false}]}
{"op":"mcm","clk":"11540975689","pt":1719500670116,"mc":[{"id":"1.230178319","rc":[{"atb":[[1.17,23.25]],"id":70642246}],"con":true,"img":false}]}
{"op":"mcm","clk":"11540975709","pt":1719500670323,"mc":[{"id":"1.230178319","rc":[{"atb":[[1.17,23.25]],"id":69261147}],"con":true,"img":false}]}
{"op":"mcm","clk":"11540975726","pt":1719500670535,"mc":[{"id":"1.230178319","rc":[{"atb":[[1.17,23.25]],"id":39959056}],"con":true,"img":false}]}
{"op":"mcm","clk":"11540977607","pt":1719500690742,"mc":[{"id":"1.230178319","rc":[{"atb":[[1.15,0]],"id":39959056}],"con":true,"img":false}]}
{"op":"mcm","clk":"11540977637","pt":1719500691045,"mc":[{"id":"1.230178319","rc":[{"atb":[[1.15,0]],"id":69261147}],"con":true,"img":false}]}
{"op":"mcm","clk":"11540977647","pt":1719500691151,"mc":[{"id":"1.230178319","rc":[{"atb":[[1.15,0]],"id":70642246}],"con":true,"img":false}]}
{"op":"mcm","clk":"11540977723","pt":1719500692073,"mc":[{"id":"1.230178319","rc":[{"atb":[[1.19,22.28]],"id":69261147}],"con":true,"img":false}]}
{"op":"mcm","clk":"11540977733","pt":1719500692128,"mc":[{"id":"1.230178319","rc":[{"atb":[[1.19,22.28]],"id":39959056}],"con":true,"img":false}]}
{"op":"mcm","clk":"11540977769","pt":1719500692749,"mc":[{"id":"1.230178319","rc":[{"atb":[[1.19,22.28]],"id":70642246}],"con":true,"img":false}]}
{"op":"mcm","clk":"11540978786","pt":1719500705542,"mc":[{"id":"1.230178319","rc":[{"atb":[[1.17,0]],"id":39959056},{"atb":[[1.17,0]],"id":70642246}],"con":true,"img":false}]}
{"op":"mcm","clk":"11540978802","pt":1719500705752,"mc":[{"id":"1.230178319","rc":[{"atb":[[1.17,0]],"id":69261147}],"con":true,"img":false}]}
{"op":"mcm","clk":"11540978815","pt":1719500705960,"mc":[{"id":"1.230178319","rc":[{"atb":[[1.21,18.82]],"id":39959056}],"con":true,"img":false}]}
{"op":"mcm","clk":"11540978824","pt":1719500706064,"mc":[{"id":"1.230178319","rc":[{"atb":[[1.21,18.82]],"id":70642246}],"con":true,"img":false}]}
{"op":"mcm","clk":"11540980246","pt":1719500722976,"mc":[{"id":"1.230178319","rc":[{"atb":[[1.21,18.82]],"id":69261147}],"con":true,"img":false}]}
{"op":"mcm","clk":"11540980642","pt":1719500727983,"mc":[{"id":"1.230178319","rc":[{"atb":[[1.19,0]],"id":39959056},{"atb":[[1.19,0]],"id":69261147}],"con":true,"img":false}]}
{"op":"mcm","clk":"11540980668","pt":1719500728394,"mc":[{"id":"1.230178319","rc":[{"atb":[[1.19,0]],"id":70642246}],"con":true,"img":false}]}
{"op":"mcm","clk":"11540980675","pt":1719500728498,"mc":[{"id":"1.230178319","rc":[{"atb":[[1.23,18.4]],"id":39959056}],"con":true,"img":false}]}
{"op":"mcm","clk":"11540980689","pt":1719500728653,"mc":[{"id":"1.230178319","rc":[{"atb":[[1.23,18.4]],"id":69261147}],"con":true,"img":false}]}
{"op":"mcm","clk":"11540980706","pt":1719500728966,"mc":[{"id":"1.230178319","rc":[{"atb":[[1.23,18.4]],"id":70642246}],"con":true,"img":false}]}
{"op":"mcm","clk":"11540981656","pt":1719500741594,"mc":[{"id":"1.230178319","rc":[{"atb":[[1.21,0]],"id":39959056},{"atb":[[1.21,0]],"id":69261147}],"con":true,"img":false}]}
{"op":"mcm","clk":"11540981673","pt":1719500741803,"mc":[{"id":"1.230178319","rc":[{"atb":[[1.25,15.81]],"id":39959056},{"atb":[[1.21,0]],"id":70642246}],"con":true,"img":false}]}
{"op":"mcm","clk":"11540981685","pt":1719500742007,"mc":[{"id":"1.230178319","rc":[{"atb":[[1.25,15.81]],"id":69261147},{"atb":[[1.25,15.81]],"id":70642246}],"con":true,"img":false}]}
{"op":"mcm","clk":"11540983169","pt":1719500759950,"mc":[{"id":"1.230178319","rc":[{"atb":[[1.23,0]],"id":39959056},{"spn":38.12,"spf":"NaN","id":39959056},{"spn":38.12,"spf":"NaN","id":69261147},{"spn":38.12,"spf":"NaN","id":70642246}],"con":true,"img":false}]}
{"op":"mcm","clk":"11540983180","pt":1719500760057,"mc":[{"id":"1.230178319","rc":[{"atb":[[1.23,0]],"id":69261147}],"con":true,"img":false}]}
{"op":"mcm","clk":"11540983199","pt":1719500760261,"mc":[{"id":"1.230178319","rc":[{"atb":[[1.23,0]],"id":70642246}],"con":true,"img":false}]}
{"op":"mcm","clk":"11540983224","pt":1719500760570,"mc":[{"id":"1.230178319","rc":[{"atb":[[1.27,15.68]],"id":69261147}],"con":true,"img":false}]}
{"op":"mcm","clk":"11540983232","pt":1719500760669,"mc":[{"id":"1.230178319","rc":[{"atb":[[1.27,15.68]],"id":39959056}],"con":true,"img":false}]}
{"op":"mcm","clk":"11540983260","pt":1719500760949,"mc":[{"id":"1.230178319","rc":[{"atb":[[1.27,15.68]],"id":70642246}],"con":true,"img":false}]}
{"op":"mcm","clk":"11540984675","pt":1719500777376,"mc":[{"id":"1.230178319","rc":[{"atb":[[1.25,0]],"id":39959056},{"atb":[[1.25,0]],"id":69261147}],"con":true,"img":false}]}
{"op":"mcm","clk":"11540984686","pt":1719500777569,"mc":[{"id":"1.230178319","rc":[{"atb":[[1.29,13.62]],"id":69261147},{"atb":[[1.25,0]],"id":70642246}],"con":true,"img":false}]}
{"op":"mcm","clk":"11540984703","pt":1719500777786,"mc":[{"id":"1.230178319","rc":[{"atb":[[1.29,13.62]],"id":39959056},{"atb":[[1.29,13.62]],"id":70642246}],"con":true,"img":false}]}
{"op":"mcm","clk":"11540986107","pt":1719500794512,"mc":[{"id":"1.230178319","rc":[{"atb":[[1.27,0]],"id":39959056}],"con":true,"img":false}]}
{"op":"mcm","clk":"11540986136","pt":1719500794819,"mc":[{"id":"1.230178319","rc":[{"atb":[[1.27,0]],"id":69261147},{"atb":[[1.27,0]],"id":70642246}],"con":true,"img":false}]}
{"op":"mcm","clk":"11540986162","pt":1719500795077,"mc":[{"id":"1.230178319","rc":[{"atb":[[1.31,13.65]],"id":39959056},{"atb":[[1.31,13.65]],"id":70642246}],"con":true,"img":false}]}
{"op":"mcm","clk":"11540986186","pt":1719500795393,"mc":[{"id":"1.230178319","rc":[{"atb":[[1.31,13.65]],"id":69261147}],"con":true,"img":false}]}
{"op":"mcm","clk":"11540987784","pt":1719500814225,"mc":[{"id":"1.230178319","rc":[{"atb":[[1.29,0]],"id":39959056}],"con":true,"img":false}]}
{"op":"mcm","clk":"11540987799","pt":1719500814429,"mc":[{"id":"1.230178319","rc":[{"atb":[[1.29,0]],"id":69261147},{"atb":[[1.29,0]],"id":70642246}],"con":true,"img":false}]}
{"op":"mcm","clk":"11540987819","pt":1719500814587,"mc":[{"id":"1.230178319","rc":[{"atb":[[1.33,11.97]],"id":39959056},{"atb":[[1.33,11.97]],"id":69261147}],"con":true,"img":false}]}
{"op":"mcm","clk":"11540987836","pt":1719500814793,"mc":[{"id":"1.230178319","rc":[{"atb":[[1.33,11.97]],"id":70642246}],"con":true,"img":false}]}
{"op":"mcm","clk":"11540988995","pt":1719500827631,"mc":[{"id":"1.230178319","rc":[{"atb":[[1.31,0]],"id":39959056},{"spn":38.16,"spf":"NaN","id":39959056},{"spn":38.16,"spf":"NaN","id":69261147},{"spn":38.16,"spf":"NaN","id":70642246}],"con":true,"img":false}]}
{"op":"mcm","clk":"11540989030","pt":1719500828002,"mc":[{"id":"1.230178319","rc":[{"atb":[[1.31,0]],"id":70642246}],"con":true,"img":false}]}
{"op":"mcm","clk":"11540989041","pt":1719500828106,"mc":[{"id":"1.230178319","rc":[{"atb":[[1.31,0]],"id":69261147}],"con":true,"img":false}]}
{"op":"mcm","clk":"11540989056","pt":1719500828308,"mc":[{"id":"1.230178319","rc":[{"atb":[[1.35,12.09]],"id":39959056}],"con":true,"img":false}]}
{"op":"mcm","clk":"11540989063","pt":1719500828413,"mc":[{"id":"1.230178319","rc":[{"atb":[[1.35,12.09]],"id":69261147}],"con":true,"img":false}]}
{"op":"mcm","clk":"11540989081","pt":1719500828626,"mc":[{"id":"1.230178319","rc":[{"atb":[[1.35,12.09]],"id":70642246}],"con":true,"img":false}]}
{"op":"mcm","clk":"11540989325","pt":1719500831800,"mc":[{"id":"1.230178319","rc":[{"atb":[[1.33,0]],"id":69261147}],"con":true,"img":false}]}
{"op":"mcm","clk":"11540989331","pt":1719500831902,"mc":[{"id":"1.230178319","rc":[{"atb":[[1.33,0]],"id":39959056}],"con":true,"img":false}]}
{"op":"mcm","clk":"11540989343","pt":1719500832109,"mc":[{"id":"1.230178319","rc":[{"atb":[[1.37,10.68]],"id":69261147},{"atb":[[1.33,0]],"id":70642246}],"con":true,"img":false}]}
{"op":"mcm","clk":"11540989357","pt":1719500832318,"mc":[{"id":"1.230178319","rc":[{"atb":[[1.37,10.68]],"id":39959056}],"con":true,"img":false}]}
{"op":"mcm","clk":"11540989362","pt":1719500832423,"mc":[{"id":"1.230178319","rc":[{"atb":[[1.37,10.68]],"id":70642246}],"con":true,"img":false}]}
{"op":"mcm","clk":"11540992450","pt":1719500866446,"mc":[{"id":"1.230178319","rc":[{"atb":[[1.35,0]],"id":39959056},{"atb":[[1.35,0]],"id":69261147}],"con":true,"img":false}]}
{"op":"mcm","clk":"11540992476","pt":1719500866761,"mc":[{"id":"1.230178319","rc":[{"atb":[[1.39,10.85]],"id":69261147},{"atb":[[1.35,0]],"id":70642246}],"con":true,"img":false}]}
{"op":"mcm","clk":"11540992505","pt":1719500867069,"mc":[{"id":"1.230178319","rc":[{"atb":[[1.39,10.85]],"id":39959056}],"con":true,"img":false}]}
{"op":"mcm","clk":"11540992528","pt":1719500867379,"mc":[{"id":"1.230178319","rc":[{"atb":[[1.39,10.85]],"id":70642246}],"con":true,"img":false}]}
{"op":"mcm","clk":"11540993764","pt":1719500881860,"mc":[{"id":"1.230178319","rc":[{"atb":[[1.42,2.11]],"id":39959056},{"atb":[[1.42,2.11]],"id":69261147},{"atb":[[1.42,2.11]],"id":70642246}],"con":true,"img":false}]}
{"op":"mcm","clk":"11540994071","pt":1719500885587,"mc":[{"id":"1.230178319","rc":[{"atb":[[1.37,0]],"id":39959056},{"atb":[[1.37,0]],"id":69261147}],"con":true,"img":false}]}
{"op":"mcm","clk":"11540994089","pt":1719500885788,"mc":[{"id":"1.230178319","rc":[{"atb":[[1.44,8.98]],"id":69261147},{"atb":[[1.37,0]],"id":70642246}],"con":true,"img":false}]}
{"op":"mcm","clk":"11540994107","pt":1719500885997,"mc":[{"id":"1.230178319","rc":[{"atb":[[1.44,8.98]],"id":39959056},{"atb":[[1.44,8.98]],"id":70642246}],"con":true,"img":false}]}
{"op":"mcm","clk":"11540995384","pt":1719500903083,"mc":[{"id":"1.230178319","rc":[{"spn":38.22,"spf":"NaN","id":39959056},{"atb":[[1.39,0]],"id":69261147},{"spn":38.22,"spf":"NaN","id":69261147},{"spn":38.22,"spf":"NaN","id":70642246}],"con":true,"img":false}]}
{"op":"mcm","clk":"11540995399","pt":1719500903294,"mc":[{"id":"1.230178319","rc":[{"atb":[[1.39,0]],"id":39959056}],"con":true,"img":false}]}
{"op":"mcm","clk":"11540995442","pt":1719500903920,"mc":[{"id":"1.230178319","rc":[{"atb":[[1.46,9.2]],"id":39959056},{"atb":[[1.46,9.2]],"id":69261147}],"con":true,"img":false}]}
{"op":"mcm","clk":"11540995469","pt":1719500904178,"mc":[{"id":"1.230178319","rc":[{"atb":[[1.39,0]],"id":70642246}],"con":true,"img":false}]}
{"op":"mcm","clk":"11540995515","pt":1719500904801,"mc":[{"id":"1.230178319","rc":[{"atb":[[1.46,9.2]],"id":70642246}],"con":true,"img":false}]}
{"op":"mcm","clk":"11540996645","pt":1719500921111,"mc":[{"id":"1.230178319","rc":[{"atb":[[1.44,0]],"id":39959056}],"con":true,"img":false}]}
{"op":"mcm","clk":"11540996660","pt":1719500921321,"mc":[{"id":"1.230178319","rc":[{"atb":[[1.44,0]],"id":69261147}],"con":true,"img":false}]}
{"op":"mcm","clk":"11540996676","pt":1719500921528,"mc":[{"id":"1.230178319","rc":[{"atb":[[1.48,8.23]],"id":39959056}],"con":true,"img":false}]}
{"op":"mcm","clk":"11540996681","pt":1719500921632,"mc":[{"id":"1.230178319","rc":[{"atb":[[1.44,0]],"id":70642246}],"con":true,"img":false}]}
{"op":"mcm","clk":"11540996717","pt":1719500921996,"mc":[{"id":"1.230178319","rc":[{"atb":[[1.48,8.23]],"id":69261147}],"con":true,"img":false}]}
{"op":"mcm","clk":"11540996725","pt":1719500922100,"mc":[{"id":"1.230178319","rc":[{"atb":[[1.48,8.23]],"id":70642246}],"con":true,"img":false}]}
{"op":"mcm","clk":"11540997907","pt":1719500937126,"mc":[{"id":"1.230178319","rc":[{"atb":[[1.46,0]],"id":69261147}],"con":true,"img":false}]}
{"op":"mcm","clk":"11540997915","pt":1719500937230,"mc":[{"id":"1.230178319","rc":[{"atb":[[1.46,0]],"id":39959056}],"con":true,"img":false}]}
{"op":"mcm","clk":"11540997933","pt":1719500937438,"mc":[{"id":"1.230178319","rc":[{"atb":[[1.46,0]],"id":70642246}],"con":true,"img":false}]}
{"op":"mcm","clk":"11540997997","pt":1719500938320,"mc":[{"id":"1.230178319","rc":[{"atb":[[1.5,8.46]],"id":69261147}],"con":true,"img":false}]}
{"op":"mcm","clk":"11540998040","pt":1719500938943,"mc":[{"id":"1.230178319","rc":[{"atb":[[1.5,8.46]],"id":39959056}],"con":true,"img":false}]}
{"op":"mcm","clk":"11540998044","pt":1719500939048,"mc":[{"id":"1.230178319","rc":[{"atb":[[1.5,8.46]],"id":70642246}],"con":true,"img":false}]}
{"op":"mcm","clk":"11540998103","pt":1719500939932,"mc":[{"id":"1.230178319","rc":[{"atb":[[1.48,0]],"id":69261147}],"con":true,"img":false}]}
{"op":"mcm","clk":"11540998135","pt":1719500940300,"mc":[{"id":"1.230178319","rc":[{"atb":[[1.52,7.6]],"id":69261147}],"con":true,"img":false}]}
{"op":"mcm","clk":"11540999547","pt":1719500960031,"mc":[{"id":"1.230178319","rc":[{"atb":[[1.48,0]],"id":39959056}],"con":true,"img":false}]}
{"op":"mcm","clk":"11540999559","pt":1719500960242,"mc":[{"id":"1.230178319","rc":[{"atb":[[1.48,0]],"id":70642246}],"con":true,"img":false}]}
{"op":"mcm","clk":"11540999574","pt":1719500960448,"mc":[{"id":"1.230178319","rc":[{"atb":[[1.52,7.6]],"id":39959056},{"atb":[[1.52,7.6]],"id":70642246}],"con":true,"img":false}]}
{"op":"mcm","clk":"11541000321","pt":1719500971365,"mc":[{"id":"1.230178319","rc":[{"atb":[[1.5,0]],"id":39959056},{"spn":38.26,"spf":"NaN","id":39959056},{"spn":38.26,"spf":"NaN","id":69261147},{"spn":38.26,"spf":"NaN","id":70642246}],"con":true,"img":false}]}
{"op":"mcm","clk":"11541000383","pt":1719500972043,"mc":[{"id":"1.230178319","rc":[{"atb":[[1.5,0]],"id":69261147}],"con":true,"img":false}]}
{"op":"mcm","clk":"11541000423","pt":1719500972565,"mc":[{"id":"1.230178319","rc":[{"atb":[[1.5,0]],"id":70642246}],"con":true,"img":false}]}
{"op":"mcm","clk":"11541000473","pt":1719500973046,"mc":[{"id":"1.230178319","rc":[{"atb":[[1.54,7.84]],"id":39959056}],"con":true,"img":false}]}
{"op":"mcm","clk":"11541000500","pt":1719500973344,"mc":[{"id":"1.230178319","rc":[{"atb":[[1.54,7.84]],"id":69261147}],"con":true,"img":false}]}
{"op":"mcm","clk":"11541000573","pt":1719500974252,"mc":[{"id":"1.230178319","rc":[{"atb":[[1.54,7.84]],"id":70642246}],"con":true,"img":false}]}
{"op":"mcm","clk":"11541000873","pt":1719500978458,"mc":[{"id":"1.230178319","rc":[{"atb":[[1.52,0]],"id":39959056}],"con":true,"img":false}]}
{"op":"mcm","clk":"11541000880","pt":1719500978562,"mc":[{"id":"1.230178319","rc":[{"atb":[[1.52,0]],"id":69261147}],"con":true,"img":false}]}
{"op":"mcm","clk":"11541000905","pt":1719500978876,"mc":[{"id":"1.230178319","rc":[{"atb":[[1.52,0]],"id":70642246}],"con":true,"img":false}]}
{"op":"mcm","clk":"11541000938","pt":1719500979449,"mc":[{"id":"1.230178319","rc":[{"atb":[[1.56,7.05]],"id":69261147}],"con":true,"img":false}]}
{"op":"mcm","clk":"11541000952","pt":1719500979657,"mc":[{"id":"1.230178319","rc":[{"atb":[[1.56,7.05]],"id":70642246}],"con":true,"img":false}]}
{"op":"mcm","clk":"11541000985","pt":1719500980073,"mc":[{"id":"1.230178319","rc":[{"atb":[[1.56,7.05]],"id":39959056}],"con":true,"img":false}]}
{"op":"mcm","clk":"11541003230","pt":1719501008813,"mc":[{"id":"1.230178319","rc":[{"atb":[[1.54,0]],"id":39959056}],"con":true,"img":false}]}
{"op":"mcm","clk":"11541003253","pt":1719501008991,"mc":[{"id":"1.230178319","rc":[{"atb":[[1.54,0]],"id":69261147}],"con":true,"img":false}]}
{"op":"mcm","clk":"11541003275","pt":1719501009176,"mc":[{"id":"1.230178319","rc":[{"atb":[[1.54,0]],"id":70642246}],"con":true,"img":false}]}
{"op":"mcm","clk":"11541003413","pt":1719501010795,"mc":[{"id":"1.230178319","rc":[{"atb":[[1.58,7.29]],"id":39959056}],"con":true,"img":false}]}
{"op":"mcm","clk":"11541003440","pt":1719501011110,"mc":[{"id":"1.230178319","rc":[{"atb":[[1.58,7.29]],"id":70642246}],"con":true,"img":false}]}
{"op":"mcm","clk":"11541003463","pt":1719501011320,"mc":[{"id":"1.230178319","rc":[{"atb":[[1.58,7.29]],"id":69261147}],"con":true,"img":false}]}
{"op":"mcm","clk":"11541003802","pt":1719501015691,"mc":[{"id":"1.230178319","rc":[{"atb":[[1.56,0]],"id":70642246}],"con":true,"img":false}]}
{"op":"mcm","clk":"11541003855","pt":1719501016627,"mc":[{"id":"1.230178319","rc":[{"atb":[[1.56,0]],"id":39959056}],"con":true,"img":false}]}
{"op":"mcm","clk":"11541003875","pt":1719501016796,"mc":[{"id":"1.230178319","rc":[{"atb":[[1.6,6.58]],"id":39959056}],"con":true,"img":false}]}
{"op":"mcm","clk":"11541003892","pt":1719501017007,"mc":[{"id":"1.230178319","rc":[{"atb":[[1.6,6.58]],"id":70642246}],"con":true,"img":false}]}
{"op":"mcm","clk":"11541003918","pt":1719501017305,"mc":[{"id":"1.230178319","rc":[{"atb":[[1.56,0]],"id":69261147}],"con":true,"img":false}]}
{"op":"mcm","clk":"11541003960","pt":1719501017723,"mc":[{"id":"1.230178319","rc":[{"atb":[[1.6,6.58]],"id":69261147}],"con":true,"img":false}]}
{"op":"mcm","clk":"11541005908","pt":1719501044357,"mc":[{"id":"1.230178319","rc":[{"atb":[[1.58,0]],"id":39959056},{"spn":38.3,"spf":"NaN","id":39959056},{"spn":38.3,"spf":"NaN","id":69261147},{"spn":38.3,"spf":"NaN","id":70642246}],"con":true,"img":false}]}
{"op":"mcm","clk":"11541005933","pt":1719501044725,"mc":[{"id":"1.230178319","rc":[{"atb":[[1.58,0]],"id":69261147},{"atb":[[1.58,0]],"id":70642246}],"con":true,"img":false}]}
{"op":"mcm","clk":"11541005983","pt":1719501045549,"mc":[{"id":"1.230178319","rc":[{"atb":[[1.62,6.82]],"id":39959056}],"con":true,"img":false}]}
{"op":"mcm","clk":"11541006012","pt":1719501045924,"mc":[{"id":"1.230178319","rc":[{"atb":[[1.62,6.82]],"id":70642246}],"con":true,"img":false}]}
{"op":"mcm","clk":"11541006042","pt":1719501046428,"mc":[{"id":"1.230178319","rc":[{"atb":[[1.62,6.82]],"id":69261147}],"con":true,"img":false}]}
{"op":"mcm","clk":"11541006380","pt":1719501051546,"mc":[{"id":"1.230178319","rc":[{"atb":[[1.6,0]],"id":69261147}],"con":true,"img":false}]}
{"op":"mcm","clk":"11541006411","pt":1719501051927,"mc":[{"id":"1.230178319","rc":[{"atb":[[1.6,0]],"id":39959056}],"con":true,"img":false}]}
{"op":"mcm","clk":"11541006443","pt":1719501052441,"mc":[{"id":"1.230178319","rc":[{"atb":[[1.6,0]],"id":70642246}],"con":true,"img":false}]}
{"op":"mcm","clk":"11541006463","pt":1719501052635,"mc":[{"id":"1.230178319","rc":[{"atb":[[1.64,6.17]],"id":69261147}],"con":true,"img":false}]}
{"op":"mcm","clk":"11541006472","pt":1719501052843,"mc":[{"id":"1.230178319","rc":[{"atb":[[1.64,6.17]],"id":39959056}],"con":true,"img":false}]}
{"op":"mcm","clk":"11541006490","pt":1719501053153,"mc":[{"id":"1.230178319","rc":[{"atb":[[1.64,6.17]],"id":70642246}],"con":true,"img":false}]}
{"op":"mcm","clk":"11541008351","pt":1719501080670,"mc":[{"id":"1.230178319","rc":[{"atb":[[1.62,0]],"id":39959056}],"con":true,"img":false}]}
{"op":"mcm","clk":"11541008375","pt":1719501081082,"mc":[{"id":"1.230178319","rc":[{"atb":[[1.62,0]],"id":69261147}],"con":true,"img":false}]}
{"op":"mcm","clk":"11541008405","pt":1719501081393,"mc":[{"id":"1.230178319","rc":[{"atb":[[1.62,0]],"id":70642246}],"con":true,"img":false}]}
{"op":"mcm","clk":"11541008500","pt":1719501082771,"mc":[{"id":"1.230178319","rc":[{"atb":[[1.66,6.41]],"id":70642246}],"con":true,"img":false}]}
{"op":"mcm","clk":"11541008523","pt":1719501083073,"mc":[{"id":"1.230178319","rc":[{"atb":[[1.66,6.41]],"id":39959056}],"con":true,"img":false}]}
{"op":"mcm","clk":"11541008540","pt":1719501083382,"mc":[{"id":"1.230178319","rc":[{"atb":[[1.66,6.41]],"id":69261147}],"con":true,"img":false}]}
{"op":"mcm","clk":"11541008868","pt":1719501088195,"mc":[{"id":"1.230178319","rc":[{"atb":[[1.64,0]],"id":70642246}],"con":true,"img":false}]}
{"op":"mcm","clk":"11541008881","pt":1719501088468,"mc":[{"id":"1.230178319","rc":[{"atb":[[1.64,0]],"id":39959056}],"con":true,"img":false}]}
{"op":"mcm","clk":"11541008911","pt":1719501088880,"mc":[{"id":"1.230178319","rc":[{"atb":[[1.64,0]],"id":69261147}],"con":true,"img":false}]}
{"op":"mcm","clk":"11541008930","pt":1719501089089,"mc":[{"id":"1.230178319","rc":[{"atb":[[1.68,5.81]],"id":69261147},{"atb":[[1.68,5.81]],"id":70642246}],"con":true,"img":false}]}
{"op":"mcm","clk":"11541008958","pt":1719501089389,"mc":[{"id":"1.230178319","rc":[{"atb":[[1.68,5.81]],"id":39959056}],"con":true,"img":false}]}
{"op":"mcm","clk":"11541010088","pt":1719501105005,"mc":[{"id":"1.230178319","rc":[{"spn":38.34,"spf":"NaN","id":39959056},{"atb":[[1.68,0]],"id":69261147},{"spn":38.33,"spf":"NaN","id":69261147},{"spn":38.34,"spf":"NaN","id":70642246}],"con":true,"img":false}]}
{"op":"mcm","clk":"11541010918","pt":1719501116121,"mc":[{"id":"1.230178319","rc":[{"atb":[[1.66,0]],"id":70642246}],"con":true,"img":false}]}
{"op":"mcm","clk":"11541010997","pt":1719501117113,"mc":[{"id":"1.230178319","rc":[{"atb":[[1.7,6.04]],"id":70642246}],"con":true,"img":false}]}
{"op":"mcm","clk":"11541011491","pt":1719501123845,"mc":[{"id":"1.230178319","rc":[{"atb":[[1.68,0]],"id":70642246}],"con":true,"img":false}]}
{"op":"mcm","clk":"11541011502","pt":1719501124010,"mc":[{"id":"1.230178319","rc":[{"atb":[[1.72,5.48]],"id":70642246}],"con":true,"img":false}]}
{"op":"mcm","clk":"11541013727","pt":1719501152538,"mc":[{"id":"1.230178319","rc":[{"atb":[[1.66,0]],"id":69261147}],"con":true,"img":false}]}
{"op":"mcm","clk":"11541013780","pt":1719501153258,"mc":[{"id":"1.230178319","rc":[{"atb":[[1.7,0]],"id":70642246}],"con":true,"img":false}]}
{"op":"mcm","clk":"11541013864","pt":1719501154347,"mc":[{"id":"1.230178319","rc":[{"atb":[[1.74,5.72]],"id":70642246}],"con":true,"img":false}]}
{"op":"mcm","clk":"11541014309","pt":1719501160049,"mc":[{"id":"1.230178319","rc":[{"atb":[[1.72,0]],"id":70642246}],"con":true,"img":false}]}
{"op":"mcm","clk":"11541014349","pt":1719501160468,"mc":[{"id":"1.230178319","rc":[{"atb":[[1.76,5.2]],"id":70642246}],"con":true,"img":false}]}
{"op":"mcm","clk":"11541015867","pt":1719501176065,"mc":[{"id":"1.230178319","rc":[{"atb":[[1.66,0]],"id":39959056},{"spn":38.21,"spf":"NaN","id":69261147},{"spn":38.38,"spf":"NaN","id":70642246}],"con":true,"img":false}]}
{"op":"mcm","clk":"11541016260","pt":1719501180196,"mc":[{"id":"1.230178319","rc":[{"atb":[[1.69,2.12]],"id":39959056},{"atl":[[14,2]],"id":39959056},{"atb":[[1.44,1],[1.07,9.34]],"id":40214683},{"atl":[[5.1,2],[3.35,1]],"id":40214683}],"con":true,"img":false}]}
{"op":"mcm","clk":"11541016270","pt":1719501180288,"mc":[{"id":"1.230178319","rc":[{"atb":[[1.55,1],[1.07,14.96]],"id":62766534},{"atl":[[3.8,1],[5.7,2]],"id":62766534},{"atb":[[2.24,1]],"id":39959056},{"atl":[[5.9,1]],"id":39959056},{"atb":[[1.74,1],[1.48,2.48]],"id":56418091},{"atl":[[9.2,2],[4.4,1]],"id":56418091},{"atb":[[1.86,2.12]],"id":69261147},{"atl":[[28,2]],"id":69261147},{"atb":[[1.94,5.2],[2.76,1]],"id":70642246},{"atl":[[40,2],[8.2,1]],"id":70642246}],"con":true,"img":false}]}
{"op":"mcm","clk":"11541016283","pt":1719501180396,"mc":[{"id":"1.230178319","rc":[{"atb":[[2.76,1]],"id":69261147},{"atl":[[8.2,1]],"id":69261147}],"con":true,"img":false}]}
{"op":"mcm","clk":"11541016320","pt":1719501180776,"mc":[{"id":"1.230178319","rc":[{"atb":[[1.08,3.97]],"id":62766534},{"atl":[[1000,1.88]],"id":62766534},{"atb":[[1.01,1.7]],"id":39959056},{"atl":[[1000,1.7]],"id":39959056},{"atb":[[1.08,3.97]],"id":40214683},{"atl":[[1000,1.7]],"id":40214683}],"con":true,"img":false}]}
{"op":"mcm","clk":"11541016340","pt":1719501180980,"mc":[{"id":"1.230178319","rc":[{"atl":[[1000,0.24]],"id":62766534},{"atb":[[1.01,0.45]],"id":39959056},{"atl":[[1000,0.02]],"id":39959056},{"atl":[[1000,0.07]],"id":40214683}],"con":true,"img":false}]}
{"op":"mcm","clk":"11541016358","pt":1719501181185,"mc":[{"id":"1.230178319","rc":[{"atl":[[1000,0.17]],"id":62766534},{"atb":[[1.01,0]],"id":39959056},{"atl":[[1000,0]],"id":39959056},{"atl":[[1000,0]],"id":40214683}],"con":true,"img":false}]}
{"op":"mcm","clk":"11541016369","pt":1719501181295,"mc":[{"id":"1.230178319","rc":[{"atl":[[5.6,0.06]],"id":62766534},{"atb":[[1.7,0.45]],"id":39959056},{"atl":[[13.5,0.02]],"id":39959056},{"atl":[[5,0.07]],"id":40214683}],"con":true,"img":false}]}
{"op":"mcm","clk":"11541016619","pt":1719501184003,"mc":[{"id":"1.230178319","rc":[{"atb":[[1.12,14.96],[1.07,2.48]],"id":62766534},{"atb":[[1.6,2.48],[1.48,0]],"id":56418091},{"atl":[[9.2,0],[13.5,3]],"id":56418091},{"atb":[[2.18,5.2],[1.94,0]],"id":70642246},{"atl":[[75,2.48],[40,0]],"id":70642246}],"con":true,"img":false}]}
{"op":"mcm","clk":"11541016757","pt":1719501185401,"mc":[{"id":"1.230178319","rc":[{"atl":[[55,2],[28,0]],"id":69261147}],"con":true,"img":false}]}
{"op":"mcm","clk":"11541017211","pt":1719501190214,"mc":[{"id":"1.230178319","rc":[{"atl":[[5.9,0]],"id":39959056},{"trd":[[5.9,2]],"ltp":5.9,"tv":2.0,"id":39959056}],"con":true,"img":false}]}
{"op":"mcm","clk":"11541017237","pt":1719501190381,"mc":[{"id":"1.230178319","rc":[{"atl":[[6.4,1],[20,2.02],[14,0]],"id":39959056},{"atb":[[1.98,2.12],[1.86,0]],"id":69261147}],"con":true,"img":false}]}
{"op":"mcm","clk":"11541017250","pt":1719501190484,"mc":[{"id":"1.230178319","rc":[{"atl":[[20,0],[14,2]],"id":39959056}],"con":true,"img":false}]}
{"op":"mcm","clk":"11541018269","pt":1719501202421,"mc":[{"id":"1.230178319","rc":[{"atb":[[1.09,2]],"id":40214683}],"con":true,"img":false}]}
{"op":"mcm","clk":"11541018276","pt":1719501202524,"mc":[{"id":"1.230178319","rc":[{"atl":[[3.8,0],[3.75,1]],"id":62766534}],"con":true,"img":false}]}
{"op":"mcm","clk":"11541018285","pt":1719501202631,"mc":[{"id":"1.230178319","rc":[{"atb":[[1.2,4.22],[1.12,0]],"id":62766534},{"atb":[[1.12,3.97],[1.07,2.48]],"id":40214683},{"atb":[[1.6,0],[1.63,2.48]],"id":56418091},{"atb":[[1.98,0],[2.08,2.12]],"id":69261147},{"atl":[[8.2,0],[7.8,1]],"id":69261147},{"atl":[[8.2,0],[7.8,1]],"id":70642246}],"con":true,"img":false}]}
{"op":"mcm","clk":"11541018297","pt":1719501202735,"mc":[{"id":"1.230178319","rc":[{"atb":[[1.7,2.45]],"id":39959056}],"con":true,"img":false}]}
{"op":"mcm","clk":"11541018305","pt":1719501202798,"mc":[{"id":"1.230178319","rc":[{"atl":[[46,2],[55,0]],"id":69261147},{"atl":[[75,0.48],[60,2]],"id":70642246}],"con":true,"img":false}]}
{"op":"mcm","clk":"11541018313","pt":1719501202896,"mc":[{"id":"1.230178319","rc":[{"atb":[[1.13,2]],"id":62766534}],"con":true,"img":false}]}
{"op":"mcm","clk":"11541018331","pt":1719501203106,"mc":[{"id":"1.230178319","rc":[{"atb":[[1.02,2]],"id":69261147}],"con":true,"img":false}]}
{"op":"mcm","clk":"11541018354","pt":1719501203411,"mc":[{"id":"1.230178319","rc":[{"atb":[[2.2,2]],"id":70642246}],"con":true,"img":false}]}
{"op":"mcm","clk":"11541018382","pt":1719501203722,"mc":[{"id":"1.230178319","rc":[{"atb":[[1.02,13.23]],"id":56418091}],"con":true,"img":false}]}
{"op":"mcm","clk":"11541018586","pt":1719501205693,"mc":[{"id":"1.230178319","rc":[{"atb":[[2.24,0],[2.32,1]],"id":39959056}],"con":true,"img":false}]}
{"op":"mcm","clk":"11541018643","pt":1719501206409,"mc":[{"id":"1.230178319","rc":[{"atb":[[2.24,1],[2.32,0]],"id":39959056}],"con":true,"img":false}]}
{"op":"mcm","clk":"11541018651","pt":1719501206514,"mc":[{"id":"1.230178319","rc":[{"atb":[[1.72,2.45],[1.69,0]],"id":39959056}],"con":true,"img":false}]}
{"op":"mcm","clk":"11541018667","pt":1719501206720,"mc":[{"id":"1.230178319","rc":[{"atb":[[1.09,0]],"id":40214683}],"con":true,"img":false}]}
{"op":"mcm","clk":"11541018671","pt":1719501206814,"mc":[{"id":"1.230178319","rc":[{"atb":[[1.13,2]],"id":40214683}],"con":true,"img":false}]}
{"op":"mcm","clk":"11541018691","pt":1719501207025,"mc":[{"id":"1.230178319","rc":[{"atb":[[1.13,0]],"id":62766534}],"con":true,"img":false}]}
{"op":"mcm","clk":"11541018697","pt":1719501207124,"mc":[{"id":"1.230178319","rc":[{"atb":[[1.21,2]],"id":62766534}],"con":true,"img":false}]}
{"op":"mcm","clk":"11541018735","pt":1719501207392,"mc":[{"id":"1.230178319","rc":[{"atb":[[2.2,0]],"id":70642246}],"con":true,"img":false}]}
{"op":"mcm","clk":"11541018744","pt":1719501207494,"mc":[{"id":"1.230178319","rc":[{"atb":[[1.02,13.23]],"id":70642246}],"con":true,"img":false}]}
{"op":"mcm","clk":"11541018857","pt":1719501208829,"mc":[{"id":"1.230178319","rc":[{"atb":[[1.7,0.45]],"id":39959056}],"con":true,"img":false}]}
{"op":"mcm","clk":"11541018869","pt":1719501208931,"mc":[{"id":"1.230178319","rc":[{"atb":[[1.73,2]],"id":39959056}],"con":true,"img":false}]}
{"op":"mcm","clk":"11541018893","pt":1719501209209,"mc":[{"id":"1.230178319","rc":[{"atb":[[1.02,11.23]],"id":70642246}],"con":true,"img":false}]}
{"op":"mcm","clk":"11541018905","pt":1719501209314,"mc":[{"id":"1.230178319","rc":[{"atb":[[2.2,2]],"id":70642246}],"con":true,"img":false}]}
{"op":"mcm","clk":"11541019018","pt":1719501210735,"mc":[{"id":"1.230178319","rc":[{"atb":[[2.2,0]],"id":70642246}],"con":true,"img":false}]}
{"op":"mcm","clk":"11541019030","pt":1719501210801,"mc":[{"id":"1.230178319","rc":[{"atb":[[1.02,13.23]],"id":70642246}],"con":true,"img":false}]}
{"op":"mcm","clk":"11541019153","pt":1719501212300,"mc":[{"id":"1.230178319","rc":[{"atb":[[1.02,11.23]],"id":70642246}],"con":true,"img":false}]}
{"op":"mcm","clk":"11541019162","pt":1719501212411,"mc":[{"id":"1.230178319","rc":[{"atb":[[2.2,2]],"id":70642246}],"con":true,"img":false}]}
{"op":"mcm","clk":"11541019225","pt":1719501213140,"mc":[{"id":"1.230178319","rc":[{"atb":[[2.24,0],[2.32,1]],"id":39959056}],"con":true,"img":false}]}
{"op":"mcm","clk":"11541019235","pt":1719501213244,"mc":[{"id":"1.230178319","rc":[{"atb":[[1.72,0],[1.74,2]],"id":39959056}],"con":true,"img":false}]}
{"op":"mcm","clk":"11541019247","pt":1719501213341,"mc":[{"id":"1.230178319","rc":[{"atb":[[2.2,0]],"id":70642246}],"con":true,"img":false}]}
{"op":"mcm","clk":"11541019255","pt":1719501213402,"mc":[{"id":"1.230178319","rc":[{"atb":[[1.02,13.23]],"id":70642246}],"con":true,"img":false}]}
{"op":"mcm","clk":"11541019316","pt":1719501214333,"mc":[{"id":"1.230178319","rc":[{"atl":[[3.45,1],[3.75,0]],"id":62766534},{"atl":[[3.35,0],[3.05,1]],"id":40214683},{"atl":[[4.4,0],[4.2,1]],"id":56418091},{"atl":[[8.2,1],[7.8,0]],"id":69261147},{"atl":[[8.2,1],[7.8,0]],"id":70642246}],"con":true,"img":false}]}
{"op":"mcm","clk":"11541019553","pt":1719501216840,"mc":[{"id":"1.230178319","rc":[{"atb":[[2.1,1.94]],"id":69261147},{"atb":[[2.2,1.94]],"id":70642246}],"con":true,"img":false}]}
{"op":"mcm","clk":"11541019567","pt":1719501216944,"mc":[{"id":"1.230178319","rc":[{"atb":[[1.73,0]],"id":39959056}],"con":true,"img":false}]}
{"op":"mcm","clk":"11541019580","pt":1719501217047,"mc":[{"id":"1.230178319","rc":[{"atb":[[1.75,2]],"id":39959056}],"con":true,"img":false}]}
{"op":"mcm","clk":"11541019614","pt":1719501217348,"mc":[{"id":"1.230178319","rc":[{"atb":[[1.02,11.23]],"id":70642246}],"con":true,"img":false}]}
{"op":"mcm","clk":"11541019622","pt":1719501217414,"mc":[{"id":"1.230178319","rc":[{"atb":[[2.2,3.94]],"id":70642246}],"con":true,"img":false}]}
{"op":"mcm","clk":"11541019807","pt":1719501219331,"mc":[{"id":"1.230178319","rc":[{"atb":[[2.1,0]],"id":69261147}],"con":true,"img":false}]}
{"op":"mcm","clk":"11541019811","pt":1719501219417,"mc":[{"id":"1.230178319","rc":[{"atb":[[2.1,1.94]],"id":69261147},{"atb":[[2.2,1.94]],"id":70642246}],"con":true,"img":false}]}
{"op":"mcm","clk":"11541019820","pt":1719501219522,"mc":[{"id":"1.230178319","rc":[{"atb":[[1.02,13.23]],"id":70642246}],"con":true,"img":false}]}
{"op":"mcm","clk":"11541020012","pt":1719501221811,"mc":[{"id":"1.230178319","rc":[{"atb":[[2.1,0]],"id":69261147},{"atb":[[2.2,0]],"id":70642246}],"con":true,"img":false}]}
{"op":"mcm","clk":"11541020029","pt":1719501222011,"mc":[{"id":"1.230178319","rc":[{"atb":[[2.1,1.94]],"id":69261147},{"atb":[[2.2,1.94]],"id":70642246}],"con":true,"img":false}]}
{"op":"mcm","clk":"11541020213","pt":1719501224443,"mc":[{"id":"1.230178319","rc":[{"atb":[[2.1,0]],"id":69261147},{"atb":[[2.2,0]],"id":70642246}],"con":true,"img":false}]}
{"op":"mcm","clk":"11541020233","pt":1719501224652,"mc":[{"id":"1.230178319","rc":[{"atb":[[2.1,1.94]],"id":69261147},{"atb":[[2.2,1.94]],"id":70642246}],"con":true,"img":false}]}
{"op":"mcm","clk":"11541020444","pt":1719501226922,"mc":[{"id":"1.230178319","rc":[{"atb":[[2.1,0]],"id":69261147},{"atb":[[2.2,0]],"id":70642246}],"con":true,"img":false}]}
{"op":"mcm","clk":"11541020451","pt":1719501227030,"mc":[{"id":"1.230178319","rc":[{"atb":[[2.1,1.94]],"id":69261147},{"atb":[[2.2,1.94]],"id":70642246}],"con":true,"img":false}]}
{"op":"mcm","clk":"11541020470","pt":1719501227232,"mc":[{"id":"1.230178319","rc":[{"atb":[[1.02,11.23]],"id":70642246}],"con":true,"img":false}]}
{"op":"mcm","clk":"11541020484","pt":1719501227347,"mc":[{"id":"1.230178319","rc":[{"atb":[[2.2,3.94]],"id":70642246}],"con":true,"img":false}]}
{"op":"mcm","clk":"11541020527","pt":1719501227858,"mc":[{"id":"1.230178319","rc":[{"atb":[[1.08,0]],"id":62766534},{"atl":[[5.6,0]],"id":62766534},{"atb":[[1.7,0]],"id":39959056},{"atl":[[13.5,0]],"id":39959056},{"atb":[[1.08,0]],"id":40214683},{"atl":[[5,0]],"id":40214683}],"con":true,"img":false}]}
{"op":"mcm","clk":"11541020544","pt":1719501228059,"mc":[{"id":"1.230178319","rc":[{"atl":[[8.2,3],[5.7,0]],"id":62766534},{"atl":[[5.1,0],[7.6,3]],"id":40214683}],"con":true,"img":false}]}
{"op":"mcm","clk":"11541020577","pt":1719501228440,"mc":[{"id":"1.230178319","rc":[{"atl":[[7.6,5.46]],"id":62766534}],"con":true,"img":false}]}
{"op":"mcm","clk":"11541020593","pt":1719501228626,"mc":[{"id":"1.230178319","rc":[{"atb":[[2.2,1.94]],"id":70642246}],"con":true,"img":false}]}
{"op":"mcm","clk":"11541020600","pt":1719501228726,"mc":[{"id":"1.230178319","rc":[{"atb":[[1.02,13.23]],"id":70642246}],"con":true,"img":false}]}
{"op":"mcm","clk":"11541020661","pt":1719501229448,"mc":[{"id":"1.230178319","rc":[{"atb":[[2.1,0]],"id":69261147},{"atb":[[2.2,0]],"id":70642246}],"con":true,"img":false}]}
{"op":"mcm","clk":"11541020683","pt":1719501229662,"mc":[{"id":"1.230178319","rc":[{"atb":[[2.1,1.94]],"id":69261147},{"atb":[[2.2,1.94]],"id":70642246}],"con":true,"img":false}]}
{"op":"mcm","clk":"11541020876","pt":1719501231928,"mc":[{"id":"1.230178319","rc":[{"atb":[[2.1,0]],"id":69261147},{"atb":[[2.2,0]],"id":70642246}],"con":true,"img":false}]}
{"op":"mcm","clk":"11541020893","pt":1719501232139,"mc":[{"id":"1.230178319","rc":[{"atb":[[2.1,1.94]],"id":69261147},{"atb":[[2.2,1.94]],"id":70642246}],"con":true,"img":false}]}
{"op":"mcm","clk":"11541020911","pt":1719501232349,"mc":[{"id":"1.230178319","rc":[{"atl":[[6.4,0]],"id":39959056},{"trd":[[6.4,2]],"ltp":6.4,"tv":2.0,"id":39959056},{"atb":[[1.02,11.23]],"id":70642246}],"con":true,"img":false}]}
{"op":"mcm","clk":"11541020922","pt":1719501232451,"mc":[{"id":"1.230178319","rc":[{"atb":[[2.2,3.94]],"id":70642246}],"con":true,"img":false}]}
{"op":"mcm","clk":"11541020932","pt":1719501232555,"mc":[{"id":"1.230178319","rc":[{"atl":[[16.5,4],[14,0]],"id":39959056}],"con":true,"img":false}]}
{"op":"mcm","clk":"11541021002","pt":1719501233232,"mc":[{"id":"1.230178319","rc":[{"atb":[[2.2,1.94]],"id":70642246}],"con":true,"img":false}]}
{"op":"mcm","clk":"11541021011","pt":1719501233329,"mc":[{"id":"1.230178319","rc":[{"atb":[[1.02,13.23]],"id":70642246}],"con":true,"img":false}]}
{"op":"mcm","clk":"11541021118","pt":1719501234466,"mc":[{"id":"1.230178319","rc":[{"atb":[[2.1,0]],"id":69261147},{"atb":[[2.2,0]],"id":70642246}],"con":true,"img":false}]}
{"op":"mcm","clk":"11541021135","pt":1719501234623,"mc":[{"id":"1.230178319","rc":[{"atl":[[6.4,1]],"id":39959056},{"atb":[[2.1,1.94]],"id":69261147},{"atb":[[2.2,1.94]],"id":70642246}],"con":true,"img":false}]}
{"op":"mcm","clk":"11541021336","pt":1719501236945,"mc":[{"id":"1.230178319","rc":[{"spn":2.5,"spf":"NaN","id":62766534},{"spn":4.36,"spf":"NaN","id":39959056},{"spn":2.24,"spf":"NaN","id":40214683},{"spn":2.97,"spf":"NaN","id":56418091},{"atb":[[2.1,0]],"id":69261147},{"spn":5.48,"spf":"NaN","id":69261147},{"atb":[[2.2,0]],"id":70642246},{"spn":5.48,"spf":"NaN","id":70642246}],"con":true,"img":false}]}
{"op":"mcm","clk":"11541021344","pt":1719501237048,"mc":[{"id":"1.230178319","rc":[{"atb":[[2.1,1.94]],"id":69261147},{"atb":[[2.2,1.94]],"id":70642246}],"con":true,"img":false}]}
{"op":"mcm","clk":"11541021552","pt":1719501239432,"mc":[{"id":"1.230178319","rc":[{"atb":[[2.1,0]],"id":69261147},{"atb":[[2.2,0]],"id":70642246}],"con":true,"img":false}]}
{"op":"mcm","clk":"11541021559","pt":1719501239529,"mc":[{"id":"1.230178319","rc":[{"atb":[[2.1,1.94]],"id":69261147},{"atb":[[2.2,1.94]],"id":70642246}],"con":true,"img":false}]}
{"op":"mcm","clk":"11541021788","pt":1719501241959,"mc":[{"id":"1.230178319","rc":[{"atb":[[2.1,0]],"id":69261147},{"atb":[[2.2,0]],"id":70642246}],"con":true,"img":false}]}
{"op":"mcm","clk":"11541021801","pt":1719501242165,"mc":[{"id":"1.230178319","rc":[{"atb":[[2.1,1.94]],"id":69261147},{"atb":[[2.2,1.94]],"id":70642246}],"con":true,"img":false}]}
{"op":"mcm","clk":"11541022006","pt":1719501244544,"mc":[{"id":"1.230178319","rc":[{"atb":[[2.1,0]],"id":69261147},{"atb":[[2.2,0]],"id":70642246}],"con":true,"img":false}]}
{"op":"mcm","clk":"11541022017","pt":1719501244652,"mc":[{"id":"1.230178319","rc":[{"atb":[[2.1,1.94]],"id":69261147},{"atb":[[2.2,1.94]],"id":70642246}],"con":true,"img":false}]}
{"op":"mcm","clk":"11541022058","pt":1719501245058,"mc":[{"id":"1.230178319","rc":[{"atl":[[6.4,0]],"id":39959056},{"trd":[[6.4,4]],"ltp":6.4,"tv":4.0,"id":39959056}],"con":true,"img":false}]}
{"op":"mcm","clk":"11541022067","pt":1719501245161,"mc":[{"id":"1.230178319","rc":[{"atb":[[1.76,2.12]],"id":39959056}],"con":true,"img":false}]}
{"op":"mcm","clk":"11541022119","pt":1719501245778,"mc":[{"id":"1.230178319","rc":[{"atl":[[6.4,1]],"id":39959056}],"con":true,"img":false}]}
{"op":"mcm","clk":"11541022181","pt":1719501246449,"mc":[{"id":"1.230178319","rc":[{"atb":[[1.75,0]],"id":39959056}],"con":true,"img":false}]}
{"op":"mcm","clk":"11541022191","pt":1719501246558,"mc":[{"id":"1.230178319","rc":[{"atb":[[1.77,2]],"id":39959056}],"con":true,"img":false}]}
{"op":"mcm","clk":"11541022225","pt":1719501247066,"mc":[{"id":"1.230178319","rc":[{"atb":[[2.1,0]],"id":69261147},{"atb":[[2.2,0]],"id":70642246}],"con":true,"img":false}]}
{"op":"mcm","clk":"11541022243","pt":1719501247277,"mc":[{"id":"1.230178319","rc":[{"atb":[[2.1,1.94]],"id":69261147},{"atb":[[2.2,1.94]],"id":70642246}],"con":true,"img":false}]}
{"op":"mcm","clk":"11541022268","pt":1719501247590,"mc":[{"id":"1.230178319","rc":[{"atb":[[1.02,11.23]],"id":70642246}],"con":true,"img":false}]}
{"op":"mcm","clk":"11541022274","pt":1719501247636,"mc":[{"id":"1.230178319","rc":[{"atb":[[2.2,3.94]],"id":70642246}],"con":true,"img":false}]}
{"op":"mcm","clk":"11541022381","pt":1719501248676,"mc":[{"id":"1.230178319","rc":[{"atb":[[2.2,1.94]],"id":70642246}],"con":true,"img":false}]}
{"op":"mcm","clk":"11541022387","pt":1719501248772,"mc":[{"id":"1.230178319","rc":[{"atb":[[1.02,13.23]],"id":70642246}],"con":true,"img":false}]}
{"op":"mcm","clk":"11541022430","pt":1719501249241,"mc":[{"id":"1.230178319","rc":[{"atb":[[1.68,0]],"id":39959056}],"con":true,"img":false}]}
{"op":"mcm","clk":"11541022456","pt":1719501249546,"mc":[{"id":"1.230178319","rc":[{"atb":[[2.1,0]],"id":69261147},{"atb":[[2.2,0]],"id":70642246}],"con":true,"img":false}]}
{"op":"mcm","clk":"11541022474","pt":1719501249754,"mc":[{"id":"1.230178319","rc":[{"atb":[[2.1,1.94]],"id":69261147},{"atb":[[2.2,1.94]],"id":70642246}],"con":true,"img":false}]}
{"op":"mcm","clk":"11541022713","pt":1719501252075,"mc":[{"id":"1.230178319","rc":[{"atb":[[2.1,0]],"id":69261147},{"atb":[[2.2,0]],"id":70642246}],"con":true,"img":false}]}
{"op":"mcm","clk":"11541022729","pt":1719501252281,"mc":[{"id":"1.230178319","rc":[{"atb":[[2.1,1.94]],"id":69261147},{"atb":[[2.2,1.94]],"id":70642246}],"con":true,"img":false}]}
{"op":"mcm","clk":"11541022904","pt":1719501254626,"mc":[{"id":"1.230178319","rc":[{"atb":[[2.1,0]],"id":69261147},{"atb":[[2.2,0]],"id":70642246}],"con":true,"img":false}]}
{"op":"mcm","clk":"11541022912","pt":1719501254647,"mc":[{"id":"1.230178319","rc":[{"atb":[[2.1,1.94]],"id":69261147},{"atb":[[2.2,1.94]],"id":70642246}],"con":true,"img":false}]}
{"op":"mcm","clk":"11541023020","pt":1719501255991,"mc":[{"id":"1.230178319","rc":[{"atl":[[6.4,0]],"id":39959056},{"trd":[[6.4,6]],"ltp":6.4,"tv":6.0,"id":39959056}],"con":true,"img":false}]}
{"op":"mcm","clk":"11541023030","pt":1719501256044,"mc":[{"id":"1.230178319","rc":[{"atb":[[1.76,0]],"id":39959056}],"con":true,"img":false}]}
{"op":"mcm","clk":"11541023107","pt":1719501257072,"mc":[{"id":"1.230178319","rc":[{"atb":[[2.1,0]],"id":69261147},{"atb":[[2.2,0]],"id":70642246}],"con":true,"img":false}]}
{"op":"mcm","clk":"11541023121","pt":1719501257278,"mc":[{"id":"1.230178319","rc":[{"atb":[[2.1,1.94]],"id":69261147},{"atb":[[2.2,1.94]],"id":70642246}],"con":true,"img":false}]}
{"op":"mcm","clk":"11541023151","pt":1719501257667,"mc":[{"id":"1.230178319","rc":[{"atb":[[1.77,0]],"id":39959056}],"con":true,"img":false}]}
{"op":"mcm","clk":"11541023159","pt":1719501257770,"mc":[{"id":"1.230178319","rc":[{"atb":[[1.75,2]],"id":39959056}],"con":true,"img":false}]}
{"op":"mcm","clk":"11541023198","pt":1719501258173,"mc":[{"id":"1.230178319","rc":[{"atb":[[1.74,0]],"id":70642246}],"con":true,"img":false}]}
{"op":"mcm","clk":"11541023219","pt":1719501258381,"mc":[{"id":"1.230178319","rc":[{"atl":[[6.4,1]],"id":39959056}],"con":true,"img":false}]}
{"op":"mcm","clk":"11541023314","pt":1719501259676,"mc":[{"id":"1.230178319","rc":[{"atb":[[2.1,0]],"id":69261147},{"atb":[[2.2,0]],"id":70642246}],"con":true,"img":false}]}
{"op":"mcm","clk":"11541023332","pt":1719501259881,"mc":[{"id":"1.230178319","rc":[{"atb":[[2.1,1.94]],"id":69261147},{"atb":[[2.2,1.94]],"id":70642246}],"con":true,"img":false}]}
{"op":"mcm","clk":"11541023391","pt":1719501260661,"mc":[{"id":"1.230178319","rc":[{"atb":[[1.75,0]],"id":39959056}],"con":true,"img":false}]}
{"op":"mcm","clk":"11541023399","pt":1719501260764,"mc":[{"id":"1.230178319","rc":[{"atb":[[1.02,2]],"id":39959056}],"con":true,"img":false}]}
{"op":"mcm","clk":"11541023496","pt":1719501262199,"mc":[{"id":"1.230178319","rc":[{"atb":[[2.1,0]],"id":69261147},{"atb":[[2.2,0]],"id":70642246}],"con":true,"img":false}]}
{"op":"mcm","clk":"11541023514","pt":1719501262366,"mc":[{"id":"1.230178319","rc":[{"atb":[[2.1,1.94]],"id":69261147},{"atb":[[2.2,1.94]],"id":70642246}],"con":true,"img":false}]}
{"op":"mcm","clk":"11541023727","pt":1719501264761,"mc":[{"id":"1.230178319","rc":[{"atb":[[2.1,0]],"id":69261147},{"atb":[[2.2,0]],"id":70642246}],"con":true,"img":false}]}
{"op":"mcm","clk":"11541023733","pt":1719501264864,"mc":[{"id":"1.230178319","rc":[{"atb":[[1.43,2.48]],"id":39959056}],"con":true,"img":false}]}
{"op":"mcm","clk":"11541023738","pt":1719501264964,"mc":[{"id":"1.230178319","rc":[{"atb":[[2.1,1.94]],"id":69261147},{"atb":[[2.2,1.94]],"id":70642246}],"con":true,"img":false}]}
{"op":"mcm","clk":"11541023868","pt":1719501266467,"mc":[{"id":"1.230178319","rc":[{"atb":[[1.76,0]],"id":70642246}],"con":true,"img":false}]}
{"op":"mcm","clk":"11541023905","pt":1719501266877,"mc":[{"id":"1.230178319","rc":[{"atl":[[6.4,0]],"id":39959056},{"trd":[[6.4,8]],"ltp":6.4,"tv":8.0,"id":39959056}],"con":true,"img":false}]}
{"op":"mcm","clk":"11541023929","pt":1719501267288,"mc":[{"id":"1.230178319","rc":[{"atb":[[2.1,0]],"id":69261147},{"atb":[[2.2,0]],"id":70642246}],"con":true,"img":false}]}
{"op":"mcm","clk":"11541023941","pt":1719501267494,"mc":[{"id":"1.230178319","rc":[{"atb":[[2.1,1.94]],"id":69261147},{"atb":[[2.2,1.94]],"id":70642246}],"con":true,"img":false}]}
{"op":"mcm","clk":"11541024120","pt":1719501269770,"mc":[{"id":"1.230178319","rc":[{"atb":[[2.1,0]],"id":69261147},{"atb":[[2.2,0]],"id":70642246}],"con":true,"img":false}]}
{"op":"mcm","clk":"11541024135","pt":1719501269980,"mc":[{"id":"1.230178319","rc":[{"atb":[[2.1,1.94]],"id":69261147},{"atb":[[2.2,1.94]],"id":70642246}],"con":true,"img":false}]}
{"op":"mcm","clk":"11541024333","pt":1719501272269,"mc":[{"id":"1.230178319","rc":[{"atb":[[2.1,0]],"id":69261147},{"atb":[[2.2,0]],"id":70642246}],"con":true,"img":false}]}
{"op":"mcm","clk":"11541024348","pt":1719501272479,"mc":[{"id":"1.230178319","rc":[{"atb":[[2.1,1.94]],"id":69261147},{"atb":[[2.2,1.94]],"id":70642246}],"con":true,"img":false}]}
{"op":"mcm","clk":"11541024561","pt":1719501274804,"mc":[{"id":"1.230178319","rc":[{"atb":[[2.1,0]],"id":69261147},{"atb":[[2.2,0]],"id":70642246}],"con":true,"img":false}]}
{"op":"mcm","clk":"11541024583","pt":1719501274971,"mc":[{"id":"1.230178319","rc":[{"atb":[[2.1,1.94]],"id":69261147},{"atb":[[2.2,1.94]],"id":70642246}],"con":true,"img":false}]}
{"op":"mcm","clk":"11541024778","pt":1719501277281,"mc":[{"id":"1.230178319","rc":[{"atb":[[2.1,0]],"id":69261147},{"atb":[[2.2,0]],"id":70642246}],"con":true,"img":false}]}
{"op":"mcm","clk":"11541024788","pt":1719501277389,"mc":[{"id":"1.230178319","rc":[{"atb":[[2.1,1.94]],"id":69261147},{"atb":[[2.2,1.94]],"id":70642246}],"con":true,"img":false}]}
{"op":"mcm","clk":"11541024995","pt":1719501279811,"mc":[{"id":"1.230178319","rc":[{"atb":[[2.1,0]],"id":69261147},{"atb":[[2.2,0]],"id":70642246}],"con":true,"img":false}]}
{"op":"mcm","clk":"11541025011","pt":1719501280016,"mc":[{"id":"1.230178319","rc":[{"atb":[[2.1,1.94]],"id":69261147},{"atb":[[2.2,1.94]],"id":70642246}],"con":true,"img":false}]}
{"op":"mcm","clk":"11541025238","pt":1719501282289,"mc":[{"id":"1.230178319","rc":[{"atb":[[2.1,0]],"id":69261147},{"atb":[[2.2,0]],"id":70642246}],"con":true,"img":false}]}
{"op":"mcm","clk":"11541025246","pt":1719501282391,"mc":[{"id":"1.230178319","rc":[{"atb":[[2.1,1.94]],"id":69261147},{"atb":[[2.2,1.94]],"id":70642246}],"con":true,"img":false}]}
{"op":"mcm","clk":"11541025455","pt":1719501284897,"mc":[{"id":"1.230178319","rc":[{"atb":[[2.1,0]],"id":69261147},{"atb":[[2.2,0]],"id":70642246}],"con":true,"img":false}]}
{"op":"mcm","clk":"11541025478","pt":1719501285098,"mc":[{"id":"1.230178319","rc":[{"atb":[[2.1,1.94]],"id":69261147},{"atb":[[2.2,1.94]],"id":70642246}],"con":true,"img":false}]}
{"op":"mcm","clk":"11541025552","pt":1719501285717,"mc":[{"id":"1.230178319","rc":[{"atl":[[16,0.84]],"id":39959056}],"con":true,"img":false}]}
{"op":"mcm","clk":"11541025710","pt":1719501287421,"mc":[{"id":"1.230178319","rc":[{"atb":[[2.1,0]],"id":69261147},{"atb":[[2.2,0]],"id":70642246}],"con":true,"img":false}]}
{"op":"mcm","clk":"11541025716","pt":1719501287472,"mc":[{"id":"1.230178319","rc":[{"atb":[[2.1,1.94]],"id":69261147},{"atb":[[2.2,1.94]],"id":70642246}],"con":true,"img":false}]}
{"op":"mcm","clk":"11541025935","pt":1719501289904,"mc":[{"id":"1.230178319","rc":[{"atb":[[2.1,0]],"id":69261147},{"atb":[[2.2,0]],"id":70642246}],"con":true,"img":false}]}
{"op":"mcm","clk":"11541025955","pt":1719501290108,"mc":[{"id":"1.230178319","rc":[{"atb":[[2.1,1.94]],"id":69261147},{"atb":[[2.2,1.94]],"id":70642246}],"con":true,"img":false}]}
{"op":"mcm","clk":"11541026157","pt":1719501292495,"mc":[{"id":"1.230178319","rc":[{"atb":[[2.1,0]],"id":69261147},{"atb":[[2.2,0]],"id":70642246}],"con":true,"img":false}]}
{"op":"mcm","clk":"11541026171","pt":1719501292708,"mc":[{"id":"1.230178319","rc":[{"atb":[[2.1,1.94]],"id":69261147},{"atb":[[2.2,1.94]],"id":70642246}],"con":true,"img":false}]}
{"op":"mcm","clk":"11541026368","pt":1719501295034,"mc":[{"id":"1.230178319","rc":[{"atb":[[2.1,0]],"id":69261147},{"atb":[[2.2,0]],"id":70642246}],"con":true,"img":false}]}
{"op":"mcm","clk":"11541026389","pt":1719501295182,"mc":[{"id":"1.230178319","rc":[{"atb":[[2.1,1.94]],"id":69261147},{"atb":[[2.2,1.94]],"id":70642246}],"con":true,"img":false}]}
{"op":"mcm","clk":"11541026607","pt":1719501297719,"mc":[{"id":"1.230178319","rc":[{"spn":9.16,"spf":"NaN","id":39959056},{"atb":[[2.1,0]],"id":69261147},{"atb":[[2.2,0]],"id":70642246}],"con":true,"img":false}]}
{"op":"mcm","clk":"11541026616","pt":1719501297817,"mc":[{"id":"1.230178319","rc":[{"atb":[[2.1,1.94]],"id":69261147},{"atb":[[2.2,1.94]],"id":70642246}],"con":true,"img":false}]}
{"op":"mcm","clk":"11541026839","pt":1719501300096,"mc":[{"id":"1.230178319","rc":[{"atb":[[2.1,0]],"id":69261147},{"atb":[[2.2,0]],"id":70642246}],"con":true,"img":false}]}
{"op":"mcm","clk":"11541026867","pt":1719501300308,"mc":[{"id":"1.230178319","rc":[{"atb":[[2.1,1.94]],"id":69261147},{"atb":[[2.2,1.94]],"id":70642246}],"con":true,"img":false}]}
{"op":"mcm","clk":"11541027120","pt":1719501302720,"mc":[{"id":"1.230178319","rc":[{"atb":[[2.1,0]],"id":69261147},{"atb":[[2.2,0]],"id":70642246}],"con":true,"img":false}]}
{"op":"mcm","clk":"11541027140","pt":1719501302927,"mc":[{"id":"1.230178319","rc":[{"atb":[[2.1,1.94]],"id":69261147},{"atb":[[2.2,1.94]],"id":70642246}],"con":true,"img":false}]}
{"op":"mcm","clk":"11541027353","pt":1719501304598,"mc":[{"id":"1.230178319","rc":[{"atb":[[1.01,24.17]],"id":62766534},{"atl":[[1000,1.88]],"id":62766534},{"atb":[[1.01,1.7]],"id":39959056},{"atl":[[1000,1.7]],"id":39959056},{"atb":[[1.14,2.19]],"id":40214683},{"atl":[[1000,1.7]],"id":40214683}],"con":true,"img":false}]}
{"op":"mcm","clk":"11541027378","pt":1719501304805,"mc":[{"id":"1.230178319","rc":[{"atb":[[1.01,23.86]],"id":62766534},{"atl":[[1000,0.22]],"id":62766534},{"atb":[[1.01,0.4]],"id":39959056},{"atl":[[1000,0.02]],"id":39959056},{"atl":[[1000,0.04]],"id":40214683}],"con":true,"img":false}]}
{"op":"mcm","clk":"11541027397","pt":1719501305007,"mc":[{"id":"1.230178319","rc":[{"atb":[[1.01,22.47]],"id":62766534},{"atl":[[1000,0.17]],"id":62766534},{"atb":[[1.01,0]],"id":39959056},{"atl":[[1000,0]],"id":39959056},{"atl":[[1000,0]],"id":40214683}],"con":true,"img":false}]}
{"op":"mcm","clk":"11541027411","pt":1719501305113,"mc":[{"id":"1.230178319","rc":[{"atb":[[1.22,1.39]],"id":62766534},{"atl":[[7.4,0.04]],"id":62766534},{"atb":[[1.75,0.4]],"id":39959056},{"atl":[[16,0.86]],"id":39959056},{"atl":[[7.4,0.04]],"id":40214683}],"con":true,"img":false}]}
{"op":"mcm","clk":"11541027433","pt":1719501305323,"mc":[{"id":"1.230178319","rc":[{"atb":[[2.1,0]],"id":69261147},{"atb":[[2.2,0]],"id":70642246}],"con":true,"img":false}]}
{"op":"mcm","clk":"11541027447","pt":1719501305530,"mc":[{"id":"1.230178319","rc":[{"atb":[[2.1,1.94]],"id":69261147},{"atb":[[2.2,1.94]],"id":70642246}],"con":true,"img":false}]}
{"op":"mcm","clk":"11541027458","pt":1719501305631,"mc":[{"id":"1.230178319","rc":[{"atb":[[1.13,0]],"id":40214683}],"con":true,"img":false}]}
{"op":"mcm","clk":"11541027470","pt":1719501305735,"mc":[{"id":"1.230178319","rc":[{"atb":[[1.15,2]],"id":40214683}],"con":true,"img":false}]}
{"op":"mcm","clk":"11541027495","pt":1719501305996,"mc":[{"id":"1.230178319","rc":[{"atb":[[1.21,0]],"id":62766534}],"con":true,"img":false}]}
{"op":"mcm","clk":"11541027510","pt":1719501306103,"mc":[{"id":"1.230178319","rc":[{"atb":[[1.23,2]],"id":62766534}],"con":true,"img":false}]}
{"op":"mcm","clk":"11541027605","pt":1719501307149,"mc":[{"id":"1.230178319","rc":[{"atb":[[1.23,0]],"id":62766534}],"con":true,"img":false}]}
{"op":"mcm","clk":"11541027613","pt":1719501307244,"mc":[{"id":"1.230178319","rc":[{"atb":[[1.21,2]],"id":62766534}],"con":true,"img":false}]}
{"op":"mcm","clk":"11541027679","pt":1719501307815,"mc":[{"id":"1.230178319","rc":[{"atb":[[2.1,0]],"id":69261147},{"atb":[[2.2,0]],"id":70642246}],"con":true,"img":false}]}
{"op":"mcm","clk":"11541027698","pt":1719501308022,"mc":[{"id":"1.230178319","rc":[{"atb":[[2.1,1.94]],"id":69261147},{"atb":[[2.2,1.94]],"id":70642246}],"con":true,"img":false}]}
{"op":"mcm","clk":"11541027714","pt":1719501308233,"mc":[{"id":"1.230178319","rc":[{"atb":[[1.21,0]],"id":62766534}],"con":true,"img":false}]}
{"op":"mcm","clk":"11541027723","pt":1719501308338,"mc":[{"id":"1.230178319","rc":[{"atb":[[1.23,2]],"id":62766534}],"con":true,"img":false}]}
{"op":"mcm","clk":"11541027802","pt":1719501309213,"mc":[{"id":"1.230178319","rc":[{"atb":[[1.23,0]],"id":62766534}],"con":true,"img":false}]}
{"op":"mcm","clk":"11541027811","pt":1719501309318,"mc":[{"id":"1.230178319","rc":[{"atb":[[1.21,2]],"id":62766534}],"con":true,"img":false}]}
{"op":"mcm","clk":"11541027926","pt":1719501310301,"mc":[{"id":"1.230178319","rc":[{"atb":[[2.1,0]],"id":69261147},{"atb":[[2.2,0]],"id":70642246}],"con":true,"img":false}]}
{"op":"mcm","clk":"11541027948","pt":1719501310508,"mc":[{"id":"1.230178319","rc":[{"atb":[[2.1,1.94]],"id":69261147},{"atb":[[2.2,1.94]],"id":70642246}],"con":true,"img":false}]}
{"op":"mcm","clk":"11541028057","pt":1719501311438,"mc":[{"id":"1.230178319","rc":[{"atb":[[1.21,0]],"id":62766534}],"con":true,"img":false}]}
{"op":"mcm","clk":"11541028067","pt":1719501311541,"mc":[{"id":"1.230178319","rc":[{"atb":[[1.23,2]],"id":62766534}],"con":true,"img":false}]}
{"op":"mcm","clk":"11541028159","pt":1719501312427,"mc":[{"id":"1.230178319","rc":[{"atb":[[1.23,0]],"id":62766534}],"con":true,"img":false}]}
{"op":"mcm","clk":"11541028171","pt":1719501312533,"mc":[{"id":"1.230178319","rc":[{"atb":[[1.21,2]],"id":62766534}],"con":true,"img":false}]}
{"op":"mcm","clk":"11541028210","pt":1719501312839,"mc":[{"id":"1.230178319","rc":[{"atb":[[2.1,0]],"id":69261147},{"atb":[[2.2,0]],"id":70642246}],"con":true,"img":false}]}
{"op":"mcm","clk":"11541028222","pt":1719501312950,"mc":[{"id":"1.230178319","rc":[{"atb":[[2.1,1.94]],"id":69261147},{"atb":[[2.2,1.94]],"id":70642246}],"con":true,"img":false}]}
{"op":"mcm","clk":"11541028351","pt":1719501314444,"mc":[{"id":"1.230178319","rc":[{"atb":[[1.21,0]],"id":62766534}],"con":true,"img":false}]}
{"op":"mcm","clk":"11541028359","pt":1719501314543,"mc":[{"id":"1.230178319","rc":[{"atb":[[1.23,2]],"id":62766534}],"con":true,"img":false}]}
{"op":"mcm","clk":"11541028448","pt":1719501315534,"mc":[{"id":"1.230178319","rc":[{"atb":[[2.1,0]],"id":69261147},{"atb":[[2.2,0]],"id":70642246}],"con":true,"img":false}]}
{"op":"mcm","clk":"11541028466","pt":1719501315735,"mc":[{"id":"1.230178319","rc":[{"atb":[[2.1,1.94]],"id":69261147},{"atb":[[2.2,1.94]],"id":70642246}],"con":true,"img":false}]}
{"op":"mcm","clk":"11541028480","pt":1719501315838,"mc":[{"id":"1.230178319","rc":[{"atb":[[1.23,0]],"id":62766534}],"con":true,"img":false}]}
{"op":"mcm","clk":"11541028491","pt":1719501315942,"mc":[{"id":"1.230178319","rc":[{"atb":[[1.21,2]],"id":62766534}],"con":true,"img":false}]}
{"op":"mcm","clk":"11541028586","pt":1719501316925,"mc":[{"id":"1.230178319","rc":[{"atb":[[1.21,0]],"id":62766534}],"con":true,"img":false}]}
{"op":"mcm","clk":"11541028598","pt":1719501317031,"mc":[{"id":"1.230178319","rc":[{"atb":[[1.23,2]],"id":62766534}],"con":true,"img":false}]}
{"op":"mcm","clk":"11541028688","pt":1719501318059,"mc":[{"id":"1.230178319","rc":[{"atb":[[1.23,0]],"id":62766534},{"atb":[[2.1,0]],"id":69261147},{"atb":[[2.2,0]],"id":70642246}],"con":true,"img":false}]}
{"op":"mcm","clk":"11541028695","pt":1719501318113,"mc":[{"id":"1.230178319","rc":[{"atb":[[1.21,2]],"id":62766534}],"con":true,"img":false}]}
{"op":"mcm","clk":"11541028702","pt":1719501318216,"mc":[{"id":"1.230178319","rc":[{"atb":[[2.1,1.94]],"id":69261147},{"atb":[[2.2,1.94]],"id":70642246}],"con":true,"img":false}]}
{"op":"mcm","clk":"11541028833","pt":1719501319633,"mc":[{"id":"1.230178319","rc":[{"atb":[[1.21,0]],"id":62766534}],"con":true,"img":false}]}
{"op":"mcm","clk":"11541028843","pt":1719501319733,"mc":[{"id":"1.230178319","rc":[{"atb":[[1.23,2]],"id":62766534}],"con":true,"img":false}]}
{"op":"mcm","clk":"11541028948","pt":1719501320619,"mc":[{"id":"1.230178319","rc":[{"atb":[[2.1,0]],"id":69261147},{"atb":[[2.2,0]],"id":70642246}],"con":true,"img":false}]}
{"op":"mcm","clk":"11541028973","pt":1719501320824,"mc":[{"id":"1.230178319","rc":[{"atb":[[2.1,1.94]],"id":69261147},{"atb":[[2.2,1.94]],"id":70642246}],"con":true,"img":false}]}
{"op":"mcm","clk":"11541029035","pt":1719501321241,"mc":[{"id":"1.230178319","rc":[{"atb":[[1.23,0]],"id":62766534}],"con":true,"img":false}]}
{"op":"mcm","clk":"11541029050","pt":1719501321347,"mc":[{"id":"1.230178319","rc":[{"atb":[[1.21,2]],"id":62766534}],"con":true,"img":false}]}
{"op":"mcm","clk":"11541029190","pt":1719501322546,"mc":[{"id":"1.230178319","rc":[{"atl":[[16.5,0],[18,4.87]],"id":39959056}],"con":true,"img":false}]}
{"op":"mcm","clk":"11541029206","pt":1719501322748,"mc":[{"id":"1.230178319","rc":[{"atb":[[1.21,0]],"id":62766534}],"con":true,"img":false}]}
{"op":"mcm","clk":"11541029218","pt":1719501322855,"mc":[{"id":"1.230178319","rc":[{"atb":[[1.23,2]],"id":62766534}],"con":true,"img":false}]}
{"op":"mcm","clk":"11541029257","pt":1719501323221,"mc":[{"id":"1.230178319","rc":[{"atl":[[16,0.02]],"id":39959056}],"con":true,"img":false}]}
{"op":"mcm","clk":"11541029291","pt":1719501323633,"mc":[{"id":"1.230178319","rc":[{"atl":[[17.5,0.84]],"id":39959056}],"con":true,"img":false}]}
{"op":"mcm","clk":"11541029328","pt":1719501323942,"mc":[{"id":"1.230178319","rc":[{"atb":[[1.23,0]],"id":62766534}],"con":true,"img":false}]}
{"op":"mcm","clk":"11541029338","pt":1719501324046,"mc":[{"id":"1.230178319","rc":[{"atb":[[1.21,2]],"id":62766534}],"con":true,"img":false}]}
{"op":"mcm","clk":"11541029443","pt":1719501325136,"mc":[{"id":"1.230178319","rc":[{"spl":[[1.01,1.39]],"id":39959056}],"con":true,"img":false}]}
{"op":"mcm","clk":"11541029466","pt":1719501325344,"mc":[{"id":"1.230178319","rc":[{"atb":[[1.21,0]],"id":62766534}],"con":true,"img":false}]}
{"op":"mcm","clk":"11541029477","pt":1719501325457,"mc":[{"id":"1.230178319","rc":[{"atb":[[1.23,2]],"id":62766534}],"con":true,"img":false}]}
{"op":"mcm","clk":"11541029561","pt":1719501326434,"mc":[{"id":"1.230178319","rc":[{"atb":[[1.23,0]],"id":62766534}],"con":true,"img":false}]}
{"op":"mcm","clk":"11541029568","pt":1719501326531,"mc":[{"id":"1.230178319","rc":[{"atb":[[1.21,2]],"id":62766534}],"con":true,"img":false}]}
{"op":"mcm","clk":"11541029685","pt":1719501327832,"mc":[{"id":"1.230178319","rc":[{"atb":[[1.21,0]],"id":62766534}],"con":true,"img":false}]}
{"op":"mcm","clk":"11541029695","pt":1719501327934,"mc":[{"id":"1.230178319","rc":[{"atb":[[1.23,2]],"id":62766534}],"con":true,"img":false}]}
{"op":"mcm","clk":"11541029766","pt":1719501328755,"mc":[{"id":"1.230178319","rc":[{"atb":[[1.23,0]],"id":62766534}],"con":true,"img":false}]}
{"op":"mcm","clk":"11541029775","pt":1719501328860,"mc":[{"id":"1.230178319","rc":[{"atb":[[1.21,2]],"id":62766534}],"con":true,"img":false}]}
{"op":"mcm","clk":"11541029954","pt":1719501330877,"mc":[{"id":"1.230178319","rc":[{"atb":[[1.21,0]],"id":62766534}],"con":true,"img":false}]}
{"op":"mcm","clk":"11541029966","pt":1719501330934,"mc":[{"id":"1.230178319","rc":[{"atb":[[1.23,2]],"id":62766534}],"con":true,"img":false}]}
{"op":"mcm","clk":"11541030076","pt":1719501332141,"mc":[{"id":"1.230178319","rc":[{"atb":[[1.23,0]],"id":62766534}],"con":true,"img":false}]}
{"op":"mcm","clk":"11541030087","pt":1719501332247,"mc":[{"id":"1.230178319","rc":[{"atb":[[1.21,2]],"id":62766534}],"con":true,"img":false}]}
{"op":"mcm","clk":"11541030150","pt":1719501333278,"mc":[{"id":"1.230178319","rc":[{"atb":[[1.21,0]],"id":62766534}],"con":true,"img":false}]}
{"op":"mcm","clk":"11541030152","pt":1719501333332,"mc":[{"id":"1.230178319","rc":[{"atb":[[1.23,2]],"id":62766534}],"con":true,"img":false}]}
{"op":"mcm","clk":"11541030261","pt":1719501334635,"mc":[{"id":"1.230178319","rc":[{"atb":[[1.23,0]],"id":62766534}],"con":true,"img":false}]}
{"op":"mcm","clk":"11541030267","pt":1719501334746,"mc":[{"id":"1.230178319","rc":[{"atb":[[1.21,2]],"id":62766534}],"con":true,"img":false}]}
{"op":"mcm","clk":"11541030359","pt":1719501336033,"mc":[{"id":"1.230178319","rc":[{"atb":[[1.21,0]],"id":62766534}],"con":true,"img":false}]}
{"op":"mcm","clk":"11541030367","pt":1719501336143,"mc":[{"id":"1.230178319","rc":[{"atb":[[1.23,2]],"id":62766534}],"con":true,"img":false}]}
{"op":"mcm","clk":"11541030440","pt":1719501337068,"mc":[{"id":"1.230178319","rc":[{"atb":[[1.23,0]],"id":62766534}],"con":true,"img":false}]}
{"op":"mcm","clk":"11541030445","pt":1719501337172,"mc":[{"id":"1.230178319","rc":[{"atb":[[1.21,2]],"id":62766534}],"con":true,"img":false}]}
{"op":"mcm","clk":"11541030547","pt":1719501338359,"mc":[{"id":"1.230178319","rc":[{"atb":[[1.21,0]],"id":62766534}],"con":true,"img":false}]}
{"op":"mcm","clk":"11541030559","pt":1719501338467,"mc":[{"id":"1.230178319","rc":[{"atb":[[1.23,2]],"id":62766534}],"con":true,"img":false}]}
{"op":"mcm","clk":"11541030768","pt":1719501340546,"mc":[{"id":"1.230178319","rc":[{"atb":[[1.23,0]],"id":62766534}],"con":true,"img":false}]}
{"op":"mcm","clk":"11541030777","pt":1719501340651,"mc":[{"id":"1.230178319","rc":[{"atb":[[1.21,2]],"id":62766534}],"con":true,"img":false}]}
{"op":"mcm","clk":"11541030942","pt":1719501342578,"mc":[{"id":"1.230178319","rc":[{"atb":[[1.21,0]],"id":62766534}],"con":true,"img":false}]}
{"op":"mcm","clk":"11541030954","pt":1719501342682,"mc":[{"id":"1.230178319","rc":[{"atb":[[1.23,2]],"id":62766534}],"con":true,"img":false}]}
{"op":"mcm","clk":"11541030970","pt":1719501342840,"mc":[{"id":"1.230178319","rc":[{"atb":[[1.22,0]],"id":62766534},{"atl":[[7.4,0]],"id":62766534},{"atb":[[1.75,0]],"id":39959056},{"atl":[[16,0]],"id":39959056},{"atb":[[1.14,0]],"id":40214683},{"atl":[[7.4,0]],"id":40214683}],"con":true,"img":false}]}
{"op":"mcm","clk":"11541030990","pt":1719501343048,"mc":[{"id":"1.230178319","rc":[{"atb":[[1.74,0],[1.68,3]],"id":39959056}],"con":true,"img":false}]}
{"op":"mcm","clk":"11541031048","pt":1719501343671,"mc":[{"id":"1.230178319","rc":[{"atb":[[1.15,0]],"id":40214683}],"con":true,"img":false}]}
{"op":"mcm","clk":"11541031058","pt":1719501343774,"mc":[{"id":"1.230178319","rc":[{"atb":[[1.13,2]],"id":40214683}],"con":true,"img":false}]}
{"op":"mcm","clk":"11541031083","pt":1719501344105,"mc":[{"id":"1.230178319","rc":[{"atb":[[1.02,0]],"id":39959056}],"con":true,"img":false}]}
{"op":"mcm","clk":"11541031091","pt":1719501344140,"mc":[{"id":"1.230178319","rc":[{"atb":[[1.69,2]],"id":39959056}],"con":true,"img":false}]}
{"op":"mcm","clk":"11541031122","pt":1719501344557,"mc":[{"id":"1.230178319","rc":[{"atb":[[1.23,0]],"id":62766534}],"con":true,"img":false}]}
{"op":"mcm","clk":"11541031131","pt":1719501344661,"mc":[{"id":"1.230178319","rc":[{"atb":[[1.21,2]],"id":62766534}],"con":true,"img":false}]}
{"op":"mcm","clk":"11541031547","pt":1719501349289,"mc":[{"id":"1.230178319","rc":[{"atb":[[1.06,2.5]],"id":40214683}],"con":true,"img":false}]}
{"op":"mcm","clk":"11541031558","pt":1719501349393,"mc":[{"id":"1.230178319","rc":[{"atb":[[1.06,0]],"id":40214683}],"con":true,"img":false}]}
{"op":"mcm","clk":"11541031656","pt":1719501350484,"mc":[{"id":"1.230178319","rc":[{"atb":[[2.24,1],[2.32,0],[1.43,0],[1.7,2.12]],"id":39959056}],"con":true,"img":false}]}
{"op":"mcm","clk":"11541031672","pt":1719501350689,"mc":[{"id":"1.230178319","rc":[{"atl":[[3.45,0],[3.75,1]],"id":62766534},{"atl":[[3.35,1],[3.05,0]],"id":40214683},{"atl":[[4.4,1],[4.2,0]],"id":56418091}],"con":true,"img":false}]}
{"op":"mcm","clk":"11541031679","pt":1719501350794,"mc":[{"id":"1.230178319","rc":[{"atl":[[8.2,0],[7.4,3]],"id":62766534}],"con":true,"img":false}]}
{"op":"mcm","clk":"11541031757","pt":1719501351580,"mc":[{"id":"1.230178319","rc":[{"atb":[[1.69,0]],"id":39959056}],"con":true,"img":false}]}
{"op":"mcm","clk":"11541031767","pt":1719501351677,"mc":[{"id":"1.230178319","rc":[{"atb":[[1.71,2]],"id":39959056},{"atb":[[2.1,0]],"id":69261147},{"atb":[[2.2,0]],"id":70642246}],"con":true,"img":false}]}
{"op":"mcm","clk":"11541031776","pt":1719501351787,"mc":[{"id":"1.230178319","rc":[{"atb":[[2.1,1.94]],"id":69261147},{"atb":[[2.2,1.94]],"id":70642246}],"con":true,"img":false}]}
{"op":"mcm","clk":"11541031946","pt":1719501353677,"mc":[{"id":"1.230178319","rc":[{"atb":[[2.1,0]],"id":69261147},{"atb":[[2.2,0]],"id":70642246}],"con":true,"img":false}]}
{"op":"mcm","clk":"11541031973","pt":1719501353887,"mc":[{"id":"1.230178319","rc":[{"atb":[[2.1,1.94]],"id":69261147},{"atb":[[2.2,1.94]],"id":70642246}],"con":true,"img":false}]}
{"op":"mcm","clk":"11541032111","pt":1719501355696,"mc":[{"id":"1.230178319","rc":[{"atb":[[2.1,0]],"id":69261147},{"atb":[[2.2,0]],"id":70642246}],"con":true,"img":false}]}
{"op":"mcm","clk":"11541032129","pt":1719501355860,"mc":[{"id":"1.230178319","rc":[{"atb":[[2.1,1.94]],"id":69261147},{"atb":[[2.2,1.94]],"id":70642246}],"con":true,"img":false}]}
{"op":"mcm","clk":"11541032283","pt":1719501357671,"mc":[{"id":"1.230178319","rc":[{"atb":[[2.1,0]],"id":69261147},{"atb":[[2.2,0]],"id":70642246}],"con":true,"img":false}]}
{"op":"mcm","clk":"11541032299","pt":1719501357876,"mc":[{"id":"1.230178319","rc":[{"spn":2.65,"spf":"NaN","id":62766534},{"spn":2.09,"spf":1.0,"id":39959056},{"spn":2.39,"spf":"NaN","id":40214683},{"spn":3.07,"spf":"NaN","id":56418091},{"atb":[[2.1,1.94]],"id":69261147},{"atb":[[2.2,1.94]],"id":70642246}],"con":true,"img":false}]}
{"op":"mcm","clk":"11541032461","pt":1719501359699,"mc":[{"id":"1.230178319","rc":[{"atb":[[2.1,0]],"id":69261147},{"atb":[[2.2,0]],"id":70642246}],"con":true,"img":false}]}
{"op":"mcm","clk":"11541032475","pt":1719501359906,"mc":[{"id":"1.230178319","rc":[{"atb":[[2.1,1.94]],"id":69261147},{"atb":[[2.2,1.94]],"id":70642246}],"con":true,"img":false}]}
{"op":"mcm","clk":"11541032539","pt":1719501360586,"mc":[{"id":"1.230178319","rc":[{"atl":[[7.8,1]],"id":70642246}],"con":true,"img":false}]}
{"op":"mcm","clk":"11541032547","pt":1719501360691,"mc":[{"id":"1.230178319","rc":[{"atl":[[8.2,0],[7.8,1]],"id":69261147},{"atl":[[8.2,0]],"id":70642246}],"con":true,"img":false}]}
{"op":"mcm","clk":"11541032656","pt":1719501361682,"mc":[{"id":"1.230178319","rc":[{"atb":[[2.1,0]],"id":69261147},{"atb":[[2.2,0]],"id":70642246}],"con":true,"img":false}]}
{"op":"mcm","clk":"11541032670","pt":1719501361887,"mc":[{"id":"1.230178319","rc":[{"atb":[[2.1,1.94]],"id":69261147},{"atb":[[2.2,1.94]],"id":70642246}],"con":true,"img":false}]}
{"op":"mcm","clk":"11541032718","pt":1719501362461,"mc":[{"id":"1.230178319","rc":[{"atb":[[1.7,0]],"id":39959056}],"con":true,"img":false}]}
{"op":"mcm","clk":"11541032751","pt":1719501362874,"mc":[{"id":"1.230178319","rc":[{"atb":[[1.71,0]],"id":39959056}],"con":true,"img":false}]}
{"op":"mcm","clk":"11541032762","pt":1719501362978,"mc":[{"id":"1.230178319","rc":[{"atb":[[1.69,2]],"id":39959056}],"con":true,"img":false}]}
{"op":"mcm","clk":"11541032824","pt":1719501363707,"mc":[{"id":"1.230178319","rc":[{"atb":[[2.1,0]],"id":69261147},{"atb":[[2.2,0]],"id":70642246}],"con":true,"img":false}]}
{"op":"mcm","clk":"11541032845","pt":1719501363866,"mc":[{"id":"1.230178319","rc":[{"atb":[[2.1,1.94]],"id":69261147},{"atb":[[2.2,1.94]],"id":70642246}],"con":true,"img":false}]}
{"op":"mcm","clk":"11541033049","pt":1719501366206,"mc":[{"id":"1.230178319","rc":[{"atb":[[2.1,0]],"id":69261147},{"atb":[[2.2,0]],"id":70642246}],"con":true,"img":false}]}
{"op":"mcm","clk":"11541033068","pt":1719501366363,"mc":[{"id":"1.230178319","rc":[{"atb":[[2.1,1.94]],"id":69261147},{"atb":[[2.2,1.94]],"id":70642246}],"con":true,"img":false}]}
{"op":"mcm","clk":"11541033237","pt":1719501368090,"mc":[{"id":"1.230178319","rc":[{"atb":[[1.7,2.12]],"id":39959056}],"con":true,"img":false}]}
{"op":"mcm","clk":"11541033300","pt":1719501368665,"mc":[{"id":"1.230178319","rc":[{"atb":[[2.1,0]],"id":69261147},{"atb":[[2.2,0]],"id":70642246}],"con":true,"img":false}]}
{"op":"mcm","clk":"11541033319","pt":1719501368873,"mc":[{"id":"1.230178319","rc":[{"atb":[[2.1,1.94]],"id":69261147},{"atb":[[2.2,1.94]],"id":70642246}],"con":true,"img":false}]}
{"op":"mcm","clk":"11541033363","pt":1719501369289,"mc":[{"id":"1.230178319","rc":[{"atb":[[2.24,0],[2.32,1],[1.69,0]],"id":39959056}],"con":true,"img":false}]}
{"op":"mcm","clk":"11541033373","pt":1719501369389,"mc":[{"id":"1.230178319","rc":[{"atb":[[1.7,4.24],[1.68,0],[1.71,2]],"id":39959056}],"con":true,"img":false}]}
{"op":"mcm","clk":"11541033495","pt":1719501370690,"mc":[{"id":"1.230178319","rc":[{"atl":[[8.2,1],[7.8,0]],"id":69261147},{"atl":[[8.2,1],[7.8,0]],"id":70642246}],"con":true,"img":false}]}
{"op":"mcm","clk":"11541033505","pt":1719501370792,"mc":[{"id":"1.230178319","rc":[{"atl":[[65,2],[60,0]],"id":70642246}],"con":true,"img":false}]}
{"op":"mcm","clk":"11541033554","pt":1719501371306,"mc":[{"id":"1.230178319","rc":[{"atb":[[2.1,0]],"id":69261147},{"atb":[[2.2,0]],"id":70642246}],"con":true,"img":false}]}
{"op":"mcm","clk":"11541033564","pt":1719501371409,"mc":[{"id":"1.230178319","rc":[{"atb":[[2.1,1.94]],"id":69261147},{"atb":[[2.2,1.94]],"id":70642246}],"con":true,"img":false}]}
{"op":"mcm","clk":"11541033779","pt":1719501373800,"mc":[{"id":"1.230178319","rc":[{"atb":[[2.1,0]],"id":69261147},{"atb":[[2.2,0]],"id":70642246}],"con":true,"img":false}]}
{"op":"mcm","clk":"11541033788","pt":1719501373909,"mc":[{"id":"1.230178319","rc":[{"atb":[[2.1,1.94]],"id":69261147},{"atb":[[2.2,1.94]],"id":70642246}],"con":true,"img":false}]}
{"op":"mcm","clk":"11541033835","pt":1719501374379,"mc":[{"id":"1.230178319","rc":[{"atb":[[2.24,1],[2.32,0],[1.7,2.12]],"id":39959056}],"con":true,"img":false}]}
{"op":"mcm","clk":"11541033989","pt":1719501376291,"mc":[{"id":"1.230178319","rc":[{"atb":[[2.1,0]],"id":69261147},{"atb":[[2.2,0]],"id":70642246}],"con":true,"img":false}]}
{"op":"mcm","clk":"11541034007","pt":1719501376492,"mc":[{"id":"1.230178319","rc":[{"atb":[[2.1,1.94]],"id":69261147},{"atb":[[2.2,1.94]],"id":70642246}],"con":true,"img":false}]}
{"op":"mcm","clk":"11541034039","pt":1719501376822,"mc":[{"id":"1.230178319","rc":[{"atb":[[2.24,0],[2.32,1]],"id":39959056}],"con":true,"img":false}]}
{"op":"mcm","clk":"11541034187","pt":1719501378622,"mc":[{"id":"1.230178319","rc":[{"atb":[[2.24,1],[2.32,0]],"id":39959056}],"con":true,"img":false}]}
{"op":"mcm","clk":"11541034197","pt":1719501378721,"mc":[{"id":"1.230178319","rc":[{"atb":[[1.72,2.12],[1.7,0]],"id":39959056}],"con":true,"img":false}]}
{"op":"mcm","clk":"11541034205","pt":1719501378820,"mc":[{"id":"1.230178319","rc":[{"atb":[[2.1,0]],"id":69261147},{"atb":[[2.2,0]],"id":70642246}],"con":true,"img":false}]}
{"op":"mcm","clk":"11541034227","pt":1719501378979,"mc":[{"id":"1.230178319","rc":[{"atb":[[2.1,1.94]],"id":69261147},{"atb":[[2.2,1.94]],"id":70642246}],"con":true,"img":false}]}
{"op":"mcm","clk":"11541034312","pt":1719501380019,"mc":[{"id":"1.230178319","rc":[{"atb":[[1.71,0]],"id":39959056}],"con":true,"img":false}]}
{"op":"mcm","clk":"11541034321","pt":1719501380119,"mc":[{"id":"1.230178319","rc":[{"atb":[[1.02,2]],"id":39959056}],"con":true,"img":false}]}
{"op":"mcm","clk":"11541034776","pt":1719501385294,"mc":[{"id":"1.230178319","rc":[{"atb":[[1.43,2.48]],"id":39959056}],"con":true,"img":false}]}
{"op":"mcm","clk":"11541034854","pt":1719501386320,"mc":[{"id":"1.230178319","rc":[{"atb":[[2.1,0]],"id":69261147},{"atb":[[2.2,0]],"id":70642246}],"con":true,"img":false}]}
{"op":"mcm","clk":"11541034866","pt":1719501386424,"mc":[{"id":"1.230178319","rc":[{"atb":[[2.1,1.94]],"id":69261147},{"atb":[[2.2,1.94]],"id":70642246}],"con":true,"img":false}]}
{"op":"mcm","clk":"11541036219","pt":1719501403840,"mc":[{"id":"1.230178319","rc":[{"atb":[[2.1,0]],"id":69261147},{"atb":[[2.2,0]],"id":70642246}],"con":true,"img":false}]}
{"op":"mcm","clk":"11541036234","pt":1719501404042,"mc":[{"id":"1.230178319","rc":[{"atb":[[2.1,1.94]],"id":69261147},{"atb":[[2.2,1.94]],"id":70642246}],"con":true,"img":false}]}
{"op":"mcm","clk":"11541037889","pt":1719501426260,"mc":[{"id":"1.230178319","rc":[{"atb":[[1.01,24.17]],"id":62766534},{"atl":[[1000,1.88]],"id":62766534},{"atb":[[1.01,1.7]],"id":39959056},{"atl":[[1000,1.7]],"id":39959056},{"spn":2.09,"spf":1.0,"id":39959056},{"atb":[[1.14,2.1]],"id":40214683},{"atl":[[1000,1.7]],"id":40214683}],"con":true,"img":false}]}
{"op":"mcm","clk":"11541037912","pt":1719501426564,"mc":[{"id":"1.230178319","rc":[{"atb":[[1.01,23.81]],"id":62766534},{"atl":[[1000,0.22]],"id":62766534},{"atb":[[1.01,0.4]],"id":39959056},{"atl":[[1000,0.01]],"id":39959056},{"atl":[[1000,0.04]],"id":40214683}],"con":true,"img":false}]}
{"op":"mcm","clk":"11541037922","pt":1719501426619,"mc":[{"id":"1.230178319","rc":[{"atb":[[1.01,22.47]],"id":62766534},{"atl":[[1000,0.17]],"id":62766534},{"atb":[[1.01,0]],"id":39959056},{"atl":[[1000,0]],"id":39959056},{"atb":[[1.13,0]],"id":40214683},{"atl":[[1000,0]],"id":40214683}],"con":true,"img":false}]}
{"op":"mcm","clk":"11541037930","pt":1719501426721,"mc":[{"id":"1.230178319","rc":[{"atb":[[1.22,1.34]],"id":62766534},{"atl":[[7.2,0.04]],"id":62766534},{"atb":[[1.73,0.4]],"id":39959056},{"atl":[[17.5,0.86]],"id":39959056},{"atb":[[1.15,2]],"id":40214683},{"atl":[[7.4,0.04]],"id":40214683}],"con":true,"img":false}]}
{"op":"mcm","clk":"11541038088","pt":1719501428947,"mc":[{"id":"1.230178319","rc":[{"atb":[[2.1,0]],"id":69261147},{"atb":[[2.2,0]],"id":70642246}],"con":true,"img":false}]}
{"op":"mcm","clk":"11541038110","pt":1719501429149,"mc":[{"id":"1.230178319","rc":[{"atb":[[2.1,1.94]],"id":69261147},{"atb":[[2.2,1.94]],"id":70642246}],"con":true,"img":false}]}
{"op":"mcm","clk":"11541038159","pt":1719501429727,"mc":[{"id":"1.230178319","rc":[{"atb":[[1.21,0]],"id":62766534}],"con":true,"img":false}]}
{"op":"mcm","clk":"11541038166","pt":1719501429822,"mc":[{"id":"1.230178319","rc":[{"atb":[[1.23,2]],"id":62766534}],"con":true,"img":false}]}
{"op":"mcm","clk":"11541038324","pt":1719501431429,"mc":[{"id":"1.230178319","rc":[{"atb":[[2.1,0]],"id":69261147},{"atb":[[2.2,0]],"id":70642246}],"con":true,"img":false}]}
{"op":"mcm","clk":"11541038332","pt":1719501431531,"mc":[{"id":"1.230178319","rc":[{"atb":[[2.1,1.94]],"id":69261147},{"atb":[[2.2,1.94]],"id":70642246}],"con":true,"img":false}]}
{"op":"mcm","clk":"11541038544","pt":1719501434049,"mc":[{"id":"1.230178319","rc":[{"atb":[[2.1,0]],"id":69261147},{"atb":[[2.2,0]],"id":70642246}],"con":true,"img":false}]}
{"op":"mcm","clk":"11541038562","pt":1719501434255,"mc":[{"id":"1.230178319","rc":[{"atb":[[2.1,1.94]],"id":69261147},{"atb":[[2.2,1.94]],"id":70642246}],"con":true,"img":false}]}
{"op":"mcm","clk":"11541038644","pt":1719501435237,"mc":[{"id":"1.230178319","rc":[{"atb":[[1.23,0]],"id":62766534}],"con":true,"img":false}]}
{"op":"mcm","clk":"11541038651","pt":1719501435339,"mc":[{"id":"1.230178319","rc":[{"atb":[[1.21,2]],"id":62766534}],"con":true,"img":false}]}
{"op":"mcm","clk":"11541038939","pt":1719501439164,"mc":[{"id":"1.230178319","rc":[{"atb":[[1.21,0]],"id":62766534}],"con":true,"img":false}]}
{"op":"mcm","clk":"11541038952","pt":1719501439267,"mc":[{"id":"1.230178319","rc":[{"atb":[[1.23,2]],"id":62766534}],"con":true,"img":false}]}
{"op":"mcm","clk":"11541039067","pt":1719501440668,"mc":[{"id":"1.230178319","rc":[{"atb":[[1.23,0]],"id":62766534}],"con":true,"img":false}]}
{"op":"mcm","clk":"11541039083","pt":1719501440763,"mc":[{"id":"1.230178319","rc":[{"atb":[[1.21,2]],"id":62766534}],"con":true,"img":false}]}
{"op":"mcm","clk":"11541039217","pt":1719501442476,"mc":[{"id":"1.230178319","rc":[{"atb":[[1.21,0]],"id":62766534}],"con":true,"img":false}]}
{"op":"mcm","clk":"11541039232","pt":1719501442583,"mc":[{"id":"1.230178319","rc":[{"atb":[[1.23,2]],"id":62766534}],"con":true,"img":false}]}
{"op":"mcm","clk":"11541039322","pt":1719501443777,"mc":[{"id":"1.230178319","rc":[{"atb":[[1.23,0]],"id":62766534}],"con":true,"img":false}]}
{"op":"mcm","clk":"11541039330","pt":1719501443891,"mc":[{"id":"1.230178319","rc":[{"atb":[[1.21,2]],"id":62766534}],"con":true,"img":false}]}
{"op":"mcm","clk":"11541039490","pt":1719501445579,"mc":[{"id":"1.230178319","rc":[{"atb":[[1.21,0]],"id":62766534}],"con":true,"img":false}]}
{"op":"mcm","clk":"11541039503","pt":1719501445684,"mc":[{"id":"1.230178319","rc":[{"atb":[[1.23,2]],"id":62766534}],"con":true,"img":false}]}
{"op":"mcm","clk":"11541039616","pt":1719501447279,"mc":[{"id":"1.230178319","rc":[{"atb":[[1.23,0]],"id":62766534}],"con":true,"img":false}]}
{"op":"mcm","clk":"11541039622","pt":1719501447380,"mc":[{"id":"1.230178319","rc":[{"atb":[[1.21,2]],"id":62766534}],"con":true,"img":false}]}
{"op":"mcm","clk":"11541039684","pt":1719501448259,"mc":[{"id":"1.230178319","rc":[{"atb":[[1.21,0]],"id":62766534}],"con":true,"img":false}]}
{"op":"mcm","clk":"11541039690","pt":1719501448363,"mc":[{"id":"1.230178319","rc":[{"atb":[[1.23,2]],"id":62766534}],"con":true,"img":false}]}
{"op":"mcm","clk":"11541039781","pt":1719501449573,"mc":[{"id":"1.230178319","rc":[{"atb":[[1.23,0]],"id":62766534}],"con":true,"img":false}]}
{"op":"mcm","clk":"11541039792","pt":1719501449686,"mc":[{"id":"1.230178319","rc":[{"atb":[[1.21,2]],"id":62766534}],"con":true,"img":false}]}
{"op":"mcm","clk":"11541040013","pt":1719501452060,"mc":[{"id":"1.230178319","rc":[{"atb":[[1.21,0]],"id":62766534}],"con":true,"img":false}]}
{"op":"mcm","clk":"11541040025","pt":1719501452168,"mc":[{"id":"1.230178319","rc":[{"atb":[[1.23,2]],"id":62766534}],"con":true,"img":false}]}
{"op":"mcm","clk":"11541040146","pt":1719501453601,"mc":[{"id":"1.230178319","rc":[{"atb":[[1.23,0]],"id":62766534}],"con":true,"img":false}]}
{"op":"mcm","clk":"11541040152","pt":1719501453660,"mc":[{"id":"1.230178319","rc":[{"atb":[[1.21,2]],"id":62766534}],"con":true,"img":false}]}
{"op":"mcm","clk":"11541040258","pt":1719501454983,"mc":[{"id":"1.230178319","rc":[{"atb":[[1.21,0]],"id":62766534}],"con":true,"img":false}]}
{"op":"mcm","clk":"11541040264","pt":1719501455097,"mc":[{"id":"1.230178319","rc":[{"atb":[[1.23,2]],"id":62766534}],"con":true,"img":false}]}
{"op":"mcm","clk":"11541040358","pt":1719501456181,"mc":[{"id":"1.230178319","rc":[{"atb":[[1.23,0]],"id":62766534}],"con":true,"img":false}]}
{"op":"mcm","clk":"11541040365","pt":1719501456284,"mc":[{"id":"1.230178319","rc":[{"atb":[[1.21,2]],"id":62766534}],"con":true,"img":false}]}
{"op":"mcm","clk":"11541040445","pt":1719501457269,"mc":[{"id":"1.230178319","rc":[{"atb":[[1.21,0]],"id":62766534}],"con":true,"img":false}]}
{"op":"mcm","clk":"11541040452","pt":1719501457372,"mc":[{"id":"1.230178319","rc":[{"atb":[[1.23,2]],"id":62766534}],"con":true,"img":false}]}
{"op":"mcm","clk":"11541040566","pt":1719501458969,"mc":[{"id":"1.230178319","rc":[{"atb":[[1.23,0]],"id":62766534}],"con":true,"img":false}]}
{"op":"mcm","clk":"11541040576","pt":1719501459073,"mc":[{"id":"1.230178319","rc":[{"atb":[[1.21,2]],"id":62766534}],"con":true,"img":false}]}
{"op":"mcm","clk":"11541040685","pt":1719501460470,"mc":[{"id":"1.230178319","rc":[{"atb":[[1.21,0],[1.22,0]],"id":62766534},{"atl":[[7.2,0]],"id":62766534},{"atb":[[1.73,0]],"id":39959056},{"atl":[[17.5,0.84]],"id":39959056},{"atb":[[1.14,0]],"id":40214683},{"atl":[[7.4,0]],"id":40214683}],"con":true,"img":false}]}
{"op":"mcm","clk":"11541040693","pt":1719501460571,"mc":[{"id":"1.230178319","rc":[{"atb":[[1.23,2]],"id":62766534}],"con":true,"img":false}]}
{"op":"mcm","clk":"11541040784","pt":1719501461698,"mc":[{"id":"1.230178319","rc":[{"atb":[[2.1,0]],"id":69261147},{"atb":[[2.2,0]],"id":70642246}],"con":true,"img":false}]}
{"op":"mcm","clk":"11541040793","pt":1719501461809,"mc":[{"id":"1.230178319","rc":[{"atb":[[1.15,0]],"id":40214683}],"con":true,"img":false}]}
{"op":"mcm","clk":"11541040799","pt":1719501461905,"mc":[{"id":"1.230178319","rc":[{"atb":[[1.13,2]],"id":40214683},{"atb":[[2.1,1.94]],"id":69261147},{"atb":[[2.2,1.94]],"id":70642246}],"con":true,"img":false}]}
{"op":"mcm","clk":"11541040822","pt":1719501462281,"mc":[{"id":"1.230178319","rc":[{"atb":[[1.23,0]],"id":62766534}],"con":true,"img":false}]}
{"op":"mcm","clk":"11541040829","pt":1719501462384,"mc":[{"id":"1.230178319","rc":[{"atb":[[1.21,2]],"id":62766534}],"con":true,"img":false}]}
{"op":"mcm","clk":"11541040964","pt":1719501464196,"mc":[{"id":"1.230178319","rc":[{"atb":[[2.1,0]],"id":69261147},{"atb":[[2.2,0]],"id":70642246}],"con":true,"img":false}]}
{"op":"mcm","clk":"11541040972","pt":1719501464294,"mc":[{"id":"1.230178319","rc":[{"atb":[[2.1,1.94]],"id":69261147},{"atb":[[2.2,1.94]],"id":70642246}],"con":true,"img":false}]}
{"op":"mcm","clk":"11541041141","pt":1719501466883,"mc":[{"id":"1.230178319","rc":[{"atb":[[2.1,0]],"id":69261147},{"atb":[[2.2,0]],"id":70642246}],"con":true,"img":false}]}
{"op":"mcm","clk":"11541041156","pt":1719501467086,"mc":[{"id":"1.230178319","rc":[{"atb":[[2.1,1.94]],"id":69261147},{"atb":[[2.2,1.94]],"id":70642246}],"con":true,"img":false}]}
{"op":"mcm","clk":"11541041328","pt":1719501469406,"mc":[{"id":"1.230178319","rc":[{"atb":[[2.1,0]],"id":69261147},{"atb":[[2.2,0]],"id":70642246}],"con":true,"img":false}]}
{"op":"mcm","clk":"11541041336","pt":1719501469500,"mc":[{"id":"1.230178319","rc":[{"atb":[[2.1,1.94]],"id":69261147},{"atb":[[2.2,1.94]],"id":70642246}],"con":true,"img":false}]}
{"op":"mcm","clk":"11541043181","pt":1719501492121,"mc":[{"id":"1.230178319","rc":[{"atl":[[17.5,1.37]],"id":39959056}],"con":true,"img":false}]}
{"op":"mcm","clk":"11541043192","pt":1719501492229,"mc":[{"id":"1.230178319","rc":[{"atb":[[1.03,8.02]],"id":39959056}],"con":true,"img":false}]}
{"op":"mcm","clk":"11541043214","pt":1719501492541,"mc":[{"id":"1.230178319","rc":[{"atb":[[1.03,7.9]],"id":39959056}],"con":true,"img":false}]}
{"op":"mcm","clk":"11541043236","pt":1719501492836,"mc":[{"id":"1.230178319","rc":[{"atb":[[1.03,7.49]],"id":39959056}],"con":true,"img":false}]}
{"op":"mcm","clk":"11541043247","pt":1719501492940,"mc":[{"id":"1.230178319","rc":[{"atb":[[2.26,0.41]],"id":39959056}],"con":true,"img":false}]}
{"op":"mcm","clk":"11541043539","pt":1719501496640,"mc":[{"id":"1.230178319","rc":[{"atb":[[1.08,50]],"id":62766534},{"atb":[[1.08,50]],"id":39959056},{"atb":[[1.08,50]],"id":40214683},{"atb":[[1.08,50]],"id":56418091},{"atb":[[1.08,50]],"id":69261147},{"atb":[[1.08,50]],"id":70642246}],"con":true,"img":false}]}
{"op":"mcm","clk":"11541043975","pt":1719501502235,"mc":[{"id":"1.230178319","rc":[{"atb":[[2.1,0]],"id":69261147},{"atb":[[2.2,0]],"id":70642246}],"con":true,"img":false}]}
{"op":"mcm","clk":"11541043994","pt":1719501502438,"mc":[{"id":"1.230178319","rc":[{"atb":[[2.1,1.94]],"id":69261147},{"atb":[[2.2,1.94]],"id":70642246}],"con":true,"img":false}]}
{"op":"mcm","clk":"11541044357","pt":1719501507524,"mc":[{"id":"1.230178319","rc":[{"atl":[[17.5,0.84]],"id":39959056}],"con":true,"img":false}]}
{"op":"mcm","clk":"11541044412","pt":1719501508148,"mc":[{"id":"1.230178319","rc":[{"atb":[[2.26,0]],"id":39959056}],"con":true,"img":false}]}
{"op":"mcm","clk":"11541044515","pt":1719501509445,"mc":[{"id":"1.230178319","rc":[{"atl":[[17.5,1.37]],"id":39959056}],"con":true,"img":false}]}
{"op":"mcm","clk":"11541044523","pt":1719501509551,"mc":[{"id":"1.230178319","rc":[{"atb":[[1.03,8.02]],"id":39959056}],"con":true,"img":false}]}
{"op":"mcm","clk":"11541044541","pt":1719501509755,"mc":[{"id":"1.230178319","rc":[{"atb":[[1.03,7.9]],"id":39959056}],"con":true,"img":false}]}
{"op":"mcm","clk":"11541044569","pt":1719501510055,"mc":[{"id":"1.230178319","rc":[{"atb":[[1.03,7.49]],"id":39959056}],"con":true,"img":false}]}
{"op":"mcm","clk":"11541044577","pt":1719501510158,"mc":[{"id":"1.230178319","rc":[{"atb":[[2.26,0.41]],"id":39959056}],"con":true,"img":false}]}
{"op":"mcm","clk":"11541045223","pt":1719501518159,"mc":[{"id":"1.230178319","rc":[{"atb":[[2.24,0],[2.32,1]],"id":39959056}],"con":true,"img":false}]}
{"op":"mcm","clk":"11541045234","pt":1719501518255,"mc":[{"id":"1.230178319","rc":[{"atb":[[1.72,0],[2.16,2.12]],"id":39959056}],"con":true,"img":false}]}
{"op":"mcm","clk":"11541045250","pt":1719501518366,"mc":[{"id":"1.230178319","rc":[{"atl":[[3.45,1],[3.75,0]],"id":62766534},{"atl":[[3.35,0],[3.05,1]],"id":40214683},{"atl":[[4.4,0],[4.2,1]],"id":56418091}],"con":true,"img":false}]}
{"op":"mcm","clk":"11541045261","pt":1719501518471,"mc":[{"id":"1.230178319","rc":[{"atb":[[2.24,1],[2.32,0]],"id":39959056}],"con":true,"img":false}]}
{"op":"mcm","clk":"11541045268","pt":1719501518531,"mc":[{"id":"1.230178319","rc":[{"atl":[[7.6,0],[8.4,4]],"id":40214683}],"con":true,"img":false}]}
{"op":"mcm","clk":"11541045305","pt":1719501519048,"mc":[{"id":"1.230178319","rc":[{"atb":[[2.24,0],[2.32,1]],"id":39959056}],"con":true,"img":false}]}
{"op":"mcm","clk":"11541045363","pt":1719501519731,"mc":[{"id":"1.230178319","rc":[{"atb":[[2.24,1],[2.32,0]],"id":39959056}],"con":true,"img":false}]}
{"op":"mcm","clk":"11541045387","pt":1719501520153,"mc":[{"id":"1.230178319","rc":[{"atl":[[7.8,3.25]],"id":62766534}],"con":true,"img":false}]}
{"op":"mcm","clk":"11541045413","pt":1719501520461,"mc":[{"id":"1.230178319","rc":[{"atl":[[7.8,0]],"id":62766534}],"con":true,"img":false}]}
{"op":"mcm","clk":"11541045489","pt":1719501521344,"mc":[{"id":"1.230178319","rc":[{"atb":[[2.24,0],[2.32,1]],"id":39959056}],"con":true,"img":false}]}
{"op":"mcm","clk":"11541045567","pt":1719501522365,"mc":[{"id":"1.230178319","rc":[{"atb":[[2.24,1],[2.32,0]],"id":39959056}],"con":true,"img":false}]}
{"op":"mcm","clk":"11541045665","pt":1719501523560,"mc":[{"id":"1.230178319","rc":[{"atl":[[3.45,0],[3.75,1]],"id":62766534},{"atl":[[3.35,1],[3.05,0]],"id":40214683},{"atl":[[4.4,1],[4.2,0]],"id":56418091}],"con":true,"img":false}]}
{"op":"mcm","clk":"11541045758","pt":1719501524760,"mc":[{"id":"1.230178319","rc":[{"atl":[[17.5,0.84]],"id":39959056}],"con":true,"img":false}]}
{"op":"mcm","clk":"11541045774","pt":1719501524969,"mc":[{"id":"1.230178319","rc":[{"atb":[[2.24,0],[2.32,1]],"id":39959056}],"con":true,"img":false}]}
{"op":"mcm","clk":"11541045819","pt":1719501525467,"mc":[{"id":"1.230178319","rc":[{"atb":[[2.26,0]],"id":39959056}],"con":true,"img":false}]}
{"op":"mcm","clk":"11541045828","pt":1719501525571,"mc":[{"id":"1.230178319","rc":[{"atb":[[2.24,1],[2.32,0],[1.68,3.12]],"id":39959056}],"con":true,"img":false}]}
{"op":"mcm","clk":"11541045840","pt":1719501525673,"mc":[{"id":"1.230178319","rc":[{"atb":[[2.16,0]],"id":39959056}],"con":true,"img":false}]}
{"op":"mcm","clk":"11541045916","pt":1719501526566,"mc":[{"id":"1.230178319","rc":[{"atl":[[17.5,1.37]],"id":39959056}],"con":true,"img":false}]}
{"op":"mcm","clk":"11541045925","pt":1719501526669,"mc":[{"id":"1.230178319","rc":[{"atb":[[1.03,8.02],[1.02,0]],"id":39959056}],"con":true,"img":false}]}
{"op":"mcm","clk":"11541045932","pt":1719501526769,"mc":[{"id":"1.230178319","rc":[{"atb":[[1.69,2]],"id":39959056}],"con":true,"img":false}]}
{"op":"mcm","clk":"11541045941","pt":1719501526884,"mc":[{"id":"1.230178319","rc":[{"atb":[[1.03,7.9]],"id":39959056}],"con":true,"img":false}]}
{"op":"mcm","clk":"11541045952","pt":1719501527070,"mc":[{"id":"1.230178319","rc":[{"atb":[[1.03,7.49]],"id":39959056}],"con":true,"img":false}]}
{"op":"mcm","clk":"11541045962","pt":1719501527182,"mc":[{"id":"1.230178319","rc":[{"atb":[[2.26,0.41]],"id":39959056}],"con":true,"img":false}]}
{"op":"mcm","clk":"11541046150","pt":1719501529868,"mc":[{"id":"1.230178319","rc":[{"atb":[[2.1,0]],"id":69261147},{"atb":[[2.2,0]],"id":70642246}],"con":true,"img":false}]}
{"op":"mcm","clk":"11541046166","pt":1719501530070,"mc":[{"id":"1.230178319","rc":[{"atb":[[2.1,1.94]],"id":69261147},{"atb":[[2.2,1.94]],"id":70642246}],"con":true,"img":false}]}
{"op":"mcm","clk":"11541046176","pt":1719501530174,"mc":[{"id":"1.230178319","rc":[{"atb":[[2.24,0],[2.32,1]],"id":39959056}],"con":true,"img":false}]}
{"op":"mcm","clk":"11541046189","pt":1719501530379,"mc":[{"id":"1.230178319","rc":[{"atl":[[3.45,1],[3.75,0]],"id":62766534},{"atl":[[3.35,0],[3.05,1]],"id":40214683},{"atl":[[4.4,0],[4.2,1]],"id":56418091}],"con":true,"img":false}]}
{"op":"mcm","clk":"11541046248","pt":1719501531173,"mc":[{"id":"1.230178319","rc":[{"atb":[[2.24,1],[2.32,0]],"id":39959056}],"con":true,"img":false}]}
{"op":"mcm","clk":"11541046259","pt":1719501531282,"mc":[{"id":"1.230178319","rc":[{"atl":[[3.75,1]],"id":62766534},{"atl":[[3.35,1],[3.05,0]],"id":40214683},{"atl":[[4.4,1]],"id":56418091}],"con":true,"img":false}]}
{"op":"mcm","clk":"11541046270","pt":1719501531371,"mc":[{"id":"1.230178319","rc":[{"atl":[[3.45,0]],"id":62766534},{"atl":[[4.2,0]],"id":56418091}],"con":true,"img":false}]}
{"op":"mcm","clk":"11541046297","pt":1719501531677,"mc":[{"id":"1.230178319","rc":[{"atb":[[1.43,0],[1.7,2.06]],"id":39959056}],"con":true,"img":false}]}
{"op":"mcm","clk":"11541046345","pt":1719501532167,"mc":[{"id":"1.230178319","rc":[{"atb":[[1.69,0]],"id":39959056}],"con":true,"img":false}]}
{"op":"mcm","clk":"11541046354","pt":1719501532262,"mc":[{"id":"1.230178319","rc":[{"atb":[[1.71,2]],"id":39959056}],"con":true,"img":false}]}
{"op":"mcm","clk":"11541046363","pt":1719501532386,"mc":[{"id":"1.230178319","rc":[{"atb":[[2.1,0]],"id":69261147},{"atb":[[2.2,0]],"id":70642246}],"con":true,"img":false}]}
{"op":"mcm","clk":"11541046379","pt":1719501532578,"mc":[{"id":"1.230178319","rc":[{"atb":[[2.1,1.94]],"id":69261147},{"atb":[[2.2,1.94]],"id":70642246}],"con":true,"img":false}]}
{"op":"mcm","clk":"11541046589","pt":1719501535163,"mc":[{"id":"1.230178319","rc":[{"atb":[[2.1,0]],"id":69261147},{"atb":[[2.2,0]],"id":70642246}],"con":true,"img":false}]}
{"op":"mcm","clk":"11541046603","pt":1719501535370,"mc":[{"id":"1.230178319","rc":[{"atb":[[2.1,1.94]],"id":69261147},{"atb":[[2.2,1.94]],"id":70642246}],"con":true,"img":false}]}
{"op":"mcm","clk":"11541046805","pt":1719501537787,"mc":[{"id":"1.230178319","rc":[{"atb":[[2.1,0]],"id":69261147},{"atb":[[2.2,0]],"id":70642246}],"con":true,"img":false}]}
{"op":"mcm","clk":"11541046814","pt":1719501537892,"mc":[{"id":"1.230178319","rc":[{"atb":[[2.1,1.94]],"id":69261147},{"atb":[[2.2,1.94]],"id":70642246}],"con":true,"img":false}]}
{"op":"mcm","clk":"11541046910","pt":1719501538981,"mc":[{"id":"1.230178319","rc":[{"atb":[[1.7,0]],"id":39959056}],"con":true,"img":false}]}
{"op":"mcm","clk":"11541046993","pt":1719501539759,"mc":[{"id":"1.230178319","rc":[{"atb":[[1.71,0]],"id":39959056}],"con":true,"img":false}]}
{"op":"mcm","clk":"11541047001","pt":1719501539863,"mc":[{"id":"1.230178319","rc":[{"atb":[[1.69,2]],"id":39959056}],"con":true,"img":false}]}
{"op":"mcm","clk":"11541047030","pt":1719501540174,"mc":[{"id":"1.230178319","rc":[{"atb":[[2.1,0]],"id":69261147},{"atb":[[2.2,0]],"id":70642246}],"con":true,"img":false}]}
{"op":"mcm","clk":"11541047048","pt":1719501540379,"mc":[{"id":"1.230178319","rc":[{"atb":[[2.1,1.94]],"id":69261147},{"atb":[[2.2,1.94]],"id":70642246}],"con":true,"img":false}]}
{"op":"mcm","clk":"11541047168","pt":1719501541886,"mc":[{"id":"1.230178319","rc":[{"atl":[[17.5,0.84]],"id":39959056}],"con":true,"img":false}]}
{"op":"mcm","clk":"11541047212","pt":1719501542471,"mc":[{"id":"1.230178319","rc":[{"atb":[[2.26,0]],"id":39959056}],"con":true,"img":false}]}
{"op":"mcm","clk":"11541047232","pt":1719501542682,"mc":[{"id":"1.230178319","rc":[{"atb":[[2.1,0]],"id":69261147},{"atb":[[2.2,0]],"id":70642246}],"con":true,"img":false}]}
{"op":"mcm","clk":"11541047240","pt":1719501542876,"mc":[{"id":"1.230178319","rc":[{"atb":[[2.1,1.94]],"id":69261147},{"atb":[[2.2,1.94]],"id":70642246}],"con":true,"img":false}]}
{"op":"mcm","clk":"11541047322","pt":1719501544277,"mc":[{"id":"1.230178319","rc":[{"atl":[[17.5,1.37]],"id":39959056}],"con":true,"img":false}]}
{"op":"mcm","clk":"11541047330","pt":1719501544378,"mc":[{"id":"1.230178319","rc":[{"atb":[[1.03,8.02]],"id":39959056}],"con":true,"img":false}]}
{"op":"mcm","clk":"11541047347","pt":1719501544587,"mc":[{"id":"1.230178319","rc":[{"atb":[[1.03,7.9]],"id":39959056}],"con":true,"img":false}]}
{"op":"mcm","clk":"11541047358","pt":1719501544795,"mc":[{"id":"1.230178319","rc":[{"atb":[[1.03,7.49]],"id":39959056}],"con":true,"img":false}]}
{"op":"mcm","clk":"11541047364","pt":1719501544866,"mc":[{"id":"1.230178319","rc":[{"atb":[[2.26,0.41]],"id":39959056}],"con":true,"img":false}]}
{"op":"mcm","clk":"11541047422","pt":1719501545677,"mc":[{"id":"1.230178319","rc":[{"atb":[[1.7,2.06]],"id":39959056}],"con":true,"img":false}]}
{"op":"mcm","clk":"11541047436","pt":1719501545792,"mc":[{"id":"1.230178319","rc":[{"atb":[[2.1,0]],"id":69261147},{"atb":[[2.2,0]],"id":70642246}],"con":true,"img":false}]}
{"op":"mcm","clk":"11541047442","pt":1719501545890,"mc":[{"id":"1.230178319","rc":[{"atb":[[2.1,1.94]],"id":69261147},{"atb":[[2.2,1.94]],"id":70642246}],"con":true,"img":false}]}
{"op":"mcm","clk":"11541047479","pt":1719501546369,"mc":[{"id":"1.230178319","rc":[{"atb":[[1.69,0]],"id":39959056}],"con":true,"img":false}]}
{"op":"mcm","clk":"11541047487","pt":1719501546476,"mc":[{"id":"1.230178319","rc":[{"atb":[[1.71,2]],"id":39959056}],"con":true,"img":false}]}
{"op":"mcm","clk":"11541047673","pt":1719501548787,"mc":[{"id":"1.230178319","rc":[{"atb":[[2.1,0]],"id":69261147},{"atb":[[2.2,0]],"id":70642246}],"con":true,"img":false}]}
{"op":"mcm","clk":"11541047686","pt":1719501548890,"mc":[{"id":"1.230178319","rc":[{"atb":[[2.1,1.94]],"id":69261147},{"atb":[[2.2,1.94]],"id":70642246}],"con":true,"img":false}]}
{"op":"mcm","clk":"11541047758","pt":1719501549788,"mc":[{"id":"1.230178319","rc":[{"atb":[[1.01,24.17]],"id":62766534},{"atl":[[1000,1.88]],"id":62766534},{"atb":[[1.01,1.7]],"id":39959056},{"atl":[[1000,1.7]],"id":39959056},{"atb":[[1.14,2.02]],"id":40214683},{"atl":[[1000,1.7]],"id":40214683}],"con":true,"img":false}]}
{"op":"mcm","clk":"11541047786","pt":1719501549984,"mc":[{"id":"1.230178319","rc":[{"atb":[[1.01,23.76]],"id":62766534},{"atl":[[1000,0.22]],"id":62766534},{"atb":[[1.01,0.39]],"id":39959056},{"atl":[[1000,0.01]],"id":39959056}],"con":true,"img":false}]}
{"op":"mcm","clk":"11541047796","pt":1719501550086,"mc":[{"id":"1.230178319","rc":[{"atl":[[1000,0.03]],"id":40214683}],"con":true,"img":false}]}
{"op":"mcm","clk":"11541047806","pt":1719501550192,"mc":[{"id":"1.230178319","rc":[{"atb":[[1.01,22.47]],"id":62766534},{"atl":[[1000,0.17]],"id":62766534},{"atb":[[1.01,0]],"id":39959056},{"atl":[[1000,0]],"id":39959056}],"con":true,"img":false}]}
{"op":"mcm","clk":"11541047827","pt":1719501550285,"mc":[{"id":"1.230178319","rc":[{"atb":[[1.22,1.28]],"id":62766534},{"atl":[[7.2,0.04]],"id":62766534},{"atb":[[1.72,0.39]],"id":39959056},{"atl":[[17.5,1.39]],"id":39959056},{"atb":[[1.13,0]],"id":40214683},{"atl":[[1000,0]],"id":40214683}],"con":true,"img":false}]}
{"op":"mcm","clk":"11541047838","pt":1719501550386,"mc":[{"id":"1.230178319","rc":[{"atb":[[1.15,2]],"id":40214683},{"atl":[[8.2,0.03]],"id":40214683}],"con":true,"img":false}]}
{"op":"mcm","clk":"11541047884","pt":1719501550905,"mc":[{"id":"1.230178319","rc":[{"atb":[[1.7,0]],"id":39959056}],"con":true,"img":false}]}
{"op":"mcm","clk":"11541047934","pt":1719501551576,"mc":[{"id":"1.230178319","rc":[{"atb":[[1.71,0]],"id":39959056}],"con":true,"img":false}]}
{"op":"mcm","clk":"11541047943","pt":1719501551688,"mc":[{"id":"1.230178319","rc":[{"atb":[[1.69,2]],"id":39959056},{"atb":[[2.1,0]],"id":69261147},{"atb":[[2.2,0]],"id":70642246}],"con":true,"img":false}]}
{"op":"mcm","clk":"11541047959","pt":1719501551900,"mc":[{"id":"1.230178319","rc":[{"atb":[[2.1,1.94]],"id":69261147},{"atb":[[2.2,1.94]],"id":70642246}],"con":true,"img":false}]}
{"op":"mcm","clk":"11541047970","pt":1719501552094,"mc":[{"id":"1.230178319","rc":[{"atb":[[1.21,0]],"id":62766534}],"con":true,"img":false}]}
{"op":"mcm","clk":"11541047979","pt":1719501552211,"mc":[{"id":"1.230178319","rc":[{"atb":[[1.23,2]],"id":62766534},{"spn":2.24,"spf":1.0,"id":39959056}],"con":true,"img":false}]}
{"op":"mcm","clk":"11541048076","pt":1719501553286,"mc":[{"id":"1.230178319","rc":[{"atb":[[1.23,0]],"id":62766534}],"con":true,"img":false}]}
{"op":"mcm","clk":"11541048085","pt":1719501553390,"mc":[{"id":"1.230178319","rc":[{"atb":[[1.21,2]],"id":62766534}],"con":true,"img":false}]}
{"op":"mcm","clk":"11541048197","pt":1719501554789,"mc":[{"id":"1.230178319","rc":[{"atb":[[2.1,0]],"id":69261147},{"atb":[[2.2,0]],"id":70642246}],"con":true,"img":false}]}
{"op":"mcm","clk":"11541048214","pt":1719501555000,"mc":[{"id":"1.230178319","rc":[{"atb":[[2.1,1.94]],"id":69261147},{"atb":[[2.2,1.94]],"id":70642246}],"con":true,"img":false}]}
{"op":"mcm","clk":"11541048275","pt":1719501555709,"mc":[{"id":"1.230178319","rc":[{"atb":[[1.21,0]],"id":62766534}],"con":true,"img":false}]}
{"op":"mcm","clk":"11541048285","pt":1719501555768,"mc":[{"id":"1.230178319","rc":[{"atb":[[1.23,2]],"id":62766534}],"con":true,"img":false}]}
{"op":"mcm","clk":"11541048372","pt":1719501557006,"mc":[{"id":"1.230178319","rc":[{"atb":[[1.23,0]],"id":62766534}],"con":true,"img":false}]}
{"op":"mcm","clk":"11541048379","pt":1719501557102,"mc":[{"id":"1.230178319","rc":[{"atb":[[1.21,2]],"id":62766534}],"con":true,"img":false}]}
{"op":"mcm","clk":"11541048438","pt":1719501557784,"mc":[{"id":"1.230178319","rc":[{"atb":[[2.1,0]],"id":69261147},{"atb":[[2.2,0]],"id":70642246}],"con":true,"img":false}]}
{"op":"mcm","clk":"11541048453","pt":1719501557984,"mc":[{"id":"1.230178319","rc":[{"atb":[[2.1,1.94]],"id":69261147},{"atb":[[2.2,1.94]],"id":70642246}],"con":true,"img":false}]}
{"op":"mcm","clk":"11541048522","pt":1719501558200,"mc":[{"id":"1.230178319","rc":[{"atb":[[1.21,0]],"id":62766534}],"con":true,"img":false}]}
{"op":"mcm","clk":"11541048531","pt":1719501558295,"mc":[{"id":"1.230178319","rc":[{"atb":[[1.23,2]],"id":62766534}],"con":true,"img":false}]}
{"op":"mcm","clk":"11541048628","pt":1719501559289,"mc":[{"id":"1.230178319","rc":[{"atb":[[1.7,2.06]],"id":39959056}],"con":true,"img":false}]}
{"op":"mcm","clk":"11541048652","pt":1719501559591,"mc":[{"id":"1.230178319","rc":[{"atl":[[17.5,0.86]],"id":39959056}],"con":true,"img":false}]}
{"op":"mcm","clk":"11541048664","pt":1719501559697,"mc":[{"id":"1.230178319","rc":[{"atb":[[1.23,0]],"id":62766534}],"con":true,"img":false}]}
{"op":"mcm","clk":"11541048672","pt":1719501559799,"mc":[{"id":"1.230178319","rc":[{"atb":[[1.21,2]],"id":62766534}],"con":true,"img":false}]}
{"op":"mcm","clk":"11541048752","pt":1719501560205,"mc":[{"id":"1.230178319","rc":[{"atb":[[2.26,0]],"id":39959056}],"con":true,"img":false}]}
{"op":"mcm","clk":"11541048800","pt":1719501560893,"mc":[{"id":"1.230178319","rc":[{"atb":[[1.69,0]],"id":39959056},{"atb":[[2.1,0]],"id":69261147},{"atb":[[2.2,0]],"id":70642246}],"con":true,"img":false}]}
{"op":"mcm","clk":"11541048808","pt":1719501561015,"mc":[{"id":"1.230178319","rc":[{"atb":[[1.71,2]],"id":39959056}],"con":true,"img":false}]}
{"op":"mcm","clk":"11541048817","pt":1719501561098,"mc":[{"id":"1.230178319","rc":[{"atb":[[2.1,1.94]],"id":69261147},{"atb":[[2.2,1.94]],"id":70642246}],"con":true,"img":false}]}
{"op":"mcm","clk":"11541048834","pt":1719501561308,"mc":[{"id":"1.230178319","rc":[{"atb":[[1.21,0]],"id":62766534}],"con":true,"img":false}]}
{"op":"mcm","clk":"11541048844","pt":1719501561411,"mc":[{"id":"1.230178319","rc":[{"atb":[[1.23,2]],"id":62766534}],"con":true,"img":false}]}
{"op":"mcm","clk":"11541048883","pt":1719501562017,"mc":[{"id":"1.230178319","rc":[{"atl":[[17.5,1.39]],"id":39959056}],"con":true,"img":false}]}
{"op":"mcm","clk":"11541048890","pt":1719501562079,"mc":[{"id":"1.230178319","rc":[{"atb":[[1.03,8.02]],"id":39959056}],"con":true,"img":false}]}
{"op":"mcm","clk":"11541048902","pt":1719501562287,"mc":[{"id":"1.230178319","rc":[{"atb":[[1.03,7.9]],"id":39959056}],"con":true,"img":false}]}
{"op":"mcm","clk":"11541048910","pt":1719501562396,"mc":[{"id":"1.230178319","rc":[{"atb":[[1.23,0]],"id":62766534}],"con":true,"img":false}]}
{"op":"mcm","clk":"11541048919","pt":1719501562493,"mc":[{"id":"1.230178319","rc":[{"atb":[[1.03,7.49]],"id":39959056}],"con":true,"img":false}]}
{"op":"mcm","clk":"11541048926","pt":1719501562604,"mc":[{"id":"1.230178319","rc":[{"atb":[[1.21,2]],"id":62766534},{"atb":[[2.26,0.41]],"id":39959056}],"con":true,"img":false}]}
{"op":"mcm","clk":"11541049029","pt":1719501563896,"mc":[{"id":"1.230178319","rc":[{"atb":[[1.21,0]],"id":62766534},{"atb":[[2.1,0]],"id":69261147},{"atb":[[2.2,0]],"id":70642246}],"con":true,"img":false}]}
{"op":"mcm","clk":"11541049040","pt":1719501563996,"mc":[{"id":"1.230178319","rc":[{"atb":[[1.23,2]],"id":62766534}],"con":true,"img":false}]}
{"op":"mcm","clk":"11541049048","pt":1719501564107,"mc":[{"id":"1.230178319","rc":[{"atb":[[2.1,1.94]],"id":69261147},{"atb":[[2.2,1.94]],"id":70642246}],"con":true,"img":false}]}
{"op":"mcm","clk":"11541049116","pt":1719501564917,"mc":[{"id":"1.230178319","rc":[{"atb":[[1.23,0]],"id":62766534}],"con":true,"img":false}]}
{"op":"mcm","clk":"11541049127","pt":1719501565020,"mc":[{"id":"1.230178319","rc":[{"atb":[[1.21,2]],"id":62766534}],"con":true,"img":false}]}
{"op":"mcm","clk":"11541049230","pt":1719501566211,"mc":[{"id":"1.230178319","rc":[{"atb":[[1.21,0]],"id":62766534}],"con":true,"img":false}]}
{"op":"mcm","clk":"11541049240","pt":1719501566316,"mc":[{"id":"1.230178319","rc":[{"atb":[[1.23,2]],"id":62766534}],"con":true,"img":false}]}
{"op":"mcm","clk":"11541049269","pt":1719501566623,"mc":[{"id":"1.230178319","rc":[{"atb":[[1.7,0]],"id":39959056}],"con":true,"img":false}]}
{"op":"mcm","clk":"11541049309","pt":1719501567199,"mc":[{"id":"1.230178319","rc":[{"atb":[[2.1,0]],"id":69261147},{"atb":[[2.2,0]],"id":70642246}],"con":true,"img":false}]}
{"op":"mcm","clk":"11541049317","pt":1719501567305,"mc":[{"id":"1.230178319","rc":[{"atb":[[1.71,0]],"id":39959056},{"atb":[[2.1,1.94]],"id":69261147},{"atb":[[2.2,1.94]],"id":70642246}],"con":true,"img":false}]}
{"op":"mcm","clk":"11541049326","pt":1719501567425,"mc":[{"id":"1.230178319","rc":[{"atb":[[1.69,2]],"id":39959056}],"con":true,"img":false}]}
{"op":"mcm","clk":"11541049333","pt":1719501567522,"mc":[{"id":"1.230178319","rc":[{"atb":[[2.04,3]],"id":69261147}],"con":true,"img":false}]}
{"op":"mcm","clk":"11541049345","pt":1719501567729,"mc":[{"id":"1.230178319","rc":[{"atb":[[1.23,0]],"id":62766534}],"con":true,"img":false}]}
{"op":"mcm","clk":"11541049353","pt":1719501567813,"mc":[{"id":"1.230178319","rc":[{"atb":[[1.21,2]],"id":62766534}],"con":true,"img":false}]}
{"op":"mcm","clk":"11541049368","pt":1719501568019,"mc":[{"id":"1.230178319","rc":[{"atb":[[2.04,0]],"id":69261147}],"con":true,"img":false}]}
{"op":"mcm","clk":"11541049375","pt":1719501568120,"mc":[{"id":"1.230178319","rc":[{"atb":[[2.14,3.69]],"id":70642246}],"con":true,"img":false}]}
{"op":"mcm","clk":"11541049401","pt":1719501568492,"mc":[{"id":"1.230178319","rc":[{"atb":[[2.14,0]],"id":70642246}],"con":true,"img":false}]}
{"op":"mcm","clk":"11541049427","pt":1719501568801,"mc":[{"id":"1.230178319","rc":[{"atb":[[1.21,0]],"id":62766534}],"con":true,"img":false}]}
{"op":"mcm","clk":"11541049434","pt":1719501568910,"mc":[{"id":"1.230178319","rc":[{"atb":[[1.23,2]],"id":62766534}],"con":true,"img":false}]}
{"op":"mcm","clk":"11541049519","pt":1719501569793,"mc":[{"id":"1.230178319","rc":[{"atb":[[1.02,11.23]],"id":70642246}],"con":true,"img":false}]}
{"op":"mcm","clk":"11541049529","pt":1719501569895,"mc":[{"id":"1.230178319","rc":[{"atb":[[2.22,2]],"id":70642246}],"con":true,"img":false}]}
{"op":"mcm","clk":"11541049550","pt":1719501570109,"mc":[{"id":"1.230178319","rc":[{"atb":[[2.1,0]],"id":69261147},{"atb":[[2.2,0]],"id":70642246}],"con":true,"img":false}]}
{"op":"mcm","clk":"11541049565","pt":1719501570309,"mc":[{"id":"1.230178319","rc":[{"atb":[[2.1,1.94]],"id":69261147},{"atb":[[2.2,1.94]],"id":70642246}],"con":true,"img":false}]}
{"op":"mcm","clk":"11541049656","pt":1719501571295,"mc":[{"id":"1.230178319","rc":[{"atb":[[1.23,0]],"id":62766534}],"con":true,"img":false}]}
{"op":"mcm","clk":"11541049664","pt":1719501571406,"mc":[{"id":"1.230178319","rc":[{"atb":[[1.21,2]],"id":62766534}],"con":true,"img":false}]}
{"op":"mcm","clk":"11541049692","pt":1719501571715,"mc":[{"id":"1.230178319","rc":[{"atb":[[2.22,0]],"id":70642246}],"con":true,"img":false}]}
{"op":"mcm","clk":"11541049702","pt":1719501571813,"mc":[{"id":"1.230178319","rc":[{"atb":[[2.2,3.94]],"id":70642246}],"con":true,"img":false}]}
{"op":"mcm","clk":"11541049778","pt":1719501572696,"mc":[{"id":"1.230178319","rc":[{"atb":[[1.21,0]],"id":62766534}],"con":true,"img":false}]}
{"op":"mcm","clk":"11541049786","pt":1719501572789,"mc":[{"id":"1.230178319","rc":[{"atb":[[1.23,2]],"id":62766534},{"atb":[[1.7,2.06]],"id":39959056}],"con":true,"img":false}]}
{"op":"mcm","clk":"11541049824","pt":1719501573225,"mc":[{"id":"1.230178319","rc":[{"atb":[[2.1,0]],"id":69261147},{"atb":[[2.2,1.94]],"id":70642246}],"con":true,"img":false}]}
{"op":"mcm","clk":"11541049834","pt":1719501573314,"mc":[{"id":"1.230178319","rc":[{"atb":[[1.02,13.23]],"id":70642246}],"con":true,"img":false}]}
{"op":"mcm","clk":"11541049843","pt":1719501573418,"mc":[{"id":"1.230178319","rc":[{"atb":[[2.1,1.94]],"id":69261147}],"con":true,"img":false}]}
{"op":"mcm","clk":"11541049905","pt":1719501574128,"mc":[{"id":"1.230178319","rc":[{"atb":[[2.24,0],[2.32,1]],"id":39959056}],"con":true,"img":false}]}
{"op":"mcm","clk":"11541049914","pt":1719501574221,"mc":[{"id":"1.230178319","rc":[{"atb":[[1.68,0],[2.16,2]],"id":39959056}],"con":true,"img":false}]}
{"op":"mcm","clk":"11541049923","pt":1719501574323,"mc":[{"id":"1.230178319","rc":[{"atb":[[1.72,2.39],[2.16,0],[1.69,0]],"id":39959056}],"con":true,"img":false}]}
{"op":"mcm","clk":"11541049931","pt":1719501574429,"mc":[{"id":"1.230178319","rc":[{"atb":[[2.24,1],[1.71,2]],"id":39959056}],"con":true,"img":false}]}
{"op":"mcm","clk":"11541049943","pt":1719501574500,"mc":[{"id":"1.230178319","rc":[{"atb":[[1.72,0.39],[2.32,0],[2.16,2.12]],"id":39959056}],"con":true,"img":false}]}
{"op":"mcm","clk":"11541049963","pt":1719501574708,"mc":[{"id":"1.230178319","rc":[{"atb":[[1.23,0]],"id":62766534}],"con":true,"img":false}]}
{"op":"mcm","clk":"11541049971","pt":1719501574806,"mc":[{"id":"1.230178319","rc":[{"atb":[[1.21,2]],"id":62766534}],"con":true,"img":false}]}
{"op":"mcm","clk":"11541049983","pt":1719501574900,"mc":[{"id":"1.230178319","rc":[{"atl":[[3.45,1]],"id":62766534},{"atl":[[3.35,0]],"id":40214683},{"atl":[[4.2,1]],"id":56418091}],"con":true,"img":false}]}
{"op":"mcm","clk":"11541049993","pt":1719501575007,"mc":[{"id":"1.230178319","rc":[{"atl":[[3.75,0]],"id":62766534},{"atl":[[3.05,1]],"id":40214683},{"atl":[[4.4,0]],"id":56418091}],"con":true,"img":false}]}
{"op":"mcm","clk":"11541050023","pt":1719501575313,"mc":[{"id":"1.230178319","rc":[{"atl":[[8.2,0.88]],"id":40214683}],"con":true,"img":false}]}
{"op":"mcm","clk":"11541050040","pt":1719501575513,"mc":[{"id":"1.230178319","rc":[{"atb":[[1.29,3.38]],"id":62766534},{"atb":[[2.24,3.38]],"id":39959056},{"atb":[[1.25,4.2]],"id":40214683},{"atb":[[1.64,4]],"id":56418091},{"atb":[[2.24,2]],"id":69261147},{"atb":[[2.28,2]],"id":70642246}],"con":true,"img":false}]}
{"op":"mcm","clk":"11541050048","pt":1719501575616,"mc":[{"id":"1.230178319","rc":[{"atb":[[1.2,0.25],[1.3,2]],"id":62766534},{"atb":[[1.12,0],[1.26,2]],"id":40214683},{"atb":[[1.63,0],[1.65,2.48]],"id":56418091},{"atb":[[2.24,4],[2.08,0]],"id":69261147},{"atb":[[2.28,4],[2.18,0]],"id":70642246}],"con":true,"img":false}]}
{"op":"mcm","clk":"11541050090","pt":1719501576196,"mc":[{"id":"1.230178319","rc":[{"atl":[[7.8,3.12]],"id":62766534},{"atb":[[1.15,0]],"id":40214683},{"atb":[[2.1,0]],"id":69261147},{"atb":[[2.2,0]],"id":70642246}],"con":true,"img":false}]}
{"op":"mcm","clk":"11541050100","pt":1719501576301,"mc":[{"id":"1.230178319","rc":[{"atb":[[1.27,2]],"id":40214683}],"con":true,"img":false}]}
{"op":"mcm","clk":"11541050108","pt":1719501576401,"mc":[{"id":"1.230178319","rc":[{"atb":[[2.26,2.36]],"id":39959056},{"atb":[[2.26,1.94]],"id":69261147},{"atb":[[2.3,1.94]],"id":70642246}],"con":true,"img":false}]}
{"op":"mcm","clk":"11541050115","pt":1719501576505,"mc":[{"id":"1.230178319","rc":[{"atl":[[7.8,0]],"id":62766534}],"con":true,"img":false}]}
{"op":"mcm","clk":"11541050122","pt":1719501576608,"mc":[{"id":"1.230178319","rc":[{"atb":[[1.71,0]],"id":39959056}],"con":true,"img":false}]}
{"op":"mcm","clk":"11541050131","pt":1719501576719,"mc":[{"id":"1.230178319","rc":[{"atb":[[1.02,2]],"id":39959056}],"con":true,"img":false}]}
{"op":"mcm","clk":"11541050162","pt":1719501577119,"mc":[{"id":"1.230178319","rc":[{"atb":[[1.21,0]],"id":62766534}],"con":true,"img":false}]}
{"op":"mcm","clk":"11541050171","pt":1719501577223,"mc":[{"id":"1.230178319","rc":[{"atb":[[1.31,2]],"id":62766534}],"con":true,"img":false}]}
{"op":"mcm","clk":"11541050181","pt":1719501577325,"mc":[{"id":"1.230178319","rc":[{"atl":[[17.5,0.86]],"id":39959056}],"con":true,"img":false}]}
{"op":"mcm","clk":"11541050234","pt":1719501577907,"mc":[{"id":"1.230178319","rc":[{"atl":[[3.45,0],[3.75,1]],"id":62766534},{"atb":[[2.26,1.94]],"id":39959056},{"atl":[[3.35,1],[3.05,0]],"id":40214683},{"atl":[[4.4,1],[4.2,0]],"id":56418091}],"con":true,"img":false}]}
{"op":"mcm","clk":"11541050253","pt":1719501578114,"mc":[{"id":"1.230178319","rc":[{"atb":[[1.7,0]],"id":39959056}],"con":true,"img":false}]}
{"op":"mcm","clk":"11541050354","pt":1719501579298,"mc":[{"id":"1.230178319","rc":[{"atb":[[2.26,0]],"id":39959056},{"atb":[[2.26,0]],"id":69261147},{"atb":[[2.3,0]],"id":70642246}],"con":true,"img":false}]}
{"op":"mcm","clk":"11541050419","pt":1719501580023,"mc":[{"id":"1.230178319","rc":[{"atl":[[17.5,1.39]],"id":39959056}],"con":true,"img":false}]}
{"op":"mcm","clk":"11541050428","pt":1719501580124,"mc":[{"id":"1.230178319","rc":[{"atb":[[1.03,8.02]],"id":39959056}],"con":true,"img":false}]}
{"op":"mcm","clk":"11541050442","pt":1719501580325,"mc":[{"id":"1.230178319","rc":[{"atb":[[1.03,7.9]],"id":39959056}],"con":true,"img":false}]}
{"op":"mcm","clk":"11541050464","pt":1719501580534,"mc":[{"id":"1.230178319","rc":[{"atb":[[1.03,7.49]],"id":39959056}],"con":true,"img":false}]}
{"op":"mcm","clk":"11541050480","pt":1719501580598,"mc":[{"id":"1.230178319","rc":[{"atb":[[2.26,0.41]],"id":39959056}],"con":true,"img":false}]}
{"op":"mcm","clk":"11541050870","pt":1719501585937,"mc":[{"id":"1.230178319","rc":[{"atb":[[2.26,2.66]],"id":39959056}],"con":true,"img":false}]}
{"op":"mcm","clk":"11541050881","pt":1719501586041,"mc":[{"id":"1.230178319","rc":[{"atb":[[1.29,14.59]],"id":40214683}],"con":true,"img":false}]}
{"op":"mcm","clk":"11541050897","pt":1719501586143,"mc":[{"id":"1.230178319","rc":[{"atb":[[1.26,0],[1.3,2]],"id":40214683}],"con":true,"img":false}]}
{"op":"mcm","clk":"11541050989","pt":1719501587123,"mc":[{"id":"1.230178319","rc":[{"atb":[[1.27,0]],"id":40214683}],"con":true,"img":false}]}
{"op":"mcm","clk":"11541050996","pt":1719501587228,"mc":[{"id":"1.230178319","rc":[{"atb":[[1.31,2]],"id":40214683}],"con":true,"img":false}]}
{"op":"mcm","clk":"11541051061","pt":1719501588120,"mc":[{"id":"1.230178319","rc":[{"atb":[[1.22,0]],"id":62766534},{"atl":[[7.2,0]],"id":62766534},{"atb":[[1.72,0]],"id":39959056},{"atl":[[17.5,1.37]],"id":39959056},{"atb":[[1.14,0]],"id":40214683},{"atl":[[8.2,0.84]],"id":40214683}],"con":true,"img":false}]}
{"op":"mcm","clk":"11541051081","pt":1719501588423,"mc":[{"id":"1.230178319","rc":[{"atl":[[7.6,0]],"id":62766534}],"con":true,"img":false}]}
{"op":"mcm","clk":"11541051086","pt":1719501588533,"mc":[{"id":"1.230178319","rc":[{"atl":[[7.4,0],[8.8,4]],"id":62766534}],"con":true,"img":false}]}
{"op":"mcm","clk":"11541051162","pt":1719501589615,"mc":[{"id":"1.230178319","rc":[{"atb":[[1.29,0]],"id":62766534},{"atb":[[2.24,1]],"id":39959056},{"atb":[[1.25,0]],"id":40214683},{"atb":[[1.64,0]],"id":56418091}],"con":true,"img":false}]}
{"op":"mcm","clk":"11541051175","pt":1719501589722,"mc":[{"id":"1.230178319","rc":[{"atb":[[1.65,0],[1.61,3.48]],"id":56418091}],"con":true,"img":false}]}
{"op":"mcm","clk":"11541051181","pt":1719501589822,"mc":[{"id":"1.230178319","rc":[{"atb":[[1.32,3]],"id":62766534},{"atb":[[2.28,2.6]],"id":39959056},{"atb":[[1.32,4.2]],"id":40214683},{"atb":[[1.74,4.6]],"id":56418091}],"con":true,"img":false}]}
{"op":"mcm","clk":"11541051189","pt":1719501589927,"mc":[{"id":"1.230178319","rc":[{"atb":[[1.33,2]],"id":40214683},{"atb":[[1.75,3.48],[1.61,0]],"id":56418091}],"con":true,"img":false}]}
{"op":"mcm","clk":"11541051193","pt":1719501590029,"mc":[{"id":"1.230178319","rc":[{"atb":[[1.31,0]],"id":62766534},{"atb":[[1.3,0]],"id":40214683}],"con":true,"img":false}]}
{"op":"mcm","clk":"11541051201","pt":1719501590131,"mc":[{"id":"1.230178319","rc":[{"atb":[[1.02,2]],"id":62766534}],"con":true,"img":false}]}
{"op":"mcm","clk":"11541051207","pt":1719501590227,"mc":[{"id":"1.230178319","rc":[{"atb":[[1.33,4.11]],"id":40214683}],"con":true,"img":false}]}
{"op":"mcm","clk":"11541051229","pt":1719501590551,"mc":[{"id":"1.230178319","rc":[{"atb":[[1.33,16.09]],"id":40214683}],"con":true,"img":false}]}
{"op":"mcm","clk":"11541051265","pt":1719501590915,"mc":[{"id":"1.230178319","rc":[{"atb":[[1.31,19.85]],"id":40214683}],"con":true,"img":false}]}
{"op":"mcm","clk":"11541051277","pt":1719501591121,"mc":[{"id":"1.230178319","rc":[{"atb":[[2.26,0.41]],"id":39959056}],"con":true,"img":false}]}
{"op":"mcm","clk":"11541051284","pt":1719501591221,"mc":[{"id":"1.230178319","rc":[{"atb":[[1.31,17.85]],"id":40214683}],"con":true,"img":false}]}
{"op":"mcm","clk":"11541051294","pt":1719501591333,"mc":[{"id":"1.230178319","rc":[{"atb":[[1.34,2]],"id":40214683}],"con":true,"img":false}]}
{"op":"mcm","clk":"11541051646","pt":1719501595244,"mc":[{"id":"1.230178319","rc":[{"atl":[[17.5,0.84]],"id":39959056}],"con":true,"img":false}]}
{"op":"mcm","clk":"11541051701","pt":1719501595922,"mc":[{"id":"1.230178319","rc":[{"atb":[[2.26,0]],"id":39959056}],"con":true,"img":false}]}
{"op":"mcm","clk":"11541051795","pt":1719501597054,"mc":[{"id":"1.230178319","rc":[{"atl":[[17.5,1.37]],"id":39959056}],"con":true,"img":false}]}
{"op":"mcm","clk":"11541051818","pt":1719501597223,"mc":[{"id":"1.230178319","rc":[{"atb":[[1.03,8.02]],"id":39959056}],"con":true,"img":false}]}
{"op":"mcm","clk":"11541051836","pt":1719501597429,"mc":[{"id":"1.230178319","rc":[{"atb":[[1.03,7.89]],"id":39959056}],"con":true,"img":false}]}
{"op":"mcm","clk":"11541051855","pt":1719501597652,"mc":[{"id":"1.230178319","rc":[{"atb":[[1.03,7.49]],"id":39959056}],"con":true,"img":false}]}
{"op":"mcm","clk":"11541051864","pt":1719501597737,"mc":[{"id":"1.230178319","rc":[{"atb":[[2.3,0.4]],"id":39959056}],"con":true,"img":false}]}
{"op":"mcm","clk":"11541051956","pt":1719501598823,"mc":[{"id":"1.230178319","rc":[{"atb":[[2.3,2.76]],"id":39959056}],"con":true,"img":false}]}
{"op":"mcm","clk":"11541052386","pt":1719501603858,"mc":[{"id":"1.230178319","rc":[{"atb":[[1.32,0]],"id":40214683},{"atb":[[1.74,1]],"id":56418091}],"con":true,"img":false}]}
{"op":"mcm","clk":"11541052395","pt":1719501603959,"mc":[{"id":"1.230178319","rc":[{"atb":[[1.35,5]],"id":40214683},{"atb":[[1.75,7.44]],"id":56418091}],"con":true,"img":false}]}
{"op":"mcm","clk":"11541052404","pt":1719501604081,"mc":[{"id":"1.230178319","rc":[{"atb":[[2.32,1]],"id":39959056},{"atl":[[17,1]],"id":39959056},{"atb":[[1.75,3.96],[1.61,4.48]],"id":56418091}],"con":true,"img":false}]}
{"op":"mcm","clk":"11541052409","pt":1719501604152,"mc":[{"id":"1.230178319","rc":[{"atb":[[1.36,5],[1.33,14.09]],"id":40214683}],"con":true,"img":false}]}
{"op":"mcm","clk":"11541052451","pt":1719501604644,"mc":[{"id":"1.230178319","rc":[{"atb":[[1.34,0]],"id":40214683}],"con":true,"img":false}]}
{"op":"mcm","clk":"11541052456","pt":1719501604748,"mc":[{"id":"1.230178319","rc":[{"atb":[[1.37,2]],"id":40214683}],"con":true,"img":false}]}
{"op":"mcm","clk":"11541052867","pt":1719501609540,"mc":[{"id":"1.230178319","rc":[{"atb":[[2.32,2.94]],"id":39959056},{"atb":[[2.26,1.94]],"id":69261147},{"atb":[[2.3,1.94]],"id":70642246}],"con":true,"img":false}]}
{"op":"mcm","clk":"11541052875","pt":1719501609639,"mc":[{"id":"1.230178319","rc":[{"atb":[[2.3,0.4]],"id":39959056},{"atb":[[1.33,2.11]],"id":40214683}],"con":true,"img":false}]}
{"op":"mcm","clk":"11541052901","pt":1719501609952,"mc":[{"id":"1.230178319","rc":[{"atb":[[1.39,10.13]],"id":40214683},{"atb":[[1.61,0],[1.76,3.96]],"id":56418091}],"con":true,"img":false}]}
{"op":"mcm","clk":"11541052911","pt":1719501610045,"mc":[{"id":"1.230178319","rc":[{"atb":[[1.4,5],[1.36,0]],"id":40214683}],"con":true,"img":false}]}
{"op":"mcm","clk":"11541053018","pt":1719501611454,"mc":[{"id":"1.230178319","rc":[{"atb":[[2.34,2.12]],"id":39959056}],"con":true,"img":false}]}
{"op":"mcm","clk":"11541053037","pt":1719501611658,"mc":[{"id":"1.230178319","rc":[{"atb":[[2.32,1.94]],"id":39959056}],"con":true,"img":false}]}
{"op":"mcm","clk":"11541053044","pt":1719501611763,"mc":[{"id":"1.230178319","rc":[{"atb":[[1.37,0]],"id":40214683}],"con":true,"img":false}]}
{"op":"mcm","clk":"11541053051","pt":1719501611867,"mc":[{"id":"1.230178319","rc":[{"atb":[[2.24,0],[2.32,2.94]],"id":39959056},{"atb":[[1.41,2]],"id":40214683},{"atl":[[3.15,1]],"id":40214683},{"atb":[[2.84,1],[2.76,0]],"id":69261147},{"atl":[[8,1],[8.2,0]],"id":70642246}],"con":true,"img":false}]}
{"op":"mcm","clk":"11541053058","pt":1719501611970,"mc":[{"id":"1.230178319","rc":[{"atl":[[3.75,0],[3.65,1]],"id":62766534},{"atl":[[3.35,0]],"id":40214683},{"atl":[[4.1,1],[4.4,0]],"id":56418091},{"atb":[[2.28,2.12]],"id":69261147},{"atb":[[2.84,1],[2.76,0]],"id":70642246}],"con":true,"img":false}]}
{"op":"mcm","clk":"11541053066","pt":1719501612039,"mc":[{"id":"1.230178319","rc":[{"atb":[[2.24,2]],"id":69261147},{"atb":[[2.32,2.12],[2.28,2]],"id":70642246}],"con":true,"img":false}]}
{"op":"mcm","clk":"11541053075","pt":1719501612143,"mc":[{"id":"1.230178319","rc":[{"atl":[[8,0],[8.2,1]],"id":70642246}],"con":true,"img":false}]}
{"op":"mcm","clk":"11541053092","pt":1719501612344,"mc":[{"id":"1.230178319","rc":[{"spn":2.6,"spf":"NaN","id":62766534},{"atb":[[2.24,1],[2.32,1.94]],"id":39959056},{"atl":[[17.5,0.84]],"id":39959056},{"spn":2.34,"spf":1.0,"id":39959056},{"spn":2.29,"spf":"NaN","id":40214683},{"atl":[[4.1,0],[4.2,1]],"id":56418091},{"spn":2.98,"spf":"NaN","id":56418091},{"atb":[[2.84,0],[2.76,1]],"id":69261147},{"atb":[[2.84,0],[2.76,1]],"id":70642246}],"con":true,"img":false}]}
{"op":"mcm","clk":"11541053108","pt":1719501612554,"mc":[{"id":"1.230178319","rc":[{"atl":[[3.65,0],[3.75,1]],"id":62766534},{"atl":[[3.35,1],[3.15,0]],"id":40214683},{"atl":[[4.4,1],[4.2,0]],"id":56418091}],"con":true,"img":false}]}
{"op":"mcm","clk":"11541053156","pt":1719501613168,"mc":[{"id":"1.230178319","rc":[{"atb":[[2.3,0]],"id":39959056}],"con":true,"img":false}]}
{"op":"mcm","clk":"11541053267","pt":1719501614570,"mc":[{"id":"1.230178319","rc":[{"atl":[[16.5,0.52]],"id":39959056}],"con":true,"img":false}]}
{"op":"mcm","clk":"11541053277","pt":1719501614676,"mc":[{"id":"1.230178319","rc":[{"atl":[[17,0]],"id":39959056}],"con":true,"img":false}]}
{"op":"mcm","clk":"11541053291","pt":1719501614741,"mc":[{"id":"1.230178319","rc":[{"atb":[[1.03,8.02]],"id":39959056}],"con":true,"img":false}]}
{"op":"mcm","clk":"11541053315","pt":1719501614953,"mc":[{"id":"1.230178319","rc":[{"atb":[[1.03,7.88]],"id":39959056}],"con":true,"img":false}]}
{"op":"mcm","clk":"11541053345","pt":1719501615155,"mc":[{"id":"1.230178319","rc":[{"atb":[[1.03,7.49]],"id":39959056}],"con":true,"img":false}]}
{"op":"mcm","clk":"11541053363","pt":1719501615251,"mc":[{"id":"1.230178319","rc":[{"atb":[[2.36,0.38]],"id":39959056}],"con":true,"img":false}]}
{"op":"mcm","clk":"11541053393","pt":1719501615560,"mc":[{"id":"1.230178319","rc":[{"atb":[[2.32,0]],"id":39959056},{"atb":[[2.26,0]],"id":69261147},{"atb":[[2.3,0]],"id":70642246}],"con":true,"img":false}]}
{"op":"mcm","clk":"11541053412","pt":1719501615766,"mc":[{"id":"1.230178319","rc":[{"atb":[[2.36,2.33]],"id":39959056},{"atb":[[2.3,1.94]],"id":69261147},{"atb":[[2.34,1.94]],"id":70642246}],"con":true,"img":false}]}
{"op":"mcm","clk":"11541053452","pt":1719501616143,"mc":[{"id":"1.230178319","rc":[{"atb":[[1.02,0]],"id":69261147}],"con":true,"img":false}]}
{"op":"mcm","clk":"11541053460","pt":1719501616246,"mc":[{"id":"1.230178319","rc":[{"atb":[[2.32,2]],"id":69261147}],"con":true,"img":false}]}
{"op":"mcm","clk":"11541053489","pt":1719501616557,"mc":[{"id":"1.230178319","rc":[{"atb":[[1.02,11.23]],"id":70642246}],"con":true,"img":false}]}
{"op":"mcm","clk":"11541053499","pt":1719501616660,"mc":[{"id":"1.230178319","rc":[{"atb":[[2.36,2]],"id":70642246}],"con":true,"img":false}]}
{"op":"mcm","clk":"11541053507","pt":1719501616752,"mc":[{"id":"1.230178319","rc":[{"atb":[[2.38,1],[2.34,0]],"id":39959056},{"atl":[[16,1]],"id":39959056}],"con":true,"img":false}]}
{"op":"mcm","clk":"11541053604","pt":1719501617956,"mc":[{"id":"1.230178319","rc":[{"atb":[[2.28,0]],"id":39959056},{"atb":[[1.35,0]],"id":40214683},{"atb":[[1.75,0]],"id":56418091},{"atb":[[2.24,0]],"id":69261147},{"atb":[[2.28,0]],"id":70642246}],"con":true,"img":false}]}
{"op":"mcm","clk":"11541053623","pt":1719501618165,"mc":[{"id":"1.230178319","rc":[{"atb":[[2.38,4]],"id":39959056},{"atb":[[1.44,5.01]],"id":40214683},{"atb":[[1.77,3.56],[1.61,4.96],[1.76,0]],"id":56418091},{"atb":[[2.34,3]],"id":69261147},{"atb":[[2.38,2]],"id":70642246}],"con":true,"img":false}]}
{"op":"mcm","clk":"11541053642","pt":1719501618361,"mc":[{"id":"1.230178319","rc":[{"atb":[[1.4,0],[1.45,5]],"id":40214683},{"atb":[[1.78,3.56],[1.61,0]],"id":56418091}],"con":true,"img":false}]}
{"op":"mcm","clk":"11541053652","pt":1719501618465,"mc":[{"id":"1.230178319","rc":[{"atb":[[2.32,0]],"id":69261147}],"con":true,"img":false}]}
{"op":"mcm","clk":"11541053660","pt":1719501618567,"mc":[{"id":"1.230178319","rc":[{"atb":[[2.36,0.38]],"id":39959056},{"atb":[[2.3,2]],"id":69261147}],"con":true,"img":false}]}
{"op":"mcm","clk":"11541053671","pt":1719501618671,"mc":[{"id":"1.230178319","rc":[{"atb":[[2.4,1.94]],"id":39959056},{"atb":[[2.36,1.94]],"id":69261147}],"con":true,"img":false}]}
{"op":"mcm","clk":"11541053686","pt":1719501618878,"mc":[{"id":"1.230178319","rc":[{"atb":[[2.38,3]],"id":39959056},{"atb":[[2.36,0]],"id":70642246}],"con":true,"img":false}]}
{"op":"mcm","clk":"11541053693","pt":1719501618941,"mc":[{"id":"1.230178319","rc":[{"atb":[[2.34,3.94]],"id":70642246}],"con":true,"img":false}]}
{"op":"mcm","clk":"11541053738","pt":1719501619562,"mc":[{"id":"1.230178319","rc":[{"atb":[[1.33,20.07]],"id":40214683}],"con":true,"img":false}]}
{"op":"mcm","clk":"11541053770","pt":1719501619862,"mc":[{"id":"1.230178319","rc":[{"atl":[[3.75,0],[3.65,1]],"id":62766534},{"atb":[[2.24,0],[2.32,1]],"id":39959056},{"atl":[[3.35,0],[3.15,1]],"id":40214683},{"atl":[[4.1,1],[4.4,0]],"id":56418091},{"atb":[[2.84,1],[2.76,0]],"id":69261147},{"atl":[[8,1],[8.2,0]],"id":69261147},{"atb":[[2.84,1],[2.76,0]],"id":70642246}],"con":true,"img":false}]}
{"op":"mcm","clk":"11541053779","pt":1719501619963,"mc":[{"id":"1.230178319","rc":[{"atb":[[1.41,0]],"id":40214683},{"atb":[[2.38,2],[2.28,0]],"id":69261147}],"con":true,"img":false}]}
{"op":"mcm","clk":"11541053787","pt":1719501620066,"mc":[{"id":"1.230178319","rc":[{"atb":[[1.46,2]],"id":40214683}],"con":true,"img":false}]}
{"op":"mcm","clk":"11541053794","pt":1719501620169,"mc":[{"id":"1.230178319","rc":[{"atb":[[1.29,0]],"id":40214683}],"con":true,"img":false}]}
{"op":"mcm","clk":"11541053835","pt":1719501620583,"mc":[{"id":"1.230178319","rc":[{"atl":[[3.75,1]],"id":62766534},{"atb":[[2.24,1],[2.32,0]],"id":39959056},{"atl":[[4.1,0],[4.4,1],[4.2,1]],"id":56418091},{"atb":[[2.3,0],[2.84,0],[2.76,1]],"id":69261147},{"atl":[[8,0],[8.2,1]],"id":69261147},{"atb":[[2.84,0],[2.76,1]],"id":70642246},{"atl":[[8,1],[8.2,0]],"id":70642246}],"con":true,"img":false}]}
{"op":"mcm","clk":"11541053849","pt":1719501620643,"mc":[{"id":"1.230178319","rc":[{"atl":[[3.65,0]],"id":62766534},{"atl":[[4.8,2]],"id":56418091},{"atb":[[2.38,4]],"id":69261147},{"atb":[[2.4,2.12],[2.32,0]],"id":70642246}],"con":true,"img":false}]}
{"op":"mcm","clk":"11541053859","pt":1719501620753,"mc":[{"id":"1.230178319","rc":[{"atl":[[3.75,0]],"id":62766534},{"atb":[[2.32,1],[2.24,0],[2.42,1]],"id":39959056},{"atb":[[1.43,9.84]],"id":40214683},{"atl":[[4.1,1],[4.4,0],[13.5,0],[4.2,0]],"id":56418091},{"atb":[[2.84,1],[2.76,0]],"id":69261147},{"atb":[[2.84,1],[2.76,0]],"id":70642246},{"atl":[[8,0],[8.2,1]],"id":70642246}],"con":true,"img":false}]}
{"op":"mcm","clk":"11541053872","pt":1719501620857,"mc":[{"id":"1.230178319","rc":[{"atb":[[2.34,1.94]],"id":70642246}],"con":true,"img":false}]}
{"op":"mcm","clk":"11541053887","pt":1719501620956,"mc":[{"id":"1.230178319","rc":[{"atb":[[2.4,4.12]],"id":70642246}],"con":true,"img":false}]}
{"op":"mcm","clk":"11541053925","pt":1719501621261,"mc":[{"id":"1.230178319","rc":[{"atl":[[8.6,0.84],[3.65,1]],"id":62766534},{"atb":[[2.24,1]],"id":39959056},{"atl":[[4.1,0],[4.2,1]],"id":56418091},{"atb":[[2.84,0],[2.76,1]],"id":69261147},{"atb":[[2.84,0],[2.76,1]],"id":70642246}],"con":true,"img":false}]}
{"op":"mcm","clk":"11541053942","pt":1719501621363,"mc":[{"id":"1.230178319","rc":[{"atb":[[2.32,0]],"id":39959056}],"con":true,"img":false}]}
{"op":"mcm","clk":"11541053957","pt":1719501621469,"mc":[{"id":"1.230178319","rc":[{"atl":[[3.65,0],[3.75,1]],"id":62766534},{"atl":[[3.35,1],[3.15,0]],"id":40214683}],"con":true,"img":false}]}
{"op":"mcm","clk":"11541053970","pt":1719501621573,"mc":[{"id":"1.230178319","rc":[{"atb":[[2.4,0]],"id":39959056},{"atl":[[5.3,3.33],[4.4,1],[4.2,0]],"id":56418091},{"atb":[[2.36,0]],"id":69261147},{"atb":[[2.34,0]],"id":70642246}],"con":true,"img":false}]}
{"op":"mcm","clk":"11541053990","pt":1719501621781,"mc":[{"id":"1.230178319","rc":[{"atb":[[2.4,1.94],[2.42,0]],"id":39959056},{"atb":[[2.4,1.94]],"id":69261147},{"atb":[[2.42,1.94]],"id":70642246}],"con":true,"img":false}]}
{"op":"mcm","clk":"11541054054","pt":1719501622363,"mc":[{"id":"1.230178319","rc":[{"atb":[[2.38,2]],"id":69261147}],"con":true,"img":false}]}
{"op":"mcm","clk":"11541054062","pt":1719501622458,"mc":[{"id":"1.230178319","rc":[{"atb":[[2.42,2]],"id":69261147}],"con":true,"img":false}]}
{"op":"mcm","clk":"11541054090","pt":1719501622767,"mc":[{"id":"1.230178319","rc":[{"atb":[[1.33,17.95],[1.47,2.11]],"id":40214683},{"atb":[[2.4,2.12]],"id":70642246}],"con":true,"img":false}]}
{"op":"mcm","clk":"11541054102","pt":1719501622870,"mc":[{"id":"1.230178319","rc":[{"atb":[[2.44,2]],"id":70642246}],"con":true,"img":false}]}
{"op":"mcm","clk":"11541054112","pt":1719501622974,"mc":[{"id":"1.230178319","rc":[{"atb":[[1.45,0],[1.47,4.23]],"id":40214683}],"con":true,"img":false}]}
{"op":"mcm","clk":"11541054186","pt":1719501623870,"mc":[{"id":"1.230178319","rc":[{"atb":[[2.42,2.04]],"id":39959056}],"con":true,"img":false}]}
{"op":"mcm","clk":"11541054196","pt":1719501623962,"mc":[{"id":"1.230178319","rc":[{"atb":[[2.44,1]],"id":39959056},{"atb":[[1.46,0]],"id":40214683}],"con":true,"img":false}]}
{"op":"mcm","clk":"11541054207","pt":1719501624064,"mc":[{"id":"1.230178319","rc":[{"atb":[[1.48,2]],"id":40214683}],"con":true,"img":false}]}
{"op":"mcm","clk":"11541054237","pt":1719501624375,"mc":[{"id":"1.230178319","rc":[{"atb":[[2.42,0]],"id":69261147}],"con":true,"img":false}]}
{"op":"mcm","clk":"11541054245","pt":1719501624477,"mc":[{"id":"1.230178319","rc":[{"atb":[[2.4,3.94]],"id":69261147}],"con":true,"img":false}]}
{"op":"mcm","clk":"11541054253","pt":1719501624580,"mc":[{"id":"1.230178319","rc":[{"atb":[[2.4,0]],"id":39959056}],"con":true,"img":false}]}
{"op":"mcm","clk":"11541054272","pt":1719501624787,"mc":[{"id":"1.230178319","rc":[{"atb":[[2.44,2.94]],"id":39959056}],"con":true,"img":false}]}
{"op":"mcm","clk":"11541054283","pt":1719501624853,"mc":[{"id":"1.230178319","rc":[{"atb":[[2.44,0]],"id":70642246}],"con":true,"img":false}]}
{"op":"mcm","clk":"11541054291","pt":1719501624958,"mc":[{"id":"1.230178319","rc":[{"atb":[[2.42,3.94]],"id":70642246}],"con":true,"img":false}]}
{"op":"mcm","clk":"11541054330","pt":1719501625372,"mc":[{"id":"1.230178319","rc":[{"atl":[[3.45,1],[3.75,0]],"id":62766534},{"atb":[[2.32,1],[2.24,0]],"id":39959056},{"atl":[[3.05,1]],"id":40214683},{"atb":[[1.74,0],[1.7,1]],"id":56418091},{"atl":[[4.1,1],[4.4,0]],"id":56418091},{"atl":[[8.2,0],[7.8,1]],"id":69261147},{"atb":[[2.84,1],[2.76,0]],"id":70642246}],"con":true,"img":false}]}
{"op":"mcm","clk":"11541054340","pt":1719501625464,"mc":[{"id":"1.230178319","rc":[{"atb":[[1.55,2.5],[1.7,2.5],[1.62,10],[1.66,5]],"id":62766534},{"atl":[[4.8,5],[8.6,2.34],[5.2,10],[4.4,2.5]],"id":62766534},{"atb":[[2.32,5.99],[2.5,5],[2.44,5.22],[2.58,2.5],[2.42,10],[2.46,1.52],[2.16,0]],"id":39959056},{"atl":[[9.6,5],[11,10],[8.8,2.5],[15.5,2.28]],"id":39959056},{"atb":[[1.48,6.5],[1.53,10],[1.57,5],[1.61,2.5]],"id":40214683},{"atl":[[4,2.5],[4.8,10],[3.35,0],[4.4,5],[3.3,4.5]],"id":40214683},{"atb":[[1.79,2.25],[2.02,10],[2.18,2.5],[2.1,5]],"id":56418091},{"atl":[[5.1,5],[5.5,10],[4.7,4.75]],"id":56418091},{"atb":[[2.6,10],[2.78,2.25],[2.68,5],[2.76,3.5]],"id":69261147},{"atl":[[8,2.25],[9.2,5],[10,10],[8.4,2.5]],"id":69261147},{"atb":[[2.42,6.44],[2.78,2.25]],"id":70642246},{"atl":[[8,2.25],[8.6,2.5],[10.5,10],[9.4,5]],"id":70642246}],"con":true,"img":false}]}
{"op":"mcm","clk":"11541054354","pt":1719501625567,"mc":[{"id":"1.230178319","rc":[{"atl":[[8.8,0],[3.75,2]],"id":62766534}],"con":true,"img":false}]}
{"op":"mcm","clk":"11541054365","pt":1719501625670,"mc":[{"id":"1.230178319","rc":[{"atb":[[1.58,10],[1.3,0]],"id":62766534},{"atl":[[4.8,10],[3.75,0]],"id":62766534},{"atb":[[2.44,4.22]],"id":39959056},{"atl":[[16,0],[18,0],[8.8,7.5]],"id":39959056},{"atl":[[3.4,5.5],[8.4,0]],"id":40214683},{"atb":[[2.06,7.5],[1.78,0]],"id":56418091},{"atb":[[2.38,0],[2.78,5.75]],"id":69261147},{"atl":[[46,0],[9.4,4.75]],"id":69261147},{"atl":[[65,0],[11.5,5]],"id":70642246}],"con":true,"img":false}]}
{"op":"mcm","clk":"11541054376","pt":1719501625774,"mc":[{"id":"1.230178319","rc":[{"atl":[[4.8,5],[4.4,7.5]],"id":62766534},{"atl":[[11,17.5]],"id":39959056},{"atb":[[2.78,2.25],[2.68,10.75]],"id":69261147}],"con":true,"img":false}]}
{"op":"mcm","clk":"11541054386","pt":1719501625877,"mc":[{"id":"1.230178319","rc":[{"atl":[[8.8,2.5]],"id":39959056},{"atl":[[8.2,0]],"id":40214683}],"con":true,"img":false}]}
{"op":"mcm","clk":"11541054399","pt":1719501626083,"mc":[{"id":"1.230178319","rc":[{"atl":[[4.5,13.58]],"id":62766534},{"atb":[[2.5,3.4]],"id":70642246}],"con":true,"img":false}]}
{"op":"mcm","clk":"11541054416","pt":1719501626289,"mc":[{"id":"1.230178319","rc":[{"atl":[[8.6,0.84]],"id":39959056},{"atb":[[2.5,0]],"id":70642246},{"atl":[[7.8,0.84]],"id":70642246}],"con":true,"img":false}]}
{"op":"mcm","clk":"11541054424","pt":1719501626350,"mc":[{"id":"1.230178319","rc":[{"atl":[[8.6,1.5]],"id":62766534},{"atl":[[9.6,10],[17.5,0]],"id":39959056},{"atl":[[5.3,0]],"id":56418091},{"atb":[[2.4,0],[2.5,3.4]],"id":70642246}],"con":true,"img":false}]}
{"op":"mcm","clk":"11541054433","pt":1719501626470,"mc":[{"id":"1.230178319","rc":[{"atl":[[11,10]],"id":39959056}],"con":true,"img":false}]}
{"op":"mcm","clk":"11541054443","pt":1719501626568,"mc":[{"id":"1.230178319","rc":[{"atb":[[1.32,0]],"id":62766534},{"atb":[[2.38,0]],"id":39959056},{"atb":[[1.44,1],[1.48,4.5]],"id":40214683},{"atb":[[1.77,0]],"id":56418091},{"atb":[[2.34,0]],"id":69261147},{"atb":[[2.38,0]],"id":70642246}],"con":true,"img":false}]}
{"op":"mcm","clk":"11541054456","pt":1719501626671,"mc":[{"id":"1.230178319","rc":[{"atb":[[1.7,6.3]],"id":62766534},{"atb":[[2.32,4.99],[2.6,3.4]],"id":39959056},{"atb":[[1.62,2],[1.61,6.5]],"id":40214683},{"atl":[[5.2,3.42]],"id":56418091},{"atb":[[2.78,5.55]],"id":69261147},{"atb":[[2.84,0],[2.76,1]],"id":70642246}],"con":true,"img":false}]}
{"op":"mcm","clk":"11541054464","pt":1719501626775,"mc":[{"id":"1.230178319","rc":[{"atb":[[2.8,5.55],[2.68,5]],"id":69261147}],"con":true,"img":false}]}
{"op":"mcm","clk":"11541054475","pt":1719501626878,"mc":[{"id":"1.230178319","rc":[{"atb":[[1.65,2.11]],"id":62766534},{"atb":[[2.12,2.11]],"id":56418091}],"con":true,"img":false}]}
{"op":"mcm","clk":"11541054492","pt":1719501627084,"mc":[{"id":"1.230178319","rc":[{"atb":[[1.02,0]],"id":62766534},{"atb":[[1.39,15.68]],"id":40214683}],"con":true,"img":false}]}
{"op":"mcm","clk":"11541054502","pt":1719501627187,"mc":[{"id":"1.230178319","rc":[{"atb":[[1.71,2]],"id":62766534}],"con":true,"img":false}]}
{"op":"mcm","clk":"11541054515","pt":1719501627291,"mc":[{"id":"1.230178319","rc":[{"atb":[[1.69,5.66]],"id":62766534},{"atb":[[2.56,3.49]],"id":39959056},{"atb":[[2.16,4.76]],"id":56418091},{"atb":[[2.76,6.52]],"id":69261147}],"con":true,"img":false}]}
{"op":"mcm","clk":"11541054527","pt":1719501627353,"mc":[{"id":"1.230178319","rc":[{"atl":[[3.35,1],[3.05,0]],"id":40214683},{"atl":[[4.4,1]],"id":56418091}],"con":true,"img":false}]}
{"op":"mcm","clk":"11541054535","pt":1719501627453,"mc":[{"id":"1.230178319","rc":[{"atl":[[4.1,0]],"id":56418091}],"con":true,"img":false}]}
{"op":"mcm","clk":"11541054545","pt":1719501627558,"mc":[{"id":"1.230178319","rc":[{"atl":[[3.25,2.54]],"id":40214683},{"atb":[[2.4,1.94]],"id":69261147}],"con":true,"img":false}]}
{"op":"mcm","clk":"11541054556","pt":1719501627662,"mc":[{"id":"1.230178319","rc":[{"atb":[[2.44,2.28],[2.62,1]],"id":39959056},{"atl":[[8.4,1]],"id":39959056},{"atl":[[3.25,3.38]],"id":40214683},{"atb":[[2.8,7.55],[2.4,0]],"id":69261147},{"atb":[[2.42,4.5]],"id":70642246}],"con":true,"img":false}]}
{"op":"mcm","clk":"11541054571","pt":1719501627858,"mc":[{"id":"1.230178319","rc":[{"atb":[[2.62,2.94]],"id":39959056},{"atb":[[2.2,1.94]],"id":56418091},{"atb":[[2.82,1.94]],"id":69261147},{"atb":[[2.8,1.94]],"id":70642246}],"con":true,"img":false}]}
{"op":"mcm","clk":"11541054581","pt":1719501627977,"mc":[{"id":"1.230178319","rc":[{"atb":[[2.42,2.5]],"id":70642246}],"con":true,"img":false}]}
{"op":"mcm","clk":"11541054588","pt":1719501628064,"mc":[{"id":"1.230178319","rc":[{"atb":[[2.8,3.94]],"id":70642246}],"con":true,"img":false}]}
{"op":"mcm","clk":"11541054617","pt":1719501628477,"mc":[{"id":"1.230178319","rc":[{"atl":[[3.75,1]],"id":62766534}],"con":true,"img":false}]}
{"op":"mcm","clk":"11541054625","pt":1719501628581,"mc":[{"id":"1.230178319","rc":[{"atl":[[3.45,0]],"id":62766534}],"con":true,"img":false}]}
{"op":"mcm","clk":"11541054635","pt":1719501628684,"mc":[{"id":"1.230178319","rc":[{"atb":[[1.5,11.5],[1.47,2.11]],"id":40214683},{"atb":[[2.84,1]],"id":70642246}],"con":true,"img":false}]}
{"op":"mcm","clk":"11541054643","pt":1719501628788,"mc":[{"id":"1.230178319","rc":[{"atb":[[2.76,0]],"id":70642246}],"con":true,"img":false}]}
{"op":"mcm","clk":"11541054651","pt":1719501628891,"mc":[{"id":"1.230178319","rc":[{"atb":[[1.39,10.13]],"id":40214683}],"con":true,"img":false}]}
{"op":"mcm","clk":"11541054658","pt":1719501628995,"mc":[{"id":"1.230178319","rc":[{"atb":[[2.16,0]],"id":56418091}],"con":true,"img":false}]}
{"op":"mcm","clk":"11541054697","pt":1719501629367,"mc":[{"id":"1.230178319","rc":[{"atl":[[3.45,1],[3.75,0]],"id":62766534},{"atl":[[4.1,1]],"id":56418091}],"con":true,"img":false}]}
{"op":"mcm","clk":"11541054705","pt":1719501629470,"mc":[{"id":"1.230178319","rc":[{"atl":[[3.4,1]],"id":62766534},{"atb":[[1.31,0]],"id":40214683},{"atl":[[3.35,0],[3.05,1]],"id":40214683},{"atl":[[4.4,0]],"id":56418091},{"atl":[[8,3.25],[7.8,0]],"id":69261147},{"atl":[[8,3.25],[8.2,0]],"id":70642246}],"con":true,"img":false}]}
{"op":"mcm","clk":"11541054710","pt":1719501629565,"mc":[{"id":"1.230178319","rc":[{"atl":[[3.6,1]],"id":62766534},{"atl":[[3.15,1]],"id":40214683}],"con":true,"img":false}]}
{"op":"mcm","clk":"11541054717","pt":1719501629668,"mc":[{"id":"1.230178319","rc":[{"atl":[[3.45,0],[3.6,8.5],[4.4,2.5]],"id":62766534}],"con":true,"img":false}]}
{"op":"mcm","clk":"11541054742","pt":1719501629979,"mc":[{"id":"1.230178319","rc":[{"atl":[[16.5,0]],"id":39959056}],"con":true,"img":false}]}
{"op":"mcm","clk":"11541054748","pt":1719501630082,"mc":[{"id":"1.230178319","rc":[{"atb":[[1.56,9.88]],"id":40214683}],"con":true,"img":false}]}
{"op":"mcm","clk":"11541054759","pt":1719501630185,"mc":[{"id":"1.230178319","rc":[{"atl":[[3.6,7.5],[3.4,0]],"id":62766534},{"atl":[[3.15,0],[3.25,2.54],[3.05,0]],"id":40214683},{"atl":[[7.8,0.84]],"id":69261147}],"con":true,"img":false}]}
{"op":"mcm","clk":"11541054798","pt":1719501630558,"mc":[{"id":"1.230178319","rc":[{"atb":[[2.36,0]],"id":39959056}],"con":true,"img":false}]}
{"op":"mcm","clk":"11541054805","pt":1719501630663,"mc":[{"id":"1.230178319","rc":[{"atl":[[3.55,0.84]],"id":62766534}],"con":true,"img":false}]}
{"op":"mcm","clk":"11541054813","pt":1719501630771,"mc":[{"id":"1.230178319","rc":[{"atb":[[2.2,0]],"id":56418091},{"atb":[[2.82,0]],"id":69261147}],"con":true,"img":false}]}
{"op":"mcm","clk":"11541054835","pt":1719501630975,"mc":[{"id":"1.230178319","rc":[{"atb":[[2.2,1.94]],"id":56418091},{"atb":[[2.82,1.94]],"id":69261147}],"con":true,"img":false}]}
{"op":"mcm","clk":"11541054853","pt":1719501631175,"mc":[{"id":"1.230178319","rc":[{"atl":[[8.2,0.52]],"id":39959056}],"con":true,"img":false}]}
{"op":"mcm","clk":"11541054863","pt":1719501631279,"mc":[{"id":"1.230178319","rc":[{"atb":[[1.04,0.52]],"id":39959056}],"con":true,"img":false}]}
{"op":"mcm","clk":"11541054876","pt":1719501631382,"mc":[{"id":"1.230178319","rc":[{"atl":[[8.4,0]],"id":39959056}],"con":true,"img":false}]}
{"op":"mcm","clk":"11541054888","pt":1719501631487,"mc":[{"id":"1.230178319","rc":[{"atl":[[3.6,8.5]],"id":62766534},{"atb":[[1.04,0.32]],"id":39959056}],"con":true,"img":false}]}
{"op":"mcm","clk":"11541054897","pt":1719501631590,"mc":[{"id":"1.230178319","rc":[{"atb":[[1.04,0]],"id":39959056},{"atl":[[3.15,1]],"id":40214683}],"con":true,"img":false}]}
{"op":"mcm","clk":"11541054906","pt":1719501631693,"mc":[{"id":"1.230178319","rc":[{"atb":[[2.64,0.32]],"id":39959056}],"con":true,"img":false}]}
{"op":"mcm","clk":"11541054929","pt":1719501631900,"mc":[{"id":"1.230178319","rc":[{"atb":[[2.62,1.94]],"id":39959056}],"con":true,"img":false}]}
{"op":"mcm","clk":"11541054937","pt":1719501631966,"mc":[{"id":"1.230178319","rc":[{"atl":[[8.8,12.5]],"id":39959056},{"atb":[[2.82,3.4],[2.5,0]],"id":70642246}],"con":true,"img":false}]}
{"op":"mcm","clk":"11541054951","pt":1719501632072,"mc":[{"id":"1.230178319","rc":[{"atl":[[3.6,7.5],[3.65,1]],"id":62766534},{"atl":[[9.6,5]],"id":39959056},{"atb":[[2.84,0],[2.76,1]],"id":70642246},{"atl":[[8,2.25],[8.2,1]],"id":70642246}],"con":true,"img":false}]}
{"op":"mcm","clk":"11541054958","pt":1719501632170,"mc":[{"id":"1.230178319","rc":[{"atl":[[3.7,1]],"id":62766534},{"atl":[[3.3,5.5]],"id":40214683},{"atl":[[4.3,1]],"id":56418091}],"con":true,"img":false}]}
{"op":"mcm","clk":"11541054969","pt":1719501632276,"mc":[{"id":"1.230178319","rc":[{"atl":[[3.6,8.5],[3.65,0]],"id":62766534},{"atl":[[3.15,0]],"id":40214683},{"atl":[[4.1,0]],"id":56418091},{"atb":[[2.84,1],[2.76,0]],"id":70642246},{"atl":[[8,3.25],[8.2,0]],"id":70642246}],"con":true,"img":false}]}
{"op":"mcm","clk":"11541054987","pt":1719501632473,"mc":[{"id":"1.230178319","rc":[{"atb":[[2.76,3.5]],"id":69261147}],"con":true,"img":false}]}
{"op":"mcm","clk":"11541055059","pt":1719501633305,"mc":[{"id":"1.230178319","rc":[{"atb":[[2.8,1.94]],"id":70642246}],"con":true,"img":false}]}
{"op":"mcm","clk":"11541055070","pt":1719501633407,"mc":[{"id":"1.230178319","rc":[{"atb":[[2.84,3]],"id":70642246}],"con":true,"img":false}]}
{"op":"mcm","clk":"11541055109","pt":1719501633872,"mc":[{"id":"1.230178319","rc":[{"atb":[[2.2,0]],"id":56418091},{"atb":[[2.82,0]],"id":69261147},{"atb":[[2.8,0]],"id":70642246}],"con":true,"img":false}]}
{"op":"mcm","clk":"11541055127","pt":1719501634079,"mc":[{"id":"1.230178319","rc":[{"atb":[[2.66,1]],"id":39959056},{"atb":[[2.2,1.94]],"id":56418091},{"atb":[[2.82,1.94]],"id":69261147},{"atb":[[2.86,1.94]],"id":70642246}],"con":true,"img":false}]}
{"op":"mcm","clk":"11541055135","pt":1719501634182,"mc":[{"id":"1.230178319","rc":[{"atb":[[2.82,0],[2.86,4.94]],"id":70642246}],"con":true,"img":false}]}
{"op":"mcm","clk":"11541055176","pt":1719501634699,"mc":[{"id":"1.230178319","rc":[{"atb":[[1.72,2.11],[1.65,0]],"id":62766534},{"atb":[[2.62,4.06],[1.42,0]],"id":39959056},{"atb":[[1.6,2.11],[1.47,0]],"id":40214683},{"atl":[[3.2,0.84]],"id":40214683}],"con":true,"img":false}]}
{"op":"mcm","clk":"11541055185","pt":1719501634802,"mc":[{"id":"1.230178319","rc":[{"atl":[[3.6,1],[3.65,9.35]],"id":62766534}],"con":true,"img":false}]}
{"op":"mcm","clk":"11541055192","pt":1719501634904,"mc":[{"id":"1.230178319","rc":[{"atb":[[2.84,1]],"id":70642246}],"con":true,"img":false}]}
{"op":"mcm","clk":"11541055199","pt":1719501635008,"mc":[{"id":"1.230178319","rc":[{"atb":[[2.88,2]],"id":70642246}],"con":true,"img":false}]}
{"op":"mcm","clk":"11541055218","pt":1719501635177,"mc":[{"id":"1.230178319","rc":[{"atb":[[1.7,2.5]],"id":62766534},{"atb":[[2.6,0]],"id":39959056},{"atb":[[1.61,2.5]],"id":40214683},{"atb":[[2.78,2.25]],"id":69261147}],"con":true,"img":false}]}
{"op":"mcm","clk":"11541055226","pt":1719501635278,"mc":[{"id":"1.230178319","rc":[{"atb":[[1.72,4.11]],"id":62766534},{"atb":[[2.66,3.6]],"id":39959056},{"atb":[[1.62,5.27]],"id":40214683},{"atb":[[2.82,3.94]],"id":69261147}],"con":true,"img":false}]}
{"op":"mcm","clk":"11541055241","pt":1719501635484,"mc":[{"id":"1.230178319","rc":[{"atb":[[2.8,2],[2.84,3.95]],"id":69261147}],"con":true,"img":false}]}
{"op":"mcm","clk":"11541055273","pt":1719501635885,"mc":[{"id":"1.230178319","rc":[{"atl":[[3.55,3.38]],"id":62766534}],"con":true,"img":false}]}
{"op":"mcm","clk":"11541055282","pt":1719501635987,"mc":[{"id":"1.230178319","rc":[{"atb":[[2.68,4.06]],"id":39959056}],"con":true,"img":false}]}
{"op":"mcm","clk":"11541055295","pt":1719501636194,"mc":[{"id":"1.230178319","rc":[{"atb":[[2.66,2.6]],"id":39959056}],"con":true,"img":false}]}
{"op":"mcm","clk":"11541055310","pt":1719501636401,"mc":[{"id":"1.230178319","rc":[{"atb":[[1.71,0]],"id":62766534}],"con":true,"img":false}]}
{"op":"mcm","clk":"11541055317","pt":1719501636505,"mc":[{"id":"1.230178319","rc":[{"atb":[[1.73,2]],"id":62766534}],"con":true,"img":false}]}
{"op":"mcm","clk":"11541055333","pt":1719501636668,"mc":[{"id":"1.230178319","rc":[{"atl":[[3.7,0]],"id":62766534},{"atl":[[3.15,1],[3.3,4.5]],"id":40214683},{"atl":[[4.3,0],[4.1,1]],"id":56418091}],"con":true,"img":false}]}
{"op":"mcm","clk":"11541055340","pt":1719501636772,"mc":[{"id":"1.230178319","rc":[{"atb":[[2.8,0]],"id":69261147}],"con":true,"img":false}]}
{"op":"mcm","clk":"11541055353","pt":1719501636881,"mc":[{"id":"1.230178319","rc":[{"atb":[[2.62,2.11]],"id":39959056},{"atb":[[2.2,0]],"id":56418091},{"atb":[[2.82,2],[2.86,2]],"id":69261147}],"con":true,"img":false}]}
{"op":"mcm","clk":"11541055372","pt":1719501637079,"mc":[{"id":"1.230178319","rc":[{"atb":[[2.7,1.94]],"id":39959056},{"atb":[[2.2,1.94]],"id":56418091},{"atb":[[2.86,3.94]],"id":69261147}],"con":true,"img":false}]}
{"op":"mcm","clk":"11541055381","pt":1719501637185,"mc":[{"id":"1.230178319","rc":[{"atb":[[2.84,0],[2.88,3.95]],"id":69261147}],"con":true,"img":false}]}
{"op":"mcm","clk":"11541055433","pt":1719501637800,"mc":[{"id":"1.230178319","rc":[{"atb":[[1.73,6.42]],"id":62766534},{"atl":[[3.5,4.42]],"id":62766534},{"atb":[[2.72,2.28],[2.7,5.35]],"id":39959056},{"atl":[[8.4,3.41]],"id":39959056},{"atb":[[1.62,8.73]],"id":40214683},{"atl":[[3.1,3.46]],"id":40214683},{"atb":[[2.2,5.03]],"id":56418091},{"atl":[[4,3.09]],"id":56418091},{"atb":[[2.9,4.31]],"id":69261147},{"atl":[[7.8,5.15]],"id":69261147},{"atb":[[2.9,3.38]],"id":70642246},{"atl":[[7.8,4.22]],"id":70642246}],"con":true,"img":false}]}
{"op":"mcm","clk":"11541055443","pt":1719501637903,"mc":[{"id":"1.230178319","rc":[{"atb":[[1.55,1],[1.69,0]],"id":62766534},{"atl":[[8.6,0]],"id":62766534},{"atb":[[2.44,0],[2.56,0],[2.46,0]],"id":39959056},{"atl":[[15.5,0]],"id":39959056},{"atb":[[1.48,0]],"id":40214683},{"atl":[[3.3,0]],"id":40214683},{"atb":[[1.79,0]],"id":56418091},{"atl":[[4.7,2.5]],"id":56418091},{"atb":[[2.86,1.94],[2.78,0]],"id":69261147},{"atl":[[8,1]],"id":69261147},{"atb":[[2.78,0]],"id":70642246},{"atl":[[8,1]],"id":70642246}],"con":true,"img":false}]}
{"op":"mcm","clk":"11541055453","pt":1719501638007,"mc":[{"id":"1.230178319","rc":[{"atb":[[2.9,6.31]],"id":69261147}],"con":true,"img":false}]}
{"op":"mcm","clk":"11541055458","pt":1719501638111,"mc":[{"id":"1.230178319","rc":[{"atb":[[2.74,1]],"id":39959056}],"con":true,"img":false}]}
{"op":"mcm","clk":"11541055465","pt":1719501638172,"mc":[{"id":"1.230178319","rc":[{"atl":[[3.45,0.84]],"id":62766534},{"atl":[[8.2,1.37]],"id":39959056},{"atl":[[3.2,0]],"id":40214683},{"atl":[[3.95,0.84]],"id":56418091}],"con":true,"img":false}]}
{"op":"mcm","clk":"11541055472","pt":1719501638273,"mc":[{"id":"1.230178319","rc":[{"atl":[[8.8,2.5]],"id":39959056},{"atl":[[4.8,0],[4.4,2.5]],"id":56418091}],"con":true,"img":false}]}
{"op":"mcm","clk":"11541055482","pt":1719501638379,"mc":[{"id":"1.230178319","rc":[{"atl":[[8.2,3.37]],"id":39959056}],"con":true,"img":false}]}
{"op":"mcm","clk":"11541055495","pt":1719501638479,"mc":[{"id":"1.230178319","rc":[{"atl":[[8.6,5.62]],"id":39959056},{"atl":[[3.25,0]],"id":40214683}],"con":true,"img":false}]}
{"op":"mcm","clk":"11541055506","pt":1719501638583,"mc":[{"id":"1.230178319","rc":[{"atl":[[8.2,1.37]],"id":39959056}],"con":true,"img":false}]}
{"op":"mcm","clk":"11541055529","pt":1719501638780,"mc":[{"id":"1.230178319","rc":[{"atl":[[8.6,0.84],[8.2,4.78]],"id":39959056}],"con":true,"img":false}]}
{"op":"mcm","clk":"11541055536","pt":1719501638884,"mc":[{"id":"1.230178319","rc":[{"atl":[[8.6,5],[8.2,1.37]],"id":39959056}],"con":true,"img":false}]}
{"op":"mcm","clk":"11541055546","pt":1719501638986,"mc":[{"id":"1.230178319","rc":[{"atl":[[8.6,0],[8.2,4.78]],"id":39959056}],"con":true,"img":false}]}
{"op":"mcm","clk":"11541055576","pt":1719501639399,"mc":[{"id":"1.230178319","rc":[{"atb":[[2.88,0]],"id":70642246}],"con":true,"img":false}]}
{"op":"mcm","clk":"11541055583","pt":1719501639502,"mc":[{"id":"1.230178319","rc":[{"atb":[[2.92,2]],"id":70642246}],"con":true,"img":false}]}
{"op":"mcm","clk":"11541055594","pt":1719501639606,"mc":[{"id":"1.230178319","rc":[{"atl":[[3.55,0.84]],"id":62766534},{"atb":[[2.9,0],[2.94,4.41]],"id":70642246}],"con":true,"img":false}]}
{"op":"mcm","clk":"11541055613","pt":1719501639865,"mc":[{"id":"1.230178319","rc":[{"atb":[[2.92,10.82],[2.86,1.94]],"id":70642246}],"con":true,"img":false}]}
{"op":"mcm","clk":"11541055624","pt":1719501639976,"mc":[{"id":"1.230178319","rc":[{"atb":[[2.7,3.41]],"id":39959056},{"atb":[[2.86,0]],"id":69261147},{"atb":[[2.86,0]],"id":70642246}],"con":true,"img":false}]}
{"op":"mcm","clk":"11541055628","pt":1719501640084,"mc":[{"id":"1.230178319","rc":[{"atl":[[4.1,4.94],[4.4,0]],"id":56418091},{"atl":[[8.4,8.66],[9.4,0]],"id":69261147},{"atl":[[11.5,0],[9.8,6.73]],"id":70642246}],"con":true,"img":false}]}
{"op":"mcm","clk":"11541055635","pt":1719501640188,"mc":[{"id":"1.230178319","rc":[{"atb":[[2.74,2.94]],"id":39959056},{"atb":[[2.92,1.94]],"id":69261147},{"atb":[[2.96,1.94]],"id":70642246}],"con":true,"img":false}]}
{"op":"mcm","clk":"11541055648","pt":1719501640394,"mc":[{"id":"1.230178319","rc":[{"atl":[[3.55,6.11],[3.65,0]],"id":62766534},{"atb":[[2.92,5.89],[2.88,0]],"id":69261147}],"con":true,"img":false}]}
{"op":"mcm","clk":"11541055656","pt":1719501640488,"mc":[{"id":"1.230178319","rc":[{"atb":[[2.92,1.94],[2.9,10.26]],"id":69261147}],"con":true,"img":false}]}
{"op":"mcm","clk":"11541055703","pt":1719501641108,"mc":[{"id":"1.230178319","rc":[{"atb":[[2.92,8.82]],"id":70642246}],"con":true,"img":false}]}
{"op":"mcm","clk":"11541055709","pt":1719501641212,"mc":[{"id":"1.230178319","rc":[{"atb":[[1.02,13.23]],"id":70642246}],"con":true,"img":false}]}
{"op":"mcm","clk":"11541055762","pt":1719501641792,"mc":[{"id":"1.230178319","rc":[{"atl":[[3.05,0.84]],"id":40214683}],"con":true,"img":false}]}
{"op":"mcm","clk":"11541055780","pt":1719501642003,"mc":[{"id":"1.230178319","rc":[{"atl":[[3.4,0],[3.15,5.31]],"id":40214683}],"con":true,"img":false}]}
{"op":"mcm","clk":"11541055790","pt":1719501642094,"mc":[{"id":"1.230178319","rc":[{"atl":[[3.45,3.38]],"id":62766534}],"con":true,"img":false}]}
{"op":"mcm","clk":"11541055800","pt":1719501642198,"mc":[{"id":"1.230178319","rc":[{"atl":[[3.4,4.42],[3.55,0.84]],"id":62766534}],"con":true,"img":false}]}
{"op":"mcm","clk":"11541055847","pt":1719501642779,"mc":[{"id":"1.230178319","rc":[{"atl":[[3.55,0]],"id":62766534}],"con":true,"img":false}]}
{"op":"mcm","clk":"11541055861","pt":1719501643080,"mc":[{"id":"1.230178319","rc":[{"atb":[[2.92,0]],"id":69261147},{"atb":[[2.96,0]],"id":70642246}],"con":true,"img":false}]}
{"op":"mcm","clk":"11541055872","pt":1719501643288,"mc":[{"id":"1.230178319","rc":[{"atb":[[2.92,1.94]],"id":69261147},{"atb":[[2.96,1.94]],"id":70642246}],"con":true,"img":false}]}
{"op":"mcm","clk":"11541055915","pt":1719501643905,"mc":[{"id":"1.230178319","rc":[{"atb":[[1.72,2.11]],"id":62766534},{"atb":[[2.66,0]],"id":39959056},{"atb":[[1.62,5.46]],"id":40214683},{"atb":[[2.82,0]],"id":69261147}],"con":true,"img":false}]}
{"op":"mcm","clk":"11541055922","pt":1719501644009,"mc":[{"id":"1.230178319","rc":[{"atb":[[1.74,3]],"id":62766534},{"atb":[[2.76,2.4],[2.68,0]],"id":39959056},{"atb":[[1.63,2.73]],"id":40214683}],"con":true,"img":false}]}
{"op":"mcm","clk":"11541055932","pt":1719501644215,"mc":[{"id":"1.230178319","rc":[{"atb":[[2.74,1.94]],"id":39959056}],"con":true,"img":false}]}
{"op":"mcm","clk":"11541055954","pt":1719501644483,"mc":[{"id":"1.230178319","rc":[{"atl":[[3.05,3.38]],"id":40214683}],"con":true,"img":false}]}
{"op":"mcm","clk":"11541055964","pt":1719501644582,"mc":[{"id":"1.230178319","rc":[{"atl":[[3.45,0.84]],"id":62766534}],"con":true,"img":false}]}
{"op":"mcm","clk":"11541055973","pt":1719501644686,"mc":[{"id":"1.230178319","rc":[{"atl":[[3.4,0],[3.5,9.69]],"id":62766534}],"con":true,"img":false}]}
{"op":"mcm","clk":"11541055981","pt":1719501644789,"mc":[{"id":"1.230178319","rc":[{"atl":[[3.6,11.54],[3.5,4.42]],"id":62766534}],"con":true,"img":false}]}
{"op":"mcm","clk":"11541056024","pt":1719501645401,"mc":[{"id":"1.230178319","rc":[{"atb":[[1.62,3.46]],"id":40214683},{"atb":[[2.96,6.35]],"id":70642246}],"con":true,"img":false}]}
{"op":"mcm","clk":"11541056030","pt":1719501645506,"mc":[{"id":"1.230178319","rc":[{"atb":[[1.64,2]],"id":40214683},{"atb":[[2.92,0]],"id":70642246}],"con":true,"img":false}]}
{"op":"mcm","clk":"11541056051","pt":1719501645711,"mc":[{"id":"1.230178319","rc":[{"atb":[[1.73,4.42]],"id":62766534}],"con":true,"img":false}]}
{"op":"mcm","clk":"11541056065","pt":1719501645815,"mc":[{"id":"1.230178319","rc":[{"atb":[[1.75,2]],"id":62766534}],"con":true,"img":false}]}
{"op":"mcm","clk":"11541056089","pt":1719501646084,"mc":[{"id":"1.230178319","rc":[{"atb":[[2.74,0]],"id":39959056},{"atb":[[2.92,0]],"id":69261147}],"con":true,"img":false}]}
{"op":"mcm","clk":"11541056099","pt":1719501646191,"mc":[{"id":"1.230178319","rc":[{"atb":[[2.78,1]],"id":39959056}],"con":true,"img":false}]}
{"op":"mcm","clk":"11541056105","pt":1719501646290,"mc":[{"id":"1.230178319","rc":[{"atb":[[2.78,2.94]],"id":39959056},{"atb":[[2.92,1.94]],"id":69261147}],"con":true,"img":false}]}
{"op":"mcm","clk":"11541056113","pt":1719501646384,"mc":[{"id":"1.230178319","rc":[{"atl":[[8.2,4.25]],"id":39959056}],"con":true,"img":false}]}
{"op":"mcm","clk":"11541056124","pt":1719501646488,"mc":[{"id":"1.230178319","rc":[{"atl":[[8.2,0.84],[8.8,10.17]],"id":39959056}],"con":true,"img":false}]}
{"op":"mcm","clk":"11541056167","pt":1719501647003,"mc":[{"id":"1.230178319","rc":[{"atb":[[1.64,4.11]],"id":40214683}],"con":true,"img":false}]}
{"op":"mcm","clk":"11541056176","pt":1719501647105,"mc":[{"id":"1.230178319","rc":[{"atb":[[2.64,0]],"id":39959056},{"atb":[[1.6,0]],"id":40214683}],"con":true,"img":false}]}
{"op":"mcm","clk":"11541056212","pt":1719501647517,"mc":[{"id":"1.230178319","rc":[{"atl":[[3.15,1],[3.05,6.84]],"id":40214683}],"con":true,"img":false}]}
{"op":"mcm","clk":"11541056233","pt":1719501647787,"mc":[{"id":"1.230178319","rc":[{"atl":[[3.45,3.38]],"id":62766534}],"con":true,"img":false}]}
{"op":"mcm","clk":"11541056244","pt":1719501647891,"mc":[{"id":"1.230178319","rc":[{"atl":[[3.6,1],[3.4,4.42]],"id":62766534},{"atb":[[2.8,2.4]],"id":39959056}],"con":true,"img":false}]}
{"op":"mcm","clk":"11541056254","pt":1719501647994,"mc":[{"id":"1.230178319","rc":[{"atb":[[2.78,1.94]],"id":39959056}],"con":true,"img":false}]}
{"op":"mcm","clk":"11541056262","pt":1719501648098,"mc":[{"id":"1.230178319","rc":[{"atl":[[8.2,1.37]],"id":39959056}],"con":true,"img":false}]}
{"op":"mcm","clk":"11541056267","pt":1719501648189,"mc":[{"id":"1.230178319","rc":[{"atl":[[3.35,0.84]],"id":62766534},{"atb":[[1.04,0.52]],"id":39959056},{"atl":[[8.2,4.78],[8.8,2.5]],"id":39959056}],"con":true,"img":false}]}
{"op":"mcm","clk":"11541056279","pt":1719501648293,"mc":[{"id":"1.230178319","rc":[{"atb":[[1.55,0]],"id":62766534},{"atl":[[8.2,1.37],[8.8,12.5]],"id":39959056},{"atb":[[1.44,0]],"id":40214683},{"atb":[[2.84,1],[2.76,2.5]],"id":69261147},{"atl":[[8,0],[8.6,3.5]],"id":70642246}],"con":true,"img":false}]}
{"op":"mcm","clk":"11541056289","pt":1719501648397,"mc":[{"id":"1.230178319","rc":[{"atb":[[1.04,0.29]],"id":39959056},{"atb":[[2.06,0],[2.08,7.5]],"id":56418091}],"con":true,"img":false}]}
{"op":"mcm","clk":"11541056299","pt":1719501648499,"mc":[{"id":"1.230178319","rc":[{"atb":[[1.04,0]],"id":39959056}],"con":true,"img":false}]}
{"op":"mcm","clk":"11541056307","pt":1719501648603,"mc":[{"id":"1.230178319","rc":[{"atb":[[2.8,2.69]],"id":39959056}],"con":true,"img":false}]}
{"op":"mcm","clk":"11541056361","pt":1719501649349,"mc":[{"id":"1.230178319","rc":[{"atb":[[2.78,0]],"id":39959056},{"atb":[[2.92,0]],"id":69261147}],"con":true,"img":false}]}
{"op":"mcm","clk":"11541056376","pt":1719501649521,"mc":[{"id":"1.230178319","rc":[{"atb":[[2.82,1.94]],"id":39959056},{"atb":[[2.92,1.94]],"id":69261147}],"con":true,"img":false}]}
{"op":"mcm","clk":"11541056388","pt":1719501649986,"mc":[{"id":"1.230178319","rc":[{"atb":[[2.84,0],[2.76,3.5]],"id":69261147}],"con":true,"img":false}]}
{"op":"mcm","clk":"11541056395","pt":1719501650298,"mc":[{"id":"1.230178319","rc":[{"atb":[[1.75,6.79]],"id":62766534},{"atl":[[3.35,5.63]],"id":62766534},{"atb":[[2.82,5.76],[2.84,2.54]],"id":39959056},{"atl":[[8,3.82]],"id":39959056},{"atb":[[1.64,9.3]],"id":40214683},{"atl":[[3,5.19]],"id":40214683},{"atl":[[3.95,5.03]],"id":56418091},{"atb":[[2.94,5.33]],"id":69261147},{"atb":[[2.98,6.48],[2.78,3.07]],"id":70642246}],"con":true,"img":false}]}
{"op":"mcm","clk":"11541056407","pt":1719501650323,"mc":[{"id":"1.230178319","rc":[{"atb":[[1.73,0]],"id":62766534},{"atl":[[3.5,0]],"id":62766534},{"atb":[[2.72,0],[2.7,0]],"id":39959056},{"atl":[[8.4,0]],"id":39959056},{"atl":[[4,0]],"id":56418091},{"atb":[[2.9,5.95]],"id":69261147},{"atb":[[2.78,0]],"id":70642246}],"con":true,"img":false}]}
{"op":"mcm","clk":"11541056413","pt":1719501650651,"mc":[{"id":"1.230178319","rc":[{"atb":[[2.84,3.54]],"id":39959056},{"atb":[[1.62,0]],"id":40214683},{"atl":[[3.1,0]],"id":40214683},{"atb":[[2.94,0]],"id":70642246}],"con":true,"img":false}]}
{"op":"mcm","clk":"11541056435","pt":1719501650703,"mc":[{"id":"1.230178319","rc":[{"atl":[[4,10.08],[4.1,1]],"id":56418091}],"con":true,"img":false}]}
{"op":"mcm","clk":"11541056447","pt":1719501650726,"mc":[{"id":"1.230178319","rc":[{"atl":[[4,0],[4.7,12.48]],"id":56418091}],"con":true,"img":false}]}
{"op":"mcm","clk":"11541056458","pt":1719501650748,"mc":[{"id":"1.230178319","rc":[{"atl":[[4.1,11.08],[4.7,2.5]],"id":56418091}],"con":true,"img":false}]}
{"op":"mcm","clk":"11541056477","pt":1719501650793,"mc":[{"id":"1.230178319","rc":[{"atl":[[3.45,0]],"id":62766534},{"atl":[[7.8,0.84]],"id":39959056},{"atb":[[1.6,5.55]],"id":40214683},{"atl":[[2.98,0.84]],"id":40214683},{"atl":[[4,10.08],[4.1,1]],"id":56418091}],"con":true,"img":false}]}
{"op":"mcm","clk":"11541056488","pt":1719501650897,"mc":[{"id":"1.230178319","rc":[{"atl":[[3.6,0],[3.4,5.42]],"id":62766534},{"atl":[[3.15,0],[3.05,7.84]],"id":40214683},{"atb":[[2.18,7.18]],"id":56418091},{"atl":[[4,0],[4.1,16.12]],"id":56418091}],"con":true,"img":false}]}
{"op":"mcm","clk":"11541056499","pt":1719501650992,"mc":[{"id":"1.230178319","rc":[{"atb":[[1.6,0]],"id":40214683}],"con":true,"img":false}]}
{"op":"mcm","clk":"11541056510","pt":1719501651200,"mc":[{"id":"1.230178319","rc":[{"atb":[[2.9,3.95]],"id":69261147}],"con":true,"img":false}]}
{"op":"mcm","clk":"11541056517","pt":1719501651303,"mc":[{"id":"1.230178319","rc":[{"atb":[[2.96,2]],"id":69261147}],"con":true,"img":false}]}
{"op":"mcm","clk":"11541056531","pt":1719501651407,"mc":[{"id":"1.230178319","rc":[{"atb":[[2.92,9.27]],"id":69261147}],"con":true,"img":false}]}
{"op":"mcm","clk":"11541056542","pt":1719501651508,"mc":[{"id":"1.230178319","rc":[{"atl":[[3.6,1],[3.4,4.42]],"id":62766534},{"atl":[[3.15,1]],"id":40214683},{"atb":[[2.9,0]],"id":69261147},{"atl":[[8,1]],"id":70642246}],"con":true,"img":false}]}
{"op":"mcm","clk":"11541056554","pt":1719501651614,"mc":[{"id":"1.230178319","rc":[{"atl":[[3.05,6.84]],"id":40214683},{"atl":[[8.6,2.5]],"id":70642246}],"con":true,"img":false}]}
{"op":"mcm","clk":"11541056589","pt":1719501651992,"mc":[{"id":"1.230178319","rc":[{"atb":[[1.73,5.66]],"id":62766534},{"atl":[[3.3,2.54]],"id":62766534},{"atb":[[2.78,3.08]],"id":39959056}],"con":true,"img":false}]}
{"op":"mcm","clk":"11541056600","pt":1719501652091,"mc":[{"id":"1.230178319","rc":[{"atl":[[3.05,4.3]],"id":40214683}],"con":true,"img":false}]}
{"op":"mcm","clk":"11541056629","pt":1719501652408,"mc":[{"id":"1.230178319","rc":[{"atb":[[2.82,3.82]],"id":39959056},{"atb":[[2.92,7.33]],"id":69261147},{"atb":[[2.96,4.41]],"id":70642246}],"con":true,"img":false}]}
{"op":"mcm","clk":"11541056646","pt":1719501652609,"mc":[{"id":"1.230178319","rc":[{"atb":[[2.86,1.94]],"id":39959056},{"atb":[[2.96,3.94]],"id":69261147},{"atb":[[3,1.94],[2.84,11.89],[2.96,0]],"id":70642246}],"con":true,"img":false}]}
{"op":"mcm","clk":"11541056655","pt":1719501652713,"mc":[{"id":"1.230178319","rc":[{"atb":[[1.74,0]],"id":62766534},{"atb":[[2.84,2.54],[2.76,0]],"id":39959056},{"atb":[[1.63,0]],"id":40214683},{"atb":[[3,8.42],[2.84,1],[3.05,5.05]],"id":70642246}],"con":true,"img":false}]}
{"op":"mcm","clk":"11541056669","pt":1719501652922,"mc":[{"id":"1.230178319","rc":[{"atb":[[1.76,3.1]],"id":62766534},{"atb":[[2.86,5.04]],"id":39959056},{"atb":[[1.65,4]],"id":40214683},{"atb":[[3,1.94]],"id":70642246}],"con":true,"img":false}]}
{"op":"mcm","clk":"11541056693","pt":1719501653294,"mc":[{"id":"1.230178319","rc":[{"atb":[[1.02,11.23]],"id":70642246}],"con":true,"img":false}]}
{"op":"mcm","clk":"11541056701","pt":1719501653400,"mc":[{"id":"1.230178319","rc":[{"atl":[[3.4,0],[3.3,6.96]],"id":62766534},{"atb":[[3.1,2]],"id":70642246}],"con":true,"img":false}]}
{"op":"mcm","clk":"11541056710","pt":1719501653495,"mc":[{"id":"1.230178319","rc":[{"atl":[[3.4,8.18],[3.3,2.54]],"id":62766534}],"con":true,"img":false}]}
{"op":"mcm","clk":"11541056732","pt":1719501653807,"mc":[{"id":"1.230178319","rc":[{"atl":[[8,7.64],[8.8,2.5]],"id":39959056}],"con":true,"img":false}]}
{"op":"mcm","clk":"11541056742","pt":1719501653910,"mc":[{"id":"1.230178319","rc":[{"atb":[[2.8,0.29]],"id":39959056}],"con":true,"img":false}]}
{"op":"mcm","clk":"11541056797","pt":1719501654586,"mc":[{"id":"1.230178319","rc":[{"atl":[[2.98,3.38]],"id":40214683}],"con":true,"img":false}]}
{"op":"mcm","clk":"11541056803","pt":1719501654687,"mc":[{"id":"1.230178319","rc":[{"atl":[[3,11.97],[3.05,0.84]],"id":40214683}],"con":true,"img":false}]}
{"op":"mcm","clk":"11541056809","pt":1719501654790,"mc":[{"id":"1.230178319","rc":[{"atb":[[2.88,1]],"id":39959056}],"con":true,"img":false}]}
{"op":"mcm","clk":"11541056825","pt":1719501654994,"mc":[{"id":"1.230178319","rc":[{"atb":[[1.64,7.3]],"id":40214683}],"con":true,"img":false}]}
{"op":"mcm","clk":"11541056833","pt":1719501655097,"mc":[{"id":"1.230178319","rc":[{"atb":[[1.66,2]],"id":40214683}],"con":true,"img":false}]}
{"op":"mcm","clk":"11541056843","pt":1719501655199,"mc":[{"id":"1.230178319","rc":[{"atl":[[3.25,0.84]],"id":62766534}],"con":true,"img":false}]}
{"op":"mcm","clk":"11541056851","pt":1719501655304,"mc":[{"id":"1.230178319","rc":[{"atl":[[3.4,0],[3.3,8.18]],"id":62766534},{"atl":[[3.05,0]],"id":40214683}],"con":true,"img":false}]}
{"op":"mcm","clk":"11541056867","pt":1719501655509,"mc":[{"id":"1.230178319","rc":[{"atb":[[1.75,4.79]],"id":62766534},{"atb":[[3,0]],"id":70642246}],"con":true,"img":false}]}
{"op":"mcm","clk":"11541056876","pt":1719501655613,"mc":[{"id":"1.230178319","rc":[{"atb":[[1.77,2]],"id":62766534}],"con":true,"img":false}]}
{"op":"mcm","clk":"11541056882","pt":1719501655716,"mc":[{"id":"1.230178319","rc":[{"atb":[[3.1,3.94]],"id":70642246}],"con":true,"img":false}]}
{"op":"mcm","clk":"11541056981","pt":1719501656912,"mc":[{"id":"1.230178319","rc":[{"atb":[[1.33,0]],"id":40214683}],"con":true,"img":false}]}
{"op":"mcm","clk":"11541057056","pt":1719501657800,"mc":[{"id":"1.230178319","rc":[{"atb":[[1.68,8.71]],"id":40214683}],"con":true,"img":false}]}
{"op":"mcm","clk":"11541057087","pt":1719501658209,"mc":[{"id":"1.230178319","rc":[{"atb":[[2.98,0],[3.15,5.05]],"id":70642246}],"con":true,"img":false}]}
{"op":"mcm","clk":"11541057114","pt":1719501658521,"mc":[{"id":"1.230178319","rc":[{"atb":[[1.66,0]],"id":40214683},{"atb":[[3.1,2]],"id":70642246}],"con":true,"img":false}]}
{"op":"mcm","clk":"11541057125","pt":1719501658625,"mc":[{"id":"1.230178319","rc":[{"atb":[[3.1,12.1]],"id":70642246}],"con":true,"img":false}]}
{"op":"mcm","clk":"11541057134","pt":1719501658728,"mc":[{"id":"1.230178319","rc":[{"atb":[[1.69,2]],"id":40214683},{"atb":[[3.2,1.94],[3.15,0]],"id":70642246}],"con":true,"img":false}]}
{"op":"mcm","clk":"11541057155","pt":1719501659099,"mc":[{"id":"1.230178319","rc":[{"atb":[[1.64,5.19],[1.71,2.11]],"id":40214683},{"atb":[[2.24,2.11],[2.12,0]],"id":56418091}],"con":true,"img":false}]}
{"op":"mcm","clk":"11541057164","pt":1719501659201,"mc":[{"id":"1.230178319","rc":[{"atb":[[2.24,9.67]],"id":56418091},{"atl":[[4.7,23.66]],"id":56418091}],"con":true,"img":false}]}
{"op":"mcm","clk":"11541057170","pt":1719501659306,"mc":[{"id":"1.230178319","rc":[{"atl":[[4.1,1]],"id":56418091}],"con":true,"img":false}]}
{"op":"mcm","clk":"11541057178","pt":1719501659404,"mc":[{"id":"1.230178319","rc":[{"atb":[[2.2,1.94]],"id":56418091}],"con":true,"img":false}]}
{"op":"mcm","clk":"11541057185","pt":1719501659508,"mc":[{"id":"1.230178319","rc":[{"atb":[[2.88,3]],"id":39959056}],"con":true,"img":false}]}
{"op":"mcm","clk":"11541057201","pt":1719501659822,"mc":[{"id":"1.230178319","rc":[{"atb":[[1.69,0]],"id":40214683}],"con":true,"img":false}]}
{"op":"mcm","clk":"11541057208","pt":1719501659924,"mc":[{"id":"1.230178319","rc":[{"atb":[[1.72,2]],"id":40214683}],"con":true,"img":false}]}
{"op":"mcm","clk":"11541057223","pt":1719501660132,"mc":[{"id":"1.230178319","rc":[{"atb":[[2.18,2.5]],"id":56418091}],"con":true,"img":false}]}
{"op":"mcm","clk":"11541057230","pt":1719501660196,"mc":[{"id":"1.230178319","rc":[{"atb":[[3.1,10.1]],"id":70642246}],"con":true,"img":false}]}
{"op":"mcm","clk":"11541057238","pt":1719501660298,"mc":[{"id":"1.230178319","rc":[{"atb":[[1.02,13.23]],"id":70642246}],"con":true,"img":false}]}
{"op":"mcm","clk":"11541057337","pt":1719501661433,"mc":[{"id":"1.230178319","rc":[{"atb":[[1.76,0]],"id":62766534},{"atb":[[2.86,1.94]],"id":39959056},{"atb":[[1.65,0]],"id":40214683}],"con":true,"img":false}]}
{"op":"mcm","clk":"11541057345","pt":1719501661538,"mc":[{"id":"1.230178319","rc":[{"atb":[[1.77,5.36]],"id":62766534},{"atl":[[3.25,8.66]],"id":62766534},{"atb":[[2.88,6.37],[2.86,0],[2.9,4.24]],"id":39959056},{"atb":[[1.72,8.84]],"id":40214683},{"atl":[[2.96,4.13]],"id":40214683},{"atb":[[2.2,0]],"id":56418091},{"atb":[[3.2,0],[3.25,5.05]],"id":70642246}],"con":true,"img":false}]}
{"op":"mcm","clk":"11541057353","pt":1719501661599,"mc":[{"id":"1.230178319","rc":[{"atb":[[1.77,13.18]],"id":62766534},{"atl":[[3.35,0.84]],"id":62766534},{"atb":[[2.82,0],[2.84,0],[2.88,5.37],[2.9,6.18]],"id":39959056},{"atl":[[7.8,4.21]],"id":39959056},{"atb":[[1.64,0]],"id":40214683},{"atl":[[3,6.78]],"id":40214683},{"atb":[[2.98,7.87]],"id":69261147},{"atb":[[3.25,0],[3.15,1.94],[3.05,0]],"id":70642246}],"con":true,"img":false}]}
{"op":"mcm","clk":"11541057362","pt":1719501661703,"mc":[{"id":"1.230178319","rc":[{"atb":[[2.94,0]],"id":69261147},{"atb":[[3.15,8.9]],"id":70642246}],"con":true,"img":false}]}
{"op":"mcm","clk":"11541057368","pt":1719501661797,"mc":[{"id":"1.230178319","rc":[{"atb":[[1.75,0]],"id":62766534},{"atl":[[8,3.82]],"id":39959056}],"con":true,"img":false}]}
{"op":"mcm","clk":"11541057392","pt":1719501662007,"mc":[{"id":"1.230178319","rc":[{"atb":[[1.73,0]],"id":62766534},{"atb":[[2.78,0]],"id":39959056}],"con":true,"img":false}]}
{"op":"mcm","clk":"11541057408","pt":1719501662214,"mc":[{"id":"1.230178319","rc":[{"atl":[[3.35,0]],"id":62766534},{"atl":[[8.2,0.52]],"id":39959056},{"atl":[[2.94,0.84]],"id":40214683},{"atb":[[2.96,1.94]],"id":69261147}],"con":true,"img":false}]}
{"op":"mcm","clk":"11541057419","pt":1719501662319,"mc":[{"id":"1.230178319","rc":[{"atl":[[8,0],[8.2,8.56]],"id":39959056},{"atb":[[3,2]],"id":69261147}],"con":true,"img":false}]}
{"op":"mcm","clk":"11541057452","pt":1719501662636,"mc":[{"id":"1.230178319","rc":[{"atl":[[5.2,0]],"id":56418091}],"con":true,"img":false}]}
{"op":"mcm","clk":"11541057512","pt":1719501663210,"mc":[{"id":"1.230178319","rc":[{"atl":[[3.3,5.64]],"id":62766534},{"atl":[[2.98,0.84]],"id":40214683}],"con":true,"img":false}]}
{"op":"mcm","clk":"11541057525","pt":1719501663317,"mc":[{"id":"1.230178319","rc":[{"atl":[[3.6,15.31],[3.3,0]],"id":62766534}],"con":true,"img":false}]}
{"op":"mcm","clk":"11541057558","pt":1719501663628,"mc":[{"id":"1.230178319","rc":[{"atl":[[8.2,8.04]],"id":39959056}],"con":true,"img":false}]}
{"op":"mcm","clk":"11541057571","pt":1719501663733,"mc":[{"id":"1.230178319","rc":[{"atb":[[2.92,1]],"id":39959056},{"atl":[[8.2,0],[8.8,14.76]],"id":39959056}],"con":true,"img":false}]}
{"op":"mcm","clk":"11541057615","pt":1719501664109,"mc":[{"id":"1.230178319","rc":[{"atb":[[2.8,0]],"id":39959056}],"con":true,"img":false}]}
{"op":"mcm","clk":"11541057649","pt":1719501664512,"mc":[{"id":"1.230178319","rc":[{"atb":[[2.96,0]],"id":69261147}],"con":true,"img":false}]}
{"op":"mcm","clk":"11541057666","pt":1719501664718,"mc":[{"id":"1.230178319","rc":[{"atb":[[3,3.94]],"id":69261147}],"con":true,"img":false}]}
{"op":"mcm","clk":"11541057724","pt":1719501665442,"mc":[{"id":"1.230178319","rc":[{"atl":[[7.6,0.52]],"id":39959056}],"con":true,"img":false}]}
{"op":"mcm","clk":"11541057735","pt":1719501665502,"mc":[{"id":"1.230178319","rc":[{"atb":[[1.04,0.52]],"id":39959056},{"atb":[[1.56,0]],"id":40214683}],"con":true,"img":false}]}
{"op":"mcm","clk":"11541057741","pt":1719501665608,"mc":[{"id":"1.230178319","rc":[{"atb":[[2.88,3.37]],"id":39959056}],"con":true,"img":false}]}
{"op":"mcm","clk":"11541057751","pt":1719501665714,"mc":[{"id":"1.230178319","rc":[{"atl":[[4.5,0]],"id":62766534},{"atl":[[2.94,3.38]],"id":40214683}],"con":true,"img":false}]}
{"op":"mcm","clk":"11541057760","pt":1719501665806,"mc":[{"id":"1.230178319","rc":[{"atb":[[1.04,0.27]],"id":39959056}],"con":true,"img":false}]}
{"op":"mcm","clk":"11541057778","pt":1719501666022,"mc":[{"id":"1.230178319","rc":[{"atb":[[1.04,0]],"id":39959056},{"atb":[[1.76,7.28]],"id":40214683}],"con":true,"img":false}]}
{"op":"mcm","clk":"11541057788","pt":1719501666116,"mc":[{"id":"1.230178319","rc":[{"atb":[[2.94,0.27]],"id":39959056}],"con":true,"img":false}]}
{"op":"mcm","clk":"11541057809","pt":1719501666322,"mc":[{"id":"1.230178319","rc":[{"atb":[[2.92,0]],"id":39959056},{"atl":[[2.98,0]],"id":40214683}],"con":true,"img":false}]}
{"op":"mcm","clk":"11541057853","pt":1719501666902,"mc":[{"id":"1.230178319","rc":[{"atb":[[1.72,6.84]],"id":40214683}],"con":true,"img":false}]}
{"op":"mcm","clk":"11541057859","pt":1719501667007,"mc":[{"id":"1.230178319","rc":[{"atb":[[1.77,2]],"id":40214683}],"con":true,"img":false}]}
{"op":"mcm","clk":"11541057990","pt":1719501668423,"mc":[{"id":"1.230178319","rc":[{"atl":[[4.4,26.48]],"id":62766534}],"con":true,"img":false}]}
{"op":"mcm","clk":"11541058003","pt":1719501668528,"mc":[{"id":"1.230178319","rc":[{"atl":[[3.6,1]],"id":62766534},{"atb":[[2.96,1]],"id":39959056}],"con":true,"img":false}]}
{"op":"mcm","clk":"11541058130","pt":1719501670036,"mc":[{"id":"1.230178319","rc":[{"atb":[[1.77,9.82]],"id":62766534},{"atb":[[2.9,4.18]],"id":39959056},{"atb":[[1.72,4.13]],"id":40214683}],"con":true,"img":false}]}
{"op":"mcm","clk":"11541058139","pt":1719501670141,"mc":[{"id":"1.230178319","rc":[{"atb":[[1.78,3.64]],"id":62766534},{"atb":[[2.96,3.88]],"id":39959056},{"atb":[[1.77,5.35]],"id":40214683}],"con":true,"img":false}]}
{"op":"mcm","clk":"11541058176","pt":1719501670526,"mc":[{"id":"1.230178319","rc":[{"atb":[[2.9,2.24]],"id":39959056}],"con":true,"img":false}]}
{"op":"mcm","clk":"11541058194","pt":1719501670716,"mc":[{"id":"1.230178319","rc":[{"atb":[[2.98,1.94]],"id":39959056}],"con":true,"img":false}]}
{"op":"mcm","clk":"11541058215","pt":1719501670925,"mc":[{"id":"1.230178319","rc":[{"atb":[[1.77,7.82]],"id":62766534},{"atb":[[3,2.12],[2.96,2.88]],"id":39959056}],"con":true,"img":false}]}
{"op":"mcm","clk":"11541058225","pt":1719501671029,"mc":[{"id":"1.230178319","rc":[{"atb":[[1.79,2]],"id":62766534}],"con":true,"img":false}]}
{"op":"mcm","clk":"11541058391","pt":1719501673020,"mc":[{"id":"1.230178319","rc":[{"spn":2.52,"spf":"NaN","id":62766534},{"atb":[[3,5.87],[3.05,2.5]],"id":39959056},{"spn":3.05,"spf":1.0,"id":39959056},{"atb":[[1.77,12.46]],"id":40214683},{"atl":[[2.92,7.11]],"id":40214683},{"spn":2.34,"spf":"NaN","id":40214683},{"spn":3.09,"spf":"NaN","id":56418091},{"spn":5.4,"spf":"NaN","id":69261147},{"spn":5.47,"spf":"NaN","id":70642246}],"con":true,"img":false}]}
{"op":"mcm","clk":"11541058401","pt":1719501673128,"mc":[{"id":"1.230178319","rc":[{"atb":[[1.79,10.6]],"id":62766534},{"atb":[[3.1,1]],"id":39959056},{"atl":[[7.6,4.27]],"id":39959056},{"atl":[[2.96,0]],"id":40214683},{"atb":[[3.05,9.37]],"id":69261147}],"con":true,"img":false}]}
