{"op":"mcm","clk":"11536832972","pt":1719431775488,"mc":[{"id":"1.230180124","marketDefinition":{"bspMarket":true,"turnInPlayEnabled":false,"persistenceEnabled":false,"marketBaseRate":5.0,"eventId":"33376437","eventTypeId":"4339","numberOfWinners":1,"bettingType":"ODDS","marketType":"WIN","marketTime":"2024-06-27T15:26:00.000Z","suspendTime":"2024-06-27T15:26:00.000Z","bspReconciled":false,"complete":true,"inPlay":false,"crossMatching":false,"runnersVoidable":false,"numberOfActiveRunners":6,"betDelay":0,"status":"OPEN","runners":[{"status":"ACTIVE","sortPriority":1,"id":42767337,"name":"1. Salacres Liam"},{"status":"ACTIVE","sortPriority":2,"id":56263473,"name":"2. Makeit Spot"},{"status":"ACTIVE","sortPriority":3,"id":67245400,"name":"3. Lillibeth Royale"},{"status":"ACTIVE","sortPriority":4,"id":65992794,"name":"4. Come Back Kid"},{"status":"ACTIVE","sortPriority":5,"id":70902709,"name":"5. Cloud Canine"},{"status":"ACTIVE","sortPriority":6,"id":51567147,"name":"6. Coolemore North"}],"regulators":["MR_INT"],"venue":"Towcester","countryCode":"GB","discountAllowed":false,"timezone":"Europe/London","openDate":"2024-06-27T13:33:00.000Z","version":5994767056,"name":"A4 500m","eventName":"Towcester 27th Jun"},"rc":[],"con":true,"img":false}]}
{"op":"mcm","clk":"11536833123","pt":1719431777502,"mc":[{"id":"1.230180124","marketDefinition":{"bspMarket":true,"turnInPlayEnabled":false,"persistenceEnabled":false,"marketBaseRate":5.0,"eventId":"33376437","eventTypeId":"4339","numberOfWinners":1,"bettingType":"ODDS","marketType":"WIN","marketTime":"2024-06-27T15:26:00.000Z","suspendTime":"2024-06-27T15:26:00.000Z","bspReconciled":false,"complete":true,"inPlay":false,"crossMatching":false,"runnersVoidable":false,"numberOfActiveRunners":6,"betDelay":0,"status":"OPEN","runners":[{"status":"ACTIVE","sortPriority":1,"id":42767337,"name":"1. Salacres Liam"},{"status":"ACTIVE","sortPriority":2,"id":56263473,"name":"2. Makeit Spot"},{"status":"ACTIVE","sortPriority":3,"id":67245400,"name":"3. Lillibeth Royale"},{"status":"ACTIVE","sortPriority":4,"id":65992794,"name":"4. Come Back Kid"},{"status":"ACTIVE","sortPriority":5,"id":70902709,"name":"5. Cloud Canine"},{"status":"ACTIVE","sortPriority":6,"id":51567147,"name":"6. Coolemore North"}],"regulators":["MR_INT"],"venue":"Towcester","countryCode":"GB","discountAllowed":true,"timezone":"Europe/London","openDate":"2024-06-27T13:33:00.000Z","version":5994767056,"name":"A4 500m","eventName":"Towcester 27th Jun"},"rc":[],"con":true,"img":false}]}
{"op":"mcm","clk":"11537083953","pt":1719435434598,"mc":[{"id":"1.230180124","rc":[{"atb":[[1.03,17.28]],"id":56263473},{"atl":[[1000,0.84]],"id":56263473},{"spn":500.51,"spf":"NaN","id":56263473},{"atb":[[1.03,17.28]],"id":65992794},{"atl":[[990,0.84]],"id":65992794},{"spn":495.51,"spf":"NaN","id":65992794},{"atb":[[1.01,51.84]],"id":67245400},{"atl":[[1000,0.84]],"id":67245400},{"spn":500.5,"spf":"NaN","id":67245400},{"atb":[[1.03,17.28]],"id":42767337},{"atl":[[1000,0.84]],"id":42767337},{"spn":500.51,"spf":"NaN","id":42767337},{"atb":[[1.01,51.84]],"id":51567147},{"atl":[[990,0.84]],"id":51567147},{"spn":495.5,"spf":"NaN","id":51567147},{"atb":[[1.01,51.84]],"id":70902709},{"atl":[[1000,0.84]],"id":70902709},{"spn":500.5,"spf":"NaN","id":70902709}],"con":true,"img":false}]}
{"op":"mcm","clk":"11537233732","pt":1719437882653,"mc":[{"id":"1.230180124","marketDefinition":{"bspMarket":true,"turnInPlayEnabled":false,"persistenceEnabled":false,"marketBaseRate":5.0,"eventId":"33376437","eventTypeId":"4339","numberOfWinners":1,"bettingType":"ODDS","marketType":"WIN","marketTime":"2024-06-27T15:26:00.000Z","suspendTime":"2024-06-27T15:26:00.000Z","bspReconciled":false,"complete":true,"inPlay":false,"crossMatching":false,"runnersVoidable":false,"numberOfActiveRunners":6,"betDelay":0,"status":"OPEN","runners":[{"status":"ACTIVE","sortPriority":1,"id":42767337,"name":"1. Salacres Liam"},{"status":"ACTIVE","sortPriority":2,"id":56263473,"name":"2. Makeit Spot"},{"status":"ACTIVE","sortPriority":3,"id":67245400,"name":"3. Lillibeth Royale"},{"status":"ACTIVE","sortPriority":4,"id":65992794,"name":"4. Come Back Kid"},{"status":"ACTIVE","sortPriority":5,"id":70902709,"name":"5. Cloud Canine"},{"status":"ACTIVE","sortPriority":6,"id":51567147,"name":"6. Coolemore North"}],"regulators":["MR_INT"],"venue":"Towcester","countryCode":"GB","discountAllowed":true,"timezone":"Europe/London","openDate":"2024-06-27T13:33:00.000Z","version":5994767056,"name":"A4 500m","eventName":"Towcester 27th Jun"},"rc":[{"atb":[[1.03,17.28]],"id":56263473},{"atl":[[1000,0.84]],"id":56263473},{"spn":500.51,"spf":"NaN","id":56263473},{"atb":[[1.03,17.28]],"id":65992794},{"atl":[[990,0.84]],"id":65992794},{"spn":495.51,"spf":"NaN","id":65992794},{"atb":[[1.01,51.85]],"id":67245400},{"atl":[[1000,0.84]],"id":67245400},{"spn":500.5,"spf":"NaN","id":67245400},{"atb":[[1.03,17.28]],"id":42767337},{"atl":[[1000,0.84]],"id":42767337},{"spn":500.51,"spf":"NaN","id":42767337},{"atb":[[1.01,51.85]],"id":51567147},{"atl":[[990,0.84]],"id":51567147},{"spn":495.5,"spf":"NaN","id":51567147},{"atb":[[1.01,51.85]],"id":70902709},{"atl":[[1000,0.84]],"id":70902709},{"spn":500.5,"spf":"NaN","id":70902709}],"con":true,"img":true}]}
{"op":"mcm","clk":"11537302482","pt":1719439038033,"mc":[{"id":"1.230180124","rc":[{"atb":[[1.03,17.28]],"id":56263473},{"atl":[[1000,0.23]],"id":56263473},{"atb":[[1.03,17.28]],"id":65992794},{"atl":[[990,0.23]],"id":65992794},{"atb":[[1.01,51.85]],"id":67245400},{"atl":[[1000,0.23]],"id":67245400},{"atb":[[1.03,17.28]],"id":42767337},{"atl":[[1000,0.23]],"id":42767337},{"atb":[[1.01,51.85]],"id":51567147},{"atl":[[990,0.23]],"id":51567147},{"atb":[[1.01,51.85]],"id":70902709},{"atl":[[1000,0.23]],"id":70902709}],"con":true,"img":false}]}
{"op":"mcm","clk":"11537574883","pt":1719443282704,"mc":[{"id":"1.230180124","marketDefinition":{"bspMarket":true,"turnInPlayEnabled":false,"persistenceEnabled":false,"marketBaseRate":5.0,"eventId":"33376437","eventTypeId":"4339","numberOfWinners":1,"bettingType":"ODDS","marketType":"WIN","marketTime":"2024-06-27T15:26:00.000Z","suspendTime":"2024-06-27T15:26:00.000Z","bspReconciled":false,"complete":true,"inPlay":false,"crossMatching":false,"runnersVoidable":false,"numberOfActiveRunners":6,"betDelay":0,"status":"OPEN","runners":[{"status":"ACTIVE","sortPriority":1,"id":42767337,"name":"1. Salacres Liam"},{"status":"ACTIVE","sortPriority":2,"id":56263473,"name":"2. Makeit Spot"},{"status":"ACTIVE","sortPriority":3,"id":67245400,"name":"3. Lillibeth Royale"},{"status":"ACTIVE","sortPriority":4,"id":65992794,"name":"4. Come Back Kid"},{"status":"ACTIVE","sortPriority":5,"id":70902709,"name":"5. Cloud Canine"},{"status":"ACTIVE","sortPriority":6,"id":51567147,"name":"6. Coolemore North"}],"regulators":["MR_INT"],"venue":"Towcester","countryCode":"GB","discountAllowed":true,"timezone":"Europe/London","openDate":"2024-06-27T13:33:00.000Z","version":5994767056,"name":"A4 500m","eventName":"Towcester 27th Jun"},"rc":[{"atb":[[1.03,17.28]],"id":56263473},{"atl":[[1000,0.23]],"id":56263473},{"spn":500.51,"spf":"NaN","id":56263473},{"atb":[[1.03,17.28]],"id":65992794},{"atl":[[990,0.23]],"id":65992794},{"spn":495.51,"spf":"NaN","id":65992794},{"atb":[[1.01,51.85]],"id":67245400},{"atl":[[1000,0.23]],"id":67245400},{"spn":500.5,"spf":"NaN","id":67245400},{"atb":[[1.03,17.28]],"id":42767337},{"atl":[[1000,0.23]],"id":42767337},{"spn":500.51,"spf":"NaN","id":42767337},{"atb":[[1.01,51.85]],"id":51567147},{"atl":[[990,0.23]],"id":51567147},{"spn":495.5,"spf":"NaN","id":51567147},{"atb":[[1.01,51.85]],"id":70902709},{"atl":[[1000,0.23]],"id":70902709},{"spn":500.5,"spf":"NaN","id":70902709}],"con":true,"img":true}]}
{"op":"mcm","clk":"11537956503","pt":1719448682745,"mc":[{"id":"1.230180124","marketDefinition":{"bspMarket":true,"turnInPlayEnabled":false,"persistenceEnabled":false,"marketBaseRate":5.0,"eventId":"33376437","eventTypeId":"4339","numberOfWinners":1,"bettingType":"ODDS","marketType":"WIN","marketTime":"2024-06-27T15:26:00.000Z","suspendTime":"2024-06-27T15:26:00.000Z","bspReconciled":false,"complete":true,"inPlay":false,"crossMatching":false,"runnersVoidable":false,"numberOfActiveRunners":6,"betDelay":0,"status":"OPEN","runners":[{"status":"ACTIVE","sortPriority":1,"id":42767337,"name":"1. Salacres Liam"},{"status":"ACTIVE","sortPriority":2,"id":56263473,"name":"2. Makeit Spot"},{"status":"ACTIVE","sortPriority":3,"id":67245400,"name":"3. Lillibeth Royale"},{"status":"ACTIVE","sortPriority":4,"id":65992794,"name":"4. Come Back Kid"},{"status":"ACTIVE","sortPriority":5,"id":70902709,"name":"5. Cloud Canine"},{"status":"ACTIVE","sortPriority":6,"id":51567147,"name":"6. Coolemore North"}],"regulators":["MR_INT"],"venue":"Towcester","countryCode":"GB","discountAllowed":true,"timezone":"Europe/London","openDate":"2024-06-27T13:33:00.000Z","version":5994767056,"name":"A4 500m","eventName":"Towcester 27th Jun"},"rc":[{"atb":[[1.03,17.28]],"id":56263473},{"atl":[[1000,0.23]],"id":56263473},{"spn":500.51,"spf":"NaN","id":56263473},{"atb":[[1.03,17.28]],"id":65992794},{"atl":[[990,0.23]],"id":65992794},{"spn":495.51,"spf":"NaN","id":65992794},{"atb":[[1.01,51.85]],"id":67245400},{"atl":[[1000,0.23]],"id":67245400},{"spn":500.5,"spf":"NaN","id":67245400},{"atb":[[1.03,17.28]],"id":42767337},{"atl":[[1000,0.23]],"id":42767337},{"spn":500.51,"spf":"NaN","id":42767337},{"atb":[[1.01,51.85]],"id":51567147},{"atl":[[990,0.23]],"id":51567147},{"spn":495.5,"spf":"NaN","id":51567147},{"atb":[[1.01,51.85]],"id":70902709},{"atl":[[1000,0.23]],"id":70902709},{"spn":500.5,"spf":"NaN","id":70902709}],"con":true,"img":true}]}
{"op":"mcm","clk":"11538172120","pt":1719454082688,"mc":[{"id":"1.230180124","marketDefinition":{"bspMarket":true,"turnInPlayEnabled":false,"persistenceEnabled":false,"marketBaseRate":5.0,"eventId":"33376437","eventTypeId":"4339","numberOfWinners":1,"bettingType":"ODDS","marketType":"WIN","marketTime":"2024-06-27T15:26:00.000Z","suspendTime":"2024-06-27T15:26:00.000Z","bspReconciled":false,"complete":true,"inPlay":false,"crossMatching":false,"runnersVoidable":false,"numberOfActiveRunners":6,"betDelay":0,"status":"OPEN","runners":[{"status":"ACTIVE","sortPriority":1,"id":42767337,"name":"1. Salacres Liam"},{"status":"ACTIVE","sortPriority":2,"id":56263473,"name":"2. Makeit Spot"},{"status":"ACTIVE","sortPriority":3,"id":67245400,"name":"3. Lillibeth Royale"},{"status":"ACTIVE","sortPriority":4,"id":65992794,"name":"4. Come Back Kid"},{"status":"ACTIVE","sortPriority":5,"id":70902709,"name":"5. Cloud Canine"},{"status":"ACTIVE","sortPriority":6,"id":51567147,"name":"6. Coolemore North"}],"regulators":["MR_INT"],"venue":"Towcester","countryCode":"GB","discountAllowed":true,"timezone":"Europe/London","openDate":"2024-06-27T13:33:00.000Z","version":5994767056,"name":"A4 500m","eventName":"Towcester 27th Jun"},"rc":[{"atb":[[1.03,17.29]],"id":56263473},{"atl":[[1000,0.23]],"id":56263473},{"spn":500.51,"spf":"NaN","id":56263473},{"atb":[[1.03,17.29]],"id":65992794},{"atl":[[990,0.23]],"id":65992794},{"spn":495.51,"spf":"NaN","id":65992794},{"atb":[[1.01,51.86]],"id":67245400},{"atl":[[1000,0.23]],"id":67245400},{"spn":500.5,"spf":"NaN","id":67245400},{"atb":[[1.03,17.29]],"id":42767337},{"atl":[[1000,0.23]],"id":42767337},{"spn":500.51,"spf":"NaN","id":42767337},{"atb":[[1.01,51.86]],"id":51567147},{"atl":[[990,0.23]],"id":51567147},{"spn":495.5,"spf":"NaN","id":51567147},{"atb":[[1.01,51.86]],"id":70902709},{"atl":[[1000,0.23]],"id":70902709},{"spn":500.5,"spf":"NaN","id":70902709}],"con":true,"img":true}]}
{"op":"mcm","clk":"11538369787","pt":1719459482773,"mc":[{"id":"1.230180124","marketDefinition":{"bspMarket":true,"turnInPlayEnabled":false,"persistenceEnabled":false,"marketBaseRate":5.0,"eventId":"33376437","eventTypeId":"4339","numberOfWinners":1,"bettingType":"ODDS","marketType":"WIN","marketTime":"2024-06-27T15:26:00.000Z","suspendTime":"2024-06-27T15:26:00.000Z","bspReconciled":false,"complete":true,"inPlay":false,"crossMatching":false,"runnersVoidable":false,"numberOfActiveRunners":6,"betDelay":0,"status":"OPEN","runners":[{"status":"ACTIVE","sortPriority":1,"id":42767337,"name":"1. Salacres Liam"},{"status":"ACTIVE","sortPriority":2,"id":56263473,"name":"2. Makeit Spot"},{"status":"ACTIVE","sortPriority":3,"id":67245400,"name":"3. Lillibeth Royale"},{"status":"ACTIVE","sortPriority":4,"id":65992794,"name":"4. Come Back Kid"},{"status":"ACTIVE","sortPriority":5,"id":70902709,"name":"5. Cloud Canine"},{"status":"ACTIVE","sortPriority":6,"id":51567147,"name":"6. Coolemore North"}],"regulators":["MR_INT"],"venue":"Towcester","countryCode":"GB","discountAllowed":true,"timezone":"Europe/London","openDate":"2024-06-27T13:33:00.000Z","version":5994767056,"name":"A4 500m","eventName":"Towcester 27th Jun"},"rc":[{"atb":[[1.03,17.29]],"id":56263473},{"atl":[[1000,0.23]],"id":56263473},{"spn":500.51,"spf":"NaN","id":56263473},{"atb":[[1.03,17.29]],"id":65992794},{"atl":[[990,0.23]],"id":65992794},{"spn":495.51,"spf":"NaN","id":65992794},{"atb":[[1.01,51.87]],"id":67245400},{"atl":[[1000,0.23]],"id":67245400},{"spn":500.5,"spf":"NaN","id":67245400},{"atb":[[1.03,17.29]],"id":42767337},{"atl":[[1000,0.23]],"id":42767337},{"spn":500.51,"spf":"NaN","id":42767337},{"atb":[[1.01,51.87]],"id":51567147},{"atl":[[990,0.23]],"id":51567147},{"spn":495.5,"spf":"NaN","id":51567147},{"atb":[[1.01,51.87]],"id":70902709},{"atl":[[1000,0.23]],"id":70902709},{"spn":500.5,"spf":"NaN","id":70902709}],"con":true,"img":true}]}
{"op":"mcm","clk":"11538596917","pt":1719464882717,"mc":[{"id":"1.230180124","marketDefinition":{"bspMarket":true,"turnInPlayEnabled":false,"persistenceEnabled":false,"marketBaseRate":5.0,"eventId":"33376437","eventTypeId":"4339","numberOfWinners":1,"bettingType":"ODDS","marketType":"WIN","marketTime":"2024-06-27T15:26:00.000Z","suspendTime":"2024-06-27T15:26:00.000Z","bspReconciled":false,"complete":true,"inPlay":false,"crossMatching":false,"runnersVoidable":false,"numberOfActiveRunners":6,"betDelay":0,"status":"OPEN","runners":[{"status":"ACTIVE","sortPriority":1,"id":42767337,"name":"1. Salacres Liam"},{"status":"ACTIVE","sortPriority":2,"id":56263473,"name":"2. Makeit Spot"},{"status":"ACTIVE","sortPriority":3,"id":67245400,"name":"3. Lillibeth Royale"},{"status":"ACTIVE","sortPriority":4,"id":65992794,"name":"4. Come Back Kid"},{"status":"ACTIVE","sortPriority":5,"id":70902709,"name":"5. Cloud Canine"},{"status":"ACTIVE","sortPriority":6,"id":51567147,"name":"6. Coolemore North"}],"regulators":["MR_INT"],"venue":"Towcester","countryCode":"GB","discountAllowed":true,"timezone":"Europe/London","openDate":"2024-06-27T13:33:00.000Z","version":5994767056,"name":"A4 500m","eventName":"Towcester 27th Jun"},"rc":[{"atb":[[1.03,17.29]],"id":56263473},{"atl":[[1000,0.23]],"id":56263473},{"spn":500.51,"spf":"NaN","id":56263473},{"atb":[[1.03,17.29]],"id":65992794},{"atl":[[990,0.23]],"id":65992794},{"spn":495.51,"spf":"NaN","id":65992794},{"atb":[[1.01,51.86]],"id":67245400},{"atl":[[1000,0.23]],"id":67245400},{"spn":500.5,"spf":"NaN","id":67245400},{"atb":[[1.03,17.29]],"id":42767337},{"atl":[[1000,0.23]],"id":42767337},{"spn":500.51,"spf":"NaN","id":42767337},{"atb":[[1.01,51.86]],"id":51567147},{"atl":[[990,0.23]],"id":51567147},{"spn":495.5,"spf":"NaN","id":51567147},{"atb":[[1.01,51.86]],"id":70902709},{"atl":[[1000,0.23]],"id":70902709},{"spn":500.5,"spf":"NaN","id":70902709}],"con":true,"img":true}]}
{"op":"mcm","clk":"11538748650","pt":1719468205372,"mc":[{"id":"1.230180124","rc":[{"atb":[[2.02,10.35],[1.03,17.29]],"id":56263473},{"spn":501.01,"spf":"NaN","id":56263473},{"atb":[[1.03,17.29],[2.08,8.88]],"id":65992794},{"spn":496.04,"spf":"NaN","id":65992794},{"atb":[[2,8.54],[1.01,51.86]],"id":67245400},{"spn":501.0,"spf":"NaN","id":67245400},{"atb":[[2,12.82],[1.03,17.29]],"id":42767337},{"spn":501.0,"spf":"NaN","id":42767337},{"atb":[[1.01,51.86],[2.02,8.63]],"id":51567147},{"spn":496.01,"spf":"NaN","id":51567147},{"atb":[[1.01,51.86],[2.08,9.77]],"id":70902709},{"spn":501.04,"spf":"NaN","id":70902709}],"con":true,"img":false}]}
{"op":"mcm","clk":"11538750679","pt":1719468247669,"mc":[{"id":"1.230180124","rc":[{"atb":[[2.04,3.16]],"id":56263473}],"con":true,"img":false}]}
{"op":"mcm","clk":"11538750695","pt":1719468247873,"mc":[{"id":"1.230180124","rc":[{"atb":[[2.02,3.16]],"id":42767337}],"con":true,"img":false}]}
{"op":"mcm","clk":"11538750723","pt":1719468248438,"mc":[{"id":"1.230180124","rc":[{"atb":[[2.1,3.16]],"id":70902709}],"con":true,"img":false}]}
{"op":"mcm","clk":"11538750733","pt":1719468248641,"mc":[{"id":"1.230180124","rc":[{"atb":[[2.1,3.16]],"id":65992794}],"con":true,"img":false}]}
{"op":"mcm","clk":"11538750749","pt":1719468249047,"mc":[{"id":"1.230180124","rc":[{"atb":[[2.04,3.16]],"id":51567147}],"con":true,"img":false}]}
{"op":"mcm","clk":"11538750766","pt":1719468249453,"mc":[{"id":"1.230180124","rc":[{"atb":[[2.02,3.16]],"id":67245400}],"con":true,"img":false}]}
{"op":"mcm","clk":"11538752698","pt":1719468287532,"mc":[{"id":"1.230180124","rc":[{"spn":501.02,"spf":"NaN","id":56263473},{"spn":496.05,"spf":"NaN","id":65992794},{"spn":501.01,"spf":"NaN","id":67245400},{"atb":[[2.02,6.55]],"id":42767337},{"spn":501.01,"spf":"NaN","id":42767337},{"spn":496.02,"spf":"NaN","id":51567147},{"spn":501.05,"spf":"NaN","id":70902709}],"con":true,"img":false}]}
{"op":"mcm","clk":"11538752708","pt":1719468287687,"mc":[{"id":"1.230180124","rc":[{"atb":[[2.1,6.55]],"id":65992794}],"con":true,"img":false}]}
{"op":"mcm","clk":"11538752746","pt":1719468288405,"mc":[{"id":"1.230180124","rc":[{"atb":[[2.02,6.55]],"id":67245400}],"con":true,"img":false}]}
{"op":"mcm","clk":"11538752760","pt":1719468288612,"mc":[{"id":"1.230180124","rc":[{"atb":[[2.04,6.55]],"id":51567147}],"con":true,"img":false}]}
{"op":"mcm","clk":"11538752794","pt":1719468289225,"mc":[{"id":"1.230180124","rc":[{"atb":[[2.04,6.55]],"id":56263473},{"atb":[[2.1,6.55]],"id":70902709}],"con":true,"img":false}]}
{"op":"mcm","clk":"11538754052","pt":1719468311787,"mc":[{"id":"1.230180124","marketDefinition":{"bspMarket":true,"turnInPlayEnabled":false,"persistenceEnabled":false,"marketBaseRate":5.0,"eventId":"33376437","eventTypeId":"4339","numberOfWinners":1,"bettingType":"ODDS","marketType":"WIN","marketTime":"2024-06-27T15:26:00.000Z","suspendTime":"2024-06-27T15:26:00.000Z","bspReconciled":false,"complete":true,"inPlay":false,"crossMatching":true,"runnersVoidable":false,"numberOfActiveRunners":6,"betDelay":0,"status":"OPEN","runners":[{"status":"ACTIVE","sortPriority":1,"id":42767337,"name":"1. Salacres Liam"},{"status":"ACTIVE","sortPriority":2,"id":56263473,"name":"2. Makeit Spot"},{"status":"ACTIVE","sortPriority":3,"id":67245400,"name":"3. Lillibeth Royale"},{"status":"ACTIVE","sortPriority":4,"id":65992794,"name":"4. Come Back Kid"},{"status":"ACTIVE","sortPriority":5,"id":70902709,"name":"5. Cloud Canine"},{"status":"ACTIVE","sortPriority":6,"id":51567147,"name":"6. Coolemore North"}],"regulators":["MR_INT"],"venue":"Towcester","countryCode":"GB","discountAllowed":true,"timezone":"Europe/London","openDate":"2024-06-27T13:33:00.000Z","version":5994767056,"name":"A4 500m","eventName":"Towcester 27th Jun"},"rc":[],"con":true,"img":false}]}
{"op":"mcm","clk":"11538818685","pt":1719469561968,"mc":[{"id":"1.230180124","rc":[{"atl":[[150,4]],"id":56263473},{"spn":76.02,"spf":"NaN","id":56263473},{"atl":[[150,4]],"id":65992794},{"spn":76.05,"spf":"NaN","id":65992794},{"atl":[[150,4]],"id":67245400},{"spn":76.01,"spf":"NaN","id":67245400},{"atl":[[150,4]],"id":42767337},{"spn":76.01,"spf":"NaN","id":42767337},{"atl":[[150,4]],"id":51567147},{"spn":76.02,"spf":"NaN","id":51567147},{"atl":[[150,4]],"id":70902709},{"spn":76.05,"spf":"NaN","id":70902709}],"con":true,"img":false}]}
{"op":"mcm","clk":"11538937255","pt":1719472049117,"mc":[{"id":"1.230180124","rc":[{"atb":[[2.02,10.35],[1.03,17.27],[2.04,6.54]],"id":56263473},{"atl":[[1000,0.23]],"id":56263473},{"atb":[[1.03,17.27],[2.1,6.54],[2.08,8.88]],"id":65992794},{"atl":[[21,4],[11.5,2],[990,0.23],[15.5,3]],"id":65992794},{"spn":6.8,"spf":"NaN","id":65992794},{"atb":[[2,8.54],[2.02,6.54],[1.01,51.82]],"id":67245400},{"atl":[[1000,0.23]],"id":67245400},{"atb":[[2,12.81],[2.02,6.54],[1.03,17.27]],"id":42767337},{"atl":[[1000,0.23]],"id":42767337},{"atb":[[2.02,8.62],[1.01,51.82],[2.04,6.54]],"id":51567147},{"atl":[[990,0.23]],"id":51567147},{"atb":[[1.01,51.82],[2.1,6.54],[2.08,9.76]],"id":70902709},{"atl":[[1000,0.23]],"id":70902709}],"con":true,"img":false}]}
{"op":"mcm","clk":"11538940739","pt":1719472113219,"mc":[{"id":"1.230180124","rc":[{"atb":[[2.02,0]],"id":56263473},{"atb":[[2.08,0]],"id":65992794},{"atb":[[2,0]],"id":67245400},{"atb":[[2,0]],"id":42767337},{"atb":[[2.02,0]],"id":51567147},{"atb":[[2.08,0]],"id":70902709}],"con":true,"img":false}]}
{"op":"mcm","clk":"11538940749","pt":1719472113323,"mc":[{"id":"1.230180124","rc":[{"atb":[[2.06,10.35]],"id":56263473},{"atb":[[2.12,8.88]],"id":65992794},{"atb":[[2.04,8.54]],"id":67245400},{"atb":[[2.04,12.81]],"id":42767337},{"atb":[[2.06,8.62]],"id":51567147},{"atb":[[2.12,9.76]],"id":70902709}],"con":true,"img":false}]}
{"op":"mcm","clk":"11538943234","pt":1719472152252,"mc":[{"id":"1.230180124","rc":[{"atb":[[2.04,3.38]],"id":51567147}],"con":true,"img":false}]}
{"op":"mcm","clk":"11538943250","pt":1719472152560,"mc":[{"id":"1.230180124","rc":[{"atb":[[2.02,3.38]],"id":67245400}],"con":true,"img":false}]}
{"op":"mcm","clk":"11538943279","pt":1719472153176,"mc":[{"id":"1.230180124","rc":[{"atb":[[2.04,3.38]],"id":56263473}],"con":true,"img":false}]}
{"op":"mcm","clk":"11538943314","pt":1719472153690,"mc":[{"id":"1.230180124","rc":[{"atb":[[2.1,3.38]],"id":70902709}],"con":true,"img":false}]}
{"op":"mcm","clk":"11538943354","pt":1719472154258,"mc":[{"id":"1.230180124","rc":[{"atb":[[2.06,3.16]],"id":67245400}],"con":true,"img":false}]}
{"op":"mcm","clk":"11538943400","pt":1719472154976,"mc":[{"id":"1.230180124","rc":[{"atb":[[2.1,3.38]],"id":65992794}],"con":true,"img":false}]}
{"op":"mcm","clk":"11538943423","pt":1719472155288,"mc":[{"id":"1.230180124","rc":[{"atb":[[2.14,3.16]],"id":70902709}],"con":true,"img":false}]}
{"op":"mcm","clk":"11538943435","pt":1719472155488,"mc":[{"id":"1.230180124","rc":[{"atb":[[2.08,3.16]],"id":51567147}],"con":true,"img":false}]}
{"op":"mcm","clk":"11538943452","pt":1719472155795,"mc":[{"id":"1.230180124","rc":[{"atb":[[2.02,3.38]],"id":42767337}],"con":true,"img":false}]}
{"op":"mcm","clk":"11538943479","pt":1719472156204,"mc":[{"id":"1.230180124","rc":[{"atb":[[2.14,3.16]],"id":65992794}],"con":true,"img":false}]}
{"op":"mcm","clk":"11538943505","pt":1719472156562,"mc":[{"id":"1.230180124","rc":[{"atb":[[2.08,3.16]],"id":56263473}],"con":true,"img":false}]}
{"op":"mcm","clk":"11538943582","pt":1719472158197,"mc":[{"id":"1.230180124","rc":[{"atb":[[2.06,3.16]],"id":42767337}],"con":true,"img":false}]}
{"op":"mcm","clk":"11538944242","pt":1719472169421,"mc":[{"id":"1.230180124","rc":[{"atb":[[2.02,0]],"id":42767337}],"con":true,"img":false}]}
{"op":"mcm","clk":"11538944253","pt":1719472169575,"mc":[{"id":"1.230180124","rc":[{"atb":[[2.04,0]],"id":56263473}],"con":true,"img":false}]}
{"op":"mcm","clk":"11538944293","pt":1719472170292,"mc":[{"id":"1.230180124","rc":[{"atb":[[2.1,0]],"id":65992794},{"atb":[[2.1,0]],"id":70902709}],"con":true,"img":false}]}
{"op":"mcm","clk":"11538944333","pt":1719472170907,"mc":[{"id":"1.230180124","rc":[{"atb":[[2.04,0]],"id":51567147}],"con":true,"img":false}]}
{"op":"mcm","clk":"11538944341","pt":1719472171014,"mc":[{"id":"1.230180124","rc":[{"atb":[[2.02,0]],"id":67245400}],"con":true,"img":false}]}
{"op":"mcm","clk":"11538945469","pt":1719472189923,"mc":[{"id":"1.230180124","rc":[{"spn":76.04,"spf":"NaN","id":56263473},{"spn":6.82,"spf":"NaN","id":65992794},{"spn":76.03,"spf":"NaN","id":67245400},{"atb":[[2.06,6.54]],"id":42767337},{"spn":76.03,"spf":"NaN","id":42767337},{"spn":76.04,"spf":"NaN","id":51567147},{"spn":76.07,"spf":"NaN","id":70902709}],"con":true,"img":false}]}
{"op":"mcm","clk":"11538945480","pt":1719472190129,"mc":[{"id":"1.230180124","rc":[{"atb":[[2.08,6.54]],"id":56263473}],"con":true,"img":false}]}
{"op":"mcm","clk":"11538945504","pt":1719472190434,"mc":[{"id":"1.230180124","rc":[{"atb":[[2.14,6.54]],"id":65992794}],"con":true,"img":false}]}
{"op":"mcm","clk":"11538945524","pt":1719472190739,"mc":[{"id":"1.230180124","rc":[{"atb":[[2.14,6.54]],"id":70902709}],"con":true,"img":false}]}
{"op":"mcm","clk":"11538945544","pt":1719472191054,"mc":[{"id":"1.230180124","rc":[{"atb":[[2.08,6.54]],"id":51567147}],"con":true,"img":false}]}
{"op":"mcm","clk":"11538945632","pt":1719472192549,"mc":[{"id":"1.230180124","rc":[{"atb":[[2.06,6.54]],"id":67245400}],"con":true,"img":false}]}
{"op":"mcm","clk":"11539124105","pt":1719475682704,"mc":[{"id":"1.230180124","marketDefinition":{"bspMarket":true,"turnInPlayEnabled":false,"persistenceEnabled":false,"marketBaseRate":5.0,"eventId":"33376437","eventTypeId":"4339","numberOfWinners":1,"bettingType":"ODDS","marketType":"WIN","marketTime":"2024-06-27T15:26:00.000Z","suspendTime":"2024-06-27T15:26:00.000Z","bspReconciled":false,"complete":true,"inPlay":false,"crossMatching":true,"runnersVoidable":false,"numberOfActiveRunners":6,"betDelay":0,"status":"OPEN","runners":[{"status":"ACTIVE","sortPriority":1,"id":42767337,"name":"1. Salacres Liam"},{"status":"ACTIVE","sortPriority":2,"id":56263473,"name":"2. Makeit Spot"},{"status":"ACTIVE","sortPriority":3,"id":67245400,"name":"3. Lillibeth Royale"},{"status":"ACTIVE","sortPriority":4,"id":65992794,"name":"4. Come Back Kid"},{"status":"ACTIVE","sortPriority":5,"id":70902709,"name":"5. Cloud Canine"},{"status":"ACTIVE","sortPriority":6,"id":51567147,"name":"6. Coolemore North"}],"regulators":["MR_INT"],"venue":"Towcester","countryCode":"GB","discountAllowed":true,"timezone":"Europe/London","openDate":"2024-06-27T13:33:00.000Z","version":5994767056,"name":"A4 500m","eventName":"Towcester 27th Jun"},"rc":[{"atb":[[2.06,10.35],[1.03,17.28],[2.08,6.55]],"id":56263473},{"atl":[[150,4],[1000,0.23]],"id":56263473},{"spn":76.04,"spf":"NaN","id":56263473},{"atb":[[1.03,17.28],[2.12,8.88],[2.14,6.55]],"id":65992794},{"atl":[[150,4],[21,4],[11.5,2],[990,0.23],[15.5,3]],"id":65992794},{"spn":6.82,"spf":"NaN","id":65992794},{"atb":[[1.01,51.84],[2.06,6.55],[2.04,8.54]],"id":67245400},{"atl":[[150,4],[1000,0.23]],"id":67245400},{"spn":76.03,"spf":"NaN","id":67245400},{"atb":[[2.06,6.55],[1.03,17.28],[2.04,12.81]],"id":42767337},{"atl":[[150,4],[1000,0.23]],"id":42767337},{"spn":76.03,"spf":"NaN","id":42767337},{"atb":[[1.01,51.84],[2.06,8.63],[2.08,6.55]],"id":51567147},{"atl":[[150,4],[990,0.23]],"id":51567147},{"spn":76.04,"spf":"NaN","id":51567147},{"atb":[[1.01,51.84],[2.12,9.77],[2.14,6.55]],"id":70902709},{"atl":[[150,4],[1000,0.23]],"id":70902709},{"spn":76.07,"spf":"NaN","id":70902709}],"con":true,"img":true}]}
{"op":"mcm","clk":"11539128043","pt":1719475713329,"mc":[{"id":"1.230180124","rc":[{"atb":[[2.06,0],[1.03,17.28],[2.08,6.55]],"id":56263473},{"atl":[[1000,0.23]],"id":56263473},{"atb":[[1.03,17.28],[2.12,0],[2.14,6.55]],"id":65992794},{"atl":[[990,0.23]],"id":65992794},{"atb":[[1.01,51.84],[2.06,6.55],[2.04,0]],"id":67245400},{"atl":[[1000,0.23]],"id":67245400},{"atb":[[2.06,6.55],[1.03,17.28],[2.04,0]],"id":42767337},{"atl":[[1000,0.23]],"id":42767337},{"atb":[[1.01,51.84],[2.06,0],[2.08,6.55]],"id":51567147},{"atl":[[990,0.23]],"id":51567147},{"atb":[[1.01,51.84],[2.12,0],[2.14,6.55]],"id":70902709},{"atl":[[1000,0.23]],"id":70902709}],"con":true,"img":false}]}
{"op":"mcm","clk":"11539128049","pt":1719475713433,"mc":[{"id":"1.230180124","rc":[{"atb":[[2.1,10.35]],"id":56263473},{"atb":[[2.16,8.88]],"id":65992794},{"atb":[[2.08,8.54]],"id":67245400},{"atb":[[2.08,12.81]],"id":42767337},{"atb":[[2.1,8.63]],"id":51567147},{"atb":[[2.16,9.77]],"id":70902709}],"con":true,"img":false}]}
{"op":"mcm","clk":"11539133873","pt":1719475804759,"mc":[{"id":"1.230180124","rc":[{"spn":76.05,"spf":"NaN","id":56263473},{"spn":6.83,"spf":"NaN","id":65992794},{"spn":76.04,"spf":"NaN","id":67245400},{"atb":[[2.06,3.16]],"id":42767337},{"spn":76.04,"spf":"NaN","id":42767337},{"spn":76.05,"spf":"NaN","id":51567147},{"spn":76.08,"spf":"NaN","id":70902709}],"con":true,"img":false}]}
{"op":"mcm","clk":"11539133913","pt":1719475805169,"mc":[{"id":"1.230180124","rc":[{"atb":[[2.14,3.16]],"id":65992794}],"con":true,"img":false}]}
{"op":"mcm","clk":"11539133935","pt":1719475805431,"mc":[{"id":"1.230180124","rc":[{"atb":[[2.08,3.16]],"id":56263473}],"con":true,"img":false}]}
{"op":"mcm","clk":"11539133955","pt":1719475805739,"mc":[{"id":"1.230180124","rc":[{"atb":[[2.08,3.16]],"id":51567147}],"con":true,"img":false}]}
{"op":"mcm","clk":"11539133997","pt":1719475806251,"mc":[{"id":"1.230180124","rc":[{"atb":[[2.06,3.16]],"id":67245400}],"con":true,"img":false}]}
{"op":"mcm","clk":"11539134038","pt":1719475806969,"mc":[{"id":"1.230180124","rc":[{"atb":[[2.14,3.16]],"id":70902709}],"con":true,"img":false}]}
{"op":"mcm","clk":"11539134118","pt":1719475807947,"mc":[{"id":"1.230180124","rc":[{"atb":[[2.1,3.38]],"id":42767337}],"con":true,"img":false}]}
{"op":"mcm","clk":"11539134154","pt":1719475808465,"mc":[{"id":"1.230180124","rc":[{"atb":[[2.18,3.38]],"id":65992794}],"con":true,"img":false}]}
{"op":"mcm","clk":"11539134259","pt":1719475810065,"mc":[{"id":"1.230180124","rc":[{"atb":[[2.12,3.38]],"id":56263473}],"con":true,"img":false}]}
{"op":"mcm","clk":"11539134281","pt":1719475810375,"mc":[{"id":"1.230180124","rc":[{"atb":[[2.12,3.38]],"id":51567147}],"con":true,"img":false}]}
{"op":"mcm","clk":"11539134297","pt":1719475810582,"mc":[{"id":"1.230180124","rc":[{"atb":[[2.1,3.38]],"id":67245400}],"con":true,"img":false}]}
{"op":"mcm","clk":"11539134330","pt":1719475810841,"mc":[{"id":"1.230180124","rc":[{"atb":[[2.18,3.38]],"id":70902709}],"con":true,"img":false}]}
{"op":"mcm","clk":"11539134409","pt":1719475811983,"mc":[{"id":"1.230180124","rc":[{"atb":[[2.08,0]],"id":56263473},{"atb":[[2.14,0]],"id":65992794},{"atb":[[2.06,0]],"id":67245400},{"atb":[[2.06,0]],"id":42767337},{"atb":[[2.08,0]],"id":51567147},{"atb":[[2.14,0]],"id":70902709}],"con":true,"img":false}]}
{"op":"mcm","clk":"11539153508","pt":1719476120174,"mc":[{"id":"1.230180124","rc":[{"atb":[[2.12,6.55]],"id":56263473},{"spn":76.06,"spf":"NaN","id":56263473},{"spn":6.84,"spf":"NaN","id":65992794},{"atb":[[2.1,6.55]],"id":67245400},{"spn":76.05,"spf":"NaN","id":67245400},{"spn":76.05,"spf":"NaN","id":42767337},{"spn":76.06,"spf":"NaN","id":51567147},{"spn":76.09,"spf":"NaN","id":70902709}],"con":true,"img":false}]}
{"op":"mcm","clk":"11539153526","pt":1719476120373,"mc":[{"id":"1.230180124","rc":[{"atb":[[2.18,6.55]],"id":65992794}],"con":true,"img":false}]}
{"op":"mcm","clk":"11539153539","pt":1719476120579,"mc":[{"id":"1.230180124","rc":[{"atb":[[2.1,6.55]],"id":42767337},{"atb":[[2.18,6.55]],"id":70902709}],"con":true,"img":false}]}
{"op":"mcm","clk":"11539153562","pt":1719476120991,"mc":[{"id":"1.230180124","rc":[{"atb":[[2.12,6.55]],"id":51567147}],"con":true,"img":false}]}
{"op":"mcm","clk":"11539341494","pt":1719479311705,"mc":[{"id":"1.230180124","rc":[{"atb":[[1.03,17.28],[2.12,6.54],[2.1,0]],"id":56263473},{"atb":[[1.03,17.28],[2.18,6.54],[2.16,0]],"id":65992794},{"atb":[[1.01,51.83],[2.1,6.54],[2.08,0]],"id":67245400},{"atb":[[1.03,17.28],[2.1,6.54],[2.08,0]],"id":42767337},{"atb":[[1.01,51.83],[2.12,6.54],[2.1,0]],"id":51567147},{"atb":[[1.01,51.83],[2.18,6.54],[2.16,0]],"id":70902709}],"con":true,"img":false}]}
{"op":"mcm","clk":"11539341502","pt":1719479311748,"mc":[{"id":"1.230180124","rc":[{"atb":[[2.14,10.35]],"id":56263473},{"atb":[[2.2,8.88]],"id":65992794},{"atb":[[2.12,8.54]],"id":67245400},{"atb":[[2.12,12.81]],"id":42767337},{"atb":[[2.14,8.62]],"id":51567147},{"atb":[[2.2,9.77]],"id":70902709}],"con":true,"img":false}]}
{"op":"mcm","clk":"11539346992","pt":1719479400311,"mc":[{"id":"1.230180124","rc":[{"spn":76.07,"spf":"NaN","id":56263473},{"spn":6.85,"spf":"NaN","id":65992794},{"spn":76.06,"spf":"NaN","id":67245400},{"atb":[[2.1,3.38]],"id":42767337},{"spn":76.06,"spf":"NaN","id":42767337},{"spn":76.07,"spf":"NaN","id":51567147},{"spn":76.1,"spf":"NaN","id":70902709}],"con":true,"img":false}]}
{"op":"mcm","clk":"11539347049","pt":1719479401196,"mc":[{"id":"1.230180124","rc":[{"atb":[[2.12,3.38]],"id":56263473}],"con":true,"img":false}]}
{"op":"mcm","clk":"11539347055","pt":1719479401301,"mc":[{"id":"1.230180124","rc":[{"atb":[[2.1,3.38]],"id":67245400}],"con":true,"img":false}]}
{"op":"mcm","clk":"11539347073","pt":1719479401607,"mc":[{"id":"1.230180124","rc":[{"atb":[[2.18,3.38]],"id":65992794},{"atb":[[2.18,3.38]],"id":70902709}],"con":true,"img":false}]}
{"op":"mcm","clk":"11539347154","pt":1719479402598,"mc":[{"id":"1.230180124","rc":[{"atb":[[2.12,3.38]],"id":51567147}],"con":true,"img":false}]}
{"op":"mcm","clk":"11539349317","pt":1719479436444,"mc":[{"id":"1.230180124","rc":[{"atb":[[2.18,0]],"id":65992794}],"con":true,"img":false}]}
{"op":"mcm","clk":"11539349354","pt":1719479437125,"mc":[{"id":"1.230180124","rc":[{"atb":[[2.1,0]],"id":67245400}],"con":true,"img":false}]}
{"op":"mcm","clk":"11539349422","pt":1719479438350,"mc":[{"id":"1.230180124","rc":[{"atb":[[2.1,0]],"id":42767337}],"con":true,"img":false}]}
{"op":"mcm","clk":"11539349463","pt":1719479438927,"mc":[{"id":"1.230180124","rc":[{"atb":[[2.18,0]],"id":70902709}],"con":true,"img":false}]}
{"op":"mcm","clk":"11539349534","pt":1719479440158,"mc":[{"id":"1.230180124","rc":[{"atb":[[2.12,0]],"id":56263473}],"con":true,"img":false}]}
{"op":"mcm","clk":"11539349551","pt":1719479440425,"mc":[{"id":"1.230180124","rc":[{"atb":[[2.22,3.38]],"id":65992794}],"con":true,"img":false}]}
{"op":"mcm","clk":"11539349574","pt":1719479440842,"mc":[{"id":"1.230180124","rc":[{"atb":[[2.12,0]],"id":51567147}],"con":true,"img":false}]}
{"op":"mcm","clk":"11539349611","pt":1719479441359,"mc":[{"id":"1.230180124","rc":[{"atb":[[2.14,3.38]],"id":67245400}],"con":true,"img":false}]}
{"op":"mcm","clk":"11539349650","pt":1719479441919,"mc":[{"id":"1.230180124","rc":[{"atb":[[2.22,3.38]],"id":70902709}],"con":true,"img":false}]}
{"op":"mcm","clk":"11539349666","pt":1719479442230,"mc":[{"id":"1.230180124","rc":[{"atb":[[2.14,3.38]],"id":42767337}],"con":true,"img":false}]}
{"op":"mcm","clk":"11539349684","pt":1719479442543,"mc":[{"id":"1.230180124","rc":[{"atb":[[2.16,3.38]],"id":56263473},{"atb":[[2.16,3.38]],"id":51567147}],"con":true,"img":false}]}
{"op":"mcm","clk":"11539367882","pt":1719479709733,"mc":[{"id":"1.230180124","rc":[{"spn":76.08,"spf":"NaN","id":56263473},{"spn":6.86,"spf":"NaN","id":65992794},{"spn":76.07,"spf":"NaN","id":67245400},{"spn":76.07,"spf":"NaN","id":42767337},{"atb":[[2.16,6.54]],"id":51567147},{"spn":76.08,"spf":"NaN","id":51567147},{"spn":76.11,"spf":"NaN","id":70902709}],"con":true,"img":false}]}
{"op":"mcm","clk":"11539367923","pt":1719479710242,"mc":[{"id":"1.230180124","rc":[{"atb":[[2.16,6.54]],"id":56263473}],"con":true,"img":false}]}
{"op":"mcm","clk":"11539367957","pt":1719479710657,"mc":[{"id":"1.230180124","rc":[{"atb":[[2.14,6.54]],"id":67245400}],"con":true,"img":false}]}
{"op":"mcm","clk":"11539367979","pt":1719479710867,"mc":[{"id":"1.230180124","rc":[{"atb":[[2.22,6.54]],"id":70902709}],"con":true,"img":false}]}
{"op":"mcm","clk":"11539368065","pt":1719479711856,"mc":[{"id":"1.230180124","rc":[{"atb":[[2.22,6.54]],"id":65992794}],"con":true,"img":false}]}
{"op":"mcm","clk":"11539368082","pt":1719479712056,"mc":[{"id":"1.230180124","rc":[{"atb":[[2.14,6.54]],"id":42767337}],"con":true,"img":false}]}
{"op":"mcm","clk":"11539416999","pt":1719480712345,"mc":[{"id":"1.230180124","rc":[{"spl":[[2,1]],"id":65992794},{"spn":2.22,"spf":1.0,"id":65992794}],"con":true,"img":false}]}
{"op":"mcm","clk":"11539545373","pt":1719482909491,"mc":[{"id":"1.230180124","rc":[{"atb":[[1.03,17.27],[2.16,6.54],[2.14,0]],"id":56263473},{"atb":[[1.03,17.27],[2.22,6.54],[2.2,0]],"id":65992794},{"atb":[[1.01,51.83],[2.12,0],[2.14,6.54]],"id":67245400},{"atb":[[1.03,17.27],[2.12,0],[2.14,6.54]],"id":42767337},{"atb":[[1.01,51.83],[2.16,6.54],[2.14,0]],"id":51567147},{"atb":[[1.01,51.83],[2.22,6.54],[2.2,0]],"id":70902709}],"con":true,"img":false}]}
{"op":"mcm","clk":"11539545378","pt":1719482909595,"mc":[{"id":"1.230180124","rc":[{"atb":[[2.18,10.35]],"id":56263473},{"atb":[[2.24,8.88]],"id":65992794},{"atb":[[2.16,8.54]],"id":67245400},{"atb":[[2.16,12.81]],"id":42767337},{"atb":[[2.18,8.62]],"id":51567147},{"atb":[[2.24,9.76]],"id":70902709}],"con":true,"img":false}]}
{"op":"mcm","clk":"11539548819","pt":1719482962254,"mc":[{"id":"1.230180124","rc":[{"atb":[[2.22,3.16]],"id":70902709}],"con":true,"img":false}]}
{"op":"mcm","clk":"11539548835","pt":1719482962559,"mc":[{"id":"1.230180124","rc":[{"atb":[[2.14,3.16]],"id":42767337}],"con":true,"img":false}]}
{"op":"mcm","clk":"11539548859","pt":1719482962986,"mc":[{"id":"1.230180124","rc":[{"atb":[[2.14,3.16]],"id":67245400}],"con":true,"img":false}]}
{"op":"mcm","clk":"11539548891","pt":1719482963558,"mc":[{"id":"1.230180124","rc":[{"atb":[[2.16,3.16]],"id":56263473}],"con":true,"img":false}]}
{"op":"mcm","clk":"11539549045","pt":1719482965985,"mc":[{"id":"1.230180124","rc":[{"atb":[[2.22,3.16]],"id":65992794}],"con":true,"img":false}]}
{"op":"mcm","clk":"11539549106","pt":1719482967159,"mc":[{"id":"1.230180124","rc":[{"atb":[[2.16,3.16]],"id":51567147}],"con":true,"img":false}]}
{"op":"mcm","clk":"11539549193","pt":1719482968552,"mc":[{"id":"1.230180124","rc":[{"atb":[[2.2,3.38]],"id":56263473}],"con":true,"img":false}]}
{"op":"mcm","clk":"11539549205","pt":1719482968860,"mc":[{"id":"1.230180124","rc":[{"atb":[[2.18,3.38]],"id":42767337}],"con":true,"img":false}]}
{"op":"mcm","clk":"11539549222","pt":1719482969172,"mc":[{"id":"1.230180124","rc":[{"atb":[[2.26,3.38]],"id":70902709}],"con":true,"img":false}]}
{"op":"mcm","clk":"11539549260","pt":1719482969887,"mc":[{"id":"1.230180124","rc":[{"spn":76.1,"spf":"NaN","id":56263473},{"spn":2.24,"spf":1.0,"id":65992794},{"atb":[[2.18,3.38]],"id":67245400},{"spn":76.09,"spf":"NaN","id":67245400},{"spn":76.09,"spf":"NaN","id":42767337},{"spn":76.09,"spf":"NaN","id":51567147},{"spn":76.13,"spf":"NaN","id":70902709}],"con":true,"img":false}]}
{"op":"mcm","clk":"11539549327","pt":1719482970866,"mc":[{"id":"1.230180124","rc":[{"atb":[[2.26,3.38]],"id":65992794}],"con":true,"img":false}]}
{"op":"mcm","clk":"11539549406","pt":1719482972063,"mc":[{"id":"1.230180124","rc":[{"atb":[[2.2,3.38]],"id":51567147}],"con":true,"img":false}]}
{"op":"mcm","clk":"11539553341","pt":1719483028479,"mc":[{"id":"1.230180124","rc":[{"atb":[[2.16,0]],"id":56263473},{"atb":[[2.22,0]],"id":65992794},{"atb":[[2.14,0]],"id":67245400},{"atb":[[2.14,0]],"id":42767337},{"atb":[[2.16,0]],"id":51567147},{"atb":[[2.22,0]],"id":70902709}],"con":true,"img":false}]}
{"op":"mcm","clk":"11539572998","pt":1719483323236,"mc":[{"id":"1.230180124","rc":[{"spn":2.26,"spf":1.0,"id":65992794},{"atb":[[2.2,6.54]],"id":51567147},{"spn":76.1,"spf":"NaN","id":51567147}],"con":true,"img":false}]}
{"op":"mcm","clk":"11539573079","pt":1719483324021,"mc":[{"id":"1.230180124","rc":[{"atb":[[2.2,6.54]],"id":56263473}],"con":true,"img":false}]}
{"op":"mcm","clk":"11539573162","pt":1719483324954,"mc":[{"id":"1.230180124","rc":[{"atb":[[2.26,6.54]],"id":65992794}],"con":true,"img":false}]}
{"op":"mcm","clk":"11539573172","pt":1719483325011,"mc":[{"id":"1.230180124","rc":[{"atb":[[2.18,6.54]],"id":42767337}],"con":true,"img":false}]}
{"op":"mcm","clk":"11539573182","pt":1719483325114,"mc":[{"id":"1.230180124","rc":[{"atb":[[2.18,6.54]],"id":67245400}],"con":true,"img":false}]}
{"op":"mcm","clk":"11539573463","pt":1719483328035,"mc":[{"id":"1.230180124","rc":[{"atb":[[2.26,6.54]],"id":70902709}],"con":true,"img":false}]}
{"op":"mcm","clk":"11539624000","pt":1719483975011,"mc":[{"id":"1.230180124","rc":[{"atl":[[48,12],[28,8]],"id":56263473},{"spn":15.1,"spf":"NaN","id":56263473},{"atl":[[32,12],[18.5,8]],"id":65992794},{"atl":[[48,12],[28,8]],"id":51567147},{"spn":15.1,"spf":"NaN","id":51567147}],"con":true,"img":false}]}
{"op":"mcm","clk":"11539745874","pt":1719485572850,"mc":[{"id":"1.230180124","rc":[{"atb":[[2.58,6]],"id":56263473},{"spn":15.29,"spf":"NaN","id":56263473},{"atb":[[2.16,6]],"id":65992794},{"atb":[[4.2,6]],"id":67245400},{"spn":77.1,"spf":"NaN","id":67245400},{"atb":[[4.6,6]],"id":42767337},{"spn":77.3,"spf":"NaN","id":42767337},{"atb":[[3.1,6]],"id":51567147},{"spn":15.55,"spf":"NaN","id":51567147},{"atb":[[3.55,6]],"id":70902709},{"spn":76.77,"spf":"NaN","id":70902709}],"con":true,"img":false}]}
{"op":"mcm","clk":"11539745938","pt":1719485573833,"mc":[{"id":"1.230180124","rc":[{"atb":[[2.18,3.38]],"id":67245400},{"atb":[[2.18,3.38]],"id":42767337},{"atb":[[2.2,3.38]],"id":51567147},{"atb":[[2.26,3.38]],"id":70902709}],"con":true,"img":false}]}
{"op":"mcm","clk":"11539746537","pt":1719485581666,"mc":[{"id":"1.230180124","rc":[{"atb":[[2.18,0]],"id":67245400},{"atb":[[2.18,0]],"id":42767337},{"atb":[[2.2,0]],"id":51567147},{"atb":[[2.26,0]],"id":70902709}],"con":true,"img":false}]}
{"op":"mcm","clk":"11539812625","pt":1719486482665,"mc":[{"id":"1.230180124","marketDefinition":{"bspMarket":true,"turnInPlayEnabled":false,"persistenceEnabled":false,"marketBaseRate":5.0,"eventId":"33376437","eventTypeId":"4339","numberOfWinners":1,"bettingType":"ODDS","marketType":"WIN","marketTime":"2024-06-27T15:26:00.000Z","suspendTime":"2024-06-27T15:26:00.000Z","bspReconciled":false,"complete":true,"inPlay":false,"crossMatching":true,"runnersVoidable":false,"numberOfActiveRunners":6,"betDelay":0,"status":"OPEN","runners":[{"status":"ACTIVE","sortPriority":1,"id":42767337,"name":"1. Salacres Liam"},{"status":"ACTIVE","sortPriority":2,"id":56263473,"name":"2. Makeit Spot"},{"status":"ACTIVE","sortPriority":3,"id":67245400,"name":"3. Lillibeth Royale"},{"status":"ACTIVE","sortPriority":4,"id":65992794,"name":"4. Come Back Kid"},{"status":"ACTIVE","sortPriority":5,"id":70902709,"name":"5. Cloud Canine"},{"status":"ACTIVE","sortPriority":6,"id":51567147,"name":"6. Coolemore North"}],"regulators":["MR_INT"],"venue":"Towcester","countryCode":"GB","discountAllowed":true,"timezone":"Europe/London","openDate":"2024-06-27T13:33:00.000Z","version":5994767056,"name":"A4 500m","eventName":"Towcester 27th Jun"},"rc":[{"atb":[[1.03,17.28],[2.18,10.35],[2.58,6],[2.2,6.54]],"id":56263473},{"atl":[[150,4],[48,12],[28,8],[1000,0.23]],"id":56263473},{"spn":15.29,"spf":"NaN","id":56263473},{"spl":[[2,1]],"id":65992794},{"atb":[[2.24,8.88],[1.03,17.28],[2.26,6.54],[2.16,6]],"id":65992794},{"atl":[[32,12],[18.5,8],[150,4],[21,4],[11.5,2],[990,0.23],[15.5,3]],"id":65992794},{"spn":2.26,"spf":1.0,"id":65992794},{"atb":[[1.01,51.83],[4.2,6],[2.16,8.54]],"id":67245400},{"atl":[[150,4],[1000,0.23]],"id":67245400},{"spn":77.1,"spf":"NaN","id":67245400},{"atb":[[4.6,6],[1.03,17.28],[2.16,12.81]],"id":42767337},{"atl":[[150,4],[1000,0.23]],"id":42767337},{"spn":77.3,"spf":"NaN","id":42767337},{"atb":[[1.01,51.83],[3.1,6],[2.18,8.62]],"id":51567147},{"atl":[[150,4],[48,12],[28,8],[990,0.23]],"id":51567147},{"spn":15.55,"spf":"NaN","id":51567147},{"atb":[[2.24,9.77],[1.01,51.83],[3.55,6]],"id":70902709},{"atl":[[150,4],[1000,0.23]],"id":70902709},{"spn":76.77,"spf":"NaN","id":70902709}],"con":true,"img":true}]}
{"op":"mcm","clk":"11539817369","pt":1719486506721,"mc":[{"id":"1.230180124","rc":[{"atb":[[1.03,17.28],[2.18,0],[2.2,6.54]],"id":56263473},{"atb":[[2.24,0],[1.03,17.28],[2.26,6.54]],"id":65992794},{"atb":[[1.01,51.83],[2.16,8.54]],"id":67245400},{"atb":[[1.03,17.28],[2.16,12.81]],"id":42767337},{"atb":[[1.01,51.83],[2.18,8.62]],"id":51567147},{"atb":[[2.24,9.77],[1.01,51.83]],"id":70902709}],"con":true,"img":false}]}
{"op":"mcm","clk":"11539817381","pt":1719486506820,"mc":[{"id":"1.230180124","rc":[{"atb":[[2.22,10.35]],"id":56263473},{"atb":[[2.28,8.88]],"id":65992794}],"con":true,"img":false}]}
{"op":"mcm","clk":"11539818909","pt":1719486523475,"mc":[{"id":"1.230180124","rc":[{"atb":[[2.2,3.38]],"id":56263473},{"atb":[[2.26,3.38]],"id":65992794}],"con":true,"img":false}]}
{"op":"mcm","clk":"11539818966","pt":1719486523838,"mc":[{"id":"1.230180124","rc":[{"atb":[[2.3,3.16]],"id":65992794}],"con":true,"img":false}]}
{"op":"mcm","clk":"11539818984","pt":1719486524048,"mc":[{"id":"1.230180124","rc":[{"atb":[[2.24,3.16]],"id":56263473}],"con":true,"img":false}]}
{"op":"mcm","clk":"11539825269","pt":1719486598451,"mc":[{"id":"1.230180124","rc":[{"atb":[[2.26,0]],"id":65992794},{"spn":2.3,"spf":1.0,"id":65992794}],"con":true,"img":false}]}
{"op":"mcm","clk":"11539825491","pt":1719486601259,"mc":[{"id":"1.230180124","rc":[{"atb":[[2.2,0]],"id":56263473}],"con":true,"img":false}]}
{"op":"mcm","clk":"11539825794","pt":1719486605359,"mc":[{"id":"1.230180124","rc":[{"atb":[[2.3,6.54]],"id":65992794}],"con":true,"img":false}]}
{"op":"mcm","clk":"11539825833","pt":1719486605962,"mc":[{"id":"1.230180124","rc":[{"atb":[[2.24,6.54]],"id":56263473}],"con":true,"img":false}]}
{"op":"mcm","clk":"11539840634","pt":1719486806719,"mc":[{"id":"1.230180124","rc":[{"atb":[[2.22,0]],"id":56263473},{"atb":[[2.28,0]],"id":65992794}],"con":true,"img":false}]}
{"op":"mcm","clk":"11539840642","pt":1719486806804,"mc":[{"id":"1.230180124","rc":[{"atb":[[2.26,10.35]],"id":56263473},{"atb":[[2.32,8.88]],"id":65992794}],"con":true,"img":false}]}
{"op":"mcm","clk":"11539841559","pt":1719486822017,"mc":[{"id":"1.230180124","rc":[{"atb":[[2.24,3.38]],"id":56263473},{"atb":[[2.3,3.38]],"id":65992794}],"con":true,"img":false}]}
{"op":"mcm","clk":"11539843107","pt":1719486845080,"mc":[{"id":"1.230180124","rc":[{"atb":[[2.24,0]],"id":56263473},{"atb":[[2.3,0]],"id":65992794}],"con":true,"img":false}]}
{"op":"mcm","clk":"11539848868","pt":1719486926510,"mc":[{"id":"1.230180124","rc":[{"atb":[[2.28,3.38]],"id":56263473},{"spn":2.32,"spf":1.0,"id":65992794}],"con":true,"img":false}]}
{"op":"mcm","clk":"11539850350","pt":1719486945339,"mc":[{"id":"1.230180124","rc":[{"atb":[[2.28,6.54]],"id":56263473}],"con":true,"img":false}]}
{"op":"mcm","clk":"11539898132","pt":1719487560769,"mc":[{"id":"1.230180124","rc":[{"atb":[[3.65,1]],"id":56263473},{"spn":15.82,"spf":"NaN","id":56263473},{"atb":[[3.3,1]],"id":65992794},{"spn":3.3,"spf":1.0,"id":65992794},{"atb":[[5,1]],"id":67245400},{"spn":77.5,"spf":"NaN","id":67245400},{"atb":[[5,1]],"id":42767337},{"spn":77.5,"spf":"NaN","id":42767337},{"atb":[[5,1]],"id":51567147},{"spn":16.5,"spf":"NaN","id":51567147},{"atb":[[5,1]],"id":70902709},{"spn":77.5,"spf":"NaN","id":70902709}],"con":true,"img":false}]}
{"op":"mcm","clk":"11539899512","pt":1719487575085,"mc":[{"id":"1.230180124","rc":[{"atb":[[1.51,196.08]],"id":67245400},{"atb":[[2.12,89.29],[1.51,196.08]],"id":42767337},{"atb":[[1.51,196.08]],"id":51567147},{"atb":[[1.51,196.08]],"id":70902709}],"con":true,"img":false}]}
{"op":"mcm","clk":"11539973022","pt":1719488530799,"mc":[{"id":"1.230180124","rc":[{"atb":[[1.51,196.08]],"id":56263473},{"atb":[[1.51,196.08]],"id":65992794},{"atb":[[2.12,89.29]],"id":67245400},{"atb":[[2.12,89.29]],"id":70902709}],"con":true,"img":false}]}
{"op":"mcm","clk":"11540014403","pt":1719488999456,"mc":[{"id":"1.230180124","rc":[{"atb":[[1.16,150]],"id":56263473},{"atl":[[390,2]],"id":56263473},{"atb":[[1.16,150]],"id":65992794},{"atl":[[270,2]],"id":65992794},{"atb":[[1.16,150]],"id":67245400},{"atl":[[550,2]],"id":67245400},{"atb":[[1.16,150]],"id":42767337},{"atl":[[370,2]],"id":42767337},{"atb":[[1.16,150]],"id":51567147},{"atl":[[500,2]],"id":51567147},{"atb":[[1.16,150]],"id":70902709},{"atl":[[560,2]],"id":70902709}],"con":true,"img":false}]}
{"op":"mcm","clk":"11540136280","pt":1719490399970,"mc":[{"id":"1.230180124","rc":[{"atb":[[2.28,6.54],[2.26,0]],"id":56263473}],"con":true,"img":false}]}
{"op":"mcm","clk":"11540136293","pt":1719490400066,"mc":[{"id":"1.230180124","rc":[{"atb":[[2.3,10.35]],"id":56263473}],"con":true,"img":false}]}
{"op":"mcm","clk":"11540141393","pt":1719490450299,"mc":[{"id":"1.230180124","rc":[{"atb":[[2.28,3.16]],"id":56263473}],"con":true,"img":false}]}
{"op":"mcm","clk":"11540141773","pt":1719490454003,"mc":[{"id":"1.230180124","rc":[{"atb":[[2.32,3.38]],"id":56263473}],"con":true,"img":false}]}
{"op":"mcm","clk":"11540143793","pt":1719490473736,"mc":[{"id":"1.230180124","rc":[{"atb":[[2.28,0]],"id":56263473}],"con":true,"img":false}]}
{"op":"mcm","clk":"11540145737","pt":1719490491640,"mc":[{"id":"1.230180124","rc":[{"atb":[[2.32,6.54]],"id":56263473}],"con":true,"img":false}]}
{"op":"mcm","clk":"11540156729","pt":1719490601376,"mc":[{"id":"1.230180124","rc":[{"atb":[[3.65,0]],"id":56263473},{"spn":15.29,"spf":"NaN","id":56263473},{"atb":[[3.3,0]],"id":65992794},{"spn":2.32,"spf":1.0,"id":65992794},{"atb":[[5,0]],"id":67245400},{"spn":77.1,"spf":"NaN","id":67245400},{"atb":[[5,0]],"id":42767337},{"spn":77.3,"spf":"NaN","id":42767337},{"atb":[[5,0]],"id":51567147},{"spn":15.55,"spf":"NaN","id":51567147},{"atb":[[5,0]],"id":70902709},{"spn":76.77,"spf":"NaN","id":70902709}],"con":true,"img":false}]}
{"op":"mcm","clk":"11540161448","pt":1719490656302,"mc":[{"id":"1.230180124","marketDefinition":{"bspMarket":true,"turnInPlayEnabled":false,"persistenceEnabled":false,"marketBaseRate":5.0,"eventId":"33376437","eventTypeId":"4339","numberOfWinners":1,"bettingType":"ODDS","marketType":"WIN","marketTime":"2024-06-27T15:26:00.000Z","suspendTime":"2024-06-27T15:26:00.000Z","bspReconciled":false,"complete":true,"inPlay":false,"crossMatching":true,"runnersVoidable":false,"numberOfActiveRunners":6,"betDelay":0,"status":"SUSPENDED","runners":[{"status":"ACTIVE","sortPriority":1,"id":42767337,"name":"1. Salacres Liam"},{"status":"ACTIVE","sortPriority":2,"id":56263473,"name":"2. Makeit Spot"},{"status":"ACTIVE","sortPriority":3,"id":67245400,"name":"3. Lillibeth Royale"},{"status":"ACTIVE","sortPriority":4,"id":65992794,"name":"4. Come Back Kid"},{"status":"ACTIVE","sortPriority":5,"id":70902709,"name":"5. Cloud Canine"},{"status":"ACTIVE","sortPriority":6,"id":51567147,"name":"6. Coolemore North"}],"regulators":["MR_INT"],"venue":"Towcester","countryCode":"GB","discountAllowed":true,"timezone":"Europe/London","openDate":"2024-06-27T13:33:00.000Z","version":5995360154,"name":"A4 500m","eventName":"Towcester 27th Jun"},"rc":[],"con":true,"img":false}]}
{"op":"mcm","clk":"11540161621","pt":1719490658770,"mc":[{"id":"1.230180124","marketDefinition":{"bspMarket":true,"turnInPlayEnabled":false,"persistenceEnabled":false,"marketBaseRate":5.0,"eventId":"33376437","eventTypeId":"4339","numberOfWinners":1,"bettingType":"ODDS","marketType":"WIN","marketTime":"2024-06-27T15:26:00.000Z","suspendTime":"2024-06-27T15:26:00.000Z","bspReconciled":false,"complete":true,"inPlay":false,"crossMatching":true,"runnersVoidable":false,"numberOfActiveRunners":6,"betDelay":0,"status":"SUSPENDED","runners":[{"status":"ACTIVE","sortPriority":1,"id":42767337,"name":"1. Salacres Liam"},{"status":"ACTIVE","sortPriority":2,"id":56263473,"name":"2. Makeit Spot"},{"status":"ACTIVE","sortPriority":3,"id":67245400,"name":"3. Lillibeth Royale"},{"status":"ACTIVE","sortPriority":4,"id":65992794,"name":"4. Come Back Kid"},{"status":"ACTIVE","sortPriority":5,"id":70902709,"name":"5. Cloud Canine"},{"status":"ACTIVE","sortPriority":6,"id":51567147,"name":"6. Coolemore North"}],"regulators":["MR_INT"],"venue":"Towcester","countryCode":"GB","discountAllowed":true,"timezone":"Europe/London","openDate":"2024-06-27T13:33:00.000Z","version":5995360160,"name":"A4 500m","eventName":"Towcester 27th Jun"},"rc":[],"con":true,"img":false}]}
{"op":"mcm","clk":"11540161621","pt":1719490658770,"mc":[{"id":"1.230180124","rc":[{"atb":[[2.32,0],[2.3,0],[1.16,0],[1.03,0],[2.58,0],[1.51,0]],"id":56263473},{"atl":[[150,0],[48,0],[390,0],[28,0],[1000,0]],"id":56263473},{"atb":[[2.32,0],[1.16,0],[1.03,0],[1.51,0],[2.16,0]],"id":65992794},{"atl":[[32,0],[270,0],[18.5,0],[150,0],[21,0],[11.5,0],[990,0],[15.5,0]],"id":65992794},{"atb":[[1.01,0],[1.16,0],[2.12,0],[1.51,0],[4.2,0],[2.16,0]],"id":67245400},{"atl":[[550,0],[150,0],[1000,0]],"id":67245400},{"atb":[[4.6,0],[1.16,0],[1.03,0],[2.12,0],[1.51,0],[2.16,0]],"id":42767337},{"atl":[[150,0],[370,0],[1000,0]],"id":42767337},{"atb":[[1.01,0],[1.16,0],[3.1,0],[2.18,0],[1.51,0]],"id":51567147},{"atl":[[150,0],[48,0],[28,0],[990,0],[500,0]],"id":51567147},{"atb":[[2.24,0],[1.01,0],[1.16,0],[2.12,0],[3.55,0],[1.51,0]],"id":70902709},{"atl":[[560,0],[150,0],[1000,0]],"id":70902709}],"con":true,"img":false}]}
{"op":"mcm","clk":"11540161679","pt":1719490659312,"mc":[{"id":"1.230180124","marketDefinition":{"bspMarket":true,"turnInPlayEnabled":false,"persistenceEnabled":false,"marketBaseRate":5.0,"eventId":"33376437","eventTypeId":"4339","numberOfWinners":1,"bettingType":"ODDS","marketType":"WIN","marketTime":"2024-06-27T15:26:00.000Z","suspendTime":"2024-06-27T15:26:00.000Z","bspReconciled":false,"complete":true,"inPlay":false,"crossMatching":true,"runnersVoidable":false,"numberOfActiveRunners":5,"betDelay":0,"status":"SUSPENDED","runners":[{"status":"ACTIVE","sortPriority":1,"id":42767337,"name":"1. Salacres Liam"},{"status":"ACTIVE","sortPriority":2,"id":67245400,"name":"3. Lillibeth Royale"},{"status":"ACTIVE","sortPriority":3,"id":65992794,"name":"4. Come Back Kid"},{"status":"ACTIVE","sortPriority":4,"id":70902709,"name":"5. Cloud Canine"},{"status":"ACTIVE","sortPriority":5,"id":51567147,"name":"6. Coolemore North"},{"status":"REMOVED","sortPriority":6,"removalDate":"2024-06-27T12:17:39.000Z","id":56263473,"name":"2. Makeit Spot"}],"regulators":["MR_INT"],"venue":"Towcester","countryCode":"GB","discountAllowed":true,"timezone":"Europe/London","openDate":"2024-06-27T13:33:00.000Z","version":5995360208,"name":"A4 500m","eventName":"Towcester 27th Jun"},"rc":[],"con":true,"img":false}]}
{"op":"mcm","clk":"11540161690","pt":1719490659439,"mc":[{"id":"1.230180124","marketDefinition":{"bspMarket":true,"turnInPlayEnabled":false,"persistenceEnabled":false,"marketBaseRate":5.0,"eventId":"33376437","eventTypeId":"4339","numberOfWinners":1,"bettingType":"ODDS","marketType":"WIN","marketTime":"2024-06-27T15:26:00.000Z","suspendTime":"2024-06-27T15:26:00.000Z","bspReconciled":false,"complete":true,"inPlay":false,"crossMatching":true,"runnersVoidable":false,"numberOfActiveRunners":5,"betDelay":0,"status":"OPEN","runners":[{"status":"ACTIVE","sortPriority":1,"id":42767337,"name":"1. Salacres Liam"},{"status":"ACTIVE","sortPriority":2,"id":67245400,"name":"3. Lillibeth Royale"},{"status":"ACTIVE","sortPriority":3,"id":65992794,"name":"4. Come Back Kid"},{"status":"ACTIVE","sortPriority":4,"id":70902709,"name":"5. Cloud Canine"},{"status":"ACTIVE","sortPriority":5,"id":51567147,"name":"6. Coolemore North"},{"status":"REMOVED","sortPriority":6,"removalDate":"2024-06-27T12:17:39.000Z","id":56263473,"name":"2. Makeit Spot"}],"regulators":["MR_INT"],"venue":"Towcester","countryCode":"GB","discountAllowed":true,"timezone":"Europe/London","openDate":"2024-06-27T13:33:00.000Z","version":5995360212,"name":"A4 500m","eventName":"Towcester 27th Jun"},"rc":[],"con":true,"img":false}]}
{"op":"mcm","clk":"11540161690","pt":1719490659439,"mc":[{"id":"1.230180124","rc":[{"spn":2.32,"spf":1.0,"id":65992794}],"con":true,"img":false}]}
{"op":"mcm","clk":"11540162013","pt":1719490663651,"mc":[{"id":"1.230180124","rc":[{"atb":[[1.16,150]],"id":65992794},{"atl":[[550,2]],"id":65992794},{"spn":1.58,"spf":1.0,"id":65992794},{"atb":[[1.16,150]],"id":67245400},{"atl":[[390,2]],"id":67245400},{"spn":195.58,"spf":"NaN","id":67245400},{"atb":[[1.16,150]],"id":42767337},{"atl":[[370,2]],"id":42767337},{"spn":185.58,"spf":"NaN","id":42767337},{"atb":[[1.16,150]],"id":51567147},{"atl":[[560,2]],"id":51567147},{"spn":280.58,"spf":"NaN","id":51567147},{"atb":[[1.16,150]],"id":70902709},{"atl":[[270,2]],"id":70902709},{"spn":135.58,"spf":"NaN","id":70902709}],"con":true,"img":false}]}
{"op":"mcm","clk":"11540164681","pt":1719490697883,"mc":[{"id":"1.230180124","rc":[{"atb":[[1.7,17.35]],"id":65992794},{"atb":[[1.75,20.84]],"id":67245400},{"atb":[[1.75,16.37]],"id":42767337},{"atb":[[1.7,18.8]],"id":51567147},{"atb":[[1.72,17.56]],"id":70902709}],"con":true,"img":false}]}
{"op":"mcm","clk":"11540185439","pt":1719490987306,"mc":[{"id":"1.230180124","rc":[{"atl":[[150,4]],"id":65992794},{"spn":1.85,"spf":1.0,"id":65992794},{"atl":[[150,4]],"id":67245400},{"spn":75.87,"spf":"NaN","id":67245400},{"atl":[[150,4]],"id":42767337},{"spn":75.87,"spf":"NaN","id":42767337},{"atl":[[150,4]],"id":51567147},{"spn":75.85,"spf":"NaN","id":51567147},{"atl":[[150,4]],"id":70902709},{"spn":75.86,"spf":"NaN","id":70902709}],"con":true,"img":false}]}
{"op":"mcm","clk":"11540325272","pt":1719493032615,"mc":[{"id":"1.230180124","rc":[{"atb":[[1.01,16.93]],"id":65992794},{"atl":[[1000,0.84]],"id":65992794},{"atb":[[1.01,16.93]],"id":67245400},{"atl":[[1000,0.84]],"id":67245400},{"atb":[[1.01,16.93]],"id":42767337},{"atl":[[990,0.84]],"id":42767337},{"atb":[[1.02,8.46]],"id":51567147},{"atl":[[990,0.84]],"id":51567147},{"atb":[[1.03,5.64]],"id":70902709},{"atl":[[1000,0.84]],"id":70902709}],"con":true,"img":false}]}
{"op":"mcm","clk":"11540620655","pt":1719496536271,"mc":[{"id":"1.230180124","rc":[{"atb":[[1.01,16.95],[1.02,131.27],[1.7,17.37]],"id":65992794},{"atl":[[970,1.24],[1000,0.84]],"id":65992794},{"atb":[[1.01,121.13],[1.75,20.86]],"id":67245400},{"atl":[[990,1.17],[1000,0.84]],"id":67245400},{"atb":[[1.01,16.95],[1.03,106.71],[1.75,16.39]],"id":42767337},{"atl":[[990,0.84],[960,0.86]],"id":42767337},{"atb":[[1.02,154.15],[1.7,18.82]],"id":51567147},{"atl":[[990,0.84],[960,1.62]],"id":51567147},{"atb":[[1.72,17.58],[1.03,5.64],[1.02,168.54]],"id":70902709},{"atl":[[990,2.11],[1000,0.84]],"id":70902709}],"con":true,"img":false}]}
{"op":"mcm","clk":"11540629261","pt":1719496638885,"mc":[{"id":"1.230180124","rc":[{"atl":[[1000,0.18]],"id":65992794},{"atl":[[1000,0.18]],"id":67245400},{"atl":[[990,0.18]],"id":42767337},{"atl":[[990,0.18]],"id":51567147},{"atl":[[1000,0.18]],"id":70902709}],"con":true,"img":false}]}
{"op":"mcm","clk":"11540635212","pt":1719496713086,"mc":[{"id":"1.230180124","rc":[{"atb":[[2.68,1.34]],"id":65992794},{"spn":2.68,"spf":1.0,"id":65992794},{"atb":[[5,1]],"id":67245400},{"spn":77.5,"spf":"NaN","id":67245400},{"atb":[[5,1]],"id":42767337},{"spn":77.5,"spf":"NaN","id":42767337},{"atb":[[4.1,1]],"id":51567147},{"spn":77.05,"spf":"NaN","id":51567147},{"atb":[[5,1]],"id":70902709},{"spn":77.5,"spf":"NaN","id":70902709}],"con":true,"img":false}]}
{"op":"mcm","clk":"11540685094","pt":1719497282629,"mc":[{"id":"1.230180124","marketDefinition":{"bspMarket":true,"turnInPlayEnabled":false,"persistenceEnabled":false,"marketBaseRate":5.0,"eventId":"33376437","eventTypeId":"4339","numberOfWinners":1,"bettingType":"ODDS","marketType":"WIN","marketTime":"2024-06-27T15:26:00.000Z","suspendTime":"2024-06-27T15:26:00.000Z","bspReconciled":false,"complete":true,"inPlay":false,"crossMatching":true,"runnersVoidable":false,"numberOfActiveRunners":5,"betDelay":0,"status":"OPEN","runners":[{"status":"ACTIVE","sortPriority":1,"id":42767337,"name":"1. Salacres Liam"},{"status":"ACTIVE","sortPriority":2,"id":67245400,"name":"3. Lillibeth Royale"},{"status":"ACTIVE","sortPriority":3,"id":65992794,"name":"4. Come Back Kid"},{"status":"ACTIVE","sortPriority":4,"id":70902709,"name":"5. Cloud Canine"},{"status":"ACTIVE","sortPriority":5,"id":51567147,"name":"6. Coolemore North"},{"status":"REMOVED","sortPriority":6,"removalDate":"2024-06-27T12:17:39.000Z","id":56263473,"name":"2. Makeit Spot"}],"regulators":["MR_INT"],"venue":"Towcester","countryCode":"GB","discountAllowed":true,"timezone":"Europe/London","openDate":"2024-06-27T13:33:00.000Z","version":5995360212,"name":"A4 500m","eventName":"Towcester 27th Jun"},"rc":[{"spl":[[2,1]],"id":65992794},{"atb":[[1.01,16.94],[1.16,150],[1.02,131.22],[1.7,17.37],[2.68,1.34]],"id":65992794},{"atl":[[550,2],[150,4],[970,1.24],[1000,0.18]],"id":65992794},{"spn":2.68,"spf":1.0,"id":65992794},{"atb":[[1.01,121.08],[5,1],[1.16,150],[1.75,20.86]],"id":67245400},{"atl":[[150,4],[390,2],[990,1.17],[1000,0.18]],"id":67245400},{"spn":77.5,"spf":"NaN","id":67245400},{"atb":[[1.01,16.94],[5,1],[1.16,150],[1.03,106.67],[1.75,16.39]],"id":42767337},{"atl":[[150,4],[370,2],[960,0.86],[990,0.18]],"id":42767337},{"spn":77.5,"spf":"NaN","id":42767337},{"atb":[[1.16,150],[4.1,1],[1.02,154.08],[1.7,18.81]],"id":51567147},{"atl":[[560,2],[150,4],[960,1.62],[990,0.18]],"id":51567147},{"spn":77.05,"spf":"NaN","id":51567147},{"atb":[[1.72,17.57],[5,1],[1.16,150],[1.03,5.64],[1.02,168.47]],"id":70902709},{"atl":[[270,2],[150,4],[990,2.11],[1000,0.18]],"id":70902709},{"spn":77.5,"spf":"NaN","id":70902709}],"con":true,"img":true}]}
{"op":"mcm","clk":"11540721492","pt":1719497663530,"mc":[{"id":"1.230180124","rc":[{"spl":[[1.01,1]],"id":65992794},{"atb":[[1.01,16.94],[1.02,131.22],[1.7,17.37]],"id":65992794},{"atl":[[970,1.24]],"id":65992794},{"spn":2.35,"spf":1.0,"id":65992794},{"atb":[[1.01,121.08],[1.75,20.86]],"id":67245400},{"atl":[[990,1.17]],"id":67245400},{"atb":[[1.01,16.94],[1.03,106.67],[1.75,16.39]],"id":42767337},{"atl":[[960,0.86]],"id":42767337},{"atb":[[1.02,154.08],[1.7,18.81]],"id":51567147},{"atl":[[960,1.62]],"id":51567147},{"atb":[[1.72,17.57],[1.03,5.64],[1.02,168.47]],"id":70902709},{"atl":[[990,2.11]],"id":70902709}],"con":true,"img":false}]}
{"op":"mcm","clk":"11540722140","pt":1719497671257,"mc":[{"id":"1.230180124","rc":[{"atb":[[1.51,196.08]],"id":67245400},{"atb":[[1.51,196.08]],"id":42767337},{"atb":[[1.51,196.08]],"id":51567147},{"atb":[[1.51,196.08]],"id":70902709}],"con":true,"img":false}]}
{"op":"mcm","clk":"11540959063","pt":1719500464393,"mc":[{"id":"1.230180124","rc":[{"atb":[[1.01,16.95],[1.02,131.24],[1.7,17.37]],"id":65992794},{"atl":[[970,1.24]],"id":65992794},{"atb":[[1.01,121.1],[1.75,20.86]],"id":67245400},{"atl":[[990,1.17]],"id":67245400},{"atb":[[1.01,16.95],[1.03,106.68],[1.02,2],[1.75,16.39]],"id":42767337},{"atl":[[960,0.86]],"id":42767337},{"atb":[[1.02,154.11],[1.7,18.82]],"id":51567147},{"atl":[[960,1.62]],"id":51567147},{"atb":[[1.72,17.57],[1.03,5.64],[1.02,168.5]],"id":70902709},{"atl":[[990,2.11]],"id":70902709}],"con":true,"img":false}]}
{"op":"mcm","clk":"11540959096","pt":1719500464761,"mc":[{"id":"1.230180124","rc":[{"atb":[[1.02,2]],"id":67245400}],"con":true,"img":false}]}
{"op":"mcm","clk":"11540959118","pt":1719500465065,"mc":[{"id":"1.230180124","rc":[{"atb":[[1.02,133.24]],"id":65992794}],"con":true,"img":false}]}
{"op":"mcm","clk":"11540959135","pt":1719500465375,"mc":[{"id":"1.230180124","rc":[{"atb":[[1.02,170.5]],"id":70902709}],"con":true,"img":false}]}
{"op":"mcm","clk":"11540959160","pt":1719500465787,"mc":[{"id":"1.230180124","rc":[{"atb":[[1.02,156.11]],"id":51567147}],"con":true,"img":false}]}
{"op":"mcm","clk":"11540959546","pt":1719500471166,"mc":[{"id":"1.230180124","rc":[{"atl":[[190,4]],"id":65992794},{"atl":[[190,4]],"id":67245400},{"atl":[[190,4]],"id":42767337},{"atl":[[190,4]],"id":51567147},{"atl":[[190,4]],"id":70902709}],"con":true,"img":false}]}
{"op":"mcm","clk":"11540969798","pt":1719500603419,"mc":[{"id":"1.230180124","rc":[{"atb":[[4.1,10]],"id":67245400}],"con":true,"img":false}]}
{"op":"mcm","clk":"11540969823","pt":1719500603625,"mc":[{"id":"1.230180124","rc":[{"atb":[[4.1,0]],"id":67245400}],"con":true,"img":false}]}
{"op":"mcm","clk":"11540988687","pt":1719500824282,"mc":[{"id":"1.230180124","rc":[{"spl":[[1.01,4]],"id":42767337},{"spn":2.56,"spf":1.0,"id":42767337}],"con":true,"img":false}]}
{"op":"mcm","clk":"11541003303","pt":1719501009543,"mc":[{"id":"1.230180124","rc":[{"atl":[[140,0.84]],"id":70902709},{"spn":72.5,"spf":"NaN","id":70902709}],"con":true,"img":false}]}
{"op":"mcm","clk":"11541006768","pt":1719501057411,"mc":[{"id":"1.230180124","rc":[{"atb":[[1.12,1.69]],"id":67245400},{"atb":[[1.12,1.69]],"id":42767337}],"con":true,"img":false}]}
{"op":"mcm","clk":"11541006791","pt":1719501057715,"mc":[{"id":"1.230180124","rc":[{"atb":[[1.09,1.69]],"id":51567147},{"atb":[[1.12,1.69]],"id":70902709}],"con":true,"img":false}]}
{"op":"mcm","clk":"11541006814","pt":1719501057981,"mc":[{"id":"1.230180124","rc":[{"atb":[[1.12,0.05]],"id":67245400},{"atb":[[1.12,0.05]],"id":42767337}],"con":true,"img":false}]}
{"op":"mcm","clk":"11541006837","pt":1719501058293,"mc":[{"id":"1.230180124","rc":[{"atb":[[1.07,1.69]],"id":65992794},{"atb":[[1.09,0.07]],"id":51567147}],"con":true,"img":false}]}
{"op":"mcm","clk":"11541006862","pt":1719501058600,"mc":[{"id":"1.230180124","rc":[{"atb":[[1.12,0]],"id":42767337},{"atb":[[1.12,0.05]],"id":70902709}],"con":true,"img":false}]}
{"op":"mcm","clk":"11541006871","pt":1719501058706,"mc":[{"id":"1.230180124","rc":[{"atb":[[5.1,0.05]],"id":42767337}],"con":true,"img":false}]}
{"op":"mcm","clk":"11541006892","pt":1719501059018,"mc":[{"id":"1.230180124","rc":[{"atb":[[1.12,0]],"id":67245400}],"con":true,"img":false}]}
{"op":"mcm","clk":"11541006900","pt":1719501059124,"mc":[{"id":"1.230180124","rc":[{"atb":[[5.1,0.05]],"id":67245400}],"con":true,"img":false}]}
{"op":"mcm","clk":"11541006924","pt":1719501059385,"mc":[{"id":"1.230180124","rc":[{"atb":[[1.07,0.11]],"id":65992794},{"atb":[[1.09,0]],"id":51567147}],"con":true,"img":false}]}
{"op":"mcm","clk":"11541006933","pt":1719501059484,"mc":[{"id":"1.230180124","rc":[{"atb":[[4.2,0.07]],"id":51567147}],"con":true,"img":false}]}
{"op":"mcm","clk":"11541006946","pt":1719501059793,"mc":[{"id":"1.230180124","rc":[{"atb":[[1.12,0]],"id":70902709}],"con":true,"img":false}]}
{"op":"mcm","clk":"11541006952","pt":1719501059895,"mc":[{"id":"1.230180124","rc":[{"atb":[[5.1,0.05]],"id":70902709}],"con":true,"img":false}]}
{"op":"mcm","clk":"11541006960","pt":1719501060109,"mc":[{"id":"1.230180124","rc":[{"atl":[[140,2]],"id":65992794}],"con":true,"img":false}]}
{"op":"mcm","clk":"11541006969","pt":1719501060207,"mc":[{"id":"1.230180124","rc":[{"atb":[[2.3,17.38],[1.07,0]],"id":65992794},{"atl":[[13.5,4]],"id":65992794}],"con":true,"img":false}]}
{"op":"mcm","clk":"11541006975","pt":1719501060311,"mc":[{"id":"1.230180124","rc":[{"atb":[[2.7,0.11]],"id":65992794},{"atb":[[2.76,56.82]],"id":67245400},{"atl":[[140,2]],"id":67245400},{"atb":[[2.84,54.35]],"id":42767337},{"atl":[[140,2]],"id":42767337},{"atb":[[2.54,64.94]],"id":51567147},{"atl":[[90,2]],"id":51567147},{"atb":[[2.7,58.82]],"id":70902709},{"atl":[[140,2.84]],"id":70902709}],"con":true,"img":false}]}
{"op":"mcm","clk":"11541006997","pt":1719501060620,"mc":[{"id":"1.230180124","rc":[{"atl":[[140,0]],"id":65992794}],"con":true,"img":false}]}
{"op":"mcm","clk":"11541007085","pt":1719501061981,"mc":[{"id":"1.230180124","rc":[{"atl":[[11.5,4],[13.5,0]],"id":65992794}],"con":true,"img":false}]}
{"op":"mcm","clk":"11541007106","pt":1719501062293,"mc":[{"id":"1.230180124","rc":[{"atl":[[13,1.67]],"id":65992794}],"con":true,"img":false}]}
{"op":"mcm","clk":"11541007197","pt":1719501063596,"mc":[{"id":"1.230180124","rc":[{"atb":[[1.01,18.65]],"id":65992794},{"atl":[[1000,1.88]],"id":65992794},{"atb":[[1.02,3.7]],"id":67245400},{"atl":[[1000,1.88]],"id":67245400},{"atb":[[1.02,3.7]],"id":42767337},{"atl":[[1000,1.7]],"id":42767337}],"con":true,"img":false}]}
{"op":"mcm","clk":"11541007219","pt":1719501063820,"mc":[{"id":"1.230180124","rc":[{"atb":[[1.01,17.19]],"id":65992794},{"atl":[[1000,0.21]],"id":65992794},{"atb":[[1.02,2.17]],"id":67245400},{"atl":[[1000,0.18]],"id":67245400},{"atb":[[1.02,2.17]],"id":42767337},{"atl":[[1000,0]],"id":42767337}],"con":true,"img":false}]}
{"op":"mcm","clk":"11541007239","pt":1719501064020,"mc":[{"id":"1.230180124","rc":[{"atb":[[1.01,16.95]],"id":65992794},{"atl":[[1000,0.18]],"id":65992794},{"atb":[[1.02,2]],"id":67245400},{"atb":[[1.02,2]],"id":42767337}],"con":true,"img":false}]}
{"op":"mcm","clk":"11541007246","pt":1719501064123,"mc":[{"id":"1.230180124","rc":[{"atb":[[2.32,0.24]],"id":65992794},{"atl":[[11,0.03]],"id":65992794},{"atb":[[2.78,0.17]],"id":67245400},{"atb":[[2.86,0.17]],"id":42767337}],"con":true,"img":false}]}
{"op":"mcm","clk":"11541007345","pt":1719501065313,"mc":[{"id":"1.230180124","rc":[{"atl":[[13,0]],"id":65992794}],"con":true,"img":false}]}
{"op":"mcm","clk":"11541007533","pt":1719501068320,"mc":[{"id":"1.230180124","rc":[{"atl":[[11,1.67]],"id":65992794}],"con":true,"img":false}]}
{"op":"mcm","clk":"11541007681","pt":1719501070941,"mc":[{"id":"1.230180124","rc":[{"spn":2.57,"spf":1.0,"id":65992794},{"spn":72.55,"spf":"NaN","id":67245400},{"spn":3.41,"spf":1.0,"id":42767337},{"atl":[[70,2],[90,0]],"id":51567147},{"spn":37.1,"spf":"NaN","id":51567147},{"spn":72.55,"spf":"NaN","id":70902709}],"con":true,"img":false}]}
{"op":"mcm","clk":"11541007791","pt":1719501072102,"mc":[{"id":"1.230180124","rc":[{"atl":[[10.5,2]],"id":65992794}],"con":true,"img":false}]}
{"op":"mcm","clk":"11541007806","pt":1719501072415,"mc":[{"id":"1.230180124","rc":[{"atl":[[10.5,4]],"id":65992794}],"con":true,"img":false}]}
{"op":"mcm","clk":"11541007815","pt":1719501072523,"mc":[{"id":"1.230180124","rc":[{"atl":[[11.5,0]],"id":65992794}],"con":true,"img":false}]}
{"op":"mcm","clk":"11541007960","pt":1719501074393,"mc":[{"id":"1.230180124","rc":[{"atl":[[11,0.03]],"id":65992794}],"con":true,"img":false}]}
{"op":"mcm","clk":"11541008147","pt":1719501077305,"mc":[{"id":"1.230180124","rc":[{"atl":[[10,1.57]],"id":65992794}],"con":true,"img":false}]}
{"op":"mcm","clk":"11541008151","pt":1719501077409,"mc":[{"id":"1.230180124","rc":[{"atl":[[10.5,2]],"id":65992794}],"con":true,"img":false}]}
{"op":"mcm","clk":"11541008261","pt":1719501079318,"mc":[{"id":"1.230180124","rc":[{"atl":[[9.8,2]],"id":65992794}],"con":true,"img":false}]}
{"op":"mcm","clk":"11541008319","pt":1719501080364,"mc":[{"id":"1.230180124","rc":[{"atl":[[10,0]],"id":65992794}],"con":true,"img":false}]}
{"op":"mcm","clk":"11541008476","pt":1719501082453,"mc":[{"id":"1.230180124","rc":[{"atl":[[10.5,0],[9.8,4]],"id":65992794}],"con":true,"img":false}]}
{"op":"mcm","clk":"11541008482","pt":1719501082553,"mc":[{"id":"1.230180124","rc":[{"atl":[[11,4.03],[9.8,2]],"id":65992794}],"con":true,"img":false}]}
{"op":"mcm","clk":"11541008488","pt":1719501082657,"mc":[{"id":"1.230180124","rc":[{"atl":[[11,0.03],[9.8,6]],"id":65992794}],"con":true,"img":false}]}
{"op":"mcm","clk":"11541008495","pt":1719501082722,"mc":[{"id":"1.230180124","rc":[{"atl":[[11.5,6.03],[9.8,2]],"id":65992794}],"con":true,"img":false}]}
{"op":"mcm","clk":"11541008504","pt":1719501082827,"mc":[{"id":"1.230180124","rc":[{"atl":[[11.5,0],[9.8,6]],"id":65992794}],"con":true,"img":false}]}
{"op":"mcm","clk":"11541008513","pt":1719501082919,"mc":[{"id":"1.230180124","rc":[{"atl":[[11.5,4]],"id":65992794}],"con":true,"img":false}]}
{"op":"mcm","clk":"11541008519","pt":1719501083033,"mc":[{"id":"1.230180124","rc":[{"atl":[[9.8,2]],"id":65992794}],"con":true,"img":false}]}
{"op":"mcm","clk":"11541008525","pt":1719501083127,"mc":[{"id":"1.230180124","rc":[{"atl":[[11.5,0],[9.8,6]],"id":65992794}],"con":true,"img":false}]}
{"op":"mcm","clk":"11541008530","pt":1719501083236,"mc":[{"id":"1.230180124","rc":[{"atl":[[11.5,4]],"id":65992794}],"con":true,"img":false}]}
{"op":"mcm","clk":"11541008542","pt":1719501083441,"mc":[{"id":"1.230180124","rc":[{"atl":[[9.8,2]],"id":65992794}],"con":true,"img":false}]}
{"op":"mcm","clk":"11541008624","pt":1719501084523,"mc":[{"id":"1.230180124","rc":[{"atl":[[9.8,0]],"id":65992794}],"con":true,"img":false}]}
{"op":"mcm","clk":"11541008750","pt":1719501086333,"mc":[{"id":"1.230180124","rc":[{"atl":[[11,1.7]],"id":65992794}],"con":true,"img":false}]}
{"op":"mcm","clk":"11541008778","pt":1719501086746,"mc":[{"id":"1.230180124","rc":[{"atl":[[10.5,2]],"id":65992794}],"con":true,"img":false}]}
{"op":"mcm","clk":"11541008969","pt":1719501089546,"mc":[{"id":"1.230180124","rc":[{"atl":[[11,0.03]],"id":65992794}],"con":true,"img":false}]}
{"op":"mcm","clk":"11541009154","pt":1719501091930,"mc":[{"id":"1.230180124","rc":[{"atl":[[10.5,0]],"id":65992794}],"con":true,"img":false}]}
{"op":"mcm","clk":"11541009288","pt":1719501093856,"mc":[{"id":"1.230180124","rc":[{"atl":[[11,2.03]],"id":65992794}],"con":true,"img":false}]}
{"op":"mcm","clk":"11541009390","pt":1719501095461,"mc":[{"id":"1.230180124","rc":[{"atl":[[10.5,1.54]],"id":65992794}],"con":true,"img":false}]}
{"op":"mcm","clk":"11541009397","pt":1719501095559,"mc":[{"id":"1.230180124","rc":[{"atl":[[10.5,3.57],[11.5,0]],"id":65992794}],"con":true,"img":false}]}
{"op":"mcm","clk":"11541009655","pt":1719501099174,"mc":[{"id":"1.230180124","rc":[{"atl":[[11,0.03]],"id":65992794}],"con":true,"img":false}]}
{"op":"mcm","clk":"11541009774","pt":1719501101054,"mc":[{"id":"1.230180124","rc":[{"atl":[[10,2]],"id":65992794}],"con":true,"img":false}]}
{"op":"mcm","clk":"11541009900","pt":1719501102654,"mc":[{"id":"1.230180124","rc":[{"atb":[[2.32,0]],"id":65992794},{"atl":[[11,0]],"id":65992794},{"atb":[[2.78,0]],"id":67245400},{"atb":[[2.86,0]],"id":42767337}],"con":true,"img":false}]}
{"op":"mcm","clk":"11541010046","pt":1719501104575,"mc":[{"id":"1.230180124","rc":[{"atl":[[10.5,2.03]],"id":65992794}],"con":true,"img":false}]}
{"op":"mcm","clk":"11541010197","pt":1719501106347,"mc":[{"id":"1.230180124","rc":[{"atl":[[10,0]],"id":65992794}],"con":true,"img":false}]}
{"op":"mcm","clk":"11541010218","pt":1719501106554,"mc":[{"id":"1.230180124","rc":[{"atl":[[10.5,0],[11.5,4.06]],"id":65992794}],"con":true,"img":false}]}
{"op":"mcm","clk":"11541010280","pt":1719501107447,"mc":[{"id":"1.230180124","rc":[{"atl":[[11,1.74]],"id":65992794}],"con":true,"img":false}]}
{"op":"mcm","clk":"11541010330","pt":1719501108163,"mc":[{"id":"1.230180124","rc":[{"atl":[[10.5,2]],"id":65992794}],"con":true,"img":false}]}
{"op":"mcm","clk":"11541010514","pt":1719501110563,"mc":[{"id":"1.230180124","rc":[{"atl":[[11,0]],"id":65992794}],"con":true,"img":false}]}
{"op":"mcm","clk":"11541010745","pt":1719501113394,"mc":[{"id":"1.230180124","rc":[{"atl":[[10.5,0]],"id":65992794}],"con":true,"img":false}]}
{"op":"mcm","clk":"11541010870","pt":1719501115386,"mc":[{"id":"1.230180124","rc":[{"atl":[[11,2]],"id":65992794}],"con":true,"img":false}]}
{"op":"mcm","clk":"11541010950","pt":1719501116584,"mc":[{"id":"1.230180124","rc":[{"atl":[[10.5,1.69]],"id":65992794}],"con":true,"img":false}]}
{"op":"mcm","clk":"11541010966","pt":1719501116743,"mc":[{"id":"1.230180124","rc":[{"atl":[[10.5,3.69],[11.5,0]],"id":65992794}],"con":true,"img":false}]}
{"op":"mcm","clk":"11541010998","pt":1719501117167,"mc":[{"id":"1.230180124","rc":[{"atl":[[11,0]],"id":65992794}],"con":true,"img":false}]}
{"op":"mcm","clk":"11541011380","pt":1719501122485,"mc":[{"id":"1.230180124","rc":[{"atl":[[10,2]],"id":65992794}],"con":true,"img":false}]}
{"op":"mcm","clk":"11541011616","pt":1719501125684,"mc":[{"id":"1.230180124","rc":[{"atl":[[10.5,2]],"id":65992794}],"con":true,"img":false}]}
{"op":"mcm","clk":"11541011773","pt":1719501127786,"mc":[{"id":"1.230180124","rc":[{"atl":[[10,0]],"id":65992794}],"con":true,"img":false}]}
{"op":"mcm","clk":"11541011781","pt":1719501127891,"mc":[{"id":"1.230180124","rc":[{"atl":[[11.5,4]],"id":65992794}],"con":true,"img":false}]}
{"op":"mcm","clk":"11541011788","pt":1719501127996,"mc":[{"id":"1.230180124","rc":[{"atl":[[10.5,0]],"id":65992794}],"con":true,"img":false}]}
{"op":"mcm","clk":"11541011907","pt":1719501129582,"mc":[{"id":"1.230180124","rc":[{"atl":[[11,2]],"id":65992794}],"con":true,"img":false}]}
{"op":"mcm","clk":"11541012073","pt":1719501131586,"mc":[{"id":"1.230180124","rc":[{"atl":[[10.5,1.59]],"id":65992794},{"spn":2.57,"spf":1.0,"id":65992794},{"spn":3.41,"spf":1.0,"id":42767337}],"con":true,"img":false}]}
{"op":"mcm","clk":"11541012330","pt":1719501134908,"mc":[{"id":"1.230180124","rc":[{"atl":[[11,0]],"id":65992794}],"con":true,"img":false}]}
{"op":"mcm","clk":"11541012451","pt":1719501136706,"mc":[{"id":"1.230180124","rc":[{"atl":[[10,2]],"id":65992794}],"con":true,"img":false}]}
{"op":"mcm","clk":"11541012502","pt":1719501137412,"mc":[{"id":"1.230180124","rc":[{"atl":[[10,4],[11.5,0]],"id":65992794}],"con":true,"img":false}]}
{"op":"mcm","clk":"11541012537","pt":1719501137775,"mc":[{"id":"1.230180124","rc":[{"atl":[[10.5,0]],"id":65992794}],"con":true,"img":false}]}
{"op":"mcm","clk":"11541012762","pt":1719501140783,"mc":[{"id":"1.230180124","rc":[{"atl":[[9.8,1.51]],"id":65992794}],"con":true,"img":false}]}
{"op":"mcm","clk":"11541012847","pt":1719501141921,"mc":[{"id":"1.230180124","rc":[{"atl":[[10,2]],"id":65992794}],"con":true,"img":false}]}
{"op":"mcm","clk":"11541013027","pt":1719501143914,"mc":[{"id":"1.230180124","rc":[{"atl":[[9.6,2]],"id":65992794}],"con":true,"img":false}]}
{"op":"mcm","clk":"11541013278","pt":1719501146793,"mc":[{"id":"1.230180124","rc":[{"atl":[[9.6,4],[10,0],[9.8,0]],"id":65992794}],"con":true,"img":false}]}
{"op":"mcm","clk":"11541013467","pt":1719501149109,"mc":[{"id":"1.230180124","rc":[{"atl":[[9.6,2]],"id":65992794}],"con":true,"img":false}]}
{"op":"mcm","clk":"11541013570","pt":1719501150404,"mc":[{"id":"1.230180124","rc":[{"atl":[[1000,1.18]],"id":65992794}],"con":true,"img":false}]}
{"op":"mcm","clk":"11541013591","pt":1719501150721,"mc":[{"id":"1.230180124","rc":[{"atl":[[1000,0.21]],"id":65992794}],"con":true,"img":false}]}
{"op":"mcm","clk":"11541013620","pt":1719501151023,"mc":[{"id":"1.230180124","rc":[{"atl":[[1000,0.18]],"id":65992794}],"con":true,"img":false}]}
{"op":"mcm","clk":"11541013629","pt":1719501151128,"mc":[{"id":"1.230180124","rc":[{"atl":[[9.4,2.03]],"id":65992794}],"con":true,"img":false}]}
{"op":"mcm","clk":"11541013974","pt":1719501156209,"mc":[{"id":"1.230180124","rc":[{"atl":[[9.2,1.64]],"id":65992794}],"con":true,"img":false}]}
{"op":"mcm","clk":"11541013989","pt":1719501156291,"mc":[{"id":"1.230180124","rc":[{"atl":[[9.6,0],[9.2,3.64],[9.4,0.03]],"id":65992794}],"con":true,"img":false}]}
{"op":"mcm","clk":"11541013997","pt":1719501156475,"mc":[{"id":"1.230180124","rc":[{"atl":[[9.2,1.64],[9.4,3.31]],"id":65992794}],"con":true,"img":false}]}
{"op":"mcm","clk":"11541014096","pt":1719501157531,"mc":[{"id":"1.230180124","rc":[{"atl":[[9.4,3.28]],"id":65992794}],"con":true,"img":false}]}
{"op":"mcm","clk":"11541014107","pt":1719501157628,"mc":[{"id":"1.230180124","rc":[{"atl":[[9,0.03]],"id":65992794}],"con":true,"img":false}]}
{"op":"mcm","clk":"11541014165","pt":1719501158296,"mc":[{"id":"1.230180124","rc":[{"atl":[[9,2.03]],"id":65992794}],"con":true,"img":false}]}
{"op":"mcm","clk":"11541014185","pt":1719501158506,"mc":[{"id":"1.230180124","rc":[{"atl":[[9,4.06],[9.4,0]],"id":65992794}],"con":true,"img":false}]}
{"op":"mcm","clk":"11541014195","pt":1719501158610,"mc":[{"id":"1.230180124","rc":[{"atl":[[9.2,5.7]],"id":65992794}],"con":true,"img":false}]}
{"op":"mcm","clk":"11541014205","pt":1719501158708,"mc":[{"id":"1.230180124","rc":[{"atl":[[9,2.03]],"id":65992794}],"con":true,"img":false}]}
{"op":"mcm","clk":"11541014458","pt":1719501161708,"mc":[{"id":"1.230180124","rc":[{"atl":[[9.2,4.06]],"id":65992794}],"con":true,"img":false}]}
{"op":"mcm","clk":"11541014634","pt":1719501163529,"mc":[{"id":"1.230180124","rc":[{"atl":[[9,0.03]],"id":65992794}],"con":true,"img":false}]}
{"op":"mcm","clk":"11541014658","pt":1719501163733,"mc":[{"id":"1.230180124","rc":[{"atl":[[9.2,0],[11.5,4.09]],"id":65992794}],"con":true,"img":false}]}
{"op":"mcm","clk":"11541014824","pt":1719501165440,"mc":[{"id":"1.230180124","rc":[{"atl":[[11,2]],"id":65992794}],"con":true,"img":false}]}
{"op":"mcm","clk":"11541014861","pt":1719501165704,"mc":[{"id":"1.230180124","rc":[{"atl":[[10.5,0.84]],"id":65992794}],"con":true,"img":false}]}
{"op":"mcm","clk":"11541014870","pt":1719501165812,"mc":[{"id":"1.230180124","rc":[{"atl":[[10.5,2.84],[11.5,0]],"id":65992794}],"con":true,"img":false}]}
{"op":"mcm","clk":"11541014894","pt":1719501166125,"mc":[{"id":"1.230180124","rc":[{"atl":[[11,0]],"id":65992794}],"con":true,"img":false}]}
{"op":"mcm","clk":"11541015040","pt":1719501167727,"mc":[{"id":"1.230180124","rc":[{"atl":[[10,1.54]],"id":65992794}],"con":true,"img":false}]}
{"op":"mcm","clk":"11541015500","pt":1719501172531,"mc":[{"id":"1.230180124","rc":[{"atl":[[9.8,2]],"id":65992794}],"con":true,"img":false}]}
{"op":"mcm","clk":"11541015522","pt":1719501172743,"mc":[{"id":"1.230180124","rc":[{"atl":[[9.8,2.84]],"id":65992794}],"con":true,"img":false}]}
{"op":"mcm","clk":"11541015578","pt":1719501173216,"mc":[{"id":"1.230180124","rc":[{"atl":[[10.5,2]],"id":65992794}],"con":true,"img":false}]}
{"op":"mcm","clk":"11541015625","pt":1719501173725,"mc":[{"id":"1.230180124","rc":[{"atl":[[10,0]],"id":65992794}],"con":true,"img":false}]}
{"op":"mcm","clk":"11541015751","pt":1719501174912,"mc":[{"id":"1.230180124","rc":[{"atl":[[10.5,0],[9.8,5.69]],"id":65992794}],"con":true,"img":false}]}
{"op":"mcm","clk":"11541015990","pt":1719501177450,"mc":[{"id":"1.230180124","rc":[{"atl":[[9.6,1.65]],"id":65992794}],"con":true,"img":false}]}
{"op":"mcm","clk":"11541016021","pt":1719501177757,"mc":[{"id":"1.230180124","rc":[{"atl":[[9.8,3.69]],"id":65992794}],"con":true,"img":false}]}
{"op":"mcm","clk":"11541016043","pt":1719501177920,"mc":[{"id":"1.230180124","rc":[{"atb":[[5.1,0]],"id":42767337}],"con":true,"img":false}]}
{"op":"mcm","clk":"11541016115","pt":1719501178738,"mc":[{"id":"1.230180124","rc":[{"atb":[[5.1,0]],"id":70902709}],"con":true,"img":false}]}
{"op":"mcm","clk":"11541016178","pt":1719501179358,"mc":[{"id":"1.230180124","rc":[{"atb":[[5.1,0]],"id":67245400}],"con":true,"img":false}]}
{"op":"mcm","clk":"11541016216","pt":1719501179720,"mc":[{"id":"1.230180124","rc":[{"atl":[[9.4,2]],"id":65992794}],"con":true,"img":false}]}
{"op":"mcm","clk":"11541016264","pt":1719501180239,"mc":[{"id":"1.230180124","rc":[{"atl":[[9.2,0.84],[9.8,2.85]],"id":65992794},{"atb":[[10,5]],"id":42767337}],"con":true,"img":false}]}
{"op":"mcm","clk":"11541016276","pt":1719501180345,"mc":[{"id":"1.230180124","rc":[{"atb":[[2.7,0]],"id":65992794},{"atb":[[5.2,16.39],[2.84,0]],"id":42767337}],"con":true,"img":false}]}
{"op":"mcm","clk":"11541016286","pt":1719501180450,"mc":[{"id":"1.230180124","rc":[{"atl":[[9.4,0]],"id":65992794}],"con":true,"img":false}]}
{"op":"mcm","clk":"11541016305","pt":1719501180660,"mc":[{"id":"1.230180124","rc":[{"atb":[[10.5,0.84]],"id":42767337}],"con":true,"img":false}]}
{"op":"mcm","clk":"11541016372","pt":1719501181338,"mc":[{"id":"1.230180124","rc":[{"atb":[[1.12,1.69]],"id":42767337},{"atb":[[4.2,0]],"id":51567147}],"con":true,"img":false}]}
{"op":"mcm","clk":"11541016401","pt":1719501181653,"mc":[{"id":"1.230180124","rc":[{"atb":[[1.12,1.69]],"id":67245400},{"atb":[[1.12,1.69]],"id":70902709}],"con":true,"img":false}]}
{"op":"mcm","clk":"11541016426","pt":1719501181962,"mc":[{"id":"1.230180124","rc":[{"atb":[[1.07,1.69]],"id":65992794},{"atb":[[1.09,1.69]],"id":51567147}],"con":true,"img":false}]}
{"op":"mcm","clk":"11541016461","pt":1719501182326,"mc":[{"id":"1.230180124","rc":[{"atb":[[1.07,0.11]],"id":65992794},{"atb":[[1.12,0.05]],"id":42767337}],"con":true,"img":false}]}
{"op":"mcm","clk":"11541016472","pt":1719501182426,"mc":[{"id":"1.230180124","rc":[{"atb":[[5,0]],"id":42767337}],"con":true,"img":false}]}
{"op":"mcm","clk":"11541016493","pt":1719501182641,"mc":[{"id":"1.230180124","rc":[{"atb":[[1.09,0.07]],"id":51567147},{"atb":[[1.12,0.05]],"id":70902709}],"con":true,"img":false}]}
{"op":"mcm","clk":"11541016515","pt":1719501182957,"mc":[{"id":"1.230180124","rc":[{"atb":[[1.12,0.05]],"id":67245400}],"con":true,"img":false}]}
{"op":"mcm","clk":"11541016551","pt":1719501183318,"mc":[{"id":"1.230180124","rc":[{"atb":[[1.12,0]],"id":42767337}],"con":true,"img":false}]}
{"op":"mcm","clk":"11541016561","pt":1719501183424,"mc":[{"id":"1.230180124","rc":[{"atb":[[5.1,0.05]],"id":42767337}],"con":true,"img":false}]}
{"op":"mcm","clk":"11541016590","pt":1719501183731,"mc":[{"id":"1.230180124","rc":[{"atb":[[1.07,0]],"id":65992794}],"con":true,"img":false}]}
{"op":"mcm","clk":"11541016600","pt":1719501183843,"mc":[{"id":"1.230180124","rc":[{"atb":[[2.7,0.11]],"id":65992794}],"con":true,"img":false}]}
{"op":"mcm","clk":"11541016611","pt":1719501183939,"mc":[{"id":"1.230180124","rc":[{"atl":[[9.8,0],[9.4,2.85]],"id":65992794}],"con":true,"img":false}]}
{"op":"mcm","clk":"11541016643","pt":1719501184250,"mc":[{"id":"1.230180124","rc":[{"atb":[[1.12,0]],"id":70902709}],"con":true,"img":false}]}
{"op":"mcm","clk":"11541016651","pt":1719501184363,"mc":[{"id":"1.230180124","rc":[{"atb":[[5.1,0.05]],"id":70902709}],"con":true,"img":false}]}
{"op":"mcm","clk":"11541016692","pt":1719501184724,"mc":[{"id":"1.230180124","rc":[{"atb":[[1.09,0]],"id":51567147}],"con":true,"img":false}]}
{"op":"mcm","clk":"11541016704","pt":1719501184826,"mc":[{"id":"1.230180124","rc":[{"atb":[[4.2,0.07]],"id":51567147}],"con":true,"img":false}]}
{"op":"mcm","clk":"11541016729","pt":1719501185144,"mc":[{"id":"1.230180124","rc":[{"atb":[[1.12,0]],"id":67245400}],"con":true,"img":false}]}
{"op":"mcm","clk":"11541016738","pt":1719501185243,"mc":[{"id":"1.230180124","rc":[{"atb":[[5.1,0.05]],"id":67245400}],"con":true,"img":false}]}
{"op":"mcm","clk":"11541016799","pt":1719501185861,"mc":[{"id":"1.230180124","rc":[{"atl":[[9.6,0]],"id":65992794}],"con":true,"img":false}]}
{"op":"mcm","clk":"11541016888","pt":1719501186849,"mc":[{"id":"1.230180124","rc":[{"atl":[[3.8,2]],"id":65992794}],"con":true,"img":false}]}
{"op":"mcm","clk":"11541016914","pt":1719501187153,"mc":[{"id":"1.230180124","rc":[{"atl":[[9.2,0]],"id":65992794}],"con":true,"img":false}]}
{"op":"mcm","clk":"11541016952","pt":1719501187677,"mc":[{"id":"1.230180124","rc":[{"atl":[[3.75,0.84]],"id":65992794}],"con":true,"img":false}]}
{"op":"mcm","clk":"11541017022","pt":1719501188455,"mc":[{"id":"1.230180124","rc":[{"atl":[[1000,1.88]],"id":65992794},{"atb":[[1.02,3.7]],"id":67245400},{"atl":[[1000,1.88]],"id":67245400},{"atb":[[1.08,1.7]],"id":42767337},{"atl":[[1000,1.7]],"id":42767337}],"con":true,"img":false}]}
{"op":"mcm","clk":"11541017032","pt":1719501188562,"mc":[{"id":"1.230180124","rc":[{"atb":[[1.01,18.65]],"id":65992794}],"con":true,"img":false}]}
{"op":"mcm","clk":"11541017046","pt":1719501188666,"mc":[{"id":"1.230180124","rc":[{"atl":[[1000,0.29]],"id":65992794},{"atb":[[1.02,2.17]],"id":67245400},{"atl":[[1000,0.18]],"id":67245400},{"atb":[[1.08,0.03]],"id":42767337},{"atl":[[1000,0]],"id":42767337}],"con":true,"img":false}]}
{"op":"mcm","clk":"11541017057","pt":1719501188764,"mc":[{"id":"1.230180124","rc":[{"atb":[[1.01,17.18]],"id":65992794}],"con":true,"img":false}]}
{"op":"mcm","clk":"11541017066","pt":1719501188874,"mc":[{"id":"1.230180124","rc":[{"atl":[[1000,0.18]],"id":65992794},{"atb":[[1.02,2]],"id":67245400},{"atb":[[1.08,0]],"id":42767337}],"con":true,"img":false}]}
{"op":"mcm","clk":"11541017075","pt":1719501188968,"mc":[{"id":"1.230180124","rc":[{"atl":[[3.75,0.95]],"id":65992794},{"atb":[[2.78,0.17]],"id":67245400},{"atb":[[10.5,0.87]],"id":42767337}],"con":true,"img":false}]}
{"op":"mcm","clk":"11541017084","pt":1719501189079,"mc":[{"id":"1.230180124","rc":[{"atb":[[1.01,16.95]],"id":65992794}],"con":true,"img":false}]}
{"op":"mcm","clk":"11541017097","pt":1719501189137,"mc":[{"id":"1.230180124","rc":[{"atb":[[2.32,0.23]],"id":65992794}],"con":true,"img":false}]}
{"op":"mcm","clk":"11541017403","pt":1719501192082,"mc":[{"id":"1.230180124","rc":[{"atl":[[3.8,0]],"id":65992794},{"spn":2.57,"spf":1.0,"id":65992794},{"spn":10.1,"spf":1.0,"id":42767337}],"con":true,"img":false}]}
{"op":"mcm","clk":"11541017470","pt":1719501192649,"mc":[{"id":"1.230180124","rc":[{"atl":[[3.75,0.11]],"id":65992794}],"con":true,"img":false}]}
{"op":"mcm","clk":"11541017622","pt":1719501194462,"mc":[{"id":"1.230180124","rc":[{"atl":[[3.8,2]],"id":65992794}],"con":true,"img":false}]}
{"op":"mcm","clk":"11541017634","pt":1719501194566,"mc":[{"id":"1.230180124","rc":[{"atl":[[4.3,2.85],[9.4,0]],"id":65992794}],"con":true,"img":false}]}
{"op":"mcm","clk":"11541017662","pt":1719501194879,"mc":[{"id":"1.230180124","rc":[{"atl":[[9.2,1.65]],"id":65992794}],"con":true,"img":false}]}
{"op":"mcm","clk":"11541017689","pt":1719501195180,"mc":[{"id":"1.230180124","rc":[{"atl":[[3.75,0.95]],"id":65992794},{"atb":[[10,0]],"id":42767337}],"con":true,"img":false}]}
{"op":"mcm","clk":"11541017729","pt":1719501195647,"mc":[{"id":"1.230180124","rc":[{"atl":[[3.8,0]],"id":65992794}],"con":true,"img":false}]}
{"op":"mcm","clk":"11541017737","pt":1719501195756,"mc":[{"id":"1.230180124","rc":[{"atl":[[4.3,0],[9,3.84]],"id":65992794},{"atb":[[10.5,0.03]],"id":42767337}],"con":true,"img":false}]}
{"op":"mcm","clk":"11541017744","pt":1719501195851,"mc":[{"id":"1.230180124","rc":[{"atb":[[3.4,1]],"id":42767337}],"con":true,"img":false}]}
{"op":"mcm","clk":"11541017770","pt":1719501196170,"mc":[{"id":"1.230180124","rc":[{"atl":[[3.75,0.11]],"id":65992794},{"atb":[[5.3,0.84]],"id":42767337}],"con":true,"img":false}]}
{"op":"mcm","clk":"11541017883","pt":1719501197457,"mc":[{"id":"1.230180124","rc":[{"atb":[[5,1]],"id":42767337}],"con":true,"img":false}]}
{"op":"mcm","clk":"11541017960","pt":1719501198385,"mc":[{"id":"1.230180124","rc":[{"atl":[[9.2,0]],"id":65992794}],"con":true,"img":false}]}
{"op":"mcm","clk":"11541017967","pt":1719501198488,"mc":[{"id":"1.230180124","rc":[{"atl":[[9,0.03],[11.5,4]],"id":65992794}],"con":true,"img":false}]}
{"op":"mcm","clk":"11541018214","pt":1719501201546,"mc":[{"id":"1.230180124","rc":[{"atl":[[11,2]],"id":65992794}],"con":true,"img":false}]}
{"op":"mcm","clk":"11541018394","pt":1719501203877,"mc":[{"id":"1.230180124","rc":[{"atl":[[10.5,1.51]],"id":65992794}],"con":true,"img":false}]}
{"op":"mcm","clk":"11541018677","pt":1719501206869,"mc":[{"id":"1.230180124","rc":[{"atl":[[11,0]],"id":65992794}],"con":true,"img":false}]}
{"op":"mcm","clk":"11541018843","pt":1719501208678,"mc":[{"id":"1.230180124","rc":[{"atl":[[10,2]],"id":65992794}],"con":true,"img":false}]}
{"op":"mcm","clk":"11541018957","pt":1719501209969,"mc":[{"id":"1.230180124","rc":[{"atl":[[10.5,0]],"id":65992794}],"con":true,"img":false}]}
{"op":"mcm","clk":"11541019287","pt":1719501213974,"mc":[{"id":"1.230180124","rc":[{"atl":[[10,0]],"id":65992794}],"con":true,"img":false}]}
{"op":"mcm","clk":"11541019464","pt":1719501215898,"mc":[{"id":"1.230180124","rc":[{"atl":[[11,3.59]],"id":65992794}],"con":true,"img":false}]}
{"op":"mcm","clk":"11541019955","pt":1719501221180,"mc":[{"id":"1.230180124","rc":[{"atl":[[11,1.59]],"id":65992794}],"con":true,"img":false}]}
{"op":"mcm","clk":"11541020100","pt":1719501222989,"mc":[{"id":"1.230180124","rc":[{"atl":[[10.5,2]],"id":65992794}],"con":true,"img":false}]}
{"op":"mcm","clk":"11541020243","pt":1719501224799,"mc":[{"id":"1.230180124","rc":[{"atb":[[2.32,0]],"id":65992794},{"atl":[[3.75,0]],"id":65992794},{"atb":[[2.78,0]],"id":67245400},{"atb":[[10.5,0]],"id":42767337}],"con":true,"img":false}]}
{"op":"mcm","clk":"11541020254","pt":1719501224904,"mc":[{"id":"1.230180124","rc":[{"atl":[[10.5,4],[11.5,0]],"id":65992794},{"atb":[[5.1,17.29]],"id":42767337}],"con":true,"img":false}]}
{"op":"mcm","clk":"11541020262","pt":1719501225006,"mc":[{"id":"1.230180124","rc":[{"atl":[[11,0]],"id":65992794},{"atb":[[5.2,0]],"id":42767337}],"con":true,"img":false}]}
{"op":"mcm","clk":"11541020280","pt":1719501225216,"mc":[{"id":"1.230180124","rc":[{"atl":[[10,0.84]],"id":65992794}],"con":true,"img":false}]}
{"op":"mcm","clk":"11541020323","pt":1719501225736,"mc":[{"id":"1.230180124","rc":[{"atb":[[5.3,0]],"id":42767337}],"con":true,"img":false}]}
{"op":"mcm","clk":"11541020335","pt":1719501225784,"mc":[{"id":"1.230180124","rc":[{"atl":[[10.5,2]],"id":65992794}],"con":true,"img":false}]}
{"op":"mcm","clk":"11541020374","pt":1719501226197,"mc":[{"id":"1.230180124","rc":[{"atb":[[5.2,0.84]],"id":42767337}],"con":true,"img":false}]}
{"op":"mcm","clk":"11541020383","pt":1719501226300,"mc":[{"id":"1.230180124","rc":[{"atb":[[5.2,5.73]],"id":42767337}],"con":true,"img":false}]}
{"op":"mcm","clk":"11541020547","pt":1719501228105,"mc":[{"id":"1.230180124","rc":[{"atl":[[10,2.58]],"id":65992794}],"con":true,"img":false}]}
{"op":"mcm","clk":"11541020719","pt":1719501230122,"mc":[{"id":"1.230180124","rc":[{"atl":[[9.8,2]],"id":65992794}],"con":true,"img":false}]}
{"op":"mcm","clk":"11541020796","pt":1719501231105,"mc":[{"id":"1.230180124","rc":[{"atl":[[10,0.84]],"id":65992794}],"con":true,"img":false}]}
{"op":"mcm","clk":"11541020903","pt":1719501232341,"mc":[{"id":"1.230180124","rc":[{"atl":[[9.6,0.84]],"id":65992794}],"con":true,"img":false}]}
{"op":"mcm","clk":"11541021016","pt":1719501233431,"mc":[{"id":"1.230180124","rc":[{"atl":[[9.6,2.84]],"id":65992794},{"atb":[[5.1,0.05],[5.2,11.46]],"id":42767337}],"con":true,"img":false}]}
{"op":"mcm","clk":"11541021026","pt":1719501233536,"mc":[{"id":"1.230180124","rc":[{"atl":[[10.5,0]],"id":65992794}],"con":true,"img":false}]}
{"op":"mcm","clk":"11541021037","pt":1719501233640,"mc":[{"id":"1.230180124","rc":[{"atb":[[5.1,11.51],[5.2,5.73]],"id":42767337}],"con":true,"img":false}]}
{"op":"mcm","clk":"11541021045","pt":1719501233746,"mc":[{"id":"1.230180124","rc":[{"atl":[[10,0]],"id":65992794}],"con":true,"img":false}]}
{"op":"mcm","clk":"11541021058","pt":1719501233794,"mc":[{"id":"1.230180124","rc":[{"atb":[[5.1,0.05],[5.2,7.73]],"id":42767337}],"con":true,"img":false}]}
{"op":"mcm","clk":"11541021096","pt":1719501234205,"mc":[{"id":"1.230180124","rc":[{"atl":[[9.4,1.65]],"id":65992794}],"con":true,"img":false}]}
{"op":"mcm","clk":"11541021143","pt":1719501234725,"mc":[{"id":"1.230180124","rc":[{"atl":[[9.8,0]],"id":65992794}],"con":true,"img":false}]}
{"op":"mcm","clk":"11541021362","pt":1719501237308,"mc":[{"id":"1.230180124","rc":[{"atl":[[9.2,2]],"id":65992794}],"con":true,"img":false}]}
{"op":"mcm","clk":"11541021372","pt":1719501237413,"mc":[{"id":"1.230180124","rc":[{"atl":[[9.6,0.84],[9.2,4]],"id":65992794}],"con":true,"img":false}]}
{"op":"mcm","clk":"11541021400","pt":1719501237720,"mc":[{"id":"1.230180124","rc":[{"atl":[[9.6,0]],"id":65992794}],"con":true,"img":false}]}
{"op":"mcm","clk":"11541021577","pt":1719501239734,"mc":[{"id":"1.230180124","rc":[{"atl":[[9,0.87]],"id":65992794}],"con":true,"img":false}]}
{"op":"mcm","clk":"11541021626","pt":1719501240208,"mc":[{"id":"1.230180124","rc":[{"atl":[[9.4,0]],"id":65992794}],"con":true,"img":false}]}
{"op":"mcm","clk":"11541021692","pt":1719501240924,"mc":[{"id":"1.230180124","rc":[{"atl":[[1000,0.97]],"id":65992794}],"con":true,"img":false}]}
{"op":"mcm","clk":"11541021832","pt":1719501242534,"mc":[{"id":"1.230180124","rc":[{"atl":[[9.2,2]],"id":65992794}],"con":true,"img":false}]}
{"op":"mcm","clk":"11541021847","pt":1719501242732,"mc":[{"id":"1.230180124","rc":[{"atl":[[9.2,0],[11.5,4]],"id":65992794}],"con":true,"img":false}]}
{"op":"mcm","clk":"11541021881","pt":1719501243148,"mc":[{"id":"1.230180124","rc":[{"atl":[[9,2.4]],"id":65992794}],"con":true,"img":false}]}
{"op":"mcm","clk":"11541021890","pt":1719501243206,"mc":[{"id":"1.230180124","rc":[{"atl":[[9,1.56]],"id":65992794}],"con":true,"img":false}]}
{"op":"mcm","clk":"11541021947","pt":1719501243930,"mc":[{"id":"1.230180124","rc":[{"atl":[[4.4,1]],"id":65992794},{"atb":[[4.6,1]],"id":67245400},{"atl":[[14,1]],"id":67245400},{"atl":[[9.4,1]],"id":51567147},{"atl":[[12,1]],"id":70902709}],"con":true,"img":false}]}
{"op":"mcm","clk":"11541021960","pt":1719501244028,"mc":[{"id":"1.230180124","rc":[{"atb":[[2.76,0],[4.7,20.86]],"id":67245400}],"con":true,"img":false}]}
{"op":"mcm","clk":"11541021969","pt":1719501244134,"mc":[{"id":"1.230180124","rc":[{"atb":[[4.6,21.86],[4.7,0]],"id":67245400}],"con":true,"img":false}]}
{"op":"mcm","clk":"11541021985","pt":1719501244343,"mc":[{"id":"1.230180124","rc":[{"atl":[[4.3,2]],"id":65992794}],"con":true,"img":false}]}
{"op":"mcm","clk":"11541022126","pt":1719501245831,"mc":[{"id":"1.230180124","rc":[{"atl":[[4.3,4],[11.5,0]],"id":65992794}],"con":true,"img":false}]}
{"op":"mcm","clk":"11541022136","pt":1719501245942,"mc":[{"id":"1.230180124","rc":[{"atl":[[4.3,2],[8.8,4]],"id":65992794}],"con":true,"img":false}]}
{"op":"mcm","clk":"11541022145","pt":1719501246038,"mc":[{"id":"1.230180124","rc":[{"atl":[[4.3,4],[8.8,0]],"id":65992794}],"con":true,"img":false}]}
{"op":"mcm","clk":"11541022154","pt":1719501246139,"mc":[{"id":"1.230180124","rc":[{"atl":[[4.3,2],[9,0.03],[8.8,4]],"id":65992794}],"con":true,"img":false}]}
{"op":"mcm","clk":"11541022245","pt":1719501247326,"mc":[{"id":"1.230180124","rc":[{"atl":[[4.2,0.84]],"id":65992794}],"con":true,"img":false}]}
{"op":"mcm","clk":"11541022452","pt":1719501249545,"mc":[{"id":"1.230180124","rc":[{"atl":[[4.3,0]],"id":65992794}],"con":true,"img":false}]}
{"op":"mcm","clk":"11541022532","pt":1719501250322,"mc":[{"id":"1.230180124","rc":[{"atl":[[4.2,0]],"id":65992794}],"con":true,"img":false}]}
{"op":"mcm","clk":"11541022716","pt":1719501252133,"mc":[{"id":"1.230180124","rc":[{"atl":[[4.3,3.63]],"id":65992794},{"spn":2.57,"spf":1.0,"id":65992794},{"spn":9.55,"spf":"NaN","id":67245400},{"spn":5.2,"spf":1.0,"id":42767337},{"spn":6.8,"spf":"NaN","id":51567147},{"spn":8.55,"spf":"NaN","id":70902709}],"con":true,"img":false}]}
{"op":"mcm","clk":"11541022889","pt":1719501254618,"mc":[{"id":"1.230180124","rc":[{"atl":[[4.3,7.26],[8.8,0]],"id":65992794}],"con":true,"img":false}]}
{"op":"mcm","clk":"11541022898","pt":1719501254626,"mc":[{"id":"1.230180124","rc":[{"atl":[[4.3,3.63],[8.8,4.63]],"id":65992794}],"con":true,"img":false}]}
{"op":"mcm","clk":"11541022907","pt":1719501254646,"mc":[{"id":"1.230180124","rc":[{"atl":[[4.2,0.84]],"id":65992794}],"con":true,"img":false}]}
{"op":"mcm","clk":"11541022921","pt":1719501254752,"mc":[{"id":"1.230180124","rc":[{"atl":[[4.3,5.63],[8.8,0]],"id":65992794}],"con":true,"img":false}]}
{"op":"mcm","clk":"11541023131","pt":1719501257439,"mc":[{"id":"1.230180124","rc":[{"atl":[[4.3,3.63]],"id":65992794}],"con":true,"img":false}]}
{"op":"mcm","clk":"11541023282","pt":1719501259271,"mc":[{"id":"1.230180124","rc":[{"atl":[[4.2,2.84]],"id":65992794}],"con":true,"img":false}]}
{"op":"mcm","clk":"11541023430","pt":1719501261223,"mc":[{"id":"1.230180124","rc":[{"atl":[[4.3,2]],"id":65992794}],"con":true,"img":false}]}
{"op":"mcm","clk":"11541023677","pt":1719501264138,"mc":[{"id":"1.230180124","rc":[{"atb":[[2.3,18.17]],"id":65992794},{"atb":[[2.54,65.73]],"id":51567147}],"con":true,"img":false}]}
{"op":"mcm","clk":"11541023706","pt":1719501264551,"mc":[{"id":"1.230180124","rc":[{"atl":[[4.2,0.84]],"id":65992794}],"con":true,"img":false}]}
{"op":"mcm","clk":"11541023715","pt":1719501264663,"mc":[{"id":"1.230180124","rc":[{"atl":[[4.3,0],[4.4,3.85]],"id":65992794}],"con":true,"img":false}]}
{"op":"mcm","clk":"11541023723","pt":1719501264760,"mc":[{"id":"1.230180124","rc":[{"atl":[[9,4.73],[4.4,1]],"id":65992794}],"con":true,"img":false}]}
{"op":"mcm","clk":"11541023755","pt":1719501265223,"mc":[{"id":"1.230180124","rc":[{"atl":[[4.2,0]],"id":65992794}],"con":true,"img":false}]}
{"op":"mcm","clk":"11541023772","pt":1719501265430,"mc":[{"id":"1.230180124","rc":[{"atl":[[9,0.03],[11.5,5.73]],"id":65992794}],"con":true,"img":false}]}
{"op":"mcm","clk":"11541023856","pt":1719501266362,"mc":[{"id":"1.230180124","rc":[{"atl":[[4.3,2]],"id":65992794}],"con":true,"img":false}]}
{"op":"mcm","clk":"11541023864","pt":1719501266465,"mc":[{"id":"1.230180124","rc":[{"atl":[[4.3,4],[11.5,0]],"id":65992794}],"con":true,"img":false}]}
{"op":"mcm","clk":"11541023884","pt":1719501266678,"mc":[{"id":"1.230180124","rc":[{"atl":[[4.2,0.84]],"id":65992794}],"con":true,"img":false}]}
{"op":"mcm","clk":"11541024268","pt":1719501271584,"mc":[{"id":"1.230180124","rc":[{"atl":[[4.3,2]],"id":65992794}],"con":true,"img":false}]}
{"op":"mcm","clk":"11541024276","pt":1719501271648,"mc":[{"id":"1.230180124","rc":[{"atl":[[4.3,0],[4.4,3.85]],"id":65992794}],"con":true,"img":false}]}
{"op":"mcm","clk":"11541024288","pt":1719501271746,"mc":[{"id":"1.230180124","rc":[{"atl":[[9,4.73],[4.4,1]],"id":65992794}],"con":true,"img":false}]}
{"op":"mcm","clk":"11541024319","pt":1719501272161,"mc":[{"id":"1.230180124","rc":[{"atl":[[4.2,0]],"id":65992794}],"con":true,"img":false}]}
{"op":"mcm","clk":"11541024329","pt":1719501272267,"mc":[{"id":"1.230180124","rc":[{"atl":[[9,0.03],[11.5,5.73]],"id":65992794}],"con":true,"img":false}]}
{"op":"mcm","clk":"11541024417","pt":1719501273253,"mc":[{"id":"1.230180124","rc":[{"atl":[[4.3,1.58]],"id":65992794}],"con":true,"img":false}]}
{"op":"mcm","clk":"11541024426","pt":1719501273362,"mc":[{"id":"1.230180124","rc":[{"atl":[[1000,0.18]],"id":65992794}],"con":true,"img":false}]}
{"op":"mcm","clk":"11541024445","pt":1719501273561,"mc":[{"id":"1.230180124","rc":[{"atl":[[4.2,2]],"id":65992794}],"con":true,"img":false}]}
{"op":"mcm","clk":"11541024502","pt":1719501274180,"mc":[{"id":"1.230180124","rc":[{"atl":[[4.1,0.84]],"id":65992794}],"con":true,"img":false}]}
{"op":"mcm","clk":"11541024696","pt":1719501276458,"mc":[{"id":"1.230180124","rc":[{"atl":[[4.3,0]],"id":65992794}],"con":true,"img":false}]}
{"op":"mcm","clk":"11541024919","pt":1719501278775,"mc":[{"id":"1.230180124","rc":[{"atl":[[4.2,0]],"id":65992794}],"con":true,"img":false}]}
{"op":"mcm","clk":"11541024960","pt":1719501279298,"mc":[{"id":"1.230180124","rc":[{"atl":[[4.1,0]],"id":65992794}],"con":true,"img":false}]}
{"op":"mcm","clk":"11541025074","pt":1719501280586,"mc":[{"id":"1.230180124","rc":[{"atl":[[4.3,2]],"id":65992794}],"con":true,"img":false}]}
{"op":"mcm","clk":"11541025081","pt":1719501280694,"mc":[{"id":"1.230180124","rc":[{"atl":[[4.3,4],[11.5,0]],"id":65992794}],"con":true,"img":false}]}
{"op":"mcm","clk":"11541025090","pt":1719501280794,"mc":[{"id":"1.230180124","rc":[{"atl":[[4.3,2],[9,4.03]],"id":65992794}],"con":true,"img":false}]}
{"op":"mcm","clk":"11541025127","pt":1719501281153,"mc":[{"id":"1.230180124","rc":[{"atl":[[4.2,0.84]],"id":65992794}],"con":true,"img":false}]}
{"op":"mcm","clk":"11541025138","pt":1719501281260,"mc":[{"id":"1.230180124","rc":[{"atl":[[4.3,4],[9,0.03]],"id":65992794}],"con":true,"img":false}]}
{"op":"mcm","clk":"11541025560","pt":1719501285770,"mc":[{"id":"1.230180124","rc":[{"atl":[[4.3,2]],"id":65992794}],"con":true,"img":false}]}
{"op":"mcm","clk":"11541025571","pt":1719501285879,"mc":[{"id":"1.230180124","rc":[{"atl":[[4.3,0],[4.4,3.85]],"id":65992794}],"con":true,"img":false}]}
{"op":"mcm","clk":"11541025585","pt":1719501285976,"mc":[{"id":"1.230180124","rc":[{"atl":[[9,4.73],[4.4,1]],"id":65992794}],"con":true,"img":false}]}
{"op":"mcm","clk":"11541025605","pt":1719501286185,"mc":[{"id":"1.230180124","rc":[{"atl":[[4.2,0]],"id":65992794}],"con":true,"img":false}]}
{"op":"mcm","clk":"11541025620","pt":1719501286401,"mc":[{"id":"1.230180124","rc":[{"atl":[[9,0.03],[11.5,5.73]],"id":65992794}],"con":true,"img":false}]}
{"op":"mcm","clk":"11541025745","pt":1719501287789,"mc":[{"id":"1.230180124","rc":[{"atl":[[4.3,2]],"id":65992794}],"con":true,"img":false}]}
{"op":"mcm","clk":"11541025754","pt":1719501287886,"mc":[{"id":"1.230180124","rc":[{"atl":[[4.3,4],[11.5,0]],"id":65992794}],"con":true,"img":false}]}
{"op":"mcm","clk":"11541025792","pt":1719501288302,"mc":[{"id":"1.230180124","rc":[{"atl":[[4.2,0.84]],"id":65992794}],"con":true,"img":false}]}
{"op":"mcm","clk":"11541026197","pt":1719501293015,"mc":[{"id":"1.230180124","rc":[{"atl":[[4.3,2]],"id":65992794}],"con":true,"img":false}]}
{"op":"mcm","clk":"11541026208","pt":1719501293113,"mc":[{"id":"1.230180124","rc":[{"atl":[[4.3,0],[4.4,3.85]],"id":65992794}],"con":true,"img":false}]}
{"op":"mcm","clk":"11541026252","pt":1719501293693,"mc":[{"id":"1.230180124","rc":[{"atl":[[4.2,0]],"id":65992794}],"con":true,"img":false}]}
{"op":"mcm","clk":"11541026304","pt":1719501294310,"mc":[{"id":"1.230180124","rc":[{"atl":[[4.3,1.52]],"id":65992794}],"con":true,"img":false}]}
{"op":"mcm","clk":"11541026356","pt":1719501294871,"mc":[{"id":"1.230180124","rc":[{"atl":[[4.2,2]],"id":65992794}],"con":true,"img":false}]}
{"op":"mcm","clk":"11541026431","pt":1719501295706,"mc":[{"id":"1.230180124","rc":[{"atl":[[4.1,0.84]],"id":65992794}],"con":true,"img":false}]}
{"op":"mcm","clk":"11541026573","pt":1719501297405,"mc":[{"id":"1.230180124","rc":[{"atl":[[4.3,0]],"id":65992794}],"con":true,"img":false}]}
{"op":"mcm","clk":"11541026835","pt":1719501300094,"mc":[{"id":"1.230180124","rc":[{"atl":[[4.2,0]],"id":65992794}],"con":true,"img":false}]}
{"op":"mcm","clk":"11541026847","pt":1719501300199,"mc":[{"id":"1.230180124","rc":[{"atl":[[9,4.73],[4.4,1]],"id":65992794}],"con":true,"img":false}]}
{"op":"mcm","clk":"11541026916","pt":1719501300826,"mc":[{"id":"1.230180124","rc":[{"atl":[[4.1,0]],"id":65992794}],"con":true,"img":false}]}
{"op":"mcm","clk":"11541026927","pt":1719501300928,"mc":[{"id":"1.230180124","rc":[{"atl":[[9,0.03],[11.5,5.73]],"id":65992794}],"con":true,"img":false}]}
{"op":"mcm","clk":"11541027001","pt":1719501301618,"mc":[{"id":"1.230180124","rc":[{"atb":[[1.03,1.7]],"id":67245400},{"atl":[[1000,1.88]],"id":67245400},{"atb":[[1.04,1.7]],"id":42767337},{"atl":[[1000,1.7]],"id":42767337}],"con":true,"img":false}]}
{"op":"mcm","clk":"11541027012","pt":1719501301713,"mc":[{"id":"1.230180124","rc":[{"atb":[[1.02,134.94]],"id":65992794},{"atl":[[1000,1.88]],"id":65992794},{"atb":[[1.05,1.7]],"id":67245400}],"con":true,"img":false}]}
{"op":"mcm","clk":"11541027027","pt":1719501301927,"mc":[{"id":"1.230180124","rc":[{"atb":[[1.02,133.46]],"id":65992794},{"atl":[[1000,0.24]],"id":65992794},{"atb":[[1.03,0.07],[1.05,0.04]],"id":67245400},{"atl":[[1000,0.18]],"id":67245400},{"atb":[[5.1,0],[1.04,0.06]],"id":42767337},{"atl":[[1000,0]],"id":42767337}],"con":true,"img":false}]}
{"op":"mcm","clk":"11541027044","pt":1719501302089,"mc":[{"id":"1.230180124","rc":[{"atb":[[1.02,133.24]],"id":65992794},{"atl":[[4.3,2],[1000,0.18]],"id":65992794},{"atb":[[5.1,0],[1.03,0],[1.05,0]],"id":67245400},{"atb":[[1.04,0]],"id":42767337}],"con":true,"img":false}]}
{"op":"mcm","clk":"11541027059","pt":1719501302206,"mc":[{"id":"1.230180124","rc":[{"atb":[[2.32,0.22]],"id":65992794},{"atl":[[4.3,4],[6,0.05]],"id":65992794},{"atb":[[4.6,1],[4.7,0.12],[2.76,56.82]],"id":67245400},{"atb":[[5.3,0.06]],"id":42767337},{"atb":[[5.1,0]],"id":70902709}],"con":true,"img":false}]}
{"op":"mcm","clk":"11541027069","pt":1719501302295,"mc":[{"id":"1.230180124","rc":[{"atl":[[11.5,0]],"id":65992794}],"con":true,"img":false}]}
{"op":"mcm","clk":"11541027090","pt":1719501302510,"mc":[{"id":"1.230180124","rc":[{"atb":[[2.7,0]],"id":65992794}],"con":true,"img":false}]}
{"op":"mcm","clk":"11541027115","pt":1719501302717,"mc":[{"id":"1.230180124","rc":[{"atl":[[4.2,0.84]],"id":65992794},{"atb":[[4.2,0]],"id":51567147}],"con":true,"img":false}]}
{"op":"mcm","clk":"11541027137","pt":1719501302926,"mc":[{"id":"1.230180124","rc":[{"atb":[[1.12,1.69]],"id":70902709}],"con":true,"img":false}]}
{"op":"mcm","clk":"11541027148","pt":1719501303028,"mc":[{"id":"1.230180124","rc":[{"atb":[[1.12,1.69]],"id":67245400}],"con":true,"img":false}]}
{"op":"mcm","clk":"11541027173","pt":1719501303187,"mc":[{"id":"1.230180124","rc":[{"atb":[[1.12,1.69]],"id":42767337}],"con":true,"img":false}]}
{"op":"mcm","clk":"11541027184","pt":1719501303295,"mc":[{"id":"1.230180124","rc":[{"atb":[[1.07,1.69]],"id":65992794}],"con":true,"img":false}]}
{"op":"mcm","clk":"11541027218","pt":1719501303603,"mc":[{"id":"1.230180124","rc":[{"atb":[[1.09,1.69]],"id":51567147}],"con":true,"img":false}]}
{"op":"mcm","clk":"11541027230","pt":1719501303714,"mc":[{"id":"1.230180124","rc":[{"atb":[[1.12,0.05]],"id":70902709}],"con":true,"img":false}]}
{"op":"mcm","clk":"11541027257","pt":1719501303916,"mc":[{"id":"1.230180124","rc":[{"atb":[[1.07,0.11]],"id":65992794}],"con":true,"img":false}]}
{"op":"mcm","clk":"11541027295","pt":1719501304232,"mc":[{"id":"1.230180124","rc":[{"atb":[[1.12,0.05]],"id":67245400},{"atb":[[1.12,0.05]],"id":42767337}],"con":true,"img":false}]}
{"op":"mcm","clk":"11541027347","pt":1719501304596,"mc":[{"id":"1.230180124","rc":[{"atb":[[1.09,0.07]],"id":51567147},{"atb":[[1.12,0]],"id":70902709}],"con":true,"img":false}]}
{"op":"mcm","clk":"11541027361","pt":1719501304703,"mc":[{"id":"1.230180124","rc":[{"atb":[[5.1,0.05]],"id":70902709}],"con":true,"img":false}]}
{"op":"mcm","clk":"11541027404","pt":1719501305111,"mc":[{"id":"1.230180124","rc":[{"atb":[[1.07,0]],"id":65992794}],"con":true,"img":false}]}
{"op":"mcm","clk":"11541027417","pt":1719501305220,"mc":[{"id":"1.230180124","rc":[{"atb":[[2.7,0.11]],"id":65992794}],"con":true,"img":false}]}
{"op":"mcm","clk":"11541027455","pt":1719501305580,"mc":[{"id":"1.230180124","rc":[{"atb":[[1.12,0]],"id":67245400}],"con":true,"img":false}]}
{"op":"mcm","clk":"11541027465","pt":1719501305691,"mc":[{"id":"1.230180124","rc":[{"atb":[[5.1,0.05]],"id":67245400}],"con":true,"img":false}]}
{"op":"mcm","clk":"11541027505","pt":1719501306101,"mc":[{"id":"1.230180124","rc":[{"atb":[[1.12,0]],"id":42767337}],"con":true,"img":false}]}
{"op":"mcm","clk":"11541027515","pt":1719501306208,"mc":[{"id":"1.230180124","rc":[{"atb":[[5.3,0.12]],"id":42767337}],"con":true,"img":false}]}
{"op":"mcm","clk":"11541027554","pt":1719501306623,"mc":[{"id":"1.230180124","rc":[{"atb":[[1.09,0]],"id":51567147}],"con":true,"img":false}]}
{"op":"mcm","clk":"11541027563","pt":1719501306731,"mc":[{"id":"1.230180124","rc":[{"atb":[[4.2,0.07]],"id":51567147}],"con":true,"img":false}]}
{"op":"mcm","clk":"11541027623","pt":1719501307295,"mc":[{"id":"1.230180124","rc":[{"atl":[[4.3,2]],"id":65992794}],"con":true,"img":false}]}
{"op":"mcm","clk":"11541027632","pt":1719501307403,"mc":[{"id":"1.230180124","rc":[{"atl":[[4.3,0],[4.4,3.85]],"id":65992794}],"con":true,"img":false}]}
{"op":"mcm","clk":"11541027675","pt":1719501307813,"mc":[{"id":"1.230180124","rc":[{"atl":[[4.2,0]],"id":65992794}],"con":true,"img":false}]}
{"op":"mcm","clk":"11541027817","pt":1719501309417,"mc":[{"id":"1.230180124","rc":[{"atl":[[4.3,1.57]],"id":65992794}],"con":true,"img":false}]}
{"op":"mcm","clk":"11541027838","pt":1719501309626,"mc":[{"id":"1.230180124","rc":[{"atl":[[4.2,2]],"id":65992794}],"con":true,"img":false}]}
{"op":"mcm","clk":"11541027876","pt":1719501309901,"mc":[{"id":"1.230180124","rc":[{"atb":[[4.7,2.12],[2.76,0]],"id":67245400}],"con":true,"img":false}]}
{"op":"mcm","clk":"11541027910","pt":1719501310204,"mc":[{"id":"1.230180124","rc":[{"atl":[[4.1,0.84]],"id":65992794}],"con":true,"img":false}]}
{"op":"mcm","clk":"11541027969","pt":1719501310719,"mc":[{"id":"1.230180124","rc":[{"atl":[[130,0.84]],"id":42767337},{"atl":[[140,2]],"id":70902709}],"con":true,"img":false}]}
{"op":"mcm","clk":"11541028167","pt":1719501312530,"mc":[{"id":"1.230180124","rc":[{"atl":[[4.3,0]],"id":65992794},{"spn":2.57,"spf":1.0,"id":65992794},{"spn":5.2,"spf":1.0,"id":42767337}],"con":true,"img":false}]}
{"op":"mcm","clk":"11541028389","pt":1719501314906,"mc":[{"id":"1.230180124","rc":[{"atl":[[4.2,0]],"id":65992794}],"con":true,"img":false}]}
{"op":"mcm","clk":"11541028396","pt":1719501315008,"mc":[{"id":"1.230180124","rc":[{"atl":[[6,4.75],[4.4,1]],"id":65992794}],"con":true,"img":false}]}
{"op":"mcm","clk":"11541028424","pt":1719501315317,"mc":[{"id":"1.230180124","rc":[{"atl":[[4.1,0]],"id":65992794}],"con":true,"img":false}]}
{"op":"mcm","clk":"11541028433","pt":1719501315420,"mc":[{"id":"1.230180124","rc":[{"atl":[[9,5.79],[6,0.05]],"id":65992794}],"con":true,"img":false}]}
{"op":"mcm","clk":"11541028540","pt":1719501316517,"mc":[{"id":"1.230180124","rc":[{"atb":[[2.3,17.38]],"id":65992794}],"con":true,"img":false}]}
{"op":"mcm","clk":"11541028568","pt":1719501316831,"mc":[{"id":"1.230180124","rc":[{"atl":[[4.3,2]],"id":65992794}],"con":true,"img":false}]}
{"op":"mcm","clk":"11541028581","pt":1719501316923,"mc":[{"id":"1.230180124","rc":[{"atl":[[4.3,4],[9,0.03]],"id":65992794}],"con":true,"img":false}]}
{"op":"mcm","clk":"11541028622","pt":1719501317337,"mc":[{"id":"1.230180124","rc":[{"atl":[[4.2,0.84]],"id":65992794}],"con":true,"img":false}]}
{"op":"mcm","clk":"11541028866","pt":1719501320042,"mc":[{"id":"1.230180124","rc":[{"atb":[[2.68,0],[2.7,0]],"id":65992794},{"atl":[[2.68,4.11]],"id":65992794},{"trd":[[2.68,2.68],[2.7,0.22]],"ltp":2.68,"tv":2.9,"id":65992794}],"con":true,"img":false}]}
{"op":"mcm","clk":"11541028886","pt":1719501320249,"mc":[{"id":"1.230180124","rc":[{"atb":[[2.3,0],[1.75,133.24]],"id":65992794}],"con":true,"img":false}]}
{"op":"mcm","clk":"11541028900","pt":1719501320305,"mc":[{"id":"1.230180124","rc":[{"atb":[[5.1,1.71]],"id":67245400}],"con":true,"img":false}]}
{"op":"mcm","clk":"11541028916","pt":1719501320408,"mc":[{"id":"1.230180124","rc":[{"atb":[[4.8,2.72],[4.7,0.12]],"id":67245400},{"atl":[[9.2,0.92]],"id":51567147}],"con":true,"img":false}]}
{"op":"mcm","clk":"11541028932","pt":1719501320511,"mc":[{"id":"1.230180124","rc":[{"atb":[[5.1,1.65]],"id":67245400},{"atb":[[5.3,0.06]],"id":42767337},{"atb":[[4.2,0]],"id":51567147},{"atb":[[5.1,0]],"id":70902709}],"con":true,"img":false}]}
{"op":"mcm","clk":"11541028944","pt":1719501320613,"mc":[{"id":"1.230180124","rc":[{"atl":[[4.3,2]],"id":65992794},{"atl":[[1000,1.03]],"id":67245400}],"con":true,"img":false}]}
{"op":"mcm","clk":"11541028956","pt":1719501320719,"mc":[{"id":"1.230180124","rc":[{"atb":[[1.76,0.84]],"id":65992794},{"atl":[[4.2,0]],"id":65992794},{"atb":[[5.2,0.84]],"id":67245400}],"con":true,"img":false}]}
{"op":"mcm","clk":"11541028967","pt":1719501320821,"mc":[{"id":"1.230180124","rc":[{"atb":[[4.2,2.01]],"id":51567147},{"atl":[[1000,1.03]],"id":70902709}],"con":true,"img":false}]}
{"op":"mcm","clk":"11541028980","pt":1719501320926,"mc":[{"id":"1.230180124","rc":[{"atb":[[2.54,0.79],[3.85,35.09]],"id":51567147}],"con":true,"img":false}]}
{"op":"mcm","clk":"11541029010","pt":1719501321139,"mc":[{"id":"1.230180124","rc":[{"atb":[[4.2,4.03]],"id":51567147},{"atb":[[5.1,1.65]],"id":70902709}],"con":true,"img":false}]}
{"op":"mcm","clk":"11541029027","pt":1719501321239,"mc":[{"id":"1.230180124","rc":[{"atb":[[4.3,0.84]],"id":51567147}],"con":true,"img":false}]}
{"op":"mcm","clk":"11541029043","pt":1719501321345,"mc":[{"id":"1.230180124","rc":[{"atb":[[4.5,28.57],[2.7,0]],"id":70902709}],"con":true,"img":false}]}
{"op":"mcm","clk":"11541029061","pt":1719501321454,"mc":[{"id":"1.230180124","rc":[{"atb":[[5.1,3.31]],"id":70902709},{"atl":[[1000,0.92]],"id":70902709}],"con":true,"img":false}]}
{"op":"mcm","clk":"11541029099","pt":1719501321708,"mc":[{"id":"1.230180124","rc":[{"atl":[[1000,0.81]],"id":67245400},{"atb":[[5.2,0.84]],"id":70902709}],"con":true,"img":false}]}
{"op":"mcm","clk":"11541029130","pt":1719501322018,"mc":[{"id":"1.230180124","rc":[{"atl":[[1000,0.18]],"id":70902709}],"con":true,"img":false}]}
{"op":"mcm","clk":"11541029142","pt":1719501322127,"mc":[{"id":"1.230180124","rc":[{"atl":[[11.5,0.73]],"id":70902709}],"con":true,"img":false}]}
{"op":"mcm","clk":"11541029175","pt":1719501322435,"mc":[{"id":"1.230180124","rc":[{"atl":[[1000,0.18]],"id":67245400},{"atl":[[9.2,0]],"id":51567147}],"con":true,"img":false}]}
{"op":"mcm","clk":"11541029185","pt":1719501322544,"mc":[{"id":"1.230180124","rc":[{"atl":[[13.5,0.62]],"id":67245400}],"con":true,"img":false}]}
{"op":"mcm","clk":"11541029201","pt":1719501322746,"mc":[{"id":"1.230180124","rc":[{"atl":[[65,0.92]],"id":51567147},{"atl":[[11.5,1.58]],"id":70902709}],"con":true,"img":false}]}
{"op":"mcm","clk":"11541029213","pt":1719501322853,"mc":[{"id":"1.230180124","rc":[{"atl":[[17,4]],"id":70902709}],"con":true,"img":false}]}
{"op":"mcm","clk":"11541029223","pt":1719501322903,"mc":[{"id":"1.230180124","rc":[{"atl":[[140,0]],"id":70902709}],"con":true,"img":false}]}
{"op":"mcm","clk":"11541029231","pt":1719501323007,"mc":[{"id":"1.230180124","rc":[{"atl":[[9.2,0.92]],"id":51567147}],"con":true,"img":false}]}
{"op":"mcm","clk":"11541029243","pt":1719501323107,"mc":[{"id":"1.230180124","rc":[{"atl":[[65,0]],"id":51567147}],"con":true,"img":false}]}
{"op":"mcm","clk":"11541029251","pt":1719501323220,"mc":[{"id":"1.230180124","rc":[{"atb":[[2.58,1.43]],"id":65992794}],"con":true,"img":false}]}
{"op":"mcm","clk":"11541029678","pt":1719501327831,"mc":[{"id":"1.230180124","rc":[{"atb":[[2.3,17.38],[1.75,0]],"id":65992794}],"con":true,"img":false}]}
{"op":"mcm","clk":"11541029719","pt":1719501328237,"mc":[{"id":"1.230180124","rc":[{"atb":[[1.76,0]],"id":65992794}],"con":true,"img":false}]}
{"op":"mcm","clk":"11541030306","pt":1719501335365,"mc":[{"id":"1.230180124","rc":[{"atb":[[2.54,0]],"id":51567147}],"con":true,"img":false}]}
{"op":"mcm","clk":"11541030684","pt":1719501339760,"mc":[{"id":"1.230180124","rc":[{"atl":[[1000,5.29]],"id":65992794}],"con":true,"img":false}]}
{"op":"mcm","clk":"11541030696","pt":1719501339873,"mc":[{"id":"1.230180124","rc":[{"atb":[[1.02,136.65]],"id":65992794}],"con":true,"img":false}]}
{"op":"mcm","clk":"11541030707","pt":1719501339974,"mc":[{"id":"1.230180124","rc":[{"atl":[[1000,0.53]],"id":65992794}],"con":true,"img":false}]}
{"op":"mcm","clk":"11541030713","pt":1719501340076,"mc":[{"id":"1.230180124","rc":[{"atb":[[1.02,133.54]],"id":65992794}],"con":true,"img":false}]}
{"op":"mcm","clk":"11541030737","pt":1719501340229,"mc":[{"id":"1.230180124","rc":[{"atl":[[1000,0.18]],"id":65992794}],"con":true,"img":false}]}
{"op":"mcm","clk":"11541030747","pt":1719501340334,"mc":[{"id":"1.230180124","rc":[{"atb":[[1.02,133.24]],"id":65992794},{"atl":[[2.66,0.34]],"id":65992794}],"con":true,"img":false}]}
{"op":"mcm","clk":"11541030758","pt":1719501340437,"mc":[{"id":"1.230180124","rc":[{"atb":[[2.32,0.52]],"id":65992794}],"con":true,"img":false}]}
{"op":"mcm","clk":"11541031683","pt":1719501350850,"mc":[{"id":"1.230180124","rc":[{"atb":[[5.1,0],[5.3,1.6]],"id":67245400}],"con":true,"img":false}]}
{"op":"mcm","clk":"11541031712","pt":1719501351159,"mc":[{"id":"1.230180124","rc":[{"atb":[[5.1,1.6],[5.3,0]],"id":67245400}],"con":true,"img":false}]}
{"op":"mcm","clk":"11541031852","pt":1719501352669,"mc":[{"id":"1.230180124","rc":[{"atb":[[2.32,0]],"id":65992794},{"atl":[[6,0],[2.66,0]],"id":65992794},{"atb":[[4.7,0]],"id":67245400},{"atb":[[5.3,0]],"id":42767337}],"con":true,"img":false}]}
{"op":"mcm","clk":"11541032621","pt":1719501361367,"mc":[{"id":"1.230180124","rc":[{"atb":[[1.01,17.95]],"id":42767337}],"con":true,"img":false}]}
{"op":"mcm","clk":"11541032714","pt":1719501362458,"mc":[{"id":"1.230180124","rc":[{"atb":[[4.6,0]],"id":67245400}],"con":true,"img":false}]}
{"op":"mcm","clk":"11541033398","pt":1719501369700,"mc":[{"id":"1.230180124","rc":[{"atl":[[2.66,1]],"id":65992794},{"atb":[[2.72,1]],"id":70902709}],"con":true,"img":false}]}
{"op":"mcm","clk":"11541033429","pt":1719501369957,"mc":[{"id":"1.230180124","rc":[{"atb":[[5.3,1.6]],"id":70902709}],"con":true,"img":false}]}
{"op":"mcm","clk":"11541033437","pt":1719501370059,"mc":[{"id":"1.230180124","rc":[{"atb":[[5.1,1.65]],"id":70902709}],"con":true,"img":false}]}
{"op":"mcm","clk":"11541033447","pt":1719501370164,"mc":[{"id":"1.230180124","rc":[{"atb":[[2.72,0]],"id":70902709}],"con":true,"img":false}]}
{"op":"mcm","clk":"11541033462","pt":1719501370380,"mc":[{"id":"1.230180124","rc":[{"atb":[[4.6,1],[5.3,0]],"id":70902709}],"con":true,"img":false}]}
{"op":"mcm","clk":"11541033490","pt":1719501370686,"mc":[{"id":"1.230180124","rc":[{"atb":[[1.25,20]],"id":65992794},{"atb":[[1.25,20]],"id":67245400},{"atb":[[1.25,20]],"id":42767337},{"atb":[[1.25,20]],"id":51567147},{"atb":[[1.25,20],[5.2,2.44]],"id":70902709}],"con":true,"img":false}]}
{"op":"mcm","clk":"11541033512","pt":1719501370899,"mc":[{"id":"1.230180124","rc":[{"atb":[[4.6,0],[5.3,1.6]],"id":70902709}],"con":true,"img":false}]}
{"op":"mcm","clk":"11541033532","pt":1719501371102,"mc":[{"id":"1.230180124","rc":[{"atb":[[5.4,1]],"id":70902709}],"con":true,"img":false}]}
{"op":"mcm","clk":"11541033542","pt":1719501371203,"mc":[{"id":"1.230180124","rc":[{"atb":[[5.1,0]],"id":70902709}],"con":true,"img":false}]}
{"op":"mcm","clk":"11541033749","pt":1719501373488,"mc":[{"id":"1.230180124","rc":[{"atb":[[1.7,27.1]],"id":65992794},{"spn":2.5,"spf":1.0,"id":65992794},{"atb":[[5.2,1.63]],"id":67245400},{"spn":9.35,"spf":"NaN","id":67245400},{"spn":5.2,"spf":1.0,"id":42767337},{"atb":[[4.3,1.63]],"id":51567147},{"spn":6.75,"spf":"NaN","id":51567147},{"atb":[[5.2,3.23]],"id":70902709},{"spn":8.45,"spf":"NaN","id":70902709}],"con":true,"img":false}]}
{"op":"mcm","clk":"11541033775","pt":1719501373797,"mc":[{"id":"1.230180124","rc":[{"atb":[[5.1,0],[5.3,1.6]],"id":67245400}],"con":true,"img":false}]}
{"op":"mcm","clk":"11541035089","pt":1719501388907,"mc":[{"id":"1.230180124","rc":[{"atl":[[2.66,2]],"id":65992794},{"atl":[[130,1]],"id":67245400},{"atl":[[130,1.84]],"id":42767337},{"atl":[[65,1]],"id":51567147},{"atl":[[11,1]],"id":70902709}],"con":true,"img":false}]}
{"op":"mcm","clk":"11541035110","pt":1719501389215,"mc":[{"id":"1.230180124","rc":[{"atl":[[120,0.62]],"id":67245400}],"con":true,"img":false}]}
{"op":"mcm","clk":"11541035116","pt":1719501389324,"mc":[{"id":"1.230180124","rc":[{"atl":[[13.5,0]],"id":67245400}],"con":true,"img":false}]}
{"op":"mcm","clk":"11541035136","pt":1719501389476,"mc":[{"id":"1.230180124","rc":[{"atl":[[60,0.92]],"id":51567147}],"con":true,"img":false}]}
{"op":"mcm","clk":"11541035155","pt":1719501389685,"mc":[{"id":"1.230180124","rc":[{"atl":[[9.2,0]],"id":51567147}],"con":true,"img":false}]}
{"op":"mcm","clk":"11541035167","pt":1719501389894,"mc":[{"id":"1.230180124","rc":[{"atl":[[120,0]],"id":67245400}],"con":true,"img":false}]}
{"op":"mcm","clk":"11541035177","pt":1719501390000,"mc":[{"id":"1.230180124","rc":[{"atl":[[1000,1.03]],"id":67245400}],"con":true,"img":false}]}
{"op":"mcm","clk":"11541035206","pt":1719501390408,"mc":[{"id":"1.230180124","rc":[{"atl":[[1000,0.81]],"id":67245400}],"con":true,"img":false}]}
{"op":"mcm","clk":"11541035236","pt":1719501390773,"mc":[{"id":"1.230180124","rc":[{"atl":[[1000,0.18]],"id":67245400}],"con":true,"img":false}]}
{"op":"mcm","clk":"11541035246","pt":1719501390895,"mc":[{"id":"1.230180124","rc":[{"atl":[[13.5,0.62]],"id":67245400}],"con":true,"img":false}]}
{"op":"mcm","clk":"11541035373","pt":1719501392502,"mc":[{"id":"1.230180124","rc":[{"atb":[[1.7,17.37]],"id":65992794},{"atb":[[5.2,0.84]],"id":67245400},{"atb":[[5.2,2.44]],"id":70902709}],"con":true,"img":false}]}
{"op":"mcm","clk":"11541036125","pt":1719501402799,"mc":[{"id":"1.230180124","rc":[{"atb":[[2.58,0.43]],"id":65992794},{"trd":[[2.58,2]],"ltp":2.58,"tv":2.0,"id":65992794}],"con":true,"img":false}]}
{"op":"mcm","clk":"11541036136","pt":1719501402904,"mc":[{"id":"1.230180124","rc":[{"atb":[[2.3,0],[2.58,0],[1.75,20]],"id":65992794},{"trd":[[2.58,2.86]],"ltp":2.58,"tv":2.86,"id":65992794}],"con":true,"img":false}]}
{"op":"mcm","clk":"11541036153","pt":1719501403115,"mc":[{"id":"1.230180124","rc":[{"atb":[[5.1,1.6],[5.3,0]],"id":67245400}],"con":true,"img":false}]}
{"op":"mcm","clk":"11541036168","pt":1719501403211,"mc":[{"id":"1.230180124","rc":[{"atb":[[1.76,0.84]],"id":65992794},{"atl":[[2.64,0.84]],"id":65992794}],"con":true,"img":false}]}
{"op":"mcm","clk":"11541036187","pt":1719501403419,"mc":[{"id":"1.230180124","rc":[{"atb":[[4.4,1.92]],"id":51567147},{"atb":[[5.3,0]],"id":70902709}],"con":true,"img":false}]}
{"op":"mcm","clk":"11541036210","pt":1719501403731,"mc":[{"id":"1.230180124","rc":[{"atb":[[2.48,1.52]],"id":65992794},{"atb":[[4.5,0.84],[4.2,2.01]],"id":51567147},{"atb":[[5.5,1.54]],"id":70902709}],"con":true,"img":false}]}
{"op":"mcm","clk":"11541036216","pt":1719501403783,"mc":[{"id":"1.230180124","rc":[{"atb":[[2.48,0.47]],"id":65992794},{"trd":[[2.48,2.1]],"ltp":2.48,"tv":2.1,"id":65992794}],"con":true,"img":false}]}
{"op":"mcm","clk":"11541036225","pt":1719501403887,"mc":[{"id":"1.230180124","rc":[{"atb":[[2.3,17.38],[1.75,0],[2.48,0]],"id":65992794},{"trd":[[2.48,3.04]],"ltp":2.48,"tv":3.04,"id":65992794}],"con":true,"img":false}]}
{"op":"mcm","clk":"11541036229","pt":1719501403998,"mc":[{"id":"1.230180124","rc":[{"atb":[[2.3,0],[1.75,20]],"id":65992794}],"con":true,"img":false}]}
{"op":"mcm","clk":"11541036240","pt":1719501404094,"mc":[{"id":"1.230180124","rc":[{"atb":[[2.3,17.38],[1.75,0]],"id":65992794},{"atl":[[2.64,2.84]],"id":65992794}],"con":true,"img":false}]}
{"op":"mcm","clk":"11541036246","pt":1719501404201,"mc":[{"id":"1.230180124","rc":[{"atb":[[2.3,0],[1.75,20],[1.76,0]],"id":65992794},{"atb":[[5.2,1.6]],"id":70902709}],"con":true,"img":false}]}
{"op":"mcm","clk":"11541036279","pt":1719501404717,"mc":[{"id":"1.230180124","rc":[{"atb":[[1.76,1.32]],"id":65992794}],"con":true,"img":false}]}
{"op":"mcm","clk":"11541036351","pt":1719501405794,"mc":[{"id":"1.230180124","rc":[{"atl":[[2.66,1]],"id":65992794}],"con":true,"img":false}]}
{"op":"mcm","clk":"11541036358","pt":1719501405902,"mc":[{"id":"1.230180124","rc":[{"atl":[[2.62,1]],"id":65992794}],"con":true,"img":false}]}
{"op":"mcm","clk":"11541036555","pt":1719501408738,"mc":[{"id":"1.230180124","rc":[{"atb":[[2.38,1.63]],"id":65992794}],"con":true,"img":false}]}
{"op":"mcm","clk":"11541036561","pt":1719501408841,"mc":[{"id":"1.230180124","rc":[{"atb":[[2.38,0]],"id":65992794},{"trd":[[2.38,3.26]],"ltp":2.38,"tv":3.26,"id":65992794}],"con":true,"img":false}]}
{"op":"mcm","clk":"11541036567","pt":1719501408893,"mc":[{"id":"1.230180124","rc":[{"atb":[[2.3,17.38],[1.75,0]],"id":65992794}],"con":true,"img":false}]}
{"op":"mcm","clk":"11541036574","pt":1719501409000,"mc":[{"id":"1.230180124","rc":[{"atb":[[2.3,0],[1.76,18.7]],"id":65992794}],"con":true,"img":false}]}
{"op":"mcm","clk":"11541036587","pt":1719501409206,"mc":[{"id":"1.230180124","rc":[{"atb":[[1.75,20],[1.76,1.32]],"id":65992794}],"con":true,"img":false}]}
{"op":"mcm","clk":"11541036597","pt":1719501409408,"mc":[{"id":"1.230180124","rc":[{"atl":[[2.64,0.84]],"id":65992794}],"con":true,"img":false}]}
{"op":"mcm","clk":"11541036662","pt":1719501410541,"mc":[{"id":"1.230180124","rc":[{"atl":[[2.62,0]],"id":65992794}],"con":true,"img":false}]}
{"op":"mcm","clk":"11541036671","pt":1719501410651,"mc":[{"id":"1.230180124","rc":[{"atl":[[2.66,2]],"id":65992794}],"con":true,"img":false}]}
{"op":"mcm","clk":"11541036699","pt":1719501411003,"mc":[{"id":"1.230180124","rc":[{"atb":[[5.3,1.6]],"id":67245400}],"con":true,"img":false}]}
{"op":"mcm","clk":"11541036709","pt":1719501411107,"mc":[{"id":"1.230180124","rc":[{"atb":[[5.1,0]],"id":67245400}],"con":true,"img":false}]}
{"op":"mcm","clk":"11541036889","pt":1719501413838,"mc":[{"id":"1.230180124","rc":[{"atb":[[2.28,1]],"id":65992794}],"con":true,"img":false}]}
{"op":"mcm","clk":"11541036911","pt":1719501414143,"mc":[{"id":"1.230180124","rc":[{"atb":[[5.1,1.6],[5.3,0]],"id":67245400}],"con":true,"img":false}]}
{"op":"mcm","clk":"11541036918","pt":1719501414244,"mc":[{"id":"1.230180124","rc":[{"atl":[[2.64,2.84]],"id":65992794}],"con":true,"img":false}]}
{"op":"mcm","clk":"11541036993","pt":1719501415335,"mc":[{"id":"1.230180124","rc":[{"atl":[[2.52,2]],"id":65992794}],"con":true,"img":false}]}
{"op":"mcm","clk":"11541037002","pt":1719501415432,"mc":[{"id":"1.230180124","rc":[{"atb":[[1.76,6.32]],"id":65992794}],"con":true,"img":false}]}
{"op":"mcm","clk":"11541037021","pt":1719501415743,"mc":[{"id":"1.230180124","rc":[{"atl":[[2.5,0.84],[2.64,2],[2.66,1]],"id":65992794}],"con":true,"img":false}]}
{"op":"mcm","clk":"11541037029","pt":1719501415850,"mc":[{"id":"1.230180124","rc":[{"atl":[[2.62,1]],"id":65992794}],"con":true,"img":false}]}
{"op":"mcm","clk":"11541037046","pt":1719501416009,"mc":[{"id":"1.230180124","rc":[{"atl":[[2.64,0]],"id":65992794}],"con":true,"img":false}]}
{"op":"mcm","clk":"11541037065","pt":1719501416263,"mc":[{"id":"1.230180124","rc":[{"atl":[[2.62,0]],"id":65992794}],"con":true,"img":false}]}
{"op":"mcm","clk":"11541037076","pt":1719501416429,"mc":[{"id":"1.230180124","rc":[{"atl":[[2.5,1.84]],"id":65992794}],"con":true,"img":false}]}
{"op":"mcm","clk":"11541037099","pt":1719501416727,"mc":[{"id":"1.230180124","rc":[{"atb":[[4.6,1.83]],"id":51567147}],"con":true,"img":false}]}
{"op":"mcm","clk":"11541037132","pt":1719501417111,"mc":[{"id":"1.230180124","rc":[{"atb":[[4.4,0]],"id":51567147}],"con":true,"img":false}]}
{"op":"mcm","clk":"11541037146","pt":1719501417317,"mc":[{"id":"1.230180124","rc":[{"atb":[[4.3,0.79],[4.7,0.84]],"id":51567147}],"con":true,"img":false}]}
{"op":"mcm","clk":"11541037154","pt":1719501417419,"mc":[{"id":"1.230180124","rc":[{"atb":[[4.4,1.83],[4.6,0]],"id":51567147}],"con":true,"img":false}]}
{"op":"mcm","clk":"11541037188","pt":1719501417832,"mc":[{"id":"1.230180124","rc":[{"atb":[[4.7,0]],"id":51567147}],"con":true,"img":false}]}
{"op":"mcm","clk":"11541037342","pt":1719501419940,"mc":[{"id":"1.230180124","rc":[{"atb":[[1.76,5]],"id":65992794}],"con":true,"img":false}]}
{"op":"mcm","clk":"11541037446","pt":1719501421233,"mc":[{"id":"1.230180124","rc":[{"atb":[[1.77,26.98]],"id":65992794},{"atl":[[130,1.21]],"id":67245400},{"atb":[[4.5,8.09]],"id":51567147},{"atl":[[65,1.36]],"id":51567147},{"atb":[[5.5,7.43]],"id":70902709},{"atl":[[11,3.79]],"id":70902709}],"con":true,"img":false}]}
{"op":"mcm","clk":"11541037463","pt":1719501421442,"mc":[{"id":"1.230180124","rc":[{"atb":[[5.4,0]],"id":70902709}],"con":true,"img":false}]}
{"op":"mcm","clk":"11541037484","pt":1719501421654,"mc":[{"id":"1.230180124","rc":[{"atb":[[5.6,1]],"id":70902709}],"con":true,"img":false}]}
{"op":"mcm","clk":"11541037497","pt":1719501421758,"mc":[{"id":"1.230180124","rc":[{"atb":[[5.6,1.84]],"id":70902709},{"atl":[[10.5,0.84]],"id":70902709}],"con":true,"img":false}]}
{"op":"mcm","clk":"11541037553","pt":1719501422327,"mc":[{"id":"1.230180124","rc":[{"atb":[[5.6,7.81]],"id":70902709}],"con":true,"img":false}]}
{"op":"mcm","clk":"11541037572","pt":1719501422638,"mc":[{"id":"1.230180124","rc":[{"atb":[[1.89,4.81]],"id":65992794},{"atb":[[4.3,0]],"id":51567147}],"con":true,"img":false}]}
{"op":"mcm","clk":"11541037584","pt":1719501422741,"mc":[{"id":"1.230180124","rc":[{"atb":[[1.9,5],[1.75,0]],"id":65992794}],"con":true,"img":false}]}
{"op":"mcm","clk":"11541037592","pt":1719501422845,"mc":[{"id":"1.230180124","rc":[{"atb":[[1.9,0],[1.78,20]],"id":65992794}],"con":true,"img":false}]}
{"op":"mcm","clk":"11541037601","pt":1719501422948,"mc":[{"id":"1.230180124","rc":[{"atb":[[1.89,10.81]],"id":65992794}],"con":true,"img":false}]}
{"op":"mcm","clk":"11541037611","pt":1719501423051,"mc":[{"id":"1.230180124","rc":[{"atb":[[1.78,0]],"id":65992794}],"con":true,"img":false}]}
{"op":"mcm","clk":"11541037616","pt":1719501423154,"mc":[{"id":"1.230180124","rc":[{"atb":[[1.89,4.81],[1.78,17.38]],"id":65992794},{"atl":[[1000,1.88]],"id":65992794},{"atl":[[1000,1.88]],"id":67245400},{"atl":[[1000,1.7]],"id":42767337}],"con":true,"img":false}]}
{"op":"mcm","clk":"11541037624","pt":1719501423258,"mc":[{"id":"1.230180124","rc":[{"atb":[[1.02,134.94],[1.9,25.09]],"id":65992794},{"atl":[[1000,0.3]],"id":65992794},{"atb":[[1.04,1.7]],"id":67245400},{"atl":[[1000,0.18]],"id":67245400},{"atb":[[1.04,1.7]],"id":42767337},{"atl":[[1000,0]],"id":42767337}],"con":true,"img":false}]}
{"op":"mcm","clk":"11541037639","pt":1719501423413,"mc":[{"id":"1.230180124","rc":[{"atb":[[1.02,133.43]],"id":65992794},{"atl":[[1000,0.18]],"id":65992794},{"atb":[[1.04,0.06]],"id":67245400},{"atb":[[1.04,0.06]],"id":42767337}],"con":true,"img":false}]}
{"op":"mcm","clk":"11541037648","pt":1719501423522,"mc":[{"id":"1.230180124","rc":[{"atl":[[2.48,0.11]],"id":65992794}],"con":true,"img":false}]}
{"op":"mcm","clk":"11541037660","pt":1719501423629,"mc":[{"id":"1.230180124","rc":[{"atb":[[1.02,133.24]],"id":65992794},{"atb":[[1.04,0]],"id":67245400},{"atb":[[1.04,0]],"id":42767337}],"con":true,"img":false}]}
{"op":"mcm","clk":"11541037668","pt":1719501423725,"mc":[{"id":"1.230180124","rc":[{"atb":[[1.9,25.27]],"id":65992794},{"atb":[[5.2,0.91]],"id":67245400},{"atb":[[5.3,0.06]],"id":42767337}],"con":true,"img":false}]}
{"op":"mcm","clk":"11541037869","pt":1719501426053,"mc":[{"id":"1.230180124","rc":[{"atl":[[2.48,35.69]],"id":65992794}],"con":true,"img":false}]}
{"op":"mcm","clk":"11541037897","pt":1719501426361,"mc":[{"id":"1.230180124","rc":[{"atl":[[2.66,0]],"id":65992794},{"atl":[[13.5,0],[120,0.62]],"id":67245400}],"con":true,"img":false}]}
{"op":"mcm","clk":"11541037909","pt":1719501426523,"mc":[{"id":"1.230180124","rc":[{"atl":[[2.5,0.84],[2.6,1]],"id":65992794}],"con":true,"img":false}]}
{"op":"mcm","clk":"11541037920","pt":1719501426618,"mc":[{"id":"1.230180124","rc":[{"atl":[[2.46,1]],"id":65992794},{"atl":[[1000,1.03]],"id":67245400}],"con":true,"img":false}]}
{"op":"mcm","clk":"11541037926","pt":1719501426721,"mc":[{"id":"1.230180124","rc":[{"atl":[[2.6,0],[2.46,1.84]],"id":65992794}],"con":true,"img":false}]}
{"op":"mcm","clk":"11541037938","pt":1719501426926,"mc":[{"id":"1.230180124","rc":[{"atl":[[120,0]],"id":67245400}],"con":true,"img":false}]}
{"op":"mcm","clk":"11541037945","pt":1719501427033,"mc":[{"id":"1.230180124","rc":[{"atl":[[2.46,2.84]],"id":65992794}],"con":true,"img":false}]}
{"op":"mcm","clk":"11541037960","pt":1719501427242,"mc":[{"id":"1.230180124","rc":[{"atb":[[1.91,5]],"id":65992794},{"atl":[[2.5,0]],"id":65992794},{"atl":[[1000,0.81]],"id":67245400}],"con":true,"img":false}]}
{"op":"mcm","clk":"11541037988","pt":1719501427545,"mc":[{"id":"1.230180124","rc":[{"atl":[[1000,0.18]],"id":67245400}],"con":true,"img":false}]}
{"op":"mcm","clk":"11541037997","pt":1719501427648,"mc":[{"id":"1.230180124","rc":[{"atl":[[13.5,0.62]],"id":67245400}],"con":true,"img":false}]}
{"op":"mcm","clk":"11541038067","pt":1719501428737,"mc":[{"id":"1.230180124","rc":[{"atb":[[1.92,27.05]],"id":65992794}],"con":true,"img":false}]}
{"op":"mcm","clk":"11541038082","pt":1719501428945,"mc":[{"id":"1.230180124","rc":[{"atb":[[2.28,0]],"id":65992794},{"atb":[[4.1,0],[4.2,3.01]],"id":51567147}],"con":true,"img":false}]}
{"op":"mcm","clk":"11541038092","pt":1719501429048,"mc":[{"id":"1.230180124","rc":[{"atb":[[1.91,0]],"id":65992794}],"con":true,"img":false}]}
{"op":"mcm","clk":"11541038103","pt":1719501429148,"mc":[{"id":"1.230180124","rc":[{"atl":[[2.46,7.84]],"id":65992794}],"con":true,"img":false}]}
{"op":"mcm","clk":"11541038114","pt":1719501429252,"mc":[{"id":"1.230180124","rc":[{"atb":[[1.93,0.84]],"id":65992794}],"con":true,"img":false}]}
{"op":"mcm","clk":"11541038128","pt":1719501429457,"mc":[{"id":"1.230180124","rc":[{"atl":[[2.44,6.35]],"id":65992794}],"con":true,"img":false}]}
{"op":"mcm","clk":"11541038144","pt":1719501429671,"mc":[{"id":"1.230180124","rc":[{"atb":[[1.78,0],[1.93,26.12]],"id":65992794}],"con":true,"img":false}]}
{"op":"mcm","clk":"11541038181","pt":1719501430038,"mc":[{"id":"1.230180124","rc":[{"atb":[[1.97,1]],"id":65992794},{"atl":[[14,0],[14.5,1]],"id":67245400},{"atb":[[4.6,1]],"id":42767337},{"atl":[[16.5,1]],"id":42767337},{"atl":[[17,0],[21,4]],"id":70902709}],"con":true,"img":false}]}
{"op":"mcm","clk":"11541038193","pt":1719501430140,"mc":[{"id":"1.230180124","rc":[{"atb":[[1.94,6.35]],"id":65992794},{"atl":[[140,0],[25,2]],"id":67245400}],"con":true,"img":false}]}
{"op":"mcm","clk":"11541038215","pt":1719501430348,"mc":[{"id":"1.230180124","rc":[{"atb":[[1.81,11.7]],"id":65992794}],"con":true,"img":false}]}
{"op":"mcm","clk":"11541038238","pt":1719501430563,"mc":[{"id":"1.230180124","rc":[{"atb":[[1.95,26.73]],"id":65992794},{"atl":[[2.46,6.84]],"id":65992794},{"atb":[[5.1,8.41]],"id":67245400},{"atl":[[130,0.21],[24,1.05]],"id":67245400}],"con":true,"img":false}]}
{"op":"mcm","clk":"11541038246","pt":1719501430652,"mc":[{"id":"1.230180124","rc":[{"atl":[[2.42,1]],"id":65992794},{"atl":[[24,2.05]],"id":67245400}],"con":true,"img":false}]}
{"op":"mcm","clk":"11541038262","pt":1719501430757,"mc":[{"id":"1.230180124","rc":[{"atb":[[1.94,0]],"id":65992794}],"con":true,"img":false}]}
{"op":"mcm","clk":"11541038271","pt":1719501430859,"mc":[{"id":"1.230180124","rc":[{"atb":[[1.98,1.02]],"id":65992794}],"con":true,"img":false}]}
{"op":"mcm","clk":"11541038305","pt":1719501431275,"mc":[{"id":"1.230180124","rc":[{"atb":[[1.93,25.28]],"id":65992794}],"con":true,"img":false}]}
{"op":"mcm","clk":"11541038319","pt":1719501431429,"mc":[{"id":"1.230180124","rc":[{"atl":[[2.42,6]],"id":65992794}],"con":true,"img":false}]}
{"op":"mcm","clk":"11541038346","pt":1719501431737,"mc":[{"id":"1.230180124","rc":[{"atb":[[2.1,1],[1.97,0]],"id":65992794},{"atb":[[4.6,1]],"id":67245400}],"con":true,"img":false}]}
{"op":"mcm","clk":"11541038359","pt":1719501431841,"mc":[{"id":"1.230180124","rc":[{"atb":[[1.96,5]],"id":65992794},{"atl":[[2.44,0],[2.46,6]],"id":65992794}],"con":true,"img":false}]}
{"op":"mcm","clk":"11541038382","pt":1719501432047,"mc":[{"id":"1.230180124","rc":[{"atb":[[5.7,4.45]],"id":70902709}],"con":true,"img":false}]}
{"op":"mcm","clk":"11541038390","pt":1719501432150,"mc":[{"id":"1.230180124","rc":[{"atb":[[1.77,0]],"id":65992794}],"con":true,"img":false}]}
{"op":"mcm","clk":"11541038407","pt":1719501432356,"mc":[{"id":"1.230180124","rc":[{"atb":[[1.97,24.7]],"id":65992794},{"atl":[[2.4,2]],"id":65992794}],"con":true,"img":false}]}
{"op":"mcm","clk":"11541038446","pt":1719501432770,"mc":[{"id":"1.230180124","rc":[{"atb":[[5.8,0.84]],"id":70902709}],"con":true,"img":false}]}
{"op":"mcm","clk":"11541038464","pt":1719501432932,"mc":[{"id":"1.230180124","rc":[{"atb":[[5.8,6.44]],"id":70902709}],"con":true,"img":false}]}
{"op":"mcm","clk":"11541038490","pt":1719501433368,"mc":[{"id":"1.230180124","rc":[{"atb":[[5.7,0]],"id":70902709}],"con":true,"img":false}]}
{"op":"mcm","clk":"11541038523","pt":1719501433726,"mc":[{"id":"1.230180124","rc":[{"spn":2.04,"spf":1.0,"id":65992794},{"spn":5.2,"spf":1.0,"id":42767337},{"spn":6.95,"spf":"NaN","id":51567147},{"atb":[[5.6,6.97]],"id":70902709},{"spn":8.15,"spf":"NaN","id":70902709}],"con":true,"img":false}]}
{"op":"mcm","clk":"11541038538","pt":1719501433984,"mc":[{"id":"1.230180124","rc":[{"atb":[[5,0]],"id":70902709}],"con":true,"img":false}]}
{"op":"mcm","clk":"11541038556","pt":1719501434146,"mc":[{"id":"1.230180124","rc":[{"spl":[[1.01,1.44]],"id":67245400}],"con":true,"img":false}]}
{"op":"mcm","clk":"11541038664","pt":1719501435546,"mc":[{"id":"1.230180124","rc":[{"atl":[[2.42,5]],"id":65992794}],"con":true,"img":false}]}
{"op":"mcm","clk":"11541038676","pt":1719501435652,"mc":[{"id":"1.230180124","rc":[{"atl":[[2.38,1]],"id":65992794}],"con":true,"img":false}]}
{"op":"mcm","clk":"11541038692","pt":1719501435856,"mc":[{"id":"1.230180124","rc":[{"atl":[[2.46,5]],"id":65992794}],"con":true,"img":false}]}
{"op":"mcm","clk":"11541038710","pt":1719501436062,"mc":[{"id":"1.230180124","rc":[{"atb":[[1.98,6.02],[1.93,0]],"id":65992794},{"atl":[[2.4,3]],"id":65992794}],"con":true,"img":false}]}
{"op":"mcm","clk":"11541038781","pt":1719501437247,"mc":[{"id":"1.230180124","rc":[{"atb":[[1.89,0],[1.9,0.18]],"id":65992794}],"con":true,"img":false}]}
{"op":"mcm","clk":"11541038795","pt":1719501437448,"mc":[{"id":"1.230180124","rc":[{"atb":[[1.99,26.04]],"id":65992794}],"con":true,"img":false}]}
{"op":"mcm","clk":"11541038801","pt":1719501437556,"mc":[{"id":"1.230180124","rc":[{"atl":[[2.4,1]],"id":65992794}],"con":true,"img":false}]}
{"op":"mcm","clk":"11541038813","pt":1719501437669,"mc":[{"id":"1.230180124","rc":[{"atl":[[14,1],[14.5,0]],"id":67245400}],"con":true,"img":false}]}
{"op":"mcm","clk":"11541038821","pt":1719501437772,"mc":[{"id":"1.230180124","rc":[{"atl":[[2.4,0]],"id":65992794}],"con":true,"img":false}]}
{"op":"mcm","clk":"11541038837","pt":1719501437974,"mc":[{"id":"1.230180124","rc":[{"atl":[[2.4,1]],"id":65992794}],"con":true,"img":false}]}
{"op":"mcm","clk":"11541038867","pt":1719501438375,"mc":[{"id":"1.230180124","rc":[{"atl":[[2.4,0],[2.38,0]],"id":65992794}],"con":true,"img":false}]}
{"op":"mcm","clk":"11541038875","pt":1719501438480,"mc":[{"id":"1.230180124","rc":[{"atl":[[2.4,1]],"id":65992794}],"con":true,"img":false}]}
{"op":"mcm","clk":"11541038884","pt":1719501438540,"mc":[{"id":"1.230180124","rc":[{"atl":[[2.4,2]],"id":65992794}],"con":true,"img":false}]}
{"op":"mcm","clk":"11541039116","pt":1719501441170,"mc":[{"id":"1.230180124","rc":[{"atb":[[5.3,1.6]],"id":67245400}],"con":true,"img":false}]}
{"op":"mcm","clk":"11541039132","pt":1719501441376,"mc":[{"id":"1.230180124","rc":[{"atb":[[5.1,6.81]],"id":67245400}],"con":true,"img":false}]}
{"op":"mcm","clk":"11541039142","pt":1719501441541,"mc":[{"id":"1.230180124","rc":[{"atb":[[5.3,0]],"id":67245400}],"con":true,"img":false}]}
{"op":"mcm","clk":"11541039153","pt":1719501441740,"mc":[{"id":"1.230180124","rc":[{"atb":[[5.2,2.51]],"id":67245400}],"con":true,"img":false}]}
{"op":"mcm","clk":"11541039172","pt":1719501441961,"mc":[{"id":"1.230180124","rc":[{"atb":[[5.3,4.79]],"id":67245400}],"con":true,"img":false}]}
{"op":"mcm","clk":"11541039194","pt":1719501442268,"mc":[{"id":"1.230180124","rc":[{"atb":[[5.4,0.84]],"id":67245400}],"con":true,"img":false}]}
{"op":"mcm","clk":"11541039219","pt":1719501442477,"mc":[{"id":"1.230180124","rc":[{"atb":[[2,24.7],[1.98,1.02]],"id":65992794}],"con":true,"img":false}]}
{"op":"mcm","clk":"11541039229","pt":1719501442583,"mc":[{"id":"1.230180124","rc":[{"atb":[[5.3,0],[5.4,2.41],[5.2,0.91]],"id":67245400}],"con":true,"img":false}]}
{"op":"mcm","clk":"11541039249","pt":1719501442776,"mc":[{"id":"1.230180124","rc":[{"atb":[[1.92,0]],"id":65992794}],"con":true,"img":false}]}
{"op":"mcm","clk":"11541039263","pt":1719501442938,"mc":[{"id":"1.230180124","rc":[{"atb":[[2.02,25.88]],"id":65992794}],"con":true,"img":false}]}
{"op":"mcm","clk":"11541039289","pt":1719501443355,"mc":[{"id":"1.230180124","rc":[{"atb":[[5.2,0.06]],"id":67245400}],"con":true,"img":false}]}
{"op":"mcm","clk":"11541039524","pt":1719501445983,"mc":[{"id":"1.230180124","rc":[{"atb":[[1.98,0]],"id":65992794}],"con":true,"img":false}]}
{"op":"mcm","clk":"11541039636","pt":1719501447582,"mc":[{"id":"1.230180124","rc":[{"atb":[[5.2,0.89]],"id":67245400}],"con":true,"img":false}]}
{"op":"mcm","clk":"11541039709","pt":1719501448780,"mc":[{"id":"1.230180124","rc":[{"atb":[[2,0],[2.04,25.88]],"id":65992794}],"con":true,"img":false}]}
{"op":"mcm","clk":"11541039753","pt":1719501449294,"mc":[{"id":"1.230180124","rc":[{"atb":[[1.95,0]],"id":65992794}],"con":true,"img":false}]}
{"op":"mcm","clk":"11541039786","pt":1719501449686,"mc":[{"id":"1.230180124","rc":[{"atb":[[2.06,23.5]],"id":65992794}],"con":true,"img":false}]}
{"op":"mcm","clk":"11541039869","pt":1719501450563,"mc":[{"id":"1.230180124","rc":[{"atb":[[1.96,10.28]],"id":65992794}],"con":true,"img":false}]}
{"op":"mcm","clk":"11541039912","pt":1719501451073,"mc":[{"id":"1.230180124","rc":[{"atl":[[2.68,0]],"id":65992794}],"con":true,"img":false}]}
{"op":"mcm","clk":"11541039928","pt":1719501451277,"mc":[{"id":"1.230180124","rc":[{"atb":[[2.1,0]],"id":65992794},{"atl":[[2.1,3.11]],"id":65992794},{"trd":[[2.1,2]],"ltp":2.1,"tv":2.0,"id":65992794}],"con":true,"img":false}]}
{"op":"mcm","clk":"11541039934","pt":1719501451380,"mc":[{"id":"1.230180124","rc":[{"atb":[[2.04,26.88]],"id":65992794},{"atl":[[2.1,0]],"id":65992794},{"trd":[[2.1,8.22]],"ltp":2.1,"tv":8.22,"id":65992794}],"con":true,"img":false}]}
{"op":"mcm","clk":"11541039949","pt":1719501451489,"mc":[{"id":"1.230180124","rc":[{"atb":[[2.1,3.11]],"id":65992794}],"con":true,"img":false}]}
{"op":"mcm","clk":"11541039969","pt":1719501451684,"mc":[{"id":"1.230180124","rc":[{"atb":[[2.08,0.84]],"id":65992794},{"atl":[[2.38,0.84]],"id":65992794}],"con":true,"img":false}]}
{"op":"mcm","clk":"11541040006","pt":1719501452046,"mc":[{"id":"1.230180124","rc":[{"atb":[[2.04,25.88]],"id":65992794}],"con":true,"img":false}]}
{"op":"mcm","clk":"11541040019","pt":1719501452167,"mc":[{"id":"1.230180124","rc":[{"atb":[[1.96,5]],"id":65992794}],"con":true,"img":false}]}
{"op":"mcm","clk":"11541040039","pt":1719501452371,"mc":[{"id":"1.230180124","rc":[{"atb":[[1.97,0]],"id":65992794}],"con":true,"img":false}]}
{"op":"mcm","clk":"11541040090","pt":1719501452985,"mc":[{"id":"1.230180124","rc":[{"atb":[[2.1,26.86]],"id":65992794}],"con":true,"img":false}]}
{"op":"mcm","clk":"11541040115","pt":1719501453246,"mc":[{"id":"1.230180124","rc":[{"atb":[[2.12,6.35]],"id":65992794}],"con":true,"img":false}]}
{"op":"mcm","clk":"11541040154","pt":1719501453755,"mc":[{"id":"1.230180124","rc":[{"atb":[[2.08,0]],"id":65992794}],"con":true,"img":false}]}
{"op":"mcm","clk":"11541040175","pt":1719501453962,"mc":[{"id":"1.230180124","rc":[{"atb":[[1.99,0]],"id":65992794}],"con":true,"img":false}]}
{"op":"mcm","clk":"11541040181","pt":1719501454073,"mc":[{"id":"1.230180124","rc":[{"atb":[[2.12,29.93]],"id":65992794}],"con":true,"img":false}]}
{"op":"mcm","clk":"11541040189","pt":1719501454175,"mc":[{"id":"1.230180124","rc":[{"atb":[[2.14,1]],"id":65992794},{"atb":[[4.5,9.09],[4.2,2.01]],"id":51567147}],"con":true,"img":false}]}
{"op":"mcm","clk":"11541040235","pt":1719501454782,"mc":[{"id":"1.230180124","rc":[{"atb":[[2.12,23.58]],"id":65992794}],"con":true,"img":false}]}
{"op":"mcm","clk":"11541040255","pt":1719501454983,"mc":[{"id":"1.230180124","rc":[{"atb":[[2.04,0],[2.14,24.58]],"id":65992794}],"con":true,"img":false}]}
{"op":"mcm","clk":"11541040278","pt":1719501455293,"mc":[{"id":"1.230180124","rc":[{"atl":[[17.5,1],[14,0]],"id":67245400}],"con":true,"img":false}]}
{"op":"mcm","clk":"11541040311","pt":1719501455666,"mc":[{"id":"1.230180124","rc":[{"atb":[[5.2,0.06]],"id":67245400}],"con":true,"img":false}]}
{"op":"mcm","clk":"11541040325","pt":1719501455863,"mc":[{"id":"1.230180124","rc":[{"atb":[[2.02,0],[2.16,6.35]],"id":65992794}],"con":true,"img":false}]}
{"op":"mcm","clk":"11541040335","pt":1719501455968,"mc":[{"id":"1.230180124","rc":[{"atb":[[2.14,48.39]],"id":65992794}],"con":true,"img":false}]}
{"op":"mcm","clk":"11541040427","pt":1719501457066,"mc":[{"id":"1.230180124","rc":[{"spl":[[1.01,2.44]],"id":67245400}],"con":true,"img":false}]}
{"op":"mcm","clk":"11541040442","pt":1719501457268,"mc":[{"id":"1.230180124","rc":[{"atb":[[2.06,0]],"id":65992794}],"con":true,"img":false}]}
{"op":"mcm","clk":"11541040461","pt":1719501457575,"mc":[{"id":"1.230180124","rc":[{"atb":[[2.16,25.76]],"id":65992794}],"con":true,"img":false}]}
{"op":"mcm","clk":"11541040579","pt":1719501459178,"mc":[{"id":"1.230180124","rc":[{"atl":[[2.56,3.43]],"id":65992794}],"con":true,"img":false}]}
{"op":"mcm","clk":"11541040690","pt":1719501460570,"mc":[{"id":"1.230180124","rc":[{"atb":[[2.1,10.78]],"id":67245400}],"con":true,"img":false}]}
{"op":"mcm","clk":"11541040700","pt":1719501460671,"mc":[{"id":"1.230180124","rc":[{"atb":[[1.77,15.4]],"id":65992794}],"con":true,"img":false}]}
{"op":"mcm","clk":"11541040708","pt":1719501460782,"mc":[{"id":"1.230180124","rc":[{"atb":[[1.89,13.32]],"id":70902709}],"con":true,"img":false}]}
{"op":"mcm","clk":"11541040726","pt":1719501460982,"mc":[{"id":"1.230180124","rc":[{"atb":[[2.2,9.88]],"id":51567147}],"con":true,"img":false}]}
{"op":"mcm","clk":"11541040739","pt":1719501461194,"mc":[{"id":"1.230180124","rc":[{"atb":[[2.14,24.81],[2.18,25.76]],"id":65992794}],"con":true,"img":false}]}
{"op":"mcm","clk":"11541040759","pt":1719501461398,"mc":[{"id":"1.230180124","rc":[{"atb":[[2.16,19.41]],"id":65992794}],"con":true,"img":false}]}
{"op":"mcm","clk":"11541040774","pt":1719501461594,"mc":[{"id":"1.230180124","rc":[{"atb":[[2.2,6.35]],"id":65992794},{"atl":[[16.5,0],[17.5,1]],"id":42767337}],"con":true,"img":false}]}
{"op":"mcm","clk":"11541040848","pt":1719501462694,"mc":[{"id":"1.230180124","rc":[{"atb":[[2.1,3.11]],"id":65992794}],"con":true,"img":false}]}
{"op":"mcm","clk":"11541040856","pt":1719501462795,"mc":[{"id":"1.230180124","rc":[{"atb":[[2.2,26.87]],"id":65992794}],"con":true,"img":false}]}
{"op":"mcm","clk":"11541040959","pt":1719501464196,"mc":[{"id":"1.230180124","rc":[{"atb":[[2.14,23.81]],"id":65992794}],"con":true,"img":false}]}
{"op":"mcm","clk":"11541041017","pt":1719501465074,"mc":[{"id":"1.230180124","rc":[{"atl":[[2.48,0.11]],"id":65992794}],"con":true,"img":false}]}
{"op":"mcm","clk":"11541041137","pt":1719501466882,"mc":[{"id":"1.230180124","rc":[{"atl":[[2.56,0]],"id":65992794}],"con":true,"img":false}]}
{"op":"mcm","clk":"11541041167","pt":1719501467288,"mc":[{"id":"1.230180124","rc":[{"atb":[[2.18,0],[2.2,52.63]],"id":65992794}],"con":true,"img":false}]}
{"op":"mcm","clk":"11541041213","pt":1719501468001,"mc":[{"id":"1.230180124","rc":[{"atb":[[2.12,22.96],[2.14,0],[2.2,32.11],[2.16,0]],"id":65992794}],"con":true,"img":false}]}
{"op":"mcm","clk":"11541041230","pt":1719501468170,"mc":[{"id":"1.230180124","rc":[{"atl":[[120,1]],"id":42767337}],"con":true,"img":false}]}
{"op":"mcm","clk":"11541041309","pt":1719501469201,"mc":[{"id":"1.230180124","rc":[{"atb":[[2.14,1]],"id":65992794}],"con":true,"img":false}]}
{"op":"mcm","clk":"11541041385","pt":1719501470171,"mc":[{"id":"1.230180124","rc":[{"atb":[[1.9,0]],"id":65992794},{"atl":[[2.48,0]],"id":65992794},{"atb":[[5.2,0]],"id":67245400},{"atb":[[5.3,0]],"id":42767337}],"con":true,"img":false}]}
{"op":"mcm","clk":"11541041396","pt":1719501470284,"mc":[{"id":"1.230180124","rc":[{"atb":[[2.2,55.43]],"id":65992794}],"con":true,"img":false}]}
{"op":"mcm","clk":"11541041468","pt":1719501471277,"mc":[{"id":"1.230180124","rc":[{"atl":[[13.5,0]],"id":67245400}],"con":true,"img":false}]}
{"op":"mcm","clk":"11541041476","pt":1719501471361,"mc":[{"id":"1.230180124","rc":[{"atl":[[1000,1.03]],"id":67245400}],"con":true,"img":false}]}
{"op":"mcm","clk":"11541041490","pt":1719501471567,"mc":[{"id":"1.230180124","rc":[{"atl":[[1000,0.84]],"id":42767337}],"con":true,"img":false}]}
{"op":"mcm","clk":"11541041515","pt":1719501471879,"mc":[{"id":"1.230180124","rc":[{"atb":[[4.6,1.83],[4.4,0]],"id":51567147}],"con":true,"img":false}]}
{"op":"mcm","clk":"11541041537","pt":1719501472193,"mc":[{"id":"1.230180124","rc":[{"atl":[[1000,0.49]],"id":42767337},{"atb":[[4.7,0.84]],"id":51567147}],"con":true,"img":false}]}
{"op":"mcm","clk":"11541041551","pt":1719501472397,"mc":[{"id":"1.230180124","rc":[{"atl":[[1000,0.81]],"id":67245400}],"con":true,"img":false}]}
{"op":"mcm","clk":"11541041556","pt":1719501472491,"mc":[{"id":"1.230180124","rc":[{"atl":[[1000,0]],"id":42767337},{"atb":[[4.7,7.33]],"id":51567147}],"con":true,"img":false}]}
{"op":"mcm","clk":"11541041564","pt":1719501472604,"mc":[{"id":"1.230180124","rc":[{"atl":[[17,0.49]],"id":42767337}],"con":true,"img":false}]}
{"op":"mcm","clk":"11541041582","pt":1719501472905,"mc":[{"id":"1.230180124","rc":[{"atl":[[1000,0.18]],"id":67245400}],"con":true,"img":false}]}
{"op":"mcm","clk":"11541041594","pt":1719501472972,"mc":[{"id":"1.230180124","rc":[{"atl":[[17,0.62]],"id":67245400},{"atb":[[4.8,5.29]],"id":51567147}],"con":true,"img":false}]}
{"op":"mcm","clk":"11541041600","pt":1719501473061,"mc":[{"id":"1.230180124","rc":[{"atb":[[4.8,12.25]],"id":51567147}],"con":true,"img":false}]}
{"op":"mcm","clk":"11541041611","pt":1719501473175,"mc":[{"id":"1.230180124","rc":[{"atb":[[4.8,14.01],[4.6,0]],"id":51567147}],"con":true,"img":false}]}
{"op":"mcm","clk":"11541041621","pt":1719501473281,"mc":[{"id":"1.230180124","rc":[{"atb":[[4.5,8.25]],"id":51567147}],"con":true,"img":false}]}
{"op":"mcm","clk":"11541041711","pt":1719501474261,"mc":[{"id":"1.230180124","rc":[{"atb":[[4.5,7.25]],"id":51567147}],"con":true,"img":false}]}
{"op":"mcm","clk":"11541041913","pt":1719501477068,"mc":[{"id":"1.230180124","rc":[{"atb":[[2.16,4.47]],"id":65992794}],"con":true,"img":false}]}
{"op":"mcm","clk":"11541041986","pt":1719501477997,"mc":[{"id":"1.230180124","rc":[{"atb":[[2.16,0]],"id":65992794}],"con":true,"img":false}]}
{"op":"mcm","clk":"11541042073","pt":1719501479300,"mc":[{"id":"1.230180124","rc":[{"atb":[[4.9,0.84]],"id":51567147}],"con":true,"img":false}]}
{"op":"mcm","clk":"11541042116","pt":1719501479771,"mc":[{"id":"1.230180124","rc":[{"atb":[[4.8,8.72]],"id":51567147}],"con":true,"img":false}]}
{"op":"mcm","clk":"11541042158","pt":1719501480181,"mc":[{"id":"1.230180124","rc":[{"atb":[[5.4,4.57]],"id":67245400}],"con":true,"img":false}]}
{"op":"mcm","clk":"11541042168","pt":1719501480284,"mc":[{"id":"1.230180124","rc":[{"atb":[[2.38,8.59]],"id":42767337}],"con":true,"img":false}]}
{"op":"mcm","clk":"11541042529","pt":1719501484288,"mc":[{"id":"1.230180124","rc":[{"atb":[[4.5,8.25]],"id":51567147}],"con":true,"img":false}]}
{"op":"mcm","clk":"11541042736","pt":1719501486488,"mc":[{"id":"1.230180124","rc":[{"atb":[[2.36,2.5]],"id":42767337},{"atb":[[1.88,5.12]],"id":70902709}],"con":true,"img":false}]}
{"op":"mcm","clk":"11541043011","pt":1719501489823,"mc":[{"id":"1.230180124","rc":[{"atb":[[1.7,0]],"id":65992794},{"atb":[[1.72,0]],"id":70902709}],"con":true,"img":false}]}
{"op":"mcm","clk":"11541043016","pt":1719501489872,"mc":[{"id":"1.230180124","rc":[{"atb":[[1.97,17.37]],"id":65992794},{"atb":[[1.9,17.57]],"id":70902709}],"con":true,"img":false}]}
{"op":"mcm","clk":"11541043074","pt":1719501490613,"mc":[{"id":"1.230180124","rc":[{"atb":[[1.88,0]],"id":70902709}],"con":true,"img":false}]}
{"op":"mcm","clk":"11541043270","pt":1719501493310,"mc":[{"id":"1.230180124","rc":[{"atb":[[2.1,49.03],[2.2,29.67]],"id":65992794},{"atb":[[4.6,0]],"id":67245400},{"atl":[[17.5,0],[18.5,1]],"id":67245400},{"atl":[[17.5,0],[18,1]],"id":42767337}],"con":true,"img":false}]}
{"op":"mcm","clk":"11541043276","pt":1719501493411,"mc":[{"id":"1.230180124","rc":[{"atb":[[4.9,1]],"id":67245400},{"atl":[[140,0],[30,2]],"id":42767337}],"con":true,"img":false}]}
{"op":"mcm","clk":"11541043286","pt":1719501493519,"mc":[{"id":"1.230180124","rc":[{"atl":[[120,0]],"id":42767337}],"con":true,"img":false}]}
{"op":"mcm","clk":"11541043311","pt":1719501493826,"mc":[{"id":"1.230180124","rc":[{"spn":2.2,"spf":1.0,"id":65992794},{"spn":5.4,"spf":1.0,"id":67245400},{"atl":[[130,0.84]],"id":42767337},{"spn":5.2,"spf":1.0,"id":42767337},{"spn":7.15,"spf":"NaN","id":51567147}],"con":true,"img":false}]}
{"op":"mcm","clk":"11541043315","pt":1719501493931,"mc":[{"id":"1.230180124","rc":[{"atl":[[29,1]],"id":42767337}],"con":true,"img":false}]}
{"op":"mcm","clk":"11541043325","pt":1719501493995,"mc":[{"id":"1.230180124","rc":[{"atl":[[29,2]],"id":42767337}],"con":true,"img":false}]}
{"op":"mcm","clk":"11541043331","pt":1719501494087,"mc":[{"id":"1.230180124","rc":[{"atl":[[1000,0.46]],"id":67245400},{"atl":[[1000,0.28]],"id":42767337},{"atl":[[1000,0.54]],"id":51567147}],"con":true,"img":false}]}
{"op":"mcm","clk":"11541043348","pt":1719501494296,"mc":[{"id":"1.230180124","rc":[{"atl":[[1000,0.18]],"id":67245400},{"atl":[[29,1],[1000,0]],"id":42767337},{"atl":[[1000,0]],"id":51567147}],"con":true,"img":false}]}
{"op":"mcm","clk":"11541043362","pt":1719501494434,"mc":[{"id":"1.230180124","rc":[{"atl":[[18.5,1.28]],"id":67245400},{"atl":[[18,1.28]],"id":42767337},{"atl":[[9.4,1.54]],"id":51567147}],"con":true,"img":false}]}
{"op":"mcm","clk":"11541043379","pt":1719501494610,"mc":[{"id":"1.230180124","rc":[{"atl":[[17,1.49]],"id":42767337}],"con":true,"img":false}]}
{"op":"mcm","clk":"11541043391","pt":1719501494720,"mc":[{"id":"1.230180124","rc":[{"atl":[[18,0.84]],"id":67245400},{"atl":[[17.5,0.84]],"id":42767337}],"con":true,"img":false}]}
{"op":"mcm","clk":"11541043644","pt":1719501498041,"mc":[{"id":"1.230180124","rc":[{"atb":[[1.82,15.48]],"id":65992794}],"con":true,"img":false}]}
{"op":"mcm","clk":"11541043659","pt":1719501498236,"mc":[{"id":"1.230180124","rc":[{"atb":[[1.67,15.16]],"id":65992794}],"con":true,"img":false}]}
{"op":"mcm","clk":"11541043667","pt":1719501498341,"mc":[{"id":"1.230180124","rc":[{"atl":[[17,0],[1000,1.03]],"id":67245400}],"con":true,"img":false}]}
{"op":"mcm","clk":"11541043686","pt":1719501498600,"mc":[{"id":"1.230180124","rc":[{"atl":[[29,0]],"id":42767337},{"atb":[[5,1.69]],"id":51567147},{"atl":[[65,0.36]],"id":51567147}],"con":true,"img":false}]}
{"op":"mcm","clk":"11541043692","pt":1719501498709,"mc":[{"id":"1.230180124","rc":[{"atl":[[16.5,1]],"id":42767337},{"atb":[[4.8,6.96]],"id":51567147},{"atl":[[9.2,1]],"id":51567147}],"con":true,"img":false}]}
{"op":"mcm","clk":"11541043710","pt":1719501498911,"mc":[{"id":"1.230180124","rc":[{"atl":[[1000,0.81]],"id":67245400},{"atb":[[5.1,4.97]],"id":51567147}],"con":true,"img":false}]}
{"op":"mcm","clk":"11541043722","pt":1719501499047,"mc":[{"id":"1.230180124","rc":[{"atb":[[5.1,11.19],[5,0]],"id":51567147},{"atl":[[9.2,3.84]],"id":51567147}],"con":true,"img":false}]}
{"op":"mcm","clk":"11541043730","pt":1719501499117,"mc":[{"id":"1.230180124","rc":[{"atl":[[70,0],[14,5.38]],"id":51567147}],"con":true,"img":false}]}
{"op":"mcm","clk":"11541043738","pt":1719501499220,"mc":[{"id":"1.230180124","rc":[{"atb":[[4.9,1.69],[5.2,0.84],[4.7,6.49]],"id":51567147}],"con":true,"img":false}]}
{"op":"mcm","clk":"11541043744","pt":1719501499324,"mc":[{"id":"1.230180124","rc":[{"atl":[[1000,0.84]],"id":42767337}],"con":true,"img":false}]}
{"op":"mcm","clk":"11541043754","pt":1719501499441,"mc":[{"id":"1.230180124","rc":[{"atb":[[4.5,7.25]],"id":51567147}],"con":true,"img":false}]}
{"op":"mcm","clk":"11541043761","pt":1719501499546,"mc":[{"id":"1.230180124","rc":[{"atl":[[1000,0.18]],"id":67245400}],"con":true,"img":false}]}
{"op":"mcm","clk":"11541043765","pt":1719501499634,"mc":[{"id":"1.230180124","rc":[{"atl":[[17.5,0.62]],"id":67245400}],"con":true,"img":false}]}
{"op":"mcm","clk":"11541043775","pt":1719501499691,"mc":[{"id":"1.230180124","rc":[{"atl":[[9,0.84]],"id":51567147}],"con":true,"img":false}]}
{"op":"mcm","clk":"11541043788","pt":1719501499805,"mc":[{"id":"1.230180124","rc":[{"atb":[[5.1,6.22]],"id":51567147}],"con":true,"img":false}]}
{"op":"mcm","clk":"11541043803","pt":1719501500011,"mc":[{"id":"1.230180124","rc":[{"atl":[[17,1],[1000,0.52]],"id":42767337}],"con":true,"img":false}]}
{"op":"mcm","clk":"11541043825","pt":1719501500305,"mc":[{"id":"1.230180124","rc":[{"atl":[[1000,0]],"id":42767337}],"con":true,"img":false}]}
{"op":"mcm","clk":"11541043831","pt":1719501500409,"mc":[{"id":"1.230180124","rc":[{"atl":[[16,0.52]],"id":42767337}],"con":true,"img":false}]}
{"op":"mcm","clk":"11541043839","pt":1719501500518,"mc":[{"id":"1.230180124","rc":[{"atl":[[16.5,0]],"id":42767337}],"con":true,"img":false}]}
{"op":"mcm","clk":"11541043847","pt":1719501500619,"mc":[{"id":"1.230180124","rc":[{"atl":[[29,1]],"id":42767337}],"con":true,"img":false}]}
{"op":"mcm","clk":"11541043960","pt":1719501502126,"mc":[{"id":"1.230180124","rc":[{"atl":[[17.5,1.84],[18,0.28]],"id":42767337}],"con":true,"img":false}]}
{"op":"mcm","clk":"11541043971","pt":1719501502234,"mc":[{"id":"1.230180124","rc":[{"atb":[[2.18,4.44]],"id":65992794}],"con":true,"img":false}]}
{"op":"mcm","clk":"11541043979","pt":1719501502340,"mc":[{"id":"1.230180124","rc":[{"spl":[[1.01,31]],"id":65992794}],"con":true,"img":false}]}
{"op":"mcm","clk":"11541043998","pt":1719501502544,"mc":[{"id":"1.230180124","rc":[{"atl":[[29,0]],"id":42767337}],"con":true,"img":false}]}
{"op":"mcm","clk":"11541044005","pt":1719501502637,"mc":[{"id":"1.230180124","rc":[{"atl":[[17,2]],"id":42767337}],"con":true,"img":false}]}
{"op":"mcm","clk":"11541044045","pt":1719501503215,"mc":[{"id":"1.230180124","rc":[{"atl":[[16.5,0.84]],"id":42767337}],"con":true,"img":false}]}
{"op":"mcm","clk":"11541044444","pt":1719501508605,"mc":[{"id":"1.230180124","rc":[{"atl":[[18.5,1]],"id":67245400},{"atl":[[18,0]],"id":42767337},{"atl":[[9.4,1]],"id":51567147}],"con":true,"img":false}]}
{"op":"mcm","clk":"11541044548","pt":1719501509848,"mc":[{"id":"1.230180124","rc":[{"atl":[[9.2,2.84]],"id":51567147}],"con":true,"img":false}]}
{"op":"mcm","clk":"11541044556","pt":1719501509910,"mc":[{"id":"1.230180124","rc":[{"atl":[[13.5,1]],"id":51567147}],"con":true,"img":false}]}
{"op":"mcm","clk":"11541044636","pt":1719501511052,"mc":[{"id":"1.230180124","rc":[{"atb":[[5.2,14.68]],"id":42767337}],"con":true,"img":false}]}
{"op":"mcm","clk":"11541044654","pt":1719501511250,"mc":[{"id":"1.230180124","rc":[{"atb":[[1.89,18.44]],"id":70902709}],"con":true,"img":false}]}
{"op":"mcm","clk":"11541044689","pt":1719501511729,"mc":[{"id":"1.230180124","rc":[{"atb":[[2,45.92],[2.1,3.11]],"id":65992794},{"atl":[[18.5,0],[19.5,1],[21,2],[25,0]],"id":67245400},{"atb":[[2.36,0]],"id":42767337},{"atl":[[17.5,0.84],[18,1],[18.5,1],[26,2.7],[30,0]],"id":42767337},{"atl":[[12,2],[13.5,0],[14,0]],"id":51567147},{"atl":[[17,4],[21,0]],"id":70902709}],"con":true,"img":false}]}
{"op":"mcm","clk":"11541044698","pt":1719501511832,"mc":[{"id":"1.230180124","rc":[{"atl":[[9,1.84]],"id":51567147}],"con":true,"img":false}]}
{"op":"mcm","clk":"11541044728","pt":1719501512148,"mc":[{"id":"1.230180124","rc":[{"atl":[[24,1.05]],"id":67245400},{"atl":[[17,1]],"id":42767337}],"con":true,"img":false}]}
{"op":"mcm","clk":"11541044736","pt":1719501512250,"mc":[{"id":"1.230180124","rc":[{"atl":[[20,1]],"id":67245400},{"atl":[[25,1]],"id":42767337}],"con":true,"img":false}]}
{"op":"mcm","clk":"11541044748","pt":1719501512349,"mc":[{"id":"1.230180124","rc":[{"atl":[[18,0]],"id":67245400}],"con":true,"img":false}]}
{"op":"mcm","clk":"11541044752","pt":1719501512443,"mc":[{"id":"1.230180124","rc":[{"atl":[[9,4.73]],"id":51567147}],"con":true,"img":false}]}
{"op":"mcm","clk":"11541044847","pt":1719501513655,"mc":[{"id":"1.230180124","rc":[{"atl":[[2.58,3.36]],"id":65992794}],"con":true,"img":false}]}
{"op":"mcm","clk":"11541044912","pt":1719501514430,"mc":[{"id":"1.230180124","rc":[{"atb":[[2.1,0]],"id":67245400},{"atl":[[1000,0.44]],"id":67245400},{"atl":[[1000,0.31]],"id":42767337},{"atb":[[2.2,0]],"id":51567147},{"atl":[[1000,0.57]],"id":51567147},{"atb":[[1.89,5.12]],"id":70902709}],"con":true,"img":false}]}
{"op":"mcm","clk":"11541044930","pt":1719501514636,"mc":[{"id":"1.230180124","rc":[{"atl":[[1000,0.18]],"id":67245400},{"atl":[[1000,0]],"id":42767337},{"atl":[[1000,0]],"id":51567147}],"con":true,"img":false}]}
{"op":"mcm","clk":"11541044938","pt":1719501514741,"mc":[{"id":"1.230180124","rc":[{"atl":[[19.5,1.26]],"id":67245400},{"atl":[[16.5,1.15]],"id":42767337},{"atl":[[9,5.3]],"id":51567147}],"con":true,"img":false}]}
{"op":"mcm","clk":"11541044979","pt":1719501515251,"mc":[{"id":"1.230180124","rc":[{"atl":[[19,0.84]],"id":67245400}],"con":true,"img":false}]}
{"op":"mcm","clk":"11541045390","pt":1719501520247,"mc":[{"id":"1.230180124","rc":[{"atl":[[18.5,0]],"id":42767337}],"con":true,"img":false}]}
{"op":"mcm","clk":"11541045596","pt":1719501522732,"mc":[{"id":"1.230180124","rc":[{"atl":[[8.8,2.88]],"id":51567147}],"con":true,"img":false}]}
{"op":"mcm","clk":"11541045640","pt":1719501523389,"mc":[{"id":"1.230180124","rc":[{"atl":[[8.6,0.84]],"id":51567147}],"con":true,"img":false}]}
{"op":"mcm","clk":"11541045659","pt":1719501523559,"mc":[{"id":"1.230180124","rc":[{"atl":[[9,4.3],[8.6,4.12]],"id":51567147}],"con":true,"img":false}]}
{"op":"mcm","clk":"11541045671","pt":1719501523690,"mc":[{"id":"1.230180124","rc":[{"atl":[[8.6,5.12]],"id":51567147}],"con":true,"img":false}]}
{"op":"mcm","clk":"11541045679","pt":1719501523760,"mc":[{"id":"1.230180124","rc":[{"atl":[[8.8,0]],"id":51567147}],"con":true,"img":false}]}
{"op":"mcm","clk":"11541045721","pt":1719501524340,"mc":[{"id":"1.230180124","rc":[{"atl":[[9,3.46]],"id":51567147}],"con":true,"img":false}]}
{"op":"mcm","clk":"11541045735","pt":1719501524550,"mc":[{"id":"1.230180124","rc":[{"atl":[[8.6,4.12]],"id":51567147}],"con":true,"img":false}]}
{"op":"mcm","clk":"11541045743","pt":1719501524662,"mc":[{"id":"1.230180124","rc":[{"atl":[[8.8,1]],"id":51567147}],"con":true,"img":false}]}
{"op":"mcm","clk":"11541045753","pt":1719501524759,"mc":[{"id":"1.230180124","rc":[{"atl":[[2.4,1]],"id":65992794}],"con":true,"img":false}]}
{"op":"mcm","clk":"11541045763","pt":1719501524864,"mc":[{"id":"1.230180124","rc":[{"atl":[[8.4,3.02]],"id":51567147}],"con":true,"img":false}]}
{"op":"mcm","clk":"11541045813","pt":1719501525433,"mc":[{"id":"1.230180124","rc":[{"atl":[[65,0]],"id":51567147}],"con":true,"img":false}]}
{"op":"mcm","clk":"11541045824","pt":1719501525539,"mc":[{"id":"1.230180124","rc":[{"atl":[[8.8,0]],"id":51567147}],"con":true,"img":false}]}
{"op":"mcm","clk":"11541045834","pt":1719501525644,"mc":[{"id":"1.230180124","rc":[{"atl":[[8.2,1]],"id":51567147}],"con":true,"img":false}]}
{"op":"mcm","clk":"11541045844","pt":1719501525742,"mc":[{"id":"1.230180124","rc":[{"atl":[[2.58,0]],"id":65992794}],"con":true,"img":false}]}
{"op":"mcm","clk":"11541045859","pt":1719501525952,"mc":[{"id":"1.230180124","rc":[{"atl":[[8.4,0]],"id":51567147}],"con":true,"img":false}]}
{"op":"mcm","clk":"11541045868","pt":1719501526056,"mc":[{"id":"1.230180124","rc":[{"atl":[[8.4,3.65]],"id":51567147}],"con":true,"img":false}]}
{"op":"mcm","clk":"11541046070","pt":1719501528743,"mc":[{"id":"1.230180124","rc":[{"atl":[[17.5,0]],"id":67245400}],"con":true,"img":false}]}
{"op":"mcm","clk":"11541046083","pt":1719501528939,"mc":[{"id":"1.230180124","rc":[{"atl":[[19.5,1]],"id":67245400},{"atl":[[16.5,0.84]],"id":42767337},{"atl":[[9,2.89]],"id":51567147}],"con":true,"img":false}]}
{"op":"mcm","clk":"11541046093","pt":1719501529146,"mc":[{"id":"1.230180124","rc":[{"atl":[[1000,1.03]],"id":67245400}],"con":true,"img":false}]}
{"op":"mcm","clk":"11541046138","pt":1719501529771,"mc":[{"id":"1.230180124","rc":[{"atl":[[1000,0.81]],"id":67245400}],"con":true,"img":false}]}
{"op":"mcm","clk":"11541046163","pt":1719501530069,"mc":[{"id":"1.230180124","rc":[{"atl":[[1000,0.18]],"id":67245400}],"con":true,"img":false}]}
{"op":"mcm","clk":"11541046172","pt":1719501530173,"mc":[{"id":"1.230180124","rc":[{"atl":[[18.5,0.62]],"id":67245400}],"con":true,"img":false}]}
{"op":"mcm","clk":"11541046646","pt":1719501535973,"mc":[{"id":"1.230180124","rc":[{"atl":[[2.58,3.36]],"id":65992794}],"con":true,"img":false}]}
{"op":"mcm","clk":"11541046662","pt":1719501536242,"mc":[{"id":"1.230180124","rc":[{"atb":[[2.18,0]],"id":65992794}],"con":true,"img":false}]}
{"op":"mcm","clk":"11541046701","pt":1719501536756,"mc":[{"id":"1.230180124","rc":[{"atl":[[9,0],[8.4,0],[8.6,0.84]],"id":51567147}],"con":true,"img":false}]}
{"op":"mcm","clk":"11541046709","pt":1719501536861,"mc":[{"id":"1.230180124","rc":[{"atb":[[1.89,0]],"id":70902709}],"con":true,"img":false}]}
{"op":"mcm","clk":"11541046747","pt":1719501537301,"mc":[{"id":"1.230180124","rc":[{"atl":[[2.58,0]],"id":65992794}],"con":true,"img":false}]}
{"op":"mcm","clk":"11541046778","pt":1719501537580,"mc":[{"id":"1.230180124","rc":[{"atl":[[2.5,18.29]],"id":65992794}],"con":true,"img":false}]}
{"op":"mcm","clk":"11541046791","pt":1719501537684,"mc":[{"id":"1.230180124","rc":[{"atb":[[1.91,13.95]],"id":70902709}],"con":true,"img":false}]}
{"op":"mcm","clk":"11541046802","pt":1719501537786,"mc":[{"id":"1.230180124","rc":[{"atb":[[2.08,4.8]],"id":65992794}],"con":true,"img":false}]}
{"op":"mcm","clk":"11541046898","pt":1719501538870,"mc":[{"id":"1.230180124","rc":[{"atb":[[5.9,1.43],[5.5,5.89]],"id":70902709}],"con":true,"img":false}]}
{"op":"mcm","clk":"11541046905","pt":1719501538980,"mc":[{"id":"1.230180124","rc":[{"atb":[[5.9,6.52]],"id":70902709}],"con":true,"img":false}]}
{"op":"mcm","clk":"11541046919","pt":1719501539082,"mc":[{"id":"1.230180124","rc":[{"atb":[[5.6,5.97]],"id":70902709}],"con":true,"img":false}]}
{"op":"mcm","clk":"11541046926","pt":1719501539181,"mc":[{"id":"1.230180124","rc":[{"atb":[[6,0.84]],"id":70902709}],"con":true,"img":false}]}
{"op":"mcm","clk":"11541046938","pt":1719501539286,"mc":[{"id":"1.230180124","rc":[{"atb":[[6,1.84]],"id":70902709}],"con":true,"img":false}]}
{"op":"mcm","clk":"11541046980","pt":1719501539653,"mc":[{"id":"1.230180124","rc":[{"atb":[[5.8,5.6]],"id":70902709}],"con":true,"img":false}]}
{"op":"mcm","clk":"11541046990","pt":1719501539758,"mc":[{"id":"1.230180124","rc":[{"atb":[[5.5,0]],"id":70902709}],"con":true,"img":false}]}
{"op":"mcm","clk":"11541046998","pt":1719501539862,"mc":[{"id":"1.230180124","rc":[{"atl":[[1000,0.45]],"id":67245400},{"atl":[[1000,0.31]],"id":42767337},{"atl":[[1000,0.62]],"id":51567147}],"con":true,"img":false}]}
{"op":"mcm","clk":"11541047006","pt":1719501539969,"mc":[{"id":"1.230180124","rc":[{"atb":[[6,7.01]],"id":70902709}],"con":true,"img":false}]}
{"op":"mcm","clk":"11541047015","pt":1719501540069,"mc":[{"id":"1.230180124","rc":[{"atl":[[1000,0.18]],"id":67245400},{"atl":[[1000,0]],"id":42767337},{"atl":[[1000,0]],"id":51567147}],"con":true,"img":false}]}
{"op":"mcm","clk":"11541047023","pt":1719501540173,"mc":[{"id":"1.230180124","rc":[{"atl":[[19,1.11]],"id":67245400},{"atl":[[16.5,1.15]],"id":42767337},{"atl":[[8.2,1.62]],"id":51567147}],"con":true,"img":false}]}
{"op":"mcm","clk":"11541047109","pt":1719501541161,"mc":[{"id":"1.230180124","rc":[{"atl":[[8.2,4.84]],"id":51567147}],"con":true,"img":false}]}
{"op":"mcm","clk":"11541047140","pt":1719501541587,"mc":[{"id":"1.230180124","rc":[{"atl":[[8.2,3.84]],"id":51567147}],"con":true,"img":false}]}
{"op":"mcm","clk":"11541047149","pt":1719501541680,"mc":[{"id":"1.230180124","rc":[{"atl":[[8,0.84],[9,1],[8.6,0]],"id":51567147}],"con":true,"img":false}]}
{"op":"mcm","clk":"11541047189","pt":1719501542257,"mc":[{"id":"1.230180124","rc":[{"atl":[[9,0]],"id":51567147}],"con":true,"img":false}]}
{"op":"mcm","clk":"11541047198","pt":1719501542370,"mc":[{"id":"1.230180124","rc":[{"atl":[[8,1.84]],"id":51567147}],"con":true,"img":false}]}
{"op":"mcm","clk":"11541047268","pt":1719501543356,"mc":[{"id":"1.230180124","rc":[{"atl":[[8,5.14]],"id":51567147}],"con":true,"img":false}]}
{"op":"mcm","clk":"11541047351","pt":1719501544697,"mc":[{"id":"1.230180124","rc":[{"atb":[[6.2,4.09]],"id":70902709}],"con":true,"img":false}]}
{"op":"mcm","clk":"11541047366","pt":1719501544905,"mc":[{"id":"1.230180124","rc":[{"atb":[[5.6,0]],"id":70902709}],"con":true,"img":false}]}
{"op":"mcm","clk":"11541047373","pt":1719501544962,"mc":[{"id":"1.230180124","rc":[{"atb":[[6.2,8.42]],"id":70902709}],"con":true,"img":false}]}
{"op":"mcm","clk":"11541047388","pt":1719501545176,"mc":[{"id":"1.230180124","rc":[{"atb":[[6,6.01]],"id":70902709}],"con":true,"img":false}]}
{"op":"mcm","clk":"11541047404","pt":1719501545384,"mc":[{"id":"1.230180124","rc":[{"atb":[[6.4,1]],"id":70902709}],"con":true,"img":false}]}
{"op":"mcm","clk":"11541047433","pt":1719501545791,"mc":[{"id":"1.230180124","rc":[{"atb":[[6.2,4.33]],"id":70902709}],"con":true,"img":false}]}
{"op":"mcm","clk":"11541047550","pt":1719501547400,"mc":[{"id":"1.230180124","rc":[{"atb":[[1.77,0]],"id":65992794},{"atb":[[2.38,0]],"id":42767337}],"con":true,"img":false}]}
{"op":"mcm","clk":"11541047719","pt":1719501549262,"mc":[{"id":"1.230180124","rc":[{"atl":[[18,0],[18.5,1]],"id":42767337}],"con":true,"img":false}]}
{"op":"mcm","clk":"11541047747","pt":1719501549687,"mc":[{"id":"1.230180124","rc":[{"atb":[[2.3,1]],"id":65992794},{"atb":[[5,1]],"id":51567147}],"con":true,"img":false}]}
{"op":"mcm","clk":"11541047761","pt":1719501549796,"mc":[{"id":"1.230180124","rc":[{"atb":[[2.3,0],[2.14,0]],"id":65992794},{"trd":[[2.3,2]],"ltp":2.3,"tv":2.0,"id":65992794}],"con":true,"img":false}]}
{"op":"mcm","clk":"11541047798","pt":1719501550088,"mc":[{"id":"1.230180124","rc":[{"atb":[[4.9,0]],"id":67245400},{"atl":[[19,2.11],[19.5,0]],"id":67245400},{"atb":[[4.3,1],[4.6,0]],"id":42767337},{"atb":[[5.1,0]],"id":51567147}],"con":true,"img":false}]}
{"op":"mcm","clk":"11541047811","pt":1719501550194,"mc":[{"id":"1.230180124","rc":[{"atb":[[2,0],[2.22,0.84],[2.1,55.74]],"id":65992794},{"atl":[[18.5,1.62]],"id":67245400},{"atl":[[18.5,0],[18,1]],"id":42767337},{"atb":[[5,7.53]],"id":51567147}],"con":true,"img":false}]}
{"op":"mcm","clk":"11541047835","pt":1719501550386,"mc":[{"id":"1.230180124","rc":[{"atb":[[2.08,0]],"id":65992794}],"con":true,"img":false}]}
{"op":"mcm","clk":"11541047849","pt":1719501550491,"mc":[{"id":"1.230180124","rc":[{"atb":[[2.2,23.32]],"id":65992794}],"con":true,"img":false}]}
{"op":"mcm","clk":"11541047857","pt":1719501550591,"mc":[{"id":"1.230180124","rc":[{"atb":[[4.4,1.7]],"id":42767337}],"con":true,"img":false}]}
{"op":"mcm","clk":"11541047865","pt":1719501550695,"mc":[{"id":"1.230180124","rc":[{"atl":[[7.8,3.25]],"id":51567147}],"con":true,"img":false}]}
{"op":"mcm","clk":"11541047870","pt":1719501550796,"mc":[{"id":"1.230180124","rc":[{"atb":[[5.2,0]],"id":51567147}],"con":true,"img":false}]}
{"op":"mcm","clk":"11541047878","pt":1719501550904,"mc":[{"id":"1.230180124","rc":[{"atl":[[9.2,0]],"id":51567147}],"con":true,"img":false}]}
{"op":"mcm","clk":"11541047890","pt":1719501550965,"mc":[{"id":"1.230180124","rc":[{"atl":[[7.8,6.87]],"id":51567147}],"con":true,"img":false}]}
{"op":"mcm","clk":"11541047905","pt":1719501551165,"mc":[{"id":"1.230180124","rc":[{"atb":[[5.1,0.84]],"id":51567147},{"atl":[[7.6,0.84]],"id":51567147}],"con":true,"img":false}]}
{"op":"mcm","clk":"11541047947","pt":1719501551783,"mc":[{"id":"1.230180124","rc":[{"atl":[[20,0]],"id":67245400},{"atl":[[8,4.14],[7.8,3.62]],"id":51567147}],"con":true,"img":false}]}
{"op":"mcm","clk":"11541047955","pt":1719501551898,"mc":[{"id":"1.230180124","rc":[{"atl":[[18,1]],"id":67245400},{"atl":[[7.6,1.84]],"id":51567147}],"con":true,"img":false}]}
{"op":"mcm","clk":"11541047976","pt":1719501552208,"mc":[{"id":"1.230180124","rc":[{"atl":[[8,3.3]],"id":51567147}],"con":true,"img":false}]}
{"op":"mcm","clk":"11541048039","pt":1719501552876,"mc":[{"id":"1.230180124","rc":[{"atb":[[1.83,14.28]],"id":65992794}],"con":true,"img":false}]}
{"op":"mcm","clk":"11541048050","pt":1719501552984,"mc":[{"id":"1.230180124","rc":[{"atl":[[7.6,5.31]],"id":51567147}],"con":true,"img":false}]}
{"op":"mcm","clk":"11541048156","pt":1719501554276,"mc":[{"id":"1.230180124","rc":[{"spn":2.18,"spf":1.0,"id":65992794},{"atl":[[19,1.84]],"id":67245400},{"atl":[[16.5,0.84]],"id":42767337},{"atl":[[8.2,3.22]],"id":51567147},{"spn":6.35,"spf":"NaN","id":51567147},{"spn":8.45,"spf":"NaN","id":70902709}],"con":true,"img":false}]}
{"op":"mcm","clk":"11541048209","pt":1719501554997,"mc":[{"id":"1.230180124","rc":[{"atl":[[8,0],[8.2,0],[7.6,1.84],[7.8,0]],"id":51567147}],"con":true,"img":false}]}
{"op":"mcm","clk":"11541048219","pt":1719501555089,"mc":[{"id":"1.230180124","rc":[{"atl":[[9.2,2.72]],"id":51567147}],"con":true,"img":false}]}
{"op":"mcm","clk":"11541048264","pt":1719501555561,"mc":[{"id":"1.230180124","rc":[{"atl":[[7.6,0.84]],"id":51567147}],"con":true,"img":false}]}
{"op":"mcm","clk":"11541048270","pt":1719501555667,"mc":[{"id":"1.230180124","rc":[{"atb":[[2.12,47.13]],"id":65992794},{"atl":[[18.5,1]],"id":42767337},{"atl":[[9,1]],"id":51567147}],"con":true,"img":false}]}
{"op":"mcm","clk":"11541048282","pt":1719501555768,"mc":[{"id":"1.230180124","rc":[{"atb":[[2.1,3.11]],"id":65992794},{"atl":[[18,2],[18.5,0.62],[19,0.84]],"id":67245400},{"atl":[[18,0]],"id":42767337}],"con":true,"img":false}]}
{"op":"mcm","clk":"11541048306","pt":1719501556178,"mc":[{"id":"1.230180124","rc":[{"atl":[[17.5,0.84],[19,0]],"id":67245400},{"atl":[[7.6,0]],"id":51567147}],"con":true,"img":false}]}
{"op":"mcm","clk":"11541048327","pt":1719501556480,"mc":[{"id":"1.230180124","rc":[{"atl":[[18,1]],"id":67245400}],"con":true,"img":false}]}
{"op":"mcm","clk":"11541048337","pt":1719501556588,"mc":[{"id":"1.230180124","rc":[{"atl":[[20,1]],"id":67245400}],"con":true,"img":false}]}
{"op":"mcm","clk":"11541048622","pt":1719501559286,"mc":[{"id":"1.230180124","rc":[{"atl":[[2.48,3.62]],"id":65992794}],"con":true,"img":false}]}
{"op":"mcm","clk":"11541048675","pt":1719501559900,"mc":[{"id":"1.230180124","rc":[{"atb":[[2.16,4.47]],"id":65992794}],"con":true,"img":false}]}
{"op":"mcm","clk":"11541048683","pt":1719501560002,"mc":[{"id":"1.230180124","rc":[{"atl":[[1000,0.46]],"id":67245400},{"atl":[[1000,0.31]],"id":42767337},{"atl":[[1000,0.57]],"id":51567147}],"con":true,"img":false}]}
{"op":"mcm","clk":"11541048733","pt":1719501560102,"mc":[{"id":"1.230180124","rc":[{"atl":[[1000,0.18]],"id":67245400},{"atl":[[1000,0]],"id":42767337},{"atl":[[1000,0]],"id":51567147}],"con":true,"img":false}]}
{"op":"mcm","clk":"11541048744","pt":1719501560203,"mc":[{"id":"1.230180124","rc":[{"atl":[[18,1.28]],"id":67245400},{"atl":[[16.5,1.15]],"id":42767337},{"atl":[[9,1.57]],"id":51567147}],"con":true,"img":false}]}
{"op":"mcm","clk":"11541048823","pt":1719501561201,"mc":[{"id":"1.230180124","rc":[{"atl":[[9,4.73]],"id":51567147}],"con":true,"img":false}]}
{"op":"mcm","clk":"11541048862","pt":1719501561665,"mc":[{"id":"1.230180124","rc":[{"atl":[[8.8,0.84]],"id":51567147}],"con":true,"img":false}]}
{"op":"mcm","clk":"11541048931","pt":1719501562704,"mc":[{"id":"1.230180124","rc":[{"atb":[[5.2,7.73]],"id":42767337}],"con":true,"img":false}]}
{"op":"mcm","clk":"11541048990","pt":1719501563476,"mc":[{"id":"1.230180124","rc":[{"atl":[[18.5,0],[18,1]],"id":42767337}],"con":true,"img":false}]}
{"op":"mcm","clk":"11541049726","pt":1719501572118,"mc":[{"id":"1.230180124","rc":[{"atl":[[14,1],[18,0.28]],"id":67245400},{"atl":[[18,0],[18.5,1]],"id":42767337}],"con":true,"img":false}]}
{"op":"mcm","clk":"11541049817","pt":1719501573120,"mc":[{"id":"1.230180124","rc":[{"atb":[[5.1,0]],"id":67245400}],"con":true,"img":false}]}
{"op":"mcm","clk":"11541049836","pt":1719501573319,"mc":[{"id":"1.230180124","rc":[{"atb":[[5,7.06]],"id":67245400},{"atl":[[20,2.17]],"id":67245400}],"con":true,"img":false}]}
{"op":"mcm","clk":"11541049892","pt":1719501574050,"mc":[{"id":"1.230180124","rc":[{"atl":[[2.48,0]],"id":65992794}],"con":true,"img":false}]}
{"op":"mcm","clk":"11541049934","pt":1719501574438,"mc":[{"id":"1.230180124","rc":[{"atl":[[18,0]],"id":67245400},{"atl":[[16.5,0.84]],"id":42767337},{"atl":[[9,4.16]],"id":51567147}],"con":true,"img":false}]}
{"op":"mcm","clk":"11541050330","pt":1719501579043,"mc":[{"id":"1.230180124","rc":[{"atb":[[2.16,3.02]],"id":65992794}],"con":true,"img":false}]}
{"op":"mcm","clk":"11541050371","pt":1719501579550,"mc":[{"id":"1.230180124","rc":[{"atl":[[15,1]],"id":67245400}],"con":true,"img":false}]}
{"op":"mcm","clk":"11541050379","pt":1719501579656,"mc":[{"id":"1.230180124","rc":[{"atl":[[14,0]],"id":67245400}],"con":true,"img":false}]}
{"op":"mcm","clk":"11541050410","pt":1719501579926,"mc":[{"id":"1.230180124","rc":[{"atb":[[2.16,4.48]],"id":65992794}],"con":true,"img":false}]}
{"op":"mcm","clk":"11541050437","pt":1719501580240,"mc":[{"id":"1.230180124","rc":[{"atl":[[1000,0.52]],"id":67245400},{"atl":[[1000,0.31]],"id":42767337},{"atl":[[1000,0.57]],"id":51567147}],"con":true,"img":false}]}
{"op":"mcm","clk":"11541050450","pt":1719501580347,"mc":[{"id":"1.230180124","rc":[{"atl":[[2.5,21.83]],"id":65992794}],"con":true,"img":false}]}
{"op":"mcm","clk":"11541050460","pt":1719501580442,"mc":[{"id":"1.230180124","rc":[{"atl":[[1000,0.18]],"id":67245400},{"atl":[[1000,0]],"id":42767337},{"atl":[[1000,0]],"id":51567147}],"con":true,"img":false}]}
{"op":"mcm","clk":"11541050470","pt":1719501580556,"mc":[{"id":"1.230180124","rc":[{"atl":[[15,1.34]],"id":67245400},{"atl":[[16.5,1.15]],"id":42767337},{"atl":[[9,4.73]],"id":51567147}],"con":true,"img":false}]}
{"op":"mcm","clk":"11541051167","pt":1719501589667,"mc":[{"id":"1.230180124","rc":[{"atb":[[3.05,5.78]],"id":67245400}],"con":true,"img":false}]}
{"op":"mcm","clk":"11541051184","pt":1719501589826,"mc":[{"id":"1.230180124","rc":[{"atb":[[2.6,7.41]],"id":51567147}],"con":true,"img":false}]}
{"op":"mcm","clk":"11541051234","pt":1719501590651,"mc":[{"id":"1.230180124","rc":[{"atb":[[6.4,2.02]],"id":70902709}],"con":true,"img":false}]}
{"op":"mcm","clk":"11541051256","pt":1719501590857,"mc":[{"id":"1.230180124","rc":[{"atb":[[5.8,0]],"id":70902709}],"con":true,"img":false}]}
{"op":"mcm","clk":"11541051266","pt":1719501590959,"mc":[{"id":"1.230180124","rc":[{"atb":[[6.4,6.21]],"id":70902709}],"con":true,"img":false}]}
{"op":"mcm","clk":"11541051285","pt":1719501591267,"mc":[{"id":"1.230180124","rc":[{"atb":[[6.6,3.85]],"id":70902709}],"con":true,"img":false}]}
{"op":"mcm","clk":"11541051296","pt":1719501591371,"mc":[{"id":"1.230180124","rc":[{"atb":[[6,5.17],[6.6,4.69]],"id":70902709}],"con":true,"img":false}]}
{"op":"mcm","clk":"11541051456","pt":1719501593264,"mc":[{"id":"1.230180124","rc":[{"atb":[[5.9,1.43]],"id":70902709}],"con":true,"img":false}]}
{"op":"mcm","clk":"11541051466","pt":1719501593373,"mc":[{"id":"1.230180124","rc":[{"atb":[[6.6,8.73]],"id":70902709}],"con":true,"img":false}]}
{"op":"mcm","clk":"11541051492","pt":1719501593581,"mc":[{"id":"1.230180124","rc":[{"atb":[[6.4,5.21]],"id":70902709}],"con":true,"img":false}]}
{"op":"mcm","clk":"11541051601","pt":1719501594774,"mc":[{"id":"1.230180124","rc":[{"atl":[[15,1]],"id":67245400},{"atl":[[16.5,0.84]],"id":42767337},{"atl":[[9,4.16]],"id":51567147}],"con":true,"img":false}]}
{"op":"mcm","clk":"11541051612","pt":1719501594876,"mc":[{"id":"1.230180124","rc":[{"atb":[[6.8,1]],"id":70902709}],"con":true,"img":false}]}
{"op":"mcm","clk":"11541051625","pt":1719501594979,"mc":[{"id":"1.230180124","rc":[{"atb":[[6.6,4.88]],"id":70902709}],"con":true,"img":false}]}
{"op":"mcm","clk":"11541051841","pt":1719501597475,"mc":[{"id":"1.230180124","rc":[{"atl":[[2.4,2]],"id":65992794}],"con":true,"img":false}]}
{"op":"mcm","clk":"11541052079","pt":1719501600278,"mc":[{"id":"1.230180124","rc":[{"atl":[[1000,0.52]],"id":67245400},{"atl":[[1000,0.31]],"id":42767337},{"atl":[[1000,0.57]],"id":51567147}],"con":true,"img":false}]}
{"op":"mcm","clk":"11541052090","pt":1719501600397,"mc":[{"id":"1.230180124","rc":[{"atl":[[1000,0.18]],"id":67245400},{"atl":[[1000,0]],"id":42767337}],"con":true,"img":false}]}
{"op":"mcm","clk":"11541052100","pt":1719501600498,"mc":[{"id":"1.230180124","rc":[{"atl":[[15,1.34]],"id":67245400},{"atl":[[16.5,1.15]],"id":42767337},{"atl":[[1000,0]],"id":51567147}],"con":true,"img":false}]}
{"op":"mcm","clk":"11541052109","pt":1719501600601,"mc":[{"id":"1.230180124","rc":[{"atl":[[9,4.73]],"id":51567147}],"con":true,"img":false}]}
{"op":"mcm","clk":"11541052250","pt":1719501602179,"mc":[{"id":"1.230180124","rc":[{"atl":[[17,0]],"id":42767337}],"con":true,"img":false}]}
{"op":"mcm","clk":"11541052289","pt":1719501602650,"mc":[{"id":"1.230180124","rc":[{"atl":[[16.5,0.31]],"id":42767337}],"con":true,"img":false}]}
{"op":"mcm","clk":"11541052342","pt":1719501603377,"mc":[{"id":"1.230180124","rc":[{"atl":[[17.5,0]],"id":42767337}],"con":true,"img":false}]}
{"op":"mcm","clk":"11541052372","pt":1719501603687,"mc":[{"id":"1.230180124","rc":[{"atl":[[18,0.84]],"id":42767337}],"con":true,"img":false}]}
{"op":"mcm","clk":"11541052633","pt":1719501606670,"mc":[{"id":"1.230180124","rc":[{"atb":[[1.82,0]],"id":65992794},{"atb":[[1.91,0]],"id":70902709}],"con":true,"img":false}]}
{"op":"mcm","clk":"11541052965","pt":1719501610785,"mc":[{"id":"1.230180124","rc":[{"atb":[[4.4,0]],"id":42767337}],"con":true,"img":false}]}
{"op":"mcm","clk":"11541053002","pt":1719501611297,"mc":[{"id":"1.230180124","rc":[{"atb":[[4.4,1.7]],"id":42767337}],"con":true,"img":false}]}
{"op":"mcm","clk":"11541053110","pt":1719501612598,"mc":[{"id":"1.230180124","rc":[{"atb":[[4.4,12.92]],"id":42767337}],"con":true,"img":false}]}
{"op":"mcm","clk":"11541053281","pt":1719501614687,"mc":[{"id":"1.230180124","rc":[{"spn":2.18,"spf":1.0,"id":65992794},{"atl":[[15,1]],"id":67245400},{"atl":[[16.5,0]],"id":42767337},{"atl":[[5.7,2]],"id":51567147},{"spn":5.4,"spf":"NaN","id":51567147},{"spn":8.65,"spf":"NaN","id":70902709}],"con":true,"img":false}]}
{"op":"mcm","clk":"11541053294","pt":1719501614784,"mc":[{"id":"1.230180124","rc":[{"atl":[[9,4.16]],"id":51567147}],"con":true,"img":false}]}
{"op":"mcm","clk":"11541053306","pt":1719501614892,"mc":[{"id":"1.230180124","rc":[{"atl":[[5.7,0]],"id":51567147},{"trd":[[5.7,4]],"ltp":5.7,"tv":4.0,"id":51567147}],"con":true,"img":false}]}
{"op":"mcm","clk":"11541053508","pt":1719501616805,"mc":[{"id":"1.230180124","rc":[{"atl":[[5.9,2]],"id":51567147}],"con":true,"img":false}]}
{"op":"mcm","clk":"11541053543","pt":1719501617174,"mc":[{"id":"1.230180124","rc":[{"atl":[[5.8,0.84],[8.8,0]],"id":51567147}],"con":true,"img":false}]}
{"op":"mcm","clk":"11541053549","pt":1719501617277,"mc":[{"id":"1.230180124","rc":[{"atb":[[5.2,6.35]],"id":67245400}],"con":true,"img":false}]}
{"op":"mcm","clk":"11541053588","pt":1719501617792,"mc":[{"id":"1.230180124","rc":[{"atb":[[1.84,15.12]],"id":65992794},{"atl":[[2.5,18.29]],"id":65992794}],"con":true,"img":false}]}
{"op":"mcm","clk":"11541053613","pt":1719501618105,"mc":[{"id":"1.230180124","rc":[{"atl":[[9,3.16]],"id":51567147}],"con":true,"img":false}]}
{"op":"mcm","clk":"11541053626","pt":1719501618207,"mc":[{"id":"1.230180124","rc":[{"atl":[[5.8,1.84]],"id":51567147}],"con":true,"img":false}]}
{"op":"mcm","clk":"11541053634","pt":1719501618310,"mc":[{"id":"1.230180124","rc":[{"atl":[[14.5,0.84]],"id":67245400},{"atl":[[130,0]],"id":42767337}],"con":true,"img":false}]}
{"op":"mcm","clk":"11541053673","pt":1719501618677,"mc":[{"id":"1.230180124","rc":[{"atl":[[17.5,0]],"id":67245400},{"atl":[[16,0],[1000,0.84]],"id":42767337}],"con":true,"img":false}]}
{"op":"mcm","clk":"11541053695","pt":1719501618989,"mc":[{"id":"1.230180124","rc":[{"atb":[[5.2,0]],"id":67245400},{"atl":[[1000,0.52]],"id":42767337}],"con":true,"img":false}]}
{"op":"mcm","clk":"11541053702","pt":1719501619088,"mc":[{"id":"1.230180124","rc":[{"atb":[[5.1,5.97]],"id":67245400},{"atl":[[18.5,0]],"id":67245400}],"con":true,"img":false}]}
{"op":"mcm","clk":"11541053719","pt":1719501619294,"mc":[{"id":"1.230180124","rc":[{"atl":[[1000,1.03]],"id":67245400}],"con":true,"img":false}]}
{"op":"mcm","clk":"11541053741","pt":1719501619603,"mc":[{"id":"1.230180124","rc":[{"atl":[[1000,0]],"id":42767337}],"con":true,"img":false}]}
{"op":"mcm","clk":"11541053751","pt":1719501619707,"mc":[{"id":"1.230180124","rc":[{"atl":[[17.5,0.52]],"id":42767337}],"con":true,"img":false}]}
{"op":"mcm","clk":"11541053772","pt":1719501619866,"mc":[{"id":"1.230180124","rc":[{"atl":[[1000,0.81]],"id":67245400}],"con":true,"img":false}]}
{"op":"mcm","clk":"11541053797","pt":1719501620177,"mc":[{"id":"1.230180124","rc":[{"atl":[[1000,0.18]],"id":67245400}],"con":true,"img":false}]}
{"op":"mcm","clk":"11541053804","pt":1719501620277,"mc":[{"id":"1.230180124","rc":[{"atl":[[19.5,0.62]],"id":67245400}],"con":true,"img":false}]}
{"op":"mcm","clk":"11541053994","pt":1719501621787,"mc":[{"id":"1.230180124","rc":[{"atl":[[2.56,3.43]],"id":65992794}],"con":true,"img":false}]}
{"op":"mcm","clk":"11541054027","pt":1719501622099,"mc":[{"id":"1.230180124","rc":[{"atl":[[5.9,0]],"id":51567147}],"con":true,"img":false}]}
{"op":"mcm","clk":"11541054104","pt":1719501622875,"mc":[{"id":"1.230180124","rc":[{"atl":[[5.8,0.84]],"id":51567147}],"con":true,"img":false}]}
{"op":"mcm","clk":"11541054115","pt":1719501622983,"mc":[{"id":"1.230180124","rc":[{"atl":[[8.8,1]],"id":51567147}],"con":true,"img":false}]}
{"op":"mcm","clk":"11541054143","pt":1719501623289,"mc":[{"id":"1.230180124","rc":[{"atb":[[1.06,3.4],[1.07,1.7],[1.05,1.7]],"id":67245400},{"atl":[[1000,6.99]],"id":67245400},{"atl":[[5.8,0]],"id":51567147}],"con":true,"img":false}]}
{"op":"mcm","clk":"11541054159","pt":1719501623497,"mc":[{"id":"1.230180124","rc":[{"atb":[[1.06,0.08],[1.07,0.03],[1.05,0.04]],"id":67245400},{"atl":[[1000,0.24]],"id":67245400}],"con":true,"img":false}]}
{"op":"mcm","clk":"11541054179","pt":1719501623808,"mc":[{"id":"1.230180124","rc":[{"atb":[[1.06,0],[1.07,0],[1.05,0]],"id":67245400},{"atl":[[1000,0.18]],"id":67245400}],"con":true,"img":false}]}
{"op":"mcm","clk":"11541054189","pt":1719501623911,"mc":[{"id":"1.230180124","rc":[{"atb":[[5.1,0],[5,6.71],[5.5,0.16]],"id":67245400},{"atl":[[14.5,0.9]],"id":67245400}],"con":true,"img":false}]}
{"op":"mcm","clk":"11541054209","pt":1719501624118,"mc":[{"id":"1.230180124","rc":[{"atl":[[5.7,2]],"id":51567147}],"con":true,"img":false}]}
{"op":"mcm","clk":"11541054231","pt":1719501624275,"mc":[{"id":"1.230180124","rc":[{"atl":[[2.56,0]],"id":65992794}],"con":true,"img":false}]}
{"op":"mcm","clk":"11541054256","pt":1719501624584,"mc":[{"id":"1.230180124","rc":[{"atl":[[8.8,0]],"id":51567147}],"con":true,"img":false}]}
{"op":"mcm","clk":"11541054266","pt":1719501624687,"mc":[{"id":"1.230180124","rc":[{"atl":[[5.6,1]],"id":51567147}],"con":true,"img":false}]}
{"op":"mcm","clk":"11541054309","pt":1719501625219,"mc":[{"id":"1.230180124","rc":[{"atb":[[1.81,0]],"id":65992794}],"con":true,"img":false}]}
{"op":"mcm","clk":"11541055424","pt":1719501637703,"mc":[{"id":"1.230180124","rc":[{"atb":[[5.4,2.41]],"id":67245400}],"con":true,"img":false}]}
{"op":"mcm","clk":"11541055604","pt":1719501639714,"mc":[{"id":"1.230180124","rc":[{"atl":[[2.56,3.43]],"id":65992794}],"con":true,"img":false}]}
{"op":"mcm","clk":"11541055643","pt":1719501640335,"mc":[{"id":"1.230180124","rc":[{"atb":[[1.83,0]],"id":65992794},{"atb":[[3.05,0]],"id":67245400},{"atb":[[2.6,0]],"id":51567147}],"con":true,"img":false}]}
{"op":"mcm","clk":"11541055893","pt":1719501643504,"mc":[{"id":"1.230180124","rc":[{"atb":[[3.4,3.87]],"id":51567147}],"con":true,"img":false}]}
{"op":"mcm","clk":"11541055917","pt":1719501643911,"mc":[{"id":"1.230180124","rc":[{"atb":[[2.98,5.13]],"id":51567147}],"con":true,"img":false}]}
{"op":"mcm","clk":"11541056115","pt":1719501646438,"mc":[{"id":"1.230180124","rc":[{"atb":[[1.77,15.4]],"id":65992794},{"atb":[[2.78,6.66]],"id":70902709}],"con":true,"img":false}]}
{"op":"mcm","clk":"11541056134","pt":1719501646647,"mc":[{"id":"1.230180124","rc":[{"atb":[[2.98,9.92]],"id":51567147}],"con":true,"img":false}]}
{"op":"mcm","clk":"11541056152","pt":1719501646806,"mc":[{"id":"1.230180124","rc":[{"atb":[[2.98,5.99]],"id":67245400}],"con":true,"img":false}]}
{"op":"mcm","clk":"11541056171","pt":1719501647009,"mc":[{"id":"1.230180124","rc":[{"atb":[[3.4,7.49]],"id":51567147}],"con":true,"img":false}]}
{"op":"mcm","clk":"11541056203","pt":1719501647429,"mc":[{"id":"1.230180124","rc":[{"atb":[[3.1,5.64]],"id":42767337}],"con":true,"img":false}]}
{"op":"mcm","clk":"11541056292","pt":1719501648407,"mc":[{"id":"1.230180124","rc":[{"atl":[[2.38,4.84]],"id":65992794}],"con":true,"img":false}]}
{"op":"mcm","clk":"11541056331","pt":1719501648918,"mc":[{"id":"1.230180124","rc":[{"atl":[[17.5,1.37]],"id":42767337},{"atl":[[10.5,1.69]],"id":70902709}],"con":true,"img":false}]}
{"op":"mcm","clk":"11541056338","pt":1719501649025,"mc":[{"id":"1.230180124","rc":[{"atb":[[5.6,1.51]],"id":67245400}],"con":true,"img":false}]}
{"op":"mcm","clk":"11541056347","pt":1719501649131,"mc":[{"id":"1.230180124","rc":[{"atb":[[5.4,0.84]],"id":67245400}],"con":true,"img":false}]}
{"op":"mcm","clk":"11541056356","pt":1719501649249,"mc":[{"id":"1.230180124","rc":[{"atl":[[11.5,0.73]],"id":70902709}],"con":true,"img":false}]}
{"op":"mcm","clk":"11541056363","pt":1719501649353,"mc":[{"id":"1.230180124","rc":[{"atb":[[5.2,6.26]],"id":67245400},{"atl":[[10.5,4.57]],"id":70902709}],"con":true,"img":false}]}
{"op":"mcm","clk":"11541056372","pt":1719501649442,"mc":[{"id":"1.230180124","rc":[{"atb":[[5.5,1.68]],"id":67245400}],"con":true,"img":false}]}
{"op":"mcm","clk":"11541056390","pt":1719501649990,"mc":[{"id":"1.230180124","rc":[{"atb":[[5.6,0]],"id":67245400}],"con":true,"img":false}]}
{"op":"mcm","clk":"11541056401","pt":1719501650323,"mc":[{"id":"1.230180124","rc":[{"atl":[[2.56,0]],"id":65992794}],"con":true,"img":false}]}
{"op":"mcm","clk":"11541056470","pt":1719501650774,"mc":[{"id":"1.230180124","rc":[{"atl":[[2.4,1]],"id":65992794},{"atl":[[11,2.79]],"id":70902709}],"con":true,"img":false}]}
{"op":"mcm","clk":"11541056480","pt":1719501650839,"mc":[{"id":"1.230180124","rc":[{"atl":[[2.36,1]],"id":65992794},{"atl":[[10,1]],"id":70902709}],"con":true,"img":false}]}
{"op":"mcm","clk":"11541056557","pt":1719501651625,"mc":[{"id":"1.230180124","rc":[{"atl":[[10.5,3.72]],"id":70902709}],"con":true,"img":false}]}
{"op":"mcm","clk":"11541056591","pt":1719501652037,"mc":[{"id":"1.230180124","rc":[{"atb":[[2.16,3.02]],"id":65992794}],"con":true,"img":false}]}
{"op":"mcm","clk":"11541056613","pt":1719501652249,"mc":[{"id":"1.230180124","rc":[{"atl":[[2.38,9.84]],"id":65992794}],"con":true,"img":false}]}
{"op":"mcm","clk":"11541056630","pt":1719501652415,"mc":[{"id":"1.230180124","rc":[{"atl":[[2.4,0]],"id":65992794}],"con":true,"img":false}]}
{"op":"mcm","clk":"11541056648","pt":1719501652619,"mc":[{"id":"1.230180124","rc":[{"atl":[[2.36,2]],"id":65992794}],"con":true,"img":false}]}
{"op":"mcm","clk":"11541056687","pt":1719501653239,"mc":[{"id":"1.230180124","rc":[{"atl":[[2.34,0.84]],"id":65992794}],"con":true,"img":false}]}
{"op":"mcm","clk":"11541056800","pt":1719501654634,"mc":[{"id":"1.230180124","rc":[{"atb":[[5.5,4.22]],"id":67245400}],"con":true,"img":false}]}
{"op":"mcm","clk":"11541056845","pt":1719501655252,"mc":[{"id":"1.230180124","rc":[{"atb":[[5.6,0.84]],"id":67245400}],"con":true,"img":false}]}
{"op":"mcm","clk":"11541056969","pt":1719501656758,"mc":[{"id":"1.230180124","rc":[{"atl":[[2.6,3.34]],"id":65992794}],"con":true,"img":false}]}
{"op":"mcm","clk":"11541057256","pt":1719501660447,"mc":[{"id":"1.230180124","rc":[{"atb":[[1.8,25]],"id":65992794},{"atb":[[4,25]],"id":67245400},{"atb":[[3.8,25]],"id":42767337},{"atb":[[3.65,25]],"id":51567147},{"atb":[[4.8,25]],"id":70902709}],"con":true,"img":false}]}
{"op":"mcm","clk":"11541057266","pt":1719501660551,"mc":[{"id":"1.230180124","rc":[{"atb":[[2.32,10.27]],"id":65992794},{"atl":[[2.6,0]],"id":65992794},{"atb":[[5,9.1]],"id":67245400},{"atb":[[5,3.39]],"id":42767337},{"atb":[[5,9.92]],"id":51567147},{"atb":[[5,3.39]],"id":70902709}],"con":true,"img":false}]}
{"op":"mcm","clk":"11541057273","pt":1719501660655,"mc":[{"id":"1.230180124","rc":[{"atl":[[2.34,3.47]],"id":65992794},{"atb":[[5.6,3.47]],"id":67245400},{"atl":[[14.5,2.21]],"id":67245400},{"atb":[[5.2,11.8]],"id":42767337},{"atl":[[17.5,1.89]],"id":42767337},{"atb":[[5.1,3.47]],"id":51567147},{"atb":[[6.8,3.63]],"id":70902709},{"atl":[[10,3.63]],"id":70902709}],"con":true,"img":false}]}
{"op":"mcm","clk":"11541057280","pt":1719501660766,"mc":[{"id":"1.230180124","rc":[{"atb":[[2.32,7.35]],"id":65992794},{"trd":[[2.32,5.84]],"ltp":2.32,"tv":5.84,"id":65992794}],"con":true,"img":false}]}
{"op":"mcm","clk":"11541057292","pt":1719501660862,"mc":[{"id":"1.230180124","rc":[{"atb":[[2.32,0]],"id":65992794},{"trd":[[2.32,20.54]],"ltp":2.32,"tv":20.54,"id":65992794}],"con":true,"img":false}]}
{"op":"mcm","clk":"11541057311","pt":1719501661075,"mc":[{"id":"1.230180124","rc":[{"atl":[[2.34,0.84]],"id":65992794},{"atb":[[5.6,0.84]],"id":67245400},{"atb":[[5.1,0.84]],"id":51567147},{"atb":[[6.8,1]],"id":70902709},{"atl":[[10,1]],"id":70902709}],"con":true,"img":false}]}
{"op":"mcm","clk":"11541057319","pt":1719501661129,"mc":[{"id":"1.230180124","rc":[{"atl":[[2.36,3.63]],"id":65992794},{"atb":[[5.5,6.85]],"id":67245400},{"atl":[[20,1.17],[14.5,0.9]],"id":67245400},{"atl":[[17.5,1.37],[25,0]],"id":42767337},{"atb":[[5,12.55]],"id":51567147},{"atb":[[6.6,7.51]],"id":70902709},{"atl":[[10.5,6.35]],"id":70902709}],"con":true,"img":false}]}
{"op":"mcm","clk":"11541057327","pt":1719501661232,"mc":[{"id":"1.230180124","rc":[{"atl":[[2.32,1],[2.38,9]],"id":65992794},{"atb":[[5.4,0]],"id":67245400},{"atl":[[14,1.84]],"id":67245400},{"atl":[[17,1.84]],"id":42767337},{"atb":[[7,0.84]],"id":70902709},{"atl":[[9.8,0.84]],"id":70902709}],"con":true,"img":false}]}
{"op":"mcm","clk":"11541057340","pt":1719501661439,"mc":[{"id":"1.230180124","rc":[{"atl":[[14,3.96]],"id":67245400},{"atb":[[5.3,1.79]],"id":42767337},{"atb":[[6.8,2.72]],"id":70902709}],"con":true,"img":false}]}
{"op":"mcm","clk":"11541057354","pt":1719501661646,"mc":[{"id":"1.230180124","rc":[{"atb":[[5.2,7.73]],"id":42767337}],"con":true,"img":false}]}
{"op":"mcm","clk":"11541057363","pt":1719501661752,"mc":[{"id":"1.230180124","rc":[{"atl":[[2.36,1]],"id":65992794},{"atb":[[5.3,5.86],[5.4,0.84],[5.2,2.84]],"id":42767337},{"atl":[[18,0]],"id":42767337},{"atb":[[6.6,4.88]],"id":70902709}],"con":true,"img":false}]}
{"op":"mcm","clk":"11541057369","pt":1719501661865,"mc":[{"id":"1.230180124","rc":[{"atl":[[2.38,11.63]],"id":65992794},{"atb":[[6.8,5.35]],"id":70902709}],"con":true,"img":false}]}
{"op":"mcm","clk":"11541057382","pt":1719501661963,"mc":[{"id":"1.230180124","rc":[{"atb":[[2.12,22.96],[2.14,17.38],[2.16,0]],"id":65992794},{"atl":[[15,0],[16.5,1]],"id":67245400}],"con":true,"img":false}]}
{"op":"mcm","clk":"11541057394","pt":1719501662060,"mc":[{"id":"1.230180124","rc":[{"atl":[[14.5,0.05]],"id":67245400},{"atl":[[17.5,0.52]],"id":42767337},{"atb":[[6.8,6.2]],"id":70902709}],"con":true,"img":false}]}
{"op":"mcm","clk":"11541057411","pt":1719501662270,"mc":[{"id":"1.230180124","rc":[{"atl":[[2.32,0]],"id":65992794},{"atl":[[14,2.96]],"id":67245400},{"atl":[[17,0.84]],"id":42767337},{"atb":[[6,0]],"id":70902709}],"con":true,"img":false}]}
{"op":"mcm","clk":"11541057422","pt":1719501662372,"mc":[{"id":"1.230180124","rc":[{"atl":[[2.36,2]],"id":65992794},{"atl":[[20,2.17]],"id":67245400},{"atl":[[25,1]],"id":42767337}],"con":true,"img":false}]}
{"op":"mcm","clk":"11541057444","pt":1719501662543,"mc":[{"id":"1.230180124","rc":[{"atl":[[2.38,9]],"id":65992794},{"atl":[[13.5,0.84]],"id":67245400},{"atb":[[5.3,1.79]],"id":42767337},{"atl":[[16.5,0.84]],"id":42767337}],"con":true,"img":false}]}
{"op":"mcm","clk":"11541057457","pt":1719501662641,"mc":[{"id":"1.230180124","rc":[{"atl":[[2.36,4.63]],"id":65992794},{"atb":[[5.2,6.91]],"id":42767337},{"atb":[[7,5.18]],"id":70902709}],"con":true,"img":false}]}
{"op":"mcm","clk":"11541057466","pt":1719501662743,"mc":[{"id":"1.230180124","rc":[{"atl":[[17,0]],"id":42767337}],"con":true,"img":false}]}
{"op":"mcm","clk":"11541057489","pt":1719501662953,"mc":[{"id":"1.230180124","rc":[{"atb":[[6.8,3.57]],"id":70902709}],"con":true,"img":false}]}
{"op":"mcm","clk":"11541057498","pt":1719501663062,"mc":[{"id":"1.230180124","rc":[{"atb":[[5.2,0]],"id":67245400},{"atb":[[7,7.81]],"id":70902709}],"con":true,"img":false}]}
{"op":"mcm","clk":"11541057506","pt":1719501663161,"mc":[{"id":"1.230180124","rc":[{"atl":[[20,1.17]],"id":67245400},{"atb":[[7.2,3.53]],"id":70902709}],"con":true,"img":false}]}
{"op":"mcm","clk":"11541057515","pt":1719501663264,"mc":[{"id":"1.230180124","rc":[{"atb":[[5.1,6.79]],"id":67245400},{"atl":[[13.5,1.84]],"id":67245400},{"atb":[[5.4,3.38]],"id":42767337},{"atb":[[6.8,0.26],[6.6,4.04]],"id":70902709}],"con":true,"img":false}]}
{"op":"mcm","clk":"11541057528","pt":1719501663368,"mc":[{"id":"1.230180124","rc":[{"atb":[[7.4,1.72]],"id":70902709}],"con":true,"img":false}]}
{"op":"mcm","clk":"11541057537","pt":1719501663473,"mc":[{"id":"1.230180124","rc":[{"atl":[[2.36,2]],"id":65992794},{"atb":[[5.2,2.84]],"id":42767337},{"atb":[[7.2,4.53]],"id":70902709}],"con":true,"img":false}]}
{"op":"mcm","clk":"11541057549","pt":1719501663537,"mc":[{"id":"1.230180124","rc":[{"atl":[[2.38,11.63]],"id":65992794},{"atb":[[5.4,7.45]],"id":42767337}],"con":true,"img":false}]}
{"op":"mcm","clk":"11541057574","pt":1719501663740,"mc":[{"id":"1.230180124","rc":[{"atb":[[5.2,2]],"id":42767337},{"atb":[[7,6.97]],"id":70902709}],"con":true,"img":false}]}
{"op":"mcm","clk":"11541057585","pt":1719501663863,"mc":[{"id":"1.230180124","rc":[{"atl":[[130,0]],"id":67245400},{"atb":[[6.2,0]],"id":70902709}],"con":true,"img":false}]}
{"op":"mcm","clk":"11541057594","pt":1719501663949,"mc":[{"id":"1.230180124","rc":[{"atl":[[13.5,3.74]],"id":67245400},{"atb":[[5.3,0]],"id":42767337},{"atb":[[7.2,4.69],[7,4.34]],"id":70902709}],"con":true,"img":false}]}
{"op":"mcm","clk":"11541057607","pt":1719501664050,"mc":[{"id":"1.230180124","rc":[{"atb":[[5.5,1.79]],"id":42767337},{"atb":[[7.4,4.35]],"id":70902709}],"con":true,"img":false}]}
{"op":"mcm","clk":"11541057628","pt":1719501664261,"mc":[{"id":"1.230180124","rc":[{"atl":[[2.38,9]],"id":65992794},{"atb":[[5.4,3.38]],"id":42767337},{"atb":[[7.2,3.69]],"id":70902709}],"con":true,"img":false}]}
{"op":"mcm","clk":"11541057635","pt":1719501664362,"mc":[{"id":"1.230180124","rc":[{"atl":[[2.36,4.63]],"id":65992794},{"atb":[[5.5,5.86]],"id":42767337}],"con":true,"img":false}]}
{"op":"mcm","clk":"11541057643","pt":1719501664463,"mc":[{"id":"1.230180124","rc":[{"atb":[[7.6,1]],"id":70902709}],"con":true,"img":false}]}
{"op":"mcm","clk":"11541057652","pt":1719501664570,"mc":[{"id":"1.230180124","rc":[{"atb":[[5.5,10.96]],"id":42767337},{"atl":[[25,2.14]],"id":42767337},{"atb":[[7.4,2.63]],"id":70902709}],"con":true,"img":false}]}
