{"op":"mcm","clk":"11536832986","pt":1719431775521,"mc":[{"id":"1.230180132","marketDefinition":{"bspMarket":true,"turnInPlayEnabled":false,"persistenceEnabled":false,"marketBaseRate":5.0,"eventId":"33376437","eventTypeId":"4339","numberOfWinners":1,"bettingType":"ODDS","marketType":"WIN","marketTime":"2024-06-27T16:39:00.000Z","suspendTime":"2024-06-27T16:39:00.000Z","bspReconciled":false,"complete":true,"inPlay":false,"crossMatching":false,"runnersVoidable":false,"numberOfActiveRunners":6,"betDelay":0,"status":"OPEN","runners":[{"status":"ACTIVE","sortPriority":1,"id":66314580,"name":"1. Shesbeenlit"},{"status":"ACTIVE","sortPriority":2,"id":67487134,"name":"2. Salacres Elbuena"},{"status":"ACTIVE","sortPriority":3,"id":67130716,"name":"3. Donishall Dolly"},{"status":"ACTIVE","sortPriority":4,"id":70086038,"name":"4. Greencroft Gerry"},{"status":"ACTIVE","sortPriority":5,"id":53826530,"name":"5. Meena"},{"status":"ACTIVE","sortPriority":6,"id":64618726,"name":"6. Ballyboss Rose"}],"regulators":["MR_INT"],"venue":"Towcester","countryCode":"GB","discountAllowed":false,"timezone":"Europe/London","openDate":"2024-06-27T13:33:00.000Z","version":5994767129,"name":"A7 500m","eventName":"Towcester 27th Jun"},"rc":[],"con":true,"img":false}]}
{"op":"mcm","clk":"11536833146","pt":1719431777529,"mc":[{"id":"1.230180132","marketDefinition":{"bspMarket":true,"turnInPlayEnabled":false,"persistenceEnabled":false,"marketBaseRate":5.0,"eventId":"33376437","eventTypeId":"4339","numberOfWinners":1,"bettingType":"ODDS","marketType":"WIN","marketTime":"2024-06-27T16:39:00.000Z","suspendTime":"2024-06-27T16:39:00.000Z","bspReconciled":false,"complete":true,"inPlay":false,"crossMatching":false,"runnersVoidable":false,"numberOfActiveRunners":6,"betDelay":0,"status":"OPEN","runners":[{"status":"ACTIVE","sortPriority":1,"id":66314580,"name":"1. Shesbeenlit"},{"status":"ACTIVE","sortPriority":2,"id":67487134,"name":"2. Salacres Elbuena"},{"status":"ACTIVE","sortPriority":3,"id":67130716,"name":"3. Donishall Dolly"},{"status":"ACTIVE","sortPriority":4,"id":70086038,"name":"4. Greencroft Gerry"},{"status":"ACTIVE","sortPriority":5,"id":53826530,"name":"5. Meena"},{"status":"ACTIVE","sortPriority":6,"id":64618726,"name":"6. Ballyboss Rose"}],"regulators":["MR_INT"],"venue":"Towcester","countryCode":"GB","discountAllowed":true,"timezone":"Europe/London","openDate":"2024-06-27T13:33:00.000Z","version":5994767129,"name":"A7 500m","eventName":"Towcester 27th Jun"},"rc":[],"con":true,"img":false}]}
{"op":"mcm","clk":"11537083942","pt":1719435434291,"mc":[{"id":"1.230180132","rc":[{"atb":[[1.03,17.28]],"id":67487134},{"atl":[[1000,0.84]],"id":67487134},{"spn":500.51,"spf":"NaN","id":67487134},{"atb":[[1.01,51.84]],"id":66314580},{"atl":[[990,0.84]],"id":66314580},{"spn":495.5,"spf":"NaN","id":66314580},{"atb":[[1.02,25.92]],"id":53826530},{"atl":[[990,0.84]],"id":53826530},{"spn":495.51,"spf":"NaN","id":53826530},{"atb":[[1.02,25.92]],"id":70086038},{"atl":[[990,0.84]],"id":70086038},{"spn":495.51,"spf":"NaN","id":70086038},{"atb":[[1.03,17.28]],"id":64618726},{"atl":[[990,0.84]],"id":64618726},{"spn":495.51,"spf":"NaN","id":64618726},{"atb":[[1.02,25.92]],"id":67130716},{"atl":[[990,0.84]],"id":67130716},{"spn":495.51,"spf":"NaN","id":67130716}],"con":true,"img":false}]}
{"op":"mcm","clk":"11537235640","pt":1719437882802,"mc":[{"id":"1.230180132","marketDefinition":{"bspMarket":true,"turnInPlayEnabled":false,"persistenceEnabled":false,"marketBaseRate":5.0,"eventId":"33376437","eventTypeId":"4339","numberOfWinners":1,"bettingType":"ODDS","marketType":"WIN","marketTime":"2024-06-27T16:39:00.000Z","suspendTime":"2024-06-27T16:39:00.000Z","bspReconciled":false,"complete":true,"inPlay":false,"crossMatching":false,"runnersVoidable":false,"numberOfActiveRunners":6,"betDelay":0,"status":"OPEN","runners":[{"status":"ACTIVE","sortPriority":1,"id":66314580,"name":"1. Shesbeenlit"},{"status":"ACTIVE","sortPriority":2,"id":67487134,"name":"2. Salacres Elbuena"},{"status":"ACTIVE","sortPriority":3,"id":67130716,"name":"3. Donishall Dolly"},{"status":"ACTIVE","sortPriority":4,"id":70086038,"name":"4. Greencroft Gerry"},{"status":"ACTIVE","sortPriority":5,"id":53826530,"name":"5. Meena"},{"status":"ACTIVE","sortPriority":6,"id":64618726,"name":"6. Ballyboss Rose"}],"regulators":["MR_INT"],"venue":"Towcester","countryCode":"GB","discountAllowed":true,"timezone":"Europe/London","openDate":"2024-06-27T13:33:00.000Z","version":5994767129,"name":"A7 500m","eventName":"Towcester 27th Jun"},"rc":[{"atb":[[1.03,17.28]],"id":67487134},{"atl":[[1000,0.84]],"id":67487134},{"spn":500.51,"spf":"NaN","id":67487134},{"atb":[[1.01,51.85]],"id":66314580},{"atl":[[990,0.84]],"id":66314580},{"spn":495.5,"spf":"NaN","id":66314580},{"atb":[[1.02,25.92]],"id":53826530},{"atl":[[990,0.84]],"id":53826530},{"spn":495.51,"spf":"NaN","id":53826530},{"atb":[[1.02,25.92]],"id":70086038},{"atl":[[990,0.84]],"id":70086038},{"spn":495.51,"spf":"NaN","id":70086038},{"atb":[[1.03,17.28]],"id":64618726},{"atl":[[990,0.84]],"id":64618726},{"spn":495.51,"spf":"NaN","id":64618726},{"atb":[[1.02,25.92]],"id":67130716},{"atl":[[990,0.84]],"id":67130716},{"spn":495.51,"spf":"NaN","id":67130716}],"con":true,"img":true}]}
{"op":"mcm","clk":"11537302448","pt":1719439037420,"mc":[{"id":"1.230180132","rc":[{"atb":[[1.03,17.28]],"id":67487134},{"atl":[[1000,0.23]],"id":67487134},{"atb":[[1.01,51.85]],"id":66314580},{"atl":[[990,0.23]],"id":66314580},{"atb":[[1.02,25.92]],"id":53826530},{"atl":[[990,0.23]],"id":53826530},{"atb":[[1.02,25.92]],"id":70086038},{"atl":[[990,0.23]],"id":70086038},{"atb":[[1.03,17.28]],"id":64618726},{"atl":[[990,0.23]],"id":64618726},{"atb":[[1.02,25.92]],"id":67130716},{"atl":[[990,0.23]],"id":67130716}],"con":true,"img":false}]}
{"op":"mcm","clk":"11537576928","pt":1719443282847,"mc":[{"id":"1.230180132","marketDefinition":{"bspMarket":true,"turnInPlayEnabled":false,"persistenceEnabled":false,"marketBaseRate":5.0,"eventId":"33376437","eventTypeId":"4339","numberOfWinners":1,"bettingType":"ODDS","marketType":"WIN","marketTime":"2024-06-27T16:39:00.000Z","suspendTime":"2024-06-27T16:39:00.000Z","bspReconciled":false,"complete":true,"inPlay":false,"crossMatching":false,"runnersVoidable":false,"numberOfActiveRunners":6,"betDelay":0,"status":"OPEN","runners":[{"status":"ACTIVE","sortPriority":1,"id":66314580,"name":"1. Shesbeenlit"},{"status":"ACTIVE","sortPriority":2,"id":67487134,"name":"2. Salacres Elbuena"},{"status":"ACTIVE","sortPriority":3,"id":67130716,"name":"3. Donishall Dolly"},{"status":"ACTIVE","sortPriority":4,"id":70086038,"name":"4. Greencroft Gerry"},{"status":"ACTIVE","sortPriority":5,"id":53826530,"name":"5. Meena"},{"status":"ACTIVE","sortPriority":6,"id":64618726,"name":"6. Ballyboss Rose"}],"regulators":["MR_INT"],"venue":"Towcester","countryCode":"GB","discountAllowed":true,"timezone":"Europe/London","openDate":"2024-06-27T13:33:00.000Z","version":5994767129,"name":"A7 500m","eventName":"Towcester 27th Jun"},"rc":[{"atb":[[1.03,17.28]],"id":67487134},{"atl":[[1000,0.23]],"id":67487134},{"spn":500.51,"spf":"NaN","id":67487134},{"atb":[[1.01,51.85]],"id":66314580},{"atl":[[990,0.23]],"id":66314580},{"spn":495.5,"spf":"NaN","id":66314580},{"atb":[[1.02,25.92]],"id":53826530},{"atl":[[990,0.23]],"id":53826530},{"spn":495.51,"spf":"NaN","id":53826530},{"atb":[[1.02,25.92]],"id":70086038},{"atl":[[990,0.23]],"id":70086038},{"spn":495.51,"spf":"NaN","id":70086038},{"atb":[[1.03,17.28]],"id":64618726},{"atl":[[990,0.23]],"id":64618726},{"spn":495.51,"spf":"NaN","id":64618726},{"atb":[[1.02,25.92]],"id":67130716},{"atl":[[990,0.23]],"id":67130716},{"spn":495.51,"spf":"NaN","id":67130716}],"con":true,"img":true}]}
{"op":"mcm","clk":"11537958616","pt":1719448682893,"mc":[{"id":"1.230180132","marketDefinition":{"bspMarket":true,"turnInPlayEnabled":false,"persistenceEnabled":false,"marketBaseRate":5.0,"eventId":"33376437","eventTypeId":"4339","numberOfWinners":1,"bettingType":"ODDS","marketType":"WIN","marketTime":"2024-06-27T16:39:00.000Z","suspendTime":"2024-06-27T16:39:00.000Z","bspReconciled":false,"complete":true,"inPlay":false,"crossMatching":false,"runnersVoidable":false,"numberOfActiveRunners":6,"betDelay":0,"status":"OPEN","runners":[{"status":"ACTIVE","sortPriority":1,"id":66314580,"name":"1. Shesbeenlit"},{"status":"ACTIVE","sortPriority":2,"id":67487134,"name":"2. Salacres Elbuena"},{"status":"ACTIVE","sortPriority":3,"id":67130716,"name":"3. Donishall Dolly"},{"status":"ACTIVE","sortPriority":4,"id":70086038,"name":"4. Greencroft Gerry"},{"status":"ACTIVE","sortPriority":5,"id":53826530,"name":"5. Meena"},{"status":"ACTIVE","sortPriority":6,"id":64618726,"name":"6. Ballyboss Rose"}],"regulators":["MR_INT"],"venue":"Towcester","countryCode":"GB","discountAllowed":true,"timezone":"Europe/London","openDate":"2024-06-27T13:33:00.000Z","version":5994767129,"name":"A7 500m","eventName":"Towcester 27th Jun"},"rc":[{"atb":[[1.03,17.28]],"id":67487134},{"atl":[[1000,0.23]],"id":67487134},{"spn":500.51,"spf":"NaN","id":67487134},{"atb":[[1.01,51.85]],"id":66314580},{"atl":[[990,0.23]],"id":66314580},{"spn":495.5,"spf":"NaN","id":66314580},{"atb":[[1.02,25.92]],"id":53826530},{"atl":[[990,0.23]],"id":53826530},{"spn":495.51,"spf":"NaN","id":53826530},{"atb":[[1.02,25.92]],"id":70086038},{"atl":[[990,0.23]],"id":70086038},{"spn":495.51,"spf":"NaN","id":70086038},{"atb":[[1.03,17.28]],"id":64618726},{"atl":[[990,0.23]],"id":64618726},{"spn":495.51,"spf":"NaN","id":64618726},{"atb":[[1.02,25.92]],"id":67130716},{"atl":[[990,0.23]],"id":67130716},{"spn":495.51,"spf":"NaN","id":67130716}],"con":true,"img":true}]}
{"op":"mcm","clk":"11538174192","pt":1719454082864,"mc":[{"id":"1.230180132","marketDefinition":{"bspMarket":true,"turnInPlayEnabled":false,"persistenceEnabled":false,"marketBaseRate":5.0,"eventId":"33376437","eventTypeId":"4339","numberOfWinners":1,"bettingType":"ODDS","marketType":"WIN","marketTime":"2024-06-27T16:39:00.000Z","suspendTime":"2024-06-27T16:39:00.000Z","bspReconciled":false,"complete":true,"inPlay":false,"crossMatching":false,"runnersVoidable":false,"numberOfActiveRunners":6,"betDelay":0,"status":"OPEN","runners":[{"status":"ACTIVE","sortPriority":1,"id":66314580,"name":"1. Shesbeenlit"},{"status":"ACTIVE","sortPriority":2,"id":67487134,"name":"2. Salacres Elbuena"},{"status":"ACTIVE","sortPriority":3,"id":67130716,"name":"3. Donishall Dolly"},{"status":"ACTIVE","sortPriority":4,"id":70086038,"name":"4. Greencroft Gerry"},{"status":"ACTIVE","sortPriority":5,"id":53826530,"name":"5. Meena"},{"status":"ACTIVE","sortPriority":6,"id":64618726,"name":"6. Ballyboss Rose"}],"regulators":["MR_INT"],"venue":"Towcester","countryCode":"GB","discountAllowed":true,"timezone":"Europe/London","openDate":"2024-06-27T13:33:00.000Z","version":5994767129,"name":"A7 500m","eventName":"Towcester 27th Jun"},"rc":[{"atb":[[1.03,17.29]],"id":67487134},{"atl":[[1000,0.23]],"id":67487134},{"spn":500.51,"spf":"NaN","id":67487134},{"atb":[[1.01,51.86]],"id":66314580},{"atl":[[990,0.23]],"id":66314580},{"spn":495.5,"spf":"NaN","id":66314580},{"atb":[[1.02,25.93]],"id":53826530},{"atl":[[990,0.23]],"id":53826530},{"spn":495.51,"spf":"NaN","id":53826530},{"atb":[[1.02,25.93]],"id":70086038},{"atl":[[990,0.23]],"id":70086038},{"spn":495.51,"spf":"NaN","id":70086038},{"atb":[[1.03,17.29]],"id":64618726},{"atl":[[990,0.23]],"id":64618726},{"spn":495.51,"spf":"NaN","id":64618726},{"atb":[[1.02,25.93]],"id":67130716},{"atl":[[990,0.23]],"id":67130716},{"spn":495.51,"spf":"NaN","id":67130716}],"con":true,"img":true}]}
{"op":"mcm","clk":"11538371905","pt":1719459482939,"mc":[{"id":"1.230180132","marketDefinition":{"bspMarket":true,"turnInPlayEnabled":false,"persistenceEnabled":false,"marketBaseRate":5.0,"eventId":"33376437","eventTypeId":"4339","numberOfWinners":1,"bettingType":"ODDS","marketType":"WIN","marketTime":"2024-06-27T16:39:00.000Z","suspendTime":"2024-06-27T16:39:00.000Z","bspReconciled":false,"complete":true,"inPlay":false,"crossMatching":false,"runnersVoidable":false,"numberOfActiveRunners":6,"betDelay":0,"status":"OPEN","runners":[{"status":"ACTIVE","sortPriority":1,"id":66314580,"name":"1. Shesbeenlit"},{"status":"ACTIVE","sortPriority":2,"id":67487134,"name":"2. Salacres Elbuena"},{"status":"ACTIVE","sortPriority":3,"id":67130716,"name":"3. Donishall Dolly"},{"status":"ACTIVE","sortPriority":4,"id":70086038,"name":"4. Greencroft Gerry"},{"status":"ACTIVE","sortPriority":5,"id":53826530,"name":"5. Meena"},{"status":"ACTIVE","sortPriority":6,"id":64618726,"name":"6. Ballyboss Rose"}],"regulators":["MR_INT"],"venue":"Towcester","countryCode":"GB","discountAllowed":true,"timezone":"Europe/London","openDate":"2024-06-27T13:33:00.000Z","version":5994767129,"name":"A7 500m","eventName":"Towcester 27th Jun"},"rc":[{"atb":[[1.03,17.29]],"id":67487134},{"atl":[[1000,0.23]],"id":67487134},{"spn":500.51,"spf":"NaN","id":67487134},{"atb":[[1.01,51.87]],"id":66314580},{"atl":[[990,0.23]],"id":66314580},{"spn":495.5,"spf":"NaN","id":66314580},{"atb":[[1.02,25.93]],"id":53826530},{"atl":[[990,0.23]],"id":53826530},{"spn":495.51,"spf":"NaN","id":53826530},{"atb":[[1.02,25.93]],"id":70086038},{"atl":[[990,0.23]],"id":70086038},{"spn":495.51,"spf":"NaN","id":70086038},{"atb":[[1.03,17.29]],"id":64618726},{"atl":[[990,0.23]],"id":64618726},{"spn":495.51,"spf":"NaN","id":64618726},{"atb":[[1.02,25.93]],"id":67130716},{"atl":[[990,0.23]],"id":67130716},{"spn":495.51,"spf":"NaN","id":67130716}],"con":true,"img":true}]}
{"op":"mcm","clk":"11538598982","pt":1719464882864,"mc":[{"id":"1.230180132","marketDefinition":{"bspMarket":true,"turnInPlayEnabled":false,"persistenceEnabled":false,"marketBaseRate":5.0,"eventId":"33376437","eventTypeId":"4339","numberOfWinners":1,"bettingType":"ODDS","marketType":"WIN","marketTime":"2024-06-27T16:39:00.000Z","suspendTime":"2024-06-27T16:39:00.000Z","bspReconciled":false,"complete":true,"inPlay":false,"crossMatching":false,"runnersVoidable":false,"numberOfActiveRunners":6,"betDelay":0,"status":"OPEN","runners":[{"status":"ACTIVE","sortPriority":1,"id":66314580,"name":"1. Shesbeenlit"},{"status":"ACTIVE","sortPriority":2,"id":67487134,"name":"2. Salacres Elbuena"},{"status":"ACTIVE","sortPriority":3,"id":67130716,"name":"3. Donishall Dolly"},{"status":"ACTIVE","sortPriority":4,"id":70086038,"name":"4. Greencroft Gerry"},{"status":"ACTIVE","sortPriority":5,"id":53826530,"name":"5. Meena"},{"status":"ACTIVE","sortPriority":6,"id":64618726,"name":"6. Ballyboss Rose"}],"regulators":["MR_INT"],"venue":"Towcester","countryCode":"GB","discountAllowed":true,"timezone":"Europe/London","openDate":"2024-06-27T13:33:00.000Z","version":5994767129,"name":"A7 500m","eventName":"Towcester 27th Jun"},"rc":[{"atb":[[1.03,17.29]],"id":67487134},{"atl":[[1000,0.23]],"id":67487134},{"spn":500.51,"spf":"NaN","id":67487134},{"atb":[[1.01,51.86]],"id":66314580},{"atl":[[990,0.23]],"id":66314580},{"spn":495.5,"spf":"NaN","id":66314580},{"atb":[[1.02,25.93]],"id":53826530},{"atl":[[990,0.23]],"id":53826530},{"spn":495.51,"spf":"NaN","id":53826530},{"atb":[[1.02,25.93]],"id":70086038},{"atl":[[990,0.23]],"id":70086038},{"spn":495.51,"spf":"NaN","id":70086038},{"atb":[[1.03,17.29]],"id":64618726},{"atl":[[990,0.23]],"id":64618726},{"spn":495.51,"spf":"NaN","id":64618726},{"atb":[[1.02,25.93]],"id":67130716},{"atl":[[990,0.23]],"id":67130716},{"spn":495.51,"spf":"NaN","id":67130716}],"con":true,"img":true}]}
{"op":"mcm","clk":"11538748674","pt":1719468205880,"mc":[{"id":"1.230180132","rc":[{"atb":[[1.03,17.29],[2.06,10.56]],"id":67487134},{"spn":501.03,"spf":"NaN","id":67487134},{"atb":[[1.01,51.86],[2.08,11.55]],"id":66314580},{"spn":496.04,"spf":"NaN","id":66314580},{"atb":[[2.02,12.08],[1.02,25.93]],"id":53826530},{"spn":496.01,"spf":"NaN","id":53826530},{"atb":[[1.02,25.93],[2.1,12.55]],"id":70086038},{"spn":496.05,"spf":"NaN","id":70086038},{"atb":[[1.03,17.29],[2.1,9.86]],"id":64618726},{"spn":496.05,"spf":"NaN","id":64618726},{"atb":[[1.02,25.93],[2.1,12.55]],"id":67130716},{"spn":496.05,"spf":"NaN","id":67130716}],"con":true,"img":false}]}
{"op":"mcm","clk":"11538750276","pt":1719468240840,"mc":[{"id":"1.230180132","rc":[{"atb":[[2.12,3.16]],"id":67130716}],"con":true,"img":false}]}
{"op":"mcm","clk":"11538750322","pt":1719468241660,"mc":[{"id":"1.230180132","rc":[{"atb":[[2.08,3.16]],"id":67487134}],"con":true,"img":false}]}
{"op":"mcm","clk":"11538750331","pt":1719468241824,"mc":[{"id":"1.230180132","rc":[{"atb":[[2.1,3.16]],"id":66314580}],"con":true,"img":false}]}
{"op":"mcm","clk":"11538750353","pt":1719468242236,"mc":[{"id":"1.230180132","rc":[{"atb":[[2.04,3.16]],"id":53826530}],"con":true,"img":false}]}
{"op":"mcm","clk":"11538750372","pt":1719468242644,"mc":[{"id":"1.230180132","rc":[{"atb":[[2.12,3.16]],"id":64618726}],"con":true,"img":false}]}
{"op":"mcm","clk":"11538752127","pt":1719468276502,"mc":[{"id":"1.230180132","rc":[{"spn":501.04,"spf":"NaN","id":67487134},{"spn":496.05,"spf":"NaN","id":66314580},{"spn":496.02,"spf":"NaN","id":53826530},{"spn":496.06,"spf":"NaN","id":64618726},{"atb":[[2.12,6.55]],"id":67130716},{"spn":496.06,"spf":"NaN","id":67130716}],"con":true,"img":false}]}
{"op":"mcm","clk":"11538752134","pt":1719468276603,"mc":[{"id":"1.230180132","rc":[{"atb":[[2.08,6.55]],"id":67487134}],"con":true,"img":false}]}
{"op":"mcm","clk":"11538752136","pt":1719468276806,"mc":[{"id":"1.230180132","rc":[{"atb":[[2.12,6.55]],"id":64618726}],"con":true,"img":false}]}
{"op":"mcm","clk":"11538752139","pt":1719468276908,"mc":[{"id":"1.230180132","rc":[{"atb":[[2.04,6.55]],"id":53826530}],"con":true,"img":false}]}
{"op":"mcm","clk":"11538752151","pt":1719468277113,"mc":[{"id":"1.230180132","rc":[{"atb":[[2.1,6.55]],"id":66314580}],"con":true,"img":false}]}
{"op":"mcm","clk":"11538752385","pt":1719468281747,"mc":[{"id":"1.230180132","marketDefinition":{"bspMarket":true,"turnInPlayEnabled":false,"persistenceEnabled":false,"marketBaseRate":5.0,"eventId":"33376437","eventTypeId":"4339","numberOfWinners":1,"bettingType":"ODDS","marketType":"WIN","marketTime":"2024-06-27T16:39:00.000Z","suspendTime":"2024-06-27T16:39:00.000Z","bspReconciled":false,"complete":true,"inPlay":false,"crossMatching":true,"runnersVoidable":false,"numberOfActiveRunners":6,"betDelay":0,"status":"OPEN","runners":[{"status":"ACTIVE","sortPriority":1,"id":66314580,"name":"1. Shesbeenlit"},{"status":"ACTIVE","sortPriority":2,"id":67487134,"name":"2. Salacres Elbuena"},{"status":"ACTIVE","sortPriority":3,"id":67130716,"name":"3. Donishall Dolly"},{"status":"ACTIVE","sortPriority":4,"id":70086038,"name":"4. Greencroft Gerry"},{"status":"ACTIVE","sortPriority":5,"id":53826530,"name":"5. Meena"},{"status":"ACTIVE","sortPriority":6,"id":64618726,"name":"6. Ballyboss Rose"}],"regulators":["MR_INT"],"venue":"Towcester","countryCode":"GB","discountAllowed":true,"timezone":"Europe/London","openDate":"2024-06-27T13:33:00.000Z","version":5994767129,"name":"A7 500m","eventName":"Towcester 27th Jun"},"rc":[],"con":true,"img":false}]}
{"op":"mcm","clk":"11538938939","pt":1719472080883,"mc":[{"id":"1.230180132","rc":[{"atb":[[2.06,10.55],[1.03,17.27],[2.08,6.54]],"id":67487134},{"atl":[[1000,0.23]],"id":67487134},{"atb":[[1.01,51.82],[2.1,6.54],[2.08,11.54]],"id":66314580},{"atl":[[990,0.23]],"id":66314580},{"atb":[[2.02,12.07],[2.04,6.54],[1.02,25.91]],"id":53826530},{"atl":[[990,0.23]],"id":53826530},{"atb":[[1.02,25.91],[2.1,12.55]],"id":70086038},{"atl":[[990,0.23]],"id":70086038},{"atb":[[1.03,17.27],[2.12,6.54],[2.1,9.86]],"id":64618726},{"atl":[[24,0.6],[990,0.23]],"id":64618726},{"spn":13.06,"spf":"NaN","id":64618726},{"atb":[[1.02,25.91],[2.12,6.54],[2.1,12.55]],"id":67130716},{"atl":[[990,0.23]],"id":67130716}],"con":true,"img":false}]}
{"op":"mcm","clk":"11538940814","pt":1719472114400,"mc":[{"id":"1.230180132","rc":[{"atb":[[2.06,0]],"id":67487134},{"atb":[[2.08,0]],"id":66314580},{"atb":[[2.02,0]],"id":53826530},{"atb":[[2.1,0]],"id":64618726},{"atb":[[2.1,0]],"id":67130716}],"con":true,"img":false}]}
{"op":"mcm","clk":"11538940817","pt":1719472114502,"mc":[{"id":"1.230180132","rc":[{"atb":[[2.1,10.55]],"id":67487134},{"atb":[[2.12,11.54]],"id":66314580},{"atb":[[2.06,12.07]],"id":53826530},{"atb":[[2.14,9.86]],"id":64618726},{"atb":[[2.14,12.55]],"id":67130716}],"con":true,"img":false}]}
{"op":"mcm","clk":"11538942234","pt":1719472137350,"mc":[{"id":"1.230180132","rc":[{"atb":[[2.12,3.38]],"id":67130716}],"con":true,"img":false}]}
{"op":"mcm","clk":"11538942260","pt":1719472137656,"mc":[{"id":"1.230180132","rc":[{"atb":[[2.04,3.38]],"id":53826530}],"con":true,"img":false}]}
{"op":"mcm","clk":"11538942286","pt":1719472138167,"mc":[{"id":"1.230180132","rc":[{"atb":[[2.08,3.38]],"id":67487134}],"con":true,"img":false}]}
{"op":"mcm","clk":"11538942360","pt":1719472139347,"mc":[{"id":"1.230180132","rc":[{"atb":[[2.1,3.38]],"id":66314580}],"con":true,"img":false}]}
{"op":"mcm","clk":"11538942402","pt":1719472140167,"mc":[{"id":"1.230180132","rc":[{"atb":[[2.08,3.16]],"id":53826530}],"con":true,"img":false}]}
{"op":"mcm","clk":"11538942488","pt":1719472141245,"mc":[{"id":"1.230180132","rc":[{"spn":501.05,"spf":"NaN","id":67487134},{"spn":496.06,"spf":"NaN","id":66314580},{"spn":496.04,"spf":"NaN","id":53826530},{"atb":[[2.12,3.38]],"id":64618726},{"spn":13.07,"spf":"NaN","id":64618726},{"spn":496.07,"spf":"NaN","id":67130716}],"con":true,"img":false}]}
{"op":"mcm","clk":"11538942497","pt":1719472141348,"mc":[{"id":"1.230180132","rc":[{"atb":[[2.12,3.16]],"id":67487134}],"con":true,"img":false}]}
{"op":"mcm","clk":"11538942505","pt":1719472141450,"mc":[{"id":"1.230180132","rc":[{"atb":[[2.16,3.16]],"id":67130716}],"con":true,"img":false}]}
{"op":"mcm","clk":"11538942567","pt":1719472142273,"mc":[{"id":"1.230180132","rc":[{"atb":[[2.14,3.16]],"id":66314580}],"con":true,"img":false}]}
{"op":"mcm","clk":"11538942605","pt":1719472142838,"mc":[{"id":"1.230180132","rc":[{"atb":[[2.16,3.16]],"id":64618726}],"con":true,"img":false}]}
{"op":"mcm","clk":"11538943063","pt":1719472149487,"mc":[{"id":"1.230180132","rc":[{"atb":[[2.1,0]],"id":66314580}],"con":true,"img":false}]}
{"op":"mcm","clk":"11538943069","pt":1719472149583,"mc":[{"id":"1.230180132","rc":[{"atb":[[2.12,0]],"id":67130716}],"con":true,"img":false}]}
{"op":"mcm","clk":"11538943082","pt":1719472149893,"mc":[{"id":"1.230180132","rc":[{"atb":[[2.12,0]],"id":64618726}],"con":true,"img":false}]}
{"op":"mcm","clk":"11538943124","pt":1719472150457,"mc":[{"id":"1.230180132","rc":[{"atb":[[2.08,0]],"id":67487134}],"con":true,"img":false}]}
{"op":"mcm","clk":"11538943218","pt":1719472151993,"mc":[{"id":"1.230180132","rc":[{"atb":[[2.04,0]],"id":53826530}],"con":true,"img":false}]}
{"op":"mcm","clk":"11538943726","pt":1719472160913,"mc":[{"id":"1.230180132","rc":[{"atb":[[2.16,6.54]],"id":67130716}],"con":true,"img":false}]}
{"op":"mcm","clk":"11538943736","pt":1719472161013,"mc":[{"id":"1.230180132","rc":[{"atb":[[2.14,6.54]],"id":66314580}],"con":true,"img":false}]}
{"op":"mcm","clk":"11538943756","pt":1719472161272,"mc":[{"id":"1.230180132","rc":[{"atb":[[2.16,6.54]],"id":64618726}],"con":true,"img":false}]}
{"op":"mcm","clk":"11538943796","pt":1719472161988,"mc":[{"id":"1.230180132","rc":[{"atb":[[2.12,6.54]],"id":67487134}],"con":true,"img":false}]}
{"op":"mcm","clk":"11538943915","pt":1719472163788,"mc":[{"id":"1.230180132","rc":[{"atb":[[2.08,6.54]],"id":53826530}],"con":true,"img":false}]}
{"op":"mcm","clk":"11539031685","pt":1719473965967,"mc":[{"id":"1.230180132","rc":[{"atl":[[150,4]],"id":67487134},{"spn":76.06,"spf":"NaN","id":67487134},{"atl":[[150,4]],"id":66314580},{"spn":76.07,"spf":"NaN","id":66314580},{"atl":[[150,4]],"id":53826530},{"spn":76.04,"spf":"NaN","id":53826530},{"atl":[[150,4]],"id":70086038},{"spn":76.05,"spf":"NaN","id":70086038},{"atl":[[150,4]],"id":64618726},{"spn":13.08,"spf":"NaN","id":64618726},{"atl":[[150,4]],"id":67130716},{"spn":76.08,"spf":"NaN","id":67130716}],"con":true,"img":false}]}
{"op":"mcm","clk":"11539126214","pt":1719475682886,"mc":[{"id":"1.230180132","marketDefinition":{"bspMarket":true,"turnInPlayEnabled":false,"persistenceEnabled":false,"marketBaseRate":5.0,"eventId":"33376437","eventTypeId":"4339","numberOfWinners":1,"bettingType":"ODDS","marketType":"WIN","marketTime":"2024-06-27T16:39:00.000Z","suspendTime":"2024-06-27T16:39:00.000Z","bspReconciled":false,"complete":true,"inPlay":false,"crossMatching":true,"runnersVoidable":false,"numberOfActiveRunners":6,"betDelay":0,"status":"OPEN","runners":[{"status":"ACTIVE","sortPriority":1,"id":66314580,"name":"1. Shesbeenlit"},{"status":"ACTIVE","sortPriority":2,"id":67487134,"name":"2. Salacres Elbuena"},{"status":"ACTIVE","sortPriority":3,"id":67130716,"name":"3. Donishall Dolly"},{"status":"ACTIVE","sortPriority":4,"id":70086038,"name":"4. Greencroft Gerry"},{"status":"ACTIVE","sortPriority":5,"id":53826530,"name":"5. Meena"},{"status":"ACTIVE","sortPriority":6,"id":64618726,"name":"6. Ballyboss Rose"}],"regulators":["MR_INT"],"venue":"Towcester","countryCode":"GB","discountAllowed":true,"timezone":"Europe/London","openDate":"2024-06-27T13:33:00.000Z","version":5994767129,"name":"A7 500m","eventName":"Towcester 27th Jun"},"rc":[{"atb":[[1.03,17.28],[2.12,6.55],[2.1,10.55]],"id":67487134},{"atl":[[150,4],[1000,0.23]],"id":67487134},{"spn":76.06,"spf":"NaN","id":67487134},{"atb":[[1.01,51.84],[2.12,11.54],[2.14,6.55]],"id":66314580},{"atl":[[150,4],[990,0.23]],"id":66314580},{"spn":76.07,"spf":"NaN","id":66314580},{"atb":[[2.06,12.08],[1.02,25.92],[2.08,6.55]],"id":53826530},{"atl":[[150,4],[990,0.23]],"id":53826530},{"spn":76.04,"spf":"NaN","id":53826530},{"atb":[[1.02,25.92],[2.1,12.55]],"id":70086038},{"atl":[[150,4],[990,0.23]],"id":70086038},{"spn":76.05,"spf":"NaN","id":70086038},{"atb":[[1.03,17.28],[2.16,6.55],[2.14,9.86]],"id":64618726},{"atl":[[150,4],[24,0.6],[990,0.23]],"id":64618726},{"spn":13.08,"spf":"NaN","id":64618726},{"atb":[[1.02,25.92],[2.16,6.55],[2.14,12.55]],"id":67130716},{"atl":[[150,4],[990,0.23]],"id":67130716},{"spn":76.08,"spf":"NaN","id":67130716}],"con":true,"img":true}]}
{"op":"mcm","clk":"11539128170","pt":1719475714459,"mc":[{"id":"1.230180132","rc":[{"atb":[[1.03,17.28],[2.12,6.55],[2.1,0]],"id":67487134},{"atl":[[1000,0.23]],"id":67487134},{"atb":[[1.01,51.84],[2.12,0],[2.14,6.55]],"id":66314580},{"atl":[[990,0.23]],"id":66314580},{"atb":[[2.06,0],[1.02,25.92],[2.08,6.55]],"id":53826530},{"atl":[[990,0.23]],"id":53826530},{"atb":[[1.02,25.92],[2.1,12.55]],"id":70086038},{"atl":[[990,0.23]],"id":70086038},{"atb":[[1.03,17.28],[2.16,6.55],[2.14,0]],"id":64618726},{"atl":[[990,0.23]],"id":64618726},{"atb":[[1.02,25.92],[2.16,6.55],[2.14,0]],"id":67130716},{"atl":[[990,0.23]],"id":67130716}],"con":true,"img":false}]}
{"op":"mcm","clk":"11539128178","pt":1719475714561,"mc":[{"id":"1.230180132","rc":[{"atb":[[2.14,10.55]],"id":67487134},{"atb":[[2.16,11.54]],"id":66314580},{"atb":[[2.1,12.08]],"id":53826530},{"atb":[[2.18,9.86]],"id":64618726},{"atb":[[2.18,12.55]],"id":67130716}],"con":true,"img":false}]}
{"op":"mcm","clk":"11539134252","pt":1719475809957,"mc":[{"id":"1.230180132","rc":[{"atb":[[2.12,3.38]],"id":67487134},{"spn":76.07,"spf":"NaN","id":67487134},{"atb":[[2.14,3.38]],"id":66314580},{"spn":76.08,"spf":"NaN","id":66314580},{"atb":[[2.08,3.38]],"id":53826530},{"spn":76.05,"spf":"NaN","id":53826530},{"atb":[[2.16,3.38]],"id":64618726},{"spn":13.09,"spf":"NaN","id":64618726},{"atb":[[2.16,3.38]],"id":67130716},{"spn":76.09,"spf":"NaN","id":67130716}],"con":true,"img":false}]}
{"op":"mcm","clk":"11539146845","pt":1719476015861,"mc":[{"id":"1.230180132","rc":[{"atb":[[2.12,0]],"id":67487134},{"atb":[[2.14,0]],"id":66314580},{"atb":[[2.08,0]],"id":53826530},{"atb":[[2.16,0]],"id":64618726},{"atb":[[2.16,0]],"id":67130716}],"con":true,"img":false}]}
{"op":"mcm","clk":"11539153060","pt":1719476113747,"mc":[{"id":"1.230180132","rc":[{"atb":[[2.18,3.16]],"id":66314580},{"spn":76.09,"spf":"NaN","id":66314580}],"con":true,"img":false}]}
{"op":"mcm","clk":"11539153068","pt":1719476113849,"mc":[{"id":"1.230180132","rc":[{"atb":[[2.16,3.16]],"id":67487134}],"con":true,"img":false}]}
{"op":"mcm","clk":"11539153077","pt":1719476113952,"mc":[{"id":"1.230180132","rc":[{"atb":[[2.2,3.16]],"id":64618726}],"con":true,"img":false}]}
{"op":"mcm","clk":"11539153085","pt":1719476114106,"mc":[{"id":"1.230180132","rc":[{"atb":[[2.12,3.16]],"id":53826530}],"con":true,"img":false}]}
{"op":"mcm","clk":"11539153090","pt":1719476114157,"mc":[{"id":"1.230180132","rc":[{"atb":[[2.2,3.16]],"id":67130716}],"con":true,"img":false}]}
{"op":"mcm","clk":"11539154687","pt":1719476138876,"mc":[{"id":"1.230180132","rc":[{"atb":[[2.18,6.55]],"id":66314580}],"con":true,"img":false}]}
{"op":"mcm","clk":"11539154717","pt":1719476139296,"mc":[{"id":"1.230180132","rc":[{"atb":[[2.2,6.55]],"id":67130716}],"con":true,"img":false}]}
{"op":"mcm","clk":"11539154735","pt":1719476139492,"mc":[{"id":"1.230180132","rc":[{"atb":[[2.12,6.55]],"id":53826530}],"con":true,"img":false}]}
{"op":"mcm","clk":"11539154769","pt":1719476139903,"mc":[{"id":"1.230180132","rc":[{"atb":[[2.2,6.55]],"id":64618726}],"con":true,"img":false}]}
{"op":"mcm","clk":"11539154782","pt":1719476140105,"mc":[{"id":"1.230180132","rc":[{"atb":[[2.16,6.55]],"id":67487134}],"con":true,"img":false}]}
{"op":"mcm","clk":"11539341577","pt":1719479313005,"mc":[{"id":"1.230180132","rc":[{"atb":[[1.03,17.28],[2.16,6.54],[2.14,0]],"id":67487134},{"spn":76.08,"spf":"NaN","id":67487134},{"atb":[[1.01,51.83],[2.18,6.54],[2.16,0]],"id":66314580},{"atb":[[1.02,25.91],[2.12,6.54],[2.1,0]],"id":53826530},{"spn":76.06,"spf":"NaN","id":53826530},{"atb":[[1.02,25.91],[2.1,12.55]],"id":70086038},{"atb":[[1.03,17.28],[2.18,0],[2.2,6.54]],"id":64618726},{"spn":13.1,"spf":"NaN","id":64618726},{"atb":[[1.02,25.91],[2.18,0],[2.2,6.54]],"id":67130716},{"spn":76.1,"spf":"NaN","id":67130716}],"con":true,"img":false}]}
{"op":"mcm","clk":"11539341584","pt":1719479313053,"mc":[{"id":"1.230180132","rc":[{"atb":[[2.18,10.55]],"id":67487134},{"atb":[[2.2,11.54]],"id":66314580},{"atb":[[2.14,12.08]],"id":53826530},{"atb":[[2.22,9.86]],"id":64618726},{"atb":[[2.22,12.55]],"id":67130716}],"con":true,"img":false}]}
{"op":"mcm","clk":"11539346332","pt":1719479389062,"mc":[{"id":"1.230180132","rc":[{"spn":76.09,"spf":"NaN","id":67487134},{"spn":76.1,"spf":"NaN","id":66314580},{"spn":76.07,"spf":"NaN","id":53826530},{"atb":[[2.2,3.38]],"id":64618726},{"spn":13.11,"spf":"NaN","id":64618726},{"spn":76.11,"spf":"NaN","id":67130716}],"con":true,"img":false}]}
{"op":"mcm","clk":"11539346384","pt":1719479389784,"mc":[{"id":"1.230180132","rc":[{"atb":[[2.12,3.38]],"id":53826530}],"con":true,"img":false}]}
{"op":"mcm","clk":"11539346402","pt":1719479390091,"mc":[{"id":"1.230180132","rc":[{"atb":[[2.16,3.38]],"id":67487134},{"atb":[[2.2,3.38]],"id":67130716}],"con":true,"img":false}]}
{"op":"mcm","clk":"11539346452","pt":1719479390869,"mc":[{"id":"1.230180132","rc":[{"atb":[[2.18,3.38]],"id":66314580}],"con":true,"img":false}]}
{"op":"mcm","clk":"11539348398","pt":1719479421927,"mc":[{"id":"1.230180132","rc":[{"atb":[[2.2,0]],"id":67130716}],"con":true,"img":false}]}
{"op":"mcm","clk":"11539348406","pt":1719479422036,"mc":[{"id":"1.230180132","rc":[{"atb":[[2.16,0]],"id":67487134}],"con":true,"img":false}]}
{"op":"mcm","clk":"11539348421","pt":1719479422236,"mc":[{"id":"1.230180132","rc":[{"atb":[[2.18,0]],"id":66314580}],"con":true,"img":false}]}
{"op":"mcm","clk":"11539348457","pt":1719479422705,"mc":[{"id":"1.230180132","rc":[{"atb":[[2.12,0]],"id":53826530}],"con":true,"img":false}]}
{"op":"mcm","clk":"11539348473","pt":1719479422916,"mc":[{"id":"1.230180132","rc":[{"atb":[[2.2,0]],"id":64618726}],"con":true,"img":false}]}
{"op":"mcm","clk":"11539348607","pt":1719479424927,"mc":[{"id":"1.230180132","rc":[{"atb":[[2.24,3.38]],"id":67130716}],"con":true,"img":false}]}
{"op":"mcm","clk":"11539348614","pt":1719479425229,"mc":[{"id":"1.230180132","rc":[{"atb":[[2.22,3.38]],"id":66314580}],"con":true,"img":false}]}
{"op":"mcm","clk":"11539348654","pt":1719479425803,"mc":[{"id":"1.230180132","rc":[{"atb":[[2.24,3.38]],"id":64618726}],"con":true,"img":false}]}
{"op":"mcm","clk":"11539348683","pt":1719479426218,"mc":[{"id":"1.230180132","rc":[{"atb":[[2.16,3.38]],"id":53826530}],"con":true,"img":false}]}
{"op":"mcm","clk":"11539348715","pt":1719479426730,"mc":[{"id":"1.230180132","rc":[{"atb":[[2.2,3.38]],"id":67487134}],"con":true,"img":false}]}
{"op":"mcm","clk":"11539367425","pt":1719479703854,"mc":[{"id":"1.230180132","rc":[{"spn":76.1,"spf":"NaN","id":67487134},{"spn":76.11,"spf":"NaN","id":66314580},{"atb":[[2.16,6.54]],"id":53826530},{"spn":76.08,"spf":"NaN","id":53826530},{"spn":13.12,"spf":"NaN","id":64618726},{"spn":76.12,"spf":"NaN","id":67130716}],"con":true,"img":false}]}
{"op":"mcm","clk":"11539367450","pt":1719479704161,"mc":[{"id":"1.230180132","rc":[{"atb":[[2.22,6.54]],"id":66314580}],"con":true,"img":false}]}
{"op":"mcm","clk":"11539367466","pt":1719479704320,"mc":[{"id":"1.230180132","rc":[{"atb":[[2.24,6.54]],"id":64618726}],"con":true,"img":false}]}
{"op":"mcm","clk":"11539367578","pt":1719479705761,"mc":[{"id":"1.230180132","rc":[{"atb":[[2.24,6.54]],"id":67130716}],"con":true,"img":false}]}
{"op":"mcm","clk":"11539367783","pt":1719479708348,"mc":[{"id":"1.230180132","rc":[{"atb":[[2.2,6.54]],"id":67487134}],"con":true,"img":false}]}
{"op":"mcm","clk":"11539545628","pt":1719482913293,"mc":[{"id":"1.230180132","rc":[{"atb":[[1.03,17.27],[2.18,0],[2.2,6.54]],"id":67487134},{"atb":[[1.01,51.83],[2.22,6.54],[2.2,0]],"id":66314580},{"atb":[[1.02,25.91],[2.16,6.54],[2.14,0]],"id":53826530},{"atb":[[1.02,25.91],[2.1,12.55]],"id":70086038},{"atb":[[2.24,6.54],[1.03,17.27],[2.22,0]],"id":64618726},{"atb":[[2.24,6.54],[2.22,0],[1.02,25.91]],"id":67130716}],"con":true,"img":false}]}
{"op":"mcm","clk":"11539545638","pt":1719482913392,"mc":[{"id":"1.230180132","rc":[{"atb":[[2.22,10.55]],"id":67487134},{"atb":[[2.24,11.54]],"id":66314580},{"atb":[[2.18,12.07]],"id":53826530},{"atb":[[2.26,9.86]],"id":64618726},{"atb":[[2.26,12.55]],"id":67130716}],"con":true,"img":false}]}
{"op":"mcm","clk":"11539547608","pt":1719482942323,"mc":[{"id":"1.230180132","rc":[{"atb":[[2.24,3.16]],"id":67130716}],"con":true,"img":false}]}
{"op":"mcm","clk":"11539547621","pt":1719482942529,"mc":[{"id":"1.230180132","rc":[{"atb":[[2.22,3.16]],"id":66314580}],"con":true,"img":false}]}
{"op":"mcm","clk":"11539547645","pt":1719482942948,"mc":[{"id":"1.230180132","rc":[{"atb":[[2.16,3.16]],"id":53826530},{"atb":[[2.24,3.16]],"id":64618726}],"con":true,"img":false}]}
{"op":"mcm","clk":"11539547657","pt":1719482943249,"mc":[{"id":"1.230180132","rc":[{"atb":[[2.2,3.16]],"id":67487134}],"con":true,"img":false}]}
{"op":"mcm","clk":"11539547823","pt":1719482945731,"mc":[{"id":"1.230180132","rc":[{"atb":[[2.28,3.38]],"id":67130716}],"con":true,"img":false}]}
{"op":"mcm","clk":"11539547845","pt":1719482946030,"mc":[{"id":"1.230180132","rc":[{"atb":[[2.2,3.38]],"id":53826530}],"con":true,"img":false}]}
{"op":"mcm","clk":"11539547852","pt":1719482946134,"mc":[{"id":"1.230180132","rc":[{"atb":[[2.26,3.38]],"id":66314580}],"con":true,"img":false}]}
{"op":"mcm","clk":"11539547900","pt":1719482946856,"mc":[{"id":"1.230180132","rc":[{"atb":[[2.28,3.38]],"id":64618726}],"con":true,"img":false}]}
{"op":"mcm","clk":"11539547911","pt":1719482946959,"mc":[{"id":"1.230180132","rc":[{"atb":[[2.24,3.38]],"id":67487134}],"con":true,"img":false}]}
{"op":"mcm","clk":"11539552932","pt":1719483022966,"mc":[{"id":"1.230180132","rc":[{"spn":76.12,"spf":"NaN","id":67487134},{"spn":76.13,"spf":"NaN","id":66314580},{"spn":76.1,"spf":"NaN","id":53826530},{"spn":13.14,"spf":"NaN","id":64618726},{"atb":[[2.24,0]],"id":67130716},{"spn":76.14,"spf":"NaN","id":67130716}],"con":true,"img":false}]}
{"op":"mcm","clk":"11539552959","pt":1719483023236,"mc":[{"id":"1.230180132","rc":[{"atb":[[2.22,0]],"id":66314580}],"con":true,"img":false}]}
{"op":"mcm","clk":"11539552979","pt":1719483023537,"mc":[{"id":"1.230180132","rc":[{"atb":[[2.24,0]],"id":64618726}],"con":true,"img":false}]}
{"op":"mcm","clk":"11539552989","pt":1719483023649,"mc":[{"id":"1.230180132","rc":[{"atb":[[2.2,0]],"id":67487134}],"con":true,"img":false}]}
{"op":"mcm","clk":"11539553042","pt":1719483024263,"mc":[{"id":"1.230180132","rc":[{"atb":[[2.26,6.54]],"id":66314580}],"con":true,"img":false}]}
{"op":"mcm","clk":"11539553085","pt":1719483024832,"mc":[{"id":"1.230180132","rc":[{"atb":[[2.28,6.54]],"id":64618726}],"con":true,"img":false}]}
{"op":"mcm","clk":"11539553097","pt":1719483025041,"mc":[{"id":"1.230180132","rc":[{"atb":[[2.24,6.54]],"id":67487134}],"con":true,"img":false}]}
{"op":"mcm","clk":"11539553112","pt":1719483025249,"mc":[{"id":"1.230180132","rc":[{"atb":[[2.16,0]],"id":53826530}],"con":true,"img":false}]}
{"op":"mcm","clk":"11539553193","pt":1719483026340,"mc":[{"id":"1.230180132","rc":[{"atb":[[2.2,6.54]],"id":53826530}],"con":true,"img":false}]}
{"op":"mcm","clk":"11539553231","pt":1719483026955,"mc":[{"id":"1.230180132","rc":[{"atb":[[2.28,6.54]],"id":67130716}],"con":true,"img":false}]}
{"op":"mcm","clk":"11539680816","pt":1719484784550,"mc":[{"id":"1.230180132","rc":[{"atb":[[2.26,2]],"id":67487134},{"spn":76.13,"spf":"NaN","id":67487134}],"con":true,"img":false}]}
{"op":"mcm","clk":"11539814864","pt":1719486482814,"mc":[{"id":"1.230180132","marketDefinition":{"bspMarket":true,"turnInPlayEnabled":false,"persistenceEnabled":false,"marketBaseRate":5.0,"eventId":"33376437","eventTypeId":"4339","numberOfWinners":1,"bettingType":"ODDS","marketType":"WIN","marketTime":"2024-06-27T16:39:00.000Z","suspendTime":"2024-06-27T16:39:00.000Z","bspReconciled":false,"complete":true,"inPlay":false,"crossMatching":true,"runnersVoidable":false,"numberOfActiveRunners":6,"betDelay":0,"status":"OPEN","runners":[{"status":"ACTIVE","sortPriority":1,"id":66314580,"name":"1. Shesbeenlit"},{"status":"ACTIVE","sortPriority":2,"id":67487134,"name":"2. Salacres Elbuena"},{"status":"ACTIVE","sortPriority":3,"id":67130716,"name":"3. Donishall Dolly"},{"status":"ACTIVE","sortPriority":4,"id":70086038,"name":"4. Greencroft Gerry"},{"status":"ACTIVE","sortPriority":5,"id":53826530,"name":"5. Meena"},{"status":"ACTIVE","sortPriority":6,"id":64618726,"name":"6. Ballyboss Rose"}],"regulators":["MR_INT"],"venue":"Towcester","countryCode":"GB","discountAllowed":true,"timezone":"Europe/London","openDate":"2024-06-27T13:33:00.000Z","version":5994767129,"name":"A7 500m","eventName":"Towcester 27th Jun"},"rc":[{"atb":[[2.24,6.54],[1.03,17.28],[2.22,10.55],[2.26,2]],"id":67487134},{"atl":[[150,4],[1000,0.23]],"id":67487134},{"spn":76.13,"spf":"NaN","id":67487134},{"atb":[[2.24,11.54],[1.01,51.83],[2.26,6.54]],"id":66314580},{"atl":[[150,4],[990,0.23]],"id":66314580},{"spn":76.13,"spf":"NaN","id":66314580},{"atb":[[1.02,25.91],[2.18,12.08],[2.2,6.54]],"id":53826530},{"atl":[[150,4],[990,0.23]],"id":53826530},{"spn":76.1,"spf":"NaN","id":53826530},{"atb":[[1.02,25.91],[2.1,12.55]],"id":70086038},{"atl":[[150,4],[990,0.23]],"id":70086038},{"spn":76.05,"spf":"NaN","id":70086038},{"atb":[[1.03,17.28],[2.28,6.54],[2.26,9.86]],"id":64618726},{"atl":[[150,4],[24,0.6],[990,0.23]],"id":64618726},{"spn":13.14,"spf":"NaN","id":64618726},{"atb":[[1.02,25.91],[2.28,6.54],[2.26,12.55]],"id":67130716},{"atl":[[150,4],[990,0.23]],"id":67130716},{"spn":76.14,"spf":"NaN","id":67130716}],"con":true,"img":true}]}
{"op":"mcm","clk":"11539817739","pt":1719486510881,"mc":[{"id":"1.230180132","rc":[{"atb":[[2.24,6.54],[1.03,17.28],[2.22,0]],"id":67487134},{"atb":[[2.24,0],[1.01,51.83],[2.26,6.54]],"id":66314580},{"atb":[[1.02,25.91],[2.18,0],[2.2,6.54]],"id":53826530},{"atb":[[1.02,25.91],[2.1,12.55]],"id":70086038},{"atb":[[1.03,17.28],[2.28,6.54],[2.26,0]],"id":64618726},{"atb":[[1.02,25.91],[2.28,6.54],[2.26,0]],"id":67130716}],"con":true,"img":false}]}
{"op":"mcm","clk":"11539817749","pt":1719486510933,"mc":[{"id":"1.230180132","rc":[{"atb":[[2.26,12.55]],"id":67487134},{"atb":[[2.28,11.54]],"id":66314580},{"atb":[[2.22,12.08]],"id":53826530},{"atb":[[2.3,9.86]],"id":64618726},{"atb":[[2.3,12.55]],"id":67130716}],"con":true,"img":false}]}
{"op":"mcm","clk":"11539818461","pt":1719486518666,"mc":[{"id":"1.230180132","rc":[{"atb":[[2.26,3.38]],"id":66314580}],"con":true,"img":false}]}
{"op":"mcm","clk":"11539818505","pt":1719486519084,"mc":[{"id":"1.230180132","rc":[{"atb":[[2.28,3.38]],"id":64618726}],"con":true,"img":false}]}
{"op":"mcm","clk":"11539818553","pt":1719486519546,"mc":[{"id":"1.230180132","rc":[{"atb":[[2.3,3.16]],"id":66314580}],"con":true,"img":false}]}
{"op":"mcm","clk":"11539818571","pt":1719486519755,"mc":[{"id":"1.230180132","rc":[{"atb":[[2.24,3.38]],"id":67487134}],"con":true,"img":false}]}
{"op":"mcm","clk":"11539818600","pt":1719486520072,"mc":[{"id":"1.230180132","rc":[{"atb":[[2.32,3.16]],"id":64618726}],"con":true,"img":false}]}
{"op":"mcm","clk":"11539818644","pt":1719486520530,"mc":[{"id":"1.230180132","rc":[{"atb":[[2.2,3.38]],"id":53826530}],"con":true,"img":false}]}
{"op":"mcm","clk":"11539818701","pt":1719486521264,"mc":[{"id":"1.230180132","rc":[{"atb":[[2.28,3.38]],"id":67130716}],"con":true,"img":false}]}
{"op":"mcm","clk":"11539818713","pt":1719486521368,"mc":[{"id":"1.230180132","rc":[{"atb":[[2.28,3.16]],"id":67487134}],"con":true,"img":false}]}
{"op":"mcm","clk":"11539818755","pt":1719486521738,"mc":[{"id":"1.230180132","rc":[{"atb":[[2.24,3.16]],"id":53826530}],"con":true,"img":false}]}
{"op":"mcm","clk":"11539818773","pt":1719486521945,"mc":[{"id":"1.230180132","rc":[{"atb":[[2.32,3.16]],"id":67130716}],"con":true,"img":false}]}
{"op":"mcm","clk":"11539820196","pt":1719486538788,"mc":[{"id":"1.230180132","rc":[{"atb":[[4.7,6]],"id":67487134},{"atb":[[2.44,6]],"id":66314580},{"atb":[[4.4,6]],"id":53826530},{"atb":[[2.58,6]],"id":70086038},{"atb":[[2.44,6]],"id":64618726},{"atb":[[3.55,6]],"id":67130716}],"con":true,"img":false}]}
{"op":"mcm","clk":"11539825483","pt":1719486601157,"mc":[{"id":"1.230180132","rc":[{"atb":[[2.28,0]],"id":67487134},{"spn":77.35,"spf":"NaN","id":67487134},{"spn":76.22,"spf":"NaN","id":66314580},{"atb":[[2.24,0]],"id":53826530},{"spn":77.2,"spf":"NaN","id":53826530},{"spn":76.29,"spf":"NaN","id":70086038},{"spn":13.22,"spf":"NaN","id":64618726},{"atb":[[2.32,0]],"id":67130716},{"spn":76.77,"spf":"NaN","id":67130716}],"con":true,"img":false}]}
{"op":"mcm","clk":"11539831846","pt":1719486679092,"mc":[{"id":"1.230180132","rc":[{"atb":[[2.26,0]],"id":66314580}],"con":true,"img":false}]}
{"op":"mcm","clk":"11539831877","pt":1719486679451,"mc":[{"id":"1.230180132","rc":[{"atb":[[2.24,0]],"id":67487134},{"atb":[[2.2,0]],"id":53826530},{"atb":[[2.28,0]],"id":67130716}],"con":true,"img":false}]}
{"op":"mcm","clk":"11539831964","pt":1719486680485,"mc":[{"id":"1.230180132","rc":[{"atb":[[2.28,0]],"id":64618726}],"con":true,"img":false}]}
{"op":"mcm","clk":"11539832027","pt":1719486681269,"mc":[{"id":"1.230180132","rc":[{"atb":[[2.3,6.54]],"id":66314580}],"con":true,"img":false}]}
{"op":"mcm","clk":"11539832065","pt":1719486681892,"mc":[{"id":"1.230180132","rc":[{"atb":[[2.32,6.54]],"id":64618726}],"con":true,"img":false}]}
{"op":"mcm","clk":"11539840884","pt":1719486811028,"mc":[{"id":"1.230180132","rc":[{"atb":[[2.28,0]],"id":66314580},{"atb":[[2.3,0]],"id":64618726}],"con":true,"img":false}]}
{"op":"mcm","clk":"11539840894","pt":1719486811128,"mc":[{"id":"1.230180132","rc":[{"atb":[[2.32,11.54]],"id":66314580},{"atb":[[2.34,9.86]],"id":64618726}],"con":true,"img":false}]}
{"op":"mcm","clk":"11539841398","pt":1719486819241,"mc":[{"id":"1.230180132","rc":[{"atb":[[2.3,3.38]],"id":66314580},{"atb":[[2.32,3.38]],"id":64618726}],"con":true,"img":false}]}
{"op":"mcm","clk":"11539842932","pt":1719486842561,"mc":[{"id":"1.230180132","rc":[{"atb":[[2.3,0]],"id":66314580},{"atb":[[2.32,0]],"id":64618726}],"con":true,"img":false}]}
{"op":"mcm","clk":"11539848459","pt":1719486920378,"mc":[{"id":"1.230180132","rc":[{"atb":[[2.36,3.38]],"id":64618726}],"con":true,"img":false}]}
{"op":"mcm","clk":"11539848510","pt":1719486921259,"mc":[{"id":"1.230180132","rc":[{"atb":[[2.34,3.38]],"id":66314580}],"con":true,"img":false}]}
{"op":"mcm","clk":"11539850228","pt":1719486943794,"mc":[{"id":"1.230180132","rc":[{"atb":[[2.34,6.54]],"id":66314580}],"con":true,"img":false}]}
{"op":"mcm","clk":"11539850297","pt":1719486944719,"mc":[{"id":"1.230180132","rc":[{"atb":[[2.36,6.54]],"id":64618726}],"con":true,"img":false}]}
{"op":"mcm","clk":"11539960088","pt":1719488355784,"mc":[{"id":"1.230180132","rc":[{"atl":[[36,12],[21,8]],"id":66314580},{"spn":11.72,"spf":"NaN","id":66314580},{"atl":[[42,12],[25,8]],"id":70086038},{"spn":13.79,"spf":"NaN","id":70086038},{"atl":[[36,12],[21,8]],"id":64618726},{"spn":11.72,"spf":"NaN","id":64618726}],"con":true,"img":false}]}
{"op":"mcm","clk":"11540014586","pt":1719489001241,"mc":[{"id":"1.230180132","rc":[{"atl":[[390,2]],"id":67487134},{"atb":[[1.16,150]],"id":66314580},{"atl":[[370,2]],"id":66314580},{"atl":[[560,2]],"id":53826530},{"atl":[[500,2]],"id":64618726},{"atl":[[550,2]],"id":67130716}],"con":true,"img":false}]}
{"op":"mcm","clk":"11540014599","pt":1719489001341,"mc":[{"id":"1.230180132","rc":[{"atb":[[1.16,150]],"id":67487134},{"atb":[[1.16,150]],"id":53826530},{"atb":[[1.16,150]],"id":70086038},{"atl":[[270,2]],"id":70086038},{"atb":[[1.16,150]],"id":64618726},{"atb":[[1.16,150]],"id":67130716}],"con":true,"img":false}]}
{"op":"mcm","clk":"11540136549","pt":1719490402656,"mc":[{"id":"1.230180132","rc":[{"atb":[[2.32,0],[2.34,6.54]],"id":66314580},{"atb":[[2.36,6.54]],"id":64618726}],"con":true,"img":false}]}
{"op":"mcm","clk":"11540136563","pt":1719490402755,"mc":[{"id":"1.230180132","rc":[{"atb":[[2.36,11.54]],"id":66314580}],"con":true,"img":false}]}
{"op":"mcm","clk":"11540143359","pt":1719490468721,"mc":[{"id":"1.230180132","rc":[{"atb":[[2.34,3.38]],"id":66314580}],"con":true,"img":false}]}
{"op":"mcm","clk":"11540145439","pt":1719490488779,"mc":[{"id":"1.230180132","rc":[{"atb":[[2.38,3.16]],"id":66314580}],"con":true,"img":false}]}
{"op":"mcm","clk":"11540159360","pt":1719490631216,"mc":[{"id":"1.230180132","rc":[{"atb":[[2.34,0]],"id":66314580}],"con":true,"img":false}]}
{"op":"mcm","clk":"11540159508","pt":1719490632617,"mc":[{"id":"1.230180132","rc":[{"atb":[[2.38,6.54]],"id":66314580}],"con":true,"img":false}]}
{"op":"mcm","clk":"11540255423","pt":1719491941812,"mc":[{"id":"1.230180132","rc":[{"atb":[[5,1]],"id":67487134},{"atb":[[3.95,1]],"id":66314580},{"atb":[[5,1]],"id":53826530},{"atb":[[3.95,1]],"id":70086038},{"atb":[[3.3,1]],"id":64618726},{"atb":[[5,1]],"id":67130716}],"con":true,"img":false}]}
{"op":"mcm","clk":"11540255472","pt":1719491942797,"mc":[{"id":"1.230180132","rc":[{"atb":[[2.12,89.29],[1.51,196.08]],"id":67487134},{"atb":[[1.51,196.08]],"id":67130716}],"con":true,"img":false}]}
{"op":"mcm","clk":"11540255477","pt":1719491942900,"mc":[{"id":"1.230180132","rc":[{"spn":77.5,"spf":"NaN","id":67487134},{"spn":12.47,"spf":"NaN","id":66314580},{"atb":[[1.51,196.08]],"id":53826530},{"spn":77.5,"spf":"NaN","id":53826530},{"spn":14.47,"spf":"NaN","id":70086038},{"spn":12.15,"spf":"NaN","id":64618726},{"spn":77.5,"spf":"NaN","id":67130716}],"con":true,"img":false}]}
{"op":"mcm","clk":"11540311970","pt":1719492850700,"mc":[{"id":"1.230180132","rc":[{"atb":[[2.12,89.29]],"id":53826530}],"con":true,"img":false}]}
{"op":"mcm","clk":"11540315778","pt":1719492897020,"mc":[{"id":"1.230180132","rc":[{"atb":[[1.51,196.08]],"id":66314580},{"atb":[[1.51,196.08]],"id":70086038},{"atb":[[1.51,196.08]],"id":64618726},{"atb":[[2.12,89.29]],"id":67130716}],"con":true,"img":false}]}
{"op":"mcm","clk":"11540687363","pt":1719497282745,"mc":[{"id":"1.230180132","marketDefinition":{"bspMarket":true,"turnInPlayEnabled":false,"persistenceEnabled":false,"marketBaseRate":5.0,"eventId":"33376437","eventTypeId":"4339","numberOfWinners":1,"bettingType":"ODDS","marketType":"WIN","marketTime":"2024-06-27T16:39:00.000Z","suspendTime":"2024-06-27T16:39:00.000Z","bspReconciled":false,"complete":true,"inPlay":false,"crossMatching":true,"runnersVoidable":false,"numberOfActiveRunners":6,"betDelay":0,"status":"OPEN","runners":[{"status":"ACTIVE","sortPriority":1,"id":66314580,"name":"1. Shesbeenlit"},{"status":"ACTIVE","sortPriority":2,"id":67487134,"name":"2. Salacres Elbuena"},{"status":"ACTIVE","sortPriority":3,"id":67130716,"name":"3. Donishall Dolly"},{"status":"ACTIVE","sortPriority":4,"id":70086038,"name":"4. Greencroft Gerry"},{"status":"ACTIVE","sortPriority":5,"id":53826530,"name":"5. Meena"},{"status":"ACTIVE","sortPriority":6,"id":64618726,"name":"6. Ballyboss Rose"}],"regulators":["MR_INT"],"venue":"Towcester","countryCode":"GB","discountAllowed":true,"timezone":"Europe/London","openDate":"2024-06-27T13:33:00.000Z","version":5994767129,"name":"A7 500m","eventName":"Towcester 27th Jun"},"rc":[{"atb":[[5,1],[1.16,150],[1.03,17.29],[2.12,89.29],[2.26,12.56],[1.51,196.08],[4.7,6]],"id":67487134},{"atl":[[150,4],[390,2],[1000,0.23]],"id":67487134},{"spn":77.5,"spf":"NaN","id":67487134},{"atb":[[2.36,11.55],[1.01,51.87],[1.16,150],[3.95,1],[2.38,6.54],[2.44,6],[1.51,196.08]],"id":66314580},{"atl":[[36,12],[150,4],[21,8],[370,2],[990,0.23]],"id":66314580},{"spn":12.47,"spf":"NaN","id":66314580},{"atb":[[5,1],[1.16,150],[2.22,12.08],[1.02,25.93],[2.12,89.29],[4.4,6],[1.51,196.08]],"id":53826530},{"atl":[[560,2],[150,4],[990,0.23]],"id":53826530},{"spn":77.5,"spf":"NaN","id":53826530},{"atb":[[1.16,150],[3.95,1],[1.02,25.93],[2.58,6],[1.51,196.08],[2.1,12.56]],"id":70086038},{"atl":[[270,2],[150,4],[42,12],[25,8],[990,0.23]],"id":70086038},{"spn":14.47,"spf":"NaN","id":70086038},{"atb":[[2.36,6.54],[1.16,150],[1.03,17.29],[2.44,6],[1.51,196.08],[3.3,1],[2.34,9.87]],"id":64618726},{"atl":[[36,12],[150,4],[21,8],[24,0.6],[990,0.23],[500,2]],"id":64618726},{"spn":12.15,"spf":"NaN","id":64618726},{"atb":[[5,1],[2.3,12.56],[1.16,150],[1.02,25.93],[2.12,89.29],[3.55,6],[1.51,196.08]],"id":67130716},{"atl":[[550,2],[150,4],[990,0.23]],"id":67130716},{"spn":77.5,"spf":"NaN","id":67130716}],"con":true,"img":true}]}
{"op":"mcm","clk":"11540725771","pt":1719497711076,"mc":[{"id":"1.230180132","rc":[{"atb":[[1.03,17.29],[2.26,12.56]],"id":67487134},{"atl":[[1000,0.23]],"id":67487134},{"spl":[[1.01,1]],"id":66314580},{"atb":[[2.36,11.55],[1.01,51.87],[2.38,6.54]],"id":66314580},{"atl":[[990,0.23]],"id":66314580},{"spn":3.95,"spf":1.0,"id":66314580},{"atb":[[2.22,12.08],[1.02,25.93]],"id":53826530},{"atl":[[990,0.23]],"id":53826530},{"atb":[[1.02,25.93],[2.1,12.56]],"id":70086038},{"atl":[[990,0.23]],"id":70086038},{"atb":[[2.36,6.54],[1.03,17.29],[2.34,9.87]],"id":64618726},{"atl":[[990,0.23]],"id":64618726},{"atb":[[2.3,12.56],[1.02,25.93]],"id":67130716},{"atl":[[990,0.23]],"id":67130716}],"con":true,"img":false}]}
{"op":"mcm","clk":"11541142970","pt":1719502682765,"mc":[{"id":"1.230180132","marketDefinition":{"bspMarket":true,"turnInPlayEnabled":false,"persistenceEnabled":false,"marketBaseRate":5.0,"eventId":"33376437","eventTypeId":"4339","numberOfWinners":1,"bettingType":"ODDS","marketType":"WIN","marketTime":"2024-06-27T16:39:00.000Z","suspendTime":"2024-06-27T16:39:00.000Z","bspReconciled":false,"complete":true,"inPlay":false,"crossMatching":true,"runnersVoidable":false,"numberOfActiveRunners":6,"betDelay":0,"status":"OPEN","runners":[{"status":"ACTIVE","sortPriority":1,"id":66314580,"name":"1. Shesbeenlit"},{"status":"ACTIVE","sortPriority":2,"id":67487134,"name":"2. Salacres Elbuena"},{"status":"ACTIVE","sortPriority":3,"id":67130716,"name":"3. Donishall Dolly"},{"status":"ACTIVE","sortPriority":4,"id":70086038,"name":"4. Greencroft Gerry"},{"status":"ACTIVE","sortPriority":5,"id":53826530,"name":"5. Meena"},{"status":"ACTIVE","sortPriority":6,"id":64618726,"name":"6. Ballyboss Rose"}],"regulators":["MR_INT"],"venue":"Towcester","countryCode":"GB","discountAllowed":true,"timezone":"Europe/London","openDate":"2024-06-27T13:33:00.000Z","version":5994767129,"name":"A7 500m","eventName":"Towcester 27th Jun"},"rc":[{"atb":[[5,1],[1.16,150],[1.03,17.29],[2.12,89.29],[2.26,12.56],[1.51,196.08],[4.7,6]],"id":67487134},{"atl":[[150,4],[390,2],[1000,0.23]],"id":67487134},{"spn":77.5,"spf":"NaN","id":67487134},{"spl":[[1.01,1]],"id":66314580},{"atb":[[2.36,11.55],[1.01,51.88],[1.16,150],[3.95,1],[2.38,6.54],[2.44,6],[1.51,196.08]],"id":66314580},{"atl":[[36,12],[150,4],[21,8],[370,2],[990,0.23]],"id":66314580},{"spn":3.95,"spf":1.0,"id":66314580},{"atb":[[5,1],[1.16,150],[2.22,12.09],[1.02,25.94],[2.12,89.29],[4.4,6],[1.51,196.08]],"id":53826530},{"atl":[[560,2],[150,4],[990,0.23]],"id":53826530},{"spn":77.5,"spf":"NaN","id":53826530},{"atb":[[1.16,150],[3.95,1],[1.02,25.94],[2.58,6],[1.51,196.08],[2.1,12.56]],"id":70086038},{"atl":[[270,2],[150,4],[42,12],[25,8],[990,0.23]],"id":70086038},{"spn":14.47,"spf":"NaN","id":70086038},{"atb":[[2.36,6.54],[1.16,150],[1.03,17.29],[2.44,6],[1.51,196.08],[3.3,1],[2.34,9.87]],"id":64618726},{"atl":[[36,12],[150,4],[21,8],[24,0.6],[990,0.23],[500,2]],"id":64618726},{"spn":12.15,"spf":"NaN","id":64618726},{"atb":[[5,1],[2.3,12.56],[1.16,150],[1.02,25.94],[2.12,89.29],[3.55,6],[1.51,196.08]],"id":67130716},{"atl":[[550,2],[150,4],[990,0.23]],"id":67130716},{"spn":77.5,"spf":"NaN","id":67130716}],"con":true,"img":true}]}
{"op":"mcm","clk":"11541287640","pt":1719504156166,"mc":[{"id":"1.230180132","rc":[{"atb":[[1.03,17.29],[2.26,12.56]],"id":67487134},{"atb":[[2.36,11.55],[1.01,51.86],[2.38,6.54]],"id":66314580},{"atb":[[2.22,12.08],[1.02,25.93]],"id":53826530},{"atb":[[1.02,25.93],[2.1,12.55]],"id":70086038},{"atb":[[2.36,6.54],[1.03,17.29],[2.34,9.86]],"id":64618726},{"atl":[[20,1.65]],"id":64618726},{"spn":11.65,"spf":"NaN","id":64618726},{"atb":[[2.3,12.55],[1.02,25.93]],"id":67130716}],"con":true,"img":false}]}
{"op":"mcm","clk":"11541287665","pt":1719504156479,"mc":[{"id":"1.230180132","rc":[{"atl":[[24,1.63]],"id":70086038}],"con":true,"img":false}]}
{"op":"mcm","clk":"11541287698","pt":1719504156786,"mc":[{"id":"1.230180132","rc":[{"atl":[[20,1.71]],"id":66314580}],"con":true,"img":false}]}
{"op":"mcm","clk":"11541351699","pt":1719504852389,"mc":[{"id":"1.230180132","rc":[{"atl":[[190,4]],"id":67487134},{"atl":[[190,4]],"id":66314580},{"atl":[[190,4]],"id":53826530},{"atl":[[190,4]],"id":70086038},{"spn":13.97,"spf":"NaN","id":70086038},{"atl":[[190,4]],"id":64618726},{"atl":[[190,4]],"id":67130716}],"con":true,"img":false}]}
{"op":"mcm","clk":"11541355719","pt":1719504899174,"mc":[{"id":"1.230180132","rc":[{"atb":[[1.02,2]],"id":66314580}],"con":true,"img":false}]}
{"op":"mcm","clk":"11541355733","pt":1719504899381,"mc":[{"id":"1.230180132","rc":[{"atb":[[1.02,2]],"id":67487134}],"con":true,"img":false}]}
{"op":"mcm","clk":"11541355748","pt":1719504899591,"mc":[{"id":"1.230180132","rc":[{"atb":[[1.02,27.93]],"id":67130716}],"con":true,"img":false}]}
{"op":"mcm","clk":"11541355763","pt":1719504899804,"mc":[{"id":"1.230180132","rc":[{"atb":[[1.02,27.93]],"id":70086038}],"con":true,"img":false}]}
{"op":"mcm","clk":"11541355785","pt":1719504900065,"mc":[{"id":"1.230180132","rc":[{"atb":[[1.02,27.93]],"id":53826530}],"con":true,"img":false}]}
{"op":"mcm","clk":"11541355820","pt":1719504900486,"mc":[{"id":"1.230180132","rc":[{"atb":[[1.02,2]],"id":64618726}],"con":true,"img":false}]}
{"op":"mcm","clk":"11541386410","pt":1719505213655,"mc":[{"id":"1.230180132","rc":[{"atb":[[3.95,0]],"id":66314580},{"trd":[[3.95,1.99]],"ltp":3.95,"tv":1.99,"id":66314580},{"spn":2.44,"spf":1.0,"id":66314580}],"con":true,"img":false}]}
{"op":"mcm","clk":"11541386464","pt":1719505214259,"mc":[{"id":"1.230180132","rc":[{"atb":[[1.03,1]],"id":66314580},{"atl":[[1000,0.05]],"id":66314580}],"con":true,"img":false}]}
{"op":"mcm","clk":"11541386481","pt":1719505214465,"mc":[{"id":"1.230180132","rc":[{"atb":[[1.03,0.68]],"id":66314580},{"atl":[[1000,0]],"id":66314580}],"con":true,"img":false}]}
{"op":"mcm","clk":"11541386490","pt":1719505214575,"mc":[{"id":"1.230180132","rc":[{"atl":[[19.5,0.05]],"id":66314580}],"con":true,"img":false}]}
{"op":"mcm","clk":"11541386502","pt":1719505214672,"mc":[{"id":"1.230180132","rc":[{"atb":[[1.03,0]],"id":66314580}],"con":true,"img":false}]}
{"op":"mcm","clk":"11541386512","pt":1719505214779,"mc":[{"id":"1.230180132","rc":[{"atb":[[2.46,0.68]],"id":66314580}],"con":true,"img":false}]}
{"op":"mcm","clk":"11541386654","pt":1719505216073,"mc":[{"id":"1.230180132","rc":[{"atb":[[3.7,1]],"id":66314580}],"con":true,"img":false}]}
{"op":"mcm","clk":"11541387490","pt":1719505224587,"mc":[{"id":"1.230180132","rc":[{"atb":[[3.7,0]],"id":66314580},{"trd":[[3.7,1.99]],"ltp":3.7,"tv":1.99,"id":66314580}],"con":true,"img":false}]}
{"op":"mcm","clk":"11541387673","pt":1719505226148,"mc":[{"id":"1.230180132","rc":[{"atb":[[3.45,1]],"id":66314580}],"con":true,"img":false}]}
{"op":"mcm","clk":"11541388014","pt":1719505229663,"mc":[{"id":"1.230180132","rc":[{"atl":[[19.5,0]],"id":66314580}],"con":true,"img":false}]}
{"op":"mcm","clk":"11541388045","pt":1719505229976,"mc":[{"id":"1.230180132","rc":[{"atb":[[2.46,0]],"id":66314580}],"con":true,"img":false}]}
{"op":"mcm","clk":"11541388094","pt":1719505230395,"mc":[{"id":"1.230180132","rc":[{"atl":[[1000,0.05]],"id":66314580}],"con":true,"img":false}]}
{"op":"mcm","clk":"11541388113","pt":1719505230498,"mc":[{"id":"1.230180132","rc":[{"atl":[[1000,0]],"id":66314580}],"con":true,"img":false}]}
{"op":"mcm","clk":"11541388124","pt":1719505230595,"mc":[{"id":"1.230180132","rc":[{"atl":[[19.5,0.05]],"id":66314580}],"con":true,"img":false}]}
{"op":"mcm","clk":"11541388635","pt":1719505235682,"mc":[{"id":"1.230180132","rc":[{"atb":[[3.45,0]],"id":66314580},{"trd":[[3.45,1.99]],"ltp":3.45,"tv":1.99,"id":66314580}],"con":true,"img":false}]}
{"op":"mcm","clk":"11541388682","pt":1719505236197,"mc":[{"id":"1.230180132","rc":[{"atb":[[3.2,1]],"id":66314580}],"con":true,"img":false}]}
{"op":"mcm","clk":"11541389722","pt":1719505245829,"mc":[{"id":"1.230180132","rc":[{"atl":[[19.5,0]],"id":66314580}],"con":true,"img":false}]}
{"op":"mcm","clk":"11541389773","pt":1719505246277,"mc":[{"id":"1.230180132","rc":[{"atb":[[2.32,8.97]],"id":67130716}],"con":true,"img":false}]}
{"op":"mcm","clk":"11541389811","pt":1719505246693,"mc":[{"id":"1.230180132","rc":[{"atb":[[2.28,9.26]],"id":67487134}],"con":true,"img":false}]}
{"op":"mcm","clk":"11541389824","pt":1719505246814,"mc":[{"id":"1.230180132","rc":[{"atl":[[1000,0.05]],"id":66314580}],"con":true,"img":false}]}
{"op":"mcm","clk":"11541389835","pt":1719505246954,"mc":[{"id":"1.230180132","rc":[{"atb":[[3.2,0]],"id":66314580},{"trd":[[3.2,1.99]],"ltp":3.2,"tv":1.99,"id":66314580}],"con":true,"img":false}]}
{"op":"mcm","clk":"11541389843","pt":1719505247007,"mc":[{"id":"1.230180132","rc":[{"atl":[[1000,0]],"id":66314580},{"atb":[[2.24,9.56]],"id":53826530}],"con":true,"img":false}]}
{"op":"mcm","clk":"11541389851","pt":1719505247112,"mc":[{"id":"1.230180132","rc":[{"atl":[[19.5,0.05]],"id":66314580}],"con":true,"img":false}]}
{"op":"mcm","clk":"11541389934","pt":1719505247844,"mc":[{"id":"1.230180132","rc":[{"atb":[[2.32,2.09]],"id":53826530}],"con":true,"img":false}]}
{"op":"mcm","clk":"11541391575","pt":1719505262238,"mc":[{"id":"1.230180132","rc":[{"atl":[[19.5,0]],"id":66314580}],"con":true,"img":false}]}
{"op":"mcm","clk":"11541391605","pt":1719505262555,"mc":[{"id":"1.230180132","rc":[{"atb":[[1.03,1]],"id":66314580},{"atl":[[1000,0.05]],"id":66314580}],"con":true,"img":false}]}
{"op":"mcm","clk":"11541391618","pt":1719505262608,"mc":[{"id":"1.230180132","rc":[{"atb":[[1.03,0.68]],"id":66314580}],"con":true,"img":false}]}
{"op":"mcm","clk":"11541391626","pt":1719505262713,"mc":[{"id":"1.230180132","rc":[{"atb":[[1.03,0]],"id":66314580},{"atl":[[1000,0]],"id":66314580}],"con":true,"img":false}]}
{"op":"mcm","clk":"11541391637","pt":1719505262835,"mc":[{"id":"1.230180132","rc":[{"atb":[[2.46,0.68]],"id":66314580},{"atl":[[19.5,0.05]],"id":66314580}],"con":true,"img":false}]}
{"op":"mcm","clk":"11541393122","pt":1719505278042,"mc":[{"id":"1.230180132","rc":[{"atl":[[19.5,0]],"id":66314580},{"spn":2.45,"spf":1.0,"id":66314580}],"con":true,"img":false}]}
{"op":"mcm","clk":"11541393133","pt":1719505278145,"mc":[{"id":"1.230180132","rc":[{"atb":[[2.46,0]],"id":66314580}],"con":true,"img":false}]}
{"op":"mcm","clk":"11541393151","pt":1719505278350,"mc":[{"id":"1.230180132","rc":[{"atb":[[1.03,1]],"id":66314580},{"atl":[[1000,0.05]],"id":66314580}],"con":true,"img":false}]}
{"op":"mcm","clk":"11541393171","pt":1719505278556,"mc":[{"id":"1.230180132","rc":[{"atb":[[1.03,0.68]],"id":66314580},{"atl":[[1000,0]],"id":66314580}],"con":true,"img":false}]}
{"op":"mcm","clk":"11541393182","pt":1719505278614,"mc":[{"id":"1.230180132","rc":[{"atl":[[19.5,0.05]],"id":66314580}],"con":true,"img":false}]}
{"op":"mcm","clk":"11541393193","pt":1719505278713,"mc":[{"id":"1.230180132","rc":[{"atb":[[1.03,0]],"id":66314580}],"con":true,"img":false}]}
{"op":"mcm","clk":"11541393205","pt":1719505278816,"mc":[{"id":"1.230180132","rc":[{"atb":[[2.46,0.68]],"id":66314580}],"con":true,"img":false}]}
{"op":"mcm","clk":"11541393482","pt":1719505282236,"mc":[{"id":"1.230180132","rc":[{"atb":[[1.52,22.8]],"id":66314580}],"con":true,"img":false}]}
{"op":"mcm","clk":"11541393719","pt":1719505284823,"mc":[{"id":"1.230180132","rc":[{"atb":[[10,5]],"id":67130716}],"con":true,"img":false}]}
{"op":"mcm","clk":"11541394490","pt":1719505293974,"mc":[{"id":"1.230180132","rc":[{"atl":[[19.5,0]],"id":66314580}],"con":true,"img":false}]}
{"op":"mcm","clk":"11541394505","pt":1719505294175,"mc":[{"id":"1.230180132","rc":[{"atb":[[2.46,0]],"id":66314580}],"con":true,"img":false}]}
{"op":"mcm","clk":"11541394522","pt":1719505294399,"mc":[{"id":"1.230180132","rc":[{"atb":[[1.03,1]],"id":66314580},{"atl":[[1000,0.05]],"id":66314580}],"con":true,"img":false}]}
{"op":"mcm","clk":"11541394548","pt":1719505294656,"mc":[{"id":"1.230180132","rc":[{"atb":[[1.03,0.68]],"id":66314580},{"atl":[[1000,0]],"id":66314580}],"con":true,"img":false}]}
{"op":"mcm","clk":"11541394559","pt":1719505294756,"mc":[{"id":"1.230180132","rc":[{"atl":[[19.5,0.05]],"id":66314580}],"con":true,"img":false}]}
{"op":"mcm","clk":"11541394574","pt":1719505294954,"mc":[{"id":"1.230180132","rc":[{"atb":[[1.03,0]],"id":66314580}],"con":true,"img":false}]}
{"op":"mcm","clk":"11541394581","pt":1719505295058,"mc":[{"id":"1.230180132","rc":[{"atb":[[2.46,0.68]],"id":66314580}],"con":true,"img":false}]}
{"op":"mcm","clk":"11541395859","pt":1719505309996,"mc":[{"id":"1.230180132","rc":[{"atl":[[19.5,0]],"id":66314580}],"con":true,"img":false}]}
{"op":"mcm","clk":"11541395915","pt":1719505310465,"mc":[{"id":"1.230180132","rc":[{"atb":[[2.46,0]],"id":66314580}],"con":true,"img":false}]}
{"op":"mcm","clk":"11541396052","pt":1719505311403,"mc":[{"id":"1.230180132","rc":[{"atb":[[1.03,1]],"id":66314580},{"atl":[[1000,0.05]],"id":66314580}],"con":true,"img":false}]}
{"op":"mcm","clk":"11541396072","pt":1719505311611,"mc":[{"id":"1.230180132","rc":[{"atb":[[1.03,0.68]],"id":66314580},{"atl":[[1000,0]],"id":66314580}],"con":true,"img":false}]}
{"op":"mcm","clk":"11541396087","pt":1719505311719,"mc":[{"id":"1.230180132","rc":[{"atl":[[19.5,0.05]],"id":66314580}],"con":true,"img":false}]}
{"op":"mcm","clk":"11541396109","pt":1719505311977,"mc":[{"id":"1.230180132","rc":[{"atb":[[1.03,0]],"id":66314580}],"con":true,"img":false}]}
{"op":"mcm","clk":"11541396116","pt":1719505312079,"mc":[{"id":"1.230180132","rc":[{"atb":[[2.46,0.68]],"id":66314580}],"con":true,"img":false}]}
{"op":"mcm","clk":"11541397595","pt":1719505326902,"mc":[{"id":"1.230180132","rc":[{"atl":[[19.5,0]],"id":66314580}],"con":true,"img":false}]}
{"op":"mcm","clk":"11541397650","pt":1719505327420,"mc":[{"id":"1.230180132","rc":[{"atb":[[2.46,0]],"id":66314580}],"con":true,"img":false}]}
{"op":"mcm","clk":"11541397708","pt":1719505327896,"mc":[{"id":"1.230180132","rc":[{"atb":[[1.03,1]],"id":66314580},{"atl":[[1000,0.05]],"id":66314580}],"con":true,"img":false}]}
{"op":"mcm","clk":"11541397738","pt":1719505328207,"mc":[{"id":"1.230180132","rc":[{"atb":[[1.03,0.68]],"id":66314580},{"atl":[[1000,0]],"id":66314580}],"con":true,"img":false}]}
{"op":"mcm","clk":"11541397746","pt":1719505328300,"mc":[{"id":"1.230180132","rc":[{"atl":[[19.5,0.05]],"id":66314580}],"con":true,"img":false}]}
{"op":"mcm","clk":"11541397774","pt":1719505328611,"mc":[{"id":"1.230180132","rc":[{"atb":[[1.03,0]],"id":66314580}],"con":true,"img":false}]}
{"op":"mcm","clk":"11541397784","pt":1719505328736,"mc":[{"id":"1.230180132","rc":[{"atb":[[2.46,0.68]],"id":66314580}],"con":true,"img":false}]}
{"op":"mcm","clk":"11541398025","pt":1719505331401,"mc":[{"id":"1.230180132","rc":[{"atb":[[2.32,0]],"id":67130716}],"con":true,"img":false}]}
{"op":"mcm","clk":"11541398555","pt":1719505336831,"mc":[{"id":"1.230180132","rc":[{"atb":[[3.6,4.56]],"id":67130716}],"con":true,"img":false}]}
{"op":"mcm","clk":"11541399197","pt":1719505343560,"mc":[{"id":"1.230180132","rc":[{"atl":[[19.5,0]],"id":66314580},{"spn":80.0,"spf":"NaN","id":67130716}],"con":true,"img":false}]}
{"op":"mcm","clk":"11541399247","pt":1719505344045,"mc":[{"id":"1.230180132","rc":[{"atb":[[2.46,0]],"id":66314580}],"con":true,"img":false}]}
{"op":"mcm","clk":"11541399275","pt":1719505344261,"mc":[{"id":"1.230180132","rc":[{"atb":[[1.03,1]],"id":66314580},{"atl":[[1000,0.05]],"id":66314580}],"con":true,"img":false}]}
{"op":"mcm","clk":"11541399287","pt":1719505344362,"mc":[{"id":"1.230180132","rc":[{"atb":[[1.03,0.68]],"id":66314580}],"con":true,"img":false}]}
{"op":"mcm","clk":"11541399302","pt":1719505344469,"mc":[{"id":"1.230180132","rc":[{"atl":[[1000,0]],"id":66314580}],"con":true,"img":false}]}
{"op":"mcm","clk":"11541399314","pt":1719505344578,"mc":[{"id":"1.230180132","rc":[{"atb":[[1.03,0]],"id":66314580},{"atl":[[19.5,0.05]],"id":66314580}],"con":true,"img":false}]}
{"op":"mcm","clk":"11541399325","pt":1719505344631,"mc":[{"id":"1.230180132","rc":[{"atb":[[2.46,0.68]],"id":66314580}],"con":true,"img":false}]}
{"op":"mcm","clk":"11541400682","pt":1719505357852,"mc":[{"id":"1.230180132","rc":[{"atl":[[19.5,0.89]],"id":66314580},{"atl":[[23,0.84]],"id":70086038},{"atl":[[19.5,0.84]],"id":64618726}],"con":true,"img":false}]}
{"op":"mcm","clk":"11541400892","pt":1719505359768,"mc":[{"id":"1.230180132","rc":[{"atl":[[19.5,0.84]],"id":66314580}],"con":true,"img":false}]}
{"op":"mcm","clk":"11541400904","pt":1719505359868,"mc":[{"id":"1.230180132","rc":[{"atb":[[2.46,0]],"id":66314580}],"con":true,"img":false}]}
{"op":"mcm","clk":"11541401020","pt":1719505361060,"mc":[{"id":"1.230180132","rc":[{"atb":[[1.03,1]],"id":66314580},{"atl":[[1000,0.05]],"id":66314580}],"con":true,"img":false}]}
{"op":"mcm","clk":"11541401043","pt":1719505361268,"mc":[{"id":"1.230180132","rc":[{"atb":[[1.03,0.68]],"id":66314580},{"atl":[[1000,0]],"id":66314580}],"con":true,"img":false}]}
{"op":"mcm","clk":"11541401056","pt":1719505361369,"mc":[{"id":"1.230180132","rc":[{"atl":[[19.5,0.89]],"id":66314580}],"con":true,"img":false}]}
{"op":"mcm","clk":"11541401067","pt":1719505361472,"mc":[{"id":"1.230180132","rc":[{"atb":[[1.03,0]],"id":66314580}],"con":true,"img":false}]}
{"op":"mcm","clk":"11541401078","pt":1719505361582,"mc":[{"id":"1.230180132","rc":[{"atb":[[2.46,0.68]],"id":66314580}],"con":true,"img":false}]}
{"op":"mcm","clk":"11541401092","pt":1719505361681,"mc":[{"id":"1.230180132","rc":[{"atb":[[2.3,9.76]],"id":67487134}],"con":true,"img":false}]}
{"op":"mcm","clk":"11541401124","pt":1719505361940,"mc":[{"id":"1.230180132","rc":[{"atb":[[2.26,10.07]],"id":53826530}],"con":true,"img":false}]}
{"op":"mcm","clk":"11541402602","pt":1719505376588,"mc":[{"id":"1.230180132","rc":[{"atl":[[19.5,0.84]],"id":66314580}],"con":true,"img":false}]}
{"op":"mcm","clk":"11541402629","pt":1719505376892,"mc":[{"id":"1.230180132","rc":[{"atb":[[2.46,0]],"id":66314580}],"con":true,"img":false}]}
{"op":"mcm","clk":"11541402700","pt":1719505377664,"mc":[{"id":"1.230180132","rc":[{"atb":[[1.03,1]],"id":66314580},{"atl":[[1000,0.05]],"id":66314580}],"con":true,"img":false}]}
{"op":"mcm","clk":"11541402725","pt":1719505377874,"mc":[{"id":"1.230180132","rc":[{"atb":[[1.03,0.68]],"id":66314580},{"atl":[[1000,0]],"id":66314580}],"con":true,"img":false}]}
{"op":"mcm","clk":"11541402736","pt":1719505377972,"mc":[{"id":"1.230180132","rc":[{"atb":[[1.03,0]],"id":66314580},{"atl":[[19.5,0.89]],"id":66314580}],"con":true,"img":false}]}
{"op":"mcm","clk":"11541402746","pt":1719505378076,"mc":[{"id":"1.230180132","rc":[{"atb":[[2.46,0.68]],"id":66314580}],"con":true,"img":false}]}
{"op":"mcm","clk":"11541403924","pt":1719505389314,"mc":[{"id":"1.230180132","rc":[{"atb":[[2.26,2]],"id":67487134},{"atb":[[2.22,0]],"id":53826530}],"con":true,"img":false}]}
{"op":"mcm","clk":"11541403935","pt":1719505389374,"mc":[{"id":"1.230180132","rc":[{"atb":[[2.32,10.56]],"id":67487134},{"atb":[[2.28,12.08]],"id":53826530}],"con":true,"img":false}]}
{"op":"mcm","clk":"11541404398","pt":1719505393197,"mc":[{"id":"1.230180132","rc":[{"atb":[[2.46,0]],"id":66314580},{"atl":[[19.5,0.84]],"id":66314580}],"con":true,"img":false}]}
{"op":"mcm","clk":"11541404534","pt":1719505394292,"mc":[{"id":"1.230180132","rc":[{"atb":[[1.03,1]],"id":66314580},{"atl":[[1000,0.05]],"id":66314580}],"con":true,"img":false}]}
{"op":"mcm","clk":"11541404567","pt":1719505394599,"mc":[{"id":"1.230180132","rc":[{"atb":[[1.03,0.68]],"id":66314580},{"atl":[[1000,0]],"id":66314580}],"con":true,"img":false}]}
{"op":"mcm","clk":"11541404579","pt":1719505394693,"mc":[{"id":"1.230180132","rc":[{"atl":[[19.5,0.89]],"id":66314580}],"con":true,"img":false}]}
{"op":"mcm","clk":"11541404587","pt":1719505394799,"mc":[{"id":"1.230180132","rc":[{"atb":[[1.03,0]],"id":66314580}],"con":true,"img":false}]}
{"op":"mcm","clk":"11541404599","pt":1719505394901,"mc":[{"id":"1.230180132","rc":[{"atb":[[2.46,0.68]],"id":66314580}],"con":true,"img":false}]}
{"op":"mcm","clk":"11541404921","pt":1719505397804,"mc":[{"id":"1.230180132","rc":[{"atb":[[1.53,23.95]],"id":66314580}],"con":true,"img":false}]}
{"op":"mcm","clk":"11541406040","pt":1719505409010,"mc":[{"id":"1.230180132","rc":[{"atb":[[2.28,0]],"id":67487134},{"atb":[[2.24,0]],"id":53826530},{"spn":13.47,"spf":"NaN","id":70086038},{"spn":11.4,"spf":"NaN","id":64618726}],"con":true,"img":false}]}
{"op":"mcm","clk":"11541406129","pt":1719505409929,"mc":[{"id":"1.230180132","rc":[{"atl":[[19.5,0.84]],"id":66314580}],"con":true,"img":false}]}
{"op":"mcm","clk":"11541406149","pt":1719505410133,"mc":[{"id":"1.230180132","rc":[{"atb":[[2.46,0]],"id":66314580}],"con":true,"img":false}]}
{"op":"mcm","clk":"11541406172","pt":1719505410344,"mc":[{"id":"1.230180132","rc":[{"atb":[[1.03,1]],"id":66314580},{"atl":[[1000,0.05]],"id":66314580}],"con":true,"img":false}]}
{"op":"mcm","clk":"11541406194","pt":1719505410516,"mc":[{"id":"1.230180132","rc":[{"atb":[[1.03,0.68]],"id":66314580},{"atl":[[1000,0]],"id":66314580}],"con":true,"img":false}]}
{"op":"mcm","clk":"11541406209","pt":1719505410617,"mc":[{"id":"1.230180132","rc":[{"atl":[[19.5,0.89]],"id":66314580}],"con":true,"img":false}]}
{"op":"mcm","clk":"11541406222","pt":1719505410721,"mc":[{"id":"1.230180132","rc":[{"atb":[[1.03,0]],"id":66314580}],"con":true,"img":false}]}
{"op":"mcm","clk":"11541406235","pt":1719505410821,"mc":[{"id":"1.230180132","rc":[{"atb":[[2.46,0.68]],"id":66314580}],"con":true,"img":false}]}
{"op":"mcm","clk":"11541406503","pt":1719505413234,"mc":[{"id":"1.230180132","rc":[{"atb":[[2.34,8.84]],"id":67487134}],"con":true,"img":false}]}
{"op":"mcm","clk":"11541406551","pt":1719505413644,"mc":[{"id":"1.230180132","rc":[{"atb":[[2.3,9.12]],"id":53826530}],"con":true,"img":false}]}
{"op":"mcm","clk":"11541406564","pt":1719505413703,"mc":[{"id":"1.230180132","rc":[{"atb":[[2.42,2.09]],"id":67487134}],"con":true,"img":false}]}
{"op":"mcm","clk":"11541407813","pt":1719505425764,"mc":[{"id":"1.230180132","rc":[{"atb":[[2.3,0]],"id":67487134},{"atb":[[2.26,0]],"id":53826530}],"con":true,"img":false}]}
{"op":"mcm","clk":"11541407825","pt":1719505425814,"mc":[{"id":"1.230180132","rc":[{"atl":[[19.5,0.84]],"id":66314580}],"con":true,"img":false}]}
{"op":"mcm","clk":"11541407847","pt":1719505426021,"mc":[{"id":"1.230180132","rc":[{"atb":[[2.46,0]],"id":66314580}],"con":true,"img":false}]}
{"op":"mcm","clk":"11541407910","pt":1719505426641,"mc":[{"id":"1.230180132","rc":[{"atb":[[1.03,1]],"id":66314580},{"atl":[[1000,0.05]],"id":66314580}],"con":true,"img":false}]}
{"op":"mcm","clk":"11541407930","pt":1719505426861,"mc":[{"id":"1.230180132","rc":[{"atb":[[1.03,0.68]],"id":66314580},{"atl":[[1000,0]],"id":66314580}],"con":true,"img":false}]}
{"op":"mcm","clk":"11541407942","pt":1719505426942,"mc":[{"id":"1.230180132","rc":[{"atl":[[19.5,0.89]],"id":66314580}],"con":true,"img":false}]}
{"op":"mcm","clk":"11541407952","pt":1719505427044,"mc":[{"id":"1.230180132","rc":[{"atb":[[1.03,0]],"id":66314580}],"con":true,"img":false}]}
{"op":"mcm","clk":"11541407963","pt":1719505427148,"mc":[{"id":"1.230180132","rc":[{"atb":[[2.46,0.68]],"id":66314580}],"con":true,"img":false}]}
{"op":"mcm","clk":"11541408957","pt":1719505436724,"mc":[{"id":"1.230180132","rc":[{"atb":[[1.12,1.69]],"id":67487134},{"atb":[[1.06,1.69]],"id":66314580}],"con":true,"img":false}]}
{"op":"mcm","clk":"11541408991","pt":1719505437028,"mc":[{"id":"1.230180132","rc":[{"atb":[[1.09,1.69]],"id":70086038},{"atb":[[1.27,1.69]],"id":67130716}],"con":true,"img":false}]}
{"op":"mcm","clk":"11541409018","pt":1719505437337,"mc":[{"id":"1.230180132","rc":[{"atb":[[1.06,0.12]],"id":66314580},{"atb":[[1.08,1.69]],"id":64618726}],"con":true,"img":false}]}
{"op":"mcm","clk":"11541409050","pt":1719505437647,"mc":[{"id":"1.230180132","rc":[{"atb":[[1.12,0.05]],"id":67487134},{"atb":[[1.12,1.69]],"id":53826530}],"con":true,"img":false}]}
{"op":"mcm","clk":"11541409080","pt":1719505437955,"mc":[{"id":"1.230180132","rc":[{"atb":[[1.27,0.02]],"id":67130716}],"con":true,"img":false}]}
{"op":"mcm","clk":"11541409093","pt":1719505438057,"mc":[{"id":"1.230180132","rc":[{"atb":[[1.09,0.07]],"id":70086038}],"con":true,"img":false}]}
{"op":"mcm","clk":"11541409118","pt":1719505438259,"mc":[{"id":"1.230180132","rc":[{"atb":[[1.06,0]],"id":66314580}],"con":true,"img":false}]}
{"op":"mcm","clk":"11541409130","pt":1719505438317,"mc":[{"id":"1.230180132","rc":[{"atb":[[2.46,0.8]],"id":66314580}],"con":true,"img":false}]}
{"op":"mcm","clk":"11541409161","pt":1719505438629,"mc":[{"id":"1.230180132","rc":[{"atb":[[1.12,0]],"id":67487134},{"atb":[[1.08,0.09]],"id":64618726}],"con":true,"img":false}]}
{"op":"mcm","clk":"11541409173","pt":1719505438737,"mc":[{"id":"1.230180132","rc":[{"atb":[[5.1,0.05]],"id":67487134}],"con":true,"img":false}]}
{"op":"mcm","clk":"11541409200","pt":1719505439039,"mc":[{"id":"1.230180132","rc":[{"atb":[[1.12,0.05]],"id":53826530},{"atb":[[1.27,0]],"id":67130716}],"con":true,"img":false}]}
{"op":"mcm","clk":"11541409211","pt":1719505439171,"mc":[{"id":"1.230180132","rc":[{"atb":[[10.5,0.02]],"id":67130716}],"con":true,"img":false}]}
{"op":"mcm","clk":"11541409243","pt":1719505439458,"mc":[{"id":"1.230180132","rc":[{"atb":[[1.09,0]],"id":70086038}],"con":true,"img":false}]}
{"op":"mcm","clk":"11541409255","pt":1719505439560,"mc":[{"id":"1.230180132","rc":[{"atb":[[4,0.07]],"id":70086038}],"con":true,"img":false}]}
{"op":"mcm","clk":"11541409282","pt":1719505439828,"mc":[{"id":"1.230180132","rc":[{"atb":[[1.08,0]],"id":64618726}],"con":true,"img":false}]}
{"op":"mcm","clk":"11541409291","pt":1719505439931,"mc":[{"id":"1.230180132","rc":[{"atb":[[3.35,0.09]],"id":64618726}],"con":true,"img":false}]}
{"op":"mcm","clk":"11541409317","pt":1719505440245,"mc":[{"id":"1.230180132","rc":[{"atb":[[1.12,0]],"id":53826530},{"atb":[[2.6,12.56]],"id":70086038},{"atl":[[24,5.98]],"id":70086038}],"con":true,"img":false}]}
{"op":"mcm","clk":"11541409331","pt":1719505440343,"mc":[{"id":"1.230180132","rc":[{"atb":[[5.1,0.05]],"id":53826530}],"con":true,"img":false}]}
{"op":"mcm","clk":"11541409340","pt":1719505440449,"mc":[{"id":"1.230180132","rc":[{"atb":[[4.5,6]],"id":53826530},{"atl":[[140,2]],"id":53826530}],"con":true,"img":false}]}
{"op":"mcm","clk":"11541409353","pt":1719505440552,"mc":[{"id":"1.230180132","rc":[{"atb":[[4.8,6]],"id":67487134},{"atl":[[140,2]],"id":67487134},{"atb":[[2.46,6.8]],"id":66314580},{"atl":[[20,6.97]],"id":66314580},{"atb":[[2.46,6.55]],"id":64618726},{"atl":[[20,3.65]],"id":64618726},{"atb":[[3.55,18.56]],"id":67130716},{"atl":[[80,2]],"id":67130716}],"con":true,"img":false}]}
{"op":"mcm","clk":"11541409495","pt":1719505442050,"mc":[{"id":"1.230180132","rc":[{"atb":[[2.8,1]],"id":66314580},{"atl":[[7,1]],"id":66314580},{"atl":[[140,2],[80,0]],"id":67130716}],"con":true,"img":false}]}
{"op":"mcm","clk":"11541409505","pt":1719505442156,"mc":[{"id":"1.230180132","rc":[{"atl":[[19.5,0.84]],"id":66314580}],"con":true,"img":false}]}
{"op":"mcm","clk":"11541409526","pt":1719505442362,"mc":[{"id":"1.230180132","rc":[{"atb":[[2.46,6.12]],"id":66314580}],"con":true,"img":false}]}
{"op":"mcm","clk":"11541409593","pt":1719505443141,"mc":[{"id":"1.230180132","rc":[{"atl":[[1000,0.17]],"id":66314580}],"con":true,"img":false}]}
{"op":"mcm","clk":"11541409601","pt":1719505443243,"mc":[{"id":"1.230180132","rc":[{"atl":[[1000,0]],"id":66314580}],"con":true,"img":false}]}
{"op":"mcm","clk":"11541409608","pt":1719505443340,"mc":[{"id":"1.230180132","rc":[{"atl":[[6.8,0.17]],"id":66314580}],"con":true,"img":false}]}
{"op":"mcm","clk":"11541409669","pt":1719505443972,"mc":[{"id":"1.230180132","rc":[{"atb":[[1.52,0]],"id":66314580}],"con":true,"img":false}]}
{"op":"mcm","clk":"11541410139","pt":1719505448057,"mc":[{"id":"1.230180132","rc":[{"atb":[[1.03,18.99]],"id":67487134},{"atl":[[1000,1.93]],"id":67487134},{"atb":[[1.02,3.7]],"id":66314580},{"atl":[[1000,1.7]],"id":66314580},{"atb":[[1.07,1.7]],"id":67130716},{"atl":[[1000,1.7]],"id":67130716}],"con":true,"img":false}]}
{"op":"mcm","clk":"11541410158","pt":1719505448271,"mc":[{"id":"1.230180132","rc":[{"atl":[[1000,0.23]],"id":67487134},{"atb":[[1.07,0.03]],"id":67130716},{"atl":[[1000,0]],"id":67130716}],"con":true,"img":false}]}
{"op":"mcm","clk":"11541410171","pt":1719505448368,"mc":[{"id":"1.230180132","rc":[{"atb":[[1.03,17.37]],"id":67487134},{"atb":[[1.02,2.21]],"id":66314580},{"atl":[[1000,0.01]],"id":66314580}],"con":true,"img":false}]}
{"op":"mcm","clk":"11541410181","pt":1719505448471,"mc":[{"id":"1.230180132","rc":[{"atb":[[1.07,0]],"id":67130716}],"con":true,"img":false}]}
{"op":"mcm","clk":"11541410188","pt":1719505448533,"mc":[{"id":"1.230180132","rc":[{"atb":[[1.03,17.29]],"id":67487134},{"atb":[[1.02,2]],"id":66314580},{"atl":[[1000,0]],"id":66314580},{"atb":[[10.5,0.05]],"id":67130716}],"con":true,"img":false}]}
{"op":"mcm","clk":"11541410198","pt":1719505448641,"mc":[{"id":"1.230180132","rc":[{"atb":[[4.9,0.08]],"id":67487134},{"atb":[[2.48,0.21]],"id":66314580},{"atl":[[19,0.01]],"id":66314580}],"con":true,"img":false}]}
{"op":"mcm","clk":"11541410219","pt":1719505448847,"mc":[{"id":"1.230180132","rc":[{"atb":[[2.36,3.38]],"id":64618726}],"con":true,"img":false}]}
{"op":"mcm","clk":"11541410237","pt":1719505449054,"mc":[{"id":"1.230180132","rc":[{"atb":[[1.54,21.95]],"id":66314580}],"con":true,"img":false}]}
{"op":"mcm","clk":"11541410260","pt":1719505449258,"mc":[{"id":"1.230180132","rc":[{"atb":[[2.48,3.16]],"id":64618726}],"con":true,"img":false}]}
{"op":"mcm","clk":"11541410667","pt":1719505453641,"mc":[{"id":"1.230180132","rc":[{"spb":[[1000,10]],"id":66314580}],"con":true,"img":false}]}
{"op":"mcm","clk":"11541411042","pt":1719505458577,"mc":[{"id":"1.230180132","rc":[{"atl":[[6.8,0]],"id":66314580}],"con":true,"img":false}]}
{"op":"mcm","clk":"11541411063","pt":1719505458740,"mc":[{"id":"1.230180132","rc":[{"atl":[[1000,0.17]],"id":66314580}],"con":true,"img":false}]}
{"op":"mcm","clk":"11541411075","pt":1719505458941,"mc":[{"id":"1.230180132","rc":[{"atl":[[1000,0]],"id":66314580}],"con":true,"img":false}]}
{"op":"mcm","clk":"11541411087","pt":1719505459051,"mc":[{"id":"1.230180132","rc":[{"atl":[[6.8,0.17]],"id":66314580}],"con":true,"img":false}]}
{"op":"mcm","clk":"11541412314","pt":1719505473097,"mc":[{"id":"1.230180132","rc":[{"spn":72.55,"spf":"NaN","id":67487134},{"spn":6.95,"spf":11.0,"id":66314580},{"atb":[[2.32,11.71]],"id":53826530},{"spn":72.55,"spf":"NaN","id":53826530},{"spn":13.5,"spf":"NaN","id":70086038},{"spn":11.42,"spf":"NaN","id":64618726},{"spn":75.25,"spf":"NaN","id":67130716}],"con":true,"img":false}]}
{"op":"mcm","clk":"11541412363","pt":1719505473556,"mc":[{"id":"1.230180132","rc":[{"atb":[[2.36,9.33]],"id":67487134}],"con":true,"img":false}]}
{"op":"mcm","clk":"11541412435","pt":1719505474383,"mc":[{"id":"1.230180132","rc":[{"atl":[[6.8,0]],"id":66314580}],"con":true,"img":false}]}
{"op":"mcm","clk":"11541412465","pt":1719505474688,"mc":[{"id":"1.230180132","rc":[{"atl":[[1000,0.17]],"id":66314580}],"con":true,"img":false}]}
{"op":"mcm","clk":"11541412486","pt":1719505474898,"mc":[{"id":"1.230180132","rc":[{"atl":[[1000,0]],"id":66314580}],"con":true,"img":false}]}
{"op":"mcm","clk":"11541412497","pt":1719505474991,"mc":[{"id":"1.230180132","rc":[{"atl":[[6.8,0.17]],"id":66314580}],"con":true,"img":false}]}
{"op":"mcm","clk":"11541413380","pt":1719505484486,"mc":[{"id":"1.230180132","rc":[{"atb":[[4.9,0]],"id":67487134},{"atb":[[2.48,0]],"id":66314580},{"atl":[[19,0]],"id":66314580},{"atb":[[10.5,0.02]],"id":67130716}],"con":true,"img":false}]}
{"op":"mcm","clk":"11541413849","pt":1719505490210,"mc":[{"id":"1.230180132","rc":[{"atl":[[6.8,0]],"id":66314580}],"con":true,"img":false}]}
{"op":"mcm","clk":"11541413908","pt":1719505490887,"mc":[{"id":"1.230180132","rc":[{"atl":[[1000,0.17]],"id":66314580}],"con":true,"img":false}]}
{"op":"mcm","clk":"11541413921","pt":1719505491097,"mc":[{"id":"1.230180132","rc":[{"atl":[[1000,0]],"id":66314580}],"con":true,"img":false}]}
{"op":"mcm","clk":"11541413927","pt":1719505491207,"mc":[{"id":"1.230180132","rc":[{"atl":[[6.8,0.17]],"id":66314580}],"con":true,"img":false}]}
{"op":"mcm","clk":"11541414398","pt":1719505496730,"mc":[{"id":"1.230180132","rc":[{"atb":[[1.53,0]],"id":66314580}],"con":true,"img":false}]}
{"op":"mcm","clk":"11541415227","pt":1719505506227,"mc":[{"id":"1.230180132","rc":[{"atb":[[1.55,23.07]],"id":66314580}],"con":true,"img":false}]}
{"op":"mcm","clk":"11541415245","pt":1719505506478,"mc":[{"id":"1.230180132","rc":[{"atl":[[6.8,0]],"id":66314580}],"con":true,"img":false}]}
{"op":"mcm","clk":"11541415278","pt":1719505506745,"mc":[{"id":"1.230180132","rc":[{"atl":[[1000,0.17]],"id":66314580}],"con":true,"img":false}]}
{"op":"mcm","clk":"11541415302","pt":1719505507009,"mc":[{"id":"1.230180132","rc":[{"atl":[[1000,0]],"id":66314580}],"con":true,"img":false}]}
{"op":"mcm","clk":"11541415312","pt":1719505507105,"mc":[{"id":"1.230180132","rc":[{"atl":[[6.8,0.17]],"id":66314580}],"con":true,"img":false}]}
{"op":"mcm","clk":"11541415954","pt":1719505514441,"mc":[{"id":"1.230180132","rc":[{"atb":[[2.34,0]],"id":67487134},{"atb":[[2.3,0]],"id":53826530}],"con":true,"img":false}]}
{"op":"mcm","clk":"11541416547","pt":1719505521761,"mc":[{"id":"1.230180132","rc":[{"atb":[[2.34,8.84]],"id":53826530}],"con":true,"img":false}]}
{"op":"mcm","clk":"11541416558","pt":1719505521823,"mc":[{"id":"1.230180132","rc":[{"atb":[[2.38,8.59]],"id":67487134}],"con":true,"img":false}]}
{"op":"mcm","clk":"11541416616","pt":1719505522437,"mc":[{"id":"1.230180132","rc":[{"atl":[[6.8,0]],"id":66314580}],"con":true,"img":false}]}
{"op":"mcm","clk":"11541416651","pt":1719505522850,"mc":[{"id":"1.230180132","rc":[{"atl":[[1000,0.17]],"id":66314580}],"con":true,"img":false}]}
{"op":"mcm","clk":"11541416674","pt":1719505523154,"mc":[{"id":"1.230180132","rc":[{"atl":[[1000,0]],"id":66314580}],"con":true,"img":false}]}
{"op":"mcm","clk":"11541416680","pt":1719505523259,"mc":[{"id":"1.230180132","rc":[{"atl":[[6.8,0.17]],"id":66314580}],"con":true,"img":false}]}
{"op":"mcm","clk":"11541417628","pt":1719505534270,"mc":[{"id":"1.230180132","rc":[{"atb":[[1.54,0]],"id":66314580}],"con":true,"img":false}]}
{"op":"mcm","clk":"11541417995","pt":1719505538558,"mc":[{"id":"1.230180132","rc":[{"atl":[[6.8,0]],"id":66314580}],"con":true,"img":false}]}
{"op":"mcm","clk":"11541418036","pt":1719505539177,"mc":[{"id":"1.230180132","rc":[{"atl":[[1000,0.17]],"id":66314580}],"con":true,"img":false}]}
{"op":"mcm","clk":"11541418049","pt":1719505539345,"mc":[{"id":"1.230180132","rc":[{"atl":[[1000,0]],"id":66314580}],"con":true,"img":false}]}
{"op":"mcm","clk":"11541418060","pt":1719505539440,"mc":[{"id":"1.230180132","rc":[{"atl":[[6.8,0.17]],"id":66314580}],"con":true,"img":false}]}
{"op":"mcm","clk":"11541418114","pt":1719505540173,"mc":[{"id":"1.230180132","rc":[{"atb":[[1.56,21.17]],"id":66314580}],"con":true,"img":false}]}
{"op":"mcm","clk":"11541418594","pt":1719505545796,"mc":[{"id":"1.230180132","rc":[{"atb":[[10.5,0.87]],"id":67130716}],"con":true,"img":false}]}
{"op":"mcm","clk":"11541419391","pt":1719505554665,"mc":[{"id":"1.230180132","rc":[{"atl":[[6.8,0]],"id":66314580}],"con":true,"img":false}]}
{"op":"mcm","clk":"11541419449","pt":1719505555385,"mc":[{"id":"1.230180132","rc":[{"atl":[[1000,0.17]],"id":66314580}],"con":true,"img":false}]}
{"op":"mcm","clk":"11541419467","pt":1719505555592,"mc":[{"id":"1.230180132","rc":[{"atl":[[1000,0]],"id":66314580}],"con":true,"img":false}]}
{"op":"mcm","clk":"11541419480","pt":1719505555693,"mc":[{"id":"1.230180132","rc":[{"atl":[[6.8,0.17]],"id":66314580}],"con":true,"img":false}]}
{"op":"mcm","clk":"11541419886","pt":1719505560177,"mc":[{"id":"1.230180132","rc":[{"atb":[[2.46,6]],"id":66314580}],"con":true,"img":false}]}
{"op":"mcm","clk":"11541419919","pt":1719505560490,"mc":[{"id":"1.230180132","rc":[{"atb":[[5.1,0]],"id":67487134}],"con":true,"img":false}]}
{"op":"mcm","clk":"11541419951","pt":1719505560793,"mc":[{"id":"1.230180132","rc":[{"atb":[[10.5,0.84]],"id":67130716}],"con":true,"img":false}]}
{"op":"mcm","clk":"11541419988","pt":1719505561112,"mc":[{"id":"1.230180132","rc":[{"atb":[[4,0]],"id":70086038}],"con":true,"img":false}]}
{"op":"mcm","clk":"11541420025","pt":1719505561472,"mc":[{"id":"1.230180132","rc":[{"atb":[[5.1,0]],"id":53826530}],"con":true,"img":false}]}
{"op":"mcm","clk":"11541420073","pt":1719505561787,"mc":[{"id":"1.230180132","rc":[{"atb":[[3.35,0]],"id":64618726}],"con":true,"img":false}]}
{"op":"mcm","clk":"11541420100","pt":1719505562095,"mc":[{"id":"1.230180132","rc":[{"atb":[[1.07,1.69]],"id":66314580},{"atb":[[1.27,1.69]],"id":67130716}],"con":true,"img":false}]}
{"op":"mcm","clk":"11541420117","pt":1719505562302,"mc":[{"id":"1.230180132","rc":[{"atb":[[1.12,1.69]],"id":67487134},{"atb":[[1.12,1.69]],"id":53826530}],"con":true,"img":false}]}
{"op":"mcm","clk":"11541420132","pt":1719505562503,"mc":[{"id":"1.230180132","rc":[{"atb":[[1.08,1.69]],"id":64618726}],"con":true,"img":false}]}
{"op":"mcm","clk":"11541420141","pt":1719505562561,"mc":[{"id":"1.230180132","rc":[{"atb":[[1.27,0.02]],"id":67130716}],"con":true,"img":false}]}
{"op":"mcm","clk":"11541420175","pt":1719505562665,"mc":[{"id":"1.230180132","rc":[{"atb":[[1.09,1.69]],"id":70086038}],"con":true,"img":false}]}
{"op":"mcm","clk":"11541420187","pt":1719505562864,"mc":[{"id":"1.230180132","rc":[{"atb":[[1.07,0.11]],"id":66314580}],"con":true,"img":false}]}
{"op":"mcm","clk":"11541420197","pt":1719505562979,"mc":[{"id":"1.230180132","rc":[{"atb":[[1.08,0.09]],"id":64618726}],"con":true,"img":false}]}
{"op":"mcm","clk":"11541420214","pt":1719505563182,"mc":[{"id":"1.230180132","rc":[{"atb":[[1.27,0]],"id":67130716}],"con":true,"img":false}]}
{"op":"mcm","clk":"11541420219","pt":1719505563282,"mc":[{"id":"1.230180132","rc":[{"atb":[[10.5,0.87]],"id":67130716}],"con":true,"img":false}]}
{"op":"mcm","clk":"11541420234","pt":1719505563486,"mc":[{"id":"1.230180132","rc":[{"atb":[[1.12,0.05]],"id":67487134}],"con":true,"img":false}]}
{"op":"mcm","clk":"11541420239","pt":1719505563587,"mc":[{"id":"1.230180132","rc":[{"atb":[[1.12,0.05]],"id":53826530}],"con":true,"img":false}]}
{"op":"mcm","clk":"11541420270","pt":1719505563908,"mc":[{"id":"1.230180132","rc":[{"atb":[[1.09,0.07]],"id":70086038}],"con":true,"img":false}]}
{"op":"mcm","clk":"11541420296","pt":1719505564209,"mc":[{"id":"1.230180132","rc":[{"atb":[[1.07,0]],"id":66314580}],"con":true,"img":false}]}
{"op":"mcm","clk":"11541420304","pt":1719505564280,"mc":[{"id":"1.230180132","rc":[{"atb":[[2.82,0.11]],"id":66314580}],"con":true,"img":false}]}
{"op":"mcm","clk":"11541420325","pt":1719505564573,"mc":[{"id":"1.230180132","rc":[{"atb":[[1.08,0]],"id":64618726}],"con":true,"img":false}]}
{"op":"mcm","clk":"11541420380","pt":1719505564679,"mc":[{"id":"1.230180132","rc":[{"atb":[[3.35,0.09]],"id":64618726}],"con":true,"img":false}]}
{"op":"mcm","clk":"11541420438","pt":1719505565295,"mc":[{"id":"1.230180132","rc":[{"atb":[[1.12,0]],"id":67487134}],"con":true,"img":false}]}
{"op":"mcm","clk":"11541420447","pt":1719505565401,"mc":[{"id":"1.230180132","rc":[{"atb":[[5.1,0.05]],"id":67487134}],"con":true,"img":false}]}
{"op":"mcm","clk":"11541420539","pt":1719505565720,"mc":[{"id":"1.230180132","rc":[{"atb":[[1.12,0]],"id":53826530}],"con":true,"img":false}]}
{"op":"mcm","clk":"11541420551","pt":1719505565825,"mc":[{"id":"1.230180132","rc":[{"atb":[[5.1,0.05]],"id":53826530}],"con":true,"img":false}]}
{"op":"mcm","clk":"11541420594","pt":1719505566083,"mc":[{"id":"1.230180132","rc":[{"atb":[[1.09,0]],"id":70086038}],"con":true,"img":false}]}
{"op":"mcm","clk":"11541420607","pt":1719505566186,"mc":[{"id":"1.230180132","rc":[{"atb":[[4,0.07]],"id":70086038}],"con":true,"img":false}]}
{"op":"mcm","clk":"11541420690","pt":1719505566799,"mc":[{"id":"1.230180132","rc":[{"atb":[[2.36,0]],"id":67487134},{"atb":[[2.32,2.09]],"id":53826530}],"con":true,"img":false}]}
{"op":"mcm","clk":"11541421117","pt":1719505570429,"mc":[{"id":"1.230180132","rc":[{"atb":[[1.03,18.99]],"id":67487134},{"atl":[[1000,1.93]],"id":67487134},{"atb":[[1.02,3.7]],"id":66314580},{"atl":[[1000,1.7]],"id":66314580},{"atl":[[1000,1.7]],"id":67130716}],"con":true,"img":false}]}
{"op":"mcm","clk":"11541421124","pt":1719505570472,"mc":[{"id":"1.230180132","rc":[{"atb":[[1.08,1.7]],"id":67130716}],"con":true,"img":false}]}
{"op":"mcm","clk":"11541421145","pt":1719505570680,"mc":[{"id":"1.230180132","rc":[{"atb":[[1.03,17.36]],"id":67487134},{"atl":[[1000,0.23]],"id":67487134},{"atb":[[1.02,2.2]],"id":66314580},{"atl":[[1000,0.01]],"id":66314580},{"atb":[[1.08,0.03]],"id":67130716},{"atl":[[1000,0]],"id":67130716}],"con":true,"img":false}]}
{"op":"mcm","clk":"11541421163","pt":1719505570888,"mc":[{"id":"1.230180132","rc":[{"atl":[[1000,0]],"id":66314580},{"atb":[[1.08,0]],"id":67130716}],"con":true,"img":false}]}
{"op":"mcm","clk":"11541421175","pt":1719505570988,"mc":[{"id":"1.230180132","rc":[{"atb":[[1.03,17.29]],"id":67487134},{"atb":[[1.02,2]],"id":66314580},{"atl":[[19,0.01],[6.8,0]],"id":66314580},{"atb":[[10.5,0.9]],"id":67130716}],"con":true,"img":false}]}
{"op":"mcm","clk":"11541421183","pt":1719505571080,"mc":[{"id":"1.230180132","rc":[{"atb":[[4.9,0.07]],"id":67487134},{"atb":[[2.48,0.2]],"id":66314580}],"con":true,"img":false}]}
{"op":"mcm","clk":"11541421194","pt":1719505571183,"mc":[{"id":"1.230180132","rc":[{"atl":[[1000,0.17]],"id":66314580}],"con":true,"img":false}]}
{"op":"mcm","clk":"11541421207","pt":1719505571294,"mc":[{"id":"1.230180132","rc":[{"atl":[[1000,0]],"id":66314580}],"con":true,"img":false}]}
{"op":"mcm","clk":"11541421224","pt":1719505571397,"mc":[{"id":"1.230180132","rc":[{"atl":[[6.8,0.17]],"id":66314580}],"con":true,"img":false}]}
{"op":"mcm","clk":"11541421663","pt":1719505575696,"mc":[{"id":"1.230180132","rc":[{"atb":[[2.4,9.06]],"id":67487134}],"con":true,"img":false}]}
{"op":"mcm","clk":"11541421771","pt":1719505576932,"mc":[{"id":"1.230180132","rc":[{"atb":[[2.36,9.33]],"id":53826530}],"con":true,"img":false}]}
{"op":"mcm","clk":"11541421854","pt":1719505577812,"mc":[{"id":"1.230180132","rc":[{"atl":[[1000,1]],"id":66314580}],"con":true,"img":false}]}
{"op":"mcm","clk":"11541421879","pt":1719505578075,"mc":[{"id":"1.230180132","rc":[{"atl":[[1000,0.01]],"id":66314580}],"con":true,"img":false}]}
{"op":"mcm","clk":"11541421892","pt":1719505578279,"mc":[{"id":"1.230180132","rc":[{"atl":[[1000,0]],"id":66314580}],"con":true,"img":false}]}
{"op":"mcm","clk":"11541421902","pt":1719505578387,"mc":[{"id":"1.230180132","rc":[{"atl":[[6.6,0.01]],"id":66314580}],"con":true,"img":false}]}
{"op":"mcm","clk":"11541421913","pt":1719505578484,"mc":[{"id":"1.230180132","rc":[{"atl":[[8,2],[20,1.71]],"id":66314580}],"con":true,"img":false}]}
{"op":"mcm","clk":"11541422617","pt":1719505586504,"mc":[{"id":"1.230180132","rc":[{"atl":[[6.8,0]],"id":66314580}],"con":true,"img":false}]}
{"op":"mcm","clk":"11541422640","pt":1719505586811,"mc":[{"id":"1.230180132","rc":[{"atl":[[1000,0.17]],"id":66314580}],"con":true,"img":false}]}
{"op":"mcm","clk":"11541422658","pt":1719505587036,"mc":[{"id":"1.230180132","rc":[{"atl":[[1000,0]],"id":66314580}],"con":true,"img":false}]}
{"op":"mcm","clk":"11541422670","pt":1719505587121,"mc":[{"id":"1.230180132","rc":[{"atl":[[6.8,0.17]],"id":66314580}],"con":true,"img":false}]}
{"op":"mcm","clk":"11541423827","pt":1719505600651,"mc":[{"id":"1.230180132","rc":[{"atb":[[1.55,0]],"id":66314580},{"spn":6.94,"spf":11.0,"id":66314580}],"con":true,"img":false}]}
{"op":"mcm","clk":"11541423960","pt":1719505602406,"mc":[{"id":"1.230180132","rc":[{"atl":[[6.8,0]],"id":66314580}],"con":true,"img":false}]}
{"op":"mcm","clk":"11541424014","pt":1719505603228,"mc":[{"id":"1.230180132","rc":[{"atl":[[1000,0.17]],"id":66314580}],"con":true,"img":false}]}
{"op":"mcm","clk":"11541424040","pt":1719505603535,"mc":[{"id":"1.230180132","rc":[{"atl":[[1000,0]],"id":66314580}],"con":true,"img":false}]}
{"op":"mcm","clk":"11541424048","pt":1719505603638,"mc":[{"id":"1.230180132","rc":[{"atl":[[6.8,0.17]],"id":66314580}],"con":true,"img":false}]}
{"op":"mcm","clk":"11541424323","pt":1719505606741,"mc":[{"id":"1.230180132","rc":[{"atb":[[4.9,0]],"id":67487134},{"atb":[[2.48,0]],"id":66314580},{"atl":[[19,0]],"id":66314580},{"atb":[[10.5,0.87]],"id":67130716}],"con":true,"img":false}]}
{"op":"mcm","clk":"11541424572","pt":1719505609851,"mc":[{"id":"1.230180132","rc":[{"atb":[[2.38,0]],"id":67487134},{"atb":[[1.57,22.27]],"id":66314580},{"atb":[[2.34,0]],"id":53826530}],"con":true,"img":false}]}
{"op":"mcm","clk":"11541425068","pt":1719505615128,"mc":[{"id":"1.230180132","rc":[{"atb":[[2.42,10.44]],"id":67487134}],"con":true,"img":false}]}
{"op":"mcm","clk":"11541425086","pt":1719505615334,"mc":[{"id":"1.230180132","rc":[{"atb":[[2.38,8.59]],"id":53826530}],"con":true,"img":false}]}
{"op":"mcm","clk":"11541425423","pt":1719505618951,"mc":[{"id":"1.230180132","rc":[{"atl":[[6.8,0]],"id":66314580}],"con":true,"img":false}]}
{"op":"mcm","clk":"11541425455","pt":1719505619258,"mc":[{"id":"1.230180132","rc":[{"atl":[[1000,0.17]],"id":66314580}],"con":true,"img":false}]}
{"op":"mcm","clk":"11541425474","pt":1719505619483,"mc":[{"id":"1.230180132","rc":[{"atl":[[1000,0]],"id":66314580}],"con":true,"img":false}]}
{"op":"mcm","clk":"11541425483","pt":1719505619537,"mc":[{"id":"1.230180132","rc":[{"atl":[[6.8,0.17]],"id":66314580}],"con":true,"img":false}]}
{"op":"mcm","clk":"11541425531","pt":1719505620052,"mc":[{"id":"1.230180132","rc":[{"atb":[[6,1]],"id":67487134},{"atl":[[23,1]],"id":67487134},{"atb":[[2.98,1]],"id":66314580},{"atb":[[5.5,1]],"id":53826530},{"atl":[[19,1]],"id":53826530}],"con":true,"img":false}]}
{"op":"mcm","clk":"11541425541","pt":1719505620155,"mc":[{"id":"1.230180132","rc":[{"atb":[[2.8,0],[2.56,6],[2.46,0]],"id":66314580}],"con":true,"img":false}]}
{"op":"mcm","clk":"11541426397","pt":1719505629375,"mc":[{"id":"1.230180132","rc":[{"atl":[[19,0]],"id":53826530},{"trd":[[19,1.99]],"ltp":19.0,"tv":1.99,"id":53826530}],"con":true,"img":false}]}
{"op":"mcm","clk":"11541426404","pt":1719505629478,"mc":[{"id":"1.230180132","rc":[{"atl":[[21,1]],"id":53826530}],"con":true,"img":false}]}
{"op":"mcm","clk":"11541426591","pt":1719505631560,"mc":[{"id":"1.230180132","rc":[{"atb":[[1.1,1]],"id":53826530}],"con":true,"img":false}]}
{"op":"mcm","clk":"11541426609","pt":1719505631769,"mc":[{"id":"1.230180132","rc":[{"atb":[[1.1,0.22]],"id":53826530}],"con":true,"img":false}]}
{"op":"mcm","clk":"11541426634","pt":1719505632081,"mc":[{"id":"1.230180132","rc":[{"atb":[[1.1,0]],"id":53826530}],"con":true,"img":false}]}
{"op":"mcm","clk":"11541426644","pt":1719505632137,"mc":[{"id":"1.230180132","rc":[{"atb":[[5.6,0.22]],"id":53826530}],"con":true,"img":false}]}
{"op":"mcm","clk":"11541426905","pt":1719505634770,"mc":[{"id":"1.230180132","rc":[{"atl":[[6.8,0]],"id":66314580}],"con":true,"img":false}]}
{"op":"mcm","clk":"11541426925","pt":1719505634976,"mc":[{"id":"1.230180132","rc":[{"atl":[[1000,0.17]],"id":66314580}],"con":true,"img":false}]}
{"op":"mcm","clk":"11541426942","pt":1719505635182,"mc":[{"id":"1.230180132","rc":[{"atl":[[1000,0]],"id":66314580}],"con":true,"img":false}]}
{"op":"mcm","clk":"11541426950","pt":1719505635238,"mc":[{"id":"1.230180132","rc":[{"atl":[[6.8,0.17]],"id":66314580}],"con":true,"img":false}]}
{"op":"mcm","clk":"11541427023","pt":1719505636062,"mc":[{"id":"1.230180132","rc":[{"atb":[[2.56,13.22]],"id":66314580},{"atb":[[2.6,13.57]],"id":70086038},{"atb":[[2.48,4.18]],"id":64618726}],"con":true,"img":false}]}
{"op":"mcm","clk":"11541427456","pt":1719505640973,"mc":[{"id":"1.230180132","rc":[{"atl":[[21,0]],"id":53826530},{"trd":[[21,1.99]],"ltp":21.0,"tv":1.99,"id":53826530}],"con":true,"img":false}]}
{"op":"mcm","clk":"11541427625","pt":1719505642798,"mc":[{"id":"1.230180132","rc":[{"atl":[[6.4,1.32]],"id":66314580}],"con":true,"img":false}]}
{"op":"mcm","clk":"11541427635","pt":1719505642896,"mc":[{"id":"1.230180132","rc":[{"atb":[[2.38,3.16]],"id":66314580}],"con":true,"img":false}]}
{"op":"mcm","clk":"11541427644","pt":1719505642949,"mc":[{"id":"1.230180132","rc":[{"atl":[[1000,0.84]],"id":70086038}],"con":true,"img":false}]}
{"op":"mcm","clk":"11541427718","pt":1719505643782,"mc":[{"id":"1.230180132","rc":[{"atl":[[1000,0.84]],"id":64618726}],"con":true,"img":false}]}
{"op":"mcm","clk":"11541427728","pt":1719505643881,"mc":[{"id":"1.230180132","rc":[{"atl":[[6.6,0]],"id":66314580}],"con":true,"img":false}]}
{"op":"mcm","clk":"11541427738","pt":1719505643986,"mc":[{"id":"1.230180132","rc":[{"atl":[[6.2,0.01]],"id":66314580}],"con":true,"img":false}]}
{"op":"mcm","clk":"11541427748","pt":1719505644088,"mc":[{"id":"1.230180132","rc":[{"atl":[[6.4,0],[6.2,1.37]],"id":66314580}],"con":true,"img":false}]}
{"op":"mcm","clk":"11541427778","pt":1719505644403,"mc":[{"id":"1.230180132","rc":[{"atl":[[1000,0.38]],"id":70086038}],"con":true,"img":false}]}
{"op":"mcm","clk":"11541427799","pt":1719505644603,"mc":[{"id":"1.230180132","rc":[{"atl":[[6.8,1.49]],"id":66314580}],"con":true,"img":false}]}
{"op":"mcm","clk":"11541427817","pt":1719505644762,"mc":[{"id":"1.230180132","rc":[{"atl":[[1000,0.44]],"id":64618726}],"con":true,"img":false}]}
{"op":"mcm","clk":"11541427848","pt":1719505645175,"mc":[{"id":"1.230180132","rc":[{"atl":[[1000,0]],"id":70086038}],"con":true,"img":false}]}
{"op":"mcm","clk":"11541427855","pt":1719505645281,"mc":[{"id":"1.230180132","rc":[{"atl":[[22,0.38]],"id":70086038}],"con":true,"img":false}]}
{"op":"mcm","clk":"11541427884","pt":1719505645691,"mc":[{"id":"1.230180132","rc":[{"atl":[[1000,0]],"id":64618726}],"con":true,"img":false}]}
{"op":"mcm","clk":"11541427893","pt":1719505645799,"mc":[{"id":"1.230180132","rc":[{"atl":[[19,0.44]],"id":64618726}],"con":true,"img":false}]}
{"op":"mcm","clk":"11541428006","pt":1719505646982,"mc":[{"id":"1.230180132","rc":[{"atb":[[1.56,0]],"id":66314580}],"con":true,"img":false}]}
{"op":"mcm","clk":"11541428041","pt":1719505647394,"mc":[{"id":"1.230180132","rc":[{"atb":[[5.6,0]],"id":53826530}],"con":true,"img":false}]}
{"op":"mcm","clk":"11541428056","pt":1719505647605,"mc":[{"id":"1.230180132","rc":[{"atb":[[1.1,1]],"id":53826530},{"atl":[[1000,0.01]],"id":53826530}],"con":true,"img":false}]}
{"op":"mcm","clk":"11541428075","pt":1719505647816,"mc":[{"id":"1.230180132","rc":[{"atb":[[1.1,0.22]],"id":53826530},{"atl":[[1000,0]],"id":53826530}],"con":true,"img":false}]}
{"op":"mcm","clk":"11541428085","pt":1719505647911,"mc":[{"id":"1.230180132","rc":[{"atl":[[130,0.01]],"id":53826530}],"con":true,"img":false}]}
{"op":"mcm","clk":"11541428107","pt":1719505648070,"mc":[{"id":"1.230180132","rc":[{"atb":[[1.1,0]],"id":53826530}],"con":true,"img":false}]}
{"op":"mcm","clk":"11541428114","pt":1719505648170,"mc":[{"id":"1.230180132","rc":[{"atb":[[5.6,0.22]],"id":53826530}],"con":true,"img":false}]}
{"op":"mcm","clk":"11541428319","pt":1719505650505,"mc":[{"id":"1.230180132","rc":[{"atl":[[6.8,1.32]],"id":66314580}],"con":true,"img":false}]}
{"op":"mcm","clk":"11541428353","pt":1719505650816,"mc":[{"id":"1.230180132","rc":[{"atl":[[1000,0.2]],"id":66314580}],"con":true,"img":false}]}
{"op":"mcm","clk":"11541428379","pt":1719505651074,"mc":[{"id":"1.230180132","rc":[{"atl":[[1000,0]],"id":66314580}],"con":true,"img":false}]}
{"op":"mcm","clk":"11541428388","pt":1719505651179,"mc":[{"id":"1.230180132","rc":[{"atl":[[6,0.2]],"id":66314580}],"con":true,"img":false}]}
{"op":"mcm","clk":"11541428410","pt":1719505651385,"mc":[{"id":"1.230180132","rc":[{"atb":[[2.38,0]],"id":66314580}],"con":true,"img":false}]}
{"op":"mcm","clk":"11541428443","pt":1719505651695,"mc":[{"id":"1.230180132","rc":[{"atl":[[7.2,2.32]],"id":66314580},{"atl":[[140,0],[110,2]],"id":67130716}],"con":true,"img":false}]}
{"op":"mcm","clk":"11541428453","pt":1719505651805,"mc":[{"id":"1.230180132","rc":[{"atl":[[8,0]],"id":66314580}],"con":true,"img":false}]}
{"op":"mcm","clk":"11541428473","pt":1719505652004,"mc":[{"id":"1.230180132","rc":[{"atl":[[6.2,1.36]],"id":66314580}],"con":true,"img":false}]}
{"op":"mcm","clk":"11541428484","pt":1719505652108,"mc":[{"id":"1.230180132","rc":[{"atl":[[5.9,0.01]],"id":66314580}],"con":true,"img":false}]}
{"op":"mcm","clk":"11541429313","pt":1719505661296,"mc":[{"id":"1.230180132","rc":[{"spn":14.5,"spf":"NaN","id":67487134},{"spn":6.15,"spf":11.0,"id":66314580},{"atl":[[130,0.85]],"id":53826530},{"spn":67.8,"spf":"NaN","id":53826530},{"spn":13.0,"spf":"NaN","id":70086038},{"spn":11.17,"spf":"NaN","id":64618726},{"atl":[[100,0.84]],"id":67130716},{"spn":55.25,"spf":"NaN","id":67130716}],"con":true,"img":false}]}
{"op":"mcm","clk":"11541429322","pt":1719505661403,"mc":[{"id":"1.230180132","rc":[{"atl":[[19.5,0]],"id":66314580}],"con":true,"img":false}]}
{"op":"mcm","clk":"11541429340","pt":1719505661611,"mc":[{"id":"1.230180132","rc":[{"atl":[[6.6,1.36]],"id":66314580}],"con":true,"img":false}]}
{"op":"mcm","clk":"11541429353","pt":1719505661712,"mc":[{"id":"1.230180132","rc":[{"atl":[[6.2,0]],"id":66314580}],"con":true,"img":false}]}
{"op":"mcm","clk":"11541429502","pt":1719505663215,"mc":[{"id":"1.230180132","rc":[{"atl":[[130,0.84]],"id":53826530}],"con":true,"img":false}]}
{"op":"mcm","clk":"11541429520","pt":1719505663423,"mc":[{"id":"1.230180132","rc":[{"atb":[[5.6,0]],"id":53826530}],"con":true,"img":false}]}
{"op":"mcm","clk":"11541429557","pt":1719505663732,"mc":[{"id":"1.230180132","rc":[{"atb":[[1.1,1]],"id":53826530},{"atl":[[1000,0.01]],"id":53826530}],"con":true,"img":false}]}
{"op":"mcm","clk":"11541429576","pt":1719505663895,"mc":[{"id":"1.230180132","rc":[{"atb":[[1.1,0.22]],"id":53826530},{"atl":[[1000,0]],"id":53826530}],"con":true,"img":false}]}
{"op":"mcm","clk":"11541429587","pt":1719505663999,"mc":[{"id":"1.230180132","rc":[{"atl":[[130,0.85]],"id":53826530}],"con":true,"img":false}]}
{"op":"mcm","clk":"11541429599","pt":1719505664101,"mc":[{"id":"1.230180132","rc":[{"atb":[[1.1,0]],"id":53826530}],"con":true,"img":false}]}
{"op":"mcm","clk":"11541429612","pt":1719505664203,"mc":[{"id":"1.230180132","rc":[{"atb":[[5.6,0.22]],"id":53826530}],"con":true,"img":false}]}
{"op":"mcm","clk":"11541429824","pt":1719505666432,"mc":[{"id":"1.230180132","rc":[{"atl":[[6,0]],"id":66314580}],"con":true,"img":false}]}
{"op":"mcm","clk":"11541429837","pt":1719505666637,"mc":[{"id":"1.230180132","rc":[{"atl":[[1000,0.19]],"id":66314580}],"con":true,"img":false}]}
{"op":"mcm","clk":"11541429858","pt":1719505666801,"mc":[{"id":"1.230180132","rc":[{"atl":[[1000,0]],"id":66314580}],"con":true,"img":false}]}
{"op":"mcm","clk":"11541429867","pt":1719505666909,"mc":[{"id":"1.230180132","rc":[{"atl":[[6.4,0.19]],"id":66314580}],"con":true,"img":false}]}
{"op":"mcm","clk":"11541430018","pt":1719505668820,"mc":[{"id":"1.230180132","rc":[{"atb":[[2.58,3.16]],"id":66314580}],"con":true,"img":false}]}
{"op":"mcm","clk":"11541430027","pt":1719505668915,"mc":[{"id":"1.230180132","rc":[{"atb":[[2.38,8.59]],"id":66314580}],"con":true,"img":false}]}
{"op":"mcm","clk":"11541430198","pt":1719505670825,"mc":[{"id":"1.230180132","rc":[{"atb":[[2.4,0]],"id":67487134},{"atb":[[1.57,0]],"id":66314580},{"atb":[[2.36,0]],"id":53826530}],"con":true,"img":false}]}
{"op":"mcm","clk":"11541430381","pt":1719505672846,"mc":[{"id":"1.230180132","rc":[{"atl":[[1000,1.08]],"id":67487134}],"con":true,"img":false}]}
{"op":"mcm","clk":"11541430403","pt":1719505673005,"mc":[{"id":"1.230180132","rc":[{"atb":[[5.7,1.48]],"id":53826530}],"con":true,"img":false}]}
{"op":"mcm","clk":"11541430422","pt":1719505673216,"mc":[{"id":"1.230180132","rc":[{"atl":[[1000,0.61]],"id":67487134}],"con":true,"img":false}]}
{"op":"mcm","clk":"11541430451","pt":1719505673523,"mc":[{"id":"1.230180132","rc":[{"atb":[[5.6,1.7]],"id":53826530}],"con":true,"img":false}]}
{"op":"mcm","clk":"11541430458","pt":1719505673626,"mc":[{"id":"1.230180132","rc":[{"atb":[[5.7,0]],"id":53826530}],"con":true,"img":false}]}
{"op":"mcm","clk":"11541430494","pt":1719505674045,"mc":[{"id":"1.230180132","rc":[{"atl":[[1000,0.23]],"id":67487134}],"con":true,"img":false}]}
{"op":"mcm","clk":"11541430502","pt":1719505674143,"mc":[{"id":"1.230180132","rc":[{"atl":[[22,0.38]],"id":67487134}],"con":true,"img":false}]}
{"op":"mcm","clk":"11541430529","pt":1719505674462,"mc":[{"id":"1.230180132","rc":[{"atb":[[5.8,1.45],[5.6,0.22],[5.7,0.84]],"id":53826530}],"con":true,"img":false}]}
{"op":"mcm","clk":"11541430738","pt":1719505676848,"mc":[{"id":"1.230180132","rc":[{"atb":[[2.58,6.54]],"id":66314580}],"con":true,"img":false}]}
{"op":"mcm","clk":"11541430748","pt":1719505676947,"mc":[{"id":"1.230180132","rc":[{"atb":[[2.4,9.06]],"id":53826530}],"con":true,"img":false}]}
{"op":"mcm","clk":"11541430805","pt":1719505677517,"mc":[{"id":"1.230180132","rc":[{"atb":[[2.44,8.81]],"id":67487134}],"con":true,"img":false}]}
{"op":"mcm","clk":"11541430836","pt":1719505677931,"mc":[{"id":"1.230180132","rc":[{"atb":[[2.4,9.06]],"id":66314580}],"con":true,"img":false}]}
{"op":"mcm","clk":"11541430969","pt":1719505679226,"mc":[{"id":"1.230180132","rc":[{"atl":[[130,0.84]],"id":53826530}],"con":true,"img":false}]}
{"op":"mcm","clk":"11541430996","pt":1719505679533,"mc":[{"id":"1.230180132","rc":[{"atb":[[5.6,0]],"id":53826530}],"con":true,"img":false}]}
{"op":"mcm","clk":"11541431033","pt":1719505679945,"mc":[{"id":"1.230180132","rc":[{"atb":[[1.1,1]],"id":53826530},{"atl":[[1000,0.01]],"id":53826530}],"con":true,"img":false}]}
{"op":"mcm","clk":"11541431065","pt":1719505680255,"mc":[{"id":"1.230180132","rc":[{"atb":[[1.1,0.2]],"id":53826530},{"atl":[[1000,0]],"id":53826530}],"con":true,"img":false}]}
{"op":"mcm","clk":"11541431076","pt":1719505680310,"mc":[{"id":"1.230180132","rc":[{"atl":[[130,0.85]],"id":53826530}],"con":true,"img":false}]}
{"op":"mcm","clk":"11541431088","pt":1719505680426,"mc":[{"id":"1.230180132","rc":[{"atb":[[1.1,0]],"id":53826530}],"con":true,"img":false}]}
{"op":"mcm","clk":"11541431098","pt":1719505680534,"mc":[{"id":"1.230180132","rc":[{"atb":[[5.9,0.2]],"id":53826530}],"con":true,"img":false}]}
{"op":"mcm","clk":"11541431251","pt":1719505682152,"mc":[{"id":"1.230180132","rc":[{"atl":[[6.4,0]],"id":66314580}],"con":true,"img":false}]}
{"op":"mcm","clk":"11541431273","pt":1719505682315,"mc":[{"id":"1.230180132","rc":[{"atl":[[1000,0.19]],"id":66314580}],"con":true,"img":false}]}
{"op":"mcm","clk":"11541431287","pt":1719505682420,"mc":[{"id":"1.230180132","rc":[{"atb":[[2.82,0]],"id":66314580}],"con":true,"img":false}]}
{"op":"mcm","clk":"11541431296","pt":1719505682524,"mc":[{"id":"1.230180132","rc":[{"atl":[[1000,0]],"id":66314580}],"con":true,"img":false}]}
{"op":"mcm","clk":"11541431307","pt":1719505682623,"mc":[{"id":"1.230180132","rc":[{"atl":[[6.4,0.19]],"id":66314580}],"con":true,"img":false}]}
{"op":"mcm","clk":"11541431315","pt":1719505682730,"mc":[{"id":"1.230180132","rc":[{"atb":[[5.1,0]],"id":67487134}],"con":true,"img":false}]}
{"op":"mcm","clk":"11541431343","pt":1719505683041,"mc":[{"id":"1.230180132","rc":[{"atb":[[10.5,0.84]],"id":67130716}],"con":true,"img":false}]}
{"op":"mcm","clk":"11541431364","pt":1719505683248,"mc":[{"id":"1.230180132","rc":[{"atb":[[5.1,0]],"id":53826530}],"con":true,"img":false}]}
{"op":"mcm","clk":"11541431371","pt":1719505683347,"mc":[{"id":"1.230180132","rc":[{"atb":[[1.04,1.7]],"id":67487134},{"atl":[[1000,1.93]],"id":67487134},{"atb":[[1.02,3.7]],"id":66314580},{"atl":[[1000,1.7]],"id":66314580},{"atb":[[1.08,1.7]],"id":67130716},{"atl":[[1000,1.7]],"id":67130716}],"con":true,"img":false}]}
{"op":"mcm","clk":"11541431382","pt":1719505683449,"mc":[{"id":"1.230180132","rc":[{"atb":[[5.6,1.45]],"id":53826530},{"atb":[[3.35,0]],"id":64618726}],"con":true,"img":false}]}
{"op":"mcm","clk":"11541431390","pt":1719505683553,"mc":[{"id":"1.230180132","rc":[{"atb":[[1.14,1.69],[1.04,0.07]],"id":67487134},{"atb":[[5.8,0]],"id":53826530}],"con":true,"img":false}]}
{"op":"mcm","clk":"11541431402","pt":1719505683658,"mc":[{"id":"1.230180132","rc":[{"atl":[[1000,0.23]],"id":67487134},{"atb":[[1.02,2.18]],"id":66314580},{"atl":[[1000,0.05]],"id":66314580},{"atb":[[1.08,0.03]],"id":67130716},{"atl":[[1000,0]],"id":67130716}],"con":true,"img":false}]}
{"op":"mcm","clk":"11541431423","pt":1719505683817,"mc":[{"id":"1.230180132","rc":[{"atb":[[1.04,0]],"id":67487134},{"atb":[[5.8,1.45]],"id":53826530},{"atb":[[1.27,1.69]],"id":67130716}],"con":true,"img":false}]}
{"op":"mcm","clk":"11541431433","pt":1719505683919,"mc":[{"id":"1.230180132","rc":[{"atb":[[5.1,0.07]],"id":67487134}],"con":true,"img":false}]}
{"op":"mcm","clk":"11541431446","pt":1719505684027,"mc":[{"id":"1.230180132","rc":[{"atb":[[1.02,2]],"id":66314580},{"atl":[[1000,0]],"id":66314580},{"atb":[[4,0]],"id":70086038},{"atb":[[1.08,0]],"id":67130716}],"con":true,"img":false}]}
{"op":"mcm","clk":"11541431457","pt":1719505684127,"mc":[{"id":"1.230180132","rc":[{"atb":[[2.6,0.18],[1.07,1.69]],"id":66314580},{"atl":[[6.6,1.41]],"id":66314580},{"atb":[[5.6,0]],"id":53826530},{"atb":[[10.5,0.87]],"id":67130716}],"con":true,"img":false}]}
{"op":"mcm","clk":"11541431469","pt":1719505684228,"mc":[{"id":"1.230180132","rc":[{"atb":[[1.14,1.69]],"id":53826530}],"con":true,"img":false}]}
{"op":"mcm","clk":"11541431481","pt":1719505684337,"mc":[{"id":"1.230180132","rc":[{"atb":[[1.27,0.02]],"id":67130716}],"con":true,"img":false}]}
{"op":"mcm","clk":"11541431496","pt":1719505684436,"mc":[{"id":"1.230180132","rc":[{"spl":[[1.01,4]],"id":64618726}],"con":true,"img":false}]}
{"op":"mcm","clk":"11541431519","pt":1719505684642,"mc":[{"id":"1.230180132","rc":[{"atb":[[1.14,0.05]],"id":67487134},{"atb":[[1.07,0.1]],"id":66314580}],"con":true,"img":false}]}
{"op":"mcm","clk":"11541431539","pt":1719505684861,"mc":[{"id":"1.230180132","rc":[{"atb":[[1.09,1.69]],"id":70086038}],"con":true,"img":false}]}
{"op":"mcm","clk":"11541431548","pt":1719505684955,"mc":[{"id":"1.230180132","rc":[{"atb":[[1.14,0.05]],"id":53826530}],"con":true,"img":false}]}
{"op":"mcm","clk":"11541431577","pt":1719505685223,"mc":[{"id":"1.230180132","rc":[{"atb":[[1.08,1.69]],"id":64618726},{"atb":[[1.27,0]],"id":67130716}],"con":true,"img":false}]}
{"op":"mcm","clk":"11541431587","pt":1719505685323,"mc":[{"id":"1.230180132","rc":[{"atb":[[10.5,0.9]],"id":67130716}],"con":true,"img":false}]}
{"op":"mcm","clk":"11541431619","pt":1719505685636,"mc":[{"id":"1.230180132","rc":[{"atb":[[1.14,0]],"id":67487134}],"con":true,"img":false}]}
{"op":"mcm","clk":"11541431630","pt":1719505685738,"mc":[{"id":"1.230180132","rc":[{"atb":[[6.2,0.05]],"id":67487134}],"con":true,"img":false}]}
{"op":"mcm","clk":"11541431665","pt":1719505686045,"mc":[{"id":"1.230180132","rc":[{"atb":[[1.07,0]],"id":66314580}],"con":true,"img":false}]}
{"op":"mcm","clk":"11541431674","pt":1719505686149,"mc":[{"id":"1.230180132","rc":[{"atb":[[3,0.1]],"id":66314580}],"con":true,"img":false}]}
{"op":"mcm","clk":"11541431706","pt":1719505686455,"mc":[{"id":"1.230180132","rc":[{"atb":[[1.14,0]],"id":53826530},{"atb":[[1.09,0.07]],"id":70086038}],"con":true,"img":false}]}
{"op":"mcm","clk":"11541431715","pt":1719505686572,"mc":[{"id":"1.230180132","rc":[{"atb":[[5.9,0.25]],"id":53826530}],"con":true,"img":false}]}
{"op":"mcm","clk":"11541431754","pt":1719505686934,"mc":[{"id":"1.230180132","rc":[{"atb":[[1.08,0.09]],"id":64618726}],"con":true,"img":false}]}
{"op":"mcm","clk":"11541431785","pt":1719505687235,"mc":[{"id":"1.230180132","rc":[{"atb":[[1.09,0]],"id":70086038}],"con":true,"img":false}]}
{"op":"mcm","clk":"11541431800","pt":1719505687344,"mc":[{"id":"1.230180132","rc":[{"atb":[[4,0.07]],"id":70086038}],"con":true,"img":false}]}
{"op":"mcm","clk":"11541431812","pt":1719505687444,"mc":[{"id":"1.230180132","rc":[{"atb":[[5.9,1.09]],"id":53826530}],"con":true,"img":false}]}
{"op":"mcm","clk":"11541431831","pt":1719505687650,"mc":[{"id":"1.230180132","rc":[{"atb":[[1.08,0]],"id":64618726}],"con":true,"img":false}]}
{"op":"mcm","clk":"11541431841","pt":1719505687756,"mc":[{"id":"1.230180132","rc":[{"atb":[[5.8,0],[6,1.41]],"id":53826530},{"atb":[[3.35,0.09]],"id":64618726}],"con":true,"img":false}]}
{"op":"mcm","clk":"11541431910","pt":1719505688530,"mc":[{"id":"1.230180132","rc":[{"atb":[[5.7,0]],"id":53826530}],"con":true,"img":false}]}
{"op":"mcm","clk":"11541432007","pt":1719505689458,"mc":[{"id":"1.230180132","rc":[{"atb":[[2.56,6]],"id":66314580}],"con":true,"img":false}]}
{"op":"mcm","clk":"11541432568","pt":1719505695461,"mc":[{"id":"1.230180132","rc":[{"atl":[[130,0.84]],"id":53826530}],"con":true,"img":false}]}
{"op":"mcm","clk":"11541432598","pt":1719505695778,"mc":[{"id":"1.230180132","rc":[{"atb":[[5.9,0.89]],"id":53826530}],"con":true,"img":false}]}
{"op":"mcm","clk":"11541432619","pt":1719505695940,"mc":[{"id":"1.230180132","rc":[{"atb":[[5.6,1.41],[1.11,1]],"id":53826530},{"atl":[[1000,0.01]],"id":53826530}],"con":true,"img":false}]}
{"op":"mcm","clk":"11541432636","pt":1719505696144,"mc":[{"id":"1.230180132","rc":[{"atb":[[1.11,0.19],[6,0]],"id":53826530},{"atl":[[1000,0]],"id":53826530}],"con":true,"img":false}]}
{"op":"mcm","clk":"11541432647","pt":1719505696248,"mc":[{"id":"1.230180132","rc":[{"atb":[[1.11,0]],"id":53826530},{"atl":[[130,0.85]],"id":53826530}],"con":true,"img":false}]}
{"op":"mcm","clk":"11541432657","pt":1719505696347,"mc":[{"id":"1.230180132","rc":[{"atb":[[6.2,0.19]],"id":53826530}],"con":true,"img":false}]}
{"op":"mcm","clk":"11541432688","pt":1719505696659,"mc":[{"id":"1.230180132","rc":[{"atb":[[5.6,0],[6,1.41]],"id":53826530}],"con":true,"img":false}]}
{"op":"mcm","clk":"11541432720","pt":1719505696975,"mc":[{"id":"1.230180132","rc":[{"atb":[[5.9,0.05]],"id":53826530}],"con":true,"img":false}]}
{"op":"mcm","clk":"11541432812","pt":1719505697849,"mc":[{"id":"1.230180132","rc":[{"atl":[[6.4,0]],"id":66314580}],"con":true,"img":false}]}
{"op":"mcm","clk":"11541432832","pt":1719505698057,"mc":[{"id":"1.230180132","rc":[{"atl":[[1000,0.19]],"id":66314580}],"con":true,"img":false}]}
{"op":"mcm","clk":"11541432841","pt":1719505698161,"mc":[{"id":"1.230180132","rc":[{"atl":[[1000,0]],"id":66314580}],"con":true,"img":false}]}
{"op":"mcm","clk":"11541432852","pt":1719505698267,"mc":[{"id":"1.230180132","rc":[{"atl":[[6.4,0.19]],"id":66314580}],"con":true,"img":false}]}
{"op":"mcm","clk":"11541433253","pt":1719505702867,"mc":[{"id":"1.230180132","rc":[{"atl":[[5.8,1.45]],"id":66314580}],"con":true,"img":false}]}
{"op":"mcm","clk":"11541433276","pt":1719505703077,"mc":[{"id":"1.230180132","rc":[{"atl":[[6.8,0]],"id":66314580}],"con":true,"img":false}]}
{"op":"mcm","clk":"11541433285","pt":1719505703182,"mc":[{"id":"1.230180132","rc":[{"atl":[[1000,0.84]],"id":67130716}],"con":true,"img":false}]}
{"op":"mcm","clk":"11541433305","pt":1719505703384,"mc":[{"id":"1.230180132","rc":[{"atl":[[5.8,0]],"id":66314580}],"con":true,"img":false}]}
{"op":"mcm","clk":"11541433323","pt":1719505703544,"mc":[{"id":"1.230180132","rc":[{"atb":[[6,0]],"id":53826530}],"con":true,"img":false}]}
{"op":"mcm","clk":"11541433334","pt":1719505703649,"mc":[{"id":"1.230180132","rc":[{"atb":[[6.4,1.32]],"id":53826530}],"con":true,"img":false}]}
{"op":"mcm","clk":"11541433358","pt":1719505703961,"mc":[{"id":"1.230180132","rc":[{"atl":[[6.6,0.05]],"id":66314580}],"con":true,"img":false}]}
{"op":"mcm","clk":"11541433402","pt":1719505704476,"mc":[{"id":"1.230180132","rc":[{"atl":[[5.7,1.48]],"id":66314580}],"con":true,"img":false}]}
{"op":"mcm","clk":"11541433412","pt":1719505704580,"mc":[{"id":"1.230180132","rc":[{"atb":[[10,0.91],[10.5,0]],"id":67130716},{"atl":[[1000,0.09]],"id":67130716},{"trd":[[10,8.17],[10.5,1.81]],"ltp":10.0,"tv":9.98,"id":67130716}],"con":true,"img":false}]}
{"op":"mcm","clk":"11541433430","pt":1719505704785,"mc":[{"id":"1.230180132","rc":[{"atl":[[6.4,1.64]],"id":66314580}],"con":true,"img":false}]}
{"op":"mcm","clk":"11541433439","pt":1719505704893,"mc":[{"id":"1.230180132","rc":[{"atb":[[6.4,1.32]],"id":67487134}],"con":true,"img":false}]}
{"op":"mcm","clk":"11541433452","pt":1719505704957,"mc":[{"id":"1.230180132","rc":[{"atl":[[5.9,0]],"id":66314580}],"con":true,"img":false}]}
{"op":"mcm","clk":"11541433464","pt":1719505705048,"mc":[{"id":"1.230180132","rc":[{"atb":[[6.2,0]],"id":67487134},{"atb":[[3,0]],"id":66314580},{"atl":[[5.6,0.01]],"id":66314580},{"atb":[[5.9,0]],"id":53826530},{"atb":[[4,0]],"id":70086038},{"atb":[[3.35,0]],"id":64618726}],"con":true,"img":false}]}
{"op":"mcm","clk":"11541433473","pt":1719505705155,"mc":[{"id":"1.230180132","rc":[{"atb":[[4.1,2.06]],"id":70086038}],"con":true,"img":false}]}
{"op":"mcm","clk":"11541433485","pt":1719505705267,"mc":[{"id":"1.230180132","rc":[{"atb":[[2.72,12.56],[2.6,1.01]],"id":70086038},{"atb":[[1.09,1]],"id":67130716},{"atl":[[1000,0.1]],"id":67130716}],"con":true,"img":false}]}
{"op":"mcm","clk":"11541433506","pt":1719505705463,"mc":[{"id":"1.230180132","rc":[{"atb":[[1.09,0.24]],"id":67130716},{"atl":[[1000,0.09]],"id":67130716}],"con":true,"img":false}]}
{"op":"mcm","clk":"11541433518","pt":1719505705564,"mc":[{"id":"1.230180132","rc":[{"atl":[[100,0.85]],"id":67130716}],"con":true,"img":false}]}
{"op":"mcm","clk":"11541433528","pt":1719505705670,"mc":[{"id":"1.230180132","rc":[{"atb":[[1.09,0]],"id":67130716}],"con":true,"img":false}]}
{"op":"mcm","clk":"11541433539","pt":1719505705769,"mc":[{"id":"1.230180132","rc":[{"atb":[[5.1,0.24]],"id":67130716},{"atl":[[1000,0]],"id":67130716}],"con":true,"img":false}]}
{"op":"mcm","clk":"11541433550","pt":1719505705873,"mc":[{"id":"1.230180132","rc":[{"atl":[[95,0.09]],"id":67130716}],"con":true,"img":false}]}
{"op":"mcm","clk":"11541433561","pt":1719505705980,"mc":[{"id":"1.230180132","rc":[{"atb":[[4.2,0.84]],"id":70086038}],"con":true,"img":false}]}
{"op":"mcm","clk":"11541433579","pt":1719505706180,"mc":[{"id":"1.230180132","rc":[{"atb":[[6.4,0],[5.6,1.32]],"id":53826530}],"con":true,"img":false}]}
{"op":"mcm","clk":"11541433607","pt":1719505706499,"mc":[{"id":"1.230180132","rc":[{"atb":[[4,2.06]],"id":70086038}],"con":true,"img":false}]}
{"op":"mcm","clk":"11541433647","pt":1719505706861,"mc":[{"id":"1.230180132","rc":[{"atb":[[6.4,0]],"id":67487134}],"con":true,"img":false}]}
{"op":"mcm","clk":"11541433667","pt":1719505707081,"mc":[{"id":"1.230180132","rc":[{"atb":[[4.1,0]],"id":70086038}],"con":true,"img":false}]}
{"op":"mcm","clk":"11541433677","pt":1719505707181,"mc":[{"id":"1.230180132","rc":[{"atb":[[6.2,1.32]],"id":67487134}],"con":true,"img":false}]}
{"op":"mcm","clk":"11541433712","pt":1719505707488,"mc":[{"id":"1.230180132","rc":[{"atb":[[4,0],[4.2,2.86]],"id":70086038}],"con":true,"img":false}]}
{"op":"mcm","clk":"11541433824","pt":1719505708676,"mc":[{"id":"1.230180132","rc":[{"atb":[[2.42,2.09]],"id":67487134},{"atb":[[2.38,0]],"id":66314580},{"atb":[[2.38,0]],"id":53826530}],"con":true,"img":false}]}
{"op":"mcm","clk":"11541433852","pt":1719505708984,"mc":[{"id":"1.230180132","rc":[{"atb":[[2.58,3.38]],"id":66314580}],"con":true,"img":false}]}
{"op":"mcm","clk":"11541433954","pt":1719505710067,"mc":[{"id":"1.230180132","rc":[{"atb":[[2.58,0]],"id":66314580}],"con":true,"img":false}]}
{"op":"mcm","clk":"11541434079","pt":1719505711459,"mc":[{"id":"1.230180132","rc":[{"atl":[[130,0.84]],"id":53826530}],"con":true,"img":false}]}
{"op":"mcm","clk":"11541434092","pt":1719505711564,"mc":[{"id":"1.230180132","rc":[{"atb":[[6.2,0]],"id":53826530}],"con":true,"img":false}]}
{"op":"mcm","clk":"11541434120","pt":1719505711878,"mc":[{"id":"1.230180132","rc":[{"atb":[[1.1,1]],"id":53826530},{"atl":[[1000,0.01]],"id":53826530}],"con":true,"img":false}]}
{"op":"mcm","clk":"11541434132","pt":1719505711973,"mc":[{"id":"1.230180132","rc":[{"atl":[[1000,0]],"id":53826530}],"con":true,"img":false}]}
{"op":"mcm","clk":"11541434140","pt":1719505712082,"mc":[{"id":"1.230180132","rc":[{"atb":[[1.1,0.21]],"id":53826530},{"atl":[[130,0.85]],"id":53826530}],"con":true,"img":false}]}
{"op":"mcm","clk":"11541434156","pt":1719505712283,"mc":[{"id":"1.230180132","rc":[{"atb":[[1.1,0]],"id":53826530}],"con":true,"img":false}]}
{"op":"mcm","clk":"11541434165","pt":1719505712384,"mc":[{"id":"1.230180132","rc":[{"atb":[[5.7,0.21]],"id":53826530}],"con":true,"img":false}]}
{"op":"mcm","clk":"11541434255","pt":1719505713375,"mc":[{"id":"1.230180132","rc":[{"atl":[[6.4,1.45]],"id":66314580}],"con":true,"img":false}]}
{"op":"mcm","clk":"11541434283","pt":1719505713678,"mc":[{"id":"1.230180132","rc":[{"atl":[[1000,0.22],[6.2,1.48],[5.7,0]],"id":66314580}],"con":true,"img":false}]}
{"op":"mcm","clk":"11541434307","pt":1719505713884,"mc":[{"id":"1.230180132","rc":[{"atl":[[1000,0]],"id":66314580}],"con":true,"img":false}]}
{"op":"mcm","clk":"11541434312","pt":1719505713986,"mc":[{"id":"1.230180132","rc":[{"atl":[[5.6,0.23]],"id":66314580}],"con":true,"img":false}]}
{"op":"mcm","clk":"11541434355","pt":1719505714460,"mc":[{"id":"1.230180132","rc":[{"atl":[[6,0.84]],"id":66314580}],"con":true,"img":false}]}
{"op":"mcm","clk":"11541434887","pt":1719505720790,"mc":[{"id":"1.230180132","rc":[{"atl":[[100,0.84]],"id":67130716}],"con":true,"img":false}]}
{"op":"mcm","clk":"11541434918","pt":1719505721092,"mc":[{"id":"1.230180132","rc":[{"atb":[[5.1,0]],"id":67130716}],"con":true,"img":false}]}
{"op":"mcm","clk":"11541434961","pt":1719505721559,"mc":[{"id":"1.230180132","rc":[{"spn":14.1,"spf":"NaN","id":67487134},{"spn":5.91,"spf":11.0,"id":66314580},{"spn":67.85,"spf":"NaN","id":53826530},{"spn":13.1,"spf":"NaN","id":70086038},{"spn":2.68,"spf":1.0,"id":64618726},{"atb":[[1.09,1]],"id":67130716},{"atl":[[1000,0.01]],"id":67130716},{"spn":52.5,"spf":"NaN","id":67130716}],"con":true,"img":false}]}
{"op":"mcm","clk":"11541434979","pt":1719505721770,"mc":[{"id":"1.230180132","rc":[{"atb":[[1.09,0.24]],"id":67130716},{"atl":[[1000,0]],"id":67130716}],"con":true,"img":false}]}
{"op":"mcm","clk":"11541434988","pt":1719505721871,"mc":[{"id":"1.230180132","rc":[{"atb":[[2.6,0]],"id":70086038},{"atl":[[100,0.85]],"id":67130716}],"con":true,"img":false}]}
{"op":"mcm","clk":"11541435000","pt":1719505721975,"mc":[{"id":"1.230180132","rc":[{"atb":[[1.09,0]],"id":67130716}],"con":true,"img":false}]}
{"op":"mcm","clk":"11541435010","pt":1719505722073,"mc":[{"id":"1.230180132","rc":[{"atb":[[5.1,0.24]],"id":67130716}],"con":true,"img":false}]}
{"op":"mcm","clk":"11541435325","pt":1719505725589,"mc":[{"id":"1.230180132","rc":[{"atb":[[5.1,0]],"id":67487134},{"atb":[[2.6,0]],"id":66314580},{"atl":[[6.6,0]],"id":66314580}],"con":true,"img":false}]}
{"op":"mcm","clk":"11541435380","pt":1719505726110,"mc":[{"id":"1.230180132","rc":[{"atb":[[2.42,11.5]],"id":66314580}],"con":true,"img":false}]}
{"op":"mcm","clk":"11541435399","pt":1719505726270,"mc":[{"id":"1.230180132","rc":[{"atb":[[2.74,6.81]],"id":70086038}],"con":true,"img":false}]}
{"op":"mcm","clk":"11541435412","pt":1719505726372,"mc":[{"id":"1.230180132","rc":[{"atb":[[2.16,5.45]],"id":53826530}],"con":true,"img":false}]}
{"op":"mcm","clk":"11541435423","pt":1719505726475,"mc":[{"id":"1.230180132","rc":[{"atb":[[2.46,8.11]],"id":67487134},{"atb":[[2.52,2.09]],"id":66314580}],"con":true,"img":false}]}
{"op":"mcm","clk":"11541435446","pt":1719505726678,"mc":[{"id":"1.230180132","rc":[{"atb":[[1.54,11.7]],"id":66314580}],"con":true,"img":false}]}
{"op":"mcm","clk":"11541435456","pt":1719505726787,"mc":[{"id":"1.230180132","rc":[{"atb":[[2.42,8.34]],"id":53826530}],"con":true,"img":false}]}
{"op":"mcm","clk":"11541435492","pt":1719505727201,"mc":[{"id":"1.230180132","rc":[{"atl":[[130,0.84]],"id":53826530}],"con":true,"img":false}]}
{"op":"mcm","clk":"11541435512","pt":1719505727400,"mc":[{"id":"1.230180132","rc":[{"atb":[[2.16,5.45]],"id":67487134}],"con":true,"img":false}]}
{"op":"mcm","clk":"11541435533","pt":1719505727604,"mc":[{"id":"1.230180132","rc":[{"atb":[[5.7,0]],"id":53826530}],"con":true,"img":false}]}
{"op":"mcm","clk":"11541435564","pt":1719505727886,"mc":[{"id":"1.230180132","rc":[{"atb":[[1.1,1]],"id":53826530},{"atl":[[1000,0.01]],"id":53826530}],"con":true,"img":false}]}
{"op":"mcm","clk":"11541435586","pt":1719505728087,"mc":[{"id":"1.230180132","rc":[{"atl":[[1000,0]],"id":53826530}],"con":true,"img":false}]}
{"op":"mcm","clk":"11541435593","pt":1719505728184,"mc":[{"id":"1.230180132","rc":[{"atb":[[1.1,0.21]],"id":53826530},{"atl":[[130,0.85]],"id":53826530}],"con":true,"img":false}]}
{"op":"mcm","clk":"11541435606","pt":1719505728394,"mc":[{"id":"1.230180132","rc":[{"atb":[[1.1,0]],"id":53826530}],"con":true,"img":false}]}
{"op":"mcm","clk":"11541435615","pt":1719505728494,"mc":[{"id":"1.230180132","rc":[{"atb":[[5.7,0.21]],"id":53826530}],"con":true,"img":false}]}
{"op":"mcm","clk":"11541435669","pt":1719505729182,"mc":[{"id":"1.230180132","rc":[{"atl":[[5.6,0.01]],"id":66314580}],"con":true,"img":false}]}
{"op":"mcm","clk":"11541435687","pt":1719505729401,"mc":[{"id":"1.230180132","rc":[{"atl":[[1000,0.2]],"id":66314580}],"con":true,"img":false}]}
{"op":"mcm","clk":"11541435707","pt":1719505729587,"mc":[{"id":"1.230180132","rc":[{"atl":[[1000,0]],"id":66314580}],"con":true,"img":false}]}
{"op":"mcm","clk":"11541435717","pt":1719505729693,"mc":[{"id":"1.230180132","rc":[{"atl":[[5.9,0.2]],"id":66314580}],"con":true,"img":false}]}
{"op":"mcm","clk":"11541436125","pt":1719505734388,"mc":[{"id":"1.230180132","rc":[{"atb":[[6.2,0]],"id":67487134},{"atl":[[6.2,3.07]],"id":67487134},{"trd":[[6.2,2.64]],"ltp":6.2,"tv":2.64,"id":67487134},{"atb":[[2.98,0]],"id":66314580},{"atl":[[2.98,8.13]],"id":66314580},{"trd":[[2.98,2]],"ltp":2.98,"tv":2.0,"id":66314580},{"atb":[[4.2,0]],"id":70086038},{"atl":[[4.2,3.62]],"id":70086038},{"trd":[[4.2,5.72]],"ltp":4.2,"tv":5.72,"id":70086038}],"con":true,"img":false}]}
{"op":"mcm","clk":"11541436137","pt":1719505734489,"mc":[{"id":"1.230180132","rc":[{"atl":[[40,2.56],[6.2,0]],"id":67487134},{"trd":[[6.2,8.78]],"ltp":6.2,"tv":8.78,"id":67487134},{"atl":[[2.98,0.01]],"id":66314580},{"trd":[[2.98,18.24]],"ltp":2.98,"tv":18.24,"id":66314580},{"atl":[[8,7.24],[24,1.63],[4.2,0]],"id":70086038},{"trd":[[4.2,12.96]],"ltp":4.2,"tv":12.96,"id":70086038}],"con":true,"img":false}]}
{"op":"mcm","clk":"11541436148","pt":1719505734626,"mc":[{"id":"1.230180132","rc":[{"atb":[[6.2,3.07]],"id":67487134},{"atl":[[140,0]],"id":67487134},{"atb":[[2.54,12],[2.56,0],[2.9,1]],"id":66314580},{"atl":[[20,4.44]],"id":64618726}],"con":true,"img":false}]}
{"op":"mcm","clk":"11541436159","pt":1719505734696,"mc":[{"id":"1.230180132","rc":[{"atb":[[4.9,1.77]],"id":67487134},{"atb":[[4.6,1.76]],"id":53826530},{"atb":[[2.76,1.74]],"id":70086038},{"atb":[[2.5,1.74]],"id":64618726},{"atb":[[3.65,1.73]],"id":67130716}],"con":true,"img":false}]}
{"op":"mcm","clk":"11541436176","pt":1719505734902,"mc":[{"id":"1.230180132","rc":[{"atb":[[2.58,0.84],[2.56,1.15]],"id":66314580},{"atb":[[2.74,7.96]],"id":70086038},{"atl":[[7.8,4.1]],"id":70086038},{"atl":[[19,0],[1000,0.84]],"id":64618726},{"atb":[[3.6,5.73]],"id":67130716}],"con":true,"img":false}]}
{"op":"mcm","clk":"11541436197","pt":1719505735106,"mc":[{"id":"1.230180132","rc":[{"atl":[[24,0]],"id":70086038}],"con":true,"img":false}]}
{"op":"mcm","clk":"11541436209","pt":1719505735207,"mc":[{"id":"1.230180132","rc":[{"atb":[[6.2,0]],"id":67487134},{"atl":[[1000,0.44]],"id":64618726}],"con":true,"img":false}]}
{"op":"mcm","clk":"11541436217","pt":1719505735311,"mc":[{"id":"1.230180132","rc":[{"atb":[[2.56,2.86]],"id":66314580},{"atl":[[7.6,0.79]],"id":70086038},{"atl":[[20,4.11]],"id":64618726}],"con":true,"img":false}]}
{"op":"mcm","clk":"11541436231","pt":1719505735479,"mc":[{"id":"1.230180132","rc":[{"atl":[[1000,0.28]],"id":67487134},{"atl":[[1000,0.15]],"id":70086038}],"con":true,"img":false}]}
{"op":"mcm","clk":"11541436240","pt":1719505735584,"mc":[{"id":"1.230180132","rc":[{"atl":[[1000,0]],"id":64618726}],"con":true,"img":false}]}
{"op":"mcm","clk":"11541436249","pt":1719505735686,"mc":[{"id":"1.230180132","rc":[{"atl":[[1000,0.23]],"id":67487134},{"atl":[[1000,0]],"id":70086038},{"atl":[[19.5,1.29]],"id":64618726}],"con":true,"img":false}]}
{"op":"mcm","clk":"11541436256","pt":1719505735788,"mc":[{"id":"1.230180132","rc":[{"atl":[[22,0.43]],"id":67487134},{"atl":[[7.6,0.94]],"id":70086038}],"con":true,"img":false}]}
{"op":"mcm","clk":"11541436263","pt":1719505735891,"mc":[{"id":"1.230180132","rc":[{"atl":[[7.6,0.59]],"id":70086038}],"con":true,"img":false}]}
{"op":"mcm","clk":"11541436363","pt":1719505737124,"mc":[{"id":"1.230180132","rc":[{"atl":[[100,0.84]],"id":67130716}],"con":true,"img":false}]}
{"op":"mcm","clk":"11541436381","pt":1719505737282,"mc":[{"id":"1.230180132","rc":[{"atb":[[5.1,0]],"id":67130716}],"con":true,"img":false}]}
{"op":"mcm","clk":"11541436434","pt":1719505737900,"mc":[{"id":"1.230180132","rc":[{"atb":[[4.6,1],[6,0]],"id":67487134},{"atl":[[22,1.43],[23,0]],"id":67487134},{"atb":[[2.9,0],[2.46,1]],"id":66314580},{"atb":[[2.98,1]],"id":70086038},{"atl":[[7,1]],"id":70086038},{"atb":[[4.6,1]],"id":67130716},{"atl":[[14.5,1]],"id":67130716}],"con":true,"img":false}]}
{"op":"mcm","clk":"11541436446","pt":1719505738002,"mc":[{"id":"1.230180132","rc":[{"atb":[[2.56,5.72]],"id":66314580},{"atb":[[2.62,1]],"id":64618726},{"atl":[[5.7,1]],"id":64618726}],"con":true,"img":false}]}
{"op":"mcm","clk":"11541436459","pt":1719505738104,"mc":[{"id":"1.230180132","rc":[{"atb":[[4.8,0],[3.95,8.12]],"id":67487134},{"atb":[[2.54,0]],"id":66314580},{"atl":[[6.2,3.02]],"id":66314580},{"atb":[[4.5,0],[5,3]],"id":53826530},{"atb":[[2.76,6.29]],"id":70086038},{"atl":[[8,8.24],[7.6,2.17],[7,0]],"id":70086038},{"atb":[[3.85,5.74],[3.55,6]],"id":67130716},{"atl":[[18,1],[14.5,0]],"id":67130716}],"con":true,"img":false}]}
{"op":"mcm","clk":"11541436470","pt":1719505738210,"mc":[{"id":"1.230180132","rc":[{"atb":[[1.09,1]],"id":67130716}],"con":true,"img":false}]}
{"op":"mcm","clk":"11541436480","pt":1719505738314,"mc":[{"id":"1.230180132","rc":[{"atb":[[4.9,2],[3.95,0]],"id":67487134}],"con":true,"img":false}]}
{"op":"mcm","clk":"11541436488","pt":1719505738414,"mc":[{"id":"1.230180132","rc":[{"atb":[[4.8,1.77]],"id":67487134},{"atb":[[2.56,4.01]],"id":66314580},{"atb":[[1.09,0.24]],"id":67130716}],"con":true,"img":false}]}
{"op":"mcm","clk":"11541436497","pt":1719505738524,"mc":[{"id":"1.230180132","rc":[{"atb":[[4.8,7.77]],"id":67487134}],"con":true,"img":false}]}
{"op":"mcm","clk":"11541436507","pt":1719505738579,"mc":[{"id":"1.230180132","rc":[{"atb":[[4.9,0]],"id":67487134},{"atb":[[4.8,1],[2.74,6.81]],"id":70086038},{"atl":[[7.8,0.84]],"id":70086038},{"atb":[[3.35,1]],"id":64618726},{"atb":[[1.09,0]],"id":67130716}],"con":true,"img":false}]}
{"op":"mcm","clk":"11541436517","pt":1719505738688,"mc":[{"id":"1.230180132","rc":[{"atb":[[2.88,6.81],[3.95,0],[2.76,7.44]],"id":70086038},{"atb":[[3.3,0],[2.62,3],[2.46,0]],"id":64618726},{"atb":[[5.1,0.24]],"id":67130716}],"con":true,"img":false}]}
{"op":"mcm","clk":"11541436525","pt":1719505738788,"mc":[{"id":"1.230180132","rc":[{"atb":[[2.72,0]],"id":70086038},{"atl":[[7.4,3.42]],"id":70086038}],"con":true,"img":false}]}
{"op":"mcm","clk":"11541436535","pt":1719505738894,"mc":[{"id":"1.230180132","rc":[{"atb":[[2.44,0]],"id":67487134},{"atb":[[2.4,0]],"id":66314580},{"atb":[[2.4,0]],"id":53826530},{"atl":[[7.6,1.73]],"id":70086038}],"con":true,"img":false}]}
{"op":"mcm","clk":"11541436544","pt":1719505738992,"mc":[{"id":"1.230180132","rc":[{"atl":[[1000,0.44]],"id":70086038}],"con":true,"img":false}]}
{"op":"mcm","clk":"11541436584","pt":1719505739403,"mc":[{"id":"1.230180132","rc":[{"atl":[[7.8,0]],"id":70086038}],"con":true,"img":false}]}
{"op":"mcm","clk":"11541436605","pt":1719505739605,"mc":[{"id":"1.230180132","rc":[{"atl":[[8,1],[8.6,6.86]],"id":70086038}],"con":true,"img":false}]}
{"op":"mcm","clk":"11541436614","pt":1719505739708,"mc":[{"id":"1.230180132","rc":[{"atl":[[140,2],[40,0]],"id":67487134}],"con":true,"img":false}]}
{"op":"mcm","clk":"11541436771","pt":1719505741236,"mc":[{"id":"1.230180132","rc":[{"atl":[[7.6,0.15]],"id":70086038}],"con":true,"img":false}]}
{"op":"mcm","clk":"11541436794","pt":1719505741416,"mc":[{"id":"1.230180132","rc":[{"atb":[[1.01,52.86]],"id":66314580},{"atl":[[6,1.84]],"id":66314580},{"atb":[[6.2,1]],"id":53826530},{"atb":[[2.9,4.21],[4.2,1]],"id":70086038},{"atb":[[2.64,1]],"id":64618726},{"atl":[[100,1.84]],"id":67130716}],"con":true,"img":false}]}
{"op":"mcm","clk":"11541436815","pt":1719505741616,"mc":[{"id":"1.230180132","rc":[{"atl":[[5.9,1.25]],"id":66314580},{"atb":[[5,1],[5.7,2.21]],"id":53826530},{"atb":[[3.85,0],[4.4,5.74]],"id":67130716},{"atl":[[17.5,1],[18,0]],"id":67130716}],"con":true,"img":false}]}
{"op":"mcm","clk":"11541436826","pt":1719505741715,"mc":[{"id":"1.230180132","rc":[{"atb":[[2.58,1.84]],"id":66314580},{"atl":[[9.4,4.43]],"id":70086038},{"atl":[[5.6,1],[5.7,0]],"id":64618726}],"con":true,"img":false}]}
{"op":"mcm","clk":"11541436837","pt":1719505741823,"mc":[{"id":"1.230180132","rc":[{"atl":[[7.4,0],[8.6,0]],"id":70086038},{"atl":[[19,4.12]],"id":64618726},{"atl":[[100,0.84]],"id":67130716}],"con":true,"img":false}]}
{"op":"mcm","clk":"11541436848","pt":1719505741922,"mc":[{"id":"1.230180132","rc":[{"atb":[[4.6,0]],"id":53826530},{"atb":[[2.76,5.7]],"id":70086038},{"atl":[[7.2,0.84]],"id":70086038},{"atl":[[20,2.11]],"id":64618726}],"con":true,"img":false}]}
{"op":"mcm","clk":"11541436859","pt":1719505741984,"mc":[{"id":"1.230180132","rc":[{"atb":[[2.6,6.34]],"id":66314580},{"atb":[[2.92,1.74]],"id":70086038},{"atl":[[7.2,4.37]],"id":70086038},{"atl":[[75,1]],"id":67130716}],"con":true,"img":false}]}
{"op":"mcm","clk":"11541436895","pt":1719505742104,"mc":[{"id":"1.230180132","rc":[{"atb":[[2.62,4.02],[2.56,0]],"id":66314580},{"atb":[[2.76,4.55]],"id":70086038}],"con":true,"img":false}]}
{"op":"mcm","clk":"11541436905","pt":1719505742189,"mc":[{"id":"1.230180132","rc":[{"atb":[[2.44,7.15]],"id":66314580},{"atb":[[2.9,5.36]],"id":70086038}],"con":true,"img":false}]}
{"op":"mcm","clk":"11541436916","pt":1719505742308,"mc":[{"id":"1.230180132","rc":[{"atl":[[5.9,3.25],[7.2,0]],"id":66314580},{"atb":[[5.5,0],[5.2,1]],"id":53826530},{"atl":[[8.2,2],[9.4,0]],"id":70086038}],"con":true,"img":false}]}
{"op":"mcm","clk":"11541436929","pt":1719505742395,"mc":[{"id":"1.230180132","rc":[{"atb":[[2.62,4.86]],"id":66314580}],"con":true,"img":false}]}
{"op":"mcm","clk":"11541436938","pt":1719505742504,"mc":[{"id":"1.230180132","rc":[{"atb":[[2.64,1.7]],"id":66314580},{"atl":[[20,1.65]],"id":64618726}],"con":true,"img":false}]}
{"op":"mcm","clk":"11541436949","pt":1719505742604,"mc":[{"id":"1.230180132","rc":[{"atb":[[2.6,0]],"id":66314580}],"con":true,"img":false}]}
{"op":"mcm","clk":"11541436962","pt":1719505742709,"mc":[{"id":"1.230180132","rc":[{"atb":[[2.44,6]],"id":66314580}],"con":true,"img":false}]}
{"op":"mcm","clk":"11541436972","pt":1719505742801,"mc":[{"id":"1.230180132","rc":[{"atb":[[2.62,6.02]],"id":66314580},{"atl":[[18.5,0.46]],"id":64618726}],"con":true,"img":false}]}
{"op":"mcm","clk":"11541436984","pt":1719505742919,"mc":[{"id":"1.230180132","rc":[{"atl":[[5.8,0.84]],"id":66314580}],"con":true,"img":false}]}
{"op":"mcm","clk":"11541436997","pt":1719505743010,"mc":[{"id":"1.230180132","rc":[{"atb":[[2.58,0.99]],"id":66314580}],"con":true,"img":false}]}
{"op":"mcm","clk":"11541437007","pt":1719505743113,"mc":[{"id":"1.230180132","rc":[{"atb":[[2.64,0]],"id":66314580}],"con":true,"img":false}]}
{"op":"mcm","clk":"11541437035","pt":1719505743421,"mc":[{"id":"1.230180132","rc":[{"atl":[[130,0.84]],"id":53826530}],"con":true,"img":false}]}
{"op":"mcm","clk":"11541437071","pt":1719505743794,"mc":[{"id":"1.230180132","rc":[{"atb":[[5.7,2]],"id":53826530}],"con":true,"img":false}]}
{"op":"mcm","clk":"11541437091","pt":1719505743998,"mc":[{"id":"1.230180132","rc":[{"atb":[[1.11,1]],"id":53826530},{"atl":[[1000,0.01]],"id":53826530}],"con":true,"img":false}]}
{"op":"mcm","clk":"11541437122","pt":1719505744107,"mc":[{"id":"1.230180132","rc":[{"atl":[[20,0]],"id":66314580}],"con":true,"img":false}]}
{"op":"mcm","clk":"11541437130","pt":1719505744204,"mc":[{"id":"1.230180132","rc":[{"atb":[[1.11,0.19]],"id":53826530},{"atl":[[1000,0]],"id":53826530}],"con":true,"img":false}]}
{"op":"mcm","clk":"11541437137","pt":1719505744316,"mc":[{"id":"1.230180132","rc":[{"atl":[[130,0.85]],"id":53826530}],"con":true,"img":false}]}
{"op":"mcm","clk":"11541437151","pt":1719505744518,"mc":[{"id":"1.230180132","rc":[{"atb":[[1.11,0]],"id":53826530}],"con":true,"img":false}]}
{"op":"mcm","clk":"11541437158","pt":1719505744620,"mc":[{"id":"1.230180132","rc":[{"atb":[[6.4,0.19]],"id":53826530}],"con":true,"img":false}]}
{"op":"mcm","clk":"11541437182","pt":1719505744894,"mc":[{"id":"1.230180132","rc":[{"atl":[[5.9,3.05]],"id":66314580}],"con":true,"img":false}]}
{"op":"mcm","clk":"11541437191","pt":1719505745009,"mc":[{"id":"1.230180132","rc":[{"atl":[[5.9,4.68]],"id":66314580}],"con":true,"img":false}]}
{"op":"mcm","clk":"11541437217","pt":1719505745096,"mc":[{"id":"1.230180132","rc":[{"atl":[[1000,0.21]],"id":66314580}],"con":true,"img":false}]}
{"op":"mcm","clk":"11541437225","pt":1719505745200,"mc":[{"id":"1.230180132","rc":[{"atl":[[6,0.84]],"id":66314580}],"con":true,"img":false}]}
{"op":"mcm","clk":"11541437233","pt":1719505745300,"mc":[{"id":"1.230180132","rc":[{"atb":[[2.42,8.34]],"id":66314580},{"atl":[[1000,0]],"id":66314580},{"atb":[[2.48,1.02]],"id":64618726}],"con":true,"img":false}]}
{"op":"mcm","clk":"11541437242","pt":1719505745410,"mc":[{"id":"1.230180132","rc":[{"atl":[[5.8,2.05]],"id":66314580}],"con":true,"img":false}]}
{"op":"mcm","clk":"11541437274","pt":1719505745814,"mc":[{"id":"1.230180132","rc":[{"atb":[[2.98,3],[2.88,0]],"id":70086038}],"con":true,"img":false}]}
{"op":"mcm","clk":"11541437284","pt":1719505745912,"mc":[{"id":"1.230180132","rc":[{"atb":[[2.94,4.12]],"id":70086038},{"atl":[[8,2.25]],"id":70086038}],"con":true,"img":false}]}
{"op":"mcm","clk":"11541437295","pt":1719505746023,"mc":[{"id":"1.230180132","rc":[{"atl":[[6,0]],"id":66314580}],"con":true,"img":false}]}
{"op":"mcm","clk":"11541437349","pt":1719505746328,"mc":[{"id":"1.230180132","rc":[{"atb":[[2.9,4.21]],"id":70086038}],"con":true,"img":false}]}
{"op":"mcm","clk":"11541437359","pt":1719505746428,"mc":[{"id":"1.230180132","rc":[{"atb":[[2.94,5.27]],"id":70086038}],"con":true,"img":false}]}
{"op":"mcm","clk":"11541437385","pt":1719505746808,"mc":[{"id":"1.230180132","rc":[{"atb":[[2.16,11.29]],"id":67487134}],"con":true,"img":false}]}
{"op":"mcm","clk":"11541437397","pt":1719505746901,"mc":[{"id":"1.230180132","rc":[{"atb":[[1.54,24.23]],"id":66314580}],"con":true,"img":false}]}
{"op":"mcm","clk":"11541437420","pt":1719505747105,"mc":[{"id":"1.230180132","rc":[{"atl":[[20,1],[22,0.43]],"id":67487134},{"atl":[[6.4,2.45],[5.7,1.55],[7,0]],"id":66314580},{"atl":[[5.6,0],[5.7,1]],"id":64618726}],"con":true,"img":false}]}
{"op":"mcm","clk":"11541437431","pt":1719505747212,"mc":[{"id":"1.230180132","rc":[{"atb":[[3,4]],"id":70086038}],"con":true,"img":false}]}
{"op":"mcm","clk":"11541437448","pt":1719505747409,"mc":[{"id":"1.230180132","rc":[{"atl":[[8.2,0],[8.4,4.25]],"id":70086038}],"con":true,"img":false}]}
{"op":"mcm","clk":"11541437456","pt":1719505747512,"mc":[{"id":"1.230180132","rc":[{"atb":[[2.16,11.29]],"id":53826530},{"atb":[[2.94,4.12]],"id":70086038}],"con":true,"img":false}]}
{"op":"mcm","clk":"11541437466","pt":1719505747615,"mc":[{"id":"1.230180132","rc":[{"atb":[[3,5.15]],"id":70086038}],"con":true,"img":false}]}
{"op":"mcm","clk":"11541437491","pt":1719505747934,"mc":[{"id":"1.230180132","rc":[{"atb":[[2.92,0]],"id":70086038}],"con":true,"img":false}]}
{"op":"mcm","clk":"11541437501","pt":1719505748030,"mc":[{"id":"1.230180132","rc":[{"atb":[[3.05,1.74]],"id":70086038}],"con":true,"img":false}]}
{"op":"mcm","clk":"11541437709","pt":1719505750515,"mc":[{"id":"1.230180132","rc":[{"atb":[[1.25,20]],"id":67487134},{"atb":[[1.25,20]],"id":66314580},{"atb":[[1.25,20]],"id":53826530},{"atb":[[1.25,20]],"id":70086038},{"atb":[[1.25,20]],"id":64618726},{"atb":[[1.25,20]],"id":67130716}],"con":true,"img":false}]}
{"op":"mcm","clk":"11541437728","pt":1719505750722,"mc":[{"id":"1.230180132","rc":[{"atb":[[2.48,0]],"id":64618726}],"con":true,"img":false}]}
{"op":"mcm","clk":"11541437760","pt":1719505751034,"mc":[{"id":"1.230180132","rc":[{"atl":[[22,0.38]],"id":67487134},{"atl":[[7.6,0]],"id":70086038}],"con":true,"img":false}]}
{"op":"mcm","clk":"11541437864","pt":1719505751931,"mc":[{"id":"1.230180132","rc":[{"atl":[[1000,0.28]],"id":67487134}],"con":true,"img":false}]}
{"op":"mcm","clk":"11541437887","pt":1719505752100,"mc":[{"id":"1.230180132","rc":[{"atl":[[1000,0.23]],"id":67487134}],"con":true,"img":false}]}
{"op":"mcm","clk":"11541437897","pt":1719505752195,"mc":[{"id":"1.230180132","rc":[{"atl":[[19.5,0.05]],"id":67487134}],"con":true,"img":false}]}
{"op":"mcm","clk":"11541437917","pt":1719505752401,"mc":[{"id":"1.230180132","rc":[{"atl":[[140,0],[29,3.57]],"id":67487134},{"atb":[[4.8,0]],"id":70086038},{"trd":[[4.8,1.99]],"ltp":4.8,"tv":1.99,"id":70086038}],"con":true,"img":false}]}
{"op":"mcm","clk":"11541438038","pt":1719505753698,"mc":[{"id":"1.230180132","rc":[{"atb":[[4.3,1]],"id":70086038}],"con":true,"img":false}]}
{"op":"mcm","clk":"11541438057","pt":1719505753899,"mc":[{"id":"1.230180132","rc":[{"atb":[[5.1,0]],"id":67130716}],"con":true,"img":false}]}
{"op":"mcm","clk":"11541438125","pt":1719505754523,"mc":[{"id":"1.230180132","rc":[{"atb":[[1.09,1]],"id":67130716}],"con":true,"img":false}]}
{"op":"mcm","clk":"11541438137","pt":1719505754627,"mc":[{"id":"1.230180132","rc":[{"atb":[[1.09,0.24]],"id":67130716}],"con":true,"img":false}]}
{"op":"mcm","clk":"11541438147","pt":1719505754723,"mc":[{"id":"1.230180132","rc":[{"atb":[[1.09,0]],"id":67130716}],"con":true,"img":false}]}
{"op":"mcm","clk":"11541438158","pt":1719505754827,"mc":[{"id":"1.230180132","rc":[{"atb":[[5.1,0.24]],"id":67130716}],"con":true,"img":false}]}
{"op":"mcm","clk":"11541438237","pt":1719505755713,"mc":[{"id":"1.230180132","rc":[{"atl":[[7,1.05]],"id":70086038}],"con":true,"img":false}]}
{"op":"mcm","clk":"11541438281","pt":1719505756227,"mc":[{"id":"1.230180132","rc":[{"atl":[[7.2,0.84]],"id":70086038}],"con":true,"img":false}]}
{"op":"mcm","clk":"11541438333","pt":1719505756803,"mc":[{"id":"1.230180132","rc":[{"atl":[[5.9,3.63]],"id":66314580}],"con":true,"img":false}]}
{"op":"mcm","clk":"11541438369","pt":1719505757218,"mc":[{"id":"1.230180132","rc":[{"atb":[[2.58,0]],"id":66314580}],"con":true,"img":false}]}
{"op":"mcm","clk":"11541438477","pt":1719505758406,"mc":[{"id":"1.230180132","rc":[{"atb":[[2.38,3.16]],"id":66314580},{"atb":[[2.36,6.54]],"id":64618726}],"con":true,"img":false}]}
{"op":"mcm","clk":"11541438501","pt":1719505758626,"mc":[{"id":"1.230180132","rc":[{"atb":[[2.38,5.15]],"id":64618726}],"con":true,"img":false}]}
{"op":"mcm","clk":"11541438522","pt":1719505758832,"mc":[{"id":"1.230180132","rc":[{"atb":[[2.22,7.77]],"id":66314580}],"con":true,"img":false}]}
{"op":"mcm","clk":"11541438536","pt":1719505759037,"mc":[{"id":"1.230180132","rc":[{"atb":[[3.15,4.41]],"id":67487134}],"con":true,"img":false}]}
{"op":"mcm","clk":"11541438557","pt":1719505759236,"mc":[{"id":"1.230180132","rc":[{"atb":[[2.4,6.21]],"id":66314580}],"con":true,"img":false}]}
{"op":"mcm","clk":"11541438586","pt":1719505759543,"mc":[{"id":"1.230180132","rc":[{"atb":[[2.62,4.86]],"id":66314580},{"atl":[[130,0.84]],"id":53826530}],"con":true,"img":false}]}
{"op":"mcm","clk":"11541438601","pt":1719505759706,"mc":[{"id":"1.230180132","rc":[{"atb":[[2.62,0.84],[2.52,11.83]],"id":66314580}],"con":true,"img":false}]}
{"op":"mcm","clk":"11541438611","pt":1719505759812,"mc":[{"id":"1.230180132","rc":[{"atb":[[6.4,0]],"id":53826530}],"con":true,"img":false}]}
{"op":"mcm","clk":"11541438621","pt":1719505759920,"mc":[{"id":"1.230180132","rc":[{"atb":[[2.54,1.7]],"id":66314580}],"con":true,"img":false}]}
{"op":"mcm","clk":"11541438644","pt":1719505760125,"mc":[{"id":"1.230180132","rc":[{"atb":[[2.54,2.91]],"id":66314580},{"atb":[[1.11,1]],"id":53826530},{"atl":[[1000,0.01]],"id":53826530}],"con":true,"img":false}]}
{"op":"mcm","clk":"11541438666","pt":1719505760333,"mc":[{"id":"1.230180132","rc":[{"atb":[[1.11,0.19]],"id":53826530},{"atl":[[1000,0]],"id":53826530}],"con":true,"img":false}]}
{"op":"mcm","clk":"11541438677","pt":1719505760441,"mc":[{"id":"1.230180132","rc":[{"atb":[[2.62,0]],"id":66314580},{"atl":[[130,0.85]],"id":53826530}],"con":true,"img":false}]}
{"op":"mcm","clk":"11541438685","pt":1719505760531,"mc":[{"id":"1.230180132","rc":[{"atb":[[1.11,0]],"id":53826530}],"con":true,"img":false}]}
{"op":"mcm","clk":"11541438697","pt":1719505760633,"mc":[{"id":"1.230180132","rc":[{"atl":[[5.8,1.84]],"id":66314580},{"atb":[[6.4,0.19]],"id":53826530}],"con":true,"img":false}]}
{"op":"mcm","clk":"11541438727","pt":1719505760942,"mc":[{"id":"1.230180132","rc":[{"atb":[[2.56,0.84]],"id":66314580}],"con":true,"img":false}]}
{"op":"mcm","clk":"11541438739","pt":1719505761006,"mc":[{"id":"1.230180132","rc":[{"atb":[[2.56,7.19]],"id":66314580},{"atl":[[1000,0.22]],"id":66314580}],"con":true,"img":false}]}
{"op":"mcm","clk":"11541438756","pt":1719505761211,"mc":[{"id":"1.230180132","rc":[{"atl":[[1000,0]],"id":66314580}],"con":true,"img":false}]}
{"op":"mcm","clk":"11541438768","pt":1719505761313,"mc":[{"id":"1.230180132","rc":[{"atl":[[5.6,0.23]],"id":66314580}],"con":true,"img":false}]}
{"op":"mcm","clk":"11541438781","pt":1719505761419,"mc":[{"id":"1.230180132","rc":[{"atb":[[2.54,1.7]],"id":66314580}],"con":true,"img":false}]}
{"op":"mcm","clk":"11541438789","pt":1719505761514,"mc":[{"id":"1.230180132","rc":[{"atb":[[2.56,8.4]],"id":66314580}],"con":true,"img":false}]}
{"op":"mcm","clk":"11541438811","pt":1719505761724,"mc":[{"id":"1.230180132","rc":[{"atb":[[2.54,0]],"id":66314580}],"con":true,"img":false}]}
{"op":"mcm","clk":"11541438822","pt":1719505761831,"mc":[{"id":"1.230180132","rc":[{"atb":[[2.58,1.7]],"id":66314580}],"con":true,"img":false}]}
{"op":"mcm","clk":"11541438838","pt":1719505761937,"mc":[{"id":"1.230180132","rc":[{"atl":[[5.6,1.07]],"id":66314580}],"con":true,"img":false}]}
{"op":"mcm","clk":"11541438858","pt":1719505762141,"mc":[{"id":"1.230180132","rc":[{"atb":[[2.56,2.05]],"id":66314580}],"con":true,"img":false}]}
{"op":"mcm","clk":"11541438878","pt":1719505762350,"mc":[{"id":"1.230180132","rc":[{"atb":[[2.6,6.34]],"id":66314580}],"con":true,"img":false}]}
{"op":"mcm","clk":"11541438902","pt":1719505762606,"mc":[{"id":"1.230180132","rc":[{"atb":[[2.56,0.84]],"id":66314580}],"con":true,"img":false}]}
{"op":"mcm","clk":"11541438913","pt":1719505762710,"mc":[{"id":"1.230180132","rc":[{"atb":[[2.6,7.55]],"id":66314580}],"con":true,"img":false}]}
{"op":"mcm","clk":"11541438937","pt":1719505763017,"mc":[{"id":"1.230180132","rc":[{"atl":[[20,0],[21,1]],"id":67487134},{"atb":[[2.56,0],[2.52,2.09]],"id":66314580},{"atl":[[6.4,1.45],[6.2,4.02]],"id":66314580},{"atl":[[8,1.25],[8.2,1],[8.4,5.25]],"id":70086038},{"atl":[[5.8,1],[5.7,0]],"id":64618726},{"atb":[[3.85,5.74],[4.4,0]],"id":67130716},{"atl":[[17.5,0],[18,1],[18.5,1],[19,1]],"id":67130716}],"con":true,"img":false}]}
{"op":"mcm","clk":"11541438945","pt":1719505763123,"mc":[{"id":"1.230180132","rc":[{"atb":[[4.8,1.77],[4.7,14.78]],"id":67487134},{"atl":[[26,4],[29,0]],"id":67487134},{"atb":[[2.46,7]],"id":66314580},{"atb":[[5.3,2.32],[5.7,0]],"id":53826530},{"atl":[[9,3.3],[8.4,1]],"id":70086038},{"atl":[[5.9,1]],"id":64618726},{"atl":[[18,3],[110,0]],"id":67130716}],"con":true,"img":false}]}
{"op":"mcm","clk":"11541438954","pt":1719505763223,"mc":[{"id":"1.230180132","rc":[{"atl":[[20,1],[21,0]],"id":67487134},{"atl":[[8.4,0]],"id":70086038},{"atb":[[3.85,0],[3,50]],"id":67130716},{"atl":[[18,2],[18.5,0],[75,0]],"id":67130716}],"con":true,"img":false}]}
{"op":"mcm","clk":"11541438964","pt":1719505763333,"mc":[{"id":"1.230180132","rc":[{"atb":[[4.3,5.74],[3,0]],"id":67130716},{"atl":[[17.5,1.44]],"id":67130716}],"con":true,"img":false}]}
{"op":"mcm","clk":"11541438987","pt":1719505763543,"mc":[{"id":"1.230180132","rc":[{"atl":[[17,1]],"id":67130716}],"con":true,"img":false}]}
{"op":"mcm","clk":"11541439004","pt":1719505763741,"mc":[{"id":"1.230180132","rc":[{"atb":[[4.8,2.97]],"id":67487134}],"con":true,"img":false}]}
{"op":"mcm","clk":"11541439025","pt":1719505763943,"mc":[{"id":"1.230180132","rc":[{"atl":[[17.5,0]],"id":67130716}],"con":true,"img":false}]}
{"op":"mcm","clk":"11541439311","pt":1719505767552,"mc":[{"id":"1.230180132","rc":[{"atl":[[19.5,0]],"id":67487134}],"con":true,"img":false}]}
{"op":"mcm","clk":"11541439331","pt":1719505767787,"mc":[{"id":"1.230180132","rc":[{"atl":[[1000,0.28]],"id":67487134}],"con":true,"img":false}]}
{"op":"mcm","clk":"11541439349","pt":1719505767990,"mc":[{"id":"1.230180132","rc":[{"atl":[[1000,0.23]],"id":67487134},{"atb":[[2.62,0.84]],"id":66314580}],"con":true,"img":false}]}
{"op":"mcm","clk":"11541439359","pt":1719505768080,"mc":[{"id":"1.230180132","rc":[{"atl":[[19.5,0.05]],"id":67487134}],"con":true,"img":false}]}
{"op":"mcm","clk":"11541439374","pt":1719505768232,"mc":[{"id":"1.230180132","rc":[{"atb":[[4.6,6.94],[4.7,6]],"id":67487134},{"atb":[[2.6,1.21]],"id":66314580},{"atl":[[18,0],[19,4]],"id":67130716}],"con":true,"img":false}]}
{"op":"mcm","clk":"11541439382","pt":1719505768333,"mc":[{"id":"1.230180132","rc":[{"atl":[[19,1],[95,2.09]],"id":67130716}],"con":true,"img":false}]}
{"op":"mcm","clk":"11541439407","pt":1719505768643,"mc":[{"id":"1.230180132","rc":[{"atb":[[2.6,0]],"id":66314580}],"con":true,"img":false}]}
{"op":"mcm","clk":"11541439414","pt":1719505768750,"mc":[{"id":"1.230180132","rc":[{"atb":[[2.46,8.21]],"id":66314580}],"con":true,"img":false}]}
{"op":"mcm","clk":"11541439431","pt":1719505768954,"mc":[{"id":"1.230180132","rc":[{"atb":[[2.58,0]],"id":66314580}],"con":true,"img":false}]}
{"op":"mcm","clk":"11541439440","pt":1719505769055,"mc":[{"id":"1.230180132","rc":[{"atb":[[2.48,1.7]],"id":66314580}],"con":true,"img":false}]}
{"op":"mcm","clk":"11541439472","pt":1719505769424,"mc":[{"id":"1.230180132","rc":[{"atb":[[2.62,0]],"id":66314580}],"con":true,"img":false}]}
{"op":"mcm","clk":"11541439481","pt":1719505769532,"mc":[{"id":"1.230180132","rc":[{"atb":[[2.42,16.44],[2.46,2.21]],"id":66314580},{"atl":[[5.7,3.25]],"id":66314580}],"con":true,"img":false}]}
{"op":"mcm","clk":"11541439496","pt":1719505769738,"mc":[{"id":"1.230180132","rc":[{"atb":[[4.8,1.77]],"id":67487134},{"atb":[[2.46,1]],"id":66314580}],"con":true,"img":false}]}
{"op":"mcm","clk":"11541439508","pt":1719505769842,"mc":[{"id":"1.230180132","rc":[{"atb":[[2.44,7.21]],"id":66314580},{"atl":[[5.5,1.05]],"id":66314580}],"con":true,"img":false}]}
{"op":"mcm","clk":"11541439516","pt":1719505769952,"mc":[{"id":"1.230180132","rc":[{"atb":[[2.54,1.02]],"id":66314580}],"con":true,"img":false}]}
{"op":"mcm","clk":"11541439527","pt":1719505770037,"mc":[{"id":"1.230180132","rc":[{"atl":[[23,4]],"id":67487134},{"atb":[[5.3,0],[5.5,2]],"id":53826530},{"atl":[[9,0],[8.6,2.05]],"id":70086038},{"atb":[[5.1,0]],"id":67130716}],"con":true,"img":false}]}
{"op":"mcm","clk":"11541439535","pt":1719505770142,"mc":[{"id":"1.230180132","rc":[{"atl":[[26,0]],"id":67487134},{"atb":[[2.48,0]],"id":66314580}],"con":true,"img":false}]}
{"op":"mcm","clk":"11541439548","pt":1719505770245,"mc":[{"id":"1.230180132","rc":[{"atb":[[2.46,2.7]],"id":66314580},{"atb":[[1.09,1]],"id":67130716}],"con":true,"img":false}]}
{"op":"mcm","clk":"11541439567","pt":1719505770451,"mc":[{"id":"1.230180132","rc":[{"atl":[[5.8,1]],"id":66314580},{"atb":[[1.09,0.24]],"id":67130716}],"con":true,"img":false}]}
{"op":"mcm","clk":"11541439585","pt":1719505770660,"mc":[{"id":"1.230180132","rc":[{"atb":[[1.09,0]],"id":67130716}],"con":true,"img":false}]}
{"op":"mcm","clk":"11541439598","pt":1719505770770,"mc":[{"id":"1.230180132","rc":[{"atb":[[5.1,0.24]],"id":67130716}],"con":true,"img":false}]}
{"op":"mcm","clk":"11541439626","pt":1719505770932,"mc":[{"id":"1.230180132","rc":[{"atl":[[7,0]],"id":70086038}],"con":true,"img":false}]}
{"op":"mcm","clk":"11541439676","pt":1719505771439,"mc":[{"id":"1.230180132","rc":[{"atl":[[6.8,1.05]],"id":70086038}],"con":true,"img":false}]}
{"op":"mcm","clk":"11541439684","pt":1719505771553,"mc":[{"id":"1.230180132","rc":[{"atl":[[7.2,0]],"id":70086038}],"con":true,"img":false}]}
{"op":"mcm","clk":"11541439882","pt":1719505773856,"mc":[{"id":"1.230180132","rc":[{"atl":[[5.9,0]],"id":64618726}],"con":true,"img":false}]}
{"op":"mcm","clk":"11541439964","pt":1719505774851,"mc":[{"id":"1.230180132","rc":[{"atb":[[2.46,0]],"id":67487134},{"atb":[[2.42,8.1]],"id":66314580},{"atb":[[2.42,0]],"id":53826530},{"atb":[[2.74,0]],"id":70086038},{"atb":[[3.6,1.17]],"id":67130716}],"con":true,"img":false}]}
{"op":"mcm","clk":"11541440032","pt":1719505775668,"mc":[{"id":"1.230180132","rc":[{"atl":[[130,0.84]],"id":53826530}],"con":true,"img":false}]}
{"op":"mcm","clk":"11541440052","pt":1719505775872,"mc":[{"id":"1.230180132","rc":[{"atb":[[6.4,0]],"id":53826530}],"con":true,"img":false}]}
{"op":"mcm","clk":"11541440067","pt":1719505776079,"mc":[{"id":"1.230180132","rc":[{"atb":[[4.4,7.48]],"id":53826530}],"con":true,"img":false}]}
{"op":"mcm","clk":"11541440088","pt":1719505776282,"mc":[{"id":"1.230180132","rc":[{"atb":[[1.11,1]],"id":53826530},{"atl":[[1000,0.01]],"id":53826530}],"con":true,"img":false}]}
{"op":"mcm","clk":"11541440108","pt":1719505776469,"mc":[{"id":"1.230180132","rc":[{"atl":[[1000,0]],"id":53826530}],"con":true,"img":false}]}
{"op":"mcm","clk":"11541440115","pt":1719505776561,"mc":[{"id":"1.230180132","rc":[{"atl":[[5.6,0.85]],"id":66314580},{"atb":[[1.11,0.19]],"id":53826530},{"atl":[[130,0.85]],"id":53826530}],"con":true,"img":false}]}
{"op":"mcm","clk":"11541440129","pt":1719505776745,"mc":[{"id":"1.230180132","rc":[{"atl":[[1000,0.23]],"id":66314580}],"con":true,"img":false}]}
{"op":"mcm","clk":"11541440135","pt":1719505776850,"mc":[{"id":"1.230180132","rc":[{"atb":[[1.04,1]],"id":66314580}],"con":true,"img":false}]}
{"op":"mcm","clk":"11541440146","pt":1719505776960,"mc":[{"id":"1.230180132","rc":[{"atl":[[1000,0]],"id":66314580}],"con":true,"img":false}]}
{"op":"mcm","clk":"11541440156","pt":1719505777055,"mc":[{"id":"1.230180132","rc":[{"atb":[[1.04,0.64]],"id":66314580},{"atl":[[5.4,0.23]],"id":66314580},{"atb":[[1.11,0]],"id":53826530}],"con":true,"img":false}]}
{"op":"mcm","clk":"11541440172","pt":1719505777157,"mc":[{"id":"1.230180132","rc":[{"atb":[[6.4,1]],"id":67487134},{"atb":[[1.04,0]],"id":66314580},{"atl":[[5.9,1.63],[5.4,2.23]],"id":66314580},{"atb":[[6.4,0.19]],"id":53826530}],"con":true,"img":false}]}
{"op":"mcm","clk":"11541440194","pt":1719505777258,"mc":[{"id":"1.230180132","rc":[{"atb":[[2.56,0.64]],"id":66314580}],"con":true,"img":false}]}
{"op":"mcm","clk":"11541440203","pt":1719505777363,"mc":[{"id":"1.230180132","rc":[{"atl":[[5.8,0]],"id":66314580}],"con":true,"img":false}]}
{"op":"mcm","clk":"11541440223","pt":1719505777570,"mc":[{"id":"1.230180132","rc":[{"atl":[[5.6,1.85]],"id":66314580}],"con":true,"img":false}]}
{"op":"mcm","clk":"11541440257","pt":1719505778008,"mc":[{"id":"1.230180132","rc":[{"atl":[[5.3,0.84],[5.6,1.01]],"id":66314580}],"con":true,"img":false}]}
{"op":"mcm","clk":"11541440277","pt":1719505778262,"mc":[{"id":"1.230180132","rc":[{"atb":[[4.4,6]],"id":53826530}],"con":true,"img":false}]}
{"op":"mcm","clk":"11541440415","pt":1719505779968,"mc":[{"id":"1.230180132","rc":[{"atb":[[1.55,21.55]],"id":66314580}],"con":true,"img":false}]}
{"op":"mcm","clk":"11541440433","pt":1719505780170,"mc":[{"id":"1.230180132","rc":[{"atb":[[2.38,0]],"id":66314580}],"con":true,"img":false}]}
{"op":"mcm","clk":"11541440442","pt":1719505780271,"mc":[{"id":"1.230180132","rc":[{"atb":[[2.92,6.17]],"id":70086038}],"con":true,"img":false}]}
{"op":"mcm","clk":"11541440449","pt":1719505780375,"mc":[{"id":"1.230180132","rc":[{"atl":[[5.7,1.7]],"id":66314580}],"con":true,"img":false}]}
{"op":"mcm","clk":"11541440460","pt":1719505780482,"mc":[{"id":"1.230180132","rc":[{"atb":[[2.34,8.84]],"id":67487134},{"atl":[[5.4,4.05]],"id":66314580}],"con":true,"img":false}]}
{"op":"mcm","clk":"11541440468","pt":1719505780581,"mc":[{"id":"1.230180132","rc":[{"atl":[[2.98,0],[5.6,0.01]],"id":66314580},{"atb":[[2.46,8.11]],"id":64618726}],"con":true,"img":false}]}
{"op":"mcm","clk":"11541440478","pt":1719505780689,"mc":[{"id":"1.230180132","rc":[{"atb":[[2.3,9.12]],"id":53826530}],"con":true,"img":false}]}
{"op":"mcm","clk":"11541440488","pt":1719505780790,"mc":[{"id":"1.230180132","rc":[{"atl":[[5.3,1.84]],"id":66314580}],"con":true,"img":false}]}
{"op":"mcm","clk":"11541440515","pt":1719505781050,"mc":[{"id":"1.230180132","rc":[{"atb":[[2.14,6.23]],"id":70086038}],"con":true,"img":false}]}
{"op":"mcm","clk":"11541440541","pt":1719505781360,"mc":[{"id":"1.230180132","rc":[{"atb":[[1.53,14.91]],"id":66314580},{"atb":[[2.16,18.1]],"id":53826530}],"con":true,"img":false}]}
{"op":"mcm","clk":"11541440569","pt":1719505781770,"mc":[{"id":"1.230180132","rc":[{"spn":12.95,"spf":"NaN","id":67487134},{"spn":5.3,"spf":11.0,"id":66314580},{"spn":68.2,"spf":"NaN","id":53826530},{"spn":5.55,"spf":"NaN","id":70086038},{"atb":[[2.54,2.09],[2.36,3.16]],"id":64618726},{"spn":2.8,"spf":1.0,"id":64618726},{"spn":13.5,"spf":"NaN","id":67130716}],"con":true,"img":false}]}
{"op":"mcm","clk":"11541440578","pt":1719505781882,"mc":[{"id":"1.230180132","rc":[{"atb":[[3.15,9.13]],"id":67487134}],"con":true,"img":false}]}
{"op":"mcm","clk":"11541440587","pt":1719505781979,"mc":[{"id":"1.230180132","rc":[{"atb":[[2.46,5.86]],"id":66314580}],"con":true,"img":false}]}
{"op":"mcm","clk":"11541440595","pt":1719505782090,"mc":[{"id":"1.230180132","rc":[{"atb":[[2.48,5]],"id":66314580},{"atb":[[2.92,12.78]],"id":70086038}],"con":true,"img":false}]}
{"op":"mcm","clk":"11541440624","pt":1719505782353,"mc":[{"id":"1.230180132","rc":[{"atb":[[2.22,16.1],[2.44,6]],"id":66314580}],"con":true,"img":false}]}
{"op":"mcm","clk":"11541440636","pt":1719505782449,"mc":[{"id":"1.230180132","rc":[{"atb":[[2.48,6.21]],"id":66314580}],"con":true,"img":false}]}
{"op":"mcm","clk":"11541440656","pt":1719505782655,"mc":[{"id":"1.230180132","rc":[{"atb":[[2.4,12.86],[2.46,4.16]],"id":66314580}],"con":true,"img":false}]}
{"op":"mcm","clk":"11541440667","pt":1719505782764,"mc":[{"id":"1.230180132","rc":[{"atb":[[2.5,1.7]],"id":66314580}],"con":true,"img":false}]}
{"op":"mcm","clk":"11541440675","pt":1719505782862,"mc":[{"id":"1.230180132","rc":[{"atb":[[2.16,25.4]],"id":53826530}],"con":true,"img":false}]}
{"op":"mcm","clk":"11541440685","pt":1719505782972,"mc":[{"id":"1.230180132","rc":[{"atb":[[2.48,3.38]],"id":64618726}],"con":true,"img":false}]}
{"op":"mcm","clk":"11541440704","pt":1719505783176,"mc":[{"id":"1.230180132","rc":[{"atl":[[19.5,0]],"id":67487134}],"con":true,"img":false}]}
{"op":"mcm","clk":"11541440711","pt":1719505783280,"mc":[{"id":"1.230180132","rc":[{"atl":[[5.2,1.52]],"id":66314580}],"con":true,"img":false}]}
{"op":"mcm","clk":"11541440720","pt":1719505783388,"mc":[{"id":"1.230180132","rc":[{"atl":[[5.3,4.88],[5.4,2.05]],"id":66314580}],"con":true,"img":false}]}
{"op":"mcm","clk":"11541440759","pt":1719505783759,"mc":[{"id":"1.230180132","rc":[{"atb":[[3.2,1]],"id":66314580}],"con":true,"img":false}]}
{"op":"mcm","clk":"11541440770","pt":1719505783850,"mc":[{"id":"1.230180132","rc":[{"atl":[[1000,0.28]],"id":67487134},{"atb":[[2.52,7.09]],"id":66314580}],"con":true,"img":false}]}
{"op":"mcm","clk":"11541440785","pt":1719505784056,"mc":[{"id":"1.230180132","rc":[{"atl":[[1000,0.23]],"id":67487134}],"con":true,"img":false}]}
{"op":"mcm","clk":"11541440795","pt":1719505784162,"mc":[{"id":"1.230180132","rc":[{"atl":[[19.5,0.05]],"id":67487134},{"atb":[[2.48,5]],"id":66314580}],"con":true,"img":false}]}
{"op":"mcm","clk":"11541440807","pt":1719505784262,"mc":[{"id":"1.230180132","rc":[{"atb":[[2.52,8.3]],"id":66314580}],"con":true,"img":false}]}
{"op":"mcm","clk":"11541440835","pt":1719505784572,"mc":[{"id":"1.230180132","rc":[{"atb":[[2.5,0]],"id":66314580}],"con":true,"img":false}]}
{"op":"mcm","clk":"11541440847","pt":1719505784678,"mc":[{"id":"1.230180132","rc":[{"atb":[[2.54,2.72]],"id":66314580}],"con":true,"img":false}]}
{"op":"mcm","clk":"11541440893","pt":1719505785149,"mc":[{"id":"1.230180132","rc":[{"atl":[[5.5,0]],"id":66314580}],"con":true,"img":false}]}
{"op":"mcm","clk":"11541440918","pt":1719505785457,"mc":[{"id":"1.230180132","rc":[{"atb":[[2.54,1.7],[2.52,7.09]],"id":66314580}],"con":true,"img":false}]}
{"op":"mcm","clk":"11541440926","pt":1719505785566,"mc":[{"id":"1.230180132","rc":[{"atb":[[2.54,2.91]],"id":66314580}],"con":true,"img":false}]}
{"op":"mcm","clk":"11541440954","pt":1719505785875,"mc":[{"id":"1.230180132","rc":[{"atb":[[5.1,0]],"id":67130716}],"con":true,"img":false}]}
{"op":"mcm","clk":"11541440964","pt":1719505785979,"mc":[{"id":"1.230180132","rc":[{"atb":[[2.54,1.7]],"id":66314580}],"con":true,"img":false}]}
{"op":"mcm","clk":"11541440974","pt":1719505786081,"mc":[{"id":"1.230180132","rc":[{"atb":[[2.52,8.3]],"id":66314580}],"con":true,"img":false}]}
{"op":"mcm","clk":"11541441008","pt":1719505786592,"mc":[{"id":"1.230180132","rc":[{"atb":[[1.09,1]],"id":67130716}],"con":true,"img":false}]}
{"op":"mcm","clk":"11541441028","pt":1719505786750,"mc":[{"id":"1.230180132","rc":[{"atl":[[6.8,0]],"id":70086038},{"atb":[[1.09,0.24]],"id":67130716}],"con":true,"img":false}]}
{"op":"mcm","clk":"11541441046","pt":1719505786962,"mc":[{"id":"1.230180132","rc":[{"atb":[[1.09,0]],"id":67130716}],"con":true,"img":false}]}
{"op":"mcm","clk":"11541441056","pt":1719505787059,"mc":[{"id":"1.230180132","rc":[{"atb":[[5.1,0.24]],"id":67130716}],"con":true,"img":false}]}
{"op":"mcm","clk":"11541441227","pt":1719505789382,"mc":[{"id":"1.230180132","rc":[{"atl":[[7.8,1.54],[1000,0.59]],"id":70086038}],"con":true,"img":false}]}
{"op":"mcm","clk":"11541441239","pt":1719505789480,"mc":[{"id":"1.230180132","rc":[{"atl":[[1000,0.44]],"id":70086038}],"con":true,"img":false}]}
{"op":"mcm","clk":"11541441248","pt":1719505789585,"mc":[{"id":"1.230180132","rc":[{"atl":[[7.8,1.69]],"id":70086038}],"con":true,"img":false}]}
{"op":"mcm","clk":"11541441277","pt":1719505789995,"mc":[{"id":"1.230180132","rc":[{"atl":[[7.6,0.84]],"id":70086038}],"con":true,"img":false}]}
{"op":"mcm","clk":"11541441445","pt":1719505791767,"mc":[{"id":"1.230180132","rc":[{"atl":[[130,0.84]],"id":53826530}],"con":true,"img":false}]}
{"op":"mcm","clk":"11541441502","pt":1719505792275,"mc":[{"id":"1.230180132","rc":[{"atl":[[5.4,1.82]],"id":66314580}],"con":true,"img":false}]}
{"op":"mcm","clk":"11541441513","pt":1719505792382,"mc":[{"id":"1.230180132","rc":[{"atb":[[6.4,0]],"id":53826530}],"con":true,"img":false}]}
{"op":"mcm","clk":"11541441523","pt":1719505792485,"mc":[{"id":"1.230180132","rc":[{"atb":[[2.56,0]],"id":66314580}],"con":true,"img":false}]}
{"op":"mcm","clk":"11541441529","pt":1719505792587,"mc":[{"id":"1.230180132","rc":[{"atb":[[4.8,1.5],[1.11,1]],"id":53826530},{"atl":[[1000,0.01]],"id":53826530}],"con":true,"img":false}]}
{"op":"mcm","clk":"11541441552","pt":1719505792792,"mc":[{"id":"1.230180132","rc":[{"atb":[[1.11,0.19]],"id":53826530},{"atl":[[1000,0]],"id":53826530}],"con":true,"img":false}]}
{"op":"mcm","clk":"11541441562","pt":1719505792895,"mc":[{"id":"1.230180132","rc":[{"atl":[[1000,0.24]],"id":66314580},{"atl":[[130,0.85]],"id":53826530}],"con":true,"img":false}]}
{"op":"mcm","clk":"11541441573","pt":1719505792998,"mc":[{"id":"1.230180132","rc":[{"atb":[[1.11,0]],"id":53826530}],"con":true,"img":false}]}
{"op":"mcm","clk":"11541441587","pt":1719505793102,"mc":[{"id":"1.230180132","rc":[{"atl":[[1000,1.08]],"id":67487134},{"atl":[[1000,0]],"id":66314580},{"atb":[[6.4,0.19]],"id":53826530}],"con":true,"img":false}]}
{"op":"mcm","clk":"11541441598","pt":1719505793164,"mc":[{"id":"1.230180132","rc":[{"atl":[[5.1,0.24]],"id":66314580}],"con":true,"img":false}]}
{"op":"mcm","clk":"11541441611","pt":1719505793268,"mc":[{"id":"1.230180132","rc":[{"atl":[[22,0]],"id":67487134}],"con":true,"img":false}]}
{"op":"mcm","clk":"11541441621","pt":1719505793370,"mc":[{"id":"1.230180132","rc":[{"atl":[[7.4,1.14]],"id":70086038}],"con":true,"img":false}]}
{"op":"mcm","clk":"11541441638","pt":1719505793578,"mc":[{"id":"1.230180132","rc":[{"atl":[[5.1,5.21]],"id":66314580}],"con":true,"img":false}]}
{"op":"mcm","clk":"11541441648","pt":1719505793682,"mc":[{"id":"1.230180132","rc":[{"atb":[[4.8,0]],"id":53826530},{"atl":[[95,2],[1000,0.84]],"id":67130716}],"con":true,"img":false}]}
{"op":"mcm","clk":"11541441666","pt":1719505793899,"mc":[{"id":"1.230180132","rc":[{"atl":[[5.3,3.88],[5.1,6.06]],"id":66314580}],"con":true,"img":false}]}
{"op":"mcm","clk":"11541441673","pt":1719505793981,"mc":[{"id":"1.230180132","rc":[{"atb":[[4.9,1.45],[5.6,0]],"id":53826530},{"atl":[[22,0]],"id":70086038}],"con":true,"img":false}]}
{"op":"mcm","clk":"11541441688","pt":1719505794103,"mc":[{"id":"1.230180132","rc":[{"atl":[[5,1]],"id":66314580}],"con":true,"img":false}]}
{"op":"mcm","clk":"11541441700","pt":1719505794188,"mc":[{"id":"1.230180132","rc":[{"atl":[[7.6,1.98]],"id":70086038},{"atl":[[1000,0.51]],"id":67130716}],"con":true,"img":false}]}
{"op":"mcm","clk":"11541441732","pt":1719505794499,"mc":[{"id":"1.230180132","rc":[{"atl":[[1000,0.68]],"id":67487134},{"atl":[[5.3,3.04]],"id":66314580},{"atb":[[6.4,1.51]],"id":53826530}],"con":true,"img":false}]}
{"op":"mcm","clk":"11541441746","pt":1719505794664,"mc":[{"id":"1.230180132","rc":[{"atl":[[5.1,1.08]],"id":66314580}],"con":true,"img":false}]}
{"op":"mcm","clk":"11541441764","pt":1719505794876,"mc":[{"id":"1.230180132","rc":[{"atl":[[7.4,0]],"id":70086038}],"con":true,"img":false}]}
{"op":"mcm","clk":"11541441775","pt":1719505794977,"mc":[{"id":"1.230180132","rc":[{"atl":[[1000,0]],"id":67130716}],"con":true,"img":false}]}
{"op":"mcm","clk":"11541441783","pt":1719505795078,"mc":[{"id":"1.230180132","rc":[{"atl":[[16.5,0.51]],"id":67130716}],"con":true,"img":false}]}
{"op":"mcm","clk":"11541441795","pt":1719505795184,"mc":[{"id":"1.230180132","rc":[{"atl":[[19,3],[95,0]],"id":67130716}],"con":true,"img":false}]}
{"op":"mcm","clk":"11541441820","pt":1719505795482,"mc":[{"id":"1.230180132","rc":[{"atl":[[1000,0.23]],"id":67487134}],"con":true,"img":false}]}
{"op":"mcm","clk":"11541441828","pt":1719505795586,"mc":[{"id":"1.230180132","rc":[{"atl":[[19,0.44]],"id":67487134}],"con":true,"img":false}]}
{"op":"mcm","clk":"11541441843","pt":1719505795792,"mc":[{"id":"1.230180132","rc":[{"atl":[[5.1,3.03]],"id":66314580},{"atl":[[7.8,0.15]],"id":70086038}],"con":true,"img":false}]}
{"op":"mcm","clk":"11541441857","pt":1719505795896,"mc":[{"id":"1.230180132","rc":[{"atl":[[7.2,1.17],[7.6,0.84]],"id":70086038}],"con":true,"img":false}]}
{"op":"mcm","clk":"11541441891","pt":1719505796159,"mc":[{"id":"1.230180132","rc":[{"atb":[[2.46,1]],"id":66314580},{"atb":[[2.14,0]],"id":70086038}],"con":true,"img":false}]}
{"op":"mcm","clk":"11541441903","pt":1719505796264,"mc":[{"id":"1.230180132","rc":[{"atl":[[4.9,1.05]],"id":66314580}],"con":true,"img":false}]}
{"op":"mcm","clk":"11541441922","pt":1719505796472,"mc":[{"id":"1.230180132","rc":[{"atb":[[1.53,0]],"id":66314580},{"atb":[[6.4,3.51]],"id":53826530},{"atl":[[7,1.05]],"id":70086038}],"con":true,"img":false}]}
{"op":"mcm","clk":"11541441932","pt":1719505796578,"mc":[{"id":"1.230180132","rc":[{"atb":[[4.9,6],[4.6,1]],"id":67487134},{"atb":[[2.54,6.7],[2.42,0]],"id":66314580},{"atb":[[5.5,0]],"id":53826530},{"atl":[[8.2,0],[8.4,1]],"id":70086038},{"atb":[[4.3,0],[4.9,2]],"id":67130716},{"atl":[[19.5,1]],"id":67130716}],"con":true,"img":false}]}
{"op":"mcm","clk":"11541441938","pt":1719505796678,"mc":[{"id":"1.230180132","rc":[{"atl":[[23,0],[24,4]],"id":67487134},{"atb":[[2.54,9.86]],"id":66314580},{"atl":[[5.3,0],[5.2,3.62]],"id":66314580},{"atb":[[6.2,0]],"id":53826530},{"atl":[[19,2]],"id":67130716}],"con":true,"img":false}]}
{"op":"mcm","clk":"11541441947","pt":1719505796775,"mc":[{"id":"1.230180132","rc":[{"atb":[[6.4,0]],"id":67487134},{"atb":[[2.52,7.09]],"id":66314580},{"atb":[[6.6,1]],"id":53826530},{"atb":[[3.6,0]],"id":67130716}],"con":true,"img":false}]}
{"op":"mcm","clk":"11541441959","pt":1719505796892,"mc":[{"id":"1.230180132","rc":[{"atb":[[6.4,1]],"id":67487134},{"atl":[[19.5,1.05],[20,0]],"id":67487134},{"atb":[[2.54,11.07]],"id":66314580},{"atb":[[6.6,1.84]],"id":53826530},{"atl":[[8.2,1],[8.4,0],[7.6,0]],"id":70086038},{"atl":[[19,3],[19.5,0]],"id":67130716}],"con":true,"img":false}]}
{"op":"mcm","clk":"11541441975","pt":1719505797087,"mc":[{"id":"1.230180132","rc":[{"atb":[[4.8,0]],"id":67487134},{"atl":[[23,4],[24,0]],"id":67487134},{"atb":[[6.4,0.19],[6.8,1.24]],"id":53826530},{"atl":[[5.7,1]],"id":64618726},{"atb":[[3.65,0]],"id":67130716}],"con":true,"img":false}]}
{"op":"mcm","clk":"11541441982","pt":1719505797191,"mc":[{"id":"1.230180132","rc":[{"atb":[[6.4,0],[5,2.77]],"id":67487134},{"atb":[[6.4,3.89],[4.9,0]],"id":53826530},{"atl":[[5.8,0]],"id":64618726}],"con":true,"img":false}]}
{"op":"mcm","clk":"11541442006","pt":1719505797394,"mc":[{"id":"1.230180132","rc":[{"atb":[[5.1,1]],"id":67487134},{"atl":[[19,1.44],[19.5,0.05]],"id":67487134},{"atl":[[8.2,0],[8.4,1],[9.4,8],[8.6,0]],"id":70086038},{"atl":[[18.5,1],[19,2]],"id":67130716}],"con":true,"img":false}]}
{"op":"mcm","clk":"11541442032","pt":1719505797711,"mc":[{"id":"1.230180132","rc":[{"atl":[[8.2,1],[8.4,0]],"id":70086038},{"atl":[[18.5,0],[19,3]],"id":67130716}],"con":true,"img":false}]}
{"op":"mcm","clk":"11541442053","pt":1719505797878,"mc":[{"id":"1.230180132","rc":[{"atb":[[2.62,2.09],[2.52,5]],"id":66314580}],"con":true,"img":false}]}
{"op":"mcm","clk":"11541442062","pt":1719505797979,"mc":[{"id":"1.230180132","rc":[{"atb":[[2.56,5]],"id":66314580}],"con":true,"img":false}]}
{"op":"mcm","clk":"11541442093","pt":1719505798282,"mc":[{"id":"1.230180132","rc":[{"atb":[[2.54,9.37]],"id":66314580}],"con":true,"img":false}]}
{"op":"mcm","clk":"11541442101","pt":1719505798385,"mc":[{"id":"1.230180132","rc":[{"atb":[[2.58,1.7]],"id":66314580}],"con":true,"img":false}]}
{"op":"mcm","clk":"11541442119","pt":1719505798589,"mc":[{"id":"1.230180132","rc":[{"atb":[[2.54,8.16]],"id":66314580}],"con":true,"img":false}]}
{"op":"mcm","clk":"11541442128","pt":1719505798695,"mc":[{"id":"1.230180132","rc":[{"atb":[[2.56,6.21]],"id":66314580}],"con":true,"img":false}]}
{"op":"mcm","clk":"11541442190","pt":1719505799371,"mc":[{"id":"1.230180132","rc":[{"atl":[[19.5,0]],"id":67487134}],"con":true,"img":false}]}
{"op":"mcm","clk":"11541442199","pt":1719505799473,"mc":[{"id":"1.230180132","rc":[{"atl":[[140,2],[23,0]],"id":67487134}],"con":true,"img":false}]}
{"op":"mcm","clk":"11541442250","pt":1719505800194,"mc":[{"id":"1.230180132","rc":[{"atl":[[1000,0.29]],"id":67487134},{"atl":[[5,7.27]],"id":66314580},{"atb":[[3.1,10.8]],"id":70086038},{"atb":[[2.64,17.5]],"id":64618726},{"atl":[[18.5,1.81]],"id":64618726},{"atb":[[5,7.14]],"id":67130716},{"atl":[[18.5,1.39]],"id":67130716}],"con":true,"img":false}]}
{"op":"mcm","clk":"11541442262","pt":1719505800295,"mc":[{"id":"1.230180132","rc":[{"atl":[[1000,0.23]],"id":67487134},{"atl":[[19,1]],"id":67130716}],"con":true,"img":false}]}
{"op":"mcm","clk":"11541442275","pt":1719505800416,"mc":[{"id":"1.230180132","rc":[{"atl":[[18.5,0.06]],"id":67487134},{"atb":[[2.6,5]],"id":66314580},{"atl":[[21,4]],"id":67130716}],"con":true,"img":false}]}
{"op":"mcm","clk":"11541442287","pt":1719505800508,"mc":[{"id":"1.230180132","rc":[{"atl":[[5,6.27]],"id":66314580},{"atb":[[2.64,16.5]],"id":64618726}],"con":true,"img":false}]}
{"op":"mcm","clk":"11541442298","pt":1719505800613,"mc":[{"id":"1.230180132","rc":[{"atb":[[3.2,0]],"id":66314580},{"trd":[[3.2,3.99]],"ltp":3.2,"tv":3.99,"id":66314580}],"con":true,"img":false}]}
{"op":"mcm","clk":"11541442312","pt":1719505800719,"mc":[{"id":"1.230180132","rc":[{"atb":[[2.58,0]],"id":66314580},{"atl":[[4.9,2.05]],"id":66314580},{"atb":[[3.05,0]],"id":70086038},{"atb":[[2.5,0],[2.66,1]],"id":64618726},{"atb":[[5.1,1.97]],"id":67130716}],"con":true,"img":false}]}
{"op":"mcm","clk":"11541442322","pt":1719505800784,"mc":[{"id":"1.230180132","rc":[{"atb":[[2.64,6.34],[2.62,3.79]],"id":66314580},{"atb":[[3.15,1.74]],"id":70086038},{"atb":[[2.66,2.74]],"id":64618726}],"con":true,"img":false}]}
{"op":"mcm","clk":"11541442344","pt":1719505801000,"mc":[{"id":"1.230180132","rc":[{"atb":[[2.56,5]],"id":66314580},{"atb":[[3,4],[2.98,1],[3.2,16.31]],"id":70086038},{"atb":[[2.68,16.57]],"id":64618726},{"atb":[[5.2,6.36]],"id":67130716}],"con":true,"img":false}]}
{"op":"mcm","clk":"11541442354","pt":1719505801097,"mc":[{"id":"1.230180132","rc":[{"atb":[[2.64,7.55]],"id":66314580},{"atb":[[3.3,2.09],[3.15,2.89]],"id":70086038}],"con":true,"img":false}]}
{"op":"mcm","clk":"11541442362","pt":1719505801189,"mc":[{"id":"1.230180132","rc":[{"atb":[[2.66,1.74]],"id":64618726}],"con":true,"img":false}]}
{"op":"mcm","clk":"11541442377","pt":1719505801295,"mc":[{"id":"1.230180132","rc":[{"atb":[[1.04,1.7]],"id":67487134},{"atl":[[1000,1.93]],"id":67487134},{"atb":[[2.62,2.09],[1.02,3.7]],"id":66314580},{"atl":[[1000,1.7]],"id":66314580},{"atb":[[3.15,1.15]],"id":70086038},{"atb":[[2.66,0],[2.7,1]],"id":64618726},{"atb":[[5.1,0.24],[1.04,1.7]],"id":67130716},{"atl":[[1000,1.7]],"id":67130716}],"con":true,"img":false}]}
{"op":"mcm","clk":"11541442390","pt":1719505801396,"mc":[{"id":"1.230180132","rc":[{"atb":[[2.66,1.7]],"id":66314580},{"atb":[[3.25,1.74]],"id":70086038},{"atb":[[2.7,2.74]],"id":64618726},{"atb":[[5.3,1.73]],"id":67130716}],"con":true,"img":false}]}
{"op":"mcm","clk":"11541442401","pt":1719505801500,"mc":[{"id":"1.230180132","rc":[{"atb":[[1.04,0.06]],"id":67487134},{"atl":[[1000,0.23]],"id":67487134},{"atb":[[1.02,2.17],[2.66,2.54]],"id":66314580},{"atl":[[4.8,0.84],[1000,0.07],[5.1,2.19],[5.2,2.1]],"id":66314580},{"atb":[[1.04,0.06]],"id":67130716},{"atl":[[1000,0.01]],"id":67130716}],"con":true,"img":false}]}
{"op":"mcm","clk":"11541442412","pt":1719505801604,"mc":[{"id":"1.230180132","rc":[{"atb":[[3.15,0]],"id":70086038}],"con":true,"img":false}]}
{"op":"mcm","clk":"11541442422","pt":1719505801707,"mc":[{"id":"1.230180132","rc":[{"atb":[[1.04,0]],"id":67487134},{"atb":[[1.02,2]],"id":66314580},{"atl":[[1000,0]],"id":66314580},{"atb":[[3.25,2.89]],"id":70086038},{"atb":[[1.04,0]],"id":67130716},{"atl":[[1000,0]],"id":67130716}],"con":true,"img":false}]}
{"op":"mcm","clk":"11541442430","pt":1719505801772,"mc":[{"id":"1.230180132","rc":[{"atb":[[5.1,1.06]],"id":67487134},{"atb":[[2.66,2.71]],"id":66314580},{"atl":[[4.8,0.92]],"id":66314580},{"atb":[[3.35,10.88]],"id":70086038},{"atb":[[2.72,15.67]],"id":64618726},{"atb":[[5.4,5.48],[5.2,6.42]],"id":67130716},{"atl":[[18,0.01]],"id":67130716}],"con":true,"img":false}]}
{"op":"mcm","clk":"11541442454","pt":1719505801984,"mc":[{"id":"1.230180132","rc":[{"atb":[[2.64,1.21]],"id":66314580},{"atl":[[4.9,4.1]],"id":66314580},{"atb":[[2.62,1],[2.74,15.67],[2.7,1.74]],"id":64618726}],"con":true,"img":false}]}
{"op":"mcm","clk":"11541442475","pt":1719505802193,"mc":[{"id":"1.230180132","rc":[{"atb":[[2.64,0]],"id":66314580},{"atb":[[3.25,1.74]],"id":70086038},{"atb":[[2.76,1]],"id":64618726},{"atb":[[5.4,6.66]],"id":67130716}],"con":true,"img":false}]}
{"op":"mcm","clk":"11541442492","pt":1719505802295,"mc":[{"id":"1.230180132","rc":[{"atb":[[2.6,6.21],[2.68,6.34]],"id":66314580},{"atb":[[3.4,1.15]],"id":70086038},{"atb":[[5.1,0]],"id":67130716}],"con":true,"img":false}]}
{"op":"mcm","clk":"11541442514","pt":1719505802491,"mc":[{"id":"1.230180132","rc":[{"atb":[[3.25,0],[3.45,10.17]],"id":70086038},{"atb":[[2.76,14.73],[2.7,0]],"id":64618726},{"atb":[[5.3,0]],"id":67130716}],"con":true,"img":false}]}
{"op":"mcm","clk":"11541442523","pt":1719505802594,"mc":[{"id":"1.230180132","rc":[{"atb":[[3.4,2.89]],"id":70086038},{"atb":[[2.76,16.47]],"id":64618726},{"atb":[[5.5,1.73]],"id":67130716}],"con":true,"img":false}]}
{"op":"mcm","clk":"11541442547","pt":1719505802805,"mc":[{"id":"1.230180132","rc":[{"atb":[[2.6,5]],"id":66314580},{"atb":[[3.4,1.74]],"id":70086038}],"con":true,"img":false}]}
{"op":"mcm","clk":"11541442560","pt":1719505802903,"mc":[{"id":"1.230180132","rc":[{"atb":[[2.68,7.55]],"id":66314580},{"atb":[[3.45,11.32]],"id":70086038},{"atb":[[1.1,1]],"id":67130716}],"con":true,"img":false}]}
{"op":"mcm","clk":"11541442577","pt":1719505803110,"mc":[{"id":"1.230180132","rc":[{"atb":[[6.4,0.19],[6.8,3.24]],"id":53826530},{"atb":[[3.4,0]],"id":70086038},{"atb":[[1.1,0.22]],"id":67130716}],"con":true,"img":false}]}
{"op":"mcm","clk":"11541442587","pt":1719505803174,"mc":[{"id":"1.230180132","rc":[{"atb":[[4.9,0],[5.1,3.84]],"id":67487134},{"atb":[[3.5,1.74]],"id":70086038}],"con":true,"img":false}]}
{"op":"mcm","clk":"11541442598","pt":1719505803276,"mc":[{"id":"1.230180132","rc":[{"atb":[[5.1,1.06],[5,8.77]],"id":67487134},{"atl":[[4.9,8.2],[5.2,0]],"id":66314580},{"atb":[[1.1,0],[5.6,4.88]],"id":67130716}],"con":true,"img":false}]}
{"op":"mcm","clk":"11541442609","pt":1719505803384,"mc":[{"id":"1.230180132","rc":[{"atb":[[5.1,0.06],[5.2,4.88]],"id":67487134},{"atb":[[5.6,5.1]],"id":67130716}],"con":true,"img":false}]}
{"op":"mcm","clk":"11541442619","pt":1719505803483,"mc":[{"id":"1.230180132","rc":[{"atl":[[4.9,7.2]],"id":66314580}],"con":true,"img":false}]}
{"op":"mcm","clk":"11541442629","pt":1719505803587,"mc":[{"id":"1.230180132","rc":[{"atb":[[5.3,5.88],[5,2.77]],"id":67487134},{"atl":[[4.8,1.92]],"id":66314580}],"con":true,"img":false}]}
{"op":"mcm","clk":"11541442637","pt":1719505803691,"mc":[{"id":"1.230180132","rc":[{"atl":[[4.8,2.71]],"id":66314580},{"atb":[[7,1.76]],"id":53826530}],"con":true,"img":false}]}
{"op":"mcm","clk":"11541442647","pt":1719505803796,"mc":[{"id":"1.230180132","rc":[{"atb":[[5.3,4.88],[5,1]],"id":67487134},{"atb":[[5.5,0]],"id":67130716}],"con":true,"img":false}]}
{"op":"mcm","clk":"11541442660","pt":1719505803894,"mc":[{"id":"1.230180132","rc":[{"atb":[[5.3,7.5]],"id":67487134},{"atb":[[7,2.6]],"id":53826530},{"atb":[[5,6.14],[5.7,1.73]],"id":67130716}],"con":true,"img":false}]}
{"op":"mcm","clk":"11541442671","pt":1719505803995,"mc":[{"id":"1.230180132","rc":[{"atb":[[5.4,1],[5.2,0]],"id":67487134},{"atb":[[6.8,2],[7.2,1.17]],"id":53826530},{"atb":[[5.4,5.48]],"id":67130716}],"con":true,"img":false}]}
{"op":"mcm","clk":"11541442684","pt":1719505804100,"mc":[{"id":"1.230180132","rc":[{"atb":[[5.6,6.28]],"id":67130716}],"con":true,"img":false}]}
{"op":"mcm","clk":"11541442692","pt":1719505804201,"mc":[{"id":"1.230180132","rc":[{"atl":[[4.7,5.39]],"id":66314580},{"atb":[[5,0]],"id":67130716}],"con":true,"img":false}]}
{"op":"mcm","clk":"11541442702","pt":1719505804310,"mc":[{"id":"1.230180132","rc":[{"atb":[[5.3,5.72]],"id":67487134},{"atl":[[4.8,2.37]],"id":66314580},{"atb":[[7,0.84]],"id":53826530},{"atb":[[5.8,5.41]],"id":67130716}],"con":true,"img":false}]}
{"op":"mcm","clk":"11541442725","pt":1719505804516,"mc":[{"id":"1.230180132","rc":[{"atb":[[6.6,1]],"id":53826530}],"con":true,"img":false}]}
{"op":"mcm","clk":"11541442736","pt":1719505804622,"mc":[{"id":"1.230180132","rc":[{"atb":[[7.2,0],[7,2.02]],"id":53826530},{"atb":[[5.6,5.1]],"id":67130716}],"con":true,"img":false}]}
{"op":"mcm","clk":"11541442747","pt":1719505804678,"mc":[{"id":"1.230180132","rc":[{"atb":[[5.8,6.59]],"id":67130716}],"con":true,"img":false}]}
{"op":"mcm","clk":"11541442760","pt":1719505804790,"mc":[{"id":"1.230180132","rc":[{"atl":[[7.8,0]],"id":70086038}],"con":true,"img":false}]}
{"op":"mcm","clk":"11541442783","pt":1719505805005,"mc":[{"id":"1.230180132","rc":[{"atl":[[4.8,1.92]],"id":66314580},{"atb":[[5.7,0]],"id":67130716}],"con":true,"img":false}]}
{"op":"mcm","clk":"11541442793","pt":1719505805097,"mc":[{"id":"1.230180132","rc":[{"atl":[[1000,0.45]],"id":66314580},{"atb":[[5.9,1.73]],"id":67130716}],"con":true,"img":false}]}
{"op":"mcm","clk":"11541442864","pt":1719505805791,"mc":[{"id":"1.230180132","rc":[{"atb":[[5.2,0.06]],"id":67130716}],"con":true,"img":false}]}
{"op":"mcm","clk":"11541442875","pt":1719505805896,"mc":[{"id":"1.230180132","rc":[{"atb":[[5.9,7.18]],"id":67130716}],"con":true,"img":false}]}
{"op":"mcm","clk":"11541442930","pt":1719505806400,"mc":[{"id":"1.230180132","rc":[{"atb":[[5.8,5.41]],"id":67130716}],"con":true,"img":false}]}
{"op":"mcm","clk":"11541442941","pt":1719505806504,"mc":[{"id":"1.230180132","rc":[{"atb":[[5.9,8.36]],"id":67130716}],"con":true,"img":false}]}
{"op":"mcm","clk":"11541443045","pt":1719505807507,"mc":[{"id":"1.230180132","rc":[{"atb":[[3.55,10.88],[3.2,11.16]],"id":70086038}],"con":true,"img":false}]}
{"op":"mcm","clk":"11541443097","pt":1719505808019,"mc":[{"id":"1.230180132","rc":[{"atb":[[3.5,0]],"id":70086038}],"con":true,"img":false}]}
{"op":"mcm","clk":"11541443112","pt":1719505808115,"mc":[{"id":"1.230180132","rc":[{"atl":[[130,0.84]],"id":53826530},{"atb":[[3.6,1.74]],"id":70086038}],"con":true,"img":false}]}
{"op":"mcm","clk":"11541443131","pt":1719505808285,"mc":[{"id":"1.230180132","rc":[{"atb":[[6.4,0]],"id":53826530},{"atb":[[3.45,10.17]],"id":70086038}],"con":true,"img":false}]}
{"op":"mcm","clk":"11541443144","pt":1719505808392,"mc":[{"id":"1.230180132","rc":[{"atb":[[2.7,0.84]],"id":66314580},{"atl":[[5.1,1.95],[4.6,0.84]],"id":66314580},{"atb":[[3.6,2.89]],"id":70086038}],"con":true,"img":false}]}
{"op":"mcm","clk":"11541443156","pt":1719505808496,"mc":[{"id":"1.230180132","rc":[{"atb":[[1.13,1]],"id":53826530},{"atl":[[1000,0.01]],"id":53826530}],"con":true,"img":false}]}
{"op":"mcm","clk":"11541443167","pt":1719505808601,"mc":[{"id":"1.230180132","rc":[{"atb":[[2.62,0],[2.74,2.09]],"id":66314580},{"atl":[[4.7,7.55]],"id":66314580},{"atb":[[1.13,0.16]],"id":53826530},{"atl":[[1000,0]],"id":53826530},{"atb":[[2.54,0],[2.84,2.09]],"id":64618726}],"con":true,"img":false}]}
{"op":"mcm","clk":"11541443179","pt":1719505808696,"mc":[{"id":"1.230180132","rc":[{"atb":[[5.3,0.84],[5.1,6.79]],"id":67487134},{"atl":[[130,0.85]],"id":53826530},{"atb":[[2.84,17.76],[2.74,0]],"id":64618726}],"con":true,"img":false}]}
{"op":"mcm","clk":"11541443190","pt":1719505808805,"mc":[{"id":"1.230180132","rc":[{"atl":[[4.8,0.92],[1000,0.73]],"id":66314580},{"atb":[[2.76,15.47]],"id":64618726}],"con":true,"img":false}]}
{"op":"mcm","clk":"11541443198","pt":1719505808902,"mc":[{"id":"1.230180132","rc":[{"atb":[[1.13,0]],"id":53826530}],"con":true,"img":false}]}
{"op":"mcm","clk":"11541443207","pt":1719505809003,"mc":[{"id":"1.230180132","rc":[{"atb":[[2.68,1.21]],"id":66314580},{"atl":[[1000,0.45],[4.6,1.84],[4.7,2.16]],"id":66314580},{"atb":[[7.2,0.16]],"id":53826530},{"atb":[[2.86,1]],"id":64618726}],"con":true,"img":false}]}
{"op":"mcm","clk":"11541443218","pt":1719505809105,"mc":[{"id":"1.230180132","rc":[{"atb":[[5.2,1.77]],"id":67487134},{"atl":[[1000,0],[4.6,2.12]],"id":66314580}],"con":true,"img":false}]}
{"op":"mcm","clk":"11541443230","pt":1719505809212,"mc":[{"id":"1.230180132","rc":[{"atl":[[4.6,1.58]],"id":66314580},{"atb":[[2.76,13.73]],"id":64618726}],"con":true,"img":false}]}
{"op":"mcm","clk":"11541443239","pt":1719505809317,"mc":[{"id":"1.230180132","rc":[{"atb":[[2.86,2.74]],"id":64618726}],"con":true,"img":false}]}
{"op":"mcm","clk":"11541443256","pt":1719505809418,"mc":[{"id":"1.230180132","rc":[{"atb":[[2.68,0]],"id":66314580},{"atl":[[4.8,1.92]],"id":66314580}],"con":true,"img":false}]}
{"op":"mcm","clk":"11541443266","pt":1719505809523,"mc":[{"id":"1.230180132","rc":[{"atb":[[2.6,6.21],[2.66,1.87],[2.7,0]],"id":66314580},{"atl":[[4.8,1.07]],"id":66314580}],"con":true,"img":false}]}
{"op":"mcm","clk":"11541443303","pt":1719505809787,"mc":[{"id":"1.230180132","rc":[{"atb":[[2.66,0.17]],"id":66314580},{"atl":[[4.6,1.12]],"id":66314580}],"con":true,"img":false}]}
{"op":"mcm","clk":"11541443312","pt":1719505809888,"mc":[{"id":"1.230180132","rc":[{"atb":[[2.62,1.7]],"id":66314580},{"atl":[[1000,0.45]],"id":66314580}],"con":true,"img":false}]}
{"op":"mcm","clk":"11541443338","pt":1719505810095,"mc":[{"id":"1.230180132","rc":[{"atb":[[5.3,2.84],[5.1,0.06]],"id":67487134}],"con":true,"img":false}]}
{"op":"mcm","clk":"11541443459","pt":1719505811329,"mc":[{"id":"1.230180132","rc":[{"atb":[[5.3,8.02]],"id":53826530}],"con":true,"img":false}]}
{"op":"mcm","clk":"11541443481","pt":1719505811490,"mc":[{"id":"1.230180132","rc":[{"atb":[[5.4,1.76]],"id":53826530}],"con":true,"img":false}]}
{"op":"mcm","clk":"11541443500","pt":1719505811701,"mc":[{"id":"1.230180132","rc":[{"atl":[[4.9,6.15]],"id":66314580}],"con":true,"img":false}]}
{"op":"mcm","clk":"11541443520","pt":1719505811898,"mc":[{"id":"1.230180132","rc":[{"atl":[[7,0]],"id":70086038}],"con":true,"img":false}]}
{"op":"mcm","clk":"11541443532","pt":1719505812016,"mc":[{"id":"1.230180132","rc":[{"atl":[[4.5,1.05]],"id":66314580}],"con":true,"img":false}]}
{"op":"mcm","clk":"11541443559","pt":1719505812209,"mc":[{"id":"1.230180132","rc":[{"atb":[[2.76,0.89]],"id":66314580},{"atl":[[7.8,1.17],[7.2,0]],"id":70086038}],"con":true,"img":false}]}
{"op":"mcm","clk":"11541443590","pt":1719505812520,"mc":[{"id":"1.230180132","rc":[{"atb":[[5.3,0]],"id":53826530},{"atb":[[3.1,0]],"id":70086038}],"con":true,"img":false}]}
{"op":"mcm","clk":"11541443613","pt":1719505812726,"mc":[{"id":"1.230180132","rc":[{"atb":[[2.62,0]],"id":66314580},{"atl":[[4.5,7.76]],"id":66314580},{"atb":[[5.4,0]],"id":53826530},{"atb":[[3.6,12.59]],"id":70086038}],"con":true,"img":false}]}
{"op":"mcm","clk":"11541443631","pt":1719505812891,"mc":[{"id":"1.230180132","rc":[{"atl":[[4.8,0.07]],"id":66314580},{"atb":[[5.4,2.81]],"id":53826530}],"con":true,"img":false}]}
{"op":"mcm","clk":"11541443654","pt":1719505813097,"mc":[{"id":"1.230180132","rc":[{"atl":[[4.4,1]],"id":66314580}],"con":true,"img":false}]}
{"op":"mcm","clk":"11541443694","pt":1719505813528,"mc":[{"id":"1.230180132","rc":[{"atl":[[7.6,1.71]],"id":70086038}],"con":true,"img":false}]}
{"op":"mcm","clk":"11541443734","pt":1719505813918,"mc":[{"id":"1.230180132","rc":[{"atl":[[7.4,0.84]],"id":70086038}],"con":true,"img":false}]}
{"op":"mcm","clk":"11541443792","pt":1719505814536,"mc":[{"id":"1.230180132","rc":[{"atb":[[1.54,12.53]],"id":66314580}],"con":true,"img":false}]}
{"op":"mcm","clk":"11541443894","pt":1719505815621,"mc":[{"id":"1.230180132","rc":[{"atb":[[5.1,0.97]],"id":67487134},{"atl":[[18.5,0]],"id":67487134},{"atb":[[2.62,7.83]],"id":66314580},{"atb":[[2.64,24.93]],"id":64618726},{"atb":[[5.1,8.8]],"id":67130716}],"con":true,"img":false}]}
{"op":"mcm","clk":"11541443917","pt":1719505815826,"mc":[{"id":"1.230180132","rc":[{"atl":[[4.4,3.35]],"id":66314580}],"con":true,"img":false}]}
{"op":"mcm","clk":"11541443935","pt":1719505816037,"mc":[{"id":"1.230180132","rc":[{"atb":[[2.6,5]],"id":66314580},{"atl":[[1000,2.16]],"id":66314580}],"con":true,"img":false}]}
{"op":"mcm","clk":"11541443947","pt":1719505816101,"mc":[{"id":"1.230180132","rc":[{"atb":[[1.03,5.1],[2.62,9.04],[1.02,3.7]],"id":66314580},{"atl":[[4.4,10.85],[1000,7.26]],"id":66314580}],"con":true,"img":false}]}
{"op":"mcm","clk":"11541443956","pt":1719505816208,"mc":[{"id":"1.230180132","rc":[{"atl":[[1000,0.29]],"id":67487134},{"atl":[[4.4,9.85],[1000,5.62]],"id":66314580}],"con":true,"img":false}]}
{"op":"mcm","clk":"11541443968","pt":1719505816317,"mc":[{"id":"1.230180132","rc":[{"atb":[[1.03,0.3],[1.02,2.11]],"id":66314580},{"atl":[[1000,0.22]],"id":66314580}],"con":true,"img":false}]}
{"op":"mcm","clk":"11541443979","pt":1719505816406,"mc":[{"id":"1.230180132","rc":[{"atl":[[1000,0.23]],"id":67487134},{"atl":[[4.3,1.3],[1000,0.15]],"id":66314580}],"con":true,"img":false}]}
{"op":"mcm","clk":"11541443987","pt":1719505816513,"mc":[{"id":"1.230180132","rc":[{"atl":[[18.5,0.06]],"id":67487134},{"atb":[[1.03,0],[1.02,2]],"id":66314580},{"atl":[[4.3,8.21],[4.4,9.91],[1000,0],[4.6,0.28]],"id":66314580}],"con":true,"img":false}]}
{"op":"mcm","clk":"11541443997","pt":1719505816618,"mc":[{"id":"1.230180132","rc":[{"atb":[[2.76,1.31]],"id":66314580},{"atl":[[4.4,10.07]],"id":66314580}],"con":true,"img":false}]}
{"op":"mcm","clk":"11541444012","pt":1719505816813,"mc":[{"id":"1.230180132","rc":[{"atb":[[1.55,0]],"id":66314580},{"atb":[[2.46,0]],"id":64618726}],"con":true,"img":false}]}
{"op":"mcm","clk":"11541444024","pt":1719505816919,"mc":[{"id":"1.230180132","rc":[{"atb":[[2.64,1.7]],"id":66314580},{"atl":[[4.3,16.05]],"id":66314580}],"con":true,"img":false}]}
{"op":"mcm","clk":"11541444042","pt":1719505817124,"mc":[{"id":"1.230180132","rc":[{"atl":[[4.3,15.05]],"id":66314580}],"con":true,"img":false}]}
{"op":"mcm","clk":"11541444066","pt":1719505817336,"mc":[{"id":"1.230180132","rc":[{"atl":[[4.2,1]],"id":66314580}],"con":true,"img":false}]}
{"op":"mcm","clk":"11541444096","pt":1719505817598,"mc":[{"id":"1.230180132","rc":[{"atl":[[4.3,9.14]],"id":66314580}],"con":true,"img":false}]}
{"op":"mcm","clk":"11541444121","pt":1719505817906,"mc":[{"id":"1.230180132","rc":[{"atb":[[2.48,0]],"id":64618726}],"con":true,"img":false}]}
{"op":"mcm","clk":"11541444149","pt":1719505818320,"mc":[{"id":"1.230180132","rc":[{"atb":[[1.56,22.67]],"id":66314580}],"con":true,"img":false}]}
{"op":"mcm","clk":"11541444162","pt":1719505818420,"mc":[{"id":"1.230180132","rc":[{"atb":[[2.32,11.71]],"id":53826530}],"con":true,"img":false}]}
{"op":"mcm","clk":"11541444180","pt":1719505818618,"mc":[{"id":"1.230180132","rc":[{"atb":[[2.48,8.58]],"id":64618726},{"atb":[[5.6,4.88]],"id":67130716}],"con":true,"img":false}]}
{"op":"mcm","clk":"11541444203","pt":1719505818935,"mc":[{"id":"1.230180132","rc":[{"atb":[[2.16,18.58]],"id":67487134},{"atb":[[1.57,14.84]],"id":66314580}],"con":true,"img":false}]}
{"op":"mcm","clk":"11541444219","pt":1719505819133,"mc":[{"id":"1.230180132","rc":[{"atb":[[2.74,0],[2.7,2.09]],"id":66314580}],"con":true,"img":false}]}
{"op":"mcm","clk":"11541444241","pt":1719505819298,"mc":[{"id":"1.230180132","rc":[{"atl":[[4.2,3.5]],"id":66314580}],"con":true,"img":false}]}
{"op":"mcm","clk":"11541444260","pt":1719505819507,"mc":[{"id":"1.230180132","rc":[{"atb":[[2.36,0],[2.86,6.12]],"id":64618726}],"con":true,"img":false}]}
{"op":"mcm","clk":"11541444266","pt":1719505819608,"mc":[{"id":"1.230180132","rc":[{"atl":[[4.1,6.19]],"id":66314580}],"con":true,"img":false}]}
{"op":"mcm","clk":"11541444277","pt":1719505819712,"mc":[{"id":"1.230180132","rc":[{"atb":[[2.5,7.9]],"id":64618726}],"con":true,"img":false}]}
{"op":"mcm","clk":"11541444294","pt":1719505819920,"mc":[{"id":"1.230180132","rc":[{"atl":[[4.3,8.68]],"id":66314580}],"con":true,"img":false}]}
{"op":"mcm","clk":"11541444305","pt":1719505820030,"mc":[{"id":"1.230180132","rc":[{"atl":[[4,0.45]],"id":66314580},{"atb":[[2.38,0]],"id":64618726}],"con":true,"img":false}]}
{"op":"mcm","clk":"11541444324","pt":1719505820224,"mc":[{"id":"1.230180132","rc":[{"atb":[[5.4,0]],"id":53826530}],"con":true,"img":false}]}
{"op":"mcm","clk":"11541444338","pt":1719505820328,"mc":[{"id":"1.230180132","rc":[{"atb":[[2.54,5]],"id":66314580}],"con":true,"img":false}]}
{"op":"mcm","clk":"11541444351","pt":1719505820431,"mc":[{"id":"1.230180132","rc":[{"atl":[[5,0]],"id":66314580}],"con":true,"img":false}]}
{"op":"mcm","clk":"11541444363","pt":1719505820536,"mc":[{"id":"1.230180132","rc":[{"atl":[[4.3,7.84],[4,9.71]],"id":66314580},{"atb":[[5.5,2.15]],"id":53826530},{"atb":[[2.86,9.29]],"id":64618726}],"con":true,"img":false}]}
{"op":"mcm","clk":"11541444387","pt":1719505820705,"mc":[{"id":"1.230180132","rc":[{"atl":[[4.1,0],[4.2,2.5]],"id":66314580}],"con":true,"img":false}]}
{"op":"mcm","clk":"11541444406","pt":1719505820909,"mc":[{"id":"1.230180132","rc":[{"atl":[[3.95,7.34]],"id":66314580}],"con":true,"img":false}]}
{"op":"mcm","clk":"11541444428","pt":1719505821115,"mc":[{"id":"1.230180132","rc":[{"atl":[[4,9.26]],"id":66314580}],"con":true,"img":false}]}
{"op":"mcm","clk":"11541444440","pt":1719505821214,"mc":[{"id":"1.230180132","rc":[{"atl":[[3.9,0.45]],"id":66314580}],"con":true,"img":false}]}
{"op":"mcm","clk":"11541444450","pt":1719505821316,"mc":[{"id":"1.230180132","rc":[{"atl":[[4.5,1.05]],"id":66314580}],"con":true,"img":false}]}
{"op":"mcm","clk":"11541444458","pt":1719505821419,"mc":[{"id":"1.230180132","rc":[{"atb":[[5.5,0]],"id":53826530}],"con":true,"img":false}]}
{"op":"mcm","clk":"11541444468","pt":1719505821527,"mc":[{"id":"1.230180132","rc":[{"atl":[[3.95,15.37]],"id":66314580}],"con":true,"img":false}]}
{"op":"mcm","clk":"11541444485","pt":1719505821730,"mc":[{"id":"1.230180132","rc":[{"atl":[[3.95,14.37]],"id":66314580},{"atb":[[5.5,2.83]],"id":53826530}],"con":true,"img":false}]}
{"op":"mcm","clk":"11541444495","pt":1719505821834,"mc":[{"id":"1.230180132","rc":[{"atl":[[3.9,1.45]],"id":66314580}],"con":true,"img":false}]}
{"op":"mcm","clk":"11541444509","pt":1719505821996,"mc":[{"id":"1.230180132","rc":[{"atl":[[3.95,8.03]],"id":66314580}],"con":true,"img":false}]}
{"op":"mcm","clk":"11541444543","pt":1719505822311,"mc":[{"id":"1.230180132","rc":[{"atl":[[3.9,0.45]],"id":66314580}],"con":true,"img":false}]}
{"op":"mcm","clk":"11541444560","pt":1719505822518,"mc":[{"id":"1.230180132","rc":[{"atl":[[3.9,3.21]],"id":66314580}],"con":true,"img":false}]}
{"op":"mcm","clk":"11541444570","pt":1719505822619,"mc":[{"id":"1.230180132","rc":[{"atl":[[3.95,9.03],[3.9,9.56]],"id":66314580}],"con":true,"img":false}]}
{"op":"mcm","clk":"11541444587","pt":1719505822817,"mc":[{"id":"1.230180132","rc":[{"atl":[[3.95,8.03]],"id":66314580}],"con":true,"img":false}]}
{"op":"mcm","clk":"11541444597","pt":1719505822923,"mc":[{"id":"1.230180132","rc":[{"atl":[[3.85,1]],"id":66314580}],"con":true,"img":false}]}
{"op":"mcm","clk":"11541444628","pt":1719505823232,"mc":[{"id":"1.230180132","rc":[{"atl":[[1000,1.08]],"id":67487134}],"con":true,"img":false}]}
{"op":"mcm","clk":"11541444639","pt":1719505823337,"mc":[{"id":"1.230180132","rc":[{"atl":[[3.9,3.21]],"id":66314580}],"con":true,"img":false}]}
{"op":"mcm","clk":"11541444650","pt":1719505823441,"mc":[{"id":"1.230180132","rc":[{"atl":[[19,1]],"id":67487134},{"atl":[[7.4,1.89]],"id":70086038}],"con":true,"img":false}]}
{"op":"mcm","clk":"11541444660","pt":1719505823498,"mc":[{"id":"1.230180132","rc":[{"atl":[[1000,0.71]],"id":67487134}],"con":true,"img":false}]}
{"op":"mcm","clk":"11541444670","pt":1719505823605,"mc":[{"id":"1.230180132","rc":[{"atl":[[3.85,0]],"id":66314580}],"con":true,"img":false}]}
{"op":"mcm","clk":"11541444687","pt":1719505823832,"mc":[{"id":"1.230180132","rc":[{"atl":[[1000,0.23]],"id":67487134},{"atl":[[4.4,2.57],[3.95,9.03]],"id":66314580}],"con":true,"img":false}]}
{"op":"mcm","clk":"11541444694","pt":1719505823917,"mc":[{"id":"1.230180132","rc":[{"atl":[[18,0.47]],"id":67487134},{"atl":[[3.85,15.64]],"id":66314580},{"atl":[[130,0.84]],"id":53826530}],"con":true,"img":false}]}
{"op":"mcm","clk":"11541444703","pt":1719505824019,"mc":[{"id":"1.230180132","rc":[{"atl":[[140,0],[23,4]],"id":67487134}],"con":true,"img":false}]}
{"op":"mcm","clk":"11541444714","pt":1719505824114,"mc":[{"id":"1.230180132","rc":[{"atl":[[3.95,8.03],[3.9,2.76]],"id":66314580}],"con":true,"img":false}]}
{"op":"mcm","clk":"11541444723","pt":1719505824216,"mc":[{"id":"1.230180132","rc":[{"atl":[[3.8,1.45]],"id":66314580},{"atb":[[7.2,0]],"id":53826530}],"con":true,"img":false}]}
{"op":"mcm","clk":"11541444731","pt":1719505824318,"mc":[{"id":"1.230180132","rc":[{"atl":[[4.6,0]],"id":66314580}],"con":true,"img":false}]}
{"op":"mcm","clk":"11541444737","pt":1719505824424,"mc":[{"id":"1.230180132","rc":[{"atl":[[3.8,2.3]],"id":66314580}],"con":true,"img":false}]}
{"op":"mcm","clk":"11541444748","pt":1719505824530,"mc":[{"id":"1.230180132","rc":[{"atl":[[3.85,9.3],[4.3,0]],"id":66314580}],"con":true,"img":false}]}
{"op":"mcm","clk":"11541444757","pt":1719505824628,"mc":[{"id":"1.230180132","rc":[{"atl":[[3.75,6.34],[3.8,11.55]],"id":66314580}],"con":true,"img":false}]}
{"op":"mcm","clk":"11541444770","pt":1719505824731,"mc":[{"id":"1.230180132","rc":[{"atb":[[1.13,1]],"id":53826530},{"atl":[[1000,0.01]],"id":53826530}],"con":true,"img":false}]}
{"op":"mcm","clk":"11541444782","pt":1719505824936,"mc":[{"id":"1.230180132","rc":[{"atb":[[1.13,0.16]],"id":53826530},{"atl":[[1000,0]],"id":53826530}],"con":true,"img":false}]}
{"op":"mcm","clk":"11541444788","pt":1719505825041,"mc":[{"id":"1.230180132","rc":[{"atb":[[5.5,0]],"id":53826530},{"atl":[[130,0.85]],"id":53826530}],"con":true,"img":false}]}
{"op":"mcm","clk":"11541444795","pt":1719505825144,"mc":[{"id":"1.230180132","rc":[{"atb":[[1.13,0]],"id":53826530}],"con":true,"img":false}]}
{"op":"mcm","clk":"11541444804","pt":1719505825199,"mc":[{"id":"1.230180132","rc":[{"atb":[[7.2,0.16]],"id":53826530}],"con":true,"img":false}]}
{"op":"mcm","clk":"11541444813","pt":1719505825307,"mc":[{"id":"1.230180132","rc":[{"atl":[[3.8,11.09]],"id":66314580},{"atb":[[5.7,10.61]],"id":53826530}],"con":true,"img":false}]}
{"op":"mcm","clk":"11541444823","pt":1719505825409,"mc":[{"id":"1.230180132","rc":[{"atl":[[4,0],[3.7,0.45]],"id":66314580}],"con":true,"img":false}]}
{"op":"mcm","clk":"11541444832","pt":1719505825523,"mc":[{"id":"1.230180132","rc":[{"atl":[[3.75,16.17]],"id":66314580}],"con":true,"img":false}]}
{"op":"mcm","clk":"11541444853","pt":1719505825719,"mc":[{"id":"1.230180132","rc":[{"atl":[[7.6,0]],"id":70086038}],"con":true,"img":false}]}
{"op":"mcm","clk":"11541444861","pt":1719505825816,"mc":[{"id":"1.230180132","rc":[{"atl":[[3.8,10.09]],"id":66314580}],"con":true,"img":false}]}
{"op":"mcm","clk":"11541444869","pt":1719505825927,"mc":[{"id":"1.230180132","rc":[{"atl":[[3.7,1.45]],"id":66314580},{"atb":[[5.8,1.76]],"id":53826530}],"con":true,"img":false}]}
{"op":"mcm","clk":"11541444896","pt":1719505826229,"mc":[{"id":"1.230180132","rc":[{"atl":[[3.75,9.83]],"id":66314580}],"con":true,"img":false}]}
{"op":"mcm","clk":"11541444924","pt":1719505826541,"mc":[{"id":"1.230180132","rc":[{"atl":[[3.95,0]],"id":66314580}],"con":true,"img":false}]}
{"op":"mcm","clk":"11541444933","pt":1719505826652,"mc":[{"id":"1.230180132","rc":[{"atl":[[3.7,4.41]],"id":66314580}],"con":true,"img":false}]}
{"op":"mcm","clk":"11541444944","pt":1719505826704,"mc":[{"id":"1.230180132","rc":[{"atl":[[3.7,13.44]],"id":66314580}],"con":true,"img":false}]}
{"op":"mcm","clk":"11541444956","pt":1719505826856,"mc":[{"id":"1.230180132","rc":[{"atl":[[3.7,12.44],[3.65,6.34]],"id":66314580}],"con":true,"img":false}]}
