{"op":"mcm","clk":"11536380642","pt":1719425245577,"mc":[{"id":"1.230178318","marketDefinition":{"bspMarket":true,"turnInPlayEnabled":false,"persistenceEnabled":false,"marketBaseRate":5.0,"eventId":"33376062","eventTypeId":"4339","numberOfWinners":1,"bettingType":"ODDS","marketType":"WIN","marketTime":"2024-06-27T15:28:00.000Z","suspendTime":"2024-06-27T15:28:00.000Z","bspReconciled":false,"complete":true,"inPlay":false,"crossMatching":false,"runnersVoidable":false,"numberOfActiveRunners":6,"betDelay":0,"status":"OPEN","runners":[{"status":"ACTIVE","sortPriority":1,"id":40214683,"name":"1. Corner Zoom"},{"status":"ACTIVE","sortPriority":2,"id":39959056,"name":"2. Endova Zoey"},{"status":"ACTIVE","sortPriority":3,"id":62766534,"name":"3. Glenvale Beau"},{"status":"ACTIVE","sortPriority":4,"id":69261147,"name":"4. Madam Tiger"},{"status":"ACTIVE","sortPriority":5,"id":70642246,"name":"5. Burgess Lana"},{"status":"ACTIVE","sortPriority":6,"id":56418091,"name":"6. Strike It Josie"}],"regulators":["MR_INT"],"venue":"Kinsley","countryCode":"GB","discountAllowed":false,"timezone":"Europe/London","openDate":"2024-06-27T13:36:00.000Z","version":5994643755,"name":"D4 268m","eventName":"Kinsley 27th Jun"},"rc":[],"con":true,"img":false}]}
{"op":"mcm","clk":"11536381012","pt":1719425248523,"mc":[{"id":"1.230178318","marketDefinition":{"bspMarket":true,"turnInPlayEnabled":false,"persistenceEnabled":false,"marketBaseRate":5.0,"eventId":"33376062","eventTypeId":"4339","numberOfWinners":1,"bettingType":"ODDS","marketType":"WIN","marketTime":"2024-06-27T15:28:00.000Z","suspendTime":"2024-06-27T15:28:00.000Z","bspReconciled":false,"complete":true,"inPlay":false,"crossMatching":false,"runnersVoidable":false,"numberOfActiveRunners":6,"betDelay":0,"status":"OPEN","runners":[{"status":"ACTIVE","sortPriority":1,"id":40214683,"name":"1. Corner Zoom"},{"status":"ACTIVE","sortPriority":2,"id":39959056,"name":"2. Endova Zoey"},{"status":"ACTIVE","sortPriority":3,"id":62766534,"name":"3. Glenvale Beau"},{"status":"ACTIVE","sortPriority":4,"id":69261147,"name":"4. Madam Tiger"},{"status":"ACTIVE","sortPriority":5,"id":70642246,"name":"5. Burgess Lana"},{"status":"ACTIVE","sortPriority":6,"id":56418091,"name":"6. Strike It Josie"}],"regulators":["MR_INT"],"venue":"Kinsley","countryCode":"GB","discountAllowed":true,"timezone":"Europe/London","openDate":"2024-06-27T13:36:00.000Z","version":5994643755,"name":"D4 268m","eventName":"Kinsley 27th Jun"},"rc":[],"con":true,"img":false}]}
{"op":"mcm","clk":"11536614480","pt":1719428235110,"mc":[{"id":"1.230178318","rc":[{"atb":[[1.01,23.65]],"id":62766534},{"atl":[[990,0.84]],"id":62766534},{"spn":495.5,"spf":"NaN","id":62766534},{"atb":[[1.03,7.88]],"id":39959056},{"atl":[[990,0.84]],"id":39959056},{"spn":495.51,"spf":"NaN","id":39959056},{"atb":[[1.01,23.65]],"id":40214683},{"atl":[[990,0.84]],"id":40214683},{"spn":495.5,"spf":"NaN","id":40214683},{"atb":[[1.03,7.88]],"id":56418091},{"atl":[[990,0.84]],"id":56418091},{"spn":495.51,"spf":"NaN","id":56418091},{"atb":[[1.02,11.82]],"id":69261147},{"atl":[[990,0.84]],"id":69261147},{"spn":495.51,"spf":"NaN","id":69261147},{"atb":[[1.03,7.88]],"id":70642246},{"atl":[[1000,0.84]],"id":70642246},{"spn":500.51,"spf":"NaN","id":70642246}],"con":true,"img":false}]}
{"op":"mcm","clk":"11536836610","pt":1719431845537,"mc":[{"id":"1.230178318","rc":[{"atb":[[1.01,23.66]],"id":62766534},{"atl":[[990,0.22]],"id":62766534},{"atb":[[1.03,7.88]],"id":39959056},{"atl":[[990,0.22]],"id":39959056},{"atb":[[1.01,23.66]],"id":40214683},{"atl":[[990,0.22]],"id":40214683},{"atb":[[1.03,7.88]],"id":56418091},{"atl":[[990,0.22]],"id":56418091},{"atb":[[1.02,11.82]],"id":69261147},{"atl":[[990,0.22]],"id":69261147},{"atb":[[1.03,7.88]],"id":70642246},{"atl":[[1000,0.22]],"id":70642246}],"con":true,"img":false}]}
{"op":"mcm","clk":"11537232240","pt":1719437882515,"mc":[{"id":"1.230178318","marketDefinition":{"bspMarket":true,"turnInPlayEnabled":false,"persistenceEnabled":false,"marketBaseRate":5.0,"eventId":"33376062","eventTypeId":"4339","numberOfWinners":1,"bettingType":"ODDS","marketType":"WIN","marketTime":"2024-06-27T15:28:00.000Z","suspendTime":"2024-06-27T15:28:00.000Z","bspReconciled":false,"complete":true,"inPlay":false,"crossMatching":false,"runnersVoidable":false,"numberOfActiveRunners":6,"betDelay":0,"status":"OPEN","runners":[{"status":"ACTIVE","sortPriority":1,"id":40214683,"name":"1. Corner Zoom"},{"status":"ACTIVE","sortPriority":2,"id":39959056,"name":"2. Endova Zoey"},{"status":"ACTIVE","sortPriority":3,"id":62766534,"name":"3. Glenvale Beau"},{"status":"ACTIVE","sortPriority":4,"id":69261147,"name":"4. Madam Tiger"},{"status":"ACTIVE","sortPriority":5,"id":70642246,"name":"5. Burgess Lana"},{"status":"ACTIVE","sortPriority":6,"id":56418091,"name":"6. Strike It Josie"}],"regulators":["MR_INT"],"venue":"Kinsley","countryCode":"GB","discountAllowed":true,"timezone":"Europe/London","openDate":"2024-06-27T13:36:00.000Z","version":5994643755,"name":"D4 268m","eventName":"Kinsley 27th Jun"},"rc":[{"atb":[[1.01,23.66]],"id":62766534},{"atl":[[990,0.22]],"id":62766534},{"spn":495.5,"spf":"NaN","id":62766534},{"atb":[[1.03,7.88]],"id":39959056},{"atl":[[990,0.22]],"id":39959056},{"spn":495.51,"spf":"NaN","id":39959056},{"atb":[[1.01,23.66]],"id":40214683},{"atl":[[990,0.22]],"id":40214683},{"spn":495.5,"spf":"NaN","id":40214683},{"atb":[[1.03,7.88]],"id":56418091},{"atl":[[990,0.22]],"id":56418091},{"spn":495.51,"spf":"NaN","id":56418091},{"atb":[[1.02,11.82]],"id":69261147},{"atl":[[990,0.22]],"id":69261147},{"spn":495.51,"spf":"NaN","id":69261147},{"atb":[[1.03,7.88]],"id":70642246},{"atl":[[1000,0.22]],"id":70642246},{"spn":500.51,"spf":"NaN","id":70642246}],"con":true,"img":true}]}
{"op":"mcm","clk":"11537573367","pt":1719443282536,"mc":[{"id":"1.230178318","marketDefinition":{"bspMarket":true,"turnInPlayEnabled":false,"persistenceEnabled":false,"marketBaseRate":5.0,"eventId":"33376062","eventTypeId":"4339","numberOfWinners":1,"bettingType":"ODDS","marketType":"WIN","marketTime":"2024-06-27T15:28:00.000Z","suspendTime":"2024-06-27T15:28:00.000Z","bspReconciled":false,"complete":true,"inPlay":false,"crossMatching":false,"runnersVoidable":false,"numberOfActiveRunners":6,"betDelay":0,"status":"OPEN","runners":[{"status":"ACTIVE","sortPriority":1,"id":40214683,"name":"1. Corner Zoom"},{"status":"ACTIVE","sortPriority":2,"id":39959056,"name":"2. Endova Zoey"},{"status":"ACTIVE","sortPriority":3,"id":62766534,"name":"3. Glenvale Beau"},{"status":"ACTIVE","sortPriority":4,"id":69261147,"name":"4. Madam Tiger"},{"status":"ACTIVE","sortPriority":5,"id":70642246,"name":"5. Burgess Lana"},{"status":"ACTIVE","sortPriority":6,"id":56418091,"name":"6. Strike It Josie"}],"regulators":["MR_INT"],"venue":"Kinsley","countryCode":"GB","discountAllowed":true,"timezone":"Europe/London","openDate":"2024-06-27T13:36:00.000Z","version":5994643755,"name":"D4 268m","eventName":"Kinsley 27th Jun"},"rc":[{"atb":[[1.01,23.66]],"id":62766534},{"atl":[[990,0.22]],"id":62766534},{"spn":495.5,"spf":"NaN","id":62766534},{"atb":[[1.03,7.88]],"id":39959056},{"atl":[[990,0.22]],"id":39959056},{"spn":495.51,"spf":"NaN","id":39959056},{"atb":[[1.01,23.66]],"id":40214683},{"atl":[[990,0.22]],"id":40214683},{"spn":495.5,"spf":"NaN","id":40214683},{"atb":[[1.03,7.88]],"id":56418091},{"atl":[[990,0.22]],"id":56418091},{"spn":495.51,"spf":"NaN","id":56418091},{"atb":[[1.02,11.83]],"id":69261147},{"atl":[[990,0.22]],"id":69261147},{"spn":495.51,"spf":"NaN","id":69261147},{"atb":[[1.03,7.88]],"id":70642246},{"atl":[[1000,0.22]],"id":70642246},{"spn":500.51,"spf":"NaN","id":70642246}],"con":true,"img":true}]}
{"op":"mcm","clk":"11537954927","pt":1719448682555,"mc":[{"id":"1.230178318","marketDefinition":{"bspMarket":true,"turnInPlayEnabled":false,"persistenceEnabled":false,"marketBaseRate":5.0,"eventId":"33376062","eventTypeId":"4339","numberOfWinners":1,"bettingType":"ODDS","marketType":"WIN","marketTime":"2024-06-27T15:28:00.000Z","suspendTime":"2024-06-27T15:28:00.000Z","bspReconciled":false,"complete":true,"inPlay":false,"crossMatching":false,"runnersVoidable":false,"numberOfActiveRunners":6,"betDelay":0,"status":"OPEN","runners":[{"status":"ACTIVE","sortPriority":1,"id":40214683,"name":"1. Corner Zoom"},{"status":"ACTIVE","sortPriority":2,"id":39959056,"name":"2. Endova Zoey"},{"status":"ACTIVE","sortPriority":3,"id":62766534,"name":"3. Glenvale Beau"},{"status":"ACTIVE","sortPriority":4,"id":69261147,"name":"4. Madam Tiger"},{"status":"ACTIVE","sortPriority":5,"id":70642246,"name":"5. Burgess Lana"},{"status":"ACTIVE","sortPriority":6,"id":56418091,"name":"6. Strike It Josie"}],"regulators":["MR_INT"],"venue":"Kinsley","countryCode":"GB","discountAllowed":true,"timezone":"Europe/London","openDate":"2024-06-27T13:36:00.000Z","version":5994643755,"name":"D4 268m","eventName":"Kinsley 27th Jun"},"rc":[{"atb":[[1.01,23.66]],"id":62766534},{"atl":[[990,0.22]],"id":62766534},{"spn":495.5,"spf":"NaN","id":62766534},{"atb":[[1.03,7.88]],"id":39959056},{"atl":[[990,0.22]],"id":39959056},{"spn":495.51,"spf":"NaN","id":39959056},{"atb":[[1.01,23.66]],"id":40214683},{"atl":[[990,0.22]],"id":40214683},{"spn":495.5,"spf":"NaN","id":40214683},{"atb":[[1.03,7.88]],"id":56418091},{"atl":[[990,0.22]],"id":56418091},{"spn":495.51,"spf":"NaN","id":56418091},{"atb":[[1.02,11.82]],"id":69261147},{"atl":[[990,0.22]],"id":69261147},{"spn":495.51,"spf":"NaN","id":69261147},{"atb":[[1.03,7.88]],"id":70642246},{"atl":[[1000,0.22]],"id":70642246},{"spn":500.51,"spf":"NaN","id":70642246}],"con":true,"img":true}]}
{"op":"mcm","clk":"11538170590","pt":1719454082538,"mc":[{"id":"1.230178318","marketDefinition":{"bspMarket":true,"turnInPlayEnabled":false,"persistenceEnabled":false,"marketBaseRate":5.0,"eventId":"33376062","eventTypeId":"4339","numberOfWinners":1,"bettingType":"ODDS","marketType":"WIN","marketTime":"2024-06-27T15:28:00.000Z","suspendTime":"2024-06-27T15:28:00.000Z","bspReconciled":false,"complete":true,"inPlay":false,"crossMatching":false,"runnersVoidable":false,"numberOfActiveRunners":6,"betDelay":0,"status":"OPEN","runners":[{"status":"ACTIVE","sortPriority":1,"id":40214683,"name":"1. Corner Zoom"},{"status":"ACTIVE","sortPriority":2,"id":39959056,"name":"2. Endova Zoey"},{"status":"ACTIVE","sortPriority":3,"id":62766534,"name":"3. Glenvale Beau"},{"status":"ACTIVE","sortPriority":4,"id":69261147,"name":"4. Madam Tiger"},{"status":"ACTIVE","sortPriority":5,"id":70642246,"name":"5. Burgess Lana"},{"status":"ACTIVE","sortPriority":6,"id":56418091,"name":"6. Strike It Josie"}],"regulators":["MR_INT"],"venue":"Kinsley","countryCode":"GB","discountAllowed":true,"timezone":"Europe/London","openDate":"2024-06-27T13:36:00.000Z","version":5994643755,"name":"D4 268m","eventName":"Kinsley 27th Jun"},"rc":[{"atb":[[1.01,23.67]],"id":62766534},{"atl":[[990,0.22]],"id":62766534},{"spn":495.5,"spf":"NaN","id":62766534},{"atb":[[1.03,7.88]],"id":39959056},{"atl":[[990,0.22]],"id":39959056},{"spn":495.51,"spf":"NaN","id":39959056},{"atb":[[1.01,23.67]],"id":40214683},{"atl":[[990,0.22]],"id":40214683},{"spn":495.5,"spf":"NaN","id":40214683},{"atb":[[1.03,7.88]],"id":56418091},{"atl":[[990,0.22]],"id":56418091},{"spn":495.51,"spf":"NaN","id":56418091},{"atb":[[1.02,11.83]],"id":69261147},{"atl":[[990,0.22]],"id":69261147},{"spn":495.51,"spf":"NaN","id":69261147},{"atb":[[1.03,7.88]],"id":70642246},{"atl":[[1000,0.22]],"id":70642246},{"spn":500.51,"spf":"NaN","id":70642246}],"con":true,"img":true}]}
{"op":"mcm","clk":"11538368248","pt":1719459482566,"mc":[{"id":"1.230178318","marketDefinition":{"bspMarket":true,"turnInPlayEnabled":false,"persistenceEnabled":false,"marketBaseRate":5.0,"eventId":"33376062","eventTypeId":"4339","numberOfWinners":1,"bettingType":"ODDS","marketType":"WIN","marketTime":"2024-06-27T15:28:00.000Z","suspendTime":"2024-06-27T15:28:00.000Z","bspReconciled":false,"complete":true,"inPlay":false,"crossMatching":false,"runnersVoidable":false,"numberOfActiveRunners":6,"betDelay":0,"status":"OPEN","runners":[{"status":"ACTIVE","sortPriority":1,"id":40214683,"name":"1. Corner Zoom"},{"status":"ACTIVE","sortPriority":2,"id":39959056,"name":"2. Endova Zoey"},{"status":"ACTIVE","sortPriority":3,"id":62766534,"name":"3. Glenvale Beau"},{"status":"ACTIVE","sortPriority":4,"id":69261147,"name":"4. Madam Tiger"},{"status":"ACTIVE","sortPriority":5,"id":70642246,"name":"5. Burgess Lana"},{"status":"ACTIVE","sortPriority":6,"id":56418091,"name":"6. Strike It Josie"}],"regulators":["MR_INT"],"venue":"Kinsley","countryCode":"GB","discountAllowed":true,"timezone":"Europe/London","openDate":"2024-06-27T13:36:00.000Z","version":5994643755,"name":"D4 268m","eventName":"Kinsley 27th Jun"},"rc":[{"atb":[[1.01,23.67]],"id":62766534},{"atl":[[990,0.22]],"id":62766534},{"spn":495.5,"spf":"NaN","id":62766534},{"atb":[[1.03,7.88]],"id":39959056},{"atl":[[990,0.22]],"id":39959056},{"spn":495.51,"spf":"NaN","id":39959056},{"atb":[[1.01,23.67]],"id":40214683},{"atl":[[990,0.22]],"id":40214683},{"spn":495.5,"spf":"NaN","id":40214683},{"atb":[[1.03,7.88]],"id":56418091},{"atl":[[990,0.22]],"id":56418091},{"spn":495.51,"spf":"NaN","id":56418091},{"atb":[[1.02,11.83]],"id":69261147},{"atl":[[990,0.22]],"id":69261147},{"spn":495.51,"spf":"NaN","id":69261147},{"atb":[[1.03,7.88]],"id":70642246},{"atl":[[1000,0.22]],"id":70642246},{"spn":500.51,"spf":"NaN","id":70642246}],"con":true,"img":true}]}
{"op":"mcm","clk":"11538595374","pt":1719464882537,"mc":[{"id":"1.230178318","marketDefinition":{"bspMarket":true,"turnInPlayEnabled":false,"persistenceEnabled":false,"marketBaseRate":5.0,"eventId":"33376062","eventTypeId":"4339","numberOfWinners":1,"bettingType":"ODDS","marketType":"WIN","marketTime":"2024-06-27T15:28:00.000Z","suspendTime":"2024-06-27T15:28:00.000Z","bspReconciled":false,"complete":true,"inPlay":false,"crossMatching":false,"runnersVoidable":false,"numberOfActiveRunners":6,"betDelay":0,"status":"OPEN","runners":[{"status":"ACTIVE","sortPriority":1,"id":40214683,"name":"1. Corner Zoom"},{"status":"ACTIVE","sortPriority":2,"id":39959056,"name":"2. Endova Zoey"},{"status":"ACTIVE","sortPriority":3,"id":62766534,"name":"3. Glenvale Beau"},{"status":"ACTIVE","sortPriority":4,"id":69261147,"name":"4. Madam Tiger"},{"status":"ACTIVE","sortPriority":5,"id":70642246,"name":"5. Burgess Lana"},{"status":"ACTIVE","sortPriority":6,"id":56418091,"name":"6. Strike It Josie"}],"regulators":["MR_INT"],"venue":"Kinsley","countryCode":"GB","discountAllowed":true,"timezone":"Europe/London","openDate":"2024-06-27T13:36:00.000Z","version":5994643755,"name":"D4 268m","eventName":"Kinsley 27th Jun"},"rc":[{"atb":[[1.01,23.67]],"id":62766534},{"atl":[[990,0.22]],"id":62766534},{"spn":495.5,"spf":"NaN","id":62766534},{"atb":[[1.03,7.88]],"id":39959056},{"atl":[[990,0.22]],"id":39959056},{"spn":495.51,"spf":"NaN","id":39959056},{"atb":[[1.01,23.67]],"id":40214683},{"atl":[[990,0.22]],"id":40214683},{"spn":495.5,"spf":"NaN","id":40214683},{"atb":[[1.03,7.88]],"id":56418091},{"atl":[[990,0.22]],"id":56418091},{"spn":495.51,"spf":"NaN","id":56418091},{"atb":[[1.02,11.83]],"id":69261147},{"atl":[[990,0.22]],"id":69261147},{"spn":495.51,"spf":"NaN","id":69261147},{"atb":[[1.03,7.88]],"id":70642246},{"atl":[[1000,0.22]],"id":70642246},{"spn":500.51,"spf":"NaN","id":70642246}],"con":true,"img":true}]}
{"op":"mcm","clk":"11538748620","pt":1719468204821,"mc":[{"id":"1.230178318","rc":[{"atb":[[1.01,23.67],[2.08,8.88]],"id":62766534},{"spn":496.04,"spf":"NaN","id":62766534},{"atb":[[1.03,7.88],[2.06,12.32]],"id":39959056},{"spn":496.03,"spf":"NaN","id":39959056},{"atb":[[2,12.82],[1.01,23.67]],"id":40214683},{"spn":496.0,"spf":"NaN","id":40214683},{"atb":[[1.03,7.88],[2.08,9.77]],"id":56418091},{"spn":496.04,"spf":"NaN","id":56418091},{"atb":[[1.02,11.83],[2.1,9.86]],"id":69261147},{"spn":496.05,"spf":"NaN","id":69261147},{"atb":[[2,10.25],[1.03,7.88]],"id":70642246},{"spn":501.0,"spf":"NaN","id":70642246}],"con":true,"img":false}]}
{"op":"mcm","clk":"11538750641","pt":1719468246951,"mc":[{"id":"1.230178318","rc":[{"atb":[[2.02,3.16]],"id":40214683}],"con":true,"img":false}]}
{"op":"mcm","clk":"11538750648","pt":1719468247058,"mc":[{"id":"1.230178318","rc":[{"atb":[[2.08,3.16]],"id":39959056}],"con":true,"img":false}]}
{"op":"mcm","clk":"11538750668","pt":1719468247465,"mc":[{"id":"1.230178318","rc":[{"atb":[[2.12,3.16]],"id":69261147}],"con":true,"img":false}]}
{"op":"mcm","clk":"11538750683","pt":1719468247670,"mc":[{"id":"1.230178318","rc":[{"atb":[[2.1,3.16]],"id":62766534}],"con":true,"img":false}]}
{"op":"mcm","clk":"11538750713","pt":1719468248283,"mc":[{"id":"1.230178318","rc":[{"atb":[[2.02,3.16]],"id":70642246}],"con":true,"img":false}]}
{"op":"mcm","clk":"11538750724","pt":1719468248440,"mc":[{"id":"1.230178318","rc":[{"atb":[[2.1,3.16]],"id":56418091}],"con":true,"img":false}]}
{"op":"mcm","clk":"11538752633","pt":1719468286308,"mc":[{"id":"1.230178318","rc":[{"atb":[[2.1,6.55]],"id":62766534},{"spn":496.05,"spf":"NaN","id":62766534},{"spn":496.04,"spf":"NaN","id":39959056},{"spn":496.01,"spf":"NaN","id":40214683},{"spn":496.05,"spf":"NaN","id":56418091},{"spn":496.06,"spf":"NaN","id":69261147},{"spn":501.01,"spf":"NaN","id":70642246}],"con":true,"img":false}]}
{"op":"mcm","clk":"11538752639","pt":1719468286410,"mc":[{"id":"1.230178318","rc":[{"atb":[[2.02,6.55]],"id":40214683}],"con":true,"img":false}]}
{"op":"mcm","clk":"11538752692","pt":1719468287386,"mc":[{"id":"1.230178318","rc":[{"atb":[[2.08,6.55]],"id":39959056}],"con":true,"img":false}]}
{"op":"mcm","clk":"11538752714","pt":1719468287795,"mc":[{"id":"1.230178318","rc":[{"atb":[[2.12,6.55]],"id":69261147}],"con":true,"img":false}]}
{"op":"mcm","clk":"11538752724","pt":1719468288001,"mc":[{"id":"1.230178318","rc":[{"atb":[[2.02,6.55]],"id":70642246}],"con":true,"img":false}]}
{"op":"mcm","clk":"11538752775","pt":1719468288918,"mc":[{"id":"1.230178318","rc":[{"atb":[[2.1,6.55]],"id":56418091}],"con":true,"img":false}]}
{"op":"mcm","clk":"11538754057","pt":1719468311791,"mc":[{"id":"1.230178318","marketDefinition":{"bspMarket":true,"turnInPlayEnabled":false,"persistenceEnabled":false,"marketBaseRate":5.0,"eventId":"33376062","eventTypeId":"4339","numberOfWinners":1,"bettingType":"ODDS","marketType":"WIN","marketTime":"2024-06-27T15:28:00.000Z","suspendTime":"2024-06-27T15:28:00.000Z","bspReconciled":false,"complete":true,"inPlay":false,"crossMatching":true,"runnersVoidable":false,"numberOfActiveRunners":6,"betDelay":0,"status":"OPEN","runners":[{"status":"ACTIVE","sortPriority":1,"id":40214683,"name":"1. Corner Zoom"},{"status":"ACTIVE","sortPriority":2,"id":39959056,"name":"2. Endova Zoey"},{"status":"ACTIVE","sortPriority":3,"id":62766534,"name":"3. Glenvale Beau"},{"status":"ACTIVE","sortPriority":4,"id":69261147,"name":"4. Madam Tiger"},{"status":"ACTIVE","sortPriority":5,"id":70642246,"name":"5. Burgess Lana"},{"status":"ACTIVE","sortPriority":6,"id":56418091,"name":"6. Strike It Josie"}],"regulators":["MR_INT"],"venue":"Kinsley","countryCode":"GB","discountAllowed":true,"timezone":"Europe/London","openDate":"2024-06-27T13:36:00.000Z","version":5994643755,"name":"D4 268m","eventName":"Kinsley 27th Jun"},"rc":[],"con":true,"img":false}]}
{"op":"mcm","clk":"11538825552","pt":1719469704884,"mc":[{"id":"1.230178318","rc":[{"atl":[[150,4]],"id":62766534},{"spn":76.05,"spf":"NaN","id":62766534},{"atl":[[150,4]],"id":39959056},{"spn":76.04,"spf":"NaN","id":39959056},{"atl":[[150,4]],"id":40214683},{"spn":76.01,"spf":"NaN","id":40214683},{"atl":[[150,4]],"id":56418091},{"spn":76.05,"spf":"NaN","id":56418091},{"atl":[[150,4]],"id":69261147},{"spn":76.06,"spf":"NaN","id":69261147},{"atl":[[150,4]],"id":70642246},{"spn":76.01,"spf":"NaN","id":70642246}],"con":true,"img":false}]}
{"op":"mcm","clk":"11538937263","pt":1719472049273,"mc":[{"id":"1.230178318","rc":[{"atb":[[1.01,23.65],[2.1,6.54],[2.08,8.88]],"id":62766534},{"atl":[[21,4],[11.5,2],[990,0.22],[15.5,3]],"id":62766534},{"spn":6.8,"spf":"NaN","id":62766534},{"atb":[[2.06,12.31],[1.03,7.88],[2.08,6.54]],"id":39959056},{"atl":[[990,0.22]],"id":39959056},{"atb":[[2,12.81],[2.02,6.54],[1.01,23.65]],"id":40214683},{"atl":[[990,0.22]],"id":40214683},{"atb":[[1.03,7.88],[2.1,6.54],[2.08,9.76]],"id":56418091},{"atl":[[990,0.22]],"id":56418091},{"atb":[[1.02,11.82],[2.12,6.54],[2.1,9.86]],"id":69261147},{"atl":[[990,0.22]],"id":69261147},{"atb":[[2,10.25],[2.02,6.54],[1.03,7.88]],"id":70642246},{"atl":[[1000,0.22]],"id":70642246}],"con":true,"img":false}]}
{"op":"mcm","clk":"11538940630","pt":1719472111771,"mc":[{"id":"1.230178318","rc":[{"atb":[[2.08,0]],"id":62766534},{"atb":[[2.06,0]],"id":39959056},{"atb":[[2,0]],"id":40214683},{"atb":[[2.08,0]],"id":56418091},{"atb":[[2.1,0]],"id":69261147},{"atb":[[2,0]],"id":70642246}],"con":true,"img":false}]}
{"op":"mcm","clk":"11538940638","pt":1719472111873,"mc":[{"id":"1.230178318","rc":[{"atb":[[2.12,8.88]],"id":62766534},{"atb":[[2.1,12.31]],"id":39959056},{"atb":[[2.04,12.81]],"id":40214683},{"atb":[[2.12,9.76]],"id":56418091},{"atb":[[2.14,9.86]],"id":69261147},{"atb":[[2.04,10.25]],"id":70642246}],"con":true,"img":false}]}
{"op":"mcm","clk":"11538943238","pt":1719472152305,"mc":[{"id":"1.230178318","rc":[{"atb":[[2.08,3.38]],"id":39959056}],"con":true,"img":false}]}
{"op":"mcm","clk":"11538943254","pt":1719472152614,"mc":[{"id":"1.230178318","rc":[{"atb":[[2.1,3.38]],"id":56418091}],"con":true,"img":false}]}
{"op":"mcm","clk":"11538943287","pt":1719472153226,"mc":[{"id":"1.230178318","rc":[{"atb":[[2.02,3.38]],"id":70642246}],"con":true,"img":false}]}
{"op":"mcm","clk":"11538943328","pt":1719472153902,"mc":[{"id":"1.230178318","rc":[{"atb":[[2.06,3.16]],"id":70642246}],"con":true,"img":false}]}
{"op":"mcm","clk":"11538943345","pt":1719472154107,"mc":[{"id":"1.230178318","rc":[{"atb":[[2.1,3.38]],"id":62766534}],"con":true,"img":false}]}
{"op":"mcm","clk":"11538943365","pt":1719472154513,"mc":[{"id":"1.230178318","rc":[{"atb":[[2.14,3.16]],"id":56418091}],"con":true,"img":false}]}
{"op":"mcm","clk":"11538943380","pt":1719472154720,"mc":[{"id":"1.230178318","rc":[{"atb":[[2.12,3.16]],"id":39959056}],"con":true,"img":false}]}
{"op":"mcm","clk":"11538943411","pt":1719472155129,"mc":[{"id":"1.230178318","rc":[{"atb":[[2.14,3.16]],"id":62766534}],"con":true,"img":false}]}
{"op":"mcm","clk":"11538943496","pt":1719472156411,"mc":[{"id":"1.230178318","rc":[{"atb":[[2.12,3.38]],"id":69261147}],"con":true,"img":false}]}
{"op":"mcm","clk":"11538943549","pt":1719472157431,"mc":[{"id":"1.230178318","rc":[{"atb":[[2.02,3.38]],"id":40214683}],"con":true,"img":false}]}
{"op":"mcm","clk":"11538943615","pt":1719472158913,"mc":[{"id":"1.230178318","rc":[{"atb":[[2.16,3.16]],"id":69261147}],"con":true,"img":false}]}
{"op":"mcm","clk":"11538943700","pt":1719472160549,"mc":[{"id":"1.230178318","rc":[{"atb":[[2.06,3.16]],"id":40214683}],"con":true,"img":false}]}
{"op":"mcm","clk":"11538944180","pt":1719472168247,"mc":[{"id":"1.230178318","rc":[{"atb":[[2.02,0]],"id":40214683}],"con":true,"img":false}]}
{"op":"mcm","clk":"11538944192","pt":1719472168451,"mc":[{"id":"1.230178318","rc":[{"atb":[[2.08,0]],"id":39959056}],"con":true,"img":false}]}
{"op":"mcm","clk":"11538944202","pt":1719472168654,"mc":[{"id":"1.230178318","rc":[{"atb":[[2.1,0]],"id":62766534}],"con":true,"img":false}]}
{"op":"mcm","clk":"11538944219","pt":1719472168912,"mc":[{"id":"1.230178318","rc":[{"atb":[[2.02,0]],"id":70642246}],"con":true,"img":false}]}
{"op":"mcm","clk":"11538944235","pt":1719472169220,"mc":[{"id":"1.230178318","rc":[{"atb":[[2.1,0]],"id":56418091}],"con":true,"img":false}]}
{"op":"mcm","clk":"11538944283","pt":1719472170036,"mc":[{"id":"1.230178318","rc":[{"atb":[[2.12,0]],"id":69261147}],"con":true,"img":false}]}
{"op":"mcm","clk":"11538945230","pt":1719472185770,"mc":[{"id":"1.230178318","rc":[{"spn":6.82,"spf":"NaN","id":62766534},{"atb":[[2.12,6.54]],"id":39959056},{"spn":76.06,"spf":"NaN","id":39959056},{"spn":76.03,"spf":"NaN","id":40214683},{"spn":76.07,"spf":"NaN","id":56418091},{"spn":76.08,"spf":"NaN","id":69261147},{"spn":76.03,"spf":"NaN","id":70642246}],"con":true,"img":false}]}
{"op":"mcm","clk":"11538945313","pt":1719472187049,"mc":[{"id":"1.230178318","rc":[{"atb":[[2.14,6.54]],"id":62766534}],"con":true,"img":false}]}
{"op":"mcm","clk":"11538945406","pt":1719472188789,"mc":[{"id":"1.230178318","rc":[{"atb":[[2.06,6.54]],"id":40214683}],"con":true,"img":false}]}
{"op":"mcm","clk":"11538945494","pt":1719472190282,"mc":[{"id":"1.230178318","rc":[{"atb":[[2.06,6.54]],"id":70642246}],"con":true,"img":false}]}
{"op":"mcm","clk":"11538945529","pt":1719472190791,"mc":[{"id":"1.230178318","rc":[{"atb":[[2.14,6.54]],"id":56418091}],"con":true,"img":false}]}
{"op":"mcm","clk":"11538945592","pt":1719472191674,"mc":[{"id":"1.230178318","rc":[{"atb":[[2.16,6.54]],"id":69261147}],"con":true,"img":false}]}
{"op":"mcm","clk":"11539122521","pt":1719475682544,"mc":[{"id":"1.230178318","marketDefinition":{"bspMarket":true,"turnInPlayEnabled":false,"persistenceEnabled":false,"marketBaseRate":5.0,"eventId":"33376062","eventTypeId":"4339","numberOfWinners":1,"bettingType":"ODDS","marketType":"WIN","marketTime":"2024-06-27T15:28:00.000Z","suspendTime":"2024-06-27T15:28:00.000Z","bspReconciled":false,"complete":true,"inPlay":false,"crossMatching":true,"runnersVoidable":false,"numberOfActiveRunners":6,"betDelay":0,"status":"OPEN","runners":[{"status":"ACTIVE","sortPriority":1,"id":40214683,"name":"1. Corner Zoom"},{"status":"ACTIVE","sortPriority":2,"id":39959056,"name":"2. Endova Zoey"},{"status":"ACTIVE","sortPriority":3,"id":62766534,"name":"3. Glenvale Beau"},{"status":"ACTIVE","sortPriority":4,"id":69261147,"name":"4. Madam Tiger"},{"status":"ACTIVE","sortPriority":5,"id":70642246,"name":"5. Burgess Lana"},{"status":"ACTIVE","sortPriority":6,"id":56418091,"name":"6. Strike It Josie"}],"regulators":["MR_INT"],"venue":"Kinsley","countryCode":"GB","discountAllowed":true,"timezone":"Europe/London","openDate":"2024-06-27T13:36:00.000Z","version":5994643755,"name":"D4 268m","eventName":"Kinsley 27th Jun"},"rc":[{"atb":[[1.01,23.66],[2.12,8.88],[2.14,6.55]],"id":62766534},{"atl":[[150,4],[21,4],[11.5,2],[990,0.22],[15.5,3]],"id":62766534},{"spn":6.82,"spf":"NaN","id":62766534},{"atb":[[1.03,7.88],[2.12,6.55],[2.1,12.31]],"id":39959056},{"atl":[[150,4],[990,0.22]],"id":39959056},{"spn":76.06,"spf":"NaN","id":39959056},{"atb":[[1.01,23.66],[2.06,6.55],[2.04,12.81]],"id":40214683},{"atl":[[150,4],[990,0.22]],"id":40214683},{"spn":76.03,"spf":"NaN","id":40214683},{"atb":[[1.03,7.88],[2.12,9.77],[2.14,6.55]],"id":56418091},{"atl":[[150,4],[990,0.22]],"id":56418091},{"spn":76.07,"spf":"NaN","id":56418091},{"atb":[[1.02,11.82],[2.16,6.55],[2.14,9.86]],"id":69261147},{"atl":[[150,4],[990,0.22]],"id":69261147},{"spn":76.08,"spf":"NaN","id":69261147},{"atb":[[2.06,6.55],[1.03,7.88],[2.04,10.25]],"id":70642246},{"atl":[[150,4],[1000,0.22]],"id":70642246},{"spn":76.03,"spf":"NaN","id":70642246}],"con":true,"img":true}]}
{"op":"mcm","clk":"11539127948","pt":1719475711790,"mc":[{"id":"1.230178318","rc":[{"atb":[[1.01,23.66],[2.12,0],[2.14,6.55]],"id":62766534},{"atb":[[1.03,7.88],[2.12,6.55],[2.1,0]],"id":39959056},{"atb":[[1.01,23.66],[2.06,6.55],[2.04,0]],"id":40214683},{"atb":[[1.03,7.88],[2.12,0],[2.14,6.55]],"id":56418091},{"atb":[[1.02,11.82],[2.16,6.55],[2.14,0]],"id":69261147},{"atb":[[2.06,6.55],[1.03,7.88],[2.04,0]],"id":70642246}],"con":true,"img":false}]}
{"op":"mcm","clk":"11539127954","pt":1719475711892,"mc":[{"id":"1.230178318","rc":[{"atb":[[2.16,8.88]],"id":62766534},{"atb":[[2.14,12.31]],"id":39959056},{"atb":[[2.08,12.81]],"id":40214683},{"atb":[[2.16,9.77]],"id":56418091},{"atb":[[2.18,9.86]],"id":69261147},{"atb":[[2.08,10.25]],"id":70642246}],"con":true,"img":false}]}
{"op":"mcm","clk":"11539133811","pt":1719475803999,"mc":[{"id":"1.230178318","rc":[{"spn":6.83,"spf":"NaN","id":62766534},{"spn":76.07,"spf":"NaN","id":39959056},{"atb":[[2.06,3.16]],"id":40214683},{"spn":76.04,"spf":"NaN","id":40214683},{"spn":76.08,"spf":"NaN","id":56418091},{"spn":76.09,"spf":"NaN","id":69261147},{"spn":76.04,"spf":"NaN","id":70642246}],"con":true,"img":false}]}
{"op":"mcm","clk":"11539133817","pt":1719475804098,"mc":[{"id":"1.230178318","rc":[{"atb":[[2.12,3.16]],"id":39959056}],"con":true,"img":false}]}
{"op":"mcm","clk":"11539133835","pt":1719475804304,"mc":[{"id":"1.230178318","rc":[{"atb":[[2.14,3.16]],"id":62766534}],"con":true,"img":false}]}
{"op":"mcm","clk":"11539133843","pt":1719475804405,"mc":[{"id":"1.230178318","rc":[{"atb":[[2.16,3.16]],"id":69261147}],"con":true,"img":false}]}
{"op":"mcm","clk":"11539133887","pt":1719475804816,"mc":[{"id":"1.230178318","rc":[{"atb":[[2.14,3.16]],"id":56418091}],"con":true,"img":false}]}
{"op":"mcm","clk":"11539133940","pt":1719475805485,"mc":[{"id":"1.230178318","rc":[{"atb":[[2.06,3.16]],"id":70642246}],"con":true,"img":false}]}
{"op":"mcm","clk":"11539134089","pt":1719475807589,"mc":[{"id":"1.230178318","rc":[{"atb":[[2.1,3.38]],"id":40214683}],"con":true,"img":false}]}
{"op":"mcm","clk":"11539134181","pt":1719475808833,"mc":[{"id":"1.230178318","rc":[{"atb":[[2.16,3.38]],"id":39959056}],"con":true,"img":false}]}
{"op":"mcm","clk":"11539134194","pt":1719475809137,"mc":[{"id":"1.230178318","rc":[{"atb":[[2.2,3.38]],"id":69261147}],"con":true,"img":false}]}
{"op":"mcm","clk":"11539134227","pt":1719475809605,"mc":[{"id":"1.230178318","rc":[{"atb":[[2.18,3.38]],"id":62766534}],"con":true,"img":false}]}
{"op":"mcm","clk":"11539134377","pt":1719475811512,"mc":[{"id":"1.230178318","rc":[{"atb":[[2.1,3.38]],"id":70642246}],"con":true,"img":false}]}
{"op":"mcm","clk":"11539134401","pt":1719475811818,"mc":[{"id":"1.230178318","rc":[{"atb":[[2.14,0]],"id":62766534},{"atb":[[2.12,0]],"id":39959056},{"atb":[[2.06,0]],"id":40214683},{"atb":[[2.14,0]],"id":56418091},{"atb":[[2.16,0]],"id":69261147},{"atb":[[2.06,0]],"id":70642246}],"con":true,"img":false}]}
{"op":"mcm","clk":"11539134511","pt":1719475813831,"mc":[{"id":"1.230178318","rc":[{"atb":[[2.18,3.38]],"id":56418091}],"con":true,"img":false}]}
{"op":"mcm","clk":"11539153470","pt":1719476119697,"mc":[{"id":"1.230178318","rc":[{"spn":6.84,"spf":"NaN","id":62766534},{"atb":[[2.16,6.55]],"id":39959056},{"spn":76.08,"spf":"NaN","id":39959056},{"spn":76.05,"spf":"NaN","id":40214683},{"spn":76.09,"spf":"NaN","id":56418091},{"spn":76.1,"spf":"NaN","id":69261147},{"spn":76.05,"spf":"NaN","id":70642246}],"con":true,"img":false}]}
{"op":"mcm","clk":"11539153478","pt":1719476119804,"mc":[{"id":"1.230178318","rc":[{"atb":[[2.1,6.55]],"id":40214683}],"con":true,"img":false}]}
{"op":"mcm","clk":"11539153494","pt":1719476120011,"mc":[{"id":"1.230178318","rc":[{"atb":[[2.2,6.55]],"id":69261147},{"atb":[[2.1,6.55]],"id":70642246}],"con":true,"img":false}]}
{"op":"mcm","clk":"11539153566","pt":1719476120992,"mc":[{"id":"1.230178318","rc":[{"atb":[[2.18,6.55]],"id":62766534}],"con":true,"img":false}]}
{"op":"mcm","clk":"11539153581","pt":1719476121203,"mc":[{"id":"1.230178318","rc":[{"atb":[[2.18,6.55]],"id":56418091}],"con":true,"img":false}]}
{"op":"mcm","clk":"11539341427","pt":1719479310554,"mc":[{"id":"1.230178318","rc":[{"atb":[[1.01,23.66],[2.18,6.54],[2.16,0]],"id":62766534},{"atb":[[1.03,7.88],[2.16,6.54],[2.14,0]],"id":39959056},{"atb":[[1.01,23.66],[2.1,6.54],[2.08,0]],"id":40214683},{"atb":[[1.03,7.88],[2.18,6.54],[2.16,0]],"id":56418091},{"atb":[[1.02,11.82],[2.18,0],[2.2,6.54]],"id":69261147},{"atb":[[1.03,7.88],[2.1,6.54],[2.08,0]],"id":70642246}],"con":true,"img":false}]}
{"op":"mcm","clk":"11539341430","pt":1719479310655,"mc":[{"id":"1.230178318","rc":[{"atb":[[2.2,8.88]],"id":62766534},{"atb":[[2.18,12.31]],"id":39959056},{"atb":[[2.12,12.81]],"id":40214683},{"atb":[[2.2,9.77]],"id":56418091},{"atb":[[2.22,9.86]],"id":69261147},{"atb":[[2.12,10.25]],"id":70642246}],"con":true,"img":false}]}
{"op":"mcm","clk":"11539346913","pt":1719479399062,"mc":[{"id":"1.230178318","rc":[{"spn":6.85,"spf":"NaN","id":62766534},{"spn":76.09,"spf":"NaN","id":39959056},{"atb":[[2.1,3.38]],"id":40214683},{"spn":76.06,"spf":"NaN","id":40214683},{"spn":76.1,"spf":"NaN","id":56418091},{"spn":76.11,"spf":"NaN","id":69261147},{"spn":76.06,"spf":"NaN","id":70642246}],"con":true,"img":false}]}
{"op":"mcm","clk":"11539347023","pt":1719479400780,"mc":[{"id":"1.230178318","rc":[{"atb":[[2.16,3.38]],"id":39959056}],"con":true,"img":false}]}
{"op":"mcm","clk":"11539347034","pt":1719479400990,"mc":[{"id":"1.230178318","rc":[{"atb":[[2.1,3.38]],"id":70642246}],"con":true,"img":false}]}
{"op":"mcm","clk":"11539347044","pt":1719479401093,"mc":[{"id":"1.230178318","rc":[{"atb":[[2.2,3.38]],"id":69261147}],"con":true,"img":false}]}
{"op":"mcm","clk":"11539347095","pt":1719479401872,"mc":[{"id":"1.230178318","rc":[{"atb":[[2.18,3.38]],"id":56418091}],"con":true,"img":false}]}
{"op":"mcm","clk":"11539347149","pt":1719479402496,"mc":[{"id":"1.230178318","rc":[{"atb":[[2.18,3.38]],"id":62766534}],"con":true,"img":false}]}
{"op":"mcm","clk":"11539349334","pt":1719479436805,"mc":[{"id":"1.230178318","rc":[{"atb":[[2.16,0]],"id":39959056}],"con":true,"img":false}]}
{"op":"mcm","clk":"11539349353","pt":1719479437114,"mc":[{"id":"1.230178318","rc":[{"atb":[[2.1,0]],"id":40214683}],"con":true,"img":false}]}
{"op":"mcm","clk":"11539349372","pt":1719479437421,"mc":[{"id":"1.230178318","rc":[{"atb":[[2.1,0]],"id":70642246}],"con":true,"img":false}]}
{"op":"mcm","clk":"11539349398","pt":1719479437936,"mc":[{"id":"1.230178318","rc":[{"atb":[[2.18,0]],"id":62766534},{"atb":[[2.2,0]],"id":69261147}],"con":true,"img":false}]}
{"op":"mcm","clk":"11539349420","pt":1719479438248,"mc":[{"id":"1.230178318","rc":[{"atb":[[2.18,0]],"id":56418091}],"con":true,"img":false}]}
{"op":"mcm","clk":"11539349568","pt":1719479440727,"mc":[{"id":"1.230178318","rc":[{"atb":[[2.2,3.38]],"id":39959056}],"con":true,"img":false}]}
{"op":"mcm","clk":"11539349589","pt":1719479441035,"mc":[{"id":"1.230178318","rc":[{"atb":[[2.24,3.38]],"id":69261147}],"con":true,"img":false}]}
{"op":"mcm","clk":"11539349610","pt":1719479441298,"mc":[{"id":"1.230178318","rc":[{"atb":[[2.22,3.38]],"id":62766534}],"con":true,"img":false}]}
{"op":"mcm","clk":"11539349630","pt":1719479441606,"mc":[{"id":"1.230178318","rc":[{"atb":[[2.14,3.38]],"id":40214683}],"con":true,"img":false}]}
{"op":"mcm","clk":"11539349649","pt":1719479441916,"mc":[{"id":"1.230178318","rc":[{"atb":[[2.14,3.38]],"id":70642246}],"con":true,"img":false}]}
{"op":"mcm","clk":"11539349665","pt":1719479442230,"mc":[{"id":"1.230178318","rc":[{"atb":[[2.22,3.38]],"id":56418091}],"con":true,"img":false}]}
{"op":"mcm","clk":"11539367870","pt":1719479709578,"mc":[{"id":"1.230178318","rc":[{"spn":6.86,"spf":"NaN","id":62766534},{"spn":76.1,"spf":"NaN","id":39959056},{"atb":[[2.14,6.54]],"id":40214683},{"spn":76.07,"spf":"NaN","id":40214683},{"spn":76.11,"spf":"NaN","id":56418091},{"spn":76.12,"spf":"NaN","id":69261147},{"spn":76.07,"spf":"NaN","id":70642246}],"con":true,"img":false}]}
{"op":"mcm","clk":"11539367888","pt":1719479709785,"mc":[{"id":"1.230178318","rc":[{"atb":[[2.2,6.54]],"id":39959056}],"con":true,"img":false}]}
{"op":"mcm","clk":"11539367985","pt":1719479710919,"mc":[{"id":"1.230178318","rc":[{"atb":[[2.22,6.54]],"id":62766534}],"con":true,"img":false}]}
{"op":"mcm","clk":"11539368037","pt":1719479711489,"mc":[{"id":"1.230178318","rc":[{"atb":[[2.14,6.54]],"id":70642246}],"con":true,"img":false}]}
{"op":"mcm","clk":"11539368116","pt":1719479712475,"mc":[{"id":"1.230178318","rc":[{"atb":[[2.22,6.54]],"id":56418091}],"con":true,"img":false}]}
{"op":"mcm","clk":"11539368148","pt":1719479712885,"mc":[{"id":"1.230178318","rc":[{"atb":[[2.24,6.54]],"id":69261147}],"con":true,"img":false}]}
{"op":"mcm","clk":"11539545272","pt":1719482907946,"mc":[{"id":"1.230178318","rc":[{"atb":[[1.01,23.65],[2.22,6.54],[2.2,0]],"id":62766534},{"atb":[[1.03,7.88],[2.18,0],[2.2,6.54]],"id":39959056},{"atb":[[1.01,23.65],[2.12,0],[2.14,6.54]],"id":40214683},{"atb":[[1.03,7.88],[2.22,6.54],[2.2,0]],"id":56418091},{"atb":[[2.24,6.54],[2.22,0],[1.02,11.82]],"id":69261147},{"atb":[[1.03,7.88],[2.12,0],[2.14,6.54]],"id":70642246}],"con":true,"img":false}]}
{"op":"mcm","clk":"11539545278","pt":1719482908047,"mc":[{"id":"1.230178318","rc":[{"atb":[[2.24,8.88]],"id":62766534},{"atb":[[2.22,12.31]],"id":39959056},{"atb":[[2.16,12.81]],"id":40214683},{"atb":[[2.24,9.76]],"id":56418091},{"atb":[[2.26,9.86]],"id":69261147},{"atb":[[2.16,10.25]],"id":70642246}],"con":true,"img":false}]}
{"op":"mcm","clk":"11539548537","pt":1719482957719,"mc":[{"id":"1.230178318","rc":[{"atb":[[2.24,3.16]],"id":69261147}],"con":true,"img":false}]}
{"op":"mcm","clk":"11539548572","pt":1719482958336,"mc":[{"id":"1.230178318","rc":[{"atb":[[2.14,3.16]],"id":40214683}],"con":true,"img":false}]}
{"op":"mcm","clk":"11539548615","pt":1719482959007,"mc":[{"id":"1.230178318","rc":[{"atb":[[2.22,3.16]],"id":62766534}],"con":true,"img":false}]}
{"op":"mcm","clk":"11539548633","pt":1719482959316,"mc":[{"id":"1.230178318","rc":[{"atb":[[2.22,3.16]],"id":56418091}],"con":true,"img":false}]}
{"op":"mcm","clk":"11539548656","pt":1719482959626,"mc":[{"id":"1.230178318","rc":[{"atb":[[2.2,3.16]],"id":39959056},{"atb":[[2.14,3.16]],"id":70642246}],"con":true,"img":false}]}
{"op":"mcm","clk":"11539548909","pt":1719482963854,"mc":[{"id":"1.230178318","rc":[{"atb":[[2.28,3.38]],"id":69261147}],"con":true,"img":false}]}
{"op":"mcm","clk":"11539549043","pt":1719482965918,"mc":[{"id":"1.230178318","rc":[{"atb":[[2.18,3.38]],"id":40214683}],"con":true,"img":false}]}
{"op":"mcm","clk":"11539549088","pt":1719482966756,"mc":[{"id":"1.230178318","rc":[{"atb":[[2.26,3.38]],"id":56418091}],"con":true,"img":false}]}
{"op":"mcm","clk":"11539549101","pt":1719482967054,"mc":[{"id":"1.230178318","rc":[{"atb":[[2.24,3.38]],"id":39959056}],"con":true,"img":false}]}
{"op":"mcm","clk":"11539549139","pt":1719482967625,"mc":[{"id":"1.230178318","rc":[{"atb":[[2.18,3.38]],"id":70642246}],"con":true,"img":false}]}
{"op":"mcm","clk":"11539549168","pt":1719482967934,"mc":[{"id":"1.230178318","rc":[{"atb":[[2.26,3.38]],"id":62766534}],"con":true,"img":false}]}
{"op":"mcm","clk":"11539553361","pt":1719483028684,"mc":[{"id":"1.230178318","rc":[{"atb":[[2.22,0]],"id":62766534},{"spn":6.88,"spf":"NaN","id":62766534},{"atb":[[2.2,0]],"id":39959056},{"spn":76.12,"spf":"NaN","id":39959056},{"atb":[[2.14,0]],"id":40214683},{"spn":76.09,"spf":"NaN","id":40214683},{"atb":[[2.22,0]],"id":56418091},{"spn":76.13,"spf":"NaN","id":56418091},{"atb":[[2.24,0]],"id":69261147},{"spn":76.14,"spf":"NaN","id":69261147},{"atb":[[2.14,0]],"id":70642246},{"spn":76.09,"spf":"NaN","id":70642246}],"con":true,"img":false}]}
{"op":"mcm","clk":"11539573026","pt":1719483323452,"mc":[{"id":"1.230178318","rc":[{"atb":[[2.26,6.54]],"id":56418091}],"con":true,"img":false}]}
{"op":"mcm","clk":"11539573075","pt":1719483323978,"mc":[{"id":"1.230178318","rc":[{"atb":[[2.18,6.54]],"id":40214683}],"con":true,"img":false}]}
{"op":"mcm","clk":"11539573103","pt":1719483324233,"mc":[{"id":"1.230178318","rc":[{"atb":[[2.18,6.54]],"id":70642246}],"con":true,"img":false}]}
{"op":"mcm","clk":"11539573122","pt":1719483324488,"mc":[{"id":"1.230178318","rc":[{"atb":[[2.28,6.54]],"id":69261147}],"con":true,"img":false}]}
{"op":"mcm","clk":"11539573208","pt":1719483325380,"mc":[{"id":"1.230178318","rc":[{"atb":[[2.24,6.54]],"id":39959056}],"con":true,"img":false}]}
{"op":"mcm","clk":"11539573355","pt":1719483326774,"mc":[{"id":"1.230178318","rc":[{"atb":[[2.26,6.54]],"id":62766534}],"con":true,"img":false}]}
{"op":"mcm","clk":"11539631486","pt":1719484087102,"mc":[{"id":"1.230178318","rc":[{"atl":[[40,12],[23,8]],"id":62766534},{"atl":[[46,12],[27,8]],"id":40214683},{"spn":14.59,"spf":"NaN","id":40214683}],"con":true,"img":false}]}
{"op":"mcm","clk":"11539749184","pt":1719485620136,"mc":[{"id":"1.230178318","rc":[{"atb":[[3.75,6]],"id":39959056},{"spn":76.87,"spf":"NaN","id":39959056},{"atb":[[2.44,6]],"id":40214683},{"spn":14.72,"spf":"NaN","id":40214683},{"atb":[[2.86,6]],"id":56418091},{"spn":76.43,"spf":"NaN","id":56418091},{"atb":[[4.1,6]],"id":69261147},{"spn":77.05,"spf":"NaN","id":69261147},{"atb":[[4.1,6]],"id":70642246},{"spn":77.05,"spf":"NaN","id":70642246}],"con":true,"img":false}]}
{"op":"mcm","clk":"11539749194","pt":1719485620238,"mc":[{"id":"1.230178318","rc":[{"atb":[[2.58,6]],"id":62766534}],"con":true,"img":false}]}
{"op":"mcm","clk":"11539750818","pt":1719485644364,"mc":[{"id":"1.230178318","rc":[{"atb":[[2.26,3.16]],"id":56418091}],"con":true,"img":false}]}
{"op":"mcm","clk":"11539750837","pt":1719485644574,"mc":[{"id":"1.230178318","rc":[{"atb":[[2.24,3.16]],"id":39959056},{"atb":[[2.28,3.16]],"id":69261147},{"atb":[[2.18,3.16]],"id":70642246}],"con":true,"img":false}]}
{"op":"mcm","clk":"11539750847","pt":1719485644672,"mc":[{"id":"1.230178318","rc":[{"atb":[[2.88,3.38]],"id":56418091}],"con":true,"img":false}]}
{"op":"mcm","clk":"11539751379","pt":1719485652908,"mc":[{"id":"1.230178318","rc":[{"atb":[[2.26,0]],"id":56418091}],"con":true,"img":false}]}
{"op":"mcm","clk":"11539751394","pt":1719485653107,"mc":[{"id":"1.230178318","rc":[{"atb":[[2.24,0]],"id":39959056},{"atb":[[2.28,0]],"id":69261147},{"atb":[[2.18,0]],"id":70642246}],"con":true,"img":false}]}
{"op":"mcm","clk":"11539751408","pt":1719485653349,"mc":[{"id":"1.230178318","rc":[{"atb":[[2.88,6.54]],"id":56418091}],"con":true,"img":false}]}
{"op":"mcm","clk":"11539810794","pt":1719486482531,"mc":[{"id":"1.230178318","marketDefinition":{"bspMarket":true,"turnInPlayEnabled":false,"persistenceEnabled":false,"marketBaseRate":5.0,"eventId":"33376062","eventTypeId":"4339","numberOfWinners":1,"bettingType":"ODDS","marketType":"WIN","marketTime":"2024-06-27T15:28:00.000Z","suspendTime":"2024-06-27T15:28:00.000Z","bspReconciled":false,"complete":true,"inPlay":false,"crossMatching":true,"runnersVoidable":false,"numberOfActiveRunners":6,"betDelay":0,"status":"OPEN","runners":[{"status":"ACTIVE","sortPriority":1,"id":40214683,"name":"1. Corner Zoom"},{"status":"ACTIVE","sortPriority":2,"id":39959056,"name":"2. Endova Zoey"},{"status":"ACTIVE","sortPriority":3,"id":62766534,"name":"3. Glenvale Beau"},{"status":"ACTIVE","sortPriority":4,"id":69261147,"name":"4. Madam Tiger"},{"status":"ACTIVE","sortPriority":5,"id":70642246,"name":"5. Burgess Lana"},{"status":"ACTIVE","sortPriority":6,"id":56418091,"name":"6. Strike It Josie"}],"regulators":["MR_INT"],"venue":"Kinsley","countryCode":"GB","discountAllowed":true,"timezone":"Europe/London","openDate":"2024-06-27T13:36:00.000Z","version":5994643755,"name":"D4 268m","eventName":"Kinsley 27th Jun"},"rc":[{"atb":[[2.24,8.88],[1.01,23.66],[2.58,6],[2.26,6.54]],"id":62766534},{"atl":[[150,4],[40,12],[21,4],[11.5,2],[23,8],[990,0.22],[15.5,3]],"id":62766534},{"spn":7.04,"spf":"NaN","id":62766534},{"atb":[[1.03,7.88],[2.22,12.31],[3.75,6]],"id":39959056},{"atl":[[150,4],[990,0.22]],"id":39959056},{"spn":76.87,"spf":"NaN","id":39959056},{"atb":[[1.01,23.66],[2.44,6],[2.18,6.54],[2.16,12.81]],"id":40214683},{"atl":[[150,4],[46,12],[27,8],[990,0.22]],"id":40214683},{"spn":14.72,"spf":"NaN","id":40214683},{"atb":[[2.24,9.77],[2.88,6.54],[2.86,6],[1.03,7.88]],"id":56418091},{"atl":[[150,4],[990,0.22]],"id":56418091},{"spn":76.44,"spf":"NaN","id":56418091},{"atb":[[4.1,6],[1.02,11.82],[2.26,9.86]],"id":69261147},{"atl":[[150,4],[990,0.22]],"id":69261147},{"spn":77.05,"spf":"NaN","id":69261147},{"atb":[[1.03,7.88],[4.1,6],[2.16,10.25]],"id":70642246},{"atl":[[150,4],[1000,0.22]],"id":70642246},{"spn":77.05,"spf":"NaN","id":70642246}],"con":true,"img":true}]}
{"op":"mcm","clk":"11539817285","pt":1719486505737,"mc":[{"id":"1.230178318","rc":[{"atb":[[2.24,0],[1.01,23.66],[2.26,6.54]],"id":62766534},{"spn":7.04,"spf":"NaN","id":62766534},{"atb":[[1.03,7.88],[2.22,12.31]],"id":39959056},{"atb":[[1.01,23.66],[2.18,6.54],[2.16,0]],"id":40214683},{"atb":[[2.24,9.77],[2.88,6.54],[1.03,7.88]],"id":56418091},{"spn":76.44,"spf":"NaN","id":56418091},{"atb":[[1.02,11.82],[2.26,9.86]],"id":69261147},{"atb":[[1.03,7.88],[2.16,10.25]],"id":70642246}],"con":true,"img":false}]}
{"op":"mcm","clk":"11539817297","pt":1719486505862,"mc":[{"id":"1.230178318","rc":[{"atb":[[2.28,8.88]],"id":62766534},{"atb":[[2.2,12.81]],"id":40214683}],"con":true,"img":false}]}
{"op":"mcm","clk":"11539818873","pt":1719486523164,"mc":[{"id":"1.230178318","rc":[{"atb":[[2.18,3.38]],"id":40214683}],"con":true,"img":false}]}
{"op":"mcm","clk":"11539818936","pt":1719486523635,"mc":[{"id":"1.230178318","rc":[{"atb":[[2.26,3.38]],"id":62766534}],"con":true,"img":false}]}
{"op":"mcm","clk":"11539818962","pt":1719486523837,"mc":[{"id":"1.230178318","rc":[{"atb":[[2.22,3.16]],"id":40214683}],"con":true,"img":false}]}
{"op":"mcm","clk":"11539819003","pt":1719486524253,"mc":[{"id":"1.230178318","rc":[{"atb":[[2.3,3.16]],"id":62766534}],"con":true,"img":false}]}
{"op":"mcm","clk":"11539825218","pt":1719486597828,"mc":[{"id":"1.230178318","rc":[{"atb":[[2.18,0]],"id":40214683}],"con":true,"img":false}]}
{"op":"mcm","clk":"11539825364","pt":1719486599746,"mc":[{"id":"1.230178318","rc":[{"atb":[[2.26,0]],"id":62766534}],"con":true,"img":false}]}
{"op":"mcm","clk":"11539825791","pt":1719486605349,"mc":[{"id":"1.230178318","rc":[{"atb":[[2.3,6.54]],"id":62766534}],"con":true,"img":false}]}
{"op":"mcm","clk":"11539825876","pt":1719486606429,"mc":[{"id":"1.230178318","rc":[{"atb":[[2.22,6.54]],"id":40214683}],"con":true,"img":false}]}
{"op":"mcm","clk":"11539840558","pt":1719486805514,"mc":[{"id":"1.230178318","rc":[{"atb":[[2.28,0]],"id":62766534},{"atb":[[2.2,0]],"id":40214683}],"con":true,"img":false}]}
{"op":"mcm","clk":"11539840563","pt":1719486805625,"mc":[{"id":"1.230178318","rc":[{"atb":[[2.32,8.88]],"id":62766534},{"atb":[[2.24,12.81]],"id":40214683}],"con":true,"img":false}]}
{"op":"mcm","clk":"11539841520","pt":1719486821143,"mc":[{"id":"1.230178318","rc":[{"atb":[[2.3,3.38]],"id":62766534},{"atb":[[2.22,3.38]],"id":40214683}],"con":true,"img":false}]}
{"op":"mcm","clk":"11539843045","pt":1719486844266,"mc":[{"id":"1.230178318","rc":[{"atb":[[2.3,0]],"id":62766534},{"atb":[[2.22,0]],"id":40214683}],"con":true,"img":false}]}
{"op":"mcm","clk":"11539848799","pt":1719486925376,"mc":[{"id":"1.230178318","rc":[{"atb":[[2.26,3.38]],"id":40214683}],"con":true,"img":false}]}
{"op":"mcm","clk":"11539848812","pt":1719486925684,"mc":[{"id":"1.230178318","rc":[{"atb":[[2.34,3.38]],"id":62766534}],"con":true,"img":false}]}
{"op":"mcm","clk":"11539850267","pt":1719486944262,"mc":[{"id":"1.230178318","rc":[{"atb":[[2.26,6.54]],"id":40214683}],"con":true,"img":false}]}
{"op":"mcm","clk":"11539850347","pt":1719486945292,"mc":[{"id":"1.230178318","rc":[{"atb":[[2.34,6.54]],"id":62766534}],"con":true,"img":false}]}
{"op":"mcm","clk":"11539908348","pt":1719487681387,"mc":[{"id":"1.230178318","rc":[{"atb":[[3.75,1]],"id":62766534},{"spn":7.62,"spf":"NaN","id":62766534},{"atb":[[5,1]],"id":39959056},{"spn":77.5,"spf":"NaN","id":39959056},{"atb":[[3,1.13]],"id":40214683},{"spn":15.0,"spf":"NaN","id":40214683},{"atb":[[4.8,1]],"id":56418091},{"spn":77.4,"spf":"NaN","id":56418091},{"atb":[[5,1]],"id":69261147},{"spn":77.5,"spf":"NaN","id":69261147},{"atb":[[5,1]],"id":70642246},{"spn":77.5,"spf":"NaN","id":70642246}],"con":true,"img":false}]}
{"op":"mcm","clk":"11539910441","pt":1719487706131,"mc":[{"id":"1.230178318","rc":[{"atb":[[1.51,196.08]],"id":39959056},{"atb":[[1.51,196.08]],"id":69261147},{"atb":[[1.51,196.08]],"id":70642246}],"con":true,"img":false}]}
{"op":"mcm","clk":"11539983385","pt":1719488658763,"mc":[{"id":"1.230178318","rc":[{"atb":[[1.51,196.08]],"id":62766534},{"atb":[[2.12,89.29]],"id":39959056},{"atb":[[1.51,196.08]],"id":56418091},{"atb":[[2.12,89.29]],"id":69261147},{"atb":[[2.12,89.29]],"id":70642246}],"con":true,"img":false}]}
{"op":"mcm","clk":"11540014419","pt":1719488999610,"mc":[{"id":"1.230178318","rc":[{"atb":[[1.16,150]],"id":62766534},{"atl":[[550,2]],"id":62766534},{"atb":[[1.16,150]],"id":39959056},{"atl":[[390,2]],"id":39959056},{"atb":[[1.16,150]],"id":40214683},{"atl":[[370,2]],"id":40214683},{"atb":[[1.16,150]],"id":56418091},{"atl":[[500,2]],"id":56418091},{"atb":[[1.16,150]],"id":69261147},{"atl":[[270,2]],"id":69261147},{"atb":[[1.16,150]],"id":70642246},{"atl":[[560,2]],"id":70642246}],"con":true,"img":false}]}
{"op":"mcm","clk":"11540136149","pt":1719490398728,"mc":[{"id":"1.230178318","rc":[{"atb":[[2.32,0],[2.34,6.54]],"id":62766534},{"atb":[[2.24,0],[2.26,6.54]],"id":40214683},{"atb":[[2.88,6.54]],"id":56418091}],"con":true,"img":false}]}
{"op":"mcm","clk":"11540136158","pt":1719490398831,"mc":[{"id":"1.230178318","rc":[{"atb":[[2.36,8.88]],"id":62766534},{"atb":[[2.28,12.81]],"id":40214683}],"con":true,"img":false}]}
{"op":"mcm","clk":"11540141362","pt":1719490449987,"mc":[{"id":"1.230178318","rc":[{"atb":[[2.26,3.16]],"id":40214683}],"con":true,"img":false}]}
{"op":"mcm","clk":"11540141406","pt":1719490450506,"mc":[{"id":"1.230178318","rc":[{"atb":[[2.34,3.16]],"id":62766534}],"con":true,"img":false}]}
{"op":"mcm","clk":"11540141733","pt":1719490453633,"mc":[{"id":"1.230178318","rc":[{"atb":[[2.3,3.38]],"id":40214683}],"con":true,"img":false}]}
{"op":"mcm","clk":"11540141848","pt":1719490454732,"mc":[{"id":"1.230178318","rc":[{"atb":[[2.38,3.38]],"id":62766534}],"con":true,"img":false}]}
{"op":"mcm","clk":"11540143790","pt":1719490473688,"mc":[{"id":"1.230178318","rc":[{"atb":[[2.34,0]],"id":62766534}],"con":true,"img":false}]}
{"op":"mcm","clk":"11540144102","pt":1719490476534,"mc":[{"id":"1.230178318","rc":[{"atb":[[2.26,0]],"id":40214683}],"con":true,"img":false}]}
{"op":"mcm","clk":"11540145756","pt":1719490491843,"mc":[{"id":"1.230178318","rc":[{"atb":[[2.3,6.54]],"id":40214683}],"con":true,"img":false}]}
{"op":"mcm","clk":"11540145944","pt":1719490493721,"mc":[{"id":"1.230178318","rc":[{"atb":[[2.38,6.54]],"id":62766534}],"con":true,"img":false}]}
{"op":"mcm","clk":"11540164621","pt":1719490697113,"mc":[{"id":"1.230178318","rc":[{"atb":[[2.28,0]],"id":40214683}],"con":true,"img":false}]}
{"op":"mcm","clk":"11540164628","pt":1719490697213,"mc":[{"id":"1.230178318","rc":[{"atb":[[2.32,12.81]],"id":40214683}],"con":true,"img":false}]}
{"op":"mcm","clk":"11540168602","pt":1719490747268,"mc":[{"id":"1.230178318","rc":[{"atb":[[2.3,3.38]],"id":40214683}],"con":true,"img":false}]}
{"op":"mcm","clk":"11540168626","pt":1719490747578,"mc":[{"id":"1.230178318","rc":[{"atb":[[2.34,3.16]],"id":40214683}],"con":true,"img":false}]}
{"op":"mcm","clk":"11540171034","pt":1719490783287,"mc":[{"id":"1.230178318","rc":[{"atb":[[2.3,0]],"id":40214683}],"con":true,"img":false}]}
{"op":"mcm","clk":"11540173243","pt":1719490811429,"mc":[{"id":"1.230178318","rc":[{"atb":[[2.34,6.54]],"id":40214683}],"con":true,"img":false}]}
{"op":"mcm","clk":"11540207342","pt":1719491299066,"mc":[{"id":"1.230178318","rc":[{"atl":[[34,18]],"id":62766534}],"con":true,"img":false}]}
{"op":"mcm","clk":"11540397819","pt":1719493995827,"mc":[{"id":"1.230178318","rc":[{"atb":[[2.36,8.89],[1.01,23.68],[2.38,6.54]],"id":62766534},{"atl":[[990,0.22]],"id":62766534},{"atb":[[1.03,7.89],[2.22,12.33]],"id":39959056},{"atl":[[990,0.22]],"id":39959056},{"atb":[[1.01,23.68],[2.32,0],[2.34,6.54]],"id":40214683},{"atl":[[990,0.22]],"id":40214683},{"atb":[[2.24,9.78],[2.88,6.54],[1.03,7.89]],"id":56418091},{"atl":[[990,0.22]],"id":56418091},{"atb":[[1.02,11.84],[2.26,9.87]],"id":69261147},{"atl":[[990,0.22]],"id":69261147},{"atb":[[1.03,7.89],[2.16,10.26]],"id":70642246},{"atl":[[1000,0.22]],"id":70642246}],"con":true,"img":false}]}
{"op":"mcm","clk":"11540397828","pt":1719493995928,"mc":[{"id":"1.230178318","rc":[{"atb":[[2.36,12.83]],"id":40214683}],"con":true,"img":false}]}
{"op":"mcm","clk":"11540397990","pt":1719493998005,"mc":[{"id":"1.230178318","rc":[{"atb":[[2.34,3.38]],"id":40214683}],"con":true,"img":false}]}
{"op":"mcm","clk":"11540398005","pt":1719493998208,"mc":[{"id":"1.230178318","rc":[{"atb":[[2.38,3.16]],"id":40214683}],"con":true,"img":false}]}
{"op":"mcm","clk":"11540400054","pt":1719494022843,"mc":[{"id":"1.230178318","rc":[{"atb":[[2.34,0]],"id":40214683}],"con":true,"img":false}]}
{"op":"mcm","clk":"11540400082","pt":1719494023155,"mc":[{"id":"1.230178318","rc":[{"atb":[[2.38,6.54]],"id":40214683}],"con":true,"img":false}]}
{"op":"mcm","clk":"11540579750","pt":1719496111745,"mc":[{"id":"1.230178318","rc":[{"atb":[[3.4,1]],"id":62766534},{"atb":[[5.5,1]],"id":39959056},{"spn":77.75,"spf":"NaN","id":39959056},{"atb":[[2.8,1]],"id":40214683},{"atb":[[4.2,1]],"id":56418091},{"atb":[[8,1]],"id":69261147},{"spn":79.0,"spf":"NaN","id":69261147},{"atb":[[8,1]],"id":70642246},{"spn":79.0,"spf":"NaN","id":70642246}],"con":true,"img":false}]}
{"op":"mcm","clk":"11540581446","pt":1719496129972,"mc":[{"id":"1.230178318","rc":[{"atb":[[2.12,89.29]],"id":56418091}],"con":true,"img":false}]}
{"op":"mcm","clk":"11540665705","pt":1719497090590,"mc":[{"id":"1.230178318","rc":[{"atb":[[2.36,8.88],[1.01,23.67],[2.38,6.54]],"id":62766534},{"atb":[[1.03,7.89],[2.22,12.32]],"id":39959056},{"atb":[[2.36,12.82],[1.01,23.67],[2.38,6.54]],"id":40214683},{"atb":[[2.24,9.77],[2.88,6.54],[1.03,7.89]],"id":56418091},{"atb":[[2.02,30.3],[1.02,11.83],[2.26,9.87],[3.05,48.78]],"id":69261147},{"atb":[[2.02,30.3],[1.03,7.89],[2.16,10.26],[3.05,48.78]],"id":70642246}],"con":true,"img":false}]}
{"op":"mcm","clk":"11540729124","pt":1719497749109,"mc":[{"id":"1.230178318","rc":[{"spl":[[1.01,1]],"id":62766534},{"spn":3.75,"spf":1.0,"id":62766534}],"con":true,"img":false}]}
{"op":"mcm","clk":"11540777596","pt":1719498277976,"mc":[{"id":"1.230178318","rc":[{"atl":[[150,15]],"id":70642246}],"con":true,"img":false}]}
{"op":"mcm","clk":"11540778019","pt":1719498281247,"mc":[{"id":"1.230178318","rc":[{"atl":[[150,25]],"id":70642246}],"con":true,"img":false}]}
{"op":"mcm","clk":"11540778603","pt":1719498286672,"mc":[{"id":"1.230178318","rc":[{"atl":[[150,11]],"id":69261147}],"con":true,"img":false}]}
{"op":"mcm","clk":"11540779041","pt":1719498290273,"mc":[{"id":"1.230178318","rc":[{"atl":[[150,13]],"id":69261147}],"con":true,"img":false}]}
{"op":"mcm","clk":"11540792413","pt":1719498432900,"mc":[{"id":"1.230178318","rc":[{"atl":[[150,15]],"id":70642246}],"con":true,"img":false}]}
{"op":"mcm","clk":"11540805675","pt":1719498577962,"mc":[{"id":"1.230178318","rc":[{"atl":[[150,11]],"id":69261147}],"con":true,"img":false}]}
{"op":"mcm","clk":"11540814056","pt":1719498662957,"mc":[{"id":"1.230178318","rc":[{"atb":[[3.4,0]],"id":62766534},{"atb":[[5.5,0]],"id":39959056},{"spn":77.5,"spf":"NaN","id":39959056},{"atb":[[2.8,0]],"id":40214683},{"atb":[[4.2,0]],"id":56418091},{"atb":[[8,0]],"id":69261147},{"spn":77.5,"spf":"NaN","id":69261147},{"atb":[[8,0]],"id":70642246},{"spn":77.5,"spf":"NaN","id":70642246}],"con":true,"img":false}]}
{"op":"mcm","clk":"11540829611","pt":1719498855799,"mc":[{"id":"1.230178318","rc":[{"atl":[[150,10]],"id":69261147}],"con":true,"img":false}]}
{"op":"mcm","clk":"11540848779","pt":1719499075322,"mc":[{"id":"1.230178318","rc":[{"atl":[[150,14]],"id":69261147}],"con":true,"img":false}]}
{"op":"mcm","clk":"11540885304","pt":1719499551400,"mc":[{"id":"1.230178318","rc":[{"atl":[[9,1]],"id":69261147},{"spn":7.0,"spf":"NaN","id":69261147}],"con":true,"img":false}]}
{"op":"mcm","clk":"11540885312","pt":1719499551504,"mc":[{"id":"1.230178318","rc":[{"atl":[[9,11],[150,10]],"id":69261147}],"con":true,"img":false}]}
{"op":"mcm","clk":"11540885321","pt":1719499551609,"mc":[{"id":"1.230178318","rc":[{"atl":[[150,4]],"id":69261147}],"con":true,"img":false}]}
{"op":"mcm","clk":"11540887732","pt":1719499584503,"mc":[{"id":"1.230178318","rc":[{"atl":[[9,10]],"id":69261147}],"con":true,"img":false}]}
{"op":"mcm","clk":"11540918542","pt":1719499956306,"mc":[{"id":"1.230178318","rc":[{"atl":[[11,1.63]],"id":62766534}],"con":true,"img":false}]}
{"op":"mcm","clk":"11540918565","pt":1719499956614,"mc":[{"id":"1.230178318","rc":[{"atl":[[26,1.71]],"id":40214683}],"con":true,"img":false}]}
{"op":"mcm","clk":"11540925543","pt":1719500048213,"mc":[{"id":"1.230178318","rc":[{"spn":14.5,"spf":"NaN","id":40214683},{"atl":[[150,4]],"id":70642246}],"con":true,"img":false}]}
{"op":"mcm","clk":"11540928797","pt":1719500088858,"mc":[{"id":"1.230178318","rc":[{"atl":[[9,6]],"id":69261147}],"con":true,"img":false}]}
{"op":"mcm","clk":"11540930658","pt":1719500110191,"mc":[{"id":"1.230178318","rc":[{"spl":[[1.01,16.93]],"id":69261147},{"spn":3.53,"spf":1.0,"id":69261147}],"con":true,"img":false}]}
{"op":"mcm","clk":"11540930822","pt":1719500112773,"mc":[{"id":"1.230178318","rc":[{"atl":[[9,16]],"id":69261147}],"con":true,"img":false}]}
{"op":"mcm","clk":"11540932325","pt":1719500130816,"mc":[{"id":"1.230178318","rc":[{"atb":[[3.7,1],[3.75,0]],"id":62766534},{"atb":[[3,0],[2.98,1.14]],"id":40214683},{"atb":[[4.8,0],[4.7,1]],"id":56418091}],"con":true,"img":false}]}
{"op":"mcm","clk":"11540936647","pt":1719500182975,"mc":[{"id":"1.230178318","rc":[{"spn":3.7,"spf":1.0,"id":62766534},{"spn":14.49,"spf":"NaN","id":40214683},{"spn":77.35,"spf":"NaN","id":56418091},{"spl":[[1.01,18.64]],"id":69261147},{"spn":3.49,"spf":1.0,"id":69261147}],"con":true,"img":false}]}
{"op":"mcm","clk":"11540940955","pt":1719500238820,"mc":[{"id":"1.230178318","rc":[{"spl":[[1.01,28.64]],"id":69261147}],"con":true,"img":false}]}
{"op":"mcm","clk":"11540949327","pt":1719500346268,"mc":[{"id":"1.230178318","rc":[{"atb":[[2.7,3.7]],"id":62766534},{"atb":[[5,3]],"id":39959056},{"atb":[[2.38,10.74]],"id":40214683},{"atb":[[3.5,2.85]],"id":56418091},{"atb":[[5.5,1.81]],"id":69261147},{"spn":3.49,"spf":1.0,"id":69261147},{"atb":[[6,1.66]],"id":70642246},{"spn":78.0,"spf":"NaN","id":70642246}],"con":true,"img":false}]}
{"op":"mcm","clk":"11540949865","pt":1719500352891,"mc":[{"id":"1.230178318","rc":[{"atb":[[2.38,7.58]],"id":40214683}],"con":true,"img":false}]}
{"op":"mcm","clk":"11540949878","pt":1719500353098,"mc":[{"id":"1.230178318","rc":[{"atb":[[2.4,3.15]],"id":40214683}],"con":true,"img":false}]}
{"op":"mcm","clk":"11540968410","pt":1719500586227,"mc":[{"id":"1.230178318","rc":[{"atb":[[2.36,8.89],[1.01,23.68],[2.38,6.54]],"id":62766534},{"atb":[[1.03,7.89],[2.22,12.32]],"id":39959056},{"atb":[[2.4,3.16],[2.36,12.82],[1.01,23.68],[2.38,7.58],[1.02,2]],"id":40214683},{"atb":[[2.24,9.77],[2.88,6.54],[1.03,7.89]],"id":56418091},{"spl":[[1.01,28.64]],"id":69261147},{"atb":[[1.02,11.83],[2.26,9.87]],"id":69261147},{"atb":[[1.03,7.89],[2.16,10.26]],"id":70642246}],"con":true,"img":false}]}
{"op":"mcm","clk":"11540968427","pt":1719500586430,"mc":[{"id":"1.230178318","rc":[{"atb":[[1.02,2]],"id":39959056}],"con":true,"img":false}]}
{"op":"mcm","clk":"11540968445","pt":1719500586633,"mc":[{"id":"1.230178318","rc":[{"atb":[[1.02,2]],"id":62766534}],"con":true,"img":false}]}
{"op":"mcm","clk":"11540968461","pt":1719500586841,"mc":[{"id":"1.230178318","rc":[{"atb":[[1.02,13.83]],"id":69261147}],"con":true,"img":false}]}
{"op":"mcm","clk":"11540968476","pt":1719500587046,"mc":[{"id":"1.230178318","rc":[{"atb":[[1.02,2]],"id":70642246}],"con":true,"img":false}]}
{"op":"mcm","clk":"11540968496","pt":1719500587256,"mc":[{"id":"1.230178318","rc":[{"atb":[[1.02,2]],"id":56418091}],"con":true,"img":false}]}
{"op":"mcm","clk":"11540968739","pt":1719500590143,"mc":[{"id":"1.230178318","rc":[{"spl":[[1.01,78.64]],"id":69261147}],"con":true,"img":false}]}
{"op":"mcm","clk":"11540969169","pt":1719500595558,"mc":[{"id":"1.230178318","rc":[{"atl":[[190,4]],"id":62766534},{"atl":[[190,4]],"id":39959056},{"atl":[[190,4]],"id":40214683},{"atl":[[190,4]],"id":56418091},{"atl":[[190,4]],"id":69261147},{"atl":[[190,4]],"id":70642246}],"con":true,"img":false}]}
{"op":"mcm","clk":"11540976430","pt":1719500679065,"mc":[{"id":"1.230178318","rc":[{"atb":[[6,2.28]],"id":69261147},{"spn":3.09,"spf":1.0,"id":69261147}],"con":true,"img":false}]}
{"op":"mcm","clk":"11540977710","pt":1719500691875,"mc":[{"id":"1.230178318","rc":[{"atb":[[6,0]],"id":69261147}],"con":true,"img":false}]}
{"op":"mcm","clk":"11540978492","pt":1719500702065,"mc":[{"id":"1.230178318","rc":[{"atb":[[7,2.14]],"id":69261147}],"con":true,"img":false}]}
{"op":"mcm","clk":"11540979177","pt":1719500710265,"mc":[{"id":"1.230178318","rc":[{"atb":[[7,0]],"id":69261147}],"con":true,"img":false}]}
{"op":"mcm","clk":"11540982369","pt":1719500750642,"mc":[{"id":"1.230178318","rc":[{"spl":[[1.01,103.64]],"id":69261147},{"spn":2.77,"spf":1.0,"id":69261147}],"con":true,"img":false}]}
{"op":"mcm","clk":"11540991094","pt":1719500851058,"mc":[{"id":"1.230178318","rc":[{"spl":[[1.01,4]],"id":40214683},{"spn":2.59,"spf":1.0,"id":40214683}],"con":true,"img":false}]}
{"op":"mcm","clk":"11540992895","pt":1719500871368,"mc":[{"id":"1.230178318","rc":[{"atl":[[9,19]],"id":69261147}],"con":true,"img":false}]}
{"op":"mcm","clk":"11540992910","pt":1719500871568,"mc":[{"id":"1.230178318","rc":[{"atl":[[9,22.28]],"id":69261147}],"con":true,"img":false}]}
{"op":"mcm","clk":"11540993388","pt":1719500877253,"mc":[{"id":"1.230178318","rc":[{"atl":[[9,23.28]],"id":69261147}],"con":true,"img":false}]}
{"op":"mcm","clk":"11540995840","pt":1719500909785,"mc":[{"id":"1.230178318","rc":[{"atl":[[9,22.28]],"id":69261147}],"con":true,"img":false}]}
{"op":"mcm","clk":"11540995896","pt":1719500910829,"mc":[{"id":"1.230178318","rc":[{"atl":[[44,6.36]],"id":62766534}],"con":true,"img":false}]}
{"op":"mcm","clk":"11541002148","pt":1719500996190,"mc":[{"id":"1.230178318","rc":[{"atl":[[8.4,1]],"id":69261147}],"con":true,"img":false}]}
{"op":"mcm","clk":"11541002157","pt":1719500996284,"mc":[{"id":"1.230178318","rc":[{"atl":[[9,13.28],[8.4,10]],"id":69261147}],"con":true,"img":false}]}
{"op":"mcm","clk":"11541002222","pt":1719500997275,"mc":[{"id":"1.230178318","rc":[{"atl":[[34,18]],"id":69261147}],"con":true,"img":false}]}
{"op":"mcm","clk":"11541002230","pt":1719500997370,"mc":[{"id":"1.230178318","rc":[{"atl":[[44,6.36]],"id":69261147}],"con":true,"img":false}]}
{"op":"mcm","clk":"11541005020","pt":1719501030935,"mc":[{"id":"1.230178318","rc":[{"atl":[[8.4,9]],"id":69261147}],"con":true,"img":false}]}
{"op":"mcm","clk":"11541008265","pt":1719501079369,"mc":[{"id":"1.230178318","rc":[{"spl":[[1.01,5]],"id":62766534},{"spn":2.89,"spf":1.0,"id":62766534},{"spb":[[1000,11]],"id":39959056},{"spn":150.0,"spf":"Infinity","id":39959056},{"spl":[[1.01,6]],"id":40214683},{"spn":2.54,"spf":1.0,"id":40214683},{"spl":[[1.01,4]],"id":56418091},{"spn":3.77,"spf":1.0,"id":56418091},{"spb":[[1000,22]],"id":69261147},{"spn":2.85,"spf":1.21,"id":69261147},{"spl":[[1.01,2]],"id":70642246},{"spn":5.83,"spf":1.0,"id":70642246}],"con":true,"img":false}]}
{"op":"mcm","clk":"11541009740","pt":1719501100380,"mc":[{"id":"1.230178318","rc":[{"atb":[[7,2.14]],"id":69261147}],"con":true,"img":false}]}
{"op":"mcm","clk":"11541010163","pt":1719501105889,"mc":[{"id":"1.230178318","rc":[{"atl":[[25,0.84]],"id":40214683}],"con":true,"img":false}]}
{"op":"mcm","clk":"11541010170","pt":1719501105990,"mc":[{"id":"1.230178318","rc":[{"atl":[[10.5,0.84]],"id":62766534}],"con":true,"img":false}]}
{"op":"mcm","clk":"11541012936","pt":1719501142929,"mc":[{"id":"1.230178318","rc":[{"atl":[[8.2,1]],"id":69261147},{"spn":2.96,"spf":1.21,"id":69261147}],"con":true,"img":false}]}
{"op":"mcm","clk":"11541012943","pt":1719501143041,"mc":[{"id":"1.230178318","rc":[{"atl":[[8.4,0]],"id":69261147}],"con":true,"img":false}]}
{"op":"mcm","clk":"11541016007","pt":1719501177560,"mc":[{"id":"1.230178318","rc":[{"atb":[[1.12,1.69]],"id":39959056},{"atb":[[1.07,1.69]],"id":40214683}],"con":true,"img":false}]}
{"op":"mcm","clk":"11541016041","pt":1719501177869,"mc":[{"id":"1.230178318","rc":[{"atb":[[1.08,1.69]],"id":62766534}],"con":true,"img":false}]}
{"op":"mcm","clk":"11541016059","pt":1719501178073,"mc":[{"id":"1.230178318","rc":[{"atb":[[1.1,1.69]],"id":56418091}],"con":true,"img":false}]}
{"op":"mcm","clk":"11541016071","pt":1719501178175,"mc":[{"id":"1.230178318","rc":[{"atb":[[1.14,1.69]],"id":70642246}],"con":true,"img":false}]}
{"op":"mcm","clk":"11541016088","pt":1719501178385,"mc":[{"id":"1.230178318","rc":[{"atb":[[1.07,0.1]],"id":40214683}],"con":true,"img":false}]}
{"op":"mcm","clk":"11541016098","pt":1719501178484,"mc":[{"id":"1.230178318","rc":[{"atb":[[1.12,0.05]],"id":39959056}],"con":true,"img":false}]}
{"op":"mcm","clk":"11541016114","pt":1719501178683,"mc":[{"id":"1.230178318","rc":[{"atb":[[1.08,0.08]],"id":62766534}],"con":true,"img":false}]}
{"op":"mcm","clk":"11541016143","pt":1719501178995,"mc":[{"id":"1.230178318","rc":[{"atb":[[1.1,0.06]],"id":56418091}],"con":true,"img":false}]}
{"op":"mcm","clk":"11541016156","pt":1719501179098,"mc":[{"id":"1.230178318","rc":[{"atb":[[1.14,0.05]],"id":70642246}],"con":true,"img":false}]}
{"op":"mcm","clk":"11541016174","pt":1719501179270,"mc":[{"id":"1.230178318","rc":[{"atb":[[1.07,0]],"id":40214683}],"con":true,"img":false}]}
{"op":"mcm","clk":"11541016183","pt":1719501179364,"mc":[{"id":"1.230178318","rc":[{"atb":[[3,0.1]],"id":40214683}],"con":true,"img":false}]}
{"op":"mcm","clk":"11541016213","pt":1719501179672,"mc":[{"id":"1.230178318","rc":[{"atb":[[1.12,0]],"id":39959056}],"con":true,"img":false}]}
{"op":"mcm","clk":"11541016223","pt":1719501179779,"mc":[{"id":"1.230178318","rc":[{"atb":[[5.1,0.05]],"id":39959056}],"con":true,"img":false}]}
{"op":"mcm","clk":"11541016239","pt":1719501179988,"mc":[{"id":"1.230178318","rc":[{"atb":[[1.08,0]],"id":62766534}],"con":true,"img":false}]}
{"op":"mcm","clk":"11541016250","pt":1719501180088,"mc":[{"id":"1.230178318","rc":[{"atb":[[3.75,0.08]],"id":62766534}],"con":true,"img":false}]}
{"op":"mcm","clk":"11541016260","pt":1719501180196,"mc":[{"id":"1.230178318","rc":[{"atb":[[2.54,8.89]],"id":62766534},{"atl":[[11,3.63]],"id":62766534},{"atb":[[4.1,12.33]],"id":39959056},{"atl":[[140,2]],"id":39959056},{"atb":[[2.46,6]],"id":40214683},{"atl":[[18.5,2]],"id":40214683},{"atb":[[2.86,15.78]],"id":56418091},{"atl":[[29,3.57]],"id":56418091},{"atb":[[4.2,9.87]],"id":69261147},{"atl":[[21,5]],"id":69261147},{"atb":[[4.5,10.26]],"id":70642246},{"atl":[[140,2]],"id":70642246}],"con":true,"img":false}]}
{"op":"mcm","clk":"11541016292","pt":1719501180499,"mc":[{"id":"1.230178318","rc":[{"atl":[[18,2]],"id":40214683}],"con":true,"img":false}]}
{"op":"mcm","clk":"11541016298","pt":1719501180602,"mc":[{"id":"1.230178318","rc":[{"atb":[[1.1,0]],"id":56418091}],"con":true,"img":false}]}
{"op":"mcm","clk":"11541016311","pt":1719501180711,"mc":[{"id":"1.230178318","rc":[{"atb":[[4.8,0.06]],"id":56418091}],"con":true,"img":false}]}
{"op":"mcm","clk":"11541016320","pt":1719501180776,"mc":[{"id":"1.230178318","rc":[{"atb":[[2.52,2.09]],"id":40214683}],"con":true,"img":false}]}
{"op":"mcm","clk":"11541016340","pt":1719501180980,"mc":[{"id":"1.230178318","rc":[{"atb":[[1.14,0]],"id":70642246}],"con":true,"img":false}]}
{"op":"mcm","clk":"11541016350","pt":1719501181087,"mc":[{"id":"1.230178318","rc":[{"atb":[[6.2,0.05]],"id":70642246}],"con":true,"img":false}]}
{"op":"mcm","clk":"11541016541","pt":1719501183209,"mc":[{"id":"1.230178318","rc":[{"atl":[[26,0]],"id":40214683}],"con":true,"img":false}]}
{"op":"mcm","clk":"11541016746","pt":1719501185303,"mc":[{"id":"1.230178318","rc":[{"atl":[[40,2.56],[29,0]],"id":56418091}],"con":true,"img":false}]}
{"op":"mcm","clk":"11541016787","pt":1719501185703,"mc":[{"id":"1.230178318","rc":[{"atl":[[18,0]],"id":40214683}],"con":true,"img":false}]}
{"op":"mcm","clk":"11541016805","pt":1719501185892,"mc":[{"id":"1.230178318","rc":[{"atl":[[18.5,0],[23,4.55]],"id":40214683}],"con":true,"img":false}]}
{"op":"mcm","clk":"11541016830","pt":1719501186181,"mc":[{"id":"1.230178318","rc":[{"atl":[[17.5,1.58]],"id":40214683}],"con":true,"img":false}]}
{"op":"mcm","clk":"11541017224","pt":1719501190291,"mc":[{"id":"1.230178318","rc":[{"atb":[[2.72,6],[2.54,0]],"id":62766534},{"atb":[[4.1,0],[4.7,12.33]],"id":39959056},{"atb":[[2.46,0],[2.66,6]],"id":40214683},{"atl":[[17.5,3.58],[23,0]],"id":40214683},{"atb":[[2.86,6],[3.1,9.78]],"id":56418091},{"atb":[[4.8,9.87],[4.2,0]],"id":69261147},{"atb":[[4.5,0],[5.2,6]],"id":70642246}],"con":true,"img":false}]}
{"op":"mcm","clk":"11541017250","pt":1719501190484,"mc":[{"id":"1.230178318","rc":[{"atl":[[1000,1.7]],"id":62766534},{"atb":[[1.03,9.59]],"id":39959056},{"atl":[[1000,1.7]],"id":39959056},{"atb":[[1.02,3.7]],"id":40214683},{"atl":[[1000,1.7]],"id":40214683}],"con":true,"img":false}]}
{"op":"mcm","clk":"11541017264","pt":1719501190588,"mc":[{"id":"1.230178318","rc":[{"atb":[[1.02,3.7]],"id":62766534}],"con":true,"img":false}]}
{"op":"mcm","clk":"11541017278","pt":1719501190693,"mc":[{"id":"1.230178318","rc":[{"atl":[[1000,0.03]],"id":62766534},{"atb":[[1.03,7.96]],"id":39959056},{"atl":[[1000,0]],"id":39959056},{"atb":[[1.02,2.2]],"id":40214683},{"atl":[[1000,0.01]],"id":40214683}],"con":true,"img":false}]}
{"op":"mcm","clk":"11541017290","pt":1719501190819,"mc":[{"id":"1.230178318","rc":[{"atb":[[1.02,2.18]],"id":62766534}],"con":true,"img":false}]}
{"op":"mcm","clk":"11541017297","pt":1719501190893,"mc":[{"id":"1.230178318","rc":[{"atl":[[1000,0]],"id":62766534},{"atb":[[1.03,7.89]],"id":39959056},{"atb":[[1.02,2]],"id":40214683},{"atl":[[1000,0]],"id":40214683}],"con":true,"img":false}]}
{"op":"mcm","clk":"11541017310","pt":1719501190997,"mc":[{"id":"1.230178318","rc":[{"atb":[[1.02,2]],"id":62766534},{"atb":[[5.1,0.13]],"id":39959056},{"atb":[[2.54,0.2]],"id":40214683},{"atl":[[22,0.01]],"id":40214683}],"con":true,"img":false}]}
{"op":"mcm","clk":"11541017320","pt":1719501191095,"mc":[{"id":"1.230178318","rc":[{"atb":[[2.72,6.18]],"id":62766534},{"atl":[[10.5,0.87]],"id":62766534}],"con":true,"img":false}]}
{"op":"mcm","clk":"11541017423","pt":1719501192186,"mc":[{"id":"1.230178318","rc":[{"atl":[[17,2]],"id":40214683}],"con":true,"img":false}]}
{"op":"mcm","clk":"11541017588","pt":1719501194102,"mc":[{"id":"1.230178318","rc":[{"atb":[[2.4,0]],"id":40214683}],"con":true,"img":false}]}
{"op":"mcm","clk":"11541017611","pt":1719501194311,"mc":[{"id":"1.230178318","rc":[{"atb":[[2.38,3.38]],"id":62766534},{"atb":[[2.88,3.38]],"id":56418091}],"con":true,"img":false}]}
{"op":"mcm","clk":"11541017644","pt":1719501194612,"mc":[{"id":"1.230178318","rc":[{"atb":[[2.68,3.16]],"id":40214683}],"con":true,"img":false}]}
{"op":"mcm","clk":"11541017652","pt":1719501194715,"mc":[{"id":"1.230178318","rc":[{"atb":[[2.74,3.16]],"id":62766534}],"con":true,"img":false}]}
{"op":"mcm","clk":"11541017697","pt":1719501195188,"mc":[{"id":"1.230178318","rc":[{"atl":[[17.5,2]],"id":40214683}],"con":true,"img":false}]}
{"op":"mcm","clk":"11541017881","pt":1719501197409,"mc":[{"id":"1.230178318","rc":[{"atl":[[17,0]],"id":40214683}],"con":true,"img":false}]}
{"op":"mcm","clk":"11541017891","pt":1719501197514,"mc":[{"id":"1.230178318","rc":[{"atl":[[17.5,0],[23,4.55]],"id":40214683}],"con":true,"img":false}]}
{"op":"mcm","clk":"11541017980","pt":1719501198598,"mc":[{"id":"1.230178318","rc":[{"atl":[[17,1.74]],"id":40214683}],"con":true,"img":false}]}
{"op":"mcm","clk":"11541018045","pt":1719501199420,"mc":[{"id":"1.230178318","rc":[{"atl":[[16.5,2]],"id":40214683}],"con":true,"img":false}]}
{"op":"mcm","clk":"11541018154","pt":1719501200822,"mc":[{"id":"1.230178318","rc":[{"atl":[[17,0]],"id":40214683}],"con":true,"img":false}]}
{"op":"mcm","clk":"11541018276","pt":1719501202524,"mc":[{"id":"1.230178318","rc":[{"atl":[[6.8,1]],"id":62766534},{"atb":[[4.3,1]],"id":39959056},{"atl":[[15.5,1]],"id":39959056},{"atl":[[5.5,1]],"id":40214683},{"atl":[[8.6,1]],"id":56418091},{"atb":[[5.5,1]],"id":70642246},{"atl":[[22,1]],"id":70642246}],"con":true,"img":false}]}
{"op":"mcm","clk":"11541018285","pt":1719501202631,"mc":[{"id":"1.230178318","rc":[{"atb":[[2.8,3.16],[2.66,0]],"id":40214683},{"atl":[[34,3.03],[40,0]],"id":56418091},{"atb":[[4.8,0],[5.1,6]],"id":69261147}],"con":true,"img":false}]}
{"op":"mcm","clk":"11541018483","pt":1719501204610,"mc":[{"id":"1.230178318","rc":[{"spn":2.94,"spf":1.0,"id":62766534},{"spn":15.5,"spf":"Infinity","id":39959056},{"atl":[[16.5,0]],"id":40214683},{"spn":2.8,"spf":1.0,"id":40214683},{"spn":3.81,"spf":1.0,"id":56418091},{"spn":3.14,"spf":1.21,"id":69261147},{"spn":5.93,"spf":1.0,"id":70642246}],"con":true,"img":false}]}
{"op":"mcm","clk":"11541018643","pt":1719501206409,"mc":[{"id":"1.230178318","rc":[{"atl":[[8.2,0]],"id":69261147}],"con":true,"img":false}]}
{"op":"mcm","clk":"11541018651","pt":1719501206514,"mc":[{"id":"1.230178318","rc":[{"atl":[[5.4,2]],"id":40214683},{"atl":[[9,22.28]],"id":69261147}],"con":true,"img":false}]}
{"op":"mcm","clk":"11541018744","pt":1719501207494,"mc":[{"id":"1.230178318","rc":[{"atl":[[6.4,3],[23,0]],"id":40214683}],"con":true,"img":false}]}
{"op":"mcm","clk":"11541018942","pt":1719501209817,"mc":[{"id":"1.230178318","rc":[{"atb":[[2.88,0]],"id":56418091}],"con":true,"img":false}]}
{"op":"mcm","clk":"11541019040","pt":1719501210904,"mc":[{"id":"1.230178318","rc":[{"atl":[[1000,1]],"id":40214683}],"con":true,"img":false}]}
{"op":"mcm","clk":"11541019059","pt":1719501211112,"mc":[{"id":"1.230178318","rc":[{"atl":[[1000,0.03]],"id":40214683}],"con":true,"img":false}]}
{"op":"mcm","clk":"11541019074","pt":1719501211321,"mc":[{"id":"1.230178318","rc":[{"atl":[[1000,0]],"id":40214683}],"con":true,"img":false}]}
{"op":"mcm","clk":"11541019084","pt":1719501211417,"mc":[{"id":"1.230178318","rc":[{"atl":[[5.3,0.03]],"id":40214683}],"con":true,"img":false}]}
{"op":"mcm","clk":"11541019106","pt":1719501211733,"mc":[{"id":"1.230178318","rc":[{"atl":[[5.4,0]],"id":40214683}],"con":true,"img":false}]}
{"op":"mcm","clk":"11541019247","pt":1719501213341,"mc":[{"id":"1.230178318","rc":[{"atb":[[2.68,0]],"id":40214683}],"con":true,"img":false}]}
{"op":"mcm","clk":"11541019268","pt":1719501213615,"mc":[{"id":"1.230178318","rc":[{"atl":[[5.4,2]],"id":40214683}],"con":true,"img":false}]}
{"op":"mcm","clk":"11541019298","pt":1719501214131,"mc":[{"id":"1.230178318","rc":[{"atb":[[7,0]],"id":69261147}],"con":true,"img":false}]}
{"op":"mcm","clk":"11541019309","pt":1719501214230,"mc":[{"id":"1.230178318","rc":[{"atb":[[7.4,2.14]],"id":69261147}],"con":true,"img":false}]}
{"op":"mcm","clk":"11541019457","pt":1719501215842,"mc":[{"id":"1.230178318","rc":[{"atl":[[15.5,0]],"id":39959056},{"trd":[[15.5,2]],"ltp":15.5,"tv":2.0,"id":39959056}],"con":true,"img":false}]}
{"op":"mcm","clk":"11541019770","pt":1719501218914,"mc":[{"id":"1.230178318","rc":[{"atb":[[1.09,1]],"id":39959056},{"atl":[[1000,0.01]],"id":39959056},{"atl":[[5.4,0]],"id":40214683}],"con":true,"img":false}]}
{"op":"mcm","clk":"11541019790","pt":1719501219125,"mc":[{"id":"1.230178318","rc":[{"atb":[[1.09,0.24]],"id":39959056},{"atl":[[1000,0]],"id":39959056}],"con":true,"img":false}]}
{"op":"mcm","clk":"11541019799","pt":1719501219224,"mc":[{"id":"1.230178318","rc":[{"atl":[[130,0.01]],"id":39959056}],"con":true,"img":false}]}
{"op":"mcm","clk":"11541019807","pt":1719501219331,"mc":[{"id":"1.230178318","rc":[{"atb":[[1.09,0]],"id":39959056}],"con":true,"img":false}]}
{"op":"mcm","clk":"11541019811","pt":1719501219417,"mc":[{"id":"1.230178318","rc":[{"atb":[[5.1,0.37]],"id":39959056}],"con":true,"img":false}]}
{"op":"mcm","clk":"11541019924","pt":1719501220827,"mc":[{"id":"1.230178318","rc":[{"atl":[[5.4,2]],"id":40214683}],"con":true,"img":false}]}
{"op":"mcm","clk":"11541020372","pt":1719501226157,"mc":[{"id":"1.230178318","rc":[{"atl":[[5.4,0]],"id":40214683}],"con":true,"img":false}]}
{"op":"mcm","clk":"11541020434","pt":1719501226823,"mc":[{"id":"1.230178318","rc":[{"atb":[[2.72,6]],"id":62766534},{"atl":[[10.5,0.84]],"id":62766534},{"atb":[[5.1,0.29]],"id":39959056},{"atb":[[2.54,0]],"id":40214683},{"atl":[[22,0]],"id":40214683}],"con":true,"img":false}]}
{"op":"mcm","clk":"11541020535","pt":1719501227954,"mc":[{"id":"1.230178318","rc":[{"atl":[[5.4,2]],"id":40214683}],"con":true,"img":false}]}
{"op":"mcm","clk":"11541020757","pt":1719501230536,"mc":[{"id":"1.230178318","rc":[{"atb":[[2.4,3.16]],"id":40214683}],"con":true,"img":false}]}
{"op":"mcm","clk":"11541021002","pt":1719501233232,"mc":[{"id":"1.230178318","rc":[{"atl":[[5.4,0]],"id":40214683}],"con":true,"img":false}]}
{"op":"mcm","clk":"11541021118","pt":1719501234466,"mc":[{"id":"1.230178318","rc":[{"atl":[[130,0]],"id":39959056}],"con":true,"img":false}]}
{"op":"mcm","clk":"11541021135","pt":1719501234623,"mc":[{"id":"1.230178318","rc":[{"atb":[[5.1,0.05]],"id":39959056}],"con":true,"img":false}]}
{"op":"mcm","clk":"11541021177","pt":1719501235135,"mc":[{"id":"1.230178318","rc":[{"atl":[[5.4,2]],"id":40214683}],"con":true,"img":false}]}
{"op":"mcm","clk":"11541021184","pt":1719501235239,"mc":[{"id":"1.230178318","rc":[{"atb":[[1.09,1]],"id":39959056},{"atl":[[1000,0.01]],"id":39959056}],"con":true,"img":false}]}
{"op":"mcm","clk":"11541021204","pt":1719501235445,"mc":[{"id":"1.230178318","rc":[{"atb":[[1.09,0.24]],"id":39959056},{"atl":[[1000,0]],"id":39959056}],"con":true,"img":false}]}
{"op":"mcm","clk":"11541021215","pt":1719501235549,"mc":[{"id":"1.230178318","rc":[{"atl":[[130,0.01]],"id":39959056}],"con":true,"img":false}]}
{"op":"mcm","clk":"11541021225","pt":1719501235654,"mc":[{"id":"1.230178318","rc":[{"atb":[[1.09,0]],"id":39959056}],"con":true,"img":false}]}
{"op":"mcm","clk":"11541021236","pt":1719501235757,"mc":[{"id":"1.230178318","rc":[{"atb":[[5.1,0.29]],"id":39959056}],"con":true,"img":false}]}
{"op":"mcm","clk":"11541021640","pt":1719501240354,"mc":[{"id":"1.230178318","rc":[{"atl":[[5.4,0]],"id":40214683}],"con":true,"img":false}]}
{"op":"mcm","clk":"11541021825","pt":1719501242474,"mc":[{"id":"1.230178318","rc":[{"atl":[[5.4,2]],"id":40214683}],"con":true,"img":false}]}
{"op":"mcm","clk":"11541022102","pt":1719501245581,"mc":[{"id":"1.230178318","rc":[{"atl":[[9.6,3]],"id":70642246}],"con":true,"img":false}]}
{"op":"mcm","clk":"11541022113","pt":1719501245684,"mc":[{"id":"1.230178318","rc":[{"atl":[[140,0]],"id":70642246}],"con":true,"img":false}]}
{"op":"mcm","clk":"11541022119","pt":1719501245778,"mc":[{"id":"1.230178318","rc":[{"atl":[[25,4]],"id":70642246}],"con":true,"img":false}]}
{"op":"mcm","clk":"11541022288","pt":1719501247752,"mc":[{"id":"1.230178318","rc":[{"atl":[[5.4,0]],"id":40214683}],"con":true,"img":false}]}
{"op":"mcm","clk":"11541022456","pt":1719501249546,"mc":[{"id":"1.230178318","rc":[{"atl":[[5.4,2]],"id":40214683}],"con":true,"img":false}]}
{"op":"mcm","clk":"11541022515","pt":1719501250165,"mc":[{"id":"1.230178318","rc":[{"atb":[[4.3,0],[4.6,1]],"id":39959056},{"atl":[[15.5,1]],"id":39959056},{"atb":[[5.8,1],[5.5,0]],"id":70642246}],"con":true,"img":false}]}
{"op":"mcm","clk":"11541022569","pt":1719501250681,"mc":[{"id":"1.230178318","rc":[{"atl":[[130,0]],"id":39959056}],"con":true,"img":false}]}
{"op":"mcm","clk":"11541022590","pt":1719501250887,"mc":[{"id":"1.230178318","rc":[{"atb":[[5.1,0.05]],"id":39959056}],"con":true,"img":false}]}
{"op":"mcm","clk":"11541022729","pt":1719501252281,"mc":[{"id":"1.230178318","rc":[{"atb":[[1.09,1]],"id":39959056}],"con":true,"img":false}]}
{"op":"mcm","clk":"11541022735","pt":1719501252385,"mc":[{"id":"1.230178318","rc":[{"atb":[[1.09,0.24]],"id":39959056}],"con":true,"img":false}]}
{"op":"mcm","clk":"11541022742","pt":1719501252439,"mc":[{"id":"1.230178318","rc":[{"atb":[[4.3,1],[4.6,0]],"id":39959056},{"atb":[[5.8,0],[5.5,1]],"id":70642246}],"con":true,"img":false}]}
{"op":"mcm","clk":"11541022757","pt":1719501252645,"mc":[{"id":"1.230178318","rc":[{"atb":[[1.09,0]],"id":39959056}],"con":true,"img":false}]}
{"op":"mcm","clk":"11541022764","pt":1719501252748,"mc":[{"id":"1.230178318","rc":[{"atb":[[5.1,0.29]],"id":39959056}],"con":true,"img":false}]}
{"op":"mcm","clk":"11541022924","pt":1719501254803,"mc":[{"id":"1.230178318","rc":[{"atl":[[5.4,0]],"id":40214683}],"con":true,"img":false}]}
{"op":"mcm","clk":"11541023077","pt":1719501256665,"mc":[{"id":"1.230178318","rc":[{"atl":[[5.4,2]],"id":40214683}],"con":true,"img":false}]}
{"op":"mcm","clk":"11541023142","pt":1719501257562,"mc":[{"id":"1.230178318","rc":[{"atb":[[4.3,0],[4.6,1]],"id":39959056},{"atb":[[5.8,1],[5.5,0]],"id":70642246}],"con":true,"img":false}]}
{"op":"mcm","clk":"11541023209","pt":1719501258278,"mc":[{"id":"1.230178318","rc":[{"atl":[[15.5,0]],"id":39959056},{"trd":[[15.5,4]],"ltp":15.5,"tv":4.0,"id":39959056}],"con":true,"img":false}]}
{"op":"mcm","clk":"11541023338","pt":1719501259984,"mc":[{"id":"1.230178318","rc":[{"atb":[[4.3,1],[4.6,0]],"id":39959056}],"con":true,"img":false}]}
{"op":"mcm","clk":"11541023349","pt":1719501260086,"mc":[{"id":"1.230178318","rc":[{"atb":[[5.8,0],[5.5,1]],"id":70642246}],"con":true,"img":false}]}
{"op":"mcm","clk":"11541023473","pt":1719501261888,"mc":[{"id":"1.230178318","rc":[{"atl":[[5.4,0]],"id":40214683}],"con":true,"img":false}]}
{"op":"mcm","clk":"11541023698","pt":1719501264500,"mc":[{"id":"1.230178318","rc":[{"atl":[[5.4,2]],"id":40214683}],"con":true,"img":false}]}
{"op":"mcm","clk":"11541023738","pt":1719501264964,"mc":[{"id":"1.230178318","rc":[{"atb":[[4.3,0],[4.6,1]],"id":39959056},{"spn":140.0,"spf":"Infinity","id":39959056},{"spn":2.76,"spf":1.0,"id":40214683},{"spn":3.15,"spf":1.21,"id":69261147},{"atb":[[5.8,1],[5.5,0]],"id":70642246},{"spn":5.97,"spf":1.0,"id":70642246}],"con":true,"img":false}]}
{"op":"mcm","clk":"11541023933","pt":1719501267390,"mc":[{"id":"1.230178318","rc":[{"atb":[[4.3,1],[4.6,0]],"id":39959056},{"atb":[[5.8,0],[5.5,1]],"id":70642246}],"con":true,"img":false}]}
{"op":"mcm","clk":"11541023980","pt":1719501268011,"mc":[{"id":"1.230178318","rc":[{"atb":[[5.1,0.05]],"id":39959056}],"con":true,"img":false}]}
{"op":"mcm","clk":"11541024057","pt":1719501268992,"mc":[{"id":"1.230178318","rc":[{"atb":[[1.09,1]],"id":39959056},{"atl":[[1000,0.01]],"id":39959056}],"con":true,"img":false}]}
{"op":"mcm","clk":"11541024067","pt":1719501269095,"mc":[{"id":"1.230178318","rc":[{"atb":[[1.09,0.24]],"id":39959056},{"atl":[[1000,0]],"id":39959056}],"con":true,"img":false}]}
{"op":"mcm","clk":"11541024077","pt":1719501269198,"mc":[{"id":"1.230178318","rc":[{"atb":[[1.09,0]],"id":39959056},{"atl":[[130,0.01]],"id":39959056}],"con":true,"img":false}]}
{"op":"mcm","clk":"11541024084","pt":1719501269301,"mc":[{"id":"1.230178318","rc":[{"atb":[[5.1,0.29]],"id":39959056}],"con":true,"img":false}]}
{"op":"mcm","clk":"11541024120","pt":1719501269770,"mc":[{"id":"1.230178318","rc":[{"atl":[[5.4,0]],"id":40214683}],"con":true,"img":false}]}
{"op":"mcm","clk":"11541024282","pt":1719501271691,"mc":[{"id":"1.230178318","rc":[{"atl":[[5.4,2]],"id":40214683}],"con":true,"img":false}]}
{"op":"mcm","clk":"11541024339","pt":1719501272369,"mc":[{"id":"1.230178318","rc":[{"atb":[[4.3,0],[4.6,1]],"id":39959056},{"atb":[[5.8,1]],"id":70642246}],"con":true,"img":false}]}
{"op":"mcm","clk":"11541024348","pt":1719501272479,"mc":[{"id":"1.230178318","rc":[{"atb":[[5.5,0]],"id":70642246}],"con":true,"img":false}]}
{"op":"mcm","clk":"11541024554","pt":1719501274714,"mc":[{"id":"1.230178318","rc":[{"atb":[[4.3,1],[4.6,0]],"id":39959056},{"atb":[[5.8,0],[5.5,1]],"id":70642246}],"con":true,"img":false}]}
{"op":"mcm","clk":"11541024751","pt":1719501276973,"mc":[{"id":"1.230178318","rc":[{"atl":[[5.4,0]],"id":40214683}],"con":true,"img":false}]}
{"op":"mcm","clk":"11541024942","pt":1719501278983,"mc":[{"id":"1.230178318","rc":[{"atl":[[5.4,2]],"id":40214683}],"con":true,"img":false}]}
{"op":"mcm","clk":"11541025011","pt":1719501280016,"mc":[{"id":"1.230178318","rc":[{"atb":[[4.6,1]],"id":39959056},{"atb":[[5.8,1],[5.5,0]],"id":70642246}],"con":true,"img":false}]}
{"op":"mcm","clk":"11541025022","pt":1719501280075,"mc":[{"id":"1.230178318","rc":[{"atb":[[4.3,0]],"id":39959056}],"con":true,"img":false}]}
{"op":"mcm","clk":"11541025220","pt":1719501282083,"mc":[{"id":"1.230178318","rc":[{"atb":[[4.3,1],[4.6,0]],"id":39959056},{"atb":[[5.8,0],[5.5,1]],"id":70642246}],"con":true,"img":false}]}
{"op":"mcm","clk":"11541025391","pt":1719501284216,"mc":[{"id":"1.230178318","rc":[{"atl":[[5.4,0]],"id":40214683}],"con":true,"img":false}]}
{"op":"mcm","clk":"11541025398","pt":1719501284320,"mc":[{"id":"1.230178318","rc":[{"atl":[[130,0]],"id":39959056}],"con":true,"img":false}]}
{"op":"mcm","clk":"11541025408","pt":1719501284372,"mc":[{"id":"1.230178318","rc":[{"atb":[[5.1,0.05]],"id":39959056},{"atb":[[2.46,8.11]],"id":40214683}],"con":true,"img":false}]}
{"op":"mcm","clk":"11541025417","pt":1719501284479,"mc":[{"id":"1.230178318","rc":[{"atb":[[2.24,9.56]],"id":39959056}],"con":true,"img":false}]}
{"op":"mcm","clk":"11541025434","pt":1719501284689,"mc":[{"id":"1.230178318","rc":[{"atb":[[3.1,5.64]],"id":69261147},{"atb":[[3.1,5.64]],"id":70642246}],"con":true,"img":false}]}
{"op":"mcm","clk":"11541025455","pt":1719501284897,"mc":[{"id":"1.230178318","rc":[{"atb":[[6,3.37]],"id":69261147}],"con":true,"img":false}]}
{"op":"mcm","clk":"11541025478","pt":1719501285098,"mc":[{"id":"1.230178318","rc":[{"atb":[[2.88,6.3]],"id":56418091}],"con":true,"img":false}]}
{"op":"mcm","clk":"11541025525","pt":1719501285510,"mc":[{"id":"1.230178318","rc":[{"atb":[[1.09,1]],"id":39959056},{"atl":[[1000,0.01]],"id":39959056}],"con":true,"img":false}]}
{"op":"mcm","clk":"11541025537","pt":1719501285615,"mc":[{"id":"1.230178318","rc":[{"atb":[[1.09,0.24]],"id":39959056},{"atl":[[1000,0]],"id":39959056}],"con":true,"img":false}]}
{"op":"mcm","clk":"11541025552","pt":1719501285717,"mc":[{"id":"1.230178318","rc":[{"atb":[[1.09,0],[5.1,0.9]],"id":39959056},{"atl":[[130,0.01]],"id":39959056},{"atb":[[7.6,0.84]],"id":69261147},{"atl":[[8.8,0.84]],"id":69261147},{"atb":[[6.2,0.89]],"id":70642246},{"atl":[[9.4,0.84]],"id":70642246}],"con":true,"img":false}]}
{"op":"mcm","clk":"11541025564","pt":1719501285820,"mc":[{"id":"1.230178318","rc":[{"atb":[[5.1,1.14]],"id":39959056}],"con":true,"img":false}]}
{"op":"mcm","clk":"11541025577","pt":1719501285881,"mc":[{"id":"1.230178318","rc":[{"atl":[[9,13.28],[8.8,9.84]],"id":69261147}],"con":true,"img":false}]}
{"op":"mcm","clk":"11541025598","pt":1719501286083,"mc":[{"id":"1.230178318","rc":[{"atl":[[9,10]],"id":69261147}],"con":true,"img":false}]}
{"op":"mcm","clk":"11541025608","pt":1719501286186,"mc":[{"id":"1.230178318","rc":[{"atl":[[8.6,3.28]],"id":69261147}],"con":true,"img":false}]}
{"op":"mcm","clk":"11541025627","pt":1719501286403,"mc":[{"id":"1.230178318","rc":[{"atl":[[8.6,12.28],[8.8,0.84]],"id":69261147}],"con":true,"img":false}]}
{"op":"mcm","clk":"11541025636","pt":1719501286497,"mc":[{"id":"1.230178318","rc":[{"atl":[[8.6,9]],"id":69261147}],"con":true,"img":false}]}
{"op":"mcm","clk":"11541025643","pt":1719501286598,"mc":[{"id":"1.230178318","rc":[{"atl":[[9,13.28]],"id":69261147}],"con":true,"img":false}]}
{"op":"mcm","clk":"11541025660","pt":1719501286807,"mc":[{"id":"1.230178318","rc":[{"atl":[[5.4,2]],"id":40214683}],"con":true,"img":false}]}
{"op":"mcm","clk":"11541025697","pt":1719501287213,"mc":[{"id":"1.230178318","rc":[{"atl":[[5.3,0.87]],"id":40214683}],"con":true,"img":false}]}
{"op":"mcm","clk":"11541025727","pt":1719501287587,"mc":[{"id":"1.230178318","rc":[{"atb":[[4.3,0],[4.6,1]],"id":39959056},{"atb":[[5.8,1],[5.5,0]],"id":70642246}],"con":true,"img":false}]}
{"op":"mcm","clk":"11541025905","pt":1719501289597,"mc":[{"id":"1.230178318","rc":[{"atb":[[4.3,1],[4.6,0]],"id":39959056},{"atb":[[5.8,0],[5.5,1]],"id":70642246}],"con":true,"img":false}]}
{"op":"mcm","clk":"11541026113","pt":1719501292024,"mc":[{"id":"1.230178318","rc":[{"atl":[[5.4,0]],"id":40214683}],"con":true,"img":false}]}
{"op":"mcm","clk":"11541026171","pt":1719501292708,"mc":[{"id":"1.230178318","rc":[{"atl":[[5.3,0.03]],"id":40214683}],"con":true,"img":false}]}
{"op":"mcm","clk":"11541026182","pt":1719501292805,"mc":[{"id":"1.230178318","rc":[{"atl":[[8.4,0.84]],"id":69261147}],"con":true,"img":false}]}
{"op":"mcm","clk":"11541026192","pt":1719501292908,"mc":[{"id":"1.230178318","rc":[{"atl":[[8.6,0],[8.4,9.84]],"id":69261147}],"con":true,"img":false}]}
{"op":"mcm","clk":"11541026216","pt":1719501293218,"mc":[{"id":"1.230178318","rc":[{"atl":[[8.8,0]],"id":69261147}],"con":true,"img":false}]}
{"op":"mcm","clk":"11541026277","pt":1719501293892,"mc":[{"id":"1.230178318","rc":[{"atl":[[5.4,2]],"id":40214683}],"con":true,"img":false}]}
{"op":"mcm","clk":"11541026311","pt":1719501294312,"mc":[{"id":"1.230178318","rc":[{"atl":[[5.3,0.87]],"id":40214683}],"con":true,"img":false}]}
{"op":"mcm","clk":"11541026368","pt":1719501295034,"mc":[{"id":"1.230178318","rc":[{"atb":[[4.3,0],[4.6,1]],"id":39959056},{"atb":[[5.8,1],[5.5,0]],"id":70642246}],"con":true,"img":false}]}
{"op":"mcm","clk":"11541026607","pt":1719501297719,"mc":[{"id":"1.230178318","rc":[{"atb":[[4.3,1]],"id":39959056},{"atb":[[5.8,0],[5.5,1]],"id":70642246}],"con":true,"img":false}]}
{"op":"mcm","clk":"11541026616","pt":1719501297817,"mc":[{"id":"1.230178318","rc":[{"atb":[[4.6,0]],"id":39959056}],"con":true,"img":false}]}
{"op":"mcm","clk":"11541026635","pt":1719501298023,"mc":[{"id":"1.230178318","rc":[{"atb":[[5.1,1.08]],"id":39959056},{"atb":[[3,0]],"id":40214683}],"con":true,"img":false}]}
{"op":"mcm","clk":"11541026659","pt":1719501298285,"mc":[{"id":"1.230178318","rc":[{"atb":[[3.75,0]],"id":62766534}],"con":true,"img":false}]}
{"op":"mcm","clk":"11541026691","pt":1719501298598,"mc":[{"id":"1.230178318","rc":[{"atb":[[6.2,0.84]],"id":70642246}],"con":true,"img":false}]}
{"op":"mcm","clk":"11541026711","pt":1719501298905,"mc":[{"id":"1.230178318","rc":[{"atb":[[4.8,0]],"id":56418091}],"con":true,"img":false}]}
{"op":"mcm","clk":"11541026727","pt":1719501299110,"mc":[{"id":"1.230178318","rc":[{"atl":[[5.4,0]],"id":40214683}],"con":true,"img":false}]}
{"op":"mcm","clk":"11541026735","pt":1719501299216,"mc":[{"id":"1.230178318","rc":[{"atb":[[1.12,1.69]],"id":39959056},{"atb":[[1.07,1.69]],"id":40214683}],"con":true,"img":false}]}
{"op":"mcm","clk":"11541026777","pt":1719501299525,"mc":[{"id":"1.230178318","rc":[{"atb":[[1.08,1.69]],"id":62766534},{"atb":[[1.07,0.1]],"id":40214683}],"con":true,"img":false}]}
{"op":"mcm","clk":"11541026799","pt":1719501299734,"mc":[{"id":"1.230178318","rc":[{"atl":[[5.3,0.03]],"id":40214683}],"con":true,"img":false}]}
{"op":"mcm","clk":"11541026810","pt":1719501299837,"mc":[{"id":"1.230178318","rc":[{"atb":[[1.08,0.08]],"id":62766534},{"atb":[[1.1,1.69]],"id":56418091}],"con":true,"img":false}]}
{"op":"mcm","clk":"11541026839","pt":1719501300096,"mc":[{"id":"1.230178318","rc":[{"atb":[[1.12,0.05]],"id":39959056},{"atb":[[1.07,0]],"id":40214683}],"con":true,"img":false}]}
{"op":"mcm","clk":"11541026852","pt":1719501300201,"mc":[{"id":"1.230178318","rc":[{"atb":[[3,0.1]],"id":40214683}],"con":true,"img":false}]}
{"op":"mcm","clk":"11541026886","pt":1719501300515,"mc":[{"id":"1.230178318","rc":[{"atb":[[1.08,0]],"id":62766534}],"con":true,"img":false}]}
{"op":"mcm","clk":"11541026898","pt":1719501300620,"mc":[{"id":"1.230178318","rc":[{"atb":[[3.75,0.08]],"id":62766534}],"con":true,"img":false}]}
{"op":"mcm","clk":"11541026910","pt":1719501300729,"mc":[{"id":"1.230178318","rc":[{"atb":[[1.1,0.06]],"id":56418091}],"con":true,"img":false}]}
{"op":"mcm","clk":"11541026931","pt":1719501300929,"mc":[{"id":"1.230178318","rc":[{"atl":[[130,0]],"id":39959056}],"con":true,"img":false}]}
{"op":"mcm","clk":"11541026941","pt":1719501301033,"mc":[{"id":"1.230178318","rc":[{"atb":[[1.12,0],[5.1,0.84]],"id":39959056}],"con":true,"img":false}]}
{"op":"mcm","clk":"11541026952","pt":1719501301136,"mc":[{"id":"1.230178318","rc":[{"atb":[[5.2,0.05]],"id":39959056}],"con":true,"img":false}]}
{"op":"mcm","clk":"11541026962","pt":1719501301243,"mc":[{"id":"1.230178318","rc":[{"atl":[[5.4,2]],"id":40214683}],"con":true,"img":false}]}
{"op":"mcm","clk":"11541026983","pt":1719501301402,"mc":[{"id":"1.230178318","rc":[{"atb":[[1.1,0]],"id":56418091}],"con":true,"img":false}]}
{"op":"mcm","clk":"11541026993","pt":1719501301507,"mc":[{"id":"1.230178318","rc":[{"atb":[[4.8,0.06]],"id":56418091}],"con":true,"img":false}]}
{"op":"mcm","clk":"11541027014","pt":1719501301715,"mc":[{"id":"1.230178318","rc":[{"atl":[[5.3,0.87]],"id":40214683}],"con":true,"img":false}]}
{"op":"mcm","clk":"11541027082","pt":1719501302401,"mc":[{"id":"1.230178318","rc":[{"atb":[[1.09,1]],"id":39959056},{"atl":[[1000,0.01]],"id":39959056}],"con":true,"img":false}]}
{"op":"mcm","clk":"11541027096","pt":1719501302512,"mc":[{"id":"1.230178318","rc":[{"atb":[[1.09,0.24]],"id":39959056},{"atl":[[1000,0]],"id":39959056}],"con":true,"img":false}]}
{"op":"mcm","clk":"11541027107","pt":1719501302610,"mc":[{"id":"1.230178318","rc":[{"atb":[[1.09,0]],"id":39959056},{"atl":[[130,0.01]],"id":39959056}],"con":true,"img":false}]}
{"op":"mcm","clk":"11541027120","pt":1719501302720,"mc":[{"id":"1.230178318","rc":[{"atb":[[5.1,1.08]],"id":39959056}],"con":true,"img":false}]}
{"op":"mcm","clk":"11541027140","pt":1719501302927,"mc":[{"id":"1.230178318","rc":[{"atb":[[4.3,0],[4.6,1]],"id":39959056},{"atb":[[5.8,1],[5.5,0]],"id":70642246}],"con":true,"img":false}]}
{"op":"mcm","clk":"11541027222","pt":1719501303605,"mc":[{"id":"1.230178318","rc":[{"atb":[[1.02,3.7]],"id":62766534},{"atl":[[1000,1.7]],"id":62766534},{"atb":[[1.04,1.7]],"id":39959056},{"atl":[[1000,1.7]],"id":39959056},{"atb":[[1.02,3.7]],"id":40214683},{"atl":[[1000,1.7]],"id":40214683}],"con":true,"img":false}]}
{"op":"mcm","clk":"11541027246","pt":1719501303815,"mc":[{"id":"1.230178318","rc":[{"atb":[[1.02,2.17]],"id":62766534},{"atl":[[1000,0.03]],"id":62766534},{"atb":[[1.04,0.07]],"id":39959056},{"atl":[[1000,0]],"id":39959056},{"atb":[[1.02,2.16]],"id":40214683},{"atl":[[1000,0.07]],"id":40214683}],"con":true,"img":false}]}
{"op":"mcm","clk":"11541027273","pt":1719501304025,"mc":[{"id":"1.230178318","rc":[{"atb":[[1.02,2]],"id":62766534},{"atl":[[1000,0]],"id":62766534},{"atb":[[1.04,0]],"id":39959056},{"atb":[[1.02,2]],"id":40214683},{"atl":[[1000,0]],"id":40214683}],"con":true,"img":false}]}
{"op":"mcm","clk":"11541027287","pt":1719501304133,"mc":[{"id":"1.230178318","rc":[{"atb":[[2.76,0.17]],"id":62766534},{"atl":[[10,0.03]],"id":62766534},{"atb":[[5.1,1.16]],"id":39959056},{"atb":[[2.82,0.16]],"id":40214683},{"atl":[[5.3,0.94]],"id":40214683}],"con":true,"img":false}]}
{"op":"mcm","clk":"11541027317","pt":1719501304337,"mc":[{"id":"1.230178318","rc":[{"atb":[[4.3,1],[4.6,0]],"id":39959056},{"atb":[[5.8,0],[5.5,1]],"id":70642246}],"con":true,"img":false}]}
{"op":"mcm","clk":"11541027539","pt":1719501306416,"mc":[{"id":"1.230178318","rc":[{"atl":[[5.4,0]],"id":40214683}],"con":true,"img":false}]}
{"op":"mcm","clk":"11541027565","pt":1719501306732,"mc":[{"id":"1.230178318","rc":[{"atl":[[5.3,0.1]],"id":40214683}],"con":true,"img":false}]}
{"op":"mcm","clk":"11541027613","pt":1719501307244,"mc":[{"id":"1.230178318","rc":[{"atb":[[4.3,0],[4.6,1]],"id":39959056},{"atb":[[5.8,1]],"id":70642246}],"con":true,"img":false}]}
{"op":"mcm","clk":"11541027626","pt":1719501307296,"mc":[{"id":"1.230178318","rc":[{"atb":[[5.5,0]],"id":70642246}],"con":true,"img":false}]}
{"op":"mcm","clk":"11541027788","pt":1719501309008,"mc":[{"id":"1.230178318","rc":[{"atl":[[5.4,2]],"id":40214683}],"con":true,"img":false}]}
{"op":"mcm","clk":"11541027868","pt":1719501309840,"mc":[{"id":"1.230178318","rc":[{"atl":[[5.3,0.94]],"id":40214683}],"con":true,"img":false}]}
{"op":"mcm","clk":"11541028147","pt":1719501312324,"mc":[{"id":"1.230178318","rc":[{"atb":[[2.7,0]],"id":62766534},{"atb":[[5,1]],"id":39959056},{"atb":[[2.38,3.38]],"id":40214683},{"atb":[[3.5,0]],"id":56418091},{"atb":[[5.5,0]],"id":69261147},{"atb":[[6,0]],"id":70642246}],"con":true,"img":false}]}
{"op":"mcm","clk":"11541028199","pt":1719501312739,"mc":[{"id":"1.230178318","rc":[{"atb":[[6.2,0]],"id":70642246}],"con":true,"img":false}]}
{"op":"mcm","clk":"11541028334","pt":1719501314235,"mc":[{"id":"1.230178318","rc":[{"atl":[[5.4,0]],"id":40214683}],"con":true,"img":false}]}
{"op":"mcm","clk":"11541028375","pt":1719501314750,"mc":[{"id":"1.230178318","rc":[{"atl":[[5.3,0.1]],"id":40214683}],"con":true,"img":false}]}
{"op":"mcm","clk":"11541028510","pt":1719501316149,"mc":[{"id":"1.230178318","rc":[{"atl":[[5.4,2]],"id":40214683}],"con":true,"img":false}]}
{"op":"mcm","clk":"11541028573","pt":1719501316833,"mc":[{"id":"1.230178318","rc":[{"atl":[[5.3,0.94]],"id":40214683}],"con":true,"img":false}]}
{"op":"mcm","clk":"11541028677","pt":1719501317956,"mc":[{"id":"1.230178318","rc":[{"atl":[[130,0]],"id":39959056}],"con":true,"img":false}]}
{"op":"mcm","clk":"11541028702","pt":1719501318216,"mc":[{"id":"1.230178318","rc":[{"atl":[[8,3]],"id":69261147}],"con":true,"img":false}]}
{"op":"mcm","clk":"11541028712","pt":1719501318322,"mc":[{"id":"1.230178318","rc":[{"atl":[[8.4,0.84]],"id":69261147}],"con":true,"img":false}]}
{"op":"mcm","clk":"11541028736","pt":1719501318532,"mc":[{"id":"1.230178318","rc":[{"atb":[[5.1,0.92]],"id":39959056}],"con":true,"img":false}]}
{"op":"mcm","clk":"11541028763","pt":1719501318848,"mc":[{"id":"1.230178318","rc":[{"atl":[[8.4,0]],"id":69261147}],"con":true,"img":false}]}
{"op":"mcm","clk":"11541028813","pt":1719501319359,"mc":[{"id":"1.230178318","rc":[{"atb":[[1.09,1]],"id":39959056},{"atl":[[1000,0.01]],"id":39959056}],"con":true,"img":false}]}
{"op":"mcm","clk":"11541028908","pt":1719501320355,"mc":[{"id":"1.230178318","rc":[{"atb":[[1.09,0.24]],"id":39959056},{"atl":[[1000,0]],"id":39959056}],"con":true,"img":false}]}
{"op":"mcm","clk":"11541028923","pt":1719501320458,"mc":[{"id":"1.230178318","rc":[{"atl":[[130,0.01]],"id":39959056}],"con":true,"img":false}]}
{"op":"mcm","clk":"11541029035","pt":1719501321241,"mc":[{"id":"1.230178318","rc":[{"atb":[[1.09,0]],"id":39959056}],"con":true,"img":false}]}
{"op":"mcm","clk":"11541029050","pt":1719501321347,"mc":[{"id":"1.230178318","rc":[{"atb":[[5.2,0.29]],"id":39959056},{"atl":[[5.4,0]],"id":40214683}],"con":true,"img":false}]}
{"op":"mcm","clk":"11541029091","pt":1719501321657,"mc":[{"id":"1.230178318","rc":[{"atl":[[5.3,0.1]],"id":40214683}],"con":true,"img":false}]}
{"op":"mcm","clk":"11541029111","pt":1719501321862,"mc":[{"id":"1.230178318","rc":[{"atb":[[2.4,0]],"id":40214683}],"con":true,"img":false}]}
{"op":"mcm","clk":"11541029190","pt":1719501322546,"mc":[{"id":"1.230178318","rc":[{"atb":[[4.7,0]],"id":39959056},{"atb":[[2.8,0],[2.72,6]],"id":40214683}],"con":true,"img":false}]}
{"op":"mcm","clk":"11541029195","pt":1719501322644,"mc":[{"id":"1.230178318","rc":[{"atb":[[4.4,9.57]],"id":39959056}],"con":true,"img":false}]}
{"op":"mcm","clk":"11541029267","pt":1719501323322,"mc":[{"id":"1.230178318","rc":[{"atl":[[5.4,2]],"id":40214683}],"con":true,"img":false}]}
{"op":"mcm","clk":"11541029305","pt":1719501323737,"mc":[{"id":"1.230178318","rc":[{"atl":[[5.3,0.94]],"id":40214683}],"con":true,"img":false}]}
{"op":"mcm","clk":"11541029605","pt":1719501326956,"mc":[{"id":"1.230178318","rc":[{"spn":2.94,"spf":1.0,"id":62766534},{"spn":138.74,"spf":"Infinity","id":39959056},{"atb":[[2.38,0],[2.46,16.81]],"id":40214683},{"spn":2.77,"spf":1.0,"id":40214683},{"spn":3.52,"spf":1.0,"id":56418091},{"spn":3.33,"spf":1.21,"id":69261147},{"spn":5.5,"spf":1.0,"id":70642246}],"con":true,"img":false}]}
{"op":"mcm","clk":"11541029647","pt":1719501327461,"mc":[{"id":"1.230178318","rc":[{"atb":[[2.48,3.38]],"id":40214683}],"con":true,"img":false}]}
{"op":"mcm","clk":"11541029743","pt":1719501328548,"mc":[{"id":"1.230178318","rc":[{"atl":[[5.4,0]],"id":40214683}],"con":true,"img":false}]}
{"op":"mcm","clk":"11541029819","pt":1719501329333,"mc":[{"id":"1.230178318","rc":[{"atl":[[5.3,0.1]],"id":40214683}],"con":true,"img":false}]}
{"op":"mcm","clk":"11541029984","pt":1719501331140,"mc":[{"id":"1.230178318","rc":[{"atl":[[5.4,2]],"id":40214683}],"con":true,"img":false}]}
{"op":"mcm","clk":"11541030042","pt":1719501331767,"mc":[{"id":"1.230178318","rc":[{"atl":[[5.3,0.94]],"id":40214683}],"con":true,"img":false}]}
{"op":"mcm","clk":"11541030367","pt":1719501336143,"mc":[{"id":"1.230178318","rc":[{"atl":[[130,0]],"id":39959056}],"con":true,"img":false}]}
{"op":"mcm","clk":"11541030381","pt":1719501336346,"mc":[{"id":"1.230178318","rc":[{"atl":[[5.4,0]],"id":40214683}],"con":true,"img":false}]}
{"op":"mcm","clk":"11541030405","pt":1719501336663,"mc":[{"id":"1.230178318","rc":[{"atl":[[5.3,0.1]],"id":40214683}],"con":true,"img":false}]}
{"op":"mcm","clk":"11541030445","pt":1719501337172,"mc":[{"id":"1.230178318","rc":[{"atb":[[5.2,0.05]],"id":39959056}],"con":true,"img":false}]}
{"op":"mcm","clk":"11541030467","pt":1719501337436,"mc":[{"id":"1.230178318","rc":[{"atb":[[1.09,1]],"id":39959056}],"con":true,"img":false}]}
{"op":"mcm","clk":"11541030475","pt":1719501337535,"mc":[{"id":"1.230178318","rc":[{"atb":[[1.09,0.24]],"id":39959056},{"atl":[[1000,0.01]],"id":39959056}],"con":true,"img":false}]}
{"op":"mcm","clk":"11541030490","pt":1719501337741,"mc":[{"id":"1.230178318","rc":[{"atb":[[1.09,0]],"id":39959056},{"atl":[[1000,0]],"id":39959056}],"con":true,"img":false}]}
{"op":"mcm","clk":"11541030500","pt":1719501337849,"mc":[{"id":"1.230178318","rc":[{"atb":[[5.2,0.29]],"id":39959056},{"atl":[[130,0.01]],"id":39959056}],"con":true,"img":false}]}
{"op":"mcm","clk":"11541030535","pt":1719501338256,"mc":[{"id":"1.230178318","rc":[{"atl":[[5.4,2]],"id":40214683}],"con":true,"img":false}]}
{"op":"mcm","clk":"11541030581","pt":1719501338772,"mc":[{"id":"1.230178318","rc":[{"atl":[[5.3,0.94]],"id":40214683}],"con":true,"img":false}]}
{"op":"mcm","clk":"11541030878","pt":1719501341855,"mc":[{"id":"1.230178318","rc":[{"atb":[[2.76,0]],"id":62766534},{"atl":[[10,0]],"id":62766534},{"atb":[[5.1,0.84]],"id":39959056},{"atb":[[2.82,0]],"id":40214683},{"atl":[[5.3,0.87]],"id":40214683}],"con":true,"img":false}]}
{"op":"mcm","clk":"11541031028","pt":1719501343465,"mc":[{"id":"1.230178318","rc":[{"atl":[[5.4,0]],"id":40214683}],"con":true,"img":false}]}
{"op":"mcm","clk":"11541031066","pt":1719501343877,"mc":[{"id":"1.230178318","rc":[{"atl":[[5.3,0.03]],"id":40214683}],"con":true,"img":false}]}
{"op":"mcm","clk":"11541031209","pt":1719501345487,"mc":[{"id":"1.230178318","rc":[{"atl":[[5.4,2]],"id":40214683}],"con":true,"img":false}]}
{"op":"mcm","clk":"11541031293","pt":1719501346261,"mc":[{"id":"1.230178318","rc":[{"atl":[[5.3,0.87]],"id":40214683}],"con":true,"img":false}]}
{"op":"mcm","clk":"11541031656","pt":1719501350484,"mc":[{"id":"1.230178318","rc":[{"atb":[[4.3,1],[4.6,0]],"id":39959056},{"atb":[[5.8,0],[5.5,1]],"id":70642246}],"con":true,"img":false}]}
{"op":"mcm","clk":"11541031664","pt":1719501350586,"mc":[{"id":"1.230178318","rc":[{"atb":[[5,8],[5.2,0]],"id":70642246}],"con":true,"img":false}]}
{"op":"mcm","clk":"11541031672","pt":1719501350689,"mc":[{"id":"1.230178318","rc":[{"atl":[[5.4,0]],"id":40214683},{"atb":[[5,1]],"id":70642246}],"con":true,"img":false}]}
{"op":"mcm","clk":"11541031679","pt":1719501350794,"mc":[{"id":"1.230178318","rc":[{"atb":[[1.14,1.69],[4.2,9]],"id":70642246}],"con":true,"img":false}]}
{"op":"mcm","clk":"11541031698","pt":1719501350955,"mc":[{"id":"1.230178318","rc":[{"atb":[[1.14,0.05]],"id":70642246}],"con":true,"img":false}]}
{"op":"mcm","clk":"11541031717","pt":1719501351161,"mc":[{"id":"1.230178318","rc":[{"atb":[[1.14,0]],"id":70642246}],"con":true,"img":false}]}
{"op":"mcm","clk":"11541031727","pt":1719501351265,"mc":[{"id":"1.230178318","rc":[{"atl":[[5.3,0.03]],"id":40214683},{"atb":[[5.6,0.05]],"id":70642246}],"con":true,"img":false}]}
{"op":"mcm","clk":"11541031744","pt":1719501351471,"mc":[{"id":"1.230178318","rc":[{"atb":[[5,7],[4.2,0]],"id":70642246}],"con":true,"img":false}]}
{"op":"mcm","clk":"11541031829","pt":1719501352358,"mc":[{"id":"1.230178318","rc":[{"atb":[[7.8,0.84]],"id":69261147}],"con":true,"img":false}]}
{"op":"mcm","clk":"11541031884","pt":1719501353084,"mc":[{"id":"1.230178318","rc":[{"atb":[[5.2,0.05]],"id":39959056},{"atl":[[130,0]],"id":39959056}],"con":true,"img":false}]}
{"op":"mcm","clk":"11541031896","pt":1719501353212,"mc":[{"id":"1.230178318","rc":[{"atl":[[5.4,2]],"id":40214683}],"con":true,"img":false}]}
{"op":"mcm","clk":"11541031905","pt":1719501353263,"mc":[{"id":"1.230178318","rc":[{"atb":[[1.09,1]],"id":39959056},{"atl":[[1000,0.01]],"id":39959056}],"con":true,"img":false}]}
{"op":"mcm","clk":"11541031914","pt":1719501353364,"mc":[{"id":"1.230178318","rc":[{"atb":[[1.09,0.24]],"id":39959056},{"atl":[[1000,0]],"id":39959056}],"con":true,"img":false}]}
{"op":"mcm","clk":"11541031923","pt":1719501353470,"mc":[{"id":"1.230178318","rc":[{"atl":[[130,0.01]],"id":39959056}],"con":true,"img":false}]}
{"op":"mcm","clk":"11541031936","pt":1719501353572,"mc":[{"id":"1.230178318","rc":[{"atb":[[1.09,0]],"id":39959056}],"con":true,"img":false}]}
{"op":"mcm","clk":"11541031946","pt":1719501353677,"mc":[{"id":"1.230178318","rc":[{"atb":[[5.2,0.29]],"id":39959056}],"con":true,"img":false}]}
{"op":"mcm","clk":"11541031959","pt":1719501353788,"mc":[{"id":"1.230178318","rc":[{"atl":[[5.3,0.87]],"id":40214683}],"con":true,"img":false}]}
{"op":"mcm","clk":"11541032336","pt":1719501358294,"mc":[{"id":"1.230178318","rc":[{"atl":[[5.4,0]],"id":40214683}],"con":true,"img":false}]}
{"op":"mcm","clk":"11541032372","pt":1719501358706,"mc":[{"id":"1.230178318","rc":[{"atl":[[5.3,0.03]],"id":40214683}],"con":true,"img":false}]}
{"op":"mcm","clk":"11541032519","pt":1719501360380,"mc":[{"id":"1.230178318","rc":[{"atl":[[5.4,2]],"id":40214683}],"con":true,"img":false}]}
{"op":"mcm","clk":"11541032547","pt":1719501360691,"mc":[{"id":"1.230178318","rc":[{"atl":[[1000,0.79]],"id":40214683}],"con":true,"img":false}]}
{"op":"mcm","clk":"11541032559","pt":1719501360794,"mc":[{"id":"1.230178318","rc":[{"atl":[[5.3,0.87]],"id":40214683}],"con":true,"img":false}]}
{"op":"mcm","clk":"11541032918","pt":1719501364802,"mc":[{"id":"1.230178318","rc":[{"atb":[[2.9,6.68]],"id":56418091}],"con":true,"img":false}]}
{"op":"mcm","clk":"11541032937","pt":1719501365003,"mc":[{"id":"1.230178318","rc":[{"atb":[[3.15,5.91]],"id":70642246}],"con":true,"img":false}]}
{"op":"mcm","clk":"11541032946","pt":1719501365062,"mc":[{"id":"1.230178318","rc":[{"atb":[[2.26,10.07]],"id":39959056}],"con":true,"img":false}]}
{"op":"mcm","clk":"11541032996","pt":1719501365682,"mc":[{"id":"1.230178318","rc":[{"atl":[[5.4,0]],"id":40214683}],"con":true,"img":false}]}
{"op":"mcm","clk":"11541033068","pt":1719501366363,"mc":[{"id":"1.230178318","rc":[{"atl":[[5.3,0.03]],"id":40214683}],"con":true,"img":false}]}
{"op":"mcm","clk":"11541033168","pt":1719501367399,"mc":[{"id":"1.230178318","rc":[{"atl":[[5.4,2]],"id":40214683}],"con":true,"img":false}]}
{"op":"mcm","clk":"11541033258","pt":1719501368308,"mc":[{"id":"1.230178318","rc":[{"atl":[[5.3,0.87]],"id":40214683}],"con":true,"img":false}]}
{"op":"mcm","clk":"11541033300","pt":1719501368665,"mc":[{"id":"1.230178318","rc":[{"atl":[[130,0]],"id":39959056}],"con":true,"img":false}]}
{"op":"mcm","clk":"11541033319","pt":1719501368873,"mc":[{"id":"1.230178318","rc":[{"atb":[[5.2,0.05]],"id":39959056}],"con":true,"img":false}]}
{"op":"mcm","clk":"11541033393","pt":1719501369595,"mc":[{"id":"1.230178318","rc":[{"atb":[[1.09,1]],"id":39959056},{"atl":[[1000,0.01]],"id":39959056}],"con":true,"img":false}]}
{"op":"mcm","clk":"11541033404","pt":1719501369704,"mc":[{"id":"1.230178318","rc":[{"atb":[[1.09,0.24]],"id":39959056},{"atl":[[1000,0]],"id":39959056}],"con":true,"img":false}]}
{"op":"mcm","clk":"11541033413","pt":1719501369811,"mc":[{"id":"1.230178318","rc":[{"atb":[[1.09,0]],"id":39959056},{"atl":[[130,0.01]],"id":39959056}],"con":true,"img":false}]}
{"op":"mcm","clk":"11541033421","pt":1719501369903,"mc":[{"id":"1.230178318","rc":[{"atb":[[5.1,1.08]],"id":39959056}],"con":true,"img":false}]}
{"op":"mcm","clk":"11541033676","pt":1719501372606,"mc":[{"id":"1.230178318","rc":[{"atl":[[5.4,0]],"id":40214683}],"con":true,"img":false}]}
{"op":"mcm","clk":"11541033729","pt":1719501373183,"mc":[{"id":"1.230178318","rc":[{"atl":[[5.3,0.03]],"id":40214683}],"con":true,"img":false}]}
{"op":"mcm","clk":"11541033895","pt":1719501375198,"mc":[{"id":"1.230178318","rc":[{"atl":[[5.4,2]],"id":40214683}],"con":true,"img":false}]}
{"op":"mcm","clk":"11541033903","pt":1719501375302,"mc":[{"id":"1.230178318","rc":[{"atb":[[2.74,3.16]],"id":40214683}],"con":true,"img":false}]}
{"op":"mcm","clk":"11541033941","pt":1719501375816,"mc":[{"id":"1.230178318","rc":[{"atl":[[5.3,0.87]],"id":40214683}],"con":true,"img":false}]}
{"op":"mcm","clk":"11541033959","pt":1719501375981,"mc":[{"id":"1.230178318","rc":[{"atb":[[2.74,3.96]],"id":62766534},{"atb":[[2.72,6.79]],"id":40214683},{"atb":[[3.1,10.57]],"id":56418091}],"con":true,"img":false}]}
{"op":"mcm","clk":"11541034347","pt":1719501380378,"mc":[{"id":"1.230178318","rc":[{"atl":[[5.4,0]],"id":40214683}],"con":true,"img":false}]}
{"op":"mcm","clk":"11541034385","pt":1719501380797,"mc":[{"id":"1.230178318","rc":[{"atl":[[5.3,0.03]],"id":40214683}],"con":true,"img":false}]}
{"op":"mcm","clk":"11541034391","pt":1719501380894,"mc":[{"id":"1.230178318","rc":[{"atb":[[5.3,1.6]],"id":39959056}],"con":true,"img":false}]}
{"op":"mcm","clk":"11541034453","pt":1719501381517,"mc":[{"id":"1.230178318","rc":[{"atb":[[5.3,0]],"id":39959056}],"con":true,"img":false}]}
{"op":"mcm","clk":"11541034486","pt":1719501381827,"mc":[{"id":"1.230178318","rc":[{"atb":[[5.2,1.65]],"id":39959056},{"atl":[[1000,0]],"id":40214683}],"con":true,"img":false}]}
{"op":"mcm","clk":"11541034529","pt":1719501382197,"mc":[{"id":"1.230178318","rc":[{"atb":[[6,2.47]],"id":70642246}],"con":true,"img":false}]}
{"op":"mcm","clk":"11541034540","pt":1719501382294,"mc":[{"id":"1.230178318","rc":[{"atl":[[5.4,2]],"id":40214683}],"con":true,"img":false}]}
{"op":"mcm","clk":"11541034571","pt":1719501382709,"mc":[{"id":"1.230178318","rc":[{"atb":[[6.2,0.84]],"id":70642246}],"con":true,"img":false}]}
{"op":"mcm","clk":"11541034610","pt":1719501383228,"mc":[{"id":"1.230178318","rc":[{"atl":[[5.3,0.87]],"id":40214683}],"con":true,"img":false}]}
{"op":"mcm","clk":"11541034760","pt":1719501385087,"mc":[{"id":"1.230178318","rc":[{"atl":[[130,0]],"id":39959056}],"con":true,"img":false}]}
{"op":"mcm","clk":"11541034766","pt":1719501385187,"mc":[{"id":"1.230178318","rc":[{"atb":[[5.1,0.84]],"id":39959056}],"con":true,"img":false}]}
{"op":"mcm","clk":"11541034890","pt":1719501386580,"mc":[{"id":"1.230178318","rc":[{"atb":[[1.09,1]],"id":39959056},{"atl":[[1000,0.01]],"id":39959056}],"con":true,"img":false}]}
{"op":"mcm","clk":"11541034906","pt":1719501386895,"mc":[{"id":"1.230178318","rc":[{"atb":[[1.09,0.23]],"id":39959056},{"atl":[[1000,0]],"id":39959056}],"con":true,"img":false}]}
{"op":"mcm","clk":"11541034917","pt":1719501387007,"mc":[{"id":"1.230178318","rc":[{"spn":2.94,"spf":1.0,"id":62766534},{"atl":[[130,0.01]],"id":39959056},{"spn":2.78,"spf":1.0,"id":40214683},{"spn":3.37,"spf":1.21,"id":69261147},{"spn":6.08,"spf":1.0,"id":70642246}],"con":true,"img":false}]}
{"op":"mcm","clk":"11541034923","pt":1719501387095,"mc":[{"id":"1.230178318","rc":[{"atb":[[1.09,0]],"id":39959056}],"con":true,"img":false}]}
{"op":"mcm","clk":"11541034931","pt":1719501387199,"mc":[{"id":"1.230178318","rc":[{"atb":[[5.3,0.23]],"id":39959056}],"con":true,"img":false}]}
{"op":"mcm","clk":"11541034954","pt":1719501387508,"mc":[{"id":"1.230178318","rc":[{"atb":[[3.1,0]],"id":69261147}],"con":true,"img":false}]}
{"op":"mcm","clk":"11541034963","pt":1719501387617,"mc":[{"id":"1.230178318","rc":[{"atl":[[5.4,0]],"id":40214683}],"con":true,"img":false}]}
{"op":"mcm","clk":"11541034976","pt":1719501387725,"mc":[{"id":"1.230178318","rc":[{"atb":[[5.3,1.07]],"id":39959056}],"con":true,"img":false}]}
{"op":"mcm","clk":"11541034995","pt":1719501387922,"mc":[{"id":"1.230178318","rc":[{"atl":[[8,0.46]],"id":69261147},{"trd":[[8,5.08]],"ltp":8.0,"tv":5.08,"id":69261147}],"con":true,"img":false}]}
{"op":"mcm","clk":"11541035029","pt":1719501388241,"mc":[{"id":"1.230178318","rc":[{"atb":[[5.4,1.56]],"id":39959056},{"atl":[[5.3,0.03]],"id":40214683},{"atl":[[8.8,0.84]],"id":69261147}],"con":true,"img":false}]}
{"op":"mcm","clk":"11541035045","pt":1719501388391,"mc":[{"id":"1.230178318","rc":[{"atl":[[9,10]],"id":69261147}],"con":true,"img":false}]}
{"op":"mcm","clk":"11541035054","pt":1719501388493,"mc":[{"id":"1.230178318","rc":[{"atb":[[5.2,0.05]],"id":39959056},{"atl":[[8.6,3.28]],"id":69261147}],"con":true,"img":false}]}
{"op":"mcm","clk":"11541035081","pt":1719501388803,"mc":[{"id":"1.230178318","rc":[{"atb":[[5.1,0]],"id":39959056}],"con":true,"img":false}]}
{"op":"mcm","clk":"11541035122","pt":1719501389334,"mc":[{"id":"1.230178318","rc":[{"atb":[[2.48,0]],"id":40214683}],"con":true,"img":false}]}
{"op":"mcm","clk":"11541035139","pt":1719501389528,"mc":[{"id":"1.230178318","rc":[{"atl":[[5.4,2]],"id":40214683}],"con":true,"img":false}]}
{"op":"mcm","clk":"11541035150","pt":1719501389632,"mc":[{"id":"1.230178318","rc":[{"atb":[[2.74,6.54]],"id":40214683}],"con":true,"img":false}]}
{"op":"mcm","clk":"11541035199","pt":1719501390306,"mc":[{"id":"1.230178318","rc":[{"atl":[[5.3,0.87]],"id":40214683}],"con":true,"img":false}]}
{"op":"mcm","clk":"11541035263","pt":1719501391103,"mc":[{"id":"1.230178318","rc":[{"atl":[[8.6,0]],"id":69261147}],"con":true,"img":false}]}
{"op":"mcm","clk":"11541035512","pt":1719501394318,"mc":[{"id":"1.230178318","rc":[{"atb":[[2.72,6]],"id":40214683}],"con":true,"img":false}]}
{"op":"mcm","clk":"11541035527","pt":1719501394523,"mc":[{"id":"1.230178318","rc":[{"atb":[[4.3,4.31]],"id":39959056}],"con":true,"img":false}]}
{"op":"mcm","clk":"11541035546","pt":1719501394727,"mc":[{"id":"1.230178318","rc":[{"atl":[[5.4,0]],"id":40214683}],"con":true,"img":false}]}
{"op":"mcm","clk":"11541035585","pt":1719501395296,"mc":[{"id":"1.230178318","rc":[{"atl":[[5.3,0.03]],"id":40214683}],"con":true,"img":false}]}
{"op":"mcm","clk":"11541035596","pt":1719501395503,"mc":[{"id":"1.230178318","rc":[{"atb":[[4.3,1]],"id":39959056}],"con":true,"img":false}]}
{"op":"mcm","clk":"11541035668","pt":1719501396633,"mc":[{"id":"1.230178318","rc":[{"atl":[[5.4,2]],"id":40214683}],"con":true,"img":false}]}
{"op":"mcm","clk":"11541035744","pt":1719501397827,"mc":[{"id":"1.230178318","rc":[{"atl":[[5.3,0.87]],"id":40214683}],"con":true,"img":false}]}
{"op":"mcm","clk":"11541035983","pt":1719501400916,"mc":[{"id":"1.230178318","rc":[{"atb":[[8,0.38]],"id":69261147},{"atl":[[8,0]],"id":69261147},{"trd":[[8,5.99]],"ltp":8.0,"tv":5.99,"id":69261147}],"con":true,"img":false}]}
{"op":"mcm","clk":"11541036056","pt":1719501401817,"mc":[{"id":"1.230178318","rc":[{"atl":[[5.4,0]],"id":40214683}],"con":true,"img":false}]}
{"op":"mcm","clk":"11541036080","pt":1719501402226,"mc":[{"id":"1.230178318","rc":[{"atl":[[130,0]],"id":39959056}],"con":true,"img":false}]}
{"op":"mcm","clk":"11541036087","pt":1719501402328,"mc":[{"id":"1.230178318","rc":[{"atb":[[5.3,0.84]],"id":39959056},{"atl":[[5.3,0.03]],"id":40214683}],"con":true,"img":false}]}
{"op":"mcm","clk":"11541036110","pt":1719501402643,"mc":[{"id":"1.230178318","rc":[{"atb":[[5.4,0],[5.1,1.56]],"id":39959056}],"con":true,"img":false}]}
{"op":"mcm","clk":"11541036141","pt":1719501402904,"mc":[{"id":"1.230178318","rc":[{"atb":[[1.09,1]],"id":39959056},{"atl":[[1000,0.01]],"id":39959056}],"con":true,"img":false}]}
{"op":"mcm","clk":"11541036169","pt":1719501403212,"mc":[{"id":"1.230178318","rc":[{"atb":[[1.09,0.24]],"id":39959056},{"atl":[[1000,0]],"id":39959056}],"con":true,"img":false}]}
{"op":"mcm","clk":"11541036179","pt":1719501403318,"mc":[{"id":"1.230178318","rc":[{"atb":[[5.3,0],[1.09,0]],"id":39959056},{"atl":[[130,0.01]],"id":39959056}],"con":true,"img":false}]}
{"op":"mcm","clk":"11541036189","pt":1719501403421,"mc":[{"id":"1.230178318","rc":[{"atb":[[5.2,0.29]],"id":39959056}],"con":true,"img":false}]}
{"op":"mcm","clk":"11541036211","pt":1719501403731,"mc":[{"id":"1.230178318","rc":[{"atb":[[5.2,1.14]],"id":39959056}],"con":true,"img":false}]}
{"op":"mcm","clk":"11541036219","pt":1719501403840,"mc":[{"id":"1.230178318","rc":[{"atl":[[5.4,2]],"id":40214683}],"con":true,"img":false}]}
{"op":"mcm","clk":"11541036234","pt":1719501404042,"mc":[{"id":"1.230178318","rc":[{"atb":[[5.3,1.6],[5.1,0]],"id":39959056}],"con":true,"img":false}]}
{"op":"mcm","clk":"11541036282","pt":1719501404719,"mc":[{"id":"1.230178318","rc":[{"atb":[[6,0]],"id":70642246}],"con":true,"img":false}]}
{"op":"mcm","clk":"11541036314","pt":1719501405330,"mc":[{"id":"1.230178318","rc":[{"atl":[[5.3,0.87]],"id":40214683},{"atb":[[6.2,0]],"id":70642246}],"con":true,"img":false}]}
{"op":"mcm","clk":"11541036456","pt":1719501407243,"mc":[{"id":"1.230178318","rc":[{"atl":[[10.5,0]],"id":62766534},{"atl":[[130,0.85]],"id":39959056},{"atl":[[25,0]],"id":40214683}],"con":true,"img":false}]}
{"op":"mcm","clk":"11541036512","pt":1719501407908,"mc":[{"id":"1.230178318","rc":[{"atb":[[2.24,0]],"id":39959056},{"atb":[[2.88,0]],"id":56418091},{"atb":[[3.1,0]],"id":70642246}],"con":true,"img":false}]}
{"op":"mcm","clk":"11541036577","pt":1719501409046,"mc":[{"id":"1.230178318","rc":[{"atl":[[5.4,0]],"id":40214683},{"atb":[[8,0]],"id":69261147}],"con":true,"img":false}]}
{"op":"mcm","clk":"11541036631","pt":1719501409930,"mc":[{"id":"1.230178318","rc":[{"atl":[[5.3,0.03]],"id":40214683}],"con":true,"img":false}]}
{"op":"mcm","clk":"11541036704","pt":1719501411004,"mc":[{"id":"1.230178318","rc":[{"atl":[[5.4,2]],"id":40214683}],"con":true,"img":false}]}
{"op":"mcm","clk":"11541036802","pt":1719501412344,"mc":[{"id":"1.230178318","rc":[{"atl":[[5.3,0.87]],"id":40214683}],"con":true,"img":false}]}
{"op":"mcm","clk":"11541036855","pt":1719501413214,"mc":[{"id":"1.230178318","rc":[{"atb":[[2.28,9.26]],"id":39959056}],"con":true,"img":false}]}
{"op":"mcm","clk":"11541036867","pt":1719501413421,"mc":[{"id":"1.230178318","rc":[{"atb":[[2.92,6.17]],"id":56418091},{"atb":[[3.2,5.39]],"id":70642246}],"con":true,"img":false}]}
{"op":"mcm","clk":"11541037015","pt":1719501415640,"mc":[{"id":"1.230178318","rc":[{"atb":[[8,0.84]],"id":69261147}],"con":true,"img":false}]}
{"op":"mcm","clk":"11541037060","pt":1719501416262,"mc":[{"id":"1.230178318","rc":[{"atl":[[5.4,0]],"id":40214683}],"con":true,"img":false}]}
{"op":"mcm","clk":"11541037101","pt":1719501416728,"mc":[{"id":"1.230178318","rc":[{"atl":[[5.3,0.03]],"id":40214683}],"con":true,"img":false}]}
{"op":"mcm","clk":"11541037215","pt":1719501418146,"mc":[{"id":"1.230178318","rc":[{"atl":[[5.4,2]],"id":40214683}],"con":true,"img":false}]}
{"op":"mcm","clk":"11541037256","pt":1719501418654,"mc":[{"id":"1.230178318","rc":[{"atl":[[130,0.84]],"id":39959056}],"con":true,"img":false}]}
{"op":"mcm","clk":"11541037262","pt":1719501418757,"mc":[{"id":"1.230178318","rc":[{"atb":[[5.2,0.9]],"id":39959056}],"con":true,"img":false}]}
{"op":"mcm","clk":"11541037273","pt":1719501418912,"mc":[{"id":"1.230178318","rc":[{"atb":[[5.3,0],[5.1,1.6]],"id":39959056}],"con":true,"img":false}]}
{"op":"mcm","clk":"11541037302","pt":1719501419322,"mc":[{"id":"1.230178318","rc":[{"atb":[[1.09,1]],"id":39959056},{"atl":[[1000,0.01]],"id":39959056}],"con":true,"img":false}]}
{"op":"mcm","clk":"11541037318","pt":1719501419529,"mc":[{"id":"1.230178318","rc":[{"atb":[[1.09,0.24]],"id":39959056},{"atl":[[1000,0]],"id":39959056}],"con":true,"img":false}]}
{"op":"mcm","clk":"11541037321","pt":1719501419631,"mc":[{"id":"1.230178318","rc":[{"atl":[[130,0.85]],"id":39959056},{"atb":[[2.74,3.16],[3,0]],"id":40214683}],"con":true,"img":false}]}
{"op":"mcm","clk":"11541037330","pt":1719501419736,"mc":[{"id":"1.230178318","rc":[{"atb":[[1.09,0]],"id":39959056},{"atl":[[5.3,0.87]],"id":40214683},{"atb":[[7.4,0]],"id":69261147}],"con":true,"img":false}]}
{"op":"mcm","clk":"11541037338","pt":1719501419838,"mc":[{"id":"1.230178318","rc":[{"atb":[[5.2,1.08]],"id":39959056}],"con":true,"img":false}]}
{"op":"mcm","clk":"11541037350","pt":1719501420044,"mc":[{"id":"1.230178318","rc":[{"atb":[[3.75,0]],"id":62766534}],"con":true,"img":false}]}
{"op":"mcm","clk":"11541037357","pt":1719501420151,"mc":[{"id":"1.230178318","rc":[{"atb":[[5.3,1.6],[5.1,0]],"id":39959056},{"atb":[[1.07,1.69]],"id":40214683}],"con":true,"img":false}]}
{"op":"mcm","clk":"11541037365","pt":1719501420352,"mc":[{"id":"1.230178318","rc":[{"atb":[[1.08,1.69]],"id":62766534}],"con":true,"img":false}]}
{"op":"mcm","clk":"11541037376","pt":1719501420456,"mc":[{"id":"1.230178318","rc":[{"atb":[[1.12,1.69]],"id":39959056}],"con":true,"img":false}]}
{"op":"mcm","clk":"11541037402","pt":1719501420719,"mc":[{"id":"1.230178318","rc":[{"atb":[[1.07,0.1]],"id":40214683}],"con":true,"img":false}]}
{"op":"mcm","clk":"11541037421","pt":1719501420923,"mc":[{"id":"1.230178318","rc":[{"atb":[[1.08,0.08]],"id":62766534}],"con":true,"img":false}]}
{"op":"mcm","clk":"11541037432","pt":1719501421031,"mc":[{"id":"1.230178318","rc":[{"atb":[[4.8,0]],"id":56418091}],"con":true,"img":false}]}
{"op":"mcm","clk":"11541037457","pt":1719501421336,"mc":[{"id":"1.230178318","rc":[{"atb":[[1.12,0.05]],"id":39959056}],"con":true,"img":false}]}
{"op":"mcm","clk":"11541037488","pt":1719501421654,"mc":[{"id":"1.230178318","rc":[{"atb":[[1.07,0]],"id":40214683}],"con":true,"img":false}]}
{"op":"mcm","clk":"11541037496","pt":1719501421752,"mc":[{"id":"1.230178318","rc":[{"atb":[[3,0.1]],"id":40214683}],"con":true,"img":false}]}
{"op":"mcm","clk":"11541037527","pt":1719501422064,"mc":[{"id":"1.230178318","rc":[{"atb":[[1.08,0]],"id":62766534}],"con":true,"img":false}]}
{"op":"mcm","clk":"11541037541","pt":1719501422119,"mc":[{"id":"1.230178318","rc":[{"atb":[[3.75,0.08]],"id":62766534}],"con":true,"img":false}]}
{"op":"mcm","clk":"11541037556","pt":1719501422328,"mc":[{"id":"1.230178318","rc":[{"atb":[[1.1,1.69]],"id":56418091}],"con":true,"img":false}]}
{"op":"mcm","clk":"11541037567","pt":1719501422533,"mc":[{"id":"1.230178318","rc":[{"atb":[[1.12,0]],"id":39959056}],"con":true,"img":false}]}
{"op":"mcm","clk":"11541037577","pt":1719501422639,"mc":[{"id":"1.230178318","rc":[{"atb":[[5.3,1.65]],"id":39959056}],"con":true,"img":false}]}
{"op":"mcm","clk":"11541037605","pt":1719501422950,"mc":[{"id":"1.230178318","rc":[{"atb":[[1.1,0.06]],"id":56418091}],"con":true,"img":false}]}
{"op":"mcm","clk":"11541037631","pt":1719501423361,"mc":[{"id":"1.230178318","rc":[{"atb":[[1.1,0]],"id":56418091}],"con":true,"img":false}]}
{"op":"mcm","clk":"11541037644","pt":1719501423413,"mc":[{"id":"1.230178318","rc":[{"atl":[[5.4,0]],"id":40214683},{"atb":[[4.8,0.06]],"id":56418091}],"con":true,"img":false}]}
{"op":"mcm","clk":"11541037657","pt":1719501423622,"mc":[{"id":"1.230178318","rc":[{"atb":[[8.8,0.72]],"id":69261147},{"atl":[[8.8,0]],"id":69261147},{"trd":[[8.8,1.69]],"ltp":8.8,"tv":1.69,"id":69261147}],"con":true,"img":false}]}
{"op":"mcm","clk":"11541037667","pt":1719501423722,"mc":[{"id":"1.230178318","rc":[{"atl":[[5.3,0.03]],"id":40214683},{"atl":[[9,23]],"id":69261147}],"con":true,"img":false}]}
{"op":"mcm","clk":"11541037805","pt":1719501425220,"mc":[{"id":"1.230178318","rc":[{"atb":[[1.02,3.7]],"id":62766534},{"atl":[[1000,1.7]],"id":62766534},{"atb":[[1.04,1.7]],"id":39959056},{"atl":[[1000,1.7]],"id":39959056},{"atb":[[1.02,3.7]],"id":40214683},{"atl":[[1000,1.7]],"id":40214683}],"con":true,"img":false}]}
{"op":"mcm","clk":"11541037823","pt":1719501425427,"mc":[{"id":"1.230178318","rc":[{"atb":[[1.02,2.16]],"id":62766534},{"atl":[[1000,0.03]],"id":62766534},{"atb":[[1.04,0.06]],"id":39959056},{"atl":[[1000,0]],"id":39959056},{"atb":[[1.02,2.16]],"id":40214683}],"con":true,"img":false}]}
{"op":"mcm","clk":"11541037831","pt":1719501425532,"mc":[{"id":"1.230178318","rc":[{"atl":[[1000,0.05]],"id":40214683}],"con":true,"img":false}]}
{"op":"mcm","clk":"11541037836","pt":1719501425634,"mc":[{"id":"1.230178318","rc":[{"atb":[[1.02,2]],"id":62766534},{"atl":[[1000,0]],"id":62766534},{"atb":[[1.04,0]],"id":39959056},{"atb":[[1.02,2]],"id":40214683}],"con":true,"img":false}]}
{"op":"mcm","clk":"11541037845","pt":1719501425740,"mc":[{"id":"1.230178318","rc":[{"atb":[[2.76,0.16]],"id":62766534},{"atl":[[10.5,0.03]],"id":62766534},{"atb":[[5.3,1.72]],"id":39959056},{"atb":[[2.76,0.16]],"id":40214683},{"atl":[[1000,0]],"id":40214683}],"con":true,"img":false}]}
{"op":"mcm","clk":"11541037856","pt":1719501425842,"mc":[{"id":"1.230178318","rc":[{"atl":[[6.2,0.05]],"id":40214683}],"con":true,"img":false}]}
{"op":"mcm","clk":"11541037863","pt":1719501425946,"mc":[{"id":"1.230178318","rc":[{"atl":[[5.4,2]],"id":40214683}],"con":true,"img":false}]}
{"op":"mcm","clk":"11541037895","pt":1719501426357,"mc":[{"id":"1.230178318","rc":[{"atb":[[5.4,0.84]],"id":39959056}],"con":true,"img":false}]}
{"op":"mcm","clk":"11541037965","pt":1719501427243,"mc":[{"id":"1.230178318","rc":[{"atl":[[5.3,0.87]],"id":40214683}],"con":true,"img":false}]}
{"op":"mcm","clk":"11541038300","pt":1719501431170,"mc":[{"id":"1.230178318","rc":[{"atl":[[5.4,0]],"id":40214683}],"con":true,"img":false}]}
{"op":"mcm","clk":"11541038332","pt":1719501431531,"mc":[{"id":"1.230178318","rc":[{"atb":[[8.8,0]],"id":69261147},{"trd":[[8.8,3.14]],"ltp":8.8,"tv":3.14,"id":69261147}],"con":true,"img":false}]}
{"op":"mcm","clk":"11541038368","pt":1719501431843,"mc":[{"id":"1.230178318","rc":[{"atl":[[5.3,0.03]],"id":40214683}],"con":true,"img":false}]}
{"op":"mcm","clk":"11541038462","pt":1719501432930,"mc":[{"id":"1.230178318","rc":[{"atl":[[5.4,2]],"id":40214683}],"con":true,"img":false}]}
{"op":"mcm","clk":"11541038536","pt":1719501433935,"mc":[{"id":"1.230178318","rc":[{"atb":[[8,0]],"id":69261147}],"con":true,"img":false}]}
{"op":"mcm","clk":"11541038562","pt":1719501434255,"mc":[{"id":"1.230178318","rc":[{"atl":[[5.3,0.87]],"id":40214683}],"con":true,"img":false}]}
{"op":"mcm","clk":"11541038610","pt":1719501434865,"mc":[{"id":"1.230178318","rc":[{"atl":[[130,0.84]],"id":39959056}],"con":true,"img":false}]}
{"op":"mcm","clk":"11541038634","pt":1719501435175,"mc":[{"id":"1.230178318","rc":[{"atb":[[5.2,0.84]],"id":39959056}],"con":true,"img":false}]}
{"op":"mcm","clk":"11541038671","pt":1719501435549,"mc":[{"id":"1.230178318","rc":[{"atb":[[1.09,1]],"id":39959056},{"atl":[[1000,0.01]],"id":39959056}],"con":true,"img":false}]}
{"op":"mcm","clk":"11541038698","pt":1719501435857,"mc":[{"id":"1.230178318","rc":[{"atb":[[1.09,0.23]],"id":39959056},{"atl":[[1000,0]],"id":39959056}],"con":true,"img":false}]}
{"op":"mcm","clk":"11541038704","pt":1719501435959,"mc":[{"id":"1.230178318","rc":[{"atl":[[130,0.85]],"id":39959056}],"con":true,"img":false}]}
{"op":"mcm","clk":"11541038719","pt":1719501436156,"mc":[{"id":"1.230178318","rc":[{"atb":[[1.09,0]],"id":39959056}],"con":true,"img":false}]}
{"op":"mcm","clk":"11541038724","pt":1719501436259,"mc":[{"id":"1.230178318","rc":[{"atb":[[5.4,1.07]],"id":39959056}],"con":true,"img":false}]}
{"op":"mcm","clk":"11541038743","pt":1719501436567,"mc":[{"id":"1.230178318","rc":[{"atb":[[5.5,1.54]],"id":39959056}],"con":true,"img":false}]}
{"op":"mcm","clk":"11541038753","pt":1719501436772,"mc":[{"id":"1.230178318","rc":[{"atb":[[5.3,0.12]],"id":39959056}],"con":true,"img":false}]}
{"op":"mcm","clk":"11541038785","pt":1719501437247,"mc":[{"id":"1.230178318","rc":[{"atb":[[5.2,0]],"id":39959056}],"con":true,"img":false}]}
{"op":"mcm","clk":"11541038854","pt":1719501438172,"mc":[{"id":"1.230178318","rc":[{"atl":[[5.4,0]],"id":40214683}],"con":true,"img":false}]}
{"op":"mcm","clk":"11541038902","pt":1719501438752,"mc":[{"id":"1.230178318","rc":[{"atl":[[5.3,0.03]],"id":40214683}],"con":true,"img":false}]}
{"op":"mcm","clk":"11541039034","pt":1719501440142,"mc":[{"id":"1.230178318","rc":[{"atl":[[5.4,2]],"id":40214683}],"con":true,"img":false}]}
{"op":"mcm","clk":"11541039151","pt":1719501441647,"mc":[{"id":"1.230178318","rc":[{"atl":[[5.3,0.87]],"id":40214683}],"con":true,"img":false}]}
{"op":"mcm","clk":"11541039437","pt":1719501445062,"mc":[{"id":"1.230178318","rc":[{"atb":[[2.26,0]],"id":39959056},{"atb":[[2.9,0]],"id":56418091},{"atb":[[3.15,0]],"id":70642246}],"con":true,"img":false}]}
{"op":"mcm","clk":"11541039459","pt":1719501445270,"mc":[{"id":"1.230178318","rc":[{"atb":[[2.74,3.16]],"id":62766534}],"con":true,"img":false}]}
{"op":"mcm","clk":"11541039470","pt":1719501445375,"mc":[{"id":"1.230178318","rc":[{"atl":[[5.4,0]],"id":40214683}],"con":true,"img":false}]}
{"op":"mcm","clk":"11541039503","pt":1719501445684,"mc":[{"id":"1.230178318","rc":[{"atl":[[5.3,0.03]],"id":40214683}],"con":true,"img":false}]}
{"op":"mcm","clk":"11541039622","pt":1719501447380,"mc":[{"id":"1.230178318","rc":[{"spn":2.94,"spf":1.0,"id":62766534},{"spn":130.0,"spf":"Infinity","id":39959056},{"atl":[[5.4,2]],"id":40214683},{"spn":2.78,"spf":1.0,"id":40214683},{"spn":3.2,"spf":1.21,"id":69261147},{"spn":5.26,"spf":1.0,"id":70642246}],"con":true,"img":false}]}
{"op":"mcm","clk":"11541039703","pt":1719501448674,"mc":[{"id":"1.230178318","rc":[{"atl":[[5.3,0.87]],"id":40214683}],"con":true,"img":false}]}
{"op":"mcm","clk":"11541039931","pt":1719501451278,"mc":[{"id":"1.230178318","rc":[{"atl":[[130,0.84]],"id":39959056}],"con":true,"img":false}]}
{"op":"mcm","clk":"11541039956","pt":1719501451490,"mc":[{"id":"1.230178318","rc":[{"atb":[[5.4,0.84]],"id":39959056}],"con":true,"img":false}]}
{"op":"mcm","clk":"11541039995","pt":1719501451891,"mc":[{"id":"1.230178318","rc":[{"atb":[[5.1,1.54],[5.5,0]],"id":39959056}],"con":true,"img":false}]}
{"op":"mcm","clk":"11541040025","pt":1719501452168,"mc":[{"id":"1.230178318","rc":[{"atb":[[1.09,1]],"id":39959056}],"con":true,"img":false}]}
{"op":"mcm","clk":"11541040033","pt":1719501452265,"mc":[{"id":"1.230178318","rc":[{"atl":[[1000,0.01]],"id":39959056}],"con":true,"img":false}]}
{"op":"mcm","clk":"11541040044","pt":1719501452371,"mc":[{"id":"1.230178318","rc":[{"atb":[[1.09,0.24],[5.4,0]],"id":39959056}],"con":true,"img":false}]}
{"op":"mcm","clk":"11541040051","pt":1719501452472,"mc":[{"id":"1.230178318","rc":[{"atl":[[1000,0]],"id":39959056}],"con":true,"img":false}]}
{"op":"mcm","clk":"11541040060","pt":1719501452573,"mc":[{"id":"1.230178318","rc":[{"atb":[[1.09,0]],"id":39959056},{"atl":[[130,0.85]],"id":39959056},{"atl":[[5.4,0]],"id":40214683}],"con":true,"img":false}]}
{"op":"mcm","clk":"11541040067","pt":1719501452675,"mc":[{"id":"1.230178318","rc":[{"atb":[[5.2,0.24]],"id":39959056}],"con":true,"img":false}]}
{"op":"mcm","clk":"11541040121","pt":1719501453289,"mc":[{"id":"1.230178318","rc":[{"atb":[[5.2,1.08]],"id":39959056}],"con":true,"img":false}]}
{"op":"mcm","clk":"11541040132","pt":1719501453393,"mc":[{"id":"1.230178318","rc":[{"atl":[[5.3,0.03]],"id":40214683}],"con":true,"img":false}]}
{"op":"mcm","clk":"11541040146","pt":1719501453601,"mc":[{"id":"1.230178318","rc":[{"atb":[[5.3,1.72]],"id":39959056}],"con":true,"img":false}]}
{"op":"mcm","clk":"11541040152","pt":1719501453660,"mc":[{"id":"1.230178318","rc":[{"atb":[[5.1,0]],"id":39959056}],"con":true,"img":false}]}
{"op":"mcm","clk":"11541040240","pt":1719501454788,"mc":[{"id":"1.230178318","rc":[{"atl":[[5.4,2]],"id":40214683}],"con":true,"img":false}]}
{"op":"mcm","clk":"11541040320","pt":1719501455763,"mc":[{"id":"1.230178318","rc":[{"atl":[[5.3,0.87]],"id":40214683}],"con":true,"img":false}]}
{"op":"mcm","clk":"11541040653","pt":1719501460096,"mc":[{"id":"1.230178318","rc":[{"atl":[[5.4,0]],"id":40214683}],"con":true,"img":false}]}
{"op":"mcm","clk":"11541040711","pt":1719501460783,"mc":[{"id":"1.230178318","rc":[{"atb":[[5.4,0.84]],"id":39959056}],"con":true,"img":false}]}
{"op":"mcm","clk":"11541040721","pt":1719501460880,"mc":[{"id":"1.230178318","rc":[{"atl":[[5.3,0.03]],"id":40214683}],"con":true,"img":false}]}
{"op":"mcm","clk":"11541040799","pt":1719501461905,"mc":[{"id":"1.230178318","rc":[{"atl":[[5.4,2]],"id":40214683}],"con":true,"img":false}]}
{"op":"mcm","clk":"11541040859","pt":1719501462796,"mc":[{"id":"1.230178318","rc":[{"atl":[[5.3,0.87]],"id":40214683}],"con":true,"img":false}]}
{"op":"mcm","clk":"11541041156","pt":1719501467086,"mc":[{"id":"1.230178318","rc":[{"atl":[[5.4,0]],"id":40214683}],"con":true,"img":false}]}
{"op":"mcm","clk":"11541041207","pt":1719501467805,"mc":[{"id":"1.230178318","rc":[{"atl":[[130,0.84]],"id":39959056},{"atl":[[5.3,0.03]],"id":40214683}],"con":true,"img":false}]}
{"op":"mcm","clk":"11541041217","pt":1719501468002,"mc":[{"id":"1.230178318","rc":[{"atb":[[5.2,0.84]],"id":39959056}],"con":true,"img":false}]}
{"op":"mcm","clk":"11541041305","pt":1719501469093,"mc":[{"id":"1.230178318","rc":[{"atl":[[5.4,2]],"id":40214683}],"con":true,"img":false}]}
{"op":"mcm","clk":"11541041315","pt":1719501469202,"mc":[{"id":"1.230178318","rc":[{"atb":[[1.09,1]],"id":39959056},{"atl":[[1000,0.01]],"id":39959056}],"con":true,"img":false}]}
{"op":"mcm","clk":"11541041328","pt":1719501469406,"mc":[{"id":"1.230178318","rc":[{"atb":[[1.09,0.23]],"id":39959056},{"atl":[[1000,0]],"id":39959056}],"con":true,"img":false}]}
{"op":"mcm","clk":"11541041336","pt":1719501469500,"mc":[{"id":"1.230178318","rc":[{"atl":[[130,0.85]],"id":39959056}],"con":true,"img":false}]}
{"op":"mcm","clk":"11541041343","pt":1719501469603,"mc":[{"id":"1.230178318","rc":[{"atb":[[1.09,0]],"id":39959056}],"con":true,"img":false}]}
{"op":"mcm","clk":"11541041353","pt":1719501469705,"mc":[{"id":"1.230178318","rc":[{"atb":[[5.4,1.07]],"id":39959056}],"con":true,"img":false}]}
{"op":"mcm","clk":"11541041376","pt":1719501469975,"mc":[{"id":"1.230178318","rc":[{"atb":[[5.5,1.54]],"id":39959056}],"con":true,"img":false}]}
{"op":"mcm","clk":"11541041402","pt":1719501470284,"mc":[{"id":"1.230178318","rc":[{"atb":[[5.3,0.12]],"id":39959056},{"atl":[[5.3,0.87]],"id":40214683}],"con":true,"img":false}]}
{"op":"mcm","clk":"11541041434","pt":1719501470798,"mc":[{"id":"1.230178318","rc":[{"atb":[[5.2,0]],"id":39959056}],"con":true,"img":false}]}
{"op":"mcm","clk":"11541041464","pt":1719501471210,"mc":[{"id":"1.230178318","rc":[{"atb":[[5.6,0]],"id":70642246}],"con":true,"img":false}]}
{"op":"mcm","clk":"11541041472","pt":1719501471302,"mc":[{"id":"1.230178318","rc":[{"atb":[[5,1],[4.2,8]],"id":70642246}],"con":true,"img":false}]}
{"op":"mcm","clk":"11541041495","pt":1719501471611,"mc":[{"id":"1.230178318","rc":[{"atb":[[1.14,1.69]],"id":70642246}],"con":true,"img":false}]}
{"op":"mcm","clk":"11541041526","pt":1719501471984,"mc":[{"id":"1.230178318","rc":[{"atb":[[1.14,0.05]],"id":70642246}],"con":true,"img":false}]}
{"op":"mcm","clk":"11541041547","pt":1719501472293,"mc":[{"id":"1.230178318","rc":[{"atb":[[2.76,0]],"id":62766534},{"atl":[[10.5,0]],"id":62766534},{"atb":[[5.3,0.05]],"id":39959056},{"atb":[[2.76,0]],"id":40214683},{"atl":[[6.2,0]],"id":40214683},{"atb":[[1.14,0]],"id":70642246}],"con":true,"img":false}]}
{"op":"mcm","clk":"11541041554","pt":1719501472397,"mc":[{"id":"1.230178318","rc":[{"atb":[[5.6,0.05]],"id":70642246}],"con":true,"img":false}]}
{"op":"mcm","clk":"11541041560","pt":1719501472498,"mc":[{"id":"1.230178318","rc":[{"atb":[[5,7],[4.2,0]],"id":70642246}],"con":true,"img":false}]}
{"op":"mcm","clk":"11541041614","pt":1719501473216,"mc":[{"id":"1.230178318","rc":[{"atb":[[7,2.14]],"id":70642246}],"con":true,"img":false}]}
{"op":"mcm","clk":"11541041634","pt":1719501473425,"mc":[{"id":"1.230178318","rc":[{"atb":[[2.28,0]],"id":39959056},{"atb":[[2.92,0]],"id":56418091},{"atb":[[3.2,0]],"id":70642246}],"con":true,"img":false}]}
{"op":"mcm","clk":"11541041663","pt":1719501473692,"mc":[{"id":"1.230178318","rc":[{"atb":[[7.2,0.84]],"id":70642246}],"con":true,"img":false}]}
{"op":"mcm","clk":"11541041723","pt":1719501474415,"mc":[{"id":"1.230178318","rc":[{"atl":[[5.4,0]],"id":40214683}],"con":true,"img":false}]}
{"op":"mcm","clk":"11541041754","pt":1719501474798,"mc":[{"id":"1.230178318","rc":[{"atl":[[5.3,0.03]],"id":40214683}],"con":true,"img":false}]}
{"op":"mcm","clk":"11541041896","pt":1719501476809,"mc":[{"id":"1.230178318","rc":[{"atl":[[5.4,2]],"id":40214683}],"con":true,"img":false}]}
{"op":"mcm","clk":"11541041977","pt":1719501477801,"mc":[{"id":"1.230178318","rc":[{"atl":[[5.3,0.87]],"id":40214683}],"con":true,"img":false}]}
{"op":"mcm","clk":"11541042087","pt":1719501479407,"mc":[{"id":"1.230178318","rc":[{"atb":[[2.48,3.38]],"id":40214683}],"con":true,"img":false}]}
{"op":"mcm","clk":"11541042156","pt":1719501480128,"mc":[{"id":"1.230178318","rc":[{"atb":[[2.24,9.56]],"id":39959056}],"con":true,"img":false}]}
{"op":"mcm","clk":"11541042166","pt":1719501480229,"mc":[{"id":"1.230178318","rc":[{"atb":[[3.1,5.64]],"id":70642246}],"con":true,"img":false}]}
{"op":"mcm","clk":"11541042192","pt":1719501480504,"mc":[{"id":"1.230178318","rc":[{"atb":[[2.88,6.3]],"id":56418091}],"con":true,"img":false}]}
{"op":"mcm","clk":"11541042224","pt":1719501480921,"mc":[{"id":"1.230178318","rc":[{"atb":[[7,0]],"id":70642246}],"con":true,"img":false}]}
{"op":"mcm","clk":"11541042249","pt":1719501481226,"mc":[{"id":"1.230178318","rc":[{"atb":[[1.01,24.68]],"id":40214683},{"atb":[[7.2,0]],"id":70642246}],"con":true,"img":false}]}
{"op":"mcm","clk":"11541042260","pt":1719501481346,"mc":[{"id":"1.230178318","rc":[{"atb":[[5.6,1]],"id":39959056},{"atl":[[28,1]],"id":56418091},{"atl":[[24,1]],"id":70642246}],"con":true,"img":false}]}
{"op":"mcm","clk":"11541042286","pt":1719501481621,"mc":[{"id":"1.230178318","rc":[{"atb":[[5.7,1.48]],"id":39959056}],"con":true,"img":false}]}
{"op":"mcm","clk":"11541042318","pt":1719501482036,"mc":[{"id":"1.230178318","rc":[{"atb":[[5.5,0]],"id":39959056},{"atl":[[5.4,0]],"id":40214683}],"con":true,"img":false}]}
{"op":"mcm","clk":"11541042350","pt":1719501482312,"mc":[{"id":"1.230178318","rc":[{"atb":[[5.4,0.23]],"id":39959056}],"con":true,"img":false}]}
{"op":"mcm","clk":"11541042393","pt":1719501482824,"mc":[{"id":"1.230178318","rc":[{"atl":[[5.3,0.03]],"id":40214683}],"con":true,"img":false}]}
{"op":"mcm","clk":"11541042413","pt":1719501483031,"mc":[{"id":"1.230178318","rc":[{"atb":[[2.8,2.09],[2.52,0]],"id":40214683}],"con":true,"img":false}]}
{"op":"mcm","clk":"11541042513","pt":1719501484026,"mc":[{"id":"1.230178318","rc":[{"atl":[[5.4,2]],"id":40214683}],"con":true,"img":false}]}
{"op":"mcm","clk":"11541042574","pt":1719501484716,"mc":[{"id":"1.230178318","rc":[{"atl":[[130,0.84]],"id":39959056},{"atb":[[5.8,1],[5.5,0]],"id":70642246}],"con":true,"img":false}]}
{"op":"mcm","clk":"11541042582","pt":1719501484822,"mc":[{"id":"1.230178318","rc":[{"atl":[[5.3,0.87]],"id":40214683}],"con":true,"img":false}]}
{"op":"mcm","clk":"11541042590","pt":1719501484924,"mc":[{"id":"1.230178318","rc":[{"atb":[[5.4,0]],"id":39959056}],"con":true,"img":false}]}
{"op":"mcm","clk":"11541042680","pt":1719501485924,"mc":[{"id":"1.230178318","rc":[{"atb":[[6,0]],"id":69261147}],"con":true,"img":false}]}
{"op":"mcm","clk":"11541042690","pt":1719501486023,"mc":[{"id":"1.230178318","rc":[{"atb":[[5.5,3.37]],"id":69261147}],"con":true,"img":false}]}
{"op":"mcm","clk":"11541042702","pt":1719501486134,"mc":[{"id":"1.230178318","rc":[{"atb":[[1.1,1]],"id":39959056},{"atl":[[1000,0.01]],"id":39959056}],"con":true,"img":false}]}
{"op":"mcm","clk":"11541042714","pt":1719501486229,"mc":[{"id":"1.230178318","rc":[{"atb":[[1.1,0.21]],"id":39959056},{"atl":[[1000,0]],"id":39959056}],"con":true,"img":false}]}
{"op":"mcm","clk":"11541042725","pt":1719501486333,"mc":[{"id":"1.230178318","rc":[{"atl":[[130,0.85]],"id":39959056}],"con":true,"img":false}]}
{"op":"mcm","clk":"11541042734","pt":1719501486436,"mc":[{"id":"1.230178318","rc":[{"atb":[[1.1,0]],"id":39959056}],"con":true,"img":false}]}
{"op":"mcm","clk":"11541042746","pt":1719501486496,"mc":[{"id":"1.230178318","rc":[{"atb":[[5.8,0.21]],"id":39959056}],"con":true,"img":false}]}
{"op":"mcm","clk":"11541042821","pt":1719501487329,"mc":[{"id":"1.230178318","rc":[{"atb":[[5.8,1.05]],"id":39959056}],"con":true,"img":false}]}
{"op":"mcm","clk":"11541042971","pt":1719501489205,"mc":[{"id":"1.230178318","rc":[{"atl":[[5.4,0]],"id":40214683}],"con":true,"img":false}]}
{"op":"mcm","clk":"11541043021","pt":1719501489931,"mc":[{"id":"1.230178318","rc":[{"atl":[[5.3,0.03]],"id":40214683}],"con":true,"img":false}]}
{"op":"mcm","clk":"11541043115","pt":1719501491130,"mc":[{"id":"1.230178318","rc":[{"atl":[[5.4,2]],"id":40214683}],"con":true,"img":false}]}
{"op":"mcm","clk":"11541043192","pt":1719501492229,"mc":[{"id":"1.230178318","rc":[{"atl":[[5.3,0.87]],"id":40214683}],"con":true,"img":false}]}
{"op":"mcm","clk":"11541043284","pt":1719501493425,"mc":[{"id":"1.230178318","rc":[{"atb":[[4.8,0],[2.72,58.14],[3.1,0.79],[4.7,0]],"id":56418091},{"atl":[[4.7,2.53]],"id":56418091},{"trd":[[4.7,2],[4.8,0.13]],"ltp":4.7,"tv":2.13,"id":56418091}],"con":true,"img":false}]}
{"op":"mcm","clk":"11541043294","pt":1719501493530,"mc":[{"id":"1.230178318","rc":[{"atb":[[2.9,6.35]],"id":56418091},{"atl":[[34,0],[9.2,3.53],[4.7,0]],"id":56418091},{"trd":[[4.7,7.06]],"ltp":4.7,"tv":7.06,"id":56418091}],"con":true,"img":false}]}
{"op":"mcm","clk":"11541043307","pt":1719501493731,"mc":[{"id":"1.230178318","rc":[{"atb":[[2.9,7.19]],"id":56418091},{"atl":[[9.2,0],[27,3.53]],"id":56418091}],"con":true,"img":false}]}
{"op":"mcm","clk":"11541043321","pt":1719501493943,"mc":[{"id":"1.230178318","rc":[{"atb":[[3.75,0]],"id":62766534},{"atb":[[5.3,0]],"id":39959056},{"atb":[[3,0]],"id":40214683},{"atb":[[5.6,0]],"id":70642246}],"con":true,"img":false}]}
{"op":"mcm","clk":"11541043328","pt":1719501494035,"mc":[{"id":"1.230178318","rc":[{"atb":[[4.2,8]],"id":70642246}],"con":true,"img":false}]}
{"op":"mcm","clk":"11541043337","pt":1719501494138,"mc":[{"id":"1.230178318","rc":[{"atb":[[5,1]],"id":70642246}],"con":true,"img":false}]}
{"op":"mcm","clk":"11541043356","pt":1719501494309,"mc":[{"id":"1.230178318","rc":[{"atb":[[4.2,1]],"id":56418091}],"con":true,"img":false}]}
{"op":"mcm","clk":"11541043398","pt":1719501494824,"mc":[{"id":"1.230178318","rc":[{"atb":[[2.9,0.84]],"id":56418091}],"con":true,"img":false}]}
{"op":"mcm","clk":"11541043405","pt":1719501494923,"mc":[{"id":"1.230178318","rc":[{"atb":[[1.25,20]],"id":62766534},{"atb":[[1.25,20]],"id":39959056},{"atb":[[1.25,20]],"id":40214683},{"atb":[[1.25,20]],"id":56418091},{"atb":[[1.25,20]],"id":69261147},{"atb":[[1.25,20]],"id":70642246}],"con":true,"img":false}]}
{"op":"mcm","clk":"11541043510","pt":1719501496331,"mc":[{"id":"1.230178318","rc":[{"atl":[[5.4,0]],"id":40214683}],"con":true,"img":false}]}
{"op":"mcm","clk":"11541043549","pt":1719501496744,"mc":[{"id":"1.230178318","rc":[{"atl":[[5.3,0.03]],"id":40214683}],"con":true,"img":false}]}
{"op":"mcm","clk":"11541043671","pt":1719501498341,"mc":[{"id":"1.230178318","rc":[{"atl":[[5.4,2]],"id":40214683}],"con":true,"img":false}]}
{"op":"mcm","clk":"11541043750","pt":1719501499333,"mc":[{"id":"1.230178318","rc":[{"atl":[[5.3,0.87]],"id":40214683}],"con":true,"img":false}]}
{"op":"mcm","clk":"11541043921","pt":1719501501508,"mc":[{"id":"1.230178318","rc":[{"atl":[[130,0.84]],"id":39959056}],"con":true,"img":false}]}
{"op":"mcm","clk":"11541043945","pt":1719501501817,"mc":[{"id":"1.230178318","rc":[{"atb":[[5.8,0.84]],"id":39959056}],"con":true,"img":false}]}
{"op":"mcm","clk":"11541043952","pt":1719501501920,"mc":[{"id":"1.230178318","rc":[{"atb":[[1.1,1]],"id":39959056},{"atl":[[1000,0.01]],"id":39959056}],"con":true,"img":false}]}
{"op":"mcm","clk":"11541043957","pt":1719501502023,"mc":[{"id":"1.230178318","rc":[{"atb":[[1.1,0.2]],"id":39959056},{"atl":[[1000,0]],"id":39959056}],"con":true,"img":false}]}
{"op":"mcm","clk":"11541043965","pt":1719501502127,"mc":[{"id":"1.230178318","rc":[{"atl":[[130,0.85]],"id":39959056}],"con":true,"img":false}]}
{"op":"mcm","clk":"11541043975","pt":1719501502235,"mc":[{"id":"1.230178318","rc":[{"atb":[[1.1,0]],"id":39959056}],"con":true,"img":false}]}
{"op":"mcm","clk":"11541043987","pt":1719501502340,"mc":[{"id":"1.230178318","rc":[{"atb":[[5.9,0.2]],"id":39959056}],"con":true,"img":false}]}
{"op":"mcm","clk":"11541044076","pt":1719501503633,"mc":[{"id":"1.230178318","rc":[{"atl":[[5.4,0]],"id":40214683}],"con":true,"img":false}]}
{"op":"mcm","clk":"11541044122","pt":1719501504448,"mc":[{"id":"1.230178318","rc":[{"atl":[[5.3,0.03]],"id":40214683}],"con":true,"img":false}]}
{"op":"mcm","clk":"11541044142","pt":1719501504718,"mc":[{"id":"1.230178318","rc":[{"atb":[[2.74,3.96]],"id":62766534},{"atb":[[2.8,2.89]],"id":40214683},{"atb":[[5.5,7.69]],"id":69261147}],"con":true,"img":false}]}
{"op":"mcm","clk":"11541044156","pt":1719501504932,"mc":[{"id":"1.230178318","rc":[{"atl":[[9,14]],"id":69261147}],"con":true,"img":false}]}
{"op":"mcm","clk":"11541044170","pt":1719501505134,"mc":[{"id":"1.230178318","rc":[{"atl":[[9,18]],"id":69261147}],"con":true,"img":false}]}
{"op":"mcm","clk":"11541044222","pt":1719501505847,"mc":[{"id":"1.230178318","rc":[{"atl":[[5.4,2]],"id":40214683}],"con":true,"img":false}]}
{"op":"mcm","clk":"11541044290","pt":1719501506732,"mc":[{"id":"1.230178318","rc":[{"atl":[[5.3,0.87]],"id":40214683}],"con":true,"img":false}]}
{"op":"mcm","clk":"11541044641","pt":1719501511054,"mc":[{"id":"1.230178318","rc":[{"spn":2.93,"spf":1.0,"id":62766534},{"atl":[[5.4,0]],"id":40214683},{"spn":2.81,"spf":1.0,"id":40214683},{"spn":3.25,"spf":1.0,"id":56418091},{"spn":3.33,"spf":1.21,"id":69261147},{"spn":5.4,"spf":1.0,"id":70642246}],"con":true,"img":false}]}
{"op":"mcm","clk":"11541044701","pt":1719501511833,"mc":[{"id":"1.230178318","rc":[{"atl":[[5.3,0.03]],"id":40214683}],"con":true,"img":false}]}
{"op":"mcm","clk":"11541044806","pt":1719501513040,"mc":[{"id":"1.230178318","rc":[{"atl":[[5.4,2]],"id":40214683}],"con":true,"img":false}]}
{"op":"mcm","clk":"11541044858","pt":1719501513747,"mc":[{"id":"1.230178318","rc":[{"atl":[[5.3,0.87]],"id":40214683}],"con":true,"img":false}]}
{"op":"mcm","clk":"11541044893","pt":1719501514161,"mc":[{"id":"1.230178318","rc":[{"atb":[[3.1,0]],"id":56418091}],"con":true,"img":false}]}
{"op":"mcm","clk":"11541045156","pt":1719501517327,"mc":[{"id":"1.230178318","rc":[{"atl":[[130,0.84]],"id":39959056}],"con":true,"img":false}]}
{"op":"mcm","clk":"11541045170","pt":1719501517533,"mc":[{"id":"1.230178318","rc":[{"atb":[[5.9,0]],"id":39959056}],"con":true,"img":false}]}
{"op":"mcm","clk":"11541045188","pt":1719501517742,"mc":[{"id":"1.230178318","rc":[{"atb":[[1.1,1]],"id":39959056},{"atl":[[1000,0.01]],"id":39959056}],"con":true,"img":false}]}
{"op":"mcm","clk":"11541045195","pt":1719501517845,"mc":[{"id":"1.230178318","rc":[{"atb":[[1.1,0.2]],"id":39959056},{"atl":[[1000,0]],"id":39959056}],"con":true,"img":false}]}
{"op":"mcm","clk":"11541045203","pt":1719501517948,"mc":[{"id":"1.230178318","rc":[{"atl":[[130,0.85]],"id":39959056}],"con":true,"img":false}]}
{"op":"mcm","clk":"11541045210","pt":1719501518058,"mc":[{"id":"1.230178318","rc":[{"atb":[[1.1,0]],"id":39959056}],"con":true,"img":false}]}
{"op":"mcm","clk":"11541045223","pt":1719501518159,"mc":[{"id":"1.230178318","rc":[{"atb":[[5.9,0.2]],"id":39959056}],"con":true,"img":false}]}
{"op":"mcm","clk":"11541045234","pt":1719501518255,"mc":[{"id":"1.230178318","rc":[{"atl":[[5.4,0]],"id":40214683}],"con":true,"img":false}]}
{"op":"mcm","clk":"11541045277","pt":1719501518641,"mc":[{"id":"1.230178318","rc":[{"atl":[[5.3,0.03]],"id":40214683}],"con":true,"img":false}]}
{"op":"mcm","clk":"11541045305","pt":1719501519048,"mc":[{"id":"1.230178318","rc":[{"atb":[[2.46,8.69]],"id":40214683}],"con":true,"img":false}]}
{"op":"mcm","clk":"11541045335","pt":1719501519463,"mc":[{"id":"1.230178318","rc":[{"atb":[[2.78,3.54]],"id":56418091},{"atb":[[3.1,3.01]],"id":69261147}],"con":true,"img":false}]}
{"op":"mcm","clk":"11541045352","pt":1719501519669,"mc":[{"id":"1.230178318","rc":[{"atb":[[2.16,5.45]],"id":39959056},{"atb":[[2.78,8.87]],"id":56418091}],"con":true,"img":false}]}
{"op":"mcm","clk":"11541045371","pt":1719501519836,"mc":[{"id":"1.230178318","rc":[{"atb":[[2.88,9.47]],"id":56418091},{"atb":[[3.1,8.65]],"id":70642246}],"con":true,"img":false}]}
{"op":"mcm","clk":"11541045387","pt":1719501520153,"mc":[{"id":"1.230178318","rc":[{"atl":[[5.4,2]],"id":40214683}],"con":true,"img":false}]}
{"op":"mcm","clk":"11541045434","pt":1719501520772,"mc":[{"id":"1.230178318","rc":[{"atl":[[5.3,0.87]],"id":40214683}],"con":true,"img":false}]}
{"op":"mcm","clk":"11541045476","pt":1719501521236,"mc":[{"id":"1.230178318","rc":[{"atb":[[2.96,2.09]],"id":56418091}],"con":true,"img":false}]}
{"op":"mcm","clk":"11541045519","pt":1719501521752,"mc":[{"id":"1.230178318","rc":[{"atb":[[2.9,0]],"id":56418091}],"con":true,"img":false}]}
{"op":"mcm","clk":"11541045646","pt":1719501523390,"mc":[{"id":"1.230178318","rc":[{"atb":[[5.8,0],[5.5,1]],"id":70642246}],"con":true,"img":false}]}
{"op":"mcm","clk":"11541045655","pt":1719501523515,"mc":[{"id":"1.230178318","rc":[{"atb":[[5,7],[4.2,0]],"id":70642246}],"con":true,"img":false}]}
{"op":"mcm","clk":"11541045665","pt":1719501523560,"mc":[{"id":"1.230178318","rc":[{"atb":[[4.2,8]],"id":70642246}],"con":true,"img":false}]}
{"op":"mcm","clk":"11541045675","pt":1719501523691,"mc":[{"id":"1.230178318","rc":[{"atb":[[5,1]],"id":70642246}],"con":true,"img":false}]}
{"op":"mcm","clk":"11541045691","pt":1719501523863,"mc":[{"id":"1.230178318","rc":[{"atb":[[2.46,0]],"id":40214683}],"con":true,"img":false}]}
{"op":"mcm","clk":"11541045717","pt":1719501524243,"mc":[{"id":"1.230178318","rc":[{"atb":[[5.8,1],[5.5,0]],"id":70642246}],"con":true,"img":false}]}
{"op":"mcm","clk":"11541045724","pt":1719501524341,"mc":[{"id":"1.230178318","rc":[{"atb":[[5,7],[4.2,0]],"id":70642246}],"con":true,"img":false}]}
{"op":"mcm","clk":"11541045731","pt":1719501524443,"mc":[{"id":"1.230178318","rc":[{"atb":[[5,1],[4.2,8.66]],"id":70642246}],"con":true,"img":false}]}
{"op":"mcm","clk":"11541045819","pt":1719501525467,"mc":[{"id":"1.230178318","rc":[{"atl":[[5.4,0]],"id":40214683}],"con":true,"img":false}]}
{"op":"mcm","clk":"11541045828","pt":1719501525571,"mc":[{"id":"1.230178318","rc":[{"atb":[[5.8,0],[5.5,1]],"id":70642246}],"con":true,"img":false}]}
{"op":"mcm","clk":"11541045891","pt":1719501526280,"mc":[{"id":"1.230178318","rc":[{"atl":[[5.3,0.03]],"id":40214683}],"con":true,"img":false}]}
{"op":"mcm","clk":"11541045971","pt":1719501527278,"mc":[{"id":"1.230178318","rc":[{"atl":[[5.4,2]],"id":40214683},{"atl":[[9,1]],"id":70642246}],"con":true,"img":false}]}
{"op":"mcm","clk":"11541046007","pt":1719501527755,"mc":[{"id":"1.230178318","rc":[{"atl":[[5.3,0.87]],"id":40214683}],"con":true,"img":false}]}
{"op":"mcm","clk":"11541046048","pt":1719501528360,"mc":[{"id":"1.230178318","rc":[{"atb":[[6,1.41]],"id":39959056}],"con":true,"img":false}]}
{"op":"mcm","clk":"11541046055","pt":1719501528463,"mc":[{"id":"1.230178318","rc":[{"atb":[[5.7,0]],"id":39959056}],"con":true,"img":false}]}
{"op":"mcm","clk":"11541046065","pt":1719501528670,"mc":[{"id":"1.230178318","rc":[{"atl":[[8.4,1]],"id":56418091}],"con":true,"img":false}]}
{"op":"mcm","clk":"11541046072","pt":1719501528774,"mc":[{"id":"1.230178318","rc":[{"atl":[[9.2,3.53]],"id":56418091}],"con":true,"img":false}]}
{"op":"mcm","clk":"11541046080","pt":1719501528877,"mc":[{"id":"1.230178318","rc":[{"atb":[[5.9,1.61]],"id":39959056},{"atl":[[27,0],[28,0]],"id":56418091}],"con":true,"img":false}]}
{"op":"mcm","clk":"11541046090","pt":1719501529043,"mc":[{"id":"1.230178318","rc":[{"atb":[[5.6,0],[6,0]],"id":39959056},{"atl":[[9,1]],"id":56418091}],"con":true,"img":false}]}
{"op":"mcm","clk":"11541046104","pt":1719501529261,"mc":[{"id":"1.230178318","rc":[{"atb":[[6.2,1]],"id":39959056}],"con":true,"img":false}]}
{"op":"mcm","clk":"11541046116","pt":1719501529452,"mc":[{"id":"1.230178318","rc":[{"atb":[[5.9,0.2],[6.2,2.36]],"id":39959056}],"con":true,"img":false}]}
{"op":"mcm","clk":"11541046133","pt":1719501529662,"mc":[{"id":"1.230178318","rc":[{"atb":[[6.4,0.84]],"id":39959056}],"con":true,"img":false}]}
{"op":"mcm","clk":"11541046142","pt":1719501529772,"mc":[{"id":"1.230178318","rc":[{"atb":[[5.8,0]],"id":39959056}],"con":true,"img":false}]}
{"op":"mcm","clk":"11541046176","pt":1719501530174,"mc":[{"id":"1.230178318","rc":[{"atb":[[5.8,1],[5.5,0]],"id":70642246}],"con":true,"img":false}]}
{"op":"mcm","clk":"11541046248","pt":1719501531173,"mc":[{"id":"1.230178318","rc":[{"atb":[[5.8,0],[5.5,1]],"id":70642246}],"con":true,"img":false}]}
{"op":"mcm","clk":"11541046259","pt":1719501531282,"mc":[{"id":"1.230178318","rc":[{"atb":[[5,7],[4.2,0]],"id":70642246}],"con":true,"img":false}]}
{"op":"mcm","clk":"11541046379","pt":1719501532578,"mc":[{"id":"1.230178318","rc":[{"atl":[[5.4,0]],"id":40214683}],"con":true,"img":false}]}
{"op":"mcm","clk":"11541046423","pt":1719501533148,"mc":[{"id":"1.230178318","rc":[{"atl":[[130,0.84]],"id":39959056}],"con":true,"img":false}]}
{"op":"mcm","clk":"11541046433","pt":1719501533256,"mc":[{"id":"1.230178318","rc":[{"atl":[[5.3,0.03]],"id":40214683}],"con":true,"img":false}]}
{"op":"mcm","clk":"11541046442","pt":1719501533353,"mc":[{"id":"1.230178318","rc":[{"atb":[[5.9,0]],"id":39959056}],"con":true,"img":false}]}
{"op":"mcm","clk":"11541046458","pt":1719501533560,"mc":[{"id":"1.230178318","rc":[{"atb":[[1.11,1]],"id":39959056},{"atl":[[1000,0.01]],"id":39959056}],"con":true,"img":false}]}
{"op":"mcm","clk":"11541046476","pt":1719501533764,"mc":[{"id":"1.230178318","rc":[{"atb":[[1.11,0.19]],"id":39959056},{"atl":[[1000,0]],"id":39959056}],"con":true,"img":false}]}
{"op":"mcm","clk":"11541046482","pt":1719501533862,"mc":[{"id":"1.230178318","rc":[{"atl":[[130,0.85]],"id":39959056}],"con":true,"img":false}]}
{"op":"mcm","clk":"11541046490","pt":1719501533979,"mc":[{"id":"1.230178318","rc":[{"atb":[[1.11,0]],"id":39959056}],"con":true,"img":false}]}
{"op":"mcm","clk":"11541046499","pt":1719501534075,"mc":[{"id":"1.230178318","rc":[{"atb":[[6.4,1.03]],"id":39959056}],"con":true,"img":false}]}
{"op":"mcm","clk":"11541046540","pt":1719501534580,"mc":[{"id":"1.230178318","rc":[{"atl":[[5.4,2]],"id":40214683}],"con":true,"img":false}]}
{"op":"mcm","clk":"11541046595","pt":1719501535258,"mc":[{"id":"1.230178318","rc":[{"atl":[[5.3,0.87]],"id":40214683}],"con":true,"img":false}]}
{"op":"mcm","clk":"11541046665","pt":1719501536285,"mc":[{"id":"1.230178318","rc":[{"atb":[[2.48,0]],"id":40214683}],"con":true,"img":false}]}
{"op":"mcm","clk":"11541046672","pt":1719501536387,"mc":[{"id":"1.230178318","rc":[{"atb":[[5,1],[4.2,8.66]],"id":70642246}],"con":true,"img":false}]}
{"op":"mcm","clk":"11541046680","pt":1719501536447,"mc":[{"id":"1.230178318","rc":[{"atb":[[2.16,11.29]],"id":39959056}],"con":true,"img":false}]}
{"op":"mcm","clk":"11541046688","pt":1719501536550,"mc":[{"id":"1.230178318","rc":[{"atb":[[2.38,9.2]],"id":40214683}],"con":true,"img":false}]}
{"op":"mcm","clk":"11541046704","pt":1719501536757,"mc":[{"id":"1.230178318","rc":[{"atb":[[2.26,10.07]],"id":39959056}],"con":true,"img":false}]}
{"op":"mcm","clk":"11541046713","pt":1719501536872,"mc":[{"id":"1.230178318","rc":[{"atb":[[3.1,6.23]],"id":69261147}],"con":true,"img":false}]}
{"op":"mcm","clk":"11541046734","pt":1719501537077,"mc":[{"id":"1.230178318","rc":[{"atb":[[2.78,12.68]],"id":56418091}],"con":true,"img":false}]}
{"op":"mcm","clk":"11541046743","pt":1719501537173,"mc":[{"id":"1.230178318","rc":[{"atb":[[2.9,3.38]],"id":56418091}],"con":true,"img":false}]}
{"op":"mcm","clk":"11541046762","pt":1719501537378,"mc":[{"id":"1.230178318","rc":[{"atb":[[3.1,11.88]],"id":70642246}],"con":true,"img":false}]}
{"op":"mcm","clk":"11541046773","pt":1719501537491,"mc":[{"id":"1.230178318","rc":[{"atb":[[2.9,10.06]],"id":56418091}],"con":true,"img":false}]}
{"op":"mcm","clk":"11541046805","pt":1719501537787,"mc":[{"id":"1.230178318","rc":[{"atb":[[2.78,18.38]],"id":56418091}],"con":true,"img":false}]}
{"op":"mcm","clk":"11541046847","pt":1719501538170,"mc":[{"id":"1.230178318","rc":[{"atb":[[3.15,5.91]],"id":70642246}],"con":true,"img":false}]}
{"op":"mcm","clk":"11541046993","pt":1719501539759,"mc":[{"id":"1.230178318","rc":[{"atl":[[5.4,0]],"id":40214683}],"con":true,"img":false}]}
{"op":"mcm","clk":"11541047030","pt":1719501540174,"mc":[{"id":"1.230178318","rc":[{"atl":[[5.3,0.03]],"id":40214683}],"con":true,"img":false}]}
{"op":"mcm","clk":"11541047048","pt":1719501540379,"mc":[{"id":"1.230178318","rc":[{"atb":[[4.3,7.89]],"id":70642246},{"atl":[[9.4,4.08]],"id":70642246}],"con":true,"img":false}]}
{"op":"mcm","clk":"11541047068","pt":1719501540587,"mc":[{"id":"1.230178318","rc":[{"atl":[[24,0]],"id":70642246}],"con":true,"img":false}]}
{"op":"mcm","clk":"11541047086","pt":1719501540790,"mc":[{"id":"1.230178318","rc":[{"atl":[[9.2,1]],"id":70642246}],"con":true,"img":false}]}
{"op":"mcm","clk":"11541047152","pt":1719501541682,"mc":[{"id":"1.230178318","rc":[{"atl":[[5.4,2]],"id":40214683}],"con":true,"img":false}]}
{"op":"mcm","clk":"11541047232","pt":1719501542682,"mc":[{"id":"1.230178318","rc":[{"atl":[[5.3,0.87]],"id":40214683}],"con":true,"img":false}]}
{"op":"mcm","clk":"11541047523","pt":1719501546980,"mc":[{"id":"1.230178318","rc":[{"atl":[[5.4,0]],"id":40214683}],"con":true,"img":false}]}
{"op":"mcm","clk":"11541047556","pt":1719501547401,"mc":[{"id":"1.230178318","rc":[{"atl":[[5.3,0.03]],"id":40214683}],"con":true,"img":false}]}
{"op":"mcm","clk":"11541047673","pt":1719501548787,"mc":[{"id":"1.230178318","rc":[{"atb":[[1.02,3.7]],"id":62766534},{"atl":[[1000,1.7]],"id":62766534},{"atb":[[1.05,1.7]],"id":39959056},{"atl":[[1000,1.7]],"id":39959056},{"atb":[[1.02,3.7]],"id":40214683},{"atl":[[5.4,2],[1000,1.7]],"id":40214683}],"con":true,"img":false}]}
{"op":"mcm","clk":"11541047696","pt":1719501548999,"mc":[{"id":"1.230178318","rc":[{"atb":[[1.02,2.16]],"id":62766534},{"atl":[[1000,0.02]],"id":62766534},{"atb":[[1.05,0.05]],"id":39959056},{"atl":[[1000,0]],"id":39959056},{"atb":[[1.02,2.15]],"id":40214683},{"atl":[[1000,0.05]],"id":40214683}],"con":true,"img":false}]}
{"op":"mcm","clk":"11541047713","pt":1719501549202,"mc":[{"id":"1.230178318","rc":[{"atl":[[130,0.84]],"id":39959056}],"con":true,"img":false}]}
{"op":"mcm","clk":"11541047723","pt":1719501549302,"mc":[{"id":"1.230178318","rc":[{"atb":[[1.02,2]],"id":62766534},{"atl":[[1000,0]],"id":62766534},{"atb":[[6.4,0.84],[1.05,0]],"id":39959056},{"atb":[[1.02,2]],"id":40214683},{"atl":[[1000,0]],"id":40214683}],"con":true,"img":false}]}
{"op":"mcm","clk":"11541047727","pt":1719501549364,"mc":[{"id":"1.230178318","rc":[{"atb":[[2.76,0.16]],"id":62766534},{"atl":[[10.5,0.02]],"id":62766534},{"atb":[[6.4,0.89]],"id":39959056},{"atb":[[2.82,0.15]],"id":40214683},{"atl":[[6.2,0.05]],"id":40214683}],"con":true,"img":false}]}
{"op":"mcm","clk":"11541047741","pt":1719501549583,"mc":[{"id":"1.230178318","rc":[{"atb":[[1.12,1]],"id":39959056},{"atl":[[1000,0.01]],"id":39959056}],"con":true,"img":false}]}
{"op":"mcm","clk":"11541047750","pt":1719501549688,"mc":[{"id":"1.230178318","rc":[{"atb":[[1.12,0.18]],"id":39959056},{"atl":[[1000,0]],"id":39959056}],"con":true,"img":false}]}
{"op":"mcm","clk":"11541047758","pt":1719501549788,"mc":[{"id":"1.230178318","rc":[{"atl":[[130,0.85]],"id":39959056},{"atl":[[5.3,0.87]],"id":40214683}],"con":true,"img":false}]}
{"op":"mcm","clk":"11541047777","pt":1719501549892,"mc":[{"id":"1.230178318","rc":[{"atb":[[1.12,0]],"id":39959056}],"con":true,"img":false}]}
{"op":"mcm","clk":"11541047786","pt":1719501549984,"mc":[{"id":"1.230178318","rc":[{"atb":[[6.6,0.18]],"id":39959056}],"con":true,"img":false}]}
{"op":"mcm","clk":"11541048025","pt":1719501552667,"mc":[{"id":"1.230178318","rc":[{"atb":[[2.88,6.3]],"id":56418091}],"con":true,"img":false}]}
{"op":"mcm","clk":"11541048034","pt":1719501552772,"mc":[{"id":"1.230178318","rc":[{"atb":[[2.4,8.46]],"id":40214683}],"con":true,"img":false}]}
{"op":"mcm","clk":"11541048135","pt":1719501554004,"mc":[{"id":"1.230178318","rc":[{"atl":[[5.4,0]],"id":40214683}],"con":true,"img":false}]}
{"op":"mcm","clk":"11541048197","pt":1719501554789,"mc":[{"id":"1.230178318","rc":[{"atl":[[5.3,0.03]],"id":40214683}],"con":true,"img":false}]}
{"op":"mcm","clk":"11541048324","pt":1719501556390,"mc":[{"id":"1.230178318","rc":[{"atl":[[5.4,2]],"id":40214683}],"con":true,"img":false}]}
{"op":"mcm","clk":"11541048394","pt":1719501557305,"mc":[{"id":"1.230178318","rc":[{"atl":[[5.3,0.87]],"id":40214683}],"con":true,"img":false}]}
{"op":"mcm","clk":"11541048866","pt":1719501561708,"mc":[{"id":"1.230178318","rc":[{"atl":[[5.4,0]],"id":40214683}],"con":true,"img":false}]}
{"op":"mcm","clk":"11541048902","pt":1719501562287,"mc":[{"id":"1.230178318","rc":[{"atl":[[5.3,0.03]],"id":40214683}],"con":true,"img":false}]}
{"op":"mcm","clk":"11541049004","pt":1719501563624,"mc":[{"id":"1.230178318","rc":[{"atl":[[5.4,2]],"id":40214683}],"con":true,"img":false}]}
{"op":"mcm","clk":"11541049098","pt":1719501564715,"mc":[{"id":"1.230178318","rc":[{"atl":[[5.3,0.87]],"id":40214683}],"con":true,"img":false}]}
{"op":"mcm","clk":"11541049127","pt":1719501565020,"mc":[{"id":"1.230178318","rc":[{"atl":[[130,0.84]],"id":39959056}],"con":true,"img":false}]}
{"op":"mcm","clk":"11541049147","pt":1719501565193,"mc":[{"id":"1.230178318","rc":[{"atb":[[6.6,0]],"id":39959056}],"con":true,"img":false}]}
{"op":"mcm","clk":"11541049182","pt":1719501565600,"mc":[{"id":"1.230178318","rc":[{"atb":[[1.12,1]],"id":39959056},{"atl":[[1000,0.01]],"id":39959056}],"con":true,"img":false}]}
{"op":"mcm","clk":"11541049195","pt":1719501565805,"mc":[{"id":"1.230178318","rc":[{"atb":[[1.12,0.18]],"id":39959056},{"atl":[[1000,0]],"id":39959056}],"con":true,"img":false}]}
{"op":"mcm","clk":"11541049207","pt":1719501565909,"mc":[{"id":"1.230178318","rc":[{"atl":[[130,0.85]],"id":39959056},{"atb":[[7,2.14]],"id":70642246}],"con":true,"img":false}]}
{"op":"mcm","clk":"11541049215","pt":1719501566010,"mc":[{"id":"1.230178318","rc":[{"atb":[[1.12,0]],"id":39959056},{"atb":[[5,8.89]],"id":70642246}],"con":true,"img":false}]}
{"op":"mcm","clk":"11541049222","pt":1719501566113,"mc":[{"id":"1.230178318","rc":[{"atb":[[2.24,0],[6.6,0.18]],"id":39959056},{"atb":[[4.2,0]],"id":70642246}],"con":true,"img":false}]}
{"op":"mcm","clk":"11541049230","pt":1719501566211,"mc":[{"id":"1.230178318","rc":[{"atb":[[7.2,0.84]],"id":70642246}],"con":true,"img":false}]}
{"op":"mcm","clk":"11541049427","pt":1719501568801,"mc":[{"id":"1.230178318","rc":[{"atb":[[2.72,8.5]],"id":62766534},{"atb":[[2.72,8.68]],"id":40214683}],"con":true,"img":false}]}
{"op":"mcm","clk":"11541049434","pt":1719501568910,"mc":[{"id":"1.230178318","rc":[{"atl":[[5.4,0]],"id":40214683}],"con":true,"img":false}]}
{"op":"mcm","clk":"11541049455","pt":1719501569109,"mc":[{"id":"1.230178318","rc":[{"atb":[[2.74,3.16]],"id":62766534},{"atb":[[2.8,2.09]],"id":40214683}],"con":true,"img":false}]}
{"op":"mcm","clk":"11541049466","pt":1719501569212,"mc":[{"id":"1.230178318","rc":[{"atl":[[5.3,0.03]],"id":40214683}],"con":true,"img":false}]}
{"op":"mcm","clk":"11541049602","pt":1719501570714,"mc":[{"id":"1.230178318","rc":[{"atl":[[5.4,2]],"id":40214683}],"con":true,"img":false}]}
{"op":"mcm","clk":"11541049692","pt":1719501571715,"mc":[{"id":"1.230178318","rc":[{"spn":2.92,"spf":1.0,"id":62766534},{"atl":[[5.3,0.87]],"id":40214683},{"spn":2.8,"spf":1.0,"id":40214683},{"spn":3.25,"spf":1.0,"id":56418091},{"spn":3.4,"spf":1.21,"id":69261147},{"spn":7.08,"spf":1.0,"id":70642246}],"con":true,"img":false}]}
{"op":"mcm","clk":"11541049725","pt":1719501572113,"mc":[{"id":"1.230178318","rc":[{"atb":[[2.38,0]],"id":62766534}],"con":true,"img":false}]}
{"op":"mcm","clk":"11541049751","pt":1719501572426,"mc":[{"id":"1.230178318","rc":[{"atb":[[2.74,6.54]],"id":62766534}],"con":true,"img":false}]}
{"op":"mcm","clk":"11541049834","pt":1719501573314,"mc":[{"id":"1.230178318","rc":[{"atb":[[2.88,0]],"id":56418091},{"atb":[[3.1,6.23]],"id":70642246}],"con":true,"img":false}]}
{"op":"mcm","clk":"11541049843","pt":1719501573418,"mc":[{"id":"1.230178318","rc":[{"atb":[[2.92,3.16]],"id":56418091}],"con":true,"img":false}]}
{"op":"mcm","clk":"11541049905","pt":1719501574128,"mc":[{"id":"1.230178318","rc":[{"atb":[[5.8,1],[5.5,0]],"id":70642246}],"con":true,"img":false}]}
{"op":"mcm","clk":"11541049943","pt":1719501574500,"mc":[{"id":"1.230178318","rc":[{"atb":[[5.8,0]],"id":70642246}],"con":true,"img":false}]}
{"op":"mcm","clk":"11541050074","pt":1719501576028,"mc":[{"id":"1.230178318","rc":[{"atl":[[5.4,0]],"id":40214683}],"con":true,"img":false}]}
{"op":"mcm","clk":"11541050100","pt":1719501576301,"mc":[{"id":"1.230178318","rc":[{"atl":[[5.3,0.03]],"id":40214683}],"con":true,"img":false}]}
{"op":"mcm","clk":"11541050188","pt":1719501577431,"mc":[{"id":"1.230178318","rc":[{"atb":[[7,0]],"id":70642246}],"con":true,"img":false}]}
{"op":"mcm","clk":"11541050223","pt":1719501577804,"mc":[{"id":"1.230178318","rc":[{"atb":[[7.2,0]],"id":70642246}],"con":true,"img":false}]}
{"op":"mcm","clk":"11541050275","pt":1719501578325,"mc":[{"id":"1.230178318","rc":[{"atb":[[5.1,0.84]],"id":70642246}],"con":true,"img":false}]}
{"op":"mcm","clk":"11541050283","pt":1719501578421,"mc":[{"id":"1.230178318","rc":[{"atl":[[5.4,2]],"id":40214683}],"con":true,"img":false}]}
{"op":"mcm","clk":"11541050311","pt":1719501578826,"mc":[{"id":"1.230178318","rc":[{"atl":[[5.3,0.87]],"id":40214683}],"con":true,"img":false}]}
{"op":"mcm","clk":"11541050442","pt":1719501580325,"mc":[{"id":"1.230178318","rc":[{"atb":[[2.74,9.28]],"id":62766534},{"atb":[[5.1,1.47]],"id":39959056},{"atb":[[2.94,2.55]],"id":56418091},{"atb":[[5.2,1.44]],"id":69261147},{"atb":[[4.2,1.79]],"id":70642246}],"con":true,"img":false}]}
{"op":"mcm","clk":"11541050487","pt":1719501580710,"mc":[{"id":"1.230178318","rc":[{"atb":[[5.2,7.49]],"id":69261147}],"con":true,"img":false}]}
{"op":"mcm","clk":"11541050524","pt":1719501581126,"mc":[{"id":"1.230178318","rc":[{"atl":[[130,0.84]],"id":39959056}],"con":true,"img":false}]}
{"op":"mcm","clk":"11541050548","pt":1719501581423,"mc":[{"id":"1.230178318","rc":[{"atb":[[6.6,0]],"id":39959056}],"con":true,"img":false}]}
{"op":"mcm","clk":"11541050580","pt":1719501581798,"mc":[{"id":"1.230178318","rc":[{"atb":[[1.12,1]],"id":39959056},{"atl":[[1000,0.01]],"id":39959056}],"con":true,"img":false}]}
{"op":"mcm","clk":"11541050598","pt":1719501582105,"mc":[{"id":"1.230178318","rc":[{"atb":[[1.12,0.18]],"id":39959056},{"atl":[[1000,0]],"id":39959056}],"con":true,"img":false}]}
{"op":"mcm","clk":"11541050604","pt":1719501582208,"mc":[{"id":"1.230178318","rc":[{"atl":[[130,0.85]],"id":39959056}],"con":true,"img":false}]}
{"op":"mcm","clk":"11541050614","pt":1719501582315,"mc":[{"id":"1.230178318","rc":[{"atb":[[1.12,0]],"id":39959056}],"con":true,"img":false}]}
{"op":"mcm","clk":"11541050618","pt":1719501582419,"mc":[{"id":"1.230178318","rc":[{"atb":[[6.6,0.18]],"id":39959056}],"con":true,"img":false}]}
{"op":"mcm","clk":"11541050706","pt":1719501583513,"mc":[{"id":"1.230178318","rc":[{"atl":[[5.4,0]],"id":40214683},{"atb":[[5.5,1]],"id":70642246}],"con":true,"img":false}]}
{"op":"mcm","clk":"11541050757","pt":1719501584332,"mc":[{"id":"1.230178318","rc":[{"atl":[[5.3,0.03]],"id":40214683}],"con":true,"img":false}]}
{"op":"mcm","clk":"11541050805","pt":1719501585018,"mc":[{"id":"1.230178318","rc":[{"atb":[[5,0]],"id":69261147}],"con":true,"img":false}]}
{"op":"mcm","clk":"11541050848","pt":1719501585636,"mc":[{"id":"1.230178318","rc":[{"atl":[[5.4,2]],"id":40214683}],"con":true,"img":false}]}
{"op":"mcm","clk":"11541050906","pt":1719501586204,"mc":[{"id":"1.230178318","rc":[{"atl":[[5.3,0.87]],"id":40214683}],"con":true,"img":false}]}
{"op":"mcm","clk":"11541050989","pt":1719501587123,"mc":[{"id":"1.230178318","rc":[{"atb":[[2.76,0]],"id":62766534},{"atl":[[10.5,0]],"id":62766534},{"atb":[[6.4,0.84]],"id":39959056},{"atb":[[2.82,0]],"id":40214683},{"atl":[[6.2,0]],"id":40214683}],"con":true,"img":false}]}
{"op":"mcm","clk":"11541051068","pt":1719501588220,"mc":[{"id":"1.230178318","rc":[{"atb":[[2.76,15.28]],"id":62766534},{"atl":[[10.5,2.8]],"id":62766534}],"con":true,"img":false}]}
{"op":"mcm","clk":"11541051086","pt":1719501588533,"mc":[{"id":"1.230178318","rc":[{"atb":[[6.8,1.24],[6.2,1]],"id":39959056}],"con":true,"img":false}]}
{"op":"mcm","clk":"11541051104","pt":1719501588835,"mc":[{"id":"1.230178318","rc":[{"atb":[[6.8,0],[6.6,1.42]],"id":39959056}],"con":true,"img":false}]}
{"op":"mcm","clk":"11541051136","pt":1719501589307,"mc":[{"id":"1.230178318","rc":[{"atb":[[2.74,6.12]],"id":62766534}],"con":true,"img":false}]}
{"op":"mcm","clk":"11541051143","pt":1719501589409,"mc":[{"id":"1.230178318","rc":[{"atb":[[3.2,5.39]],"id":70642246}],"con":true,"img":false}]}
{"op":"mcm","clk":"11541051254","pt":1719501590808,"mc":[{"id":"1.230178318","rc":[{"atl":[[5.4,0]],"id":40214683}],"con":true,"img":false}]}
{"op":"mcm","clk":"11541051272","pt":1719501591015,"mc":[{"id":"1.230178318","rc":[{"atl":[[6.2,4.74]],"id":40214683}],"con":true,"img":false}]}
{"op":"mcm","clk":"11541051294","pt":1719501591333,"mc":[{"id":"1.230178318","rc":[{"atl":[[5.3,0.03]],"id":40214683}],"con":true,"img":false}]}
{"op":"mcm","clk":"11541051402","pt":1719501592628,"mc":[{"id":"1.230178318","rc":[{"atl":[[5.4,2]],"id":40214683}],"con":true,"img":false}]}
{"op":"mcm","clk":"11541051465","pt":1719501593325,"mc":[{"id":"1.230178318","rc":[{"atl":[[5.3,0.87]],"id":40214683}],"con":true,"img":false}]}
{"op":"mcm","clk":"11541051569","pt":1719501594313,"mc":[{"id":"1.230178318","rc":[{"atb":[[2.72,9.25]],"id":62766534},{"atb":[[2.72,9.02]],"id":40214683}],"con":true,"img":false}]}
{"op":"mcm","clk":"11541051836","pt":1719501597429,"mc":[{"id":"1.230178318","rc":[{"atl":[[130,0.84]],"id":39959056}],"con":true,"img":false}]}
{"op":"mcm","clk":"11541051855","pt":1719501597652,"mc":[{"id":"1.230178318","rc":[{"atb":[[6.6,1.24]],"id":39959056}],"con":true,"img":false}]}
{"op":"mcm","clk":"11541051872","pt":1719501597843,"mc":[{"id":"1.230178318","rc":[{"atb":[[1.12,1]],"id":39959056},{"atl":[[1000,0.01]],"id":39959056},{"atl":[[5.4,0]],"id":40214683}],"con":true,"img":false}]}
{"op":"mcm","clk":"11541051889","pt":1719501598041,"mc":[{"id":"1.230178318","rc":[{"atb":[[1.12,0.17]],"id":39959056},{"atl":[[1000,0]],"id":39959056}],"con":true,"img":false}]}
{"op":"mcm","clk":"11541051901","pt":1719501598143,"mc":[{"id":"1.230178318","rc":[{"atl":[[130,0.85]],"id":39959056}],"con":true,"img":false}]}
{"op":"mcm","clk":"11541051911","pt":1719501598247,"mc":[{"id":"1.230178318","rc":[{"atb":[[1.12,0]],"id":39959056},{"atl":[[5.3,0.03]],"id":40214683}],"con":true,"img":false}]}
{"op":"mcm","clk":"11541051920","pt":1719501598349,"mc":[{"id":"1.230178318","rc":[{"atb":[[6.8,0.17]],"id":39959056}],"con":true,"img":false}]}
{"op":"mcm","clk":"11541052049","pt":1719501599918,"mc":[{"id":"1.230178318","rc":[{"atl":[[5.4,2]],"id":40214683}],"con":true,"img":false}]}
{"op":"mcm","clk":"11541052084","pt":1719501600330,"mc":[{"id":"1.230178318","rc":[{"atl":[[5.3,0.87]],"id":40214683}],"con":true,"img":false}]}
{"op":"mcm","clk":"11541052097","pt":1719501600456,"mc":[{"id":"1.230178318","rc":[{"atl":[[7,0.26]],"id":62766534},{"atl":[[120,0.26]],"id":39959056},{"atl":[[5.2,0.26]],"id":40214683},{"atl":[[8.2,0.26]],"id":56418091},{"atl":[[9,18.26]],"id":69261147},{"atl":[[8.8,0.26]],"id":70642246}],"con":true,"img":false}]}
{"op":"mcm","clk":"11541052140","pt":1719501600925,"mc":[{"id":"1.230178318","rc":[{"atl":[[5.4,0]],"id":40214683}],"con":true,"img":false}]}
{"op":"mcm","clk":"11541052178","pt":1719501601350,"mc":[{"id":"1.230178318","rc":[{"atl":[[5.3,0.03]],"id":40214683}],"con":true,"img":false}]}
{"op":"mcm","clk":"11541052494","pt":1719501605252,"mc":[{"id":"1.230178318","rc":[{"atb":[[2.72,6]],"id":62766534}],"con":true,"img":false}]}
{"op":"mcm","clk":"11541052516","pt":1719501605460,"mc":[{"id":"1.230178318","rc":[{"atb":[[3.75,0.26]],"id":62766534},{"atb":[[5.1,1.73]],"id":39959056},{"atb":[[3,0.26]],"id":40214683},{"atb":[[4.3,0.26]],"id":56418091},{"atb":[[7,0.26]],"id":69261147},{"atb":[[5.6,0.26]],"id":70642246}],"con":true,"img":false}]}
{"op":"mcm","clk":"11541052530","pt":1719501605565,"mc":[{"id":"1.230178318","rc":[{"atb":[[3,12.5]],"id":40214683},{"atb":[[2.98,13.59]],"id":56418091},{"atl":[[9,4]],"id":56418091},{"atb":[[5.6,5.38]],"id":69261147}],"con":true,"img":false}]}
{"op":"mcm","clk":"11541052597","pt":1719501606369,"mc":[{"id":"1.230178318","rc":[{"atb":[[3.05,0.84]],"id":40214683}],"con":true,"img":false}]}
{"op":"mcm","clk":"11541052618","pt":1719501606560,"mc":[{"id":"1.230178318","rc":[{"atb":[[2.26,0]],"id":39959056},{"atb":[[2.8,0],[3.2,2.09],[2.38,0]],"id":40214683},{"atb":[[3.15,2.09],[2.96,0]],"id":56418091},{"atb":[[3.15,0]],"id":70642246}],"con":true,"img":false}]}
{"op":"mcm","clk":"11541052680","pt":1719501607250,"mc":[{"id":"1.230178318","rc":[{"atb":[[3.05,0]],"id":40214683},{"atl":[[5.4,2]],"id":40214683}],"con":true,"img":false}]}
{"op":"mcm","clk":"11541052688","pt":1719501607352,"mc":[{"id":"1.230178318","rc":[{"atb":[[3.2,13.73]],"id":40214683},{"atb":[[3.2,10.13]],"id":56418091}],"con":true,"img":false}]}
{"op":"mcm","clk":"11541052722","pt":1719501607757,"mc":[{"id":"1.230178318","rc":[{"atl":[[5.3,0.87]],"id":40214683}],"con":true,"img":false}]}
{"op":"mcm","clk":"11541052764","pt":1719501608238,"mc":[{"id":"1.230178318","rc":[{"atl":[[5.4,0]],"id":40214683}],"con":true,"img":false}]}
{"op":"mcm","clk":"11541052782","pt":1719501608440,"mc":[{"id":"1.230178318","rc":[{"atb":[[3.2,2.09],[3,11.43]],"id":40214683}],"con":true,"img":false}]}
{"op":"mcm","clk":"11541052797","pt":1719501608652,"mc":[{"id":"1.230178318","rc":[{"atb":[[6.6,3.28]],"id":39959056}],"con":true,"img":false}]}
{"op":"mcm","clk":"11541052812","pt":1719501608848,"mc":[{"id":"1.230178318","rc":[{"atb":[[2.4,0],[2.74,0]],"id":40214683},{"atl":[[5.3,0.03]],"id":40214683},{"atb":[[2.92,0]],"id":56418091}],"con":true,"img":false}]}
{"op":"mcm","clk":"11541052844","pt":1719501609263,"mc":[{"id":"1.230178318","rc":[{"atb":[[6.8,1.01]],"id":39959056}],"con":true,"img":false}]}
{"op":"mcm","clk":"11541052867","pt":1719501609540,"mc":[{"id":"1.230178318","rc":[{"atb":[[6.6,2.04],[7,1.21]],"id":39959056}],"con":true,"img":false}]}
{"op":"mcm","clk":"11541052884","pt":1719501609748,"mc":[{"id":"1.230178318","rc":[{"atb":[[6.2,0]],"id":39959056}],"con":true,"img":false}]}
{"op":"mcm","clk":"11541052892","pt":1719501609848,"mc":[{"id":"1.230178318","rc":[{"atb":[[7.2,1]],"id":39959056}],"con":true,"img":false}]}
{"op":"mcm","clk":"11541052928","pt":1719501610264,"mc":[{"id":"1.230178318","rc":[{"atb":[[6.4,0]],"id":39959056}],"con":true,"img":false}]}
{"op":"mcm","clk":"11541053051","pt":1719501611867,"mc":[{"id":"1.230178318","rc":[{"atl":[[9.2,0],[8.8,4]],"id":56418091}],"con":true,"img":false}]}
{"op":"mcm","clk":"11541053058","pt":1719501611970,"mc":[{"id":"1.230178318","rc":[{"atb":[[5.8,1],[5.5,0]],"id":70642246}],"con":true,"img":false}]}
{"op":"mcm","clk":"11541053066","pt":1719501612039,"mc":[{"id":"1.230178318","rc":[{"atl":[[9,3]],"id":56418091}],"con":true,"img":false}]}
{"op":"mcm","clk":"11541053084","pt":1719501612244,"mc":[{"id":"1.230178318","rc":[{"atl":[[8.6,4.57]],"id":56418091}],"con":true,"img":false}]}
{"op":"mcm","clk":"11541053092","pt":1719501612344,"mc":[{"id":"1.230178318","rc":[{"atl":[[8.4,2]],"id":56418091},{"atb":[[5.8,0],[5.5,1]],"id":70642246}],"con":true,"img":false}]}
{"op":"mcm","clk":"11541053108","pt":1719501612554,"mc":[{"id":"1.230178318","rc":[{"atb":[[1.03,3.4]],"id":40214683},{"atl":[[1000,6.81]],"id":40214683}],"con":true,"img":false}]}
{"op":"mcm","clk":"11541053117","pt":1719501612648,"mc":[{"id":"1.230178318","rc":[{"atb":[[1.03,6.81]],"id":40214683},{"atl":[[8.2,1.1]],"id":56418091}],"con":true,"img":false}]}
{"op":"mcm","clk":"11541053130","pt":1719501612885,"mc":[{"id":"1.230178318","rc":[{"atb":[[1.03,3.58]],"id":40214683},{"atl":[[1000,0.14]],"id":40214683}],"con":true,"img":false}]}
{"op":"mcm","clk":"11541053140","pt":1719501612960,"mc":[{"id":"1.230178318","rc":[{"atb":[[1.03,0.33]],"id":40214683},{"atl":[[8,1.05]],"id":56418091}],"con":true,"img":false}]}
{"op":"mcm","clk":"11541053147","pt":1719501613065,"mc":[{"id":"1.230178318","rc":[{"atb":[[1.03,0.24]],"id":40214683},{"atl":[[1000,0.03]],"id":40214683},{"atl":[[8,4.85],[8.4,1]],"id":56418091}],"con":true,"img":false}]}
{"op":"mcm","clk":"11541053156","pt":1719501613168,"mc":[{"id":"1.230178318","rc":[{"atb":[[1.03,0],[3.25,0.08]],"id":40214683},{"atl":[[1000,0],[6,0.11]],"id":40214683}],"con":true,"img":false}]}
{"op":"mcm","clk":"11541053164","pt":1719501613272,"mc":[{"id":"1.230178318","rc":[{"atb":[[3.25,0.33]],"id":40214683},{"atl":[[6,0.14]],"id":40214683}],"con":true,"img":false}]}
{"op":"mcm","clk":"11541053177","pt":1719501613440,"mc":[{"id":"1.230178318","rc":[{"atl":[[130,0.84]],"id":39959056}],"con":true,"img":false}]}
{"op":"mcm","clk":"11541053187","pt":1719501613649,"mc":[{"id":"1.230178318","rc":[{"atb":[[6.8,0.84]],"id":39959056}],"con":true,"img":false}]}
{"op":"mcm","clk":"11541053194","pt":1719501613751,"mc":[{"id":"1.230178318","rc":[{"atb":[[3.25,1.18]],"id":40214683}],"con":true,"img":false}]}
{"op":"mcm","clk":"11541053200","pt":1719501613852,"mc":[{"id":"1.230178318","rc":[{"atb":[[3.25,12.54]],"id":40214683}],"con":true,"img":false}]}
{"op":"mcm","clk":"11541053219","pt":1719501614051,"mc":[{"id":"1.230178318","rc":[{"atl":[[5.2,0]],"id":40214683}],"con":true,"img":false}]}
{"op":"mcm","clk":"11541053235","pt":1719501614257,"mc":[{"id":"1.230178318","rc":[{"atb":[[1.13,1]],"id":39959056},{"atl":[[1000,0.01]],"id":39959056}],"con":true,"img":false}]}
{"op":"mcm","clk":"11541053245","pt":1719501614363,"mc":[{"id":"1.230178318","rc":[{"atl":[[5.4,2]],"id":40214683}],"con":true,"img":false}]}
{"op":"mcm","clk":"11541053254","pt":1719501614466,"mc":[{"id":"1.230178318","rc":[{"atb":[[1.13,0.16]],"id":39959056}],"con":true,"img":false}]}
{"op":"mcm","clk":"11541053267","pt":1719501614570,"mc":[{"id":"1.230178318","rc":[{"atl":[[1000,0]],"id":39959056}],"con":true,"img":false}]}
{"op":"mcm","clk":"11541053277","pt":1719501614676,"mc":[{"id":"1.230178318","rc":[{"atb":[[1.13,0]],"id":39959056},{"atl":[[120,0.27]],"id":39959056},{"atl":[[5.8,4.7]],"id":40214683}],"con":true,"img":false}]}
{"op":"mcm","clk":"11541053291","pt":1719501614741,"mc":[{"id":"1.230178318","rc":[{"atb":[[7.4,0.16]],"id":39959056},{"atb":[[3.3,1.41]],"id":40214683},{"atl":[[5.3,0.87]],"id":40214683}],"con":true,"img":false}]}
{"op":"mcm","clk":"11541053422","pt":1719501615870,"mc":[{"id":"1.230178318","rc":[{"atb":[[3.3,11.69]],"id":40214683}],"con":true,"img":false}]}
{"op":"mcm","clk":"11541053433","pt":1719501615975,"mc":[{"id":"1.230178318","rc":[{"atl":[[5.4,2.26]],"id":40214683}],"con":true,"img":false}]}
{"op":"mcm","clk":"11541053442","pt":1719501616036,"mc":[{"id":"1.230178318","rc":[{"atb":[[3.35,6.35]],"id":40214683}],"con":true,"img":false}]}
{"op":"mcm","clk":"11541053499","pt":1719501616660,"mc":[{"id":"1.230178318","rc":[{"atb":[[2.74,2.74]],"id":62766534},{"atb":[[3.35,17.58]],"id":40214683},{"atb":[[2.9,6.68]],"id":56418091}],"con":true,"img":false}]}
{"op":"mcm","clk":"11541053507","pt":1719501616752,"mc":[{"id":"1.230178318","rc":[{"atb":[[3.25,11.69]],"id":40214683}],"con":true,"img":false}]}
{"op":"mcm","clk":"11541053738","pt":1719501619562,"mc":[{"id":"1.230178318","rc":[{"atl":[[5.4,0.26]],"id":40214683}],"con":true,"img":false}]}
{"op":"mcm","clk":"11541053770","pt":1719501619862,"mc":[{"id":"1.230178318","rc":[{"atl":[[7.8,0.84]],"id":56418091},{"atb":[[5.8,1],[5.5,0]],"id":70642246}],"con":true,"img":false}]}
{"op":"mcm","clk":"11541053787","pt":1719501620066,"mc":[{"id":"1.230178318","rc":[{"atl":[[8.4,0]],"id":56418091}],"con":true,"img":false}]}
{"op":"mcm","clk":"11541053794","pt":1719501620169,"mc":[{"id":"1.230178318","rc":[{"atb":[[2.98,0]],"id":40214683},{"atl":[[7.8,1.84]],"id":56418091}],"con":true,"img":false}]}
{"op":"mcm","clk":"11541053809","pt":1719501620376,"mc":[{"id":"1.230178318","rc":[{"atb":[[2.76,23.94]],"id":62766534},{"atb":[[2.8,4.09],[3.3,10.28],[3.4,1.41]],"id":40214683},{"atl":[[5.3,0.03]],"id":40214683},{"atb":[[3.2,12.47],[2.96,8.07]],"id":56418091},{"atb":[[5.6,6.72]],"id":69261147}],"con":true,"img":false}]}
{"op":"mcm","clk":"11541053835","pt":1719501620583,"mc":[{"id":"1.230178318","rc":[{"atb":[[5.8,0],[5.5,1]],"id":70642246}],"con":true,"img":false}]}
{"op":"mcm","clk":"11541053849","pt":1719501620643,"mc":[{"id":"1.230178318","rc":[{"atl":[[1000,0.75]],"id":62766534},{"atl":[[1000,0.65]],"id":56418091},{"atl":[[1000,0.79]],"id":70642246}],"con":true,"img":false}]}
{"op":"mcm","clk":"11541053859","pt":1719501620753,"mc":[{"id":"1.230178318","rc":[{"atl":[[1000,0]],"id":62766534},{"atb":[[3.35,11.23],[3,0.26]],"id":40214683},{"atl":[[1000,0]],"id":56418091},{"atl":[[1000,0.22]],"id":70642246}],"con":true,"img":false}]}
{"op":"mcm","clk":"11541053872","pt":1719501620857,"mc":[{"id":"1.230178318","rc":[{"atl":[[6.8,1.75]],"id":62766534},{"atb":[[3.4,12.89]],"id":40214683},{"atl":[[8.2,0.26],[7.8,6.37]],"id":56418091},{"atl":[[9,1.57]],"id":70642246}],"con":true,"img":false}]}
{"op":"mcm","clk":"11541053901","pt":1719501621066,"mc":[{"id":"1.230178318","rc":[{"atl":[[5.4,0]],"id":40214683}],"con":true,"img":false}]}
{"op":"mcm","clk":"11541053925","pt":1719501621261,"mc":[{"id":"1.230178318","rc":[{"atl":[[6.6,0.84]],"id":62766534},{"atb":[[3.45,0.84]],"id":40214683},{"atl":[[8.8,1.1]],"id":70642246}],"con":true,"img":false}]}
{"op":"mcm","clk":"11541053942","pt":1719501621363,"mc":[{"id":"1.230178318","rc":[{"atb":[[3.45,7.19]],"id":40214683},{"atl":[[7.6,3.34]],"id":56418091},{"atl":[[9.4,3.24]],"id":70642246}],"con":true,"img":false}]}
{"op":"mcm","clk":"11541053957","pt":1719501621469,"mc":[{"id":"1.230178318","rc":[{"atl":[[11,1.63],[7,3.06]],"id":62766534}],"con":true,"img":false}]}
{"op":"mcm","clk":"11541053970","pt":1719501621573,"mc":[{"id":"1.230178318","rc":[{"atb":[[3.25,0.33]],"id":40214683},{"atl":[[5.4,2]],"id":40214683},{"atl":[[9,0]],"id":56418091}],"con":true,"img":false}]}
{"op":"mcm","clk":"11541053990","pt":1719501621781,"mc":[{"id":"1.230178318","rc":[{"atl":[[6.6,5.52]],"id":62766534},{"atb":[[3.45,16.78]],"id":40214683},{"atl":[[7.6,7.48]],"id":56418091},{"atl":[[8.8,4.04]],"id":70642246}],"con":true,"img":false}]}
{"op":"mcm","clk":"11541054013","pt":1719501621955,"mc":[{"id":"1.230178318","rc":[{"atl":[[6.4,3.97]],"id":62766534},{"atl":[[7.8,5.37]],"id":56418091}],"con":true,"img":false}]}
{"op":"mcm","clk":"11541054036","pt":1719501622159,"mc":[{"id":"1.230178318","rc":[{"atl":[[7.4,1]],"id":56418091}],"con":true,"img":false}]}
{"op":"mcm","clk":"11541054047","pt":1719501622261,"mc":[{"id":"1.230178318","rc":[{"atl":[[5.3,0.87],[5.6,0.26]],"id":40214683}],"con":true,"img":false}]}
{"op":"mcm","clk":"11541054054","pt":1719501622363,"mc":[{"id":"1.230178318","rc":[{"atl":[[6.4,8.06]],"id":62766534}],"con":true,"img":false}]}
{"op":"mcm","clk":"11541054071","pt":1719501622562,"mc":[{"id":"1.230178318","rc":[{"atl":[[7.6,4.14]],"id":56418091}],"con":true,"img":false}]}
{"op":"mcm","clk":"11541054123","pt":1719501623078,"mc":[{"id":"1.230178318","rc":[{"atl":[[11,0]],"id":62766534}],"con":true,"img":false}]}
{"op":"mcm","clk":"11541054340","pt":1719501625464,"mc":[{"id":"1.230178318","rc":[{"atl":[[6.4,13.59],[7,0.26]],"id":62766534},{"atb":[[4.4,0],[5.2,2]],"id":39959056},{"atb":[[2.72,0],[2.88,20.56]],"id":40214683},{"atl":[[6.4,0],[6,3.14]],"id":40214683},{"atb":[[2.72,0],[2.86,24.39]],"id":56418091},{"atl":[[8,13.13],[8.8,0]],"id":56418091},{"atb":[[5.4,6],[5.1,0]],"id":69261147}],"con":true,"img":false}]}
{"op":"mcm","clk":"11541054354","pt":1719501625567,"mc":[{"id":"1.230178318","rc":[{"atb":[[3.4,11.48]],"id":40214683}],"con":true,"img":false}]}
{"op":"mcm","clk":"11541054365","pt":1719501625670,"mc":[{"id":"1.230178318","rc":[{"atb":[[3.5,1.41]],"id":40214683},{"atl":[[7.4,0]],"id":56418091}],"con":true,"img":false}]}
{"op":"mcm","clk":"11541054386","pt":1719501625877,"mc":[{"id":"1.230178318","rc":[{"atl":[[7.8,6.37]],"id":56418091}],"con":true,"img":false}]}
{"op":"mcm","clk":"11541054399","pt":1719501626083,"mc":[{"id":"1.230178318","rc":[{"atb":[[3.45,10.43]],"id":40214683}],"con":true,"img":false}]}
{"op":"mcm","clk":"11541054406","pt":1719501626186,"mc":[{"id":"1.230178318","rc":[{"atl":[[7.4,3.42]],"id":56418091}],"con":true,"img":false}]}
{"op":"mcm","clk":"11541054443","pt":1719501626568,"mc":[{"id":"1.230178318","rc":[{"atb":[[3.3,0]],"id":40214683},{"atl":[[8.6,1]],"id":56418091}],"con":true,"img":false}]}
{"op":"mcm","clk":"11541054456","pt":1719501626671,"mc":[{"id":"1.230178318","rc":[{"atl":[[7.8,5.53]],"id":56418091}],"con":true,"img":false}]}
{"op":"mcm","clk":"11541054464","pt":1719501626775,"mc":[{"id":"1.230178318","rc":[{"atb":[[3.5,11.41]],"id":40214683},{"atl":[[5.4,0]],"id":40214683},{"atl":[[7.4,6.89]],"id":56418091}],"con":true,"img":false}]}
{"op":"mcm","clk":"11541054502","pt":1719501627187,"mc":[{"id":"1.230178318","rc":[{"atb":[[3.55,6.35]],"id":40214683},{"atl":[[5.3,0.03]],"id":40214683},{"atl":[[7.2,0.84]],"id":56418091}],"con":true,"img":false}]}
{"op":"mcm","clk":"11541054556","pt":1719501627662,"mc":[{"id":"1.230178318","rc":[{"atb":[[3.45,9.59]],"id":40214683}],"con":true,"img":false}]}
{"op":"mcm","clk":"11541054564","pt":1719501627765,"mc":[{"id":"1.230178318","rc":[{"atl":[[7.4,3.47]],"id":56418091}],"con":true,"img":false}]}
{"op":"mcm","clk":"11541054595","pt":1719501628167,"mc":[{"id":"1.230178318","rc":[{"atb":[[3.35,0]],"id":40214683}],"con":true,"img":false}]}
{"op":"mcm","clk":"11541054599","pt":1719501628271,"mc":[{"id":"1.230178318","rc":[{"atl":[[6.2,0.84]],"id":62766534},{"atb":[[3.6,0.84],[2.46,8.11]],"id":40214683}],"con":true,"img":false}]}
{"op":"mcm","clk":"11541054609","pt":1719501628374,"mc":[{"id":"1.230178318","rc":[{"atb":[[3.55,15.29]],"id":40214683},{"atb":[[2.92,6.17]],"id":56418091}],"con":true,"img":false}]}
{"op":"mcm","clk":"11541054635","pt":1719501628684,"mc":[{"id":"1.230178318","rc":[{"atb":[[5.5,10.15]],"id":70642246}],"con":true,"img":false}]}
{"op":"mcm","clk":"11541054643","pt":1719501628788,"mc":[{"id":"1.230178318","rc":[{"atl":[[6.4,9.62]],"id":62766534},{"atb":[[3.55,8.94]],"id":40214683},{"atb":[[5.6,2.26],[5,1]],"id":70642246}],"con":true,"img":false}]}
{"op":"mcm","clk":"11541054687","pt":1719501629263,"mc":[{"id":"1.230178318","rc":[{"atl":[[5.4,2]],"id":40214683},{"atb":[[5.1,0],[5.7,0.84]],"id":70642246}],"con":true,"img":false}]}
{"op":"mcm","clk":"11541054705","pt":1719501629470,"mc":[{"id":"1.230178318","rc":[{"atb":[[5.8,1],[5.5,9.15]],"id":70642246}],"con":true,"img":false}]}
{"op":"mcm","clk":"11541054717","pt":1719501629668,"mc":[{"id":"1.230178318","rc":[{"atl":[[5.3,0.87]],"id":40214683}],"con":true,"img":false}]}
{"op":"mcm","clk":"11541054742","pt":1719501629979,"mc":[{"id":"1.230178318","rc":[{"atb":[[7.4,0]],"id":39959056},{"atl":[[120,0.26]],"id":39959056}],"con":true,"img":false}]}
{"op":"mcm","clk":"11541054748","pt":1719501630082,"mc":[{"id":"1.230178318","rc":[{"atb":[[5.5,3.37]],"id":69261147}],"con":true,"img":false}]}
{"op":"mcm","clk":"11541054759","pt":1719501630185,"mc":[{"id":"1.230178318","rc":[{"atb":[[2.74,5.95]],"id":62766534}],"con":true,"img":false}]}
{"op":"mcm","clk":"11541054823","pt":1719501630872,"mc":[{"id":"1.230178318","rc":[{"atb":[[1.13,1]],"id":39959056},{"atl":[[1000,0.01]],"id":39959056}],"con":true,"img":false}]}
{"op":"mcm","clk":"11541054844","pt":1719501631070,"mc":[{"id":"1.230178318","rc":[{"atb":[[1.13,0.16]],"id":39959056},{"atl":[[1000,0]],"id":39959056}],"con":true,"img":false}]}
{"op":"mcm","clk":"11541054853","pt":1719501631175,"mc":[{"id":"1.230178318","rc":[{"atl":[[120,0.27]],"id":39959056}],"con":true,"img":false}]}
{"op":"mcm","clk":"11541054863","pt":1719501631279,"mc":[{"id":"1.230178318","rc":[{"atb":[[1.13,0]],"id":39959056}],"con":true,"img":false}]}
{"op":"mcm","clk":"11541054876","pt":1719501631382,"mc":[{"id":"1.230178318","rc":[{"atb":[[7.4,0.16]],"id":39959056}],"con":true,"img":false}]}
{"op":"mcm","clk":"11541054951","pt":1719501632072,"mc":[{"id":"1.230178318","rc":[{"spn":3.0,"spf":1.0,"id":62766534},{"spn":120.0,"spf":"Infinity","id":39959056},{"spn":3.55,"spf":1.0,"id":40214683},{"spn":3.52,"spf":1.0,"id":56418091},{"spn":3.72,"spf":1.21,"id":69261147},{"atb":[[5.8,0],[5.5,10.15]],"id":70642246},{"spn":5.64,"spf":1.0,"id":70642246}],"con":true,"img":false}]}
{"op":"mcm","clk":"11541055117","pt":1719501633975,"mc":[{"id":"1.230178318","rc":[{"atl":[[6.8,0.75],[6.6,6.52]],"id":62766534},{"atl":[[5.3,1.87],[5.5,0]],"id":40214683},{"atl":[[8.6,0],[8.2,1.26]],"id":56418091}],"con":true,"img":false}]}
{"op":"mcm","clk":"11541055169","pt":1719501634595,"mc":[{"id":"1.230178318","rc":[{"atl":[[5.4,0]],"id":40214683}],"con":true,"img":false}]}
{"op":"mcm","clk":"11541055210","pt":1719501635071,"mc":[{"id":"1.230178318","rc":[{"atl":[[6.8,0]],"id":62766534},{"atl":[[7.8,4.88]],"id":56418091},{"atl":[[9,1]],"id":70642246}],"con":true,"img":false}]}
{"op":"mcm","clk":"11541055317","pt":1719501636505,"mc":[{"id":"1.230178318","rc":[{"atl":[[5.2,2]],"id":40214683}],"con":true,"img":false}]}
{"op":"mcm","clk":"11541055381","pt":1719501637185,"mc":[{"id":"1.230178318","rc":[{"atl":[[5.1,0.84]],"id":40214683}],"con":true,"img":false}]}
{"op":"mcm","clk":"11541055465","pt":1719501638172,"mc":[{"id":"1.230178318","rc":[{"atb":[[2.9,0]],"id":56418091}],"con":true,"img":false}]}
{"op":"mcm","clk":"11541055628","pt":1719501640084,"mc":[{"id":"1.230178318","rc":[{"atb":[[3.2,0]],"id":70642246}],"con":true,"img":false}]}
{"op":"mcm","clk":"11541055656","pt":1719501640488,"mc":[{"id":"1.230178318","rc":[{"atb":[[2.74,3.21]],"id":62766534},{"atb":[[2.94,0]],"id":56418091},{"atb":[[5.2,6.05]],"id":69261147},{"atb":[[4.2,0]],"id":70642246}],"con":true,"img":false}]}
{"op":"mcm","clk":"11541055665","pt":1719501640591,"mc":[{"id":"1.230178318","rc":[{"atb":[[5.8,1],[5.5,9.15]],"id":70642246}],"con":true,"img":false}]}
{"op":"mcm","clk":"11541055681","pt":1719501640798,"mc":[{"id":"1.230178318","rc":[{"atb":[[5.1,0.26]],"id":39959056}],"con":true,"img":false}]}
{"op":"mcm","clk":"11541055689","pt":1719501640902,"mc":[{"id":"1.230178318","rc":[{"atb":[[2.76,26.66]],"id":62766534}],"con":true,"img":false}]}
{"op":"mcm","clk":"11541055752","pt":1719501641686,"mc":[{"id":"1.230178318","rc":[{"atl":[[5.2,0]],"id":40214683}],"con":true,"img":false}]}
{"op":"mcm","clk":"11541055800","pt":1719501642198,"mc":[{"id":"1.230178318","rc":[{"atl":[[5.1,0]],"id":40214683}],"con":true,"img":false}]}
{"op":"mcm","clk":"11541055841","pt":1719501642719,"mc":[{"id":"1.230178318","rc":[{"atb":[[2.8,0]],"id":40214683},{"atb":[[2.96,0]],"id":56418091}],"con":true,"img":false}]}
{"op":"mcm","clk":"11541055885","pt":1719501643390,"mc":[{"id":"1.230178318","rc":[{"atb":[[2.88,6.75]],"id":56418091}],"con":true,"img":false}]}
{"op":"mcm","clk":"11541055892","pt":1719501643492,"mc":[{"id":"1.230178318","rc":[{"atl":[[5.2,2]],"id":40214683}],"con":true,"img":false}]}
{"op":"mcm","clk":"11541055922","pt":1719501644009,"mc":[{"id":"1.230178318","rc":[{"atb":[[2.78,14.83]],"id":56418091}],"con":true,"img":false}]}
{"op":"mcm","clk":"11541055932","pt":1719501644215,"mc":[{"id":"1.230178318","rc":[{"atl":[[5.1,0.84]],"id":40214683}],"con":true,"img":false}]}
{"op":"mcm","clk":"11541056113","pt":1719501646384,"mc":[{"id":"1.230178318","rc":[{"atl":[[120,0.26]],"id":39959056}],"con":true,"img":false}]}
{"op":"mcm","clk":"11541056132","pt":1719501646591,"mc":[{"id":"1.230178318","rc":[{"atb":[[7.4,0]],"id":39959056}],"con":true,"img":false}]}
{"op":"mcm","clk":"11541056142","pt":1719501646694,"mc":[{"id":"1.230178318","rc":[{"atb":[[3.1,11.88]],"id":70642246}],"con":true,"img":false}]}
{"op":"mcm","clk":"11541056160","pt":1719501646900,"mc":[{"id":"1.230178318","rc":[{"atb":[[2.94,3.25]],"id":40214683}],"con":true,"img":false}]}
{"op":"mcm","clk":"11541056176","pt":1719501647105,"mc":[{"id":"1.230178318","rc":[{"atb":[[2.82,3.47]],"id":62766534}],"con":true,"img":false}]}
{"op":"mcm","clk":"11541056184","pt":1719501647208,"mc":[{"id":"1.230178318","rc":[{"atb":[[2.72,0],[2.84,3.48]],"id":62766534},{"atb":[[2.92,9.47]],"id":56418091}],"con":true,"img":false}]}
{"op":"mcm","clk":"11541056219","pt":1719501647621,"mc":[{"id":"1.230178318","rc":[{"atb":[[1.13,1]],"id":39959056},{"atl":[[1000,0.01]],"id":39959056}],"con":true,"img":false}]}
{"op":"mcm","clk":"11541056233","pt":1719501647787,"mc":[{"id":"1.230178318","rc":[{"atb":[[1.13,0.16]],"id":39959056},{"atl":[[1000,0]],"id":39959056}],"con":true,"img":false}]}
{"op":"mcm","clk":"11541056244","pt":1719501647891,"mc":[{"id":"1.230178318","rc":[{"atb":[[2.86,14.56]],"id":62766534},{"atl":[[120,0.27]],"id":39959056}],"con":true,"img":false}]}
{"op":"mcm","clk":"11541056254","pt":1719501647994,"mc":[{"id":"1.230178318","rc":[{"atb":[[1.13,0]],"id":39959056}],"con":true,"img":false}]}
{"op":"mcm","clk":"11541056262","pt":1719501648098,"mc":[{"id":"1.230178318","rc":[{"atb":[[7.4,0.16]],"id":39959056}],"con":true,"img":false}]}
{"op":"mcm","clk":"11541056314","pt":1719501648705,"mc":[{"id":"1.230178318","rc":[{"atb":[[7.4,1.3]],"id":39959056},{"atl":[[5.2,0]],"id":40214683}],"con":true,"img":false}]}
{"op":"mcm","clk":"11541056323","pt":1719501648833,"mc":[{"id":"1.230178318","rc":[{"atb":[[7,0]],"id":39959056}],"con":true,"img":false}]}
{"op":"mcm","clk":"11541056361","pt":1719501649349,"mc":[{"id":"1.230178318","rc":[{"atb":[[6.8,0]],"id":39959056},{"atl":[[5.1,0]],"id":40214683}],"con":true,"img":false}]}
{"op":"mcm","clk":"11541056376","pt":1719501649521,"mc":[{"id":"1.230178318","rc":[{"atl":[[6,0.14],[5.9,4.74]],"id":40214683}],"con":true,"img":false}]}
{"op":"mcm","clk":"11541056477","pt":1719501650793,"mc":[{"id":"1.230178318","rc":[{"atl":[[5.2,2]],"id":40214683}],"con":true,"img":false}]}
{"op":"mcm","clk":"11541056517","pt":1719501651303,"mc":[{"id":"1.230178318","rc":[{"atl":[[5.1,0.84]],"id":40214683}],"con":true,"img":false}]}
{"op":"mcm","clk":"11541056908","pt":1719501656030,"mc":[{"id":"1.230178318","rc":[{"atl":[[5.2,0]],"id":40214683}],"con":true,"img":false}]}
{"op":"mcm","clk":"11541056975","pt":1719501656808,"mc":[{"id":"1.230178318","rc":[{"atl":[[5.1,0]],"id":40214683}],"con":true,"img":false}]}
{"op":"mcm","clk":"11541057078","pt":1719501658105,"mc":[{"id":"1.230178318","rc":[{"atl":[[5.2,2]],"id":40214683}],"con":true,"img":false}]}
{"op":"mcm","clk":"11541057134","pt":1719501658728,"mc":[{"id":"1.230178318","rc":[{"atl":[[5.1,0.84]],"id":40214683}],"con":true,"img":false}]}
{"op":"mcm","clk":"11541057145","pt":1719501658891,"mc":[{"id":"1.230178318","rc":[{"atb":[[3.6,1.84]],"id":40214683}],"con":true,"img":false}]}
{"op":"mcm","clk":"11541057178","pt":1719501659404,"mc":[{"id":"1.230178318","rc":[{"atb":[[3.65,6.35]],"id":40214683}],"con":true,"img":false}]}
{"op":"mcm","clk":"11541057185","pt":1719501659508,"mc":[{"id":"1.230178318","rc":[{"atb":[[2.74,0]],"id":62766534}],"con":true,"img":false}]}
{"op":"mcm","clk":"11541057189","pt":1719501659611,"mc":[{"id":"1.230178318","rc":[{"atb":[[3.4,0]],"id":40214683}],"con":true,"img":false}]}
{"op":"mcm","clk":"11541057194","pt":1719501659717,"mc":[{"id":"1.230178318","rc":[{"atb":[[3.7,0.84]],"id":40214683}],"con":true,"img":false}]}
{"op":"mcm","clk":"11541057201","pt":1719501659822,"mc":[{"id":"1.230178318","rc":[{"atb":[[3.6,12.58]],"id":40214683}],"con":true,"img":false}]}
{"op":"mcm","clk":"11541057223","pt":1719501660132,"mc":[{"id":"1.230178318","rc":[{"atb":[[3.65,0]],"id":40214683},{"atl":[[1000,0.69]],"id":56418091},{"atl":[[1000,0.8]],"id":70642246}],"con":true,"img":false}]}
{"op":"mcm","clk":"11541057238","pt":1719501660298,"mc":[{"id":"1.230178318","rc":[{"atl":[[1000,0]],"id":56418091},{"atl":[[1000,0.22]],"id":70642246}],"con":true,"img":false}]}
{"op":"mcm","clk":"11541057253","pt":1719501660400,"mc":[{"id":"1.230178318","rc":[{"atl":[[7.4,4.16]],"id":56418091},{"atl":[[8.8,4.62]],"id":70642246}],"con":true,"img":false}]}
{"op":"mcm","clk":"11541057263","pt":1719501660507,"mc":[{"id":"1.230178318","rc":[{"atl":[[9.2,0]],"id":70642246}],"con":true,"img":false}]}
{"op":"mcm","clk":"11541057288","pt":1719501660810,"mc":[{"id":"1.230178318","rc":[{"atb":[[3.7,0]],"id":40214683}],"con":true,"img":false}]}
{"op":"mcm","clk":"11541057298","pt":1719501660913,"mc":[{"id":"1.230178318","rc":[{"atb":[[3.5,10],[3.65,1.41]],"id":40214683},{"atl":[[8.6,1]],"id":70642246}],"con":true,"img":false}]}
{"op":"mcm","clk":"11541057345","pt":1719501661538,"mc":[{"id":"1.230178318","rc":[{"atb":[[3.45,0]],"id":40214683}],"con":true,"img":false}]}
{"op":"mcm","clk":"11541057362","pt":1719501661703,"mc":[{"id":"1.230178318","rc":[{"atb":[[2.82,6.54]],"id":62766534},{"atb":[[3.65,10.98]],"id":40214683}],"con":true,"img":false}]}
{"op":"mcm","clk":"11541057380","pt":1719501661902,"mc":[{"id":"1.230178318","rc":[{"atb":[[3.6,11.58]],"id":40214683}],"con":true,"img":false}]}
{"op":"mcm","clk":"11541057392","pt":1719501662007,"mc":[{"id":"1.230178318","rc":[{"atb":[[3.7,7.35]],"id":40214683}],"con":true,"img":false}]}
{"op":"mcm","clk":"11541057428","pt":1719501662426,"mc":[{"id":"1.230178318","rc":[{"atb":[[3.5,0]],"id":40214683},{"atl":[[5.3,4.72],[5.9,0]],"id":40214683},{"atl":[[8,4.85],[7.2,4.98]],"id":56418091},{"atl":[[18,5.88],[21,0]],"id":69261147}],"con":true,"img":false}]}
{"op":"mcm","clk":"11541057452","pt":1719501662636,"mc":[{"id":"1.230178318","rc":[{"atb":[[3.7,16.41]],"id":40214683},{"atl":[[7.8,3.88],[7,3.63]],"id":56418091}],"con":true,"img":false}]}
{"op":"mcm","clk":"11541057463","pt":1719501662699,"mc":[{"id":"1.230178318","rc":[{"atb":[[3.6,10.74]],"id":40214683},{"atl":[[6.8,1]],"id":56418091}],"con":true,"img":false}]}
{"op":"mcm","clk":"11541057484","pt":1719501662907,"mc":[{"id":"1.230178318","rc":[{"atb":[[3.7,15.41]],"id":40214683}],"con":true,"img":false}]}
{"op":"mcm","clk":"11541057504","pt":1719501663115,"mc":[{"id":"1.230178318","rc":[{"atb":[[3.75,1]],"id":40214683}],"con":true,"img":false}]}
{"op":"mcm","clk":"11541057512","pt":1719501663210,"mc":[{"id":"1.230178318","rc":[{"atl":[[120,0.26]],"id":39959056}],"con":true,"img":false}]}
{"op":"mcm","clk":"11541057525","pt":1719501663317,"mc":[{"id":"1.230178318","rc":[{"atb":[[7.4,1.14]],"id":39959056},{"atb":[[3.7,9.06]],"id":40214683},{"atl":[[5.2,0]],"id":40214683},{"atl":[[8,1.05],[7,0]],"id":56418091}],"con":true,"img":false}]}
{"op":"mcm","clk":"11541057534","pt":1719501663420,"mc":[{"id":"1.230178318","rc":[{"atl":[[5.6,5.84],[5.3,1.87]],"id":40214683}],"con":true,"img":false}]}
{"op":"mcm","clk":"11541057544","pt":1719501663525,"mc":[{"id":"1.230178318","rc":[{"atl":[[6.8,5.5]],"id":56418091}],"con":true,"img":false}]}
{"op":"mcm","clk":"11541057571","pt":1719501663733,"mc":[{"id":"1.230178318","rc":[{"atl":[[5.1,0]],"id":40214683}],"con":true,"img":false}]}
{"op":"mcm","clk":"11541057580","pt":1719501663838,"mc":[{"id":"1.230178318","rc":[{"atb":[[1.14,1]],"id":39959056},{"atl":[[1000,0.01]],"id":39959056}],"con":true,"img":false}]}
{"op":"mcm","clk":"11541057615","pt":1719501664109,"mc":[{"id":"1.230178318","rc":[{"atb":[[2.82,3.47]],"id":62766534},{"atb":[[1.14,0.15]],"id":39959056},{"atl":[[1000,0]],"id":39959056},{"atl":[[6.6,3.85]],"id":56418091}],"con":true,"img":false}]}
{"op":"mcm","clk":"11541057626","pt":1719501664211,"mc":[{"id":"1.230178318","rc":[{"atl":[[120,0.27]],"id":39959056},{"atl":[[7.2,4.14],[6.6,4.69]],"id":56418091}],"con":true,"img":false}]}
{"op":"mcm","clk":"11541057634","pt":1719501664318,"mc":[{"id":"1.230178318","rc":[{"atb":[[1.14,0]],"id":39959056}],"con":true,"img":false}]}
{"op":"mcm","clk":"11541057639","pt":1719501664410,"mc":[{"id":"1.230178318","rc":[{"atb":[[7.6,0.15]],"id":39959056},{"atl":[[6.8,4.5]],"id":56418091}],"con":true,"img":false}]}
{"op":"mcm","clk":"11541057657","pt":1719501664615,"mc":[{"id":"1.230178318","rc":[{"atl":[[6.4,1]],"id":56418091}],"con":true,"img":false}]}
{"op":"mcm","clk":"11541057684","pt":1719501664925,"mc":[{"id":"1.230178318","rc":[{"atl":[[6.6,0.84]],"id":56418091}],"con":true,"img":false}]}
{"op":"mcm","clk":"11541057724","pt":1719501665442,"mc":[{"id":"1.230178318","rc":[{"atl":[[6.2,2.84]],"id":62766534}],"con":true,"img":false}]}
{"op":"mcm","clk":"11541057760","pt":1719501665806,"mc":[{"id":"1.230178318","rc":[{"atl":[[6.6,5.68]],"id":62766534}],"con":true,"img":false}]}
{"op":"mcm","clk":"11541057770","pt":1719501665908,"mc":[{"id":"1.230178318","rc":[{"atl":[[6,4.23]],"id":62766534}],"con":true,"img":false}]}
{"op":"mcm","clk":"11541057778","pt":1719501666022,"mc":[{"id":"1.230178318","rc":[{"atl":[[5.9,4.23]],"id":62766534}],"con":true,"img":false}]}
