{"op":"mcm","clk":"11536380650","pt":1719425245588,"mc":[{"id":"1.230178316","marketDefinition":{"bspMarket":true,"turnInPlayEnabled":false,"persistenceEnabled":false,"marketBaseRate":5.0,"eventId":"33376062","eventTypeId":"4339","numberOfWinners":1,"bettingType":"ODDS","marketType":"WIN","marketTime":"2024-06-27T15:09:00.000Z","suspendTime":"2024-06-27T15:09:00.000Z","bspReconciled":false,"complete":true,"inPlay":false,"crossMatching":false,"runnersVoidable":false,"numberOfActiveRunners":6,"betDelay":0,"status":"OPEN","runners":[{"status":"ACTIVE","sortPriority":1,"id":69685608,"name":"1. Spin It Danny"},{"status":"ACTIVE","sortPriority":2,"id":49159417,"name":"2. Derrymore Ella"},{"status":"ACTIVE","sortPriority":3,"id":57196226,"name":"3. Shrewd Cass"},{"status":"ACTIVE","sortPriority":4,"id":70902601,"name":"4. Fairy Hill John"},{"status":"ACTIVE","sortPriority":5,"id":52655636,"name":"5. Lady Quickstep"},{"status":"ACTIVE","sortPriority":6,"id":46611436,"name":"6. Curryhills Tiana"}],"regulators":["MR_INT"],"venue":"Kinsley","countryCode":"GB","discountAllowed":false,"timezone":"Europe/London","openDate":"2024-06-27T13:36:00.000Z","version":5994643757,"name":"A5 462m","eventName":"Kinsley 27th Jun"},"rc":[],"con":true,"img":false}]}
{"op":"mcm","clk":"11536381011","pt":1719425248523,"mc":[{"id":"1.230178316","marketDefinition":{"bspMarket":true,"turnInPlayEnabled":false,"persistenceEnabled":false,"marketBaseRate":5.0,"eventId":"33376062","eventTypeId":"4339","numberOfWinners":1,"bettingType":"ODDS","marketType":"WIN","marketTime":"2024-06-27T15:09:00.000Z","suspendTime":"2024-06-27T15:09:00.000Z","bspReconciled":false,"complete":true,"inPlay":false,"crossMatching":false,"runnersVoidable":false,"numberOfActiveRunners":6,"betDelay":0,"status":"OPEN","runners":[{"status":"ACTIVE","sortPriority":1,"id":69685608,"name":"1. Spin It Danny"},{"status":"ACTIVE","sortPriority":2,"id":49159417,"name":"2. Derrymore Ella"},{"status":"ACTIVE","sortPriority":3,"id":57196226,"name":"3. Shrewd Cass"},{"status":"ACTIVE","sortPriority":4,"id":70902601,"name":"4. Fairy Hill John"},{"status":"ACTIVE","sortPriority":5,"id":52655636,"name":"5. Lady Quickstep"},{"status":"ACTIVE","sortPriority":6,"id":46611436,"name":"6. Curryhills Tiana"}],"regulators":["MR_INT"],"venue":"Kinsley","countryCode":"GB","discountAllowed":true,"timezone":"Europe/London","openDate":"2024-06-27T13:36:00.000Z","version":5994643757,"name":"A5 462m","eventName":"Kinsley 27th Jun"},"rc":[],"con":true,"img":false}]}
{"op":"mcm","clk":"11536614491","pt":1719428235317,"mc":[{"id":"1.230178316","rc":[{"atb":[[1.03,7.88]],"id":57196226},{"atl":[[990,0.84]],"id":57196226},{"spn":495.51,"spf":"NaN","id":57196226},{"atb":[[1.01,23.65]],"id":46611436},{"atl":[[1000,0.84]],"id":46611436},{"spn":500.5,"spf":"NaN","id":46611436},{"atb":[[1.03,7.88]],"id":52655636},{"atl":[[1000,0.84]],"id":52655636},{"spn":500.51,"spf":"NaN","id":52655636},{"atb":[[1.01,23.65]],"id":70902601},{"atl":[[990,0.84]],"id":70902601},{"spn":495.5,"spf":"NaN","id":70902601},{"atb":[[1.01,23.65]],"id":69685608},{"atl":[[1000,0.84]],"id":69685608},{"spn":500.5,"spf":"NaN","id":69685608},{"atb":[[1.01,23.65]],"id":49159417},{"atl":[[1000,0.84]],"id":49159417},{"spn":500.5,"spf":"NaN","id":49159417}],"con":true,"img":false}]}
{"op":"mcm","clk":"11536836627","pt":1719431845799,"mc":[{"id":"1.230178316","rc":[{"atb":[[1.03,7.88]],"id":57196226},{"atl":[[990,0.22]],"id":57196226},{"atb":[[1.01,23.66]],"id":46611436},{"atl":[[1000,0.22]],"id":46611436},{"atb":[[1.03,7.88]],"id":52655636},{"atl":[[1000,0.22]],"id":52655636},{"atb":[[1.01,23.66]],"id":70902601},{"atl":[[990,0.22]],"id":70902601},{"atb":[[1.01,23.66]],"id":69685608},{"atl":[[1000,0.22]],"id":69685608},{"atb":[[1.01,23.66]],"id":49159417},{"atl":[[1000,0.22]],"id":49159417}],"con":true,"img":false}]}
{"op":"mcm","clk":"11537232235","pt":1719437882515,"mc":[{"id":"1.230178316","marketDefinition":{"bspMarket":true,"turnInPlayEnabled":false,"persistenceEnabled":false,"marketBaseRate":5.0,"eventId":"33376062","eventTypeId":"4339","numberOfWinners":1,"bettingType":"ODDS","marketType":"WIN","marketTime":"2024-06-27T15:09:00.000Z","suspendTime":"2024-06-27T15:09:00.000Z","bspReconciled":false,"complete":true,"inPlay":false,"crossMatching":false,"runnersVoidable":false,"numberOfActiveRunners":6,"betDelay":0,"status":"OPEN","runners":[{"status":"ACTIVE","sortPriority":1,"id":69685608,"name":"1. Spin It Danny"},{"status":"ACTIVE","sortPriority":2,"id":49159417,"name":"2. Derrymore Ella"},{"status":"ACTIVE","sortPriority":3,"id":57196226,"name":"3. Shrewd Cass"},{"status":"ACTIVE","sortPriority":4,"id":70902601,"name":"4. Fairy Hill John"},{"status":"ACTIVE","sortPriority":5,"id":52655636,"name":"5. Lady Quickstep"},{"status":"ACTIVE","sortPriority":6,"id":46611436,"name":"6. Curryhills Tiana"}],"regulators":["MR_INT"],"venue":"Kinsley","countryCode":"GB","discountAllowed":true,"timezone":"Europe/London","openDate":"2024-06-27T13:36:00.000Z","version":5994643757,"name":"A5 462m","eventName":"Kinsley 27th Jun"},"rc":[{"atb":[[1.03,7.88]],"id":57196226},{"atl":[[990,0.22]],"id":57196226},{"spn":495.51,"spf":"NaN","id":57196226},{"atb":[[1.01,23.66]],"id":46611436},{"atl":[[1000,0.22]],"id":46611436},{"spn":500.5,"spf":"NaN","id":46611436},{"atb":[[1.03,7.88]],"id":52655636},{"atl":[[1000,0.22]],"id":52655636},{"spn":500.51,"spf":"NaN","id":52655636},{"atb":[[1.01,23.66]],"id":70902601},{"atl":[[990,0.22]],"id":70902601},{"spn":495.5,"spf":"NaN","id":70902601},{"atb":[[1.01,23.66]],"id":69685608},{"atl":[[1000,0.22]],"id":69685608},{"spn":500.5,"spf":"NaN","id":69685608},{"atb":[[1.01,23.66]],"id":49159417},{"atl":[[1000,0.22]],"id":49159417},{"spn":500.5,"spf":"NaN","id":49159417}],"con":true,"img":true}]}
{"op":"mcm","clk":"11537573362","pt":1719443282536,"mc":[{"id":"1.230178316","marketDefinition":{"bspMarket":true,"turnInPlayEnabled":false,"persistenceEnabled":false,"marketBaseRate":5.0,"eventId":"33376062","eventTypeId":"4339","numberOfWinners":1,"bettingType":"ODDS","marketType":"WIN","marketTime":"2024-06-27T15:09:00.000Z","suspendTime":"2024-06-27T15:09:00.000Z","bspReconciled":false,"complete":true,"inPlay":false,"crossMatching":false,"runnersVoidable":false,"numberOfActiveRunners":6,"betDelay":0,"status":"OPEN","runners":[{"status":"ACTIVE","sortPriority":1,"id":69685608,"name":"1. Spin It Danny"},{"status":"ACTIVE","sortPriority":2,"id":49159417,"name":"2. Derrymore Ella"},{"status":"ACTIVE","sortPriority":3,"id":57196226,"name":"3. Shrewd Cass"},{"status":"ACTIVE","sortPriority":4,"id":70902601,"name":"4. Fairy Hill John"},{"status":"ACTIVE","sortPriority":5,"id":52655636,"name":"5. Lady Quickstep"},{"status":"ACTIVE","sortPriority":6,"id":46611436,"name":"6. Curryhills Tiana"}],"regulators":["MR_INT"],"venue":"Kinsley","countryCode":"GB","discountAllowed":true,"timezone":"Europe/London","openDate":"2024-06-27T13:36:00.000Z","version":5994643757,"name":"A5 462m","eventName":"Kinsley 27th Jun"},"rc":[{"atb":[[1.03,7.88]],"id":57196226},{"atl":[[990,0.22]],"id":57196226},{"spn":495.51,"spf":"NaN","id":57196226},{"atb":[[1.01,23.66]],"id":46611436},{"atl":[[1000,0.22]],"id":46611436},{"spn":500.5,"spf":"NaN","id":46611436},{"atb":[[1.03,7.88]],"id":52655636},{"atl":[[1000,0.22]],"id":52655636},{"spn":500.51,"spf":"NaN","id":52655636},{"atb":[[1.01,23.66]],"id":70902601},{"atl":[[990,0.22]],"id":70902601},{"spn":495.5,"spf":"NaN","id":70902601},{"atb":[[1.01,23.66]],"id":69685608},{"atl":[[1000,0.22]],"id":69685608},{"spn":500.5,"spf":"NaN","id":69685608},{"atb":[[1.01,23.66]],"id":49159417},{"atl":[[1000,0.22]],"id":49159417},{"spn":500.5,"spf":"NaN","id":49159417}],"con":true,"img":true}]}
{"op":"mcm","clk":"11537954922","pt":1719448682555,"mc":[{"id":"1.230178316","marketDefinition":{"bspMarket":true,"turnInPlayEnabled":false,"persistenceEnabled":false,"marketBaseRate":5.0,"eventId":"33376062","eventTypeId":"4339","numberOfWinners":1,"bettingType":"ODDS","marketType":"WIN","marketTime":"2024-06-27T15:09:00.000Z","suspendTime":"2024-06-27T15:09:00.000Z","bspReconciled":false,"complete":true,"inPlay":false,"crossMatching":false,"runnersVoidable":false,"numberOfActiveRunners":6,"betDelay":0,"status":"OPEN","runners":[{"status":"ACTIVE","sortPriority":1,"id":69685608,"name":"1. Spin It Danny"},{"status":"ACTIVE","sortPriority":2,"id":49159417,"name":"2. Derrymore Ella"},{"status":"ACTIVE","sortPriority":3,"id":57196226,"name":"3. Shrewd Cass"},{"status":"ACTIVE","sortPriority":4,"id":70902601,"name":"4. Fairy Hill John"},{"status":"ACTIVE","sortPriority":5,"id":52655636,"name":"5. Lady Quickstep"},{"status":"ACTIVE","sortPriority":6,"id":46611436,"name":"6. Curryhills Tiana"}],"regulators":["MR_INT"],"venue":"Kinsley","countryCode":"GB","discountAllowed":true,"timezone":"Europe/London","openDate":"2024-06-27T13:36:00.000Z","version":5994643757,"name":"A5 462m","eventName":"Kinsley 27th Jun"},"rc":[{"atb":[[1.03,7.88]],"id":57196226},{"atl":[[990,0.22]],"id":57196226},{"spn":495.51,"spf":"NaN","id":57196226},{"atb":[[1.01,23.66]],"id":46611436},{"atl":[[1000,0.22]],"id":46611436},{"spn":500.5,"spf":"NaN","id":46611436},{"atb":[[1.03,7.88]],"id":52655636},{"atl":[[1000,0.22]],"id":52655636},{"spn":500.51,"spf":"NaN","id":52655636},{"atb":[[1.01,23.66]],"id":70902601},{"atl":[[990,0.22]],"id":70902601},{"spn":495.5,"spf":"NaN","id":70902601},{"atb":[[1.01,23.66]],"id":69685608},{"atl":[[1000,0.22]],"id":69685608},{"spn":500.5,"spf":"NaN","id":69685608},{"atb":[[1.01,23.66]],"id":49159417},{"atl":[[1000,0.22]],"id":49159417},{"spn":500.5,"spf":"NaN","id":49159417}],"con":true,"img":true}]}
{"op":"mcm","clk":"11538170585","pt":1719454082536,"mc":[{"id":"1.230178316","marketDefinition":{"bspMarket":true,"turnInPlayEnabled":false,"persistenceEnabled":false,"marketBaseRate":5.0,"eventId":"33376062","eventTypeId":"4339","numberOfWinners":1,"bettingType":"ODDS","marketType":"WIN","marketTime":"2024-06-27T15:09:00.000Z","suspendTime":"2024-06-27T15:09:00.000Z","bspReconciled":false,"complete":true,"inPlay":false,"crossMatching":false,"runnersVoidable":false,"numberOfActiveRunners":6,"betDelay":0,"status":"OPEN","runners":[{"status":"ACTIVE","sortPriority":1,"id":69685608,"name":"1. Spin It Danny"},{"status":"ACTIVE","sortPriority":2,"id":49159417,"name":"2. Derrymore Ella"},{"status":"ACTIVE","sortPriority":3,"id":57196226,"name":"3. Shrewd Cass"},{"status":"ACTIVE","sortPriority":4,"id":70902601,"name":"4. Fairy Hill John"},{"status":"ACTIVE","sortPriority":5,"id":52655636,"name":"5. Lady Quickstep"},{"status":"ACTIVE","sortPriority":6,"id":46611436,"name":"6. Curryhills Tiana"}],"regulators":["MR_INT"],"venue":"Kinsley","countryCode":"GB","discountAllowed":true,"timezone":"Europe/London","openDate":"2024-06-27T13:36:00.000Z","version":5994643757,"name":"A5 462m","eventName":"Kinsley 27th Jun"},"rc":[{"atb":[[1.03,7.88]],"id":57196226},{"atl":[[990,0.22]],"id":57196226},{"spn":495.51,"spf":"NaN","id":57196226},{"atb":[[1.01,23.67]],"id":46611436},{"atl":[[1000,0.22]],"id":46611436},{"spn":500.5,"spf":"NaN","id":46611436},{"atb":[[1.03,7.88]],"id":52655636},{"atl":[[1000,0.22]],"id":52655636},{"spn":500.51,"spf":"NaN","id":52655636},{"atb":[[1.01,23.67]],"id":70902601},{"atl":[[990,0.22]],"id":70902601},{"spn":495.5,"spf":"NaN","id":70902601},{"atb":[[1.01,23.67]],"id":69685608},{"atl":[[1000,0.22]],"id":69685608},{"spn":500.5,"spf":"NaN","id":69685608},{"atb":[[1.01,23.67]],"id":49159417},{"atl":[[1000,0.22]],"id":49159417},{"spn":500.5,"spf":"NaN","id":49159417}],"con":true,"img":true}]}
{"op":"mcm","clk":"11538368243","pt":1719459482564,"mc":[{"id":"1.230178316","marketDefinition":{"bspMarket":true,"turnInPlayEnabled":false,"persistenceEnabled":false,"marketBaseRate":5.0,"eventId":"33376062","eventTypeId":"4339","numberOfWinners":1,"bettingType":"ODDS","marketType":"WIN","marketTime":"2024-06-27T15:09:00.000Z","suspendTime":"2024-06-27T15:09:00.000Z","bspReconciled":false,"complete":true,"inPlay":false,"crossMatching":false,"runnersVoidable":false,"numberOfActiveRunners":6,"betDelay":0,"status":"OPEN","runners":[{"status":"ACTIVE","sortPriority":1,"id":69685608,"name":"1. Spin It Danny"},{"status":"ACTIVE","sortPriority":2,"id":49159417,"name":"2. Derrymore Ella"},{"status":"ACTIVE","sortPriority":3,"id":57196226,"name":"3. Shrewd Cass"},{"status":"ACTIVE","sortPriority":4,"id":70902601,"name":"4. Fairy Hill John"},{"status":"ACTIVE","sortPriority":5,"id":52655636,"name":"5. Lady Quickstep"},{"status":"ACTIVE","sortPriority":6,"id":46611436,"name":"6. Curryhills Tiana"}],"regulators":["MR_INT"],"venue":"Kinsley","countryCode":"GB","discountAllowed":true,"timezone":"Europe/London","openDate":"2024-06-27T13:36:00.000Z","version":5994643757,"name":"A5 462m","eventName":"Kinsley 27th Jun"},"rc":[{"atb":[[1.03,7.88]],"id":57196226},{"atl":[[990,0.22]],"id":57196226},{"spn":495.51,"spf":"NaN","id":57196226},{"atb":[[1.01,23.67]],"id":46611436},{"atl":[[1000,0.22]],"id":46611436},{"spn":500.5,"spf":"NaN","id":46611436},{"atb":[[1.03,7.88]],"id":52655636},{"atl":[[1000,0.22]],"id":52655636},{"spn":500.51,"spf":"NaN","id":52655636},{"atb":[[1.01,23.67]],"id":70902601},{"atl":[[990,0.22]],"id":70902601},{"spn":495.5,"spf":"NaN","id":70902601},{"atb":[[1.01,23.67]],"id":69685608},{"atl":[[1000,0.22]],"id":69685608},{"spn":500.5,"spf":"NaN","id":69685608},{"atb":[[1.01,23.67]],"id":49159417},{"atl":[[1000,0.22]],"id":49159417},{"spn":500.5,"spf":"NaN","id":49159417}],"con":true,"img":true}]}
{"op":"mcm","clk":"11538595369","pt":1719464882536,"mc":[{"id":"1.230178316","marketDefinition":{"bspMarket":true,"turnInPlayEnabled":false,"persistenceEnabled":false,"marketBaseRate":5.0,"eventId":"33376062","eventTypeId":"4339","numberOfWinners":1,"bettingType":"ODDS","marketType":"WIN","marketTime":"2024-06-27T15:09:00.000Z","suspendTime":"2024-06-27T15:09:00.000Z","bspReconciled":false,"complete":true,"inPlay":false,"crossMatching":false,"runnersVoidable":false,"numberOfActiveRunners":6,"betDelay":0,"status":"OPEN","runners":[{"status":"ACTIVE","sortPriority":1,"id":69685608,"name":"1. Spin It Danny"},{"status":"ACTIVE","sortPriority":2,"id":49159417,"name":"2. Derrymore Ella"},{"status":"ACTIVE","sortPriority":3,"id":57196226,"name":"3. Shrewd Cass"},{"status":"ACTIVE","sortPriority":4,"id":70902601,"name":"4. Fairy Hill John"},{"status":"ACTIVE","sortPriority":5,"id":52655636,"name":"5. Lady Quickstep"},{"status":"ACTIVE","sortPriority":6,"id":46611436,"name":"6. Curryhills Tiana"}],"regulators":["MR_INT"],"venue":"Kinsley","countryCode":"GB","discountAllowed":true,"timezone":"Europe/London","openDate":"2024-06-27T13:36:00.000Z","version":5994643757,"name":"A5 462m","eventName":"Kinsley 27th Jun"},"rc":[{"atb":[[1.03,7.88]],"id":57196226},{"atl":[[990,0.22]],"id":57196226},{"spn":495.51,"spf":"NaN","id":57196226},{"atb":[[1.01,23.67]],"id":46611436},{"atl":[[1000,0.22]],"id":46611436},{"spn":500.5,"spf":"NaN","id":46611436},{"atb":[[1.03,7.88]],"id":52655636},{"atl":[[1000,0.22]],"id":52655636},{"spn":500.51,"spf":"NaN","id":52655636},{"atb":[[1.01,23.67]],"id":70902601},{"atl":[[990,0.22]],"id":70902601},{"spn":495.5,"spf":"NaN","id":70902601},{"atb":[[1.01,23.67]],"id":69685608},{"atl":[[1000,0.22]],"id":69685608},{"spn":500.5,"spf":"NaN","id":69685608},{"atb":[[1.01,23.67]],"id":49159417},{"atl":[[1000,0.22]],"id":49159417},{"spn":500.5,"spf":"NaN","id":49159417}],"con":true,"img":true}]}
{"op":"mcm","clk":"11538748532","pt":1719468203209,"mc":[{"id":"1.230178316","rc":[{"atb":[[1.03,7.88],[2.08,12.44]],"id":57196226},{"spn":496.04,"spf":"NaN","id":57196226},{"atb":[[1.01,23.67],[2.1,11.66]],"id":46611436},{"spn":501.05,"spf":"NaN","id":46611436},{"atb":[[1.03,7.88],[2.08,12.44]],"id":52655636},{"spn":501.04,"spf":"NaN","id":52655636},{"atb":[[1.01,23.67],[2.04,11.33]],"id":70902601},{"spn":496.02,"spf":"NaN","id":70902601},{"atb":[[1.01,23.67],[2.08,11.55]],"id":69685608},{"spn":501.04,"spf":"NaN","id":69685608},{"atb":[[1.01,23.67],[2.02,8.63]],"id":49159417},{"spn":501.01,"spf":"NaN","id":49159417}],"con":true,"img":false}]}
{"op":"mcm","clk":"11538750781","pt":1719468249660,"mc":[{"id":"1.230178316","rc":[{"atb":[[2.1,3.16]],"id":57196226}],"con":true,"img":false}]}
{"op":"mcm","clk":"11538750783","pt":1719468249761,"mc":[{"id":"1.230178316","rc":[{"atb":[[2.04,3.16]],"id":49159417}],"con":true,"img":false}]}
{"op":"mcm","clk":"11538750796","pt":1719468250071,"mc":[{"id":"1.230178316","rc":[{"atb":[[2.06,3.16]],"id":70902601},{"atb":[[2.1,3.16]],"id":69685608}],"con":true,"img":false}]}
{"op":"mcm","clk":"11538750807","pt":1719468250274,"mc":[{"id":"1.230178316","rc":[{"atb":[[2.12,3.16]],"id":46611436}],"con":true,"img":false}]}
{"op":"mcm","clk":"11538750821","pt":1719468250483,"mc":[{"id":"1.230178316","rc":[{"atb":[[2.1,3.16]],"id":52655636}],"con":true,"img":false}]}
{"op":"mcm","clk":"11538752821","pt":1719468289694,"mc":[{"id":"1.230178316","rc":[{"atb":[[2.1,6.55]],"id":57196226},{"spn":496.05,"spf":"NaN","id":57196226},{"spn":501.06,"spf":"NaN","id":46611436},{"spn":501.05,"spf":"NaN","id":52655636},{"spn":496.03,"spf":"NaN","id":70902601},{"spn":501.05,"spf":"NaN","id":69685608},{"spn":501.02,"spf":"NaN","id":49159417}],"con":true,"img":false}]}
{"op":"mcm","clk":"11538752826","pt":1719468289794,"mc":[{"id":"1.230178316","rc":[{"atb":[[2.1,6.55]],"id":69685608}],"con":true,"img":false}]}
{"op":"mcm","clk":"11538752842","pt":1719468290097,"mc":[{"id":"1.230178316","rc":[{"atb":[[2.06,6.55]],"id":70902601}],"con":true,"img":false}]}
{"op":"mcm","clk":"11538752863","pt":1719468290406,"mc":[{"id":"1.230178316","rc":[{"atb":[[2.12,6.55]],"id":46611436}],"con":true,"img":false}]}
{"op":"mcm","clk":"11538752865","pt":1719468290506,"mc":[{"id":"1.230178316","rc":[{"atb":[[2.1,6.55]],"id":52655636}],"con":true,"img":false}]}
{"op":"mcm","clk":"11538752889","pt":1719468290815,"mc":[{"id":"1.230178316","rc":[{"atb":[[2.04,6.55]],"id":49159417}],"con":true,"img":false}]}
{"op":"mcm","clk":"11538754058","pt":1719468311791,"mc":[{"id":"1.230178316","marketDefinition":{"bspMarket":true,"turnInPlayEnabled":false,"persistenceEnabled":false,"marketBaseRate":5.0,"eventId":"33376062","eventTypeId":"4339","numberOfWinners":1,"bettingType":"ODDS","marketType":"WIN","marketTime":"2024-06-27T15:09:00.000Z","suspendTime":"2024-06-27T15:09:00.000Z","bspReconciled":false,"complete":true,"inPlay":false,"crossMatching":true,"runnersVoidable":false,"numberOfActiveRunners":6,"betDelay":0,"status":"OPEN","runners":[{"status":"ACTIVE","sortPriority":1,"id":69685608,"name":"1. Spin It Danny"},{"status":"ACTIVE","sortPriority":2,"id":49159417,"name":"2. Derrymore Ella"},{"status":"ACTIVE","sortPriority":3,"id":57196226,"name":"3. Shrewd Cass"},{"status":"ACTIVE","sortPriority":4,"id":70902601,"name":"4. Fairy Hill John"},{"status":"ACTIVE","sortPriority":5,"id":52655636,"name":"5. Lady Quickstep"},{"status":"ACTIVE","sortPriority":6,"id":46611436,"name":"6. Curryhills Tiana"}],"regulators":["MR_INT"],"venue":"Kinsley","countryCode":"GB","discountAllowed":true,"timezone":"Europe/London","openDate":"2024-06-27T13:36:00.000Z","version":5994643757,"name":"A5 462m","eventName":"Kinsley 27th Jun"},"rc":[],"con":true,"img":false}]}
{"op":"mcm","clk":"11538766506","pt":1719468563208,"mc":[{"id":"1.230178316","rc":[{"atl":[[150,4]],"id":57196226},{"spn":76.05,"spf":"NaN","id":57196226},{"atl":[[150,4]],"id":46611436},{"spn":76.06,"spf":"NaN","id":46611436},{"atl":[[150,4]],"id":52655636},{"spn":76.05,"spf":"NaN","id":52655636},{"atl":[[150,4]],"id":70902601},{"spn":76.03,"spf":"NaN","id":70902601},{"atl":[[150,4]],"id":69685608},{"spn":76.05,"spf":"NaN","id":69685608},{"atl":[[150,4]],"id":49159417},{"spn":76.02,"spf":"NaN","id":49159417}],"con":true,"img":false}]}
{"op":"mcm","clk":"11538940446","pt":1719472108956,"mc":[{"id":"1.230178316","rc":[{"atb":[[1.03,7.88],[2.1,6.54],[2.08,0]],"id":57196226},{"atl":[[990,0.22]],"id":57196226},{"atb":[[1.01,23.65],[2.12,6.54],[2.1,0]],"id":46611436},{"atl":[[1000,0.22]],"id":46611436},{"atb":[[1.03,7.88],[2.1,6.54],[2.08,0]],"id":52655636},{"atl":[[1000,0.22]],"id":52655636},{"atb":[[1.01,23.65],[2.06,6.54],[2.04,0]],"id":70902601},{"atl":[[990,0.22]],"id":70902601},{"atb":[[1.01,23.65],[2.1,6.54],[2.08,0]],"id":69685608},{"atl":[[1000,0.22]],"id":69685608},{"atb":[[2.02,0],[1.01,23.65],[2.04,6.54]],"id":49159417},{"atl":[[1000,0.22]],"id":49159417}],"con":true,"img":false}]}
{"op":"mcm","clk":"11538940453","pt":1719472109058,"mc":[{"id":"1.230178316","rc":[{"atb":[[2.12,12.43]],"id":57196226},{"atb":[[2.14,11.65]],"id":46611436},{"atb":[[2.12,12.43]],"id":52655636},{"atb":[[2.08,11.32]],"id":70902601},{"atb":[[2.12,11.54]],"id":69685608},{"atb":[[2.06,8.62]],"id":49159417}],"con":true,"img":false}]}
{"op":"mcm","clk":"11538943542","pt":1719472157226,"mc":[{"id":"1.230178316","rc":[{"atb":[[2.1,3.38]],"id":69685608}],"con":true,"img":false}]}
{"op":"mcm","clk":"11538943549","pt":1719472157431,"mc":[{"id":"1.230178316","rc":[{"atb":[[2.12,3.38]],"id":46611436}],"con":true,"img":false}]}
{"op":"mcm","clk":"11538943568","pt":1719472157737,"mc":[{"id":"1.230178316","rc":[{"atb":[[2.1,3.38]],"id":52655636}],"con":true,"img":false}]}
{"op":"mcm","clk":"11538943592","pt":1719472158404,"mc":[{"id":"1.230178316","rc":[{"atb":[[2.1,3.38]],"id":57196226}],"con":true,"img":false}]}
{"op":"mcm","clk":"11538943639","pt":1719472159323,"mc":[{"id":"1.230178316","rc":[{"atb":[[2.04,3.38]],"id":49159417}],"con":true,"img":false}]}
{"op":"mcm","clk":"11538943684","pt":1719472160241,"mc":[{"id":"1.230178316","rc":[{"atb":[[2.16,3.16]],"id":46611436}],"con":true,"img":false}]}
{"op":"mcm","clk":"11538943697","pt":1719472160446,"mc":[{"id":"1.230178316","rc":[{"atb":[[2.14,3.16]],"id":57196226}],"con":true,"img":false}]}
{"op":"mcm","clk":"11538943782","pt":1719472161732,"mc":[{"id":"1.230178316","rc":[{"atb":[[2.06,3.38]],"id":70902601}],"con":true,"img":false}]}
{"op":"mcm","clk":"11538943857","pt":1719472162916,"mc":[{"id":"1.230178316","rc":[{"atb":[[2.14,3.16]],"id":69685608}],"con":true,"img":false}]}
{"op":"mcm","clk":"11538943996","pt":1719472164924,"mc":[{"id":"1.230178316","rc":[{"atb":[[2.08,3.16]],"id":49159417}],"con":true,"img":false}]}
{"op":"mcm","clk":"11538944030","pt":1719472165536,"mc":[{"id":"1.230178316","rc":[{"atb":[[2.1,3.16]],"id":70902601}],"con":true,"img":false}]}
{"op":"mcm","clk":"11538944075","pt":1719472166453,"mc":[{"id":"1.230178316","rc":[{"atb":[[2.14,3.16]],"id":52655636}],"con":true,"img":false}]}
{"op":"mcm","clk":"11538944416","pt":1719472172229,"mc":[{"id":"1.230178316","rc":[{"spn":76.07,"spf":"NaN","id":57196226},{"spn":76.08,"spf":"NaN","id":46611436},{"spn":76.07,"spf":"NaN","id":52655636},{"spn":76.05,"spf":"NaN","id":70902601},{"atb":[[2.1,0]],"id":69685608},{"spn":76.07,"spf":"NaN","id":69685608},{"spn":76.04,"spf":"NaN","id":49159417}],"con":true,"img":false}]}
{"op":"mcm","clk":"11538944426","pt":1719472172436,"mc":[{"id":"1.230178316","rc":[{"atb":[[2.1,0]],"id":57196226}],"con":true,"img":false}]}
{"op":"mcm","clk":"11538944436","pt":1719472172640,"mc":[{"id":"1.230178316","rc":[{"atb":[[2.04,0]],"id":49159417}],"con":true,"img":false}]}
{"op":"mcm","clk":"11538944473","pt":1719472173151,"mc":[{"id":"1.230178316","rc":[{"atb":[[2.06,0]],"id":70902601}],"con":true,"img":false}]}
{"op":"mcm","clk":"11538944500","pt":1719472173558,"mc":[{"id":"1.230178316","rc":[{"atb":[[2.12,0]],"id":46611436}],"con":true,"img":false}]}
{"op":"mcm","clk":"11538944553","pt":1719472174328,"mc":[{"id":"1.230178316","rc":[{"atb":[[2.1,0]],"id":52655636}],"con":true,"img":false}]}
{"op":"mcm","clk":"11538945619","pt":1719472192190,"mc":[{"id":"1.230178316","rc":[{"atb":[[2.08,6.54]],"id":49159417}],"con":true,"img":false}]}
{"op":"mcm","clk":"11538945621","pt":1719472192287,"mc":[{"id":"1.230178316","rc":[{"atb":[[2.14,6.54]],"id":69685608}],"con":true,"img":false}]}
{"op":"mcm","clk":"11538945655","pt":1719472193009,"mc":[{"id":"1.230178316","rc":[{"atb":[[2.14,6.54]],"id":57196226}],"con":true,"img":false}]}
{"op":"mcm","clk":"11538945848","pt":1719472195588,"mc":[{"id":"1.230178316","rc":[{"atb":[[2.1,6.54]],"id":70902601}],"con":true,"img":false}]}
{"op":"mcm","clk":"11538945868","pt":1719472195897,"mc":[{"id":"1.230178316","rc":[{"atb":[[2.14,6.54]],"id":52655636}],"con":true,"img":false}]}
{"op":"mcm","clk":"11538945964","pt":1719472197185,"mc":[{"id":"1.230178316","rc":[{"atb":[[2.16,6.54]],"id":46611436}],"con":true,"img":false}]}
{"op":"mcm","clk":"11539122516","pt":1719475682543,"mc":[{"id":"1.230178316","marketDefinition":{"bspMarket":true,"turnInPlayEnabled":false,"persistenceEnabled":false,"marketBaseRate":5.0,"eventId":"33376062","eventTypeId":"4339","numberOfWinners":1,"bettingType":"ODDS","marketType":"WIN","marketTime":"2024-06-27T15:09:00.000Z","suspendTime":"2024-06-27T15:09:00.000Z","bspReconciled":false,"complete":true,"inPlay":false,"crossMatching":true,"runnersVoidable":false,"numberOfActiveRunners":6,"betDelay":0,"status":"OPEN","runners":[{"status":"ACTIVE","sortPriority":1,"id":69685608,"name":"1. Spin It Danny"},{"status":"ACTIVE","sortPriority":2,"id":49159417,"name":"2. Derrymore Ella"},{"status":"ACTIVE","sortPriority":3,"id":57196226,"name":"3. Shrewd Cass"},{"status":"ACTIVE","sortPriority":4,"id":70902601,"name":"4. Fairy Hill John"},{"status":"ACTIVE","sortPriority":5,"id":52655636,"name":"5. Lady Quickstep"},{"status":"ACTIVE","sortPriority":6,"id":46611436,"name":"6. Curryhills Tiana"}],"regulators":["MR_INT"],"venue":"Kinsley","countryCode":"GB","discountAllowed":true,"timezone":"Europe/London","openDate":"2024-06-27T13:36:00.000Z","version":5994643757,"name":"A5 462m","eventName":"Kinsley 27th Jun"},"rc":[{"atb":[[1.03,7.88],[2.12,12.43],[2.14,6.55]],"id":57196226},{"atl":[[150,4],[990,0.22]],"id":57196226},{"spn":76.07,"spf":"NaN","id":57196226},{"atb":[[1.01,23.66],[2.16,6.55],[2.14,11.65]],"id":46611436},{"atl":[[150,4],[1000,0.22]],"id":46611436},{"spn":76.08,"spf":"NaN","id":46611436},{"atb":[[1.03,7.88],[2.12,12.43],[2.14,6.55]],"id":52655636},{"atl":[[150,4],[1000,0.22]],"id":52655636},{"spn":76.07,"spf":"NaN","id":52655636},{"atb":[[1.01,23.66],[2.1,6.55],[2.08,11.32]],"id":70902601},{"atl":[[150,4],[990,0.22]],"id":70902601},{"spn":76.05,"spf":"NaN","id":70902601},{"atb":[[1.01,23.66],[2.12,11.54],[2.14,6.55]],"id":69685608},{"atl":[[150,4],[1000,0.22]],"id":69685608},{"spn":76.07,"spf":"NaN","id":69685608},{"atb":[[1.01,23.66],[2.06,8.63],[2.08,6.55]],"id":49159417},{"atl":[[150,4],[1000,0.22]],"id":49159417},{"spn":76.04,"spf":"NaN","id":49159417}],"con":true,"img":true}]}
{"op":"mcm","clk":"11539127763","pt":1719475709092,"mc":[{"id":"1.230178316","rc":[{"atb":[[1.03,7.88],[2.12,0],[2.14,6.55]],"id":57196226},{"atb":[[1.01,23.66],[2.16,6.55],[2.14,0]],"id":46611436},{"atb":[[1.03,7.88],[2.12,0],[2.14,6.55]],"id":52655636},{"atb":[[1.01,23.66],[2.1,6.55],[2.08,0]],"id":70902601},{"atb":[[1.01,23.66],[2.12,0],[2.14,6.55]],"id":69685608},{"atb":[[1.01,23.66],[2.06,0],[2.08,6.55]],"id":49159417}],"con":true,"img":false}]}
{"op":"mcm","clk":"11539127773","pt":1719475709199,"mc":[{"id":"1.230178316","rc":[{"atb":[[2.16,12.43]],"id":57196226},{"atb":[[2.18,11.65]],"id":46611436},{"atb":[[2.16,12.43]],"id":52655636},{"atb":[[2.12,11.32]],"id":70902601},{"atb":[[2.16,11.54]],"id":69685608},{"atb":[[2.1,8.63]],"id":49159417}],"con":true,"img":false}]}
{"op":"mcm","clk":"11539127834","pt":1719475710114,"mc":[{"id":"1.230178316","rc":[{"atb":[[2.14,3.38]],"id":69685608}],"con":true,"img":false}]}
{"op":"mcm","clk":"11539127853","pt":1719475710424,"mc":[{"id":"1.230178316","rc":[{"atb":[[2.08,3.38]],"id":49159417}],"con":true,"img":false}]}
{"op":"mcm","clk":"11539127887","pt":1719475710917,"mc":[{"id":"1.230178316","rc":[{"atb":[[2.18,3.16]],"id":69685608}],"con":true,"img":false}]}
{"op":"mcm","clk":"11539127954","pt":1719475711892,"mc":[{"id":"1.230178316","rc":[{"atb":[[2.14,3.38]],"id":52655636}],"con":true,"img":false}]}
{"op":"mcm","clk":"11539127983","pt":1719475712404,"mc":[{"id":"1.230178316","rc":[{"atb":[[2.1,3.38]],"id":70902601}],"con":true,"img":false}]}
{"op":"mcm","clk":"11539127996","pt":1719475712610,"mc":[{"id":"1.230178316","rc":[{"atb":[[2.16,3.38]],"id":46611436}],"con":true,"img":false}]}
{"op":"mcm","clk":"11539128011","pt":1719475712818,"mc":[{"id":"1.230178316","rc":[{"atb":[[2.14,3.38]],"id":57196226},{"atb":[[2.18,3.16]],"id":52655636}],"con":true,"img":false}]}
{"op":"mcm","clk":"11539128151","pt":1719475714204,"mc":[{"id":"1.230178316","rc":[{"atb":[[2.2,3.16]],"id":46611436}],"con":true,"img":false}]}
{"op":"mcm","clk":"11539128313","pt":1719475715800,"mc":[{"id":"1.230178316","rc":[{"atb":[[2.18,3.16]],"id":57196226}],"con":true,"img":false}]}
{"op":"mcm","clk":"11539128351","pt":1719475716516,"mc":[{"id":"1.230178316","rc":[{"atb":[[2.14,3.16]],"id":70902601}],"con":true,"img":false}]}
{"op":"mcm","clk":"11539128387","pt":1719475717083,"mc":[{"id":"1.230178316","rc":[{"atb":[[2.12,3.16]],"id":49159417}],"con":true,"img":false}]}
{"op":"mcm","clk":"11539134009","pt":1719475806409,"mc":[{"id":"1.230178316","rc":[{"spn":76.09,"spf":"NaN","id":57196226},{"spn":76.1,"spf":"NaN","id":46611436},{"spn":76.09,"spf":"NaN","id":52655636},{"atb":[[2.1,0]],"id":70902601},{"spn":76.07,"spf":"NaN","id":70902601},{"spn":76.09,"spf":"NaN","id":69685608},{"spn":76.06,"spf":"NaN","id":49159417}],"con":true,"img":false}]}
{"op":"mcm","clk":"11539134062","pt":1719475807282,"mc":[{"id":"1.230178316","rc":[{"atb":[[2.14,0]],"id":57196226}],"con":true,"img":false}]}
{"op":"mcm","clk":"11539134123","pt":1719475808007,"mc":[{"id":"1.230178316","rc":[{"atb":[[2.08,0]],"id":49159417}],"con":true,"img":false}]}
{"op":"mcm","clk":"11539134143","pt":1719475808317,"mc":[{"id":"1.230178316","rc":[{"atb":[[2.16,0]],"id":46611436}],"con":true,"img":false}]}
{"op":"mcm","clk":"11539134181","pt":1719475808833,"mc":[{"id":"1.230178316","rc":[{"atb":[[2.14,0]],"id":52655636}],"con":true,"img":false}]}
{"op":"mcm","clk":"11539134194","pt":1719475809137,"mc":[{"id":"1.230178316","rc":[{"atb":[[2.14,0]],"id":69685608}],"con":true,"img":false}]}
{"op":"mcm","clk":"11539134349","pt":1719475811099,"mc":[{"id":"1.230178316","rc":[{"atb":[[2.14,6.55]],"id":70902601}],"con":true,"img":false}]}
{"op":"mcm","clk":"11539134390","pt":1719475811721,"mc":[{"id":"1.230178316","rc":[{"atb":[[2.2,6.55]],"id":46611436}],"con":true,"img":false}]}
{"op":"mcm","clk":"11539134415","pt":1719475812029,"mc":[{"id":"1.230178316","rc":[{"atb":[[2.12,6.55]],"id":49159417}],"con":true,"img":false}]}
{"op":"mcm","clk":"11539134429","pt":1719475812235,"mc":[{"id":"1.230178316","rc":[{"atb":[[2.18,6.55]],"id":52655636}],"con":true,"img":false}]}
{"op":"mcm","clk":"11539134443","pt":1719475812494,"mc":[{"id":"1.230178316","rc":[{"atb":[[2.18,6.55]],"id":57196226}],"con":true,"img":false}]}
{"op":"mcm","clk":"11539134599","pt":1719475815325,"mc":[{"id":"1.230178316","rc":[{"atb":[[2.18,6.55]],"id":69685608}],"con":true,"img":false}]}
{"op":"mcm","clk":"11539341259","pt":1719479308029,"mc":[{"id":"1.230178316","rc":[{"atb":[[1.03,7.88],[2.18,6.54],[2.16,0]],"id":57196226},{"atb":[[1.01,23.66],[2.18,0],[2.2,6.54]],"id":46611436},{"atb":[[1.03,7.88],[2.18,6.54],[2.16,0]],"id":52655636},{"atb":[[1.01,23.66],[2.12,0],[2.14,6.54]],"id":70902601},{"atb":[[1.01,23.66],[2.18,6.54],[2.16,0]],"id":69685608},{"atb":[[1.01,23.66],[2.12,6.54],[2.1,0]],"id":49159417}],"con":true,"img":false}]}
{"op":"mcm","clk":"11539341269","pt":1719479308130,"mc":[{"id":"1.230178316","rc":[{"atb":[[2.2,12.43]],"id":57196226},{"atb":[[2.22,11.65]],"id":46611436},{"atb":[[2.2,12.43]],"id":52655636},{"atb":[[2.16,11.32]],"id":70902601},{"atb":[[2.2,11.54]],"id":69685608},{"atb":[[2.14,8.62]],"id":49159417}],"con":true,"img":false}]}
{"op":"mcm","clk":"11539347114","pt":1719479402081,"mc":[{"id":"1.230178316","rc":[{"spn":76.1,"spf":"NaN","id":57196226},{"spn":76.11,"spf":"NaN","id":46611436},{"spn":76.1,"spf":"NaN","id":52655636},{"spn":76.08,"spf":"NaN","id":70902601},{"spn":76.1,"spf":"NaN","id":69685608},{"atb":[[2.12,3.38]],"id":49159417},{"spn":76.07,"spf":"NaN","id":49159417}],"con":true,"img":false}]}
{"op":"mcm","clk":"11539347134","pt":1719479402303,"mc":[{"id":"1.230178316","rc":[{"atb":[[2.18,3.38]],"id":69685608}],"con":true,"img":false}]}
{"op":"mcm","clk":"11539347170","pt":1719479402761,"mc":[{"id":"1.230178316","rc":[{"atb":[[2.14,3.38]],"id":70902601}],"con":true,"img":false}]}
{"op":"mcm","clk":"11539347237","pt":1719479403690,"mc":[{"id":"1.230178316","rc":[{"atb":[[2.18,3.38]],"id":57196226}],"con":true,"img":false}]}
{"op":"mcm","clk":"11539347400","pt":1719479406074,"mc":[{"id":"1.230178316","rc":[{"atb":[[2.2,3.38]],"id":46611436}],"con":true,"img":false}]}
{"op":"mcm","clk":"11539347480","pt":1719479407098,"mc":[{"id":"1.230178316","rc":[{"atb":[[2.18,3.38]],"id":52655636}],"con":true,"img":false}]}
{"op":"mcm","clk":"11539349755","pt":1719479443724,"mc":[{"id":"1.230178316","rc":[{"atb":[[2.18,0]],"id":69685608}],"con":true,"img":false}]}
{"op":"mcm","clk":"11539349793","pt":1719479444442,"mc":[{"id":"1.230178316","rc":[{"atb":[[2.12,0]],"id":49159417}],"con":true,"img":false}]}
{"op":"mcm","clk":"11539349821","pt":1719479444804,"mc":[{"id":"1.230178316","rc":[{"atb":[[2.18,0]],"id":57196226}],"con":true,"img":false}]}
{"op":"mcm","clk":"11539349861","pt":1719479445420,"mc":[{"id":"1.230178316","rc":[{"atb":[[2.18,0]],"id":52655636}],"con":true,"img":false}]}
{"op":"mcm","clk":"11539349875","pt":1719479445624,"mc":[{"id":"1.230178316","rc":[{"atb":[[2.14,0]],"id":70902601}],"con":true,"img":false}]}
{"op":"mcm","clk":"11539349905","pt":1719479446041,"mc":[{"id":"1.230178316","rc":[{"atb":[[2.2,0]],"id":46611436}],"con":true,"img":false}]}
{"op":"mcm","clk":"11539350159","pt":1719479450047,"mc":[{"id":"1.230178316","rc":[{"atb":[[2.22,3.38]],"id":52655636}],"con":true,"img":false}]}
{"op":"mcm","clk":"11539350211","pt":1719479450770,"mc":[{"id":"1.230178316","rc":[{"atb":[[2.24,3.38]],"id":46611436}],"con":true,"img":false}]}
{"op":"mcm","clk":"11539350225","pt":1719479450924,"mc":[{"id":"1.230178316","rc":[{"atb":[[2.22,3.38]],"id":57196226}],"con":true,"img":false}]}
{"op":"mcm","clk":"11539350281","pt":1719479451586,"mc":[{"id":"1.230178316","rc":[{"atb":[[2.16,3.38]],"id":49159417}],"con":true,"img":false}]}
{"op":"mcm","clk":"11539350308","pt":1719479451912,"mc":[{"id":"1.230178316","rc":[{"atb":[[2.22,3.38]],"id":69685608}],"con":true,"img":false}]}
{"op":"mcm","clk":"11539350403","pt":1719479452950,"mc":[{"id":"1.230178316","rc":[{"atb":[[2.18,3.38]],"id":70902601}],"con":true,"img":false}]}
{"op":"mcm","clk":"11539367937","pt":1719479710400,"mc":[{"id":"1.230178316","rc":[{"spn":76.11,"spf":"NaN","id":57196226},{"spn":76.12,"spf":"NaN","id":46611436},{"spn":76.11,"spf":"NaN","id":52655636},{"spn":76.09,"spf":"NaN","id":70902601},{"atb":[[2.22,6.54]],"id":69685608},{"spn":76.11,"spf":"NaN","id":69685608},{"spn":76.08,"spf":"NaN","id":49159417}],"con":true,"img":false}]}
{"op":"mcm","clk":"11539367947","pt":1719479710502,"mc":[{"id":"1.230178316","rc":[{"atb":[[2.22,6.54]],"id":57196226}],"con":true,"img":false}]}
{"op":"mcm","clk":"11539368000","pt":1719479711079,"mc":[{"id":"1.230178316","rc":[{"atb":[[2.22,6.54]],"id":52655636}],"con":true,"img":false}]}
{"op":"mcm","clk":"11539368103","pt":1719479712318,"mc":[{"id":"1.230178316","rc":[{"atb":[[2.16,6.54]],"id":49159417}],"con":true,"img":false}]}
{"op":"mcm","clk":"11539368252","pt":1719479714122,"mc":[{"id":"1.230178316","rc":[{"atb":[[2.18,6.54]],"id":70902601}],"con":true,"img":false}]}
{"op":"mcm","clk":"11539368273","pt":1719479714380,"mc":[{"id":"1.230178316","rc":[{"atb":[[2.24,6.54]],"id":46611436}],"con":true,"img":false}]}
{"op":"mcm","clk":"11539545250","pt":1719482907695,"mc":[{"id":"1.230178316","rc":[{"atb":[[1.03,7.88],[2.22,6.54],[2.2,0]],"id":57196226},{"atb":[[2.24,6.54],[1.01,23.65],[2.22,0]],"id":46611436},{"atb":[[1.03,7.88],[2.22,6.54],[2.2,0]],"id":52655636},{"atb":[[1.01,23.65],[2.18,6.54],[2.16,0]],"id":70902601},{"atb":[[1.01,23.65],[2.22,6.54],[2.2,0]],"id":69685608},{"atb":[[1.01,23.65],[2.16,6.54],[2.14,0]],"id":49159417}],"con":true,"img":false}]}
{"op":"mcm","clk":"11539545258","pt":1719482907789,"mc":[{"id":"1.230178316","rc":[{"atb":[[2.24,12.43]],"id":57196226},{"atb":[[2.26,11.65]],"id":46611436},{"atb":[[2.24,12.43]],"id":52655636},{"atb":[[2.2,11.32]],"id":70902601},{"atb":[[2.24,11.54]],"id":69685608},{"atb":[[2.18,8.62]],"id":49159417}],"con":true,"img":false}]}
{"op":"mcm","clk":"11539548537","pt":1719482957719,"mc":[{"id":"1.230178316","rc":[{"atl":[[36,8],[60,12]],"id":57196226},{"atl":[[32,8],[55,12]],"id":46611436},{"atl":[[36,8],[60,12]],"id":52655636},{"atl":[[48,12],[28,8]],"id":70902601},{"atl":[[32,8],[55,12]],"id":69685608},{"atl":[[32,8],[55,12]],"id":49159417}],"con":true,"img":false}]}
{"op":"mcm","clk":"11539548769","pt":1719482961328,"mc":[{"id":"1.230178316","rc":[{"atb":[[2.22,3.16]],"id":57196226}],"con":true,"img":false}]}
{"op":"mcm","clk":"11539548938","pt":1719482964116,"mc":[{"id":"1.230178316","rc":[{"atb":[[2.22,3.16]],"id":69685608}],"con":true,"img":false}]}
{"op":"mcm","clk":"11539548964","pt":1719482964428,"mc":[{"id":"1.230178316","rc":[{"atb":[[2.22,3.16]],"id":52655636}],"con":true,"img":false}]}
{"op":"mcm","clk":"11539548971","pt":1719482964634,"mc":[{"id":"1.230178316","rc":[{"atb":[[2.16,3.16]],"id":49159417}],"con":true,"img":false}]}
{"op":"mcm","clk":"11539548999","pt":1719482965250,"mc":[{"id":"1.230178316","rc":[{"atb":[[2.24,3.16]],"id":46611436}],"con":true,"img":false}]}
{"op":"mcm","clk":"11539549065","pt":1719482966435,"mc":[{"id":"1.230178316","rc":[{"atb":[[2.18,3.16]],"id":70902601}],"con":true,"img":false}]}
{"op":"mcm","clk":"11539549182","pt":1719482968241,"mc":[{"id":"1.230178316","rc":[{"atb":[[2.26,3.38]],"id":57196226},{"spn":19.13,"spf":"NaN","id":57196226},{"spn":17.13,"spf":"NaN","id":46611436},{"spn":19.12,"spf":"NaN","id":52655636},{"spn":15.1,"spf":"NaN","id":70902601},{"spn":17.12,"spf":"NaN","id":69685608},{"spn":17.09,"spf":"NaN","id":49159417}],"con":true,"img":false}]}
{"op":"mcm","clk":"11539549228","pt":1719482969220,"mc":[{"id":"1.230178316","rc":[{"atb":[[2.26,3.38]],"id":52655636}],"con":true,"img":false}]}
{"op":"mcm","clk":"11539549247","pt":1719482969530,"mc":[{"id":"1.230178316","rc":[{"atb":[[2.2,3.38]],"id":49159417}],"con":true,"img":false}]}
{"op":"mcm","clk":"11539549256","pt":1719482969735,"mc":[{"id":"1.230178316","rc":[{"atb":[[2.26,3.38]],"id":69685608}],"con":true,"img":false}]}
{"op":"mcm","clk":"11539549271","pt":1719482970043,"mc":[{"id":"1.230178316","rc":[{"atb":[[2.28,3.38]],"id":46611436}],"con":true,"img":false}]}
{"op":"mcm","clk":"11539549283","pt":1719482970247,"mc":[{"id":"1.230178316","rc":[{"atb":[[2.22,3.38]],"id":70902601}],"con":true,"img":false}]}
{"op":"mcm","clk":"11539553384","pt":1719483029102,"mc":[{"id":"1.230178316","rc":[{"atb":[[2.22,0]],"id":57196226},{"atb":[[2.24,0]],"id":46611436},{"spn":17.14,"spf":"NaN","id":46611436},{"atb":[[2.22,0]],"id":52655636},{"spn":19.13,"spf":"NaN","id":52655636},{"atb":[[2.18,0]],"id":70902601},{"spn":15.11,"spf":"NaN","id":70902601},{"atb":[[2.22,0]],"id":69685608},{"spn":17.13,"spf":"NaN","id":69685608},{"atb":[[2.16,0]],"id":49159417},{"spn":17.1,"spf":"NaN","id":49159417}],"con":true,"img":false}]}
{"op":"mcm","clk":"11539573311","pt":1719483326262,"mc":[{"id":"1.230178316","rc":[{"atb":[[2.28,6.54]],"id":46611436}],"con":true,"img":false}]}
{"op":"mcm","clk":"11539573331","pt":1719483326475,"mc":[{"id":"1.230178316","rc":[{"atb":[[2.22,6.54]],"id":70902601}],"con":true,"img":false}]}
{"op":"mcm","clk":"11539573365","pt":1719483326903,"mc":[{"id":"1.230178316","rc":[{"atb":[[2.26,6.54]],"id":52655636}],"con":true,"img":false}]}
{"op":"mcm","clk":"11539573385","pt":1719483327166,"mc":[{"id":"1.230178316","rc":[{"atb":[[2.2,6.54]],"id":49159417}],"con":true,"img":false}]}
{"op":"mcm","clk":"11539573425","pt":1719483327577,"mc":[{"id":"1.230178316","rc":[{"atb":[[2.26,6.54]],"id":69685608}],"con":true,"img":false}]}
{"op":"mcm","clk":"11539573444","pt":1719483327778,"mc":[{"id":"1.230178316","rc":[{"atb":[[2.26,6.54]],"id":57196226}],"con":true,"img":false}]}
{"op":"mcm","clk":"11539730254","pt":1719485383005,"mc":[{"id":"1.230178316","rc":[{"atb":[[3.55,6]],"id":57196226},{"spn":19.77,"spf":"NaN","id":57196226},{"atb":[[3.1,6]],"id":46611436},{"spn":17.55,"spf":"NaN","id":46611436},{"atb":[[3.55,6]],"id":52655636},{"spn":19.77,"spf":"NaN","id":52655636},{"atb":[[3.1,6]],"id":70902601},{"spn":15.55,"spf":"NaN","id":70902601},{"atb":[[2.86,6]],"id":69685608},{"spn":17.43,"spf":"NaN","id":69685608},{"atb":[[2.86,6]],"id":49159417},{"spn":17.43,"spf":"NaN","id":49159417}],"con":true,"img":false}]}
{"op":"mcm","clk":"11539732544","pt":1719485411010,"mc":[{"id":"1.230178316","rc":[{"atb":[[2.26,3.38]],"id":69685608}],"con":true,"img":false}]}
{"op":"mcm","clk":"11539732553","pt":1719485411112,"mc":[{"id":"1.230178316","rc":[{"atb":[[2.2,3.38]],"id":49159417}],"con":true,"img":false}]}
{"op":"mcm","clk":"11539732563","pt":1719485411216,"mc":[{"id":"1.230178316","rc":[{"atb":[[2.26,3.38]],"id":57196226},{"atb":[[2.28,3.38]],"id":46611436},{"atb":[[2.26,3.38]],"id":52655636},{"atb":[[2.22,3.38]],"id":70902601}],"con":true,"img":false}]}
{"op":"mcm","clk":"11539732580","pt":1719485411420,"mc":[{"id":"1.230178316","rc":[{"atb":[[2.88,3.16]],"id":69685608},{"atb":[[2.88,3.16]],"id":49159417}],"con":true,"img":false}]}
{"op":"mcm","clk":"11539734879","pt":1719485439159,"mc":[{"id":"1.230178316","rc":[{"atb":[[2.26,0]],"id":69685608}],"con":true,"img":false}]}
{"op":"mcm","clk":"11539734888","pt":1719485439262,"mc":[{"id":"1.230178316","rc":[{"atb":[[2.26,0]],"id":57196226},{"atb":[[2.28,0]],"id":46611436},{"atb":[[2.26,0]],"id":52655636},{"atb":[[2.22,0]],"id":70902601}],"con":true,"img":false}]}
{"op":"mcm","clk":"11539734909","pt":1719485439424,"mc":[{"id":"1.230178316","rc":[{"atb":[[2.2,0]],"id":49159417}],"con":true,"img":false}]}
{"op":"mcm","clk":"11539734945","pt":1719485439840,"mc":[{"id":"1.230178316","rc":[{"atb":[[2.88,6.54]],"id":69685608}],"con":true,"img":false}]}
{"op":"mcm","clk":"11539734954","pt":1719485439936,"mc":[{"id":"1.230178316","rc":[{"atb":[[2.88,6.54]],"id":49159417}],"con":true,"img":false}]}
{"op":"mcm","clk":"11539810789","pt":1719486482531,"mc":[{"id":"1.230178316","marketDefinition":{"bspMarket":true,"turnInPlayEnabled":false,"persistenceEnabled":false,"marketBaseRate":5.0,"eventId":"33376062","eventTypeId":"4339","numberOfWinners":1,"bettingType":"ODDS","marketType":"WIN","marketTime":"2024-06-27T15:09:00.000Z","suspendTime":"2024-06-27T15:09:00.000Z","bspReconciled":false,"complete":true,"inPlay":false,"crossMatching":true,"runnersVoidable":false,"numberOfActiveRunners":6,"betDelay":0,"status":"OPEN","runners":[{"status":"ACTIVE","sortPriority":1,"id":69685608,"name":"1. Spin It Danny"},{"status":"ACTIVE","sortPriority":2,"id":49159417,"name":"2. Derrymore Ella"},{"status":"ACTIVE","sortPriority":3,"id":57196226,"name":"3. Shrewd Cass"},{"status":"ACTIVE","sortPriority":4,"id":70902601,"name":"4. Fairy Hill John"},{"status":"ACTIVE","sortPriority":5,"id":52655636,"name":"5. Lady Quickstep"},{"status":"ACTIVE","sortPriority":6,"id":46611436,"name":"6. Curryhills Tiana"}],"regulators":["MR_INT"],"venue":"Kinsley","countryCode":"GB","discountAllowed":true,"timezone":"Europe/London","openDate":"2024-06-27T13:36:00.000Z","version":5994643757,"name":"A5 462m","eventName":"Kinsley 27th Jun"},"rc":[{"atb":[[2.24,12.43],[1.03,7.88],[3.55,6]],"id":57196226},{"atl":[[36,8],[150,4],[60,12],[990,0.22]],"id":57196226},{"spn":19.77,"spf":"NaN","id":57196226},{"atb":[[1.01,23.66],[3.1,6],[2.26,11.65]],"id":46611436},{"atl":[[32,8],[150,4],[55,12],[1000,0.22]],"id":46611436},{"spn":17.55,"spf":"NaN","id":46611436},{"atb":[[2.24,12.43],[1.03,7.88],[3.55,6]],"id":52655636},{"atl":[[36,8],[150,4],[60,12],[1000,0.22]],"id":52655636},{"spn":19.77,"spf":"NaN","id":52655636},{"atb":[[1.01,23.66],[3.1,6],[2.2,11.32]],"id":70902601},{"atl":[[150,4],[48,12],[28,8],[990,0.22]],"id":70902601},{"spn":15.55,"spf":"NaN","id":70902601},{"atb":[[2.24,11.54],[2.88,6.54],[1.01,23.66],[2.86,6]],"id":69685608},{"atl":[[32,8],[150,4],[55,12],[1000,0.22]],"id":69685608},{"spn":17.44,"spf":"NaN","id":69685608},{"atb":[[2.88,6.54],[1.01,23.66],[2.86,6],[2.18,8.62]],"id":49159417},{"atl":[[32,8],[150,4],[55,12],[1000,0.22]],"id":49159417},{"spn":17.44,"spf":"NaN","id":49159417}],"con":true,"img":true}]}
{"op":"mcm","clk":"11539820345","pt":1719486540448,"mc":[{"id":"1.230178316","rc":[{"atb":[[2.24,12.43],[1.03,7.88],[3.1,1.07]],"id":57196226},{"atb":[[1.01,23.66],[5,1],[2.26,11.65]],"id":46611436},{"atb":[[2.24,12.43],[1.03,7.88],[5,1]],"id":52655636},{"atb":[[1.01,23.66],[2.2,11.32],[4.2,1]],"id":70902601},{"atb":[[2.24,11.54],[2.88,6.54],[1.01,23.66],[5,1]],"id":69685608},{"spn":17.44,"spf":"NaN","id":69685608},{"atb":[[2.88,6.54],[1.01,23.66],[5,1],[2.18,8.62]],"id":49159417},{"spn":17.44,"spf":"NaN","id":49159417}],"con":true,"img":false}]}
{"op":"mcm","clk":"11539820828","pt":1719486545557,"mc":[{"id":"1.230178316","rc":[{"atb":[[1.51,196.08]],"id":57196226},{"atb":[[1.51,196.08]],"id":46611436},{"spn":18.5,"spf":"NaN","id":46611436},{"atb":[[1.51,196.08]],"id":52655636},{"spn":20.5,"spf":"NaN","id":52655636},{"atb":[[1.51,196.08]],"id":70902601},{"spn":16.1,"spf":"NaN","id":70902601},{"spn":18.5,"spf":"NaN","id":69685608},{"spn":18.5,"spf":"NaN","id":49159417}],"con":true,"img":false}]}
{"op":"mcm","clk":"11539894613","pt":1719487522319,"mc":[{"id":"1.230178316","rc":[{"atb":[[2.12,89.29]],"id":52655636},{"atb":[[1.51,196.08]],"id":69685608},{"atb":[[1.51,196.08]],"id":49159417}],"con":true,"img":false}]}
{"op":"mcm","clk":"11539916884","pt":1719487782131,"mc":[{"id":"1.230178316","rc":[{"atb":[[3.1,0],[3.15,1.05]],"id":57196226},{"atb":[[4.3,1],[4.2,0]],"id":70902601},{"spn":16.15,"spf":"NaN","id":70902601}],"con":true,"img":false}]}
{"op":"mcm","clk":"11540014370","pt":1719488999103,"mc":[{"id":"1.230178316","rc":[{"atl":[[550,2]],"id":57196226},{"atl":[[500,2]],"id":46611436},{"atl":[[560,2]],"id":52655636},{"atl":[[270,2]],"id":70902601},{"atl":[[370,2]],"id":69685608},{"atb":[[1.16,150]],"id":49159417},{"atl":[[390,2]],"id":49159417}],"con":true,"img":false}]}
{"op":"mcm","clk":"11540014381","pt":1719488999203,"mc":[{"id":"1.230178316","rc":[{"atb":[[1.16,150]],"id":57196226},{"atb":[[1.16,150]],"id":52655636},{"atb":[[1.16,150]],"id":69685608}],"con":true,"img":false}]}
{"op":"mcm","clk":"11540014391","pt":1719488999309,"mc":[{"id":"1.230178316","rc":[{"atb":[[1.16,150]],"id":46611436},{"atb":[[1.16,150]],"id":70902601}],"con":true,"img":false}]}
{"op":"mcm","clk":"11540247708","pt":1719491882543,"mc":[{"id":"1.230178316","marketDefinition":{"bspMarket":true,"turnInPlayEnabled":false,"persistenceEnabled":false,"marketBaseRate":5.0,"eventId":"33376062","eventTypeId":"4339","numberOfWinners":1,"bettingType":"ODDS","marketType":"WIN","marketTime":"2024-06-27T15:09:00.000Z","suspendTime":"2024-06-27T15:09:00.000Z","bspReconciled":false,"complete":true,"inPlay":false,"crossMatching":true,"runnersVoidable":false,"numberOfActiveRunners":6,"betDelay":0,"status":"OPEN","runners":[{"status":"ACTIVE","sortPriority":1,"id":69685608,"name":"1. Spin It Danny"},{"status":"ACTIVE","sortPriority":2,"id":49159417,"name":"2. Derrymore Ella"},{"status":"ACTIVE","sortPriority":3,"id":57196226,"name":"3. Shrewd Cass"},{"status":"ACTIVE","sortPriority":4,"id":70902601,"name":"4. Fairy Hill John"},{"status":"ACTIVE","sortPriority":5,"id":52655636,"name":"5. Lady Quickstep"},{"status":"ACTIVE","sortPriority":6,"id":46611436,"name":"6. Curryhills Tiana"}],"regulators":["MR_INT"],"venue":"Kinsley","countryCode":"GB","discountAllowed":true,"timezone":"Europe/London","openDate":"2024-06-27T13:36:00.000Z","version":5994643757,"name":"A5 462m","eventName":"Kinsley 27th Jun"},"rc":[{"atb":[[2.24,12.43],[1.16,150],[1.03,7.88],[3.55,6],[3.15,1.05],[1.51,196.08]],"id":57196226},{"atl":[[550,2],[36,8],[150,4],[60,12],[990,0.22]],"id":57196226},{"spn":19.77,"spf":"NaN","id":57196226},{"atb":[[1.01,23.66],[5,1],[1.16,150],[3.1,6],[2.26,11.65],[1.51,196.08]],"id":46611436},{"atl":[[32,8],[150,4],[55,12],[500,2],[1000,0.22]],"id":46611436},{"spn":18.5,"spf":"NaN","id":46611436},{"atb":[[2.24,12.43],[5,1],[1.16,150],[1.03,7.88],[2.12,89.29],[3.55,6],[1.51,196.08]],"id":52655636},{"atl":[[560,2],[36,8],[150,4],[60,12],[1000,0.22]],"id":52655636},{"spn":20.5,"spf":"NaN","id":52655636},{"atb":[[4.3,1],[1.01,23.66],[1.16,150],[3.1,6],[2.2,11.32],[1.51,196.08]],"id":70902601},{"atl":[[270,2],[150,4],[48,12],[28,8],[990,0.22]],"id":70902601},{"spn":16.15,"spf":"NaN","id":70902601},{"atb":[[2.24,11.54],[2.88,6.54],[1.01,23.66],[5,1],[2.86,6],[1.16,150],[1.51,196.08]],"id":69685608},{"atl":[[32,8],[150,4],[370,2],[55,12],[1000,0.22]],"id":69685608},{"spn":18.5,"spf":"NaN","id":69685608},{"atb":[[2.88,6.54],[1.01,23.66],[5,1],[2.86,6],[1.16,150],[2.18,8.62],[1.51,196.08]],"id":49159417},{"atl":[[32,8],[150,4],[390,2],[55,12],[1000,0.22]],"id":49159417},{"spn":18.5,"spf":"NaN","id":49159417}],"con":true,"img":true}]}
{"op":"mcm","clk":"11540499620","pt":1719495211583,"mc":[{"id":"1.230178316","rc":[{"atb":[[2.24,12.45],[1.03,7.89]],"id":57196226},{"atl":[[990,0.22]],"id":57196226},{"atb":[[1.01,23.68],[2.26,11.67]],"id":46611436},{"atl":[[1000,0.22]],"id":46611436},{"atb":[[2.24,12.45],[1.03,7.89]],"id":52655636},{"atl":[[1000,0.22]],"id":52655636},{"spl":[[1.01,1]],"id":70902601},{"atb":[[1.01,23.68],[2.2,11.34]],"id":70902601},{"atl":[[990,0.22]],"id":70902601},{"spn":4.3,"spf":1.0,"id":70902601},{"atb":[[2.24,11.56],[2.88,6.54],[1.01,23.68]],"id":69685608},{"atl":[[1000,0.22]],"id":69685608},{"atb":[[2.88,6.54],[1.01,23.68],[2.18,8.63]],"id":49159417},{"atl":[[1000,0.22]],"id":49159417}],"con":true,"img":false}]}
{"op":"mcm","clk":"11540577960","pt":1719496092437,"mc":[{"id":"1.230178316","rc":[{"atb":[[3.3,1]],"id":57196226},{"atb":[[5,2]],"id":46611436},{"atb":[[6,1]],"id":52655636},{"spn":21.0,"spf":"NaN","id":52655636},{"atb":[[4.6,1]],"id":70902601},{"spn":4.6,"spf":1.0,"id":70902601},{"atb":[[4.4,1]],"id":69685608},{"atb":[[4.6,1]],"id":49159417}],"con":true,"img":false}]}
{"op":"mcm","clk":"11540579470","pt":1719496108535,"mc":[{"id":"1.230178316","rc":[{"atb":[[2.12,89.29]],"id":69685608},{"atb":[[2.12,89.29]],"id":49159417}],"con":true,"img":false}]}
{"op":"mcm","clk":"11540659038","pt":1719497009885,"mc":[{"id":"1.230178316","rc":[{"atb":[[2.24,12.44],[1.03,7.89]],"id":57196226},{"atb":[[1.01,23.67],[2.26,11.66]],"id":46611436},{"atb":[[2.24,12.44],[1.03,7.89]],"id":52655636},{"atb":[[1.01,23.67],[2.12,89.29],[2.2,11.33]],"id":70902601},{"atb":[[2.24,11.55],[2.88,6.54],[1.01,23.67]],"id":69685608},{"atb":[[2.88,6.54],[1.01,23.67],[2.18,8.63]],"id":49159417}],"con":true,"img":false}]}
{"op":"mcm","clk":"11540813471","pt":1719498655969,"mc":[{"id":"1.230178316","rc":[{"atb":[[3.3,0]],"id":57196226},{"atb":[[5,1]],"id":46611436},{"atb":[[6,0]],"id":52655636},{"spn":20.5,"spf":"NaN","id":52655636},{"atb":[[4.6,0]],"id":70902601},{"spn":4.3,"spf":1.0,"id":70902601},{"atb":[[4.4,0]],"id":69685608},{"atb":[[4.6,0]],"id":49159417}],"con":true,"img":false}]}
{"op":"mcm","clk":"11540821918","pt":1719498755434,"mc":[{"id":"1.230178316","rc":[{"atl":[[30,1.51]],"id":46611436},{"spn":17.5,"spf":"NaN","id":46611436}],"con":true,"img":false}]}
{"op":"mcm","clk":"11540821933","pt":1719498755740,"mc":[{"id":"1.230178316","rc":[{"atl":[[34,1.66]],"id":52655636}],"con":true,"img":false}]}
{"op":"mcm","clk":"11540821952","pt":1719498756059,"mc":[{"id":"1.230178316","rc":[{"atl":[[27,1.68]],"id":70902601}],"con":true,"img":false}]}
{"op":"mcm","clk":"11540822022","pt":1719498756367,"mc":[{"id":"1.230178316","rc":[{"atl":[[34,1.64]],"id":57196226}],"con":true,"img":false}]}
{"op":"mcm","clk":"11540834493","pt":1719498909227,"mc":[{"id":"1.230178316","rc":[{"spn":18.77,"spf":"NaN","id":57196226},{"spn":19.5,"spf":"NaN","id":52655636},{"atb":[[3.7,1]],"id":49159417}],"con":true,"img":false}]}
{"op":"mcm","clk":"11540835178","pt":1719498917754,"mc":[{"id":"1.230178316","rc":[{"atb":[[3.7,1]],"id":57196226}],"con":true,"img":false}]}
{"op":"mcm","clk":"11540835958","pt":1719498926760,"mc":[{"id":"1.230178316","rc":[{"atb":[[3.7,1]],"id":52655636}],"con":true,"img":false}]}
{"op":"mcm","clk":"11540877522","pt":1719499451287,"mc":[{"id":"1.230178316","rc":[{"atl":[[190,4]],"id":57196226},{"spn":18.85,"spf":"NaN","id":57196226},{"atl":[[190,4]],"id":46611436},{"atl":[[190,4]],"id":52655636},{"atl":[[190,4]],"id":69685608},{"atl":[[190,4]],"id":49159417}],"con":true,"img":false}]}
{"op":"mcm","clk":"11540877531","pt":1719499451387,"mc":[{"id":"1.230178316","rc":[{"atl":[[190,4]],"id":70902601}],"con":true,"img":false}]}
{"op":"mcm","clk":"11540880588","pt":1719499490324,"mc":[{"id":"1.230178316","rc":[{"atb":[[1.02,2]],"id":69685608}],"con":true,"img":false}]}
{"op":"mcm","clk":"11540880602","pt":1719499490532,"mc":[{"id":"1.230178316","rc":[{"atb":[[1.02,2]],"id":49159417}],"con":true,"img":false}]}
{"op":"mcm","clk":"11540880628","pt":1719499490844,"mc":[{"id":"1.230178316","rc":[{"atb":[[3.75,2]],"id":57196226}],"con":true,"img":false}]}
{"op":"mcm","clk":"11540880672","pt":1719499491311,"mc":[{"id":"1.230178316","rc":[{"atb":[[1.02,2]],"id":70902601}],"con":true,"img":false}]}
{"op":"mcm","clk":"11540880696","pt":1719499491620,"mc":[{"id":"1.230178316","rc":[{"atb":[[1.02,2]],"id":52655636}],"con":true,"img":false}]}
{"op":"mcm","clk":"11540880729","pt":1719499491932,"mc":[{"id":"1.230178316","rc":[{"atb":[[1.02,2]],"id":46611436}],"con":true,"img":false}]}
{"op":"mcm","clk":"11540913363","pt":1719499891364,"mc":[{"id":"1.230178316","rc":[{"atl":[[32,0.84]],"id":57196226},{"spn":17.87,"spf":"NaN","id":57196226},{"atl":[[32,0.84]],"id":52655636},{"spn":18.5,"spf":"NaN","id":52655636},{"atl":[[26,0.84]],"id":70902601}],"con":true,"img":false}]}
{"op":"mcm","clk":"11540913374","pt":1719499891468,"mc":[{"id":"1.230178316","rc":[{"atl":[[29,0.84]],"id":46611436}],"con":true,"img":false}]}
{"op":"mcm","clk":"11540917726","pt":1719499944391,"mc":[{"id":"1.230178316","rc":[{"atb":[[3,13.19]],"id":49159417}],"con":true,"img":false}]}
{"op":"mcm","clk":"11540917769","pt":1719499944803,"mc":[{"id":"1.230178316","rc":[{"atb":[[3,0]],"id":49159417}],"con":true,"img":false}]}
{"op":"mcm","clk":"11540919323","pt":1719499966457,"mc":[{"id":"1.230178316","rc":[{"spn":17.0,"spf":"NaN","id":46611436},{"atb":[[5,2.02]],"id":52655636}],"con":true,"img":false}]}
{"op":"mcm","clk":"11540924523","pt":1719500035511,"mc":[{"id":"1.230178316","rc":[{"atb":[[1.12,1.69]],"id":69685608},{"atb":[[1.12,1.69]],"id":49159417}],"con":true,"img":false}]}
{"op":"mcm","clk":"11540924540","pt":1719500035718,"mc":[{"id":"1.230178316","rc":[{"atb":[[1.09,1.69]],"id":57196226}],"con":true,"img":false}]}
{"op":"mcm","clk":"11540924549","pt":1719500035820,"mc":[{"id":"1.230178316","rc":[{"atb":[[1.12,0.05]],"id":69685608}],"con":true,"img":false}]}
{"op":"mcm","clk":"11540924558","pt":1719500035922,"mc":[{"id":"1.230178316","rc":[{"atb":[[1.12,1.69]],"id":46611436}],"con":true,"img":false}]}
{"op":"mcm","clk":"11540924573","pt":1719500036128,"mc":[{"id":"1.230178316","rc":[{"atb":[[1.1,1.69]],"id":70902601}],"con":true,"img":false}]}
{"op":"mcm","clk":"11540924582","pt":1719500036230,"mc":[{"id":"1.230178316","rc":[{"atb":[[1.12,1.69]],"id":52655636}],"con":true,"img":false}]}
{"op":"mcm","clk":"11540924602","pt":1719500036435,"mc":[{"id":"1.230178316","rc":[{"atb":[[1.12,0.05]],"id":49159417}],"con":true,"img":false}]}
{"op":"mcm","clk":"11540924617","pt":1719500036698,"mc":[{"id":"1.230178316","rc":[{"atb":[[1.09,0.07]],"id":57196226},{"atb":[[1.12,0]],"id":69685608}],"con":true,"img":false}]}
{"op":"mcm","clk":"11540924622","pt":1719500036794,"mc":[{"id":"1.230178316","rc":[{"atb":[[5.1,0.05]],"id":69685608}],"con":true,"img":false}]}
{"op":"mcm","clk":"11540924640","pt":1719500037102,"mc":[{"id":"1.230178316","rc":[{"atb":[[1.12,0.05]],"id":46611436}],"con":true,"img":false}]}
{"op":"mcm","clk":"11540924649","pt":1719500037207,"mc":[{"id":"1.230178316","rc":[{"atb":[[1.12,0.05]],"id":52655636}],"con":true,"img":false}]}
{"op":"mcm","clk":"11540924659","pt":1719500037309,"mc":[{"id":"1.230178316","rc":[{"atb":[[1.12,0]],"id":49159417}],"con":true,"img":false}]}
{"op":"mcm","clk":"11540924669","pt":1719500037413,"mc":[{"id":"1.230178316","rc":[{"atb":[[5.1,0.05]],"id":49159417}],"con":true,"img":false}]}
{"op":"mcm","clk":"11540924684","pt":1719500037619,"mc":[{"id":"1.230178316","rc":[{"atb":[[1.09,0]],"id":57196226},{"atb":[[1.1,0.06]],"id":70902601}],"con":true,"img":false}]}
{"op":"mcm","clk":"11540924692","pt":1719500037722,"mc":[{"id":"1.230178316","rc":[{"atb":[[3.8,0.07]],"id":57196226}],"con":true,"img":false}]}
{"op":"mcm","clk":"11540924712","pt":1719500038031,"mc":[{"id":"1.230178316","rc":[{"atb":[[1.12,0]],"id":46611436}],"con":true,"img":false}]}
{"op":"mcm","clk":"11540924720","pt":1719500038134,"mc":[{"id":"1.230178316","rc":[{"atb":[[5.1,0.05]],"id":46611436}],"con":true,"img":false}]}
{"op":"mcm","clk":"11540924762","pt":1719500038598,"mc":[{"id":"1.230178316","rc":[{"atb":[[1.12,0]],"id":52655636}],"con":true,"img":false}]}
{"op":"mcm","clk":"11540924771","pt":1719500038699,"mc":[{"id":"1.230178316","rc":[{"atb":[[5.1,0.05]],"id":52655636}],"con":true,"img":false}]}
{"op":"mcm","clk":"11540924796","pt":1719500039064,"mc":[{"id":"1.230178316","rc":[{"atb":[[1.1,0]],"id":70902601}],"con":true,"img":false}]}
{"op":"mcm","clk":"11540924807","pt":1719500039115,"mc":[{"id":"1.230178316","rc":[{"atb":[[4.4,0.06]],"id":70902601}],"con":true,"img":false}]}
{"op":"mcm","clk":"11540924894","pt":1719500040200,"mc":[{"id":"1.230178316","rc":[{"atb":[[2.46,68.49]],"id":57196226},{"atl":[[32,2.84],[17.5,2]],"id":57196226},{"atb":[[3.1,17.34]],"id":70902601},{"atl":[[27,5.53]],"id":70902601}],"con":true,"img":false}]}
{"op":"mcm","clk":"11540924904","pt":1719500040321,"mc":[{"id":"1.230178316","rc":[{"atb":[[3.15,11.67]],"id":46611436},{"atl":[[30,4.96]],"id":46611436},{"atb":[[2.9,6.55]],"id":69685608},{"atl":[[30,3.45]],"id":69685608},{"atb":[[3.75,6]],"id":49159417},{"atl":[[30,3.45]],"id":49159417}],"con":true,"img":false}]}
{"op":"mcm","clk":"11540924915","pt":1719500040425,"mc":[{"id":"1.230178316","rc":[{"atb":[[4.3,6]],"id":52655636},{"atl":[[34,4.69]],"id":52655636}],"con":true,"img":false}]}
{"op":"mcm","clk":"11540924977","pt":1719500041099,"mc":[{"id":"1.230178316","rc":[{"atl":[[32,0.84]],"id":57196226}],"con":true,"img":false}]}
{"op":"mcm","clk":"11540925156","pt":1719500043317,"mc":[{"id":"1.230178316","rc":[{"atl":[[34,0]],"id":57196226}],"con":true,"img":false}]}
{"op":"mcm","clk":"11540925273","pt":1719500045017,"mc":[{"id":"1.230178316","rc":[{"atl":[[11.5,1]],"id":49159417}],"con":true,"img":false}]}
{"op":"mcm","clk":"11540925281","pt":1719500045121,"mc":[{"id":"1.230178316","rc":[{"atb":[[1.02,1.7]],"id":57196226},{"atl":[[1000,1.7]],"id":57196226},{"atb":[[1.02,3.7]],"id":69685608},{"atl":[[1000,1.93]],"id":69685608},{"atb":[[1.02,3.7]],"id":49159417},{"atl":[[1000,1.93]],"id":49159417}],"con":true,"img":false}]}
{"op":"mcm","clk":"11540925297","pt":1719500045327,"mc":[{"id":"1.230178316","rc":[{"atb":[[1.02,0.11]],"id":57196226},{"atl":[[1000,0.02]],"id":57196226},{"atb":[[1.02,2.16]],"id":69685608},{"atl":[[18.5,1],[1000,0.23]],"id":69685608},{"atb":[[1.02,2.11]],"id":49159417},{"atl":[[1000,0.23]],"id":49159417}],"con":true,"img":false}]}
{"op":"mcm","clk":"11540925313","pt":1719500045533,"mc":[{"id":"1.230178316","rc":[{"atb":[[1.02,0]],"id":57196226},{"atl":[[1000,0]],"id":57196226},{"atb":[[1.02,2]],"id":69685608},{"atl":[[1000,0.22]],"id":69685608},{"atb":[[1.02,2]],"id":49159417},{"atl":[[1000,0.22]],"id":49159417}],"con":true,"img":false}]}
{"op":"mcm","clk":"11540925323","pt":1719500045635,"mc":[{"id":"1.230178316","rc":[{"atb":[[3.8,0.18]],"id":57196226},{"atl":[[17,0.02]],"id":57196226},{"atb":[[2.92,0.16]],"id":69685608},{"atl":[[29,0.01]],"id":69685608},{"atb":[[3.8,0.11]],"id":49159417},{"atl":[[29,0.01]],"id":49159417}],"con":true,"img":false}]}
{"op":"mcm","clk":"11540925375","pt":1719500046209,"mc":[{"id":"1.230178316","rc":[{"atl":[[17,1.58]],"id":57196226}],"con":true,"img":false}]}
{"op":"mcm","clk":"11540925564","pt":1719500048522,"mc":[{"id":"1.230178316","rc":[{"atb":[[2.88,3.38]],"id":69685608},{"atb":[[2.88,3.38]],"id":49159417}],"con":true,"img":false}]}
{"op":"mcm","clk":"11540925585","pt":1719500048729,"mc":[{"id":"1.230178316","rc":[{"atb":[[2.92,3.32]],"id":69685608}],"con":true,"img":false}]}
{"op":"mcm","clk":"11540925710","pt":1719500050323,"mc":[{"id":"1.230178316","rc":[{"atb":[[3.65,2.5]],"id":69685608},{"atb":[[2.94,2]],"id":49159417}],"con":true,"img":false}]}
{"op":"mcm","clk":"11540925722","pt":1719500050426,"mc":[{"id":"1.230178316","rc":[{"atb":[[2.9,0],[3.65,5.89]],"id":69685608}],"con":true,"img":false}]}
{"op":"mcm","clk":"11540925739","pt":1719500050633,"mc":[{"id":"1.230178316","rc":[{"atb":[[3.65,3.39]],"id":69685608},{"atb":[[2.94,0]],"id":49159417}],"con":true,"img":false}]}
{"op":"mcm","clk":"11540925864","pt":1719500052126,"mc":[{"id":"1.230178316","rc":[{"atl":[[16.5,2]],"id":57196226}],"con":true,"img":false}]}
{"op":"mcm","clk":"11540925878","pt":1719500052229,"mc":[{"id":"1.230178316","rc":[{"atl":[[16.5,4],[17.5,0]],"id":57196226}],"con":true,"img":false}]}
{"op":"mcm","clk":"11540926126","pt":1719500055444,"mc":[{"id":"1.230178316","rc":[{"atl":[[17,0.02]],"id":57196226}],"con":true,"img":false}]}
{"op":"mcm","clk":"11540926281","pt":1719500057349,"mc":[{"id":"1.230178316","rc":[{"atl":[[16.5,2]],"id":57196226}],"con":true,"img":false}]}
{"op":"mcm","clk":"11540926291","pt":1719500057453,"mc":[{"id":"1.230178316","rc":[{"atl":[[16.5,0],[17.5,6.06]],"id":57196226},{"atl":[[11,1]],"id":46611436},{"atb":[[4.3,7]],"id":52655636},{"atl":[[14,1]],"id":52655636},{"atl":[[9.4,1]],"id":70902601}],"con":true,"img":false}]}
{"op":"mcm","clk":"11540926300","pt":1719500057556,"mc":[{"id":"1.230178316","rc":[{"atl":[[6.2,1]],"id":57196226},{"atl":[[11,1],[11.5,0]],"id":49159417}],"con":true,"img":false}]}
{"op":"mcm","clk":"11540926485","pt":1719500059718,"mc":[{"id":"1.230178316","rc":[{"atl":[[6,2]],"id":57196226}],"con":true,"img":false}]}
{"op":"mcm","clk":"11540926777","pt":1719500063469,"mc":[{"id":"1.230178316","rc":[{"atb":[[2.92,0.16]],"id":69685608}],"con":true,"img":false}]}
{"op":"mcm","clk":"11540926881","pt":1719500064962,"mc":[{"id":"1.230178316","rc":[{"atl":[[6,0]],"id":57196226}],"con":true,"img":false}]}
{"op":"mcm","clk":"11540927014","pt":1719500066731,"mc":[{"id":"1.230178316","rc":[{"atl":[[6,2]],"id":57196226}],"con":true,"img":false}]}
{"op":"mcm","clk":"11540927073","pt":1719500067452,"mc":[{"id":"1.230178316","rc":[{"atl":[[17.5,0],[6,4]],"id":57196226}],"con":true,"img":false}]}
{"op":"mcm","clk":"11540927321","pt":1719500070539,"mc":[{"id":"1.230178316","rc":[{"atb":[[1.04,1.7]],"id":57196226},{"atl":[[1000,1.7]],"id":57196226}],"con":true,"img":false}]}
{"op":"mcm","clk":"11540927339","pt":1719500070744,"mc":[{"id":"1.230178316","rc":[{"atb":[[1.04,0.07]],"id":57196226},{"atl":[[1000,0.04]],"id":57196226}],"con":true,"img":false}]}
{"op":"mcm","clk":"11540927358","pt":1719500070951,"mc":[{"id":"1.230178316","rc":[{"atb":[[1.04,0]],"id":57196226},{"atl":[[1000,0]],"id":57196226}],"con":true,"img":false}]}
{"op":"mcm","clk":"11540927370","pt":1719500071054,"mc":[{"id":"1.230178316","rc":[{"atb":[[3.8,0.26]],"id":57196226},{"atl":[[5.9,0.04]],"id":57196226}],"con":true,"img":false}]}
{"op":"mcm","clk":"11540927442","pt":1719500071938,"mc":[{"id":"1.230178316","rc":[{"atl":[[6,2]],"id":57196226}],"con":true,"img":false}]}
{"op":"mcm","clk":"11540927496","pt":1719500072548,"mc":[{"id":"1.230178316","rc":[{"atl":[[6.2,3.04],[6,0]],"id":57196226}],"con":true,"img":false}]}
{"op":"mcm","clk":"11540927510","pt":1719500072754,"mc":[{"id":"1.230178316","rc":[{"atl":[[16.5,3.08],[6.2,1]],"id":57196226}],"con":true,"img":false}]}
{"op":"mcm","clk":"11540927589","pt":1719500073950,"mc":[{"id":"1.230178316","rc":[{"atl":[[6,2]],"id":57196226}],"con":true,"img":false}]}
{"op":"mcm","clk":"11540927633","pt":1719500074568,"mc":[{"id":"1.230178316","rc":[{"atb":[[2.88,0]],"id":49159417}],"con":true,"img":false}]}
{"op":"mcm","clk":"11540927882","pt":1719500077355,"mc":[{"id":"1.230178316","rc":[{"atb":[[2.88,6.54]],"id":69685608}],"con":true,"img":false}]}
{"op":"mcm","clk":"11540928003","pt":1719500079153,"mc":[{"id":"1.230178316","rc":[{"atl":[[6,0]],"id":57196226}],"con":true,"img":false}]}
{"op":"mcm","clk":"11540928184","pt":1719500081645,"mc":[{"id":"1.230178316","rc":[{"atl":[[6,2]],"id":57196226}],"con":true,"img":false}]}
{"op":"mcm","clk":"11540928251","pt":1719500082572,"mc":[{"id":"1.230178316","rc":[{"atl":[[16.5,0],[6,4]],"id":57196226}],"con":true,"img":false}]}
{"op":"mcm","clk":"11540928313","pt":1719500083350,"mc":[{"id":"1.230178316","rc":[{"atb":[[3.8,0.07]],"id":57196226},{"atl":[[17,0],[5.9,0]],"id":57196226},{"atb":[[2.92,0]],"id":69685608},{"atl":[[29,0]],"id":69685608},{"atb":[[3.8,0]],"id":49159417},{"atl":[[29,0]],"id":49159417}],"con":true,"img":false}]}
{"op":"mcm","clk":"11540928625","pt":1719500086846,"mc":[{"id":"1.230178316","rc":[{"atl":[[6,2]],"id":57196226}],"con":true,"img":false}]}
{"op":"mcm","clk":"11540928645","pt":1719500087052,"mc":[{"id":"1.230178316","rc":[{"atl":[[16.5,6.45],[6,0]],"id":57196226}],"con":true,"img":false}]}
{"op":"mcm","clk":"11540928797","pt":1719500088858,"mc":[{"id":"1.230178316","rc":[{"atl":[[6,2]],"id":57196226}],"con":true,"img":false}]}
{"op":"mcm","clk":"11540928808","pt":1719500088959,"mc":[{"id":"1.230178316","rc":[{"atl":[[16.5,0],[6,4]],"id":57196226}],"con":true,"img":false}]}
{"op":"mcm","clk":"11540929211","pt":1719500094076,"mc":[{"id":"1.230178316","rc":[{"atl":[[6,2]],"id":57196226}],"con":true,"img":false}]}
{"op":"mcm","clk":"11540929223","pt":1719500094179,"mc":[{"id":"1.230178316","rc":[{"atl":[[16.5,6.45],[6,0]],"id":57196226}],"con":true,"img":false}]}
{"op":"mcm","clk":"11540929409","pt":1719500096596,"mc":[{"id":"1.230178316","rc":[{"atl":[[6,2]],"id":57196226},{"spn":4.9,"spf":"NaN","id":57196226},{"spn":8.05,"spf":"NaN","id":46611436},{"spn":9.55,"spf":"NaN","id":52655636},{"spn":4.3,"spf":1.0,"id":70902601},{"spn":11.8,"spf":"NaN","id":69685608},{"spn":8.05,"spf":"NaN","id":49159417}],"con":true,"img":false}]}
{"op":"mcm","clk":"11540929423","pt":1719500096762,"mc":[{"id":"1.230178316","rc":[{"atl":[[16.5,0],[6,4]],"id":57196226}],"con":true,"img":false}]}
{"op":"mcm","clk":"11540929435","pt":1719500096865,"mc":[{"id":"1.230178316","rc":[{"atl":[[16.5,6.45],[6,2]],"id":57196226}],"con":true,"img":false}]}
{"op":"mcm","clk":"11540929441","pt":1719500096969,"mc":[{"id":"1.230178316","rc":[{"atl":[[16.5,0],[6,4]],"id":57196226}],"con":true,"img":false}]}
{"op":"mcm","clk":"11540929854","pt":1719500101780,"mc":[{"id":"1.230178316","rc":[{"atl":[[6,2]],"id":57196226}],"con":true,"img":false}]}
{"op":"mcm","clk":"11540929881","pt":1719500102193,"mc":[{"id":"1.230178316","rc":[{"atl":[[16.5,6.45],[6,0]],"id":57196226}],"con":true,"img":false}]}
{"op":"mcm","clk":"11540930015","pt":1719500103799,"mc":[{"id":"1.230178316","rc":[{"atl":[[6,2]],"id":57196226}],"con":true,"img":false}]}
{"op":"mcm","clk":"11540930273","pt":1719500106568,"mc":[{"id":"1.230178316","rc":[{"atl":[[16.5,0],[6,4]],"id":57196226}],"con":true,"img":false}]}
{"op":"mcm","clk":"11540930528","pt":1719500109000,"mc":[{"id":"1.230178316","rc":[{"atl":[[6,2]],"id":57196226}],"con":true,"img":false}]}
{"op":"mcm","clk":"11540930715","pt":1719500111018,"mc":[{"id":"1.230178316","rc":[{"atl":[[5.9,2]],"id":57196226}],"con":true,"img":false}]}
{"op":"mcm","clk":"11540931064","pt":1719500116176,"mc":[{"id":"1.230178316","rc":[{"atl":[[5.9,0]],"id":57196226}],"con":true,"img":false}]}
{"op":"mcm","clk":"11540931078","pt":1719500116278,"mc":[{"id":"1.230178316","rc":[{"atl":[[16.5,6.45],[6,0]],"id":57196226}],"con":true,"img":false}]}
{"op":"mcm","clk":"11540931324","pt":1719500118911,"mc":[{"id":"1.230178316","rc":[{"atl":[[6,2]],"id":57196226}],"con":true,"img":false}]}
{"op":"mcm","clk":"11540931752","pt":1719500124095,"mc":[{"id":"1.230178316","rc":[{"atl":[[6,0]],"id":57196226}],"con":true,"img":false}]}
{"op":"mcm","clk":"11540931891","pt":1719500126105,"mc":[{"id":"1.230178316","rc":[{"atl":[[6,2]],"id":57196226}],"con":true,"img":false}]}
{"op":"mcm","clk":"11540931897","pt":1719500126208,"mc":[{"id":"1.230178316","rc":[{"atl":[[16.5,0],[6,4]],"id":57196226}],"con":true,"img":false}]}
{"op":"mcm","clk":"11540932378","pt":1719500131336,"mc":[{"id":"1.230178316","rc":[{"atl":[[6,2]],"id":57196226}],"con":true,"img":false}]}
{"op":"mcm","clk":"11540932391","pt":1719500131396,"mc":[{"id":"1.230178316","rc":[{"atl":[[17.5,6.06],[6,0]],"id":57196226}],"con":true,"img":false}]}
{"op":"mcm","clk":"11540932540","pt":1719500133194,"mc":[{"id":"1.230178316","rc":[{"atl":[[6,2]],"id":57196226}],"con":true,"img":false}]}
{"op":"mcm","clk":"11540932549","pt":1719500133299,"mc":[{"id":"1.230178316","rc":[{"atl":[[17.5,0],[6,4]],"id":57196226}],"con":true,"img":false}]}
{"op":"mcm","clk":"11540932560","pt":1719500133401,"mc":[{"id":"1.230178316","rc":[{"atl":[[6,2]],"id":57196226}],"con":true,"img":false}]}
{"op":"mcm","clk":"11540932572","pt":1719500133504,"mc":[{"id":"1.230178316","rc":[{"atl":[[17.5,6.06]],"id":57196226}],"con":true,"img":false}]}
{"op":"mcm","clk":"11540932935","pt":1719500138421,"mc":[{"id":"1.230178316","rc":[{"atl":[[6,0]],"id":57196226}],"con":true,"img":false}]}
{"op":"mcm","clk":"11540933148","pt":1719500140838,"mc":[{"id":"1.230178316","rc":[{"atl":[[6,2]],"id":57196226}],"con":true,"img":false}]}
{"op":"mcm","clk":"11540933303","pt":1719500142709,"mc":[{"id":"1.230178316","rc":[{"atl":[[17.5,0],[6,4]],"id":57196226}],"con":true,"img":false}]}
{"op":"mcm","clk":"11540933311","pt":1719500142808,"mc":[{"id":"1.230178316","rc":[{"atl":[[17.5,6.06],[6,2]],"id":57196226}],"con":true,"img":false}]}
{"op":"mcm","clk":"11540933321","pt":1719500142913,"mc":[{"id":"1.230178316","rc":[{"atl":[[17.5,0],[6,4]],"id":57196226}],"con":true,"img":false}]}
{"op":"mcm","clk":"11540933329","pt":1719500143015,"mc":[{"id":"1.230178316","rc":[{"atl":[[17.5,6.06],[6,2]],"id":57196226}],"con":true,"img":false}]}
{"op":"mcm","clk":"11540933338","pt":1719500143118,"mc":[{"id":"1.230178316","rc":[{"atl":[[17.5,0],[6,4]],"id":57196226}],"con":true,"img":false}]}
{"op":"mcm","clk":"11540933529","pt":1719500145646,"mc":[{"id":"1.230178316","rc":[{"atb":[[3.8,0.92]],"id":57196226},{"atl":[[5.9,0.84]],"id":57196226},{"atb":[[5.1,0.9]],"id":52655636}],"con":true,"img":false}]}
{"op":"mcm","clk":"11540933566","pt":1719500146007,"mc":[{"id":"1.230178316","rc":[{"atl":[[6,2]],"id":57196226}],"con":true,"img":false}]}
{"op":"mcm","clk":"11540933718","pt":1719500147919,"mc":[{"id":"1.230178316","rc":[{"atl":[[5.9,2.84]],"id":57196226}],"con":true,"img":false}]}
{"op":"mcm","clk":"11540934150","pt":1719500153130,"mc":[{"id":"1.230178316","rc":[{"atl":[[5.9,0.84]],"id":57196226}],"con":true,"img":false}]}
{"op":"mcm","clk":"11540934160","pt":1719500153233,"mc":[{"id":"1.230178316","rc":[{"atl":[[6.2,3.85],[6,0]],"id":57196226}],"con":true,"img":false}]}
{"op":"mcm","clk":"11540934189","pt":1719500153645,"mc":[{"id":"1.230178316","rc":[{"atl":[[6,0.84],[5.9,0]],"id":57196226}],"con":true,"img":false}]}
{"op":"mcm","clk":"11540934297","pt":1719500155143,"mc":[{"id":"1.230178316","rc":[{"atl":[[6,2.84]],"id":57196226}],"con":true,"img":false}]}
{"op":"mcm","clk":"11540934564","pt":1719500158746,"mc":[{"id":"1.230178316","rc":[{"atb":[[5.1,0]],"id":69685608},{"spn":11.75,"spf":"NaN","id":69685608}],"con":true,"img":false}]}
{"op":"mcm","clk":"11540934572","pt":1719500158849,"mc":[{"id":"1.230178316","rc":[{"atb":[[2.9,6.55],[3.65,0]],"id":69685608}],"con":true,"img":false}]}
{"op":"mcm","clk":"11540934586","pt":1719500159056,"mc":[{"id":"1.230178316","rc":[{"atb":[[5.1,0]],"id":49159417}],"con":true,"img":false}]}
{"op":"mcm","clk":"11540934595","pt":1719500159159,"mc":[{"id":"1.230178316","rc":[{"atb":[[3.8,0.84]],"id":57196226}],"con":true,"img":false}]}
{"op":"mcm","clk":"11540934616","pt":1719500159468,"mc":[{"id":"1.230178316","rc":[{"atb":[[4.4,0]],"id":70902601}],"con":true,"img":false}]}
{"op":"mcm","clk":"11540934625","pt":1719500159527,"mc":[{"id":"1.230178316","rc":[{"atb":[[5.1,0.84]],"id":52655636}],"con":true,"img":false}]}
{"op":"mcm","clk":"11540934639","pt":1719500159727,"mc":[{"id":"1.230178316","rc":[{"atb":[[5.1,0]],"id":46611436}],"con":true,"img":false}]}
{"op":"mcm","clk":"11540934656","pt":1719500159934,"mc":[{"id":"1.230178316","rc":[{"atb":[[1.09,1.69]],"id":57196226},{"atb":[[1.12,1.69]],"id":49159417}],"con":true,"img":false}]}
{"op":"mcm","clk":"11540934682","pt":1719500160243,"mc":[{"id":"1.230178316","rc":[{"atb":[[1.1,1.69]],"id":70902601},{"atb":[[1.12,0.05]],"id":49159417}],"con":true,"img":false}]}
{"op":"mcm","clk":"11540934693","pt":1719500160348,"mc":[{"id":"1.230178316","rc":[{"atl":[[6,0.84]],"id":57196226}],"con":true,"img":false}]}
{"op":"mcm","clk":"11540934701","pt":1719500160450,"mc":[{"id":"1.230178316","rc":[{"atl":[[17.5,6.06],[6.2,1]],"id":57196226}],"con":true,"img":false}]}
{"op":"mcm","clk":"11540934709","pt":1719500160554,"mc":[{"id":"1.230178316","rc":[{"atb":[[1.09,0.07]],"id":57196226},{"atb":[[1.12,1.69]],"id":69685608}],"con":true,"img":false}]}
{"op":"mcm","clk":"11540934737","pt":1719500160864,"mc":[{"id":"1.230178316","rc":[{"atb":[[1.12,1.69]],"id":52655636}],"con":true,"img":false}]}
{"op":"mcm","clk":"11540934761","pt":1719500161072,"mc":[{"id":"1.230178316","rc":[{"atb":[[1.12,0]],"id":49159417}],"con":true,"img":false}]}
{"op":"mcm","clk":"11540934771","pt":1719500161126,"mc":[{"id":"1.230178316","rc":[{"atb":[[5.1,0.05]],"id":49159417}],"con":true,"img":false}]}
{"op":"mcm","clk":"11540934787","pt":1719500161332,"mc":[{"id":"1.230178316","rc":[{"atb":[[1.1,0.06]],"id":70902601}],"con":true,"img":false}]}
{"op":"mcm","clk":"11540934811","pt":1719500161640,"mc":[{"id":"1.230178316","rc":[{"atb":[[1.09,0]],"id":57196226}],"con":true,"img":false}]}
{"op":"mcm","clk":"11540934822","pt":1719500161746,"mc":[{"id":"1.230178316","rc":[{"atb":[[3.8,0.92]],"id":57196226}],"con":true,"img":false}]}
{"op":"mcm","clk":"11540934845","pt":1719500162056,"mc":[{"id":"1.230178316","rc":[{"atb":[[1.12,0.05]],"id":69685608}],"con":true,"img":false}]}
{"op":"mcm","clk":"11540934868","pt":1719500162366,"mc":[{"id":"1.230178316","rc":[{"atb":[[1.1,0]],"id":70902601}],"con":true,"img":false}]}
{"op":"mcm","clk":"11540934875","pt":1719500162420,"mc":[{"id":"1.230178316","rc":[{"atb":[[4.4,0.06]],"id":70902601}],"con":true,"img":false}]}
{"op":"mcm","clk":"11540934889","pt":1719500162628,"mc":[{"id":"1.230178316","rc":[{"atl":[[6,2.84]],"id":57196226},{"atb":[[1.12,0.05]],"id":52655636}],"con":true,"img":false}]}
{"op":"mcm","clk":"11540934908","pt":1719500162939,"mc":[{"id":"1.230178316","rc":[{"atb":[[1.12,0]],"id":69685608}],"con":true,"img":false}]}
{"op":"mcm","clk":"11540934918","pt":1719500163041,"mc":[{"id":"1.230178316","rc":[{"atb":[[5.1,0.05]],"id":69685608}],"con":true,"img":false}]}
{"op":"mcm","clk":"11540934939","pt":1719500163353,"mc":[{"id":"1.230178316","rc":[{"atb":[[1.12,0]],"id":52655636}],"con":true,"img":false}]}
{"op":"mcm","clk":"11540934948","pt":1719500163459,"mc":[{"id":"1.230178316","rc":[{"atb":[[5.1,0.9]],"id":52655636}],"con":true,"img":false}]}
{"op":"mcm","clk":"11540935235","pt":1719500166772,"mc":[{"id":"1.230178316","rc":[{"atb":[[2.88,3.38]],"id":69685608}],"con":true,"img":false}]}
{"op":"mcm","clk":"11540935256","pt":1719500166940,"mc":[{"id":"1.230178316","rc":[{"atb":[[2.92,3.15]],"id":69685608}],"con":true,"img":false}]}
{"op":"mcm","clk":"11540935325","pt":1719500167770,"mc":[{"id":"1.230178316","rc":[{"atl":[[6,0.84]],"id":57196226}],"con":true,"img":false}]}
{"op":"mcm","clk":"11540935343","pt":1719500167981,"mc":[{"id":"1.230178316","rc":[{"atb":[[4.6,1]],"id":69685608}],"con":true,"img":false}]}
{"op":"mcm","clk":"11540935354","pt":1719500168036,"mc":[{"id":"1.230178316","rc":[{"atb":[[2.9,0],[4.7,3.16]],"id":69685608}],"con":true,"img":false}]}
{"op":"mcm","clk":"11540935365","pt":1719500168146,"mc":[{"id":"1.230178316","rc":[{"atb":[[4.6,4.16]],"id":69685608}],"con":true,"img":false}]}
{"op":"mcm","clk":"11540935376","pt":1719500168248,"mc":[{"id":"1.230178316","rc":[{"atb":[[4.7,0]],"id":69685608}],"con":true,"img":false}]}
{"op":"mcm","clk":"11540935411","pt":1719500168659,"mc":[{"id":"1.230178316","rc":[{"atb":[[1.12,1.69]],"id":46611436}],"con":true,"img":false}]}
{"op":"mcm","clk":"11540935553","pt":1719500169855,"mc":[{"id":"1.230178316","rc":[{"atl":[[6,2.84]],"id":57196226}],"con":true,"img":false}]}
{"op":"mcm","clk":"11540935577","pt":1719500170061,"mc":[{"id":"1.230178316","rc":[{"atl":[[17.5,0],[6,5.69]],"id":57196226}],"con":true,"img":false}]}
{"op":"mcm","clk":"11540935587","pt":1719500170165,"mc":[{"id":"1.230178316","rc":[{"atl":[[17.5,6.06],[6,2.84]],"id":57196226}],"con":true,"img":false}]}
{"op":"mcm","clk":"11540935600","pt":1719500170268,"mc":[{"id":"1.230178316","rc":[{"atl":[[6,4.84]],"id":57196226}],"con":true,"img":false}]}
{"op":"mcm","clk":"11540935611","pt":1719500170372,"mc":[{"id":"1.230178316","rc":[{"atl":[[17.5,0]],"id":57196226},{"atb":[[1.12,0.05]],"id":46611436}],"con":true,"img":false}]}
{"op":"mcm","clk":"11540935689","pt":1719500171251,"mc":[{"id":"1.230178316","rc":[{"atb":[[1.12,0]],"id":46611436}],"con":true,"img":false}]}
{"op":"mcm","clk":"11540935698","pt":1719500171354,"mc":[{"id":"1.230178316","rc":[{"atb":[[5.1,0.05]],"id":46611436}],"con":true,"img":false}]}
{"op":"mcm","clk":"11540935804","pt":1719500172552,"mc":[{"id":"1.230178316","rc":[{"atl":[[1000,1.7]],"id":57196226},{"atl":[[1000,1.93]],"id":69685608},{"atb":[[1.03,1.7]],"id":49159417},{"atl":[[1000,1.93]],"id":49159417}],"con":true,"img":false}]}
{"op":"mcm","clk":"11540935814","pt":1719500172653,"mc":[{"id":"1.230178316","rc":[{"atb":[[1.04,1.7]],"id":57196226},{"atb":[[1.03,1.7]],"id":69685608}],"con":true,"img":false}]}
{"op":"mcm","clk":"11540935821","pt":1719500172756,"mc":[{"id":"1.230178316","rc":[{"atb":[[1.04,0.06]],"id":57196226},{"atl":[[1000,0.03]],"id":57196226},{"atb":[[1.03,0.08]],"id":69685608},{"atl":[[1000,0.23]],"id":69685608},{"atb":[[1.03,0.1]],"id":49159417},{"atl":[[1000,0.23]],"id":49159417}],"con":true,"img":false}]}
{"op":"mcm","clk":"11540935833","pt":1719500172859,"mc":[{"id":"1.230178316","rc":[{"atl":[[1000,0]],"id":57196226},{"atb":[[1.03,0]],"id":69685608},{"atl":[[1000,0.22]],"id":69685608},{"atb":[[1.03,0]],"id":49159417},{"atl":[[1000,0.22]],"id":49159417}],"con":true,"img":false}]}
{"op":"mcm","clk":"11540935838","pt":1719500172964,"mc":[{"id":"1.230178316","rc":[{"atb":[[1.04,0]],"id":57196226},{"atl":[[5.9,0.03]],"id":57196226},{"atb":[[4.7,0.08]],"id":69685608},{"atl":[[29,0.01]],"id":69685608},{"atb":[[3.8,0.1]],"id":49159417},{"atl":[[29,0.01]],"id":49159417}],"con":true,"img":false}]}
{"op":"mcm","clk":"11540935849","pt":1719500173067,"mc":[{"id":"1.230178316","rc":[{"atb":[[3.8,0.99]],"id":57196226}],"con":true,"img":false}]}
{"op":"mcm","clk":"11540936014","pt":1719500175036,"mc":[{"id":"1.230178316","rc":[{"atl":[[6,2.84]],"id":57196226}],"con":true,"img":false}]}
{"op":"mcm","clk":"11540936024","pt":1719500175141,"mc":[{"id":"1.230178316","rc":[{"atl":[[6.2,3.89],[6,0.84]],"id":57196226}],"con":true,"img":false}]}
{"op":"mcm","clk":"11540936070","pt":1719500175658,"mc":[{"id":"1.230178316","rc":[{"atb":[[4.6,3.16]],"id":69685608}],"con":true,"img":false}]}
{"op":"mcm","clk":"11540936151","pt":1719500176643,"mc":[{"id":"1.230178316","rc":[{"atb":[[4.6,4.16]],"id":69685608}],"con":true,"img":false}]}
{"op":"mcm","clk":"11540936171","pt":1719500176952,"mc":[{"id":"1.230178316","rc":[{"atl":[[6,2.84]],"id":57196226}],"con":true,"img":false}]}
{"op":"mcm","clk":"11540936466","pt":1719500180684,"mc":[{"id":"1.230178316","rc":[{"atb":[[2.88,0]],"id":69685608}],"con":true,"img":false}]}
{"op":"mcm","clk":"11540936569","pt":1719500182087,"mc":[{"id":"1.230178316","rc":[{"atl":[[6,0.84]],"id":57196226}],"con":true,"img":false}]}
{"op":"mcm","clk":"11540936684","pt":1719500183496,"mc":[{"id":"1.230178316","rc":[{"atb":[[4.6,3.16]],"id":69685608}],"con":true,"img":false}]}
{"op":"mcm","clk":"11540936782","pt":1719500184588,"mc":[{"id":"1.230178316","rc":[{"atl":[[6,2.84]],"id":57196226}],"con":true,"img":false}]}
{"op":"mcm","clk":"11540936816","pt":1719500185002,"mc":[{"id":"1.230178316","rc":[{"atb":[[2.92,0]],"id":69685608}],"con":true,"img":false}]}
{"op":"mcm","clk":"11540936984","pt":1719500186668,"mc":[{"id":"1.230178316","rc":[{"atb":[[4.6,4.16]],"id":69685608}],"con":true,"img":false}]}
{"op":"mcm","clk":"11540937228","pt":1719500189773,"mc":[{"id":"1.230178316","rc":[{"atl":[[6,0.84]],"id":57196226}],"con":true,"img":false}]}
{"op":"mcm","clk":"11540937286","pt":1719500190499,"mc":[{"id":"1.230178316","rc":[{"atb":[[4.6,3.16]],"id":69685608}],"con":true,"img":false}]}
{"op":"mcm","clk":"11540937322","pt":1719500190915,"mc":[{"id":"1.230178316","rc":[{"atb":[[4.6,4.16]],"id":69685608}],"con":true,"img":false}]}
{"op":"mcm","clk":"11540937386","pt":1719500191693,"mc":[{"id":"1.230178316","rc":[{"atl":[[32,0],[6,2.84]],"id":57196226},{"atl":[[29,0]],"id":46611436},{"atl":[[32,0]],"id":52655636},{"atl":[[26,0]],"id":70902601},{"atl":[[18,0.84]],"id":69685608}],"con":true,"img":false}]}
{"op":"mcm","clk":"11540937419","pt":1719500192211,"mc":[{"id":"1.230178316","rc":[{"atl":[[18,1.69]],"id":69685608}],"con":true,"img":false}]}
{"op":"mcm","clk":"11540937428","pt":1719500192315,"mc":[{"id":"1.230178316","rc":[{"atl":[[23,3.45],[30,0]],"id":69685608}],"con":true,"img":false}]}
{"op":"mcm","clk":"11540937479","pt":1719500193005,"mc":[{"id":"1.230178316","rc":[{"atb":[[2.5,4]],"id":57196226},{"atb":[[3.75,2.66]],"id":46611436},{"atb":[[4.3,9.32]],"id":52655636},{"atb":[[3.25,3.07]],"id":70902601},{"atb":[[5.5,1.81]],"id":69685608},{"atb":[[4,2.5]],"id":49159417}],"con":true,"img":false}]}
{"op":"mcm","clk":"11540937493","pt":1719500193201,"mc":[{"id":"1.230178316","rc":[{"atb":[[3.8,6],[3.15,0]],"id":46611436},{"atb":[[3.75,0],[4,5]],"id":49159417}],"con":true,"img":false}]}
{"op":"mcm","clk":"11540937531","pt":1719500193669,"mc":[{"id":"1.230178316","rc":[{"atb":[[5.6,0.84]],"id":69685608}],"con":true,"img":false}]}
{"op":"mcm","clk":"11540937828","pt":1719500196888,"mc":[{"id":"1.230178316","rc":[{"atl":[[6,0.84]],"id":57196226}],"con":true,"img":false}]}
{"op":"mcm","clk":"11540937902","pt":1719500197875,"mc":[{"id":"1.230178316","rc":[{"atb":[[4.6,3.16]],"id":69685608}],"con":true,"img":false}]}
{"op":"mcm","clk":"11540937959","pt":1719500198399,"mc":[{"id":"1.230178316","rc":[{"atb":[[4.6,4.16]],"id":69685608}],"con":true,"img":false}]}
{"op":"mcm","clk":"11540937991","pt":1719500198707,"mc":[{"id":"1.230178316","rc":[{"atb":[[4.6,3.16]],"id":69685608}],"con":true,"img":false}]}
{"op":"mcm","clk":"11540938007","pt":1719500198912,"mc":[{"id":"1.230178316","rc":[{"atl":[[6,2.84]],"id":57196226}],"con":true,"img":false}]}
{"op":"mcm","clk":"11540938116","pt":1719500200101,"mc":[{"id":"1.230178316","rc":[{"atb":[[4.6,4.16]],"id":69685608}],"con":true,"img":false}]}
{"op":"mcm","clk":"11540938185","pt":1719500200880,"mc":[{"id":"1.230178316","rc":[{"atb":[[4.6,3.16]],"id":69685608}],"con":true,"img":false}]}
{"op":"mcm","clk":"11540938339","pt":1719500202891,"mc":[{"id":"1.230178316","rc":[{"atb":[[4.6,4.16]],"id":69685608}],"con":true,"img":false}]}
{"op":"mcm","clk":"11540938353","pt":1719500203097,"mc":[{"id":"1.230178316","rc":[{"atb":[[2.88,3.15]],"id":69685608}],"con":true,"img":false}]}
{"op":"mcm","clk":"11540938361","pt":1719500203200,"mc":[{"id":"1.230178316","rc":[{"atb":[[4.6,3.16]],"id":69685608}],"con":true,"img":false}]}
{"op":"mcm","clk":"11540938441","pt":1719500204083,"mc":[{"id":"1.230178316","rc":[{"atl":[[6,0.84]],"id":57196226}],"con":true,"img":false}]}
{"op":"mcm","clk":"11540938506","pt":1719500205010,"mc":[{"id":"1.230178316","rc":[{"atb":[[4.6,4.16]],"id":69685608}],"con":true,"img":false}]}
{"op":"mcm","clk":"11540938527","pt":1719500205321,"mc":[{"id":"1.230178316","rc":[{"atb":[[4.6,3.16]],"id":69685608}],"con":true,"img":false}]}
{"op":"mcm","clk":"11540938552","pt":1719500205785,"mc":[{"id":"1.230178316","rc":[{"atb":[[4.6,4.16]],"id":69685608}],"con":true,"img":false}]}
{"op":"mcm","clk":"11540938562","pt":1719500205990,"mc":[{"id":"1.230178316","rc":[{"atb":[[4.6,3.16]],"id":69685608}],"con":true,"img":false}]}
{"op":"mcm","clk":"11540938603","pt":1719500206508,"mc":[{"id":"1.230178316","rc":[{"atl":[[6,2.84]],"id":57196226}],"con":true,"img":false}]}
{"op":"mcm","clk":"11540938906","pt":1719500210810,"mc":[{"id":"1.230178316","rc":[{"atb":[[3.8,0.92]],"id":57196226},{"atl":[[5.9,0]],"id":57196226},{"atb":[[4.7,0]],"id":69685608},{"atl":[[29,0]],"id":69685608},{"atb":[[3.8,0]],"id":49159417},{"atl":[[29,0]],"id":49159417}],"con":true,"img":false}]}
{"op":"mcm","clk":"11540938982","pt":1719500211699,"mc":[{"id":"1.230178316","rc":[{"atl":[[6,0.84]],"id":57196226}],"con":true,"img":false}]}
{"op":"mcm","clk":"11540939000","pt":1719500211899,"mc":[{"id":"1.230178316","rc":[{"atl":[[18,5.88],[6.2,1]],"id":57196226}],"con":true,"img":false}]}
{"op":"mcm","clk":"11540939133","pt":1719500213615,"mc":[{"id":"1.230178316","rc":[{"atl":[[6,2.84]],"id":57196226}],"con":true,"img":false}]}
{"op":"mcm","clk":"11540939495","pt":1719500218324,"mc":[{"id":"1.230178316","rc":[{"atb":[[5.1,0],[5,0]],"id":46611436},{"atl":[[5,1.94]],"id":46611436},{"trd":[[5,2],[5.1,0.11]],"ltp":5.0,"tv":2.11,"id":46611436}],"con":true,"img":false}]}
{"op":"mcm","clk":"11540939502","pt":1719500218429,"mc":[{"id":"1.230178316","rc":[{"atl":[[6.2,0]],"id":57196226},{"atb":[[3.8,0],[3.75,14.66]],"id":46611436},{"atl":[[16,6.67],[5,1.68],[10.5,1],[11,0],[30,1.51]],"id":46611436},{"trd":[[5,2.52]],"ltp":5.0,"tv":2.52,"id":46611436},{"atl":[[12.5,1],[14,0]],"id":52655636},{"atl":[[9.4,0]],"id":70902601}],"con":true,"img":false}]}
{"op":"mcm","clk":"11540939512","pt":1719500218533,"mc":[{"id":"1.230178316","rc":[{"atb":[[3.75,2.66]],"id":46611436},{"atl":[[9.2,1]],"id":70902601}],"con":true,"img":false}]}
{"op":"mcm","clk":"11540939522","pt":1719500218638,"mc":[{"id":"1.230178316","rc":[{"atb":[[3.85,0.84],[3.15,11.67]],"id":46611436},{"atl":[[26,0.97]],"id":70902601}],"con":true,"img":false}]}
{"op":"mcm","clk":"11540939530","pt":1719500218740,"mc":[{"id":"1.230178316","rc":[{"atb":[[3.8,0.84]],"id":57196226},{"atb":[[5.1,0.84]],"id":52655636},{"atb":[[4.4,0]],"id":70902601},{"atb":[[5.1,0]],"id":69685608},{"atb":[[5.1,0]],"id":49159417}],"con":true,"img":false}]}
{"op":"mcm","clk":"11540939538","pt":1719500218846,"mc":[{"id":"1.230178316","rc":[{"atl":[[6,0.84]],"id":57196226},{"atb":[[3.15,0],[3.75,8.66]],"id":46611436},{"spn":4.42,"spf":"NaN","id":46611436},{"spn":8.8,"spf":"NaN","id":52655636},{"spn":4.3,"spf":1.0,"id":70902601},{"spn":11.8,"spf":"NaN","id":69685608},{"spn":8.0,"spf":"NaN","id":49159417}],"con":true,"img":false}]}
{"op":"mcm","clk":"11540939557","pt":1719500219154,"mc":[{"id":"1.230178316","rc":[{"atl":[[17.5,0.84],[6,0]],"id":57196226},{"atb":[[3.85,0]],"id":46611436}],"con":true,"img":false}]}
{"op":"mcm","clk":"11540939567","pt":1719500219206,"mc":[{"id":"1.230178316","rc":[{"atl":[[26,0]],"id":70902601}],"con":true,"img":false}]}
{"op":"mcm","clk":"11540939574","pt":1719500219362,"mc":[{"id":"1.230178316","rc":[{"atb":[[3.75,1]],"id":49159417}],"con":true,"img":false}]}
{"op":"mcm","clk":"11540939581","pt":1719500219415,"mc":[{"id":"1.230178316","rc":[{"atb":[[3.8,6.34]],"id":46611436}],"con":true,"img":false}]}
{"op":"mcm","clk":"11540939604","pt":1719500219725,"mc":[{"id":"1.230178316","rc":[{"atl":[[5,0]],"id":46611436},{"trd":[[5,5.88]],"ltp":5.0,"tv":5.88,"id":46611436}],"con":true,"img":false}]}
{"op":"mcm","clk":"11540939612","pt":1719500219826,"mc":[{"id":"1.230178316","rc":[{"atl":[[6.2,1]],"id":57196226},{"atb":[[3.65,1]],"id":46611436},{"atl":[[16,0],[10.5,0],[11,1],[29,3.57]],"id":46611436},{"atl":[[12.5,0],[14,1]],"id":52655636},{"atb":[[3.15,1]],"id":70902601},{"atl":[[9.2,0],[9.4,1]],"id":70902601}],"con":true,"img":false}]}
{"op":"mcm","clk":"11540939630","pt":1719500220033,"mc":[{"id":"1.230178316","rc":[{"atl":[[16,3.57],[29,0]],"id":46611436}],"con":true,"img":false}]}
{"op":"mcm","clk":"11540939647","pt":1719500220240,"mc":[{"id":"1.230178316","rc":[{"atl":[[16,0],[29,3.57]],"id":46611436}],"con":true,"img":false}]}
{"op":"mcm","clk":"11540939686","pt":1719500220706,"mc":[{"id":"1.230178316","rc":[{"atl":[[6,2]],"id":57196226}],"con":true,"img":false}]}
{"op":"mcm","clk":"11540939704","pt":1719500220914,"mc":[{"id":"1.230178316","rc":[{"atl":[[18,0],[6,4]],"id":57196226}],"con":true,"img":false}]}
{"op":"mcm","clk":"11540939729","pt":1719500221224,"mc":[{"id":"1.230178316","rc":[{"atl":[[17.5,0]],"id":57196226},{"atb":[[4.5,1]],"id":46611436}],"con":true,"img":false}]}
{"op":"mcm","clk":"11540939752","pt":1719500221535,"mc":[{"id":"1.230178316","rc":[{"atb":[[3.8,0]],"id":46611436}],"con":true,"img":false}]}
{"op":"mcm","clk":"11540940036","pt":1719500225927,"mc":[{"id":"1.230178316","rc":[{"atl":[[6,2]],"id":57196226}],"con":true,"img":false}]}
{"op":"mcm","clk":"11540940051","pt":1719500226132,"mc":[{"id":"1.230178316","rc":[{"atl":[[18,5.88],[6,0]],"id":57196226}],"con":true,"img":false}]}
{"op":"mcm","clk":"11540940199","pt":1719500228346,"mc":[{"id":"1.230178316","rc":[{"atl":[[6,2]],"id":57196226}],"con":true,"img":false}]}
{"op":"mcm","clk":"11540940235","pt":1719500228656,"mc":[{"id":"1.230178316","rc":[{"atl":[[5.9,0.84]],"id":57196226}],"con":true,"img":false}]}
{"op":"mcm","clk":"11540940292","pt":1719500229224,"mc":[{"id":"1.230178316","rc":[{"atl":[[18,0],[6,4]],"id":57196226}],"con":true,"img":false}]}
{"op":"mcm","clk":"11540940297","pt":1719500229326,"mc":[{"id":"1.230178316","rc":[{"atl":[[6.2,6.88],[6,2]],"id":57196226}],"con":true,"img":false}]}
{"op":"mcm","clk":"11540940317","pt":1719500229637,"mc":[{"id":"1.230178316","rc":[{"atl":[[5.9,5.14]],"id":57196226}],"con":true,"img":false}]}
{"op":"mcm","clk":"11540940329","pt":1719500229739,"mc":[{"id":"1.230178316","rc":[{"atl":[[5.8,5.15],[6.2,1]],"id":57196226}],"con":true,"img":false}]}
{"op":"mcm","clk":"11540940359","pt":1719500230154,"mc":[{"id":"1.230178316","rc":[{"atl":[[6,0]],"id":57196226}],"con":true,"img":false}]}
{"op":"mcm","clk":"11540940366","pt":1719500230257,"mc":[{"id":"1.230178316","rc":[{"atl":[[5.9,0.84]],"id":57196226}],"con":true,"img":false}]}
{"op":"mcm","clk":"11540940552","pt":1719500232628,"mc":[{"id":"1.230178316","rc":[{"atl":[[6,3]],"id":46611436}],"con":true,"img":false}]}
{"op":"mcm","clk":"11540940561","pt":1719500232730,"mc":[{"id":"1.230178316","rc":[{"atl":[[16,4],[29,0]],"id":46611436}],"con":true,"img":false}]}
{"op":"mcm","clk":"11540940586","pt":1719500233143,"mc":[{"id":"1.230178316","rc":[{"atl":[[5.9,0.84]],"id":46611436}],"con":true,"img":false}]}
{"op":"mcm","clk":"11540940628","pt":1719500233713,"mc":[{"id":"1.230178316","rc":[{"atl":[[30,0]],"id":46611436}],"con":true,"img":false}]}
{"op":"mcm","clk":"11540940706","pt":1719500234846,"mc":[{"id":"1.230178316","rc":[{"atl":[[5.8,0],[6.2,9]],"id":57196226}],"con":true,"img":false}]}
{"op":"mcm","clk":"11540940720","pt":1719500235053,"mc":[{"id":"1.230178316","rc":[{"atl":[[18,5.88],[6.2,1]],"id":57196226}],"con":true,"img":false}]}
{"op":"mcm","clk":"11540940726","pt":1719500235157,"mc":[{"id":"1.230178316","rc":[{"atl":[[5.9,0]],"id":57196226}],"con":true,"img":false}]}
{"op":"mcm","clk":"11540940745","pt":1719500235417,"mc":[{"id":"1.230178316","rc":[{"atl":[[6,2]],"id":57196226}],"con":true,"img":false}]}
{"op":"mcm","clk":"11540940756","pt":1719500235621,"mc":[{"id":"1.230178316","rc":[{"atl":[[5.9,0.84]],"id":57196226}],"con":true,"img":false}]}
{"op":"mcm","clk":"11540940875","pt":1719500237528,"mc":[{"id":"1.230178316","rc":[{"atl":[[5.9,0]],"id":46611436},{"trd":[[5.9,1.69]],"ltp":5.9,"tv":1.69,"id":46611436}],"con":true,"img":false}]}
{"op":"mcm","clk":"11540940929","pt":1719500238353,"mc":[{"id":"1.230178316","rc":[{"atl":[[1000,1.07]],"id":69685608},{"atb":[[5.1,1.65]],"id":49159417}],"con":true,"img":false}]}
{"op":"mcm","clk":"11540940945","pt":1719500238660,"mc":[{"id":"1.230178316","rc":[{"atb":[[5.2,1.62]],"id":52655636},{"atb":[[4.4,1.92]],"id":70902601}],"con":true,"img":false}]}
{"op":"mcm","clk":"11540940963","pt":1719500239021,"mc":[{"id":"1.230178316","rc":[{"atb":[[5.2,0]],"id":52655636},{"atl":[[1000,0.71]],"id":69685608}],"con":true,"img":false}]}
{"op":"mcm","clk":"11540940972","pt":1719500239226,"mc":[{"id":"1.230178316","rc":[{"atb":[[4.5,0.84]],"id":70902601}],"con":true,"img":false}]}
{"op":"mcm","clk":"11540940976","pt":1719500239329,"mc":[{"id":"1.230178316","rc":[{"atb":[[5.1,2.47]],"id":52655636}],"con":true,"img":false}]}
{"op":"mcm","clk":"11540940983","pt":1719500239432,"mc":[{"id":"1.230178316","rc":[{"atl":[[1000,0.22]],"id":69685608}],"con":true,"img":false}]}
{"op":"mcm","clk":"11540940986","pt":1719500239534,"mc":[{"id":"1.230178316","rc":[{"atl":[[17.5,0.48]],"id":69685608}],"con":true,"img":false}]}
{"op":"mcm","clk":"11540941044","pt":1719500240615,"mc":[{"id":"1.230178316","rc":[{"atl":[[6,0]],"id":57196226}],"con":true,"img":false}]}
{"op":"mcm","clk":"11540941091","pt":1719500241231,"mc":[{"id":"1.230178316","rc":[{"atl":[[5.9,0]],"id":57196226}],"con":true,"img":false}]}
{"op":"mcm","clk":"11540941133","pt":1719500242055,"mc":[{"id":"1.230178316","rc":[{"atb":[[2.88,9.46]],"id":69685608}],"con":true,"img":false}]}
{"op":"mcm","clk":"11540941141","pt":1719500242157,"mc":[{"id":"1.230178316","rc":[{"atb":[[2.88,6.3]],"id":49159417}],"con":true,"img":false}]}
{"op":"mcm","clk":"11540941148","pt":1719500242261,"mc":[{"id":"1.230178316","rc":[{"atb":[[2.26,9.39]],"id":52655636}],"con":true,"img":false}]}
{"op":"mcm","clk":"11540941154","pt":1719500242314,"mc":[{"id":"1.230178316","rc":[{"atb":[[2.28,9.25]],"id":46611436}],"con":true,"img":false}]}
{"op":"mcm","clk":"11540941162","pt":1719500242417,"mc":[{"id":"1.230178316","rc":[{"atb":[[2.52,7.79]],"id":57196226}],"con":true,"img":false}]}
{"op":"mcm","clk":"11540941167","pt":1719500242519,"mc":[{"id":"1.230178316","rc":[{"atb":[[4.4,1.68]],"id":57196226},{"atl":[[6,2]],"id":57196226},{"atb":[[2.22,9.71]],"id":70902601}],"con":true,"img":false}]}
{"op":"mcm","clk":"11540941207","pt":1719500243140,"mc":[{"id":"1.230178316","rc":[{"atl":[[5.9,0.84]],"id":57196226}],"con":true,"img":false}]}
{"op":"mcm","clk":"11540941215","pt":1719500243244,"mc":[{"id":"1.230178316","rc":[{"atl":[[18,0],[6,4]],"id":57196226}],"con":true,"img":false}]}
{"op":"mcm","clk":"11540941221","pt":1719500243347,"mc":[{"id":"1.230178316","rc":[{"atl":[[6.2,6.88],[6,2]],"id":57196226}],"con":true,"img":false}]}
{"op":"mcm","clk":"11540941238","pt":1719500243658,"mc":[{"id":"1.230178316","rc":[{"atl":[[5.9,5.14]],"id":57196226}],"con":true,"img":false}]}
{"op":"mcm","clk":"11540941253","pt":1719500243815,"mc":[{"id":"1.230178316","rc":[{"atb":[[3.75,0]],"id":57196226}],"con":true,"img":false}]}
{"op":"mcm","clk":"11540941261","pt":1719500243969,"mc":[{"id":"1.230178316","rc":[{"atb":[[1.02,2]],"id":57196226}],"con":true,"img":false}]}
{"op":"mcm","clk":"11540941274","pt":1719500244125,"mc":[{"id":"1.230178316","rc":[{"atb":[[3.8,0]],"id":57196226},{"atl":[[6,0]],"id":57196226}],"con":true,"img":false}]}
{"op":"mcm","clk":"11540941570","pt":1719500248351,"mc":[{"id":"1.230178316","rc":[{"atl":[[6,0]],"id":46611436},{"trd":[[6,5.99]],"ltp":6.0,"tv":5.99,"id":46611436}],"con":true,"img":false}]}
{"op":"mcm","clk":"11540941576","pt":1719500248454,"mc":[{"id":"1.230178316","rc":[{"atl":[[16,0],[30,3.45]],"id":46611436}],"con":true,"img":false}]}
{"op":"mcm","clk":"11540941584","pt":1719500248661,"mc":[{"id":"1.230178316","rc":[{"atl":[[1000,1.07]],"id":49159417}],"con":true,"img":false}]}
{"op":"mcm","clk":"11540941603","pt":1719500248969,"mc":[{"id":"1.230178316","rc":[{"atl":[[1000,1.03]],"id":49159417}],"con":true,"img":false}]}
{"op":"mcm","clk":"11540941624","pt":1719500249230,"mc":[{"id":"1.230178316","rc":[{"atl":[[1000,0.22]],"id":49159417}],"con":true,"img":false}]}
{"op":"mcm","clk":"11540941634","pt":1719500249334,"mc":[{"id":"1.230178316","rc":[{"atl":[[10.5,0.8]],"id":49159417}],"con":true,"img":false}]}
{"op":"mcm","clk":"11540941644","pt":1719500249435,"mc":[{"id":"1.230178316","rc":[{"atb":[[3.8,2.86]],"id":46611436}],"con":true,"img":false}]}
{"op":"mcm","clk":"11540941660","pt":1719500249641,"mc":[{"id":"1.230178316","rc":[{"atl":[[10.5,1.65]],"id":49159417}],"con":true,"img":false}]}
{"op":"mcm","clk":"11540941667","pt":1719500249743,"mc":[{"id":"1.230178316","rc":[{"atl":[[30,0],[15,7.14]],"id":49159417}],"con":true,"img":false}]}
{"op":"mcm","clk":"11540941782","pt":1719500251446,"mc":[{"id":"1.230178316","rc":[{"atl":[[5.8,6.88],[6.2,1]],"id":57196226}],"con":true,"img":false}]}
{"op":"mcm","clk":"11540941810","pt":1719500251858,"mc":[{"id":"1.230178316","rc":[{"atl":[[5.9,0.84]],"id":57196226}],"con":true,"img":false}]}
{"op":"mcm","clk":"11540941836","pt":1719500252169,"mc":[{"id":"1.230178316","rc":[{"atl":[[5.7,0.84]],"id":57196226}],"con":true,"img":false}]}
{"op":"mcm","clk":"11540942095","pt":1719500255946,"mc":[{"id":"1.230178316","rc":[{"atb":[[4.5,3.15]],"id":57196226}],"con":true,"img":false}]}
{"op":"mcm","clk":"11540942131","pt":1719500256559,"mc":[{"id":"1.230178316","rc":[{"atl":[[5.8,0],[5.9,8.57]],"id":57196226}],"con":true,"img":false}]}
{"op":"mcm","clk":"11540942137","pt":1719500256663,"mc":[{"id":"1.230178316","rc":[{"atb":[[4.6,0.84]],"id":57196226}],"con":true,"img":false}]}
{"op":"mcm","clk":"11540942145","pt":1719500256767,"mc":[{"id":"1.230178316","rc":[{"atl":[[6.2,10.43],[5.9,0.84]],"id":57196226}],"con":true,"img":false}]}
{"op":"mcm","clk":"11540942167","pt":1719500257078,"mc":[{"id":"1.230178316","rc":[{"atl":[[10.5,1.05]],"id":46611436}],"con":true,"img":false}]}
{"op":"mcm","clk":"11540942174","pt":1719500257181,"mc":[{"id":"1.230178316","rc":[{"atl":[[5.7,0]],"id":57196226},{"atl":[[30,0],[15,7.14]],"id":46611436}],"con":true,"img":false}]}
{"op":"mcm","clk":"11540942187","pt":1719500257341,"mc":[{"id":"1.230178316","rc":[{"atb":[[1.03,0.52]],"id":46611436}],"con":true,"img":false}]}
{"op":"mcm","clk":"11540942196","pt":1719500257547,"mc":[{"id":"1.230178316","rc":[{"atb":[[1.03,0.43]],"id":46611436}],"con":true,"img":false}]}
{"op":"mcm","clk":"11540942202","pt":1719500257650,"mc":[{"id":"1.230178316","rc":[{"atl":[[5.9,0]],"id":57196226}],"con":true,"img":false}]}
{"op":"mcm","clk":"11540942209","pt":1719500257756,"mc":[{"id":"1.230178316","rc":[{"atb":[[1.03,0]],"id":46611436}],"con":true,"img":false}]}
{"op":"mcm","clk":"11540942217","pt":1719500257860,"mc":[{"id":"1.230178316","rc":[{"atb":[[4.6,0.43]],"id":46611436}],"con":true,"img":false}]}
{"op":"mcm","clk":"11540942229","pt":1719500257964,"mc":[{"id":"1.230178316","rc":[{"atb":[[3.85,2.86],[3.75,2.66]],"id":46611436}],"con":true,"img":false}]}
{"op":"mcm","clk":"11540942330","pt":1719500259361,"mc":[{"id":"1.230178316","rc":[{"atl":[[9.2,2]],"id":70902601}],"con":true,"img":false}]}
{"op":"mcm","clk":"11540942339","pt":1719500259464,"mc":[{"id":"1.230178316","rc":[{"atl":[[9.2,4],[27,1.68]],"id":70902601}],"con":true,"img":false}]}
{"op":"mcm","clk":"11540942356","pt":1719500259672,"mc":[{"id":"1.230178316","rc":[{"atb":[[4.4,3.73]],"id":57196226},{"atl":[[6,0.84]],"id":57196226},{"atl":[[9,0.84]],"id":70902601}],"con":true,"img":false}]}
{"op":"mcm","clk":"11540942365","pt":1719500259776,"mc":[{"id":"1.230178316","rc":[{"atb":[[1.05,3.4]],"id":49159417},{"atl":[[1000,3.63]],"id":49159417}],"con":true,"img":false}]}
{"op":"mcm","clk":"11540942385","pt":1719500259982,"mc":[{"id":"1.230178316","rc":[{"atb":[[1.05,1.75]],"id":49159417},{"atl":[[1000,0.27]],"id":49159417}],"con":true,"img":false}]}
{"op":"mcm","clk":"11540942392","pt":1719500260034,"mc":[{"id":"1.230178316","rc":[{"atb":[[1.05,0.09]],"id":49159417}],"con":true,"img":false}]}
{"op":"mcm","clk":"11540942409","pt":1719500260241,"mc":[{"id":"1.230178316","rc":[{"atb":[[1.05,0.04]],"id":49159417},{"atl":[[1000,0.22]],"id":49159417}],"con":true,"img":false}]}
{"op":"mcm","clk":"11540942417","pt":1719500260345,"mc":[{"id":"1.230178316","rc":[{"atb":[[5.1,1.7],[1.05,0]],"id":49159417},{"atl":[[10.5,1.69]],"id":49159417}],"con":true,"img":false}]}
{"op":"mcm","clk":"11540942423","pt":1719500260448,"mc":[{"id":"1.230178316","rc":[{"atb":[[5.1,1.75]],"id":49159417}],"con":true,"img":false}]}
{"op":"mcm","clk":"11540942436","pt":1719500260653,"mc":[{"id":"1.230178316","rc":[{"atb":[[5.2,0.84]],"id":49159417}],"con":true,"img":false}]}
{"op":"mcm","clk":"11540942480","pt":1719500261272,"mc":[{"id":"1.230178316","rc":[{"atl":[[27,0]],"id":70902601}],"con":true,"img":false}]}
{"op":"mcm","clk":"11540942521","pt":1719500261947,"mc":[{"id":"1.230178316","rc":[{"atl":[[17,6.25],[6.2,1]],"id":57196226}],"con":true,"img":false}]}
{"op":"mcm","clk":"11540942714","pt":1719500264687,"mc":[{"id":"1.230178316","rc":[{"atb":[[2.5,0]],"id":57196226},{"atb":[[3.75,0]],"id":46611436},{"atb":[[4.3,7]],"id":52655636},{"atb":[[3.25,0]],"id":70902601},{"atl":[[9.2,2]],"id":70902601},{"atb":[[5.5,0]],"id":69685608},{"atb":[[4,2.5]],"id":49159417}],"con":true,"img":false}]}
{"op":"mcm","clk":"11540942722","pt":1719500264739,"mc":[{"id":"1.230178316","rc":[{"atl":[[9.2,0],[9.4,9]],"id":70902601}],"con":true,"img":false}]}
{"op":"mcm","clk":"11540942762","pt":1719500265253,"mc":[{"id":"1.230178316","rc":[{"atl":[[9,0]],"id":70902601},{"atb":[[5.6,0],[5.1,0.84]],"id":69685608}],"con":true,"img":false}]}
{"op":"mcm","clk":"11540942865","pt":1719500266494,"mc":[{"id":"1.230178316","rc":[{"atl":[[9.2,2]],"id":70902601}],"con":true,"img":false}]}
{"op":"mcm","clk":"11540942889","pt":1719500266752,"mc":[{"id":"1.230178316","rc":[{"atl":[[9.2,2.84]],"id":70902601}],"con":true,"img":false}]}
{"op":"mcm","clk":"11540942895","pt":1719500266854,"mc":[{"id":"1.230178316","rc":[{"atl":[[9.2,4.43]],"id":70902601}],"con":true,"img":false}]}
{"op":"mcm","clk":"11540943013","pt":1719500268450,"mc":[{"id":"1.230178316","rc":[{"atl":[[1000,1.07]],"id":52655636}],"con":true,"img":false}]}
{"op":"mcm","clk":"11540943038","pt":1719500268870,"mc":[{"id":"1.230178316","rc":[{"atl":[[1000,0.85]],"id":52655636}],"con":true,"img":false}]}
{"op":"mcm","clk":"11540943057","pt":1719500269171,"mc":[{"id":"1.230178316","rc":[{"atl":[[1000,0.22]],"id":52655636}],"con":true,"img":false}]}
{"op":"mcm","clk":"11540943065","pt":1719500269273,"mc":[{"id":"1.230178316","rc":[{"atl":[[13.5,0.62]],"id":52655636}],"con":true,"img":false}]}
{"op":"mcm","clk":"11540943074","pt":1719500269377,"mc":[{"id":"1.230178316","rc":[{"atl":[[9,2.81]],"id":70902601}],"con":true,"img":false}]}
{"op":"mcm","clk":"11540943245","pt":1719500271793,"mc":[{"id":"1.230178316","rc":[{"atl":[[9.2,2.43]],"id":70902601}],"con":true,"img":false}]}
{"op":"mcm","clk":"11540943319","pt":1719500272567,"mc":[{"id":"1.230178316","rc":[{"atl":[[10.5,0]],"id":46611436}],"con":true,"img":false}]}
{"op":"mcm","clk":"11540943329","pt":1719500272670,"mc":[{"id":"1.230178316","rc":[{"atl":[[15,0],[30,3.45]],"id":46611436},{"atl":[[9,5.63],[9.4,1]],"id":70902601}],"con":true,"img":false}]}
{"op":"mcm","clk":"11540943350","pt":1719500272982,"mc":[{"id":"1.230178316","rc":[{"atl":[[9.2,0.84]],"id":70902601}],"con":true,"img":false}]}
{"op":"mcm","clk":"11540943364","pt":1719500273189,"mc":[{"id":"1.230178316","rc":[{"atb":[[4.6,0]],"id":46611436}],"con":true,"img":false}]}
{"op":"mcm","clk":"11540943392","pt":1719500273659,"mc":[{"id":"1.230178316","rc":[{"atl":[[8.8,2]],"id":70902601}],"con":true,"img":false}]}
{"op":"mcm","clk":"11540943398","pt":1719500273763,"mc":[{"id":"1.230178316","rc":[{"atl":[[8.8,2.84]],"id":70902601}],"con":true,"img":false}]}
{"op":"mcm","clk":"11540943429","pt":1719500274170,"mc":[{"id":"1.230178316","rc":[{"atl":[[9.2,0]],"id":70902601}],"con":true,"img":false}]}
{"op":"mcm","clk":"11540943444","pt":1719500274374,"mc":[{"id":"1.230178316","rc":[{"atl":[[9,2.82]],"id":70902601}],"con":true,"img":false}]}
{"op":"mcm","clk":"11540943462","pt":1719500274682,"mc":[{"id":"1.230178316","rc":[{"atl":[[10.5,1.05]],"id":46611436}],"con":true,"img":false}]}
{"op":"mcm","clk":"11540943473","pt":1719500274784,"mc":[{"id":"1.230178316","rc":[{"atb":[[1.03,0.52]],"id":46611436},{"atl":[[30,0],[15,7.14]],"id":46611436}],"con":true,"img":false}]}
{"op":"mcm","clk":"11540943491","pt":1719500275090,"mc":[{"id":"1.230178316","rc":[{"atb":[[1.03,0.43]],"id":46611436}],"con":true,"img":false}]}
{"op":"mcm","clk":"11540943511","pt":1719500275296,"mc":[{"id":"1.230178316","rc":[{"atb":[[1.03,0]],"id":46611436}],"con":true,"img":false}]}
{"op":"mcm","clk":"11540943516","pt":1719500275399,"mc":[{"id":"1.230178316","rc":[{"atb":[[4.6,0.43]],"id":46611436}],"con":true,"img":false}]}
{"op":"mcm","clk":"11540943726","pt":1719500277768,"mc":[{"id":"1.230178316","rc":[{"atb":[[3.1,10.5]],"id":46611436}],"con":true,"img":false}]}
{"op":"mcm","clk":"11540943791","pt":1719500278585,"mc":[{"id":"1.230178316","rc":[{"atl":[[8.6,1.74]],"id":70902601}],"con":true,"img":false}]}
{"op":"mcm","clk":"11540943806","pt":1719500278790,"mc":[{"id":"1.230178316","rc":[{"atl":[[9,0],[8.8,6.32]],"id":70902601}],"con":true,"img":false}]}
{"op":"mcm","clk":"11540943814","pt":1719500278892,"mc":[{"id":"1.230178316","rc":[{"spn":5.3,"spf":"NaN","id":57196226},{"spn":7.55,"spf":"NaN","id":46611436},{"spn":9.3,"spf":"NaN","id":52655636},{"atl":[[8.8,4.32]],"id":70902601},{"spn":4.48,"spf":1.0,"id":70902601},{"spn":11.3,"spf":"NaN","id":69685608},{"spn":7.85,"spf":"NaN","id":49159417}],"con":true,"img":false}]}
{"op":"mcm","clk":"11540943933","pt":1719500280498,"mc":[{"id":"1.230178316","rc":[{"atb":[[4.4,1]],"id":46611436}],"con":true,"img":false}]}
{"op":"mcm","clk":"11540943939","pt":1719500280601,"mc":[{"id":"1.230178316","rc":[{"atb":[[3.85,0],[4,2.86]],"id":46611436}],"con":true,"img":false}]}
{"op":"mcm","clk":"11540943988","pt":1719500281185,"mc":[{"id":"1.230178316","rc":[{"atl":[[8.4,0.84]],"id":70902601}],"con":true,"img":false}]}
{"op":"mcm","clk":"11540943996","pt":1719500281292,"mc":[{"id":"1.230178316","rc":[{"atl":[[1000,1.7]],"id":57196226},{"atl":[[8.4,2.84]],"id":70902601},{"atl":[[1000,1.93]],"id":69685608},{"atl":[[1000,1.93]],"id":49159417}],"con":true,"img":false}]}
{"op":"mcm","clk":"11540944003","pt":1719500281383,"mc":[{"id":"1.230178316","rc":[{"atb":[[1.04,1.7]],"id":69685608},{"atb":[[1.06,3.4]],"id":49159417}],"con":true,"img":false}]}
{"op":"mcm","clk":"11540944018","pt":1719500281594,"mc":[{"id":"1.230178316","rc":[{"atl":[[1000,0.03]],"id":57196226},{"atl":[[1000,0.24]],"id":69685608},{"atl":[[1000,0.24]],"id":49159417}],"con":true,"img":false}]}
{"op":"mcm","clk":"11540944025","pt":1719500281698,"mc":[{"id":"1.230178316","rc":[{"atl":[[8.2,3.09]],"id":70902601},{"atb":[[1.04,0.07]],"id":69685608},{"atb":[[1.06,0.08]],"id":49159417}],"con":true,"img":false}]}
{"op":"mcm","clk":"11540944036","pt":1719500281804,"mc":[{"id":"1.230178316","rc":[{"atl":[[8.8,3.48]],"id":70902601}],"con":true,"img":false}]}
{"op":"mcm","clk":"11540944042","pt":1719500281908,"mc":[{"id":"1.230178316","rc":[{"atl":[[1000,0]],"id":57196226},{"atb":[[1.04,0]],"id":69685608},{"atl":[[1000,0.22]],"id":69685608},{"atb":[[1.06,0]],"id":49159417},{"atl":[[1000,0.22]],"id":49159417}],"con":true,"img":false}]}
{"op":"mcm","clk":"11540944055","pt":1719500281984,"mc":[{"id":"1.230178316","rc":[{"atl":[[6,0.88]],"id":57196226},{"atb":[[5.1,0.91]],"id":69685608},{"atl":[[17.5,0.5]],"id":69685608},{"atb":[[5.2,0.93]],"id":49159417},{"atl":[[10.5,1.71]],"id":49159417}],"con":true,"img":false}]}
{"op":"mcm","clk":"11540944087","pt":1719500282282,"mc":[{"id":"1.230178316","rc":[{"atl":[[8.4,0.84]],"id":70902601}],"con":true,"img":false}]}
{"op":"mcm","clk":"11540944221","pt":1719500283783,"mc":[{"id":"1.230178316","rc":[{"atb":[[3.75,0]],"id":49159417}],"con":true,"img":false}]}
{"op":"mcm","clk":"11540944279","pt":1719500284600,"mc":[{"id":"1.230178316","rc":[{"atl":[[8.6,0]],"id":70902601}],"con":true,"img":false}]}
{"op":"mcm","clk":"11540944318","pt":1719500285187,"mc":[{"id":"1.230178316","rc":[{"atl":[[8.2,0]],"id":70902601}],"con":true,"img":false}]}
{"op":"mcm","clk":"11540944330","pt":1719500285290,"mc":[{"id":"1.230178316","rc":[{"atl":[[8.8,0],[9.4,9]],"id":70902601}],"con":true,"img":false}]}
{"op":"mcm","clk":"11540944361","pt":1719500285798,"mc":[{"id":"1.230178316","rc":[{"atl":[[8.4,0]],"id":70902601}],"con":true,"img":false}]}
{"op":"mcm","clk":"11540944373","pt":1719500285903,"mc":[{"id":"1.230178316","rc":[{"atl":[[27,3.85],[9.4,1]],"id":70902601}],"con":true,"img":false}]}
{"op":"mcm","clk":"11540944415","pt":1719500286385,"mc":[{"id":"1.230178316","rc":[{"atb":[[4.4,1.68]],"id":57196226}],"con":true,"img":false}]}
{"op":"mcm","clk":"11540944558","pt":1719500288395,"mc":[{"id":"1.230178316","rc":[{"atl":[[9.2,2]],"id":70902601}],"con":true,"img":false}]}
{"op":"mcm","clk":"11540944563","pt":1719500288498,"mc":[{"id":"1.230178316","rc":[{"atl":[[9.2,4],[27,0]],"id":70902601}],"con":true,"img":false}]}
{"op":"mcm","clk":"11540944571","pt":1719500288602,"mc":[{"id":"1.230178316","rc":[{"atb":[[4.4,0]],"id":57196226},{"atl":[[9.2,2],[27,3.85]],"id":70902601}],"con":true,"img":false}]}
{"op":"mcm","clk":"11540944586","pt":1719500288809,"mc":[{"id":"1.230178316","rc":[{"atl":[[9,0.84]],"id":70902601}],"con":true,"img":false}]}
{"op":"mcm","clk":"11540944701","pt":1719500290316,"mc":[{"id":"1.230178316","rc":[{"atl":[[10.5,0]],"id":46611436}],"con":true,"img":false}]}
{"op":"mcm","clk":"11540944711","pt":1719500290384,"mc":[{"id":"1.230178316","rc":[{"atl":[[15,0],[30,3.45]],"id":46611436}],"con":true,"img":false}]}
{"op":"mcm","clk":"11540944722","pt":1719500290486,"mc":[{"id":"1.230178316","rc":[{"atl":[[9,2.52]],"id":70902601}],"con":true,"img":false}]}
{"op":"mcm","clk":"11540944754","pt":1719500290797,"mc":[{"id":"1.230178316","rc":[{"atb":[[4.6,0]],"id":46611436}],"con":true,"img":false}]}
{"op":"mcm","clk":"11540944893","pt":1719500292299,"mc":[{"id":"1.230178316","rc":[{"atb":[[2.26,0]],"id":46611436},{"atb":[[2.24,0]],"id":52655636},{"atb":[[2.2,0]],"id":70902601}],"con":true,"img":false}]}
{"op":"mcm","clk":"11540944903","pt":1719500292404,"mc":[{"id":"1.230178316","rc":[{"atb":[[2.3,11.66]],"id":46611436},{"atb":[[2.28,12.44]],"id":52655636},{"atb":[[2.24,11.33]],"id":70902601}],"con":true,"img":false}]}
{"op":"mcm","clk":"11540944914","pt":1719500292501,"mc":[{"id":"1.230178316","rc":[{"atb":[[2.9,3.38]],"id":69685608}],"con":true,"img":false}]}
{"op":"mcm","clk":"11540944934","pt":1719500292697,"mc":[{"id":"1.230178316","rc":[{"atb":[[2.9,10.06]],"id":69685608}],"con":true,"img":false}]}
{"op":"mcm","clk":"11540944943","pt":1719500292800,"mc":[{"id":"1.230178316","rc":[{"atb":[[2.9,6.67]],"id":49159417}],"con":true,"img":false}]}
{"op":"mcm","clk":"11540944960","pt":1719500293008,"mc":[{"id":"1.230178316","rc":[{"atb":[[2.28,22.36]],"id":52655636}],"con":true,"img":false}]}
{"op":"mcm","clk":"11540944966","pt":1719500293113,"mc":[{"id":"1.230178316","rc":[{"atb":[[2.3,21.43]],"id":46611436}],"con":true,"img":false}]}
{"op":"mcm","clk":"11540944982","pt":1719500293286,"mc":[{"id":"1.230178316","rc":[{"atb":[[3.1,15.34]],"id":46611436}],"con":true,"img":false}]}
{"op":"mcm","clk":"11540944999","pt":1719500293499,"mc":[{"id":"1.230178316","rc":[{"atl":[[10.5,1.05]],"id":46611436}],"con":true,"img":false}]}
{"op":"mcm","clk":"11540945008","pt":1719500293590,"mc":[{"id":"1.230178316","rc":[{"atb":[[2.54,8.24]],"id":57196226},{"atb":[[1.03,0.52]],"id":46611436},{"atl":[[9.2,0]],"id":70902601}],"con":true,"img":false}]}
{"op":"mcm","clk":"11540945016","pt":1719500293697,"mc":[{"id":"1.230178316","rc":[{"atb":[[2.24,21.57]],"id":70902601}],"con":true,"img":false}]}
{"op":"mcm","clk":"11540945032","pt":1719500293903,"mc":[{"id":"1.230178316","rc":[{"atb":[[1.03,0.43]],"id":46611436}],"con":true,"img":false}]}
{"op":"mcm","clk":"11540945062","pt":1719500294201,"mc":[{"id":"1.230178316","rc":[{"atb":[[1.03,0]],"id":46611436}],"con":true,"img":false}]}
{"op":"mcm","clk":"11540945070","pt":1719500294305,"mc":[{"id":"1.230178316","rc":[{"atb":[[4.6,0.43]],"id":46611436}],"con":true,"img":false}]}
{"op":"mcm","clk":"11540945163","pt":1719500295495,"mc":[{"id":"1.230178316","rc":[{"atl":[[8.8,2]],"id":70902601}],"con":true,"img":false}]}
{"op":"mcm","clk":"11540945210","pt":1719500296116,"mc":[{"id":"1.230178316","rc":[{"atb":[[2.88,6.3]],"id":69685608}],"con":true,"img":false}]}
{"op":"mcm","clk":"11540945218","pt":1719500296221,"mc":[{"id":"1.230178316","rc":[{"atl":[[8.6,0.84],[8.8,4],[27,0]],"id":70902601}],"con":true,"img":false}]}
{"op":"mcm","clk":"11540945250","pt":1719500296503,"mc":[{"id":"1.230178316","rc":[{"atb":[[2.92,3.15]],"id":69685608}],"con":true,"img":false}]}
{"op":"mcm","clk":"11540945266","pt":1719500296699,"mc":[{"id":"1.230178316","rc":[{"atl":[[9,0.84]],"id":70902601}],"con":true,"img":false}]}
{"op":"mcm","clk":"11540945377","pt":1719500297992,"mc":[{"id":"1.230178316","rc":[{"atl":[[30,0],[15,7.14]],"id":46611436}],"con":true,"img":false}]}
{"op":"mcm","clk":"11540945420","pt":1719500298501,"mc":[{"id":"1.230178316","rc":[{"atl":[[10,0.84]],"id":46611436}],"con":true,"img":false}]}
{"op":"mcm","clk":"11540945471","pt":1719500299225,"mc":[{"id":"1.230178316","rc":[{"atl":[[10,1.69]],"id":46611436}],"con":true,"img":false}]}
{"op":"mcm","clk":"11540945511","pt":1719500299795,"mc":[{"id":"1.230178316","rc":[{"atb":[[4.5,0]],"id":57196226}],"con":true,"img":false}]}
{"op":"mcm","clk":"11540945545","pt":1719500300209,"mc":[{"id":"1.230178316","rc":[{"atb":[[3.75,0.84]],"id":57196226}],"con":true,"img":false}]}
{"op":"mcm","clk":"11540945556","pt":1719500300311,"mc":[{"id":"1.230178316","rc":[{"atb":[[4.6,0]],"id":57196226},{"atl":[[8.8,2]],"id":70902601}],"con":true,"img":false}]}
{"op":"mcm","clk":"11540945635","pt":1719500301303,"mc":[{"id":"1.230178316","rc":[{"atl":[[9,3.69],[8.8,0]],"id":70902601}],"con":true,"img":false}]}
{"op":"mcm","clk":"11540945668","pt":1719500301707,"mc":[{"id":"1.230178316","rc":[{"atl":[[8.6,0]],"id":70902601}],"con":true,"img":false}]}
{"op":"mcm","clk":"11540945675","pt":1719500301811,"mc":[{"id":"1.230178316","rc":[{"atl":[[9,0.84],[27,3.85]],"id":70902601}],"con":true,"img":false}]}
{"op":"mcm","clk":"11540945706","pt":1719500302225,"mc":[{"id":"1.230178316","rc":[{"atl":[[9,0]],"id":70902601}],"con":true,"img":false}]}
{"op":"mcm","clk":"11540945733","pt":1719500302643,"mc":[{"id":"1.230178316","rc":[{"atl":[[9.2,1.54]],"id":70902601}],"con":true,"img":false}]}
{"op":"mcm","clk":"11540945774","pt":1719500303109,"mc":[{"id":"1.230178316","rc":[{"atl":[[6,2.88]],"id":57196226}],"con":true,"img":false}]}
{"op":"mcm","clk":"11540945787","pt":1719500303213,"mc":[{"id":"1.230178316","rc":[{"atl":[[17,0],[6,5.76]],"id":57196226}],"con":true,"img":false}]}
{"op":"mcm","clk":"11540946198","pt":1719500308338,"mc":[{"id":"1.230178316","rc":[{"atl":[[6,3.76]],"id":57196226}],"con":true,"img":false}]}
{"op":"mcm","clk":"11540946208","pt":1719500308443,"mc":[{"id":"1.230178316","rc":[{"atl":[[18,5.88],[6,0.88]],"id":57196226}],"con":true,"img":false}]}
{"op":"mcm","clk":"11540946242","pt":1719500308812,"mc":[{"id":"1.230178316","rc":[{"atb":[[2.52,0]],"id":57196226},{"atl":[[10.5,0]],"id":46611436}],"con":true,"img":false}]}
{"op":"mcm","clk":"11540946276","pt":1719500309318,"mc":[{"id":"1.230178316","rc":[{"atl":[[9.2,3.54],[27,0]],"id":70902601}],"con":true,"img":false}]}
{"op":"mcm","clk":"11540946287","pt":1719500309420,"mc":[{"id":"1.230178316","rc":[{"atl":[[9.2,1.54],[27,3.85]],"id":70902601}],"con":true,"img":false}]}
{"op":"mcm","clk":"11540946305","pt":1719500309628,"mc":[{"id":"1.230178316","rc":[{"atb":[[4.6,0]],"id":46611436}],"con":true,"img":false}]}
{"op":"mcm","clk":"11540946367","pt":1719500310313,"mc":[{"id":"1.230178316","rc":[{"atl":[[6,2.88]],"id":57196226}],"con":true,"img":false}]}
{"op":"mcm","clk":"11540946378","pt":1719500310410,"mc":[{"id":"1.230178316","rc":[{"atl":[[6,5.76]],"id":57196226}],"con":true,"img":false}]}
{"op":"mcm","clk":"11540946384","pt":1719500310505,"mc":[{"id":"1.230178316","rc":[{"atl":[[18,0]],"id":57196226}],"con":true,"img":false}]}
{"op":"mcm","clk":"11540946482","pt":1719500311613,"mc":[{"id":"1.230178316","rc":[{"atl":[[9.8,1.05]],"id":46611436}],"con":true,"img":false}]}
{"op":"mcm","clk":"11540946509","pt":1719500311914,"mc":[{"id":"1.230178316","rc":[{"atb":[[1.03,0.52]],"id":46611436}],"con":true,"img":false}]}
{"op":"mcm","clk":"11540946524","pt":1719500312122,"mc":[{"id":"1.230178316","rc":[{"atb":[[1.03,0.43]],"id":46611436}],"con":true,"img":false}]}
{"op":"mcm","clk":"11540946554","pt":1719500312434,"mc":[{"id":"1.230178316","rc":[{"atb":[[1.03,0]],"id":46611436}],"con":true,"img":false}]}
{"op":"mcm","clk":"11540946561","pt":1719500312537,"mc":[{"id":"1.230178316","rc":[{"atb":[[4.6,0.43]],"id":46611436}],"con":true,"img":false}]}
{"op":"mcm","clk":"11540946674","pt":1719500313937,"mc":[{"id":"1.230178316","rc":[{"atb":[[2.92,3.15]],"id":49159417}],"con":true,"img":false}]}
{"op":"mcm","clk":"11540946685","pt":1719500314144,"mc":[{"id":"1.230178316","rc":[{"atb":[[2.56,7.59]],"id":57196226}],"con":true,"img":false}]}
{"op":"mcm","clk":"11540946781","pt":1719500315536,"mc":[{"id":"1.230178316","rc":[{"atl":[[6,3.76]],"id":57196226}],"con":true,"img":false}]}
{"op":"mcm","clk":"11540946788","pt":1719500315641,"mc":[{"id":"1.230178316","rc":[{"atl":[[18,5.88],[6,0.88]],"id":57196226}],"con":true,"img":false}]}
{"op":"mcm","clk":"11540946914","pt":1719500317448,"mc":[{"id":"1.230178316","rc":[{"atl":[[6,2.88]],"id":57196226}],"con":true,"img":false}]}
{"op":"mcm","clk":"11540946936","pt":1719500317823,"mc":[{"id":"1.230178316","rc":[{"atl":[[18,0],[6,5.76]],"id":57196226}],"con":true,"img":false}]}
{"op":"mcm","clk":"11540947356","pt":1719500322628,"mc":[{"id":"1.230178316","rc":[{"atl":[[6,3.76]],"id":57196226}],"con":true,"img":false}]}
{"op":"mcm","clk":"11540947377","pt":1719500322933,"mc":[{"id":"1.230178316","rc":[{"atl":[[18,5.88],[6,0.88]],"id":57196226}],"con":true,"img":false}]}
{"op":"mcm","clk":"11540947488","pt":1719500324435,"mc":[{"id":"1.230178316","rc":[{"atl":[[6,0.84]],"id":57196226},{"atb":[[5.1,0.84]],"id":69685608},{"atl":[[17.5,0.48]],"id":69685608},{"atb":[[5.1,1.65],[5.2,0.84]],"id":49159417},{"atl":[[10.5,1.65]],"id":49159417}],"con":true,"img":false}]}
{"op":"mcm","clk":"11540947539","pt":1719500325052,"mc":[{"id":"1.230178316","rc":[{"atl":[[6,2.84]],"id":57196226}],"con":true,"img":false}]}
{"op":"mcm","clk":"11540947557","pt":1719500325258,"mc":[{"id":"1.230178316","rc":[{"atl":[[18,0],[6,5.69]],"id":57196226}],"con":true,"img":false}]}
{"op":"mcm","clk":"11540947720","pt":1719500327063,"mc":[{"id":"1.230178316","rc":[{"atl":[[9.8,0]],"id":46611436}],"con":true,"img":false}]}
{"op":"mcm","clk":"11540947793","pt":1719500327841,"mc":[{"id":"1.230178316","rc":[{"atb":[[2.28,0]],"id":46611436},{"atb":[[2.26,0]],"id":52655636},{"atb":[[2.22,0]],"id":70902601},{"atb":[[2.88,0]],"id":69685608},{"atb":[[2.88,0]],"id":49159417}],"con":true,"img":false}]}
{"op":"mcm","clk":"11540947798","pt":1719500327943,"mc":[{"id":"1.230178316","rc":[{"atb":[[4.6,0]],"id":46611436},{"atl":[[9.2,3.54]],"id":70902601}],"con":true,"img":false}]}
{"op":"mcm","clk":"11540947808","pt":1719500328047,"mc":[{"id":"1.230178316","rc":[{"atl":[[27,0]],"id":70902601}],"con":true,"img":false}]}
{"op":"mcm","clk":"11540947825","pt":1719500328255,"mc":[{"id":"1.230178316","rc":[{"atl":[[9,0.84]],"id":70902601}],"con":true,"img":false}]}
{"op":"mcm","clk":"11540947964","pt":1719500329865,"mc":[{"id":"1.230178316","rc":[{"atb":[[2.9,6.67]],"id":69685608}],"con":true,"img":false}]}
{"op":"mcm","clk":"11540947973","pt":1719500329968,"mc":[{"id":"1.230178316","rc":[{"atl":[[9.8,1.05]],"id":46611436}],"con":true,"img":false}]}
{"op":"mcm","clk":"11540947990","pt":1719500330136,"mc":[{"id":"1.230178316","rc":[{"atb":[[1.03,0.52]],"id":46611436}],"con":true,"img":false}]}
{"op":"mcm","clk":"11540948000","pt":1719500330235,"mc":[{"id":"1.230178316","rc":[{"atl":[[6,3.69]],"id":57196226}],"con":true,"img":false}]}
{"op":"mcm","clk":"11540948017","pt":1719500330436,"mc":[{"id":"1.230178316","rc":[{"atl":[[18,5.88],[6,0.84]],"id":57196226},{"atb":[[1.03,0.43]],"id":46611436}],"con":true,"img":false}]}
{"op":"mcm","clk":"11540948035","pt":1719500330644,"mc":[{"id":"1.230178316","rc":[{"atb":[[1.03,0]],"id":46611436}],"con":true,"img":false}]}
{"op":"mcm","clk":"11540948044","pt":1719500330745,"mc":[{"id":"1.230178316","rc":[{"atb":[[4.6,0.43]],"id":46611436}],"con":true,"img":false}]}
{"op":"mcm","clk":"11540948143","pt":1719500332242,"mc":[{"id":"1.230178316","rc":[{"atl":[[6,2.84]],"id":57196226}],"con":true,"img":false}]}
{"op":"mcm","clk":"11540948169","pt":1719500332551,"mc":[{"id":"1.230178316","rc":[{"atl":[[18,0],[6,5.69]],"id":57196226}],"con":true,"img":false}]}
{"op":"mcm","clk":"11540948177","pt":1719500332654,"mc":[{"id":"1.230178316","rc":[{"atl":[[18,5.88],[6,2.84]],"id":57196226}],"con":true,"img":false}]}
{"op":"mcm","clk":"11540948189","pt":1719500332758,"mc":[{"id":"1.230178316","rc":[{"atl":[[18,0],[6,8.54]],"id":57196226}],"con":true,"img":false}]}
{"op":"mcm","clk":"11540948199","pt":1719500332859,"mc":[{"id":"1.230178316","rc":[{"atl":[[18,5.88],[6,2.84]],"id":57196226}],"con":true,"img":false}]}
{"op":"mcm","clk":"11540948256","pt":1719500333479,"mc":[{"id":"1.230178316","rc":[{"atl":[[6.2,5.5]],"id":57196226}],"con":true,"img":false}]}
{"op":"mcm","clk":"11540948266","pt":1719500333541,"mc":[{"id":"1.230178316","rc":[{"atl":[[18,0],[6,8.34]],"id":57196226}],"con":true,"img":false}]}
{"op":"mcm","clk":"11540948280","pt":1719500333644,"mc":[{"id":"1.230178316","rc":[{"atl":[[6.2,1]],"id":57196226}],"con":true,"img":false}]}
{"op":"mcm","clk":"11540948315","pt":1719500334047,"mc":[{"id":"1.230178316","rc":[{"atl":[[5.9,4.3]],"id":57196226}],"con":true,"img":false}]}
{"op":"mcm","clk":"11540948331","pt":1719500334253,"mc":[{"id":"1.230178316","rc":[{"atl":[[5.8,4.3],[6,2.84]],"id":57196226},{"atb":[[2.3,9.11]],"id":52655636},{"atb":[[2.92,9.32]],"id":69685608}],"con":true,"img":false}]}
{"op":"mcm","clk":"11540948344","pt":1719500334460,"mc":[{"id":"1.230178316","rc":[{"atb":[[2.26,9.39]],"id":70902601},{"atb":[[2.92,9.32]],"id":49159417}],"con":true,"img":false}]}
{"op":"mcm","clk":"11540948363","pt":1719500334665,"mc":[{"id":"1.230178316","rc":[{"atl":[[5.7,0.84]],"id":57196226},{"atb":[[2.32,8.97]],"id":46611436}],"con":true,"img":false}]}
{"op":"mcm","clk":"11540948371","pt":1719500334768,"mc":[{"id":"1.230178316","rc":[{"atl":[[6,2],[5.9,0]],"id":57196226}],"con":true,"img":false}]}
{"op":"mcm","clk":"11540948381","pt":1719500334871,"mc":[{"id":"1.230178316","rc":[{"atl":[[5.8,0],[5.9,5.15]],"id":57196226}],"con":true,"img":false}]}
{"op":"mcm","clk":"11540948401","pt":1719500335134,"mc":[{"id":"1.230178316","rc":[{"atl":[[6,0]],"id":57196226}],"con":true,"img":false}]}
{"op":"mcm","clk":"11540948410","pt":1719500335246,"mc":[{"id":"1.230178316","rc":[{"atl":[[6.2,9],[5.7,0],[5.9,0]],"id":57196226}],"con":true,"img":false}]}
{"op":"mcm","clk":"11540948726","pt":1719500339365,"mc":[{"id":"1.230178316","rc":[{"atl":[[6,2]],"id":57196226},{"spn":4.87,"spf":"NaN","id":57196226},{"spn":7.2,"spf":"NaN","id":46611436}],"con":true,"img":false}]}
{"op":"mcm","clk":"11540948764","pt":1719500339983,"mc":[{"id":"1.230178316","rc":[{"atl":[[5.9,4.3]],"id":57196226}],"con":true,"img":false}]}
{"op":"mcm","clk":"11540948851","pt":1719500341170,"mc":[{"id":"1.230178316","rc":[{"atb":[[3.8,14.18]],"id":57196226}],"con":true,"img":false}]}
{"op":"mcm","clk":"11540948863","pt":1719500341275,"mc":[{"id":"1.230178316","rc":[{"atb":[[1.01,24.67]],"id":69685608}],"con":true,"img":false}]}
{"op":"mcm","clk":"11540948902","pt":1719500341649,"mc":[{"id":"1.230178316","rc":[{"atb":[[3.85,0.84]],"id":57196226},{"atl":[[6,3]],"id":57196226},{"atb":[[4.1,1]],"id":46611436},{"atl":[[32,1]],"id":52655636},{"atb":[[3.3,1]],"id":70902601},{"atl":[[29,1]],"id":69685608},{"atb":[[5.2,1.84]],"id":49159417}],"con":true,"img":false}]}
{"op":"mcm","clk":"11540948911","pt":1719500341755,"mc":[{"id":"1.230178316","rc":[{"atl":[[5.8,0.84]],"id":57196226}],"con":true,"img":false}]}
{"op":"mcm","clk":"11540948929","pt":1719500341959,"mc":[{"id":"1.230178316","rc":[{"atl":[[30,0.62]],"id":52655636}],"con":true,"img":false}]}
{"op":"mcm","clk":"11540948938","pt":1719500342062,"mc":[{"id":"1.230178316","rc":[{"atl":[[13.5,0]],"id":52655636}],"con":true,"img":false}]}
{"op":"mcm","clk":"11540948960","pt":1719500342270,"mc":[{"id":"1.230178316","rc":[{"atl":[[1000,1.07]],"id":52655636}],"con":true,"img":false}]}
{"op":"mcm","clk":"11540948977","pt":1719500342470,"mc":[{"id":"1.230178316","rc":[{"atl":[[5.8,3.84],[6.2,1]],"id":57196226}],"con":true,"img":false}]}
{"op":"mcm","clk":"11540948987","pt":1719500342675,"mc":[{"id":"1.230178316","rc":[{"atl":[[6,2]],"id":57196226}],"con":true,"img":false}]}
{"op":"mcm","clk":"11540948995","pt":1719500342779,"mc":[{"id":"1.230178316","rc":[{"atl":[[5.9,0]],"id":57196226}],"con":true,"img":false}]}
{"op":"mcm","clk":"11540949000","pt":1719500342883,"mc":[{"id":"1.230178316","rc":[{"atl":[[5.7,1]],"id":57196226},{"atl":[[30,0]],"id":52655636}],"con":true,"img":false}]}
{"op":"mcm","clk":"11540949010","pt":1719500342988,"mc":[{"id":"1.230178316","rc":[{"atb":[[4.2,2.5]],"id":46611436}],"con":true,"img":false}]}
{"op":"mcm","clk":"11540949039","pt":1719500343267,"mc":[{"id":"1.230178316","rc":[{"atl":[[1000,0.88]],"id":52655636}],"con":true,"img":false}]}
{"op":"mcm","clk":"11540949067","pt":1719500343572,"mc":[{"id":"1.230178316","rc":[{"atl":[[1000,0.22]],"id":52655636}],"con":true,"img":false}]}
{"op":"mcm","clk":"11540949076","pt":1719500343679,"mc":[{"id":"1.230178316","rc":[{"atl":[[13,0.65]],"id":52655636}],"con":true,"img":false}]}
{"op":"mcm","clk":"11540949152","pt":1719500344662,"mc":[{"id":"1.230178316","rc":[{"atl":[[6,0]],"id":57196226}],"con":true,"img":false}]}
{"op":"mcm","clk":"11540949239","pt":1719500345277,"mc":[{"id":"1.230178316","rc":[{"atl":[[9.8,0]],"id":46611436}],"con":true,"img":false}]}
{"op":"mcm","clk":"11540949327","pt":1719500346268,"mc":[{"id":"1.230178316","rc":[{"atb":[[4.6,0]],"id":46611436}],"con":true,"img":false}]}
{"op":"mcm","clk":"11540949372","pt":1719500346983,"mc":[{"id":"1.230178316","rc":[{"atl":[[5.6,2]],"id":57196226}],"con":true,"img":false}]}
{"op":"mcm","clk":"11540949417","pt":1719500347551,"mc":[{"id":"1.230178316","rc":[{"atl":[[9.8,1.05]],"id":46611436}],"con":true,"img":false}]}
{"op":"mcm","clk":"11540949430","pt":1719500347659,"mc":[{"id":"1.230178316","rc":[{"atb":[[1.03,0.52]],"id":46611436}],"con":true,"img":false}]}
{"op":"mcm","clk":"11540949445","pt":1719500347868,"mc":[{"id":"1.230178316","rc":[{"atl":[[5.8,3]],"id":57196226},{"atb":[[1.03,0.43]],"id":46611436}],"con":true,"img":false}]}
{"op":"mcm","clk":"11540949458","pt":1719500348074,"mc":[{"id":"1.230178316","rc":[{"atb":[[1.03,0]],"id":46611436}],"con":true,"img":false}]}
{"op":"mcm","clk":"11540949463","pt":1719500348170,"mc":[{"id":"1.230178316","rc":[{"atb":[[4.6,0.43]],"id":46611436}],"con":true,"img":false}]}
{"op":"mcm","clk":"11540949533","pt":1719500349165,"mc":[{"id":"1.230178316","rc":[{"atl":[[5.5,0.84]],"id":57196226}],"con":true,"img":false}]}
{"op":"mcm","clk":"11540949557","pt":1719500349579,"mc":[{"id":"1.230178316","rc":[{"atl":[[5.6,4],[5.8,0]],"id":57196226}],"con":true,"img":false}]}
{"op":"mcm","clk":"11540949579","pt":1719500349879,"mc":[{"id":"1.230178316","rc":[{"atl":[[5.7,0]],"id":57196226}],"con":true,"img":false}]}
{"op":"mcm","clk":"11540949595","pt":1719500350087,"mc":[{"id":"1.230178316","rc":[{"atl":[[5.5,1.84]],"id":57196226}],"con":true,"img":false}]}
{"op":"mcm","clk":"11540949819","pt":1719500352277,"mc":[{"id":"1.230178316","rc":[{"atb":[[1.25,20]],"id":57196226},{"atl":[[5.6,2]],"id":57196226},{"atb":[[1.25,20]],"id":46611436},{"atb":[[1.25,20]],"id":52655636},{"atb":[[1.25,20]],"id":70902601},{"atb":[[1.25,20]],"id":69685608},{"atb":[[1.25,20]],"id":49159417}],"con":true,"img":false}]}
{"op":"mcm","clk":"11540949952","pt":1719500353977,"mc":[{"id":"1.230178316","rc":[{"atb":[[2.54,0]],"id":57196226},{"atb":[[2.3,11.66]],"id":46611436},{"atb":[[2.28,12.44]],"id":52655636},{"atb":[[2.24,11.33]],"id":70902601},{"atb":[[2.9,0]],"id":69685608},{"atb":[[2.9,0]],"id":49159417}],"con":true,"img":false}]}
{"op":"mcm","clk":"11540949959","pt":1719500354079,"mc":[{"id":"1.230178316","rc":[{"atl":[[5.4,2]],"id":57196226}],"con":true,"img":false}]}
{"op":"mcm","clk":"11540950086","pt":1719500356200,"mc":[{"id":"1.230178316","rc":[{"atl":[[5.3,0.84]],"id":57196226}],"con":true,"img":false}]}
{"op":"mcm","clk":"11540950236","pt":1719500358574,"mc":[{"id":"1.230178316","rc":[{"atl":[[13,0],[1000,1.07]],"id":52655636}],"con":true,"img":false}]}
{"op":"mcm","clk":"11540950256","pt":1719500358892,"mc":[{"id":"1.230178316","rc":[{"atl":[[9.6,0.88]],"id":46611436}],"con":true,"img":false}]}
{"op":"mcm","clk":"11540950289","pt":1719500359297,"mc":[{"id":"1.230178316","rc":[{"atl":[[5.4,0]],"id":57196226}],"con":true,"img":false}]}
{"op":"mcm","clk":"11540950298","pt":1719500359401,"mc":[{"id":"1.230178316","rc":[{"atl":[[10,0.84]],"id":46611436}],"con":true,"img":false}]}
{"op":"mcm","clk":"11540950313","pt":1719500359565,"mc":[{"id":"1.230178316","rc":[{"atl":[[1000,0.88]],"id":52655636}],"con":true,"img":false}]}
{"op":"mcm","clk":"11540950319","pt":1719500359670,"mc":[{"id":"1.230178316","rc":[{"atl":[[5.3,0]],"id":57196226}],"con":true,"img":false}]}
{"op":"mcm","clk":"11540950344","pt":1719500359981,"mc":[{"id":"1.230178316","rc":[{"atl":[[1000,0.22]],"id":52655636}],"con":true,"img":false}]}
{"op":"mcm","clk":"11540950352","pt":1719500360086,"mc":[{"id":"1.230178316","rc":[{"atl":[[13.5,0.65]],"id":52655636}],"con":true,"img":false}]}
{"op":"mcm","clk":"11540950436","pt":1719500361375,"mc":[{"id":"1.230178316","rc":[{"atl":[[5.4,2]],"id":57196226}],"con":true,"img":false}]}
{"op":"mcm","clk":"11540950451","pt":1719500361583,"mc":[{"id":"1.230178316","rc":[{"atl":[[1000,1]],"id":57196226}],"con":true,"img":false}]}
{"op":"mcm","clk":"11540950470","pt":1719500361792,"mc":[{"id":"1.230178316","rc":[{"atl":[[1000,0.02]],"id":57196226}],"con":true,"img":false}]}
{"op":"mcm","clk":"11540950484","pt":1719500362094,"mc":[{"id":"1.230178316","rc":[{"atl":[[1000,0]],"id":57196226}],"con":true,"img":false}]}
{"op":"mcm","clk":"11540950499","pt":1719500362209,"mc":[{"id":"1.230178316","rc":[{"atl":[[5.4,2.02]],"id":57196226}],"con":true,"img":false}]}
{"op":"mcm","clk":"11540950563","pt":1719500362999,"mc":[{"id":"1.230178316","rc":[{"atl":[[9.8,0]],"id":46611436}],"con":true,"img":false}]}
{"op":"mcm","clk":"11540950595","pt":1719500363300,"mc":[{"id":"1.230178316","rc":[{"atl":[[5.3,0.84]],"id":57196226}],"con":true,"img":false}]}
{"op":"mcm","clk":"11540950605","pt":1719500363393,"mc":[{"id":"1.230178316","rc":[{"atb":[[4.6,0]],"id":46611436}],"con":true,"img":false}]}
{"op":"mcm","clk":"11540950648","pt":1719500363811,"mc":[{"id":"1.230178316","rc":[{"atl":[[5.4,2]],"id":57196226},{"atl":[[10,0]],"id":46611436}],"con":true,"img":false}]}
{"op":"mcm","clk":"11540950654","pt":1719500363871,"mc":[{"id":"1.230178316","rc":[{"atl":[[5.2,0.02]],"id":57196226}],"con":true,"img":false}]}
{"op":"mcm","clk":"11540950729","pt":1719500365016,"mc":[{"id":"1.230178316","rc":[{"atl":[[10.5,1.05]],"id":46611436}],"con":true,"img":false}]}
{"op":"mcm","clk":"11540950737","pt":1719500365118,"mc":[{"id":"1.230178316","rc":[{"atb":[[1.03,0.52]],"id":46611436}],"con":true,"img":false}]}
{"op":"mcm","clk":"11540950756","pt":1719500365291,"mc":[{"id":"1.230178316","rc":[{"atb":[[1.03,0.43]],"id":46611436}],"con":true,"img":false}]}
{"op":"mcm","clk":"11540950769","pt":1719500365491,"mc":[{"id":"1.230178316","rc":[{"atb":[[1.03,0]],"id":46611436}],"con":true,"img":false}]}
{"op":"mcm","clk":"11540950773","pt":1719500365582,"mc":[{"id":"1.230178316","rc":[{"atb":[[4.6,0.43]],"id":46611436}],"con":true,"img":false}]}
{"op":"mcm","clk":"11540950823","pt":1719500366205,"mc":[{"id":"1.230178316","rc":[{"atb":[[2.94,6.54]],"id":69685608}],"con":true,"img":false}]}
{"op":"mcm","clk":"11540950853","pt":1719500366508,"mc":[{"id":"1.230178316","rc":[{"atb":[[2.58,8.03]],"id":57196226},{"atb":[[2.94,6.54]],"id":49159417}],"con":true,"img":false}]}
{"op":"mcm","clk":"11540950868","pt":1719500366612,"mc":[{"id":"1.230178316","rc":[{"atl":[[5.4,0]],"id":57196226}],"con":true,"img":false}]}
{"op":"mcm","clk":"11540950935","pt":1719500367292,"mc":[{"id":"1.230178316","rc":[{"atl":[[5.3,0]],"id":57196226}],"con":true,"img":false}]}
{"op":"mcm","clk":"11540951070","pt":1719500368997,"mc":[{"id":"1.230178316","rc":[{"atl":[[5.4,2]],"id":57196226}],"con":true,"img":false}]}
{"op":"mcm","clk":"11540951190","pt":1719500370299,"mc":[{"id":"1.230178316","rc":[{"atl":[[5.3,0.84]],"id":57196226}],"con":true,"img":false}]}
{"op":"mcm","clk":"11540951273","pt":1719500371496,"mc":[{"id":"1.230178316","rc":[{"atb":[[2.92,6.16]],"id":69685608}],"con":true,"img":false}]}
{"op":"mcm","clk":"11540951289","pt":1719500371702,"mc":[{"id":"1.230178316","rc":[{"atb":[[2.92,6.16]],"id":49159417}],"con":true,"img":false}]}
{"op":"mcm","clk":"11540951302","pt":1719500371907,"mc":[{"id":"1.230178316","rc":[{"atb":[[2.96,3.15]],"id":69685608}],"con":true,"img":false}]}
{"op":"mcm","clk":"11540951367","pt":1719500372595,"mc":[{"id":"1.230178316","rc":[{"atb":[[2.96,3.15]],"id":49159417}],"con":true,"img":false}]}
{"op":"mcm","clk":"11540951513","pt":1719500374196,"mc":[{"id":"1.230178316","rc":[{"atl":[[5.4,0]],"id":57196226}],"con":true,"img":false}]}
{"op":"mcm","clk":"11540951578","pt":1719500374912,"mc":[{"id":"1.230178316","rc":[{"atl":[[5.3,0]],"id":57196226}],"con":true,"img":false}]}
{"op":"mcm","clk":"11540951650","pt":1719500375906,"mc":[{"id":"1.230178316","rc":[{"spl":[[1.01,4]],"id":57196226},{"spb":[[1000,11]],"id":46611436},{"spl":[[1.01,4]],"id":52655636},{"spl":[[1.01,3]],"id":70902601},{"spl":[[1.01,2]],"id":69685608},{"spb":[[1000,22]],"id":49159417}],"con":true,"img":false}]}
{"op":"mcm","clk":"11540951679","pt":1719500376328,"mc":[{"id":"1.230178316","rc":[{"atl":[[5.4,2]],"id":57196226}],"con":true,"img":false}]}
{"op":"mcm","clk":"11540951757","pt":1719500377206,"mc":[{"id":"1.230178316","rc":[{"atb":[[4.6,1.22]],"id":46611436},{"atb":[[4.3,15.15]],"id":52655636},{"atb":[[4.5,1.63]],"id":70902601},{"atb":[[5.1,1.63]],"id":69685608},{"atb":[[5.2,3.51]],"id":49159417}],"con":true,"img":false}]}
{"op":"mcm","clk":"11540951773","pt":1719500377417,"mc":[{"id":"1.230178316","rc":[{"atb":[[4.1,0]],"id":46611436}],"con":true,"img":false}]}
{"op":"mcm","clk":"11540951787","pt":1719500377616,"mc":[{"id":"1.230178316","rc":[{"atb":[[4.3,1]],"id":46611436}],"con":true,"img":false}]}
{"op":"mcm","clk":"11540951797","pt":1719500377719,"mc":[{"id":"1.230178316","rc":[{"atl":[[5.3,0.84]],"id":57196226}],"con":true,"img":false}]}
{"op":"mcm","clk":"11540952023","pt":1719500380425,"mc":[{"id":"1.230178316","rc":[{"atl":[[10.5,0]],"id":46611436}],"con":true,"img":false}]}
{"op":"mcm","clk":"11540952081","pt":1719500381011,"mc":[{"id":"1.230178316","rc":[{"atb":[[4.6,0.78]],"id":46611436}],"con":true,"img":false}]}
{"op":"mcm","clk":"11540952112","pt":1719500381325,"mc":[{"id":"1.230178316","rc":[{"atb":[[4.6,6.3]],"id":46611436}],"con":true,"img":false}]}
{"op":"mcm","clk":"11540952134","pt":1719500381535,"mc":[{"id":"1.230178316","rc":[{"atl":[[5.4,0]],"id":57196226},{"atb":[[4.3,0]],"id":46611436}],"con":true,"img":false}]}
{"op":"mcm","clk":"11540952149","pt":1719500381727,"mc":[{"id":"1.230178316","rc":[{"atb":[[4.7,1.84]],"id":46611436}],"con":true,"img":false}]}
{"op":"mcm","clk":"11540952169","pt":1719500382000,"mc":[{"id":"1.230178316","rc":[{"atb":[[4.6,0.78]],"id":46611436}],"con":true,"img":false}]}
{"op":"mcm","clk":"11540952187","pt":1719500382210,"mc":[{"id":"1.230178316","rc":[{"atl":[[5.3,0]],"id":57196226},{"atb":[[4.8,5.29]],"id":46611436}],"con":true,"img":false}]}
{"op":"mcm","clk":"11540952225","pt":1719500382622,"mc":[{"id":"1.230178316","rc":[{"atl":[[10.5,1.05]],"id":46611436}],"con":true,"img":false}]}
{"op":"mcm","clk":"11540952240","pt":1719500382815,"mc":[{"id":"1.230178316","rc":[{"atb":[[1.03,0.52]],"id":46611436}],"con":true,"img":false}]}
{"op":"mcm","clk":"11540952251","pt":1719500383021,"mc":[{"id":"1.230178316","rc":[{"atb":[[1.03,0.4]],"id":46611436}],"con":true,"img":false}]}
{"op":"mcm","clk":"11540952266","pt":1719500383227,"mc":[{"id":"1.230178316","rc":[{"atb":[[1.03,0]],"id":46611436}],"con":true,"img":false}]}
{"op":"mcm","clk":"11540952278","pt":1719500383331,"mc":[{"id":"1.230178316","rc":[{"atb":[[4.9,0.4]],"id":46611436}],"con":true,"img":false}]}
{"op":"mcm","clk":"11540952287","pt":1719500383435,"mc":[{"id":"1.230178316","rc":[{"atl":[[5.4,2]],"id":57196226}],"con":true,"img":false}]}
{"op":"mcm","clk":"11540952370","pt":1719500384728,"mc":[{"id":"1.230178316","rc":[{"atl":[[5.3,0.84]],"id":57196226}],"con":true,"img":false}]}
{"op":"mcm","clk":"11540952454","pt":1719500385628,"mc":[{"id":"1.230178316","rc":[{"atb":[[2.94,9.93]],"id":69685608}],"con":true,"img":false}]}
{"op":"mcm","clk":"11540952462","pt":1719500385731,"mc":[{"id":"1.230178316","rc":[{"atb":[[2.28,9.92]],"id":70902601}],"con":true,"img":false}]}
{"op":"mcm","clk":"11540952493","pt":1719500386031,"mc":[{"id":"1.230178316","rc":[{"atb":[[2.32,9.61]],"id":52655636}],"con":true,"img":false}]}
{"op":"mcm","clk":"11540952505","pt":1719500386136,"mc":[{"id":"1.230178316","rc":[{"atb":[[2.34,9.47]],"id":46611436}],"con":true,"img":false}]}
{"op":"mcm","clk":"11540952708","pt":1719500388633,"mc":[{"id":"1.230178316","rc":[{"atl":[[5.4,0]],"id":57196226}],"con":true,"img":false}]}
{"op":"mcm","clk":"11540952713","pt":1719500388725,"mc":[{"id":"1.230178316","rc":[{"atb":[[4.9,1.25]],"id":46611436},{"atl":[[9.6,0],[10,0.88]],"id":46611436}],"con":true,"img":false}]}
{"op":"mcm","clk":"11540952755","pt":1719500389213,"mc":[{"id":"1.230178316","rc":[{"atb":[[4.8,0]],"id":46611436}],"con":true,"img":false}]}
{"op":"mcm","clk":"11540952766","pt":1719500389310,"mc":[{"id":"1.230178316","rc":[{"atl":[[5.3,0]],"id":57196226}],"con":true,"img":false}]}
{"op":"mcm","clk":"11540952798","pt":1719500389717,"mc":[{"id":"1.230178316","rc":[{"atb":[[4.9,0.4]],"id":46611436}],"con":true,"img":false}]}
{"op":"mcm","clk":"11540952817","pt":1719500389928,"mc":[{"id":"1.230178316","rc":[{"atb":[[2.96,0]],"id":49159417}],"con":true,"img":false}]}
{"op":"mcm","clk":"11540952902","pt":1719500391019,"mc":[{"id":"1.230178316","rc":[{"atl":[[5.4,2]],"id":57196226}],"con":true,"img":false}]}
{"op":"mcm","clk":"11540952973","pt":1719500391745,"mc":[{"id":"1.230178316","rc":[{"atl":[[5.3,0.84]],"id":57196226}],"con":true,"img":false}]}
{"op":"mcm","clk":"11540953340","pt":1719500396334,"mc":[{"id":"1.230178316","rc":[{"atl":[[5.4,0]],"id":57196226}],"con":true,"img":false}]}
{"op":"mcm","clk":"11540953364","pt":1719500396738,"mc":[{"id":"1.230178316","rc":[{"atl":[[5.3,0]],"id":57196226}],"con":true,"img":false}]}
{"op":"mcm","clk":"11540953479","pt":1719500397843,"mc":[{"id":"1.230178316","rc":[{"atb":[[4.6,0]],"id":46611436}],"con":true,"img":false}]}
{"op":"mcm","clk":"11540953492","pt":1719500397952,"mc":[{"id":"1.230178316","rc":[{"atl":[[10.5,0]],"id":46611436}],"con":true,"img":false}]}
{"op":"mcm","clk":"11540953512","pt":1719500398156,"mc":[{"id":"1.230178316","rc":[{"atl":[[5.4,2]],"id":57196226},{"atb":[[4.8,5.29]],"id":46611436}],"con":true,"img":false}]}
{"op":"mcm","clk":"11540953558","pt":1719500398622,"mc":[{"id":"1.230178316","rc":[{"atb":[[4.9,0]],"id":46611436}],"con":true,"img":false}]}
{"op":"mcm","clk":"11540953569","pt":1719500398727,"mc":[{"id":"1.230178316","rc":[{"atl":[[5.3,0.84]],"id":57196226},{"atb":[[4.9,0.84]],"id":46611436}],"con":true,"img":false}]}
{"op":"mcm","clk":"11540953698","pt":1719500400225,"mc":[{"id":"1.230178316","rc":[{"atb":[[3.75,9.45]],"id":57196226},{"atl":[[5.3,6.3]],"id":57196226},{"spn":3.81,"spf":1.0,"id":57196226},{"atb":[[4.9,7.33]],"id":46611436},{"atl":[[14.5,1.96]],"id":46611436},{"spn":10.25,"spf":"Infinity","id":46611436},{"atb":[[5.1,8.74]],"id":52655636},{"atl":[[32,1.73]],"id":52655636},{"spn":5.1,"spf":1.0,"id":52655636},{"atl":[[9,3.6]],"id":70902601},{"spn":4.45,"spf":1.0,"id":70902601},{"spn":5.08,"spf":1.0,"id":69685608},{"atb":[[5.2,9.74]],"id":49159417},{"atl":[[10.5,4.12]],"id":49159417},{"spn":10.5,"spf":"Infinity","id":49159417}],"con":true,"img":false}]}
{"op":"mcm","clk":"11540953722","pt":1719500400431,"mc":[{"id":"1.230178316","rc":[{"atl":[[5.5,0.84]],"id":57196226},{"atl":[[10.5,1.05]],"id":46611436},{"atb":[[5.2,8.74]],"id":49159417}],"con":true,"img":false}]}
{"op":"mcm","clk":"11540953734","pt":1719500400536,"mc":[{"id":"1.230178316","rc":[{"atb":[[1.03,0.52]],"id":46611436},{"atl":[[13.5,0],[30,0.65]],"id":52655636}],"con":true,"img":false}]}
{"op":"mcm","clk":"11540953742","pt":1719500400625,"mc":[{"id":"1.230178316","rc":[{"atl":[[5.2,1.02]],"id":57196226},{"atb":[[4.8,0]],"id":46611436},{"atb":[[5.3,1]],"id":49159417}],"con":true,"img":false}]}
{"op":"mcm","clk":"11540953755","pt":1719500400746,"mc":[{"id":"1.230178316","rc":[{"atl":[[5.5,0]],"id":57196226},{"atb":[[4.7,1]],"id":46611436}],"con":true,"img":false}]}
{"op":"mcm","clk":"11540953766","pt":1719500400855,"mc":[{"id":"1.230178316","rc":[{"atb":[[3.85,7.19]],"id":57196226},{"atb":[[1.03,0.4],[5,5.07]],"id":46611436},{"atb":[[5.2,4.88]],"id":52655636},{"atl":[[30,0],[1000,1.07]],"id":52655636}],"con":true,"img":false}]}
{"op":"mcm","clk":"11540953779","pt":1719500400959,"mc":[{"id":"1.230178316","rc":[{"atl":[[5.4,0]],"id":57196226}],"con":true,"img":false}]}
{"op":"mcm","clk":"11540953794","pt":1719500401123,"mc":[{"id":"1.230178316","rc":[{"atb":[[3.75,8.61]],"id":57196226},{"atb":[[1.03,0]],"id":46611436},{"atb":[[5.3,2.44],[5.1,7.11]],"id":52655636}],"con":true,"img":false}]}
{"op":"mcm","clk":"11540953805","pt":1719500401229,"mc":[{"id":"1.230178316","rc":[{"atb":[[4.9,7.74]],"id":46611436}],"con":true,"img":false}]}
{"op":"mcm","clk":"11540953830","pt":1719500401451,"mc":[{"id":"1.230178316","rc":[{"atl":[[1000,0.85]],"id":52655636}],"con":true,"img":false}]}
{"op":"mcm","clk":"11540953838","pt":1719500401530,"mc":[{"id":"1.230178316","rc":[{"atb":[[5.2,0]],"id":52655636}],"con":true,"img":false}]}
{"op":"mcm","clk":"11540953854","pt":1719500401648,"mc":[{"id":"1.230178316","rc":[{"atb":[[3.85,8.6]],"id":57196226}],"con":true,"img":false}]}
{"op":"mcm","clk":"11540953859","pt":1719500401741,"mc":[{"id":"1.230178316","rc":[{"atb":[[5,11.12]],"id":46611436},{"atb":[[5.3,8.55]],"id":52655636},{"atl":[[1000,0.22]],"id":52655636}],"con":true,"img":false}]}
{"op":"mcm","clk":"11540953875","pt":1719500401862,"mc":[{"id":"1.230178316","rc":[{"atb":[[5.1,6.27]],"id":52655636},{"atl":[[13.5,0.62]],"id":52655636}],"con":true,"img":false}]}
{"op":"mcm","clk":"11540953885","pt":1719500401956,"mc":[{"id":"1.230178316","rc":[{"atb":[[4.7,0]],"id":46611436}],"con":true,"img":false}]}
{"op":"mcm","clk":"11540953916","pt":1719500402132,"mc":[{"id":"1.230178316","rc":[{"atb":[[5.1,1]],"id":46611436},{"atl":[[9.2,2]],"id":70902601}],"con":true,"img":false}]}
{"op":"mcm","clk":"11540953950","pt":1719500402456,"mc":[{"id":"1.230178316","rc":[{"atb":[[3.15,0]],"id":57196226}],"con":true,"img":false}]}
{"op":"mcm","clk":"11540954025","pt":1719500403041,"mc":[{"id":"1.230178316","rc":[{"atb":[[5,6.05]],"id":46611436}],"con":true,"img":false}]}
{"op":"mcm","clk":"11540954054","pt":1719500403249,"mc":[{"id":"1.230178316","rc":[{"atb":[[3.8,14.16],[2.56,7.6]],"id":57196226},{"atb":[[2.32,8.98],[3.1,15.34],[4.9,7.74],[5,8.05]],"id":46611436},{"atl":[[10.5,1.05]],"id":46611436},{"trd":[[6,6],[5,5.88],[5.9,1.69]],"ltp":6.0,"tv":13.57,"id":46611436},{"atb":[[4.3,15.16],[2.3,9.12]],"id":52655636},{"atb":[[2.26,9.4],[4.5,1.63]],"id":70902601},{"atb":[[2.92,6.17],[5.1,1.63],[2.96,3.16]],"id":69685608},{"atb":[[2.92,6.17],[5.2,8.74]],"id":49159417}],"con":true,"img":false}]}
{"op":"mcm","clk":"11540954168","pt":1719500404352,"mc":[{"id":"1.230178316","rc":[{"atb":[[3.85,8.6],[1.03,7.89],[2.58,8.03],[2.24,12.44]],"id":57196226},{"atl":[[5.3,6.3]],"id":57196226},{"atb":[[1.01,23.68],[2.3,11.66],[3.1,15.34],[4.9,7.74],[2.34,9.47]],"id":46611436},{"atl":[[10,0.88]],"id":46611436},{"trd":[[6,6],[5.9,1.69]],"ltp":6.0,"tv":7.68,"id":46611436},{"atb":[[2.32,9.61],[1.03,7.89],[5.3,2.44],[5.1,0],[2.28,12.44]],"id":52655636},{"atl":[[13.5,0.62]],"id":52655636},{"atb":[[1.01,23.68],[4.4,1.92],[2.24,11.33],[4.5,1.63],[2.28,9.92]],"id":70902601},{"atl":[[9,3.6]],"id":70902601},{"atb":[[1.01,24.68],[2.94,9.93],[2.24,11.55],[5.1,1.63]],"id":69685608},{"atl":[[18,1.69]],"id":69685608},{"atb":[[1.01,23.68],[2.94,6.54],[5.1,1.65],[5.2,8.74],[2.18,8.63]],"id":49159417},{"atl":[[10.5,4.12]],"id":49159417}],"con":true,"img":false}]}
{"op":"mcm","clk":"11540954189","pt":1719500404563,"mc":[{"id":"1.230178316","rc":[{"atb":[[3.85,17.66]],"id":57196226}],"con":true,"img":false}]}
{"op":"mcm","clk":"11540954268","pt":1719500405269,"mc":[{"id":"1.230178316","rc":[{"atb":[[5.3,7.59]],"id":52655636}],"con":true,"img":false}]}
{"op":"mcm","clk":"11540954291","pt":1719500405432,"mc":[{"id":"1.230178316","rc":[{"atb":[[2.26,13.72]],"id":70902601}],"con":true,"img":false}]}
{"op":"mcm","clk":"11540954306","pt":1719500405549,"mc":[{"id":"1.230178316","rc":[{"atl":[[1000,1.7]],"id":57196226},{"atb":[[1.04,1.7]],"id":69685608},{"atl":[[1000,1.93]],"id":69685608},{"atl":[[1000,1.93]],"id":49159417}],"con":true,"img":false}]}
{"op":"mcm","clk":"11540954321","pt":1719500405643,"mc":[{"id":"1.230178316","rc":[{"atb":[[1.04,1.7]],"id":57196226},{"atb":[[1.06,1.7]],"id":49159417}],"con":true,"img":false}]}
{"op":"mcm","clk":"11540954331","pt":1719500405745,"mc":[{"id":"1.230178316","rc":[{"atl":[[1000,0.04]],"id":57196226},{"atb":[[1.04,0.06]],"id":69685608},{"atl":[[1000,0.24]],"id":69685608},{"atl":[[1000,0.24]],"id":49159417}],"con":true,"img":false}]}
{"op":"mcm","clk":"11540954344","pt":1719500405847,"mc":[{"id":"1.230178316","rc":[{"atb":[[1.04,0.05]],"id":57196226},{"atb":[[1.06,0.03]],"id":49159417}],"con":true,"img":false}]}
{"op":"mcm","clk":"11540954360","pt":1719500406063,"mc":[{"id":"1.230178316","rc":[{"atl":[[1000,0]],"id":57196226},{"atb":[[1.04,0]],"id":69685608},{"atl":[[1000,0.22]],"id":69685608},{"atl":[[1000,0.22]],"id":49159417}],"con":true,"img":false}]}
{"op":"mcm","clk":"11540954370","pt":1719500406162,"mc":[{"id":"1.230178316","rc":[{"atb":[[1.04,0]],"id":57196226},{"atl":[[5.2,1.06]],"id":57196226},{"atb":[[5.1,1.7]],"id":69685608},{"atl":[[17.5,0.49]],"id":69685608},{"atb":[[1.06,0]],"id":49159417},{"atl":[[10,0.01]],"id":49159417}],"con":true,"img":false}]}
{"op":"mcm","clk":"11540954380","pt":1719500406268,"mc":[{"id":"1.230178316","rc":[{"atb":[[3.9,0.05]],"id":57196226},{"atb":[[5.3,1.03]],"id":49159417}],"con":true,"img":false}]}
{"op":"mcm","clk":"11540954409","pt":1719500406529,"mc":[{"id":"1.230178316","rc":[{"atb":[[2.94,3.38]],"id":69685608},{"atb":[[2.94,0]],"id":49159417}],"con":true,"img":false}]}
{"op":"mcm","clk":"11540954560","pt":1719500408041,"mc":[{"id":"1.230178316","rc":[{"atl":[[8.8,1.6]],"id":70902601}],"con":true,"img":false}]}
{"op":"mcm","clk":"11540954632","pt":1719500408862,"mc":[{"id":"1.230178316","rc":[{"atb":[[2.56,0]],"id":57196226},{"atb":[[2.92,0]],"id":69685608},{"atb":[[2.92,0]],"id":49159417}],"con":true,"img":false}]}
{"op":"mcm","clk":"11540954742","pt":1719500410057,"mc":[{"id":"1.230178316","rc":[{"atb":[[2.32,0]],"id":46611436},{"atb":[[2.3,0]],"id":52655636},{"atb":[[2.26,4.32]],"id":70902601}],"con":true,"img":false}]}
{"op":"mcm","clk":"11540955262","pt":1719500415285,"mc":[{"id":"1.230178316","rc":[{"atl":[[9.2,0],[8.8,3.6]],"id":70902601}],"con":true,"img":false}]}
{"op":"mcm","clk":"11540955271","pt":1719500415600,"mc":[{"id":"1.230178316","rc":[{"atl":[[5.6,0],[5.4,7.37]],"id":57196226}],"con":true,"img":false}]}
{"op":"mcm","clk":"11540955289","pt":1719500415920,"mc":[{"id":"1.230178316","rc":[{"atl":[[8.6,0.84]],"id":70902601}],"con":true,"img":false}]}
{"op":"mcm","clk":"11540955305","pt":1719500415989,"mc":[{"id":"1.230178316","rc":[{"atl":[[10.5,0]],"id":46611436}],"con":true,"img":false}]}
{"op":"mcm","clk":"11540955341","pt":1719500416335,"mc":[{"id":"1.230178316","rc":[{"atb":[[2.96,0]],"id":69685608}],"con":true,"img":false}]}
{"op":"mcm","clk":"11540955359","pt":1719500416439,"mc":[{"id":"1.230178316","rc":[{"atb":[[2.6,7.41]],"id":57196226}],"con":true,"img":false}]}
{"op":"mcm","clk":"11540955374","pt":1719500416545,"mc":[{"id":"1.230178316","rc":[{"atb":[[4.9,7.33]],"id":46611436}],"con":true,"img":false}]}
{"op":"mcm","clk":"11540955384","pt":1719500416646,"mc":[{"id":"1.230178316","rc":[{"atb":[[2.3,9.12]],"id":70902601}],"con":true,"img":false}]}
{"op":"mcm","clk":"11540955407","pt":1719500416855,"mc":[{"id":"1.230178316","rc":[{"atb":[[2.36,8.72]],"id":46611436},{"atb":[[2.34,8.84]],"id":52655636}],"con":true,"img":false}]}
{"op":"mcm","clk":"11540955475","pt":1719500417646,"mc":[{"id":"1.230178316","rc":[{"atb":[[2.26,0]],"id":70902601}],"con":true,"img":false}]}
{"op":"mcm","clk":"11540955573","pt":1719500418849,"mc":[{"id":"1.230178316","rc":[{"atl":[[10.5,0.88]],"id":46611436}],"con":true,"img":false}]}
{"op":"mcm","clk":"11540955583","pt":1719500418946,"mc":[{"id":"1.230178316","rc":[{"atl":[[10,0]],"id":46611436}],"con":true,"img":false}]}
{"op":"mcm","clk":"11540955658","pt":1719500419768,"mc":[{"id":"1.230178316","rc":[{"atl":[[10.5,1.93]],"id":46611436}],"con":true,"img":false}]}
{"op":"mcm","clk":"11540955668","pt":1719500419872,"mc":[{"id":"1.230178316","rc":[{"atb":[[1.03,0.52]],"id":46611436}],"con":true,"img":false}]}
{"op":"mcm","clk":"11540955682","pt":1719500420080,"mc":[{"id":"1.230178316","rc":[{"atb":[[1.03,0.37]],"id":46611436}],"con":true,"img":false}]}
{"op":"mcm","clk":"11540955691","pt":1719500420151,"mc":[{"id":"1.230178316","rc":[{"atl":[[10,0.84]],"id":46611436}],"con":true,"img":false}]}
{"op":"mcm","clk":"11540955710","pt":1719500420358,"mc":[{"id":"1.230178316","rc":[{"atb":[[1.03,0]],"id":46611436}],"con":true,"img":false}]}
{"op":"mcm","clk":"11540955720","pt":1719500420457,"mc":[{"id":"1.230178316","rc":[{"atb":[[5.2,0.37]],"id":46611436}],"con":true,"img":false}]}
{"op":"mcm","clk":"11540955728","pt":1719500420562,"mc":[{"id":"1.230178316","rc":[{"atl":[[10,3.65]],"id":46611436}],"con":true,"img":false}]}
{"op":"mcm","clk":"11540955960","pt":1719500423172,"mc":[{"id":"1.230178316","rc":[{"atb":[[5.2,7.07]],"id":49159417}],"con":true,"img":false}]}
{"op":"mcm","clk":"11540956710","pt":1719500433186,"mc":[{"id":"1.230178316","rc":[{"atb":[[2.28,14.18]],"id":70902601},{"atb":[[2.88,3.16]],"id":69685608}],"con":true,"img":false}]}
{"op":"mcm","clk":"11540956726","pt":1719500433364,"mc":[{"id":"1.230178316","rc":[{"atb":[[2.88,6.3]],"id":49159417}],"con":true,"img":false}]}
{"op":"mcm","clk":"11540956823","pt":1719500434959,"mc":[{"id":"1.230178316","rc":[{"atb":[[2.94,0]],"id":69685608}],"con":true,"img":false}]}
{"op":"mcm","clk":"11540956828","pt":1719500435056,"mc":[{"id":"1.230178316","rc":[{"atl":[[10.5,0.88]],"id":46611436}],"con":true,"img":false}]}
{"op":"mcm","clk":"11540956881","pt":1719500435780,"mc":[{"id":"1.230178316","rc":[{"atb":[[5.2,0]],"id":46611436}],"con":true,"img":false}]}
{"op":"mcm","clk":"11540957055","pt":1719500438365,"mc":[{"id":"1.230178316","rc":[{"atb":[[1.03,0.52]],"id":46611436},{"atl":[[9.8,1.05]],"id":46611436}],"con":true,"img":false}]}
{"op":"mcm","clk":"11540957072","pt":1719500438566,"mc":[{"id":"1.230178316","rc":[{"atb":[[1.03,0.37]],"id":46611436}],"con":true,"img":false}]}
{"op":"mcm","clk":"11540957090","pt":1719500438772,"mc":[{"id":"1.230178316","rc":[{"atb":[[1.03,0]],"id":46611436}],"con":true,"img":false}]}
{"op":"mcm","clk":"11540957099","pt":1719500438886,"mc":[{"id":"1.230178316","rc":[{"atb":[[5.2,0.37]],"id":46611436}],"con":true,"img":false}]}
{"op":"mcm","clk":"11540957128","pt":1719500439290,"mc":[{"id":"1.230178316","rc":[{"atb":[[2.28,9.92]],"id":70902601}],"con":true,"img":false}]}
{"op":"mcm","clk":"11540957195","pt":1719500440387,"mc":[{"id":"1.230178316","rc":[{"atb":[[4.4,1.7]],"id":52655636}],"con":true,"img":false}]}
{"op":"mcm","clk":"11540957296","pt":1719500441687,"mc":[{"id":"1.230178316","rc":[{"atb":[[3.9,0]],"id":57196226},{"atl":[[5.2,1.02]],"id":57196226},{"atb":[[5.1,1.63]],"id":69685608},{"atl":[[17.5,0.48]],"id":69685608},{"atb":[[5.3,1]],"id":49159417},{"atl":[[10,0]],"id":49159417}],"con":true,"img":false}]}
{"op":"mcm","clk":"11540958184","pt":1719500453798,"mc":[{"id":"1.230178316","rc":[{"atl":[[9.8,0]],"id":46611436}],"con":true,"img":false}]}
{"op":"mcm","clk":"11540958234","pt":1719500454303,"mc":[{"id":"1.230178316","rc":[{"atb":[[5.2,0]],"id":46611436}],"con":true,"img":false}]}
{"op":"mcm","clk":"11540958436","pt":1719500456800,"mc":[{"id":"1.230178316","rc":[{"atl":[[9.8,1.05]],"id":46611436}],"con":true,"img":false}]}
{"op":"mcm","clk":"11540958458","pt":1719500457105,"mc":[{"id":"1.230178316","rc":[{"atb":[[1.03,0.52]],"id":46611436}],"con":true,"img":false}]}
{"op":"mcm","clk":"11540958471","pt":1719500457313,"mc":[{"id":"1.230178316","rc":[{"atb":[[1.03,0.37]],"id":46611436}],"con":true,"img":false}]}
{"op":"mcm","clk":"11540958484","pt":1719500457508,"mc":[{"id":"1.230178316","rc":[{"atb":[[1.03,0]],"id":46611436}],"con":true,"img":false}]}
{"op":"mcm","clk":"11540958490","pt":1719500457611,"mc":[{"id":"1.230178316","rc":[{"atb":[[5.2,0.37]],"id":46611436}],"con":true,"img":false}]}
{"op":"mcm","clk":"11540958566","pt":1719500458603,"mc":[{"id":"1.230178316","rc":[{"atb":[[4.3,7]],"id":52655636}],"con":true,"img":false}]}
{"op":"mcm","clk":"11540958619","pt":1719500459213,"mc":[{"id":"1.230178316","rc":[{"atb":[[2.58,0]],"id":57196226},{"atb":[[2.34,0]],"id":46611436},{"atb":[[2.32,0]],"id":52655636},{"atb":[[2.28,0]],"id":70902601}],"con":true,"img":false}]}
{"op":"mcm","clk":"11540958642","pt":1719500459522,"mc":[{"id":"1.230178316","rc":[{"atl":[[8.6,4.28]],"id":70902601}],"con":true,"img":false}]}
{"op":"mcm","clk":"11540958684","pt":1719500459997,"mc":[{"id":"1.230178316","rc":[{"atl":[[8.4,3.02]],"id":70902601}],"con":true,"img":false}]}
{"op":"mcm","clk":"11540958701","pt":1719500460212,"mc":[{"id":"1.230178316","rc":[{"atl":[[9,2.76]],"id":70902601}],"con":true,"img":false}]}
{"op":"mcm","clk":"11540958715","pt":1719500460312,"mc":[{"id":"1.230178316","rc":[{"atl":[[5.4,7.63]],"id":57196226},{"spn":3.85,"spf":1.0,"id":57196226},{"atl":[[9.6,0.26]],"id":46611436},{"spn":9.75,"spf":"Infinity","id":46611436},{"atl":[[13,0.26]],"id":52655636},{"spn":5.3,"spf":1.0,"id":52655636},{"atl":[[8.2,0.26],[8.4,6.13]],"id":70902601},{"atl":[[17,0.26]],"id":69685608},{"atl":[[10,0.26]],"id":49159417},{"spn":10.44,"spf":"Infinity","id":49159417}],"con":true,"img":false}]}
{"op":"mcm","clk":"11540958727","pt":1719500460413,"mc":[{"id":"1.230178316","rc":[{"atl":[[34,1.66]],"id":52655636},{"atl":[[1000,0.5]],"id":69685608}],"con":true,"img":false}]}
{"op":"mcm","clk":"11540958738","pt":1719500460517,"mc":[{"id":"1.230178316","rc":[{"atl":[[1000,0.74]],"id":46611436},{"atl":[[17,4.69],[1000,0.58]],"id":52655636},{"atl":[[1000,0.61]],"id":70902601}],"con":true,"img":false}]}
{"op":"mcm","clk":"11540958749","pt":1719500460611,"mc":[{"id":"1.230178316","rc":[{"atl":[[1000,0.22]],"id":46611436},{"atl":[[32,0.73],[1000,0.22]],"id":52655636},{"atl":[[1000,0]],"id":70902601},{"atl":[[1000,0.22]],"id":69685608}],"con":true,"img":false}]}
{"op":"mcm","clk":"11540958758","pt":1719500460723,"mc":[{"id":"1.230178316","rc":[{"atl":[[9.8,1.57]],"id":46611436},{"atl":[[14,1.36]],"id":52655636},{"atl":[[8.2,1.1],[8.4,6.74]],"id":70902601},{"atl":[[18,1.97]],"id":69685608}],"con":true,"img":false}]}
{"op":"mcm","clk":"11540958765","pt":1719500460817,"mc":[{"id":"1.230178316","rc":[{"atl":[[16.5,1]],"id":52655636}],"con":true,"img":false}]}
{"op":"mcm","clk":"11540958783","pt":1719500461080,"mc":[{"id":"1.230178316","rc":[{"atl":[[8.4,3.72]],"id":70902601}],"con":true,"img":false}]}
{"op":"mcm","clk":"11540958795","pt":1719500461193,"mc":[{"id":"1.230178316","rc":[{"atl":[[9.6,1.1]],"id":46611436}],"con":true,"img":false}]}
{"op":"mcm","clk":"11540958802","pt":1719500461292,"mc":[{"id":"1.230178316","rc":[{"atl":[[9.6,4.21]],"id":46611436},{"atl":[[8.2,4.77]],"id":70902601}],"con":true,"img":false}]}
{"op":"mcm","clk":"11540958811","pt":1719500461404,"mc":[{"id":"1.230178316","rc":[{"atb":[[3.9,0.26]],"id":57196226},{"atb":[[5.3,0.26]],"id":46611436},{"atb":[[5.4,0.26]],"id":52655636},{"atb":[[4.1,0.26]],"id":70902601},{"atb":[[5.2,0.26]],"id":69685608},{"atb":[[5.4,0.26]],"id":49159417}],"con":true,"img":false}]}
{"op":"mcm","clk":"11540958846","pt":1719500461811,"mc":[{"id":"1.230178316","rc":[{"atl":[[10,2.81]],"id":46611436},{"atl":[[8.6,3.44]],"id":70902601}],"con":true,"img":false}]}
{"op":"mcm","clk":"11540958856","pt":1719500461912,"mc":[{"id":"1.230178316","rc":[{"atl":[[8,3.17]],"id":70902601}],"con":true,"img":false}]}
{"op":"mcm","clk":"11540958882","pt":1719500462224,"mc":[{"id":"1.230178316","rc":[{"atl":[[9,0]],"id":70902601}],"con":true,"img":false}]}
{"op":"mcm","clk":"11540958892","pt":1719500462319,"mc":[{"id":"1.230178316","rc":[{"atl":[[13.5,2.52]],"id":52655636},{"atb":[[4.2,7.32]],"id":70902601},{"atl":[[8,7.05]],"id":70902601}],"con":true,"img":false}]}
{"op":"mcm","clk":"11540958919","pt":1719500462495,"mc":[{"id":"1.230178316","rc":[{"atb":[[3.3,0]],"id":70902601}],"con":true,"img":false}]}
{"op":"mcm","clk":"11540958934","pt":1719500462697,"mc":[{"id":"1.230178316","rc":[{"atl":[[13,1.1]],"id":52655636},{"atb":[[4.3,2]],"id":70902601}],"con":true,"img":false}]}
{"op":"mcm","clk":"11540958939","pt":1719500462795,"mc":[{"id":"1.230178316","rc":[{"atl":[[34,0]],"id":52655636}],"con":true,"img":false}]}
{"op":"mcm","clk":"11540958947","pt":1719500462889,"mc":[{"id":"1.230178316","rc":[{"atl":[[13,3]],"id":52655636}],"con":true,"img":false}]}
{"op":"mcm","clk":"11540958958","pt":1719500463007,"mc":[{"id":"1.230178316","rc":[{"atl":[[16.5,0]],"id":52655636}],"con":true,"img":false}]}
{"op":"mcm","clk":"11540958975","pt":1719500463209,"mc":[{"id":"1.230178316","rc":[{"atl":[[12.5,1]],"id":52655636},{"atl":[[8.8,2]],"id":70902601}],"con":true,"img":false}]}
{"op":"mcm","clk":"11540959104","pt":1719500464811,"mc":[{"id":"1.230178316","rc":[{"atb":[[2.88,9.47]],"id":69685608}],"con":true,"img":false}]}
{"op":"mcm","clk":"11540959165","pt":1719500465800,"mc":[{"id":"1.230178316","rc":[{"atl":[[12,1.69]],"id":52655636}],"con":true,"img":false}]}
{"op":"mcm","clk":"11540959195","pt":1719500466214,"mc":[{"id":"1.230178316","rc":[{"atl":[[13,2.16]],"id":52655636}],"con":true,"img":false}]}
{"op":"mcm","clk":"11540959277","pt":1719500467198,"mc":[{"id":"1.230178316","rc":[{"atl":[[12,3.85]],"id":52655636}],"con":true,"img":false}]}
{"op":"mcm","clk":"11540959295","pt":1719500467498,"mc":[{"id":"1.230178316","rc":[{"atl":[[12.5,0]],"id":52655636}],"con":true,"img":false}]}
{"op":"mcm","clk":"11540959310","pt":1719500467713,"mc":[{"id":"1.230178316","rc":[{"atl":[[11.5,1]],"id":52655636}],"con":true,"img":false}]}
{"op":"mcm","clk":"11540959315","pt":1719500467810,"mc":[{"id":"1.230178316","rc":[{"atl":[[7.8,0.84]],"id":70902601}],"con":true,"img":false}]}
{"op":"mcm","clk":"11540959341","pt":1719500468125,"mc":[{"id":"1.230178316","rc":[{"atl":[[8,3.88]],"id":70902601}],"con":true,"img":false}]}
{"op":"mcm","clk":"11540959610","pt":1719500472100,"mc":[{"id":"1.230178316","rc":[{"atb":[[2.9,6.68]],"id":49159417}],"con":true,"img":false}]}
{"op":"mcm","clk":"11540959615","pt":1719500472205,"mc":[{"id":"1.230178316","rc":[{"atl":[[9.8,0.52]],"id":46611436}],"con":true,"img":false}]}
{"op":"mcm","clk":"11540959624","pt":1719500472309,"mc":[{"id":"1.230178316","rc":[{"atb":[[2.62,7.84]],"id":57196226}],"con":true,"img":false}]}
{"op":"mcm","clk":"11540959633","pt":1719500472414,"mc":[{"id":"1.230178316","rc":[{"atb":[[2.32,9.61]],"id":70902601}],"con":true,"img":false}]}
{"op":"mcm","clk":"11540959654","pt":1719500472623,"mc":[{"id":"1.230178316","rc":[{"atb":[[2.36,9.33]],"id":52655636}],"con":true,"img":false}]}
{"op":"mcm","clk":"11540959664","pt":1719500472728,"mc":[{"id":"1.230178316","rc":[{"atb":[[2.38,9.2]],"id":46611436}],"con":true,"img":false}]}
{"op":"mcm","clk":"11540959691","pt":1719500472993,"mc":[{"id":"1.230178316","rc":[{"atb":[[5.2,0]],"id":46611436}],"con":true,"img":false}]}
{"op":"mcm","clk":"11540959834","pt":1719500474706,"mc":[{"id":"1.230178316","rc":[{"atl":[[9.4,1.05]],"id":46611436}],"con":true,"img":false}]}
{"op":"mcm","clk":"11540959846","pt":1719500474810,"mc":[{"id":"1.230178316","rc":[{"atl":[[9.6,5.26],[9.8,0]],"id":46611436},{"atl":[[8.4,3.11]],"id":70902601},{"atl":[[18,1.69]],"id":69685608}],"con":true,"img":false}]}
{"op":"mcm","clk":"11540959852","pt":1719500474914,"mc":[{"id":"1.230178316","rc":[{"atb":[[1.03,0.52]],"id":46611436},{"atl":[[14,1]],"id":52655636}],"con":true,"img":false}]}
{"op":"mcm","clk":"11540959863","pt":1719500475121,"mc":[{"id":"1.230178316","rc":[{"atb":[[1.03,0.37]],"id":46611436}],"con":true,"img":false}]}
{"op":"mcm","clk":"11540959875","pt":1719500475335,"mc":[{"id":"1.230178316","rc":[{"atb":[[1.03,0]],"id":46611436}],"con":true,"img":false}]}
{"op":"mcm","clk":"11540959882","pt":1719500475431,"mc":[{"id":"1.230178316","rc":[{"atb":[[5.2,0.37]],"id":46611436}],"con":true,"img":false}]}
{"op":"mcm","clk":"11540960102","pt":1719500478904,"mc":[{"id":"1.230178316","rc":[{"atl":[[17.5,0],[1000,1.07]],"id":69685608}],"con":true,"img":false}]}
{"op":"mcm","clk":"11540960114","pt":1719500479016,"mc":[{"id":"1.230178316","rc":[{"atl":[[5.9,1]],"id":57196226},{"atl":[[13.5,3.52],[14,0]],"id":52655636},{"atl":[[18,2.69]],"id":69685608}],"con":true,"img":false}]}
{"op":"mcm","clk":"11540960122","pt":1719500479119,"mc":[{"id":"1.230178316","rc":[{"atb":[[2.6,23.09],[2.46,0]],"id":57196226},{"atl":[[6.2,0],[5.2,7.33],[5.4,0.26]],"id":57196226},{"atb":[[4.4,3.5],[4,0]],"id":46611436},{"atl":[[13.5,7.14],[15,0]],"id":46611436},{"atb":[[4.3,1],[4.6,4.04]],"id":52655636},{"atl":[[15.5,4.69],[17,0]],"id":52655636},{"atb":[[3.1,6],[3.35,9.62]],"id":70902601},{"atl":[[8.2,9.5],[8.8,0]],"id":70902601},{"atb":[[5.1,3.63],[4.6,0]],"id":69685608},{"atl":[[18.5,0],[19.5,3.45],[23,0]],"id":69685608},{"atb":[[4,0],[4.5,2.5]],"id":49159417}],"con":true,"img":false}]}
{"op":"mcm","clk":"11540960130","pt":1719500479219,"mc":[{"id":"1.230178316","rc":[{"atl":[[9.2,0.92]],"id":46611436},{"atb":[[5.5,1.54]],"id":52655636},{"atl":[[13.5,2.52],[14,1]],"id":52655636},{"atl":[[18,1.69]],"id":69685608}],"con":true,"img":false}]}
{"op":"mcm","clk":"11540960138","pt":1719500479323,"mc":[{"id":"1.230178316","rc":[{"atl":[[12.5,1]],"id":52655636},{"atl":[[18.5,1],[29,0]],"id":69685608},{"atl":[[14,7.69],[15,0]],"id":49159417}],"con":true,"img":false}]}
{"op":"mcm","clk":"11540960152","pt":1719500479529,"mc":[{"id":"1.230178316","rc":[{"atl":[[10.5,0]],"id":46611436},{"atb":[[5.3,5.99]],"id":52655636},{"atl":[[18,2.69],[18.5,0]],"id":69685608}],"con":true,"img":false}]}
{"op":"mcm","clk":"11540960160","pt":1719500479638,"mc":[{"id":"1.230178316","rc":[{"atl":[[14,0]],"id":52655636},{"atl":[[19,1]],"id":69685608}],"con":true,"img":false}]}
{"op":"mcm","clk":"11540960164","pt":1719500479736,"mc":[{"id":"1.230178316","rc":[{"atl":[[5.1,0.84]],"id":57196226},{"atb":[[2.9,2.59]],"id":69685608}],"con":true,"img":false}]}
{"op":"mcm","clk":"11540960173","pt":1719500479792,"mc":[{"id":"1.230178316","rc":[{"atl":[[5.2,13.43]],"id":57196226},{"atb":[[5.5,6.06]],"id":52655636},{"atl":[[1000,0.74]],"id":69685608}],"con":true,"img":false}]}
{"op":"mcm","clk":"11540960196","pt":1719500480107,"mc":[{"id":"1.230178316","rc":[{"atl":[[5.2,12.43]],"id":57196226},{"atb":[[5.4,1.8]],"id":52655636}],"con":true,"img":false}]}
{"op":"mcm","clk":"11540960202","pt":1719500480209,"mc":[{"id":"1.230178316","rc":[{"atb":[[5.3,5.15],[5.6,0.84]],"id":52655636},{"atl":[[1000,0.22]],"id":69685608}],"con":true,"img":false}]}
{"op":"mcm","clk":"11540960211","pt":1719500480312,"mc":[{"id":"1.230178316","rc":[{"atl":[[16.5,0.51]],"id":69685608}],"con":true,"img":false}]}
{"op":"mcm","clk":"11540960217","pt":1719500480416,"mc":[{"id":"1.230178316","rc":[{"atl":[[5.1,1.84]],"id":57196226}],"con":true,"img":false}]}
{"op":"mcm","clk":"11540960224","pt":1719500480519,"mc":[{"id":"1.230178316","rc":[{"atb":[[5.1,2.84]],"id":69685608}],"con":true,"img":false}]}
{"op":"mcm","clk":"11540960231","pt":1719500480623,"mc":[{"id":"1.230178316","rc":[{"atl":[[5.1,7.54]],"id":57196226},{"atl":[[1000,0.76]],"id":46611436},{"atb":[[5.4,0.26],[5.6,2.36]],"id":52655636},{"atl":[[1000,0.66]],"id":52655636},{"atl":[[1000,0.64]],"id":70902601},{"atl":[[1000,0.5]],"id":69685608}],"con":true,"img":false}]}
{"op":"mcm","clk":"11540960245","pt":1719500480832,"mc":[{"id":"1.230178316","rc":[{"atl":[[5.3,5.46]],"id":57196226},{"atl":[[1000,0.22]],"id":46611436},{"atl":[[1000,0.22]],"id":52655636},{"atl":[[1000,0]],"id":70902601},{"atl":[[1000,0.22]],"id":69685608}],"con":true,"img":false}]}
{"op":"mcm","clk":"11540960253","pt":1719500480938,"mc":[{"id":"1.230178316","rc":[{"atl":[[9.4,1.59]],"id":46611436},{"atl":[[11.5,1.44]],"id":52655636},{"atl":[[8,4.52]],"id":70902601},{"atl":[[18,2.97]],"id":69685608}],"con":true,"img":false}]}
{"op":"mcm","clk":"11540960290","pt":1719500481509,"mc":[{"id":"1.230178316","rc":[{"atl":[[32,0]],"id":52655636}],"con":true,"img":false}]}
{"op":"mcm","clk":"11540960343","pt":1719500482033,"mc":[{"id":"1.230178316","rc":[{"atl":[[9.2,4.19]],"id":46611436},{"atb":[[5.6,7.66]],"id":52655636},{"atl":[[11.5,3.71]],"id":52655636},{"atl":[[9.2,1],[9.4,0]],"id":70902601},{"atl":[[18,1.97],[18.5,1]],"id":69685608}],"con":true,"img":false}]}
{"op":"mcm","clk":"11540960346","pt":1719500482131,"mc":[{"id":"1.230178316","rc":[{"atl":[[12.5,0],[14,1]],"id":52655636}],"con":true,"img":false}]}
{"op":"mcm","clk":"11540960371","pt":1719500482451,"mc":[{"id":"1.230178316","rc":[{"atb":[[5.7,4.45]],"id":52655636}],"con":true,"img":false}]}
{"op":"mcm","clk":"11540960387","pt":1719500482615,"mc":[{"id":"1.230178316","rc":[{"atl":[[9,0.84],[9.6,4.42]],"id":46611436},{"atl":[[11,0.84]],"id":52655636}],"con":true,"img":false}]}
{"op":"mcm","clk":"11540960412","pt":1719500482925,"mc":[{"id":"1.230178316","rc":[{"atb":[[5,1.02]],"id":52655636}],"con":true,"img":false}]}
{"op":"mcm","clk":"11540960418","pt":1719500483025,"mc":[{"id":"1.230178316","rc":[{"atb":[[5.7,9.22]],"id":52655636}],"con":true,"img":false}]}
{"op":"mcm","clk":"11540960486","pt":1719500483900,"mc":[{"id":"1.230178316","rc":[{"atl":[[12,2.16]],"id":52655636}],"con":true,"img":false}]}
{"op":"mcm","clk":"11540960568","pt":1719500484934,"mc":[{"id":"1.230178316","rc":[{"atl":[[5.1,15.09],[5.2,6.12]],"id":57196226}],"con":true,"img":false}]}
{"op":"mcm","clk":"11540960592","pt":1719500485256,"mc":[{"id":"1.230178316","rc":[{"atl":[[5.1,14.09]],"id":57196226}],"con":true,"img":false}]}
{"op":"mcm","clk":"11540960617","pt":1719500485403,"mc":[{"id":"1.230178316","rc":[{"atl":[[5,1]],"id":57196226}],"con":true,"img":false}]}
{"op":"mcm","clk":"11540960730","pt":1719500487110,"mc":[{"id":"1.230178316","rc":[{"atb":[[5.8,0.84]],"id":52655636}],"con":true,"img":false}]}
{"op":"mcm","clk":"11540960781","pt":1719500487735,"mc":[{"id":"1.230178316","rc":[{"atb":[[5.7,4.77]],"id":52655636}],"con":true,"img":false}]}
{"op":"mcm","clk":"11540960904","pt":1719500489805,"mc":[{"id":"1.230178316","rc":[{"atl":[[11,2.38]],"id":52655636}],"con":true,"img":false}]}
{"op":"mcm","clk":"11540960922","pt":1719500490015,"mc":[{"id":"1.230178316","rc":[{"atl":[[9.4,0.54]],"id":46611436}],"con":true,"img":false}]}
{"op":"mcm","clk":"11540960986","pt":1719500490842,"mc":[{"id":"1.230178316","rc":[{"atb":[[5.2,0]],"id":46611436}],"con":true,"img":false}]}
{"op":"mcm","clk":"11540961001","pt":1719500491050,"mc":[{"id":"1.230178316","rc":[{"atl":[[13.5,0.62]],"id":52655636}],"con":true,"img":false}]}
{"op":"mcm","clk":"11540961008","pt":1719500491151,"mc":[{"id":"1.230178316","rc":[{"atl":[[11,4.79]],"id":52655636}],"con":true,"img":false}]}
{"op":"mcm","clk":"11540961023","pt":1719500491349,"mc":[{"id":"1.230178316","rc":[{"atl":[[11.5,2.71]],"id":52655636}],"con":true,"img":false}]}
{"op":"mcm","clk":"11540961040","pt":1719500491559,"mc":[{"id":"1.230178316","rc":[{"atl":[[10.5,1]],"id":52655636}],"con":true,"img":false}]}
{"op":"mcm","clk":"11540961102","pt":1719500492443,"mc":[{"id":"1.230178316","rc":[{"atb":[[2.6,15.68]],"id":57196226},{"atb":[[2.36,0]],"id":46611436},{"atb":[[2.34,0]],"id":52655636},{"atb":[[2.3,0]],"id":70902601}],"con":true,"img":false}]}
{"op":"mcm","clk":"11540961194","pt":1719500493543,"mc":[{"id":"1.230178316","rc":[{"atl":[[9,1.89]],"id":46611436}],"con":true,"img":false}]}
{"op":"mcm","clk":"11540961202","pt":1719500493620,"mc":[{"id":"1.230178316","rc":[{"atb":[[1.03,0.52]],"id":46611436}],"con":true,"img":false}]}
{"op":"mcm","clk":"11540961217","pt":1719500493827,"mc":[{"id":"1.230178316","rc":[{"atb":[[1.03,0.37]],"id":46611436},{"atl":[[8.8,0.96]],"id":46611436}],"con":true,"img":false}]}
{"op":"mcm","clk":"11540961228","pt":1719500493934,"mc":[{"id":"1.230178316","rc":[{"atl":[[9.2,3.27]],"id":46611436}],"con":true,"img":false}]}
{"op":"mcm","clk":"11540961230","pt":1719500494033,"mc":[{"id":"1.230178316","rc":[{"atb":[[1.03,0]],"id":46611436}],"con":true,"img":false}]}
{"op":"mcm","clk":"11540961241","pt":1719500494144,"mc":[{"id":"1.230178316","rc":[{"atb":[[5.2,0.37]],"id":46611436},{"atl":[[14.5,0]],"id":46611436},{"atl":[[12.5,1],[14,0]],"id":52655636},{"atl":[[18,2.97],[18.5,0]],"id":69685608}],"con":true,"img":false}]}
{"op":"mcm","clk":"11540961255","pt":1719500494343,"mc":[{"id":"1.230178316","rc":[{"atl":[[8.8,4.2]],"id":46611436}],"con":true,"img":false}]}
{"op":"mcm","clk":"11540961285","pt":1719500494709,"mc":[{"id":"1.230178316","rc":[{"atl":[[8.6,0.84]],"id":46611436}],"con":true,"img":false}]}
{"op":"mcm","clk":"11540961306","pt":1719500494919,"mc":[{"id":"1.230178316","rc":[{"atl":[[9,3.01]],"id":46611436}],"con":true,"img":false}]}
{"op":"mcm","clk":"11540961336","pt":1719500495229,"mc":[{"id":"1.230178316","rc":[{"atl":[[9.4,0]],"id":46611436},{"atl":[[11.5,2.27]],"id":52655636},{"atl":[[8,3.88]],"id":70902601},{"atl":[[18,2.69]],"id":69685608}],"con":true,"img":false}]}
{"op":"mcm","clk":"11540961446","pt":1719500496742,"mc":[{"id":"1.230178316","rc":[{"atl":[[10,1.1]],"id":49159417}],"con":true,"img":false}]}
{"op":"mcm","clk":"11540961451","pt":1719500496847,"mc":[{"id":"1.230178316","rc":[{"atl":[[10,3.6]],"id":49159417}],"con":true,"img":false}]}
{"op":"mcm","clk":"11540961477","pt":1719500497110,"mc":[{"id":"1.230178316","rc":[{"atl":[[9.8,0.84]],"id":49159417}],"con":true,"img":false}]}
{"op":"mcm","clk":"11540961525","pt":1719500497738,"mc":[{"id":"1.230178316","rc":[{"atl":[[18,1.69],[18.5,1]],"id":69685608}],"con":true,"img":false}]}
{"op":"mcm","clk":"11540961543","pt":1719500497935,"mc":[{"id":"1.230178316","rc":[{"atl":[[12.5,0]],"id":52655636}],"con":true,"img":false}]}
{"op":"mcm","clk":"11540961596","pt":1719500498454,"mc":[{"id":"1.230178316","rc":[{"atb":[[2.64,7.23]],"id":57196226}],"con":true,"img":false}]}
{"op":"mcm","clk":"11540961604","pt":1719500498513,"mc":[{"id":"1.230178316","rc":[{"atb":[[2.34,8.84]],"id":70902601}],"con":true,"img":false}]}
{"op":"mcm","clk":"11540961612","pt":1719500498613,"mc":[{"id":"1.230178316","rc":[{"atb":[[2.4,8.46]],"id":46611436}],"con":true,"img":false}]}
{"op":"mcm","clk":"11540961777","pt":1719500500630,"mc":[{"id":"1.230178316","rc":[{"atl":[[1000,0.8]],"id":46611436},{"atb":[[4.4,0]],"id":52655636},{"atl":[[1000,0.64]],"id":70902601},{"atl":[[1000,0.5]],"id":69685608}],"con":true,"img":false}]}
{"op":"mcm","clk":"11540961790","pt":1719500500833,"mc":[{"id":"1.230178316","rc":[{"atl":[[1000,0.22]],"id":46611436},{"atl":[[1000,0]],"id":70902601},{"atl":[[1000,0.22]],"id":69685608}],"con":true,"img":false}]}
{"op":"mcm","clk":"11540961797","pt":1719500501191,"mc":[{"id":"1.230178316","rc":[{"atl":[[8.8,4.78]],"id":46611436},{"atl":[[8,4.52]],"id":70902601},{"atl":[[18,1.97]],"id":69685608}],"con":true,"img":false}]}
{"op":"mcm","clk":"11540961877","pt":1719500501818,"mc":[{"id":"1.230178316","rc":[{"atl":[[13.5,1.62]],"id":52655636},{"atl":[[18,2.97],[18.5,0]],"id":69685608}],"con":true,"img":false}]}
{"op":"mcm","clk":"11540962289","pt":1719500507129,"mc":[{"id":"1.230178316","rc":[{"atb":[[2.9,5.97]],"id":69685608}],"con":true,"img":false}]}
{"op":"mcm","clk":"11540962305","pt":1719500507331,"mc":[{"id":"1.230178316","rc":[{"atl":[[12.5,1],[13.5,0.62]],"id":52655636},{"atl":[[9,1],[9.2,0]],"id":70902601},{"atl":[[18,1.97],[18.5,1]],"id":69685608}],"con":true,"img":false}]}
{"op":"mcm","clk":"11540962316","pt":1719500507444,"mc":[{"id":"1.230178316","rc":[{"atl":[[8.2,4.77],[7.8,5.36]],"id":70902601},{"atb":[[2.9,12.65]],"id":69685608}],"con":true,"img":false}]}
{"op":"mcm","clk":"11540962337","pt":1719500507751,"mc":[{"id":"1.230178316","rc":[{"atl":[[12.5,0],[13,3.16]],"id":52655636},{"atl":[[8,15.26],[9,0],[7.8,0.84]],"id":70902601},{"atl":[[11,0],[11.5,1]],"id":49159417}],"con":true,"img":false}]}
{"op":"mcm","clk":"11540962374","pt":1719500508262,"mc":[{"id":"1.230178316","rc":[{"atl":[[9.2,1]],"id":70902601},{"atl":[[19,2]],"id":69685608}],"con":true,"img":false}]}
{"op":"mcm","clk":"11540962383","pt":1719500508362,"mc":[{"id":"1.230178316","rc":[{"atb":[[3.15,0]],"id":70902601},{"atb":[[5.1,0.84],[4.6,9.47]],"id":69685608},{"atl":[[18.5,0],[19.5,0],[23,4.55]],"id":69685608}],"con":true,"img":false}]}
{"op":"mcm","clk":"11540962420","pt":1719500508836,"mc":[{"id":"1.230178316","rc":[{"atl":[[9,1.96]],"id":46611436}],"con":true,"img":false}]}
{"op":"mcm","clk":"11540962466","pt":1719500509452,"mc":[{"id":"1.230178316","rc":[{"atb":[[5.2,0]],"id":46611436}],"con":true,"img":false}]}
{"op":"mcm","clk":"11540962549","pt":1719500510643,"mc":[{"id":"1.230178316","rc":[{"atl":[[8.6,1.89]],"id":46611436}],"con":true,"img":false}]}
{"op":"mcm","clk":"11540962554","pt":1719500510746,"mc":[{"id":"1.230178316","rc":[{"atb":[[1.03,0.52]],"id":46611436}],"con":true,"img":false}]}
{"op":"mcm","clk":"11540962568","pt":1719500510952,"mc":[{"id":"1.230178316","rc":[{"atb":[[2.88,0]],"id":49159417}],"con":true,"img":false}]}
{"op":"mcm","clk":"11540962574","pt":1719500511055,"mc":[{"id":"1.230178316","rc":[{"atb":[[1.03,0.37]],"id":46611436}],"con":true,"img":false}]}
{"op":"mcm","clk":"11540962594","pt":1719500511364,"mc":[{"id":"1.230178316","rc":[{"atb":[[1.03,0]],"id":46611436},{"atl":[[9,1.12]],"id":46611436}],"con":true,"img":false}]}
{"op":"mcm","clk":"11540962603","pt":1719500511421,"mc":[{"id":"1.230178316","rc":[{"atb":[[5.2,0.37]],"id":46611436}],"con":true,"img":false}]}
{"op":"mcm","clk":"11540962613","pt":1719500511531,"mc":[{"id":"1.230178316","rc":[{"atl":[[10,0]],"id":46611436}],"con":true,"img":false}]}
{"op":"mcm","clk":"11540962622","pt":1719500511631,"mc":[{"id":"1.230178316","rc":[{"atl":[[8.6,5.47]],"id":46611436}],"con":true,"img":false}]}
{"op":"mcm","clk":"11540962784","pt":1719500513852,"mc":[{"id":"1.230178316","rc":[{"atb":[[5.1,2.84],[4.6,0]],"id":69685608}],"con":true,"img":false}]}
{"op":"mcm","clk":"11540962893","pt":1719500515153,"mc":[{"id":"1.230178316","rc":[{"atl":[[18,1.69]],"id":69685608}],"con":true,"img":false}]}
{"op":"mcm","clk":"11540962902","pt":1719500515256,"mc":[{"id":"1.230178316","rc":[{"atl":[[8.8,4.2]],"id":46611436},{"atl":[[8,14.62]],"id":70902601}],"con":true,"img":false}]}
{"op":"mcm","clk":"11540963055","pt":1719500517261,"mc":[{"id":"1.230178316","rc":[{"atb":[[2.46,8.11]],"id":52655636},{"atb":[[2.92,6.17]],"id":49159417}],"con":true,"img":false}]}
{"op":"mcm","clk":"11540963073","pt":1719500517567,"mc":[{"id":"1.230178316","rc":[{"atb":[[2.88,6.3]],"id":69685608}],"con":true,"img":false}]}
{"op":"mcm","clk":"11540963094","pt":1719500517870,"mc":[{"id":"1.230178316","rc":[{"atb":[[2.92,3.16]],"id":69685608}],"con":true,"img":false}]}
{"op":"mcm","clk":"11540963155","pt":1719500519160,"mc":[{"id":"1.230178316","rc":[{"atb":[[3,15.19]],"id":57196226}],"con":true,"img":false}]}
{"op":"mcm","clk":"11540963212","pt":1719500519939,"mc":[{"id":"1.230178316","rc":[{"atb":[[2.94,2.55]],"id":69685608}],"con":true,"img":false}]}
{"op":"mcm","clk":"11540963291","pt":1719500520975,"mc":[{"id":"1.230178316","rc":[{"spn":3.85,"spf":1.0,"id":57196226},{"atl":[[1000,0.81]],"id":46611436},{"spn":8.6,"spf":"Infinity","id":46611436},{"spn":5.72,"spf":1.0,"id":52655636},{"atl":[[1000,0.64]],"id":70902601},{"atl":[[1000,0.5]],"id":69685608},{"spn":5.11,"spf":1.0,"id":69685608},{"spn":9.93,"spf":"Infinity","id":49159417}],"con":true,"img":false}]}
{"op":"mcm","clk":"11540963307","pt":1719500521178,"mc":[{"id":"1.230178316","rc":[{"atl":[[1000,0.22]],"id":46611436},{"atl":[[1000,0]],"id":70902601},{"atl":[[1000,0.22]],"id":69685608}],"con":true,"img":false}]}
{"op":"mcm","clk":"11540963314","pt":1719500521275,"mc":[{"id":"1.230178316","rc":[{"atl":[[8.6,6.06]],"id":46611436},{"atl":[[8,15.26]],"id":70902601},{"atl":[[18,1.97]],"id":69685608}],"con":true,"img":false}]}
{"op":"mcm","clk":"11540963324","pt":1719500521379,"mc":[{"id":"1.230178316","rc":[{"atl":[[8.6,7.23]],"id":46611436}],"con":true,"img":false}]}
{"op":"mcm","clk":"11540963644","pt":1719500525156,"mc":[{"id":"1.230178316","rc":[{"atb":[[2.32,13.74]],"id":70902601}],"con":true,"img":false}]}
{"op":"mcm","clk":"11540963715","pt":1719500525984,"mc":[{"id":"1.230178316","rc":[{"atl":[[8.6,6.18]],"id":46611436}],"con":true,"img":false}]}
{"op":"mcm","clk":"11540963786","pt":1719500526760,"mc":[{"id":"1.230178316","rc":[{"atb":[[5.2,0]],"id":46611436}],"con":true,"img":false}]}
{"op":"mcm","clk":"11540963874","pt":1719500527860,"mc":[{"id":"1.230178316","rc":[{"atl":[[8.4,1.05]],"id":46611436}],"con":true,"img":false}]}
{"op":"mcm","clk":"11540963891","pt":1719500528063,"mc":[{"id":"1.230178316","rc":[{"atb":[[1.03,0.52]],"id":46611436}],"con":true,"img":false}]}
{"op":"mcm","clk":"11540963914","pt":1719500528273,"mc":[{"id":"1.230178316","rc":[{"atb":[[1.03,0.37]],"id":46611436}],"con":true,"img":false}]}
{"op":"mcm","clk":"11540963931","pt":1719500528479,"mc":[{"id":"1.230178316","rc":[{"atb":[[1.03,0]],"id":46611436}],"con":true,"img":false}]}
{"op":"mcm","clk":"11540963941","pt":1719500528580,"mc":[{"id":"1.230178316","rc":[{"atb":[[5.2,0.37]],"id":46611436}],"con":true,"img":false}]}
{"op":"mcm","clk":"11540964420","pt":1719500533975,"mc":[{"id":"1.230178316","rc":[{"atb":[[2.62,0]],"id":57196226},{"atb":[[2.38,0]],"id":46611436},{"atb":[[2.36,0]],"id":52655636},{"atb":[[2.32,4.13]],"id":70902601}],"con":true,"img":false}]}
{"op":"mcm","clk":"11540964523","pt":1719500535566,"mc":[{"id":"1.230178316","rc":[{"atl":[[8.6,5.59]],"id":46611436},{"atl":[[8,14.62]],"id":70902601},{"atl":[[18,1.69]],"id":69685608}],"con":true,"img":false}]}
{"op":"mcm","clk":"11540964535","pt":1719500535768,"mc":[{"id":"1.230178316","rc":[{"atb":[[5.2,1.05]],"id":69685608}],"con":true,"img":false}]}
{"op":"mcm","clk":"11540964566","pt":1719500536188,"mc":[{"id":"1.230178316","rc":[{"atb":[[3,2.09]],"id":69685608}],"con":true,"img":false}]}
{"op":"mcm","clk":"11540964786","pt":1719500538895,"mc":[{"id":"1.230178316","rc":[{"atb":[[2.42,8.94]],"id":46611436}],"con":true,"img":false}]}
{"op":"mcm","clk":"11540964814","pt":1719500539158,"mc":[{"id":"1.230178316","rc":[{"atb":[[2.66,7.65]],"id":57196226}],"con":true,"img":false}]}
{"op":"mcm","clk":"11540964834","pt":1719500539475,"mc":[{"id":"1.230178316","rc":[{"atb":[[2.36,9.33]],"id":70902601}],"con":true,"img":false}]}
{"op":"mcm","clk":"11540964867","pt":1719500539880,"mc":[{"id":"1.230178316","rc":[{"atb":[[4,1.5]],"id":69685608}],"con":true,"img":false}]}
{"op":"mcm","clk":"11540964873","pt":1719500539984,"mc":[{"id":"1.230178316","rc":[{"atb":[[2.9,10.06]],"id":69685608}],"con":true,"img":false}]}
{"op":"mcm","clk":"11540964892","pt":1719500540195,"mc":[{"id":"1.230178316","rc":[{"atb":[[4,0]],"id":69685608}],"con":true,"img":false}]}
{"op":"mcm","clk":"11540964900","pt":1719500540292,"mc":[{"id":"1.230178316","rc":[{"atb":[[2.32,0]],"id":70902601}],"con":true,"img":false}]}
{"op":"mcm","clk":"11540964916","pt":1719500540494,"mc":[{"id":"1.230178316","rc":[{"atb":[[4.1,3.98]],"id":69685608}],"con":true,"img":false}]}
{"op":"mcm","clk":"11540964944","pt":1719500540761,"mc":[{"id":"1.230178316","rc":[{"atb":[[4.1,0]],"id":69685608}],"con":true,"img":false}]}
{"op":"mcm","clk":"11540964952","pt":1719500540875,"mc":[{"id":"1.230178316","rc":[{"atl":[[1000,0.5]],"id":69685608}],"con":true,"img":false}]}
{"op":"mcm","clk":"11540964965","pt":1719500540981,"mc":[{"id":"1.230178316","rc":[{"atl":[[1000,0.83]],"id":46611436},{"atl":[[1000,0.64]],"id":70902601}],"con":true,"img":false}]}
{"op":"mcm","clk":"11540964976","pt":1719500541085,"mc":[{"id":"1.230178316","rc":[{"atl":[[1000,0.22]],"id":46611436},{"atb":[[4.3,3.92]],"id":69685608},{"atl":[[1000,0.22]],"id":69685608}],"con":true,"img":false}]}
{"op":"mcm","clk":"11540964985","pt":1719500541189,"mc":[{"id":"1.230178316","rc":[{"atl":[[8.4,1.66]],"id":46611436},{"atl":[[1000,0]],"id":70902601},{"atl":[[18,1.97]],"id":69685608}],"con":true,"img":false}]}
{"op":"mcm","clk":"11540964994","pt":1719500541294,"mc":[{"id":"1.230178316","rc":[{"atl":[[8,15.26]],"id":70902601}],"con":true,"img":false}]}
{"op":"mcm","clk":"11540965043","pt":1719500541970,"mc":[{"id":"1.230178316","rc":[{"atb":[[4.3,0]],"id":69685608}],"con":true,"img":false}]}
{"op":"mcm","clk":"11540965050","pt":1719500542068,"mc":[{"id":"1.230178316","rc":[{"atl":[[9.6,1.31]],"id":46611436}],"con":true,"img":false}]}
{"op":"mcm","clk":"11540965057","pt":1719500542171,"mc":[{"id":"1.230178316","rc":[{"atl":[[8.4,4.64]],"id":46611436},{"atb":[[4.3,1.49]],"id":69685608}],"con":true,"img":false}]}
{"op":"mcm","clk":"11540965109","pt":1719500542794,"mc":[{"id":"1.230178316","rc":[{"atl":[[8.2,0.84]],"id":46611436}],"con":true,"img":false}]}
{"op":"mcm","clk":"11540965125","pt":1719500543103,"mc":[{"id":"1.230178316","rc":[{"atl":[[8.4,3.59]],"id":46611436}],"con":true,"img":false}]}
{"op":"mcm","clk":"11540965159","pt":1719500543580,"mc":[{"id":"1.230178316","rc":[{"atb":[[4.3,0]],"id":69685608}],"con":true,"img":false}]}
{"op":"mcm","clk":"11540965175","pt":1719500543782,"mc":[{"id":"1.230178316","rc":[{"atb":[[4.3,1.47]],"id":69685608}],"con":true,"img":false}]}
{"op":"mcm","clk":"11540965186","pt":1719500543985,"mc":[{"id":"1.230178316","rc":[{"atb":[[5.2,0]],"id":46611436}],"con":true,"img":false}]}
{"op":"mcm","clk":"11540965203","pt":1719500544291,"mc":[{"id":"1.230178316","rc":[{"atb":[[4.3,0]],"id":69685608}],"con":true,"img":false}]}
{"op":"mcm","clk":"11540965227","pt":1719500544595,"mc":[{"id":"1.230178316","rc":[{"atb":[[4.3,3.98]],"id":69685608}],"con":true,"img":false}]}
{"op":"mcm","clk":"11540965321","pt":1719500545686,"mc":[{"id":"1.230178316","rc":[{"atl":[[8.2,1.89]],"id":46611436}],"con":true,"img":false}]}
{"op":"mcm","clk":"11540965337","pt":1719500545892,"mc":[{"id":"1.230178316","rc":[{"atb":[[1.03,0.52]],"id":46611436},{"atb":[[4.3,0]],"id":69685608}],"con":true,"img":false}]}
{"op":"mcm","clk":"11540965351","pt":1719500546098,"mc":[{"id":"1.230178316","rc":[{"atb":[[1.03,0.37]],"id":46611436}],"con":true,"img":false}]}
{"op":"mcm","clk":"11540965357","pt":1719500546202,"mc":[{"id":"1.230178316","rc":[{"atb":[[4.5,3.91]],"id":69685608}],"con":true,"img":false}]}
{"op":"mcm","clk":"11540965367","pt":1719500546305,"mc":[{"id":"1.230178316","rc":[{"atb":[[1.03,0]],"id":46611436},{"atl":[[8.6,4.75]],"id":46611436}],"con":true,"img":false}]}
{"op":"mcm","clk":"11540965375","pt":1719500546401,"mc":[{"id":"1.230178316","rc":[{"atb":[[5.2,0.37]],"id":46611436},{"atl":[[9.2,0]],"id":46611436}],"con":true,"img":false}]}
{"op":"mcm","clk":"11540965397","pt":1719500546570,"mc":[{"id":"1.230178316","rc":[{"atl":[[8.2,5.73]],"id":46611436}],"con":true,"img":false}]}
{"op":"mcm","clk":"11540965412","pt":1719500546881,"mc":[{"id":"1.230178316","rc":[{"atb":[[2.34,12.91]],"id":70902601},{"atb":[[4.5,0]],"id":69685608}],"con":true,"img":false}]}
{"op":"mcm","clk":"11540965434","pt":1719500547187,"mc":[{"id":"1.230178316","rc":[{"atb":[[4.6,1.46]],"id":69685608}],"con":true,"img":false}]}
{"op":"mcm","clk":"11540965478","pt":1719500547697,"mc":[{"id":"1.230178316","rc":[{"atb":[[2.88,0]],"id":69685608}],"con":true,"img":false}]}
{"op":"mcm","clk":"11540965625","pt":1719500549497,"mc":[{"id":"1.230178316","rc":[{"atb":[[4.6,0]],"id":69685608}],"con":true,"img":false}]}
{"op":"mcm","clk":"11540965650","pt":1719500549799,"mc":[{"id":"1.230178316","rc":[{"atb":[[4.7,5.4]],"id":69685608}],"con":true,"img":false}]}
{"op":"mcm","clk":"11540965709","pt":1719500550484,"mc":[{"id":"1.230178316","rc":[{"atb":[[4.7,0]],"id":69685608}],"con":true,"img":false}]}
{"op":"mcm","clk":"11540965732","pt":1719500550789,"mc":[{"id":"1.230178316","rc":[{"atb":[[4.7,1.69]],"id":69685608}],"con":true,"img":false}]}
{"op":"mcm","clk":"11540965956","pt":1719500553989,"mc":[{"id":"1.230178316","rc":[{"atb":[[2.92,9.33],[4.7,0]],"id":69685608}],"con":true,"img":false}]}
{"op":"mcm","clk":"11540965970","pt":1719500554194,"mc":[{"id":"1.230178316","rc":[{"atb":[[4.8,5.08]],"id":69685608}],"con":true,"img":false}]}
{"op":"mcm","clk":"11540966052","pt":1719500555381,"mc":[{"id":"1.230178316","rc":[{"atl":[[8.4,2.98]],"id":46611436},{"atl":[[18,1.69]],"id":69685608}],"con":true,"img":false}]}
{"op":"mcm","clk":"11540966060","pt":1719500555487,"mc":[{"id":"1.230178316","rc":[{"atl":[[8,14.62]],"id":70902601}],"con":true,"img":false}]}
{"op":"mcm","clk":"11540966277","pt":1719500558224,"mc":[{"id":"1.230178316","rc":[{"atb":[[4.8,0]],"id":69685608}],"con":true,"img":false}]}
{"op":"mcm","clk":"11540966309","pt":1719500558590,"mc":[{"id":"1.230178316","rc":[{"atb":[[4.8,3.62]],"id":69685608}],"con":true,"img":false}]}
{"op":"mcm","clk":"11540966358","pt":1719500559210,"mc":[{"id":"1.230178316","rc":[{"atb":[[2.9,3.38]],"id":69685608},{"atb":[[2.9,0]],"id":49159417}],"con":true,"img":false}]}
{"op":"mcm","clk":"11540966498","pt":1719500561018,"mc":[{"id":"1.230178316","rc":[{"atl":[[1000,0.84]],"id":46611436},{"atl":[[1000,0.64]],"id":70902601},{"atl":[[1000,0.5]],"id":69685608}],"con":true,"img":false}]}
{"op":"mcm","clk":"11540966508","pt":1719500561121,"mc":[{"id":"1.230178316","rc":[{"atl":[[8.2,4.68]],"id":46611436}],"con":true,"img":false}]}
{"op":"mcm","clk":"11540966515","pt":1719500561225,"mc":[{"id":"1.230178316","rc":[{"atl":[[8.2,5.9],[1000,0.22]],"id":46611436},{"atl":[[1000,0]],"id":70902601},{"atl":[[1000,0.22]],"id":69685608}],"con":true,"img":false}]}
{"op":"mcm","clk":"11540966520","pt":1719500561329,"mc":[{"id":"1.230178316","rc":[{"atl":[[8.2,6.52]],"id":46611436},{"atl":[[8,15.26]],"id":70902601},{"atl":[[18,1.97]],"id":69685608}],"con":true,"img":false}]}
{"op":"mcm","clk":"11540966550","pt":1719500561812,"mc":[{"id":"1.230178316","rc":[{"atb":[[5.2,0]],"id":46611436}],"con":true,"img":false}]}
{"op":"mcm","clk":"11540966773","pt":1719500564914,"mc":[{"id":"1.230178316","rc":[{"atb":[[2.64,0]],"id":57196226},{"atb":[[2.4,0]],"id":46611436}],"con":true,"img":false}]}
{"op":"mcm","clk":"11540966825","pt":1719500565632,"mc":[{"id":"1.230178316","rc":[{"atb":[[2.9,0]],"id":69685608}],"con":true,"img":false}]}
{"op":"mcm","clk":"11540966834","pt":1719500565736,"mc":[{"id":"1.230178316","rc":[{"atb":[[2.94,9.09]],"id":69685608}],"con":true,"img":false}]}
{"op":"mcm","clk":"11540966848","pt":1719500565901,"mc":[{"id":"1.230178316","rc":[{"atb":[[2.94,6.54]],"id":49159417}],"con":true,"img":false}]}
{"op":"mcm","clk":"11540967053","pt":1719500568601,"mc":[{"id":"1.230178316","rc":[{"atb":[[3,0]],"id":57196226}],"con":true,"img":false}]}
{"op":"mcm","clk":"11540967063","pt":1719500568710,"mc":[{"id":"1.230178316","rc":[{"atb":[[3.9,15.46]],"id":57196226}],"con":true,"img":false}]}
{"op":"mcm","clk":"11540967088","pt":1719500569035,"mc":[{"id":"1.230178316","rc":[{"atb":[[3.85,11.31]],"id":57196226}],"con":true,"img":false}]}
{"op":"mcm","clk":"11540967105","pt":1719500569229,"mc":[{"id":"1.230178316","rc":[{"atb":[[3.95,6.35]],"id":57196226}],"con":true,"img":false}]}
{"op":"mcm","clk":"11540967112","pt":1719500569332,"mc":[{"id":"1.230178316","rc":[{"atb":[[3.95,7.19]],"id":57196226}],"con":true,"img":false}]}
{"op":"mcm","clk":"11540967170","pt":1719500569910,"mc":[{"id":"1.230178316","rc":[{"atb":[[3.85,10.47]],"id":57196226}],"con":true,"img":false}]}
{"op":"mcm","clk":"11540967195","pt":1719500570214,"mc":[{"id":"1.230178316","rc":[{"atb":[[2.92,6.17]],"id":69685608}],"con":true,"img":false}]}
{"op":"mcm","clk":"11540967203","pt":1719500570319,"mc":[{"id":"1.230178316","rc":[{"atb":[[2.44,8.23]],"id":46611436}],"con":true,"img":false}]}
{"op":"mcm","clk":"11540967213","pt":1719500570429,"mc":[{"id":"1.230178316","rc":[{"atb":[[2.68,7.05]],"id":57196226}],"con":true,"img":false}]}
{"op":"mcm","clk":"11540967615","pt":1719500575648,"mc":[{"id":"1.230178316","rc":[{"atl":[[8.2,5.9]],"id":46611436},{"atl":[[8,14.62]],"id":70902601},{"atl":[[18,1.69]],"id":69685608}],"con":true,"img":false}]}
{"op":"mcm","clk":"11540967920","pt":1719500580232,"mc":[{"id":"1.230178316","rc":[{"atb":[[2.94,6.54]],"id":69685608}],"con":true,"img":false}]}
{"op":"mcm","clk":"11540968106","pt":1719500582746,"mc":[{"id":"1.230178316","rc":[{"atb":[[3.9,0.26]],"id":57196226},{"spn":3.95,"spf":1.0,"id":57196226},{"spn":8.2,"spf":"Infinity","id":46611436},{"spn":5.15,"spf":1.0,"id":69685608}],"con":true,"img":false}]}
{"op":"mcm","clk":"11540968112","pt":1719500582849,"mc":[{"id":"1.230178316","rc":[{"atb":[[3.5,15.19]],"id":57196226}],"con":true,"img":false}]}
{"op":"mcm","clk":"11540968128","pt":1719500583016,"mc":[{"id":"1.230178316","rc":[{"atb":[[2.46,0]],"id":52655636},{"atb":[[2.34,4.07]],"id":70902601}],"con":true,"img":false}]}
{"op":"mcm","clk":"11540968192","pt":1719500583741,"mc":[{"id":"1.230178316","rc":[{"atl":[[11,2.38],[11.5,0],[12,0],[13,1.26]],"id":52655636}],"con":true,"img":false}]}
{"op":"mcm","clk":"11540968601","pt":1719500588342,"mc":[{"id":"1.230178316","rc":[{"atb":[[2.38,8.59]],"id":70902601}],"con":true,"img":false}]}
{"op":"mcm","clk":"11540968611","pt":1719500588547,"mc":[{"id":"1.230178316","rc":[{"atb":[[2.5,7.9]],"id":52655636}],"con":true,"img":false}]}
{"op":"mcm","clk":"11540968653","pt":1719500589060,"mc":[{"id":"1.230178316","rc":[{"atb":[[2.34,0]],"id":70902601}],"con":true,"img":false}]}
{"op":"mcm","clk":"11540968747","pt":1719500590251,"mc":[{"id":"1.230178316","rc":[{"atb":[[2.36,13.34]],"id":70902601}],"con":true,"img":false}]}
{"op":"mcm","clk":"11540968903","pt":1719500592155,"mc":[{"id":"1.230178316","rc":[{"atb":[[2.24,0]],"id":70902601}],"con":true,"img":false}]}
{"op":"mcm","clk":"11540968912","pt":1719500592258,"mc":[{"id":"1.230178316","rc":[{"atb":[[2.36,24.68]],"id":70902601}],"con":true,"img":false}]}
{"op":"mcm","clk":"11540969214","pt":1719500596140,"mc":[{"id":"1.230178316","rc":[{"atb":[[2.36,20.67]],"id":70902601}],"con":true,"img":false}]}
{"op":"mcm","clk":"11540969292","pt":1719500597061,"mc":[{"id":"1.230178316","rc":[{"atb":[[2.42,12.69]],"id":46611436}],"con":true,"img":false}]}
{"op":"mcm","clk":"11540969544","pt":1719500600473,"mc":[{"id":"1.230178316","rc":[{"atb":[[3.75,11.41]],"id":57196226},{"atb":[[4.8,2.18]],"id":46611436},{"atb":[[1.03,9.89]],"id":52655636},{"atb":[[4.2,9.82]],"id":70902601},{"atb":[[4.9,2.14]],"id":69685608},{"atb":[[5,3.1]],"id":49159417}],"con":true,"img":false}]}
{"op":"mcm","clk":"11540969561","pt":1719500600640,"mc":[{"id":"1.230178316","rc":[{"atb":[[1.03,9.83]],"id":52655636}],"con":true,"img":false}]}
{"op":"mcm","clk":"11540969570","pt":1719500600841,"mc":[{"id":"1.230178316","rc":[{"atb":[[4.9,0.84],[5,2]],"id":46611436},{"atb":[[1.03,7.89]],"id":52655636},{"atl":[[10,1.1],[10.5,1.65]],"id":49159417}],"con":true,"img":false}]}
{"op":"mcm","clk":"11540969582","pt":1719500600953,"mc":[{"id":"1.230178316","rc":[{"atb":[[4.8,8.63],[5.3,0]],"id":46611436},{"atb":[[5.4,2.2]],"id":52655636},{"atb":[[2.92,0]],"id":69685608},{"atb":[[2.92,0]],"id":49159417},{"atl":[[13.5,2.18]],"id":49159417}],"con":true,"img":false}]}
{"op":"mcm","clk":"11540969590","pt":1719500601053,"mc":[{"id":"1.230178316","rc":[{"atb":[[5.1,0],[2.42,8.94]],"id":46611436}],"con":true,"img":false}]}
{"op":"mcm","clk":"11540969601","pt":1719500601155,"mc":[{"id":"1.230178316","rc":[{"atb":[[5,3]],"id":46611436}],"con":true,"img":false}]}
{"op":"mcm","clk":"11540969616","pt":1719500601359,"mc":[{"id":"1.230178316","rc":[{"atb":[[5.1,4.97]],"id":46611436}],"con":true,"img":false}]}
{"op":"mcm","clk":"11540969635","pt":1719500601564,"mc":[{"id":"1.230178316","rc":[{"atb":[[5.1,11.34]],"id":46611436},{"atl":[[13,3.43]],"id":52655636},{"atl":[[10,3.76]],"id":49159417}],"con":true,"img":false}]}
{"op":"mcm","clk":"11540969644","pt":1719500601668,"mc":[{"id":"1.230178316","rc":[{"atb":[[5.2,0.84]],"id":46611436}],"con":true,"img":false}]}
{"op":"mcm","clk":"11540969654","pt":1719500601762,"mc":[{"id":"1.230178316","rc":[{"atb":[[4.9,0],[5,2]],"id":46611436}],"con":true,"img":false}]}
{"op":"mcm","clk":"11540969673","pt":1719500601968,"mc":[{"id":"1.230178316","rc":[{"atb":[[5.2,1.84]],"id":46611436}],"con":true,"img":false}]}
{"op":"mcm","clk":"11540969685","pt":1719500602071,"mc":[{"id":"1.230178316","rc":[{"atb":[[5.2,3.25]],"id":46611436}],"con":true,"img":false}]}
{"op":"mcm","clk":"11540969692","pt":1719500602135,"mc":[{"id":"1.230178316","rc":[{"atb":[[5.3,0.26],[5.1,6.37]],"id":46611436}],"con":true,"img":false}]}
{"op":"mcm","clk":"11540969714","pt":1719500602443,"mc":[{"id":"1.230178316","rc":[{"atb":[[5.3,6.13]],"id":46611436}],"con":true,"img":false}]}
{"op":"mcm","clk":"11540969841","pt":1719500603732,"mc":[{"id":"1.230178316","rc":[{"atb":[[4.5,0]],"id":46611436}],"con":true,"img":false}]}
{"op":"mcm","clk":"11540969851","pt":1719500603833,"mc":[{"id":"1.230178316","rc":[{"atb":[[5.2,5.15]],"id":46611436}],"con":true,"img":false}]}
{"op":"mcm","clk":"11540970192","pt":1719500607551,"mc":[{"id":"1.230178316","rc":[{"atb":[[2.96,6.04]],"id":49159417}],"con":true,"img":false}]}
{"op":"mcm","clk":"11540970215","pt":1719500607765,"mc":[{"id":"1.230178316","rc":[{"atb":[[2.96,6.04],[1.04,1]],"id":69685608}],"con":true,"img":false}]}
{"op":"mcm","clk":"11540970225","pt":1719500607862,"mc":[{"id":"1.230178316","rc":[{"atb":[[1.03,8.89],[1.04,1]],"id":57196226},{"atb":[[1.05,1],[1.04,1]],"id":46611436},{"atb":[[1.06,1],[1.04,1]],"id":52655636},{"atb":[[1.03,1],[1.05,1]],"id":70902601},{"atb":[[1.05,1]],"id":69685608},{"atb":[[1.05,1],[1.04,1]],"id":49159417}],"con":true,"img":false}]}
{"op":"mcm","clk":"11540970234","pt":1719500607964,"mc":[{"id":"1.230178316","rc":[{"atb":[[1.04,0.61]],"id":69685608}],"con":true,"img":false}]}
{"op":"mcm","clk":"11540970241","pt":1719500608070,"mc":[{"id":"1.230178316","rc":[{"atb":[[1.03,8.69],[1.04,0.53]],"id":57196226},{"atb":[[1.05,0.4],[1.04,0.6]],"id":46611436},{"atb":[[1.06,0.37],[1.04,0.56]],"id":52655636},{"atb":[[1.03,0.71],[1.05,0.48]],"id":70902601},{"atb":[[1.05,0.41]],"id":69685608},{"atb":[[1.04,0.6]],"id":49159417}],"con":true,"img":false}]}
{"op":"mcm","clk":"11540970249","pt":1719500608171,"mc":[{"id":"1.230178316","rc":[{"atb":[[1.04,0]],"id":69685608},{"atb":[[1.05,0.4]],"id":49159417}],"con":true,"img":false}]}
{"op":"mcm","clk":"11540970254","pt":1719500608274,"mc":[{"id":"1.230178316","rc":[{"atb":[[1.03,7.89],[1.04,0]],"id":57196226},{"atb":[[1.05,0],[1.04,0]],"id":46611436},{"atb":[[1.06,0],[1.04,0]],"id":52655636},{"atb":[[1.03,0],[1.05,0]],"id":70902601},{"atb":[[4.9,2.75],[1.05,0]],"id":69685608},{"atb":[[1.04,0]],"id":49159417}],"con":true,"img":false}]}
{"op":"mcm","clk":"11540970264","pt":1719500608373,"mc":[{"id":"1.230178316","rc":[{"atb":[[3.75,12.74]],"id":57196226},{"atb":[[5,3]],"id":46611436},{"atb":[[5.4,3.13]],"id":52655636},{"atb":[[4.2,11.01]],"id":70902601},{"atb":[[4.9,3.16]],"id":69685608},{"atb":[[5,3.7],[1.05,0]],"id":49159417}],"con":true,"img":false}]}
{"op":"mcm","clk":"11540970285","pt":1719500608445,"mc":[{"id":"1.230178316","rc":[{"atb":[[5,4.1]],"id":49159417}],"con":true,"img":false}]}
{"op":"mcm","clk":"11540970314","pt":1719500608762,"mc":[{"id":"1.230178316","rc":[{"atb":[[5.4,0.84]],"id":46611436}],"con":true,"img":false}]}
{"op":"mcm","clk":"11540971330","pt":1719500619672,"mc":[{"id":"1.230178316","rc":[{"atb":[[4.2,9.76]],"id":70902601}],"con":true,"img":false}]}
{"op":"mcm","clk":"11540971341","pt":1719500619773,"mc":[{"id":"1.230178316","rc":[{"atb":[[4.9,2.09]],"id":69685608}],"con":true,"img":false}]}
{"op":"mcm","clk":"11540971368","pt":1719500619979,"mc":[{"id":"1.230178316","rc":[{"atb":[[4.8,7.54]],"id":46611436}],"con":true,"img":false}]}
{"op":"mcm","clk":"11540971380","pt":1719500620086,"mc":[{"id":"1.230178316","rc":[{"atb":[[3.75,11.34]],"id":57196226}],"con":true,"img":false}]}
{"op":"mcm","clk":"11540971395","pt":1719500620291,"mc":[{"id":"1.230178316","rc":[{"atb":[[4.8,6.45]],"id":46611436}],"con":true,"img":false}]}
{"op":"mcm","clk":"11540971409","pt":1719500620492,"mc":[{"id":"1.230178316","rc":[{"atb":[[3.75,14.14]],"id":57196226},{"atb":[[5,5.1]],"id":46611436},{"atb":[[1.03,9.89]],"id":52655636},{"atb":[[4.2,11.01]],"id":70902601},{"atb":[[4.9,4.23]],"id":69685608},{"atb":[[5,6.2]],"id":49159417}],"con":true,"img":false}]}
{"op":"mcm","clk":"11540971430","pt":1719500620690,"mc":[{"id":"1.230178316","rc":[{"atb":[[1.03,9.86]],"id":52655636},{"atb":[[4.9,3.16]],"id":69685608}],"con":true,"img":false}]}
{"op":"mcm","clk":"11540971441","pt":1719500620750,"mc":[{"id":"1.230178316","rc":[{"atb":[[1.03,9.83]],"id":52655636}],"con":true,"img":false}]}
{"op":"mcm","clk":"11540971453","pt":1719500620863,"mc":[{"id":"1.230178316","rc":[{"atb":[[1.03,8.86]],"id":52655636},{"atb":[[5,5.15]],"id":49159417}],"con":true,"img":false}]}
{"op":"mcm","clk":"11540971464","pt":1719500620958,"mc":[{"id":"1.230178316","rc":[{"atb":[[1.03,7.89],[5.4,4.1]],"id":52655636}],"con":true,"img":false}]}
{"op":"mcm","clk":"11540971490","pt":1719500621272,"mc":[{"id":"1.230178316","rc":[{"atb":[[5.4,3.13]],"id":52655636}],"con":true,"img":false}]}
{"op":"mcm","clk":"11540971504","pt":1719500621485,"mc":[{"id":"1.230178316","rc":[{"atb":[[3.75,12.74]],"id":57196226}],"con":true,"img":false}]}
{"op":"mcm","clk":"11540971515","pt":1719500621592,"mc":[{"id":"1.230178316","rc":[{"atb":[[5,4.1]],"id":49159417}],"con":true,"img":false}]}
{"op":"mcm","clk":"11540971832","pt":1719500625200,"mc":[{"id":"1.230178316","rc":[{"atb":[[2.66,0]],"id":57196226},{"atb":[[2.42,0]],"id":46611436},{"atb":[[2.36,11.33]],"id":70902601}],"con":true,"img":false}]}
{"op":"mcm","clk":"11540971904","pt":1719500625982,"mc":[{"id":"1.230178316","rc":[{"atl":[[8,3.17]],"id":46611436}],"con":true,"img":false}]}
{"op":"mcm","clk":"11540971924","pt":1719500626292,"mc":[{"id":"1.230178316","rc":[{"atl":[[8.8,0.96]],"id":46611436}],"con":true,"img":false}]}
{"op":"mcm","clk":"11540971929","pt":1719500626354,"mc":[{"id":"1.230178316","rc":[{"atl":[[8,6.67]],"id":46611436}],"con":true,"img":false}]}
