{"op":"mcm","clk":"11536832969","pt":1719431775485,"mc":[{"id":"1.230180123","marketDefinition":{"bspMarket":true,"turnInPlayEnabled":false,"persistenceEnabled":false,"marketBaseRate":5.0,"eventId":"33376437","eventTypeId":"4339","numberOfWinners":2,"bettingType":"ODDS","marketType":"PLACE","marketTime":"2024-06-27T15:07:00.000Z","suspendTime":"2024-06-27T15:07:00.000Z","bspReconciled":false,"complete":true,"inPlay":false,"crossMatching":false,"runnersVoidable":false,"numberOfActiveRunners":6,"betDelay":0,"status":"OPEN","runners":[{"status":"ACTIVE","sortPriority":1,"id":67487132,"name":"1. Salacres Belleza"},{"status":"ACTIVE","sortPriority":2,"id":43318163,"name":"2. Walking Dead"},{"status":"ACTIVE","sortPriority":3,"id":40028187,"name":"3. The Grafter"},{"status":"ACTIVE","sortPriority":4,"id":70396461,"name":"4. Late Yahoo"},{"status":"ACTIVE","sortPriority":5,"id":47703807,"name":"5. Fabulous Twirl"},{"status":"ACTIVE","sortPriority":6,"id":57697855,"name":"6. Salacres Driller"}],"regulators":["MR_INT"],"venue":"Towcester","countryCode":"GB","discountAllowed":false,"timezone":"Europe/London","openDate":"2024-06-27T13:33:00.000Z","version":5994767059,"name":"To Be Placed","eventName":"Towcester 27th Jun"},"rc":[],"con":true,"img":false}]}
{"op":"mcm","clk":"11536833112","pt":1719431777486,"mc":[{"id":"1.230180123","marketDefinition":{"bspMarket":true,"turnInPlayEnabled":false,"persistenceEnabled":false,"marketBaseRate":5.0,"eventId":"33376437","eventTypeId":"4339","numberOfWinners":2,"bettingType":"ODDS","marketType":"PLACE","marketTime":"2024-06-27T15:07:00.000Z","suspendTime":"2024-06-27T15:07:00.000Z","bspReconciled":false,"complete":true,"inPlay":false,"crossMatching":false,"runnersVoidable":false,"numberOfActiveRunners":6,"betDelay":0,"status":"OPEN","runners":[{"status":"ACTIVE","sortPriority":1,"id":67487132,"name":"1. Salacres Belleza"},{"status":"ACTIVE","sortPriority":2,"id":43318163,"name":"2. Walking Dead"},{"status":"ACTIVE","sortPriority":3,"id":40028187,"name":"3. The Grafter"},{"status":"ACTIVE","sortPriority":4,"id":70396461,"name":"4. Late Yahoo"},{"status":"ACTIVE","sortPriority":5,"id":47703807,"name":"5. Fabulous Twirl"},{"status":"ACTIVE","sortPriority":6,"id":57697855,"name":"6. Salacres Driller"}],"regulators":["MR_INT"],"venue":"Towcester","countryCode":"GB","discountAllowed":true,"timezone":"Europe/London","openDate":"2024-06-27T13:33:00.000Z","version":5994767059,"name":"To Be Placed","eventName":"Towcester 27th Jun"},"rc":[],"con":true,"img":false}]}
{"op":"mcm","clk":"11537084036","pt":1719435436029,"mc":[{"id":"1.230180123","rc":[{"atb":[[1.03,17.28]],"id":40028187},{"atl":[[1000,0.84]],"id":40028187},{"spn":500.51,"spf":"NaN","id":40028187},{"atb":[[1.01,51.84]],"id":43318163},{"atl":[[990,0.84]],"id":43318163},{"spn":495.5,"spf":"NaN","id":43318163},{"atb":[[1.01,51.84]],"id":47703807},{"atl":[[990,0.84]],"id":47703807},{"spn":495.5,"spf":"NaN","id":47703807},{"atb":[[1.01,51.84]],"id":67487132},{"atl":[[1000,0.84]],"id":67487132},{"spn":500.5,"spf":"NaN","id":67487132},{"atb":[[1.02,25.92]],"id":70396461},{"atl":[[990,0.84]],"id":70396461},{"spn":495.51,"spf":"NaN","id":70396461},{"atb":[[1.01,51.84]],"id":57697855},{"atl":[[990,0.84]],"id":57697855},{"spn":495.5,"spf":"NaN","id":57697855}],"con":true,"img":false}]}
{"op":"mcm","clk":"11537233735","pt":1719437882656,"mc":[{"id":"1.230180123","marketDefinition":{"bspMarket":true,"turnInPlayEnabled":false,"persistenceEnabled":false,"marketBaseRate":5.0,"eventId":"33376437","eventTypeId":"4339","numberOfWinners":2,"bettingType":"ODDS","marketType":"PLACE","marketTime":"2024-06-27T15:07:00.000Z","suspendTime":"2024-06-27T15:07:00.000Z","bspReconciled":false,"complete":true,"inPlay":false,"crossMatching":false,"runnersVoidable":false,"numberOfActiveRunners":6,"betDelay":0,"status":"OPEN","runners":[{"status":"ACTIVE","sortPriority":1,"id":67487132,"name":"1. Salacres Belleza"},{"status":"ACTIVE","sortPriority":2,"id":43318163,"name":"2. Walking Dead"},{"status":"ACTIVE","sortPriority":3,"id":40028187,"name":"3. The Grafter"},{"status":"ACTIVE","sortPriority":4,"id":70396461,"name":"4. Late Yahoo"},{"status":"ACTIVE","sortPriority":5,"id":47703807,"name":"5. Fabulous Twirl"},{"status":"ACTIVE","sortPriority":6,"id":57697855,"name":"6. Salacres Driller"}],"regulators":["MR_INT"],"venue":"Towcester","countryCode":"GB","discountAllowed":true,"timezone":"Europe/London","openDate":"2024-06-27T13:33:00.000Z","version":5994767059,"name":"To Be Placed","eventName":"Towcester 27th Jun"},"rc":[{"atb":[[1.03,17.28]],"id":40028187},{"atl":[[1000,0.84]],"id":40028187},{"spn":500.51,"spf":"NaN","id":40028187},{"atb":[[1.01,51.85]],"id":43318163},{"atl":[[990,0.84]],"id":43318163},{"spn":495.5,"spf":"NaN","id":43318163},{"atb":[[1.01,51.85]],"id":47703807},{"atl":[[990,0.84]],"id":47703807},{"spn":495.5,"spf":"NaN","id":47703807},{"atb":[[1.01,51.85]],"id":67487132},{"atl":[[1000,0.84]],"id":67487132},{"spn":500.5,"spf":"NaN","id":67487132},{"atb":[[1.02,25.92]],"id":70396461},{"atl":[[990,0.84]],"id":70396461},{"spn":495.51,"spf":"NaN","id":70396461},{"atb":[[1.01,51.85]],"id":57697855},{"atl":[[990,0.84]],"id":57697855},{"spn":495.5,"spf":"NaN","id":57697855}],"con":true,"img":true}]}
{"op":"mcm","clk":"11537302614","pt":1719439040551,"mc":[{"id":"1.230180123","rc":[{"atb":[[1.03,17.28]],"id":40028187},{"atl":[[1000,0.23]],"id":40028187},{"atb":[[1.01,51.85]],"id":43318163},{"atl":[[990,0.23]],"id":43318163},{"atb":[[1.01,51.85]],"id":47703807},{"atl":[[990,0.23]],"id":47703807},{"atb":[[1.01,51.85]],"id":67487132},{"atl":[[1000,0.23]],"id":67487132},{"atb":[[1.02,25.92]],"id":70396461},{"atl":[[990,0.23]],"id":70396461},{"atb":[[1.01,51.85]],"id":57697855},{"atl":[[990,0.23]],"id":57697855}],"con":true,"img":false}]}
{"op":"mcm","clk":"11537574886","pt":1719443282706,"mc":[{"id":"1.230180123","marketDefinition":{"bspMarket":true,"turnInPlayEnabled":false,"persistenceEnabled":false,"marketBaseRate":5.0,"eventId":"33376437","eventTypeId":"4339","numberOfWinners":2,"bettingType":"ODDS","marketType":"PLACE","marketTime":"2024-06-27T15:07:00.000Z","suspendTime":"2024-06-27T15:07:00.000Z","bspReconciled":false,"complete":true,"inPlay":false,"crossMatching":false,"runnersVoidable":false,"numberOfActiveRunners":6,"betDelay":0,"status":"OPEN","runners":[{"status":"ACTIVE","sortPriority":1,"id":67487132,"name":"1. Salacres Belleza"},{"status":"ACTIVE","sortPriority":2,"id":43318163,"name":"2. Walking Dead"},{"status":"ACTIVE","sortPriority":3,"id":40028187,"name":"3. The Grafter"},{"status":"ACTIVE","sortPriority":4,"id":70396461,"name":"4. Late Yahoo"},{"status":"ACTIVE","sortPriority":5,"id":47703807,"name":"5. Fabulous Twirl"},{"status":"ACTIVE","sortPriority":6,"id":57697855,"name":"6. Salacres Driller"}],"regulators":["MR_INT"],"venue":"Towcester","countryCode":"GB","discountAllowed":true,"timezone":"Europe/London","openDate":"2024-06-27T13:33:00.000Z","version":5994767059,"name":"To Be Placed","eventName":"Towcester 27th Jun"},"rc":[{"atb":[[1.03,17.28]],"id":40028187},{"atl":[[1000,0.23]],"id":40028187},{"spn":500.51,"spf":"NaN","id":40028187},{"atb":[[1.01,51.85]],"id":43318163},{"atl":[[990,0.23]],"id":43318163},{"spn":495.5,"spf":"NaN","id":43318163},{"atb":[[1.01,51.85]],"id":47703807},{"atl":[[990,0.23]],"id":47703807},{"spn":495.5,"spf":"NaN","id":47703807},{"atb":[[1.01,51.85]],"id":67487132},{"atl":[[1000,0.23]],"id":67487132},{"spn":500.5,"spf":"NaN","id":67487132},{"atb":[[1.02,25.92]],"id":70396461},{"atl":[[990,0.23]],"id":70396461},{"spn":495.51,"spf":"NaN","id":70396461},{"atb":[[1.01,51.85]],"id":57697855},{"atl":[[990,0.23]],"id":57697855},{"spn":495.5,"spf":"NaN","id":57697855}],"con":true,"img":true}]}
{"op":"mcm","clk":"11537956506","pt":1719448682747,"mc":[{"id":"1.230180123","marketDefinition":{"bspMarket":true,"turnInPlayEnabled":false,"persistenceEnabled":false,"marketBaseRate":5.0,"eventId":"33376437","eventTypeId":"4339","numberOfWinners":2,"bettingType":"ODDS","marketType":"PLACE","marketTime":"2024-06-27T15:07:00.000Z","suspendTime":"2024-06-27T15:07:00.000Z","bspReconciled":false,"complete":true,"inPlay":false,"crossMatching":false,"runnersVoidable":false,"numberOfActiveRunners":6,"betDelay":0,"status":"OPEN","runners":[{"status":"ACTIVE","sortPriority":1,"id":67487132,"name":"1. Salacres Belleza"},{"status":"ACTIVE","sortPriority":2,"id":43318163,"name":"2. Walking Dead"},{"status":"ACTIVE","sortPriority":3,"id":40028187,"name":"3. The Grafter"},{"status":"ACTIVE","sortPriority":4,"id":70396461,"name":"4. Late Yahoo"},{"status":"ACTIVE","sortPriority":5,"id":47703807,"name":"5. Fabulous Twirl"},{"status":"ACTIVE","sortPriority":6,"id":57697855,"name":"6. Salacres Driller"}],"regulators":["MR_INT"],"venue":"Towcester","countryCode":"GB","discountAllowed":true,"timezone":"Europe/London","openDate":"2024-06-27T13:33:00.000Z","version":5994767059,"name":"To Be Placed","eventName":"Towcester 27th Jun"},"rc":[{"atb":[[1.03,17.28]],"id":40028187},{"atl":[[1000,0.23]],"id":40028187},{"spn":500.51,"spf":"NaN","id":40028187},{"atb":[[1.01,51.85]],"id":43318163},{"atl":[[990,0.23]],"id":43318163},{"spn":495.5,"spf":"NaN","id":43318163},{"atb":[[1.01,51.85]],"id":47703807},{"atl":[[990,0.23]],"id":47703807},{"spn":495.5,"spf":"NaN","id":47703807},{"atb":[[1.01,51.85]],"id":67487132},{"atl":[[1000,0.23]],"id":67487132},{"spn":500.5,"spf":"NaN","id":67487132},{"atb":[[1.02,25.92]],"id":70396461},{"atl":[[990,0.23]],"id":70396461},{"spn":495.51,"spf":"NaN","id":70396461},{"atb":[[1.01,51.85]],"id":57697855},{"atl":[[990,0.23]],"id":57697855},{"spn":495.5,"spf":"NaN","id":57697855}],"con":true,"img":true}]}
{"op":"mcm","clk":"11538172123","pt":1719454082690,"mc":[{"id":"1.230180123","marketDefinition":{"bspMarket":true,"turnInPlayEnabled":false,"persistenceEnabled":false,"marketBaseRate":5.0,"eventId":"33376437","eventTypeId":"4339","numberOfWinners":2,"bettingType":"ODDS","marketType":"PLACE","marketTime":"2024-06-27T15:07:00.000Z","suspendTime":"2024-06-27T15:07:00.000Z","bspReconciled":false,"complete":true,"inPlay":false,"crossMatching":false,"runnersVoidable":false,"numberOfActiveRunners":6,"betDelay":0,"status":"OPEN","runners":[{"status":"ACTIVE","sortPriority":1,"id":67487132,"name":"1. Salacres Belleza"},{"status":"ACTIVE","sortPriority":2,"id":43318163,"name":"2. Walking Dead"},{"status":"ACTIVE","sortPriority":3,"id":40028187,"name":"3. The Grafter"},{"status":"ACTIVE","sortPriority":4,"id":70396461,"name":"4. Late Yahoo"},{"status":"ACTIVE","sortPriority":5,"id":47703807,"name":"5. Fabulous Twirl"},{"status":"ACTIVE","sortPriority":6,"id":57697855,"name":"6. Salacres Driller"}],"regulators":["MR_INT"],"venue":"Towcester","countryCode":"GB","discountAllowed":true,"timezone":"Europe/London","openDate":"2024-06-27T13:33:00.000Z","version":5994767059,"name":"To Be Placed","eventName":"Towcester 27th Jun"},"rc":[{"atb":[[1.03,17.29]],"id":40028187},{"atl":[[1000,0.23]],"id":40028187},{"spn":500.51,"spf":"NaN","id":40028187},{"atb":[[1.01,51.86]],"id":43318163},{"atl":[[990,0.23]],"id":43318163},{"spn":495.5,"spf":"NaN","id":43318163},{"atb":[[1.01,51.86]],"id":47703807},{"atl":[[990,0.23]],"id":47703807},{"spn":495.5,"spf":"NaN","id":47703807},{"atb":[[1.01,51.86]],"id":67487132},{"atl":[[1000,0.23]],"id":67487132},{"spn":500.5,"spf":"NaN","id":67487132},{"atb":[[1.02,25.93]],"id":70396461},{"atl":[[990,0.23]],"id":70396461},{"spn":495.51,"spf":"NaN","id":70396461},{"atb":[[1.01,51.86]],"id":57697855},{"atl":[[990,0.23]],"id":57697855},{"spn":495.5,"spf":"NaN","id":57697855}],"con":true,"img":true}]}
{"op":"mcm","clk":"11538369790","pt":1719459482776,"mc":[{"id":"1.230180123","marketDefinition":{"bspMarket":true,"turnInPlayEnabled":false,"persistenceEnabled":false,"marketBaseRate":5.0,"eventId":"33376437","eventTypeId":"4339","numberOfWinners":2,"bettingType":"ODDS","marketType":"PLACE","marketTime":"2024-06-27T15:07:00.000Z","suspendTime":"2024-06-27T15:07:00.000Z","bspReconciled":false,"complete":true,"inPlay":false,"crossMatching":false,"runnersVoidable":false,"numberOfActiveRunners":6,"betDelay":0,"status":"OPEN","runners":[{"status":"ACTIVE","sortPriority":1,"id":67487132,"name":"1. Salacres Belleza"},{"status":"ACTIVE","sortPriority":2,"id":43318163,"name":"2. Walking Dead"},{"status":"ACTIVE","sortPriority":3,"id":40028187,"name":"3. The Grafter"},{"status":"ACTIVE","sortPriority":4,"id":70396461,"name":"4. Late Yahoo"},{"status":"ACTIVE","sortPriority":5,"id":47703807,"name":"5. Fabulous Twirl"},{"status":"ACTIVE","sortPriority":6,"id":57697855,"name":"6. Salacres Driller"}],"regulators":["MR_INT"],"venue":"Towcester","countryCode":"GB","discountAllowed":true,"timezone":"Europe/London","openDate":"2024-06-27T13:33:00.000Z","version":5994767059,"name":"To Be Placed","eventName":"Towcester 27th Jun"},"rc":[{"atb":[[1.03,17.29]],"id":40028187},{"atl":[[1000,0.23]],"id":40028187},{"spn":500.51,"spf":"NaN","id":40028187},{"atb":[[1.01,51.87]],"id":43318163},{"atl":[[990,0.23]],"id":43318163},{"spn":495.5,"spf":"NaN","id":43318163},{"atb":[[1.01,51.87]],"id":47703807},{"atl":[[990,0.23]],"id":47703807},{"spn":495.5,"spf":"NaN","id":47703807},{"atb":[[1.01,51.87]],"id":67487132},{"atl":[[1000,0.23]],"id":67487132},{"spn":500.5,"spf":"NaN","id":67487132},{"atb":[[1.02,25.93]],"id":70396461},{"atl":[[990,0.23]],"id":70396461},{"spn":495.51,"spf":"NaN","id":70396461},{"atb":[[1.01,51.87]],"id":57697855},{"atl":[[990,0.23]],"id":57697855},{"spn":495.5,"spf":"NaN","id":57697855}],"con":true,"img":true}]}
{"op":"mcm","clk":"11538596920","pt":1719464882720,"mc":[{"id":"1.230180123","marketDefinition":{"bspMarket":true,"turnInPlayEnabled":false,"persistenceEnabled":false,"marketBaseRate":5.0,"eventId":"33376437","eventTypeId":"4339","numberOfWinners":2,"bettingType":"ODDS","marketType":"PLACE","marketTime":"2024-06-27T15:07:00.000Z","suspendTime":"2024-06-27T15:07:00.000Z","bspReconciled":false,"complete":true,"inPlay":false,"crossMatching":false,"runnersVoidable":false,"numberOfActiveRunners":6,"betDelay":0,"status":"OPEN","runners":[{"status":"ACTIVE","sortPriority":1,"id":67487132,"name":"1. Salacres Belleza"},{"status":"ACTIVE","sortPriority":2,"id":43318163,"name":"2. Walking Dead"},{"status":"ACTIVE","sortPriority":3,"id":40028187,"name":"3. The Grafter"},{"status":"ACTIVE","sortPriority":4,"id":70396461,"name":"4. Late Yahoo"},{"status":"ACTIVE","sortPriority":5,"id":47703807,"name":"5. Fabulous Twirl"},{"status":"ACTIVE","sortPriority":6,"id":57697855,"name":"6. Salacres Driller"}],"regulators":["MR_INT"],"venue":"Towcester","countryCode":"GB","discountAllowed":true,"timezone":"Europe/London","openDate":"2024-06-27T13:33:00.000Z","version":5994767059,"name":"To Be Placed","eventName":"Towcester 27th Jun"},"rc":[{"atb":[[1.03,17.29]],"id":40028187},{"atl":[[1000,0.23]],"id":40028187},{"spn":500.51,"spf":"NaN","id":40028187},{"atb":[[1.01,51.86]],"id":43318163},{"atl":[[990,0.23]],"id":43318163},{"spn":495.5,"spf":"NaN","id":43318163},{"atb":[[1.01,51.86]],"id":47703807},{"atl":[[990,0.23]],"id":47703807},{"spn":495.5,"spf":"NaN","id":47703807},{"atb":[[1.01,51.86]],"id":67487132},{"atl":[[1000,0.23]],"id":67487132},{"spn":500.5,"spf":"NaN","id":67487132},{"atb":[[1.02,25.93]],"id":70396461},{"atl":[[990,0.23]],"id":70396461},{"spn":495.51,"spf":"NaN","id":70396461},{"atb":[[1.01,51.86]],"id":57697855},{"atl":[[990,0.23]],"id":57697855},{"spn":495.5,"spf":"NaN","id":57697855}],"con":true,"img":true}]}
{"op":"mcm","clk":"11538906756","pt":1719471498990,"mc":[{"id":"1.230180123","rc":[{"atb":[[1.03,17.29]],"id":40028187},{"atl":[[1000,1.23]],"id":40028187},{"atb":[[1.01,51.86]],"id":43318163},{"atl":[[1000,1]],"id":43318163},{"atb":[[1.01,51.86]],"id":47703807},{"atl":[[1000,1]],"id":47703807},{"atb":[[1.01,51.86]],"id":67487132},{"atl":[[1000,1.23]],"id":67487132},{"atb":[[1.02,25.93]],"id":70396461},{"atl":[[1000,1]],"id":70396461},{"atb":[[1.01,51.86]],"id":57697855},{"atl":[[1000,1]],"id":57697855}],"con":true,"img":false}]}
{"op":"mcm","clk":"11538906762","pt":1719471499095,"mc":[{"id":"1.230180123","rc":[{"atb":[[1.07,2.48]],"id":40028187},{"atb":[[1.07,2.48]],"id":43318163},{"atb":[[1.07,2.48]],"id":47703807},{"atb":[[1.07,2.48]],"id":67487132},{"atb":[[1.07,2.48]],"id":70396461},{"atb":[[1.07,2.48]],"id":57697855}],"con":true,"img":false}]}
{"op":"mcm","clk":"11538906767","pt":1719471499194,"mc":[{"id":"1.230180123","rc":[{"atl":[[1000,0.71]],"id":40028187},{"atl":[[1000,0.48]],"id":43318163},{"atl":[[1000,0.48]],"id":47703807},{"atl":[[1000,0.71]],"id":67487132},{"atl":[[1000,0.48]],"id":70396461},{"atl":[[1000,0.48]],"id":57697855}],"con":true,"img":false}]}
{"op":"mcm","clk":"11538906777","pt":1719471499404,"mc":[{"id":"1.230180123","rc":[{"atl":[[1000,0.23]],"id":40028187},{"atl":[[1000,0]],"id":43318163},{"atl":[[1000,0]],"id":47703807},{"atl":[[1000,0.23]],"id":67487132},{"atl":[[1000,0]],"id":70396461},{"atl":[[1000,0]],"id":57697855}],"con":true,"img":false}]}
{"op":"mcm","clk":"11538906785","pt":1719471499517,"mc":[{"id":"1.230180123","rc":[{"atl":[[75,0.48]],"id":40028187},{"atl":[[75,0.48]],"id":43318163},{"atl":[[75,0.48]],"id":47703807},{"atl":[[75,0.48]],"id":67487132},{"atl":[[75,0.48]],"id":70396461},{"atl":[[75,0.48]],"id":57697855}],"con":true,"img":false}]}
{"op":"mcm","clk":"11539124108","pt":1719475682707,"mc":[{"id":"1.230180123","marketDefinition":{"bspMarket":true,"turnInPlayEnabled":false,"persistenceEnabled":false,"marketBaseRate":5.0,"eventId":"33376437","eventTypeId":"4339","numberOfWinners":2,"bettingType":"ODDS","marketType":"PLACE","marketTime":"2024-06-27T15:07:00.000Z","suspendTime":"2024-06-27T15:07:00.000Z","bspReconciled":false,"complete":true,"inPlay":false,"crossMatching":false,"runnersVoidable":false,"numberOfActiveRunners":6,"betDelay":0,"status":"OPEN","runners":[{"status":"ACTIVE","sortPriority":1,"id":67487132,"name":"1. Salacres Belleza"},{"status":"ACTIVE","sortPriority":2,"id":43318163,"name":"2. Walking Dead"},{"status":"ACTIVE","sortPriority":3,"id":40028187,"name":"3. The Grafter"},{"status":"ACTIVE","sortPriority":4,"id":70396461,"name":"4. Late Yahoo"},{"status":"ACTIVE","sortPriority":5,"id":47703807,"name":"5. Fabulous Twirl"},{"status":"ACTIVE","sortPriority":6,"id":57697855,"name":"6. Salacres Driller"}],"regulators":["MR_INT"],"venue":"Towcester","countryCode":"GB","discountAllowed":true,"timezone":"Europe/London","openDate":"2024-06-27T13:33:00.000Z","version":5994767059,"name":"To Be Placed","eventName":"Towcester 27th Jun"},"rc":[{"atb":[[1.03,17.28],[1.07,2.48]],"id":40028187},{"atl":[[75,0.48],[1000,0.23]],"id":40028187},{"spn":38.03,"spf":"NaN","id":40028187},{"atb":[[1.01,51.84],[1.07,2.48]],"id":43318163},{"atl":[[75,0.48],[990,0.23]],"id":43318163},{"spn":38.03,"spf":"NaN","id":43318163},{"atb":[[1.01,51.84],[1.07,2.48]],"id":47703807},{"atl":[[75,0.48],[990,0.23]],"id":47703807},{"spn":38.03,"spf":"NaN","id":47703807},{"atb":[[1.01,51.84],[1.07,2.48]],"id":67487132},{"atl":[[75,0.48],[1000,0.23]],"id":67487132},{"spn":38.03,"spf":"NaN","id":67487132},{"atb":[[1.02,25.92],[1.07,2.48]],"id":70396461},{"atl":[[75,0.48],[990,0.23]],"id":70396461},{"spn":38.03,"spf":"NaN","id":70396461},{"atb":[[1.01,51.84],[1.07,2.48]],"id":57697855},{"atl":[[75,0.48],[990,0.23]],"id":57697855},{"spn":38.03,"spf":"NaN","id":57697855}],"con":true,"img":true}]}
{"op":"mcm","clk":"11539338113","pt":1719479249297,"mc":[{"id":"1.230180123","rc":[{"atb":[[1.03,17.28]],"id":40028187},{"atl":[[1000,0.23]],"id":40028187},{"spn":38.03,"spf":"NaN","id":40028187},{"atb":[[1.01,51.83]],"id":43318163},{"atl":[[990,0.23]],"id":43318163},{"spn":38.03,"spf":"NaN","id":43318163},{"atb":[[1.01,51.83]],"id":47703807},{"atl":[[990,0.23]],"id":47703807},{"spn":38.03,"spf":"NaN","id":47703807},{"atb":[[1.01,51.83]],"id":67487132},{"atl":[[1000,0.23]],"id":67487132},{"spn":38.03,"spf":"NaN","id":67487132},{"atb":[[1.02,25.91]],"id":70396461},{"atl":[[990,0.23]],"id":70396461},{"spn":38.03,"spf":"NaN","id":70396461},{"spl":[[1.71,6]],"id":57697855},{"atb":[[1.01,51.83]],"id":57697855},{"atl":[[990,0.23]],"id":57697855},{"spn":1.39,"spf":1.0,"id":57697855}],"con":true,"img":false}]}
{"op":"mcm","clk":"11540685100","pt":1719497282633,"mc":[{"id":"1.230180123","marketDefinition":{"bspMarket":true,"turnInPlayEnabled":false,"persistenceEnabled":false,"marketBaseRate":5.0,"eventId":"33376437","eventTypeId":"4339","numberOfWinners":2,"bettingType":"ODDS","marketType":"PLACE","marketTime":"2024-06-27T15:07:00.000Z","suspendTime":"2024-06-27T15:07:00.000Z","bspReconciled":false,"complete":true,"inPlay":false,"crossMatching":false,"runnersVoidable":false,"numberOfActiveRunners":6,"betDelay":0,"status":"OPEN","runners":[{"status":"ACTIVE","sortPriority":1,"id":67487132,"name":"1. Salacres Belleza"},{"status":"ACTIVE","sortPriority":2,"id":43318163,"name":"2. Walking Dead"},{"status":"ACTIVE","sortPriority":3,"id":40028187,"name":"3. The Grafter"},{"status":"ACTIVE","sortPriority":4,"id":70396461,"name":"4. Late Yahoo"},{"status":"ACTIVE","sortPriority":5,"id":47703807,"name":"5. Fabulous Twirl"},{"status":"ACTIVE","sortPriority":6,"id":57697855,"name":"6. Salacres Driller"}],"regulators":["MR_INT"],"venue":"Towcester","countryCode":"GB","discountAllowed":true,"timezone":"Europe/London","openDate":"2024-06-27T13:33:00.000Z","version":5994767059,"name":"To Be Placed","eventName":"Towcester 27th Jun"},"rc":[{"atb":[[1.03,17.29],[1.07,2.48]],"id":40028187},{"atl":[[75,0.48],[1000,0.23]],"id":40028187},{"spn":38.03,"spf":"NaN","id":40028187},{"atb":[[1.01,51.87],[1.07,2.48]],"id":43318163},{"atl":[[75,0.48],[990,0.23]],"id":43318163},{"spn":38.03,"spf":"NaN","id":43318163},{"atb":[[1.01,51.87],[1.07,2.48]],"id":47703807},{"atl":[[75,0.48],[990,0.23]],"id":47703807},{"spn":38.03,"spf":"NaN","id":47703807},{"atb":[[1.01,51.87],[1.07,2.48]],"id":67487132},{"atl":[[75,0.48],[1000,0.23]],"id":67487132},{"spn":38.03,"spf":"NaN","id":67487132},{"atb":[[1.02,25.93],[1.07,2.48]],"id":70396461},{"atl":[[75,0.48],[990,0.23]],"id":70396461},{"spn":38.03,"spf":"NaN","id":70396461},{"spl":[[1.71,6]],"id":57697855},{"atb":[[1.01,51.87],[1.07,2.48]],"id":57697855},{"atl":[[75,0.48],[990,0.23]],"id":57697855},{"spn":1.39,"spf":1.0,"id":57697855}],"con":true,"img":true}]}
{"op":"mcm","clk":"11540849351","pt":1719499083096,"mc":[{"id":"1.230180123","rc":[{"atb":[[1.03,17.29],[1.04,1]],"id":40028187},{"atl":[[1000,0.23]],"id":40028187},{"atb":[[1.01,51.87],[1.04,1]],"id":43318163},{"atl":[[990,0.23]],"id":43318163},{"atb":[[1.01,51.87],[1.04,1]],"id":47703807},{"atl":[[990,0.23]],"id":47703807},{"atb":[[1.01,51.87],[1.04,1]],"id":67487132},{"atl":[[1000,0.23]],"id":67487132},{"atb":[[1.02,25.93],[1.04,1]],"id":70396461},{"atl":[[990,0.23]],"id":70396461},{"atb":[[1.01,51.87],[1.04,1]],"id":57697855},{"atl":[[990,0.23]],"id":57697855}],"con":true,"img":false}]}
{"op":"mcm","clk":"11540849372","pt":1719499083296,"mc":[{"id":"1.230180123","rc":[{"atb":[[1.04,0.25]],"id":40028187},{"atb":[[1.04,0.25]],"id":43318163},{"atb":[[1.04,0.25]],"id":47703807},{"atb":[[1.04,0.25]],"id":67487132},{"atb":[[1.04,0.25]],"id":70396461},{"atb":[[1.04,0.25]],"id":57697855}],"con":true,"img":false}]}
{"op":"mcm","clk":"11540849391","pt":1719499083502,"mc":[{"id":"1.230180123","rc":[{"atb":[[1.04,0]],"id":40028187},{"atb":[[1.04,0]],"id":43318163},{"atb":[[1.04,0]],"id":47703807},{"atb":[[1.04,0]],"id":67487132},{"atb":[[1.04,0]],"id":70396461},{"atb":[[1.04,0]],"id":57697855}],"con":true,"img":false}]}
{"op":"mcm","clk":"11540849402","pt":1719499083606,"mc":[{"id":"1.230180123","rc":[{"atb":[[1.2,0.25]],"id":40028187},{"atb":[[1.2,0.25]],"id":43318163},{"atb":[[1.2,0.25]],"id":47703807},{"atb":[[1.2,0.25]],"id":67487132},{"atb":[[1.2,0.25]],"id":70396461},{"atb":[[1.2,0.25]],"id":57697855}],"con":true,"img":false}]}
{"op":"mcm","clk":"11540851828","pt":1719499115028,"mc":[{"id":"1.230180123","rc":[{"atb":[[1.09,47.03]],"id":47703807}],"con":true,"img":false}]}
{"op":"mcm","clk":"11540854761","pt":1719499156858,"mc":[{"id":"1.230180123","rc":[{"spn":38.1,"spf":"NaN","id":40028187},{"spn":38.1,"spf":"NaN","id":43318163},{"atb":[[1.09,0]],"id":47703807},{"spn":38.1,"spf":"NaN","id":47703807},{"spn":38.1,"spf":"NaN","id":67487132},{"spn":38.1,"spf":"NaN","id":70396461},{"spn":1.45,"spf":1.0,"id":57697855}],"con":true,"img":false}]}
{"op":"mcm","clk":"11540896527","pt":1719499695988,"mc":[{"id":"1.230180123","rc":[{"atb":[[1.09,43.87]],"id":57697855}],"con":true,"img":false}]}
{"op":"mcm","clk":"11540898249","pt":1719499715545,"mc":[{"id":"1.230180123","rc":[{"atb":[[1.09,0]],"id":57697855}],"con":true,"img":false}]}
{"op":"mcm","clk":"11540915827","pt":1719499920658,"mc":[{"id":"1.230180123","rc":[{"atb":[[1.46,2.48]],"id":40028187},{"atl":[[13,2]],"id":40028187},{"spn":7.23,"spf":"NaN","id":40028187},{"atb":[[1.59,2.48]],"id":43318163},{"atl":[[17,2]],"id":43318163},{"spn":9.29,"spf":"NaN","id":43318163},{"atb":[[1.83,2.48]],"id":47703807},{"atl":[[46,2]],"id":47703807},{"spn":23.91,"spf":"NaN","id":47703807},{"atb":[[1.53,2.48]],"id":67487132},{"atl":[[15,2]],"id":67487132},{"spn":8.26,"spf":"NaN","id":67487132},{"atb":[[1.19,14.21]],"id":70396461},{"atl":[[9.4,2]],"id":70396461},{"spn":5.3,"spf":"NaN","id":70396461},{"atb":[[1.53,2.48]],"id":57697855},{"atl":[[15,2]],"id":57697855},{"spn":1.62,"spf":1.0,"id":57697855}],"con":true,"img":false}]}
{"op":"mcm","clk":"11540915845","pt":1719499920882,"mc":[{"id":"1.230180123","rc":[{"atb":[[1.74,1]],"id":40028187},{"atl":[[5.3,1]],"id":40028187},{"atb":[[1.74,1]],"id":43318163},{"atl":[[5.3,1]],"id":43318163},{"atb":[[1.97,1]],"id":47703807},{"atl":[[6.4,1]],"id":47703807},{"atb":[[1.55,1]],"id":67487132},{"atl":[[4.3,1]],"id":67487132},{"atb":[[1.41,1]],"id":70396461},{"atl":[[3.55,1]],"id":70396461},{"atb":[[1.55,1]],"id":57697855},{"atl":[[4.3,1]],"id":57697855}],"con":true,"img":false}]}
{"op":"mcm","clk":"11540916135","pt":1719499923960,"mc":[{"id":"1.230180123","rc":[{"atb":[[1.01,1.7]],"id":40028187},{"atl":[[1000,1.93]],"id":40028187},{"atb":[[1.01,53.58]],"id":43318163},{"atl":[[1000,1.7]],"id":43318163},{"atb":[[1.01,53.58]],"id":67487132},{"atl":[[1000,1.93]],"id":67487132}],"con":true,"img":false}]}
{"op":"mcm","clk":"11540916162","pt":1719499924262,"mc":[{"id":"1.230180123","rc":[{"atb":[[1.01,0.67]],"id":40028187},{"atl":[[1000,0.26]],"id":40028187},{"atb":[[1.01,52.4]],"id":43318163},{"atl":[[1000,0.02]],"id":43318163},{"atb":[[1.01,52.46]],"id":67487132},{"atl":[[1000,0.26]],"id":67487132}],"con":true,"img":false}]}
{"op":"mcm","clk":"11540916182","pt":1719499924525,"mc":[{"id":"1.230180123","rc":[{"atb":[[1.01,0]],"id":40028187},{"atl":[[1000,0.23]],"id":40028187},{"atb":[[1.01,51.87]],"id":43318163},{"atl":[[1000,0]],"id":43318163},{"atb":[[1.01,51.87]],"id":67487132},{"atl":[[1000,0.23]],"id":67487132}],"con":true,"img":false}]}
{"op":"mcm","clk":"11540916187","pt":1719499924634,"mc":[{"id":"1.230180123","rc":[{"atb":[[1.47,0.67]],"id":40028187},{"atl":[[12.5,0.02]],"id":40028187},{"atb":[[1.6,0.53]],"id":43318163},{"atl":[[16.5,0.02]],"id":43318163},{"atb":[[1.54,0.58]],"id":67487132},{"atl":[[14.5,0.02]],"id":67487132}],"con":true,"img":false}]}
{"op":"mcm","clk":"11540916680","pt":1719499930775,"mc":[{"id":"1.230180123","rc":[{"atb":[[1.46,0]],"id":40028187},{"atb":[[1.66,2]],"id":43318163},{"atb":[[1.95,2.48]],"id":47703807},{"atb":[[1.63,2]],"id":67487132},{"atb":[[1.63,2]],"id":57697855}],"con":true,"img":false}]}
{"op":"mcm","clk":"11540916697","pt":1719499930894,"mc":[{"id":"1.230180123","rc":[{"atb":[[1.58,2]],"id":40028187},{"atl":[[6.4,1],[5.3,0]],"id":40028187},{"atb":[[1.59,0]],"id":43318163},{"atl":[[6.4,1],[5.3,0]],"id":43318163},{"atb":[[1.83,0]],"id":47703807},{"atl":[[6.4,0],[8.4,1]],"id":47703807},{"atb":[[1.53,0]],"id":67487132},{"atl":[[4.3,0],[5,1]],"id":67487132},{"atb":[[1.28,2.48],[1.19,0]],"id":70396461},{"atl":[[4.3,1],[3.55,0]],"id":70396461},{"atb":[[1.53,0]],"id":57697855},{"atl":[[4.3,0],[5,1]],"id":57697855}],"con":true,"img":false}]}
{"op":"mcm","clk":"11540916806","pt":1719499932038,"mc":[{"id":"1.230180123","marketDefinition":{"bspMarket":true,"turnInPlayEnabled":false,"persistenceEnabled":false,"marketBaseRate":5.0,"eventId":"33376437","eventTypeId":"4339","numberOfWinners":2,"bettingType":"ODDS","marketType":"PLACE","marketTime":"2024-06-27T15:07:00.000Z","suspendTime":"2024-06-27T15:07:00.000Z","bspReconciled":false,"complete":true,"inPlay":false,"crossMatching":true,"runnersVoidable":false,"numberOfActiveRunners":6,"betDelay":0,"status":"OPEN","runners":[{"status":"ACTIVE","sortPriority":1,"id":67487132,"name":"1. Salacres Belleza"},{"status":"ACTIVE","sortPriority":2,"id":43318163,"name":"2. Walking Dead"},{"status":"ACTIVE","sortPriority":3,"id":40028187,"name":"3. The Grafter"},{"status":"ACTIVE","sortPriority":4,"id":70396461,"name":"4. Late Yahoo"},{"status":"ACTIVE","sortPriority":5,"id":47703807,"name":"5. Fabulous Twirl"},{"status":"ACTIVE","sortPriority":6,"id":57697855,"name":"6. Salacres Driller"}],"regulators":["MR_INT"],"venue":"Towcester","countryCode":"GB","discountAllowed":true,"timezone":"Europe/London","openDate":"2024-06-27T13:33:00.000Z","version":5994767059,"name":"To Be Placed","eventName":"Towcester 27th Jun"},"rc":[],"con":true,"img":false}]}
{"op":"mcm","clk":"11540918436","pt":1719499954689,"mc":[{"id":"1.230180123","rc":[{"atb":[[1.68,5.8]],"id":43318163}],"con":true,"img":false}]}
{"op":"mcm","clk":"11540918444","pt":1719499954792,"mc":[{"id":"1.230180123","rc":[{"atb":[[1.66,0],[1.69,2]],"id":43318163}],"con":true,"img":false}]}
{"op":"mcm","clk":"11540919049","pt":1719499962914,"mc":[{"id":"1.230180123","rc":[{"atb":[[1.47,0]],"id":40028187},{"atl":[[12.5,0]],"id":40028187},{"atb":[[1.6,0]],"id":43318163},{"atl":[[16.5,0]],"id":43318163},{"atb":[[1.54,0]],"id":67487132},{"atl":[[14.5,0]],"id":67487132}],"con":true,"img":false}]}
{"op":"mcm","clk":"11540919244","pt":1719499965284,"mc":[{"id":"1.230180123","rc":[{"atb":[[1.71,5.96]],"id":43318163}],"con":true,"img":false}]}
{"op":"mcm","clk":"11540919251","pt":1719499965388,"mc":[{"id":"1.230180123","rc":[{"atb":[[1.72,5.8]],"id":43318163}],"con":true,"img":false}]}
{"op":"mcm","clk":"11540919258","pt":1719499965486,"mc":[{"id":"1.230180123","rc":[{"atb":[[1.69,0]],"id":43318163}],"con":true,"img":false}]}
{"op":"mcm","clk":"11540919474","pt":1719499968308,"mc":[{"id":"1.230180123","rc":[{"atb":[[1.74,3.11]],"id":43318163}],"con":true,"img":false}]}
{"op":"mcm","clk":"11540919492","pt":1719499968513,"mc":[{"id":"1.230180123","rc":[{"atb":[[1.72,0],[1.74,8.91]],"id":43318163}],"con":true,"img":false}]}
{"op":"mcm","clk":"11540920043","pt":1719499975418,"mc":[{"id":"1.230180123","rc":[{"atb":[[1.78,7.08]],"id":43318163}],"con":true,"img":false}]}
{"op":"mcm","clk":"11540920255","pt":1719499978198,"mc":[{"id":"1.230180123","rc":[{"atb":[[1.79,7.08],[1.74,3.11]],"id":43318163}],"con":true,"img":false}]}
{"op":"mcm","clk":"11540920755","pt":1719499984220,"mc":[{"id":"1.230180123","rc":[{"spn":4.07,"spf":"NaN","id":40028187},{"spn":4.09,"spf":"NaN","id":43318163},{"spn":5.18,"spf":"NaN","id":47703807},{"atb":[[1.02,2]],"id":67487132},{"spn":3.31,"spf":"NaN","id":67487132},{"spn":2.85,"spf":"NaN","id":70396461},{"spn":1.67,"spf":1.0,"id":57697855}],"con":true,"img":false}]}
{"op":"mcm","clk":"11540920771","pt":1719499984434,"mc":[{"id":"1.230180123","rc":[{"atb":[[1.8,2]],"id":43318163}],"con":true,"img":false}]}
{"op":"mcm","clk":"11540920789","pt":1719499984631,"mc":[{"id":"1.230180123","rc":[{"atb":[[1.02,2]],"id":40028187}],"con":true,"img":false}]}
{"op":"mcm","clk":"11540920810","pt":1719499984893,"mc":[{"id":"1.230180123","rc":[{"atb":[[1.29,2]],"id":70396461}],"con":true,"img":false}]}
{"op":"mcm","clk":"11540920838","pt":1719499985214,"mc":[{"id":"1.230180123","rc":[{"atb":[[1.02,2]],"id":47703807}],"con":true,"img":false}]}
{"op":"mcm","clk":"11540920869","pt":1719499985525,"mc":[{"id":"1.230180123","rc":[{"atb":[[1.02,2]],"id":57697855}],"con":true,"img":false}]}
{"op":"mcm","clk":"11540925208","pt":1719500044090,"mc":[{"id":"1.230180123","rc":[{"atb":[[1.01,1.7]],"id":40028187},{"atl":[[1000,1.93]],"id":40028187},{"atb":[[1.01,53.58]],"id":43318163},{"atl":[[1000,1.7]],"id":43318163},{"atb":[[1.01,53.58]],"id":67487132},{"atl":[[1000,1.93]],"id":67487132}],"con":true,"img":false}]}
{"op":"mcm","clk":"11540925214","pt":1719500044198,"mc":[{"id":"1.230180123","rc":[{"atl":[[1000,0.26]],"id":40028187}],"con":true,"img":false}]}
{"op":"mcm","clk":"11540925220","pt":1719500044297,"mc":[{"id":"1.230180123","rc":[{"atb":[[1.01,0.51]],"id":40028187},{"atb":[[1.01,52.25]],"id":43318163},{"atl":[[1000,0.01]],"id":43318163},{"spn":4.1,"spf":"NaN","id":43318163},{"atb":[[1.01,52.35]],"id":67487132},{"atl":[[1000,0.25]],"id":67487132}],"con":true,"img":false}]}
{"op":"mcm","clk":"11540925225","pt":1719500044399,"mc":[{"id":"1.230180123","rc":[{"atl":[[1000,0.23]],"id":40028187}],"con":true,"img":false}]}
{"op":"mcm","clk":"11540925234","pt":1719500044502,"mc":[{"id":"1.230180123","rc":[{"atb":[[1.01,0]],"id":40028187},{"atl":[[12.5,0.02]],"id":40028187},{"atb":[[1.01,51.87]],"id":43318163},{"atl":[[1000,0]],"id":43318163},{"atb":[[1.01,51.87]],"id":67487132},{"atl":[[1000,0.23]],"id":67487132}],"con":true,"img":false}]}
{"op":"mcm","clk":"11540925241","pt":1719500044607,"mc":[{"id":"1.230180123","rc":[{"atb":[[1.59,0.51]],"id":40028187},{"atb":[[1.81,0.37]],"id":43318163},{"atl":[[16.5,0.01]],"id":43318163},{"atb":[[1.64,0.47]],"id":67487132},{"atl":[[14.5,0.02]],"id":67487132}],"con":true,"img":false}]}
{"op":"mcm","clk":"11540925530","pt":1719500048109,"mc":[{"id":"1.230180123","rc":[{"atb":[[1.68,0]],"id":43318163}],"con":true,"img":false}]}
{"op":"mcm","clk":"11540926715","pt":1719500062702,"mc":[{"id":"1.230180123","rc":[{"atb":[[1.78,0]],"id":43318163}],"con":true,"img":false}]}
{"op":"mcm","clk":"11540927559","pt":1719500073534,"mc":[{"id":"1.230180123","rc":[{"atb":[[1.71,0]],"id":43318163}],"con":true,"img":false}]}
{"op":"mcm","clk":"11540928237","pt":1719500082431,"mc":[{"id":"1.230180123","rc":[{"atb":[[1.59,0]],"id":40028187},{"atl":[[12.5,0]],"id":40028187},{"atb":[[1.81,0]],"id":43318163},{"atl":[[16.5,0]],"id":43318163},{"atb":[[1.64,0]],"id":67487132},{"atl":[[14.5,0]],"id":67487132}],"con":true,"img":false}]}
{"op":"mcm","clk":"11540935712","pt":1719500171522,"mc":[{"id":"1.230180123","rc":[{"atl":[[1000,1.93]],"id":67487132}],"con":true,"img":false}]}
{"op":"mcm","clk":"11540935718","pt":1719500171628,"mc":[{"id":"1.230180123","rc":[{"atb":[[1.01,1.7]],"id":40028187},{"atl":[[1000,1.93]],"id":40028187},{"atb":[[1.01,53.58]],"id":43318163},{"atl":[[1000,1.7]],"id":43318163},{"atb":[[1.01,53.58]],"id":67487132}],"con":true,"img":false}]}
{"op":"mcm","clk":"11540935722","pt":1719500171722,"mc":[{"id":"1.230180123","rc":[{"atl":[[1000,0.25]],"id":67487132}],"con":true,"img":false}]}
{"op":"mcm","clk":"11540935742","pt":1719500171934,"mc":[{"id":"1.230180123","rc":[{"atb":[[1.01,0.5]],"id":40028187},{"atl":[[1000,0.26]],"id":40028187},{"atb":[[1.01,52.24]],"id":43318163},{"atl":[[1000,0.01]],"id":43318163},{"atb":[[1.01,52.34]],"id":67487132},{"atl":[[1000,0.23]],"id":67487132}],"con":true,"img":false}]}
{"op":"mcm","clk":"11540935755","pt":1719500172032,"mc":[{"id":"1.230180123","rc":[{"atl":[[14.5,0.02]],"id":67487132}],"con":true,"img":false}]}
{"op":"mcm","clk":"11540935763","pt":1719500172136,"mc":[{"id":"1.230180123","rc":[{"atl":[[1000,0.23]],"id":40028187},{"atb":[[1.01,51.87]],"id":43318163},{"atl":[[1000,0]],"id":43318163},{"atb":[[1.01,51.87]],"id":67487132}],"con":true,"img":false}]}
{"op":"mcm","clk":"11540935773","pt":1719500172245,"mc":[{"id":"1.230180123","rc":[{"atb":[[1.01,0]],"id":40028187},{"atl":[[12.5,0.02]],"id":40028187},{"atb":[[1.81,0.36]],"id":43318163},{"atl":[[16.5,0.01]],"id":43318163},{"atb":[[1.64,0.46]],"id":67487132}],"con":true,"img":false}]}
{"op":"mcm","clk":"11540935782","pt":1719500172348,"mc":[{"id":"1.230180123","rc":[{"atb":[[1.59,0.5]],"id":40028187}],"con":true,"img":false}]}
{"op":"mcm","clk":"11540938829","pt":1719500209882,"mc":[{"id":"1.230180123","rc":[{"atb":[[1.59,0]],"id":40028187},{"atl":[[12.5,0]],"id":40028187},{"atb":[[1.81,0]],"id":43318163},{"atl":[[16.5,0]],"id":43318163},{"atb":[[1.64,0]],"id":67487132},{"atl":[[14.5,0]],"id":67487132}],"con":true,"img":false}]}
{"op":"mcm","clk":"11540941491","pt":1719500247224,"mc":[{"id":"1.230180123","rc":[{"atb":[[1.08,50]],"id":40028187},{"atb":[[1.08,50]],"id":43318163},{"atb":[[1.08,50]],"id":47703807},{"atb":[[1.08,50]],"id":67487132},{"atb":[[1.08,50]],"id":70396461},{"atb":[[1.08,50]],"id":57697855}],"con":true,"img":false}]}
{"op":"mcm","clk":"11540943913","pt":1719500280343,"mc":[{"id":"1.230180123","rc":[{"atl":[[1000,1.93]],"id":40028187},{"atb":[[1.01,53.58]],"id":43318163},{"atl":[[1000,1.7]],"id":43318163},{"atb":[[1.01,53.58]],"id":67487132},{"atl":[[1000,1.93]],"id":67487132}],"con":true,"img":false}]}
{"op":"mcm","clk":"11540943923","pt":1719500280459,"mc":[{"id":"1.230180123","rc":[{"atb":[[1.01,1.7]],"id":40028187}],"con":true,"img":false}]}
{"op":"mcm","clk":"11540943937","pt":1719500280557,"mc":[{"id":"1.230180123","rc":[{"atl":[[1000,0.26]],"id":40028187},{"atb":[[1.01,52.23]],"id":43318163},{"atl":[[1000,0.01]],"id":43318163},{"atb":[[1.01,52.32]],"id":67487132},{"atl":[[1000,0.25]],"id":67487132}],"con":true,"img":false}]}
{"op":"mcm","clk":"11540943942","pt":1719500280656,"mc":[{"id":"1.230180123","rc":[{"atb":[[1.01,0.48]],"id":40028187}],"con":true,"img":false}]}
{"op":"mcm","clk":"11540943951","pt":1719500280759,"mc":[{"id":"1.230180123","rc":[{"atl":[[1000,0.23]],"id":40028187},{"atb":[[1.01,51.87]],"id":43318163},{"atl":[[1000,0]],"id":43318163},{"atb":[[1.01,51.87]],"id":67487132},{"atl":[[1000,0.23]],"id":67487132}],"con":true,"img":false}]}
{"op":"mcm","clk":"11540943958","pt":1719500280870,"mc":[{"id":"1.230180123","rc":[{"atb":[[1.01,0]],"id":40028187},{"atl":[[12.5,0.02]],"id":40028187},{"atb":[[1.81,0.35]],"id":43318163},{"atl":[[16.5,0.01]],"id":43318163},{"atb":[[1.64,0.44]],"id":67487132},{"atl":[[14.5,0.02]],"id":67487132}],"con":true,"img":false}]}
{"op":"mcm","clk":"11540943968","pt":1719500280968,"mc":[{"id":"1.230180123","rc":[{"atb":[[1.59,0.48]],"id":40028187}],"con":true,"img":false}]}
{"op":"mcm","clk":"11540945220","pt":1719500296277,"mc":[{"id":"1.230180123","rc":[{"atb":[[1.65,6.51]],"id":57697855}],"con":true,"img":false}]}
{"op":"mcm","clk":"11540945235","pt":1719500296387,"mc":[{"id":"1.230180123","rc":[{"atb":[[1.63,0],[1.66,2]],"id":57697855}],"con":true,"img":false}]}
{"op":"mcm","clk":"11540945799","pt":1719500303384,"mc":[{"id":"1.230180123","rc":[{"atb":[[1.68,5.8]],"id":57697855}],"con":true,"img":false}]}
{"op":"mcm","clk":"11540945805","pt":1719500303482,"mc":[{"id":"1.230180123","rc":[{"atb":[[1.66,0],[1.69,5.8]],"id":57697855}],"con":true,"img":false}]}
{"op":"mcm","clk":"11540945834","pt":1719500303897,"mc":[{"id":"1.230180123","rc":[{"atb":[[1.74,5.53]],"id":40028187},{"atb":[[1.81,2.65]],"id":43318163},{"atb":[[1.97,5]],"id":47703807},{"atb":[[1.63,7]],"id":67487132},{"atb":[[1.41,5]],"id":70396461},{"atb":[[1.7,2.9]],"id":57697855}],"con":true,"img":false}]}
{"op":"mcm","clk":"11540945843","pt":1719500304003,"mc":[{"id":"1.230180123","rc":[{"atb":[[1.58,0],[1.75,2]],"id":40028187},{"atb":[[1.81,5.3]],"id":43318163},{"atb":[[1.95,0]],"id":47703807},{"atb":[[1.42,2.48]],"id":70396461}],"con":true,"img":false}]}
{"op":"mcm","clk":"11540945849","pt":1719500304104,"mc":[{"id":"1.230180123","rc":[{"atb":[[1.8,7.3],[1.79,0],[1.81,2.65]],"id":43318163},{"atb":[[1.98,2.48]],"id":47703807},{"atb":[[1.28,0]],"id":70396461}],"con":true,"img":false}]}
{"op":"mcm","clk":"11540945891","pt":1719500304573,"mc":[{"id":"1.230180123","rc":[{"atb":[[1.02,0]],"id":67487132}],"con":true,"img":false}]}
{"op":"mcm","clk":"11540945899","pt":1719500304672,"mc":[{"id":"1.230180123","rc":[{"atb":[[1.64,2.44]],"id":67487132}],"con":true,"img":false}]}
{"op":"mcm","clk":"11540945926","pt":1719500304982,"mc":[{"id":"1.230180123","rc":[{"atb":[[1.8,5.3]],"id":43318163}],"con":true,"img":false}]}
{"op":"mcm","clk":"11540945937","pt":1719500305084,"mc":[{"id":"1.230180123","rc":[{"atb":[[1.82,2]],"id":43318163}],"con":true,"img":false}]}
{"op":"mcm","clk":"11540945955","pt":1719500305293,"mc":[{"id":"1.230180123","rc":[{"atb":[[1.29,0]],"id":70396461}],"con":true,"img":false}]}
{"op":"mcm","clk":"11540945964","pt":1719500305399,"mc":[{"id":"1.230180123","rc":[{"atb":[[1.43,2]],"id":70396461}],"con":true,"img":false}]}
{"op":"mcm","clk":"11540946014","pt":1719500305963,"mc":[{"id":"1.230180123","rc":[{"atb":[[1.58,2.11]],"id":67487132},{"atb":[[1.71,2.11]],"id":57697855}],"con":true,"img":false}]}
{"op":"mcm","clk":"11540946324","pt":1719500309796,"mc":[{"id":"1.230180123","rc":[{"spn":4.07,"spf":"NaN","id":40028187},{"spn":4.11,"spf":"NaN","id":43318163},{"spn":5.19,"spf":"NaN","id":47703807},{"spn":3.32,"spf":"NaN","id":67487132},{"spn":2.86,"spf":"NaN","id":70396461},{"atb":[[1.71,5.01],[1.69,0]],"id":57697855},{"spn":1.71,"spf":1.0,"id":57697855}],"con":true,"img":false}]}
{"op":"mcm","clk":"11540946334","pt":1719500309908,"mc":[{"id":"1.230180123","rc":[{"atb":[[1.7,8.7],[1.71,2.11]],"id":57697855}],"con":true,"img":false}]}
{"op":"mcm","clk":"11540946374","pt":1719500310409,"mc":[{"id":"1.230180123","rc":[{"atb":[[1.82,4.65],[1.8,0]],"id":43318163}],"con":true,"img":false}]}
{"op":"mcm","clk":"11540946382","pt":1719500310504,"mc":[{"id":"1.230180123","rc":[{"atb":[[1.82,2],[1.81,6.65]],"id":43318163}],"con":true,"img":false}]}
{"op":"mcm","clk":"11540946949","pt":1719500318021,"mc":[{"id":"1.230180123","rc":[{"atb":[[1.81,4.35]],"id":43318163},{"atb":[[1.63,2]],"id":67487132},{"atb":[[1.41,1]],"id":70396461},{"atb":[[1.7,5.8]],"id":57697855}],"con":true,"img":false}]}
{"op":"mcm","clk":"11540946963","pt":1719500318082,"mc":[{"id":"1.230180123","rc":[{"atb":[[1.82,4.94]],"id":43318163},{"atb":[[1.65,3.26]],"id":67487132},{"atb":[[1.43,5.53]],"id":70396461},{"atb":[[1.71,5.51]],"id":57697855}],"con":true,"img":false}]}
{"op":"mcm","clk":"11540946970","pt":1719500318176,"mc":[{"id":"1.230180123","rc":[{"atb":[[1.83,4.35]],"id":43318163},{"atb":[[1.63,0],[1.66,2.44]],"id":67487132},{"atb":[[1.44,2.48]],"id":70396461}],"con":true,"img":false}]}
{"op":"mcm","clk":"11540946978","pt":1719500318279,"mc":[{"id":"1.230180123","rc":[{"atb":[[1.81,0.35]],"id":43318163},{"atb":[[1.42,0]],"id":70396461},{"atb":[[1.72,5.8],[1.7,0]],"id":57697855}],"con":true,"img":false}]}
{"op":"mcm","clk":"11540947022","pt":1719500318793,"mc":[{"id":"1.230180123","rc":[{"atb":[[1.64,0.44]],"id":67487132}],"con":true,"img":false}]}
{"op":"mcm","clk":"11540947033","pt":1719500318902,"mc":[{"id":"1.230180123","rc":[{"atb":[[1.67,2]],"id":67487132}],"con":true,"img":false}]}
{"op":"mcm","clk":"11540947078","pt":1719500319418,"mc":[{"id":"1.230180123","rc":[{"atb":[[1.82,2.94]],"id":43318163}],"con":true,"img":false}]}
{"op":"mcm","clk":"11540947091","pt":1719500319467,"mc":[{"id":"1.230180123","rc":[{"atb":[[1.84,2]],"id":43318163}],"con":true,"img":false}]}
{"op":"mcm","clk":"11540947116","pt":1719500319777,"mc":[{"id":"1.230180123","rc":[{"atb":[[1.43,3.53]],"id":70396461}],"con":true,"img":false}]}
{"op":"mcm","clk":"11540947125","pt":1719500319885,"mc":[{"id":"1.230180123","rc":[{"atb":[[1.02,27.93]],"id":70396461}],"con":true,"img":false}]}
{"op":"mcm","clk":"11540947397","pt":1719500323301,"mc":[{"id":"1.230180123","rc":[{"atb":[[1.59,0]],"id":40028187},{"atl":[[12.5,0]],"id":40028187},{"atb":[[1.81,0]],"id":43318163},{"atl":[[16.5,0]],"id":43318163},{"atb":[[1.64,0]],"id":67487132},{"atl":[[14.5,0]],"id":67487132}],"con":true,"img":false}]}
{"op":"mcm","clk":"11540947790","pt":1719500327796,"mc":[{"id":"1.230180123","rc":[{"atb":[[2.3,2.5],[2.22,5],[2.14,10],[1.76,2.25]],"id":40028187},{"atl":[[7.2,10],[6.4,6],[5.8,2.5],[6.2,2.25]],"id":40028187},{"atb":[[2.42,2.5],[1.85,3],[2.26,10],[2.34,5]],"id":43318163},{"atl":[[17,0],[6.2,3],[6,2.5],[6.8,5],[7.6,10],[12,2]],"id":43318163},{"atb":[[2.92,5],[1.99,2.25],[1.98,0],[2.04,2.48],[3,2.5],[2.84,10]],"id":47703807},{"atl":[[8,2.5],[9.6,10],[8.2,2.25],[46,0],[8.8,5],[28,2]],"id":47703807},{"atb":[[1.7,2.44],[1.68,3],[1.95,10],[1.99,5],[2.06,2.5],[1.66,0]],"id":67487132},{"atl":[[5,6],[4.6,2.5],[4.9,3],[12.5,2],[15,0],[5.4,10]],"id":67487132},{"atb":[[1.44,0],[1.89,5],[1.45,2.25],[1.85,10],[1.93,2.5],[1.48,2.48]],"id":70396461},{"atl":[[4.6,5],[5,10],[7,2],[4.2,4.75],[9.4,0]],"id":70396461},{"atb":[[1.73,5.64],[2.08,10],[2.24,2.5],[1.72,0],[1.77,5.8],[2.16,5]],"id":57697855},{"atl":[[5.1,2.5],[5.5,5],[11,2],[4.9,5.64],[5.9,10],[15,0]],"id":57697855}],"con":true,"img":false}]}
{"op":"mcm","clk":"11540947795","pt":1719500327896,"mc":[{"id":"1.230180123","rc":[{"atb":[[2.28,2.48]],"id":47703807},{"atl":[[28,0]],"id":47703807}],"con":true,"img":false}]}
{"op":"mcm","clk":"11540947802","pt":1719500328002,"mc":[{"id":"1.230180123","rc":[{"atb":[[1.75,0],[2.14,12]],"id":40028187},{"atl":[[6.4,8],[13,0]],"id":40028187},{"atb":[[1.83,0],[2.26,12.94]],"id":43318163},{"atl":[[6.4,3],[12,0]],"id":43318163},{"atb":[[2.04,0]],"id":47703807},{"atl":[[8.4,3]],"id":47703807},{"atb":[[1.7,0],[1.95,12.44]],"id":67487132},{"atl":[[12.5,0],[9.8,2]],"id":67487132}],"con":true,"img":false}]}
{"op":"mcm","clk":"11540947813","pt":1719500328104,"mc":[{"id":"1.230180123","rc":[{"atb":[[2.28,0],[2.84,17.5]],"id":47703807}],"con":true,"img":false}]}
{"op":"mcm","clk":"11540947821","pt":1719500328207,"mc":[{"id":"1.230180123","rc":[{"atl":[[3.85,12.98]],"id":70396461}],"con":true,"img":false}]}
{"op":"mcm","clk":"11540947830","pt":1719500328307,"mc":[{"id":"1.230180123","rc":[{"atl":[[5.7,0.84]],"id":40028187},{"atl":[[5.9,0.84]],"id":43318163},{"atl":[[7.8,0.84]],"id":47703807},{"atl":[[4.5,0.84]],"id":67487132},{"atl":[[4.1,0.84]],"id":70396461},{"atl":[[4.8,0.84]],"id":57697855}],"con":true,"img":false}]}
{"op":"mcm","clk":"11540947862","pt":1719500328725,"mc":[{"id":"1.230180123","rc":[{"atb":[[1.67,0]],"id":67487132},{"atl":[[4.1,0]],"id":70396461}],"con":true,"img":false}]}
{"op":"mcm","clk":"11540947871","pt":1719500328827,"mc":[{"id":"1.230180123","rc":[{"atb":[[2.08,2]],"id":67487132}],"con":true,"img":false}]}
{"op":"mcm","clk":"11540947905","pt":1719500329201,"mc":[{"id":"1.230180123","rc":[{"atb":[[1.84,0]],"id":43318163}],"con":true,"img":false}]}
{"op":"mcm","clk":"11540947914","pt":1719500329299,"mc":[{"id":"1.230180123","rc":[{"atb":[[2.44,2]],"id":43318163}],"con":true,"img":false}]}
{"op":"mcm","clk":"11540947922","pt":1719500329415,"mc":[{"id":"1.230180123","rc":[{"atb":[[2.4,5],[2.26,10]],"id":43318163}],"con":true,"img":false}]}
{"op":"mcm","clk":"11540947946","pt":1719500329712,"mc":[{"id":"1.230180123","rc":[{"atb":[[1.02,0]],"id":40028187}],"con":true,"img":false}]}
{"op":"mcm","clk":"11540947957","pt":1719500329817,"mc":[{"id":"1.230180123","rc":[{"atb":[[2.32,2]],"id":40028187}],"con":true,"img":false}]}
{"op":"mcm","clk":"11540947976","pt":1719500330025,"mc":[{"id":"1.230180123","rc":[{"atl":[[4.8,5.03]],"id":67487132}],"con":true,"img":false}]}
{"op":"mcm","clk":"11540947985","pt":1719500330125,"mc":[{"id":"1.230180123","rc":[{"atb":[[1.02,25.93]],"id":70396461}],"con":true,"img":false}]}
{"op":"mcm","clk":"11540947993","pt":1719500330182,"mc":[{"id":"1.230180123","rc":[{"atb":[[1.94,2]],"id":70396461}],"con":true,"img":false}]}
{"op":"mcm","clk":"11540948001","pt":1719500330290,"mc":[{"id":"1.230180123","rc":[{"atb":[[2.2,2.11]],"id":40028187},{"atl":[[4.8,0]],"id":67487132},{"atb":[[1.88,2.11]],"id":70396461}],"con":true,"img":false}]}
{"op":"mcm","clk":"11540948201","pt":1719500332913,"mc":[{"id":"1.230180123","rc":[{"atb":[[1.74,1]],"id":40028187},{"atb":[[1.82,0]],"id":43318163},{"atb":[[1.97,1]],"id":47703807},{"atb":[[1.65,0]],"id":67487132},{"atb":[[1.43,0]],"id":70396461},{"atb":[[1.71,2.11]],"id":57697855}],"con":true,"img":false}]}
{"op":"mcm","clk":"11540948211","pt":1719500333019,"mc":[{"id":"1.230180123","rc":[{"atb":[[2.32,4.55]],"id":40028187},{"atb":[[2.44,4.21]],"id":43318163},{"atb":[[3,6.5]],"id":47703807}],"con":true,"img":false}]}
{"op":"mcm","clk":"11540948305","pt":1719500333906,"mc":[{"id":"1.230180123","rc":[{"atb":[[1.88,7.11],[1.48,0]],"id":70396461},{"atl":[[3.8,4.75],[7,0]],"id":70396461},{"atb":[[2.08,17.5],[1.77,0]],"id":57697855},{"atl":[[5,7.49],[11,0]],"id":57697855}],"con":true,"img":false}]}
{"op":"mcm","clk":"11540948311","pt":1719500334000,"mc":[{"id":"1.230180123","rc":[{"atb":[[2.4,0],[2.42,10.92]],"id":43318163}],"con":true,"img":false}]}
{"op":"mcm","clk":"11540948319","pt":1719500334102,"mc":[{"id":"1.230180123","rc":[{"atb":[[2.84,10],[3.05,6.5]],"id":47703807},{"atb":[[1.95,10],[2.08,4.5]],"id":67487132},{"atl":[[4.9,9],[9.8,0]],"id":67487132}],"con":true,"img":false}]}
{"op":"mcm","clk":"11540948334","pt":1719500334306,"mc":[{"id":"1.230180123","rc":[{"atb":[[2.28,2.11],[2.2,0]],"id":40028187},{"atb":[[1.74,1],[2.46,2.11]],"id":43318163}],"con":true,"img":false}]}
{"op":"mcm","clk":"11540948425","pt":1719500335393,"mc":[{"id":"1.230180123","rc":[{"atb":[[2.44,2.21]],"id":43318163}],"con":true,"img":false}]}
{"op":"mcm","clk":"11540948434","pt":1719500335496,"mc":[{"id":"1.230180123","rc":[{"atb":[[2.48,2]],"id":43318163}],"con":true,"img":false}]}
{"op":"mcm","clk":"11540948446","pt":1719500335703,"mc":[{"id":"1.230180123","rc":[{"atl":[[3.75,0.84]],"id":70396461}],"con":true,"img":false}]}
{"op":"mcm","clk":"11540948824","pt":1719500340812,"mc":[{"id":"1.230180123","rc":[{"atb":[[2.32,8.11]],"id":40028187},{"atl":[[5.7,4.4]],"id":40028187},{"atb":[[2.48,5.25]],"id":43318163},{"atl":[[5.9,4.09]],"id":43318163},{"atb":[[3.05,12.12]],"id":47703807},{"atl":[[7.8,6.46]],"id":47703807},{"atb":[[2.08,9.75]],"id":67487132},{"atl":[[4.5,6.09]],"id":67487132},{"atb":[[1.94,7.44]],"id":70396461},{"atl":[[3.75,6.28]],"id":70396461},{"atb":[[2.24,10.48]],"id":57697855},{"atl":[[4.8,8.82]],"id":57697855}],"con":true,"img":false}]}
{"op":"mcm","clk":"11540948832","pt":1719500340917,"mc":[{"id":"1.230180123","rc":[{"atb":[[1.76,0]],"id":40028187},{"atl":[[6.2,0]],"id":40028187},{"atb":[[1.99,0]],"id":47703807},{"atl":[[8.2,0]],"id":47703807},{"atb":[[1.99,12],[1.68,0],[2.08,7.25]],"id":67487132},{"atl":[[4.9,6]],"id":67487132},{"atb":[[1.45,0]],"id":70396461},{"atl":[[4.2,2.5]],"id":70396461},{"atb":[[1.73,0]],"id":57697855},{"atl":[[4.9,0]],"id":57697855}],"con":true,"img":false}]}
{"op":"mcm","clk":"11540948838","pt":1719500341018,"mc":[{"id":"1.230180123","rc":[{"atb":[[1.85,0]],"id":43318163},{"atl":[[6.2,0]],"id":43318163},{"atb":[[1.99,5],[2.08,12.25]],"id":67487132},{"atl":[[5.1,18.82]],"id":57697855}],"con":true,"img":false}]}
{"op":"mcm","clk":"11540948845","pt":1719500341120,"mc":[{"id":"1.230180123","rc":[{"atb":[[1.99,15],[2.08,7.25]],"id":67487132},{"atl":[[5,1]],"id":57697855}],"con":true,"img":false}]}
{"op":"mcm","clk":"11540949345","pt":1719500346623,"mc":[{"id":"1.230180123","rc":[{"atb":[[1.92,2.11],[1.88,5]],"id":70396461}],"con":true,"img":false}]}
{"op":"mcm","clk":"11540949376","pt":1719500347035,"mc":[{"id":"1.230180123","rc":[{"atb":[[2.44,0]],"id":43318163},{"atb":[[3,2.5]],"id":47703807},{"atb":[[1.99,5],[2.08,14.5]],"id":67487132}],"con":true,"img":false}]}
{"op":"mcm","clk":"11540949384","pt":1719500347138,"mc":[{"id":"1.230180123","rc":[{"atb":[[2.5,3]],"id":43318163},{"atb":[[2.92,19.62],[3.1,2.42],[3.05,5.62]],"id":47703807},{"atb":[[2.26,3.18]],"id":57697855}],"con":true,"img":false}]}
{"op":"mcm","clk":"11540949393","pt":1719500347244,"mc":[{"id":"1.230180123","rc":[{"atb":[[2.08,10],[2.28,5]],"id":57697855}],"con":true,"img":false}]}
{"op":"mcm","clk":"11540949419","pt":1719500347603,"mc":[{"id":"1.230180123","rc":[{"atb":[[2.06,10],[2.14,10]],"id":40028187},{"atb":[[2.4,8.25],[2.42,2.5]],"id":43318163}],"con":true,"img":false}]}
{"op":"mcm","clk":"11540949471","pt":1719500348326,"mc":[{"id":"1.230180123","rc":[{"atb":[[2.48,3.25]],"id":43318163}],"con":true,"img":false}]}
{"op":"mcm","clk":"11540949479","pt":1719500348435,"mc":[{"id":"1.230180123","rc":[{"atb":[[2.52,2]],"id":43318163}],"con":true,"img":false}]}
{"op":"mcm","clk":"11540949873","pt":1719500353049,"mc":[{"id":"1.230180123","rc":[{"atb":[[2.92,5],[3.1,4.92]],"id":47703807}],"con":true,"img":false}]}
{"op":"mcm","clk":"11540949911","pt":1719500353516,"mc":[{"id":"1.230180123","rc":[{"atb":[[2.52,6.5]],"id":43318163},{"atb":[[3.1,10.86]],"id":47703807},{"atb":[[2.28,15.37]],"id":57697855}],"con":true,"img":false}]}
{"op":"mcm","clk":"11540949920","pt":1719500353620,"mc":[{"id":"1.230180123","rc":[{"atl":[[5.8,4.5]],"id":43318163},{"atb":[[2.24,2.5]],"id":57697855}],"con":true,"img":false}]}
{"op":"mcm","clk":"11540949929","pt":1719500353722,"mc":[{"id":"1.230180123","rc":[{"atb":[[2.48,0]],"id":43318163},{"atl":[[6.4,1],[5.7,4.1]],"id":43318163},{"atb":[[3.05,0]],"id":47703807}],"con":true,"img":false}]}
{"op":"mcm","clk":"11540949939","pt":1719500353827,"mc":[{"id":"1.230180123","rc":[{"atl":[[5.9,0.84]],"id":43318163}],"con":true,"img":false}]}
{"op":"mcm","clk":"11540949963","pt":1719500354141,"mc":[{"id":"1.230180123","rc":[{"atl":[[5.6,0.84],[5.9,0]],"id":43318163}],"con":true,"img":false}]}
{"op":"mcm","clk":"11540950246","pt":1719500358737,"mc":[{"id":"1.230180123","rc":[{"atb":[[1.71,0],[2.34,2.11]],"id":57697855}],"con":true,"img":false}]}
{"op":"mcm","clk":"11540950251","pt":1719500358835,"mc":[{"id":"1.230180123","rc":[{"atl":[[5.8,9.45],[5.7,0]],"id":43318163},{"atb":[[2.3,4.24],[2.28,10.37]],"id":57697855}],"con":true,"img":false}]}
{"op":"mcm","clk":"11540950276","pt":1719500359143,"mc":[{"id":"1.230180123","rc":[{"atl":[[5.6,0]],"id":43318163}],"con":true,"img":false}]}
{"op":"mcm","clk":"11540950283","pt":1719500359247,"mc":[{"id":"1.230180123","rc":[{"atl":[[6.4,12.95],[5.8,4.5]],"id":43318163}],"con":true,"img":false}]}
{"op":"mcm","clk":"11540950417","pt":1719500361165,"mc":[{"id":"1.230180123","rc":[{"atb":[[2.5,0]],"id":43318163},{"atl":[[5.7,0.84]],"id":43318163},{"atb":[[2.26,0]],"id":57697855}],"con":true,"img":false}]}
{"op":"mcm","clk":"11540950424","pt":1719500361273,"mc":[{"id":"1.230180123","rc":[{"atb":[[2.54,2.54]],"id":43318163},{"atl":[[6.4,1],[6,7.85]],"id":43318163},{"atb":[[2.34,5.67]],"id":57697855}],"con":true,"img":false}]}
{"op":"mcm","clk":"11540950509","pt":1719500362356,"mc":[{"id":"1.230180123","rc":[{"atb":[[2.52,4.5]],"id":43318163}],"con":true,"img":false}]}
{"op":"mcm","clk":"11540950518","pt":1719500362458,"mc":[{"id":"1.230180123","rc":[{"atb":[[2.56,2]],"id":43318163}],"con":true,"img":false}]}
{"op":"mcm","clk":"11540950631","pt":1719500363657,"mc":[{"id":"1.230180123","rc":[{"atl":[[5.3,3.33]],"id":57697855}],"con":true,"img":false}]}
{"op":"mcm","clk":"11540950723","pt":1719500364953,"mc":[{"id":"1.230180123","rc":[{"atl":[[5.3,0]],"id":57697855}],"con":true,"img":false}]}
{"op":"mcm","clk":"11540950747","pt":1719500365273,"mc":[{"id":"1.230180123","rc":[{"atl":[[5.3,5.4]],"id":57697855}],"con":true,"img":false}]}
{"op":"mcm","clk":"11540950771","pt":1719500365572,"mc":[{"id":"1.230180123","rc":[{"atl":[[3.85,0]],"id":70396461}],"con":true,"img":false}]}
{"op":"mcm","clk":"11540950776","pt":1719500365678,"mc":[{"id":"1.230180123","rc":[{"atl":[[4.4,8.25]],"id":67487132},{"atl":[[3.7,5.44],[3.8,0],[4.2,13.54]],"id":70396461}],"con":true,"img":false}]}
{"op":"mcm","clk":"11540950784","pt":1719500365783,"mc":[{"id":"1.230180123","rc":[{"atl":[[4.5,0.84],[4.6,14.7],[4.9,0]],"id":67487132},{"atl":[[3.8,12.58],[4.2,2.5],[3.75,0.84]],"id":70396461},{"atl":[[4.7,10.88]],"id":57697855}],"con":true,"img":false}]}
{"op":"mcm","clk":"11540950794","pt":1719500365885,"mc":[{"id":"1.230180123","rc":[{"atl":[[3.8,0],[4.2,14.23]],"id":70396461},{"atl":[[4.8,0.84]],"id":57697855}],"con":true,"img":false}]}
{"op":"mcm","clk":"11540950802","pt":1719500365940,"mc":[{"id":"1.230180123","rc":[{"atl":[[3.8,6.29],[4.2,2.5]],"id":70396461}],"con":true,"img":false}]}
{"op":"mcm","clk":"11540950809","pt":1719500366047,"mc":[{"id":"1.230180123","rc":[{"atb":[[2.3,6.39]],"id":40028187},{"atb":[[2.5,3.47],[2.56,7.28]],"id":43318163},{"atl":[[5.7,6.12]],"id":43318163},{"atb":[[2.06,7.8]],"id":67487132},{"atb":[[1.92,7.26]],"id":70396461},{"atl":[[3.8,0],[4.2,8.79]],"id":70396461},{"atb":[[2.34,13.11]],"id":57697855}],"con":true,"img":false}]}
{"op":"mcm","clk":"11540950817","pt":1719500366151,"mc":[{"id":"1.230180123","rc":[{"atb":[[2.5,0],[2.52,0]],"id":43318163},{"atl":[[5.8,0]],"id":43318163},{"atl":[[4.3,0.84]],"id":67487132},{"atl":[[3.8,6.29],[4.2,2.5],[3.65,0.84]],"id":70396461},{"atb":[[2.3,0],[2.28,9.92]],"id":57697855},{"atl":[[4.6,0.84]],"id":57697855}],"con":true,"img":false}]}
{"op":"mcm","clk":"11540950825","pt":1719500366258,"mc":[{"id":"1.230180123","rc":[{"atl":[[3.85,8.91],[3.8,0],[4.2,8.79]],"id":70396461},{"atb":[[2.3,26.24],[2.28,0]],"id":57697855}],"con":true,"img":false}]}
{"op":"mcm","clk":"11540950836","pt":1719500366353,"mc":[{"id":"1.230180123","rc":[{"atl":[[6.4,14.98],[6,2.5]],"id":43318163},{"atl":[[4.8,12.57],[5.1,2.5]],"id":57697855}],"con":true,"img":false}]}
{"op":"mcm","clk":"11540950846","pt":1719500366462,"mc":[{"id":"1.230180123","rc":[{"atl":[[3.85,0],[4.2,2.5],[3.75,7.13]],"id":70396461}],"con":true,"img":false}]}
{"op":"mcm","clk":"11540950879","pt":1719500366776,"mc":[{"id":"1.230180123","rc":[{"atl":[[5.3,0]],"id":57697855}],"con":true,"img":false}]}
{"op":"mcm","clk":"11540950890","pt":1719500366870,"mc":[{"id":"1.230180123","rc":[{"atl":[[3.8,5.61]],"id":70396461}],"con":true,"img":false}]}
{"op":"mcm","clk":"11540950918","pt":1719500367191,"mc":[{"id":"1.230180123","rc":[{"atl":[[3.8,0]],"id":70396461}],"con":true,"img":false}]}
{"op":"mcm","clk":"11540950948","pt":1719500367443,"mc":[{"id":"1.230180123","rc":[{"atl":[[3.7,14.72]],"id":70396461}],"con":true,"img":false}]}
{"op":"mcm","clk":"11540951018","pt":1719500368275,"mc":[{"id":"1.230180123","rc":[{"atb":[[2.06,36.8],[2.08,7.25]],"id":67487132},{"atb":[[2.3,0],[2.26,39.36]],"id":57697855}],"con":true,"img":false}]}
{"op":"mcm","clk":"11540951029","pt":1719500368378,"mc":[{"id":"1.230180123","rc":[{"atb":[[1.99,49.05]],"id":67487132}],"con":true,"img":false}]}
{"op":"mcm","clk":"11540951040","pt":1719500368476,"mc":[{"id":"1.230180123","rc":[{"atb":[[2.06,7.8]],"id":67487132}],"con":true,"img":false}]}
{"op":"mcm","clk":"11540951045","pt":1719500368582,"mc":[{"id":"1.230180123","rc":[{"atb":[[1.99,5],[2.06,22.3]],"id":67487132}],"con":true,"img":false}]}
{"op":"mcm","clk":"11540951095","pt":1719500369255,"mc":[{"id":"1.230180123","rc":[{"atl":[[3.7,5.44]],"id":70396461}],"con":true,"img":false}]}
{"op":"mcm","clk":"11540951109","pt":1719500369465,"mc":[{"id":"1.230180123","rc":[{"atl":[[3.65,7.37]],"id":70396461}],"con":true,"img":false}]}
{"op":"mcm","clk":"11540951138","pt":1719500369778,"mc":[{"id":"1.230180123","rc":[{"atb":[[2.54,0]],"id":43318163}],"con":true,"img":false}]}
{"op":"mcm","clk":"11540951148","pt":1719500369883,"mc":[{"id":"1.230180123","rc":[{"spn":4.01,"spf":"NaN","id":40028187},{"atb":[[2.58,2.89]],"id":43318163},{"spn":4.14,"spf":"NaN","id":43318163},{"spn":5.45,"spf":"NaN","id":47703807},{"spn":3.19,"spf":"NaN","id":67487132},{"spn":2.79,"spf":"NaN","id":70396461},{"atb":[[2.24,6.75]],"id":57697855},{"spn":2.34,"spf":1.0,"id":57697855}],"con":true,"img":false}]}
{"op":"mcm","clk":"11540951174","pt":1719500370190,"mc":[{"id":"1.230180123","rc":[{"atl":[[3.75,6.29]],"id":70396461}],"con":true,"img":false}]}
{"op":"mcm","clk":"11540951228","pt":1719500370870,"mc":[{"id":"1.230180123","rc":[{"atb":[[2.56,5.28]],"id":43318163}],"con":true,"img":false}]}
{"op":"mcm","clk":"11540951234","pt":1719500370971,"mc":[{"id":"1.230180123","rc":[{"atb":[[2.6,2]],"id":43318163}],"con":true,"img":false}]}
{"op":"mcm","clk":"11540951324","pt":1719500372168,"mc":[{"id":"1.230180123","rc":[{"atl":[[3.6,6.29],[3.75,0]],"id":70396461}],"con":true,"img":false}]}
{"op":"mcm","clk":"11540951426","pt":1719500373261,"mc":[{"id":"1.230180123","rc":[{"atl":[[3.55,0.84]],"id":70396461}],"con":true,"img":false}]}
{"op":"mcm","clk":"11540951454","pt":1719500373572,"mc":[{"id":"1.230180123","rc":[{"atb":[[2.4,0],[2.28,5.78]],"id":43318163},{"atb":[[2.02,29.55],[2.06,2.5]],"id":67487132},{"atb":[[1.82,12.27],[1.92,2.11],[1.88,0]],"id":70396461},{"atb":[[2.26,0],[2.2,26.24]],"id":57697855}],"con":true,"img":false}]}
{"op":"mcm","clk":"11540951478","pt":1719500373879,"mc":[{"id":"1.230180123","rc":[{"atb":[[2.24,2.5]],"id":57697855}],"con":true,"img":false}]}
{"op":"mcm","clk":"11540951539","pt":1719500374449,"mc":[{"id":"1.230180123","rc":[{"atl":[[5.2,1.68]],"id":57697855}],"con":true,"img":false}]}
{"op":"mcm","clk":"11540951580","pt":1719500374966,"mc":[{"id":"1.230180123","rc":[{"atb":[[1.58,0],[2.08,9.36]],"id":67487132}],"con":true,"img":false}]}
{"op":"mcm","clk":"11540951606","pt":1719500375274,"mc":[{"id":"1.230180123","rc":[{"atb":[[2.04,5.1]],"id":57697855},{"atl":[[5.2,0]],"id":57697855}],"con":true,"img":false}]}
{"op":"mcm","clk":"11540951618","pt":1719500375483,"mc":[{"id":"1.230180123","rc":[{"atl":[[5,6.34]],"id":57697855}],"con":true,"img":false}]}
{"op":"mcm","clk":"11540951702","pt":1719500376570,"mc":[{"id":"1.230180123","rc":[{"atl":[[5,1]],"id":57697855}],"con":true,"img":false}]}
{"op":"mcm","clk":"11540951720","pt":1719500376888,"mc":[{"id":"1.230180123","rc":[{"atl":[[4.9,5.11]],"id":57697855}],"con":true,"img":false}]}
{"op":"mcm","clk":"11540951782","pt":1719500377565,"mc":[{"id":"1.230180123","rc":[{"atl":[[4.9,0]],"id":57697855}],"con":true,"img":false}]}
{"op":"mcm","clk":"11540951807","pt":1719500377878,"mc":[{"id":"1.230180123","rc":[{"atl":[[4.2,8.06]],"id":67487132},{"atl":[[3.55,7.43]],"id":70396461}],"con":true,"img":false}]}
{"op":"mcm","clk":"11540951814","pt":1719500377981,"mc":[{"id":"1.230180123","rc":[{"atl":[[4.6,2.5]],"id":67487132},{"atl":[[3.7,0]],"id":70396461},{"atl":[[4.5,17.6]],"id":57697855}],"con":true,"img":false}]}
{"op":"mcm","clk":"11540951825","pt":1719500378091,"mc":[{"id":"1.230180123","rc":[{"atl":[[4.7,0]],"id":57697855}],"con":true,"img":false}]}
{"op":"mcm","clk":"11540951834","pt":1719500378192,"mc":[{"id":"1.230180123","rc":[{"atl":[[4.5,0],[4.1,0.84]],"id":67487132},{"atl":[[3.65,6.53]],"id":70396461}],"con":true,"img":false}]}
{"op":"mcm","clk":"11540951848","pt":1719500378292,"mc":[{"id":"1.230180123","rc":[{"atb":[[2.6,8.13]],"id":43318163}],"con":true,"img":false}]}
{"op":"mcm","clk":"11540951860","pt":1719500378347,"mc":[{"id":"1.230180123","rc":[{"atb":[[2.56,0]],"id":43318163}],"con":true,"img":false}]}
{"op":"mcm","clk":"11540951867","pt":1719500378451,"mc":[{"id":"1.230180123","rc":[{"atb":[[2.58,0]],"id":43318163},{"atb":[[2.34,9.55]],"id":57697855}],"con":true,"img":false}]}
{"op":"mcm","clk":"11540951879","pt":1719500378655,"mc":[{"id":"1.230180123","rc":[{"atb":[[2.06,0],[1.87,14.5]],"id":40028187},{"atb":[[2.6,11.03]],"id":43318163},{"atb":[[3.1,8.36],[3,24.22]],"id":47703807},{"atb":[[2.02,0],[2.06,21.24]],"id":67487132},{"atb":[[1.82,0],[1.85,20]],"id":70396461},{"atb":[[1.96,14.66],[2.34,2.11],[2.08,0],[2.24,0],[2.2,0],[2.16,0]],"id":57697855},{"atl":[[4.8,11.73],[4.4,0.84]],"id":57697855}],"con":true,"img":false}]}
{"op":"mcm","clk":"11540951884","pt":1719500378766,"mc":[{"id":"1.230180123","rc":[{"atb":[[2.04,0]],"id":57697855}],"con":true,"img":false}]}
{"op":"mcm","clk":"11540951891","pt":1719500378863,"mc":[{"id":"1.230180123","rc":[{"atb":[[2.92,37.58],[3,2.5]],"id":47703807},{"atb":[[1.96,15.93],[1.71,10],[1.79,2.5],[1.75,5]],"id":57697855},{"atl":[[4.8,0],[4.6,19.29]],"id":57697855}],"con":true,"img":false}]}
{"op":"mcm","clk":"11540952200","pt":1719500382401,"mc":[{"id":"1.230180123","rc":[{"atb":[[2.3,3.89],[2.5,10],[2.22,0],[2.58,5],[2.14,0],[2.66,2.5]],"id":40028187},{"atb":[[2.54,10],[2.26,0],[2.62,5],[2.34,0],[2.42,0],[2.7,2.5]],"id":43318163},{"atb":[[3.2,2.5],[2.84,0]],"id":47703807},{"atl":[[4.2,10.56],[5.4,0]],"id":67487132},{"atl":[[4.6,0],[5,0],[4.1,2.5],[4.2,0]],"id":70396461},{"atl":[[5.1,0],[4.6,24.29],[5,11],[5.5,0],[5.9,0],[4.2,2.5]],"id":57697855}],"con":true,"img":false}]}
{"op":"mcm","clk":"11540952208","pt":1719500382461,"mc":[{"id":"1.230180123","rc":[{"atb":[[2.66,9.56]],"id":40028187},{"atb":[[3.25,4.12]],"id":47703807},{"atl":[[4.4,0],[4.2,18.81]],"id":67487132}],"con":true,"img":false}]}
{"op":"mcm","clk":"11540952218","pt":1719500382562,"mc":[{"id":"1.230180123","rc":[{"atb":[[2.32,4.55]],"id":40028187},{"atb":[[3.1,2.42]],"id":47703807}],"con":true,"img":false}]}
{"op":"mcm","clk":"11540952235","pt":1719500382767,"mc":[{"id":"1.230180123","rc":[{"atb":[[2.3,0]],"id":40028187},{"atl":[[4.6,23.45],[4.4,0]],"id":57697855}],"con":true,"img":false}]}
{"op":"mcm","clk":"11540952291","pt":1719500383487,"mc":[{"id":"1.230180123","rc":[{"atb":[[2.6,9.03]],"id":43318163}],"con":true,"img":false}]}
{"op":"mcm","clk":"11540952302","pt":1719500383590,"mc":[{"id":"1.230180123","rc":[{"atb":[[2.72,2]],"id":43318163}],"con":true,"img":false}]}
{"op":"mcm","clk":"11540952315","pt":1719500383797,"mc":[{"id":"1.230180123","rc":[{"atb":[[1.96,1.27],[1.88,18.05]],"id":57697855}],"con":true,"img":false}]}
{"op":"mcm","clk":"11540952320","pt":1719500383899,"mc":[{"id":"1.230180123","rc":[{"atb":[[2.32,2.55]],"id":40028187}],"con":true,"img":false}]}
{"op":"mcm","clk":"11540952325","pt":1719500384003,"mc":[{"id":"1.230180123","rc":[{"atb":[[2.68,2]],"id":40028187}],"con":true,"img":false}]}
{"op":"mcm","clk":"11540952349","pt":1719500384372,"mc":[{"id":"1.230180123","rc":[{"atb":[[2.92,5],[3,7.5]],"id":47703807}],"con":true,"img":false}]}
{"op":"mcm","clk":"11540952508","pt":1719500386193,"mc":[{"id":"1.230180123","rc":[{"atl":[[4.1,0.84]],"id":57697855}],"con":true,"img":false}]}
{"op":"mcm","clk":"11540952597","pt":1719500387180,"mc":[{"id":"1.230180123","rc":[{"atb":[[2.32,0]],"id":40028187},{"atb":[[2.6,6.13]],"id":43318163},{"atb":[[3.1,0]],"id":47703807}],"con":true,"img":false}]}
{"op":"mcm","clk":"11540952607","pt":1719500387280,"mc":[{"id":"1.230180123","rc":[{"atb":[[2.68,5.08]],"id":40028187},{"atb":[[2.72,4.5]],"id":43318163},{"atb":[[3.3,2.34]],"id":47703807},{"atb":[[1.95,2]],"id":70396461},{"atb":[[1.97,4.2]],"id":57697855}],"con":true,"img":false}]}
{"op":"mcm","clk":"11540952614","pt":1719500387382,"mc":[{"id":"1.230180123","rc":[{"atb":[[1.95,11.62]],"id":70396461}],"con":true,"img":false}]}
{"op":"mcm","clk":"11540952623","pt":1719500387486,"mc":[{"id":"1.230180123","rc":[{"atb":[[1.94,2]],"id":70396461}],"con":true,"img":false}]}
{"op":"mcm","clk":"11540952632","pt":1719500387593,"mc":[{"id":"1.230180123","rc":[{"atl":[[4.3,20.5],[4.2,10.56]],"id":67487132}],"con":true,"img":false}]}
{"op":"mcm","clk":"11540952688","pt":1719500388365,"mc":[{"id":"1.230180123","rc":[{"atb":[[1.94,0]],"id":70396461}],"con":true,"img":false}]}
{"op":"mcm","clk":"11540952693","pt":1719500388471,"mc":[{"id":"1.230180123","rc":[{"atb":[[1.96,2]],"id":70396461}],"con":true,"img":false}]}
{"op":"mcm","clk":"11540952714","pt":1719500388785,"mc":[{"id":"1.230180123","rc":[{"atb":[[2.06,26.54]],"id":67487132}],"con":true,"img":false}]}
{"op":"mcm","clk":"11540952769","pt":1719500389401,"mc":[{"id":"1.230180123","rc":[{"atb":[[1.68,0]],"id":57697855}],"con":true,"img":false}]}
{"op":"mcm","clk":"11540952801","pt":1719500389773,"mc":[{"id":"1.230180123","rc":[{"atb":[[2.66,12.62]],"id":40028187},{"atb":[[2.62,8.19]],"id":43318163},{"atl":[[4.1,15.79]],"id":67487132},{"atb":[[1.93,7.65]],"id":70396461}],"con":true,"img":false}]}
{"op":"mcm","clk":"11540952811","pt":1719500389870,"mc":[{"id":"1.230180123","rc":[{"atl":[[4,15.8],[4.3,0.84],[4.2,2.5]],"id":67487132},{"atl":[[3.5,9.62]],"id":70396461},{"atl":[[4.1,4.3]],"id":57697855}],"con":true,"img":false}]}
{"op":"mcm","clk":"11540952820","pt":1719500389978,"mc":[{"id":"1.230180123","rc":[{"atl":[[4,0],[4.2,33.75]],"id":67487132},{"atl":[[3.6,0],[3.45,7.44],[3.55,0.84]],"id":70396461},{"atl":[[4,4.31],[4.5,0],[4.6,5]],"id":57697855}],"con":true,"img":false}]}
{"op":"mcm","clk":"11540952827","pt":1719500390075,"mc":[{"id":"1.230180123","rc":[{"atl":[[4,0],[4.2,11.12]],"id":57697855}],"con":true,"img":false}]}
{"op":"mcm","clk":"11540952843","pt":1719500390289,"mc":[{"id":"1.230180123","rc":[{"atb":[[2.72,12.47]],"id":43318163},{"atl":[[4.3,0],[3.95,0.84]],"id":67487132},{"atl":[[3.45,8.28]],"id":70396461}],"con":true,"img":false}]}
{"op":"mcm","clk":"11540952851","pt":1719500390392,"mc":[{"id":"1.230180123","rc":[{"atb":[[2.6,0],[2.62,5]],"id":43318163}],"con":true,"img":false}]}
{"op":"mcm","clk":"11540952875","pt":1719500390704,"mc":[{"id":"1.230180123","rc":[{"atl":[[3.95,0]],"id":67487132},{"atl":[[3.55,0]],"id":70396461}],"con":true,"img":false}]}
{"op":"mcm","clk":"11540952890","pt":1719500390906,"mc":[{"id":"1.230180123","rc":[{"atl":[[4.6,30.28],[4.2,2.5]],"id":67487132}],"con":true,"img":false}]}
{"op":"mcm","clk":"11540952924","pt":1719500391272,"mc":[{"id":"1.230180123","rc":[{"atb":[[1.92,0],[1.98,2.11]],"id":70396461}],"con":true,"img":false}]}
{"op":"mcm","clk":"11540952984","pt":1719500391901,"mc":[{"id":"1.230180123","rc":[{"atb":[[3,2.5],[3.3,4.84]],"id":47703807},{"atl":[[8.6,1],[8.4,2]],"id":47703807},{"atl":[[5,5],[4.9,1]],"id":67487132},{"atl":[[5,10],[4.9,1]],"id":57697855}],"con":true,"img":false}]}
{"op":"mcm","clk":"11540952992","pt":1719500392006,"mc":[{"id":"1.230180123","rc":[{"atb":[[1.96,0]],"id":70396461},{"atl":[[4.2,2.5]],"id":57697855}],"con":true,"img":false}]}
{"op":"mcm","clk":"11540953002","pt":1719500392112,"mc":[{"id":"1.230180123","rc":[{"atb":[[1.99,2]],"id":70396461},{"atl":[[4.6,20.43]],"id":57697855}],"con":true,"img":false}]}
{"op":"mcm","clk":"11540953186","pt":1719500394406,"mc":[{"id":"1.230180123","rc":[{"atb":[[2.7,7.56]],"id":40028187},{"atb":[[3.3,9.8]],"id":47703807}],"con":true,"img":false}]}
{"op":"mcm","clk":"11540953193","pt":1719500394509,"mc":[{"id":"1.230180123","rc":[{"atb":[[2.66,5.56]],"id":40028187},{"atb":[[3.25,0]],"id":47703807}],"con":true,"img":false}]}
{"op":"mcm","clk":"11540953231","pt":1719500394880,"mc":[{"id":"1.230180123","rc":[{"atb":[[2.66,2.5]],"id":40028187}],"con":true,"img":false}]}
{"op":"mcm","clk":"11540953247","pt":1719500395080,"mc":[{"id":"1.230180123","rc":[{"atl":[[3.45,0.84],[3.6,17.91]],"id":70396461}],"con":true,"img":false}]}
{"op":"mcm","clk":"11540953265","pt":1719500395289,"mc":[{"id":"1.230180123","rc":[{"atb":[[3.1,6.25]],"id":47703807}],"con":true,"img":false}]}
{"op":"mcm","clk":"11540953280","pt":1719500395496,"mc":[{"id":"1.230180123","rc":[{"atb":[[3.1,0]],"id":47703807}],"con":true,"img":false}]}
{"op":"mcm","clk":"11540953294","pt":1719500395704,"mc":[{"id":"1.230180123","rc":[{"atb":[[2.68,3.08]],"id":40028187}],"con":true,"img":false}]}
{"op":"mcm","clk":"11540953300","pt":1719500395807,"mc":[{"id":"1.230180123","rc":[{"atb":[[2.72,2]],"id":40028187}],"con":true,"img":false}]}
{"op":"mcm","clk":"11540953334","pt":1719500396275,"mc":[{"id":"1.230180123","rc":[{"atb":[[1.87,0],[2.08,6.16]],"id":40028187},{"atb":[[2.04,10.78],[2.28,0]],"id":43318163},{"atb":[[2.06,7.8],[2.1,9.37]],"id":67487132}],"con":true,"img":false}]}
{"op":"mcm","clk":"11540953342","pt":1719500396380,"mc":[{"id":"1.230180123","rc":[{"atb":[[2.68,0]],"id":40028187},{"atb":[[2.72,9.97]],"id":43318163},{"atb":[[2.1,23.43]],"id":67487132},{"atb":[[1.95,9.62]],"id":70396461}],"con":true,"img":false}]}
{"op":"mcm","clk":"11540953354","pt":1719500396586,"mc":[{"id":"1.230180123","rc":[{"atb":[[2.72,5.09]],"id":40028187},{"atb":[[2.74,2.46]],"id":43318163},{"atb":[[2.08,4.11]],"id":67487132},{"atb":[[1.99,5.07]],"id":70396461}],"con":true,"img":false}]}
{"op":"mcm","clk":"11540953377","pt":1719500396897,"mc":[{"id":"1.230180123","rc":[{"atb":[[2.06,2.5]],"id":67487132},{"atb":[[1.71,0],[1.79,0],[1.75,0]],"id":57697855}],"con":true,"img":false}]}
{"op":"mcm","clk":"11540953398","pt":1719500397102,"mc":[{"id":"1.230180123","rc":[{"atb":[[3.2,22.1],[3.3,7.3]],"id":47703807}],"con":true,"img":false}]}
{"op":"mcm","clk":"11540953407","pt":1719500397212,"mc":[{"id":"1.230180123","rc":[{"atb":[[3.2,2.49],[3,31.9]],"id":47703807},{"atb":[[2.08,2.11]],"id":67487132}],"con":true,"img":false}]}
{"op":"mcm","clk":"11540953420","pt":1719500397311,"mc":[{"id":"1.230180123","rc":[{"atb":[[3.2,17.09]],"id":47703807},{"atb":[[2.12,2]],"id":67487132},{"atb":[[1.9,2.5]],"id":57697855}],"con":true,"img":false}]}
{"op":"mcm","clk":"11540953431","pt":1719500397414,"mc":[{"id":"1.230180123","rc":[{"atb":[[3,2.5]],"id":47703807}],"con":true,"img":false}]}
{"op":"mcm","clk":"11540953453","pt":1719500397578,"mc":[{"id":"1.230180123","rc":[{"atb":[[2.72,7.97]],"id":43318163}],"con":true,"img":false}]}
{"op":"mcm","clk":"11540953464","pt":1719500397678,"mc":[{"id":"1.230180123","rc":[{"atb":[[2.76,2]],"id":43318163}],"con":true,"img":false}]}
{"op":"mcm","clk":"11540953537","pt":1719500398508,"mc":[{"id":"1.230180123","rc":[{"atb":[[2,5.25]],"id":57697855}],"con":true,"img":false}]}
{"op":"mcm","clk":"11540953589","pt":1719500398980,"mc":[{"id":"1.230180123","rc":[{"atb":[[2.08,5.36]],"id":67487132}],"con":true,"img":false}]}
{"op":"mcm","clk":"11540953604","pt":1719500399201,"mc":[{"id":"1.230180123","rc":[{"atb":[[1.99,16.09]],"id":70396461}],"con":true,"img":false}]}
{"op":"mcm","clk":"11540953618","pt":1719500399391,"mc":[{"id":"1.230180123","rc":[{"atb":[[1.95,0]],"id":70396461}],"con":true,"img":false}]}
{"op":"mcm","clk":"11540953652","pt":1719500399819,"mc":[{"id":"1.230180123","rc":[{"atl":[[4.5,4.2]],"id":57697855}],"con":true,"img":false}]}
{"op":"mcm","clk":"11540953661","pt":1719500399913,"mc":[{"id":"1.230180123","rc":[{"atb":[[1.93,2.5]],"id":70396461},{"atl":[[4.6,5],[4.4,6.81]],"id":57697855}],"con":true,"img":false}]}
{"op":"mcm","clk":"11540953715","pt":1719500400415,"mc":[{"id":"1.230180123","rc":[{"atl":[[4.5,0]],"id":57697855}],"con":true,"img":false}]}
{"op":"mcm","clk":"11540953736","pt":1719500400624,"mc":[{"id":"1.230180123","rc":[{"atb":[[1.65,0]],"id":57697855}],"con":true,"img":false}]}
{"op":"mcm","clk":"11540953834","pt":1719500401529,"mc":[{"id":"1.230180123","rc":[{"atb":[[2.1,14.06],[2.08,30.79]],"id":67487132},{"atl":[[4,15.88]],"id":67487132},{"atb":[[1.93,6.32],[1.88,0]],"id":57697855}],"con":true,"img":false}]}
{"op":"mcm","clk":"11540953844","pt":1719500401591,"mc":[{"id":"1.230180123","rc":[{"atl":[[3.95,15.8]],"id":67487132},{"atb":[[2,0]],"id":57697855}],"con":true,"img":false}]}
{"op":"mcm","clk":"11540953856","pt":1719500401691,"mc":[{"id":"1.230180123","rc":[{"atb":[[2.04,0],[2.26,5]],"id":43318163},{"atl":[[4.6,2.5],[4.1,0.84]],"id":67487132},{"atl":[[3.4,9.09]],"id":70396461}],"con":true,"img":false}]}
{"op":"mcm","clk":"11540953865","pt":1719500401814,"mc":[{"id":"1.230180123","rc":[{"atl":[[3.6,0]],"id":70396461}],"con":true,"img":false}]}
{"op":"mcm","clk":"11540953892","pt":1719500402014,"mc":[{"id":"1.230180123","rc":[{"atb":[[2.76,8.47]],"id":43318163}],"con":true,"img":false}]}
{"op":"mcm","clk":"11540953921","pt":1719500402231,"mc":[{"id":"1.230180123","rc":[{"atb":[[2.72,0]],"id":43318163}],"con":true,"img":false}]}
{"op":"mcm","clk":"11540953932","pt":1719500402290,"mc":[{"id":"1.230180123","rc":[{"atl":[[4.1,0],[3.9,0.84]],"id":67487132},{"atl":[[3.35,0.84]],"id":70396461}],"con":true,"img":false}]}
{"op":"mcm","clk":"11540953976","pt":1719500402712,"mc":[{"id":"1.230180123","rc":[{"atb":[[3.2,2.49],[3.3,14.6]],"id":47703807}],"con":true,"img":false}]}
{"op":"mcm","clk":"11540954014","pt":1719500403028,"mc":[{"id":"1.230180123","rc":[{"atl":[[4.1,3.48]],"id":67487132}],"con":true,"img":false}]}
{"op":"mcm","clk":"11540954028","pt":1719500403135,"mc":[{"id":"1.230180123","rc":[{"atb":[[2.08,27.54]],"id":67487132}],"con":true,"img":false}]}
{"op":"mcm","clk":"11540954044","pt":1719500403192,"mc":[{"id":"1.230180123","rc":[{"atl":[[4.1,0]],"id":67487132}],"con":true,"img":false}]}
{"op":"mcm","clk":"11540954090","pt":1719500403608,"mc":[{"id":"1.230180123","rc":[{"atb":[[2.16,2.11],[2.08,25.43]],"id":67487132}],"con":true,"img":false}]}
{"op":"mcm","clk":"11540954251","pt":1719500405098,"mc":[{"id":"1.230180123","rc":[{"atb":[[1.03,17.29],[2.28,2.11]],"id":40028187},{"atl":[[5.7,4.4]],"id":40028187},{"atb":[[1.01,51.88],[2.46,2.11]],"id":43318163},{"atl":[[5.7,6.12]],"id":43318163},{"atb":[[1.01,51.88]],"id":47703807},{"atl":[[7.8,6.46]],"id":47703807},{"atb":[[1.01,51.88],[2.12,0],[2.16,2.11]],"id":67487132},{"atl":[[3.9,0.84]],"id":67487132},{"atb":[[1.98,2.11],[1.02,25.94]],"id":70396461},{"atl":[[3.45,0.84],[3.35,0.84]],"id":70396461},{"atb":[[1.01,51.88],[2.34,2.11]],"id":57697855},{"atl":[[4.1,4.3]],"id":57697855}],"con":true,"img":false}]}
{"op":"mcm","clk":"11540954259","pt":1719500405212,"mc":[{"id":"1.230180123","rc":[{"atb":[[2.18,2]],"id":67487132}],"con":true,"img":false}]}
{"op":"mcm","clk":"11540954282","pt":1719500405413,"mc":[{"id":"1.230180123","rc":[{"atb":[[2.74,0]],"id":43318163},{"atb":[[1.99,13.02]],"id":70396461}],"con":true,"img":false}]}
{"op":"mcm","clk":"11540954311","pt":1719500405628,"mc":[{"id":"1.230180123","rc":[{"atb":[[2.78,2.82]],"id":43318163},{"atb":[[2,3]],"id":70396461}],"con":true,"img":false}]}
{"op":"mcm","clk":"11540954354","pt":1719500405995,"mc":[{"id":"1.230180123","rc":[{"atb":[[2.72,12.21]],"id":40028187}],"con":true,"img":false}]}
{"op":"mcm","clk":"11540954363","pt":1719500406098,"mc":[{"id":"1.230180123","rc":[{"atb":[[2.7,0]],"id":40028187}],"con":true,"img":false}]}
{"op":"mcm","clk":"11540954393","pt":1719500406410,"mc":[{"id":"1.230180123","rc":[{"atl":[[3.65,0]],"id":70396461}],"con":true,"img":false}]}
{"op":"mcm","clk":"11540954411","pt":1719500406628,"mc":[{"id":"1.230180123","rc":[{"atb":[[2.76,6.47]],"id":43318163}],"con":true,"img":false}]}
{"op":"mcm","clk":"11540954425","pt":1719500406722,"mc":[{"id":"1.230180123","rc":[{"atb":[[2.8,2]],"id":43318163},{"atl":[[4,32.53],[3.95,0]],"id":67487132},{"atl":[[3.65,2.3]],"id":70396461}],"con":true,"img":false}]}
{"op":"mcm","clk":"11540954452","pt":1719500407039,"mc":[{"id":"1.230180123","rc":[{"atb":[[1.99,11.02]],"id":70396461}],"con":true,"img":false}]}
{"op":"mcm","clk":"11540954461","pt":1719500407086,"mc":[{"id":"1.230180123","rc":[{"atb":[[2.02,2]],"id":70396461}],"con":true,"img":false}]}
{"op":"mcm","clk":"11540954475","pt":1719500407195,"mc":[{"id":"1.230180123","rc":[{"atl":[[3.9,0]],"id":67487132}],"con":true,"img":false}]}
{"op":"mcm","clk":"11540954487","pt":1719500407301,"mc":[{"id":"1.230180123","rc":[{"atl":[[4,15.88],[4.6,30.28]],"id":67487132}],"con":true,"img":false}]}
{"op":"mcm","clk":"11540954551","pt":1719500408025,"mc":[{"id":"1.230180123","rc":[{"atb":[[2.18,14.42]],"id":67487132}],"con":true,"img":false}]}
{"op":"mcm","clk":"11540954563","pt":1719500408138,"mc":[{"id":"1.230180123","rc":[{"atb":[[2.1,0]],"id":67487132}],"con":true,"img":false}]}
{"op":"mcm","clk":"11540954706","pt":1719500409703,"mc":[{"id":"1.230180123","rc":[{"atl":[[3.95,0.84]],"id":67487132}],"con":true,"img":false}]}
{"op":"mcm","clk":"11540954716","pt":1719500409808,"mc":[{"id":"1.230180123","rc":[{"atl":[[4.6,2.5],[4.2,19.23]],"id":67487132}],"con":true,"img":false}]}
{"op":"mcm","clk":"11540954774","pt":1719500410422,"mc":[{"id":"1.230180123","rc":[{"atl":[[5.7,6.39]],"id":40028187}],"con":true,"img":false}]}
{"op":"mcm","clk":"11540954791","pt":1719500410638,"mc":[{"id":"1.230180123","rc":[{"atl":[[6.4,6],[5.7,12.79]],"id":40028187}],"con":true,"img":false}]}
{"op":"mcm","clk":"11540954805","pt":1719500410694,"mc":[{"id":"1.230180123","rc":[{"atb":[[2.02,5.75]],"id":70396461}],"con":true,"img":false}]}
{"op":"mcm","clk":"11540954814","pt":1719500410796,"mc":[{"id":"1.230180123","rc":[{"atb":[[1.99,0]],"id":70396461}],"con":true,"img":false}]}
{"op":"mcm","clk":"11540954845","pt":1719500411107,"mc":[{"id":"1.230180123","rc":[{"atl":[[5.6,1.98]],"id":40028187},{"atl":[[5.6,1.98]],"id":43318163},{"atl":[[7.6,2.04]],"id":47703807},{"atl":[[3.95,3.03]],"id":67487132},{"atl":[[3.35,3.95]],"id":70396461},{"atl":[[4,2.11]],"id":57697855}],"con":true,"img":false}]}
{"op":"mcm","clk":"11540954866","pt":1719500411318,"mc":[{"id":"1.230180123","rc":[{"atl":[[5.5,5.62]],"id":40028187},{"atl":[[5.6,4.48],[6.4,1],[5.5,3.99]],"id":43318163},{"atl":[[7.4,3.75],[7.8,10.54],[8.4,0]],"id":47703807},{"atb":[[2.16,7]],"id":67487132},{"atl":[[3.5,0],[3.3,3.96]],"id":70396461},{"atl":[[4,4.61],[3.95,3.46],[4.4,0]],"id":57697855}],"con":true,"img":false}]}
{"op":"mcm","clk":"11540954880","pt":1719500411428,"mc":[{"id":"1.230180123","rc":[{"atl":[[5.4,2.15]],"id":40028187},{"atl":[[7.2,2.31]],"id":47703807},{"atl":[[3.25,3.11]],"id":70396461},{"atl":[[3.9,2.25]],"id":57697855}],"con":true,"img":false}]}
{"op":"mcm","clk":"11540954891","pt":1719500411527,"mc":[{"id":"1.230180123","rc":[{"atl":[[5.7,9.23]],"id":40028187},{"atl":[[5.7,0.84]],"id":43318163},{"atl":[[7.8,4.92]],"id":47703807},{"atl":[[4.1,0.84]],"id":57697855}],"con":true,"img":false}]}
{"op":"mcm","clk":"11540954906","pt":1719500411648,"mc":[{"id":"1.230180123","rc":[{"atl":[[4,2.11],[3.9,5.71]],"id":57697855}],"con":true,"img":false}]}
{"op":"mcm","clk":"11540954913","pt":1719500411696,"mc":[{"id":"1.230180123","rc":[{"atl":[[5.3,0.84],[5.7,8.39]],"id":40028187},{"atl":[[5.7,0],[5.4,0.84]],"id":43318163},{"atl":[[7.8,4.08],[7,0.84]],"id":47703807},{"atl":[[3.45,0],[3.2,0.84],[3.35,3.11]],"id":70396461},{"atl":[[3.85,0.84],[4.1,0]],"id":57697855}],"con":true,"img":false}]}
{"op":"mcm","clk":"11540954954","pt":1719500412111,"mc":[{"id":"1.230180123","rc":[{"atb":[[2.24,10],[2.08,0]],"id":40028187},{"atb":[[2.26,0],[2.1,7.82]],"id":43318163},{"atb":[[2.16,2.11],[2.1,21.43],[2.08,0]],"id":67487132}],"con":true,"img":false}]}
{"op":"mcm","clk":"11540954982","pt":1719500412316,"mc":[{"id":"1.230180123","rc":[{"atb":[[2.7,3]],"id":40028187},{"atb":[[1.97,5.15]],"id":70396461}],"con":true,"img":false}]}
{"op":"mcm","clk":"11540955002","pt":1719500412525,"mc":[{"id":"1.230180123","rc":[{"atb":[[1.97,0]],"id":70396461}],"con":true,"img":false}]}
{"op":"mcm","clk":"11540955061","pt":1719500413206,"mc":[{"id":"1.230180123","rc":[{"atl":[[3.9,22.72]],"id":67487132},{"atl":[[3.2,5.42]],"id":70396461}],"con":true,"img":false}]}
{"op":"mcm","clk":"11540955071","pt":1719500413313,"mc":[{"id":"1.230180123","rc":[{"atl":[[4,0]],"id":67487132},{"atl":[[3.4,0]],"id":70396461}],"con":true,"img":false}]}
{"op":"mcm","clk":"11540955097","pt":1719500413516,"mc":[{"id":"1.230180123","rc":[{"atb":[[2.8,7.11]],"id":43318163}],"con":true,"img":false}]}
{"op":"mcm","clk":"11540955117","pt":1719500413729,"mc":[{"id":"1.230180123","rc":[{"atl":[[5.7,6.4]],"id":40028187},{"atb":[[2.76,0]],"id":43318163}],"con":true,"img":false}]}
{"op":"mcm","clk":"11540955145","pt":1719500413993,"mc":[{"id":"1.230180123","rc":[{"atl":[[5.6,3.97]],"id":40028187}],"con":true,"img":false}]}
{"op":"mcm","clk":"11540955155","pt":1719500414104,"mc":[{"id":"1.230180123","rc":[{"atb":[[2.72,9.12]],"id":40028187},{"atb":[[2.78,0]],"id":43318163},{"atb":[[2,0]],"id":70396461}],"con":true,"img":false}]}
{"op":"mcm","clk":"11540955173","pt":1719500414306,"mc":[{"id":"1.230180123","rc":[{"atb":[[2.74,3.3]],"id":40028187},{"atb":[[2.82,2]],"id":43318163},{"atl":[[5.6,2.5]],"id":43318163},{"atb":[[2.04,3]],"id":70396461}],"con":true,"img":false}]}
{"op":"mcm","clk":"11540955239","pt":1719500415137,"mc":[{"id":"1.230180123","rc":[{"atl":[[3.9,41.95],[4.2,2.5]],"id":67487132}],"con":true,"img":false}]}
{"op":"mcm","clk":"11540955283","pt":1719500415863,"mc":[{"id":"1.230180123","rc":[{"atb":[[2.8,5.11]],"id":43318163}],"con":true,"img":false}]}
{"op":"mcm","clk":"11540955292","pt":1719500415928,"mc":[{"id":"1.230180123","rc":[{"atb":[[2.84,2]],"id":43318163},{"atb":[[2.24,2.11],[2.16,0]],"id":67487132}],"con":true,"img":false}]}
{"op":"mcm","clk":"11540955301","pt":1719500415988,"mc":[{"id":"1.230180123","rc":[{"atl":[[5.7,0],[5.4,6.12]],"id":40028187}],"con":true,"img":false}]}
{"op":"mcm","clk":"11540955326","pt":1719500416318,"mc":[{"id":"1.230180123","rc":[{"atb":[[2.72,7.12]],"id":40028187}],"con":true,"img":false}]}
{"op":"mcm","clk":"11540955335","pt":1719500416331,"mc":[{"id":"1.230180123","rc":[{"atb":[[2.76,2]],"id":40028187}],"con":true,"img":false}]}
{"op":"mcm","clk":"11540955362","pt":1719500416535,"mc":[{"id":"1.230180123","rc":[{"atb":[[2.7,0]],"id":40028187},{"atl":[[5.6,0],[5.8,5]],"id":43318163},{"atl":[[8,7.12],[7.8,0]],"id":47703807}],"con":true,"img":false}]}
{"op":"mcm","clk":"11540955376","pt":1719500416639,"mc":[{"id":"1.230180123","rc":[{"atl":[[3.2,9.38],[3.3,0]],"id":70396461}],"con":true,"img":false}]}
{"op":"mcm","clk":"11540955386","pt":1719500416746,"mc":[{"id":"1.230180123","rc":[{"atb":[[2.02,3.75]],"id":70396461}],"con":true,"img":false}]}
{"op":"mcm","clk":"11540955397","pt":1719500416802,"mc":[{"id":"1.230180123","rc":[{"atb":[[2.06,2]],"id":70396461}],"con":true,"img":false}]}
{"op":"mcm","clk":"11540955415","pt":1719500417006,"mc":[{"id":"1.230180123","rc":[{"atb":[[2.5,0],[2.58,0],[2.66,0]],"id":40028187},{"atl":[[5.8,0],[6.2,6.49]],"id":43318163}],"con":true,"img":false}]}
{"op":"mcm","clk":"11540955424","pt":1719500417111,"mc":[{"id":"1.230180123","rc":[{"atb":[[2.34,2.5]],"id":40028187}],"con":true,"img":false}]}
{"op":"mcm","clk":"11540955431","pt":1719500417215,"mc":[{"id":"1.230180123","rc":[{"atl":[[3.85,0.84]],"id":67487132}],"con":true,"img":false}]}
{"op":"mcm","clk":"11540955512","pt":1719500418105,"mc":[{"id":"1.230180123","rc":[{"atb":[[2.18,12.42]],"id":67487132}],"con":true,"img":false}]}
{"op":"mcm","clk":"11540955526","pt":1719500418207,"mc":[{"id":"1.230180123","rc":[{"atb":[[2.26,2]],"id":67487132}],"con":true,"img":false}]}
{"op":"mcm","clk":"11540955618","pt":1719500419406,"mc":[{"id":"1.230180123","rc":[{"atb":[[2.26,5.87]],"id":67487132}],"con":true,"img":false}]}
{"op":"mcm","clk":"11540955636","pt":1719500419615,"mc":[{"id":"1.230180123","rc":[{"atb":[[2.18,0]],"id":67487132}],"con":true,"img":false}]}
{"op":"mcm","clk":"11540955731","pt":1719500420608,"mc":[{"id":"1.230180123","rc":[{"atb":[[1.92,5.36]],"id":57697855}],"con":true,"img":false}]}
{"op":"mcm","clk":"11540955853","pt":1719500422007,"mc":[{"id":"1.230180123","rc":[{"atb":[[2.06,6.66]],"id":70396461}],"con":true,"img":false}]}
{"op":"mcm","clk":"11540955861","pt":1719500422112,"mc":[{"id":"1.230180123","rc":[{"atb":[[2.02,0]],"id":70396461}],"con":true,"img":false}]}
{"op":"mcm","clk":"11540955887","pt":1719500422318,"mc":[{"id":"1.230180123","rc":[{"atb":[[2.24,0],[2.34,9.1]],"id":40028187},{"atb":[[3.25,29.2],[3.3,7.3]],"id":47703807},{"atl":[[8,2.5],[8.6,0],[7.8,5]],"id":47703807},{"atl":[[4.9,0],[4.7,1]],"id":67487132},{"atl":[[4.9,0]],"id":57697855}],"con":true,"img":false}]}
{"op":"mcm","clk":"11540955895","pt":1719500422446,"mc":[{"id":"1.230180123","rc":[{"atb":[[3.2,39],[3.25,0]],"id":47703807}],"con":true,"img":false}]}
{"op":"mcm","clk":"11540955902","pt":1719500422508,"mc":[{"id":"1.230180123","rc":[{"atb":[[3.2,2.5],[3.25,14.6]],"id":47703807}],"con":true,"img":false}]}
{"op":"mcm","clk":"11540955913","pt":1719500422600,"mc":[{"id":"1.230180123","rc":[{"atl":[[5.3,7.53]],"id":40028187},{"atl":[[7,5.53]],"id":47703807},{"atl":[[3.85,5.03]],"id":57697855}],"con":true,"img":false}]}
{"op":"mcm","clk":"11540955918","pt":1719500422706,"mc":[{"id":"1.230180123","rc":[{"atl":[[5.2,6.12],[5.4,2.15]],"id":40028187},{"atb":[[2.82,0]],"id":43318163},{"atb":[[2.04,0]],"id":70396461},{"atl":[[3.8,5.04]],"id":57697855}],"con":true,"img":false}]}
{"op":"mcm","clk":"11540955930","pt":1719500422810,"mc":[{"id":"1.230180123","rc":[{"atl":[[5.5,0]],"id":40028187},{"atb":[[2.84,4.38]],"id":43318163},{"atl":[[7.4,0]],"id":47703807},{"atb":[[2.08,3.1]],"id":70396461},{"atl":[[3.95,0],[3.9,2.25]],"id":57697855}],"con":true,"img":false}]}
{"op":"mcm","clk":"11540955943","pt":1719500423019,"mc":[{"id":"1.230180123","rc":[{"atl":[[5.6,1.98]],"id":40028187}],"con":true,"img":false}]}
{"op":"mcm","clk":"11540955975","pt":1719500423336,"mc":[{"id":"1.230180123","rc":[{"atl":[[5.1,0.84]],"id":40028187},{"atl":[[3.75,0.84]],"id":57697855}],"con":true,"img":false}]}
{"op":"mcm","clk":"11540956023","pt":1719500423805,"mc":[{"id":"1.230180123","rc":[{"atb":[[2.06,4.66]],"id":70396461}],"con":true,"img":false}]}
{"op":"mcm","clk":"11540956031","pt":1719500423910,"mc":[{"id":"1.230180123","rc":[{"atb":[[2.1,2]],"id":70396461}],"con":true,"img":false}]}
{"op":"mcm","clk":"11540956054","pt":1719500424426,"mc":[{"id":"1.230180123","rc":[{"atl":[[3.8,6.68]],"id":67487132}],"con":true,"img":false}]}
{"op":"mcm","clk":"11540956067","pt":1719500424632,"mc":[{"id":"1.230180123","rc":[{"atl":[[3.9,19.23],[3.75,0.84]],"id":67487132}],"con":true,"img":false}]}
{"op":"mcm","clk":"11540956073","pt":1719500424737,"mc":[{"id":"1.230180123","rc":[{"atl":[[8.8,6]],"id":47703807},{"atl":[[3.95,2.19]],"id":67487132}],"con":true,"img":false}]}
{"op":"mcm","clk":"11540956077","pt":1719500424839,"mc":[{"id":"1.230180123","rc":[{"atb":[[2.84,9.25]],"id":43318163}],"con":true,"img":false}]}
{"op":"mcm","clk":"11540956087","pt":1719500425044,"mc":[{"id":"1.230180123","rc":[{"atb":[[2.8,0]],"id":43318163}],"con":true,"img":false}]}
{"op":"mcm","clk":"11540956126","pt":1719500425619,"mc":[{"id":"1.230180123","rc":[{"atb":[[2.2,6.6],[2.34,2.5]],"id":40028187},{"atl":[[6.4,5]],"id":40028187},{"atb":[[2.56,10],[2.1,0]],"id":43318163},{"atl":[[6.4,0],[5.4,5.71]],"id":43318163},{"atb":[[3.25,0],[3.05,14.6]],"id":47703807},{"atl":[[7.4,7.85],[7.8,0]],"id":47703807},{"atb":[[2.1,0],[2.14,7.99]],"id":67487132},{"atb":[[1.85,10],[1.79,6.2],[2.06,0]],"id":70396461},{"atb":[[1.93,0],[2.24,4.24],[1.92,0]],"id":57697855}],"con":true,"img":false}]}
{"op":"mcm","clk":"11540956135","pt":1719500425721,"mc":[{"id":"1.230180123","rc":[{"atl":[[5.1,3.28]],"id":40028187},{"atb":[[2.38,14.25]],"id":43318163},{"atl":[[6.2,0],[5.5,0],[5.3,3.99]],"id":43318163},{"atl":[[6.8,2.62]],"id":47703807},{"atl":[[3.75,3.3]],"id":67487132},{"atb":[[1.68,6.2],[1.79,0]],"id":70396461},{"atl":[[3.15,2.68]],"id":70396461},{"atb":[[2.24,0]],"id":57697855},{"atl":[[3.75,3.3]],"id":57697855}],"con":true,"img":false}]}
{"op":"mcm","clk":"11540956142","pt":1719500425825,"mc":[{"id":"1.230180123","rc":[{"atb":[[2.56,0]],"id":43318163},{"atb":[[2.04,8.37],[2.14,0]],"id":67487132},{"atl":[[3.7,3.31],[3.9,0]],"id":67487132},{"atl":[[3.1,4.34]],"id":70396461},{"atb":[[2.12,6.36]],"id":57697855}],"con":true,"img":false}]}
{"op":"mcm","clk":"11540956146","pt":1719500425929,"mc":[{"id":"1.230180123","rc":[{"atl":[[5.3,0],[5.5,9.71]],"id":43318163},{"atl":[[3.2,4.8]],"id":70396461}],"con":true,"img":false}]}
{"op":"mcm","clk":"11540956158","pt":1719500426136,"mc":[{"id":"1.230180123","rc":[{"atl":[[3.45,1.84]],"id":67487132}],"con":true,"img":false}]}
{"op":"mcm","clk":"11540956165","pt":1719500426244,"mc":[{"id":"1.230180123","rc":[{"atb":[[3.3,16]],"id":47703807},{"atl":[[6.8,6.14]],"id":47703807}],"con":true,"img":false}]}
{"op":"mcm","clk":"11540956175","pt":1719500426349,"mc":[{"id":"1.230180123","rc":[{"atl":[[5.3,6.69]],"id":40028187},{"atl":[[6.6,0.84]],"id":47703807},{"atl":[[3.85,0]],"id":67487132},{"atl":[[3.2,3.96],[3.05,0.84]],"id":70396461},{"atl":[[3.85,4.19]],"id":57697855}],"con":true,"img":false}]}
{"op":"mcm","clk":"11540956183","pt":1719500426457,"mc":[{"id":"1.230180123","rc":[{"atl":[[3.1,8.3]],"id":70396461}],"con":true,"img":false}]}
{"op":"mcm","clk":"11540956192","pt":1719500426551,"mc":[{"id":"1.230180123","rc":[{"atl":[[7,1]],"id":43318163},{"atl":[[3.2,0]],"id":70396461}],"con":true,"img":false}]}
{"op":"mcm","clk":"11540956206","pt":1719500426708,"mc":[{"id":"1.230180123","rc":[{"atb":[[2.78,10],[3.05,0]],"id":47703807},{"atl":[[7.4,0],[6.8,11.68]],"id":47703807},{"atl":[[3.75,2.46]],"id":67487132}],"con":true,"img":false}]}
{"op":"mcm","clk":"11540956214","pt":1719500426812,"mc":[{"id":"1.230180123","rc":[{"atb":[[2.76,9.06]],"id":40028187},{"atb":[[2.78,0],[2.96,17.1]],"id":47703807},{"atl":[[6.8,6.14],[7,12.52]],"id":47703807}],"con":true,"img":false}]}
{"op":"mcm","clk":"11540956220","pt":1719500426918,"mc":[{"id":"1.230180123","rc":[{"atb":[[2.72,0]],"id":40028187}],"con":true,"img":false}]}
{"op":"mcm","clk":"11540956275","pt":1719500427537,"mc":[{"id":"1.230180123","rc":[{"atb":[[2.38,12.36],[2.2,0],[2.76,2]],"id":40028187},{"atb":[[2.38,0],[1.96,14.25]],"id":43318163},{"atl":[[5.5,0]],"id":43318163},{"atb":[[2.72,10],[2.96,0]],"id":47703807},{"atl":[[7.6,10.49],[7,5.53]],"id":47703807},{"atb":[[1.68,0],[2.1,5.6],[1.79,5.6]],"id":70396461},{"atl":[[3.65,0]],"id":70396461},{"atb":[[2.12,0]],"id":57697855}],"con":true,"img":false}]}
{"op":"mcm","clk":"11540956286","pt":1719500427640,"mc":[{"id":"1.230180123","rc":[{"atl":[[6,17.93]],"id":43318163},{"atb":[[1.93,6.32]],"id":57697855}],"con":true,"img":false}]}
{"op":"mcm","clk":"11540956300","pt":1719500427846,"mc":[{"id":"1.230180123","rc":[{"atl":[[5,6.12]],"id":40028187},{"atl":[[3.7,4.19],[3.8,0]],"id":57697855}],"con":true,"img":false}]}
{"op":"mcm","clk":"11540956303","pt":1719500427956,"mc":[{"id":"1.230180123","rc":[{"atl":[[5.2,0]],"id":40028187},{"atb":[[2.24,0]],"id":67487132}],"con":true,"img":false}]}
{"op":"mcm","clk":"11540956311","pt":1719500428054,"mc":[{"id":"1.230180123","rc":[{"atb":[[2.12,2.11]],"id":67487132}],"con":true,"img":false}]}
{"op":"mcm","clk":"11540956473","pt":1719500430234,"mc":[{"id":"1.230180123","rc":[{"atl":[[4.9,0.84]],"id":40028187},{"spn":3.83,"spf":"NaN","id":40028187},{"spn":4.12,"spf":"NaN","id":43318163},{"spn":4.95,"spf":"NaN","id":47703807},{"spn":2.85,"spf":"NaN","id":67487132},{"spn":2.57,"spf":"NaN","id":70396461},{"atl":[[3.65,0.84]],"id":57697855},{"spn":2.1,"spf":1.0,"id":57697855}],"con":true,"img":false}]}
{"op":"mcm","clk":"11540956527","pt":1719500430953,"mc":[{"id":"1.230180123","rc":[{"atb":[[2.08,7.99]],"id":67487132},{"atl":[[3.45,4.3],[3.7,0]],"id":67487132}],"con":true,"img":false}]}
{"op":"mcm","clk":"11540956535","pt":1719500431055,"mc":[{"id":"1.230180123","rc":[{"atl":[[6,2.5],[6.8,22.24]],"id":43318163},{"atb":[[2.04,0]],"id":67487132}],"con":true,"img":false}]}
{"op":"mcm","clk":"11540956563","pt":1719500431421,"mc":[{"id":"1.230180123","rc":[{"atb":[[2.84,6.87]],"id":43318163},{"atb":[[2.08,0]],"id":70396461}],"con":true,"img":false}]}
{"op":"mcm","clk":"11540956578","pt":1719500431629,"mc":[{"id":"1.230180123","rc":[{"atb":[[2.86,2.81]],"id":43318163},{"atb":[[2.12,3]],"id":70396461}],"con":true,"img":false}]}
{"op":"mcm","clk":"11540956587","pt":1719500431740,"mc":[{"id":"1.230180123","rc":[{"atl":[[3.4,0.84]],"id":67487132}],"con":true,"img":false}]}
{"op":"mcm","clk":"11540956606","pt":1719500432043,"mc":[{"id":"1.230180123","rc":[{"atb":[[2.84,4.87]],"id":43318163}],"con":true,"img":false}]}
{"op":"mcm","clk":"11540956618","pt":1719500432148,"mc":[{"id":"1.230180123","rc":[{"atb":[[2.88,2]],"id":43318163}],"con":true,"img":false}]}
{"op":"mcm","clk":"11540956642","pt":1719500432466,"mc":[{"id":"1.230180123","rc":[{"atb":[[2.1,3.6]],"id":70396461}],"con":true,"img":false}]}
{"op":"mcm","clk":"11540956652","pt":1719500432515,"mc":[{"id":"1.230180123","rc":[{"atb":[[2.14,2]],"id":70396461}],"con":true,"img":false}]}
{"op":"mcm","clk":"11540956658","pt":1719500432628,"mc":[{"id":"1.230180123","rc":[{"atb":[[1.96,0],[2.26,5.62]],"id":43318163},{"atb":[[2.72,0],[3.1,18.5]],"id":47703807}],"con":true,"img":false}]}
{"op":"mcm","clk":"11540956676","pt":1719500432826,"mc":[{"id":"1.230180123","rc":[{"atb":[[2.22,4.62]],"id":67487132}],"con":true,"img":false}]}
{"op":"mcm","clk":"11540956747","pt":1719500433762,"mc":[{"id":"1.230180123","rc":[{"atl":[[4.9,5.78]],"id":40028187},{"atl":[[6.6,9.6]],"id":47703807},{"atl":[[3.65,4.91]],"id":57697855}],"con":true,"img":false}]}
{"op":"mcm","clk":"11540956756","pt":1719500433865,"mc":[{"id":"1.230180123","rc":[{"atl":[[5.3,0]],"id":40028187},{"atl":[[7,0.84]],"id":47703807},{"atl":[[3.85,0]],"id":57697855}],"con":true,"img":false}]}
{"op":"mcm","clk":"11540956774","pt":1719500434121,"mc":[{"id":"1.230180123","rc":[{"atl":[[5.1,2.44]],"id":40028187},{"atl":[[7,0]],"id":47703807},{"atl":[[3.75,2.46]],"id":57697855}],"con":true,"img":false}]}
{"op":"mcm","clk":"11540956782","pt":1719500434328,"mc":[{"id":"1.230180123","rc":[{"atb":[[2.54,0],[2.62,0],[2.94,5],[3.05,2.5],[2.86,12.81],[2.7,0]],"id":43318163},{"atl":[[6.8,2.62]],"id":47703807}],"con":true,"img":false}]}
{"op":"mcm","clk":"11540956807","pt":1719500434745,"mc":[{"id":"1.230180123","rc":[{"atb":[[2.1,8.24]],"id":70396461}],"con":true,"img":false}]}
{"op":"mcm","clk":"11540956816","pt":1719500434951,"mc":[{"id":"1.230180123","rc":[{"atb":[[2.88,0]],"id":43318163}],"con":true,"img":false}]}
{"op":"mcm","clk":"11540956824","pt":1719500435047,"mc":[{"id":"1.230180123","rc":[{"atb":[[3.1,2]],"id":43318163},{"atl":[[6.6,13.98]],"id":47703807}],"con":true,"img":false}]}
{"op":"mcm","clk":"11540956850","pt":1719500435461,"mc":[{"id":"1.230180123","rc":[{"atl":[[3.4,5.91]],"id":67487132}],"con":true,"img":false}]}
{"op":"mcm","clk":"11540956858","pt":1719500435564,"mc":[{"id":"1.230180123","rc":[{"atl":[[3.8,0]],"id":67487132}],"con":true,"img":false}]}
{"op":"mcm","clk":"11540956883","pt":1719500435825,"mc":[{"id":"1.230180123","rc":[{"atb":[[3.1,7.62]],"id":43318163}],"con":true,"img":false}]}
{"op":"mcm","clk":"11540956889","pt":1719500435935,"mc":[{"id":"1.230180123","rc":[{"atb":[[3.1,19.63]],"id":43318163}],"con":true,"img":false}]}
{"op":"mcm","clk":"11540956897","pt":1719500436032,"mc":[{"id":"1.230180123","rc":[{"atb":[[2.84,0]],"id":43318163}],"con":true,"img":false}]}
{"op":"mcm","clk":"11540957047","pt":1719500438356,"mc":[{"id":"1.230180123","rc":[{"atb":[[3,0],[3.25,2.5],[3.05,5],[2.92,0],[3.2,0]],"id":47703807}],"con":true,"img":false}]}
{"op":"mcm","clk":"11540957065","pt":1719500438558,"mc":[{"id":"1.230180123","rc":[{"atb":[[3.1,0],[3.05,37]],"id":47703807},{"atl":[[7.6,2.04],[7.8,13.11]],"id":47703807},{"atl":[[4.6,0],[5,0],[4.2,0]],"id":57697855}],"con":true,"img":false}]}
{"op":"mcm","clk":"11540957115","pt":1719500439128,"mc":[{"id":"1.230180123","rc":[{"atb":[[2.22,0]],"id":67487132}],"con":true,"img":false}]}
{"op":"mcm","clk":"11540957124","pt":1719500439234,"mc":[{"id":"1.230180123","rc":[{"atb":[[2.1,3.6]],"id":70396461}],"con":true,"img":false}]}
{"op":"mcm","clk":"11540957177","pt":1719500440163,"mc":[{"id":"1.230180123","rc":[{"atb":[[2.86,10]],"id":43318163},{"atb":[[2.12,0]],"id":70396461}],"con":true,"img":false}]}
{"op":"mcm","clk":"11540957189","pt":1719500440376,"mc":[{"id":"1.230180123","rc":[{"atl":[[4.8,2.8]],"id":40028187},{"atb":[[3.15,3.05]],"id":43318163},{"atl":[[3.35,3.23]],"id":67487132},{"atb":[[2.14,5]],"id":70396461},{"atl":[[3.05,3.32]],"id":70396461},{"atl":[[3.6,2.71]],"id":57697855}],"con":true,"img":false}]}
{"op":"mcm","clk":"11540957198","pt":1719500440475,"mc":[{"id":"1.230180123","rc":[{"atl":[[4.8,8.59],[5,0]],"id":40028187},{"atl":[[3.45,1.84],[3.35,7.53]],"id":67487132},{"atl":[[3.1,4.34],[3,3.33],[3.05,8.52]],"id":70396461},{"atl":[[3.6,6.9],[3.7,0]],"id":57697855}],"con":true,"img":false}]}
{"op":"mcm","clk":"11540957204","pt":1719500440528,"mc":[{"id":"1.230180123","rc":[{"atl":[[2.98,1.71]],"id":70396461}],"con":true,"img":false}]}
{"op":"mcm","clk":"11540957211","pt":1719500440632,"mc":[{"id":"1.230180123","rc":[{"atl":[[3.1,0]],"id":70396461}],"con":true,"img":false}]}
{"op":"mcm","clk":"11540957219","pt":1719500440736,"mc":[{"id":"1.230180123","rc":[{"atl":[[4.7,0.84]],"id":40028187},{"atl":[[3.3,0.84]],"id":67487132},{"atl":[[2.98,2.55]],"id":70396461},{"atl":[[3.55,0.84]],"id":57697855}],"con":true,"img":false}]}
{"op":"mcm","clk":"11540957243","pt":1719500441147,"mc":[{"id":"1.230180123","rc":[{"atl":[[3.05,7.68]],"id":70396461}],"con":true,"img":false}]}
{"op":"mcm","clk":"11540957262","pt":1719500441355,"mc":[{"id":"1.230180123","rc":[{"atb":[[3.1,17.63]],"id":43318163}],"con":true,"img":false}]}
{"op":"mcm","clk":"11540957273","pt":1719500441459,"mc":[{"id":"1.230180123","rc":[{"atb":[[2.26,0],[2.48,10],[1.02,2]],"id":43318163}],"con":true,"img":false}]}
{"op":"mcm","clk":"11540957283","pt":1719500441584,"mc":[{"id":"1.230180123","rc":[{"atb":[[1.92,5.36]],"id":57697855}],"con":true,"img":false}]}
{"op":"mcm","clk":"11540957366","pt":1719500442627,"mc":[{"id":"1.230180123","rc":[{"atl":[[3.5,3.42]],"id":67487132}],"con":true,"img":false}]}
{"op":"mcm","clk":"11540957375","pt":1719500442729,"mc":[{"id":"1.230180123","rc":[{"atl":[[3.5,0]],"id":67487132}],"con":true,"img":false}]}
{"op":"mcm","clk":"11540957431","pt":1719500443561,"mc":[{"id":"1.230180123","rc":[{"atb":[[3,32],[3.05,5]],"id":47703807}],"con":true,"img":false}]}
{"op":"mcm","clk":"11540957462","pt":1719500443974,"mc":[{"id":"1.230180123","rc":[{"atb":[[2.36,2.5],[2.76,8.82]],"id":40028187},{"atl":[[7.2,1]],"id":43318163}],"con":true,"img":false}]}
{"op":"mcm","clk":"11540957473","pt":1719500444029,"mc":[{"id":"1.230180123","rc":[{"atb":[[2.34,0]],"id":40028187},{"atl":[[7,0]],"id":43318163}],"con":true,"img":false}]}
{"op":"mcm","clk":"11540957512","pt":1719500444647,"mc":[{"id":"1.230180123","rc":[{"atl":[[4.7,11.62]],"id":40028187},{"atl":[[3.55,5.58]],"id":57697855}],"con":true,"img":false}]}
{"op":"mcm","clk":"11540957518","pt":1719500444750,"mc":[{"id":"1.230180123","rc":[{"atl":[[4.6,3.09]],"id":40028187},{"atl":[[3.5,2.9]],"id":57697855}],"con":true,"img":false}]}
{"op":"mcm","clk":"11540957524","pt":1719500444854,"mc":[{"id":"1.230180123","rc":[{"atl":[[4.9,0.84]],"id":40028187},{"atl":[[3.65,0.84]],"id":57697855}],"con":true,"img":false}]}
{"op":"mcm","clk":"11540957551","pt":1719500445265,"mc":[{"id":"1.230180123","rc":[{"atl":[[4.9,0]],"id":40028187},{"atl":[[3.65,0]],"id":57697855}],"con":true,"img":false}]}
{"op":"mcm","clk":"11540957571","pt":1719500445678,"mc":[{"id":"1.230180123","rc":[{"atl":[[4.8,2.8],[4.5,8.59]],"id":40028187},{"atl":[[3.6,2.7],[3.5,8.49]],"id":57697855}],"con":true,"img":false}]}
{"op":"mcm","clk":"11540957579","pt":1719500445730,"mc":[{"id":"1.230180123","rc":[{"atb":[[2.76,20.19]],"id":40028187},{"atl":[[4.4,3.42],[4.6,9.42]],"id":40028187}],"con":true,"img":false}]}
{"op":"mcm","clk":"11540957610","pt":1719500446153,"mc":[{"id":"1.230180123","rc":[{"atl":[[4.7,10.78]],"id":40028187}],"con":true,"img":false}]}
{"op":"mcm","clk":"11540957619","pt":1719500446252,"mc":[{"id":"1.230180123","rc":[{"atl":[[3.35,16.37]],"id":67487132}],"con":true,"img":false}]}
{"op":"mcm","clk":"11540957627","pt":1719500446361,"mc":[{"id":"1.230180123","rc":[{"atl":[[3.4,0.84]],"id":67487132}],"con":true,"img":false}]}
{"op":"mcm","clk":"11540957651","pt":1719500446667,"mc":[{"id":"1.230180123","rc":[{"atb":[[3.15,9.63]],"id":43318163}],"con":true,"img":false}]}
{"op":"mcm","clk":"11540957660","pt":1719500446772,"mc":[{"id":"1.230180123","rc":[{"atl":[[4.6,9.01]],"id":40028187},{"atb":[[3.1,12.01]],"id":43318163}],"con":true,"img":false}]}
{"op":"mcm","clk":"11540957698","pt":1719500447189,"mc":[{"id":"1.230180123","rc":[{"atl":[[4.6,3.09]],"id":40028187}],"con":true,"img":false}]}
{"op":"mcm","clk":"11540957707","pt":1719500447236,"mc":[{"id":"1.230180123","rc":[{"atl":[[4.4,9.34]],"id":40028187}],"con":true,"img":false}]}
{"op":"mcm","clk":"11540957774","pt":1719500448160,"mc":[{"id":"1.230180123","rc":[{"atl":[[4.3,0.84]],"id":40028187},{"atl":[[3.45,0.84]],"id":57697855}],"con":true,"img":false}]}
{"op":"mcm","clk":"11540957829","pt":1719500448831,"mc":[{"id":"1.230180123","rc":[{"atb":[[2.74,0]],"id":40028187}],"con":true,"img":false}]}
{"op":"mcm","clk":"11540957833","pt":1719500448936,"mc":[{"id":"1.230180123","rc":[{"atb":[[2.78,3]],"id":40028187}],"con":true,"img":false}]}
{"op":"mcm","clk":"11540957864","pt":1719500449450,"mc":[{"id":"1.230180123","rc":[{"atb":[[2.76,8.82]],"id":40028187}],"con":true,"img":false}]}
{"op":"mcm","clk":"11540957907","pt":1719500450076,"mc":[{"id":"1.230180123","rc":[{"atb":[[2.76,6.82]],"id":40028187}],"con":true,"img":false}]}
{"op":"mcm","clk":"11540957917","pt":1719500450180,"mc":[{"id":"1.230180123","rc":[{"atb":[[2.8,2],[2.74,3]],"id":40028187}],"con":true,"img":false}]}
{"op":"mcm","clk":"11540957930","pt":1719500450278,"mc":[{"id":"1.230180123","rc":[{"atb":[[2.78,15.78]],"id":40028187}],"con":true,"img":false}]}
{"op":"mcm","clk":"11540957964","pt":1719500450744,"mc":[{"id":"1.230180123","rc":[{"atb":[[2.74,0]],"id":40028187},{"atl":[[4.3,9.43],[4.5,0]],"id":40028187}],"con":true,"img":false}]}
{"op":"mcm","clk":"11540957977","pt":1719500450953,"mc":[{"id":"1.230180123","rc":[{"atb":[[2.76,0]],"id":40028187},{"atl":[[4.2,3.64]],"id":40028187},{"atl":[[7.6,7.28],[7.8,0]],"id":47703807},{"atb":[[1.92,0]],"id":57697855}],"con":true,"img":false}]}
{"op":"mcm","clk":"11540957988","pt":1719500451157,"mc":[{"id":"1.230180123","rc":[{"atb":[[2.78,14.77]],"id":40028187},{"atl":[[4.3,0.84],[4.4,3.42],[4.1,9.34]],"id":40028187},{"atl":[[2.98,7.75]],"id":70396461}],"con":true,"img":false}]}
{"op":"mcm","clk":"11540957995","pt":1719500451259,"mc":[{"id":"1.230180123","rc":[{"atl":[[4,2.11]],"id":40028187},{"atl":[[3,0],[2.96,7.68]],"id":70396461}],"con":true,"img":false}]}
{"op":"mcm","clk":"11540958000","pt":1719500451370,"mc":[{"id":"1.230180123","rc":[{"atb":[[2.78,3]],"id":40028187},{"atl":[[2.98,23.11],[2.96,0],[2.94,1.77],[3.05,2.48]],"id":70396461}],"con":true,"img":false}]}
{"op":"mcm","clk":"11540958008","pt":1719500451469,"mc":[{"id":"1.230180123","rc":[{"atb":[[2.8,13.77]],"id":40028187},{"atl":[[2.98,7.75],[2.94,4.25]],"id":70396461}],"con":true,"img":false}]}
{"op":"mcm","clk":"11540958017","pt":1719500451670,"mc":[{"id":"1.230180123","rc":[{"atl":[[4.3,0]],"id":40028187},{"atl":[[2.92,0.84],[2.98,6.91]],"id":70396461}],"con":true,"img":false}]}
{"op":"mcm","clk":"11540958081","pt":1719500452472,"mc":[{"id":"1.230180123","rc":[{"atl":[[4,10.62]],"id":40028187}],"con":true,"img":false}]}
{"op":"mcm","clk":"11540958097","pt":1719500452652,"mc":[{"id":"1.230180123","rc":[{"atl":[[3.95,9.34],[4.1,0]],"id":40028187}],"con":true,"img":false}]}
{"op":"mcm","clk":"11540958107","pt":1719500452757,"mc":[{"id":"1.230180123","rc":[{"atl":[[3.9,2.25]],"id":40028187}],"con":true,"img":false}]}
{"op":"mcm","clk":"11540958187","pt":1719500453845,"mc":[{"id":"1.230180123","rc":[{"atl":[[4,9.91]],"id":40028187}],"con":true,"img":false}]}
{"op":"mcm","clk":"11540958208","pt":1719500454047,"mc":[{"id":"1.230180123","rc":[{"atl":[[4,2.11]],"id":40028187}],"con":true,"img":false}]}
{"op":"mcm","clk":"11540958218","pt":1719500454150,"mc":[{"id":"1.230180123","rc":[{"atl":[[3.9,10.05]],"id":40028187},{"atb":[[2.22,4.62]],"id":67487132}],"con":true,"img":false}]}
{"op":"mcm","clk":"11540958296","pt":1719500455078,"mc":[{"id":"1.230180123","rc":[{"atb":[[2.1,8.24]],"id":70396461}],"con":true,"img":false}]}
{"op":"mcm","clk":"11540958315","pt":1719500455285,"mc":[{"id":"1.230180123","rc":[{"atl":[[3.85,15.38]],"id":40028187},{"atl":[[3.45,5.58]],"id":57697855}],"con":true,"img":false}]}
{"op":"mcm","clk":"11540958323","pt":1719500455387,"mc":[{"id":"1.230180123","rc":[{"atl":[[3.8,2.39],[4.7,0]],"id":40028187},{"atl":[[3.4,2.93],[3.55,0.84]],"id":57697855}],"con":true,"img":false}]}
{"op":"mcm","clk":"11540958339","pt":1719500455549,"mc":[{"id":"1.230180123","rc":[{"atl":[[3.4,8.52],[3.5,2.9]],"id":57697855}],"con":true,"img":false}]}
{"op":"mcm","clk":"11540958356","pt":1719500455753,"mc":[{"id":"1.230180123","rc":[{"atl":[[3.9,9.99]],"id":40028187},{"atl":[[3.35,0.84],[3.55,0]],"id":57697855}],"con":true,"img":false}]}
{"op":"mcm","clk":"11540958368","pt":1719500455962,"mc":[{"id":"1.230180123","rc":[{"atl":[[3.9,2.25]],"id":40028187}],"con":true,"img":false}]}
{"op":"mcm","clk":"11540958380","pt":1719500456060,"mc":[{"id":"1.230180123","rc":[{"atl":[[3.8,10.13]],"id":40028187}],"con":true,"img":false}]}
{"op":"mcm","clk":"11540958485","pt":1719500457561,"mc":[{"id":"1.230180123","rc":[{"atb":[[2.78,0]],"id":40028187}],"con":true,"img":false}]}
{"op":"mcm","clk":"11540958499","pt":1719500457767,"mc":[{"id":"1.230180123","rc":[{"atb":[[2.82,2.37]],"id":40028187}],"con":true,"img":false}]}
{"op":"mcm","clk":"11540958551","pt":1719500458490,"mc":[{"id":"1.230180123","rc":[{"atb":[[2.8,2]],"id":40028187}],"con":true,"img":false}]}
{"op":"mcm","clk":"11540958613","pt":1719500459162,"mc":[{"id":"1.230180123","rc":[{"atb":[[2.8,0]],"id":40028187}],"con":true,"img":false}]}
{"op":"mcm","clk":"11540958622","pt":1719500459264,"mc":[{"id":"1.230180123","rc":[{"atb":[[2.84,2]],"id":40028187}],"con":true,"img":false}]}
{"op":"mcm","clk":"11540958718","pt":1719500460361,"mc":[{"id":"1.230180123","rc":[{"atb":[[2.84,13.56]],"id":40028187}],"con":true,"img":false}]}
{"op":"mcm","clk":"11540958741","pt":1719500460565,"mc":[{"id":"1.230180123","rc":[{"atb":[[1.92,5.36]],"id":57697855}],"con":true,"img":false}]}
{"op":"mcm","clk":"11540958828","pt":1719500461647,"mc":[{"id":"1.230180123","rc":[{"atl":[[2.94,11.19]],"id":70396461}],"con":true,"img":false}]}
{"op":"mcm","clk":"11540958836","pt":1719500461760,"mc":[{"id":"1.230180123","rc":[{"atl":[[2.98,1.71],[2.96,5.1],[2.94,8.71]],"id":70396461}],"con":true,"img":false}]}
{"op":"mcm","clk":"11540958857","pt":1719500461963,"mc":[{"id":"1.230180123","rc":[{"atl":[[6.6,16.78]],"id":47703807},{"atl":[[3.45,0]],"id":67487132}],"con":true,"img":false}]}
{"op":"mcm","clk":"11540958865","pt":1719500462069,"mc":[{"id":"1.230180123","rc":[{"atb":[[2.32,19.26],[2.48,0]],"id":43318163},{"atl":[[6,0],[6.8,17.24],[7.6,0]],"id":43318163},{"atb":[[2.92,21],[3,0]],"id":47703807},{"atb":[[2.22,0],[1.96,9.62],[2.26,2],[2.08,0]],"id":67487132},{"atl":[[4.6,0],[5,0],[3.3,5.9],[4.2,0]],"id":67487132},{"atb":[[2.14,12.57]],"id":70396461},{"atb":[[1.92,0]],"id":57697855}],"con":true,"img":false}]}
{"op":"mcm","clk":"11540958872","pt":1719500462165,"mc":[{"id":"1.230180123","rc":[{"atl":[[3.8,7.74],[3.9,0]],"id":40028187},{"atl":[[3.35,7.53],[3.25,6.05]],"id":67487132},{"atb":[[2.1,4.64]],"id":70396461}],"con":true,"img":false}]}
{"op":"mcm","clk":"11540958883","pt":1719500462274,"mc":[{"id":"1.230180123","rc":[{"atl":[[3.75,0.84]],"id":40028187},{"atl":[[9.6,5],[11,10],[8.8,2.5]],"id":43318163}],"con":true,"img":false}]}
{"op":"mcm","clk":"11540958895","pt":1719500462377,"mc":[{"id":"1.230180123","rc":[{"atl":[[3.25,0]],"id":67487132}],"con":true,"img":false}]}
{"op":"mcm","clk":"11540958908","pt":1719500462481,"mc":[{"id":"1.230180123","rc":[{"atl":[[3.25,3.48]],"id":67487132}],"con":true,"img":false}]}
{"op":"mcm","clk":"11540958935","pt":1719500462786,"mc":[{"id":"1.230180123","rc":[{"atl":[[3.4,0]],"id":67487132}],"con":true,"img":false}]}
{"op":"mcm","clk":"11540958941","pt":1719500462889,"mc":[{"id":"1.230180123","rc":[{"atb":[[2.1,0]],"id":70396461}],"con":true,"img":false}]}
{"op":"mcm","clk":"11540958961","pt":1719500463054,"mc":[{"id":"1.230180123","rc":[{"atl":[[6.2,3.62]],"id":43318163},{"atb":[[2.26,0]],"id":67487132},{"atb":[[2.08,6.33]],"id":70396461}],"con":true,"img":false}]}
{"op":"mcm","clk":"11540958968","pt":1719500463150,"mc":[{"id":"1.230180123","rc":[{"atl":[[6.2,0]],"id":43318163},{"atb":[[2.12,8.47],[2.14,2]],"id":67487132},{"atl":[[3.2,0.84]],"id":67487132},{"atb":[[2.08,0]],"id":70396461}],"con":true,"img":false}]}
{"op":"mcm","clk":"11540958992","pt":1719500463460,"mc":[{"id":"1.230180123","rc":[{"atb":[[3.1,0]],"id":43318163}],"con":true,"img":false}]}
{"op":"mcm","clk":"11540959049","pt":1719500464182,"mc":[{"id":"1.230180123","rc":[{"atb":[[3.15,19.03]],"id":43318163}],"con":true,"img":false}]}
{"op":"mcm","clk":"11540959153","pt":1719500465684,"mc":[{"id":"1.230180123","rc":[{"atl":[[3.8,22.82]],"id":40028187},{"atl":[[3.35,5.58]],"id":57697855}],"con":true,"img":false}]}
{"op":"mcm","clk":"11540959160","pt":1719500465787,"mc":[{"id":"1.230180123","rc":[{"atl":[[3.85,0.84]],"id":40028187},{"atl":[[3.3,2.63]],"id":57697855}],"con":true,"img":false}]}
{"op":"mcm","clk":"11540959168","pt":1719500465890,"mc":[{"id":"1.230180123","rc":[{"atl":[[3.45,0.84],[3.35,11.17],[3.4,2.93]],"id":57697855}],"con":true,"img":false}]}
{"op":"mcm","clk":"11540959174","pt":1719500465944,"mc":[{"id":"1.230180123","rc":[{"atl":[[3.05,4.66]],"id":57697855}],"con":true,"img":false}]}
{"op":"mcm","clk":"11540959180","pt":1719500466050,"mc":[{"id":"1.230180123","rc":[{"atl":[[3,1.68]],"id":57697855}],"con":true,"img":false}]}
{"op":"mcm","clk":"11540959190","pt":1719500466156,"mc":[{"id":"1.230180123","rc":[{"atb":[[2.82,0]],"id":40028187},{"atb":[[2.14,9.57]],"id":70396461},{"atl":[[3.25,0.84],[3.45,0]],"id":57697855}],"con":true,"img":false}]}
{"op":"mcm","clk":"11540959206","pt":1719500466366,"mc":[{"id":"1.230180123","rc":[{"atb":[[2.86,3.52]],"id":40028187}],"con":true,"img":false}]}
{"op":"mcm","clk":"11540959232","pt":1719500466671,"mc":[{"id":"1.230180123","rc":[{"atl":[[3.35,10.33],[3.25,0]],"id":57697855}],"con":true,"img":false}]}
{"op":"mcm","clk":"11540959265","pt":1719500467085,"mc":[{"id":"1.230180123","rc":[{"atb":[[2.84,13]],"id":40028187}],"con":true,"img":false}]}
{"op":"mcm","clk":"11540959274","pt":1719500467188,"mc":[{"id":"1.230180123","rc":[{"atb":[[2.86,15.43]],"id":40028187},{"atl":[[3.95,0],[4.2,7.86]],"id":40028187},{"atb":[[2.32,0],[2.44,10]],"id":43318163},{"atb":[[2.92,0],[3,10]],"id":47703807},{"atb":[[2.02,9.62],[1.96,0]],"id":67487132},{"atl":[[3.35,3.23],[3.3,11.81]],"id":67487132},{"atb":[[2.14,2]],"id":70396461}],"con":true,"img":false}]}
{"op":"mcm","clk":"11540959285","pt":1719500467396,"mc":[{"id":"1.230180123","rc":[{"atb":[[2.84,2]],"id":40028187}],"con":true,"img":false}]}
{"op":"mcm","clk":"11540959291","pt":1719500467457,"mc":[{"id":"1.230180123","rc":[{"atb":[[2.86,26.43]],"id":40028187}],"con":true,"img":false}]}
{"op":"mcm","clk":"11540959305","pt":1719500467657,"mc":[{"id":"1.230180123","rc":[{"atl":[[3.25,5.91]],"id":67487132}],"con":true,"img":false}]}
{"op":"mcm","clk":"11540959320","pt":1719500467865,"mc":[{"id":"1.230180123","rc":[{"atb":[[2.84,0]],"id":40028187}],"con":true,"img":false}]}
{"op":"mcm","clk":"11540959327","pt":1719500467988,"mc":[{"id":"1.230180123","rc":[{"atb":[[2.88,2]],"id":40028187}],"con":true,"img":false}]}
{"op":"mcm","clk":"11540959397","pt":1719500468959,"mc":[{"id":"1.230180123","rc":[{"atb":[[2.86,15.43]],"id":40028187}],"con":true,"img":false}]}
{"op":"mcm","clk":"11540959409","pt":1719500469183,"mc":[{"id":"1.230180123","rc":[{"atb":[[2.88,0]],"id":40028187}],"con":true,"img":false}]}
{"op":"mcm","clk":"11540959417","pt":1719500469292,"mc":[{"id":"1.230180123","rc":[{"atb":[[1.02,2]],"id":40028187}],"con":true,"img":false}]}
{"op":"mcm","clk":"11540959467","pt":1719500469760,"mc":[{"id":"1.230180123","rc":[{"atb":[[2.14,0]],"id":70396461}],"con":true,"img":false}]}
{"op":"mcm","clk":"11540959477","pt":1719500469864,"mc":[{"id":"1.230180123","rc":[{"atb":[[1.99,2],[1.98,7.73]],"id":70396461}],"con":true,"img":false}]}
{"op":"mcm","clk":"11540959561","pt":1719500471373,"mc":[{"id":"1.230180123","rc":[{"atb":[[1.02,0]],"id":40028187}],"con":true,"img":false}]}
{"op":"mcm","clk":"11540959567","pt":1719500471485,"mc":[{"id":"1.230180123","rc":[{"atb":[[2.88,2]],"id":40028187}],"con":true,"img":false}]}
{"op":"mcm","clk":"11540959630","pt":1719500472365,"mc":[{"id":"1.230180123","rc":[{"atl":[[3.2,7.15]],"id":67487132},{"atb":[[1.99,7.7]],"id":70396461}],"con":true,"img":false}]}
{"op":"mcm","clk":"11540959639","pt":1719500472478,"mc":[{"id":"1.230180123","rc":[{"atb":[[2.88,14.59]],"id":40028187}],"con":true,"img":false}]}
{"op":"mcm","clk":"11540959650","pt":1719500472576,"mc":[{"id":"1.230180123","rc":[{"atl":[[3.3,6.75]],"id":67487132},{"atb":[[1.98,2.11]],"id":70396461}],"con":true,"img":false}]}
{"op":"mcm","clk":"11540959658","pt":1719500472679,"mc":[{"id":"1.230180123","rc":[{"atl":[[3.3,5.91]],"id":67487132}],"con":true,"img":false}]}
{"op":"mcm","clk":"11540959675","pt":1719500472889,"mc":[{"id":"1.230180123","rc":[{"atb":[[2.88,12.59]],"id":40028187}],"con":true,"img":false}]}
{"op":"mcm","clk":"11540959687","pt":1719500472993,"mc":[{"id":"1.230180123","rc":[{"atb":[[1.02,2]],"id":40028187}],"con":true,"img":false}]}
{"op":"mcm","clk":"11540959713","pt":1719500473261,"mc":[{"id":"1.230180123","rc":[{"atl":[[3.15,3.76]],"id":67487132}],"con":true,"img":false}]}
{"op":"mcm","clk":"11540959723","pt":1719500473363,"mc":[{"id":"1.230180123","rc":[{"atl":[[3.25,3.48]],"id":67487132}],"con":true,"img":false}]}
{"op":"mcm","clk":"11540959731","pt":1719500473471,"mc":[{"id":"1.230180123","rc":[{"atl":[[7.6,2.04],[7.8,9.9]],"id":47703807},{"atb":[[2.02,0],[2.12,13.49],[1.93,13.48],[2.14,9.25]],"id":67487132},{"atl":[[3.35,19.49],[3.3,0]],"id":67487132}],"con":true,"img":false}]}
{"op":"mcm","clk":"11540959740","pt":1719500473567,"mc":[{"id":"1.230180123","rc":[{"atb":[[2.12,7.13]],"id":67487132}],"con":true,"img":false}]}
{"op":"mcm","clk":"11540959748","pt":1719500473671,"mc":[{"id":"1.230180123","rc":[{"atl":[[3.1,0.84],[3.15,11.09]],"id":67487132}],"con":true,"img":false}]}
{"op":"mcm","clk":"11540959760","pt":1719500473880,"mc":[{"id":"1.230180123","rc":[{"atl":[[3.35,15.05],[3.15,3.76]],"id":67487132}],"con":true,"img":false}]}
{"op":"mcm","clk":"11540959799","pt":1719500474296,"mc":[{"id":"1.230180123","rc":[{"atb":[[1.98,7.26]],"id":70396461}],"con":true,"img":false}]}
{"op":"mcm","clk":"11540959815","pt":1719500474458,"mc":[{"id":"1.230180123","rc":[{"atl":[[3.15,12.33]],"id":67487132}],"con":true,"img":false}]}
{"op":"mcm","clk":"11540959841","pt":1719500474763,"mc":[{"id":"1.230180123","rc":[{"atl":[[3.15,3.76]],"id":67487132}],"con":true,"img":false}]}
{"op":"mcm","clk":"11540959854","pt":1719500474975,"mc":[{"id":"1.230180123","rc":[{"atb":[[2.86,11.91]],"id":40028187}],"con":true,"img":false}]}
{"op":"mcm","clk":"11540959861","pt":1719500475073,"mc":[{"id":"1.230180123","rc":[{"atb":[[2.9,3.6]],"id":40028187},{"atl":[[3.15,9.03]],"id":67487132},{"atb":[[2,3.1]],"id":70396461}],"con":true,"img":false}]}
{"op":"mcm","clk":"11540959886","pt":1719500475493,"mc":[{"id":"1.230180123","rc":[{"atb":[[1.98,2.11]],"id":70396461}],"con":true,"img":false}]}
{"op":"mcm","clk":"11540959907","pt":1719500475801,"mc":[{"id":"1.230180123","rc":[{"atb":[[2.88,0],[1.02,0]],"id":40028187},{"atl":[[3.15,3.76]],"id":67487132}],"con":true,"img":false}]}
{"op":"mcm","clk":"11540959917","pt":1719500475898,"mc":[{"id":"1.230180123","rc":[{"atb":[[2.92,2]],"id":40028187},{"atl":[[3,5.24]],"id":57697855}],"con":true,"img":false}]}
{"op":"mcm","clk":"11540959921","pt":1719500476002,"mc":[{"id":"1.230180123","rc":[{"atl":[[3.35,5.59]],"id":57697855}],"con":true,"img":false}]}
{"op":"mcm","clk":"11540959927","pt":1719500476056,"mc":[{"id":"1.230180123","rc":[{"atl":[[3.75,5.04]],"id":40028187},{"atl":[[3.1,5.5]],"id":67487132}],"con":true,"img":false}]}
{"op":"mcm","clk":"11540959931","pt":1719500476169,"mc":[{"id":"1.230180123","rc":[{"atl":[[3.8,7.74]],"id":40028187},{"atl":[[3.05,3.96]],"id":67487132},{"atl":[[2.98,0.84]],"id":57697855}],"con":true,"img":false}]}
{"op":"mcm","clk":"11540959936","pt":1719500476265,"mc":[{"id":"1.230180123","rc":[{"atb":[[1.99,5.7]],"id":70396461}],"con":true,"img":false}]}
{"op":"mcm","clk":"11540959944","pt":1719500476368,"mc":[{"id":"1.230180123","rc":[{"atb":[[2.02,2]],"id":70396461}],"con":true,"img":false}]}
{"op":"mcm","clk":"11540959951","pt":1719500476480,"mc":[{"id":"1.230180123","rc":[{"atl":[[3.75,0.84]],"id":40028187}],"con":true,"img":false}]}
{"op":"mcm","clk":"11540959960","pt":1719500476574,"mc":[{"id":"1.230180123","rc":[{"atl":[[3.8,11.94]],"id":40028187}],"con":true,"img":false}]}
{"op":"mcm","clk":"11540959969","pt":1719500476679,"mc":[{"id":"1.230180123","rc":[{"atb":[[2.92,13.31]],"id":40028187},{"atl":[[3.85,0]],"id":40028187},{"atl":[[3.2,6.31]],"id":67487132}],"con":true,"img":false}]}
{"op":"mcm","clk":"11540960076","pt":1719500478592,"mc":[{"id":"1.230180123","rc":[{"atb":[[1.92,5.36]],"id":57697855}],"con":true,"img":false}]}
{"op":"mcm","clk":"11540960091","pt":1719500478800,"mc":[{"id":"1.230180123","rc":[{"atb":[[1.92,0]],"id":57697855}],"con":true,"img":false}]}
{"op":"mcm","clk":"11540960142","pt":1719500479377,"mc":[{"id":"1.230180123","rc":[{"atl":[[3.75,3.3]],"id":40028187}],"con":true,"img":false}]}
{"op":"mcm","clk":"11540960155","pt":1719500479585,"mc":[{"id":"1.230180123","rc":[{"atl":[[3.05,0]],"id":57697855}],"con":true,"img":false}]}
{"op":"mcm","clk":"11540960169","pt":1719500479792,"mc":[{"id":"1.230180123","rc":[{"atl":[[3.15,15.63]],"id":57697855}],"con":true,"img":false}]}
{"op":"mcm","clk":"11540960184","pt":1719500479999,"mc":[{"id":"1.230180123","rc":[{"atb":[[2.02,8.15]],"id":70396461}],"con":true,"img":false}]}
{"op":"mcm","clk":"11540960192","pt":1719500480105,"mc":[{"id":"1.230180123","rc":[{"atl":[[3.15,0]],"id":57697855}],"con":true,"img":false}]}
{"op":"mcm","clk":"11540960199","pt":1719500480209,"mc":[{"id":"1.230180123","rc":[{"atb":[[1.99,0]],"id":70396461}],"con":true,"img":false}]}
{"op":"mcm","clk":"11540960239","pt":1719500480783,"mc":[{"id":"1.230180123","rc":[{"atb":[[2.9,0]],"id":40028187},{"atl":[[3,0.84]],"id":67487132},{"atb":[[2,0]],"id":70396461}],"con":true,"img":false}]}
{"op":"mcm","clk":"11540960254","pt":1719500480997,"mc":[{"id":"1.230180123","rc":[{"atb":[[2.94,2]],"id":40028187},{"atb":[[2.04,2.44]],"id":70396461}],"con":true,"img":false}]}
{"op":"mcm","clk":"11540960262","pt":1719500481095,"mc":[{"id":"1.230180123","rc":[{"atl":[[3.75,0.84]],"id":40028187}],"con":true,"img":false}]}
{"op":"mcm","clk":"11540960267","pt":1719500481199,"mc":[{"id":"1.230180123","rc":[{"atl":[[3.05,2.97]],"id":57697855}],"con":true,"img":false}]}
{"op":"mcm","clk":"11540960325","pt":1719500481876,"mc":[{"id":"1.230180123","rc":[{"atb":[[2.92,2]],"id":40028187}],"con":true,"img":false}]}
{"op":"mcm","clk":"11540960373","pt":1719500482502,"mc":[{"id":"1.230180123","rc":[{"atl":[[3.1,0.84],[3.05,11.06]],"id":67487132}],"con":true,"img":false}]}
{"op":"mcm","clk":"11540960381","pt":1719500482605,"mc":[{"id":"1.230180123","rc":[{"atb":[[2.94,14.38]],"id":40028187},{"atb":[[2.04,8.09]],"id":70396461}],"con":true,"img":false}]}
{"op":"mcm","clk":"11540960391","pt":1719500482706,"mc":[{"id":"1.230180123","rc":[{"atl":[[3.2,0],[3,20.83]],"id":67487132}],"con":true,"img":false}]}
{"op":"mcm","clk":"11540960397","pt":1719500482762,"mc":[{"id":"1.230180123","rc":[{"atl":[[2.98,1.71]],"id":67487132},{"atb":[[2.02,2]],"id":70396461}],"con":true,"img":false}]}
{"op":"mcm","clk":"11540960428","pt":1719500483173,"mc":[{"id":"1.230180123","rc":[{"atl":[[3.1,0]],"id":67487132}],"con":true,"img":false}]}
{"op":"mcm","clk":"11540960450","pt":1719500483491,"mc":[{"id":"1.230180123","rc":[{"atl":[[3.05,0]],"id":57697855}],"con":true,"img":false}]}
{"op":"mcm","clk":"11540960460","pt":1719500483591,"mc":[{"id":"1.230180123","rc":[{"atb":[[3.1,2.5],[2.88,10],[2.96,5]],"id":43318163}],"con":true,"img":false}]}
{"op":"mcm","clk":"11540960466","pt":1719500483694,"mc":[{"id":"1.230180123","rc":[{"atb":[[2.94,0],[3.05,0],[2.86,0]],"id":43318163}],"con":true,"img":false}]}
{"op":"mcm","clk":"11540960473","pt":1719500483802,"mc":[{"id":"1.230180123","rc":[{"atb":[[2.92,0]],"id":40028187}],"con":true,"img":false}]}
{"op":"mcm","clk":"11540960482","pt":1719500483899,"mc":[{"id":"1.230180123","rc":[{"atb":[[2.96,2]],"id":40028187},{"atb":[[3.4,5.72]],"id":47703807}],"con":true,"img":false}]}
{"op":"mcm","clk":"11540960493","pt":1719500484112,"mc":[{"id":"1.230180123","rc":[{"atb":[[3.3,11.04]],"id":47703807}],"con":true,"img":false}]}
{"op":"mcm","clk":"11540960519","pt":1719500484367,"mc":[{"id":"1.230180123","rc":[{"atb":[[2.94,2]],"id":40028187},{"atb":[[3.3,2.34]],"id":47703807},{"atb":[[2.02,0]],"id":70396461}],"con":true,"img":false}]}
{"op":"mcm","clk":"11540960529","pt":1719500484475,"mc":[{"id":"1.230180123","rc":[{"atl":[[6.6,12.4]],"id":47703807},{"atb":[[2.06,2]],"id":70396461}],"con":true,"img":false}]}
{"op":"mcm","clk":"11540960537","pt":1719500484572,"mc":[{"id":"1.230180123","rc":[{"atl":[[6.8,7]],"id":47703807}],"con":true,"img":false}]}
{"op":"mcm","clk":"11540960562","pt":1719500484884,"mc":[{"id":"1.230180123","rc":[{"atb":[[2.96,13.97]],"id":40028187},{"atb":[[3.4,14.77]],"id":47703807}],"con":true,"img":false}]}
{"op":"mcm","clk":"11540960687","pt":1719500486494,"mc":[{"id":"1.230180123","rc":[{"atb":[[2.94,0]],"id":40028187},{"atb":[[3.3,0]],"id":47703807},{"atb":[[2.04,5.65]],"id":70396461}],"con":true,"img":false}]}
{"op":"mcm","clk":"11540960693","pt":1719500486601,"mc":[{"id":"1.230180123","rc":[{"atb":[[2.98,2.76]],"id":40028187},{"atb":[[3.45,3]],"id":47703807},{"atb":[[2.06,4.3]],"id":70396461}],"con":true,"img":false}]}
{"op":"mcm","clk":"11540960749","pt":1719500487371,"mc":[{"id":"1.230180123","rc":[{"atb":[[2.96,0]],"id":40028187},{"atb":[[3.4,14.26]],"id":47703807}],"con":true,"img":false}]}
{"op":"mcm","clk":"11540960759","pt":1719500487476,"mc":[{"id":"1.230180123","rc":[{"atb":[[3,2]],"id":40028187},{"atb":[[3.1,5],[3.25,0],[3.3,2.5],[3.05,0]],"id":47703807}],"con":true,"img":false}]}
{"op":"mcm","clk":"11540960768","pt":1719500487578,"mc":[{"id":"1.230180123","rc":[{"atb":[[3.4,5.72]],"id":47703807}],"con":true,"img":false}]}
{"op":"mcm","clk":"11540960775","pt":1719500487677,"mc":[{"id":"1.230180123","rc":[{"atb":[[3.45,11.54]],"id":47703807}],"con":true,"img":false}]}
{"op":"mcm","clk":"11540960810","pt":1719500488198,"mc":[{"id":"1.230180123","rc":[{"atb":[[3,13.46]],"id":40028187},{"atl":[[2.96,0.84]],"id":67487132},{"atl":[[3.05,3.99]],"id":57697855}],"con":true,"img":false}]}
{"op":"mcm","clk":"11540960909","pt":1719500489903,"mc":[{"id":"1.230180123","rc":[{"atb":[[2.06,11.35]],"id":70396461}],"con":true,"img":false}]}
{"op":"mcm","clk":"11540960926","pt":1719500490109,"mc":[{"id":"1.230180123","rc":[{"atb":[[2.04,0]],"id":70396461}],"con":true,"img":false}]}
{"op":"mcm","clk":"11540961089","pt":1719500492286,"mc":[{"id":"1.230180123","rc":[{"atb":[[2.98,0]],"id":40028187},{"spn":3.37,"spf":"NaN","id":40028187},{"spn":4.27,"spf":"NaN","id":43318163},{"spn":5.02,"spf":"NaN","id":47703807},{"spn":2.55,"spf":"NaN","id":67487132},{"atb":[[2.06,9.05]],"id":70396461},{"spn":2.49,"spf":"NaN","id":70396461}],"con":true,"img":false}]}
{"op":"mcm","clk":"11540961096","pt":1719500492388,"mc":[{"id":"1.230180123","rc":[{"atb":[[3.05,3]],"id":40028187},{"atl":[[2.98,8.94]],"id":67487132},{"atb":[[2.08,3.43]],"id":70396461}],"con":true,"img":false}]}
{"op":"mcm","clk":"11540961106","pt":1719500492494,"mc":[{"id":"1.230180123","rc":[{"atb":[[2.08,9.83]],"id":70396461}],"con":true,"img":false}]}
{"op":"mcm","clk":"11540961117","pt":1719500492597,"mc":[{"id":"1.230180123","rc":[{"atl":[[3.05,3.96]],"id":67487132},{"atb":[[2.04,6.54]],"id":70396461}],"con":true,"img":false}]}
{"op":"mcm","clk":"11540961124","pt":1719500492698,"mc":[{"id":"1.230180123","rc":[{"atb":[[3,2]],"id":40028187},{"atb":[[2.06,2]],"id":70396461}],"con":true,"img":false}]}
{"op":"mcm","clk":"11540961131","pt":1719500492796,"mc":[{"id":"1.230180123","rc":[{"atb":[[2.44,2.5]],"id":40028187}],"con":true,"img":false}]}
{"op":"mcm","clk":"11540961148","pt":1719500493003,"mc":[{"id":"1.230180123","rc":[{"atb":[[2.04,0]],"id":70396461}],"con":true,"img":false}]}
{"op":"mcm","clk":"11540961207","pt":1719500493679,"mc":[{"id":"1.230180123","rc":[{"atb":[[3.05,15.58]],"id":40028187}],"con":true,"img":false}]}
{"op":"mcm","clk":"11540961215","pt":1719500493784,"mc":[{"id":"1.230180123","rc":[{"atb":[[3.5,9.54]],"id":47703807}],"con":true,"img":false}]}
{"op":"mcm","clk":"11540961222","pt":1719500493887,"mc":[{"id":"1.230180123","rc":[{"atb":[[3.4,0]],"id":47703807}],"con":true,"img":false}]}
{"op":"mcm","clk":"11540961290","pt":1719500494816,"mc":[{"id":"1.230180123","rc":[{"atb":[[3,0]],"id":40028187}],"con":true,"img":false}]}
{"op":"mcm","clk":"11540961300","pt":1719500494918,"mc":[{"id":"1.230180123","rc":[{"atb":[[3.1,2]],"id":40028187}],"con":true,"img":false}]}
{"op":"mcm","clk":"11540961311","pt":1719500495030,"mc":[{"id":"1.230180123","rc":[{"atb":[[3.05,13.78]],"id":40028187},{"atb":[[3.45,3]],"id":47703807}],"con":true,"img":false}]}
{"op":"mcm","clk":"11540961331","pt":1719500495179,"mc":[{"id":"1.230180123","rc":[{"atb":[[3.05,3]],"id":40028187}],"con":true,"img":false}]}
{"op":"mcm","clk":"11540961345","pt":1719500495283,"mc":[{"id":"1.230180123","rc":[{"atb":[[2.88,10.78]],"id":40028187}],"con":true,"img":false}]}
{"op":"mcm","clk":"11540961348","pt":1719500495394,"mc":[{"id":"1.230180123","rc":[{"atb":[[2.06,0]],"id":70396461}],"con":true,"img":false}]}
{"op":"mcm","clk":"11540961358","pt":1719500495490,"mc":[{"id":"1.230180123","rc":[{"atb":[[2.1,2]],"id":70396461}],"con":true,"img":false}]}
{"op":"mcm","clk":"11540961364","pt":1719500495594,"mc":[{"id":"1.230180123","rc":[{"atb":[[1.92,5.36]],"id":57697855}],"con":true,"img":false}]}
{"op":"mcm","clk":"11540961380","pt":1719500495810,"mc":[{"id":"1.230180123","rc":[{"atb":[[2.88,0]],"id":40028187}],"con":true,"img":false}]}
{"op":"mcm","clk":"11540961388","pt":1719500495909,"mc":[{"id":"1.230180123","rc":[{"atb":[[3.5,19.04]],"id":47703807}],"con":true,"img":false}]}
{"op":"mcm","clk":"11540961456","pt":1719500496900,"mc":[{"id":"1.230180123","rc":[{"atb":[[3.1,12.31]],"id":40028187}],"con":true,"img":false}]}
{"op":"mcm","clk":"11540961558","pt":1719500498099,"mc":[{"id":"1.230180123","rc":[{"atb":[[3.05,0]],"id":40028187},{"atb":[[3.45,0]],"id":47703807},{"atb":[[2.08,6.4]],"id":70396461}],"con":true,"img":false}]}
{"op":"mcm","clk":"11540961567","pt":1719500498197,"mc":[{"id":"1.230180123","rc":[{"atb":[[3.55,3.55]],"id":47703807},{"atb":[[2.1,5]],"id":70396461}],"con":true,"img":false}]}
{"op":"mcm","clk":"11540961692","pt":1719500499597,"mc":[{"id":"1.230180123","rc":[{"atb":[[2.1,12.57]],"id":70396461}],"con":true,"img":false}]}
{"op":"mcm","clk":"11540961702","pt":1719500499703,"mc":[{"id":"1.230180123","rc":[{"atb":[[3.1,2]],"id":40028187},{"atb":[[3.5,18.13]],"id":47703807},{"atb":[[2.08,0]],"id":70396461}],"con":true,"img":false}]}
{"op":"mcm","clk":"11540961720","pt":1719500499905,"mc":[{"id":"1.230180123","rc":[{"atb":[[3.5,9.54]],"id":47703807}],"con":true,"img":false}]}
{"op":"mcm","clk":"11540961724","pt":1719500500008,"mc":[{"id":"1.230180123","rc":[{"atb":[[3.55,12.14]],"id":47703807}],"con":true,"img":false}]}
{"op":"mcm","clk":"11540961762","pt":1719500500524,"mc":[{"id":"1.230180123","rc":[{"atl":[[3.75,4.3]],"id":40028187}],"con":true,"img":false}]}
{"op":"mcm","clk":"11540961771","pt":1719500500629,"mc":[{"id":"1.230180123","rc":[{"atl":[[3.8,7.74]],"id":40028187}],"con":true,"img":false}]}
{"op":"mcm","clk":"11540961795","pt":1719500501190,"mc":[{"id":"1.230180123","rc":[{"atb":[[3,0],[2.68,19.08]],"id":47703807},{"atl":[[9,12],[7.8,0]],"id":47703807},{"atb":[[1.92,0]],"id":57697855}],"con":true,"img":false}]}
{"op":"mcm","clk":"11540961799","pt":1719500501204,"mc":[{"id":"1.230180123","rc":[{"atb":[[3.1,0]],"id":40028187}],"con":true,"img":false}]}
{"op":"mcm","clk":"11540961811","pt":1719500501214,"mc":[{"id":"1.230180123","rc":[{"atb":[[2.88,2]],"id":40028187}],"con":true,"img":false}]}
{"op":"mcm","clk":"11540961825","pt":1719500501302,"mc":[{"id":"1.230180123","rc":[{"atb":[[2.86,0]],"id":40028187}],"con":true,"img":false}]}
{"op":"mcm","clk":"11540961982","pt":1719500503311,"mc":[{"id":"1.230180123","rc":[{"atb":[[2.88,0]],"id":40028187}],"con":true,"img":false}]}
{"op":"mcm","clk":"11540961989","pt":1719500503411,"mc":[{"id":"1.230180123","rc":[{"atb":[[2.46,2]],"id":40028187},{"atb":[[3.6,12.4]],"id":47703807}],"con":true,"img":false}]}
{"op":"mcm","clk":"11540961997","pt":1719500503512,"mc":[{"id":"1.230180123","rc":[{"atb":[[2.86,5.11],[2.38,0],[2.34,5]],"id":40028187},{"atb":[[3.5,0]],"id":47703807}],"con":true,"img":false}]}
{"op":"mcm","clk":"11540962022","pt":1719500503824,"mc":[{"id":"1.230180123","rc":[{"atb":[[3.55,0]],"id":47703807},{"atl":[[6.8,6.34]],"id":47703807},{"atb":[[2.1,9.57]],"id":70396461}],"con":true,"img":false}]}
{"op":"mcm","clk":"11540962041","pt":1719500504034,"mc":[{"id":"1.230180123","rc":[{"atb":[[2.88,2.57],[2.86,0]],"id":40028187},{"atb":[[3.6,0],[3.65,3]],"id":47703807},{"atl":[[6.8,2.62]],"id":47703807},{"atb":[[2.12,4]],"id":70396461}],"con":true,"img":false}]}
{"op":"mcm","clk":"11540962047","pt":1719500504134,"mc":[{"id":"1.230180123","rc":[{"atb":[[3.7,3.84]],"id":47703807},{"atb":[[2.12,10.82]],"id":70396461}],"con":true,"img":false}]}
{"op":"mcm","clk":"11540962056","pt":1719500504239,"mc":[{"id":"1.230180123","rc":[{"atl":[[3.75,0.84]],"id":40028187},{"atl":[[7,3.72]],"id":47703807}],"con":true,"img":false}]}
{"op":"mcm","clk":"11540962066","pt":1719500504337,"mc":[{"id":"1.230180123","rc":[{"atl":[[3.8,11.2]],"id":40028187},{"atb":[[2.1,2]],"id":70396461}],"con":true,"img":false}]}
{"op":"mcm","clk":"11540962127","pt":1719500505223,"mc":[{"id":"1.230180123","rc":[{"atb":[[3.7,12.72]],"id":47703807}],"con":true,"img":false}]}
{"op":"mcm","clk":"11540962136","pt":1719500505326,"mc":[{"id":"1.230180123","rc":[{"atl":[[6.6,9.6]],"id":47703807}],"con":true,"img":false}]}
{"op":"mcm","clk":"11540962190","pt":1719500506043,"mc":[{"id":"1.230180123","rc":[{"atb":[[2.46,0]],"id":40028187}],"con":true,"img":false}]}
{"op":"mcm","clk":"11540962198","pt":1719500506096,"mc":[{"id":"1.230180123","rc":[{"atb":[[2.9,2]],"id":40028187}],"con":true,"img":false}]}
{"op":"mcm","clk":"11540962228","pt":1719500506406,"mc":[{"id":"1.230180123","rc":[{"atb":[[2.1,0]],"id":70396461}],"con":true,"img":false}]}
{"op":"mcm","clk":"11540962239","pt":1719500506510,"mc":[{"id":"1.230180123","rc":[{"atb":[[2.14,2]],"id":70396461}],"con":true,"img":false}]}
{"op":"mcm","clk":"11540962255","pt":1719500506715,"mc":[{"id":"1.230180123","rc":[{"atb":[[2.9,8],[2.68,0]],"id":47703807},{"atl":[[9,0],[8.2,10]],"id":47703807}],"con":true,"img":false}]}
{"op":"mcm","clk":"11540962269","pt":1719500506921,"mc":[{"id":"1.230180123","rc":[{"atb":[[2.9,13.52]],"id":40028187}],"con":true,"img":false}]}
{"op":"mcm","clk":"11540962441","pt":1719500509141,"mc":[{"id":"1.230180123","rc":[{"atb":[[2.14,7.42]],"id":70396461}],"con":true,"img":false}]}
{"op":"mcm","clk":"11540962449","pt":1719500509245,"mc":[{"id":"1.230180123","rc":[{"atb":[[2.12,4]],"id":70396461}],"con":true,"img":false}]}
{"op":"mcm","clk":"11540962479","pt":1719500509615,"mc":[{"id":"1.230180123","rc":[{"atb":[[2.88,0]],"id":40028187},{"atb":[[3.65,0]],"id":47703807},{"atb":[[2.12,0]],"id":70396461}],"con":true,"img":false}]}
{"op":"mcm","clk":"11540962491","pt":1719500509819,"mc":[{"id":"1.230180123","rc":[{"atb":[[2.92,3.1]],"id":40028187},{"atb":[[3.75,3]],"id":47703807},{"atb":[[2.16,2.51]],"id":70396461}],"con":true,"img":false}]}
{"op":"mcm","clk":"11540962503","pt":1719500510024,"mc":[{"id":"1.230180123","rc":[{"atb":[[2.12,4.56]],"id":70396461}],"con":true,"img":false}]}
{"op":"mcm","clk":"11540962509","pt":1719500510125,"mc":[{"id":"1.230180123","rc":[{"atb":[[2.9,2]],"id":40028187},{"atb":[[3.7,11.21]],"id":47703807}],"con":true,"img":false}]}
{"op":"mcm","clk":"11540962517","pt":1719500510229,"mc":[{"id":"1.230180123","rc":[{"atb":[[3.7,3.84]],"id":47703807}],"con":true,"img":false}]}
{"op":"mcm","clk":"11540962523","pt":1719500510339,"mc":[{"id":"1.230180123","rc":[{"atb":[[3.75,10.37]],"id":47703807}],"con":true,"img":false}]}
{"op":"mcm","clk":"11540962530","pt":1719500510436,"mc":[{"id":"1.230180123","rc":[{"atb":[[2.16,24.71]],"id":70396461},{"atl":[[2.92,12.68]],"id":70396461}],"con":true,"img":false}]}
{"op":"mcm","clk":"11540962534","pt":1719500510547,"mc":[{"id":"1.230180123","rc":[{"atl":[[2.9,13.93]],"id":70396461}],"con":true,"img":false}]}
{"op":"mcm","clk":"11540962544","pt":1719500510643,"mc":[{"id":"1.230180123","rc":[{"atl":[[2.94,1.77]],"id":70396461}],"con":true,"img":false}]}
{"op":"mcm","clk":"11540962557","pt":1719500510850,"mc":[{"id":"1.230180123","rc":[{"atb":[[2.9,0]],"id":40028187}],"con":true,"img":false}]}
{"op":"mcm","clk":"11540962564","pt":1719500510905,"mc":[{"id":"1.230180123","rc":[{"atb":[[2.94,2]],"id":40028187},{"atl":[[2.92,0.84]],"id":70396461}],"con":true,"img":false}]}
{"op":"mcm","clk":"11540962582","pt":1719500511212,"mc":[{"id":"1.230180123","rc":[{"atl":[[2.88,0.84]],"id":70396461}],"con":true,"img":false}]}
{"op":"mcm","clk":"11540962589","pt":1719500511324,"mc":[{"id":"1.230180123","rc":[{"atb":[[2.14,5.42]],"id":70396461}],"con":true,"img":false}]}
{"op":"mcm","clk":"11540962600","pt":1719500511420,"mc":[{"id":"1.230180123","rc":[{"atb":[[2.18,2]],"id":70396461}],"con":true,"img":false}]}
{"op":"mcm","clk":"11540962608","pt":1719500511530,"mc":[{"id":"1.230180123","rc":[{"atl":[[3.75,4.3]],"id":40028187},{"atl":[[5.4,0.84]],"id":43318163}],"con":true,"img":false}]}
{"op":"mcm","clk":"11540962619","pt":1719500511630,"mc":[{"id":"1.230180123","rc":[{"atl":[[3.8,7.74]],"id":40028187},{"atl":[[5.4,7]],"id":43318163}],"con":true,"img":false}]}
{"op":"mcm","clk":"11540962628","pt":1719500511735,"mc":[{"id":"1.230180123","rc":[{"atl":[[6.6,2.5]],"id":43318163},{"atb":[[2.16,24.01]],"id":70396461}],"con":true,"img":false}]}
{"op":"mcm","clk":"11540962633","pt":1719500511839,"mc":[{"id":"1.230180123","rc":[{"atb":[[2.94,13.85]],"id":40028187},{"atl":[[6.6,6.94]],"id":43318163},{"atl":[[2.88,13.6]],"id":70396461}],"con":true,"img":false}]}
{"op":"mcm","clk":"11540962641","pt":1719500511941,"mc":[{"id":"1.230180123","rc":[{"atb":[[2.16,2.51]],"id":70396461},{"atb":[[1.92,5.36]],"id":57697855}],"con":true,"img":false}]}
{"op":"mcm","clk":"11540962647","pt":1719500512044,"mc":[{"id":"1.230180123","rc":[{"atl":[[6.4,14.02],[6.8,0]],"id":43318163},{"atb":[[2.18,23.5]],"id":70396461},{"atl":[[2.86,1.9]],"id":70396461}],"con":true,"img":false}]}
{"op":"mcm","clk":"11540962655","pt":1719500512148,"mc":[{"id":"1.230180123","rc":[{"atl":[[2.92,0]],"id":70396461}],"con":true,"img":false}]}
{"op":"mcm","clk":"11540962698","pt":1719500512616,"mc":[{"id":"1.230180123","rc":[{"atl":[[2.88,11.88]],"id":70396461}],"con":true,"img":false}]}
{"op":"mcm","clk":"11540962722","pt":1719500512926,"mc":[{"id":"1.230180123","rc":[{"atb":[[3.8,5.67]],"id":47703807}],"con":true,"img":false}]}
{"op":"mcm","clk":"11540962730","pt":1719500513034,"mc":[{"id":"1.230180123","rc":[{"atl":[[2.88,0.84]],"id":70396461}],"con":true,"img":false}]}
{"op":"mcm","clk":"11540962737","pt":1719500513131,"mc":[{"id":"1.230180123","rc":[{"atb":[[3.7,0]],"id":47703807},{"atl":[[2.86,12.94]],"id":70396461}],"con":true,"img":false}]}
{"op":"mcm","clk":"11540962753","pt":1719500513341,"mc":[{"id":"1.230180123","rc":[{"atb":[[3.75,3]],"id":47703807},{"atb":[[1.98,0],[2.24,2.11]],"id":70396461}],"con":true,"img":false}]}
{"op":"mcm","clk":"11540962766","pt":1719500513548,"mc":[{"id":"1.230180123","rc":[{"atb":[[2.12,0]],"id":70396461}],"con":true,"img":false}]}
{"op":"mcm","clk":"11540962867","pt":1719500514836,"mc":[{"id":"1.230180123","rc":[{"atb":[[2.18,18.31]],"id":70396461}],"con":true,"img":false}]}
{"op":"mcm","clk":"11540962883","pt":1719500515042,"mc":[{"id":"1.230180123","rc":[{"atb":[[3.8,13.37]],"id":47703807},{"atb":[[2.18,2]],"id":70396461}],"con":true,"img":false}]}
{"op":"mcm","clk":"11540962888","pt":1719500515146,"mc":[{"id":"1.230180123","rc":[{"atb":[[2.24,18.42]],"id":70396461}],"con":true,"img":false}]}
{"op":"mcm","clk":"11540962910","pt":1719500515404,"mc":[{"id":"1.230180123","rc":[{"atb":[[2.92,0]],"id":40028187},{"atb":[[3.75,0]],"id":47703807},{"atb":[[2.18,0],[2.16,0]],"id":70396461}],"con":true,"img":false}]}
{"op":"mcm","clk":"11540962920","pt":1719500515513,"mc":[{"id":"1.230180123","rc":[{"atb":[[2.96,2.3],[2.94,2]],"id":40028187},{"atb":[[3.85,2.6],[3.8,5.67]],"id":47703807},{"atb":[[2.24,2.11],[2.26,2]],"id":70396461}],"con":true,"img":false}]}
{"op":"mcm","clk":"11540962927","pt":1719500515611,"mc":[{"id":"1.230180123","rc":[{"atb":[[3.85,7.36]],"id":47703807}],"con":true,"img":false}]}
{"op":"mcm","clk":"11540962940","pt":1719500515816,"mc":[{"id":"1.230180123","rc":[{"atb":[[3.8,0]],"id":47703807}],"con":true,"img":false}]}
{"op":"mcm","clk":"11540963001","pt":1719500516540,"mc":[{"id":"1.230180123","rc":[{"atb":[[2.96,13.85]],"id":40028187},{"atb":[[2.26,20.8]],"id":70396461}],"con":true,"img":false}]}
{"op":"mcm","clk":"11540963080","pt":1719500517717,"mc":[{"id":"1.230180123","rc":[{"atb":[[2.94,0]],"id":40028187}],"con":true,"img":false}]}
{"op":"mcm","clk":"11540963085","pt":1719500517828,"mc":[{"id":"1.230180123","rc":[{"atb":[[1.02,2]],"id":40028187}],"con":true,"img":false}]}
{"op":"mcm","clk":"11540963133","pt":1719500518741,"mc":[{"id":"1.230180123","rc":[{"atl":[[2.84,0.84]],"id":70396461}],"con":true,"img":false}]}
{"op":"mcm","clk":"11540963138","pt":1719500518845,"mc":[{"id":"1.230180123","rc":[{"atb":[[2.96,2.3]],"id":40028187}],"con":true,"img":false}]}
{"op":"mcm","clk":"11540963197","pt":1719500519825,"mc":[{"id":"1.230180123","rc":[{"atl":[[2.84,6.5]],"id":70396461}],"con":true,"img":false}]}
{"op":"mcm","clk":"11540963205","pt":1719500519930,"mc":[{"id":"1.230180123","rc":[{"atl":[[2.82,1.97]],"id":70396461}],"con":true,"img":false}]}
{"op":"mcm","clk":"11540963216","pt":1719500520032,"mc":[{"id":"1.230180123","rc":[{"atl":[[2.86,1.9],[2.9,1.83]],"id":70396461}],"con":true,"img":false}]}
{"op":"mcm","clk":"11540963221","pt":1719500520136,"mc":[{"id":"1.230180123","rc":[{"atl":[[2.88,0]],"id":70396461}],"con":true,"img":false}]}
{"op":"mcm","clk":"11540963274","pt":1719500520861,"mc":[{"id":"1.230180123","rc":[{"atl":[[4.1,8.62],[4.2,3.64]],"id":40028187},{"atb":[[2.54,15],[2.44,0]],"id":43318163},{"atb":[[2.9,0],[3.05,10]],"id":47703807},{"atl":[[8.2,0],[7.8,6]],"id":47703807},{"atl":[[3.35,3.23],[3.25,11.4]],"id":67487132},{"atl":[[2.88,3.94],[2.96,0]],"id":70396461},{"atb":[[1.92,0]],"id":57697855},{"atl":[[3.35,0],[3.25,7.98]],"id":57697855}],"con":true,"img":false}]}
{"op":"mcm","clk":"11540963293","pt":1719500521020,"mc":[{"id":"1.230180123","rc":[{"atl":[[2.82,14.58]],"id":70396461}],"con":true,"img":false}]}
{"op":"mcm","clk":"11540963310","pt":1719500521226,"mc":[{"id":"1.230180123","rc":[{"atb":[[2.96,0]],"id":40028187}],"con":true,"img":false}]}
{"op":"mcm","clk":"11540963317","pt":1719500521333,"mc":[{"id":"1.230180123","rc":[{"atb":[[2.88,5.11],[2.46,3]],"id":40028187}],"con":true,"img":false}]}
{"op":"mcm","clk":"11540963329","pt":1719500521432,"mc":[{"id":"1.230180123","rc":[{"atl":[[3.75,0.84]],"id":40028187}],"con":true,"img":false}]}
{"op":"mcm","clk":"11540963348","pt":1719500521637,"mc":[{"id":"1.230180123","rc":[{"atl":[[3.8,11.86]],"id":40028187}],"con":true,"img":false}]}
{"op":"mcm","clk":"11540963373","pt":1719500521952,"mc":[{"id":"1.230180123","rc":[{"atl":[[7.2,0],[7.6,1]],"id":43318163},{"atb":[[1.55,0]],"id":67487132},{"atb":[[1.55,0]],"id":57697855}],"con":true,"img":false}]}
{"op":"mcm","clk":"11540963385","pt":1719500522153,"mc":[{"id":"1.230180123","rc":[{"atb":[[2.88,0]],"id":40028187}],"con":true,"img":false}]}
{"op":"mcm","clk":"11540963390","pt":1719500522257,"mc":[{"id":"1.230180123","rc":[{"atb":[[2.34,0],[2.4,5.5],[2.86,3.46]],"id":40028187}],"con":true,"img":false}]}
{"op":"mcm","clk":"11540963443","pt":1719500522932,"mc":[{"id":"1.230180123","rc":[{"atb":[[1.02,0]],"id":40028187}],"con":true,"img":false}]}
{"op":"mcm","clk":"11540963451","pt":1719500523034,"mc":[{"id":"1.230180123","rc":[{"atb":[[2.88,2]],"id":40028187}],"con":true,"img":false}]}
{"op":"mcm","clk":"11540963467","pt":1719500523239,"mc":[{"id":"1.230180123","rc":[{"atb":[[2.88,6.95]],"id":40028187},{"atb":[[3.15,24.83]],"id":43318163},{"atl":[[5.4,8.55]],"id":43318163},{"atb":[[3.85,12.69]],"id":47703807},{"atl":[[2.98,17.79]],"id":67487132},{"atb":[[2.26,25.71]],"id":70396461}],"con":true,"img":false}]}
{"op":"mcm","clk":"11540963477","pt":1719500523346,"mc":[{"id":"1.230180123","rc":[{"atl":[[6,17.12]],"id":43318163},{"atl":[[2.96,13.13]],"id":67487132}],"con":true,"img":false}]}
{"op":"mcm","clk":"11540963487","pt":1719500523446,"mc":[{"id":"1.230180123","rc":[{"atl":[[6.4,0]],"id":43318163},{"atl":[[2.98,10.56]],"id":67487132}],"con":true,"img":false}]}
{"op":"mcm","clk":"11540963497","pt":1719500523554,"mc":[{"id":"1.230180123","rc":[{"atl":[[2.94,1.77]],"id":67487132}],"con":true,"img":false}]}
{"op":"mcm","clk":"11540963509","pt":1719500523653,"mc":[{"id":"1.230180123","rc":[{"atl":[[3,19.99]],"id":67487132}],"con":true,"img":false}]}
{"op":"mcm","clk":"11540963550","pt":1719500524017,"mc":[{"id":"1.230180123","rc":[{"atl":[[3.8,4.12]],"id":40028187}],"con":true,"img":false}]}
{"op":"mcm","clk":"11540963561","pt":1719500524123,"mc":[{"id":"1.230180123","rc":[{"atb":[[2.88,18.6]],"id":40028187},{"atb":[[2.12,2.11]],"id":67487132}],"con":true,"img":false}]}
{"op":"mcm","clk":"11540963570","pt":1719500524224,"mc":[{"id":"1.230180123","rc":[{"atl":[[2.92,0.84]],"id":67487132}],"con":true,"img":false}]}
{"op":"mcm","clk":"11540963628","pt":1719500525045,"mc":[{"id":"1.230180123","rc":[{"atl":[[7.6,0]],"id":43318163},{"atl":[[8.8,5]],"id":47703807}],"con":true,"img":false}]}
{"op":"mcm","clk":"11540963647","pt":1719500525251,"mc":[{"id":"1.230180123","rc":[{"atb":[[2.1,5.11]],"id":67487132}],"con":true,"img":false}]}
{"op":"mcm","clk":"11540963692","pt":1719500525720,"mc":[{"id":"1.230180123","rc":[{"atl":[[2.96,16.28]],"id":67487132}],"con":true,"img":false}]}
{"op":"mcm","clk":"11540963701","pt":1719500525827,"mc":[{"id":"1.230180123","rc":[{"atb":[[2.14,0]],"id":70396461},{"atl":[[2.88,0],[2.86,22.99]],"id":70396461}],"con":true,"img":false}]}
{"op":"mcm","clk":"11540963730","pt":1719500526134,"mc":[{"id":"1.230180123","rc":[{"atl":[[2.8,0.84]],"id":70396461}],"con":true,"img":false}]}
{"op":"mcm","clk":"11540963796","pt":1719500526961,"mc":[{"id":"1.230180123","rc":[{"atb":[[2.46,0]],"id":40028187}],"con":true,"img":false}]}
{"op":"mcm","clk":"11540963811","pt":1719500527171,"mc":[{"id":"1.230180123","rc":[{"atb":[[2.9,3]],"id":40028187}],"con":true,"img":false}]}
{"op":"mcm","clk":"11540963831","pt":1719500527327,"mc":[{"id":"1.230180123","rc":[{"atb":[[1.92,5.36]],"id":57697855}],"con":true,"img":false}]}
{"op":"mcm","clk":"11540963879","pt":1719500527951,"mc":[{"id":"1.230180123","rc":[{"atb":[[2.88,16.6]],"id":40028187}],"con":true,"img":false}]}
{"op":"mcm","clk":"11540963885","pt":1719500528057,"mc":[{"id":"1.230180123","rc":[{"atb":[[2.92,2],[2.88,15.97]],"id":40028187},{"atl":[[2.98,1.71]],"id":67487132}],"con":true,"img":false}]}
{"op":"mcm","clk":"11540963903","pt":1719500528265,"mc":[{"id":"1.230180123","rc":[{"atb":[[2.88,4.95]],"id":40028187},{"atl":[[2.96,25.03]],"id":67487132}],"con":true,"img":false}]}
{"op":"mcm","clk":"11540963915","pt":1719500528317,"mc":[{"id":"1.230180123","rc":[{"atb":[[2.9,14.02]],"id":40028187}],"con":true,"img":false}]}
{"op":"mcm","clk":"11540963959","pt":1719500528841,"mc":[{"id":"1.230180123","rc":[{"atb":[[2.9,13.78]],"id":40028187}],"con":true,"img":false}]}
{"op":"mcm","clk":"11540963967","pt":1719500528939,"mc":[{"id":"1.230180123","rc":[{"atb":[[2.9,3]],"id":40028187},{"atl":[[2.8,7.6]],"id":70396461}],"con":true,"img":false}]}
{"op":"mcm","clk":"11540963973","pt":1719500529044,"mc":[{"id":"1.230180123","rc":[{"atb":[[2.92,12.78]],"id":40028187},{"atl":[[2.84,0.84]],"id":70396461}],"con":true,"img":false}]}
{"op":"mcm","clk":"11540963989","pt":1719500529249,"mc":[{"id":"1.230180123","rc":[{"atl":[[2.84,0]],"id":70396461}],"con":true,"img":false}]}
{"op":"mcm","clk":"11540964035","pt":1719500529867,"mc":[{"id":"1.230180123","rc":[{"atl":[[2.82,1.97]],"id":70396461}],"con":true,"img":false}]}
{"op":"mcm","clk":"11540964085","pt":1719500530446,"mc":[{"id":"1.230180123","rc":[{"atb":[[3.1,0],[2.98,5],[2.88,0],[2.9,10],[3.15,27.33],[2.96,0]],"id":43318163}],"con":true,"img":false}]}
{"op":"mcm","clk":"11540964094","pt":1719500530554,"mc":[{"id":"1.230180123","rc":[{"atl":[[2.8,19.18]],"id":70396461}],"con":true,"img":false}]}
{"op":"mcm","clk":"11540964124","pt":1719500530858,"mc":[{"id":"1.230180123","rc":[{"atl":[[6,0],[5.9,17.12]],"id":43318163}],"con":true,"img":false}]}
{"op":"mcm","clk":"11540964170","pt":1719500531323,"mc":[{"id":"1.230180123","rc":[{"atl":[[5.6,0]],"id":40028187},{"atb":[[3.15,17.93]],"id":43318163},{"atl":[[3.95,0]],"id":67487132},{"atl":[[3.35,0]],"id":70396461},{"atl":[[4,0]],"id":57697855}],"con":true,"img":false}]}
{"op":"mcm","clk":"11540964192","pt":1719500531528,"mc":[{"id":"1.230180123","rc":[{"atl":[[5.4,0]],"id":40028187},{"atl":[[3.25,0]],"id":70396461},{"atl":[[3.9,0]],"id":57697855}],"con":true,"img":false}]}
{"op":"mcm","clk":"11540964264","pt":1719500532360,"mc":[{"id":"1.230180123","rc":[{"atl":[[2.94,7.19]],"id":67487132}],"con":true,"img":false}]}
{"op":"mcm","clk":"11540964271","pt":1719500532460,"mc":[{"id":"1.230180123","rc":[{"atl":[[2.96,12.74]],"id":67487132}],"con":true,"img":false}]}
{"op":"mcm","clk":"11540964292","pt":1719500532666,"mc":[{"id":"1.230180123","rc":[{"atb":[[2.96,3.38]],"id":43318163}],"con":true,"img":false}]}
{"op":"mcm","clk":"11540964304","pt":1719500532770,"mc":[{"id":"1.230180123","rc":[{"atb":[[2.9,0]],"id":40028187}],"con":true,"img":false}]}
{"op":"mcm","clk":"11540964322","pt":1719500532926,"mc":[{"id":"1.230180123","rc":[{"atb":[[2.94,3.84]],"id":40028187}],"con":true,"img":false}]}
{"op":"mcm","clk":"11540964329","pt":1719500533032,"mc":[{"id":"1.230180123","rc":[{"atb":[[2.88,0]],"id":40028187}],"con":true,"img":false}]}
{"op":"mcm","clk":"11540964344","pt":1719500533237,"mc":[{"id":"1.230180123","rc":[{"atb":[[2.92,17.41]],"id":40028187},{"atl":[[2.96,9.59]],"id":67487132}],"con":true,"img":false}]}
{"op":"mcm","clk":"11540964366","pt":1719500533451,"mc":[{"id":"1.230180123","rc":[{"atb":[[2.96,0]],"id":43318163}],"con":true,"img":false}]}
{"op":"mcm","clk":"11540964397","pt":1719500533755,"mc":[{"id":"1.230180123","rc":[{"atb":[[2.92,6.63]],"id":40028187}],"con":true,"img":false}]}
{"op":"mcm","clk":"11540964430","pt":1719500534167,"mc":[{"id":"1.230180123","rc":[{"atb":[[3.2,5],[3.1,0],[3.4,2.5],[3.3,0]],"id":47703807}],"con":true,"img":false}]}
{"op":"mcm","clk":"11540964462","pt":1719500534631,"mc":[{"id":"1.230180123","rc":[{"atb":[[2.94,15.46]],"id":40028187}],"con":true,"img":false}]}
{"op":"mcm","clk":"11540964536","pt":1719500535865,"mc":[{"id":"1.230180123","rc":[{"atl":[[6,20],[5.9,0]],"id":43318163},{"atl":[[3.2,7.98],[3.25,0]],"id":57697855}],"con":true,"img":false}]}
{"op":"mcm","clk":"11540964632","pt":1719500537078,"mc":[{"id":"1.230180123","rc":[{"atb":[[2.92,4.63]],"id":40028187}],"con":true,"img":false}]}
{"op":"mcm","clk":"11540964641","pt":1719500537131,"mc":[{"id":"1.230180123","rc":[{"atb":[[2.96,2]],"id":40028187}],"con":true,"img":false}]}
{"op":"mcm","clk":"11540964699","pt":1719500537857,"mc":[{"id":"1.230180123","rc":[{"atb":[[2.92,0]],"id":40028187},{"atl":[[2.96,0.84]],"id":67487132}],"con":true,"img":false}]}
{"op":"mcm","clk":"11540964713","pt":1719500538071,"mc":[{"id":"1.230180123","rc":[{"atb":[[2.94,19.21]],"id":40028187},{"atl":[[2.94,15.83]],"id":67487132}],"con":true,"img":false}]}
{"op":"mcm","clk":"11540964729","pt":1719500538272,"mc":[{"id":"1.230180123","rc":[{"atb":[[2.94,8.31]],"id":40028187}],"con":true,"img":false}]}
{"op":"mcm","clk":"11540964737","pt":1719500538380,"mc":[{"id":"1.230180123","rc":[{"atb":[[2.96,12.9]],"id":40028187}],"con":true,"img":false}]}
{"op":"mcm","clk":"11540964745","pt":1719500538483,"mc":[{"id":"1.230180123","rc":[{"atb":[[2.94,4.47]],"id":40028187}],"con":true,"img":false}]}
{"op":"mcm","clk":"11540964762","pt":1719500538636,"mc":[{"id":"1.230180123","rc":[{"atb":[[2.96,16.8]],"id":40028187}],"con":true,"img":false}]}
{"op":"mcm","clk":"11540964987","pt":1719500541235,"mc":[{"id":"1.230180123","rc":[{"atl":[[2.92,6.26]],"id":67487132}],"con":true,"img":false}]}
{"op":"mcm","clk":"11540964997","pt":1719500541339,"mc":[{"id":"1.230180123","rc":[{"atl":[[2.9,1.83]],"id":67487132}],"con":true,"img":false}]}
{"op":"mcm","clk":"11540965002","pt":1719500541444,"mc":[{"id":"1.230180123","rc":[{"atl":[[2.94,10.41]],"id":67487132}],"con":true,"img":false}]}
{"op":"mcm","clk":"11540965016","pt":1719500541652,"mc":[{"id":"1.230180123","rc":[{"atl":[[2.88,0.84],[2.96,0]],"id":67487132}],"con":true,"img":false}]}
{"op":"mcm","clk":"11540965075","pt":1719500542476,"mc":[{"id":"1.230180123","rc":[{"atb":[[2.12,21.02]],"id":67487132},{"atl":[[2.88,12.4]],"id":67487132}],"con":true,"img":false}]}
{"op":"mcm","clk":"11540965092","pt":1719500542639,"mc":[{"id":"1.230180123","rc":[{"atb":[[2.94,0]],"id":40028187},{"atl":[[2.94,1.77],[2.86,1.9]],"id":67487132}],"con":true,"img":false}]}
{"op":"mcm","clk":"11540965111","pt":1719500542839,"mc":[{"id":"1.230180123","rc":[{"atb":[[2.96,21.12]],"id":40028187},{"atl":[[2.92,14.79]],"id":67487132}],"con":true,"img":false}]}
{"op":"mcm","clk":"11540965135","pt":1719500543254,"mc":[{"id":"1.230180123","rc":[{"atb":[[2.96,17.22]],"id":40028187},{"atl":[[2.92,13.95]],"id":67487132}],"con":true,"img":false}]}
{"op":"mcm","clk":"11540965142","pt":1719500543356,"mc":[{"id":"1.230180123","rc":[{"atb":[[2.98,4]],"id":40028187}],"con":true,"img":false}]}
{"op":"mcm","clk":"11540965148","pt":1719500543459,"mc":[{"id":"1.230180123","rc":[{"atb":[[2.96,6.32]],"id":40028187},{"atl":[[2.88,12.08]],"id":67487132}],"con":true,"img":false}]}
{"op":"mcm","clk":"11540965153","pt":1719500543570,"mc":[{"id":"1.230180123","rc":[{"atl":[[2.92,17.18],[2.88,0.84]],"id":67487132}],"con":true,"img":false}]}
{"op":"mcm","clk":"11540965161","pt":1719500543668,"mc":[{"id":"1.230180123","rc":[{"atb":[[2.1,0]],"id":67487132},{"atl":[[2.86,13.14]],"id":67487132}],"con":true,"img":false}]}
{"op":"mcm","clk":"11540965169","pt":1719500543771,"mc":[{"id":"1.230180123","rc":[{"atl":[[2.92,13.95]],"id":67487132}],"con":true,"img":false}]}
{"op":"mcm","clk":"11540965222","pt":1719500544548,"mc":[{"id":"1.230180123","rc":[{"atb":[[2.98,15.6],[2.96,4.32]],"id":40028187}],"con":true,"img":false}]}
{"op":"mcm","clk":"11540965229","pt":1719500544652,"mc":[{"id":"1.230180123","rc":[{"atb":[[3,2]],"id":40028187}],"con":true,"img":false}]}
{"op":"mcm","clk":"11540965236","pt":1719500544757,"mc":[{"id":"1.230180123","rc":[{"atb":[[2.1,5.11]],"id":67487132}],"con":true,"img":false}]}
{"op":"mcm","clk":"11540965288","pt":1719500545384,"mc":[{"id":"1.230180123","rc":[{"atb":[[2.98,14.74]],"id":40028187}],"con":true,"img":false}]}
{"op":"mcm","clk":"11540965316","pt":1719500545681,"mc":[{"id":"1.230180123","rc":[{"atb":[[2.98,4]],"id":40028187}],"con":true,"img":false}]}
{"op":"mcm","clk":"11540965325","pt":1719500545795,"mc":[{"id":"1.230180123","rc":[{"atb":[[3,12.74]],"id":40028187},{"atl":[[5.1,0]],"id":40028187},{"atl":[[3.75,0]],"id":67487132},{"atl":[[3.15,0]],"id":70396461},{"atl":[[3.75,0]],"id":57697855}],"con":true,"img":false}]}
{"op":"mcm","clk":"11540965346","pt":1719500546044,"mc":[{"id":"1.230180123","rc":[{"atb":[[1.92,6.76]],"id":57697855}],"con":true,"img":false}]}
{"op":"mcm","clk":"11540965360","pt":1719500546250,"mc":[{"id":"1.230180123","rc":[{"atb":[[1.92,5.52]],"id":57697855}],"con":true,"img":false}]}
{"op":"mcm","clk":"11540965452","pt":1719500547491,"mc":[{"id":"1.230180123","rc":[{"atb":[[2.96,0]],"id":40028187},{"atl":[[2.92,5.42]],"id":67487132}],"con":true,"img":false}]}
{"op":"mcm","clk":"11540965472","pt":1719500547640,"mc":[{"id":"1.230180123","rc":[{"atb":[[3,16.77]],"id":40028187},{"atl":[[2.86,21.33]],"id":67487132}],"con":true,"img":false}]}
{"op":"mcm","clk":"11540965488","pt":1719500547851,"mc":[{"id":"1.230180123","rc":[{"atl":[[1000,7.04]],"id":67487132}],"con":true,"img":false}]}
{"op":"mcm","clk":"11540965497","pt":1719500547949,"mc":[{"id":"1.230180123","rc":[{"atb":[[2.96,3.38]],"id":43318163},{"atb":[[1.02,6.81]],"id":67487132},{"atl":[[1000,8.75]],"id":67487132}],"con":true,"img":false}]}
{"op":"mcm","clk":"11540965507","pt":1719500548052,"mc":[{"id":"1.230180123","rc":[{"atb":[[2.98,0]],"id":40028187},{"atl":[[6.8,0]],"id":47703807},{"atb":[[1.02,8.51]],"id":67487132},{"atl":[[1000,2.34]],"id":67487132}],"con":true,"img":false}]}
{"op":"mcm","clk":"11540965521","pt":1719500548258,"mc":[{"id":"1.230180123","rc":[{"atb":[[3.05,4]],"id":40028187},{"atb":[[1.02,0.77]],"id":67487132},{"atl":[[1000,0.31]],"id":67487132}],"con":true,"img":false}]}
{"op":"mcm","clk":"11540965529","pt":1719500548365,"mc":[{"id":"1.230180123","rc":[{"atl":[[2.84,0.4]],"id":67487132}],"con":true,"img":false}]}
{"op":"mcm","clk":"11540965539","pt":1719500548471,"mc":[{"id":"1.230180123","rc":[{"atb":[[1.02,0]],"id":67487132},{"atl":[[1000,0.23]],"id":67487132}],"con":true,"img":false}]}
{"op":"mcm","clk":"11540965547","pt":1719500548567,"mc":[{"id":"1.230180123","rc":[{"atb":[[2.96,0]],"id":43318163},{"atb":[[2.16,0.77]],"id":67487132},{"atl":[[2.84,0.48]],"id":67487132}],"con":true,"img":false}]}
{"op":"mcm","clk":"11540965555","pt":1719500548670,"mc":[{"id":"1.230180123","rc":[{"atb":[[3,6.03]],"id":40028187},{"atl":[[2.84,1.33]],"id":67487132}],"con":true,"img":false}]}
{"op":"mcm","clk":"11540965561","pt":1719500548773,"mc":[{"id":"1.230180123","rc":[{"atl":[[2.82,1.97]],"id":67487132}],"con":true,"img":false}]}
{"op":"mcm","clk":"11540965567","pt":1719500548880,"mc":[{"id":"1.230180123","rc":[{"atl":[[7.2,0]],"id":47703807}],"con":true,"img":false}]}
{"op":"mcm","clk":"11540965592","pt":1719500549184,"mc":[{"id":"1.230180123","rc":[{"atl":[[3,0]],"id":67487132}],"con":true,"img":false}]}
{"op":"mcm","clk":"11540965600","pt":1719500549286,"mc":[{"id":"1.230180123","rc":[{"atb":[[3,4.03]],"id":40028187},{"atb":[[2.1,0]],"id":67487132},{"atl":[[2.88,0]],"id":67487132}],"con":true,"img":false}]}
{"op":"mcm","clk":"11540965609","pt":1719500549394,"mc":[{"id":"1.230180123","rc":[{"atb":[[3.1,2]],"id":40028187}],"con":true,"img":false}]}
{"op":"mcm","clk":"11540965626","pt":1719500549545,"mc":[{"id":"1.230180123","rc":[{"atb":[[2.12,2.11]],"id":67487132},{"atl":[[2.86,10.09]],"id":67487132}],"con":true,"img":false}]}
{"op":"mcm","clk":"11540965652","pt":1719500549854,"mc":[{"id":"1.230180123","rc":[{"atb":[[3.05,16.56]],"id":40028187}],"con":true,"img":false}]}
{"op":"mcm","clk":"11540965659","pt":1719500549957,"mc":[{"id":"1.230180123","rc":[{"atl":[[2.82,5.04]],"id":67487132}],"con":true,"img":false}]}
{"op":"mcm","clk":"11540965666","pt":1719500550065,"mc":[{"id":"1.230180123","rc":[{"atl":[[2.92,0]],"id":67487132}],"con":true,"img":false}]}
{"op":"mcm","clk":"11540965677","pt":1719500550162,"mc":[{"id":"1.230180123","rc":[{"atb":[[3.05,16.35]],"id":40028187}],"con":true,"img":false}]}
{"op":"mcm","clk":"11540965694","pt":1719500550370,"mc":[{"id":"1.230180123","rc":[{"atb":[[3.05,4]],"id":40028187}],"con":true,"img":false}]}
{"op":"mcm","clk":"11540965702","pt":1719500550476,"mc":[{"id":"1.230180123","rc":[{"atb":[[3.1,14.35]],"id":40028187},{"atb":[[2.16,18.59]],"id":67487132},{"atl":[[2.82,18.74]],"id":67487132}],"con":true,"img":false}]}
{"op":"mcm","clk":"11540965747","pt":1719500551193,"mc":[{"id":"1.230180123","rc":[{"atb":[[2.14,7.25]],"id":67487132}],"con":true,"img":false}]}
{"op":"mcm","clk":"11540965754","pt":1719500551294,"mc":[{"id":"1.230180123","rc":[{"atb":[[2.18,2]],"id":67487132}],"con":true,"img":false}]}
{"op":"mcm","clk":"11540965763","pt":1719500551456,"mc":[{"id":"1.230180123","rc":[{"atl":[[7.8,0],[8.4,7.44]],"id":47703807},{"atb":[[2.14,0]],"id":67487132}],"con":true,"img":false}]}
{"op":"mcm","clk":"11540965793","pt":1719500551968,"mc":[{"id":"1.230180123","rc":[{"atl":[[2.78,1.69]],"id":70396461}],"con":true,"img":false}]}
{"op":"mcm","clk":"11540965802","pt":1719500552071,"mc":[{"id":"1.230180123","rc":[{"atl":[[2.78,5.15]],"id":70396461}],"con":true,"img":false}]}
{"op":"mcm","clk":"11540965807","pt":1719500552175,"mc":[{"id":"1.230180123","rc":[{"atl":[[2.8,12.42]],"id":70396461}],"con":true,"img":false}]}
{"op":"mcm","clk":"11540965814","pt":1719500552286,"mc":[{"id":"1.230180123","rc":[{"atb":[[3,0]],"id":40028187},{"atb":[[2.16,0.77]],"id":67487132},{"atl":[[2.86,1.9]],"id":67487132}],"con":true,"img":false}]}
{"op":"mcm","clk":"11540965832","pt":1719500552492,"mc":[{"id":"1.230180123","rc":[{"atb":[[3.1,17.69]],"id":40028187},{"spn":3.42,"spf":"NaN","id":40028187},{"spn":5.22,"spf":"NaN","id":47703807},{"atl":[[2.82,26.68]],"id":67487132},{"spn":2.5,"spf":"NaN","id":67487132},{"spn":2.52,"spf":"NaN","id":70396461}],"con":true,"img":false}]}
{"op":"mcm","clk":"11540965852","pt":1719500552700,"mc":[{"id":"1.230180123","rc":[{"atl":[[2.76,0.84]],"id":70396461}],"con":true,"img":false}]}
{"op":"mcm","clk":"11540965859","pt":1719500552798,"mc":[{"id":"1.230180123","rc":[{"atl":[[2.8,0.84]],"id":70396461}],"con":true,"img":false}]}
{"op":"mcm","clk":"11540965868","pt":1719500552851,"mc":[{"id":"1.230180123","rc":[{"atb":[[3.05,0]],"id":40028187},{"atl":[[7.6,0]],"id":47703807}],"con":true,"img":false}]}
{"op":"mcm","clk":"11540965875","pt":1719500552955,"mc":[{"id":"1.230180123","rc":[{"atb":[[3.15,3]],"id":40028187},{"atb":[[2.18,17.31]],"id":67487132}],"con":true,"img":false}]}
{"op":"mcm","clk":"11540965880","pt":1719500553056,"mc":[{"id":"1.230180123","rc":[{"atb":[[2.14,2]],"id":67487132}],"con":true,"img":false}]}
{"op":"mcm","clk":"11540965905","pt":1719500553473,"mc":[{"id":"1.230180123","rc":[{"atb":[[3.1,16.42]],"id":40028187}],"con":true,"img":false}]}
{"op":"mcm","clk":"11540965926","pt":1719500553677,"mc":[{"id":"1.230180123","rc":[{"atb":[[3.1,5.34]],"id":40028187}],"con":true,"img":false}]}
{"op":"mcm","clk":"11540965936","pt":1719500553784,"mc":[{"id":"1.230180123","rc":[{"atb":[[3.15,14.08]],"id":40028187},{"atl":[[2.76,14.86]],"id":70396461}],"con":true,"img":false}]}
{"op":"mcm","clk":"11540965964","pt":1719500554190,"mc":[{"id":"1.230180123","rc":[{"atl":[[2.8,0]],"id":70396461}],"con":true,"img":false}]}
{"op":"mcm","clk":"11540965971","pt":1719500554291,"mc":[{"id":"1.230180123","rc":[{"atb":[[2.14,0]],"id":67487132}],"con":true,"img":false}]}
{"op":"mcm","clk":"11540965975","pt":1719500554394,"mc":[{"id":"1.230180123","rc":[{"atb":[[2.2,2]],"id":67487132}],"con":true,"img":false}]}
{"op":"mcm","clk":"11540966008","pt":1719500554860,"mc":[{"id":"1.230180123","rc":[{"atb":[[3.1,3.34]],"id":40028187}],"con":true,"img":false}]}
{"op":"mcm","clk":"11540966014","pt":1719500554966,"mc":[{"id":"1.230180123","rc":[{"atb":[[3.2,2]],"id":40028187}],"con":true,"img":false}]}
{"op":"mcm","clk":"11540966028","pt":1719500555183,"mc":[{"id":"1.230180123","rc":[{"atb":[[3.15,3]],"id":40028187},{"atb":[[2.18,0]],"id":67487132}],"con":true,"img":false}]}
{"op":"mcm","clk":"11540966035","pt":1719500555275,"mc":[{"id":"1.230180123","rc":[{"atl":[[3.85,8.72]],"id":40028187}],"con":true,"img":false}]}
{"op":"mcm","clk":"11540966069","pt":1719500555682,"mc":[{"id":"1.230180123","rc":[{"atb":[[2.2,0]],"id":67487132}],"con":true,"img":false}]}
{"op":"mcm","clk":"11540966076","pt":1719500555786,"mc":[{"id":"1.230180123","rc":[{"atb":[[2.12,5.12],[2.14,2]],"id":67487132},{"atl":[[2.8,0.84]],"id":67487132}],"con":true,"img":false}]}
{"op":"mcm","clk":"11540966082","pt":1719500555888,"mc":[{"id":"1.230180123","rc":[{"atb":[[3.2,13.07]],"id":40028187},{"atb":[[2.16,18.38]],"id":67487132}],"con":true,"img":false}]}
{"op":"mcm","clk":"11540966137","pt":1719500556565,"mc":[{"id":"1.230180123","rc":[{"atb":[[2.14,0]],"id":67487132}],"con":true,"img":false}]}
{"op":"mcm","clk":"11540966144","pt":1719500556663,"mc":[{"id":"1.230180123","rc":[{"atb":[[2.54,0]],"id":43318163},{"atl":[[6,0]],"id":43318163},{"atl":[[8,0],[9.6,0],[8.8,0]],"id":47703807},{"atb":[[2.18,2]],"id":67487132}],"con":true,"img":false}]}
{"op":"mcm","clk":"11540966152","pt":1719500556766,"mc":[{"id":"1.230180123","rc":[{"atb":[[2.64,20]],"id":43318163},{"atl":[[5.9,17.12]],"id":43318163},{"atl":[[10.5,2.5],[12.5,5],[14.5,10]],"id":47703807}],"con":true,"img":false}]}
{"op":"mcm","clk":"11540966187","pt":1719500557183,"mc":[{"id":"1.230180123","rc":[{"atb":[[3.1,0]],"id":40028187}],"con":true,"img":false}]}
{"op":"mcm","clk":"11540966202","pt":1719500557388,"mc":[{"id":"1.230180123","rc":[{"atb":[[3.2,15.78]],"id":40028187}],"con":true,"img":false}]}
{"op":"mcm","clk":"11540966219","pt":1719500557601,"mc":[{"id":"1.230180123","rc":[{"atb":[[2.16,0.77]],"id":67487132}],"con":true,"img":false}]}
{"op":"mcm","clk":"11540966234","pt":1719500557808,"mc":[{"id":"1.230180123","rc":[{"atb":[[3.15,0]],"id":40028187}],"con":true,"img":false}]}
{"op":"mcm","clk":"11540966250","pt":1719500558016,"mc":[{"id":"1.230180123","rc":[{"atb":[[3.25,3.5]],"id":40028187}],"con":true,"img":false}]}
{"op":"mcm","clk":"11540966285","pt":1719500558376,"mc":[{"id":"1.230180123","rc":[{"atl":[[2.84,4.47]],"id":67487132}],"con":true,"img":false}]}
{"op":"mcm","clk":"11540966292","pt":1719500558475,"mc":[{"id":"1.230180123","rc":[{"atl":[[2.8,3.34]],"id":67487132}],"con":true,"img":false}]}
{"op":"mcm","clk":"11540966302","pt":1719500558578,"mc":[{"id":"1.230180123","rc":[{"atb":[[3.2,15.32]],"id":40028187},{"atl":[[2.82,23.61],[2.78,2.04]],"id":67487132}],"con":true,"img":false}]}
{"op":"mcm","clk":"11540966315","pt":1719500558784,"mc":[{"id":"1.230180123","rc":[{"atb":[[3.2,4.71]],"id":40028187},{"atb":[[2.18,0]],"id":67487132},{"atl":[[2.84,1.33]],"id":67487132}],"con":true,"img":false}]}
{"op":"mcm","clk":"11540966325","pt":1719500558891,"mc":[{"id":"1.230180123","rc":[{"atb":[[3.25,14.11]],"id":40028187},{"atb":[[2.14,2]],"id":67487132}],"con":true,"img":false}]}
{"op":"mcm","clk":"11540966332","pt":1719500558993,"mc":[{"id":"1.230180123","rc":[{"atb":[[2.18,20.45]],"id":67487132}],"con":true,"img":false}]}
{"op":"mcm","clk":"11540966349","pt":1719500559201,"mc":[{"id":"1.230180123","rc":[{"atl":[[2.84,0.48]],"id":67487132}],"con":true,"img":false}]}
{"op":"mcm","clk":"11540966359","pt":1719500559305,"mc":[{"id":"1.230180123","rc":[{"atb":[[3.2,2.71]],"id":40028187},{"atl":[[2.82,21.52]],"id":67487132}],"con":true,"img":false}]}
{"op":"mcm","clk":"11540966367","pt":1719500559362,"mc":[{"id":"1.230180123","rc":[{"atb":[[3.3,2]],"id":40028187}],"con":true,"img":false}]}
{"op":"mcm","clk":"11540966373","pt":1719500559465,"mc":[{"id":"1.230180123","rc":[{"atl":[[2.82,9.91]],"id":67487132}],"con":true,"img":false}]}
{"op":"mcm","clk":"11540966384","pt":1719500559565,"mc":[{"id":"1.230180123","rc":[{"atb":[[2.14,6.93]],"id":67487132},{"atl":[[2.78,13.65]],"id":67487132}],"con":true,"img":false}]}
{"op":"mcm","clk":"11540966430","pt":1719500560188,"mc":[{"id":"1.230180123","rc":[{"atb":[[2.14,5.66]],"id":67487132}],"con":true,"img":false}]}
{"op":"mcm","clk":"11540966462","pt":1719500560604,"mc":[{"id":"1.230180123","rc":[{"atl":[[2.74,5.74]],"id":70396461}],"con":true,"img":false}]}
{"op":"mcm","clk":"11540966471","pt":1719500560718,"mc":[{"id":"1.230180123","rc":[{"atl":[[3.35,0]],"id":67487132},{"atl":[[2.78,1.69]],"id":70396461},{"atl":[[3.6,0]],"id":57697855}],"con":true,"img":false}]}
{"op":"mcm","clk":"11540966485","pt":1719500560865,"mc":[{"id":"1.230180123","rc":[{"atl":[[2.76,0.84]],"id":70396461}],"con":true,"img":false}]}
{"op":"mcm","clk":"11540966516","pt":1719500561281,"mc":[{"id":"1.230180123","rc":[{"atl":[[2.72,0.85]],"id":70396461}],"con":true,"img":false}]}
{"op":"mcm","clk":"11540966540","pt":1719500561693,"mc":[{"id":"1.230180123","rc":[{"atb":[[1.79,0],[1.84,10]],"id":70396461}],"con":true,"img":false}]}
{"op":"mcm","clk":"11540966546","pt":1719500561802,"mc":[{"id":"1.230180123","rc":[{"atl":[[2.72,12.86]],"id":70396461}],"con":true,"img":false}]}
{"op":"mcm","clk":"11540966551","pt":1719500561901,"mc":[{"id":"1.230180123","rc":[{"atl":[[5.8,17.12],[5.9,0]],"id":43318163}],"con":true,"img":false}]}
{"op":"mcm","clk":"11540966561","pt":1719500562002,"mc":[{"id":"1.230180123","rc":[{"atb":[[3.2,0]],"id":40028187},{"atl":[[2.82,1.97]],"id":67487132}],"con":true,"img":false}]}
{"op":"mcm","clk":"11540966577","pt":1719500562209,"mc":[{"id":"1.230180123","rc":[{"atb":[[3.25,16.53]],"id":40028187},{"atb":[[2.14,3.66]],"id":67487132},{"atl":[[2.78,21.35]],"id":67487132},{"atl":[[2.76,0]],"id":70396461}],"con":true,"img":false}]}
{"op":"mcm","clk":"11540966583","pt":1719500562262,"mc":[{"id":"1.230180123","rc":[{"atb":[[2.12,3.01],[2.24,2.11],[2.2,2]],"id":67487132}],"con":true,"img":false}]}
{"op":"mcm","clk":"11540966598","pt":1719500562469,"mc":[{"id":"1.230180123","rc":[{"atb":[[3.25,13.03]],"id":40028187},{"atb":[[2.18,19.74]],"id":67487132}],"con":true,"img":false}]}
{"op":"mcm","clk":"11540966605","pt":1719500562575,"mc":[{"id":"1.230180123","rc":[{"atb":[[3.3,5]],"id":40028187},{"atb":[[2.18,0]],"id":67487132},{"atb":[[2.28,2.44]],"id":70396461}],"con":true,"img":false}]}
{"op":"mcm","clk":"11540966614","pt":1719500562672,"mc":[{"id":"1.230180123","rc":[{"atb":[[2.96,3.38]],"id":43318163},{"atb":[[2.2,21.74]],"id":67487132}],"con":true,"img":false}]}
{"op":"mcm","clk":"11540966627","pt":1719500562883,"mc":[{"id":"1.230180123","rc":[{"atb":[[2.14,0]],"id":67487132}],"con":true,"img":false}]}
{"op":"mcm","clk":"11540966646","pt":1719500563190,"mc":[{"id":"1.230180123","rc":[{"atb":[[3.2,3.61]],"id":43318163},{"atb":[[3.9,1.76]],"id":47703807},{"atl":[[2.76,0.84]],"id":67487132}],"con":true,"img":false}]}
{"op":"mcm","clk":"11540966650","pt":1719500563301,"mc":[{"id":"1.230180123","rc":[{"atb":[[2.96,0]],"id":43318163}],"con":true,"img":false}]}
{"op":"mcm","clk":"11540966656","pt":1719500563402,"mc":[{"id":"1.230180123","rc":[{"atb":[[3.2,15.23]],"id":43318163},{"atl":[[9.6,0],[8.6,2.5],[11,0],[8.8,0]],"id":43318163},{"atb":[[3.9,10.12]],"id":47703807},{"atb":[[2.26,6.91]],"id":70396461}],"con":true,"img":false}]}
{"op":"mcm","clk":"11540966662","pt":1719500563501,"mc":[{"id":"1.230180123","rc":[{"atb":[[3.15,11.35]],"id":43318163},{"atl":[[3.05,0]],"id":57697855}],"con":true,"img":false}]}
{"op":"mcm","clk":"11540966668","pt":1719500563609,"mc":[{"id":"1.230180123","rc":[{"atb":[[3.85,7.93]],"id":47703807}],"con":true,"img":false}]}
{"op":"mcm","clk":"11540966680","pt":1719500563761,"mc":[{"id":"1.230180123","rc":[{"atb":[[2.2,19.74]],"id":67487132},{"atl":[[3.15,3.75]],"id":57697855}],"con":true,"img":false}]}
{"op":"mcm","clk":"11540966686","pt":1719500563863,"mc":[{"id":"1.230180123","rc":[{"atb":[[2.26,2]],"id":67487132}],"con":true,"img":false}]}
{"op":"mcm","clk":"11540966718","pt":1719500564295,"mc":[{"id":"1.230180123","rc":[{"atb":[[3.2,26.79]],"id":43318163},{"atb":[[3.9,17.04]],"id":47703807},{"atb":[[2.28,18.79],[2.26,4.91]],"id":70396461}],"con":true,"img":false}]}
{"op":"mcm","clk":"11540966726","pt":1719500564403,"mc":[{"id":"1.230180123","rc":[{"atb":[[2.3,2]],"id":70396461},{"atl":[[3.15,0]],"id":57697855}],"con":true,"img":false}]}
{"op":"mcm","clk":"11540966746","pt":1719500564603,"mc":[{"id":"1.230180123","rc":[{"atl":[[2.78,0]],"id":70396461},{"atl":[[3.25,2.41]],"id":57697855}],"con":true,"img":false}]}
{"op":"mcm","clk":"11540966774","pt":1719500564967,"mc":[{"id":"1.230180123","rc":[{"atb":[[2.28,2.44]],"id":70396461}],"con":true,"img":false}]}
{"op":"mcm","clk":"11540966826","pt":1719500565689,"mc":[{"id":"1.230180123","rc":[{"atb":[[2.3,19.67]],"id":70396461}],"con":true,"img":false}]}
{"op":"mcm","clk":"11540966880","pt":1719500566419,"mc":[{"id":"1.230180123","rc":[{"atb":[[2.28,0]],"id":40028187},{"atb":[[2.46,0]],"id":43318163},{"atb":[[2.24,0]],"id":67487132},{"atb":[[2.24,0]],"id":70396461},{"atb":[[2.34,0]],"id":57697855}],"con":true,"img":false}]}
{"op":"mcm","clk":"11540966896","pt":1719500566619,"mc":[{"id":"1.230180123","rc":[{"atb":[[1.92,13.92],[1.97,11.28],[1.93,0]],"id":57697855}],"con":true,"img":false}]}
{"op":"mcm","clk":"11540966912","pt":1719500566776,"mc":[{"id":"1.230180123","rc":[{"atb":[[2.26,0]],"id":67487132},{"atb":[[1.96,0]],"id":57697855}],"con":true,"img":false}]}
{"op":"mcm","clk":"11540966918","pt":1719500566881,"mc":[{"id":"1.230180123","rc":[{"atb":[[2.86,0],[3.25,10.61]],"id":40028187},{"atl":[[3.95,8.24],[4.1,0]],"id":40028187},{"atb":[[3.15,5.55]],"id":43318163},{"atb":[[3.85,2.6]],"id":47703807},{"atb":[[2.22,2]],"id":67487132},{"atl":[[2.76,4.85]],"id":67487132},{"atb":[[2.26,0]],"id":70396461},{"atl":[[2.84,11.48],[2.86,1.9]],"id":70396461},{"atb":[[1.92,0],[1.98,11.28]],"id":57697855}],"con":true,"img":false}]}
{"op":"mcm","clk":"11540966935","pt":1719500567085,"mc":[{"id":"1.230180123","rc":[{"atb":[[3.3,7.14]],"id":40028187},{"atb":[[3.2,32.25]],"id":43318163},{"atl":[[5.6,17.12],[5.8,0]],"id":43318163},{"atb":[[3.9,22.17]],"id":47703807},{"atl":[[2.8,0.84]],"id":67487132},{"atb":[[2.3,23.98]],"id":70396461}],"con":true,"img":false}]}
{"op":"mcm","clk":"11540966943","pt":1719500567191,"mc":[{"id":"1.230180123","rc":[{"atl":[[2.8,0]],"id":67487132}],"con":true,"img":false}]}
{"op":"mcm","clk":"11540966950","pt":1719500567294,"mc":[{"id":"1.230180123","rc":[{"atb":[[3.3,4.14]],"id":40028187},{"atb":[[3.15,2.5]],"id":43318163},{"atl":[[6.6,2.49]],"id":43318163},{"atb":[[3.85,0]],"id":47703807},{"atl":[[2.78,9.74]],"id":67487132},{"atb":[[2.28,0]],"id":70396461},{"atb":[[1.97,7.08],[1.02,0]],"id":57697855}],"con":true,"img":false}]}
{"op":"mcm","clk":"11540966956","pt":1719500567398,"mc":[{"id":"1.230180123","rc":[{"atb":[[3.25,3.8]],"id":43318163},{"atb":[[3.95,3]],"id":47703807},{"atb":[[1.99,4],[1.98,13.28]],"id":57697855}],"con":true,"img":false}]}
{"op":"mcm","clk":"11540966966","pt":1719500567510,"mc":[{"id":"1.230180123","rc":[{"atb":[[3.3,3.35]],"id":43318163},{"atb":[[4,1.88]],"id":47703807},{"atb":[[2.26,4.33]],"id":70396461}],"con":true,"img":false}]}
{"op":"mcm","clk":"11540966996","pt":1719500567864,"mc":[{"id":"1.230180123","rc":[{"atb":[[2.26,0]],"id":70396461}],"con":true,"img":false}]}
{"op":"mcm","clk":"11540967009","pt":1719500568072,"mc":[{"id":"1.230180123","rc":[{"atb":[[3.2,30.75]],"id":43318163},{"atb":[[3.9,15.26]],"id":47703807},{"atb":[[2.3,6.31]],"id":70396461}],"con":true,"img":false}]}
{"op":"mcm","clk":"11540967023","pt":1719500568280,"mc":[{"id":"1.230180123","rc":[{"atb":[[3.3,2.14]],"id":40028187},{"atb":[[3.2,20.69]],"id":43318163}],"con":true,"img":false}]}
{"op":"mcm","clk":"11540967031","pt":1719500568390,"mc":[{"id":"1.230180123","rc":[{"atb":[[1.02,2]],"id":40028187},{"atb":[[3.3,13.41]],"id":43318163}],"con":true,"img":false}]}
{"op":"mcm","clk":"11540967037","pt":1719500568492,"mc":[{"id":"1.230180123","rc":[{"atl":[[5.4,14.44]],"id":43318163},{"atl":[[2.76,17.89]],"id":67487132}],"con":true,"img":false}]}
{"op":"mcm","clk":"11540967066","pt":1719500568798,"mc":[{"id":"1.230180123","rc":[{"atb":[[1.98,11.28]],"id":57697855}],"con":true,"img":false}]}
{"op":"mcm","clk":"11540967075","pt":1719500568899,"mc":[{"id":"1.230180123","rc":[{"atb":[[4,9.62]],"id":47703807},{"atl":[[2.7,8.06]],"id":70396461},{"atb":[[2,2]],"id":57697855}],"con":true,"img":false}]}
{"op":"mcm","clk":"11540967081","pt":1719500569027,"mc":[{"id":"1.230180123","rc":[{"atl":[[2.74,0]],"id":70396461}],"con":true,"img":false}]}
{"op":"mcm","clk":"11540967107","pt":1719500569284,"mc":[{"id":"1.230180123","rc":[{"atl":[[2.68,0.85]],"id":70396461}],"con":true,"img":false}]}
{"op":"mcm","clk":"11540967116","pt":1719500569392,"mc":[{"id":"1.230180123","rc":[{"atb":[[2.16,0]],"id":67487132},{"atl":[[2.84,0]],"id":67487132}],"con":true,"img":false}]}
{"op":"mcm","clk":"11540967153","pt":1719500569799,"mc":[{"id":"1.230180123","rc":[{"atl":[[3.25,0]],"id":57697855}],"con":true,"img":false}]}
{"op":"mcm","clk":"11540967277","pt":1719500571403,"mc":[{"id":"1.230180123","rc":[{"atb":[[3.05,0],[3.7,19.24]],"id":47703807},{"atl":[[2.72,15.89]],"id":70396461},{"atl":[[3.2,0],[3.15,6.09]],"id":57697855}],"con":true,"img":false}]}
{"op":"mcm","clk":"11540967300","pt":1719500571714,"mc":[{"id":"1.230180123","rc":[{"atb":[[3.35,20.9]],"id":43318163},{"atb":[[4.1,12.79]],"id":47703807}],"con":true,"img":false}]}
{"op":"mcm","clk":"11540967310","pt":1719500571811,"mc":[{"id":"1.230180123","rc":[{"atb":[[3.2,9.07],[3.4,3.11]],"id":43318163},{"atb":[[3.9,6.89],[4.2,1.96]],"id":47703807}],"con":true,"img":false}]}
{"op":"mcm","clk":"11540967318","pt":1719500571916,"mc":[{"id":"1.230180123","rc":[{"atb":[[1.99,0],[2.06,0],[2.12,0],[1.95,0]],"id":67487132}],"con":true,"img":false}]}
{"op":"mcm","clk":"11540967325","pt":1719500572022,"mc":[{"id":"1.230180123","rc":[{"atb":[[1.58,10],[1.62,5],[1.66,2.5]],"id":67487132}],"con":true,"img":false}]}
{"op":"mcm","clk":"11540967332","pt":1719500572071,"mc":[{"id":"1.230180123","rc":[{"atb":[[3.25,0],[3.2,3.61]],"id":43318163},{"atb":[[3.95,0],[3.9,1.76]],"id":47703807},{"atl":[[2.78,2.04]],"id":67487132},{"atb":[[2,6],[1.99,0],[1.98,0]],"id":57697855}],"con":true,"img":false}]}
{"op":"mcm","clk":"11540967338","pt":1719500572179,"mc":[{"id":"1.230180123","rc":[{"atb":[[3.4,6.81]],"id":43318163},{"atb":[[4.2,3.96]],"id":47703807},{"atb":[[1.94,2.2]],"id":70396461},{"atb":[[2,10.24]],"id":57697855}],"con":true,"img":false}]}
{"op":"mcm","clk":"11540967346","pt":1719500572278,"mc":[{"id":"1.230180123","rc":[{"atb":[[3.3,18.26]],"id":43318163},{"atb":[[4,14.37]],"id":47703807},{"atl":[[2.76,25.46]],"id":67487132},{"atl":[[3,15.12]],"id":57697855}],"con":true,"img":false}]}
{"op":"mcm","clk":"11540967351","pt":1719500572389,"mc":[{"id":"1.230180123","rc":[{"atb":[[3.3,18.09]],"id":43318163},{"atb":[[4,13.66]],"id":47703807},{"atl":[[2.98,10.72]],"id":57697855}],"con":true,"img":false}]}
{"op":"mcm","clk":"11540967362","pt":1719500572487,"mc":[{"id":"1.230180123","rc":[{"atl":[[2.78,5.28]],"id":67487132}],"con":true,"img":false}]}
{"op":"mcm","clk":"11540967369","pt":1719500572592,"mc":[{"id":"1.230180123","rc":[{"atb":[[3.3,8.2]],"id":43318163},{"atb":[[4,6.63]],"id":47703807},{"atl":[[3,11.56],[3.5,0]],"id":57697855}],"con":true,"img":false}]}
{"op":"mcm","clk":"11540967376","pt":1719500572696,"mc":[{"id":"1.230180123","rc":[{"atb":[[3.4,16.7]],"id":43318163},{"atb":[[4.2,10.99]],"id":47703807}],"con":true,"img":false}]}
{"op":"mcm","clk":"11540967394","pt":1719500572903,"mc":[{"id":"1.230180123","rc":[{"atl":[[2.78,2.04]],"id":67487132}],"con":true,"img":false}]}
{"op":"mcm","clk":"11540967551","pt":1719500574820,"mc":[{"id":"1.230180123","rc":[{"atb":[[2,23.23]],"id":57697855}],"con":true,"img":false}]}
{"op":"mcm","clk":"11540967562","pt":1719500574873,"mc":[{"id":"1.230180123","rc":[{"atb":[[1.97,0]],"id":57697855}],"con":true,"img":false}]}
{"op":"mcm","clk":"11540967587","pt":1719500575184,"mc":[{"id":"1.230180123","rc":[{"atb":[[2.18,4.77]],"id":67487132}],"con":true,"img":false}]}
{"op":"mcm","clk":"11540967598","pt":1719500575396,"mc":[{"id":"1.230180123","rc":[{"atb":[[2.18,0]],"id":67487132}],"con":true,"img":false}]}
{"op":"mcm","clk":"11540967610","pt":1719500575597,"mc":[{"id":"1.230180123","rc":[{"atb":[[2,21.23]],"id":57697855}],"con":true,"img":false}]}
{"op":"mcm","clk":"11540967616","pt":1719500575702,"mc":[{"id":"1.230180123","rc":[{"atb":[[1.02,2]],"id":57697855}],"con":true,"img":false}]}
{"op":"mcm","clk":"11540967690","pt":1719500576793,"mc":[{"id":"1.230180123","rc":[{"atb":[[1.89,3.25]],"id":57697855}],"con":true,"img":false}]}
{"op":"mcm","clk":"11540967697","pt":1719500576893,"mc":[{"id":"1.230180123","rc":[{"atl":[[4,14.47],[3.95,0]],"id":40028187}],"con":true,"img":false}]}
{"op":"mcm","clk":"11540967702","pt":1719500576999,"mc":[{"id":"1.230180123","rc":[{"atb":[[2,16.99]],"id":57697855}],"con":true,"img":false}]}
{"op":"mcm","clk":"11540967712","pt":1719500577207,"mc":[{"id":"1.230180123","rc":[{"atb":[[3.3,3.35]],"id":43318163},{"atb":[[4,1.88]],"id":47703807},{"atb":[[2,12.99],[2.02,4],[1.89,22.74]],"id":57697855},{"atl":[[3,1.68]],"id":57697855}],"con":true,"img":false}]}
{"op":"mcm","clk":"11540967719","pt":1719500577308,"mc":[{"id":"1.230180123","rc":[{"atb":[[2.02,8],[1.89,3.25]],"id":57697855}],"con":true,"img":false}]}
{"op":"mcm","clk":"11540967726","pt":1719500577412,"mc":[{"id":"1.230180123","rc":[{"atb":[[3.4,21]],"id":43318163},{"atb":[[4.2,15.05]],"id":47703807},{"atb":[[1.02,0]],"id":57697855},{"atl":[[2.98,20.51]],"id":57697855}],"con":true,"img":false}]}
{"op":"mcm","clk":"11540967736","pt":1719500577514,"mc":[{"id":"1.230180123","rc":[{"atb":[[2.02,10]],"id":57697855}],"con":true,"img":false}]}
{"op":"mcm","clk":"11540967745","pt":1719500577618,"mc":[{"id":"1.230180123","rc":[{"atb":[[1.89,0]],"id":57697855}],"con":true,"img":false}]}
{"op":"mcm","clk":"11540967769","pt":1719500577877,"mc":[{"id":"1.230180123","rc":[{"atl":[[2.72,12.86]],"id":70396461}],"con":true,"img":false}]}
{"op":"mcm","clk":"11540967803","pt":1719500578392,"mc":[{"id":"1.230180123","rc":[{"atb":[[3.2,0],[3.4,0]],"id":47703807}],"con":true,"img":false}]}
{"op":"mcm","clk":"11540967888","pt":1719500579808,"mc":[{"id":"1.230180123","rc":[{"atb":[[3.45,22.63]],"id":43318163},{"atb":[[4.3,12.79]],"id":47703807}],"con":true,"img":false}]}
{"op":"mcm","clk":"11540967893","pt":1719500579910,"mc":[{"id":"1.230180123","rc":[{"atb":[[3.35,0],[3.5,2.9]],"id":43318163},{"atb":[[4.4,2.06]],"id":47703807}],"con":true,"img":false}]}
{"op":"mcm","clk":"11540967900","pt":1719500580023,"mc":[{"id":"1.230180123","rc":[{"atb":[[4.1,0]],"id":47703807}],"con":true,"img":false}]}
{"op":"mcm","clk":"11540967912","pt":1719500580224,"mc":[{"id":"1.230180123","rc":[{"atl":[[4.3,10.32]],"id":40028187},{"atb":[[3.5,7.74],[3.45,32.33]],"id":43318163},{"atb":[[4.3,21.54],[4.4,6.43]],"id":47703807},{"atl":[[2.74,8.28],[2.78,18.61]],"id":67487132},{"atl":[[2.82,15.6]],"id":70396461},{"atb":[[2,27.93],[2.04,7.47]],"id":57697855}],"con":true,"img":false}]}
{"op":"mcm","clk":"11540967926","pt":1719500580377,"mc":[{"id":"1.230180123","rc":[{"atb":[[3.3,7.39]],"id":40028187},{"atb":[[3.4,19.65]],"id":43318163},{"atb":[[4.2,14.27]],"id":47703807},{"atl":[[2.72,24.08]],"id":67487132}],"con":true,"img":false}]}
{"op":"mcm","clk":"11540967934","pt":1719500580479,"mc":[{"id":"1.230180123","rc":[{"atb":[[3.25,21.11]],"id":40028187},{"atb":[[1.94,16.94]],"id":67487132},{"atl":[[2.76,21.45]],"id":67487132},{"atb":[[2.32,6.94],[1.94,16.1]],"id":70396461},{"atl":[[3,16.42],[2.96,7.36]],"id":57697855}],"con":true,"img":false}]}
{"op":"mcm","clk":"11540967943","pt":1719500580587,"mc":[{"id":"1.230180123","rc":[{"atb":[[3.4,11.11]],"id":43318163},{"atl":[[5.3,4.75],[5.5,9.51]],"id":43318163},{"atb":[[4.2,8.02]],"id":47703807},{"atl":[[2.7,8.28]],"id":67487132},{"atl":[[3.4,0],[2.94,19.82]],"id":57697855}],"con":true,"img":false}]}
{"op":"mcm","clk":"11540967950","pt":1719500580687,"mc":[{"id":"1.230180123","rc":[{"atb":[[3.5,16.28]],"id":43318163},{"atl":[[5.2,15.46]],"id":43318163},{"atb":[[4.4,12.68]],"id":47703807},{"atl":[[2.76,20.6],[2.7,9.13]],"id":67487132},{"atl":[[2.98,10.63]],"id":57697855}],"con":true,"img":false}]}
{"op":"mcm","clk":"11540967959","pt":1719500580788,"mc":[{"id":"1.230180123","rc":[{"atl":[[5.4,8.28]],"id":43318163}],"con":true,"img":false}]}
{"op":"mcm","clk":"11540967964","pt":1719500580892,"mc":[{"id":"1.230180123","rc":[{"atb":[[2.02,8]],"id":57697855}],"con":true,"img":false}]}
{"op":"mcm","clk":"11540967973","pt":1719500580995,"mc":[{"id":"1.230180123","rc":[{"atb":[[2.06,2]],"id":57697855}],"con":true,"img":false}]}
{"op":"mcm","clk":"11540967992","pt":1719500581208,"mc":[{"id":"1.230180123","rc":[{"atl":[[5.1,0.84],[5.4,6.59]],"id":43318163},{"atl":[[2.76,19.62]],"id":67487132},{"atl":[[2.92,0.84],[2.98,9.78]],"id":57697855}],"con":true,"img":false}]}
{"op":"mcm","clk":"11540968007","pt":1719500581413,"mc":[{"id":"1.230180123","rc":[{"atl":[[5.4,1.55]],"id":43318163},{"atl":[[2.76,7.56]],"id":67487132}],"con":true,"img":false}]}
{"op":"mcm","clk":"11540968016","pt":1719500581515,"mc":[{"id":"1.230180123","rc":[{"atl":[[5.2,20.5]],"id":43318163},{"atl":[[2.7,21.19]],"id":67487132},{"atb":[[2.32,23.93]],"id":70396461}],"con":true,"img":false}]}
{"op":"mcm","clk":"11540968039","pt":1719500581820,"mc":[{"id":"1.230180123","rc":[{"atb":[[3.4,7.41]],"id":43318163},{"atb":[[4.2,6.02]],"id":47703807},{"atb":[[1.94,13.9]],"id":70396461},{"atb":[[2.02,4]],"id":57697855}],"con":true,"img":false}]}
{"op":"mcm","clk":"11540968051","pt":1719500581983,"mc":[{"id":"1.230180123","rc":[{"atb":[[3.55,4]],"id":43318163},{"atb":[[4.5,2.4]],"id":47703807},{"atb":[[2.3,4.31]],"id":70396461},{"atb":[[2.06,5]],"id":57697855}],"con":true,"img":false}]}
{"op":"mcm","clk":"11540968060","pt":1719500582078,"mc":[{"id":"1.230180123","rc":[{"atb":[[3.6,2.71]],"id":43318163},{"atb":[[4.6,2.12]],"id":47703807},{"atb":[[1.02,27.94]],"id":70396461}],"con":true,"img":false}]}
{"op":"mcm","clk":"11540968085","pt":1719500582496,"mc":[{"id":"1.230180123","rc":[{"atl":[[3.25,7.92]],"id":67487132}],"con":true,"img":false}]}
{"op":"mcm","clk":"11540968100","pt":1719500582698,"mc":[{"id":"1.230180123","rc":[{"atb":[[3.5,7.74],[3.4,3.11]],"id":43318163},{"atl":[[5.4,0]],"id":43318163},{"atb":[[4.4,6.43],[4.2,1.96]],"id":47703807},{"atl":[[2.76,0]],"id":67487132},{"atb":[[2.3,0]],"id":70396461},{"atl":[[2.98,0]],"id":57697855}],"con":true,"img":false}]}
{"op":"mcm","clk":"11540968107","pt":1719500582805,"mc":[{"id":"1.230180123","rc":[{"atb":[[2.06,14.28]],"id":57697855}],"con":true,"img":false}]}
{"op":"mcm","clk":"11540968114","pt":1719500582905,"mc":[{"id":"1.230180123","rc":[{"atb":[[3.5,11.53]],"id":43318163},{"atl":[[5.2,21.71]],"id":43318163},{"atb":[[4.4,9.88]],"id":47703807},{"atl":[[2.7,28.35]],"id":67487132},{"atb":[[2.32,27.96]],"id":70396461},{"atb":[[2,14.94]],"id":57697855},{"atl":[[2.94,29.4]],"id":57697855}],"con":true,"img":false}]}
{"op":"mcm","clk":"11540968166","pt":1719500583528,"mc":[{"id":"1.230180123","rc":[{"atb":[[3.6,7.54],[3.55,13.66]],"id":43318163},{"atl":[[2.68,8.34]],"id":67487132},{"atb":[[2.32,10.97],[2.34,6.93]],"id":70396461},{"atb":[[2.08,7.5]],"id":57697855}],"con":true,"img":false}]}
{"op":"mcm","clk":"11540968176","pt":1719500583627,"mc":[{"id":"1.230180123","rc":[{"atb":[[3.6,16.41]],"id":43318163},{"atb":[[4.6,8.58]],"id":47703807}],"con":true,"img":false}]}
{"op":"mcm","clk":"11540968185","pt":1719500583685,"mc":[{"id":"1.230180123","rc":[{"atl":[[6.8,8.58]],"id":47703807}],"con":true,"img":false}]}
{"op":"mcm","clk":"11540968196","pt":1719500583784,"mc":[{"id":"1.230180123","rc":[{"atl":[[5.1,5.6],[5.2,31.22]],"id":43318163},{"atl":[[6.4,4.29]],"id":47703807}],"con":true,"img":false}]}
{"op":"mcm","clk":"11540968201","pt":1719500583891,"mc":[{"id":"1.230180123","rc":[{"atb":[[3.65,4.83]],"id":43318163},{"atl":[[6.2,3.22]],"id":47703807}],"con":true,"img":false}]}
{"op":"mcm","clk":"11540968218","pt":1719500584093,"mc":[{"id":"1.230180123","rc":[{"atl":[[6.6,0.84]],"id":47703807}],"con":true,"img":false}]}
{"op":"mcm","clk":"11540968223","pt":1719500584198,"mc":[{"id":"1.230180123","rc":[{"atl":[[6.2,7.51],[6,0.84],[6.6,0]],"id":47703807},{"atl":[[2.92,8.16],[2.94,44.05]],"id":57697855}],"con":true,"img":false}]}
{"op":"mcm","clk":"11540968232","pt":1719500584305,"mc":[{"id":"1.230180123","rc":[{"atb":[[3.6,16.19]],"id":43318163},{"atl":[[5.2,31.09]],"id":43318163},{"atl":[[2.7,16.29]],"id":67487132},{"atb":[[2.06,12.28]],"id":57697855}],"con":true,"img":false}]}
{"op":"mcm","clk":"11540968244","pt":1719500584404,"mc":[{"id":"1.230180123","rc":[{"atb":[[2.1,2]],"id":57697855}],"con":true,"img":false}]}
{"op":"mcm","clk":"11540968251","pt":1719500584513,"mc":[{"id":"1.230180123","rc":[{"atb":[[3.6,7.54]],"id":43318163},{"atl":[[5.2,26.18]],"id":43318163}],"con":true,"img":false}]}
{"op":"mcm","clk":"11540968265","pt":1719500584616,"mc":[{"id":"1.230180123","rc":[{"atb":[[3.65,13.48]],"id":43318163},{"atl":[[5.1,10.51]],"id":43318163},{"atb":[[2.34,26.24]],"id":70396461}],"con":true,"img":false}]}
{"op":"mcm","clk":"11540968274","pt":1719500584713,"mc":[{"id":"1.230180123","rc":[{"atl":[[2.72,27.33]],"id":67487132}],"con":true,"img":false}]}
{"op":"mcm","clk":"11540968283","pt":1719500584818,"mc":[{"id":"1.230180123","rc":[{"atl":[[2.72,24.08]],"id":67487132},{"atb":[[2.3,4.37]],"id":70396461}],"con":true,"img":false}]}
{"op":"mcm","clk":"11540968291","pt":1719500584922,"mc":[{"id":"1.230180123","rc":[{"atb":[[2.3,0]],"id":70396461}],"con":true,"img":false}]}
{"op":"mcm","clk":"11540968338","pt":1719500585388,"mc":[{"id":"1.230180123","rc":[{"atl":[[2.66,2.29],[2.68,22.6]],"id":67487132},{"atl":[[3.05,0]],"id":70396461},{"atl":[[2.9,1.83]],"id":57697855}],"con":true,"img":false}]}
{"op":"mcm","clk":"11540968349","pt":1719500585601,"mc":[{"id":"1.230180123","rc":[{"atb":[[2.22,0]],"id":67487132}],"con":true,"img":false}]}
{"op":"mcm","clk":"11540968357","pt":1719500585698,"mc":[{"id":"1.230180123","rc":[{"atb":[[1.02,2]],"id":67487132}],"con":true,"img":false}]}
{"op":"mcm","clk":"11540968365","pt":1719500585800,"mc":[{"id":"1.230180123","rc":[{"atb":[[3.7,4.82]],"id":43318163},{"atl":[[2.7,15.44]],"id":67487132},{"atb":[[2.36,6.93]],"id":70396461},{"atl":[[2.9,9.21]],"id":57697855}],"con":true,"img":false}]}
{"op":"mcm","clk":"11540968373","pt":1719500585908,"mc":[{"id":"1.230180123","rc":[{"atb":[[2.2,0]],"id":67487132},{"atl":[[2.68,21.83]],"id":67487132},{"atb":[[2.1,0]],"id":57697855},{"atl":[[3.3,0]],"id":57697855}],"con":true,"img":false}]}
{"op":"mcm","clk":"11540968380","pt":1719500586007,"mc":[{"id":"1.230180123","rc":[{"atb":[[1.91,30.42],[1.93,0],[1.95,21.69]],"id":67487132},{"atl":[[2.68,8.34]],"id":67487132},{"atb":[[1.02,2]],"id":57697855}],"con":true,"img":false}]}
{"op":"mcm","clk":"11540968390","pt":1719500586110,"mc":[{"id":"1.230180123","rc":[{"atl":[[2.66,15.78]],"id":67487132}],"con":true,"img":false}]}
{"op":"mcm","clk":"11540968430","pt":1719500586527,"mc":[{"id":"1.230180123","rc":[{"atb":[[3.55,9.66]],"id":43318163},{"atb":[[4.5,0]],"id":47703807},{"atb":[[1.02,0]],"id":67487132},{"atb":[[2.06,9.28]],"id":57697855}],"con":true,"img":false}]}
{"op":"mcm","clk":"11540968439","pt":1719500586625,"mc":[{"id":"1.230180123","rc":[{"atb":[[3.7,7.82]],"id":43318163},{"atb":[[4.7,3]],"id":47703807},{"atb":[[1.96,2]],"id":67487132},{"atl":[[2.64,8.39]],"id":67487132},{"atb":[[2.08,11.78]],"id":57697855}],"con":true,"img":false}]}
{"op":"mcm","clk":"11540968449","pt":1719500586733,"mc":[{"id":"1.230180123","rc":[{"atb":[[3.65,12.59]],"id":43318163},{"atl":[[2.62,2.38]],"id":67487132},{"atb":[[2.34,23.51]],"id":70396461}],"con":true,"img":false}]}
{"op":"mcm","clk":"11540968463","pt":1719500586888,"mc":[{"id":"1.230180123","rc":[{"atb":[[3.65,4.83]],"id":43318163},{"atb":[[2.34,6.93]],"id":70396461},{"atb":[[1.02,0]],"id":57697855}],"con":true,"img":false}]}
{"op":"mcm","clk":"11540968469","pt":1719500586988,"mc":[{"id":"1.230180123","rc":[{"atb":[[3.7,15.58]],"id":43318163},{"atb":[[2.36,23.51]],"id":70396461},{"atb":[[2.1,2]],"id":57697855}],"con":true,"img":false}]}
{"op":"mcm","clk":"11540968536","pt":1719500587609,"mc":[{"id":"1.230180123","rc":[{"atb":[[4.6,7.96]],"id":47703807},{"atl":[[2.66,15.51]],"id":67487132}],"con":true,"img":false}]}
{"op":"mcm","clk":"11540968544","pt":1719500587718,"mc":[{"id":"1.230180123","rc":[{"atb":[[3.5,7.74]],"id":43318163},{"atl":[[5.2,24.97]],"id":43318163},{"atb":[[4.8,8.85],[4.4,6.43],[4.6,2.12]],"id":47703807},{"atl":[[2.6,0.84],[2.66,2.29],[2.7,8.28]],"id":67487132},{"atb":[[2.32,6.94]],"id":70396461},{"atl":[[2.94,34.46]],"id":57697855}],"con":true,"img":false}]}
{"op":"mcm","clk":"11540968554","pt":1719500587816,"mc":[{"id":"1.230180123","rc":[{"atb":[[4.3,8.75],[4.7,8.84]],"id":47703807},{"atb":[[1.96,27.27]],"id":67487132},{"atl":[[2.62,24.02],[2.74,0]],"id":67487132},{"atb":[[2.38,6.91]],"id":70396461},{"atb":[[2.1,9.52]],"id":57697855}],"con":true,"img":false}]}
{"op":"mcm","clk":"11540968563","pt":1719500587918,"mc":[{"id":"1.230180123","rc":[{"atb":[[3.7,18.45]],"id":43318163},{"atl":[[5.1,11.54]],"id":43318163},{"atb":[[4.7,11.5]],"id":47703807},{"atl":[[2.6,9.27],[2.64,15.11]],"id":67487132},{"atb":[[2.36,26.98]],"id":70396461},{"atl":[[2.9,18.58]],"id":57697855}],"con":true,"img":false}]}
{"op":"mcm","clk":"11540968571","pt":1719500588027,"mc":[{"id":"1.230180123","rc":[{"atl":[[2.58,2.48],[2.7,0]],"id":67487132}],"con":true,"img":false}]}
{"op":"mcm","clk":"11540968594","pt":1719500588331,"mc":[{"id":"1.230180123","rc":[{"atl":[[2.58,27.49]],"id":67487132},{"atl":[[2.88,0.84]],"id":57697855}],"con":true,"img":false}]}
{"op":"mcm","clk":"11540968607","pt":1719500588487,"mc":[{"id":"1.230180123","rc":[{"atb":[[4.7,5.66]],"id":47703807},{"atl":[[2.72,0],[2.62,10.8]],"id":67487132},{"atl":[[2.88,14.95]],"id":57697855}],"con":true,"img":false}]}
{"op":"mcm","clk":"11540968615","pt":1719500588596,"mc":[{"id":"1.230180123","rc":[{"atl":[[5,14.32]],"id":43318163},{"atl":[[2.94,14.64]],"id":57697855}],"con":true,"img":false}]}
{"op":"mcm","clk":"11540968624","pt":1719500588694,"mc":[{"id":"1.230180123","rc":[{"atl":[[5.2,9.51]],"id":43318163},{"atl":[[2.86,1.9]],"id":57697855}],"con":true,"img":false}]}
{"op":"mcm","clk":"11540968666","pt":1719500589211,"mc":[{"id":"1.230180123","rc":[{"atl":[[5.1,6.63],[4.9,0.84]],"id":43318163},{"atl":[[2.92,7.32]],"id":57697855}],"con":true,"img":false}]}
{"op":"mcm","clk":"11540968672","pt":1719500589314,"mc":[{"id":"1.230180123","rc":[{"atb":[[3.5,2.9]],"id":43318163},{"atb":[[4.8,14.82]],"id":47703807},{"atl":[[2.56,8.43],[2.68,0]],"id":67487132},{"atl":[[2.86,12.65]],"id":57697855}],"con":true,"img":false}]}
{"op":"mcm","clk":"11540968682","pt":1719500589418,"mc":[{"id":"1.230180123","rc":[{"atl":[[3.8,0]],"id":40028187},{"atb":[[3.75,4.82]],"id":43318163},{"atl":[[5,0]],"id":43318163},{"atl":[[2.54,2.58]],"id":67487132}],"con":true,"img":false}]}
{"op":"mcm","clk":"11540968692","pt":1719500589521,"mc":[{"id":"1.230180123","rc":[{"atl":[[3.85,16.14]],"id":40028187},{"atl":[[5.1,13.87]],"id":43318163},{"atb":[[2.02,7.24]],"id":67487132}],"con":true,"img":false}]}
{"op":"mcm","clk":"11540968710","pt":1719500589726,"mc":[{"id":"1.230180123","rc":[{"atl":[[3.75,0]],"id":40028187},{"atl":[[4.9,0]],"id":43318163},{"atl":[[2.6,8.42]],"id":67487132}],"con":true,"img":false}]}
{"op":"mcm","clk":"11540968728","pt":1719500589985,"mc":[{"id":"1.230180123","rc":[{"atb":[[2.02,0]],"id":67487132}],"con":true,"img":false}]}
{"op":"mcm","clk":"11540968734","pt":1719500590089,"mc":[{"id":"1.230180123","rc":[{"atb":[[3.7,10.69]],"id":43318163},{"atb":[[1.96,25.27]],"id":67487132}],"con":true,"img":false}]}
{"op":"mcm","clk":"11540968740","pt":1719500590192,"mc":[{"id":"1.230180123","rc":[{"atl":[[3.8,0.84]],"id":40028187},{"atl":[[5.1,19.96]],"id":43318163},{"atb":[[2.04,2]],"id":67487132},{"atl":[[2.54,19.46]],"id":67487132}],"con":true,"img":false}]}
{"op":"mcm","clk":"11540968786","pt":1719500590713,"mc":[{"id":"1.230180123","rc":[{"atb":[[2.12,18.33]],"id":57697855}],"con":true,"img":false}]}
{"op":"mcm","clk":"11540968794","pt":1719500590811,"mc":[{"id":"1.230180123","rc":[{"atb":[[3.75,13.53]],"id":43318163},{"atb":[[2.06,0]],"id":57697855}],"con":true,"img":false}]}
{"op":"mcm","clk":"11540968807","pt":1719500591020,"mc":[{"id":"1.230180123","rc":[{"atb":[[4.2,5.89]],"id":47703807},{"atb":[[2.04,0]],"id":67487132}],"con":true,"img":false}]}
{"op":"mcm","clk":"11540968815","pt":1719500591122,"mc":[{"id":"1.230180123","rc":[{"atb":[[1.97,2]],"id":67487132}],"con":true,"img":false}]}
{"op":"mcm","clk":"11540968827","pt":1719500591327,"mc":[{"id":"1.230180123","rc":[{"atb":[[3.7,7.69]],"id":43318163},{"atb":[[4.7,2.66]],"id":47703807},{"atb":[[2.08,7.5]],"id":57697855}],"con":true,"img":false}]}
{"op":"mcm","clk":"11540968838","pt":1719500591485,"mc":[{"id":"1.230180123","rc":[{"atb":[[3.8,3.5]],"id":43318163},{"atb":[[4.9,3]],"id":47703807},{"atb":[[2.14,4.6]],"id":57697855}],"con":true,"img":false}]}
{"op":"mcm","clk":"11540968856","pt":1719500591691,"mc":[{"id":"1.230180123","rc":[{"atb":[[1.96,23.9]],"id":67487132}],"con":true,"img":false}]}
{"op":"mcm","clk":"11540968861","pt":1719500591802,"mc":[{"id":"1.230180123","rc":[{"atb":[[3.6,2.71],[3.8,8.29]],"id":43318163},{"atl":[[6,2.31]],"id":47703807},{"atb":[[1.96,0]],"id":67487132},{"atl":[[2.52,8.45]],"id":67487132},{"atl":[[2.88,29.7],[2.84,7.36]],"id":57697855}],"con":true,"img":false}]}
{"op":"mcm","clk":"11540968871","pt":1719500591899,"mc":[{"id":"1.230180123","rc":[{"atl":[[6.2,4.29]],"id":47703807},{"atb":[[1.97,25.9]],"id":67487132},{"atl":[[2.64,6.72]],"id":67487132}],"con":true,"img":false}]}
{"op":"mcm","clk":"11540968882","pt":1719500592007,"mc":[{"id":"1.230180123","rc":[{"atb":[[4.2,1.96]],"id":47703807},{"atl":[[2.5,2.69]],"id":67487132},{"atb":[[2.1,7.52]],"id":57697855},{"atl":[[2.82,1.97]],"id":57697855}],"con":true,"img":false}]}
{"op":"mcm","clk":"11540968892","pt":1719500592106,"mc":[{"id":"1.230180123","rc":[{"atb":[[1.02,2]],"id":57697855}],"con":true,"img":false}]}
{"op":"mcm","clk":"11540968906","pt":1719500592208,"mc":[{"id":"1.230180123","rc":[{"atl":[[2.88,28.85]],"id":57697855}],"con":true,"img":false}]}
{"op":"mcm","clk":"11540968934","pt":1719500592519,"mc":[{"id":"1.230180123","rc":[{"atb":[[3.75,13.07]],"id":43318163},{"atb":[[4.8,8.85]],"id":47703807},{"atl":[[2.54,2.58]],"id":67487132},{"atl":[[2.86,1.9]],"id":57697855}],"con":true,"img":false}]}
{"op":"mcm","clk":"11540968944","pt":1719500592620,"mc":[{"id":"1.230180123","rc":[{"atb":[[3.7,4.82]],"id":43318163},{"atb":[[4.7,0]],"id":47703807},{"atl":[[2.64,0]],"id":67487132},{"atb":[[2.36,23.51]],"id":70396461},{"atl":[[2.9,9.21]],"id":57697855}],"con":true,"img":false}]}
{"op":"mcm","clk":"11540968954","pt":1719500592725,"mc":[{"id":"1.230180123","rc":[{"atl":[[4,2.11],[4.1,28.94]],"id":40028187},{"atb":[[3.8,10.75],[3.75,4.82]],"id":43318163},{"atl":[[5.6,0],[5.7,19.02]],"id":43318163},{"atb":[[4.9,5.2]],"id":47703807},{"atb":[[1.91,0],[1.86,47.59]],"id":67487132},{"atl":[[2.52,14.19]],"id":67487132},{"atb":[[2.38,10.12]],"id":70396461},{"atb":[[2.04,22.51],[2.02,0]],"id":57697855},{"atl":[[2.84,16.39]],"id":57697855}],"con":true,"img":false}]}
{"op":"mcm","clk":"11540968961","pt":1719500592834,"mc":[{"id":"1.230180123","rc":[{"atb":[[3.8,19]],"id":43318163}],"con":true,"img":false}]}
{"op":"mcm","clk":"11540968980","pt":1719500593135,"mc":[{"id":"1.230180123","rc":[{"atb":[[3.85,4.78],[3.65,0]],"id":43318163},{"atl":[[2.5,11.14],[2.62,2.38]],"id":67487132},{"atl":[[2.82,9.34],[2.96,0]],"id":57697855}],"con":true,"img":false}]}
{"op":"mcm","clk":"11540968996","pt":1719500593394,"mc":[{"id":"1.230180123","rc":[{"atb":[[2.14,4.48]],"id":57697855},{"trd":[[2.14,0.22]],"ltp":2.14,"tv":0.22,"id":57697855}],"con":true,"img":false}]}
{"op":"mcm","clk":"11540969005","pt":1719500593497,"mc":[{"id":"1.230180123","rc":[{"atb":[[3.8,17.98]],"id":43318163},{"atl":[[2.58,32.79],[3.15,0]],"id":67487132}],"con":true,"img":false}]}
{"op":"mcm","clk":"11540969013","pt":1719500593601,"mc":[{"id":"1.230180123","rc":[{"atl":[[2.58,27.49]],"id":67487132}],"con":true,"img":false}]}
{"op":"mcm","clk":"11540969020","pt":1719500593705,"mc":[{"id":"1.230180123","rc":[{"atb":[[3.8,10.75]],"id":43318163}],"con":true,"img":false}]}
{"op":"mcm","clk":"11540969030","pt":1719500593808,"mc":[{"id":"1.230180123","rc":[{"atb":[[3.85,12.01]],"id":43318163},{"atb":[[1.98,23.36]],"id":67487132}],"con":true,"img":false}]}
{"op":"mcm","clk":"11540969034","pt":1719500593912,"mc":[{"id":"1.230180123","rc":[{"atb":[[4.9,10.61]],"id":47703807},{"atl":[[2.5,27.8]],"id":67487132},{"atl":[[2.82,22.09]],"id":57697855}],"con":true,"img":false}]}
{"op":"mcm","clk":"11540969044","pt":1719500594012,"mc":[{"id":"1.230180123","rc":[{"atb":[[1.95,0]],"id":67487132}],"con":true,"img":false}]}
{"op":"mcm","clk":"11540969095","pt":1719500594739,"mc":[{"id":"1.230180123","rc":[{"atl":[[2.48,0.84]],"id":67487132}],"con":true,"img":false}]}
{"op":"mcm","clk":"11540969102","pt":1719500594836,"mc":[{"id":"1.230180123","rc":[{"atb":[[1.97,23.9]],"id":67487132}],"con":true,"img":false}]}
{"op":"mcm","clk":"11540969111","pt":1719500594942,"mc":[{"id":"1.230180123","rc":[{"atb":[[1.99,2]],"id":67487132}],"con":true,"img":false}]}
{"op":"mcm","clk":"11540969139","pt":1719500595199,"mc":[{"id":"1.230180123","rc":[{"atl":[[2.8,0.84]],"id":57697855}],"con":true,"img":false}]}
{"op":"mcm","clk":"11540969163","pt":1719500595508,"mc":[{"id":"1.230180123","rc":[{"atb":[[4.9,17.05]],"id":47703807}],"con":true,"img":false}]}
{"op":"mcm","clk":"11540969179","pt":1719500595715,"mc":[{"id":"1.230180123","rc":[{"atb":[[4.8,0]],"id":47703807}],"con":true,"img":false}]}
