{"op":"mcm","clk":"11547086394","pt":1719432856317,"mc":[{"id":"1.230178174","marketDefinition":{"bspMarket":false,"turnInPlayEnabled":false,"persistenceEnabled":false,"marketBaseRate":5.0,"eventId":"33376048","eventTypeId":"4339","numberOfWinners":1,"bettingType":"ODDS","marketType":"FORECAST","marketTime":"2024-06-27T15:59:00.000Z","suspendTime":"2024-06-27T15:59:00.000Z","bspReconciled":false,"complete":true,"inPlay":false,"crossMatching":false,"runnersVoidable":false,"numberOfActiveRunners":20,"betDelay":0,"status":"OPEN","runners":[{"status":"ACTIVE","sortPriority":1,"id":52385882,"name":"1 - 2"},{"status":"ACTIVE","sortPriority":2,"id":52385883,"name":"1 - 3"},{"status":"ACTIVE","sortPriority":3,"id":52385884,"name":"1 - 4"},{"status":"ACTIVE","sortPriority":4,"id":52385885,"name":"1 - 5"},{"status":"ACTIVE","sortPriority":5,"id":52385889,"name":"2 - 1"},{"status":"ACTIVE","sortPriority":6,"id":52385890,"name":"2 - 3"},{"status":"ACTIVE","sortPriority":7,"id":52385891,"name":"2 - 4"},{"status":"ACTIVE","sortPriority":8,"id":52385892,"name":"2 - 5"},{"status":"ACTIVE","sortPriority":9,"id":52385896,"name":"3 - 1"},{"status":"ACTIVE","sortPriority":10,"id":52385897,"name":"3 - 2"},{"status":"ACTIVE","sortPriority":11,"id":52385898,"name":"3 - 4"},{"status":"ACTIVE","sortPriority":12,"id":52385899,"name":"3 - 5"},{"status":"ACTIVE","sortPriority":13,"id":52385903,"name":"4 - 1"},{"status":"ACTIVE","sortPriority":14,"id":52385904,"name":"4 - 2"},{"status":"ACTIVE","sortPriority":15,"id":52385905,"name":"4 - 3"},{"status":"ACTIVE","sortPriority":16,"id":52385906,"name":"4 - 5"},{"status":"ACTIVE","sortPriority":17,"id":52385910,"name":"5 - 1"},{"status":"ACTIVE","sortPriority":18,"id":52385911,"name":"5 - 2"},{"status":"ACTIVE","sortPriority":19,"id":52385912,"name":"5 - 3"},{"status":"ACTIVE","sortPriority":20,"id":52385913,"name":"5 - 4"}],"regulators":["MR_INT"],"venue":"Perry Barr","countryCode":"GB","discountAllowed":false,"timezone":"Europe/London","openDate":"2024-06-27T13:29:00.000Z","version":5994794132,"name":"Forecast","eventName":"Perry Barr (F/C) 27th Jun"},"rc":[],"con":true,"img":false}]}
{"op":"mcm","clk":"11547086548","pt":1719432858318,"mc":[{"id":"1.230178174","marketDefinition":{"bspMarket":false,"turnInPlayEnabled":false,"persistenceEnabled":false,"marketBaseRate":5.0,"eventId":"33376048","eventTypeId":"4339","numberOfWinners":1,"bettingType":"ODDS","marketType":"FORECAST","marketTime":"2024-06-27T15:59:00.000Z","suspendTime":"2024-06-27T15:59:00.000Z","bspReconciled":false,"complete":true,"inPlay":false,"crossMatching":false,"runnersVoidable":false,"numberOfActiveRunners":20,"betDelay":0,"status":"OPEN","runners":[{"status":"ACTIVE","sortPriority":1,"id":52385882,"name":"1 - 2"},{"status":"ACTIVE","sortPriority":2,"id":52385883,"name":"1 - 3"},{"status":"ACTIVE","sortPriority":3,"id":52385884,"name":"1 - 4"},{"status":"ACTIVE","sortPriority":4,"id":52385885,"name":"1 - 5"},{"status":"ACTIVE","sortPriority":5,"id":52385889,"name":"2 - 1"},{"status":"ACTIVE","sortPriority":6,"id":52385890,"name":"2 - 3"},{"status":"ACTIVE","sortPriority":7,"id":52385891,"name":"2 - 4"},{"status":"ACTIVE","sortPriority":8,"id":52385892,"name":"2 - 5"},{"status":"ACTIVE","sortPriority":9,"id":52385896,"name":"3 - 1"},{"status":"ACTIVE","sortPriority":10,"id":52385897,"name":"3 - 2"},{"status":"ACTIVE","sortPriority":11,"id":52385898,"name":"3 - 4"},{"status":"ACTIVE","sortPriority":12,"id":52385899,"name":"3 - 5"},{"status":"ACTIVE","sortPriority":13,"id":52385903,"name":"4 - 1"},{"status":"ACTIVE","sortPriority":14,"id":52385904,"name":"4 - 2"},{"status":"ACTIVE","sortPriority":15,"id":52385905,"name":"4 - 3"},{"status":"ACTIVE","sortPriority":16,"id":52385906,"name":"4 - 5"},{"status":"ACTIVE","sortPriority":17,"id":52385910,"name":"5 - 1"},{"status":"ACTIVE","sortPriority":18,"id":52385911,"name":"5 - 2"},{"status":"ACTIVE","sortPriority":19,"id":52385912,"name":"5 - 3"},{"status":"ACTIVE","sortPriority":20,"id":52385913,"name":"5 - 4"}],"regulators":["MR_INT"],"venue":"Perry Barr","countryCode":"GB","discountAllowed":true,"timezone":"Europe/London","openDate":"2024-06-27T13:29:00.000Z","version":5994794132,"name":"Forecast","eventName":"Perry Barr (F/C) 27th Jun"},"rc":[],"con":true,"img":false}]}
{"op":"mcm","clk":"11547146247","pt":1719434093598,"mc":[{"id":"1.230178174","rc":[{"atb":[[1.1,200]],"id":52385910},{"atb":[[1.1,200]],"id":52385911},{"atb":[[1.1,200]],"id":52385912},{"atb":[[1.1,200]],"id":52385913},{"atb":[[1.1,200]],"id":52385906},{"atb":[[1.1,200]],"id":52385889},{"atb":[[1.1,200]],"id":52385882},{"atb":[[1.1,200]],"id":52385883},{"atb":[[1.1,200]],"id":52385884},{"atb":[[1.1,200]],"id":52385885},{"atb":[[1.1,200]],"id":52385896},{"atb":[[1.1,200]],"id":52385897},{"atb":[[1.1,200]],"id":52385890},{"atb":[[1.1,200]],"id":52385891},{"atb":[[1.1,200]],"id":52385892},{"atb":[[1.1,200]],"id":52385903},{"atb":[[1.1,200]],"id":52385904},{"atb":[[1.1,200]],"id":52385905},{"atb":[[1.1,200]],"id":52385898},{"atb":[[1.1,200]],"id":52385899}],"con":true,"img":false}]}
{"op":"mcm","clk":"11547210704","pt":1719435446319,"mc":[{"id":"1.230178174","rc":[{"atb":[[1.01,32.96]],"id":52385910},{"atl":[[1000,0.84]],"id":52385910},{"atb":[[1.01,32.96]],"id":52385911},{"atl":[[1000,0.84]],"id":52385911},{"atb":[[1.02,16.48]],"id":52385912},{"atl":[[990,0.84]],"id":52385912},{"atb":[[1.03,10.99]],"id":52385913},{"atl":[[1000,0.84]],"id":52385913},{"atb":[[1.03,10.99]],"id":52385906},{"atl":[[1000,0.84]],"id":52385906},{"atb":[[1.03,10.99]],"id":52385889},{"atl":[[990,0.84]],"id":52385889},{"atb":[[1.01,32.96]],"id":52385882},{"atl":[[990,0.84]],"id":52385882},{"atb":[[1.02,16.48]],"id":52385883},{"atl":[[990,0.84]],"id":52385883},{"atb":[[1.01,32.96]],"id":52385884},{"atl":[[1000,0.84]],"id":52385884},{"atb":[[1.02,16.48]],"id":52385885},{"atl":[[990,0.84]],"id":52385885},{"atb":[[1.02,16.48]],"id":52385896},{"atl":[[990,0.84]],"id":52385896},{"atb":[[1.03,10.99]],"id":52385897},{"atl":[[990,0.84]],"id":52385897},{"atb":[[1.02,16.48]],"id":52385890},{"atl":[[1000,0.84]],"id":52385890},{"atb":[[1.01,32.96]],"id":52385891},{"atl":[[990,0.84]],"id":52385891},{"atb":[[1.03,10.99]],"id":52385892},{"atl":[[990,0.84]],"id":52385892},{"atb":[[1.03,10.99]],"id":52385903},{"atl":[[990,0.84]],"id":52385903},{"atb":[[1.03,10.99]],"id":52385904},{"atl":[[990,0.84]],"id":52385904},{"atb":[[1.02,16.48]],"id":52385905},{"atl":[[990,0.84]],"id":52385905},{"atb":[[1.02,16.48]],"id":52385898},{"atl":[[990,0.84]],"id":52385898},{"atb":[[1.03,10.99]],"id":52385899},{"atl":[[1000,0.84]],"id":52385899}],"con":true,"img":false}]}
{"op":"mcm","clk":"11547344089","pt":1719439052405,"mc":[{"id":"1.230178174","rc":[{"atb":[[1.01,32.96]],"id":52385910},{"atl":[[1000,0.17]],"id":52385910},{"atb":[[1.01,32.96]],"id":52385911},{"atl":[[1000,0.17]],"id":52385911},{"atb":[[1.02,16.48]],"id":52385912},{"atl":[[990,0.17]],"id":52385912},{"atb":[[1.03,10.99]],"id":52385913},{"atl":[[1000,0.17]],"id":52385913},{"atb":[[1.03,10.99]],"id":52385906},{"atl":[[1000,0.17]],"id":52385906},{"atb":[[1.03,10.99]],"id":52385889},{"atl":[[990,0.17]],"id":52385889},{"atb":[[1.01,32.96]],"id":52385882},{"atl":[[990,0.17]],"id":52385882},{"atb":[[1.02,16.48]],"id":52385883},{"atl":[[990,0.17]],"id":52385883},{"atb":[[1.01,32.96]],"id":52385884},{"atl":[[1000,0.17]],"id":52385884},{"atb":[[1.02,16.48]],"id":52385885},{"atl":[[990,0.17]],"id":52385885},{"atb":[[1.02,16.48]],"id":52385896},{"atl":[[990,0.17]],"id":52385896},{"atb":[[1.03,10.99]],"id":52385897},{"atl":[[990,0.17]],"id":52385897},{"atb":[[1.02,16.48]],"id":52385890},{"atl":[[1000,0.17]],"id":52385890},{"atb":[[1.01,32.96]],"id":52385891},{"atl":[[990,0.17]],"id":52385891},{"atb":[[1.03,10.99]],"id":52385892},{"atl":[[990,0.17]],"id":52385892},{"atb":[[1.03,10.99]],"id":52385903},{"atl":[[990,0.17]],"id":52385903},{"atb":[[1.03,10.99]],"id":52385904},{"atl":[[990,0.17]],"id":52385904},{"atb":[[1.02,16.48]],"id":52385905},{"atl":[[990,0.17]],"id":52385905},{"atb":[[1.02,16.48]],"id":52385898},{"atl":[[990,0.17]],"id":52385898},{"atb":[[1.03,10.99]],"id":52385899},{"atl":[[1000,0.17]],"id":52385899}],"con":true,"img":false}]}
{"op":"mcm","clk":"11547371015","pt":1719439682592,"mc":[{"id":"1.230178174","marketDefinition":{"bspMarket":false,"turnInPlayEnabled":false,"persistenceEnabled":false,"marketBaseRate":5.0,"eventId":"33376048","eventTypeId":"4339","numberOfWinners":1,"bettingType":"ODDS","marketType":"FORECAST","marketTime":"2024-06-27T15:59:00.000Z","suspendTime":"2024-06-27T15:59:00.000Z","bspReconciled":false,"complete":true,"inPlay":false,"crossMatching":false,"runnersVoidable":false,"numberOfActiveRunners":20,"betDelay":0,"status":"OPEN","runners":[{"status":"ACTIVE","sortPriority":1,"id":52385882,"name":"1 - 2"},{"status":"ACTIVE","sortPriority":2,"id":52385883,"name":"1 - 3"},{"status":"ACTIVE","sortPriority":3,"id":52385884,"name":"1 - 4"},{"status":"ACTIVE","sortPriority":4,"id":52385885,"name":"1 - 5"},{"status":"ACTIVE","sortPriority":5,"id":52385889,"name":"2 - 1"},{"status":"ACTIVE","sortPriority":6,"id":52385890,"name":"2 - 3"},{"status":"ACTIVE","sortPriority":7,"id":52385891,"name":"2 - 4"},{"status":"ACTIVE","sortPriority":8,"id":52385892,"name":"2 - 5"},{"status":"ACTIVE","sortPriority":9,"id":52385896,"name":"3 - 1"},{"status":"ACTIVE","sortPriority":10,"id":52385897,"name":"3 - 2"},{"status":"ACTIVE","sortPriority":11,"id":52385898,"name":"3 - 4"},{"status":"ACTIVE","sortPriority":12,"id":52385899,"name":"3 - 5"},{"status":"ACTIVE","sortPriority":13,"id":52385903,"name":"4 - 1"},{"status":"ACTIVE","sortPriority":14,"id":52385904,"name":"4 - 2"},{"status":"ACTIVE","sortPriority":15,"id":52385905,"name":"4 - 3"},{"status":"ACTIVE","sortPriority":16,"id":52385906,"name":"4 - 5"},{"status":"ACTIVE","sortPriority":17,"id":52385910,"name":"5 - 1"},{"status":"ACTIVE","sortPriority":18,"id":52385911,"name":"5 - 2"},{"status":"ACTIVE","sortPriority":19,"id":52385912,"name":"5 - 3"},{"status":"ACTIVE","sortPriority":20,"id":52385913,"name":"5 - 4"}],"regulators":["MR_INT"],"venue":"Perry Barr","countryCode":"GB","discountAllowed":true,"timezone":"Europe/London","openDate":"2024-06-27T13:29:00.000Z","version":5994794132,"name":"Forecast","eventName":"Perry Barr (F/C) 27th Jun"},"rc":[{"atb":[[1.01,32.96],[1.1,200]],"id":52385910},{"atl":[[1000,0.17]],"id":52385910},{"atb":[[1.01,32.96],[1.1,200]],"id":52385911},{"atl":[[1000,0.17]],"id":52385911},{"atb":[[1.02,16.48],[1.1,200]],"id":52385912},{"atl":[[990,0.17]],"id":52385912},{"atb":[[1.03,10.98],[1.1,200]],"id":52385913},{"atl":[[1000,0.17]],"id":52385913},{"atb":[[1.03,10.98],[1.1,200]],"id":52385906},{"atl":[[1000,0.17]],"id":52385906},{"atb":[[1.03,10.98],[1.1,200]],"id":52385889},{"atl":[[990,0.17]],"id":52385889},{"atb":[[1.01,32.96],[1.1,200]],"id":52385882},{"atl":[[990,0.17]],"id":52385882},{"atb":[[1.02,16.48],[1.1,200]],"id":52385883},{"atl":[[990,0.17]],"id":52385883},{"atb":[[1.01,32.96],[1.1,200]],"id":52385884},{"atl":[[1000,0.17]],"id":52385884},{"atb":[[1.02,16.48],[1.1,200]],"id":52385885},{"atl":[[990,0.17]],"id":52385885},{"atb":[[1.02,16.48],[1.1,200]],"id":52385896},{"atl":[[990,0.17]],"id":52385896},{"atb":[[1.03,10.98],[1.1,200]],"id":52385897},{"atl":[[990,0.17]],"id":52385897},{"atb":[[1.02,16.48],[1.1,200]],"id":52385890},{"atl":[[1000,0.17]],"id":52385890},{"atb":[[1.01,32.96],[1.1,200]],"id":52385891},{"atl":[[990,0.17]],"id":52385891},{"atb":[[1.03,10.98],[1.1,200]],"id":52385892},{"atl":[[990,0.17]],"id":52385892},{"atb":[[1.03,10.98],[1.1,200]],"id":52385903},{"atl":[[990,0.17]],"id":52385903},{"atb":[[1.03,10.98],[1.1,200]],"id":52385904},{"atl":[[990,0.17]],"id":52385904},{"atb":[[1.02,16.48],[1.1,200]],"id":52385905},{"atl":[[990,0.17]],"id":52385905},{"atb":[[1.02,16.48],[1.1,200]],"id":52385898},{"atl":[[990,0.17]],"id":52385898},{"atb":[[1.03,10.98],[1.1,200]],"id":52385899},{"atl":[[1000,0.17]],"id":52385899}],"con":true,"img":true}]}
{"op":"mcm","clk":"11547659683","pt":1719445082619,"mc":[{"id":"1.230178174","marketDefinition":{"bspMarket":false,"turnInPlayEnabled":false,"persistenceEnabled":false,"marketBaseRate":5.0,"eventId":"33376048","eventTypeId":"4339","numberOfWinners":1,"bettingType":"ODDS","marketType":"FORECAST","marketTime":"2024-06-27T15:59:00.000Z","suspendTime":"2024-06-27T15:59:00.000Z","bspReconciled":false,"complete":true,"inPlay":false,"crossMatching":false,"runnersVoidable":false,"numberOfActiveRunners":20,"betDelay":0,"status":"OPEN","runners":[{"status":"ACTIVE","sortPriority":1,"id":52385882,"name":"1 - 2"},{"status":"ACTIVE","sortPriority":2,"id":52385883,"name":"1 - 3"},{"status":"ACTIVE","sortPriority":3,"id":52385884,"name":"1 - 4"},{"status":"ACTIVE","sortPriority":4,"id":52385885,"name":"1 - 5"},{"status":"ACTIVE","sortPriority":5,"id":52385889,"name":"2 - 1"},{"status":"ACTIVE","sortPriority":6,"id":52385890,"name":"2 - 3"},{"status":"ACTIVE","sortPriority":7,"id":52385891,"name":"2 - 4"},{"status":"ACTIVE","sortPriority":8,"id":52385892,"name":"2 - 5"},{"status":"ACTIVE","sortPriority":9,"id":52385896,"name":"3 - 1"},{"status":"ACTIVE","sortPriority":10,"id":52385897,"name":"3 - 2"},{"status":"ACTIVE","sortPriority":11,"id":52385898,"name":"3 - 4"},{"status":"ACTIVE","sortPriority":12,"id":52385899,"name":"3 - 5"},{"status":"ACTIVE","sortPriority":13,"id":52385903,"name":"4 - 1"},{"status":"ACTIVE","sortPriority":14,"id":52385904,"name":"4 - 2"},{"status":"ACTIVE","sortPriority":15,"id":52385905,"name":"4 - 3"},{"status":"ACTIVE","sortPriority":16,"id":52385906,"name":"4 - 5"},{"status":"ACTIVE","sortPriority":17,"id":52385910,"name":"5 - 1"},{"status":"ACTIVE","sortPriority":18,"id":52385911,"name":"5 - 2"},{"status":"ACTIVE","sortPriority":19,"id":52385912,"name":"5 - 3"},{"status":"ACTIVE","sortPriority":20,"id":52385913,"name":"5 - 4"}],"regulators":["MR_INT"],"venue":"Perry Barr","countryCode":"GB","discountAllowed":true,"timezone":"Europe/London","openDate":"2024-06-27T13:29:00.000Z","version":5994794132,"name":"Forecast","eventName":"Perry Barr (F/C) 27th Jun"},"rc":[{"atb":[[1.01,32.96],[1.1,200]],"id":52385910},{"atl":[[1000,0.17]],"id":52385910},{"atb":[[1.01,32.96],[1.1,200]],"id":52385911},{"atl":[[1000,0.17]],"id":52385911},{"atb":[[1.02,16.48],[1.1,200]],"id":52385912},{"atl":[[990,0.17]],"id":52385912},{"atb":[[1.03,10.99],[1.1,200]],"id":52385913},{"atl":[[1000,0.17]],"id":52385913},{"atb":[[1.03,10.99],[1.1,200]],"id":52385906},{"atl":[[1000,0.17]],"id":52385906},{"atb":[[1.03,10.99],[1.1,200]],"id":52385889},{"atl":[[990,0.17]],"id":52385889},{"atb":[[1.01,32.96],[1.1,200]],"id":52385882},{"atl":[[990,0.17]],"id":52385882},{"atb":[[1.02,16.48],[1.1,200]],"id":52385883},{"atl":[[990,0.17]],"id":52385883},{"atb":[[1.01,32.96],[1.1,200]],"id":52385884},{"atl":[[1000,0.17]],"id":52385884},{"atb":[[1.02,16.48],[1.1,200]],"id":52385885},{"atl":[[990,0.17]],"id":52385885},{"atb":[[1.02,16.48],[1.1,200]],"id":52385896},{"atl":[[990,0.17]],"id":52385896},{"atb":[[1.03,10.99],[1.1,200]],"id":52385897},{"atl":[[990,0.17]],"id":52385897},{"atb":[[1.02,16.48],[1.1,200]],"id":52385890},{"atl":[[1000,0.17]],"id":52385890},{"atb":[[1.01,32.96],[1.1,200]],"id":52385891},{"atl":[[990,0.17]],"id":52385891},{"atb":[[1.03,10.99],[1.1,200]],"id":52385892},{"atl":[[990,0.17]],"id":52385892},{"atb":[[1.03,10.99],[1.1,200]],"id":52385903},{"atl":[[990,0.17]],"id":52385903},{"atb":[[1.03,10.99],[1.1,200]],"id":52385904},{"atl":[[990,0.17]],"id":52385904},{"atb":[[1.02,16.48],[1.1,200]],"id":52385905},{"atl":[[990,0.17]],"id":52385905},{"atb":[[1.02,16.48],[1.1,200]],"id":52385898},{"atl":[[990,0.17]],"id":52385898},{"atb":[[1.03,10.99],[1.1,200]],"id":52385899},{"atl":[[1000,0.17]],"id":52385899}],"con":true,"img":true}]}
{"op":"mcm","clk":"11548031727","pt":1719450482634,"mc":[{"id":"1.230178174","marketDefinition":{"bspMarket":false,"turnInPlayEnabled":false,"persistenceEnabled":false,"marketBaseRate":5.0,"eventId":"33376048","eventTypeId":"4339","numberOfWinners":1,"bettingType":"ODDS","marketType":"FORECAST","marketTime":"2024-06-27T15:59:00.000Z","suspendTime":"2024-06-27T15:59:00.000Z","bspReconciled":false,"complete":true,"inPlay":false,"crossMatching":false,"runnersVoidable":false,"numberOfActiveRunners":20,"betDelay":0,"status":"OPEN","runners":[{"status":"ACTIVE","sortPriority":1,"id":52385882,"name":"1 - 2"},{"status":"ACTIVE","sortPriority":2,"id":52385883,"name":"1 - 3"},{"status":"ACTIVE","sortPriority":3,"id":52385884,"name":"1 - 4"},{"status":"ACTIVE","sortPriority":4,"id":52385885,"name":"1 - 5"},{"status":"ACTIVE","sortPriority":5,"id":52385889,"name":"2 - 1"},{"status":"ACTIVE","sortPriority":6,"id":52385890,"name":"2 - 3"},{"status":"ACTIVE","sortPriority":7,"id":52385891,"name":"2 - 4"},{"status":"ACTIVE","sortPriority":8,"id":52385892,"name":"2 - 5"},{"status":"ACTIVE","sortPriority":9,"id":52385896,"name":"3 - 1"},{"status":"ACTIVE","sortPriority":10,"id":52385897,"name":"3 - 2"},{"status":"ACTIVE","sortPriority":11,"id":52385898,"name":"3 - 4"},{"status":"ACTIVE","sortPriority":12,"id":52385899,"name":"3 - 5"},{"status":"ACTIVE","sortPriority":13,"id":52385903,"name":"4 - 1"},{"status":"ACTIVE","sortPriority":14,"id":52385904,"name":"4 - 2"},{"status":"ACTIVE","sortPriority":15,"id":52385905,"name":"4 - 3"},{"status":"ACTIVE","sortPriority":16,"id":52385906,"name":"4 - 5"},{"status":"ACTIVE","sortPriority":17,"id":52385910,"name":"5 - 1"},{"status":"ACTIVE","sortPriority":18,"id":52385911,"name":"5 - 2"},{"status":"ACTIVE","sortPriority":19,"id":52385912,"name":"5 - 3"},{"status":"ACTIVE","sortPriority":20,"id":52385913,"name":"5 - 4"}],"regulators":["MR_INT"],"venue":"Perry Barr","countryCode":"GB","discountAllowed":true,"timezone":"Europe/London","openDate":"2024-06-27T13:29:00.000Z","version":5994794132,"name":"Forecast","eventName":"Perry Barr (F/C) 27th Jun"},"rc":[{"atb":[[1.01,32.97],[1.1,200]],"id":52385910},{"atl":[[1000,0.17]],"id":52385910},{"atb":[[1.01,32.97],[1.1,200]],"id":52385911},{"atl":[[1000,0.17]],"id":52385911},{"atb":[[1.02,16.48],[1.1,200]],"id":52385912},{"atl":[[990,0.17]],"id":52385912},{"atb":[[1.03,10.99],[1.1,200]],"id":52385913},{"atl":[[1000,0.17]],"id":52385913},{"atb":[[1.03,10.99],[1.1,200]],"id":52385906},{"atl":[[1000,0.17]],"id":52385906},{"atb":[[1.03,10.99],[1.1,200]],"id":52385889},{"atl":[[990,0.17]],"id":52385889},{"atb":[[1.01,32.97],[1.1,200]],"id":52385882},{"atl":[[990,0.17]],"id":52385882},{"atb":[[1.02,16.48],[1.1,200]],"id":52385883},{"atl":[[990,0.17]],"id":52385883},{"atb":[[1.01,32.97],[1.1,200]],"id":52385884},{"atl":[[1000,0.17]],"id":52385884},{"atb":[[1.02,16.48],[1.1,200]],"id":52385885},{"atl":[[990,0.17]],"id":52385885},{"atb":[[1.02,16.48],[1.1,200]],"id":52385896},{"atl":[[990,0.17]],"id":52385896},{"atb":[[1.03,10.99],[1.1,200]],"id":52385897},{"atl":[[990,0.17]],"id":52385897},{"atb":[[1.02,16.48],[1.1,200]],"id":52385890},{"atl":[[1000,0.17]],"id":52385890},{"atb":[[1.01,32.97],[1.1,200]],"id":52385891},{"atl":[[990,0.17]],"id":52385891},{"atb":[[1.03,10.99],[1.1,200]],"id":52385892},{"atl":[[990,0.17]],"id":52385892},{"atb":[[1.03,10.99],[1.1,200]],"id":52385903},{"atl":[[990,0.17]],"id":52385903},{"atb":[[1.03,10.99],[1.1,200]],"id":52385904},{"atl":[[990,0.17]],"id":52385904},{"atb":[[1.02,16.48],[1.1,200]],"id":52385905},{"atl":[[990,0.17]],"id":52385905},{"atb":[[1.02,16.48],[1.1,200]],"id":52385898},{"atl":[[990,0.17]],"id":52385898},{"atb":[[1.03,10.99],[1.1,200]],"id":52385899},{"atl":[[1000,0.17]],"id":52385899}],"con":true,"img":true}]}
{"op":"mcm","clk":"11548270791","pt":1719455882654,"mc":[{"id":"1.230178174","marketDefinition":{"bspMarket":false,"turnInPlayEnabled":false,"persistenceEnabled":false,"marketBaseRate":5.0,"eventId":"33376048","eventTypeId":"4339","numberOfWinners":1,"bettingType":"ODDS","marketType":"FORECAST","marketTime":"2024-06-27T15:59:00.000Z","suspendTime":"2024-06-27T15:59:00.000Z","bspReconciled":false,"complete":true,"inPlay":false,"crossMatching":false,"runnersVoidable":false,"numberOfActiveRunners":20,"betDelay":0,"status":"OPEN","runners":[{"status":"ACTIVE","sortPriority":1,"id":52385882,"name":"1 - 2"},{"status":"ACTIVE","sortPriority":2,"id":52385883,"name":"1 - 3"},{"status":"ACTIVE","sortPriority":3,"id":52385884,"name":"1 - 4"},{"status":"ACTIVE","sortPriority":4,"id":52385885,"name":"1 - 5"},{"status":"ACTIVE","sortPriority":5,"id":52385889,"name":"2 - 1"},{"status":"ACTIVE","sortPriority":6,"id":52385890,"name":"2 - 3"},{"status":"ACTIVE","sortPriority":7,"id":52385891,"name":"2 - 4"},{"status":"ACTIVE","sortPriority":8,"id":52385892,"name":"2 - 5"},{"status":"ACTIVE","sortPriority":9,"id":52385896,"name":"3 - 1"},{"status":"ACTIVE","sortPriority":10,"id":52385897,"name":"3 - 2"},{"status":"ACTIVE","sortPriority":11,"id":52385898,"name":"3 - 4"},{"status":"ACTIVE","sortPriority":12,"id":52385899,"name":"3 - 5"},{"status":"ACTIVE","sortPriority":13,"id":52385903,"name":"4 - 1"},{"status":"ACTIVE","sortPriority":14,"id":52385904,"name":"4 - 2"},{"status":"ACTIVE","sortPriority":15,"id":52385905,"name":"4 - 3"},{"status":"ACTIVE","sortPriority":16,"id":52385906,"name":"4 - 5"},{"status":"ACTIVE","sortPriority":17,"id":52385910,"name":"5 - 1"},{"status":"ACTIVE","sortPriority":18,"id":52385911,"name":"5 - 2"},{"status":"ACTIVE","sortPriority":19,"id":52385912,"name":"5 - 3"},{"status":"ACTIVE","sortPriority":20,"id":52385913,"name":"5 - 4"}],"regulators":["MR_INT"],"venue":"Perry Barr","countryCode":"GB","discountAllowed":true,"timezone":"Europe/London","openDate":"2024-06-27T13:29:00.000Z","version":5994794132,"name":"Forecast","eventName":"Perry Barr (F/C) 27th Jun"},"rc":[{"atb":[[1.01,32.97],[1.1,200]],"id":52385910},{"atl":[[1000,0.17]],"id":52385910},{"atb":[[1.01,32.97],[1.1,200]],"id":52385911},{"atl":[[1000,0.17]],"id":52385911},{"atb":[[1.02,16.48],[1.1,200]],"id":52385912},{"atl":[[990,0.17]],"id":52385912},{"atb":[[1.03,10.99],[1.1,200]],"id":52385913},{"atl":[[1000,0.17]],"id":52385913},{"atb":[[1.03,10.99],[1.1,200]],"id":52385906},{"atl":[[1000,0.17]],"id":52385906},{"atb":[[1.03,10.99],[1.1,200]],"id":52385889},{"atl":[[990,0.17]],"id":52385889},{"atb":[[1.01,32.97],[1.1,200]],"id":52385882},{"atl":[[990,0.17]],"id":52385882},{"atb":[[1.02,16.48],[1.1,200]],"id":52385883},{"atl":[[990,0.17]],"id":52385883},{"atb":[[1.01,32.97],[1.1,200]],"id":52385884},{"atl":[[1000,0.17]],"id":52385884},{"atb":[[1.02,16.48],[1.1,200]],"id":52385885},{"atl":[[990,0.17]],"id":52385885},{"atb":[[1.02,16.48],[1.1,200]],"id":52385896},{"atl":[[990,0.17]],"id":52385896},{"atb":[[1.03,10.99],[1.1,200]],"id":52385897},{"atl":[[990,0.17]],"id":52385897},{"atb":[[1.02,16.48],[1.1,200]],"id":52385890},{"atl":[[1000,0.17]],"id":52385890},{"atb":[[1.01,32.97],[1.1,200]],"id":52385891},{"atl":[[990,0.17]],"id":52385891},{"atb":[[1.03,10.99],[1.1,200]],"id":52385892},{"atl":[[990,0.17]],"id":52385892},{"atb":[[1.03,10.99],[1.1,200]],"id":52385903},{"atl":[[990,0.17]],"id":52385903},{"atb":[[1.03,10.99],[1.1,200]],"id":52385904},{"atl":[[990,0.17]],"id":52385904},{"atb":[[1.02,16.48],[1.1,200]],"id":52385905},{"atl":[[990,0.17]],"id":52385905},{"atb":[[1.02,16.48],[1.1,200]],"id":52385898},{"atl":[[990,0.17]],"id":52385898},{"atb":[[1.03,10.99],[1.1,200]],"id":52385899},{"atl":[[1000,0.17]],"id":52385899}],"con":true,"img":true}]}
{"op":"mcm","clk":"11548426213","pt":1719461282620,"mc":[{"id":"1.230178174","marketDefinition":{"bspMarket":false,"turnInPlayEnabled":false,"persistenceEnabled":false,"marketBaseRate":5.0,"eventId":"33376048","eventTypeId":"4339","numberOfWinners":1,"bettingType":"ODDS","marketType":"FORECAST","marketTime":"2024-06-27T15:59:00.000Z","suspendTime":"2024-06-27T15:59:00.000Z","bspReconciled":false,"complete":true,"inPlay":false,"crossMatching":false,"runnersVoidable":false,"numberOfActiveRunners":20,"betDelay":0,"status":"OPEN","runners":[{"status":"ACTIVE","sortPriority":1,"id":52385882,"name":"1 - 2"},{"status":"ACTIVE","sortPriority":2,"id":52385883,"name":"1 - 3"},{"status":"ACTIVE","sortPriority":3,"id":52385884,"name":"1 - 4"},{"status":"ACTIVE","sortPriority":4,"id":52385885,"name":"1 - 5"},{"status":"ACTIVE","sortPriority":5,"id":52385889,"name":"2 - 1"},{"status":"ACTIVE","sortPriority":6,"id":52385890,"name":"2 - 3"},{"status":"ACTIVE","sortPriority":7,"id":52385891,"name":"2 - 4"},{"status":"ACTIVE","sortPriority":8,"id":52385892,"name":"2 - 5"},{"status":"ACTIVE","sortPriority":9,"id":52385896,"name":"3 - 1"},{"status":"ACTIVE","sortPriority":10,"id":52385897,"name":"3 - 2"},{"status":"ACTIVE","sortPriority":11,"id":52385898,"name":"3 - 4"},{"status":"ACTIVE","sortPriority":12,"id":52385899,"name":"3 - 5"},{"status":"ACTIVE","sortPriority":13,"id":52385903,"name":"4 - 1"},{"status":"ACTIVE","sortPriority":14,"id":52385904,"name":"4 - 2"},{"status":"ACTIVE","sortPriority":15,"id":52385905,"name":"4 - 3"},{"status":"ACTIVE","sortPriority":16,"id":52385906,"name":"4 - 5"},{"status":"ACTIVE","sortPriority":17,"id":52385910,"name":"5 - 1"},{"status":"ACTIVE","sortPriority":18,"id":52385911,"name":"5 - 2"},{"status":"ACTIVE","sortPriority":19,"id":52385912,"name":"5 - 3"},{"status":"ACTIVE","sortPriority":20,"id":52385913,"name":"5 - 4"}],"regulators":["MR_INT"],"venue":"Perry Barr","countryCode":"GB","discountAllowed":true,"timezone":"Europe/London","openDate":"2024-06-27T13:29:00.000Z","version":5994794132,"name":"Forecast","eventName":"Perry Barr (F/C) 27th Jun"},"rc":[{"atb":[[1.01,32.97],[1.1,200]],"id":52385910},{"atl":[[1000,0.17]],"id":52385910},{"atb":[[1.01,32.97],[1.1,200]],"id":52385911},{"atl":[[1000,0.17]],"id":52385911},{"atb":[[1.02,16.48],[1.1,200]],"id":52385912},{"atl":[[990,0.17]],"id":52385912},{"atb":[[1.03,10.99],[1.1,200]],"id":52385913},{"atl":[[1000,0.17]],"id":52385913},{"atb":[[1.03,10.99],[1.1,200]],"id":52385906},{"atl":[[1000,0.17]],"id":52385906},{"atb":[[1.03,10.99],[1.1,200]],"id":52385889},{"atl":[[990,0.17]],"id":52385889},{"atb":[[1.01,32.97],[1.1,200]],"id":52385882},{"atl":[[990,0.17]],"id":52385882},{"atb":[[1.02,16.48],[1.1,200]],"id":52385883},{"atl":[[990,0.17]],"id":52385883},{"atb":[[1.01,32.97],[1.1,200]],"id":52385884},{"atl":[[1000,0.17]],"id":52385884},{"atb":[[1.02,16.48],[1.1,200]],"id":52385885},{"atl":[[990,0.17]],"id":52385885},{"atb":[[1.02,16.48],[1.1,200]],"id":52385896},{"atl":[[990,0.17]],"id":52385896},{"atb":[[1.03,10.99],[1.1,200]],"id":52385897},{"atl":[[990,0.17]],"id":52385897},{"atb":[[1.02,16.48],[1.1,200]],"id":52385890},{"atl":[[1000,0.17]],"id":52385890},{"atb":[[1.01,32.97],[1.1,200]],"id":52385891},{"atl":[[990,0.17]],"id":52385891},{"atb":[[1.03,10.99],[1.1,200]],"id":52385892},{"atl":[[990,0.17]],"id":52385892},{"atb":[[1.03,10.99],[1.1,200]],"id":52385903},{"atl":[[990,0.17]],"id":52385903},{"atb":[[1.03,10.99],[1.1,200]],"id":52385904},{"atl":[[990,0.17]],"id":52385904},{"atb":[[1.02,16.48],[1.1,200]],"id":52385905},{"atl":[[990,0.17]],"id":52385905},{"atb":[[1.02,16.48],[1.1,200]],"id":52385898},{"atl":[[990,0.17]],"id":52385898},{"atb":[[1.03,10.99],[1.1,200]],"id":52385899},{"atl":[[1000,0.17]],"id":52385899}],"con":true,"img":true}]}
{"op":"mcm","clk":"11548535727","pt":1719466682820,"mc":[{"id":"1.230178174","marketDefinition":{"bspMarket":false,"turnInPlayEnabled":false,"persistenceEnabled":false,"marketBaseRate":5.0,"eventId":"33376048","eventTypeId":"4339","numberOfWinners":1,"bettingType":"ODDS","marketType":"FORECAST","marketTime":"2024-06-27T15:59:00.000Z","suspendTime":"2024-06-27T15:59:00.000Z","bspReconciled":false,"complete":true,"inPlay":false,"crossMatching":false,"runnersVoidable":false,"numberOfActiveRunners":20,"betDelay":0,"status":"OPEN","runners":[{"status":"ACTIVE","sortPriority":1,"id":52385882,"name":"1 - 2"},{"status":"ACTIVE","sortPriority":2,"id":52385883,"name":"1 - 3"},{"status":"ACTIVE","sortPriority":3,"id":52385884,"name":"1 - 4"},{"status":"ACTIVE","sortPriority":4,"id":52385885,"name":"1 - 5"},{"status":"ACTIVE","sortPriority":5,"id":52385889,"name":"2 - 1"},{"status":"ACTIVE","sortPriority":6,"id":52385890,"name":"2 - 3"},{"status":"ACTIVE","sortPriority":7,"id":52385891,"name":"2 - 4"},{"status":"ACTIVE","sortPriority":8,"id":52385892,"name":"2 - 5"},{"status":"ACTIVE","sortPriority":9,"id":52385896,"name":"3 - 1"},{"status":"ACTIVE","sortPriority":10,"id":52385897,"name":"3 - 2"},{"status":"ACTIVE","sortPriority":11,"id":52385898,"name":"3 - 4"},{"status":"ACTIVE","sortPriority":12,"id":52385899,"name":"3 - 5"},{"status":"ACTIVE","sortPriority":13,"id":52385903,"name":"4 - 1"},{"status":"ACTIVE","sortPriority":14,"id":52385904,"name":"4 - 2"},{"status":"ACTIVE","sortPriority":15,"id":52385905,"name":"4 - 3"},{"status":"ACTIVE","sortPriority":16,"id":52385906,"name":"4 - 5"},{"status":"ACTIVE","sortPriority":17,"id":52385910,"name":"5 - 1"},{"status":"ACTIVE","sortPriority":18,"id":52385911,"name":"5 - 2"},{"status":"ACTIVE","sortPriority":19,"id":52385912,"name":"5 - 3"},{"status":"ACTIVE","sortPriority":20,"id":52385913,"name":"5 - 4"}],"regulators":["MR_INT"],"venue":"Perry Barr","countryCode":"GB","discountAllowed":true,"timezone":"Europe/London","openDate":"2024-06-27T13:29:00.000Z","version":5994794132,"name":"Forecast","eventName":"Perry Barr (F/C) 27th Jun"},"rc":[{"atb":[[1.01,32.97],[1.1,200]],"id":52385910},{"atl":[[1000,0.17]],"id":52385910},{"atb":[[1.01,32.97],[1.1,200]],"id":52385911},{"atl":[[1000,0.17]],"id":52385911},{"atb":[[1.02,16.48],[1.1,200]],"id":52385912},{"atl":[[990,0.17]],"id":52385912},{"atb":[[1.03,10.99],[1.1,200]],"id":52385913},{"atl":[[1000,0.17]],"id":52385913},{"atb":[[1.03,10.99],[1.1,200]],"id":52385906},{"atl":[[1000,0.17]],"id":52385906},{"atb":[[1.03,10.99],[1.1,200]],"id":52385889},{"atl":[[990,0.17]],"id":52385889},{"atb":[[1.01,32.97],[1.1,200]],"id":52385882},{"atl":[[990,0.17]],"id":52385882},{"atb":[[1.02,16.48],[1.1,200]],"id":52385883},{"atl":[[990,0.17]],"id":52385883},{"atb":[[1.01,32.97],[1.1,200]],"id":52385884},{"atl":[[1000,0.17]],"id":52385884},{"atb":[[1.02,16.48],[1.1,200]],"id":52385885},{"atl":[[990,0.17]],"id":52385885},{"atb":[[1.02,16.48],[1.1,200]],"id":52385896},{"atl":[[990,0.17]],"id":52385896},{"atb":[[1.03,10.99],[1.1,200]],"id":52385897},{"atl":[[990,0.17]],"id":52385897},{"atb":[[1.02,16.48],[1.1,200]],"id":52385890},{"atl":[[1000,0.17]],"id":52385890},{"atb":[[1.01,32.97],[1.1,200]],"id":52385891},{"atl":[[990,0.17]],"id":52385891},{"atb":[[1.03,10.99],[1.1,200]],"id":52385892},{"atl":[[990,0.17]],"id":52385892},{"atb":[[1.03,10.99],[1.1,200]],"id":52385903},{"atl":[[990,0.17]],"id":52385903},{"atb":[[1.03,10.99],[1.1,200]],"id":52385904},{"atl":[[990,0.17]],"id":52385904},{"atb":[[1.02,16.48],[1.1,200]],"id":52385905},{"atl":[[990,0.17]],"id":52385905},{"atb":[[1.02,16.48],[1.1,200]],"id":52385898},{"atl":[[990,0.17]],"id":52385898},{"atb":[[1.03,10.99],[1.1,200]],"id":52385899},{"atl":[[1000,0.17]],"id":52385899}],"con":true,"img":true}]}
{"op":"mcm","clk":"11548656208","pt":1719472082591,"mc":[{"id":"1.230178174","marketDefinition":{"bspMarket":false,"turnInPlayEnabled":false,"persistenceEnabled":false,"marketBaseRate":5.0,"eventId":"33376048","eventTypeId":"4339","numberOfWinners":1,"bettingType":"ODDS","marketType":"FORECAST","marketTime":"2024-06-27T15:59:00.000Z","suspendTime":"2024-06-27T15:59:00.000Z","bspReconciled":false,"complete":true,"inPlay":false,"crossMatching":false,"runnersVoidable":false,"numberOfActiveRunners":20,"betDelay":0,"status":"OPEN","runners":[{"status":"ACTIVE","sortPriority":1,"id":52385882,"name":"1 - 2"},{"status":"ACTIVE","sortPriority":2,"id":52385883,"name":"1 - 3"},{"status":"ACTIVE","sortPriority":3,"id":52385884,"name":"1 - 4"},{"status":"ACTIVE","sortPriority":4,"id":52385885,"name":"1 - 5"},{"status":"ACTIVE","sortPriority":5,"id":52385889,"name":"2 - 1"},{"status":"ACTIVE","sortPriority":6,"id":52385890,"name":"2 - 3"},{"status":"ACTIVE","sortPriority":7,"id":52385891,"name":"2 - 4"},{"status":"ACTIVE","sortPriority":8,"id":52385892,"name":"2 - 5"},{"status":"ACTIVE","sortPriority":9,"id":52385896,"name":"3 - 1"},{"status":"ACTIVE","sortPriority":10,"id":52385897,"name":"3 - 2"},{"status":"ACTIVE","sortPriority":11,"id":52385898,"name":"3 - 4"},{"status":"ACTIVE","sortPriority":12,"id":52385899,"name":"3 - 5"},{"status":"ACTIVE","sortPriority":13,"id":52385903,"name":"4 - 1"},{"status":"ACTIVE","sortPriority":14,"id":52385904,"name":"4 - 2"},{"status":"ACTIVE","sortPriority":15,"id":52385905,"name":"4 - 3"},{"status":"ACTIVE","sortPriority":16,"id":52385906,"name":"4 - 5"},{"status":"ACTIVE","sortPriority":17,"id":52385910,"name":"5 - 1"},{"status":"ACTIVE","sortPriority":18,"id":52385911,"name":"5 - 2"},{"status":"ACTIVE","sortPriority":19,"id":52385912,"name":"5 - 3"},{"status":"ACTIVE","sortPriority":20,"id":52385913,"name":"5 - 4"}],"regulators":["MR_INT"],"venue":"Perry Barr","countryCode":"GB","discountAllowed":true,"timezone":"Europe/London","openDate":"2024-06-27T13:29:00.000Z","version":5994794132,"name":"Forecast","eventName":"Perry Barr (F/C) 27th Jun"},"rc":[{"atb":[[1.01,32.94],[1.1,200]],"id":52385910},{"atl":[[1000,0.17]],"id":52385910},{"atb":[[1.01,32.94],[1.1,200]],"id":52385911},{"atl":[[1000,0.17]],"id":52385911},{"atb":[[1.02,16.47],[1.1,200]],"id":52385912},{"atl":[[990,0.17]],"id":52385912},{"atb":[[1.03,10.98],[1.1,200]],"id":52385913},{"atl":[[1000,0.17]],"id":52385913},{"atb":[[1.03,10.98],[1.1,200]],"id":52385906},{"atl":[[1000,0.17]],"id":52385906},{"atb":[[1.03,10.98],[1.1,200]],"id":52385889},{"atl":[[990,0.17]],"id":52385889},{"atb":[[1.01,32.94],[1.1,200]],"id":52385882},{"atl":[[990,0.17]],"id":52385882},{"atb":[[1.02,16.47],[1.1,200]],"id":52385883},{"atl":[[990,0.17]],"id":52385883},{"atb":[[1.01,32.94],[1.1,200]],"id":52385884},{"atl":[[1000,0.17]],"id":52385884},{"atb":[[1.02,16.47],[1.1,200]],"id":52385885},{"atl":[[990,0.17]],"id":52385885},{"atb":[[1.02,16.47],[1.1,200]],"id":52385896},{"atl":[[990,0.17]],"id":52385896},{"atb":[[1.03,10.98],[1.1,200]],"id":52385897},{"atl":[[990,0.17]],"id":52385897},{"atb":[[1.02,16.47],[1.1,200]],"id":52385890},{"atl":[[1000,0.17]],"id":52385890},{"atb":[[1.01,32.94],[1.1,200]],"id":52385891},{"atl":[[990,0.17]],"id":52385891},{"atb":[[1.03,10.98],[1.1,200]],"id":52385892},{"atl":[[990,0.17]],"id":52385892},{"atb":[[1.03,10.98],[1.1,200]],"id":52385903},{"atl":[[990,0.17]],"id":52385903},{"atb":[[1.03,10.98],[1.1,200]],"id":52385904},{"atl":[[990,0.17]],"id":52385904},{"atb":[[1.02,16.47],[1.1,200]],"id":52385905},{"atl":[[990,0.17]],"id":52385905},{"atb":[[1.02,16.47],[1.1,200]],"id":52385898},{"atl":[[990,0.17]],"id":52385898},{"atb":[[1.03,10.98],[1.1,200]],"id":52385899},{"atl":[[1000,0.17]],"id":52385899}],"con":true,"img":true}]}
{"op":"mcm","clk":"11548861954","pt":1719477482591,"mc":[{"id":"1.230178174","marketDefinition":{"bspMarket":false,"turnInPlayEnabled":false,"persistenceEnabled":false,"marketBaseRate":5.0,"eventId":"33376048","eventTypeId":"4339","numberOfWinners":1,"bettingType":"ODDS","marketType":"FORECAST","marketTime":"2024-06-27T15:59:00.000Z","suspendTime":"2024-06-27T15:59:00.000Z","bspReconciled":false,"complete":true,"inPlay":false,"crossMatching":false,"runnersVoidable":false,"numberOfActiveRunners":20,"betDelay":0,"status":"OPEN","runners":[{"status":"ACTIVE","sortPriority":1,"id":52385882,"name":"1 - 2"},{"status":"ACTIVE","sortPriority":2,"id":52385883,"name":"1 - 3"},{"status":"ACTIVE","sortPriority":3,"id":52385884,"name":"1 - 4"},{"status":"ACTIVE","sortPriority":4,"id":52385885,"name":"1 - 5"},{"status":"ACTIVE","sortPriority":5,"id":52385889,"name":"2 - 1"},{"status":"ACTIVE","sortPriority":6,"id":52385890,"name":"2 - 3"},{"status":"ACTIVE","sortPriority":7,"id":52385891,"name":"2 - 4"},{"status":"ACTIVE","sortPriority":8,"id":52385892,"name":"2 - 5"},{"status":"ACTIVE","sortPriority":9,"id":52385896,"name":"3 - 1"},{"status":"ACTIVE","sortPriority":10,"id":52385897,"name":"3 - 2"},{"status":"ACTIVE","sortPriority":11,"id":52385898,"name":"3 - 4"},{"status":"ACTIVE","sortPriority":12,"id":52385899,"name":"3 - 5"},{"status":"ACTIVE","sortPriority":13,"id":52385903,"name":"4 - 1"},{"status":"ACTIVE","sortPriority":14,"id":52385904,"name":"4 - 2"},{"status":"ACTIVE","sortPriority":15,"id":52385905,"name":"4 - 3"},{"status":"ACTIVE","sortPriority":16,"id":52385906,"name":"4 - 5"},{"status":"ACTIVE","sortPriority":17,"id":52385910,"name":"5 - 1"},{"status":"ACTIVE","sortPriority":18,"id":52385911,"name":"5 - 2"},{"status":"ACTIVE","sortPriority":19,"id":52385912,"name":"5 - 3"},{"status":"ACTIVE","sortPriority":20,"id":52385913,"name":"5 - 4"}],"regulators":["MR_INT"],"venue":"Perry Barr","countryCode":"GB","discountAllowed":true,"timezone":"Europe/London","openDate":"2024-06-27T13:29:00.000Z","version":5994794132,"name":"Forecast","eventName":"Perry Barr (F/C) 27th Jun"},"rc":[{"atb":[[1.01,32.96],[1.1,200]],"id":52385910},{"atl":[[1000,0.17]],"id":52385910},{"atb":[[1.01,32.96],[1.1,200]],"id":52385911},{"atl":[[1000,0.17]],"id":52385911},{"atb":[[1.02,16.48],[1.1,200]],"id":52385912},{"atl":[[990,0.17]],"id":52385912},{"atb":[[1.03,10.99],[1.1,200]],"id":52385913},{"atl":[[1000,0.17]],"id":52385913},{"atb":[[1.03,10.99],[1.1,200]],"id":52385906},{"atl":[[1000,0.17]],"id":52385906},{"atb":[[1.03,10.99],[1.1,200]],"id":52385889},{"atl":[[990,0.17]],"id":52385889},{"atb":[[1.01,32.96],[1.1,200]],"id":52385882},{"atl":[[990,0.17]],"id":52385882},{"atb":[[1.02,16.48],[1.1,200]],"id":52385883},{"atl":[[990,0.17]],"id":52385883},{"atb":[[1.01,32.96],[1.1,200]],"id":52385884},{"atl":[[1000,0.17]],"id":52385884},{"atb":[[1.02,16.48],[1.1,200]],"id":52385885},{"atl":[[990,0.17]],"id":52385885},{"atb":[[1.02,16.48],[1.1,200]],"id":52385896},{"atl":[[990,0.17]],"id":52385896},{"atb":[[1.03,10.99],[1.1,200]],"id":52385897},{"atl":[[990,0.17]],"id":52385897},{"atb":[[1.02,16.48],[1.1,200]],"id":52385890},{"atl":[[1000,0.17]],"id":52385890},{"atb":[[1.01,32.96],[1.1,200]],"id":52385891},{"atl":[[990,0.17]],"id":52385891},{"atb":[[1.03,10.99],[1.1,200]],"id":52385892},{"atl":[[990,0.17]],"id":52385892},{"atb":[[1.03,10.99],[1.1,200]],"id":52385903},{"atl":[[990,0.17]],"id":52385903},{"atb":[[1.03,10.99],[1.1,200]],"id":52385904},{"atl":[[990,0.17]],"id":52385904},{"atb":[[1.02,16.48],[1.1,200]],"id":52385905},{"atl":[[990,0.17]],"id":52385905},{"atb":[[1.02,16.48],[1.1,200]],"id":52385898},{"atl":[[990,0.17]],"id":52385898},{"atb":[[1.03,10.99],[1.1,200]],"id":52385899},{"atl":[[1000,0.17]],"id":52385899}],"con":true,"img":true}]}
{"op":"mcm","clk":"11549140218","pt":1719482882591,"mc":[{"id":"1.230178174","marketDefinition":{"bspMarket":false,"turnInPlayEnabled":false,"persistenceEnabled":false,"marketBaseRate":5.0,"eventId":"33376048","eventTypeId":"4339","numberOfWinners":1,"bettingType":"ODDS","marketType":"FORECAST","marketTime":"2024-06-27T15:59:00.000Z","suspendTime":"2024-06-27T15:59:00.000Z","bspReconciled":false,"complete":true,"inPlay":false,"crossMatching":false,"runnersVoidable":false,"numberOfActiveRunners":20,"betDelay":0,"status":"OPEN","runners":[{"status":"ACTIVE","sortPriority":1,"id":52385882,"name":"1 - 2"},{"status":"ACTIVE","sortPriority":2,"id":52385883,"name":"1 - 3"},{"status":"ACTIVE","sortPriority":3,"id":52385884,"name":"1 - 4"},{"status":"ACTIVE","sortPriority":4,"id":52385885,"name":"1 - 5"},{"status":"ACTIVE","sortPriority":5,"id":52385889,"name":"2 - 1"},{"status":"ACTIVE","sortPriority":6,"id":52385890,"name":"2 - 3"},{"status":"ACTIVE","sortPriority":7,"id":52385891,"name":"2 - 4"},{"status":"ACTIVE","sortPriority":8,"id":52385892,"name":"2 - 5"},{"status":"ACTIVE","sortPriority":9,"id":52385896,"name":"3 - 1"},{"status":"ACTIVE","sortPriority":10,"id":52385897,"name":"3 - 2"},{"status":"ACTIVE","sortPriority":11,"id":52385898,"name":"3 - 4"},{"status":"ACTIVE","sortPriority":12,"id":52385899,"name":"3 - 5"},{"status":"ACTIVE","sortPriority":13,"id":52385903,"name":"4 - 1"},{"status":"ACTIVE","sortPriority":14,"id":52385904,"name":"4 - 2"},{"status":"ACTIVE","sortPriority":15,"id":52385905,"name":"4 - 3"},{"status":"ACTIVE","sortPriority":16,"id":52385906,"name":"4 - 5"},{"status":"ACTIVE","sortPriority":17,"id":52385910,"name":"5 - 1"},{"status":"ACTIVE","sortPriority":18,"id":52385911,"name":"5 - 2"},{"status":"ACTIVE","sortPriority":19,"id":52385912,"name":"5 - 3"},{"status":"ACTIVE","sortPriority":20,"id":52385913,"name":"5 - 4"}],"regulators":["MR_INT"],"venue":"Perry Barr","countryCode":"GB","discountAllowed":true,"timezone":"Europe/London","openDate":"2024-06-27T13:29:00.000Z","version":5994794132,"name":"Forecast","eventName":"Perry Barr (F/C) 27th Jun"},"rc":[{"atb":[[1.01,32.95],[1.1,200]],"id":52385910},{"atl":[[1000,0.17]],"id":52385910},{"atb":[[1.01,32.95],[1.1,200]],"id":52385911},{"atl":[[1000,0.17]],"id":52385911},{"atb":[[1.02,16.47],[1.1,200]],"id":52385912},{"atl":[[990,0.17]],"id":52385912},{"atb":[[1.03,10.98],[1.1,200]],"id":52385913},{"atl":[[1000,0.17]],"id":52385913},{"atb":[[1.03,10.98],[1.1,200]],"id":52385906},{"atl":[[1000,0.17]],"id":52385906},{"atb":[[1.03,10.98],[1.1,200]],"id":52385889},{"atl":[[990,0.17]],"id":52385889},{"atb":[[1.01,32.95],[1.1,200]],"id":52385882},{"atl":[[990,0.17]],"id":52385882},{"atb":[[1.02,16.47],[1.1,200]],"id":52385883},{"atl":[[990,0.17]],"id":52385883},{"atb":[[1.01,32.95],[1.1,200]],"id":52385884},{"atl":[[1000,0.17]],"id":52385884},{"atb":[[1.02,16.47],[1.1,200]],"id":52385885},{"atl":[[990,0.17]],"id":52385885},{"atb":[[1.02,16.47],[1.1,200]],"id":52385896},{"atl":[[990,0.17]],"id":52385896},{"atb":[[1.03,10.98],[1.1,200]],"id":52385897},{"atl":[[990,0.17]],"id":52385897},{"atb":[[1.02,16.47],[1.1,200]],"id":52385890},{"atl":[[1000,0.17]],"id":52385890},{"atb":[[1.01,32.95],[1.1,200]],"id":52385891},{"atl":[[990,0.17]],"id":52385891},{"atb":[[1.03,10.98],[1.1,200]],"id":52385892},{"atl":[[990,0.17]],"id":52385892},{"atb":[[1.03,10.98],[1.1,200]],"id":52385903},{"atl":[[990,0.17]],"id":52385903},{"atb":[[1.03,10.98],[1.1,200]],"id":52385904},{"atl":[[990,0.17]],"id":52385904},{"atb":[[1.02,16.47],[1.1,200]],"id":52385905},{"atl":[[990,0.17]],"id":52385905},{"atb":[[1.02,16.47],[1.1,200]],"id":52385898},{"atl":[[990,0.17]],"id":52385898},{"atb":[[1.03,10.98],[1.1,200]],"id":52385899},{"atl":[[1000,0.17]],"id":52385899}],"con":true,"img":true}]}
{"op":"mcm","clk":"11549606653","pt":1719488282608,"mc":[{"id":"1.230178174","marketDefinition":{"bspMarket":false,"turnInPlayEnabled":false,"persistenceEnabled":false,"marketBaseRate":5.0,"eventId":"33376048","eventTypeId":"4339","numberOfWinners":1,"bettingType":"ODDS","marketType":"FORECAST","marketTime":"2024-06-27T15:59:00.000Z","suspendTime":"2024-06-27T15:59:00.000Z","bspReconciled":false,"complete":true,"inPlay":false,"crossMatching":false,"runnersVoidable":false,"numberOfActiveRunners":20,"betDelay":0,"status":"OPEN","runners":[{"status":"ACTIVE","sortPriority":1,"id":52385882,"name":"1 - 2"},{"status":"ACTIVE","sortPriority":2,"id":52385883,"name":"1 - 3"},{"status":"ACTIVE","sortPriority":3,"id":52385884,"name":"1 - 4"},{"status":"ACTIVE","sortPriority":4,"id":52385885,"name":"1 - 5"},{"status":"ACTIVE","sortPriority":5,"id":52385889,"name":"2 - 1"},{"status":"ACTIVE","sortPriority":6,"id":52385890,"name":"2 - 3"},{"status":"ACTIVE","sortPriority":7,"id":52385891,"name":"2 - 4"},{"status":"ACTIVE","sortPriority":8,"id":52385892,"name":"2 - 5"},{"status":"ACTIVE","sortPriority":9,"id":52385896,"name":"3 - 1"},{"status":"ACTIVE","sortPriority":10,"id":52385897,"name":"3 - 2"},{"status":"ACTIVE","sortPriority":11,"id":52385898,"name":"3 - 4"},{"status":"ACTIVE","sortPriority":12,"id":52385899,"name":"3 - 5"},{"status":"ACTIVE","sortPriority":13,"id":52385903,"name":"4 - 1"},{"status":"ACTIVE","sortPriority":14,"id":52385904,"name":"4 - 2"},{"status":"ACTIVE","sortPriority":15,"id":52385905,"name":"4 - 3"},{"status":"ACTIVE","sortPriority":16,"id":52385906,"name":"4 - 5"},{"status":"ACTIVE","sortPriority":17,"id":52385910,"name":"5 - 1"},{"status":"ACTIVE","sortPriority":18,"id":52385911,"name":"5 - 2"},{"status":"ACTIVE","sortPriority":19,"id":52385912,"name":"5 - 3"},{"status":"ACTIVE","sortPriority":20,"id":52385913,"name":"5 - 4"}],"regulators":["MR_INT"],"venue":"Perry Barr","countryCode":"GB","discountAllowed":true,"timezone":"Europe/London","openDate":"2024-06-27T13:29:00.000Z","version":5994794132,"name":"Forecast","eventName":"Perry Barr (F/C) 27th Jun"},"rc":[{"atb":[[1.01,32.95],[1.1,200]],"id":52385910},{"atl":[[1000,0.17]],"id":52385910},{"atb":[[1.01,32.95],[1.1,200]],"id":52385911},{"atl":[[1000,0.17]],"id":52385911},{"atb":[[1.02,16.47],[1.1,200]],"id":52385912},{"atl":[[990,0.17]],"id":52385912},{"atb":[[1.03,10.98],[1.1,200]],"id":52385913},{"atl":[[1000,0.17]],"id":52385913},{"atb":[[1.03,10.98],[1.1,200]],"id":52385906},{"atl":[[1000,0.17]],"id":52385906},{"atb":[[1.03,10.98],[1.1,200]],"id":52385889},{"atl":[[990,0.17]],"id":52385889},{"atb":[[1.01,32.95],[1.1,200]],"id":52385882},{"atl":[[990,0.17]],"id":52385882},{"atb":[[1.02,16.47],[1.1,200]],"id":52385883},{"atl":[[990,0.17]],"id":52385883},{"atb":[[1.01,32.95],[1.1,200]],"id":52385884},{"atl":[[1000,0.17]],"id":52385884},{"atb":[[1.02,16.47],[1.1,200]],"id":52385885},{"atl":[[990,0.17]],"id":52385885},{"atb":[[1.02,16.47],[1.1,200]],"id":52385896},{"atl":[[990,0.17]],"id":52385896},{"atb":[[1.03,10.98],[1.1,200]],"id":52385897},{"atl":[[990,0.17]],"id":52385897},{"atb":[[1.02,16.47],[1.1,200]],"id":52385890},{"atl":[[1000,0.17]],"id":52385890},{"atb":[[1.01,32.95],[1.1,200]],"id":52385891},{"atl":[[990,0.17]],"id":52385891},{"atb":[[1.03,10.98],[1.1,200]],"id":52385892},{"atl":[[990,0.17]],"id":52385892},{"atb":[[1.03,10.98],[1.1,200]],"id":52385903},{"atl":[[990,0.17]],"id":52385903},{"atb":[[1.03,10.98],[1.1,200]],"id":52385904},{"atl":[[990,0.17]],"id":52385904},{"atb":[[1.02,16.47],[1.1,200]],"id":52385905},{"atl":[[990,0.17]],"id":52385905},{"atb":[[1.02,16.47],[1.1,200]],"id":52385898},{"atl":[[990,0.17]],"id":52385898},{"atb":[[1.03,10.98],[1.1,200]],"id":52385899},{"atl":[[1000,0.17]],"id":52385899}],"con":true,"img":true}]}
{"op":"mcm","clk":"11549979839","pt":1719493320806,"mc":[{"id":"1.230178174","rc":[{"atb":[[1.01,32.99]],"id":52385910},{"atl":[[1000,0.17]],"id":52385910},{"atb":[[1.01,32.99]],"id":52385911},{"atl":[[1000,0.17]],"id":52385911},{"atb":[[1.02,16.49]],"id":52385912},{"atl":[[990,0.17]],"id":52385912},{"atb":[[1.03,11]],"id":52385913},{"atl":[[1000,0.17]],"id":52385913},{"atb":[[1.03,11]],"id":52385906},{"atl":[[1000,0.17]],"id":52385906},{"atb":[[1.03,11]],"id":52385889},{"atl":[[990,0.17]],"id":52385889},{"atb":[[1.01,237.07]],"id":52385882},{"atl":[[990,0.17]],"id":52385882},{"atb":[[1.01,204.08],[1.02,16.49]],"id":52385883},{"atl":[[990,0.17]],"id":52385883},{"atb":[[1.01,32.99]],"id":52385884},{"atl":[[1000,0.17]],"id":52385884},{"atb":[[1.01,204.08],[1.02,16.49]],"id":52385885},{"atl":[[990,0.17]],"id":52385885},{"atb":[[1.02,16.49]],"id":52385896},{"atl":[[990,0.17]],"id":52385896},{"atb":[[1.03,11]],"id":52385897},{"atl":[[990,0.17]],"id":52385897},{"atb":[[1.02,16.49]],"id":52385890},{"atl":[[1000,0.17]],"id":52385890},{"atb":[[1.01,32.99]],"id":52385891},{"atl":[[990,0.17]],"id":52385891},{"atb":[[1.03,11]],"id":52385892},{"atl":[[990,0.17]],"id":52385892},{"atb":[[1.03,11]],"id":52385903},{"atl":[[990,0.17]],"id":52385903},{"atb":[[1.03,11]],"id":52385904},{"atl":[[990,0.17]],"id":52385904},{"atb":[[1.02,16.49]],"id":52385905},{"atl":[[990,0.17]],"id":52385905},{"atb":[[1.02,16.49]],"id":52385898},{"atl":[[990,0.17]],"id":52385898},{"atb":[[1.03,11]],"id":52385899},{"atl":[[1000,0.17]],"id":52385899}],"con":true,"img":false}]}
{"op":"mcm","clk":"11549979846","pt":1719493320905,"mc":[{"id":"1.230178174","rc":[{"atb":[[1.01,204.08]],"id":52385889},{"atb":[[1.01,237.07]],"id":52385884}],"con":true,"img":false}]}
{"op":"mcm","clk":"11549979853","pt":1719493321003,"mc":[{"id":"1.230178174","rc":[{"atb":[[1.01,204.08]],"id":52385890},{"atb":[[1.01,237.07]],"id":52385891}],"con":true,"img":false}]}
{"op":"mcm","clk":"11549979864","pt":1719493321112,"mc":[{"id":"1.230178174","rc":[{"atb":[[1.01,204.08]],"id":52385896},{"atb":[[1.01,204.08]],"id":52385892}],"con":true,"img":false}]}
{"op":"mcm","clk":"11549979867","pt":1719493321211,"mc":[{"id":"1.230178174","rc":[{"atb":[[1.01,204.08]],"id":52385897}],"con":true,"img":false}]}
{"op":"mcm","clk":"11549979914","pt":1719493321312,"mc":[{"id":"1.230178174","rc":[{"atb":[[1.01,204.08]],"id":52385898},{"atb":[[1.01,204.08]],"id":52385899}],"con":true,"img":false}]}
{"op":"mcm","clk":"11549979933","pt":1719493321414,"mc":[{"id":"1.230178174","rc":[{"atb":[[1.01,204.08]],"id":52385903},{"atb":[[1.01,204.08]],"id":52385904},{"atb":[[1.01,204.08]],"id":52385905}],"con":true,"img":false}]}
{"op":"mcm","clk":"11549979941","pt":1719493321516,"mc":[{"id":"1.230178174","rc":[{"atb":[[1.01,237.07]],"id":52385910},{"atb":[[1.01,204.08]],"id":52385906}],"con":true,"img":false}]}
{"op":"mcm","clk":"11549979948","pt":1719493321619,"mc":[{"id":"1.230178174","rc":[{"atb":[[1.01,237.07]],"id":52385911},{"atb":[[1.01,204.08]],"id":52385912},{"atb":[[1.01,204.08]],"id":52385913}],"con":true,"img":false}]}
{"op":"mcm","clk":"11550491754","pt":1719499082587,"mc":[{"id":"1.230178174","marketDefinition":{"bspMarket":false,"turnInPlayEnabled":false,"persistenceEnabled":false,"marketBaseRate":5.0,"eventId":"33376048","eventTypeId":"4339","numberOfWinners":1,"bettingType":"ODDS","marketType":"FORECAST","marketTime":"2024-06-27T15:59:00.000Z","suspendTime":"2024-06-27T15:59:00.000Z","bspReconciled":false,"complete":true,"inPlay":false,"crossMatching":false,"runnersVoidable":false,"numberOfActiveRunners":20,"betDelay":0,"status":"OPEN","runners":[{"status":"ACTIVE","sortPriority":1,"id":52385882,"name":"1 - 2"},{"status":"ACTIVE","sortPriority":2,"id":52385883,"name":"1 - 3"},{"status":"ACTIVE","sortPriority":3,"id":52385884,"name":"1 - 4"},{"status":"ACTIVE","sortPriority":4,"id":52385885,"name":"1 - 5"},{"status":"ACTIVE","sortPriority":5,"id":52385889,"name":"2 - 1"},{"status":"ACTIVE","sortPriority":6,"id":52385890,"name":"2 - 3"},{"status":"ACTIVE","sortPriority":7,"id":52385891,"name":"2 - 4"},{"status":"ACTIVE","sortPriority":8,"id":52385892,"name":"2 - 5"},{"status":"ACTIVE","sortPriority":9,"id":52385896,"name":"3 - 1"},{"status":"ACTIVE","sortPriority":10,"id":52385897,"name":"3 - 2"},{"status":"ACTIVE","sortPriority":11,"id":52385898,"name":"3 - 4"},{"status":"ACTIVE","sortPriority":12,"id":52385899,"name":"3 - 5"},{"status":"ACTIVE","sortPriority":13,"id":52385903,"name":"4 - 1"},{"status":"ACTIVE","sortPriority":14,"id":52385904,"name":"4 - 2"},{"status":"ACTIVE","sortPriority":15,"id":52385905,"name":"4 - 3"},{"status":"ACTIVE","sortPriority":16,"id":52385906,"name":"4 - 5"},{"status":"ACTIVE","sortPriority":17,"id":52385910,"name":"5 - 1"},{"status":"ACTIVE","sortPriority":18,"id":52385911,"name":"5 - 2"},{"status":"ACTIVE","sortPriority":19,"id":52385912,"name":"5 - 3"},{"status":"ACTIVE","sortPriority":20,"id":52385913,"name":"5 - 4"}],"regulators":["MR_INT"],"venue":"Perry Barr","countryCode":"GB","discountAllowed":true,"timezone":"Europe/London","openDate":"2024-06-27T13:29:00.000Z","version":5994794132,"name":"Forecast","eventName":"Perry Barr (F/C) 27th Jun"},"rc":[{"atb":[[1.01,237.06],[1.1,200]],"id":52385910},{"atl":[[1000,0.17]],"id":52385910},{"atb":[[1.01,237.06],[1.1,200]],"id":52385911},{"atl":[[1000,0.17]],"id":52385911},{"atb":[[1.01,204.08],[1.02,16.49],[1.1,200]],"id":52385912},{"atl":[[990,0.17]],"id":52385912},{"atb":[[1.01,204.08],[1.03,10.99],[1.1,200]],"id":52385913},{"atl":[[1000,0.17]],"id":52385913},{"atb":[[1.01,204.08],[1.03,10.99],[1.1,200]],"id":52385906},{"atl":[[1000,0.17]],"id":52385906},{"atb":[[1.01,204.08],[1.03,10.99],[1.1,200]],"id":52385889},{"atl":[[990,0.17]],"id":52385889},{"atb":[[1.01,237.06],[1.1,200]],"id":52385882},{"atl":[[990,0.17]],"id":52385882},{"atb":[[1.01,204.08],[1.02,16.49],[1.1,200]],"id":52385883},{"atl":[[990,0.17]],"id":52385883},{"atb":[[1.01,237.06],[1.1,200]],"id":52385884},{"atl":[[1000,0.17]],"id":52385884},{"atb":[[1.01,204.08],[1.02,16.49],[1.1,200]],"id":52385885},{"atl":[[990,0.17]],"id":52385885},{"atb":[[1.01,204.08],[1.02,16.49],[1.1,200]],"id":52385896},{"atl":[[990,0.17]],"id":52385896},{"atb":[[1.01,204.08],[1.03,10.99],[1.1,200]],"id":52385897},{"atl":[[990,0.17]],"id":52385897},{"atb":[[1.01,204.08],[1.02,16.49],[1.1,200]],"id":52385890},{"atl":[[1000,0.17]],"id":52385890},{"atb":[[1.01,237.06],[1.1,200]],"id":52385891},{"atl":[[990,0.17]],"id":52385891},{"atb":[[1.01,204.08],[1.03,10.99],[1.1,200]],"id":52385892},{"atl":[[990,0.17]],"id":52385892},{"atb":[[1.01,204.08],[1.03,10.99],[1.1,200]],"id":52385903},{"atl":[[990,0.17]],"id":52385903},{"atb":[[1.01,204.08],[1.03,10.99],[1.1,200]],"id":52385904},{"atl":[[990,0.17]],"id":52385904},{"atb":[[1.01,204.08],[1.02,16.49],[1.1,200]],"id":52385905},{"atl":[[990,0.17]],"id":52385905},{"atb":[[1.01,204.08],[1.02,16.49],[1.1,200]],"id":52385898},{"atl":[[990,0.17]],"id":52385898},{"atb":[[1.01,204.08],[1.03,10.99],[1.1,200]],"id":52385899},{"atl":[[1000,0.17]],"id":52385899}],"con":true,"img":true}]}
{"op":"mcm","clk":"11550558241","pt":1719499966149,"mc":[{"id":"1.230178174","rc":[{"atb":[[1.01,237.06],[1.03,1]],"id":52385910},{"atb":[[1.01,237.06],[1.03,1]],"id":52385911},{"atb":[[1.03,1],[1.02,16.49]],"id":52385912},{"atb":[[1.03,11.99]],"id":52385913},{"atb":[[1.03,11.99]],"id":52385906},{"atb":[[1.03,11.99]],"id":52385889},{"atb":[[1.01,237.06],[1.03,1]],"id":52385882},{"atb":[[1.03,1],[1.02,16.49]],"id":52385883},{"atb":[[1.01,237.06],[1.03,1]],"id":52385884},{"atb":[[1.03,1],[1.02,16.49]],"id":52385885},{"atb":[[1.03,1],[1.02,16.49]],"id":52385896},{"atb":[[1.03,11.99]],"id":52385897},{"atb":[[1.03,1],[1.02,16.49]],"id":52385890},{"atb":[[1.01,237.06],[1.03,1]],"id":52385891},{"atb":[[1.03,11.99]],"id":52385892},{"atb":[[1.03,11.99]],"id":52385903},{"atb":[[1.03,11.99]],"id":52385904},{"atb":[[1.03,1],[1.02,16.49]],"id":52385905},{"atb":[[1.03,1],[1.02,16.49]],"id":52385898},{"atb":[[1.03,11.99]],"id":52385899}],"con":true,"img":false}]}
{"op":"mcm","clk":"11550558251","pt":1719499966354,"mc":[{"id":"1.230178174","rc":[{"atb":[[1.03,0.9]],"id":52385910},{"atb":[[1.03,0.9]],"id":52385911},{"atb":[[1.03,0.9]],"id":52385912},{"atb":[[1.03,11.89]],"id":52385913},{"atb":[[1.03,11.89]],"id":52385906},{"atb":[[1.03,11.89]],"id":52385889},{"atb":[[1.03,0.9]],"id":52385882},{"atb":[[1.03,0.9]],"id":52385883},{"atb":[[1.03,0.9]],"id":52385884},{"atb":[[1.03,0.9]],"id":52385885},{"atb":[[1.03,0.9]],"id":52385896},{"atb":[[1.03,11.89]],"id":52385897},{"atb":[[1.03,0.9]],"id":52385890},{"atb":[[1.03,0.9]],"id":52385891},{"atb":[[1.03,11.89]],"id":52385892},{"atb":[[1.03,11.89]],"id":52385903},{"atb":[[1.03,11.89]],"id":52385904},{"atb":[[1.03,0.9]],"id":52385905},{"atb":[[1.03,0.9]],"id":52385898},{"atb":[[1.03,11.89]],"id":52385899}],"con":true,"img":false}]}
{"op":"mcm","clk":"11550558268","pt":1719499966663,"mc":[{"id":"1.230178174","rc":[{"atb":[[1.03,0]],"id":52385910},{"atb":[[1.03,0]],"id":52385911},{"atb":[[1.03,0]],"id":52385912},{"atb":[[1.03,10.99]],"id":52385913},{"atb":[[1.03,10.99]],"id":52385906},{"atb":[[1.03,10.99]],"id":52385889},{"atb":[[1.03,0]],"id":52385882},{"atb":[[1.03,0]],"id":52385883},{"atb":[[1.03,0]],"id":52385884},{"atb":[[1.03,0]],"id":52385885},{"atb":[[1.03,0]],"id":52385896},{"atb":[[1.03,10.99]],"id":52385897},{"atb":[[1.03,0]],"id":52385890},{"atb":[[1.03,0]],"id":52385891},{"atb":[[1.03,10.99]],"id":52385892},{"atb":[[1.03,10.99]],"id":52385903},{"atb":[[1.03,10.99]],"id":52385904},{"atb":[[1.03,0]],"id":52385905},{"atb":[[1.03,0]],"id":52385898},{"atb":[[1.03,10.99]],"id":52385899}],"con":true,"img":false}]}
{"op":"mcm","clk":"11550558279","pt":1719499966768,"mc":[{"id":"1.230178174","rc":[{"atb":[[3.05,0.9]],"id":52385910},{"atb":[[3.05,0.9]],"id":52385911},{"atb":[[3.05,0.9]],"id":52385912},{"atb":[[3.05,0.9]],"id":52385913},{"atb":[[3.05,0.9]],"id":52385906},{"atb":[[3.05,0.9]],"id":52385889},{"atb":[[3.05,0.9]],"id":52385882},{"atb":[[3.05,0.9]],"id":52385883},{"atb":[[3.05,0.9]],"id":52385884},{"atb":[[3.05,0.9]],"id":52385885},{"atb":[[3.05,0.9]],"id":52385896},{"atb":[[3.05,0.9]],"id":52385897},{"atb":[[3.05,0.9]],"id":52385890},{"atb":[[3.05,0.9]],"id":52385891},{"atb":[[3.05,0.9]],"id":52385892},{"atb":[[3.05,0.9]],"id":52385903},{"atb":[[3.05,0.9]],"id":52385904},{"atb":[[3.05,0.9]],"id":52385905},{"atb":[[3.05,0.9]],"id":52385898},{"atb":[[3.05,0.9]],"id":52385899}],"con":true,"img":false}]}
{"op":"mcm","clk":"11550559831","pt":1719499992185,"mc":[{"id":"1.230178174","marketDefinition":{"bspMarket":false,"turnInPlayEnabled":false,"persistenceEnabled":false,"marketBaseRate":5.0,"eventId":"33376048","eventTypeId":"4339","numberOfWinners":1,"bettingType":"ODDS","marketType":"FORECAST","marketTime":"2024-06-27T15:59:00.000Z","suspendTime":"2024-06-27T15:59:00.000Z","bspReconciled":false,"complete":true,"inPlay":false,"crossMatching":true,"runnersVoidable":false,"numberOfActiveRunners":20,"betDelay":0,"status":"OPEN","runners":[{"status":"ACTIVE","sortPriority":1,"id":52385882,"name":"1 - 2"},{"status":"ACTIVE","sortPriority":2,"id":52385883,"name":"1 - 3"},{"status":"ACTIVE","sortPriority":3,"id":52385884,"name":"1 - 4"},{"status":"ACTIVE","sortPriority":4,"id":52385885,"name":"1 - 5"},{"status":"ACTIVE","sortPriority":5,"id":52385889,"name":"2 - 1"},{"status":"ACTIVE","sortPriority":6,"id":52385890,"name":"2 - 3"},{"status":"ACTIVE","sortPriority":7,"id":52385891,"name":"2 - 4"},{"status":"ACTIVE","sortPriority":8,"id":52385892,"name":"2 - 5"},{"status":"ACTIVE","sortPriority":9,"id":52385896,"name":"3 - 1"},{"status":"ACTIVE","sortPriority":10,"id":52385897,"name":"3 - 2"},{"status":"ACTIVE","sortPriority":11,"id":52385898,"name":"3 - 4"},{"status":"ACTIVE","sortPriority":12,"id":52385899,"name":"3 - 5"},{"status":"ACTIVE","sortPriority":13,"id":52385903,"name":"4 - 1"},{"status":"ACTIVE","sortPriority":14,"id":52385904,"name":"4 - 2"},{"status":"ACTIVE","sortPriority":15,"id":52385905,"name":"4 - 3"},{"status":"ACTIVE","sortPriority":16,"id":52385906,"name":"4 - 5"},{"status":"ACTIVE","sortPriority":17,"id":52385910,"name":"5 - 1"},{"status":"ACTIVE","sortPriority":18,"id":52385911,"name":"5 - 2"},{"status":"ACTIVE","sortPriority":19,"id":52385912,"name":"5 - 3"},{"status":"ACTIVE","sortPriority":20,"id":52385913,"name":"5 - 4"}],"regulators":["MR_INT"],"venue":"Perry Barr","countryCode":"GB","discountAllowed":true,"timezone":"Europe/London","openDate":"2024-06-27T13:29:00.000Z","version":5994794132,"name":"Forecast","eventName":"Perry Barr (F/C) 27th Jun"},"rc":[],"con":true,"img":false}]}
{"op":"mcm","clk":"11550741851","pt":1719502734595,"mc":[{"id":"1.230178174","rc":[{"atb":[[1.01,237.06]],"id":52385910},{"atb":[[1.01,237.06]],"id":52385911},{"atb":[[1.02,16.49]],"id":52385912},{"atb":[[1.03,10.99]],"id":52385913},{"atb":[[1.03,10.99]],"id":52385906},{"atb":[[1.03,10.99]],"id":52385889},{"atb":[[1.01,237.06]],"id":52385882},{"atb":[[1.02,16.49]],"id":52385883},{"atb":[[1.01,237.06],[25,10.7]],"id":52385884},{"atb":[[1.02,16.49]],"id":52385885},{"atb":[[1.02,16.49]],"id":52385896},{"atb":[[1.03,10.99]],"id":52385897},{"atb":[[1.02,16.49]],"id":52385890},{"atb":[[1.01,237.06]],"id":52385891},{"atb":[[1.03,10.99]],"id":52385892},{"atb":[[1.03,10.99]],"id":52385903},{"atb":[[1.03,10.99]],"id":52385904},{"atb":[[1.02,16.49]],"id":52385905},{"atb":[[1.02,16.49]],"id":52385898},{"atb":[[1.03,10.99]],"id":52385899}],"con":true,"img":false}]}
{"op":"mcm","clk":"11550741864","pt":1719502734804,"mc":[{"id":"1.230178174","rc":[{"atb":[[25,0]],"id":52385884}],"con":true,"img":false}]}
{"op":"mcm","clk":"11550749393","pt":1719502862900,"mc":[{"id":"1.230178174","rc":[{"atb":[[11,9]],"id":52385910},{"atb":[[8,12]],"id":52385911},{"atb":[[9,11]],"id":52385912},{"atb":[[7,12]],"id":52385913},{"atb":[[7,12]],"id":52385906},{"atb":[[7,12]],"id":52385889},{"atb":[[10,10]],"id":52385882},{"atb":[[16,6]],"id":52385883},{"atb":[[16,6]],"id":52385884},{"atb":[[16,6]],"id":52385885},{"atb":[[13,8]],"id":52385896},{"atb":[[8,12]],"id":52385897},{"atb":[[8,12]],"id":52385890},{"atb":[[6,12]],"id":52385891},{"atb":[[6,12]],"id":52385892},{"atb":[[9,11]],"id":52385903},{"atb":[[6,12]],"id":52385904},{"atb":[[8,12]],"id":52385905},{"atb":[[9,11]],"id":52385898},{"atb":[[10,10]],"id":52385899}],"con":true,"img":false}]}
{"op":"mcm","clk":"11550749859","pt":1719502869656,"mc":[{"id":"1.230178174","rc":[{"atb":[[2,50]],"id":52385882},{"atb":[[2,50]],"id":52385883},{"atb":[[2,50]],"id":52385884},{"atb":[[2,50]],"id":52385897},{"atb":[[2,50]],"id":52385898}],"con":true,"img":false}]}
{"op":"mcm","clk":"11550749863","pt":1719502869752,"mc":[{"id":"1.230178174","rc":[{"atb":[[2,50]],"id":52385910},{"atb":[[2,50]],"id":52385906},{"atb":[[2,50]],"id":52385889},{"atb":[[2,50]],"id":52385885},{"atb":[[2,50]],"id":52385896},{"atb":[[2,50]],"id":52385891},{"atb":[[2,50]],"id":52385903},{"atb":[[2,50]],"id":52385904},{"atb":[[2,50]],"id":52385905},{"atb":[[2,50]],"id":52385899}],"con":true,"img":false}]}
{"op":"mcm","clk":"11550749870","pt":1719502869860,"mc":[{"id":"1.230178174","rc":[{"atb":[[2,50]],"id":52385912}],"con":true,"img":false}]}
{"op":"mcm","clk":"11550749878","pt":1719502869962,"mc":[{"id":"1.230178174","rc":[{"atb":[[2,50]],"id":52385911},{"atb":[[2,50]],"id":52385890},{"atb":[[2,50]],"id":52385892}],"con":true,"img":false}]}
{"op":"mcm","clk":"11550749907","pt":1719502870370,"mc":[{"id":"1.230178174","rc":[{"atb":[[2,50]],"id":52385913}],"con":true,"img":false}]}
{"op":"mcm","clk":"11550750193","pt":1719502874857,"mc":[{"id":"1.230178174","rc":[{"atb":[[2,0]],"id":52385897}],"con":true,"img":false}]}
{"op":"mcm","clk":"11550750221","pt":1719502875369,"mc":[{"id":"1.230178174","rc":[{"atb":[[2,0]],"id":52385884}],"con":true,"img":false}]}
{"op":"mcm","clk":"11550750229","pt":1719502875599,"mc":[{"id":"1.230178174","rc":[{"atb":[[2,0]],"id":52385882}],"con":true,"img":false}]}
{"op":"mcm","clk":"11550750236","pt":1719502875784,"mc":[{"id":"1.230178174","rc":[{"atb":[[2,0]],"id":52385898}],"con":true,"img":false}]}
{"op":"mcm","clk":"11550750255","pt":1719502876248,"mc":[{"id":"1.230178174","rc":[{"atb":[[2,0]],"id":52385913}],"con":true,"img":false}]}
{"op":"mcm","clk":"11550750269","pt":1719502876581,"mc":[{"id":"1.230178174","rc":[{"atb":[[2,0]],"id":52385911}],"con":true,"img":false}]}
{"op":"mcm","clk":"11550750279","pt":1719502876771,"mc":[{"id":"1.230178174","rc":[{"atb":[[2,0]],"id":52385890}],"con":true,"img":false}]}
{"op":"mcm","clk":"11550750291","pt":1719502876963,"mc":[{"id":"1.230178174","rc":[{"atb":[[2,0]],"id":52385892}],"con":true,"img":false}]}
{"op":"mcm","clk":"11550750315","pt":1719502877439,"mc":[{"id":"1.230178174","rc":[{"atb":[[2,0]],"id":52385912}],"con":true,"img":false}]}
{"op":"mcm","clk":"11550750337","pt":1719502877763,"mc":[{"id":"1.230178174","rc":[{"atb":[[2,0]],"id":52385899}],"con":true,"img":false}]}
{"op":"mcm","clk":"11550750347","pt":1719502877966,"mc":[{"id":"1.230178174","rc":[{"atb":[[2,0]],"id":52385885}],"con":true,"img":false}]}
{"op":"mcm","clk":"11550750355","pt":1719502878171,"mc":[{"id":"1.230178174","rc":[{"atb":[[2,0]],"id":52385904}],"con":true,"img":false}]}
{"op":"mcm","clk":"11550750365","pt":1719502878373,"mc":[{"id":"1.230178174","rc":[{"atb":[[2,0]],"id":52385889}],"con":true,"img":false}]}
{"op":"mcm","clk":"11550750385","pt":1719502878580,"mc":[{"id":"1.230178174","rc":[{"atb":[[2,0]],"id":52385891}],"con":true,"img":false}]}
{"op":"mcm","clk":"11550750401","pt":1719502878799,"mc":[{"id":"1.230178174","rc":[{"atb":[[2,0]],"id":52385905}],"con":true,"img":false}]}
{"op":"mcm","clk":"11550750417","pt":1719502878994,"mc":[{"id":"1.230178174","rc":[{"atb":[[2,0]],"id":52385896}],"con":true,"img":false}]}
{"op":"mcm","clk":"11550750445","pt":1719502879478,"mc":[{"id":"1.230178174","rc":[{"atb":[[2,0]],"id":52385906}],"con":true,"img":false}]}
{"op":"mcm","clk":"11550750454","pt":1719502879567,"mc":[{"id":"1.230178174","rc":[{"atb":[[2,0]],"id":52385903}],"con":true,"img":false}]}
{"op":"mcm","clk":"11550750470","pt":1719502879776,"mc":[{"id":"1.230178174","rc":[{"atb":[[2,0]],"id":52385910}],"con":true,"img":false}]}
{"op":"mcm","clk":"11550750487","pt":1719502879978,"mc":[{"id":"1.230178174","rc":[{"atb":[[2,0]],"id":52385883}],"con":true,"img":false}]}
{"op":"mcm","clk":"11550751637","pt":1719502901909,"mc":[{"id":"1.230178174","rc":[{"atb":[[11,0]],"id":52385910}],"con":true,"img":false}]}
{"op":"mcm","clk":"11550751645","pt":1719502902007,"mc":[{"id":"1.230178174","rc":[{"atb":[[10,9]],"id":52385910}],"con":true,"img":false}]}
{"op":"mcm","clk":"11550758687","pt":1719503040257,"mc":[{"id":"1.230178174","rc":[{"atb":[[7,16.67]],"id":52385910},{"atl":[[500,2]],"id":52385910},{"atb":[[6,20]],"id":52385912},{"atl":[[460,2]],"id":52385912},{"atb":[[4.7,24]],"id":52385913},{"atl":[[330,2]],"id":52385913},{"atb":[[4.2,24]],"id":52385906},{"atl":[[250,2]],"id":52385906},{"atb":[[5.3,23.26]],"id":52385889},{"atl":[[430,2]],"id":52385889},{"atb":[[9.4,11.9]],"id":52385882},{"atl":[[570,2]],"id":52385882},{"atb":[[14.5,7.41]],"id":52385883},{"atl":[[740,2]],"id":52385883},{"atb":[[10,11.11]],"id":52385884},{"atl":[[610,2]],"id":52385884},{"atb":[[9.4,11.9]],"id":52385885},{"atl":[[570,2]],"id":52385885},{"atb":[[10.5,10.53]],"id":52385896},{"atl":[[660,2]],"id":52385896},{"atb":[[7.4,15.62]],"id":52385897},{"atl":[[510,2]],"id":52385897},{"atb":[[5.2,23.81]],"id":52385890},{"atl":[[410,2]],"id":52385890},{"atb":[[4.4,29.41]],"id":52385891},{"atl":[[280,2]],"id":52385891},{"atb":[[4,24]],"id":52385892},{"atl":[[220,2]],"id":52385892},{"atb":[[6.8,17.24]],"id":52385903},{"atl":[[490,2]],"id":52385903},{"atb":[[4.7,24]],"id":52385904},{"atl":[[330,2]],"id":52385904},{"atb":[[5.8,20.83]],"id":52385905},{"atl":[[450,2]],"id":52385905},{"atb":[[7.8,14.71]],"id":52385898},{"atl":[[510,2]],"id":52385898},{"atb":[[6.8,17.24]],"id":52385899},{"atl":[[480,2]],"id":52385899}],"con":true,"img":false}]}
{"op":"mcm","clk":"11550758696","pt":1719503040362,"mc":[{"id":"1.230178174","rc":[{"atb":[[4.8,26.32]],"id":52385911},{"atl":[[350,2]],"id":52385911}],"con":true,"img":false}]}
{"op":"mcm","clk":"11550758821","pt":1719503042980,"mc":[{"id":"1.230178174","rc":[{"atb":[[8,0]],"id":52385890}],"con":true,"img":false}]}
{"op":"mcm","clk":"11550758827","pt":1719503043082,"mc":[{"id":"1.230178174","rc":[{"atb":[[7,12]],"id":52385890}],"con":true,"img":false}]}
{"op":"mcm","clk":"11550764325","pt":1719503145869,"mc":[{"id":"1.230178174","rc":[{"atb":[[27,5]],"id":52385896}],"con":true,"img":false}]}
{"op":"mcm","clk":"11550764400","pt":1719503147175,"mc":[{"id":"1.230178174","rc":[{"atb":[[27,0]],"id":52385896}],"con":true,"img":false}]}
{"op":"mcm","clk":"11550766486","pt":1719503182351,"mc":[{"id":"1.230178174","rc":[{"atl":[[490,2],[500,0]],"id":52385910},{"atl":[[350,0],[340,2]],"id":52385911},{"atl":[[460,0],[450,2]],"id":52385912},{"atl":[[330,0],[320,2]],"id":52385913},{"atl":[[240,2],[250,0]],"id":52385906},{"atb":[[5.3,0],[5.9,20.41]],"id":52385889},{"atl":[[410,2],[430,0]],"id":52385889},{"atb":[[10.5,10],[9.4,0]],"id":52385882},{"atl":[[570,0],[550,2]],"id":52385882},{"atb":[[16,12],[14.5,0]],"id":52385883},{"atl":[[700,2],[740,0]],"id":52385883},{"atb":[[10,0],[11.5,9.52]],"id":52385884},{"atl":[[580,2],[610,0]],"id":52385884},{"atb":[[10,11.11],[9.4,0]],"id":52385885},{"atl":[[570,0],[550,2]],"id":52385885},{"atb":[[10.5,0],[12,9.09]],"id":52385896},{"atl":[[620,2],[660,0]],"id":52385896},{"atb":[[8.2,12],[7.4,0]],"id":52385897},{"atl":[[490,2],[510,0]],"id":52385897},{"atb":[[5.2,0],[5.7,21.28]],"id":52385890},{"atl":[[390,2],[410,0]],"id":52385890},{"atb":[[4.4,0],[4.7,27.03]],"id":52385891},{"atl":[[280,0],[250,2]],"id":52385891},{"atl":[[210,2],[220,0]],"id":52385892},{"atb":[[7.4,15.62],[6.8,0]],"id":52385903},{"atl":[[460,2],[490,0]],"id":52385903},{"atb":[[5.1,24],[4.7,0]],"id":52385904},{"atl":[[310,2],[330,0]],"id":52385904},{"atb":[[6.4,18.52],[5.8,0]],"id":52385905},{"atl":[[430,2],[450,0]],"id":52385905},{"atb":[[8.6,13.16],[7.8,0]],"id":52385898},{"atl":[[510,0],[500,2]],"id":52385898},{"atb":[[7.4,15.62],[6.8,0]],"id":52385899},{"atl":[[470,2],[480,0]],"id":52385899}],"con":true,"img":false}]}
{"op":"mcm","clk":"11550766493","pt":1719503182415,"mc":[{"id":"1.230178174","rc":[{"atb":[[8.2,13.89],[7,0]],"id":52385910},{"atb":[[4.8,0],[5.4,22.73]],"id":52385911},{"atb":[[6,0],[7,16.67]],"id":52385912},{"atb":[[5.2,23.81],[4.7,0]],"id":52385913},{"atb":[[5.2,16.49]],"id":52385883},{"atl":[[490,0],[480,2]],"id":52385897}],"con":true,"img":false}]}
{"op":"mcm","clk":"11550766499","pt":1719503182527,"mc":[{"id":"1.230178174","rc":[{"atb":[[16,6]],"id":52385883},{"atl":[[490,2],[500,0]],"id":52385898}],"con":true,"img":false}]}
{"op":"mcm","clk":"11550766524","pt":1719503182937,"mc":[{"id":"1.230178174","rc":[{"atl":[[490,0],[480,2]],"id":52385910},{"atl":[[330,2],[340,0]],"id":52385911},{"atl":[[440,2],[450,0]],"id":52385912},{"atl":[[310,2]],"id":52385913},{"atl":[[230,2],[240,0]],"id":52385906},{"atb":[[5.5,22.22],[5.9,0]],"id":52385889},{"atb":[[9.6,11.63],[10,0],[10.5,0]],"id":52385882},{"atb":[[5.2,0],[4.9,22.49]],"id":52385883},{"atl":[[700,0],[710,2]],"id":52385883},{"atl":[[580,0],[590,2]],"id":52385884},{"atb":[[10.5,10.53],[12,0]],"id":52385896},{"atl":[[620,0],[630,2]],"id":52385896},{"atb":[[8,0],[8.2,0],[7.6,15.15]],"id":52385897},{"atl":[[480,0],[490,2]],"id":52385897},{"atb":[[5.3,23.26],[5.7,0]],"id":52385890},{"atl":[[390,0],[400,2]],"id":52385890},{"atl":[[260,2],[250,0]],"id":52385891},{"atl":[[200,2],[210,0]],"id":52385892},{"atl":[[460,0],[470,2]],"id":52385903},{"atl":[[310,0],[320,2]],"id":52385904},{"atb":[[8.6,0],[7.8,14.71]],"id":52385898},{"atl":[[490,0],[500,2]],"id":52385898}],"con":true,"img":false}]}
{"op":"mcm","clk":"11550766532","pt":1719503183049,"mc":[{"id":"1.230178174","rc":[{"atl":[[320,0]],"id":52385913},{"atb":[[13,10]],"id":52385882},{"atb":[[9,12]],"id":52385897}],"con":true,"img":false}]}
{"op":"mcm","clk":"11550766538","pt":1719503183142,"mc":[{"id":"1.230178174","rc":[{"atb":[[8.2,0],[6.8,17.24]],"id":52385910},{"atb":[[4.7,27.03]],"id":52385911},{"atb":[[7,0],[5.9,20.41]],"id":52385912},{"atb":[[4.6,27.78]],"id":52385913}],"con":true,"img":false}]}
{"op":"mcm","clk":"11550766547","pt":1719503183250,"mc":[{"id":"1.230178174","rc":[{"atb":[[8,14.29],[6.8,0]],"id":52385910},{"atb":[[5.3,23.26],[5.4,0],[4.7,0]],"id":52385911},{"atb":[[6.8,17.24],[5.9,0]],"id":52385912},{"atb":[[5.1,24.39],[4.6,0],[5.2,0]],"id":52385913}],"con":true,"img":false}]}
{"op":"mcm","clk":"11550766587","pt":1719503184131,"mc":[{"id":"1.230178174","rc":[{"atl":[[48,5]],"id":52385898}],"con":true,"img":false}]}
{"op":"mcm","clk":"11550766596","pt":1719503184336,"mc":[{"id":"1.230178174","rc":[{"atl":[[48,0]],"id":52385898}],"con":true,"img":false}]}
{"op":"mcm","clk":"11550767001","pt":1719503191666,"mc":[{"id":"1.230178174","rc":[{"atb":[[5.5,0],[6,20]],"id":52385889},{"atb":[[9.6,0],[10.5,10.53]],"id":52385882},{"atb":[[16.5,6],[4.9,0]],"id":52385883},{"atb":[[10.5,0],[12.5,8.7]],"id":52385896},{"atb":[[7.6,0],[8.4,13.51]],"id":52385897},{"atb":[[5.8,20.83],[5.3,0]],"id":52385890},{"atb":[[8.8,12.82],[7.8,0]],"id":52385898}],"con":true,"img":false}]}
{"op":"mcm","clk":"11550767093","pt":1719503192951,"mc":[{"id":"1.230178174","rc":[{"atb":[[16,0]],"id":52385883}],"con":true,"img":false}]}
{"op":"mcm","clk":"11550767100","pt":1719503193052,"mc":[{"id":"1.230178174","rc":[{"atb":[[20,6]],"id":52385883}],"con":true,"img":false}]}
{"op":"mcm","clk":"11550767319","pt":1719503196572,"mc":[{"id":"1.230178174","rc":[{"atl":[[700,2]],"id":52385883}],"con":true,"img":false}]}
{"op":"mcm","clk":"11550767327","pt":1719503196669,"mc":[{"id":"1.230178174","rc":[{"atb":[[8,0],[6.8,17.24]],"id":52385910},{"atl":[[480,0],[490,2]],"id":52385910},{"atb":[[5.3,0],[4.7,27.03]],"id":52385911},{"atl":[[330,0],[340,2]],"id":52385911},{"atl":[[440,0],[450,2]],"id":52385912},{"atl":[[310,0],[320,2]],"id":52385913},{"atl":[[230,0],[240,2]],"id":52385906},{"atl":[[710,0]],"id":52385883},{"atl":[[590,0],[580,2]],"id":52385884},{"atl":[[630,0],[620,2]],"id":52385896},{"atl":[[490,0],[480,2]],"id":52385897},{"atl":[[390,2],[400,0]],"id":52385890},{"atl":[[260,0],[250,2]],"id":52385891},{"atl":[[200,0],[210,2]],"id":52385892},{"atl":[[460,2],[470,0]],"id":52385903},{"atl":[[310,2],[320,0]],"id":52385904},{"atb":[[8.6,13.16],[8.8,0]],"id":52385898},{"atl":[[490,2],[500,0]],"id":52385898}],"con":true,"img":false}]}
{"op":"mcm","clk":"11550767342","pt":1719503196840,"mc":[{"id":"1.230178174","rc":[{"atb":[[6,0],[5.9,20.41]],"id":52385889},{"atb":[[12,9.09],[12.5,0]],"id":52385896},{"atb":[[8.2,13.89],[8.4,0]],"id":52385897}],"con":true,"img":false}]}
{"op":"mcm","clk":"11550767365","pt":1719503197153,"mc":[{"id":"1.230178174","rc":[{"atb":[[9.6,11.63],[10.5,0]],"id":52385882},{"atb":[[16.5,0],[14.5,7.41]],"id":52385883},{"atb":[[5.8,0],[5.3,23.26]],"id":52385890},{"atb":[[8.6,0],[7.8,14.71]],"id":52385898}],"con":true,"img":false}]}
{"op":"mcm","clk":"11550767679","pt":1719503201974,"mc":[{"id":"1.230178174","rc":[{"atb":[[5.5,22.22]],"id":52385889},{"atb":[[13,0]],"id":52385882},{"atl":[[700,0],[710,2]],"id":52385883},{"atl":[[580,0],[590,2]],"id":52385884},{"atb":[[10.5,10.53],[12,0]],"id":52385896},{"atl":[[620,0],[630,2]],"id":52385896},{"atb":[[8.2,0],[7.6,15.15]],"id":52385897},{"atl":[[480,0],[490,2]],"id":52385897},{"atl":[[390,0],[400,2]],"id":52385890},{"atl":[[260,2],[250,0]],"id":52385891},{"atl":[[460,0],[470,2]],"id":52385903},{"atl":[[310,0],[320,2]],"id":52385904},{"atl":[[490,0],[500,2]],"id":52385898}],"con":true,"img":false}]}
{"op":"mcm","clk":"11550767685","pt":1719503202040,"mc":[{"id":"1.230178174","rc":[{"atb":[[5.9,0]],"id":52385889},{"atb":[[11,10]],"id":52385882}],"con":true,"img":false}]}
{"op":"mcm","clk":"11550767853","pt":1719503205286,"mc":[{"id":"1.230178174","rc":[{"atb":[[8,14.29],[6.8,0]],"id":52385910},{"atl":[[490,0],[480,2]],"id":52385910},{"atb":[[5.3,23.26]],"id":52385911},{"atl":[[330,2],[340,0]],"id":52385911},{"atl":[[440,2],[450,0]],"id":52385912},{"atl":[[310,2],[320,0]],"id":52385913},{"atl":[[230,2],[240,0]],"id":52385906},{"atl":[[200,2],[210,0]],"id":52385892}],"con":true,"img":false}]}
{"op":"mcm","clk":"11550767858","pt":1719503205340,"mc":[{"id":"1.230178174","rc":[{"atb":[[4.7,0]],"id":52385911}],"con":true,"img":false}]}
{"op":"mcm","clk":"11550767877","pt":1719503205757,"mc":[{"id":"1.230178174","rc":[{"atb":[[9.6,0],[10.5,10.53]],"id":52385882},{"atb":[[16.5,6.45],[14.5,0]],"id":52385883},{"atb":[[5.8,20.83],[5.3,0]],"id":52385890},{"atb":[[8.8,12.82],[7.8,0]],"id":52385898}],"con":true,"img":false}]}
{"op":"mcm","clk":"11550768179","pt":1719503210462,"mc":[{"id":"1.230178174","rc":[{"atb":[[6,20]],"id":52385889},{"atb":[[12.5,8.7]],"id":52385896},{"atb":[[7.6,0],[8.4,13.51]],"id":52385897}],"con":true,"img":false}]}
{"op":"mcm","clk":"11550768184","pt":1719503210570,"mc":[{"id":"1.230178174","rc":[{"atb":[[5.5,0]],"id":52385889},{"atb":[[10.5,0]],"id":52385896}],"con":true,"img":false}]}
{"op":"mcm","clk":"11550768229","pt":1719503211193,"mc":[{"id":"1.230178174","rc":[{"atb":[[6.8,17.24]],"id":52385910},{"atl":[[490,2]],"id":52385910},{"atb":[[5.3,0],[4.7,27.03]],"id":52385911},{"atl":[[330,0],[340,2]],"id":52385911},{"atl":[[440,0],[450,2]],"id":52385912},{"atl":[[310,0],[320,2]],"id":52385913},{"atl":[[230,0],[240,2]],"id":52385906},{"atb":[[6,0]],"id":52385889},{"atl":[[700,2],[710,0]],"id":52385883},{"atl":[[590,0],[580,2]],"id":52385884},{"atl":[[630,0],[620,2]],"id":52385896},{"atl":[[390,2],[400,0]],"id":52385890},{"atl":[[260,0],[250,2]],"id":52385891},{"atl":[[200,0],[210,2]],"id":52385892},{"atl":[[460,2],[470,0]],"id":52385903},{"atl":[[310,2],[320,0]],"id":52385904},{"atb":[[8.6,13.16],[8.8,0]],"id":52385898}],"con":true,"img":false}]}
{"op":"mcm","clk":"11550768238","pt":1719503211296,"mc":[{"id":"1.230178174","rc":[{"atb":[[8,0]],"id":52385910},{"atl":[[480,0]],"id":52385910},{"atb":[[5.9,20.41]],"id":52385889},{"atl":[[490,0],[480,2]],"id":52385897},{"atl":[[490,2],[500,0]],"id":52385898}],"con":true,"img":false}]}
{"op":"mcm","clk":"11550768512","pt":1719503215597,"mc":[{"id":"1.230178174","rc":[{"atb":[[12,9.09],[12.5,0]],"id":52385896},{"atb":[[8.2,13.89],[8.4,0]],"id":52385897}],"con":true,"img":false}]}
{"op":"mcm","clk":"11550768634","pt":1719503217554,"mc":[{"id":"1.230178174","rc":[{"atb":[[5.5,22.22],[5.9,0]],"id":52385889},{"atb":[[9.6,11.63],[10.5,0]],"id":52385882},{"atb":[[16.5,0],[14.5,7.41]],"id":52385883},{"atl":[[700,0],[710,2]],"id":52385883},{"atl":[[580,0],[590,2]],"id":52385884},{"atb":[[10.5,10.53],[12,0]],"id":52385896},{"atl":[[620,0],[630,2]],"id":52385896},{"atb":[[8.2,0],[7.6,15.15]],"id":52385897},{"atl":[[480,0],[490,2]],"id":52385897},{"atb":[[5.8,0],[5.3,23.26]],"id":52385890},{"atl":[[390,0],[400,2]],"id":52385890},{"atl":[[260,2],[250,0]],"id":52385891},{"atl":[[460,0],[470,2]],"id":52385903},{"atl":[[310,0],[320,2]],"id":52385904},{"atb":[[8.6,0],[7.8,14.71]],"id":52385898},{"atl":[[490,0],[500,2]],"id":52385898}],"con":true,"img":false}]}
{"op":"mcm","clk":"11550768782","pt":1719503219591,"mc":[{"id":"1.230178174","rc":[{"atb":[[4.7,0],[5.4,22.73]],"id":52385911},{"atl":[[590,0],[580,2]],"id":52385884},{"atl":[[250,2]],"id":52385891}],"con":true,"img":false}]}
{"op":"mcm","clk":"11550768788","pt":1719503219695,"mc":[{"id":"1.230178174","rc":[{"atb":[[8.2,13.89],[6.8,0]],"id":52385910},{"atl":[[260,0]],"id":52385891}],"con":true,"img":false}]}
{"op":"mcm","clk":"11550768844","pt":1719503220379,"mc":[{"id":"1.230178174","rc":[{"atb":[[7.2,8]],"id":52385913},{"atl":[[19.5,8]],"id":52385913},{"atb":[[9.8,8]],"id":52385889},{"atl":[[150,4.03]],"id":52385889},{"atb":[[24,8]],"id":52385885},{"atl":[[100,6.06]],"id":52385885},{"atb":[[16,4.36]],"id":52385897},{"atl":[[36,4.36]],"id":52385897},{"atb":[[6.2,8]],"id":52385892},{"atl":[[200,3.02]],"id":52385892},{"atb":[[9.2,5.8]],"id":52385903},{"atl":[[38,5.8]],"id":52385903},{"atb":[[9,5.8]],"id":52385904},{"atl":[[980,0.61]],"id":52385904},{"atb":[[16,8]],"id":52385905},{"atl":[[27,8]],"id":52385905},{"atb":[[18,4.36]],"id":52385898},{"atl":[[190,3.17]],"id":52385898},{"atb":[[20,8]],"id":52385899},{"atl":[[38,8]],"id":52385899}],"con":true,"img":false}]}
{"op":"mcm","clk":"11550768854","pt":1719503220492,"mc":[{"id":"1.230178174","rc":[{"atb":[[10.5,8]],"id":52385910},{"atl":[[65,8]],"id":52385910},{"atb":[[4.8,2.5],[4.4,5]],"id":52385911},{"atl":[[24,2.5],[28,5]],"id":52385911},{"atb":[[9.2,8],[10.5,2.5],[9.4,5]],"id":52385912},{"atl":[[38,2.5],[80,7.59],[46,5]],"id":52385912},{"atb":[[5.8,2.5],[5.4,5]],"id":52385913},{"atl":[[34,3.03],[24,2.5],[28,5]],"id":52385913},{"atb":[[5.1,5],[5.5,2.5],[7,20]],"id":52385906},{"atl":[[18.5,8],[25,2.5],[29,5]],"id":52385906},{"atb":[[8.6,2.5],[7.8,5]],"id":52385889},{"atl":[[36,5],[410,0],[29,2.5]],"id":52385889},{"atb":[[18.5,5],[21,2.5],[26,8]],"id":52385882},{"atl":[[65,2.5],[80,7.59],[85,5]],"id":52385882},{"atb":[[32,5],[40,2.5],[46,4.36]],"id":52385883},{"atl":[[130,2.5],[150,4.03],[170,5]],"id":52385883},{"atb":[[22,5],[26,2.5],[30,8]],"id":52385884},{"atl":[[80,2.5],[95,6.38],[100,5]],"id":52385884},{"atb":[[19.5,5],[23,2.5]],"id":52385885},{"atl":[[150,2],[85,2.5],[110,5]],"id":52385885},{"atb":[[42,4.36],[21,5],[25,2.5]],"id":52385896},{"atl":[[150,5],[110,2.5],[120,4.36]],"id":52385896},{"atb":[[5.6,2.5],[12,4.36],[5.2,5]],"id":52385890},{"atl":[[25,2.5],[29,5],[990,0.61]],"id":52385890},{"atl":[[210,0]],"id":52385892},{"atb":[[4.5,5],[4.9,2.5]],"id":52385904},{"atl":[[21,2.5],[25,5]],"id":52385904},{"atb":[[10,2.5],[9.2,5]],"id":52385905},{"atl":[[65,2],[36,2.5],[44,5],[430,0]],"id":52385905},{"atb":[[12,5],[14,2.5]],"id":52385898},{"atl":[[65,5],[48,2.5]],"id":52385898},{"atb":[[10,15],[12,2.5]],"id":52385899},{"atl":[[75,5],[55,2.5]],"id":52385899}],"con":true,"img":false}]}
{"op":"mcm","clk":"11550768858","pt":1719503220588,"mc":[{"id":"1.230178174","rc":[{"atb":[[10,14],[12,2.5]],"id":52385910},{"atl":[[75,5],[55,2.5]],"id":52385910},{"atb":[[10,8]],"id":52385911},{"atl":[[330,1.82]],"id":52385911},{"atl":[[320,0]],"id":52385913},{"atl":[[140,2]],"id":52385889},{"atl":[[550,0]],"id":52385885},{"atb":[[9,17],[9.8,2.5]],"id":52385897},{"atl":[[44,2.5],[55,5]],"id":52385897},{"atb":[[4.5,2.5],[6.2,8],[4.1,5]],"id":52385891},{"atl":[[16.5,2.5],[18.5,5],[240,2.51]],"id":52385891},{"atb":[[4,26.5],[3.8,5]],"id":52385892},{"atl":[[16,5],[190,2],[14,2.5]],"id":52385892},{"atb":[[9.2,10.8],[10,2.5]],"id":52385903},{"atl":[[65,5],[48,2.5]],"id":52385903},{"atl":[[38,0],[85,2],[470,0]],"id":52385899}],"con":true,"img":false}]}
{"op":"mcm","clk":"11550768865","pt":1719503220691,"mc":[{"id":"1.230178174","rc":[{"atl":[[95,2]],"id":52385910},{"atl":[[38,2.7]],"id":52385911},{"atl":[[75,2]],"id":52385912},{"atl":[[24,4.35]],"id":52385906},{"atl":[[150,2]],"id":52385882},{"atl":[[180,2]],"id":52385884}],"con":true,"img":false}]}
{"op":"mcm","clk":"11550768872","pt":1719503220795,"mc":[{"id":"1.230178174","rc":[{"atl":[[490,0]],"id":52385910},{"atl":[[38,0],[330,3.82],[340,0]],"id":52385911},{"atl":[[450,0]],"id":52385912},{"atl":[[24,0],[29,8.57],[240,0]],"id":52385906},{"atl":[[550,0]],"id":52385882},{"atl":[[580,0]],"id":52385884},{"atl":[[50,12.24]],"id":52385899}],"con":true,"img":false}]}
{"op":"mcm","clk":"11550768876","pt":1719503220850,"mc":[{"id":"1.230178174","rc":[{"atl":[[38,2.7]],"id":52385911},{"atl":[[25,6.67]],"id":52385906}],"con":true,"img":false}]}
{"op":"mcm","clk":"11550768882","pt":1719503220954,"mc":[{"id":"1.230178174","rc":[{"atl":[[330,1.82]],"id":52385911},{"atl":[[29,5]],"id":52385906}],"con":true,"img":false}]}
{"op":"mcm","clk":"11550768904","pt":1719503221371,"mc":[{"id":"1.230178174","rc":[{"atb":[[11,0]],"id":52385882}],"con":true,"img":false}]}
{"op":"mcm","clk":"11550768917","pt":1719503221679,"mc":[{"id":"1.230178174","rc":[{"atb":[[20,0]],"id":52385883}],"con":true,"img":false}]}
{"op":"mcm","clk":"11550768931","pt":1719503221887,"mc":[{"id":"1.230178174","rc":[{"atb":[[16,0]],"id":52385884}],"con":true,"img":false}]}
{"op":"mcm","clk":"11550768941","pt":1719503222095,"mc":[{"id":"1.230178174","rc":[{"atb":[[16,0]],"id":52385885}],"con":true,"img":false}]}
{"op":"mcm","clk":"11550768953","pt":1719503222302,"mc":[{"id":"1.230178174","rc":[{"atb":[[7,0]],"id":52385889}],"con":true,"img":false}]}
{"op":"mcm","clk":"11550768973","pt":1719503222472,"mc":[{"id":"1.230178174","rc":[{"atb":[[13,0]],"id":52385896}],"con":true,"img":false}]}
{"op":"mcm","clk":"11550768986","pt":1719503222776,"mc":[{"id":"1.230178174","rc":[{"atb":[[9,0]],"id":52385898}],"con":true,"img":false}]}
{"op":"mcm","clk":"11550769004","pt":1719503223083,"mc":[{"id":"1.230178174","rc":[{"atb":[[8,0]],"id":52385905}],"con":true,"img":false}]}
{"op":"mcm","clk":"11550769014","pt":1719503223290,"mc":[{"id":"1.230178174","rc":[{"atb":[[9,0]],"id":52385912}],"con":true,"img":false}]}
{"op":"mcm","clk":"11550769028","pt":1719503223597,"mc":[{"id":"1.230178174","rc":[{"atb":[[10,5]],"id":52385910},{"atb":[[7,0]],"id":52385913},{"atb":[[9,5]],"id":52385897},{"atb":[[7,0]],"id":52385890},{"atb":[[9,0]],"id":52385903},{"atb":[[6,0]],"id":52385904},{"atb":[[10,5]],"id":52385899}],"con":true,"img":false}]}
{"op":"mcm","clk":"11550769033","pt":1719503223701,"mc":[{"id":"1.230178174","rc":[{"atb":[[13,9]],"id":52385910},{"atb":[[8,12]],"id":52385913},{"atb":[[10,12]],"id":52385897},{"atb":[[9,12]],"id":52385890},{"atb":[[11,11]],"id":52385903},{"atb":[[7,12]],"id":52385904},{"atb":[[14,10]],"id":52385899}],"con":true,"img":false}]}
{"op":"mcm","clk":"11550769042","pt":1719503223758,"mc":[{"id":"1.230178174","rc":[{"atb":[[7.2,0],[8.2,26]],"id":52385913}],"con":true,"img":false}]}
{"op":"mcm","clk":"11550769065","pt":1719503224276,"mc":[{"id":"1.230178174","rc":[{"atb":[[12,8]],"id":52385912}],"con":true,"img":false}]}
{"op":"mcm","clk":"11550769092","pt":1719503224759,"mc":[{"id":"1.230178174","rc":[{"atb":[[16,0]],"id":52385905}],"con":true,"img":false}]}
{"op":"mcm","clk":"11550769098","pt":1719503224863,"mc":[{"id":"1.230178174","rc":[{"atb":[[4.2,0],[4.7,24]],"id":52385906},{"atb":[[16,15]],"id":52385905}],"con":true,"img":false}]}
{"op":"mcm","clk":"11550769106","pt":1719503224970,"mc":[{"id":"1.230178174","rc":[{"atb":[[26,0]],"id":52385882},{"atb":[[46,0]],"id":52385883}],"con":true,"img":false}]}
{"op":"mcm","clk":"11550769119","pt":1719503225180,"mc":[{"id":"1.230178174","rc":[{"atb":[[23,15]],"id":52385882},{"atb":[[40,15.56]],"id":52385883}],"con":true,"img":false}]}
{"op":"mcm","clk":"11550769133","pt":1719503225388,"mc":[{"id":"1.230178174","rc":[{"atb":[[30,0]],"id":52385884}],"con":true,"img":false}]}
{"op":"mcm","clk":"11550769138","pt":1719503225487,"mc":[{"id":"1.230178174","rc":[{"atb":[[32,19.35]],"id":52385884}],"con":true,"img":false}]}
{"op":"mcm","clk":"11550769144","pt":1719503225592,"mc":[{"id":"1.230178174","rc":[{"atb":[[42,0]],"id":52385896}],"con":true,"img":false}]}
{"op":"mcm","clk":"11550769151","pt":1719503225695,"mc":[{"id":"1.230178174","rc":[{"atb":[[32,0]],"id":52385884},{"atb":[[38,13.72]],"id":52385896}],"con":true,"img":false}]}
{"op":"mcm","clk":"11550769163","pt":1719503225903,"mc":[{"id":"1.230178174","rc":[{"atl":[[290,2]],"id":52385883},{"atb":[[28,15]],"id":52385884},{"atb":[[42,3.49]],"id":52385896},{"atl":[[630,0],[220,2]],"id":52385896},{"atl":[[90,2],[490,0]],"id":52385897},{"atl":[[80,2],[470,0]],"id":52385903}],"con":true,"img":false}]}
{"op":"mcm","clk":"11550769169","pt":1719503225960,"mc":[{"id":"1.230178174","rc":[{"atl":[[25,2.5],[29,8.57]],"id":52385906},{"atl":[[710,0]],"id":52385883},{"atl":[[190,5.17],[500,0]],"id":52385898}],"con":true,"img":false}]}
{"op":"mcm","clk":"11550769176","pt":1719503226063,"mc":[{"id":"1.230178174","rc":[{"atb":[[28,0]],"id":52385884}],"con":true,"img":false}]}
{"op":"mcm","clk":"11550769181","pt":1719503226207,"mc":[{"id":"1.230178174","rc":[{"atb":[[27,20]],"id":52385884}],"con":true,"img":false}]}
{"op":"mcm","clk":"11550769202","pt":1719503226610,"mc":[{"id":"1.230178174","rc":[{"atb":[[42,0]],"id":52385896}],"con":true,"img":false}]}
{"op":"mcm","clk":"11550769216","pt":1719503226888,"mc":[{"id":"1.230178174","rc":[{"atl":[[85,2],[95,0]],"id":52385910}],"con":true,"img":false}]}
{"op":"mcm","clk":"11550769349","pt":1719503228696,"mc":[{"id":"1.230178174","rc":[{"atb":[[16,0]],"id":52385905}],"con":true,"img":false}]}
{"op":"mcm","clk":"11550769359","pt":1719503228798,"mc":[{"id":"1.230178174","rc":[{"atb":[[9.4,15]],"id":52385905}],"con":true,"img":false}]}
{"op":"mcm","clk":"11550769425","pt":1719503229778,"mc":[{"id":"1.230178174","rc":[{"atb":[[10,12.5]],"id":52385905}],"con":true,"img":false}]}
{"op":"mcm","clk":"11550769553","pt":1719503232362,"mc":[{"id":"1.230178174","rc":[{"atl":[[80,2],[85,0]],"id":52385899}],"con":true,"img":false}]}
{"op":"mcm","clk":"11550769814","pt":1719503237305,"mc":[{"id":"1.230178174","rc":[{"atl":[[27,0]],"id":52385905}],"con":true,"img":false}]}
{"op":"mcm","clk":"11550769820","pt":1719503237407,"mc":[{"id":"1.230178174","rc":[{"atl":[[38,0]],"id":52385903},{"atl":[[34,18.18]],"id":52385905}],"con":true,"img":false}]}
{"op":"mcm","clk":"11550769825","pt":1719503237510,"mc":[{"id":"1.230178174","rc":[{"atl":[[46,13.33]],"id":52385903}],"con":true,"img":false}]}
{"op":"mcm","clk":"11550769833","pt":1719503237616,"mc":[{"id":"1.230178174","rc":[{"atl":[[19.5,0]],"id":52385913},{"atl":[[18.5,0]],"id":52385906}],"con":true,"img":false}]}
{"op":"mcm","clk":"11550769841","pt":1719503237671,"mc":[{"id":"1.230178174","rc":[{"atl":[[20,26]],"id":52385913},{"atl":[[19,26],[240,2]],"id":52385906}],"con":true,"img":false}]}
{"op":"mcm","clk":"11550769846","pt":1719503237772,"mc":[{"id":"1.230178174","rc":[{"atl":[[29,5]],"id":52385906}],"con":true,"img":false}]}
{"op":"mcm","clk":"11550769852","pt":1719503237876,"mc":[{"id":"1.230178174","rc":[{"atl":[[29,8.57],[240,0]],"id":52385906},{"atl":[[22,15]],"id":52385889},{"atb":[[25,20]],"id":52385885},{"atl":[[80,7.59]],"id":52385885},{"atb":[[16.5,17.44]],"id":52385897},{"atl":[[13.5,26]],"id":52385892},{"atb":[[11.5,31.6]],"id":52385903},{"atl":[[40,15.38]],"id":52385903},{"atb":[[7,0],[9.4,21.6]],"id":52385904},{"atl":[[20,21.6]],"id":52385904},{"atb":[[16,35]],"id":52385905},{"atb":[[18.5,18.72]],"id":52385898},{"atl":[[46,13.33]],"id":52385898}],"con":true,"img":false}]}
{"op":"mcm","clk":"11550769858","pt":1719503237981,"mc":[{"id":"1.230178174","rc":[{"atl":[[140,0],[150,0],[55,2]],"id":52385889},{"atb":[[24,0]],"id":52385885},{"atl":[[100,0]],"id":52385885},{"atb":[[16,0]],"id":52385897},{"atl":[[20,5.26],[190,0],[200,0]],"id":52385892},{"atb":[[9.2,5]],"id":52385903},{"atl":[[46,0]],"id":52385903},{"atb":[[9,0],[6,12]],"id":52385904},{"atl":[[32,3.23],[320,0],[980,0]],"id":52385904},{"atb":[[9.4,0]],"id":52385905},{"atb":[[18,0]],"id":52385898},{"atl":[[190,0],[95,2]],"id":52385898}],"con":true,"img":false}]}
{"op":"mcm","clk":"11550769865","pt":1719503238084,"mc":[{"id":"1.230178174","rc":[{"atb":[[13.5,26]],"id":52385910},{"atl":[[50,12.24]],"id":52385910},{"atl":[[23,26]],"id":52385911},{"atb":[[12.5,15]],"id":52385912},{"atl":[[36,15]],"id":52385912},{"atb":[[28,20]],"id":52385882},{"atl":[[60,10.17]],"id":52385882},{"atb":[[48,12.77]],"id":52385883},{"atl":[[120,5.04]],"id":52385883},{"atb":[[32,19.35]],"id":52385884},{"atl":[[75,8.11]],"id":52385884},{"atb":[[42,14.63]],"id":52385896},{"atl":[[100,6.06]],"id":52385896},{"atl":[[24,13.72]],"id":52385890},{"atb":[[7,26]],"id":52385891},{"atl":[[16,26]],"id":52385891}],"con":true,"img":false}]}
{"op":"mcm","clk":"11550769878","pt":1719503238201,"mc":[{"id":"1.230178174","rc":[{"atb":[[10.5,0]],"id":52385910},{"atl":[[65,0]],"id":52385910},{"atb":[[9.2,0]],"id":52385912},{"atl":[[80,0]],"id":52385912},{"atb":[[23,0]],"id":52385882},{"atl":[[80,0]],"id":52385882},{"atb":[[40,2.5]],"id":52385883},{"atl":[[150,0]],"id":52385883},{"atb":[[27,0]],"id":52385884},{"atl":[[95,0]],"id":52385884},{"atb":[[38,0]],"id":52385896},{"atl":[[120,0]],"id":52385896},{"atl":[[46,2.22],[400,0],[990,0]],"id":52385890},{"atb":[[6.2,0]],"id":52385891},{"atl":[[25,4.17],[240,0]],"id":52385891}],"con":true,"img":false}]}
{"op":"mcm","clk":"11550769882","pt":1719503238290,"mc":[{"id":"1.230178174","rc":[{"atl":[[330,0]],"id":52385911},{"atl":[[250,0]],"id":52385891}],"con":true,"img":false}]}
{"op":"mcm","clk":"11550769891","pt":1719503238400,"mc":[{"id":"1.230178174","rc":[{"atl":[[42,3.84]],"id":52385912}],"con":true,"img":false}]}
{"op":"mcm","clk":"11550769895","pt":1719503238498,"mc":[{"id":"1.230178174","rc":[{"atl":[[42,0]],"id":52385912},{"atl":[[19.5,32.43]],"id":52385913},{"atl":[[18.5,27.14]],"id":52385906}],"con":true,"img":false}]}
{"op":"mcm","clk":"11550769906","pt":1719503238603,"mc":[{"id":"1.230178174","rc":[{"atl":[[20,0]],"id":52385913},{"atl":[[19,0],[25,6.67],[29,5]],"id":52385906},{"atl":[[32,19.35]],"id":52385905}],"con":true,"img":false}]}
{"op":"mcm","clk":"11550769918","pt":1719503238810,"mc":[{"id":"1.230178174","rc":[{"atl":[[34,0]],"id":52385905}],"con":true,"img":false}]}
{"op":"mcm","clk":"11550770053","pt":1719503240924,"mc":[{"id":"1.230178174","rc":[{"atb":[[8,0]],"id":52385913},{"atb":[[9,0]],"id":52385890}],"con":true,"img":false}]}
{"op":"mcm","clk":"11550770060","pt":1719503240979,"mc":[{"id":"1.230178174","rc":[{"atb":[[9,12]],"id":52385913},{"atb":[[8,12]],"id":52385890}],"con":true,"img":false}]}
{"op":"mcm","clk":"11550770068","pt":1719503241083,"mc":[{"id":"1.230178174","rc":[{"atb":[[9,46],[8.2,0]],"id":52385913}],"con":true,"img":false}]}
{"op":"mcm","clk":"11550770155","pt":1719503242582,"mc":[{"id":"1.230178174","rc":[{"atb":[[50,12.24]],"id":52385883}],"con":true,"img":false}]}
{"op":"mcm","clk":"11550770165","pt":1719503242789,"mc":[{"id":"1.230178174","rc":[{"atb":[[48,0]],"id":52385883}],"con":true,"img":false}]}
{"op":"mcm","clk":"11550770208","pt":1719503243717,"mc":[{"id":"1.230178174","rc":[{"atl":[[25,2.5],[29,8.57]],"id":52385906}],"con":true,"img":false}]}
{"op":"mcm","clk":"11550770287","pt":1719503245481,"mc":[{"id":"1.230178174","rc":[{"atb":[[7.4,27.14]],"id":52385906},{"atl":[[22,0]],"id":52385889},{"atb":[[5.6,21.74],[6.4,0]],"id":52385905},{"atb":[[20,0]],"id":52385899}],"con":true,"img":false}]}
{"op":"mcm","clk":"11550770292","pt":1719503245586,"mc":[{"id":"1.230178174","rc":[{"atl":[[28,20]],"id":52385889},{"atb":[[42,0]],"id":52385896},{"atb":[[12,0]],"id":52385890},{"atb":[[16,0],[5.6,0],[6.6,17.86]],"id":52385905},{"atb":[[14.5,26]],"id":52385899}],"con":true,"img":false}]}
{"op":"mcm","clk":"11550770296","pt":1719503245689,"mc":[{"id":"1.230178174","rc":[{"atb":[[7,12]],"id":52385906},{"atb":[[9.6,0],[8,14.29]],"id":52385882},{"atb":[[8.6,13.16],[11.5,0]],"id":52385884},{"atb":[[10,0],[8.2,13.89]],"id":52385885},{"atb":[[36,17.14]],"id":52385896},{"atb":[[10.5,18.72]],"id":52385890},{"atl":[[18.5,5.71],[20,0]],"id":52385892},{"atb":[[8,14.29],[7.4,0]],"id":52385903},{"atb":[[11.5,35]],"id":52385905},{"atb":[[18.5,0],[8.8,12.82],[7.8,0]],"id":52385898}],"con":true,"img":false}]}
{"op":"mcm","clk":"11550770302","pt":1719503245792,"mc":[{"id":"1.230178174","rc":[{"atb":[[7,0]],"id":52385906},{"atb":[[17,6.25],[14.5,0]],"id":52385883},{"atb":[[36,0]],"id":52385896},{"atb":[[18,15]],"id":52385898}],"con":true,"img":false}]}
{"op":"mcm","clk":"11550770306","pt":1719503245896,"mc":[{"id":"1.230178174","rc":[{"atb":[[8,12]],"id":52385906},{"atb":[[34,15]],"id":52385896},{"atb":[[10.5,0]],"id":52385890}],"con":true,"img":false}]}
{"op":"mcm","clk":"11550770312","pt":1719503246000,"mc":[{"id":"1.230178174","rc":[{"atb":[[6.2,15]],"id":52385890}],"con":true,"img":false}]}
{"op":"mcm","clk":"11550770332","pt":1719503246520,"mc":[{"id":"1.230178174","rc":[{"atb":[[8.2,25.71]],"id":52385906},{"atl":[[28,30.26]],"id":52385889},{"atb":[[15,11.7]],"id":52385897}],"con":true,"img":false}]}
{"op":"mcm","clk":"11550770335","pt":1719503246621,"mc":[{"id":"1.230178174","rc":[{"atb":[[9.6,21.46]],"id":52385911},{"atb":[[22,11.72]],"id":52385882},{"atb":[[44,4.44]],"id":52385883}],"con":true,"img":false}]}
{"op":"mcm","clk":"11550770341","pt":1719503246732,"mc":[{"id":"1.230178174","rc":[{"atb":[[8.2,0]],"id":52385906},{"atl":[[28,20]],"id":52385889},{"atb":[[28,0]],"id":52385882},{"atb":[[16.5,0],[15,0]],"id":52385897},{"atl":[[40,0]],"id":52385903},{"atb":[[9.4,0]],"id":52385904}],"con":true,"img":false}]}
{"op":"mcm","clk":"11550770349","pt":1719503246832,"mc":[{"id":"1.230178174","rc":[{"atb":[[9.6,0]],"id":52385911},{"atb":[[22,0]],"id":52385882},{"atb":[[44,0]],"id":52385883},{"atb":[[15.5,33.4]],"id":52385897},{"atl":[[42,14.63]],"id":52385903},{"atb":[[9,67.2]],"id":52385904}],"con":true,"img":false}]}
{"op":"mcm","clk":"11550770356","pt":1719503246889,"mc":[{"id":"1.230178174","rc":[{"atb":[[26,15]],"id":52385882}],"con":true,"img":false}]}
{"op":"mcm","clk":"11550770365","pt":1719503246993,"mc":[{"id":"1.230178174","rc":[{"atb":[[15.5,0]],"id":52385897},{"atl":[[42,0]],"id":52385903},{"atb":[[9,0]],"id":52385904}],"con":true,"img":false}]}
{"op":"mcm","clk":"11550770373","pt":1719503247100,"mc":[{"id":"1.230178174","rc":[{"atb":[[10,0],[5.4,0],[4.7,20]],"id":52385911},{"atb":[[26,0]],"id":52385882},{"atb":[[7.6,0],[13.5,13.72]],"id":52385897},{"atb":[[4.5,24],[5.3,0]],"id":52385890},{"atb":[[4,2.5],[3.7,20]],"id":52385892},{"atl":[[50,12.24]],"id":52385903},{"atb":[[5.9,34]],"id":52385904},{"atb":[[16,35]],"id":52385905}],"con":true,"img":false}]}
{"op":"mcm","clk":"11550770382","pt":1719503247203,"mc":[{"id":"1.230178174","rc":[{"atb":[[9.8,15]],"id":52385911},{"atb":[[8.2,13.89]],"id":52385897}],"con":true,"img":false}]}
{"op":"mcm","clk":"11550770389","pt":1719503247306,"mc":[{"id":"1.230178174","rc":[{"atb":[[4.7,0],[5.4,22.73]],"id":52385911},{"atb":[[19,15]],"id":52385882},{"atb":[[16,0],[11.5,0]],"id":52385905}],"con":true,"img":false}]}
{"op":"mcm","clk":"11550770397","pt":1719503247414,"mc":[{"id":"1.230178174","rc":[{"atb":[[9.8,0]],"id":52385911},{"atb":[[11,60]],"id":52385905}],"con":true,"img":false}]}
{"op":"mcm","clk":"11550770402","pt":1719503247511,"mc":[{"id":"1.230178174","rc":[{"atb":[[9.4,54]],"id":52385911}],"con":true,"img":false}]}
{"op":"mcm","clk":"11550770410","pt":1719503247616,"mc":[{"id":"1.230178174","rc":[{"atb":[[11,0],[15.5,35]],"id":52385905}],"con":true,"img":false}]}
{"op":"mcm","clk":"11550770421","pt":1719503247821,"mc":[{"id":"1.230178174","rc":[{"atb":[[9.4,0]],"id":52385911}],"con":true,"img":false}]}
{"op":"mcm","clk":"11550770427","pt":1719503247923,"mc":[{"id":"1.230178174","rc":[{"atb":[[5.5,34]],"id":52385911},{"atb":[[17,0]],"id":52385883},{"atb":[[15.5,0]],"id":52385905}],"con":true,"img":false}]}
{"op":"mcm","clk":"11550770432","pt":1719503248028,"mc":[{"id":"1.230178174","rc":[{"atb":[[15,7.14]],"id":52385883},{"atb":[[8,0]],"id":52385903},{"atb":[[5.1,0],[4.6,27.78]],"id":52385904},{"atb":[[10,32.5],[5.5,22.22],[6.6,0]],"id":52385905}],"con":true,"img":false}]}
{"op":"mcm","clk":"11550770438","pt":1719503248129,"mc":[{"id":"1.230178174","rc":[{"atb":[[8.2,13.89]],"id":52385903},{"atb":[[5.2,23.81]],"id":52385904},{"atb":[[6.6,17.86]],"id":52385905}],"con":true,"img":false}]}
{"op":"mcm","clk":"11550770444","pt":1719503248239,"mc":[{"id":"1.230178174","rc":[{"atb":[[4.6,0]],"id":52385904},{"atb":[[5.5,0]],"id":52385905}],"con":true,"img":false}]}
{"op":"mcm","clk":"11550770485","pt":1719503249216,"mc":[{"id":"1.230178174","rc":[{"atb":[[4.7,27.03]],"id":52385911},{"atb":[[8.2,0],[6.8,17.24]],"id":52385897}],"con":true,"img":false}]}
{"op":"mcm","clk":"11550770492","pt":1719503249319,"mc":[{"id":"1.230178174","rc":[{"atb":[[5.4,0]],"id":52385911}],"con":true,"img":false}]}
{"op":"mcm","clk":"11550770529","pt":1719503249892,"mc":[{"id":"1.230178174","rc":[{"atb":[[13,0]],"id":52385910},{"atb":[[6,0]],"id":52385891},{"atb":[[11,0]],"id":52385903}],"con":true,"img":false}]}
{"op":"mcm","clk":"11550770536","pt":1719503249997,"mc":[{"id":"1.230178174","rc":[{"atb":[[14,9]],"id":52385910},{"atb":[[5,12]],"id":52385891},{"atb":[[12,11]],"id":52385903}],"con":true,"img":false}]}
{"op":"mcm","clk":"11550770541","pt":1719503250102,"mc":[{"id":"1.230178174","rc":[{"atb":[[13.5,0],[14.5,28]],"id":52385910}],"con":true,"img":false}]}
{"op":"mcm","clk":"11550770548","pt":1719503250204,"mc":[{"id":"1.230178174","rc":[{"atl":[[100,2]],"id":52385910}],"con":true,"img":false}]}
{"op":"mcm","clk":"11550770555","pt":1719503250308,"mc":[{"id":"1.230178174","rc":[{"atl":[[85,0]],"id":52385910},{"atb":[[8.2,0]],"id":52385903}],"con":true,"img":false}]}
{"op":"mcm","clk":"11550770561","pt":1719503250421,"mc":[{"id":"1.230178174","rc":[{"atb":[[8.2,13.89]],"id":52385903}],"con":true,"img":false}]}
{"op":"mcm","clk":"11550770573","pt":1719503250619,"mc":[{"id":"1.230178174","rc":[{"atl":[[34,18.18]],"id":52385897}],"con":true,"img":false}]}
{"op":"mcm","clk":"11550770584","pt":1719503250827,"mc":[{"id":"1.230178174","rc":[{"atl":[[36,0]],"id":52385897}],"con":true,"img":false}]}
{"op":"mcm","clk":"11550770643","pt":1719503251920,"mc":[{"id":"1.230178174","rc":[{"atb":[[9,34]],"id":52385913}],"con":true,"img":false}]}
{"op":"mcm","clk":"11550770651","pt":1719503252025,"mc":[{"id":"1.230178174","rc":[{"atb":[[8,12]],"id":52385913}],"con":true,"img":false}]}
{"op":"mcm","clk":"11550770657","pt":1719503252129,"mc":[{"id":"1.230178174","rc":[{"atb":[[9,0]],"id":52385913}],"con":true,"img":false}]}
{"op":"mcm","clk":"11550770666","pt":1719503252235,"mc":[{"id":"1.230178174","rc":[{"atb":[[8.8,15]],"id":52385913}],"con":true,"img":false}]}
{"op":"mcm","clk":"11550770754","pt":1719503253790,"mc":[{"id":"1.230178174","rc":[{"atb":[[8,0],[10.5,10.53]],"id":52385882},{"atb":[[8.6,0],[12,9.09]],"id":52385884},{"atb":[[8.2,0],[11,10]],"id":52385885}],"con":true,"img":false}]}
{"op":"mcm","clk":"11550770809","pt":1719503254720,"mc":[{"id":"1.230178174","rc":[{"atb":[[25,0]],"id":52385885},{"atl":[[46,13.33]],"id":52385903}],"con":true,"img":false}]}
{"op":"mcm","clk":"11550770816","pt":1719503254822,"mc":[{"id":"1.230178174","rc":[{"atb":[[24,20]],"id":52385885}],"con":true,"img":false}]}
{"op":"mcm","clk":"11550770823","pt":1719503254925,"mc":[{"id":"1.230178174","rc":[{"atl":[[50,0]],"id":52385903}],"con":true,"img":false}]}
{"op":"mcm","clk":"11550770830","pt":1719503255028,"mc":[{"id":"1.230178174","rc":[{"atl":[[24,20]],"id":52385889}],"con":true,"img":false}]}
{"op":"mcm","clk":"11550770836","pt":1719503255129,"mc":[{"id":"1.230178174","rc":[{"atb":[[18.5,32]],"id":52385903},{"atb":[[7,67.2]],"id":52385904},{"atb":[[19.5,20]],"id":52385898}],"con":true,"img":false}]}
{"op":"mcm","clk":"11550770843","pt":1719503255233,"mc":[{"id":"1.230178174","rc":[{"atl":[[28,0]],"id":52385889},{"atb":[[4.5,0],[5.7,21.28]],"id":52385890},{"atb":[[3.7,0],[4.4,20]],"id":52385892}],"con":true,"img":false}]}
{"op":"mcm","clk":"11550770847","pt":1719503255287,"mc":[{"id":"1.230178174","rc":[{"atb":[[16.5,28]],"id":52385910},{"atb":[[18.5,26]],"id":52385912},{"atb":[[22,20]],"id":52385882},{"atb":[[11.5,0]],"id":52385903},{"atb":[[5.9,0]],"id":52385904},{"atb":[[18,0]],"id":52385898}],"con":true,"img":false}]}
{"op":"mcm","clk":"11550770858","pt":1719503255492,"mc":[{"id":"1.230178174","rc":[{"atb":[[14.5,0]],"id":52385910},{"atb":[[12.5,0]],"id":52385912},{"atb":[[19,0]],"id":52385882}],"con":true,"img":false}]}
{"op":"mcm","clk":"11550770864","pt":1719503255599,"mc":[{"id":"1.230178174","rc":[{"atb":[[42,14.63]],"id":52385896},{"atb":[[15.5,29]],"id":52385897},{"atl":[[38,16.22]],"id":52385903},{"atb":[[16,40]],"id":52385905}],"con":true,"img":false}]}
{"op":"mcm","clk":"11550770873","pt":1719503255801,"mc":[{"id":"1.230178174","rc":[{"atl":[[46,0]],"id":52385903}],"con":true,"img":false}]}
{"op":"mcm","clk":"11550770881","pt":1719503255910,"mc":[{"id":"1.230178174","rc":[{"atb":[[34,0]],"id":52385896},{"atb":[[13.5,0]],"id":52385897},{"atl":[[34,0]],"id":52385897},{"atb":[[10,12.5]],"id":52385905}],"con":true,"img":false}]}
{"op":"mcm","clk":"11550770885","pt":1719503256009,"mc":[{"id":"1.230178174","rc":[{"atl":[[42,14.63]],"id":52385897}],"con":true,"img":false}]}
{"op":"mcm","clk":"11550770953","pt":1719503257196,"mc":[{"id":"1.230178174","rc":[{"atb":[[4.7,0],[5.4,22.73]],"id":52385911},{"atb":[[8.2,13.89],[6.8,0]],"id":52385897}],"con":true,"img":false}]}
{"op":"mcm","clk":"11550771215","pt":1719503261737,"mc":[{"id":"1.230178174","rc":[{"atb":[[18.5,0]],"id":52385912},{"atb":[[4.1,24],[4.7,0]],"id":52385906},{"atb":[[12,9.09],[15,0]],"id":52385883},{"atb":[[12,0],[6.6,17.86]],"id":52385884},{"atb":[[36,17.14],[11,0],[8.2,13.89]],"id":52385885},{"atb":[[42,0]],"id":52385896},{"atb":[[15.5,0]],"id":52385897},{"atl":[[11,40]],"id":52385892},{"atb":[[18.5,0],[8.2,0],[5.3,22]],"id":52385903},{"atl":[[38,0]],"id":52385903},{"atb":[[16,0],[5.3,23.26],[6.6,0]],"id":52385905}],"con":true,"img":false}]}
{"op":"mcm","clk":"11550771225","pt":1719503261842,"mc":[{"id":"1.230178174","rc":[{"atb":[[11,26]],"id":52385912},{"atb":[[12,9.09],[6.6,0]],"id":52385884},{"atb":[[24,0]],"id":52385885},{"atb":[[38,16.22]],"id":52385896},{"atb":[[14.5,34]],"id":52385897},{"atl":[[11,0],[13.5,0]],"id":52385892},{"atb":[[18,27]],"id":52385903},{"atl":[[46,13.33]],"id":52385903},{"atb":[[12.5,35]],"id":52385905}],"con":true,"img":false}]}
{"op":"mcm","clk":"11550771231","pt":1719503261896,"mc":[{"id":"1.230178174","rc":[{"atl":[[13,50]],"id":52385892}],"con":true,"img":false}]}
{"op":"mcm","clk":"11550771239","pt":1719503261999,"mc":[{"id":"1.230178174","rc":[{"atl":[[13,0]],"id":52385892}],"con":true,"img":false}]}
{"op":"mcm","clk":"11550771245","pt":1719503262102,"mc":[{"id":"1.230178174","rc":[{"atl":[[13.5,40]],"id":52385892}],"con":true,"img":false}]}
{"op":"mcm","clk":"11550771277","pt":1719503262515,"mc":[{"id":"1.230178174","rc":[{"atb":[[8,53.14]],"id":52385906}],"con":true,"img":false}]}
{"op":"mcm","clk":"11550771283","pt":1719503262618,"mc":[{"id":"1.230178174","rc":[{"atb":[[7.4,0]],"id":52385906},{"atb":[[20,30]],"id":52385899}],"con":true,"img":false}]}
{"op":"mcm","clk":"11550771291","pt":1719503262725,"mc":[{"id":"1.230178174","rc":[{"atb":[[9.6,25.51],[8.2,51.44]],"id":52385890},{"atb":[[13,35]],"id":52385905},{"atb":[[14.5,0]],"id":52385899}],"con":true,"img":false}]}
{"op":"mcm","clk":"11550771302","pt":1719503262929,"mc":[{"id":"1.230178174","rc":[{"atb":[[6.2,0]],"id":52385890},{"atb":[[12.5,0]],"id":52385905},{"atb":[[20,15]],"id":52385898}],"con":true,"img":false}]}
{"op":"mcm","clk":"11550771308","pt":1719503263032,"mc":[{"id":"1.230178174","rc":[{"atb":[[9.8,51.44]],"id":52385890},{"atb":[[19.5,0]],"id":52385898}],"con":true,"img":false}]}
{"op":"mcm","clk":"11550771321","pt":1719503263240,"mc":[{"id":"1.230178174","rc":[{"atb":[[8.2,0]],"id":52385890}],"con":true,"img":false}]}
{"op":"mcm","clk":"11550771339","pt":1719503263604,"mc":[{"id":"1.230178174","rc":[{"atb":[[7,0],[8.4,34]],"id":52385904}],"con":true,"img":false}]}
{"op":"mcm","clk":"11550771344","pt":1719503263708,"mc":[{"id":"1.230178174","rc":[{"atb":[[9.6,0]],"id":52385890}],"con":true,"img":false}]}
{"op":"mcm","clk":"11550771353","pt":1719503263913,"mc":[{"id":"1.230178174","rc":[{"atb":[[26,15]],"id":52385882}],"con":true,"img":false}]}
{"op":"mcm","clk":"11550771360","pt":1719503264020,"mc":[{"id":"1.230178174","rc":[{"atb":[[22,0]],"id":52385882}],"con":true,"img":false}]}
{"op":"mcm","clk":"11550771365","pt":1719503264124,"mc":[{"id":"1.230178174","rc":[{"atb":[[5.4,0],[4.7,27.03]],"id":52385911},{"atb":[[36,0]],"id":52385885},{"atb":[[8.2,0],[6.8,17.24]],"id":52385897},{"atb":[[4.5,24],[5.7,0]],"id":52385890},{"atb":[[3.7,16],[4.4,0]],"id":52385892}],"con":true,"img":false}]}
{"op":"mcm","clk":"11550771372","pt":1719503264232,"mc":[{"id":"1.230178174","rc":[{"atb":[[8.2,69.46]],"id":52385911},{"atb":[[20,15]],"id":52385885},{"atb":[[14.5,0]],"id":52385897},{"atb":[[8.4,0]],"id":52385904},{"atb":[[13,0]],"id":52385905}],"con":true,"img":false}]}
{"op":"mcm","clk":"11550771377","pt":1719503264332,"mc":[{"id":"1.230178174","rc":[{"atb":[[5.5,0]],"id":52385911},{"atb":[[13,15]],"id":52385897},{"atb":[[7.4,34]],"id":52385904},{"atb":[[9.8,20]],"id":52385905}],"con":true,"img":false}]}
{"op":"mcm","clk":"11550771387","pt":1719503264543,"mc":[{"id":"1.230178174","rc":[{"atb":[[26,0]],"id":52385882}],"con":true,"img":false}]}
{"op":"mcm","clk":"11550771393","pt":1719503264646,"mc":[{"id":"1.230178174","rc":[{"atb":[[22,20]],"id":52385882},{"atb":[[10.5,35]],"id":52385905}],"con":true,"img":false}]}
{"op":"mcm","clk":"11550771397","pt":1719503264697,"mc":[{"id":"1.230178174","rc":[{"atb":[[10,34]],"id":52385911},{"atb":[[42,14.63]],"id":52385896},{"atl":[[38,16.22]],"id":52385903}],"con":true,"img":false}]}
{"op":"mcm","clk":"11550771402","pt":1719503264800,"mc":[{"id":"1.230178174","rc":[{"atb":[[9.8,0]],"id":52385905}],"con":true,"img":false}]}
{"op":"mcm","clk":"11550771408","pt":1719503264904,"mc":[{"id":"1.230178174","rc":[{"atb":[[8.2,0]],"id":52385911},{"atb":[[38,0]],"id":52385896},{"atl":[[46,0]],"id":52385903}],"con":true,"img":false}]}
{"op":"mcm","clk":"11550771415","pt":1719503265007,"mc":[{"id":"1.230178174","rc":[{"atb":[[16,35]],"id":52385905}],"con":true,"img":false}]}
{"op":"mcm","clk":"11550771431","pt":1719503265213,"mc":[{"id":"1.230178174","rc":[{"atb":[[10.5,0]],"id":52385905}],"con":true,"img":false}]}
{"op":"mcm","clk":"11550771650","pt":1719503269237,"mc":[{"id":"1.230178174","rc":[{"atb":[[12,0],[6.6,17.86]],"id":52385884},{"atl":[[34,18.18]],"id":52385897},{"atb":[[9.8,0]],"id":52385890}],"con":true,"img":false}]}
{"op":"mcm","clk":"11550771655","pt":1719503269346,"mc":[{"id":"1.230178174","rc":[{"atb":[[10,0]],"id":52385911},{"atb":[[12,9.09]],"id":52385884},{"atb":[[9.8,34]],"id":52385890},{"atl":[[38,0]],"id":52385903},{"atb":[[16,0]],"id":52385905}],"con":true,"img":false}]}
{"op":"mcm","clk":"11550771662","pt":1719503269398,"mc":[{"id":"1.230178174","rc":[{"atb":[[9.6,34]],"id":52385911},{"atb":[[6.6,0]],"id":52385884},{"atl":[[42,0]],"id":52385897},{"atl":[[42,14.63]],"id":52385903},{"atb":[[13.5,35]],"id":52385905}],"con":true,"img":false}]}
{"op":"mcm","clk":"11550771672","pt":1719503269607,"mc":[{"id":"1.230178174","rc":[{"atb":[[9.6,0]],"id":52385911},{"atb":[[4.8,24],[4.1,0]],"id":52385906},{"atb":[[17,6.25]],"id":52385883},{"atb":[[8.2,0],[11,10]],"id":52385885},{"atb":[[5.3,0],[8.2,13.89]],"id":52385903},{"atl":[[38,16.22],[42,0]],"id":52385903},{"atb":[[5.3,0],[6.6,17.86]],"id":52385905}],"con":true,"img":false}]}
{"op":"mcm","clk":"11550771677","pt":1719503269707,"mc":[{"id":"1.230178174","rc":[{"atb":[[9.4,34]],"id":52385911},{"atb":[[12,0]],"id":52385883}],"con":true,"img":false}]}
{"op":"mcm","clk":"11550771682","pt":1719503269819,"mc":[{"id":"1.230178174","rc":[{"atl":[[38,0]],"id":52385903}],"con":true,"img":false}]}
{"op":"mcm","clk":"11550771689","pt":1719503269920,"mc":[{"id":"1.230178174","rc":[{"atl":[[50,12.24]],"id":52385903}],"con":true,"img":false}]}
{"op":"mcm","clk":"11550771739","pt":1719503270904,"mc":[{"id":"1.230178174","rc":[{"atb":[[8,0]],"id":52385913}],"con":true,"img":false}]}
{"op":"mcm","clk":"11550771747","pt":1719503271008,"mc":[{"id":"1.230178174","rc":[{"atb":[[9,12]],"id":52385913},{"atl":[[46,0]],"id":52385898}],"con":true,"img":false}]}
{"op":"mcm","clk":"11550771755","pt":1719503271112,"mc":[{"id":"1.230178174","rc":[{"atb":[[9.2,34]],"id":52385913},{"atl":[[48,15.27]],"id":52385898}],"con":true,"img":false}]}
{"op":"mcm","clk":"11550771762","pt":1719503271318,"mc":[{"id":"1.230178174","rc":[{"atb":[[8.8,0]],"id":52385913}],"con":true,"img":false}]}
{"op":"mcm","clk":"11550771774","pt":1719503271525,"mc":[{"id":"1.230178174","rc":[{"atl":[[46,13.33]],"id":52385903}],"con":true,"img":false}]}
{"op":"mcm","clk":"11550771783","pt":1719503271628,"mc":[{"id":"1.230178174","rc":[{"atb":[[36,17.14]],"id":52385885}],"con":true,"img":false}]}
{"op":"mcm","clk":"11550771791","pt":1719503271729,"mc":[{"id":"1.230178174","rc":[{"atb":[[11.5,15]],"id":52385889},{"atl":[[21,15]],"id":52385889},{"atb":[[20,0]],"id":52385885},{"atl":[[50,0]],"id":52385903}],"con":true,"img":false}]}
{"op":"mcm","clk":"11550771801","pt":1719503271936,"mc":[{"id":"1.230178174","rc":[{"atb":[[9.8,0]],"id":52385889},{"atl":[[24,0]],"id":52385889},{"atb":[[8.4,67.2]],"id":52385904}],"con":true,"img":false}]}
{"op":"mcm","clk":"11550771807","pt":1719503272039,"mc":[{"id":"1.230178174","rc":[{"atb":[[5.3,23.26],[4.7,0]],"id":52385911},{"atb":[[6.8,0],[7.8,14.71]],"id":52385897},{"atb":[[4.5,0],[5.5,22.22]],"id":52385890},{"atb":[[4.2,20]],"id":52385892}],"con":true,"img":false}]}
{"op":"mcm","clk":"11550771812","pt":1719503272142,"mc":[{"id":"1.230178174","rc":[{"atb":[[12.5,26]],"id":52385912},{"atb":[[26,20]],"id":52385882},{"atb":[[3.7,0]],"id":52385892},{"atb":[[7.4,0]],"id":52385904}],"con":true,"img":false}]}
{"op":"mcm","clk":"11550771822","pt":1719503272349,"mc":[{"id":"1.230178174","rc":[{"atb":[[11,0]],"id":52385912},{"atb":[[22,0]],"id":52385882}],"con":true,"img":false}]}
{"op":"mcm","clk":"11550771828","pt":1719503272406,"mc":[{"id":"1.230178174","rc":[{"atb":[[14.5,34]],"id":52385897},{"atb":[[17.5,35]],"id":52385905}],"con":true,"img":false}]}
{"op":"mcm","clk":"11550771836","pt":1719503272611,"mc":[{"id":"1.230178174","rc":[{"atb":[[13,0]],"id":52385897},{"atb":[[13.5,0]],"id":52385905}],"con":true,"img":false}]}
{"op":"mcm","clk":"11550771910","pt":1719503273953,"mc":[{"id":"1.230178174","rc":[{"atb":[[14,0]],"id":52385910},{"atb":[[5,0]],"id":52385891}],"con":true,"img":false}]}
{"op":"mcm","clk":"11550771916","pt":1719503274005,"mc":[{"id":"1.230178174","rc":[{"atb":[[13,9]],"id":52385910},{"atb":[[6,12]],"id":52385891}],"con":true,"img":false}]}
{"op":"mcm","clk":"11550772220","pt":1719503279439,"mc":[{"id":"1.230178174","rc":[{"atb":[[10.5,34]],"id":52385890}],"con":true,"img":false}]}
{"op":"mcm","clk":"11550772233","pt":1719503279645,"mc":[{"id":"1.230178174","rc":[{"atb":[[9.8,0]],"id":52385890}],"con":true,"img":false}]}
{"op":"mcm","clk":"11550772398","pt":1719503282738,"mc":[{"id":"1.230178174","rc":[{"atb":[[46,13.33]],"id":52385896}],"con":true,"img":false}]}
{"op":"mcm","clk":"11550772408","pt":1719503282947,"mc":[{"id":"1.230178174","rc":[{"atb":[[42,0]],"id":52385896}],"con":true,"img":false}]}
{"op":"mcm","clk":"11550772412","pt":1719503283050,"mc":[{"id":"1.230178174","rc":[{"atb":[[12,0]],"id":52385903},{"atb":[[6,0]],"id":52385904}],"con":true,"img":false}]}
{"op":"mcm","clk":"11550772420","pt":1719503283155,"mc":[{"id":"1.230178174","rc":[{"atb":[[11,11]],"id":52385903},{"atb":[[7,12]],"id":52385904}],"con":true,"img":false}]}
{"op":"mcm","clk":"11550772510","pt":1719503284927,"mc":[{"id":"1.230178174","rc":[{"atl":[[18.5,0]],"id":52385906}],"con":true,"img":false}]}
{"op":"mcm","clk":"11550772516","pt":1719503285031,"mc":[{"id":"1.230178174","rc":[{"atl":[[19,15]],"id":52385906}],"con":true,"img":false}]}
{"op":"mcm","clk":"11550772524","pt":1719503285137,"mc":[{"id":"1.230178174","rc":[{"atl":[[19,0],[26,4],[29,5]],"id":52385906}],"con":true,"img":false}]}
{"op":"mcm","clk":"11550772531","pt":1719503285238,"mc":[{"id":"1.230178174","rc":[{"atl":[[24,15],[29,8.57]],"id":52385906}],"con":true,"img":false}]}
{"op":"mcm","clk":"11550772538","pt":1719503285345,"mc":[{"id":"1.230178174","rc":[{"atl":[[26,0]],"id":52385906}],"con":true,"img":false}]}
{"op":"mcm","clk":"11550772546","pt":1719503285447,"mc":[{"id":"1.230178174","rc":[{"atl":[[26,4],[29,5]],"id":52385906}],"con":true,"img":false}]}
{"op":"mcm","clk":"11550772559","pt":1719503285759,"mc":[{"id":"1.230178174","rc":[{"atl":[[18,34]],"id":52385913}],"con":true,"img":false}]}
{"op":"mcm","clk":"11550772571","pt":1719503285921,"mc":[{"id":"1.230178174","rc":[{"atl":[[19.5,0]],"id":52385913}],"con":true,"img":false}]}
{"op":"mcm","clk":"11550772598","pt":1719503286443,"mc":[{"id":"1.230178174","rc":[{"atb":[[5.9,2.5]],"id":52385906},{"atb":[[19.5,0],[21,5],[23,0],[25,2.5]],"id":52385885},{"atb":[[12,0],[12.5,5],[14,0],[14.5,2.5]],"id":52385898}],"con":true,"img":false}]}
{"op":"mcm","clk":"11550772603","pt":1719503286545,"mc":[{"id":"1.230178174","rc":[{"atb":[[10,0],[10.5,5],[12,0],[12.5,2.5]],"id":52385910},{"atl":[[23,28.5],[24,0],[27,5],[28,0]],"id":52385911},{"atb":[[5.6,5],[5.8,0],[6,2.5],[5.4,0]],"id":52385913},{"atb":[[5.1,0]],"id":52385906},{"atl":[[24,17.5],[28,5]],"id":52385906},{"atl":[[34,5],[36,0],[28,2.5],[29,0]],"id":52385889},{"atb":[[32,0],[34,5],[40,0],[42,2.5]],"id":52385883},{"atl":[[75,2.5],[85,0],[95,5],[110,0]],"id":52385885},{"atb":[[9.6,5],[9,0],[11,2.5],[9.8,0]],"id":52385897},{"atb":[[5.6,0],[6.2,2.5],[5.2,0],[5.7,5]],"id":52385890},{"atl":[[16.5,0],[17.5,5],[18.5,0],[15.5,2.5]],"id":52385891},{"atl":[[16,0],[13,2.5],[14,0],[15,5]],"id":52385892},{"atb":[[10,0],[9.2,0],[11.5,2.5],[9.8,5]],"id":52385903},{"atb":[[9.6,5],[10,10],[9.2,0],[11,2.5]],"id":52385905}],"con":true,"img":false}]}
{"op":"mcm","clk":"11550772609","pt":1719503286655,"mc":[{"id":"1.230178174","rc":[{"atl":[[65,5],[75,0],[48,2.5],[55,0]],"id":52385910},{"atl":[[25,0],[29,0]],"id":52385906},{"atl":[[70,8.7]],"id":52385885},{"atl":[[23,2.5],[25,0],[27,5],[29,0]],"id":52385890},{"atl":[[15,42.86]],"id":52385891},{"atl":[[12.5,40]],"id":52385892},{"atl":[[65,0],[44,2.5],[48,0],[55,5]],"id":52385903}],"con":true,"img":false}]}
{"op":"mcm","clk":"11550772615","pt":1719503286758,"mc":[{"id":"1.230178174","rc":[{"atl":[[48,15.27]],"id":52385910},{"atl":[[22,28.57]],"id":52385890},{"atl":[[42,14.63]],"id":52385903}],"con":true,"img":false}]}
{"op":"mcm","clk":"11550772622","pt":1719503286866,"mc":[{"id":"1.230178174","rc":[{"atl":[[50,0]],"id":52385910},{"atl":[[80,0]],"id":52385885},{"atl":[[24,0]],"id":52385890},{"atl":[[16,0]],"id":52385891},{"atl":[[13.5,0]],"id":52385892},{"atl":[[46,0]],"id":52385903}],"con":true,"img":false}]}
{"op":"mcm","clk":"11550772670","pt":1719503287746,"mc":[{"id":"1.230178174","rc":[{"atl":[[46,13.33]],"id":52385898}],"con":true,"img":false}]}
{"op":"mcm","clk":"11550772680","pt":1719503287956,"mc":[{"id":"1.230178174","rc":[{"atl":[[48,2.5]],"id":52385898}],"con":true,"img":false}]}
{"op":"mcm","clk":"11550772728","pt":1719503288845,"mc":[{"id":"1.230178174","rc":[{"atb":[[8,0]],"id":52385890}],"con":true,"img":false}]}
{"op":"mcm","clk":"11550772739","pt":1719503288953,"mc":[{"id":"1.230178174","rc":[{"atb":[[9,12]],"id":52385890}],"con":true,"img":false}]}
{"op":"mcm","clk":"11550772847","pt":1719503290427,"mc":[{"id":"1.230178174","rc":[{"atb":[[18.5,26]],"id":52385912}],"con":true,"img":false}]}
{"op":"mcm","clk":"11550772865","pt":1719503290646,"mc":[{"id":"1.230178174","rc":[{"atb":[[12.5,0]],"id":52385912}],"con":true,"img":false}]}
{"op":"mcm","clk":"11550773239","pt":1719503297247,"mc":[{"id":"1.230178174","rc":[{"atl":[[23,2.5],[24,0],[27,5],[28,0]],"id":52385913}],"con":true,"img":false}]}
{"op":"mcm","clk":"11550773270","pt":1719503297766,"mc":[{"id":"1.230178174","rc":[{"atl":[[34,0]],"id":52385897}],"con":true,"img":false}]}
{"op":"mcm","clk":"11550773278","pt":1719503297870,"mc":[{"id":"1.230178174","rc":[{"atb":[[9,0]],"id":52385913},{"atl":[[36,17.14]],"id":52385897}],"con":true,"img":false}]}
{"op":"mcm","clk":"11550773289","pt":1719503297977,"mc":[{"id":"1.230178174","rc":[{"atb":[[8,12]],"id":52385913}],"con":true,"img":false}]}
{"op":"mcm","clk":"11550773297","pt":1719503298027,"mc":[{"id":"1.230178174","rc":[{"atb":[[9.2,0]],"id":52385913}],"con":true,"img":false}]}
{"op":"mcm","clk":"11550773303","pt":1719503298131,"mc":[{"id":"1.230178174","rc":[{"atb":[[8.8,34]],"id":52385913}],"con":true,"img":false}]}
{"op":"mcm","clk":"11550773314","pt":1719503298338,"mc":[{"id":"1.230178174","rc":[{"atl":[[46,0]],"id":52385898}],"con":true,"img":false}]}
{"op":"mcm","clk":"11550773319","pt":1719503298442,"mc":[{"id":"1.230178174","rc":[{"atl":[[36,0]],"id":52385897},{"atl":[[48,15.27]],"id":52385898}],"con":true,"img":false}]}
{"op":"mcm","clk":"11550773325","pt":1719503298546,"mc":[{"id":"1.230178174","rc":[{"atl":[[42,14.63]],"id":52385897}],"con":true,"img":false}]}
{"op":"mcm","clk":"11550773478","pt":1719503301239,"mc":[{"id":"1.230178174","rc":[{"atl":[[17,13]],"id":52385906}],"con":true,"img":false}]}
{"op":"mcm","clk":"11550773487","pt":1719503301448,"mc":[{"id":"1.230178174","rc":[{"atl":[[24,2.5]],"id":52385906}],"con":true,"img":false}]}
{"op":"mcm","clk":"11550773493","pt":1719503301555,"mc":[{"id":"1.230178174","rc":[{"atl":[[50,0]],"id":52385899}],"con":true,"img":false}]}
{"op":"mcm","clk":"11550773501","pt":1719503301656,"mc":[{"id":"1.230178174","rc":[{"atl":[[55,13.61]],"id":52385899}],"con":true,"img":false}]}
{"op":"mcm","clk":"11550773527","pt":1719503302173,"mc":[{"id":"1.230178174","rc":[{"atl":[[70,2.5],[90,5],[48,2.5]],"id":52385898}],"con":true,"img":false}]}
{"op":"mcm","clk":"11550773533","pt":1719503302278,"mc":[{"id":"1.230178174","rc":[{"atl":[[65,0],[48,0],[50,12.24]],"id":52385898}],"con":true,"img":false}]}
{"op":"mcm","clk":"11550773996","pt":1719503310577,"mc":[{"id":"1.230178174","rc":[{"atl":[[50,0]],"id":52385898}],"con":true,"img":false}]}
{"op":"mcm","clk":"11550774005","pt":1719503310684,"mc":[{"id":"1.230178174","rc":[{"atl":[[100,2],[55,11.11]],"id":52385898}],"con":true,"img":false}]}
{"op":"mcm","clk":"11550774013","pt":1719503310788,"mc":[{"id":"1.230178174","rc":[{"atl":[[95,0]],"id":52385898}],"con":true,"img":false}]}
{"op":"mcm","clk":"11550774026","pt":1719503310945,"mc":[{"id":"1.230178174","rc":[{"atl":[[55,0]],"id":52385898}],"con":true,"img":false}]}
{"op":"mcm","clk":"11550774031","pt":1719503311050,"mc":[{"id":"1.230178174","rc":[{"atl":[[60,10.17]],"id":52385898}],"con":true,"img":false}]}
{"op":"mcm","clk":"11550774052","pt":1719503311470,"mc":[{"id":"1.230178174","rc":[{"atl":[[55,5.96]],"id":52385898}],"con":true,"img":false}]}
{"op":"mcm","clk":"11550774061","pt":1719503311676,"mc":[{"id":"1.230178174","rc":[{"atl":[[55,0]],"id":52385898}],"con":true,"img":false}]}
{"op":"mcm","clk":"11550774071","pt":1719503311888,"mc":[{"id":"1.230178174","rc":[{"atb":[[19.5,28]],"id":52385910},{"atb":[[5.8,20.83],[5.3,0]],"id":52385911},{"atl":[[16,40],[34,3.03],[38,0]],"id":52385911},{"atb":[[2.36,73.53],[10.5,0],[11.5,5],[6.8,0],[13.5,2.5],[9.4,0]],"id":52385912},{"atl":[[65,5],[38,0],[46,0],[48,2.5]],"id":52385912},{"atb":[[5.1,0],[5.8,20.83]],"id":52385913},{"atl":[[34,0],[29,3.57]],"id":52385913},{"atb":[[8.6,0],[5.5,27.22],[11.5,0],[7.8,0],[5.9,2.5]],"id":52385889},{"atl":[[36,2.86],[55,0]],"id":52385889},{"atb":[[16.5,2.5],[18.5,0],[8.6,13.16],[21,0],[10.5,0],[26,0],[14.5,5]],"id":52385882},{"atl":[[150,0],[85,0],[48,2.5],[110,2]],"id":52385882},{"atb":[[17,0],[20,5.26]],"id":52385883},{"atl":[[290,0],[250,2]],"id":52385883},{"atl":[[70,2.5],[140,2],[80,0],[180,0],[90,5],[100,0]],"id":52385884},{"atb":[[16.5,5],[36,0],[18.5,2.5],[21,0],[25,0]],"id":52385885},{"atl":[[150,0],[120,2]],"id":52385885},{"atb":[[32,5],[40,2.5],[21,0],[10.5,0],[25,0]],"id":52385896},{"atl":[[350,2],[190,5],[110,0],[220,0]],"id":52385896},{"atb":[[7.8,0]],"id":52385897},{"atl":[[80,2.5],[42,0],[44,0],[90,0],[190,2],[55,0]],"id":52385897},{"atb":[[2.54,64.94],[5.5,0]],"id":52385890},{"atl":[[34,5],[23,0],[27,0],[28,2.5]],"id":52385890},{"atb":[[7,0]],"id":52385891},{"atl":[[20,5.26],[12,54.55],[25,0]],"id":52385891},{"atb":[[6.2,0]],"id":52385892},{"atl":[[16,6.67],[18.5,0],[9.8,40]],"id":52385892},{"atb":[[9.4,11.9]],"id":52385903},{"atb":[[5.2,0],[5.7,21.28]],"id":52385904},{"atl":[[32,0],[29,3.57]],"id":52385904},{"atb":[[6.6,0]],"id":52385905},{"atl":[[32,0],[65,0],[36,0],[44,0],[55,2.5],[120,2]],"id":52385905},{"atb":[[8.8,0]],"id":52385898},{"atl":[[70,0],[90,0],[95,2.5],[100,0],[60,0],[240,2]],"id":52385898},{"atb":[[19,5],[10,0],[22,2.5],[7.4,0],[12,0]],"id":52385899},{"atl":[[75,0],[80,2.5],[180,2],[100,5],[55,11.11]],"id":52385899}],"con":true,"img":false}]}
{"op":"mcm","clk":"11550774076","pt":1719503311991,"mc":[{"id":"1.230178174","rc":[{"atb":[[16.5,0]],"id":52385910},{"atl":[[34,0],[23,2.5],[29,3.57]],"id":52385911},{"atb":[[5.6,36.74],[5.5,5]],"id":52385889},{"atl":[[36,0],[30,3.45]],"id":52385889},{"atb":[[8.6,0],[10,11.11],[1.11,10]],"id":52385882},{"atl":[[95,2],[110,0],[55,10]],"id":52385882},{"atl":[[70,11.2]],"id":52385884},{"atb":[[10.5,10.53],[11,0],[11.5,15]],"id":52385885},{"atl":[[100,2],[120,0]],"id":52385885},{"atl":[[280,2],[350,0]],"id":52385896},{"atl":[[160,2],[190,0],[980,0.61]],"id":52385897},{"atb":[[2.54,0],[3.35,24]],"id":52385890},{"atb":[[6,88]],"id":52385891},{"atl":[[17.5,11.06],[20,0],[15,0]],"id":52385891},{"atl":[[16,0],[12.5,0],[15,12.14]],"id":52385892},{"atb":[[8.2,0]],"id":52385903},{"atl":[[90,2],[120,0],[980,0.61]],"id":52385905},{"atl":[[190,2],[980,0.61]],"id":52385898},{"atb":[[21,14]],"id":52385899},{"atl":[[140,2],[180,0]],"id":52385899}],"con":true,"img":false}]}
{"op":"mcm","clk":"11550774082","pt":1719503312046,"mc":[{"id":"1.230178174","rc":[{"atl":[[36,0]],"id":52385912},{"atb":[[5.6,15],[3.05,30.62]],"id":52385889},{"atb":[[8.6,13.16],[10,0]],"id":52385882},{"atl":[[60,0]],"id":52385882},{"atl":[[75,0]],"id":52385884},{"atl":[[100,0]],"id":52385896},{"atl":[[560,2],[160,0]],"id":52385897},{"atl":[[22,0]],"id":52385890},{"atl":[[14,7.69],[15,5]],"id":52385892},{"atl":[[90,0],[480,2]],"id":52385905},{"atb":[[20,0]],"id":52385898},{"atl":[[590,2],[190,0],[240,0]],"id":52385898},{"atb":[[20,0]],"id":52385899},{"atl":[[55,0]],"id":52385899}],"con":true,"img":false}]}
{"op":"mcm","clk":"11550774089","pt":1719503312149,"mc":[{"id":"1.230178174","rc":[{"atl":[[46,13.33]],"id":52385912},{"atb":[[5.5,27.22],[3.05,0.9]],"id":52385889},{"atb":[[8.6,0],[10,10]],"id":52385882},{"atl":[[140,4.32]],"id":52385896},{"atb":[[14.5,0]],"id":52385897},{"atl":[[25,25]],"id":52385890},{"atb":[[19.5,10]],"id":52385898},{"atl":[[590,0],[240,2]],"id":52385898},{"atl":[[60,10.17]],"id":52385899}],"con":true,"img":false}]}
{"op":"mcm","clk":"11550774094","pt":1719503312252,"mc":[{"id":"1.230178174","rc":[{"atb":[[14,9]],"id":52385897},{"atl":[[590,2],[240,0]],"id":52385898}],"con":true,"img":false}]}
{"op":"mcm","clk":"11550774106","pt":1719503312460,"mc":[{"id":"1.230178174","rc":[{"atb":[[19,26]],"id":52385912},{"atl":[[20,31.58]],"id":52385889},{"atb":[[48,12.77]],"id":52385896},{"atb":[[18,10]],"id":52385905}],"con":true,"img":false}]}
{"op":"mcm","clk":"11550774115","pt":1719503312564,"mc":[{"id":"1.230178174","rc":[{"atl":[[60,0]],"id":52385899}],"con":true,"img":false}]}
{"op":"mcm","clk":"11550774123","pt":1719503312668,"mc":[{"id":"1.230178174","rc":[{"atb":[[18.5,0]],"id":52385912},{"atl":[[21,0]],"id":52385889},{"atb":[[46,0]],"id":52385896},{"atb":[[17.5,0]],"id":52385905},{"atl":[[70,8.7]],"id":52385899}],"con":true,"img":false}]}
{"op":"mcm","clk":"11550774135","pt":1719503312876,"mc":[{"id":"1.230178174","rc":[{"atb":[[11.5,20.83]],"id":52385889},{"atb":[[14,0]],"id":52385899}],"con":true,"img":false}]}
{"op":"mcm","clk":"11550774148","pt":1719503313083,"mc":[{"id":"1.230178174","rc":[{"atb":[[10,0]],"id":52385905}],"con":true,"img":false}]}
{"op":"mcm","clk":"11550774161","pt":1719503313242,"mc":[{"id":"1.230178174","rc":[{"atb":[[12,0]],"id":52385912}],"con":true,"img":false}]}
{"op":"mcm","clk":"11550774169","pt":1719503313448,"mc":[{"id":"1.230178174","rc":[{"atb":[[8,12]],"id":52385889},{"atb":[[20,5]],"id":52385885}],"con":true,"img":false}]}
{"op":"mcm","clk":"11550774176","pt":1719503313553,"mc":[{"id":"1.230178174","rc":[{"atb":[[11.5,0]],"id":52385889},{"atl":[[70,0]],"id":52385899}],"con":true,"img":false}]}
{"op":"mcm","clk":"11550774185","pt":1719503313759,"mc":[{"id":"1.230178174","rc":[{"atb":[[13,0]],"id":52385910},{"atb":[[7,0]],"id":52385904},{"atl":[[70,8.7]],"id":52385899}],"con":true,"img":false}]}
{"op":"mcm","clk":"11550774190","pt":1719503313862,"mc":[{"id":"1.230178174","rc":[{"atb":[[14,9]],"id":52385910},{"atl":[[65,9.38]],"id":52385897},{"atb":[[6,12],[4.9,28.14],[5.7,0]],"id":52385904}],"con":true,"img":false}]}
{"op":"mcm","clk":"11550774198","pt":1719503314068,"mc":[{"id":"1.230178174","rc":[{"atb":[[9.4,34]],"id":52385913},{"atl":[[980,0]],"id":52385897}],"con":true,"img":false}]}
{"op":"mcm","clk":"11550774210","pt":1719503314274,"mc":[{"id":"1.230178174","rc":[{"atb":[[8.8,0]],"id":52385913}],"con":true,"img":false}]}
{"op":"mcm","clk":"11550774217","pt":1719503314379,"mc":[{"id":"1.230178174","rc":[{"atl":[[90,6.74]],"id":52385898}],"con":true,"img":false}]}
{"op":"mcm","clk":"11550774223","pt":1719503314482,"mc":[{"id":"1.230178174","rc":[{"atl":[[980,0],[240,2]],"id":52385898}],"con":true,"img":false}]}
{"op":"mcm","clk":"11550774229","pt":1719503314584,"mc":[{"id":"1.230178174","rc":[{"atl":[[590,0]],"id":52385898}],"con":true,"img":false}]}
{"op":"mcm","clk":"11550774367","pt":1719503316962,"mc":[{"id":"1.230178174","rc":[{"atb":[[2.36,0]],"id":52385912},{"atl":[[75,0],[100,2]],"id":52385912},{"atb":[[4.8,0],[5.3,23.26]],"id":52385906},{"atb":[[17,6.25],[20,0]],"id":52385883},{"atl":[[280,0],[350,2]],"id":52385896},{"atl":[[65,0],[80,0],[90,2.5],[120,5]],"id":52385897},{"atb":[[3.35,0],[2.12,89.29]],"id":52385890},{"atl":[[140,0],[190,2]],"id":52385899}],"con":true,"img":false}]}
{"op":"mcm","clk":"11550774375","pt":1719503317067,"mc":[{"id":"1.230178174","rc":[{"atl":[[560,0],[550,1.09],[210,2]],"id":52385897}],"con":true,"img":false}]}
{"op":"mcm","clk":"11550774424","pt":1719503318155,"mc":[{"id":"1.230178174","rc":[{"atl":[[85,7.14]],"id":52385898}],"con":true,"img":false}]}
{"op":"mcm","clk":"11550774434","pt":1719503318361,"mc":[{"id":"1.230178174","rc":[{"atl":[[90,0]],"id":52385898}],"con":true,"img":false}]}
{"op":"mcm","clk":"11550774597","pt":1719503321256,"mc":[{"id":"1.230178174","rc":[{"atb":[[5.8,20.83],[4.9,2.5]],"id":52385904}],"con":true,"img":false}]}
{"op":"mcm","clk":"11550774741","pt":1719503323891,"mc":[{"id":"1.230178174","rc":[{"atb":[[6,0]],"id":52385904}],"con":true,"img":false}]}
{"op":"mcm","clk":"11550774746","pt":1719503323994,"mc":[{"id":"1.230178174","rc":[{"atb":[[7,12]],"id":52385904}],"con":true,"img":false}]}
{"op":"mcm","clk":"11550774766","pt":1719503324358,"mc":[{"id":"1.230178174","rc":[{"atl":[[310,2],[250,0]],"id":52385883},{"atl":[[150,0],[170,2.5],[190,0],[210,5]],"id":52385896},{"atb":[[1.74,135.14],[2.12,0]],"id":52385890},{"atl":[[32,2.5],[34,0],[40,5],[28,0]],"id":52385890},{"atl":[[150,5],[95,0],[110,2.5]],"id":52385898}],"con":true,"img":false}]}
{"op":"mcm","clk":"11550774774","pt":1719503324462,"mc":[{"id":"1.230178174","rc":[{"atl":[[25,0]],"id":52385890},{"atl":[[85,0]],"id":52385898}],"con":true,"img":false}]}
{"op":"mcm","clk":"11550774777","pt":1719503324563,"mc":[{"id":"1.230178174","rc":[{"atl":[[140,0]],"id":52385896},{"atl":[[46,0],[30,20.69],[60,2]],"id":52385890},{"atl":[[100,6.06]],"id":52385898}],"con":true,"img":false}]}
{"op":"mcm","clk":"11550774785","pt":1719503324669,"mc":[{"id":"1.230178174","rc":[{"atl":[[150,4.03]],"id":52385896}],"con":true,"img":false}]}
{"op":"mcm","clk":"11550774795","pt":1719503324875,"mc":[{"id":"1.230178174","rc":[{"atl":[[150,0]],"id":52385896}],"con":true,"img":false}]}
{"op":"mcm","clk":"11550774801","pt":1719503324979,"mc":[{"id":"1.230178174","rc":[{"atl":[[170,6.05]],"id":52385896}],"con":true,"img":false}]}
{"op":"mcm","clk":"11550774927","pt":1719503327657,"mc":[{"id":"1.230178174","rc":[{"atb":[[6,11.9]],"id":52385889},{"atb":[[17,15]],"id":52385882},{"atl":[[46,13.33]],"id":52385882},{"atb":[[21,20]],"id":52385885},{"atl":[[85,7.14]],"id":52385897},{"atl":[[50,10]],"id":52385905},{"atb":[[23,20]],"id":52385899}],"con":true,"img":false}]}
{"op":"mcm","clk":"11550774934","pt":1719503327863,"mc":[{"id":"1.230178174","rc":[{"atl":[[42,14.63]],"id":52385912},{"atb":[[5.6,0]],"id":52385889},{"atb":[[1.11,0]],"id":52385882},{"atl":[[55,0]],"id":52385882},{"atb":[[11.5,0]],"id":52385885},{"atl":[[550,0]],"id":52385897},{"atl":[[980,0]],"id":52385905},{"atb":[[23,20]],"id":52385898},{"atb":[[21,0]],"id":52385899}],"con":true,"img":false}]}
{"op":"mcm","clk":"11550774940","pt":1719503327968,"mc":[{"id":"1.230178174","rc":[{"atb":[[17,24.28]],"id":52385897}],"con":true,"img":false}]}
{"op":"mcm","clk":"11550774945","pt":1719503328070,"mc":[{"id":"1.230178174","rc":[{"atl":[[46,0]],"id":52385912},{"atb":[[19.5,0]],"id":52385898}],"con":true,"img":false}]}
{"op":"mcm","clk":"11550774955","pt":1719503328174,"mc":[{"id":"1.230178174","rc":[{"atb":[[14,0]],"id":52385897}],"con":true,"img":false}]}
{"op":"mcm","clk":"11550775104","pt":1719503331013,"mc":[{"id":"1.230178174","rc":[{"atb":[[19.5,0],[14,0]],"id":52385910},{"atb":[[1.21,200],[1.74,0]],"id":52385890},{"atl":[[70,2],[80,0]],"id":52385903},{"atl":[[130,5],[70,0],[95,2.5]],"id":52385899}],"con":true,"img":false}]}
{"op":"mcm","clk":"11550775112","pt":1719503331066,"mc":[{"id":"1.230178174","rc":[{"atb":[[13,9],[14.5,28]],"id":52385910},{"atl":[[80,7.59],[100,0]],"id":52385899}],"con":true,"img":false}]}
{"op":"mcm","clk":"11550775125","pt":1719503331272,"mc":[{"id":"1.230178174","rc":[{"atb":[[14.5,0]],"id":52385910}],"con":true,"img":false}]}
{"op":"mcm","clk":"11550775131","pt":1719503331374,"mc":[{"id":"1.230178174","rc":[{"atb":[[13.5,28]],"id":52385910}],"con":true,"img":false}]}
{"op":"mcm","clk":"11550775147","pt":1719503331684,"mc":[{"id":"1.230178174","rc":[{"atl":[[270,2],[310,0]],"id":52385883}],"con":true,"img":false}]}
{"op":"mcm","clk":"11550775159","pt":1719503331889,"mc":[{"id":"1.230178174","rc":[{"atl":[[42,0]],"id":52385912}],"con":true,"img":false}]}
{"op":"mcm","clk":"11550775164","pt":1719503331993,"mc":[{"id":"1.230178174","rc":[{"atl":[[90,2],[46,13.33],[100,0]],"id":52385912}],"con":true,"img":false}]}
{"op":"mcm","clk":"11550775211","pt":1719503332973,"mc":[{"id":"1.230178174","rc":[{"atl":[[130,0],[90,2.5],[95,0],[120,5]],"id":52385899}],"con":true,"img":false}]}
{"op":"mcm","clk":"11550775520","pt":1719503338220,"mc":[{"id":"1.230178174","rc":[{"atb":[[1.63,158.73],[1.21,0]],"id":52385890}],"con":true,"img":false}]}
{"op":"mcm","clk":"11550775610","pt":1719503339990,"mc":[{"id":"1.230178174","rc":[{"atb":[[20,0]],"id":52385885},{"atb":[[11,0]],"id":52385903},{"atb":[[7,0]],"id":52385904}],"con":true,"img":false}]}
{"op":"mcm","clk":"11550775617","pt":1719503340097,"mc":[{"id":"1.230178174","rc":[{"atb":[[21,0],[24,5]],"id":52385885},{"atb":[[13,11]],"id":52385903},{"atb":[[6,12],[4.9,28.14]],"id":52385904}],"con":true,"img":false}]}
{"op":"mcm","clk":"11550775622","pt":1719503340195,"mc":[{"id":"1.230178174","rc":[{"atb":[[5.8,0]],"id":52385904}],"con":true,"img":false}]}
{"op":"mcm","clk":"11550775626","pt":1719503340302,"mc":[{"id":"1.230178174","rc":[{"atb":[[24,20]],"id":52385885},{"atb":[[5.8,20.83],[4.9,2.5]],"id":52385904}],"con":true,"img":false}]}
{"op":"mcm","clk":"11550775718","pt":1719503341914,"mc":[{"id":"1.230178174","rc":[{"atb":[[13,0]],"id":52385910}],"con":true,"img":false}]}
{"op":"mcm","clk":"11550775725","pt":1719503342022,"mc":[{"id":"1.230178174","rc":[{"atb":[[16,9],[18,20],[8.2,0],[13.5,0],[8.8,12.82]],"id":52385910},{"atl":[[15,42.86]],"id":52385911},{"atb":[[1.04,110.29]],"id":52385912},{"atb":[[5.6,5],[5.5,0],[6,34.4],[5.9,0]],"id":52385889},{"atb":[[16.5,0],[17,17.5],[14.5,0],[15,5]],"id":52385882},{"atb":[[17,0],[13.5,8]],"id":52385883},{"atl":[[150,5],[90,0],[110,2.5],[120,0]],"id":52385897},{"atb":[[1.28,200],[1.63,0]],"id":52385890},{"atl":[[25,9.17],[29,0]],"id":52385904}],"con":true,"img":false}]}
{"op":"mcm","clk":"11550775746","pt":1719503342280,"mc":[{"id":"1.230178174","rc":[{"atl":[[16,0]],"id":52385911}],"con":true,"img":false}]}
{"op":"mcm","clk":"11550775784","pt":1719503342904,"mc":[{"id":"1.230178174","rc":[{"atb":[[1.31,100]],"id":52385899}],"con":true,"img":false}]}
{"op":"mcm","clk":"11550775792","pt":1719503343009,"mc":[{"id":"1.230178174","rc":[{"atb":[[3.05,0]],"id":52385910},{"atb":[[3.05,0]],"id":52385911},{"atb":[[3.05,0]],"id":52385912},{"atb":[[3.05,0]],"id":52385913},{"atb":[[1.31,100],[3.05,0]],"id":52385906},{"atb":[[8.2,30.9],[1.31,100],[3.05,0]],"id":52385889},{"atb":[[1.31,100],[3.05,0]],"id":52385882},{"atb":[[1.31,100],[3.05,0]],"id":52385883},{"atb":[[1.31,100],[3.05,0]],"id":52385884},{"atb":[[1.31,100],[3.05,0]],"id":52385885},{"atb":[[1.31,100],[3.05,0]],"id":52385896},{"atb":[[1.31,100],[3.05,0]],"id":52385897},{"atb":[[1.31,100],[3.05,0]],"id":52385890},{"atb":[[1.31,100],[3.05,0]],"id":52385891},{"atb":[[1.31,100],[3.05,0]],"id":52385892},{"atb":[[1.31,100],[3.05,0]],"id":52385903},{"atb":[[3.05,0]],"id":52385904},{"atb":[[3.05,0]],"id":52385905},{"atb":[[1.31,100],[3.05,0]],"id":52385898},{"atb":[[3.05,0]],"id":52385899}],"con":true,"img":false}]}
{"op":"mcm","clk":"11550775800","pt":1719503343112,"mc":[{"id":"1.230178174","rc":[{"atb":[[1.31,100]],"id":52385910},{"atb":[[1.31,100]],"id":52385911},{"atb":[[1.31,100]],"id":52385912},{"atb":[[1.31,100]],"id":52385913},{"atb":[[6,22.5]],"id":52385889}],"con":true,"img":false}]}
{"op":"mcm","clk":"11550775806","pt":1719503343213,"mc":[{"id":"1.230178174","rc":[{"atl":[[85,0]],"id":52385897},{"atb":[[1.31,100]],"id":52385904},{"atb":[[1.31,100]],"id":52385905}],"con":true,"img":false}]}
{"op":"mcm","clk":"11550775815","pt":1719503343317,"mc":[{"id":"1.230178174","rc":[{"atl":[[140,4.32],[190,2],[210,0]],"id":52385897}],"con":true,"img":false}]}
{"op":"mcm","clk":"11550775864","pt":1719503343994,"mc":[{"id":"1.230178174","rc":[{"atb":[[8,0]],"id":52385889}],"con":true,"img":false}]}
{"op":"mcm","clk":"11550775871","pt":1719503344098,"mc":[{"id":"1.230178174","rc":[{"atb":[[9,12]],"id":52385889}],"con":true,"img":false}]}
{"op":"mcm","clk":"11550775876","pt":1719503344201,"mc":[{"id":"1.230178174","rc":[{"atb":[[9,81],[8.2,0]],"id":52385889}],"con":true,"img":false}]}
{"op":"mcm","clk":"11550776059","pt":1719503347416,"mc":[{"id":"1.230178174","rc":[{"atb":[[25,25]],"id":52385882},{"atl":[[130,0],[270,0],[160,2.5],[330,2],[170,0],[200,5]],"id":52385883},{"atl":[[32,3.23],[25,5]],"id":52385904}],"con":true,"img":false}]}
{"op":"mcm","clk":"11550776066","pt":1719503347519,"mc":[{"id":"1.230178174","rc":[{"atb":[[17,2.5]],"id":52385882}],"con":true,"img":false}]}
{"op":"mcm","clk":"11550776073","pt":1719503347622,"mc":[{"id":"1.230178174","rc":[{"atl":[[120,0]],"id":52385883}],"con":true,"img":false}]}
{"op":"mcm","clk":"11550776081","pt":1719503347725,"mc":[{"id":"1.230178174","rc":[{"atl":[[130,4.65]],"id":52385883}],"con":true,"img":false}]}
{"op":"mcm","clk":"11550776102","pt":1719503347991,"mc":[{"id":"1.230178174","rc":[{"atl":[[130,0]],"id":52385883}],"con":true,"img":false}]}
{"op":"mcm","clk":"11550776111","pt":1719503348093,"mc":[{"id":"1.230178174","rc":[{"atl":[[160,6.27]],"id":52385883}],"con":true,"img":false}]}
{"op":"mcm","clk":"11550776129","pt":1719503348402,"mc":[{"id":"1.230178174","rc":[{"atl":[[190,0],[250,2]],"id":52385897}],"con":true,"img":false}]}
{"op":"mcm","clk":"11550776162","pt":1719503349125,"mc":[{"id":"1.230178174","rc":[{"atb":[[25,5],[29,2.5]],"id":52385898}],"con":true,"img":false}]}
{"op":"mcm","clk":"11550776167","pt":1719503349239,"mc":[{"id":"1.230178174","rc":[{"atl":[[20,2.5],[23,0],[24,5],[27,0]],"id":52385911},{"atl":[[21,2.5],[24,0],[25,5],[28,0]],"id":52385906},{"atl":[[34,0],[25,2.5],[28,0],[29,5]],"id":52385889},{"atb":[[34,0],[50,14.74]],"id":52385883},{"atl":[[70,11.2],[75,0],[90,5],[95,0]],"id":52385885},{"atb":[[9.6,0],[18,5],[20,2.5],[11,0]],"id":52385897},{"atb":[[6.2,0],[7.6,5],[5.7,0],[8.4,2.5]],"id":52385890},{"atl":[[17.5,6.06],[13,2.5],[15,5],[15.5,0]],"id":52385891},{"atl":[[12,2.5],[13,0],[14,12.69],[15,0]],"id":52385892},{"atb":[[9.6,0],[16,2.5],[11,0],[14,5]],"id":52385905},{"atb":[[24,15],[12.5,0],[14.5,0]],"id":52385898}],"con":true,"img":false}]}
{"op":"mcm","clk":"11550776175","pt":1719503349283,"mc":[{"id":"1.230178174","rc":[{"atb":[[17.5,13.64]],"id":52385897}],"con":true,"img":false}]}
{"op":"mcm","clk":"11550776181","pt":1719503349386,"mc":[{"id":"1.230178174","rc":[{"atl":[[65,0],[42,2.5],[48,12.77],[50,5]],"id":52385910},{"atl":[[24,4.35],[26,0]],"id":52385906},{"atl":[[42,17.13],[50,5]],"id":52385903},{"atb":[[23,0]],"id":52385898}],"con":true,"img":false}]}
{"op":"mcm","clk":"11550776187","pt":1719503349490,"mc":[{"id":"1.230178174","rc":[{"atl":[[80,2],[44,13.95],[100,0]],"id":52385910},{"atb":[[17,0]],"id":52385897},{"atl":[[44,0],[55,0]],"id":52385903}],"con":true,"img":false}]}
{"op":"mcm","clk":"11550776200","pt":1719503349698,"mc":[{"id":"1.230178174","rc":[{"atl":[[48,0]],"id":52385910}],"con":true,"img":false}]}
{"op":"mcm","clk":"11550776214","pt":1719503349904,"mc":[{"id":"1.230178174","rc":[{"atb":[[10,0]],"id":52385897}],"con":true,"img":false}]}
{"op":"mcm","clk":"11550776274","pt":1719503350888,"mc":[{"id":"1.230178174","rc":[{"atb":[[6,0]],"id":52385904}],"con":true,"img":false}]}
{"op":"mcm","clk":"11550776281","pt":1719503350991,"mc":[{"id":"1.230178174","rc":[{"atb":[[4.9,28.14],[7,12]],"id":52385904}],"con":true,"img":false}]}
{"op":"mcm","clk":"11550776288","pt":1719503351095,"mc":[{"id":"1.230178174","rc":[{"atb":[[5.8,0]],"id":52385904}],"con":true,"img":false}]}
{"op":"mcm","clk":"11550776296","pt":1719503351197,"mc":[{"id":"1.230178174","rc":[{"atb":[[6,20],[4.9,2.5]],"id":52385904}],"con":true,"img":false}]}
{"op":"mcm","clk":"11550776461","pt":1719503353988,"mc":[{"id":"1.230178174","rc":[{"atl":[[65,2],[80,0]],"id":52385910},{"atl":[[25,4.17],[29,0]],"id":52385911},{"atb":[[1.04,0]],"id":52385912},{"atb":[[25,0]],"id":52385882},{"atl":[[170,3.55],[190,2.5],[210,0],[230,5]],"id":52385896},{"atb":[[1.28,0]],"id":52385890},{"atl":[[16.5,6.45],[17.5,0]],"id":52385891},{"atl":[[32,0],[20,24.1],[21,0],[24,5],[25,4.17]],"id":52385904}],"con":true,"img":false}]}
{"op":"mcm","clk":"11550776468","pt":1719503354195,"mc":[{"id":"1.230178174","rc":[{"atb":[[4,2]],"id":52385910},{"atb":[[4,2]],"id":52385911},{"atb":[[4,2]],"id":52385912},{"atb":[[4,2]],"id":52385913},{"atb":[[4,2]],"id":52385906},{"atb":[[4,2]],"id":52385889},{"atb":[[4,2],[15.5,10]],"id":52385882},{"atb":[[4,2]],"id":52385883},{"atb":[[4,2]],"id":52385884},{"atb":[[4,2]],"id":52385885},{"atb":[[4,2]],"id":52385896},{"atl":[[310,2],[350,0]],"id":52385896},{"atb":[[4,2]],"id":52385897},{"atb":[[4,2]],"id":52385890},{"atb":[[4,2]],"id":52385891},{"atb":[[4,4.5]],"id":52385892},{"atb":[[4,2]],"id":52385903},{"atb":[[4,2]],"id":52385904},{"atb":[[4,2]],"id":52385905},{"atb":[[4,2]],"id":52385898},{"atb":[[4,2]],"id":52385899}],"con":true,"img":false}]}
{"op":"mcm","clk":"11550776527","pt":1719503355431,"mc":[{"id":"1.230178174","rc":[{"atl":[[200,2],[250,0]],"id":52385897}],"con":true,"img":false}]}
{"op":"mcm","clk":"11550776698","pt":1719503358399,"mc":[{"id":"1.230178174","rc":[{"atl":[[100,6.06]],"id":52385897}],"con":true,"img":false}]}
{"op":"mcm","clk":"11550776711","pt":1719503358605,"mc":[{"id":"1.230178174","rc":[{"atl":[[140,0]],"id":52385897}],"con":true,"img":false}]}
{"op":"mcm","clk":"11550776759","pt":1719503359428,"mc":[{"id":"1.230178174","rc":[{"atl":[[20,2.5],[23,0],[24,5],[27,0]],"id":52385913}],"con":true,"img":false}]}
{"op":"mcm","clk":"11550776767","pt":1719503359534,"mc":[{"id":"1.230178174","rc":[{"atl":[[25,4.17]],"id":52385913}],"con":true,"img":false}]}
{"op":"mcm","clk":"11550776774","pt":1719503359637,"mc":[{"id":"1.230178174","rc":[{"atl":[[29,0]],"id":52385913}],"con":true,"img":false}]}
{"op":"mcm","clk":"11550776921","pt":1719503362425,"mc":[{"id":"1.230178174","rc":[{"atb":[[25,15]],"id":52385882}],"con":true,"img":false}]}
{"op":"mcm","clk":"11550776937","pt":1719503362613,"mc":[{"id":"1.230178174","rc":[{"atb":[[15.5,0]],"id":52385882}],"con":true,"img":false}]}
{"op":"mcm","clk":"11550776946","pt":1719503362709,"mc":[{"id":"1.230178174","rc":[{"atl":[[150,4.03]],"id":52385883}],"con":true,"img":false}]}
{"op":"mcm","clk":"11550776954","pt":1719503362816,"mc":[{"id":"1.230178174","rc":[{"atl":[[260,2]],"id":52385883}],"con":true,"img":false}]}
{"op":"mcm","clk":"11550776963","pt":1719503362920,"mc":[{"id":"1.230178174","rc":[{"atl":[[160,2.5],[330,0]],"id":52385883}],"con":true,"img":false}]}
{"op":"mcm","clk":"11550776969","pt":1719503363023,"mc":[{"id":"1.230178174","rc":[{"atl":[[75,5],[55,2.5]],"id":52385912},{"atb":[[25,0]],"id":52385882},{"atl":[[85,2]],"id":52385882},{"atl":[[130,2.5],[170,5]],"id":52385898}],"con":true,"img":false}]}
{"op":"mcm","clk":"11550776977","pt":1719503363126,"mc":[{"id":"1.230178174","rc":[{"atl":[[65,0],[48,0]],"id":52385912},{"atb":[[15.5,10]],"id":52385882},{"atl":[[95,0]],"id":52385882},{"atl":[[150,0],[110,0]],"id":52385898}],"con":true,"img":false}]}
{"op":"mcm","clk":"11550777030","pt":1719503364113,"mc":[{"id":"1.230178174","rc":[{"atb":[[30,15]],"id":52385898}],"con":true,"img":false}]}
{"op":"mcm","clk":"11550777039","pt":1719503364219,"mc":[{"id":"1.230178174","rc":[{"atb":[[25,20]],"id":52385897},{"atb":[[24,0]],"id":52385898}],"con":true,"img":false}]}
{"op":"mcm","clk":"11550777051","pt":1719503364422,"mc":[{"id":"1.230178174","rc":[{"atl":[[40,15.38]],"id":52385910},{"atb":[[17.5,0]],"id":52385897},{"atl":[[100,0]],"id":52385898}],"con":true,"img":false}]}
{"op":"mcm","clk":"11550777056","pt":1719503364525,"mc":[{"id":"1.230178174","rc":[{"atl":[[44,0]],"id":52385910},{"atl":[[160,3.77]],"id":52385898}],"con":true,"img":false}]}
{"op":"mcm","clk":"11550777827","pt":1719503369052,"mc":[{"id":"1.230178174","rc":[{"atb":[[25,15]],"id":52385882}],"con":true,"img":false}]}
{"op":"mcm","clk":"11550777849","pt":1719503369256,"mc":[{"id":"1.230178174","rc":[{"atb":[[15.5,0]],"id":52385882}],"con":true,"img":false}]}
{"op":"mcm","clk":"11550778165","pt":1719503373279,"mc":[{"id":"1.230178174","rc":[{"atb":[[11.5,0],[15.5,2.5]],"id":52385912},{"atb":[[32,0],[40,0],[44,5],[55,2.5]],"id":52385896},{"atb":[[19,0],[22,0],[26,5],[30,2.5]],"id":52385899}],"con":true,"img":false}]}
{"op":"mcm","clk":"11550778175","pt":1719503373382,"mc":[{"id":"1.230178174","rc":[{"atb":[[48,0],[50,12.1]],"id":52385896},{"atb":[[24,15]],"id":52385899}],"con":true,"img":false}]}
{"op":"mcm","clk":"11550778189","pt":1719503373590,"mc":[{"id":"1.230178174","rc":[{"atb":[[23,0]],"id":52385899}],"con":true,"img":false}]}
{"op":"mcm","clk":"11550778599","pt":1719503377773,"mc":[{"id":"1.230178174","rc":[{"atb":[[25,0]],"id":52385882}],"con":true,"img":false}]}
{"op":"mcm","clk":"11550778613","pt":1719503377878,"mc":[{"id":"1.230178174","rc":[{"atb":[[24,15]],"id":52385882},{"atb":[[10.5,0]],"id":52385890}],"con":true,"img":false}]}
{"op":"mcm","clk":"11550778626","pt":1719503378087,"mc":[{"id":"1.230178174","rc":[{"atb":[[24,0]],"id":52385882},{"atb":[[10,34]],"id":52385890}],"con":true,"img":false}]}
{"op":"mcm","clk":"11550778639","pt":1719503378139,"mc":[{"id":"1.230178174","rc":[{"atb":[[9.8,65.66]],"id":52385911},{"atb":[[9.2,64]],"id":52385904}],"con":true,"img":false}]}
{"op":"mcm","clk":"11550778642","pt":1719503378188,"mc":[{"id":"1.230178174","rc":[{"atb":[[23,15]],"id":52385882}],"con":true,"img":false}]}
{"op":"mcm","clk":"11550778659","pt":1719503378300,"mc":[{"id":"1.230178174","rc":[{"atb":[[9.4,0]],"id":52385911},{"atb":[[8.4,0]],"id":52385904}],"con":true,"img":false}]}
{"op":"mcm","clk":"11550778713","pt":1719503378927,"mc":[{"id":"1.230178174","rc":[{"atb":[[26,20]],"id":52385897}],"con":true,"img":false}]}
{"op":"mcm","clk":"11550778724","pt":1719503379027,"mc":[{"id":"1.230178174","rc":[{"atb":[[25,0]],"id":52385897}],"con":true,"img":false}]}
{"op":"mcm","clk":"11550778737","pt":1719503379088,"mc":[{"id":"1.230178174","rc":[{"atl":[[120,5.04]],"id":52385898}],"con":true,"img":false}]}
{"op":"mcm","clk":"11550778755","pt":1719503379302,"mc":[{"id":"1.230178174","rc":[{"atl":[[160,0]],"id":52385898}],"con":true,"img":false}]}
{"op":"mcm","clk":"11550778953","pt":1719503381734,"mc":[{"id":"1.230178174","rc":[{"atl":[[65,2.5],[70,8.7],[85,5],[90,0]],"id":52385884},{"atl":[[32,0],[36,2.5],[40,0],[44,5]],"id":52385890}],"con":true,"img":false}]}
{"op":"mcm","clk":"11550778961","pt":1719503381798,"mc":[{"id":"1.230178174","rc":[{"atl":[[65,11.88],[120,2]],"id":52385884}],"con":true,"img":false}]}
{"op":"mcm","clk":"11550778972","pt":1719503381897,"mc":[{"id":"1.230178174","rc":[{"atl":[[70,0],[140,0]],"id":52385884},{"atl":[[30,0]],"id":52385890}],"con":true,"img":false}]}
{"op":"mcm","clk":"11550778978","pt":1719503381990,"mc":[{"id":"1.230178174","rc":[{"atl":[[42,14.63]],"id":52385890}],"con":true,"img":false}]}
{"op":"mcm","clk":"11550779266","pt":1719503386502,"mc":[{"id":"1.230178174","rc":[{"atb":[[24,15]],"id":52385882}],"con":true,"img":false}]}
{"op":"mcm","clk":"11550779279","pt":1719503386618,"mc":[{"id":"1.230178174","rc":[{"atb":[[19,0]],"id":52385912}],"con":true,"img":false}]}
{"op":"mcm","clk":"11550779285","pt":1719503386712,"mc":[{"id":"1.230178174","rc":[{"atb":[[18.5,10]],"id":52385912},{"atb":[[23,0]],"id":52385882}],"con":true,"img":false}]}
{"op":"mcm","clk":"11550779298","pt":1719503386933,"mc":[{"id":"1.230178174","rc":[{"atl":[[15,42.86]],"id":52385904}],"con":true,"img":false}]}
{"op":"mcm","clk":"11550779313","pt":1719503387131,"mc":[{"id":"1.230178174","rc":[{"atl":[[20,2.5]],"id":52385904}],"con":true,"img":false}]}
{"op":"mcm","clk":"11550779321","pt":1719503387228,"mc":[{"id":"1.230178174","rc":[{"atb":[[9.8,0]],"id":52385911}],"con":true,"img":false}]}
{"op":"mcm","clk":"11550779331","pt":1719503387344,"mc":[{"id":"1.230178174","rc":[{"atb":[[9.6,65.66],[5.8,0],[6,20]],"id":52385911}],"con":true,"img":false}]}
{"op":"mcm","clk":"11550779352","pt":1719503387604,"mc":[{"id":"1.230178174","rc":[{"atb":[[9.6,0]],"id":52385911}],"con":true,"img":false}]}
{"op":"mcm","clk":"11550779358","pt":1719503387697,"mc":[{"id":"1.230178174","rc":[{"atb":[[9,34]],"id":52385911}],"con":true,"img":false}]}
{"op":"mcm","clk":"11550779369","pt":1719503387816,"mc":[{"id":"1.230178174","rc":[{"atb":[[34,18.18]],"id":52385884},{"atb":[[32,19.35]],"id":52385899}],"con":true,"img":false}]}
{"op":"mcm","clk":"11550779375","pt":1719503387911,"mc":[{"id":"1.230178174","rc":[{"atb":[[18.5,0]],"id":52385912},{"atb":[[60,10.17]],"id":52385896},{"atb":[[13,0]],"id":52385903}],"con":true,"img":false}]}
{"op":"mcm","clk":"11550779387","pt":1719503388012,"mc":[{"id":"1.230178174","rc":[{"atb":[[18,15]],"id":52385912},{"atb":[[32,0]],"id":52385884},{"atb":[[14,11]],"id":52385903},{"atb":[[24,0]],"id":52385899}],"con":true,"img":false}]}
{"op":"mcm","clk":"11550779391","pt":1719503388116,"mc":[{"id":"1.230178174","rc":[{"atb":[[50,0]],"id":52385896}],"con":true,"img":false}]}
{"op":"mcm","clk":"11550779558","pt":1719503390915,"mc":[{"id":"1.230178174","rc":[{"atb":[[6,0]],"id":52385892}],"con":true,"img":false}]}
{"op":"mcm","clk":"11550779565","pt":1719503391019,"mc":[{"id":"1.230178174","rc":[{"atb":[[4,37.83],[4.3,35.38],[7,12]],"id":52385892}],"con":true,"img":false}]}
{"op":"mcm","clk":"11550779572","pt":1719503391121,"mc":[{"id":"1.230178174","rc":[{"atb":[[4.2,0]],"id":52385892}],"con":true,"img":false}]}
{"op":"mcm","clk":"11550779635","pt":1719503392208,"mc":[{"id":"1.230178174","rc":[{"atb":[[25,10]],"id":52385882}],"con":true,"img":false}]}
{"op":"mcm","clk":"11550779648","pt":1719503392417,"mc":[{"id":"1.230178174","rc":[{"atb":[[24,0]],"id":52385882},{"atb":[[10.5,34]],"id":52385890}],"con":true,"img":false}]}
{"op":"mcm","clk":"11550779656","pt":1719503392519,"mc":[{"id":"1.230178174","rc":[{"atb":[[9.6,64]],"id":52385911}],"con":true,"img":false}]}
{"op":"mcm","clk":"11550779662","pt":1719503392623,"mc":[{"id":"1.230178174","rc":[{"atb":[[10,0]],"id":52385890}],"con":true,"img":false}]}
{"op":"mcm","clk":"11550779674","pt":1719503392832,"mc":[{"id":"1.230178174","rc":[{"atb":[[9,0]],"id":52385911}],"con":true,"img":false}]}
{"op":"mcm","clk":"11550779875","pt":1719503396336,"mc":[{"id":"1.230178174","rc":[{"atl":[[34,18.18]],"id":52385890}],"con":true,"img":false}]}
{"op":"mcm","clk":"11550779883","pt":1719503396533,"mc":[{"id":"1.230178174","rc":[{"atl":[[42,0]],"id":52385890}],"con":true,"img":false}]}
{"op":"mcm","clk":"11550780181","pt":1719503400908,"mc":[{"id":"1.230178174","rc":[{"atb":[[18.5,15]],"id":52385912}],"con":true,"img":false}]}
{"op":"mcm","clk":"11550780188","pt":1719503401011,"mc":[{"id":"1.230178174","rc":[{"atl":[[15,0]],"id":52385904}],"con":true,"img":false}]}
{"op":"mcm","clk":"11550780197","pt":1719503401117,"mc":[{"id":"1.230178174","rc":[{"atb":[[18,0]],"id":52385912},{"atl":[[19.5,32.43]],"id":52385904}],"con":true,"img":false}]}
{"op":"mcm","clk":"11550780210","pt":1719503401323,"mc":[{"id":"1.230178174","rc":[{"atb":[[9.6,0]],"id":52385911},{"atl":[[14,46.15]],"id":52385911},{"atb":[[1.05,110.29]],"id":52385912},{"atb":[[9.4,0]],"id":52385913},{"atb":[[25,20]],"id":52385885},{"atb":[[5,25],[4.7,0]],"id":52385891},{"atl":[[65,2.5],[85,5],[55,0]],"id":52385905}],"con":true,"img":false}]}
{"op":"mcm","clk":"11550780217","pt":1719503401425,"mc":[{"id":"1.230178174","rc":[{"atb":[[9.4,64]],"id":52385911},{"atl":[[15,0]],"id":52385911},{"atb":[[9.2,34]],"id":52385913},{"atb":[[24,5]],"id":52385885},{"atl":[[110,2]],"id":52385905}],"con":true,"img":false}]}
{"op":"mcm","clk":"11550780222","pt":1719503401531,"mc":[{"id":"1.230178174","rc":[{"atl":[[480,0]],"id":52385905}],"con":true,"img":false}]}
{"op":"mcm","clk":"11550780231","pt":1719503401636,"mc":[{"id":"1.230178174","rc":[{"atl":[[14,0]],"id":52385911},{"atl":[[50,0]],"id":52385905}],"con":true,"img":false}]}
{"op":"mcm","clk":"11550780240","pt":1719503401742,"mc":[{"id":"1.230178174","rc":[{"atl":[[20,34.08]],"id":52385911},{"atb":[[9.2,0]],"id":52385913},{"atl":[[60,10.17]],"id":52385905}],"con":true,"img":false}]}
{"op":"mcm","clk":"11550780252","pt":1719503401849,"mc":[{"id":"1.230178174","rc":[{"atl":[[24,9.35],[25,0]],"id":52385911},{"atl":[[42,14.63]],"id":52385912},{"atb":[[9,15]],"id":52385913},{"atb":[[7,0]],"id":52385892}],"con":true,"img":false}]}
{"op":"mcm","clk":"11550780258","pt":1719503401952,"mc":[{"id":"1.230178174","rc":[{"atb":[[4.3,0],[6,12]],"id":52385892}],"con":true,"img":false}]}
{"op":"mcm","clk":"11550780268","pt":1719503402057,"mc":[{"id":"1.230178174","rc":[{"atl":[[25,4.17]],"id":52385911},{"atl":[[46,0]],"id":52385912}],"con":true,"img":false}]}
{"op":"mcm","clk":"11550780278","pt":1719503402114,"mc":[{"id":"1.230178174","rc":[{"atl":[[24,5]],"id":52385911}],"con":true,"img":false}]}
{"op":"mcm","clk":"11550780285","pt":1719503402219,"mc":[{"id":"1.230178174","rc":[{"atb":[[9.4,0]],"id":52385911}],"con":true,"img":false}]}
{"op":"mcm","clk":"11550780294","pt":1719503402324,"mc":[{"id":"1.230178174","rc":[{"atb":[[9,64]],"id":52385911},{"atl":[[170,0]],"id":52385896},{"atl":[[80,0]],"id":52385899}],"con":true,"img":false}]}
{"op":"mcm","clk":"11550780302","pt":1719503402427,"mc":[{"id":"1.230178174","rc":[{"atl":[[180,3.35]],"id":52385896},{"atl":[[85,7.14]],"id":52385899}],"con":true,"img":false}]}
{"op":"mcm","clk":"11550780322","pt":1719503402739,"mc":[{"id":"1.230178174","rc":[{"atb":[[9,0]],"id":52385911}],"con":true,"img":false}]}
{"op":"mcm","clk":"11550780327","pt":1719503402844,"mc":[{"id":"1.230178174","rc":[{"atb":[[8.8,34]],"id":52385911}],"con":true,"img":false}]}
{"op":"mcm","clk":"11550780334","pt":1719503402950,"mc":[{"id":"1.230178174","rc":[{"atb":[[16,0]],"id":52385910}],"con":true,"img":false}]}
{"op":"mcm","clk":"11550780354","pt":1719503403213,"mc":[{"id":"1.230178174","rc":[{"atb":[[8,0]],"id":52385911},{"atb":[[8,0]],"id":52385913},{"atb":[[24,0]],"id":52385885},{"atb":[[7,0]],"id":52385904}],"con":true,"img":false}]}
{"op":"mcm","clk":"11550780362","pt":1719503403319,"mc":[{"id":"1.230178174","rc":[{"atb":[[4.8,28.82],[6,12],[8.8,0]],"id":52385911},{"atb":[[6,14.5]],"id":52385913},{"atb":[[20,5]],"id":52385885},{"atb":[[8,12],[4.9,28.14]],"id":52385904}],"con":true,"img":false}]}
{"op":"mcm","clk":"11550780370","pt":1719503403425,"mc":[{"id":"1.230178174","rc":[{"atb":[[5.8,20.83],[8.4,50]],"id":52385911},{"atb":[[6.2,19.23],[6,0]],"id":52385904}],"con":true,"img":false}]}
{"op":"mcm","clk":"11550780379","pt":1719503403528,"mc":[{"id":"1.230178174","rc":[{"atb":[[4.8,2.5]],"id":52385911},{"atb":[[4.9,2.5]],"id":52385904}],"con":true,"img":false}]}
{"op":"mcm","clk":"11550780393","pt":1719503403732,"mc":[{"id":"1.230178174","rc":[{"atb":[[8.4,0]],"id":52385911}],"con":true,"img":false}]}
{"op":"mcm","clk":"11550780400","pt":1719503403835,"mc":[{"id":"1.230178174","rc":[{"atb":[[8.8,65.66]],"id":52385911},{"atl":[[110,5.5]],"id":52385898}],"con":true,"img":false}]}
{"op":"mcm","clk":"11550780413","pt":1719503404043,"mc":[{"id":"1.230178174","rc":[{"atl":[[120,0]],"id":52385898}],"con":true,"img":false}]}
{"op":"mcm","clk":"11550780428","pt":1719503404251,"mc":[{"id":"1.230178174","rc":[{"atb":[[8.8,0]],"id":52385911},{"atl":[[11,60]],"id":52385891}],"con":true,"img":false}]}
{"op":"mcm","clk":"11550780435","pt":1719503404305,"mc":[{"id":"1.230178174","rc":[{"atb":[[8.4,34]],"id":52385911},{"atl":[[12,0]],"id":52385891}],"con":true,"img":false}]}
{"op":"mcm","clk":"11550780444","pt":1719503404410,"mc":[{"id":"1.230178174","rc":[{"atb":[[4.5,0],[4.6,2.5],[4.1,0],[4.2,5]],"id":52385891}],"con":true,"img":false}]}
{"op":"mcm","clk":"11550780499","pt":1719503405344,"mc":[{"id":"1.230178174","rc":[{"atl":[[20,0]],"id":52385889},{"atb":[[22,28.57]],"id":52385903},{"atb":[[4.5,0],[5,2.5],[4.9,0]],"id":52385904},{"atl":[[110,0]],"id":52385898}],"con":true,"img":false}]}
{"op":"mcm","clk":"11550780503","pt":1719503405447,"mc":[{"id":"1.230178174","rc":[{"atl":[[21,30]],"id":52385889},{"atb":[[18,0]],"id":52385903},{"atl":[[120,5.04]],"id":52385898}],"con":true,"img":false}]}
{"op":"mcm","clk":"11550780515","pt":1719503405654,"mc":[{"id":"1.230178174","rc":[{"atl":[[21,0]],"id":52385889}],"con":true,"img":false}]}
{"op":"mcm","clk":"11550780522","pt":1719503405758,"mc":[{"id":"1.230178174","rc":[{"atl":[[24,20]],"id":52385889}],"con":true,"img":false}]}
{"op":"mcm","clk":"11550780528","pt":1719503405812,"mc":[{"id":"1.230178174","rc":[{"atl":[[29,8.57],[30,0]],"id":52385889}],"con":true,"img":false}]}
{"op":"mcm","clk":"11550780550","pt":1719503406229,"mc":[{"id":"1.230178174","rc":[{"atl":[[23,7.14]],"id":52385889}],"con":true,"img":false}]}
{"op":"mcm","clk":"11550780559","pt":1719503406433,"mc":[{"id":"1.230178174","rc":[{"atl":[[23,0]],"id":52385889}],"con":true,"img":false}]}
{"op":"mcm","clk":"11550780705","pt":1719503408714,"mc":[{"id":"1.230178174","rc":[{"atl":[[19,2.5],[20,31.58],[22,5],[24,0]],"id":52385911},{"atb":[[18,0],[20,0],[26,25],[30,2.5]],"id":52385897},{"atb":[[10.5,36.5],[7.6,0],[8.4,0],[9.4,5]],"id":52385890},{"atb":[[18,12.5]],"id":52385905},{"atb":[[36,2.5],[25,0]],"id":52385898}],"con":true,"img":false}]}
{"op":"mcm","clk":"11550780716","pt":1719503408824,"mc":[{"id":"1.230178174","rc":[{"atl":[[36,17.14]],"id":52385910},{"atl":[[24,4.35],[25,0]],"id":52385911},{"atl":[[16.5,2.5],[18.5,5],[21,0],[25,0]],"id":52385906},{"atl":[[70,8.7],[75,5],[90,0],[55,2.5],[60,10.17]],"id":52385885},{"atb":[[27,15]],"id":52385897},{"atb":[[14,0]],"id":52385905},{"atb":[[32,15]],"id":52385898}],"con":true,"img":false}]}
{"op":"mcm","clk":"11550780721","pt":1719503408925,"mc":[{"id":"1.230178174","rc":[{"atl":[[36,19.64],[42,0],[44,5],[50,0]],"id":52385910},{"atl":[[16.5,12.5],[19.5,5.41]],"id":52385906},{"atl":[[70,0],[95,2]],"id":52385885},{"atb":[[26,5]],"id":52385897},{"atb":[[14,0]],"id":52385903}],"con":true,"img":false}]}
{"op":"mcm","clk":"11550780730","pt":1719503409031,"mc":[{"id":"1.230178174","rc":[{"atl":[[40,0]],"id":52385910},{"atl":[[17,0],[24,0]],"id":52385906},{"atl":[[100,0]],"id":52385885},{"atb":[[11,34]],"id":52385890},{"atb":[[16,11]],"id":52385903},{"atb":[[30,0]],"id":52385898}],"con":true,"img":false}]}
{"op":"mcm","clk":"11550780746","pt":1719503409335,"mc":[{"id":"1.230178174","rc":[{"atb":[[10.5,2.5]],"id":52385890}],"con":true,"img":false}]}
{"op":"mcm","clk":"11550780774","pt":1719503409954,"mc":[{"id":"1.230178174","rc":[{"atb":[[9,0]],"id":52385890}],"con":true,"img":false}]}
{"op":"mcm","clk":"11550781058","pt":1719503413954,"mc":[{"id":"1.230178174","rc":[{"atb":[[6,2.5]],"id":52385913},{"atb":[[8,0]],"id":52385904}],"con":true,"img":false}]}
{"op":"mcm","clk":"11550781063","pt":1719503414056,"mc":[{"id":"1.230178174","rc":[{"atb":[[7,12]],"id":52385913},{"atb":[[9,12],[5,27.5],[6.2,0]],"id":52385904}],"con":true,"img":false}]}
{"op":"mcm","clk":"11550781135","pt":1719503415248,"mc":[{"id":"1.230178174","rc":[{"atl":[[18.5,34.29]],"id":52385911}],"con":true,"img":false}]}
{"op":"mcm","clk":"11550781148","pt":1719503415455,"mc":[{"id":"1.230178174","rc":[{"atl":[[20,0]],"id":52385911}],"con":true,"img":false}]}
{"op":"mcm","clk":"11550781161","pt":1719503415663,"mc":[{"id":"1.230178174","rc":[{"atl":[[50,12.24]],"id":52385905}],"con":true,"img":false}]}
{"op":"mcm","clk":"11550781183","pt":1719503415871,"mc":[{"id":"1.230178174","rc":[{"atl":[[60,0]],"id":52385905}],"con":true,"img":false}]}
{"op":"mcm","clk":"11550781240","pt":1719503416748,"mc":[{"id":"1.230178174","rc":[{"atl":[[95,6.38]],"id":52385897}],"con":true,"img":false}]}
{"op":"mcm","clk":"11550781252","pt":1719503416954,"mc":[{"id":"1.230178174","rc":[{"atl":[[100,0]],"id":52385897}],"con":true,"img":false}]}
{"op":"mcm","clk":"11550781287","pt":1719503417631,"mc":[{"id":"1.230178174","rc":[{"atb":[[8.4,0]],"id":52385911},{"atb":[[22,0]],"id":52385903}],"con":true,"img":false}]}
{"op":"mcm","clk":"11550781293","pt":1719503417732,"mc":[{"id":"1.230178174","rc":[{"atb":[[8.2,34]],"id":52385911},{"atb":[[19.5,15]],"id":52385903},{"atl":[[110,5.5]],"id":52385898}],"con":true,"img":false}]}
{"op":"mcm","clk":"11550781302","pt":1719503417943,"mc":[{"id":"1.230178174","rc":[{"atb":[[18,0]],"id":52385910},{"atl":[[120,0]],"id":52385898}],"con":true,"img":false}]}
{"op":"mcm","clk":"11550781308","pt":1719503418051,"mc":[{"id":"1.230178174","rc":[{"atb":[[17.5,15]],"id":52385910}],"con":true,"img":false}]}
{"op":"mcm","clk":"11550781326","pt":1719503418459,"mc":[{"id":"1.230178174","rc":[{"atl":[[17,2.5],[19,5],[20,0],[24,0]],"id":52385913},{"atl":[[11,0]],"id":52385891}],"con":true,"img":false}]}
{"op":"mcm","clk":"11550781331","pt":1719503418556,"mc":[{"id":"1.230178174","rc":[{"atl":[[17.5,29]],"id":52385913},{"atl":[[11.5,57.14]],"id":52385891}],"con":true,"img":false}]}
{"op":"mcm","clk":"11550781341","pt":1719503418761,"mc":[{"id":"1.230178174","rc":[{"atl":[[18,0]],"id":52385913},{"atl":[[11.5,0]],"id":52385891}],"con":true,"img":false}]}
{"op":"mcm","clk":"11550781351","pt":1719503418871,"mc":[{"id":"1.230178174","rc":[{"atb":[[18,8.57]],"id":52385910},{"atl":[[12.5,52.17]],"id":52385891}],"con":true,"img":false}]}
{"op":"mcm","clk":"11550781366","pt":1719503419081,"mc":[{"id":"1.230178174","rc":[{"atb":[[18,0]],"id":52385910}],"con":true,"img":false}]}
{"op":"mcm","clk":"11550781375","pt":1719503419228,"mc":[{"id":"1.230178174","rc":[{"atl":[[23,27.27]],"id":52385889}],"con":true,"img":false}]}
{"op":"mcm","clk":"11550781383","pt":1719503419441,"mc":[{"id":"1.230178174","rc":[{"atl":[[24,0]],"id":52385889}],"con":true,"img":false}]}
{"op":"mcm","clk":"11550781418","pt":1719503420006,"mc":[{"id":"1.230178174","rc":[{"atb":[[17.5,0]],"id":52385910}],"con":true,"img":false}]}
{"op":"mcm","clk":"11550781425","pt":1719503420157,"mc":[{"id":"1.230178174","rc":[{"atb":[[16.5,20]],"id":52385910}],"con":true,"img":false}]}
{"op":"mcm","clk":"11550781446","pt":1719503420472,"mc":[{"id":"1.230178174","rc":[{"atb":[[6.2,19.23]],"id":52385904}],"con":true,"img":false}]}
{"op":"mcm","clk":"11550781451","pt":1719503420570,"mc":[{"id":"1.230178174","rc":[{"atb":[[5,2.5]],"id":52385904}],"con":true,"img":false}]}
{"op":"mcm","clk":"11550781557","pt":1719503422546,"mc":[{"id":"1.230178174","rc":[{"atl":[[50,12.24]],"id":52385885},{"atb":[[38,16.22]],"id":52385897},{"atb":[[38,10]],"id":52385898}],"con":true,"img":false}]}
{"op":"mcm","clk":"11550781571","pt":1719503422754,"mc":[{"id":"1.230178174","rc":[{"atl":[[60,0]],"id":52385885},{"atb":[[27,0]],"id":52385897},{"atb":[[11.5,20]],"id":52385890},{"atb":[[32,0]],"id":52385898}],"con":true,"img":false}]}
{"op":"mcm","clk":"11550781576","pt":1719503422846,"mc":[{"id":"1.230178174","rc":[{"atl":[[34,18.18]],"id":52385910}],"con":true,"img":false}]}
{"op":"mcm","clk":"11550781584","pt":1719503422956,"mc":[{"id":"1.230178174","rc":[{"atl":[[36,2.5]],"id":52385910},{"atb":[[8.2,0]],"id":52385911},{"atb":[[11,0]],"id":52385890}],"con":true,"img":false}]}
{"op":"mcm","clk":"11550781589","pt":1719503423054,"mc":[{"id":"1.230178174","rc":[{"atb":[[7.8,65.66]],"id":52385911}],"con":true,"img":false}]}
{"op":"mcm","clk":"11550781622","pt":1719503423677,"mc":[{"id":"1.230178174","rc":[{"atb":[[10.5,6.25]],"id":52385890}],"con":true,"img":false}]}
{"op":"mcm","clk":"11550781640","pt":1719503423938,"mc":[{"id":"1.230178174","rc":[{"atb":[[10.5,2.5]],"id":52385890}],"con":true,"img":false}]}
{"op":"mcm","clk":"11550781657","pt":1719503424347,"mc":[{"id":"1.230178174","rc":[{"atb":[[10.5,55]],"id":52385889}],"con":true,"img":false}]}
{"op":"mcm","clk":"11550781667","pt":1719503424550,"mc":[{"id":"1.230178174","rc":[{"atb":[[9,12]],"id":52385889}],"con":true,"img":false}]}
{"op":"mcm","clk":"11550781791","pt":1719503426893,"mc":[{"id":"1.230178174","rc":[{"atl":[[34,0]],"id":52385890}],"con":true,"img":false}]}
{"op":"mcm","clk":"11550781808","pt":1719503427096,"mc":[{"id":"1.230178174","rc":[{"atl":[[36,17.5]],"id":52385890}],"con":true,"img":false}]}
{"op":"mcm","clk":"11550781858","pt":1719503427967,"mc":[{"id":"1.230178174","rc":[{"atb":[[9,18.29]],"id":52385913}],"con":true,"img":false}]}
{"op":"mcm","clk":"11550781862","pt":1719503428070,"mc":[{"id":"1.230178174","rc":[{"atb":[[8.8,34]],"id":52385913}],"con":true,"img":false}]}
{"op":"mcm","clk":"11550781872","pt":1719503428182,"mc":[{"id":"1.230178174","rc":[{"atb":[[9,0]],"id":52385913}],"con":true,"img":false}]}
{"op":"mcm","clk":"11550781967","pt":1719503430041,"mc":[{"id":"1.230178174","rc":[{"atb":[[8.8,0]],"id":52385913}],"con":true,"img":false}]}
{"op":"mcm","clk":"11550781974","pt":1719503430259,"mc":[{"id":"1.230178174","rc":[{"atb":[[8.6,34]],"id":52385913}],"con":true,"img":false}]}
{"op":"mcm","clk":"11550782064","pt":1719503432057,"mc":[{"id":"1.230178174","rc":[{"atl":[[16.5,34]],"id":52385913}],"con":true,"img":false}]}
{"op":"mcm","clk":"11550782077","pt":1719503432266,"mc":[{"id":"1.230178174","rc":[{"atl":[[17.5,0]],"id":52385913}],"con":true,"img":false}]}
{"op":"mcm","clk":"11550782175","pt":1719503433782,"mc":[{"id":"1.230178174","rc":[{"atb":[[16.5,0]],"id":52385910},{"atl":[[36,0],[75,5],[44,0],[55,2.5]],"id":52385890},{"atb":[[21,30]],"id":52385903}],"con":true,"img":false}]}
{"op":"mcm","clk":"11550782182","pt":1719503433884,"mc":[{"id":"1.230178174","rc":[{"atb":[[16,15]],"id":52385910},{"atl":[[38,10]],"id":52385890}],"con":true,"img":false}]}
{"op":"mcm","clk":"11550782190","pt":1719503433987,"mc":[{"id":"1.230178174","rc":[{"atb":[[19.5,0]],"id":52385903}],"con":true,"img":false}]}
{"op":"mcm","clk":"11550782197","pt":1719503434091,"mc":[{"id":"1.230178174","rc":[{"atl":[[38,0]],"id":52385890}],"con":true,"img":false}]}
{"op":"mcm","clk":"11550782208","pt":1719503434196,"mc":[{"id":"1.230178174","rc":[{"atl":[[40,10]],"id":52385890}],"con":true,"img":false}]}
{"op":"mcm","clk":"11550782229","pt":1719503434459,"mc":[{"id":"1.230178174","rc":[{"atl":[[9.8,0]],"id":52385892}],"con":true,"img":false}]}
{"op":"mcm","clk":"11550782234","pt":1719503434560,"mc":[{"id":"1.230178174","rc":[{"atl":[[10,49.38]],"id":52385892}],"con":true,"img":false}]}
{"op":"mcm","clk":"11550782240","pt":1719503434666,"mc":[{"id":"1.230178174","rc":[{"atl":[[80,2],[14,5]],"id":52385892}],"con":true,"img":false}]}
{"op":"mcm","clk":"11550782248","pt":1719503434768,"mc":[{"id":"1.230178174","rc":[{"atl":[[10,0]],"id":52385892}],"con":true,"img":false}]}
{"op":"mcm","clk":"11550782255","pt":1719503434872,"mc":[{"id":"1.230178174","rc":[{"atl":[[80,0],[11.5,34],[14,12.69]],"id":52385892}],"con":true,"img":false}]}
{"op":"mcm","clk":"11550782263","pt":1719503434976,"mc":[{"id":"1.230178174","rc":[{"atb":[[16,0]],"id":52385910}],"con":true,"img":false}]}
{"op":"mcm","clk":"11550782271","pt":1719503435080,"mc":[{"id":"1.230178174","rc":[{"atb":[[15.5,15]],"id":52385910}],"con":true,"img":false}]}
{"op":"mcm","clk":"11550782329","pt":1719503435963,"mc":[{"id":"1.230178174","rc":[{"atb":[[15.5,0]],"id":52385910},{"atb":[[6,0]],"id":52385911},{"atb":[[16,0]],"id":52385903}],"con":true,"img":false}]}
{"op":"mcm","clk":"11550782336","pt":1719503436072,"mc":[{"id":"1.230178174","rc":[{"atb":[[14.5,20]],"id":52385910},{"atb":[[7,12]],"id":52385911},{"atb":[[14,11]],"id":52385903}],"con":true,"img":false}]}
{"op":"mcm","clk":"11550782344","pt":1719503436171,"mc":[{"id":"1.230178174","rc":[{"atb":[[4.8,28.82],[5.8,0]],"id":52385911}],"con":true,"img":false}]}
{"op":"mcm","clk":"11550782352","pt":1719503436276,"mc":[{"id":"1.230178174","rc":[{"atb":[[4.8,2.5],[5.8,20.83]],"id":52385911},{"atb":[[12,15]],"id":52385890}],"con":true,"img":false}]}
{"op":"mcm","clk":"11550782358","pt":1719503436377,"mc":[{"id":"1.230178174","rc":[{"atb":[[34,0]],"id":52385884}],"con":true,"img":false}]}
{"op":"mcm","clk":"11550782365","pt":1719503436480,"mc":[{"id":"1.230178174","rc":[{"atl":[[23,0]],"id":52385889},{"atb":[[32,19.35]],"id":52385884},{"atb":[[11.5,0]],"id":52385890},{"atl":[[40,0]],"id":52385890}],"con":true,"img":false}]}
{"op":"mcm","clk":"11550782373","pt":1719503436587,"mc":[{"id":"1.230178174","rc":[{"atl":[[24,26.09]],"id":52385889},{"atl":[[42,14.63]],"id":52385890}],"con":true,"img":false}]}
{"op":"mcm","clk":"11550782378","pt":1719503436687,"mc":[{"id":"1.230178174","rc":[{"atl":[[290,2],[29,5]],"id":52385889},{"atb":[[12,0]],"id":52385890},{"atl":[[75,7],[60,0]],"id":52385890}],"con":true,"img":false}]}
{"op":"mcm","clk":"11550782384","pt":1719503436791,"mc":[{"id":"1.230178174","rc":[{"atb":[[11.5,10]],"id":52385890}],"con":true,"img":false}]}
{"op":"mcm","clk":"11550782422","pt":1719503437415,"mc":[{"id":"1.230178174","rc":[{"atb":[[10,11.11],[8.8,0]],"id":52385910},{"atl":[[65,7],[36,0],[44,0],[48,2.5]],"id":52385910},{"atb":[[6.4,18.52],[5.8,0]],"id":52385911},{"atl":[[24,0],[28,3.7]],"id":52385911},{"atb":[[8.6,13.16],[10,2.5],[9.2,5],[13.5,0],[1.05,0],[15.5,0]],"id":52385912},{"atl":[[75,0],[38,2.5],[90,0],[46,5],[55,2]],"id":52385912},{"atb":[[6.4,18.52],[5.8,0]],"id":52385913},{"atl":[[17,0],[19,0],[21,2.5],[25,9.17]],"id":52385913},{"atb":[[5.3,0],[5.7,21.28]],"id":52385906},{"atb":[[5.6,0],[6,20],[7.6,5],[8.4,2.5]],"id":52385889},{"atb":[[16.5,5],[17,0],[18.5,2.5],[15,0]],"id":52385882},{"atl":[[65,0],[70,2.5],[48,0],[120,2]],"id":52385882},{"atl":[[260,0],[150,6.53],[160,0],[190,5],[200,0],[240,2]],"id":52385883},{"atl":[[65,9.38],[130,5],[85,0],[170,2],[95,2.5],[120,0]],"id":52385884},{"atb":[[27,15]],"id":52385885},{"atl":[[130,2],[75,0],[80,2.5],[95,0],[55,0]],"id":52385885},{"atb":[[44,0],[22,5],[26,2.5],[55,0],[14.5,7.41],[60,0]],"id":52385896},{"atl":[[230,7]],"id":52385896},{"atb":[[9.6,16.63],[38,0],[11,2.5]],"id":52385897},{"atl":[[150,7],[200,0]],"id":52385897},{"atb":[[6.4,2.5],[5.8,5],[10.5,0],[6.6,17.86],[9.4,0]],"id":52385890},{"atb":[[5,0],[7.4,60],[5.4,22.73]],"id":52385891},{"atl":[[16.5,0],[18.5,5.71],[13,0],[15,0]],"id":52385891},{"atb":[[4,4.5],[4.8,26.32],[6,61.38]],"id":52385892},{"atb":[[16,0],[9.6,5],[18,10],[11,2.5],[4.1,32.26]],"id":52385905},{"atl":[[65,0],[75,5],[85,2],[110,0],[55,2.5]],"id":52385905},{"atb":[[36,0],[38,0],[10.5,10.53],[12.5,5],[29,0],[14.5,2.5]],"id":52385898},{"atl":[[130,0],[160,5],[170,2],[240,0],[120,2.5]],"id":52385898},{"atb":[[32,0],[11.5,2.5],[9.8,5],[26,0],[30,0],[9.4,11.9]],"id":52385899},{"atl":[[190,0],[120,7]],"id":52385899}],"con":true,"img":false}]}
{"op":"mcm","clk":"11550782427","pt":1719503437467,"mc":[{"id":"1.230178174","rc":[{"atb":[[14.5,0]],"id":52385910},{"atl":[[65,5],[100,2]],"id":52385910},{"atb":[[7.8,0]],"id":52385911},{"atl":[[13.5,48]],"id":52385911},{"atb":[[8.6,0]],"id":52385913},{"atl":[[36,2.86],[25,5]],"id":52385913},{"atb":[[8,12],[5.5,0],[5.9,0]],"id":52385906},{"atl":[[19.5,0],[26,4]],"id":52385906},{"atb":[[7.2,16.13],[10.5,0],[6,0]],"id":52385889},{"atb":[[10,0],[14,7.69]],"id":52385882},{"atl":[[70,0],[75,5],[85,0],[90,2],[55,2.5]],"id":52385882},{"atb":[[32,0],[16,6.67],[12,0]],"id":52385884},{"atl":[[65,0]],"id":52385884},{"atb":[[10.5,0],[14.5,7.41]],"id":52385885},{"atl":[[310,0]],"id":52385896},{"atb":[[26,0],[30,0]],"id":52385897},{"atl":[[95,0]],"id":52385897},{"atl":[[75,5],[42,0]],"id":52385890},{"atl":[[23,2.5],[12.5,0],[27,5]],"id":52385891},{"atb":[[4,2],[3.8,0],[3.9,5],[4.2,2.5]],"id":52385892},{"atl":[[17,5],[12,0],[14,0],[15,2.5]],"id":52385892},{"atb":[[21,0],[7,16.67],[9.4,0]],"id":52385903},{"atl":[[70,0],[36,2.5],[42,14.63],[44,5],[95,2],[50,0]],"id":52385903},{"atb":[[6.2,0],[5.2,23.81]],"id":52385904},{"atl":[[34,3.03],[20,0],[24,0],[25,0]],"id":52385904},{"atb":[[18,0]],"id":52385905},{"atl":[[50,0]],"id":52385905},{"atl":[[110,0]],"id":52385898}],"con":true,"img":false}]}
{"op":"mcm","clk":"11550782433","pt":1719503437573,"mc":[{"id":"1.230178174","rc":[{"atb":[[6.4,18.52],[10,0],[10.5,0],[12.5,0]],"id":52385910},{"atl":[[24,15],[100,0]],"id":52385910},{"atb":[[5.1,24.39],[6.4,0]],"id":52385911},{"atl":[[22,9.76],[28,0]],"id":52385911},{"atb":[[9.6,5],[8.6,0],[10,0],[9.2,0],[11,2.5],[5.7,21.28]],"id":52385912},{"atl":[[36,15]],"id":52385912},{"atb":[[5.6,0],[4.5,28.57],[6.4,0],[6,0]],"id":52385913},{"atb":[[4.8,26.32],[5.7,0]],"id":52385906},{"atb":[[10.5,10.53],[14,0]],"id":52385882},{"atl":[[46,0],[120,0]],"id":52385882},{"atb":[[17.5,2.5],[22,0],[26,0],[15.5,5]],"id":52385884},{"atl":[[170,0],[110,2]],"id":52385884},{"atb":[[16.5,0],[18.5,0],[25,0],[27,0]],"id":52385885},{"atl":[[130,0],[80,4.5],[50,0]],"id":52385885},{"atb":[[22,0],[44,5],[26,0],[55,7.5],[14.5,0]],"id":52385896},{"atl":[[320,2],[230,5]],"id":52385896},{"atb":[[9.6,0],[36,15],[11,0]],"id":52385897},{"atl":[[270,2],[150,0],[160,2.5],[200,5],[110,0]],"id":52385897},{"atb":[[17,19],[11.5,0],[6.6,0]],"id":52385890},{"atl":[[65,2.5],[75,0],[85,5],[55,0]],"id":52385890},{"atb":[[1.8,125],[6,12],[5.4,0]],"id":52385891},{"atl":[[32,3.23],[18.5,0],[22,28.57]],"id":52385891},{"atb":[[4.8,0],[4.2,33.75]],"id":52385892},{"atl":[[40,15.38]],"id":52385903},{"atl":[[32,5],[27,2.5]],"id":52385904},{"atb":[[4.1,0]],"id":52385905},{"atl":[[70,2.5],[75,0],[85,0],[55,0],[120,2]],"id":52385905},{"atb":[[36,0.3],[10.5,0]],"id":52385898},{"atl":[[270,2],[170,0],[200,5],[120,0]],"id":52385898},{"atb":[[11.5,0],[9.8,0],[25,5],[29,2.5],[30,5],[9.4,0]],"id":52385899},{"atl":[[150,5],[90,0],[190,2],[110,2.5],[120,0]],"id":52385899}],"con":true,"img":false}]}
{"op":"mcm","clk":"11550782443","pt":1719503437676,"mc":[{"id":"1.230178174","rc":[{"atb":[[10.5,15],[5.5,5],[5.9,2.5]],"id":52385910},{"atl":[[65,7],[34,0]],"id":52385910},{"atb":[[7,73.04]],"id":52385911},{"atl":[[18.5,0]],"id":52385911},{"atl":[[42,0]],"id":52385912},{"atb":[[3.1,5],[4.1,34],[3.3,2.5]],"id":52385913},{"atl":[[36,0],[25,9.17]],"id":52385913},{"atb":[[4.5,2.5],[4.1,5],[5.7,34]],"id":52385906},{"atl":[[19.5,5.41],[26,0]],"id":52385906},{"atb":[[10,15]],"id":52385889},{"atl":[[48,12.77]],"id":52385882},{"atb":[[16,5],[17.5,0],[18,2.5],[23,10],[12,9.09],[15.5,0]],"id":52385884},{"atl":[[65,9.38]],"id":52385884},{"atb":[[8.6,13.16],[10.5,5],[12.5,2.5],[14.5,0]],"id":52385885},{"atl":[[140,4.32]],"id":52385897},{"atl":[[70,8.7],[110,2]],"id":52385890},{"atl":[[16.5,6.45]],"id":52385892},{"atb":[[8.6,13.16],[12,15],[7,0]],"id":52385903},{"atl":[[65,2],[42,0],[95,0]],"id":52385903},{"atb":[[3.4,41.67],[5.2,0]],"id":52385904},{"atb":[[17.5,10]],"id":52385905},{"atl":[[70,11.2]],"id":52385905},{"atb":[[36,0]],"id":52385898},{"atl":[[150,4.03]],"id":52385898}],"con":true,"img":false}]}
{"op":"mcm","clk":"11550782449","pt":1719503437781,"mc":[{"id":"1.230178174","rc":[{"atb":[[9.6,15]],"id":52385889},{"atl":[[55,11.11]],"id":52385885},{"atb":[[26,5],[30,2.5]],"id":52385897},{"atl":[[11.5,0]],"id":52385892},{"atl":[[19.5,0]],"id":52385904},{"atb":[[34,15]],"id":52385898}],"con":true,"img":false}]}
{"op":"mcm","clk":"11550782457","pt":1719503437884,"mc":[{"id":"1.230178174","rc":[{"atb":[[10,10],[10.5,0]],"id":52385910},{"atl":[[13.5,0]],"id":52385911},{"atb":[[9.6,0],[10,0]],"id":52385889},{"atb":[[20,5],[23,0]],"id":52385884},{"atl":[[140,0]],"id":52385897},{"atl":[[12.5,52.17]],"id":52385892},{"atl":[[34,0],[36,2.86],[20,31.58]],"id":52385904},{"atb":[[13,8]],"id":52385905}],"con":true,"img":false}]}
{"op":"mcm","clk":"11550782463","pt":1719503437990,"mc":[{"id":"1.230178174","rc":[{"atb":[[10,44]],"id":52385910},{"atl":[[13,50]],"id":52385911},{"atb":[[9.8,15]],"id":52385889},{"atl":[[48,0]],"id":52385882},{"atb":[[18.5,10]],"id":52385884},{"atl":[[190,3.17]],"id":52385897}],"con":true,"img":false}]}
{"op":"mcm","clk":"11550782468","pt":1719503438092,"mc":[{"id":"1.230178174","rc":[{"atl":[[21,5]],"id":52385911},{"atl":[[50,12.24]],"id":52385882},{"atb":[[6,0]],"id":52385891}],"con":true,"img":false}]}
{"op":"mcm","clk":"11550782474","pt":1719503438198,"mc":[{"id":"1.230178174","rc":[{"atl":[[22,5]],"id":52385911},{"atb":[[8,12]],"id":52385891}],"con":true,"img":false}]}
{"op":"mcm","clk":"11550782496","pt":1719503438460,"mc":[{"id":"1.230178174","rc":[{"atl":[[12.5,0]],"id":52385892}],"con":true,"img":false}]}
{"op":"mcm","clk":"11550782508","pt":1719503438679,"mc":[{"id":"1.230178174","rc":[{"atl":[[13,17.9]],"id":52385892}],"con":true,"img":false}]}
{"op":"mcm","clk":"11550782563","pt":1719503439703,"mc":[{"id":"1.230178174","rc":[{"atl":[[130,0],[75,5],[95,0],[55,2.5]],"id":52385884}],"con":true,"img":false}]}
{"op":"mcm","clk":"11550782618","pt":1719503440483,"mc":[{"id":"1.230178174","rc":[{"atl":[[24,0]],"id":52385889},{"atl":[[50,12.24]],"id":52385890}],"con":true,"img":false}]}
{"op":"mcm","clk":"11550782627","pt":1719503440589,"mc":[{"id":"1.230178174","rc":[{"atl":[[25,27.5]],"id":52385889},{"atl":[[70,0]],"id":52385890}],"con":true,"img":false}]}
{"op":"mcm","clk":"11550782772","pt":1719503442620,"mc":[{"id":"1.230178174","rc":[{"atb":[[5.7,0],[6.6,17.86]],"id":52385912},{"atl":[[40,2.5],[48,5],[25,25],[29,0]],"id":52385889},{"atl":[[50,0]],"id":52385890},{"atb":[[1.8,0]],"id":52385891},{"atb":[[3.4,0]],"id":52385904},{"atl":[[20,0]],"id":52385904}],"con":true,"img":false}]}
{"op":"mcm","clk":"11550782780","pt":1719503442683,"mc":[{"id":"1.230178174","rc":[{"atb":[[5,25],[6.6,0]],"id":52385912},{"atl":[[25,0]],"id":52385889},{"atl":[[80,2.5],[460,2]],"id":52385885},{"atl":[[80,7.59]],"id":52385890},{"atb":[[3.8,35.71]],"id":52385892},{"atb":[[3.25,44.44]],"id":52385904},{"atl":[[30,15]],"id":52385904},{"atl":[[530,2],[120,0]],"id":52385905}],"con":true,"img":false}]}
{"op":"mcm","clk":"11550782785","pt":1719503442777,"mc":[{"id":"1.230178174","rc":[{"atb":[[4.2,2.5]],"id":52385892}],"con":true,"img":false}]}
{"op":"mcm","clk":"11550782795","pt":1719503442882,"mc":[{"id":"1.230178174","rc":[{"atl":[[290,0],[48,7.13],[26,15]],"id":52385889}],"con":true,"img":false}]}
{"op":"mcm","clk":"11550782808","pt":1719503443090,"mc":[{"id":"1.230178174","rc":[{"atl":[[42,2.44],[48,5],[26,0]],"id":52385889}],"con":true,"img":false}]}
{"op":"mcm","clk":"11550782814","pt":1719503443194,"mc":[{"id":"1.230178174","rc":[{"atl":[[48,7.13],[30,20.69]],"id":52385889}],"con":true,"img":false}]}
{"op":"mcm","clk":"11550782821","pt":1719503443300,"mc":[{"id":"1.230178174","rc":[{"atl":[[42,0]],"id":52385889}],"con":true,"img":false}]}
{"op":"mcm","clk":"11550782945","pt":1719503445376,"mc":[{"id":"1.230178174","rc":[{"atl":[[13.5,48]],"id":52385913}],"con":true,"img":false}]}
{"op":"mcm","clk":"11550782953","pt":1719503445481,"mc":[{"id":"1.230178174","rc":[{"atl":[[21,7.5]],"id":52385913}],"con":true,"img":false}]}
{"op":"mcm","clk":"11550782958","pt":1719503445583,"mc":[{"id":"1.230178174","rc":[{"atl":[[16.5,0],[25,5]],"id":52385913}],"con":true,"img":false}]}
{"op":"mcm","clk":"11550783034","pt":1719503446996,"mc":[{"id":"1.230178174","rc":[{"atb":[[7,61.04]],"id":52385911},{"atl":[[30,0]],"id":52385889},{"atb":[[20,31.58]],"id":52385903}],"con":true,"img":false}]}
{"op":"mcm","clk":"11550783043","pt":1719503447085,"mc":[{"id":"1.230178174","rc":[{"atb":[[6,12],[7,0]],"id":52385911},{"atl":[[32,19.26]],"id":52385889},{"atl":[[60,10.17]],"id":52385890},{"atb":[[12,0]],"id":52385903}],"con":true,"img":false}]}
{"op":"mcm","clk":"11550783048","pt":1719503447191,"mc":[{"id":"1.230178174","rc":[{"atb":[[7,34]],"id":52385911},{"atl":[[80,0]],"id":52385890}],"con":true,"img":false}]}
{"op":"mcm","clk":"11550783058","pt":1719503447399,"mc":[{"id":"1.230178174","rc":[{"atb":[[17.5,0]],"id":52385905}],"con":true,"img":false}]}
{"op":"mcm","clk":"11550783066","pt":1719503447502,"mc":[{"id":"1.230178174","rc":[{"atb":[[17,21]],"id":52385905}],"con":true,"img":false}]}
{"op":"mcm","clk":"11550783070","pt":1719503447608,"mc":[{"id":"1.230178174","rc":[{"atl":[[15,42.86]],"id":52385906},{"atb":[[9.6,34]],"id":52385904}],"con":true,"img":false}]}
{"op":"mcm","clk":"11550783079","pt":1719503447714,"mc":[{"id":"1.230178174","rc":[{"atl":[[80,2],[55,0]],"id":52385912},{"atl":[[16.5,2.5],[18.5,10.71]],"id":52385906},{"atl":[[90,0],[120,2]],"id":52385882},{"atl":[[330,2],[240,0]],"id":52385883},{"atl":[[150,2],[110,0]],"id":52385884},{"atl":[[260,5],[320,0],[190,0],[410,2],[220,2.5],[230,0]],"id":52385896},{"atl":[[270,0],[360,2]],"id":52385897},{"atl":[[150,2],[110,0]],"id":52385890},{"atb":[[1.37,200]],"id":52385891},{"atl":[[32,0],[44,2.33]],"id":52385891},{"atb":[[3.8,0],[3.15,46.51]],"id":52385892},{"atl":[[16.5,0],[20,5.26]],"id":52385892},{"atb":[[9.2,0]],"id":52385904},{"atl":[[36,0],[50,2.04]],"id":52385904},{"atl":[[270,0],[350,2]],"id":52385898},{"atl":[[190,0],[250,2]],"id":52385899}],"con":true,"img":false}]}
{"op":"mcm","clk":"11550783082","pt":1719503447810,"mc":[{"id":"1.230178174","rc":[{"atl":[[19.5,0]],"id":52385906}],"con":true,"img":false}]}
{"op":"mcm","clk":"11550783091","pt":1719503447915,"mc":[{"id":"1.230178174","rc":[{"atb":[[5,0],[4.2,31.25]],"id":52385912},{"atl":[[180,0]],"id":52385896}],"con":true,"img":false}]}
{"op":"mcm","clk":"11550783097","pt":1719503448016,"mc":[{"id":"1.230178174","rc":[{"atb":[[10,34]],"id":52385910},{"atl":[[190,3.17]],"id":52385896}],"con":true,"img":false}]}
{"op":"mcm","clk":"11550783103","pt":1719503448119,"mc":[{"id":"1.230178174","rc":[{"atb":[[9,10]],"id":52385910}],"con":true,"img":false}]}
{"op":"mcm","clk":"11550783112","pt":1719503448225,"mc":[{"id":"1.230178174","rc":[{"atb":[[10,0]],"id":52385910}],"con":true,"img":false}]}
{"op":"mcm","clk":"11550783120","pt":1719503448288,"mc":[{"id":"1.230178174","rc":[{"atb":[[9.8,50]],"id":52385910}],"con":true,"img":false}]}
{"op":"mcm","clk":"11550783151","pt":1719503448704,"mc":[{"id":"1.230178174","rc":[{"atl":[[15,0]],"id":52385906},{"atl":[[190,0]],"id":52385896}],"con":true,"img":false}]}
{"op":"mcm","clk":"11550783162","pt":1719503448800,"mc":[{"id":"1.230178174","rc":[{"atl":[[15.5,41.38]],"id":52385906},{"atl":[[210,2.87]],"id":52385896},{"atb":[[3.7,37.04]],"id":52385904}],"con":true,"img":false}]}
{"op":"mcm","clk":"11550783179","pt":1719503449008,"mc":[{"id":"1.230178174","rc":[{"atl":[[15.5,0]],"id":52385906},{"atb":[[3.25,0]],"id":52385904}],"con":true,"img":false}]}
{"op":"mcm","clk":"11550783192","pt":1719503449216,"mc":[{"id":"1.230178174","rc":[{"atl":[[16,40]],"id":52385906}],"con":true,"img":false}]}
{"op":"mcm","clk":"11550783214","pt":1719503449476,"mc":[{"id":"1.230178174","rc":[{"atb":[[20,20]],"id":52385890}],"con":true,"img":false}]}
{"op":"mcm","clk":"11550783228","pt":1719503449688,"mc":[{"id":"1.230178174","rc":[{"atb":[[25,20]],"id":52385884},{"atb":[[17,0]],"id":52385890}],"con":true,"img":false}]}
{"op":"mcm","clk":"11550783233","pt":1719503449785,"mc":[{"id":"1.230178174","rc":[{"atl":[[30,20.69]],"id":52385889}],"con":true,"img":false}]}
{"op":"mcm","clk":"11550783240","pt":1719503449892,"mc":[{"id":"1.230178174","rc":[{"atb":[[18.5,0]],"id":52385884}],"con":true,"img":false}]}
{"op":"mcm","clk":"11550783249","pt":1719503449997,"mc":[{"id":"1.230178174","rc":[{"atl":[[32,0]],"id":52385889},{"atb":[[21,20]],"id":52385890}],"con":true,"img":false}]}
{"op":"mcm","clk":"11550783261","pt":1719503450200,"mc":[{"id":"1.230178174","rc":[{"atb":[[20,0]],"id":52385890}],"con":true,"img":false}]}
{"op":"mcm","clk":"11550783288","pt":1719503450623,"mc":[{"id":"1.230178174","rc":[{"atb":[[8.6,34]],"id":52385891},{"atb":[[7,15]],"id":52385892}],"con":true,"img":false}]}
{"op":"mcm","clk":"11550783305","pt":1719503450827,"mc":[{"id":"1.230178174","rc":[{"atl":[[23,27.27]],"id":52385910},{"atb":[[60,10.17]],"id":52385896},{"atb":[[40,15.38]],"id":52385897},{"atb":[[7.4,0]],"id":52385891},{"atb":[[6,12]],"id":52385892},{"atl":[[34,18.18]],"id":52385903},{"atb":[[36,17.14]],"id":52385898}],"con":true,"img":false}]}
{"op":"mcm","clk":"11550783315","pt":1719503450933,"mc":[{"id":"1.230178174","rc":[{"atb":[[7.2,72.78]],"id":52385911},{"atb":[[14,29]],"id":52385889},{"atl":[[50,12.24]],"id":52385884},{"atl":[[130,4.65]],"id":52385897},{"atb":[[21,21]],"id":52385905},{"atl":[[60,10.17]],"id":52385905}],"con":true,"img":false}]}
{"op":"mcm","clk":"11550783322","pt":1719503451033,"mc":[{"id":"1.230178174","rc":[{"atl":[[65,5],[24,0],[48,4.63]],"id":52385910},{"atl":[[48,12.77]],"id":52385885},{"atb":[[55,2.5]],"id":52385896},{"atb":[[36,0]],"id":52385897},{"atl":[[40,0]],"id":52385903},{"atl":[[26,24]],"id":52385904},{"atb":[[34,0]],"id":52385898}],"con":true,"img":false}]}
{"op":"mcm","clk":"11550783327","pt":1719503451087,"mc":[{"id":"1.230178174","rc":[{"atb":[[7,0]],"id":52385911},{"atb":[[9.8,0]],"id":52385889},{"atl":[[65,0]],"id":52385884},{"atl":[[190,0]],"id":52385897},{"atb":[[17,0]],"id":52385905},{"atl":[[530,0],[70,2.5],[160,2]],"id":52385905}],"con":true,"img":false}]}
{"op":"mcm","clk":"11550783335","pt":1719503451193,"mc":[{"id":"1.230178174","rc":[{"atl":[[90,2],[55,0]],"id":52385885}],"con":true,"img":false}]}
{"op":"mcm","clk":"11550783344","pt":1719503451308,"mc":[{"id":"1.230178174","rc":[{"atl":[[460,0]],"id":52385885},{"atl":[[30,0]],"id":52385904},{"atl":[[530,2],[160,0]],"id":52385905}],"con":true,"img":false}]}
{"op":"mcm","clk":"11550783350","pt":1719503451393,"mc":[{"id":"1.230178174","rc":[{"atl":[[530,0],[160,2]],"id":52385905}],"con":true,"img":false}]}
{"op":"mcm","clk":"11550783359","pt":1719503451505,"mc":[{"id":"1.230178174","rc":[{"atl":[[530,2],[160,0]],"id":52385905}],"con":true,"img":false}]}
{"op":"mcm","clk":"11550783427","pt":1719503452795,"mc":[{"id":"1.230178174","rc":[{"atl":[[13,0]],"id":52385911}],"con":true,"img":false}]}
{"op":"mcm","clk":"11550783439","pt":1719503452894,"mc":[{"id":"1.230178174","rc":[{"atb":[[7.2,0]],"id":52385911},{"atl":[[13.5,48]],"id":52385911},{"atb":[[9,12.5],[4.2,0]],"id":52385912},{"atb":[[7.2,0],[4.5,28.57]],"id":52385889},{"atb":[[1.37,0],[1.07,237.07]],"id":52385891},{"atl":[[23,0],[26,2.5],[27,0],[30,5]],"id":52385891},{"atb":[[3.7,0]],"id":52385904}],"con":true,"img":false}]}
{"op":"mcm","clk":"11550783447","pt":1719503453004,"mc":[{"id":"1.230178174","rc":[{"atb":[[6,46]],"id":52385911},{"atl":[[21,0],[22,9.76]],"id":52385911},{"atb":[[20,0]],"id":52385903},{"atb":[[1.5,100]],"id":52385904}],"con":true,"img":false}]}
{"op":"mcm","clk":"11550783451","pt":1719503453101,"mc":[{"id":"1.230178174","rc":[{"atb":[[1.07,0]],"id":52385891},{"atl":[[22,0]],"id":52385891},{"atb":[[8.6,0],[19.5,15],[9.2,12.2]],"id":52385903}],"con":true,"img":false}]}
{"op":"mcm","clk":"11550783459","pt":1719503453207,"mc":[{"id":"1.230178174","rc":[{"atl":[[23,15]],"id":52385891}],"con":true,"img":false}]}
{"op":"mcm","clk":"11550783477","pt":1719503453519,"mc":[{"id":"1.230178174","rc":[{"atl":[[130,0]],"id":52385897}],"con":true,"img":false}]}
{"op":"mcm","clk":"11550783480","pt":1719503453619,"mc":[{"id":"1.230178174","rc":[{"atl":[[190,3.17]],"id":52385897}],"con":true,"img":false}]}
{"op":"mcm","clk":"11550783493","pt":1719503453831,"mc":[{"id":"1.230178174","rc":[{"atl":[[80,0],[60,2]],"id":52385912},{"atl":[[90,2],[120,0]],"id":52385882},{"atl":[[150,0],[110,2]],"id":52385884},{"atl":[[340,2],[410,0]],"id":52385896},{"atl":[[290,2],[360,0]],"id":52385897},{"atl":[[150,0],[120,2]],"id":52385890},{"atl":[[38,2.7],[44,0]],"id":52385891},{"atb":[[3.8,35.71],[3.15,0]],"id":52385892},{"atl":[[17,11.25],[20,0]],"id":52385892},{"atl":[[42,2.44],[50,0]],"id":52385904},{"atl":[[290,2],[350,0]],"id":52385898},{"atl":[[200,2],[250,0]],"id":52385899}],"con":true,"img":false}]}
{"op":"mcm","clk":"11550783532","pt":1719503454506,"mc":[{"id":"1.230178174","rc":[{"atb":[[25,0]],"id":52385884}],"con":true,"img":false}]}
{"op":"mcm","clk":"11550783536","pt":1719503454601,"mc":[{"id":"1.230178174","rc":[{"atb":[[24,20]],"id":52385884}],"con":true,"img":false}]}
{"op":"mcm","clk":"11550783541","pt":1719503454705,"mc":[{"id":"1.230178174","rc":[{"atb":[[19.5,20]],"id":52385912},{"atb":[[26,20]],"id":52385882}],"con":true,"img":false}]}
{"op":"mcm","clk":"11550783546","pt":1719503454814,"mc":[{"id":"1.230178174","rc":[{"atb":[[8.6,0]],"id":52385891},{"atb":[[21,0]],"id":52385905}],"con":true,"img":false}]}
{"op":"mcm","clk":"11550783550","pt":1719503454918,"mc":[{"id":"1.230178174","rc":[{"atb":[[18.5,0]],"id":52385912},{"atb":[[25,0]],"id":52385882},{"atb":[[8.4,15]],"id":52385891},{"atb":[[19.5,10]],"id":52385905}],"con":true,"img":false}]}
{"op":"mcm","clk":"11550783559","pt":1719503455121,"mc":[{"id":"1.230178174","rc":[{"atb":[[8.4,0]],"id":52385891},{"atb":[[19.5,0]],"id":52385905}],"con":true,"img":false}]}
{"op":"mcm","clk":"11550783566","pt":1719503455229,"mc":[{"id":"1.230178174","rc":[{"atb":[[18.5,10]],"id":52385905}],"con":true,"img":false}]}
{"op":"mcm","clk":"11550783574","pt":1719503455326,"mc":[{"id":"1.230178174","rc":[{"atb":[[7.8,15]],"id":52385891}],"con":true,"img":false}]}
{"op":"mcm","clk":"11550783748","pt":1719503458131,"mc":[{"id":"1.230178174","rc":[{"atb":[[4.8,26.32],[9,0]],"id":52385912},{"atl":[[30,15]],"id":52385912},{"atb":[[3.8,0],[7,0]],"id":52385892},{"atb":[[9.6,0]],"id":52385904}],"con":true,"img":false}]}
{"op":"mcm","clk":"11550783758","pt":1719503458231,"mc":[{"id":"1.230178174","rc":[{"atl":[[36,0]],"id":52385912},{"atb":[[6.8,46.5],[2.94,51.55]],"id":52385892},{"atb":[[9.4,34]],"id":52385904}],"con":true,"img":false}]}
{"op":"mcm","clk":"11550783772","pt":1719503458438,"mc":[{"id":"1.230178174","rc":[{"atl":[[13,50]],"id":52385913},{"atb":[[6.8,0]],"id":52385892}],"con":true,"img":false}]}
{"op":"mcm","clk":"11550783781","pt":1719503458499,"mc":[{"id":"1.230178174","rc":[{"atl":[[13.5,0]],"id":52385913},{"atb":[[6.2,46.5]],"id":52385892}],"con":true,"img":false}]}
{"op":"mcm","clk":"11550783792","pt":1719503458698,"mc":[{"id":"1.230178174","rc":[{"atb":[[60,10.17]],"id":52385883}],"con":true,"img":false}]}
{"op":"mcm","clk":"11550783799","pt":1719503458801,"mc":[{"id":"1.230178174","rc":[{"atb":[[50,2.5],[27,3.85]],"id":52385883},{"atb":[[24,0]],"id":52385884}],"con":true,"img":false}]}
{"op":"mcm","clk":"11550783806","pt":1719503458903,"mc":[{"id":"1.230178174","rc":[{"atb":[[4.5,0],[6.6,17.86]],"id":52385889},{"atb":[[13.5,0]],"id":52385883},{"atb":[[21,20]],"id":52385884}],"con":true,"img":false}]}
{"op":"mcm","clk":"11550783811","pt":1719503459007,"mc":[{"id":"1.230178174","rc":[{"atb":[[3.2,45.45]],"id":52385904}],"con":true,"img":false}]}
{"op":"mcm","clk":"11550783819","pt":1719503459111,"mc":[{"id":"1.230178174","rc":[{"atb":[[1.5,0]],"id":52385904}],"con":true,"img":false}]}
{"op":"mcm","clk":"11550783846","pt":1719503459525,"mc":[{"id":"1.230178174","rc":[{"atb":[[60,0]],"id":52385883}],"con":true,"img":false}]}
{"op":"mcm","clk":"11550783853","pt":1719503459626,"mc":[{"id":"1.230178174","rc":[{"atb":[[55,10]],"id":52385883}],"con":true,"img":false}]}
{"op":"mcm","clk":"11550783870","pt":1719503459834,"mc":[{"id":"1.230178174","rc":[{"atb":[[9.4,0]],"id":52385904}],"con":true,"img":false}]}
{"op":"mcm","clk":"11550783879","pt":1719503459938,"mc":[{"id":"1.230178174","rc":[{"atb":[[9,27]],"id":52385904}],"con":true,"img":false}]}
{"op":"mcm","clk":"11550783915","pt":1719503460511,"mc":[{"id":"1.230178174","rc":[{"atb":[[19,21]],"id":52385905}],"con":true,"img":false}]}
{"op":"mcm","clk":"11550783922","pt":1719503460613,"mc":[{"id":"1.230178174","rc":[{"atl":[[15.5,41.38]],"id":52385906},{"atb":[[9.2,15]],"id":52385904}],"con":true,"img":false}]}
{"op":"mcm","clk":"11550783930","pt":1719503460717,"mc":[{"id":"1.230178174","rc":[{"atl":[[16.5,8.95]],"id":52385906},{"atb":[[9,12]],"id":52385904},{"atb":[[18.5,0]],"id":52385905}],"con":true,"img":false}]}
{"op":"mcm","clk":"11550783936","pt":1719503460818,"mc":[{"id":"1.230178174","rc":[{"atl":[[16,0],[18.5,5]],"id":52385906}],"con":true,"img":false}]}
{"op":"mcm","clk":"11550783966","pt":1719503461294,"mc":[{"id":"1.230178174","rc":[{"atb":[[4.6,0],[7.8,17.5],[7,5],[4.2,0]],"id":52385891}],"con":true,"img":false}]}
{"op":"mcm","clk":"11550783990","pt":1719503461702,"mc":[{"id":"1.230178174","rc":[{"atl":[[15,42.86]],"id":52385906}],"con":true,"img":false}]}
{"op":"mcm","clk":"11550784000","pt":1719503461908,"mc":[{"id":"1.230178174","rc":[{"atl":[[15.5,0]],"id":52385906}],"con":true,"img":false}]}
{"op":"mcm","clk":"11550784011","pt":1719503462116,"mc":[{"id":"1.230178174","rc":[{"atl":[[16.5,2.5],[18.5,10.71]],"id":52385906},{"atb":[[6.2,2.5],[5.7,5]],"id":52385904}],"con":true,"img":false}]}
{"op":"mcm","clk":"11550784018","pt":1719503462219,"mc":[{"id":"1.230178174","rc":[{"atb":[[5,0]],"id":52385904}],"con":true,"img":false}]}
{"op":"mcm","clk":"11550784074","pt":1719503463220,"mc":[{"id":"1.230178174","rc":[{"atl":[[15,0]],"id":52385906},{"atb":[[19,0]],"id":52385905}],"con":true,"img":false}]}
{"op":"mcm","clk":"11550784080","pt":1719503463318,"mc":[{"id":"1.230178174","rc":[{"atb":[[4.8,0],[3.5,40]],"id":52385912},{"atl":[[16,40]],"id":52385906},{"atb":[[14.5,7.41]],"id":52385896},{"atb":[[2.52,65.79],[2.94,0]],"id":52385892},{"atb":[[18.5,21]],"id":52385905}],"con":true,"img":false}]}
{"op":"mcm","clk":"11550784086","pt":1719503463422,"mc":[{"id":"1.230178174","rc":[{"atl":[[18.5,5],[110,2]],"id":52385906}],"con":true,"img":false}]}
{"op":"mcm","clk":"11550784092","pt":1719503463527,"mc":[{"id":"1.230178174","rc":[{"atl":[[110,0]],"id":52385906},{"atb":[[8.2,34]],"id":52385891},{"atb":[[6.4,46.5]],"id":52385892}],"con":true,"img":false}]}
{"op":"mcm","clk":"11550784098","pt":1719503463629,"mc":[{"id":"1.230178174","rc":[{"atl":[[18.5,10.71]],"id":52385906}],"con":true,"img":false}]}
{"op":"mcm","clk":"11550784104","pt":1719503463734,"mc":[{"id":"1.230178174","rc":[{"atl":[[22,28.57]],"id":52385910},{"atb":[[7.8,2.5]],"id":52385891},{"atb":[[6.2,0]],"id":52385892}],"con":true,"img":false}]}
{"op":"mcm","clk":"11550784110","pt":1719503463836,"mc":[{"id":"1.230178174","rc":[{"atl":[[23,0]],"id":52385910},{"atl":[[150,4.03]],"id":52385897}],"con":true,"img":false}]}
{"op":"mcm","clk":"11550784117","pt":1719503463892,"mc":[{"id":"1.230178174","rc":[{"atb":[[6.6,53.78]],"id":52385911},{"atl":[[46,13.33]],"id":52385885},{"atl":[[190,0]],"id":52385897},{"atb":[[20,21]],"id":52385905}],"con":true,"img":false}]}
{"op":"mcm","clk":"11550784124","pt":1719503463997,"mc":[{"id":"1.230178174","rc":[{"atb":[[6,12]],"id":52385911},{"atl":[[80,4.5],[90,0]],"id":52385885},{"atb":[[18.5,0]],"id":52385905}],"con":true,"img":false}]}
{"op":"mcm","clk":"11550784129","pt":1719503464105,"mc":[{"id":"1.230178174","rc":[{"atl":[[48,0]],"id":52385885},{"atb":[[46,3.43]],"id":52385896}],"con":true,"img":false}]}
{"op":"mcm","clk":"11550784137","pt":1719503464211,"mc":[{"id":"1.230178174","rc":[{"atl":[[80,2.5],[450,2]],"id":52385885}],"con":true,"img":false}]}
{"op":"mcm","clk":"11550784175","pt":1719503464826,"mc":[{"id":"1.230178174","rc":[{"atb":[[7.6,20.15]],"id":52385889}],"con":true,"img":false}]}
{"op":"mcm","clk":"11550784182","pt":1719503464931,"mc":[{"id":"1.230178174","rc":[{"atb":[[6.6,0]],"id":52385889},{"atb":[[46,0]],"id":52385896},{"atb":[[4.1,32.26]],"id":52385904}],"con":true,"img":false}]}
{"op":"mcm","clk":"11550784189","pt":1719503465032,"mc":[{"id":"1.230178174","rc":[{"atb":[[3.2,0]],"id":52385904}],"con":true,"img":false}]}
{"op":"mcm","clk":"11550784212","pt":1719503465295,"mc":[{"id":"1.230178174","rc":[{"atl":[[16,5],[19,0],[22,4.76],[14,2.5]],"id":52385911},{"atb":[[36,2.5],[29,5]],"id":52385897},{"atb":[[16.5,5],[18.5,2.5],[6.4,0],[5.8,0]],"id":52385890},{"atb":[[16.5,5],[18.5,2.5]],"id":52385905},{"atb":[[36,19.64],[12.5,0],[14.5,0],[29,5]],"id":52385898}],"con":true,"img":false}]}
{"op":"mcm","clk":"11550784219","pt":1719503465401,"mc":[{"id":"1.230178174","rc":[{"atl":[[16,11.67]],"id":52385911},{"atl":[[16.5,0],[17,5],[18.5,5.71],[15,2.5]],"id":52385906},{"atl":[[80,0],[42,2.5],[46,0],[50,5]],"id":52385885},{"atb":[[40,0],[26,0],[30,0]],"id":52385897},{"atb":[[9.6,0],[11,0]],"id":52385905}],"con":true,"img":false}]}
{"op":"mcm","clk":"11550784229","pt":1719503465506,"mc":[{"id":"1.230178174","rc":[{"atl":[[65,0],[21,2.5],[22,0],[48,2.13],[25,5]],"id":52385910},{"atl":[[22,0]],"id":52385911},{"atl":[[16.5,6.45]],"id":52385906},{"atl":[[44,13.95]],"id":52385885},{"atb":[[38,13.06]],"id":52385897}],"con":true,"img":false}]}
{"op":"mcm","clk":"11550784238","pt":1719503465612,"mc":[{"id":"1.230178174","rc":[{"atl":[[65,2],[23,27.27],[48,0]],"id":52385910},{"atl":[[18.5,0]],"id":52385906}],"con":true,"img":false}]}
{"op":"mcm","clk":"11550784262","pt":1719503466025,"mc":[{"id":"1.230178174","rc":[{"atb":[[13,0]],"id":52385905}],"con":true,"img":false}]}
{"op":"mcm","clk":"11550784275","pt":1719503466233,"mc":[{"id":"1.230178174","rc":[{"atb":[[9,0]],"id":52385910},{"atb":[[6,0]],"id":52385911}],"con":true,"img":false}]}
{"op":"mcm","clk":"11550784282","pt":1719503466337,"mc":[{"id":"1.230178174","rc":[{"atb":[[10,10]],"id":52385910},{"atb":[[7,12]],"id":52385911}],"con":true,"img":false}]}
{"op":"mcm","clk":"11550784290","pt":1719503466441,"mc":[{"id":"1.230178174","rc":[{"atb":[[10,67.04]],"id":52385910},{"atb":[[7,84.78]],"id":52385911}],"con":true,"img":false}]}
{"op":"mcm","clk":"11550784305","pt":1719503466599,"mc":[{"id":"1.230178174","rc":[{"atb":[[9.8,0]],"id":52385910},{"atb":[[6.6,0]],"id":52385911}],"con":true,"img":false}]}
{"op":"mcm","clk":"11550784362","pt":1719503467738,"mc":[{"id":"1.230178174","rc":[{"atb":[[8.6,34]],"id":52385891},{"atb":[[21,15]],"id":52385905}],"con":true,"img":false}]}
{"op":"mcm","clk":"11550784367","pt":1719503467842,"mc":[{"id":"1.230178174","rc":[{"atb":[[8.2,0]],"id":52385891}],"con":true,"img":false}]}
{"op":"mcm","clk":"11550784376","pt":1719503467901,"mc":[{"id":"1.230178174","rc":[{"atb":[[20,0]],"id":52385905}],"con":true,"img":false}]}
{"op":"mcm","clk":"11550784386","pt":1719503468110,"mc":[{"id":"1.230178174","rc":[{"atb":[[8.8,34]],"id":52385891}],"con":true,"img":false}]}
{"op":"mcm","clk":"11550784395","pt":1719503468211,"mc":[{"id":"1.230178174","rc":[{"atb":[[8.6,0],[1.34,200]],"id":52385891},{"atb":[[4.1,0],[4.9,25.64]],"id":52385904},{"atb":[[1.05,110.29]],"id":52385905}],"con":true,"img":false}]}
{"op":"mcm","clk":"11550784402","pt":1719503468329,"mc":[{"id":"1.230178174","rc":[{"atb":[[3.5,0]],"id":52385912},{"atl":[[30,0]],"id":52385912},{"atb":[[14.5,0]],"id":52385896},{"atb":[[2.52,0],[2.7,58.82]],"id":52385892},{"atb":[[19.5,0]],"id":52385903}],"con":true,"img":false}]}
{"op":"mcm","clk":"11550784410","pt":1719503468420,"mc":[{"id":"1.230178174","rc":[{"atb":[[2.7,58.82]],"id":52385912},{"atl":[[36,17.14]],"id":52385912},{"atb":[[4.1,32.26]],"id":52385896},{"atb":[[19,32]],"id":52385903},{"atb":[[1.05,0]],"id":52385905}],"con":true,"img":false}]}
{"op":"mcm","clk":"11550784425","pt":1719503468628,"mc":[{"id":"1.230178174","rc":[{"atb":[[19,0]],"id":52385903}],"con":true,"img":false}]}
{"op":"mcm","clk":"11550784431","pt":1719503468732,"mc":[{"id":"1.230178174","rc":[{"atb":[[18,32]],"id":52385903}],"con":true,"img":false}]}
{"op":"mcm","clk":"11550784472","pt":1719503469310,"mc":[{"id":"1.230178174","rc":[{"atb":[[18,45.51]],"id":52385903}],"con":true,"img":false}]}
{"op":"mcm","clk":"11550784525","pt":1719503470131,"mc":[{"id":"1.230178174","rc":[{"atl":[[75,2],[450,0]],"id":52385885}],"con":true,"img":false}]}
{"op":"mcm","clk":"11550784532","pt":1719503470235,"mc":[{"id":"1.230178174","rc":[{"atb":[[18,32]],"id":52385903}],"con":true,"img":false}]}
{"op":"mcm","clk":"11550784567","pt":1719503470931,"mc":[{"id":"1.230178174","rc":[{"atb":[[9.8,34]],"id":52385904}],"con":true,"img":false}]}
{"op":"mcm","clk":"11550784581","pt":1719503471136,"mc":[{"id":"1.230178174","rc":[{"atb":[[9.2,0]],"id":52385904}],"con":true,"img":false}]}
{"op":"mcm","clk":"11550784588","pt":1719503471240,"mc":[{"id":"1.230178174","rc":[{"atl":[[11.5,57.14]],"id":52385913}],"con":true,"img":false}]}
{"op":"mcm","clk":"11550784599","pt":1719503471397,"mc":[{"id":"1.230178174","rc":[{"atl":[[13,0]],"id":52385913}],"con":true,"img":false}]}
{"op":"mcm","clk":"11550784613","pt":1719503471511,"mc":[{"id":"1.230178174","rc":[{"atl":[[65,0],[34,3.03]],"id":52385910},{"atb":[[60,10.17]],"id":52385883}],"con":true,"img":false}]}
{"op":"mcm","clk":"11550784628","pt":1719503471712,"mc":[{"id":"1.230178174","rc":[{"atb":[[55,0]],"id":52385883}],"con":true,"img":false}]}
{"op":"mcm","clk":"11550784666","pt":1719503472338,"mc":[{"id":"1.230178174","rc":[{"atl":[[30,0]],"id":52385889},{"atb":[[24,20]],"id":52385884}],"con":true,"img":false}]}
{"op":"mcm","clk":"11550784673","pt":1719503472440,"mc":[{"id":"1.230178174","rc":[{"atl":[[32,19.35],[380,2],[48,5]],"id":52385889},{"atb":[[21,0]],"id":52385884}],"con":true,"img":false}]}
{"op":"mcm","clk":"11550784681","pt":1719503472543,"mc":[{"id":"1.230178174","rc":[{"atl":[[380,0],[48,7.13]],"id":52385889}],"con":true,"img":false}]}
