{"op":"mcm","clk":"11536380633","pt":1719425245562,"mc":[{"id":"1.230178309","marketDefinition":{"bspMarket":true,"turnInPlayEnabled":false,"persistenceEnabled":false,"marketBaseRate":5.0,"eventId":"33376062","eventTypeId":"4339","numberOfWinners":2,"bettingType":"ODDS","marketType":"PLACE","marketTime":"2024-06-27T13:54:00.000Z","suspendTime":"2024-06-27T13:54:00.000Z","bspReconciled":false,"complete":true,"inPlay":false,"crossMatching":false,"runnersVoidable":false,"numberOfActiveRunners":6,"betDelay":0,"status":"OPEN","runners":[{"status":"ACTIVE","sortPriority":1,"id":39362025,"name":"1. Errill Merry"},{"status":"ACTIVE","sortPriority":2,"id":70218235,"name":"2. Boozed Jill"},{"status":"ACTIVE","sortPriority":3,"id":44798446,"name":"3. Fearmore Diva"},{"status":"ACTIVE","sortPriority":4,"id":48500723,"name":"4. Magical Legend"},{"status":"ACTIVE","sortPriority":5,"id":40953876,"name":"5. Coonough Chimes"},{"status":"ACTIVE","sortPriority":6,"id":55829870,"name":"6. Grumpy Cookie"}],"regulators":["MR_INT"],"venue":"Kinsley","countryCode":"GB","discountAllowed":false,"timezone":"Europe/London","openDate":"2024-06-27T13:36:00.000Z","version":5994643737,"name":"To Be Placed","eventName":"Kinsley 27th Jun"},"rc":[],"con":true,"img":false}]}
{"op":"mcm","clk":"11536380896","pt":1719425247549,"mc":[{"id":"1.230178309","marketDefinition":{"bspMarket":true,"turnInPlayEnabled":false,"persistenceEnabled":false,"marketBaseRate":5.0,"eventId":"33376062","eventTypeId":"4339","numberOfWinners":2,"bettingType":"ODDS","marketType":"PLACE","marketTime":"2024-06-27T13:54:00.000Z","suspendTime":"2024-06-27T13:54:00.000Z","bspReconciled":false,"complete":true,"inPlay":false,"crossMatching":false,"runnersVoidable":false,"numberOfActiveRunners":6,"betDelay":0,"status":"OPEN","runners":[{"status":"ACTIVE","sortPriority":1,"id":39362025,"name":"1. Errill Merry"},{"status":"ACTIVE","sortPriority":2,"id":70218235,"name":"2. Boozed Jill"},{"status":"ACTIVE","sortPriority":3,"id":44798446,"name":"3. Fearmore Diva"},{"status":"ACTIVE","sortPriority":4,"id":48500723,"name":"4. Magical Legend"},{"status":"ACTIVE","sortPriority":5,"id":40953876,"name":"5. Coonough Chimes"},{"status":"ACTIVE","sortPriority":6,"id":55829870,"name":"6. Grumpy Cookie"}],"regulators":["MR_INT"],"venue":"Kinsley","countryCode":"GB","discountAllowed":true,"timezone":"Europe/London","openDate":"2024-06-27T13:36:00.000Z","version":5994643737,"name":"To Be Placed","eventName":"Kinsley 27th Jun"},"rc":[],"con":true,"img":false}]}
{"op":"mcm","clk":"11536615625","pt":1719428252131,"mc":[{"id":"1.230178309","rc":[{"atb":[[1.03,15.09]],"id":40953876},{"atl":[[990,0.84]],"id":40953876},{"spn":495.51,"spf":"NaN","id":40953876},{"atb":[[1.01,45.27]],"id":39362025},{"atl":[[1000,0.84]],"id":39362025},{"spn":500.5,"spf":"NaN","id":39362025},{"atb":[[1.02,22.63]],"id":48500723},{"atl":[[1000,0.84]],"id":48500723},{"spn":500.51,"spf":"NaN","id":48500723},{"atb":[[1.01,45.27]],"id":44798446},{"atl":[[1000,0.84]],"id":44798446},{"spn":500.5,"spf":"NaN","id":44798446},{"atb":[[1.01,45.27]],"id":70218235},{"atl":[[990,0.84]],"id":70218235},{"spn":495.5,"spf":"NaN","id":70218235},{"atb":[[1.02,22.63]],"id":55829870},{"atl":[[1000,0.84]],"id":55829870},{"spn":500.51,"spf":"NaN","id":55829870}],"con":true,"img":false}]}
{"op":"mcm","clk":"11536837682","pt":1719431865039,"mc":[{"id":"1.230178309","rc":[{"atb":[[1.03,15.09]],"id":40953876},{"atl":[[990,0.26]],"id":40953876},{"atb":[[1.01,45.28]],"id":39362025},{"atl":[[1000,0.26]],"id":39362025},{"atb":[[1.02,22.64]],"id":48500723},{"atl":[[1000,0.26]],"id":48500723},{"atb":[[1.01,45.28]],"id":44798446},{"atl":[[1000,0.26]],"id":44798446},{"atb":[[1.01,45.28]],"id":70218235},{"atl":[[990,0.26]],"id":70218235},{"atb":[[1.02,22.64]],"id":55829870},{"atl":[[1000,0.26]],"id":55829870}],"con":true,"img":false}]}
{"op":"mcm","clk":"11537232224","pt":1719437882514,"mc":[{"id":"1.230178309","marketDefinition":{"bspMarket":true,"turnInPlayEnabled":false,"persistenceEnabled":false,"marketBaseRate":5.0,"eventId":"33376062","eventTypeId":"4339","numberOfWinners":2,"bettingType":"ODDS","marketType":"PLACE","marketTime":"2024-06-27T13:54:00.000Z","suspendTime":"2024-06-27T13:54:00.000Z","bspReconciled":false,"complete":true,"inPlay":false,"crossMatching":false,"runnersVoidable":false,"numberOfActiveRunners":6,"betDelay":0,"status":"OPEN","runners":[{"status":"ACTIVE","sortPriority":1,"id":39362025,"name":"1. Errill Merry"},{"status":"ACTIVE","sortPriority":2,"id":70218235,"name":"2. Boozed Jill"},{"status":"ACTIVE","sortPriority":3,"id":44798446,"name":"3. Fearmore Diva"},{"status":"ACTIVE","sortPriority":4,"id":48500723,"name":"4. Magical Legend"},{"status":"ACTIVE","sortPriority":5,"id":40953876,"name":"5. Coonough Chimes"},{"status":"ACTIVE","sortPriority":6,"id":55829870,"name":"6. Grumpy Cookie"}],"regulators":["MR_INT"],"venue":"Kinsley","countryCode":"GB","discountAllowed":true,"timezone":"Europe/London","openDate":"2024-06-27T13:36:00.000Z","version":5994643737,"name":"To Be Placed","eventName":"Kinsley 27th Jun"},"rc":[{"atb":[[1.03,15.09]],"id":40953876},{"atl":[[990,0.26]],"id":40953876},{"spn":495.51,"spf":"NaN","id":40953876},{"atb":[[1.01,45.28]],"id":39362025},{"atl":[[1000,0.26]],"id":39362025},{"spn":500.5,"spf":"NaN","id":39362025},{"atb":[[1.02,22.64]],"id":48500723},{"atl":[[1000,0.26]],"id":48500723},{"spn":500.51,"spf":"NaN","id":48500723},{"atb":[[1.01,45.28]],"id":44798446},{"atl":[[1000,0.26]],"id":44798446},{"spn":500.5,"spf":"NaN","id":44798446},{"atb":[[1.01,45.28]],"id":70218235},{"atl":[[990,0.26]],"id":70218235},{"spn":495.5,"spf":"NaN","id":70218235},{"atb":[[1.02,22.64]],"id":55829870},{"atl":[[1000,0.26]],"id":55829870},{"spn":500.51,"spf":"NaN","id":55829870}],"con":true,"img":true}]}
{"op":"mcm","clk":"11537573351","pt":1719443282535,"mc":[{"id":"1.230178309","marketDefinition":{"bspMarket":true,"turnInPlayEnabled":false,"persistenceEnabled":false,"marketBaseRate":5.0,"eventId":"33376062","eventTypeId":"4339","numberOfWinners":2,"bettingType":"ODDS","marketType":"PLACE","marketTime":"2024-06-27T13:54:00.000Z","suspendTime":"2024-06-27T13:54:00.000Z","bspReconciled":false,"complete":true,"inPlay":false,"crossMatching":false,"runnersVoidable":false,"numberOfActiveRunners":6,"betDelay":0,"status":"OPEN","runners":[{"status":"ACTIVE","sortPriority":1,"id":39362025,"name":"1. Errill Merry"},{"status":"ACTIVE","sortPriority":2,"id":70218235,"name":"2. Boozed Jill"},{"status":"ACTIVE","sortPriority":3,"id":44798446,"name":"3. Fearmore Diva"},{"status":"ACTIVE","sortPriority":4,"id":48500723,"name":"4. Magical Legend"},{"status":"ACTIVE","sortPriority":5,"id":40953876,"name":"5. Coonough Chimes"},{"status":"ACTIVE","sortPriority":6,"id":55829870,"name":"6. Grumpy Cookie"}],"regulators":["MR_INT"],"venue":"Kinsley","countryCode":"GB","discountAllowed":true,"timezone":"Europe/London","openDate":"2024-06-27T13:36:00.000Z","version":5994643737,"name":"To Be Placed","eventName":"Kinsley 27th Jun"},"rc":[{"atb":[[1.03,15.09]],"id":40953876},{"atl":[[990,0.26]],"id":40953876},{"spn":495.51,"spf":"NaN","id":40953876},{"atb":[[1.01,45.29]],"id":39362025},{"atl":[[1000,0.26]],"id":39362025},{"spn":500.5,"spf":"NaN","id":39362025},{"atb":[[1.02,22.64]],"id":48500723},{"atl":[[1000,0.26]],"id":48500723},{"spn":500.51,"spf":"NaN","id":48500723},{"atb":[[1.01,45.29]],"id":44798446},{"atl":[[1000,0.26]],"id":44798446},{"spn":500.5,"spf":"NaN","id":44798446},{"atb":[[1.01,45.29]],"id":70218235},{"atl":[[990,0.26]],"id":70218235},{"spn":495.5,"spf":"NaN","id":70218235},{"atb":[[1.02,22.64]],"id":55829870},{"atl":[[1000,0.26]],"id":55829870},{"spn":500.51,"spf":"NaN","id":55829870}],"con":true,"img":true}]}
{"op":"mcm","clk":"11537954911","pt":1719448682555,"mc":[{"id":"1.230178309","marketDefinition":{"bspMarket":true,"turnInPlayEnabled":false,"persistenceEnabled":false,"marketBaseRate":5.0,"eventId":"33376062","eventTypeId":"4339","numberOfWinners":2,"bettingType":"ODDS","marketType":"PLACE","marketTime":"2024-06-27T13:54:00.000Z","suspendTime":"2024-06-27T13:54:00.000Z","bspReconciled":false,"complete":true,"inPlay":false,"crossMatching":false,"runnersVoidable":false,"numberOfActiveRunners":6,"betDelay":0,"status":"OPEN","runners":[{"status":"ACTIVE","sortPriority":1,"id":39362025,"name":"1. Errill Merry"},{"status":"ACTIVE","sortPriority":2,"id":70218235,"name":"2. Boozed Jill"},{"status":"ACTIVE","sortPriority":3,"id":44798446,"name":"3. Fearmore Diva"},{"status":"ACTIVE","sortPriority":4,"id":48500723,"name":"4. Magical Legend"},{"status":"ACTIVE","sortPriority":5,"id":40953876,"name":"5. Coonough Chimes"},{"status":"ACTIVE","sortPriority":6,"id":55829870,"name":"6. Grumpy Cookie"}],"regulators":["MR_INT"],"venue":"Kinsley","countryCode":"GB","discountAllowed":true,"timezone":"Europe/London","openDate":"2024-06-27T13:36:00.000Z","version":5994643737,"name":"To Be Placed","eventName":"Kinsley 27th Jun"},"rc":[{"atb":[[1.03,15.09]],"id":40953876},{"atl":[[990,0.26]],"id":40953876},{"spn":495.51,"spf":"NaN","id":40953876},{"atb":[[1.01,45.28]],"id":39362025},{"atl":[[1000,0.26]],"id":39362025},{"spn":500.5,"spf":"NaN","id":39362025},{"atb":[[1.02,22.64]],"id":48500723},{"atl":[[1000,0.26]],"id":48500723},{"spn":500.51,"spf":"NaN","id":48500723},{"atb":[[1.01,45.28]],"id":44798446},{"atl":[[1000,0.26]],"id":44798446},{"spn":500.5,"spf":"NaN","id":44798446},{"atb":[[1.01,45.28]],"id":70218235},{"atl":[[990,0.26]],"id":70218235},{"spn":495.5,"spf":"NaN","id":70218235},{"atb":[[1.02,22.64]],"id":55829870},{"atl":[[1000,0.26]],"id":55829870},{"spn":500.51,"spf":"NaN","id":55829870}],"con":true,"img":true}]}
{"op":"mcm","clk":"11538170574","pt":1719454082533,"mc":[{"id":"1.230178309","marketDefinition":{"bspMarket":true,"turnInPlayEnabled":false,"persistenceEnabled":false,"marketBaseRate":5.0,"eventId":"33376062","eventTypeId":"4339","numberOfWinners":2,"bettingType":"ODDS","marketType":"PLACE","marketTime":"2024-06-27T13:54:00.000Z","suspendTime":"2024-06-27T13:54:00.000Z","bspReconciled":false,"complete":true,"inPlay":false,"crossMatching":false,"runnersVoidable":false,"numberOfActiveRunners":6,"betDelay":0,"status":"OPEN","runners":[{"status":"ACTIVE","sortPriority":1,"id":39362025,"name":"1. Errill Merry"},{"status":"ACTIVE","sortPriority":2,"id":70218235,"name":"2. Boozed Jill"},{"status":"ACTIVE","sortPriority":3,"id":44798446,"name":"3. Fearmore Diva"},{"status":"ACTIVE","sortPriority":4,"id":48500723,"name":"4. Magical Legend"},{"status":"ACTIVE","sortPriority":5,"id":40953876,"name":"5. Coonough Chimes"},{"status":"ACTIVE","sortPriority":6,"id":55829870,"name":"6. Grumpy Cookie"}],"regulators":["MR_INT"],"venue":"Kinsley","countryCode":"GB","discountAllowed":true,"timezone":"Europe/London","openDate":"2024-06-27T13:36:00.000Z","version":5994643737,"name":"To Be Placed","eventName":"Kinsley 27th Jun"},"rc":[{"atb":[[1.03,15.09]],"id":40953876},{"atl":[[990,0.26]],"id":40953876},{"spn":495.51,"spf":"NaN","id":40953876},{"atb":[[1.01,45.29]],"id":39362025},{"atl":[[1000,0.26]],"id":39362025},{"spn":500.5,"spf":"NaN","id":39362025},{"atb":[[1.02,22.64]],"id":48500723},{"atl":[[1000,0.26]],"id":48500723},{"spn":500.51,"spf":"NaN","id":48500723},{"atb":[[1.01,45.29]],"id":44798446},{"atl":[[1000,0.26]],"id":44798446},{"spn":500.5,"spf":"NaN","id":44798446},{"atb":[[1.01,45.29]],"id":70218235},{"atl":[[990,0.26]],"id":70218235},{"spn":495.5,"spf":"NaN","id":70218235},{"atb":[[1.02,22.64]],"id":55829870},{"atl":[[1000,0.26]],"id":55829870},{"spn":500.51,"spf":"NaN","id":55829870}],"con":true,"img":true}]}
{"op":"mcm","clk":"11538368232","pt":1719459482560,"mc":[{"id":"1.230178309","marketDefinition":{"bspMarket":true,"turnInPlayEnabled":false,"persistenceEnabled":false,"marketBaseRate":5.0,"eventId":"33376062","eventTypeId":"4339","numberOfWinners":2,"bettingType":"ODDS","marketType":"PLACE","marketTime":"2024-06-27T13:54:00.000Z","suspendTime":"2024-06-27T13:54:00.000Z","bspReconciled":false,"complete":true,"inPlay":false,"crossMatching":false,"runnersVoidable":false,"numberOfActiveRunners":6,"betDelay":0,"status":"OPEN","runners":[{"status":"ACTIVE","sortPriority":1,"id":39362025,"name":"1. Errill Merry"},{"status":"ACTIVE","sortPriority":2,"id":70218235,"name":"2. Boozed Jill"},{"status":"ACTIVE","sortPriority":3,"id":44798446,"name":"3. Fearmore Diva"},{"status":"ACTIVE","sortPriority":4,"id":48500723,"name":"4. Magical Legend"},{"status":"ACTIVE","sortPriority":5,"id":40953876,"name":"5. Coonough Chimes"},{"status":"ACTIVE","sortPriority":6,"id":55829870,"name":"6. Grumpy Cookie"}],"regulators":["MR_INT"],"venue":"Kinsley","countryCode":"GB","discountAllowed":true,"timezone":"Europe/London","openDate":"2024-06-27T13:36:00.000Z","version":5994643737,"name":"To Be Placed","eventName":"Kinsley 27th Jun"},"rc":[{"atb":[[1.03,15.1]],"id":40953876},{"atl":[[990,0.26]],"id":40953876},{"spn":495.51,"spf":"NaN","id":40953876},{"atb":[[1.01,45.3]],"id":39362025},{"atl":[[1000,0.26]],"id":39362025},{"spn":500.5,"spf":"NaN","id":39362025},{"atb":[[1.02,22.65]],"id":48500723},{"atl":[[1000,0.26]],"id":48500723},{"spn":500.51,"spf":"NaN","id":48500723},{"atb":[[1.01,45.3]],"id":44798446},{"atl":[[1000,0.26]],"id":44798446},{"spn":500.5,"spf":"NaN","id":44798446},{"atb":[[1.01,45.3]],"id":70218235},{"atl":[[990,0.26]],"id":70218235},{"spn":495.5,"spf":"NaN","id":70218235},{"atb":[[1.02,22.65]],"id":55829870},{"atl":[[1000,0.26]],"id":55829870},{"spn":500.51,"spf":"NaN","id":55829870}],"con":true,"img":true}]}
{"op":"mcm","clk":"11538595358","pt":1719464882536,"mc":[{"id":"1.230178309","marketDefinition":{"bspMarket":true,"turnInPlayEnabled":false,"persistenceEnabled":false,"marketBaseRate":5.0,"eventId":"33376062","eventTypeId":"4339","numberOfWinners":2,"bettingType":"ODDS","marketType":"PLACE","marketTime":"2024-06-27T13:54:00.000Z","suspendTime":"2024-06-27T13:54:00.000Z","bspReconciled":false,"complete":true,"inPlay":false,"crossMatching":false,"runnersVoidable":false,"numberOfActiveRunners":6,"betDelay":0,"status":"OPEN","runners":[{"status":"ACTIVE","sortPriority":1,"id":39362025,"name":"1. Errill Merry"},{"status":"ACTIVE","sortPriority":2,"id":70218235,"name":"2. Boozed Jill"},{"status":"ACTIVE","sortPriority":3,"id":44798446,"name":"3. Fearmore Diva"},{"status":"ACTIVE","sortPriority":4,"id":48500723,"name":"4. Magical Legend"},{"status":"ACTIVE","sortPriority":5,"id":40953876,"name":"5. Coonough Chimes"},{"status":"ACTIVE","sortPriority":6,"id":55829870,"name":"6. Grumpy Cookie"}],"regulators":["MR_INT"],"venue":"Kinsley","countryCode":"GB","discountAllowed":true,"timezone":"Europe/London","openDate":"2024-06-27T13:36:00.000Z","version":5994643737,"name":"To Be Placed","eventName":"Kinsley 27th Jun"},"rc":[{"atb":[[1.03,15.09]],"id":40953876},{"atl":[[990,0.26]],"id":40953876},{"spn":495.51,"spf":"NaN","id":40953876},{"atb":[[1.01,45.29]],"id":39362025},{"atl":[[1000,0.26]],"id":39362025},{"spn":500.5,"spf":"NaN","id":39362025},{"atb":[[1.02,22.64]],"id":48500723},{"atl":[[1000,0.26]],"id":48500723},{"spn":500.51,"spf":"NaN","id":48500723},{"atb":[[1.01,45.29]],"id":44798446},{"atl":[[1000,0.26]],"id":44798446},{"spn":500.5,"spf":"NaN","id":44798446},{"atb":[[1.01,45.29]],"id":70218235},{"atl":[[990,0.26]],"id":70218235},{"spn":495.5,"spf":"NaN","id":70218235},{"atb":[[1.02,22.64]],"id":55829870},{"atl":[[1000,0.26]],"id":55829870},{"spn":500.51,"spf":"NaN","id":55829870}],"con":true,"img":true}]}
{"op":"mcm","clk":"11538905700","pt":1719471477931,"mc":[{"id":"1.230178309","rc":[{"atb":[[1.03,15.09]],"id":40953876},{"atl":[[990,0.16]],"id":40953876},{"atb":[[1.01,45.29]],"id":39362025},{"atl":[[1000,0.16]],"id":39362025},{"atb":[[1.02,22.64]],"id":48500723},{"atl":[[1000,0.16]],"id":48500723},{"atb":[[1.01,45.29]],"id":44798446},{"atl":[[1000,0.16]],"id":44798446},{"atb":[[1.01,45.29]],"id":70218235},{"atl":[[990,0.16]],"id":70218235},{"atb":[[1.02,22.64]],"id":55829870},{"atl":[[1000,0.16]],"id":55829870}],"con":true,"img":false}]}
{"op":"mcm","clk":"11538907381","pt":1719471509499,"mc":[{"id":"1.230178309","rc":[{"atb":[[1.07,2.48]],"id":40953876},{"atl":[[1000,1]],"id":40953876},{"atb":[[1.07,2.48]],"id":39362025},{"atl":[[1000,1.16]],"id":39362025},{"atb":[[1.07,2.48]],"id":48500723},{"atl":[[1000,1.16]],"id":48500723},{"atb":[[1.07,2.48]],"id":44798446},{"atl":[[1000,1.16]],"id":44798446},{"atb":[[1.07,2.48]],"id":70218235},{"atl":[[1000,1]],"id":70218235},{"atb":[[1.07,2.48]],"id":55829870},{"atl":[[1000,1.16]],"id":55829870}],"con":true,"img":false}]}
{"op":"mcm","clk":"11538907392","pt":1719471509653,"mc":[{"id":"1.230178309","rc":[{"atl":[[1000,0.48]],"id":40953876},{"atl":[[1000,0.64]],"id":39362025},{"atl":[[1000,0.64]],"id":48500723},{"atl":[[1000,0.64]],"id":44798446},{"atl":[[1000,0.48]],"id":70218235},{"atl":[[1000,0.64]],"id":55829870}],"con":true,"img":false}]}
{"op":"mcm","clk":"11538907411","pt":1719471509862,"mc":[{"id":"1.230178309","rc":[{"atl":[[1000,0]],"id":40953876},{"atl":[[1000,0.16]],"id":39362025},{"atl":[[1000,0.16]],"id":48500723},{"atl":[[1000,0.16]],"id":44798446},{"atl":[[1000,0]],"id":70218235},{"atl":[[1000,0.16]],"id":55829870}],"con":true,"img":false}]}
{"op":"mcm","clk":"11538907418","pt":1719471509965,"mc":[{"id":"1.230178309","rc":[{"atl":[[75,0.48]],"id":40953876},{"atl":[[75,0.48]],"id":39362025},{"atl":[[75,0.48]],"id":48500723},{"atl":[[75,0.48]],"id":44798446},{"atl":[[75,0.48]],"id":70218235},{"atl":[[75,0.48]],"id":55829870}],"con":true,"img":false}]}
{"op":"mcm","clk":"11539122505","pt":1719475682543,"mc":[{"id":"1.230178309","marketDefinition":{"bspMarket":true,"turnInPlayEnabled":false,"persistenceEnabled":false,"marketBaseRate":5.0,"eventId":"33376062","eventTypeId":"4339","numberOfWinners":2,"bettingType":"ODDS","marketType":"PLACE","marketTime":"2024-06-27T13:54:00.000Z","suspendTime":"2024-06-27T13:54:00.000Z","bspReconciled":false,"complete":true,"inPlay":false,"crossMatching":false,"runnersVoidable":false,"numberOfActiveRunners":6,"betDelay":0,"status":"OPEN","runners":[{"status":"ACTIVE","sortPriority":1,"id":39362025,"name":"1. Errill Merry"},{"status":"ACTIVE","sortPriority":2,"id":70218235,"name":"2. Boozed Jill"},{"status":"ACTIVE","sortPriority":3,"id":44798446,"name":"3. Fearmore Diva"},{"status":"ACTIVE","sortPriority":4,"id":48500723,"name":"4. Magical Legend"},{"status":"ACTIVE","sortPriority":5,"id":40953876,"name":"5. Coonough Chimes"},{"status":"ACTIVE","sortPriority":6,"id":55829870,"name":"6. Grumpy Cookie"}],"regulators":["MR_INT"],"venue":"Kinsley","countryCode":"GB","discountAllowed":true,"timezone":"Europe/London","openDate":"2024-06-27T13:36:00.000Z","version":5994643737,"name":"To Be Placed","eventName":"Kinsley 27th Jun"},"rc":[{"atb":[[1.03,15.09],[1.07,2.48]],"id":40953876},{"atl":[[75,0.48],[990,0.16]],"id":40953876},{"spn":38.03,"spf":"NaN","id":40953876},{"atb":[[1.01,45.28],[1.07,2.48]],"id":39362025},{"atl":[[75,0.48],[1000,0.16]],"id":39362025},{"spn":38.03,"spf":"NaN","id":39362025},{"atb":[[1.02,22.64],[1.07,2.48]],"id":48500723},{"atl":[[75,0.48],[1000,0.16]],"id":48500723},{"spn":38.03,"spf":"NaN","id":48500723},{"atb":[[1.01,45.28],[1.07,2.48]],"id":44798446},{"atl":[[75,0.48],[1000,0.16]],"id":44798446},{"spn":38.03,"spf":"NaN","id":44798446},{"atb":[[1.01,45.28],[1.07,2.48]],"id":70218235},{"atl":[[75,0.48],[990,0.16]],"id":70218235},{"spn":38.03,"spf":"NaN","id":70218235},{"atb":[[1.02,22.64],[1.07,2.48]],"id":55829870},{"atl":[[75,0.48],[1000,0.16]],"id":55829870},{"spn":38.03,"spf":"NaN","id":55829870}],"con":true,"img":true}]}
{"op":"mcm","clk":"11539438481","pt":1719481082544,"mc":[{"id":"1.230178309","marketDefinition":{"bspMarket":true,"turnInPlayEnabled":false,"persistenceEnabled":false,"marketBaseRate":5.0,"eventId":"33376062","eventTypeId":"4339","numberOfWinners":2,"bettingType":"ODDS","marketType":"PLACE","marketTime":"2024-06-27T13:54:00.000Z","suspendTime":"2024-06-27T13:54:00.000Z","bspReconciled":false,"complete":true,"inPlay":false,"crossMatching":false,"runnersVoidable":false,"numberOfActiveRunners":6,"betDelay":0,"status":"OPEN","runners":[{"status":"ACTIVE","sortPriority":1,"id":39362025,"name":"1. Errill Merry"},{"status":"ACTIVE","sortPriority":2,"id":70218235,"name":"2. Boozed Jill"},{"status":"ACTIVE","sortPriority":3,"id":44798446,"name":"3. Fearmore Diva"},{"status":"ACTIVE","sortPriority":4,"id":48500723,"name":"4. Magical Legend"},{"status":"ACTIVE","sortPriority":5,"id":40953876,"name":"5. Coonough Chimes"},{"status":"ACTIVE","sortPriority":6,"id":55829870,"name":"6. Grumpy Cookie"}],"regulators":["MR_INT"],"venue":"Kinsley","countryCode":"GB","discountAllowed":true,"timezone":"Europe/London","openDate":"2024-06-27T13:36:00.000Z","version":5994643737,"name":"To Be Placed","eventName":"Kinsley 27th Jun"},"rc":[{"atb":[[1.03,15.09],[1.07,2.48]],"id":40953876},{"atl":[[75,0.48],[990,0.16]],"id":40953876},{"spn":38.03,"spf":"NaN","id":40953876},{"atb":[[1.01,45.27],[1.07,2.48]],"id":39362025},{"atl":[[75,0.48],[1000,0.16]],"id":39362025},{"spn":38.03,"spf":"NaN","id":39362025},{"atb":[[1.02,22.63],[1.07,2.48]],"id":48500723},{"atl":[[75,0.48],[1000,0.16]],"id":48500723},{"spn":38.03,"spf":"NaN","id":48500723},{"atb":[[1.01,45.27],[1.07,2.48]],"id":44798446},{"atl":[[75,0.48],[1000,0.16]],"id":44798446},{"spn":38.03,"spf":"NaN","id":44798446},{"atb":[[1.01,45.27],[1.07,2.48]],"id":70218235},{"atl":[[75,0.48],[990,0.16]],"id":70218235},{"spn":38.03,"spf":"NaN","id":70218235},{"atb":[[1.02,22.63],[1.07,2.48]],"id":55829870},{"atl":[[75,0.48],[1000,0.16]],"id":55829870},{"spn":38.03,"spf":"NaN","id":55829870}],"con":true,"img":true}]}
{"op":"mcm","clk":"11539618083","pt":1719483896516,"mc":[{"id":"1.230178309","rc":[{"atb":[[1.03,15.08]],"id":40953876},{"atl":[[990,0.16]],"id":40953876},{"spn":38.03,"spf":"NaN","id":40953876},{"spl":[[1.01,1.43]],"id":39362025},{"atb":[[1.01,45.26]],"id":39362025},{"atl":[[1000,0.16]],"id":39362025},{"spn":1.07,"spf":1.0,"id":39362025},{"atb":[[1.02,22.63]],"id":48500723},{"atl":[[1000,0.16]],"id":48500723},{"spn":38.03,"spf":"NaN","id":48500723},{"atb":[[1.01,45.26]],"id":44798446},{"atl":[[1000,0.16]],"id":44798446},{"spn":38.03,"spf":"NaN","id":44798446},{"atb":[[1.01,45.26]],"id":70218235},{"atl":[[990,0.16]],"id":70218235},{"spn":38.03,"spf":"NaN","id":70218235},{"atb":[[1.02,22.63]],"id":55829870},{"atl":[[1000,0.16]],"id":55829870},{"spn":38.03,"spf":"NaN","id":55829870}],"con":true,"img":false}]}
{"op":"mcm","clk":"11539810779","pt":1719486482531,"mc":[{"id":"1.230178309","marketDefinition":{"bspMarket":true,"turnInPlayEnabled":false,"persistenceEnabled":false,"marketBaseRate":5.0,"eventId":"33376062","eventTypeId":"4339","numberOfWinners":2,"bettingType":"ODDS","marketType":"PLACE","marketTime":"2024-06-27T13:54:00.000Z","suspendTime":"2024-06-27T13:54:00.000Z","bspReconciled":false,"complete":true,"inPlay":false,"crossMatching":false,"runnersVoidable":false,"numberOfActiveRunners":6,"betDelay":0,"status":"OPEN","runners":[{"status":"ACTIVE","sortPriority":1,"id":39362025,"name":"1. Errill Merry"},{"status":"ACTIVE","sortPriority":2,"id":70218235,"name":"2. Boozed Jill"},{"status":"ACTIVE","sortPriority":3,"id":44798446,"name":"3. Fearmore Diva"},{"status":"ACTIVE","sortPriority":4,"id":48500723,"name":"4. Magical Legend"},{"status":"ACTIVE","sortPriority":5,"id":40953876,"name":"5. Coonough Chimes"},{"status":"ACTIVE","sortPriority":6,"id":55829870,"name":"6. Grumpy Cookie"}],"regulators":["MR_INT"],"venue":"Kinsley","countryCode":"GB","discountAllowed":true,"timezone":"Europe/London","openDate":"2024-06-27T13:36:00.000Z","version":5994643737,"name":"To Be Placed","eventName":"Kinsley 27th Jun"},"rc":[{"atb":[[1.03,15.09],[1.07,2.48]],"id":40953876},{"atl":[[75,0.48],[990,0.16]],"id":40953876},{"spn":38.03,"spf":"NaN","id":40953876},{"spl":[[1.01,1.43]],"id":39362025},{"atb":[[1.01,45.27],[1.07,2.48]],"id":39362025},{"atl":[[75,0.48],[1000,0.16]],"id":39362025},{"spn":1.07,"spf":1.0,"id":39362025},{"atb":[[1.02,22.63],[1.07,2.48]],"id":48500723},{"atl":[[75,0.48],[1000,0.16]],"id":48500723},{"spn":38.03,"spf":"NaN","id":48500723},{"atb":[[1.01,45.27],[1.07,2.48]],"id":44798446},{"atl":[[75,0.48],[1000,0.16]],"id":44798446},{"spn":38.03,"spf":"NaN","id":44798446},{"atb":[[1.01,45.27],[1.07,2.48]],"id":70218235},{"atl":[[75,0.48],[990,0.16]],"id":70218235},{"spn":38.03,"spf":"NaN","id":70218235},{"atb":[[1.02,22.63],[1.07,2.48]],"id":55829870},{"atl":[[75,0.48],[1000,0.16]],"id":55829870},{"spn":38.03,"spf":"NaN","id":55829870}],"con":true,"img":true}]}
{"op":"mcm","clk":"11540042694","pt":1719489341251,"mc":[{"id":"1.230178309","rc":[{"atb":[[1.03,15.09]],"id":40953876},{"atl":[[970,0.87]],"id":40953876},{"spl":[[1.01,1.43]],"id":39362025},{"atb":[[1.01,45.27]],"id":39362025},{"atl":[[970,1.86]],"id":39362025},{"atb":[[1.02,22.63]],"id":48500723},{"atl":[[990,1.53]],"id":48500723},{"atb":[[1.01,45.27]],"id":44798446},{"atl":[[960,0.87]],"id":44798446},{"atb":[[1.01,45.27]],"id":70218235},{"atl":[[960,0.9]],"id":70218235},{"atb":[[1.02,22.63]],"id":55829870},{"atl":[[990,1.21]],"id":55829870}],"con":true,"img":false}]}
{"op":"mcm","clk":"11540247700","pt":1719491882542,"mc":[{"id":"1.230178309","marketDefinition":{"bspMarket":true,"turnInPlayEnabled":false,"persistenceEnabled":false,"marketBaseRate":5.0,"eventId":"33376062","eventTypeId":"4339","numberOfWinners":2,"bettingType":"ODDS","marketType":"PLACE","marketTime":"2024-06-27T13:54:00.000Z","suspendTime":"2024-06-27T13:54:00.000Z","bspReconciled":false,"complete":true,"inPlay":false,"crossMatching":false,"runnersVoidable":false,"numberOfActiveRunners":6,"betDelay":0,"status":"OPEN","runners":[{"status":"ACTIVE","sortPriority":1,"id":39362025,"name":"1. Errill Merry"},{"status":"ACTIVE","sortPriority":2,"id":70218235,"name":"2. Boozed Jill"},{"status":"ACTIVE","sortPriority":3,"id":44798446,"name":"3. Fearmore Diva"},{"status":"ACTIVE","sortPriority":4,"id":48500723,"name":"4. Magical Legend"},{"status":"ACTIVE","sortPriority":5,"id":40953876,"name":"5. Coonough Chimes"},{"status":"ACTIVE","sortPriority":6,"id":55829870,"name":"6. Grumpy Cookie"}],"regulators":["MR_INT"],"venue":"Kinsley","countryCode":"GB","discountAllowed":true,"timezone":"Europe/London","openDate":"2024-06-27T13:36:00.000Z","version":5994643737,"name":"To Be Placed","eventName":"Kinsley 27th Jun"},"rc":[{"atb":[[1.03,15.09],[1.07,2.48]],"id":40953876},{"atl":[[75,0.48],[970,0.87],[990,0.16]],"id":40953876},{"spn":38.03,"spf":"NaN","id":40953876},{"spl":[[1.01,1.43]],"id":39362025},{"atb":[[1.01,45.27],[1.07,2.48]],"id":39362025},{"atl":[[75,0.48],[970,1.86],[1000,0.16]],"id":39362025},{"spn":1.07,"spf":1.0,"id":39362025},{"atb":[[1.02,22.63],[1.07,2.48]],"id":48500723},{"atl":[[75,0.48],[990,1.53],[1000,0.16]],"id":48500723},{"spn":38.03,"spf":"NaN","id":48500723},{"atb":[[1.01,45.27],[1.07,2.48]],"id":44798446},{"atl":[[75,0.48],[960,0.87],[1000,0.16]],"id":44798446},{"spn":38.03,"spf":"NaN","id":44798446},{"atb":[[1.01,45.27],[1.07,2.48]],"id":70218235},{"atl":[[75,0.48],[960,0.9],[990,0.16]],"id":70218235},{"spn":38.03,"spf":"NaN","id":70218235},{"atb":[[1.02,22.63],[1.07,2.48]],"id":55829870},{"atl":[[75,0.48],[990,1.21],[1000,0.16]],"id":55829870},{"spn":38.03,"spf":"NaN","id":55829870}],"con":true,"img":true}]}
{"op":"mcm","clk":"11540423341","pt":1719494343466,"mc":[{"id":"1.230178309","rc":[{"atb":[[1.03,15.1],[1.04,1]],"id":40953876},{"atl":[[970,0.87],[990,0.16]],"id":40953876},{"spl":[[1.01,1.43]],"id":39362025},{"atb":[[1.01,45.32],[1.04,1]],"id":39362025},{"atl":[[970,1.87],[1000,0.16]],"id":39362025},{"atb":[[1.02,22.66],[1.04,1]],"id":48500723},{"atl":[[990,1.54],[1000,0.16]],"id":48500723},{"atb":[[1.01,45.32],[1.04,1]],"id":44798446},{"atl":[[960,0.87],[1000,0.16]],"id":44798446},{"atb":[[1.01,45.32],[1.04,1]],"id":70218235},{"atl":[[960,0.9],[990,0.16]],"id":70218235},{"atb":[[1.02,22.66],[1.04,1]],"id":55829870},{"atl":[[990,1.21],[1000,0.16]],"id":55829870}],"con":true,"img":false}]}
{"op":"mcm","clk":"11540423361","pt":1719494343671,"mc":[{"id":"1.230178309","rc":[{"atb":[[1.04,0.25]],"id":40953876},{"atb":[[1.04,0.25]],"id":39362025},{"atb":[[1.04,0.25]],"id":48500723},{"atb":[[1.04,0.25]],"id":44798446},{"atb":[[1.04,0.25]],"id":70218235},{"atb":[[1.04,0.25]],"id":55829870}],"con":true,"img":false}]}
{"op":"mcm","clk":"11540423385","pt":1719494343880,"mc":[{"id":"1.230178309","rc":[{"atb":[[1.04,0]],"id":40953876},{"atb":[[1.04,0]],"id":39362025},{"atb":[[1.04,0]],"id":48500723},{"atb":[[1.04,0]],"id":44798446},{"atb":[[1.04,0]],"id":70218235},{"atb":[[1.04,0]],"id":55829870}],"con":true,"img":false}]}
{"op":"mcm","clk":"11540423396","pt":1719494344009,"mc":[{"id":"1.230178309","rc":[{"atb":[[1.2,0.25]],"id":40953876},{"atb":[[1.2,0.25]],"id":39362025},{"atb":[[1.2,0.25]],"id":48500723},{"atb":[[1.2,0.25]],"id":44798446},{"atb":[[1.2,0.25]],"id":70218235},{"atb":[[1.2,0.25]],"id":55829870}],"con":true,"img":false}]}
{"op":"mcm","clk":"11540471087","pt":1719494891488,"mc":[{"id":"1.230178309","rc":[{"spn":38.1,"spf":"NaN","id":40953876},{"spn":1.09,"spf":1.0,"id":39362025},{"spn":38.1,"spf":"NaN","id":48500723},{"atb":[[1.09,47.05]],"id":44798446},{"spn":38.1,"spf":"NaN","id":44798446},{"spn":38.1,"spf":"NaN","id":70218235},{"spn":38.1,"spf":"NaN","id":55829870}],"con":true,"img":false}]}
{"op":"mcm","clk":"11540471098","pt":1719494891688,"mc":[{"id":"1.230178309","rc":[{"atb":[[1.09,47.05]],"id":48500723}],"con":true,"img":false}]}
{"op":"mcm","clk":"11540471133","pt":1719494892206,"mc":[{"id":"1.230178309","rc":[{"atb":[[1.09,47.05]],"id":40953876}],"con":true,"img":false}]}
{"op":"mcm","clk":"11540471143","pt":1719494892313,"mc":[{"id":"1.230178309","rc":[{"atb":[[1.09,47.05]],"id":55829870}],"con":true,"img":false}]}
{"op":"mcm","clk":"11540473704","pt":1719494922490,"mc":[{"id":"1.230178309","marketDefinition":{"bspMarket":true,"turnInPlayEnabled":false,"persistenceEnabled":false,"marketBaseRate":5.0,"eventId":"33376062","eventTypeId":"4339","numberOfWinners":2,"bettingType":"ODDS","marketType":"PLACE","marketTime":"2024-06-27T13:54:00.000Z","suspendTime":"2024-06-27T13:54:00.000Z","bspReconciled":false,"complete":true,"inPlay":false,"crossMatching":true,"runnersVoidable":false,"numberOfActiveRunners":6,"betDelay":0,"status":"OPEN","runners":[{"status":"ACTIVE","sortPriority":1,"id":39362025,"name":"1. Errill Merry"},{"status":"ACTIVE","sortPriority":2,"id":70218235,"name":"2. Boozed Jill"},{"status":"ACTIVE","sortPriority":3,"id":44798446,"name":"3. Fearmore Diva"},{"status":"ACTIVE","sortPriority":4,"id":48500723,"name":"4. Magical Legend"},{"status":"ACTIVE","sortPriority":5,"id":40953876,"name":"5. Coonough Chimes"},{"status":"ACTIVE","sortPriority":6,"id":55829870,"name":"6. Grumpy Cookie"}],"regulators":["MR_INT"],"venue":"Kinsley","countryCode":"GB","discountAllowed":true,"timezone":"Europe/London","openDate":"2024-06-27T13:36:00.000Z","version":5994643737,"name":"To Be Placed","eventName":"Kinsley 27th Jun"},"rc":[],"con":true,"img":false}]}
{"op":"mcm","clk":"11540478182","pt":1719494976309,"mc":[{"id":"1.230178309","rc":[{"atb":[[1.11,35.9]],"id":44798446}],"con":true,"img":false}]}
{"op":"mcm","clk":"11540478193","pt":1719494976411,"mc":[{"id":"1.230178309","rc":[{"atb":[[1.11,35.9]],"id":40953876}],"con":true,"img":false}]}
{"op":"mcm","clk":"11540478202","pt":1719494976480,"mc":[{"id":"1.230178309","rc":[{"atb":[[1.11,35.9]],"id":48500723}],"con":true,"img":false}]}
{"op":"mcm","clk":"11540478236","pt":1719494976893,"mc":[{"id":"1.230178309","rc":[{"atb":[[1.11,35.9]],"id":55829870}],"con":true,"img":false}]}
{"op":"mcm","clk":"11540478582","pt":1719494981399,"mc":[{"id":"1.230178309","rc":[{"atb":[[1.09,0]],"id":48500723},{"atb":[[1.09,0]],"id":44798446}],"con":true,"img":false}]}
{"op":"mcm","clk":"11540478613","pt":1719494981819,"mc":[{"id":"1.230178309","rc":[{"atb":[[1.09,0]],"id":40953876},{"atb":[[1.09,0]],"id":55829870}],"con":true,"img":false}]}
{"op":"mcm","clk":"11540478670","pt":1719494982507,"mc":[{"id":"1.230178309","rc":[{"atb":[[1.13,32.57]],"id":48500723}],"con":true,"img":false}]}
{"op":"mcm","clk":"11540478693","pt":1719494982806,"mc":[{"id":"1.230178309","rc":[{"atb":[[1.13,32.57]],"id":44798446}],"con":true,"img":false}]}
{"op":"mcm","clk":"11540478711","pt":1719494983015,"mc":[{"id":"1.230178309","rc":[{"atb":[[1.13,32.57]],"id":55829870}],"con":true,"img":false}]}
{"op":"mcm","clk":"11540478722","pt":1719494983118,"mc":[{"id":"1.230178309","rc":[{"atb":[[1.13,32.57]],"id":40953876}],"con":true,"img":false}]}
{"op":"mcm","clk":"11540479927","pt":1719494996307,"mc":[{"id":"1.230178309","rc":[{"atb":[[1.11,0]],"id":40953876},{"atb":[[1.11,0]],"id":44798446}],"con":true,"img":false}]}
{"op":"mcm","clk":"11540479950","pt":1719494996509,"mc":[{"id":"1.230178309","rc":[{"atb":[[1.11,0]],"id":48500723}],"con":true,"img":false}]}
{"op":"mcm","clk":"11540479989","pt":1719494997025,"mc":[{"id":"1.230178309","rc":[{"atb":[[1.15,26.33]],"id":44798446}],"con":true,"img":false}]}
{"op":"mcm","clk":"11540480005","pt":1719494997220,"mc":[{"id":"1.230178309","rc":[{"atb":[[1.15,26.33]],"id":48500723}],"con":true,"img":false}]}
{"op":"mcm","clk":"11540480027","pt":1719494997427,"mc":[{"id":"1.230178309","rc":[{"atb":[[1.15,26.33]],"id":40953876}],"con":true,"img":false}]}
{"op":"mcm","clk":"11540480045","pt":1719494997597,"mc":[{"id":"1.230178309","rc":[{"atb":[[1.11,0]],"id":55829870}],"con":true,"img":false}]}
{"op":"mcm","clk":"11540480095","pt":1719494998220,"mc":[{"id":"1.230178309","rc":[{"atb":[[1.15,26.33]],"id":55829870}],"con":true,"img":false}]}
{"op":"mcm","clk":"11540482006","pt":1719495020858,"mc":[{"id":"1.230178309","rc":[{"atb":[[1.15,0]],"id":55829870}],"con":true,"img":false}]}
{"op":"mcm","clk":"11540482237","pt":1719495023960,"mc":[{"id":"1.230178309","rc":[{"atb":[[1.13,0]],"id":55829870}],"con":true,"img":false}]}
{"op":"mcm","clk":"11540482427","pt":1719495026600,"mc":[{"id":"1.230178309","rc":[{"atb":[[1.13,0]],"id":44798446}],"con":true,"img":false}]}
{"op":"mcm","clk":"11540482444","pt":1719495026769,"mc":[{"id":"1.230178309","rc":[{"atb":[[1.13,0]],"id":48500723}],"con":true,"img":false}]}
{"op":"mcm","clk":"11540482467","pt":1719495027067,"mc":[{"id":"1.230178309","rc":[{"atb":[[1.13,0]],"id":40953876}],"con":true,"img":false}]}
{"op":"mcm","clk":"11540482563","pt":1719495028168,"mc":[{"id":"1.230178309","rc":[{"atb":[[1.17,24.9]],"id":44798446}],"con":true,"img":false}]}
{"op":"mcm","clk":"11540482583","pt":1719495028374,"mc":[{"id":"1.230178309","rc":[{"atb":[[1.17,24.9]],"id":40953876}],"con":true,"img":false}]}
{"op":"mcm","clk":"11540482593","pt":1719495028471,"mc":[{"id":"1.230178309","rc":[{"atb":[[1.17,24.9]],"id":48500723}],"con":true,"img":false}]}
{"op":"mcm","clk":"11540483773","pt":1719495042288,"mc":[{"id":"1.230178309","rc":[{"atb":[[1.15,0]],"id":40953876},{"atb":[[1.15,0]],"id":48500723}],"con":true,"img":false}]}
{"op":"mcm","clk":"11540483791","pt":1719495042582,"mc":[{"id":"1.230178309","rc":[{"atb":[[1.15,0]],"id":44798446}],"con":true,"img":false}]}
{"op":"mcm","clk":"11540483817","pt":1719495042895,"mc":[{"id":"1.230178309","rc":[{"atb":[[1.19,20.79]],"id":40953876},{"atb":[[1.19,20.79]],"id":48500723}],"con":true,"img":false}]}
{"op":"mcm","clk":"11540483829","pt":1719495043102,"mc":[{"id":"1.230178309","rc":[{"atb":[[1.19,20.79]],"id":44798446}],"con":true,"img":false}]}
{"op":"mcm","clk":"11540486972","pt":1719495076660,"mc":[{"id":"1.230178309","rc":[{"atb":[[1.17,0]],"id":44798446}],"con":true,"img":false}]}
{"op":"mcm","clk":"11540486980","pt":1719495076728,"mc":[{"id":"1.230178309","rc":[{"atb":[[1.09,47.05]],"id":55829870}],"con":true,"img":false}]}
{"op":"mcm","clk":"11540487042","pt":1719495077339,"mc":[{"id":"1.230178309","rc":[{"atb":[[1.21,20.16]],"id":44798446}],"con":true,"img":false}]}
{"op":"mcm","clk":"11540487050","pt":1719495077443,"mc":[{"id":"1.230178309","rc":[{"atb":[[1.17,0]],"id":48500723}],"con":true,"img":false}]}
{"op":"mcm","clk":"11540487070","pt":1719495077649,"mc":[{"id":"1.230178309","rc":[{"atb":[[1.17,0]],"id":40953876}],"con":true,"img":false}]}
{"op":"mcm","clk":"11540487116","pt":1719495078262,"mc":[{"id":"1.230178309","rc":[{"atb":[[1.21,20.16]],"id":48500723}],"con":true,"img":false}]}
{"op":"mcm","clk":"11540487137","pt":1719495078532,"mc":[{"id":"1.230178309","rc":[{"atb":[[1.21,20.16]],"id":40953876}],"con":true,"img":false}]}
{"op":"mcm","clk":"11540487550","pt":1719495083893,"mc":[{"id":"1.230178309","rc":[{"atb":[[1.1,55.3]],"id":55829870}],"con":true,"img":false}]}
{"op":"mcm","clk":"11540487568","pt":1719495084061,"mc":[{"id":"1.230178309","rc":[{"atb":[[1.19,0]],"id":40953876}],"con":true,"img":false}]}
{"op":"mcm","clk":"11540487587","pt":1719495084228,"mc":[{"id":"1.230178309","rc":[{"atb":[[1.19,0]],"id":48500723}],"con":true,"img":false}]}
{"op":"mcm","clk":"11540487608","pt":1719495084434,"mc":[{"id":"1.230178309","rc":[{"atb":[[1.23,17.17]],"id":40953876}],"con":true,"img":false}]}
{"op":"mcm","clk":"11540487630","pt":1719495084643,"mc":[{"id":"1.230178309","rc":[{"atb":[[1.11,35.9]],"id":55829870}],"con":true,"img":false}]}
{"op":"mcm","clk":"11540487650","pt":1719495084853,"mc":[{"id":"1.230178309","rc":[{"atb":[[1.19,0]],"id":44798446}],"con":true,"img":false}]}
{"op":"mcm","clk":"11540487669","pt":1719495085052,"mc":[{"id":"1.230178309","rc":[{"atb":[[1.23,17.17]],"id":48500723},{"atb":[[1.23,17.17]],"id":44798446}],"con":true,"img":false}]}
{"op":"mcm","clk":"11540489383","pt":1719495103866,"mc":[{"id":"1.230178309","rc":[{"spn":38.11,"spf":"NaN","id":40953876},{"spn":38.11,"spf":"NaN","id":48500723},{"spn":38.11,"spf":"NaN","id":44798446},{"atb":[[1.1,0]],"id":55829870}],"con":true,"img":false}]}
{"op":"mcm","clk":"11540489398","pt":1719495104070,"mc":[{"id":"1.230178309","rc":[{"atb":[[1.11,0]],"id":55829870}],"con":true,"img":false}]}
{"op":"mcm","clk":"11540490482","pt":1719495115577,"mc":[{"id":"1.230178309","rc":[{"atb":[[1.09,0]],"id":55829870}],"con":true,"img":false}]}
{"op":"mcm","clk":"11540490637","pt":1719495117171,"mc":[{"id":"1.230178309","rc":[{"atb":[[1.21,0]],"id":40953876},{"atb":[[1.21,0]],"id":44798446}],"con":true,"img":false}]}
{"op":"mcm","clk":"11540490664","pt":1719495117584,"mc":[{"id":"1.230178309","rc":[{"atb":[[1.21,0]],"id":48500723}],"con":true,"img":false}]}
{"op":"mcm","clk":"11540490696","pt":1719495117898,"mc":[{"id":"1.230178309","rc":[{"atb":[[1.25,16.93]],"id":40953876}],"con":true,"img":false}]}
{"op":"mcm","clk":"11540490724","pt":1719495118151,"mc":[{"id":"1.230178309","rc":[{"atb":[[1.25,16.93]],"id":44798446}],"con":true,"img":false}]}
{"op":"mcm","clk":"11540490752","pt":1719495118360,"mc":[{"id":"1.230178309","rc":[{"atb":[[1.09,47.05]],"id":55829870}],"con":true,"img":false}]}
{"op":"mcm","clk":"11540490760","pt":1719495118463,"mc":[{"id":"1.230178309","rc":[{"atb":[[1.25,16.93]],"id":48500723}],"con":true,"img":false}]}
{"op":"mcm","clk":"11540491366","pt":1719495124477,"mc":[{"id":"1.230178309","rc":[{"atb":[[1.23,0]],"id":48500723},{"atb":[[1.23,0]],"id":44798446}],"con":true,"img":false}]}
{"op":"mcm","clk":"11540491385","pt":1719495124676,"mc":[{"id":"1.230178309","rc":[{"atb":[[1.11,35.9]],"id":55829870}],"con":true,"img":false}]}
{"op":"mcm","clk":"11540491395","pt":1719495124779,"mc":[{"id":"1.230178309","rc":[{"atb":[[1.23,0]],"id":40953876}],"con":true,"img":false}]}
{"op":"mcm","clk":"11540491442","pt":1719495125295,"mc":[{"id":"1.230178309","rc":[{"atb":[[1.27,14.63]],"id":48500723}],"con":true,"img":false}]}
{"op":"mcm","clk":"11540491460","pt":1719495125502,"mc":[{"id":"1.230178309","rc":[{"atb":[[1.27,14.63]],"id":40953876}],"con":true,"img":false}]}
{"op":"mcm","clk":"11540491477","pt":1719495125661,"mc":[{"id":"1.230178309","rc":[{"atb":[[1.27,14.63]],"id":44798446}],"con":true,"img":false}]}
{"op":"mcm","clk":"11540494194","pt":1719495154031,"mc":[{"id":"1.230178309","rc":[{"atb":[[1.25,0]],"id":40953876}],"con":true,"img":false}]}
{"op":"mcm","clk":"11540494209","pt":1719495154187,"mc":[{"id":"1.230178309","rc":[{"atb":[[1.09,0]],"id":55829870}],"con":true,"img":false}]}
{"op":"mcm","clk":"11540494230","pt":1719495154393,"mc":[{"id":"1.230178309","rc":[{"atb":[[1.25,0]],"id":44798446}],"con":true,"img":false}]}
{"op":"mcm","clk":"11540494241","pt":1719495154498,"mc":[{"id":"1.230178309","rc":[{"atb":[[1.29,14.6]],"id":40953876}],"con":true,"img":false}]}
{"op":"mcm","clk":"11540494277","pt":1719495154810,"mc":[{"id":"1.230178309","rc":[{"atb":[[1.13,32.57]],"id":55829870}],"con":true,"img":false}]}
{"op":"mcm","clk":"11540494286","pt":1719495154912,"mc":[{"id":"1.230178309","rc":[{"atb":[[1.29,14.6]],"id":44798446}],"con":true,"img":false}]}
{"op":"mcm","clk":"11540494323","pt":1719495155327,"mc":[{"id":"1.230178309","rc":[{"atb":[[1.25,0]],"id":48500723}],"con":true,"img":false}]}
{"op":"mcm","clk":"11540494367","pt":1719495155796,"mc":[{"id":"1.230178309","rc":[{"atb":[[1.29,14.6]],"id":48500723}],"con":true,"img":false}]}
{"op":"mcm","clk":"11540494472","pt":1719495157236,"mc":[{"id":"1.230178309","rc":[{"atb":[[1.18,2.52]],"id":48500723}],"con":true,"img":false}]}
{"op":"mcm","clk":"11540494647","pt":1719495159199,"mc":[{"id":"1.230178309","rc":[{"atb":[[1.18,0]],"id":48500723}],"con":true,"img":false}]}
{"op":"mcm","clk":"11540494899","pt":1719495161642,"mc":[{"id":"1.230178309","rc":[{"atb":[[1.27,0]],"id":48500723},{"atb":[[1.27,0]],"id":44798446}],"con":true,"img":false}]}
{"op":"mcm","clk":"11540494916","pt":1719495161800,"mc":[{"id":"1.230178309","rc":[{"atb":[[1.31,12.74]],"id":48500723},{"atb":[[1.11,0]],"id":55829870}],"con":true,"img":false}]}
{"op":"mcm","clk":"11540494953","pt":1719495162212,"mc":[{"id":"1.230178309","rc":[{"atb":[[1.27,0]],"id":40953876}],"con":true,"img":false}]}
{"op":"mcm","clk":"11540494961","pt":1719495162316,"mc":[{"id":"1.230178309","rc":[{"atb":[[1.31,12.74]],"id":44798446}],"con":true,"img":false}]}
{"op":"mcm","clk":"11540494980","pt":1719495162523,"mc":[{"id":"1.230178309","rc":[{"atb":[[1.15,26.33]],"id":55829870}],"con":true,"img":false}]}
{"op":"mcm","clk":"11540495007","pt":1719495162835,"mc":[{"id":"1.230178309","rc":[{"atb":[[1.31,12.74]],"id":40953876}],"con":true,"img":false}]}
{"op":"mcm","clk":"11540498233","pt":1719495196242,"mc":[{"id":"1.230178309","rc":[{"spn":38.15,"spf":"NaN","id":40953876},{"atb":[[1.29,0]],"id":48500723},{"spn":38.15,"spf":"NaN","id":48500723},{"atb":[[1.29,0]],"id":44798446},{"spn":38.15,"spf":"NaN","id":44798446}],"con":true,"img":false}]}
{"op":"mcm","clk":"11540498265","pt":1719495196655,"mc":[{"id":"1.230178309","rc":[{"atb":[[1.29,0]],"id":40953876},{"atb":[[1.13,0]],"id":55829870}],"con":true,"img":false}]}
{"op":"mcm","clk":"11540498330","pt":1719495197583,"mc":[{"id":"1.230178309","rc":[{"atb":[[1.17,24.9]],"id":55829870}],"con":true,"img":false}]}
{"op":"mcm","clk":"11540498358","pt":1719495197889,"mc":[{"id":"1.230178309","rc":[{"atb":[[1.33,12.83]],"id":40953876},{"atb":[[1.33,12.83]],"id":44798446}],"con":true,"img":false}]}
{"op":"mcm","clk":"11540498387","pt":1719495198153,"mc":[{"id":"1.230178309","rc":[{"atb":[[1.33,12.83]],"id":48500723}],"con":true,"img":false}]}
{"op":"mcm","clk":"11540498739","pt":1719495202082,"mc":[{"id":"1.230178309","rc":[{"atb":[[1.31,0]],"id":48500723},{"atb":[[1.31,0]],"id":44798446}],"con":true,"img":false}]}
{"op":"mcm","clk":"11540498759","pt":1719495202289,"mc":[{"id":"1.230178309","rc":[{"atb":[[1.31,0]],"id":40953876}],"con":true,"img":false}]}
{"op":"mcm","clk":"11540498785","pt":1719495202445,"mc":[{"id":"1.230178309","rc":[{"atb":[[1.15,0]],"id":55829870}],"con":true,"img":false}]}
{"op":"mcm","clk":"11540498801","pt":1719495202654,"mc":[{"id":"1.230178309","rc":[{"atb":[[1.35,11.29]],"id":48500723},{"atb":[[1.35,11.29]],"id":44798446}],"con":true,"img":false}]}
{"op":"mcm","clk":"11540498814","pt":1719495202858,"mc":[{"id":"1.230178309","rc":[{"atb":[[1.35,11.29]],"id":40953876}],"con":true,"img":false}]}
{"op":"mcm","clk":"11540498830","pt":1719495203067,"mc":[{"id":"1.230178309","rc":[{"atb":[[1.19,20.79]],"id":55829870}],"con":true,"img":false}]}
{"op":"mcm","clk":"11540501578","pt":1719495235990,"mc":[{"id":"1.230178309","rc":[{"atb":[[1.33,0]],"id":40953876}],"con":true,"img":false}]}
{"op":"mcm","clk":"11540501600","pt":1719495236303,"mc":[{"id":"1.230178309","rc":[{"atb":[[1.17,0]],"id":55829870}],"con":true,"img":false}]}
{"op":"mcm","clk":"11540501607","pt":1719495236405,"mc":[{"id":"1.230178309","rc":[{"atb":[[1.33,0]],"id":44798446}],"con":true,"img":false}]}
{"op":"mcm","clk":"11540501634","pt":1719495236717,"mc":[{"id":"1.230178309","rc":[{"atb":[[1.33,0]],"id":48500723}],"con":true,"img":false}]}
{"op":"mcm","clk":"11540501684","pt":1719495237331,"mc":[{"id":"1.230178309","rc":[{"atb":[[1.37,11.44]],"id":40953876}],"con":true,"img":false}]}
{"op":"mcm","clk":"11540501707","pt":1719495237593,"mc":[{"id":"1.230178309","rc":[{"atb":[[1.37,11.44]],"id":44798446}],"con":true,"img":false}]}
{"op":"mcm","clk":"11540501714","pt":1719495237696,"mc":[{"id":"1.230178309","rc":[{"atb":[[1.21,20.16]],"id":55829870}],"con":true,"img":false}]}
{"op":"mcm","clk":"11540501734","pt":1719495238006,"mc":[{"id":"1.230178309","rc":[{"atb":[[1.37,11.44]],"id":48500723}],"con":true,"img":false}]}
{"op":"mcm","clk":"11540501999","pt":1719495241829,"mc":[{"id":"1.230178309","rc":[{"atb":[[1.4,2.11]],"id":40953876},{"atb":[[1.4,2.11]],"id":48500723},{"atb":[[1.4,2.11]],"id":44798446}],"con":true,"img":false}]}
{"op":"mcm","clk":"11540502175","pt":1719495244010,"mc":[{"id":"1.230178309","rc":[{"atb":[[1.19,0]],"id":55829870}],"con":true,"img":false}]}
{"op":"mcm","clk":"11540502190","pt":1719495244215,"mc":[{"id":"1.230178309","rc":[{"atb":[[1.35,0]],"id":40953876}],"con":true,"img":false}]}
{"op":"mcm","clk":"11540502223","pt":1719495244626,"mc":[{"id":"1.230178309","rc":[{"atb":[[1.23,17.17]],"id":55829870}],"con":true,"img":false}]}
{"op":"mcm","clk":"11540502244","pt":1719495244937,"mc":[{"id":"1.230178309","rc":[{"atb":[[1.35,0]],"id":48500723}],"con":true,"img":false}]}
{"op":"mcm","clk":"11540502257","pt":1719495245095,"mc":[{"id":"1.230178309","rc":[{"atb":[[1.42,9.4]],"id":40953876}],"con":true,"img":false}]}
{"op":"mcm","clk":"11540502275","pt":1719495245301,"mc":[{"id":"1.230178309","rc":[{"atb":[[1.42,9.4]],"id":48500723}],"con":true,"img":false}]}
{"op":"mcm","clk":"11540505247","pt":1719495277959,"mc":[{"id":"1.230178309","rc":[{"spn":38.21,"spf":"NaN","id":40953876},{"atb":[[1.37,0]],"id":48500723},{"spn":38.21,"spf":"NaN","id":48500723},{"spn":38.2,"spf":"NaN","id":44798446},{"spn":38.11,"spf":"NaN","id":55829870}],"con":true,"img":false}]}
{"op":"mcm","clk":"11540505309","pt":1719495278581,"mc":[{"id":"1.230178309","rc":[{"atb":[[1.37,0]],"id":40953876}],"con":true,"img":false}]}
{"op":"mcm","clk":"11540505353","pt":1719495279053,"mc":[{"id":"1.230178309","rc":[{"atb":[[1.21,0]],"id":55829870}],"con":true,"img":false}]}
{"op":"mcm","clk":"11540505365","pt":1719495279153,"mc":[{"id":"1.230178309","rc":[{"atb":[[1.44,9.62]],"id":48500723}],"con":true,"img":false}]}
{"op":"mcm","clk":"11540505468","pt":1719495280038,"mc":[{"id":"1.230178309","rc":[{"atb":[[1.44,9.62]],"id":40953876}],"con":true,"img":false}]}
{"op":"mcm","clk":"11540505486","pt":1719495280353,"mc":[{"id":"1.230178309","rc":[{"atb":[[1.25,16.93]],"id":55829870}],"con":true,"img":false}]}
{"op":"mcm","clk":"11540505937","pt":1719495284367,"mc":[{"id":"1.230178309","rc":[{"atb":[[1.42,0]],"id":48500723},{"atb":[[1.23,0]],"id":55829870}],"con":true,"img":false}]}
{"op":"mcm","clk":"11540505990","pt":1719495284939,"mc":[{"id":"1.230178309","rc":[{"atb":[[1.42,0]],"id":40953876},{"atb":[[1.46,8.58]],"id":48500723}],"con":true,"img":false}]}
{"op":"mcm","clk":"11540506006","pt":1719495285150,"mc":[{"id":"1.230178309","rc":[{"atb":[[1.27,14.63]],"id":55829870}],"con":true,"img":false}]}
{"op":"mcm","clk":"11540506097","pt":1719495286187,"mc":[{"id":"1.230178309","rc":[{"atb":[[1.46,8.58]],"id":40953876}],"con":true,"img":false}]}
{"op":"mcm","clk":"11540508620","pt":1719495313009,"mc":[{"id":"1.230178309","rc":[{"atb":[[1.35,0]],"id":44798446}],"con":true,"img":false}]}
{"op":"mcm","clk":"11540509197","pt":1719495319613,"mc":[{"id":"1.230178309","rc":[{"atb":[[1.44,0]],"id":48500723}],"con":true,"img":false}]}
{"op":"mcm","clk":"11540509255","pt":1719495320085,"mc":[{"id":"1.230178309","rc":[{"atb":[[1.44,0]],"id":40953876}],"con":true,"img":false}]}
{"op":"mcm","clk":"11540509334","pt":1719495320808,"mc":[{"id":"1.230178309","rc":[{"atb":[[1.25,0]],"id":55829870}],"con":true,"img":false}]}
{"op":"mcm","clk":"11540509406","pt":1719495321390,"mc":[{"id":"1.230178309","rc":[{"atb":[[1.48,8.82]],"id":40953876}],"con":true,"img":false}]}
{"op":"mcm","clk":"11540509441","pt":1719495321701,"mc":[{"id":"1.230178309","rc":[{"atb":[[1.48,8.82]],"id":48500723}],"con":true,"img":false}]}
{"op":"mcm","clk":"11540509470","pt":1719495322011,"mc":[{"id":"1.230178309","rc":[{"atb":[[1.29,14.6]],"id":55829870}],"con":true,"img":false}]}
{"op":"mcm","clk":"11540511194","pt":1719495341361,"mc":[{"id":"1.230178309","rc":[{"spn":38.24,"spf":"NaN","id":40953876},{"atb":[[1.46,0]],"id":48500723},{"spn":38.24,"spf":"NaN","id":48500723},{"spn":38.14,"spf":"NaN","id":55829870}],"con":true,"img":false}]}
{"op":"mcm","clk":"11540511209","pt":1719495341564,"mc":[{"id":"1.230178309","rc":[{"atb":[[1.46,0]],"id":40953876},{"atb":[[1.27,0]],"id":55829870}],"con":true,"img":false}]}
{"op":"mcm","clk":"11540511225","pt":1719495341760,"mc":[{"id":"1.230178309","rc":[{"atb":[[1.5,7.9]],"id":48500723}],"con":true,"img":false}]}
{"op":"mcm","clk":"11540511246","pt":1719495341978,"mc":[{"id":"1.230178309","rc":[{"atb":[[1.31,12.74]],"id":55829870}],"con":true,"img":false}]}
{"op":"mcm","clk":"11540511264","pt":1719495342185,"mc":[{"id":"1.230178309","rc":[{"atb":[[1.5,7.9]],"id":40953876}],"con":true,"img":false}]}
{"op":"mcm","clk":"11540511423","pt":1719495343953,"mc":[{"id":"1.230178309","rc":[{"atb":[[1.34,2.11]],"id":55829870}],"con":true,"img":false}]}
{"op":"mcm","clk":"11540512735","pt":1719495358381,"mc":[{"id":"1.230178309","rc":[{"atb":[[1.37,0]],"id":44798446}],"con":true,"img":false}]}
{"op":"mcm","clk":"11540512884","pt":1719495360166,"mc":[{"id":"1.230178309","rc":[{"atb":[[1.31,0]],"id":55829870}],"con":true,"img":false}]}
{"op":"mcm","clk":"11540512927","pt":1719495360693,"mc":[{"id":"1.230178309","rc":[{"atb":[[1.36,10.97]],"id":55829870}],"con":true,"img":false}]}
{"op":"mcm","clk":"11540513290","pt":1719495363962,"mc":[{"id":"1.230178309","rc":[{"atb":[[1.48,0]],"id":40953876}],"con":true,"img":false}]}
{"op":"mcm","clk":"11540513350","pt":1719495364586,"mc":[{"id":"1.230178309","rc":[{"atb":[[1.29,0]],"id":55829870}],"con":true,"img":false}]}
{"op":"mcm","clk":"11540513389","pt":1719495364901,"mc":[{"id":"1.230178309","rc":[{"atb":[[1.48,0]],"id":48500723}],"con":true,"img":false}]}
{"op":"mcm","clk":"11540513469","pt":1719495365592,"mc":[{"id":"1.230178309","rc":[{"atb":[[1.52,8.14]],"id":40953876}],"con":true,"img":false}]}
{"op":"mcm","clk":"11540513566","pt":1719495366479,"mc":[{"id":"1.230178309","rc":[{"atb":[[1.52,8.14]],"id":48500723}],"con":true,"img":false}]}
{"op":"mcm","clk":"11540513582","pt":1719495366688,"mc":[{"id":"1.230178309","rc":[{"atb":[[1.38,11.14]],"id":55829870}],"con":true,"img":false}]}
{"op":"mcm","clk":"11540513769","pt":1719495368366,"mc":[{"id":"1.230178309","rc":[{"atb":[[1.41,2.11],[1.34,0]],"id":55829870}],"con":true,"img":false}]}
{"op":"mcm","clk":"11540514615","pt":1719495378795,"mc":[{"id":"1.230178309","rc":[{"atb":[[1.36,0]],"id":55829870}],"con":true,"img":false}]}
{"op":"mcm","clk":"11540514634","pt":1719495379102,"mc":[{"id":"1.230178309","rc":[{"atb":[[1.5,0]],"id":48500723}],"con":true,"img":false}]}
{"op":"mcm","clk":"11540514648","pt":1719495379310,"mc":[{"id":"1.230178309","rc":[{"atb":[[1.5,0]],"id":40953876}],"con":true,"img":false}]}
{"op":"mcm","clk":"11540514664","pt":1719495379516,"mc":[{"id":"1.230178309","rc":[{"atb":[[1.43,9.18]],"id":55829870}],"con":true,"img":false}]}
{"op":"mcm","clk":"11540514698","pt":1719495379880,"mc":[{"id":"1.230178309","rc":[{"atb":[[1.54,7.31]],"id":48500723}],"con":true,"img":false}]}
{"op":"mcm","clk":"11540514713","pt":1719495380089,"mc":[{"id":"1.230178309","rc":[{"atb":[[1.54,7.31]],"id":40953876}],"con":true,"img":false}]}
{"op":"mcm","clk":"11540516473","pt":1719495404102,"mc":[{"id":"1.230178309","rc":[{"spn":38.27,"spf":"NaN","id":40953876},{"atb":[[1.52,0]],"id":48500723},{"spn":38.27,"spf":"NaN","id":48500723},{"spn":38.21,"spf":"NaN","id":55829870}],"con":true,"img":false}]}
{"op":"mcm","clk":"11540516493","pt":1719495404514,"mc":[{"id":"1.230178309","rc":[{"atb":[[1.38,0]],"id":55829870}],"con":true,"img":false}]}
{"op":"mcm","clk":"11540516528","pt":1719495405126,"mc":[{"id":"1.230178309","rc":[{"atb":[[1.52,0]],"id":40953876}],"con":true,"img":false}]}
{"op":"mcm","clk":"11540516565","pt":1719495405692,"mc":[{"id":"1.230178309","rc":[{"atb":[[1.45,9.4]],"id":55829870}],"con":true,"img":false}]}
{"op":"mcm","clk":"11540516570","pt":1719495405794,"mc":[{"id":"1.230178309","rc":[{"atb":[[1.56,7.56]],"id":48500723}],"con":true,"img":false}]}
{"op":"mcm","clk":"11540516613","pt":1719495406414,"mc":[{"id":"1.230178309","rc":[{"atb":[[1.56,7.56]],"id":40953876}],"con":true,"img":false}]}
{"op":"mcm","clk":"11540517374","pt":1719495417242,"mc":[{"id":"1.230178309","rc":[{"atb":[[1.54,0]],"id":48500723}],"con":true,"img":false}]}
{"op":"mcm","clk":"11540517448","pt":1719495418216,"mc":[{"id":"1.230178309","rc":[{"atb":[[1.58,6.81]],"id":48500723}],"con":true,"img":false}]}
{"op":"mcm","clk":"11540519552","pt":1719495443635,"mc":[{"id":"1.230178309","rc":[{"atb":[[1.56,0]],"id":48500723}],"con":true,"img":false}]}
{"op":"mcm","clk":"11540519643","pt":1719495444668,"mc":[{"id":"1.230178309","rc":[{"atb":[[1.6,7.05]],"id":48500723}],"con":true,"img":false}]}
{"op":"mcm","clk":"11540520531","pt":1719495456264,"mc":[{"id":"1.230178309","rc":[{"atb":[[1.43,0]],"id":55829870}],"con":true,"img":false}]}
{"op":"mcm","clk":"11540520591","pt":1719495456985,"mc":[{"id":"1.230178309","rc":[{"atb":[[1.54,0]],"id":40953876}],"con":true,"img":false}]}
{"op":"mcm","clk":"11540520598","pt":1719495457083,"mc":[{"id":"1.230178309","rc":[{"atb":[[1.58,0]],"id":48500723}],"con":true,"img":false}]}
{"op":"mcm","clk":"11540520647","pt":1719495457555,"mc":[{"id":"1.230178309","rc":[{"atb":[[1.58,6.81]],"id":40953876}],"con":true,"img":false}]}
{"op":"mcm","clk":"11540520658","pt":1719495457656,"mc":[{"id":"1.230178309","rc":[{"atb":[[1.62,6.36]],"id":48500723}],"con":true,"img":false}]}
{"op":"mcm","clk":"11540522119","pt":1719495476005,"mc":[{"id":"1.230178309","rc":[{"spn":38.29,"spf":"NaN","id":40953876},{"spn":38.31,"spf":"NaN","id":48500723},{"atb":[[1.47,8.4]],"id":55829870},{"spn":38.23,"spf":"NaN","id":55829870}],"con":true,"img":false}]}
{"op":"mcm","clk":"11540522803","pt":1719495483909,"mc":[{"id":"1.230178309","rc":[{"atb":[[1.6,0]],"id":48500723}],"con":true,"img":false}]}
{"op":"mcm","clk":"11540522835","pt":1719495484182,"mc":[{"id":"1.230178309","rc":[{"atb":[[1.64,6.61]],"id":48500723}],"con":true,"img":false}]}
{"op":"mcm","clk":"11540523908","pt":1719495497528,"mc":[{"id":"1.230178309","rc":[{"atb":[[1.62,0]],"id":48500723}],"con":true,"img":false}]}
{"op":"mcm","clk":"11540523955","pt":1719495498011,"mc":[{"id":"1.230178309","rc":[{"atb":[[1.66,5.98]],"id":48500723}],"con":true,"img":false}]}
{"op":"mcm","clk":"11540525557","pt":1719495518161,"mc":[{"id":"1.230178309","rc":[{"atb":[[1.58,0]],"id":40953876}],"con":true,"img":false}]}
{"op":"mcm","clk":"11540525761","pt":1719495520348,"mc":[{"id":"1.230178309","rc":[{"atb":[[1.64,0]],"id":48500723}],"con":true,"img":false}]}
{"op":"mcm","clk":"11540525835","pt":1719495521336,"mc":[{"id":"1.230178309","rc":[{"atb":[[1.68,6.22]],"id":48500723}],"con":true,"img":false}]}
{"op":"mcm","clk":"11540527356","pt":1719495539156,"mc":[{"id":"1.230178309","rc":[{"atb":[[1.58,6.81]],"id":40953876},{"spn":38.34,"spf":"NaN","id":48500723}],"con":true,"img":false}]}
{"op":"mcm","clk":"11540527440","pt":1719495540133,"mc":[{"id":"1.230178309","rc":[{"atb":[[1.69,5.99]],"id":48500723},{"atl":[[13,2]],"id":48500723}],"con":true,"img":false}]}
{"op":"mcm","clk":"11540527451","pt":1719495540237,"mc":[{"id":"1.230178309","rc":[{"atb":[[2.32,1],[1.68,6.81]],"id":40953876},{"atl":[[6.2,1],[24,2]],"id":40953876},{"atb":[[2.02,1],[1.58,2.48]],"id":39362025},{"atl":[[16.5,2],[5.8,1]],"id":39362025},{"atb":[[1.7,1]],"id":48500723},{"atl":[[4.4,1]],"id":48500723},{"atb":[[1.37,1],[1.33,4.24]],"id":44798446},{"atl":[[3.25,1],[7,2]],"id":44798446},{"atb":[[2.32,1],[1.67,2.48]],"id":70218235},{"atl":[[23,2],[6.8,1]],"id":70218235},{"atb":[[1.76,8.41]],"id":55829870},{"atl":[[34,2]],"id":55829870}],"con":true,"img":false}]}
{"op":"mcm","clk":"11540527458","pt":1719495540341,"mc":[{"id":"1.230178309","rc":[{"atb":[[2.22,1]],"id":55829870},{"atl":[[6.6,1]],"id":55829870}],"con":true,"img":false}]}
{"op":"mcm","clk":"11540527733","pt":1719495543265,"mc":[{"id":"1.230178309","rc":[{"atb":[[1.41,0],[1.5,2.11]],"id":55829870}],"con":true,"img":false}]}
{"op":"mcm","clk":"11540528692","pt":1719495554088,"mc":[{"id":"1.230178309","rc":[{"atb":[[1.76,6.81]],"id":40953876},{"atb":[[1.58,0],[1.66,2.48]],"id":39362025},{"atb":[[1.38,4.24]],"id":44798446},{"atb":[[1.75,2.48]],"id":70218235},{"atb":[[1.87,8.41],[1.76,0]],"id":55829870}],"con":true,"img":false}]}
{"op":"mcm","clk":"11540528707","pt":1719495554194,"mc":[{"id":"1.230178309","rc":[{"atb":[[1.68,0]],"id":40953876},{"atb":[[1.33,0]],"id":44798446},{"atb":[[1.67,0]],"id":70218235}],"con":true,"img":false}]}
{"op":"mcm","clk":"11540528899","pt":1719495556586,"mc":[{"id":"1.230178309","rc":[{"atb":[[1.56,0]],"id":40953876},{"atb":[[1.45,0]],"id":55829870}],"con":true,"img":false}]}
{"op":"mcm","clk":"11540528988","pt":1719495557679,"mc":[{"id":"1.230178309","rc":[{"atl":[[5.8,1],[6.2,0]],"id":40953876},{"atb":[[2.02,0],[2.32,1]],"id":39362025},{"atb":[[1.7,0],[1.66,6.98]],"id":48500723},{"atl":[[4.3,1],[4.4,0]],"id":48500723},{"atl":[[3.25,0],[3.15,1]],"id":44798446},{"atb":[[2.32,0],[2.18,1]],"id":70218235},{"atl":[[6.8,0],[6.6,1]],"id":70218235},{"atl":[[6.4,1],[6.6,0]],"id":55829870}],"con":true,"img":false}]}
{"op":"mcm","clk":"11540528997","pt":1719495557779,"mc":[{"id":"1.230178309","rc":[{"atl":[[4.3,0],[3.95,1]],"id":48500723},{"atl":[[3.15,0],[2.78,1]],"id":44798446},{"atl":[[5.8,1],[6.6,0]],"id":70218235},{"atl":[[6.4,0],[6.8,1]],"id":55829870}],"con":true,"img":false}]}
{"op":"mcm","clk":"11540529008","pt":1719495557888,"mc":[{"id":"1.230178309","rc":[{"atb":[[2.22,0],[2.46,1]],"id":55829870}],"con":true,"img":false}]}
{"op":"mcm","clk":"11540529019","pt":1719495557996,"mc":[{"id":"1.230178309","rc":[{"atb":[[1.82,6.81],[1.76,0]],"id":40953876},{"atb":[[1.4,4.23],[1.38,0]],"id":44798446},{"atb":[[1.8,2.48],[1.75,0]],"id":70218235},{"atb":[[1.94,8.41],[1.87,0]],"id":55829870}],"con":true,"img":false}]}
{"op":"mcm","clk":"11540529032","pt":1719495558095,"mc":[{"id":"1.230178309","rc":[{"atb":[[1.4,2.11],[1.37,7.36]],"id":44798446}],"con":true,"img":false}]}
{"op":"mcm","clk":"11540529036","pt":1719495558201,"mc":[{"id":"1.230178309","rc":[{"atb":[[1.4,4.11],[1.37,1]],"id":44798446}],"con":true,"img":false}]}
{"op":"mcm","clk":"11540529050","pt":1719495558291,"mc":[{"id":"1.230178309","rc":[{"atb":[[1.4,2.11],[1.2,9.73]],"id":44798446}],"con":true,"img":false}]}
{"op":"mcm","clk":"11540529059","pt":1719495558356,"mc":[{"id":"1.230178309","rc":[{"atb":[[1.4,4.11],[1.2,0.25]],"id":44798446}],"con":true,"img":false}]}
{"op":"mcm","clk":"11540529751","pt":1719495566997,"mc":[{"id":"1.230178309","rc":[{"atl":[[7.6,9.46]],"id":44798446}],"con":true,"img":false}]}
{"op":"mcm","clk":"11540529892","pt":1719495568966,"mc":[{"id":"1.230178309","rc":[{"atl":[[7.6,0]],"id":44798446}],"con":true,"img":false}]}
{"op":"mcm","clk":"11540530848","pt":1719495580905,"mc":[{"id":"1.230178309","rc":[{"atb":[[1.58,0]],"id":40953876},{"atb":[[1.47,0]],"id":55829870}],"con":true,"img":false}]}
{"op":"mcm","clk":"11540530931","pt":1719495581811,"mc":[{"id":"1.230178309","rc":[{"atl":[[7.6,9.4]],"id":44798446}],"con":true,"img":false}]}
{"op":"mcm","clk":"11540531189","pt":1719495584722,"mc":[{"id":"1.230178309","rc":[{"atl":[[7.6,0]],"id":44798446}],"con":true,"img":false}]}
{"op":"mcm","clk":"11540531637","pt":1719495590115,"mc":[{"id":"1.230178309","rc":[{"atl":[[7.6,9.46]],"id":44798446}],"con":true,"img":false}]}
{"op":"mcm","clk":"11540531806","pt":1719495592189,"mc":[{"id":"1.230178309","rc":[{"atl":[[7.6,0]],"id":44798446}],"con":true,"img":false}]}
{"op":"mcm","clk":"11540532221","pt":1719495597608,"mc":[{"id":"1.230178309","rc":[{"atl":[[7.6,9.46]],"id":44798446}],"con":true,"img":false}]}
{"op":"mcm","clk":"11540532379","pt":1719495599631,"mc":[{"id":"1.230178309","rc":[{"spn":4.06,"spf":"NaN","id":40953876},{"spn":2.11,"spf":1.0,"id":39362025},{"atb":[[1.66,1]],"id":48500723},{"spn":2.82,"spf":"NaN","id":48500723},{"spn":2.09,"spf":"NaN","id":44798446},{"spn":3.99,"spf":"NaN","id":70218235},{"spn":4.63,"spf":"NaN","id":55829870}],"con":true,"img":false}]}
{"op":"mcm","clk":"11540532386","pt":1719495599735,"mc":[{"id":"1.230178309","rc":[{"atl":[[7.6,0]],"id":44798446}],"con":true,"img":false}]}
{"op":"mcm","clk":"11540532838","pt":1719495604925,"mc":[{"id":"1.230178309","rc":[{"atl":[[7.6,9.46]],"id":44798446}],"con":true,"img":false}]}
{"op":"mcm","clk":"11540533011","pt":1719495606802,"mc":[{"id":"1.230178309","rc":[{"atl":[[7.6,0]],"id":44798446}],"con":true,"img":false}]}
{"op":"mcm","clk":"11540533407","pt":1719495611633,"mc":[{"id":"1.230178309","rc":[{"atb":[[1.02,2]],"id":39362025}],"con":true,"img":false}]}
{"op":"mcm","clk":"11540533432","pt":1719495611953,"mc":[{"id":"1.230178309","rc":[{"atb":[[1.02,2]],"id":70218235}],"con":true,"img":false}]}
{"op":"mcm","clk":"11540533472","pt":1719495612327,"mc":[{"id":"1.230178309","rc":[{"atb":[[1.02,2]],"id":44798446}],"con":true,"img":false}]}
{"op":"mcm","clk":"11540533505","pt":1719495612642,"mc":[{"id":"1.230178309","rc":[{"atb":[[1.7,2]],"id":48500723},{"atl":[[7.6,9.46]],"id":44798446}],"con":true,"img":false}]}
{"op":"mcm","clk":"11540533534","pt":1719495612905,"mc":[{"id":"1.230178309","rc":[{"atb":[[1.02,2]],"id":40953876}],"con":true,"img":false}]}
{"op":"mcm","clk":"11540533567","pt":1719495613342,"mc":[{"id":"1.230178309","rc":[{"atb":[[1.02,24.66]],"id":55829870}],"con":true,"img":false}]}
{"op":"mcm","clk":"11540533641","pt":1719495614122,"mc":[{"id":"1.230178309","rc":[{"atl":[[7.6,0]],"id":44798446}],"con":true,"img":false}]}
{"op":"mcm","clk":"11540534109","pt":1719495619522,"mc":[{"id":"1.230178309","rc":[{"atl":[[7.6,9.46]],"id":44798446}],"con":true,"img":false}]}
{"op":"mcm","clk":"11540534412","pt":1719495622648,"mc":[{"id":"1.230178309","rc":[{"atl":[[7.6,0]],"id":44798446}],"con":true,"img":false}]}
{"op":"mcm","clk":"11540534951","pt":1719495628071,"mc":[{"id":"1.230178309","rc":[{"atl":[[7.6,9.46]],"id":44798446}],"con":true,"img":false}]}
{"op":"mcm","clk":"11540535130","pt":1719495629943,"mc":[{"id":"1.230178309","rc":[{"atl":[[7.6,0]],"id":44798446}],"con":true,"img":false}]}
{"op":"mcm","clk":"11540535618","pt":1719495635151,"mc":[{"id":"1.230178309","rc":[{"atl":[[7.6,9.46]],"id":44798446}],"con":true,"img":false}]}
{"op":"mcm","clk":"11540535816","pt":1719495637384,"mc":[{"id":"1.230178309","rc":[{"atb":[[1.68,0]],"id":48500723}],"con":true,"img":false}]}
{"op":"mcm","clk":"11540535840","pt":1719495637540,"mc":[{"id":"1.230178309","rc":[{"atl":[[7.6,0]],"id":44798446}],"con":true,"img":false}]}
{"op":"mcm","clk":"11540536034","pt":1719495639560,"mc":[{"id":"1.230178309","rc":[{"atb":[[1.64,3.75]],"id":48500723}],"con":true,"img":false}]}
{"op":"mcm","clk":"11540536044","pt":1719495639664,"mc":[{"id":"1.230178309","rc":[{"atb":[[1.64,0]],"id":48500723}],"con":true,"img":false}]}
{"op":"mcm","clk":"11540536175","pt":1719495641065,"mc":[{"id":"1.230178309","rc":[{"atb":[[1.7,0]],"id":48500723}],"con":true,"img":false}]}
{"op":"mcm","clk":"11540536185","pt":1719495641167,"mc":[{"id":"1.230178309","rc":[{"atb":[[1.64,6.99],[1.02,24.66],[1.69,0]],"id":48500723}],"con":true,"img":false}]}
{"op":"mcm","clk":"11540536368","pt":1719495643042,"mc":[{"id":"1.230178309","rc":[{"atl":[[7.6,9.46]],"id":44798446}],"con":true,"img":false}]}
{"op":"mcm","clk":"11540536486","pt":1719495644387,"mc":[{"id":"1.230178309","rc":[{"atl":[[7.6,0]],"id":44798446}],"con":true,"img":false}]}
{"op":"mcm","clk":"11540537080","pt":1719495650600,"mc":[{"id":"1.230178309","rc":[{"atl":[[7.6,9.53]],"id":44798446}],"con":true,"img":false}]}
{"op":"mcm","clk":"11540537264","pt":1719495652275,"mc":[{"id":"1.230178309","rc":[{"atl":[[7.6,0]],"id":44798446}],"con":true,"img":false}]}
{"op":"mcm","clk":"11540537918","pt":1719495659366,"mc":[{"id":"1.230178309","rc":[{"atb":[[1.66,6.98]],"id":48500723}],"con":true,"img":false}]}
{"op":"mcm","clk":"11540537931","pt":1719495659470,"mc":[{"id":"1.230178309","rc":[{"atb":[[1.64,0],[1.67,6.99]],"id":48500723}],"con":true,"img":false}]}
{"op":"mcm","clk":"11540538069","pt":1719495660771,"mc":[{"id":"1.230178309","rc":[{"atb":[[1.02,22.66]],"id":48500723},{"spn":2.81,"spf":"NaN","id":48500723}],"con":true,"img":false}]}
{"op":"mcm","clk":"11540538079","pt":1719495660870,"mc":[{"id":"1.230178309","rc":[{"atb":[[1.68,2]],"id":48500723}],"con":true,"img":false}]}
{"op":"mcm","clk":"11540538520","pt":1719495665567,"mc":[{"id":"1.230178309","rc":[{"atl":[[7.6,9.53]],"id":44798446}],"con":true,"img":false}]}
{"op":"mcm","clk":"11540538604","pt":1719495666400,"mc":[{"id":"1.230178309","rc":[{"atl":[[7.6,0]],"id":44798446}],"con":true,"img":false}]}
{"op":"mcm","clk":"11540539184","pt":1719495672271,"mc":[{"id":"1.230178309","rc":[{"atl":[[7.6,9.53]],"id":44798446}],"con":true,"img":false}]}
{"op":"mcm","clk":"11540539347","pt":1719495673885,"mc":[{"id":"1.230178309","rc":[{"atl":[[7.6,0]],"id":44798446}],"con":true,"img":false}]}
{"op":"mcm","clk":"11540539750","pt":1719495677878,"mc":[{"id":"1.230178309","rc":[{"atb":[[1.94,0]],"id":55829870}],"con":true,"img":false}]}
{"op":"mcm","clk":"11540539759","pt":1719495677980,"mc":[{"id":"1.230178309","rc":[{"atb":[[1.82,0],[1.76,7.81]],"id":40953876},{"atb":[[1.4,2.11],[1.38,8.24]],"id":44798446},{"atb":[[1.87,9.41]],"id":55829870}],"con":true,"img":false}]}
{"op":"mcm","clk":"11540539778","pt":1719495678185,"mc":[{"id":"1.230178309","rc":[{"atb":[[1.37,11.36],[1.38,0]],"id":44798446}],"con":true,"img":false}]}
{"op":"mcm","clk":"11540539805","pt":1719495678393,"mc":[{"id":"1.230178309","rc":[{"atb":[[1.37,1],[1.38,4.24]],"id":44798446}],"con":true,"img":false}]}
{"op":"mcm","clk":"11540546374","pt":1719495757798,"mc":[{"id":"1.230178309","rc":[{"atb":[[1.66,1]],"id":48500723},{"spn":2.81,"spf":"NaN","id":48500723}],"con":true,"img":false}]}
{"op":"mcm","clk":"11540547297","pt":1719495767926,"mc":[{"id":"1.230178309","rc":[{"atl":[[7.8,9.74]],"id":44798446}],"con":true,"img":false}]}
{"op":"mcm","clk":"11540547391","pt":1719495769011,"mc":[{"id":"1.230178309","rc":[{"atl":[[7.8,0]],"id":44798446}],"con":true,"img":false}]}
{"op":"mcm","clk":"11540548617","pt":1719495781882,"mc":[{"id":"1.230178309","rc":[{"atl":[[7.8,9.52]],"id":44798446}],"con":true,"img":false}]}
{"op":"mcm","clk":"11540548755","pt":1719495783222,"mc":[{"id":"1.230178309","rc":[{"atl":[[7.8,0]],"id":44798446}],"con":true,"img":false}]}
{"op":"mcm","clk":"11540549473","pt":1719495790395,"mc":[{"id":"1.230178309","rc":[{"atl":[[7.8,9.55]],"id":44798446}],"con":true,"img":false}]}
{"op":"mcm","clk":"11540549531","pt":1719495791120,"mc":[{"id":"1.230178309","rc":[{"atl":[[7.8,0]],"id":44798446}],"con":true,"img":false}]}
{"op":"mcm","clk":"11540550047","pt":1719495796810,"mc":[{"id":"1.230178309","rc":[{"atl":[[7.8,9.55]],"id":44798446}],"con":true,"img":false}]}
{"op":"mcm","clk":"11540550251","pt":1719495798827,"mc":[{"id":"1.230178309","rc":[{"atl":[[7.8,0]],"id":44798446}],"con":true,"img":false}]}
{"op":"mcm","clk":"11540550793","pt":1719495805131,"mc":[{"id":"1.230178309","rc":[{"atl":[[7.8,9.55]],"id":44798446}],"con":true,"img":false}]}
{"op":"mcm","clk":"11540550877","pt":1719495806010,"mc":[{"id":"1.230178309","rc":[{"atl":[[7.8,0]],"id":44798446}],"con":true,"img":false}]}
{"op":"mcm","clk":"11540554296","pt":1719495841470,"mc":[{"id":"1.230178309","rc":[{"atb":[[1.01,1]],"id":48500723}],"con":true,"img":false}]}
{"op":"mcm","clk":"11540554953","pt":1719495848382,"mc":[{"id":"1.230178309","rc":[{"atb":[[1.08,50]],"id":40953876},{"atb":[[1.08,50]],"id":39362025},{"atb":[[1.08,50]],"id":48500723},{"atb":[[1.08,50]],"id":44798446},{"atb":[[1.08,50]],"id":70218235},{"atb":[[1.08,50]],"id":55829870}],"con":true,"img":false}]}
{"op":"mcm","clk":"11540559699","pt":1719495900549,"mc":[{"id":"1.230178309","rc":[{"atl":[[7.8,9.58]],"id":44798446}],"con":true,"img":false}]}
{"op":"mcm","clk":"11540559841","pt":1719495901940,"mc":[{"id":"1.230178309","rc":[{"atl":[[7.8,0]],"id":44798446}],"con":true,"img":false}]}
{"op":"mcm","clk":"11540559868","pt":1719495902107,"mc":[{"id":"1.230178309","rc":[{"atl":[[7.6,2.42]],"id":44798446}],"con":true,"img":false}]}
{"op":"mcm","clk":"11540560053","pt":1719495903916,"mc":[{"id":"1.230178309","rc":[{"atl":[[7.6,0]],"id":44798446}],"con":true,"img":false}]}
{"op":"mcm","clk":"11540560138","pt":1719495904750,"mc":[{"id":"1.230178309","rc":[{"atl":[[7.8,9.55]],"id":44798446}],"con":true,"img":false}]}
{"op":"mcm","clk":"11540560293","pt":1719495906252,"mc":[{"id":"1.230178309","rc":[{"atl":[[7.8,0]],"id":44798446}],"con":true,"img":false}]}
{"op":"mcm","clk":"11540560333","pt":1719495906523,"mc":[{"id":"1.230178309","rc":[{"atl":[[7.6,4.82]],"id":44798446}],"con":true,"img":false}]}
{"op":"mcm","clk":"11540560945","pt":1719495912039,"mc":[{"id":"1.230178309","rc":[{"atb":[[1.42,9.4]],"id":44798446}],"con":true,"img":false}]}
{"op":"mcm","clk":"11540560969","pt":1719495912255,"mc":[{"id":"1.230178309","rc":[{"atb":[[1.7,5.64]],"id":48500723}],"con":true,"img":false}]}
{"op":"mcm","clk":"11540560986","pt":1719495912446,"mc":[{"id":"1.230178309","rc":[{"atb":[[1.67,0],[1.71,5.64]],"id":48500723}],"con":true,"img":false}]}
{"op":"mcm","clk":"11540561102","pt":1719495913445,"mc":[{"id":"1.230178309","rc":[{"atb":[[1.02,0]],"id":44798446}],"con":true,"img":false}]}
{"op":"mcm","clk":"11540561112","pt":1719495913546,"mc":[{"id":"1.230178309","rc":[{"atb":[[1.43,2]],"id":44798446}],"con":true,"img":false}]}
{"op":"mcm","clk":"11540561127","pt":1719495913746,"mc":[{"id":"1.230178309","rc":[{"atb":[[1.68,0]],"id":48500723}],"con":true,"img":false}]}
{"op":"mcm","clk":"11540561136","pt":1719495913847,"mc":[{"id":"1.230178309","rc":[{"atb":[[1.72,2]],"id":48500723}],"con":true,"img":false}]}
{"op":"mcm","clk":"11540561309","pt":1719495915655,"mc":[{"id":"1.230178309","rc":[{"atl":[[5.9,1]],"id":40953876},{"atl":[[5.8,0],[5.9,1]],"id":39362025},{"atl":[[4,1],[3.95,0]],"id":48500723}],"con":true,"img":false}]}
{"op":"mcm","clk":"11540561319","pt":1719495915713,"mc":[{"id":"1.230178309","rc":[{"atl":[[5.8,0]],"id":40953876}],"con":true,"img":false}]}
{"op":"mcm","clk":"11540561326","pt":1719495915818,"mc":[{"id":"1.230178309","rc":[{"atl":[[5.6,1],[5.8,0]],"id":70218235}],"con":true,"img":false}]}
{"op":"mcm","clk":"11540561526","pt":1719495917840,"mc":[{"id":"1.230178309","rc":[{"atb":[[1.45,9.4]],"id":44798446}],"con":true,"img":false}]}
{"op":"mcm","clk":"11540561742","pt":1719495919955,"mc":[{"id":"1.230178309","rc":[{"atb":[[1.43,0]],"id":44798446}],"con":true,"img":false}]}
{"op":"mcm","clk":"11540561754","pt":1719495920053,"mc":[{"id":"1.230178309","rc":[{"atb":[[1.46,2]],"id":44798446},{"atl":[[2.8,1],[2.78,0]],"id":44798446}],"con":true,"img":false}]}
{"op":"mcm","clk":"11540561850","pt":1719495920833,"mc":[{"id":"1.230178309","rc":[{"atl":[[2.8,0],[2.82,1]],"id":44798446}],"con":true,"img":false}]}
{"op":"mcm","clk":"11540561875","pt":1719495921044,"mc":[{"id":"1.230178309","rc":[{"atl":[[2.82,0],[2.8,1]],"id":44798446}],"con":true,"img":false}]}
{"op":"mcm","clk":"11540561897","pt":1719495921252,"mc":[{"id":"1.230178309","rc":[{"atl":[[2.8,0],[2.82,1]],"id":44798446}],"con":true,"img":false}]}
{"op":"mcm","clk":"11540561922","pt":1719495921457,"mc":[{"id":"1.230178309","rc":[{"atl":[[7.6,0]],"id":44798446}],"con":true,"img":false}]}
{"op":"mcm","clk":"11540561964","pt":1719495921760,"mc":[{"id":"1.230178309","rc":[{"atb":[[1.4,0],[1.48,2.11]],"id":44798446},{"atl":[[2.82,0],[2.8,1]],"id":44798446}],"con":true,"img":false}]}
{"op":"mcm","clk":"11540561995","pt":1719495921924,"mc":[{"id":"1.230178309","rc":[{"atb":[[1.91,2.6]],"id":40953876},{"atb":[[1.66,3]],"id":44798446},{"atb":[[1.84,2]],"id":70218235}],"con":true,"img":false}]}
{"op":"mcm","clk":"11540562024","pt":1719495922137,"mc":[{"id":"1.230178309","rc":[{"atb":[[1.91,5.2],[1.76,0]],"id":40953876},{"atl":[[7.2,2.44]],"id":44798446}],"con":true,"img":false}]}
{"op":"mcm","clk":"11540562047","pt":1719495922339,"mc":[{"id":"1.230178309","rc":[{"atl":[[2.8,0],[2.82,1]],"id":44798446}],"con":true,"img":false}]}
{"op":"mcm","clk":"11540562057","pt":1719495922444,"mc":[{"id":"1.230178309","rc":[{"atl":[[7.2,0]],"id":44798446}],"con":true,"img":false}]}
{"op":"mcm","clk":"11540562067","pt":1719495922549,"mc":[{"id":"1.230178309","rc":[{"atb":[[1.46,0]],"id":44798446},{"atl":[[2.82,0],[2.8,1]],"id":44798446}],"con":true,"img":false}]}
{"op":"mcm","clk":"11540562076","pt":1719495922649,"mc":[{"id":"1.230178309","rc":[{"atb":[[1.67,2]],"id":44798446}],"con":true,"img":false}]}
{"op":"mcm","clk":"11540562202","pt":1719495923842,"mc":[{"id":"1.230178309","rc":[{"atl":[[2.8,0],[2.78,1]],"id":44798446}],"con":true,"img":false}]}
{"op":"mcm","clk":"11540562294","pt":1719495924722,"mc":[{"id":"1.230178309","rc":[{"atl":[[2.8,1],[2.78,0]],"id":44798446}],"con":true,"img":false}]}
{"op":"mcm","clk":"11540562789","pt":1719495929834,"mc":[{"id":"1.230178309","rc":[{"atl":[[2.8,0],[2.84,1]],"id":44798446}],"con":true,"img":false}]}
{"op":"mcm","clk":"11540562809","pt":1719495930034,"mc":[{"id":"1.230178309","rc":[{"atb":[[1.42,0]],"id":44798446}],"con":true,"img":false}]}
{"op":"mcm","clk":"11540562830","pt":1719495930244,"mc":[{"id":"1.230178309","rc":[{"atb":[[1.69,5.72]],"id":44798446},{"atl":[[2.8,1],[2.84,0]],"id":44798446}],"con":true,"img":false}]}
{"op":"mcm","clk":"11540562847","pt":1719495930350,"mc":[{"id":"1.230178309","rc":[{"atl":[[2.8,0],[2.84,1]],"id":44798446}],"con":true,"img":false}]}
{"op":"mcm","clk":"11540562913","pt":1719495930968,"mc":[{"id":"1.230178309","rc":[{"atb":[[1.67,0]],"id":44798446}],"con":true,"img":false}]}
{"op":"mcm","clk":"11540562924","pt":1719495931071,"mc":[{"id":"1.230178309","rc":[{"atb":[[1.7,2]],"id":44798446}],"con":true,"img":false}]}
{"op":"mcm","clk":"11540562966","pt":1719495931434,"mc":[{"id":"1.230178309","rc":[{"atl":[[2.82,1],[2.84,0]],"id":44798446}],"con":true,"img":false}]}
{"op":"mcm","clk":"11540563006","pt":1719495931851,"mc":[{"id":"1.230178309","rc":[{"atl":[[2.82,0],[2.84,1]],"id":44798446}],"con":true,"img":false}]}
{"op":"mcm","clk":"11540563067","pt":1719495932467,"mc":[{"id":"1.230178309","rc":[{"atl":[[2.82,1],[2.84,0]],"id":44798446}],"con":true,"img":false}]}
{"op":"mcm","clk":"11540563087","pt":1719495932673,"mc":[{"id":"1.230178309","rc":[{"atl":[[2.84,1]],"id":44798446}],"con":true,"img":false}]}
{"op":"mcm","clk":"11540563109","pt":1719495932837,"mc":[{"id":"1.230178309","rc":[{"atl":[[2.82,0],[2.86,1],[2.84,0]],"id":44798446}],"con":true,"img":false}]}
{"op":"mcm","clk":"11540563118","pt":1719495932942,"mc":[{"id":"1.230178309","rc":[{"atl":[[3.25,2],[7,0]],"id":44798446}],"con":true,"img":false}]}
{"op":"mcm","clk":"11540563154","pt":1719495933359,"mc":[{"id":"1.230178309","rc":[{"atb":[[2.32,2.5],[2.42,2.5],[2.26,10],[2.34,5]],"id":40953876},{"atl":[[5.6,2.5],[18,2],[5.8,1.5],[24,0],[6,5],[6.8,10]],"id":40953876},{"atb":[[2.4,2.5],[2.24,10],[1.79,2.48],[2.32,7.5],[1.66,0]],"id":39362025},{"atl":[[16.5,0],[8.6,10],[5.8,1.5],[12.5,2],[7,2.5],[7.8,5]],"id":39362025},{"atb":[[1.73,3],[2.14,2.5],[1.99,10],[2.06,5]],"id":48500723},{"atl":[[4,3],[17,3],[6.2,5],[13,0],[4.4,1],[5.7,2.5],[7,10]],"id":48500723},{"atb":[[1.83,10],[1.7,5],[1.87,5],[1.91,2.5],[1.29,6],[1.38,0]],"id":44798446},{"atl":[[4.3,2.5],[5.1,10],[3.2,1],[2.86,3],[3.25,0],[4.7,5]],"id":44798446},{"atb":[[2.5,5],[2.58,2.5],[1.8,0],[2.42,10],[1.9,2],[2.2,2.25]],"id":70218235},{"atl":[[8,10],[7.2,5],[18.5,2],[6.4,2.5],[5.5,2.25],[23,0]],"id":70218235},{"atb":[[2.06,10],[2.22,2.5],[2.46,2.25],[1.62,10.41],[2.44,1],[1.87,0],[2.14,5]],"id":55829870},{"atl":[[34,0],[19,2],[5,2.5],[5.8,10],[6.6,2.25],[5.4,5]],"id":55829870}],"con":true,"img":false}]}
{"op":"mcm","clk":"11540563181","pt":1719495933569,"mc":[{"id":"1.230178309","rc":[{"atb":[[2.32,4.62],[1.91,2.6]],"id":40953876},{"atb":[[1.71,0],[2.1,5]],"id":48500723},{"atl":[[4,0]],"id":48500723},{"atl":[[2.86,0],[7,3]],"id":44798446}],"con":true,"img":false}]}
{"op":"mcm","clk":"11540563193","pt":1719495933672,"mc":[{"id":"1.230178309","rc":[{"atb":[[2.1,0],[1.99,17.5]],"id":48500723},{"atl":[[2.88,4.12]],"id":44798446}],"con":true,"img":false}]}
{"op":"mcm","clk":"11540563202","pt":1719495933785,"mc":[{"id":"1.230178309","rc":[{"atl":[[4.1,3.75]],"id":48500723}],"con":true,"img":false}]}
{"op":"mcm","clk":"11540563212","pt":1719495933868,"mc":[{"id":"1.230178309","rc":[{"atb":[[1.99,10],[2.06,10]],"id":48500723},{"atl":[[2.88,0]],"id":44798446}],"con":true,"img":false}]}
{"op":"mcm","clk":"11540563222","pt":1719495933974,"mc":[{"id":"1.230178309","rc":[{"atb":[[2.3,2.11]],"id":39362025},{"atl":[[5.2,9.39]],"id":48500723},{"atl":[[4.1,3.75]],"id":44798446},{"atb":[[2.48,2.11]],"id":70218235}],"con":true,"img":false}]}
{"op":"mcm","clk":"11540563235","pt":1719495934036,"mc":[{"id":"1.230178309","rc":[{"atl":[[5.5,0.84]],"id":40953876},{"atb":[[1.99,22.5],[2.06,5]],"id":48500723},{"atl":[[4,0.84]],"id":48500723},{"atl":[[2.86,0.84]],"id":44798446},{"atl":[[5.4,0.84]],"id":70218235},{"atl":[[4.9,0.84]],"id":55829870}],"con":true,"img":false}]}
{"op":"mcm","clk":"11540563259","pt":1719495934349,"mc":[{"id":"1.230178309","rc":[{"atb":[[1.02,0]],"id":70218235},{"atl":[[5.4,8.93]],"id":55829870}],"con":true,"img":false}]}
{"op":"mcm","clk":"11540563270","pt":1719495934449,"mc":[{"id":"1.230178309","rc":[{"atb":[[2.6,2]],"id":70218235}],"con":true,"img":false}]}
{"op":"mcm","clk":"11540563295","pt":1719495934656,"mc":[{"id":"1.230178309","rc":[{"atl":[[2.86,0]],"id":44798446}],"con":true,"img":false}]}
{"op":"mcm","clk":"11540563306","pt":1719495934758,"mc":[{"id":"1.230178309","rc":[{"atb":[[1.7,3]],"id":44798446}],"con":true,"img":false}]}
{"op":"mcm","clk":"11540563314","pt":1719495934860,"mc":[{"id":"1.230178309","rc":[{"atb":[[1.92,2]],"id":44798446}],"con":true,"img":false}]}
{"op":"mcm","clk":"11540563325","pt":1719495934963,"mc":[{"id":"1.230178309","rc":[{"atl":[[5.2,0]],"id":48500723}],"con":true,"img":false}]}
{"op":"mcm","clk":"11540563370","pt":1719495935377,"mc":[{"id":"1.230178309","rc":[{"atb":[[1.72,0]],"id":48500723}],"con":true,"img":false}]}
{"op":"mcm","clk":"11540563379","pt":1719495935475,"mc":[{"id":"1.230178309","rc":[{"atb":[[2.16,2]],"id":48500723}],"con":true,"img":false}]}
{"op":"mcm","clk":"11540563389","pt":1719495935538,"mc":[{"id":"1.230178309","rc":[{"atb":[[2.1,5],[1.99,10]],"id":48500723}],"con":true,"img":false}]}
{"op":"mcm","clk":"11540563422","pt":1719495935845,"mc":[{"id":"1.230178309","rc":[{"atb":[[1.02,0]],"id":40953876}],"con":true,"img":false}]}
{"op":"mcm","clk":"11540563437","pt":1719495935949,"mc":[{"id":"1.230178309","rc":[{"atb":[[2.44,2]],"id":40953876}],"con":true,"img":false}]}
{"op":"mcm","clk":"11540563447","pt":1719495936049,"mc":[{"id":"1.230178309","rc":[{"atb":[[1.91,0]],"id":40953876},{"atb":[[1.66,0]],"id":44798446},{"atb":[[1.84,0]],"id":70218235}],"con":true,"img":false}]}
{"op":"mcm","clk":"11540563457","pt":1719495936159,"mc":[{"id":"1.230178309","rc":[{"atb":[[2.32,2.5],[2.44,8.1]],"id":40953876},{"atb":[[2.42,2]],"id":39362025},{"atb":[[2.16,4.79]],"id":48500723},{"atb":[[1.92,5]],"id":44798446},{"atb":[[2.6,4.9]],"id":70218235}],"con":true,"img":false}]}
{"op":"mcm","clk":"11540563478","pt":1719495936367,"mc":[{"id":"1.230178309","rc":[{"atb":[[1.02,22.66]],"id":55829870}],"con":true,"img":false}]}
{"op":"mcm","clk":"11540563485","pt":1719495936467,"mc":[{"id":"1.230178309","rc":[{"atb":[[2.48,2]],"id":55829870}],"con":true,"img":false}]}
{"op":"mcm","clk":"11540563630","pt":1719495937967,"mc":[{"id":"1.230178309","rc":[{"atb":[[2.3,0],[2.38,2.11]],"id":39362025},{"atb":[[1.4,0],[2.16,6.9]],"id":48500723},{"atb":[[2.48,0],[2.56,2.11]],"id":70218235}],"con":true,"img":false}]}
{"op":"mcm","clk":"11540563689","pt":1719495938579,"mc":[{"id":"1.230178309","rc":[{"atb":[[2.12,9.41],[2.1,0]],"id":48500723},{"atl":[[4.3,1],[4.4,0]],"id":48500723}],"con":true,"img":false}]}
{"op":"mcm","clk":"11540563763","pt":1719495939165,"mc":[{"id":"1.230178309","rc":[{"atl":[[4.3,7.5],[7,0]],"id":44798446}],"con":true,"img":false}]}
{"op":"mcm","clk":"11540563813","pt":1719495939582,"mc":[{"id":"1.230178309","rc":[{"atl":[[18,0],[5.8,4.85]],"id":40953876},{"atb":[[2.4,6.5],[1.79,0]],"id":39362025},{"atl":[[12.5,0],[7,7.5]],"id":39362025},{"atl":[[17,0],[4.3,5.6]],"id":48500723},{"atb":[[1.9,0],[2.6,7.4]],"id":70218235},{"atl":[[5.6,4.1],[18.5,0]],"id":70218235},{"atb":[[2.22,7.5],[1.62,0]],"id":55829870},{"atl":[[19,0],[5.3,8.93]],"id":55829870}],"con":true,"img":false}]}
{"op":"mcm","clk":"11540563822","pt":1719495939675,"mc":[{"id":"1.230178309","rc":[{"atb":[[1.44,10],[1.29,0]],"id":44798446}],"con":true,"img":false}]}
{"op":"mcm","clk":"11540564230","pt":1719495943787,"mc":[{"id":"1.230178309","rc":[{"atl":[[5.4,5]],"id":55829870}],"con":true,"img":false}]}
{"op":"mcm","clk":"11540564239","pt":1719495943844,"mc":[{"id":"1.230178309","rc":[{"atl":[[3.2,0],[3.25,1]],"id":44798446}],"con":true,"img":false}]}
{"op":"mcm","clk":"11540564250","pt":1719495943954,"mc":[{"id":"1.230178309","rc":[{"atl":[[4.3,2.5],[4.1,8.75]],"id":44798446}],"con":true,"img":false}]}
{"op":"mcm","clk":"11540564314","pt":1719495944673,"mc":[{"id":"1.230178309","rc":[{"atb":[[2.46,1]],"id":40953876},{"atb":[[2.44,1]],"id":39362025},{"atb":[[2.18,1]],"id":48500723},{"atb":[[1.93,1.44]],"id":44798446},{"atb":[[2.62,1]],"id":70218235},{"atb":[[2.5,1.4]],"id":55829870}],"con":true,"img":false}]}
{"op":"mcm","clk":"11540564354","pt":1719495944974,"mc":[{"id":"1.230178309","rc":[{"atl":[[5.8,5.85],[5.9,0]],"id":40953876},{"atl":[[5.8,2.5],[5.9,0]],"id":39362025},{"atl":[[5.6,3.1],[5.5,3.25]],"id":70218235},{"atl":[[6.8,0],[6.6,3.25]],"id":55829870}],"con":true,"img":false}]}
{"op":"mcm","clk":"11540564363","pt":1719495945086,"mc":[{"id":"1.230178309","rc":[{"atb":[[2.4,2.5],[2.38,9.61]],"id":39362025},{"atl":[[7,2.5],[7.8,15]],"id":39362025},{"atb":[[2.12,0],[2.1,9.41]],"id":48500723},{"atb":[[2.6,4.9],[2.58,10.9]],"id":70218235}],"con":true,"img":false}]}
{"op":"mcm","clk":"11540564405","pt":1719495945567,"mc":[{"id":"1.230178309","rc":[{"atl":[[5.7,0.84]],"id":39362025}],"con":true,"img":false}]}
{"op":"mcm","clk":"11540564425","pt":1719495945777,"mc":[{"id":"1.230178309","rc":[{"atl":[[7,12.5],[7.8,5]],"id":39362025},{"atl":[[6.4,1],[6.6,2.25]],"id":55829870}],"con":true,"img":false}]}
{"op":"mcm","clk":"11540564520","pt":1719495946655,"mc":[{"id":"1.230178309","rc":[{"atb":[[2.46,4.75]],"id":40953876},{"atl":[[5.3,3.75]],"id":40953876},{"atb":[[2.44,4.38]],"id":39362025},{"atl":[[5.7,4.22]],"id":39362025},{"atb":[[2.18,5.69]],"id":48500723},{"atb":[[1.93,5.19]],"id":44798446},{"atl":[[3.2,3.75]],"id":44798446},{"atb":[[2.62,5.76]],"id":70218235},{"atl":[[5.4,5.6]],"id":70218235},{"atl":[[4.9,4.03]],"id":55829870}],"con":true,"img":false}]}
{"op":"mcm","clk":"11540564530","pt":1719495946762,"mc":[{"id":"1.230178309","rc":[{"atl":[[5.6,7.5],[5.8,2.5]],"id":40953876}],"con":true,"img":false}]}
{"op":"mcm","clk":"11540564542","pt":1719495946875,"mc":[{"id":"1.230178309","rc":[{"atb":[[2.32,1]],"id":40953876},{"atl":[[5.8,1]],"id":40953876},{"atb":[[2.32,6]],"id":39362025},{"atl":[[5.8,1]],"id":39362025},{"atb":[[1.73,0]],"id":48500723},{"atb":[[1.7,0]],"id":44798446},{"atl":[[4.1,5]],"id":44798446},{"atb":[[2.2,0]],"id":70218235},{"atl":[[5.5,1]],"id":70218235},{"atl":[[6.6,0]],"id":55829870}],"con":true,"img":false}]}
{"op":"mcm","clk":"11540564564","pt":1719495947073,"mc":[{"id":"1.230178309","rc":[{"atl":[[5.2,0.84]],"id":40953876},{"atl":[[3.15,0.84]],"id":44798446}],"con":true,"img":false}]}
{"op":"mcm","clk":"11540564574","pt":1719495947176,"mc":[{"id":"1.230178309","rc":[{"atl":[[5.5,0]],"id":40953876}],"con":true,"img":false}]}
{"op":"mcm","clk":"11540564581","pt":1719495947275,"mc":[{"id":"1.230178309","rc":[{"atl":[[4.1,0],[3.25,5.6]],"id":44798446}],"con":true,"img":false}]}
{"op":"mcm","clk":"11540564669","pt":1719495948056,"mc":[{"id":"1.230178309","rc":[{"atb":[[2.6,2.9]],"id":70218235}],"con":true,"img":false}]}
{"op":"mcm","clk":"11540564679","pt":1719495948161,"mc":[{"id":"1.230178309","rc":[{"atb":[[2.64,2]],"id":70218235}],"con":true,"img":false}]}
{"op":"mcm","clk":"11540564689","pt":1719495948265,"mc":[{"id":"1.230178309","rc":[{"atb":[[2.42,10.76],[2.38,2.11]],"id":39362025},{"atb":[[2.12,11.38],[2.1,0]],"id":48500723},{"atb":[[1.44,0],[1.49,10.19]],"id":44798446}],"con":true,"img":false}]}
{"op":"mcm","clk":"11540564698","pt":1719495948372,"mc":[{"id":"1.230178309","rc":[{"atb":[[1.92,3]],"id":44798446},{"atb":[[2.6,10.66],[2.58,2.5]],"id":70218235}],"con":true,"img":false}]}
{"op":"mcm","clk":"11540564710","pt":1719495948473,"mc":[{"id":"1.230178309","rc":[{"atb":[[1.94,2]],"id":44798446}],"con":true,"img":false}]}
{"op":"mcm","clk":"11540564742","pt":1719495948783,"mc":[{"id":"1.230178309","rc":[{"atb":[[2.16,4.9]],"id":48500723}],"con":true,"img":false}]}
{"op":"mcm","clk":"11540564755","pt":1719495948886,"mc":[{"id":"1.230178309","rc":[{"atb":[[2.2,2]],"id":48500723},{"atb":[[2.5,4.96]],"id":55829870}],"con":true,"img":false}]}
{"op":"mcm","clk":"11540564779","pt":1719495949086,"mc":[{"id":"1.230178309","rc":[{"atb":[[2.46,0]],"id":55829870}],"con":true,"img":false}]}
{"op":"mcm","clk":"11540564808","pt":1719495949358,"mc":[{"id":"1.230178309","rc":[{"atb":[[2.44,6.1]],"id":40953876}],"con":true,"img":false}]}
{"op":"mcm","clk":"11540564815","pt":1719495949460,"mc":[{"id":"1.230178309","rc":[{"atb":[[2.48,2]],"id":40953876}],"con":true,"img":false}]}
{"op":"mcm","clk":"11540564826","pt":1719495949565,"mc":[{"id":"1.230178309","rc":[{"atb":[[1.88,6.28]],"id":44798446}],"con":true,"img":false}]}
{"op":"mcm","clk":"11540564873","pt":1719495950188,"mc":[{"id":"1.230178309","rc":[{"atb":[[2.44,2.5]],"id":40953876},{"atb":[[2.42,8.76],[2.48,2.11]],"id":39362025},{"atb":[[2.16,2.11]],"id":48500723},{"atb":[[1.95,2.11],[1.92,0]],"id":44798446},{"atb":[[2.6,7.76]],"id":70218235}],"con":true,"img":false}]}
{"op":"mcm","clk":"11540564880","pt":1719495950284,"mc":[{"id":"1.230178309","rc":[{"atb":[[2.48,5]],"id":40953876},{"atb":[[2.38,0],[2.46,3]],"id":39362025},{"atb":[[2.2,4.26]],"id":48500723},{"atb":[[1.94,5.5],[1.48,0]],"id":44798446}],"con":true,"img":false}]}
{"op":"mcm","clk":"11540564975","pt":1719495951381,"mc":[{"id":"1.230178309","rc":[{"atb":[[1.94,3.5]],"id":44798446}],"con":true,"img":false}]}
{"op":"mcm","clk":"11540564985","pt":1719495951481,"mc":[{"id":"1.230178309","rc":[{"atb":[[1.96,2]],"id":44798446}],"con":true,"img":false}]}
{"op":"mcm","clk":"11540565008","pt":1719495951794,"mc":[{"id":"1.230178309","rc":[{"atb":[[2.48,0]],"id":55829870}],"con":true,"img":false}]}
{"op":"mcm","clk":"11540565012","pt":1719495951888,"mc":[{"id":"1.230178309","rc":[{"atb":[[2.52,2]],"id":55829870}],"con":true,"img":false}]}
{"op":"mcm","clk":"11540565208","pt":1719495954384,"mc":[{"id":"1.230178309","rc":[{"atb":[[2.42,12],[2.44,0]],"id":40953876},{"atl":[[3.3,1]],"id":44798446},{"atb":[[2.5,1.4]],"id":55829870}],"con":true,"img":false}]}
{"op":"mcm","clk":"11540565219","pt":1719495954486,"mc":[{"id":"1.230178309","rc":[{"atl":[[3.25,4.6]],"id":44798446}],"con":true,"img":false}]}
{"op":"mcm","clk":"11540565262","pt":1719495954913,"mc":[{"id":"1.230178309","rc":[{"atb":[[2.52,0]],"id":55829870}],"con":true,"img":false}]}
{"op":"mcm","clk":"11540565273","pt":1719495955000,"mc":[{"id":"1.230178309","rc":[{"atb":[[2.46,2]],"id":55829870}],"con":true,"img":false}]}
{"op":"mcm","clk":"11540565412","pt":1719495956769,"mc":[{"id":"1.230178309","rc":[{"atb":[[2.46,0]],"id":55829870}],"con":true,"img":false}]}
{"op":"mcm","clk":"11540565422","pt":1719495956872,"mc":[{"id":"1.230178309","rc":[{"atb":[[2.24,2]],"id":55829870}],"con":true,"img":false}]}
{"op":"mcm","clk":"11540565462","pt":1719495957282,"mc":[{"id":"1.230178309","rc":[{"atb":[[1.88,13.01]],"id":44798446}],"con":true,"img":false}]}
{"op":"mcm","clk":"11540565561","pt":1719495958368,"mc":[{"id":"1.230178309","rc":[{"atb":[[2.24,0]],"id":55829870}],"con":true,"img":false}]}
{"op":"mcm","clk":"11540565575","pt":1719495958477,"mc":[{"id":"1.230178309","rc":[{"atb":[[2.46,2]],"id":55829870}],"con":true,"img":false}]}
{"op":"mcm","clk":"11540565707","pt":1719495959702,"mc":[{"id":"1.230178309","rc":[{"atb":[[2.48,11.38]],"id":40953876},{"atl":[[5.2,7.22]],"id":40953876},{"atb":[[2.48,7.53]],"id":39362025},{"atb":[[2.2,10.27]],"id":48500723},{"atb":[[1.96,6.22]],"id":44798446},{"atb":[[2.64,8.53]],"id":70218235}],"con":true,"img":false}]}
{"op":"mcm","clk":"11540565725","pt":1719495959864,"mc":[{"id":"1.230178309","rc":[{"atb":[[2.46,1]],"id":40953876},{"atb":[[2.44,1]],"id":39362025},{"atb":[[2.18,0.99]],"id":48500723},{"atb":[[1.93,1.44]],"id":44798446},{"atb":[[2.62,1]],"id":70218235}],"con":true,"img":false}]}
{"op":"mcm","clk":"11540565729","pt":1719495959967,"mc":[{"id":"1.230178309","rc":[{"atl":[[5.3,0]],"id":40953876}],"con":true,"img":false}]}
{"op":"mcm","clk":"11540565760","pt":1719495960280,"mc":[{"id":"1.230178309","rc":[{"atb":[[2.46,0]],"id":55829870}],"con":true,"img":false}]}
{"op":"mcm","clk":"11540565771","pt":1719495960384,"mc":[{"id":"1.230178309","rc":[{"atb":[[2.24,2]],"id":55829870}],"con":true,"img":false}]}
{"op":"mcm","clk":"11540565906","pt":1719495961890,"mc":[{"id":"1.230178309","rc":[{"atl":[[4.5,1.95]],"id":48500723}],"con":true,"img":false}]}
{"op":"mcm","clk":"11540565915","pt":1719495962098,"mc":[{"id":"1.230178309","rc":[{"spn":3.84,"spf":"NaN","id":40953876},{"spn":2.48,"spf":1.0,"id":39362025},{"spn":3.1,"spf":"NaN","id":48500723},{"spn":2.55,"spf":"NaN","id":44798446},{"spn":4.02,"spf":"NaN","id":70218235},{"atb":[[2.24,0]],"id":55829870},{"spn":3.7,"spf":"NaN","id":55829870}],"con":true,"img":false}]}
{"op":"mcm","clk":"11540565922","pt":1719495962199,"mc":[{"id":"1.230178309","rc":[{"atb":[[2.46,2]],"id":55829870}],"con":true,"img":false}]}
{"op":"mcm","clk":"11540565930","pt":1719495962302,"mc":[{"id":"1.230178309","rc":[{"atb":[[1.4,0],[2.54,2.11]],"id":40953876},{"atb":[[2.26,2.11],[2.16,0]],"id":48500723}],"con":true,"img":false}]}
{"op":"mcm","clk":"11540565936","pt":1719495962398,"mc":[{"id":"1.230178309","rc":[{"atl":[[5.6,2.5],[5.8,15.73]],"id":40953876}],"con":true,"img":false}]}
{"op":"mcm","clk":"11540565995","pt":1719495963185,"mc":[{"id":"1.230178309","rc":[{"atb":[[2.5,4.78]],"id":55829870}],"con":true,"img":false}]}
{"op":"mcm","clk":"11540566027","pt":1719495963601,"mc":[{"id":"1.230178309","rc":[{"atl":[[4.5,0]],"id":48500723}],"con":true,"img":false}]}
{"op":"mcm","clk":"11540566041","pt":1719495963800,"mc":[{"id":"1.230178309","rc":[{"atb":[[2.2,8.27]],"id":48500723}],"con":true,"img":false}]}
{"op":"mcm","clk":"11540566048","pt":1719495963903,"mc":[{"id":"1.230178309","rc":[{"atb":[[2.28,2]],"id":48500723}],"con":true,"img":false}]}
{"op":"mcm","clk":"11540566077","pt":1719495964175,"mc":[{"id":"1.230178309","rc":[{"atb":[[2.48,9.38]],"id":40953876}],"con":true,"img":false}]}
{"op":"mcm","clk":"11540566084","pt":1719495964275,"mc":[{"id":"1.230178309","rc":[{"atb":[[2.56,2],[2.48,6.38]],"id":40953876},{"atb":[[2.46,0]],"id":39362025},{"atb":[[2.2,6.01]],"id":48500723},{"atb":[[1.94,0]],"id":44798446}],"con":true,"img":false}]}
{"op":"mcm","clk":"11540566101","pt":1719495964481,"mc":[{"id":"1.230178309","rc":[{"atb":[[2.54,5.14]],"id":40953876},{"atb":[[2.5,2.7]],"id":39362025},{"atb":[[1.97,2.74]],"id":44798446}],"con":true,"img":false}]}
{"op":"mcm","clk":"11540566111","pt":1719495964585,"mc":[{"id":"1.230178309","rc":[{"atb":[[2.46,0]],"id":55829870}],"con":true,"img":false}]}
{"op":"mcm","clk":"11540566120","pt":1719495964691,"mc":[{"id":"1.230178309","rc":[{"atb":[[2.52,2]],"id":55829870}],"con":true,"img":false}]}
{"op":"mcm","clk":"11540566156","pt":1719495965100,"mc":[{"id":"1.230178309","rc":[{"atl":[[4.5,5.36]],"id":48500723}],"con":true,"img":false}]}
{"op":"mcm","clk":"11540566211","pt":1719495965610,"mc":[{"id":"1.230178309","rc":[{"atb":[[2.44,7.15],[2.42,2.5]],"id":40953876},{"atb":[[2.6,0],[2.62,18.06]],"id":70218235},{"atb":[[2.46,1],[2.44,0]],"id":55829870}],"con":true,"img":false}]}
{"op":"mcm","clk":"11540566270","pt":1719495966190,"mc":[{"id":"1.230178309","rc":[{"atb":[[1.96,4.22]],"id":44798446}],"con":true,"img":false}]}
{"op":"mcm","clk":"11540566281","pt":1719495966293,"mc":[{"id":"1.230178309","rc":[{"atb":[[1.98,2]],"id":44798446}],"con":true,"img":false}]}
{"op":"mcm","clk":"11540566720","pt":1719495970894,"mc":[{"id":"1.230178309","rc":[{"atl":[[4.3,4.6],[4.5,0],[4.2,1]],"id":48500723},{"atl":[[3.35,1],[3.3,0]],"id":44798446}],"con":true,"img":false}]}
{"op":"mcm","clk":"11540566757","pt":1719495971208,"mc":[{"id":"1.230178309","rc":[{"atl":[[4.5,6.21]],"id":48500723}],"con":true,"img":false}]}
{"op":"mcm","clk":"11540566873","pt":1719495972396,"mc":[{"id":"1.230178309","rc":[{"atb":[[2.56,10.65]],"id":40953876},{"atb":[[2.5,7.9]],"id":39362025},{"atb":[[2.28,5.09]],"id":48500723},{"atb":[[1.98,6.87]],"id":44798446}],"con":true,"img":false}]}
{"op":"mcm","clk":"11540566885","pt":1719495972497,"mc":[{"id":"1.230178309","rc":[{"atb":[[2.48,0]],"id":40953876},{"atb":[[2.48,2.11]],"id":39362025},{"atl":[[5.6,8.83]],"id":39362025},{"atb":[[2.2,0]],"id":48500723},{"atb":[[1.96,0]],"id":44798446},{"atl":[[5.3,6.53]],"id":70218235}],"con":true,"img":false}]}
{"op":"mcm","clk":"11540566894","pt":1719495972606,"mc":[{"id":"1.230178309","rc":[{"atl":[[5.5,4.23],[5.7,0.84],[7,2.5]],"id":39362025},{"atl":[[5.6,0],[5.2,5.61]],"id":70218235}],"con":true,"img":false}]}
{"op":"mcm","clk":"11540566904","pt":1719495972709,"mc":[{"id":"1.230178309","rc":[{"atl":[[5.4,0.84]],"id":70218235}],"con":true,"img":false}]}
{"op":"mcm","clk":"11540566944","pt":1719495973214,"mc":[{"id":"1.230178309","rc":[{"atl":[[5.7,0],[5.4,0.84]],"id":39362025},{"atl":[[5.1,0.84],[5.4,0]],"id":70218235}],"con":true,"img":false}]}
{"op":"mcm","clk":"11540567049","pt":1719495974514,"mc":[{"id":"1.230178309","rc":[{"atb":[[2.54,3.03],[2.62,2.11]],"id":40953876}],"con":true,"img":false}]}
{"op":"mcm","clk":"11540567081","pt":1719495974919,"mc":[{"id":"1.230178309","rc":[{"atb":[[2.56,8.65]],"id":40953876}],"con":true,"img":false}]}
{"op":"mcm","clk":"11540567092","pt":1719495975020,"mc":[{"id":"1.230178309","rc":[{"atb":[[1.02,2]],"id":40953876}],"con":true,"img":false}]}
{"op":"mcm","clk":"11540567168","pt":1719495975913,"mc":[{"id":"1.230178309","rc":[{"atb":[[2.52,6.9]],"id":55829870}],"con":true,"img":false}]}
{"op":"mcm","clk":"11540567183","pt":1719495976118,"mc":[{"id":"1.230178309","rc":[{"atb":[[2.5,1.4]],"id":55829870}],"con":true,"img":false}]}
{"op":"mcm","clk":"11540567255","pt":1719495977205,"mc":[{"id":"1.230178309","rc":[{"atb":[[2.58,29.09]],"id":70218235}],"con":true,"img":false}]}
{"op":"mcm","clk":"11540567266","pt":1719495977311,"mc":[{"id":"1.230178309","rc":[{"atb":[[2.62,1]],"id":70218235}],"con":true,"img":false}]}
{"op":"mcm","clk":"11540567285","pt":1719495977517,"mc":[{"id":"1.230178309","rc":[{"atl":[[4.3,5.6]],"id":48500723},{"atl":[[3.35,0],[3.25,5.6]],"id":44798446}],"con":true,"img":false}]}
{"op":"mcm","clk":"11540567298","pt":1719495977614,"mc":[{"id":"1.230178309","rc":[{"atl":[[4.2,0]],"id":48500723}],"con":true,"img":false}]}
{"op":"mcm","clk":"11540567308","pt":1719495977718,"mc":[{"id":"1.230178309","rc":[{"atl":[[5.6,13.91],[5.5,0]],"id":39362025},{"atl":[[5.3,12.99],[5.2,0]],"id":70218235}],"con":true,"img":false}]}
{"op":"mcm","clk":"11540567363","pt":1719495978189,"mc":[{"id":"1.230178309","rc":[{"atl":[[5.4,0]],"id":39362025},{"atl":[[5.1,0]],"id":70218235}],"con":true,"img":false}]}
{"op":"mcm","clk":"11540567385","pt":1719495978336,"mc":[{"id":"1.230178309","rc":[{"atb":[[2.54,0]],"id":40953876},{"atb":[[1.97,0]],"id":44798446}],"con":true,"img":false}]}
{"op":"mcm","clk":"11540567397","pt":1719495978440,"mc":[{"id":"1.230178309","rc":[{"atb":[[2.62,4.31]],"id":40953876},{"atb":[[1.99,3]],"id":44798446},{"atb":[[2.66,3.2]],"id":70218235},{"atb":[[2.54,2]],"id":55829870}],"con":true,"img":false}]}
{"op":"mcm","clk":"11540567409","pt":1719495978501,"mc":[{"id":"1.230178309","rc":[{"atb":[[2.66,7.48]],"id":70218235}],"con":true,"img":false}]}
{"op":"mcm","clk":"11540567421","pt":1719495978706,"mc":[{"id":"1.230178309","rc":[{"atb":[[2.64,2]],"id":70218235}],"con":true,"img":false}]}
{"op":"mcm","clk":"11540567457","pt":1719495979018,"mc":[{"id":"1.230178309","rc":[{"atl":[[3.45,5.73]],"id":44798446}],"con":true,"img":false}]}
{"op":"mcm","clk":"11540567608","pt":1719495980312,"mc":[{"id":"1.230178309","rc":[{"atb":[[2.64,0]],"id":70218235}],"con":true,"img":false}]}
{"op":"mcm","clk":"11540567622","pt":1719495980421,"mc":[{"id":"1.230178309","rc":[{"atb":[[2.68,2]],"id":70218235}],"con":true,"img":false}]}
{"op":"mcm","clk":"11540567630","pt":1719495980523,"mc":[{"id":"1.230178309","rc":[{"atl":[[5.5,0.84]],"id":39362025},{"atl":[[5.2,0.84]],"id":70218235}],"con":true,"img":false}]}
{"op":"mcm","clk":"11540567671","pt":1719495980927,"mc":[{"id":"1.230178309","rc":[{"atb":[[1.98,4.87]],"id":44798446}],"con":true,"img":false}]}
{"op":"mcm","clk":"11540567684","pt":1719495981030,"mc":[{"id":"1.230178309","rc":[{"atb":[[1.02,2]],"id":44798446}],"con":true,"img":false}]}
{"op":"mcm","clk":"11540567708","pt":1719495981341,"mc":[{"id":"1.230178309","rc":[{"atb":[[2.32,5]],"id":39362025},{"atb":[[2.52,4.9],[2.46,0]],"id":55829870}],"con":true,"img":false}]}
{"op":"mcm","clk":"11540567723","pt":1719495981401,"mc":[{"id":"1.230178309","rc":[{"atb":[[2.56,2],[2.4,1]],"id":55829870}],"con":true,"img":false}]}
{"op":"mcm","clk":"11540567862","pt":1719495982844,"mc":[{"id":"1.230178309","rc":[{"atl":[[5.6,8.83],[5.8,15.76]],"id":39362025},{"atl":[[5.5,14.84]],"id":70218235}],"con":true,"img":false}]}
{"op":"mcm","clk":"11540567873","pt":1719495982902,"mc":[{"id":"1.230178309","rc":[{"atl":[[5.3,6.53]],"id":70218235}],"con":true,"img":false}]}
{"op":"mcm","clk":"11540568030","pt":1719495984508,"mc":[{"id":"1.230178309","rc":[{"atb":[[2.4,0]],"id":55829870}],"con":true,"img":false}]}
{"op":"mcm","clk":"11540568055","pt":1719495984826,"mc":[{"id":"1.230178309","rc":[{"atb":[[2.62,12.97]],"id":40953876},{"atb":[[1.99,8.06]],"id":44798446}],"con":true,"img":false}]}
{"op":"mcm","clk":"11540568064","pt":1719495984923,"mc":[{"id":"1.230178309","rc":[{"atl":[[5.5,8.36]],"id":39362025}],"con":true,"img":false}]}
{"op":"mcm","clk":"11540568074","pt":1719495985020,"mc":[{"id":"1.230178309","rc":[{"atb":[[2.56,0]],"id":40953876},{"atl":[[5.8,1],[5.4,8.83]],"id":39362025},{"atb":[[1.98,0]],"id":44798446},{"atl":[[5.2,7.24]],"id":70218235}],"con":true,"img":false}]}
{"op":"mcm","clk":"11540568085","pt":1719495985125,"mc":[{"id":"1.230178309","rc":[{"atl":[[5.6,0]],"id":39362025},{"atb":[[2.4,1]],"id":55829870}],"con":true,"img":false}]}
{"op":"mcm","clk":"11540568095","pt":1719495985225,"mc":[{"id":"1.230178309","rc":[{"atl":[[5.3,0]],"id":70218235}],"con":true,"img":false}]}
{"op":"mcm","clk":"11540568145","pt":1719495985741,"mc":[{"id":"1.230178309","rc":[{"atl":[[5.8,14.73],[6,6]],"id":40953876},{"atl":[[5.5,13.84],[6,1]],"id":70218235}],"con":true,"img":false}]}
{"op":"mcm","clk":"11540568156","pt":1719495985845,"mc":[{"id":"1.230178309","rc":[{"atb":[[2.44,0],[2.52,25.96]],"id":40953876},{"atb":[[2.42,0],[2.44,11.02]],"id":39362025},{"atl":[[3.45,0],[3.1,1],[3.15,5.24],[3.25,4.6]],"id":44798446},{"atl":[[5.5,0],[5.9,20.41]],"id":70218235}],"con":true,"img":false}]}
{"op":"mcm","clk":"11540568164","pt":1719495985901,"mc":[{"id":"1.230178309","rc":[{"atb":[[2.26,6.32]],"id":48500723},{"atl":[[3.1,4.75],[3.25,0]],"id":44798446},{"atb":[[2.52,8.52]],"id":55829870}],"con":true,"img":false}]}
{"op":"mcm","clk":"11540568175","pt":1719495986008,"mc":[{"id":"1.230178309","rc":[{"atl":[[3.2,0]],"id":44798446}],"con":true,"img":false}]}
{"op":"mcm","clk":"11540568184","pt":1719495986111,"mc":[{"id":"1.230178309","rc":[{"atl":[[3.35,3.36]],"id":44798446}],"con":true,"img":false}]}
{"op":"mcm","clk":"11540568215","pt":1719495986418,"mc":[{"id":"1.230178309","rc":[{"atb":[[2.48,5.89]],"id":39362025},{"atl":[[3.35,0]],"id":44798446}],"con":true,"img":false}]}
{"op":"mcm","clk":"11540568237","pt":1719495986618,"mc":[{"id":"1.230178309","rc":[{"atb":[[2.5,5.5]],"id":40953876},{"atl":[[3.05,0.84]],"id":44798446}],"con":true,"img":false}]}
{"op":"mcm","clk":"11540568245","pt":1719495986723,"mc":[{"id":"1.230178309","rc":[{"atl":[[3.3,6]],"id":44798446}],"con":true,"img":false}]}
{"op":"mcm","clk":"11540568258","pt":1719495986927,"mc":[{"id":"1.230178309","rc":[{"atb":[[1.97,5.42]],"id":44798446}],"con":true,"img":false}]}
{"op":"mcm","clk":"11540568273","pt":1719495987134,"mc":[{"id":"1.230178309","rc":[{"atb":[[2.66,4.28]],"id":70218235},{"atb":[[2.54,0]],"id":55829870}],"con":true,"img":false}]}
{"op":"mcm","clk":"11540568289","pt":1719495987341,"mc":[{"id":"1.230178309","rc":[{"atb":[[2.68,4.83]],"id":70218235},{"atb":[[2.56,4]],"id":55829870}],"con":true,"img":false}]}
{"op":"mcm","clk":"11540568318","pt":1719495987612,"mc":[{"id":"1.230178309","rc":[{"atl":[[5.3,0.84]],"id":39362025}],"con":true,"img":false}]}
{"op":"mcm","clk":"11540568350","pt":1719495987930,"mc":[{"id":"1.230178309","rc":[{"atb":[[2.6,3.44]],"id":40953876}],"con":true,"img":false}]}
{"op":"mcm","clk":"11540568413","pt":1719495988646,"mc":[{"id":"1.230178309","rc":[{"atb":[[2.5,0]],"id":40953876},{"atb":[[1.88,6.73]],"id":44798446}],"con":true,"img":false}]}
{"op":"mcm","clk":"11540568426","pt":1719495988753,"mc":[{"id":"1.230178309","rc":[{"atb":[[2.26,0],[2.34,0],[2.42,0],[2.52,28.46]],"id":40953876},{"atl":[[6.2,0],[5.7,0],[7,0]],"id":48500723},{"atl":[[4.3,0],[5.1,0],[4.7,0]],"id":44798446},{"atl":[[8,0],[7.2,0],[6.4,0],[6.2,2.5]],"id":70218235},{"atb":[[2.06,0],[2.22,5],[2.14,0]],"id":55829870}],"con":true,"img":false}]}
{"op":"mcm","clk":"11540568552","pt":1719495990140,"mc":[{"id":"1.230178309","rc":[{"atl":[[5.5,18.04]],"id":39362025}],"con":true,"img":false}]}
{"op":"mcm","clk":"11540568560","pt":1719495990242,"mc":[{"id":"1.230178309","rc":[{"atl":[[5.4,0]],"id":39362025}],"con":true,"img":false}]}
{"op":"mcm","clk":"11540568605","pt":1719495990717,"mc":[{"id":"1.230178309","rc":[{"atl":[[5.3,0]],"id":39362025}],"con":true,"img":false}]}
{"op":"mcm","clk":"11540568616","pt":1719495990820,"mc":[{"id":"1.230178309","rc":[{"atb":[[2.68,11.66]],"id":70218235}],"con":true,"img":false}]}
{"op":"mcm","clk":"11540568631","pt":1719495991022,"mc":[{"id":"1.230178309","rc":[{"atl":[[3.1,1],[3.15,10.84]],"id":44798446},{"atb":[[2.66,0]],"id":70218235}],"con":true,"img":false}]}
{"op":"mcm","clk":"11540568642","pt":1719495991127,"mc":[{"id":"1.230178309","rc":[{"atb":[[2.52,4.9]],"id":55829870}],"con":true,"img":false}]}
{"op":"mcm","clk":"11540568769","pt":1719495992929,"mc":[{"id":"1.230178309","rc":[{"atb":[[2.6,3.25]],"id":70218235}],"con":true,"img":false}]}
{"op":"mcm","clk":"11540568851","pt":1719495993856,"mc":[{"id":"1.230178309","rc":[{"atb":[[2.56,10.03]],"id":55829870}],"con":true,"img":false}]}
{"op":"mcm","clk":"11540568859","pt":1719495993914,"mc":[{"id":"1.230178309","rc":[{"atl":[[3.3,0]],"id":44798446}],"con":true,"img":false}]}
{"op":"mcm","clk":"11540568869","pt":1719495994018,"mc":[{"id":"1.230178309","rc":[{"atl":[[4.6,5],[5,10],[4.2,2.5]],"id":44798446},{"atb":[[2.52,0]],"id":55829870}],"con":true,"img":false}]}
{"op":"mcm","clk":"11540568878","pt":1719495994125,"mc":[{"id":"1.230178309","rc":[{"atb":[[2.26,2.5]],"id":55829870}],"con":true,"img":false}]}
{"op":"mcm","clk":"11540568927","pt":1719495994642,"mc":[{"id":"1.230178309","rc":[{"atb":[[1.88,0]],"id":44798446}],"con":true,"img":false}]}
{"op":"mcm","clk":"11540568981","pt":1719495995252,"mc":[{"id":"1.230178309","rc":[{"atl":[[7,19.17]],"id":39362025}],"con":true,"img":false}]}
{"op":"mcm","clk":"11540568988","pt":1719495995355,"mc":[{"id":"1.230178309","rc":[{"atl":[[5.5,8.36]],"id":39362025}],"con":true,"img":false}]}
{"op":"mcm","clk":"11540569026","pt":1719495995728,"mc":[{"id":"1.230178309","rc":[{"atb":[[2.68,8.83]],"id":70218235},{"atb":[[2.56,8.03]],"id":55829870}],"con":true,"img":false}]}
{"op":"mcm","clk":"11540569036","pt":1719495995830,"mc":[{"id":"1.230178309","rc":[{"atb":[[2.7,2]],"id":70218235},{"atb":[[2.58,2]],"id":55829870}],"con":true,"img":false}]}
{"op":"mcm","clk":"11540569054","pt":1719495996032,"mc":[{"id":"1.230178309","rc":[{"atb":[[2.6,0]],"id":70218235}],"con":true,"img":false}]}
{"op":"mcm","clk":"11540569154","pt":1719495997125,"mc":[{"id":"1.230178309","rc":[{"atb":[[2.68,6.83]],"id":70218235}],"con":true,"img":false}]}
{"op":"mcm","clk":"11540569164","pt":1719495997224,"mc":[{"id":"1.230178309","rc":[{"atb":[[2.72,2]],"id":70218235}],"con":true,"img":false}]}
{"op":"mcm","clk":"11540569181","pt":1719495997530,"mc":[{"id":"1.230178309","rc":[{"atb":[[2.56,6.03]],"id":55829870}],"con":true,"img":false}]}
{"op":"mcm","clk":"11540569188","pt":1719495997633,"mc":[{"id":"1.230178309","rc":[{"atb":[[2.6,2]],"id":55829870}],"con":true,"img":false}]}
{"op":"mcm","clk":"11540569223","pt":1719495998099,"mc":[{"id":"1.230178309","rc":[{"atl":[[3.05,6.5]],"id":44798446}],"con":true,"img":false}]}
{"op":"mcm","clk":"11540569233","pt":1719495998252,"mc":[{"id":"1.230178309","rc":[{"atl":[[3.15,6.44]],"id":44798446}],"con":true,"img":false}]}
{"op":"mcm","clk":"11540569257","pt":1719495998557,"mc":[{"id":"1.230178309","rc":[{"atl":[[3.15,5.6]],"id":44798446}],"con":true,"img":false}]}
{"op":"mcm","clk":"11540569313","pt":1719495999231,"mc":[{"id":"1.230178309","rc":[{"atb":[[2.48,2.11]],"id":39362025},{"atl":[[3.2,1],[3.1,0]],"id":44798446},{"atb":[[2.56,0]],"id":55829870}],"con":true,"img":false}]}
{"op":"mcm","clk":"11540569620","pt":1719496003048,"mc":[{"id":"1.230178309","rc":[{"atb":[[2.72,8.62]],"id":70218235}],"con":true,"img":false}]}
{"op":"mcm","clk":"11540569629","pt":1719496003155,"mc":[{"id":"1.230178309","rc":[{"atb":[[2.68,0]],"id":70218235}],"con":true,"img":false}]}
{"op":"mcm","clk":"11540569714","pt":1719496004340,"mc":[{"id":"1.230178309","rc":[{"atb":[[2.54,16.42],[2.52,2.5]],"id":40953876},{"atl":[[3.2,0],[3.15,6.6]],"id":44798446}],"con":true,"img":false}]}
{"op":"mcm","clk":"11540569723","pt":1719496004442,"mc":[{"id":"1.230178309","rc":[{"atb":[[2.6,0]],"id":40953876},{"atl":[[3.2,13.11]],"id":44798446}],"con":true,"img":false}]}
{"op":"mcm","clk":"11540569731","pt":1719496004546,"mc":[{"id":"1.230178309","rc":[{"atl":[[3.15,1]],"id":44798446}],"con":true,"img":false}]}
{"op":"mcm","clk":"11540569756","pt":1719496004854,"mc":[{"id":"1.230178309","rc":[{"atb":[[2.62,10.77]],"id":40953876},{"atb":[[2.7,0]],"id":70218235}],"con":true,"img":false}]}
{"op":"mcm","clk":"11540569764","pt":1719496004957,"mc":[{"id":"1.230178309","rc":[{"atb":[[2.64,3]],"id":40953876},{"atb":[[2.74,3]],"id":70218235}],"con":true,"img":false}]}
{"op":"mcm","clk":"11540569771","pt":1719496005061,"mc":[{"id":"1.230178309","rc":[{"atb":[[2.64,16.51]],"id":40953876}],"con":true,"img":false}]}
{"op":"mcm","clk":"11540569778","pt":1719496005163,"mc":[{"id":"1.230178309","rc":[{"atb":[[2.62,2.11]],"id":40953876}],"con":true,"img":false}]}
{"op":"mcm","clk":"11540569921","pt":1719496006656,"mc":[{"id":"1.230178309","rc":[{"atb":[[2.72,6.62]],"id":70218235}],"con":true,"img":false}]}
{"op":"mcm","clk":"11540569931","pt":1719496006760,"mc":[{"id":"1.230178309","rc":[{"atb":[[2.76,2]],"id":70218235}],"con":true,"img":false}]}
{"op":"mcm","clk":"11540569989","pt":1719496007538,"mc":[{"id":"1.230178309","rc":[{"atb":[[1.7,0]],"id":48500723}],"con":true,"img":false}]}
{"op":"mcm","clk":"11540570064","pt":1719496008359,"mc":[{"id":"1.230178309","rc":[{"atl":[[6.2,1]],"id":40953876},{"atl":[[5.9,1]],"id":39362025}],"con":true,"img":false}]}
{"op":"mcm","clk":"11540570074","pt":1719496008461,"mc":[{"id":"1.230178309","rc":[{"atb":[[2.32,0]],"id":40953876},{"atl":[[6,5]],"id":40953876},{"atl":[[5.8,0],[7,2.5]],"id":39362025},{"atb":[[2.26,2.11],[1.66,0]],"id":48500723},{"atl":[[6.4,0]],"id":55829870}],"con":true,"img":false}]}
{"op":"mcm","clk":"11540570087","pt":1719496008565,"mc":[{"id":"1.230178309","rc":[{"atl":[[5.8,16.74]],"id":39362025}],"con":true,"img":false}]}
{"op":"mcm","clk":"11540570096","pt":1719496008669,"mc":[{"id":"1.230178309","rc":[{"atl":[[5.8,0],[5.9,17.74]],"id":39362025}],"con":true,"img":false}]}
{"op":"mcm","clk":"11540570104","pt":1719496008770,"mc":[{"id":"1.230178309","rc":[{"atl":[[7,19.17],[5.9,1]],"id":39362025}],"con":true,"img":false}]}
{"op":"mcm","clk":"11540570140","pt":1719496009037,"mc":[{"id":"1.230178309","rc":[{"atb":[[2.48,5.89]],"id":39362025}],"con":true,"img":false}]}
{"op":"mcm","clk":"11540570198","pt":1719496009647,"mc":[{"id":"1.230178309","rc":[{"atb":[[2.54,3.58]],"id":55829870}],"con":true,"img":false}]}
{"op":"mcm","clk":"11540570250","pt":1719496010164,"mc":[{"id":"1.230178309","rc":[{"atl":[[3.1,1],[3.15,0]],"id":44798446},{"atl":[[7,1]],"id":55829870}],"con":true,"img":false}]}
{"op":"mcm","clk":"11540570259","pt":1719496010269,"mc":[{"id":"1.230178309","rc":[{"atb":[[2.48,2.11]],"id":39362025}],"con":true,"img":false}]}
{"op":"mcm","clk":"11540570294","pt":1719496010633,"mc":[{"id":"1.230178309","rc":[{"atb":[[2.26,6.32]],"id":48500723}],"con":true,"img":false}]}
{"op":"mcm","clk":"11540570373","pt":1719496011555,"mc":[{"id":"1.230178309","rc":[{"atb":[[2.62,5.51]],"id":40953876}],"con":true,"img":false}]}
{"op":"mcm","clk":"11540570545","pt":1719496013776,"mc":[{"id":"1.230178309","rc":[{"atb":[[2.74,0]],"id":70218235},{"atb":[[2.58,0]],"id":55829870}],"con":true,"img":false}]}
{"op":"mcm","clk":"11540570555","pt":1719496013878,"mc":[{"id":"1.230178309","rc":[{"atb":[[2.76,4.56]],"id":70218235},{"atb":[[2.6,4.8]],"id":55829870}],"con":true,"img":false}]}
{"op":"mcm","clk":"11540570623","pt":1719496014858,"mc":[{"id":"1.230178309","rc":[{"atb":[[2.76,12.94]],"id":70218235}],"con":true,"img":false}]}
{"op":"mcm","clk":"11540570632","pt":1719496014961,"mc":[{"id":"1.230178309","rc":[{"atb":[[2.72,0]],"id":70218235}],"con":true,"img":false}]}
{"op":"mcm","clk":"11540570749","pt":1719496016456,"mc":[{"id":"1.230178309","rc":[{"atl":[[6.8,2.5],[7.6,5]],"id":39362025}],"con":true,"img":false}]}
{"op":"mcm","clk":"11540570757","pt":1719496016560,"mc":[{"id":"1.230178309","rc":[{"atb":[[2.54,0],[2.52,35.34]],"id":40953876},{"atb":[[2.42,15.8],[2.44,1]],"id":39362025},{"atl":[[8.6,0],[7,0],[7.8,0],[6.6,9.37]],"id":39362025},{"atl":[[4.5,0]],"id":48500723},{"atb":[[2.54,0],[2.3,4.98],[2.22,0],[2.6,10.52]],"id":55829870}],"con":true,"img":false}]}
{"op":"mcm","clk":"11540570767","pt":1719496016663,"mc":[{"id":"1.230178309","rc":[{"atl":[[5.5,2.5],[6.6,10],[5.9,5]],"id":48500723}],"con":true,"img":false}]}
{"op":"mcm","clk":"11540571145","pt":1719496021294,"mc":[{"id":"1.230178309","rc":[{"atb":[[1.69,0]],"id":44798446}],"con":true,"img":false}]}
{"op":"mcm","clk":"11540571240","pt":1719496022279,"mc":[{"id":"1.230178309","rc":[{"spn":3.92,"spf":"NaN","id":40953876},{"spn":2.5,"spf":1.0,"id":39362025},{"spn":3.14,"spf":"NaN","id":48500723},{"spn":2.52,"spf":"NaN","id":44798446},{"spn":3.98,"spf":"NaN","id":70218235},{"atb":[[2.6,7.72]],"id":55829870},{"spn":3.75,"spf":"NaN","id":55829870}],"con":true,"img":false}]}
{"op":"mcm","clk":"11540571249","pt":1719496022383,"mc":[{"id":"1.230178309","rc":[{"atb":[[2.62,2.9]],"id":55829870}],"con":true,"img":false}]}
{"op":"mcm","clk":"11540571366","pt":1719496023780,"mc":[{"id":"1.230178309","rc":[{"atb":[[2.62,2.11]],"id":40953876},{"atb":[[2.6,5.72]],"id":55829870}],"con":true,"img":false}]}
{"op":"mcm","clk":"11540571373","pt":1719496023883,"mc":[{"id":"1.230178309","rc":[{"atb":[[2.26,2.11]],"id":48500723},{"atb":[[2.64,2]],"id":55829870}],"con":true,"img":false}]}
{"op":"mcm","clk":"11540571388","pt":1719496024091,"mc":[{"id":"1.230178309","rc":[{"atl":[[4.5,6.23]],"id":48500723}],"con":true,"img":false}]}
{"op":"mcm","clk":"11540571404","pt":1719496024258,"mc":[{"id":"1.230178309","rc":[{"atb":[[1.97,0]],"id":44798446}],"con":true,"img":false}]}
{"op":"mcm","clk":"11540571487","pt":1719496025287,"mc":[{"id":"1.230178309","rc":[{"atl":[[4.5,0]],"id":48500723}],"con":true,"img":false}]}
{"op":"mcm","clk":"11540571505","pt":1719496025494,"mc":[{"id":"1.230178309","rc":[{"atl":[[4.4,1.54]],"id":48500723}],"con":true,"img":false}]}
{"op":"mcm","clk":"11540571590","pt":1719496026376,"mc":[{"id":"1.230178309","rc":[{"atb":[[1.97,5.42]],"id":44798446}],"con":true,"img":false}]}
{"op":"mcm","clk":"11540571762","pt":1719496028189,"mc":[{"id":"1.230178309","rc":[{"atb":[[2.64,7.2]],"id":55829870}],"con":true,"img":false}]}
{"op":"mcm","clk":"11540571774","pt":1719496028293,"mc":[{"id":"1.230178309","rc":[{"atb":[[2.6,0]],"id":55829870}],"con":true,"img":false}]}
{"op":"mcm","clk":"11540571879","pt":1719496029383,"mc":[{"id":"1.230178309","rc":[{"atl":[[4.4,0]],"id":48500723}],"con":true,"img":false}]}
{"op":"mcm","clk":"11540571910","pt":1719496029797,"mc":[{"id":"1.230178309","rc":[{"atl":[[4.5,6.66]],"id":48500723}],"con":true,"img":false}]}
{"op":"mcm","clk":"11540571970","pt":1719496030383,"mc":[{"id":"1.230178309","rc":[{"atl":[[6.2,0],[5.9,1]],"id":40953876},{"atb":[[2.32,6]],"id":39362025},{"atl":[[4.5,0],[4.2,1]],"id":48500723},{"atl":[[5.6,1],[6,0]],"id":70218235},{"atb":[[2.4,0],[2.46,1]],"id":55829870}],"con":true,"img":false}]}
{"op":"mcm","clk":"11540571983","pt":1719496030474,"mc":[{"id":"1.230178309","rc":[{"atl":[[4.3,4.6]],"id":48500723}],"con":true,"img":false}]}
{"op":"mcm","clk":"11540571997","pt":1719496030580,"mc":[{"id":"1.230178309","rc":[{"atl":[[4.5,6.92]],"id":48500723}],"con":true,"img":false}]}
{"op":"mcm","clk":"11540572047","pt":1719496031096,"mc":[{"id":"1.230178309","rc":[{"atb":[[2.62,0]],"id":55829870}],"con":true,"img":false}]}
{"op":"mcm","clk":"11540572067","pt":1719496031302,"mc":[{"id":"1.230178309","rc":[{"atb":[[2.66,3]],"id":55829870}],"con":true,"img":false}]}
{"op":"mcm","clk":"11540572098","pt":1719496031672,"mc":[{"id":"1.230178309","rc":[{"atb":[[2.42,19.71]],"id":39362025},{"atb":[[1.45,0]],"id":44798446}],"con":true,"img":false}]}
{"op":"mcm","clk":"11540572139","pt":1719496032185,"mc":[{"id":"1.230178309","rc":[{"atb":[[2.62,3.4]],"id":55829870}],"con":true,"img":false}]}
{"op":"mcm","clk":"11540572209","pt":1719496032977,"mc":[{"id":"1.230178309","rc":[{"atl":[[4.5,0]],"id":48500723}],"con":true,"img":false}]}
{"op":"mcm","clk":"11540572228","pt":1719496033182,"mc":[{"id":"1.230178309","rc":[{"atb":[[2.24,3.9]],"id":48500723},{"atl":[[4.4,1.68]],"id":48500723}],"con":true,"img":false}]}
{"op":"mcm","clk":"11540572298","pt":1719496034004,"mc":[{"id":"1.230178309","rc":[{"atl":[[4.4,0]],"id":48500723}],"con":true,"img":false}]}
{"op":"mcm","clk":"11540572308","pt":1719496034067,"mc":[{"id":"1.230178309","rc":[{"atb":[[2.6,3.42]],"id":40953876}],"con":true,"img":false}]}
{"op":"mcm","clk":"11540572318","pt":1719496034170,"mc":[{"id":"1.230178309","rc":[{"atl":[[4.5,5.98]],"id":48500723}],"con":true,"img":false}]}
{"op":"mcm","clk":"11540572361","pt":1719496034579,"mc":[{"id":"1.230178309","rc":[{"atb":[[2.64,5.2]],"id":55829870}],"con":true,"img":false}]}
{"op":"mcm","clk":"11540572373","pt":1719496034683,"mc":[{"id":"1.230178309","rc":[{"atb":[[2.68,2]],"id":55829870}],"con":true,"img":false}]}
{"op":"mcm","clk":"11540572853","pt":1719496039915,"mc":[{"id":"1.230178309","rc":[{"atl":[[4.5,0]],"id":48500723}],"con":true,"img":false}]}
{"op":"mcm","clk":"11540572867","pt":1719496039977,"mc":[{"id":"1.230178309","rc":[{"atb":[[2.66,0]],"id":55829870}],"con":true,"img":false}]}
{"op":"mcm","clk":"11540572876","pt":1719496040082,"mc":[{"id":"1.230178309","rc":[{"atb":[[2.68,4]],"id":55829870}],"con":true,"img":false}]}
{"op":"mcm","clk":"11540572885","pt":1719496040186,"mc":[{"id":"1.230178309","rc":[{"atl":[[4.4,1.68]],"id":48500723}],"con":true,"img":false}]}
{"op":"mcm","clk":"11540572949","pt":1719496040898,"mc":[{"id":"1.230178309","rc":[{"atl":[[4.4,0]],"id":48500723}],"con":true,"img":false}]}
{"op":"mcm","clk":"11540572982","pt":1719496041210,"mc":[{"id":"1.230178309","rc":[{"atl":[[4.5,5.98]],"id":48500723}],"con":true,"img":false}]}
{"op":"mcm","clk":"11540573462","pt":1719496046599,"mc":[{"id":"1.230178309","rc":[{"atb":[[2.26,0]],"id":55829870}],"con":true,"img":false}]}
{"op":"mcm","clk":"11540573536","pt":1719496047488,"mc":[{"id":"1.230178309","rc":[{"atl":[[4.5,0]],"id":48500723}],"con":true,"img":false}]}
{"op":"mcm","clk":"11540573562","pt":1719496047797,"mc":[{"id":"1.230178309","rc":[{"atl":[[4.4,1.68]],"id":48500723}],"con":true,"img":false}]}
{"op":"mcm","clk":"11540573616","pt":1719496048516,"mc":[{"id":"1.230178309","rc":[{"atl":[[4.4,0]],"id":48500723}],"con":true,"img":false}]}
{"op":"mcm","clk":"11540573630","pt":1719496048706,"mc":[{"id":"1.230178309","rc":[{"atb":[[2.76,10.38]],"id":70218235}],"con":true,"img":false}]}
{"op":"mcm","clk":"11540573636","pt":1719496048789,"mc":[{"id":"1.230178309","rc":[{"atl":[[4.5,5.98]],"id":48500723},{"atb":[[2.78,3]],"id":70218235}],"con":true,"img":false}]}
{"op":"mcm","clk":"11540573640","pt":1719496048897,"mc":[{"id":"1.230178309","rc":[{"atb":[[2.78,10.69]],"id":70218235}],"con":true,"img":false}]}
{"op":"mcm","clk":"11540573650","pt":1719496049096,"mc":[{"id":"1.230178309","rc":[{"atb":[[2.76,1.99]],"id":70218235}],"con":true,"img":false}]}
{"op":"mcm","clk":"11540573680","pt":1719496049409,"mc":[{"id":"1.230178309","rc":[{"atb":[[2.76,0]],"id":70218235}],"con":true,"img":false}]}
{"op":"mcm","clk":"11540573689","pt":1719496049511,"mc":[{"id":"1.230178309","rc":[{"atb":[[2.8,2]],"id":70218235}],"con":true,"img":false}]}
{"op":"mcm","clk":"11540574069","pt":1719496053723,"mc":[{"id":"1.230178309","rc":[{"atl":[[4.3,5.6],[4.2,0]],"id":48500723},{"atl":[[3.1,0],[3.15,1]],"id":44798446}],"con":true,"img":false}]}
{"op":"mcm","clk":"11540574080","pt":1719496053818,"mc":[{"id":"1.230178309","rc":[{"atb":[[2.6,0]],"id":40953876}],"con":true,"img":false}]}
{"op":"mcm","clk":"11540574131","pt":1719496054293,"mc":[{"id":"1.230178309","rc":[{"atb":[[2.6,3.42]],"id":40953876},{"atl":[[4.5,0]],"id":48500723}],"con":true,"img":false}]}
{"op":"mcm","clk":"11540574156","pt":1719496054612,"mc":[{"id":"1.230178309","rc":[{"atl":[[4.4,1.68]],"id":48500723}],"con":true,"img":false}]}
{"op":"mcm","clk":"11540574227","pt":1719496055428,"mc":[{"id":"1.230178309","rc":[{"atl":[[4.4,0]],"id":48500723}],"con":true,"img":false}]}
{"op":"mcm","clk":"11540574248","pt":1719496055595,"mc":[{"id":"1.230178309","rc":[{"atl":[[4.5,6.92]],"id":48500723}],"con":true,"img":false}]}
{"op":"mcm","clk":"11540574439","pt":1719496057405,"mc":[{"id":"1.230178309","rc":[{"atb":[[2.78,7.69]],"id":70218235}],"con":true,"img":false}]}
{"op":"mcm","clk":"11540574458","pt":1719496057615,"mc":[{"id":"1.230178309","rc":[{"atb":[[2.8,4.71]],"id":70218235}],"con":true,"img":false}]}
{"op":"mcm","clk":"11540574656","pt":1719496059827,"mc":[{"id":"1.230178309","rc":[{"atb":[[2.8,13.68]],"id":70218235}],"con":true,"img":false}]}
{"op":"mcm","clk":"11540574675","pt":1719496060033,"mc":[{"id":"1.230178309","rc":[{"atb":[[2.78,0]],"id":70218235}],"con":true,"img":false}]}
{"op":"mcm","clk":"11540574868","pt":1719496061808,"mc":[{"id":"1.230178309","rc":[{"atl":[[4.3,4.6],[4.5,0],[4.2,1]],"id":48500723},{"atl":[[3.1,1]],"id":44798446}],"con":true,"img":false}]}
{"op":"mcm","clk":"11540574881","pt":1719496061911,"mc":[{"id":"1.230178309","rc":[{"atl":[[4.3,0],[4.1,7.5]],"id":48500723},{"atl":[[3.15,0]],"id":44798446}],"con":true,"img":false}]}
{"op":"mcm","clk":"11540574895","pt":1719496062014,"mc":[{"id":"1.230178309","rc":[{"atl":[[4.1,3.75],[4.4,1.68],[4.2,5.6]],"id":48500723}],"con":true,"img":false}]}
{"op":"mcm","clk":"11540574976","pt":1719496062946,"mc":[{"id":"1.230178309","rc":[{"atl":[[4.4,0]],"id":48500723}],"con":true,"img":false}]}
{"op":"mcm","clk":"11540575004","pt":1719496063210,"mc":[{"id":"1.230178309","rc":[{"atl":[[4.5,6.92]],"id":48500723}],"con":true,"img":false}]}
{"op":"mcm","clk":"11540575300","pt":1719496066214,"mc":[{"id":"1.230178309","rc":[{"atb":[[2.8,10.97]],"id":70218235}],"con":true,"img":false}]}
{"op":"mcm","clk":"11540575312","pt":1719496066319,"mc":[{"id":"1.230178309","rc":[{"atb":[[2.82,3.16]],"id":70218235}],"con":true,"img":false}]}
{"op":"mcm","clk":"11540575339","pt":1719496066528,"mc":[{"id":"1.230178309","rc":[{"atb":[[2.62,0]],"id":70218235}],"con":true,"img":false}]}
{"op":"mcm","clk":"11540575441","pt":1719496067710,"mc":[{"id":"1.230178309","rc":[{"atb":[[2.8,8.97]],"id":70218235}],"con":true,"img":false}]}
{"op":"mcm","clk":"11540575452","pt":1719496067814,"mc":[{"id":"1.230178309","rc":[{"atb":[[2.84,2]],"id":70218235}],"con":true,"img":false}]}
{"op":"mcm","clk":"11540575553","pt":1719496068944,"mc":[{"id":"1.230178309","rc":[{"atl":[[4.5,0]],"id":48500723}],"con":true,"img":false}]}
{"op":"mcm","clk":"11540575570","pt":1719496069113,"mc":[{"id":"1.230178309","rc":[{"atl":[[4.4,1.68]],"id":48500723}],"con":true,"img":false}]}
{"op":"mcm","clk":"11540575646","pt":1719496069931,"mc":[{"id":"1.230178309","rc":[{"atl":[[4.4,0]],"id":48500723}],"con":true,"img":false}]}
{"op":"mcm","clk":"11540575667","pt":1719496070135,"mc":[{"id":"1.230178309","rc":[{"atl":[[4.5,5.98]],"id":48500723}],"con":true,"img":false}]}
{"op":"mcm","clk":"11540575706","pt":1719496070543,"mc":[{"id":"1.230178309","rc":[{"atb":[[2.84,9.81]],"id":70218235}],"con":true,"img":false}]}
{"op":"mcm","clk":"11540575727","pt":1719496070751,"mc":[{"id":"1.230178309","rc":[{"atb":[[2.8,0]],"id":70218235}],"con":true,"img":false}]}
{"op":"mcm","clk":"11540576036","pt":1719496074140,"mc":[{"id":"1.230178309","rc":[{"atl":[[4.3,1],[4.2,4.6]],"id":48500723},{"atl":[[3.1,0],[3.15,1]],"id":44798446}],"con":true,"img":false}]}
{"op":"mcm","clk":"11540576147","pt":1719496075334,"mc":[{"id":"1.230178309","rc":[{"atb":[[2.82,0]],"id":70218235}],"con":true,"img":false}]}
{"op":"mcm","clk":"11540576158","pt":1719496075440,"mc":[{"id":"1.230178309","rc":[{"atb":[[2.86,2.36]],"id":70218235}],"con":true,"img":false}]}
{"op":"mcm","clk":"11540576254","pt":1719496076329,"mc":[{"id":"1.230178309","rc":[{"atb":[[2.84,7.81]],"id":70218235}],"con":true,"img":false}]}
{"op":"mcm","clk":"11540576268","pt":1719496076430,"mc":[{"id":"1.230178309","rc":[{"atl":[[4.5,0]],"id":48500723},{"atb":[[2.88,2]],"id":70218235}],"con":true,"img":false}]}
{"op":"mcm","clk":"11540576306","pt":1719496076743,"mc":[{"id":"1.230178309","rc":[{"atl":[[4.4,1.68]],"id":48500723}],"con":true,"img":false}]}
{"op":"mcm","clk":"11540576380","pt":1719496077462,"mc":[{"id":"1.230178309","rc":[{"atl":[[4.4,0]],"id":48500723}],"con":true,"img":false}]}
{"op":"mcm","clk":"11540576410","pt":1719496077745,"mc":[{"id":"1.230178309","rc":[{"atl":[[4.5,6.82]],"id":48500723}],"con":true,"img":false}]}
{"op":"mcm","clk":"11540576758","pt":1719496081053,"mc":[{"id":"1.230178309","rc":[{"atb":[[2.88,9.21]],"id":70218235}],"con":true,"img":false}]}
{"op":"mcm","clk":"11540576780","pt":1719496081253,"mc":[{"id":"1.230178309","rc":[{"atb":[[2.84,0]],"id":70218235}],"con":true,"img":false}]}
{"op":"mcm","clk":"11540577005","pt":1719496083343,"mc":[{"id":"1.230178309","rc":[{"atl":[[4.5,0]],"id":48500723},{"spn":4.04,"spf":"NaN","id":70218235},{"spn":3.79,"spf":"NaN","id":55829870}],"con":true,"img":false}]}
{"op":"mcm","clk":"11540577025","pt":1719496083547,"mc":[{"id":"1.230178309","rc":[{"atl":[[4.4,1.68]],"id":48500723}],"con":true,"img":false}]}
{"op":"mcm","clk":"11540577066","pt":1719496083960,"mc":[{"id":"1.230178309","rc":[{"atb":[[2.86,0]],"id":70218235}],"con":true,"img":false}]}
{"op":"mcm","clk":"11540577095","pt":1719496084127,"mc":[{"id":"1.230178309","rc":[{"atb":[[2.9,3.39]],"id":70218235}],"con":true,"img":false}]}
{"op":"mcm","clk":"11540577130","pt":1719496084437,"mc":[{"id":"1.230178309","rc":[{"atl":[[4.4,0]],"id":48500723}],"con":true,"img":false}]}
{"op":"mcm","clk":"11540577153","pt":1719496084762,"mc":[{"id":"1.230178309","rc":[{"atl":[[4.5,6.82]],"id":48500723}],"con":true,"img":false}]}
{"op":"mcm","clk":"11540577164","pt":1719496084854,"mc":[{"id":"1.230178309","rc":[{"atb":[[2.88,7.21]],"id":70218235}],"con":true,"img":false}]}
{"op":"mcm","clk":"11540577180","pt":1719496084958,"mc":[{"id":"1.230178309","rc":[{"atb":[[2.92,2]],"id":70218235}],"con":true,"img":false}]}
{"op":"mcm","clk":"11540577739","pt":1719496090351,"mc":[{"id":"1.230178309","rc":[{"atl":[[4.3,0],[4.5,0],[4.2,5.6]],"id":48500723},{"atl":[[3.1,1]],"id":44798446}],"con":true,"img":false}]}
{"op":"mcm","clk":"11540577750","pt":1719496090455,"mc":[{"id":"1.230178309","rc":[{"atl":[[3.15,0]],"id":44798446}],"con":true,"img":false}]}
{"op":"mcm","clk":"11540577772","pt":1719496090663,"mc":[{"id":"1.230178309","rc":[{"atl":[[4.4,1.68]],"id":48500723}],"con":true,"img":false}]}
{"op":"mcm","clk":"11540577845","pt":1719496091349,"mc":[{"id":"1.230178309","rc":[{"atb":[[2.92,9.95]],"id":70218235}],"con":true,"img":false}]}
{"op":"mcm","clk":"11540577860","pt":1719496091552,"mc":[{"id":"1.230178309","rc":[{"atl":[[4.4,0]],"id":48500723},{"atb":[[2.88,0]],"id":70218235}],"con":true,"img":false}]}
{"op":"mcm","clk":"11540577893","pt":1719496091854,"mc":[{"id":"1.230178309","rc":[{"atl":[[4.5,6.82]],"id":48500723}],"con":true,"img":false}]}
{"op":"mcm","clk":"11540578001","pt":1719496092951,"mc":[{"id":"1.230178309","rc":[{"atb":[[2.9,0]],"id":70218235}],"con":true,"img":false}]}
{"op":"mcm","clk":"11540578013","pt":1719496093052,"mc":[{"id":"1.230178309","rc":[{"atb":[[2.3,2]],"id":48500723},{"atl":[[4.5,0]],"id":48500723},{"atb":[[2.94,3]],"id":70218235}],"con":true,"img":false}]}
{"op":"mcm","clk":"11540578022","pt":1719496093164,"mc":[{"id":"1.230178309","rc":[{"atb":[[2.3,6.4]],"id":48500723}],"con":true,"img":false}]}
{"op":"mcm","clk":"11540578047","pt":1719496093362,"mc":[{"id":"1.230178309","rc":[{"atb":[[2.28,2]],"id":48500723}],"con":true,"img":false}]}
{"op":"mcm","clk":"11540578113","pt":1719496093941,"mc":[{"id":"1.230178309","rc":[{"atb":[[2.24,0]],"id":48500723},{"atb":[[2.92,7.95]],"id":70218235}],"con":true,"img":false}]}
{"op":"mcm","clk":"11540578119","pt":1719496094042,"mc":[{"id":"1.230178309","rc":[{"atb":[[2.96,2]],"id":70218235}],"con":true,"img":false}]}
{"op":"mcm","clk":"11540578166","pt":1719496094551,"mc":[{"id":"1.230178309","rc":[{"atb":[[2.28,0]],"id":48500723}],"con":true,"img":false}]}
{"op":"mcm","clk":"11540578178","pt":1719496094659,"mc":[{"id":"1.230178309","rc":[{"atb":[[2.32,2]],"id":48500723},{"atl":[[5.8,4.93]],"id":70218235}],"con":true,"img":false}]}
{"op":"mcm","clk":"11540578184","pt":1719496094757,"mc":[{"id":"1.230178309","rc":[{"atl":[[5.7,8.25],[5.9,0]],"id":70218235}],"con":true,"img":false}]}
{"op":"mcm","clk":"11540578210","pt":1719496095188,"mc":[{"id":"1.230178309","rc":[{"atb":[[2.26,6.29]],"id":48500723}],"con":true,"img":false}]}
{"op":"mcm","clk":"11540578493","pt":1719496097862,"mc":[{"id":"1.230178309","rc":[{"atl":[[4.4,1.71]],"id":48500723}],"con":true,"img":false}]}
{"op":"mcm","clk":"11540578586","pt":1719496098851,"mc":[{"id":"1.230178309","rc":[{"atl":[[4.4,0]],"id":48500723}],"con":true,"img":false}]}
{"op":"mcm","clk":"11540578722","pt":1719496100242,"mc":[{"id":"1.230178309","rc":[{"atl":[[4.4,2.09]],"id":48500723},{"atl":[[5.4,6.95]],"id":55829870}],"con":true,"img":false}]}
{"op":"mcm","clk":"11540578779","pt":1719496100859,"mc":[{"id":"1.230178309","rc":[{"atl":[[4.4,0]],"id":48500723}],"con":true,"img":false}]}
{"op":"mcm","clk":"11540578787","pt":1719496100963,"mc":[{"id":"1.230178309","rc":[{"atb":[[2.26,2.11]],"id":48500723},{"atl":[[5.5,0],[6.6,0],[5.9,0],[5.4,2.5]],"id":48500723},{"atl":[[3.1,0],[3.15,1]],"id":44798446}],"con":true,"img":false}]}
{"op":"mcm","clk":"11540578797","pt":1719496101063,"mc":[{"id":"1.230178309","rc":[{"atl":[[4.3,4.22]],"id":48500723}],"con":true,"img":false}]}
{"op":"mcm","clk":"11540578838","pt":1719496101440,"mc":[{"id":"1.230178309","rc":[{"atb":[[2.96,9.69]],"id":70218235}],"con":true,"img":false}]}
{"op":"mcm","clk":"11540578858","pt":1719496101646,"mc":[{"id":"1.230178309","rc":[{"atb":[[2.3,4.4]],"id":48500723},{"atb":[[2.92,0],[2.94,0]],"id":70218235}],"con":true,"img":false}]}
{"op":"mcm","clk":"11540578870","pt":1719496101750,"mc":[{"id":"1.230178309","rc":[{"atl":[[4.3,0]],"id":48500723},{"atb":[[2.96,12.69]],"id":70218235}],"con":true,"img":false}]}
{"op":"mcm","clk":"11540578898","pt":1719496102064,"mc":[{"id":"1.230178309","rc":[{"atl":[[4.2,7.27]],"id":48500723}],"con":true,"img":false}]}
{"op":"mcm","clk":"11540578932","pt":1719496102431,"mc":[{"id":"1.230178309","rc":[{"atl":[[4.2,5.6]],"id":48500723}],"con":true,"img":false}]}
{"op":"mcm","clk":"11540578949","pt":1719496102633,"mc":[{"id":"1.230178309","rc":[{"atl":[[4.3,6.57]],"id":48500723}],"con":true,"img":false}]}
{"op":"mcm","clk":"11540578976","pt":1719496102949,"mc":[{"id":"1.230178309","rc":[{"atl":[[4.3,0]],"id":48500723}],"con":true,"img":false}]}
{"op":"mcm","clk":"11540579003","pt":1719496103251,"mc":[{"id":"1.230178309","rc":[{"atb":[[2.32,6.4]],"id":48500723},{"atl":[[4.2,8.42]],"id":48500723}],"con":true,"img":false}]}
{"op":"mcm","clk":"11540579019","pt":1719496103458,"mc":[{"id":"1.230178309","rc":[{"atb":[[2.3,0]],"id":48500723}],"con":true,"img":false}]}
{"op":"mcm","clk":"11540579027","pt":1719496103562,"mc":[{"id":"1.230178309","rc":[{"atl":[[4.2,5.6]],"id":48500723}],"con":true,"img":false}]}
{"op":"mcm","clk":"11540579052","pt":1719496103879,"mc":[{"id":"1.230178309","rc":[{"atl":[[4.2,8.35]],"id":48500723}],"con":true,"img":false}]}
{"op":"mcm","clk":"11540579103","pt":1719496104452,"mc":[{"id":"1.230178309","rc":[{"atl":[[4.2,5.6]],"id":48500723}],"con":true,"img":false}]}
{"op":"mcm","clk":"11540579115","pt":1719496104652,"mc":[{"id":"1.230178309","rc":[{"atl":[[4.1,8.19]],"id":48500723}],"con":true,"img":false}]}
{"op":"mcm","clk":"11540579122","pt":1719496104755,"mc":[{"id":"1.230178309","rc":[{"atl":[[4,12.23],[4.2,1]],"id":48500723}],"con":true,"img":false}]}
{"op":"mcm","clk":"11540579134","pt":1719496104858,"mc":[{"id":"1.230178309","rc":[{"atl":[[4.1,4.44]],"id":48500723}],"con":true,"img":false}]}
{"op":"mcm","clk":"11540579170","pt":1719496105269,"mc":[{"id":"1.230178309","rc":[{"atb":[[2.56,5.11]],"id":70218235}],"con":true,"img":false}]}
{"op":"mcm","clk":"11540579186","pt":1719496105429,"mc":[{"id":"1.230178309","rc":[{"atl":[[4.1,0]],"id":48500723},{"atb":[[2.56,2.11]],"id":70218235}],"con":true,"img":false}]}
{"op":"mcm","clk":"11540579207","pt":1719496105641,"mc":[{"id":"1.230178309","rc":[{"atl":[[4,6.63],[5.4,15.74]],"id":48500723}],"con":true,"img":false}]}
{"op":"mcm","clk":"11540579231","pt":1719496105848,"mc":[{"id":"1.230178309","rc":[{"atb":[[2.44,11.02]],"id":39362025},{"atl":[[4,9.41],[4.1,1],[4.2,0]],"id":48500723}],"con":true,"img":false}]}
{"op":"mcm","clk":"11540579240","pt":1719496105948,"mc":[{"id":"1.230178309","rc":[{"atb":[[2.54,2.5]],"id":40953876},{"atb":[[2.42,3.91]],"id":39362025},{"atl":[[4.2,13.28],[5.4,2.5]],"id":48500723}],"con":true,"img":false}]}
{"op":"mcm","clk":"11540579245","pt":1719496106052,"mc":[{"id":"1.230178309","rc":[{"atb":[[2.52,32.84]],"id":40953876},{"atl":[[4,6.63]],"id":48500723}],"con":true,"img":false}]}
{"op":"mcm","clk":"11540579276","pt":1719496106456,"mc":[{"id":"1.230178309","rc":[{"atl":[[4,16.14]],"id":48500723}],"con":true,"img":false}]}
{"op":"mcm","clk":"11540579323","pt":1719496106973,"mc":[{"id":"1.230178309","rc":[{"atl":[[4,6.63]],"id":48500723}],"con":true,"img":false}]}
{"op":"mcm","clk":"11540579348","pt":1719496107243,"mc":[{"id":"1.230178309","rc":[{"atl":[[3.95,4.61]],"id":48500723}],"con":true,"img":false}]}
{"op":"mcm","clk":"11540579368","pt":1719496107446,"mc":[{"id":"1.230178309","rc":[{"atb":[[2.96,9.69]],"id":70218235}],"con":true,"img":false}]}
{"op":"mcm","clk":"11540579376","pt":1719496107545,"mc":[{"id":"1.230178309","rc":[{"atl":[[3.95,0]],"id":48500723},{"atb":[[2.98,3.21]],"id":70218235}],"con":true,"img":false}]}
{"op":"mcm","clk":"11540579387","pt":1719496107648,"mc":[{"id":"1.230178309","rc":[{"atl":[[3.9,0.84]],"id":48500723}],"con":true,"img":false}]}
{"op":"mcm","clk":"11540579407","pt":1719496107865,"mc":[{"id":"1.230178309","rc":[{"atl":[[3.9,7.26]],"id":48500723}],"con":true,"img":false}]}
{"op":"mcm","clk":"11540579434","pt":1719496108168,"mc":[{"id":"1.230178309","rc":[{"atl":[[3.9,6.42]],"id":48500723}],"con":true,"img":false}]}
{"op":"mcm","clk":"11540579480","pt":1719496108636,"mc":[{"id":"1.230178309","rc":[{"atl":[[4,5.79]],"id":48500723},{"atb":[[2.96,7.69]],"id":70218235}],"con":true,"img":false}]}
{"op":"mcm","clk":"11540579490","pt":1719496108740,"mc":[{"id":"1.230178309","rc":[{"atb":[[3,2]],"id":70218235}],"con":true,"img":false}]}
{"op":"mcm","clk":"11540579527","pt":1719496109156,"mc":[{"id":"1.230178309","rc":[{"atl":[[3.9,0]],"id":48500723}],"con":true,"img":false}]}
{"op":"mcm","clk":"11540579558","pt":1719496109463,"mc":[{"id":"1.230178309","rc":[{"atl":[[3.85,2.83]],"id":48500723}],"con":true,"img":false}]}
{"op":"mcm","clk":"11540579695","pt":1719496111063,"mc":[{"id":"1.230178309","rc":[{"atl":[[3.9,5.79]],"id":48500723}],"con":true,"img":false}]}
{"op":"mcm","clk":"11540579701","pt":1719496111167,"mc":[{"id":"1.230178309","rc":[{"atl":[[4.2,0]],"id":48500723}],"con":true,"img":false}]}
{"op":"mcm","clk":"11540579715","pt":1719496111372,"mc":[{"id":"1.230178309","rc":[{"atb":[[3,9.85]],"id":70218235}],"con":true,"img":false}]}
{"op":"mcm","clk":"11540579730","pt":1719496111579,"mc":[{"id":"1.230178309","rc":[{"atb":[[2.96,0]],"id":70218235}],"con":true,"img":false}]}
{"op":"mcm","clk":"11540579813","pt":1719496112361,"mc":[{"id":"1.230178309","rc":[{"atb":[[2.54,9.34]],"id":40953876}],"con":true,"img":false}]}
{"op":"mcm","clk":"11540579824","pt":1719496112462,"mc":[{"id":"1.230178309","rc":[{"atb":[[2.52,0],[2.6,0]],"id":40953876}],"con":true,"img":false}]}
{"op":"mcm","clk":"11540579833","pt":1719496112567,"mc":[{"id":"1.230178309","rc":[{"atb":[[2.6,3.42]],"id":40953876}],"con":true,"img":false}]}
{"op":"mcm","clk":"11540579909","pt":1719496113246,"mc":[{"id":"1.230178309","rc":[{"atb":[[2.98,0]],"id":70218235}],"con":true,"img":false}]}
{"op":"mcm","clk":"11540579930","pt":1719496113452,"mc":[{"id":"1.230178309","rc":[{"atb":[[2.26,6.29]],"id":48500723},{"atb":[[3.05,3]],"id":70218235}],"con":true,"img":false}]}
{"op":"mcm","clk":"11540580016","pt":1719496114279,"mc":[{"id":"1.230178309","rc":[{"atb":[[3,7.85]],"id":70218235}],"con":true,"img":false}]}
{"op":"mcm","clk":"11540580028","pt":1719496114384,"mc":[{"id":"1.230178309","rc":[{"atb":[[3.1,2]],"id":70218235}],"con":true,"img":false}]}
{"op":"mcm","clk":"11540580046","pt":1719496114544,"mc":[{"id":"1.230178309","rc":[{"atl":[[3.85,11.51]],"id":48500723}],"con":true,"img":false}]}
{"op":"mcm","clk":"11540580062","pt":1719496114750,"mc":[{"id":"1.230178309","rc":[{"atl":[[4,0]],"id":48500723}],"con":true,"img":false}]}
{"op":"mcm","clk":"11540580099","pt":1719496115167,"mc":[{"id":"1.230178309","rc":[{"atl":[[3.8,0.84]],"id":48500723}],"con":true,"img":false}]}
{"op":"mcm","clk":"11540580373","pt":1719496117848,"mc":[{"id":"1.230178309","rc":[{"atb":[[2.54,2.5],[2.6,0],[2.58,6.84]],"id":40953876},{"atb":[[2.12,0],[2.16,12.6]],"id":48500723}],"con":true,"img":false}]}
{"op":"mcm","clk":"11540580398","pt":1719496118056,"mc":[{"id":"1.230178309","rc":[{"atb":[[2.42,0]],"id":39362025}],"con":true,"img":false}]}
{"op":"mcm","clk":"11540580490","pt":1719496118981,"mc":[{"id":"1.230178309","rc":[{"atb":[[3.05,0]],"id":70218235}],"con":true,"img":false}]}
{"op":"mcm","clk":"11540580498","pt":1719496119084,"mc":[{"id":"1.230178309","rc":[{"atb":[[3.1,4.02]],"id":70218235}],"con":true,"img":false}]}
{"op":"mcm","clk":"11540580537","pt":1719496119447,"mc":[{"id":"1.230178309","rc":[{"atb":[[2.42,3.91]],"id":39362025}],"con":true,"img":false}]}
{"op":"mcm","clk":"11540580658","pt":1719496121044,"mc":[{"id":"1.230178309","rc":[{"atb":[[3.1,15.34]],"id":70218235}],"con":true,"img":false}]}
{"op":"mcm","clk":"11540580679","pt":1719496121252,"mc":[{"id":"1.230178309","rc":[{"atb":[[3,0]],"id":70218235}],"con":true,"img":false}]}
{"op":"mcm","clk":"11540580820","pt":1719496122849,"mc":[{"id":"1.230178309","rc":[{"atb":[[2.54,16.18],[2.58,0]],"id":40953876}],"con":true,"img":false}]}
{"op":"mcm","clk":"11540580941","pt":1719496124245,"mc":[{"id":"1.230178309","rc":[{"atl":[[3.8,9.91]],"id":48500723}],"con":true,"img":false}]}
{"op":"mcm","clk":"11540580960","pt":1719496124461,"mc":[{"id":"1.230178309","rc":[{"atl":[[3.85,2.83]],"id":48500723}],"con":true,"img":false}]}
{"op":"mcm","clk":"11540580987","pt":1719496124761,"mc":[{"id":"1.230178309","rc":[{"atb":[[3.1,13.32]],"id":70218235}],"con":true,"img":false}]}
{"op":"mcm","clk":"11540580996","pt":1719496124866,"mc":[{"id":"1.230178309","rc":[{"atb":[[3.15,3]],"id":70218235}],"con":true,"img":false}]}
{"op":"mcm","clk":"11540581003","pt":1719496124966,"mc":[{"id":"1.230178309","rc":[{"atb":[[2.52,3.13]],"id":40953876}],"con":true,"img":false}]}
{"op":"mcm","clk":"11540581045","pt":1719496125477,"mc":[{"id":"1.230178309","rc":[{"atb":[[3.1,11.32]],"id":70218235}],"con":true,"img":false}]}
{"op":"mcm","clk":"11540581055","pt":1719496125581,"mc":[{"id":"1.230178309","rc":[{"atb":[[1.02,2]],"id":70218235}],"con":true,"img":false}]}
{"op":"mcm","clk":"11540581109","pt":1719496126156,"mc":[{"id":"1.230178309","rc":[{"atb":[[2.52,0]],"id":40953876}],"con":true,"img":false}]}
{"op":"mcm","clk":"11540581272","pt":1719496128173,"mc":[{"id":"1.230178309","rc":[{"atb":[[2.54,2.5],[2.58,18.63]],"id":40953876}],"con":true,"img":false}]}
{"op":"mcm","clk":"11540581345","pt":1719496128989,"mc":[{"id":"1.230178309","rc":[{"atb":[[2.6,3.42]],"id":40953876}],"con":true,"img":false}]}
{"op":"mcm","clk":"11540581516","pt":1719496130589,"mc":[{"id":"1.230178309","rc":[{"atb":[[3.15,14.62]],"id":70218235}],"con":true,"img":false}]}
{"op":"mcm","clk":"11540581526","pt":1719496130696,"mc":[{"id":"1.230178309","rc":[{"atb":[[3.1,0]],"id":70218235}],"con":true,"img":false}]}
{"op":"mcm","clk":"11540581662","pt":1719496131979,"mc":[{"id":"1.230178309","rc":[{"atb":[[1.02,0]],"id":70218235}],"con":true,"img":false}]}
{"op":"mcm","clk":"11540581670","pt":1719496132083,"mc":[{"id":"1.230178309","rc":[{"atb":[[3.2,2]],"id":70218235}],"con":true,"img":false}]}
{"op":"mcm","clk":"11540581838","pt":1719496134106,"mc":[{"id":"1.230178309","rc":[{"atb":[[3.2,0]],"id":70218235}],"con":true,"img":false}]}
{"op":"mcm","clk":"11540581854","pt":1719496134264,"mc":[{"id":"1.230178309","rc":[{"atb":[[1.02,2]],"id":70218235}],"con":true,"img":false}]}
{"op":"mcm","clk":"11540582028","pt":1719496136179,"mc":[{"id":"1.230178309","rc":[{"atb":[[3.15,11.62]],"id":70218235}],"con":true,"img":false}]}
{"op":"mcm","clk":"11540582042","pt":1719496136284,"mc":[{"id":"1.230178309","rc":[{"atb":[[2.6,3]],"id":70218235}],"con":true,"img":false}]}
{"op":"mcm","clk":"11540582062","pt":1719496136384,"mc":[{"id":"1.230178309","rc":[{"atb":[[1.02,0],[3.15,0]],"id":70218235},{"atb":[[2.68,10.03]],"id":55829870}],"con":true,"img":false}]}
{"op":"mcm","clk":"11540582075","pt":1719496136486,"mc":[{"id":"1.230178309","rc":[{"atb":[[2.6,0]],"id":40953876},{"atb":[[3.2,2],[3.1,11.62]],"id":70218235},{"atl":[[6.2,0]],"id":70218235},{"atb":[[2.64,0]],"id":55829870}],"con":true,"img":false}]}
{"op":"mcm","clk":"11540582087","pt":1719496136590,"mc":[{"id":"1.230178309","rc":[{"atb":[[2.58,2.5],[2.62,3]],"id":70218235}],"con":true,"img":false}]}
{"op":"mcm","clk":"11540582173","pt":1719496137575,"mc":[{"id":"1.230178309","rc":[{"atb":[[2.62,0]],"id":55829870}],"con":true,"img":false}]}
{"op":"mcm","clk":"11540582187","pt":1719496137683,"mc":[{"id":"1.230178309","rc":[{"atb":[[2.34,2.5]],"id":55829870}],"con":true,"img":false}]}
{"op":"mcm","clk":"11540582247","pt":1719496138298,"mc":[{"id":"1.230178309","rc":[{"atb":[[3.2,0]],"id":70218235}],"con":true,"img":false}]}
{"op":"mcm","clk":"11540582257","pt":1719496138402,"mc":[{"id":"1.230178309","rc":[{"atb":[[3.15,2]],"id":70218235}],"con":true,"img":false}]}
{"op":"mcm","clk":"11540582286","pt":1719496138665,"mc":[{"id":"1.230178309","rc":[{"atb":[[2.66,3.32]],"id":55829870}],"con":true,"img":false}]}
{"op":"mcm","clk":"11540582408","pt":1719496139859,"mc":[{"id":"1.230178309","rc":[{"atb":[[3.15,9.69]],"id":70218235}],"con":true,"img":false}]}
{"op":"mcm","clk":"11540582425","pt":1719496140061,"mc":[{"id":"1.230178309","rc":[{"atb":[[3.1,0]],"id":70218235}],"con":true,"img":false}]}
{"op":"mcm","clk":"11540582465","pt":1719496140370,"mc":[{"id":"1.230178309","rc":[{"atb":[[2.42,5.55]],"id":39362025}],"con":true,"img":false}]}
{"op":"mcm","clk":"11540582475","pt":1719496140476,"mc":[{"id":"1.230178309","rc":[{"atb":[[2.42,4.17]],"id":39362025},{"atl":[[5.4,5]],"id":55829870}],"con":true,"img":false}]}
{"op":"mcm","clk":"11540582486","pt":1719496140578,"mc":[{"id":"1.230178309","rc":[{"atb":[[2.66,0]],"id":55829870}],"con":true,"img":false}]}
{"op":"mcm","clk":"11540582495","pt":1719496140680,"mc":[{"id":"1.230178309","rc":[{"atl":[[5.3,12.51]],"id":55829870}],"con":true,"img":false}]}
{"op":"mcm","clk":"11540582558","pt":1719496141302,"mc":[{"id":"1.230178309","rc":[{"atl":[[5.3,8.93]],"id":55829870}],"con":true,"img":false}]}
{"op":"mcm","clk":"11540582610","pt":1719496141667,"mc":[{"id":"1.230178309","rc":[{"atb":[[2.66,16.51],[2.58,0]],"id":40953876},{"atb":[[2.5,15.8],[2.44,1]],"id":39362025},{"atb":[[2.2,12.7],[2.16,0]],"id":48500723},{"atl":[[4,1],[4.1,0]],"id":48500723},{"atb":[[2.62,0],[2.74,19.38]],"id":70218235},{"atb":[[2.4,2.8],[2.3,0],[2.68,4]],"id":55829870},{"atl":[[5.2,1.84]],"id":55829870}],"con":true,"img":false}]}
{"op":"mcm","clk":"11540582621","pt":1719496141776,"mc":[{"id":"1.230178309","rc":[{"atb":[[2.56,3.5],[2.46,0],[2.66,32.98]],"id":40953876},{"atl":[[5.1,6.54],[5.3,0]],"id":55829870}],"con":true,"img":false}]}
{"op":"mcm","clk":"11540582643","pt":1719496141979,"mc":[{"id":"1.230178309","rc":[{"atb":[[2.56,0],[2.64,3]],"id":40953876}],"con":true,"img":false}]}
{"op":"mcm","clk":"11540582651","pt":1719496142083,"mc":[{"id":"1.230178309","rc":[{"atb":[[2.64,0]],"id":40953876},{"atb":[[2.42,0]],"id":39362025},{"atb":[[2.6,0]],"id":70218235}],"con":true,"img":false}]}
{"op":"mcm","clk":"11540582661","pt":1719496142190,"mc":[{"id":"1.230178309","rc":[{"atb":[[2.68,3.3]],"id":40953876},{"atb":[[2.76,2.4]],"id":70218235}],"con":true,"img":false}]}
{"op":"mcm","clk":"11540582734","pt":1719496142967,"mc":[{"id":"1.230178309","rc":[{"atl":[[5.2,0]],"id":55829870}],"con":true,"img":false}]}
{"op":"mcm","clk":"11540582765","pt":1719496143277,"mc":[{"id":"1.230178309","rc":[{"atl":[[5.3,1.8]],"id":55829870}],"con":true,"img":false}]}
{"op":"mcm","clk":"11540582881","pt":1719496144211,"mc":[{"id":"1.230178309","rc":[{"atl":[[5.2,17.25]],"id":40953876},{"spn":3.94,"spf":"NaN","id":40953876},{"atb":[[2.5,24.72]],"id":39362025},{"atl":[[5.5,12.35]],"id":39362025},{"atb":[[2.32,15.09]],"id":48500723},{"atl":[[3.8,12.2]],"id":48500723},{"spn":3.06,"spf":"NaN","id":48500723},{"atb":[[1.99,11.67]],"id":44798446},{"atl":[[3.05,14.09]],"id":44798446},{"atb":[[3.15,14.1]],"id":70218235},{"atl":[[5.2,9.63]],"id":70218235},{"spn":4.17,"spf":"NaN","id":70218235}],"con":true,"img":false}]}
{"op":"mcm","clk":"11540582894","pt":1719496144314,"mc":[{"id":"1.230178309","rc":[{"atl":[[5.1,14.73],[5.8,0]],"id":40953876},{"atl":[[6.6,0],[5.4,9.37]],"id":39362025},{"atl":[[3.9,0],[3.75,5.79]],"id":48500723},{"atl":[[3.2,0],[3,13.11]],"id":44798446},{"atl":[[5.1,8.25],[5.7,0]],"id":70218235}],"con":true,"img":false}]}
{"op":"mcm","clk":"11540582903","pt":1719496144369,"mc":[{"id":"1.230178309","rc":[{"atl":[[5,13.52]],"id":40953876},{"atl":[[5.3,8.62]],"id":39362025},{"atl":[[3.7,13.88]],"id":48500723},{"atl":[[2.98,12.82]],"id":44798446},{"atl":[[5,13.41]],"id":70218235}],"con":true,"img":false}]}
{"op":"mcm","clk":"11540582919","pt":1719496144479,"mc":[{"id":"1.230178309","rc":[{"atl":[[5.1,0],[4.9,14.73]],"id":40953876},{"atl":[[5.2,9.37],[5.4,0]],"id":39362025},{"atl":[[3.75,0],[3.65,12.2]],"id":48500723},{"atl":[[3,0],[2.96,13.11]],"id":44798446},{"atl":[[5.1,0],[4.9,9.63]],"id":70218235}],"con":true,"img":false}]}
{"op":"mcm","clk":"11540582930","pt":1719496144576,"mc":[{"id":"1.230178309","rc":[{"atl":[[5,14.36],[5.8,1],[5.2,10.87],[5.9,0]],"id":40953876},{"atl":[[5.8,1],[5.3,9.46],[5.5,4.83],[5.9,0]],"id":39362025},{"atl":[[3.7,14.72],[3.8,3.13]],"id":48500723},{"atl":[[2.98,13.66],[3.05,8.43]],"id":44798446},{"atl":[[5,14.25],[5.5,1],[5.2,3.23]],"id":70218235}],"con":true,"img":false}]}
{"op":"mcm","clk":"11540582940","pt":1719496144679,"mc":[{"id":"1.230178309","rc":[{"atl":[[5.6,0]],"id":70218235}],"con":true,"img":false}]}
{"op":"mcm","clk":"11540582959","pt":1719496144884,"mc":[{"id":"1.230178309","rc":[{"atl":[[5.8,0]],"id":70218235}],"con":true,"img":false}]}
{"op":"mcm","clk":"11540582971","pt":1719496144987,"mc":[{"id":"1.230178309","rc":[{"atb":[[2.18,0]],"id":70218235}],"con":true,"img":false}]}
{"op":"mcm","clk":"11540582984","pt":1719496145091,"mc":[{"id":"1.230178309","rc":[{"atb":[[2.26,2.11]],"id":48500723}],"con":true,"img":false}]}
{"op":"mcm","clk":"11540583000","pt":1719496145197,"mc":[{"id":"1.230178309","rc":[{"atl":[[5.2,10.02]],"id":40953876},{"atl":[[5.5,3.99]],"id":39362025},{"atl":[[3.8,2.28]],"id":48500723},{"atl":[[3.05,7.58]],"id":44798446},{"atl":[[5.2,2.38]],"id":70218235}],"con":true,"img":false}]}
{"op":"mcm","clk":"11540583023","pt":1719496145400,"mc":[{"id":"1.230178309","rc":[{"atb":[[2.38,2.11]],"id":48500723}],"con":true,"img":false}]}
{"op":"mcm","clk":"11540583041","pt":1719496145502,"mc":[{"id":"1.230178309","rc":[{"atl":[[5.8,0],[6,1]],"id":39362025}],"con":true,"img":false}]}
{"op":"mcm","clk":"11540583056","pt":1719496145606,"mc":[{"id":"1.230178309","rc":[{"atb":[[2.64,3.33]],"id":40953876},{"atb":[[2.26,0],[2.38,12.98]],"id":48500723}],"con":true,"img":false}]}
{"op":"mcm","clk":"11540583076","pt":1719496145814,"mc":[{"id":"1.230178309","rc":[{"atl":[[5.8,0],[5.7,1]],"id":40953876},{"atl":[[6,0],[5.9,1]],"id":39362025},{"atb":[[2.32,10.69]],"id":48500723},{"atl":[[3.2,1],[3.15,0]],"id":44798446},{"atl":[[5.5,0],[5.4,1]],"id":70218235},{"atb":[[2.46,0]],"id":55829870}],"con":true,"img":false}]}
{"op":"mcm","clk":"11540583089","pt":1719496145918,"mc":[{"id":"1.230178309","rc":[{"atb":[[1.56,10],[1.49,0]],"id":44798446},{"atl":[[4.9,15.14]],"id":70218235}],"con":true,"img":false}]}
{"op":"mcm","clk":"11540583101","pt":1719496145975,"mc":[{"id":"1.230178309","rc":[{"atl":[[6,1]],"id":39362025},{"atl":[[3.2,0],[3.25,1]],"id":44798446},{"atl":[[5.5,1],[5.4,0]],"id":70218235}],"con":true,"img":false}]}
{"op":"mcm","clk":"11540583111","pt":1719496146074,"mc":[{"id":"1.230178309","rc":[{"atl":[[5.9,0]],"id":39362025}],"con":true,"img":false}]}
{"op":"mcm","clk":"11540583178","pt":1719496146692,"mc":[{"id":"1.230178309","rc":[{"atb":[[2.64,0]],"id":40953876},{"atb":[[2.32,8.69]],"id":48500723}],"con":true,"img":false}]}
{"op":"mcm","clk":"11540583193","pt":1719496146795,"mc":[{"id":"1.230178309","rc":[{"atb":[[2.68,6.63]],"id":40953876},{"atb":[[2.4,2]],"id":48500723}],"con":true,"img":false}]}
{"op":"mcm","clk":"11540583204","pt":1719496146897,"mc":[{"id":"1.230178309","rc":[{"atb":[[2.66,16.47],[2.64,36.28],[2.68,3.3]],"id":40953876}],"con":true,"img":false}]}
{"op":"mcm","clk":"11540583216","pt":1719496147002,"mc":[{"id":"1.230178309","rc":[{"atb":[[2.64,0],[2.68,9.93]],"id":40953876},{"atl":[[5.5,1],[5.7,0]],"id":40953876},{"atb":[[2.5,16.82],[2.46,26.84]],"id":39362025},{"atb":[[2.24,17.4],[2.2,0]],"id":48500723},{"atl":[[4,0],[3.95,1]],"id":48500723},{"atb":[[1.83,0],[1.98,2.5],[1.94,5],[1.87,0],[1.91,0]],"id":44798446},{"atl":[[3.25,0],[3.3,1]],"id":44798446}],"con":true,"img":false}]}
{"op":"mcm","clk":"11540583227","pt":1719496147103,"mc":[{"id":"1.230178309","rc":[{"atb":[[2.64,19.77],[2.68,3.3]],"id":40953876}],"con":true,"img":false}]}
{"op":"mcm","clk":"11540583238","pt":1719496147206,"mc":[{"id":"1.230178309","rc":[{"atb":[[2.3,4.08]],"id":48500723}],"con":true,"img":false}]}
{"op":"mcm","clk":"11540583334","pt":1719496147985,"mc":[{"id":"1.230178309","rc":[{"atl":[[5.4,0]],"id":48500723}],"con":true,"img":false}]}
{"op":"mcm","clk":"11540583390","pt":1719496148500,"mc":[{"id":"1.230178309","rc":[{"atb":[[1.93,12.44]],"id":44798446}],"con":true,"img":false}]}
{"op":"mcm","clk":"11540583401","pt":1719496148608,"mc":[{"id":"1.230178309","rc":[{"atl":[[5.1,24.39],[4.9,0]],"id":40953876},{"atl":[[6.8,0],[7.6,0],[5.2,0],[5.4,18.84]],"id":39362025},{"atl":[[3.65,0],[3.75,26.93]],"id":48500723},{"atl":[[3,26.78],[2.96,0]],"id":44798446}],"con":true,"img":false}]}
{"op":"mcm","clk":"11540583442","pt":1719496148911,"mc":[{"id":"1.230178309","rc":[{"atl":[[5.2,0]],"id":40953876},{"atl":[[5.5,0]],"id":39362025},{"atb":[[2.32,0]],"id":48500723},{"atl":[[3.8,0]],"id":48500723},{"atl":[[3.05,0]],"id":44798446},{"atl":[[5.2,0]],"id":70218235}],"con":true,"img":false}]}
{"op":"mcm","clk":"11540583457","pt":1719496149017,"mc":[{"id":"1.230178309","rc":[{"atl":[[8.2,10],[7.4,5],[6,21],[6.6,2.5]],"id":39362025},{"atl":[[3.8,35.71],[3.75,0]],"id":48500723},{"atl":[[3.3,41.45]],"id":44798446},{"atl":[[6,2.5],[6.8,5],[7.6,10]],"id":70218235}],"con":true,"img":false}]}
{"op":"mcm","clk":"11540583474","pt":1719496149074,"mc":[{"id":"1.230178309","rc":[{"atl":[[5.1,0],[5.5,23.22],[4.9,9.59]],"id":40953876},{"atl":[[5.2,3.52],[5.4,0]],"id":39362025},{"atb":[[2.38,20.78]],"id":48500723},{"atl":[[3.65,1.72]],"id":48500723},{"atl":[[3,0],[2.96,7.11]],"id":44798446},{"atl":[[4.9,16.97]],"id":70218235},{"atb":[[1.26,21.06]],"id":55829870},{"atl":[[4.9,10.49]],"id":55829870}],"con":true,"img":false}]}
{"op":"mcm","clk":"11540583492","pt":1719496149277,"mc":[{"id":"1.230178309","rc":[{"atl":[[4.8,6.54],[5.1,0]],"id":55829870}],"con":true,"img":false}]}
{"op":"mcm","clk":"11540583502","pt":1719496149384,"mc":[{"id":"1.230178309","rc":[{"atb":[[1.93,1.44]],"id":44798446},{"atl":[[4.7,5.1]],"id":55829870}],"con":true,"img":false}]}
{"op":"mcm","clk":"11540583525","pt":1719496149585,"mc":[{"id":"1.230178309","rc":[{"atl":[[5.1,9.47],[6,1]],"id":39362025},{"atl":[[3.8,0],[3.65,16.45]],"id":48500723},{"atl":[[3.3,0.99],[2.94,13.67]],"id":44798446},{"atl":[[4.9,7.3],[4.7,5.94]],"id":55829870}],"con":true,"img":false}]}
{"op":"mcm","clk":"11540583537","pt":1719496149689,"mc":[{"id":"1.230178309","rc":[{"atl":[[3.8,16.46],[3.65,1.72]],"id":48500723}],"con":true,"img":false}]}
{"op":"mcm","clk":"11540583576","pt":1719496150002,"mc":[{"id":"1.230178309","rc":[{"atl":[[3.35,1],[3.3,0]],"id":44798446}],"con":true,"img":false}]}
{"op":"mcm","clk":"11540583585","pt":1719496150099,"mc":[{"id":"1.230178309","rc":[{"atl":[[5.3,8.62]],"id":39362025},{"atl":[[2.98,12.82]],"id":44798446},{"atl":[[4.9,6.45]],"id":55829870}],"con":true,"img":false}]}
{"op":"mcm","clk":"11540583647","pt":1719496150617,"mc":[{"id":"1.230178309","rc":[{"atb":[[2.7,2.21]],"id":40953876},{"atb":[[2.52,2.64]],"id":39362025},{"atb":[[2,2.52]],"id":44798446},{"atb":[[2.7,2.21]],"id":55829870}],"con":true,"img":false}]}
{"op":"mcm","clk":"11540583658","pt":1719496150721,"mc":[{"id":"1.230178309","rc":[{"atb":[[2.52,11.75]],"id":39362025}],"con":true,"img":false}]}
{"op":"mcm","clk":"11540583668","pt":1719496150777,"mc":[{"id":"1.230178309","rc":[{"atb":[[2,16.6]],"id":44798446}],"con":true,"img":false}]}
{"op":"mcm","clk":"11540583679","pt":1719496150878,"mc":[{"id":"1.230178309","rc":[{"atb":[[2.7,20.19]],"id":40953876},{"atb":[[2.5,11.62]],"id":39362025}],"con":true,"img":false}]}
{"op":"mcm","clk":"11540583688","pt":1719496150979,"mc":[{"id":"1.230178309","rc":[{"atb":[[2.66,0]],"id":40953876},{"atb":[[1.99,6.61]],"id":44798446}],"con":true,"img":false}]}
{"op":"mcm","clk":"11540583698","pt":1719496151083,"mc":[{"id":"1.230178309","rc":[{"atb":[[1.97,0]],"id":44798446}],"con":true,"img":false}]}
{"op":"mcm","clk":"11540583751","pt":1719496151598,"mc":[{"id":"1.230178309","rc":[{"atl":[[4.8,0.84]],"id":40953876},{"atl":[[5,0.84]],"id":39362025},{"atl":[[3.6,0.84]],"id":48500723},{"atl":[[2.92,0.84]],"id":44798446},{"atl":[[4.8,0.84]],"id":70218235}],"con":true,"img":false}]}
{"op":"mcm","clk":"11540583760","pt":1719496151702,"mc":[{"id":"1.230178309","rc":[{"atl":[[3.65,16.45]],"id":48500723}],"con":true,"img":false}]}
{"op":"mcm","clk":"11540583774","pt":1719496151810,"mc":[{"id":"1.230178309","rc":[{"atl":[[3.8,0]],"id":48500723}],"con":true,"img":false}]}
{"op":"mcm","clk":"11540583799","pt":1719496152013,"mc":[{"id":"1.230178309","rc":[{"atb":[[2.64,0],[2.62,41.65]],"id":40953876},{"atb":[[2.42,23.24]],"id":39362025},{"atl":[[3.35,0],[2.94,0],[3.05,19.93]],"id":44798446}],"con":true,"img":false}]}
{"op":"mcm","clk":"11540583808","pt":1719496152116,"mc":[{"id":"1.230178309","rc":[{"atb":[[2.46,0]],"id":39362025}],"con":true,"img":false}]}
{"op":"mcm","clk":"11540583816","pt":1719496152219,"mc":[{"id":"1.230178309","rc":[{"atb":[[1.98,7.92]],"id":44798446},{"atb":[[2.68,2]],"id":55829870}],"con":true,"img":false}]}
{"op":"mcm","clk":"11540583830","pt":1719496152379,"mc":[{"id":"1.230178309","rc":[{"atb":[[2.72,2]],"id":55829870}],"con":true,"img":false}]}
{"op":"mcm","clk":"11540583841","pt":1719496152483,"mc":[{"id":"1.230178309","rc":[{"atl":[[2.92,0]],"id":44798446},{"atb":[[2.5,0]],"id":55829870}],"con":true,"img":false}]}
{"op":"mcm","clk":"11540583855","pt":1719496152588,"mc":[{"id":"1.230178309","rc":[{"atb":[[2.74,2.12]],"id":55829870}],"con":true,"img":false}]}
{"op":"mcm","clk":"11540583926","pt":1719496153315,"mc":[{"id":"1.230178309","rc":[{"atb":[[2.72,0]],"id":55829870}],"con":true,"img":false}]}
{"op":"mcm","clk":"11540583940","pt":1719496153415,"mc":[{"id":"1.230178309","rc":[{"atb":[[2.76,2]],"id":55829870}],"con":true,"img":false}]}
{"op":"mcm","clk":"11540583955","pt":1719496153519,"mc":[{"id":"1.230178309","rc":[{"atl":[[4.8,10.51]],"id":40953876},{"atl":[[5,10.59]],"id":39362025},{"atl":[[3.65,30.56]],"id":48500723},{"atl":[[2.94,15.56]],"id":44798446},{"atl":[[4.8,21.89]],"id":70218235},{"atb":[[2.74,0],[2.7,0]],"id":55829870}],"con":true,"img":false}]}
{"op":"mcm","clk":"11540583966","pt":1719496153576,"mc":[{"id":"1.230178309","rc":[{"atb":[[2.68,0]],"id":40953876},{"atl":[[5,0.84]],"id":40953876},{"atb":[[2.5,8.92]],"id":39362025},{"atl":[[5.3,0]],"id":39362025},{"atl":[[3.7,18.15],[3.65,15.83]],"id":48500723},{"atb":[[1.99,3.61]],"id":44798446},{"atl":[[2.98,0]],"id":44798446},{"atl":[[5,0.84]],"id":70218235},{"atb":[[2.68,0]],"id":55829870}],"con":true,"img":false}]}
{"op":"mcm","clk":"11540583981","pt":1719496153684,"mc":[{"id":"1.230178309","rc":[{"atb":[[2.72,3]],"id":40953876},{"atb":[[2.54,4.65],[2.5,0]],"id":39362025},{"atl":[[5.2,0]],"id":39362025},{"atb":[[1.99,0],[2.02,5.3]],"id":44798446},{"atb":[[2.74,3],[1.26,0]],"id":55829870},{"atl":[[4.9,0]],"id":55829870}],"con":true,"img":false}]}
{"op":"mcm","clk":"11540583991","pt":1719496153784,"mc":[{"id":"1.230178309","rc":[{"atb":[[2.74,2.12]],"id":40953876},{"atb":[[2.44,5.25],[2.56,2.52]],"id":39362025},{"atb":[[2.04,4.24]],"id":44798446},{"atb":[[2.78,2.04]],"id":55829870}],"con":true,"img":false}]}
{"op":"mcm","clk":"11540584003","pt":1719496153890,"mc":[{"id":"1.230178309","rc":[{"atb":[[2.44,1],[2.52,20.41]],"id":39362025},{"atl":[[5.1,3.36],[6,21]],"id":39362025},{"atb":[[2,19.99]],"id":44798446},{"atl":[[4.8,0],[5,14.99]],"id":55829870}],"con":true,"img":false}]}
{"op":"mcm","clk":"11540584025","pt":1719496154091,"mc":[{"id":"1.230178309","rc":[{"atl":[[5,21.19],[6,1]],"id":39362025},{"atl":[[5,2.5],[5.2,20.94]],"id":55829870}],"con":true,"img":false}]}
{"op":"mcm","clk":"11540584040","pt":1719496154199,"mc":[{"id":"1.230178309","rc":[{"atl":[[4.8,20.11],[5,0],[5.5,1]],"id":40953876},{"atl":[[5,0]],"id":70218235}],"con":true,"img":false}]}
{"op":"mcm","clk":"11540584085","pt":1719496154607,"mc":[{"id":"1.230178309","rc":[{"atb":[[2.4,16.94]],"id":48500723}],"con":true,"img":false}]}
{"op":"mcm","clk":"11540584093","pt":1719496154711,"mc":[{"id":"1.230178309","rc":[{"atb":[[2.38,9.91]],"id":48500723},{"atl":[[3.85,0]],"id":48500723}],"con":true,"img":false}]}
{"op":"mcm","clk":"11540584101","pt":1719496154814,"mc":[{"id":"1.230178309","rc":[{"atb":[[2.78,13.53]],"id":55829870},{"atl":[[4.7,11.45]],"id":55829870}],"con":true,"img":false}]}
{"op":"mcm","clk":"11540584111","pt":1719496154922,"mc":[{"id":"1.230178309","rc":[{"atb":[[2.76,0]],"id":55829870},{"atl":[[4.6,11.46],[5.2,0]],"id":55829870}],"con":true,"img":false}]}
{"op":"mcm","clk":"11540584120","pt":1719496154973,"mc":[{"id":"1.230178309","rc":[{"atb":[[2.8,2]],"id":55829870}],"con":true,"img":false}]}
{"op":"mcm","clk":"11540584141","pt":1719496155181,"mc":[{"id":"1.230178309","rc":[{"atb":[[1.98,2.5]],"id":44798446}],"con":true,"img":false}]}
{"op":"mcm","clk":"11540584171","pt":1719496155487,"mc":[{"id":"1.230178309","rc":[{"atb":[[2.78,2.04]],"id":55829870},{"atl":[[4.7,5.94]],"id":55829870}],"con":true,"img":false}]}
{"op":"mcm","clk":"11540584226","pt":1719496156103,"mc":[{"id":"1.230178309","rc":[{"atb":[[2.8,15.67]],"id":55829870},{"atl":[[4.6,17.34]],"id":55829870}],"con":true,"img":false}]}
{"op":"mcm","clk":"11540584324","pt":1719496157092,"mc":[{"id":"1.230178309","rc":[{"atl":[[4.5,0.84]],"id":55829870}],"con":true,"img":false}]}
{"op":"mcm","clk":"11540584347","pt":1719496157295,"mc":[{"id":"1.230178309","rc":[{"atb":[[2.54,25.69],[2.62,2.11]],"id":40953876},{"atb":[[1.56,0],[1.61,8.48]],"id":44798446},{"atl":[[3.1,31.12],[3.05,0]],"id":44798446},{"atb":[[3.15,6.41]],"id":70218235}],"con":true,"img":false}]}
{"op":"mcm","clk":"11540584358","pt":1719496157395,"mc":[{"id":"1.230178309","rc":[{"atb":[[3.1,17.55]],"id":70218235}],"con":true,"img":false}]}
{"op":"mcm","clk":"11540584369","pt":1719496157504,"mc":[{"id":"1.230178309","rc":[{"atb":[[2.58,2.11],[2.48,0]],"id":39362025},{"atb":[[2.38,7.79],[2.46,2.11]],"id":48500723},{"atb":[[1.95,0],[2.06,2.11]],"id":44798446}],"con":true,"img":false}]}
{"op":"mcm","clk":"11540584376","pt":1719496157601,"mc":[{"id":"1.230178309","rc":[{"atb":[[2.6,2.44]],"id":39362025},{"atb":[[1.93,0],[2.08,4.5]],"id":44798446}],"con":true,"img":false}]}
{"op":"mcm","clk":"11540584424","pt":1719496158118,"mc":[{"id":"1.230178309","rc":[{"atb":[[2.4,14.94]],"id":48500723},{"atb":[[2.76,3.12]],"id":55829870}],"con":true,"img":false}]}
{"op":"mcm","clk":"11540584436","pt":1719496158221,"mc":[{"id":"1.230178309","rc":[{"atb":[[2.48,2]],"id":48500723}],"con":true,"img":false}]}
{"op":"mcm","clk":"11540584444","pt":1719496158274,"mc":[{"id":"1.230178309","rc":[{"atl":[[4.5,7.64]],"id":55829870}],"con":true,"img":false}]}
{"op":"mcm","clk":"11540584460","pt":1719496158484,"mc":[{"id":"1.230178309","rc":[{"atl":[[4.7,0.84]],"id":55829870}],"con":true,"img":false}]}
{"op":"mcm","clk":"11540584468","pt":1719496158585,"mc":[{"id":"1.230178309","rc":[{"atl":[[4.9,0]],"id":40953876},{"atl":[[5.1,0]],"id":39362025},{"atb":[[2.38,0]],"id":48500723},{"atl":[[2.96,0]],"id":44798446},{"atl":[[4.9,15.14]],"id":70218235},{"atl":[[4.6,11.46]],"id":55829870}],"con":true,"img":false}]}
{"op":"mcm","clk":"11540584474","pt":1719496158689,"mc":[{"id":"1.230178309","rc":[{"atl":[[4.8,10.51],[5.6,23.62]],"id":40953876},{"atl":[[5,10.59],[6.6,20.36]],"id":39362025},{"atb":[[2.3,0]],"id":48500723},{"atl":[[3.6,9.09]],"id":48500723},{"atl":[[3.1,0],[4.2,33.75]],"id":44798446},{"atl":[[4.7,0]],"id":55829870}],"con":true,"img":false}]}
{"op":"mcm","clk":"11540584482","pt":1719496158788,"mc":[{"id":"1.230178309","rc":[{"atl":[[4.8,19.94]],"id":40953876},{"atl":[[5,13.78]],"id":39362025},{"atb":[[2.4,22.45]],"id":48500723},{"atl":[[3.6,24.93],[3.7,0.84]],"id":48500723},{"atl":[[2.94,6.99]],"id":44798446},{"atl":[[4.8,23.52]],"id":70218235},{"atl":[[4.6,17.35]],"id":55829870}],"con":true,"img":false}]}
{"op":"mcm","clk":"11540584491","pt":1719496158895,"mc":[{"id":"1.230178309","rc":[{"atl":[[5.6,2.5],[4.7,19.95]],"id":40953876},{"atl":[[2.96,7.12]],"id":44798446},{"atl":[[4.6,5.89],[5,21.61]],"id":55829870}],"con":true,"img":false}]}
{"op":"mcm","clk":"11540584514","pt":1719496159099,"mc":[{"id":"1.230178309","rc":[{"atl":[[3.7,0]],"id":48500723},{"atl":[[2.92,0.84]],"id":44798446}],"con":true,"img":false}]}
{"op":"mcm","clk":"11540584527","pt":1719496159203,"mc":[{"id":"1.230178309","rc":[{"atb":[[2.54,0]],"id":39362025},{"atl":[[5.6,5],[6,10],[5.2,2.5]],"id":48500723},{"atb":[[2.02,0]],"id":44798446},{"atb":[[2.76,0]],"id":70218235},{"atb":[[2.74,0]],"id":55829870}],"con":true,"img":false}]}
{"op":"mcm","clk":"11540584535","pt":1719496159306,"mc":[{"id":"1.230178309","rc":[{"atb":[[2.62,2]],"id":39362025},{"atb":[[2.1,3.9]],"id":44798446},{"atb":[[3.15,9.57]],"id":70218235},{"atb":[[2.82,3]],"id":55829870},{"atl":[[4.5,14.25]],"id":55829870}],"con":true,"img":false}]}
{"op":"mcm","clk":"11540584544","pt":1719496159407,"mc":[{"id":"1.230178309","rc":[{"atb":[[2.64,2.33]],"id":39362025},{"atb":[[2.12,4.26]],"id":44798446}],"con":true,"img":false}]}
{"op":"mcm","clk":"11540584553","pt":1719496159510,"mc":[{"id":"1.230178309","rc":[{"atl":[[4.6,0.84]],"id":40953876}],"con":true,"img":false}]}
{"op":"mcm","clk":"11540584561","pt":1719496159613,"mc":[{"id":"1.230178309","rc":[{"atb":[[2.64,5.91],[2.56,6.35]],"id":39362025}],"con":true,"img":false}]}
{"op":"mcm","clk":"11540584570","pt":1719496159717,"mc":[{"id":"1.230178309","rc":[{"atb":[[2.12,10.83]],"id":44798446},{"atb":[[2.8,13.67]],"id":55829870}],"con":true,"img":false}]}
{"op":"mcm","clk":"11540584577","pt":1719496159819,"mc":[{"id":"1.230178309","rc":[{"atb":[[2.74,19.33]],"id":40953876},{"atb":[[2.52,11.3]],"id":39362025},{"atb":[[2,5.91]],"id":44798446},{"atb":[[2.84,2]],"id":55829870}],"con":true,"img":false}]}
{"op":"mcm","clk":"11540584587","pt":1719496159923,"mc":[{"id":"1.230178309","rc":[{"atb":[[2.7,2.21]],"id":40953876}],"con":true,"img":false}]}
{"op":"mcm","clk":"11540584619","pt":1719496160287,"mc":[{"id":"1.230178309","rc":[{"atb":[[2.8,12.8]],"id":55829870}],"con":true,"img":false}]}
{"op":"mcm","clk":"11540584641","pt":1719496160496,"mc":[{"id":"1.230178309","rc":[{"atb":[[2.8,0]],"id":55829870}],"con":true,"img":false}]}
{"op":"mcm","clk":"11540584652","pt":1719496160602,"mc":[{"id":"1.230178309","rc":[{"atb":[[2.84,14.8]],"id":55829870}],"con":true,"img":false}]}
{"op":"mcm","clk":"11540584666","pt":1719496160702,"mc":[{"id":"1.230178309","rc":[{"atb":[[2.56,2.52]],"id":39362025},{"atb":[[2.36,3]],"id":48500723},{"atb":[[2.76,0]],"id":55829870}],"con":true,"img":false}]}
{"op":"mcm","clk":"11540584690","pt":1719496161010,"mc":[{"id":"1.230178309","rc":[{"atb":[[2.76,3.13]],"id":55829870}],"con":true,"img":false}]}
{"op":"mcm","clk":"11540584797","pt":1719496162102,"mc":[{"id":"1.230178309","rc":[{"atl":[[5.3,1.84]],"id":70218235}],"con":true,"img":false}]}
{"op":"mcm","clk":"11540584816","pt":1719496162309,"mc":[{"id":"1.230178309","rc":[{"atb":[[2.72,6.2]],"id":40953876},{"atl":[[3.55,13.47]],"id":48500723}],"con":true,"img":false}]}
{"op":"mcm","clk":"11540584825","pt":1719496162412,"mc":[{"id":"1.230178309","rc":[{"atl":[[4.6,17.59]],"id":40953876},{"atl":[[2.92,9.46]],"id":44798446}],"con":true,"img":false}]}
{"op":"mcm","clk":"11540584837","pt":1719496162519,"mc":[{"id":"1.230178309","rc":[{"atl":[[3.65,1.72]],"id":48500723}],"con":true,"img":false}]}
{"op":"mcm","clk":"11540584849","pt":1719496162618,"mc":[{"id":"1.230178309","rc":[{"atl":[[4.8,10.27]],"id":40953876},{"atl":[[2.96,0]],"id":44798446}],"con":true,"img":false}]}
{"op":"mcm","clk":"11540584859","pt":1719496162720,"mc":[{"id":"1.230178309","rc":[{"atl":[[4.9,6.26]],"id":39362025}],"con":true,"img":false}]}
{"op":"mcm","clk":"11540584870","pt":1719496162822,"mc":[{"id":"1.230178309","rc":[{"atl":[[3.6,16.68]],"id":48500723}],"con":true,"img":false}]}
{"op":"mcm","clk":"11540584879","pt":1719496162877,"mc":[{"id":"1.230178309","rc":[{"atl":[[5,4.03]],"id":39362025}],"con":true,"img":false}]}
{"op":"mcm","clk":"11540584892","pt":1719496163030,"mc":[{"id":"1.230178309","rc":[{"atb":[[2.36,0]],"id":48500723}],"con":true,"img":false}]}
{"op":"mcm","clk":"11540584902","pt":1719496163083,"mc":[{"id":"1.230178309","rc":[{"atl":[[4.8,9.43]],"id":40953876},{"atl":[[4.8,0.84]],"id":39362025},{"atl":[[3.5,0.84]],"id":48500723}],"con":true,"img":false}]}
{"op":"mcm","clk":"11540584938","pt":1719496163393,"mc":[{"id":"1.230178309","rc":[{"atl":[[4.8,0]],"id":40953876},{"atb":[[2.52,2.64]],"id":39362025},{"atl":[[5,0.84]],"id":39362025},{"atb":[[2.48,13.69]],"id":48500723},{"atl":[[3.65,0]],"id":48500723},{"atb":[[2,2.52]],"id":44798446},{"atl":[[2.94,0]],"id":44798446},{"atl":[[4.6,0]],"id":55829870}],"con":true,"img":false}]}
{"op":"mcm","clk":"11540584947","pt":1719496163496,"mc":[{"id":"1.230178309","rc":[{"atb":[[2.4,7.51]],"id":48500723},{"atl":[[3.5,9.94],[3.65,3.5]],"id":48500723}],"con":true,"img":false}]}
{"op":"mcm","clk":"11540584956","pt":1719496163598,"mc":[{"id":"1.230178309","rc":[{"atl":[[4.6,26.68],[5.5,23.22],[4.7,0]],"id":40953876},{"atb":[[2.64,13.17]],"id":39362025},{"atl":[[4.9,9.25]],"id":39362025},{"atl":[[3.55,14.79]],"id":48500723},{"atl":[[2.92,16.35]],"id":44798446},{"atl":[[4.5,19.94]],"id":55829870}],"con":true,"img":false}]}
{"op":"mcm","clk":"11540584967","pt":1719496163702,"mc":[{"id":"1.230178309","rc":[{"atl":[[4.5,23.22],[5.5,1]],"id":40953876},{"atl":[[3.65,0]],"id":48500723}],"con":true,"img":false}]}
{"op":"mcm","clk":"11540584982","pt":1719496163805,"mc":[{"id":"1.230178309","rc":[{"atl":[[4.9,11.25],[6.6,2.5]],"id":39362025},{"atl":[[3.1,32.7],[4.2,2.5]],"id":44798446}],"con":true,"img":false}]}
{"op":"mcm","clk":"11540585006","pt":1719496164015,"mc":[{"id":"1.230178309","rc":[{"atl":[[3.65,7.5]],"id":48500723},{"atl":[[5.3,0]],"id":70218235},{"atl":[[4.4,19.95]],"id":55829870}],"con":true,"img":false}]}
{"op":"mcm","clk":"11540585018","pt":1719496164114,"mc":[{"id":"1.230178309","rc":[{"atl":[[5,2.5]],"id":55829870}],"con":true,"img":false}]}
{"op":"mcm","clk":"11540585029","pt":1719496164216,"mc":[{"id":"1.230178309","rc":[{"atb":[[2.72,3.2]],"id":40953876},{"atb":[[2.62,0]],"id":39362025},{"atb":[[2.3,4.08]],"id":48500723},{"atl":[[3.6,15.84],[3.65,0]],"id":48500723},{"atb":[[2.1,0]],"id":44798446},{"atb":[[3.15,6.41]],"id":70218235},{"atb":[[2.82,0]],"id":55829870},{"atl":[[4.5,19.5]],"id":55829870}],"con":true,"img":false}]}
{"op":"mcm","clk":"11540585045","pt":1719496164419,"mc":[{"id":"1.230178309","rc":[{"atb":[[2.76,3.9]],"id":40953876},{"atb":[[2.66,3]],"id":39362025},{"atb":[[2.14,3]],"id":44798446},{"atb":[[2.86,2.5],[2.76,0]],"id":55829870}],"con":true,"img":false}]}
{"op":"mcm","clk":"11540585066","pt":1719496164626,"mc":[{"id":"1.230178309","rc":[{"atb":[[2.44,0]],"id":39362025}],"con":true,"img":false}]}
{"op":"mcm","clk":"11540585078","pt":1719496164729,"mc":[{"id":"1.230178309","rc":[{"atl":[[4.5,13.33],[4.3,0.84]],"id":55829870}],"con":true,"img":false}]}
{"op":"mcm","clk":"11540585085","pt":1719496164833,"mc":[{"id":"1.230178309","rc":[{"atl":[[4.4,26.12]],"id":55829870}],"con":true,"img":false}]}
{"op":"mcm","clk":"11540585101","pt":1719496164997,"mc":[{"id":"1.230178309","rc":[{"atb":[[2.84,12.8]],"id":55829870}],"con":true,"img":false}]}
{"op":"mcm","clk":"11540585115","pt":1719496165096,"mc":[{"id":"1.230178309","rc":[{"atb":[[2.74,33.17]],"id":40953876},{"atb":[[2.88,2]],"id":55829870}],"con":true,"img":false}]}
{"op":"mcm","clk":"11540585176","pt":1719496165712,"mc":[{"id":"1.230178309","rc":[{"atb":[[2.74,31.36]],"id":40953876},{"atb":[[2.84,10.99]],"id":55829870}],"con":true,"img":false}]}
{"op":"mcm","clk":"11540585185","pt":1719496165815,"mc":[{"id":"1.230178309","rc":[{"atl":[[4.7,5.5]],"id":40953876}],"con":true,"img":false}]}
{"op":"mcm","clk":"11540585191","pt":1719496165918,"mc":[{"id":"1.230178309","rc":[{"atb":[[2.74,19.33]],"id":40953876},{"atl":[[4.7,0]],"id":40953876},{"atb":[[2.84,0]],"id":55829870}],"con":true,"img":false}]}
{"op":"mcm","clk":"11540585199","pt":1719496166022,"mc":[{"id":"1.230178309","rc":[{"atb":[[2.78,2.04],[2.76,15.93]],"id":40953876},{"atb":[[2.68,2.25]],"id":39362025},{"atb":[[2.16,4.03]],"id":44798446},{"atb":[[2.88,12.99]],"id":55829870}],"con":true,"img":false}]}
{"op":"mcm","clk":"11540585247","pt":1719496166590,"mc":[{"id":"1.230178309","rc":[{"atb":[[2.76,3.9]],"id":40953876},{"atl":[[4.4,0.84]],"id":40953876}],"con":true,"img":false}]}
{"op":"mcm","clk":"11540585261","pt":1719496166699,"mc":[{"id":"1.230178309","rc":[{"atb":[[2.72,0]],"id":40953876},{"atb":[[1.73,8.06],[1.61,0]],"id":44798446}],"con":true,"img":false}]}
{"op":"mcm","clk":"11540585267","pt":1719496166797,"mc":[{"id":"1.230178309","rc":[{"atl":[[6,0]],"id":39362025},{"atb":[[2.16,24.8]],"id":44798446}],"con":true,"img":false}]}
{"op":"mcm","clk":"11540585281","pt":1719496167004,"mc":[{"id":"1.230178309","rc":[{"atb":[[2.68,0]],"id":39362025}],"con":true,"img":false}]}
{"op":"mcm","clk":"11540585290","pt":1719496167105,"mc":[{"id":"1.230178309","rc":[{"atl":[[4.3,12.46]],"id":55829870}],"con":true,"img":false}]}
{"op":"mcm","clk":"11540585301","pt":1719496167207,"mc":[{"id":"1.230178309","rc":[{"atl":[[4.4,6.17],[4.2,13.34]],"id":55829870}],"con":true,"img":false}]}
{"op":"mcm","clk":"11540585313","pt":1719496167309,"mc":[{"id":"1.230178309","rc":[{"atl":[[4.5,6.53]],"id":55829870}],"con":true,"img":false}]}
{"op":"mcm","clk":"11540585324","pt":1719496167414,"mc":[{"id":"1.230178309","rc":[{"atb":[[2.36,6.11],[2.54,2.5]],"id":40953876},{"atl":[[3.6,0],[3.65,29.58]],"id":48500723},{"atb":[[2.74,0],[2.44,11.42]],"id":70218235},{"atl":[[4.4,0]],"id":55829870}],"con":true,"img":false}]}
{"op":"mcm","clk":"11540585332","pt":1719496167516,"mc":[{"id":"1.230178309","rc":[{"atb":[[2.78,16.46]],"id":40953876},{"atl":[[4.4,7.55]],"id":40953876}],"con":true,"img":false}]}
{"op":"mcm","clk":"11540585342","pt":1719496167618,"mc":[{"id":"1.230178309","rc":[{"atl":[[4.5,0],[4.3,23.22]],"id":40953876},{"atb":[[2.48,6],[2.42,0]],"id":39362025},{"atl":[[3.95,0]],"id":48500723},{"atb":[[3.1,0]],"id":70218235}],"con":true,"img":false}]}
{"op":"mcm","clk":"11540585362","pt":1719496167826,"mc":[{"id":"1.230178309","rc":[{"atl":[[4.5,5.68]],"id":55829870}],"con":true,"img":false}]}
{"op":"mcm","clk":"11540585371","pt":1719496167878,"mc":[{"id":"1.230178309","rc":[{"atb":[[3.15,4.41]],"id":70218235}],"con":true,"img":false}]}
{"op":"mcm","clk":"11540585379","pt":1719496167986,"mc":[{"id":"1.230178309","rc":[{"atl":[[4.6,25.83]],"id":40953876},{"atb":[[1.02,2]],"id":70218235}],"con":true,"img":false}]}
{"op":"mcm","clk":"11540585414","pt":1719496168294,"mc":[{"id":"1.230178309","rc":[{"atl":[[4.6,16.75]],"id":40953876},{"atb":[[2.66,7.08]],"id":39362025},{"atb":[[2.4,0]],"id":48500723},{"atl":[[3.55,13.47]],"id":48500723},{"atb":[[2.5,21.33]],"id":70218235},{"atl":[[4.5,0],[4.2,20.59]],"id":55829870}],"con":true,"img":false}]}
{"op":"mcm","clk":"11540585422","pt":1719496168397,"mc":[{"id":"1.230178309","rc":[{"atl":[[4.3,31.7]],"id":40953876},{"atb":[[2.64,9.59]],"id":39362025},{"atb":[[2.48,20.14]],"id":48500723},{"atb":[[2.18,20.38]],"id":44798446},{"atl":[[4.2,25.57]],"id":55829870}],"con":true,"img":false}]}
{"op":"mcm","clk":"11540585431","pt":1719496168502,"mc":[{"id":"1.230178309","rc":[{"atb":[[2.8,22.94]],"id":40953876},{"atb":[[2.12,4.26],[2.2,3.83]],"id":44798446}],"con":true,"img":false}]}
{"op":"mcm","clk":"11540585441","pt":1719496168603,"mc":[{"id":"1.230178309","rc":[{"atb":[[2.74,2.12]],"id":40953876},{"atb":[[2.12,9.02]],"id":44798446}],"con":true,"img":false}]}
{"op":"mcm","clk":"11540585459","pt":1719496168813,"mc":[{"id":"1.230178309","rc":[{"atb":[[2.72,8.83],[2.76,0],[2.78,14.42]],"id":40953876},{"atb":[[2.14,0]],"id":44798446},{"atl":[[5.5,0],[5.4,1]],"id":70218235},{"atb":[[2.86,0]],"id":55829870}],"con":true,"img":false}]}
{"op":"mcm","clk":"11540585480","pt":1719496169017,"mc":[{"id":"1.230178309","rc":[{"atb":[[2.82,4.09]],"id":40953876},{"atb":[[2.2,8.98],[2.16,4.03]],"id":44798446},{"atb":[[2.6,3.2]],"id":70218235},{"atb":[[2.88,2],[2.9,2]],"id":55829870}],"con":true,"img":false}]}
{"op":"mcm","clk":"11540585500","pt":1719496169225,"mc":[{"id":"1.230178309","rc":[{"atb":[[2.72,0]],"id":40953876},{"atb":[[2.12,4.26]],"id":44798446}],"con":true,"img":false}]}
{"op":"mcm","clk":"11540585512","pt":1719496169327,"mc":[{"id":"1.230178309","rc":[{"atb":[[2.74,0]],"id":40953876}],"con":true,"img":false}]}
{"op":"mcm","clk":"11540585542","pt":1719496169586,"mc":[{"id":"1.230178309","rc":[{"atl":[[5.5,1],[5.4,0]],"id":70218235}],"con":true,"img":false}]}
{"op":"mcm","clk":"11540585553","pt":1719496169692,"mc":[{"id":"1.230178309","rc":[{"atb":[[2.5,24.7]],"id":70218235},{"atb":[[2.88,0]],"id":55829870}],"con":true,"img":false}]}
{"op":"mcm","clk":"11540585564","pt":1719496169793,"mc":[{"id":"1.230178309","rc":[{"atb":[[2.24,2.11],[2.06,0]],"id":44798446},{"atb":[[2.92,2]],"id":55829870}],"con":true,"img":false}]}
{"op":"mcm","clk":"11540585574","pt":1719496169898,"mc":[{"id":"1.230178309","rc":[{"atb":[[2.78,11.7]],"id":40953876}],"con":true,"img":false}]}
{"op":"mcm","clk":"11540585585","pt":1719496169999,"mc":[{"id":"1.230178309","rc":[{"atb":[[2.2,28.46]],"id":44798446},{"atb":[[2.9,14.19]],"id":55829870}],"con":true,"img":false}]}
{"op":"mcm","clk":"11540585594","pt":1719496170102,"mc":[{"id":"1.230178309","rc":[{"atb":[[2.78,0]],"id":40953876}],"con":true,"img":false}]}
{"op":"mcm","clk":"11540585608","pt":1719496170206,"mc":[{"id":"1.230178309","rc":[{"atb":[[2.82,15.79]],"id":40953876},{"atb":[[2.14,8.51]],"id":44798446}],"con":true,"img":false}]}
{"op":"mcm","clk":"11540585629","pt":1719496170412,"mc":[{"id":"1.230178309","rc":[{"atb":[[2.14,0]],"id":44798446},{"atl":[[5.3,0]],"id":55829870}],"con":true,"img":false}]}
{"op":"mcm","clk":"11540585639","pt":1719496170515,"mc":[{"id":"1.230178309","rc":[{"atb":[[2.2,27.96]],"id":44798446},{"atb":[[2.9,2]],"id":55829870}],"con":true,"img":false}]}
{"op":"mcm","clk":"11540585660","pt":1719496170719,"mc":[{"id":"1.230178309","rc":[{"atb":[[2.3,0]],"id":48500723},{"atb":[[2.5,21.33]],"id":70218235}],"con":true,"img":false}]}
{"op":"mcm","clk":"11540585681","pt":1719496170926,"mc":[{"id":"1.230178309","rc":[{"atb":[[2.2,8.98]],"id":44798446}],"con":true,"img":false}]}
{"op":"mcm","clk":"11540585693","pt":1719496171028,"mc":[{"id":"1.230178309","rc":[{"atb":[[2.68,2.25]],"id":39362025},{"atl":[[3.45,23.15]],"id":48500723},{"atb":[[2.26,3.55],[2.24,21.09]],"id":44798446}],"con":true,"img":false}]}
{"op":"mcm","clk":"11540585702","pt":1719496171081,"mc":[{"id":"1.230178309","rc":[{"atl":[[4.2,24.4]],"id":40953876}],"con":true,"img":false}]}
{"op":"mcm","clk":"11540585715","pt":1719496171185,"mc":[{"id":"1.230178309","rc":[{"atl":[[4.3,8.48],[4.1,24.4]],"id":40953876},{"atl":[[3.55,0]],"id":48500723}],"con":true,"img":false}]}
{"op":"mcm","clk":"11540585728","pt":1719496171289,"mc":[{"id":"1.230178309","rc":[{"atl":[[4.6,0],[4.1,0],[4.2,48.8]],"id":40953876}],"con":true,"img":false}]}
{"op":"mcm","clk":"11540585736","pt":1719496171391,"mc":[{"id":"1.230178309","rc":[{"atl":[[4.7,7]],"id":39362025},{"atb":[[2.24,19.81]],"id":44798446}],"con":true,"img":false}]}
{"op":"mcm","clk":"11540585745","pt":1719496171495,"mc":[{"id":"1.230178309","rc":[{"atl":[[4.9,4.99]],"id":39362025},{"atl":[[3.4,0.84]],"id":48500723}],"con":true,"img":false}]}
{"op":"mcm","clk":"11540585752","pt":1719496171599,"mc":[{"id":"1.230178309","rc":[{"atl":[[4.4,6.71]],"id":40953876},{"atb":[[2.24,2.11]],"id":44798446}],"con":true,"img":false}]}
{"op":"mcm","clk":"11540585761","pt":1719496171703,"mc":[{"id":"1.230178309","rc":[{"atb":[[2.26,21.25]],"id":44798446}],"con":true,"img":false}]}
{"op":"mcm","clk":"11540585775","pt":1719496171805,"mc":[{"id":"1.230178309","rc":[{"atb":[[1.73,0],[1.8,8.48]],"id":44798446},{"atb":[[2.92,15.35]],"id":55829870}],"con":true,"img":false}]}
{"op":"mcm","clk":"11540585820","pt":1719496172219,"mc":[{"id":"1.230178309","rc":[{"atl":[[5,0],[4.6,0.84]],"id":39362025},{"atl":[[4.1,0.84]],"id":55829870}],"con":true,"img":false}]}
{"op":"mcm","clk":"11540585881","pt":1719496172791,"mc":[{"id":"1.230178309","rc":[{"atl":[[3.95,1]],"id":48500723},{"atl":[[3.05,32.7]],"id":44798446}],"con":true,"img":false}]}
{"op":"mcm","clk":"11540585890","pt":1719496172893,"mc":[{"id":"1.230178309","rc":[{"atl":[[3.1,0]],"id":44798446}],"con":true,"img":false}]}
{"op":"mcm","clk":"11540585906","pt":1719496173101,"mc":[{"id":"1.230178309","rc":[{"atl":[[4.3,0]],"id":40953876},{"atb":[[2.64,2.33]],"id":39362025},{"atl":[[4.9,2]],"id":39362025}],"con":true,"img":false}]}
{"op":"mcm","clk":"11540585918","pt":1719496173204,"mc":[{"id":"1.230178309","rc":[{"atl":[[4.2,57.05]],"id":40953876},{"atb":[[2.66,14.13]],"id":39362025},{"atl":[[4.7,9.59]],"id":39362025}],"con":true,"img":false}]}
{"op":"mcm","clk":"11540585932","pt":1719496173410,"mc":[{"id":"1.230178309","rc":[{"atl":[[4.9,0],[4.7,11.59]],"id":39362025}],"con":true,"img":false}]}
{"op":"mcm","clk":"11540585962","pt":1719496173719,"mc":[{"id":"1.230178309","rc":[{"atb":[[2.66,11.13]],"id":39362025},{"atb":[[2.2,3.83]],"id":44798446},{"atb":[[2.9,0]],"id":55829870}],"con":true,"img":false}]}
{"op":"mcm","clk":"11540585971","pt":1719496173823,"mc":[{"id":"1.230178309","rc":[{"atb":[[2.68,5.15]],"id":39362025},{"atb":[[2.28,3.57]],"id":44798446},{"atb":[[2.94,3.7]],"id":55829870}],"con":true,"img":false}]}
{"op":"mcm","clk":"11540585981","pt":1719496173926,"mc":[{"id":"1.230178309","rc":[{"atb":[[2.3,3.38]],"id":44798446}],"con":true,"img":false}]}
{"op":"mcm","clk":"11540586003","pt":1719496174138,"mc":[{"id":"1.230178309","rc":[{"atl":[[4.1,0.84]],"id":40953876}],"con":true,"img":false}]}
{"op":"mcm","clk":"11540586072","pt":1719496174803,"mc":[{"id":"1.230178309","rc":[{"atb":[[2.26,3.55]],"id":44798446},{"atl":[[3.1,3.75]],"id":44798446},{"atb":[[2.92,10.72]],"id":55829870}],"con":true,"img":false}]}
{"op":"mcm","clk":"11540586080","pt":1719496174905,"mc":[{"id":"1.230178309","rc":[{"atb":[[2.92,0],[2.96,2]],"id":55829870}],"con":true,"img":false}]}
{"op":"mcm","clk":"11540586088","pt":1719496175008,"mc":[{"id":"1.230178309","rc":[{"atb":[[2.94,14.42]],"id":55829870}],"con":true,"img":false}]}
{"op":"mcm","clk":"11540586122","pt":1719496175418,"mc":[{"id":"1.230178309","rc":[{"atl":[[3.1,0]],"id":44798446}],"con":true,"img":false}]}
{"op":"mcm","clk":"11540586137","pt":1719496175625,"mc":[{"id":"1.230178309","rc":[{"atb":[[2.94,3.7]],"id":55829870}],"con":true,"img":false}]}
{"op":"mcm","clk":"11540586144","pt":1719496175727,"mc":[{"id":"1.230178309","rc":[{"atb":[[2.66,14.5]],"id":39362025},{"atb":[[2.3,19.84]],"id":44798446},{"atl":[[4.1,11.72]],"id":55829870}],"con":true,"img":false}]}
{"op":"mcm","clk":"11540586153","pt":1719496175830,"mc":[{"id":"1.230178309","rc":[{"atl":[[4,12.47],[4.2,12.23]],"id":55829870}],"con":true,"img":false}]}
{"op":"mcm","clk":"11540586163","pt":1719496175935,"mc":[{"id":"1.230178309","rc":[{"atl":[[5.5,0],[5.4,1]],"id":70218235},{"atl":[[4.3,0.84]],"id":55829870}],"con":true,"img":false}]}
{"op":"mcm","clk":"11540586173","pt":1719496175989,"mc":[{"id":"1.230178309","rc":[{"atl":[[4,0],[4.2,36.43]],"id":55829870}],"con":true,"img":false}]}
{"op":"mcm","clk":"11540586192","pt":1719496176196,"mc":[{"id":"1.230178309","rc":[{"atl":[[4.3,0]],"id":55829870}],"con":true,"img":false}]}
{"op":"mcm","clk":"11540586212","pt":1719496176400,"mc":[{"id":"1.230178309","rc":[{"atl":[[4.2,36.19]],"id":55829870}],"con":true,"img":false}]}
{"op":"mcm","clk":"11540586230","pt":1719496176605,"mc":[{"id":"1.230178309","rc":[{"atl":[[4.2,29.18]],"id":55829870}],"con":true,"img":false}]}
{"op":"mcm","clk":"11540586241","pt":1719496176709,"mc":[{"id":"1.230178309","rc":[{"atb":[[2.96,12.35]],"id":55829870},{"atl":[[4.1,18.73]],"id":55829870}],"con":true,"img":false}]}
{"op":"mcm","clk":"11540586261","pt":1719496176915,"mc":[{"id":"1.230178309","rc":[{"atb":[[2.68,10.76]],"id":39362025},{"atl":[[4,18.74],[4.2,4.98]],"id":55829870}],"con":true,"img":false}]}
{"op":"mcm","clk":"11540586275","pt":1719496177018,"mc":[{"id":"1.230178309","rc":[{"atb":[[2.84,16.88]],"id":40953876},{"atb":[[2.66,10.42]],"id":39362025},{"atb":[[2.32,14.94]],"id":44798446}],"con":true,"img":false}]}
{"op":"mcm","clk":"11540586305","pt":1719496177226,"mc":[{"id":"1.230178309","rc":[{"atb":[[2.82,4.09],[2.8,0],[2.78,3.07]],"id":40953876},{"atb":[[2.3,3.38],[2.34,3.22],[2.18,0]],"id":44798446},{"atl":[[4.1,11.72]],"id":55829870}],"con":true,"img":false}]}
{"op":"mcm","clk":"11540586326","pt":1719496177431,"mc":[{"id":"1.230178309","rc":[{"atb":[[2.78,0]],"id":40953876}],"con":true,"img":false}]}
{"op":"mcm","clk":"11540586378","pt":1719496177794,"mc":[{"id":"1.230178309","rc":[{"atb":[[2.66,3.37]],"id":39362025},{"atl":[[4.2,0]],"id":55829870}],"con":true,"img":false}]}
{"op":"mcm","clk":"11540586395","pt":1719496177899,"mc":[{"id":"1.230178309","rc":[{"atb":[[2.62,0]],"id":40953876},{"atb":[[2.58,0]],"id":39362025},{"atb":[[2.46,0]],"id":48500723},{"atb":[[2.24,0]],"id":44798446},{"atb":[[2.56,0]],"id":70218235},{"atb":[[1.5,0]],"id":55829870}],"con":true,"img":false}]}
{"op":"mcm","clk":"11540586407","pt":1719496178002,"mc":[{"id":"1.230178309","rc":[{"atb":[[2.68,17.6]],"id":39362025},{"atl":[[4,23.17]],"id":55829870}],"con":true,"img":false}]}
{"op":"mcm","clk":"11540586426","pt":1719496178103,"mc":[{"id":"1.230178309","rc":[{"atb":[[2.84,28.78]],"id":40953876},{"atb":[[2.34,21.26]],"id":44798446},{"atl":[[4,31.29],[6.8,1],[7,0]],"id":55829870}],"con":true,"img":false}]}
{"op":"mcm","clk":"11540586463","pt":1719496178418,"mc":[{"id":"1.230178309","rc":[{"atb":[[2.82,0]],"id":40953876},{"atb":[[2.68,14.7]],"id":39362025},{"atb":[[2.28,0]],"id":44798446},{"atb":[[2.94,0]],"id":55829870}],"con":true,"img":false}]}
{"op":"mcm","clk":"11540586476","pt":1719496178521,"mc":[{"id":"1.230178309","rc":[{"atb":[[2.86,4.43]],"id":40953876},{"atb":[[2.7,4]],"id":39362025},{"atb":[[2.36,3]],"id":44798446},{"atb":[[2.98,2.5]],"id":55829870}],"con":true,"img":false}]}
{"op":"mcm","clk":"11540586503","pt":1719496178727,"mc":[{"id":"1.230178309","rc":[{"atb":[[2.38,3.08]],"id":44798446}],"con":true,"img":false}]}
{"op":"mcm","clk":"11540586545","pt":1719496179037,"mc":[{"id":"1.230178309","rc":[{"atb":[[2.84,16.88]],"id":40953876},{"atb":[[2.3,4.08]],"id":48500723},{"atb":[[2.34,21.06]],"id":44798446},{"atb":[[2.96,2]],"id":55829870}],"con":true,"img":false}]}
{"op":"mcm","clk":"11540586567","pt":1719496179195,"mc":[{"id":"1.230178309","rc":[{"atb":[[2.34,3.22]],"id":44798446}],"con":true,"img":false}]}
{"op":"mcm","clk":"11540586577","pt":1719496179295,"mc":[{"id":"1.230178309","rc":[{"atb":[[2.36,20.84]],"id":44798446}],"con":true,"img":false}]}
{"op":"mcm","clk":"11540586584","pt":1719496179400,"mc":[{"id":"1.230178309","rc":[{"atb":[[2.96,0]],"id":55829870}],"con":true,"img":false}]}
{"op":"mcm","clk":"11540586592","pt":1719496179502,"mc":[{"id":"1.230178309","rc":[{"atb":[[1.02,24.66]],"id":55829870},{"atl":[[3.95,0.84]],"id":55829870}],"con":true,"img":false}]}
{"op":"mcm","clk":"11540586600","pt":1719496179605,"mc":[{"id":"1.230178309","rc":[{"atl":[[4.1,9.2]],"id":40953876}],"con":true,"img":false}]}
{"op":"mcm","clk":"11540586626","pt":1719496179815,"mc":[{"id":"1.230178309","rc":[{"atb":[[2.36,20.03]],"id":44798446}],"con":true,"img":false}]}
{"op":"mcm","clk":"11540586635","pt":1719496179918,"mc":[{"id":"1.230178309","rc":[{"atb":[[2.86,18.11]],"id":40953876}],"con":true,"img":false}]}
{"op":"mcm","clk":"11540586642","pt":1719496180016,"mc":[{"id":"1.230178309","rc":[{"atl":[[4,9.21],[4.2,32.65]],"id":40953876},{"atl":[[4.5,5.53]],"id":39362025}],"con":true,"img":false}]}
{"op":"mcm","clk":"11540586656","pt":1719496180121,"mc":[{"id":"1.230178309","rc":[{"atl":[[4.2,8.25]],"id":40953876},{"atb":[[2.36,3]],"id":44798446}],"con":true,"img":false}]}
{"op":"mcm","clk":"11540586665","pt":1719496180225,"mc":[{"id":"1.230178309","rc":[{"atl":[[4.7,4.59]],"id":39362025},{"atb":[[2.38,20.11]],"id":44798446}],"con":true,"img":false}]}
{"op":"mcm","clk":"11540586698","pt":1719496180532,"mc":[{"id":"1.230178309","rc":[{"atl":[[4.4,0]],"id":40953876}],"con":true,"img":false}]}
{"op":"mcm","clk":"11540586705","pt":1719496180636,"mc":[{"id":"1.230178309","rc":[{"atl":[[4.8,0],[4.4,0.84]],"id":39362025}],"con":true,"img":false}]}
{"op":"mcm","clk":"11540586764","pt":1719496181208,"mc":[{"id":"1.230178309","rc":[{"atl":[[4,16.34]],"id":40953876}],"con":true,"img":false}]}
{"op":"mcm","clk":"11540586793","pt":1719496181519,"mc":[{"id":"1.230178309","rc":[{"atl":[[3.95,0.84]],"id":40953876}],"con":true,"img":false}]}
{"op":"mcm","clk":"11540586883","pt":1719496182344,"mc":[{"id":"1.230178309","rc":[{"atb":[[2.66,0]],"id":39362025}],"con":true,"img":false}]}
{"op":"mcm","clk":"11540586907","pt":1719496182604,"mc":[{"id":"1.230178309","rc":[{"atl":[[4.2,0]],"id":40953876},{"atl":[[4.7,2]],"id":39362025},{"atl":[[4,26.85]],"id":55829870}],"con":true,"img":false}]}
{"op":"mcm","clk":"11540586921","pt":1719496182810,"mc":[{"id":"1.230178309","rc":[{"atl":[[4,24.1]],"id":40953876},{"atl":[[4.5,7.67]],"id":39362025}],"con":true,"img":false}]}
{"op":"mcm","clk":"11540586929","pt":1719496182914,"mc":[{"id":"1.230178309","rc":[{"atl":[[4.5,9.67],[4.7,0]],"id":39362025}],"con":true,"img":false}]}
{"op":"mcm","clk":"11540586959","pt":1719496183222,"mc":[{"id":"1.230178309","rc":[{"atl":[[3.95,0]],"id":48500723},{"atb":[[2.34,7.21],[2.36,0]],"id":44798446},{"atb":[[2.98,0]],"id":55829870}],"con":true,"img":false}]}
{"op":"mcm","clk":"11540586971","pt":1719496183327,"mc":[{"id":"1.230178309","rc":[{"atb":[[2.4,3]],"id":44798446},{"atb":[[2.8,2.57]],"id":55829870}],"con":true,"img":false}]}
{"op":"mcm","clk":"11540586984","pt":1719496183430,"mc":[{"id":"1.230178309","rc":[{"atb":[[2.42,2.94]],"id":44798446},{"atb":[[2.82,1.97],[2.78,0]],"id":55829870}],"con":true,"img":false}]}
{"op":"mcm","clk":"11540587045","pt":1719496184102,"mc":[{"id":"1.230178309","rc":[{"atb":[[2.38,18.35]],"id":44798446},{"atb":[[1.02,22.66]],"id":55829870},{"atl":[[3.95,4.87]],"id":55829870}],"con":true,"img":false}]}
{"op":"mcm","clk":"11540587057","pt":1719496184209,"mc":[{"id":"1.230178309","rc":[{"atb":[[2.5,24.7]],"id":70218235},{"atb":[[2.82,17.39]],"id":55829870},{"atl":[[4.1,0.84]],"id":55829870}],"con":true,"img":false}]}
{"op":"mcm","clk":"11540587074","pt":1719496184415,"mc":[{"id":"1.230178309","rc":[{"atb":[[2.38,3.08]],"id":44798446}],"con":true,"img":false}]}
{"op":"mcm","clk":"11540587082","pt":1719496184515,"mc":[{"id":"1.230178309","rc":[{"atb":[[2.42,18.21]],"id":44798446}],"con":true,"img":false}]}
{"op":"mcm","clk":"11540587097","pt":1719496184620,"mc":[{"id":"1.230178309","rc":[{"atl":[[4.1,0]],"id":55829870}],"con":true,"img":false}]}
{"op":"mcm","clk":"11540587106","pt":1719496184720,"mc":[{"id":"1.230178309","rc":[{"atb":[[2.36,3.5]],"id":44798446}],"con":true,"img":false}]}
{"op":"mcm","clk":"11540587117","pt":1719496184824,"mc":[{"id":"1.230178309","rc":[{"atb":[[2.34,3.22]],"id":44798446},{"atb":[[2.8,5.61]],"id":55829870}],"con":true,"img":false}]}
{"op":"mcm","clk":"11540587169","pt":1719496185337,"mc":[{"id":"1.230178309","rc":[{"atb":[[2.7,8.75]],"id":39362025},{"atl":[[4,25.77]],"id":55829870}],"con":true,"img":false}]}
{"op":"mcm","clk":"11540587181","pt":1719496185440,"mc":[{"id":"1.230178309","rc":[{"atl":[[4.2,3.24]],"id":55829870}],"con":true,"img":false}]}
{"op":"mcm","clk":"11540587195","pt":1719496185544,"mc":[{"id":"1.230178309","rc":[{"atb":[[2.32,5],[2.68,9.09]],"id":39362025},{"atb":[[1.8,0],[1.91,7.38]],"id":44798446},{"atl":[[5.3,1],[5.4,0]],"id":70218235}],"con":true,"img":false}]}
{"op":"mcm","clk":"11540587212","pt":1719496185648,"mc":[{"id":"1.230178309","rc":[{"atl":[[5.5,0]],"id":40953876},{"atb":[[2.36,0]],"id":44798446},{"atl":[[5.6,1]],"id":70218235},{"atl":[[4,18.73],[4.2,0]],"id":55829870}],"con":true,"img":false}]}
{"op":"mcm","clk":"11540587223","pt":1719496185700,"mc":[{"id":"1.230178309","rc":[{"atl":[[4,0],[5.6,1],[3.95,11.91],[6.8,0],[4.2,23.62]],"id":55829870}],"con":true,"img":false}]}
{"op":"mcm","clk":"11540587237","pt":1719496185804,"mc":[{"id":"1.230178309","rc":[{"atl":[[5.3,0]],"id":70218235},{"atl":[[3.9,11.92],[4.2,0]],"id":55829870}],"con":true,"img":false}]}
{"op":"mcm","clk":"11540587260","pt":1719496186019,"mc":[{"id":"1.230178309","rc":[{"atb":[[2.7,10.96]],"id":39362025}],"con":true,"img":false}]}
{"op":"mcm","clk":"11540587323","pt":1719496186627,"mc":[{"id":"1.230178309","rc":[{"atl":[[3.85,0.84]],"id":55829870}],"con":true,"img":false}]}
{"op":"mcm","clk":"11540587333","pt":1719496186729,"mc":[{"id":"1.230178309","rc":[{"atl":[[3.95,4.87]],"id":55829870}],"con":true,"img":false}]}
{"op":"mcm","clk":"11540587342","pt":1719496186833,"mc":[{"id":"1.230178309","rc":[{"atl":[[3.95,17.64],[3.9,0]],"id":55829870}],"con":true,"img":false}]}
{"op":"mcm","clk":"11540587405","pt":1719496187402,"mc":[{"id":"1.230178309","rc":[{"atb":[[2.68,2.25]],"id":39362025}],"con":true,"img":false}]}
{"op":"mcm","clk":"11540587419","pt":1719496187606,"mc":[{"id":"1.230178309","rc":[{"atb":[[2.7,17.6]],"id":39362025},{"atl":[[3.95,21.93]],"id":55829870}],"con":true,"img":false}]}
{"op":"mcm","clk":"11540587428","pt":1719496187712,"mc":[{"id":"1.230178309","rc":[{"atl":[[3.85,0],[3.9,7.56]],"id":55829870}],"con":true,"img":false}]}
{"op":"mcm","clk":"11540587443","pt":1719496187913,"mc":[{"id":"1.230178309","rc":[{"atb":[[2.4,0]],"id":44798446},{"atb":[[2.8,3.04]],"id":55829870}],"con":true,"img":false}]}
{"op":"mcm","clk":"11540587452","pt":1719496188018,"mc":[{"id":"1.230178309","rc":[{"atl":[[3.95,20.41]],"id":40953876},{"atb":[[2.44,2]],"id":44798446},{"atb":[[2.84,2.88]],"id":55829870}],"con":true,"img":false}]}
{"op":"mcm","clk":"11540587463","pt":1719496188121,"mc":[{"id":"1.230178309","rc":[{"atl":[[4.1,0.84]],"id":40953876},{"atb":[[2.46,2.81]],"id":44798446},{"atb":[[2.86,1.9]],"id":55829870}],"con":true,"img":false}]}
{"op":"mcm","clk":"11540587471","pt":1719496188224,"mc":[{"id":"1.230178309","rc":[{"atb":[[2.84,0]],"id":40953876},{"atb":[[2.42,16.95]],"id":44798446},{"atb":[[2.82,16.58],[2.8,0],[2.34,0]],"id":55829870}],"con":true,"img":false}]}
{"op":"mcm","clk":"11540587481","pt":1719496188328,"mc":[{"id":"1.230178309","rc":[{"atl":[[4.3,3.44]],"id":39362025},{"atb":[[2.3,0]],"id":48500723},{"atb":[[2.42,2.94]],"id":44798446},{"atb":[[2.82,3.97]],"id":55829870}],"con":true,"img":false}]}
{"op":"mcm","clk":"11540587488","pt":1719496188431,"mc":[{"id":"1.230178309","rc":[{"atl":[[4.5,4.14]],"id":39362025},{"atb":[[2.44,16.01]],"id":44798446},{"atb":[[2.84,15.49]],"id":55829870}],"con":true,"img":false}]}
{"op":"mcm","clk":"11540587507","pt":1719496188637,"mc":[{"id":"1.230178309","rc":[{"atl":[[4.1,0]],"id":40953876}],"con":true,"img":false}]}
{"op":"mcm","clk":"11540587543","pt":1719496189003,"mc":[{"id":"1.230178309","rc":[{"atb":[[2.86,4.43]],"id":40953876},{"atl":[[4.6,0],[4.2,0.84]],"id":39362025},{"atb":[[2.44,2]],"id":44798446},{"atb":[[2.82,1.97],[2.84,14.41]],"id":55829870}],"con":true,"img":false}]}
{"op":"mcm","clk":"11540587551","pt":1719496189106,"mc":[{"id":"1.230178309","rc":[{"atb":[[2.86,3.9]],"id":55829870}],"con":true,"img":false}]}
{"op":"mcm","clk":"11540587579","pt":1719496189416,"mc":[{"id":"1.230178309","rc":[{"atb":[[2.84,2.88]],"id":55829870}],"con":true,"img":false}]}
{"op":"mcm","clk":"11540587588","pt":1719496189518,"mc":[{"id":"1.230178309","rc":[{"atb":[[2.7,29.99]],"id":39362025},{"atl":[[4.3,9.81]],"id":39362025},{"atb":[[2.86,15.43]],"id":55829870}],"con":true,"img":false}]}
{"op":"mcm","clk":"11540587599","pt":1719496189620,"mc":[{"id":"1.230178309","rc":[{"atl":[[4.3,13.96],[4.5,2.14]],"id":39362025}],"con":true,"img":false}]}
{"op":"mcm","clk":"11540587611","pt":1719496189725,"mc":[{"id":"1.230178309","rc":[{"atb":[[2.62,5.72]],"id":39362025}],"con":true,"img":false}]}
{"op":"mcm","clk":"11540587629","pt":1719496189929,"mc":[{"id":"1.230178309","rc":[{"atb":[[2.62,0],[2.68,5.58]],"id":39362025},{"atb":[[2.46,19.98]],"id":44798446}],"con":true,"img":false}]}
{"op":"mcm","clk":"11540587692","pt":1719496190548,"mc":[{"id":"1.230178309","rc":[{"atb":[[2.7,0]],"id":40953876}],"con":true,"img":false}]}
{"op":"mcm","clk":"11540587708","pt":1719496190757,"mc":[{"id":"1.230178309","rc":[{"spl":[[1.01,5.43]],"id":39362025}],"con":true,"img":false}]}
{"op":"mcm","clk":"11540587813","pt":1719496191812,"mc":[{"id":"1.230178309","rc":[{"atb":[[1.07,6.73]],"id":40953876},{"atb":[[1.98,0],[1.94,0]],"id":44798446}],"con":true,"img":false}]}
{"op":"mcm","clk":"11540587825","pt":1719496192018,"mc":[{"id":"1.230178309","rc":[{"atl":[[3.85,7.56],[3.95,9.16]],"id":55829870}],"con":true,"img":false}]}
{"op":"mcm","clk":"11540587838","pt":1719496192226,"mc":[{"id":"1.230178309","rc":[{"atl":[[3.9,0]],"id":55829870}],"con":true,"img":false}]}
{"op":"mcm","clk":"11540587846","pt":1719496192328,"mc":[{"id":"1.230178309","rc":[{"atl":[[4,16.34]],"id":40953876},{"atl":[[4.5,0]],"id":39362025},{"atl":[[3.85,11.34],[3.95,4.87],[3.9,15.12]],"id":55829870}],"con":true,"img":false}]}
{"op":"mcm","clk":"11540587857","pt":1719496192434,"mc":[{"id":"1.230178309","rc":[{"atl":[[3.95,28.04]],"id":40953876},{"atl":[[4.3,15.6]],"id":39362025},{"atl":[[3.95,0.84],[3.9,19.25]],"id":55829870}],"con":true,"img":false}]}
{"op":"mcm","clk":"11540587867","pt":1719496192536,"mc":[{"id":"1.230178309","rc":[{"atb":[[2.86,0]],"id":40953876},{"atl":[[4,7.12],[3.95,44.38]],"id":40953876},{"atb":[[2.44,0]],"id":44798446},{"atb":[[2.84,0]],"id":55829870}],"con":true,"img":false}]}
{"op":"mcm","clk":"11540587878","pt":1719496192641,"mc":[{"id":"1.230178309","rc":[{"atb":[[2.56,2.52]],"id":40953876},{"atb":[[2.36,2.5],[2.28,5],[2.2,10]],"id":55829870},{"atl":[[3.95,0]],"id":55829870}],"con":true,"img":false}]}
{"op":"mcm","clk":"11540587885","pt":1719496192742,"mc":[{"id":"1.230178309","rc":[{"atb":[[2.36,0],[1.07,5.95]],"id":40953876}],"con":true,"img":false}]}
{"op":"mcm","clk":"11540587896","pt":1719496192848,"mc":[{"id":"1.230178309","rc":[{"atb":[[2.56,6.52],[1.79,8.61],[2.54,8.96]],"id":40953876},{"atb":[[2.48,3.61]],"id":44798446},{"atb":[[2.88,3]],"id":55829870}],"con":true,"img":false}]}
{"op":"mcm","clk":"11540587906","pt":1719496192954,"mc":[{"id":"1.230178309","rc":[{"atb":[[1.79,0],[2.38,5.95],[1.07,2.48]],"id":40953876},{"atb":[[2.5,2.69]],"id":44798446},{"atl":[[5.5,1]],"id":70218235},{"atb":[[2.9,1.83]],"id":55829870},{"atl":[[5.6,0]],"id":55829870}],"con":true,"img":false}]}
{"op":"mcm","clk":"11540587919","pt":1719496193009,"mc":[{"id":"1.230178309","rc":[{"atb":[[2.3,4.05]],"id":48500723},{"atb":[[2.46,19.59]],"id":44798446},{"atl":[[5.6,0]],"id":70218235},{"atb":[[2.86,14.77]],"id":55829870}],"con":true,"img":false}]}
{"op":"mcm","clk":"11540587930","pt":1719496193114,"mc":[{"id":"1.230178309","rc":[{"atl":[[5.5,0]],"id":70218235}],"con":true,"img":false}]}
{"op":"mcm","clk":"11540587941","pt":1719496193216,"mc":[{"id":"1.230178309","rc":[{"atb":[[2.46,2.81]],"id":44798446},{"spl":[[1.01,4]],"id":70218235},{"atb":[[2.86,3.9]],"id":55829870}],"con":true,"img":false}]}
{"op":"mcm","clk":"11540587949","pt":1719496193319,"mc":[{"id":"1.230178309","rc":[{"atb":[[2.48,20.39]],"id":44798446},{"atb":[[2.5,21.33]],"id":70218235},{"atb":[[2.88,13.87]],"id":55829870}],"con":true,"img":false}]}
{"op":"mcm","clk":"11540587958","pt":1719496193422,"mc":[{"id":"1.230178309","rc":[{"atl":[[5.6,1]],"id":70218235},{"atl":[[3.85,18.77]],"id":55829870}],"con":true,"img":false}]}
{"op":"mcm","clk":"11540587977","pt":1719496193629,"mc":[{"id":"1.230178309","rc":[{"atl":[[6,0],[6.8,0],[7.6,0],[5.7,2.5]],"id":70218235}],"con":true,"img":false}]}
{"op":"mcm","clk":"11540588000","pt":1719496193836,"mc":[{"id":"1.230178309","rc":[{"atb":[[2.48,18.05]],"id":44798446},{"atb":[[2.88,3]],"id":55829870}],"con":true,"img":false}]}
{"op":"mcm","clk":"11540588010","pt":1719496193940,"mc":[{"id":"1.230178309","rc":[{"atb":[[2.48,3.61]],"id":44798446}],"con":true,"img":false}]}
{"op":"mcm","clk":"11540588022","pt":1719496194042,"mc":[{"id":"1.230178309","rc":[{"atb":[[2.5,17.13]],"id":44798446}],"con":true,"img":false}]}
{"op":"mcm","clk":"11540588033","pt":1719496194146,"mc":[{"id":"1.230178309","rc":[{"atb":[[2.86,1.9]],"id":55829870},{"atl":[[3.8,0.84]],"id":55829870}],"con":true,"img":false}]}
{"op":"mcm","clk":"11540588042","pt":1719496194248,"mc":[{"id":"1.230178309","rc":[{"atb":[[2.9,3.83]],"id":55829870}],"con":true,"img":false}]}
{"op":"mcm","clk":"11540588052","pt":1719496194353,"mc":[{"id":"1.230178309","rc":[{"atb":[[2.24,0],[2.28,24.19]],"id":48500723},{"atb":[[1.97,7.22],[1.91,0]],"id":44798446},{"atl":[[5.6,0],[5.7,3.5]],"id":70218235}],"con":true,"img":false}]}
{"op":"mcm","clk":"11540588074","pt":1719496194510,"mc":[{"id":"1.230178309","rc":[{"atb":[[2.3,0]],"id":48500723}],"con":true,"img":false}]}
{"op":"mcm","clk":"11540588085","pt":1719496194611,"mc":[{"id":"1.230178309","rc":[{"atb":[[2.9,14.42]],"id":55829870}],"con":true,"img":false}]}
{"op":"mcm","clk":"11540588203","pt":1719496195951,"mc":[{"id":"1.230178309","rc":[{"spl":[[1.01,4]],"id":40953876}],"con":true,"img":false}]}
{"op":"mcm","clk":"11540588256","pt":1719496196419,"mc":[{"id":"1.230178309","rc":[{"atl":[[4.2,6.77]],"id":39362025}],"con":true,"img":false}]}
{"op":"mcm","clk":"11540588274","pt":1719496196626,"mc":[{"id":"1.230178309","rc":[{"atl":[[4.3,5.79]],"id":39362025}],"con":true,"img":false}]}
{"op":"mcm","clk":"11540588308","pt":1719496197038,"mc":[{"id":"1.230178309","rc":[{"atl":[[4.3,4.15]],"id":39362025},{"atl":[[3.9,15.12]],"id":55829870}],"con":true,"img":false}]}
{"op":"mcm","clk":"11540588315","pt":1719496197141,"mc":[{"id":"1.230178309","rc":[{"atl":[[4.3,0],[4.4,10.93],[4.2,8.14]],"id":39362025},{"atb":[[2.46,6.47]],"id":44798446},{"atl":[[3.85,22.74]],"id":55829870}],"con":true,"img":false}]}
{"op":"mcm","clk":"11540588334","pt":1719496197349,"mc":[{"id":"1.230178309","rc":[{"atl":[[4.2,15.47]],"id":39362025},{"atb":[[2.48,0]],"id":44798446},{"atb":[[2.88,0]],"id":55829870}],"con":true,"img":false}]}
{"op":"mcm","clk":"11540588343","pt":1719496197451,"mc":[{"id":"1.230178309","rc":[{"atb":[[2.92,3.73]],"id":55829870},{"atl":[[3.8,15.96],[3.9,0]],"id":55829870}],"con":true,"img":false}]}
{"op":"mcm","clk":"11540588354","pt":1719496197554,"mc":[{"id":"1.230178309","rc":[{"atb":[[2.94,1.77]],"id":55829870}],"con":true,"img":false}]}
{"op":"mcm","clk":"11540588403","pt":1719496198020,"mc":[{"id":"1.230178309","rc":[{"atb":[[2.52,3.34]],"id":70218235}],"con":true,"img":false}]}
{"op":"mcm","clk":"11540588416","pt":1719496198121,"mc":[{"id":"1.230178309","rc":[{"atb":[[2.9,12.42]],"id":55829870}],"con":true,"img":false}]}
{"op":"mcm","clk":"11540588427","pt":1719496198227,"mc":[{"id":"1.230178309","rc":[{"atb":[[2.94,3.77]],"id":55829870}],"con":true,"img":false}]}
