{"op":"mcm","clk":"11536832971","pt":1719431775486,"mc":[{"id":"1.230180117","marketDefinition":{"bspMarket":true,"turnInPlayEnabled":false,"persistenceEnabled":false,"marketBaseRate":5.0,"eventId":"33376437","eventTypeId":"4339","numberOfWinners":2,"bettingType":"ODDS","marketType":"PLACE","marketTime":"2024-06-27T14:11:00.000Z","suspendTime":"2024-06-27T14:11:00.000Z","bspReconciled":false,"complete":true,"inPlay":false,"crossMatching":false,"runnersVoidable":false,"numberOfActiveRunners":6,"betDelay":0,"status":"OPEN","runners":[{"status":"ACTIVE","sortPriority":1,"id":48536142,"name":"1. Liz Of Rhyl"},{"status":"ACTIVE","sortPriority":2,"id":64253836,"name":"2. Keeperhill Fagan"},{"status":"ACTIVE","sortPriority":3,"id":68900945,"name":"3. Salacres Elmejor"},{"status":"ACTIVE","sortPriority":4,"id":69366841,"name":"4. Fleurs Gamble"},{"status":"ACTIVE","sortPriority":5,"id":63031611,"name":"5. Greencroft Oscar"},{"status":"ACTIVE","sortPriority":6,"id":40831161,"name":"6. Milton Mia"}],"regulators":["MR_INT"],"venue":"Towcester","countryCode":"GB","discountAllowed":false,"timezone":"Europe/London","openDate":"2024-06-27T13:33:00.000Z","version":5994767062,"name":"To Be Placed","eventName":"Towcester 27th Jun"},"rc":[],"con":true,"img":false}]}
{"op":"mcm","clk":"11536833110","pt":1719431777486,"mc":[{"id":"1.230180117","marketDefinition":{"bspMarket":true,"turnInPlayEnabled":false,"persistenceEnabled":false,"marketBaseRate":5.0,"eventId":"33376437","eventTypeId":"4339","numberOfWinners":2,"bettingType":"ODDS","marketType":"PLACE","marketTime":"2024-06-27T14:11:00.000Z","suspendTime":"2024-06-27T14:11:00.000Z","bspReconciled":false,"complete":true,"inPlay":false,"crossMatching":false,"runnersVoidable":false,"numberOfActiveRunners":6,"betDelay":0,"status":"OPEN","runners":[{"status":"ACTIVE","sortPriority":1,"id":48536142,"name":"1. Liz Of Rhyl"},{"status":"ACTIVE","sortPriority":2,"id":64253836,"name":"2. Keeperhill Fagan"},{"status":"ACTIVE","sortPriority":3,"id":68900945,"name":"3. Salacres Elmejor"},{"status":"ACTIVE","sortPriority":4,"id":69366841,"name":"4. Fleurs Gamble"},{"status":"ACTIVE","sortPriority":5,"id":63031611,"name":"5. Greencroft Oscar"},{"status":"ACTIVE","sortPriority":6,"id":40831161,"name":"6. Milton Mia"}],"regulators":["MR_INT"],"venue":"Towcester","countryCode":"GB","discountAllowed":true,"timezone":"Europe/London","openDate":"2024-06-27T13:33:00.000Z","version":5994767062,"name":"To Be Placed","eventName":"Towcester 27th Jun"},"rc":[],"con":true,"img":false}]}
{"op":"mcm","clk":"11537084025","pt":1719435435929,"mc":[{"id":"1.230180117","rc":[{"atb":[[1.03,10.99]],"id":63031611},{"atl":[[990,0.84]],"id":63031611},{"spn":495.51,"spf":"NaN","id":63031611},{"atb":[[1.01,32.96]],"id":69366841},{"atl":[[990,0.84]],"id":69366841},{"spn":495.5,"spf":"NaN","id":69366841},{"atb":[[1.03,10.99]],"id":40831161},{"atl":[[1000,0.84]],"id":40831161},{"spn":500.51,"spf":"NaN","id":40831161},{"atb":[[1.01,32.96]],"id":64253836},{"atl":[[1000,0.84]],"id":64253836},{"spn":500.5,"spf":"NaN","id":64253836},{"atb":[[1.03,10.99]],"id":48536142},{"atl":[[1000,0.84]],"id":48536142},{"spn":500.51,"spf":"NaN","id":48536142},{"atb":[[1.03,10.99]],"id":68900945},{"atl":[[1000,0.84]],"id":68900945},{"spn":500.51,"spf":"NaN","id":68900945}],"con":true,"img":false}]}
{"op":"mcm","clk":"11537233726","pt":1719437882649,"mc":[{"id":"1.230180117","marketDefinition":{"bspMarket":true,"turnInPlayEnabled":false,"persistenceEnabled":false,"marketBaseRate":5.0,"eventId":"33376437","eventTypeId":"4339","numberOfWinners":2,"bettingType":"ODDS","marketType":"PLACE","marketTime":"2024-06-27T14:11:00.000Z","suspendTime":"2024-06-27T14:11:00.000Z","bspReconciled":false,"complete":true,"inPlay":false,"crossMatching":false,"runnersVoidable":false,"numberOfActiveRunners":6,"betDelay":0,"status":"OPEN","runners":[{"status":"ACTIVE","sortPriority":1,"id":48536142,"name":"1. Liz Of Rhyl"},{"status":"ACTIVE","sortPriority":2,"id":64253836,"name":"2. Keeperhill Fagan"},{"status":"ACTIVE","sortPriority":3,"id":68900945,"name":"3. Salacres Elmejor"},{"status":"ACTIVE","sortPriority":4,"id":69366841,"name":"4. Fleurs Gamble"},{"status":"ACTIVE","sortPriority":5,"id":63031611,"name":"5. Greencroft Oscar"},{"status":"ACTIVE","sortPriority":6,"id":40831161,"name":"6. Milton Mia"}],"regulators":["MR_INT"],"venue":"Towcester","countryCode":"GB","discountAllowed":true,"timezone":"Europe/London","openDate":"2024-06-27T13:33:00.000Z","version":5994767062,"name":"To Be Placed","eventName":"Towcester 27th Jun"},"rc":[{"atb":[[1.03,10.99]],"id":63031611},{"atl":[[990,0.84]],"id":63031611},{"spn":495.51,"spf":"NaN","id":63031611},{"atb":[[1.01,32.96]],"id":69366841},{"atl":[[990,0.84]],"id":69366841},{"spn":495.5,"spf":"NaN","id":69366841},{"atb":[[1.03,10.99]],"id":40831161},{"atl":[[1000,0.84]],"id":40831161},{"spn":500.51,"spf":"NaN","id":40831161},{"atb":[[1.01,32.96]],"id":64253836},{"atl":[[1000,0.84]],"id":64253836},{"spn":500.5,"spf":"NaN","id":64253836},{"atb":[[1.03,10.99]],"id":48536142},{"atl":[[1000,0.84]],"id":48536142},{"spn":500.51,"spf":"NaN","id":48536142},{"atb":[[1.03,10.99]],"id":68900945},{"atl":[[1000,0.84]],"id":68900945},{"spn":500.51,"spf":"NaN","id":68900945}],"con":true,"img":true}]}
{"op":"mcm","clk":"11537302304","pt":1719439034346,"mc":[{"id":"1.230180117","rc":[{"atb":[[1.03,10.99]],"id":63031611},{"atl":[[990,0.17]],"id":63031611},{"atb":[[1.01,32.96]],"id":69366841},{"atl":[[990,0.17]],"id":69366841},{"atb":[[1.03,10.99]],"id":40831161},{"atl":[[1000,0.17]],"id":40831161},{"atb":[[1.01,32.96]],"id":64253836},{"atl":[[1000,0.17]],"id":64253836},{"atb":[[1.03,10.99]],"id":48536142},{"atl":[[1000,0.17]],"id":48536142},{"atb":[[1.03,10.99]],"id":68900945},{"atl":[[1000,0.17]],"id":68900945}],"con":true,"img":false}]}
{"op":"mcm","clk":"11537574874","pt":1719443282700,"mc":[{"id":"1.230180117","marketDefinition":{"bspMarket":true,"turnInPlayEnabled":false,"persistenceEnabled":false,"marketBaseRate":5.0,"eventId":"33376437","eventTypeId":"4339","numberOfWinners":2,"bettingType":"ODDS","marketType":"PLACE","marketTime":"2024-06-27T14:11:00.000Z","suspendTime":"2024-06-27T14:11:00.000Z","bspReconciled":false,"complete":true,"inPlay":false,"crossMatching":false,"runnersVoidable":false,"numberOfActiveRunners":6,"betDelay":0,"status":"OPEN","runners":[{"status":"ACTIVE","sortPriority":1,"id":48536142,"name":"1. Liz Of Rhyl"},{"status":"ACTIVE","sortPriority":2,"id":64253836,"name":"2. Keeperhill Fagan"},{"status":"ACTIVE","sortPriority":3,"id":68900945,"name":"3. Salacres Elmejor"},{"status":"ACTIVE","sortPriority":4,"id":69366841,"name":"4. Fleurs Gamble"},{"status":"ACTIVE","sortPriority":5,"id":63031611,"name":"5. Greencroft Oscar"},{"status":"ACTIVE","sortPriority":6,"id":40831161,"name":"6. Milton Mia"}],"regulators":["MR_INT"],"venue":"Towcester","countryCode":"GB","discountAllowed":true,"timezone":"Europe/London","openDate":"2024-06-27T13:33:00.000Z","version":5994767062,"name":"To Be Placed","eventName":"Towcester 27th Jun"},"rc":[{"atb":[[1.03,10.99]],"id":63031611},{"atl":[[990,0.17]],"id":63031611},{"spn":495.51,"spf":"NaN","id":63031611},{"atb":[[1.01,32.96]],"id":69366841},{"atl":[[990,0.17]],"id":69366841},{"spn":495.5,"spf":"NaN","id":69366841},{"atb":[[1.03,10.99]],"id":40831161},{"atl":[[1000,0.17]],"id":40831161},{"spn":500.51,"spf":"NaN","id":40831161},{"atb":[[1.01,32.96]],"id":64253836},{"atl":[[1000,0.17]],"id":64253836},{"spn":500.5,"spf":"NaN","id":64253836},{"atb":[[1.03,10.99]],"id":48536142},{"atl":[[1000,0.17]],"id":48536142},{"spn":500.51,"spf":"NaN","id":48536142},{"atb":[[1.03,10.99]],"id":68900945},{"atl":[[1000,0.17]],"id":68900945},{"spn":500.51,"spf":"NaN","id":68900945}],"con":true,"img":true}]}
{"op":"mcm","clk":"11537956494","pt":1719448682741,"mc":[{"id":"1.230180117","marketDefinition":{"bspMarket":true,"turnInPlayEnabled":false,"persistenceEnabled":false,"marketBaseRate":5.0,"eventId":"33376437","eventTypeId":"4339","numberOfWinners":2,"bettingType":"ODDS","marketType":"PLACE","marketTime":"2024-06-27T14:11:00.000Z","suspendTime":"2024-06-27T14:11:00.000Z","bspReconciled":false,"complete":true,"inPlay":false,"crossMatching":false,"runnersVoidable":false,"numberOfActiveRunners":6,"betDelay":0,"status":"OPEN","runners":[{"status":"ACTIVE","sortPriority":1,"id":48536142,"name":"1. Liz Of Rhyl"},{"status":"ACTIVE","sortPriority":2,"id":64253836,"name":"2. Keeperhill Fagan"},{"status":"ACTIVE","sortPriority":3,"id":68900945,"name":"3. Salacres Elmejor"},{"status":"ACTIVE","sortPriority":4,"id":69366841,"name":"4. Fleurs Gamble"},{"status":"ACTIVE","sortPriority":5,"id":63031611,"name":"5. Greencroft Oscar"},{"status":"ACTIVE","sortPriority":6,"id":40831161,"name":"6. Milton Mia"}],"regulators":["MR_INT"],"venue":"Towcester","countryCode":"GB","discountAllowed":true,"timezone":"Europe/London","openDate":"2024-06-27T13:33:00.000Z","version":5994767062,"name":"To Be Placed","eventName":"Towcester 27th Jun"},"rc":[{"atb":[[1.03,10.99]],"id":63031611},{"atl":[[990,0.17]],"id":63031611},{"spn":495.51,"spf":"NaN","id":63031611},{"atb":[[1.01,32.96]],"id":69366841},{"atl":[[990,0.17]],"id":69366841},{"spn":495.5,"spf":"NaN","id":69366841},{"atb":[[1.03,10.99]],"id":40831161},{"atl":[[1000,0.17]],"id":40831161},{"spn":500.51,"spf":"NaN","id":40831161},{"atb":[[1.01,32.96]],"id":64253836},{"atl":[[1000,0.17]],"id":64253836},{"spn":500.5,"spf":"NaN","id":64253836},{"atb":[[1.03,10.99]],"id":48536142},{"atl":[[1000,0.17]],"id":48536142},{"spn":500.51,"spf":"NaN","id":48536142},{"atb":[[1.03,10.99]],"id":68900945},{"atl":[[1000,0.17]],"id":68900945},{"spn":500.51,"spf":"NaN","id":68900945}],"con":true,"img":true}]}
{"op":"mcm","clk":"11538172111","pt":1719454082684,"mc":[{"id":"1.230180117","marketDefinition":{"bspMarket":true,"turnInPlayEnabled":false,"persistenceEnabled":false,"marketBaseRate":5.0,"eventId":"33376437","eventTypeId":"4339","numberOfWinners":2,"bettingType":"ODDS","marketType":"PLACE","marketTime":"2024-06-27T14:11:00.000Z","suspendTime":"2024-06-27T14:11:00.000Z","bspReconciled":false,"complete":true,"inPlay":false,"crossMatching":false,"runnersVoidable":false,"numberOfActiveRunners":6,"betDelay":0,"status":"OPEN","runners":[{"status":"ACTIVE","sortPriority":1,"id":48536142,"name":"1. Liz Of Rhyl"},{"status":"ACTIVE","sortPriority":2,"id":64253836,"name":"2. Keeperhill Fagan"},{"status":"ACTIVE","sortPriority":3,"id":68900945,"name":"3. Salacres Elmejor"},{"status":"ACTIVE","sortPriority":4,"id":69366841,"name":"4. Fleurs Gamble"},{"status":"ACTIVE","sortPriority":5,"id":63031611,"name":"5. Greencroft Oscar"},{"status":"ACTIVE","sortPriority":6,"id":40831161,"name":"6. Milton Mia"}],"regulators":["MR_INT"],"venue":"Towcester","countryCode":"GB","discountAllowed":true,"timezone":"Europe/London","openDate":"2024-06-27T13:33:00.000Z","version":5994767062,"name":"To Be Placed","eventName":"Towcester 27th Jun"},"rc":[{"atb":[[1.03,10.99]],"id":63031611},{"atl":[[990,0.17]],"id":63031611},{"spn":495.51,"spf":"NaN","id":63031611},{"atb":[[1.01,32.97]],"id":69366841},{"atl":[[990,0.17]],"id":69366841},{"spn":495.5,"spf":"NaN","id":69366841},{"atb":[[1.03,10.99]],"id":40831161},{"atl":[[1000,0.17]],"id":40831161},{"spn":500.51,"spf":"NaN","id":40831161},{"atb":[[1.01,32.97]],"id":64253836},{"atl":[[1000,0.17]],"id":64253836},{"spn":500.5,"spf":"NaN","id":64253836},{"atb":[[1.03,10.99]],"id":48536142},{"atl":[[1000,0.17]],"id":48536142},{"spn":500.51,"spf":"NaN","id":48536142},{"atb":[[1.03,10.99]],"id":68900945},{"atl":[[1000,0.17]],"id":68900945},{"spn":500.51,"spf":"NaN","id":68900945}],"con":true,"img":true}]}
{"op":"mcm","clk":"11538369778","pt":1719459482769,"mc":[{"id":"1.230180117","marketDefinition":{"bspMarket":true,"turnInPlayEnabled":false,"persistenceEnabled":false,"marketBaseRate":5.0,"eventId":"33376437","eventTypeId":"4339","numberOfWinners":2,"bettingType":"ODDS","marketType":"PLACE","marketTime":"2024-06-27T14:11:00.000Z","suspendTime":"2024-06-27T14:11:00.000Z","bspReconciled":false,"complete":true,"inPlay":false,"crossMatching":false,"runnersVoidable":false,"numberOfActiveRunners":6,"betDelay":0,"status":"OPEN","runners":[{"status":"ACTIVE","sortPriority":1,"id":48536142,"name":"1. Liz Of Rhyl"},{"status":"ACTIVE","sortPriority":2,"id":64253836,"name":"2. Keeperhill Fagan"},{"status":"ACTIVE","sortPriority":3,"id":68900945,"name":"3. Salacres Elmejor"},{"status":"ACTIVE","sortPriority":4,"id":69366841,"name":"4. Fleurs Gamble"},{"status":"ACTIVE","sortPriority":5,"id":63031611,"name":"5. Greencroft Oscar"},{"status":"ACTIVE","sortPriority":6,"id":40831161,"name":"6. Milton Mia"}],"regulators":["MR_INT"],"venue":"Towcester","countryCode":"GB","discountAllowed":true,"timezone":"Europe/London","openDate":"2024-06-27T13:33:00.000Z","version":5994767062,"name":"To Be Placed","eventName":"Towcester 27th Jun"},"rc":[{"atb":[[1.03,10.99]],"id":63031611},{"atl":[[990,0.17]],"id":63031611},{"spn":495.51,"spf":"NaN","id":63031611},{"atb":[[1.01,32.97]],"id":69366841},{"atl":[[990,0.17]],"id":69366841},{"spn":495.5,"spf":"NaN","id":69366841},{"atb":[[1.03,10.99]],"id":40831161},{"atl":[[1000,0.17]],"id":40831161},{"spn":500.51,"spf":"NaN","id":40831161},{"atb":[[1.01,32.97]],"id":64253836},{"atl":[[1000,0.17]],"id":64253836},{"spn":500.5,"spf":"NaN","id":64253836},{"atb":[[1.03,10.99]],"id":48536142},{"atl":[[1000,0.17]],"id":48536142},{"spn":500.51,"spf":"NaN","id":48536142},{"atb":[[1.03,10.99]],"id":68900945},{"atl":[[1000,0.17]],"id":68900945},{"spn":500.51,"spf":"NaN","id":68900945}],"con":true,"img":true}]}
{"op":"mcm","clk":"11538596908","pt":1719464882713,"mc":[{"id":"1.230180117","marketDefinition":{"bspMarket":true,"turnInPlayEnabled":false,"persistenceEnabled":false,"marketBaseRate":5.0,"eventId":"33376437","eventTypeId":"4339","numberOfWinners":2,"bettingType":"ODDS","marketType":"PLACE","marketTime":"2024-06-27T14:11:00.000Z","suspendTime":"2024-06-27T14:11:00.000Z","bspReconciled":false,"complete":true,"inPlay":false,"crossMatching":false,"runnersVoidable":false,"numberOfActiveRunners":6,"betDelay":0,"status":"OPEN","runners":[{"status":"ACTIVE","sortPriority":1,"id":48536142,"name":"1. Liz Of Rhyl"},{"status":"ACTIVE","sortPriority":2,"id":64253836,"name":"2. Keeperhill Fagan"},{"status":"ACTIVE","sortPriority":3,"id":68900945,"name":"3. Salacres Elmejor"},{"status":"ACTIVE","sortPriority":4,"id":69366841,"name":"4. Fleurs Gamble"},{"status":"ACTIVE","sortPriority":5,"id":63031611,"name":"5. Greencroft Oscar"},{"status":"ACTIVE","sortPriority":6,"id":40831161,"name":"6. Milton Mia"}],"regulators":["MR_INT"],"venue":"Towcester","countryCode":"GB","discountAllowed":true,"timezone":"Europe/London","openDate":"2024-06-27T13:33:00.000Z","version":5994767062,"name":"To Be Placed","eventName":"Towcester 27th Jun"},"rc":[{"atb":[[1.03,10.99]],"id":63031611},{"atl":[[990,0.17]],"id":63031611},{"spn":495.51,"spf":"NaN","id":63031611},{"atb":[[1.01,32.97]],"id":69366841},{"atl":[[990,0.17]],"id":69366841},{"spn":495.5,"spf":"NaN","id":69366841},{"atb":[[1.03,10.99]],"id":40831161},{"atl":[[1000,0.17]],"id":40831161},{"spn":500.51,"spf":"NaN","id":40831161},{"atb":[[1.01,32.97]],"id":64253836},{"atl":[[1000,0.17]],"id":64253836},{"spn":500.5,"spf":"NaN","id":64253836},{"atb":[[1.03,10.99]],"id":48536142},{"atl":[[1000,0.17]],"id":48536142},{"spn":500.51,"spf":"NaN","id":48536142},{"atb":[[1.03,10.99]],"id":68900945},{"atl":[[1000,0.17]],"id":68900945},{"spn":500.51,"spf":"NaN","id":68900945}],"con":true,"img":true}]}
{"op":"mcm","clk":"11538906770","pt":1719471499300,"mc":[{"id":"1.230180117","rc":[{"atb":[[1.03,10.99]],"id":63031611},{"atl":[[1000,1]],"id":63031611},{"atb":[[1.01,32.97]],"id":69366841},{"atl":[[1000,1]],"id":69366841},{"atb":[[1.03,10.99]],"id":40831161},{"atl":[[1000,1.17]],"id":40831161},{"atb":[[1.01,32.97]],"id":64253836},{"atl":[[1000,1.17]],"id":64253836},{"atb":[[1.03,10.99]],"id":48536142},{"atl":[[1000,1.17]],"id":48536142},{"atb":[[1.03,10.99]],"id":68900945},{"atl":[[1000,1.17]],"id":68900945}],"con":true,"img":false}]}
{"op":"mcm","clk":"11538906777","pt":1719471499404,"mc":[{"id":"1.230180117","rc":[{"atb":[[1.07,2.48]],"id":63031611},{"atb":[[1.07,2.48]],"id":69366841},{"atb":[[1.07,2.48]],"id":40831161},{"atb":[[1.07,2.48]],"id":64253836},{"atb":[[1.07,2.48]],"id":48536142},{"atb":[[1.07,2.48]],"id":68900945}],"con":true,"img":false}]}
{"op":"mcm","clk":"11538906785","pt":1719471499517,"mc":[{"id":"1.230180117","rc":[{"atl":[[1000,0.48]],"id":63031611},{"atl":[[1000,0.48]],"id":69366841},{"atl":[[1000,0.65]],"id":40831161},{"atl":[[1000,0.65]],"id":64253836},{"atl":[[1000,0.65]],"id":48536142},{"atl":[[1000,0.65]],"id":68900945}],"con":true,"img":false}]}
{"op":"mcm","clk":"11538906798","pt":1719471499718,"mc":[{"id":"1.230180117","rc":[{"atl":[[1000,0]],"id":63031611},{"atl":[[1000,0]],"id":69366841},{"atl":[[1000,0.17]],"id":40831161},{"atl":[[1000,0.17]],"id":64253836},{"atl":[[1000,0.17]],"id":48536142},{"atl":[[1000,0.17]],"id":68900945}],"con":true,"img":false}]}
{"op":"mcm","clk":"11538906803","pt":1719471499819,"mc":[{"id":"1.230180117","rc":[{"atl":[[75,0.48]],"id":63031611},{"atl":[[75,0.48]],"id":69366841},{"atl":[[75,0.48]],"id":40831161},{"atl":[[75,0.48]],"id":64253836},{"atl":[[75,0.48]],"id":48536142},{"atl":[[75,0.48]],"id":68900945}],"con":true,"img":false}]}
{"op":"mcm","clk":"11539124096","pt":1719475682700,"mc":[{"id":"1.230180117","marketDefinition":{"bspMarket":true,"turnInPlayEnabled":false,"persistenceEnabled":false,"marketBaseRate":5.0,"eventId":"33376437","eventTypeId":"4339","numberOfWinners":2,"bettingType":"ODDS","marketType":"PLACE","marketTime":"2024-06-27T14:11:00.000Z","suspendTime":"2024-06-27T14:11:00.000Z","bspReconciled":false,"complete":true,"inPlay":false,"crossMatching":false,"runnersVoidable":false,"numberOfActiveRunners":6,"betDelay":0,"status":"OPEN","runners":[{"status":"ACTIVE","sortPriority":1,"id":48536142,"name":"1. Liz Of Rhyl"},{"status":"ACTIVE","sortPriority":2,"id":64253836,"name":"2. Keeperhill Fagan"},{"status":"ACTIVE","sortPriority":3,"id":68900945,"name":"3. Salacres Elmejor"},{"status":"ACTIVE","sortPriority":4,"id":69366841,"name":"4. Fleurs Gamble"},{"status":"ACTIVE","sortPriority":5,"id":63031611,"name":"5. Greencroft Oscar"},{"status":"ACTIVE","sortPriority":6,"id":40831161,"name":"6. Milton Mia"}],"regulators":["MR_INT"],"venue":"Towcester","countryCode":"GB","discountAllowed":true,"timezone":"Europe/London","openDate":"2024-06-27T13:33:00.000Z","version":5994767062,"name":"To Be Placed","eventName":"Towcester 27th Jun"},"rc":[{"atb":[[1.03,10.99],[1.07,2.48]],"id":63031611},{"atl":[[75,0.48],[990,0.17]],"id":63031611},{"spn":38.03,"spf":"NaN","id":63031611},{"atb":[[1.01,32.96],[1.07,2.48]],"id":69366841},{"atl":[[75,0.48],[990,0.17]],"id":69366841},{"spn":38.03,"spf":"NaN","id":69366841},{"atb":[[1.03,10.99],[1.07,2.48]],"id":40831161},{"atl":[[75,0.48],[1000,0.17]],"id":40831161},{"spn":38.03,"spf":"NaN","id":40831161},{"atb":[[1.01,32.96],[1.07,2.48]],"id":64253836},{"atl":[[75,0.48],[1000,0.17]],"id":64253836},{"spn":38.03,"spf":"NaN","id":64253836},{"atb":[[1.03,10.99],[1.07,2.48]],"id":48536142},{"atl":[[75,0.48],[1000,0.17]],"id":48536142},{"spn":38.03,"spf":"NaN","id":48536142},{"atb":[[1.03,10.99],[1.07,2.48]],"id":68900945},{"atl":[[75,0.48],[1000,0.17]],"id":68900945},{"spn":38.03,"spf":"NaN","id":68900945}],"con":true,"img":true}]}
{"op":"mcm","clk":"11539440200","pt":1719481082674,"mc":[{"id":"1.230180117","marketDefinition":{"bspMarket":true,"turnInPlayEnabled":false,"persistenceEnabled":false,"marketBaseRate":5.0,"eventId":"33376437","eventTypeId":"4339","numberOfWinners":2,"bettingType":"ODDS","marketType":"PLACE","marketTime":"2024-06-27T14:11:00.000Z","suspendTime":"2024-06-27T14:11:00.000Z","bspReconciled":false,"complete":true,"inPlay":false,"crossMatching":false,"runnersVoidable":false,"numberOfActiveRunners":6,"betDelay":0,"status":"OPEN","runners":[{"status":"ACTIVE","sortPriority":1,"id":48536142,"name":"1. Liz Of Rhyl"},{"status":"ACTIVE","sortPriority":2,"id":64253836,"name":"2. Keeperhill Fagan"},{"status":"ACTIVE","sortPriority":3,"id":68900945,"name":"3. Salacres Elmejor"},{"status":"ACTIVE","sortPriority":4,"id":69366841,"name":"4. Fleurs Gamble"},{"status":"ACTIVE","sortPriority":5,"id":63031611,"name":"5. Greencroft Oscar"},{"status":"ACTIVE","sortPriority":6,"id":40831161,"name":"6. Milton Mia"}],"regulators":["MR_INT"],"venue":"Towcester","countryCode":"GB","discountAllowed":true,"timezone":"Europe/London","openDate":"2024-06-27T13:33:00.000Z","version":5994767062,"name":"To Be Placed","eventName":"Towcester 27th Jun"},"rc":[{"atb":[[1.03,10.98],[1.07,2.48]],"id":63031611},{"atl":[[75,0.48],[990,0.17]],"id":63031611},{"spn":38.03,"spf":"NaN","id":63031611},{"atb":[[1.01,32.95],[1.07,2.48]],"id":69366841},{"atl":[[75,0.48],[990,0.17]],"id":69366841},{"spn":38.03,"spf":"NaN","id":69366841},{"atb":[[1.03,10.98],[1.07,2.48]],"id":40831161},{"atl":[[75,0.48],[1000,0.17]],"id":40831161},{"spn":38.03,"spf":"NaN","id":40831161},{"atb":[[1.01,32.95],[1.07,2.48]],"id":64253836},{"atl":[[75,0.48],[1000,0.17]],"id":64253836},{"spn":38.03,"spf":"NaN","id":64253836},{"atb":[[1.03,10.98],[1.07,2.48]],"id":48536142},{"atl":[[75,0.48],[1000,0.17]],"id":48536142},{"spn":38.03,"spf":"NaN","id":48536142},{"atb":[[1.03,10.98],[1.07,2.48]],"id":68900945},{"atl":[[75,0.48],[1000,0.17]],"id":68900945},{"spn":38.03,"spf":"NaN","id":68900945}],"con":true,"img":true}]}
{"op":"mcm","clk":"11540543268","pt":1719495722164,"mc":[{"id":"1.230180117","rc":[{"atb":[[1.03,11],[1.04,1]],"id":63031611},{"atl":[[990,0.17]],"id":63031611},{"spn":38.03,"spf":"NaN","id":63031611},{"atb":[[1.01,32.99],[1.04,1]],"id":69366841},{"atl":[[990,0.17]],"id":69366841},{"spn":38.03,"spf":"NaN","id":69366841},{"atb":[[1.03,11],[1.04,1]],"id":40831161},{"atl":[[1000,0.17]],"id":40831161},{"spn":38.03,"spf":"NaN","id":40831161},{"atb":[[1.01,32.99],[1.04,1]],"id":64253836},{"atl":[[1000,0.17]],"id":64253836},{"spn":38.03,"spf":"NaN","id":64253836},{"atb":[[1.03,11],[1.04,1]],"id":48536142},{"atl":[[1000,0.17]],"id":48536142},{"spn":38.03,"spf":"NaN","id":48536142},{"atb":[[1.03,11],[1.04,1]],"id":68900945},{"atl":[[1000,0.17]],"id":68900945},{"spn":38.03,"spf":"NaN","id":68900945}],"con":true,"img":false}]}
{"op":"mcm","clk":"11540543285","pt":1719495722382,"mc":[{"id":"1.230180117","rc":[{"atb":[[1.04,0.25]],"id":63031611},{"atb":[[1.04,0.25]],"id":69366841},{"atb":[[1.04,0.25]],"id":40831161},{"atb":[[1.04,0.25]],"id":64253836},{"atb":[[1.04,0.25]],"id":48536142},{"atb":[[1.04,0.25]],"id":68900945}],"con":true,"img":false}]}
{"op":"mcm","clk":"11540543296","pt":1719495722581,"mc":[{"id":"1.230180117","rc":[{"atb":[[1.04,0]],"id":63031611},{"atb":[[1.04,0]],"id":69366841},{"atb":[[1.04,0]],"id":40831161},{"atb":[[1.04,0]],"id":64253836},{"atb":[[1.04,0]],"id":48536142},{"atb":[[1.04,0]],"id":68900945}],"con":true,"img":false}]}
{"op":"mcm","clk":"11540543301","pt":1719495722687,"mc":[{"id":"1.230180117","rc":[{"atb":[[1.2,0.25]],"id":63031611},{"atb":[[1.2,0.25]],"id":69366841},{"atb":[[1.2,0.25]],"id":40831161},{"atb":[[1.2,0.25]],"id":64253836},{"atb":[[1.2,0.25]],"id":48536142},{"atb":[[1.2,0.25]],"id":68900945}],"con":true,"img":false}]}
{"op":"mcm","clk":"11540550409","pt":1719495800485,"mc":[{"id":"1.230180117","rc":[{"spn":38.1,"spf":"NaN","id":63031611},{"spn":38.1,"spf":"NaN","id":69366841},{"atb":[[1.09,47.05]],"id":40831161},{"spn":38.1,"spf":"NaN","id":40831161},{"spn":38.1,"spf":"NaN","id":64253836},{"spn":38.1,"spf":"NaN","id":48536142},{"spn":38.1,"spf":"NaN","id":68900945}],"con":true,"img":false}]}
{"op":"mcm","clk":"11540557507","pt":1719495876437,"mc":[{"id":"1.230180117","rc":[{"atb":[[1.11,35.9]],"id":40831161}],"con":true,"img":false}]}
{"op":"mcm","clk":"11540557765","pt":1719495879226,"mc":[{"id":"1.230180117","rc":[{"atb":[[1.09,0]],"id":40831161}],"con":true,"img":false}]}
{"op":"mcm","clk":"11540557875","pt":1719495880772,"mc":[{"id":"1.230180117","rc":[{"atb":[[1.13,32.57]],"id":40831161}],"con":true,"img":false}]}
{"op":"mcm","clk":"11540559027","pt":1719495893386,"mc":[{"id":"1.230180117","rc":[{"atb":[[1.11,0]],"id":40831161}],"con":true,"img":false}]}
{"op":"mcm","clk":"11540559089","pt":1719495893964,"mc":[{"id":"1.230180117","rc":[{"atb":[[1.15,26.33]],"id":40831161}],"con":true,"img":false}]}
{"op":"mcm","clk":"11540560932","pt":1719495911889,"mc":[{"id":"1.230180117","marketDefinition":{"bspMarket":true,"turnInPlayEnabled":false,"persistenceEnabled":false,"marketBaseRate":5.0,"eventId":"33376437","eventTypeId":"4339","numberOfWinners":2,"bettingType":"ODDS","marketType":"PLACE","marketTime":"2024-06-27T14:11:00.000Z","suspendTime":"2024-06-27T14:11:00.000Z","bspReconciled":false,"complete":true,"inPlay":false,"crossMatching":true,"runnersVoidable":false,"numberOfActiveRunners":6,"betDelay":0,"status":"OPEN","runners":[{"status":"ACTIVE","sortPriority":1,"id":48536142,"name":"1. Liz Of Rhyl"},{"status":"ACTIVE","sortPriority":2,"id":64253836,"name":"2. Keeperhill Fagan"},{"status":"ACTIVE","sortPriority":3,"id":68900945,"name":"3. Salacres Elmejor"},{"status":"ACTIVE","sortPriority":4,"id":69366841,"name":"4. Fleurs Gamble"},{"status":"ACTIVE","sortPriority":5,"id":63031611,"name":"5. Greencroft Oscar"},{"status":"ACTIVE","sortPriority":6,"id":40831161,"name":"6. Milton Mia"}],"regulators":["MR_INT"],"venue":"Towcester","countryCode":"GB","discountAllowed":true,"timezone":"Europe/London","openDate":"2024-06-27T13:33:00.000Z","version":5994767062,"name":"To Be Placed","eventName":"Towcester 27th Jun"},"rc":[],"con":true,"img":false}]}
{"op":"mcm","clk":"11540561451","pt":1719495916998,"mc":[{"id":"1.230180117","rc":[{"atb":[[1.13,0]],"id":40831161}],"con":true,"img":false}]}
{"op":"mcm","clk":"11540561629","pt":1719495918767,"mc":[{"id":"1.230180117","rc":[{"atb":[[1.17,24.9]],"id":40831161}],"con":true,"img":false}]}
{"op":"mcm","clk":"11540562792","pt":1719495929879,"mc":[{"id":"1.230180117","rc":[{"atb":[[1.15,0]],"id":40831161}],"con":true,"img":false}]}
{"op":"mcm","clk":"11540562882","pt":1719495930702,"mc":[{"id":"1.230180117","rc":[{"atb":[[1.19,20.79]],"id":40831161}],"con":true,"img":false}]}
{"op":"mcm","clk":"11540565375","pt":1719495956448,"mc":[{"id":"1.230180117","rc":[{"atb":[[1.17,0]],"id":40831161}],"con":true,"img":false}]}
{"op":"mcm","clk":"11540565500","pt":1719495957741,"mc":[{"id":"1.230180117","rc":[{"atb":[[1.21,20.16]],"id":40831161}],"con":true,"img":false}]}
{"op":"mcm","clk":"11540566534","pt":1719495969033,"mc":[{"id":"1.230180117","rc":[{"atb":[[1.19,0]],"id":40831161}],"con":true,"img":false}]}
{"op":"mcm","clk":"11540566604","pt":1719495969760,"mc":[{"id":"1.230180117","rc":[{"atb":[[1.23,17.17]],"id":40831161}],"con":true,"img":false}]}
{"op":"mcm","clk":"11540568967","pt":1719495995097,"mc":[{"id":"1.230180117","rc":[{"atb":[[1.21,0]],"id":40831161}],"con":true,"img":false}]}
{"op":"mcm","clk":"11540569016","pt":1719495995677,"mc":[{"id":"1.230180117","rc":[{"atb":[[1.25,16.93]],"id":40831161}],"con":true,"img":false}]}
{"op":"mcm","clk":"11540569101","pt":1719495996702,"mc":[{"id":"1.230180117","rc":[{"atb":[[1.14,2]],"id":40831161}],"con":true,"img":false}]}
{"op":"mcm","clk":"11540569740","pt":1719496004699,"mc":[{"id":"1.230180117","rc":[{"atb":[[1.14,0]],"id":40831161}],"con":true,"img":false}]}
{"op":"mcm","clk":"11540570020","pt":1719496007897,"mc":[{"id":"1.230180117","rc":[{"atb":[[1.23,0]],"id":40831161}],"con":true,"img":false}]}
{"op":"mcm","clk":"11540570067","pt":1719496008414,"mc":[{"id":"1.230180117","rc":[{"atb":[[1.27,14.63]],"id":40831161}],"con":true,"img":false}]}
{"op":"mcm","clk":"11540572251","pt":1719496033441,"mc":[{"id":"1.230180117","rc":[{"atb":[[1.25,0]],"id":40831161},{"spn":38.13,"spf":"NaN","id":40831161}],"con":true,"img":false}]}
{"op":"mcm","clk":"11540572345","pt":1719496034422,"mc":[{"id":"1.230180117","rc":[{"atb":[[1.29,14.6]],"id":40831161}],"con":true,"img":false}]}
{"op":"mcm","clk":"11540573208","pt":1719496043753,"mc":[{"id":"1.230180117","rc":[{"atb":[[1.27,0]],"id":40831161}],"con":true,"img":false}]}
{"op":"mcm","clk":"11540573251","pt":1719496044332,"mc":[{"id":"1.230180117","rc":[{"atb":[[1.31,12.74]],"id":40831161}],"con":true,"img":false}]}
{"op":"mcm","clk":"11540576029","pt":1719496074090,"mc":[{"id":"1.230180117","rc":[{"atb":[[1.29,0]],"id":40831161}],"con":true,"img":false}]}
{"op":"mcm","clk":"11540576053","pt":1719496074395,"mc":[{"id":"1.230180117","rc":[{"atb":[[1.33,12.83]],"id":40831161}],"con":true,"img":false}]}
{"op":"mcm","clk":"11540576675","pt":1719496080321,"mc":[{"id":"1.230180117","rc":[{"atb":[[1.31,0]],"id":40831161}],"con":true,"img":false}]}
{"op":"mcm","clk":"11540576742","pt":1719496080894,"mc":[{"id":"1.230180117","rc":[{"atb":[[1.35,11.29]],"id":40831161}],"con":true,"img":false}]}
{"op":"mcm","clk":"11540579564","pt":1719496109516,"mc":[{"id":"1.230180117","rc":[{"atb":[[1.33,0]],"id":40831161},{"spn":38.17,"spf":"NaN","id":40831161}],"con":true,"img":false}]}
{"op":"mcm","clk":"11540579612","pt":1719496110032,"mc":[{"id":"1.230180117","rc":[{"atb":[[1.37,11.44]],"id":40831161}],"con":true,"img":false}]}
{"op":"mcm","clk":"11540580147","pt":1719496115728,"mc":[{"id":"1.230180117","rc":[{"atb":[[1.35,0]],"id":40831161}],"con":true,"img":false}]}
{"op":"mcm","clk":"11540580185","pt":1719496116146,"mc":[{"id":"1.230180117","rc":[{"atb":[[1.39,10.12]],"id":40831161}],"con":true,"img":false}]}
{"op":"mcm","clk":"11540583158","pt":1719496146484,"mc":[{"id":"1.230180117","rc":[{"atb":[[1.37,0]],"id":40831161}],"con":true,"img":false}]}
{"op":"mcm","clk":"11540583221","pt":1719496147102,"mc":[{"id":"1.230180117","rc":[{"atb":[[1.41,10.33]],"id":40831161}],"con":true,"img":false}]}
{"op":"mcm","clk":"11540583839","pt":1719496152480,"mc":[{"id":"1.230180117","rc":[{"atb":[[1.39,0]],"id":40831161}],"con":true,"img":false}]}
{"op":"mcm","clk":"11540583864","pt":1719496152690,"mc":[{"id":"1.230180117","rc":[{"atb":[[1.43,9.18]],"id":40831161}],"con":true,"img":false}]}
{"op":"mcm","clk":"11540586886","pt":1719496182350,"mc":[{"id":"1.230180117","rc":[{"atb":[[1.41,0]],"id":40831161},{"spn":38.21,"spf":"NaN","id":40831161}],"con":true,"img":false}]}
{"op":"mcm","clk":"11540586932","pt":1719496182938,"mc":[{"id":"1.230180117","rc":[{"atb":[[1.45,9.4]],"id":40831161}],"con":true,"img":false}]}
{"op":"mcm","clk":"11540587716","pt":1719496190859,"mc":[{"id":"1.230180117","rc":[{"atb":[[1.43,0]],"id":40831161}],"con":true,"img":false}]}
{"op":"mcm","clk":"11540587734","pt":1719496191066,"mc":[{"id":"1.230180117","rc":[{"atb":[[1.47,8.4]],"id":40831161}],"con":true,"img":false}]}
{"op":"mcm","clk":"11540590759","pt":1719496219972,"mc":[{"id":"1.230180117","rc":[{"atb":[[1.45,0]],"id":40831161}],"con":true,"img":false}]}
{"op":"mcm","clk":"11540590824","pt":1719496220591,"mc":[{"id":"1.230180117","rc":[{"atb":[[1.49,8.63]],"id":40831161}],"con":true,"img":false}]}
{"op":"mcm","clk":"11540591493","pt":1719496227283,"mc":[{"id":"1.230180117","rc":[{"atb":[[1.47,0]],"id":40831161}],"con":true,"img":false}]}
{"op":"mcm","clk":"11540591510","pt":1719496227492,"mc":[{"id":"1.230180117","rc":[{"atb":[[1.51,7.74]],"id":40831161}],"con":true,"img":false}]}
{"op":"mcm","clk":"11540594451","pt":1719496255527,"mc":[{"id":"1.230180117","rc":[{"atb":[[1.49,0]],"id":40831161},{"spn":38.25,"spf":"NaN","id":40831161}],"con":true,"img":false}]}
{"op":"mcm","clk":"11540594543","pt":1719496256305,"mc":[{"id":"1.230180117","rc":[{"atb":[[1.53,7.98]],"id":40831161}],"con":true,"img":false}]}
{"op":"mcm","clk":"11540595358","pt":1719496264433,"mc":[{"id":"1.230180117","rc":[{"atb":[[1.51,0]],"id":40831161}],"con":true,"img":false}]}
{"op":"mcm","clk":"11540595385","pt":1719496264638,"mc":[{"id":"1.230180117","rc":[{"atb":[[1.55,7.18]],"id":40831161}],"con":true,"img":false}]}
{"op":"mcm","clk":"11540598063","pt":1719496291756,"mc":[{"id":"1.230180117","rc":[{"atb":[[1.53,0]],"id":40831161}],"con":true,"img":false}]}
{"op":"mcm","clk":"11540598089","pt":1719496292060,"mc":[{"id":"1.230180117","rc":[{"atb":[[1.57,7.42]],"id":40831161}],"con":true,"img":false}]}
{"op":"mcm","clk":"11540599102","pt":1719496302791,"mc":[{"id":"1.230180117","rc":[{"atb":[[1.55,0]],"id":40831161}],"con":true,"img":false}]}
{"op":"mcm","clk":"11540599127","pt":1719496302991,"mc":[{"id":"1.230180117","rc":[{"atb":[[1.59,6.69]],"id":40831161}],"con":true,"img":false}]}
{"op":"mcm","clk":"11540601455","pt":1719496325987,"mc":[{"id":"1.230180117","rc":[{"atb":[[1.57,0]],"id":40831161},{"spn":38.29,"spf":"NaN","id":40831161}],"con":true,"img":false}]}
{"op":"mcm","clk":"11540601484","pt":1719496326296,"mc":[{"id":"1.230180117","rc":[{"atb":[[1.61,6.94]],"id":40831161}],"con":true,"img":false}]}
{"op":"mcm","clk":"11540602867","pt":1719496341099,"mc":[{"id":"1.230180117","rc":[{"atb":[[1.59,0]],"id":40831161}],"con":true,"img":false}]}
{"op":"mcm","clk":"11540602889","pt":1719496341305,"mc":[{"id":"1.230180117","rc":[{"atb":[[1.63,6.27]],"id":40831161}],"con":true,"img":false}]}
{"op":"mcm","clk":"11540605041","pt":1719496363044,"mc":[{"id":"1.230180117","rc":[{"atb":[[1.61,0]],"id":40831161}],"con":true,"img":false}]}
{"op":"mcm","clk":"11540605070","pt":1719496363350,"mc":[{"id":"1.230180117","rc":[{"atb":[[1.65,6.51]],"id":40831161}],"con":true,"img":false}]}
{"op":"mcm","clk":"11540606476","pt":1719496378246,"mc":[{"id":"1.230180117","rc":[{"atb":[[1.63,0]],"id":40831161}],"con":true,"img":false}]}
{"op":"mcm","clk":"11540606514","pt":1719496378560,"mc":[{"id":"1.230180117","rc":[{"atb":[[1.67,5.89]],"id":40831161}],"con":true,"img":false}]}
{"op":"mcm","clk":"11540608324","pt":1719496397559,"mc":[{"id":"1.230180117","rc":[{"atb":[[1.65,0]],"id":40831161},{"spn":38.33,"spf":"NaN","id":40831161}],"con":true,"img":false}]}
{"op":"mcm","clk":"11540608400","pt":1719496398279,"mc":[{"id":"1.230180117","rc":[{"atb":[[1.69,6.14]],"id":40831161}],"con":true,"img":false}]}
{"op":"mcm","clk":"11540609764","pt":1719496414395,"mc":[{"id":"1.230180117","rc":[{"atb":[[1.67,0]],"id":40831161}],"con":true,"img":false}]}
{"op":"mcm","clk":"11540609777","pt":1719496414607,"mc":[{"id":"1.230180117","rc":[{"atb":[[1.71,5.56]],"id":40831161}],"con":true,"img":false}]}
{"op":"mcm","clk":"11540611430","pt":1719496431956,"mc":[{"id":"1.230180117","rc":[{"atb":[[1.69,0]],"id":40831161}],"con":true,"img":false}]}
{"op":"mcm","clk":"11540611459","pt":1719496432212,"mc":[{"id":"1.230180117","rc":[{"atb":[[1.73,5.8]],"id":40831161}],"con":true,"img":false}]}
{"op":"mcm","clk":"11540613076","pt":1719496449069,"mc":[{"id":"1.230180117","rc":[{"atb":[[1.71,0]],"id":40831161}],"con":true,"img":false}]}
{"op":"mcm","clk":"11540613098","pt":1719496449229,"mc":[{"id":"1.230180117","rc":[{"atb":[[1.75,5.26]],"id":40831161}],"con":true,"img":false}]}
{"op":"mcm","clk":"11540614703","pt":1719496467374,"mc":[{"id":"1.230180117","rc":[{"atb":[[1.73,0]],"id":40831161},{"spn":38.37,"spf":"NaN","id":40831161}],"con":true,"img":false}]}
{"op":"mcm","clk":"11540614736","pt":1719496467677,"mc":[{"id":"1.230180117","rc":[{"atb":[[1.77,5.49]],"id":40831161}],"con":true,"img":false}]}
{"op":"mcm","clk":"11540614794","pt":1719496468401,"mc":[{"id":"1.230180117","rc":[{"atb":[[1.75,0]],"id":40831161}],"con":true,"img":false}]}
{"op":"mcm","clk":"11540614836","pt":1719496468758,"mc":[{"id":"1.230180117","rc":[{"atb":[[1.79,5]],"id":40831161}],"con":true,"img":false}]}
{"op":"mcm","clk":"11540618005","pt":1719496502219,"mc":[{"id":"1.230180117","rc":[{"atb":[[1.77,0]],"id":40831161}],"con":true,"img":false}]}
{"op":"mcm","clk":"11540618060","pt":1719496502892,"mc":[{"id":"1.230180117","rc":[{"atb":[[1.81,5.22]],"id":40831161}],"con":true,"img":false}]}
{"op":"mcm","clk":"11540618167","pt":1719496504301,"mc":[{"id":"1.230180117","rc":[{"atb":[[1.79,0]],"id":40831161}],"con":true,"img":false}]}
{"op":"mcm","clk":"11540618182","pt":1719496504501,"mc":[{"id":"1.230180117","rc":[{"atb":[[1.83,4.75]],"id":40831161}],"con":true,"img":false}]}
{"op":"mcm","clk":"11540620773","pt":1719496538024,"mc":[{"id":"1.230180117","rc":[{"atb":[[1.81,0]],"id":40831161},{"spn":38.41,"spf":"NaN","id":40831161}],"con":true,"img":false}]}
{"op":"mcm","clk":"11540620835","pt":1719496538742,"mc":[{"id":"1.230180117","rc":[{"atb":[[1.85,4.98]],"id":40831161}],"con":true,"img":false}]}
{"op":"mcm","clk":"11540620928","pt":1719496539939,"mc":[{"id":"1.230180117","rc":[{"atb":[[1.83,0]],"id":40831161}],"con":true,"img":false}]}
{"op":"mcm","clk":"11540620951","pt":1719496540140,"mc":[{"id":"1.230180117","rc":[{"atb":[[1.87,4.54]],"id":40831161}],"con":true,"img":false}]}
{"op":"mcm","clk":"11540622601","pt":1719496560417,"mc":[{"id":"1.230180117","rc":[{"atb":[[1.44,2.48],[1.55,1]],"id":64253836},{"atl":[[4.3,1],[12,2]],"id":64253836}],"con":true,"img":false}]}
{"op":"mcm","clk":"11540622609","pt":1719496560469,"mc":[{"id":"1.230180117","rc":[{"atb":[[1.6,2.48],[1.65,1]],"id":63031611},{"atl":[[4.8,1],[18,2]],"id":63031611},{"atb":[[1.55,2.48],[1.74,1]],"id":69366841},{"atl":[[5.3,1],[15.5,2]],"id":69366841},{"atb":[[2.24,1],[1.93,4.54]],"id":40831161},{"atl":[[70,2],[7.6,1]],"id":40831161},{"atb":[[1.41,1],[1.19,6.74]],"id":48536142},{"atl":[[3.55,1],[9.4,2]],"id":48536142},{"atb":[[1.41,2.48],[1.55,1]],"id":68900945},{"atl":[[4.3,1],[11.5,2]],"id":68900945}],"con":true,"img":false}]}
{"op":"mcm","clk":"11540622758","pt":1719496562176,"mc":[{"id":"1.230180117","rc":[{"atb":[[1.01,34.7]],"id":64253836},{"atl":[[1000,1.88]],"id":64253836},{"atb":[[1.01,1.7]],"id":48536142},{"atl":[[1000,1.88]],"id":48536142},{"atb":[[1.01,1.7]],"id":68900945},{"atl":[[1000,1.88]],"id":68900945}],"con":true,"img":false}]}
{"op":"mcm","clk":"11540622777","pt":1719496562383,"mc":[{"id":"1.230180117","rc":[{"atb":[[1.01,33.7]],"id":64253836},{"atl":[[1000,0.2]],"id":64253836},{"atb":[[1.01,1.58]],"id":48536142},{"atl":[[1000,0.21]],"id":48536142},{"atb":[[1.01,0.75]],"id":68900945},{"atl":[[1000,0.2]],"id":68900945}],"con":true,"img":false}]}
{"op":"mcm","clk":"11540622793","pt":1719496562588,"mc":[{"id":"1.230180117","rc":[{"atb":[[1.01,32.99]],"id":64253836},{"atl":[[1000,0.17]],"id":64253836},{"atb":[[1.01,0]],"id":48536142},{"atl":[[1000,0.17]],"id":48536142},{"atb":[[1.01,0]],"id":68900945},{"atl":[[1000,0.17]],"id":68900945}],"con":true,"img":false}]}
{"op":"mcm","clk":"11540622800","pt":1719496562692,"mc":[{"id":"1.230180117","rc":[{"atb":[[1.45,0.7]],"id":64253836},{"atl":[[11.5,0.03]],"id":64253836},{"atb":[[1.2,1.83]],"id":48536142},{"atl":[[9.2,0.03]],"id":48536142},{"atb":[[1.42,0.75]],"id":68900945},{"atl":[[11,0.03]],"id":68900945}],"con":true,"img":false}]}
{"op":"mcm","clk":"11540622854","pt":1719496563364,"mc":[{"id":"1.230180117","rc":[{"atb":[[1.88,2.11]],"id":40831161}],"con":true,"img":false}]}
{"op":"mcm","clk":"11540624426","pt":1719496581413,"mc":[{"id":"1.230180117","rc":[{"atb":[[1.6,0],[1.68,2]],"id":63031611},{"atb":[[1.64,2.48],[1.55,0]],"id":69366841},{"atb":[[1.93,0],[2.14,4.54]],"id":40831161},{"atb":[[1.56,2],[1.44,0]],"id":64253836},{"atb":[[1.28,2.48],[1.19,0]],"id":48536142},{"atb":[[1.41,0],[1.52,2]],"id":68900945}],"con":true,"img":false}]}
{"op":"mcm","clk":"11540624455","pt":1719496581622,"mc":[{"id":"1.230180117","rc":[{"atl":[[4.8,0],[5.7,1]],"id":63031611},{"atl":[[6.2,1],[5.3,0]],"id":69366841},{"atl":[[7.6,0],[9.8,1]],"id":40831161},{"atl":[[4.3,0],[5,1]],"id":64253836},{"atl":[[4.2,1]],"id":48536142},{"atl":[[4.3,0],[5,1]],"id":68900945}],"con":true,"img":false}]}
{"op":"mcm","clk":"11540624468","pt":1719496581732,"mc":[{"id":"1.230180117","rc":[{"atl":[[3.55,0]],"id":48536142}],"con":true,"img":false}]}
{"op":"mcm","clk":"11540624486","pt":1719496582140,"mc":[{"id":"1.230180117","rc":[{"atl":[[4.7,1.99]],"id":48536142}],"con":true,"img":false}]}
{"op":"mcm","clk":"11540624519","pt":1719496582703,"mc":[{"id":"1.230180117","rc":[{"atl":[[4.7,3.99],[9.4,0]],"id":48536142}],"con":true,"img":false}]}
{"op":"mcm","clk":"11540624751","pt":1719496584929,"mc":[{"id":"1.230180117","rc":[{"atl":[[4.7,2]],"id":48536142}],"con":true,"img":false}]}
{"op":"mcm","clk":"11540624997","pt":1719496587402,"mc":[{"id":"1.230180117","rc":[{"atl":[[9.2,3.03],[4.7,0]],"id":48536142}],"con":true,"img":false}]}
{"op":"mcm","clk":"11540625006","pt":1719496587510,"mc":[{"id":"1.230180117","rc":[{"atl":[[4.7,2.18]],"id":48536142}],"con":true,"img":false}]}
{"op":"mcm","clk":"11540625025","pt":1719496587711,"mc":[{"id":"1.230180117","rc":[{"atb":[[1.21,2]],"id":48536142}],"con":true,"img":false}]}
{"op":"mcm","clk":"11540625059","pt":1719496588127,"mc":[{"id":"1.230180117","rc":[{"atb":[[1.02,2]],"id":64253836}],"con":true,"img":false}]}
{"op":"mcm","clk":"11540625086","pt":1719496588438,"mc":[{"id":"1.230180117","rc":[{"atb":[[1.02,2]],"id":68900945}],"con":true,"img":false}]}
{"op":"mcm","clk":"11540625110","pt":1719496588693,"mc":[{"id":"1.230180117","rc":[{"atb":[[1.02,2]],"id":69366841}],"con":true,"img":false}]}
{"op":"mcm","clk":"11540625134","pt":1719496589004,"mc":[{"id":"1.230180117","rc":[{"atb":[[1.02,2]],"id":63031611}],"con":true,"img":false}]}
{"op":"mcm","clk":"11540625158","pt":1719496589312,"mc":[{"id":"1.230180117","rc":[{"atb":[[1.94,2]],"id":40831161}],"con":true,"img":false}]}
{"op":"mcm","clk":"11540625328","pt":1719496591331,"mc":[{"id":"1.230180117","rc":[{"atb":[[1.21,0]],"id":48536142}],"con":true,"img":false}]}
{"op":"mcm","clk":"11540625336","pt":1719496591437,"mc":[{"id":"1.230180117","rc":[{"atb":[[1.29,2]],"id":48536142}],"con":true,"img":false}]}
{"op":"mcm","clk":"11540625362","pt":1719496591746,"mc":[{"id":"1.230180117","rc":[{"atb":[[1.94,0]],"id":40831161}],"con":true,"img":false}]}
{"op":"mcm","clk":"11540625375","pt":1719496591796,"mc":[{"id":"1.230180117","rc":[{"atb":[[2.16,2]],"id":40831161}],"con":true,"img":false}]}
{"op":"mcm","clk":"11540625411","pt":1719496592214,"mc":[{"id":"1.230180117","rc":[{"atl":[[9.2,0.03],[4.7,4.36]],"id":48536142}],"con":true,"img":false}]}
{"op":"mcm","clk":"11540625453","pt":1719496592731,"mc":[{"id":"1.230180117","rc":[{"atl":[[4.7,2.18]],"id":48536142}],"con":true,"img":false}]}
{"op":"mcm","clk":"11540625605","pt":1719496594636,"mc":[{"id":"1.230180117","rc":[{"atl":[[4.7,4.36]],"id":48536142}],"con":true,"img":false}]}
{"op":"mcm","clk":"11540626048","pt":1719496599910,"mc":[{"id":"1.230180117","rc":[{"spn":3.69,"spf":"NaN","id":63031611},{"spn":3.97,"spf":"NaN","id":69366841},{"spn":6.02,"spf":"NaN","id":40831161},{"spn":3.28,"spf":"NaN","id":64253836},{"atl":[[4.7,2.18]],"id":48536142},{"spn":2.8,"spf":"NaN","id":48536142},{"spn":3.27,"spf":"NaN","id":68900945}],"con":true,"img":false}]}
{"op":"mcm","clk":"11540626066","pt":1719496600108,"mc":[{"id":"1.230180117","rc":[{"atl":[[9.2,3.21],[4.7,0]],"id":48536142}],"con":true,"img":false}]}
{"op":"mcm","clk":"11540626846","pt":1719496609359,"mc":[{"id":"1.230180117","rc":[{"atb":[[1.45,0]],"id":64253836},{"atl":[[11.5,0]],"id":64253836},{"atb":[[1.2,0.25]],"id":48536142},{"atl":[[9.2,3.18]],"id":48536142},{"atb":[[1.42,0]],"id":68900945},{"atl":[[11,0]],"id":68900945}],"con":true,"img":false}]}
{"op":"mcm","clk":"11540627046","pt":1719496611637,"mc":[{"id":"1.230180117","rc":[{"atb":[[1.85,8.73]],"id":40831161}],"con":true,"img":false}]}
{"op":"mcm","clk":"11540627294","pt":1719496614756,"mc":[{"id":"1.230180117","rc":[{"atb":[[1.85,4.98]],"id":40831161}],"con":true,"img":false}]}
{"op":"mcm","clk":"11540631365","pt":1719496665284,"mc":[{"id":"1.230180117","rc":[{"atb":[[1.87,0]],"id":40831161}],"con":true,"img":false}]}
{"op":"mcm","clk":"11540632890","pt":1719496684518,"mc":[{"id":"1.230180117","rc":[{"atb":[[1.85,0]],"id":40831161}],"con":true,"img":false}]}
{"op":"mcm","clk":"11540632990","pt":1719496685715,"mc":[{"id":"1.230180117","rc":[{"atl":[[1000,1.88]],"id":48536142}],"con":true,"img":false}]}
{"op":"mcm","clk":"11540632998","pt":1719496685817,"mc":[{"id":"1.230180117","rc":[{"atb":[[1.01,34.7]],"id":64253836},{"atl":[[1000,1.88]],"id":64253836},{"atb":[[1.01,1.7]],"id":48536142},{"atb":[[1.01,1.7]],"id":68900945},{"atl":[[1000,1.88]],"id":68900945}],"con":true,"img":false}]}
{"op":"mcm","clk":"11540633009","pt":1719496686029,"mc":[{"id":"1.230180117","rc":[{"atb":[[1.01,33.53]],"id":64253836},{"atl":[[1000,0.2]],"id":64253836},{"atb":[[1.01,1.02]],"id":48536142},{"atl":[[1000,0.21]],"id":48536142},{"atb":[[1.01,0.57]],"id":68900945},{"atl":[[1000,0.2]],"id":68900945}],"con":true,"img":false}]}
{"op":"mcm","clk":"11540633023","pt":1719496686234,"mc":[{"id":"1.230180117","rc":[{"atb":[[1.01,32.99]],"id":64253836},{"atl":[[1000,0.17]],"id":64253836},{"atb":[[1.01,0]],"id":48536142},{"atl":[[1000,0.17]],"id":48536142},{"atb":[[1.01,0]],"id":68900945},{"atl":[[1000,0.17]],"id":68900945}],"con":true,"img":false}]}
{"op":"mcm","clk":"11540633035","pt":1719496686338,"mc":[{"id":"1.230180117","rc":[{"atb":[[1.57,0.53]],"id":64253836},{"atl":[[11.5,0.02]],"id":64253836},{"atb":[[1.3,1.02]],"id":48536142},{"atl":[[9,0.03]],"id":48536142},{"atb":[[1.53,0.57]],"id":68900945},{"atl":[[11,0.03]],"id":68900945}],"con":true,"img":false}]}
{"op":"mcm","clk":"11540633165","pt":1719496687443,"mc":[{"id":"1.230180117","rc":[{"atb":[[1.29,0]],"id":48536142}],"con":true,"img":false}]}
{"op":"mcm","clk":"11540633177","pt":1719496687549,"mc":[{"id":"1.230180117","rc":[{"atb":[[1.31,2]],"id":48536142}],"con":true,"img":false}]}
{"op":"mcm","clk":"11540633189","pt":1719496687655,"mc":[{"id":"1.230180117","rc":[{"atb":[[1.28,0],[1.31,4]],"id":48536142}],"con":true,"img":false}]}
{"op":"mcm","clk":"11540634388","pt":1719496703248,"mc":[{"id":"1.230180117","rc":[{"atb":[[1.33,11.96]],"id":48536142}],"con":true,"img":false}]}
{"op":"mcm","clk":"11540634398","pt":1719496703351,"mc":[{"id":"1.230180117","rc":[{"atb":[[1.31,2],[1.34,4]],"id":48536142}],"con":true,"img":false}]}
{"op":"mcm","clk":"11540634616","pt":1719496705751,"mc":[{"id":"1.230180117","rc":[{"atb":[[1.36,2.11]],"id":48536142}],"con":true,"img":false}]}
{"op":"mcm","clk":"11540634624","pt":1719496705856,"mc":[{"id":"1.230180117","rc":[{"atb":[[1.36,6.11]],"id":48536142}],"con":true,"img":false}]}
{"op":"mcm","clk":"11540634634","pt":1719496705958,"mc":[{"id":"1.230180117","rc":[{"atb":[[1.34,0]],"id":48536142}],"con":true,"img":false}]}
{"op":"mcm","clk":"11540635053","pt":1719496711068,"mc":[{"id":"1.230180117","rc":[{"atb":[[1.31,0]],"id":48536142}],"con":true,"img":false}]}
{"op":"mcm","clk":"11540635064","pt":1719496711169,"mc":[{"id":"1.230180117","rc":[{"atb":[[1.37,2]],"id":48536142}],"con":true,"img":false}]}
{"op":"mcm","clk":"11540635825","pt":1719496720557,"mc":[{"id":"1.230180117","rc":[{"atb":[[1.33,0]],"id":48536142}],"con":true,"img":false}]}
{"op":"mcm","clk":"11540635841","pt":1719496720763,"mc":[{"id":"1.230180117","rc":[{"atb":[[1.39,10.12]],"id":48536142}],"con":true,"img":false}]}
{"op":"mcm","clk":"11540635857","pt":1719496720972,"mc":[{"id":"1.230180117","rc":[{"atb":[[1.4,6.12]],"id":48536142}],"con":true,"img":false}]}
{"op":"mcm","clk":"11540635864","pt":1719496721076,"mc":[{"id":"1.230180117","rc":[{"atb":[[1.36,2.11]],"id":48536142}],"con":true,"img":false}]}
{"op":"mcm","clk":"11540635877","pt":1719496721289,"mc":[{"id":"1.230180117","rc":[{"atb":[[1.37,0]],"id":48536142}],"con":true,"img":false}]}
{"op":"mcm","clk":"11540635883","pt":1719496721385,"mc":[{"id":"1.230180117","rc":[{"atb":[[1.02,2]],"id":48536142}],"con":true,"img":false}]}
{"op":"mcm","clk":"11540635936","pt":1719496722072,"mc":[{"id":"1.230180117","rc":[{"atb":[[1.41,11.33]],"id":48536142}],"con":true,"img":false}]}
{"op":"mcm","clk":"11540635986","pt":1719496722582,"mc":[{"id":"1.230180117","rc":[{"atb":[[1.02,0]],"id":48536142}],"con":true,"img":false}]}
{"op":"mcm","clk":"11540635996","pt":1719496722685,"mc":[{"id":"1.230180117","rc":[{"atb":[[1.42,2]],"id":48536142}],"con":true,"img":false}]}
{"op":"mcm","clk":"11540636137","pt":1719496724085,"mc":[{"id":"1.230180117","rc":[{"atb":[[1.57,0]],"id":64253836},{"atl":[[11.5,0]],"id":64253836},{"atb":[[1.3,0]],"id":48536142},{"atl":[[9,0]],"id":48536142},{"atb":[[1.53,0]],"id":68900945},{"atl":[[11,0]],"id":68900945}],"con":true,"img":false}]}
{"op":"mcm","clk":"11540636288","pt":1719496726175,"mc":[{"id":"1.230180117","rc":[{"atb":[[1.36,0],[1.44,2.11]],"id":48536142},{"spn":2.82,"spf":"NaN","id":48536142}],"con":true,"img":false}]}
{"op":"mcm","clk":"11540636348","pt":1719496726884,"mc":[{"id":"1.230180117","rc":[{"atb":[[1.42,0]],"id":48536142}],"con":true,"img":false}]}
{"op":"mcm","clk":"11540636359","pt":1719496726986,"mc":[{"id":"1.230180117","rc":[{"atb":[[1.45,2]],"id":48536142}],"con":true,"img":false}]}
{"op":"mcm","clk":"11540636571","pt":1719496729488,"mc":[{"id":"1.230180117","rc":[{"atb":[[1.4,0],[1.45,4.12]],"id":48536142}],"con":true,"img":false}]}
{"op":"mcm","clk":"11540636581","pt":1719496729592,"mc":[{"id":"1.230180117","rc":[{"atb":[[1.44,8.23],[1.45,2]],"id":48536142}],"con":true,"img":false}]}
{"op":"mcm","clk":"11540640432","pt":1719496778237,"mc":[{"id":"1.230180117","rc":[{"atb":[[1.78,3.75]],"id":40831161}],"con":true,"img":false}]}
{"op":"mcm","clk":"11540640550","pt":1719496779748,"mc":[{"id":"1.230180117","rc":[{"atb":[[1.78,0]],"id":40831161}],"con":true,"img":false}]}
{"op":"mcm","clk":"11540641816","pt":1719496795171,"mc":[{"id":"1.230180117","rc":[{"atb":[[1.66,6.41]],"id":69366841},{"spn":2.82,"spf":"NaN","id":48536142}],"con":true,"img":false}]}
{"op":"mcm","clk":"11540641833","pt":1719496795374,"mc":[{"id":"1.230180117","rc":[{"atb":[[1.64,0],[1.67,2.48]],"id":69366841}],"con":true,"img":false}]}
{"op":"mcm","clk":"11540641927","pt":1719496796572,"mc":[{"id":"1.230180117","rc":[{"atb":[[1.43,12.86]],"id":48536142}],"con":true,"img":false}]}
{"op":"mcm","clk":"11540641934","pt":1719496796681,"mc":[{"id":"1.230180117","rc":[{"atb":[[1.68,5.8]],"id":69366841}],"con":true,"img":false}]}
{"op":"mcm","clk":"11540641944","pt":1719496796844,"mc":[{"id":"1.230180117","rc":[{"atb":[[1.67,0],[1.69,5.81]],"id":69366841},{"atb":[[1.39,0]],"id":48536142}],"con":true,"img":false}]}
{"op":"mcm","clk":"11540641957","pt":1719496797041,"mc":[{"id":"1.230180117","rc":[{"atb":[[1.47,8.4]],"id":48536142}],"con":true,"img":false}]}
{"op":"mcm","clk":"11540641965","pt":1719496797143,"mc":[{"id":"1.230180117","rc":[{"atb":[[1.44,2.11],[1.48,8.24]],"id":48536142}],"con":true,"img":false}]}
{"op":"mcm","clk":"11540642093","pt":1719496798958,"mc":[{"id":"1.230180117","rc":[{"atb":[[1.45,0]],"id":48536142}],"con":true,"img":false}]}
{"op":"mcm","clk":"11540642101","pt":1719496799067,"mc":[{"id":"1.230180117","rc":[{"atb":[[1.49,2]],"id":48536142}],"con":true,"img":false}]}
{"op":"mcm","clk":"11540642120","pt":1719496799380,"mc":[{"id":"1.230180117","rc":[{"atb":[[1.02,0]],"id":69366841}],"con":true,"img":false}]}
{"op":"mcm","clk":"11540642129","pt":1719496799478,"mc":[{"id":"1.230180117","rc":[{"atb":[[1.7,2],[1.71,2.11]],"id":69366841},{"atb":[[1.44,0],[1.51,2.11]],"id":48536142}],"con":true,"img":false}]}
{"op":"mcm","clk":"11540642137","pt":1719496799579,"mc":[{"id":"1.230180117","rc":[{"atb":[[1.71,4.23],[1.69,0]],"id":69366841}],"con":true,"img":false}]}
{"op":"mcm","clk":"11540642228","pt":1719496800694,"mc":[{"id":"1.230180117","rc":[{"atb":[[1.01,34.7]],"id":64253836},{"atl":[[1000,1.88]],"id":64253836},{"atb":[[1.01,1.7]],"id":48536142},{"atl":[[1000,1.88]],"id":48536142},{"atb":[[1.01,1.7]],"id":68900945},{"atl":[[1000,1.88]],"id":68900945}],"con":true,"img":false}]}
{"op":"mcm","clk":"11540642251","pt":1719496800850,"mc":[{"id":"1.230180117","rc":[{"atb":[[1.01,33.51]],"id":64253836},{"atl":[[1000,0.2]],"id":64253836},{"atb":[[1.01,0.56]],"id":48536142},{"atb":[[1.01,0.55]],"id":68900945},{"atl":[[1000,0.2]],"id":68900945}],"con":true,"img":false}]}
{"op":"mcm","clk":"11540642264","pt":1719496800955,"mc":[{"id":"1.230180117","rc":[{"atl":[[1000,0.21]],"id":48536142}],"con":true,"img":false}]}
{"op":"mcm","clk":"11540642272","pt":1719496801059,"mc":[{"id":"1.230180117","rc":[{"atb":[[1.01,32.99]],"id":64253836},{"atl":[[1000,0.17]],"id":64253836},{"atb":[[1.01,0]],"id":48536142},{"atb":[[1.01,0]],"id":68900945},{"atl":[[1000,0.17]],"id":68900945}],"con":true,"img":false}]}
{"op":"mcm","clk":"11540642283","pt":1719496801163,"mc":[{"id":"1.230180117","rc":[{"atb":[[1.57,0.51]],"id":64253836},{"atl":[[11.5,0.02]],"id":64253836},{"atb":[[1.52,0.56]],"id":48536142},{"atl":[[1000,0.17]],"id":48536142},{"atb":[[1.53,0.55]],"id":68900945},{"atl":[[11,0.02]],"id":68900945}],"con":true,"img":false}]}
{"op":"mcm","clk":"11540642296","pt":1719496801271,"mc":[{"id":"1.230180117","rc":[{"atl":[[9,0.03]],"id":48536142}],"con":true,"img":false}]}
{"op":"mcm","clk":"11540642614","pt":1719496804988,"mc":[{"id":"1.230180117","rc":[{"atb":[[1.03,10.99]],"id":63031611},{"atb":[[1.01,32.98],[1.68,5.8],[1.66,6.41],[1.71,4.23]],"id":69366841},{"atb":[[1.03,10.99],[1.88,2.11]],"id":40831161},{"atb":[[1.01,32.98],[1.57,0.51]],"id":64253836},{"atb":[[1.41,11.32],[1.43,12.85],[1.03,10.99],[1.51,4.23],[1.48,0],[1.47,8.4],[1.52,0.56]],"id":48536142},{"atb":[[1.03,10.99],[1.53,0.55]],"id":68900945}],"con":true,"img":false}]}
{"op":"mcm","clk":"11540642802","pt":1719496807071,"mc":[{"id":"1.230180117","rc":[{"atb":[[1.49,0]],"id":48536142}],"con":true,"img":false}]}
{"op":"mcm","clk":"11540642808","pt":1719496807175,"mc":[{"id":"1.230180117","rc":[{"atb":[[1.52,2.56]],"id":48536142}],"con":true,"img":false}]}
{"op":"mcm","clk":"11540642842","pt":1719496807701,"mc":[{"id":"1.230180117","rc":[{"atb":[[1.7,0]],"id":69366841}],"con":true,"img":false}]}
{"op":"mcm","clk":"11540642850","pt":1719496807792,"mc":[{"id":"1.230180117","rc":[{"atb":[[1.72,2]],"id":69366841}],"con":true,"img":false}]}
{"op":"mcm","clk":"11540643688","pt":1719496817190,"mc":[{"id":"1.230180117","rc":[{"atb":[[1.68,0]],"id":69366841}],"con":true,"img":false}]}
{"op":"mcm","clk":"11540643708","pt":1719496817394,"mc":[{"id":"1.230180117","rc":[{"atb":[[1.74,6.33]],"id":69366841}],"con":true,"img":false}]}
{"op":"mcm","clk":"11540643727","pt":1719496817600,"mc":[{"id":"1.230180117","rc":[{"atb":[[1.75,4.24],[1.71,2.11]],"id":69366841}],"con":true,"img":false}]}
{"op":"mcm","clk":"11540643853","pt":1719496819106,"mc":[{"id":"1.230180117","rc":[{"atb":[[1.72,0]],"id":69366841}],"con":true,"img":false}]}
{"op":"mcm","clk":"11540643863","pt":1719496819196,"mc":[{"id":"1.230180117","rc":[{"atb":[[1.76,2]],"id":69366841}],"con":true,"img":false}]}
{"op":"mcm","clk":"11540645029","pt":1719496833595,"mc":[{"id":"1.230180117","rc":[{"atb":[[1.46,12.88]],"id":48536142}],"con":true,"img":false}]}
{"op":"mcm","clk":"11540645224","pt":1719496835610,"mc":[{"id":"1.230180117","rc":[{"atb":[[1.43,0]],"id":48536142}],"con":true,"img":false}]}
{"op":"mcm","clk":"11540645243","pt":1719496835815,"mc":[{"id":"1.230180117","rc":[{"atb":[[1.49,11.28]],"id":48536142}],"con":true,"img":false}]}
{"op":"mcm","clk":"11540646392","pt":1719496849596,"mc":[{"id":"1.230180117","rc":[{"atb":[[1.57,0]],"id":64253836},{"atl":[[11.5,0]],"id":64253836},{"atb":[[1.52,2]],"id":48536142},{"atl":[[9,0]],"id":48536142},{"atb":[[1.53,0]],"id":68900945},{"atl":[[11,0]],"id":68900945}],"con":true,"img":false}]}
{"op":"mcm","clk":"11540648458","pt":1719496873229,"mc":[{"id":"1.230180117","rc":[{"spn":3.98,"spf":"NaN","id":69366841},{"atb":[[1.46,0]],"id":48536142},{"spn":2.86,"spf":"NaN","id":48536142}],"con":true,"img":false}]}
{"op":"mcm","clk":"11540648503","pt":1719496873852,"mc":[{"id":"1.230180117","rc":[{"atb":[[1.52,13.39]],"id":48536142}],"con":true,"img":false}]}
{"op":"mcm","clk":"11540648523","pt":1719496874058,"mc":[{"id":"1.230180117","rc":[{"atb":[[1.51,2.11],[1.53,11.28]],"id":48536142}],"con":true,"img":false}]}
{"op":"mcm","clk":"11540648726","pt":1719496876760,"mc":[{"id":"1.230180117","rc":[{"atb":[[1.56,2.11],[1.51,0]],"id":48536142}],"con":true,"img":false}]}
{"op":"mcm","clk":"11540648734","pt":1719496876859,"mc":[{"id":"1.230180117","rc":[{"atb":[[1.56,13.39]],"id":48536142}],"con":true,"img":false}]}
{"op":"mcm","clk":"11540648744","pt":1719496876962,"mc":[{"id":"1.230180117","rc":[{"atb":[[1.53,0]],"id":48536142}],"con":true,"img":false}]}
{"op":"mcm","clk":"11540648789","pt":1719496877332,"mc":[{"id":"1.230180117","rc":[{"atb":[[1.52,11.39]],"id":48536142}],"con":true,"img":false}]}
{"op":"mcm","clk":"11540648800","pt":1719496877430,"mc":[{"id":"1.230180117","rc":[{"atb":[[1.54,2]],"id":48536142}],"con":true,"img":false}]}
{"op":"mcm","clk":"11540648985","pt":1719496879548,"mc":[{"id":"1.230180117","rc":[{"atb":[[1.54,0]],"id":48536142}],"con":true,"img":false}]}
{"op":"mcm","clk":"11540648993","pt":1719496879651,"mc":[{"id":"1.230180117","rc":[{"atb":[[1.57,2]],"id":48536142}],"con":true,"img":false}]}
{"op":"mcm","clk":"11540649019","pt":1719496879963,"mc":[{"id":"1.230180117","rc":[{"atb":[[1.53,3.12]],"id":48536142}],"con":true,"img":false}]}
{"op":"mcm","clk":"11540649081","pt":1719496880646,"mc":[{"id":"1.230180117","rc":[{"atb":[[1.53,0]],"id":48536142}],"con":true,"img":false}]}
{"op":"mcm","clk":"11540649462","pt":1719496885861,"mc":[{"id":"1.230180117","rc":[{"atb":[[1.08,50]],"id":63031611},{"atb":[[1.08,50]],"id":69366841},{"atb":[[1.08,50]],"id":40831161},{"atb":[[1.08,50]],"id":64253836},{"atb":[[1.08,50]],"id":48536142},{"atb":[[1.08,50]],"id":68900945}],"con":true,"img":false}]}
{"op":"mcm","clk":"11540649878","pt":1719496891868,"mc":[{"id":"1.230180117","rc":[{"atb":[[1.47,0]],"id":48536142}],"con":true,"img":false}]}
{"op":"mcm","clk":"11540649926","pt":1719496892645,"mc":[{"id":"1.230180117","rc":[{"atb":[[1.59,6.68]],"id":48536142}],"con":true,"img":false}]}
{"op":"mcm","clk":"11540649932","pt":1719496892749,"mc":[{"id":"1.230180117","rc":[{"atb":[[1.56,2.11],[1.6,6.69]],"id":48536142}],"con":true,"img":false}]}
{"op":"mcm","clk":"11540649943","pt":1719496892967,"mc":[{"id":"1.230180117","rc":[{"atb":[[1.49,0]],"id":48536142}],"con":true,"img":false}]}
{"op":"mcm","clk":"11540649974","pt":1719496893368,"mc":[{"id":"1.230180117","rc":[{"atb":[[1.59,16.05]],"id":48536142}],"con":true,"img":false}]}
{"op":"mcm","clk":"11540649999","pt":1719496893679,"mc":[{"id":"1.230180117","rc":[{"atb":[[1.57,0]],"id":48536142}],"con":true,"img":false}]}
{"op":"mcm","clk":"11540650010","pt":1719496893784,"mc":[{"id":"1.230180117","rc":[{"atb":[[1.61,2]],"id":48536142}],"con":true,"img":false}]}
{"op":"mcm","clk":"11540650222","pt":1719496896934,"mc":[{"id":"1.230180117","rc":[{"atb":[[1.56,0]],"id":48536142}],"con":true,"img":false}]}
{"op":"mcm","clk":"11540650229","pt":1719496897037,"mc":[{"id":"1.230180117","rc":[{"atb":[[1.62,2.11]],"id":48536142}],"con":true,"img":false}]}
{"op":"mcm","clk":"11540650244","pt":1719496897243,"mc":[{"id":"1.230180117","rc":[{"atb":[[1.6,0],[1.62,4.23]],"id":48536142}],"con":true,"img":false}]}
{"op":"mcm","clk":"11540650248","pt":1719496897345,"mc":[{"id":"1.230180117","rc":[{"atb":[[1.61,8.69]],"id":48536142}],"con":true,"img":false}]}
{"op":"mcm","clk":"11540650258","pt":1719496897453,"mc":[{"id":"1.230180117","rc":[{"atb":[[1.62,2.11]],"id":48536142}],"con":true,"img":false}]}
{"op":"mcm","clk":"11540650398","pt":1719496899669,"mc":[{"id":"1.230180117","rc":[{"atb":[[1.61,6.69]],"id":48536142}],"con":true,"img":false}]}
{"op":"mcm","clk":"11540650407","pt":1719496899772,"mc":[{"id":"1.230180117","rc":[{"atb":[[1.63,2]],"id":48536142}],"con":true,"img":false}]}
{"op":"mcm","clk":"11540650411","pt":1719496899875,"mc":[{"id":"1.230180117","rc":[{"atb":[[1.63,4.12],[1.61,0]],"id":48536142}],"con":true,"img":false}]}
{"op":"mcm","clk":"11540650415","pt":1719496899978,"mc":[{"id":"1.230180117","rc":[{"atb":[[1.63,2],[1.62,8.8]],"id":48536142}],"con":true,"img":false}]}
{"op":"mcm","clk":"11540651125","pt":1719496909785,"mc":[{"id":"1.230180117","rc":[{"atb":[[1.74,1],[1.66,0]],"id":69366841},{"atb":[[1.41,1]],"id":48536142}],"con":true,"img":false}]}
{"op":"mcm","clk":"11540651189","pt":1719496910565,"mc":[{"id":"1.230180117","rc":[{"atb":[[1.52,0]],"id":48536142}],"con":true,"img":false}]}
{"op":"mcm","clk":"11540651206","pt":1719496910771,"mc":[{"id":"1.230180117","rc":[{"atb":[[1.59,6.68]],"id":48536142}],"con":true,"img":false}]}
{"op":"mcm","clk":"11540651229","pt":1719496911080,"mc":[{"id":"1.230180117","rc":[{"atb":[[1.59,0]],"id":48536142}],"con":true,"img":false}]}
{"op":"mcm","clk":"11540651490","pt":1719496914394,"mc":[{"id":"1.230180117","rc":[{"atb":[[1.63,0]],"id":48536142}],"con":true,"img":false}]}
{"op":"mcm","clk":"11540651502","pt":1719496914494,"mc":[{"id":"1.230180117","rc":[{"atb":[[1.02,2]],"id":48536142}],"con":true,"img":false}]}
{"op":"mcm","clk":"11540651628","pt":1719496916298,"mc":[{"id":"1.230180117","rc":[{"atb":[[1.02,0]],"id":48536142}],"con":true,"img":false}]}
{"op":"mcm","clk":"11540651635","pt":1719496916352,"mc":[{"id":"1.230180117","rc":[{"atb":[[1.63,2]],"id":48536142}],"con":true,"img":false}]}
{"op":"mcm","clk":"11540651794","pt":1719496918475,"mc":[{"id":"1.230180117","rc":[{"atb":[[1.63,0]],"id":48536142}],"con":true,"img":false}]}
{"op":"mcm","clk":"11540651805","pt":1719496918570,"mc":[{"id":"1.230180117","rc":[{"atb":[[1.02,2]],"id":48536142}],"con":true,"img":false}]}
{"op":"mcm","clk":"11540651993","pt":1719496921268,"mc":[{"id":"1.230180117","rc":[{"atb":[[1.02,0]],"id":48536142}],"con":true,"img":false}]}
{"op":"mcm","clk":"11540652002","pt":1719496921373,"mc":[{"id":"1.230180117","rc":[{"atb":[[1.63,2]],"id":48536142}],"con":true,"img":false}]}
{"op":"mcm","clk":"11540652162","pt":1719496923485,"mc":[{"id":"1.230180117","rc":[{"atb":[[1.63,0]],"id":48536142}],"con":true,"img":false}]}
{"op":"mcm","clk":"11540652169","pt":1719496923584,"mc":[{"id":"1.230180117","rc":[{"atb":[[1.02,2]],"id":48536142}],"con":true,"img":false}]}
{"op":"mcm","clk":"11540652344","pt":1719496925801,"mc":[{"id":"1.230180117","rc":[{"atb":[[1.02,0]],"id":48536142}],"con":true,"img":false}]}
{"op":"mcm","clk":"11540652352","pt":1719496925903,"mc":[{"id":"1.230180117","rc":[{"atb":[[1.63,2]],"id":48536142}],"con":true,"img":false}]}
{"op":"mcm","clk":"11540652479","pt":1719496927401,"mc":[{"id":"1.230180117","rc":[{"atb":[[1.01,34.68]],"id":64253836},{"atl":[[1000,1.88]],"id":64253836},{"atb":[[1.01,1.7]],"id":48536142},{"atl":[[1000,1.88]],"id":48536142},{"atl":[[1000,1.88]],"id":68900945}],"con":true,"img":false}]}
{"op":"mcm","clk":"11540652487","pt":1719496927509,"mc":[{"id":"1.230180117","rc":[{"atb":[[1.01,1.7]],"id":68900945}],"con":true,"img":false}]}
{"op":"mcm","clk":"11540652491","pt":1719496927607,"mc":[{"id":"1.230180117","rc":[{"atb":[[1.01,33.48]],"id":64253836},{"atl":[[1000,0.2]],"id":64253836},{"atb":[[1.01,0.44]],"id":48536142},{"atl":[[1000,0.21]],"id":48536142},{"atl":[[1000,0.2]],"id":68900945}],"con":true,"img":false}]}
{"op":"mcm","clk":"11540652498","pt":1719496927710,"mc":[{"id":"1.230180117","rc":[{"atb":[[1.01,0.53]],"id":68900945}],"con":true,"img":false}]}
{"op":"mcm","clk":"11540652507","pt":1719496927915,"mc":[{"id":"1.230180117","rc":[{"atb":[[1.01,32.98]],"id":64253836},{"atl":[[1000,0.17]],"id":64253836},{"atb":[[1.01,0]],"id":48536142},{"atl":[[1000,0.17]],"id":48536142},{"atb":[[1.01,0]],"id":68900945},{"atl":[[1000,0.17]],"id":68900945}],"con":true,"img":false}]}
{"op":"mcm","clk":"11540652515","pt":1719496928018,"mc":[{"id":"1.230180117","rc":[{"atb":[[1.57,0.49]],"id":64253836},{"atl":[[11.5,0.02]],"id":64253836},{"atb":[[1.64,0.44]],"id":48536142},{"atl":[[9,0.03]],"id":48536142},{"atb":[[1.53,0.53]],"id":68900945},{"atl":[[11,0.02]],"id":68900945}],"con":true,"img":false}]}
{"op":"mcm","clk":"11540652524","pt":1719496928172,"mc":[{"id":"1.230180117","rc":[{"atb":[[1.63,0]],"id":48536142}],"con":true,"img":false}]}
{"op":"mcm","clk":"11540652529","pt":1719496928281,"mc":[{"id":"1.230180117","rc":[{"atb":[[1.02,2]],"id":48536142}],"con":true,"img":false}]}
{"op":"mcm","clk":"11540652835","pt":1719496932213,"mc":[{"id":"1.230180117","rc":[{"atb":[[1.02,0]],"id":48536142}],"con":true,"img":false}]}
{"op":"mcm","clk":"11540652849","pt":1719496932312,"mc":[{"id":"1.230180117","rc":[{"atb":[[1.63,2]],"id":48536142}],"con":true,"img":false}]}
{"op":"mcm","clk":"11540653102","pt":1719496935720,"mc":[{"id":"1.230180117","rc":[{"spn":3.28,"spf":"NaN","id":64253836},{"atb":[[1.63,0]],"id":48536142},{"spn":2.92,"spf":"NaN","id":48536142}],"con":true,"img":false}]}
{"op":"mcm","clk":"11540653108","pt":1719496935822,"mc":[{"id":"1.230180117","rc":[{"atb":[[1.02,2]],"id":48536142}],"con":true,"img":false}]}
{"op":"mcm","clk":"11540653361","pt":1719496939683,"mc":[{"id":"1.230180117","rc":[{"atb":[[1.02,0]],"id":48536142}],"con":true,"img":false}]}
{"op":"mcm","clk":"11540653367","pt":1719496939788,"mc":[{"id":"1.230180117","rc":[{"atb":[[1.63,2]],"id":48536142}],"con":true,"img":false}]}
{"op":"mcm","clk":"11540653372","pt":1719496939990,"mc":[{"id":"1.230180117","rc":[{"atb":[[1.66,2.6]],"id":63031611},{"atb":[[2.18,2]],"id":40831161},{"atb":[[1.55,4]],"id":64253836},{"atb":[[1.41,4.39]],"id":48536142},{"atb":[[1.53,3.04]],"id":68900945}],"con":true,"img":false}]}
{"op":"mcm","clk":"11540653376","pt":1719496940096,"mc":[{"id":"1.230180117","rc":[{"atb":[[2.14,0]],"id":40831161},{"atb":[[1.54,2]],"id":68900945}],"con":true,"img":false}]}
{"op":"mcm","clk":"11540653382","pt":1719496940196,"mc":[{"id":"1.230180117","rc":[{"atb":[[2.18,4]],"id":40831161}],"con":true,"img":false}]}
{"op":"mcm","clk":"11540653386","pt":1719496940303,"mc":[{"id":"1.230180117","rc":[{"atb":[[1.52,0]],"id":68900945}],"con":true,"img":false}]}
{"op":"mcm","clk":"11540653459","pt":1719496941538,"mc":[{"id":"1.230180117","rc":[{"atb":[[2.12,3.75]],"id":40831161}],"con":true,"img":false}]}
{"op":"mcm","clk":"11540653475","pt":1719496941795,"mc":[{"id":"1.230180117","rc":[{"atb":[[2.12,0]],"id":40831161}],"con":true,"img":false}]}
{"op":"mcm","clk":"11540653554","pt":1719496943031,"mc":[{"id":"1.230180117","rc":[{"atb":[[2.16,0]],"id":40831161}],"con":true,"img":false}]}
{"op":"mcm","clk":"11540653560","pt":1719496943090,"mc":[{"id":"1.230180117","rc":[{"atb":[[2.2,2]],"id":40831161}],"con":true,"img":false}]}
{"op":"mcm","clk":"11540654280","pt":1719496953827,"mc":[{"id":"1.230180117","rc":[{"spl":[[1.01,10]],"id":40831161}],"con":true,"img":false}]}
{"op":"mcm","clk":"11540654299","pt":1719496954136,"mc":[{"id":"1.230180117","rc":[{"atb":[[1.66,0]],"id":63031611},{"atb":[[2.18,2]],"id":40831161},{"atb":[[1.55,1]],"id":64253836},{"atb":[[1.41,1]],"id":48536142},{"atb":[[1.53,0.53]],"id":68900945}],"con":true,"img":false}]}
{"op":"mcm","clk":"11540654304","pt":1719496954238,"mc":[{"id":"1.230180117","rc":[{"atb":[[1.68,5]],"id":63031611},{"atb":[[1.76,5]],"id":69366841},{"atb":[[2.24,4]],"id":40831161},{"atb":[[1.56,6]],"id":64253836},{"atb":[[1.63,5]],"id":48536142},{"atb":[[1.55,4.71],[1.54,0],[1.53,3.53]],"id":68900945}],"con":true,"img":false}]}
{"op":"mcm","clk":"11540654310","pt":1719496954356,"mc":[{"id":"1.230180117","rc":[{"atb":[[1.77,4.24],[1.75,0]],"id":69366841},{"atb":[[2.18,0],[2.26,2]],"id":40831161},{"atb":[[1.64,5.44],[1.62,2.11]],"id":48536142},{"atb":[[1.56,3.54],[1.53,0.53]],"id":68900945}],"con":true,"img":false}]}
{"op":"mcm","clk":"11540654323","pt":1719496954509,"mc":[{"id":"1.230180117","rc":[{"atb":[[2.24,6],[2.26,0]],"id":40831161}],"con":true,"img":false}]}
{"op":"mcm","clk":"11540654332","pt":1719496954605,"mc":[{"id":"1.230180117","rc":[{"atb":[[2.24,4],[2.22,6]],"id":40831161}],"con":true,"img":false}]}
{"op":"mcm","clk":"11540654346","pt":1719496954812,"mc":[{"id":"1.230180117","rc":[{"atb":[[2.22,0],[2.26,2.12]],"id":40831161}],"con":true,"img":false}]}
{"op":"mcm","clk":"11540654356","pt":1719496954915,"mc":[{"id":"1.230180117","rc":[{"atb":[[2.24,8],[2.26,0]],"id":40831161}],"con":true,"img":false}]}
{"op":"mcm","clk":"11540654365","pt":1719496955035,"mc":[{"id":"1.230180117","rc":[{"atb":[[2.24,4],[2.22,6.12]],"id":40831161}],"con":true,"img":false}]}
{"op":"mcm","clk":"11540654373","pt":1719496955138,"mc":[{"id":"1.230180117","rc":[{"atb":[[2.22,0],[2.26,2.12]],"id":40831161}],"con":true,"img":false}]}
{"op":"mcm","clk":"11540654382","pt":1719496955246,"mc":[{"id":"1.230180117","rc":[{"atb":[[2.24,8],[2.26,0]],"id":40831161}],"con":true,"img":false}]}
{"op":"mcm","clk":"11540654396","pt":1719496955402,"mc":[{"id":"1.230180117","rc":[{"atb":[[2.24,4],[2.22,6.12]],"id":40831161}],"con":true,"img":false}]}
{"op":"mcm","clk":"11540654555","pt":1719496957532,"mc":[{"id":"1.230180117","rc":[{"atb":[[1.63,3]],"id":48536142}],"con":true,"img":false}]}
{"op":"mcm","clk":"11540654566","pt":1719496957635,"mc":[{"id":"1.230180117","rc":[{"atb":[[1.64,0.44],[1.63,13.88],[1.65,2]],"id":48536142}],"con":true,"img":false}]}
{"op":"mcm","clk":"11540654574","pt":1719496957737,"mc":[{"id":"1.230180117","rc":[{"atb":[[1.63,3],[1.65,4]],"id":48536142}],"con":true,"img":false}]}
{"op":"mcm","clk":"11540654581","pt":1719496957840,"mc":[{"id":"1.230180117","rc":[{"atb":[[1.64,4.44],[1.65,2]],"id":48536142}],"con":true,"img":false}]}
{"op":"mcm","clk":"11540654597","pt":1719496958099,"mc":[{"id":"1.230180117","rc":[{"atb":[[1.02,0]],"id":64253836}],"con":true,"img":false}]}
{"op":"mcm","clk":"11540654602","pt":1719496958200,"mc":[{"id":"1.230180117","rc":[{"atb":[[1.57,2.49]],"id":64253836}],"con":true,"img":false}]}
{"op":"mcm","clk":"11540654624","pt":1719496958518,"mc":[{"id":"1.230180117","rc":[{"atb":[[1.76,3]],"id":69366841}],"con":true,"img":false}]}
{"op":"mcm","clk":"11540654633","pt":1719496958616,"mc":[{"id":"1.230180117","rc":[{"atb":[[1.78,2]],"id":69366841}],"con":true,"img":false}]}
{"op":"mcm","clk":"11540654643","pt":1719496958723,"mc":[{"id":"1.230180117","rc":[{"atb":[[1.77,0],[1.76,11.48]],"id":69366841}],"con":true,"img":false}]}
{"op":"mcm","clk":"11540654654","pt":1719496958920,"mc":[{"id":"1.230180117","rc":[{"atb":[[1.02,0]],"id":63031611}],"con":true,"img":false}]}
{"op":"mcm","clk":"11540654662","pt":1719496959022,"mc":[{"id":"1.230180117","rc":[{"atb":[[1.69,2]],"id":63031611}],"con":true,"img":false}]}
{"op":"mcm","clk":"11540654681","pt":1719496959332,"mc":[{"id":"1.230180117","rc":[{"atb":[[2.2,0]],"id":40831161}],"con":true,"img":false}]}
{"op":"mcm","clk":"11540654687","pt":1719496959443,"mc":[{"id":"1.230180117","rc":[{"atb":[[2.22,0],[2.26,6]],"id":40831161}],"con":true,"img":false}]}
{"op":"mcm","clk":"11540654694","pt":1719496959540,"mc":[{"id":"1.230180117","rc":[{"atb":[[2.24,8]],"id":40831161}],"con":true,"img":false}]}
{"op":"mcm","clk":"11540654700","pt":1719496959640,"mc":[{"id":"1.230180117","rc":[{"atb":[[2.26,2]],"id":40831161}],"con":true,"img":false}]}
{"op":"mcm","clk":"11540654796","pt":1719496961445,"mc":[{"id":"1.230180117","rc":[{"atb":[[1.57,0.49]],"id":64253836}],"con":true,"img":false}]}
{"op":"mcm","clk":"11540654806","pt":1719496961551,"mc":[{"id":"1.230180117","rc":[{"atb":[[1.02,2]],"id":64253836}],"con":true,"img":false}]}
{"op":"mcm","clk":"11540654837","pt":1719496962062,"mc":[{"id":"1.230180117","rc":[{"atb":[[1.78,0]],"id":69366841}],"con":true,"img":false}]}
{"op":"mcm","clk":"11540654847","pt":1719496962113,"mc":[{"id":"1.230180117","rc":[{"atb":[[1.77,2]],"id":69366841}],"con":true,"img":false}]}
{"op":"mcm","clk":"11540654865","pt":1719496962424,"mc":[{"id":"1.230180117","rc":[{"atb":[[1.69,0]],"id":63031611}],"con":true,"img":false}]}
{"op":"mcm","clk":"11540654877","pt":1719496962532,"mc":[{"id":"1.230180117","rc":[{"atb":[[1.02,2]],"id":63031611}],"con":true,"img":false}]}
{"op":"mcm","clk":"11540654956","pt":1719496963660,"mc":[{"id":"1.230180117","rc":[{"atb":[[1.81,6.82]],"id":69366841}],"con":true,"img":false}]}
{"op":"mcm","clk":"11540655042","pt":1719496964849,"mc":[{"id":"1.230180117","rc":[{"atb":[[1.82,6.82],[1.76,3]],"id":69366841},{"atb":[[1.02,0]],"id":64253836}],"con":true,"img":false}]}
{"op":"mcm","clk":"11540655050","pt":1719496964954,"mc":[{"id":"1.230180117","rc":[{"atb":[[1.57,2.49]],"id":64253836}],"con":true,"img":false}]}
{"op":"mcm","clk":"11540655095","pt":1719496965632,"mc":[{"id":"1.230180117","rc":[{"atb":[[1.77,0]],"id":69366841}],"con":true,"img":false}]}
{"op":"mcm","clk":"11540655105","pt":1719496965731,"mc":[{"id":"1.230180117","rc":[{"atb":[[1.82,8.82]],"id":69366841}],"con":true,"img":false}]}
{"op":"mcm","clk":"11540655139","pt":1719496966247,"mc":[{"id":"1.230180117","rc":[{"atb":[[1.02,0]],"id":63031611}],"con":true,"img":false}]}
{"op":"mcm","clk":"11540655148","pt":1719496966354,"mc":[{"id":"1.230180117","rc":[{"atb":[[1.69,2]],"id":63031611},{"atb":[[1.57,2]],"id":64253836},{"atl":[[11.5,0]],"id":64253836},{"atb":[[1.64,4]],"id":48536142},{"atl":[[9,0]],"id":48536142},{"atb":[[1.53,0]],"id":68900945},{"atl":[[11,0]],"id":68900945}],"con":true,"img":false}]}
{"op":"mcm","clk":"11540655313","pt":1719496968362,"mc":[{"id":"1.230180117","rc":[{"atb":[[1.68,2]],"id":63031611},{"atb":[[1.76,0]],"id":69366841},{"atb":[[2.24,5]],"id":40831161},{"atb":[[1.56,2]],"id":64253836},{"atb":[[1.63,0]],"id":48536142},{"atb":[[1.55,1]],"id":68900945}],"con":true,"img":false}]}
{"op":"mcm","clk":"11540655324","pt":1719496968464,"mc":[{"id":"1.230180117","rc":[{"atb":[[1.56,0],[1.52,4.54]],"id":68900945}],"con":true,"img":false}]}
{"op":"mcm","clk":"11540655331","pt":1719496968572,"mc":[{"id":"1.230180117","rc":[{"atb":[[1.69,5.7]],"id":63031611},{"atb":[[1.83,2.9]],"id":69366841},{"atb":[[2.26,5.2]],"id":40831161},{"atb":[[1.57,5.6]],"id":64253836},{"atb":[[1.65,5]],"id":48536142},{"atb":[[1.56,3.9]],"id":68900945}],"con":true,"img":false}]}
{"op":"mcm","clk":"11540655340","pt":1719496968675,"mc":[{"id":"1.230180117","rc":[{"atb":[[1.7,2]],"id":63031611},{"atb":[[2.24,1],[2.28,5]],"id":40831161},{"atb":[[1.56,0],[1.58,2]],"id":64253836},{"atb":[[1.64,0],[1.66,4]],"id":48536142},{"atb":[[1.57,3.9],[1.52,0]],"id":68900945}],"con":true,"img":false}]}
{"op":"mcm","clk":"11540655355","pt":1719496968823,"mc":[{"id":"1.230180117","rc":[{"atb":[[1.68,0]],"id":63031611}],"con":true,"img":false}]}
{"op":"mcm","clk":"11540655358","pt":1719496968930,"mc":[{"id":"1.230180117","rc":[{"atb":[[1.57,3.6]],"id":64253836}],"con":true,"img":false}]}
{"op":"mcm","clk":"11540655367","pt":1719496969029,"mc":[{"id":"1.230180117","rc":[{"atb":[[1.02,2]],"id":64253836}],"con":true,"img":false}]}
{"op":"mcm","clk":"11540655390","pt":1719496969445,"mc":[{"id":"1.230180117","rc":[{"atb":[[1.02,0]],"id":68900945}],"con":true,"img":false}]}
{"op":"mcm","clk":"11540655395","pt":1719496969548,"mc":[{"id":"1.230180117","rc":[{"atb":[[1.53,2]],"id":68900945}],"con":true,"img":false}]}
{"op":"mcm","clk":"11540655408","pt":1719496969763,"mc":[{"id":"1.230180117","rc":[{"atb":[[1.69,3.7]],"id":63031611}],"con":true,"img":false}]}
{"op":"mcm","clk":"11540655418","pt":1719496969857,"mc":[{"id":"1.230180117","rc":[{"atb":[[1.02,2]],"id":63031611}],"con":true,"img":false}]}
{"op":"mcm","clk":"11540655462","pt":1719496970426,"mc":[{"id":"1.230180117","rc":[{"atb":[[1.56,6.01]],"id":68900945}],"con":true,"img":false}]}
{"op":"mcm","clk":"11540655524","pt":1719496971353,"mc":[{"id":"1.230180117","rc":[{"atb":[[1.65,3]],"id":48536142}],"con":true,"img":false}]}
{"op":"mcm","clk":"11540655534","pt":1719496971457,"mc":[{"id":"1.230180117","rc":[{"atb":[[1.67,2],[1.66,0],[1.65,11]],"id":48536142}],"con":true,"img":false}]}
{"op":"mcm","clk":"11540655562","pt":1719496971869,"mc":[{"id":"1.230180117","rc":[{"atb":[[1.53,0]],"id":68900945}],"con":true,"img":false}]}
{"op":"mcm","clk":"11540655569","pt":1719496971980,"mc":[{"id":"1.230180117","rc":[{"atb":[[1.58,2]],"id":68900945}],"con":true,"img":false}]}
{"op":"mcm","clk":"11540655610","pt":1719496972331,"mc":[{"id":"1.230180117","rc":[{"atb":[[1.82,6.82]],"id":69366841}],"con":true,"img":false}]}
{"op":"mcm","clk":"11540655620","pt":1719496972438,"mc":[{"id":"1.230180117","rc":[{"atb":[[1.84,2]],"id":69366841}],"con":true,"img":false}]}
{"op":"mcm","clk":"11540655641","pt":1719496972639,"mc":[{"id":"1.230180117","rc":[{"atb":[[1.82,0],[1.84,4.9]],"id":69366841}],"con":true,"img":false}]}
{"op":"mcm","clk":"11540655659","pt":1719496972847,"mc":[{"id":"1.230180117","rc":[{"atb":[[2.26,3.2]],"id":40831161}],"con":true,"img":false}]}
{"op":"mcm","clk":"11540655670","pt":1719496972950,"mc":[{"id":"1.230180117","rc":[{"atb":[[1.02,2]],"id":40831161}],"con":true,"img":false}]}
{"op":"mcm","clk":"11540655887","pt":1719496975450,"mc":[{"id":"1.230180117","rc":[{"atb":[[1.67,0]],"id":48536142}],"con":true,"img":false}]}
{"op":"mcm","clk":"11540655894","pt":1719496975562,"mc":[{"id":"1.230180117","rc":[{"atb":[[1.66,2]],"id":48536142}],"con":true,"img":false}]}
{"op":"mcm","clk":"11540656489","pt":1719496982373,"mc":[{"id":"1.230180117","rc":[{"atb":[[1.69,0]],"id":63031611},{"atb":[[1.83,0]],"id":69366841},{"atb":[[2.26,0]],"id":40831161},{"atb":[[1.57,0]],"id":64253836},{"atb":[[1.65,8]],"id":48536142},{"atb":[[1.56,2.11]],"id":68900945}],"con":true,"img":false}]}
{"op":"mcm","clk":"11540656499","pt":1719496982481,"mc":[{"id":"1.230180117","rc":[{"atb":[[1.7,5]],"id":63031611},{"atb":[[1.85,2]],"id":69366841},{"atb":[[2.3,3.43]],"id":40831161},{"atb":[[1.58,6]],"id":64253836},{"atb":[[1.66,4.35]],"id":48536142},{"atb":[[1.58,5.4]],"id":68900945}],"con":true,"img":false}]}
{"op":"mcm","clk":"11540656512","pt":1719496982579,"mc":[{"id":"1.230180117","rc":[{"atb":[[1.7,3],[1.68,4]],"id":63031611},{"atb":[[2.28,0],[2.14,6]],"id":40831161},{"atb":[[1.56,4],[1.58,4]],"id":64253836}],"con":true,"img":false}]}
{"op":"mcm","clk":"11540656521","pt":1719496982637,"mc":[{"id":"1.230180117","rc":[{"atb":[[1.67,4.35],[1.65,0]],"id":48536142},{"atb":[[1.59,3.9],[1.57,0]],"id":68900945}],"con":true,"img":false}]}
{"op":"mcm","clk":"11540656529","pt":1719496982734,"mc":[{"id":"1.230180117","rc":[{"atb":[[2.32,3.43],[2.14,0]],"id":40831161}],"con":true,"img":false}]}
{"op":"mcm","clk":"11540656578","pt":1719496983251,"mc":[{"id":"1.230180117","rc":[{"atb":[[1.41,6.22]],"id":48536142}],"con":true,"img":false}]}
{"op":"mcm","clk":"11540656642","pt":1719496983983,"mc":[{"id":"1.230180117","rc":[{"atb":[[1.66,2.35]],"id":48536142}],"con":true,"img":false}]}
{"op":"mcm","clk":"11540656652","pt":1719496984031,"mc":[{"id":"1.230180117","rc":[{"atb":[[1.68,2]],"id":48536142}],"con":true,"img":false}]}
{"op":"mcm","clk":"11540656691","pt":1719496984545,"mc":[{"id":"1.230180117","rc":[{"atb":[[1.58,3.4]],"id":68900945}],"con":true,"img":false}]}
{"op":"mcm","clk":"11540656697","pt":1719496984653,"mc":[{"id":"1.230180117","rc":[{"atb":[[1.6,2]],"id":68900945}],"con":true,"img":false}]}
{"op":"mcm","clk":"11540656732","pt":1719496985070,"mc":[{"id":"1.230180117","rc":[{"atb":[[1.84,2.9]],"id":69366841}],"con":true,"img":false}]}
{"op":"mcm","clk":"11540656743","pt":1719496985170,"mc":[{"id":"1.230180117","rc":[{"atb":[[1.86,2]],"id":69366841}],"con":true,"img":false}]}
{"op":"mcm","clk":"11540656755","pt":1719496985279,"mc":[{"id":"1.230180117","rc":[{"atb":[[1.84,0],[1.86,4]],"id":69366841}],"con":true,"img":false}]}
{"op":"mcm","clk":"11540657050","pt":1719496988448,"mc":[{"id":"1.230180117","rc":[{"atb":[[1.68,0],[1.71,3]],"id":63031611}],"con":true,"img":false}]}
{"op":"mcm","clk":"11540657063","pt":1719496988544,"mc":[{"id":"1.230180117","rc":[{"atb":[[1.7,6],[1.71,0]],"id":63031611},{"atb":[[1.56,0],[1.59,4]],"id":64253836}],"con":true,"img":false}]}
{"op":"mcm","clk":"11540657188","pt":1719496989746,"mc":[{"id":"1.230180117","rc":[{"atb":[[1.02,0]],"id":63031611}],"con":true,"img":false}]}
{"op":"mcm","clk":"11540657199","pt":1719496989848,"mc":[{"id":"1.230180117","rc":[{"atb":[[1.71,2]],"id":63031611}],"con":true,"img":false}]}
{"op":"mcm","clk":"11540657233","pt":1719496990159,"mc":[{"id":"1.230180117","rc":[{"atb":[[1.66,3.75]],"id":63031611}],"con":true,"img":false}]}
{"op":"mcm","clk":"11540657251","pt":1719496990370,"mc":[{"id":"1.230180117","rc":[{"atb":[[1.66,0]],"id":63031611}],"con":true,"img":false}]}
{"op":"mcm","clk":"11540657519","pt":1719496993178,"mc":[{"id":"1.230180117","rc":[{"atb":[[1.71,0]],"id":63031611}],"con":true,"img":false}]}
{"op":"mcm","clk":"11540657527","pt":1719496993285,"mc":[{"id":"1.230180117","rc":[{"atb":[[1.02,2]],"id":63031611}],"con":true,"img":false}]}
{"op":"mcm","clk":"11540657824","pt":1719496996545,"mc":[{"id":"1.230180117","rc":[{"atb":[[1.02,0]],"id":63031611},{"spn":3.7,"spf":"NaN","id":63031611},{"atb":[[1.85,0]],"id":69366841},{"spn":4.03,"spf":"NaN","id":69366841},{"atb":[[2.3,0]],"id":40831161},{"spn":1.79,"spf":1.0,"id":40831161},{"atb":[[1.58,0]],"id":64253836},{"spn":3.29,"spf":"NaN","id":64253836},{"atb":[[1.66,0]],"id":48536142},{"spn":2.94,"spf":"NaN","id":48536142},{"atb":[[1.58,0]],"id":68900945},{"spn":3.3,"spf":"NaN","id":68900945}],"con":true,"img":false}]}
{"op":"mcm","clk":"11540657834","pt":1719496996649,"mc":[{"id":"1.230180117","rc":[{"atb":[[1.71,2]],"id":63031611},{"atb":[[2.32,0],[2.14,4.43]],"id":40831161},{"atb":[[1.56,8],[1.59,0]],"id":64253836}],"con":true,"img":false}]}
{"op":"mcm","clk":"11540657842","pt":1719496996773,"mc":[{"id":"1.230180117","rc":[{"atb":[[1.87,3]],"id":69366841},{"atb":[[2.34,2]],"id":40831161},{"atb":[[1.6,4.1]],"id":64253836},{"atb":[[1.68,4.3]],"id":48536142},{"atb":[[1.6,6]],"id":68900945}],"con":true,"img":false}]}
{"op":"mcm","clk":"11540657855","pt":1719496996865,"mc":[{"id":"1.230180117","rc":[{"atb":[[1.88,4],[1.86,2]],"id":69366841},{"atb":[[2.14,0],[2.34,4]],"id":40831161},{"atb":[[1.56,0],[1.61,4.1]],"id":64253836},{"atb":[[1.41,1],[1.67,0],[1.68,8.6]],"id":48536142},{"atb":[[1.59,0],[1.61,3.9]],"id":68900945}],"con":true,"img":false}]}
{"op":"mcm","clk":"11540657863","pt":1719496996962,"mc":[{"id":"1.230180117","rc":[{"atb":[[2.14,3],[2.34,2]],"id":40831161}],"con":true,"img":false}]}
{"op":"mcm","clk":"11540657913","pt":1719496997483,"mc":[{"id":"1.230180117","rc":[{"atb":[[2.24,4.75]],"id":40831161}],"con":true,"img":false}]}
{"op":"mcm","clk":"11540657923","pt":1719496997589,"mc":[{"id":"1.230180117","rc":[{"atb":[[2.24,1]],"id":40831161}],"con":true,"img":false}]}
{"op":"mcm","clk":"11540657941","pt":1719496997691,"mc":[{"id":"1.230180117","rc":[{"atb":[[2.14,0],[2.34,5]],"id":40831161}],"con":true,"img":false}]}
{"op":"mcm","clk":"11540657957","pt":1719496997865,"mc":[{"id":"1.230180117","rc":[{"atb":[[2.14,3],[2.34,2]],"id":40831161}],"con":true,"img":false}]}
{"op":"mcm","clk":"11540658101","pt":1719496999264,"mc":[{"id":"1.230180117","rc":[{"atb":[[1.68,6.6]],"id":48536142}],"con":true,"img":false}]}
{"op":"mcm","clk":"11540658107","pt":1719496999368,"mc":[{"id":"1.230180117","rc":[{"atb":[[1.02,2]],"id":48536142}],"con":true,"img":false}]}
{"op":"mcm","clk":"11540658133","pt":1719496999680,"mc":[{"id":"1.230180117","rc":[{"atb":[[1.6,4]],"id":68900945}],"con":true,"img":false}]}
{"op":"mcm","clk":"11540658142","pt":1719496999788,"mc":[{"id":"1.230180117","rc":[{"atb":[[1.62,2]],"id":68900945}],"con":true,"img":false}]}
{"op":"mcm","clk":"11540658182","pt":1719497000200,"mc":[{"id":"1.230180117","rc":[{"atb":[[1.86,0]],"id":69366841}],"con":true,"img":false}]}
{"op":"mcm","clk":"11540658191","pt":1719497000255,"mc":[{"id":"1.230180117","rc":[{"atb":[[1.89,2]],"id":69366841}],"con":true,"img":false}]}
{"op":"mcm","clk":"11540658226","pt":1719497000677,"mc":[{"id":"1.230180117","rc":[{"atb":[[1.71,0]],"id":63031611}],"con":true,"img":false}]}
{"op":"mcm","clk":"11540658234","pt":1719497000775,"mc":[{"id":"1.230180117","rc":[{"atb":[[1.02,2]],"id":63031611}],"con":true,"img":false}]}
{"op":"mcm","clk":"11540658533","pt":1719497003970,"mc":[{"id":"1.230180117","rc":[{"atb":[[1.02,0]],"id":63031611}],"con":true,"img":false}]}
{"op":"mcm","clk":"11540658543","pt":1719497004083,"mc":[{"id":"1.230180117","rc":[{"atb":[[1.71,2]],"id":63031611}],"con":true,"img":false}]}
{"op":"mcm","clk":"11540658666","pt":1719497005183,"mc":[{"id":"1.230180117","rc":[{"atb":[[1.7,3]],"id":63031611},{"atb":[[1.87,0]],"id":69366841},{"atb":[[1.6,0]],"id":64253836},{"atb":[[1.6,0]],"id":68900945}],"con":true,"img":false}]}
{"op":"mcm","clk":"11540658673","pt":1719497005281,"mc":[{"id":"1.230180117","rc":[{"atb":[[1.71,6]],"id":63031611},{"atb":[[1.89,4.7]],"id":69366841},{"atb":[[1.56,8.2],[1.62,4]],"id":64253836},{"atb":[[1.62,5.7]],"id":68900945}],"con":true,"img":false}]}
{"op":"mcm","clk":"11540658683","pt":1719497005390,"mc":[{"id":"1.230180117","rc":[{"atb":[[1.61,0]],"id":64253836}],"con":true,"img":false}]}
{"op":"mcm","clk":"11540658692","pt":1719497005492,"mc":[{"id":"1.230180117","rc":[{"atb":[[1.72,3],[1.7,0]],"id":63031611},{"atb":[[1.9,4.7]],"id":69366841},{"atb":[[1.63,3.9],[1.61,0]],"id":68900945}],"con":true,"img":false}]}
{"op":"mcm","clk":"11540658698","pt":1719497005829,"mc":[{"id":"1.230180117","rc":[{"atb":[[1.88,0]],"id":69366841}],"con":true,"img":false}]}
{"op":"mcm","clk":"11540658716","pt":1719497006107,"mc":[{"id":"1.230180117","rc":[{"atb":[[1.02,0]],"id":64253836}],"con":true,"img":false}]}
{"op":"mcm","clk":"11540658721","pt":1719497006132,"mc":[{"id":"1.230180117","rc":[{"atb":[[1.63,2]],"id":64253836}],"con":true,"img":false}]}
{"op":"mcm","clk":"11540658747","pt":1719497006181,"mc":[{"id":"1.230180117","rc":[{"atb":[[1.81,12.26]],"id":69366841},{"atb":[[2.32,3.75]],"id":40831161},{"atb":[[1.55,4.75]],"id":64253836}],"con":true,"img":false}]}
{"op":"mcm","clk":"11540658757","pt":1719497006267,"mc":[{"id":"1.230180117","rc":[{"atb":[[2.24,5],[2.14,0]],"id":40831161},{"atb":[[1.58,5.05]],"id":68900945}],"con":true,"img":false}]}
{"op":"mcm","clk":"11540658772","pt":1719497006474,"mc":[{"id":"1.230180117","rc":[{"atb":[[1.71,4]],"id":63031611}],"con":true,"img":false}]}
{"op":"mcm","clk":"11540658778","pt":1719497006581,"mc":[{"id":"1.230180117","rc":[{"atb":[[1.02,2]],"id":63031611}],"con":true,"img":false}]}
{"op":"mcm","clk":"11540658810","pt":1719497007001,"mc":[{"id":"1.230180117","rc":[{"atb":[[1.59,2.11]],"id":64253836}],"con":true,"img":false}]}
{"op":"mcm","clk":"11540658831","pt":1719497007215,"mc":[{"id":"1.230180117","rc":[{"atb":[[1.71,7.75]],"id":63031611}],"con":true,"img":false}]}
{"op":"mcm","clk":"11540658850","pt":1719497007370,"mc":[{"id":"1.230180117","rc":[{"atb":[[1.72,0],[1.68,7]],"id":63031611}],"con":true,"img":false}]}
{"op":"mcm","clk":"11540658911","pt":1719497008203,"mc":[{"id":"1.230180117","rc":[{"atb":[[1.71,4]],"id":63031611},{"atb":[[1.62,6.01]],"id":48536142}],"con":true,"img":false}]}
{"op":"mcm","clk":"11540658948","pt":1719497008677,"mc":[{"id":"1.230180117","rc":[{"atb":[[1.62,3.7]],"id":68900945}],"con":true,"img":false}]}
{"op":"mcm","clk":"11540658956","pt":1719497008780,"mc":[{"id":"1.230180117","rc":[{"atb":[[1.64,2]],"id":68900945}],"con":true,"img":false}]}
{"op":"mcm","clk":"11540658989","pt":1719497009314,"mc":[{"id":"1.230180117","rc":[{"atb":[[1.89,2.7]],"id":69366841}],"con":true,"img":false}]}
{"op":"mcm","clk":"11540658999","pt":1719497009365,"mc":[{"id":"1.230180117","rc":[{"atb":[[1.91,2]],"id":69366841}],"con":true,"img":false}]}
{"op":"mcm","clk":"11540659009","pt":1719497009464,"mc":[{"id":"1.230180117","rc":[{"atb":[[1.89,12.1],[1.9,0]],"id":69366841}],"con":true,"img":false}]}
{"op":"mcm","clk":"11540659092","pt":1719497010582,"mc":[{"id":"1.230180117","rc":[{"atb":[[1.81,6.82]],"id":69366841},{"atb":[[2.32,0]],"id":40831161},{"atb":[[1.62,2.11]],"id":48536142},{"atb":[[1.58,0]],"id":68900945}],"con":true,"img":false}]}
{"op":"mcm","clk":"11540659123","pt":1719497010981,"mc":[{"id":"1.230180117","rc":[{"atb":[[1.71,6.11]],"id":63031611},{"atb":[[1.56,0],[1.63,4.12]],"id":64253836}],"con":true,"img":false}]}
{"op":"mcm","clk":"11540659151","pt":1719497011303,"mc":[{"id":"1.230180117","rc":[{"atb":[[1.91,0]],"id":69366841}],"con":true,"img":false}]}
{"op":"mcm","clk":"11540659163","pt":1719497011399,"mc":[{"id":"1.230180117","rc":[{"atb":[[1.9,2]],"id":69366841}],"con":true,"img":false}]}
{"op":"mcm","clk":"11540659211","pt":1719497011968,"mc":[{"id":"1.230180117","rc":[{"atb":[[2.24,1],[2.34,4.12]],"id":40831161}],"con":true,"img":false}]}
{"op":"mcm","clk":"11540659277","pt":1719497013112,"mc":[{"id":"1.230180117","rc":[{"atb":[[1.72,6.12],[1.68,0]],"id":63031611}],"con":true,"img":false}]}
{"op":"mcm","clk":"11540659312","pt":1719497013781,"mc":[{"id":"1.230180117","rc":[{"atb":[[1.71,2.11]],"id":63031611},{"atb":[[1.89,9.4]],"id":69366841},{"atb":[[1.62,0]],"id":64253836},{"atb":[[1.62,0]],"id":68900945}],"con":true,"img":false}]}
{"op":"mcm","clk":"11540659325","pt":1719497013991,"mc":[{"id":"1.230180117","rc":[{"atb":[[1.73,2.9],[1.72,0],[1.71,14.35]],"id":63031611},{"atb":[[1.9,6.4]],"id":69366841},{"atb":[[1.64,3.5]],"id":64253836},{"atb":[[1.64,5.9]],"id":68900945}],"con":true,"img":false}]}
{"op":"mcm","clk":"11540659331","pt":1719497014093,"mc":[{"id":"1.230180117","rc":[{"atb":[[1.63,0],[1.65,3.9]],"id":68900945}],"con":true,"img":false}]}
{"op":"mcm","clk":"11540659409","pt":1719497015077,"mc":[{"id":"1.230180117","rc":[{"atb":[[1.63,2.12]],"id":64253836}],"con":true,"img":false}]}
{"op":"mcm","clk":"11540659420","pt":1719497015186,"mc":[{"id":"1.230180117","rc":[{"atb":[[1.89,0],[1.91,6.82]],"id":69366841},{"atb":[[1.65,2]],"id":64253836}],"con":true,"img":false}]}
{"op":"mcm","clk":"11540659443","pt":1719497015496,"mc":[{"id":"1.230180117","rc":[{"atb":[[1.64,3.9]],"id":68900945}],"con":true,"img":false}]}
{"op":"mcm","clk":"11540659453","pt":1719497015594,"mc":[{"id":"1.230180117","rc":[{"atb":[[1.66,2]],"id":68900945}],"con":true,"img":false}]}
{"op":"mcm","clk":"11540659523","pt":1719497016582,"mc":[{"id":"1.230180117","rc":[{"atb":[[1.63,0],[1.65,4.12]],"id":64253836}],"con":true,"img":false}]}
{"op":"mcm","clk":"11540659586","pt":1719497017510,"mc":[{"id":"1.230180117","rc":[{"atb":[[1.9,4.4]],"id":69366841}],"con":true,"img":false}]}
{"op":"mcm","clk":"11540659594","pt":1719497017620,"mc":[{"id":"1.230180117","rc":[{"atb":[[1.92,2]],"id":69366841}],"con":true,"img":false}]}
{"op":"mcm","clk":"11540659740","pt":1719497019580,"mc":[{"id":"1.230180117","rc":[{"atb":[[1.73,5.8],[1.71,2.11]],"id":63031611}],"con":true,"img":false}]}
{"op":"mcm","clk":"11540659996","pt":1719497022416,"mc":[{"id":"1.230180117","rc":[{"atb":[[1.9,0]],"id":69366841},{"atb":[[1.64,0]],"id":64253836},{"atb":[[1.64,0]],"id":68900945}],"con":true,"img":false}]}
{"op":"mcm","clk":"11540660009","pt":1719497022515,"mc":[{"id":"1.230180117","rc":[{"atb":[[1.92,5.4]],"id":69366841},{"atb":[[1.66,2.99]],"id":64253836},{"atb":[[1.66,5.7]],"id":68900945}],"con":true,"img":false}]}
{"op":"mcm","clk":"11540660027","pt":1719497022723,"mc":[{"id":"1.230180117","rc":[{"atb":[[1.91,0],[1.93,6.82]],"id":69366841},{"atb":[[1.67,3.9],[1.65,0]],"id":68900945}],"con":true,"img":false}]}
{"op":"mcm","clk":"11540660142","pt":1719497024019,"mc":[{"id":"1.230180117","rc":[{"atb":[[1.65,2.12]],"id":64253836}],"con":true,"img":false}]}
{"op":"mcm","clk":"11540660150","pt":1719497024123,"mc":[{"id":"1.230180117","rc":[{"atb":[[1.67,2]],"id":64253836}],"con":true,"img":false}]}
{"op":"mcm","clk":"11540660172","pt":1719497024278,"mc":[{"id":"1.230180117","rc":[{"atb":[[1.67,4.12],[1.65,0]],"id":64253836},{"atb":[[1.66,3.7]],"id":68900945}],"con":true,"img":false}]}
{"op":"mcm","clk":"11540660181","pt":1719497024386,"mc":[{"id":"1.230180117","rc":[{"atb":[[1.68,2]],"id":68900945}],"con":true,"img":false}]}
{"op":"mcm","clk":"11540660203","pt":1719497024590,"mc":[{"id":"1.230180117","rc":[{"atb":[[1.55,1]],"id":64253836}],"con":true,"img":false}]}
{"op":"mcm","clk":"11540660232","pt":1719497024900,"mc":[{"id":"1.230180117","rc":[{"atb":[[1.92,3.4]],"id":69366841}],"con":true,"img":false}]}
{"op":"mcm","clk":"11540660242","pt":1719497025005,"mc":[{"id":"1.230180117","rc":[{"atb":[[1.94,2]],"id":69366841}],"con":true,"img":false}]}
{"op":"mcm","clk":"11540660539","pt":1719497028897,"mc":[{"id":"1.230180117","rc":[{"atb":[[2.32,3.75]],"id":40831161}],"con":true,"img":false}]}
{"op":"mcm","clk":"11540660598","pt":1719497029885,"mc":[{"id":"1.230180117","rc":[{"atb":[[1.64,5]],"id":68900945}],"con":true,"img":false}]}
{"op":"mcm","clk":"11540660695","pt":1719497030917,"mc":[{"id":"1.230180117","rc":[{"atb":[[1.72,3.75]],"id":63031611},{"atb":[[1.89,5]],"id":69366841},{"atb":[[1.63,5.15]],"id":64253836}],"con":true,"img":false}]}
{"op":"mcm","clk":"11540660713","pt":1719497031126,"mc":[{"id":"1.230180117","rc":[{"atb":[[1.63,0]],"id":64253836}],"con":true,"img":false}]}
{"op":"mcm","clk":"11540660770","pt":1719497031703,"mc":[{"id":"1.230180117","rc":[{"atb":[[1.92,0]],"id":69366841},{"atb":[[1.66,0]],"id":64253836},{"atb":[[1.61,3.9]],"id":48536142},{"atb":[[1.66,0]],"id":68900945}],"con":true,"img":false}]}
{"op":"mcm","clk":"11540660789","pt":1719497031918,"mc":[{"id":"1.230180117","rc":[{"atb":[[1.94,5.1]],"id":69366841},{"atb":[[1.68,3.1]],"id":64253836},{"atb":[[1.68,5]],"id":68900945}],"con":true,"img":false}]}
{"op":"mcm","clk":"11540660799","pt":1719497032016,"mc":[{"id":"1.230180117","rc":[{"atb":[[1.93,0],[1.95,5.1]],"id":69366841},{"atb":[[1.67,2],[1.69,3.1]],"id":64253836},{"atb":[[1.67,0],[1.69,5]],"id":68900945}],"con":true,"img":false}]}
{"op":"mcm","clk":"11540660809","pt":1719497032128,"mc":[{"id":"1.230180117","rc":[{"atb":[[1.02,0]],"id":63031611}],"con":true,"img":false}]}
{"op":"mcm","clk":"11540660819","pt":1719497032224,"mc":[{"id":"1.230180117","rc":[{"atb":[[1.74,2]],"id":63031611}],"con":true,"img":false}]}
{"op":"mcm","clk":"11540660915","pt":1719497033625,"mc":[{"id":"1.230180117","rc":[{"atb":[[1.02,0]],"id":48536142}],"con":true,"img":false}]}
{"op":"mcm","clk":"11540660925","pt":1719497033737,"mc":[{"id":"1.230180117","rc":[{"atb":[[1.72,0]],"id":63031611},{"atb":[[1.69,2]],"id":48536142}],"con":true,"img":false}]}
{"op":"mcm","clk":"11540660953","pt":1719497034136,"mc":[{"id":"1.230180117","rc":[{"atb":[[1.67,0]],"id":64253836},{"atb":[[1.61,0]],"id":48536142}],"con":true,"img":false}]}
{"op":"mcm","clk":"11540660961","pt":1719497034234,"mc":[{"id":"1.230180117","rc":[{"atb":[[1.7,2]],"id":64253836}],"con":true,"img":false}]}
{"op":"mcm","clk":"11540660990","pt":1719497034605,"mc":[{"id":"1.230180117","rc":[{"atb":[[1.68,3]],"id":68900945}],"con":true,"img":false}]}
{"op":"mcm","clk":"11540660999","pt":1719497034707,"mc":[{"id":"1.230180117","rc":[{"atb":[[1.7,2]],"id":68900945}],"con":true,"img":false}]}
{"op":"mcm","clk":"11540661025","pt":1719497035020,"mc":[{"id":"1.230180117","rc":[{"atb":[[1.94,3.1]],"id":69366841}],"con":true,"img":false}]}
{"op":"mcm","clk":"11540661036","pt":1719497035118,"mc":[{"id":"1.230180117","rc":[{"atb":[[1.96,2]],"id":69366841}],"con":true,"img":false}]}
{"op":"mcm","clk":"11540661077","pt":1719497035733,"mc":[{"id":"1.230180117","rc":[{"atb":[[1.64,0]],"id":68900945}],"con":true,"img":false}]}
{"op":"mcm","clk":"11540661143","pt":1719497036720,"mc":[{"id":"1.230180117","rc":[{"atb":[[1.89,0]],"id":69366841}],"con":true,"img":false}]}
{"op":"mcm","clk":"11540661387","pt":1719497040328,"mc":[{"id":"1.230180117","rc":[{"atb":[[1.73,2.9]],"id":63031611},{"atb":[[1.94,0]],"id":69366841},{"atb":[[1.68,0]],"id":64253836},{"atb":[[1.68,4.3]],"id":48536142},{"atb":[[1.68,0]],"id":68900945}],"con":true,"img":false}]}
{"op":"mcm","clk":"11540661404","pt":1719497040542,"mc":[{"id":"1.230180117","rc":[{"atb":[[1.74,5.3]],"id":63031611},{"atb":[[1.96,5.29]],"id":69366841},{"atb":[[1.7,5.01]],"id":64253836},{"atb":[[1.69,5.7]],"id":48536142},{"atb":[[1.7,4.9]],"id":68900945}],"con":true,"img":false}]}
{"op":"mcm","clk":"11540661420","pt":1719497040746,"mc":[{"id":"1.230180117","rc":[{"atb":[[1.73,0],[1.75,2.9]],"id":63031611},{"atb":[[1.97,5.29],[1.95,0]],"id":69366841},{"atb":[[1.71,3.1],[1.69,0]],"id":64253836},{"atb":[[1.71,4.9]],"id":68900945}],"con":true,"img":false}]}
{"op":"mcm","clk":"11540661428","pt":1719497040802,"mc":[{"id":"1.230180117","rc":[{"atb":[[1.69,0]],"id":68900945}],"con":true,"img":false}]}
{"op":"mcm","clk":"11540661474","pt":1719497041327,"mc":[{"id":"1.230180117","rc":[{"atb":[[1.7,3.01]],"id":64253836}],"con":true,"img":false}]}
{"op":"mcm","clk":"11540661483","pt":1719497041424,"mc":[{"id":"1.230180117","rc":[{"atb":[[1.72,2]],"id":64253836}],"con":true,"img":false}]}
{"op":"mcm","clk":"11540661516","pt":1719497041840,"mc":[{"id":"1.230180117","rc":[{"atb":[[1.7,2.9]],"id":68900945}],"con":true,"img":false}]}
{"op":"mcm","clk":"11540661524","pt":1719497041947,"mc":[{"id":"1.230180117","rc":[{"atb":[[1.72,2],[1.7,12.7],[1.71,0]],"id":68900945}],"con":true,"img":false}]}
{"op":"mcm","clk":"11540661530","pt":1719497042002,"mc":[{"id":"1.230180117","rc":[{"atb":[[1.72,4.12],[1.7,2.89]],"id":68900945}],"con":true,"img":false}]}
{"op":"mcm","clk":"11540661544","pt":1719497042314,"mc":[{"id":"1.230180117","rc":[{"atb":[[1.96,3.29]],"id":69366841}],"con":true,"img":false}]}
{"op":"mcm","clk":"11540661552","pt":1719497042419,"mc":[{"id":"1.230180117","rc":[{"atb":[[1.98,2]],"id":69366841}],"con":true,"img":false}]}
{"op":"mcm","clk":"11540661581","pt":1719497042725,"mc":[{"id":"1.230180117","rc":[{"atb":[[1.74,3.3]],"id":63031611}],"con":true,"img":false}]}
{"op":"mcm","clk":"11540661589","pt":1719497042829,"mc":[{"id":"1.230180117","rc":[{"atb":[[1.76,2]],"id":63031611}],"con":true,"img":false}]}
{"op":"mcm","clk":"11540662015","pt":1719497048040,"mc":[{"id":"1.230180117","rc":[{"atb":[[2.32,10],[2.48,2.5],[2.4,5],[1.77,3]],"id":63031611},{"atl":[[5.6,3],[8,10],[7.2,5],[6.4,2.5]],"id":63031611},{"atb":[[2.3,5],[2.22,10],[1.99,3],[2.38,2.5]],"id":69366841},{"atl":[[5.5,2.5],[6,3],[6.6,10],[5.9,5]],"id":69366841},{"atb":[[2.5,10],[2.58,5],[2.36,2.25],[2.66,2.5]],"id":40831161},{"atl":[[9.6,2.25],[9.2,2.5],[10,5],[12,10]],"id":40831161},{"atb":[[1.73,3],[2.04,10],[2.12,5],[2.2,2.5]],"id":64253836},{"atl":[[5.1,2.5],[5.5,5],[4.9,3],[5.9,10]],"id":64253836},{"atb":[[1.56,5],[1.59,8.6],[1.6,2.5],[1.68,0],[1.69,9.68],[1.52,10]],"id":48536142},{"atl":[[4.3,10],[3.95,5],[4.1,3.98],[3.75,2.5]],"id":48536142},{"atb":[[1.73,3.09],[1.98,10],[2.04,5],[2.12,2.5]],"id":68900945},{"atl":[[5.5,2.5],[4.9,3.09],[6.6,10],[5.9,5]],"id":68900945}],"con":true,"img":false}]}
{"op":"mcm","clk":"11540662023","pt":1719497048137,"mc":[{"id":"1.230180117","rc":[{"atb":[[2.26,10],[1.75,0]],"id":63031611},{"atl":[[18,0],[5.5,2.5]],"id":63031611},{"atb":[[1.97,0],[2.18,10]],"id":69366841},{"atl":[[5.5,5.5],[15.5,0]],"id":69366841},{"atb":[[2.34,2],[2.66,7.5]],"id":40831161},{"atl":[[70,0],[11.5,4.75]],"id":40831161},{"atb":[[2.04,17.5],[1.71,0]],"id":64253836},{"atl":[[4.8,2.5],[12,0]],"id":64253836},{"atl":[[9.2,0],[3.75,6.48]],"id":48536142},{"atb":[[2,7.5],[1.72,2]],"id":68900945},{"atl":[[4.8,2.5],[11.5,0]],"id":68900945}],"con":true,"img":false}]}
{"op":"mcm","clk":"11540662029","pt":1719497048243,"mc":[{"id":"1.230180117","rc":[{"atb":[[2.32,0]],"id":40831161},{"atl":[[4.1,15.46]],"id":48536142}],"con":true,"img":false}]}
{"op":"mcm","clk":"11540662037","pt":1719497048345,"mc":[{"id":"1.230180117","rc":[{"atl":[[5.5,0],[5.7,6.5]],"id":63031611},{"atl":[[5.5,2.5],[6,13.5]],"id":69366841},{"atb":[[2.5,22.5],[2.66,2.5]],"id":40831161},{"atl":[[4.8,0],[5,6.5]],"id":64253836},{"atl":[[3.75,2.5]],"id":48536142},{"atl":[[4.8,0],[5,6.59]],"id":68900945}],"con":true,"img":false}]}
{"op":"mcm","clk":"11540662045","pt":1719497048402,"mc":[{"id":"1.230180117","rc":[{"atl":[[5.7,1]],"id":63031611},{"atl":[[5.1,12]],"id":64253836}],"con":true,"img":false}]}
{"op":"mcm","clk":"11540662055","pt":1719497048505,"mc":[{"id":"1.230180117","rc":[{"atl":[[6.4,12]],"id":63031611},{"atl":[[5,1]],"id":64253836},{"atl":[[5,1],[5.5,12.18]],"id":68900945}],"con":true,"img":false}]}
{"op":"mcm","clk":"11540662063","pt":1719497048613,"mc":[{"id":"1.230180117","rc":[{"atl":[[5.5,0.84]],"id":63031611},{"atl":[[5.4,0.84]],"id":69366841},{"atl":[[9,0.84]],"id":40831161},{"atl":[[4.8,0.84]],"id":64253836},{"atl":[[3.7,0.84]],"id":48536142},{"atl":[[4.8,0.84]],"id":68900945}],"con":true,"img":false}]}
{"op":"mcm","clk":"11540662080","pt":1719497048820,"mc":[{"id":"1.230180117","rc":[{"atl":[[6.4,2.5],[5.7,6]],"id":63031611},{"atl":[[3.95,10],[4.1,3.98]],"id":48536142},{"atl":[[5,6],[5.5,2.5]],"id":68900945}],"con":true,"img":false}]}
{"op":"mcm","clk":"11540662125","pt":1719497049331,"mc":[{"id":"1.230180117","rc":[{"atb":[[1.74,0]],"id":63031611},{"atb":[[1.96,0]],"id":69366841},{"atb":[[2.34,0]],"id":40831161},{"atb":[[1.72,0],[1.7,0]],"id":64253836},{"atb":[[1.7,0]],"id":68900945}],"con":true,"img":false}]}
{"op":"mcm","clk":"11540662131","pt":1719497049434,"mc":[{"id":"1.230180117","rc":[{"atb":[[2.22,2]],"id":64253836}],"con":true,"img":false}]}
{"op":"mcm","clk":"11540662138","pt":1719497049543,"mc":[{"id":"1.230180117","rc":[{"atb":[[2.48,5.94]],"id":63031611},{"atb":[[2.38,5.39]],"id":69366841},{"atb":[[2.66,5.7]],"id":40831161},{"atb":[[2.12,6.5]],"id":68900945}],"con":true,"img":false}]}
{"op":"mcm","clk":"11540662148","pt":1719497049644,"mc":[{"id":"1.230180117","rc":[{"atb":[[2.5,10],[2.68,5.7]],"id":40831161}],"con":true,"img":false}]}
{"op":"mcm","clk":"11540662172","pt":1719497049907,"mc":[{"id":"1.230180117","rc":[{"atb":[[1.72,0]],"id":68900945}],"con":true,"img":false}]}
{"op":"mcm","clk":"11540662177","pt":1719497050010,"mc":[{"id":"1.230180117","rc":[{"atb":[[2.14,2]],"id":68900945}],"con":true,"img":false}]}
{"op":"mcm","clk":"11540662183","pt":1719497050116,"mc":[{"id":"1.230180117","rc":[{"atl":[[5.4,1.84]],"id":64253836}],"con":true,"img":false}]}
{"op":"mcm","clk":"11540662195","pt":1719497050322,"mc":[{"id":"1.230180117","rc":[{"atb":[[1.98,0]],"id":69366841}],"con":true,"img":false}]}
{"op":"mcm","clk":"11540662205","pt":1719497050423,"mc":[{"id":"1.230180117","rc":[{"atb":[[2.4,2]],"id":69366841}],"con":true,"img":false}]}
{"op":"mcm","clk":"11540662225","pt":1719497050735,"mc":[{"id":"1.230180117","rc":[{"atb":[[1.76,0]],"id":63031611}],"con":true,"img":false}]}
{"op":"mcm","clk":"11540662234","pt":1719497050845,"mc":[{"id":"1.230180117","rc":[{"atb":[[1.02,2]],"id":63031611}],"con":true,"img":false}]}
{"op":"mcm","clk":"11540662250","pt":1719497051047,"mc":[{"id":"1.230180117","rc":[{"atl":[[11.5,0],[9.8,5.75]],"id":40831161}],"con":true,"img":false}]}
{"op":"mcm","clk":"11540662297","pt":1719497051517,"mc":[{"id":"1.230180117","rc":[{"atl":[[5.9,1]],"id":63031611},{"atb":[[2.66,8.82]],"id":40831161}],"con":true,"img":false}]}
{"op":"mcm","clk":"11540662304","pt":1719497051620,"mc":[{"id":"1.230180117","rc":[{"atl":[[5.7,5]],"id":63031611},{"atb":[[1.81,0]],"id":69366841}],"con":true,"img":false}]}
{"op":"mcm","clk":"11540662324","pt":1719497051931,"mc":[{"id":"1.230180117","rc":[{"atb":[[1.71,0],[2.46,2.11]],"id":63031611},{"atb":[[1.71,0],[2.36,2.11]],"id":69366841},{"atb":[[2.1,2.11],[1.56,0]],"id":68900945}],"con":true,"img":false}]}
{"op":"mcm","clk":"11540662365","pt":1719497052450,"mc":[{"id":"1.230180117","rc":[{"atl":[[5.4,0]],"id":64253836},{"atb":[[2.12,10.93]],"id":68900945}],"con":true,"img":false}]}
{"op":"mcm","clk":"11540662391","pt":1719497052710,"mc":[{"id":"1.230180117","rc":[{"atl":[[5.3,4.32]],"id":64253836}],"con":true,"img":false}]}
{"op":"mcm","clk":"11540662409","pt":1719497052927,"mc":[{"id":"1.230180117","rc":[{"atl":[[5.3,0]],"id":64253836}],"con":true,"img":false}]}
{"op":"mcm","clk":"11540662427","pt":1719497053131,"mc":[{"id":"1.230180117","rc":[{"atl":[[5.2,5.64]],"id":64253836}],"con":true,"img":false}]}
{"op":"mcm","clk":"11540662448","pt":1719497053334,"mc":[{"id":"1.230180117","rc":[{"atb":[[1.59,0],[1.66,19.36]],"id":48536142}],"con":true,"img":false}]}
{"op":"mcm","clk":"11540662456","pt":1719497053437,"mc":[{"id":"1.230180117","rc":[{"atb":[[2.44,3.57]],"id":63031611},{"atb":[[2.38,9.27]],"id":69366841},{"atb":[[2.14,4.86]],"id":64253836},{"atl":[[5.2,0]],"id":64253836}],"con":true,"img":false}]}
{"op":"mcm","clk":"11540662512","pt":1719497054119,"mc":[{"id":"1.230180117","rc":[{"atl":[[5.2,4.63]],"id":64253836}],"con":true,"img":false}]}
{"op":"mcm","clk":"11540662522","pt":1719497054217,"mc":[{"id":"1.230180117","rc":[{"atb":[[1.63,5.55]],"id":48536142}],"con":true,"img":false}]}
{"op":"mcm","clk":"11540662536","pt":1719497054425,"mc":[{"id":"1.230180117","rc":[{"atb":[[1.63,0]],"id":48536142}],"con":true,"img":false}]}
{"op":"mcm","clk":"11540662551","pt":1719497054630,"mc":[{"id":"1.230180117","rc":[{"atl":[[5.2,0]],"id":64253836}],"con":true,"img":false}]}
{"op":"mcm","clk":"11540662576","pt":1719497054941,"mc":[{"id":"1.230180117","rc":[{"atl":[[5,2.99]],"id":64253836}],"con":true,"img":false}]}
{"op":"mcm","clk":"11540662587","pt":1719497055051,"mc":[{"id":"1.230180117","rc":[{"atl":[[5.1,2.5],[4.9,6]],"id":64253836}],"con":true,"img":false}]}
{"op":"mcm","clk":"11540662668","pt":1719497055936,"mc":[{"id":"1.230180117","rc":[{"atl":[[6,1],[5.9,0]],"id":63031611},{"atl":[[6.4,1],[6.2,0]],"id":69366841},{"atl":[[9.8,4.75],[9.4,1]],"id":40831161},{"atl":[[4.1,4.98],[4.2,0]],"id":48536142}],"con":true,"img":false}]}
{"op":"mcm","clk":"11540662679","pt":1719497056037,"mc":[{"id":"1.230180117","rc":[{"atl":[[9.2,4.75],[9.8,0]],"id":40831161}],"con":true,"img":false}]}
{"op":"mcm","clk":"11540662694","pt":1719497056147,"mc":[{"id":"1.230180117","rc":[{"atl":[[9.2,2.5],[9.4,6.6]],"id":40831161}],"con":true,"img":false}]}
{"op":"mcm","clk":"11540662791","pt":1719497057141,"mc":[{"id":"1.230180117","rc":[{"atb":[[2.26,0],[2.34,10]],"id":63031611},{"spn":3.99,"spf":"NaN","id":63031611},{"spn":3.9,"spf":"NaN","id":69366841},{"spn":2.67,"spf":1.0,"id":40831161},{"spn":3.51,"spf":"NaN","id":64253836},{"spn":2.69,"spf":"NaN","id":48536142},{"atb":[[2,0],[2.02,7.5]],"id":68900945},{"spn":3.47,"spf":"NaN","id":68900945}],"con":true,"img":false}]}
{"op":"mcm","clk":"11540662816","pt":1719497057442,"mc":[{"id":"1.230180117","rc":[{"atl":[[5,1]],"id":64253836}],"con":true,"img":false}]}
{"op":"mcm","clk":"11540662824","pt":1719497057547,"mc":[{"id":"1.230180117","rc":[{"atl":[[5,7.85],[4.9,3]],"id":64253836}],"con":true,"img":false}]}
{"op":"mcm","clk":"11540662844","pt":1719497057705,"mc":[{"id":"1.230180117","rc":[{"atl":[[4.9,7.63]],"id":64253836}],"con":true,"img":false}]}
{"op":"mcm","clk":"11540662856","pt":1719497057809,"mc":[{"id":"1.230180117","rc":[{"atl":[[4.8,8.47],[5,1]],"id":64253836}],"con":true,"img":false}]}
{"op":"mcm","clk":"11540662872","pt":1719497058018,"mc":[{"id":"1.230180117","rc":[{"atb":[[2.38,6.38]],"id":69366841},{"atb":[[2.66,5.62]],"id":40831161},{"atl":[[4.9,3]],"id":64253836},{"atb":[[2.12,6.93]],"id":68900945}],"con":true,"img":false}]}
{"op":"mcm","clk":"11540662881","pt":1719497058125,"mc":[{"id":"1.230180117","rc":[{"atb":[[2.4,5]],"id":69366841},{"atb":[[2.7,3]],"id":40831161}],"con":true,"img":false}]}
{"op":"mcm","clk":"11540662889","pt":1719497058223,"mc":[{"id":"1.230180117","rc":[{"atb":[[2.58,16.32],[2.68,0]],"id":40831161}],"con":true,"img":false}]}
{"op":"mcm","clk":"11540662897","pt":1719497058327,"mc":[{"id":"1.230180117","rc":[{"atb":[[2.44,0]],"id":63031611},{"atl":[[4.8,12.19]],"id":64253836}],"con":true,"img":false}]}
{"op":"mcm","clk":"11540662920","pt":1719497058537,"mc":[{"id":"1.230180117","rc":[{"atb":[[1.57,12.18],[1.66,0]],"id":48536142}],"con":true,"img":false}]}
{"op":"mcm","clk":"11540662993","pt":1719497059416,"mc":[{"id":"1.230180117","rc":[{"atb":[[2.48,11.94]],"id":63031611},{"atl":[[5.5,6.84]],"id":63031611},{"atb":[[2.4,10.62]],"id":69366841},{"atl":[[5.4,6.46]],"id":69366841},{"atb":[[2.72,6.47]],"id":40831161},{"atl":[[9,7.31]],"id":40831161},{"atb":[[2.22,6.12]],"id":64253836},{"atl":[[4.7,4.12]],"id":64253836},{"atl":[[3.7,4.3]],"id":48536142},{"atb":[[2.14,5.91]],"id":68900945},{"atl":[[4.8,4.75]],"id":68900945}],"con":true,"img":false}]}
{"op":"mcm","clk":"11540663003","pt":1719497059519,"mc":[{"id":"1.230180117","rc":[{"atl":[[5.6,0]],"id":63031611},{"atl":[[4.8,8.47]],"id":64253836}],"con":true,"img":false}]}
{"op":"mcm","clk":"11540663011","pt":1719497059622,"mc":[{"id":"1.230180117","rc":[{"atb":[[1.77,0]],"id":63031611},{"atb":[[1.99,0]],"id":69366841},{"atl":[[6,10.5]],"id":69366841},{"atb":[[2.36,0]],"id":40831161},{"atl":[[9.6,0]],"id":40831161},{"atb":[[1.73,0]],"id":64253836},{"atl":[[4.9,0]],"id":64253836},{"atl":[[4.1,1]],"id":48536142},{"atb":[[1.73,0]],"id":68900945},{"atl":[[4.9,0]],"id":68900945}],"con":true,"img":false}]}
{"op":"mcm","clk":"11540663023","pt":1719497059727,"mc":[{"id":"1.230180117","rc":[{"atb":[[2.66,2.5]],"id":40831161},{"atl":[[4.7,5.57]],"id":64253836}],"con":true,"img":false}]}
{"op":"mcm","clk":"11540663037","pt":1719497059830,"mc":[{"id":"1.230180117","rc":[{"atl":[[6,12.85],[5.7,0]],"id":63031611},{"atl":[[5,1],[5.5,13.26]],"id":68900945}],"con":true,"img":false}]}
{"op":"mcm","clk":"11540663059","pt":1719497060036,"mc":[{"id":"1.230180117","rc":[{"atl":[[4.6,0.84]],"id":64253836}],"con":true,"img":false}]}
{"op":"mcm","clk":"11540663072","pt":1719497060251,"mc":[{"id":"1.230180117","rc":[{"atl":[[4.7,4.12]],"id":64253836}],"con":true,"img":false}]}
{"op":"mcm","clk":"11540663093","pt":1719497060504,"mc":[{"id":"1.230180117","rc":[{"atl":[[4.5,3.96]],"id":64253836}],"con":true,"img":false}]}
{"op":"mcm","clk":"11540663136","pt":1719497061023,"mc":[{"id":"1.230180117","rc":[{"atl":[[4.8,7.63]],"id":64253836}],"con":true,"img":false}]}
{"op":"mcm","clk":"11540663158","pt":1719497061336,"mc":[{"id":"1.230180117","rc":[{"atl":[[4.5,0]],"id":64253836}],"con":true,"img":false}]}
{"op":"mcm","clk":"11540663173","pt":1719497061540,"mc":[{"id":"1.230180117","rc":[{"atl":[[4.4,2.45]],"id":64253836}],"con":true,"img":false}]}
{"op":"mcm","clk":"11540663206","pt":1719497062015,"mc":[{"id":"1.230180117","rc":[{"atl":[[4.6,0]],"id":64253836}],"con":true,"img":false}]}
{"op":"mcm","clk":"11540663280","pt":1719497062843,"mc":[{"id":"1.230180117","rc":[{"atb":[[2.14,0]],"id":64253836}],"con":true,"img":false}]}
{"op":"mcm","clk":"11540663285","pt":1719497062951,"mc":[{"id":"1.230180117","rc":[{"atl":[[4.8,0],[4.4,6.57]],"id":64253836}],"con":true,"img":false}]}
{"op":"mcm","clk":"11540663331","pt":1719497063412,"mc":[{"id":"1.230180117","rc":[{"atb":[[2.58,5],[2.7,15.94]],"id":40831161}],"con":true,"img":false}]}
{"op":"mcm","clk":"11540663340","pt":1719497063520,"mc":[{"id":"1.230180117","rc":[{"atb":[[2.66,12.5]],"id":40831161}],"con":true,"img":false}]}
{"op":"mcm","clk":"11540663349","pt":1719497063620,"mc":[{"id":"1.230180117","rc":[{"atb":[[2.7,3]],"id":40831161}],"con":true,"img":false}]}
{"op":"mcm","clk":"11540663391","pt":1719497064039,"mc":[{"id":"1.230180117","rc":[{"atb":[[2.54,2.11],[2.46,0]],"id":63031611},{"atb":[[2.36,0],[2.46,2.11]],"id":69366841},{"atb":[[1.59,0],[2.18,2.11]],"id":64253836},{"atb":[[2.18,2.11],[2.1,0]],"id":68900945}],"con":true,"img":false}]}
{"op":"mcm","clk":"11540663446","pt":1719497064565,"mc":[{"id":"1.230180117","rc":[{"atl":[[4.4,4.12]],"id":64253836}],"con":true,"img":false}]}
{"op":"mcm","clk":"11540663467","pt":1719497064724,"mc":[{"id":"1.230180117","rc":[{"atl":[[4.3,5.66]],"id":64253836}],"con":true,"img":false}]}
{"op":"mcm","clk":"11540663476","pt":1719497064819,"mc":[{"id":"1.230180117","rc":[{"atb":[[2.12,2.5]],"id":68900945}],"con":true,"img":false}]}
{"op":"mcm","clk":"11540663481","pt":1719497064923,"mc":[{"id":"1.230180117","rc":[{"atb":[[2.38,2.5]],"id":69366841}],"con":true,"img":false}]}
{"op":"mcm","clk":"11540663506","pt":1719497065236,"mc":[{"id":"1.230180117","rc":[{"atl":[[4.3,0]],"id":64253836}],"con":true,"img":false}]}
{"op":"mcm","clk":"11540663533","pt":1719497065546,"mc":[{"id":"1.230180117","rc":[{"atl":[[4.2,1.99]],"id":64253836},{"atb":[[2.14,3.91]],"id":68900945}],"con":true,"img":false}]}
{"op":"mcm","clk":"11540663540","pt":1719497065650,"mc":[{"id":"1.230180117","rc":[{"atb":[[2.2,2]],"id":68900945}],"con":true,"img":false}]}
{"op":"mcm","clk":"11540663566","pt":1719497066066,"mc":[{"id":"1.230180117","rc":[{"atb":[[2.4,8.62]],"id":69366841}],"con":true,"img":false}]}
{"op":"mcm","clk":"11540663573","pt":1719497066120,"mc":[{"id":"1.230180117","rc":[{"atb":[[2.48,2]],"id":69366841}],"con":true,"img":false}]}
{"op":"mcm","clk":"11540663623","pt":1719497066746,"mc":[{"id":"1.230180117","rc":[{"atb":[[2.48,8.5]],"id":63031611},{"atb":[[2.4,5.62]],"id":69366841},{"atb":[[2.7,0]],"id":40831161}],"con":true,"img":false}]}
{"op":"mcm","clk":"11540663630","pt":1719497066856,"mc":[{"id":"1.230180117","rc":[{"atb":[[2.54,4.41]],"id":63031611},{"atb":[[2.48,4]],"id":69366841},{"atb":[[2.72,0],[2.74,3.5]],"id":40831161},{"atb":[[2.2,4.84]],"id":68900945}],"con":true,"img":false}]}
{"op":"mcm","clk":"11540663637","pt":1719497066954,"mc":[{"id":"1.230180117","rc":[{"atb":[[2.7,9.8]],"id":40831161}],"con":true,"img":false}]}
{"op":"mcm","clk":"11540663648","pt":1719497067068,"mc":[{"id":"1.230180117","rc":[{"atl":[[4.1,0.84],[4.2,0]],"id":64253836}],"con":true,"img":false}]}
{"op":"mcm","clk":"11540663679","pt":1719497067329,"mc":[{"id":"1.230180117","rc":[{"atl":[[4.2,1.45]],"id":64253836}],"con":true,"img":false}]}
{"op":"mcm","clk":"11540663736","pt":1719497068060,"mc":[{"id":"1.230180117","rc":[{"atl":[[4.4,0]],"id":64253836}],"con":true,"img":false}]}
{"op":"mcm","clk":"11540663749","pt":1719497068160,"mc":[{"id":"1.230180117","rc":[{"atl":[[4.2,5.57]],"id":64253836}],"con":true,"img":false}]}
{"op":"mcm","clk":"11540663759","pt":1719497068263,"mc":[{"id":"1.230180117","rc":[{"atl":[[4.2,1.45],[4.7,6.62]],"id":64253836}],"con":true,"img":false}]}
{"op":"mcm","clk":"11540663772","pt":1719497068370,"mc":[{"id":"1.230180117","rc":[{"atl":[[4.2,5.57],[4.7,4.12]],"id":64253836}],"con":true,"img":false}]}
{"op":"mcm","clk":"11540663783","pt":1719497068422,"mc":[{"id":"1.230180117","rc":[{"atl":[[4.7,6.62]],"id":64253836}],"con":true,"img":false}]}
{"op":"mcm","clk":"11540663792","pt":1719497068521,"mc":[{"id":"1.230180117","rc":[{"atl":[[4.2,1.45]],"id":64253836}],"con":true,"img":false}]}
{"op":"mcm","clk":"11540663802","pt":1719497068630,"mc":[{"id":"1.230180117","rc":[{"atb":[[2.76,9.8],[2.66,2.5]],"id":40831161}],"con":true,"img":false}]}
{"op":"mcm","clk":"11540663940","pt":1719497070546,"mc":[{"id":"1.230180117","rc":[{"atb":[[2.54,13.3]],"id":63031611},{"atb":[[2.78,10.44]],"id":40831161}],"con":true,"img":false}]}
{"op":"mcm","clk":"11540663951","pt":1719497070647,"mc":[{"id":"1.230180117","rc":[{"atb":[[2.48,10.75]],"id":69366841},{"atl":[[4.2,4.91]],"id":64253836},{"atl":[[3.65,5.11]],"id":48536142},{"atb":[[2.2,11.34]],"id":68900945}],"con":true,"img":false}]}
{"op":"mcm","clk":"11540663957","pt":1719497070756,"mc":[{"id":"1.230180117","rc":[{"atb":[[2.48,2.5]],"id":63031611},{"atb":[[2.4,0]],"id":69366841},{"atb":[[2.7,0]],"id":40831161},{"atl":[[4.2,9.82],[4.7,4.12]],"id":64253836},{"atl":[[3.95,5],[3.7,0.84],[3.75,11.12]],"id":48536142},{"atb":[[2.14,0]],"id":68900945}],"con":true,"img":false}]}
{"op":"mcm","clk":"11540663968","pt":1719497070857,"mc":[{"id":"1.230180117","rc":[{"atl":[[4.7,0]],"id":64253836}],"con":true,"img":false}]}
{"op":"mcm","clk":"11540663972","pt":1719497070962,"mc":[{"id":"1.230180117","rc":[{"atb":[[2.16,20],[2.34,0]],"id":63031611},{"atb":[[2.38,13.74],[2.18,0]],"id":69366841},{"atb":[[2.76,0],[2.56,14.8]],"id":40831161},{"atb":[[2.04,10],[2.2,14.74]],"id":64253836},{"atb":[[1.57,0],[1.48,14.68]],"id":48536142},{"atb":[[2.02,0],[1.74,10]],"id":68900945}],"con":true,"img":false}]}
{"op":"mcm","clk":"11540663979","pt":1719497071065,"mc":[{"id":"1.230180117","rc":[{"atl":[[3.6,0.84]],"id":48536142}],"con":true,"img":false}]}
{"op":"mcm","clk":"11540663989","pt":1719497071167,"mc":[{"id":"1.230180117","rc":[{"atb":[[2.78,0]],"id":40831161}],"con":true,"img":false}]}
{"op":"mcm","clk":"11540664000","pt":1719497071221,"mc":[{"id":"1.230180117","rc":[{"atb":[[2.76,7.57]],"id":40831161}],"con":true,"img":false}]}
{"op":"mcm","clk":"11540664063","pt":1719497071845,"mc":[{"id":"1.230180117","rc":[{"atl":[[4.2,8.37]],"id":64253836}],"con":true,"img":false}]}
{"op":"mcm","clk":"11540664140","pt":1719497072735,"mc":[{"id":"1.230180117","rc":[{"atl":[[6.4,0],[6.6,11]],"id":69366841}],"con":true,"img":false}]}
{"op":"mcm","clk":"11540664240","pt":1719497073824,"mc":[{"id":"1.230180117","rc":[{"atb":[[2.18,6.35]],"id":68900945}],"con":true,"img":false}]}
{"op":"mcm","clk":"11540664316","pt":1719497074766,"mc":[{"id":"1.230180117","rc":[{"atb":[[2.52,3.4]],"id":63031611}],"con":true,"img":false}]}
{"op":"mcm","clk":"11540664327","pt":1719497074868,"mc":[{"id":"1.230180117","rc":[{"atb":[[2.46,5.81]],"id":69366841}],"con":true,"img":false}]}
{"op":"mcm","clk":"11540664385","pt":1719497075331,"mc":[{"id":"1.230180117","rc":[{"atb":[[2.54,11]],"id":63031611},{"atb":[[2.74,0]],"id":40831161},{"atb":[[2.2,8.5]],"id":68900945}],"con":true,"img":false}]}
{"op":"mcm","clk":"11540664394","pt":1719497075437,"mc":[{"id":"1.230180117","rc":[{"atb":[[1.67,5.55]],"id":48536142}],"con":true,"img":false}]}
{"op":"mcm","clk":"11540664403","pt":1719497075538,"mc":[{"id":"1.230180117","rc":[{"atb":[[2.56,3]],"id":63031611},{"atb":[[2.78,2.4]],"id":40831161},{"atb":[[2.22,3]],"id":68900945}],"con":true,"img":false}]}
{"op":"mcm","clk":"11540664427","pt":1719497075751,"mc":[{"id":"1.230180117","rc":[{"atl":[[5,10.22],[4.2,3.46]],"id":64253836}],"con":true,"img":false}]}
{"op":"mcm","clk":"11540664449","pt":1719497076059,"mc":[{"id":"1.230180117","rc":[{"atb":[[2.78,4.9]],"id":40831161},{"atb":[[1.98,20],[1.74,0]],"id":68900945}],"con":true,"img":false}]}
{"op":"mcm","clk":"11540664458","pt":1719497076160,"mc":[{"id":"1.230180117","rc":[{"atb":[[2.46,10],[2.16,0]],"id":63031611},{"atb":[[2.56,0],[2.66,12.47],[2.78,2.4]],"id":40831161},{"atb":[[1.6,13.6],[1.48,0]],"id":48536142}],"con":true,"img":false}]}
{"op":"mcm","clk":"11540664478","pt":1719497076366,"mc":[{"id":"1.230180117","rc":[{"atb":[[2.54,2.11],[2.46,3.7]],"id":69366841}],"con":true,"img":false}]}
{"op":"mcm","clk":"11540664505","pt":1719497076632,"mc":[{"id":"1.230180117","rc":[{"atb":[[2.2,6.5]],"id":68900945}],"con":true,"img":false}]}
{"op":"mcm","clk":"11540664516","pt":1719497076739,"mc":[{"id":"1.230180117","rc":[{"atb":[[2.24,2]],"id":68900945}],"con":true,"img":false}]}
{"op":"mcm","clk":"11540664608","pt":1719497077772,"mc":[{"id":"1.230180117","rc":[{"atb":[[2.44,6.8],[2.46,0]],"id":63031611},{"atl":[[3.95,6]],"id":48536142}],"con":true,"img":false}]}
{"op":"mcm","clk":"11540664613","pt":1719497077873,"mc":[{"id":"1.230180117","rc":[{"atl":[[4.1,0]],"id":48536142}],"con":true,"img":false}]}
{"op":"mcm","clk":"11540664758","pt":1719497079255,"mc":[{"id":"1.230180117","rc":[{"atb":[[2.48,8.75]],"id":69366841}],"con":true,"img":false}]}
{"op":"mcm","clk":"11540664769","pt":1719497079351,"mc":[{"id":"1.230180117","rc":[{"atb":[[2.56,2]],"id":69366841}],"con":true,"img":false}]}
{"op":"mcm","clk":"11540664950","pt":1719497081377,"mc":[{"id":"1.230180117","rc":[{"atl":[[5.4,7.69]],"id":63031611},{"atb":[[2.18,2.11]],"id":68900945},{"atl":[[4.7,5.82]],"id":68900945}],"con":true,"img":false}]}
{"op":"mcm","clk":"11540664959","pt":1719497081484,"mc":[{"id":"1.230180117","rc":[{"atb":[[2.56,10.69]],"id":63031611},{"atl":[[5.5,0.84]],"id":63031611},{"atl":[[4.8,0.84],[5,10.52],[5.5,2.5]],"id":68900945}],"con":true,"img":false}]}
{"op":"mcm","clk":"11540664970","pt":1719497081533,"mc":[{"id":"1.230180117","rc":[{"atb":[[2.56,7.62]],"id":69366841},{"atl":[[4.1,8.02]],"id":64253836},{"atl":[[3.6,6.26]],"id":48536142},{"atb":[[2.24,7.82]],"id":68900945}],"con":true,"img":false}]}
{"op":"mcm","clk":"11540664979","pt":1719497081646,"mc":[{"id":"1.230180117","rc":[{"atb":[[2.54,2.11]],"id":63031611},{"atb":[[2.48,2]],"id":69366841},{"atl":[[4.2,0]],"id":64253836},{"atl":[[3.65,0]],"id":48536142},{"atb":[[2.2,0]],"id":68900945}],"con":true,"img":false}]}
{"op":"mcm","clk":"11540665001","pt":1719497081846,"mc":[{"id":"1.230180117","rc":[{"atb":[[2.52,0]],"id":63031611},{"atb":[[2.46,0]],"id":69366841}],"con":true,"img":false}]}
{"op":"mcm","clk":"11540665015","pt":1719497082053,"mc":[{"id":"1.230180117","rc":[{"atl":[[5.3,0.84]],"id":63031611},{"atl":[[3.7,0]],"id":48536142},{"atl":[[4.6,0.84]],"id":68900945}],"con":true,"img":false}]}
{"op":"mcm","clk":"11540665023","pt":1719497082157,"mc":[{"id":"1.230180117","rc":[{"atl":[[5.5,9.38],[6,1]],"id":63031611},{"atl":[[3.95,23.39],[3.75,2.5]],"id":48536142}],"con":true,"img":false}]}
{"op":"mcm","clk":"11540665084","pt":1719497082990,"mc":[{"id":"1.230180117","rc":[{"atl":[[6.4,1],[6.6,10]],"id":69366841}],"con":true,"img":false}]}
{"op":"mcm","clk":"11540665166","pt":1719497083976,"mc":[{"id":"1.230180117","rc":[{"atb":[[2.48,0]],"id":69366841},{"atb":[[2.22,0]],"id":68900945}],"con":true,"img":false}]}
{"op":"mcm","clk":"11540665178","pt":1719497084081,"mc":[{"id":"1.230180117","rc":[{"atb":[[2.26,2.9]],"id":68900945}],"con":true,"img":false}]}
{"op":"mcm","clk":"11540665232","pt":1719497084654,"mc":[{"id":"1.230180117","rc":[{"atb":[[2.24,5.82]],"id":68900945}],"con":true,"img":false}]}
{"op":"mcm","clk":"11540665243","pt":1719497084751,"mc":[{"id":"1.230180117","rc":[{"atb":[[2.28,2]],"id":68900945}],"con":true,"img":false}]}
{"op":"mcm","clk":"11540665341","pt":1719497086070,"mc":[{"id":"1.230180117","rc":[{"atl":[[6.2,1],[6,0]],"id":63031611}],"con":true,"img":false}]}
{"op":"mcm","clk":"11540665379","pt":1719497086586,"mc":[{"id":"1.230180117","rc":[{"atl":[[4.8,7.51],[5,1]],"id":68900945}],"con":true,"img":false}]}
{"op":"mcm","clk":"11540665540","pt":1719497088456,"mc":[{"id":"1.230180117","rc":[{"atb":[[2.54,0],[2.62,2.11]],"id":63031611},{"atb":[[1.62,0],[1.7,2.11]],"id":48536142}],"con":true,"img":false}]}
{"op":"mcm","clk":"11540665547","pt":1719497088563,"mc":[{"id":"1.230180117","rc":[{"atb":[[1.7,10.97]],"id":48536142}],"con":true,"img":false}]}
{"op":"mcm","clk":"11540665562","pt":1719497088767,"mc":[{"id":"1.230180117","rc":[{"atb":[[1.69,5.7]],"id":48536142}],"con":true,"img":false}]}
{"op":"mcm","clk":"11540665625","pt":1719497089549,"mc":[{"id":"1.230180117","rc":[{"atb":[[1.69,3.7]],"id":48536142}],"con":true,"img":false}]}
{"op":"mcm","clk":"11540665635","pt":1719497089655,"mc":[{"id":"1.230180117","rc":[{"atb":[[1.71,2]],"id":48536142}],"con":true,"img":false}]}
{"op":"mcm","clk":"11540665657","pt":1719497089972,"mc":[{"id":"1.230180117","rc":[{"atb":[[1.67,0]],"id":48536142}],"con":true,"img":false}]}
{"op":"mcm","clk":"11540665758","pt":1719497091371,"mc":[{"id":"1.230180117","rc":[{"atb":[[2.66,2.49],[2.78,20.41]],"id":40831161}],"con":true,"img":false}]}
{"op":"mcm","clk":"11540665774","pt":1719497091599,"mc":[{"id":"1.230180117","rc":[{"atb":[[2.76,0]],"id":40831161}],"con":true,"img":false}]}
{"op":"mcm","clk":"11540665820","pt":1719497092072,"mc":[{"id":"1.230180117","rc":[{"atl":[[5.2,7.64]],"id":63031611},{"atl":[[4.5,6.54]],"id":68900945}],"con":true,"img":false}]}
{"op":"mcm","clk":"11540665828","pt":1719497092172,"mc":[{"id":"1.230180117","rc":[{"atb":[[2.62,5.57]],"id":63031611},{"atl":[[5.4,0]],"id":63031611},{"atl":[[4.7,0]],"id":68900945}],"con":true,"img":false}]}
{"op":"mcm","clk":"11540665835","pt":1719497092284,"mc":[{"id":"1.230180117","rc":[{"atb":[[2.56,3]],"id":63031611},{"atl":[[4,10.61]],"id":64253836},{"atb":[[2.28,8.54]],"id":68900945}],"con":true,"img":false}]}
{"op":"mcm","clk":"11540665843","pt":1719497092384,"mc":[{"id":"1.230180117","rc":[{"atl":[[4.1,0.84]],"id":64253836},{"atb":[[2.24,0]],"id":68900945}],"con":true,"img":false}]}
{"op":"mcm","clk":"11540665857","pt":1719497092591,"mc":[{"id":"1.230180117","rc":[{"atb":[[2.56,0]],"id":63031611},{"atl":[[5.1,0.84],[5.5,8.54]],"id":63031611},{"atl":[[3.95,0.84]],"id":64253836},{"atb":[[1.69,0]],"id":48536142},{"atb":[[2.26,0]],"id":68900945},{"atl":[[4.8,6.67],[4.4,0.84]],"id":68900945}],"con":true,"img":false}]}
{"op":"mcm","clk":"11540665864","pt":1719497092703,"mc":[{"id":"1.230180117","rc":[{"atb":[[2.64,2.6]],"id":63031611},{"atl":[[5.3,9.33],[5.5,0]],"id":63031611},{"atb":[[2.58,3]],"id":69366841},{"atl":[[5,1],[4.1,12.3]],"id":64253836},{"atb":[[1.71,4.9]],"id":48536142},{"atb":[[2.3,3.21]],"id":68900945},{"atl":[[4.8,0],[4.6,8.23]],"id":68900945}],"con":true,"img":false}]}
{"op":"mcm","clk":"11540665880","pt":1719497092848,"mc":[{"id":"1.230180117","rc":[{"atb":[[2.58,9]],"id":69366841}],"con":true,"img":false}]}
{"op":"mcm","clk":"11540665896","pt":1719497093071,"mc":[{"id":"1.230180117","rc":[{"atb":[[2.56,2]],"id":69366841}],"con":true,"img":false}]}
{"op":"mcm","clk":"11540665913","pt":1719497093262,"mc":[{"id":"1.230180117","rc":[{"atb":[[2.64,3.5]],"id":40831161}],"con":true,"img":false}]}
{"op":"mcm","clk":"11540665927","pt":1719497093472,"mc":[{"id":"1.230180117","rc":[{"atb":[[2.28,6.54]],"id":68900945}],"con":true,"img":false}]}
{"op":"mcm","clk":"11540665936","pt":1719497093590,"mc":[{"id":"1.230180117","rc":[{"atb":[[2.32,2]],"id":68900945}],"con":true,"img":false}]}
{"op":"mcm","clk":"11540665964","pt":1719497093892,"mc":[{"id":"1.230180117","rc":[{"atb":[[2.56,0]],"id":69366841}],"con":true,"img":false}]}
{"op":"mcm","clk":"11540665971","pt":1719497093990,"mc":[{"id":"1.230180117","rc":[{"atb":[[2.6,2]],"id":69366841}],"con":true,"img":false}]}
{"op":"mcm","clk":"11540665984","pt":1719497094199,"mc":[{"id":"1.230180117","rc":[{"atb":[[2.26,3.98]],"id":68900945}],"con":true,"img":false}]}
{"op":"mcm","clk":"11540666036","pt":1719497095075,"mc":[{"id":"1.230180117","rc":[{"atb":[[2.6,3.23]],"id":63031611},{"atb":[[2.56,3.46]],"id":69366841}],"con":true,"img":false}]}
{"op":"mcm","clk":"11540666098","pt":1719497095797,"mc":[{"id":"1.230180117","rc":[{"atb":[[1.68,5.55]],"id":48536142}],"con":true,"img":false}]}
{"op":"mcm","clk":"11540666335","pt":1719497098690,"mc":[{"id":"1.230180117","rc":[{"atb":[[2.32,0],[2.62,15.57],[2.48,0],[2.4,0],[2.78,2.5],[2.7,5]],"id":63031611},{"atb":[[2.8,2.5],[2.72,5],[2.5,0],[2.64,13.5],[2.58,0],[2.66,0]],"id":40831161},{"atl":[[7.2,7.57]],"id":40831161},{"atl":[[5.1,0],[5,3.5],[5.5,0],[5.9,0]],"id":64253836},{"atl":[[4.3,0],[3.95,18.39],[3.35,2.5],[3.55,5]],"id":48536142},{"atb":[[1.98,10],[2.04,0],[2.12,0],[2.26,8.98],[2.34,2.5]],"id":68900945}],"con":true,"img":false}]}
{"op":"mcm","clk":"11540666343","pt":1719497098792,"mc":[{"id":"1.230180117","rc":[{"atl":[[9.2,0],[10,0],[12,0],[6.8,2.5],[7.6,5],[8.4,10]],"id":40831161},{"atl":[[3.6,12.53],[3.55,12.84]],"id":48536142}],"con":true,"img":false}]}
{"op":"mcm","clk":"11540666348","pt":1719497098896,"mc":[{"id":"1.230180117","rc":[{"atl":[[9,0.84],[7.6,20.14],[9.4,1]],"id":40831161},{"atl":[[3.6,7.11],[3.95,1]],"id":48536142}],"con":true,"img":false}]}
{"op":"mcm","clk":"11540666356","pt":1719497099007,"mc":[{"id":"1.230180117","rc":[{"atb":[[2.6,0]],"id":63031611},{"atb":[[2.64,10]],"id":40831161},{"atb":[[2.26,5]],"id":68900945}],"con":true,"img":false}]}
{"op":"mcm","clk":"11540666367","pt":1719497099100,"mc":[{"id":"1.230180117","rc":[{"atl":[[9,0],[6.6,0.84]],"id":40831161},{"atb":[[1.71,14.4]],"id":48536142},{"atl":[[3.6,6.27],[3.3,0.84]],"id":48536142}],"con":true,"img":false}]}
{"op":"mcm","clk":"11540666375","pt":1719497099218,"mc":[{"id":"1.230180117","rc":[{"atl":[[7.2,17.57]],"id":40831161},{"atb":[[1.7,2.11]],"id":48536142}],"con":true,"img":false}]}
{"op":"mcm","clk":"11540666380","pt":1719497099608,"mc":[{"id":"1.230180117","rc":[{"atl":[[7.6,5]],"id":40831161}],"con":true,"img":false}]}
{"op":"mcm","clk":"11540666386","pt":1719497099620,"mc":[{"id":"1.230180117","rc":[{"atb":[[2.32,0]],"id":68900945}],"con":true,"img":false}]}
{"op":"mcm","clk":"11540666396","pt":1719497099628,"mc":[{"id":"1.230180117","rc":[{"atb":[[2.36,2]],"id":68900945}],"con":true,"img":false}]}
{"op":"mcm","clk":"11540666462","pt":1719497100193,"mc":[{"id":"1.230180117","rc":[{"atb":[[1.56,24.15]],"id":48536142}],"con":true,"img":false}]}
{"op":"mcm","clk":"11540666477","pt":1719497100289,"mc":[{"id":"1.230180117","rc":[{"atb":[[1.6,2.5],[1.68,0]],"id":48536142}],"con":true,"img":false}]}
{"op":"mcm","clk":"11540666604","pt":1719497101385,"mc":[{"id":"1.230180117","rc":[{"atb":[[2.64,0]],"id":63031611},{"atb":[[2.58,6]],"id":69366841},{"atb":[[2.78,18.01]],"id":40831161},{"atb":[[1.71,11.5]],"id":48536142},{"atb":[[2.3,0]],"id":68900945}],"con":true,"img":false}]}
{"op":"mcm","clk":"11540666617","pt":1719497101490,"mc":[{"id":"1.230180117","rc":[{"atb":[[2.8,3]],"id":63031611},{"atb":[[2.6,4.1]],"id":69366841},{"atb":[[2.8,5.77],[2.72,25.51],[2.78,10.44]],"id":40831161},{"atb":[[1.72,3.9]],"id":48536142},{"atb":[[2.32,3]],"id":68900945}],"con":true,"img":false}]}
{"op":"mcm","clk":"11540666655","pt":1719497101903,"mc":[{"id":"1.230180117","rc":[{"atb":[[2.8,17.93]],"id":40831161}],"con":true,"img":false}]}
{"op":"mcm","clk":"11540666679","pt":1719497102112,"mc":[{"id":"1.230180117","rc":[{"atb":[[2.78,0]],"id":40831161}],"con":true,"img":false}]}
{"op":"mcm","clk":"11540666696","pt":1719497102161,"mc":[{"id":"1.230180117","rc":[{"atb":[[1.71,9.5]],"id":48536142}],"con":true,"img":false}]}
{"op":"mcm","clk":"11540666708","pt":1719497102269,"mc":[{"id":"1.230180117","rc":[{"atb":[[1.73,2]],"id":48536142}],"con":true,"img":false}]}
{"op":"mcm","clk":"11540666737","pt":1719497102574,"mc":[{"id":"1.230180117","rc":[{"atl":[[5.1,6.84]],"id":63031611},{"atl":[[4.4,4.96]],"id":68900945}],"con":true,"img":false}]}
{"op":"mcm","clk":"11540666745","pt":1719497102678,"mc":[{"id":"1.230180117","rc":[{"atb":[[2.8,9]],"id":63031611},{"atl":[[5.3,0.84],[5.2,13.7]],"id":63031611},{"atl":[[4.5,0],[4.3,6.54],[4.6,0.84]],"id":68900945}],"con":true,"img":false}]}
{"op":"mcm","clk":"11540666753","pt":1719497102782,"mc":[{"id":"1.230180117","rc":[{"atb":[[2.62,12.11]],"id":63031611},{"atl":[[5.3,21.39]],"id":63031611},{"atl":[[3.9,12.55]],"id":64253836},{"atb":[[2.38,5.98]],"id":68900945},{"atl":[[4.5,11.51]],"id":68900945}],"con":true,"img":false}]}
{"op":"mcm","clk":"11540666759","pt":1719497102884,"mc":[{"id":"1.230180117","rc":[{"atl":[[5.2,0]],"id":63031611},{"atl":[[4.3,0]],"id":68900945}],"con":true,"img":false}]}
{"op":"mcm","clk":"11540666765","pt":1719497102991,"mc":[{"id":"1.230180117","rc":[{"atl":[[4,0]],"id":64253836},{"atb":[[2.28,0]],"id":68900945}],"con":true,"img":false}]}
{"op":"mcm","clk":"11540666774","pt":1719497103092,"mc":[{"id":"1.230180117","rc":[{"atl":[[5.3,20.55]],"id":63031611},{"atl":[[3.85,0.84],[4.1,11.46]],"id":64253836},{"atl":[[4.6,0],[4.2,0.84]],"id":68900945}],"con":true,"img":false}]}
{"op":"mcm","clk":"11540666782","pt":1719497103196,"mc":[{"id":"1.230180117","rc":[{"atl":[[3.95,14.24],[4.1,0]],"id":64253836}],"con":true,"img":false}]}
{"op":"mcm","clk":"11540666792","pt":1719497103302,"mc":[{"id":"1.230180117","rc":[{"atb":[[2.6,10.92]],"id":69366841}],"con":true,"img":false}]}
{"op":"mcm","clk":"11540666800","pt":1719497103407,"mc":[{"id":"1.230180117","rc":[{"atb":[[2.58,0]],"id":69366841}],"con":true,"img":false}]}
{"op":"mcm","clk":"11540666816","pt":1719497103607,"mc":[{"id":"1.230180117","rc":[{"atl":[[4.2,0]],"id":68900945}],"con":true,"img":false}]}
{"op":"mcm","clk":"11540666855","pt":1719497103970,"mc":[{"id":"1.230180117","rc":[{"atb":[[2.56,0]],"id":69366841},{"atb":[[2.36,0]],"id":68900945}],"con":true,"img":false}]}
{"op":"mcm","clk":"11540666866","pt":1719497104077,"mc":[{"id":"1.230180117","rc":[{"atb":[[2.4,2]],"id":68900945}],"con":true,"img":false}]}
{"op":"mcm","clk":"11540666970","pt":1719497105317,"mc":[{"id":"1.230180117","rc":[{"atb":[[2.3,0],[2.22,0],[2.42,2.5],[2.38,11.24],[2.34,5]],"id":69366841}],"con":true,"img":false}]}
{"op":"mcm","clk":"11540667058","pt":1719497106601,"mc":[{"id":"1.230180117","rc":[{"atb":[[2.82,17.93]],"id":40831161}],"con":true,"img":false}]}
{"op":"mcm","clk":"11540667065","pt":1719497106709,"mc":[{"id":"1.230180117","rc":[{"atb":[[2.72,5]],"id":40831161}],"con":true,"img":false}]}
{"op":"mcm","clk":"11540667142","pt":1719497107586,"mc":[{"id":"1.230180117","rc":[{"atl":[[6.2,20.23],[5.3,0]],"id":63031611},{"atl":[[4.5,0],[5,17.48]],"id":68900945}],"con":true,"img":false}]}
{"op":"mcm","clk":"11540667273","pt":1719497109089,"mc":[{"id":"1.230180117","rc":[{"atl":[[6.6,15.13]],"id":40831161}],"con":true,"img":false}]}
{"op":"mcm","clk":"11540667283","pt":1719497109187,"mc":[{"id":"1.230180117","rc":[{"atl":[[3.3,5.64]],"id":48536142}],"con":true,"img":false}]}
{"op":"mcm","clk":"11540667290","pt":1719497109293,"mc":[{"id":"1.230180117","rc":[{"atl":[[7.2,10]],"id":40831161},{"atl":[[3.6,0],[3.25,5.65]],"id":48536142}],"con":true,"img":false}]}
{"op":"mcm","clk":"11540667297","pt":1719497109395,"mc":[{"id":"1.230180117","rc":[{"atl":[[3.55,5]],"id":48536142}],"con":true,"img":false}]}
{"op":"mcm","clk":"11540667307","pt":1719497109499,"mc":[{"id":"1.230180117","rc":[{"atb":[[1.73,9.16]],"id":48536142}],"con":true,"img":false}]}
{"op":"mcm","clk":"11540667317","pt":1719497109600,"mc":[{"id":"1.230180117","rc":[{"atb":[[1.71,0]],"id":48536142},{"atl":[[3.2,0.84]],"id":48536142}],"con":true,"img":false}]}
{"op":"mcm","clk":"11540667351","pt":1719497110116,"mc":[{"id":"1.230180117","rc":[{"atb":[[2.6,8.82]],"id":69366841},{"atb":[[2.8,14.66]],"id":40831161},{"atb":[[1.72,0]],"id":48536142},{"atb":[[2.32,0]],"id":68900945}],"con":true,"img":false}]}
{"op":"mcm","clk":"11540667362","pt":1719497110265,"mc":[{"id":"1.230180117","rc":[{"atb":[[2.84,2]],"id":40831161},{"atb":[[1.74,3]],"id":48536142}],"con":true,"img":false}]}
{"op":"mcm","clk":"11540667483","pt":1719497111719,"mc":[{"id":"1.230180117","rc":[{"atb":[[1.73,7.16]],"id":48536142}],"con":true,"img":false}]}
{"op":"mcm","clk":"11540667491","pt":1719497111813,"mc":[{"id":"1.230180117","rc":[{"atb":[[1.75,2]],"id":48536142}],"con":true,"img":false}]}
{"op":"mcm","clk":"11540667520","pt":1719497112178,"mc":[{"id":"1.230180117","rc":[{"atb":[[2.84,20.5]],"id":40831161},{"atl":[[5,1]],"id":68900945}],"con":true,"img":false}]}
{"op":"mcm","clk":"11540667528","pt":1719497112281,"mc":[{"id":"1.230180117","rc":[{"atl":[[5.5,24.72]],"id":68900945}],"con":true,"img":false}]}
{"op":"mcm","clk":"11540667540","pt":1719497112384,"mc":[{"id":"1.230180117","rc":[{"atb":[[2.82,0],[2.8,2.5],[2.86,17.93]],"id":40831161},{"atl":[[4.2,1.98]],"id":64253836}],"con":true,"img":false}]}
{"op":"mcm","clk":"11540667562","pt":1719497112594,"mc":[{"id":"1.230180117","rc":[{"atb":[[2.8,6.99]],"id":40831161}],"con":true,"img":false}]}
{"op":"mcm","clk":"11540667585","pt":1719497112800,"mc":[{"id":"1.230180117","rc":[{"atb":[[2.8,2.5]],"id":40831161}],"con":true,"img":false}]}
{"op":"mcm","clk":"11540667616","pt":1719497113111,"mc":[{"id":"1.230180117","rc":[{"atl":[[3.85,14.84]],"id":64253836},{"atb":[[2.4,7.6]],"id":68900945}],"con":true,"img":false}]}
{"op":"mcm","clk":"11540667626","pt":1719497113209,"mc":[{"id":"1.230180117","rc":[{"atl":[[3.95,0.84],[3.8,14.25],[3.9,0]],"id":64253836}],"con":true,"img":false}]}
{"op":"mcm","clk":"11540667637","pt":1719497113313,"mc":[{"id":"1.230180117","rc":[{"atb":[[2.38,0]],"id":68900945}],"con":true,"img":false}]}
{"op":"mcm","clk":"11540667656","pt":1719497113468,"mc":[{"id":"1.230180117","rc":[{"atb":[[2.38,3.64]],"id":68900945}],"con":true,"img":false}]}
{"op":"mcm","clk":"11540667666","pt":1719497113572,"mc":[{"id":"1.230180117","rc":[{"atl":[[3.95,0],[3.75,0.84]],"id":64253836}],"con":true,"img":false}]}
{"op":"mcm","clk":"11540667702","pt":1719497113985,"mc":[{"id":"1.230180117","rc":[{"atl":[[3.25,0],[3.3,12.14]],"id":48536142}],"con":true,"img":false}]}
{"op":"mcm","clk":"11540667735","pt":1719497114297,"mc":[{"id":"1.230180117","rc":[{"atb":[[2.58,3.42]],"id":69366841}],"con":true,"img":false}]}
{"op":"mcm","clk":"11540667756","pt":1719497114610,"mc":[{"id":"1.230180117","rc":[{"atl":[[3.2,0]],"id":48536142}],"con":true,"img":false}]}
{"op":"mcm","clk":"11540667774","pt":1719497114816,"mc":[{"id":"1.230180117","rc":[{"atb":[[1.59,9.36]],"id":48536142}],"con":true,"img":false}]}
{"op":"mcm","clk":"11540667791","pt":1719497115023,"mc":[{"id":"1.230180117","rc":[{"atb":[[1.71,5.55]],"id":48536142}],"con":true,"img":false}]}
{"op":"mcm","clk":"11540667832","pt":1719497115490,"mc":[{"id":"1.230180117","rc":[{"atb":[[2.38,0],[2.2,8.42]],"id":69366841},{"atb":[[2.04,21.12],[2.2,2.5]],"id":64253836}],"con":true,"img":false}]}
{"op":"mcm","clk":"11540667867","pt":1719497115918,"mc":[{"id":"1.230180117","rc":[{"atb":[[2.84,18.5]],"id":40831161}],"con":true,"img":false}]}
{"op":"mcm","clk":"11540667876","pt":1719497116017,"mc":[{"id":"1.230180117","rc":[{"atb":[[2.62,3.1]],"id":69366841},{"atb":[[2.88,3.63]],"id":40831161}],"con":true,"img":false}]}
{"op":"mcm","clk":"11540667886","pt":1719497116126,"mc":[{"id":"1.230180117","rc":[{"atb":[[2.62,9.42]],"id":69366841}],"con":true,"img":false}]}
{"op":"mcm","clk":"11540667905","pt":1719497116278,"mc":[{"id":"1.230180117","rc":[{"atb":[[2.6,2]],"id":69366841}],"con":true,"img":false}]}
{"op":"mcm","clk":"11540667961","pt":1719497116891,"mc":[{"id":"1.230180117","rc":[{"atb":[[2.6,0]],"id":69366841}],"con":true,"img":false}]}
{"op":"mcm","clk":"11540667971","pt":1719497116999,"mc":[{"id":"1.230180117","rc":[{"atb":[[2.64,2]],"id":69366841}],"con":true,"img":false}]}
{"op":"mcm","clk":"11540667988","pt":1719497117105,"mc":[{"id":"1.230180117","rc":[{"atb":[[2.58,0]],"id":69366841}],"con":true,"img":false}]}
{"op":"mcm","clk":"11540668025","pt":1719497117511,"mc":[{"id":"1.230180117","rc":[{"spn":3.95,"spf":"NaN","id":63031611},{"spn":4.02,"spf":"NaN","id":69366841},{"atb":[[2.86,0],[2.9,17.93]],"id":40831161},{"spn":2.9,"spf":1.0,"id":40831161},{"spn":2.98,"spf":"NaN","id":64253836},{"spn":2.52,"spf":"NaN","id":48536142},{"spn":3.4,"spf":"NaN","id":68900945}],"con":true,"img":false}]}
{"op":"mcm","clk":"11540668050","pt":1719497117821,"mc":[{"id":"1.230180117","rc":[{"atl":[[3.85,29.94],[3.8,0]],"id":64253836}],"con":true,"img":false}]}
{"op":"mcm","clk":"11540668072","pt":1719497118080,"mc":[{"id":"1.230180117","rc":[{"atl":[[3.75,0]],"id":64253836}],"con":true,"img":false}]}
{"op":"mcm","clk":"11540668110","pt":1719497118593,"mc":[{"id":"1.230180117","rc":[{"atl":[[3.55,19.65],[3.3,5.64]],"id":48536142}],"con":true,"img":false}]}
{"op":"mcm","clk":"11540668191","pt":1719497119630,"mc":[{"id":"1.230180117","rc":[{"atb":[[1.75,8.49]],"id":48536142}],"con":true,"img":false}]}
{"op":"mcm","clk":"11540668196","pt":1719497119733,"mc":[{"id":"1.230180117","rc":[{"atb":[[1.73,0]],"id":48536142}],"con":true,"img":false}]}
{"op":"mcm","clk":"11540668240","pt":1719497120096,"mc":[{"id":"1.230180117","rc":[{"atb":[[1.71,0]],"id":48536142}],"con":true,"img":false}]}
{"op":"mcm","clk":"11540668272","pt":1719497120503,"mc":[{"id":"1.230180117","rc":[{"atb":[[2.52,14],[2.44,0]],"id":63031611},{"atb":[[2.88,39.49],[2.9,0]],"id":40831161}],"con":true,"img":false}]}
{"op":"mcm","clk":"11540668279","pt":1719497120607,"mc":[{"id":"1.230180117","rc":[{"atb":[[2.04,10],[2.14,5]],"id":64253836}],"con":true,"img":false}]}
{"op":"mcm","clk":"11540668371","pt":1719497121689,"mc":[{"id":"1.230180117","rc":[{"atb":[[2.62,6.32]],"id":69366841},{"atb":[[1.74,0]],"id":48536142}],"con":true,"img":false}]}
{"op":"mcm","clk":"11540668380","pt":1719497121800,"mc":[{"id":"1.230180117","rc":[{"atb":[[2.64,4]],"id":69366841},{"atb":[[1.76,2.2]],"id":48536142}],"con":true,"img":false}]}
{"op":"mcm","clk":"11540668395","pt":1719497121897,"mc":[{"id":"1.230180117","rc":[{"atb":[[1.02,0]],"id":40831161}],"con":true,"img":false}]}
{"op":"mcm","clk":"11540668405","pt":1719497122007,"mc":[{"id":"1.230180117","rc":[{"atb":[[2.9,2]],"id":40831161}],"con":true,"img":false}]}
{"op":"mcm","clk":"11540668433","pt":1719497122314,"mc":[{"id":"1.230180117","rc":[{"atb":[[2.9,20.86]],"id":40831161}],"con":true,"img":false}]}
{"op":"mcm","clk":"11540668441","pt":1719497122418,"mc":[{"id":"1.230180117","rc":[{"atb":[[2.84,0]],"id":40831161},{"atl":[[3.85,14.84],[4.2,33.23]],"id":64253836}],"con":true,"img":false}]}
{"op":"mcm","clk":"11540668571","pt":1719497123929,"mc":[{"id":"1.230180117","rc":[{"atb":[[1.75,6.49]],"id":48536142}],"con":true,"img":false}]}
{"op":"mcm","clk":"11540668578","pt":1719497124029,"mc":[{"id":"1.230180117","rc":[{"atb":[[1.77,2]],"id":48536142}],"con":true,"img":false}]}
{"op":"mcm","clk":"11540668683","pt":1719497125223,"mc":[{"id":"1.230180117","rc":[{"atl":[[4.2,31.25]],"id":64253836}],"con":true,"img":false}]}
{"op":"mcm","clk":"11540668694","pt":1719497125325,"mc":[{"id":"1.230180117","rc":[{"atl":[[5,28.5],[4.2,0]],"id":64253836}],"con":true,"img":false}]}
{"op":"mcm","clk":"11540668723","pt":1719497125635,"mc":[{"id":"1.230180117","rc":[{"atb":[[2.82,54.95],[2.88,3.63]],"id":40831161},{"atb":[[2.18,10.73],[2.14,0]],"id":64253836}],"con":true,"img":false}]}
{"op":"mcm","clk":"11540668736","pt":1719497125801,"mc":[{"id":"1.230180117","rc":[{"atl":[[4.2,2.81]],"id":64253836}],"con":true,"img":false}]}
{"op":"mcm","clk":"11540668754","pt":1719497125998,"mc":[{"id":"1.230180117","rc":[{"atl":[[4.2,0]],"id":64253836}],"con":true,"img":false}]}
{"op":"mcm","clk":"11540668761","pt":1719497126103,"mc":[{"id":"1.230180117","rc":[{"atb":[[2.64,10.75]],"id":69366841}],"con":true,"img":false}]}
{"op":"mcm","clk":"11540668768","pt":1719497126211,"mc":[{"id":"1.230180117","rc":[{"atb":[[2.62,0]],"id":69366841},{"atl":[[4.1,2.85]],"id":64253836}],"con":true,"img":false}]}
{"op":"mcm","clk":"11540668782","pt":1719497126414,"mc":[{"id":"1.230180117","rc":[{"atl":[[4.1,0]],"id":64253836}],"con":true,"img":false}]}
{"op":"mcm","clk":"11540668811","pt":1719497126832,"mc":[{"id":"1.230180117","rc":[{"atl":[[4,4.53]],"id":64253836}],"con":true,"img":false}]}
{"op":"mcm","clk":"11540668852","pt":1719497127299,"mc":[{"id":"1.230180117","rc":[{"atl":[[4,0]],"id":64253836}],"con":true,"img":false}]}
{"op":"mcm","clk":"11540668876","pt":1719497127609,"mc":[{"id":"1.230180117","rc":[{"atl":[[3.95,1.99]],"id":64253836}],"con":true,"img":false}]}
{"op":"mcm","clk":"11540668918","pt":1719497128234,"mc":[{"id":"1.230180117","rc":[{"atb":[[2.64,8.75]],"id":69366841},{"atb":[[2.88,0]],"id":40831161}],"con":true,"img":false}]}
{"op":"mcm","clk":"11540668923","pt":1719497128333,"mc":[{"id":"1.230180117","rc":[{"atb":[[2.66,3.18]],"id":69366841},{"atb":[[2.92,3]],"id":40831161}],"con":true,"img":false}]}
{"op":"mcm","clk":"11540669014","pt":1719497129520,"mc":[{"id":"1.230180117","rc":[{"atb":[[2.64,6.75]],"id":69366841}],"con":true,"img":false}]}
{"op":"mcm","clk":"11540669020","pt":1719497129626,"mc":[{"id":"1.230180117","rc":[{"atb":[[2.68,2]],"id":69366841}],"con":true,"img":false}]}
{"op":"mcm","clk":"11540669038","pt":1719497129828,"mc":[{"id":"1.230180117","rc":[{"atb":[[2.9,18.86]],"id":40831161}],"con":true,"img":false}]}
{"op":"mcm","clk":"11540669043","pt":1719497129930,"mc":[{"id":"1.230180117","rc":[{"atb":[[1.02,2]],"id":40831161}],"con":true,"img":false}]}
{"op":"mcm","clk":"11540669074","pt":1719497130398,"mc":[{"id":"1.230180117","rc":[{"atl":[[5,3.5],[3.95,31.69]],"id":64253836}],"con":true,"img":false}]}
{"op":"mcm","clk":"11540669089","pt":1719497130705,"mc":[{"id":"1.230180117","rc":[{"atb":[[2.02,6.36],[2.2,0]],"id":69366841},{"atb":[[2.82,0],[2.76,21.86]],"id":40831161}],"con":true,"img":false}]}
{"op":"mcm","clk":"11540669109","pt":1719497131018,"mc":[{"id":"1.230180117","rc":[{"atb":[[2.88,4.62]],"id":40831161}],"con":true,"img":false}]}
{"op":"mcm","clk":"11540669180","pt":1719497131842,"mc":[{"id":"1.230180117","rc":[{"atl":[[4,3.37]],"id":64253836}],"con":true,"img":false}]}
{"op":"mcm","clk":"11540669194","pt":1719497132047,"mc":[{"id":"1.230180117","rc":[{"atl":[[3.95,29.7]],"id":64253836}],"con":true,"img":false}]}
{"op":"mcm","clk":"11540669204","pt":1719497132100,"mc":[{"id":"1.230180117","rc":[{"atl":[[4,36.7],[3.95,0]],"id":64253836}],"con":true,"img":false}]}
{"op":"mcm","clk":"11540669213","pt":1719497132207,"mc":[{"id":"1.230180117","rc":[{"atb":[[2.92,13.96]],"id":40831161},{"atl":[[4,3.37],[5,28.5],[3.9,1.65]],"id":64253836}],"con":true,"img":false}]}
{"op":"mcm","clk":"11540669218","pt":1719497132310,"mc":[{"id":"1.230180117","rc":[{"atb":[[2.9,0]],"id":40831161},{"atl":[[5,3.5],[3.9,31.35]],"id":64253836}],"con":true,"img":false}]}
{"op":"mcm","clk":"11540669227","pt":1719497132418,"mc":[{"id":"1.230180117","rc":[{"atl":[[4,19.87],[3.9,1.65]],"id":64253836}],"con":true,"img":false}]}
{"op":"mcm","clk":"11540669235","pt":1719497132514,"mc":[{"id":"1.230180117","rc":[{"atb":[[2.88,0]],"id":40831161},{"atl":[[4,16.5]],"id":64253836}],"con":true,"img":false}]}
{"op":"mcm","clk":"11540669239","pt":1719497132619,"mc":[{"id":"1.230180117","rc":[{"atb":[[2.62,3.34]],"id":69366841}],"con":true,"img":false}]}
{"op":"mcm","clk":"11540669280","pt":1719497133337,"mc":[{"id":"1.230180117","rc":[{"atb":[[1.75,12.04]],"id":48536142}],"con":true,"img":false}]}
{"op":"mcm","clk":"11540669355","pt":1719497134222,"mc":[{"id":"1.230180117","rc":[{"atb":[[2.66,0]],"id":69366841},{"atb":[[1.76,0]],"id":48536142}],"con":true,"img":false}]}
{"op":"mcm","clk":"11540669363","pt":1719497134319,"mc":[{"id":"1.230180117","rc":[{"atb":[[2.68,6]],"id":69366841},{"atb":[[1.77,6.2]],"id":48536142},{"atb":[[2.42,3.7]],"id":68900945}],"con":true,"img":false}]}
{"op":"mcm","clk":"11540669371","pt":1719497134428,"mc":[{"id":"1.230180117","rc":[{"atb":[[2.42,10.2]],"id":68900945}],"con":true,"img":false}]}
{"op":"mcm","clk":"11540669382","pt":1719497134527,"mc":[{"id":"1.230180117","rc":[{"atb":[[2.38,5.03]],"id":68900945}],"con":true,"img":false}]}
{"op":"mcm","clk":"11540669389","pt":1719497134628,"mc":[{"id":"1.230180117","rc":[{"atb":[[2.4,2]],"id":68900945}],"con":true,"img":false}]}
{"op":"mcm","clk":"11540669400","pt":1719497134737,"mc":[{"id":"1.230180117","rc":[{"atb":[[2.38,3.63]],"id":68900945}],"con":true,"img":false}]}
{"op":"mcm","clk":"11540669444","pt":1719497135246,"mc":[{"id":"1.230180117","rc":[{"atb":[[2.38,0]],"id":68900945}],"con":true,"img":false}]}
{"op":"mcm","clk":"11540669460","pt":1719497135448,"mc":[{"id":"1.230180117","rc":[{"atb":[[2.4,0]],"id":68900945}],"con":true,"img":false}]}
{"op":"mcm","clk":"11540669467","pt":1719497135555,"mc":[{"id":"1.230180117","rc":[{"atb":[[2.44,2]],"id":68900945}],"con":true,"img":false}]}
{"op":"mcm","clk":"11540669489","pt":1719497135712,"mc":[{"id":"1.230180117","rc":[{"atb":[[3,5]],"id":69366841}],"con":true,"img":false}]}
{"op":"mcm","clk":"11540669507","pt":1719497135913,"mc":[{"id":"1.230180117","rc":[{"atb":[[3,13.25]],"id":69366841}],"con":true,"img":false}]}
{"op":"mcm","clk":"11540669514","pt":1719497136016,"mc":[{"id":"1.230180117","rc":[{"atb":[[2.64,0]],"id":69366841}],"con":true,"img":false}]}
{"op":"mcm","clk":"11540669564","pt":1719497136741,"mc":[{"id":"1.230180117","rc":[{"atb":[[2.62,0],[2.68,4]],"id":69366841}],"con":true,"img":false}]}
{"op":"mcm","clk":"11540669572","pt":1719497136849,"mc":[{"id":"1.230180117","rc":[{"atb":[[3.05,2]],"id":69366841}],"con":true,"img":false}]}
{"op":"mcm","clk":"11540669589","pt":1719497136999,"mc":[{"id":"1.230180117","rc":[{"atb":[[3.05,12.03]],"id":69366841}],"con":true,"img":false}]}
{"op":"mcm","clk":"11540669628","pt":1719497137524,"mc":[{"id":"1.230180117","rc":[{"atl":[[4,0],[3.9,31.35]],"id":64253836}],"con":true,"img":false}]}
{"op":"mcm","clk":"11540669637","pt":1719497137623,"mc":[{"id":"1.230180117","rc":[{"atl":[[4,16.5],[3.9,1.65]],"id":64253836}],"con":true,"img":false}]}
{"op":"mcm","clk":"11540669651","pt":1719497137731,"mc":[{"id":"1.230180117","rc":[{"atl":[[4,0],[3.9,31.35]],"id":64253836}],"con":true,"img":false}]}
{"op":"mcm","clk":"11540669665","pt":1719497137829,"mc":[{"id":"1.230180117","rc":[{"atl":[[4,16.5],[3.9,1.65]],"id":64253836}],"con":true,"img":false}]}
{"op":"mcm","clk":"11540669674","pt":1719497137936,"mc":[{"id":"1.230180117","rc":[{"atl":[[4,0],[3.9,31.35]],"id":64253836}],"con":true,"img":false}]}
{"op":"mcm","clk":"11540669680","pt":1719497138039,"mc":[{"id":"1.230180117","rc":[{"atl":[[4,16.5],[3.9,1.65]],"id":64253836}],"con":true,"img":false}]}
{"op":"mcm","clk":"11540669688","pt":1719497138139,"mc":[{"id":"1.230180117","rc":[{"atl":[[4,0],[3.9,31.35]],"id":64253836}],"con":true,"img":false}]}
{"op":"mcm","clk":"11540669698","pt":1719497138244,"mc":[{"id":"1.230180117","rc":[{"atl":[[4,16.5],[3.9,1.65]],"id":64253836}],"con":true,"img":false}]}
{"op":"mcm","clk":"11540669710","pt":1719497138342,"mc":[{"id":"1.230180117","rc":[{"atl":[[4,0],[3.9,31.35]],"id":64253836}],"con":true,"img":false}]}
{"op":"mcm","clk":"11540669715","pt":1719497138445,"mc":[{"id":"1.230180117","rc":[{"atl":[[4,16.5],[3.9,1.65]],"id":64253836}],"con":true,"img":false}]}
{"op":"mcm","clk":"11540669725","pt":1719497138549,"mc":[{"id":"1.230180117","rc":[{"atl":[[4,0],[3.9,31.35]],"id":64253836}],"con":true,"img":false}]}
{"op":"mcm","clk":"11540669843","pt":1719497140053,"mc":[{"id":"1.230180117","rc":[{"atb":[[2.68,0]],"id":69366841},{"atb":[[2.42,6.5]],"id":68900945}],"con":true,"img":false}]}
{"op":"mcm","clk":"11540669858","pt":1719497140219,"mc":[{"id":"1.230180117","rc":[{"atb":[[3.1,3.8]],"id":69366841},{"atb":[[2.44,4.44]],"id":68900945}],"con":true,"img":false}]}
{"op":"mcm","clk":"11540669925","pt":1719497141043,"mc":[{"id":"1.230180117","rc":[{"atb":[[3.05,2]],"id":69366841},{"atb":[[2.18,2.11],[2.16,12.24]],"id":64253836}],"con":true,"img":false}]}
{"op":"mcm","clk":"11540669933","pt":1719497141146,"mc":[{"id":"1.230180117","rc":[{"atb":[[3.05,0]],"id":69366841}],"con":true,"img":false}]}
{"op":"mcm","clk":"11540669943","pt":1719497141254,"mc":[{"id":"1.230180117","rc":[{"atb":[[3.15,2]],"id":69366841}],"con":true,"img":false}]}
{"op":"mcm","clk":"11540669986","pt":1719497141818,"mc":[{"id":"1.230180117","rc":[{"atb":[[3.15,13.38]],"id":69366841}],"con":true,"img":false}]}
{"op":"mcm","clk":"11540670217","pt":1719497144156,"mc":[{"id":"1.230180117","rc":[{"atb":[[2.44,11.5]],"id":68900945}],"con":true,"img":false}]}
{"op":"mcm","clk":"11540670231","pt":1719497144358,"mc":[{"id":"1.230180117","rc":[{"atb":[[2.42,0]],"id":68900945}],"con":true,"img":false}]}
{"op":"mcm","clk":"11540670324","pt":1719497145549,"mc":[{"id":"1.230180117","rc":[{"atb":[[3.2,8.6]],"id":69366841}],"con":true,"img":false}]}
{"op":"mcm","clk":"11540670346","pt":1719497145764,"mc":[{"id":"1.230180117","rc":[{"atb":[[3.1,0],[3,5]],"id":69366841},{"atb":[[2.44,9.06]],"id":68900945}],"con":true,"img":false}]}
{"op":"mcm","clk":"11540670360","pt":1719497145959,"mc":[{"id":"1.230180117","rc":[{"atb":[[3.2,11.6]],"id":69366841},{"atb":[[2.46,3.1]],"id":68900945}],"con":true,"img":false}]}
{"op":"mcm","clk":"11540670406","pt":1719497146322,"mc":[{"id":"1.230180117","rc":[{"atb":[[3.15,11.38]],"id":69366841}],"con":true,"img":false}]}
{"op":"mcm","clk":"11540670412","pt":1719497146426,"mc":[{"id":"1.230180117","rc":[{"atb":[[1.02,2]],"id":69366841}],"con":true,"img":false}]}
{"op":"mcm","clk":"11540670436","pt":1719497146739,"mc":[{"id":"1.230180117","rc":[{"atl":[[5.1,5],[5,1],[5.5,10],[4.7,2.5]],"id":64253836},{"atl":[[3.35,0],[3.7,10],[3.55,14.65],[3.3,8.14],[3.5,5],[3.75,0]],"id":48536142}],"con":true,"img":false}]}
{"op":"mcm","clk":"11540670446","pt":1719497146841,"mc":[{"id":"1.230180117","rc":[{"atl":[[3.55,0],[3.25,8.15]],"id":48536142}],"con":true,"img":false}]}
{"op":"mcm","clk":"11540670451","pt":1719497146940,"mc":[{"id":"1.230180117","rc":[{"atl":[[6.2,2.5],[6.8,0],[7.6,0],[7,5],[8.4,0]],"id":40831161},{"atl":[[3.2,10.76]],"id":48536142}],"con":true,"img":false}]}
{"op":"mcm","clk":"11540670457","pt":1719497147044,"mc":[{"id":"1.230180117","rc":[{"atl":[[7.2,0],[6,12.34],[6.6,25.13]],"id":40831161},{"atl":[[3.2,11.6],[3.3,3.34]],"id":48536142}],"con":true,"img":false}]}
{"op":"mcm","clk":"11540670464","pt":1719497147145,"mc":[{"id":"1.230180117","rc":[{"atl":[[6.6,10.84]],"id":40831161}],"con":true,"img":false}]}
{"op":"mcm","clk":"11540670470","pt":1719497147257,"mc":[{"id":"1.230180117","rc":[{"atl":[[5.6,4.43]],"id":69366841}],"con":true,"img":false}]}
{"op":"mcm","clk":"11540670473","pt":1719497147351,"mc":[{"id":"1.230180117","rc":[{"atl":[[5.6,13.4],[6,0]],"id":69366841}],"con":true,"img":false}]}
{"op":"mcm","clk":"11540670489","pt":1719497147556,"mc":[{"id":"1.230180117","rc":[{"atl":[[5.9,0.84]],"id":40831161}],"con":true,"img":false}]}
{"op":"mcm","clk":"11540670499","pt":1719497147669,"mc":[{"id":"1.230180117","rc":[{"atl":[[6.6,10]],"id":40831161},{"atl":[[3.3,2.5]],"id":48536142}],"con":true,"img":false}]}
{"op":"mcm","clk":"11540670509","pt":1719497147764,"mc":[{"id":"1.230180117","rc":[{"atb":[[3,0]],"id":69366841}],"con":true,"img":false}]}
{"op":"mcm","clk":"11540670559","pt":1719497148440,"mc":[{"id":"1.230180117","rc":[{"atb":[[2.44,7.06]],"id":68900945}],"con":true,"img":false}]}
{"op":"mcm","clk":"11540670571","pt":1719497148544,"mc":[{"id":"1.230180117","rc":[{"atb":[[2.48,2]],"id":68900945}],"con":true,"img":false}]}
{"op":"mcm","clk":"11540670793","pt":1719497151121,"mc":[{"id":"1.230180117","rc":[{"atl":[[3.25,0],[3.3,22.26]],"id":48536142}],"con":true,"img":false}]}
{"op":"mcm","clk":"11540670818","pt":1719497151440,"mc":[{"id":"1.230180117","rc":[{"atb":[[1.59,0]],"id":48536142}],"con":true,"img":false}]}
{"op":"mcm","clk":"11540670835","pt":1719497151637,"mc":[{"id":"1.230180117","rc":[{"atb":[[2.46,0]],"id":68900945}],"con":true,"img":false}]}
{"op":"mcm","clk":"11540670843","pt":1719497151751,"mc":[{"id":"1.230180117","rc":[{"atb":[[2.48,4.44]],"id":68900945}],"con":true,"img":false}]}
{"op":"mcm","clk":"11540670921","pt":1719497152673,"mc":[{"id":"1.230180117","rc":[{"atb":[[2.42,3.53]],"id":68900945}],"con":true,"img":false}]}
{"op":"mcm","clk":"11540670963","pt":1719497153040,"mc":[{"id":"1.230180117","rc":[{"atb":[[2.84,5],[2.34,0],[2.76,10],[2.92,2.5],[2.42,0]],"id":69366841}],"con":true,"img":false}]}
{"op":"mcm","clk":"11540670997","pt":1719497153653,"mc":[{"id":"1.230180117","rc":[{"atb":[[2.48,11.5]],"id":68900945}],"con":true,"img":false}]}
{"op":"mcm","clk":"11540671012","pt":1719497153752,"mc":[{"id":"1.230180117","rc":[{"atb":[[2.44,0]],"id":68900945}],"con":true,"img":false}]}
{"op":"mcm","clk":"11540671168","pt":1719497155355,"mc":[{"id":"1.230180117","rc":[{"atl":[[3.3,2.49],[3.5,38.87]],"id":48536142}],"con":true,"img":false}]}
{"op":"mcm","clk":"11540671240","pt":1719497156434,"mc":[{"id":"1.230180117","rc":[{"atl":[[5.9,11.97]],"id":40831161}],"con":true,"img":false}]}
{"op":"mcm","clk":"11540671247","pt":1719497156540,"mc":[{"id":"1.230180117","rc":[{"atl":[[6,0]],"id":40831161}],"con":true,"img":false}]}
{"op":"mcm","clk":"11540671267","pt":1719497156747,"mc":[{"id":"1.230180117","rc":[{"atl":[[3.85,1],[3.95,0]],"id":48536142}],"con":true,"img":false}]}
{"op":"mcm","clk":"11540671310","pt":1719497157363,"mc":[{"id":"1.230180117","rc":[{"atb":[[2.2,14.74],[2.16,0]],"id":64253836},{"atb":[[1.75,11.24]],"id":48536142},{"atb":[[2.48,9.06]],"id":68900945}],"con":true,"img":false}]}
{"op":"mcm","clk":"11540671319","pt":1719497157467,"mc":[{"id":"1.230180117","rc":[{"atb":[[2.24,2]],"id":64253836},{"atb":[[2.5,2]],"id":68900945}],"con":true,"img":false}]}
{"op":"mcm","clk":"11540671324","pt":1719497157569,"mc":[{"id":"1.230180117","rc":[{"atb":[[2.24,17.64]],"id":64253836}],"con":true,"img":false}]}
{"op":"mcm","clk":"11540671328","pt":1719497157671,"mc":[{"id":"1.230180117","rc":[{"atb":[[2.22,2]],"id":64253836}],"con":true,"img":false}]}
{"op":"mcm","clk":"11540671336","pt":1719497157724,"mc":[{"id":"1.230180117","rc":[{"atb":[[2.74,4.37]],"id":40831161}],"con":true,"img":false}]}
{"op":"mcm","clk":"11540671345","pt":1719497157833,"mc":[{"id":"1.230180117","rc":[{"atb":[[1.75,12.04]],"id":48536142}],"con":true,"img":false}]}
{"op":"mcm","clk":"11540671393","pt":1719497158556,"mc":[{"id":"1.230180117","rc":[{"atb":[[2.22,0]],"id":64253836}],"con":true,"img":false}]}
{"op":"mcm","clk":"11540671404","pt":1719497158656,"mc":[{"id":"1.230180117","rc":[{"atb":[[2.26,2]],"id":64253836}],"con":true,"img":false}]}
{"op":"mcm","clk":"11540671434","pt":1719497158963,"mc":[{"id":"1.230180117","rc":[{"atb":[[2.48,7.06]],"id":68900945}],"con":true,"img":false}]}
{"op":"mcm","clk":"11540671444","pt":1719497159068,"mc":[{"id":"1.230180117","rc":[{"atb":[[2.52,2]],"id":68900945}],"con":true,"img":false}]}
{"op":"mcm","clk":"11540671452","pt":1719497159180,"mc":[{"id":"1.230180117","rc":[{"atl":[[3.9,29.7]],"id":64253836}],"con":true,"img":false}]}
{"op":"mcm","clk":"11540671461","pt":1719497159230,"mc":[{"id":"1.230180117","rc":[{"atl":[[3.9,0],[4.7,29.53]],"id":64253836}],"con":true,"img":false}]}
{"op":"mcm","clk":"11540671478","pt":1719497159441,"mc":[{"id":"1.230180117","rc":[{"atl":[[3.85,16.29]],"id":64253836}],"con":true,"img":false}]}
{"op":"mcm","clk":"11540671487","pt":1719497159539,"mc":[{"id":"1.230180117","rc":[{"atl":[[4.7,2.5]],"id":64253836}],"con":true,"img":false}]}
{"op":"mcm","clk":"11540671501","pt":1719497159644,"mc":[{"id":"1.230180117","rc":[{"atl":[[3.85,32.59]],"id":64253836}],"con":true,"img":false}]}
{"op":"mcm","clk":"11540671562","pt":1719497160364,"mc":[{"id":"1.230180117","rc":[{"atb":[[2.22,3.87]],"id":64253836},{"atl":[[3.85,31.14]],"id":64253836}],"con":true,"img":false}]}
{"op":"mcm","clk":"11540671581","pt":1719497160675,"mc":[{"id":"1.230180117","rc":[{"atl":[[3.8,3.47]],"id":64253836}],"con":true,"img":false}]}
{"op":"mcm","clk":"11540671586","pt":1719497160778,"mc":[{"id":"1.230180117","rc":[{"atl":[[3.75,5.5]],"id":64253836}],"con":true,"img":false}]}
{"op":"mcm","clk":"11540671591","pt":1719497160882,"mc":[{"id":"1.230180117","rc":[{"atl":[[3.85,17.14],[3.8,0]],"id":64253836}],"con":true,"img":false}]}
{"op":"mcm","clk":"11540671602","pt":1719497160935,"mc":[{"id":"1.230180117","rc":[{"atl":[[3.75,0]],"id":64253836}],"con":true,"img":false}]}
{"op":"mcm","clk":"11540671608","pt":1719497161037,"mc":[{"id":"1.230180117","rc":[{"atl":[[3.85,16.3],[3.7,0.84],[3.8,4.78]],"id":64253836},{"atl":[[4.9,3.62]],"id":68900945}],"con":true,"img":false}]}
{"op":"mcm","clk":"11540671619","pt":1719497161144,"mc":[{"id":"1.230180117","rc":[{"atl":[[4.8,9.94],[5.5,2.5]],"id":68900945}],"con":true,"img":false}]}
{"op":"mcm","clk":"11540671649","pt":1719497161459,"mc":[{"id":"1.230180117","rc":[{"atb":[[2.22,0]],"id":64253836},{"atl":[[3.85,28.62]],"id":64253836}],"con":true,"img":false}]}
{"op":"mcm","clk":"11540671660","pt":1719497161848,"mc":[{"id":"1.230180117","rc":[{"atl":[[3.7,0]],"id":64253836}],"con":true,"img":false}]}
{"op":"mcm","clk":"11540671669","pt":1719497161861,"mc":[{"id":"1.230180117","rc":[{"atb":[[2.8,13.68]],"id":63031611},{"atl":[[5.1,11]],"id":63031611},{"atl":[[5.4,12.09]],"id":69366841},{"atb":[[2.92,23.81]],"id":40831161},{"atb":[[2.24,25.66],[2.18,0]],"id":64253836},{"atl":[[3.8,8.56]],"id":64253836},{"atl":[[3.2,26.71]],"id":48536142},{"atb":[[2.48,11.89]],"id":68900945},{"atl":[[4.4,10.21]],"id":68900945}],"con":true,"img":false}]}
{"op":"mcm","clk":"11540671677","pt":1719497161869,"mc":[{"id":"1.230180117","rc":[{"atb":[[2.3,2.11]],"id":64253836},{"atl":[[4.9,0]],"id":68900945}],"con":true,"img":false}]}
{"op":"mcm","clk":"11540671692","pt":1719497161971,"mc":[{"id":"1.230180117","rc":[{"atl":[[5,11.01],[6.2,1]],"id":63031611},{"atl":[[5.6,4.42],[5.5,24.72]],"id":69366841},{"atl":[[3.15,26.72],[3.5,5]],"id":48536142},{"atl":[[4.8,0],[4.3,9.94]],"id":68900945}],"con":true,"img":false}]}
{"op":"mcm","clk":"11540671703","pt":1719497162077,"mc":[{"id":"1.230180117","rc":[{"atb":[[2.52,0],[2.6,17.12]],"id":63031611},{"atl":[[4.9,12.01]],"id":63031611},{"atb":[[2.12,15],[2.02,0]],"id":69366841},{"atl":[[6.4,0],[5.5,2.5],[5.3,12.09],[6.6,11]],"id":69366841},{"atb":[[2.82,47.64],[2.76,0]],"id":40831161},{"atl":[[9.2,1],[9.4,0]],"id":40831161},{"atb":[[1.41,0]],"id":48536142},{"atb":[[1.98,0],[2.12,5]],"id":68900945},{"atl":[[4.8,1.63],[5,0],[4.9,1],[4.2,8.96]],"id":68900945}],"con":true,"img":false}]}
{"op":"mcm","clk":"11540671710","pt":1719497162184,"mc":[{"id":"1.230180117","rc":[{"atl":[[4.8,11.01],[5.1,5],[5,0]],"id":63031611},{"atb":[[2.32,15],[2.12,0]],"id":69366841},{"atl":[[5.2,17.24]],"id":69366841},{"atl":[[3.85,16.3]],"id":64253836},{"atl":[[3.1,13.68]],"id":48536142},{"atl":[[4.3,0],[4.1,9.94],[4.4,6.09]],"id":68900945}],"con":true,"img":false}]}
{"op":"mcm","clk":"11540671720","pt":1719497162288,"mc":[{"id":"1.230180117","rc":[{"atl":[[4.8,0],[5,23.02]],"id":63031611},{"atl":[[5.4,6.47]],"id":69366841},{"atl":[[3.2,15.95],[3.15,0],[3.05,26.72]],"id":48536142},{"atl":[[4.3,18.9],[4.1,0]],"id":68900945}],"con":true,"img":false}]}
{"op":"mcm","clk":"11540671730","pt":1719497162340,"mc":[{"id":"1.230180117","rc":[{"atl":[[5.3,0],[5.4,29.2]],"id":69366841},{"atl":[[3.05,0]],"id":48536142}],"con":true,"img":false}]}
{"op":"mcm","clk":"11540671738","pt":1719497162442,"mc":[{"id":"1.230180117","rc":[{"atl":[[5.5,0],[6.6,1],[5.9,0]],"id":69366841},{"atb":[[2.82,0],[2.94,23.82],[2.74,0]],"id":40831161},{"atl":[[3.8,13.03]],"id":64253836},{"atl":[[3.15,40.4]],"id":48536142},{"atl":[[5.5,0],[6.6,0],[5.9,0]],"id":68900945}],"con":true,"img":false}]}
{"op":"mcm","clk":"11540671754","pt":1719497162545,"mc":[{"id":"1.230180117","rc":[{"atl":[[4.8,0.84],[5.1,4.16]],"id":63031611},{"atl":[[5.1,0.84],[5.5,22.22],[5.2,0],[5.4,5.62]],"id":69366841},{"atb":[[2.96,16.48]],"id":40831161},{"atl":[[3.2,15.1],[3.05,0.84]],"id":48536142},{"atl":[[4.8,0],[4.1,0.84],[4.4,5.25]],"id":68900945}],"con":true,"img":false}]}
{"op":"mcm","clk":"11540671763","pt":1719497162659,"mc":[{"id":"1.230180117","rc":[{"atb":[[2.26,0]],"id":64253836}],"con":true,"img":false}]}
{"op":"mcm","clk":"11540671769","pt":1719497162754,"mc":[{"id":"1.230180117","rc":[{"atl":[[5.3,6.09]],"id":69366841},{"atb":[[2.94,0],[2.92,12.85],[2.96,40.3]],"id":40831161},{"atb":[[2.32,2]],"id":64253836}],"con":true,"img":false}]}
{"op":"mcm","clk":"11540671785","pt":1719497162960,"mc":[{"id":"1.230180117","rc":[{"atb":[[2.52,10.22]],"id":68900945}],"con":true,"img":false}]}
{"op":"mcm","clk":"11540671789","pt":1719497163064,"mc":[{"id":"1.230180117","rc":[{"atb":[[2.8,27.97]],"id":63031611},{"atl":[[4.8,7.59]],"id":63031611},{"atl":[[5.1,0],[6.6,0]],"id":69366841},{"atl":[[5,0]],"id":64253836},{"atb":[[2.48,4.83]],"id":68900945},{"atl":[[4.7,3.84]],"id":68900945}],"con":true,"img":false}]}
{"op":"mcm","clk":"11540671802","pt":1719497163167,"mc":[{"id":"1.230180117","rc":[{"atb":[[2.8,0],[2.82,2.5],[2.72,0],[2.64,0],[2.74,5]],"id":40831161},{"atl":[[5.1,1],[4.9,0]],"id":68900945}],"con":true,"img":false}]}
{"op":"mcm","clk":"11540671810","pt":1719497163272,"mc":[{"id":"1.230180117","rc":[{"atl":[[4.8,19.6],[5,0]],"id":63031611},{"atb":[[2.92,9.85]],"id":40831161},{"atb":[[2.24,23.66]],"id":64253836},{"atb":[[1.77,2]],"id":48536142},{"atb":[[2.5,0]],"id":68900945}],"con":true,"img":false}]}
{"op":"mcm","clk":"11540671825","pt":1719497163372,"mc":[{"id":"1.230180117","rc":[{"atb":[[2.98,4]],"id":40831161},{"atb":[[1.75,6.49],[1.76,3.15]],"id":48536142},{"atb":[[2.54,3],[2.42,0]],"id":68900945}],"con":true,"img":false}]}
{"op":"mcm","clk":"11540671843","pt":1719497163579,"mc":[{"id":"1.230180117","rc":[{"atl":[[3.8,8.56]],"id":64253836}],"con":true,"img":false}]}
{"op":"mcm","clk":"11540671871","pt":1719497163840,"mc":[{"id":"1.230180117","rc":[{"atl":[[3.7,1.72]],"id":64253836}],"con":true,"img":false}]}
{"op":"mcm","clk":"11540671893","pt":1719497164044,"mc":[{"id":"1.230180117","rc":[{"atl":[[6.2,0]],"id":63031611},{"atl":[[9.2,0],[8.4,1]],"id":40831161}],"con":true,"img":false}]}
{"op":"mcm","clk":"11540671958","pt":1719497164771,"mc":[{"id":"1.230180117","rc":[{"atl":[[3.85,0],[3.7,10.28]],"id":64253836}],"con":true,"img":false}]}
{"op":"mcm","clk":"11540671963","pt":1719497164874,"mc":[{"id":"1.230180117","rc":[{"atb":[[2.52,8.22]],"id":68900945}],"con":true,"img":false}]}
{"op":"mcm","clk":"11540671971","pt":1719497164972,"mc":[{"id":"1.230180117","rc":[{"atb":[[2.56,2]],"id":68900945}],"con":true,"img":false}]}
{"op":"mcm","clk":"11540672108","pt":1719497166670,"mc":[{"id":"1.230180117","rc":[{"atl":[[5.1,0]],"id":63031611},{"atl":[[5.4,0]],"id":69366841},{"atb":[[2.92,0]],"id":40831161},{"atl":[[3.8,4.78]],"id":64253836},{"atl":[[3.2,0]],"id":48536142},{"atb":[[2.48,0]],"id":68900945},{"atl":[[4.4,0]],"id":68900945}],"con":true,"img":false}]}
{"op":"mcm","clk":"11540672117","pt":1719497166773,"mc":[{"id":"1.230180117","rc":[{"atl":[[9,10],[5.3,0],[8.2,5],[7.4,2.5]],"id":69366841},{"atb":[[2.32,10.3]],"id":64253836},{"atl":[[3.6,1],[3.85,0]],"id":48536142}],"con":true,"img":false}]}
{"op":"mcm","clk":"11540672132","pt":1719497166875,"mc":[{"id":"1.230180117","rc":[{"atl":[[4.8,23.22]],"id":63031611},{"atl":[[5.3,5.47],[5.4,11.86]],"id":69366841},{"atb":[[2.98,13.34]],"id":40831161},{"atl":[[3.7,13.71]],"id":64253836},{"atb":[[1.56,31.32]],"id":48536142},{"atl":[[3.1,28.42]],"id":48536142},{"atb":[[2.52,12.58]],"id":68900945},{"atl":[[4.2,13.72]],"id":68900945}],"con":true,"img":false}]}
{"op":"mcm","clk":"11540672142","pt":1719497166977,"mc":[{"id":"1.230180117","rc":[{"atb":[[2.24,8.02]],"id":64253836},{"atl":[[3.15,0],[3.05,29.27]],"id":48536142},{"atl":[[4.3,0],[4.1,14.57]],"id":68900945}],"con":true,"img":false}]}
{"op":"mcm","clk":"11540672176","pt":1719497167442,"mc":[{"id":"1.230180117","rc":[{"atb":[[2.5,24.24],[2.6,0]],"id":63031611},{"atl":[[4.8,11.21],[5,25]],"id":63031611},{"atl":[[5.3,17.33],[5.5,0]],"id":69366841},{"atb":[[1.75,0]],"id":48536142},{"atl":[[5.1,3.5]],"id":68900945}],"con":true,"img":false}]}
{"op":"mcm","clk":"11540672202","pt":1719497167759,"mc":[{"id":"1.230180117","rc":[{"atl":[[6.6,1]],"id":63031611}],"con":true,"img":false}]}
{"op":"mcm","clk":"11540672213","pt":1719497167861,"mc":[{"id":"1.230180117","rc":[{"atb":[[3,13.35],[2.96,16.48]],"id":40831161}],"con":true,"img":false}]}
{"op":"mcm","clk":"11540672240","pt":1719497168169,"mc":[{"id":"1.230180117","rc":[{"atb":[[2.98,9.34]],"id":40831161},{"atb":[[2.54,0]],"id":68900945}],"con":true,"img":false}]}
{"op":"mcm","clk":"11540672248","pt":1719497168278,"mc":[{"id":"1.230180117","rc":[{"atb":[[3.05,3]],"id":40831161}],"con":true,"img":false}]}
{"op":"mcm","clk":"11540672256","pt":1719497168381,"mc":[{"id":"1.230180117","rc":[{"atb":[[3.1,9.35],[3,0]],"id":40831161}],"con":true,"img":false}]}
{"op":"mcm","clk":"11540672275","pt":1719497168582,"mc":[{"id":"1.230180117","rc":[{"atl":[[8.6,1],[8.4,0]],"id":40831161},{"atl":[[3.65,0.84]],"id":64253836},{"atl":[[4.8,1],[5.1,2.5]],"id":68900945}],"con":true,"img":false}]}
{"op":"mcm","clk":"11540672308","pt":1719497168954,"mc":[{"id":"1.230180117","rc":[{"atb":[[2.4,3.56]],"id":68900945}],"con":true,"img":false}]}
{"op":"mcm","clk":"11540672325","pt":1719497169055,"mc":[{"id":"1.230180117","rc":[{"atl":[[6.6,0]],"id":63031611}],"con":true,"img":false}]}
{"op":"mcm","clk":"11540672374","pt":1719497169474,"mc":[{"id":"1.230180117","rc":[{"atb":[[3.1,19.33]],"id":40831161},{"atl":[[5.9,16.39]],"id":40831161}],"con":true,"img":false}]}
{"op":"mcm","clk":"11540672397","pt":1719497169680,"mc":[{"id":"1.230180117","rc":[{"atl":[[5.2,0.84]],"id":69366841}],"con":true,"img":false}]}
{"op":"mcm","clk":"11540672418","pt":1719497169886,"mc":[{"id":"1.230180117","rc":[{"atl":[[3.65,10.45]],"id":64253836},{"atb":[[2.56,0],[2.4,0]],"id":68900945}],"con":true,"img":false}]}
{"op":"mcm","clk":"11540672431","pt":1719497169964,"mc":[{"id":"1.230180117","rc":[{"atl":[[3.6,10.46],[3.7,5.15],[3.8,0]],"id":64253836},{"atb":[[2.54,2]],"id":68900945}],"con":true,"img":false}]}
{"op":"mcm","clk":"11540672446","pt":1719497170044,"mc":[{"id":"1.230180117","rc":[{"atl":[[3.6,0],[3.7,26.07]],"id":64253836}],"con":true,"img":false}]}
{"op":"mcm","clk":"11540672494","pt":1719497170467,"mc":[{"id":"1.230180117","rc":[{"atb":[[1.02,1.7]],"id":64253836},{"atl":[[1000,1.88]],"id":64253836},{"atb":[[1.01,1.7]],"id":48536142},{"atl":[[1000,1.88]],"id":48536142},{"atl":[[1000,1.88]],"id":68900945}],"con":true,"img":false}]}
{"op":"mcm","clk":"11540672505","pt":1719497170564,"mc":[{"id":"1.230180117","rc":[{"atb":[[1.02,1.7]],"id":68900945}],"con":true,"img":false}]}
{"op":"mcm","clk":"11540672515","pt":1719497170672,"mc":[{"id":"1.230180117","rc":[{"atb":[[1.02,0.19]],"id":64253836},{"atl":[[1000,0.27]],"id":64253836},{"atb":[[1.01,0.33]],"id":48536142},{"atl":[[1000,0.3]],"id":48536142},{"atl":[[1000,0.26]],"id":68900945}],"con":true,"img":false}]}
{"op":"mcm","clk":"11540672531","pt":1719497170875,"mc":[{"id":"1.230180117","rc":[{"atb":[[1.02,0]],"id":64253836},{"atl":[[1000,0.17]],"id":64253836},{"atb":[[1.01,0]],"id":48536142},{"atl":[[1000,0.17]],"id":48536142},{"atb":[[1.02,0.16]],"id":68900945},{"atl":[[1000,0.17]],"id":68900945}],"con":true,"img":false}]}
{"op":"mcm","clk":"11540672540","pt":1719497170977,"mc":[{"id":"1.230180117","rc":[{"atb":[[2.34,0.19]],"id":64253836},{"atl":[[3.6,0.09]],"id":64253836},{"atb":[[1.78,0.33]],"id":48536142},{"atl":[[3,0.13]],"id":48536142},{"atl":[[4,0.08]],"id":68900945}],"con":true,"img":false}]}
{"op":"mcm","clk":"11540672552","pt":1719497171082,"mc":[{"id":"1.230180117","rc":[{"atb":[[1.02,0]],"id":68900945}],"con":true,"img":false}]}
{"op":"mcm","clk":"11540672564","pt":1719497171185,"mc":[{"id":"1.230180117","rc":[{"atb":[[2.82,1.97]],"id":63031611},{"atl":[[4.7,17.42]],"id":63031611},{"atb":[[3.25,3.04]],"id":69366841},{"atb":[[3.15,2.97]],"id":40831161},{"atb":[[2.32,13.6]],"id":64253836},{"atl":[[3.6,9.41]],"id":64253836},{"atb":[[2.56,0.16]],"id":68900945},{"atl":[[4,11.4]],"id":68900945}],"con":true,"img":false}]}
{"op":"mcm","clk":"11540672579","pt":1719497171288,"mc":[{"id":"1.230180117","rc":[{"atb":[[2.82,19.39]],"id":63031611},{"atb":[[3.25,20.27]],"id":69366841},{"atl":[[5.2,18.08]],"id":69366841},{"atl":[[3,3.99]],"id":48536142},{"atl":[[3.95,13.73],[4.1,0.84]],"id":68900945}],"con":true,"img":false}]}
{"op":"mcm","clk":"11540672587","pt":1719497171341,"mc":[{"id":"1.230180117","rc":[{"atl":[[4.9,0]],"id":63031611},{"atl":[[3.65,0.84]],"id":64253836},{"atl":[[2.98,28.43],[3.05,0.84]],"id":48536142},{"atl":[[4.2,4.76]],"id":68900945}],"con":true,"img":false}]}
{"op":"mcm","clk":"11540672601","pt":1719497171443,"mc":[{"id":"1.230180117","rc":[{"atb":[[2.8,21.97]],"id":63031611},{"atl":[[4.1,25.98]],"id":68900945}],"con":true,"img":false}]}
{"op":"mcm","clk":"11540672613","pt":1719497171552,"mc":[{"id":"1.230180117","rc":[{"atl":[[4.6,0.84]],"id":63031611},{"atb":[[3.2,3]],"id":69366841},{"atl":[[5.4,0]],"id":69366841},{"atb":[[2.98,0]],"id":40831161},{"atb":[[2.24,0]],"id":64253836},{"atl":[[3.7,22.64]],"id":64253836},{"atl":[[3.1,0],[2.98,0],[2.96,0.84],[3.05,33.26]],"id":48536142},{"atl":[[3.95,0],[3.9,0.84],[4.2,0],[4.7,0]],"id":68900945}],"con":true,"img":false}]}
{"op":"mcm","clk":"11540672619","pt":1719497171654,"mc":[{"id":"1.230180117","rc":[{"atb":[[3.1,27.74],[3.15,12.72]],"id":40831161},{"atb":[[2.32,20.33]],"id":64253836},{"atl":[[3.65,4.09]],"id":64253836},{"atl":[[3.05,46.97]],"id":48536142},{"atl":[[4.1,29.63]],"id":68900945}],"con":true,"img":false}]}
{"op":"mcm","clk":"11540672628","pt":1719497171755,"mc":[{"id":"1.230180117","rc":[{"atb":[[2.96,0]],"id":40831161},{"atl":[[4.5,1.84]],"id":68900945}],"con":true,"img":false}]}
{"op":"mcm","clk":"11540672646","pt":1719497171964,"mc":[{"id":"1.230180117","rc":[{"atb":[[2.8,19.23]],"id":63031611},{"atl":[[4.8,4.46]],"id":63031611},{"atb":[[3.1,17.76]],"id":40831161},{"atb":[[2.54,12.06]],"id":68900945}],"con":true,"img":false}]}
{"op":"mcm","clk":"11540672661","pt":1719497172067,"mc":[{"id":"1.230180117","rc":[{"atl":[[2.96,0]],"id":48536142},{"atb":[[2.52,4.36]],"id":68900945},{"atl":[[3.9,0]],"id":68900945}],"con":true,"img":false}]}
{"op":"mcm","clk":"11540672671","pt":1719497172175,"mc":[{"id":"1.230180117","rc":[{"atb":[[2.8,7.68]],"id":63031611}],"con":true,"img":false}]}
{"op":"mcm","clk":"11540672680","pt":1719497172278,"mc":[{"id":"1.230180117","rc":[{"atb":[[2.82,30.94]],"id":63031611},{"atb":[[2.94,8.53]],"id":40831161},{"atl":[[4.5,0]],"id":68900945}],"con":true,"img":false}]}
{"op":"mcm","clk":"11540672695","pt":1719497172482,"mc":[{"id":"1.230180117","rc":[{"atb":[[2.94,0]],"id":40831161}],"con":true,"img":false}]}
{"op":"mcm","clk":"11540672702","pt":1719497172585,"mc":[{"id":"1.230180117","rc":[{"atl":[[4.4,4.93]],"id":68900945}],"con":true,"img":false}]}
{"op":"mcm","clk":"11540672720","pt":1719497172792,"mc":[{"id":"1.230180117","rc":[{"atb":[[2.84,5],[2.62,2.11],[2.76,10],[2.92,2.5],[2.78,0],[2.7,0]],"id":63031611},{"atl":[[5,0],[4.7,23.32],[5.4,21.88]],"id":63031611},{"atb":[[3.15,22.36]],"id":40831161}],"con":true,"img":false}]}
{"op":"mcm","clk":"11540672730","pt":1719497172845,"mc":[{"id":"1.230180117","rc":[{"atb":[[2.8,4.68],[2.94,1.77]],"id":63031611},{"atb":[[3.2,0]],"id":69366841},{"atb":[[3.05,0]],"id":40831161}],"con":true,"img":false}]}
{"op":"mcm","clk":"11540672736","pt":1719497172947,"mc":[{"id":"1.230180117","rc":[{"atb":[[2.84,8]],"id":63031611},{"atb":[[3.3,2.72]],"id":69366841},{"atb":[[3.2,2.35]],"id":40831161}],"con":true,"img":false}]}
{"op":"mcm","clk":"11540672743","pt":1719497173051,"mc":[{"id":"1.230180117","rc":[{"atb":[[3.35,3.11]],"id":69366841},{"atb":[[3.25,2.97]],"id":40831161}],"con":true,"img":false}]}
{"op":"mcm","clk":"11540672771","pt":1719497173361,"mc":[{"id":"1.230180117","rc":[{"atb":[[2.82,19.39]],"id":63031611},{"atb":[[3.15,10.72]],"id":69366841},{"atb":[[3.15,12.72]],"id":40831161},{"atl":[[4.4,0]],"id":68900945}],"con":true,"img":false}]}
{"op":"mcm","clk":"11540672779","pt":1719497173467,"mc":[{"id":"1.230180117","rc":[{"atb":[[3.1,8.41],[3.15,30.48]],"id":40831161}],"con":true,"img":false}]}
{"op":"mcm","clk":"11540672787","pt":1719497173566,"mc":[{"id":"1.230180117","rc":[{"atl":[[4.3,2.98]],"id":68900945}],"con":true,"img":false}]}
{"op":"mcm","clk":"11540672806","pt":1719497173772,"mc":[{"id":"1.230180117","rc":[{"atb":[[3.15,0]],"id":69366841}],"con":true,"img":false}]}
{"op":"mcm","clk":"11540672815","pt":1719497173874,"mc":[{"id":"1.230180117","rc":[{"atb":[[3.35,13.83]],"id":69366841},{"atb":[[2.3,0],[2.38,2.11]],"id":64253836},{"atb":[[2.5,3.12]],"id":68900945}],"con":true,"img":false}]}
{"op":"mcm","clk":"11540672820","pt":1719497173978,"mc":[{"id":"1.230180117","rc":[{"atb":[[2.5,0]],"id":68900945}],"con":true,"img":false}]}
{"op":"mcm","clk":"11540672847","pt":1719497174294,"mc":[{"id":"1.230180117","rc":[{"atb":[[2.94,13.76]],"id":63031611},{"atb":[[3.25,13.27]],"id":40831161}],"con":true,"img":false}]}
{"op":"mcm","clk":"11540672937","pt":1719497175180,"mc":[{"id":"1.230180117","rc":[{"atl":[[3.6,18.83],[3.7,1.72]],"id":64253836}],"con":true,"img":false}]}
{"op":"mcm","clk":"11540673004","pt":1719497175788,"mc":[{"id":"1.230180117","rc":[{"atb":[[2.32,18.33]],"id":64253836}],"con":true,"img":false}]}
{"op":"mcm","clk":"11540673013","pt":1719497175892,"mc":[{"id":"1.230180117","rc":[{"atb":[[2.4,2]],"id":64253836}],"con":true,"img":false}]}
{"op":"mcm","clk":"11540673035","pt":1719497176048,"mc":[{"id":"1.230180117","rc":[{"atl":[[3.55,0.84]],"id":64253836}],"con":true,"img":false}]}
{"op":"mcm","clk":"11540673056","pt":1719497176253,"mc":[{"id":"1.230180117","rc":[{"atb":[[2.8,0]],"id":63031611},{"atl":[[4.8,0.84]],"id":63031611},{"atl":[[5.3,11.86]],"id":69366841},{"atb":[[3.1,0]],"id":40831161},{"atl":[[3.65,0.84]],"id":64253836},{"atl":[[3.05,32.42]],"id":48536142},{"atb":[[2.52,0]],"id":68900945},{"atl":[[4.1,25.14]],"id":68900945}],"con":true,"img":false}]}
{"op":"mcm","clk":"11540673064","pt":1719497176359,"mc":[{"id":"1.230180117","rc":[{"atl":[[5.3,0],[5.5,22.22]],"id":69366841},{"atl":[[3.6,9.41],[3.65,20.53]],"id":64253836},{"atl":[[3.3,38.9],[3.05,0]],"id":48536142},{"atl":[[4.2,31.25]],"id":68900945}],"con":true,"img":false}]}
{"op":"mcm","clk":"11540673073","pt":1719497176460,"mc":[{"id":"1.230180117","rc":[{"atb":[[2.94,17.3]],"id":63031611},{"atl":[[4.7,26.73]],"id":63031611},{"atl":[[5.2,23.41]],"id":69366841},{"atb":[[3.25,20.65]],"id":40831161},{"atl":[[3.6,12.48]],"id":64253836},{"atl":[[3,18.33]],"id":48536142},{"atb":[[2.54,16.2]],"id":68900945},{"atl":[[4,15.62],[4.1,0]],"id":68900945}],"con":true,"img":false}]}
{"op":"mcm","clk":"11540673082","pt":1719497176568,"mc":[{"id":"1.230180117","rc":[{"atl":[[5.5,0],[5.2,45.63]],"id":69366841},{"atl":[[3.55,13.32],[3.65,0.84]],"id":64253836}],"con":true,"img":false}]}
{"op":"mcm","clk":"11540673134","pt":1719497177180,"mc":[{"id":"1.230180117","rc":[{"atl":[[3.65,0]],"id":64253836}],"con":true,"img":false}]}
{"op":"mcm","clk":"11540673195","pt":1719497177855,"mc":[{"id":"1.230180117","rc":[{"atb":[[2.5,0],[2.32,20],[2.84,5]],"id":63031611},{"atl":[[5.8,20.83],[5.4,0]],"id":63031611},{"spn":3.77,"spf":"NaN","id":63031611},{"atb":[[3.3,0],[2.42,10]],"id":69366841},{"spn":4.27,"spf":"NaN","id":69366841},{"atb":[[3.2,0]],"id":40831161},{"spn":3.25,"spf":1.0,"id":40831161},{"spn":2.97,"spf":"NaN","id":64253836},{"spn":2.39,"spf":"NaN","id":48536142},{"atb":[[2.54,6.14]],"id":68900945},{"spn":3.28,"spf":"NaN","id":68900945}],"con":true,"img":false}]}
{"op":"mcm","clk":"11540673203","pt":1719497177956,"mc":[{"id":"1.230180117","rc":[{"atb":[[2.96,4]],"id":63031611},{"atb":[[2.32,0],[3.4,3.39]],"id":69366841},{"atb":[[3.3,2.37]],"id":40831161}],"con":true,"img":false}]}
{"op":"mcm","clk":"11540673214","pt":1719497178061,"mc":[{"id":"1.230180117","rc":[{"atb":[[2.98,1.71]],"id":63031611},{"atb":[[3.45,3.01]],"id":69366841},{"atb":[[3.35,2.99]],"id":40831161}],"con":true,"img":false}]}
{"op":"mcm","clk":"11540673223","pt":1719497178166,"mc":[{"id":"1.230180117","rc":[{"atb":[[2.94,16.16]],"id":63031611},{"atb":[[3.35,13.08]],"id":69366841},{"atb":[[3.25,19.82]],"id":40831161}],"con":true,"img":false}]}
{"op":"mcm","clk":"11540673235","pt":1719497178369,"mc":[{"id":"1.230180117","rc":[{"atb":[[2.94,5.31]],"id":63031611},{"atb":[[3.35,3.1]],"id":69366841},{"atb":[[3.25,10.35]],"id":40831161},{"atb":[[1.76,8.7]],"id":48536142}],"con":true,"img":false}]}
{"op":"mcm","clk":"11540673244","pt":1719497178478,"mc":[{"id":"1.230180117","rc":[{"atb":[[2.96,14.85]],"id":63031611},{"atb":[[3.4,13.36]],"id":69366841},{"atb":[[3.3,11.84]],"id":40831161}],"con":true,"img":false}]}
{"op":"mcm","clk":"11540673259","pt":1719497178682,"mc":[{"id":"1.230180117","rc":[{"atl":[[2.98,0.84]],"id":48536142},{"atl":[[3.95,0.84]],"id":68900945}],"con":true,"img":false}]}
{"op":"mcm","clk":"11540673269","pt":1719497178785,"mc":[{"id":"1.230180117","rc":[{"atl":[[3.5,3.09]],"id":64253836}],"con":true,"img":false}]}
{"op":"mcm","clk":"11540673278","pt":1719497178888,"mc":[{"id":"1.230180117","rc":[{"atl":[[3.45,12.48]],"id":64253836},{"atl":[[4.3,0]],"id":68900945}],"con":true,"img":false}]}
{"op":"mcm","clk":"11540673286","pt":1719497178992,"mc":[{"id":"1.230180117","rc":[{"atl":[[3.6,3.16],[3.55,0.84]],"id":64253836}],"con":true,"img":false}]}
{"op":"mcm","clk":"11540673292","pt":1719497179093,"mc":[{"id":"1.230180117","rc":[{"atb":[[2.96,4]],"id":63031611},{"atb":[[3.4,12.9]],"id":69366841},{"atb":[[3.3,2.36]],"id":40831161}],"con":true,"img":false}]}
{"op":"mcm","clk":"11540673315","pt":1719497179357,"mc":[{"id":"1.230180117","rc":[{"atb":[[3.4,3.39]],"id":69366841}],"con":true,"img":false}]}
{"op":"mcm","clk":"11540673324","pt":1719497179464,"mc":[{"id":"1.230180117","rc":[{"atb":[[3.45,12.52]],"id":69366841},{"atl":[[4.2,34.72]],"id":68900945}],"con":true,"img":false}]}
{"op":"mcm","clk":"11540673339","pt":1719497179664,"mc":[{"id":"1.230180117","rc":[{"atl":[[3.55,0]],"id":64253836}],"con":true,"img":false}]}
{"op":"mcm","clk":"11540673347","pt":1719497179771,"mc":[{"id":"1.230180117","rc":[{"atb":[[2.98,13.03]],"id":63031611},{"atb":[[3.35,13.41]],"id":40831161}],"con":true,"img":false}]}
{"op":"mcm","clk":"11540673383","pt":1719497180082,"mc":[{"id":"1.230180117","rc":[{"atl":[[4.6,7.58]],"id":63031611},{"atb":[[3.2,3.37]],"id":40831161},{"atl":[[3.45,16.39]],"id":64253836},{"atl":[[3.95,7.32],[4.2,31.25]],"id":68900945}],"con":true,"img":false}]}
{"op":"mcm","clk":"11540673393","pt":1719497180183,"mc":[{"id":"1.230180117","rc":[{"atb":[[3,6.99]],"id":63031611},{"atl":[[4.7,9.31]],"id":63031611},{"atl":[[3.5,0]],"id":64253836},{"atl":[[2.98,8.86]],"id":48536142},{"atl":[[4,4.3]],"id":68900945}],"con":true,"img":false}]}
{"op":"mcm","clk":"11540673404","pt":1719497180290,"mc":[{"id":"1.230180117","rc":[{"atb":[[2.82,1.96]],"id":63031611},{"atl":[[3,14.47]],"id":48536142}],"con":true,"img":false}]}
{"op":"mcm","clk":"11540673415","pt":1719497180388,"mc":[{"id":"1.230180117","rc":[{"atb":[[3.05,4.07]],"id":63031611}],"con":true,"img":false}]}
{"op":"mcm","clk":"11540673424","pt":1719497180493,"mc":[{"id":"1.230180117","rc":[{"atl":[[4.2,36.22]],"id":68900945}],"con":true,"img":false}]}
{"op":"mcm","clk":"11540673432","pt":1719497180596,"mc":[{"id":"1.230180117","rc":[{"atl":[[4.8,0]],"id":63031611},{"atb":[[3.4,15.26]],"id":40831161}],"con":true,"img":false}]}
{"op":"mcm","clk":"11540673443","pt":1719497180654,"mc":[{"id":"1.230180117","rc":[{"atb":[[2.98,1.71]],"id":63031611},{"atb":[[3.4,18.26],[3.15,20.73]],"id":40831161}],"con":true,"img":false}]}
{"op":"mcm","clk":"11540673449","pt":1719497180755,"mc":[{"id":"1.230180117","rc":[{"atb":[[3.2,0]],"id":40831161}],"con":true,"img":false}]}
{"op":"mcm","clk":"11540673486","pt":1719497181171,"mc":[{"id":"1.230180117","rc":[{"atb":[[2.94,1.77]],"id":63031611},{"atl":[[4.7,5.89]],"id":63031611},{"atb":[[3.25,2.96]],"id":40831161},{"atb":[[1.02,1.7]],"id":64253836},{"atl":[[3.6,0.09],[1000,8.69]],"id":64253836},{"atl":[[3,0.13]],"id":48536142},{"atl":[[4,0.08]],"id":68900945}],"con":true,"img":false}]}
{"op":"mcm","clk":"11540673494","pt":1719497181278,"mc":[{"id":"1.230180117","rc":[{"atb":[[1.03,1.7],[1.02,6.81]],"id":64253836},{"atl":[[4.2,31.25]],"id":68900945}],"con":true,"img":false}]}
{"op":"mcm","clk":"11540673503","pt":1719497181374,"mc":[{"id":"1.230180117","rc":[{"atb":[[3.05,6.83]],"id":63031611},{"atl":[[4.6,10.78]],"id":63031611},{"atb":[[3.35,20.17]],"id":40831161},{"atb":[[1.02,5.25]],"id":64253836},{"atl":[[3.45,18.83],[1000,0.55]],"id":64253836},{"atl":[[2.98,23.12]],"id":48536142},{"atl":[[3.95,11.39]],"id":68900945}],"con":true,"img":false}]}
{"op":"mcm","clk":"11540673514","pt":1719497181477,"mc":[{"id":"1.230180117","rc":[{"atb":[[1.03,0.1],[1.02,0.52]],"id":64253836}],"con":true,"img":false}]}
{"op":"mcm","clk":"11540673522","pt":1719497181583,"mc":[{"id":"1.230180117","rc":[{"atb":[[3.35,18.5]],"id":40831161},{"atb":[[1.02,0.38]],"id":64253836},{"atl":[[1000,0.17]],"id":64253836},{"atl":[[3.3,2.49],[2.96,23.13]],"id":48536142},{"atl":[[3.9,11.39],[4.2,0]],"id":68900945}],"con":true,"img":false}]}
{"op":"mcm","clk":"11540673528","pt":1719497181684,"mc":[{"id":"1.230180117","rc":[{"atb":[[3.05,19.12]],"id":63031611},{"atb":[[1.03,0],[2.42,0.14],[1.02,0]],"id":64253836},{"atl":[[3.4,0.37]],"id":64253836},{"atl":[[4.2,6.63]],"id":68900945}],"con":true,"img":false}]}
{"op":"mcm","clk":"11540673535","pt":1719497181791,"mc":[{"id":"1.230180117","rc":[{"atb":[[3.35,9.75]],"id":40831161},{"atb":[[2.42,0.63]],"id":64253836}],"con":true,"img":false}]}
{"op":"mcm","clk":"11540673543","pt":1719497181889,"mc":[{"id":"1.230180117","rc":[{"atb":[[3.4,27.01]],"id":40831161}],"con":true,"img":false}]}
{"op":"mcm","clk":"11540673570","pt":1719497182099,"mc":[{"id":"1.230180117","rc":[{"atb":[[2.94,4.89]],"id":63031611}],"con":true,"img":false}]}
{"op":"mcm","clk":"11540673585","pt":1719497182197,"mc":[{"id":"1.230180117","rc":[{"atb":[[2.94,1.77]],"id":63031611}],"con":true,"img":false}]}
{"op":"mcm","clk":"11540673604","pt":1719497182351,"mc":[{"id":"1.230180117","rc":[{"atl":[[3.4,10.34]],"id":64253836}],"con":true,"img":false}]}
{"op":"mcm","clk":"11540673616","pt":1719497182456,"mc":[{"id":"1.230180117","rc":[{"atb":[[2.96,0]],"id":63031611},{"atb":[[3.4,0]],"id":69366841},{"atb":[[3.3,0]],"id":40831161},{"atb":[[1.76,5.55]],"id":48536142}],"con":true,"img":false}]}
{"op":"mcm","clk":"11540673638","pt":1719497182665,"mc":[{"id":"1.230180117","rc":[{"atb":[[3.1,4]],"id":63031611},{"atb":[[3.5,3.1]],"id":69366841},{"atb":[[3.45,3.03]],"id":40831161},{"atb":[[1.77,5.9]],"id":48536142}],"con":true,"img":false}]}
{"op":"mcm","clk":"11540673650","pt":1719497182771,"mc":[{"id":"1.230180117","rc":[{"atb":[[3.15,3.76]],"id":63031611},{"atb":[[3.55,2.81]],"id":69366841}],"con":true,"img":false}]}
{"op":"mcm","clk":"11540673670","pt":1719497182974,"mc":[{"id":"1.230180117","rc":[{"atl":[[3.7,0]],"id":64253836}],"con":true,"img":false}]}
{"op":"mcm","clk":"11540673678","pt":1719497183077,"mc":[{"id":"1.230180117","rc":[{"atb":[[3.05,18.42]],"id":63031611},{"atb":[[3.45,3.01]],"id":69366841},{"atb":[[3.4,18.26]],"id":40831161},{"atl":[[3.35,0.84]],"id":64253836}],"con":true,"img":false}]}
{"op":"mcm","clk":"11540673697","pt":1719497183282,"mc":[{"id":"1.230180117","rc":[{"atb":[[3.05,6.83]],"id":63031611},{"atl":[[3.65,7.1]],"id":64253836}],"con":true,"img":false}]}
{"op":"mcm","clk":"11540673708","pt":1719497183386,"mc":[{"id":"1.230180117","rc":[{"atb":[[3.15,15.35]],"id":63031611}],"con":true,"img":false}]}
{"op":"mcm","clk":"11540673753","pt":1719497183956,"mc":[{"id":"1.230180117","rc":[{"atl":[[3.45,6.35],[3.35,11.18]],"id":64253836}],"con":true,"img":false}]}
{"op":"mcm","clk":"11540673759","pt":1719497184055,"mc":[{"id":"1.230180117","rc":[{"atb":[[3.55,11.37]],"id":69366841},{"atb":[[3.45,11.45]],"id":40831161}],"con":true,"img":false}]}
{"op":"mcm","clk":"11540673769","pt":1719497184160,"mc":[{"id":"1.230180117","rc":[{"atb":[[2.32,15.03]],"id":64253836}],"con":true,"img":false}]}
{"op":"mcm","clk":"11540673780","pt":1719497184263,"mc":[{"id":"1.230180117","rc":[{"atl":[[3.65,0]],"id":64253836}],"con":true,"img":false}]}
{"op":"mcm","clk":"11540673801","pt":1719497184572,"mc":[{"id":"1.230180117","rc":[{"atb":[[2.4,3.58]],"id":68900945}],"con":true,"img":false}]}
{"op":"mcm","clk":"11540673811","pt":1719497184678,"mc":[{"id":"1.230180117","rc":[{"atl":[[3.6,2.88],[3.4,0.37]],"id":64253836}],"con":true,"img":false}]}
{"op":"mcm","clk":"11540673822","pt":1719497184779,"mc":[{"id":"1.230180117","rc":[{"atl":[[3.35,0.84],[3.4,22.75]],"id":64253836}],"con":true,"img":false}]}
{"op":"mcm","clk":"11540673888","pt":1719497185503,"mc":[{"id":"1.230180117","rc":[{"atl":[[3.35,10.42]],"id":64253836}],"con":true,"img":false}]}
{"op":"mcm","clk":"11540673904","pt":1719497185660,"mc":[{"id":"1.230180117","rc":[{"atl":[[2.94,0.84]],"id":48536142},{"atl":[[3.85,0.84]],"id":68900945}],"con":true,"img":false}]}
{"op":"mcm","clk":"11540673925","pt":1719497185867,"mc":[{"id":"1.230180117","rc":[{"atl":[[4.2,0]],"id":68900945}],"con":true,"img":false}]}
{"op":"mcm","clk":"11540673946","pt":1719497186075,"mc":[{"id":"1.230180117","rc":[{"atb":[[3.05,4.07]],"id":63031611},{"atb":[[3.35,2.99]],"id":40831161},{"atl":[[3.45,3.91]],"id":64253836},{"atl":[[2.98,8.86]],"id":48536142},{"atl":[[3.95,7.32]],"id":68900945}],"con":true,"img":false}]}
{"op":"mcm","clk":"11540673954","pt":1719497186181,"mc":[{"id":"1.230180117","rc":[{"atb":[[3.15,17.46]],"id":63031611},{"atb":[[3.45,17.65]],"id":40831161},{"atl":[[3.4,24.97]],"id":64253836},{"atl":[[2.96,37.3]],"id":48536142},{"atl":[[3.9,3.9]],"id":68900945}],"con":true,"img":false}]}
{"op":"mcm","clk":"11540673961","pt":1719497186278,"mc":[{"id":"1.230180117","rc":[{"atl":[[2.98,32.84],[2.96,14.17]],"id":48536142},{"atl":[[3.95,19.56]],"id":68900945}],"con":true,"img":false}]}
{"op":"mcm","clk":"11540673978","pt":1719497186485,"mc":[{"id":"1.230180117","rc":[{"atl":[[4.1,3.91]],"id":68900945}],"con":true,"img":false}]}
{"op":"mcm","clk":"11540674043","pt":1719497187268,"mc":[{"id":"1.230180117","rc":[{"atb":[[3.1,0]],"id":63031611},{"atb":[[3.5,0]],"id":69366841}],"con":true,"img":false}]}
{"op":"mcm","clk":"11540674056","pt":1719497187467,"mc":[{"id":"1.230180117","rc":[{"atb":[[3.2,2.79]],"id":63031611},{"atb":[[3.6,2.9]],"id":69366841},{"atl":[[3.3,4.52]],"id":64253836}],"con":true,"img":false}]}
{"op":"mcm","clk":"11540674065","pt":1719497187567,"mc":[{"id":"1.230180117","rc":[{"atb":[[3.25,3.48]],"id":63031611},{"atl":[[3.45,0]],"id":64253836}],"con":true,"img":false}]}
{"op":"mcm","clk":"11540674081","pt":1719497187778,"mc":[{"id":"1.230180117","rc":[{"atb":[[3.6,5.61]],"id":69366841}],"con":true,"img":false}]}
{"op":"mcm","clk":"11540674099","pt":1719497187985,"mc":[{"id":"1.230180117","rc":[{"atb":[[3.15,16.54]],"id":63031611},{"atb":[[3.55,2.81]],"id":69366841},{"atb":[[3.2,20.64],[3.15,2.96]],"id":40831161},{"atb":[[2.32,6.73],[2.2,2.5]],"id":64253836},{"atl":[[3.35,10.02]],"id":64253836}],"con":true,"img":false}]}
{"op":"mcm","clk":"11540674107","pt":1719497188090,"mc":[{"id":"1.230180117","rc":[{"atb":[[2.1,4.24]],"id":64253836}],"con":true,"img":false}]}
{"op":"mcm","clk":"11540674114","pt":1719497188192,"mc":[{"id":"1.230180117","rc":[{"atb":[[3.15,5.87]],"id":63031611},{"atl":[[3.35,0.84]],"id":64253836}],"con":true,"img":false}]}
{"op":"mcm","clk":"11540674125","pt":1719497188301,"mc":[{"id":"1.230180117","rc":[{"atb":[[3.25,14.15]],"id":63031611},{"atl":[[3.3,13.7]],"id":64253836}],"con":true,"img":false}]}
{"op":"mcm","clk":"11540674182","pt":1719497188765,"mc":[{"id":"1.230180117","rc":[{"atb":[[3.45,20.66]],"id":40831161},{"atl":[[3.85,6.46]],"id":68900945}],"con":true,"img":false}]}
{"op":"mcm","clk":"11540674189","pt":1719497188862,"mc":[{"id":"1.230180117","rc":[{"atb":[[3.3,12.52]],"id":63031611},{"atb":[[3.6,13.88]],"id":69366841},{"atl":[[2.94,9.43]],"id":48536142}],"con":true,"img":false}]}
{"op":"mcm","clk":"11540674195","pt":1719497188973,"mc":[{"id":"1.230180117","rc":[{"atb":[[3.35,3.23],[3,0]],"id":63031611},{"atl":[[2.98,24.82]],"id":48536142},{"atl":[[3.95,13.08]],"id":68900945}],"con":true,"img":false}]}
{"op":"mcm","clk":"11540674211","pt":1719497189182,"mc":[{"id":"1.230180117","rc":[{"atl":[[2.98,23.98]],"id":48536142},{"atl":[[3.95,12.24]],"id":68900945}],"con":true,"img":false}]}
{"op":"mcm","clk":"11540674221","pt":1719497189277,"mc":[{"id":"1.230180117","rc":[{"atb":[[3.5,19.8]],"id":40831161}],"con":true,"img":false}]}
{"op":"mcm","clk":"11540674231","pt":1719497189386,"mc":[{"id":"1.230180117","rc":[{"atb":[[3.4,3]],"id":40831161}],"con":true,"img":false}]}
{"op":"mcm","clk":"11540674252","pt":1719497189586,"mc":[{"id":"1.230180117","rc":[{"atb":[[3.25,3.48]],"id":63031611},{"atb":[[3.45,12.24]],"id":40831161}],"con":true,"img":false}]}
{"op":"mcm","clk":"11540674279","pt":1719497189907,"mc":[{"id":"1.230180117","rc":[{"atl":[[3.4,2.59],[3.25,13.7]],"id":64253836}],"con":true,"img":false}]}
{"op":"mcm","clk":"11540674297","pt":1719497190106,"mc":[{"id":"1.230180117","rc":[{"atl":[[3.25,17.63]],"id":64253836}],"con":true,"img":false}]}
{"op":"mcm","clk":"11540674307","pt":1719497190206,"mc":[{"id":"1.230180117","rc":[{"atl":[[3.3,9.18]],"id":64253836}],"con":true,"img":false}]}
{"op":"mcm","clk":"11540674323","pt":1719497190362,"mc":[{"id":"1.230180117","rc":[{"atl":[[3.3,0]],"id":64253836}],"con":true,"img":false}]}
{"op":"mcm","clk":"11540674335","pt":1719497190468,"mc":[{"id":"1.230180117","rc":[{"atb":[[3.35,12.06]],"id":63031611},{"atb":[[3.5,28.99]],"id":40831161},{"atl":[[3.35,36.12],[3.25,3.93]],"id":64253836}],"con":true,"img":false}]}
{"op":"mcm","clk":"11540674342","pt":1719497190570,"mc":[{"id":"1.230180117","rc":[{"atl":[[3.35,35.28]],"id":64253836}],"con":true,"img":false}]}
{"op":"mcm","clk":"11540674395","pt":1719497191199,"mc":[{"id":"1.230180117","rc":[{"atb":[[3.15,3.76]],"id":63031611},{"atb":[[3.45,6.04]],"id":40831161},{"atl":[[3.4,0.37]],"id":64253836},{"atl":[[2.96,0]],"id":48536142},{"atl":[[3.9,0]],"id":68900945}],"con":true,"img":false}]}
{"op":"mcm","clk":"11540674407","pt":1719497191294,"mc":[{"id":"1.230180117","rc":[{"atl":[[3.95,0]],"id":68900945}],"con":true,"img":false}]}
{"op":"mcm","clk":"11540674418","pt":1719497191403,"mc":[{"id":"1.230180117","rc":[{"atb":[[3.5,34.92]],"id":40831161},{"atl":[[3.25,16.12]],"id":64253836},{"atl":[[3,33.55],[2.98,0],[2.94,23.52]],"id":48536142},{"atl":[[4,18.79],[3.85,10.21]],"id":68900945}],"con":true,"img":false}]}
{"op":"mcm","clk":"11540674432","pt":1719497191609,"mc":[{"id":"1.230180117","rc":[{"atl":[[2.92,23.52],[3,0.13]],"id":48536142},{"atl":[[4,0.08],[3.8,10.22]],"id":68900945}],"con":true,"img":false}]}
{"op":"mcm","clk":"11540674458","pt":1719497191971,"mc":[{"id":"1.230180117","rc":[{"atb":[[3.2,0]],"id":63031611},{"atb":[[3.45,3.01]],"id":40831161}],"con":true,"img":false}]}
{"op":"mcm","clk":"11540674467","pt":1719497192078,"mc":[{"id":"1.230180117","rc":[{"atb":[[2.38,16.54]],"id":68900945},{"atl":[[3.8,19.2]],"id":68900945}],"con":true,"img":false}]}
{"op":"mcm","clk":"11540674472","pt":1719497192181,"mc":[{"id":"1.230180117","rc":[{"atb":[[3.4,3.37]],"id":63031611},{"atb":[[3.55,3.4]],"id":40831161}],"con":true,"img":false}]}
{"op":"mcm","clk":"11540674476","pt":1719497192287,"mc":[{"id":"1.230180117","rc":[{"atb":[[3.45,3.01]],"id":63031611}],"con":true,"img":false}]}
{"op":"mcm","clk":"11540674488","pt":1719497192388,"mc":[{"id":"1.230180117","rc":[{"atl":[[5.1,0],[5.5,0],[4.7,0]],"id":64253836},{"atl":[[3.7,0],[3.25,2.5],[3.3,0],[3.5,0]],"id":48536142}],"con":true,"img":false}]}
{"op":"mcm","clk":"11540674509","pt":1719497192719,"mc":[{"id":"1.230180117","rc":[{"atl":[[2.9,0.84]],"id":48536142},{"atl":[[3.75,0.84]],"id":68900945}],"con":true,"img":false}]}
{"op":"mcm","clk":"11540674516","pt":1719497192802,"mc":[{"id":"1.230180117","rc":[{"atb":[[2.52,3.38]],"id":68900945}],"con":true,"img":false}]}
{"op":"mcm","clk":"11540674527","pt":1719497193006,"mc":[{"id":"1.230180117","rc":[{"atb":[[3.35,3.23]],"id":63031611},{"atb":[[3.5,25.73]],"id":40831161},{"atb":[[2.4,0]],"id":68900945}],"con":true,"img":false}]}
{"op":"mcm","clk":"11540674542","pt":1719497193112,"mc":[{"id":"1.230180117","rc":[{"atb":[[2.52,0]],"id":68900945}],"con":true,"img":false}]}
{"op":"mcm","clk":"11540674592","pt":1719497193681,"mc":[{"id":"1.230180117","rc":[{"atb":[[3.45,13.58]],"id":63031611},{"atb":[[3.55,13.4]],"id":40831161}],"con":true,"img":false}]}
{"op":"mcm","clk":"11540674638","pt":1719497194304,"mc":[{"id":"1.230180117","rc":[{"atb":[[2.62,0]],"id":63031611},{"atb":[[2.54,0]],"id":69366841},{"atb":[[1.88,0]],"id":40831161},{"atb":[[2.38,0]],"id":64253836},{"atb":[[1.7,0]],"id":48536142},{"atb":[[2.18,0]],"id":68900945}],"con":true,"img":false}]}
{"op":"mcm","clk":"11540674690","pt":1719497194870,"mc":[{"id":"1.230180117","rc":[{"atb":[[2.4,0]],"id":64253836}],"con":true,"img":false}]}
{"op":"mcm","clk":"11540674699","pt":1719497194974,"mc":[{"id":"1.230180117","rc":[{"atb":[[2.34,2.19]],"id":64253836}],"con":true,"img":false}]}
{"op":"mcm","clk":"11540674756","pt":1719497195601,"mc":[{"id":"1.230180117","rc":[{"atl":[[3.35,0],[3.25,32.25]],"id":64253836}],"con":true,"img":false}]}
{"op":"mcm","clk":"11540674764","pt":1719497195702,"mc":[{"id":"1.230180117","rc":[{"atl":[[4.8,5],[5.2,10],[4.4,2.5]],"id":64253836}],"con":true,"img":false}]}
{"op":"mcm","clk":"11540674792","pt":1719497196113,"mc":[{"id":"1.230180117","rc":[{"atb":[[3.5,19.8]],"id":40831161},{"atl":[[2.94,9.43]],"id":48536142},{"atl":[[3.85,6.46]],"id":68900945}],"con":true,"img":false}]}
{"op":"mcm","clk":"11540674801","pt":1719497196222,"mc":[{"id":"1.230180117","rc":[{"atb":[[3.55,19.08]],"id":40831161},{"atl":[[2.92,37.51]],"id":48536142},{"atl":[[3.8,22.78]],"id":68900945}],"con":true,"img":false}]}
{"op":"mcm","clk":"11540674808","pt":1719497196272,"mc":[{"id":"1.230180117","rc":[{"atl":[[2.92,13.99],[2.94,33.8]],"id":48536142}],"con":true,"img":false}]}
{"op":"mcm","clk":"11540674863","pt":1719497196795,"mc":[{"id":"1.230180117","rc":[{"atb":[[3.4,0]],"id":63031611}],"con":true,"img":false}]}
{"op":"mcm","clk":"11540674873","pt":1719497196894,"mc":[{"id":"1.230180117","rc":[{"atb":[[3.5,4]],"id":63031611}],"con":true,"img":false}]}
{"op":"mcm","clk":"11540674884","pt":1719497197002,"mc":[{"id":"1.230180117","rc":[{"atb":[[3.55,2.81]],"id":63031611}],"con":true,"img":false}]}
{"op":"mcm","clk":"11540674896","pt":1719497197103,"mc":[{"id":"1.230180117","rc":[{"atb":[[3.45,12.21]],"id":63031611}],"con":true,"img":false}]}
{"op":"mcm","clk":"11540674916","pt":1719497197316,"mc":[{"id":"1.230180117","rc":[{"atb":[[3.45,3.01]],"id":63031611}],"con":true,"img":false}]}
{"op":"mcm","clk":"11540674929","pt":1719497197412,"mc":[{"id":"1.230180117","rc":[{"atb":[[3.5,13.2]],"id":63031611},{"atl":[[2.9,9.43]],"id":48536142},{"atl":[[3.75,10.3]],"id":68900945}],"con":true,"img":false}]}
{"op":"mcm","clk":"11540674939","pt":1719497197519,"mc":[{"id":"1.230180117","rc":[{"atb":[[3.55,10.24]],"id":63031611},{"atl":[[2.94,25.21]],"id":48536142},{"atl":[[3.85,0.84]],"id":68900945}],"con":true,"img":false}]}
{"op":"mcm","clk":"11540674947","pt":1719497197624,"mc":[{"id":"1.230180117","rc":[{"atb":[[3.3,0]],"id":63031611}],"con":true,"img":false}]}
{"op":"mcm","clk":"11540674968","pt":1719497197782,"mc":[{"id":"1.230180117","rc":[{"atb":[[3.6,19.8]],"id":40831161}],"con":true,"img":false}]}
{"op":"mcm","clk":"11540674977","pt":1719497197877,"mc":[{"id":"1.230180117","rc":[{"atb":[[3.5,0]],"id":40831161}],"con":true,"img":false}]}
{"op":"mcm","clk":"11540674986","pt":1719497197989,"mc":[{"id":"1.230180117","rc":[{"atb":[[3.5,4]],"id":63031611},{"atl":[[3.8,21.67]],"id":68900945}],"con":true,"img":false}]}
{"op":"mcm","clk":"11540674996","pt":1719497198084,"mc":[{"id":"1.230180117","rc":[{"atl":[[2.94,24.37]],"id":48536142},{"atl":[[3.85,0]],"id":68900945}],"con":true,"img":false}]}
{"op":"mcm","clk":"11540675007","pt":1719497198189,"mc":[{"id":"1.230180117","rc":[{"atl":[[3.8,13.8]],"id":68900945}],"con":true,"img":false}]}
{"op":"mcm","clk":"11540675015","pt":1719497198316,"mc":[{"id":"1.230180117","rc":[{"atl":[[3.75,18.17]],"id":68900945}],"con":true,"img":false}]}
{"op":"mcm","clk":"11540675024","pt":1719497198422,"mc":[{"id":"1.230180117","rc":[{"atl":[[3.7,13.8],[3.8,3.58]],"id":68900945}],"con":true,"img":false}]}
{"op":"mcm","clk":"11540675062","pt":1719497198782,"mc":[{"id":"1.230180117","rc":[{"atb":[[3.55,18.96]],"id":40831161},{"atl":[[3.75,17.92]],"id":68900945}],"con":true,"img":false}]}
{"op":"mcm","clk":"11540675074","pt":1719497198882,"mc":[{"id":"1.230180117","rc":[{"atb":[[3.55,19.36]],"id":63031611}],"con":true,"img":false}]}
{"op":"mcm","clk":"11540675084","pt":1719497198986,"mc":[{"id":"1.230180117","rc":[{"atb":[[3.55,9.08]],"id":40831161},{"atl":[[3.75,10.3]],"id":68900945}],"con":true,"img":false}]}
{"op":"mcm","clk":"11540675092","pt":1719497199091,"mc":[{"id":"1.230180117","rc":[{"atb":[[3.6,29.68]],"id":40831161},{"atl":[[3.7,7.62]],"id":68900945}],"con":true,"img":false}]}
{"op":"mcm","clk":"11540675103","pt":1719497199190,"mc":[{"id":"1.230180117","rc":[{"atl":[[3.75,37.9]],"id":68900945}],"con":true,"img":false}]}
{"op":"mcm","clk":"11540675121","pt":1719497199396,"mc":[{"id":"1.230180117","rc":[{"atb":[[2.38,20.15]],"id":68900945}],"con":true,"img":false}]}
{"op":"mcm","clk":"11540675164","pt":1719497199821,"mc":[{"id":"1.230180117","rc":[{"atl":[[3.6,0.09]],"id":64253836}],"con":true,"img":false}]}
{"op":"mcm","clk":"11540675189","pt":1719497200074,"mc":[{"id":"1.230180117","rc":[{"atl":[[3.65,0.84]],"id":68900945}],"con":true,"img":false}]}
{"op":"mcm","clk":"11540675219","pt":1719497200439,"mc":[{"id":"1.230180117","rc":[{"atl":[[3.45,5.35]],"id":64253836}],"con":true,"img":false}]}
{"op":"mcm","clk":"11540675244","pt":1719497200593,"mc":[{"id":"1.230180117","rc":[{"spl":[[8,0.09],[7.2,0.11],[75,0.01],[6.4,0.12],[4.6,0.08],[5.8,0.13],[990,0.01],[4.7,0.16]],"id":63031611},{"spl":[[4,0.19],[4.8,0.16],[5.1,0.15],[75,0.15],[4.1,0.19],[3.7,0.1],[3.8,0.2],[3.75,0.21]],"id":68900945},{"atb":[[2.38,16.54]],"id":68900945}],"con":true,"img":false}]}
{"op":"mcm","clk":"11540675272","pt":1719497200905,"mc":[{"id":"1.230180117","rc":[{"atb":[[3.55,3.39]],"id":40831161},{"atl":[[2.92,0]],"id":48536142},{"atl":[[3.8,0]],"id":68900945}],"con":true,"img":false}]}
{"op":"mcm","clk":"11540675293","pt":1719497201111,"mc":[{"id":"1.230180117","rc":[{"atb":[[3.6,35.11],[3.5,4.37]],"id":40831161},{"atl":[[2.9,23.34],[3,33.94],[2.94,0]],"id":48536142},{"atl":[[3.7,10.85]],"id":68900945}],"con":true,"img":false}]}
{"op":"mcm","clk":"11540675315","pt":1719497201422,"mc":[{"id":"1.230180117","rc":[{"atl":[[2.88,23.35],[3,0.13]],"id":48536142}],"con":true,"img":false}]}
{"op":"mcm","clk":"11540675322","pt":1719497201523,"mc":[{"id":"1.230180117","rc":[{"atb":[[3.5,0]],"id":63031611},{"atb":[[3.55,0]],"id":40831161}],"con":true,"img":false}]}
