{"op":"mcm","clk":"11536380672","pt":1719425245616,"mc":[{"id":"1.230178320","marketDefinition":{"bspMarket":true,"turnInPlayEnabled":false,"persistenceEnabled":false,"marketBaseRate":5.0,"eventId":"33376062","eventTypeId":"4339","numberOfWinners":1,"bettingType":"ODDS","marketType":"WIN","marketTime":"2024-06-27T15:47:00.000Z","suspendTime":"2024-06-27T15:47:00.000Z","bspReconciled":false,"complete":true,"inPlay":false,"crossMatching":false,"runnersVoidable":false,"numberOfActiveRunners":6,"betDelay":0,"status":"OPEN","runners":[{"status":"ACTIVE","sortPriority":1,"id":51643934,"name":"1. Ballymac Frisby"},{"status":"ACTIVE","sortPriority":2,"id":62531723,"name":"2. Lynnway Touch"},{"status":"ACTIVE","sortPriority":3,"id":61941199,"name":"3. Kilara Thyestes"},{"status":"ACTIVE","sortPriority":4,"id":69176305,"name":"4. Moss Row Jemma"},{"status":"ACTIVE","sortPriority":5,"id":61419789,"name":"5. Buzzers Delight"},{"status":"ACTIVE","sortPriority":6,"id":43498435,"name":"6. Easy Cookie"}],"regulators":["MR_INT"],"venue":"Kinsley","countryCode":"GB","discountAllowed":false,"timezone":"Europe/London","openDate":"2024-06-27T13:36:00.000Z","version":5994643807,"name":"A2 462m","eventName":"Kinsley 27th Jun"},"rc":[],"con":true,"img":false}]}
{"op":"mcm","clk":"11536381051","pt":1719425248547,"mc":[{"id":"1.230178320","marketDefinition":{"bspMarket":true,"turnInPlayEnabled":false,"persistenceEnabled":false,"marketBaseRate":5.0,"eventId":"33376062","eventTypeId":"4339","numberOfWinners":1,"bettingType":"ODDS","marketType":"WIN","marketTime":"2024-06-27T15:47:00.000Z","suspendTime":"2024-06-27T15:47:00.000Z","bspReconciled":false,"complete":true,"inPlay":false,"crossMatching":false,"runnersVoidable":false,"numberOfActiveRunners":6,"betDelay":0,"status":"OPEN","runners":[{"status":"ACTIVE","sortPriority":1,"id":51643934,"name":"1. Ballymac Frisby"},{"status":"ACTIVE","sortPriority":2,"id":62531723,"name":"2. Lynnway Touch"},{"status":"ACTIVE","sortPriority":3,"id":61941199,"name":"3. Kilara Thyestes"},{"status":"ACTIVE","sortPriority":4,"id":69176305,"name":"4. Moss Row Jemma"},{"status":"ACTIVE","sortPriority":5,"id":61419789,"name":"5. Buzzers Delight"},{"status":"ACTIVE","sortPriority":6,"id":43498435,"name":"6. Easy Cookie"}],"regulators":["MR_INT"],"venue":"Kinsley","countryCode":"GB","discountAllowed":true,"timezone":"Europe/London","openDate":"2024-06-27T13:36:00.000Z","version":5994643807,"name":"A2 462m","eventName":"Kinsley 27th Jun"},"rc":[],"con":true,"img":false}]}
{"op":"mcm","clk":"11536615179","pt":1719428244489,"mc":[{"id":"1.230178320","rc":[{"atb":[[1.02,22.63]],"id":69176305},{"atl":[[1000,0.84]],"id":69176305},{"spn":500.51,"spf":"NaN","id":69176305},{"atb":[[1.01,45.27]],"id":43498435},{"atl":[[1000,0.84]],"id":43498435},{"spn":500.5,"spf":"NaN","id":43498435},{"atb":[[1.02,22.63]],"id":61941199},{"atl":[[1000,0.84]],"id":61941199},{"spn":500.51,"spf":"NaN","id":61941199},{"atb":[[1.03,15.09]],"id":61419789},{"atl":[[1000,0.84]],"id":61419789},{"spn":500.51,"spf":"NaN","id":61419789},{"atb":[[1.03,15.09]],"id":62531723},{"atl":[[1000,0.84]],"id":62531723},{"spn":500.51,"spf":"NaN","id":62531723},{"atb":[[1.01,45.27]],"id":51643934},{"atl":[[1000,0.84]],"id":51643934},{"spn":500.5,"spf":"NaN","id":51643934}],"con":true,"img":false}]}
{"op":"mcm","clk":"11536836949","pt":1719431851416,"mc":[{"id":"1.230178320","rc":[{"atb":[[1.02,22.64]],"id":69176305},{"atl":[[1000,0.26]],"id":69176305},{"atb":[[1.01,45.28]],"id":43498435},{"atl":[[1000,0.26]],"id":43498435},{"atb":[[1.02,22.64]],"id":61941199},{"atl":[[1000,0.26]],"id":61941199},{"atb":[[1.03,15.09]],"id":61419789},{"atl":[[1000,0.26]],"id":61419789},{"atb":[[1.03,15.09]],"id":62531723},{"atl":[[1000,0.26]],"id":62531723},{"atb":[[1.01,45.28]],"id":51643934},{"atl":[[1000,0.26]],"id":51643934}],"con":true,"img":false}]}
{"op":"mcm","clk":"11536864023","pt":1719432273175,"mc":[{"id":"1.230178320","rc":[{"spl":[[1.01,1]],"id":51643934},{"spn":1.01,"spf":1.0,"id":51643934}],"con":true,"img":false}]}
{"op":"mcm","clk":"11537232277","pt":1719437882525,"mc":[{"id":"1.230178320","marketDefinition":{"bspMarket":true,"turnInPlayEnabled":false,"persistenceEnabled":false,"marketBaseRate":5.0,"eventId":"33376062","eventTypeId":"4339","numberOfWinners":1,"bettingType":"ODDS","marketType":"WIN","marketTime":"2024-06-27T15:47:00.000Z","suspendTime":"2024-06-27T15:47:00.000Z","bspReconciled":false,"complete":true,"inPlay":false,"crossMatching":false,"runnersVoidable":false,"numberOfActiveRunners":6,"betDelay":0,"status":"OPEN","runners":[{"status":"ACTIVE","sortPriority":1,"id":51643934,"name":"1. Ballymac Frisby"},{"status":"ACTIVE","sortPriority":2,"id":62531723,"name":"2. Lynnway Touch"},{"status":"ACTIVE","sortPriority":3,"id":61941199,"name":"3. Kilara Thyestes"},{"status":"ACTIVE","sortPriority":4,"id":69176305,"name":"4. Moss Row Jemma"},{"status":"ACTIVE","sortPriority":5,"id":61419789,"name":"5. Buzzers Delight"},{"status":"ACTIVE","sortPriority":6,"id":43498435,"name":"6. Easy Cookie"}],"regulators":["MR_INT"],"venue":"Kinsley","countryCode":"GB","discountAllowed":true,"timezone":"Europe/London","openDate":"2024-06-27T13:36:00.000Z","version":5994643807,"name":"A2 462m","eventName":"Kinsley 27th Jun"},"rc":[{"atb":[[1.02,22.64]],"id":69176305},{"atl":[[1000,0.26]],"id":69176305},{"spn":500.51,"spf":"NaN","id":69176305},{"atb":[[1.01,45.28]],"id":43498435},{"atl":[[1000,0.26]],"id":43498435},{"spn":500.5,"spf":"NaN","id":43498435},{"atb":[[1.02,22.64]],"id":61941199},{"atl":[[1000,0.26]],"id":61941199},{"spn":500.51,"spf":"NaN","id":61941199},{"atb":[[1.03,15.09]],"id":61419789},{"atl":[[1000,0.26]],"id":61419789},{"spn":500.51,"spf":"NaN","id":61419789},{"atb":[[1.03,15.09]],"id":62531723},{"atl":[[1000,0.26]],"id":62531723},{"spn":500.51,"spf":"NaN","id":62531723},{"spl":[[1.01,1]],"id":51643934},{"atb":[[1.01,45.28]],"id":51643934},{"atl":[[1000,0.26]],"id":51643934},{"spn":1.01,"spf":1.0,"id":51643934}],"con":true,"img":true}]}
{"op":"mcm","clk":"11537573404","pt":1719443282544,"mc":[{"id":"1.230178320","marketDefinition":{"bspMarket":true,"turnInPlayEnabled":false,"persistenceEnabled":false,"marketBaseRate":5.0,"eventId":"33376062","eventTypeId":"4339","numberOfWinners":1,"bettingType":"ODDS","marketType":"WIN","marketTime":"2024-06-27T15:47:00.000Z","suspendTime":"2024-06-27T15:47:00.000Z","bspReconciled":false,"complete":true,"inPlay":false,"crossMatching":false,"runnersVoidable":false,"numberOfActiveRunners":6,"betDelay":0,"status":"OPEN","runners":[{"status":"ACTIVE","sortPriority":1,"id":51643934,"name":"1. Ballymac Frisby"},{"status":"ACTIVE","sortPriority":2,"id":62531723,"name":"2. Lynnway Touch"},{"status":"ACTIVE","sortPriority":3,"id":61941199,"name":"3. Kilara Thyestes"},{"status":"ACTIVE","sortPriority":4,"id":69176305,"name":"4. Moss Row Jemma"},{"status":"ACTIVE","sortPriority":5,"id":61419789,"name":"5. Buzzers Delight"},{"status":"ACTIVE","sortPriority":6,"id":43498435,"name":"6. Easy Cookie"}],"regulators":["MR_INT"],"venue":"Kinsley","countryCode":"GB","discountAllowed":true,"timezone":"Europe/London","openDate":"2024-06-27T13:36:00.000Z","version":5994643807,"name":"A2 462m","eventName":"Kinsley 27th Jun"},"rc":[{"atb":[[1.02,22.64]],"id":69176305},{"atl":[[1000,0.26]],"id":69176305},{"spn":500.51,"spf":"NaN","id":69176305},{"atb":[[1.01,45.29]],"id":43498435},{"atl":[[1000,0.26]],"id":43498435},{"spn":500.5,"spf":"NaN","id":43498435},{"atb":[[1.02,22.64]],"id":61941199},{"atl":[[1000,0.26]],"id":61941199},{"spn":500.51,"spf":"NaN","id":61941199},{"atb":[[1.03,15.09]],"id":61419789},{"atl":[[1000,0.26]],"id":61419789},{"spn":500.51,"spf":"NaN","id":61419789},{"atb":[[1.03,15.09]],"id":62531723},{"atl":[[1000,0.26]],"id":62531723},{"spn":500.51,"spf":"NaN","id":62531723},{"spl":[[1.01,1]],"id":51643934},{"atb":[[1.01,45.29]],"id":51643934},{"atl":[[1000,0.26]],"id":51643934},{"spn":1.01,"spf":1.0,"id":51643934}],"con":true,"img":true}]}
{"op":"mcm","clk":"11537954964","pt":1719448682569,"mc":[{"id":"1.230178320","marketDefinition":{"bspMarket":true,"turnInPlayEnabled":false,"persistenceEnabled":false,"marketBaseRate":5.0,"eventId":"33376062","eventTypeId":"4339","numberOfWinners":1,"bettingType":"ODDS","marketType":"WIN","marketTime":"2024-06-27T15:47:00.000Z","suspendTime":"2024-06-27T15:47:00.000Z","bspReconciled":false,"complete":true,"inPlay":false,"crossMatching":false,"runnersVoidable":false,"numberOfActiveRunners":6,"betDelay":0,"status":"OPEN","runners":[{"status":"ACTIVE","sortPriority":1,"id":51643934,"name":"1. Ballymac Frisby"},{"status":"ACTIVE","sortPriority":2,"id":62531723,"name":"2. Lynnway Touch"},{"status":"ACTIVE","sortPriority":3,"id":61941199,"name":"3. Kilara Thyestes"},{"status":"ACTIVE","sortPriority":4,"id":69176305,"name":"4. Moss Row Jemma"},{"status":"ACTIVE","sortPriority":5,"id":61419789,"name":"5. Buzzers Delight"},{"status":"ACTIVE","sortPriority":6,"id":43498435,"name":"6. Easy Cookie"}],"regulators":["MR_INT"],"venue":"Kinsley","countryCode":"GB","discountAllowed":true,"timezone":"Europe/London","openDate":"2024-06-27T13:36:00.000Z","version":5994643807,"name":"A2 462m","eventName":"Kinsley 27th Jun"},"rc":[{"atb":[[1.02,22.64]],"id":69176305},{"atl":[[1000,0.26]],"id":69176305},{"spn":500.51,"spf":"NaN","id":69176305},{"atb":[[1.01,45.28]],"id":43498435},{"atl":[[1000,0.26]],"id":43498435},{"spn":500.5,"spf":"NaN","id":43498435},{"atb":[[1.02,22.64]],"id":61941199},{"atl":[[1000,0.26]],"id":61941199},{"spn":500.51,"spf":"NaN","id":61941199},{"atb":[[1.03,15.09]],"id":61419789},{"atl":[[1000,0.26]],"id":61419789},{"spn":500.51,"spf":"NaN","id":61419789},{"atb":[[1.03,15.09]],"id":62531723},{"atl":[[1000,0.26]],"id":62531723},{"spn":500.51,"spf":"NaN","id":62531723},{"spl":[[1.01,1]],"id":51643934},{"atb":[[1.01,45.28]],"id":51643934},{"atl":[[1000,0.26]],"id":51643934},{"spn":1.01,"spf":1.0,"id":51643934}],"con":true,"img":true}]}
{"op":"mcm","clk":"11538170627","pt":1719454082551,"mc":[{"id":"1.230178320","marketDefinition":{"bspMarket":true,"turnInPlayEnabled":false,"persistenceEnabled":false,"marketBaseRate":5.0,"eventId":"33376062","eventTypeId":"4339","numberOfWinners":1,"bettingType":"ODDS","marketType":"WIN","marketTime":"2024-06-27T15:47:00.000Z","suspendTime":"2024-06-27T15:47:00.000Z","bspReconciled":false,"complete":true,"inPlay":false,"crossMatching":false,"runnersVoidable":false,"numberOfActiveRunners":6,"betDelay":0,"status":"OPEN","runners":[{"status":"ACTIVE","sortPriority":1,"id":51643934,"name":"1. Ballymac Frisby"},{"status":"ACTIVE","sortPriority":2,"id":62531723,"name":"2. Lynnway Touch"},{"status":"ACTIVE","sortPriority":3,"id":61941199,"name":"3. Kilara Thyestes"},{"status":"ACTIVE","sortPriority":4,"id":69176305,"name":"4. Moss Row Jemma"},{"status":"ACTIVE","sortPriority":5,"id":61419789,"name":"5. Buzzers Delight"},{"status":"ACTIVE","sortPriority":6,"id":43498435,"name":"6. Easy Cookie"}],"regulators":["MR_INT"],"venue":"Kinsley","countryCode":"GB","discountAllowed":true,"timezone":"Europe/London","openDate":"2024-06-27T13:36:00.000Z","version":5994643807,"name":"A2 462m","eventName":"Kinsley 27th Jun"},"rc":[{"atb":[[1.02,22.64]],"id":69176305},{"atl":[[1000,0.26]],"id":69176305},{"spn":500.51,"spf":"NaN","id":69176305},{"atb":[[1.01,45.29]],"id":43498435},{"atl":[[1000,0.26]],"id":43498435},{"spn":500.5,"spf":"NaN","id":43498435},{"atb":[[1.02,22.64]],"id":61941199},{"atl":[[1000,0.26]],"id":61941199},{"spn":500.51,"spf":"NaN","id":61941199},{"atb":[[1.03,15.09]],"id":61419789},{"atl":[[1000,0.26]],"id":61419789},{"spn":500.51,"spf":"NaN","id":61419789},{"atb":[[1.03,15.09]],"id":62531723},{"atl":[[1000,0.26]],"id":62531723},{"spn":500.51,"spf":"NaN","id":62531723},{"spl":[[1.01,1]],"id":51643934},{"atb":[[1.01,45.29]],"id":51643934},{"atl":[[1000,0.26]],"id":51643934},{"spn":1.01,"spf":1.0,"id":51643934}],"con":true,"img":true}]}
{"op":"mcm","clk":"11538368285","pt":1719459482601,"mc":[{"id":"1.230178320","marketDefinition":{"bspMarket":true,"turnInPlayEnabled":false,"persistenceEnabled":false,"marketBaseRate":5.0,"eventId":"33376062","eventTypeId":"4339","numberOfWinners":1,"bettingType":"ODDS","marketType":"WIN","marketTime":"2024-06-27T15:47:00.000Z","suspendTime":"2024-06-27T15:47:00.000Z","bspReconciled":false,"complete":true,"inPlay":false,"crossMatching":false,"runnersVoidable":false,"numberOfActiveRunners":6,"betDelay":0,"status":"OPEN","runners":[{"status":"ACTIVE","sortPriority":1,"id":51643934,"name":"1. Ballymac Frisby"},{"status":"ACTIVE","sortPriority":2,"id":62531723,"name":"2. Lynnway Touch"},{"status":"ACTIVE","sortPriority":3,"id":61941199,"name":"3. Kilara Thyestes"},{"status":"ACTIVE","sortPriority":4,"id":69176305,"name":"4. Moss Row Jemma"},{"status":"ACTIVE","sortPriority":5,"id":61419789,"name":"5. Buzzers Delight"},{"status":"ACTIVE","sortPriority":6,"id":43498435,"name":"6. Easy Cookie"}],"regulators":["MR_INT"],"venue":"Kinsley","countryCode":"GB","discountAllowed":true,"timezone":"Europe/London","openDate":"2024-06-27T13:36:00.000Z","version":5994643807,"name":"A2 462m","eventName":"Kinsley 27th Jun"},"rc":[{"atb":[[1.02,22.65]],"id":69176305},{"atl":[[1000,0.26]],"id":69176305},{"spn":500.51,"spf":"NaN","id":69176305},{"atb":[[1.01,45.3]],"id":43498435},{"atl":[[1000,0.26]],"id":43498435},{"spn":500.5,"spf":"NaN","id":43498435},{"atb":[[1.02,22.65]],"id":61941199},{"atl":[[1000,0.26]],"id":61941199},{"spn":500.51,"spf":"NaN","id":61941199},{"atb":[[1.03,15.1]],"id":61419789},{"atl":[[1000,0.26]],"id":61419789},{"spn":500.51,"spf":"NaN","id":61419789},{"atb":[[1.03,15.1]],"id":62531723},{"atl":[[1000,0.26]],"id":62531723},{"spn":500.51,"spf":"NaN","id":62531723},{"spl":[[1.01,1]],"id":51643934},{"atb":[[1.01,45.3]],"id":51643934},{"atl":[[1000,0.26]],"id":51643934},{"spn":1.01,"spf":1.0,"id":51643934}],"con":true,"img":true}]}
{"op":"mcm","clk":"11538595411","pt":1719464882549,"mc":[{"id":"1.230178320","marketDefinition":{"bspMarket":true,"turnInPlayEnabled":false,"persistenceEnabled":false,"marketBaseRate":5.0,"eventId":"33376062","eventTypeId":"4339","numberOfWinners":1,"bettingType":"ODDS","marketType":"WIN","marketTime":"2024-06-27T15:47:00.000Z","suspendTime":"2024-06-27T15:47:00.000Z","bspReconciled":false,"complete":true,"inPlay":false,"crossMatching":false,"runnersVoidable":false,"numberOfActiveRunners":6,"betDelay":0,"status":"OPEN","runners":[{"status":"ACTIVE","sortPriority":1,"id":51643934,"name":"1. Ballymac Frisby"},{"status":"ACTIVE","sortPriority":2,"id":62531723,"name":"2. Lynnway Touch"},{"status":"ACTIVE","sortPriority":3,"id":61941199,"name":"3. Kilara Thyestes"},{"status":"ACTIVE","sortPriority":4,"id":69176305,"name":"4. Moss Row Jemma"},{"status":"ACTIVE","sortPriority":5,"id":61419789,"name":"5. Buzzers Delight"},{"status":"ACTIVE","sortPriority":6,"id":43498435,"name":"6. Easy Cookie"}],"regulators":["MR_INT"],"venue":"Kinsley","countryCode":"GB","discountAllowed":true,"timezone":"Europe/London","openDate":"2024-06-27T13:36:00.000Z","version":5994643807,"name":"A2 462m","eventName":"Kinsley 27th Jun"},"rc":[{"atb":[[1.02,22.64]],"id":69176305},{"atl":[[1000,0.26]],"id":69176305},{"spn":500.51,"spf":"NaN","id":69176305},{"atb":[[1.01,45.29]],"id":43498435},{"atl":[[1000,0.26]],"id":43498435},{"spn":500.5,"spf":"NaN","id":43498435},{"atb":[[1.02,22.64]],"id":61941199},{"atl":[[1000,0.26]],"id":61941199},{"spn":500.51,"spf":"NaN","id":61941199},{"atb":[[1.03,15.09]],"id":61419789},{"atl":[[1000,0.26]],"id":61419789},{"spn":500.51,"spf":"NaN","id":61419789},{"atb":[[1.03,15.09]],"id":62531723},{"atl":[[1000,0.26]],"id":62531723},{"spn":500.51,"spf":"NaN","id":62531723},{"spl":[[1.01,1]],"id":51643934},{"atb":[[1.01,45.29]],"id":51643934},{"atl":[[1000,0.26]],"id":51643934},{"spn":1.01,"spf":1.0,"id":51643934}],"con":true,"img":true}]}
{"op":"mcm","clk":"11538748626","pt":1719468204914,"mc":[{"id":"1.230178320","rc":[{"atb":[[2,8.54],[1.02,22.64]],"id":69176305},{"spn":501.0,"spf":"NaN","id":69176305},{"atb":[[1.01,45.29],[2.08,13.32]],"id":43498435},{"spn":501.04,"spf":"NaN","id":43498435},{"atb":[[2.06,9.68],[1.02,22.64]],"id":61941199},{"spn":501.03,"spf":"NaN","id":61941199},{"atb":[[2,9.4],[1.03,15.09]],"id":61419789},{"spn":501.0,"spf":"NaN","id":61419789},{"atb":[[1.03,15.09],[2.1,10.76]],"id":62531723},{"spn":501.05,"spf":"NaN","id":62531723},{"atb":[[1.01,45.29],[2.1,13.45]],"id":51643934},{"spn":2.1,"spf":1.0,"id":51643934}],"con":true,"img":false}]}
{"op":"mcm","clk":"11538750530","pt":1719468245055,"mc":[{"id":"1.230178320","rc":[{"atb":[[2.08,3.16]],"id":61941199}],"con":true,"img":false}]}
{"op":"mcm","clk":"11538750544","pt":1719468245260,"mc":[{"id":"1.230178320","rc":[{"atb":[[2.12,3.16]],"id":62531723}],"con":true,"img":false}]}
{"op":"mcm","clk":"11538750557","pt":1719468245466,"mc":[{"id":"1.230178320","rc":[{"atb":[[2.02,3.16]],"id":61419789}],"con":true,"img":false}]}
{"op":"mcm","clk":"11538750598","pt":1719468246285,"mc":[{"id":"1.230178320","rc":[{"atb":[[2.1,3.16]],"id":43498435}],"con":true,"img":false}]}
{"op":"mcm","clk":"11538750624","pt":1719468246650,"mc":[{"id":"1.230178320","rc":[{"atb":[[2.12,3.16]],"id":51643934}],"con":true,"img":false}]}
{"op":"mcm","clk":"11538750708","pt":1719468248181,"mc":[{"id":"1.230178320","rc":[{"atb":[[2.02,3.16]],"id":69176305}],"con":true,"img":false}]}
{"op":"mcm","clk":"11538752505","pt":1719468283693,"mc":[{"id":"1.230178320","rc":[{"spn":501.01,"spf":"NaN","id":69176305},{"spn":501.05,"spf":"NaN","id":43498435},{"spn":501.04,"spf":"NaN","id":61941199},{"spn":501.01,"spf":"NaN","id":61419789},{"spn":501.06,"spf":"NaN","id":62531723},{"atb":[[2.12,6.55]],"id":51643934},{"spn":2.12,"spf":1.0,"id":51643934}],"con":true,"img":false}]}
{"op":"mcm","clk":"11538752527","pt":1719468284103,"mc":[{"id":"1.230178320","rc":[{"atb":[[2.12,6.55]],"id":62531723}],"con":true,"img":false}]}
{"op":"mcm","clk":"11538752539","pt":1719468284409,"mc":[{"id":"1.230178320","rc":[{"atb":[[2.02,6.55]],"id":69176305}],"con":true,"img":false}]}
{"op":"mcm","clk":"11538752546","pt":1719468284514,"mc":[{"id":"1.230178320","rc":[{"atb":[[2.1,6.55]],"id":43498435}],"con":true,"img":false}]}
{"op":"mcm","clk":"11538752578","pt":1719468285128,"mc":[{"id":"1.230178320","rc":[{"atb":[[2.02,6.55]],"id":61419789}],"con":true,"img":false}]}
{"op":"mcm","clk":"11538752588","pt":1719468285282,"mc":[{"id":"1.230178320","rc":[{"atb":[[2.08,6.55]],"id":61941199}],"con":true,"img":false}]}
{"op":"mcm","clk":"11538754053","pt":1719468311787,"mc":[{"id":"1.230178320","marketDefinition":{"bspMarket":true,"turnInPlayEnabled":false,"persistenceEnabled":false,"marketBaseRate":5.0,"eventId":"33376062","eventTypeId":"4339","numberOfWinners":1,"bettingType":"ODDS","marketType":"WIN","marketTime":"2024-06-27T15:47:00.000Z","suspendTime":"2024-06-27T15:47:00.000Z","bspReconciled":false,"complete":true,"inPlay":false,"crossMatching":true,"runnersVoidable":false,"numberOfActiveRunners":6,"betDelay":0,"status":"OPEN","runners":[{"status":"ACTIVE","sortPriority":1,"id":51643934,"name":"1. Ballymac Frisby"},{"status":"ACTIVE","sortPriority":2,"id":62531723,"name":"2. Lynnway Touch"},{"status":"ACTIVE","sortPriority":3,"id":61941199,"name":"3. Kilara Thyestes"},{"status":"ACTIVE","sortPriority":4,"id":69176305,"name":"4. Moss Row Jemma"},{"status":"ACTIVE","sortPriority":5,"id":61419789,"name":"5. Buzzers Delight"},{"status":"ACTIVE","sortPriority":6,"id":43498435,"name":"6. Easy Cookie"}],"regulators":["MR_INT"],"venue":"Kinsley","countryCode":"GB","discountAllowed":true,"timezone":"Europe/London","openDate":"2024-06-27T13:36:00.000Z","version":5994643807,"name":"A2 462m","eventName":"Kinsley 27th Jun"},"rc":[],"con":true,"img":false}]}
{"op":"mcm","clk":"11538880493","pt":1719470845819,"mc":[{"id":"1.230178320","rc":[{"atl":[[150,4]],"id":43498435},{"spn":76.05,"spf":"NaN","id":43498435},{"atl":[[150,4]],"id":69176305},{"spn":76.01,"spf":"NaN","id":69176305},{"atl":[[150,4]],"id":61941199},{"spn":76.04,"spf":"NaN","id":61941199},{"atl":[[150,4]],"id":61419789},{"spn":76.01,"spf":"NaN","id":61419789},{"atl":[[150,4]],"id":62531723},{"spn":76.06,"spf":"NaN","id":62531723},{"atl":[[150,4]],"id":51643934}],"con":true,"img":false}]}
{"op":"mcm","clk":"11538904989","pt":1719471464109,"mc":[{"id":"1.230178320","rc":[{"atl":[[1000,0.16]],"id":69176305},{"atl":[[1000,0.16]],"id":43498435},{"atl":[[1000,0.16]],"id":61941199},{"atl":[[1000,0.16]],"id":61419789},{"atl":[[1000,0.16]],"id":62531723},{"atl":[[1000,0.16]],"id":51643934}],"con":true,"img":false}]}
{"op":"mcm","clk":"11538938856","pt":1719472078625,"mc":[{"id":"1.230178320","rc":[{"atb":[[2,8.54],[2.02,6.54],[1.02,22.63]],"id":69176305},{"atl":[[1000,0.16]],"id":69176305},{"atb":[[1.01,45.26],[2.1,6.54],[2.08,13.32]],"id":43498435},{"atl":[[1000,0.16]],"id":43498435},{"atb":[[2.06,9.67],[1.02,22.63],[2.08,6.54]],"id":61941199},{"atl":[[1000,0.16]],"id":61941199},{"atb":[[2,9.39],[2.02,6.54],[1.03,15.08]],"id":61419789},{"atl":[[21,4],[1000,0.16]],"id":61419789},{"spn":11.51,"spf":"NaN","id":61419789},{"atb":[[1.03,15.08],[2.12,6.54],[2.1,10.75]],"id":62531723},{"atl":[[1000,0.16]],"id":62531723},{"atb":[[1.01,45.26],[2.12,6.54],[2.1,13.44]],"id":51643934},{"atl":[[1000,0.16]],"id":51643934}],"con":true,"img":false}]}
{"op":"mcm","clk":"11538940650","pt":1719472112077,"mc":[{"id":"1.230178320","rc":[{"atb":[[2,0]],"id":69176305},{"atb":[[2.08,0]],"id":43498435},{"atb":[[2.06,0]],"id":61941199},{"atb":[[2,0]],"id":61419789},{"atb":[[2.1,0]],"id":62531723},{"atb":[[2.1,0]],"id":51643934}],"con":true,"img":false}]}
{"op":"mcm","clk":"11538940654","pt":1719472112181,"mc":[{"id":"1.230178320","rc":[{"atb":[[2.04,8.54]],"id":69176305},{"atb":[[2.12,13.32]],"id":43498435},{"atb":[[2.1,9.67]],"id":61941199},{"atb":[[2.04,9.39]],"id":61419789},{"atb":[[2.14,10.75]],"id":62531723},{"atb":[[2.14,13.44]],"id":51643934}],"con":true,"img":false}]}
{"op":"mcm","clk":"11538942856","pt":1719472146505,"mc":[{"id":"1.230178320","rc":[{"spn":76.02,"spf":"NaN","id":69176305},{"spn":76.06,"spf":"NaN","id":43498435},{"spn":76.05,"spf":"NaN","id":61941199},{"spn":11.52,"spf":"NaN","id":61419789},{"atb":[[2.12,3.38]],"id":62531723},{"spn":76.07,"spf":"NaN","id":62531723},{"spn":2.14,"spf":1.0,"id":51643934}],"con":true,"img":false}]}
{"op":"mcm","clk":"11538942897","pt":1719472147022,"mc":[{"id":"1.230178320","rc":[{"atb":[[2.02,3.38]],"id":69176305}],"con":true,"img":false}]}
{"op":"mcm","clk":"11538942936","pt":1719472147534,"mc":[{"id":"1.230178320","rc":[{"atb":[[2.08,3.38]],"id":61941199}],"con":true,"img":false}]}
{"op":"mcm","clk":"11538942955","pt":1719472147802,"mc":[{"id":"1.230178320","rc":[{"atb":[[2.1,3.38]],"id":43498435}],"con":true,"img":false}]}
{"op":"mcm","clk":"11538943056","pt":1719472149327,"mc":[{"id":"1.230178320","rc":[{"atb":[[2.02,3.38]],"id":61419789}],"con":true,"img":false}]}
{"op":"mcm","clk":"11538943099","pt":1719472150102,"mc":[{"id":"1.230178320","rc":[{"atb":[[2.06,3.16]],"id":69176305}],"con":true,"img":false}]}
{"op":"mcm","clk":"11538943115","pt":1719472150306,"mc":[{"id":"1.230178320","rc":[{"atb":[[2.16,3.16]],"id":62531723}],"con":true,"img":false}]}
{"op":"mcm","clk":"11538943136","pt":1719472150616,"mc":[{"id":"1.230178320","rc":[{"atb":[[2.14,3.16]],"id":43498435}],"con":true,"img":false}]}
{"op":"mcm","clk":"11538943174","pt":1719472151127,"mc":[{"id":"1.230178320","rc":[{"atb":[[2.12,3.38]],"id":51643934}],"con":true,"img":false}]}
{"op":"mcm","clk":"11538943244","pt":1719472152407,"mc":[{"id":"1.230178320","rc":[{"atb":[[2.12,3.16]],"id":61941199}],"con":true,"img":false}]}
{"op":"mcm","clk":"11538943299","pt":1719472153432,"mc":[{"id":"1.230178320","rc":[{"atb":[[2.06,3.16]],"id":61419789}],"con":true,"img":false}]}
{"op":"mcm","clk":"11538943447","pt":1719472155745,"mc":[{"id":"1.230178320","rc":[{"atb":[[2.16,3.16]],"id":51643934}],"con":true,"img":false}]}
{"op":"mcm","clk":"11538943948","pt":1719472164251,"mc":[{"id":"1.230178320","rc":[{"atb":[[2.08,0]],"id":61941199},{"atb":[[2.12,0]],"id":62531723}],"con":true,"img":false}]}
{"op":"mcm","clk":"11538943975","pt":1719472164613,"mc":[{"id":"1.230178320","rc":[{"atb":[[2.02,0]],"id":61419789}],"con":true,"img":false}]}
{"op":"mcm","clk":"11538944025","pt":1719472165434,"mc":[{"id":"1.230178320","rc":[{"atb":[[2.12,0]],"id":51643934}],"con":true,"img":false}]}
{"op":"mcm","clk":"11538944064","pt":1719472166248,"mc":[{"id":"1.230178320","rc":[{"atb":[[2.1,0]],"id":43498435}],"con":true,"img":false}]}
{"op":"mcm","clk":"11538944075","pt":1719472166453,"mc":[{"id":"1.230178320","rc":[{"atb":[[2.02,0]],"id":69176305}],"con":true,"img":false}]}
{"op":"mcm","clk":"11538944967","pt":1719472181236,"mc":[{"id":"1.230178320","rc":[{"atb":[[2.16,6.54]],"id":51643934}],"con":true,"img":false}]}
{"op":"mcm","clk":"11538944972","pt":1719472181340,"mc":[{"id":"1.230178320","rc":[{"atb":[[2.06,6.54]],"id":61419789}],"con":true,"img":false}]}
{"op":"mcm","clk":"11538945027","pt":1719472182162,"mc":[{"id":"1.230178320","rc":[{"atb":[[2.14,6.54]],"id":43498435}],"con":true,"img":false}]}
{"op":"mcm","clk":"11538945051","pt":1719472182573,"mc":[{"id":"1.230178320","rc":[{"atb":[[2.12,6.54]],"id":61941199}],"con":true,"img":false}]}
{"op":"mcm","clk":"11538945178","pt":1719472184848,"mc":[{"id":"1.230178320","rc":[{"atb":[[2.16,6.54]],"id":62531723}],"con":true,"img":false}]}
{"op":"mcm","clk":"11538945200","pt":1719472185157,"mc":[{"id":"1.230178320","rc":[{"atb":[[2.06,6.54]],"id":69176305}],"con":true,"img":false}]}
{"op":"mcm","clk":"11539122558","pt":1719475682557,"mc":[{"id":"1.230178320","marketDefinition":{"bspMarket":true,"turnInPlayEnabled":false,"persistenceEnabled":false,"marketBaseRate":5.0,"eventId":"33376062","eventTypeId":"4339","numberOfWinners":1,"bettingType":"ODDS","marketType":"WIN","marketTime":"2024-06-27T15:47:00.000Z","suspendTime":"2024-06-27T15:47:00.000Z","bspReconciled":false,"complete":true,"inPlay":false,"crossMatching":true,"runnersVoidable":false,"numberOfActiveRunners":6,"betDelay":0,"status":"OPEN","runners":[{"status":"ACTIVE","sortPriority":1,"id":51643934,"name":"1. Ballymac Frisby"},{"status":"ACTIVE","sortPriority":2,"id":62531723,"name":"2. Lynnway Touch"},{"status":"ACTIVE","sortPriority":3,"id":61941199,"name":"3. Kilara Thyestes"},{"status":"ACTIVE","sortPriority":4,"id":69176305,"name":"4. Moss Row Jemma"},{"status":"ACTIVE","sortPriority":5,"id":61419789,"name":"5. Buzzers Delight"},{"status":"ACTIVE","sortPriority":6,"id":43498435,"name":"6. Easy Cookie"}],"regulators":["MR_INT"],"venue":"Kinsley","countryCode":"GB","discountAllowed":true,"timezone":"Europe/London","openDate":"2024-06-27T13:36:00.000Z","version":5994643807,"name":"A2 462m","eventName":"Kinsley 27th Jun"},"rc":[{"atb":[[2.06,6.55],[2.04,8.54],[1.02,22.64]],"id":69176305},{"atl":[[150,4],[1000,0.16]],"id":69176305},{"spn":76.03,"spf":"NaN","id":69176305},{"atb":[[1.01,45.28],[2.12,13.32],[2.14,6.55]],"id":43498435},{"atl":[[150,4],[1000,0.16]],"id":43498435},{"spn":76.07,"spf":"NaN","id":43498435},{"atb":[[1.02,22.64],[2.12,6.55],[2.1,9.67]],"id":61941199},{"atl":[[150,4],[1000,0.16]],"id":61941199},{"spn":76.06,"spf":"NaN","id":61941199},{"atb":[[2.06,6.55],[1.03,15.09],[2.04,9.4]],"id":61419789},{"atl":[[150,4],[21,4],[1000,0.16]],"id":61419789},{"spn":11.53,"spf":"NaN","id":61419789},{"atb":[[1.03,15.09],[2.16,6.55],[2.14,10.76]],"id":62531723},{"atl":[[150,4],[1000,0.16]],"id":62531723},{"spn":76.08,"spf":"NaN","id":62531723},{"spl":[[1.01,1]],"id":51643934},{"atb":[[1.01,45.28],[2.16,6.55],[2.14,13.45]],"id":51643934},{"atl":[[150,4],[1000,0.16]],"id":51643934},{"spn":2.16,"spf":1.0,"id":51643934}],"con":true,"img":true}]}
{"op":"mcm","clk":"11539127967","pt":1719475712098,"mc":[{"id":"1.230178320","rc":[{"atb":[[2.06,6.55],[2.04,0],[1.02,22.64]],"id":69176305},{"spn":76.03,"spf":"NaN","id":69176305},{"atb":[[1.01,45.28],[2.12,0],[2.14,6.55]],"id":43498435},{"spn":76.07,"spf":"NaN","id":43498435},{"atb":[[1.02,22.64],[2.12,6.55],[2.1,0]],"id":61941199},{"spn":76.06,"spf":"NaN","id":61941199},{"atb":[[2.06,6.55],[1.03,15.09],[2.04,0]],"id":61419789},{"spn":11.53,"spf":"NaN","id":61419789},{"atb":[[1.03,15.09],[2.16,6.55],[2.14,0]],"id":62531723},{"spn":76.08,"spf":"NaN","id":62531723},{"atb":[[1.01,45.28],[2.16,6.55],[2.14,0]],"id":51643934},{"spn":2.16,"spf":1.0,"id":51643934}],"con":true,"img":false}]}
{"op":"mcm","clk":"11539127975","pt":1719475712200,"mc":[{"id":"1.230178320","rc":[{"atb":[[2.08,8.54]],"id":69176305},{"atb":[[2.16,13.32]],"id":43498435},{"atb":[[2.14,9.67]],"id":61941199},{"atb":[[2.08,9.4]],"id":61419789},{"atb":[[2.18,10.76]],"id":62531723},{"atb":[[2.18,13.45]],"id":51643934}],"con":true,"img":false}]}
{"op":"mcm","clk":"11539133321","pt":1719475797423,"mc":[{"id":"1.230178320","rc":[{"spn":76.08,"spf":"NaN","id":43498435},{"spn":76.04,"spf":"NaN","id":69176305},{"spn":76.07,"spf":"NaN","id":61941199},{"atb":[[2.06,3.16]],"id":61419789},{"spn":11.54,"spf":"NaN","id":61419789},{"spn":76.09,"spf":"NaN","id":62531723},{"spn":2.18,"spf":1.0,"id":51643934}],"con":true,"img":false}]}
{"op":"mcm","clk":"11539133347","pt":1719475797685,"mc":[{"id":"1.230178320","rc":[{"atb":[[2.12,3.16]],"id":61941199}],"con":true,"img":false}]}
{"op":"mcm","clk":"11539133366","pt":1719475797889,"mc":[{"id":"1.230178320","rc":[{"atb":[[2.14,3.16]],"id":43498435}],"con":true,"img":false}]}
{"op":"mcm","clk":"11539133377","pt":1719475797996,"mc":[{"id":"1.230178320","rc":[{"atb":[[2.16,3.16]],"id":51643934}],"con":true,"img":false}]}
{"op":"mcm","clk":"11539133430","pt":1719475798613,"mc":[{"id":"1.230178320","rc":[{"atb":[[2.16,3.16]],"id":62531723}],"con":true,"img":false}]}
{"op":"mcm","clk":"11539133456","pt":1719475798926,"mc":[{"id":"1.230178320","rc":[{"atb":[[2.06,3.16]],"id":69176305}],"con":true,"img":false}]}
{"op":"mcm","clk":"11539133532","pt":1719475800104,"mc":[{"id":"1.230178320","rc":[{"atb":[[2.1,3.38]],"id":69176305}],"con":true,"img":false}]}
{"op":"mcm","clk":"11539133642","pt":1719475801407,"mc":[{"id":"1.230178320","rc":[{"atb":[[2.2,3.38]],"id":62531723},{"atb":[[2.2,3.38]],"id":51643934}],"con":true,"img":false}]}
{"op":"mcm","clk":"11539133663","pt":1719475801711,"mc":[{"id":"1.230178320","rc":[{"atb":[[2.16,3.38]],"id":61941199}],"con":true,"img":false}]}
{"op":"mcm","clk":"11539133726","pt":1719475802597,"mc":[{"id":"1.230178320","rc":[{"atb":[[2.1,3.38]],"id":61419789}],"con":true,"img":false}]}
{"op":"mcm","clk":"11539133907","pt":1719475805121,"mc":[{"id":"1.230178320","rc":[{"atb":[[2.18,3.38]],"id":43498435}],"con":true,"img":false}]}
{"op":"mcm","clk":"11539134372","pt":1719475811410,"mc":[{"id":"1.230178320","rc":[{"atb":[[2.14,0]],"id":43498435},{"atb":[[2.06,0]],"id":69176305},{"atb":[[2.12,0]],"id":61941199},{"atb":[[2.06,0]],"id":61419789},{"atb":[[2.16,0]],"id":62531723},{"atb":[[2.16,0]],"id":51643934}],"con":true,"img":false}]}
{"op":"mcm","clk":"11539153343","pt":1719476117695,"mc":[{"id":"1.230178320","rc":[{"spn":76.05,"spf":"NaN","id":69176305},{"spn":76.09,"spf":"NaN","id":43498435},{"spn":76.08,"spf":"NaN","id":61941199},{"spn":11.55,"spf":"NaN","id":61419789},{"spn":76.1,"spf":"NaN","id":62531723},{"atb":[[2.2,6.55]],"id":51643934},{"spn":2.2,"spf":1.0,"id":51643934}],"con":true,"img":false}]}
{"op":"mcm","clk":"11539153349","pt":1719476117798,"mc":[{"id":"1.230178320","rc":[{"atb":[[2.2,6.55]],"id":62531723}],"con":true,"img":false}]}
{"op":"mcm","clk":"11539153361","pt":1719476118002,"mc":[{"id":"1.230178320","rc":[{"atb":[[2.1,6.55]],"id":69176305}],"con":true,"img":false}]}
{"op":"mcm","clk":"11539153366","pt":1719476118106,"mc":[{"id":"1.230178320","rc":[{"atb":[[2.16,6.55]],"id":61941199}],"con":true,"img":false}]}
{"op":"mcm","clk":"11539153380","pt":1719476118309,"mc":[{"id":"1.230178320","rc":[{"atb":[[2.18,6.55]],"id":43498435}],"con":true,"img":false}]}
{"op":"mcm","clk":"11539153442","pt":1719476119189,"mc":[{"id":"1.230178320","rc":[{"atb":[[2.1,6.55]],"id":61419789}],"con":true,"img":false}]}
{"op":"mcm","clk":"11539341444","pt":1719479310862,"mc":[{"id":"1.230178320","rc":[{"atb":[[1.01,45.27],[2.18,6.54],[2.16,0]],"id":43498435},{"atb":[[1.02,22.63],[2.1,6.54],[2.08,0]],"id":69176305},{"atb":[[1.02,22.63],[2.16,6.54],[2.14,0]],"id":61941199},{"atb":[[1.03,15.09],[2.1,6.54],[2.08,0]],"id":61419789},{"atb":[[1.03,15.09],[2.18,0],[2.2,6.54]],"id":62531723},{"atb":[[1.01,45.27],[2.18,0],[2.2,6.54]],"id":51643934}],"con":true,"img":false}]}
{"op":"mcm","clk":"11539341450","pt":1719479310914,"mc":[{"id":"1.230178320","rc":[{"atb":[[2.2,13.32]],"id":43498435},{"atb":[[2.12,8.54]],"id":69176305},{"atb":[[2.18,9.67]],"id":61941199},{"atb":[[2.12,9.39]],"id":61419789},{"atb":[[2.22,10.76]],"id":62531723},{"atb":[[2.22,13.45]],"id":51643934}],"con":true,"img":false}]}
{"op":"mcm","clk":"11539346779","pt":1719479396958,"mc":[{"id":"1.230178320","rc":[{"spn":76.1,"spf":"NaN","id":43498435},{"spn":76.06,"spf":"NaN","id":69176305},{"atb":[[2.16,3.38]],"id":61941199},{"spn":76.09,"spf":"NaN","id":61941199},{"spn":11.56,"spf":"NaN","id":61419789},{"spn":76.11,"spf":"NaN","id":62531723},{"spn":2.22,"spf":1.0,"id":51643934}],"con":true,"img":false}]}
{"op":"mcm","clk":"11539346797","pt":1719479397160,"mc":[{"id":"1.230178320","rc":[{"atb":[[2.1,3.38]],"id":69176305}],"con":true,"img":false}]}
{"op":"mcm","clk":"11539346818","pt":1719479397466,"mc":[{"id":"1.230178320","rc":[{"atb":[[2.18,3.38]],"id":43498435}],"con":true,"img":false}]}
{"op":"mcm","clk":"11539346827","pt":1719479397670,"mc":[{"id":"1.230178320","rc":[{"atb":[[2.2,3.38]],"id":62531723}],"con":true,"img":false}]}
{"op":"mcm","clk":"11539346881","pt":1719479398495,"mc":[{"id":"1.230178320","rc":[{"atb":[[2.2,3.38]],"id":51643934}],"con":true,"img":false}]}
{"op":"mcm","clk":"11539346968","pt":1719479399989,"mc":[{"id":"1.230178320","rc":[{"atb":[[2.1,3.38]],"id":61419789}],"con":true,"img":false}]}
{"op":"mcm","clk":"11539348925","pt":1719479429627,"mc":[{"id":"1.230178320","rc":[{"atb":[[2.2,0]],"id":62531723},{"atb":[[2.2,0]],"id":51643934}],"con":true,"img":false}]}
{"op":"mcm","clk":"11539348993","pt":1719479430921,"mc":[{"id":"1.230178320","rc":[{"atb":[[2.16,0]],"id":61941199}],"con":true,"img":false}]}
{"op":"mcm","clk":"11539348997","pt":1719479431024,"mc":[{"id":"1.230178320","rc":[{"atb":[[2.1,0]],"id":69176305}],"con":true,"img":false}]}
{"op":"mcm","clk":"11539349016","pt":1719479431285,"mc":[{"id":"1.230178320","rc":[{"atb":[[2.1,0]],"id":61419789}],"con":true,"img":false}]}
{"op":"mcm","clk":"11539349029","pt":1719479431499,"mc":[{"id":"1.230178320","rc":[{"atb":[[2.18,0]],"id":43498435}],"con":true,"img":false}]}
{"op":"mcm","clk":"11539349111","pt":1719479432986,"mc":[{"id":"1.230178320","rc":[{"atb":[[2.24,3.38]],"id":51643934}],"con":true,"img":false}]}
{"op":"mcm","clk":"11539349129","pt":1719479433301,"mc":[{"id":"1.230178320","rc":[{"atb":[[2.14,3.38]],"id":61419789}],"con":true,"img":false}]}
{"op":"mcm","clk":"11539349150","pt":1719479433606,"mc":[{"id":"1.230178320","rc":[{"atb":[[2.2,3.38]],"id":61941199}],"con":true,"img":false}]}
{"op":"mcm","clk":"11539349156","pt":1719479433709,"mc":[{"id":"1.230178320","rc":[{"atb":[[2.14,3.38]],"id":69176305}],"con":true,"img":false}]}
{"op":"mcm","clk":"11539349190","pt":1719479434225,"mc":[{"id":"1.230178320","rc":[{"atb":[[2.24,3.38]],"id":62531723}],"con":true,"img":false}]}
{"op":"mcm","clk":"11539349251","pt":1719479435101,"mc":[{"id":"1.230178320","rc":[{"atb":[[2.22,3.38]],"id":43498435}],"con":true,"img":false}]}
{"op":"mcm","clk":"11539367582","pt":1719479705812,"mc":[{"id":"1.230178320","rc":[{"spn":76.11,"spf":"NaN","id":43498435},{"spn":76.07,"spf":"NaN","id":69176305},{"spn":76.1,"spf":"NaN","id":61941199},{"spn":11.57,"spf":"NaN","id":61419789},{"spn":76.12,"spf":"NaN","id":62531723},{"atb":[[2.24,6.54]],"id":51643934},{"spn":2.24,"spf":1.0,"id":51643934}],"con":true,"img":false}]}
{"op":"mcm","clk":"11539367590","pt":1719479705916,"mc":[{"id":"1.230178320","rc":[{"atb":[[2.22,6.54]],"id":43498435}],"con":true,"img":false}]}
{"op":"mcm","clk":"11539367688","pt":1719479707006,"mc":[{"id":"1.230178320","rc":[{"atb":[[2.2,6.54]],"id":61941199}],"con":true,"img":false}]}
{"op":"mcm","clk":"11539367704","pt":1719479707165,"mc":[{"id":"1.230178320","rc":[{"atb":[[2.24,6.54]],"id":62531723}],"con":true,"img":false}]}
{"op":"mcm","clk":"11539367731","pt":1719479707576,"mc":[{"id":"1.230178320","rc":[{"atb":[[2.14,6.54]],"id":69176305}],"con":true,"img":false}]}
{"op":"mcm","clk":"11539367846","pt":1719479709167,"mc":[{"id":"1.230178320","rc":[{"atb":[[2.14,6.54]],"id":61419789}],"con":true,"img":false}]}
{"op":"mcm","clk":"11539545480","pt":1719482910996,"mc":[{"id":"1.230178320","rc":[{"atb":[[1.02,22.63],[2.12,0],[2.14,6.54]],"id":69176305},{"atb":[[1.01,45.26],[2.22,6.54],[2.2,0]],"id":43498435},{"atb":[[1.02,22.63],[2.18,0],[2.2,6.54]],"id":61941199},{"atb":[[1.03,15.08],[2.12,0],[2.14,6.54]],"id":61419789},{"atb":[[2.24,6.54],[1.03,15.08],[2.22,0]],"id":62531723},{"atb":[[2.24,6.54],[1.01,45.26],[2.22,0]],"id":51643934}],"con":true,"img":false}]}
{"op":"mcm","clk":"11539545491","pt":1719482911201,"mc":[{"id":"1.230178320","rc":[{"atb":[[2.24,13.32]],"id":43498435},{"atb":[[2.16,8.54]],"id":69176305},{"atb":[[2.22,9.67]],"id":61941199},{"atb":[[2.16,9.39]],"id":61419789},{"atb":[[2.26,10.75]],"id":62531723},{"atb":[[2.26,13.44]],"id":51643934}],"con":true,"img":false}]}
{"op":"mcm","clk":"11539548350","pt":1719482954621,"mc":[{"id":"1.230178320","rc":[{"atb":[[2.24,3.16]],"id":62531723}],"con":true,"img":false}]}
{"op":"mcm","clk":"11539548357","pt":1719482954724,"mc":[{"id":"1.230178320","rc":[{"atb":[[2.2,3.16]],"id":61941199}],"con":true,"img":false}]}
{"op":"mcm","clk":"11539548372","pt":1719482954931,"mc":[{"id":"1.230178320","rc":[{"atb":[[2.14,3.16]],"id":69176305}],"con":true,"img":false}]}
{"op":"mcm","clk":"11539548384","pt":1719482955137,"mc":[{"id":"1.230178320","rc":[{"atb":[[2.24,3.16]],"id":51643934}],"con":true,"img":false}]}
{"op":"mcm","clk":"11539548394","pt":1719482955344,"mc":[{"id":"1.230178320","rc":[{"atb":[[2.22,3.16]],"id":43498435}],"con":true,"img":false}]}
{"op":"mcm","clk":"11539548408","pt":1719482955499,"mc":[{"id":"1.230178320","rc":[{"atb":[[2.14,3.16]],"id":61419789}],"con":true,"img":false}]}
{"op":"mcm","clk":"11539548537","pt":1719482957719,"mc":[{"id":"1.230178320","rc":[{"atb":[[2.24,3.38]],"id":61941199}],"con":true,"img":false}]}
{"op":"mcm","clk":"11539548551","pt":1719482958027,"mc":[{"id":"1.230178320","rc":[{"atb":[[2.18,3.38]],"id":69176305}],"con":true,"img":false}]}
{"op":"mcm","clk":"11539548561","pt":1719482958232,"mc":[{"id":"1.230178320","rc":[{"atb":[[2.28,3.38]],"id":62531723}],"con":true,"img":false}]}
{"op":"mcm","clk":"11539548633","pt":1719482959316,"mc":[{"id":"1.230178320","rc":[{"atb":[[2.28,3.38]],"id":51643934}],"con":true,"img":false}]}
{"op":"mcm","clk":"11539548670","pt":1719482959935,"mc":[{"id":"1.230178320","rc":[{"atb":[[2.26,3.38]],"id":43498435},{"atb":[[2.18,3.38]],"id":61419789}],"con":true,"img":false}]}
{"op":"mcm","clk":"11539553322","pt":1719483028216,"mc":[{"id":"1.230178320","rc":[{"atb":[[2.22,0]],"id":43498435},{"spn":76.13,"spf":"NaN","id":43498435},{"atb":[[2.14,0]],"id":69176305},{"spn":76.09,"spf":"NaN","id":69176305},{"atb":[[2.2,0]],"id":61941199},{"spn":76.12,"spf":"NaN","id":61941199},{"atb":[[2.14,0]],"id":61419789},{"spn":11.59,"spf":"NaN","id":61419789},{"atb":[[2.24,0]],"id":62531723},{"spn":76.14,"spf":"NaN","id":62531723},{"atb":[[2.24,0]],"id":51643934},{"spn":2.28,"spf":1.0,"id":51643934}],"con":true,"img":false}]}
{"op":"mcm","clk":"11539572922","pt":1719483322249,"mc":[{"id":"1.230178320","rc":[{"atb":[[2.26,6.54]],"id":43498435}],"con":true,"img":false}]}
{"op":"mcm","clk":"11539572967","pt":1719483322876,"mc":[{"id":"1.230178320","rc":[{"atb":[[2.18,6.54]],"id":69176305}],"con":true,"img":false}]}
{"op":"mcm","clk":"11539573007","pt":1719483323292,"mc":[{"id":"1.230178320","rc":[{"atb":[[2.28,6.54]],"id":51643934}],"con":true,"img":false}]}
{"op":"mcm","clk":"11539573095","pt":1719483324177,"mc":[{"id":"1.230178320","rc":[{"atb":[[2.24,6.54]],"id":61941199}],"con":true,"img":false}]}
{"op":"mcm","clk":"11539573111","pt":1719483324384,"mc":[{"id":"1.230178320","rc":[{"atb":[[2.28,6.54]],"id":62531723}],"con":true,"img":false}]}
{"op":"mcm","clk":"11539573220","pt":1719483325481,"mc":[{"id":"1.230178320","rc":[{"atb":[[2.18,6.54]],"id":61419789}],"con":true,"img":false}]}
{"op":"mcm","clk":"11539716197","pt":1719485221457,"mc":[{"id":"1.230178320","rc":[{"atl":[[36,8],[60,12]],"id":43498435},{"spn":19.13,"spf":"NaN","id":43498435},{"atl":[[32,8],[55,12]],"id":61941199},{"spn":17.12,"spf":"NaN","id":61941199},{"atl":[[42,12]],"id":61419789},{"atl":[[46,12],[27,8]],"id":62531723},{"spn":14.64,"spf":"NaN","id":62531723},{"atl":[[36,8],[60,12]],"id":51643934}],"con":true,"img":false}]}
{"op":"mcm","clk":"11539716204","pt":1719485221557,"mc":[{"id":"1.230178320","rc":[{"atl":[[25,8]],"id":61419789}],"con":true,"img":false}]}
{"op":"mcm","clk":"11539764714","pt":1719485856684,"mc":[{"id":"1.230178320","rc":[{"atb":[[3.3,6]],"id":43498435},{"spn":19.65,"spf":"NaN","id":43498435},{"atb":[[4.1,6]],"id":69176305},{"spn":77.05,"spf":"NaN","id":69176305},{"atb":[[3.1,6]],"id":61941199},{"spn":17.55,"spf":"NaN","id":61941199},{"atb":[[2.72,6]],"id":61419789},{"spn":11.86,"spf":"NaN","id":61419789},{"atb":[[2.86,6]],"id":62531723},{"spn":14.93,"spf":"NaN","id":62531723},{"atb":[[3.1,6]],"id":51643934},{"spn":3.1,"spf":1.0,"id":51643934}],"con":true,"img":false}]}
{"op":"mcm","clk":"11539764798","pt":1719485857979,"mc":[{"id":"1.230178320","rc":[{"atb":[[2.28,3.38]],"id":62531723}],"con":true,"img":false}]}
{"op":"mcm","clk":"11539764803","pt":1719485858078,"mc":[{"id":"1.230178320","rc":[{"atb":[[2.18,3.38]],"id":69176305},{"atb":[[2.26,3.38]],"id":43498435},{"atb":[[2.24,3.38]],"id":61941199},{"atb":[[2.28,3.38]],"id":51643934}],"con":true,"img":false}]}
{"op":"mcm","clk":"11539764815","pt":1719485858290,"mc":[{"id":"1.230178320","rc":[{"atb":[[2.18,3.38]],"id":61419789}],"con":true,"img":false}]}
{"op":"mcm","clk":"11539764827","pt":1719485858447,"mc":[{"id":"1.230178320","rc":[{"atb":[[2.88,3.16]],"id":62531723}],"con":true,"img":false}]}
{"op":"mcm","clk":"11539764843","pt":1719485858659,"mc":[{"id":"1.230178320","rc":[{"atb":[[2.74,3.16]],"id":61419789}],"con":true,"img":false}]}
{"op":"mcm","clk":"11539767270","pt":1719485896833,"mc":[{"id":"1.230178320","rc":[{"atb":[[2.28,0]],"id":62531723}],"con":true,"img":false}]}
{"op":"mcm","clk":"11539767291","pt":1719485897242,"mc":[{"id":"1.230178320","rc":[{"atb":[[2.26,0]],"id":43498435},{"atb":[[2.18,0]],"id":69176305},{"atb":[[2.24,0]],"id":61941199},{"atb":[[2.28,0]],"id":51643934}],"con":true,"img":false}]}
{"op":"mcm","clk":"11539767307","pt":1719485897516,"mc":[{"id":"1.230178320","rc":[{"atb":[[2.88,6.54]],"id":62531723}],"con":true,"img":false}]}
{"op":"mcm","clk":"11539810831","pt":1719486482543,"mc":[{"id":"1.230178320","marketDefinition":{"bspMarket":true,"turnInPlayEnabled":false,"persistenceEnabled":false,"marketBaseRate":5.0,"eventId":"33376062","eventTypeId":"4339","numberOfWinners":1,"bettingType":"ODDS","marketType":"WIN","marketTime":"2024-06-27T15:47:00.000Z","suspendTime":"2024-06-27T15:47:00.000Z","bspReconciled":false,"complete":true,"inPlay":false,"crossMatching":true,"runnersVoidable":false,"numberOfActiveRunners":6,"betDelay":0,"status":"OPEN","runners":[{"status":"ACTIVE","sortPriority":1,"id":51643934,"name":"1. Ballymac Frisby"},{"status":"ACTIVE","sortPriority":2,"id":62531723,"name":"2. Lynnway Touch"},{"status":"ACTIVE","sortPriority":3,"id":61941199,"name":"3. Kilara Thyestes"},{"status":"ACTIVE","sortPriority":4,"id":69176305,"name":"4. Moss Row Jemma"},{"status":"ACTIVE","sortPriority":5,"id":61419789,"name":"5. Buzzers Delight"},{"status":"ACTIVE","sortPriority":6,"id":43498435,"name":"6. Easy Cookie"}],"regulators":["MR_INT"],"venue":"Kinsley","countryCode":"GB","discountAllowed":true,"timezone":"Europe/London","openDate":"2024-06-27T13:36:00.000Z","version":5994643807,"name":"A2 462m","eventName":"Kinsley 27th Jun"},"rc":[{"atb":[[2.24,13.32],[1.01,45.27],[3.3,6]],"id":43498435},{"atl":[[36,8],[150,4],[60,12],[1000,0.16]],"id":43498435},{"spn":19.65,"spf":"NaN","id":43498435},{"atb":[[4.1,6],[1.02,22.63],[2.16,8.54]],"id":69176305},{"atl":[[150,4],[1000,0.16]],"id":69176305},{"spn":77.05,"spf":"NaN","id":69176305},{"atb":[[3.1,6],[2.22,9.67],[1.02,22.63]],"id":61941199},{"atl":[[32,8],[150,4],[55,12],[1000,0.16]],"id":61941199},{"spn":17.55,"spf":"NaN","id":61941199},{"atb":[[2.72,6],[2.74,3.16],[1.03,15.09],[2.18,3.38],[2.16,9.39]],"id":61419789},{"atl":[[150,4],[21,4],[42,12],[25,8],[1000,0.16]],"id":61419789},{"spn":11.87,"spf":"NaN","id":61419789},{"atb":[[2.88,6.54],[2.86,6],[1.03,15.09],[2.26,10.76]],"id":62531723},{"atl":[[150,4],[46,12],[27,8],[1000,0.16]],"id":62531723},{"spn":14.94,"spf":"NaN","id":62531723},{"spl":[[1.01,1]],"id":51643934},{"atb":[[1.01,45.27],[3.1,6],[2.26,13.45]],"id":51643934},{"atl":[[36,8],[150,4],[60,12],[1000,0.16]],"id":51643934},{"spn":3.1,"spf":1.0,"id":51643934}],"con":true,"img":true}]}
{"op":"mcm","clk":"11539997843","pt":1719488823296,"mc":[{"id":"1.230178320","rc":[{"atb":[[2.24,13.32],[1.01,45.27],[5,1]],"id":43498435},{"spn":20.5,"spf":"NaN","id":43498435},{"atb":[[4.3,1],[1.02,22.63],[2.16,8.54]],"id":69176305},{"spn":77.15,"spf":"NaN","id":69176305},{"atb":[[5,1],[2.22,9.67],[1.02,22.63]],"id":61941199},{"spn":18.5,"spf":"NaN","id":61941199},{"atb":[[2.74,3.16],[1.03,15.09],[5,1],[2.18,3.38],[2.16,9.39]],"id":61419789},{"spn":13.0,"spf":"NaN","id":61419789},{"atb":[[2.88,6.54],[1.03,15.09],[5,1],[2.26,10.76]],"id":62531723},{"spn":16.0,"spf":"NaN","id":62531723},{"atb":[[1.01,45.27],[3,1.13],[2.26,13.45]],"id":51643934}],"con":true,"img":false}]}
{"op":"mcm","clk":"11539999083","pt":1719488836944,"mc":[{"id":"1.230178320","rc":[{"atb":[[1.51,196.08]],"id":43498435},{"atb":[[1.51,196.08]],"id":69176305},{"atb":[[1.51,196.08]],"id":61941199},{"atb":[[1.51,196.08]],"id":51643934}],"con":true,"img":false}]}
{"op":"mcm","clk":"11540014449","pt":1719489000022,"mc":[{"id":"1.230178320","rc":[{"atl":[[270,2]],"id":69176305},{"atb":[[1.16,150]],"id":43498435},{"atl":[[500,2]],"id":43498435},{"atl":[[550,2]],"id":61941199},{"atl":[[560,2]],"id":61419789},{"atb":[[1.16,150]],"id":62531723},{"atl":[[390,2]],"id":62531723},{"atb":[[1.16,150]],"id":51643934},{"atl":[[370,2]],"id":51643934}],"con":true,"img":false}]}
{"op":"mcm","clk":"11540014458","pt":1719489000124,"mc":[{"id":"1.230178320","rc":[{"atb":[[1.16,150]],"id":69176305},{"atb":[[1.16,150]],"id":61941199},{"atb":[[1.16,150]],"id":61419789}],"con":true,"img":false}]}
{"op":"mcm","clk":"11540078907","pt":1719489791771,"mc":[{"id":"1.230178320","rc":[{"atb":[[2.12,89.29]],"id":43498435},{"atb":[[2.74,3.16],[1.51,196.08]],"id":61419789},{"atb":[[2.88,6.54],[1.51,196.08]],"id":62531723}],"con":true,"img":false}]}
{"op":"mcm","clk":"11540605558","pt":1719496368418,"mc":[{"id":"1.230178320","rc":[{"atb":[[2.24,13.33],[1.01,45.32],[6.4,1]],"id":43498435},{"atl":[[1000,0.16]],"id":43498435},{"spn":21.2,"spf":"NaN","id":43498435},{"atb":[[4.6,1],[1.02,22.66],[2.16,8.55]],"id":69176305},{"atl":[[1000,0.16]],"id":69176305},{"spn":77.3,"spf":"NaN","id":69176305},{"atb":[[2.22,9.68],[5.5,1],[1.02,22.66]],"id":61941199},{"atl":[[1000,0.16]],"id":61941199},{"spn":18.75,"spf":"NaN","id":61941199},{"atb":[[4,1],[2.74,3.16],[1.03,15.1],[2.18,3.38],[2.16,9.4]],"id":61419789},{"atl":[[1000,0.16]],"id":61419789},{"atb":[[2.88,6.54],[5,2],[1.03,15.1],[2.26,10.77]],"id":62531723},{"atl":[[1000,0.16]],"id":62531723},{"atb":[[1.01,45.32],[3.1,7],[2.26,13.46]],"id":51643934},{"atl":[[1000,0.16]],"id":51643934}],"con":true,"img":false}]}
{"op":"mcm","clk":"11540606532","pt":1719496378712,"mc":[{"id":"1.230178320","rc":[{"atb":[[2.12,89.29]],"id":61941199},{"atb":[[2.12,89.29]],"id":61419789}],"con":true,"img":false}]}
{"op":"mcm","clk":"11540683368","pt":1719497282516,"mc":[{"id":"1.230178320","marketDefinition":{"bspMarket":true,"turnInPlayEnabled":false,"persistenceEnabled":false,"marketBaseRate":5.0,"eventId":"33376062","eventTypeId":"4339","numberOfWinners":1,"bettingType":"ODDS","marketType":"WIN","marketTime":"2024-06-27T15:47:00.000Z","suspendTime":"2024-06-27T15:47:00.000Z","bspReconciled":false,"complete":true,"inPlay":false,"crossMatching":true,"runnersVoidable":false,"numberOfActiveRunners":6,"betDelay":0,"status":"OPEN","runners":[{"status":"ACTIVE","sortPriority":1,"id":51643934,"name":"1. Ballymac Frisby"},{"status":"ACTIVE","sortPriority":2,"id":62531723,"name":"2. Lynnway Touch"},{"status":"ACTIVE","sortPriority":3,"id":61941199,"name":"3. Kilara Thyestes"},{"status":"ACTIVE","sortPriority":4,"id":69176305,"name":"4. Moss Row Jemma"},{"status":"ACTIVE","sortPriority":5,"id":61419789,"name":"5. Buzzers Delight"},{"status":"ACTIVE","sortPriority":6,"id":43498435,"name":"6. Easy Cookie"}],"regulators":["MR_INT"],"venue":"Kinsley","countryCode":"GB","discountAllowed":true,"timezone":"Europe/London","openDate":"2024-06-27T13:36:00.000Z","version":5994643807,"name":"A2 462m","eventName":"Kinsley 27th Jun"},"rc":[{"atb":[[2.24,13.33],[6.4,1],[1.01,45.3],[5,1],[1.16,150],[2.12,89.29],[1.51,196.08],[3.3,6]],"id":43498435},{"atl":[[36,8],[150,4],[60,12],[500,2],[1000,0.16]],"id":43498435},{"spn":21.2,"spf":"NaN","id":43498435},{"atb":[[4.3,1],[4.6,1],[1.16,150],[4.1,6],[1.02,22.65],[1.51,196.08],[2.16,8.55]],"id":69176305},{"atl":[[270,2],[150,4],[1000,0.16]],"id":69176305},{"spn":77.3,"spf":"NaN","id":69176305},{"atb":[[5,1],[1.16,150],[3.1,6],[2.22,9.68],[5.5,1],[1.02,22.65],[2.12,89.29],[1.51,196.08]],"id":61941199},{"atl":[[32,8],[550,2],[150,4],[55,12],[1000,0.16]],"id":61941199},{"spn":18.75,"spf":"NaN","id":61941199},{"atb":[[4,1],[2.72,6],[5,1],[2.74,3.15],[1.16,150],[1.03,15.1],[2.12,89.29],[2.18,3.38],[1.51,196.08],[2.16,9.4]],"id":61419789},{"atl":[[560,2],[150,4],[21,4],[42,12],[25,8],[1000,0.16]],"id":61419789},{"spn":13.0,"spf":"NaN","id":61419789},{"atb":[[2.88,6.54],[5,2],[2.86,6],[1.16,150],[1.03,15.1],[2.26,10.76],[1.51,196.08]],"id":62531723},{"atl":[[150,4],[46,12],[390,2],[27,8],[1000,0.16]],"id":62531723},{"spn":16.0,"spf":"NaN","id":62531723},{"spl":[[1.01,1]],"id":51643934},{"atb":[[1.01,45.3],[1.16,150],[3.1,7],[3,1.13],[2.26,13.46],[1.51,196.08]],"id":51643934},{"atl":[[36,8],[150,4],[370,2],[60,12],[1000,0.16]],"id":51643934},{"spn":3.1,"spf":1.0,"id":51643934}],"con":true,"img":true}]}
{"op":"mcm","clk":"11540688523","pt":1719497292850,"mc":[{"id":"1.230178320","rc":[{"atb":[[2.24,13.33],[1.01,45.3]],"id":43498435},{"atb":[[1.02,22.65],[2.12,89.29],[2.16,8.55]],"id":69176305},{"atb":[[2.22,9.68],[1.02,22.65]],"id":61941199},{"atb":[[2.74,3.15],[1.03,15.1],[2.18,3.38],[2.16,9.4]],"id":61419789},{"atb":[[2.88,6.54],[1.03,15.1],[2.26,10.76]],"id":62531723},{"atb":[[1.01,45.3],[2.26,13.46]],"id":51643934}],"con":true,"img":false}]}
{"op":"mcm","clk":"11540730336","pt":1719497762749,"mc":[{"id":"1.230178320","rc":[{"spl":[[1.01,1]],"id":61419789},{"spn":5.0,"spf":1.0,"id":61419789}],"con":true,"img":false}]}
{"op":"mcm","clk":"11540814558","pt":1719498668561,"mc":[{"id":"1.230178320","rc":[{"atb":[[4.6,0]],"id":69176305},{"spn":77.15,"spf":"NaN","id":69176305},{"atb":[[6.4,0]],"id":43498435},{"spn":20.5,"spf":"NaN","id":43498435},{"atb":[[5.5,0]],"id":61941199},{"spn":18.5,"spf":"NaN","id":61941199},{"atb":[[4,0]],"id":61419789},{"atb":[[5,1]],"id":62531723},{"atb":[[3.1,6]],"id":51643934}],"con":true,"img":false}]}
{"op":"mcm","clk":"11540950800","pt":1719500365897,"mc":[{"id":"1.230178320","rc":[{"atb":[[4,2.5]],"id":43498435},{"atb":[[3.75,2.66]],"id":69176305},{"atb":[[4,2.5]],"id":61941199},{"atb":[[3.5,2.85]],"id":61419789},{"atb":[[4,2.5]],"id":62531723},{"atb":[[2.7,3.7]],"id":51643934}],"con":true,"img":false}]}
{"op":"mcm","clk":"11540952259","pt":1719500383125,"mc":[{"id":"1.230178320","rc":[{"atb":[[2.12,89.29]],"id":62531723}],"con":true,"img":false}]}
{"op":"mcm","clk":"11540991509","pt":1719500855972,"mc":[{"id":"1.230178320","rc":[{"atb":[[1.02,22.65],[2.16,8.55]],"id":69176305},{"atb":[[2.24,13.33],[1.01,45.31]],"id":43498435},{"atb":[[2.22,9.68],[1.02,22.65]],"id":61941199},{"atb":[[2.74,3.16],[1.03,15.1],[2.18,3.38],[2.16,9.4]],"id":61419789},{"atl":[[20,1.52]],"id":61419789},{"atb":[[2.88,6.54],[1.03,15.1],[2.26,10.77]],"id":62531723},{"atb":[[1.01,45.31],[2.26,13.46]],"id":51643934}],"con":true,"img":false}]}
{"op":"mcm","clk":"11540991538","pt":1719500856238,"mc":[{"id":"1.230178320","rc":[{"atl":[[34,1.7]],"id":51643934}],"con":true,"img":false}]}
{"op":"mcm","clk":"11541047451","pt":1719501545996,"mc":[{"id":"1.230178320","rc":[{"atb":[[3.6,4.57]],"id":51643934},{"spn":3.6,"spf":1.0,"id":51643934}],"con":true,"img":false}]}
{"op":"mcm","clk":"11541048224","pt":1719501555091,"mc":[{"id":"1.230178320","rc":[{"atb":[[3.6,0]],"id":51643934}],"con":true,"img":false}]}
{"op":"mcm","clk":"11541059247","pt":1719501682751,"mc":[{"id":"1.230178320","rc":[{"atb":[[5,2.57]],"id":69176305},{"spn":77.5,"spf":"NaN","id":69176305},{"spn":3.1,"spf":1.0,"id":51643934}],"con":true,"img":false}]}
{"op":"mcm","clk":"11541060660","pt":1719501700876,"mc":[{"id":"1.230178320","rc":[{"atb":[[5,0]],"id":69176305}],"con":true,"img":false}]}
{"op":"mcm","clk":"11541062728","pt":1719501726356,"mc":[{"id":"1.230178320","rc":[{"atb":[[3.65,12.5]],"id":43498435},{"atb":[[3.25,13.19]],"id":62531723}],"con":true,"img":false}]}
{"op":"mcm","clk":"11541062738","pt":1719501726464,"mc":[{"id":"1.230178320","rc":[{"atb":[[3.65,0]],"id":43498435},{"atb":[[3.25,0]],"id":62531723}],"con":true,"img":false}]}
{"op":"mcm","clk":"11541062871","pt":1719501728055,"mc":[{"id":"1.230178320","rc":[{"atl":[[190,4]],"id":43498435},{"atl":[[190,4]],"id":69176305},{"atl":[[190,4]],"id":61941199},{"atl":[[190,4]],"id":61419789},{"atl":[[190,4]],"id":62531723},{"atl":[[190,4]],"id":51643934}],"con":true,"img":false}]}
{"op":"mcm","clk":"11541063935","pt":1719501740492,"mc":[{"id":"1.230178320","rc":[{"atb":[[3.15,2]],"id":51643934}],"con":true,"img":false}]}
{"op":"mcm","clk":"11541063954","pt":1719501740695,"mc":[{"id":"1.230178320","rc":[{"atb":[[1.02,2]],"id":62531723}],"con":true,"img":false}]}
{"op":"mcm","clk":"11541063975","pt":1719501740902,"mc":[{"id":"1.230178320","rc":[{"atb":[[1.02,24.65]],"id":61941199}],"con":true,"img":false}]}
{"op":"mcm","clk":"11541063991","pt":1719501741106,"mc":[{"id":"1.230178320","rc":[{"atb":[[4.4,2]],"id":69176305}],"con":true,"img":false}]}
{"op":"mcm","clk":"11541064010","pt":1719501741268,"mc":[{"id":"1.230178320","rc":[{"atb":[[1.02,2]],"id":61419789}],"con":true,"img":false}]}
{"op":"mcm","clk":"11541064031","pt":1719501741474,"mc":[{"id":"1.230178320","rc":[{"atb":[[1.02,2]],"id":43498435}],"con":true,"img":false}]}
{"op":"mcm","clk":"11541088238","pt":1719502030873,"mc":[{"id":"1.230178320","rc":[{"atl":[[140,0.84]],"id":69176305},{"spn":72.2,"spf":"NaN","id":69176305},{"atl":[[19.5,0.84]],"id":61419789},{"atl":[[32,0.84]],"id":51643934},{"spn":3.15,"spf":1.0,"id":51643934}],"con":true,"img":false}]}
{"op":"mcm","clk":"11541097113","pt":1719502153974,"mc":[{"id":"1.230178320","rc":[{"atb":[[5,2.02]],"id":62531723}],"con":true,"img":false}]}
{"op":"mcm","clk":"11541110202","pt":1719502319844,"mc":[{"id":"1.230178320","rc":[{"atb":[[1.12,1.69]],"id":61941199},{"atb":[[1.08,1.69]],"id":51643934}],"con":true,"img":false}]}
{"op":"mcm","clk":"11541110230","pt":1719502320155,"mc":[{"id":"1.230178320","rc":[{"atb":[[4,8.5]],"id":43498435},{"atl":[[34,3.03]],"id":43498435},{"atb":[[1.12,1.69]],"id":61419789},{"atb":[[1.12,1.69]],"id":62531723},{"atl":[[32,2.84]],"id":51643934}],"con":true,"img":false}]}
{"op":"mcm","clk":"11541110258","pt":1719502320366,"mc":[{"id":"1.230178320","rc":[{"atb":[[2.74,57.47],[1.1,1.69]],"id":69176305},{"atl":[[32,3.23]],"id":69176305},{"atb":[[1.12,0.05],[3.65,9.69]],"id":61941199},{"atl":[[30,3.45]],"id":61941199},{"atb":[[3.45,3.85]],"id":61419789},{"atl":[[20,5.52]],"id":61419789},{"atb":[[3.85,6.55]],"id":62531723},{"atl":[[26,4]],"id":62531723},{"atb":[[2.32,75.76]],"id":51643934},{"atl":[[18,2]],"id":51643934}],"con":true,"img":false}]}
{"op":"mcm","clk":"11541110279","pt":1719502320574,"mc":[{"id":"1.230178320","rc":[{"atb":[[1.12,0]],"id":61941199},{"atb":[[1.12,0.05]],"id":62531723},{"atl":[[32,0.84]],"id":51643934}],"con":true,"img":false}]}
{"op":"mcm","clk":"11541110288","pt":1719502320677,"mc":[{"id":"1.230178320","rc":[{"atb":[[5.1,0.05]],"id":61941199}],"con":true,"img":false}]}
{"op":"mcm","clk":"11541110312","pt":1719502320940,"mc":[{"id":"1.230178320","rc":[{"atb":[[1.12,1.69]],"id":43498435},{"atb":[[1.08,0.09]],"id":51643934}],"con":true,"img":false}]}
{"op":"mcm","clk":"11541110339","pt":1719502321248,"mc":[{"id":"1.230178320","rc":[{"atb":[[1.12,0.05]],"id":61419789}],"con":true,"img":false}]}
{"op":"mcm","clk":"11541110351","pt":1719502321350,"mc":[{"id":"1.230178320","rc":[{"atb":[[1.12,0]],"id":62531723}],"con":true,"img":false}]}
{"op":"mcm","clk":"11541110360","pt":1719502321454,"mc":[{"id":"1.230178320","rc":[{"atb":[[5.1,0.05]],"id":62531723}],"con":true,"img":false}]}
{"op":"mcm","clk":"11541110372","pt":1719502321568,"mc":[{"id":"1.230178320","rc":[{"atb":[[1.1,0.06]],"id":69176305}],"con":true,"img":false}]}
{"op":"mcm","clk":"11541110393","pt":1719502321765,"mc":[{"id":"1.230178320","rc":[{"atb":[[1.08,0]],"id":51643934}],"con":true,"img":false}]}
{"op":"mcm","clk":"11541110405","pt":1719502321869,"mc":[{"id":"1.230178320","rc":[{"atb":[[3.2,0.09]],"id":51643934}],"con":true,"img":false}]}
{"op":"mcm","clk":"11541110429","pt":1719502322161,"mc":[{"id":"1.230178320","rc":[{"atb":[[1.12,0.05]],"id":43498435},{"atb":[[1.12,0]],"id":61419789}],"con":true,"img":false}]}
{"op":"mcm","clk":"11541110437","pt":1719502322241,"mc":[{"id":"1.230178320","rc":[{"atb":[[5.1,0.05]],"id":61419789}],"con":true,"img":false}]}
{"op":"mcm","clk":"11541110473","pt":1719502322656,"mc":[{"id":"1.230178320","rc":[{"atb":[[4.9,1]],"id":43498435},{"atl":[[20,1]],"id":43498435},{"atb":[[1.1,0]],"id":69176305},{"atb":[[4.3,1]],"id":61941199},{"atl":[[13.5,1]],"id":61941199},{"atl":[[9.4,1]],"id":61419789},{"atl":[[14.5,1]],"id":62531723}],"con":true,"img":false}]}
{"op":"mcm","clk":"11541110481","pt":1719502322758,"mc":[{"id":"1.230178320","rc":[{"atb":[[4.5,0.06]],"id":69176305}],"con":true,"img":false}]}
{"op":"mcm","clk":"11541110496","pt":1719502323068,"mc":[{"id":"1.230178320","rc":[{"atl":[[34,0]],"id":51643934}],"con":true,"img":false}]}
{"op":"mcm","clk":"11541110507","pt":1719502323171,"mc":[{"id":"1.230178320","rc":[{"atb":[[1.12,0]],"id":43498435}],"con":true,"img":false}]}
{"op":"mcm","clk":"11541110517","pt":1719502323274,"mc":[{"id":"1.230178320","rc":[{"atb":[[5.1,0.05]],"id":43498435}],"con":true,"img":false}]}
{"op":"mcm","clk":"11541110729","pt":1719502325975,"mc":[{"id":"1.230178320","rc":[{"atl":[[17.5,1.69]],"id":51643934}],"con":true,"img":false}]}
{"op":"mcm","clk":"11541110924","pt":1719502328375,"mc":[{"id":"1.230178320","rc":[{"atb":[[2.88,3.16]],"id":62531723}],"con":true,"img":false}]}
{"op":"mcm","clk":"11541111099","pt":1719502330349,"mc":[{"id":"1.230178320","rc":[{"atb":[[4,2.5],[4.3,8.5]],"id":43498435}],"con":true,"img":false}]}
{"op":"mcm","clk":"11541111249","pt":1719502332275,"mc":[{"id":"1.230178320","rc":[{"atl":[[17,2]],"id":51643934}],"con":true,"img":false}]}
{"op":"mcm","clk":"11541111262","pt":1719502332491,"mc":[{"id":"1.230178320","rc":[{"atl":[[17,4],[18,0]],"id":51643934}],"con":true,"img":false}]}
{"op":"mcm","clk":"11541111444","pt":1719502335082,"mc":[{"id":"1.230178320","rc":[{"atl":[[19.5,0.84]],"id":43498435},{"atl":[[14,0.84]],"id":62531723}],"con":true,"img":false}]}
{"op":"mcm","clk":"11541111452","pt":1719502335184,"mc":[{"id":"1.230178320","rc":[{"atl":[[17.5,0]],"id":51643934}],"con":true,"img":false}]}
{"op":"mcm","clk":"11541111459","pt":1719502335288,"mc":[{"id":"1.230178320","rc":[{"atl":[[140,0]],"id":69176305},{"atl":[[19.5,0]],"id":61419789},{"atl":[[32,0]],"id":51643934}],"con":true,"img":false}]}
{"op":"mcm","clk":"11541111595","pt":1719502337352,"mc":[{"id":"1.230178320","rc":[{"atl":[[17,2]],"id":51643934}],"con":true,"img":false}]}
{"op":"mcm","clk":"11541111611","pt":1719502337567,"mc":[{"id":"1.230178320","rc":[{"atl":[[17,0],[18,5.88]],"id":51643934}],"con":true,"img":false}]}
{"op":"mcm","clk":"11541111640","pt":1719502337972,"mc":[{"id":"1.230178320","rc":[{"atb":[[2.88,0]],"id":62531723}],"con":true,"img":false}]}
{"op":"mcm","clk":"11541111730","pt":1719502339269,"mc":[{"id":"1.230178320","rc":[{"atl":[[9.6,1]],"id":69176305},{"atl":[[19,1],[20,0]],"id":43498435},{"atl":[[13.5,0]],"id":61941199},{"atl":[[14,1.84]],"id":62531723},{"atl":[[5.7,1]],"id":51643934}],"con":true,"img":false}]}
{"op":"mcm","clk":"11541111740","pt":1719502339377,"mc":[{"id":"1.230178320","rc":[{"atl":[[34,0],[27,3.85]],"id":43498435},{"atl":[[13,1]],"id":61941199},{"atl":[[14.5,0]],"id":62531723}],"con":true,"img":false}]}
{"op":"mcm","clk":"11541111750","pt":1719502339479,"mc":[{"id":"1.230178320","rc":[{"atb":[[4.3,0],[4.6,6]],"id":43498435},{"atb":[[2.74,0],[3,50]],"id":69176305},{"atb":[[3.85,9.69],[3.65,0]],"id":61941199},{"atl":[[9.2,1],[9.4,0]],"id":61419789},{"atb":[[3.85,0],[4.1,6]],"id":62531723},{"atb":[[2.32,0],[2.42,70.42]],"id":51643934}],"con":true,"img":false}]}
{"op":"mcm","clk":"11541111787","pt":1719502339948,"mc":[{"id":"1.230178320","rc":[{"atl":[[5.6,2]],"id":51643934}],"con":true,"img":false}]}
{"op":"mcm","clk":"11541111993","pt":1719502342468,"mc":[{"id":"1.230178320","rc":[{"atl":[[5.6,4],[18,0]],"id":51643934}],"con":true,"img":false}]}
{"op":"mcm","clk":"11541112002","pt":1719502342569,"mc":[{"id":"1.230178320","rc":[{"atl":[[5.6,2],[16.5,6.45]],"id":51643934}],"con":true,"img":false}]}
{"op":"mcm","clk":"11541112008","pt":1719502342673,"mc":[{"id":"1.230178320","rc":[{"atl":[[5.6,6],[16.5,0]],"id":51643934}],"con":true,"img":false}]}
{"op":"mcm","clk":"11541112222","pt":1719502345195,"mc":[{"id":"1.230178320","rc":[{"atl":[[5.6,4]],"id":51643934}],"con":true,"img":false}]}
{"op":"mcm","clk":"11541112372","pt":1719502346983,"mc":[{"id":"1.230178320","rc":[{"atl":[[5.5,2]],"id":51643934}],"con":true,"img":false}]}
{"op":"mcm","clk":"11541112762","pt":1719502352178,"mc":[{"id":"1.230178320","rc":[{"atl":[[5.5,0]],"id":51643934}],"con":true,"img":false}]}
{"op":"mcm","clk":"11541112779","pt":1719502352387,"mc":[{"id":"1.230178320","rc":[{"atl":[[5.6,0],[16.5,6.45]],"id":51643934}],"con":true,"img":false}]}
{"op":"mcm","clk":"11541112894","pt":1719502354106,"mc":[{"id":"1.230178320","rc":[{"atl":[[5.8,3.75]],"id":51643934}],"con":true,"img":false}]}
{"op":"mcm","clk":"11541112903","pt":1719502354210,"mc":[{"id":"1.230178320","rc":[{"atl":[[5.6,2],[5.7,4.75]],"id":51643934}],"con":true,"img":false}]}
{"op":"mcm","clk":"11541112910","pt":1719502354315,"mc":[{"id":"1.230178320","rc":[{"atl":[[16.5,0],[5.8,0]],"id":51643934}],"con":true,"img":false}]}
{"op":"mcm","clk":"11541113288","pt":1719502359380,"mc":[{"id":"1.230178320","rc":[{"atl":[[5.6,0]],"id":51643934}],"con":true,"img":false}]}
{"op":"mcm","clk":"11541113297","pt":1719502359492,"mc":[{"id":"1.230178320","rc":[{"atl":[[16.5,6.45],[5.7,1]],"id":51643934}],"con":true,"img":false}]}
{"op":"mcm","clk":"11541113441","pt":1719502361202,"mc":[{"id":"1.230178320","rc":[{"atl":[[5.6,2]],"id":51643934}],"con":true,"img":false}]}
{"op":"mcm","clk":"11541113799","pt":1719502366424,"mc":[{"id":"1.230178320","rc":[{"atl":[[5.6,0]],"id":51643934}],"con":true,"img":false}]}
{"op":"mcm","clk":"11541113933","pt":1719502368300,"mc":[{"id":"1.230178320","rc":[{"atl":[[5.6,2]],"id":51643934}],"con":true,"img":false}]}
{"op":"mcm","clk":"11541113997","pt":1719502369193,"mc":[{"id":"1.230178320","rc":[{"atl":[[5.6,4],[16.5,0]],"id":51643934}],"con":true,"img":false}]}
{"op":"mcm","clk":"11541114004","pt":1719502369298,"mc":[{"id":"1.230178320","rc":[{"atl":[[5.6,2],[16.5,6.45]],"id":51643934}],"con":true,"img":false}]}
{"op":"mcm","clk":"11541114011","pt":1719502369402,"mc":[{"id":"1.230178320","rc":[{"atl":[[5.6,6],[16.5,0]],"id":51643934}],"con":true,"img":false}]}
{"op":"mcm","clk":"11541114357","pt":1719502373504,"mc":[{"id":"1.230178320","rc":[{"atl":[[5.6,4]],"id":51643934}],"con":true,"img":false}]}
{"op":"mcm","clk":"11541114373","pt":1719502373710,"mc":[{"id":"1.230178320","rc":[{"atl":[[5.6,0],[16.5,6.45]],"id":51643934}],"con":true,"img":false}]}
{"op":"mcm","clk":"11541114518","pt":1719502375417,"mc":[{"id":"1.230178320","rc":[{"atl":[[5.6,2]],"id":51643934}],"con":true,"img":false}]}
{"op":"mcm","clk":"11541114527","pt":1719502375521,"mc":[{"id":"1.230178320","rc":[{"atl":[[5.6,4],[16.5,0]],"id":51643934}],"con":true,"img":false}]}
{"op":"mcm","clk":"11541114914","pt":1719502380635,"mc":[{"id":"1.230178320","rc":[{"spn":7.05,"spf":"NaN","id":69176305},{"spn":12.05,"spf":"NaN","id":43498435},{"spn":9.05,"spf":"NaN","id":61941199},{"spn":5.0,"spf":1.0,"id":61419789},{"spn":9.55,"spf":"NaN","id":62531723},{"atl":[[5.6,2]],"id":51643934},{"spn":3.15,"spf":1.0,"id":51643934}],"con":true,"img":false}]}
{"op":"mcm","clk":"11541114925","pt":1719502380739,"mc":[{"id":"1.230178320","rc":[{"atl":[[5.6,0],[16.5,6.45]],"id":51643934}],"con":true,"img":false}]}
{"op":"mcm","clk":"11541115084","pt":1719502382811,"mc":[{"id":"1.230178320","rc":[{"atl":[[5.6,2]],"id":51643934}],"con":true,"img":false}]}
{"op":"mcm","clk":"11541115586","pt":1719502388032,"mc":[{"id":"1.230178320","rc":[{"atl":[[5.6,0]],"id":51643934}],"con":true,"img":false}]}
{"op":"mcm","clk":"11541115714","pt":1719502389840,"mc":[{"id":"1.230178320","rc":[{"atl":[[5.6,2]],"id":51643934}],"con":true,"img":false}]}
{"op":"mcm","clk":"11541115740","pt":1719502390214,"mc":[{"id":"1.230178320","rc":[{"atl":[[5.6,4]],"id":51643934}],"con":true,"img":false}]}
{"op":"mcm","clk":"11541115749","pt":1719502390355,"mc":[{"id":"1.230178320","rc":[{"atl":[[16.5,0]],"id":51643934}],"con":true,"img":false}]}
{"op":"mcm","clk":"11541115770","pt":1719502390627,"mc":[{"id":"1.230178320","rc":[{"atb":[[4.9,0]],"id":43498435},{"atb":[[4.3,0]],"id":61941199}],"con":true,"img":false}]}
{"op":"mcm","clk":"11541116064","pt":1719502395051,"mc":[{"id":"1.230178320","rc":[{"atl":[[5.6,2]],"id":51643934}],"con":true,"img":false}]}
{"op":"mcm","clk":"11541116074","pt":1719502395156,"mc":[{"id":"1.230178320","rc":[{"atl":[[5.6,0],[16.5,6.45]],"id":51643934}],"con":true,"img":false}]}
{"op":"mcm","clk":"11541116123","pt":1719502396035,"mc":[{"id":"1.230178320","rc":[{"atb":[[4.9,1]],"id":43498435},{"atb":[[4.3,1]],"id":61941199}],"con":true,"img":false}]}
{"op":"mcm","clk":"11541116176","pt":1719502396865,"mc":[{"id":"1.230178320","rc":[{"atl":[[5.6,2]],"id":51643934}],"con":true,"img":false}]}
{"op":"mcm","clk":"11541116185","pt":1719502396969,"mc":[{"id":"1.230178320","rc":[{"atl":[[5.6,4],[16.5,0]],"id":51643934}],"con":true,"img":false}]}
{"op":"mcm","clk":"11541116564","pt":1719502402033,"mc":[{"id":"1.230178320","rc":[{"atl":[[5.6,2]],"id":51643934}],"con":true,"img":false}]}
{"op":"mcm","clk":"11541116575","pt":1719502402141,"mc":[{"id":"1.230178320","rc":[{"atl":[[5.6,0],[16.5,6.45]],"id":51643934}],"con":true,"img":false}]}
{"op":"mcm","clk":"11541116698","pt":1719502403951,"mc":[{"id":"1.230178320","rc":[{"atl":[[5.6,2]],"id":51643934}],"con":true,"img":false}]}
{"op":"mcm","clk":"11541116707","pt":1719502404148,"mc":[{"id":"1.230178320","rc":[{"atl":[[5.6,4],[16.5,0]],"id":51643934}],"con":true,"img":false}]}
{"op":"mcm","clk":"11541117055","pt":1719502409151,"mc":[{"id":"1.230178320","rc":[{"atl":[[5.6,2]],"id":51643934}],"con":true,"img":false}]}
{"op":"mcm","clk":"11541117072","pt":1719502409358,"mc":[{"id":"1.230178320","rc":[{"atl":[[5.6,0],[16.5,6.45]],"id":51643934}],"con":true,"img":false}]}
{"op":"mcm","clk":"11541117191","pt":1719502411057,"mc":[{"id":"1.230178320","rc":[{"atl":[[5.6,2]],"id":51643934}],"con":true,"img":false}]}
{"op":"mcm","clk":"11541117389","pt":1719502413444,"mc":[{"id":"1.230178320","rc":[{"atl":[[5.6,4],[16.5,0]],"id":51643934}],"con":true,"img":false}]}
{"op":"mcm","clk":"11541117397","pt":1719502413546,"mc":[{"id":"1.230178320","rc":[{"atl":[[5.6,2],[16.5,6.45]],"id":51643934}],"con":true,"img":false}]}
{"op":"mcm","clk":"11541117407","pt":1719502413649,"mc":[{"id":"1.230178320","rc":[{"atl":[[5.6,6],[16.5,0]],"id":51643934}],"con":true,"img":false}]}
{"op":"mcm","clk":"11541117586","pt":1719502416183,"mc":[{"id":"1.230178320","rc":[{"atl":[[5.6,4]],"id":51643934}],"con":true,"img":false}]}
{"op":"mcm","clk":"11541117721","pt":1719502418147,"mc":[{"id":"1.230178320","rc":[{"atl":[[5.5,2]],"id":51643934}],"con":true,"img":false}]}
{"op":"mcm","clk":"11541118048","pt":1719502423371,"mc":[{"id":"1.230178320","rc":[{"atl":[[5.5,0]],"id":51643934}],"con":true,"img":false}]}
{"op":"mcm","clk":"11541118059","pt":1719502423468,"mc":[{"id":"1.230178320","rc":[{"atl":[[5.6,0],[16.5,6.45]],"id":51643934}],"con":true,"img":false}]}
{"op":"mcm","clk":"11541118229","pt":1719502425280,"mc":[{"id":"1.230178320","rc":[{"atl":[[5.6,2]],"id":51643934}],"con":true,"img":false}]}
{"op":"mcm","clk":"11541118277","pt":1719502425863,"mc":[{"id":"1.230178320","rc":[{"atb":[[4.5,0.91]],"id":69176305},{"atb":[[5.1,0.9]],"id":62531723},{"atl":[[13.5,0.84]],"id":62531723},{"atb":[[3.2,0.93]],"id":51643934},{"atl":[[5.5,0.84]],"id":51643934}],"con":true,"img":false}]}
{"op":"mcm","clk":"11541118655","pt":1719502430355,"mc":[{"id":"1.230178320","rc":[{"atl":[[5.6,0]],"id":51643934}],"con":true,"img":false}]}
{"op":"mcm","clk":"11541118697","pt":1719502430877,"mc":[{"id":"1.230178320","rc":[{"atl":[[5.5,0]],"id":51643934}],"con":true,"img":false}]}
{"op":"mcm","clk":"11541118804","pt":1719502432382,"mc":[{"id":"1.230178320","rc":[{"atl":[[5.6,2]],"id":51643934}],"con":true,"img":false}]}
{"op":"mcm","clk":"11541118819","pt":1719502432588,"mc":[{"id":"1.230178320","rc":[{"atl":[[5.6,4],[16.5,0]],"id":51643934}],"con":true,"img":false}]}
{"op":"mcm","clk":"11541118880","pt":1719502433372,"mc":[{"id":"1.230178320","rc":[{"atl":[[5.5,0.84]],"id":51643934}],"con":true,"img":false}]}
{"op":"mcm","clk":"11541119215","pt":1719502437608,"mc":[{"id":"1.230178320","rc":[{"atl":[[5.6,2]],"id":51643934}],"con":true,"img":false}]}
{"op":"mcm","clk":"11541119237","pt":1719502437765,"mc":[{"id":"1.230178320","rc":[{"atl":[[5.6,0],[5.7,9]],"id":51643934}],"con":true,"img":false}]}
{"op":"mcm","clk":"11541119294","pt":1719502438385,"mc":[{"id":"1.230178320","rc":[{"atl":[[5.5,0]],"id":51643934}],"con":true,"img":false}]}
{"op":"mcm","clk":"11541119379","pt":1719502439475,"mc":[{"id":"1.230178320","rc":[{"atl":[[5.6,2]],"id":51643934}],"con":true,"img":false}]}
{"op":"mcm","clk":"11541119387","pt":1719502439573,"mc":[{"id":"1.230178320","rc":[{"atb":[[4.9,0]],"id":43498435}],"con":true,"img":false}]}
{"op":"mcm","clk":"11541119399","pt":1719502439683,"mc":[{"id":"1.230178320","rc":[{"atb":[[4.3,0]],"id":61941199}],"con":true,"img":false}]}
{"op":"mcm","clk":"11541119492","pt":1719502440769,"mc":[{"id":"1.230178320","rc":[{"spn":9.3,"spf":"NaN","id":62531723},{"atl":[[5.5,0.84]],"id":51643934},{"spn":3.19,"spf":1.0,"id":51643934}],"con":true,"img":false}]}
{"op":"mcm","clk":"11541119517","pt":1719502441080,"mc":[{"id":"1.230178320","rc":[{"atb":[[3.2,0.84]],"id":51643934}],"con":true,"img":false}]}
{"op":"mcm","clk":"11541119536","pt":1719502441286,"mc":[{"id":"1.230178320","rc":[{"atb":[[5.1,0.84]],"id":62531723}],"con":true,"img":false}]}
{"op":"mcm","clk":"11541119561","pt":1719502441599,"mc":[{"id":"1.230178320","rc":[{"atb":[[5.1,0]],"id":61941199}],"con":true,"img":false}]}
{"op":"mcm","clk":"11541119591","pt":1719502441913,"mc":[{"id":"1.230178320","rc":[{"atb":[[4.5,0.84]],"id":69176305}],"con":true,"img":false}]}
{"op":"mcm","clk":"11541119613","pt":1719502442175,"mc":[{"id":"1.230178320","rc":[{"atb":[[5.1,0]],"id":61419789}],"con":true,"img":false}]}
{"op":"mcm","clk":"11541119631","pt":1719502442383,"mc":[{"id":"1.230178320","rc":[{"atb":[[5.1,0]],"id":43498435}],"con":true,"img":false}]}
{"op":"mcm","clk":"11541119640","pt":1719502442492,"mc":[{"id":"1.230178320","rc":[{"atb":[[4.6,0],[4.1,7]],"id":43498435}],"con":true,"img":false}]}
{"op":"mcm","clk":"11541119647","pt":1719502442589,"mc":[{"id":"1.230178320","rc":[{"atb":[[1.12,1.69]],"id":61419789},{"atb":[[1.08,1.69]],"id":51643934}],"con":true,"img":false}]}
{"op":"mcm","clk":"11541119668","pt":1719502442898,"mc":[{"id":"1.230178320","rc":[{"atb":[[1.12,1.69]],"id":61941199}],"con":true,"img":false}]}
{"op":"mcm","clk":"11541119676","pt":1719502443000,"mc":[{"id":"1.230178320","rc":[{"atb":[[1.1,1.69]],"id":69176305}],"con":true,"img":false}]}
{"op":"mcm","clk":"11541119691","pt":1719502443206,"mc":[{"id":"1.230178320","rc":[{"atb":[[1.12,1.69]],"id":43498435}],"con":true,"img":false}]}
{"op":"mcm","clk":"11541119709","pt":1719502443416,"mc":[{"id":"1.230178320","rc":[{"atb":[[1.12,0.05]],"id":61419789}],"con":true,"img":false}]}
{"op":"mcm","clk":"11541119719","pt":1719502443520,"mc":[{"id":"1.230178320","rc":[{"atb":[[1.12,0.05]],"id":61941199}],"con":true,"img":false}]}
{"op":"mcm","clk":"11541119746","pt":1719502443681,"mc":[{"id":"1.230178320","rc":[{"atb":[[1.12,0.05]],"id":43498435}],"con":true,"img":false}]}
{"op":"mcm","clk":"11541119755","pt":1719502443781,"mc":[{"id":"1.230178320","rc":[{"atb":[[1.08,0.09]],"id":51643934}],"con":true,"img":false}]}
{"op":"mcm","clk":"11541119779","pt":1719502444091,"mc":[{"id":"1.230178320","rc":[{"atb":[[1.1,0.06]],"id":69176305},{"atb":[[1.12,1.69]],"id":62531723}],"con":true,"img":false}]}
{"op":"mcm","clk":"11541119810","pt":1719502444400,"mc":[{"id":"1.230178320","rc":[{"atb":[[1.12,0]],"id":61419789}],"con":true,"img":false}]}
{"op":"mcm","clk":"11541119820","pt":1719502444504,"mc":[{"id":"1.230178320","rc":[{"atb":[[5.1,0.05]],"id":61419789}],"con":true,"img":false}]}
{"op":"mcm","clk":"11541119842","pt":1719502444812,"mc":[{"id":"1.230178320","rc":[{"atb":[[1.12,0]],"id":61941199},{"atl":[[5.6,0]],"id":51643934}],"con":true,"img":false}]}
{"op":"mcm","clk":"11541119854","pt":1719502444916,"mc":[{"id":"1.230178320","rc":[{"atb":[[5.1,0.05]],"id":61941199},{"atl":[[5.7,1]],"id":51643934}],"con":true,"img":false}]}
{"op":"mcm","clk":"11541119862","pt":1719502444978,"mc":[{"id":"1.230178320","rc":[{"atl":[[16.5,6.45]],"id":51643934}],"con":true,"img":false}]}
{"op":"mcm","clk":"11541119870","pt":1719502445174,"mc":[{"id":"1.230178320","rc":[{"atb":[[1.12,0]],"id":43498435}],"con":true,"img":false}]}
{"op":"mcm","clk":"11541119877","pt":1719502445275,"mc":[{"id":"1.230178320","rc":[{"atb":[[5.1,0.05]],"id":43498435},{"atl":[[5.5,0]],"id":51643934}],"con":true,"img":false}]}
{"op":"mcm","clk":"11541119903","pt":1719502445588,"mc":[{"id":"1.230178320","rc":[{"atb":[[1.08,0]],"id":51643934}],"con":true,"img":false}]}
{"op":"mcm","clk":"11541119908","pt":1719502445688,"mc":[{"id":"1.230178320","rc":[{"atb":[[3.2,0.93]],"id":51643934}],"con":true,"img":false}]}
{"op":"mcm","clk":"11541119938","pt":1719502446101,"mc":[{"id":"1.230178320","rc":[{"atb":[[1.1,0]],"id":69176305}],"con":true,"img":false}]}
{"op":"mcm","clk":"11541119947","pt":1719502446205,"mc":[{"id":"1.230178320","rc":[{"atb":[[4.5,0.91]],"id":69176305}],"con":true,"img":false}]}
{"op":"mcm","clk":"11541119977","pt":1719502446498,"mc":[{"id":"1.230178320","rc":[{"atb":[[1.12,0.05]],"id":62531723}],"con":true,"img":false}]}
{"op":"mcm","clk":"11541119986","pt":1719502446600,"mc":[{"id":"1.230178320","rc":[{"atl":[[5.6,2]],"id":51643934}],"con":true,"img":false}]}
{"op":"mcm","clk":"11541120007","pt":1719502446799,"mc":[{"id":"1.230178320","rc":[{"atb":[[1.12,0]],"id":62531723},{"atl":[[5.6,4],[16.5,0]],"id":51643934}],"con":true,"img":false}]}
{"op":"mcm","clk":"11541120014","pt":1719502446907,"mc":[{"id":"1.230178320","rc":[{"atb":[[5.1,0.9]],"id":62531723}],"con":true,"img":false}]}
{"op":"mcm","clk":"11541120122","pt":1719502448309,"mc":[{"id":"1.230178320","rc":[{"atl":[[5.5,0.84]],"id":51643934}],"con":true,"img":false}]}
{"op":"mcm","clk":"11541120404","pt":1719502451805,"mc":[{"id":"1.230178320","rc":[{"atl":[[5.6,2]],"id":51643934}],"con":true,"img":false}]}
{"op":"mcm","clk":"11541120413","pt":1719502451906,"mc":[{"id":"1.230178320","rc":[{"atl":[[5.6,0],[5.7,9]],"id":51643934}],"con":true,"img":false}]}
{"op":"mcm","clk":"11541120442","pt":1719502452320,"mc":[{"id":"1.230178320","rc":[{"atl":[[5.5,0]],"id":51643934}],"con":true,"img":false}]}
{"op":"mcm","clk":"11541120531","pt":1719502453709,"mc":[{"id":"1.230178320","rc":[{"atl":[[5.6,2]],"id":51643934}],"con":true,"img":false}]}
{"op":"mcm","clk":"11541120660","pt":1719502455314,"mc":[{"id":"1.230178320","rc":[{"atl":[[5.5,0.84]],"id":51643934}],"con":true,"img":false}]}
{"op":"mcm","clk":"11541120916","pt":1719502458903,"mc":[{"id":"1.230178320","rc":[{"atl":[[5.6,0]],"id":51643934}],"con":true,"img":false}]}
{"op":"mcm","clk":"11541120933","pt":1719502459106,"mc":[{"id":"1.230178320","rc":[{"atl":[[16.5,6.45],[5.7,1]],"id":51643934}],"con":true,"img":false}]}
{"op":"mcm","clk":"11541120945","pt":1719502459311,"mc":[{"id":"1.230178320","rc":[{"atl":[[5.5,0]],"id":51643934}],"con":true,"img":false}]}
{"op":"mcm","clk":"11541120953","pt":1719502459416,"mc":[{"id":"1.230178320","rc":[{"atb":[[3,0]],"id":69176305},{"atb":[[4.1,0],[3.8,10.77]],"id":62531723}],"con":true,"img":false}]}
{"op":"mcm","clk":"11541120958","pt":1719502459520,"mc":[{"id":"1.230178320","rc":[{"atb":[[2.84,54.35]],"id":69176305}],"con":true,"img":false}]}
{"op":"mcm","clk":"11541121044","pt":1719502460809,"mc":[{"id":"1.230178320","rc":[{"atl":[[5.6,2]],"id":51643934}],"con":true,"img":false}]}
{"op":"mcm","clk":"11541121177","pt":1719502462825,"mc":[{"id":"1.230178320","rc":[{"atl":[[5.5,0.84]],"id":51643934}],"con":true,"img":false}]}
{"op":"mcm","clk":"11541121373","pt":1719502465209,"mc":[{"id":"1.230178320","rc":[{"atb":[[3.2,19.53]],"id":51643934}],"con":true,"img":false}]}
{"op":"mcm","clk":"11541121422","pt":1719502466025,"mc":[{"id":"1.230178320","rc":[{"atb":[[3.9,4.84]],"id":62531723},{"atl":[[5.6,0]],"id":51643934}],"con":true,"img":false}]}
{"op":"mcm","clk":"11541121430","pt":1719502466132,"mc":[{"id":"1.230178320","rc":[{"atb":[[3.15,0],[3.25,6.35]],"id":51643934}],"con":true,"img":false}]}
{"op":"mcm","clk":"11541121440","pt":1719502466235,"mc":[{"id":"1.230178320","rc":[{"atb":[[3.25,8.35]],"id":51643934}],"con":true,"img":false}]}
{"op":"mcm","clk":"11541121486","pt":1719502466819,"mc":[{"id":"1.230178320","rc":[{"atb":[[3.3,0.84]],"id":51643934},{"atl":[[5.5,0]],"id":51643934}],"con":true,"img":false}]}
{"op":"mcm","clk":"11541121510","pt":1719502467248,"mc":[{"id":"1.230178320","rc":[{"atb":[[3.25,2]],"id":51643934}],"con":true,"img":false}]}
{"op":"mcm","clk":"11541121542","pt":1719502467633,"mc":[{"id":"1.230178320","rc":[{"atb":[[3.9,0]],"id":62531723}],"con":true,"img":false}]}
{"op":"mcm","clk":"11541121562","pt":1719502467944,"mc":[{"id":"1.230178320","rc":[{"atl":[[5.6,2]],"id":51643934}],"con":true,"img":false}]}
{"op":"mcm","clk":"11541121569","pt":1719502468046,"mc":[{"id":"1.230178320","rc":[{"atl":[[5.6,4],[16.5,0]],"id":51643934}],"con":true,"img":false}]}
{"op":"mcm","clk":"11541121596","pt":1719502468418,"mc":[{"id":"1.230178320","rc":[{"atb":[[4.5,1.73]],"id":69176305},{"atb":[[4.1,7.79]],"id":43498435},{"atb":[[4,3.29]],"id":61941199},{"atb":[[3.5,3.64]],"id":61419789},{"atb":[[4.1,1.6]],"id":62531723},{"atb":[[3.2,20.37]],"id":51643934}],"con":true,"img":false}]}
{"op":"mcm","clk":"11541121657","pt":1719502469336,"mc":[{"id":"1.230178320","rc":[{"atb":[[4.4,0]],"id":69176305}],"con":true,"img":false}]}
{"op":"mcm","clk":"11541121666","pt":1719502469438,"mc":[{"id":"1.230178320","rc":[{"atb":[[4.6,2]],"id":69176305}],"con":true,"img":false}]}
{"op":"mcm","clk":"11541121691","pt":1719502469747,"mc":[{"id":"1.230178320","rc":[{"atb":[[4.7,0.84]],"id":69176305}],"con":true,"img":false}]}
{"op":"mcm","clk":"11541121733","pt":1719502470226,"mc":[{"id":"1.230178320","rc":[{"atl":[[5.5,0.84]],"id":51643934}],"con":true,"img":false}]}
{"op":"mcm","clk":"11541121933","pt":1719502473119,"mc":[{"id":"1.230178320","rc":[{"atl":[[5.6,2]],"id":51643934}],"con":true,"img":false}]}
{"op":"mcm","clk":"11541121942","pt":1719502473227,"mc":[{"id":"1.230178320","rc":[{"atl":[[5.6,0],[5.7,9]],"id":51643934}],"con":true,"img":false}]}
{"op":"mcm","clk":"11541121951","pt":1719502473327,"mc":[{"id":"1.230178320","rc":[{"atl":[[18,5.88],[5.7,1]],"id":51643934}],"con":true,"img":false}]}
{"op":"mcm","clk":"11541121981","pt":1719502473744,"mc":[{"id":"1.230178320","rc":[{"atl":[[5.5,0]],"id":51643934}],"con":true,"img":false}]}
{"op":"mcm","clk":"11541122071","pt":1719502475031,"mc":[{"id":"1.230178320","rc":[{"atl":[[5.6,2]],"id":51643934}],"con":true,"img":false}]}
{"op":"mcm","clk":"11541122075","pt":1719502475133,"mc":[{"id":"1.230178320","rc":[{"atl":[[5.6,4],[18,0]],"id":51643934}],"con":true,"img":false}]}
{"op":"mcm","clk":"11541122254","pt":1719502477342,"mc":[{"id":"1.230178320","rc":[{"atl":[[5.5,0.84]],"id":51643934}],"con":true,"img":false}]}
{"op":"mcm","clk":"11541122448","pt":1719502480240,"mc":[{"id":"1.230178320","rc":[{"atl":[[5.6,2]],"id":51643934}],"con":true,"img":false}]}
{"op":"mcm","clk":"11541122456","pt":1719502480343,"mc":[{"id":"1.230178320","rc":[{"atl":[[5.6,0],[5.7,9]],"id":51643934}],"con":true,"img":false}]}
{"op":"mcm","clk":"11541122468","pt":1719502480448,"mc":[{"id":"1.230178320","rc":[{"atl":[[18,5.88],[5.7,1]],"id":51643934}],"con":true,"img":false}]}
{"op":"mcm","clk":"11541122499","pt":1719502480849,"mc":[{"id":"1.230178320","rc":[{"atl":[[5.5,0]],"id":51643934}],"con":true,"img":false}]}
{"op":"mcm","clk":"11541122610","pt":1719502482244,"mc":[{"id":"1.230178320","rc":[{"atl":[[5.6,2]],"id":51643934}],"con":true,"img":false}]}
{"op":"mcm","clk":"11541122635","pt":1719502482552,"mc":[{"id":"1.230178320","rc":[{"atb":[[3.2,19.53]],"id":51643934}],"con":true,"img":false}]}
{"op":"mcm","clk":"11541122807","pt":1719502484832,"mc":[{"id":"1.230178320","rc":[{"atl":[[5.5,0.84]],"id":51643934}],"con":true,"img":false}]}
{"op":"mcm","clk":"11541122989","pt":1719502487458,"mc":[{"id":"1.230178320","rc":[{"atl":[[5.6,0]],"id":51643934}],"con":true,"img":false}]}
{"op":"mcm","clk":"11541123017","pt":1719502487870,"mc":[{"id":"1.230178320","rc":[{"atl":[[5.5,0]],"id":51643934}],"con":true,"img":false}]}
{"op":"mcm","clk":"11541123131","pt":1719502489366,"mc":[{"id":"1.230178320","rc":[{"atl":[[5.6,2]],"id":51643934}],"con":true,"img":false}]}
{"op":"mcm","clk":"11541123145","pt":1719502489573,"mc":[{"id":"1.230178320","rc":[{"atl":[[5.6,4],[18,0]],"id":51643934}],"con":true,"img":false}]}
{"op":"mcm","clk":"11541123155","pt":1719502489675,"mc":[{"id":"1.230178320","rc":[{"atl":[[5.6,2],[18,5.88]],"id":51643934}],"con":true,"img":false}]}
{"op":"mcm","clk":"11541123322","pt":1719502491754,"mc":[{"id":"1.230178320","rc":[{"atl":[[5.6,4],[18,0]],"id":51643934}],"con":true,"img":false}]}
{"op":"mcm","clk":"11541123330","pt":1719502491862,"mc":[{"id":"1.230178320","rc":[{"atl":[[5.6,2],[18,5.88]],"id":51643934}],"con":true,"img":false}]}
{"op":"mcm","clk":"11541123363","pt":1719502492366,"mc":[{"id":"1.230178320","rc":[{"atl":[[5.5,0.84]],"id":51643934}],"con":true,"img":false}]}
{"op":"mcm","clk":"11541123374","pt":1719502492470,"mc":[{"id":"1.230178320","rc":[{"atl":[[5.6,4],[18,0]],"id":51643934}],"con":true,"img":false}]}
{"op":"mcm","clk":"11541123383","pt":1719502492573,"mc":[{"id":"1.230178320","rc":[{"atl":[[5.6,2],[5.7,6.88]],"id":51643934}],"con":true,"img":false}]}
{"op":"mcm","clk":"11541123394","pt":1719502492675,"mc":[{"id":"1.230178320","rc":[{"atl":[[5.6,6],[5.7,1]],"id":51643934}],"con":true,"img":false}]}
{"op":"mcm","clk":"11541123403","pt":1719502492778,"mc":[{"id":"1.230178320","rc":[{"atl":[[5.6,2],[5.7,9]],"id":51643934}],"con":true,"img":false}]}
{"op":"mcm","clk":"11541123562","pt":1719502494586,"mc":[{"id":"1.230178320","rc":[{"atl":[[5.6,0]],"id":51643934}],"con":true,"img":false}]}
{"op":"mcm","clk":"11541123573","pt":1719502494794,"mc":[{"id":"1.230178320","rc":[{"atl":[[18,5.88],[5.7,1]],"id":51643934}],"con":true,"img":false}]}
{"op":"mcm","clk":"11541123623","pt":1719502495360,"mc":[{"id":"1.230178320","rc":[{"atl":[[5.5,0]],"id":51643934}],"con":true,"img":false}]}
{"op":"mcm","clk":"11541123713","pt":1719502496455,"mc":[{"id":"1.230178320","rc":[{"atl":[[5.6,2]],"id":51643934}],"con":true,"img":false}]}
{"op":"mcm","clk":"11541123726","pt":1719502496556,"mc":[{"id":"1.230178320","rc":[{"atl":[[5.6,4],[18,0]],"id":51643934}],"con":true,"img":false}]}
{"op":"mcm","clk":"11541123770","pt":1719502497066,"mc":[{"id":"1.230178320","rc":[{"atb":[[4.5,0.91]],"id":69176305}],"con":true,"img":false}]}
{"op":"mcm","clk":"11541123816","pt":1719502497687,"mc":[{"id":"1.230178320","rc":[{"atb":[[4.6,0]],"id":69176305}],"con":true,"img":false}]}
{"op":"mcm","clk":"11541123827","pt":1719502497790,"mc":[{"id":"1.230178320","rc":[{"atb":[[4.4,2]],"id":69176305}],"con":true,"img":false}]}
{"op":"mcm","clk":"11541123870","pt":1719502498459,"mc":[{"id":"1.230178320","rc":[{"atb":[[4.7,0]],"id":69176305}],"con":true,"img":false}]}
{"op":"mcm","clk":"11541123966","pt":1719502499798,"mc":[{"id":"1.230178320","rc":[{"atl":[[5.5,0.84]],"id":51643934}],"con":true,"img":false}]}
{"op":"mcm","clk":"11541124145","pt":1719502501980,"mc":[{"id":"1.230178320","rc":[{"atl":[[5.6,2]],"id":51643934},{"spn":3.29,"spf":1.0,"id":51643934}],"con":true,"img":false}]}
{"op":"mcm","clk":"11541124168","pt":1719502502187,"mc":[{"id":"1.230178320","rc":[{"atl":[[5.6,0],[5.7,9]],"id":51643934}],"con":true,"img":false}]}
{"op":"mcm","clk":"11541124176","pt":1719502502292,"mc":[{"id":"1.230178320","rc":[{"atl":[[18,5.88],[5.7,1]],"id":51643934}],"con":true,"img":false}]}
{"op":"mcm","clk":"11541124223","pt":1719502502869,"mc":[{"id":"1.230178320","rc":[{"atl":[[5.5,0]],"id":51643934}],"con":true,"img":false}]}
{"op":"mcm","clk":"11541124274","pt":1719502503483,"mc":[{"id":"1.230178320","rc":[{"atl":[[5.6,2]],"id":51643934}],"con":true,"img":false}]}
{"op":"mcm","clk":"11541124548","pt":1719502506774,"mc":[{"id":"1.230178320","rc":[{"atl":[[5.5,0.84]],"id":51643934}],"con":true,"img":false}]}
{"op":"mcm","clk":"11541124683","pt":1719502508676,"mc":[{"id":"1.230178320","rc":[{"atl":[[5.6,0]],"id":51643934}],"con":true,"img":false}]}
{"op":"mcm","clk":"11541124738","pt":1719502509393,"mc":[{"id":"1.230178320","rc":[{"atl":[[5.5,0]],"id":51643934}],"con":true,"img":false}]}
{"op":"mcm","clk":"11541124828","pt":1719502510581,"mc":[{"id":"1.230178320","rc":[{"atl":[[5.6,2]],"id":51643934}],"con":true,"img":false}]}
{"op":"mcm","clk":"11541124833","pt":1719502510684,"mc":[{"id":"1.230178320","rc":[{"atl":[[5.6,4],[18,0]],"id":51643934}],"con":true,"img":false}]}
{"op":"mcm","clk":"11541125096","pt":1719502514298,"mc":[{"id":"1.230178320","rc":[{"atl":[[5.5,0.84]],"id":51643934}],"con":true,"img":false}]}
{"op":"mcm","clk":"11541125201","pt":1719502515796,"mc":[{"id":"1.230178320","rc":[{"atl":[[5.6,2]],"id":51643934}],"con":true,"img":false}]}
{"op":"mcm","clk":"11541125209","pt":1719502515897,"mc":[{"id":"1.230178320","rc":[{"atl":[[5.6,0],[5.7,9]],"id":51643934}],"con":true,"img":false}]}
{"op":"mcm","clk":"11541125231","pt":1719502516103,"mc":[{"id":"1.230178320","rc":[{"atl":[[18,5.88],[5.7,1]],"id":51643934}],"con":true,"img":false}]}
{"op":"mcm","clk":"11541125250","pt":1719502516309,"mc":[{"id":"1.230178320","rc":[{"atl":[[5.5,0]],"id":51643934}],"con":true,"img":false}]}
{"op":"mcm","clk":"11541125347","pt":1719502517703,"mc":[{"id":"1.230178320","rc":[{"atl":[[5.6,2]],"id":51643934}],"con":true,"img":false}]}
{"op":"mcm","clk":"11541125442","pt":1719502518986,"mc":[{"id":"1.230178320","rc":[{"atl":[[5.6,4],[18,0]],"id":51643934}],"con":true,"img":false}]}
{"op":"mcm","clk":"11541125450","pt":1719502519088,"mc":[{"id":"1.230178320","rc":[{"atl":[[5.6,2],[18,5.88]],"id":51643934}],"con":true,"img":false}]}
{"op":"mcm","clk":"11541125457","pt":1719502519191,"mc":[{"id":"1.230178320","rc":[{"atl":[[5.6,6],[18,0]],"id":51643934}],"con":true,"img":false}]}
{"op":"mcm","clk":"11541125466","pt":1719502519294,"mc":[{"id":"1.230178320","rc":[{"atl":[[5.6,2],[18,5.88]],"id":51643934}],"con":true,"img":false}]}
{"op":"mcm","clk":"11541125470","pt":1719502519397,"mc":[{"id":"1.230178320","rc":[{"atl":[[5.6,8],[18,0]],"id":51643934}],"con":true,"img":false}]}
{"op":"mcm","clk":"11541125474","pt":1719502519499,"mc":[{"id":"1.230178320","rc":[{"atl":[[5.6,2],[18,5.88]],"id":51643934}],"con":true,"img":false}]}
{"op":"mcm","clk":"11541125482","pt":1719502519604,"mc":[{"id":"1.230178320","rc":[{"atl":[[5.6,10],[18,0]],"id":51643934}],"con":true,"img":false}]}
{"op":"mcm","clk":"11541125491","pt":1719502519705,"mc":[{"id":"1.230178320","rc":[{"atl":[[5.6,2],[18,5.88]],"id":51643934}],"con":true,"img":false}]}
{"op":"mcm","clk":"11541125500","pt":1719502519808,"mc":[{"id":"1.230178320","rc":[{"atl":[[5.6,10],[18,0]],"id":51643934}],"con":true,"img":false}]}
{"op":"mcm","clk":"11541125517","pt":1719502520013,"mc":[{"id":"1.230178320","rc":[{"atl":[[5.6,2],[18,5.88]],"id":51643934}],"con":true,"img":false}]}
{"op":"mcm","clk":"11541125532","pt":1719502520220,"mc":[{"id":"1.230178320","rc":[{"atl":[[5.6,10],[18,0]],"id":51643934}],"con":true,"img":false}]}
{"op":"mcm","clk":"11541125568","pt":1719502520788,"mc":[{"id":"1.230178320","rc":[{"atb":[[5.2,1.62]],"id":62531723},{"atl":[[1000,1.01]],"id":62531723}],"con":true,"img":false}]}
{"op":"mcm","clk":"11541125594","pt":1719502521095,"mc":[{"id":"1.230178320","rc":[{"atl":[[1000,1.01]],"id":43498435},{"atl":[[1000,1.01]],"id":61941199}],"con":true,"img":false}]}
{"op":"mcm","clk":"11541125611","pt":1719502521302,"mc":[{"id":"1.230178320","rc":[{"atl":[[5.5,0.84]],"id":51643934}],"con":true,"img":false}]}
{"op":"mcm","clk":"11541125622","pt":1719502521404,"mc":[{"id":"1.230178320","rc":[{"atb":[[5.2,1.62]],"id":61941199}],"con":true,"img":false}]}
{"op":"mcm","clk":"11541125646","pt":1719502521713,"mc":[{"id":"1.230178320","rc":[{"atl":[[9.4,0.89]],"id":69176305}],"con":true,"img":false}]}
{"op":"mcm","clk":"11541125694","pt":1719502522593,"mc":[{"id":"1.230178320","rc":[{"atb":[[5.1,2.53]],"id":62531723}],"con":true,"img":false}]}
{"op":"mcm","clk":"11541125700","pt":1719502522694,"mc":[{"id":"1.230178320","rc":[{"atl":[[1000,0.82]],"id":62531723}],"con":true,"img":false}]}
{"op":"mcm","clk":"11541125708","pt":1719502522897,"mc":[{"id":"1.230178320","rc":[{"atl":[[1000,0.84]],"id":61941199}],"con":true,"img":false}]}
{"op":"mcm","clk":"11541125713","pt":1719502523000,"mc":[{"id":"1.230178320","rc":[{"atl":[[5.6,8]],"id":51643934}],"con":true,"img":false}]}
{"op":"mcm","clk":"11541125721","pt":1719502523103,"mc":[{"id":"1.230178320","rc":[{"atb":[[5.2,0]],"id":62531723},{"atl":[[5.6,0],[5.7,9.85]],"id":51643934}],"con":true,"img":false}]}
{"op":"mcm","clk":"11541125728","pt":1719502523208,"mc":[{"id":"1.230178320","rc":[{"atb":[[5.1,1.68]],"id":61941199},{"atl":[[18,5.88],[5.7,1]],"id":51643934}],"con":true,"img":false}]}
{"op":"mcm","clk":"11541125743","pt":1719502523412,"mc":[{"id":"1.230178320","rc":[{"atl":[[1000,0.16]],"id":62531723}],"con":true,"img":false}]}
{"op":"mcm","clk":"11541125750","pt":1719502523513,"mc":[{"id":"1.230178320","rc":[{"atl":[[13,0.65]],"id":62531723}],"con":true,"img":false}]}
{"op":"mcm","clk":"11541125763","pt":1719502523719,"mc":[{"id":"1.230178320","rc":[{"atl":[[18.5,5.71],[26,0]],"id":62531723}],"con":true,"img":false}]}
{"op":"mcm","clk":"11541125778","pt":1719502523925,"mc":[{"id":"1.230178320","rc":[{"atl":[[1000,0.62]],"id":43498435},{"atb":[[5.2,0]],"id":61941199},{"atl":[[5.5,0]],"id":51643934}],"con":true,"img":false}]}
{"op":"mcm","clk":"11541125813","pt":1719502524289,"mc":[{"id":"1.230178320","rc":[{"atb":[[5.1,0.9]],"id":62531723}],"con":true,"img":false}]}
{"op":"mcm","clk":"11541125842","pt":1719502524597,"mc":[{"id":"1.230178320","rc":[{"atl":[[1000,0.16]],"id":61941199}],"con":true,"img":false}]}
{"op":"mcm","clk":"11541125856","pt":1719502524701,"mc":[{"id":"1.230178320","rc":[{"atl":[[12.5,0.67]],"id":61941199}],"con":true,"img":false}]}
{"op":"mcm","clk":"11541125864","pt":1719502524806,"mc":[{"id":"1.230178320","rc":[{"atl":[[5.6,2]],"id":51643934}],"con":true,"img":false}]}
{"op":"mcm","clk":"11541125872","pt":1719502524908,"mc":[{"id":"1.230178320","rc":[{"atl":[[5.6,4],[18,0]],"id":51643934}],"con":true,"img":false}]}
{"op":"mcm","clk":"11541125883","pt":1719502525011,"mc":[{"id":"1.230178320","rc":[{"atb":[[5.3,1.6]],"id":62531723}],"con":true,"img":false}]}
{"op":"mcm","clk":"11541125891","pt":1719502525114,"mc":[{"id":"1.230178320","rc":[{"atb":[[5.1,0.05]],"id":61941199}],"con":true,"img":false}]}
{"op":"mcm","clk":"11541125915","pt":1719502525423,"mc":[{"id":"1.230178320","rc":[{"atl":[[1000,0.16]],"id":43498435}],"con":true,"img":false}]}
{"op":"mcm","clk":"11541125924","pt":1719502525525,"mc":[{"id":"1.230178320","rc":[{"atl":[[18.5,0.45]],"id":43498435}],"con":true,"img":false}]}
{"op":"mcm","clk":"11541125945","pt":1719502525786,"mc":[{"id":"1.230178320","rc":[{"atb":[[5.3,1.6]],"id":61941199}],"con":true,"img":false}]}
{"op":"mcm","clk":"11541126131","pt":1719502528823,"mc":[{"id":"1.230178320","rc":[{"atl":[[5.5,0.84]],"id":51643934}],"con":true,"img":false}]}
{"op":"mcm","clk":"11541126216","pt":1719502530008,"mc":[{"id":"1.230178320","rc":[{"atl":[[5.6,2]],"id":51643934}],"con":true,"img":false}]}
{"op":"mcm","clk":"11541126221","pt":1719502530110,"mc":[{"id":"1.230178320","rc":[{"atl":[[5.6,0],[5.7,9]],"id":51643934}],"con":true,"img":false}]}
{"op":"mcm","clk":"11541126279","pt":1719502530832,"mc":[{"id":"1.230178320","rc":[{"atl":[[5.5,0]],"id":51643934}],"con":true,"img":false}]}
{"op":"mcm","clk":"11541126301","pt":1719502531106,"mc":[{"id":"1.230178320","rc":[{"atb":[[5.1,2.5]],"id":62531723}],"con":true,"img":false}]}
{"op":"mcm","clk":"11541126310","pt":1719502531208,"mc":[{"id":"1.230178320","rc":[{"atb":[[5.3,0]],"id":62531723}],"con":true,"img":false}]}
{"op":"mcm","clk":"11541126369","pt":1719502531930,"mc":[{"id":"1.230178320","rc":[{"atl":[[5.6,2]],"id":51643934}],"con":true,"img":false}]}
{"op":"mcm","clk":"11541126404","pt":1719502532204,"mc":[{"id":"1.230178320","rc":[{"atb":[[5.1,1.65]],"id":61941199}],"con":true,"img":false}]}
{"op":"mcm","clk":"11541126415","pt":1719502532299,"mc":[{"id":"1.230178320","rc":[{"atb":[[5.3,0]],"id":61941199}],"con":true,"img":false}]}
{"op":"mcm","clk":"11541126435","pt":1719502532509,"mc":[{"id":"1.230178320","rc":[{"atb":[[5.4,1.56]],"id":61941199}],"con":true,"img":false}]}
{"op":"mcm","clk":"11541126468","pt":1719502532819,"mc":[{"id":"1.230178320","rc":[{"atb":[[5.1,0.05]],"id":61941199}],"con":true,"img":false}]}
{"op":"mcm","clk":"11541126723","pt":1719502536335,"mc":[{"id":"1.230178320","rc":[{"atl":[[5.5,0.84]],"id":51643934}],"con":true,"img":false}]}
{"op":"mcm","clk":"11541126770","pt":1719502537118,"mc":[{"id":"1.230178320","rc":[{"atl":[[5.6,0]],"id":51643934}],"con":true,"img":false}]}
{"op":"mcm","clk":"11541126780","pt":1719502537214,"mc":[{"id":"1.230178320","rc":[{"atl":[[18,5.88],[5.7,1]],"id":51643934}],"con":true,"img":false}]}
{"op":"mcm","clk":"11541126815","pt":1719502537831,"mc":[{"id":"1.230178320","rc":[{"atl":[[5.5,0]],"id":51643934}],"con":true,"img":false}]}
{"op":"mcm","clk":"11541126886","pt":1719502538923,"mc":[{"id":"1.230178320","rc":[{"atl":[[5.6,2]],"id":51643934}],"con":true,"img":false}]}
{"op":"mcm","clk":"11541126905","pt":1719502539122,"mc":[{"id":"1.230178320","rc":[{"atl":[[5.6,4],[18,0]],"id":51643934}],"con":true,"img":false}]}
{"op":"mcm","clk":"11541127140","pt":1719502543336,"mc":[{"id":"1.230178320","rc":[{"atl":[[5.5,0.84]],"id":51643934}],"con":true,"img":false}]}
{"op":"mcm","clk":"11541127157","pt":1719502543643,"mc":[{"id":"1.230178320","rc":[{"atb":[[5.1,1.62]],"id":61941199}],"con":true,"img":false}]}
{"op":"mcm","clk":"11541127165","pt":1719502543748,"mc":[{"id":"1.230178320","rc":[{"atb":[[5.4,0]],"id":61941199}],"con":true,"img":false}]}
{"op":"mcm","clk":"11541127175","pt":1719502543903,"mc":[{"id":"1.230178320","rc":[{"atb":[[5.5,1.54]],"id":61941199}],"con":true,"img":false}]}
{"op":"mcm","clk":"11541127189","pt":1719502544212,"mc":[{"id":"1.230178320","rc":[{"atl":[[5.6,2]],"id":51643934}],"con":true,"img":false}]}
{"op":"mcm","clk":"11541127194","pt":1719502544314,"mc":[{"id":"1.230178320","rc":[{"atb":[[5.1,0.05]],"id":61941199},{"atl":[[5.6,0],[5.7,9]],"id":51643934}],"con":true,"img":false}]}
{"op":"mcm","clk":"11541127220","pt":1719502544933,"mc":[{"id":"1.230178320","rc":[{"atl":[[5.5,0]],"id":51643934}],"con":true,"img":false}]}
{"op":"mcm","clk":"11541127292","pt":1719502546069,"mc":[{"id":"1.230178320","rc":[{"atl":[[5.6,2]],"id":51643934}],"con":true,"img":false}]}
{"op":"mcm","clk":"11541127483","pt":1719502548860,"mc":[{"id":"1.230178320","rc":[{"atb":[[4,2.5]],"id":61941199}],"con":true,"img":false}]}
{"op":"mcm","clk":"11541127581","pt":1719502550149,"mc":[{"id":"1.230178320","rc":[{"atl":[[1000,1.16]],"id":51643934}],"con":true,"img":false}]}
{"op":"mcm","clk":"11541127597","pt":1719502550355,"mc":[{"id":"1.230178320","rc":[{"atl":[[1000,0.19]],"id":51643934}],"con":true,"img":false}]}
{"op":"mcm","clk":"11541127609","pt":1719502550559,"mc":[{"id":"1.230178320","rc":[{"atl":[[1000,0.16]],"id":51643934}],"con":true,"img":false}]}
{"op":"mcm","clk":"11541127616","pt":1719502550663,"mc":[{"id":"1.230178320","rc":[{"atl":[[5.5,0.03]],"id":51643934}],"con":true,"img":false}]}
{"op":"mcm","clk":"11541127619","pt":1719502550724,"mc":[{"id":"1.230178320","rc":[{"atl":[[5.5,0.87]],"id":51643934}],"con":true,"img":false}]}
{"op":"mcm","clk":"11541127645","pt":1719502551232,"mc":[{"id":"1.230178320","rc":[{"atl":[[5.6,0]],"id":51643934}],"con":true,"img":false}]}
{"op":"mcm","clk":"11541127653","pt":1719502551337,"mc":[{"id":"1.230178320","rc":[{"atl":[[18,5.88],[5.7,1]],"id":51643934}],"con":true,"img":false}]}
{"op":"mcm","clk":"11541127696","pt":1719502551956,"mc":[{"id":"1.230178320","rc":[{"atl":[[5.5,0.03]],"id":51643934}],"con":true,"img":false}]}
{"op":"mcm","clk":"11541127817","pt":1719502553561,"mc":[{"id":"1.230178320","rc":[{"atl":[[5.6,2]],"id":51643934}],"con":true,"img":false}]}
{"op":"mcm","clk":"11541127825","pt":1719502553664,"mc":[{"id":"1.230178320","rc":[{"atl":[[5.6,4],[18,0]],"id":51643934}],"con":true,"img":false}]}
{"op":"mcm","clk":"11541127838","pt":1719502553830,"mc":[{"id":"1.230178320","rc":[{"atb":[[5.5,0]],"id":61941199}],"con":true,"img":false}]}
{"op":"mcm","clk":"11541127864","pt":1719502554132,"mc":[{"id":"1.230178320","rc":[{"atb":[[5.2,1.54]],"id":61941199}],"con":true,"img":false}]}
{"op":"mcm","clk":"11541128155","pt":1719502557850,"mc":[{"id":"1.230178320","rc":[{"atl":[[5.5,0.87]],"id":51643934}],"con":true,"img":false}]}
{"op":"mcm","clk":"11541128225","pt":1719502558729,"mc":[{"id":"1.230178320","rc":[{"atl":[[5.6,2]],"id":51643934}],"con":true,"img":false}]}
{"op":"mcm","clk":"11541128232","pt":1719502558833,"mc":[{"id":"1.230178320","rc":[{"atl":[[5.7,9]],"id":51643934}],"con":true,"img":false}]}
{"op":"mcm","clk":"11541128243","pt":1719502558946,"mc":[{"id":"1.230178320","rc":[{"atl":[[5.6,0]],"id":51643934}],"con":true,"img":false}]}
{"op":"mcm","clk":"11541128255","pt":1719502559038,"mc":[{"id":"1.230178320","rc":[{"atl":[[18,5.88]],"id":51643934}],"con":true,"img":false}]}
{"op":"mcm","clk":"11541128263","pt":1719502559142,"mc":[{"id":"1.230178320","rc":[{"atl":[[5.7,1]],"id":51643934}],"con":true,"img":false}]}
{"op":"mcm","clk":"11541128286","pt":1719502559464,"mc":[{"id":"1.230178320","rc":[{"atl":[[5.5,0.03]],"id":51643934}],"con":true,"img":false}]}
{"op":"mcm","clk":"11541128364","pt":1719502560539,"mc":[{"id":"1.230178320","rc":[{"atl":[[5.6,2]],"id":51643934}],"con":true,"img":false}]}
{"op":"mcm","clk":"11541128435","pt":1719502561465,"mc":[{"id":"1.230178320","rc":[{"atl":[[5.6,4],[18,0]],"id":51643934}],"con":true,"img":false}]}
{"op":"mcm","clk":"11541128617","pt":1719502564050,"mc":[{"id":"1.230178320","rc":[{"spn":11.8,"spf":"NaN","id":43498435},{"spn":6.95,"spf":"NaN","id":69176305},{"atb":[[5.1,1.6],[5.2,0]],"id":61941199},{"spn":8.8,"spf":"NaN","id":61941199},{"spn":9.05,"spf":"NaN","id":62531723}],"con":true,"img":false}]}
{"op":"mcm","clk":"11541128645","pt":1719502564459,"mc":[{"id":"1.230178320","rc":[{"atb":[[3.2,19.44]],"id":51643934}],"con":true,"img":false}]}
{"op":"mcm","clk":"11541128676","pt":1719502564871,"mc":[{"id":"1.230178320","rc":[{"atb":[[5.1,1.54]],"id":61941199},{"atl":[[5.5,0.87]],"id":51643934}],"con":true,"img":false}]}
{"op":"mcm","clk":"11541128702","pt":1719502565180,"mc":[{"id":"1.230178320","rc":[{"atb":[[4.5,0.84]],"id":69176305}],"con":true,"img":false}]}
{"op":"mcm","clk":"11541128719","pt":1719502565439,"mc":[{"id":"1.230178320","rc":[{"atb":[[5.1,0]],"id":61419789}],"con":true,"img":false}]}
{"op":"mcm","clk":"11541128753","pt":1719502565851,"mc":[{"id":"1.230178320","rc":[{"atb":[[5.1,0]],"id":43498435},{"atl":[[5.6,2]],"id":51643934}],"con":true,"img":false}]}
{"op":"mcm","clk":"11541128766","pt":1719502565952,"mc":[{"id":"1.230178320","rc":[{"atl":[[5.6,0],[5.7,9]],"id":51643934}],"con":true,"img":false}]}
{"op":"mcm","clk":"11541128772","pt":1719502566058,"mc":[{"id":"1.230178320","rc":[{"atl":[[18,5.88],[5.7,1]],"id":51643934}],"con":true,"img":false}]}
{"op":"mcm","clk":"11541128781","pt":1719502566161,"mc":[{"id":"1.230178320","rc":[{"atb":[[1.12,1.69]],"id":61419789}],"con":true,"img":false}]}
{"op":"mcm","clk":"11541128788","pt":1719502566264,"mc":[{"id":"1.230178320","rc":[{"atb":[[1.1,1.69]],"id":69176305}],"con":true,"img":false}]}
{"op":"mcm","clk":"11541128804","pt":1719502566471,"mc":[{"id":"1.230178320","rc":[{"atb":[[1.12,1.69]],"id":61941199},{"atl":[[5.5,0.03]],"id":51643934}],"con":true,"img":false}]}
{"op":"mcm","clk":"11541128815","pt":1719502566574,"mc":[{"id":"1.230178320","rc":[{"atb":[[1.12,1.69]],"id":43498435}],"con":true,"img":false}]}
{"op":"mcm","clk":"11541128837","pt":1719502566738,"mc":[{"id":"1.230178320","rc":[{"atb":[[1.08,1.69]],"id":51643934}],"con":true,"img":false}]}
{"op":"mcm","clk":"11541128849","pt":1719502566835,"mc":[{"id":"1.230178320","rc":[{"atb":[[1.1,0.06]],"id":69176305}],"con":true,"img":false}]}
{"op":"mcm","clk":"11541128860","pt":1719502567038,"mc":[{"id":"1.230178320","rc":[{"atb":[[1.12,0.05]],"id":61941199}],"con":true,"img":false}]}
{"op":"mcm","clk":"11541128882","pt":1719502567349,"mc":[{"id":"1.230178320","rc":[{"atb":[[1.12,0.05]],"id":43498435},{"atb":[[1.12,0.05]],"id":61419789}],"con":true,"img":false}]}
{"op":"mcm","clk":"11541128899","pt":1719502567556,"mc":[{"id":"1.230178320","rc":[{"atl":[[5.6,2]],"id":51643934}],"con":true,"img":false}]}
{"op":"mcm","clk":"11541128953","pt":1719502567663,"mc":[{"id":"1.230178320","rc":[{"atb":[[5.1,2.44]],"id":62531723},{"atb":[[1.08,0.09]],"id":51643934},{"atl":[[5.6,4],[18,0]],"id":51643934}],"con":true,"img":false}]}
{"op":"mcm","clk":"11541128963","pt":1719502567766,"mc":[{"id":"1.230178320","rc":[{"atl":[[5.7,6.88]],"id":51643934}],"con":true,"img":false}]}
{"op":"mcm","clk":"11541128972","pt":1719502567879,"mc":[{"id":"1.230178320","rc":[{"atl":[[5.6,2]],"id":51643934}],"con":true,"img":false}]}
{"op":"mcm","clk":"11541128994","pt":1719502568079,"mc":[{"id":"1.230178320","rc":[{"atb":[[1.1,0]],"id":69176305}],"con":true,"img":false}]}
{"op":"mcm","clk":"11541129003","pt":1719502568178,"mc":[{"id":"1.230178320","rc":[{"atb":[[4.5,0.91]],"id":69176305}],"con":true,"img":false}]}
{"op":"mcm","clk":"11541129043","pt":1719502568442,"mc":[{"id":"1.230178320","rc":[{"atb":[[1.12,0]],"id":61941199}],"con":true,"img":false}]}
{"op":"mcm","clk":"11541129054","pt":1719502568548,"mc":[{"id":"1.230178320","rc":[{"atb":[[5.2,0.05]],"id":61941199}],"con":true,"img":false}]}
{"op":"mcm","clk":"11541129081","pt":1719502568856,"mc":[{"id":"1.230178320","rc":[{"atb":[[1.12,0]],"id":43498435}],"con":true,"img":false}]}
{"op":"mcm","clk":"11541129091","pt":1719502568964,"mc":[{"id":"1.230178320","rc":[{"atb":[[5.1,0.05]],"id":43498435}],"con":true,"img":false}]}
{"op":"mcm","clk":"11541129115","pt":1719502569374,"mc":[{"id":"1.230178320","rc":[{"atb":[[1.12,0]],"id":61419789}],"con":true,"img":false}]}
{"op":"mcm","clk":"11541129123","pt":1719502569478,"mc":[{"id":"1.230178320","rc":[{"atb":[[5.1,0.05]],"id":61419789}],"con":true,"img":false}]}
{"op":"mcm","clk":"11541129152","pt":1719502569838,"mc":[{"id":"1.230178320","rc":[{"atb":[[1.08,0]],"id":51643934}],"con":true,"img":false}]}
{"op":"mcm","clk":"11541129158","pt":1719502569941,"mc":[{"id":"1.230178320","rc":[{"atb":[[3.35,0.09]],"id":51643934}],"con":true,"img":false}]}
{"op":"mcm","clk":"11541129170","pt":1719502570255,"mc":[{"id":"1.230178320","rc":[{"atb":[[1.12,1.69]],"id":62531723}],"con":true,"img":false}]}
{"op":"mcm","clk":"11541129192","pt":1719502570561,"mc":[{"id":"1.230178320","rc":[{"atb":[[1.12,0.05]],"id":62531723}],"con":true,"img":false}]}
{"op":"mcm","clk":"11541129215","pt":1719502570974,"mc":[{"id":"1.230178320","rc":[{"atb":[[1.12,0]],"id":62531723}],"con":true,"img":false}]}
{"op":"mcm","clk":"11541129222","pt":1719502571075,"mc":[{"id":"1.230178320","rc":[{"atb":[[5.2,0.05]],"id":62531723}],"con":true,"img":false}]}
{"op":"mcm","clk":"11541129285","pt":1719502571850,"mc":[{"id":"1.230178320","rc":[{"atl":[[5.5,0.87]],"id":51643934}],"con":true,"img":false}]}
{"op":"mcm","clk":"11541129365","pt":1719502572779,"mc":[{"id":"1.230178320","rc":[{"atl":[[5.6,0]],"id":51643934}],"con":true,"img":false}]}
{"op":"mcm","clk":"11541129383","pt":1719502572983,"mc":[{"id":"1.230178320","rc":[{"atl":[[18,5.88],[5.7,1]],"id":51643934}],"con":true,"img":false}]}
{"op":"mcm","clk":"11541129423","pt":1719502573346,"mc":[{"id":"1.230178320","rc":[{"atl":[[5.5,0.03]],"id":51643934}],"con":true,"img":false}]}
{"op":"mcm","clk":"11541129591","pt":1719502575155,"mc":[{"id":"1.230178320","rc":[{"atl":[[5.6,2]],"id":51643934}],"con":true,"img":false}]}
{"op":"mcm","clk":"11541129600","pt":1719502575259,"mc":[{"id":"1.230178320","rc":[{"atl":[[5.6,4],[18,0]],"id":51643934}],"con":true,"img":false}]}
{"op":"mcm","clk":"11541129827","pt":1719502577993,"mc":[{"id":"1.230178320","rc":[{"atb":[[4.9,1]],"id":43498435},{"atb":[[4.3,1]],"id":61941199}],"con":true,"img":false}]}
{"op":"mcm","clk":"11541129928","pt":1719502579281,"mc":[{"id":"1.230178320","rc":[{"atl":[[5.5,0.87]],"id":51643934}],"con":true,"img":false}]}
{"op":"mcm","clk":"11541129998","pt":1719502580467,"mc":[{"id":"1.230178320","rc":[{"atl":[[5.6,2]],"id":51643934}],"con":true,"img":false}]}
{"op":"mcm","clk":"11541130007","pt":1719502580572,"mc":[{"id":"1.230178320","rc":[{"atl":[[5.6,0],[5.7,9]],"id":51643934}],"con":true,"img":false}]}
{"op":"mcm","clk":"11541130052","pt":1719502581086,"mc":[{"id":"1.230178320","rc":[{"atb":[[5.3,1.6],[5.1,0.84]],"id":62531723}],"con":true,"img":false}]}
{"op":"mcm","clk":"11541130073","pt":1719502581393,"mc":[{"id":"1.230178320","rc":[{"atb":[[5.3,1.6],[5.1,0]],"id":61941199},{"atl":[[5.5,0.03]],"id":51643934}],"con":true,"img":false}]}
{"op":"mcm","clk":"11541130099","pt":1719502581701,"mc":[{"id":"1.230178320","rc":[{"atb":[[5.1,2.44]],"id":62531723}],"con":true,"img":false}]}
{"op":"mcm","clk":"11541130110","pt":1719502581755,"mc":[{"id":"1.230178320","rc":[{"atb":[[5.3,0]],"id":62531723}],"con":true,"img":false}]}
{"op":"mcm","clk":"11541130130","pt":1719502581963,"mc":[{"id":"1.230178320","rc":[{"atb":[[5.1,1.6]],"id":61941199}],"con":true,"img":false}]}
{"op":"mcm","clk":"11541130148","pt":1719502582173,"mc":[{"id":"1.230178320","rc":[{"atb":[[5.3,0]],"id":61941199},{"atl":[[5.6,2]],"id":51643934}],"con":true,"img":false}]}
{"op":"mcm","clk":"11541130167","pt":1719502582377,"mc":[{"id":"1.230178320","rc":[{"atb":[[5.1,0.84]],"id":62531723}],"con":true,"img":false}]}
{"op":"mcm","clk":"11541130187","pt":1719502582689,"mc":[{"id":"1.230178320","rc":[{"atb":[[5.4,1.56]],"id":62531723}],"con":true,"img":false}]}
{"op":"mcm","clk":"11541130462","pt":1719502586303,"mc":[{"id":"1.230178320","rc":[{"atl":[[5.5,0.87]],"id":51643934}],"con":true,"img":false}]}
{"op":"mcm","clk":"11541130511","pt":1719502586880,"mc":[{"id":"1.230178320","rc":[{"atb":[[4.1,0]],"id":62531723}],"con":true,"img":false}]}
{"op":"mcm","clk":"11541130569","pt":1719502587491,"mc":[{"id":"1.230178320","rc":[{"atl":[[5.6,0]],"id":51643934}],"con":true,"img":false}]}
{"op":"mcm","clk":"11541130576","pt":1719502587601,"mc":[{"id":"1.230178320","rc":[{"atl":[[18,5.88],[5.7,1]],"id":51643934}],"con":true,"img":false}]}
{"op":"mcm","clk":"11541130600","pt":1719502587869,"mc":[{"id":"1.230178320","rc":[{"atl":[[5.5,0.03]],"id":51643934}],"con":true,"img":false}]}
{"op":"mcm","clk":"11541130692","pt":1719502589304,"mc":[{"id":"1.230178320","rc":[{"atl":[[5.6,2]],"id":51643934}],"con":true,"img":false}]}
{"op":"mcm","clk":"11541131071","pt":1719502593810,"mc":[{"id":"1.230178320","rc":[{"atl":[[5.5,0.87]],"id":51643934}],"con":true,"img":false}]}
{"op":"mcm","clk":"11541131093","pt":1719502594070,"mc":[{"id":"1.230178320","rc":[{"atb":[[5.1,2.41]],"id":62531723}],"con":true,"img":false}]}
{"op":"mcm","clk":"11541131102","pt":1719502594174,"mc":[{"id":"1.230178320","rc":[{"atb":[[5.4,0]],"id":62531723}],"con":true,"img":false}]}
{"op":"mcm","clk":"11541131116","pt":1719502594381,"mc":[{"id":"1.230178320","rc":[{"atb":[[5.5,1.54]],"id":62531723}],"con":true,"img":false}]}
{"op":"mcm","clk":"11541131126","pt":1719502594485,"mc":[{"id":"1.230178320","rc":[{"atl":[[5.6,0]],"id":51643934}],"con":true,"img":false}]}
{"op":"mcm","clk":"11541131142","pt":1719502594690,"mc":[{"id":"1.230178320","rc":[{"atb":[[5.1,0.84]],"id":62531723}],"con":true,"img":false}]}
{"op":"mcm","clk":"11541131160","pt":1719502594896,"mc":[{"id":"1.230178320","rc":[{"atl":[[5.5,0.03]],"id":51643934}],"con":true,"img":false}]}
{"op":"mcm","clk":"11541131280","pt":1719502596601,"mc":[{"id":"1.230178320","rc":[{"atl":[[5.6,2]],"id":51643934}],"con":true,"img":false}]}
{"op":"mcm","clk":"11541131287","pt":1719502596702,"mc":[{"id":"1.230178320","rc":[{"atl":[[5.6,4],[18,0]],"id":51643934}],"con":true,"img":false}]}
{"op":"mcm","clk":"11541131297","pt":1719502596807,"mc":[{"id":"1.230178320","rc":[{"atb":[[3.5,3.14]],"id":51643934}],"con":true,"img":false}]}
{"op":"mcm","clk":"11541131329","pt":1719502597270,"mc":[{"id":"1.230178320","rc":[{"atb":[[3.55,0.84]],"id":51643934}],"con":true,"img":false}]}
{"op":"mcm","clk":"11541131340","pt":1719502597376,"mc":[{"id":"1.230178320","rc":[{"atb":[[3.3,0],[3.2,18.59]],"id":51643934}],"con":true,"img":false}]}
{"op":"mcm","clk":"11541131358","pt":1719502597687,"mc":[{"id":"1.230178320","rc":[{"atb":[[3.25,0]],"id":51643934}],"con":true,"img":false}]}
{"op":"mcm","clk":"11541131364","pt":1719502597789,"mc":[{"id":"1.230178320","rc":[{"atb":[[3.55,2.84]],"id":51643934}],"con":true,"img":false}]}
{"op":"mcm","clk":"11541131442","pt":1719502598765,"mc":[{"id":"1.230178320","rc":[{"atb":[[4.1,7]],"id":43498435}],"con":true,"img":false}]}
{"op":"mcm","clk":"11541131608","pt":1719502600773,"mc":[{"id":"1.230178320","rc":[{"atl":[[5.5,0.87]],"id":51643934}],"con":true,"img":false}]}
{"op":"mcm","clk":"11541131686","pt":1719502601908,"mc":[{"id":"1.230178320","rc":[{"atl":[[5.6,2]],"id":51643934}],"con":true,"img":false}]}
{"op":"mcm","clk":"11541131692","pt":1719502602011,"mc":[{"id":"1.230178320","rc":[{"atl":[[5.6,0],[5.7,9]],"id":51643934}],"con":true,"img":false}]}
{"op":"mcm","clk":"11541131724","pt":1719502602377,"mc":[{"id":"1.230178320","rc":[{"atl":[[5.5,0.03]],"id":51643934}],"con":true,"img":false}]}
{"op":"mcm","clk":"11541131814","pt":1719502603816,"mc":[{"id":"1.230178320","rc":[{"atl":[[5.6,2]],"id":51643934}],"con":true,"img":false}]}
{"op":"mcm","clk":"11541132105","pt":1719502607890,"mc":[{"id":"1.230178320","rc":[{"atl":[[5.5,0.87]],"id":51643934}],"con":true,"img":false}]}
{"op":"mcm","clk":"11541132125","pt":1719502608199,"mc":[{"id":"1.230178320","rc":[{"atb":[[5.1,2.38],[5.5,0]],"id":62531723}],"con":true,"img":false}]}
{"op":"mcm","clk":"11541132174","pt":1719502609015,"mc":[{"id":"1.230178320","rc":[{"atl":[[5.6,0]],"id":51643934}],"con":true,"img":false}]}
{"op":"mcm","clk":"11541132180","pt":1719502609119,"mc":[{"id":"1.230178320","rc":[{"atl":[[18,5.88],[5.7,1]],"id":51643934}],"con":true,"img":false}]}
{"op":"mcm","clk":"11541132207","pt":1719502609379,"mc":[{"id":"1.230178320","rc":[{"atl":[[5.5,0.03]],"id":51643934}],"con":true,"img":false}]}
{"op":"mcm","clk":"11541132322","pt":1719502610820,"mc":[{"id":"1.230178320","rc":[{"atl":[[5.6,2]],"id":51643934}],"con":true,"img":false}]}
{"op":"mcm","clk":"11541132352","pt":1719502611080,"mc":[{"id":"1.230178320","rc":[{"atb":[[5.3,1.6]],"id":62531723}],"con":true,"img":false}]}
{"op":"mcm","clk":"11541132372","pt":1719502611285,"mc":[{"id":"1.230178320","rc":[{"atb":[[5.1,0.84]],"id":62531723}],"con":true,"img":false}]}
{"op":"mcm","clk":"11541132377","pt":1719502611388,"mc":[{"id":"1.230178320","rc":[{"atb":[[5.3,1.6]],"id":61941199}],"con":true,"img":false}]}
{"op":"mcm","clk":"11541132392","pt":1719502611595,"mc":[{"id":"1.230178320","rc":[{"atb":[[5.1,0]],"id":61941199}],"con":true,"img":false}]}
{"op":"mcm","clk":"11541132407","pt":1719502611803,"mc":[{"id":"1.230178320","rc":[{"atb":[[5.3,0]],"id":61941199}],"con":true,"img":false}]}
{"op":"mcm","clk":"11541132418","pt":1719502611908,"mc":[{"id":"1.230178320","rc":[{"atb":[[5.2,1.65]],"id":61941199}],"con":true,"img":false}]}
{"op":"mcm","clk":"11541132612","pt":1719502614808,"mc":[{"id":"1.230178320","rc":[{"atl":[[5.5,0.87]],"id":51643934}],"con":true,"img":false}]}
{"op":"mcm","clk":"11541132683","pt":1719502615993,"mc":[{"id":"1.230178320","rc":[{"atl":[[5.6,0]],"id":51643934}],"con":true,"img":false}]}
{"op":"mcm","clk":"11541132705","pt":1719502616303,"mc":[{"id":"1.230178320","rc":[{"atl":[[5.5,0.03]],"id":51643934}],"con":true,"img":false}]}
{"op":"mcm","clk":"11541132844","pt":1719502618007,"mc":[{"id":"1.230178320","rc":[{"atl":[[5.6,2]],"id":51643934}],"con":true,"img":false}]}
{"op":"mcm","clk":"11541132853","pt":1719502618111,"mc":[{"id":"1.230178320","rc":[{"atl":[[5.6,4],[18,0]],"id":51643934}],"con":true,"img":false}]}
{"op":"mcm","clk":"11541132862","pt":1719502618213,"mc":[{"id":"1.230178320","rc":[{"atl":[[5.6,2],[5.7,6.88]],"id":51643934}],"con":true,"img":false}]}
{"op":"mcm","clk":"11541132873","pt":1719502618318,"mc":[{"id":"1.230178320","rc":[{"atb":[[5.3,0],[5.1,2.44]],"id":62531723}],"con":true,"img":false}]}
{"op":"mcm","clk":"11541133053","pt":1719502620591,"mc":[{"id":"1.230178320","rc":[{"atl":[[5.5,4.64]],"id":51643934}],"con":true,"img":false}]}
{"op":"mcm","clk":"11541133063","pt":1719502620695,"mc":[{"id":"1.230178320","rc":[{"atl":[[5.6,11.28],[5.7,1]],"id":51643934}],"con":true,"img":false}]}
{"op":"mcm","clk":"11541133071","pt":1719502620796,"mc":[{"id":"1.230178320","rc":[{"atb":[[3.55,1]],"id":61419789}],"con":true,"img":false}]}
{"op":"mcm","clk":"11541133082","pt":1719502620902,"mc":[{"id":"1.230178320","rc":[{"atb":[[4.4,1]],"id":43498435},{"atl":[[30,4.45]],"id":61941199},{"atb":[[5.6,1]],"id":62531723},{"atl":[[5.5,5.64]],"id":51643934}],"con":true,"img":false}]}
{"op":"mcm","clk":"11541133106","pt":1719502621315,"mc":[{"id":"1.230178320","rc":[{"atb":[[1.01,46.31]],"id":51643934}],"con":true,"img":false}]}
{"op":"mcm","clk":"11541133179","pt":1719502622308,"mc":[{"id":"1.230178320","rc":[{"atl":[[5.4,0.84]],"id":51643934}],"con":true,"img":false}]}
{"op":"mcm","clk":"11541133204","pt":1719502622720,"mc":[{"id":"1.230178320","rc":[{"atl":[[12.5,0],[29,0.67]],"id":61941199},{"atl":[[5.5,1.03]],"id":51643934}],"con":true,"img":false}]}
{"op":"mcm","clk":"11541133228","pt":1719502623029,"mc":[{"id":"1.230178320","rc":[{"atl":[[1000,1.01]],"id":61941199}],"con":true,"img":false}]}
{"op":"mcm","clk":"11541133236","pt":1719502623133,"mc":[{"id":"1.230178320","rc":[{"atl":[[29,0]],"id":61941199}],"con":true,"img":false}]}
{"op":"mcm","clk":"11541133247","pt":1719502623293,"mc":[{"id":"1.230178320","rc":[{"atl":[[5.6,9.28]],"id":51643934}],"con":true,"img":false}]}
{"op":"mcm","clk":"11541133254","pt":1719502623396,"mc":[{"id":"1.230178320","rc":[{"atl":[[1000,0.84]],"id":61941199}],"con":true,"img":false}]}
{"op":"mcm","clk":"11541133259","pt":1719502623603,"mc":[{"id":"1.230178320","rc":[{"atl":[[5.5,1]],"id":51643934}],"con":true,"img":false}]}
{"op":"mcm","clk":"11541133264","pt":1719502623708,"mc":[{"id":"1.230178320","rc":[{"atl":[[1000,0.16]],"id":61941199},{"atl":[[5.3,0.03]],"id":51643934}],"con":true,"img":false}]}
{"op":"mcm","clk":"11541133270","pt":1719502623811,"mc":[{"id":"1.230178320","rc":[{"atl":[[12.5,0.67]],"id":61941199}],"con":true,"img":false}]}
{"op":"mcm","clk":"11541133370","pt":1719502625206,"mc":[{"id":"1.230178320","rc":[{"spn":8.85,"spf":"NaN","id":61941199},{"spn":9.3,"spf":"NaN","id":62531723},{"atl":[[5.4,2.84]],"id":51643934},{"spn":3.55,"spf":1.0,"id":51643934}],"con":true,"img":false}]}
{"op":"mcm","clk":"11541133406","pt":1719502625719,"mc":[{"id":"1.230178320","rc":[{"atl":[[5.3,4.82]],"id":51643934}],"con":true,"img":false}]}
{"op":"mcm","clk":"11541133449","pt":1719502626207,"mc":[{"id":"1.230178320","rc":[{"atl":[[5.4,0.84]],"id":51643934}],"con":true,"img":false}]}
{"op":"mcm","clk":"11541133628","pt":1719502628531,"mc":[{"id":"1.230178320","rc":[{"atb":[[1.25,20]],"id":43498435},{"atb":[[1.25,20]],"id":69176305},{"atb":[[1.25,20]],"id":61941199},{"atb":[[1.25,20]],"id":61419789},{"atb":[[1.25,20]],"id":62531723},{"atb":[[1.25,20]],"id":51643934}],"con":true,"img":false}]}
{"op":"mcm","clk":"11541133716","pt":1719502629824,"mc":[{"id":"1.230178320","rc":[{"atl":[[5.2,0.84]],"id":51643934}],"con":true,"img":false}]}
{"op":"mcm","clk":"11541133770","pt":1719502630395,"mc":[{"id":"1.230178320","rc":[{"atl":[[5.3,0.03]],"id":51643934}],"con":true,"img":false}]}
{"op":"mcm","clk":"11541133806","pt":1719502630911,"mc":[{"id":"1.230178320","rc":[{"atl":[[5.2,0]],"id":51643934}],"con":true,"img":false}]}
{"op":"mcm","clk":"11541133908","pt":1719502632413,"mc":[{"id":"1.230178320","rc":[{"atl":[[5.4,2.84]],"id":51643934}],"con":true,"img":false}]}
{"op":"mcm","clk":"11541133922","pt":1719502632618,"mc":[{"id":"1.230178320","rc":[{"atb":[[5.1,1.6]],"id":61941199}],"con":true,"img":false}]}
{"op":"mcm","clk":"11541133926","pt":1719502632721,"mc":[{"id":"1.230178320","rc":[{"atb":[[5.2,0.05]],"id":61941199}],"con":true,"img":false}]}
{"op":"mcm","clk":"11541133938","pt":1719502632927,"mc":[{"id":"1.230178320","rc":[{"atl":[[5.3,4.82]],"id":51643934}],"con":true,"img":false}]}
{"op":"mcm","clk":"11541134201","pt":1719502636808,"mc":[{"id":"1.230178320","rc":[{"atl":[[5.2,0.84]],"id":51643934}],"con":true,"img":false}]}
{"op":"mcm","clk":"11541134237","pt":1719502637322,"mc":[{"id":"1.230178320","rc":[{"atl":[[5.3,0.03]],"id":51643934}],"con":true,"img":false}]}
{"op":"mcm","clk":"11541134269","pt":1719502637735,"mc":[{"id":"1.230178320","rc":[{"atl":[[5.4,0.84]],"id":51643934}],"con":true,"img":false}]}
{"op":"mcm","clk":"11541134278","pt":1719502637840,"mc":[{"id":"1.230178320","rc":[{"atl":[[5.2,0]],"id":51643934}],"con":true,"img":false}]}
{"op":"mcm","clk":"11541134357","pt":1719502638927,"mc":[{"id":"1.230178320","rc":[{"atl":[[19.5,0]],"id":43498435},{"atl":[[14,1]],"id":62531723}],"con":true,"img":false}]}
{"op":"mcm","clk":"11541134371","pt":1719502639133,"mc":[{"id":"1.230178320","rc":[{"atl":[[13,0],[1000,1.01]],"id":62531723}],"con":true,"img":false}]}
{"op":"mcm","clk":"11541134393","pt":1719502639441,"mc":[{"id":"1.230178320","rc":[{"atl":[[1000,1.01]],"id":43498435}],"con":true,"img":false}]}
{"op":"mcm","clk":"11541134402","pt":1719502639546,"mc":[{"id":"1.230178320","rc":[{"atl":[[18.5,0]],"id":43498435},{"atb":[[3.5,2.85]],"id":61419789},{"atl":[[5.4,2.84]],"id":51643934}],"con":true,"img":false}]}
{"op":"mcm","clk":"11541134410","pt":1719502639649,"mc":[{"id":"1.230178320","rc":[{"atl":[[34,3.03],[27,0]],"id":43498435}],"con":true,"img":false}]}
{"op":"mcm","clk":"11541134419","pt":1719502639753,"mc":[{"id":"1.230178320","rc":[{"atl":[[1000,0.62]],"id":43498435},{"atl":[[5.3,4.82]],"id":51643934}],"con":true,"img":false}]}
{"op":"mcm","clk":"11541134438","pt":1719502639911,"mc":[{"id":"1.230178320","rc":[{"atl":[[1000,0.82]],"id":62531723}],"con":true,"img":false}]}
{"op":"mcm","clk":"11541134463","pt":1719502640218,"mc":[{"id":"1.230178320","rc":[{"atl":[[5.4,0.84]],"id":51643934}],"con":true,"img":false}]}
{"op":"mcm","clk":"11541134469","pt":1719502640322,"mc":[{"id":"1.230178320","rc":[{"atl":[[1000,0.16]],"id":43498435}],"con":true,"img":false}]}
{"op":"mcm","clk":"11541134481","pt":1719502640425,"mc":[{"id":"1.230178320","rc":[{"atl":[[26,0.45]],"id":43498435}],"con":true,"img":false}]}
{"op":"mcm","clk":"11541134509","pt":1719502640834,"mc":[{"id":"1.230178320","rc":[{"atl":[[1000,0.16]],"id":62531723}],"con":true,"img":false}]}
{"op":"mcm","clk":"11541134517","pt":1719502640936,"mc":[{"id":"1.230178320","rc":[{"atl":[[13.5,1.49]],"id":62531723}],"con":true,"img":false}]}
{"op":"mcm","clk":"11541134538","pt":1719502641245,"mc":[{"id":"1.230178320","rc":[{"atl":[[1000,1.01]],"id":43498435}],"con":true,"img":false}]}
{"op":"mcm","clk":"11541134560","pt":1719502641552,"mc":[{"id":"1.230178320","rc":[{"atl":[[26,0]],"id":43498435}],"con":true,"img":false}]}
{"op":"mcm","clk":"11541134569","pt":1719502641606,"mc":[{"id":"1.230178320","rc":[{"atb":[[5.1,0]],"id":61941199}],"con":true,"img":false}]}
{"op":"mcm","clk":"11541134584","pt":1719502641813,"mc":[{"id":"1.230178320","rc":[{"atb":[[5.3,1.6]],"id":61941199}],"con":true,"img":false}]}
{"op":"mcm","clk":"11541134597","pt":1719502642020,"mc":[{"id":"1.230178320","rc":[{"atl":[[1000,0.62]],"id":43498435}],"con":true,"img":false}]}
{"op":"mcm","clk":"11541134631","pt":1719502642429,"mc":[{"id":"1.230178320","rc":[{"atl":[[1000,0.16]],"id":43498435}],"con":true,"img":false}]}
{"op":"mcm","clk":"11541134640","pt":1719502642533,"mc":[{"id":"1.230178320","rc":[{"atl":[[18.5,0.45]],"id":43498435}],"con":true,"img":false}]}
{"op":"mcm","clk":"11541134669","pt":1719502642842,"mc":[{"id":"1.230178320","rc":[{"atb":[[5.3,0],[5.1,1.6]],"id":61941199}],"con":true,"img":false}]}
{"op":"mcm","clk":"11541134787","pt":1719502644348,"mc":[{"id":"1.230178320","rc":[{"atl":[[5.2,0.84]],"id":51643934}],"con":true,"img":false}]}
{"op":"mcm","clk":"11541134832","pt":1719502645018,"mc":[{"id":"1.230178320","rc":[{"atl":[[5.3,0.03]],"id":51643934}],"con":true,"img":false}]}
{"op":"mcm","clk":"11541134905","pt":1719502645942,"mc":[{"id":"1.230178320","rc":[{"atl":[[5.2,0]],"id":51643934}],"con":true,"img":false}]}
{"op":"mcm","clk":"11541134963","pt":1719502646716,"mc":[{"id":"1.230178320","rc":[{"atl":[[5.4,2.84]],"id":51643934}],"con":true,"img":false}]}
{"op":"mcm","clk":"11541135000","pt":1719502647128,"mc":[{"id":"1.230178320","rc":[{"atl":[[5.3,4.82]],"id":51643934}],"con":true,"img":false}]}
{"op":"mcm","clk":"11541135026","pt":1719502647434,"mc":[{"id":"1.230178320","rc":[{"spl":[[1.01,4]],"id":69176305}],"con":true,"img":false}]}
{"op":"mcm","clk":"11541135045","pt":1719502647742,"mc":[{"id":"1.230178320","rc":[{"atl":[[5.4,0.84]],"id":51643934}],"con":true,"img":false}]}
{"op":"mcm","clk":"11541135329","pt":1719502651863,"mc":[{"id":"1.230178320","rc":[{"atl":[[5.2,0.84],[1000,1.16]],"id":51643934}],"con":true,"img":false}]}
{"op":"mcm","clk":"11541135350","pt":1719502652133,"mc":[{"id":"1.230178320","rc":[{"atl":[[1000,0.19]],"id":51643934}],"con":true,"img":false}]}
{"op":"mcm","clk":"11541135379","pt":1719502652433,"mc":[{"id":"1.230178320","rc":[{"atl":[[5.3,0.03],[1000,0.16]],"id":51643934}],"con":true,"img":false}]}
{"op":"mcm","clk":"11541135385","pt":1719502652536,"mc":[{"id":"1.230178320","rc":[{"atl":[[5.2,0.87]],"id":51643934}],"con":true,"img":false}]}
{"op":"mcm","clk":"11541135406","pt":1719502652843,"mc":[{"id":"1.230178320","rc":[{"atl":[[5.2,0.03]],"id":51643934}],"con":true,"img":false}]}
{"op":"mcm","clk":"11541135475","pt":1719502653826,"mc":[{"id":"1.230178320","rc":[{"atl":[[5.4,2.84]],"id":51643934}],"con":true,"img":false}]}
{"op":"mcm","clk":"11541135486","pt":1719502653930,"mc":[{"id":"1.230178320","rc":[{"atl":[[5.3,4.82]],"id":51643934}],"con":true,"img":false}]}
{"op":"mcm","clk":"11541135673","pt":1719502656459,"mc":[{"id":"1.230178320","rc":[{"atb":[[4.9,0]],"id":43498435},{"atb":[[4.3,0]],"id":61941199}],"con":true,"img":false}]}
{"op":"mcm","clk":"11541135806","pt":1719502658433,"mc":[{"id":"1.230178320","rc":[{"atb":[[4.9,1]],"id":43498435},{"atb":[[4.3,1]],"id":61941199}],"con":true,"img":false}]}
{"op":"mcm","clk":"11541135836","pt":1719502658844,"mc":[{"id":"1.230178320","rc":[{"atl":[[5.2,0.87]],"id":51643934}],"con":true,"img":false}]}
{"op":"mcm","clk":"11541135857","pt":1719502659151,"mc":[{"id":"1.230178320","rc":[{"atl":[[5.4,0.84]],"id":51643934}],"con":true,"img":false}]}
{"op":"mcm","clk":"11541135881","pt":1719502659462,"mc":[{"id":"1.230178320","rc":[{"atl":[[5.3,0.03]],"id":51643934}],"con":true,"img":false}]}
{"op":"mcm","clk":"11541135902","pt":1719502659669,"mc":[{"id":"1.230178320","rc":[{"atb":[[4.9,0]],"id":43498435},{"atb":[[4.3,0]],"id":61941199}],"con":true,"img":false}]}
{"op":"mcm","clk":"11541135922","pt":1719502659825,"mc":[{"id":"1.230178320","rc":[{"atl":[[5.2,0.03]],"id":51643934}],"con":true,"img":false}]}
{"op":"mcm","clk":"11541135997","pt":1719502661061,"mc":[{"id":"1.230178320","rc":[{"atl":[[5.4,2.84]],"id":51643934}],"con":true,"img":false}]}
{"op":"mcm","clk":"11541136004","pt":1719502661267,"mc":[{"id":"1.230178320","rc":[{"atl":[[5.3,4.82]],"id":51643934}],"con":true,"img":false}]}
{"op":"mcm","clk":"11541136043","pt":1719502661733,"mc":[{"id":"1.230178320","rc":[{"atl":[[5.4,0.84]],"id":51643934}],"con":true,"img":false}]}
{"op":"mcm","clk":"11541136186","pt":1719502664260,"mc":[{"id":"1.230178320","rc":[{"atb":[[4.6,3.28]],"id":69176305}],"con":true,"img":false}]}
{"op":"mcm","clk":"11541136220","pt":1719502664827,"mc":[{"id":"1.230178320","rc":[{"atb":[[4.7,0.84]],"id":69176305}],"con":true,"img":false}]}
{"op":"mcm","clk":"11541136226","pt":1719502664928,"mc":[{"id":"1.230178320","rc":[{"atb":[[4.4,0]],"id":69176305}],"con":true,"img":false}]}
{"op":"mcm","clk":"11541136232","pt":1719502665033,"mc":[{"id":"1.230178320","rc":[{"atb":[[4.7,2.84]],"id":69176305}],"con":true,"img":false}]}
{"op":"mcm","clk":"11541136290","pt":1719502665957,"mc":[{"id":"1.230178320","rc":[{"atb":[[4.5,0.06]],"id":69176305}],"con":true,"img":false}]}
{"op":"mcm","clk":"11541136319","pt":1719502666371,"mc":[{"id":"1.230178320","rc":[{"atl":[[5.2,0.87]],"id":51643934}],"con":true,"img":false}]}
{"op":"mcm","clk":"11541136357","pt":1719502666937,"mc":[{"id":"1.230178320","rc":[{"atl":[[5.3,0.03]],"id":51643934}],"con":true,"img":false}]}
{"op":"mcm","clk":"11541136371","pt":1719502667250,"mc":[{"id":"1.230178320","rc":[{"atb":[[4.9,1]],"id":43498435},{"atb":[[4.3,1]],"id":61941199}],"con":true,"img":false}]}
{"op":"mcm","clk":"11541136388","pt":1719502667456,"mc":[{"id":"1.230178320","rc":[{"atl":[[5.2,0.03]],"id":51643934}],"con":true,"img":false}]}
{"op":"mcm","clk":"11541136451","pt":1719502668236,"mc":[{"id":"1.230178320","rc":[{"atl":[[5.4,2.84]],"id":51643934}],"con":true,"img":false}]}
{"op":"mcm","clk":"11541136467","pt":1719502668447,"mc":[{"id":"1.230178320","rc":[{"atl":[[5.3,4.82]],"id":51643934}],"con":true,"img":false}]}
{"op":"mcm","clk":"11541136485","pt":1719502668758,"mc":[{"id":"1.230178320","rc":[{"atl":[[5.4,0.84]],"id":51643934}],"con":true,"img":false}]}
{"op":"mcm","clk":"11541136612","pt":1719502670465,"mc":[{"id":"1.230178320","rc":[{"atb":[[3.7,4.72]],"id":51643934}],"con":true,"img":false}]}
{"op":"mcm","clk":"11541136630","pt":1719502670876,"mc":[{"id":"1.230178320","rc":[{"atb":[[3.75,0.84]],"id":51643934}],"con":true,"img":false}]}
{"op":"mcm","clk":"11541136637","pt":1719502670979,"mc":[{"id":"1.230178320","rc":[{"atb":[[3.55,2]],"id":51643934}],"con":true,"img":false}]}
{"op":"mcm","clk":"11541136654","pt":1719502671239,"mc":[{"id":"1.230178320","rc":[{"atb":[[5.7,1.48]],"id":62531723}],"con":true,"img":false}]}
{"op":"mcm","clk":"11541136676","pt":1719502671547,"mc":[{"id":"1.230178320","rc":[{"atb":[[5.3,1.6]],"id":61941199},{"atb":[[5.1,0.84]],"id":62531723},{"atb":[[3.55,0]],"id":51643934}],"con":true,"img":false}]}
{"op":"mcm","clk":"11541136682","pt":1719502671651,"mc":[{"id":"1.230178320","rc":[{"atb":[[1.02,2]],"id":51643934}],"con":true,"img":false}]}
{"op":"mcm","clk":"11541136704","pt":1719502671964,"mc":[{"id":"1.230178320","rc":[{"atb":[[5.1,0]],"id":61941199},{"atb":[[5.1,0]],"id":62531723}],"con":true,"img":false}]}
{"op":"mcm","clk":"11541136730","pt":1719502672272,"mc":[{"id":"1.230178320","rc":[{"atb":[[5.3,0]],"id":61941199}],"con":true,"img":false}]}
{"op":"mcm","clk":"11541136740","pt":1719502672377,"mc":[{"id":"1.230178320","rc":[{"atb":[[5.1,1.6]],"id":61941199}],"con":true,"img":false}]}
{"op":"mcm","clk":"11541136884","pt":1719502673737,"mc":[{"id":"1.230178320","rc":[{"atl":[[5.2,0.87]],"id":51643934}],"con":true,"img":false}]}
{"op":"mcm","clk":"11541136947","pt":1719502674456,"mc":[{"id":"1.230178320","rc":[{"atl":[[5.3,0.03]],"id":51643934}],"con":true,"img":false}]}
{"op":"mcm","clk":"11541136987","pt":1719502674873,"mc":[{"id":"1.230178320","rc":[{"atl":[[5.2,0.03]],"id":51643934}],"con":true,"img":false}]}
{"op":"mcm","clk":"11541137025","pt":1719502675346,"mc":[{"id":"1.230178320","rc":[{"atl":[[5.4,2.84]],"id":51643934}],"con":true,"img":false}]}
{"op":"mcm","clk":"11541137049","pt":1719502675755,"mc":[{"id":"1.230178320","rc":[{"atl":[[5.3,4.82]],"id":51643934}],"con":true,"img":false}]}
{"op":"mcm","clk":"11541137105","pt":1719502676375,"mc":[{"id":"1.230178320","rc":[{"atl":[[17.5,6.06],[18.5,0]],"id":62531723},{"atl":[[5.6,0],[5.4,7.69]],"id":51643934}],"con":true,"img":false}]}
{"op":"mcm","clk":"11541137404","pt":1719502680193,"mc":[{"id":"1.230178320","rc":[{"atb":[[4.2,7.67]],"id":69176305},{"atl":[[30,0.86]],"id":69176305},{"atb":[[5.2,5.4]],"id":61941199},{"atl":[[29,0.94]],"id":61941199},{"atb":[[5.7,6.72]],"id":62531723},{"atl":[[13.5,3.4]],"id":62531723},{"atb":[[3.5,13.16]],"id":51643934},{"atl":[[5.2,6.49]],"id":51643934}],"con":true,"img":false}]}
{"op":"mcm","clk":"11541137412","pt":1719502680259,"mc":[{"id":"1.230178320","rc":[{"atb":[[5.6,0]],"id":62531723}],"con":true,"img":false}]}
{"op":"mcm","clk":"11541137426","pt":1719502680468,"mc":[{"id":"1.230178320","rc":[{"atb":[[5.3,1.6]],"id":61941199},{"atb":[[5.8,1]],"id":62531723}],"con":true,"img":false}]}
{"op":"mcm","clk":"11541137443","pt":1719502680667,"mc":[{"id":"1.230178320","rc":[{"atl":[[5.4,5.69]],"id":51643934}],"con":true,"img":false}]}
{"op":"mcm","clk":"11541137454","pt":1719502680777,"mc":[{"id":"1.230178320","rc":[{"atb":[[5.1,0]],"id":61941199},{"atl":[[5.3,0.03]],"id":51643934}],"con":true,"img":false}]}
{"op":"mcm","clk":"11541137467","pt":1719502680879,"mc":[{"id":"1.230178320","rc":[{"atl":[[5.1,0.84]],"id":51643934}],"con":true,"img":false}]}
{"op":"mcm","clk":"11541137486","pt":1719502680984,"mc":[{"id":"1.230178320","rc":[{"atl":[[5.4,4.85]],"id":51643934}],"con":true,"img":false}]}
{"op":"mcm","clk":"11541137496","pt":1719502681091,"mc":[{"id":"1.230178320","rc":[{"atb":[[5.3,7.96]],"id":61941199}],"con":true,"img":false}]}
{"op":"mcm","clk":"11541137527","pt":1719502681355,"mc":[{"id":"1.230178320","rc":[{"atb":[[5.4,4.7]],"id":61941199}],"con":true,"img":false}]}
{"op":"mcm","clk":"11541137553","pt":1719502681667,"mc":[{"id":"1.230178320","rc":[{"atb":[[5.3,6.36],[5.5,1.54]],"id":61941199}],"con":true,"img":false}]}
{"op":"mcm","clk":"11541137575","pt":1719502681878,"mc":[{"id":"1.230178320","rc":[{"atb":[[5.4,9.76],[5.5,2.38]],"id":61941199}],"con":true,"img":false}]}
{"op":"mcm","clk":"11541137602","pt":1719502682192,"mc":[{"id":"1.230178320","rc":[{"atb":[[5.4,5.06]],"id":61941199}],"con":true,"img":false}]}
{"op":"mcm","clk":"11541137615","pt":1719502682250,"mc":[{"id":"1.230178320","rc":[{"atb":[[5,0]],"id":61941199},{"atb":[[3,0]],"id":51643934}],"con":true,"img":false}]}
{"op":"mcm","clk":"11541137625","pt":1719502682354,"mc":[{"id":"1.230178320","rc":[{"atb":[[5.6,4.53]],"id":61941199}],"con":true,"img":false}]}
{"op":"mcm","clk":"11541143263","pt":1719502682848,"mc":[{"id":"1.230178320","rc":[{"atb":[[5.6,10.41]],"id":61941199},{"atl":[[5.1,2.84]],"id":51643934}],"con":true,"img":false}]}
{"op":"mcm","clk":"11541143282","pt":1719502682982,"mc":[{"id":"1.230178320","rc":[{"atl":[[5.5,0]],"id":51643934}],"con":true,"img":false}]}
{"op":"mcm","clk":"11541143291","pt":1719502683086,"mc":[{"id":"1.230178320","rc":[{"atb":[[4.6,0]],"id":69176305},{"atb":[[3.7,0]],"id":51643934},{"atl":[[5,5.08]],"id":51643934}],"con":true,"img":false}]}
{"op":"mcm","clk":"11541143302","pt":1719502683192,"mc":[{"id":"1.230178320","rc":[{"atl":[[5.1,3.84]],"id":51643934}],"con":true,"img":false}]}
{"op":"mcm","clk":"11541143324","pt":1719502683361,"mc":[{"id":"1.230178320","rc":[{"atb":[[5.9,1.43]],"id":62531723}],"con":true,"img":false}]}
{"op":"mcm","clk":"11541143344","pt":1719502683560,"mc":[{"id":"1.230178320","rc":[{"atl":[[5.1,1.84]],"id":51643934}],"con":true,"img":false}]}
{"op":"mcm","clk":"11541143354","pt":1719502683665,"mc":[{"id":"1.230178320","rc":[{"atb":[[5.9,6.73],[5.7,5.24]],"id":62531723},{"atl":[[5,12.02]],"id":51643934}],"con":true,"img":false}]}
{"op":"mcm","clk":"11541143368","pt":1719502683771,"mc":[{"id":"1.230178320","rc":[{"atb":[[5.7,1.41]],"id":61941199},{"atb":[[3.75,0]],"id":51643934}],"con":true,"img":false}]}
{"op":"mcm","clk":"11541143376","pt":1719502683875,"mc":[{"id":"1.230178320","rc":[{"atl":[[5.1,0.84]],"id":51643934}],"con":true,"img":false}]}
{"op":"mcm","clk":"11541143388","pt":1719502683980,"mc":[{"id":"1.230178320","rc":[{"atb":[[5.8,0]],"id":62531723}],"con":true,"img":false}]}
{"op":"mcm","clk":"11541143393","pt":1719502684084,"mc":[{"id":"1.230178320","rc":[{"atl":[[4.9,1]],"id":51643934}],"con":true,"img":false}]}
{"op":"mcm","clk":"11541143402","pt":1719502684186,"mc":[{"id":"1.230178320","rc":[{"atb":[[6,1]],"id":62531723}],"con":true,"img":false}]}
{"op":"mcm","clk":"11541143409","pt":1719502684289,"mc":[{"id":"1.230178320","rc":[{"atb":[[4.7,0.84]],"id":69176305},{"atb":[[5.6,5.88]],"id":61941199}],"con":true,"img":false}]}
{"op":"mcm","clk":"11541143416","pt":1719502684394,"mc":[{"id":"1.230178320","rc":[{"atb":[[4.4,2]],"id":69176305},{"atb":[[6,1.84]],"id":62531723},{"atb":[[3.55,0.84]],"id":51643934}],"con":true,"img":false}]}
{"op":"mcm","clk":"11541143433","pt":1719502684556,"mc":[{"id":"1.230178320","rc":[{"atb":[[3.5,3.14]],"id":51643934}],"con":true,"img":false}]}
{"op":"mcm","clk":"11541143449","pt":1719502684761,"mc":[{"id":"1.230178320","rc":[{"atb":[[4.7,0]],"id":69176305},{"atb":[[3.45,9.09]],"id":51643934}],"con":true,"img":false}]}
{"op":"mcm","clk":"11541143467","pt":1719502684970,"mc":[{"id":"1.230178320","rc":[{"atl":[[5,6.94]],"id":51643934}],"con":true,"img":false}]}
{"op":"mcm","clk":"11541143498","pt":1719502685386,"mc":[{"id":"1.230178320","rc":[{"atb":[[4.5,0.91]],"id":69176305},{"spn":4.39,"spf":1.0,"id":69176305},{"spn":9.1,"spf":"NaN","id":61941199},{"spn":9.75,"spf":"NaN","id":62531723},{"spn":3.54,"spf":1.0,"id":51643934}],"con":true,"img":false}]}
{"op":"mcm","clk":"11541143512","pt":1719502685596,"mc":[{"id":"1.230178320","rc":[{"atb":[[4.5,7.78]],"id":69176305}],"con":true,"img":false}]}
{"op":"mcm","clk":"11541143604","pt":1719502686684,"mc":[{"id":"1.230178320","rc":[{"atb":[[5.1,0]],"id":61419789}],"con":true,"img":false}]}
{"op":"mcm","clk":"11541143631","pt":1719502687051,"mc":[{"id":"1.230178320","rc":[{"atb":[[4.4,0]],"id":69176305},{"atb":[[5.2,5.35]],"id":61941199}],"con":true,"img":false}]}
{"op":"mcm","clk":"11541143638","pt":1719502687154,"mc":[{"id":"1.230178320","rc":[{"atb":[[4.6,2]],"id":69176305}],"con":true,"img":false}]}
{"op":"mcm","clk":"11541143649","pt":1719502687260,"mc":[{"id":"1.230178320","rc":[{"atb":[[3,1.13]],"id":51643934}],"con":true,"img":false}]}
{"op":"mcm","clk":"11541143664","pt":1719502687466,"mc":[{"id":"1.230178320","rc":[{"atb":[[3.35,0]],"id":51643934}],"con":true,"img":false}]}
{"op":"mcm","clk":"11541143673","pt":1719502687570,"mc":[{"id":"1.230178320","rc":[{"atb":[[4.5,7.71],[4.6,8.64]],"id":69176305}],"con":true,"img":false}]}
{"op":"mcm","clk":"11541143688","pt":1719502687779,"mc":[{"id":"1.230178320","rc":[{"atb":[[5.1,0]],"id":43498435},{"atb":[[1.12,1.69]],"id":61419789}],"con":true,"img":false}]}
{"op":"mcm","clk":"11541143706","pt":1719502687985,"mc":[{"id":"1.230178320","rc":[{"atb":[[1.1,1.69]],"id":69176305},{"atb":[[1.14,1.69]],"id":61941199}],"con":true,"img":false}]}
{"op":"mcm","clk":"11541143714","pt":1719502688085,"mc":[{"id":"1.230178320","rc":[{"atb":[[4.7,5.4]],"id":69176305}],"con":true,"img":false}]}
{"op":"mcm","clk":"11541143735","pt":1719502688291,"mc":[{"id":"1.230178320","rc":[{"atb":[[1.12,1.69]],"id":43498435}],"con":true,"img":false}]}
{"op":"mcm","clk":"11541143754","pt":1719502688500,"mc":[{"id":"1.230178320","rc":[{"atb":[[4.6,6.64],[4.7,12.58]],"id":69176305},{"atb":[[1.12,0.05]],"id":61419789}],"con":true,"img":false}]}
{"op":"mcm","clk":"11541143761","pt":1719502688603,"mc":[{"id":"1.230178320","rc":[{"atb":[[4.8,2]],"id":69176305},{"atb":[[1.14,0.05]],"id":61941199}],"con":true,"img":false}]}
{"op":"mcm","clk":"11541143787","pt":1719502688866,"mc":[{"id":"1.230178320","rc":[{"atb":[[4.5,6.87],[4.7,7.18]],"id":69176305},{"atb":[[1.12,0.05]],"id":43498435}],"con":true,"img":false}]}
{"op":"mcm","clk":"11541143796","pt":1719502688969,"mc":[{"id":"1.230178320","rc":[{"atb":[[1.1,0.06]],"id":69176305}],"con":true,"img":false}]}
{"op":"mcm","clk":"11541143803","pt":1719502689073,"mc":[{"id":"1.230178320","rc":[{"atb":[[4.9,5.18]],"id":69176305}],"con":true,"img":false}]}
{"op":"mcm","clk":"11541143812","pt":1719502689177,"mc":[{"id":"1.230178320","rc":[{"atb":[[1.12,0],[3.3,1]],"id":61419789}],"con":true,"img":false}]}
{"op":"mcm","clk":"11541143818","pt":1719502689282,"mc":[{"id":"1.230178320","rc":[{"atb":[[4.2,0]],"id":69176305},{"atb":[[5.1,0.05]],"id":61419789}],"con":true,"img":false}]}
{"op":"mcm","clk":"11541143831","pt":1719502689491,"mc":[{"id":"1.230178320","rc":[{"atb":[[4.9,12.34]],"id":69176305}],"con":true,"img":false}]}
{"op":"mcm","clk":"11541143837","pt":1719502689593,"mc":[{"id":"1.230178320","rc":[{"atb":[[1.14,0]],"id":61941199}],"con":true,"img":false}]}
{"op":"mcm","clk":"11541143844","pt":1719502689697,"mc":[{"id":"1.230178320","rc":[{"atb":[[5.8,0.05]],"id":61941199}],"con":true,"img":false}]}
{"op":"mcm","clk":"11541143856","pt":1719502689802,"mc":[{"id":"1.230178320","rc":[{"atl":[[4.8,2]],"id":51643934}],"con":true,"img":false}]}
{"op":"mcm","clk":"11541143875","pt":1719502690064,"mc":[{"id":"1.230178320","rc":[{"atb":[[1.12,0]],"id":43498435}],"con":true,"img":false}]}
{"op":"mcm","clk":"11541143882","pt":1719502690170,"mc":[{"id":"1.230178320","rc":[{"atb":[[5.1,0.05]],"id":43498435},{"atb":[[4.8,0]],"id":69176305},{"atb":[[3.55,11.04]],"id":61419789},{"atl":[[19.5,1.44]],"id":61419789},{"atl":[[4.8,9.16]],"id":51643934}],"con":true,"img":false}]}
{"op":"mcm","clk":"11541143894","pt":1719502690273,"mc":[{"id":"1.230178320","rc":[{"atb":[[5,2]],"id":69176305},{"atl":[[5.1,0],[4.7,0.84]],"id":51643934}],"con":true,"img":false}]}
{"op":"mcm","clk":"11541143899","pt":1719502690376,"mc":[{"id":"1.230178320","rc":[{"atb":[[3.55,10.04]],"id":61419789},{"atl":[[4.9,0]],"id":51643934}],"con":true,"img":false}]}
{"op":"mcm","clk":"11541143905","pt":1719502690480,"mc":[{"id":"1.230178320","rc":[{"atb":[[1.1,0]],"id":69176305},{"atb":[[3.6,1]],"id":61419789},{"atl":[[4.7,1.84]],"id":51643934}],"con":true,"img":false}]}
{"op":"mcm","clk":"11541143912","pt":1719502690582,"mc":[{"id":"1.230178320","rc":[{"atb":[[4.9,7.16],[4.7,9.8]],"id":69176305},{"atb":[[5.1,0.84]],"id":43498435},{"atb":[[5.3,7.79]],"id":61941199},{"atb":[[3.55,10.83]],"id":61419789},{"atb":[[5.7,6.56]],"id":62531723}],"con":true,"img":false}]}
{"op":"mcm","clk":"11541143924","pt":1719502690792,"mc":[{"id":"1.230178320","rc":[{"atb":[[5.1,4.97]],"id":69176305}],"con":true,"img":false}]}
{"op":"mcm","clk":"11541143939","pt":1719502690998,"mc":[{"id":"1.230178320","rc":[{"atb":[[5.2,0]],"id":62531723}],"con":true,"img":false}]}
{"op":"mcm","clk":"11541143945","pt":1719502691101,"mc":[{"id":"1.230178320","rc":[{"atl":[[4.8,7.16]],"id":51643934}],"con":true,"img":false}]}
{"op":"mcm","clk":"11541143966","pt":1719502691263,"mc":[{"id":"1.230178320","rc":[{"atb":[[4.5,0]],"id":69176305},{"atb":[[1.14,1.69],[5.9,1.43]],"id":62531723},{"atb":[[3.45,0]],"id":51643934}],"con":true,"img":false}]}
{"op":"mcm","clk":"11541143981","pt":1719502691469,"mc":[{"id":"1.230178320","rc":[{"atb":[[6,0.84]],"id":62531723}],"con":true,"img":false}]}
{"op":"mcm","clk":"11541143995","pt":1719502691680,"mc":[{"id":"1.230178320","rc":[{"atb":[[5.1,11.17]],"id":69176305},{"atb":[[5.8,6.78],[1.14,0.05]],"id":62531723},{"atb":[[3.35,10.88]],"id":51643934},{"atl":[[4.7,8.22]],"id":51643934}],"con":true,"img":false}]}
{"op":"mcm","clk":"11541144007","pt":1719502691887,"mc":[{"id":"1.230178320","rc":[{"atl":[[4.6,5.52]],"id":51643934}],"con":true,"img":false}]}
{"op":"mcm","clk":"11541144017","pt":1719502691990,"mc":[{"id":"1.230178320","rc":[{"atb":[[1.14,0]],"id":62531723},{"atl":[[5.2,0.03]],"id":51643934}],"con":true,"img":false}]}
{"op":"mcm","clk":"11541144025","pt":1719502692093,"mc":[{"id":"1.230178320","rc":[{"atb":[[5.9,6.17],[6.2,0.05]],"id":62531723},{"atl":[[4.6,12.25]],"id":51643934}],"con":true,"img":false}]}
{"op":"mcm","clk":"11541144045","pt":1719502692303,"mc":[{"id":"1.230178320","rc":[{"atb":[[5,0]],"id":69176305},{"atl":[[4.7,7.22]],"id":51643934}],"con":true,"img":false}]}
{"op":"mcm","clk":"11541144052","pt":1719502692407,"mc":[{"id":"1.230178320","rc":[{"atb":[[4.3,0],[5.2,2]],"id":69176305},{"atb":[[5,1.02]],"id":62531723}],"con":true,"img":false}]}
{"op":"mcm","clk":"11541144062","pt":1719502692466,"mc":[{"id":"1.230178320","rc":[{"atl":[[4.5,1]],"id":51643934}],"con":true,"img":false}]}
{"op":"mcm","clk":"11541144097","pt":1719502692880,"mc":[{"id":"1.230178320","rc":[{"atb":[[5.3,0.84]],"id":69176305}],"con":true,"img":false}]}
{"op":"mcm","clk":"11541144115","pt":1719502693089,"mc":[{"id":"1.230178320","rc":[{"atb":[[5.1,6.2]],"id":69176305},{"atl":[[4.6,6.73]],"id":51643934}],"con":true,"img":false}]}
{"op":"mcm","clk":"11541144135","pt":1719502693399,"mc":[{"id":"1.230178320","rc":[{"atb":[[4.6,0]],"id":69176305},{"atb":[[3.35,0]],"id":51643934}],"con":true,"img":false}]}
{"op":"mcm","clk":"11541144148","pt":1719502693608,"mc":[{"id":"1.230178320","rc":[{"atb":[[5.3,7.21]],"id":69176305},{"atb":[[3.3,10.22]],"id":51643934}],"con":true,"img":false}]}
{"op":"mcm","clk":"11541144161","pt":1719502693769,"mc":[{"id":"1.230178320","rc":[{"atb":[[5.4,4.7]],"id":69176305}],"con":true,"img":false}]}
{"op":"mcm","clk":"11541144176","pt":1719502693976,"mc":[{"id":"1.230178320","rc":[{"atb":[[4.7,2.62]],"id":69176305}],"con":true,"img":false}]}
{"op":"mcm","clk":"11541144192","pt":1719502694184,"mc":[{"id":"1.230178320","rc":[{"atb":[[5.4,10.48]],"id":69176305}],"con":true,"img":false}]}
{"op":"mcm","clk":"11541144210","pt":1719502694390,"mc":[{"id":"1.230178320","rc":[{"atb":[[5.2,0]],"id":69176305}],"con":true,"img":false}]}
{"op":"mcm","clk":"11541144216","pt":1719502694493,"mc":[{"id":"1.230178320","rc":[{"atb":[[5.5,2]],"id":69176305}],"con":true,"img":false}]}
{"op":"mcm","clk":"11541144238","pt":1719502694905,"mc":[{"id":"1.230178320","rc":[{"atb":[[5.4,5.78],[5.5,3.41]],"id":69176305}],"con":true,"img":false}]}
{"op":"mcm","clk":"11541144250","pt":1719502695009,"mc":[{"id":"1.230178320","rc":[{"atb":[[5.3,6.37]],"id":69176305}],"con":true,"img":false}]}
{"op":"mcm","clk":"11541144255","pt":1719502695111,"mc":[{"id":"1.230178320","rc":[{"atb":[[4.9,0],[5.6,4.53]],"id":69176305}],"con":true,"img":false}]}
{"op":"mcm","clk":"11541144263","pt":1719502695167,"mc":[{"id":"1.230178320","rc":[{"atb":[[3.4,4.72]],"id":51643934}],"con":true,"img":false}]}
{"op":"mcm","clk":"11541144270","pt":1719502695271,"mc":[{"id":"1.230178320","rc":[{"atb":[[5.5,9.54]],"id":69176305}],"con":true,"img":false}]}
{"op":"mcm","clk":"11541144324","pt":1719502696098,"mc":[{"id":"1.230178320","rc":[{"atb":[[5.1,0]],"id":69176305}],"con":true,"img":false}]}
{"op":"mcm","clk":"11541144343","pt":1719502696305,"mc":[{"id":"1.230178320","rc":[{"atb":[[5.5,7.54]],"id":69176305}],"con":true,"img":false}]}
{"op":"mcm","clk":"11541144351","pt":1719502696408,"mc":[{"id":"1.230178320","rc":[{"atb":[[5.6,10.02],[5.7,2]],"id":69176305}],"con":true,"img":false}]}
{"op":"mcm","clk":"11541144380","pt":1719502696671,"mc":[{"id":"1.230178320","rc":[{"atb":[[5.6,5.49]],"id":69176305}],"con":true,"img":false}]}
{"op":"mcm","clk":"11541144393","pt":1719502696880,"mc":[{"id":"1.230178320","rc":[{"atb":[[5.8,4.37]],"id":69176305}],"con":true,"img":false}]}
{"op":"mcm","clk":"11541144436","pt":1719502697399,"mc":[{"id":"1.230178320","rc":[{"atb":[[5.7,0]],"id":69176305},{"atb":[[3,1]],"id":51643934}],"con":true,"img":false}]}
{"op":"mcm","clk":"11541144449","pt":1719502697504,"mc":[{"id":"1.230178320","rc":[{"atb":[[5.3,0],[5.9,2]],"id":69176305},{"atb":[[2.74,0]],"id":61419789}],"con":true,"img":false}]}
{"op":"mcm","clk":"11541144475","pt":1719502697710,"mc":[{"id":"1.230178320","rc":[{"atb":[[5.8,9.03]],"id":69176305}],"con":true,"img":false}]}
{"op":"mcm","clk":"11541144503","pt":1719502698079,"mc":[{"id":"1.230178320","rc":[{"atb":[[5.8,4.66]],"id":69176305}],"con":true,"img":false}]}
{"op":"mcm","clk":"11541144678","pt":1719502700305,"mc":[{"id":"1.230178320","rc":[{"atb":[[6,0.84]],"id":69176305}],"con":true,"img":false}]}
{"op":"mcm","clk":"11541145244","pt":1719502707297,"mc":[{"id":"1.230178320","rc":[{"atb":[[3.1,47.62],[2.84,0]],"id":69176305},{"atb":[[4.9,3],[4.1,0]],"id":43498435},{"atb":[[4.3,7.19],[3.8,0]],"id":62531723},{"atl":[[17.5,0],[15.5,6.9]],"id":62531723},{"atl":[[5.4,0],[5,20.83]],"id":51643934}],"con":true,"img":false}]}
{"op":"mcm","clk":"11541145443","pt":1719502709681,"mc":[{"id":"1.230178320","rc":[{"atb":[[3.4,0]],"id":51643934}],"con":true,"img":false}]}
{"op":"mcm","clk":"11541145449","pt":1719502709784,"mc":[{"id":"1.230178320","rc":[{"atb":[[3.6,4.72]],"id":51643934}],"con":true,"img":false}]}
{"op":"mcm","clk":"11541145496","pt":1719502710304,"mc":[{"id":"1.230178320","rc":[{"atb":[[3.65,0.84]],"id":51643934}],"con":true,"img":false}]}
{"op":"mcm","clk":"11541145682","pt":1719502712491,"mc":[{"id":"1.230178320","rc":[{"atb":[[3,0]],"id":51643934}],"con":true,"img":false}]}
{"op":"mcm","clk":"11541145700","pt":1719502712701,"mc":[{"id":"1.230178320","rc":[{"atb":[[4.9,2]],"id":43498435},{"atb":[[4.3,0]],"id":61941199},{"atb":[[3.3,0]],"id":61419789}],"con":true,"img":false}]}
{"op":"mcm","clk":"11541145737","pt":1719502713112,"mc":[{"id":"1.230178320","rc":[{"atb":[[4.9,3]],"id":43498435}],"con":true,"img":false}]}
{"op":"mcm","clk":"11541145774","pt":1719502713527,"mc":[{"id":"1.230178320","rc":[{"atb":[[4.7,0.06]],"id":69176305},{"atb":[[5.3,6.36]],"id":61941199},{"atb":[[3.55,10.04]],"id":61419789},{"atb":[[5.7,5.24]],"id":62531723}],"con":true,"img":false}]}
{"op":"mcm","clk":"11541145791","pt":1719502713684,"mc":[{"id":"1.230178320","rc":[{"atb":[[5.8,5.78]],"id":62531723}],"con":true,"img":false}]}
{"op":"mcm","clk":"11541145799","pt":1719502713788,"mc":[{"id":"1.230178320","rc":[{"atb":[[6,1.84]],"id":62531723}],"con":true,"img":false}]}
{"op":"mcm","clk":"11541145810","pt":1719502713893,"mc":[{"id":"1.230178320","rc":[{"atb":[[2.18,0]],"id":61419789}],"con":true,"img":false}]}
{"op":"mcm","clk":"11541145828","pt":1719502714104,"mc":[{"id":"1.230178320","rc":[{"atb":[[6.2,4.14]],"id":62531723}],"con":true,"img":false}]}
{"op":"mcm","clk":"11541145885","pt":1719502714724,"mc":[{"id":"1.230178320","rc":[{"atb":[[6.4,0.84]],"id":62531723}],"con":true,"img":false}]}
{"op":"mcm","clk":"11541145938","pt":1719502715193,"mc":[{"id":"1.230178320","rc":[{"atb":[[6.2,0.05]],"id":62531723}],"con":true,"img":false}]}
{"op":"mcm","clk":"11541146004","pt":1719502715913,"mc":[{"id":"1.230178320","rc":[{"atb":[[6.4,0]],"id":62531723}],"con":true,"img":false}]}
{"op":"mcm","clk":"11541146061","pt":1719502716535,"mc":[{"id":"1.230178320","rc":[{"atb":[[6.2,4.14]],"id":62531723}],"con":true,"img":false}]}
{"op":"mcm","clk":"11541146128","pt":1719502717314,"mc":[{"id":"1.230178320","rc":[{"atb":[[4.9,2]],"id":43498435}],"con":true,"img":false}]}
{"op":"mcm","clk":"11541146206","pt":1719502718303,"mc":[{"id":"1.230178320","rc":[{"atb":[[3.85,0],[3.35,10.12]],"id":61941199}],"con":true,"img":false}]}
{"op":"mcm","clk":"11541146236","pt":1719502718818,"mc":[{"id":"1.230178320","rc":[{"atb":[[4.9,3]],"id":43498435},{"atb":[[5.8,0],[5.7,0.46]],"id":61941199},{"trd":[[5.7,1.9],[5.8,0.1]],"ltp":5.7,"tv":2.0,"id":61941199}],"con":true,"img":false}]}
{"op":"mcm","clk":"11541146251","pt":1719502719023,"mc":[{"id":"1.230178320","rc":[{"atb":[[5.7,4.91]],"id":61941199},{"atl":[[1000,0.25]],"id":61941199}],"con":true,"img":false}]}
{"op":"mcm","clk":"11541146260","pt":1719502719127,"mc":[{"id":"1.230178320","rc":[{"atb":[[5.1,0.79]],"id":43498435},{"atb":[[4.7,0]],"id":69176305},{"atb":[[5.7,3.91]],"id":61941199},{"trd":[[5.7,3.9]],"ltp":5.7,"tv":3.9,"id":61941199},{"atb":[[5.1,0]],"id":61419789},{"atb":[[6.4,1.32],[6.2,4.09]],"id":62531723}],"con":true,"img":false}]}
{"op":"mcm","clk":"11541146268","pt":1719502719230,"mc":[{"id":"1.230178320","rc":[{"atl":[[1000,0.16]],"id":61941199}],"con":true,"img":false}]}
{"op":"mcm","clk":"11541146277","pt":1719502719336,"mc":[{"id":"1.230178320","rc":[{"atb":[[5.5,1.54]],"id":61941199},{"atl":[[12.5,0.76]],"id":61941199}],"con":true,"img":false}]}
{"op":"mcm","clk":"11541146291","pt":1719502719496,"mc":[{"id":"1.230178320","rc":[{"atb":[[5.9,4.74]],"id":62531723}],"con":true,"img":false}]}
{"op":"mcm","clk":"11541146309","pt":1719502719705,"mc":[{"id":"1.230178320","rc":[{"atb":[[5.1,1.63]],"id":43498435},{"atl":[[12.5,1.61]],"id":61941199},{"atb":[[6.2,0]],"id":62531723}],"con":true,"img":false}]}
{"op":"mcm","clk":"11541146319","pt":1719502719807,"mc":[{"id":"1.230178320","rc":[{"atl":[[13.5,4.45],[30,1]],"id":61941199}],"con":true,"img":false}]}
{"op":"mcm","clk":"11541146335","pt":1719502720012,"mc":[{"id":"1.230178320","rc":[{"atb":[[4.4,0]],"id":43498435},{"atl":[[30,0]],"id":61941199},{"atb":[[6.2,1.32]],"id":62531723}],"con":true,"img":false}]}
{"op":"mcm","clk":"11541146341","pt":1719502720118,"mc":[{"id":"1.230178320","rc":[{"atb":[[6.4,0]],"id":62531723}],"con":true,"img":false}]}
{"op":"mcm","clk":"11541146348","pt":1719502720220,"mc":[{"id":"1.230178320","rc":[{"atb":[[4.7,1]],"id":43498435},{"atl":[[12.5,3.63],[13,2]],"id":61941199}],"con":true,"img":false}]}
{"op":"mcm","clk":"11541146367","pt":1719502720425,"mc":[{"id":"1.230178320","rc":[{"atb":[[3.6,3.08]],"id":61419789}],"con":true,"img":false}]}
{"op":"mcm","clk":"11541146462","pt":1719502721719,"mc":[{"id":"1.230178320","rc":[{"atb":[[3.65,10.34]],"id":61419789}],"con":true,"img":false}]}
{"op":"mcm","clk":"11541146475","pt":1719502721924,"mc":[{"id":"1.230178320","rc":[{"atb":[[3.7,10.04]],"id":61419789}],"con":true,"img":false}]}
{"op":"mcm","clk":"11541146485","pt":1719502722027,"mc":[{"id":"1.230178320","rc":[{"atb":[[3.45,0]],"id":61419789}],"con":true,"img":false}]}
{"op":"mcm","clk":"11541146502","pt":1719502722235,"mc":[{"id":"1.230178320","rc":[{"atb":[[3.6,2.08]],"id":61419789}],"con":true,"img":false}]}
{"op":"mcm","clk":"11541146511","pt":1719502722391,"mc":[{"id":"1.230178320","rc":[{"atb":[[3.75,1]],"id":61419789}],"con":true,"img":false}]}
{"op":"mcm","clk":"11541146519","pt":1719502722494,"mc":[{"id":"1.230178320","rc":[{"atb":[[3.75,9.99]],"id":61419789},{"atb":[[5,2.02]],"id":62531723}],"con":true,"img":false}]}
{"op":"mcm","clk":"11541146565","pt":1719502723222,"mc":[{"id":"1.230178320","rc":[{"atb":[[3.8,5.26]],"id":51643934}],"con":true,"img":false}]}
{"op":"mcm","clk":"11541146608","pt":1719502723841,"mc":[{"id":"1.230178320","rc":[{"atb":[[3.85,0.84],[3.55,0],[3.65,0]],"id":51643934}],"con":true,"img":false}]}
{"op":"mcm","clk":"11541147408","pt":1719502732936,"mc":[{"id":"1.230178320","rc":[{"atb":[[3.5,0]],"id":51643934}],"con":true,"img":false}]}
{"op":"mcm","clk":"11541147527","pt":1719502734544,"mc":[{"id":"1.230178320","rc":[{"atl":[[12.5,3.54]],"id":61941199}],"con":true,"img":false}]}
{"op":"mcm","clk":"11541147566","pt":1719502735014,"mc":[{"id":"1.230178320","rc":[{"atl":[[1000,0.25]],"id":61941199},{"atl":[[5,13.89]],"id":51643934}],"con":true,"img":false}]}
{"op":"mcm","clk":"11541147576","pt":1719502735123,"mc":[{"id":"1.230178320","rc":[{"atl":[[1000,0.16]],"id":61941199}],"con":true,"img":false}]}
{"op":"mcm","clk":"11541147587","pt":1719502735227,"mc":[{"id":"1.230178320","rc":[{"atl":[[12,0.09]],"id":61941199}],"con":true,"img":false}]}
{"op":"mcm","clk":"11541147601","pt":1719502735434,"mc":[{"id":"1.230178320","rc":[{"atb":[[3.85,0]],"id":51643934},{"trd":[[3.85,1.69]],"ltp":3.85,"tv":1.69,"id":51643934}],"con":true,"img":false}]}
{"op":"mcm","clk":"11541148015","pt":1719502740417,"mc":[{"id":"1.230178320","rc":[{"atl":[[1000,0.43]],"id":43498435},{"atl":[[1000,0.69]],"id":69176305},{"atl":[[1000,0.57]],"id":61941199},{"atl":[[1000,0.71]],"id":61419789},{"atl":[[1000,0.54]],"id":62531723}],"con":true,"img":false}]}
{"op":"mcm","clk":"11541148028","pt":1719502740624,"mc":[{"id":"1.230178320","rc":[{"atl":[[1000,0.16]],"id":43498435},{"atl":[[1000,0.16]],"id":69176305},{"atl":[[1000,0.16]],"id":61941199},{"atl":[[1000,0.16]],"id":61419789},{"atl":[[1000,0.16]],"id":62531723}],"con":true,"img":false}]}
{"op":"mcm","clk":"11541148036","pt":1719502740727,"mc":[{"id":"1.230178320","rc":[{"atl":[[19,1.27]],"id":43498435},{"atl":[[9.6,1.53]],"id":69176305},{"atl":[[12.5,3.95]],"id":61941199},{"atl":[[9.2,1.55]],"id":61419789},{"atl":[[13.5,3.78]],"id":62531723}],"con":true,"img":false}]}
{"op":"mcm","clk":"11541148090","pt":1719502741305,"mc":[{"id":"1.230178320","rc":[{"atl":[[18.5,1.3]],"id":43498435}],"con":true,"img":false}]}
{"op":"mcm","clk":"11541148096","pt":1719502741458,"mc":[{"id":"1.230178320","rc":[{"atl":[[21,5]],"id":43498435},{"atl":[[9.4,3.9]],"id":69176305}],"con":true,"img":false}]}
{"op":"mcm","clk":"11541148106","pt":1719502741513,"mc":[{"id":"1.230178320","rc":[{"atl":[[34,0]],"id":43498435}],"con":true,"img":false}]}
{"op":"mcm","clk":"11541148114","pt":1719502741617,"mc":[{"id":"1.230178320","rc":[{"atl":[[32,0]],"id":69176305}],"con":true,"img":false}]}
{"op":"mcm","clk":"11541148122","pt":1719502741723,"mc":[{"id":"1.230178320","rc":[{"atl":[[9.2,2.84]],"id":69176305}],"con":true,"img":false}]}
{"op":"mcm","clk":"11541148173","pt":1719502742241,"mc":[{"id":"1.230178320","rc":[{"atl":[[20,4]],"id":61419789}],"con":true,"img":false}]}
{"op":"mcm","clk":"11541148204","pt":1719502742554,"mc":[{"id":"1.230178320","rc":[{"atb":[[5.8,0],[5.9,0]],"id":69176305}],"con":true,"img":false}]}
{"op":"mcm","clk":"11541148219","pt":1719502742610,"mc":[{"id":"1.230178320","rc":[{"atb":[[1.02,24.65],[5.7,5.5]],"id":69176305},{"atl":[[9.2,6.06]],"id":69176305}],"con":true,"img":false}]}
{"op":"mcm","clk":"11541148229","pt":1719502742716,"mc":[{"id":"1.230178320","rc":[{"atb":[[4.3,1]],"id":69176305}],"con":true,"img":false}]}
{"op":"mcm","clk":"11541148277","pt":1719502743236,"mc":[{"id":"1.230178320","rc":[{"atb":[[6,0]],"id":69176305}],"con":true,"img":false}]}
{"op":"mcm","clk":"11541148313","pt":1719502743653,"mc":[{"id":"1.230178320","rc":[{"atb":[[5.8,4.37]],"id":69176305}],"con":true,"img":false}]}
{"op":"mcm","clk":"11541148335","pt":1719502743813,"mc":[{"id":"1.230178320","rc":[{"atb":[[5.8,5.22]],"id":69176305}],"con":true,"img":false}]}
{"op":"mcm","clk":"11541148390","pt":1719502744332,"mc":[{"id":"1.230178320","rc":[{"atb":[[5.6,5.35],[5.7,0]],"id":69176305}],"con":true,"img":false}]}
{"op":"mcm","clk":"11541148402","pt":1719502744434,"mc":[{"id":"1.230178320","rc":[{"atb":[[3,9.28]],"id":51643934}],"con":true,"img":false}]}
{"op":"mcm","clk":"11541148480","pt":1719502745214,"mc":[{"id":"1.230178320","rc":[{"atl":[[9,1.51]],"id":61419789}],"con":true,"img":false}]}
{"op":"mcm","clk":"11541148487","pt":1719502745317,"mc":[{"id":"1.230178320","rc":[{"atl":[[20,0],[12,4]],"id":61419789}],"con":true,"img":false}]}
{"op":"mcm","clk":"11541148659","pt":1719502747361,"mc":[{"id":"1.230178320","rc":[{"spn":5.8,"spf":1.0,"id":69176305},{"atb":[[4.9,2],[5.2,1]],"id":43498435},{"spn":11.85,"spf":"NaN","id":43498435},{"spn":8.85,"spf":"NaN","id":61941199},{"spn":5.0,"spf":1.0,"id":61419789},{"spn":9.85,"spf":"NaN","id":62531723},{"spn":3.8,"spf":1.0,"id":51643934}],"con":true,"img":false}]}
{"op":"mcm","clk":"11541148671","pt":1719502747415,"mc":[{"id":"1.230178320","rc":[{"atb":[[4.7,0]],"id":43498435}],"con":true,"img":false}]}
{"op":"mcm","clk":"11541148693","pt":1719502747627,"mc":[{"id":"1.230178320","rc":[{"atb":[[5.3,1]],"id":43498435}],"con":true,"img":false}]}
{"op":"mcm","clk":"11541148706","pt":1719502747729,"mc":[{"id":"1.230178320","rc":[{"atb":[[4.3,0]],"id":69176305}],"con":true,"img":false}]}
{"op":"mcm","clk":"11541148740","pt":1719502748144,"mc":[{"id":"1.230178320","rc":[{"atb":[[4.9,3],[5.2,0]],"id":43498435}],"con":true,"img":false}]}
{"op":"mcm","clk":"11541148937","pt":1719502750028,"mc":[{"id":"1.230178320","rc":[{"atb":[[4.9,2]],"id":43498435}],"con":true,"img":false}]}
{"op":"mcm","clk":"11541148983","pt":1719502750442,"mc":[{"id":"1.230178320","rc":[{"atl":[[12,0]],"id":61941199}],"con":true,"img":false}]}
{"op":"mcm","clk":"11541149066","pt":1719502751120,"mc":[{"id":"1.230178320","rc":[{"atl":[[1000,0.25]],"id":61941199}],"con":true,"img":false}]}
{"op":"mcm","clk":"11541149084","pt":1719502751323,"mc":[{"id":"1.230178320","rc":[{"atl":[[1000,0.16]],"id":61941199}],"con":true,"img":false}]}
{"op":"mcm","clk":"11541149095","pt":1719502751428,"mc":[{"id":"1.230178320","rc":[{"atl":[[12,0.09]],"id":61941199}],"con":true,"img":false}]}
{"op":"mcm","clk":"11541149132","pt":1719502751738,"mc":[{"id":"1.230178320","rc":[{"atl":[[18.5,2.3],[19,0.27]],"id":43498435},{"atl":[[9.6,0.53],[8.6,1]],"id":69176305},{"atl":[[12.5,4.95]],"id":61941199}],"con":true,"img":false}]}
{"op":"mcm","clk":"11541149144","pt":1719502751842,"mc":[{"id":"1.230178320","rc":[{"atb":[[4.9,0],[5.1,3.63]],"id":43498435},{"atl":[[18.5,4.3],[21,0]],"id":43498435},{"atl":[[13,1],[13.5,0]],"id":61941199},{"atl":[[9.2,0.55],[11,4],[12,0],[9.4,1]],"id":61419789},{"atb":[[4.3,0],[5,11.5]],"id":62531723},{"atb":[[2.6,62.5],[2.42,0]],"id":51643934},{"atl":[[4.6,13.89],[5,0]],"id":51643934}],"con":true,"img":false}]}
{"op":"mcm","clk":"11541149155","pt":1719502751945,"mc":[{"id":"1.230178320","rc":[{"atl":[[12,2.09],[13,0]],"id":61941199}],"con":true,"img":false}]}
{"op":"mcm","clk":"11541149163","pt":1719502752051,"mc":[{"id":"1.230178320","rc":[{"atb":[[5.3,0]],"id":43498435}],"con":true,"img":false}]}
{"op":"mcm","clk":"11541149172","pt":1719502752154,"mc":[{"id":"1.230178320","rc":[{"atl":[[13,1]],"id":61941199}],"con":true,"img":false}]}
{"op":"mcm","clk":"11541149176","pt":1719502752256,"mc":[{"id":"1.230178320","rc":[{"atb":[[5.2,1]],"id":43498435},{"atl":[[1000,1.01]],"id":61941199}],"con":true,"img":false}]}
{"op":"mcm","clk":"11541149187","pt":1719502752360,"mc":[{"id":"1.230178320","rc":[{"atl":[[11.5,0.84],[12,4.14],[12.5,4.27]],"id":61941199}],"con":true,"img":false}]}
{"op":"mcm","clk":"11541149212","pt":1719502752624,"mc":[{"id":"1.230178320","rc":[{"atl":[[1000,0.9]],"id":61941199},{"atb":[[2.72,6.89]],"id":51643934}],"con":true,"img":false}]}
{"op":"mcm","clk":"11541149228","pt":1719502752833,"mc":[{"id":"1.230178320","rc":[{"atb":[[2.88,6.3],[5,10.5]],"id":62531723}],"con":true,"img":false}]}
{"op":"mcm","clk":"11541149241","pt":1719502753040,"mc":[{"id":"1.230178320","rc":[{"atb":[[3.15,5.51]],"id":69176305},{"atl":[[1000,0.16]],"id":61941199}],"con":true,"img":false}]}
{"op":"mcm","clk":"11541149253","pt":1719502753146,"mc":[{"id":"1.230178320","rc":[{"atb":[[3.4,4.94]],"id":61941199},{"atl":[[11.5,1.58]],"id":61941199}],"con":true,"img":false}]}
{"op":"mcm","clk":"11541149262","pt":1719502753256,"mc":[{"id":"1.230178320","rc":[{"atb":[[2.74,6.81]],"id":61419789}],"con":true,"img":false}]}
{"op":"mcm","clk":"11541149337","pt":1719502754031,"mc":[{"id":"1.230178320","rc":[{"atl":[[11.5,4.09]],"id":61941199}],"con":true,"img":false}]}
{"op":"mcm","clk":"11541149425","pt":1719502754963,"mc":[{"id":"1.230178320","rc":[{"atl":[[12.5,3.43]],"id":61941199}],"con":true,"img":false}]}
{"op":"mcm","clk":"11541149438","pt":1719502755018,"mc":[{"id":"1.230178320","rc":[{"atl":[[9.6,0]],"id":69176305},{"atl":[[19,0]],"id":43498435},{"atl":[[12.5,3.02]],"id":61941199},{"atl":[[9.2,0]],"id":61419789}],"con":true,"img":false}]}
{"op":"mcm","clk":"11541149456","pt":1719502755225,"mc":[{"id":"1.230178320","rc":[{"atl":[[13.5,3.4]],"id":62531723}],"con":true,"img":false}]}
{"op":"mcm","clk":"11541149813","pt":1719502758725,"mc":[{"id":"1.230178320","rc":[{"atl":[[18.5,3.3],[19,1]],"id":43498435}],"con":true,"img":false}]}
{"op":"mcm","clk":"11541149823","pt":1719502758828,"mc":[{"id":"1.230178320","rc":[{"atl":[[34,3.03],[18.5,1.3]],"id":43498435}],"con":true,"img":false}]}
{"op":"mcm","clk":"11541149833","pt":1719502758931,"mc":[{"id":"1.230178320","rc":[{"atb":[[4.9,6],[5.1,1.63]],"id":43498435}],"con":true,"img":false}]}
{"op":"mcm","clk":"11541149843","pt":1719502759039,"mc":[{"id":"1.230178320","rc":[{"atl":[[34,0],[21,5]],"id":43498435}],"con":true,"img":false}]}
{"op":"mcm","clk":"11541149854","pt":1719502759139,"mc":[{"id":"1.230178320","rc":[{"atb":[[5.2,0]],"id":43498435}],"con":true,"img":false}]}
{"op":"mcm","clk":"11541149873","pt":1719502759347,"mc":[{"id":"1.230178320","rc":[{"atb":[[5.4,1]],"id":43498435}],"con":true,"img":false}]}
{"op":"mcm","clk":"11541149988","pt":1719502760434,"mc":[{"id":"1.230178320","rc":[{"atl":[[1000,0.44]],"id":43498435},{"atl":[[1000,0.6]],"id":61941199},{"atl":[[1000,0.73]],"id":61419789},{"atl":[[1000,0.54]],"id":62531723}],"con":true,"img":false}]}
{"op":"mcm","clk":"11541149996","pt":1719502760536,"mc":[{"id":"1.230178320","rc":[{"atb":[[3.75,11.99]],"id":61419789}],"con":true,"img":false}]}
{"op":"mcm","clk":"11541150005","pt":1719502760639,"mc":[{"id":"1.230178320","rc":[{"atl":[[1000,0.16]],"id":43498435},{"atl":[[1000,0.16]],"id":61941199},{"atl":[[1000,0.16]],"id":61419789},{"atl":[[1000,0.16]],"id":62531723}],"con":true,"img":false}]}
{"op":"mcm","clk":"11541150011","pt":1719502760745,"mc":[{"id":"1.230178320","rc":[{"atl":[[18.5,1.58]],"id":43498435},{"atl":[[11.5,4.53]],"id":61941199},{"atl":[[9,2.08]],"id":61419789},{"atl":[[13.5,3.78]],"id":62531723}],"con":true,"img":false}]}
{"op":"mcm","clk":"11541150074","pt":1719502761364,"mc":[{"id":"1.230178320","rc":[{"atl":[[8.8,0.84]],"id":61419789}],"con":true,"img":false}]}
{"op":"mcm","clk":"11541150193","pt":1719502762571,"mc":[{"id":"1.230178320","rc":[{"atb":[[5.1,0.84]],"id":43498435}],"con":true,"img":false}]}
{"op":"mcm","clk":"11541150412","pt":1719502764646,"mc":[{"id":"1.230178320","rc":[{"atb":[[4.9,0],[5.1,2.84]],"id":43498435}],"con":true,"img":false}]}
{"op":"mcm","clk":"11541150615","pt":1719502766766,"mc":[{"id":"1.230178320","rc":[{"atl":[[12,4.05]],"id":61941199}],"con":true,"img":false}]}
{"op":"mcm","clk":"11541150650","pt":1719502767129,"mc":[{"id":"1.230178320","rc":[{"atl":[[1000,0.26]],"id":61941199}],"con":true,"img":false}]}
{"op":"mcm","clk":"11541150667","pt":1719502767338,"mc":[{"id":"1.230178320","rc":[{"atl":[[1000,0.16]],"id":61941199}],"con":true,"img":false}]}
{"op":"mcm","clk":"11541150679","pt":1719502767441,"mc":[{"id":"1.230178320","rc":[{"atl":[[11,0.1]],"id":61941199}],"con":true,"img":false}]}
{"op":"mcm","clk":"11541150840","pt":1719502769159,"mc":[{"id":"1.230178320","rc":[{"atl":[[19,0],[19.5,1]],"id":43498435},{"atl":[[12.5,2.02],[13,2]],"id":61941199},{"atl":[[14,0],[14.5,1]],"id":62531723}],"con":true,"img":false}]}
{"op":"mcm","clk":"11541150863","pt":1719502769365,"mc":[{"id":"1.230178320","rc":[{"atb":[[3.6,10.12],[3.35,0]],"id":61941199},{"atl":[[13,1]],"id":61941199},{"atl":[[9.4,0],[9.6,1]],"id":61419789}],"con":true,"img":false}]}
{"op":"mcm","clk":"11541150881","pt":1719502769570,"mc":[{"id":"1.230178320","rc":[{"atl":[[11,1.1]],"id":61941199}],"con":true,"img":false}]}
{"op":"mcm","clk":"11541150911","pt":1719502769880,"mc":[{"id":"1.230178320","rc":[{"atl":[[18.5,0.73]],"id":43498435}],"con":true,"img":false}]}
{"op":"mcm","clk":"11541150954","pt":1719502770246,"mc":[{"id":"1.230178320","rc":[{"atl":[[29,0]],"id":61941199}],"con":true,"img":false}]}
{"op":"mcm","clk":"11541150966","pt":1719502770354,"mc":[{"id":"1.230178320","rc":[{"atl":[[19,0.84]],"id":43498435}],"con":true,"img":false}]}
{"op":"mcm","clk":"11541150977","pt":1719502770455,"mc":[{"id":"1.230178320","rc":[{"atl":[[11,3.5]],"id":61941199}],"con":true,"img":false}]}
{"op":"mcm","clk":"11541151021","pt":1719502770871,"mc":[{"id":"1.230178320","rc":[{"atl":[[10.5,0.84]],"id":61941199}],"con":true,"img":false}]}
{"op":"mcm","clk":"11541151354","pt":1719502774870,"mc":[{"id":"1.230178320","rc":[{"atl":[[11.5,4.09]],"id":61941199},{"atl":[[13.5,3.4]],"id":62531723}],"con":true,"img":false}]}
{"op":"mcm","clk":"11541151363","pt":1719502774973,"mc":[{"id":"1.230178320","rc":[{"atl":[[18.5,0.45]],"id":43498435},{"atl":[[9,1.51]],"id":61419789}],"con":true,"img":false}]}
{"op":"mcm","clk":"11541151862","pt":1719502780461,"mc":[{"id":"1.230178320","rc":[{"atl":[[1000,0.43]],"id":43498435},{"atl":[[1000,0.73]],"id":61419789},{"atl":[[1000,0.54]],"id":62531723}],"con":true,"img":false}]}
{"op":"mcm","clk":"11541151877","pt":1719502780670,"mc":[{"id":"1.230178320","rc":[{"atl":[[1000,0.16]],"id":43498435},{"atb":[[3.6,0]],"id":61419789},{"atl":[[1000,0.16]],"id":61419789},{"atl":[[1000,0.16]],"id":62531723}],"con":true,"img":false}]}
{"op":"mcm","clk":"11541151886","pt":1719502780776,"mc":[{"id":"1.230178320","rc":[{"atl":[[19,1.11]],"id":43498435},{"atl":[[9,2.08]],"id":61419789},{"atl":[[13.5,3.78]],"id":62531723}],"con":true,"img":false}]}
{"op":"mcm","clk":"11541152039","pt":1719502782659,"mc":[{"id":"1.230178320","rc":[{"atl":[[11,3.4]],"id":61941199}],"con":true,"img":false}]}
{"op":"mcm","clk":"11541152067","pt":1719502782975,"mc":[{"id":"1.230178320","rc":[{"atl":[[1000,0.27]],"id":61941199}],"con":true,"img":false}]}
{"op":"mcm","clk":"11541152094","pt":1719502783284,"mc":[{"id":"1.230178320","rc":[{"atl":[[1000,0.16]],"id":61941199}],"con":true,"img":false}]}
{"op":"mcm","clk":"11541152104","pt":1719502783391,"mc":[{"id":"1.230178320","rc":[{"atl":[[10.5,0.95]],"id":61941199}],"con":true,"img":false}]}
{"op":"mcm","clk":"11541152136","pt":1719502783762,"mc":[{"id":"1.230178320","rc":[{"atl":[[8.4,1.58]],"id":69176305}],"con":true,"img":false}]}
{"op":"mcm","clk":"11541152141","pt":1719502783864,"mc":[{"id":"1.230178320","rc":[{"atl":[[9.2,4.06],[8.4,3.58]],"id":69176305}],"con":true,"img":false}]}
{"op":"mcm","clk":"11541152148","pt":1719502783984,"mc":[{"id":"1.230178320","rc":[{"atl":[[8.4,7.19]],"id":69176305}],"con":true,"img":false}]}
{"op":"mcm","clk":"11541152157","pt":1719502784081,"mc":[{"id":"1.230178320","rc":[{"atl":[[8.4,8.77]],"id":69176305}],"con":true,"img":false}]}
{"op":"mcm","clk":"11541152170","pt":1719502784277,"mc":[{"id":"1.230178320","rc":[{"atl":[[8.4,10.35]],"id":69176305}],"con":true,"img":false}]}
{"op":"mcm","clk":"11541152180","pt":1719502784381,"mc":[{"id":"1.230178320","rc":[{"atl":[[9.2,3.22],[8.2,0.84]],"id":69176305}],"con":true,"img":false}]}
{"op":"mcm","clk":"11541152189","pt":1719502784485,"mc":[{"id":"1.230178320","rc":[{"atl":[[8.2,2.42]],"id":69176305}],"con":true,"img":false}]}
{"op":"mcm","clk":"11541152207","pt":1719502784690,"mc":[{"id":"1.230178320","rc":[{"atl":[[8,1.58]],"id":69176305}],"con":true,"img":false}]}
{"op":"mcm","clk":"11541152214","pt":1719502784794,"mc":[{"id":"1.230178320","rc":[{"atl":[[8,4.01],[8.4,8.35],[30,0]],"id":69176305}],"con":true,"img":false}]}
{"op":"mcm","clk":"11541152222","pt":1719502784849,"mc":[{"id":"1.230178320","rc":[{"atl":[[8,5.59]],"id":69176305}],"con":true,"img":false}]}
{"op":"mcm","clk":"11541152233","pt":1719502784951,"mc":[{"id":"1.230178320","rc":[{"atl":[[8.2,5.49]],"id":69176305}],"con":true,"img":false}]}
{"op":"mcm","clk":"11541152243","pt":1719502785055,"mc":[{"id":"1.230178320","rc":[{"atl":[[7.8,1.58]],"id":69176305}],"con":true,"img":false}]}
{"op":"mcm","clk":"11541152257","pt":1719502785262,"mc":[{"id":"1.230178320","rc":[{"atl":[[7.6,1.58]],"id":69176305}],"con":true,"img":false}]}
{"op":"mcm","clk":"11541152281","pt":1719502785578,"mc":[{"id":"1.230178320","rc":[{"atl":[[7.4,1.58]],"id":69176305}],"con":true,"img":false}]}
{"op":"mcm","clk":"11541152303","pt":1719502785791,"mc":[{"id":"1.230178320","rc":[{"atl":[[7.2,1.58]],"id":69176305}],"con":true,"img":false}]}
{"op":"mcm","clk":"11541152313","pt":1719502785892,"mc":[{"id":"1.230178320","rc":[{"atl":[[8.2,4.65]],"id":69176305}],"con":true,"img":false}]}
{"op":"mcm","clk":"11541152321","pt":1719502785946,"mc":[{"id":"1.230178320","rc":[{"atl":[[9.4,0.89]],"id":69176305}],"con":true,"img":false}]}
{"op":"mcm","clk":"11541152331","pt":1719502786049,"mc":[{"id":"1.230178320","rc":[{"atl":[[7.2,3.16],[7.6,5.4]],"id":69176305}],"con":true,"img":false}]}
{"op":"mcm","clk":"11541152362","pt":1719502786362,"mc":[{"id":"1.230178320","rc":[{"atl":[[7.2,4.74]],"id":69176305}],"con":true,"img":false}]}
{"op":"mcm","clk":"11541152385","pt":1719502786570,"mc":[{"id":"1.230178320","rc":[{"atl":[[7,1.58]],"id":69176305}],"con":true,"img":false}]}
{"op":"mcm","clk":"11541152402","pt":1719502786776,"mc":[{"id":"1.230178320","rc":[{"atl":[[7,3.16]],"id":69176305}],"con":true,"img":false}]}
{"op":"mcm","clk":"11541152429","pt":1719502787088,"mc":[{"id":"1.230178320","rc":[{"atl":[[6.8,1.58]],"id":69176305}],"con":true,"img":false}]}
{"op":"mcm","clk":"11541152455","pt":1719502787294,"mc":[{"id":"1.230178320","rc":[{"atl":[[6.6,1.58]],"id":69176305}],"con":true,"img":false}]}
{"op":"mcm","clk":"11541152477","pt":1719502787454,"mc":[{"id":"1.230178320","rc":[{"atl":[[6.6,3.16]],"id":69176305}],"con":true,"img":false}]}
{"op":"mcm","clk":"11541152515","pt":1719502787763,"mc":[{"id":"1.230178320","rc":[{"atl":[[6.4,1.58]],"id":69176305}],"con":true,"img":false}]}
{"op":"mcm","clk":"11541152553","pt":1719502788180,"mc":[{"id":"1.230178320","rc":[{"atl":[[6.4,3.16]],"id":69176305}],"con":true,"img":false}]}
{"op":"mcm","clk":"11541152573","pt":1719502788389,"mc":[{"id":"1.230178320","rc":[{"atl":[[6.4,4.74],[9.2,0]],"id":69176305}],"con":true,"img":false}]}
{"op":"mcm","clk":"11541152586","pt":1719502788593,"mc":[{"id":"1.230178320","rc":[{"atl":[[7.4,5.82]],"id":69176305}],"con":true,"img":false}]}
{"op":"mcm","clk":"11541152597","pt":1719502788696,"mc":[{"id":"1.230178320","rc":[{"atl":[[6.4,6.32]],"id":69176305}],"con":true,"img":false}]}
{"op":"mcm","clk":"11541152616","pt":1719502788855,"mc":[{"id":"1.230178320","rc":[{"atl":[[6.2,1.58]],"id":69176305}],"con":true,"img":false}]}
{"op":"mcm","clk":"11541152637","pt":1719502789063,"mc":[{"id":"1.230178320","rc":[{"atb":[[5.8,10.44]],"id":69176305},{"atl":[[6.2,3.16]],"id":69176305}],"con":true,"img":false}]}
{"op":"mcm","clk":"11541152662","pt":1719502789375,"mc":[{"id":"1.230178320","rc":[{"atl":[[6,1.58]],"id":69176305}],"con":true,"img":false}]}
{"op":"mcm","clk":"11541152683","pt":1719502789594,"mc":[{"id":"1.230178320","rc":[{"atb":[[5.5,6.13]],"id":69176305},{"atl":[[6,3.16]],"id":69176305}],"con":true,"img":false}]}
{"op":"mcm","clk":"11541152714","pt":1719502789896,"mc":[{"id":"1.230178320","rc":[{"atl":[[6,4.74]],"id":69176305}],"con":true,"img":false}]}
{"op":"mcm","clk":"11541152722","pt":1719502790000,"mc":[{"id":"1.230178320","rc":[{"atb":[[5.4,0]],"id":69176305}],"con":true,"img":false}]}
{"op":"mcm","clk":"11541152730","pt":1719502790061,"mc":[{"id":"1.230178320","rc":[{"atl":[[5.9,1.58]],"id":69176305}],"con":true,"img":false}]}
{"op":"mcm","clk":"11541152739","pt":1719502790169,"mc":[{"id":"1.230178320","rc":[{"atl":[[5.9,0],[6,1.82]],"id":69176305},{"trd":[[6,5.83],[5.9,3.16]],"ltp":6.0,"tv":8.99,"id":69176305},{"atb":[[3.35,5.04]],"id":43498435}],"con":true,"img":false}]}
{"op":"mcm","clk":"11541152750","pt":1719502790274,"mc":[{"id":"1.230178320","rc":[{"atl":[[8,3.16],[6.4,12.64],[5.9,1.58]],"id":69176305}],"con":true,"img":false}]}
{"op":"mcm","clk":"11541152776","pt":1719502790588,"mc":[{"id":"1.230178320","rc":[{"atl":[[5.9,3.16]],"id":69176305}],"con":true,"img":false}]}
{"op":"mcm","clk":"11541152797","pt":1719502790785,"mc":[{"id":"1.230178320","rc":[{"atb":[[5.8,5.22],[5.6,0],[5.5,0]],"id":69176305},{"atl":[[5.9,4.74]],"id":69176305}],"con":true,"img":false}]}
{"op":"mcm","clk":"11541152808","pt":1719502790889,"mc":[{"id":"1.230178320","rc":[{"atb":[[5.8,0]],"id":69176305},{"trd":[[5.8,10.45]],"ltp":5.8,"tv":10.45,"id":69176305}],"con":true,"img":false}]}
{"op":"mcm","clk":"11541152818","pt":1719502790991,"mc":[{"id":"1.230178320","rc":[{"atb":[[4.2,7.12]],"id":69176305},{"atl":[[5.9,6.32]],"id":69176305}],"con":true,"img":false}]}
{"op":"mcm","clk":"11541152850","pt":1719502791303,"mc":[{"id":"1.230178320","rc":[{"atb":[[3.2,2.34]],"id":69176305},{"atl":[[5.8,1.58]],"id":69176305}],"con":true,"img":false}]}
{"op":"mcm","clk":"11541152860","pt":1719502791365,"mc":[{"id":"1.230178320","rc":[{"atb":[[4.3,0.84]],"id":69176305},{"atl":[[5.8,5.95]],"id":69176305}],"con":true,"img":false}]}
{"op":"mcm","clk":"11541152870","pt":1719502791460,"mc":[{"id":"1.230178320","rc":[{"atl":[[5.8,7.53]],"id":69176305}],"con":true,"img":false}]}
{"op":"mcm","clk":"11541152878","pt":1719502791574,"mc":[{"id":"1.230178320","rc":[{"atl":[[10,0.84]],"id":61941199}],"con":true,"img":false}]}
{"op":"mcm","clk":"11541152888","pt":1719502791669,"mc":[{"id":"1.230178320","rc":[{"atb":[[1.02,22.65]],"id":69176305},{"atl":[[5.8,9.12]],"id":69176305}],"con":true,"img":false}]}
{"op":"mcm","clk":"11541152897","pt":1719502791774,"mc":[{"id":"1.230178320","rc":[{"atb":[[4.3,2.84]],"id":69176305},{"atl":[[11.5,3.35]],"id":61941199}],"con":true,"img":false}]}
{"op":"mcm","clk":"11541152916","pt":1719502791981,"mc":[{"id":"1.230178320","rc":[{"atl":[[5.8,10.7]],"id":69176305}],"con":true,"img":false}]}
{"op":"mcm","clk":"11541152939","pt":1719502792293,"mc":[{"id":"1.230178320","rc":[{"atb":[[4.3,9.71]],"id":69176305}],"con":true,"img":false}]}
{"op":"mcm","clk":"11541152949","pt":1719502792397,"mc":[{"id":"1.230178320","rc":[{"atl":[[5.8,12.28]],"id":69176305},{"atl":[[11.5,2.51]],"id":61941199}],"con":true,"img":false}]}
{"op":"mcm","clk":"11541152979","pt":1719502792665,"mc":[{"id":"1.230178320","rc":[{"atl":[[5.7,1.58]],"id":69176305}],"con":true,"img":false}]}
{"op":"mcm","clk":"11541152999","pt":1719502792873,"mc":[{"id":"1.230178320","rc":[{"atl":[[5.7,3.16]],"id":69176305}],"con":true,"img":false}]}
{"op":"mcm","clk":"11541153015","pt":1719502793080,"mc":[{"id":"1.230178320","rc":[{"atb":[[4.3,10.71]],"id":69176305},{"atl":[[5.7,4.74]],"id":69176305}],"con":true,"img":false}]}
{"op":"mcm","clk":"11541153024","pt":1719502793186,"mc":[{"id":"1.230178320","rc":[{"atl":[[5.8,7.9]],"id":69176305}],"con":true,"img":false}]}
{"op":"mcm","clk":"11541153044","pt":1719502793392,"mc":[{"id":"1.230178320","rc":[{"atl":[[5.6,4.53],[5.7,6.32]],"id":69176305}],"con":true,"img":false}]}
{"op":"mcm","clk":"11541153058","pt":1719502793601,"mc":[{"id":"1.230178320","rc":[{"atl":[[5.7,7.9]],"id":69176305}],"con":true,"img":false}]}
{"op":"mcm","clk":"11541153083","pt":1719502793865,"mc":[{"id":"1.230178320","rc":[{"atl":[[5.6,6.11]],"id":69176305}],"con":true,"img":false}]}
{"op":"mcm","clk":"11541153092","pt":1719502793971,"mc":[{"id":"1.230178320","rc":[{"atb":[[4.4,1.41]],"id":69176305}],"con":true,"img":false}]}
{"op":"mcm","clk":"11541153103","pt":1719502794072,"mc":[{"id":"1.230178320","rc":[{"atl":[[5.6,7.69]],"id":69176305}],"con":true,"img":false}]}
{"op":"mcm","clk":"11541153113","pt":1719502794181,"mc":[{"id":"1.230178320","rc":[{"atb":[[4.4,3.76]],"id":69176305}],"con":true,"img":false}]}
{"op":"mcm","clk":"11541153125","pt":1719502794282,"mc":[{"id":"1.230178320","rc":[{"atl":[[5.5,1.58]],"id":69176305}],"con":true,"img":false}]}
{"op":"mcm","clk":"11541153158","pt":1719502794591,"mc":[{"id":"1.230178320","rc":[{"atl":[[5.5,3.16]],"id":69176305}],"con":true,"img":false}]}
{"op":"mcm","clk":"11541153176","pt":1719502794798,"mc":[{"id":"1.230178320","rc":[{"atb":[[4.3,8.71]],"id":69176305},{"atl":[[5.4,1.58],[5.6,3.16]],"id":69176305}],"con":true,"img":false}]}
{"op":"mcm","clk":"11541153184","pt":1719502794900,"mc":[{"id":"1.230178320","rc":[{"atb":[[4.4,11.85],[1.02,24.65]],"id":69176305}],"con":true,"img":false}]}
{"op":"mcm","clk":"11541153192","pt":1719502795004,"mc":[{"id":"1.230178320","rc":[{"atl":[[5.4,3.16],[5.3,4.79]],"id":69176305},{"atl":[[19,0.84]],"id":43498435},{"atl":[[9,1.51]],"id":61419789},{"atl":[[13.5,3.4]],"id":62531723}],"con":true,"img":false}]}
{"op":"mcm","clk":"11541153203","pt":1719502795063,"mc":[{"id":"1.230178320","rc":[{"atb":[[4.4,9.5]],"id":69176305}],"con":true,"img":false}]}
{"op":"mcm","clk":"11541153225","pt":1719502795271,"mc":[{"id":"1.230178320","rc":[{"atl":[[5.4,4.74]],"id":69176305},{"atb":[[5.1,1.65]],"id":61419789}],"con":true,"img":false}]}
{"op":"mcm","clk":"11541153246","pt":1719502795478,"mc":[{"id":"1.230178320","rc":[{"atl":[[5.3,6.37]],"id":69176305},{"atb":[[4.3,10.34],[3.7,0]],"id":61419789}],"con":true,"img":false}]}
{"op":"mcm","clk":"11541153266","pt":1719502795687,"mc":[{"id":"1.230178320","rc":[{"atl":[[5.3,7.95]],"id":69176305},{"atb":[[3.75,10.99]],"id":61419789}],"con":true,"img":false}]}
{"op":"mcm","clk":"11541153277","pt":1719502795792,"mc":[{"id":"1.230178320","rc":[{"atb":[[5.1,8]],"id":61419789},{"atl":[[8.8,4.33]],"id":61419789}],"con":true,"img":false}]}
{"op":"mcm","clk":"11541153291","pt":1719502795894,"mc":[{"id":"1.230178320","rc":[{"atl":[[5.3,9.53]],"id":69176305}],"con":true,"img":false}]}
{"op":"mcm","clk":"11541153301","pt":1719502795997,"mc":[{"id":"1.230178320","rc":[{"atb":[[3.8,1]],"id":61419789}],"con":true,"img":false}]}
{"op":"mcm","clk":"11541153316","pt":1719502796103,"mc":[{"id":"1.230178320","rc":[{"atl":[[6.4,6.32],[7.2,11.06]],"id":69176305},{"atb":[[5.1,0.84],[4.7,5.04]],"id":43498435},{"atl":[[19.5,6],[21,0]],"id":43498435},{"atb":[[3.6,0],[4.2,10.41]],"id":61941199},{"atl":[[12,2.05],[13,9]],"id":61941199},{"atl":[[11,0],[13.5,5.51],[9.6,0],[9.8,1]],"id":61419789},{"atl":[[17,6.25],[15.5,0]],"id":62531723},{"atb":[[2.6,0],[2.28,20]],"id":51643934},{"atl":[[6.4,8],[4.6,6.73]],"id":51643934}],"con":true,"img":false}]}
{"op":"mcm","clk":"11541153327","pt":1719502796204,"mc":[{"id":"1.230178320","rc":[{"atl":[[7.2,4.74]],"id":69176305},{"atl":[[11.5,5.02],[13,1]],"id":61941199},{"atl":[[11.5,5.51],[13.5,0]],"id":61419789},{"atl":[[17,0],[15,7.14]],"id":62531723},{"atl":[[6.4,0],[5.6,8.16]],"id":51643934}],"con":true,"img":false}]}
{"op":"mcm","clk":"11541153336","pt":1719502796310,"mc":[{"id":"1.230178320","rc":[{"atl":[[6.4,15.8],[5.3,11.11]],"id":69176305}],"con":true,"img":false}]}
{"op":"mcm","clk":"11541153352","pt":1719502796364,"mc":[{"id":"1.230178320","rc":[{"atb":[[5.2,0.84]],"id":61419789}],"con":true,"img":false}]}
{"op":"mcm","clk":"11541153364","pt":1719502796467,"mc":[{"id":"1.230178320","rc":[{"atl":[[9,0]],"id":61419789}],"con":true,"img":false}]}
{"op":"mcm","clk":"11541153379","pt":1719502796568,"mc":[{"id":"1.230178320","rc":[{"atl":[[5.2,1.58]],"id":69176305}],"con":true,"img":false}]}
{"op":"mcm","clk":"11541153407","pt":1719502796778,"mc":[{"id":"1.230178320","rc":[{"atl":[[5.2,3.16]],"id":69176305}],"con":true,"img":false}]}
{"op":"mcm","clk":"11541153426","pt":1719502796982,"mc":[{"id":"1.230178320","rc":[{"atl":[[5.1,1.58]],"id":69176305}],"con":true,"img":false}]}
{"op":"mcm","clk":"11541153447","pt":1719502797190,"mc":[{"id":"1.230178320","rc":[{"atl":[[5.3,6.32]],"id":69176305}],"con":true,"img":false}]}
{"op":"mcm","clk":"11541153457","pt":1719502797293,"mc":[{"id":"1.230178320","rc":[{"atl":[[5.2,4.74]],"id":69176305}],"con":true,"img":false}]}
{"op":"mcm","clk":"11541153466","pt":1719502797397,"mc":[{"id":"1.230178320","rc":[{"atl":[[5,5.08]],"id":69176305}],"con":true,"img":false}]}
{"op":"mcm","clk":"11541153479","pt":1719502797501,"mc":[{"id":"1.230178320","rc":[{"atb":[[4.4,8.09]],"id":69176305},{"atl":[[8.8,0.84]],"id":61419789}],"con":true,"img":false}]}
{"op":"mcm","clk":"11541153489","pt":1719502797604,"mc":[{"id":"1.230178320","rc":[{"atl":[[5,0],[5.1,0.56]],"id":69176305},{"trd":[[5.1,2.02],[5,10.16]],"ltp":5.1,"tv":12.18,"id":69176305},{"atl":[[9.6,2.72]],"id":61419789}],"con":true,"img":false}]}
{"op":"mcm","clk":"11541153516","pt":1719502797916,"mc":[{"id":"1.230178320","rc":[{"atl":[[8.8,0]],"id":61419789}],"con":true,"img":false}]}
{"op":"mcm","clk":"11541153541","pt":1719502798075,"mc":[{"id":"1.230178320","rc":[{"atb":[[5.8,0.84]],"id":61941199},{"atb":[[6,2.69]],"id":62531723}],"con":true,"img":false}]}
{"op":"mcm","clk":"11541153560","pt":1719502798281,"mc":[{"id":"1.230178320","rc":[{"atb":[[5.8,2.63]],"id":61941199},{"atb":[[6.2,3.14]],"id":62531723},{"atl":[[4.5,1.79]],"id":51643934}],"con":true,"img":false}]}
{"op":"mcm","clk":"11541153569","pt":1719502798388,"mc":[{"id":"1.230178320","rc":[{"atl":[[9.4,0.84]],"id":61419789}],"con":true,"img":false}]}
{"op":"mcm","clk":"11541153587","pt":1719502798589,"mc":[{"id":"1.230178320","rc":[{"atb":[[5.7,0]],"id":61941199},{"atl":[[10.5,0.84]],"id":61941199}],"con":true,"img":false}]}
{"op":"mcm","clk":"11541153601","pt":1719502798796,"mc":[{"id":"1.230178320","rc":[{"atl":[[1000,0.27]],"id":61941199},{"atb":[[6.4,3.97]],"id":62531723}],"con":true,"img":false}]}
{"op":"mcm","clk":"11541153609","pt":1719502798899,"mc":[{"id":"1.230178320","rc":[{"atb":[[4.5,0.84]],"id":69176305},{"atb":[[5.8,0.84]],"id":61941199},{"atl":[[1000,1.12]],"id":61941199},{"atb":[[6.4,4.81]],"id":62531723},{"atl":[[4.4,0.84],[4.5,1.48],[4.7,6.38]],"id":51643934}],"con":true,"img":false}]}
{"op":"mcm","clk":"11541153617","pt":1719502799002,"mc":[{"id":"1.230178320","rc":[{"atb":[[5.7,1.78]],"id":61941199}],"con":true,"img":false}]}
{"op":"mcm","clk":"11541153629","pt":1719502799107,"mc":[{"id":"1.230178320","rc":[{"atl":[[1000,0.59]],"id":61941199},{"atb":[[6.2,1.82],[6.6,1.28]],"id":62531723}],"con":true,"img":false}]}
{"op":"mcm","clk":"11541153642","pt":1719502799210,"mc":[{"id":"1.230178320","rc":[{"atl":[[4.4,8.98]],"id":51643934}],"con":true,"img":false}]}
{"op":"mcm","clk":"11541153652","pt":1719502799272,"mc":[{"id":"1.230178320","rc":[{"atb":[[6,1.69]],"id":62531723}],"con":true,"img":false}]}
{"op":"mcm","clk":"11541153662","pt":1719502799373,"mc":[{"id":"1.230178320","rc":[{"atl":[[1000,0.16]],"id":61941199},{"atb":[[6,0.84],[6.6,2.28]],"id":62531723},{"atl":[[4.5,0.48]],"id":51643934}],"con":true,"img":false}]}
{"op":"mcm","clk":"11541153670","pt":1719502799474,"mc":[{"id":"1.230178320","rc":[{"atl":[[10,0.95],[9.8,0.31]],"id":61941199},{"atl":[[4.5,0]],"id":51643934}],"con":true,"img":false}]}
{"op":"mcm","clk":"11541153680","pt":1719502799577,"mc":[{"id":"1.230178320","rc":[{"atl":[[4.3,1],[1000,0.65]],"id":51643934}],"con":true,"img":false}]}
{"op":"mcm","clk":"11541153696","pt":1719502799784,"mc":[{"id":"1.230178320","rc":[{"atl":[[5.3,7.9]],"id":69176305},{"atb":[[5.8,0.27]],"id":61941199},{"atl":[[10,0.11],[10.5,1.69]],"id":61941199},{"atb":[[6,0.27]],"id":62531723}],"con":true,"img":false}]}
{"op":"mcm","clk":"11541153710","pt":1719502799993,"mc":[{"id":"1.230178320","rc":[{"atl":[[5.3,9.48]],"id":69176305},{"atl":[[12.5,0]],"id":61941199},{"atl":[[4.8,0]],"id":51643934}],"con":true,"img":false}]}
{"op":"mcm","clk":"11541153730","pt":1719502800199,"mc":[{"id":"1.230178320","rc":[{"atl":[[5.2,6.32]],"id":69176305},{"atl":[[10,2.56]],"id":61941199},{"atb":[[6.4,0.84]],"id":62531723}],"con":true,"img":false}]}
{"op":"mcm","clk":"11541153752","pt":1719502800410,"mc":[{"id":"1.230178320","rc":[{"atl":[[5.2,7.9]],"id":69176305}],"con":true,"img":false}]}
{"op":"mcm","clk":"11541153787","pt":1719502800685,"mc":[{"id":"1.230178320","rc":[{"atl":[[5.1,2.15]],"id":69176305}],"con":true,"img":false}]}
{"op":"mcm","clk":"11541153799","pt":1719502800790,"mc":[{"id":"1.230178320","rc":[{"atb":[[4.4,1.7]],"id":61419789}],"con":true,"img":false}]}
{"op":"mcm","clk":"11541153813","pt":1719502800894,"mc":[{"id":"1.230178320","rc":[{"atl":[[5.1,3.73]],"id":69176305},{"atl":[[9.8,1.16]],"id":61941199}],"con":true,"img":false}]}
{"op":"mcm","clk":"11541153825","pt":1719502800997,"mc":[{"id":"1.230178320","rc":[{"atb":[[3.8,0]],"id":61419789}],"con":true,"img":false}]}
{"op":"mcm","clk":"11541153839","pt":1719502801108,"mc":[{"id":"1.230178320","rc":[{"atl":[[11,2.4]],"id":61941199},{"atb":[[5.2,1.84]],"id":61419789}],"con":true,"img":false}]}
{"op":"mcm","clk":"11541153851","pt":1719502801212,"mc":[{"id":"1.230178320","rc":[{"atl":[[5.1,5.31]],"id":69176305},{"atl":[[10,1],[9.8,0]],"id":61419789}],"con":true,"img":false}]}
{"op":"mcm","clk":"11541153864","pt":1719502801268,"mc":[{"id":"1.230178320","rc":[{"atl":[[9.8,2.16]],"id":61941199}],"con":true,"img":false}]}
{"op":"mcm","clk":"11541153875","pt":1719502801374,"mc":[{"id":"1.230178320","rc":[{"atl":[[5.1,6.89]],"id":69176305},{"atb":[[5.3,1.6],[5.1,6.35]],"id":61419789}],"con":true,"img":false}]}
{"op":"mcm","clk":"11541153901","pt":1719502801584,"mc":[{"id":"1.230178320","rc":[{"atl":[[5,1.58]],"id":69176305},{"atl":[[12,0]],"id":61941199},{"atb":[[3.55,0]],"id":61419789}],"con":true,"img":false}]}
{"op":"mcm","clk":"11541153922","pt":1719502801795,"mc":[{"id":"1.230178320","rc":[{"atl":[[9.8,4.93]],"id":61941199},{"atb":[[5.3,7.42]],"id":61419789}],"con":true,"img":false}]}
{"op":"mcm","clk":"11541153933","pt":1719502801900,"mc":[{"id":"1.230178320","rc":[{"atl":[[5,3.16],[5.7,12.9]],"id":69176305},{"atl":[[10.5,0.84],[9.8,3.93]],"id":61941199}],"con":true,"img":false}]}
{"op":"mcm","clk":"11541153947","pt":1719502802003,"mc":[{"id":"1.230178320","rc":[{"atl":[[5.7,7.9]],"id":69176305},{"atb":[[5.4,1.89]],"id":43498435},{"atb":[[3.75,13.37],[5.2,0.84]],"id":61419789},{"atb":[[6.2,3]],"id":62531723}],"con":true,"img":false}]}
{"op":"mcm","clk":"11541153961","pt":1719502802107,"mc":[{"id":"1.230178320","rc":[{"atl":[[5,4.74]],"id":69176305}],"con":true,"img":false}]}
{"op":"mcm","clk":"11541153975","pt":1719502802212,"mc":[{"id":"1.230178320","rc":[{"atl":[[9.6,1]],"id":61941199},{"atb":[[5.4,1]],"id":61419789}],"con":true,"img":false}]}
{"op":"mcm","clk":"11541153984","pt":1719502802316,"mc":[{"id":"1.230178320","rc":[{"atl":[[5,0]],"id":69176305},{"trd":[[5,19.64]],"ltp":5.0,"tv":19.64,"id":69176305}],"con":true,"img":false}]}
{"op":"mcm","clk":"11541153995","pt":1719502802372,"mc":[{"id":"1.230178320","rc":[{"atl":[[5,1.58]],"id":69176305},{"atb":[[5.1,0],[5.5,0.84]],"id":43498435}],"con":true,"img":false}]}
{"op":"mcm","clk":"11541154002","pt":1719502802475,"mc":[{"id":"1.230178320","rc":[{"atl":[[9.8,3.61]],"id":61941199}],"con":true,"img":false}]}
{"op":"mcm","clk":"11541154012","pt":1719502802582,"mc":[{"id":"1.230178320","rc":[{"atl":[[4.9,1.58]],"id":69176305}],"con":true,"img":false}]}
{"op":"mcm","clk":"11541154026","pt":1719502802685,"mc":[{"id":"1.230178320","rc":[{"atl":[[1000,1.01]],"id":61941199}],"con":true,"img":false}]}
{"op":"mcm","clk":"11541154037","pt":1719502802787,"mc":[{"id":"1.230178320","rc":[{"atl":[[4.9,3.16]],"id":69176305},{"atl":[[1000,0.49]],"id":61941199}],"con":true,"img":false}]}
{"op":"mcm","clk":"11541154060","pt":1719502802995,"mc":[{"id":"1.230178320","rc":[{"atl":[[4.9,4.74]],"id":69176305},{"atl":[[1000,0.16]],"id":61941199}],"con":true,"img":false}]}
{"op":"mcm","clk":"11541154070","pt":1719502803098,"mc":[{"id":"1.230178320","rc":[{"atl":[[9.4,0.33]],"id":61941199}],"con":true,"img":false}]}
{"op":"mcm","clk":"11541154083","pt":1719502803202,"mc":[{"id":"1.230178320","rc":[{"atl":[[4.9,0]],"id":69176305},{"trd":[[4.9,9.48]],"ltp":4.9,"tv":9.48,"id":69176305},{"atb":[[5.4,1.84]],"id":61419789}],"con":true,"img":false}]}
{"op":"mcm","clk":"11541154095","pt":1719502803308,"mc":[{"id":"1.230178320","rc":[{"atl":[[4.9,1.58]],"id":69176305}],"con":true,"img":false}]}
{"op":"mcm","clk":"11541154106","pt":1719502803412,"mc":[{"id":"1.230178320","rc":[{"atb":[[5.6,7]],"id":61941199}],"con":true,"img":false}]}
{"op":"mcm","clk":"11541154119","pt":1719502803518,"mc":[{"id":"1.230178320","rc":[{"atl":[[4.8,1.58]],"id":69176305}],"con":true,"img":false}]}
{"op":"mcm","clk":"11541154143","pt":1719502803677,"mc":[{"id":"1.230178320","rc":[{"atl":[[4.8,3.16]],"id":69176305}],"con":true,"img":false}]}
{"op":"mcm","clk":"11541154166","pt":1719502803883,"mc":[{"id":"1.230178320","rc":[{"atl":[[4.8,4.74]],"id":69176305},{"atb":[[5.5,0.84],[5.2,0]],"id":61419789}],"con":true,"img":false}]}
{"op":"mcm","clk":"11541154178","pt":1719502803987,"mc":[{"id":"1.230178320","rc":[{"atl":[[4.8,0]],"id":69176305},{"trd":[[4.8,9.48]],"ltp":4.8,"tv":9.48,"id":69176305}],"con":true,"img":false}]}
{"op":"mcm","clk":"11541154190","pt":1719502804092,"mc":[{"id":"1.230178320","rc":[{"atb":[[3.4,0]],"id":61941199}],"con":true,"img":false}]}
{"op":"mcm","clk":"11541154200","pt":1719502804195,"mc":[{"id":"1.230178320","rc":[{"atl":[[4.8,1.58]],"id":69176305}],"con":true,"img":false}]}
{"op":"mcm","clk":"11541154238","pt":1719502804504,"mc":[{"id":"1.230178320","rc":[{"atl":[[4.7,1.58]],"id":69176305}],"con":true,"img":false}]}
{"op":"mcm","clk":"11541154259","pt":1719502804713,"mc":[{"id":"1.230178320","rc":[{"atl":[[4.7,0]],"id":69176305},{"trd":[[4.7,6.32]],"ltp":4.7,"tv":6.32,"id":69176305}],"con":true,"img":false}]}
{"op":"mcm","clk":"11541154266","pt":1719502804769,"mc":[{"id":"1.230178320","rc":[{"atb":[[5.5,2.38]],"id":61419789}],"con":true,"img":false}]}
{"op":"mcm","clk":"11541154287","pt":1719502804978,"mc":[{"id":"1.230178320","rc":[{"atl":[[4.7,1.58]],"id":69176305},{"atb":[[5.3,5.82],[5.4,1.26]],"id":61419789}],"con":true,"img":false}]}
{"op":"mcm","clk":"11541154295","pt":1719502805079,"mc":[{"id":"1.230178320","rc":[{"atl":[[4.9,3.63]],"id":69176305}],"con":true,"img":false}]}
{"op":"mcm","clk":"11541154304","pt":1719502805184,"mc":[{"id":"1.230178320","rc":[{"atl":[[4.7,3.16]],"id":69176305}],"con":true,"img":false}]}
{"op":"mcm","clk":"11541154322","pt":1719502805395,"mc":[{"id":"1.230178320","rc":[{"atl":[[4.7,4.74]],"id":69176305}],"con":true,"img":false}]}
{"op":"mcm","clk":"11541154366","pt":1719502805807,"mc":[{"id":"1.230178320","rc":[{"atb":[[6.8,0.84]],"id":62531723}],"con":true,"img":false}]}
{"op":"mcm","clk":"11541154377","pt":1719502805910,"mc":[{"id":"1.230178320","rc":[{"atl":[[4.9,5.21]],"id":69176305}],"con":true,"img":false}]}
{"op":"mcm","clk":"11541154397","pt":1719502806118,"mc":[{"id":"1.230178320","rc":[{"atl":[[4.9,6.79]],"id":69176305}],"con":true,"img":false}]}
{"op":"mcm","clk":"11541154420","pt":1719502806277,"mc":[{"id":"1.230178320","rc":[{"atl":[[4.9,8.37]],"id":69176305},{"atb":[[4.3,0],[3.85,10.34]],"id":61419789},{"atl":[[10,0],[10.5,1],[11.5,0],[13,4]],"id":61419789},{"atl":[[15,0],[15.5,6.9]],"id":62531723}],"con":true,"img":false}]}
{"op":"mcm","clk":"11541154449","pt":1719502806589,"mc":[{"id":"1.230178320","rc":[{"atl":[[5,3.16]],"id":69176305}],"con":true,"img":false}]}
{"op":"mcm","clk":"11541154457","pt":1719502806693,"mc":[{"id":"1.230178320","rc":[{"atb":[[5.4,1]],"id":61419789}],"con":true,"img":false}]}
{"op":"mcm","clk":"11541154472","pt":1719502806795,"mc":[{"id":"1.230178320","rc":[{"atl":[[5,4.74]],"id":69176305},{"atb":[[1.13,0.26]],"id":61419789}],"con":true,"img":false}]}
{"op":"mcm","clk":"11541154480","pt":1719502806899,"mc":[{"id":"1.230178320","rc":[{"atl":[[4.7,6.9]],"id":69176305}],"con":true,"img":false}]}
{"op":"mcm","clk":"11541154501","pt":1719502807108,"mc":[{"id":"1.230178320","rc":[{"atl":[[5.2,9.48]],"id":69176305}],"con":true,"img":false}]}
{"op":"mcm","clk":"11541154535","pt":1719502807416,"mc":[{"id":"1.230178320","rc":[{"atl":[[5.1,8.47]],"id":69176305},{"spn":4.42,"spf":1.0,"id":69176305},{"spn":12.0,"spf":"NaN","id":43498435},{"spn":7.6,"spf":"NaN","id":61941199},{"spn":5.5,"spf":1.0,"id":61419789},{"spn":10.15,"spf":"NaN","id":62531723}],"con":true,"img":false}]}
{"op":"mcm","clk":"11541154557","pt":1719502807679,"mc":[{"id":"1.230178320","rc":[{"atl":[[5.1,10.05]],"id":69176305}],"con":true,"img":false}]}
{"op":"mcm","clk":"11541154582","pt":1719502807886,"mc":[{"id":"1.230178320","rc":[{"atb":[[5.6,4.53]],"id":61419789}],"con":true,"img":false}]}
{"op":"mcm","clk":"11541154595","pt":1719502807989,"mc":[{"id":"1.230178320","rc":[{"atl":[[4.9,9.95]],"id":69176305}],"con":true,"img":false}]}
{"op":"mcm","clk":"11541154616","pt":1719502808195,"mc":[{"id":"1.230178320","rc":[{"atl":[[4.9,11.53]],"id":69176305}],"con":true,"img":false}]}
{"op":"mcm","clk":"11541154659","pt":1719502808611,"mc":[{"id":"1.230178320","rc":[{"atl":[[5.1,11.63]],"id":69176305}],"con":true,"img":false}]}
{"op":"mcm","clk":"11541154679","pt":1719502808818,"mc":[{"id":"1.230178320","rc":[{"atl":[[5.3,11.06]],"id":69176305}],"con":true,"img":false}]}
{"op":"mcm","clk":"11541154705","pt":1719502809078,"mc":[{"id":"1.230178320","rc":[{"atl":[[5.3,12.64]],"id":69176305}],"con":true,"img":false}]}
{"op":"mcm","clk":"11541154730","pt":1719502809286,"mc":[{"id":"1.230178320","rc":[{"atl":[[5.4,6.32]],"id":69176305}],"con":true,"img":false}]}
{"op":"mcm","clk":"11541154736","pt":1719502809390,"mc":[{"id":"1.230178320","rc":[{"atb":[[3.15,0]],"id":69176305}],"con":true,"img":false}]}
{"op":"mcm","clk":"11541154748","pt":1719502809497,"mc":[{"id":"1.230178320","rc":[{"atl":[[5.4,7.9]],"id":69176305}],"con":true,"img":false}]}
{"op":"mcm","clk":"11541154767","pt":1719502809699,"mc":[{"id":"1.230178320","rc":[{"atb":[[3.15,5.51]],"id":61941199}],"con":true,"img":false}]}
{"op":"mcm","clk":"11541154778","pt":1719502809801,"mc":[{"id":"1.230178320","rc":[{"atl":[[5.5,4.74]],"id":69176305}],"con":true,"img":false}]}
{"op":"mcm","clk":"11541154792","pt":1719502810006,"mc":[{"id":"1.230178320","rc":[{"atl":[[5.6,4.74]],"id":69176305}],"con":true,"img":false}]}
{"op":"mcm","clk":"11541154819","pt":1719502810316,"mc":[{"id":"1.230178320","rc":[{"atl":[[5.6,6.32]],"id":69176305}],"con":true,"img":false}]}
{"op":"mcm","clk":"11541154834","pt":1719502810472,"mc":[{"id":"1.230178320","rc":[{"atl":[[5.6,7.9]],"id":69176305}],"con":true,"img":false}]}
{"op":"mcm","clk":"11541154856","pt":1719502810783,"mc":[{"id":"1.230178320","rc":[{"atl":[[5.2,11.06]],"id":69176305}],"con":true,"img":false}]}
{"op":"mcm","clk":"11541154895","pt":1719502811305,"mc":[{"id":"1.230178320","rc":[{"atb":[[5.7,0.84]],"id":61419789}],"con":true,"img":false}]}
{"op":"mcm","clk":"11541154913","pt":1719502811510,"mc":[{"id":"1.230178320","rc":[{"atl":[[10.5,0],[11,1]],"id":61419789}],"con":true,"img":false}]}
{"op":"mcm","clk":"11541154935","pt":1719502811716,"mc":[{"id":"1.230178320","rc":[{"atb":[[5.6,0]],"id":61419789}],"con":true,"img":false}]}
{"op":"mcm","clk":"11541154973","pt":1719502812084,"mc":[{"id":"1.230178320","rc":[{"atb":[[4.4,9.1]],"id":69176305},{"atl":[[4.7,5.83]],"id":69176305},{"trd":[[4.7,8.45]],"ltp":4.7,"tv":8.45,"id":69176305}],"con":true,"img":false}]}
{"op":"mcm","clk":"11541154996","pt":1719502812289,"mc":[{"id":"1.230178320","rc":[{"atb":[[4.4,8.09]],"id":69176305},{"atb":[[5.7,0]],"id":61419789}],"con":true,"img":false}]}
{"op":"mcm","clk":"11541155063","pt":1719502812915,"mc":[{"id":"1.230178320","rc":[{"atb":[[5.6,4.53]],"id":61419789}],"con":true,"img":false}]}
{"op":"mcm","clk":"11541155229","pt":1719502814676,"mc":[{"id":"1.230178320","rc":[{"atl":[[10,2.45]],"id":61941199}],"con":true,"img":false}]}
{"op":"mcm","clk":"11541155366","pt":1719502816277,"mc":[{"id":"1.230178320","rc":[{"atb":[[4.4,9.61]],"id":69176305},{"atl":[[4.7,4.76]],"id":69176305},{"trd":[[4.7,10.6]],"ltp":4.7,"tv":10.6,"id":69176305}],"con":true,"img":false}]}
{"op":"mcm","clk":"11541155375","pt":1719502816382,"mc":[{"id":"1.230178320","rc":[{"atl":[[4.9,0],[5,3.67],[4.7,0],[4.8,0]],"id":69176305},{"trd":[[5,21.77],[4.8,12.64],[4.9,32.56],[4.7,20.12]],"ltp":5.0,"tv":87.09,"id":69176305}],"con":true,"img":false}]}
{"op":"mcm","clk":"11541155386","pt":1719502816486,"mc":[{"id":"1.230178320","rc":[{"atb":[[4.4,8.09],[4.5,1.06]],"id":69176305},{"atl":[[5,3.87]],"id":69176305}],"con":true,"img":false}]}
{"op":"mcm","clk":"11541155397","pt":1719502816590,"mc":[{"id":"1.230178320","rc":[{"atb":[[4.4,9.2]],"id":69176305},{"atl":[[8.6,0]],"id":69176305},{"atl":[[10.5,1],[11,0]],"id":61419789}],"con":true,"img":false}]}
{"op":"mcm","clk":"11541155413","pt":1719502816795,"mc":[{"id":"1.230178320","rc":[{"atb":[[4,1.31],[3.95,1.33],[3.9,1.34]],"id":69176305},{"atb":[[5.4,2.86],[5.6,0.94],[5.5,1.8]],"id":43498435},{"atl":[[18.5,0.74],[18,0.29],[19,1.12]],"id":43498435},{"atb":[[5.8,1.18],[5.9,0.88],[5.7,2.7]],"id":61941199},{"atl":[[9.2,0.57],[9.4,0.88],[9.6,1.54]],"id":61941199},{"atb":[[5.4,1.97],[5.5,3.34],[5.7,0.92]],"id":61419789},{"atl":[[9.2,0.57],[9.4,1.4],[9.6,3.26]],"id":61419789},{"atb":[[6.8,1.62],[6.6,3.08],[7,0.75]],"id":62531723},{"atl":[[13,0.4],[14,0.37],[14.5,1.36]],"id":62531723},{"atb":[[3.7,1.42],[3.65,1.44]],"id":51643934},{"atl":[[4.8,1.09],[4.9,1.07],[4.5,1.16]],"id":51643934}],"con":true,"img":false}]}
{"op":"mcm","clk":"11541155419","pt":1719502816898,"mc":[{"id":"1.230178320","rc":[{"atl":[[18.5,2.74]],"id":43498435}],"con":true,"img":false}]}
{"op":"mcm","clk":"11541155428","pt":1719502817002,"mc":[{"id":"1.230178320","rc":[{"atb":[[5.3,0.99],[5.4,1.86],[5.1,1.03],[5.2,1.01]],"id":43498435},{"atl":[[19.5,1],[20,0.26],[21,0.25],[22,0.23]],"id":43498435},{"atb":[[3.85,1.36]],"id":69176305},{"atb":[[5.1,1.03],[5,1.05],[5.5,2.49]],"id":61941199},{"atl":[[10,2.97],[10.5,1.34],[11,2.89]],"id":61941199},{"atb":[[4.9,1.07],[5,2.05],[5.2,1.01]],"id":61419789},{"atl":[[10,0.52],[10.5,1.5],[9.8,0.53]],"id":61419789},{"atb":[[6.4,1.66],[5.6,0.94],[6,1.15]],"id":62531723},{"atl":[[15,0.35],[16,0.35],[16.5,0.35]],"id":62531723},{"atb":[[3.55,1.48],[3.5,1.5]],"id":51643934},{"atl":[[5.1,1.03],[5,1.05]],"id":51643934}],"con":true,"img":false}]}
{"op":"mcm","clk":"11541155439","pt":1719502817104,"mc":[{"id":"1.230178320","rc":[{"atb":[[5.6,0]],"id":61419789},{"atb":[[7,1.96],[6.6,1.8]],"id":62531723}],"con":true,"img":false}]}
{"op":"mcm","clk":"11541155451","pt":1719502817208,"mc":[{"id":"1.230178320","rc":[{"atb":[[5.6,1.94],[5,2.05],[5.7,0.92]],"id":43498435},{"atl":[[17.5,0.32],[23,0.32],[24,0.32]],"id":43498435},{"atb":[[6,0.95]],"id":61941199},{"atl":[[9,0.58],[12,0.54]],"id":61941199},{"atb":[[5.8,0.9],[5.6,1.1]],"id":61419789},{"atl":[[9,0.58],[11,0.47],[11.5,0.45]],"id":61419789},{"atb":[[5.9,5.78],[7.2,0.8],[6.6,0.8]],"id":62531723},{"atl":[[12.5,0.42],[17,0.39]],"id":62531723},{"atb":[[3.45,1.52],[3.4,1.54]],"id":51643934}],"con":true,"img":false}]}
{"op":"mcm","clk":"11541155463","pt":1719502817311,"mc":[{"id":"1.230178320","rc":[{"atl":[[18,1.14]],"id":43498435}],"con":true,"img":false}]}
{"op":"mcm","clk":"11541155472","pt":1719502817415,"mc":[{"id":"1.230178320","rc":[{"atb":[[4.5,2.26]],"id":69176305},{"atb":[[6.4,0.82],[7.2,1.8]],"id":62531723}],"con":true,"img":false}]}
{"op":"mcm","clk":"11541155484","pt":1719502817518,"mc":[{"id":"1.230178320","rc":[{"atl":[[5,2.8]],"id":69176305},{"trd":[[5,23.92]],"ltp":5.0,"tv":23.92,"id":69176305},{"atl":[[19.5,1.26]],"id":43498435}],"con":true,"img":false}]}
