{"op":"mcm","clk":"11536833042","pt":1719431776485,"mc":[{"id":"1.230180131","marketDefinition":{"bspMarket":true,"turnInPlayEnabled":false,"persistenceEnabled":false,"marketBaseRate":5.0,"eventId":"33376437","eventTypeId":"4339","numberOfWinners":2,"bettingType":"ODDS","marketType":"PLACE","marketTime":"2024-06-27T16:21:00.000Z","suspendTime":"2024-06-27T16:21:00.000Z","bspReconciled":false,"complete":true,"inPlay":false,"crossMatching":false,"runnersVoidable":false,"numberOfActiveRunners":6,"betDelay":0,"status":"OPEN","runners":[{"status":"ACTIVE","sortPriority":1,"id":66499052,"name":"1. Salacres Wild"},{"status":"ACTIVE","sortPriority":2,"id":43210435,"name":"2. Bemyangelrosa"},{"status":"ACTIVE","sortPriority":3,"id":41138102,"name":"3. Traptoline Zorro"},{"status":"ACTIVE","sortPriority":4,"id":69979297,"name":"4. Jacktavern Pele"},{"status":"ACTIVE","sortPriority":5,"id":58149406,"name":"5. Salacres Herbert"},{"status":"ACTIVE","sortPriority":6,"id":51843546,"name":"6. Salacres Maybach"}],"regulators":["MR_INT"],"venue":"Towcester","countryCode":"GB","discountAllowed":false,"timezone":"Europe/London","openDate":"2024-06-27T13:33:00.000Z","version":5994767145,"name":"To Be Placed","eventName":"Towcester 27th Jun"},"rc":[],"con":true,"img":false}]}
{"op":"mcm","clk":"11536833152","pt":1719431777536,"mc":[{"id":"1.230180131","marketDefinition":{"bspMarket":true,"turnInPlayEnabled":false,"persistenceEnabled":false,"marketBaseRate":5.0,"eventId":"33376437","eventTypeId":"4339","numberOfWinners":2,"bettingType":"ODDS","marketType":"PLACE","marketTime":"2024-06-27T16:21:00.000Z","suspendTime":"2024-06-27T16:21:00.000Z","bspReconciled":false,"complete":true,"inPlay":false,"crossMatching":false,"runnersVoidable":false,"numberOfActiveRunners":6,"betDelay":0,"status":"OPEN","runners":[{"status":"ACTIVE","sortPriority":1,"id":66499052,"name":"1. Salacres Wild"},{"status":"ACTIVE","sortPriority":2,"id":43210435,"name":"2. Bemyangelrosa"},{"status":"ACTIVE","sortPriority":3,"id":41138102,"name":"3. Traptoline Zorro"},{"status":"ACTIVE","sortPriority":4,"id":69979297,"name":"4. Jacktavern Pele"},{"status":"ACTIVE","sortPriority":5,"id":58149406,"name":"5. Salacres Herbert"},{"status":"ACTIVE","sortPriority":6,"id":51843546,"name":"6. Salacres Maybach"}],"regulators":["MR_INT"],"venue":"Towcester","countryCode":"GB","discountAllowed":true,"timezone":"Europe/London","openDate":"2024-06-27T13:33:00.000Z","version":5994767145,"name":"To Be Placed","eventName":"Towcester 27th Jun"},"rc":[],"con":true,"img":false}]}
{"op":"mcm","clk":"11537083909","pt":1719435433620,"mc":[{"id":"1.230180131","rc":[{"atb":[[1.01,32.96]],"id":58149406},{"atl":[[1000,0.84]],"id":58149406},{"spn":500.5,"spf":"NaN","id":58149406},{"atb":[[1.03,10.99]],"id":41138102},{"atl":[[1000,0.84]],"id":41138102},{"spn":500.51,"spf":"NaN","id":41138102},{"atb":[[1.02,16.48]],"id":43210435},{"atl":[[1000,0.84]],"id":43210435},{"spn":500.51,"spf":"NaN","id":43210435},{"atb":[[1.02,16.48]],"id":66499052},{"atl":[[1000,0.84]],"id":66499052},{"spn":500.51,"spf":"NaN","id":66499052},{"atb":[[1.01,32.96]],"id":51843546},{"atl":[[1000,0.84]],"id":51843546},{"spn":500.5,"spf":"NaN","id":51843546},{"atb":[[1.03,10.99]],"id":69979297},{"atl":[[1000,0.84]],"id":69979297},{"spn":500.51,"spf":"NaN","id":69979297}],"con":true,"img":false}]}
{"op":"mcm","clk":"11537235639","pt":1719437882801,"mc":[{"id":"1.230180131","marketDefinition":{"bspMarket":true,"turnInPlayEnabled":false,"persistenceEnabled":false,"marketBaseRate":5.0,"eventId":"33376437","eventTypeId":"4339","numberOfWinners":2,"bettingType":"ODDS","marketType":"PLACE","marketTime":"2024-06-27T16:21:00.000Z","suspendTime":"2024-06-27T16:21:00.000Z","bspReconciled":false,"complete":true,"inPlay":false,"crossMatching":false,"runnersVoidable":false,"numberOfActiveRunners":6,"betDelay":0,"status":"OPEN","runners":[{"status":"ACTIVE","sortPriority":1,"id":66499052,"name":"1. Salacres Wild"},{"status":"ACTIVE","sortPriority":2,"id":43210435,"name":"2. Bemyangelrosa"},{"status":"ACTIVE","sortPriority":3,"id":41138102,"name":"3. Traptoline Zorro"},{"status":"ACTIVE","sortPriority":4,"id":69979297,"name":"4. Jacktavern Pele"},{"status":"ACTIVE","sortPriority":5,"id":58149406,"name":"5. Salacres Herbert"},{"status":"ACTIVE","sortPriority":6,"id":51843546,"name":"6. Salacres Maybach"}],"regulators":["MR_INT"],"venue":"Towcester","countryCode":"GB","discountAllowed":true,"timezone":"Europe/London","openDate":"2024-06-27T13:33:00.000Z","version":5994767145,"name":"To Be Placed","eventName":"Towcester 27th Jun"},"rc":[{"atb":[[1.01,32.96]],"id":58149406},{"atl":[[1000,0.84]],"id":58149406},{"spn":500.5,"spf":"NaN","id":58149406},{"atb":[[1.03,10.99]],"id":41138102},{"atl":[[1000,0.84]],"id":41138102},{"spn":500.51,"spf":"NaN","id":41138102},{"atb":[[1.02,16.48]],"id":43210435},{"atl":[[1000,0.84]],"id":43210435},{"spn":500.51,"spf":"NaN","id":43210435},{"atb":[[1.02,16.48]],"id":66499052},{"atl":[[1000,0.84]],"id":66499052},{"spn":500.51,"spf":"NaN","id":66499052},{"atb":[[1.01,32.96]],"id":51843546},{"atl":[[1000,0.84]],"id":51843546},{"spn":500.5,"spf":"NaN","id":51843546},{"atb":[[1.03,10.99]],"id":69979297},{"atl":[[1000,0.84]],"id":69979297},{"spn":500.51,"spf":"NaN","id":69979297}],"con":true,"img":true}]}
{"op":"mcm","clk":"11537302188","pt":1719439031611,"mc":[{"id":"1.230180131","rc":[{"atb":[[1.01,32.96]],"id":58149406},{"atl":[[1000,0.17]],"id":58149406},{"atb":[[1.03,10.99]],"id":41138102},{"atl":[[1000,0.17]],"id":41138102},{"atb":[[1.02,16.48]],"id":43210435},{"atl":[[1000,0.17]],"id":43210435},{"atb":[[1.02,16.48]],"id":66499052},{"atl":[[1000,0.17]],"id":66499052},{"atb":[[1.01,32.96]],"id":51843546},{"atl":[[1000,0.17]],"id":51843546},{"atb":[[1.03,10.99]],"id":69979297},{"atl":[[1000,0.17]],"id":69979297}],"con":true,"img":false}]}
{"op":"mcm","clk":"11537576927","pt":1719443282846,"mc":[{"id":"1.230180131","marketDefinition":{"bspMarket":true,"turnInPlayEnabled":false,"persistenceEnabled":false,"marketBaseRate":5.0,"eventId":"33376437","eventTypeId":"4339","numberOfWinners":2,"bettingType":"ODDS","marketType":"PLACE","marketTime":"2024-06-27T16:21:00.000Z","suspendTime":"2024-06-27T16:21:00.000Z","bspReconciled":false,"complete":true,"inPlay":false,"crossMatching":false,"runnersVoidable":false,"numberOfActiveRunners":6,"betDelay":0,"status":"OPEN","runners":[{"status":"ACTIVE","sortPriority":1,"id":66499052,"name":"1. Salacres Wild"},{"status":"ACTIVE","sortPriority":2,"id":43210435,"name":"2. Bemyangelrosa"},{"status":"ACTIVE","sortPriority":3,"id":41138102,"name":"3. Traptoline Zorro"},{"status":"ACTIVE","sortPriority":4,"id":69979297,"name":"4. Jacktavern Pele"},{"status":"ACTIVE","sortPriority":5,"id":58149406,"name":"5. Salacres Herbert"},{"status":"ACTIVE","sortPriority":6,"id":51843546,"name":"6. Salacres Maybach"}],"regulators":["MR_INT"],"venue":"Towcester","countryCode":"GB","discountAllowed":true,"timezone":"Europe/London","openDate":"2024-06-27T13:33:00.000Z","version":5994767145,"name":"To Be Placed","eventName":"Towcester 27th Jun"},"rc":[{"atb":[[1.01,32.96]],"id":58149406},{"atl":[[1000,0.17]],"id":58149406},{"spn":500.5,"spf":"NaN","id":58149406},{"atb":[[1.03,10.99]],"id":41138102},{"atl":[[1000,0.17]],"id":41138102},{"spn":500.51,"spf":"NaN","id":41138102},{"atb":[[1.02,16.48]],"id":43210435},{"atl":[[1000,0.17]],"id":43210435},{"spn":500.51,"spf":"NaN","id":43210435},{"atb":[[1.02,16.48]],"id":66499052},{"atl":[[1000,0.17]],"id":66499052},{"spn":500.51,"spf":"NaN","id":66499052},{"atb":[[1.01,32.96]],"id":51843546},{"atl":[[1000,0.17]],"id":51843546},{"spn":500.5,"spf":"NaN","id":51843546},{"atb":[[1.03,10.99]],"id":69979297},{"atl":[[1000,0.17]],"id":69979297},{"spn":500.51,"spf":"NaN","id":69979297}],"con":true,"img":true}]}
{"op":"mcm","clk":"11537958615","pt":1719448682892,"mc":[{"id":"1.230180131","marketDefinition":{"bspMarket":true,"turnInPlayEnabled":false,"persistenceEnabled":false,"marketBaseRate":5.0,"eventId":"33376437","eventTypeId":"4339","numberOfWinners":2,"bettingType":"ODDS","marketType":"PLACE","marketTime":"2024-06-27T16:21:00.000Z","suspendTime":"2024-06-27T16:21:00.000Z","bspReconciled":false,"complete":true,"inPlay":false,"crossMatching":false,"runnersVoidable":false,"numberOfActiveRunners":6,"betDelay":0,"status":"OPEN","runners":[{"status":"ACTIVE","sortPriority":1,"id":66499052,"name":"1. Salacres Wild"},{"status":"ACTIVE","sortPriority":2,"id":43210435,"name":"2. Bemyangelrosa"},{"status":"ACTIVE","sortPriority":3,"id":41138102,"name":"3. Traptoline Zorro"},{"status":"ACTIVE","sortPriority":4,"id":69979297,"name":"4. Jacktavern Pele"},{"status":"ACTIVE","sortPriority":5,"id":58149406,"name":"5. Salacres Herbert"},{"status":"ACTIVE","sortPriority":6,"id":51843546,"name":"6. Salacres Maybach"}],"regulators":["MR_INT"],"venue":"Towcester","countryCode":"GB","discountAllowed":true,"timezone":"Europe/London","openDate":"2024-06-27T13:33:00.000Z","version":5994767145,"name":"To Be Placed","eventName":"Towcester 27th Jun"},"rc":[{"atb":[[1.01,32.96]],"id":58149406},{"atl":[[1000,0.17]],"id":58149406},{"spn":500.5,"spf":"NaN","id":58149406},{"atb":[[1.03,10.99]],"id":41138102},{"atl":[[1000,0.17]],"id":41138102},{"spn":500.51,"spf":"NaN","id":41138102},{"atb":[[1.02,16.48]],"id":43210435},{"atl":[[1000,0.17]],"id":43210435},{"spn":500.51,"spf":"NaN","id":43210435},{"atb":[[1.02,16.48]],"id":66499052},{"atl":[[1000,0.17]],"id":66499052},{"spn":500.51,"spf":"NaN","id":66499052},{"atb":[[1.01,32.96]],"id":51843546},{"atl":[[1000,0.17]],"id":51843546},{"spn":500.5,"spf":"NaN","id":51843546},{"atb":[[1.03,10.99]],"id":69979297},{"atl":[[1000,0.17]],"id":69979297},{"spn":500.51,"spf":"NaN","id":69979297}],"con":true,"img":true}]}
{"op":"mcm","clk":"11538174191","pt":1719454082864,"mc":[{"id":"1.230180131","marketDefinition":{"bspMarket":true,"turnInPlayEnabled":false,"persistenceEnabled":false,"marketBaseRate":5.0,"eventId":"33376437","eventTypeId":"4339","numberOfWinners":2,"bettingType":"ODDS","marketType":"PLACE","marketTime":"2024-06-27T16:21:00.000Z","suspendTime":"2024-06-27T16:21:00.000Z","bspReconciled":false,"complete":true,"inPlay":false,"crossMatching":false,"runnersVoidable":false,"numberOfActiveRunners":6,"betDelay":0,"status":"OPEN","runners":[{"status":"ACTIVE","sortPriority":1,"id":66499052,"name":"1. Salacres Wild"},{"status":"ACTIVE","sortPriority":2,"id":43210435,"name":"2. Bemyangelrosa"},{"status":"ACTIVE","sortPriority":3,"id":41138102,"name":"3. Traptoline Zorro"},{"status":"ACTIVE","sortPriority":4,"id":69979297,"name":"4. Jacktavern Pele"},{"status":"ACTIVE","sortPriority":5,"id":58149406,"name":"5. Salacres Herbert"},{"status":"ACTIVE","sortPriority":6,"id":51843546,"name":"6. Salacres Maybach"}],"regulators":["MR_INT"],"venue":"Towcester","countryCode":"GB","discountAllowed":true,"timezone":"Europe/London","openDate":"2024-06-27T13:33:00.000Z","version":5994767145,"name":"To Be Placed","eventName":"Towcester 27th Jun"},"rc":[{"atb":[[1.01,32.97]],"id":58149406},{"atl":[[1000,0.17]],"id":58149406},{"spn":500.5,"spf":"NaN","id":58149406},{"atb":[[1.03,10.99]],"id":41138102},{"atl":[[1000,0.17]],"id":41138102},{"spn":500.51,"spf":"NaN","id":41138102},{"atb":[[1.02,16.48]],"id":43210435},{"atl":[[1000,0.17]],"id":43210435},{"spn":500.51,"spf":"NaN","id":43210435},{"atb":[[1.02,16.48]],"id":66499052},{"atl":[[1000,0.17]],"id":66499052},{"spn":500.51,"spf":"NaN","id":66499052},{"atb":[[1.01,32.97]],"id":51843546},{"atl":[[1000,0.17]],"id":51843546},{"spn":500.5,"spf":"NaN","id":51843546},{"atb":[[1.03,10.99]],"id":69979297},{"atl":[[1000,0.17]],"id":69979297},{"spn":500.51,"spf":"NaN","id":69979297}],"con":true,"img":true}]}
{"op":"mcm","clk":"11538371904","pt":1719459482938,"mc":[{"id":"1.230180131","marketDefinition":{"bspMarket":true,"turnInPlayEnabled":false,"persistenceEnabled":false,"marketBaseRate":5.0,"eventId":"33376437","eventTypeId":"4339","numberOfWinners":2,"bettingType":"ODDS","marketType":"PLACE","marketTime":"2024-06-27T16:21:00.000Z","suspendTime":"2024-06-27T16:21:00.000Z","bspReconciled":false,"complete":true,"inPlay":false,"crossMatching":false,"runnersVoidable":false,"numberOfActiveRunners":6,"betDelay":0,"status":"OPEN","runners":[{"status":"ACTIVE","sortPriority":1,"id":66499052,"name":"1. Salacres Wild"},{"status":"ACTIVE","sortPriority":2,"id":43210435,"name":"2. Bemyangelrosa"},{"status":"ACTIVE","sortPriority":3,"id":41138102,"name":"3. Traptoline Zorro"},{"status":"ACTIVE","sortPriority":4,"id":69979297,"name":"4. Jacktavern Pele"},{"status":"ACTIVE","sortPriority":5,"id":58149406,"name":"5. Salacres Herbert"},{"status":"ACTIVE","sortPriority":6,"id":51843546,"name":"6. Salacres Maybach"}],"regulators":["MR_INT"],"venue":"Towcester","countryCode":"GB","discountAllowed":true,"timezone":"Europe/London","openDate":"2024-06-27T13:33:00.000Z","version":5994767145,"name":"To Be Placed","eventName":"Towcester 27th Jun"},"rc":[{"atb":[[1.01,32.97]],"id":58149406},{"atl":[[1000,0.17]],"id":58149406},{"spn":500.5,"spf":"NaN","id":58149406},{"atb":[[1.03,10.99]],"id":41138102},{"atl":[[1000,0.17]],"id":41138102},{"spn":500.51,"spf":"NaN","id":41138102},{"atb":[[1.02,16.48]],"id":43210435},{"atl":[[1000,0.17]],"id":43210435},{"spn":500.51,"spf":"NaN","id":43210435},{"atb":[[1.02,16.48]],"id":66499052},{"atl":[[1000,0.17]],"id":66499052},{"spn":500.51,"spf":"NaN","id":66499052},{"atb":[[1.01,32.97]],"id":51843546},{"atl":[[1000,0.17]],"id":51843546},{"spn":500.5,"spf":"NaN","id":51843546},{"atb":[[1.03,10.99]],"id":69979297},{"atl":[[1000,0.17]],"id":69979297},{"spn":500.51,"spf":"NaN","id":69979297}],"con":true,"img":true}]}
{"op":"mcm","clk":"11538598981","pt":1719464882863,"mc":[{"id":"1.230180131","marketDefinition":{"bspMarket":true,"turnInPlayEnabled":false,"persistenceEnabled":false,"marketBaseRate":5.0,"eventId":"33376437","eventTypeId":"4339","numberOfWinners":2,"bettingType":"ODDS","marketType":"PLACE","marketTime":"2024-06-27T16:21:00.000Z","suspendTime":"2024-06-27T16:21:00.000Z","bspReconciled":false,"complete":true,"inPlay":false,"crossMatching":false,"runnersVoidable":false,"numberOfActiveRunners":6,"betDelay":0,"status":"OPEN","runners":[{"status":"ACTIVE","sortPriority":1,"id":66499052,"name":"1. Salacres Wild"},{"status":"ACTIVE","sortPriority":2,"id":43210435,"name":"2. Bemyangelrosa"},{"status":"ACTIVE","sortPriority":3,"id":41138102,"name":"3. Traptoline Zorro"},{"status":"ACTIVE","sortPriority":4,"id":69979297,"name":"4. Jacktavern Pele"},{"status":"ACTIVE","sortPriority":5,"id":58149406,"name":"5. Salacres Herbert"},{"status":"ACTIVE","sortPriority":6,"id":51843546,"name":"6. Salacres Maybach"}],"regulators":["MR_INT"],"venue":"Towcester","countryCode":"GB","discountAllowed":true,"timezone":"Europe/London","openDate":"2024-06-27T13:33:00.000Z","version":5994767145,"name":"To Be Placed","eventName":"Towcester 27th Jun"},"rc":[{"atb":[[1.01,32.97]],"id":58149406},{"atl":[[1000,0.17]],"id":58149406},{"spn":500.5,"spf":"NaN","id":58149406},{"atb":[[1.03,10.99]],"id":41138102},{"atl":[[1000,0.17]],"id":41138102},{"spn":500.51,"spf":"NaN","id":41138102},{"atb":[[1.02,16.48]],"id":43210435},{"atl":[[1000,0.17]],"id":43210435},{"spn":500.51,"spf":"NaN","id":43210435},{"atb":[[1.02,16.48]],"id":66499052},{"atl":[[1000,0.17]],"id":66499052},{"spn":500.51,"spf":"NaN","id":66499052},{"atb":[[1.01,32.97]],"id":51843546},{"atl":[[1000,0.17]],"id":51843546},{"spn":500.5,"spf":"NaN","id":51843546},{"atb":[[1.03,10.99]],"id":69979297},{"atl":[[1000,0.17]],"id":69979297},{"spn":500.51,"spf":"NaN","id":69979297}],"con":true,"img":true}]}
{"op":"mcm","clk":"11538906737","pt":1719471498581,"mc":[{"id":"1.230180131","rc":[{"atb":[[1.01,32.97],[1.07,2.48]],"id":58149406},{"atl":[[1000,1.17]],"id":58149406},{"spn":500.53,"spf":"NaN","id":58149406},{"atb":[[1.03,10.99],[1.07,2.48]],"id":41138102},{"atl":[[1000,1.17]],"id":41138102},{"spn":500.53,"spf":"NaN","id":41138102},{"atb":[[1.02,16.48],[1.07,2.48]],"id":43210435},{"atl":[[1000,1.17]],"id":43210435},{"spn":500.53,"spf":"NaN","id":43210435},{"atb":[[1.02,16.48],[1.07,2.48]],"id":66499052},{"atl":[[1000,1.17]],"id":66499052},{"spn":500.53,"spf":"NaN","id":66499052},{"atb":[[1.01,32.97],[1.07,2.48]],"id":51843546},{"atl":[[1000,1.17]],"id":51843546},{"spn":500.53,"spf":"NaN","id":51843546},{"atb":[[1.03,10.99],[1.07,2.48]],"id":69979297},{"atl":[[1000,1.17]],"id":69979297},{"spn":500.53,"spf":"NaN","id":69979297}],"con":true,"img":false}]}
{"op":"mcm","clk":"11538906747","pt":1719471498785,"mc":[{"id":"1.230180131","rc":[{"atl":[[1000,0.65]],"id":58149406},{"atl":[[1000,0.65]],"id":41138102},{"atl":[[1000,0.65]],"id":43210435},{"atl":[[1000,0.65]],"id":66499052},{"atl":[[1000,0.65]],"id":51843546},{"atl":[[1000,0.65]],"id":69979297}],"con":true,"img":false}]}
{"op":"mcm","clk":"11538906756","pt":1719471498990,"mc":[{"id":"1.230180131","rc":[{"atl":[[1000,0.17]],"id":58149406},{"atl":[[1000,0.17]],"id":41138102},{"atl":[[1000,0.17]],"id":43210435},{"atl":[[1000,0.17]],"id":66499052},{"atl":[[1000,0.17]],"id":51843546},{"atl":[[1000,0.17]],"id":69979297}],"con":true,"img":false}]}
{"op":"mcm","clk":"11538906762","pt":1719471499095,"mc":[{"id":"1.230180131","rc":[{"atl":[[75,0.48]],"id":58149406},{"atl":[[75,0.48]],"id":41138102},{"atl":[[75,0.48]],"id":43210435},{"atl":[[75,0.48]],"id":66499052},{"atl":[[75,0.48]],"id":51843546},{"atl":[[75,0.48]],"id":69979297}],"con":true,"img":false}]}
{"op":"mcm","clk":"11539126213","pt":1719475682885,"mc":[{"id":"1.230180131","marketDefinition":{"bspMarket":true,"turnInPlayEnabled":false,"persistenceEnabled":false,"marketBaseRate":5.0,"eventId":"33376437","eventTypeId":"4339","numberOfWinners":2,"bettingType":"ODDS","marketType":"PLACE","marketTime":"2024-06-27T16:21:00.000Z","suspendTime":"2024-06-27T16:21:00.000Z","bspReconciled":false,"complete":true,"inPlay":false,"crossMatching":false,"runnersVoidable":false,"numberOfActiveRunners":6,"betDelay":0,"status":"OPEN","runners":[{"status":"ACTIVE","sortPriority":1,"id":66499052,"name":"1. Salacres Wild"},{"status":"ACTIVE","sortPriority":2,"id":43210435,"name":"2. Bemyangelrosa"},{"status":"ACTIVE","sortPriority":3,"id":41138102,"name":"3. Traptoline Zorro"},{"status":"ACTIVE","sortPriority":4,"id":69979297,"name":"4. Jacktavern Pele"},{"status":"ACTIVE","sortPriority":5,"id":58149406,"name":"5. Salacres Herbert"},{"status":"ACTIVE","sortPriority":6,"id":51843546,"name":"6. Salacres Maybach"}],"regulators":["MR_INT"],"venue":"Towcester","countryCode":"GB","discountAllowed":true,"timezone":"Europe/London","openDate":"2024-06-27T13:33:00.000Z","version":5994767145,"name":"To Be Placed","eventName":"Towcester 27th Jun"},"rc":[{"atb":[[1.01,32.96],[1.07,2.48]],"id":58149406},{"atl":[[75,0.48],[1000,0.17]],"id":58149406},{"spn":38.03,"spf":"NaN","id":58149406},{"atb":[[1.03,10.99],[1.07,2.48]],"id":41138102},{"atl":[[75,0.48],[1000,0.17]],"id":41138102},{"spn":38.03,"spf":"NaN","id":41138102},{"atb":[[1.02,16.48],[1.07,2.48]],"id":43210435},{"atl":[[75,0.48],[1000,0.17]],"id":43210435},{"spn":38.03,"spf":"NaN","id":43210435},{"atb":[[1.02,16.48],[1.07,2.48]],"id":66499052},{"atl":[[75,0.48],[1000,0.17]],"id":66499052},{"spn":38.03,"spf":"NaN","id":66499052},{"atb":[[1.01,32.96],[1.07,2.48]],"id":51843546},{"atl":[[75,0.48],[1000,0.17]],"id":51843546},{"spn":38.03,"spf":"NaN","id":51843546},{"atb":[[1.03,10.99],[1.07,2.48]],"id":69979297},{"atl":[[75,0.48],[1000,0.17]],"id":69979297},{"spn":38.03,"spf":"NaN","id":69979297}],"con":true,"img":true}]}
{"op":"mcm","clk":"11539442380","pt":1719481082825,"mc":[{"id":"1.230180131","marketDefinition":{"bspMarket":true,"turnInPlayEnabled":false,"persistenceEnabled":false,"marketBaseRate":5.0,"eventId":"33376437","eventTypeId":"4339","numberOfWinners":2,"bettingType":"ODDS","marketType":"PLACE","marketTime":"2024-06-27T16:21:00.000Z","suspendTime":"2024-06-27T16:21:00.000Z","bspReconciled":false,"complete":true,"inPlay":false,"crossMatching":false,"runnersVoidable":false,"numberOfActiveRunners":6,"betDelay":0,"status":"OPEN","runners":[{"status":"ACTIVE","sortPriority":1,"id":66499052,"name":"1. Salacres Wild"},{"status":"ACTIVE","sortPriority":2,"id":43210435,"name":"2. Bemyangelrosa"},{"status":"ACTIVE","sortPriority":3,"id":41138102,"name":"3. Traptoline Zorro"},{"status":"ACTIVE","sortPriority":4,"id":69979297,"name":"4. Jacktavern Pele"},{"status":"ACTIVE","sortPriority":5,"id":58149406,"name":"5. Salacres Herbert"},{"status":"ACTIVE","sortPriority":6,"id":51843546,"name":"6. Salacres Maybach"}],"regulators":["MR_INT"],"venue":"Towcester","countryCode":"GB","discountAllowed":true,"timezone":"Europe/London","openDate":"2024-06-27T13:33:00.000Z","version":5994767145,"name":"To Be Placed","eventName":"Towcester 27th Jun"},"rc":[{"atb":[[1.01,32.95],[1.07,2.48]],"id":58149406},{"atl":[[75,0.48],[1000,0.17]],"id":58149406},{"spn":38.03,"spf":"NaN","id":58149406},{"atb":[[1.03,10.98],[1.07,2.48]],"id":41138102},{"atl":[[75,0.48],[1000,0.17]],"id":41138102},{"spn":38.03,"spf":"NaN","id":41138102},{"atb":[[1.02,16.47],[1.07,2.48]],"id":43210435},{"atl":[[75,0.48],[1000,0.17]],"id":43210435},{"spn":38.03,"spf":"NaN","id":43210435},{"atb":[[1.02,16.47],[1.07,2.48]],"id":66499052},{"atl":[[75,0.48],[1000,0.17]],"id":66499052},{"spn":38.03,"spf":"NaN","id":66499052},{"atb":[[1.01,32.95],[1.07,2.48]],"id":51843546},{"atl":[[75,0.48],[1000,0.17]],"id":51843546},{"spn":38.03,"spf":"NaN","id":51843546},{"atb":[[1.03,10.98],[1.07,2.48]],"id":69979297},{"atl":[[75,0.48],[1000,0.17]],"id":69979297},{"spn":38.03,"spf":"NaN","id":69979297}],"con":true,"img":true}]}
{"op":"mcm","clk":"11540687362","pt":1719497282744,"mc":[{"id":"1.230180131","marketDefinition":{"bspMarket":true,"turnInPlayEnabled":false,"persistenceEnabled":false,"marketBaseRate":5.0,"eventId":"33376437","eventTypeId":"4339","numberOfWinners":2,"bettingType":"ODDS","marketType":"PLACE","marketTime":"2024-06-27T16:21:00.000Z","suspendTime":"2024-06-27T16:21:00.000Z","bspReconciled":false,"complete":true,"inPlay":false,"crossMatching":false,"runnersVoidable":false,"numberOfActiveRunners":6,"betDelay":0,"status":"OPEN","runners":[{"status":"ACTIVE","sortPriority":1,"id":66499052,"name":"1. Salacres Wild"},{"status":"ACTIVE","sortPriority":2,"id":43210435,"name":"2. Bemyangelrosa"},{"status":"ACTIVE","sortPriority":3,"id":41138102,"name":"3. Traptoline Zorro"},{"status":"ACTIVE","sortPriority":4,"id":69979297,"name":"4. Jacktavern Pele"},{"status":"ACTIVE","sortPriority":5,"id":58149406,"name":"5. Salacres Herbert"},{"status":"ACTIVE","sortPriority":6,"id":51843546,"name":"6. Salacres Maybach"}],"regulators":["MR_INT"],"venue":"Towcester","countryCode":"GB","discountAllowed":true,"timezone":"Europe/London","openDate":"2024-06-27T13:33:00.000Z","version":5994767145,"name":"To Be Placed","eventName":"Towcester 27th Jun"},"rc":[{"atb":[[1.01,32.98],[1.07,2.48]],"id":58149406},{"atl":[[75,0.48],[1000,0.17]],"id":58149406},{"spn":38.03,"spf":"NaN","id":58149406},{"atb":[[1.03,10.99],[1.07,2.48]],"id":41138102},{"atl":[[75,0.48],[1000,0.17]],"id":41138102},{"spn":38.03,"spf":"NaN","id":41138102},{"atb":[[1.02,16.49],[1.07,2.48]],"id":43210435},{"atl":[[75,0.48],[1000,0.17]],"id":43210435},{"spn":38.03,"spf":"NaN","id":43210435},{"atb":[[1.02,16.49],[1.07,2.48]],"id":66499052},{"atl":[[75,0.48],[1000,0.17]],"id":66499052},{"spn":38.03,"spf":"NaN","id":66499052},{"atb":[[1.01,32.98],[1.07,2.48]],"id":51843546},{"atl":[[75,0.48],[1000,0.17]],"id":51843546},{"spn":38.03,"spf":"NaN","id":51843546},{"atb":[[1.03,10.99],[1.07,2.48]],"id":69979297},{"atl":[[75,0.48],[1000,0.17]],"id":69979297},{"spn":38.03,"spf":"NaN","id":69979297}],"con":true,"img":true}]}
{"op":"mcm","clk":"11541142969","pt":1719502682764,"mc":[{"id":"1.230180131","marketDefinition":{"bspMarket":true,"turnInPlayEnabled":false,"persistenceEnabled":false,"marketBaseRate":5.0,"eventId":"33376437","eventTypeId":"4339","numberOfWinners":2,"bettingType":"ODDS","marketType":"PLACE","marketTime":"2024-06-27T16:21:00.000Z","suspendTime":"2024-06-27T16:21:00.000Z","bspReconciled":false,"complete":true,"inPlay":false,"crossMatching":false,"runnersVoidable":false,"numberOfActiveRunners":6,"betDelay":0,"status":"OPEN","runners":[{"status":"ACTIVE","sortPriority":1,"id":66499052,"name":"1. Salacres Wild"},{"status":"ACTIVE","sortPriority":2,"id":43210435,"name":"2. Bemyangelrosa"},{"status":"ACTIVE","sortPriority":3,"id":41138102,"name":"3. Traptoline Zorro"},{"status":"ACTIVE","sortPriority":4,"id":69979297,"name":"4. Jacktavern Pele"},{"status":"ACTIVE","sortPriority":5,"id":58149406,"name":"5. Salacres Herbert"},{"status":"ACTIVE","sortPriority":6,"id":51843546,"name":"6. Salacres Maybach"}],"regulators":["MR_INT"],"venue":"Towcester","countryCode":"GB","discountAllowed":true,"timezone":"Europe/London","openDate":"2024-06-27T13:33:00.000Z","version":5994767145,"name":"To Be Placed","eventName":"Towcester 27th Jun"},"rc":[{"atb":[[1.01,32.98],[1.07,2.48]],"id":58149406},{"atl":[[75,0.48],[1000,0.17]],"id":58149406},{"spn":38.03,"spf":"NaN","id":58149406},{"atb":[[1.03,10.99],[1.07,2.48]],"id":41138102},{"atl":[[75,0.48],[1000,0.17]],"id":41138102},{"spn":38.03,"spf":"NaN","id":41138102},{"atb":[[1.02,16.49],[1.07,2.48]],"id":43210435},{"atl":[[75,0.48],[1000,0.17]],"id":43210435},{"spn":38.03,"spf":"NaN","id":43210435},{"atb":[[1.02,16.49],[1.07,2.48]],"id":66499052},{"atl":[[75,0.48],[1000,0.17]],"id":66499052},{"spn":38.03,"spf":"NaN","id":66499052},{"atb":[[1.01,32.98],[1.07,2.48]],"id":51843546},{"atl":[[75,0.48],[1000,0.17]],"id":51843546},{"spn":38.03,"spf":"NaN","id":51843546},{"atb":[[1.03,10.99],[1.07,2.48]],"id":69979297},{"atl":[[75,0.48],[1000,0.17]],"id":69979297},{"spn":38.03,"spf":"NaN","id":69979297}],"con":true,"img":true}]}
{"op":"mcm","clk":"11541222771","pt":1719503523170,"mc":[{"id":"1.230180131","rc":[{"atb":[[1.01,32.98],[1.04,1]],"id":58149406},{"spn":38.03,"spf":"NaN","id":58149406},{"atb":[[1.03,10.99],[1.04,1]],"id":41138102},{"spn":38.03,"spf":"NaN","id":41138102},{"atb":[[1.02,16.49],[1.04,1]],"id":43210435},{"spn":38.03,"spf":"NaN","id":43210435},{"atb":[[1.02,16.49],[1.04,1]],"id":66499052},{"spn":38.03,"spf":"NaN","id":66499052},{"atb":[[1.01,32.98],[1.04,1]],"id":51843546},{"spn":38.03,"spf":"NaN","id":51843546},{"atb":[[1.03,10.99],[1.04,1]],"id":69979297},{"spn":38.03,"spf":"NaN","id":69979297}],"con":true,"img":false}]}
{"op":"mcm","clk":"11541222790","pt":1719503523376,"mc":[{"id":"1.230180131","rc":[{"atb":[[1.04,0.25]],"id":58149406},{"atb":[[1.04,0.25]],"id":41138102},{"atb":[[1.04,0.25]],"id":43210435},{"atb":[[1.04,0.25]],"id":66499052},{"atb":[[1.04,0.25]],"id":51843546},{"atb":[[1.04,0.25]],"id":69979297}],"con":true,"img":false}]}
{"op":"mcm","clk":"11541222820","pt":1719503523730,"mc":[{"id":"1.230180131","rc":[{"atb":[[1.04,0]],"id":58149406},{"atb":[[1.04,0]],"id":41138102},{"atb":[[1.04,0]],"id":43210435},{"atb":[[1.04,0]],"id":66499052},{"atb":[[1.04,0]],"id":51843546},{"atb":[[1.04,0]],"id":69979297}],"con":true,"img":false}]}
{"op":"mcm","clk":"11541222831","pt":1719503523741,"mc":[{"id":"1.230180131","rc":[{"atb":[[1.2,0.25]],"id":58149406},{"atb":[[1.2,0.25]],"id":41138102},{"atb":[[1.2,0.25]],"id":43210435},{"atb":[[1.2,0.25]],"id":66499052},{"atb":[[1.2,0.25]],"id":51843546},{"atb":[[1.2,0.25]],"id":69979297}],"con":true,"img":false}]}
{"op":"mcm","clk":"11541232278","pt":1719503618409,"mc":[{"id":"1.230180131","rc":[{"spn":38.1,"spf":"NaN","id":58149406},{"spn":38.1,"spf":"NaN","id":41138102},{"spn":38.1,"spf":"NaN","id":43210435},{"atb":[[1.09,47.04]],"id":66499052},{"spn":38.1,"spf":"NaN","id":66499052},{"spn":38.1,"spf":"NaN","id":51843546},{"spn":38.1,"spf":"NaN","id":69979297}],"con":true,"img":false}]}
{"op":"mcm","clk":"11541232290","pt":1719503618508,"mc":[{"id":"1.230180131","rc":[{"atb":[[1.09,47.04]],"id":41138102}],"con":true,"img":false}]}
{"op":"mcm","clk":"11541232320","pt":1719503618815,"mc":[{"id":"1.230180131","rc":[{"atb":[[1.09,47.04]],"id":51843546}],"con":true,"img":false}]}
{"op":"mcm","clk":"11541232354","pt":1719503619185,"mc":[{"id":"1.230180131","rc":[{"atb":[[1.09,47.04]],"id":43210435}],"con":true,"img":false}]}
{"op":"mcm","clk":"11541238237","pt":1719503679254,"mc":[{"id":"1.230180131","rc":[{"atb":[[1.11,35.93]],"id":43210435}],"con":true,"img":false}]}
{"op":"mcm","clk":"11541238244","pt":1719503679363,"mc":[{"id":"1.230180131","rc":[{"atb":[[1.11,35.93]],"id":66499052}],"con":true,"img":false}]}
{"op":"mcm","clk":"11541238270","pt":1719503679466,"mc":[{"id":"1.230180131","rc":[{"atb":[[1.11,35.93]],"id":51843546}],"con":true,"img":false}]}
{"op":"mcm","clk":"11541238281","pt":1719503679561,"mc":[{"id":"1.230180131","rc":[{"atb":[[1.11,35.93]],"id":41138102}],"con":true,"img":false}]}
{"op":"mcm","clk":"11541238655","pt":1719503683375,"mc":[{"id":"1.230180131","marketDefinition":{"bspMarket":true,"turnInPlayEnabled":false,"persistenceEnabled":false,"marketBaseRate":5.0,"eventId":"33376437","eventTypeId":"4339","numberOfWinners":2,"bettingType":"ODDS","marketType":"PLACE","marketTime":"2024-06-27T16:21:00.000Z","suspendTime":"2024-06-27T16:21:00.000Z","bspReconciled":false,"complete":true,"inPlay":false,"crossMatching":true,"runnersVoidable":false,"numberOfActiveRunners":6,"betDelay":0,"status":"OPEN","runners":[{"status":"ACTIVE","sortPriority":1,"id":66499052,"name":"1. Salacres Wild"},{"status":"ACTIVE","sortPriority":2,"id":43210435,"name":"2. Bemyangelrosa"},{"status":"ACTIVE","sortPriority":3,"id":41138102,"name":"3. Traptoline Zorro"},{"status":"ACTIVE","sortPriority":4,"id":69979297,"name":"4. Jacktavern Pele"},{"status":"ACTIVE","sortPriority":5,"id":58149406,"name":"5. Salacres Herbert"},{"status":"ACTIVE","sortPriority":6,"id":51843546,"name":"6. Salacres Maybach"}],"regulators":["MR_INT"],"venue":"Towcester","countryCode":"GB","discountAllowed":true,"timezone":"Europe/London","openDate":"2024-06-27T13:33:00.000Z","version":5994767145,"name":"To Be Placed","eventName":"Towcester 27th Jun"},"rc":[],"con":true,"img":false}]}
{"op":"mcm","clk":"11541239350","pt":1719503690461,"mc":[{"id":"1.230180131","rc":[{"atb":[[1.09,0]],"id":66499052}],"con":true,"img":false}]}
{"op":"mcm","clk":"11541239364","pt":1719503690668,"mc":[{"id":"1.230180131","rc":[{"atb":[[1.09,0]],"id":43210435}],"con":true,"img":false}]}
{"op":"mcm","clk":"11541239370","pt":1719503690769,"mc":[{"id":"1.230180131","rc":[{"atb":[[1.09,0]],"id":41138102}],"con":true,"img":false}]}
{"op":"mcm","clk":"11541239399","pt":1719503691183,"mc":[{"id":"1.230180131","rc":[{"atb":[[1.09,0]],"id":51843546}],"con":true,"img":false}]}
{"op":"mcm","clk":"11541239437","pt":1719503691697,"mc":[{"id":"1.230180131","rc":[{"atb":[[1.13,32.56]],"id":43210435}],"con":true,"img":false}]}
{"op":"mcm","clk":"11541239458","pt":1719503692012,"mc":[{"id":"1.230180131","rc":[{"atb":[[1.13,32.56]],"id":66499052}],"con":true,"img":false}]}
{"op":"mcm","clk":"11541239494","pt":1719503692268,"mc":[{"id":"1.230180131","rc":[{"atb":[[1.13,32.56]],"id":41138102}],"con":true,"img":false}]}
{"op":"mcm","clk":"11541239511","pt":1719503692474,"mc":[{"id":"1.230180131","rc":[{"atb":[[1.13,32.56]],"id":51843546}],"con":true,"img":false}]}
{"op":"mcm","clk":"11541239880","pt":1719503696234,"mc":[{"id":"1.230180131","rc":[{"atb":[[1.11,0]],"id":66499052}],"con":true,"img":false}]}
{"op":"mcm","clk":"11541239890","pt":1719503696286,"mc":[{"id":"1.230180131","rc":[{"atb":[[1.11,0]],"id":41138102}],"con":true,"img":false}]}
{"op":"mcm","clk":"11541239901","pt":1719503696388,"mc":[{"id":"1.230180131","rc":[{"atb":[[1.11,0]],"id":51843546}],"con":true,"img":false}]}
{"op":"mcm","clk":"11541239924","pt":1719503696593,"mc":[{"id":"1.230180131","rc":[{"atb":[[1.11,0]],"id":43210435}],"con":true,"img":false}]}
{"op":"mcm","clk":"11541239953","pt":1719503696902,"mc":[{"id":"1.230180131","rc":[{"atb":[[1.15,26.34]],"id":41138102}],"con":true,"img":false}]}
{"op":"mcm","clk":"11541239963","pt":1719503697006,"mc":[{"id":"1.230180131","rc":[{"atb":[[1.15,26.34]],"id":66499052}],"con":true,"img":false}]}
{"op":"mcm","clk":"11541239974","pt":1719503697113,"mc":[{"id":"1.230180131","rc":[{"atb":[[1.15,26.34]],"id":43210435}],"con":true,"img":false}]}
{"op":"mcm","clk":"11541239986","pt":1719503697211,"mc":[{"id":"1.230180131","rc":[{"atb":[[1.15,26.34]],"id":51843546}],"con":true,"img":false}]}
{"op":"mcm","clk":"11541242804","pt":1719503724728,"mc":[{"id":"1.230180131","rc":[{"atb":[[1.13,0]],"id":66499052}],"con":true,"img":false}]}
{"op":"mcm","clk":"11541242833","pt":1719503725040,"mc":[{"id":"1.230180131","rc":[{"atb":[[1.13,0]],"id":41138102},{"atb":[[1.13,0]],"id":51843546}],"con":true,"img":false}]}
{"op":"mcm","clk":"11541242867","pt":1719503725442,"mc":[{"id":"1.230180131","rc":[{"atb":[[1.13,0]],"id":43210435}],"con":true,"img":false}]}
{"op":"mcm","clk":"11541242930","pt":1719503726131,"mc":[{"id":"1.230180131","rc":[{"atb":[[1.17,24.9]],"id":41138102}],"con":true,"img":false}]}
{"op":"mcm","clk":"11541242941","pt":1719503726241,"mc":[{"id":"1.230180131","rc":[{"atb":[[1.17,24.9]],"id":66499052}],"con":true,"img":false}]}
{"op":"mcm","clk":"11541242970","pt":1719503726545,"mc":[{"id":"1.230180131","rc":[{"atb":[[1.17,24.9]],"id":51843546}],"con":true,"img":false}]}
{"op":"mcm","clk":"11541242998","pt":1719503726805,"mc":[{"id":"1.230180131","rc":[{"atb":[[1.17,24.9]],"id":43210435}],"con":true,"img":false}]}
{"op":"mcm","clk":"11541243581","pt":1719503732637,"mc":[{"id":"1.230180131","rc":[{"atb":[[1.15,0]],"id":43210435},{"atb":[[1.15,0]],"id":66499052}],"con":true,"img":false}]}
{"op":"mcm","clk":"11541243602","pt":1719503732843,"mc":[{"id":"1.230180131","rc":[{"atb":[[1.15,0]],"id":41138102}],"con":true,"img":false}]}
{"op":"mcm","clk":"11541243640","pt":1719503733262,"mc":[{"id":"1.230180131","rc":[{"atb":[[1.19,20.8]],"id":43210435},{"atb":[[1.19,20.8]],"id":66499052}],"con":true,"img":false}]}
{"op":"mcm","clk":"11541243655","pt":1719503733414,"mc":[{"id":"1.230180131","rc":[{"atb":[[1.19,20.8]],"id":41138102}],"con":true,"img":false}]}
{"op":"mcm","clk":"11541243671","pt":1719503733622,"mc":[{"id":"1.230180131","rc":[{"atb":[[1.15,0]],"id":51843546}],"con":true,"img":false}]}
{"op":"mcm","clk":"11541243686","pt":1719503733828,"mc":[{"id":"1.230180131","rc":[{"atb":[[1.19,20.8]],"id":51843546}],"con":true,"img":false}]}
{"op":"mcm","clk":"11541246441","pt":1719503762080,"mc":[{"id":"1.230180131","rc":[{"atb":[[1.17,0]],"id":66499052}],"con":true,"img":false}]}
{"op":"mcm","clk":"11541246454","pt":1719503762179,"mc":[{"id":"1.230180131","rc":[{"atb":[[1.17,0]],"id":43210435}],"con":true,"img":false}]}
{"op":"mcm","clk":"11541246474","pt":1719503762387,"mc":[{"id":"1.230180131","rc":[{"atb":[[1.17,0]],"id":41138102}],"con":true,"img":false}]}
{"op":"mcm","clk":"11541246495","pt":1719503762700,"mc":[{"id":"1.230180131","rc":[{"atb":[[1.21,20.16]],"id":43210435},{"atb":[[1.17,0]],"id":51843546}],"con":true,"img":false}]}
{"op":"mcm","clk":"11541246524","pt":1719503762966,"mc":[{"id":"1.230180131","rc":[{"atb":[[1.21,20.16]],"id":66499052}],"con":true,"img":false}]}
{"op":"mcm","clk":"11541246546","pt":1719503763171,"mc":[{"id":"1.230180131","rc":[{"atb":[[1.21,20.16]],"id":41138102}],"con":true,"img":false}]}
{"op":"mcm","clk":"11541246554","pt":1719503763277,"mc":[{"id":"1.230180131","rc":[{"atb":[[1.21,20.16]],"id":51843546}],"con":true,"img":false}]}
{"op":"mcm","clk":"11541247138","pt":1719503769061,"mc":[{"id":"1.230180131","rc":[{"atb":[[1.19,0]],"id":66499052}],"con":true,"img":false}]}
{"op":"mcm","clk":"11541247148","pt":1719503769173,"mc":[{"id":"1.230180131","rc":[{"atb":[[1.19,0]],"id":43210435}],"con":true,"img":false}]}
{"op":"mcm","clk":"11541247164","pt":1719503769369,"mc":[{"id":"1.230180131","rc":[{"atb":[[1.19,0]],"id":51843546}],"con":true,"img":false}]}
{"op":"mcm","clk":"11541247184","pt":1719503769580,"mc":[{"id":"1.230180131","rc":[{"atb":[[1.19,0]],"id":41138102}],"con":true,"img":false}]}
{"op":"mcm","clk":"11541247206","pt":1719503769780,"mc":[{"id":"1.230180131","rc":[{"atb":[[1.23,17.18]],"id":41138102},{"atb":[[1.23,17.18]],"id":66499052}],"con":true,"img":false}]}
{"op":"mcm","clk":"11541247223","pt":1719503769986,"mc":[{"id":"1.230180131","rc":[{"atb":[[1.23,17.18]],"id":51843546}],"con":true,"img":false}]}
{"op":"mcm","clk":"11541247276","pt":1719503770506,"mc":[{"id":"1.230180131","rc":[{"atb":[[1.23,17.18]],"id":43210435}],"con":true,"img":false}]}
{"op":"mcm","clk":"11541249699","pt":1719503795394,"mc":[{"id":"1.230180131","rc":[{"atb":[[1.21,0]],"id":51843546}],"con":true,"img":false}]}
{"op":"mcm","clk":"11541249709","pt":1719503795497,"mc":[{"id":"1.230180131","rc":[{"atb":[[1.21,0]],"id":66499052}],"con":true,"img":false}]}
{"op":"mcm","clk":"11541249738","pt":1719503795805,"mc":[{"id":"1.230180131","rc":[{"atb":[[1.21,0]],"id":41138102}],"con":true,"img":false}]}
{"op":"mcm","clk":"11541249767","pt":1719503796115,"mc":[{"id":"1.230180131","rc":[{"atb":[[1.21,0]],"id":43210435}],"con":true,"img":false}]}
{"op":"mcm","clk":"11541249809","pt":1719503796626,"mc":[{"id":"1.230180131","rc":[{"atb":[[1.25,16.93]],"id":51843546}],"con":true,"img":false}]}
{"op":"mcm","clk":"11541249825","pt":1719503796783,"mc":[{"id":"1.230180131","rc":[{"atb":[[1.25,16.93]],"id":66499052}],"con":true,"img":false}]}
{"op":"mcm","clk":"11541249850","pt":1719503797094,"mc":[{"id":"1.230180131","rc":[{"atb":[[1.25,16.93]],"id":41138102}],"con":true,"img":false}]}
{"op":"mcm","clk":"11541249879","pt":1719503797411,"mc":[{"id":"1.230180131","rc":[{"atb":[[1.25,16.93]],"id":43210435}],"con":true,"img":false}]}
{"op":"mcm","clk":"11541250612","pt":1719503804744,"mc":[{"id":"1.230180131","rc":[{"atb":[[1.23,0]],"id":66499052}],"con":true,"img":false}]}
{"op":"mcm","clk":"11541250625","pt":1719503804846,"mc":[{"id":"1.230180131","rc":[{"atb":[[1.23,0]],"id":41138102}],"con":true,"img":false}]}
{"op":"mcm","clk":"11541250635","pt":1719503804948,"mc":[{"id":"1.230180131","rc":[{"atb":[[1.23,0]],"id":51843546}],"con":true,"img":false}]}
{"op":"mcm","clk":"11541250698","pt":1719503805415,"mc":[{"id":"1.230180131","rc":[{"atb":[[1.27,14.64]],"id":41138102},{"atb":[[1.27,14.64]],"id":66499052}],"con":true,"img":false}]}
{"op":"mcm","clk":"11541250718","pt":1719503805630,"mc":[{"id":"1.230180131","rc":[{"atb":[[1.23,0]],"id":43210435},{"atb":[[1.27,14.64]],"id":51843546}],"con":true,"img":false}]}
{"op":"mcm","clk":"11541250738","pt":1719503805825,"mc":[{"id":"1.230180131","rc":[{"atb":[[1.27,14.64]],"id":43210435}],"con":true,"img":false}]}
{"op":"mcm","clk":"11541253128","pt":1719503829768,"mc":[{"id":"1.230180131","rc":[{"spn":38.13,"spf":"NaN","id":41138102},{"atb":[[1.25,0]],"id":43210435},{"spn":38.13,"spf":"NaN","id":43210435},{"atb":[[1.25,0]],"id":66499052},{"spn":38.13,"spf":"NaN","id":66499052},{"spn":38.13,"spf":"NaN","id":51843546}],"con":true,"img":false}]}
{"op":"mcm","clk":"11541253158","pt":1719503830026,"mc":[{"id":"1.230180131","rc":[{"atb":[[1.25,0]],"id":51843546}],"con":true,"img":false}]}
{"op":"mcm","clk":"11541253188","pt":1719503830336,"mc":[{"id":"1.230180131","rc":[{"atb":[[1.25,0]],"id":41138102}],"con":true,"img":false}]}
{"op":"mcm","clk":"11541253244","pt":1719503830951,"mc":[{"id":"1.230180131","rc":[{"atb":[[1.29,14.59]],"id":66499052},{"atb":[[1.29,14.59]],"id":51843546}],"con":true,"img":false}]}
{"op":"mcm","clk":"11541253273","pt":1719503831259,"mc":[{"id":"1.230180131","rc":[{"atb":[[1.29,14.59]],"id":43210435}],"con":true,"img":false}]}
{"op":"mcm","clk":"11541253308","pt":1719503831567,"mc":[{"id":"1.230180131","rc":[{"atb":[[1.29,14.59]],"id":41138102}],"con":true,"img":false}]}
{"op":"mcm","clk":"11541254150","pt":1719503840081,"mc":[{"id":"1.230180131","rc":[{"atb":[[1.27,0]],"id":43210435},{"atb":[[1.27,0]],"id":66499052}],"con":true,"img":false}]}
{"op":"mcm","clk":"11541254170","pt":1719503840289,"mc":[{"id":"1.230180131","rc":[{"atb":[[1.27,0]],"id":41138102}],"con":true,"img":false}]}
{"op":"mcm","clk":"11541254194","pt":1719503840441,"mc":[{"id":"1.230180131","rc":[{"atb":[[1.31,12.75]],"id":43210435},{"atb":[[1.31,12.75]],"id":66499052}],"con":true,"img":false}]}
{"op":"mcm","clk":"11541254219","pt":1719503840649,"mc":[{"id":"1.230180131","rc":[{"atb":[[1.27,0]],"id":51843546}],"con":true,"img":false}]}
{"op":"mcm","clk":"11541254272","pt":1719503841059,"mc":[{"id":"1.230180131","rc":[{"atb":[[1.31,12.75]],"id":51843546}],"con":true,"img":false}]}
{"op":"mcm","clk":"11541254297","pt":1719503841269,"mc":[{"id":"1.230180131","rc":[{"atb":[[1.31,12.75]],"id":41138102}],"con":true,"img":false}]}
{"op":"mcm","clk":"11541256696","pt":1719503862404,"mc":[{"id":"1.230180131","rc":[{"atb":[[1.29,0]],"id":66499052}],"con":true,"img":false}]}
{"op":"mcm","clk":"11541256707","pt":1719503862507,"mc":[{"id":"1.230180131","rc":[{"atb":[[1.29,0]],"id":43210435}],"con":true,"img":false}]}
{"op":"mcm","clk":"11541256736","pt":1719503862868,"mc":[{"id":"1.230180131","rc":[{"atb":[[1.29,0]],"id":51843546}],"con":true,"img":false}]}
{"op":"mcm","clk":"11541256768","pt":1719503863132,"mc":[{"id":"1.230180131","rc":[{"atb":[[1.33,12.82]],"id":66499052}],"con":true,"img":false}]}
{"op":"mcm","clk":"11541256803","pt":1719503863449,"mc":[{"id":"1.230180131","rc":[{"atb":[[1.29,0]],"id":41138102}],"con":true,"img":false}]}
{"op":"mcm","clk":"11541256839","pt":1719503863755,"mc":[{"id":"1.230180131","rc":[{"atb":[[1.33,12.82]],"id":43210435}],"con":true,"img":false}]}
{"op":"mcm","clk":"11541256871","pt":1719503864063,"mc":[{"id":"1.230180131","rc":[{"atb":[[1.33,12.82]],"id":51843546}],"con":true,"img":false}]}
{"op":"mcm","clk":"11541256910","pt":1719503864376,"mc":[{"id":"1.230180131","rc":[{"atb":[[1.33,12.82]],"id":41138102}],"con":true,"img":false}]}
{"op":"mcm","clk":"11541258546","pt":1719503880190,"mc":[{"id":"1.230180131","rc":[{"atb":[[1.31,0]],"id":66499052}],"con":true,"img":false}]}
{"op":"mcm","clk":"11541258556","pt":1719503880296,"mc":[{"id":"1.230180131","rc":[{"atb":[[1.31,0]],"id":41138102}],"con":true,"img":false}]}
{"op":"mcm","clk":"11541258567","pt":1719503880398,"mc":[{"id":"1.230180131","rc":[{"atb":[[1.31,0]],"id":43210435}],"con":true,"img":false}]}
{"op":"mcm","clk":"11541258588","pt":1719503880550,"mc":[{"id":"1.230180131","rc":[{"atb":[[1.35,11.29]],"id":66499052}],"con":true,"img":false}]}
{"op":"mcm","clk":"11541258628","pt":1719503880866,"mc":[{"id":"1.230180131","rc":[{"atb":[[1.35,11.29]],"id":41138102}],"con":true,"img":false}]}
{"op":"mcm","clk":"11541258638","pt":1719503880972,"mc":[{"id":"1.230180131","rc":[{"atb":[[1.35,11.29]],"id":43210435}],"con":true,"img":false}]}
{"op":"mcm","clk":"11541258663","pt":1719503881179,"mc":[{"id":"1.230180131","rc":[{"atb":[[1.31,0]],"id":51843546}],"con":true,"img":false}]}
{"op":"mcm","clk":"11541258714","pt":1719503881595,"mc":[{"id":"1.230180131","rc":[{"atb":[[1.35,11.29]],"id":51843546}],"con":true,"img":false}]}
{"op":"mcm","clk":"11541260630","pt":1719503897781,"mc":[{"id":"1.230180131","rc":[{"spn":38.17,"spf":"NaN","id":41138102},{"spn":38.17,"spf":"NaN","id":43210435},{"atb":[[1.33,0]],"id":66499052},{"spn":38.17,"spf":"NaN","id":66499052},{"spn":38.17,"spf":"NaN","id":51843546}],"con":true,"img":false}]}
{"op":"mcm","clk":"11541260650","pt":1719503897987,"mc":[{"id":"1.230180131","rc":[{"atb":[[1.33,0]],"id":43210435}],"con":true,"img":false}]}
{"op":"mcm","clk":"11541260660","pt":1719503898090,"mc":[{"id":"1.230180131","rc":[{"atb":[[1.33,0]],"id":41138102}],"con":true,"img":false}]}
{"op":"mcm","clk":"11541260696","pt":1719503898395,"mc":[{"id":"1.230180131","rc":[{"atb":[[1.33,0]],"id":51843546}],"con":true,"img":false}]}
{"op":"mcm","clk":"11541260759","pt":1719503899013,"mc":[{"id":"1.230180131","rc":[{"atb":[[1.37,11.43]],"id":43210435}],"con":true,"img":false}]}
{"op":"mcm","clk":"11541260786","pt":1719503899323,"mc":[{"id":"1.230180131","rc":[{"atb":[[1.37,11.43]],"id":41138102}],"con":true,"img":false}]}
{"op":"mcm","clk":"11541260820","pt":1719503899592,"mc":[{"id":"1.230180131","rc":[{"atb":[[1.37,11.43]],"id":51843546}],"con":true,"img":false}]}
{"op":"mcm","clk":"11541260826","pt":1719503899683,"mc":[{"id":"1.230180131","rc":[{"atb":[[1.37,11.43]],"id":66499052}],"con":true,"img":false}]}
{"op":"mcm","clk":"11541262537","pt":1719503915541,"mc":[{"id":"1.230180131","rc":[{"atb":[[1.35,0]],"id":66499052}],"con":true,"img":false}]}
{"op":"mcm","clk":"11541262545","pt":1719503915599,"mc":[{"id":"1.230180131","rc":[{"atb":[[1.35,0]],"id":43210435}],"con":true,"img":false}]}
{"op":"mcm","clk":"11541262558","pt":1719503915706,"mc":[{"id":"1.230180131","rc":[{"atb":[[1.35,0]],"id":51843546}],"con":true,"img":false}]}
{"op":"mcm","clk":"11541262597","pt":1719503916110,"mc":[{"id":"1.230180131","rc":[{"atb":[[1.35,0]],"id":41138102}],"con":true,"img":false}]}
{"op":"mcm","clk":"11541262606","pt":1719503916218,"mc":[{"id":"1.230180131","rc":[{"atb":[[1.39,10.13]],"id":43210435}],"con":true,"img":false}]}
{"op":"mcm","clk":"11541262622","pt":1719503916321,"mc":[{"id":"1.230180131","rc":[{"atb":[[1.39,10.13]],"id":66499052}],"con":true,"img":false}]}
{"op":"mcm","clk":"11541262641","pt":1719503916534,"mc":[{"id":"1.230180131","rc":[{"atb":[[1.39,10.13]],"id":51843546}],"con":true,"img":false}]}
{"op":"mcm","clk":"11541262663","pt":1719503916739,"mc":[{"id":"1.230180131","rc":[{"atb":[[1.39,10.13]],"id":41138102}],"con":true,"img":false}]}
{"op":"mcm","clk":"11541264523","pt":1719503934662,"mc":[{"id":"1.230180131","rc":[{"atb":[[1.37,0]],"id":66499052}],"con":true,"img":false}]}
{"op":"mcm","clk":"11541264549","pt":1719503934812,"mc":[{"id":"1.230180131","rc":[{"atb":[[1.37,0]],"id":43210435}],"con":true,"img":false}]}
{"op":"mcm","clk":"11541264589","pt":1719503935127,"mc":[{"id":"1.230180131","rc":[{"atb":[[1.37,0]],"id":41138102},{"atb":[[1.37,0]],"id":51843546}],"con":true,"img":false}]}
{"op":"mcm","clk":"11541264662","pt":1719503935840,"mc":[{"id":"1.230180131","rc":[{"atb":[[1.41,10.33]],"id":43210435}],"con":true,"img":false}]}
{"op":"mcm","clk":"11541264686","pt":1719503936048,"mc":[{"id":"1.230180131","rc":[{"atb":[[1.41,10.33]],"id":66499052}],"con":true,"img":false}]}
{"op":"mcm","clk":"11541264723","pt":1719503936410,"mc":[{"id":"1.230180131","rc":[{"atb":[[1.41,10.33]],"id":51843546}],"con":true,"img":false}]}
{"op":"mcm","clk":"11541264781","pt":1719503936929,"mc":[{"id":"1.230180131","rc":[{"atb":[[1.41,10.33]],"id":41138102}],"con":true,"img":false}]}
{"op":"mcm","clk":"11541266595","pt":1719503952596,"mc":[{"id":"1.230180131","rc":[{"atb":[[1.39,0]],"id":66499052}],"con":true,"img":false}]}
{"op":"mcm","clk":"11541266628","pt":1719503952808,"mc":[{"id":"1.230180131","rc":[{"atb":[[1.39,0]],"id":43210435}],"con":true,"img":false}]}
{"op":"mcm","clk":"11541266653","pt":1719503953012,"mc":[{"id":"1.230180131","rc":[{"atb":[[1.39,0]],"id":41138102},{"atb":[[1.39,0]],"id":51843546}],"con":true,"img":false}]}
{"op":"mcm","clk":"11541266672","pt":1719503953169,"mc":[{"id":"1.230180131","rc":[{"atb":[[1.43,9.19]],"id":51843546}],"con":true,"img":false}]}
{"op":"mcm","clk":"11541266687","pt":1719503953377,"mc":[{"id":"1.230180131","rc":[{"atb":[[1.43,9.19]],"id":66499052}],"con":true,"img":false}]}
{"op":"mcm","clk":"11541266708","pt":1719503953588,"mc":[{"id":"1.230180131","rc":[{"atb":[[1.43,9.19]],"id":41138102},{"atb":[[1.43,9.19]],"id":43210435}],"con":true,"img":false}]}
{"op":"mcm","clk":"11541268218","pt":1719503969833,"mc":[{"id":"1.230180131","rc":[{"spn":38.21,"spf":"NaN","id":41138102},{"spn":38.21,"spf":"NaN","id":43210435},{"atb":[[1.41,0]],"id":66499052},{"spn":38.21,"spf":"NaN","id":66499052},{"spn":38.21,"spf":"NaN","id":51843546}],"con":true,"img":false}]}
{"op":"mcm","clk":"11541268236","pt":1719503970034,"mc":[{"id":"1.230180131","rc":[{"atb":[[1.41,0]],"id":43210435}],"con":true,"img":false}]}
{"op":"mcm","clk":"11541268254","pt":1719503970196,"mc":[{"id":"1.230180131","rc":[{"atb":[[1.41,0]],"id":41138102}],"con":true,"img":false}]}
{"op":"mcm","clk":"11541268271","pt":1719503970396,"mc":[{"id":"1.230180131","rc":[{"atb":[[1.41,0]],"id":51843546}],"con":true,"img":false}]}
{"op":"mcm","clk":"11541268308","pt":1719503970814,"mc":[{"id":"1.230180131","rc":[{"atb":[[1.45,9.4]],"id":41138102}],"con":true,"img":false}]}
{"op":"mcm","clk":"11541268318","pt":1719503970914,"mc":[{"id":"1.230180131","rc":[{"atb":[[1.45,9.4]],"id":43210435}],"con":true,"img":false}]}
{"op":"mcm","clk":"11541268341","pt":1719503971116,"mc":[{"id":"1.230180131","rc":[{"atb":[[1.45,9.4]],"id":66499052}],"con":true,"img":false}]}
{"op":"mcm","clk":"11541268386","pt":1719503971737,"mc":[{"id":"1.230180131","rc":[{"atb":[[1.45,9.4]],"id":51843546}],"con":true,"img":false}]}
{"op":"mcm","clk":"11541269974","pt":1719503988034,"mc":[{"id":"1.230180131","rc":[{"atb":[[1.43,0]],"id":66499052}],"con":true,"img":false}]}
{"op":"mcm","clk":"11541269992","pt":1719503988239,"mc":[{"id":"1.230180131","rc":[{"atb":[[1.43,0]],"id":41138102},{"atb":[[1.43,0]],"id":43210435}],"con":true,"img":false}]}
{"op":"mcm","clk":"11541270023","pt":1719503988552,"mc":[{"id":"1.230180131","rc":[{"atb":[[1.43,0]],"id":51843546}],"con":true,"img":false}]}
{"op":"mcm","clk":"11541270060","pt":1719503988922,"mc":[{"id":"1.230180131","rc":[{"atb":[[1.47,8.41]],"id":66499052}],"con":true,"img":false}]}
{"op":"mcm","clk":"11541270067","pt":1719503989018,"mc":[{"id":"1.230180131","rc":[{"atb":[[1.47,8.41]],"id":41138102}],"con":true,"img":false}]}
{"op":"mcm","clk":"11541270074","pt":1719503989128,"mc":[{"id":"1.230180131","rc":[{"atb":[[1.47,8.41]],"id":43210435}],"con":true,"img":false}]}
{"op":"mcm","clk":"11541270082","pt":1719503989228,"mc":[{"id":"1.230180131","rc":[{"atb":[[1.47,8.41]],"id":51843546}],"con":true,"img":false}]}
{"op":"mcm","clk":"11541271556","pt":1719504003669,"mc":[{"id":"1.230180131","rc":[{"atb":[[1.45,0]],"id":43210435},{"atb":[[1.45,0]],"id":66499052}],"con":true,"img":false}]}
{"op":"mcm","clk":"11541271599","pt":1719504004079,"mc":[{"id":"1.230180131","rc":[{"atb":[[1.45,0]],"id":41138102},{"atb":[[1.45,0]],"id":51843546}],"con":true,"img":false}]}
{"op":"mcm","clk":"11541271626","pt":1719504004403,"mc":[{"id":"1.230180131","rc":[{"atb":[[1.01,32.97]],"id":58149406},{"atb":[[1.03,10.99],[1.47,8.4]],"id":41138102},{"atb":[[1.02,16.48],[1.49,8.63],[1.47,8.4]],"id":43210435},{"atb":[[1.02,16.48],[1.49,8.63],[1.47,8.4]],"id":66499052},{"atb":[[1.01,32.97],[1.47,8.4]],"id":51843546},{"atb":[[1.03,10.99]],"id":69979297}],"con":true,"img":false}]}
{"op":"mcm","clk":"11541271656","pt":1719504004677,"mc":[{"id":"1.230180131","rc":[{"atb":[[1.49,8.63]],"id":51843546}],"con":true,"img":false}]}
{"op":"mcm","clk":"11541271691","pt":1719504004976,"mc":[{"id":"1.230180131","rc":[{"atb":[[1.49,8.63]],"id":41138102}],"con":true,"img":false}]}
{"op":"mcm","clk":"11541271912","pt":1719504007081,"mc":[{"id":"1.230180131","rc":[{"atb":[[1.47,0]],"id":66499052}],"con":true,"img":false}]}
{"op":"mcm","clk":"11541271919","pt":1719504007181,"mc":[{"id":"1.230180131","rc":[{"atb":[[1.47,0]],"id":43210435}],"con":true,"img":false}]}
{"op":"mcm","clk":"11541271935","pt":1719504007386,"mc":[{"id":"1.230180131","rc":[{"atb":[[1.47,0]],"id":41138102}],"con":true,"img":false}]}
{"op":"mcm","clk":"11541271945","pt":1719504007446,"mc":[{"id":"1.230180131","rc":[{"atb":[[1.51,7.74]],"id":66499052}],"con":true,"img":false}]}
{"op":"mcm","clk":"11541271954","pt":1719504007599,"mc":[{"id":"1.230180131","rc":[{"atb":[[1.47,0]],"id":51843546}],"con":true,"img":false}]}
{"op":"mcm","clk":"11541271961","pt":1719504007661,"mc":[{"id":"1.230180131","rc":[{"atb":[[1.51,7.74]],"id":43210435}],"con":true,"img":false}]}
{"op":"mcm","clk":"11541271971","pt":1719504007761,"mc":[{"id":"1.230180131","rc":[{"atb":[[1.51,7.74]],"id":41138102}],"con":true,"img":false}]}
{"op":"mcm","clk":"11541272005","pt":1719504008170,"mc":[{"id":"1.230180131","rc":[{"atb":[[1.51,7.74]],"id":51843546}],"con":true,"img":false}]}
{"op":"mcm","clk":"11541275110","pt":1719504037801,"mc":[{"id":"1.230180131","rc":[{"spn":38.25,"spf":"NaN","id":41138102},{"atb":[[1.49,0]],"id":43210435},{"spn":38.25,"spf":"NaN","id":43210435},{"atb":[[1.49,0]],"id":66499052},{"spn":38.25,"spf":"NaN","id":66499052},{"spn":38.25,"spf":"NaN","id":51843546}],"con":true,"img":false}]}
{"op":"mcm","clk":"11541275148","pt":1719504038103,"mc":[{"id":"1.230180131","rc":[{"atb":[[1.49,0]],"id":41138102},{"atb":[[1.49,0]],"id":51843546}],"con":true,"img":false}]}
{"op":"mcm","clk":"11541275185","pt":1719504038419,"mc":[{"id":"1.230180131","rc":[{"atb":[[1.53,7.98]],"id":66499052}],"con":true,"img":false}]}
{"op":"mcm","clk":"11541275217","pt":1719504038698,"mc":[{"id":"1.230180131","rc":[{"atb":[[1.53,7.98]],"id":43210435}],"con":true,"img":false}]}
{"op":"mcm","clk":"11541275231","pt":1719504038897,"mc":[{"id":"1.230180131","rc":[{"atb":[[1.53,7.98]],"id":41138102}],"con":true,"img":false}]}
{"op":"mcm","clk":"11541275237","pt":1719504039004,"mc":[{"id":"1.230180131","rc":[{"atb":[[1.53,7.98]],"id":51843546}],"con":true,"img":false}]}
{"op":"mcm","clk":"11541275640","pt":1719504042714,"mc":[{"id":"1.230180131","rc":[{"atb":[[1.51,0]],"id":66499052}],"con":true,"img":false}]}
{"op":"mcm","clk":"11541275659","pt":1719504042922,"mc":[{"id":"1.230180131","rc":[{"atb":[[1.51,0]],"id":43210435}],"con":true,"img":false}]}
{"op":"mcm","clk":"11541275669","pt":1719504043031,"mc":[{"id":"1.230180131","rc":[{"atb":[[1.51,0]],"id":41138102}],"con":true,"img":false}]}
{"op":"mcm","clk":"11541275683","pt":1719504043135,"mc":[{"id":"1.230180131","rc":[{"atb":[[1.51,0]],"id":51843546}],"con":true,"img":false}]}
{"op":"mcm","clk":"11541275705","pt":1719504043303,"mc":[{"id":"1.230180131","rc":[{"atb":[[1.55,7.18]],"id":43210435}],"con":true,"img":false}]}
{"op":"mcm","clk":"11541275728","pt":1719504043501,"mc":[{"id":"1.230180131","rc":[{"atb":[[1.55,7.18]],"id":66499052}],"con":true,"img":false}]}
{"op":"mcm","clk":"11541275754","pt":1719504043708,"mc":[{"id":"1.230180131","rc":[{"atb":[[1.55,7.18]],"id":41138102},{"atb":[[1.55,7.18]],"id":51843546}],"con":true,"img":false}]}
{"op":"mcm","clk":"11541278953","pt":1719504071349,"mc":[{"id":"1.230180131","rc":[{"atb":[[1.53,0]],"id":43210435},{"atb":[[1.53,0]],"id":66499052}],"con":true,"img":false}]}
{"op":"mcm","clk":"11541278992","pt":1719504071659,"mc":[{"id":"1.230180131","rc":[{"atb":[[1.53,0]],"id":51843546}],"con":true,"img":false}]}
{"op":"mcm","clk":"11541279022","pt":1719504071930,"mc":[{"id":"1.230180131","rc":[{"atb":[[1.57,7.42]],"id":43210435}],"con":true,"img":false}]}
{"op":"mcm","clk":"11541279035","pt":1719504072028,"mc":[{"id":"1.230180131","rc":[{"atb":[[1.53,0]],"id":41138102}],"con":true,"img":false}]}
{"op":"mcm","clk":"11541279075","pt":1719504072335,"mc":[{"id":"1.230180131","rc":[{"atb":[[1.57,7.42]],"id":66499052}],"con":true,"img":false}]}
{"op":"mcm","clk":"11541279099","pt":1719504072544,"mc":[{"id":"1.230180131","rc":[{"atb":[[1.57,7.42]],"id":51843546}],"con":true,"img":false}]}
{"op":"mcm","clk":"11541279140","pt":1719504072959,"mc":[{"id":"1.230180131","rc":[{"atb":[[1.57,7.42]],"id":41138102}],"con":true,"img":false}]}
{"op":"mcm","clk":"11541279827","pt":1719504079735,"mc":[{"id":"1.230180131","rc":[{"atb":[[1.55,0]],"id":66499052}],"con":true,"img":false}]}
{"op":"mcm","clk":"11541279843","pt":1719504079939,"mc":[{"id":"1.230180131","rc":[{"atb":[[1.55,0]],"id":41138102},{"atb":[[1.55,0]],"id":43210435}],"con":true,"img":false}]}
{"op":"mcm","clk":"11541279860","pt":1719504080141,"mc":[{"id":"1.230180131","rc":[{"atb":[[1.55,0]],"id":51843546}],"con":true,"img":false}]}
{"op":"mcm","clk":"11541279895","pt":1719504080345,"mc":[{"id":"1.230180131","rc":[{"atb":[[1.59,6.69]],"id":66499052}],"con":true,"img":false}]}
{"op":"mcm","clk":"11541279913","pt":1719504080553,"mc":[{"id":"1.230180131","rc":[{"atb":[[1.59,6.69]],"id":43210435}],"con":true,"img":false}]}
{"op":"mcm","clk":"11541279923","pt":1719504080655,"mc":[{"id":"1.230180131","rc":[{"atb":[[1.59,6.69]],"id":51843546}],"con":true,"img":false}]}
{"op":"mcm","clk":"11541279952","pt":1719504080967,"mc":[{"id":"1.230180131","rc":[{"atb":[[1.59,6.69]],"id":41138102}],"con":true,"img":false}]}
{"op":"mcm","clk":"11541282622","pt":1719504106194,"mc":[{"id":"1.230180131","rc":[{"spn":38.29,"spf":"NaN","id":41138102},{"atb":[[1.57,0]],"id":43210435},{"spn":38.29,"spf":"NaN","id":43210435},{"atb":[[1.57,0]],"id":66499052},{"spn":38.29,"spf":"NaN","id":66499052},{"spn":38.29,"spf":"NaN","id":51843546}],"con":true,"img":false}]}
{"op":"mcm","clk":"11541282646","pt":1719504106502,"mc":[{"id":"1.230180131","rc":[{"atb":[[1.57,0]],"id":51843546}],"con":true,"img":false}]}
{"op":"mcm","clk":"11541282676","pt":1719504106816,"mc":[{"id":"1.230180131","rc":[{"atb":[[1.61,6.93]],"id":43210435}],"con":true,"img":false}]}
{"op":"mcm","clk":"11541282707","pt":1719504107070,"mc":[{"id":"1.230180131","rc":[{"atb":[[1.61,6.93]],"id":51843546}],"con":true,"img":false}]}
{"op":"mcm","clk":"11541282724","pt":1719504107278,"mc":[{"id":"1.230180131","rc":[{"atb":[[1.57,0]],"id":41138102}],"con":true,"img":false}]}
{"op":"mcm","clk":"11541282780","pt":1719504107897,"mc":[{"id":"1.230180131","rc":[{"atb":[[1.61,6.93]],"id":66499052}],"con":true,"img":false}]}
{"op":"mcm","clk":"11541282802","pt":1719504108211,"mc":[{"id":"1.230180131","rc":[{"atb":[[1.61,6.93]],"id":41138102}],"con":true,"img":false}]}
{"op":"mcm","clk":"11541283464","pt":1719504114615,"mc":[{"id":"1.230180131","rc":[{"atb":[[1.59,0]],"id":43210435},{"atb":[[1.59,0]],"id":66499052}],"con":true,"img":false}]}
{"op":"mcm","clk":"11541283494","pt":1719504114929,"mc":[{"id":"1.230180131","rc":[{"atb":[[1.59,0]],"id":41138102},{"atb":[[1.59,0]],"id":51843546}],"con":true,"img":false}]}
{"op":"mcm","clk":"11541283518","pt":1719504115082,"mc":[{"id":"1.230180131","rc":[{"atb":[[1.63,6.27]],"id":41138102}],"con":true,"img":false}]}
{"op":"mcm","clk":"11541283543","pt":1719504115287,"mc":[{"id":"1.230180131","rc":[{"atb":[[1.63,6.27]],"id":43210435},{"atb":[[1.63,6.27]],"id":66499052}],"con":true,"img":false}]}
{"op":"mcm","clk":"11541283584","pt":1719504115698,"mc":[{"id":"1.230180131","rc":[{"atb":[[1.63,6.27]],"id":51843546}],"con":true,"img":false}]}
{"op":"mcm","clk":"11541286266","pt":1719504142530,"mc":[{"id":"1.230180131","rc":[{"atb":[[1.61,0]],"id":41138102},{"atb":[[1.61,0]],"id":51843546}],"con":true,"img":false}]}
{"op":"mcm","clk":"11541286323","pt":1719504143150,"mc":[{"id":"1.230180131","rc":[{"atb":[[1.65,6.5]],"id":41138102},{"atb":[[1.65,6.5]],"id":51843546}],"con":true,"img":false}]}
{"op":"mcm","clk":"11541287165","pt":1719504151457,"mc":[{"id":"1.230180131","rc":[{"atb":[[1.63,0]],"id":41138102},{"atb":[[1.63,0]],"id":51843546}],"con":true,"img":false}]}
{"op":"mcm","clk":"11541287202","pt":1719504151873,"mc":[{"id":"1.230180131","rc":[{"atb":[[1.67,5.89]],"id":41138102}],"con":true,"img":false}]}
{"op":"mcm","clk":"11541287211","pt":1719504151974,"mc":[{"id":"1.230180131","rc":[{"atb":[[1.67,5.89]],"id":51843546}],"con":true,"img":false}]}
{"op":"mcm","clk":"11541289727","pt":1719504175195,"mc":[{"id":"1.230180131","rc":[{"atb":[[1.65,0]],"id":41138102},{"spn":38.33,"spf":"NaN","id":41138102},{"spn":38.31,"spf":"NaN","id":43210435},{"spn":38.31,"spf":"NaN","id":66499052},{"atb":[[1.65,0]],"id":51843546},{"spn":38.33,"spf":"NaN","id":51843546}],"con":true,"img":false}]}
{"op":"mcm","clk":"11541289838","pt":1719504176181,"mc":[{"id":"1.230180131","rc":[{"atb":[[1.69,6.13]],"id":51843546}],"con":true,"img":false}]}
{"op":"mcm","clk":"11541289855","pt":1719504176387,"mc":[{"id":"1.230180131","rc":[{"atb":[[1.69,6.13]],"id":41138102}],"con":true,"img":false}]}
{"op":"mcm","clk":"11541291471","pt":1719504189119,"mc":[{"id":"1.230180131","rc":[{"atb":[[1.67,0]],"id":41138102},{"atb":[[1.67,0]],"id":51843546}],"con":true,"img":false}]}
{"op":"mcm","clk":"11541291522","pt":1719504189552,"mc":[{"id":"1.230180131","rc":[{"atb":[[1.71,5.56]],"id":51843546}],"con":true,"img":false}]}
{"op":"mcm","clk":"11541291545","pt":1719504189698,"mc":[{"id":"1.230180131","rc":[{"atb":[[1.71,5.56]],"id":41138102}],"con":true,"img":false}]}
{"op":"mcm","clk":"11541293680","pt":1719504208643,"mc":[{"id":"1.230180131","rc":[{"atb":[[1.61,0]],"id":43210435},{"atb":[[1.61,0]],"id":66499052}],"con":true,"img":false}]}
{"op":"mcm","clk":"11541293877","pt":1719504210518,"mc":[{"id":"1.230180131","rc":[{"atb":[[1.69,0]],"id":51843546}],"con":true,"img":false}]}
{"op":"mcm","clk":"11541293913","pt":1719504210830,"mc":[{"id":"1.230180131","rc":[{"atb":[[1.73,5.79]],"id":51843546}],"con":true,"img":false}]}
{"op":"mcm","clk":"11541295647","pt":1719504226050,"mc":[{"id":"1.230180131","rc":[{"atb":[[1.71,0]],"id":51843546}],"con":true,"img":false}]}
{"op":"mcm","clk":"11541295694","pt":1719504226460,"mc":[{"id":"1.230180131","rc":[{"atb":[[1.75,5.27]],"id":51843546}],"con":true,"img":false}]}
{"op":"mcm","clk":"11541297907","pt":1719504246203,"mc":[{"id":"1.230180131","rc":[{"spn":38.35,"spf":"NaN","id":41138102},{"atb":[[1.73,0]],"id":51843546},{"spn":38.37,"spf":"NaN","id":51843546}],"con":true,"img":false}]}
{"op":"mcm","clk":"11541297947","pt":1719504246465,"mc":[{"id":"1.230180131","rc":[{"atb":[[1.77,5.49]],"id":51843546}],"con":true,"img":false}]}
{"op":"mcm","clk":"11541299601","pt":1719504262418,"mc":[{"id":"1.230180131","rc":[{"atb":[[1.75,0]],"id":51843546}],"con":true,"img":false}]}
{"op":"mcm","clk":"11541299660","pt":1719504262985,"mc":[{"id":"1.230180131","rc":[{"atb":[[1.79,5]],"id":51843546}],"con":true,"img":false}]}
{"op":"mcm","clk":"11541303665","pt":1719504299958,"mc":[{"id":"1.230180131","rc":[{"atb":[[1.63,0]],"id":43210435},{"atb":[[1.63,0]],"id":66499052}],"con":true,"img":false}]}
{"op":"mcm","clk":"11541303828","pt":1719504301476,"mc":[{"id":"1.230180131","rc":[{"atb":[[1.09,43.91]],"id":66499052}],"con":true,"img":false}]}
{"op":"mcm","clk":"11541303856","pt":1719504301637,"mc":[{"id":"1.230180131","rc":[{"atb":[[1.09,43.91]],"id":43210435}],"con":true,"img":false}]}
{"op":"mcm","clk":"11541305110","pt":1719504313665,"mc":[{"id":"1.230180131","rc":[{"spn":38.1,"spf":"NaN","id":43210435},{"atb":[[1.11,38.46]],"id":66499052},{"spn":38.1,"spf":"NaN","id":66499052},{"spn":38.39,"spf":"NaN","id":51843546}],"con":true,"img":false}]}
{"op":"mcm","clk":"11541305172","pt":1719504314287,"mc":[{"id":"1.230180131","rc":[{"atb":[[1.11,38.46]],"id":43210435}],"con":true,"img":false}]}
{"op":"mcm","clk":"11541305645","pt":1719504319169,"mc":[{"id":"1.230180131","rc":[{"atb":[[1.09,0]],"id":43210435}],"con":true,"img":false}]}
{"op":"mcm","clk":"11541305697","pt":1719504319682,"mc":[{"id":"1.230180131","rc":[{"atb":[[1.09,0]],"id":66499052}],"con":true,"img":false}]}
{"op":"mcm","clk":"11541305738","pt":1719504320095,"mc":[{"id":"1.230180131","rc":[{"atb":[[1.13,30.39]],"id":43210435}],"con":true,"img":false}]}
{"op":"mcm","clk":"11541305819","pt":1719504320775,"mc":[{"id":"1.230180131","rc":[{"atb":[[1.13,30.39]],"id":66499052}],"con":true,"img":false}]}
{"op":"mcm","clk":"11541308436","pt":1719504345518,"mc":[{"id":"1.230180131","rc":[{"atb":[[1.77,0]],"id":51843546}],"con":true,"img":false}]}
{"op":"mcm","clk":"11541308642","pt":1719504347698,"mc":[{"id":"1.230180131","rc":[{"atb":[[1.11,0]],"id":66499052}],"con":true,"img":false}]}
{"op":"mcm","clk":"11541308715","pt":1719504348317,"mc":[{"id":"1.230180131","rc":[{"atb":[[1.11,0]],"id":43210435}],"con":true,"img":false}]}
{"op":"mcm","clk":"11541308858","pt":1719504349420,"mc":[{"id":"1.230180131","rc":[{"atb":[[1.15,28.2]],"id":43210435}],"con":true,"img":false}]}
{"op":"mcm","clk":"11541308885","pt":1719504349626,"mc":[{"id":"1.230180131","rc":[{"atb":[[1.15,28.2]],"id":66499052}],"con":true,"img":false}]}
{"op":"mcm","clk":"11541309423","pt":1719504355304,"mc":[{"id":"1.230180131","rc":[{"atb":[[1.13,0]],"id":43210435}],"con":true,"img":false}]}
{"op":"mcm","clk":"11541309433","pt":1719504355411,"mc":[{"id":"1.230180131","rc":[{"atb":[[1.13,0]],"id":66499052}],"con":true,"img":false}]}
{"op":"mcm","clk":"11541309497","pt":1719504355931,"mc":[{"id":"1.230180131","rc":[{"atb":[[1.17,23.24]],"id":43210435}],"con":true,"img":false}]}
{"op":"mcm","clk":"11541309537","pt":1719504356346,"mc":[{"id":"1.230180131","rc":[{"atb":[[1.17,23.24]],"id":66499052}],"con":true,"img":false}]}
{"op":"mcm","clk":"11541309922","pt":1719504360126,"mc":[{"id":"1.230180131","rc":[{"atb":[[1.43,2.48],[1.55,1]],"id":58149406},{"atl":[[4.2,1],[8.4,2]],"id":58149406},{"atb":[[1.72,5.56],[1.97,1]],"id":41138102},{"atl":[[17.5,2],[6.2,1]],"id":41138102},{"atb":[[1.97,1],[1.68,23.25]],"id":43210435},{"atl":[[16.5,2],[6.2,1]],"id":43210435},{"atb":[[1.64,23.25],[1.65,1]],"id":66499052},{"atl":[[14.5,2],[4.7,1]],"id":66499052},{"atb":[[2.24,1],[1.8,2.48]],"id":51843546},{"atl":[[21,2],[7.4,1]],"id":51843546},{"atb":[[1.25,1],[1.07,9.22]],"id":69979297},{"atl":[[2.72,1],[3.55,2]],"id":69979297}],"con":true,"img":false}]}
{"op":"mcm","clk":"11541310251","pt":1719504363252,"mc":[{"id":"1.230180131","rc":[{"atb":[[1.74,2.11]],"id":41138102},{"atb":[[1.71,2.11]],"id":43210435},{"atb":[[1.67,2.11]],"id":66499052}],"con":true,"img":false}]}
{"op":"mcm","clk":"11541310403","pt":1719504364757,"mc":[{"id":"1.230180131","rc":[{"atl":[[1000,1.87]],"id":41138102},{"atb":[[1.01,1.7]],"id":43210435},{"atl":[[1000,1.87]],"id":43210435},{"atb":[[1.01,1.7]],"id":66499052},{"atl":[[1000,1.87]],"id":66499052}],"con":true,"img":false}]}
{"op":"mcm","clk":"11541310414","pt":1719504364813,"mc":[{"id":"1.230180131","rc":[{"atb":[[1.01,1.7]],"id":41138102}],"con":true,"img":false}]}
{"op":"mcm","clk":"11541310423","pt":1719504364924,"mc":[{"id":"1.230180131","rc":[{"atl":[[1000,0.19]],"id":41138102},{"atb":[[1.01,0.44]],"id":43210435},{"atl":[[1000,0.19]],"id":43210435},{"atb":[[1.01,0.46]],"id":66499052},{"atl":[[1000,0.2]],"id":66499052}],"con":true,"img":false}]}
{"op":"mcm","clk":"11541310441","pt":1719504365126,"mc":[{"id":"1.230180131","rc":[{"atb":[[1.01,0.42]],"id":41138102},{"atl":[[1000,0.17]],"id":41138102},{"atb":[[1.01,0]],"id":43210435},{"atl":[[1000,0.17]],"id":43210435},{"atb":[[1.01,0]],"id":66499052},{"atl":[[1000,0.17]],"id":66499052}],"con":true,"img":false}]}
{"op":"mcm","clk":"11541310457","pt":1719504365228,"mc":[{"id":"1.230180131","rc":[{"atl":[[17,0.02]],"id":41138102},{"atb":[[1.72,0.44]],"id":43210435},{"atl":[[16,0.02]],"id":43210435},{"atb":[[1.68,0.46]],"id":66499052},{"atl":[[14,0.02]],"id":66499052}],"con":true,"img":false}]}
{"op":"mcm","clk":"11541310468","pt":1719504365332,"mc":[{"id":"1.230180131","rc":[{"atb":[[1.01,0]],"id":41138102}],"con":true,"img":false}]}
{"op":"mcm","clk":"11541310481","pt":1719504365437,"mc":[{"id":"1.230180131","rc":[{"atb":[[1.75,0.42]],"id":41138102}],"con":true,"img":false}]}
{"op":"mcm","clk":"11541310703","pt":1719504367661,"mc":[{"id":"1.230180131","rc":[{"atl":[[12,3],[8.4,0]],"id":58149406},{"atl":[[32,3],[21,0]],"id":51843546},{"atl":[[5.8,3],[3.55,0]],"id":69979297}],"con":true,"img":false}]}
{"op":"mcm","clk":"11541310936","pt":1719504370154,"mc":[{"id":"1.230180131","rc":[{"atl":[[4.8,1],[4.2,0]],"id":58149406},{"atl":[[7.2,1],[6.2,0]],"id":41138102},{"atl":[[7.2,1],[6.2,0]],"id":43210435},{"atl":[[5.7,1],[4.7,0]],"id":66499052},{"atl":[[7.4,0],[8.4,1]],"id":51843546},{"atl":[[2.72,0],[3.05,1]],"id":69979297}],"con":true,"img":false}]}
{"op":"mcm","clk":"11541310945","pt":1719504370253,"mc":[{"id":"1.230180131","rc":[{"atb":[[1.43,0],[1.55,3]],"id":58149406},{"atb":[[1.72,0],[1.79,2.12]],"id":41138102},{"atb":[[1.68,0],[1.77,2.12]],"id":43210435},{"atb":[[1.64,0],[1.73,2]],"id":66499052},{"atb":[[1.8,0],[1.86,2.48]],"id":51843546},{"atl":[[5.8,0],[3.55,2]],"id":69979297}],"con":true,"img":false}]}
{"op":"mcm","clk":"11541310954","pt":1719504370357,"mc":[{"id":"1.230180131","rc":[{"atl":[[12,0],[8.4,2]],"id":58149406}],"con":true,"img":false}]}
{"op":"mcm","clk":"11541310964","pt":1719504370462,"mc":[{"id":"1.230180131","rc":[{"atl":[[12,2],[8.4,0]],"id":58149406}],"con":true,"img":false}]}
{"op":"mcm","clk":"11541311180","pt":1719504373061,"mc":[{"id":"1.230180131","rc":[{"atb":[[1.17,0]],"id":66499052}],"con":true,"img":false}]}
{"op":"mcm","clk":"11541311398","pt":1719504375446,"mc":[{"id":"1.230180131","rc":[{"spn":3.17,"spf":"NaN","id":58149406},{"spn":4.58,"spf":"NaN","id":41138102},{"spn":4.58,"spf":"NaN","id":43210435},{"spn":3.71,"spf":"NaN","id":66499052},{"spn":5.32,"spf":"NaN","id":51843546},{"atl":[[5.8,3],[3.55,0]],"id":69979297},{"spn":2.15,"spf":"NaN","id":69979297}],"con":true,"img":false}]}
{"op":"mcm","clk":"11541312079","pt":1719504383074,"mc":[{"id":"1.230180131","rc":[{"atb":[[1.15,0]],"id":66499052}],"con":true,"img":false}]}
{"op":"mcm","clk":"11541313943","pt":1719504404683,"mc":[{"id":"1.230180131","rc":[{"atb":[[1.75,0]],"id":41138102},{"atl":[[17,0]],"id":41138102},{"atb":[[1.72,0]],"id":43210435},{"atl":[[16,0]],"id":43210435},{"atb":[[1.68,0]],"id":66499052},{"atl":[[14,0]],"id":66499052}],"con":true,"img":false}]}
{"op":"mcm","clk":"11541313953","pt":1719504404790,"mc":[{"id":"1.230180131","rc":[{"atl":[[17.5,0],[26,3]],"id":41138102},{"atl":[[16.5,0],[24,3]],"id":43210435},{"atl":[[21,3],[14.5,0]],"id":66499052}],"con":true,"img":false}]}
{"op":"mcm","clk":"11541315663","pt":1719504422137,"mc":[{"id":"1.230180131","rc":[{"atb":[[1.02,18.48]],"id":66499052}],"con":true,"img":false}]}
{"op":"mcm","clk":"11541315691","pt":1719504422398,"mc":[{"id":"1.230180131","rc":[{"atb":[[1.02,18.48]],"id":43210435}],"con":true,"img":false}]}
{"op":"mcm","clk":"11541315720","pt":1719504422710,"mc":[{"id":"1.230180131","rc":[{"atb":[[1.8,2]],"id":41138102}],"con":true,"img":false}]}
{"op":"mcm","clk":"11541315753","pt":1719504423020,"mc":[{"id":"1.230180131","rc":[{"atb":[[1.08,2]],"id":69979297}],"con":true,"img":false}]}
{"op":"mcm","clk":"11541315779","pt":1719504423331,"mc":[{"id":"1.230180131","rc":[{"atb":[[1.02,2]],"id":58149406}],"con":true,"img":false}]}
{"op":"mcm","clk":"11541315791","pt":1719504423435,"mc":[{"id":"1.230180131","rc":[{"atb":[[1.02,2]],"id":51843546}],"con":true,"img":false}]}
{"op":"mcm","clk":"11541316162","pt":1719504427184,"mc":[{"id":"1.230180131","rc":[{"atb":[[1.79,0]],"id":51843546}],"con":true,"img":false}]}
{"op":"mcm","clk":"11541317757","pt":1719504445455,"mc":[{"id":"1.230180131","rc":[{"atb":[[1.71,0]],"id":41138102},{"atb":[[1.17,0]],"id":43210435}],"con":true,"img":false}]}
{"op":"mcm","clk":"11541318447","pt":1719504453543,"mc":[{"id":"1.230180131","rc":[{"atb":[[1.69,0]],"id":41138102},{"atb":[[1.15,0]],"id":43210435}],"con":true,"img":false}]}
{"op":"mcm","clk":"11541318692","pt":1719504456546,"mc":[{"id":"1.230180131","rc":[{"atb":[[1.12,3.9]],"id":43210435}],"con":true,"img":false}]}
{"op":"mcm","clk":"11541318913","pt":1719504459451,"mc":[{"id":"1.230180131","rc":[{"atb":[[1.12,0]],"id":43210435}],"con":true,"img":false}]}
{"op":"mcm","clk":"11541320475","pt":1719504480283,"mc":[{"id":"1.230180131","rc":[{"atl":[[1000,1.87]],"id":66499052}],"con":true,"img":false}]}
{"op":"mcm","clk":"11541320483","pt":1719504480384,"mc":[{"id":"1.230180131","rc":[{"atb":[[1.01,1.7]],"id":41138102},{"atl":[[1000,1.87]],"id":41138102},{"atb":[[1.01,1.7]],"id":43210435},{"atl":[[1000,1.87]],"id":43210435},{"atb":[[1.01,1.7]],"id":66499052}],"con":true,"img":false}]}
{"op":"mcm","clk":"11541320491","pt":1719504480491,"mc":[{"id":"1.230180131","rc":[{"atb":[[1.01,0.37]],"id":41138102},{"atl":[[1000,0.19]],"id":41138102},{"atb":[[1.01,0.39]],"id":43210435},{"atb":[[1.01,0.41]],"id":66499052},{"atl":[[1000,0.19]],"id":66499052}],"con":true,"img":false}]}
{"op":"mcm","clk":"11541320511","pt":1719504480596,"mc":[{"id":"1.230180131","rc":[{"atl":[[1000,0.19]],"id":43210435}],"con":true,"img":false}]}
{"op":"mcm","clk":"11541320516","pt":1719504480701,"mc":[{"id":"1.230180131","rc":[{"atb":[[1.01,0]],"id":41138102},{"atl":[[1000,0.17]],"id":41138102},{"atb":[[1.01,0]],"id":43210435},{"atb":[[1.01,0]],"id":66499052},{"atl":[[1000,0.17]],"id":66499052}],"con":true,"img":false}]}
{"op":"mcm","clk":"11541320523","pt":1719504480809,"mc":[{"id":"1.230180131","rc":[{"atb":[[1.81,0.37]],"id":41138102},{"atl":[[25,0.01]],"id":41138102},{"atb":[[1.78,0.39]],"id":43210435},{"atl":[[1000,0.17]],"id":43210435},{"atb":[[1.74,0.41]],"id":66499052},{"atl":[[20,0.01]],"id":66499052}],"con":true,"img":false}]}
{"op":"mcm","clk":"11541320532","pt":1719504480858,"mc":[{"id":"1.230180131","rc":[{"atl":[[23,0.01]],"id":43210435}],"con":true,"img":false}]}
{"op":"mcm","clk":"11541323794","pt":1719504523353,"mc":[{"id":"1.230180131","rc":[{"atb":[[1.81,0]],"id":41138102},{"atl":[[25,0]],"id":41138102},{"atb":[[1.78,0]],"id":43210435},{"atl":[[23,0]],"id":43210435},{"atb":[[1.74,0]],"id":66499052},{"atl":[[20,0]],"id":66499052}],"con":true,"img":false}]}
{"op":"mcm","clk":"11541327656","pt":1719504574936,"mc":[{"id":"1.230180131","rc":[{"atb":[[1.82,4.82]],"id":41138102}],"con":true,"img":false}]}
{"op":"mcm","clk":"11541327666","pt":1719504575038,"mc":[{"id":"1.230180131","rc":[{"atb":[[1.83,2.12],[1.79,0]],"id":41138102}],"con":true,"img":false}]}
{"op":"mcm","clk":"11541327687","pt":1719504575341,"mc":[{"id":"1.230180131","rc":[{"atb":[[1.75,5.27]],"id":66499052}],"con":true,"img":false}]}
{"op":"mcm","clk":"11541327695","pt":1719504575402,"mc":[{"id":"1.230180131","rc":[{"atb":[[1.8,0]],"id":41138102}],"con":true,"img":false}]}
{"op":"mcm","clk":"11541327703","pt":1719504575500,"mc":[{"id":"1.230180131","rc":[{"atb":[[1.57,6.93]],"id":58149406},{"atb":[[1.83,4.12]],"id":41138102},{"atb":[[1.73,0],[1.76,2.12]],"id":66499052}],"con":true,"img":false}]}
{"op":"mcm","clk":"11541327708","pt":1719504575604,"mc":[{"id":"1.230180131","rc":[{"atb":[[1.55,1],[1.58,3]],"id":58149406}],"con":true,"img":false}]}
{"op":"mcm","clk":"11541327866","pt":1719504577202,"mc":[{"id":"1.230180131","rc":[{"atb":[[1.02,16.48]],"id":66499052}],"con":true,"img":false}]}
{"op":"mcm","clk":"11541327872","pt":1719504577311,"mc":[{"id":"1.230180131","rc":[{"atb":[[1.77,2]],"id":66499052}],"con":true,"img":false}]}
{"op":"mcm","clk":"11541328028","pt":1719504578914,"mc":[{"id":"1.230180131","rc":[{"atb":[[1.58,5.11]],"id":58149406}],"con":true,"img":false}]}
{"op":"mcm","clk":"11541329298","pt":1719504593263,"mc":[{"id":"1.230180131","rc":[{"spn":3.19,"spf":"NaN","id":58149406},{"atb":[[1.75,0]],"id":66499052},{"spn":3.73,"spf":"NaN","id":66499052}],"con":true,"img":false}]}
{"op":"mcm","clk":"11541329321","pt":1719504593469,"mc":[{"id":"1.230180131","rc":[{"atb":[[1.82,0]],"id":41138102}],"con":true,"img":false}]}
{"op":"mcm","clk":"11541329332","pt":1719504593572,"mc":[{"id":"1.230180131","rc":[{"atb":[[1.57,0]],"id":58149406}],"con":true,"img":false}]}
{"op":"mcm","clk":"11541329352","pt":1719504593743,"mc":[{"id":"1.230180131","rc":[{"atb":[[1.85,4.64]],"id":41138102}],"con":true,"img":false}]}
{"op":"mcm","clk":"11541329363","pt":1719504593837,"mc":[{"id":"1.230180131","rc":[{"atb":[[1.83,2]],"id":41138102},{"atb":[[1.79,5]],"id":66499052}],"con":true,"img":false}]}
{"op":"mcm","clk":"11541329374","pt":1719504593944,"mc":[{"id":"1.230180131","rc":[{"atb":[[1.86,4.12]],"id":41138102},{"atb":[[1.8,2.12],[1.76,0]],"id":66499052}],"con":true,"img":false}]}
{"op":"mcm","clk":"11541329395","pt":1719504594148,"mc":[{"id":"1.230180131","rc":[{"atb":[[1.6,6.58]],"id":58149406}],"con":true,"img":false}]}
{"op":"mcm","clk":"11541329405","pt":1719504594251,"mc":[{"id":"1.230180131","rc":[{"atb":[[1.58,2.11],[1.61,5.12]],"id":58149406},{"atb":[[1.83,0]],"id":41138102}],"con":true,"img":false}]}
{"op":"mcm","clk":"11541329412","pt":1719504594357,"mc":[{"id":"1.230180131","rc":[{"atb":[[1.02,2]],"id":41138102}],"con":true,"img":false}]}
{"op":"mcm","clk":"11541329445","pt":1719504594769,"mc":[{"id":"1.230180131","rc":[{"atb":[[1.02,0]],"id":58149406}],"con":true,"img":false}]}
{"op":"mcm","clk":"11541329457","pt":1719504594874,"mc":[{"id":"1.230180131","rc":[{"atb":[[1.59,2]],"id":58149406}],"con":true,"img":false}]}
{"op":"mcm","clk":"11541329539","pt":1719504595866,"mc":[{"id":"1.230180131","rc":[{"atb":[[1.77,0]],"id":66499052}],"con":true,"img":false}]}
{"op":"mcm","clk":"11541329552","pt":1719504595961,"mc":[{"id":"1.230180131","rc":[{"atb":[[1.81,2]],"id":66499052}],"con":true,"img":false}]}
{"op":"mcm","clk":"11541329588","pt":1719504596372,"mc":[{"id":"1.230180131","rc":[{"atb":[[1.02,0]],"id":41138102}],"con":true,"img":false}]}
{"op":"mcm","clk":"11541329607","pt":1719504596476,"mc":[{"id":"1.230180131","rc":[{"atb":[[1.87,2]],"id":41138102}],"con":true,"img":false}]}
{"op":"mcm","clk":"11541329655","pt":1719504596944,"mc":[{"id":"1.230180131","rc":[{"atb":[[1.59,0]],"id":58149406}],"con":true,"img":false}]}
{"op":"mcm","clk":"11541329662","pt":1719504597045,"mc":[{"id":"1.230180131","rc":[{"atb":[[1.62,2]],"id":58149406}],"con":true,"img":false}]}
{"op":"mcm","clk":"11541330785","pt":1719504609177,"mc":[{"id":"1.230180131","rc":[{"atb":[[1.01,1.7]],"id":41138102},{"atl":[[1000,1.87]],"id":41138102},{"atb":[[1.01,1.7]],"id":43210435},{"atl":[[1000,1.87]],"id":43210435},{"atb":[[1.01,1.7]],"id":66499052},{"atl":[[1000,1.87]],"id":66499052}],"con":true,"img":false}]}
{"op":"mcm","clk":"11541330804","pt":1719504609385,"mc":[{"id":"1.230180131","rc":[{"atb":[[1.01,0.33]],"id":41138102},{"atl":[[1000,0.19]],"id":41138102},{"atb":[[1.01,0.37]],"id":43210435},{"atl":[[1000,0.19]],"id":43210435},{"atb":[[1.01,0.35]],"id":66499052},{"atl":[[1000,0.19]],"id":66499052}],"con":true,"img":false}]}
{"op":"mcm","clk":"11541330821","pt":1719504609590,"mc":[{"id":"1.230180131","rc":[{"atb":[[1.01,0]],"id":43210435},{"atl":[[1000,0.17]],"id":43210435},{"atl":[[1000,0.17]],"id":66499052}],"con":true,"img":false}]}
{"op":"mcm","clk":"11541330829","pt":1719504609698,"mc":[{"id":"1.230180131","rc":[{"atb":[[1.01,0]],"id":41138102},{"atl":[[1000,0.17]],"id":41138102},{"atb":[[1.78,0.37]],"id":43210435},{"atl":[[23,0.01]],"id":43210435},{"atb":[[1.01,0]],"id":66499052},{"atl":[[20,0.01]],"id":66499052}],"con":true,"img":false}]}
{"op":"mcm","clk":"11541330839","pt":1719504609797,"mc":[{"id":"1.230180131","rc":[{"atb":[[1.88,0.33]],"id":41138102},{"atl":[[25,0.01]],"id":41138102},{"atb":[[1.82,0.35]],"id":66499052}],"con":true,"img":false}]}
{"op":"mcm","clk":"11541330851","pt":1719504609859,"mc":[{"id":"1.230180131","rc":[{"atb":[[1.88,2.33]],"id":41138102}],"con":true,"img":false}]}
{"op":"mcm","clk":"11541330859","pt":1719504609962,"mc":[{"id":"1.230180131","rc":[{"atb":[[1.86,0]],"id":41138102}],"con":true,"img":false}]}
{"op":"mcm","clk":"11541330903","pt":1719504610472,"mc":[{"id":"1.230180131","rc":[{"atb":[[1.87,0]],"id":41138102}],"con":true,"img":false}]}
{"op":"mcm","clk":"11541330911","pt":1719504610586,"mc":[{"id":"1.230180131","rc":[{"atb":[[1.89,2]],"id":41138102}],"con":true,"img":false}]}
{"op":"mcm","clk":"11541332563","pt":1719504630836,"mc":[{"id":"1.230180131","rc":[{"atb":[[1.6,0]],"id":58149406}],"con":true,"img":false}]}
{"op":"mcm","clk":"11541333463","pt":1719504641438,"mc":[{"id":"1.230180131","rc":[{"atb":[[1.88,2]],"id":41138102},{"atl":[[25,0]],"id":41138102},{"atb":[[1.78,0]],"id":43210435},{"atl":[[23,0]],"id":43210435},{"atb":[[1.82,0]],"id":66499052},{"atl":[[20,0]],"id":66499052}],"con":true,"img":false}]}
{"op":"mcm","clk":"11541336183","pt":1719504672380,"mc":[{"id":"1.230180131","rc":[{"atb":[[1.08,50]],"id":58149406},{"spn":3.21,"spf":"NaN","id":58149406},{"atb":[[1.08,50]],"id":41138102},{"atb":[[1.08,50]],"id":43210435},{"atb":[[1.08,50]],"id":66499052},{"spn":3.75,"spf":"NaN","id":66499052},{"atb":[[1.08,50]],"id":51843546},{"atb":[[1.08,52]],"id":69979297}],"con":true,"img":false}]}
{"op":"mcm","clk":"11541336675","pt":1719504678818,"mc":[{"id":"1.230180131","rc":[{"atb":[[1.85,0]],"id":41138102},{"atb":[[1.79,0]],"id":66499052}],"con":true,"img":false}]}
{"op":"mcm","clk":"11541339735","pt":1719504712977,"mc":[{"id":"1.230180131","rc":[{"atb":[[1.63,3],[2.04,10],[2.12,5],[2.2,2.5]],"id":58149406},{"atl":[[6.4,10],[5.8,5],[4.7,3],[5.4,2.5]],"id":58149406},{"atb":[[2.74,2.5],[1.98,2.25],[2.66,5],[2.58,10]],"id":41138102},{"atl":[[6.8,2.5],[7.6,5],[7,2.25],[8.4,10]],"id":41138102},{"atb":[[1.83,2.12],[1.98,2.34],[1.9,5],[1.86,10],[1.77,0],[1.94,2.5]],"id":43210435},{"atl":[[8,5],[7.2,3.5],[8.8,10],[7,2.34]],"id":43210435},{"atb":[[2,5],[1.82,3.09],[1.96,10],[2.08,2.5]],"id":66499052},{"atl":[[5.6,3.09],[6.2,2.5],[7,5],[7.8,10]],"id":66499052},{"atb":[[2.8,10],[2.88,5],[1.86,0],[2.26,1.5],[2.96,2.5],[1.93,2.48]],"id":51843546},{"atl":[[10,2.5],[8.2,1.5],[12,5],[14,10]],"id":51843546},{"atb":[[1.25,2.5],[1.3,10],[1.34,5],[1.38,2.5]],"id":69979297},{"atl":[[5.8,0],[3.1,5],[3,1.5],[2.96,2.5],[3.3,10],[4.7,2]],"id":69979297}],"con":true,"img":false}]}
{"op":"mcm","clk":"11541339744","pt":1719504713028,"mc":[{"id":"1.230180131","rc":[{"atb":[[2.02,2.12]],"id":58149406},{"atl":[[5.4,4.5]],"id":58149406},{"atb":[[1.83,0]],"id":43210435},{"atl":[[24,0]],"id":43210435},{"atb":[[1.8,0],[1.96,12.12]],"id":66499052},{"atl":[[6.2,4.5],[21,0]],"id":66499052},{"atb":[[1.3,12]],"id":69979297},{"atl":[[3.05,3]],"id":69979297}],"con":true,"img":false}]}
{"op":"mcm","clk":"11541339752","pt":1719504713136,"mc":[{"id":"1.230180131","rc":[{"atb":[[1.61,0]],"id":58149406},{"atl":[[12,0]],"id":58149406},{"atb":[[2.5,2],[1.88,0]],"id":41138102},{"atl":[[7.2,3],[26,0]],"id":41138102},{"atb":[[1.94,4.62]],"id":43210435},{"atl":[[8,7]],"id":43210435},{"atb":[[2.66,2],[1.93,0]],"id":51843546},{"atl":[[32,0],[10,4.5]],"id":51843546},{"atb":[[1.07,2.48]],"id":69979297},{"atl":[[4.7,0]],"id":69979297}],"con":true,"img":false}]}
{"op":"mcm","clk":"11541339776","pt":1719504713445,"mc":[{"id":"1.230180131","rc":[{"atl":[[4.6,0.84]],"id":58149406},{"atl":[[6.6,0.84]],"id":41138102},{"atl":[[6.8,0.84]],"id":43210435},{"atl":[[5.5,0.84]],"id":66499052},{"atl":[[2.94,0.84]],"id":69979297}],"con":true,"img":false}]}
{"op":"mcm","clk":"11541339828","pt":1719504714020,"mc":[{"id":"1.230180131","rc":[{"atb":[[1.81,0]],"id":66499052}],"con":true,"img":false}]}
{"op":"mcm","clk":"11541339838","pt":1719504714126,"mc":[{"id":"1.230180131","rc":[{"atb":[[2.1,2]],"id":66499052}],"con":true,"img":false}]}
{"op":"mcm","clk":"11541339868","pt":1719504714432,"mc":[{"id":"1.230180131","rc":[{"atb":[[1.02,16.48]],"id":43210435}],"con":true,"img":false}]}
{"op":"mcm","clk":"11541339879","pt":1719504714539,"mc":[{"id":"1.230180131","rc":[{"atb":[[1.99,2]],"id":43210435}],"con":true,"img":false}]}
{"op":"mcm","clk":"11541339909","pt":1719504714848,"mc":[{"id":"1.230180131","rc":[{"atb":[[1.89,0]],"id":41138102}],"con":true,"img":false}]}
{"op":"mcm","clk":"11541339917","pt":1719504714950,"mc":[{"id":"1.230180131","rc":[{"atb":[[2.76,2]],"id":41138102}],"con":true,"img":false}]}
{"op":"mcm","clk":"11541339946","pt":1719504715262,"mc":[{"id":"1.230180131","rc":[{"atb":[[1.08,50]],"id":69979297}],"con":true,"img":false}]}
{"op":"mcm","clk":"11541339958","pt":1719504715366,"mc":[{"id":"1.230180131","rc":[{"atb":[[1.39,2]],"id":69979297}],"con":true,"img":false}]}
{"op":"mcm","clk":"11541339985","pt":1719504715520,"mc":[{"id":"1.230180131","rc":[{"atb":[[1.62,0]],"id":58149406}],"con":true,"img":false}]}
{"op":"mcm","clk":"11541339994","pt":1719504715624,"mc":[{"id":"1.230180131","rc":[{"atb":[[2.22,2]],"id":58149406}],"con":true,"img":false}]}
{"op":"mcm","clk":"11541340009","pt":1719504715833,"mc":[{"id":"1.230180131","rc":[{"atb":[[1.02,0]],"id":51843546}],"con":true,"img":false}]}
{"op":"mcm","clk":"11541340021","pt":1719504715935,"mc":[{"id":"1.230180131","rc":[{"atb":[[2.98,2]],"id":51843546}],"con":true,"img":false}]}
{"op":"mcm","clk":"11541340120","pt":1719504717125,"mc":[{"id":"1.230180131","rc":[{"atb":[[1.33,2.11]],"id":69979297}],"con":true,"img":false}]}
{"op":"mcm","clk":"11541340313","pt":1719504719678,"mc":[{"id":"1.230180131","rc":[{"atl":[[4.8,5.5],[5.4,2.5]],"id":58149406},{"atb":[[1.96,10],[2.1,4.5]],"id":66499052},{"atl":[[6.2,2.5],[5.9,5]],"id":66499052},{"atb":[[1.3,10],[1.35,5]],"id":69979297}],"con":true,"img":false}]}
{"op":"mcm","clk":"11541340322","pt":1719504719736,"mc":[{"id":"1.230180131","rc":[{"atb":[[1.99,4],[1.94,2.5]],"id":43210435},{"atl":[[8,5],[7.2,10.5]],"id":43210435}],"con":true,"img":false}]}
{"op":"mcm","clk":"11541340564","pt":1719504722451,"mc":[{"id":"1.230180131","rc":[{"atl":[[5.8,5],[5.9,0]],"id":66499052},{"atb":[[2.4,5],[2.66,0]],"id":51843546},{"atl":[[8.4,0],[9.4,1]],"id":51843546},{"atb":[[1.34,10],[1.35,0]],"id":69979297}],"con":true,"img":false}]}
{"op":"mcm","clk":"11541340574","pt":1719504722543,"mc":[{"id":"1.230180131","rc":[{"atb":[[2.4,0],[2.84,5]],"id":51843546},{"atl":[[10,2.5],[9.4,6]],"id":51843546}],"con":true,"img":false}]}
{"op":"mcm","clk":"11541340599","pt":1719504722848,"mc":[{"id":"1.230180131","rc":[{"atl":[[10,10],[8.2,0],[9.4,1]],"id":51843546}],"con":true,"img":false}]}
{"op":"mcm","clk":"11541340608","pt":1719504722951,"mc":[{"id":"1.230180131","rc":[{"atl":[[8.4,3.38]],"id":51843546}],"con":true,"img":false}]}
{"op":"mcm","clk":"11541340620","pt":1719504723055,"mc":[{"id":"1.230180131","rc":[{"atl":[[10,2.5],[8.8,6.76]],"id":51843546}],"con":true,"img":false}]}
{"op":"mcm","clk":"11541340628","pt":1719504723167,"mc":[{"id":"1.230180131","rc":[{"atl":[[8.8,0],[9.4,11.14]],"id":51843546}],"con":true,"img":false}]}
{"op":"mcm","clk":"11541340656","pt":1719504723478,"mc":[{"id":"1.230180131","rc":[{"atl":[[8.2,0.84]],"id":51843546}],"con":true,"img":false}]}
{"op":"mcm","clk":"11541340965","pt":1719504727071,"mc":[{"id":"1.230180131","rc":[{"atb":[[2.22,6.12]],"id":58149406},{"atl":[[4.6,4.96]],"id":58149406},{"atb":[[2.8,3.56]],"id":41138102},{"atl":[[6.6,4.4]],"id":41138102},{"atb":[[2.02,3.51]],"id":43210435},{"atl":[[6.8,4.35]],"id":43210435},{"atb":[[2.14,4.19]],"id":66499052},{"atl":[[5.5,5.03]],"id":66499052},{"atb":[[3,4.41]],"id":51843546},{"atl":[[8.2,5.25]],"id":51843546},{"atb":[[1.39,5.38]],"id":69979297},{"atl":[[2.94,4.22]],"id":69979297}],"con":true,"img":false}]}
{"op":"mcm","clk":"11541340977","pt":1719504727181,"mc":[{"id":"1.230180131","rc":[{"atb":[[1.63,0]],"id":58149406},{"atl":[[4.7,0]],"id":58149406},{"atb":[[1.98,0]],"id":41138102},{"atl":[[7,0],[1000,1.87]],"id":41138102},{"atb":[[1.98,0]],"id":43210435},{"atl":[[7,0],[1000,1.87]],"id":43210435},{"atb":[[1.82,0]],"id":66499052},{"atl":[[5.6,0],[1000,1.87]],"id":66499052},{"atb":[[2.26,0]],"id":51843546},{"atl":[[8.4,0]],"id":51843546},{"atb":[[1.25,1]],"id":69979297},{"atl":[[3,0]],"id":69979297}],"con":true,"img":false}]}
{"op":"mcm","clk":"11541340989","pt":1719504727234,"mc":[{"id":"1.230180131","rc":[{"atl":[[5.4,12.97]],"id":58149406},{"atb":[[1.02,1.7]],"id":41138102},{"atl":[[1000,0.22]],"id":41138102},{"atb":[[1.01,1.7]],"id":43210435},{"atl":[[8,19.29],[7.2,3.5],[1000,0.22]],"id":43210435},{"atb":[[1.01,1.7]],"id":66499052},{"atl":[[1000,0.24]],"id":66499052},{"atl":[[10,13.61],[9.4,1]],"id":51843546}],"con":true,"img":false}]}
{"op":"mcm","clk":"11541341000","pt":1719504727344,"mc":[{"id":"1.230180131","rc":[{"atl":[[4.8,1]],"id":58149406}],"con":true,"img":false}]}
{"op":"mcm","clk":"11541341012","pt":1719504727444,"mc":[{"id":"1.230180131","rc":[{"atb":[[1.02,0.15]],"id":41138102},{"atl":[[1000,0.17]],"id":41138102},{"atb":[[1.01,0.28]],"id":43210435},{"atl":[[1000,0.17]],"id":43210435},{"atb":[[1.01,0.25]],"id":66499052},{"atl":[[1000,0.17]],"id":66499052}],"con":true,"img":false}]}
{"op":"mcm","clk":"11541341021","pt":1719504727543,"mc":[{"id":"1.230180131","rc":[{"atl":[[6.6,4.45]],"id":41138102},{"atl":[[6.8,4.4]],"id":43210435},{"atl":[[5.5,5.09]],"id":66499052}],"con":true,"img":false}]}
{"op":"mcm","clk":"11541341028","pt":1719504727668,"mc":[{"id":"1.230180131","rc":[{"atb":[[1.02,0]],"id":41138102},{"atb":[[1.01,0]],"id":43210435},{"atb":[[1.01,0]],"id":66499052}],"con":true,"img":false}]}
{"op":"mcm","clk":"11541341042","pt":1719504727776,"mc":[{"id":"1.230180131","rc":[{"atb":[[2.78,0.15]],"id":41138102},{"atb":[[2,0.28]],"id":43210435},{"atb":[[2.12,0.25]],"id":66499052}],"con":true,"img":false}]}
{"op":"mcm","clk":"11541341081","pt":1719504728139,"mc":[{"id":"1.230180131","rc":[{"atb":[[2.1,2.5]],"id":66499052}],"con":true,"img":false}]}
{"op":"mcm","clk":"11541341094","pt":1719504728241,"mc":[{"id":"1.230180131","rc":[{"atb":[[2.16,2]],"id":66499052}],"con":true,"img":false}]}
{"op":"mcm","clk":"11541341106","pt":1719504728343,"mc":[{"id":"1.230180131","rc":[{"atb":[[2.16,4]],"id":66499052}],"con":true,"img":false}]}
{"op":"mcm","clk":"11541341115","pt":1719504728453,"mc":[{"id":"1.230180131","rc":[{"atb":[[2.12,6.44],[2.1,0],[2.16,2]],"id":66499052}],"con":true,"img":false}]}
{"op":"mcm","clk":"11541341124","pt":1719504728553,"mc":[{"id":"1.230180131","rc":[{"atb":[[1.99,2]],"id":43210435},{"atb":[[2.12,0.25],[2.16,6]],"id":66499052}],"con":true,"img":false}]}
{"op":"mcm","clk":"11541341132","pt":1719504728665,"mc":[{"id":"1.230180131","rc":[{"atb":[[2.04,2]],"id":43210435},{"atb":[[2.12,6.44],[2.16,2]],"id":66499052}],"con":true,"img":false}]}
{"op":"mcm","clk":"11541341140","pt":1719504728762,"mc":[{"id":"1.230180131","rc":[{"atb":[[2.12,0.25],[2.16,6.19]],"id":66499052}],"con":true,"img":false}]}
{"op":"mcm","clk":"11541341149","pt":1719504728873,"mc":[{"id":"1.230180131","rc":[{"atb":[[2.04,4],[1.99,0]],"id":43210435}],"con":true,"img":false}]}
{"op":"mcm","clk":"11541341156","pt":1719504728974,"mc":[{"id":"1.230180131","rc":[{"atb":[[2.12,6.44],[2.16,1.99]],"id":66499052}],"con":true,"img":false}]}
{"op":"mcm","clk":"11541341164","pt":1719504729078,"mc":[{"id":"1.230180131","rc":[{"atb":[[2.76,0]],"id":41138102},{"atb":[[2,5.79],[2.04,2]],"id":43210435}],"con":true,"img":false}]}
{"op":"mcm","clk":"11541341175","pt":1719504729182,"mc":[{"id":"1.230180131","rc":[{"atb":[[2.82,2]],"id":41138102}],"con":true,"img":false}]}
{"op":"mcm","clk":"11541341192","pt":1719504729286,"mc":[{"id":"1.230180131","rc":[{"atb":[[1.58,0],[2.18,2.11]],"id":58149406}],"con":true,"img":false}]}
{"op":"mcm","clk":"11541341213","pt":1719504729547,"mc":[{"id":"1.230180131","rc":[{"atb":[[2.98,0]],"id":51843546}],"con":true,"img":false}]}
{"op":"mcm","clk":"11541341221","pt":1719504729650,"mc":[{"id":"1.230180131","rc":[{"atb":[[3.05,2]],"id":51843546}],"con":true,"img":false}]}
{"op":"mcm","clk":"11541341239","pt":1719504729857,"mc":[{"id":"1.230180131","rc":[{"atb":[[3,0],[3.05,7.18]],"id":51843546}],"con":true,"img":false}]}
{"op":"mcm","clk":"11541341333","pt":1719504731048,"mc":[{"id":"1.230180131","rc":[{"atb":[[2.84,0],[2.7,10]],"id":51843546}],"con":true,"img":false}]}
{"op":"mcm","clk":"11541341346","pt":1719504731157,"mc":[{"id":"1.230180131","rc":[{"atb":[[2.92,9.68],[2.7,0]],"id":51843546}],"con":true,"img":false}]}
{"op":"mcm","clk":"11541342148","pt":1719504740853,"mc":[{"id":"1.230180131","rc":[{"spn":3.41,"spf":"NaN","id":58149406},{"atb":[[2.82,6.12]],"id":41138102},{"spn":4.71,"spf":"NaN","id":41138102},{"atb":[[2.04,7.94]],"id":43210435},{"spn":4.42,"spf":"NaN","id":43210435},{"atb":[[2.16,8.89]],"id":66499052},{"spn":3.83,"spf":"NaN","id":66499052},{"spn":5.62,"spf":"NaN","id":51843546},{"spn":2.16,"spf":"NaN","id":69979297}],"con":true,"img":false}]}
{"op":"mcm","clk":"11541342156","pt":1719504740957,"mc":[{"id":"1.230180131","rc":[{"atb":[[2.8,0]],"id":41138102},{"atb":[[2,0.28],[2.02,0],[2.06,5.79]],"id":43210435},{"atb":[[2.12,0.25],[2.18,6.44]],"id":66499052}],"con":true,"img":false}]}
{"op":"mcm","clk":"11541342166","pt":1719504741060,"mc":[{"id":"1.230180131","rc":[{"atb":[[2.06,0],[2.04,19.52]],"id":43210435},{"atb":[[2.14,0],[2.18,0],[2.16,21.77]],"id":66499052}],"con":true,"img":false}]}
{"op":"mcm","clk":"11541342176","pt":1719504741164,"mc":[{"id":"1.230180131","rc":[{"atb":[[2.02,13.73],[2.04,7.94]],"id":43210435},{"atb":[[2.16,8.89],[2.14,15.33]],"id":66499052}],"con":true,"img":false}]}
{"op":"mcm","clk":"11541342185","pt":1719504741273,"mc":[{"id":"1.230180131","rc":[{"atb":[[2,21.95],[2.02,0]],"id":43210435},{"atb":[[2.12,24.47],[2.14,0]],"id":66499052}],"con":true,"img":false}]}
{"op":"mcm","clk":"11541342195","pt":1719504741378,"mc":[{"id":"1.230180131","rc":[{"atb":[[2.04,15.88]],"id":43210435},{"atb":[[2.12,0.25]],"id":66499052}],"con":true,"img":false}]}
{"op":"mcm","clk":"11541342205","pt":1719504741475,"mc":[{"id":"1.230180131","rc":[{"atb":[[2,0.28]],"id":43210435},{"atb":[[2.16,17.78]],"id":66499052}],"con":true,"img":false}]}
{"op":"mcm","clk":"11541342267","pt":1719504742153,"mc":[{"id":"1.230180131","rc":[{"atb":[[2.1,4.25]],"id":66499052}],"con":true,"img":false}]}
{"op":"mcm","clk":"11541342291","pt":1719504742360,"mc":[{"id":"1.230180131","rc":[{"atb":[[2.1,0]],"id":66499052}],"con":true,"img":false}]}
{"op":"mcm","clk":"11541342395","pt":1719504743389,"mc":[{"id":"1.230180131","rc":[{"atl":[[9.6,1],[9.4,0]],"id":51843546}],"con":true,"img":false}]}
{"op":"mcm","clk":"11541342409","pt":1719504743444,"mc":[{"id":"1.230180131","rc":[{"atl":[[9.6,11],[10,2.5]],"id":51843546}],"con":true,"img":false}]}
{"op":"mcm","clk":"11541342720","pt":1719504746649,"mc":[{"id":"1.230180131","rc":[{"atb":[[1.99,3]],"id":43210435}],"con":true,"img":false}]}
{"op":"mcm","clk":"11541343354","pt":1719504754366,"mc":[{"id":"1.230180131","rc":[{"atb":[[2.02,0],[1.75,7.5]],"id":58149406},{"atb":[[2.5,0],[2.18,7.5]],"id":41138102},{"atl":[[7.2,1],[7.8,7.46]],"id":41138102},{"atb":[[2.06,5],[2.16,8.89]],"id":66499052},{"atb":[[2.92,0],[2.84,12.18]],"id":51843546},{"atb":[[1.31,7.88],[1.34,5]],"id":69979297},{"atl":[[2.96,3.5],[3.05,2]],"id":69979297}],"con":true,"img":false}]}
{"op":"mcm","clk":"11541343370","pt":1719504754575,"mc":[{"id":"1.230180131","rc":[{"atb":[[1.98,7.5],[1.75,0]],"id":58149406},{"atb":[[2.54,10],[2.18,0]],"id":41138102},{"atl":[[7.2,7.96],[7.8,0]],"id":41138102},{"atb":[[2.06,0],[2.16,11.39]],"id":66499052},{"atb":[[2.84,0],[3.05,14.36]],"id":51843546},{"atb":[[1.31,0],[1.38,13.26]],"id":69979297},{"atl":[[2.72,5.42]],"id":69979297}],"con":true,"img":false}]}
{"op":"mcm","clk":"11541343380","pt":1719504754683,"mc":[{"id":"1.230180131","rc":[{"atb":[[2.16,8.89],[2.08,11.64]],"id":66499052},{"atb":[[2.88,15],[3.05,7.18]],"id":51843546},{"atl":[[2.96,11.96],[2.94,0.84],[3.05,0]],"id":69979297}],"con":true,"img":false}]}
{"op":"mcm","clk":"11541343390","pt":1719504754782,"mc":[{"id":"1.230180131","rc":[{"atb":[[2.16,11.39],[2.08,2.5]],"id":66499052},{"atb":[[2.88,5],[3.05,12.18]],"id":51843546}],"con":true,"img":false}]}
{"op":"mcm","clk":"11541343396","pt":1719504754886,"mc":[{"id":"1.230180131","rc":[{"atb":[[2.16,8.89],[2.08,12.5]],"id":66499052},{"atb":[[2.88,15],[3.05,7.18]],"id":51843546},{"atl":[[2.94,0],[2.7,0.85]],"id":69979297}],"con":true,"img":false}]}
{"op":"mcm","clk":"11541343440","pt":1719504755502,"mc":[{"id":"1.230180131","rc":[{"atb":[[1.99,0]],"id":43210435}],"con":true,"img":false}]}
{"op":"mcm","clk":"11541343510","pt":1719504756278,"mc":[{"id":"1.230180131","rc":[{"atb":[[2.24,3]],"id":58149406},{"atb":[[2.84,2]],"id":41138102},{"atb":[[2.06,4]],"id":43210435},{"atb":[[3.1,2.8]],"id":51843546},{"atb":[[1.39,9.02]],"id":69979297}],"con":true,"img":false}]}
{"op":"mcm","clk":"11541343519","pt":1719504756384,"mc":[{"id":"1.230180131","rc":[{"atb":[[2.24,8.98]],"id":58149406},{"atb":[[2.84,7.22]],"id":41138102},{"atb":[[2.04,7.94],[2.08,10.31]],"id":43210435},{"atb":[[3.1,11.64]],"id":51843546}],"con":true,"img":false}]}
{"op":"mcm","clk":"11541343528","pt":1719504756484,"mc":[{"id":"1.230180131","rc":[{"atb":[[2.88,5]],"id":51843546}],"con":true,"img":false}]}
{"op":"mcm","clk":"11541343536","pt":1719504756587,"mc":[{"id":"1.230180131","rc":[{"atb":[[2.22,2]],"id":58149406},{"atb":[[2.82,2]],"id":41138102},{"atb":[[2.04,2]],"id":43210435},{"atb":[[3.1,8.84],[3.05,9.18]],"id":51843546}],"con":true,"img":false}]}
{"op":"mcm","clk":"11541343544","pt":1719504756691,"mc":[{"id":"1.230180131","rc":[{"atb":[[2.1,5.02]],"id":43210435}],"con":true,"img":false}]}
{"op":"mcm","clk":"11541343554","pt":1719504756796,"mc":[{"id":"1.230180131","rc":[{"atb":[[2.04,0],[2.12,5.03],[2.08,6.31]],"id":43210435}],"con":true,"img":false}]}
{"op":"mcm","clk":"11541343562","pt":1719504756899,"mc":[{"id":"1.230180131","rc":[{"atb":[[2.08,8.31]],"id":43210435}],"con":true,"img":false}]}
{"op":"mcm","clk":"11541343598","pt":1719504757268,"mc":[{"id":"1.230180131","rc":[{"atb":[[2.82,0]],"id":41138102}],"con":true,"img":false}]}
{"op":"mcm","clk":"11541343608","pt":1719504757365,"mc":[{"id":"1.230180131","rc":[{"atb":[[2.86,2]],"id":41138102}],"con":true,"img":false}]}
{"op":"mcm","clk":"11541343651","pt":1719504757882,"mc":[{"id":"1.230180131","rc":[{"atb":[[2.22,0]],"id":58149406}],"con":true,"img":false}]}
{"op":"mcm","clk":"11541343659","pt":1719504757986,"mc":[{"id":"1.230180131","rc":[{"atb":[[2.26,2]],"id":58149406}],"con":true,"img":false}]}
{"op":"mcm","clk":"11541343692","pt":1719504758299,"mc":[{"id":"1.230180131","rc":[{"atb":[[3.05,7.18]],"id":51843546}],"con":true,"img":false}]}
{"op":"mcm","clk":"11541343701","pt":1719504758402,"mc":[{"id":"1.230180131","rc":[{"atb":[[3.15,2]],"id":51843546}],"con":true,"img":false}]}
{"op":"mcm","clk":"11541343809","pt":1719504759797,"mc":[{"id":"1.230180131","rc":[{"atb":[[2.08,6.31]],"id":43210435}],"con":true,"img":false}]}
{"op":"mcm","clk":"11541343818","pt":1719504759902,"mc":[{"id":"1.230180131","rc":[{"atb":[[2.14,2]],"id":43210435}],"con":true,"img":false}]}
{"op":"mcm","clk":"11541344012","pt":1719504761872,"mc":[{"id":"1.230180131","rc":[{"atb":[[1.71,0],[2.16,2.11]],"id":43210435}],"con":true,"img":false}]}
{"op":"mcm","clk":"11541344062","pt":1719504762391,"mc":[{"id":"1.230180131","rc":[{"atb":[[2.14,0]],"id":43210435}],"con":true,"img":false}]}
{"op":"mcm","clk":"11541344073","pt":1719504762500,"mc":[{"id":"1.230180131","rc":[{"atb":[[2.18,2]],"id":43210435}],"con":true,"img":false}]}
{"op":"mcm","clk":"11541344106","pt":1719504762806,"mc":[{"id":"1.230180131","rc":[{"atb":[[3.15,9.18],[3.05,0]],"id":51843546}],"con":true,"img":false}]}
{"op":"mcm","clk":"11541344116","pt":1719504762909,"mc":[{"id":"1.230180131","rc":[{"atb":[[3.1,16.02],[3.15,2]],"id":51843546}],"con":true,"img":false}]}
{"op":"mcm","clk":"11541344126","pt":1719504762961,"mc":[{"id":"1.230180131","rc":[{"atb":[[2.12,0],[2.18,4.12]],"id":43210435}],"con":true,"img":false}]}
{"op":"mcm","clk":"11541344367","pt":1719504765917,"mc":[{"id":"1.230180131","rc":[{"atb":[[1.98,0],[2.16,7.5]],"id":58149406},{"atl":[[4.7,1]],"id":58149406},{"atb":[[2.76,5]],"id":41138102},{"atb":[[3.1,8.84],[3,18.02]],"id":51843546},{"atl":[[9.6,10],[10.5,1]],"id":51843546},{"atb":[[1.4,9.02],[1.38,2.5]],"id":69979297},{"atl":[[2.86,1],[2.96,10.96]],"id":69979297}],"con":true,"img":false}]}
{"op":"mcm","clk":"11541344377","pt":1719504766016,"mc":[{"id":"1.230180131","rc":[{"atb":[[2.16,0]],"id":58149406},{"atl":[[4.8,9.94],[5.4,2.5]],"id":58149406},{"atb":[[2.54,0],[2.76,0]],"id":41138102},{"atl":[[2.86,11],[2.96,2.49]],"id":69979297}],"con":true,"img":false}]}
{"op":"mcm","clk":"11541344383","pt":1719504766151,"mc":[{"id":"1.230180131","rc":[{"atb":[[2.46,10],[2.78,0]],"id":41138102},{"atl":[[6.6,4.4]],"id":41138102},{"atb":[[2,0]],"id":43210435},{"atl":[[6.8,4.35]],"id":43210435},{"atb":[[2.12,0]],"id":66499052},{"atl":[[5.5,5.03]],"id":66499052},{"atb":[[1.4,14.96]],"id":69979297}],"con":true,"img":false}]}
{"op":"mcm","clk":"11541344393","pt":1719504766196,"mc":[{"id":"1.230180131","rc":[{"atb":[[2,10]],"id":58149406}],"con":true,"img":false}]}
{"op":"mcm","clk":"11541344402","pt":1719504766304,"mc":[{"id":"1.230180131","rc":[{"atb":[[2.16,17.78],[2.08,2.5]],"id":66499052},{"atb":[[1.39,5.64]],"id":69979297}],"con":true,"img":false}]}
{"op":"mcm","clk":"11541344411","pt":1719504766406,"mc":[{"id":"1.230180131","rc":[{"atb":[[2,26.39],[2.16,8.89]],"id":66499052}],"con":true,"img":false}]}
{"op":"mcm","clk":"11541344528","pt":1719504767810,"mc":[{"id":"1.230180131","rc":[{"atl":[[2.7,9.14]],"id":69979297}],"con":true,"img":false}]}
{"op":"mcm","clk":"11541344532","pt":1719504767914,"mc":[{"id":"1.230180131","rc":[{"atb":[[1.39,3.64]],"id":69979297},{"atl":[[2.72,0]],"id":69979297}],"con":true,"img":false}]}
{"op":"mcm","clk":"11541344543","pt":1719504767970,"mc":[{"id":"1.230180131","rc":[{"atb":[[1.41,2]],"id":69979297}],"con":true,"img":false}]}
{"op":"mcm","clk":"11541344603","pt":1719504768795,"mc":[{"id":"1.230180131","rc":[{"atl":[[7.2,6.96],[7.4,1]],"id":41138102},{"atl":[[7.2,2.5],[7.4,1]],"id":43210435},{"atl":[[5.6,1],[5.7,0]],"id":66499052},{"atl":[[10.5,0],[11.5,1]],"id":51843546},{"atl":[[2.86,10],[2.74,1]],"id":69979297}],"con":true,"img":false}]}
{"op":"mcm","clk":"11541344610","pt":1719504768900,"mc":[{"id":"1.230180131","rc":[{"atl":[[8,5],[7.2,11.22]],"id":43210435},{"atb":[[2,5],[2.16,17.78]],"id":66499052},{"atb":[[1.4,5.94]],"id":69979297}],"con":true,"img":false}]}
{"op":"mcm","clk":"11541344625","pt":1719504769112,"mc":[{"id":"1.230180131","rc":[{"atl":[[7.4,11]],"id":43210435},{"atb":[[2,16.39],[2.16,8.89]],"id":66499052},{"atb":[[1.33,9.39]],"id":69979297}],"con":true,"img":false}]}
{"op":"mcm","clk":"11541344636","pt":1719504769221,"mc":[{"id":"1.230180131","rc":[{"atl":[[7.2,2.49]],"id":43210435}],"con":true,"img":false}]}
{"op":"mcm","clk":"11541344676","pt":1719504769573,"mc":[{"id":"1.230180131","rc":[{"atb":[[2.26,7.6]],"id":58149406},{"atb":[[2.86,7.18]],"id":41138102},{"atb":[[2.2,6.36]],"id":43210435},{"atb":[[3.2,10.58]],"id":51843546}],"con":true,"img":false}]}
{"op":"mcm","clk":"11541344683","pt":1719504769678,"mc":[{"id":"1.230180131","rc":[{"atb":[[2.24,3]],"id":58149406},{"atb":[[2.84,2]],"id":41138102},{"atb":[[2.08,0]],"id":43210435},{"atb":[[3.1,2.8]],"id":51843546}],"con":true,"img":false}]}
{"op":"mcm","clk":"11541344728","pt":1719504770294,"mc":[{"id":"1.230180131","rc":[{"atb":[[2.8,2.5],[2.72,5]],"id":41138102},{"atl":[[5.8,7.5],[6.2,0],[7,0],[7.8,0]],"id":66499052},{"atb":[[2.8,0],[3.35,2.5],[2.88,0],[3.15,7],[2.96,0]],"id":51843546}],"con":true,"img":false}]}
{"op":"mcm","clk":"11541344735","pt":1719504770399,"mc":[{"id":"1.230180131","rc":[{"atb":[[2.24,0]],"id":58149406},{"atb":[[2.84,0],[2.58,0],[2.74,0],[2.66,0]],"id":41138102},{"atb":[[2.06,0]],"id":43210435},{"atb":[[2.16,17.78]],"id":66499052},{"atb":[[3.1,0]],"id":51843546},{"atb":[[1.39,0]],"id":69979297}],"con":true,"img":false}]}
{"op":"mcm","clk":"11541344744","pt":1719504770500,"mc":[{"id":"1.230180131","rc":[{"atb":[[2.28,2.4]],"id":58149406},{"atb":[[2.88,2]],"id":41138102},{"atb":[[2.22,2.3]],"id":43210435},{"atb":[[2,5]],"id":66499052},{"atb":[[3.25,2.89]],"id":51843546},{"atb":[[1.41,4]],"id":69979297}],"con":true,"img":false}]}
{"op":"mcm","clk":"11541344751","pt":1719504770603,"mc":[{"id":"1.230180131","rc":[{"atb":[[2.22,6.42],[2.18,2]],"id":43210435}],"con":true,"img":false}]}
{"op":"mcm","clk":"11541344765","pt":1719504770810,"mc":[{"id":"1.230180131","rc":[{"atb":[[2.18,0]],"id":43210435}],"con":true,"img":false}]}
{"op":"mcm","clk":"11541344774","pt":1719504770915,"mc":[{"id":"1.230180131","rc":[{"atb":[[2.22,8.42]],"id":43210435}],"con":true,"img":false}]}
{"op":"mcm","clk":"11541344799","pt":1719504771223,"mc":[{"id":"1.230180131","rc":[{"atb":[[3.15,5]],"id":51843546}],"con":true,"img":false}]}
{"op":"mcm","clk":"11541344806","pt":1719504771280,"mc":[{"id":"1.230180131","rc":[{"atb":[[3.4,2]],"id":51843546}],"con":true,"img":false}]}
{"op":"mcm","clk":"11541344879","pt":1719504772216,"mc":[{"id":"1.230180131","rc":[{"atb":[[2.56,7.5],[2.46,0]],"id":41138102}],"con":true,"img":false}]}
{"op":"mcm","clk":"11541345043","pt":1719504773905,"mc":[{"id":"1.230180131","rc":[{"atb":[[2.86,5.18]],"id":41138102}],"con":true,"img":false}]}
{"op":"mcm","clk":"11541345055","pt":1719504774004,"mc":[{"id":"1.230180131","rc":[{"atb":[[2.9,2]],"id":41138102}],"con":true,"img":false}]}
{"op":"mcm","clk":"11541345071","pt":1719504774213,"mc":[{"id":"1.230180131","rc":[{"atb":[[1.41,6.11],[1.33,7.28]],"id":69979297}],"con":true,"img":false}]}
{"op":"mcm","clk":"11541345094","pt":1719504774418,"mc":[{"id":"1.230180131","rc":[{"atb":[[2.26,5.6]],"id":58149406}],"con":true,"img":false}]}
{"op":"mcm","clk":"11541345124","pt":1719504774676,"mc":[{"id":"1.230180131","rc":[{"atb":[[2.3,2]],"id":58149406}],"con":true,"img":false}]}
{"op":"mcm","clk":"11541345160","pt":1719504775089,"mc":[{"id":"1.230180131","rc":[{"atb":[[1.28,12.06],[1.33,0]],"id":69979297}],"con":true,"img":false}]}
{"op":"mcm","clk":"11541345191","pt":1719504775505,"mc":[{"id":"1.230180131","rc":[{"atb":[[2.1,0]],"id":43210435}],"con":true,"img":false}]}
{"op":"mcm","clk":"11541345211","pt":1719504775708,"mc":[{"id":"1.230180131","rc":[{"atb":[[2.3,4.25]],"id":43210435}],"con":true,"img":false}]}
{"op":"mcm","clk":"11541345220","pt":1719504775811,"mc":[{"id":"1.230180131","rc":[{"atb":[[2.32,6.36],[2.22,4.3]],"id":43210435}],"con":true,"img":false}]}
{"op":"mcm","clk":"11541345286","pt":1719504776598,"mc":[{"id":"1.230180131","rc":[{"atb":[[2.22,2.3]],"id":43210435}],"con":true,"img":false}]}
{"op":"mcm","clk":"11541345295","pt":1719504776705,"mc":[{"id":"1.230180131","rc":[{"atb":[[2.34,2]],"id":43210435}],"con":true,"img":false}]}
{"op":"mcm","clk":"11541345518","pt":1719504778998,"mc":[{"id":"1.230180131","rc":[{"atl":[[10,0],[11.5,6],[12,0],[9.8,2.5],[14,0]],"id":51843546}],"con":true,"img":false}]}
{"op":"mcm","clk":"11541345528","pt":1719504779098,"mc":[{"id":"1.230180131","rc":[{"atb":[[1.41,15.15]],"id":69979297}],"con":true,"img":false}]}
{"op":"mcm","clk":"11541345537","pt":1719504779207,"mc":[{"id":"1.230180131","rc":[{"atb":[[1.4,0]],"id":69979297}],"con":true,"img":false}]}
{"op":"mcm","clk":"11541345711","pt":1719504781139,"mc":[{"id":"1.230180131","rc":[{"atb":[[1.28,0],[1.31,10]],"id":69979297}],"con":true,"img":false}]}
{"op":"mcm","clk":"11541345835","pt":1719504782516,"mc":[{"id":"1.230180131","rc":[{"atb":[[2.3,7.53]],"id":58149406},{"atb":[[2.9,7.18]],"id":41138102},{"atb":[[2.36,6.46]],"id":43210435},{"atb":[[3.4,6.04]],"id":51843546}],"con":true,"img":false}]}
{"op":"mcm","clk":"11541345846","pt":1719504782615,"mc":[{"id":"1.230180131","rc":[{"atb":[[2.32,0],[2.38,6.36]],"id":43210435}],"con":true,"img":false}]}
{"op":"mcm","clk":"11541345855","pt":1719504782722,"mc":[{"id":"1.230180131","rc":[{"atb":[[2.26,0]],"id":58149406},{"atb":[[2.86,0]],"id":41138102},{"atb":[[2.34,14.92],[2.38,0],[2.2,0]],"id":43210435},{"atb":[[3.2,0]],"id":51843546}],"con":true,"img":false}]}
{"op":"mcm","clk":"11541345957","pt":1719504784121,"mc":[{"id":"1.230180131","rc":[{"atb":[[2.34,12.92]],"id":43210435}],"con":true,"img":false}]}
{"op":"mcm","clk":"11541345965","pt":1719504784225,"mc":[{"id":"1.230180131","rc":[{"atb":[[2.38,2]],"id":43210435}],"con":true,"img":false}]}
{"op":"mcm","clk":"11541345972","pt":1719504784329,"mc":[{"id":"1.230180131","rc":[{"atb":[[2.32,19.38],[2.34,0]],"id":43210435}],"con":true,"img":false}]}
{"op":"mcm","clk":"11541345983","pt":1719504784433,"mc":[{"id":"1.230180131","rc":[{"atb":[[2.28,0]],"id":58149406},{"atb":[[2.88,0]],"id":41138102},{"atb":[[2.32,0],[2.22,0],[2.38,8.46]],"id":43210435},{"atb":[[3.25,0]],"id":51843546},{"atb":[[1.41,13.15]],"id":69979297}],"con":true,"img":false}]}
{"op":"mcm","clk":"11541345991","pt":1719504784548,"mc":[{"id":"1.230180131","rc":[{"atb":[[2.32,3.1]],"id":58149406},{"atb":[[2.92,2.91]],"id":41138102},{"atb":[[2.32,8.46],[2.38,5.8]],"id":43210435},{"atb":[[3.45,2]],"id":51843546}],"con":true,"img":false}]}
{"op":"mcm","clk":"11541346002","pt":1719504784590,"mc":[{"id":"1.230180131","rc":[{"atb":[[2.32,0]],"id":43210435}],"con":true,"img":false}]}
{"op":"mcm","clk":"11541346006","pt":1719504784695,"mc":[{"id":"1.230180131","rc":[{"atb":[[2.38,12.26]],"id":43210435}],"con":true,"img":false}]}
{"op":"mcm","clk":"11541346021","pt":1719504784903,"mc":[{"id":"1.230180131","rc":[{"atb":[[2.32,12.26],[2.38,5.8]],"id":43210435}],"con":true,"img":false}]}
{"op":"mcm","clk":"11541346127","pt":1719504785998,"mc":[{"id":"1.230180131","rc":[{"atb":[[2.9,5.18]],"id":41138102}],"con":true,"img":false}]}
{"op":"mcm","clk":"11541346141","pt":1719504786103,"mc":[{"id":"1.230180131","rc":[{"atb":[[2.04,0],[2.12,0],[2.44,2.5],[2.36,5],[2.28,10],[2.2,0]],"id":58149406},{"atb":[[2.04,10],[2.94,2],[2.56,0]],"id":41138102},{"atl":[[7.2,0],[8.2,8.82]],"id":41138102},{"atb":[[2.04,20.28],[2.16,8.89]],"id":66499052},{"atb":[[3,0],[2.78,10]],"id":51843546},{"atb":[[1.26,20]],"id":69979297},{"atl":[[2.78,10.14]],"id":69979297}],"con":true,"img":false}]}
{"op":"mcm","clk":"11541346151","pt":1719504786215,"mc":[{"id":"1.230180131","rc":[{"atb":[[2,0],[1.66,10]],"id":58149406},{"atl":[[4.8,0],[4.9,9.94]],"id":58149406},{"atb":[[1.31,0]],"id":69979297},{"atl":[[2.86,0]],"id":69979297}],"con":true,"img":false}]}
{"op":"mcm","clk":"11541346161","pt":1719504786313,"mc":[{"id":"1.230180131","rc":[{"atb":[[1.9,10]],"id":58149406},{"atb":[[2.42,2.11],[2.16,0]],"id":43210435}],"con":true,"img":false}]}
{"op":"mcm","clk":"11541346177","pt":1719504786416,"mc":[{"id":"1.230180131","rc":[{"atb":[[1.66,0]],"id":58149406}],"con":true,"img":false}]}
{"op":"mcm","clk":"11541346183","pt":1719504786523,"mc":[{"id":"1.230180131","rc":[{"atb":[[2.3,5.53]],"id":58149406}],"con":true,"img":false}]}
{"op":"mcm","clk":"11541346192","pt":1719504786628,"mc":[{"id":"1.230180131","rc":[{"atb":[[2.34,2]],"id":58149406},{"atl":[[5.1,9.4]],"id":66499052},{"atl":[[2.6,10.6]],"id":69979297}],"con":true,"img":false}]}
{"op":"mcm","clk":"11541346200","pt":1719504786744,"mc":[{"id":"1.230180131","rc":[{"atl":[[5,5.04]],"id":66499052},{"atl":[[2.7,0.85]],"id":69979297}],"con":true,"img":false}]}
{"op":"mcm","clk":"11541346212","pt":1719504786834,"mc":[{"id":"1.230180131","rc":[{"atl":[[5.8,2.5],[5.5,0.84]],"id":66499052}],"con":true,"img":false}]}
{"op":"mcm","clk":"11541346245","pt":1719504787202,"mc":[{"id":"1.230180131","rc":[{"atb":[[3.4,4.04]],"id":51843546}],"con":true,"img":false}]}
{"op":"mcm","clk":"11541346257","pt":1719504787308,"mc":[{"id":"1.230180131","rc":[{"atb":[[3.5,2]],"id":51843546}],"con":true,"img":false}]}
{"op":"mcm","clk":"11541346266","pt":1719504787417,"mc":[{"id":"1.230180131","rc":[{"atl":[[5.5,0],[4.9,0.84]],"id":66499052},{"atl":[[2.58,0.84],[2.7,0]],"id":69979297}],"con":true,"img":false}]}
{"op":"mcm","clk":"11541346389","pt":1719504788715,"mc":[{"id":"1.230180131","rc":[{"atb":[[2.38,3.8]],"id":43210435}],"con":true,"img":false}]}
{"op":"mcm","clk":"11541346396","pt":1719504788819,"mc":[{"id":"1.230180131","rc":[{"atb":[[2.44,2]],"id":43210435}],"con":true,"img":false}]}
{"op":"mcm","clk":"11541346420","pt":1719504789138,"mc":[{"id":"1.230180131","rc":[{"atb":[[2.34,0]],"id":58149406}],"con":true,"img":false}]}
{"op":"mcm","clk":"11541346430","pt":1719504789238,"mc":[{"id":"1.230180131","rc":[{"atb":[[2.46,2]],"id":58149406}],"con":true,"img":false}]}
{"op":"mcm","clk":"11541346571","pt":1719504790821,"mc":[{"id":"1.230180131","rc":[{"atb":[[2.32,0],[2.44,4.12]],"id":43210435}],"con":true,"img":false}]}
{"op":"mcm","clk":"11541346615","pt":1719504791399,"mc":[{"id":"1.230180131","rc":[{"atb":[[1.81,8.1],[1.9,0]],"id":58149406}],"con":true,"img":false}]}
{"op":"mcm","clk":"11541346651","pt":1719504791820,"mc":[{"id":"1.230180131","rc":[{"atl":[[5.1,15.29],[5,0]],"id":66499052}],"con":true,"img":false}]}
{"op":"mcm","clk":"11541346671","pt":1719504792030,"mc":[{"id":"1.230180131","rc":[{"atb":[[2.04,0],[2.68,5.82]],"id":41138102},{"atl":[[8.2,0],[7.4,7.91]],"id":41138102},{"atb":[[2.3,0]],"id":43210435},{"atb":[[2.04,0],[2.16,17.78]],"id":66499052},{"atb":[[2.78,0],[3.05,5]],"id":51843546},{"atb":[[1.26,0],[1.32,10]],"id":69979297},{"atl":[[2.64,11.45],[2.78,0]],"id":69979297}],"con":true,"img":false}]}
{"op":"mcm","clk":"11541346680","pt":1719504792137,"mc":[{"id":"1.230180131","rc":[{"atb":[[2.04,11.39],[2.16,8.89]],"id":66499052}],"con":true,"img":false}]}
{"op":"mcm","clk":"11541346691","pt":1719504792243,"mc":[{"id":"1.230180131","rc":[{"atb":[[2.04,0],[2.16,13.89]],"id":66499052}],"con":true,"img":false}]}
{"op":"mcm","clk":"11541346705","pt":1719504792406,"mc":[{"id":"1.230180131","rc":[{"atl":[[4.9,0]],"id":66499052}],"con":true,"img":false}]}
{"op":"mcm","clk":"11541346888","pt":1719504794953,"mc":[{"id":"1.230180131","rc":[{"atl":[[5,0.84]],"id":66499052}],"con":true,"img":false}]}
{"op":"mcm","clk":"11541346909","pt":1719504795213,"mc":[{"id":"1.230180131","rc":[{"atb":[[2.46,7.6]],"id":58149406},{"atb":[[2.96,5.49]],"id":41138102},{"atb":[[2.46,5.94]],"id":43210435},{"atb":[[3.5,6.9]],"id":51843546}],"con":true,"img":false}]}
{"op":"mcm","clk":"11541346932","pt":1719504795427,"mc":[{"id":"1.230180131","rc":[{"atb":[[2.3,0]],"id":58149406},{"atb":[[2.9,0]],"id":41138102},{"atb":[[2.36,0]],"id":43210435},{"atb":[[3.4,0]],"id":51843546}],"con":true,"img":false}]}
{"op":"mcm","clk":"11541346963","pt":1719504795842,"mc":[{"id":"1.230180131","rc":[{"atb":[[2.44,2.12]],"id":43210435}],"con":true,"img":false}]}
{"op":"mcm","clk":"11541346973","pt":1719504795940,"mc":[{"id":"1.230180131","rc":[{"atb":[[2.48,2]],"id":43210435}],"con":true,"img":false}]}
{"op":"mcm","clk":"11541346988","pt":1719504796148,"mc":[{"id":"1.230180131","rc":[{"atb":[[2.94,0]],"id":41138102}],"con":true,"img":false}]}
{"op":"mcm","clk":"11541346997","pt":1719504796254,"mc":[{"id":"1.230180131","rc":[{"atb":[[2.98,2]],"id":41138102}],"con":true,"img":false}]}
{"op":"mcm","clk":"11541347006","pt":1719504796355,"mc":[{"id":"1.230180131","rc":[{"atb":[[2.96,0]],"id":41138102}],"con":true,"img":false}]}
{"op":"mcm","clk":"11541347014","pt":1719504796414,"mc":[{"id":"1.230180131","rc":[{"atb":[[3,5.49]],"id":41138102},{"atl":[[2.6,14.15]],"id":69979297}],"con":true,"img":false}]}
{"op":"mcm","clk":"11541347022","pt":1719504796518,"mc":[{"id":"1.230180131","rc":[{"atl":[[2.64,0],[2.58,12.29]],"id":69979297}],"con":true,"img":false}]}
{"op":"mcm","clk":"11541347035","pt":1719504796632,"mc":[{"id":"1.230180131","rc":[{"atb":[[2.44,0],[2.48,4.12]],"id":43210435},{"atb":[[1.38,8.11]],"id":69979297},{"atl":[[2.64,26.45],[2.58,0.84]],"id":69979297}],"con":true,"img":false}]}
{"op":"mcm","clk":"11541347075","pt":1719504797032,"mc":[{"id":"1.230180131","rc":[{"atl":[[5.6,17.14],[5.1,9.4]],"id":66499052}],"con":true,"img":false}]}
{"op":"mcm","clk":"11541347180","pt":1719504798433,"mc":[{"id":"1.230180131","rc":[{"atb":[[2.42,2.11]],"id":58149406}],"con":true,"img":false}]}
{"op":"mcm","clk":"11541347189","pt":1719504798540,"mc":[{"id":"1.230180131","rc":[{"atb":[[2.32,0],[2.18,0]],"id":58149406},{"atb":[[2.92,0],[2.98,0]],"id":41138102},{"atb":[[2.38,0]],"id":43210435},{"atb":[[3.45,0]],"id":51843546}],"con":true,"img":false}]}
{"op":"mcm","clk":"11541347196","pt":1719504798643,"mc":[{"id":"1.230180131","rc":[{"atb":[[3.05,2]],"id":41138102}],"con":true,"img":false}]}
{"op":"mcm","clk":"11541347206","pt":1719504798748,"mc":[{"id":"1.230180131","rc":[{"atb":[[2.48,3.1]],"id":58149406},{"atb":[[3,0],[3.05,9.48]],"id":41138102},{"atb":[[2.5,2.4]],"id":43210435},{"atb":[[3.55,2.3]],"id":51843546},{"atb":[[1.42,4.35]],"id":69979297}],"con":true,"img":false}]}
{"op":"mcm","clk":"11541347213","pt":1719504798851,"mc":[{"id":"1.230180131","rc":[{"atb":[[1.42,20.3]],"id":69979297}],"con":true,"img":false}]}
{"op":"mcm","clk":"11541347222","pt":1719504798954,"mc":[{"id":"1.230180131","rc":[{"atb":[[1.41,4.11]],"id":69979297}],"con":true,"img":false}]}
{"op":"mcm","clk":"11541347243","pt":1719504799217,"mc":[{"id":"1.230180131","rc":[{"atl":[[5,11.64]],"id":66499052},{"atl":[[2.34,16.7]],"id":69979297}],"con":true,"img":false}]}
{"op":"mcm","clk":"11541347253","pt":1719504799322,"mc":[{"id":"1.230180131","rc":[{"atl":[[2.32,14.15],[2.64,0]],"id":69979297}],"con":true,"img":false}]}
{"op":"mcm","clk":"11541347263","pt":1719504799424,"mc":[{"id":"1.230180131","rc":[{"atb":[[2.48,2.12]],"id":43210435},{"atl":[[5.1,0]],"id":66499052},{"atl":[[2.6,3.55]],"id":69979297}],"con":true,"img":false}]}
{"op":"mcm","clk":"11541347272","pt":1719504799529,"mc":[{"id":"1.230180131","rc":[{"atb":[[2.52,2]],"id":43210435}],"con":true,"img":false}]}
{"op":"mcm","clk":"11541347278","pt":1719504799631,"mc":[{"id":"1.230180131","rc":[{"atb":[[2.48,0],[2.52,4.12]],"id":43210435}],"con":true,"img":false}]}
{"op":"mcm","clk":"11541347288","pt":1719504799735,"mc":[{"id":"1.230180131","rc":[{"atb":[[1.41,2.11]],"id":69979297}],"con":true,"img":false}]}
{"op":"mcm","clk":"11541347299","pt":1719504799837,"mc":[{"id":"1.230180131","rc":[{"atb":[[1.43,2]],"id":69979297}],"con":true,"img":false}]}
{"op":"mcm","clk":"11541347309","pt":1719504799941,"mc":[{"id":"1.230180131","rc":[{"atl":[[2.3,0.84],[2.58,0]],"id":69979297}],"con":true,"img":false}]}
{"op":"mcm","clk":"11541347324","pt":1719504800158,"mc":[{"id":"1.230180131","rc":[{"atb":[[2.46,5.6]],"id":58149406}],"con":true,"img":false}]}
{"op":"mcm","clk":"11541347333","pt":1719504800252,"mc":[{"id":"1.230180131","rc":[{"atb":[[2.5,2]],"id":58149406},{"atl":[[2.6,0]],"id":69979297}],"con":true,"img":false}]}
{"op":"mcm","clk":"11541347373","pt":1719504800721,"mc":[{"id":"1.230180131","rc":[{"atb":[[3.5,4.9]],"id":51843546},{"atb":[[1.38,2.5]],"id":69979297}],"con":true,"img":false}]}
{"op":"mcm","clk":"11541347384","pt":1719504800825,"mc":[{"id":"1.230180131","rc":[{"atb":[[3.6,2]],"id":51843546}],"con":true,"img":false}]}
{"op":"mcm","clk":"11541347683","pt":1719504804424,"mc":[{"id":"1.230180131","rc":[{"spn":3.55,"spf":"NaN","id":58149406},{"spn":4.82,"spf":"NaN","id":41138102},{"spn":4.66,"spf":"NaN","id":43210435},{"spn":3.58,"spf":"NaN","id":66499052},{"spn":5.9,"spf":"NaN","id":51843546},{"atl":[[2.32,0],[2.34,31.7]],"id":69979297},{"spn":1.86,"spf":"NaN","id":69979297}],"con":true,"img":false}]}
{"op":"mcm","clk":"11541347726","pt":1719504804939,"mc":[{"id":"1.230180131","rc":[{"atl":[[2.3,0]],"id":69979297}],"con":true,"img":false}]}
{"op":"mcm","clk":"11541347827","pt":1719504806137,"mc":[{"id":"1.230180131","rc":[{"atb":[[2.44,6.33]],"id":58149406},{"atb":[[2.46,9.79]],"id":43210435},{"atb":[[2.06,4.94]],"id":66499052}],"con":true,"img":false}]}
{"op":"mcm","clk":"11541347898","pt":1719504806916,"mc":[{"id":"1.230180131","rc":[{"atl":[[2.32,0.84]],"id":69979297}],"con":true,"img":false}]}
{"op":"mcm","clk":"11541347951","pt":1719504807647,"mc":[{"id":"1.230180131","rc":[{"atb":[[2.5,8.05]],"id":58149406},{"atb":[[3.6,7.55]],"id":51843546}],"con":true,"img":false}]}
{"op":"mcm","clk":"11541347962","pt":1719504807750,"mc":[{"id":"1.230180131","rc":[{"atb":[[2.54,6.36]],"id":43210435}],"con":true,"img":false}]}
{"op":"mcm","clk":"11541347972","pt":1719504807853,"mc":[{"id":"1.230180131","rc":[{"atb":[[2.46,0]],"id":58149406},{"atb":[[2.56,4.12],[2.52,2],[2.46,3.85]],"id":43210435},{"atb":[[3.5,0]],"id":51843546}],"con":true,"img":false}]}
{"op":"mcm","clk":"11541347978","pt":1719504807957,"mc":[{"id":"1.230180131","rc":[{"atb":[[2.56,0],[2.52,12.48]],"id":43210435}],"con":true,"img":false}]}
{"op":"mcm","clk":"11541348021","pt":1719504808536,"mc":[{"id":"1.230180131","rc":[{"atb":[[2.52,10.48]],"id":43210435}],"con":true,"img":false}]}
{"op":"mcm","clk":"11541348029","pt":1719504808638,"mc":[{"id":"1.230180131","rc":[{"atb":[[2.58,2]],"id":43210435}],"con":true,"img":false}]}
{"op":"mcm","clk":"11541348037","pt":1719504808737,"mc":[{"id":"1.230180131","rc":[{"atb":[[2.44,2.5]],"id":58149406},{"atb":[[2.46,0]],"id":43210435}],"con":true,"img":false}]}
{"op":"mcm","clk":"11541348046","pt":1719504808841,"mc":[{"id":"1.230180131","rc":[{"atb":[[2.58,8.36],[2.52,0]],"id":43210435}],"con":true,"img":false}]}
{"op":"mcm","clk":"11541348056","pt":1719504808949,"mc":[{"id":"1.230180131","rc":[{"atb":[[2.58,2],[2.52,8.36]],"id":43210435}],"con":true,"img":false}]}
{"op":"mcm","clk":"11541348107","pt":1719504809570,"mc":[{"id":"1.230180131","rc":[{"atb":[[2.58,0]],"id":43210435},{"atl":[[2.64,32.55],[2.34,16.7]],"id":69979297}],"con":true,"img":false}]}
{"op":"mcm","clk":"11541348117","pt":1719504809619,"mc":[{"id":"1.230180131","rc":[{"atb":[[2.56,2]],"id":43210435}],"con":true,"img":false}]}
{"op":"mcm","clk":"11541348123","pt":1719504809724,"mc":[{"id":"1.230180131","rc":[{"atb":[[2.56,8.36],[2.52,0]],"id":43210435}],"con":true,"img":false}]}
{"op":"mcm","clk":"11541348229","pt":1719504811127,"mc":[{"id":"1.230180131","rc":[{"atb":[[1.43,16.12]],"id":69979297}],"con":true,"img":false}]}
{"op":"mcm","clk":"11541348237","pt":1719504811233,"mc":[{"id":"1.230180131","rc":[{"atb":[[1.42,4.35]],"id":69979297}],"con":true,"img":false}]}
{"op":"mcm","clk":"11541348277","pt":1719504811641,"mc":[{"id":"1.230180131","rc":[{"atl":[[2.32,16.19]],"id":69979297}],"con":true,"img":false}]}
{"op":"mcm","clk":"11541348288","pt":1719504811746,"mc":[{"id":"1.230180131","rc":[{"atl":[[7.4,6.91],[7.6,6]],"id":41138102},{"atl":[[7.4,10],[7.6,1]],"id":43210435},{"atl":[[5.6,16.14],[5.7,1]],"id":66499052},{"atl":[[11.5,5],[12,1]],"id":51843546},{"atb":[[1.25,0]],"id":69979297},{"atl":[[2.72,1],[2.74,0]],"id":69979297}],"con":true,"img":false}]}
{"op":"mcm","clk":"11541348295","pt":1719504811851,"mc":[{"id":"1.230180131","rc":[{"atl":[[2.34,0],[2.7,1]],"id":69979297}],"con":true,"img":false}]}
{"op":"mcm","clk":"11541348315","pt":1719504812161,"mc":[{"id":"1.230180131","rc":[{"atl":[[2.72,0]],"id":69979297}],"con":true,"img":false}]}
{"op":"mcm","clk":"11541348348","pt":1719504812576,"mc":[{"id":"1.230180131","rc":[{"atb":[[2.48,0]],"id":58149406},{"atl":[[4.6,5.96],[4.7,0]],"id":58149406},{"atb":[[3.05,7.18]],"id":41138102},{"atl":[[7.6,5],[7.8,1]],"id":41138102},{"atb":[[2.5,0]],"id":43210435},{"atl":[[7.6,0],[7.8,1]],"id":43210435},{"atl":[[5.5,1],[5.7,0]],"id":66499052},{"atb":[[3.55,0]],"id":51843546},{"atb":[[1.42,0]],"id":69979297}],"con":true,"img":false}]}
{"op":"mcm","clk":"11541348356","pt":1719504812640,"mc":[{"id":"1.230180131","rc":[{"atb":[[2.52,2.05]],"id":58149406},{"atl":[[4.9,0],[5.4,18.41]],"id":58149406},{"atb":[[2.58,2.3]],"id":43210435},{"atb":[[3.65,2.7]],"id":51843546}],"con":true,"img":false}]}
{"op":"mcm","clk":"11541348491","pt":1719504814546,"mc":[{"id":"1.230180131","rc":[{"atb":[[2.56,6.36]],"id":43210435}],"con":true,"img":false}]}
{"op":"mcm","clk":"11541348496","pt":1719504814648,"mc":[{"id":"1.230180131","rc":[{"atb":[[2.6,2]],"id":43210435}],"con":true,"img":false}]}
{"op":"mcm","clk":"11541348524","pt":1719504815061,"mc":[{"id":"1.230180131","rc":[{"atb":[[2.5,6.05]],"id":58149406}],"con":true,"img":false}]}
{"op":"mcm","clk":"11541348530","pt":1719504815165,"mc":[{"id":"1.230180131","rc":[{"atb":[[2.54,2]],"id":58149406},{"atl":[[2.56,32.4],[2.64,0]],"id":69979297}],"con":true,"img":false}]}
{"op":"mcm","clk":"11541348546","pt":1719504815373,"mc":[{"id":"1.230180131","rc":[{"atb":[[2.6,4.3],[2.56,0]],"id":43210435}],"con":true,"img":false}]}
{"op":"mcm","clk":"11541348555","pt":1719504815426,"mc":[{"id":"1.230180131","rc":[{"atb":[[3.6,5.55]],"id":51843546}],"con":true,"img":false}]}
{"op":"mcm","clk":"11541348564","pt":1719504815530,"mc":[{"id":"1.230180131","rc":[{"atb":[[3.7,2]],"id":51843546}],"con":true,"img":false}]}
{"op":"mcm","clk":"11541348738","pt":1719504817758,"mc":[{"id":"1.230180131","rc":[{"atl":[[5.8,25.83],[5.4,2.5]],"id":58149406}],"con":true,"img":false}]}
{"op":"mcm","clk":"11541348935","pt":1719504819834,"mc":[{"id":"1.230180131","rc":[{"atb":[[2.54,8.35]],"id":58149406},{"atb":[[2.62,6.5]],"id":43210435},{"atb":[[3.7,7.97]],"id":51843546}],"con":true,"img":false}]}
{"op":"mcm","clk":"11541348944","pt":1719504819937,"mc":[{"id":"1.230180131","rc":[{"atb":[[2.6,2],[2.64,4.3]],"id":43210435}],"con":true,"img":false}]}
{"op":"mcm","clk":"11541348950","pt":1719504820041,"mc":[{"id":"1.230180131","rc":[{"atb":[[2.5,0]],"id":58149406},{"atb":[[2.54,0],[2.64,0],[2.6,12.8]],"id":43210435},{"atb":[[3.6,0]],"id":51843546}],"con":true,"img":false}]}
{"op":"mcm","clk":"11541348994","pt":1719504820663,"mc":[{"id":"1.230180131","rc":[{"atl":[[2.34,4.25]],"id":69979297}],"con":true,"img":false}]}
{"op":"mcm","clk":"11541349004","pt":1719504820766,"mc":[{"id":"1.230180131","rc":[{"atb":[[1.37,5.61]],"id":69979297}],"con":true,"img":false}]}
{"op":"mcm","clk":"11541349026","pt":1719504821083,"mc":[{"id":"1.230180131","rc":[{"atb":[[2.6,10.8]],"id":43210435}],"con":true,"img":false}]}
{"op":"mcm","clk":"11541349037","pt":1719504821178,"mc":[{"id":"1.230180131","rc":[{"atb":[[2.64,2]],"id":43210435}],"con":true,"img":false}]}
{"op":"mcm","clk":"11541349074","pt":1719504821543,"mc":[{"id":"1.230180131","rc":[{"atb":[[2.52,0]],"id":58149406},{"atb":[[2.58,0]],"id":43210435},{"atb":[[3.65,0]],"id":51843546}],"con":true,"img":false}]}
{"op":"mcm","clk":"11541349083","pt":1719504821648,"mc":[{"id":"1.230180131","rc":[{"atb":[[2.56,2.9]],"id":58149406},{"atb":[[2.64,4.3]],"id":43210435},{"atb":[[3.75,2.93]],"id":51843546}],"con":true,"img":false}]}
{"op":"mcm","clk":"11541349141","pt":1719504822478,"mc":[{"id":"1.230180131","rc":[{"atb":[[2.54,6.35]],"id":58149406}],"con":true,"img":false}]}
{"op":"mcm","clk":"11541349151","pt":1719504822580,"mc":[{"id":"1.230180131","rc":[{"atb":[[1.02,2]],"id":58149406}],"con":true,"img":false}]}
{"op":"mcm","clk":"11541349181","pt":1719504822892,"mc":[{"id":"1.230180131","rc":[{"atb":[[3.7,5.97]],"id":51843546},{"atb":[[1.41,0],[1.46,2.11]],"id":69979297}],"con":true,"img":false}]}
{"op":"mcm","clk":"11541349189","pt":1719504822940,"mc":[{"id":"1.230180131","rc":[{"atb":[[3.8,2]],"id":51843546}],"con":true,"img":false}]}
{"op":"mcm","clk":"11541349258","pt":1719504823778,"mc":[{"id":"1.230180131","rc":[{"atl":[[2.3,15.28]],"id":69979297}],"con":true,"img":false}]}
{"op":"mcm","clk":"11541349268","pt":1719504823888,"mc":[{"id":"1.230180131","rc":[{"atb":[[1.43,14.12]],"id":69979297},{"atl":[[2.56,0],[2.32,0.84],[2.34,36.65]],"id":69979297}],"con":true,"img":false}]}
{"op":"mcm","clk":"11541349278","pt":1719504823985,"mc":[{"id":"1.230180131","rc":[{"atb":[[1.47,2]],"id":69979297}],"con":true,"img":false}]}
{"op":"mcm","clk":"11541349324","pt":1719504824460,"mc":[{"id":"1.230180131","rc":[{"atl":[[2.28,0.84]],"id":69979297}],"con":true,"img":false}]}
{"op":"mcm","clk":"11541349355","pt":1719504824761,"mc":[{"id":"1.230180131","rc":[{"atb":[[3.1,2.5],[2.88,10],[2.96,5]],"id":41138102},{"atl":[[5.6,26.14],[4.8,2.5],[5.8,0],[5.2,5]],"id":66499052}],"con":true,"img":false}]}
{"op":"mcm","clk":"11541349363","pt":1719504824865,"mc":[{"id":"1.230180131","rc":[{"atb":[[2.8,0],[2.72,0],[3.1,9.56]],"id":41138102},{"atl":[[4.8,14.94],[5.6,10],[5.2,28.3]],"id":66499052},{"atl":[[2.34,32.4]],"id":69979297}],"con":true,"img":false}]}
{"op":"mcm","clk":"11541349376","pt":1719504825077,"mc":[{"id":"1.230180131","rc":[{"atb":[[3.05,2]],"id":41138102},{"atl":[[5,0.84]],"id":66499052}],"con":true,"img":false}]}
{"op":"mcm","clk":"11541349397","pt":1719504825385,"mc":[{"id":"1.230180131","rc":[{"atl":[[4.7,0.84]],"id":66499052}],"con":true,"img":false}]}
{"op":"mcm","clk":"11541349407","pt":1719504825483,"mc":[{"id":"1.230180131","rc":[{"atl":[[5,0]],"id":66499052}],"con":true,"img":false}]}
{"op":"mcm","clk":"11541349425","pt":1719504825688,"mc":[{"id":"1.230180131","rc":[{"atb":[[2.6,0],[2.66,6.5]],"id":43210435}],"con":true,"img":false}]}
{"op":"mcm","clk":"11541349481","pt":1719504826364,"mc":[{"id":"1.230180131","rc":[{"atb":[[2.64,2.3]],"id":43210435}],"con":true,"img":false}]}
{"op":"mcm","clk":"11541349489","pt":1719504826474,"mc":[{"id":"1.230180131","rc":[{"atb":[[2.64,15.3],[2.66,0],[2.68,2]],"id":43210435}],"con":true,"img":false}]}
{"op":"mcm","clk":"11541349520","pt":1719504826879,"mc":[{"id":"1.230180131","rc":[{"atb":[[3.05,0]],"id":41138102}],"con":true,"img":false}]}
{"op":"mcm","clk":"11541349531","pt":1719504826982,"mc":[{"id":"1.230180131","rc":[{"atb":[[3.15,2]],"id":41138102}],"con":true,"img":false}]}
{"op":"mcm","clk":"11541349618","pt":1719504827967,"mc":[{"id":"1.230180131","rc":[{"atb":[[2.68,0]],"id":43210435}],"con":true,"img":false}]}
{"op":"mcm","clk":"11541349627","pt":1719504828070,"mc":[{"id":"1.230180131","rc":[{"atb":[[2.66,2]],"id":43210435}],"con":true,"img":false}]}
{"op":"mcm","clk":"11541349696","pt":1719504828852,"mc":[{"id":"1.230180131","rc":[{"atb":[[2.06,0]],"id":66499052}],"con":true,"img":false}]}
{"op":"mcm","clk":"11541349771","pt":1719504829796,"mc":[{"id":"1.230180131","rc":[{"atb":[[2.6,3.52]],"id":43210435}],"con":true,"img":false}]}
{"op":"mcm","clk":"11541349779","pt":1719504829891,"mc":[{"id":"1.230180131","rc":[{"atb":[[2.64,13]],"id":43210435},{"atb":[[3.75,0]],"id":51843546}],"con":true,"img":false}]}
{"op":"mcm","clk":"11541349790","pt":1719504830000,"mc":[{"id":"1.230180131","rc":[{"atb":[[3.15,4.62]],"id":41138102},{"atb":[[2.66,4.51]],"id":43210435},{"atb":[[2.04,5.04]],"id":66499052},{"atb":[[3.8,5]],"id":51843546}],"con":true,"img":false}]}
{"op":"mcm","clk":"11541349934","pt":1719504831770,"mc":[{"id":"1.230180131","rc":[{"atb":[[2.56,9.55]],"id":58149406},{"atb":[[2.66,12.77]],"id":43210435}],"con":true,"img":false}]}
{"op":"mcm","clk":"11541349951","pt":1719504831984,"mc":[{"id":"1.230180131","rc":[{"atb":[[2.54,0]],"id":58149406},{"atb":[[2.64,0],[2.62,0],[2.68,12.77]],"id":43210435}],"con":true,"img":false}]}
{"op":"mcm","clk":"11541349983","pt":1719504832382,"mc":[{"id":"1.230180131","rc":[{"atb":[[2.6,0]],"id":43210435}],"con":true,"img":false}]}
{"op":"mcm","clk":"11541350010","pt":1719504832691,"mc":[{"id":"1.230180131","rc":[{"atb":[[2.66,10.77]],"id":43210435}],"con":true,"img":false}]}
{"op":"mcm","clk":"11541350019","pt":1719504832794,"mc":[{"id":"1.230180131","rc":[{"atb":[[2.7,2]],"id":43210435}],"con":true,"img":false}]}
{"op":"mcm","clk":"11541350026","pt":1719504832849,"mc":[{"id":"1.230180131","rc":[{"atb":[[2.04,0]],"id":66499052},{"atb":[[1.37,0]],"id":69979297}],"con":true,"img":false}]}
{"op":"mcm","clk":"11541350040","pt":1719504833059,"mc":[{"id":"1.230180131","rc":[{"atl":[[9.6,15],[11,10],[11.5,0],[9.8,0],[8.8,2.5]],"id":51843546}],"con":true,"img":false}]}
{"op":"mcm","clk":"11541350059","pt":1719504833373,"mc":[{"id":"1.230180131","rc":[{"atb":[[2.54,3.59]],"id":58149406}],"con":true,"img":false}]}
{"op":"mcm","clk":"11541350068","pt":1719504833481,"mc":[{"id":"1.230180131","rc":[{"atb":[[3.8,13.27]],"id":51843546}],"con":true,"img":false}]}
{"op":"mcm","clk":"11541350210","pt":1719504835602,"mc":[{"id":"1.230180131","rc":[{"atl":[[2.28,3.93]],"id":69979297}],"con":true,"img":false}]}
{"op":"mcm","clk":"11541350217","pt":1719504835701,"mc":[{"id":"1.230180131","rc":[{"atl":[[2.26,3.94],[2.34,0]],"id":69979297}],"con":true,"img":false}]}
{"op":"mcm","clk":"11541350223","pt":1719504835752,"mc":[{"id":"1.230180131","rc":[{"atl":[[2.3,7.88],[2.26,0]],"id":69979297}],"con":true,"img":false}]}
{"op":"mcm","clk":"11541350270","pt":1719504836485,"mc":[{"id":"1.230180131","rc":[{"atl":[[2.32,0]],"id":69979297}],"con":true,"img":false}]}
{"op":"mcm","clk":"11541350286","pt":1719504836687,"mc":[{"id":"1.230180131","rc":[{"atb":[[3.15,11.84]],"id":41138102},{"atl":[[4.7,13.13]],"id":66499052}],"con":true,"img":false}]}
{"op":"mcm","clk":"11541350292","pt":1719504836793,"mc":[{"id":"1.230180131","rc":[{"atb":[[3.1,2.5]],"id":41138102},{"atl":[[4.8,2.5],[4.6,14.94],[5.2,5]],"id":66499052}],"con":true,"img":false}]}
{"op":"mcm","clk":"11541350302","pt":1719504836893,"mc":[{"id":"1.230180131","rc":[{"atl":[[4.8,28.82],[4.6,0]],"id":66499052}],"con":true,"img":false}]}
{"op":"mcm","clk":"11541350413","pt":1719504838705,"mc":[{"id":"1.230180131","rc":[{"atb":[[3.15,9.22]],"id":41138102},{"atb":[[2.66,8.26]],"id":43210435},{"atb":[[3.8,10.27]],"id":51843546}],"con":true,"img":false}]}
{"op":"mcm","clk":"11541350418","pt":1719504838810,"mc":[{"id":"1.230180131","rc":[{"atb":[[3.2,2.67]],"id":41138102},{"atb":[[2.7,5.7]],"id":43210435},{"atb":[[3.85,2.9]],"id":51843546}],"con":true,"img":false}]}
{"op":"mcm","clk":"11541350429","pt":1719504838862,"mc":[{"id":"1.230180131","rc":[{"atb":[[2.72,8.26],[2.68,0]],"id":43210435}],"con":true,"img":false}]}
{"op":"mcm","clk":"11541350455","pt":1719504839172,"mc":[{"id":"1.230180131","rc":[{"atb":[[3.15,7.22]],"id":41138102}],"con":true,"img":false}]}
{"op":"mcm","clk":"11541350464","pt":1719504839277,"mc":[{"id":"1.230180131","rc":[{"atb":[[3.25,2]],"id":41138102}],"con":true,"img":false}]}
{"op":"mcm","clk":"11541350491","pt":1719504839587,"mc":[{"id":"1.230180131","rc":[{"atb":[[3.8,8.27]],"id":51843546}],"con":true,"img":false}]}
{"op":"mcm","clk":"11541350503","pt":1719504839689,"mc":[{"id":"1.230180131","rc":[{"atb":[[3.9,2]],"id":51843546}],"con":true,"img":false}]}
{"op":"mcm","clk":"11541350512","pt":1719504839792,"mc":[{"id":"1.230180131","rc":[{"atb":[[3.8,0]],"id":51843546}],"con":true,"img":false}]}
{"op":"mcm","clk":"11541350518","pt":1719504839897,"mc":[{"id":"1.230180131","rc":[{"atb":[[2.5,2.5],[2.44,0],[2.36,0],[2.42,7.11],[2.28,0]],"id":58149406}],"con":true,"img":false}]}
{"op":"mcm","clk":"11541350527","pt":1719504839999,"mc":[{"id":"1.230180131","rc":[{"atb":[[1.03,14.39],[1.04,1.7]],"id":41138102},{"atl":[[1000,6.98]],"id":41138102}],"con":true,"img":false}]}
{"op":"mcm","clk":"11541350541","pt":1719504840213,"mc":[{"id":"1.230180131","rc":[{"atb":[[1.04,0.07]],"id":41138102},{"atl":[[1000,5.31]],"id":41138102}],"con":true,"img":false}]}
{"op":"mcm","clk":"11541350550","pt":1719504840319,"mc":[{"id":"1.230180131","rc":[{"atb":[[1.03,11.16],[1.04,0]],"id":41138102},{"atl":[[1000,0.31]],"id":41138102}],"con":true,"img":false}]}
{"op":"mcm","clk":"11541350558","pt":1719504840366,"mc":[{"id":"1.230180131","rc":[{"atb":[[3.3,0.07]],"id":41138102},{"atl":[[1000,0.28]],"id":41138102}],"con":true,"img":false}]}
{"op":"mcm","clk":"11541350565","pt":1719504840471,"mc":[{"id":"1.230180131","rc":[{"atb":[[1.03,10.99]],"id":41138102},{"atl":[[6.4,0.03],[1000,0.17]],"id":41138102},{"atb":[[3.9,10.92]],"id":51843546}],"con":true,"img":false}]}
{"op":"mcm","clk":"11541350576","pt":1719504840581,"mc":[{"id":"1.230180131","rc":[{"atb":[[3.3,0.24]],"id":41138102},{"atl":[[6.4,3.51]],"id":41138102}],"con":true,"img":false}]}
{"op":"mcm","clk":"11541350584","pt":1719504840679,"mc":[{"id":"1.230180131","rc":[{"atl":[[7.4,0],[7,5]],"id":41138102}],"con":true,"img":false}]}
{"op":"mcm","clk":"11541350592","pt":1719504840781,"mc":[{"id":"1.230180131","rc":[{"atl":[[6.6,0.84]],"id":41138102}],"con":true,"img":false}]}
{"op":"mcm","clk":"11541350599","pt":1719504840886,"mc":[{"id":"1.230180131","rc":[{"atl":[[2.56,11.82],[2.3,0]],"id":69979297}],"con":true,"img":false}]}
{"op":"mcm","clk":"11541350636","pt":1719504841312,"mc":[{"id":"1.230180131","rc":[{"atb":[[2.7,3.7]],"id":43210435}],"con":true,"img":false}]}
{"op":"mcm","clk":"11541350646","pt":1719504841410,"mc":[{"id":"1.230180131","rc":[{"atl":[[6.2,0.84]],"id":41138102},{"atb":[[2.74,2]],"id":43210435}],"con":true,"img":false}]}
{"op":"mcm","clk":"11541350658","pt":1719504841515,"mc":[{"id":"1.230180131","rc":[{"atb":[[3.3,10.88]],"id":41138102},{"atl":[[6.4,8.21]],"id":41138102}],"con":true,"img":false}]}
{"op":"mcm","clk":"11541350737","pt":1719504842296,"mc":[{"id":"1.230180131","rc":[{"atb":[[3.25,0]],"id":41138102}],"con":true,"img":false}]}
{"op":"mcm","clk":"11541350748","pt":1719504842403,"mc":[{"id":"1.230180131","rc":[{"atb":[[3.35,2]],"id":41138102}],"con":true,"img":false}]}
{"op":"mcm","clk":"11541350854","pt":1719504843397,"mc":[{"id":"1.230180131","rc":[{"atb":[[3.3,8.82]],"id":41138102}],"con":true,"img":false}]}
{"op":"mcm","clk":"11541350867","pt":1719504843512,"mc":[{"id":"1.230180131","rc":[{"atb":[[2.74,8.04]],"id":43210435}],"con":true,"img":false}]}
{"op":"mcm","clk":"11541350875","pt":1719504843607,"mc":[{"id":"1.230180131","rc":[{"atb":[[3.3,0.24]],"id":41138102},{"atb":[[2.66,0]],"id":43210435}],"con":true,"img":false}]}
{"op":"mcm","clk":"11541350885","pt":1719504843712,"mc":[{"id":"1.230180131","rc":[{"atb":[[3.35,10.58]],"id":41138102},{"atl":[[2.3,4.38]],"id":69979297}],"con":true,"img":false}]}
{"op":"mcm","clk":"11541350915","pt":1719504843974,"mc":[{"id":"1.230180131","rc":[{"atb":[[3.35,8.58]],"id":41138102}],"con":true,"img":false}]}
{"op":"mcm","clk":"11541350924","pt":1719504844079,"mc":[{"id":"1.230180131","rc":[{"atb":[[3.25,2]],"id":41138102}],"con":true,"img":false}]}
{"op":"mcm","clk":"11541350993","pt":1719504844808,"mc":[{"id":"1.230180131","rc":[{"atb":[[1.37,5.61]],"id":69979297}],"con":true,"img":false}]}
{"op":"mcm","clk":"11541351104","pt":1719504846103,"mc":[{"id":"1.230180131","rc":[{"atb":[[3.25,0]],"id":41138102}],"con":true,"img":false}]}
{"op":"mcm","clk":"11541351110","pt":1719504846208,"mc":[{"id":"1.230180131","rc":[{"atb":[[3.4,2]],"id":41138102}],"con":true,"img":false}]}
{"op":"mcm","clk":"11541351145","pt":1719504846624,"mc":[{"id":"1.230180131","rc":[{"atb":[[3.35,0]],"id":41138102}],"con":true,"img":false}]}
{"op":"mcm","clk":"11541351186","pt":1719504847187,"mc":[{"id":"1.230180131","rc":[{"atb":[[3.4,0]],"id":41138102}],"con":true,"img":false}]}
{"op":"mcm","clk":"11541351200","pt":1719504847298,"mc":[{"id":"1.230180131","rc":[{"atb":[[3.25,12.04]],"id":41138102}],"con":true,"img":false}]}
{"op":"mcm","clk":"11541351218","pt":1719504847508,"mc":[{"id":"1.230180131","rc":[{"atb":[[2.7,0]],"id":43210435},{"atb":[[3.85,0]],"id":51843546}],"con":true,"img":false}]}
{"op":"mcm","clk":"11541351229","pt":1719504847604,"mc":[{"id":"1.230180131","rc":[{"atb":[[2.76,3.6]],"id":43210435},{"atb":[[3.95,3]],"id":51843546}],"con":true,"img":false}]}
{"op":"mcm","clk":"11541351236","pt":1719504847709,"mc":[{"id":"1.230180131","rc":[{"atb":[[2.72,0],[2.78,8.04]],"id":43210435}],"con":true,"img":false}]}
{"op":"mcm","clk":"11541351297","pt":1719504848280,"mc":[{"id":"1.230180131","rc":[{"atb":[[3.3,2.88]],"id":41138102},{"atl":[[4.6,13.6]],"id":66499052},{"atb":[[3.9,9.56]],"id":51843546}],"con":true,"img":false}]}
{"op":"mcm","clk":"11541351309","pt":1719504848386,"mc":[{"id":"1.230180131","rc":[{"atb":[[3.15,0]],"id":41138102},{"atl":[[4.7,0.84]],"id":66499052}],"con":true,"img":false}]}
{"op":"mcm","clk":"11541351319","pt":1719504848495,"mc":[{"id":"1.230180131","rc":[{"atb":[[3.9,2]],"id":51843546}],"con":true,"img":false}]}
{"op":"mcm","clk":"11541351328","pt":1719504848591,"mc":[{"id":"1.230180131","rc":[{"atb":[[3.95,10.56]],"id":51843546}],"con":true,"img":false}]}
{"op":"mcm","clk":"11541351345","pt":1719504848801,"mc":[{"id":"1.230180131","rc":[{"atb":[[2.74,6.04]],"id":43210435}],"con":true,"img":false}]}
{"op":"mcm","clk":"11541351357","pt":1719504848905,"mc":[{"id":"1.230180131","rc":[{"atb":[[2.8,2]],"id":43210435},{"atl":[[4.5,0.84]],"id":66499052}],"con":true,"img":false}]}
{"op":"mcm","clk":"11541351377","pt":1719504849110,"mc":[{"id":"1.230180131","rc":[{"atb":[[3.25,2]],"id":41138102}],"con":true,"img":false}]}
{"op":"mcm","clk":"11541351389","pt":1719504849225,"mc":[{"id":"1.230180131","rc":[{"atb":[[3.25,0]],"id":41138102}],"con":true,"img":false}]}
{"op":"mcm","clk":"11541351400","pt":1719504849321,"mc":[{"id":"1.230180131","rc":[{"atb":[[3.35,2]],"id":41138102}],"con":true,"img":false}]}
{"op":"mcm","clk":"11541351431","pt":1719504849586,"mc":[{"id":"1.230180131","rc":[{"atb":[[3.9,0]],"id":51843546}],"con":true,"img":false}]}
{"op":"mcm","clk":"11541351443","pt":1719504849683,"mc":[{"id":"1.230180131","rc":[{"atb":[[4,2]],"id":51843546}],"con":true,"img":false}]}
{"op":"mcm","clk":"11541351480","pt":1719504850096,"mc":[{"id":"1.230180131","rc":[{"atb":[[3.35,11.23]],"id":41138102}],"con":true,"img":false}]}
{"op":"mcm","clk":"11541351558","pt":1719504850928,"mc":[{"id":"1.230180131","rc":[{"atb":[[3.95,3]],"id":51843546}],"con":true,"img":false}]}
{"op":"mcm","clk":"11541351667","pt":1719504852137,"mc":[{"id":"1.230180131","rc":[{"atl":[[6.2,5.01]],"id":41138102}],"con":true,"img":false}]}
{"op":"mcm","clk":"11541351687","pt":1719504852292,"mc":[{"id":"1.230180131","rc":[{"atl":[[6.4,4.83]],"id":41138102},{"atb":[[2.72,3.28]],"id":43210435}],"con":true,"img":false}]}
{"op":"mcm","clk":"11541351707","pt":1719504852499,"mc":[{"id":"1.230180131","rc":[{"atb":[[2.04,5.08]],"id":66499052}],"con":true,"img":false}]}
{"op":"mcm","clk":"11541351738","pt":1719504852809,"mc":[{"id":"1.230180131","rc":[{"atb":[[2.48,10],[2.68,0]],"id":41138102},{"atl":[[7.4,9.68],[7,0]],"id":41138102},{"atb":[[4,9.52],[3.7,0]],"id":51843546}],"con":true,"img":false}]}
{"op":"mcm","clk":"11541351758","pt":1719504853011,"mc":[{"id":"1.230180131","rc":[{"atl":[[6.6,0]],"id":41138102}],"con":true,"img":false}]}
{"op":"mcm","clk":"11541351815","pt":1719504853588,"mc":[{"id":"1.230180131","rc":[{"atl":[[6.4,4.07]],"id":41138102}],"con":true,"img":false}]}
{"op":"mcm","clk":"11541351826","pt":1719504853695,"mc":[{"id":"1.230180131","rc":[{"atb":[[1.92,10.71]],"id":58149406}],"con":true,"img":false}]}
{"op":"mcm","clk":"11541351835","pt":1719504853793,"mc":[{"id":"1.230180131","rc":[{"atb":[[1.81,0]],"id":58149406}],"con":true,"img":false}]}
{"op":"mcm","clk":"11541351867","pt":1719504854209,"mc":[{"id":"1.230180131","rc":[{"atl":[[6.4,0.13]],"id":41138102}],"con":true,"img":false}]}
{"op":"mcm","clk":"11541351925","pt":1719504854935,"mc":[{"id":"1.230180131","rc":[{"atb":[[2.8,7.97]],"id":43210435}],"con":true,"img":false}]}
{"op":"mcm","clk":"11541351933","pt":1719504855040,"mc":[{"id":"1.230180131","rc":[{"atl":[[6.2,8.87]],"id":41138102},{"atb":[[2.8,15.94],[2.72,0],[2.78,0]],"id":43210435}],"con":true,"img":false}]}
{"op":"mcm","clk":"11541351940","pt":1719504855087,"mc":[{"id":"1.230180131","rc":[{"atb":[[2.8,7.97],[2.74,0],[2.78,15.94]],"id":43210435}],"con":true,"img":false}]}
{"op":"mcm","clk":"11541352055","pt":1719504856437,"mc":[{"id":"1.230180131","rc":[{"atb":[[3.2,0]],"id":41138102},{"atb":[[2.76,0]],"id":43210435},{"atb":[[3.95,0]],"id":51843546}],"con":true,"img":false}]}
{"op":"mcm","clk":"11541352076","pt":1719504856591,"mc":[{"id":"1.230180131","rc":[{"atb":[[2.82,3.83]],"id":43210435},{"atb":[[4.1,2.53]],"id":51843546}],"con":true,"img":false}]}
{"op":"mcm","clk":"11541352141","pt":1719504857422,"mc":[{"id":"1.230180131","rc":[{"atb":[[2.8,5.97]],"id":43210435},{"atb":[[4,2]],"id":51843546}],"con":true,"img":false}]}
{"op":"mcm","clk":"11541352150","pt":1719504857522,"mc":[{"id":"1.230180131","rc":[{"atb":[[2.84,2]],"id":43210435}],"con":true,"img":false}]}
{"op":"mcm","clk":"11541352158","pt":1719504857628,"mc":[{"id":"1.230180131","rc":[{"atl":[[11.5,1],[12,0]],"id":51843546}],"con":true,"img":false}]}
{"op":"mcm","clk":"11541352175","pt":1719504857831,"mc":[{"id":"1.230180131","rc":[{"atl":[[6.8,0],[7.6,0],[8.4,0]],"id":41138102},{"atb":[[4,0]],"id":51843546}],"con":true,"img":false}]}
{"op":"mcm","clk":"11541352185","pt":1719504858043,"mc":[{"id":"1.230180131","rc":[{"atb":[[4.2,2]],"id":51843546}],"con":true,"img":false}]}
{"op":"mcm","clk":"11541352196","pt":1719504858144,"mc":[{"id":"1.230180131","rc":[{"atb":[[4.1,10.8]],"id":51843546}],"con":true,"img":false}]}
{"op":"mcm","clk":"11541352269","pt":1719504858929,"mc":[{"id":"1.230180131","rc":[{"atb":[[1.92,0],[1.99,10.71]],"id":58149406}],"con":true,"img":false}]}
{"op":"mcm","clk":"11541352277","pt":1719504859029,"mc":[{"id":"1.230180131","rc":[{"atb":[[2.54,0]],"id":58149406},{"atb":[[2.04,0]],"id":66499052},{"atb":[[1.37,0]],"id":69979297},{"atl":[[2.3,0]],"id":69979297}],"con":true,"img":false}]}
{"op":"mcm","clk":"11541352295","pt":1719504859234,"mc":[{"id":"1.230180131","rc":[{"atl":[[2.56,0],[2.7,16.76]],"id":69979297}],"con":true,"img":false}]}
{"op":"mcm","clk":"11541352333","pt":1719504859611,"mc":[{"id":"1.230180131","rc":[{"atb":[[3.4,8.83]],"id":41138102},{"atl":[[4.5,6.46]],"id":66499052}],"con":true,"img":false}]}
{"op":"mcm","clk":"11541352343","pt":1719504859704,"mc":[{"id":"1.230180131","rc":[{"atl":[[4.4,6.47]],"id":66499052}],"con":true,"img":false}]}
{"op":"mcm","clk":"11541352354","pt":1719504859812,"mc":[{"id":"1.230180131","rc":[{"atb":[[3.3,0.24]],"id":41138102},{"atl":[[4.8,2.5],[4.6,0],[4.4,0],[4.7,20.91]],"id":66499052}],"con":true,"img":false}]}
{"op":"mcm","clk":"11541352367","pt":1719504859911,"mc":[{"id":"1.230180131","rc":[{"atl":[[4.8,28.82],[4.7,0.84]],"id":66499052},{"atb":[[4.2,0]],"id":51843546}],"con":true,"img":false}]}
{"op":"mcm","clk":"11541352376","pt":1719504860015,"mc":[{"id":"1.230180131","rc":[{"atb":[[1.02,2]],"id":51843546}],"con":true,"img":false}]}
{"op":"mcm","clk":"11541352399","pt":1719504860329,"mc":[{"id":"1.230180131","rc":[{"atb":[[2.84,5.83],[2.78,0]],"id":43210435}],"con":true,"img":false}]}
{"op":"mcm","clk":"11541352409","pt":1719504860432,"mc":[{"id":"1.230180131","rc":[{"atl":[[4.7,0]],"id":66499052}],"con":true,"img":false}]}
{"op":"mcm","clk":"11541352428","pt":1719504860632,"mc":[{"id":"1.230180131","rc":[{"atb":[[3.35,2]],"id":41138102},{"atl":[[4.8,2.5],[5.2,28.81]],"id":66499052}],"con":true,"img":false}]}
{"op":"mcm","clk":"11541352460","pt":1719504861001,"mc":[{"id":"1.230180131","rc":[{"atb":[[3.35,0]],"id":41138102}],"con":true,"img":false}]}
{"op":"mcm","clk":"11541352470","pt":1719504861106,"mc":[{"id":"1.230180131","rc":[{"atb":[[3.45,2],[3.4,10.41]],"id":41138102}],"con":true,"img":false}]}
{"op":"mcm","clk":"11541352478","pt":1719504861206,"mc":[{"id":"1.230180131","rc":[{"atb":[[3.35,8.5]],"id":41138102}],"con":true,"img":false}]}
{"op":"mcm","clk":"11541352502","pt":1719504861524,"mc":[{"id":"1.230180131","rc":[{"atb":[[1.02,0]],"id":51843546}],"con":true,"img":false}]}
{"op":"mcm","clk":"11541352514","pt":1719504861628,"mc":[{"id":"1.230180131","rc":[{"atb":[[4.2,2]],"id":51843546}],"con":true,"img":false}]}
{"op":"mcm","clk":"11541352545","pt":1719504862034,"mc":[{"id":"1.230180131","rc":[{"atb":[[3.4,9.58]],"id":41138102}],"con":true,"img":false}]}
{"op":"mcm","clk":"11541352561","pt":1719504862243,"mc":[{"id":"1.230180131","rc":[{"atb":[[3.4,0]],"id":41138102}],"con":true,"img":false}]}
{"op":"mcm","clk":"11541352568","pt":1719504862352,"mc":[{"id":"1.230180131","rc":[{"atb":[[3.45,11.58]],"id":41138102}],"con":true,"img":false}]}
{"op":"mcm","clk":"11541352594","pt":1719504862616,"mc":[{"id":"1.230180131","rc":[{"atb":[[4.2,0]],"id":51843546}],"con":true,"img":false}]}
{"op":"mcm","clk":"11541352605","pt":1719504862714,"mc":[{"id":"1.230180131","rc":[{"atb":[[1.02,2]],"id":51843546}],"con":true,"img":false}]}
{"op":"mcm","clk":"11541352652","pt":1719504863133,"mc":[{"id":"1.230180131","rc":[{"atb":[[2.3,17],[2.48,0]],"id":41138102},{"atl":[[7.4,0],[8.4,9.88]],"id":41138102},{"atb":[[2.16,8.89],[2.08,30.28]],"id":66499052}],"con":true,"img":false}]}
{"op":"mcm","clk":"11541352675","pt":1719504863341,"mc":[{"id":"1.230180131","rc":[{"atb":[[2,44.17],[2.08,2.5]],"id":66499052}],"con":true,"img":false}]}
{"op":"mcm","clk":"11541352689","pt":1719504863445,"mc":[{"id":"1.230180131","rc":[{"atb":[[2,5]],"id":66499052}],"con":true,"img":false}]}
{"op":"mcm","clk":"11541352698","pt":1719504863508,"mc":[{"id":"1.230180131","rc":[{"atb":[[2.08,20.28]],"id":66499052}],"con":true,"img":false}]}
{"op":"mcm","clk":"11541352725","pt":1719504863814,"mc":[{"id":"1.230180131","rc":[{"atb":[[1.02,0]],"id":51843546}],"con":true,"img":false}]}
{"op":"mcm","clk":"11541352735","pt":1719504863917,"mc":[{"id":"1.230180131","rc":[{"atb":[[4.2,2]],"id":51843546}],"con":true,"img":false}]}
{"op":"mcm","clk":"11541352742","pt":1719504864018,"mc":[{"id":"1.230180131","rc":[{"atl":[[5.6,11],[5.5,0]],"id":66499052},{"atl":[[10.5,1],[11.5,0]],"id":51843546},{"atl":[[2.72,1],[2.7,15.76]],"id":69979297}],"con":true,"img":false}]}
{"op":"mcm","clk":"11541352752","pt":1719504864124,"mc":[{"id":"1.230180131","rc":[{"atb":[[1.99,0],[2.08,14.24]],"id":58149406},{"atl":[[4.8,1],[4.6,4.96]],"id":58149406}],"con":true,"img":false}]}
{"op":"mcm","clk":"11541352759","pt":1719504864225,"mc":[{"id":"1.230180131","rc":[{"atl":[[5.8,5],[5.4,12.5]],"id":58149406}],"con":true,"img":false}]}
{"op":"mcm","clk":"11541352793","pt":1719504864746,"mc":[{"id":"1.230180131","rc":[{"spn":3.58,"spf":"NaN","id":58149406},{"spn":4.82,"spf":"NaN","id":43210435},{"spn":3.33,"spf":"NaN","id":66499052},{"atb":[[4.1,10.37]],"id":51843546},{"spn":6.2,"spf":"NaN","id":51843546},{"spn":1.87,"spf":"NaN","id":69979297}],"con":true,"img":false}]}
{"op":"mcm","clk":"11541352818","pt":1719504865104,"mc":[{"id":"1.230180131","rc":[{"atb":[[2.82,0]],"id":43210435},{"atb":[[4.1,0],[4.2,0]],"id":51843546},{"atl":[[8.2,8.51]],"id":51843546}],"con":true,"img":false}]}
{"op":"mcm","clk":"11541352826","pt":1719504865208,"mc":[{"id":"1.230180131","rc":[{"atb":[[2.86,2.56]],"id":43210435},{"atb":[[1.02,2],[4.2,9.85]],"id":51843546}],"con":true,"img":false}]}
{"op":"mcm","clk":"11541352832","pt":1719504865311,"mc":[{"id":"1.230180131","rc":[{"atl":[[4.8,0],[4.9,1]],"id":58149406},{"atb":[[3.35,10]],"id":51843546},{"atl":[[9.6,5],[8,8.52]],"id":51843546}],"con":true,"img":false}]}
{"op":"mcm","clk":"11541352841","pt":1719504865415,"mc":[{"id":"1.230180131","rc":[{"atl":[[4.9,11]],"id":58149406},{"atl":[[8,14.14]],"id":51843546}],"con":true,"img":false}]}
{"op":"mcm","clk":"11541352849","pt":1719504865523,"mc":[{"id":"1.230180131","rc":[{"atl":[[5.4,2.5]],"id":58149406}],"con":true,"img":false}]}
{"op":"mcm","clk":"11541352857","pt":1719504865630,"mc":[{"id":"1.230180131","rc":[{"atl":[[8.2,4.1]],"id":51843546}],"con":true,"img":false}]}
{"op":"mcm","clk":"11541352877","pt":1719504865827,"mc":[{"id":"1.230180131","rc":[{"atl":[[7.8,0.84]],"id":51843546}],"con":true,"img":false}]}
{"op":"mcm","clk":"11541352891","pt":1719504866035,"mc":[{"id":"1.230180131","rc":[{"atb":[[4.2,2]],"id":51843546},{"atl":[[8.2,0.84]],"id":51843546}],"con":true,"img":false}]}
{"op":"mcm","clk":"11541352900","pt":1719504866134,"mc":[{"id":"1.230180131","rc":[{"atb":[[2.86,10.2]],"id":43210435}],"con":true,"img":false}]}
{"op":"mcm","clk":"11541352908","pt":1719504866237,"mc":[{"id":"1.230180131","rc":[{"atb":[[2.8,0]],"id":43210435}],"con":true,"img":false}]}
{"op":"mcm","clk":"11541352929","pt":1719504866556,"mc":[{"id":"1.230180131","rc":[{"atb":[[2.84,3.83]],"id":43210435},{"atb":[[1.38,8.11]],"id":69979297},{"atl":[[2.3,4.38]],"id":69979297}],"con":true,"img":false}]}
{"op":"mcm","clk":"11541352938","pt":1719504866656,"mc":[{"id":"1.230180131","rc":[{"atb":[[2.88,2]],"id":43210435}],"con":true,"img":false}]}
{"op":"mcm","clk":"11541352947","pt":1719504866765,"mc":[{"id":"1.230180131","rc":[{"atb":[[2.88,5.83]],"id":43210435}],"con":true,"img":false}]}
{"op":"mcm","clk":"11541352956","pt":1719504866808,"mc":[{"id":"1.230180131","rc":[{"atb":[[2.84,0]],"id":43210435},{"atb":[[1.02,0]],"id":51843546}],"con":true,"img":false}]}
{"op":"mcm","clk":"11541352964","pt":1719504866913,"mc":[{"id":"1.230180131","rc":[{"atb":[[4.3,2]],"id":51843546},{"atl":[[7.8,4.09]],"id":51843546}],"con":true,"img":false}]}
{"op":"mcm","clk":"11541353005","pt":1719504867428,"mc":[{"id":"1.230180131","rc":[{"atl":[[8.2,0]],"id":51843546}],"con":true,"img":false}]}
{"op":"mcm","clk":"11541353034","pt":1719504867740,"mc":[{"id":"1.230180131","rc":[{"atl":[[5.6,10],[5.5,1]],"id":66499052},{"atb":[[4.3,9.72]],"id":51843546},{"atl":[[2.72,0],[2.74,1]],"id":69979297}],"con":true,"img":false}]}
{"op":"mcm","clk":"11541353115","pt":1719504868725,"mc":[{"id":"1.230180131","rc":[{"atb":[[1.94,18.89],[2.08,2.5]],"id":66499052},{"atb":[[2.88,10],[3.05,0]],"id":51843546}],"con":true,"img":false}]}
{"op":"mcm","clk":"11541353137","pt":1719504868931,"mc":[{"id":"1.230180131","rc":[{"atb":[[4.3,7.72]],"id":51843546}],"con":true,"img":false}]}
{"op":"mcm","clk":"11541353146","pt":1719504869031,"mc":[{"id":"1.230180131","rc":[{"atb":[[1.02,2]],"id":51843546}],"con":true,"img":false}]}
{"op":"mcm","clk":"11541353276","pt":1719504870435,"mc":[{"id":"1.230180131","rc":[{"atl":[[8,5.62],[7.6,4.1]],"id":51843546}],"con":true,"img":false}]}
{"op":"mcm","clk":"11541353285","pt":1719504870543,"mc":[{"id":"1.230180131","rc":[{"atl":[[4.9,1],[5.4,18.47]],"id":58149406}],"con":true,"img":false}]}
{"op":"mcm","clk":"11541353308","pt":1719504870746,"mc":[{"id":"1.230180131","rc":[{"atb":[[3.5,6.56]],"id":41138102}],"con":true,"img":false}]}
{"op":"mcm","clk":"11541353318","pt":1719504870860,"mc":[{"id":"1.230180131","rc":[{"atb":[[3.35,0]],"id":41138102}],"con":true,"img":false}]}
{"op":"mcm","clk":"11541353331","pt":1719504870951,"mc":[{"id":"1.230180131","rc":[{"atl":[[7.8,0.84]],"id":51843546}],"con":true,"img":false}]}
{"op":"mcm","clk":"11541353340","pt":1719504871060,"mc":[{"id":"1.230180131","rc":[{"atl":[[7.6,7.35]],"id":51843546}],"con":true,"img":false}]}
{"op":"mcm","clk":"11541353414","pt":1719504871842,"mc":[{"id":"1.230180131","rc":[{"atb":[[3.45,9.36]],"id":41138102},{"atb":[[2.88,2],[2.84,16.03]],"id":43210435}],"con":true,"img":false}]}
{"op":"mcm","clk":"11541353426","pt":1719504871943,"mc":[{"id":"1.230180131","rc":[{"atb":[[3.55,2]],"id":41138102}],"con":true,"img":false}]}
{"op":"mcm","clk":"11541353443","pt":1719504872148,"mc":[{"id":"1.230180131","rc":[{"atb":[[3.45,0]],"id":41138102}],"con":true,"img":false}]}
{"op":"mcm","clk":"11541353453","pt":1719504872253,"mc":[{"id":"1.230180131","rc":[{"atb":[[3.5,15.92]],"id":41138102}],"con":true,"img":false}]}
{"op":"mcm","clk":"11541353459","pt":1719504872309,"mc":[{"id":"1.230180131","rc":[{"atb":[[3.6,2.25]],"id":41138102}],"con":true,"img":false}]}
{"op":"mcm","clk":"11541353471","pt":1719504872415,"mc":[{"id":"1.230180131","rc":[{"atb":[[3.5,9.36]],"id":41138102}],"con":true,"img":false}]}
{"op":"mcm","clk":"11541353479","pt":1719504872515,"mc":[{"id":"1.230180131","rc":[{"atb":[[3.5,0]],"id":41138102}],"con":true,"img":false}]}
{"op":"mcm","clk":"11541353517","pt":1719504872938,"mc":[{"id":"1.230180131","rc":[{"atl":[[7.4,0.84]],"id":51843546}],"con":true,"img":false}]}
{"op":"mcm","clk":"11541353529","pt":1719504873047,"mc":[{"id":"1.230180131","rc":[{"atb":[[3.55,0]],"id":41138102}],"con":true,"img":false}]}
{"op":"mcm","clk":"11541353535","pt":1719504873148,"mc":[{"id":"1.230180131","rc":[{"atb":[[3.6,0]],"id":41138102}],"con":true,"img":false}]}
{"op":"mcm","clk":"11541353544","pt":1719504873252,"mc":[{"id":"1.230180131","rc":[{"atb":[[3.55,2.44],[3.15,10.71],[3.65,2]],"id":41138102}],"con":true,"img":false}]}
{"op":"mcm","clk":"11541353581","pt":1719504873724,"mc":[{"id":"1.230180131","rc":[{"atb":[[2.84,19.11]],"id":43210435}],"con":true,"img":false}]}
{"op":"mcm","clk":"11541353598","pt":1719504873933,"mc":[{"id":"1.230180131","rc":[{"atb":[[2.86,7.64]],"id":43210435},{"atb":[[2.06,4.99]],"id":66499052},{"atb":[[4.2,0]],"id":51843546}],"con":true,"img":false}]}
{"op":"mcm","clk":"11541353609","pt":1719504874037,"mc":[{"id":"1.230180131","rc":[{"atb":[[2.88,4]],"id":43210435}],"con":true,"img":false}]}
{"op":"mcm","clk":"11541353617","pt":1719504874143,"mc":[{"id":"1.230180131","rc":[{"atb":[[3.15,8]],"id":41138102}],"con":true,"img":false}]}
{"op":"mcm","clk":"11541353628","pt":1719504874245,"mc":[{"id":"1.230180131","rc":[{"atb":[[3.65,0]],"id":41138102},{"atb":[[1.94,0],[1.97,10]],"id":66499052}],"con":true,"img":false}]}
{"op":"mcm","clk":"11541353636","pt":1719504874351,"mc":[{"id":"1.230180131","rc":[{"atb":[[3.6,2],[3.15,0]],"id":41138102}],"con":true,"img":false}]}
{"op":"mcm","clk":"11541353647","pt":1719504874450,"mc":[{"id":"1.230180131","rc":[{"atb":[[3.65,8]],"id":41138102}],"con":true,"img":false}]}
{"op":"mcm","clk":"11541353691","pt":1719504874975,"mc":[{"id":"1.230180131","rc":[{"atb":[[4.3,0]],"id":51843546}],"con":true,"img":false}]}
{"op":"mcm","clk":"11541353729","pt":1719504875440,"mc":[{"id":"1.230180131","rc":[{"atb":[[3.6,0]],"id":41138102}],"con":true,"img":false}]}
{"op":"mcm","clk":"11541353738","pt":1719504875552,"mc":[{"id":"1.230180131","rc":[{"atb":[[3.7,2]],"id":41138102}],"con":true,"img":false}]}
{"op":"mcm","clk":"11541353753","pt":1719504875755,"mc":[{"id":"1.230180131","rc":[{"atb":[[1.02,0]],"id":51843546}],"con":true,"img":false}]}
{"op":"mcm","clk":"11541353757","pt":1719504875865,"mc":[{"id":"1.230180131","rc":[{"atb":[[3.65,0]],"id":41138102},{"atb":[[2.14,2.11],[1.67,0]],"id":66499052},{"atb":[[3.4,2]],"id":51843546}],"con":true,"img":false}]}
{"op":"mcm","clk":"11541353785","pt":1719504876219,"mc":[{"id":"1.230180131","rc":[{"atb":[[2.2,14.24],[2.08,0]],"id":58149406},{"atb":[[2.18,5]],"id":41138102},{"atb":[[2.8,15.28],[2.84,3.08]],"id":43210435}],"con":true,"img":false}]}
{"op":"mcm","clk":"11541353790","pt":1719504876323,"mc":[{"id":"1.230180131","rc":[{"atb":[[2.3,0]],"id":41138102},{"atb":[[2.84,0]],"id":43210435},{"atb":[[3.4,7.25]],"id":51843546}],"con":true,"img":false}]}
{"op":"mcm","clk":"11541353799","pt":1719504876430,"mc":[{"id":"1.230180131","rc":[{"atb":[[3.35,2.5]],"id":51843546},{"atl":[[7.4,6.09]],"id":51843546}],"con":true,"img":false}]}
{"op":"mcm","clk":"11541353808","pt":1719504876531,"mc":[{"id":"1.230180131","rc":[{"atb":[[3.3,5.24],[3.5,2.5],[2.88,0],[2.96,0]],"id":41138102},{"atl":[[4.8,0],[5.6,0],[4.6,5],[5,10],[5.2,23.81],[4.2,2.5]],"id":66499052}],"con":true,"img":false}]}
{"op":"mcm","clk":"11541353821","pt":1719504876636,"mc":[{"id":"1.230180131","rc":[{"atb":[[3.7,11.29]],"id":41138102},{"atl":[[4.6,17.94],[5.2,0],[4.4,3.46]],"id":66499052},{"atl":[[8,0]],"id":51843546}],"con":true,"img":false}]}
{"op":"mcm","clk":"11541353827","pt":1719504876738,"mc":[{"id":"1.230180131","rc":[{"atl":[[4.5,0.84]],"id":66499052}],"con":true,"img":false}]}
{"op":"mcm","clk":"11541353845","pt":1719504876951,"mc":[{"id":"1.230180131","rc":[{"atl":[[4.5,0],[4.1,0.84]],"id":66499052},{"atl":[[7.8,0]],"id":51843546}],"con":true,"img":false}]}
{"op":"mcm","clk":"11541353860","pt":1719504877051,"mc":[{"id":"1.230180131","rc":[{"atl":[[4.6,5],[4.4,13.46]],"id":66499052}],"con":true,"img":false}]}
{"op":"mcm","clk":"11541353871","pt":1719504877147,"mc":[{"id":"1.230180131","rc":[{"atb":[[2.88,13]],"id":43210435},{"atb":[[2.06,0]],"id":66499052}],"con":true,"img":false}]}
{"op":"mcm","clk":"11541353878","pt":1719504877253,"mc":[{"id":"1.230180131","rc":[{"atb":[[2.86,0]],"id":43210435}],"con":true,"img":false}]}
{"op":"mcm","clk":"11541353950","pt":1719504878029,"mc":[{"id":"1.230180131","rc":[{"atb":[[2.54,3.59]],"id":58149406}],"con":true,"img":false}]}
{"op":"mcm","clk":"11541354240","pt":1719504881675,"mc":[{"id":"1.230180131","rc":[{"atl":[[5,1],[4.9,0]],"id":58149406},{"atb":[[3.75,3.7]],"id":41138102}],"con":true,"img":false}]}
{"op":"mcm","clk":"11541354249","pt":1719504881780,"mc":[{"id":"1.230180131","rc":[{"atl":[[4.9,9.94],[5.4,2.5]],"id":58149406},{"atb":[[3.55,0]],"id":41138102}],"con":true,"img":false}]}
{"op":"mcm","clk":"11541354258","pt":1719504881840,"mc":[{"id":"1.230180131","rc":[{"atl":[[5,15.91],[4.9,0]],"id":58149406}],"con":true,"img":false}]}
{"op":"mcm","clk":"11541354270","pt":1719504881944,"mc":[{"id":"1.230180131","rc":[{"atl":[[5,1]],"id":58149406}],"con":true,"img":false}]}
{"op":"mcm","clk":"11541354280","pt":1719504882053,"mc":[{"id":"1.230180131","rc":[{"atl":[[5.4,23.38]],"id":58149406},{"atl":[[10.5,0],[9.4,1]],"id":51843546}],"con":true,"img":false}]}
{"op":"mcm","clk":"11541354314","pt":1719504882356,"mc":[{"id":"1.230180131","rc":[{"atl":[[7.4,2.72]],"id":51843546},{"trd":[[7.4,6.75]],"ltp":7.4,"tv":6.75,"id":51843546}],"con":true,"img":false}]}
{"op":"mcm","clk":"11541354339","pt":1719504882562,"mc":[{"id":"1.230180131","rc":[{"atb":[[2.88,11]],"id":43210435},{"atb":[[3.45,3.53]],"id":51843546}],"con":true,"img":false}]}
{"op":"mcm","clk":"11541354347","pt":1719504882671,"mc":[{"id":"1.230180131","rc":[{"atb":[[2.9,3]],"id":43210435},{"atb":[[3.45,7.02]],"id":51843546}],"con":true,"img":false}]}
{"op":"mcm","clk":"11541354375","pt":1719504882976,"mc":[{"id":"1.230180131","rc":[{"atb":[[3.7,9.93]],"id":41138102}],"con":true,"img":false}]}
{"op":"mcm","clk":"11541354382","pt":1719504883038,"mc":[{"id":"1.230180131","rc":[{"atb":[[3.7,7.93]],"id":41138102}],"con":true,"img":false}]}
{"op":"mcm","clk":"11541354390","pt":1719504883134,"mc":[{"id":"1.230180131","rc":[{"atb":[[3.8,2]],"id":41138102}],"con":true,"img":false}]}
{"op":"mcm","clk":"11541354402","pt":1719504883250,"mc":[{"id":"1.230180131","rc":[{"atb":[[3.8,6.28],[3.7,0]],"id":41138102}],"con":true,"img":false}]}
{"op":"mcm","clk":"11541354414","pt":1719504883346,"mc":[{"id":"1.230180131","rc":[{"atb":[[3.75,7.93]],"id":41138102}],"con":true,"img":false}]}
{"op":"mcm","clk":"11541354425","pt":1719504883444,"mc":[{"id":"1.230180131","rc":[{"atl":[[7.6,4.1]],"id":51843546}],"con":true,"img":false}]}
{"op":"mcm","clk":"11541354432","pt":1719504883556,"mc":[{"id":"1.230180131","rc":[{"atb":[[3.45,15.57]],"id":51843546},{"atl":[[7.6,0]],"id":51843546}],"con":true,"img":false}]}
{"op":"mcm","clk":"11541354445","pt":1719504883659,"mc":[{"id":"1.230180131","rc":[{"atl":[[8.8,9.32]],"id":51843546}],"con":true,"img":false}]}
{"op":"mcm","clk":"11541354461","pt":1719504883855,"mc":[{"id":"1.230180131","rc":[{"atl":[[8.8,2.5],[9.4,12.9]],"id":51843546}],"con":true,"img":false}]}
{"op":"mcm","clk":"11541354503","pt":1719504884429,"mc":[{"id":"1.230180131","rc":[{"atb":[[2.88,9]],"id":43210435}],"con":true,"img":false}]}
{"op":"mcm","clk":"11541354509","pt":1719504884537,"mc":[{"id":"1.230180131","rc":[{"atb":[[2.92,2]],"id":43210435}],"con":true,"img":false}]}
{"op":"mcm","clk":"11541354531","pt":1719504884848,"mc":[{"id":"1.230180131","rc":[{"atb":[[3.4,5.25]],"id":51843546}],"con":true,"img":false}]}
{"op":"mcm","clk":"11541354542","pt":1719504884948,"mc":[{"id":"1.230180131","rc":[{"atb":[[3.5,2]],"id":51843546},{"atl":[[2.26,2.53]],"id":69979297}],"con":true,"img":false}]}
{"op":"mcm","clk":"11541354551","pt":1719504885051,"mc":[{"id":"1.230180131","rc":[{"atb":[[3.45,14.57]],"id":51843546},{"atl":[[2.24,4.86],[2.26,6.47],[2.7,0]],"id":69979297}],"con":true,"img":false}]}
{"op":"mcm","clk":"11541354559","pt":1719504885159,"mc":[{"id":"1.230180131","rc":[{"atl":[[2.28,5.92],[2.26,2.53]],"id":69979297}],"con":true,"img":false}]}
{"op":"mcm","clk":"11541354578","pt":1719504885367,"mc":[{"id":"1.230180131","rc":[{"atb":[[3.45,6.01]],"id":51843546}],"con":true,"img":false}]}
{"op":"mcm","clk":"11541354585","pt":1719504885462,"mc":[{"id":"1.230180131","rc":[{"atb":[[2.58,1.94]],"id":58149406},{"atb":[[3.85,1.94]],"id":41138102},{"atb":[[2.92,3.94]],"id":43210435},{"atl":[[2.24,5.71]],"id":69979297}],"con":true,"img":false}]}
{"op":"mcm","clk":"11541354591","pt":1719504885572,"mc":[{"id":"1.230180131","rc":[{"atb":[[2.58,8.36]],"id":58149406},{"atb":[[3.85,8.11]],"id":41138102}],"con":true,"img":false}]}
{"op":"mcm","clk":"11541354602","pt":1719504885671,"mc":[{"id":"1.230180131","rc":[{"atb":[[2.56,2.9]],"id":58149406},{"atl":[[2.3,0]],"id":69979297}],"con":true,"img":false}]}
{"op":"mcm","clk":"11541354610","pt":1719504885776,"mc":[{"id":"1.230180131","rc":[{"atb":[[3.8,2]],"id":41138102}],"con":true,"img":false}]}
{"op":"mcm","clk":"11541354626","pt":1719504885986,"mc":[{"id":"1.230180131","rc":[{"atl":[[2.28,5.08]],"id":69979297}],"con":true,"img":false}]}
{"op":"mcm","clk":"11541354644","pt":1719504886147,"mc":[{"id":"1.230180131","rc":[{"atl":[[5.1,1],[5,0]],"id":58149406},{"atb":[[3.8,0],[3.75,0]],"id":41138102},{"atl":[[5.5,0],[5.3,1]],"id":66499052},{"atl":[[8.8,3.5],[9.4,11.9]],"id":51843546}],"con":true,"img":false}]}
{"op":"mcm","clk":"11541354655","pt":1719504886259,"mc":[{"id":"1.230180131","rc":[{"atl":[[5,9.94],[5.4,2.5]],"id":58149406},{"atb":[[3.9,2]],"id":41138102}],"con":true,"img":false}]}
{"op":"mcm","clk":"11541354668","pt":1719504886357,"mc":[{"id":"1.230180131","rc":[{"atb":[[3.5,11.34]],"id":51843546}],"con":true,"img":false}]}
{"op":"mcm","clk":"11541354696","pt":1719504886663,"mc":[{"id":"1.230180131","rc":[{"atb":[[2.54,0]],"id":58149406}],"con":true,"img":false}]}
{"op":"mcm","clk":"11541354738","pt":1719504887186,"mc":[{"id":"1.230180131","rc":[{"atb":[[3.55,8.45]],"id":51843546}],"con":true,"img":false}]}
{"op":"mcm","clk":"11541354750","pt":1719504887238,"mc":[{"id":"1.230180131","rc":[{"atb":[[3.6,1],[3.5,2],[3.4,0]],"id":51843546}],"con":true,"img":false}]}
{"op":"mcm","clk":"11541354773","pt":1719504887441,"mc":[{"id":"1.230180131","rc":[{"atb":[[3.9,10.21]],"id":41138102},{"atl":[[4.1,4.59]],"id":66499052}],"con":true,"img":false}]}
{"op":"mcm","clk":"11541354781","pt":1719504887553,"mc":[{"id":"1.230180131","rc":[{"atb":[[2.8,0]],"id":43210435},{"atl":[[4.4,10]],"id":66499052},{"atl":[[2.26,0]],"id":69979297}],"con":true,"img":false}]}
{"op":"mcm","clk":"11541354792","pt":1719504887650,"mc":[{"id":"1.230180131","rc":[{"atb":[[2.82,7.9]],"id":43210435},{"atb":[[3.3,5.75]],"id":51843546},{"atl":[[2.74,11.79],[2.28,0]],"id":69979297}],"con":true,"img":false}]}
{"op":"mcm","clk":"11541354819","pt":1719504887961,"mc":[{"id":"1.230180131","rc":[{"atb":[[2.92,10.17]],"id":43210435},{"atb":[[3.3,0]],"id":51843546}],"con":true,"img":false}]}
{"op":"mcm","clk":"11541354825","pt":1719504888061,"mc":[{"id":"1.230180131","rc":[{"atb":[[2.88,0]],"id":43210435},{"atb":[[3.6,9.97]],"id":51843546}],"con":true,"img":false}]}
{"op":"mcm","clk":"11541354832","pt":1719504888139,"mc":[{"id":"1.230180131","rc":[{"atl":[[2.26,4.52]],"id":69979297}],"con":true,"img":false}]}
{"op":"mcm","clk":"11541354840","pt":1719504888242,"mc":[{"id":"1.230180131","rc":[{"atl":[[2.24,11.42],[2.74,1]],"id":69979297}],"con":true,"img":false}]}
{"op":"mcm","clk":"11541354867","pt":1719504888555,"mc":[{"id":"1.230180131","rc":[{"atb":[[3.85,6.17]],"id":41138102}],"con":true,"img":false}]}
{"op":"mcm","clk":"11541354878","pt":1719504888652,"mc":[{"id":"1.230180131","rc":[{"atb":[[3.5,0]],"id":51843546}],"con":true,"img":false}]}
{"op":"mcm","clk":"11541354884","pt":1719504888755,"mc":[{"id":"1.230180131","rc":[{"atb":[[3.95,1.94]],"id":41138102},{"atb":[[3.65,2]],"id":51843546}],"con":true,"img":false}]}
{"op":"mcm","clk":"11541354897","pt":1719504888960,"mc":[{"id":"1.230180131","rc":[{"atb":[[3.9,9.12]],"id":41138102},{"atb":[[3.6,7.63]],"id":51843546}],"con":true,"img":false}]}
{"op":"mcm","clk":"11541354914","pt":1719504889177,"mc":[{"id":"1.230180131","rc":[{"atb":[[3.9,2]],"id":41138102},{"atb":[[3.6,0]],"id":51843546}],"con":true,"img":false}]}
{"op":"mcm","clk":"11541354925","pt":1719504889276,"mc":[{"id":"1.230180131","rc":[{"atb":[[3.95,9.06]],"id":41138102},{"atb":[[3.65,9.63]],"id":51843546}],"con":true,"img":false}]}
{"op":"mcm","clk":"11541354960","pt":1719504889751,"mc":[{"id":"1.230180131","rc":[{"atb":[[3.65,7.63]],"id":51843546}],"con":true,"img":false}]}
{"op":"mcm","clk":"11541354966","pt":1719504889848,"mc":[{"id":"1.230180131","rc":[{"atb":[[3.6,2]],"id":51843546}],"con":true,"img":false}]}
{"op":"mcm","clk":"11541354999","pt":1719504890263,"mc":[{"id":"1.230180131","rc":[{"atl":[[2.22,2.53]],"id":69979297}],"con":true,"img":false}]}
{"op":"mcm","clk":"11541355057","pt":1719504891148,"mc":[{"id":"1.230180131","rc":[{"atb":[[2.56,0]],"id":58149406},{"atl":[[5.1,15.91],[5,0]],"id":58149406},{"atb":[[2.9,0]],"id":43210435},{"atb":[[3.45,2.52]],"id":51843546},{"atb":[[1.38,2.5]],"id":69979297}],"con":true,"img":false}]}
{"op":"mcm","clk":"11541355065","pt":1719504891253,"mc":[{"id":"1.230180131","rc":[{"atb":[[2.6,2]],"id":58149406},{"atb":[[3.9,0]],"id":41138102},{"atb":[[2.94,3.6]],"id":43210435},{"atb":[[3.7,3.31]],"id":51843546}],"con":true,"img":false}]}
{"op":"mcm","clk":"11541355072","pt":1719504891357,"mc":[{"id":"1.230180131","rc":[{"atl":[[5.1,1],[5.4,23.38]],"id":58149406},{"atb":[[4,2]],"id":41138102}],"con":true,"img":false}]}
{"op":"mcm","clk":"11541355097","pt":1719504891665,"mc":[{"id":"1.230180131","rc":[{"atb":[[3.95,1.94]],"id":41138102},{"atb":[[3.6,0],[3.65,0]],"id":51843546}],"con":true,"img":false}]}
{"op":"mcm","clk":"11541355105","pt":1719504891769,"mc":[{"id":"1.230180131","rc":[{"atb":[[3.7,5.31]],"id":51843546}],"con":true,"img":false}]}
{"op":"mcm","clk":"11541355140","pt":1719504892291,"mc":[{"id":"1.230180131","rc":[{"atb":[[1.37,5.61]],"id":69979297}],"con":true,"img":false}]}
{"op":"mcm","clk":"11541355147","pt":1719504892396,"mc":[{"id":"1.230180131","rc":[{"atb":[[4,4.96]],"id":41138102}],"con":true,"img":false}]}
{"op":"mcm","clk":"11541355154","pt":1719504892451,"mc":[{"id":"1.230180131","rc":[{"atb":[[3.85,0],[4,13.28]],"id":41138102},{"atb":[[3.7,13.21]],"id":51843546}],"con":true,"img":false}]}
{"op":"mcm","clk":"11541355205","pt":1719504892865,"mc":[{"id":"1.230180131","rc":[{"atl":[[2.2,0.85]],"id":69979297}],"con":true,"img":false}]}
{"op":"mcm","clk":"11541355226","pt":1719504893074,"mc":[{"id":"1.230180131","rc":[{"atb":[[2.92,8.17]],"id":43210435}],"con":true,"img":false}]}
{"op":"mcm","clk":"11541355236","pt":1719504893179,"mc":[{"id":"1.230180131","rc":[{"atb":[[2.96,2]],"id":43210435}],"con":true,"img":false}]}
{"op":"mcm","clk":"11541355244","pt":1719504893284,"mc":[{"id":"1.230180131","rc":[{"atb":[[3.75,2.53]],"id":51843546}],"con":true,"img":false}]}
{"op":"mcm","clk":"11541355252","pt":1719504893387,"mc":[{"id":"1.230180131","rc":[{"atb":[[3.45,0]],"id":51843546}],"con":true,"img":false}]}
{"op":"mcm","clk":"11541355312","pt":1719504894063,"mc":[{"id":"1.230180131","rc":[{"atb":[[3.7,13.2]],"id":51843546}],"con":true,"img":false}]}
{"op":"mcm","clk":"11541355322","pt":1719504894168,"mc":[{"id":"1.230180131","rc":[{"atb":[[3.7,11.2]],"id":51843546}],"con":true,"img":false}]}
{"op":"mcm","clk":"11541355330","pt":1719504894270,"mc":[{"id":"1.230180131","rc":[{"atb":[[3.7,2.31],[3.8,2]],"id":51843546}],"con":true,"img":false}]}
{"op":"mcm","clk":"11541355335","pt":1719504894373,"mc":[{"id":"1.230180131","rc":[{"atb":[[3.75,11.42]],"id":51843546}],"con":true,"img":false}]}
{"op":"mcm","clk":"11541355342","pt":1719504894475,"mc":[{"id":"1.230180131","rc":[{"atb":[[3.85,1]],"id":51843546}],"con":true,"img":false}]}
{"op":"mcm","clk":"11541355349","pt":1719504894585,"mc":[{"id":"1.230180131","rc":[{"atb":[[3.95,0]],"id":41138102},{"atb":[[2.92,6.23]],"id":43210435}],"con":true,"img":false}]}
{"op":"mcm","clk":"11541355370","pt":1719504894682,"mc":[{"id":"1.230180131","rc":[{"atb":[[4.1,1.94]],"id":41138102},{"atb":[[2.96,3.94]],"id":43210435}],"con":true,"img":false}]}
{"op":"mcm","clk":"11541355377","pt":1719504894786,"mc":[{"id":"1.230180131","rc":[{"atb":[[4,13.1],[4.1,5.28]],"id":41138102},{"atb":[[3.75,10.45]],"id":51843546}],"con":true,"img":false}]}
{"op":"mcm","clk":"11541355386","pt":1719504894890,"mc":[{"id":"1.230180131","rc":[{"atb":[[4,10.14]],"id":41138102}],"con":true,"img":false}]}
{"op":"mcm","clk":"11541355392","pt":1719504894995,"mc":[{"id":"1.230180131","rc":[{"atb":[[4,2]],"id":41138102},{"atb":[[3.75,2.53]],"id":51843546}],"con":true,"img":false}]}
{"op":"mcm","clk":"11541355403","pt":1719504895049,"mc":[{"id":"1.230180131","rc":[{"atb":[[4.1,13.42]],"id":41138102},{"atb":[[3.85,8.92]],"id":51843546}],"con":true,"img":false}]}
{"op":"mcm","clk":"11541355422","pt":1719504895258,"mc":[{"id":"1.230180131","rc":[{"atb":[[4,0]],"id":41138102}],"con":true,"img":false}]}
{"op":"mcm","clk":"11541355431","pt":1719504895361,"mc":[{"id":"1.230180131","rc":[{"atb":[[1.02,2]],"id":41138102}],"con":true,"img":false}]}
{"op":"mcm","clk":"11541355441","pt":1719504895464,"mc":[{"id":"1.230180131","rc":[{"atb":[[1.06,0.52]],"id":51843546}],"con":true,"img":false}]}
{"op":"mcm","clk":"11541355454","pt":1719504895673,"mc":[{"id":"1.230180131","rc":[{"atb":[[4.1,5.28]],"id":41138102},{"atb":[[1.06,0.17]],"id":51843546},{"atl":[[2.2,4.35]],"id":69979297}],"con":true,"img":false}]}
{"op":"mcm","clk":"11541355459","pt":1719504895774,"mc":[{"id":"1.230180131","rc":[{"atl":[[2.24,0.85],[2.18,4.35]],"id":69979297}],"con":true,"img":false}]}
{"op":"mcm","clk":"11541355465","pt":1719504895879,"mc":[{"id":"1.230180131","rc":[{"atb":[[1.06,0]],"id":51843546},{"atl":[[2.1,18.16]],"id":69979297}],"con":true,"img":false}]}
{"op":"mcm","clk":"11541355471","pt":1719504895983,"mc":[{"id":"1.230180131","rc":[{"atb":[[3.9,0.17]],"id":51843546},{"atl":[[2.18,0],[2.2,13.05]],"id":69979297}],"con":true,"img":false}]}
{"op":"mcm","clk":"11541355486","pt":1719504896191,"mc":[{"id":"1.230180131","rc":[{"atb":[[2.6,7.6]],"id":58149406},{"atb":[[3.85,7.92]],"id":51843546}],"con":true,"img":false}]}
{"op":"mcm","clk":"11541355493","pt":1719504896292,"mc":[{"id":"1.230180131","rc":[{"atb":[[2.58,1.94]],"id":58149406}],"con":true,"img":false}]}
{"op":"mcm","clk":"11541355502","pt":1719504896350,"mc":[{"id":"1.230180131","rc":[{"atb":[[3.8,0]],"id":51843546}],"con":true,"img":false}]}
{"op":"mcm","clk":"11541355510","pt":1719504896452,"mc":[{"id":"1.230180131","rc":[{"atb":[[3.9,2.17]],"id":51843546},{"atl":[[2.24,0],[2.2,12.2]],"id":69979297}],"con":true,"img":false}]}
{"op":"mcm","clk":"11541355562","pt":1719504897175,"mc":[{"id":"1.230180131","rc":[{"atl":[[2.22,0],[2.26,0]],"id":69979297}],"con":true,"img":false}]}
{"op":"mcm","clk":"11541355570","pt":1719504897279,"mc":[{"id":"1.230180131","rc":[{"atb":[[3.85,7.21]],"id":51843546}],"con":true,"img":false}]}
{"op":"mcm","clk":"11541355580","pt":1719504897509,"mc":[{"id":"1.230180131","rc":[{"atb":[[3.85,0]],"id":51843546}],"con":true,"img":false}]}
{"op":"mcm","clk":"11541355592","pt":1719504897668,"mc":[{"id":"1.230180131","rc":[{"atb":[[2.58,0]],"id":58149406},{"atb":[[3.9,9.38]],"id":51843546}],"con":true,"img":false}]}
{"op":"mcm","clk":"11541355609","pt":1719504897871,"mc":[{"id":"1.230180131","rc":[{"atb":[[2.62,1.94]],"id":58149406}],"con":true,"img":false}]}
{"op":"mcm","clk":"11541355626","pt":1719504898076,"mc":[{"id":"1.230180131","rc":[{"atl":[[4,5.32]],"id":66499052}],"con":true,"img":false}]}
{"op":"mcm","clk":"11541355634","pt":1719504898179,"mc":[{"id":"1.230180131","rc":[{"atb":[[2.58,3.49]],"id":58149406},{"atl":[[4.2,11.7]],"id":66499052}],"con":true,"img":false}]}
{"op":"mcm","clk":"11541355644","pt":1719504898287,"mc":[{"id":"1.230180131","rc":[{"atl":[[4.1,0.84],[4.4,0]],"id":66499052},{"atb":[[3.95,1]],"id":51843546}],"con":true,"img":false}]}
{"op":"mcm","clk":"11541355662","pt":1719504898499,"mc":[{"id":"1.230180131","rc":[{"atb":[[2.96,10.17]],"id":43210435}],"con":true,"img":false}]}
{"op":"mcm","clk":"11541355682","pt":1719504898701,"mc":[{"id":"1.230180131","rc":[{"atb":[[2.92,0]],"id":43210435}],"con":true,"img":false}]}
{"op":"mcm","clk":"11541355697","pt":1719504898861,"mc":[{"id":"1.230180131","rc":[{"atl":[[3.95,0.84]],"id":66499052}],"con":true,"img":false}]}
{"op":"mcm","clk":"11541355763","pt":1719504899804,"mc":[{"id":"1.230180131","rc":[{"atb":[[2.82,0],[2.86,13.78]],"id":43210435},{"atb":[[1.97,0],[2.12,11.01]],"id":66499052},{"atl":[[9.6,0],[8.6,2.5],[11,0],[8.8,1],[9.4,16.9]],"id":51843546}],"con":true,"img":false}]}
{"op":"mcm","clk":"11541355772","pt":1719504899904,"mc":[{"id":"1.230180131","rc":[{"atb":[[2.6,5.6]],"id":58149406},{"atb":[[2.94,0]],"id":43210435},{"atb":[[3.7,0]],"id":51843546},{"atl":[[8.6,7.94],[9.4,5]],"id":51843546},{"atl":[[2.08,0.84]],"id":69979297}],"con":true,"img":false}]}
{"op":"mcm","clk":"11541355779","pt":1719504899957,"mc":[{"id":"1.230180131","rc":[{"atb":[[2.62,4.94]],"id":58149406},{"atb":[[2.98,2.4]],"id":43210435},{"atb":[[3.95,3]],"id":51843546}],"con":true,"img":false}]}
{"op":"mcm","clk":"11541355820","pt":1719504900486,"mc":[{"id":"1.230180131","rc":[{"atb":[[3.9,2.17]],"id":51843546}],"con":true,"img":false}]}
{"op":"mcm","clk":"11541355838","pt":1719504900702,"mc":[{"id":"1.230180131","rc":[{"atb":[[2.96,6.23]],"id":43210435}],"con":true,"img":false}]}
{"op":"mcm","clk":"11541355847","pt":1719504900806,"mc":[{"id":"1.230180131","rc":[{"atb":[[1.02,18.48]],"id":43210435}],"con":true,"img":false}]}
{"op":"mcm","clk":"11541355859","pt":1719504900866,"mc":[{"id":"1.230180131","rc":[{"atb":[[3,1.94]],"id":43210435}],"con":true,"img":false}]}
{"op":"mcm","clk":"11541355877","pt":1719504901074,"mc":[{"id":"1.230180131","rc":[{"atl":[[2.2,3.5],[2.08,13.04]],"id":69979297}],"con":true,"img":false}]}
{"op":"mcm","clk":"11541355894","pt":1719504901290,"mc":[{"id":"1.230180131","rc":[{"atb":[[3.95,9.94],[3.9,0.17]],"id":51843546}],"con":true,"img":false}]}
{"op":"mcm","clk":"11541355908","pt":1719504901387,"mc":[{"id":"1.230180131","rc":[{"atb":[[4,2]],"id":51843546}],"con":true,"img":false}]}
{"op":"mcm","clk":"11541355930","pt":1719504901594,"mc":[{"id":"1.230180131","rc":[{"atb":[[3.95,8.94]],"id":51843546}],"con":true,"img":false}]}
{"op":"mcm","clk":"11541355991","pt":1719504902174,"mc":[{"id":"1.230180131","rc":[{"atb":[[3.95,2]],"id":51843546}],"con":true,"img":false}]}
{"op":"mcm","clk":"11541356037","pt":1719504902696,"mc":[{"id":"1.230180131","rc":[{"atb":[[1.37,0]],"id":69979297},{"atl":[[2.06,2.53]],"id":69979297}],"con":true,"img":false}]}
{"op":"mcm","clk":"11541356067","pt":1719504903007,"mc":[{"id":"1.230180131","rc":[{"atb":[[4,10]],"id":51843546}],"con":true,"img":false}]}
{"op":"mcm","clk":"11541356165","pt":1719504903788,"mc":[{"id":"1.230180131","rc":[{"atb":[[3,0]],"id":43210435},{"atb":[[4.1,2.36]],"id":51843546}],"con":true,"img":false}]}
{"op":"mcm","clk":"11541356179","pt":1719504903896,"mc":[{"id":"1.230180131","rc":[{"atb":[[3.75,0],[4.2,1]],"id":51843546}],"con":true,"img":false}]}
{"op":"mcm","clk":"11541356190","pt":1719504904000,"mc":[{"id":"1.230180131","rc":[{"atb":[[3,1.94]],"id":43210435}],"con":true,"img":false}]}
{"op":"mcm","clk":"11541356248","pt":1719504904583,"mc":[{"id":"1.230180131","rc":[{"atb":[[4,9.92]],"id":51843546}],"con":true,"img":false}]}
{"op":"mcm","clk":"11541356268","pt":1719504904783,"mc":[{"id":"1.230180131","rc":[{"atb":[[4,2]],"id":51843546}],"con":true,"img":false}]}
{"op":"mcm","clk":"11541356275","pt":1719504904889,"mc":[{"id":"1.230180131","rc":[{"atb":[[2.06,11.39],[2.12,0]],"id":66499052},{"atb":[[4,0],[4.2,8.92]],"id":51843546}],"con":true,"img":false}]}
{"op":"mcm","clk":"11541356284","pt":1719504904996,"mc":[{"id":"1.230180131","rc":[{"atb":[[4.2,10.92]],"id":51843546}],"con":true,"img":false}]}
{"op":"mcm","clk":"11541356387","pt":1719504906100,"mc":[{"id":"1.230180131","rc":[{"atl":[[2.06,14.22]],"id":69979297}],"con":true,"img":false}]}
{"op":"mcm","clk":"11541356394","pt":1719504906203,"mc":[{"id":"1.230180131","rc":[{"atl":[[2.2,0]],"id":69979297}],"con":true,"img":false}]}
{"op":"mcm","clk":"11541356429","pt":1719504906583,"mc":[{"id":"1.230180131","rc":[{"atb":[[2.62,12.38]],"id":58149406}],"con":true,"img":false}]}
{"op":"mcm","clk":"11541356441","pt":1719504906684,"mc":[{"id":"1.230180131","rc":[{"atb":[[2.58,0]],"id":58149406}],"con":true,"img":false}]}
{"op":"mcm","clk":"11541356451","pt":1719504906781,"mc":[{"id":"1.230180131","rc":[{"atb":[[2.6,0]],"id":58149406},{"atb":[[3,0]],"id":43210435}],"con":true,"img":false}]}
{"op":"mcm","clk":"11541356459","pt":1719504906883,"mc":[{"id":"1.230180131","rc":[{"atb":[[3,1.94]],"id":43210435},{"atb":[[2.18,1.94]],"id":66499052},{"atl":[[2.04,0.84]],"id":69979297}],"con":true,"img":false}]}
{"op":"mcm","clk":"11541356467","pt":1719504906998,"mc":[{"id":"1.230180131","rc":[{"atb":[[2.18,4.99]],"id":66499052}],"con":true,"img":false}]}
{"op":"mcm","clk":"11541356488","pt":1719504907197,"mc":[{"id":"1.230180131","rc":[{"atb":[[2.16,2]],"id":66499052}],"con":true,"img":false}]}
{"op":"mcm","clk":"11541356562","pt":1719504907976,"mc":[{"id":"1.230180131","rc":[{"atb":[[2.16,0]],"id":66499052}],"con":true,"img":false}]}
{"op":"mcm","clk":"11541356572","pt":1719504908091,"mc":[{"id":"1.230180131","rc":[{"atb":[[2.2,2]],"id":66499052}],"con":true,"img":false}]}
{"op":"mcm","clk":"11541356613","pt":1719504908492,"mc":[{"id":"1.230180131","rc":[{"atb":[[2.62,9.38]],"id":58149406},{"atb":[[2.98,0]],"id":43210435},{"atl":[[3.95,3.93]],"id":66499052},{"atb":[[3.95,0]],"id":51843546}],"con":true,"img":false}]}
{"op":"mcm","clk":"11541356632","pt":1719504908707,"mc":[{"id":"1.230180131","rc":[{"atb":[[2.64,2.9]],"id":58149406},{"atb":[[3,4]],"id":43210435},{"atl":[[4,0]],"id":66499052}],"con":true,"img":false}]}
{"op":"mcm","clk":"11541356644","pt":1719504908813,"mc":[{"id":"1.230180131","rc":[{"atl":[[3.7,8.47]],"id":66499052},{"atl":[[2.08,18.28]],"id":69979297}],"con":true,"img":false}]}
{"op":"mcm","clk":"11541356654","pt":1719504908914,"mc":[{"id":"1.230180131","rc":[{"atb":[[3,11.94]],"id":43210435},{"atl":[[4.1,0],[3.8,16.94],[4.2,2.5]],"id":66499052}],"con":true,"img":false}]}
{"op":"mcm","clk":"11541356665","pt":1719504908976,"mc":[{"id":"1.230180131","rc":[{"atb":[[2.96,0]],"id":43210435}],"con":true,"img":false}]}
{"op":"mcm","clk":"11541356707","pt":1719504909379,"mc":[{"id":"1.230180131","rc":[{"atl":[[3.65,0.84]],"id":66499052}],"con":true,"img":false}]}
{"op":"mcm","clk":"11541356717","pt":1719504909480,"mc":[{"id":"1.230180131","rc":[{"atl":[[3.95,3.09]],"id":66499052}],"con":true,"img":false}]}
{"op":"mcm","clk":"11541356744","pt":1719504909863,"mc":[{"id":"1.230180131","rc":[{"atb":[[2.62,7.44]],"id":58149406}],"con":true,"img":false}]}
{"op":"mcm","clk":"11541356751","pt":1719504909901,"mc":[{"id":"1.230180131","rc":[{"atb":[[2.66,1.94]],"id":58149406}],"con":true,"img":false}]}
{"op":"mcm","clk":"11541356883","pt":1719504911298,"mc":[{"id":"1.230180131","rc":[{"atb":[[3.9,0]],"id":51843546}],"con":true,"img":false}]}
{"op":"mcm","clk":"11541356922","pt":1719504911722,"mc":[{"id":"1.230180131","rc":[{"atb":[[1.07,3]],"id":51843546},{"atb":[[1.34,10.61]],"id":69979297}],"con":true,"img":false}]}
{"op":"mcm","clk":"11541356940","pt":1719504911893,"mc":[{"id":"1.230180131","rc":[{"atb":[[1.07,2.63]],"id":51843546},{"atl":[[2.08,13.04]],"id":69979297}],"con":true,"img":false}]}
{"op":"mcm","clk":"11541356957","pt":1719504912091,"mc":[{"id":"1.230180131","rc":[{"atb":[[1.07,2.48]],"id":51843546}],"con":true,"img":false}]}
{"op":"mcm","clk":"11541356968","pt":1719504912188,"mc":[{"id":"1.230180131","rc":[{"atb":[[4.3,0.15]],"id":51843546}],"con":true,"img":false}]}
{"op":"mcm","clk":"11541356975","pt":1719504912294,"mc":[{"id":"1.230180131","rc":[{"atb":[[2.28,7.75],[2.18,0]],"id":41138102},{"atb":[[2.88,23.9]],"id":43210435},{"atb":[[2.14,9.11]],"id":66499052},{"atl":[[3.85,16.94]],"id":66499052},{"atb":[[2.98,7.5],[2.88,0],[4.2,9.92]],"id":51843546}],"con":true,"img":false}]}
{"op":"mcm","clk":"11541356986","pt":1719504912393,"mc":[{"id":"1.230180131","rc":[{"atb":[[2.86,0]],"id":43210435},{"atb":[[2.06,0]],"id":66499052},{"atl":[[3.8,0]],"id":66499052}],"con":true,"img":false}]}
{"op":"mcm","clk":"11541357025","pt":1719504912805,"mc":[{"id":"1.230180131","rc":[{"atb":[[2.66,0]],"id":58149406}],"con":true,"img":false}]}
{"op":"mcm","clk":"11541357034","pt":1719504912907,"mc":[{"id":"1.230180131","rc":[{"atb":[[2.66,1.94]],"id":58149406}],"con":true,"img":false}]}
{"op":"mcm","clk":"11541357250","pt":1719504915823,"mc":[{"id":"1.230180131","rc":[{"atb":[[2.66,0]],"id":58149406}],"con":true,"img":false}]}
{"op":"mcm","clk":"11541357258","pt":1719504915878,"mc":[{"id":"1.230180131","rc":[{"atb":[[4.4,1]],"id":51843546}],"con":true,"img":false}]}
{"op":"mcm","clk":"11541357265","pt":1719504915984,"mc":[{"id":"1.230180131","rc":[{"atb":[[2.66,1.94]],"id":58149406}],"con":true,"img":false}]}
{"op":"mcm","clk":"11541357339","pt":1719504916810,"mc":[{"id":"1.230180131","rc":[{"atb":[[2.66,7.84]],"id":58149406}],"con":true,"img":false}]}
{"op":"mcm","clk":"11541357356","pt":1719504917014,"mc":[{"id":"1.230180131","rc":[{"atb":[[2.62,0]],"id":58149406}],"con":true,"img":false}]}
{"op":"mcm","clk":"11541357374","pt":1719504917222,"mc":[{"id":"1.230180131","rc":[{"atb":[[2.2,12.1]],"id":66499052}],"con":true,"img":false}]}
{"op":"mcm","clk":"11541357382","pt":1719504917325,"mc":[{"id":"1.230180131","rc":[{"atb":[[2.6,3.45]],"id":58149406},{"atb":[[2.18,1.94]],"id":66499052}],"con":true,"img":false}]}
{"op":"mcm","clk":"11541357391","pt":1719504917425,"mc":[{"id":"1.230180131","rc":[{"atb":[[2.64,0]],"id":58149406}],"con":true,"img":false}]}
{"op":"mcm","clk":"11541357401","pt":1719504917482,"mc":[{"id":"1.230180131","rc":[{"atb":[[2.68,2]],"id":58149406},{"atb":[[4.4,3]],"id":51843546}],"con":true,"img":false}]}
{"op":"mcm","clk":"11541357426","pt":1719504917789,"mc":[{"id":"1.230180131","rc":[{"atb":[[2.6,0]],"id":58149406}],"con":true,"img":false}]}
{"op":"mcm","clk":"11541357433","pt":1719504917896,"mc":[{"id":"1.230180131","rc":[{"atb":[[4.2,9.03]],"id":51843546}],"con":true,"img":false}]}
{"op":"mcm","clk":"11541357440","pt":1719504917996,"mc":[{"id":"1.230180131","rc":[{"atb":[[4.2,0]],"id":51843546}],"con":true,"img":false}]}
{"op":"mcm","clk":"11541357449","pt":1719504918099,"mc":[{"id":"1.230180131","rc":[{"atb":[[4.4,10.03],[4.5,2]],"id":51843546}],"con":true,"img":false}]}
{"op":"mcm","clk":"11541357459","pt":1719504918202,"mc":[{"id":"1.230180131","rc":[{"atb":[[4.4,9.03]],"id":51843546}],"con":true,"img":false}]}
{"op":"mcm","clk":"11541357469","pt":1719504918305,"mc":[{"id":"1.230180131","rc":[{"atb":[[2.06,11.62],[2.14,2.11]],"id":66499052},{"atl":[[3.85,0],[3.75,9.32]],"id":66499052}],"con":true,"img":false}]}
{"op":"mcm","clk":"11541357504","pt":1719504918723,"mc":[{"id":"1.230180131","rc":[{"atl":[[3.65,8.78]],"id":66499052}],"con":true,"img":false}]}
{"op":"mcm","clk":"11541357514","pt":1719504918822,"mc":[{"id":"1.230180131","rc":[{"atb":[[2.18,0]],"id":66499052},{"atl":[[3.95,0]],"id":66499052},{"atb":[[4.4,8.55]],"id":51843546}],"con":true,"img":false}]}
{"op":"mcm","clk":"11541357525","pt":1719504918928,"mc":[{"id":"1.230180131","rc":[{"atb":[[4.4,2]],"id":51843546}],"con":true,"img":false}]}
{"op":"mcm","clk":"11541357531","pt":1719504919032,"mc":[{"id":"1.230180131","rc":[{"atb":[[4.5,8.55]],"id":51843546}],"con":true,"img":false}]}
{"op":"mcm","clk":"11541357646","pt":1719504920587,"mc":[{"id":"1.230180131","rc":[{"atb":[[2.26,2.11],[2.14,0]],"id":66499052}],"con":true,"img":false}]}
{"op":"mcm","clk":"11541357661","pt":1719504920792,"mc":[{"id":"1.230180131","rc":[{"atb":[[4.6,1]],"id":51843546}],"con":true,"img":false}]}
{"op":"mcm","clk":"11541357737","pt":1719504921909,"mc":[{"id":"1.230180131","rc":[{"atb":[[2.2,10.1]],"id":66499052}],"con":true,"img":false}]}
{"op":"mcm","clk":"11541357740","pt":1719504922017,"mc":[{"id":"1.230180131","rc":[{"atb":[[2.28,2]],"id":66499052}],"con":true,"img":false}]}
{"op":"mcm","clk":"11541357829","pt":1719504923210,"mc":[{"id":"1.230180131","rc":[{"atb":[[2.98,0],[2.86,5]],"id":51843546}],"con":true,"img":false}]}
{"op":"mcm","clk":"11541358051","pt":1719504926111,"mc":[{"id":"1.230180131","rc":[{"spn":3.64,"spf":"NaN","id":58149406},{"spn":5.15,"spf":"NaN","id":41138102},{"spn":4.9,"spf":"NaN","id":43210435},{"spn":2.96,"spf":"NaN","id":66499052},{"atb":[[4.4,0]],"id":51843546},{"spn":6.0,"spf":"NaN","id":51843546},{"spn":1.75,"spf":"NaN","id":69979297}],"con":true,"img":false}]}
{"op":"mcm","clk":"11541358060","pt":1719504926212,"mc":[{"id":"1.230180131","rc":[{"atb":[[3.55,2]],"id":41138102},{"atb":[[4.6,3.4]],"id":51843546}],"con":true,"img":false}]}
{"op":"mcm","clk":"11541358078","pt":1719504926523,"mc":[{"id":"1.230180131","rc":[{"atb":[[4.5,7.57]],"id":51843546}],"con":true,"img":false}]}
{"op":"mcm","clk":"11541358084","pt":1719504926627,"mc":[{"id":"1.230180131","rc":[{"atb":[[4.5,2]],"id":51843546}],"con":true,"img":false}]}
{"op":"mcm","clk":"11541358091","pt":1719504926734,"mc":[{"id":"1.230180131","rc":[{"atb":[[4.6,8.97]],"id":51843546}],"con":true,"img":false}]}
{"op":"mcm","clk":"11541358100","pt":1719504926844,"mc":[{"id":"1.230180131","rc":[{"atb":[[2.68,7.23]],"id":58149406}],"con":true,"img":false}]}
{"op":"mcm","clk":"11541358113","pt":1719504926987,"mc":[{"id":"1.230180131","rc":[{"atb":[[2.66,1.94]],"id":58149406}],"con":true,"img":false}]}
{"op":"mcm","clk":"11541358122","pt":1719504927199,"mc":[{"id":"1.230180131","rc":[{"atb":[[2.28,14.94]],"id":66499052}],"con":true,"img":false}]}
{"op":"mcm","clk":"11541358128","pt":1719504927303,"mc":[{"id":"1.230180131","rc":[{"atb":[[2.2,0]],"id":66499052}],"con":true,"img":false}]}
{"op":"mcm","clk":"11541358132","pt":1719504927407,"mc":[{"id":"1.230180131","rc":[{"atl":[[2.06,19.61]],"id":69979297}],"con":true,"img":false}]}
{"op":"mcm","clk":"11541358142","pt":1719504927616,"mc":[{"id":"1.230180131","rc":[{"atb":[[4.3,0]],"id":51843546}],"con":true,"img":false}]}
{"op":"mcm","clk":"11541358160","pt":1719504927826,"mc":[{"id":"1.230180131","rc":[{"atb":[[2.66,0]],"id":58149406},{"atb":[[4.5,0]],"id":51843546}],"con":true,"img":false}]}
{"op":"mcm","clk":"11541358168","pt":1719504927923,"mc":[{"id":"1.230180131","rc":[{"atb":[[4.7,2]],"id":51843546}],"con":true,"img":false}]}
{"op":"mcm","clk":"11541358173","pt":1719504928031,"mc":[{"id":"1.230180131","rc":[{"atb":[[2.7,1.94]],"id":58149406},{"atb":[[4.6,7.97]],"id":51843546}],"con":true,"img":false}]}
{"op":"mcm","clk":"11541358185","pt":1719504928185,"mc":[{"id":"1.230180131","rc":[{"atb":[[4.6,2.4]],"id":51843546}],"con":true,"img":false}]}
{"op":"mcm","clk":"11541358291","pt":1719504929797,"mc":[{"id":"1.230180131","rc":[{"atb":[[4.7,8.3]],"id":51843546}],"con":true,"img":false}]}
{"op":"mcm","clk":"11541358371","pt":1719504930835,"mc":[{"id":"1.230180131","rc":[{"atb":[[2.7,0]],"id":58149406}],"con":true,"img":false}]}
{"op":"mcm","clk":"11541358381","pt":1719504930937,"mc":[{"id":"1.230180131","rc":[{"atb":[[4.8,1]],"id":51843546}],"con":true,"img":false}]}
{"op":"mcm","clk":"11541358391","pt":1719504931041,"mc":[{"id":"1.230180131","rc":[{"atb":[[2.7,1.94]],"id":58149406}],"con":true,"img":false}]}
{"op":"mcm","clk":"11541358454","pt":1719504931811,"mc":[{"id":"1.230180131","rc":[{"atb":[[2.68,5.23]],"id":58149406},{"atb":[[4.6,0]],"id":51843546}],"con":true,"img":false}]}
{"op":"mcm","clk":"11541358460","pt":1719504931914,"mc":[{"id":"1.230180131","rc":[{"atb":[[2.7,3.94]],"id":58149406},{"atb":[[4.8,3]],"id":51843546}],"con":true,"img":false}]}
{"op":"mcm","clk":"11541358484","pt":1719504932225,"mc":[{"id":"1.230180131","rc":[{"atl":[[2.1,0]],"id":69979297}],"con":true,"img":false}]}
{"op":"mcm","clk":"11541358513","pt":1719504932539,"mc":[{"id":"1.230180131","rc":[{"atl":[[2.08,19.67]],"id":69979297}],"con":true,"img":false}]}
{"op":"mcm","clk":"11541358535","pt":1719504932797,"mc":[{"id":"1.230180131","rc":[{"atb":[[4.7,6.3]],"id":51843546}],"con":true,"img":false}]}
{"op":"mcm","clk":"11541358545","pt":1719504932903,"mc":[{"id":"1.230180131","rc":[{"atb":[[1.02,2]],"id":51843546}],"con":true,"img":false}]}
{"op":"mcm","clk":"11541358554","pt":1719504933007,"mc":[{"id":"1.230180131","rc":[{"atb":[[4.7,6.1]],"id":51843546}],"con":true,"img":false}]}
{"op":"mcm","clk":"11541358566","pt":1719504933108,"mc":[{"id":"1.230180131","rc":[{"atl":[[2.08,13.04]],"id":69979297}],"con":true,"img":false}]}
{"op":"mcm","clk":"11541358583","pt":1719504933314,"mc":[{"id":"1.230180131","rc":[{"atl":[[2.08,16.8]],"id":69979297}],"con":true,"img":false}]}
{"op":"mcm","clk":"11541358592","pt":1719504933420,"mc":[{"id":"1.230180131","rc":[{"atb":[[4.7,0]],"id":51843546}],"con":true,"img":false}]}
{"op":"mcm","clk":"11541358603","pt":1719504933520,"mc":[{"id":"1.230180131","rc":[{"atb":[[4.8,9.1]],"id":51843546}],"con":true,"img":false}]}
{"op":"mcm","clk":"11541358610","pt":1719504933628,"mc":[{"id":"1.230180131","rc":[{"atb":[[4.8,8.1]],"id":51843546}],"con":true,"img":false}]}
{"op":"mcm","clk":"11541358663","pt":1719504934304,"mc":[{"id":"1.230180131","rc":[{"atb":[[4.8,2]],"id":51843546}],"con":true,"img":false}]}
{"op":"mcm","clk":"11541358724","pt":1719504934924,"mc":[{"id":"1.230180131","rc":[{"atl":[[2.08,13.04]],"id":69979297}],"con":true,"img":false}]}
{"op":"mcm","clk":"11541358766","pt":1719504935340,"mc":[{"id":"1.230180131","rc":[{"atl":[[2.08,18.03]],"id":69979297}],"con":true,"img":false}]}
{"op":"mcm","clk":"11541358781","pt":1719504935496,"mc":[{"id":"1.230180131","rc":[{"atb":[[2.66,3.33]],"id":58149406}],"con":true,"img":false}]}
{"op":"mcm","clk":"11541358790","pt":1719504935599,"mc":[{"id":"1.230180131","rc":[{"atb":[[4.9,1]],"id":51843546}],"con":true,"img":false}]}
{"op":"mcm","clk":"11541358824","pt":1719504935913,"mc":[{"id":"1.230180131","rc":[{"atb":[[4.9,6.2]],"id":51843546}],"con":true,"img":false}]}
{"op":"mcm","clk":"11541358899","pt":1719504936637,"mc":[{"id":"1.230180131","rc":[{"atb":[[2.7,10.63]],"id":58149406}],"con":true,"img":false}]}
{"op":"mcm","clk":"11541358918","pt":1719504936848,"mc":[{"id":"1.230180131","rc":[{"atb":[[2.68,0]],"id":58149406}],"con":true,"img":false}]}
{"op":"mcm","clk":"11541358953","pt":1719504937313,"mc":[{"id":"1.230180131","rc":[{"atb":[[2.66,0]],"id":58149406}],"con":true,"img":false}]}
{"op":"mcm","clk":"11541358963","pt":1719504937418,"mc":[{"id":"1.230180131","rc":[{"atb":[[1.08,50.52]],"id":51843546}],"con":true,"img":false}]}
{"op":"mcm","clk":"11541358969","pt":1719504937518,"mc":[{"id":"1.230180131","rc":[{"atb":[[1.08,50.13]],"id":51843546}],"con":true,"img":false}]}
{"op":"mcm","clk":"11541358979","pt":1719504937622,"mc":[{"id":"1.230180131","rc":[{"atb":[[2.7,8.63]],"id":58149406},{"atb":[[3,9.88]],"id":43210435},{"atb":[[4.8,0],[1.08,50]],"id":51843546}],"con":true,"img":false}]}
{"op":"mcm","clk":"11541358989","pt":1719504937729,"mc":[{"id":"1.230180131","rc":[{"atb":[[2.72,3.3]],"id":58149406},{"atb":[[3.05,2.4]],"id":43210435},{"atb":[[5,2.43]],"id":51843546}],"con":true,"img":false}]}
{"op":"mcm","clk":"11541358997","pt":1719504937827,"mc":[{"id":"1.230180131","rc":[{"atb":[[3.05,13.09]],"id":43210435},{"atb":[[4.9,5.2]],"id":51843546}],"con":true,"img":false}]}
{"op":"mcm","clk":"11541359015","pt":1719504938035,"mc":[{"id":"1.230180131","rc":[{"atb":[[3,1.94]],"id":43210435}],"con":true,"img":false}]}
{"op":"mcm","clk":"11541359028","pt":1719504938138,"mc":[{"id":"1.230180131","rc":[{"atl":[[3.7,26.05],[3.75,0]],"id":66499052}],"con":true,"img":false}]}
{"op":"mcm","clk":"11541359037","pt":1719504938241,"mc":[{"id":"1.230180131","rc":[{"atl":[[3.75,17.26]],"id":66499052}],"con":true,"img":false}]}
{"op":"mcm","clk":"11541359045","pt":1719504938295,"mc":[{"id":"1.230180131","rc":[{"atl":[[3.7,8.47]],"id":66499052}],"con":true,"img":false}]}
{"op":"mcm","clk":"11541359192","pt":1719504939808,"mc":[{"id":"1.230180131","rc":[{"atb":[[2.7,6.69]],"id":58149406},{"atb":[[3,0]],"id":43210435}],"con":true,"img":false}]}
{"op":"mcm","clk":"11541359201","pt":1719504939916,"mc":[{"id":"1.230180131","rc":[{"atb":[[5.1,1]],"id":51843546}],"con":true,"img":false}]}
{"op":"mcm","clk":"11541359210","pt":1719504940020,"mc":[{"id":"1.230180131","rc":[{"atb":[[2.74,1.94]],"id":58149406},{"atb":[[3.1,1.94]],"id":43210435}],"con":true,"img":false}]}
{"op":"mcm","clk":"11541359346","pt":1719504941625,"mc":[{"id":"1.230180131","rc":[{"atl":[[5.1,0],[5.2,1]],"id":58149406}],"con":true,"img":false}]}
{"op":"mcm","clk":"11541359359","pt":1719504941725,"mc":[{"id":"1.230180131","rc":[{"atl":[[5.1,9.94],[5.4,2.5]],"id":58149406}],"con":true,"img":false}]}
{"op":"mcm","clk":"11541359461","pt":1719504942880,"mc":[{"id":"1.230180131","rc":[{"atb":[[2.74,0]],"id":58149406},{"atb":[[3.1,0]],"id":43210435}],"con":true,"img":false}]}
{"op":"mcm","clk":"11541359479","pt":1719504943030,"mc":[{"id":"1.230180131","rc":[{"atb":[[2.74,1.94]],"id":58149406},{"atb":[[3.1,1.94]],"id":43210435}],"con":true,"img":false}]}
{"op":"mcm","clk":"11541359503","pt":1719504943339,"mc":[{"id":"1.230180131","rc":[{"atb":[[2.72,0]],"id":58149406},{"atb":[[3.05,10.69]],"id":43210435}],"con":true,"img":false}]}
{"op":"mcm","clk":"11541359513","pt":1719504943444,"mc":[{"id":"1.230180131","rc":[{"atb":[[2.74,4.34]],"id":58149406},{"atb":[[3.1,4.24]],"id":43210435},{"atb":[[1.34,5]],"id":69979297},{"atl":[[2.06,14.22]],"id":69979297}],"con":true,"img":false}]}
{"op":"mcm","clk":"11541359599","pt":1719504944422,"mc":[{"id":"1.230180131","rc":[{"atb":[[1.47,14.18]],"id":69979297}],"con":true,"img":false}]}
{"op":"mcm","clk":"11541359605","pt":1719504944522,"mc":[{"id":"1.230180131","rc":[{"atb":[[2.28,2]],"id":66499052},{"atb":[[1.43,0],[1.33,5.61]],"id":69979297}],"con":true,"img":false}]}
{"op":"mcm","clk":"11541359612","pt":1719504944733,"mc":[{"id":"1.230180131","rc":[{"atl":[[3.7,26.05],[3.75,0]],"id":66499052}],"con":true,"img":false}]}
{"op":"mcm","clk":"11541359628","pt":1719504944937,"mc":[{"id":"1.230180131","rc":[{"atb":[[2.12,2.11],[2.26,0]],"id":66499052}],"con":true,"img":false}]}
{"op":"mcm","clk":"11541359636","pt":1719504945051,"mc":[{"id":"1.230180131","rc":[{"atl":[[2.08,23.32]],"id":69979297}],"con":true,"img":false}]}
{"op":"mcm","clk":"11541359676","pt":1719504945454,"mc":[{"id":"1.230180131","rc":[{"atb":[[1.33,0]],"id":69979297}],"con":true,"img":false}]}
{"op":"mcm","clk":"11541359718","pt":1719504945820,"mc":[{"id":"1.230180131","rc":[{"atb":[[2.14,1.94]],"id":66499052}],"con":true,"img":false}]}
{"op":"mcm","clk":"11541359741","pt":1719504946032,"mc":[{"id":"1.230180131","rc":[{"atl":[[5.1,0],[5.2,15.91]],"id":58149406},{"atb":[[2.28,0]],"id":66499052}],"con":true,"img":false}]}
{"op":"mcm","clk":"11541359748","pt":1719504946127,"mc":[{"id":"1.230180131","rc":[{"atb":[[2.14,3.94]],"id":66499052}],"con":true,"img":false}]}
{"op":"mcm","clk":"11541359760","pt":1719504946234,"mc":[{"id":"1.230180131","rc":[{"atb":[[2.74,11.33]],"id":58149406},{"atb":[[2.26,3.75],[2.02,5],[2.06,0]],"id":66499052}],"con":true,"img":false}]}
{"op":"mcm","clk":"11541359777","pt":1719504946438,"mc":[{"id":"1.230180131","rc":[{"atb":[[2.7,0]],"id":58149406},{"atb":[[2.26,0]],"id":66499052}],"con":true,"img":false}]}
{"op":"mcm","clk":"11541359787","pt":1719504946540,"mc":[{"id":"1.230180131","rc":[{"atb":[[2.14,8.78]],"id":66499052}],"con":true,"img":false}]}
{"op":"mcm","clk":"11541359862","pt":1719504947416,"mc":[{"id":"1.230180131","rc":[{"atb":[[3.1,15.01]],"id":43210435}],"con":true,"img":false}]}
{"op":"mcm","clk":"11541359882","pt":1719504947625,"mc":[{"id":"1.230180131","rc":[{"atb":[[3.05,0]],"id":43210435}],"con":true,"img":false}]}
{"op":"mcm","clk":"11541359902","pt":1719504947831,"mc":[{"id":"1.230180131","rc":[{"atb":[[2.48,5],[2.28,0]],"id":41138102}],"con":true,"img":false}]}
{"op":"mcm","clk":"11541359913","pt":1719504947955,"mc":[{"id":"1.230180131","rc":[{"atl":[[5.2,14.91],[5.4,3.5]],"id":58149406}],"con":true,"img":false}]}
{"op":"mcm","clk":"11541359934","pt":1719504948141,"mc":[{"id":"1.230180131","rc":[{"atb":[[2.2,0],[2.34,14.24]],"id":58149406}],"con":true,"img":false}]}
{"op":"mcm","clk":"11541360018","pt":1719504949025,"mc":[{"id":"1.230180131","rc":[{"atl":[[8,1],[7.8,0]],"id":41138102},{"atl":[[8.8,0],[8.4,1]],"id":51843546}],"con":true,"img":false}]}
{"op":"mcm","clk":"11541360037","pt":1719504949231,"mc":[{"id":"1.230180131","rc":[{"atb":[[2.74,8.93]],"id":58149406},{"atb":[[3.1,12.71]],"id":43210435}],"con":true,"img":false}]}
{"op":"mcm","clk":"11541360047","pt":1719504949335,"mc":[{"id":"1.230180131","rc":[{"atb":[[2.76,2.7]],"id":58149406},{"atb":[[3.15,3]],"id":43210435}],"con":true,"img":false}]}
{"op":"mcm","clk":"11541360077","pt":1719504949641,"mc":[{"id":"1.230180131","rc":[{"atb":[[2.8,25.44],[2.88,0]],"id":43210435},{"atb":[[1.47,2]],"id":69979297}],"con":true,"img":false}]}
{"op":"mcm","clk":"11541360124","pt":1719504950161,"mc":[{"id":"1.230180131","rc":[{"atl":[[8.4,3.79]],"id":51843546}],"con":true,"img":false}]}
{"op":"mcm","clk":"11541360160","pt":1719504950526,"mc":[{"id":"1.230180131","rc":[{"atb":[[3.1,0],[3.35,5],[3.55,4.5],[3.5,0],[3.3,0.24]],"id":41138102}],"con":true,"img":false}]}
{"op":"mcm","clk":"11541360252","pt":1719504951883,"mc":[{"id":"1.230180131","rc":[{"atb":[[2.74,6.99]],"id":58149406},{"atb":[[3.1,10.77]],"id":43210435}],"con":true,"img":false}]}
{"op":"mcm","clk":"11541360270","pt":1719504952033,"mc":[{"id":"1.230180131","rc":[{"atb":[[2.78,1.94]],"id":58149406},{"atb":[[3.2,1.94]],"id":43210435}],"con":true,"img":false}]}
{"op":"mcm","clk":"11541360337","pt":1719504952770,"mc":[{"id":"1.230180131","rc":[{"atb":[[2.72,3.21]],"id":58149406}],"con":true,"img":false}]}
{"op":"mcm","clk":"11541360367","pt":1719504953066,"mc":[{"id":"1.230180131","rc":[{"atb":[[5,2.3]],"id":51843546}],"con":true,"img":false}]}
{"op":"mcm","clk":"11541360512","pt":1719504954774,"mc":[{"id":"1.230180131","rc":[{"atb":[[2.48,0],[2.36,10]],"id":41138102}],"con":true,"img":false}]}
{"op":"mcm","clk":"11541360522","pt":1719504954872,"mc":[{"id":"1.230180131","rc":[{"atb":[[2.76,0],[2.78,0]],"id":58149406},{"atl":[[5.5,1],[5.4,2.5]],"id":58149406},{"atb":[[3.2,0],[3.15,0]],"id":43210435}],"con":true,"img":false}]}
