{"op":"mcm","clk":"11536380636","pt":1719425245566,"mc":[{"id":"1.230178306","marketDefinition":{"bspMarket":true,"turnInPlayEnabled":false,"persistenceEnabled":false,"marketBaseRate":5.0,"eventId":"33376062","eventTypeId":"4339","numberOfWinners":1,"bettingType":"ODDS","marketType":"WIN","marketTime":"2024-06-27T13:36:00.000Z","suspendTime":"2024-06-27T13:36:00.000Z","bspReconciled":false,"complete":true,"inPlay":false,"crossMatching":false,"runnersVoidable":false,"numberOfActiveRunners":6,"betDelay":0,"status":"OPEN","runners":[{"status":"ACTIVE","sortPriority":1,"id":61496663,"name":"1. Glory Bomber"},{"status":"ACTIVE","sortPriority":2,"id":47801105,"name":"2. Lady Casey"},{"status":"ACTIVE","sortPriority":3,"id":47095746,"name":"3. Zipping Rush"},{"status":"ACTIVE","sortPriority":4,"id":53893973,"name":"4. Marinas Ollie"},{"status":"ACTIVE","sortPriority":5,"id":53987475,"name":"5. Brynoffa Alice"},{"status":"ACTIVE","sortPriority":6,"id":66596720,"name":"6. Ashville Bucko"}],"regulators":["MR_INT"],"venue":"Kinsley","countryCode":"GB","discountAllowed":false,"timezone":"Europe/London","openDate":"2024-06-27T13:36:00.000Z","version":5994643741,"name":"D3 268m","eventName":"Kinsley 27th Jun"},"rc":[],"con":true,"img":false}]}
{"op":"mcm","clk":"11536380897","pt":1719425247549,"mc":[{"id":"1.230178306","marketDefinition":{"bspMarket":true,"turnInPlayEnabled":false,"persistenceEnabled":false,"marketBaseRate":5.0,"eventId":"33376062","eventTypeId":"4339","numberOfWinners":1,"bettingType":"ODDS","marketType":"WIN","marketTime":"2024-06-27T13:36:00.000Z","suspendTime":"2024-06-27T13:36:00.000Z","bspReconciled":false,"complete":true,"inPlay":false,"crossMatching":false,"runnersVoidable":false,"numberOfActiveRunners":6,"betDelay":0,"status":"OPEN","runners":[{"status":"ACTIVE","sortPriority":1,"id":61496663,"name":"1. Glory Bomber"},{"status":"ACTIVE","sortPriority":2,"id":47801105,"name":"2. Lady Casey"},{"status":"ACTIVE","sortPriority":3,"id":47095746,"name":"3. Zipping Rush"},{"status":"ACTIVE","sortPriority":4,"id":53893973,"name":"4. Marinas Ollie"},{"status":"ACTIVE","sortPriority":5,"id":53987475,"name":"5. Brynoffa Alice"},{"status":"ACTIVE","sortPriority":6,"id":66596720,"name":"6. Ashville Bucko"}],"regulators":["MR_INT"],"venue":"Kinsley","countryCode":"GB","discountAllowed":true,"timezone":"Europe/London","openDate":"2024-06-27T13:36:00.000Z","version":5994643741,"name":"D3 268m","eventName":"Kinsley 27th Jun"},"rc":[],"con":true,"img":false}]}
{"op":"mcm","clk":"11536615255","pt":1719428245720,"mc":[{"id":"1.230178306","rc":[{"atb":[[1.03,15.09]],"id":47801105},{"atl":[[1000,0.84]],"id":47801105},{"spn":500.51,"spf":"NaN","id":47801105},{"atb":[[1.03,15.09]],"id":53893973},{"atl":[[990,0.84]],"id":53893973},{"spn":495.51,"spf":"NaN","id":53893973},{"atb":[[1.03,15.09]],"id":47095746},{"atl":[[1000,0.84]],"id":47095746},{"spn":500.51,"spf":"NaN","id":47095746},{"atb":[[1.01,45.27]],"id":61496663},{"atl":[[990,0.84]],"id":61496663},{"spn":495.5,"spf":"NaN","id":61496663},{"atb":[[1.01,45.27]],"id":66596720},{"atl":[[1000,0.84]],"id":66596720},{"spn":500.5,"spf":"NaN","id":66596720},{"atb":[[1.03,15.09]],"id":53987475},{"atl":[[1000,0.84]],"id":53987475},{"spn":500.51,"spf":"NaN","id":53987475}],"con":true,"img":false}]}
{"op":"mcm","clk":"11536837043","pt":1719431853526,"mc":[{"id":"1.230178306","rc":[{"atb":[[1.03,15.09]],"id":47801105},{"atl":[[1000,0.26]],"id":47801105},{"atb":[[1.03,15.09]],"id":53893973},{"atl":[[990,0.26]],"id":53893973},{"atb":[[1.03,15.09]],"id":47095746},{"atl":[[1000,0.26]],"id":47095746},{"atb":[[1.01,45.28]],"id":61496663},{"atl":[[990,0.26]],"id":61496663},{"atb":[[1.01,45.28]],"id":66596720},{"atl":[[1000,0.26]],"id":66596720},{"atb":[[1.03,15.09]],"id":53987475},{"atl":[[1000,0.26]],"id":53987475}],"con":true,"img":false}]}
{"op":"mcm","clk":"11537232225","pt":1719437882514,"mc":[{"id":"1.230178306","marketDefinition":{"bspMarket":true,"turnInPlayEnabled":false,"persistenceEnabled":false,"marketBaseRate":5.0,"eventId":"33376062","eventTypeId":"4339","numberOfWinners":1,"bettingType":"ODDS","marketType":"WIN","marketTime":"2024-06-27T13:36:00.000Z","suspendTime":"2024-06-27T13:36:00.000Z","bspReconciled":false,"complete":true,"inPlay":false,"crossMatching":false,"runnersVoidable":false,"numberOfActiveRunners":6,"betDelay":0,"status":"OPEN","runners":[{"status":"ACTIVE","sortPriority":1,"id":61496663,"name":"1. Glory Bomber"},{"status":"ACTIVE","sortPriority":2,"id":47801105,"name":"2. Lady Casey"},{"status":"ACTIVE","sortPriority":3,"id":47095746,"name":"3. Zipping Rush"},{"status":"ACTIVE","sortPriority":4,"id":53893973,"name":"4. Marinas Ollie"},{"status":"ACTIVE","sortPriority":5,"id":53987475,"name":"5. Brynoffa Alice"},{"status":"ACTIVE","sortPriority":6,"id":66596720,"name":"6. Ashville Bucko"}],"regulators":["MR_INT"],"venue":"Kinsley","countryCode":"GB","discountAllowed":true,"timezone":"Europe/London","openDate":"2024-06-27T13:36:00.000Z","version":5994643741,"name":"D3 268m","eventName":"Kinsley 27th Jun"},"rc":[{"atb":[[1.03,15.09]],"id":47801105},{"atl":[[1000,0.26]],"id":47801105},{"spn":500.51,"spf":"NaN","id":47801105},{"atb":[[1.03,15.09]],"id":53893973},{"atl":[[990,0.26]],"id":53893973},{"spn":495.51,"spf":"NaN","id":53893973},{"atb":[[1.03,15.09]],"id":47095746},{"atl":[[1000,0.26]],"id":47095746},{"spn":500.51,"spf":"NaN","id":47095746},{"atb":[[1.01,45.28]],"id":61496663},{"atl":[[990,0.26]],"id":61496663},{"spn":495.5,"spf":"NaN","id":61496663},{"atb":[[1.01,45.28]],"id":66596720},{"atl":[[1000,0.26]],"id":66596720},{"spn":500.5,"spf":"NaN","id":66596720},{"atb":[[1.03,15.09]],"id":53987475},{"atl":[[1000,0.26]],"id":53987475},{"spn":500.51,"spf":"NaN","id":53987475}],"con":true,"img":true}]}
{"op":"mcm","clk":"11537573352","pt":1719443282535,"mc":[{"id":"1.230178306","marketDefinition":{"bspMarket":true,"turnInPlayEnabled":false,"persistenceEnabled":false,"marketBaseRate":5.0,"eventId":"33376062","eventTypeId":"4339","numberOfWinners":1,"bettingType":"ODDS","marketType":"WIN","marketTime":"2024-06-27T13:36:00.000Z","suspendTime":"2024-06-27T13:36:00.000Z","bspReconciled":false,"complete":true,"inPlay":false,"crossMatching":false,"runnersVoidable":false,"numberOfActiveRunners":6,"betDelay":0,"status":"OPEN","runners":[{"status":"ACTIVE","sortPriority":1,"id":61496663,"name":"1. Glory Bomber"},{"status":"ACTIVE","sortPriority":2,"id":47801105,"name":"2. Lady Casey"},{"status":"ACTIVE","sortPriority":3,"id":47095746,"name":"3. Zipping Rush"},{"status":"ACTIVE","sortPriority":4,"id":53893973,"name":"4. Marinas Ollie"},{"status":"ACTIVE","sortPriority":5,"id":53987475,"name":"5. Brynoffa Alice"},{"status":"ACTIVE","sortPriority":6,"id":66596720,"name":"6. Ashville Bucko"}],"regulators":["MR_INT"],"venue":"Kinsley","countryCode":"GB","discountAllowed":true,"timezone":"Europe/London","openDate":"2024-06-27T13:36:00.000Z","version":5994643741,"name":"D3 268m","eventName":"Kinsley 27th Jun"},"rc":[{"atb":[[1.03,15.09]],"id":47801105},{"atl":[[1000,0.26]],"id":47801105},{"spn":500.51,"spf":"NaN","id":47801105},{"atb":[[1.03,15.09]],"id":53893973},{"atl":[[990,0.26]],"id":53893973},{"spn":495.51,"spf":"NaN","id":53893973},{"atb":[[1.03,15.09]],"id":47095746},{"atl":[[1000,0.26]],"id":47095746},{"spn":500.51,"spf":"NaN","id":47095746},{"atb":[[1.01,45.29]],"id":61496663},{"atl":[[990,0.26]],"id":61496663},{"spn":495.5,"spf":"NaN","id":61496663},{"atb":[[1.01,45.29]],"id":66596720},{"atl":[[1000,0.26]],"id":66596720},{"spn":500.5,"spf":"NaN","id":66596720},{"atb":[[1.03,15.09]],"id":53987475},{"atl":[[1000,0.26]],"id":53987475},{"spn":500.51,"spf":"NaN","id":53987475}],"con":true,"img":true}]}
{"op":"mcm","clk":"11537954912","pt":1719448682555,"mc":[{"id":"1.230178306","marketDefinition":{"bspMarket":true,"turnInPlayEnabled":false,"persistenceEnabled":false,"marketBaseRate":5.0,"eventId":"33376062","eventTypeId":"4339","numberOfWinners":1,"bettingType":"ODDS","marketType":"WIN","marketTime":"2024-06-27T13:36:00.000Z","suspendTime":"2024-06-27T13:36:00.000Z","bspReconciled":false,"complete":true,"inPlay":false,"crossMatching":false,"runnersVoidable":false,"numberOfActiveRunners":6,"betDelay":0,"status":"OPEN","runners":[{"status":"ACTIVE","sortPriority":1,"id":61496663,"name":"1. Glory Bomber"},{"status":"ACTIVE","sortPriority":2,"id":47801105,"name":"2. Lady Casey"},{"status":"ACTIVE","sortPriority":3,"id":47095746,"name":"3. Zipping Rush"},{"status":"ACTIVE","sortPriority":4,"id":53893973,"name":"4. Marinas Ollie"},{"status":"ACTIVE","sortPriority":5,"id":53987475,"name":"5. Brynoffa Alice"},{"status":"ACTIVE","sortPriority":6,"id":66596720,"name":"6. Ashville Bucko"}],"regulators":["MR_INT"],"venue":"Kinsley","countryCode":"GB","discountAllowed":true,"timezone":"Europe/London","openDate":"2024-06-27T13:36:00.000Z","version":5994643741,"name":"D3 268m","eventName":"Kinsley 27th Jun"},"rc":[{"atb":[[1.03,15.09]],"id":47801105},{"atl":[[1000,0.26]],"id":47801105},{"spn":500.51,"spf":"NaN","id":47801105},{"atb":[[1.03,15.09]],"id":53893973},{"atl":[[990,0.26]],"id":53893973},{"spn":495.51,"spf":"NaN","id":53893973},{"atb":[[1.03,15.09]],"id":47095746},{"atl":[[1000,0.26]],"id":47095746},{"spn":500.51,"spf":"NaN","id":47095746},{"atb":[[1.01,45.28]],"id":61496663},{"atl":[[990,0.26]],"id":61496663},{"spn":495.5,"spf":"NaN","id":61496663},{"atb":[[1.01,45.28]],"id":66596720},{"atl":[[1000,0.26]],"id":66596720},{"spn":500.5,"spf":"NaN","id":66596720},{"atb":[[1.03,15.09]],"id":53987475},{"atl":[[1000,0.26]],"id":53987475},{"spn":500.51,"spf":"NaN","id":53987475}],"con":true,"img":true}]}
{"op":"mcm","clk":"11538170575","pt":1719454082533,"mc":[{"id":"1.230178306","marketDefinition":{"bspMarket":true,"turnInPlayEnabled":false,"persistenceEnabled":false,"marketBaseRate":5.0,"eventId":"33376062","eventTypeId":"4339","numberOfWinners":1,"bettingType":"ODDS","marketType":"WIN","marketTime":"2024-06-27T13:36:00.000Z","suspendTime":"2024-06-27T13:36:00.000Z","bspReconciled":false,"complete":true,"inPlay":false,"crossMatching":false,"runnersVoidable":false,"numberOfActiveRunners":6,"betDelay":0,"status":"OPEN","runners":[{"status":"ACTIVE","sortPriority":1,"id":61496663,"name":"1. Glory Bomber"},{"status":"ACTIVE","sortPriority":2,"id":47801105,"name":"2. Lady Casey"},{"status":"ACTIVE","sortPriority":3,"id":47095746,"name":"3. Zipping Rush"},{"status":"ACTIVE","sortPriority":4,"id":53893973,"name":"4. Marinas Ollie"},{"status":"ACTIVE","sortPriority":5,"id":53987475,"name":"5. Brynoffa Alice"},{"status":"ACTIVE","sortPriority":6,"id":66596720,"name":"6. Ashville Bucko"}],"regulators":["MR_INT"],"venue":"Kinsley","countryCode":"GB","discountAllowed":true,"timezone":"Europe/London","openDate":"2024-06-27T13:36:00.000Z","version":5994643741,"name":"D3 268m","eventName":"Kinsley 27th Jun"},"rc":[{"atb":[[1.03,15.09]],"id":47801105},{"atl":[[1000,0.26]],"id":47801105},{"spn":500.51,"spf":"NaN","id":47801105},{"atb":[[1.03,15.09]],"id":53893973},{"atl":[[990,0.26]],"id":53893973},{"spn":495.51,"spf":"NaN","id":53893973},{"atb":[[1.03,15.09]],"id":47095746},{"atl":[[1000,0.26]],"id":47095746},{"spn":500.51,"spf":"NaN","id":47095746},{"atb":[[1.01,45.29]],"id":61496663},{"atl":[[990,0.26]],"id":61496663},{"spn":495.5,"spf":"NaN","id":61496663},{"atb":[[1.01,45.29]],"id":66596720},{"atl":[[1000,0.26]],"id":66596720},{"spn":500.5,"spf":"NaN","id":66596720},{"atb":[[1.03,15.09]],"id":53987475},{"atl":[[1000,0.26]],"id":53987475},{"spn":500.51,"spf":"NaN","id":53987475}],"con":true,"img":true}]}
{"op":"mcm","clk":"11538368233","pt":1719459482560,"mc":[{"id":"1.230178306","marketDefinition":{"bspMarket":true,"turnInPlayEnabled":false,"persistenceEnabled":false,"marketBaseRate":5.0,"eventId":"33376062","eventTypeId":"4339","numberOfWinners":1,"bettingType":"ODDS","marketType":"WIN","marketTime":"2024-06-27T13:36:00.000Z","suspendTime":"2024-06-27T13:36:00.000Z","bspReconciled":false,"complete":true,"inPlay":false,"crossMatching":false,"runnersVoidable":false,"numberOfActiveRunners":6,"betDelay":0,"status":"OPEN","runners":[{"status":"ACTIVE","sortPriority":1,"id":61496663,"name":"1. Glory Bomber"},{"status":"ACTIVE","sortPriority":2,"id":47801105,"name":"2. Lady Casey"},{"status":"ACTIVE","sortPriority":3,"id":47095746,"name":"3. Zipping Rush"},{"status":"ACTIVE","sortPriority":4,"id":53893973,"name":"4. Marinas Ollie"},{"status":"ACTIVE","sortPriority":5,"id":53987475,"name":"5. Brynoffa Alice"},{"status":"ACTIVE","sortPriority":6,"id":66596720,"name":"6. Ashville Bucko"}],"regulators":["MR_INT"],"venue":"Kinsley","countryCode":"GB","discountAllowed":true,"timezone":"Europe/London","openDate":"2024-06-27T13:36:00.000Z","version":5994643741,"name":"D3 268m","eventName":"Kinsley 27th Jun"},"rc":[{"atb":[[1.03,15.1]],"id":47801105},{"atl":[[1000,0.26]],"id":47801105},{"spn":500.51,"spf":"NaN","id":47801105},{"atb":[[1.03,15.1]],"id":53893973},{"atl":[[990,0.26]],"id":53893973},{"spn":495.51,"spf":"NaN","id":53893973},{"atb":[[1.03,15.1]],"id":47095746},{"atl":[[1000,0.26]],"id":47095746},{"spn":500.51,"spf":"NaN","id":47095746},{"atb":[[1.01,45.3]],"id":61496663},{"atl":[[990,0.26]],"id":61496663},{"spn":495.5,"spf":"NaN","id":61496663},{"atb":[[1.01,45.3]],"id":66596720},{"atl":[[1000,0.26]],"id":66596720},{"spn":500.5,"spf":"NaN","id":66596720},{"atb":[[1.03,15.1]],"id":53987475},{"atl":[[1000,0.26]],"id":53987475},{"spn":500.51,"spf":"NaN","id":53987475}],"con":true,"img":true}]}
{"op":"mcm","clk":"11538507196","pt":1719462964822,"mc":[{"id":"1.230178306","rc":[{"atb":[[1.03,15.1]],"id":47801105},{"atl":[[150,4],[1000,0.26]],"id":47801105},{"spn":75.51,"spf":"NaN","id":47801105},{"atb":[[1.03,15.1]],"id":53893973},{"atl":[[150,4],[990,0.26]],"id":53893973},{"spn":75.51,"spf":"NaN","id":53893973},{"atb":[[1.03,15.1]],"id":47095746},{"atl":[[150,4],[1000,0.26]],"id":47095746},{"spn":75.51,"spf":"NaN","id":47095746},{"atb":[[1.01,45.3]],"id":61496663},{"atl":[[150,4],[990,0.26]],"id":61496663},{"spn":75.5,"spf":"NaN","id":61496663},{"atb":[[1.01,45.3]],"id":66596720},{"atl":[[150,4],[1000,0.26]],"id":66596720},{"spn":75.5,"spf":"NaN","id":66596720},{"atb":[[1.03,15.1]],"id":53987475},{"atl":[[150,4],[1000,0.26]],"id":53987475},{"spn":75.51,"spf":"NaN","id":53987475}],"con":true,"img":false}]}
{"op":"mcm","clk":"11538595359","pt":1719464882536,"mc":[{"id":"1.230178306","marketDefinition":{"bspMarket":true,"turnInPlayEnabled":false,"persistenceEnabled":false,"marketBaseRate":5.0,"eventId":"33376062","eventTypeId":"4339","numberOfWinners":1,"bettingType":"ODDS","marketType":"WIN","marketTime":"2024-06-27T13:36:00.000Z","suspendTime":"2024-06-27T13:36:00.000Z","bspReconciled":false,"complete":true,"inPlay":false,"crossMatching":false,"runnersVoidable":false,"numberOfActiveRunners":6,"betDelay":0,"status":"OPEN","runners":[{"status":"ACTIVE","sortPriority":1,"id":61496663,"name":"1. Glory Bomber"},{"status":"ACTIVE","sortPriority":2,"id":47801105,"name":"2. Lady Casey"},{"status":"ACTIVE","sortPriority":3,"id":47095746,"name":"3. Zipping Rush"},{"status":"ACTIVE","sortPriority":4,"id":53893973,"name":"4. Marinas Ollie"},{"status":"ACTIVE","sortPriority":5,"id":53987475,"name":"5. Brynoffa Alice"},{"status":"ACTIVE","sortPriority":6,"id":66596720,"name":"6. Ashville Bucko"}],"regulators":["MR_INT"],"venue":"Kinsley","countryCode":"GB","discountAllowed":true,"timezone":"Europe/London","openDate":"2024-06-27T13:36:00.000Z","version":5994643741,"name":"D3 268m","eventName":"Kinsley 27th Jun"},"rc":[{"atb":[[1.03,15.09]],"id":47801105},{"atl":[[150,4],[1000,0.26]],"id":47801105},{"spn":75.51,"spf":"NaN","id":47801105},{"atb":[[1.03,15.09]],"id":53893973},{"atl":[[150,4],[990,0.26]],"id":53893973},{"spn":75.51,"spf":"NaN","id":53893973},{"atb":[[1.03,15.09]],"id":47095746},{"atl":[[150,4],[1000,0.26]],"id":47095746},{"spn":75.51,"spf":"NaN","id":47095746},{"atb":[[1.01,45.29]],"id":61496663},{"atl":[[150,4],[990,0.26]],"id":61496663},{"spn":75.5,"spf":"NaN","id":61496663},{"atb":[[1.01,45.29]],"id":66596720},{"atl":[[150,4],[1000,0.26]],"id":66596720},{"spn":75.5,"spf":"NaN","id":66596720},{"atb":[[1.03,15.09]],"id":53987475},{"atl":[[150,4],[1000,0.26]],"id":53987475},{"spn":75.51,"spf":"NaN","id":53987475}],"con":true,"img":true}]}
{"op":"mcm","clk":"11538748455","pt":1719468201622,"mc":[{"id":"1.230178306","rc":[{"atb":[[1.03,15.09],[2.06,13.2]],"id":47801105},{"spn":76.03,"spf":"NaN","id":47801105},{"atb":[[1.03,15.09],[2.04,10.46]],"id":53893973},{"spn":76.02,"spf":"NaN","id":53893973},{"atb":[[2.02,10.35],[1.03,15.09]],"id":47095746},{"spn":76.01,"spf":"NaN","id":47095746},{"atb":[[1.01,45.29],[2.04,13.07]],"id":61496663},{"spn":76.02,"spf":"NaN","id":61496663},{"atb":[[2,9.4],[1.01,45.29]],"id":66596720},{"spn":76.0,"spf":"NaN","id":66596720},{"atb":[[2,8.54],[1.03,15.09]],"id":53987475},{"spn":76.0,"spf":"NaN","id":53987475}],"con":true,"img":false}]}
{"op":"mcm","clk":"11538751251","pt":1719468258478,"mc":[{"id":"1.230178306","rc":[{"atb":[[2.04,3.16]],"id":47095746}],"con":true,"img":false}]}
{"op":"mcm","clk":"11538751259","pt":1719468258783,"mc":[{"id":"1.230178306","rc":[{"atb":[[2.02,3.16]],"id":66596720}],"con":true,"img":false}]}
{"op":"mcm","clk":"11538751264","pt":1719468258990,"mc":[{"id":"1.230178306","rc":[{"atb":[[2.08,3.16]],"id":47801105}],"con":true,"img":false}]}
{"op":"mcm","clk":"11538751269","pt":1719468259094,"mc":[{"id":"1.230178306","rc":[{"atb":[[2.02,3.16]],"id":53987475}],"con":true,"img":false}]}
{"op":"mcm","clk":"11538751280","pt":1719468259296,"mc":[{"id":"1.230178306","rc":[{"atb":[[2.06,3.16]],"id":61496663}],"con":true,"img":false}]}
{"op":"mcm","clk":"11538751304","pt":1719468259656,"mc":[{"id":"1.230178306","rc":[{"atb":[[2.06,3.16]],"id":53893973}],"con":true,"img":false}]}
{"op":"mcm","clk":"11538752333","pt":1719468281020,"mc":[{"id":"1.230178306","rc":[{"spn":76.04,"spf":"NaN","id":47801105},{"spl":[[1.01,1]],"id":53893973},{"spn":2.06,"spf":1.0,"id":53893973},{"spn":76.02,"spf":"NaN","id":47095746},{"spn":76.03,"spf":"NaN","id":61496663},{"spn":76.01,"spf":"NaN","id":66596720},{"spn":76.01,"spf":"NaN","id":53987475}],"con":true,"img":false}]}
{"op":"mcm","clk":"11538752391","pt":1719468281752,"mc":[{"id":"1.230178306","marketDefinition":{"bspMarket":true,"turnInPlayEnabled":false,"persistenceEnabled":false,"marketBaseRate":5.0,"eventId":"33376062","eventTypeId":"4339","numberOfWinners":1,"bettingType":"ODDS","marketType":"WIN","marketTime":"2024-06-27T13:36:00.000Z","suspendTime":"2024-06-27T13:36:00.000Z","bspReconciled":false,"complete":true,"inPlay":false,"crossMatching":true,"runnersVoidable":false,"numberOfActiveRunners":6,"betDelay":0,"status":"OPEN","runners":[{"status":"ACTIVE","sortPriority":1,"id":61496663,"name":"1. Glory Bomber"},{"status":"ACTIVE","sortPriority":2,"id":47801105,"name":"2. Lady Casey"},{"status":"ACTIVE","sortPriority":3,"id":47095746,"name":"3. Zipping Rush"},{"status":"ACTIVE","sortPriority":4,"id":53893973,"name":"4. Marinas Ollie"},{"status":"ACTIVE","sortPriority":5,"id":53987475,"name":"5. Brynoffa Alice"},{"status":"ACTIVE","sortPriority":6,"id":66596720,"name":"6. Ashville Bucko"}],"regulators":["MR_INT"],"venue":"Kinsley","countryCode":"GB","discountAllowed":true,"timezone":"Europe/London","openDate":"2024-06-27T13:36:00.000Z","version":5994643741,"name":"D3 268m","eventName":"Kinsley 27th Jun"},"rc":[],"con":true,"img":false}]}
{"op":"mcm","clk":"11538753604","pt":1719468303605,"mc":[{"id":"1.230178306","rc":[{"atb":[[2.02,6.55]],"id":66596720}],"con":true,"img":false}]}
{"op":"mcm","clk":"11538753611","pt":1719468303707,"mc":[{"id":"1.230178306","rc":[{"atb":[[2.06,6.55]],"id":61496663}],"con":true,"img":false}]}
{"op":"mcm","clk":"11538753621","pt":1719468303911,"mc":[{"id":"1.230178306","rc":[{"atb":[[2.08,6.55]],"id":47801105}],"con":true,"img":false}]}
{"op":"mcm","clk":"11538753626","pt":1719468304015,"mc":[{"id":"1.230178306","rc":[{"atb":[[2.04,6.55]],"id":47095746}],"con":true,"img":false}]}
{"op":"mcm","clk":"11538753675","pt":1719468304841,"mc":[{"id":"1.230178306","rc":[{"atb":[[2.06,6.55]],"id":53893973}],"con":true,"img":false}]}
{"op":"mcm","clk":"11538753680","pt":1719468304941,"mc":[{"id":"1.230178306","rc":[{"atb":[[2.02,6.55]],"id":53987475}],"con":true,"img":false}]}
{"op":"mcm","clk":"11538905092","pt":1719471466214,"mc":[{"id":"1.230178306","rc":[{"atl":[[1000,0.16]],"id":47801105},{"atl":[[990,0.16]],"id":53893973},{"atl":[[1000,0.16]],"id":47095746},{"atl":[[990,0.16]],"id":61496663},{"atl":[[1000,0.16]],"id":66596720},{"atl":[[1000,0.16]],"id":53987475}],"con":true,"img":false}]}
{"op":"mcm","clk":"11538940282","pt":1719472105636,"mc":[{"id":"1.230178306","rc":[{"atb":[[2.06,0],[1.03,15.08],[2.08,6.54]],"id":47801105},{"atl":[[1000,0.16]],"id":47801105},{"atb":[[2.06,6.54],[1.03,15.08],[2.04,0]],"id":53893973},{"atl":[[990,0.16]],"id":53893973},{"atb":[[2.02,0],[1.03,15.08],[2.04,6.54]],"id":47095746},{"atl":[[1000,0.16]],"id":47095746},{"atb":[[1.01,45.26],[2.06,6.54],[2.04,0]],"id":61496663},{"atl":[[990,0.16]],"id":61496663},{"atb":[[2,0],[2.02,6.54],[1.01,45.26]],"id":66596720},{"atl":[[1000,0.16]],"id":66596720},{"atb":[[2,0],[2.02,6.54],[1.03,15.08]],"id":53987475},{"atl":[[1000,0.16]],"id":53987475}],"con":true,"img":false}]}
{"op":"mcm","clk":"11538940288","pt":1719472105736,"mc":[{"id":"1.230178306","rc":[{"atb":[[2.1,13.19]],"id":47801105},{"atb":[[2.08,10.45]],"id":53893973},{"atb":[[2.06,10.35]],"id":47095746},{"atb":[[2.08,13.06]],"id":61496663},{"atb":[[2.04,9.39]],"id":66596720},{"atb":[[2.04,8.54]],"id":53987475}],"con":true,"img":false}]}
{"op":"mcm","clk":"11538944766","pt":1719472177960,"mc":[{"id":"1.230178306","rc":[{"spn":76.05,"spf":"NaN","id":47801105},{"atb":[[2.06,3.38]],"id":53893973},{"spn":2.08,"spf":1.0,"id":53893973},{"spn":76.03,"spf":"NaN","id":47095746},{"spn":76.04,"spf":"NaN","id":61496663},{"spn":76.02,"spf":"NaN","id":66596720},{"spn":76.02,"spf":"NaN","id":53987475}],"con":true,"img":false}]}
{"op":"mcm","clk":"11538944813","pt":1719472178573,"mc":[{"id":"1.230178306","rc":[{"atb":[[2.02,3.38]],"id":66596720}],"con":true,"img":false}]}
{"op":"mcm","clk":"11538944841","pt":1719472179034,"mc":[{"id":"1.230178306","rc":[{"atb":[[2.04,3.38]],"id":47095746}],"con":true,"img":false}]}
{"op":"mcm","clk":"11538944889","pt":1719472179853,"mc":[{"id":"1.230178306","rc":[{"atb":[[2.08,3.38]],"id":47801105},{"atb":[[2.1,3.16]],"id":53893973}],"con":true,"img":false}]}
{"op":"mcm","clk":"11538944934","pt":1719472180569,"mc":[{"id":"1.230178306","rc":[{"atb":[[2.12,3.16]],"id":47801105},{"atb":[[2.06,3.38]],"id":61496663}],"con":true,"img":false}]}
{"op":"mcm","clk":"11538944944","pt":1719472180773,"mc":[{"id":"1.230178306","rc":[{"atb":[[2.06,3.16]],"id":66596720}],"con":true,"img":false}]}
{"op":"mcm","clk":"11538944967","pt":1719472181236,"mc":[{"id":"1.230178306","rc":[{"atb":[[2.08,3.16]],"id":47095746}],"con":true,"img":false}]}
{"op":"mcm","clk":"11538944983","pt":1719472181544,"mc":[{"id":"1.230178306","rc":[{"atb":[[2.02,3.38]],"id":53987475}],"con":true,"img":false}]}
{"op":"mcm","clk":"11538945008","pt":1719472181858,"mc":[{"id":"1.230178306","rc":[{"atb":[[2.1,3.16]],"id":61496663}],"con":true,"img":false}]}
{"op":"mcm","clk":"11538945020","pt":1719472182059,"mc":[{"id":"1.230178306","rc":[{"atb":[[2.06,3.16]],"id":53987475}],"con":true,"img":false}]}
{"op":"mcm","clk":"11538946231","pt":1719472201605,"mc":[{"id":"1.230178306","rc":[{"atb":[[2.06,0]],"id":53893973},{"atb":[[2.02,0]],"id":53987475}],"con":true,"img":false}]}
{"op":"mcm","clk":"11538946251","pt":1719472201968,"mc":[{"id":"1.230178306","rc":[{"atb":[[2.06,0]],"id":61496663}],"con":true,"img":false}]}
{"op":"mcm","clk":"11538946272","pt":1719472202379,"mc":[{"id":"1.230178306","rc":[{"atb":[[2.08,0]],"id":47801105}],"con":true,"img":false}]}
{"op":"mcm","clk":"11538946309","pt":1719472203098,"mc":[{"id":"1.230178306","rc":[{"atb":[[2.02,0]],"id":66596720}],"con":true,"img":false}]}
{"op":"mcm","clk":"11538946358","pt":1719472203869,"mc":[{"id":"1.230178306","rc":[{"atb":[[2.04,0]],"id":47095746}],"con":true,"img":false}]}
{"op":"mcm","clk":"11538947364","pt":1719472221211,"mc":[{"id":"1.230178306","rc":[{"atb":[[2.1,6.54]],"id":53893973}],"con":true,"img":false}]}
{"op":"mcm","clk":"11538947382","pt":1719472221521,"mc":[{"id":"1.230178306","rc":[{"atb":[[2.1,6.54]],"id":61496663}],"con":true,"img":false}]}
{"op":"mcm","clk":"11538947397","pt":1719472221727,"mc":[{"id":"1.230178306","rc":[{"atb":[[2.12,6.54]],"id":47801105}],"con":true,"img":false}]}
{"op":"mcm","clk":"11538947433","pt":1719472222240,"mc":[{"id":"1.230178306","rc":[{"atb":[[2.06,6.54]],"id":53987475}],"con":true,"img":false}]}
{"op":"mcm","clk":"11538947448","pt":1719472222498,"mc":[{"id":"1.230178306","rc":[{"atb":[[2.06,6.54]],"id":66596720}],"con":true,"img":false}]}
{"op":"mcm","clk":"11538947465","pt":1719472222856,"mc":[{"id":"1.230178306","rc":[{"atb":[[2.08,6.54]],"id":47095746}],"con":true,"img":false}]}
{"op":"mcm","clk":"11539122506","pt":1719475682543,"mc":[{"id":"1.230178306","marketDefinition":{"bspMarket":true,"turnInPlayEnabled":false,"persistenceEnabled":false,"marketBaseRate":5.0,"eventId":"33376062","eventTypeId":"4339","numberOfWinners":1,"bettingType":"ODDS","marketType":"WIN","marketTime":"2024-06-27T13:36:00.000Z","suspendTime":"2024-06-27T13:36:00.000Z","bspReconciled":false,"complete":true,"inPlay":false,"crossMatching":true,"runnersVoidable":false,"numberOfActiveRunners":6,"betDelay":0,"status":"OPEN","runners":[{"status":"ACTIVE","sortPriority":1,"id":61496663,"name":"1. Glory Bomber"},{"status":"ACTIVE","sortPriority":2,"id":47801105,"name":"2. Lady Casey"},{"status":"ACTIVE","sortPriority":3,"id":47095746,"name":"3. Zipping Rush"},{"status":"ACTIVE","sortPriority":4,"id":53893973,"name":"4. Marinas Ollie"},{"status":"ACTIVE","sortPriority":5,"id":53987475,"name":"5. Brynoffa Alice"},{"status":"ACTIVE","sortPriority":6,"id":66596720,"name":"6. Ashville Bucko"}],"regulators":["MR_INT"],"venue":"Kinsley","countryCode":"GB","discountAllowed":true,"timezone":"Europe/London","openDate":"2024-06-27T13:36:00.000Z","version":5994643741,"name":"D3 268m","eventName":"Kinsley 27th Jun"},"rc":[{"atb":[[1.03,15.09],[2.12,6.55],[2.1,13.19]],"id":47801105},{"atl":[[150,4],[1000,0.16]],"id":47801105},{"spn":76.06,"spf":"NaN","id":47801105},{"spl":[[1.01,1]],"id":53893973},{"atb":[[1.03,15.09],[2.1,6.55],[2.08,10.45]],"id":53893973},{"atl":[[150,4],[990,0.16]],"id":53893973},{"spn":2.1,"spf":1.0,"id":53893973},{"atb":[[2.06,10.35],[1.03,15.09],[2.08,6.55]],"id":47095746},{"atl":[[150,4],[1000,0.16]],"id":47095746},{"spn":76.04,"spf":"NaN","id":47095746},{"atb":[[1.01,45.28],[2.1,6.55],[2.08,13.07]],"id":61496663},{"atl":[[150,4],[990,0.16]],"id":61496663},{"spn":76.05,"spf":"NaN","id":61496663},{"atb":[[1.01,45.28],[2.06,6.55],[2.04,9.4]],"id":66596720},{"atl":[[150,4],[1000,0.16]],"id":66596720},{"spn":76.03,"spf":"NaN","id":66596720},{"atb":[[2.06,6.55],[1.03,15.09],[2.04,8.54]],"id":53987475},{"atl":[[150,4],[1000,0.16]],"id":53987475},{"spn":76.03,"spf":"NaN","id":53987475}],"con":true,"img":true}]}
{"op":"mcm","clk":"11539127616","pt":1719475706173,"mc":[{"id":"1.230178306","rc":[{"atb":[[1.03,15.09],[2.12,6.55],[2.1,0]],"id":47801105},{"spn":76.06,"spf":"NaN","id":47801105},{"atb":[[1.03,15.09],[2.1,6.55],[2.08,0]],"id":53893973},{"spn":2.1,"spf":1.0,"id":53893973},{"atb":[[2.06,0],[1.03,15.09],[2.08,6.55]],"id":47095746},{"spn":76.04,"spf":"NaN","id":47095746},{"atb":[[1.01,45.28],[2.1,6.55],[2.08,0]],"id":61496663},{"spn":76.05,"spf":"NaN","id":61496663},{"atb":[[1.01,45.28],[2.06,6.55],[2.04,0]],"id":66596720},{"spn":76.03,"spf":"NaN","id":66596720},{"atb":[[2.06,6.55],[1.03,15.09],[2.04,0]],"id":53987475},{"spn":76.03,"spf":"NaN","id":53987475}],"con":true,"img":false}]}
{"op":"mcm","clk":"11539127620","pt":1719475706268,"mc":[{"id":"1.230178306","rc":[{"atb":[[2.14,13.19]],"id":47801105},{"atb":[[2.12,10.45]],"id":53893973},{"atb":[[2.1,10.35]],"id":47095746},{"atb":[[2.12,13.07]],"id":61496663},{"atb":[[2.08,9.4]],"id":66596720},{"atb":[[2.08,8.54]],"id":53987475}],"con":true,"img":false}]}
{"op":"mcm","clk":"11539129077","pt":1719475728299,"mc":[{"id":"1.230178306","rc":[{"atb":[[2.1,3.38]],"id":61496663}],"con":true,"img":false}]}
{"op":"mcm","clk":"11539129083","pt":1719475728401,"mc":[{"id":"1.230178306","rc":[{"atb":[[2.06,3.38]],"id":53987475}],"con":true,"img":false}]}
{"op":"mcm","clk":"11539129089","pt":1719475728504,"mc":[{"id":"1.230178306","rc":[{"atb":[[2.1,3.38]],"id":53893973}],"con":true,"img":false}]}
{"op":"mcm","clk":"11539129105","pt":1719475728804,"mc":[{"id":"1.230178306","rc":[{"atb":[[2.08,3.38]],"id":47095746}],"con":true,"img":false}]}
{"op":"mcm","clk":"11539129118","pt":1719475729013,"mc":[{"id":"1.230178306","rc":[{"atb":[[2.06,3.38]],"id":66596720}],"con":true,"img":false}]}
{"op":"mcm","clk":"11539129140","pt":1719475729337,"mc":[{"id":"1.230178306","rc":[{"atb":[[2.12,3.16]],"id":47095746}],"con":true,"img":false}]}
{"op":"mcm","clk":"11539129163","pt":1719475729646,"mc":[{"id":"1.230178306","rc":[{"atb":[[2.14,3.16]],"id":61496663}],"con":true,"img":false}]}
{"op":"mcm","clk":"11539129175","pt":1719475729799,"mc":[{"id":"1.230178306","rc":[{"atb":[[2.14,3.16]],"id":53893973}],"con":true,"img":false}]}
{"op":"mcm","clk":"11539129180","pt":1719475729901,"mc":[{"id":"1.230178306","rc":[{"atb":[[2.1,3.16]],"id":53987475}],"con":true,"img":false}]}
{"op":"mcm","clk":"11539129231","pt":1719475730826,"mc":[{"id":"1.230178306","rc":[{"atb":[[2.12,3.38]],"id":47801105}],"con":true,"img":false}]}
{"op":"mcm","clk":"11539129255","pt":1719475731335,"mc":[{"id":"1.230178306","rc":[{"atb":[[2.16,3.16]],"id":47801105}],"con":true,"img":false}]}
{"op":"mcm","clk":"11539129310","pt":1719475732518,"mc":[{"id":"1.230178306","rc":[{"atb":[[2.1,3.16]],"id":66596720}],"con":true,"img":false}]}
{"op":"mcm","clk":"11539136230","pt":1719475839962,"mc":[{"id":"1.230178306","rc":[{"spn":76.08,"spf":"NaN","id":47801105},{"spn":2.14,"spf":1.0,"id":53893973},{"atb":[[2.08,0]],"id":47095746},{"spn":76.06,"spf":"NaN","id":47095746},{"spn":76.07,"spf":"NaN","id":61496663},{"spn":76.05,"spf":"NaN","id":66596720},{"spn":76.05,"spf":"NaN","id":53987475}],"con":true,"img":false}]}
{"op":"mcm","clk":"11539136247","pt":1719475840267,"mc":[{"id":"1.230178306","rc":[{"atb":[[2.12,0]],"id":47801105}],"con":true,"img":false}]}
{"op":"mcm","clk":"11539136263","pt":1719475840530,"mc":[{"id":"1.230178306","rc":[{"atb":[[2.1,0]],"id":53893973}],"con":true,"img":false}]}
{"op":"mcm","clk":"11539136267","pt":1719475840628,"mc":[{"id":"1.230178306","rc":[{"atb":[[2.06,0]],"id":53987475}],"con":true,"img":false}]}
{"op":"mcm","clk":"11539136317","pt":1719475841347,"mc":[{"id":"1.230178306","rc":[{"atb":[[2.06,0]],"id":66596720}],"con":true,"img":false}]}
{"op":"mcm","clk":"11539136341","pt":1719475841754,"mc":[{"id":"1.230178306","rc":[{"atb":[[2.1,0]],"id":61496663}],"con":true,"img":false}]}
{"op":"mcm","clk":"11539136421","pt":1719475843049,"mc":[{"id":"1.230178306","rc":[{"atb":[[2.14,6.55]],"id":53893973}],"con":true,"img":false}]}
{"op":"mcm","clk":"11539136458","pt":1719475843669,"mc":[{"id":"1.230178306","rc":[{"atb":[[2.12,6.55]],"id":47095746},{"atb":[[2.1,6.55]],"id":66596720}],"con":true,"img":false}]}
{"op":"mcm","clk":"11539136475","pt":1719475843980,"mc":[{"id":"1.230178306","rc":[{"atb":[[2.16,6.55]],"id":47801105},{"atb":[[2.1,6.55]],"id":53987475}],"con":true,"img":false}]}
{"op":"mcm","clk":"11539136496","pt":1719475844249,"mc":[{"id":"1.230178306","rc":[{"atb":[[2.14,6.55]],"id":61496663}],"con":true,"img":false}]}
{"op":"mcm","clk":"11539221188","pt":1719477369643,"mc":[{"id":"1.230178306","rc":[{"atl":[[46,12],[27,8]],"id":47801105},{"spn":14.58,"spf":"NaN","id":47801105},{"atl":[[48,12],[28,8]],"id":53893973},{"atl":[[48,12],[28,8]],"id":61496663},{"spn":15.07,"spf":"NaN","id":61496663},{"atl":[[36,8],[60,12]],"id":66596720},{"spn":19.05,"spf":"NaN","id":66596720},{"atl":[[36,8],[60,12]],"id":53987475},{"spn":19.05,"spf":"NaN","id":53987475}],"con":true,"img":false}]}
{"op":"mcm","clk":"11539341079","pt":1719479305038,"mc":[{"id":"1.230178306","rc":[{"atb":[[1.03,15.09],[2.16,6.54],[2.14,0]],"id":47801105},{"atb":[[1.03,15.09],[2.12,0],[2.14,6.54]],"id":53893973},{"atb":[[1.03,15.09],[2.12,6.54],[2.1,0]],"id":47095746},{"atb":[[1.01,45.27],[2.12,0],[2.14,6.54]],"id":61496663},{"atb":[[1.01,45.27],[2.1,6.54],[2.08,0]],"id":66596720},{"atb":[[1.03,15.09],[2.1,6.54],[2.08,0]],"id":53987475}],"con":true,"img":false}]}
{"op":"mcm","clk":"11539341083","pt":1719479305139,"mc":[{"id":"1.230178306","rc":[{"atb":[[2.18,13.19]],"id":47801105},{"atb":[[2.16,10.45]],"id":53893973},{"atb":[[2.14,10.35]],"id":47095746},{"atb":[[2.16,13.06]],"id":61496663},{"atb":[[2.12,9.39]],"id":66596720},{"atb":[[2.12,8.54]],"id":53987475}],"con":true,"img":false}]}
{"op":"mcm","clk":"11539347912","pt":1719479413707,"mc":[{"id":"1.230178306","rc":[{"atb":[[2.16,3.38]],"id":47801105},{"spn":14.59,"spf":"NaN","id":47801105},{"atb":[[2.14,3.38]],"id":53893973},{"spn":2.16,"spf":1.0,"id":53893973},{"atb":[[2.12,3.38]],"id":47095746},{"spn":76.07,"spf":"NaN","id":47095746},{"atb":[[2.14,3.38]],"id":61496663},{"spn":15.08,"spf":"NaN","id":61496663},{"atb":[[2.1,3.38]],"id":66596720},{"spn":19.06,"spf":"NaN","id":66596720},{"atb":[[2.1,3.38]],"id":53987475},{"spn":19.06,"spf":"NaN","id":53987475}],"con":true,"img":false}]}
{"op":"mcm","clk":"11539350916","pt":1719479459940,"mc":[{"id":"1.230178306","rc":[{"atb":[[2.16,0]],"id":47801105},{"atb":[[2.14,0]],"id":53893973},{"atb":[[2.12,0]],"id":47095746},{"atb":[[2.14,0]],"id":61496663},{"atb":[[2.1,0]],"id":66596720},{"atb":[[2.1,0]],"id":53987475}],"con":true,"img":false}]}
{"op":"mcm","clk":"11539368761","pt":1719479720096,"mc":[{"id":"1.230178306","rc":[{"atb":[[2.16,3.16]],"id":47095746},{"spn":76.08,"spf":"NaN","id":47095746}],"con":true,"img":false}]}
{"op":"mcm","clk":"11539368782","pt":1719479720303,"mc":[{"id":"1.230178306","rc":[{"atb":[[2.18,3.16]],"id":61496663}],"con":true,"img":false}]}
{"op":"mcm","clk":"11539368865","pt":1719479721229,"mc":[{"id":"1.230178306","rc":[{"atb":[[2.2,3.16]],"id":47801105}],"con":true,"img":false}]}
{"op":"mcm","clk":"11539368881","pt":1719479721384,"mc":[{"id":"1.230178306","rc":[{"atb":[[2.14,3.16]],"id":66596720}],"con":true,"img":false}]}
{"op":"mcm","clk":"11539368902","pt":1719479721589,"mc":[{"id":"1.230178306","rc":[{"atb":[[2.14,3.16]],"id":53987475}],"con":true,"img":false}]}
{"op":"mcm","clk":"11539368913","pt":1719479721695,"mc":[{"id":"1.230178306","rc":[{"atb":[[2.18,3.16]],"id":53893973}],"con":true,"img":false}]}
{"op":"mcm","clk":"11539370625","pt":1719479744611,"mc":[{"id":"1.230178306","rc":[{"atb":[[2.18,6.54]],"id":61496663}],"con":true,"img":false}]}
{"op":"mcm","clk":"11539370651","pt":1719479744913,"mc":[{"id":"1.230178306","rc":[{"atb":[[2.14,6.54]],"id":66596720},{"atb":[[2.14,6.54]],"id":53987475}],"con":true,"img":false}]}
{"op":"mcm","clk":"11539370676","pt":1719479745222,"mc":[{"id":"1.230178306","rc":[{"atb":[[2.16,6.54]],"id":47095746}],"con":true,"img":false}]}
{"op":"mcm","clk":"11539370724","pt":1719479745840,"mc":[{"id":"1.230178306","rc":[{"atb":[[2.18,6.54]],"id":53893973}],"con":true,"img":false}]}
{"op":"mcm","clk":"11539370750","pt":1719479746097,"mc":[{"id":"1.230178306","rc":[{"atb":[[2.2,6.54]],"id":47801105}],"con":true,"img":false}]}
{"op":"mcm","clk":"11539438482","pt":1719481082544,"mc":[{"id":"1.230178306","marketDefinition":{"bspMarket":true,"turnInPlayEnabled":false,"persistenceEnabled":false,"marketBaseRate":5.0,"eventId":"33376062","eventTypeId":"4339","numberOfWinners":1,"bettingType":"ODDS","marketType":"WIN","marketTime":"2024-06-27T13:36:00.000Z","suspendTime":"2024-06-27T13:36:00.000Z","bspReconciled":false,"complete":true,"inPlay":false,"crossMatching":true,"runnersVoidable":false,"numberOfActiveRunners":6,"betDelay":0,"status":"OPEN","runners":[{"status":"ACTIVE","sortPriority":1,"id":61496663,"name":"1. Glory Bomber"},{"status":"ACTIVE","sortPriority":2,"id":47801105,"name":"2. Lady Casey"},{"status":"ACTIVE","sortPriority":3,"id":47095746,"name":"3. Zipping Rush"},{"status":"ACTIVE","sortPriority":4,"id":53893973,"name":"4. Marinas Ollie"},{"status":"ACTIVE","sortPriority":5,"id":53987475,"name":"5. Brynoffa Alice"},{"status":"ACTIVE","sortPriority":6,"id":66596720,"name":"6. Ashville Bucko"}],"regulators":["MR_INT"],"venue":"Kinsley","countryCode":"GB","discountAllowed":true,"timezone":"Europe/London","openDate":"2024-06-27T13:36:00.000Z","version":5994643741,"name":"D3 268m","eventName":"Kinsley 27th Jun"},"rc":[{"atb":[[1.03,15.09],[2.18,13.19],[2.2,6.54]],"id":47801105},{"atl":[[150,4],[46,12],[27,8],[1000,0.16]],"id":47801105},{"spn":14.6,"spf":"NaN","id":47801105},{"spl":[[1.01,1]],"id":53893973},{"atb":[[1.03,15.09],[2.18,6.54],[2.16,10.45]],"id":53893973},{"atl":[[150,4],[48,12],[28,8],[990,0.16]],"id":53893973},{"spn":2.18,"spf":1.0,"id":53893973},{"atb":[[1.03,15.09],[2.16,6.54],[2.14,10.35]],"id":47095746},{"atl":[[150,4],[1000,0.16]],"id":47095746},{"spn":76.08,"spf":"NaN","id":47095746},{"atb":[[1.01,45.27],[2.18,6.54],[2.16,13.06]],"id":61496663},{"atl":[[150,4],[48,12],[28,8],[990,0.16]],"id":61496663},{"spn":15.09,"spf":"NaN","id":61496663},{"atb":[[1.01,45.27],[2.12,9.39],[2.14,6.54]],"id":66596720},{"atl":[[36,8],[150,4],[60,12],[1000,0.16]],"id":66596720},{"spn":19.07,"spf":"NaN","id":66596720},{"atb":[[1.03,15.09],[2.12,8.54],[2.14,6.54]],"id":53987475},{"atl":[[36,8],[150,4],[60,12],[1000,0.16]],"id":53987475},{"spn":19.07,"spf":"NaN","id":53987475}],"con":true,"img":true}]}
{"op":"mcm","clk":"11539512669","pt":1719482376473,"mc":[{"id":"1.230178306","rc":[{"atb":[[8,2]],"id":47801105},{"spn":17.5,"spf":"NaN","id":47801105},{"atb":[[3.05,2]],"id":53893973},{"spn":3.05,"spf":1.0,"id":53893973},{"atb":[[5.8,2]],"id":47095746},{"spn":77.9,"spf":"NaN","id":47095746},{"atb":[[5.6,2]],"id":61496663},{"spn":16.8,"spf":"NaN","id":61496663},{"atb":[[8,2]],"id":66596720},{"spn":22.0,"spf":"NaN","id":66596720},{"atb":[[5.3,2]],"id":53987475},{"spn":20.65,"spf":"NaN","id":53987475}],"con":true,"img":false}]}
{"op":"mcm","clk":"11539513402","pt":1719482387312,"mc":[{"id":"1.230178306","rc":[{"atb":[[2.2,3.38]],"id":47801105},{"atb":[[2.14,3.38]],"id":66596720}],"con":true,"img":false}]}
{"op":"mcm","clk":"11539545000","pt":1719482904486,"mc":[{"id":"1.230178306","rc":[{"atb":[[1.03,15.08],[2.18,0],[2.2,3.38]],"id":47801105},{"atb":[[1.03,15.08],[2.18,6.54],[2.16,0]],"id":53893973},{"atb":[[1.03,15.08],[2.16,6.54],[2.14,0]],"id":47095746},{"atb":[[1.01,45.26],[2.18,6.54],[2.16,0]],"id":61496663},{"atb":[[1.01,45.26],[2.12,0],[2.14,3.38]],"id":66596720},{"atb":[[1.03,15.08],[2.12,0],[2.14,6.54]],"id":53987475}],"con":true,"img":false}]}
{"op":"mcm","clk":"11539545012","pt":1719482904589,"mc":[{"id":"1.230178306","rc":[{"atb":[[2.22,13.19]],"id":47801105},{"atb":[[2.2,10.45]],"id":53893973},{"atb":[[2.18,10.35]],"id":47095746},{"atb":[[2.2,13.06]],"id":61496663},{"atb":[[2.16,9.39]],"id":66596720},{"atb":[[2.16,8.54]],"id":53987475}],"con":true,"img":false}]}
{"op":"mcm","clk":"11539545632","pt":1719482913299,"mc":[{"id":"1.230178306","rc":[{"atb":[[2.18,3.38]],"id":61496663}],"con":true,"img":false}]}
{"op":"mcm","clk":"11539545658","pt":1719482913503,"mc":[{"id":"1.230178306","rc":[{"atb":[[2.18,3.38]],"id":53893973}],"con":true,"img":false}]}
{"op":"mcm","clk":"11539545704","pt":1719482914013,"mc":[{"id":"1.230178306","rc":[{"atb":[[2.16,3.38]],"id":47095746}],"con":true,"img":false}]}
{"op":"mcm","clk":"11539545789","pt":1719482915404,"mc":[{"id":"1.230178306","rc":[{"atb":[[2.14,3.38]],"id":53987475}],"con":true,"img":false}]}
{"op":"mcm","clk":"11539545929","pt":1719482917108,"mc":[{"id":"1.230178306","rc":[{"atb":[[2.2,3.16]],"id":47095746}],"con":true,"img":false}]}
{"op":"mcm","clk":"11539545964","pt":1719482917518,"mc":[{"id":"1.230178306","rc":[{"atb":[[2.22,3.16]],"id":61496663}],"con":true,"img":false}]}
{"op":"mcm","clk":"11539546006","pt":1719482918087,"mc":[{"id":"1.230178306","rc":[{"atb":[[2.22,3.16]],"id":53893973}],"con":true,"img":false}]}
{"op":"mcm","clk":"11539546100","pt":1719482919273,"mc":[{"id":"1.230178306","rc":[{"atb":[[2.18,3.16]],"id":53987475}],"con":true,"img":false}]}
{"op":"mcm","clk":"11539550963","pt":1719482995170,"mc":[{"id":"1.230178306","rc":[{"atb":[[2.18,0]],"id":61496663}],"con":true,"img":false}]}
{"op":"mcm","clk":"11539551003","pt":1719482995845,"mc":[{"id":"1.230178306","rc":[{"atb":[[2.16,0]],"id":47095746},{"atb":[[2.14,0]],"id":66596720}],"con":true,"img":false}]}
{"op":"mcm","clk":"11539551074","pt":1719482997190,"mc":[{"id":"1.230178306","rc":[{"atb":[[2.2,0]],"id":47801105}],"con":true,"img":false}]}
{"op":"mcm","clk":"11539551109","pt":1719482997758,"mc":[{"id":"1.230178306","rc":[{"atb":[[2.18,0]],"id":53893973},{"atb":[[2.14,0]],"id":53987475}],"con":true,"img":false}]}
{"op":"mcm","clk":"11539551162","pt":1719482998789,"mc":[{"id":"1.230178306","rc":[{"atb":[[2.18,3.38]],"id":66596720}],"con":true,"img":false}]}
{"op":"mcm","clk":"11539551210","pt":1719482999462,"mc":[{"id":"1.230178306","rc":[{"atb":[[2.22,6.54]],"id":53893973}],"con":true,"img":false}]}
{"op":"mcm","clk":"11539551256","pt":1719483000297,"mc":[{"id":"1.230178306","rc":[{"atb":[[2.18,6.54]],"id":53987475}],"con":true,"img":false}]}
{"op":"mcm","clk":"11539551303","pt":1719483000975,"mc":[{"id":"1.230178306","rc":[{"atb":[[2.22,6.54]],"id":61496663}],"con":true,"img":false}]}
{"op":"mcm","clk":"11539551315","pt":1719483001284,"mc":[{"id":"1.230178306","rc":[{"atb":[[2.24,3.38]],"id":47801105}],"con":true,"img":false}]}
{"op":"mcm","clk":"11539551339","pt":1719483001647,"mc":[{"id":"1.230178306","rc":[{"atb":[[2.2,6.54]],"id":47095746}],"con":true,"img":false}]}
{"op":"mcm","clk":"11539574992","pt":1719483350495,"mc":[{"id":"1.230178306","rc":[{"atb":[[2.02,30.3],[1.51,196.08]],"id":47801105},{"atb":[[1.51,196.08]],"id":47095746},{"atb":[[1.51,196.08]],"id":61496663},{"atb":[[2.02,30.3],[1.51,196.08]],"id":66596720},{"atb":[[1.51,196.08]],"id":53987475}],"con":true,"img":false}]}
{"op":"mcm","clk":"11539640037","pt":1719484220703,"mc":[{"id":"1.230178306","rc":[{"atb":[[2.72,6]],"id":47801105},{"atb":[[2.58,6]],"id":53893973},{"atb":[[4.1,6]],"id":47095746},{"atb":[[3,6]],"id":61496663},{"atb":[[3.55,6]],"id":66596720},{"atb":[[3.55,6]],"id":53987475}],"con":true,"img":false}]}
{"op":"mcm","clk":"11539640128","pt":1719484222043,"mc":[{"id":"1.230178306","rc":[{"atb":[[1.51,196.08]],"id":53893973},{"atb":[[2.12,89.29]],"id":47095746},{"atb":[[2.12,89.29]],"id":66596720},{"atb":[[2.12,89.29]],"id":53987475}],"con":true,"img":false}]}
{"op":"mcm","clk":"11539640744","pt":1719484231721,"mc":[{"id":"1.230178306","rc":[{"atb":[[2.22,3.38]],"id":61496663}],"con":true,"img":false}]}
{"op":"mcm","clk":"11539640782","pt":1719484232240,"mc":[{"id":"1.230178306","rc":[{"atb":[[3.05,3.16]],"id":61496663}],"con":true,"img":false}]}
{"op":"mcm","clk":"11539640794","pt":1719484232449,"mc":[{"id":"1.230178306","rc":[{"atb":[[2.2,3.38]],"id":47095746},{"atb":[[2.18,3.38]],"id":53987475}],"con":true,"img":false}]}
{"op":"mcm","clk":"11539643160","pt":1719484265942,"mc":[{"id":"1.230178306","rc":[{"atb":[[2.22,0]],"id":61496663}],"con":true,"img":false}]}
{"op":"mcm","clk":"11539643176","pt":1719484266138,"mc":[{"id":"1.230178306","rc":[{"atb":[[2.2,0]],"id":47095746},{"atb":[[2.18,0]],"id":66596720},{"atb":[[2.18,0]],"id":53987475}],"con":true,"img":false}]}
{"op":"mcm","clk":"11539643187","pt":1719484266247,"mc":[{"id":"1.230178306","rc":[{"atb":[[3.05,6.54]],"id":61496663}],"con":true,"img":false}]}
{"op":"mcm","clk":"11539810780","pt":1719486482531,"mc":[{"id":"1.230178306","marketDefinition":{"bspMarket":true,"turnInPlayEnabled":false,"persistenceEnabled":false,"marketBaseRate":5.0,"eventId":"33376062","eventTypeId":"4339","numberOfWinners":1,"bettingType":"ODDS","marketType":"WIN","marketTime":"2024-06-27T13:36:00.000Z","suspendTime":"2024-06-27T13:36:00.000Z","bspReconciled":false,"complete":true,"inPlay":false,"crossMatching":true,"runnersVoidable":false,"numberOfActiveRunners":6,"betDelay":0,"status":"OPEN","runners":[{"status":"ACTIVE","sortPriority":1,"id":61496663,"name":"1. Glory Bomber"},{"status":"ACTIVE","sortPriority":2,"id":47801105,"name":"2. Lady Casey"},{"status":"ACTIVE","sortPriority":3,"id":47095746,"name":"3. Zipping Rush"},{"status":"ACTIVE","sortPriority":4,"id":53893973,"name":"4. Marinas Ollie"},{"status":"ACTIVE","sortPriority":5,"id":53987475,"name":"5. Brynoffa Alice"},{"status":"ACTIVE","sortPriority":6,"id":66596720,"name":"6. Ashville Bucko"}],"regulators":["MR_INT"],"venue":"Kinsley","countryCode":"GB","discountAllowed":true,"timezone":"Europe/London","openDate":"2024-06-27T13:36:00.000Z","version":5994643741,"name":"D3 268m","eventName":"Kinsley 27th Jun"},"rc":[{"atb":[[8,2],[2.24,3.38],[2.72,6],[2.02,30.3],[1.03,15.09],[2.22,13.19],[1.51,196.08]],"id":47801105},{"atl":[[150,4],[46,12],[27,8],[1000,0.16]],"id":47801105},{"spn":17.5,"spf":"NaN","id":47801105},{"spl":[[1.01,1]],"id":53893973},{"atb":[[1.03,15.09],[2.22,6.54],[2.58,6],[2.2,10.45],[1.51,196.08],[3.05,2]],"id":53893973},{"atl":[[150,4],[48,12],[28,8],[990,0.16]],"id":53893973},{"spn":3.05,"spf":1.0,"id":53893973},{"atb":[[5.8,2],[1.03,15.09],[4.1,6],[2.12,89.29],[2.18,10.35],[1.51,196.08]],"id":47095746},{"atl":[[150,4],[1000,0.16]],"id":47095746},{"spn":77.9,"spf":"NaN","id":47095746},{"atb":[[5.6,2],[1.01,45.27],[3,6],[2.2,13.06],[1.51,196.08],[3.05,6.54]],"id":61496663},{"atl":[[150,4],[48,12],[28,8],[990,0.16]],"id":61496663},{"spn":16.8,"spf":"NaN","id":61496663},{"atb":[[8,2],[2.02,30.3],[1.01,45.27],[2.12,89.29],[3.55,6],[1.51,196.08],[2.16,9.39]],"id":66596720},{"atl":[[36,8],[150,4],[60,12],[1000,0.16]],"id":66596720},{"spn":22.0,"spf":"NaN","id":66596720},{"atb":[[1.03,15.09],[5.3,2],[2.12,89.29],[3.55,6],[1.51,196.08],[2.16,8.54]],"id":53987475},{"atl":[[36,8],[150,4],[60,12],[1000,0.16]],"id":53987475},{"spn":20.65,"spf":"NaN","id":53987475}],"con":true,"img":true}]}
{"op":"mcm","clk":"11539817029","pt":1719486502941,"mc":[{"id":"1.230178306","rc":[{"atb":[[2.24,3.38],[1.03,15.09],[2.22,13.19]],"id":47801105},{"atb":[[1.03,15.09],[2.22,6.54],[2.2,0]],"id":53893973},{"atb":[[1.03,15.09],[2.18,10.35]],"id":47095746},{"atb":[[1.01,45.27],[2.2,13.06],[3.05,6.54]],"id":61496663},{"atb":[[1.01,45.27],[2.16,9.39]],"id":66596720},{"atb":[[1.03,15.09],[2.16,8.54]],"id":53987475}],"con":true,"img":false}]}
{"op":"mcm","clk":"11539817038","pt":1719486503038,"mc":[{"id":"1.230178306","rc":[{"atb":[[2.24,10.45]],"id":53893973}],"con":true,"img":false}]}
{"op":"mcm","clk":"11539820099","pt":1719486537591,"mc":[{"id":"1.230178306","rc":[{"atb":[[2.22,3.38]],"id":53893973}],"con":true,"img":false}]}
{"op":"mcm","clk":"11539820113","pt":1719486537798,"mc":[{"id":"1.230178306","rc":[{"atb":[[2.26,3.16]],"id":53893973}],"con":true,"img":false}]}
{"op":"mcm","clk":"11539826231","pt":1719486610662,"mc":[{"id":"1.230178306","rc":[{"atb":[[2.22,0]],"id":53893973}],"con":true,"img":false}]}
{"op":"mcm","clk":"11539826298","pt":1719486611439,"mc":[{"id":"1.230178306","rc":[{"atb":[[2.26,6.54]],"id":53893973}],"con":true,"img":false}]}
{"op":"mcm","clk":"11539840371","pt":1719486802533,"mc":[{"id":"1.230178306","rc":[{"atb":[[2.24,0]],"id":53893973}],"con":true,"img":false}]}
{"op":"mcm","clk":"11539840378","pt":1719486802627,"mc":[{"id":"1.230178306","rc":[{"atb":[[2.28,10.45]],"id":53893973}],"con":true,"img":false}]}
{"op":"mcm","clk":"11539842007","pt":1719486828860,"mc":[{"id":"1.230178306","rc":[{"atb":[[2.26,3.38]],"id":53893973}],"con":true,"img":false}]}
{"op":"mcm","clk":"11539843462","pt":1719486850285,"mc":[{"id":"1.230178306","rc":[{"atb":[[2.26,0]],"id":53893973}],"con":true,"img":false}]}
{"op":"mcm","clk":"11539849220","pt":1719486931082,"mc":[{"id":"1.230178306","rc":[{"atb":[[2.3,3.38]],"id":53893973}],"con":true,"img":false}]}
{"op":"mcm","clk":"11539850474","pt":1719486946687,"mc":[{"id":"1.230178306","rc":[{"atb":[[2.3,6.54]],"id":53893973}],"con":true,"img":false}]}
{"op":"mcm","clk":"11539941699","pt":1719488084351,"mc":[{"id":"1.230178306","rc":[{"atb":[[3.7,1]],"id":61496663}],"con":true,"img":false}]}
{"op":"mcm","clk":"11539942237","pt":1719488091847,"mc":[{"id":"1.230178306","rc":[{"atb":[[2.12,89.29]],"id":61496663}],"con":true,"img":false}]}
{"op":"mcm","clk":"11539942568","pt":1719488096476,"mc":[{"id":"1.230178306","rc":[{"atb":[[3.7,1]],"id":47801105}],"con":true,"img":false}]}
{"op":"mcm","clk":"11539943244","pt":1719488105860,"mc":[{"id":"1.230178306","rc":[{"atb":[[3.7,1]],"id":47095746}],"con":true,"img":false}]}
{"op":"mcm","clk":"11539943971","pt":1719488117570,"mc":[{"id":"1.230178306","rc":[{"atb":[[2.12,89.29]],"id":47801105}],"con":true,"img":false}]}
{"op":"mcm","clk":"11539944260","pt":1719488121999,"mc":[{"id":"1.230178306","rc":[{"atb":[[2.9,1]],"id":53893973}],"con":true,"img":false}]}
{"op":"mcm","clk":"11540014176","pt":1719488997039,"mc":[{"id":"1.230178306","rc":[{"atb":[[1.16,150]],"id":47801105},{"atl":[[390,2]],"id":47801105},{"atb":[[1.16,150]],"id":53893973},{"atl":[[270,2]],"id":53893973},{"atb":[[1.16,150]],"id":47095746},{"atl":[[550,2]],"id":47095746},{"atb":[[1.16,150]],"id":61496663},{"atl":[[370,2]],"id":61496663},{"atb":[[1.16,150]],"id":66596720},{"atl":[[500,2]],"id":66596720},{"atb":[[1.16,150]],"id":53987475},{"atl":[[560,2]],"id":53987475}],"con":true,"img":false}]}
{"op":"mcm","clk":"11540136006","pt":1719490397023,"mc":[{"id":"1.230178306","rc":[{"atb":[[2.3,6.54],[2.28,0]],"id":53893973},{"atb":[[3.05,6.54]],"id":61496663}],"con":true,"img":false}]}
{"op":"mcm","clk":"11540136017","pt":1719490397127,"mc":[{"id":"1.230178306","rc":[{"atb":[[2.32,10.45]],"id":53893973}],"con":true,"img":false}]}
{"op":"mcm","clk":"11540136372","pt":1719490400843,"mc":[{"id":"1.230178306","rc":[{"atb":[[2.3,3.38]],"id":53893973}],"con":true,"img":false}]}
{"op":"mcm","clk":"11540142527","pt":1719490460711,"mc":[{"id":"1.230178306","rc":[{"atb":[[2.3,0]],"id":53893973}],"con":true,"img":false}]}
{"op":"mcm","clk":"11540295659","pt":1719492626202,"mc":[{"id":"1.230178306","rc":[{"spl":[[1.01,1]],"id":47801105},{"spn":8.0,"spf":1.0,"id":47801105}],"con":true,"img":false}]}
{"op":"mcm","clk":"11540327016","pt":1719493057067,"mc":[{"id":"1.230178306","rc":[{"atl":[[27,1.67]],"id":53893973}],"con":true,"img":false}]}
{"op":"mcm","clk":"11540337343","pt":1719493205287,"mc":[{"id":"1.230178306","rc":[{"atb":[[2.24,3.38],[1.03,15.1],[2.22,13.21]],"id":47801105},{"atl":[[1000,0.16]],"id":47801105},{"atb":[[2.32,10.46],[1.03,15.1]],"id":53893973},{"atl":[[990,0.16]],"id":53893973},{"atb":[[1.03,15.1],[2.18,10.36]],"id":47095746},{"atl":[[1000,0.16]],"id":47095746},{"atb":[[1.01,45.32],[2.2,13.08],[3.05,6.54]],"id":61496663},{"atl":[[990,0.16]],"id":61496663},{"atb":[[8,0],[1.01,45.32],[2.16,9.4]],"id":66596720},{"atl":[[1000,0.16]],"id":66596720},{"trd":[[8,4]],"ltp":8.0,"tv":4.0,"id":66596720},{"spn":19.77,"spf":"NaN","id":66596720},{"atb":[[1.03,15.1],[2.16,8.55]],"id":53987475},{"atl":[[1000,0.16]],"id":53987475}],"con":true,"img":false}]}
{"op":"mcm","clk":"11540337359","pt":1719493205494,"mc":[{"id":"1.230178306","rc":[{"atl":[[36,32]],"id":66596720}],"con":true,"img":false}]}
{"op":"mcm","clk":"11540337754","pt":1719493211101,"mc":[{"id":"1.230178306","rc":[{"atl":[[36,30]],"id":66596720}],"con":true,"img":false}]}
{"op":"mcm","clk":"11540339145","pt":1719493231455,"mc":[{"id":"1.230178306","rc":[{"atb":[[3.1,5.64]],"id":61496663}],"con":true,"img":false}]}
{"op":"mcm","clk":"11540339155","pt":1719493231517,"mc":[{"id":"1.230178306","rc":[{"atb":[[2.74,6.81]],"id":47801105}],"con":true,"img":false}]}
{"op":"mcm","clk":"11540339169","pt":1719493231737,"mc":[{"id":"1.230178306","rc":[{"atb":[[2.34,8.84]],"id":53893973},{"atb":[[2.2,9.87]],"id":47095746}],"con":true,"img":false}]}
{"op":"mcm","clk":"11540339188","pt":1719493231928,"mc":[{"id":"1.230178306","rc":[{"atb":[[2.18,10.04]],"id":53987475}],"con":true,"img":false}]}
{"op":"mcm","clk":"11540339218","pt":1719493232679,"mc":[{"id":"1.230178306","rc":[{"atb":[[2.18,10.04]],"id":66596720}],"con":true,"img":false}]}
{"op":"mcm","clk":"11540340287","pt":1719493246346,"mc":[{"id":"1.230178306","rc":[{"atb":[[3.05,3.16]],"id":61496663}],"con":true,"img":false}]}
{"op":"mcm","clk":"11540340296","pt":1719493246449,"mc":[{"id":"1.230178306","rc":[{"atb":[[2.24,0]],"id":47801105}],"con":true,"img":false}]}
{"op":"mcm","clk":"11540340352","pt":1719493247233,"mc":[{"id":"1.230178306","rc":[{"atb":[[2.76,3.38]],"id":47801105}],"con":true,"img":false}]}
{"op":"mcm","clk":"11540342196","pt":1719493273274,"mc":[{"id":"1.230178306","rc":[{"atb":[[2.74,0]],"id":47801105},{"atb":[[3.1,0]],"id":61496663}],"con":true,"img":false}]}
{"op":"mcm","clk":"11540342522","pt":1719493278583,"mc":[{"id":"1.230178306","rc":[{"atb":[[3.05,8.94]],"id":61496663}],"con":true,"img":false}]}
{"op":"mcm","clk":"11540342529","pt":1719493278686,"mc":[{"id":"1.230178306","rc":[{"atb":[[2.78,6.66]],"id":47801105}],"con":true,"img":false}]}
{"op":"mcm","clk":"11540343653","pt":1719493293390,"mc":[{"id":"1.230178306","rc":[{"atb":[[2.76,0]],"id":47801105}],"con":true,"img":false}]}
{"op":"mcm","clk":"11540343676","pt":1719493293698,"mc":[{"id":"1.230178306","rc":[{"atb":[[2.36,10.27]],"id":53893973}],"con":true,"img":false}]}
{"op":"mcm","clk":"11540343682","pt":1719493293801,"mc":[{"id":"1.230178306","rc":[{"atb":[[2.2,11.64]],"id":53987475}],"con":true,"img":false}]}
{"op":"mcm","clk":"11540343719","pt":1719493294277,"mc":[{"id":"1.230178306","rc":[{"atb":[[2.22,11.45]],"id":47095746},{"atb":[[2.2,11.64]],"id":66596720}],"con":true,"img":false}]}
{"op":"mcm","clk":"11540343741","pt":1719493294582,"mc":[{"id":"1.230178306","rc":[{"atb":[[2.8,3.38]],"id":47801105}],"con":true,"img":false}]}
{"op":"mcm","clk":"11540345543","pt":1719493320701,"mc":[{"id":"1.230178306","rc":[{"atb":[[3.1,6.64]],"id":61496663}],"con":true,"img":false}]}
{"op":"mcm","clk":"11540345559","pt":1719493320905,"mc":[{"id":"1.230178306","rc":[{"atb":[[2.8,11.14]],"id":47801105}],"con":true,"img":false}]}
{"op":"mcm","clk":"11540346235","pt":1719493329527,"mc":[{"id":"1.230178306","rc":[{"atb":[[2.78,0]],"id":47801105},{"atb":[[2.34,0]],"id":53893973},{"atb":[[2.2,0]],"id":47095746},{"atb":[[2.18,0]],"id":66596720},{"atb":[[2.18,0]],"id":53987475}],"con":true,"img":false}]}
{"op":"mcm","clk":"11540346326","pt":1719493330919,"mc":[{"id":"1.230178306","rc":[{"atb":[[2.82,6.51]],"id":47801105},{"atb":[[2.22,9.71]],"id":66596720}],"con":true,"img":false}]}
{"op":"mcm","clk":"11540346352","pt":1719493331324,"mc":[{"id":"1.230178306","rc":[{"atb":[[2.24,9.55]],"id":47095746}],"con":true,"img":false}]}
{"op":"mcm","clk":"11540346363","pt":1719493331532,"mc":[{"id":"1.230178306","rc":[{"atb":[[3.05,5.78]],"id":61496663}],"con":true,"img":false}]}
{"op":"mcm","clk":"11540346389","pt":1719493331903,"mc":[{"id":"1.230178306","rc":[{"atb":[[2.38,8.58]],"id":53893973}],"con":true,"img":false}]}
{"op":"mcm","clk":"11540346416","pt":1719493332216,"mc":[{"id":"1.230178306","rc":[{"atb":[[2.22,9.71]],"id":53987475}],"con":true,"img":false}]}
{"op":"mcm","clk":"11540347745","pt":1719493351953,"mc":[{"id":"1.230178306","rc":[{"atb":[[3.05,0]],"id":61496663}],"con":true,"img":false}]}
{"op":"mcm","clk":"11540347760","pt":1719493352254,"mc":[{"id":"1.230178306","rc":[{"atb":[[2.8,7.75]],"id":47801105}],"con":true,"img":false}]}
{"op":"mcm","clk":"11540347787","pt":1719493352529,"mc":[{"id":"1.230178306","rc":[{"atb":[[2.84,3.38]],"id":47801105}],"con":true,"img":false}]}
{"op":"mcm","clk":"11540349036","pt":1719493372972,"mc":[{"id":"1.230178306","rc":[{"atb":[[3.15,5.51]],"id":61496663}],"con":true,"img":false}]}
{"op":"mcm","clk":"11540349155","pt":1719493374855,"mc":[{"id":"1.230178306","rc":[{"atb":[[2.8,0]],"id":47801105},{"atb":[[2.36,0]],"id":53893973},{"atb":[[2.22,0]],"id":47095746},{"atb":[[2.2,0]],"id":66596720},{"atb":[[2.2,0]],"id":53987475}],"con":true,"img":false}]}
{"op":"mcm","clk":"11540351218","pt":1719493405373,"mc":[{"id":"1.230178306","rc":[{"atb":[[2.82,0]],"id":47801105}],"con":true,"img":false}]}
{"op":"mcm","clk":"11540351368","pt":1719493407304,"mc":[{"id":"1.230178306","rc":[{"atb":[[2.4,9.97]],"id":53893973}],"con":true,"img":false}]}
{"op":"mcm","clk":"11540351377","pt":1719493407403,"mc":[{"id":"1.230178306","rc":[{"atb":[[2.26,11.08]],"id":47095746}],"con":true,"img":false}]}
{"op":"mcm","clk":"11540351392","pt":1719493407614,"mc":[{"id":"1.230178306","rc":[{"atb":[[2.24,11.27]],"id":66596720}],"con":true,"img":false}]}
{"op":"mcm","clk":"11540351423","pt":1719493407980,"mc":[{"id":"1.230178306","rc":[{"atb":[[2.84,0]],"id":47801105}],"con":true,"img":false}]}
{"op":"mcm","clk":"11540351467","pt":1719493408494,"mc":[{"id":"1.230178306","rc":[{"atb":[[2.24,11.27]],"id":53987475}],"con":true,"img":false}]}
{"op":"mcm","clk":"11540352552","pt":1719493424012,"mc":[{"id":"1.230178306","rc":[{"atb":[[2.38,0]],"id":53893973},{"atb":[[2.24,0]],"id":47095746},{"atb":[[2.22,0]],"id":66596720},{"atb":[[2.22,0]],"id":53987475}],"con":true,"img":false}]}
{"op":"mcm","clk":"11540353190","pt":1719493431707,"mc":[{"id":"1.230178306","rc":[{"atb":[[2.74,6.81]],"id":47801105},{"atb":[[2.28,9.25]],"id":47095746}],"con":true,"img":false}]}
{"op":"mcm","clk":"11540353216","pt":1719493431918,"mc":[{"id":"1.230178306","rc":[{"atb":[[2.26,9.4]],"id":53987475}],"con":true,"img":false}]}
{"op":"mcm","clk":"11540353240","pt":1719493432132,"mc":[{"id":"1.230178306","rc":[{"atb":[[2.26,9.4]],"id":66596720}],"con":true,"img":false}]}
{"op":"mcm","clk":"11540353282","pt":1719493432491,"mc":[{"id":"1.230178306","rc":[{"atb":[[2.42,8.34]],"id":53893973}],"con":true,"img":false}]}
{"op":"mcm","clk":"11540353902","pt":1719493440599,"mc":[{"id":"1.230178306","rc":[{"atb":[[3.1,0]],"id":61496663}],"con":true,"img":false}]}
{"op":"mcm","clk":"11540353958","pt":1719493441641,"mc":[{"id":"1.230178306","rc":[{"atb":[[5,1.11]],"id":66596720}],"con":true,"img":false}]}
{"op":"mcm","clk":"11540354712","pt":1719493450643,"mc":[{"id":"1.230178306","rc":[{"atb":[[3.2,6.35]],"id":61496663}],"con":true,"img":false}]}
{"op":"mcm","clk":"11540355292","pt":1719493458258,"mc":[{"id":"1.230178306","rc":[{"atb":[[5,0]],"id":66596720}],"con":true,"img":false}]}
{"op":"mcm","clk":"11540355703","pt":1719493463146,"mc":[{"id":"1.230178306","rc":[{"atb":[[5,3.1]],"id":66596720}],"con":true,"img":false}]}
{"op":"mcm","clk":"11540356405","pt":1719493471577,"mc":[{"id":"1.230178306","rc":[{"atb":[[3.15,0]],"id":61496663}],"con":true,"img":false}]}
{"op":"mcm","clk":"11540356653","pt":1719493475070,"mc":[{"id":"1.230178306","rc":[{"atb":[[2.4,0]],"id":53893973},{"atb":[[2.26,0]],"id":47095746},{"atb":[[2.24,0]],"id":66596720},{"atb":[[2.24,0]],"id":53987475}],"con":true,"img":false}]}
{"op":"mcm","clk":"11540357764","pt":1719493488154,"mc":[{"id":"1.230178306","rc":[{"atb":[[2.76,3.38]],"id":47801105},{"spn":20.5,"spf":"NaN","id":66596720}],"con":true,"img":false}]}
{"op":"mcm","clk":"11540357787","pt":1719493488462,"mc":[{"id":"1.230178306","rc":[{"atb":[[2.76,11.32]],"id":47801105},{"atb":[[2.3,10.74]],"id":47095746}],"con":true,"img":false}]}
{"op":"mcm","clk":"11540357809","pt":1719493488777,"mc":[{"id":"1.230178306","rc":[{"atb":[[2.44,9.7]],"id":53893973}],"con":true,"img":false}]}
{"op":"mcm","clk":"11540357825","pt":1719493488983,"mc":[{"id":"1.230178306","rc":[{"atb":[[2.28,10.91]],"id":53987475}],"con":true,"img":false}]}
{"op":"mcm","clk":"11540357892","pt":1719493489699,"mc":[{"id":"1.230178306","rc":[{"atb":[[2.28,10.91]],"id":66596720}],"con":true,"img":false}]}
{"op":"mcm","clk":"11540357911","pt":1719493489861,"mc":[{"id":"1.230178306","rc":[{"atb":[[3.25,5.26]],"id":61496663}],"con":true,"img":false}]}
{"op":"mcm","clk":"11540359485","pt":1719493510497,"mc":[{"id":"1.230178306","rc":[{"atb":[[2.74,0]],"id":47801105},{"atb":[[2.42,0]],"id":53893973},{"atb":[[2.28,0]],"id":47095746},{"atb":[[2.26,0]],"id":66596720},{"atb":[[2.26,0]],"id":53987475}],"con":true,"img":false}]}
{"op":"mcm","clk":"11540359789","pt":1719493514329,"mc":[{"id":"1.230178306","rc":[{"atb":[[5,0]],"id":66596720}],"con":true,"img":false}]}
{"op":"mcm","clk":"11540359872","pt":1719493515522,"mc":[{"id":"1.230178306","rc":[{"atb":[[3.2,0]],"id":61496663}],"con":true,"img":false}]}
{"op":"mcm","clk":"11540360617","pt":1719493525721,"mc":[{"id":"1.230178306","rc":[{"atb":[[2.76,7.93]],"id":47801105}],"con":true,"img":false}]}
{"op":"mcm","clk":"11540361021","pt":1719493531407,"mc":[{"id":"1.230178306","rc":[{"atb":[[2.78,6.66]],"id":47801105}],"con":true,"img":false}]}
{"op":"mcm","clk":"11540361033","pt":1719493531621,"mc":[{"id":"1.230178306","rc":[{"atb":[[2.46,8.11]],"id":53893973},{"atb":[[2.32,8.97]],"id":47095746}],"con":true,"img":false}]}
{"op":"mcm","clk":"11540361044","pt":1719493531823,"mc":[{"id":"1.230178306","rc":[{"atb":[[2.3,9.11]],"id":53987475}],"con":true,"img":false}]}
{"op":"mcm","clk":"11540361060","pt":1719493532036,"mc":[{"id":"1.230178306","rc":[{"atb":[[2.3,9.11]],"id":66596720}],"con":true,"img":false}]}
{"op":"mcm","clk":"11540362602","pt":1719493551675,"mc":[{"id":"1.230178306","rc":[{"atb":[[3.25,0]],"id":61496663},{"spn":19.77,"spf":"NaN","id":66596720}],"con":true,"img":false}]}
{"op":"mcm","clk":"11540362661","pt":1719493552663,"mc":[{"id":"1.230178306","rc":[{"atb":[[3.05,3.16]],"id":61496663}],"con":true,"img":false}]}
{"op":"mcm","clk":"11540362677","pt":1719493552865,"mc":[{"id":"1.230178306","rc":[{"atb":[[3.05,8.94]],"id":61496663}],"con":true,"img":false}]}
{"op":"mcm","clk":"11540362949","pt":1719493556587,"mc":[{"id":"1.230178306","rc":[{"atb":[[2.76,0]],"id":47801105},{"atb":[[2.44,0]],"id":53893973},{"atb":[[2.3,0]],"id":47095746},{"atb":[[2.28,0]],"id":66596720},{"atb":[[2.28,0]],"id":53987475}],"con":true,"img":false}]}
{"op":"mcm","clk":"11540366946","pt":1719493604527,"mc":[{"id":"1.230178306","rc":[{"atb":[[2.78,0]],"id":47801105},{"atb":[[2.46,0]],"id":53893973},{"atb":[[2.32,0]],"id":47095746},{"atb":[[2.3,0]],"id":66596720},{"atb":[[2.3,0]],"id":53987475}],"con":true,"img":false}]}
{"op":"mcm","clk":"11540367086","pt":1719493606397,"mc":[{"id":"1.230178306","rc":[{"atb":[[3.1,6.64]],"id":61496663}],"con":true,"img":false}]}
{"op":"mcm","clk":"11540367128","pt":1719493606912,"mc":[{"id":"1.230178306","rc":[{"atb":[[2.8,3.38]],"id":47801105}],"con":true,"img":false}]}
{"op":"mcm","clk":"11540367152","pt":1719493607221,"mc":[{"id":"1.230178306","rc":[{"atb":[[2.8,11.14]],"id":47801105}],"con":true,"img":false}]}
{"op":"mcm","clk":"11540367174","pt":1719493607534,"mc":[{"id":"1.230178306","rc":[{"atb":[[2.48,9.44]],"id":53893973},{"atb":[[2.34,10.42]],"id":47095746}],"con":true,"img":false}]}
{"op":"mcm","clk":"11540367207","pt":1719493608001,"mc":[{"id":"1.230178306","rc":[{"atb":[[2.32,10.58]],"id":66596720}],"con":true,"img":false}]}
{"op":"mcm","clk":"11540367215","pt":1719493608106,"mc":[{"id":"1.230178306","rc":[{"atb":[[2.32,10.58]],"id":53987475}],"con":true,"img":false}]}
{"op":"mcm","clk":"11540367424","pt":1719493610804,"mc":[{"id":"1.230178306","rc":[{"atb":[[3.05,5.78]],"id":61496663}],"con":true,"img":false}]}
{"op":"mcm","clk":"11540367443","pt":1719493611012,"mc":[{"id":"1.230178306","rc":[{"atb":[[2.34,8.84]],"id":53893973}],"con":true,"img":false}]}
{"op":"mcm","clk":"11540369082","pt":1719493631823,"mc":[{"id":"1.230178306","rc":[{"atb":[[3.05,0]],"id":61496663}],"con":true,"img":false}]}
{"op":"mcm","clk":"11540369155","pt":1719493632652,"mc":[{"id":"1.230178306","rc":[{"atb":[[2.34,8.84]],"id":53987475}],"con":true,"img":false}]}
{"op":"mcm","clk":"11540369162","pt":1719493632755,"mc":[{"id":"1.230178306","rc":[{"atb":[[2.82,6.51]],"id":47801105}],"con":true,"img":false}]}
{"op":"mcm","clk":"11540369169","pt":1719493632859,"mc":[{"id":"1.230178306","rc":[{"atb":[[2.36,8.71]],"id":47095746}],"con":true,"img":false}]}
{"op":"mcm","clk":"11540369183","pt":1719493633019,"mc":[{"id":"1.230178306","rc":[{"atb":[[2.34,8.84]],"id":66596720}],"con":true,"img":false}]}
{"op":"mcm","clk":"11540370416","pt":1719493648162,"mc":[{"id":"1.230178306","rc":[{"atb":[[2.8,7.75]],"id":47801105}],"con":true,"img":false}]}
{"op":"mcm","clk":"11540370444","pt":1719493648472,"mc":[{"id":"1.230178306","rc":[{"atb":[[2.84,3.38]],"id":47801105}],"con":true,"img":false}]}
{"op":"mcm","clk":"11540370952","pt":1719493655048,"mc":[{"id":"1.230178306","rc":[{"atb":[[3.15,5.51]],"id":61496663}],"con":true,"img":false}]}
{"op":"mcm","clk":"11540371978","pt":1719493669352,"mc":[{"id":"1.230178306","rc":[{"atb":[[3.7,10.24]],"id":47801105}],"con":true,"img":false}]}
{"op":"mcm","clk":"11540371986","pt":1719493669469,"mc":[{"id":"1.230178306","rc":[{"atb":[[2.8,0]],"id":47801105},{"atb":[[2.48,0]],"id":53893973},{"atb":[[2.34,0]],"id":47095746},{"atb":[[3.1,0]],"id":61496663},{"atb":[[2.32,0]],"id":66596720},{"atb":[[2.32,0]],"id":53987475}],"con":true,"img":false}]}
{"op":"mcm","clk":"11540372713","pt":1719493678986,"mc":[{"id":"1.230178306","rc":[{"atb":[[2.36,10.27]],"id":66596720}],"con":true,"img":false}]}
{"op":"mcm","clk":"11540372721","pt":1719493679090,"mc":[{"id":"1.230178306","rc":[{"atb":[[2.38,10.12]],"id":47095746}],"con":true,"img":false}]}
{"op":"mcm","clk":"11540372744","pt":1719493679402,"mc":[{"id":"1.230178306","rc":[{"atb":[[2.36,10.27]],"id":53987475}],"con":true,"img":false}]}
{"op":"mcm","clk":"11540372757","pt":1719493679562,"mc":[{"id":"1.230178306","rc":[{"atb":[[2.84,0]],"id":47801105}],"con":true,"img":false}]}
{"op":"mcm","clk":"11540372764","pt":1719493679664,"mc":[{"id":"1.230178306","rc":[{"atb":[[2.36,10.27]],"id":53893973}],"con":true,"img":false}]}
{"op":"mcm","clk":"11540372787","pt":1719493679872,"mc":[{"id":"1.230178306","rc":[{"atb":[[3.7,1]],"id":47801105}],"con":true,"img":false}]}
{"op":"mcm","clk":"11540373358","pt":1719493687405,"mc":[{"id":"1.230178306","rc":[{"atb":[[2.82,0]],"id":47801105}],"con":true,"img":false}]}
{"op":"mcm","clk":"11540373451","pt":1719493688396,"mc":[{"id":"1.230178306","rc":[{"atb":[[2.3,2.1]],"id":47801105}],"con":true,"img":false}]}
{"op":"mcm","clk":"11540373697","pt":1719493691898,"mc":[{"id":"1.230178306","rc":[{"atb":[[3.05,3.16]],"id":61496663}],"con":true,"img":false}]}
{"op":"mcm","clk":"11540374745","pt":1719493706621,"mc":[{"id":"1.230178306","rc":[{"atb":[[2.36,0]],"id":47095746},{"atb":[[3.15,0]],"id":61496663},{"atb":[[2.34,0]],"id":66596720},{"atb":[[2.34,0]],"id":53987475}],"con":true,"img":false}]}
{"op":"mcm","clk":"11540375196","pt":1719493712534,"mc":[{"id":"1.230178306","rc":[{"atb":[[2.34,0]],"id":53893973}],"con":true,"img":false}]}
{"op":"mcm","clk":"11540375247","pt":1719493713106,"mc":[{"id":"1.230178306","rc":[{"atb":[[3.05,8.94]],"id":61496663}],"con":true,"img":false}]}
{"op":"mcm","clk":"11540375260","pt":1719493713331,"mc":[{"id":"1.230178306","rc":[{"atb":[[2.38,8.58]],"id":53987475}],"con":true,"img":false}]}
{"op":"mcm","clk":"11540375275","pt":1719493713524,"mc":[{"id":"1.230178306","rc":[{"atb":[[2.4,8.46]],"id":47095746}],"con":true,"img":false}]}
{"op":"mcm","clk":"11540375296","pt":1719493713831,"mc":[{"id":"1.230178306","rc":[{"atb":[[2.38,8.58]],"id":66596720}],"con":true,"img":false}]}
{"op":"mcm","clk":"11540375304","pt":1719493713885,"mc":[{"id":"1.230178306","rc":[{"atb":[[2.74,6.81]],"id":47801105}],"con":true,"img":false}]}
{"op":"mcm","clk":"11540376723","pt":1719493732743,"mc":[{"id":"1.230178306","rc":[{"atb":[[2.38,8.58]],"id":53893973}],"con":true,"img":false}]}
{"op":"mcm","clk":"11540376781","pt":1719493733526,"mc":[{"id":"1.230178306","rc":[{"atb":[[2.46,2.1]],"id":53893973}],"con":true,"img":false}]}
{"op":"mcm","clk":"11540378333","pt":1719493753976,"mc":[{"id":"1.230178306","rc":[{"atb":[[2.36,0]],"id":53893973},{"atb":[[2.38,0]],"id":47095746},{"atb":[[2.36,0]],"id":66596720},{"atb":[[2.36,0]],"id":53987475}],"con":true,"img":false}]}
{"op":"mcm","clk":"11540378486","pt":1719493755956,"mc":[{"id":"1.230178306","rc":[{"atb":[[2.38,0]],"id":53893973}],"con":true,"img":false}]}
{"op":"mcm","clk":"11540379547","pt":1719493767362,"mc":[{"id":"1.230178306","rc":[{"atb":[[2.76,3.38]],"id":47801105}],"con":true,"img":false}]}
{"op":"mcm","clk":"11540379571","pt":1719493767675,"mc":[{"id":"1.230178306","rc":[{"atb":[[2.76,11.32]],"id":47801105}],"con":true,"img":false}]}
{"op":"mcm","clk":"11540379592","pt":1719493767984,"mc":[{"id":"1.230178306","rc":[{"atb":[[2.42,9.84]],"id":47095746},{"atb":[[3.1,6.64]],"id":61496663}],"con":true,"img":false}]}
{"op":"mcm","clk":"11540379609","pt":1719493768255,"mc":[{"id":"1.230178306","rc":[{"atb":[[2.34,10.42]],"id":53893973},{"atb":[[2.4,9.97]],"id":66596720}],"con":true,"img":false}]}
{"op":"mcm","clk":"11540379633","pt":1719493768558,"mc":[{"id":"1.230178306","rc":[{"atb":[[2.4,9.97]],"id":53987475}],"con":true,"img":false}]}
{"op":"mcm","clk":"11540379920","pt":1719493771992,"mc":[{"id":"1.230178306","rc":[{"atb":[[3.05,5.78]],"id":61496663}],"con":true,"img":false}]}
{"op":"mcm","clk":"11540381272","pt":1719493787396,"mc":[{"id":"1.230178306","rc":[{"atb":[[2.4,0]],"id":47095746},{"atb":[[2.38,0]],"id":66596720},{"atb":[[2.38,0]],"id":53987475}],"con":true,"img":false}]}
{"op":"mcm","clk":"11540381633","pt":1719493791984,"mc":[{"id":"1.230178306","rc":[{"atb":[[2.74,0]],"id":47801105},{"atb":[[3.05,0]],"id":61496663}],"con":true,"img":false}]}
{"op":"mcm","clk":"11540381762","pt":1719493793488,"mc":[{"id":"1.230178306","rc":[{"atb":[[2.44,8.23]],"id":47095746}],"con":true,"img":false}]}
{"op":"mcm","clk":"11540381784","pt":1719493793697,"mc":[{"id":"1.230178306","rc":[{"atb":[[2.36,8.71]],"id":53893973}],"con":true,"img":false}]}
{"op":"mcm","clk":"11540381800","pt":1719493793897,"mc":[{"id":"1.230178306","rc":[{"atb":[[2.42,8.34]],"id":66596720}],"con":true,"img":false}]}
{"op":"mcm","clk":"11540381812","pt":1719493794101,"mc":[{"id":"1.230178306","rc":[{"atb":[[2.42,8.34]],"id":53987475}],"con":true,"img":false}]}
{"op":"mcm","clk":"11540383060","pt":1719493808214,"mc":[{"id":"1.230178306","rc":[{"atb":[[2.76,7.93]],"id":47801105}],"con":true,"img":false}]}
{"op":"mcm","clk":"11540384003","pt":1719493819330,"mc":[{"id":"1.230178306","rc":[{"atb":[[3.15,5.51]],"id":61496663}],"con":true,"img":false}]}
{"op":"mcm","clk":"11540384019","pt":1719493819537,"mc":[{"id":"1.230178306","rc":[{"atb":[[2.78,6.66]],"id":47801105}],"con":true,"img":false}]}
{"op":"mcm","clk":"11540384804","pt":1719493828855,"mc":[{"id":"1.230178306","rc":[{"atb":[[2.76,0]],"id":47801105},{"atb":[[2.34,0]],"id":53893973},{"atb":[[2.42,0]],"id":47095746},{"atb":[[3.1,0]],"id":61496663},{"atb":[[2.4,0]],"id":66596720},{"atb":[[2.4,0]],"id":53987475}],"con":true,"img":false}]}
{"op":"mcm","clk":"11540386496","pt":1719493848484,"mc":[{"id":"1.230178306","rc":[{"atb":[[2.46,9.57]],"id":47095746}],"con":true,"img":false}]}
{"op":"mcm","clk":"11540386549","pt":1719493849067,"mc":[{"id":"1.230178306","rc":[{"atb":[[2.44,9.7]],"id":66596720},{"atb":[[2.44,9.7]],"id":53987475}],"con":true,"img":false}]}
{"op":"mcm","clk":"11540386592","pt":1719493849679,"mc":[{"id":"1.230178306","rc":[{"atb":[[2.38,10.12]],"id":53893973}],"con":true,"img":false}]}
{"op":"mcm","clk":"11540387201","pt":1719493857081,"mc":[{"id":"1.230178306","rc":[{"atb":[[3.05,3.16]],"id":61496663}],"con":true,"img":false}]}
{"op":"mcm","clk":"11540388508","pt":1719493871879,"mc":[{"id":"1.230178306","rc":[{"atb":[[2.78,0]],"id":47801105},{"atb":[[2.36,0]],"id":53893973},{"atb":[[2.44,0]],"id":47095746},{"atb":[[3.15,0]],"id":61496663},{"atb":[[2.42,0]],"id":66596720},{"atb":[[2.42,0]],"id":53987475}],"con":true,"img":false}]}
{"op":"mcm","clk":"11540389033","pt":1719493878579,"mc":[{"id":"1.230178306","rc":[{"atb":[[2.4,8.46]],"id":53893973}],"con":true,"img":false}]}
{"op":"mcm","clk":"11540389045","pt":1719493878693,"mc":[{"id":"1.230178306","rc":[{"atb":[[2.74,6.81]],"id":47801105}],"con":true,"img":false}]}
{"op":"mcm","clk":"11540389067","pt":1719493878904,"mc":[{"id":"1.230178306","rc":[{"atb":[[2.48,8.01]],"id":47095746}],"con":true,"img":false}]}
{"op":"mcm","clk":"11540389094","pt":1719493879202,"mc":[{"id":"1.230178306","rc":[{"atb":[[3.05,8.94]],"id":61496663},{"atb":[[2.46,8.11]],"id":53987475}],"con":true,"img":false}]}
{"op":"mcm","clk":"11540389115","pt":1719493879358,"mc":[{"id":"1.230178306","rc":[{"atb":[[2.46,8.11]],"id":66596720}],"con":true,"img":false}]}
{"op":"mcm","clk":"11540389214","pt":1719493880711,"mc":[{"id":"1.230178306","rc":[{"atl":[[190,4]],"id":47801105},{"atl":[[190,4]],"id":53893973},{"atl":[[190,4]],"id":47095746},{"atl":[[190,4]],"id":61496663},{"atl":[[190,4]],"id":66596720},{"atl":[[190,4]],"id":53987475}],"con":true,"img":false}]}
{"op":"mcm","clk":"11540390194","pt":1719493893191,"mc":[{"id":"1.230178306","rc":[{"atb":[[1.02,2]],"id":61496663}],"con":true,"img":false}]}
{"op":"mcm","clk":"11540390219","pt":1719493893504,"mc":[{"id":"1.230178306","rc":[{"atb":[[1.02,2]],"id":47801105}],"con":true,"img":false}]}
{"op":"mcm","clk":"11540390265","pt":1719493894112,"mc":[{"id":"1.230178306","rc":[{"atb":[[1.02,2]],"id":47095746}],"con":true,"img":false}]}
{"op":"mcm","clk":"11540390279","pt":1719493894319,"mc":[{"id":"1.230178306","rc":[{"atb":[[3.1,2]],"id":53893973}],"con":true,"img":false}]}
{"op":"mcm","clk":"11540390295","pt":1719493894535,"mc":[{"id":"1.230178306","rc":[{"atb":[[1.02,2]],"id":53987475}],"con":true,"img":false}]}
{"op":"mcm","clk":"11540390314","pt":1719493894790,"mc":[{"id":"1.230178306","rc":[{"atb":[[1.02,2]],"id":66596720}],"con":true,"img":false}]}
{"op":"mcm","clk":"11540392162","pt":1719493922255,"mc":[{"id":"1.230178306","rc":[{"atb":[[2.38,0]],"id":53893973},{"atb":[[2.46,0]],"id":47095746},{"atb":[[2.44,0]],"id":66596720},{"atb":[[2.44,0]],"id":53987475}],"con":true,"img":false}]}
{"op":"mcm","clk":"11540392975","pt":1719493932229,"mc":[{"id":"1.230178306","rc":[{"atb":[[2.36,5]],"id":53893973}],"con":true,"img":false}]}
{"op":"mcm","clk":"11540393048","pt":1719493933469,"mc":[{"id":"1.230178306","rc":[{"atb":[[5,3.1]],"id":66596720}],"con":true,"img":false}]}
{"op":"mcm","clk":"11540393167","pt":1719493935228,"mc":[{"id":"1.230178306","rc":[{"atb":[[3.1,6.64]],"id":61496663}],"con":true,"img":false}]}
{"op":"mcm","clk":"11540393191","pt":1719493935547,"mc":[{"id":"1.230178306","rc":[{"atb":[[2.48,9.44]],"id":53987475}],"con":true,"img":false}]}
{"op":"mcm","clk":"11540393213","pt":1719493935851,"mc":[{"id":"1.230178306","rc":[{"atb":[[2.76,3.38]],"id":47801105},{"atb":[[2.5,9.31]],"id":47095746}],"con":true,"img":false}]}
{"op":"mcm","clk":"11540393234","pt":1719493936160,"mc":[{"id":"1.230178306","rc":[{"atb":[[2.48,9.44]],"id":66596720}],"con":true,"img":false}]}
{"op":"mcm","clk":"11540393248","pt":1719493936366,"mc":[{"id":"1.230178306","rc":[{"atb":[[2.42,9.84]],"id":53893973}],"con":true,"img":false}]}
{"op":"mcm","clk":"11540393258","pt":1719493936471,"mc":[{"id":"1.230178306","rc":[{"atb":[[2.76,11.32]],"id":47801105}],"con":true,"img":false}]}
{"op":"mcm","clk":"11540393324","pt":1719493937249,"mc":[{"id":"1.230178306","rc":[{"atb":[[3.05,5.78]],"id":61496663}],"con":true,"img":false}]}
{"op":"mcm","clk":"11540395985","pt":1719493971577,"mc":[{"id":"1.230178306","rc":[{"atb":[[2.74,0]],"id":47801105},{"atb":[[2.4,0]],"id":53893973},{"spn":3.1,"spf":1.0,"id":53893973},{"atb":[[2.48,0]],"id":47095746},{"atb":[[3.05,0]],"id":61496663},{"atb":[[2.46,0]],"id":66596720},{"spn":20.5,"spf":"NaN","id":66596720},{"atb":[[2.46,0]],"id":53987475}],"con":true,"img":false}]}
{"op":"mcm","clk":"11540396213","pt":1719493974606,"mc":[{"id":"1.230178306","rc":[{"atb":[[2.76,7.93]],"id":47801105}],"con":true,"img":false}]}
{"op":"mcm","clk":"11540396612","pt":1719493979908,"mc":[{"id":"1.230178306","rc":[{"atb":[[2.78,6.66]],"id":47801105},{"atb":[[2.52,7.79]],"id":47095746}],"con":true,"img":false}]}
{"op":"mcm","clk":"11540396623","pt":1719493980114,"mc":[{"id":"1.230178306","rc":[{"atb":[[2.44,8.23]],"id":53893973},{"atb":[[2.5,7.9]],"id":66596720}],"con":true,"img":false}]}
{"op":"mcm","clk":"11540396638","pt":1719493980321,"mc":[{"id":"1.230178306","rc":[{"atb":[[3.15,5.51]],"id":61496663}],"con":true,"img":false}]}
{"op":"mcm","clk":"11540396677","pt":1719493980791,"mc":[{"id":"1.230178306","rc":[{"atb":[[2.36,0]],"id":53893973},{"atb":[[2.5,7.9]],"id":53987475}],"con":true,"img":false}]}
{"op":"mcm","clk":"11540397023","pt":1719493985312,"mc":[{"id":"1.230178306","rc":[{"atb":[[5,0]],"id":66596720}],"con":true,"img":false}]}
{"op":"mcm","clk":"11540397511","pt":1719493992201,"mc":[{"id":"1.230178306","rc":[{"atb":[[2.42,14.84]],"id":53893973}],"con":true,"img":false}]}
{"op":"mcm","clk":"11540397624","pt":1719493993496,"mc":[{"id":"1.230178306","rc":[{"atb":[[2.42,9.84]],"id":53893973}],"con":true,"img":false}]}
{"op":"mcm","clk":"11540398195","pt":1719494000228,"mc":[{"id":"1.230178306","rc":[{"atb":[[2.76,0]],"id":47801105},{"atb":[[2.42,0]],"id":53893973},{"atb":[[2.5,0]],"id":47095746},{"atb":[[3.1,0]],"id":61496663},{"atb":[[2.48,0]],"id":66596720},{"atb":[[2.48,0]],"id":53987475}],"con":true,"img":false}]}
{"op":"mcm","clk":"11540403685","pt":1719494067675,"mc":[{"id":"1.230178306","rc":[{"atb":[[3.75,21.64]],"id":66596720},{"spn":19.87,"spf":"NaN","id":66596720}],"con":true,"img":false}]}
{"op":"mcm","clk":"11540403708","pt":1719494067881,"mc":[{"id":"1.230178306","rc":[{"atb":[[3.75,0]],"id":66596720}],"con":true,"img":false}]}
{"op":"mcm","clk":"11540404276","pt":1719494075625,"mc":[{"id":"1.230178306","rc":[{"atb":[[2.78,0]],"id":47801105},{"atb":[[2.44,0]],"id":53893973},{"atb":[[2.52,0]],"id":47095746},{"atb":[[3.15,0]],"id":61496663},{"atb":[[2.5,0]],"id":66596720},{"atb":[[2.5,0]],"id":53987475}],"con":true,"img":false}]}
{"op":"mcm","clk":"11540404302","pt":1719494076090,"mc":[{"id":"1.230178306","rc":[{"atb":[[2.24,2.1]],"id":66596720}],"con":true,"img":false}]}
{"op":"mcm","clk":"11540404446","pt":1719494077805,"mc":[{"id":"1.230178306","rc":[{"atb":[[2.3,5]],"id":53893973}],"con":true,"img":false}]}
{"op":"mcm","clk":"11540404711","pt":1719494081021,"mc":[{"id":"1.230178306","rc":[{"atb":[[3.05,3.16]],"id":61496663}],"con":true,"img":false}]}
{"op":"mcm","clk":"11540404717","pt":1719494081115,"mc":[{"id":"1.230178306","rc":[{"atb":[[2.74,6.81]],"id":47801105}],"con":true,"img":false}]}
{"op":"mcm","clk":"11540404732","pt":1719494081332,"mc":[{"id":"1.230178306","rc":[{"atb":[[2.34,8.84]],"id":53893973}],"con":true,"img":false}]}
{"op":"mcm","clk":"11540404746","pt":1719494081424,"mc":[{"id":"1.230178306","rc":[{"atb":[[2.2,9.87]],"id":47095746}],"con":true,"img":false}]}
{"op":"mcm","clk":"11540404764","pt":1719494081639,"mc":[{"id":"1.230178306","rc":[{"atb":[[3.05,8.94]],"id":61496663}],"con":true,"img":false}]}
{"op":"mcm","clk":"11540404781","pt":1719494081845,"mc":[{"id":"1.230178306","rc":[{"atb":[[2.18,10.04]],"id":66596720},{"atb":[[2.18,10.04]],"id":53987475}],"con":true,"img":false}]}
{"op":"mcm","clk":"11540404835","pt":1719494082523,"mc":[{"id":"1.230178306","rc":[{"atb":[[2.28,2.1]],"id":47095746}],"con":true,"img":false}]}
{"op":"mcm","clk":"11540405564","pt":1719494093515,"mc":[{"id":"1.230178306","rc":[{"atb":[[2.3,0]],"id":53893973}],"con":true,"img":false}]}
{"op":"mcm","clk":"11540407356","pt":1719494122169,"mc":[{"id":"1.230178306","rc":[{"atb":[[8,1]],"id":47801105},{"trd":[[8,2]],"ltp":8.0,"tv":2.0,"id":47801105}],"con":true,"img":false}]}
{"op":"mcm","clk":"11540407529","pt":1719494124961,"mc":[{"id":"1.230178306","rc":[{"atb":[[8,0]],"id":47801105}],"con":true,"img":false}]}
{"op":"mcm","clk":"11540408876","pt":1719494147580,"mc":[{"id":"1.230178306","rc":[{"spn":3.7,"spf":1.0,"id":47801105},{"atb":[[2.36,10.27]],"id":53893973},{"spn":19.77,"spf":"NaN","id":66596720}],"con":true,"img":false}]}
{"op":"mcm","clk":"11540408893","pt":1719494147890,"mc":[{"id":"1.230178306","rc":[{"atb":[[2.76,3.38]],"id":47801105}],"con":true,"img":false}]}
{"op":"mcm","clk":"11540408910","pt":1719494148196,"mc":[{"id":"1.230178306","rc":[{"atb":[[2.22,11.45]],"id":47095746},{"atb":[[3.1,6.64]],"id":61496663}],"con":true,"img":false}]}
{"op":"mcm","clk":"11540408925","pt":1719494148500,"mc":[{"id":"1.230178306","rc":[{"atb":[[2.2,11.64]],"id":66596720}],"con":true,"img":false}]}
{"op":"mcm","clk":"11540408939","pt":1719494148768,"mc":[{"id":"1.230178306","rc":[{"atb":[[2.2,11.64]],"id":53987475}],"con":true,"img":false}]}
{"op":"mcm","clk":"11540408983","pt":1719494149386,"mc":[{"id":"1.230178306","rc":[{"atb":[[2.28,2.1]],"id":53987475}],"con":true,"img":false}]}
{"op":"mcm","clk":"11540409483","pt":1719494156305,"mc":[{"id":"1.230178306","rc":[{"atb":[[5,1.68]],"id":66596720}],"con":true,"img":false}]}
{"op":"mcm","clk":"11540409518","pt":1719494156813,"mc":[{"id":"1.230178306","rc":[{"atb":[[3.05,5.78]],"id":61496663}],"con":true,"img":false}]}
{"op":"mcm","clk":"11540409530","pt":1719494157021,"mc":[{"id":"1.230178306","rc":[{"atb":[[2.74,9.97]],"id":47801105}],"con":true,"img":false}]}
{"op":"mcm","clk":"11540409902","pt":1719494162725,"mc":[{"id":"1.230178306","rc":[{"atb":[[1.06,1]],"id":47801105},{"atl":[[1000,0.2]],"id":47801105}],"con":true,"img":false}]}
{"op":"mcm","clk":"11540409913","pt":1719494162894,"mc":[{"id":"1.230178306","rc":[{"atl":[[1000,0.16]],"id":47801105}],"con":true,"img":false}]}
{"op":"mcm","clk":"11540409920","pt":1719494162993,"mc":[{"id":"1.230178306","rc":[{"atb":[[1.06,0.36]],"id":47801105},{"atl":[[26,0.04]],"id":47801105}],"con":true,"img":false}]}
{"op":"mcm","clk":"11540409930","pt":1719494163191,"mc":[{"id":"1.230178306","rc":[{"atb":[[1.06,0]],"id":47801105}],"con":true,"img":false}]}
{"op":"mcm","clk":"11540409941","pt":1719494163309,"mc":[{"id":"1.230178306","rc":[{"atb":[[3.75,0.36]],"id":47801105}],"con":true,"img":false}]}
{"op":"mcm","clk":"11540410798","pt":1719494177104,"mc":[{"id":"1.230178306","rc":[{"atb":[[2.34,0]],"id":53893973},{"atb":[[2.2,0]],"id":47095746},{"atb":[[3.05,0]],"id":61496663},{"atb":[[2.18,0]],"id":66596720},{"atb":[[2.18,0]],"id":53987475}],"con":true,"img":false}]}
{"op":"mcm","clk":"11540410853","pt":1719494178197,"mc":[{"id":"1.230178306","rc":[{"atl":[[26,0]],"id":47801105}],"con":true,"img":false}]}
{"op":"mcm","clk":"11540410870","pt":1719494178405,"mc":[{"id":"1.230178306","rc":[{"atb":[[3.75,0]],"id":47801105}],"con":true,"img":false}]}
{"op":"mcm","clk":"11540410998","pt":1719494180218,"mc":[{"id":"1.230178306","rc":[{"atb":[[1.06,1]],"id":47801105},{"atl":[[1000,0.2]],"id":47801105}],"con":true,"img":false}]}
{"op":"mcm","clk":"11540411011","pt":1719494180426,"mc":[{"id":"1.230178306","rc":[{"atb":[[1.06,0.36]],"id":47801105},{"atl":[[1000,0.16]],"id":47801105}],"con":true,"img":false}]}
{"op":"mcm","clk":"11540411022","pt":1719494180530,"mc":[{"id":"1.230178306","rc":[{"atb":[[1.06,0]],"id":47801105},{"atl":[[26,0.04]],"id":47801105}],"con":true,"img":false}]}
{"op":"mcm","clk":"11540411032","pt":1719494180633,"mc":[{"id":"1.230178306","rc":[{"atb":[[3.75,0.36]],"id":47801105}],"con":true,"img":false}]}
{"op":"mcm","clk":"11540411676","pt":1719494189705,"mc":[{"id":"1.230178306","rc":[{"atb":[[5,0]],"id":66596720}],"con":true,"img":false}]}
{"op":"mcm","clk":"11540411905","pt":1719494192941,"mc":[{"id":"1.230178306","rc":[{"atb":[[1.06,1]],"id":66596720}],"con":true,"img":false}]}
{"op":"mcm","clk":"11540411916","pt":1719494193097,"mc":[{"id":"1.230178306","rc":[{"atb":[[1.06,0.38]],"id":66596720}],"con":true,"img":false}]}
{"op":"mcm","clk":"11540411930","pt":1719494193306,"mc":[{"id":"1.230178306","rc":[{"atb":[[1.06,0]],"id":66596720}],"con":true,"img":false}]}
{"op":"mcm","clk":"11540411938","pt":1719494193410,"mc":[{"id":"1.230178306","rc":[{"atb":[[3.6,0.38]],"id":66596720}],"con":true,"img":false}]}
{"op":"mcm","clk":"11540412104","pt":1719494195745,"mc":[{"id":"1.230178306","rc":[{"atl":[[26,0]],"id":47801105}],"con":true,"img":false}]}
{"op":"mcm","clk":"11540412111","pt":1719494195799,"mc":[{"id":"1.230178306","rc":[{"atb":[[3.75,0]],"id":47801105}],"con":true,"img":false}]}
{"op":"mcm","clk":"11540412190","pt":1719494197042,"mc":[{"id":"1.230178306","rc":[{"atb":[[2.24,9.55]],"id":47095746}],"con":true,"img":false}]}
{"op":"mcm","clk":"11540412197","pt":1719494197145,"mc":[{"id":"1.230178306","rc":[{"atb":[[2.22,9.71]],"id":66596720}],"con":true,"img":false}]}
{"op":"mcm","clk":"11540412250","pt":1719494197819,"mc":[{"id":"1.230178306","rc":[{"atb":[[2.22,9.71]],"id":53987475}],"con":true,"img":false}]}
{"op":"mcm","clk":"11540412255","pt":1719494197920,"mc":[{"id":"1.230178306","rc":[{"atb":[[1.06,1]],"id":47801105},{"atl":[[1000,0.2]],"id":47801105},{"atb":[[2.38,8.58]],"id":53893973}],"con":true,"img":false}]}
{"op":"mcm","clk":"11540412268","pt":1719494198127,"mc":[{"id":"1.230178306","rc":[{"atb":[[1.06,0.36]],"id":47801105},{"atl":[[1000,0.16]],"id":47801105},{"atb":[[3.15,5.51]],"id":61496663}],"con":true,"img":false}]}
{"op":"mcm","clk":"11540412276","pt":1719494198232,"mc":[{"id":"1.230178306","rc":[{"atl":[[26,0.04]],"id":47801105}],"con":true,"img":false}]}
{"op":"mcm","clk":"11540412281","pt":1719494198337,"mc":[{"id":"1.230178306","rc":[{"atb":[[1.06,0]],"id":47801105}],"con":true,"img":false}]}
{"op":"mcm","clk":"11540412288","pt":1719494198441,"mc":[{"id":"1.230178306","rc":[{"atb":[[3.75,0.36]],"id":47801105}],"con":true,"img":false}]}
{"op":"mcm","clk":"11540412950","pt":1719494208643,"mc":[{"id":"1.230178306","rc":[{"spn":3.71,"spf":1.0,"id":47801105},{"atb":[[3.6,0]],"id":66596720}],"con":true,"img":false}]}
{"op":"mcm","clk":"11540412963","pt":1719494208848,"mc":[{"id":"1.230178306","rc":[{"atb":[[1.06,1]],"id":66596720}],"con":true,"img":false}]}
{"op":"mcm","clk":"11540412975","pt":1719494209054,"mc":[{"id":"1.230178306","rc":[{"atb":[[1.06,0.38]],"id":66596720}],"con":true,"img":false}]}
{"op":"mcm","clk":"11540412987","pt":1719494209209,"mc":[{"id":"1.230178306","rc":[{"atb":[[1.06,0]],"id":66596720}],"con":true,"img":false}]}
{"op":"mcm","clk":"11540412992","pt":1719494209314,"mc":[{"id":"1.230178306","rc":[{"atb":[[3.6,0.38]],"id":66596720}],"con":true,"img":false}]}
{"op":"mcm","clk":"11540413284","pt":1719494213470,"mc":[{"id":"1.230178306","rc":[{"atl":[[26,0]],"id":47801105}],"con":true,"img":false}]}
{"op":"mcm","clk":"11540413307","pt":1719494213727,"mc":[{"id":"1.230178306","rc":[{"atb":[[3.75,0]],"id":47801105}],"con":true,"img":false}]}
{"op":"mcm","clk":"11540413441","pt":1719494216018,"mc":[{"id":"1.230178306","rc":[{"atb":[[1.06,1]],"id":47801105},{"atl":[[1000,0.2]],"id":47801105}],"con":true,"img":false}]}
{"op":"mcm","clk":"11540413464","pt":1719494216330,"mc":[{"id":"1.230178306","rc":[{"atb":[[1.06,0.36]],"id":47801105},{"atl":[[1000,0.16]],"id":47801105}],"con":true,"img":false}]}
{"op":"mcm","clk":"11540413475","pt":1719494216433,"mc":[{"id":"1.230178306","rc":[{"atl":[[26,0.04]],"id":47801105}],"con":true,"img":false}]}
{"op":"mcm","clk":"11540413484","pt":1719494216536,"mc":[{"id":"1.230178306","rc":[{"atb":[[1.06,0]],"id":47801105}],"con":true,"img":false}]}
{"op":"mcm","clk":"11540413489","pt":1719494216640,"mc":[{"id":"1.230178306","rc":[{"atb":[[3.75,0.36]],"id":47801105}],"con":true,"img":false}]}
{"op":"mcm","clk":"11540413988","pt":1719494224324,"mc":[{"id":"1.230178306","rc":[{"atb":[[2.36,0]],"id":53893973},{"atb":[[2.22,0]],"id":47095746},{"atb":[[3.1,0]],"id":61496663},{"atb":[[2.2,0]],"id":66596720},{"atb":[[2.2,0]],"id":53987475}],"con":true,"img":false}]}
{"op":"mcm","clk":"11540414004","pt":1719494225026,"mc":[{"id":"1.230178306","rc":[{"atb":[[3.6,0]],"id":66596720}],"con":true,"img":false}]}
{"op":"mcm","clk":"11540414046","pt":1719494225094,"mc":[{"id":"1.230178306","rc":[{"atb":[[1.06,1]],"id":66596720}],"con":true,"img":false}]}
{"op":"mcm","clk":"11540414059","pt":1719494225259,"mc":[{"id":"1.230178306","rc":[{"atb":[[1.06,0.38]],"id":66596720}],"con":true,"img":false}]}
{"op":"mcm","clk":"11540414075","pt":1719494225468,"mc":[{"id":"1.230178306","rc":[{"atb":[[1.06,0]],"id":66596720}],"con":true,"img":false}]}
{"op":"mcm","clk":"11540414086","pt":1719494225573,"mc":[{"id":"1.230178306","rc":[{"atb":[[3.6,0.38]],"id":66596720}],"con":true,"img":false}]}
{"op":"mcm","clk":"11540414549","pt":1719494231656,"mc":[{"id":"1.230178306","rc":[{"atl":[[26,0]],"id":47801105}],"con":true,"img":false}]}
{"op":"mcm","clk":"11540414568","pt":1719494231864,"mc":[{"id":"1.230178306","rc":[{"atb":[[3.75,0]],"id":47801105}],"con":true,"img":false}]}
{"op":"mcm","clk":"11540414687","pt":1719494233575,"mc":[{"id":"1.230178306","rc":[{"atb":[[1.06,1]],"id":47801105},{"atl":[[1000,0.2]],"id":47801105}],"con":true,"img":false}]}
{"op":"mcm","clk":"11540414695","pt":1719494233677,"mc":[{"id":"1.230178306","rc":[{"atb":[[1.06,0.36]],"id":47801105},{"atl":[[1000,0.16]],"id":47801105}],"con":true,"img":false}]}
{"op":"mcm","clk":"11540414703","pt":1719494233783,"mc":[{"id":"1.230178306","rc":[{"atb":[[1.06,0]],"id":47801105},{"atl":[[26,0.04]],"id":47801105}],"con":true,"img":false}]}
{"op":"mcm","clk":"11540414715","pt":1719494233883,"mc":[{"id":"1.230178306","rc":[{"atb":[[3.75,0.36]],"id":47801105}],"con":true,"img":false}]}
{"op":"mcm","clk":"11540415229","pt":1719494240770,"mc":[{"id":"1.230178306","rc":[{"atb":[[3.6,0]],"id":66596720}],"con":true,"img":false}]}
{"op":"mcm","clk":"11540415368","pt":1719494242374,"mc":[{"id":"1.230178306","rc":[{"atb":[[1.06,1]],"id":66596720}],"con":true,"img":false}]}
{"op":"mcm","clk":"11540415378","pt":1719494242478,"mc":[{"id":"1.230178306","rc":[{"atb":[[1.06,0.38]],"id":66596720}],"con":true,"img":false}]}
{"op":"mcm","clk":"11540415392","pt":1719494242685,"mc":[{"id":"1.230178306","rc":[{"atb":[[1.06,0]],"id":66596720}],"con":true,"img":false}]}
{"op":"mcm","clk":"11540415402","pt":1719494242789,"mc":[{"id":"1.230178306","rc":[{"atb":[[3.6,0.38]],"id":66596720}],"con":true,"img":false}]}
{"op":"mcm","clk":"11540415809","pt":1719494248983,"mc":[{"id":"1.230178306","rc":[{"atl":[[26,0]],"id":47801105}],"con":true,"img":false}]}
{"op":"mcm","clk":"11540415814","pt":1719494249089,"mc":[{"id":"1.230178306","rc":[{"atb":[[3.75,0]],"id":47801105}],"con":true,"img":false}]}
{"op":"mcm","clk":"11540415939","pt":1719494250794,"mc":[{"id":"1.230178306","rc":[{"atb":[[1.06,1]],"id":47801105},{"atl":[[1000,0.2]],"id":47801105}],"con":true,"img":false}]}
{"op":"mcm","clk":"11540415950","pt":1719494250898,"mc":[{"id":"1.230178306","rc":[{"atb":[[1.06,0.36]],"id":47801105}],"con":true,"img":false}]}
{"op":"mcm","clk":"11540415955","pt":1719494251000,"mc":[{"id":"1.230178306","rc":[{"atl":[[1000,0.16]],"id":47801105}],"con":true,"img":false}]}
{"op":"mcm","clk":"11540415964","pt":1719494251051,"mc":[{"id":"1.230178306","rc":[{"atb":[[1.06,0]],"id":47801105},{"atl":[[26,0.04]],"id":47801105}],"con":true,"img":false}]}
{"op":"mcm","clk":"11540415970","pt":1719494251156,"mc":[{"id":"1.230178306","rc":[{"atb":[[3.75,0.36]],"id":47801105}],"con":true,"img":false}]}
{"op":"mcm","clk":"11540416281","pt":1719494256485,"mc":[{"id":"1.230178306","rc":[{"atb":[[3.05,3.16]],"id":61496663}],"con":true,"img":false}]}
{"op":"mcm","clk":"11540416402","pt":1719494257980,"mc":[{"id":"1.230178306","rc":[{"atb":[[3.6,0]],"id":66596720}],"con":true,"img":false}]}
{"op":"mcm","clk":"11540416510","pt":1719494259479,"mc":[{"id":"1.230178306","rc":[{"atb":[[1.06,1]],"id":66596720}],"con":true,"img":false}]}
{"op":"mcm","clk":"11540416527","pt":1719494259688,"mc":[{"id":"1.230178306","rc":[{"atb":[[1.06,0.38]],"id":66596720}],"con":true,"img":false}]}
{"op":"mcm","clk":"11540416552","pt":1719494259999,"mc":[{"id":"1.230178306","rc":[{"atb":[[1.06,0]],"id":66596720}],"con":true,"img":false}]}
{"op":"mcm","clk":"11540416559","pt":1719494260103,"mc":[{"id":"1.230178306","rc":[{"atb":[[3.6,0.38]],"id":66596720}],"con":true,"img":false}]}
{"op":"mcm","clk":"11540416868","pt":1719494264600,"mc":[{"id":"1.230178306","rc":[{"atb":[[2.38,0]],"id":53893973},{"atb":[[2.24,0]],"id":47095746},{"atb":[[3.15,0]],"id":61496663},{"atb":[[2.22,0]],"id":66596720},{"atb":[[2.22,0]],"id":53987475}],"con":true,"img":false}]}
{"op":"mcm","clk":"11540416984","pt":1719494266385,"mc":[{"id":"1.230178306","rc":[{"atl":[[26,0]],"id":47801105}],"con":true,"img":false}]}
{"op":"mcm","clk":"11540416993","pt":1719494266488,"mc":[{"id":"1.230178306","rc":[{"atb":[[3.75,0]],"id":47801105}],"con":true,"img":false}]}
{"op":"mcm","clk":"11540417116","pt":1719494268401,"mc":[{"id":"1.230178306","rc":[{"atb":[[1.06,1]],"id":47801105},{"atl":[[1000,0.2]],"id":47801105}],"con":true,"img":false}]}
{"op":"mcm","clk":"11540417132","pt":1719494268607,"mc":[{"id":"1.230178306","rc":[{"atb":[[1.06,0.36]],"id":47801105},{"atl":[[1000,0.16]],"id":47801105}],"con":true,"img":false}]}
{"op":"mcm","clk":"11540417138","pt":1719494268710,"mc":[{"id":"1.230178306","rc":[{"atl":[[26,0.04]],"id":47801105},{"spn":3.7,"spf":1.0,"id":47801105},{"spn":19.8,"spf":"NaN","id":66596720}],"con":true,"img":false}]}
{"op":"mcm","clk":"11540417146","pt":1719494268814,"mc":[{"id":"1.230178306","rc":[{"atb":[[1.06,0]],"id":47801105}],"con":true,"img":false}]}
{"op":"mcm","clk":"11540417155","pt":1719494268915,"mc":[{"id":"1.230178306","rc":[{"atb":[[3.75,0.36]],"id":47801105}],"con":true,"img":false}]}
{"op":"mcm","clk":"11540417647","pt":1719494275301,"mc":[{"id":"1.230178306","rc":[{"atb":[[2.34,8.84]],"id":53893973},{"atb":[[3.6,0]],"id":66596720},{"atb":[[2.18,10.04]],"id":53987475}],"con":true,"img":false}]}
{"op":"mcm","clk":"11540417660","pt":1719494275609,"mc":[{"id":"1.230178306","rc":[{"atb":[[2.18,10.04]],"id":66596720}],"con":true,"img":false}]}
{"op":"mcm","clk":"11540417670","pt":1719494275816,"mc":[{"id":"1.230178306","rc":[{"atb":[[2.2,9.87]],"id":47095746}],"con":true,"img":false}]}
{"op":"mcm","clk":"11540417683","pt":1719494276022,"mc":[{"id":"1.230178306","rc":[{"atb":[[3.05,8.94]],"id":61496663}],"con":true,"img":false}]}
{"op":"mcm","clk":"11540417729","pt":1719494276797,"mc":[{"id":"1.230178306","rc":[{"atb":[[1.06,1]],"id":66596720}],"con":true,"img":false}]}
{"op":"mcm","clk":"11540417742","pt":1719494277002,"mc":[{"id":"1.230178306","rc":[{"atb":[[1.06,0.38]],"id":66596720}],"con":true,"img":false}]}
{"op":"mcm","clk":"11540417754","pt":1719494277208,"mc":[{"id":"1.230178306","rc":[{"atb":[[1.06,0]],"id":66596720}],"con":true,"img":false}]}
{"op":"mcm","clk":"11540417762","pt":1719494277311,"mc":[{"id":"1.230178306","rc":[{"atb":[[3.6,0.38]],"id":66596720}],"con":true,"img":false}]}
{"op":"mcm","clk":"11540418296","pt":1719494283904,"mc":[{"id":"1.230178306","rc":[{"atl":[[26,0]],"id":47801105}],"con":true,"img":false}]}
{"op":"mcm","clk":"11540418311","pt":1719494284112,"mc":[{"id":"1.230178306","rc":[{"atb":[[3.75,0]],"id":47801105}],"con":true,"img":false}]}
{"op":"mcm","clk":"11540418426","pt":1719494285524,"mc":[{"id":"1.230178306","rc":[{"atb":[[1.06,1]],"id":47801105},{"atl":[[1000,0.2]],"id":47801105}],"con":true,"img":false}]}
{"op":"mcm","clk":"11540418444","pt":1719494285731,"mc":[{"id":"1.230178306","rc":[{"atb":[[1.06,0.36]],"id":47801105},{"atl":[[1000,0.16]],"id":47801105}],"con":true,"img":false}]}
{"op":"mcm","clk":"11540418452","pt":1719494285835,"mc":[{"id":"1.230178306","rc":[{"atl":[[26,0.04]],"id":47801105}],"con":true,"img":false}]}
{"op":"mcm","clk":"11540418463","pt":1719494285938,"mc":[{"id":"1.230178306","rc":[{"atb":[[1.06,0]],"id":47801105}],"con":true,"img":false}]}
{"op":"mcm","clk":"11540418473","pt":1719494286001,"mc":[{"id":"1.230178306","rc":[{"atb":[[3.75,0.36]],"id":47801105}],"con":true,"img":false}]}
{"op":"mcm","clk":"11540418711","pt":1719494288823,"mc":[{"id":"1.230178306","rc":[{"atl":[[26,0.84]],"id":53893973}],"con":true,"img":false}]}
{"op":"mcm","clk":"11540419023","pt":1719494292511,"mc":[{"id":"1.230178306","rc":[{"atb":[[3.6,0]],"id":66596720}],"con":true,"img":false}]}
{"op":"mcm","clk":"11540419141","pt":1719494294117,"mc":[{"id":"1.230178306","rc":[{"atb":[[1.06,1]],"id":66596720}],"con":true,"img":false}]}
{"op":"mcm","clk":"11540419162","pt":1719494294428,"mc":[{"id":"1.230178306","rc":[{"atb":[[1.06,0.38]],"id":66596720}],"con":true,"img":false}]}
{"op":"mcm","clk":"11540419169","pt":1719494294535,"mc":[{"id":"1.230178306","rc":[{"atb":[[1.06,0]],"id":66596720}],"con":true,"img":false}]}
{"op":"mcm","clk":"11540419177","pt":1719494294628,"mc":[{"id":"1.230178306","rc":[{"atb":[[3.6,0.38]],"id":66596720}],"con":true,"img":false}]}
{"op":"mcm","clk":"11540419242","pt":1719494295417,"mc":[{"id":"1.230178306","rc":[{"atb":[[2.32,0]],"id":53893973},{"atb":[[2.18,0]],"id":47095746},{"atb":[[2.16,0]],"id":66596720},{"atb":[[2.16,0]],"id":53987475}],"con":true,"img":false}]}
{"op":"mcm","clk":"11540419248","pt":1719494295516,"mc":[{"id":"1.230178306","rc":[{"atb":[[2.36,10.46]],"id":53893973},{"atb":[[2.22,10.36]],"id":47095746},{"atb":[[2.2,9.4]],"id":66596720},{"atb":[[2.2,8.55]],"id":53987475}],"con":true,"img":false}]}
{"op":"mcm","clk":"11540419714","pt":1719494301022,"mc":[{"id":"1.230178306","rc":[{"atl":[[26,0]],"id":47801105}],"con":true,"img":false}]}
{"op":"mcm","clk":"11540419733","pt":1719494301224,"mc":[{"id":"1.230178306","rc":[{"atb":[[3.75,0]],"id":47801105}],"con":true,"img":false}]}
{"op":"mcm","clk":"11540419854","pt":1719494302734,"mc":[{"id":"1.230178306","rc":[{"atb":[[1.06,1]],"id":47801105},{"atl":[[1000,0.2]],"id":47801105}],"con":true,"img":false}]}
{"op":"mcm","clk":"11540419862","pt":1719494302835,"mc":[{"id":"1.230178306","rc":[{"atb":[[1.06,0.36]],"id":47801105},{"atl":[[1000,0.16]],"id":47801105}],"con":true,"img":false}]}
{"op":"mcm","clk":"11540419870","pt":1719494302938,"mc":[{"id":"1.230178306","rc":[{"atl":[[26,0.04]],"id":47801105}],"con":true,"img":false}]}
{"op":"mcm","clk":"11540419882","pt":1719494303042,"mc":[{"id":"1.230178306","rc":[{"atb":[[1.06,0]],"id":47801105}],"con":true,"img":false}]}
{"op":"mcm","clk":"11540419890","pt":1719494303146,"mc":[{"id":"1.230178306","rc":[{"atb":[[3.75,0.36]],"id":47801105}],"con":true,"img":false}]}
{"op":"mcm","clk":"11540420469","pt":1719494309857,"mc":[{"id":"1.230178306","rc":[{"atb":[[3.6,0]],"id":66596720}],"con":true,"img":false}]}
{"op":"mcm","clk":"11540420508","pt":1719494310264,"mc":[{"id":"1.230178306","rc":[{"atb":[[3.1,6.64]],"id":61496663}],"con":true,"img":false}]}
{"op":"mcm","clk":"11540420567","pt":1719494310952,"mc":[{"id":"1.230178306","rc":[{"atl":[[36,29]],"id":66596720}],"con":true,"img":false}]}
{"op":"mcm","clk":"11540420578","pt":1719494311058,"mc":[{"id":"1.230178306","rc":[{"atl":[[36,33.17]],"id":66596720}],"con":true,"img":false}]}
{"op":"mcm","clk":"11540420600","pt":1719494311266,"mc":[{"id":"1.230178306","rc":[{"atb":[[1.06,1]],"id":66596720},{"atl":[[36,37.34]],"id":66596720}],"con":true,"img":false}]}
{"op":"mcm","clk":"11540420619","pt":1719494311463,"mc":[{"id":"1.230178306","rc":[{"atb":[[1.06,0.38]],"id":66596720}],"con":true,"img":false}]}
{"op":"mcm","clk":"11540420640","pt":1719494311671,"mc":[{"id":"1.230178306","rc":[{"atb":[[1.06,0]],"id":66596720}],"con":true,"img":false}]}
{"op":"mcm","clk":"11540420650","pt":1719494311777,"mc":[{"id":"1.230178306","rc":[{"atb":[[3.6,0.38]],"id":66596720}],"con":true,"img":false}]}
{"op":"mcm","clk":"11540421177","pt":1719494318177,"mc":[{"id":"1.230178306","rc":[{"atl":[[26,0]],"id":47801105}],"con":true,"img":false}]}
{"op":"mcm","clk":"11540421199","pt":1719494318387,"mc":[{"id":"1.230178306","rc":[{"atb":[[3.75,0]],"id":47801105}],"con":true,"img":false}]}
{"op":"mcm","clk":"11540421312","pt":1719494320044,"mc":[{"id":"1.230178306","rc":[{"atb":[[1.06,1]],"id":47801105},{"atl":[[1000,0.2]],"id":47801105}],"con":true,"img":false}]}
{"op":"mcm","clk":"11540421328","pt":1719494320249,"mc":[{"id":"1.230178306","rc":[{"atb":[[1.06,0.36]],"id":47801105},{"atl":[[1000,0.16]],"id":47801105}],"con":true,"img":false}]}
{"op":"mcm","clk":"11540421332","pt":1719494320353,"mc":[{"id":"1.230178306","rc":[{"atl":[[26,0.04]],"id":47801105}],"con":true,"img":false}]}
{"op":"mcm","clk":"11540421340","pt":1719494320457,"mc":[{"id":"1.230178306","rc":[{"atb":[[1.06,0]],"id":47801105},{"atb":[[2.34,0]],"id":53893973},{"atb":[[2.2,0]],"id":47095746},{"atb":[[2.18,0]],"id":66596720},{"atb":[[2.18,0]],"id":53987475}],"con":true,"img":false}]}
{"op":"mcm","clk":"11540421348","pt":1719494320560,"mc":[{"id":"1.230178306","rc":[{"atb":[[3.75,0.36]],"id":47801105}],"con":true,"img":false}]}
{"op":"mcm","clk":"11540421847","pt":1719494326958,"mc":[{"id":"1.230178306","rc":[{"atb":[[3.6,0]],"id":66596720}],"con":true,"img":false}]}
{"op":"mcm","clk":"11540422002","pt":1719494328661,"mc":[{"id":"1.230178306","rc":[{"atb":[[1.06,1]],"id":66596720}],"con":true,"img":false}]}
{"op":"mcm","clk":"11540422012","pt":1719494328764,"mc":[{"id":"1.230178306","rc":[{"spn":3.71,"spf":1.0,"id":47801105},{"atb":[[1.06,0.38]],"id":66596720},{"spn":19.77,"spf":"NaN","id":66596720}],"con":true,"img":false}]}
{"op":"mcm","clk":"11540422028","pt":1719494328970,"mc":[{"id":"1.230178306","rc":[{"atb":[[1.06,0]],"id":66596720}],"con":true,"img":false}]}
{"op":"mcm","clk":"11540422033","pt":1719494329073,"mc":[{"id":"1.230178306","rc":[{"atb":[[3.6,0.38]],"id":66596720}],"con":true,"img":false}]}
{"op":"mcm","clk":"11540422624","pt":1719494335565,"mc":[{"id":"1.230178306","rc":[{"atl":[[26,0]],"id":47801105}],"con":true,"img":false}]}
{"op":"mcm","clk":"11540422639","pt":1719494335777,"mc":[{"id":"1.230178306","rc":[{"atb":[[3.75,0]],"id":47801105}],"con":true,"img":false}]}
{"op":"mcm","clk":"11540422778","pt":1719494337182,"mc":[{"id":"1.230178306","rc":[{"atb":[[1.06,1]],"id":47801105},{"atl":[[1000,0.2]],"id":47801105}],"con":true,"img":false}]}
{"op":"mcm","clk":"11540422806","pt":1719494337482,"mc":[{"id":"1.230178306","rc":[{"atb":[[1.06,0.36]],"id":47801105},{"atl":[[1000,0.16]],"id":47801105}],"con":true,"img":false}]}
{"op":"mcm","clk":"11540422817","pt":1719494337585,"mc":[{"id":"1.230178306","rc":[{"atl":[[26,0.04]],"id":47801105}],"con":true,"img":false}]}
{"op":"mcm","clk":"11540422823","pt":1719494337690,"mc":[{"id":"1.230178306","rc":[{"atb":[[1.06,0]],"id":47801105}],"con":true,"img":false}]}
{"op":"mcm","clk":"11540422829","pt":1719494337793,"mc":[{"id":"1.230178306","rc":[{"atb":[[3.75,0.36]],"id":47801105}],"con":true,"img":false}]}
{"op":"mcm","clk":"11540423069","pt":1719494340587,"mc":[{"id":"1.230178306","rc":[{"atb":[[5.3,3.02]],"id":53987475}],"con":true,"img":false}]}
{"op":"mcm","clk":"11540423422","pt":1719494344285,"mc":[{"id":"1.230178306","rc":[{"atb":[[3.6,0]],"id":66596720}],"con":true,"img":false}]}
{"op":"mcm","clk":"11540423593","pt":1719494345889,"mc":[{"id":"1.230178306","rc":[{"atb":[[2.24,9.55]],"id":47095746},{"atb":[[3.05,5.78]],"id":61496663},{"atb":[[1.06,1]],"id":66596720}],"con":true,"img":false}]}
{"op":"mcm","clk":"11540423617","pt":1719494346096,"mc":[{"id":"1.230178306","rc":[{"atb":[[1.06,0.38]],"id":66596720},{"atb":[[2.22,9.71]],"id":53987475}],"con":true,"img":false}]}
{"op":"mcm","clk":"11540423633","pt":1719494346303,"mc":[{"id":"1.230178306","rc":[{"atb":[[1.06,0]],"id":66596720}],"con":true,"img":false}]}
{"op":"mcm","clk":"11540423646","pt":1719494346362,"mc":[{"id":"1.230178306","rc":[{"atb":[[3.6,0.38]],"id":66596720}],"con":true,"img":false}]}
{"op":"mcm","clk":"11540423682","pt":1719494346782,"mc":[{"id":"1.230178306","rc":[{"atb":[[2.22,9.71]],"id":66596720}],"con":true,"img":false}]}
{"op":"mcm","clk":"11540423707","pt":1719494346983,"mc":[{"id":"1.230178306","rc":[{"atb":[[2.38,8.58]],"id":53893973}],"con":true,"img":false}]}
{"op":"mcm","clk":"11540424212","pt":1719494352795,"mc":[{"id":"1.230178306","rc":[{"atl":[[26,0]],"id":47801105}],"con":true,"img":false}]}
{"op":"mcm","clk":"11540424222","pt":1719494352898,"mc":[{"id":"1.230178306","rc":[{"atb":[[3.75,0]],"id":47801105}],"con":true,"img":false}]}
{"op":"mcm","clk":"11540424369","pt":1719494354709,"mc":[{"id":"1.230178306","rc":[{"atb":[[1.06,1]],"id":47801105},{"atl":[[1000,0.2]],"id":47801105}],"con":true,"img":false}]}
{"op":"mcm","clk":"11540424389","pt":1719494354885,"mc":[{"id":"1.230178306","rc":[{"atb":[[1.06,0.36]],"id":47801105},{"atl":[[1000,0.16]],"id":47801105}],"con":true,"img":false}]}
{"op":"mcm","clk":"11540424402","pt":1719494354989,"mc":[{"id":"1.230178306","rc":[{"atl":[[26,0.04]],"id":47801105}],"con":true,"img":false}]}
{"op":"mcm","clk":"11540424412","pt":1719494355088,"mc":[{"id":"1.230178306","rc":[{"atb":[[1.06,0]],"id":47801105}],"con":true,"img":false}]}
{"op":"mcm","clk":"11540424421","pt":1719494355193,"mc":[{"id":"1.230178306","rc":[{"atb":[[3.75,0.36]],"id":47801105}],"con":true,"img":false}]}
{"op":"mcm","clk":"11540424954","pt":1719494361602,"mc":[{"id":"1.230178306","rc":[{"atb":[[3.6,0]],"id":66596720}],"con":true,"img":false}]}
{"op":"mcm","clk":"11540425072","pt":1719494363412,"mc":[{"id":"1.230178306","rc":[{"atb":[[1.06,1]],"id":66596720}],"con":true,"img":false}]}
{"op":"mcm","clk":"11540425093","pt":1719494363621,"mc":[{"id":"1.230178306","rc":[{"atb":[[1.06,0.38]],"id":66596720}],"con":true,"img":false}]}
{"op":"mcm","clk":"11540425115","pt":1719494363830,"mc":[{"id":"1.230178306","rc":[{"atb":[[1.06,0]],"id":66596720}],"con":true,"img":false}]}
{"op":"mcm","clk":"11540425126","pt":1719494363883,"mc":[{"id":"1.230178306","rc":[{"atb":[[3.6,0.38]],"id":66596720}],"con":true,"img":false}]}
{"op":"mcm","clk":"11540425330","pt":1719494366123,"mc":[{"id":"1.230178306","rc":[{"atb":[[3.05,0]],"id":61496663}],"con":true,"img":false}]}
{"op":"mcm","clk":"11540425659","pt":1719494370227,"mc":[{"id":"1.230178306","rc":[{"atl":[[26,0]],"id":47801105}],"con":true,"img":false}]}
{"op":"mcm","clk":"11540425672","pt":1719494370442,"mc":[{"id":"1.230178306","rc":[{"atb":[[3.75,0]],"id":47801105}],"con":true,"img":false}]}
{"op":"mcm","clk":"11540425760","pt":1719494371419,"mc":[{"id":"1.230178306","rc":[{"atb":[[3.15,5.51]],"id":61496663}],"con":true,"img":false}]}
{"op":"mcm","clk":"11540425842","pt":1719494372207,"mc":[{"id":"1.230178306","rc":[{"atb":[[1.06,1]],"id":47801105},{"atl":[[1000,0.2]],"id":47801105}],"con":true,"img":false}]}
{"op":"mcm","clk":"11540425864","pt":1719494372415,"mc":[{"id":"1.230178306","rc":[{"atb":[[1.06,0.36]],"id":47801105},{"atl":[[1000,0.16]],"id":47801105}],"con":true,"img":false}]}
{"op":"mcm","clk":"11540425872","pt":1719494372520,"mc":[{"id":"1.230178306","rc":[{"atl":[[26,0.04]],"id":47801105}],"con":true,"img":false}]}
{"op":"mcm","clk":"11540425886","pt":1719494372626,"mc":[{"id":"1.230178306","rc":[{"atb":[[1.06,0]],"id":47801105}],"con":true,"img":false}]}
{"op":"mcm","clk":"11540425894","pt":1719494372718,"mc":[{"id":"1.230178306","rc":[{"atb":[[3.75,0.36]],"id":47801105}],"con":true,"img":false}]}
{"op":"mcm","clk":"11540426433","pt":1719494379043,"mc":[{"id":"1.230178306","rc":[{"atb":[[3.6,0]],"id":66596720}],"con":true,"img":false}]}
{"op":"mcm","clk":"11540426588","pt":1719494381024,"mc":[{"id":"1.230178306","rc":[{"atb":[[1.06,1]],"id":66596720}],"con":true,"img":false}]}
{"op":"mcm","clk":"11540426606","pt":1719494381231,"mc":[{"id":"1.230178306","rc":[{"atb":[[1.06,0.38]],"id":66596720}],"con":true,"img":false}]}
{"op":"mcm","clk":"11540426622","pt":1719494381439,"mc":[{"id":"1.230178306","rc":[{"atb":[[1.06,0]],"id":66596720}],"con":true,"img":false}]}
{"op":"mcm","clk":"11540426632","pt":1719494381536,"mc":[{"id":"1.230178306","rc":[{"atb":[[3.6,0.38]],"id":66596720}],"con":true,"img":false}]}
{"op":"mcm","clk":"11540427203","pt":1719494387854,"mc":[{"id":"1.230178306","rc":[{"atl":[[26,0]],"id":47801105}],"con":true,"img":false}]}
{"op":"mcm","clk":"11540427220","pt":1719494388026,"mc":[{"id":"1.230178306","rc":[{"atb":[[3.75,0]],"id":47801105}],"con":true,"img":false}]}
{"op":"mcm","clk":"11540427395","pt":1719494390156,"mc":[{"id":"1.230178306","rc":[{"atb":[[1.06,1]],"id":47801105},{"atl":[[1000,0.2]],"id":47801105},{"spn":3.7,"spf":1.0,"id":47801105},{"spn":19.8,"spf":"NaN","id":66596720}],"con":true,"img":false}]}
{"op":"mcm","clk":"11540427411","pt":1719494390352,"mc":[{"id":"1.230178306","rc":[{"atb":[[1.06,0.36]],"id":47801105},{"atl":[[1000,0.16]],"id":47801105}],"con":true,"img":false}]}
{"op":"mcm","clk":"11540427419","pt":1719494390456,"mc":[{"id":"1.230178306","rc":[{"atl":[[26,0.04]],"id":47801105}],"con":true,"img":false}]}
{"op":"mcm","clk":"11540427424","pt":1719494390522,"mc":[{"id":"1.230178306","rc":[{"atb":[[1.06,0]],"id":47801105}],"con":true,"img":false}]}
{"op":"mcm","clk":"11540427434","pt":1719494390626,"mc":[{"id":"1.230178306","rc":[{"atb":[[3.75,0.36]],"id":47801105}],"con":true,"img":false}]}
{"op":"mcm","clk":"11540427957","pt":1719494396755,"mc":[{"id":"1.230178306","rc":[{"atb":[[3.6,0]],"id":66596720}],"con":true,"img":false}]}
{"op":"mcm","clk":"11540428184","pt":1719494399152,"mc":[{"id":"1.230178306","rc":[{"atb":[[1.06,1]],"id":66596720}],"con":true,"img":false}]}
{"op":"mcm","clk":"11540428208","pt":1719494399356,"mc":[{"id":"1.230178306","rc":[{"atb":[[1.06,0.38]],"id":66596720}],"con":true,"img":false}]}
{"op":"mcm","clk":"11540428224","pt":1719494399564,"mc":[{"id":"1.230178306","rc":[{"atb":[[1.06,0]],"id":66596720}],"con":true,"img":false}]}
{"op":"mcm","clk":"11540428235","pt":1719494399669,"mc":[{"id":"1.230178306","rc":[{"atb":[[3.6,0.38]],"id":66596720}],"con":true,"img":false}]}
{"op":"mcm","clk":"11540428778","pt":1719494405671,"mc":[{"id":"1.230178306","rc":[{"atl":[[26,0]],"id":47801105}],"con":true,"img":false}]}
{"op":"mcm","clk":"11540428810","pt":1719494405986,"mc":[{"id":"1.230178306","rc":[{"atb":[[3.75,0]],"id":47801105}],"con":true,"img":false}]}
{"op":"mcm","clk":"11540428977","pt":1719494407586,"mc":[{"id":"1.230178306","rc":[{"atb":[[1.06,1]],"id":47801105},{"atl":[[1000,0.2]],"id":47801105}],"con":true,"img":false}]}
{"op":"mcm","clk":"11540429001","pt":1719494407779,"mc":[{"id":"1.230178306","rc":[{"atb":[[1.06,0.36]],"id":47801105},{"atl":[[1000,0.16]],"id":47801105}],"con":true,"img":false}]}
{"op":"mcm","clk":"11540429012","pt":1719494407860,"mc":[{"id":"1.230178306","rc":[{"atb":[[1.06,0]],"id":47801105},{"atl":[[26,0.04]],"id":47801105}],"con":true,"img":false}]}
{"op":"mcm","clk":"11540429023","pt":1719494407977,"mc":[{"id":"1.230178306","rc":[{"atb":[[3.75,0.36]],"id":47801105}],"con":true,"img":false}]}
{"op":"mcm","clk":"11540429665","pt":1719494414879,"mc":[{"id":"1.230178306","rc":[{"atb":[[3.6,0]],"id":66596720}],"con":true,"img":false}]}
{"op":"mcm","clk":"11540429764","pt":1719494416083,"mc":[{"id":"1.230178306","rc":[{"atb":[[1.06,1]],"id":66596720}],"con":true,"img":false}]}
{"op":"mcm","clk":"11540429775","pt":1719494416187,"mc":[{"id":"1.230178306","rc":[{"atb":[[1.06,0.38]],"id":66596720}],"con":true,"img":false}]}
{"op":"mcm","clk":"11540429794","pt":1719494416397,"mc":[{"id":"1.230178306","rc":[{"atb":[[1.06,0]],"id":66596720}],"con":true,"img":false}]}
{"op":"mcm","clk":"11540429806","pt":1719494416488,"mc":[{"id":"1.230178306","rc":[{"atb":[[3.6,0.38]],"id":66596720}],"con":true,"img":false}]}
{"op":"mcm","clk":"11540430198","pt":1719494420484,"mc":[{"id":"1.230178306","rc":[{"atb":[[3.1,0]],"id":61496663}],"con":true,"img":false}]}
{"op":"mcm","clk":"11540430423","pt":1719494423084,"mc":[{"id":"1.230178306","rc":[{"atl":[[26,0]],"id":47801105}],"con":true,"img":false}]}
{"op":"mcm","clk":"11540430430","pt":1719494423186,"mc":[{"id":"1.230178306","rc":[{"atb":[[3.75,0]],"id":47801105}],"con":true,"img":false}]}
{"op":"mcm","clk":"11540430549","pt":1719494424490,"mc":[{"id":"1.230178306","rc":[{"atb":[[1.06,1]],"id":47801105},{"atl":[[1000,0.2]],"id":47801105}],"con":true,"img":false}]}
{"op":"mcm","clk":"11540430567","pt":1719494424587,"mc":[{"id":"1.230178306","rc":[{"atb":[[1.06,0.36]],"id":47801105},{"atl":[[1000,0.16]],"id":47801105}],"con":true,"img":false}]}
{"op":"mcm","clk":"11540430575","pt":1719494424701,"mc":[{"id":"1.230178306","rc":[{"atb":[[1.06,0]],"id":47801105},{"atl":[[26,0.04]],"id":47801105}],"con":true,"img":false}]}
{"op":"mcm","clk":"11540430584","pt":1719494424794,"mc":[{"id":"1.230178306","rc":[{"atb":[[3.75,0.36]],"id":47801105}],"con":true,"img":false}]}
{"op":"mcm","clk":"11540431214","pt":1719494431703,"mc":[{"id":"1.230178306","rc":[{"atb":[[3.6,0]],"id":66596720}],"con":true,"img":false}]}
{"op":"mcm","clk":"11540431303","pt":1719494432796,"mc":[{"id":"1.230178306","rc":[{"atb":[[1.06,1]],"id":66596720}],"con":true,"img":false}]}
{"op":"mcm","clk":"11540431316","pt":1719494432898,"mc":[{"id":"1.230178306","rc":[{"atb":[[1.06,0.38]],"id":66596720}],"con":true,"img":false}]}
{"op":"mcm","clk":"11540431329","pt":1719494433004,"mc":[{"id":"1.230178306","rc":[{"atb":[[1.06,0]],"id":66596720}],"con":true,"img":false}]}
{"op":"mcm","clk":"11540431340","pt":1719494433106,"mc":[{"id":"1.230178306","rc":[{"atb":[[3.6,0.38]],"id":66596720}],"con":true,"img":false}]}
{"op":"mcm","clk":"11540431635","pt":1719494436107,"mc":[{"id":"1.230178306","rc":[{"atb":[[3.2,6.35]],"id":61496663}],"con":true,"img":false}]}
{"op":"mcm","clk":"11540431662","pt":1719494436417,"mc":[{"id":"1.230178306","rc":[{"atb":[[2.4,9.97]],"id":53893973},{"atb":[[2.26,11.08]],"id":47095746}],"con":true,"img":false}]}
{"op":"mcm","clk":"11540431691","pt":1719494436690,"mc":[{"id":"1.230178306","rc":[{"atb":[[2.24,13.37]],"id":66596720}],"con":true,"img":false}]}
{"op":"mcm","clk":"11540431715","pt":1719494437003,"mc":[{"id":"1.230178306","rc":[{"atb":[[2.24,11.27]],"id":53987475}],"con":true,"img":false}]}
{"op":"mcm","clk":"11540431976","pt":1719494439912,"mc":[{"id":"1.230178306","rc":[{"atl":[[26,0]],"id":47801105}],"con":true,"img":false}]}
{"op":"mcm","clk":"11540431986","pt":1719494440008,"mc":[{"id":"1.230178306","rc":[{"atb":[[3.75,0]],"id":47801105}],"con":true,"img":false}]}
{"op":"mcm","clk":"11540432007","pt":1719494440214,"mc":[{"id":"1.230178306","rc":[{"atl":[[36,21.34]],"id":66596720}],"con":true,"img":false}]}
{"op":"mcm","clk":"11540432024","pt":1719494440420,"mc":[{"id":"1.230178306","rc":[{"atl":[[36,26.23]],"id":66596720}],"con":true,"img":false}]}
{"op":"mcm","clk":"11540432166","pt":1719494441891,"mc":[{"id":"1.230178306","rc":[{"atb":[[1.06,1]],"id":47801105},{"atl":[[1000,0.2]],"id":47801105}],"con":true,"img":false}]}
{"op":"mcm","clk":"11540432175","pt":1719494441994,"mc":[{"id":"1.230178306","rc":[{"atb":[[1.06,0.36]],"id":47801105},{"atl":[[1000,0.16]],"id":47801105}],"con":true,"img":false}]}
{"op":"mcm","clk":"11540432183","pt":1719494442098,"mc":[{"id":"1.230178306","rc":[{"atb":[[1.06,0]],"id":47801105},{"atl":[[26,0.04]],"id":47801105}],"con":true,"img":false}]}
{"op":"mcm","clk":"11540432191","pt":1719494442201,"mc":[{"id":"1.230178306","rc":[{"atb":[[3.75,0.36]],"id":47801105}],"con":true,"img":false}]}
{"op":"mcm","clk":"11540432730","pt":1719494448324,"mc":[{"id":"1.230178306","rc":[{"atb":[[3.6,0]],"id":66596720}],"con":true,"img":false}]}
{"op":"mcm","clk":"11540432971","pt":1719494450913,"mc":[{"id":"1.230178306","rc":[{"spn":3.71,"spf":1.0,"id":47801105},{"atb":[[1.06,1]],"id":66596720},{"spn":19.77,"spf":"NaN","id":66596720}],"con":true,"img":false}]}
{"op":"mcm","clk":"11540432993","pt":1719494451120,"mc":[{"id":"1.230178306","rc":[{"atb":[[1.06,0.38]],"id":66596720}],"con":true,"img":false}]}
{"op":"mcm","clk":"11540433005","pt":1719494451222,"mc":[{"id":"1.230178306","rc":[{"atb":[[1.06,0]],"id":66596720}],"con":true,"img":false}]}
{"op":"mcm","clk":"11540433012","pt":1719494451329,"mc":[{"id":"1.230178306","rc":[{"atb":[[3.6,0.38]],"id":66596720}],"con":true,"img":false}]}
{"op":"mcm","clk":"11540433055","pt":1719494451837,"mc":[{"id":"1.230178306","rc":[{"atb":[[4,23.33]],"id":47801105}],"con":true,"img":false}]}
{"op":"mcm","clk":"11540433284","pt":1719494454432,"mc":[{"id":"1.230178306","rc":[{"atb":[[3.15,0]],"id":61496663}],"con":true,"img":false}]}
{"op":"mcm","clk":"11540433428","pt":1719494456039,"mc":[{"id":"1.230178306","rc":[{"atb":[[2.74,6.81]],"id":47801105}],"con":true,"img":false}]}
{"op":"mcm","clk":"11540433543","pt":1719494457330,"mc":[{"id":"1.230178306","rc":[{"atl":[[26,0]],"id":47801105}],"con":true,"img":false}]}
{"op":"mcm","clk":"11540433550","pt":1719494457431,"mc":[{"id":"1.230178306","rc":[{"atb":[[3.75,0]],"id":47801105}],"con":true,"img":false}]}
{"op":"mcm","clk":"11540433764","pt":1719494459920,"mc":[{"id":"1.230178306","rc":[{"atb":[[1.07,1]],"id":47801105},{"atl":[[1000,0.2]],"id":47801105}],"con":true,"img":false}]}
{"op":"mcm","clk":"11540433775","pt":1719494460022,"mc":[{"id":"1.230178306","rc":[{"atb":[[1.07,0.32]],"id":47801105},{"atl":[[1000,0.16]],"id":47801105}],"con":true,"img":false}]}
{"op":"mcm","clk":"11540433785","pt":1719494460124,"mc":[{"id":"1.230178306","rc":[{"atb":[[1.09,1.69],[1.07,0]],"id":47801105},{"atl":[[26,0.04]],"id":47801105},{"atb":[[1.14,1.69]],"id":61496663}],"con":true,"img":false}]}
{"op":"mcm","clk":"11540433797","pt":1719494460226,"mc":[{"id":"1.230178306","rc":[{"atb":[[4,26.72],[4.1,0.32]],"id":47801105},{"atl":[[26,4.04]],"id":47801105},{"atb":[[2.26,79.37]],"id":53893973},{"atl":[[20,2]],"id":53893973},{"atb":[[3.4,9.56]],"id":47095746},{"atl":[[120,2]],"id":47095746},{"atb":[[3.1,13.09]],"id":61496663},{"atl":[[27,3.85]],"id":61496663},{"atb":[[3.6,6.38]],"id":66596720},{"atl":[[36,29.09]],"id":66596720},{"atb":[[3.1,9.72]],"id":53987475},{"atl":[[34,3.03]],"id":53987475}],"con":true,"img":false}]}
{"op":"mcm","clk":"11540433815","pt":1719494460425,"mc":[{"id":"1.230178306","rc":[{"atb":[[1.08,1.69]],"id":53893973},{"atb":[[1.12,1.69]],"id":53987475}],"con":true,"img":false}]}
{"op":"mcm","clk":"11540433841","pt":1719494460737,"mc":[{"id":"1.230178306","rc":[{"atl":[[19.5,2]],"id":53893973},{"atb":[[1.14,1.69]],"id":47095746},{"atb":[[1.08,1.69]],"id":66596720}],"con":true,"img":false}]}
{"op":"mcm","clk":"11540433868","pt":1719494461050,"mc":[{"id":"1.230178306","rc":[{"atb":[[1.09,0.07]],"id":47801105},{"atb":[[1.08,0.09]],"id":53893973}],"con":true,"img":false}]}
{"op":"mcm","clk":"11540433911","pt":1719494461330,"mc":[{"id":"1.230178306","rc":[{"atb":[[1.08,0.08]],"id":66596720}],"con":true,"img":false}]}
{"op":"mcm","clk":"11540433920","pt":1719494461431,"mc":[{"id":"1.230178306","rc":[{"atb":[[1.14,0.05]],"id":47095746}],"con":true,"img":false}]}
{"op":"mcm","clk":"11540433942","pt":1719494461639,"mc":[{"id":"1.230178306","rc":[{"atb":[[1.14,0.05]],"id":61496663}],"con":true,"img":false}]}
{"op":"mcm","clk":"11540433949","pt":1719494461730,"mc":[{"id":"1.230178306","rc":[{"atb":[[1.12,0.05]],"id":53987475}],"con":true,"img":false}]}
{"op":"mcm","clk":"11540433960","pt":1719494461843,"mc":[{"id":"1.230178306","rc":[{"atl":[[27,0]],"id":53893973}],"con":true,"img":false}]}
{"op":"mcm","clk":"11540433984","pt":1719494462055,"mc":[{"id":"1.230178306","rc":[{"atb":[[1.09,0]],"id":47801105}],"con":true,"img":false}]}
{"op":"mcm","clk":"11540433995","pt":1719494462164,"mc":[{"id":"1.230178306","rc":[{"atb":[[4.1,0.39]],"id":47801105}],"con":true,"img":false}]}
{"op":"mcm","clk":"11540434020","pt":1719494462525,"mc":[{"id":"1.230178306","rc":[{"atb":[[1.08,0]],"id":53893973}],"con":true,"img":false}]}
{"op":"mcm","clk":"11540434029","pt":1719494462626,"mc":[{"id":"1.230178306","rc":[{"atb":[[3.15,0.09]],"id":53893973}],"con":true,"img":false}]}
{"op":"mcm","clk":"11540434051","pt":1719494462938,"mc":[{"id":"1.230178306","rc":[{"atb":[[1.08,0]],"id":66596720}],"con":true,"img":false}]}
{"op":"mcm","clk":"11540434059","pt":1719494463045,"mc":[{"id":"1.230178306","rc":[{"atb":[[3.6,6.46]],"id":66596720}],"con":true,"img":false}]}
{"op":"mcm","clk":"11540434093","pt":1719494463443,"mc":[{"id":"1.230178306","rc":[{"atb":[[1.14,0]],"id":47095746},{"atl":[[36,57.09]],"id":66596720}],"con":true,"img":false}]}
{"op":"mcm","clk":"11540434100","pt":1719494463548,"mc":[{"id":"1.230178306","rc":[{"atb":[[5.9,0.05]],"id":47095746}],"con":true,"img":false}]}
{"op":"mcm","clk":"11540434131","pt":1719494463917,"mc":[{"id":"1.230178306","rc":[{"atb":[[1.14,0]],"id":61496663}],"con":true,"img":false}]}
{"op":"mcm","clk":"11540434140","pt":1719494464019,"mc":[{"id":"1.230178306","rc":[{"atb":[[5.7,0.05]],"id":61496663}],"con":true,"img":false}]}
{"op":"mcm","clk":"11540434162","pt":1719494464227,"mc":[{"id":"1.230178306","rc":[{"atb":[[3.65,1]],"id":47801105},{"atl":[[14,1]],"id":47801105},{"atl":[[5.4,1]],"id":53893973},{"atl":[[11,1]],"id":47095746},{"atl":[[9.4,1]],"id":61496663},{"atb":[[4.9,1]],"id":66596720},{"atl":[[18.5,1]],"id":66596720},{"atl":[[11.5,1]],"id":53987475}],"con":true,"img":false}]}
{"op":"mcm","clk":"11540434171","pt":1719494464328,"mc":[{"id":"1.230178306","rc":[{"atl":[[18.5,34],[36,19.92]],"id":66596720},{"atb":[[1.12,0]],"id":53987475}],"con":true,"img":false}]}
{"op":"mcm","clk":"11540434181","pt":1719494464432,"mc":[{"id":"1.230178306","rc":[{"atl":[[18,4.17]],"id":66596720},{"atb":[[5.4,0.05]],"id":53987475}],"con":true,"img":false}]}
{"op":"mcm","clk":"11540434194","pt":1719494464538,"mc":[{"id":"1.230178306","rc":[{"atl":[[18,37.17],[18.5,1]],"id":66596720}],"con":true,"img":false}]}
{"op":"mcm","clk":"11540434231","pt":1719494464852,"mc":[{"id":"1.230178306","rc":[{"atb":[[4.6,1]],"id":47801105}],"con":true,"img":false}]}
{"op":"mcm","clk":"11540434242","pt":1719494464955,"mc":[{"id":"1.230178306","rc":[{"atb":[[3.65,0]],"id":47801105},{"atl":[[19.5,0]],"id":53893973},{"atb":[[4.9,0],[5.5,1]],"id":66596720}],"con":true,"img":false}]}
{"op":"mcm","clk":"11540434254","pt":1719494465057,"mc":[{"id":"1.230178306","rc":[{"atb":[[3.4,1.54]],"id":66596720}],"con":true,"img":false}]}
{"op":"mcm","clk":"11540434276","pt":1719494465222,"mc":[{"id":"1.230178306","rc":[{"atb":[[3.4,0]],"id":66596720}],"con":true,"img":false}]}
{"op":"mcm","clk":"11540434297","pt":1719494465429,"mc":[{"id":"1.230178306","rc":[{"atb":[[1.03,16.81]],"id":47801105},{"atl":[[1000,1.87]],"id":47801105},{"atl":[[1000,1.87]],"id":47095746},{"atb":[[1.04,1.7]],"id":61496663},{"atl":[[1000,1.7]],"id":61496663}],"con":true,"img":false}]}
{"op":"mcm","clk":"11540434307","pt":1719494465532,"mc":[{"id":"1.230178306","rc":[{"atb":[[1.04,1.7]],"id":47095746}],"con":true,"img":false}]}
{"op":"mcm","clk":"11540434317","pt":1719494465629,"mc":[{"id":"1.230178306","rc":[{"atb":[[1.03,15.21]],"id":47801105},{"atl":[[1000,0.18]],"id":47801105},{"atl":[[1000,0.16]],"id":47095746},{"atb":[[1.04,0.06]],"id":61496663},{"atl":[[1000,0.01]],"id":61496663}],"con":true,"img":false}]}
{"op":"mcm","clk":"11540434326","pt":1719494465734,"mc":[{"id":"1.230178306","rc":[{"atb":[[1.04,0.06]],"id":47095746}],"con":true,"img":false}]}
{"op":"mcm","clk":"11540434333","pt":1719494465830,"mc":[{"id":"1.230178306","rc":[{"atb":[[1.03,15.1]],"id":47801105},{"atl":[[1000,0.16]],"id":47801105},{"atb":[[1.04,0]],"id":61496663},{"atl":[[1000,0]],"id":61496663}],"con":true,"img":false}]}
{"op":"mcm","clk":"11540434344","pt":1719494465941,"mc":[{"id":"1.230178306","rc":[{"atb":[[4.1,0.49]],"id":47801105},{"atl":[[25,0.01]],"id":47801105},{"atb":[[1.04,0]],"id":47095746},{"atb":[[5.7,0.11]],"id":61496663},{"atl":[[26,0.01]],"id":61496663}],"con":true,"img":false}]}
{"op":"mcm","clk":"11540434356","pt":1719494466044,"mc":[{"id":"1.230178306","rc":[{"atb":[[5.9,0.11]],"id":47095746}],"con":true,"img":false}]}
{"op":"mcm","clk":"11540434391","pt":1719494466445,"mc":[{"id":"1.230178306","rc":[{"atb":[[3.6,6.08]],"id":66596720}],"con":true,"img":false}]}
{"op":"mcm","clk":"11540434571","pt":1719494468317,"mc":[{"id":"1.230178306","rc":[{"atb":[[3.25,5.26]],"id":61496663}],"con":true,"img":false}]}
{"op":"mcm","clk":"11540434746","pt":1719494470338,"mc":[{"id":"1.230178306","rc":[{"atl":[[17,2],[20,0]],"id":53893973},{"atl":[[85,2],[120,0]],"id":47095746},{"atl":[[30,3.45]],"id":66596720}],"con":true,"img":false}]}
{"op":"mcm","clk":"11540434754","pt":1719494470431,"mc":[{"id":"1.230178306","rc":[{"atl":[[36,17.06]],"id":66596720}],"con":true,"img":false}]}
{"op":"mcm","clk":"11540434983","pt":1719494473026,"mc":[{"id":"1.230178306","rc":[{"atl":[[5.3,2]],"id":53893973}],"con":true,"img":false}]}
{"op":"mcm","clk":"11540434997","pt":1719494473231,"mc":[{"id":"1.230178306","rc":[{"atl":[[17,0],[5.4,5]],"id":53893973}],"con":true,"img":false}]}
{"op":"mcm","clk":"11540435046","pt":1719494473953,"mc":[{"id":"1.230178306","rc":[{"atl":[[18,33]],"id":66596720}],"con":true,"img":false}]}
{"op":"mcm","clk":"11540435054","pt":1719494474057,"mc":[{"id":"1.230178306","rc":[{"atl":[[36,12.89]],"id":66596720}],"con":true,"img":false}]}
{"op":"mcm","clk":"11540435063","pt":1719494474160,"mc":[{"id":"1.230178306","rc":[{"atl":[[17.5,4.17]],"id":66596720}],"con":true,"img":false}]}
{"op":"mcm","clk":"11540435070","pt":1719494474213,"mc":[{"id":"1.230178306","rc":[{"atl":[[5.1,1],[5.4,4]],"id":53893973},{"atl":[[10.5,1],[11,0]],"id":47095746},{"atl":[[17.5,37.17],[18,0]],"id":66596720},{"atl":[[9,1],[11.5,0]],"id":53987475}],"con":true,"img":false}]}
{"op":"mcm","clk":"11540435087","pt":1719494474421,"mc":[{"id":"1.230178306","rc":[{"atl":[[17.5,33]],"id":66596720}],"con":true,"img":false}]}
{"op":"mcm","clk":"11540435095","pt":1719494474525,"mc":[{"id":"1.230178306","rc":[{"atl":[[18.5,5.17]],"id":66596720}],"con":true,"img":false}]}
{"op":"mcm","clk":"11540435114","pt":1719494474731,"mc":[{"id":"1.230178306","rc":[{"atl":[[18.5,1]],"id":66596720}],"con":true,"img":false}]}
{"op":"mcm","clk":"11540435124","pt":1719494474834,"mc":[{"id":"1.230178306","rc":[{"atl":[[17,4.17]],"id":66596720}],"con":true,"img":false}]}
{"op":"mcm","clk":"11540435141","pt":1719494475040,"mc":[{"id":"1.230178306","rc":[{"atl":[[17,37.17],[17.5,0],[36,8]],"id":66596720}],"con":true,"img":false}]}
{"op":"mcm","clk":"11540435153","pt":1719494475154,"mc":[{"id":"1.230178306","rc":[{"atl":[[16.5,4.89]],"id":66596720}],"con":true,"img":false}]}
{"op":"mcm","clk":"11540435161","pt":1719494475247,"mc":[{"id":"1.230178306","rc":[{"atl":[[26,4]],"id":47801105},{"atl":[[5.3,0]],"id":53893973},{"atl":[[16.5,37.89],[17,0]],"id":66596720}],"con":true,"img":false}]}
{"op":"mcm","clk":"11540435171","pt":1719494475356,"mc":[{"id":"1.230178306","rc":[{"atb":[[4.1,0.17]],"id":47801105},{"atl":[[17,6.25],[5.4,0]],"id":53893973},{"atl":[[16,4.17]],"id":66596720}],"con":true,"img":false}]}
{"op":"mcm","clk":"11540435178","pt":1719494475454,"mc":[{"id":"1.230178306","rc":[{"atl":[[16,37.17],[16.5,0]],"id":66596720}],"con":true,"img":false}]}
{"op":"mcm","clk":"11540435187","pt":1719494475555,"mc":[{"id":"1.230178306","rc":[{"atl":[[18.5,5.89]],"id":66596720}],"con":true,"img":false}]}
{"op":"mcm","clk":"11540435198","pt":1719494475668,"mc":[{"id":"1.230178306","rc":[{"atl":[[16,33]],"id":66596720}],"con":true,"img":false}]}
{"op":"mcm","clk":"11540435204","pt":1719494475711,"mc":[{"id":"1.230178306","rc":[{"atl":[[18,4.17]],"id":66596720}],"con":true,"img":false}]}
{"op":"mcm","clk":"11540435213","pt":1719494475820,"mc":[{"id":"1.230178306","rc":[{"atl":[[18,0]],"id":66596720}],"con":true,"img":false}]}
{"op":"mcm","clk":"11540435223","pt":1719494475919,"mc":[{"id":"1.230178306","rc":[{"atl":[[15.5,4.17]],"id":66596720}],"con":true,"img":false}]}
{"op":"mcm","clk":"11540435234","pt":1719494476023,"mc":[{"id":"1.230178306","rc":[{"atl":[[18.5,1],[15.5,37.17]],"id":66596720}],"con":true,"img":false}]}
{"op":"mcm","clk":"11540435242","pt":1719494476128,"mc":[{"id":"1.230178306","rc":[{"atl":[[16,0],[15,4.89]],"id":66596720}],"con":true,"img":false}]}
{"op":"mcm","clk":"11540435253","pt":1719494476234,"mc":[{"id":"1.230178306","rc":[{"atl":[[15,37.89],[15.5,33]],"id":66596720}],"con":true,"img":false}]}
{"op":"mcm","clk":"11540435261","pt":1719494476337,"mc":[{"id":"1.230178306","rc":[{"atl":[[14.5,4.17],[15.5,0]],"id":66596720}],"con":true,"img":false}]}
{"op":"mcm","clk":"11540435274","pt":1719494476441,"mc":[{"id":"1.230178306","rc":[{"atl":[[14.5,37.17],[15,4.89]],"id":66596720}],"con":true,"img":false}]}
{"op":"mcm","clk":"11540435344","pt":1719494477325,"mc":[{"id":"1.230178306","rc":[{"atb":[[1.08,1]],"id":47801105}],"con":true,"img":false}]}
{"op":"mcm","clk":"11540435361","pt":1719494477535,"mc":[{"id":"1.230178306","rc":[{"atb":[[1.08,0.27]],"id":47801105}],"con":true,"img":false}]}
{"op":"mcm","clk":"11540435368","pt":1719494477644,"mc":[{"id":"1.230178306","rc":[{"atb":[[1.08,0]],"id":47801105}],"con":true,"img":false}]}
{"op":"mcm","clk":"11540435379","pt":1719494477735,"mc":[{"id":"1.230178306","rc":[{"atb":[[4.7,0.27]],"id":47801105}],"con":true,"img":false}]}
{"op":"mcm","clk":"11540435517","pt":1719494479454,"mc":[{"id":"1.230178306","rc":[{"atb":[[2.76,0]],"id":47801105}],"con":true,"img":false}]}
{"op":"mcm","clk":"11540435559","pt":1719494479822,"mc":[{"id":"1.230178306","rc":[{"atb":[[2.76,7.93]],"id":47801105}],"con":true,"img":false}]}
{"op":"mcm","clk":"11540435620","pt":1719494480446,"mc":[{"id":"1.230178306","rc":[{"atl":[[5,2]],"id":53893973}],"con":true,"img":false}]}
{"op":"mcm","clk":"11540435937","pt":1719494484228,"mc":[{"id":"1.230178306","rc":[{"atl":[[9,0],[9.2,1]],"id":53987475}],"con":true,"img":false}]}
{"op":"mcm","clk":"11540436027","pt":1719494485326,"mc":[{"id":"1.230178306","rc":[{"atl":[[17,0],[5.2,6.25]],"id":53893973}],"con":true,"img":false}]}
{"op":"mcm","clk":"11540436054","pt":1719494485634,"mc":[{"id":"1.230178306","rc":[{"atl":[[5,0]],"id":53893973}],"con":true,"img":false}]}
{"op":"mcm","clk":"11540436073","pt":1719494485839,"mc":[{"id":"1.230178306","rc":[{"atl":[[16,6.67],[5.2,0]],"id":53893973}],"con":true,"img":false}]}
{"op":"mcm","clk":"11540436229","pt":1719494487555,"mc":[{"id":"1.230178306","rc":[{"atl":[[14,1.81]],"id":66596720}],"con":true,"img":false}]}
{"op":"mcm","clk":"11540436240","pt":1719494487662,"mc":[{"id":"1.230178306","rc":[{"atl":[[5,2]],"id":53893973},{"atl":[[14,34.81],[14.5,4.17]],"id":66596720}],"con":true,"img":false}]}
{"op":"mcm","clk":"11540436251","pt":1719494487764,"mc":[{"id":"1.230178306","rc":[{"atl":[[14.5,0]],"id":66596720}],"con":true,"img":false}]}
{"op":"mcm","clk":"11540436264","pt":1719494487867,"mc":[{"id":"1.230178306","rc":[{"atl":[[13.5,4.17]],"id":66596720}],"con":true,"img":false}]}
{"op":"mcm","clk":"11540436277","pt":1719494487922,"mc":[{"id":"1.230178306","rc":[{"atl":[[13.5,37.17]],"id":66596720}],"con":true,"img":false}]}
{"op":"mcm","clk":"11540436284","pt":1719494488026,"mc":[{"id":"1.230178306","rc":[{"atl":[[14,1.81]],"id":66596720}],"con":true,"img":false}]}
{"op":"mcm","clk":"11540436302","pt":1719494488230,"mc":[{"id":"1.230178306","rc":[{"atl":[[14,0]],"id":66596720}],"con":true,"img":false}]}
{"op":"mcm","clk":"11540436317","pt":1719494488441,"mc":[{"id":"1.230178306","rc":[{"atl":[[13,1.95],[13.5,33]],"id":66596720}],"con":true,"img":false}]}
{"op":"mcm","clk":"11540436327","pt":1719494488545,"mc":[{"id":"1.230178306","rc":[{"atl":[[15,9.06]],"id":66596720}],"con":true,"img":false}]}
{"op":"mcm","clk":"11540436334","pt":1719494488650,"mc":[{"id":"1.230178306","rc":[{"atl":[[13,34.95],[13.5,0]],"id":66596720}],"con":true,"img":false}]}
{"op":"mcm","clk":"11540436345","pt":1719494488753,"mc":[{"id":"1.230178306","rc":[{"atl":[[15,4.89]],"id":66596720}],"con":true,"img":false}]}
{"op":"mcm","clk":"11540436352","pt":1719494488857,"mc":[{"id":"1.230178306","rc":[{"atl":[[12.5,4.17]],"id":66596720}],"con":true,"img":false}]}
{"op":"mcm","clk":"11540436364","pt":1719494488966,"mc":[{"id":"1.230178306","rc":[{"atl":[[12.5,37.17],[13,1.95]],"id":66596720}],"con":true,"img":false}]}
{"op":"mcm","clk":"11540436373","pt":1719494489065,"mc":[{"id":"1.230178306","rc":[{"atl":[[15,0]],"id":66596720}],"con":true,"img":false}]}
{"op":"mcm","clk":"11540436384","pt":1719494489168,"mc":[{"id":"1.230178306","rc":[{"atl":[[12,4.89],[13,0]],"id":66596720}],"con":true,"img":false}]}
{"op":"mcm","clk":"11540436392","pt":1719494489273,"mc":[{"id":"1.230178306","rc":[{"atl":[[12,37.89],[12.5,4.17]],"id":66596720}],"con":true,"img":false}]}
{"op":"mcm","clk":"11540436405","pt":1719494489375,"mc":[{"id":"1.230178306","rc":[{"atl":[[11.5,2.21],[12.5,0]],"id":66596720}],"con":true,"img":false}]}
{"op":"mcm","clk":"11540436414","pt":1719494489429,"mc":[{"id":"1.230178306","rc":[{"atl":[[11.5,39.38]],"id":66596720}],"con":true,"img":false}]}
{"op":"mcm","clk":"11540436425","pt":1719494489533,"mc":[{"id":"1.230178306","rc":[{"atl":[[12,4.89]],"id":66596720}],"con":true,"img":false}]}
{"op":"mcm","clk":"11540436431","pt":1719494489636,"mc":[{"id":"1.230178306","rc":[{"atl":[[12,0]],"id":66596720}],"con":true,"img":false}]}
{"op":"mcm","clk":"11540436439","pt":1719494489744,"mc":[{"id":"1.230178306","rc":[{"atl":[[11,4.89]],"id":66596720}],"con":true,"img":false}]}
{"op":"mcm","clk":"11540436458","pt":1719494489946,"mc":[{"id":"1.230178306","rc":[{"atl":[[11,37.89],[11.5,2.21]],"id":66596720}],"con":true,"img":false}]}
{"op":"mcm","clk":"11540436470","pt":1719494490050,"mc":[{"id":"1.230178306","rc":[{"atl":[[18.5,5.17],[11.5,0]],"id":66596720}],"con":true,"img":false}]}
{"op":"mcm","clk":"11540436490","pt":1719494490261,"mc":[{"id":"1.230178306","rc":[{"atl":[[10.5,2.42],[11,33]],"id":66596720}],"con":true,"img":false}]}
{"op":"mcm","clk":"11540436500","pt":1719494490364,"mc":[{"id":"1.230178306","rc":[{"atl":[[18,4.89],[10.5,35.42],[11,0]],"id":66596720}],"con":true,"img":false}]}
{"op":"mcm","clk":"11540436517","pt":1719494490573,"mc":[{"id":"1.230178306","rc":[{"atl":[[18.5,1]],"id":66596720}],"con":true,"img":false}]}
{"op":"mcm","clk":"11540436531","pt":1719494490634,"mc":[{"id":"1.230178306","rc":[{"atl":[[10,4.17]],"id":66596720}],"con":true,"img":false}]}
{"op":"mcm","clk":"11540436539","pt":1719494490737,"mc":[{"id":"1.230178306","rc":[{"atl":[[18,0],[10,37.17],[10.5,2.42]],"id":66596720}],"con":true,"img":false}]}
{"op":"mcm","clk":"11540436550","pt":1719494490844,"mc":[{"id":"1.230178306","rc":[{"atl":[[10,42.06]],"id":66596720}],"con":true,"img":false}]}
{"op":"mcm","clk":"11540436559","pt":1719494490941,"mc":[{"id":"1.230178306","rc":[{"atl":[[10.5,0]],"id":66596720}],"con":true,"img":false}]}
{"op":"mcm","clk":"11540436578","pt":1719494491144,"mc":[{"id":"1.230178306","rc":[{"atl":[[10,37.89],[9.8,2.59]],"id":66596720}],"con":true,"img":false}]}
{"op":"mcm","clk":"11540436587","pt":1719494491249,"mc":[{"id":"1.230178306","rc":[{"atl":[[18.5,5.17]],"id":66596720}],"con":true,"img":false}]}
{"op":"mcm","clk":"11540436595","pt":1719494491351,"mc":[{"id":"1.230178306","rc":[{"atl":[[10,4.89],[9.8,35.59]],"id":66596720}],"con":true,"img":false}]}
{"op":"mcm","clk":"11540436605","pt":1719494491452,"mc":[{"id":"1.230178306","rc":[{"atl":[[18.5,1]],"id":66596720}],"con":true,"img":false}]}
{"op":"mcm","clk":"11540436611","pt":1719494491560,"mc":[{"id":"1.230178306","rc":[{"atl":[[9.6,4.17]],"id":66596720}],"con":true,"img":false}]}
{"op":"mcm","clk":"11540436619","pt":1719494491660,"mc":[{"id":"1.230178306","rc":[{"atl":[[9.6,37.17]],"id":66596720}],"con":true,"img":false}]}
{"op":"mcm","clk":"11540436629","pt":1719494491762,"mc":[{"id":"1.230178306","rc":[{"atl":[[10,0],[9.8,0]],"id":66596720}],"con":true,"img":false}]}
{"op":"mcm","clk":"11540436636","pt":1719494491865,"mc":[{"id":"1.230178306","rc":[{"atl":[[9.4,4.89]],"id":66596720}],"con":true,"img":false}]}
{"op":"mcm","clk":"11540436644","pt":1719494491971,"mc":[{"id":"1.230178306","rc":[{"atl":[[9.6,4.17],[9.4,40.59]],"id":66596720}],"con":true,"img":false}]}
{"op":"mcm","clk":"11540436654","pt":1719494492074,"mc":[{"id":"1.230178306","rc":[{"atl":[[9.6,0]],"id":66596720}],"con":true,"img":false}]}
{"op":"mcm","clk":"11540436662","pt":1719494492132,"mc":[{"id":"1.230178306","rc":[{"atl":[[18.5,5.17]],"id":66596720}],"con":true,"img":false}]}
{"op":"mcm","clk":"11540436681","pt":1719494492339,"mc":[{"id":"1.230178306","rc":[{"atl":[[9.4,35.7]],"id":66596720}],"con":true,"img":false}]}
{"op":"mcm","clk":"11540436690","pt":1719494492441,"mc":[{"id":"1.230178306","rc":[{"atl":[[18.5,10.06]],"id":66596720}],"con":true,"img":false}]}
{"op":"mcm","clk":"11540436701","pt":1719494492551,"mc":[{"id":"1.230178306","rc":[{"atb":[[2.74,0]],"id":47801105},{"atb":[[2.38,0]],"id":53893973},{"atb":[[2.24,0]],"id":47095746},{"atb":[[2.22,0]],"id":66596720},{"atl":[[18.5,5.17]],"id":66596720},{"atb":[[2.22,0]],"id":53987475}],"con":true,"img":false}]}
{"op":"mcm","clk":"11540436713","pt":1719494492646,"mc":[{"id":"1.230178306","rc":[{"atl":[[9.2,4.89]],"id":66596720}],"con":true,"img":false}]}
{"op":"mcm","clk":"11540436731","pt":1719494492855,"mc":[{"id":"1.230178306","rc":[{"atb":[[4.7,0]],"id":47801105},{"atl":[[5,0]],"id":53893973},{"atl":[[18.5,1],[9.2,37.89],[9.4,2.7]],"id":66596720}],"con":true,"img":false}]}
{"op":"mcm","clk":"11540436742","pt":1719494492957,"mc":[{"id":"1.230178306","rc":[{"atl":[[9,4.17]],"id":66596720}],"con":true,"img":false}]}
{"op":"mcm","clk":"11540436760","pt":1719494493166,"mc":[{"id":"1.230178306","rc":[{"atl":[[9,37.17],[9.2,0]],"id":66596720}],"con":true,"img":false}]}
{"op":"mcm","clk":"11540436771","pt":1719494493269,"mc":[{"id":"1.230178306","rc":[{"atl":[[8.8,4.89]],"id":66596720}],"con":true,"img":false}]}
{"op":"mcm","clk":"11540436778","pt":1719494493371,"mc":[{"id":"1.230178306","rc":[{"atl":[[8.8,37.89]],"id":66596720}],"con":true,"img":false}]}
{"op":"mcm","clk":"11540436787","pt":1719494493475,"mc":[{"id":"1.230178306","rc":[{"atl":[[9,0]],"id":66596720}],"con":true,"img":false}]}
{"op":"mcm","clk":"11540436793","pt":1719494493579,"mc":[{"id":"1.230178306","rc":[{"atl":[[9.4,4.17]],"id":66596720}],"con":true,"img":false}]}
{"op":"mcm","clk":"11540436810","pt":1719494493736,"mc":[{"id":"1.230178306","rc":[{"atl":[[8.8,33]],"id":66596720}],"con":true,"img":false}]}
{"op":"mcm","clk":"11540436818","pt":1719494493839,"mc":[{"id":"1.230178306","rc":[{"atl":[[9.4,9.06]],"id":66596720}],"con":true,"img":false}]}
{"op":"mcm","clk":"11540436825","pt":1719494493947,"mc":[{"id":"1.230178306","rc":[{"atl":[[9.4,4.17]],"id":66596720}],"con":true,"img":false}]}
{"op":"mcm","clk":"11540436833","pt":1719494494046,"mc":[{"id":"1.230178306","rc":[{"atl":[[8.6,4.89]],"id":66596720}],"con":true,"img":false}]}
{"op":"mcm","clk":"11540436843","pt":1719494494149,"mc":[{"id":"1.230178306","rc":[{"atl":[[8.6,37.89],[9.4,0]],"id":66596720}],"con":true,"img":false}]}
{"op":"mcm","clk":"11540436852","pt":1719494494252,"mc":[{"id":"1.230178306","rc":[{"atl":[[8.8,0],[8.4,7.19]],"id":66596720}],"con":true,"img":false}]}
{"op":"mcm","clk":"11540436858","pt":1719494494355,"mc":[{"id":"1.230178306","rc":[{"atl":[[8.6,33],[8.4,40.19]],"id":66596720}],"con":true,"img":false}]}
{"op":"mcm","clk":"11540436866","pt":1719494494459,"mc":[{"id":"1.230178306","rc":[{"atl":[[8.6,0],[8.2,4.89]],"id":66596720}],"con":true,"img":false}]}
{"op":"mcm","clk":"11540436882","pt":1719494494632,"mc":[{"id":"1.230178306","rc":[{"atl":[[8.2,37.89],[8.4,7.19]],"id":66596720}],"con":true,"img":false}]}
{"op":"mcm","clk":"11540436907","pt":1719494494946,"mc":[{"id":"1.230178306","rc":[{"atb":[[1.08,1]],"id":47801105},{"atl":[[5,2]],"id":53893973},{"atl":[[8.4,4.17]],"id":66596720}],"con":true,"img":false}]}
{"op":"mcm","clk":"11540436934","pt":1719494495155,"mc":[{"id":"1.230178306","rc":[{"atb":[[1.08,0.27]],"id":47801105},{"atl":[[8,3.17]],"id":66596720}],"con":true,"img":false}]}
{"op":"mcm","clk":"11540436946","pt":1719494495258,"mc":[{"id":"1.230178306","rc":[{"atb":[[1.08,0]],"id":47801105},{"atl":[[8,36.17],[8.2,4.89]],"id":66596720}],"con":true,"img":false}]}
{"op":"mcm","clk":"11540436957","pt":1719494495362,"mc":[{"id":"1.230178306","rc":[{"atb":[[4.7,0.27]],"id":47801105}],"con":true,"img":false}]}
{"op":"mcm","clk":"11540436997","pt":1719494495776,"mc":[{"id":"1.230178306","rc":[{"atl":[[16,0],[5.2,6.67]],"id":53893973}],"con":true,"img":false}]}
{"op":"mcm","clk":"11540437332","pt":1719494499258,"mc":[{"id":"1.230178306","rc":[{"atb":[[2.78,6.66]],"id":47801105}],"con":true,"img":false}]}
{"op":"mcm","clk":"11540437344","pt":1719494499359,"mc":[{"id":"1.230178306","rc":[{"atb":[[3.45,4.83]],"id":47095746}],"con":true,"img":false}]}
{"op":"mcm","clk":"11540437360","pt":1719494499465,"mc":[{"id":"1.230178306","rc":[{"atb":[[3.15,5.51]],"id":53987475}],"con":true,"img":false}]}
{"op":"mcm","clk":"11540437386","pt":1719494499672,"mc":[{"id":"1.230178306","rc":[{"atb":[[2.42,8.34]],"id":53893973}],"con":true,"img":false}]}
{"op":"mcm","clk":"11540437421","pt":1719494500139,"mc":[{"id":"1.230178306","rc":[{"atl":[[5,0]],"id":53893973}],"con":true,"img":false}]}
{"op":"mcm","clk":"11540437431","pt":1719494500247,"mc":[{"id":"1.230178306","rc":[{"atl":[[16,6.67],[5.2,0]],"id":53893973}],"con":true,"img":false}]}
{"op":"mcm","clk":"11540437689","pt":1719494503248,"mc":[{"id":"1.230178306","rc":[{"atl":[[5,2]],"id":53893973}],"con":true,"img":false}]}
{"op":"mcm","clk":"11540437823","pt":1719494504962,"mc":[{"id":"1.230178306","rc":[{"atb":[[2.26,0]],"id":47095746},{"atb":[[3.2,0]],"id":61496663},{"atb":[[2.24,0]],"id":53987475}],"con":true,"img":false}]}
{"op":"mcm","clk":"11540437979","pt":1719494507079,"mc":[{"id":"1.230178306","rc":[{"atb":[[2.44,9.98],[2.26,0]],"id":53893973},{"atb":[[3.8,4.84],[3.4,0]],"id":47095746},{"atb":[[3.1,0],[3.45,6]],"id":61496663},{"atb":[[3.1,0],[3.45,6.04]],"id":53987475}],"con":true,"img":false}]}
{"op":"mcm","clk":"11540438095","pt":1719494508496,"mc":[{"id":"1.230178306","rc":[{"atl":[[5,0]],"id":53893973}],"con":true,"img":false}]}
{"op":"mcm","clk":"11540438104","pt":1719494508551,"mc":[{"id":"1.230178306","rc":[{"atb":[[4.1,0.07]],"id":47801105},{"atl":[[25,0]],"id":47801105},{"atb":[[5.9,0.05]],"id":47095746},{"atb":[[5.7,0.05]],"id":61496663},{"atl":[[26,0]],"id":61496663}],"con":true,"img":false}]}
{"op":"mcm","clk":"11540438247","pt":1719494510470,"mc":[{"id":"1.230178306","rc":[{"atl":[[5,2]],"id":53893973}],"con":true,"img":false}]}
{"op":"mcm","clk":"11540438258","pt":1719494510568,"mc":[{"id":"1.230178306","rc":[{"atb":[[4.7,0]],"id":47801105},{"atl":[[16,0],[5.2,6.67]],"id":53893973}],"con":true,"img":false}]}
{"op":"mcm","clk":"11540438445","pt":1719494512596,"mc":[{"id":"1.230178306","rc":[{"atb":[[1.08,1]],"id":47801105},{"spn":4.6,"spf":1.0,"id":47801105},{"spn":3.1,"spf":1.0,"id":53893973},{"spn":8.2,"spf":"NaN","id":47095746},{"spn":7.55,"spf":"NaN","id":61496663},{"spn":6.75,"spf":"NaN","id":66596720},{"spn":7.3,"spf":"NaN","id":53987475}],"con":true,"img":false}]}
{"op":"mcm","clk":"11540438463","pt":1719494512756,"mc":[{"id":"1.230178306","rc":[{"atb":[[1.08,0.27]],"id":47801105}],"con":true,"img":false}]}
{"op":"mcm","clk":"11540438481","pt":1719494512959,"mc":[{"id":"1.230178306","rc":[{"atb":[[1.08,0]],"id":47801105}],"con":true,"img":false}]}
{"op":"mcm","clk":"11540438491","pt":1719494513067,"mc":[{"id":"1.230178306","rc":[{"atb":[[4.7,0.27]],"id":47801105}],"con":true,"img":false}]}
{"op":"mcm","clk":"11540438564","pt":1719494513996,"mc":[{"id":"1.230178306","rc":[{"atl":[[4.9,5.18]],"id":53893973}],"con":true,"img":false}]}
{"op":"mcm","clk":"11540438685","pt":1719494515701,"mc":[{"id":"1.230178306","rc":[{"atl":[[5,0]],"id":53893973}],"con":true,"img":false}]}
{"op":"mcm","clk":"11540438833","pt":1719494517870,"mc":[{"id":"1.230178306","rc":[{"atl":[[4.8,2]],"id":53893973}],"con":true,"img":false}]}
{"op":"mcm","clk":"11540438877","pt":1719494518391,"mc":[{"id":"1.230178306","rc":[{"atl":[[4.9,0]],"id":53893973}],"con":true,"img":false}]}
{"op":"mcm","clk":"11540439244","pt":1719494523107,"mc":[{"id":"1.230178306","rc":[{"atl":[[4.8,0]],"id":53893973}],"con":true,"img":false}]}
{"op":"mcm","clk":"11540439252","pt":1719494523161,"mc":[{"id":"1.230178306","rc":[{"atl":[[16,6.67],[5.2,0]],"id":53893973}],"con":true,"img":false}]}
{"op":"mcm","clk":"11540439434","pt":1719494525183,"mc":[{"id":"1.230178306","rc":[{"atl":[[5,2]],"id":53893973}],"con":true,"img":false}]}
{"op":"mcm","clk":"11540439724","pt":1719494528311,"mc":[{"id":"1.230178306","rc":[{"atb":[[4.7,0]],"id":47801105}],"con":true,"img":false}]}
{"op":"mcm","clk":"11540439846","pt":1719494529711,"mc":[{"id":"1.230178306","rc":[{"atb":[[1.08,1]],"id":47801105}],"con":true,"img":false}]}
{"op":"mcm","clk":"11540439863","pt":1719494529916,"mc":[{"id":"1.230178306","rc":[{"atb":[[1.08,0.27]],"id":47801105}],"con":true,"img":false}]}
{"op":"mcm","clk":"11540439883","pt":1719494530080,"mc":[{"id":"1.230178306","rc":[{"atb":[[1.08,0]],"id":47801105}],"con":true,"img":false}]}
{"op":"mcm","clk":"11540439894","pt":1719494530181,"mc":[{"id":"1.230178306","rc":[{"atb":[[4.7,0.27]],"id":47801105}],"con":true,"img":false}]}
{"op":"mcm","clk":"11540439916","pt":1719494530488,"mc":[{"id":"1.230178306","rc":[{"atl":[[5,0]],"id":53893973}],"con":true,"img":false}]}
{"op":"mcm","clk":"11540440060","pt":1719494532417,"mc":[{"id":"1.230178306","rc":[{"atl":[[5,2]],"id":53893973}],"con":true,"img":false}]}
{"op":"mcm","clk":"11540440086","pt":1719494532726,"mc":[{"id":"1.230178306","rc":[{"atl":[[16,0],[5.2,6.67]],"id":53893973}],"con":true,"img":false}]}
{"op":"mcm","clk":"11540440235","pt":1719494534703,"mc":[{"id":"1.230178306","rc":[{"atl":[[4.9,5.18]],"id":53893973}],"con":true,"img":false}]}
{"op":"mcm","clk":"11540440463","pt":1719494537723,"mc":[{"id":"1.230178306","rc":[{"atl":[[5,0]],"id":53893973}],"con":true,"img":false}]}
{"op":"mcm","clk":"11540440546","pt":1719494538506,"mc":[{"id":"1.230178306","rc":[{"atb":[[2.42,0]],"id":53893973},{"atb":[[3.45,0]],"id":47095746},{"atb":[[3.25,0]],"id":61496663},{"atb":[[3.15,0]],"id":53987475}],"con":true,"img":false}]}
{"op":"mcm","clk":"11540440657","pt":1719494539695,"mc":[{"id":"1.230178306","rc":[{"atl":[[4.8,2]],"id":53893973}],"con":true,"img":false}]}
{"op":"mcm","clk":"11540440700","pt":1719494540218,"mc":[{"id":"1.230178306","rc":[{"atl":[[4.9,0]],"id":53893973}],"con":true,"img":false}]}
{"op":"mcm","clk":"11540440754","pt":1719494540891,"mc":[{"id":"1.230178306","rc":[{"atb":[[3.5,4.74]],"id":61496663}],"con":true,"img":false}]}
{"op":"mcm","clk":"11540440767","pt":1719494541090,"mc":[{"id":"1.230178306","rc":[{"atb":[[2.46,10.21]],"id":53893973}],"con":true,"img":false}]}
{"op":"mcm","clk":"11540440864","pt":1719494542126,"mc":[{"id":"1.230178306","rc":[{"atb":[[2.76,0]],"id":47801105},{"atb":[[2.4,0]],"id":53893973},{"atb":[[2.24,2.1]],"id":66596720}],"con":true,"img":false}]}
{"op":"mcm","clk":"11540441115","pt":1719494544935,"mc":[{"id":"1.230178306","rc":[{"atl":[[4.8,0]],"id":53893973}],"con":true,"img":false}]}
{"op":"mcm","clk":"11540441124","pt":1719494545038,"mc":[{"id":"1.230178306","rc":[{"atl":[[16,6.67],[5.2,0]],"id":53893973}],"con":true,"img":false}]}
{"op":"mcm","clk":"11540441158","pt":1719494545508,"mc":[{"id":"1.230178306","rc":[{"atb":[[4.7,0]],"id":47801105}],"con":true,"img":false}]}
{"op":"mcm","clk":"11540441286","pt":1719494546905,"mc":[{"id":"1.230178306","rc":[{"atl":[[5,2]],"id":53893973}],"con":true,"img":false}]}
{"op":"mcm","clk":"11540441294","pt":1719494547010,"mc":[{"id":"1.230178306","rc":[{"atl":[[16,0],[5.2,6.67]],"id":53893973}],"con":true,"img":false}]}
{"op":"mcm","clk":"11540441334","pt":1719494547530,"mc":[{"id":"1.230178306","rc":[{"atb":[[1.08,1]],"id":47801105}],"con":true,"img":false}]}
{"op":"mcm","clk":"11540441346","pt":1719494547633,"mc":[{"id":"1.230178306","rc":[{"atb":[[1.08,0.27]],"id":47801105}],"con":true,"img":false}]}
{"op":"mcm","clk":"11540441362","pt":1719494547836,"mc":[{"id":"1.230178306","rc":[{"atb":[[1.08,0]],"id":47801105}],"con":true,"img":false}]}
{"op":"mcm","clk":"11540441375","pt":1719494547942,"mc":[{"id":"1.230178306","rc":[{"atb":[[4.7,0.27]],"id":47801105}],"con":true,"img":false}]}
{"op":"mcm","clk":"11540441423","pt":1719494548410,"mc":[{"id":"1.230178306","rc":[{"atl":[[4.9,5.18]],"id":53893973}],"con":true,"img":false}]}
{"op":"mcm","clk":"11540441731","pt":1719494552145,"mc":[{"id":"1.230178306","rc":[{"atl":[[5,0]],"id":53893973}],"con":true,"img":false}]}
{"op":"mcm","clk":"11540441927","pt":1719494554531,"mc":[{"id":"1.230178306","rc":[{"atl":[[4.8,2]],"id":53893973}],"con":true,"img":false}]}
{"op":"mcm","clk":"11540441955","pt":1719494554833,"mc":[{"id":"1.230178306","rc":[{"atl":[[4.9,0]],"id":53893973}],"con":true,"img":false}]}
{"op":"mcm","clk":"11540442135","pt":1719494556949,"mc":[{"id":"1.230178306","rc":[{"atb":[[2.8,7.75]],"id":47801105}],"con":true,"img":false}]}
{"op":"mcm","clk":"11540442174","pt":1719494557420,"mc":[{"id":"1.230178306","rc":[{"atb":[[2.42,9.84]],"id":66596720}],"con":true,"img":false}]}
{"op":"mcm","clk":"11540442197","pt":1719494557734,"mc":[{"id":"1.230178306","rc":[{"atb":[[3.5,10.33]],"id":61496663}],"con":true,"img":false}]}
{"op":"mcm","clk":"11540442356","pt":1719494559744,"mc":[{"id":"1.230178306","rc":[{"atl":[[4.8,0]],"id":53893973}],"con":true,"img":false}]}
{"op":"mcm","clk":"11540442366","pt":1719494559845,"mc":[{"id":"1.230178306","rc":[{"atl":[[16,6.67],[5.2,0]],"id":53893973}],"con":true,"img":false}]}
{"op":"mcm","clk":"11540442517","pt":1719494561361,"mc":[{"id":"1.230178306","rc":[{"atb":[[2.78,0]],"id":47801105}],"con":true,"img":false}]}
{"op":"mcm","clk":"11540442636","pt":1719494562548,"mc":[{"id":"1.230178306","rc":[{"atb":[[2.82,6.51]],"id":47801105}],"con":true,"img":false}]}
{"op":"mcm","clk":"11540442649","pt":1719494562654,"mc":[{"id":"1.230178306","rc":[{"atb":[[2.44,8.23]],"id":66596720}],"con":true,"img":false}]}
{"op":"mcm","clk":"11540442668","pt":1719494562862,"mc":[{"id":"1.230178306","rc":[{"atl":[[5,2]],"id":53893973}],"con":true,"img":false}]}
{"op":"mcm","clk":"11540442694","pt":1719494563129,"mc":[{"id":"1.230178306","rc":[{"atb":[[4.7,0]],"id":47801105}],"con":true,"img":false}]}
{"op":"mcm","clk":"11540442798","pt":1719494564367,"mc":[{"id":"1.230178306","rc":[{"atb":[[1.08,1]],"id":47801105}],"con":true,"img":false}]}
{"op":"mcm","clk":"11540442814","pt":1719494564523,"mc":[{"id":"1.230178306","rc":[{"atb":[[1.08,0.27]],"id":47801105}],"con":true,"img":false}]}
{"op":"mcm","clk":"11540442831","pt":1719494564727,"mc":[{"id":"1.230178306","rc":[{"atb":[[1.08,0]],"id":47801105}],"con":true,"img":false}]}
{"op":"mcm","clk":"11540442839","pt":1719494564835,"mc":[{"id":"1.230178306","rc":[{"atb":[[4.7,0.27]],"id":47801105}],"con":true,"img":false}]}
{"op":"mcm","clk":"11540442907","pt":1719494565551,"mc":[{"id":"1.230178306","rc":[{"atb":[[3.15,0.94]],"id":53893973},{"atl":[[4.9,0.84]],"id":53893973},{"atb":[[5.9,0.89]],"id":47095746},{"atb":[[5.7,0.89]],"id":61496663},{"atb":[[5.4,0.9]],"id":53987475}],"con":true,"img":false}]}
{"op":"mcm","clk":"11540443103","pt":1719494568037,"mc":[{"id":"1.230178306","rc":[{"atl":[[5,0]],"id":53893973}],"con":true,"img":false}]}
{"op":"mcm","clk":"11540443160","pt":1719494568666,"mc":[{"id":"1.230178306","rc":[{"atl":[[4.9,0]],"id":53893973}],"con":true,"img":false}]}
{"op":"mcm","clk":"11540443291","pt":1719494570161,"mc":[{"id":"1.230178306","rc":[{"atl":[[5,2]],"id":53893973}],"con":true,"img":false}]}
{"op":"mcm","clk":"11540443303","pt":1719494570264,"mc":[{"id":"1.230178306","rc":[{"atl":[[16,0],[5.2,6.67]],"id":53893973}],"con":true,"img":false}]}
{"op":"mcm","clk":"11540443415","pt":1719494571565,"mc":[{"id":"1.230178306","rc":[{"atl":[[4.9,5.18]],"id":53893973}],"con":true,"img":false}]}
{"op":"mcm","clk":"11540443508","pt":1719494572554,"mc":[{"id":"1.230178306","rc":[{"atl":[[4.8,0.84]],"id":53893973}],"con":true,"img":false}]}
{"op":"mcm","clk":"11540443523","pt":1719494572761,"mc":[{"id":"1.230178306","rc":[{"spn":4.62,"spf":1.0,"id":47801105},{"atl":[[4.9,0]],"id":53893973},{"spn":3.14,"spf":1.0,"id":53893973}],"con":true,"img":false}]}
{"op":"mcm","clk":"11540443579","pt":1719494573240,"mc":[{"id":"1.230178306","rc":[{"atl":[[4.8,0]],"id":53893973}],"con":true,"img":false}]}
{"op":"mcm","clk":"11540443784","pt":1719494575334,"mc":[{"id":"1.230178306","rc":[{"atl":[[5,0]],"id":53893973}],"con":true,"img":false}]}
{"op":"mcm","clk":"11540443797","pt":1719494575437,"mc":[{"id":"1.230178306","rc":[{"atl":[[16,6.67],[5.2,0]],"id":53893973}],"con":true,"img":false}]}
{"op":"mcm","clk":"11540444082","pt":1719494578349,"mc":[{"id":"1.230178306","rc":[{"atl":[[5,2]],"id":53893973}],"con":true,"img":false}]}
{"op":"mcm","clk":"11540444133","pt":1719494578974,"mc":[{"id":"1.230178306","rc":[{"atb":[[2.24,9.55]],"id":47095746}],"con":true,"img":false}]}
{"op":"mcm","clk":"11540444148","pt":1719494579179,"mc":[{"id":"1.230178306","rc":[{"atb":[[2.22,9.71]],"id":53987475}],"con":true,"img":false}]}
{"op":"mcm","clk":"11540444221","pt":1719494580079,"mc":[{"id":"1.230178306","rc":[{"atb":[[4.7,0]],"id":47801105},{"atl":[[4.9,0.84]],"id":53893973}],"con":true,"img":false}]}
{"op":"mcm","clk":"11540444346","pt":1719494581533,"mc":[{"id":"1.230178306","rc":[{"atb":[[1.08,1]],"id":47801105}],"con":true,"img":false}]}
{"op":"mcm","clk":"11540444362","pt":1719494581747,"mc":[{"id":"1.230178306","rc":[{"atb":[[1.08,0.27]],"id":47801105}],"con":true,"img":false}]}
{"op":"mcm","clk":"11540444371","pt":1719494581951,"mc":[{"id":"1.230178306","rc":[{"atb":[[1.08,0]],"id":47801105}],"con":true,"img":false}]}
{"op":"mcm","clk":"11540444377","pt":1719494582053,"mc":[{"id":"1.230178306","rc":[{"atb":[[4.7,0.27]],"id":47801105}],"con":true,"img":false}]}
{"op":"mcm","clk":"11540444397","pt":1719494582366,"mc":[{"id":"1.230178306","rc":[{"atb":[[5.7,0.84]],"id":61496663}],"con":true,"img":false}]}
{"op":"mcm","clk":"11540444426","pt":1719494582678,"mc":[{"id":"1.230178306","rc":[{"atb":[[4.1,0]],"id":47801105}],"con":true,"img":false}]}
{"op":"mcm","clk":"11540444451","pt":1719494582939,"mc":[{"id":"1.230178306","rc":[{"atb":[[5.9,0.84]],"id":47095746}],"con":true,"img":false}]}
{"op":"mcm","clk":"11540444476","pt":1719494583254,"mc":[{"id":"1.230178306","rc":[{"atb":[[3.15,0.84]],"id":53893973}],"con":true,"img":false}]}
{"op":"mcm","clk":"11540444506","pt":1719494583568,"mc":[{"id":"1.230178306","rc":[{"atl":[[5,0]],"id":53893973}],"con":true,"img":false}]}
{"op":"mcm","clk":"11540444516","pt":1719494583673,"mc":[{"id":"1.230178306","rc":[{"atb":[[5.4,0.84]],"id":53987475}],"con":true,"img":false}]}
{"op":"mcm","clk":"11540444531","pt":1719494583780,"mc":[{"id":"1.230178306","rc":[{"atb":[[1.03,16.81]],"id":47801105},{"atl":[[1000,1.87]],"id":47801105},{"atb":[[1.04,1.7]],"id":47095746},{"atl":[[1000,1.87]],"id":47095746},{"atb":[[1.04,1.7]],"id":61496663},{"atl":[[1000,1.7]],"id":61496663}],"con":true,"img":false}]}
{"op":"mcm","clk":"11540444540","pt":1719494583833,"mc":[{"id":"1.230178306","rc":[{"atb":[[3.6,6]],"id":66596720}],"con":true,"img":false}]}
{"op":"mcm","clk":"11540444546","pt":1719494583934,"mc":[{"id":"1.230178306","rc":[{"atb":[[1.03,15.2],[1.1,1.69]],"id":47801105},{"atb":[[1.04,0.06]],"id":47095746},{"atl":[[1000,0.16]],"id":47095746},{"atb":[[1.04,0.06]],"id":61496663},{"atl":[[1000,0.01]],"id":61496663}],"con":true,"img":false}]}
{"op":"mcm","clk":"11540444554","pt":1719494584038,"mc":[{"id":"1.230178306","rc":[{"atl":[[1000,0.18]],"id":47801105},{"atl":[[4.9,0]],"id":53893973}],"con":true,"img":false}]}
{"op":"mcm","clk":"11540444562","pt":1719494584146,"mc":[{"id":"1.230178306","rc":[{"atb":[[1.03,15.1]],"id":47801105},{"atb":[[1.08,1.69]],"id":53893973},{"atb":[[1.04,0]],"id":47095746},{"atb":[[1.04,0]],"id":61496663},{"atl":[[1000,0]],"id":61496663}],"con":true,"img":false}]}
{"op":"mcm","clk":"11540444570","pt":1719494584244,"mc":[{"id":"1.230178306","rc":[{"atb":[[4.1,0.09]],"id":47801105},{"atl":[[1000,0.16]],"id":47801105},{"atb":[[5.9,0.9]],"id":47095746},{"atb":[[5.7,0.91]],"id":61496663},{"atl":[[26,0.01]],"id":61496663},{"atb":[[1.12,1.69]],"id":53987475}],"con":true,"img":false}]}
{"op":"mcm","clk":"11540444577","pt":1719494584349,"mc":[{"id":"1.230178306","rc":[{"atl":[[25,0.01]],"id":47801105}],"con":true,"img":false}]}
{"op":"mcm","clk":"11540444586","pt":1719494584452,"mc":[{"id":"1.230178306","rc":[{"atb":[[1.1,0.06]],"id":47801105}],"con":true,"img":false}]}
{"op":"mcm","clk":"11540444596","pt":1719494584559,"mc":[{"id":"1.230178306","rc":[{"atb":[[1.14,1.69]],"id":47095746}],"con":true,"img":false}]}
{"op":"mcm","clk":"11540444619","pt":1719494584759,"mc":[{"id":"1.230178306","rc":[{"atb":[[1.08,0.09]],"id":53893973}],"con":true,"img":false}]}
{"op":"mcm","clk":"11540444628","pt":1719494584863,"mc":[{"id":"1.230178306","rc":[{"atb":[[1.12,0.05]],"id":53987475}],"con":true,"img":false}]}
{"op":"mcm","clk":"11540444664","pt":1719494585278,"mc":[{"id":"1.230178306","rc":[{"atb":[[1.1,0]],"id":47801105}],"con":true,"img":false}]}
{"op":"mcm","clk":"11540444673","pt":1719494585329,"mc":[{"id":"1.230178306","rc":[{"atb":[[4.7,0.33]],"id":47801105}],"con":true,"img":false}]}
{"op":"mcm","clk":"11540444695","pt":1719494585537,"mc":[{"id":"1.230178306","rc":[{"atl":[[5,2]],"id":53893973}],"con":true,"img":false}]}
{"op":"mcm","clk":"11540444705","pt":1719494585642,"mc":[{"id":"1.230178306","rc":[{"atb":[[1.08,0]],"id":53893973},{"atl":[[16,0],[5.2,6.67]],"id":53893973},{"atb":[[1.14,0.05]],"id":47095746}],"con":true,"img":false}]}
{"op":"mcm","clk":"11540444711","pt":1719494585744,"mc":[{"id":"1.230178306","rc":[{"atb":[[3.15,0.94]],"id":53893973}],"con":true,"img":false}]}
{"op":"mcm","clk":"11540444737","pt":1719494586055,"mc":[{"id":"1.230178306","rc":[{"atb":[[1.12,0]],"id":53987475}],"con":true,"img":false}]}
{"op":"mcm","clk":"11540444746","pt":1719494586157,"mc":[{"id":"1.230178306","rc":[{"atb":[[5.4,0.9]],"id":53987475}],"con":true,"img":false}]}
{"op":"mcm","clk":"11540444778","pt":1719494586674,"mc":[{"id":"1.230178306","rc":[{"atb":[[1.14,0]],"id":47095746}],"con":true,"img":false}]}
{"op":"mcm","clk":"11540444796","pt":1719494586777,"mc":[{"id":"1.230178306","rc":[{"atb":[[6,0.05]],"id":47095746}],"con":true,"img":false}]}
{"op":"mcm","clk":"11540444850","pt":1719494587452,"mc":[{"id":"1.230178306","rc":[{"atl":[[4.9,0.84]],"id":53893973}],"con":true,"img":false}]}
{"op":"mcm","clk":"11540445120","pt":1719494590776,"mc":[{"id":"1.230178306","rc":[{"atl":[[5,0]],"id":53893973}],"con":true,"img":false}]}
{"op":"mcm","clk":"11540445147","pt":1719494591038,"mc":[{"id":"1.230178306","rc":[{"atl":[[4.9,0]],"id":53893973}],"con":true,"img":false}]}
{"op":"mcm","clk":"11540445162","pt":1719494591245,"mc":[{"id":"1.230178306","rc":[{"atl":[[16,6.67],[5.2,0]],"id":53893973}],"con":true,"img":false}]}
{"op":"mcm","clk":"11540445337","pt":1719494593272,"mc":[{"id":"1.230178306","rc":[{"atl":[[13.5,0.84]],"id":47801105}],"con":true,"img":false}]}
{"op":"mcm","clk":"11540445341","pt":1719494593376,"mc":[{"id":"1.230178306","rc":[{"atl":[[26,0]],"id":53893973}],"con":true,"img":false}]}
{"op":"mcm","clk":"11540445389","pt":1719494593844,"mc":[{"id":"1.230178306","rc":[{"atl":[[5,2]],"id":53893973}],"con":true,"img":false}]}
{"op":"mcm","clk":"11540445436","pt":1719494594466,"mc":[{"id":"1.230178306","rc":[{"atl":[[4.9,0.84]],"id":53893973}],"con":true,"img":false}]}
{"op":"mcm","clk":"11540445447","pt":1719494594568,"mc":[{"id":"1.230178306","rc":[{"atl":[[16,0],[5.2,8]],"id":53893973}],"con":true,"img":false}]}
{"op":"mcm","clk":"11540445672","pt":1719494597266,"mc":[{"id":"1.230178306","rc":[{"atb":[[4.7,0.06]],"id":47801105}],"con":true,"img":false}]}
{"op":"mcm","clk":"11540445864","pt":1719494598873,"mc":[{"id":"1.230178306","rc":[{"atb":[[1.08,1]],"id":47801105}],"con":true,"img":false}]}
{"op":"mcm","clk":"11540445894","pt":1719494599185,"mc":[{"id":"1.230178306","rc":[{"atb":[[1.08,0.27]],"id":47801105},{"atl":[[5,0]],"id":53893973}],"con":true,"img":false}]}
{"op":"mcm","clk":"11540445912","pt":1719494599394,"mc":[{"id":"1.230178306","rc":[{"atb":[[1.08,0]],"id":47801105}],"con":true,"img":false}]}
{"op":"mcm","clk":"11540445922","pt":1719494599494,"mc":[{"id":"1.230178306","rc":[{"atb":[[4.7,0.33]],"id":47801105}],"con":true,"img":false}]}
{"op":"mcm","clk":"11540445939","pt":1719494599655,"mc":[{"id":"1.230178306","rc":[{"atl":[[4.9,0]],"id":53893973}],"con":true,"img":false}]}
{"op":"mcm","clk":"11540445948","pt":1719494599762,"mc":[{"id":"1.230178306","rc":[{"atl":[[16,6.67],[5.2,0]],"id":53893973}],"con":true,"img":false}]}
{"op":"mcm","clk":"11540446064","pt":1719494601056,"mc":[{"id":"1.230178306","rc":[{"atl":[[5,2]],"id":53893973}],"con":true,"img":false}]}
{"op":"mcm","clk":"11540446081","pt":1719494601263,"mc":[{"id":"1.230178306","rc":[{"atl":[[16,0],[5.2,8]],"id":53893973}],"con":true,"img":false}]}
{"op":"mcm","clk":"11540446091","pt":1719494601367,"mc":[{"id":"1.230178306","rc":[{"atb":[[2.48,9.44]],"id":53893973}],"con":true,"img":false}]}
{"op":"mcm","clk":"11540446105","pt":1719494601576,"mc":[{"id":"1.230178306","rc":[{"atl":[[4.9,0.84]],"id":53893973}],"con":true,"img":false}]}
{"op":"mcm","clk":"11540446543","pt":1719494606302,"mc":[{"id":"1.230178306","rc":[{"atl":[[5,0]],"id":53893973}],"con":true,"img":false}]}
{"op":"mcm","clk":"11540446635","pt":1719494607085,"mc":[{"id":"1.230178306","rc":[{"atl":[[4.9,0]],"id":53893973}],"con":true,"img":false}]}
{"op":"mcm","clk":"11540446644","pt":1719494607185,"mc":[{"id":"1.230178306","rc":[{"atl":[[16,6.67],[5.2,0]],"id":53893973}],"con":true,"img":false}]}
{"op":"mcm","clk":"11540446821","pt":1719494609363,"mc":[{"id":"1.230178306","rc":[{"atl":[[5,2]],"id":53893973}],"con":true,"img":false}]}
{"op":"mcm","clk":"11540446871","pt":1719494609985,"mc":[{"id":"1.230178306","rc":[{"atl":[[4.9,0.84]],"id":53893973}],"con":true,"img":false}]}
{"op":"mcm","clk":"11540447249","pt":1719494614704,"mc":[{"id":"1.230178306","rc":[{"atb":[[4.7,0.06]],"id":47801105},{"atl":[[5,0]],"id":53893973}],"con":true,"img":false}]}
{"op":"mcm","clk":"11540447286","pt":1719494615115,"mc":[{"id":"1.230178306","rc":[{"atl":[[4.9,0]],"id":53893973}],"con":true,"img":false}]}
{"op":"mcm","clk":"11540447412","pt":1719494616511,"mc":[{"id":"1.230178306","rc":[{"atb":[[1.08,1]],"id":47801105}],"con":true,"img":false}]}
{"op":"mcm","clk":"11540447426","pt":1719494616564,"mc":[{"id":"1.230178306","rc":[{"atl":[[5,2]],"id":53893973}],"con":true,"img":false}]}
{"op":"mcm","clk":"11540447435","pt":1719494616667,"mc":[{"id":"1.230178306","rc":[{"atb":[[1.08,0.27]],"id":47801105},{"atl":[[16,0],[5.2,8]],"id":53893973}],"con":true,"img":false}]}
{"op":"mcm","clk":"11540447450","pt":1719494616874,"mc":[{"id":"1.230178306","rc":[{"atb":[[1.08,0]],"id":47801105}],"con":true,"img":false}]}
{"op":"mcm","clk":"11540447458","pt":1719494616976,"mc":[{"id":"1.230178306","rc":[{"atb":[[4.7,0.33]],"id":47801105}],"con":true,"img":false}]}
{"op":"mcm","clk":"11540447469","pt":1719494617078,"mc":[{"id":"1.230178306","rc":[{"atl":[[4.9,0.84]],"id":53893973}],"con":true,"img":false}]}
{"op":"mcm","clk":"11540447909","pt":1719494621898,"mc":[{"id":"1.230178306","rc":[{"atl":[[5,0]],"id":53893973}],"con":true,"img":false}]}
{"op":"mcm","clk":"11540447969","pt":1719494622573,"mc":[{"id":"1.230178306","rc":[{"atl":[[4.9,0]],"id":53893973}],"con":true,"img":false}]}
{"op":"mcm","clk":"11540447977","pt":1719494622678,"mc":[{"id":"1.230178306","rc":[{"atl":[[16,6.67],[5.2,0]],"id":53893973}],"con":true,"img":false}]}
{"op":"mcm","clk":"11540448088","pt":1719494623976,"mc":[{"id":"1.230178306","rc":[{"atb":[[4.7,1.12]],"id":47801105},{"atb":[[3.15,1.78]],"id":53893973},{"atb":[[3.7,3.9]],"id":61496663},{"atb":[[3.6,9.2]],"id":66596720},{"atb":[[3.55,8.9]],"id":53987475}],"con":true,"img":false}]}
{"op":"mcm","clk":"11540448100","pt":1719494624080,"mc":[{"id":"1.230178306","rc":[{"atb":[[4,23.33],[4.5,2.13]],"id":47801105}],"con":true,"img":false}]}
{"op":"mcm","clk":"11540448185","pt":1719494624917,"mc":[{"id":"1.230178306","rc":[{"atl":[[5,2]],"id":53893973}],"con":true,"img":false}]}
{"op":"mcm","clk":"11540448212","pt":1719494625275,"mc":[{"id":"1.230178306","rc":[{"atl":[[16,0],[5.2,8]],"id":53893973}],"con":true,"img":false}]}
{"op":"mcm","clk":"11540448221","pt":1719494625381,"mc":[{"id":"1.230178306","rc":[{"atb":[[3.1,0]],"id":53893973}],"con":true,"img":false}]}
{"op":"mcm","clk":"11540448231","pt":1719494625486,"mc":[{"id":"1.230178306","rc":[{"atb":[[3.2,2]],"id":53893973},{"atl":[[4.9,0.84]],"id":53893973}],"con":true,"img":false}]}
{"op":"mcm","clk":"11540448286","pt":1719494626012,"mc":[{"id":"1.230178306","rc":[{"atb":[[3.25,0.84]],"id":53893973}],"con":true,"img":false}]}
{"op":"mcm","clk":"11540448415","pt":1719494627472,"mc":[{"id":"1.230178306","rc":[{"atb":[[4.1,0]],"id":47801105},{"atl":[[25,0]],"id":47801105},{"atb":[[5.9,0.84]],"id":47095746},{"atb":[[5.7,0.84]],"id":61496663},{"atl":[[26,0]],"id":61496663}],"con":true,"img":false}]}
{"op":"mcm","clk":"11540448643","pt":1719494629499,"mc":[{"id":"1.230178306","rc":[{"atb":[[5.7,10.6]],"id":66596720}],"con":true,"img":false}]}
{"op":"mcm","clk":"11540448656","pt":1719494629604,"mc":[{"id":"1.230178306","rc":[{"atb":[[3.6,3.2],[5.1,11.6]],"id":66596720}],"con":true,"img":false}]}
{"op":"mcm","clk":"11540448692","pt":1719494630023,"mc":[{"id":"1.230178306","rc":[{"atb":[[5.8,0.84]],"id":66596720}],"con":true,"img":false}]}
{"op":"mcm","clk":"11540448702","pt":1719494630124,"mc":[{"id":"1.230178306","rc":[{"atl":[[5,0]],"id":53893973},{"atb":[[5.8,5.22]],"id":66596720}],"con":true,"img":false}]}
{"op":"mcm","clk":"11540448737","pt":1719494630490,"mc":[{"id":"1.230178306","rc":[{"atl":[[4.9,0]],"id":53893973}],"con":true,"img":false}]}
{"op":"mcm","clk":"11540448748","pt":1719494630694,"mc":[{"id":"1.230178306","rc":[{"atl":[[16,6.67],[5.2,0]],"id":53893973},{"atb":[[2.24,0]],"id":66596720}],"con":true,"img":false}]}
{"op":"mcm","clk":"11540448878","pt":1719494632098,"mc":[{"id":"1.230178306","rc":[{"atl":[[5,2]],"id":53893973}],"con":true,"img":false}]}
{"op":"mcm","clk":"11540448901","pt":1719494632309,"mc":[{"id":"1.230178306","rc":[{"atb":[[4.7,0.85]],"id":47801105}],"con":true,"img":false}]}
{"op":"mcm","clk":"11540448933","pt":1719494632620,"mc":[{"id":"1.230178306","rc":[{"atl":[[4.9,0.84]],"id":53893973}],"con":true,"img":false}]}
{"op":"mcm","clk":"11540449045","pt":1719494633723,"mc":[{"id":"1.230178306","rc":[{"spn":4.68,"spf":1.0,"id":47801105},{"spn":3.24,"spf":1.0,"id":53893973},{"spn":8.25,"spf":"NaN","id":47095746},{"atl":[[8.8,1.46]],"id":66596720},{"spn":6.9,"spf":"NaN","id":66596720}],"con":true,"img":false}]}
{"op":"mcm","clk":"11540449054","pt":1719494633818,"mc":[{"id":"1.230178306","rc":[{"atb":[[4.1,15.83]],"id":66596720}],"con":true,"img":false}]}
{"op":"mcm","clk":"11540449064","pt":1719494633923,"mc":[{"id":"1.230178306","rc":[{"atb":[[5.1,0]],"id":66596720}],"con":true,"img":false}]}
{"op":"mcm","clk":"11540449124","pt":1719494634495,"mc":[{"id":"1.230178306","rc":[{"atb":[[2.46,2.1]],"id":53893973}],"con":true,"img":false}]}
{"op":"mcm","clk":"11540449140","pt":1719494634707,"mc":[{"id":"1.230178306","rc":[{"atb":[[1.08,1]],"id":47801105}],"con":true,"img":false}]}
{"op":"mcm","clk":"11540449150","pt":1719494634808,"mc":[{"id":"1.230178306","rc":[{"atb":[[1.08,0.27]],"id":47801105}],"con":true,"img":false}]}
{"op":"mcm","clk":"11540449166","pt":1719494635021,"mc":[{"id":"1.230178306","rc":[{"atb":[[1.08,0]],"id":47801105}],"con":true,"img":false}]}
{"op":"mcm","clk":"11540449172","pt":1719494635119,"mc":[{"id":"1.230178306","rc":[{"atb":[[4.7,1.12]],"id":47801105}],"con":true,"img":false}]}
{"op":"mcm","clk":"11540449348","pt":1719494637293,"mc":[{"id":"1.230178306","rc":[{"atl":[[5,0]],"id":53893973}],"con":true,"img":false}]}
{"op":"mcm","clk":"11540449414","pt":1719494638123,"mc":[{"id":"1.230178306","rc":[{"atl":[[4.9,0]],"id":53893973}],"con":true,"img":false}]}
{"op":"mcm","clk":"11540449578","pt":1719494640303,"mc":[{"id":"1.230178306","rc":[{"atl":[[5,2]],"id":53893973}],"con":true,"img":false}]}
{"op":"mcm","clk":"11540449587","pt":1719494640408,"mc":[{"id":"1.230178306","rc":[{"atl":[[16,0],[5.2,8]],"id":53893973}],"con":true,"img":false}]}
{"op":"mcm","clk":"11540449610","pt":1719494640720,"mc":[{"id":"1.230178306","rc":[{"atl":[[6,5.06]],"id":66596720}],"con":true,"img":false}]}
{"op":"mcm","clk":"11540449629","pt":1719494640928,"mc":[{"id":"1.230178306","rc":[{"atl":[[8,3.17]],"id":66596720}],"con":true,"img":false}]}
{"op":"mcm","clk":"11540449635","pt":1719494641031,"mc":[{"id":"1.230178306","rc":[{"atl":[[4.9,0.84]],"id":53893973}],"con":true,"img":false}]}
{"op":"mcm","clk":"11540449679","pt":1719494641609,"mc":[{"id":"1.230178306","rc":[{"atl":[[8,0]],"id":66596720}],"con":true,"img":false}]}
{"op":"mcm","clk":"11540449742","pt":1719494642341,"mc":[{"id":"1.230178306","rc":[{"atl":[[8.6,1.5],[8.8,0]],"id":66596720}],"con":true,"img":false}]}
{"op":"mcm","clk":"11540449776","pt":1719494642712,"mc":[{"id":"1.230178306","rc":[{"atb":[[2.8,0]],"id":47801105},{"atb":[[2.42,0]],"id":66596720}],"con":true,"img":false}]}
{"op":"mcm","clk":"11540449870","pt":1719494643805,"mc":[{"id":"1.230178306","rc":[{"atb":[[3.15,0.94]],"id":53893973},{"atb":[[3.6,0]],"id":66596720}],"con":true,"img":false}]}
{"op":"mcm","clk":"11540449933","pt":1719494644637,"mc":[{"id":"1.230178306","rc":[{"atb":[[3.2,0]],"id":53893973}],"con":true,"img":false}]}
{"op":"mcm","clk":"11540449943","pt":1719494644739,"mc":[{"id":"1.230178306","rc":[{"atb":[[3.1,2]],"id":53893973}],"con":true,"img":false}]}
{"op":"mcm","clk":"11540449977","pt":1719494645002,"mc":[{"id":"1.230178306","rc":[{"atb":[[3.25,0]],"id":53893973}],"con":true,"img":false}]}
{"op":"mcm","clk":"11540450028","pt":1719494645634,"mc":[{"id":"1.230178306","rc":[{"atl":[[5,0]],"id":53893973}],"con":true,"img":false}]}
{"op":"mcm","clk":"11540450065","pt":1719494646103,"mc":[{"id":"1.230178306","rc":[{"atb":[[2.5,7.9]],"id":53893973},{"atl":[[4.9,0]],"id":53893973}],"con":true,"img":false}]}
{"op":"mcm","clk":"11540450075","pt":1719494646211,"mc":[{"id":"1.230178306","rc":[{"atl":[[16,6.67]],"id":53893973}],"con":true,"img":false}]}
{"op":"mcm","clk":"11540450082","pt":1719494646311,"mc":[{"id":"1.230178306","rc":[{"atl":[[5.2,0]],"id":53893973}],"con":true,"img":false}]}
{"op":"mcm","clk":"11540450172","pt":1719494647611,"mc":[{"id":"1.230178306","rc":[{"atl":[[5,2]],"id":53893973}],"con":true,"img":false}]}
{"op":"mcm","clk":"11540450209","pt":1719494648130,"mc":[{"id":"1.230178306","rc":[{"atl":[[4.9,0.84]],"id":53893973}],"con":true,"img":false}]}
{"op":"mcm","clk":"11540450369","pt":1719494650323,"mc":[{"id":"1.230178306","rc":[{"atb":[[4.7,0.85]],"id":47801105}],"con":true,"img":false}]}
{"op":"mcm","clk":"11540450528","pt":1719494652456,"mc":[{"id":"1.230178306","rc":[{"atb":[[1.08,1]],"id":47801105}],"con":true,"img":false}]}
{"op":"mcm","clk":"11540450539","pt":1719494652680,"mc":[{"id":"1.230178306","rc":[{"atb":[[1.08,0.27],[4.5,0],[4.1,6.51]],"id":47801105},{"atb":[[2.44,0],[2.28,78.13]],"id":53893973},{"atl":[[5.1,0]],"id":53893973},{"atb":[[2.94,51.55]],"id":61496663},{"atb":[[3.25,12],[5.5,0],[4.1,0]],"id":66596720},{"atl":[[16.5,6.45],[30,0]],"id":66596720},{"atb":[[3.45,0]],"id":53987475}],"con":true,"img":false}]}
{"op":"mcm","clk":"11540450554","pt":1719494652734,"mc":[{"id":"1.230178306","rc":[{"atl":[[5.2,1]],"id":53893973},{"atb":[[3.8,0],[3.25,9.56]],"id":47095746},{"atb":[[3.45,0]],"id":61496663},{"atb":[[3.1,9.06]],"id":53987475}],"con":true,"img":false}]}
{"op":"mcm","clk":"11540450560","pt":1719494652840,"mc":[{"id":"1.230178306","rc":[{"atb":[[1.08,0]],"id":47801105},{"atl":[[5,0]],"id":53893973}],"con":true,"img":false}]}
{"op":"mcm","clk":"11540450570","pt":1719494652946,"mc":[{"id":"1.230178306","rc":[{"atb":[[4.7,1.12]],"id":47801105}],"con":true,"img":false}]}
{"op":"mcm","clk":"11540450631","pt":1719494653521,"mc":[{"id":"1.230178306","rc":[{"atl":[[4.9,0]],"id":53893973}],"con":true,"img":false}]}
{"op":"mcm","clk":"11540450780","pt":1719494655341,"mc":[{"id":"1.230178306","rc":[{"atb":[[4.8,1.76]],"id":47801105}],"con":true,"img":false}]}
{"op":"mcm","clk":"11540450798","pt":1719494655548,"mc":[{"id":"1.230178306","rc":[{"atl":[[1000,1.01]],"id":47801105}],"con":true,"img":false}]}
{"op":"mcm","clk":"11540450828","pt":1719494655854,"mc":[{"id":"1.230178306","rc":[{"atb":[[4.9,5.18]],"id":47801105},{"atl":[[1000,1.86]],"id":47801105}],"con":true,"img":false}]}
{"op":"mcm","clk":"11540450836","pt":1719494655958,"mc":[{"id":"1.230178306","rc":[{"atl":[[5.1,2]],"id":53893973}],"con":true,"img":false}]}
{"op":"mcm","clk":"11540450846","pt":1719494656010,"mc":[{"id":"1.230178306","rc":[{"atb":[[4.9,6.03]],"id":47801105},{"atl":[[5.4,8]],"id":53893973}],"con":true,"img":false}]}
{"op":"mcm","clk":"11540450856","pt":1719494656113,"mc":[{"id":"1.230178306","rc":[{"atb":[[5,1.69]],"id":47801105},{"atl":[[16,0]],"id":53893973}],"con":true,"img":false}]}
{"op":"mcm","clk":"11540450862","pt":1719494656217,"mc":[{"id":"1.230178306","rc":[{"atb":[[4.8,0]],"id":47801105}],"con":true,"img":false}]}
{"op":"mcm","clk":"11540450883","pt":1719494656430,"mc":[{"id":"1.230178306","rc":[{"atl":[[1000,1.66]],"id":47801105}],"con":true,"img":false}]}
{"op":"mcm","clk":"11540450888","pt":1719494656528,"mc":[{"id":"1.230178306","rc":[{"atb":[[4.9,0.84]],"id":47801105},{"atl":[[5,0.84]],"id":53893973}],"con":true,"img":false}]}
{"op":"mcm","clk":"11540450900","pt":1719494656637,"mc":[{"id":"1.230178306","rc":[{"atl":[[1000,1.47]],"id":47801105}],"con":true,"img":false}]}
{"op":"mcm","clk":"11540450933","pt":1719494657151,"mc":[{"id":"1.230178306","rc":[{"atb":[[5.1,4.98]],"id":47801105},{"atl":[[1000,0.82]],"id":47801105}],"con":true,"img":false}]}
{"op":"mcm","clk":"11540450940","pt":1719494657253,"mc":[{"id":"1.230178306","rc":[{"atl":[[13,0.65]],"id":47801105}],"con":true,"img":false}]}
{"op":"mcm","clk":"11540450945","pt":1719494657357,"mc":[{"id":"1.230178306","rc":[{"atl":[[26,0],[14,5]],"id":47801105}],"con":true,"img":false}]}
{"op":"mcm","clk":"11540450958","pt":1719494657515,"mc":[{"id":"1.230178306","rc":[{"atb":[[4.9,0]],"id":47801105}],"con":true,"img":false}]}
{"op":"mcm","clk":"11540450967","pt":1719494657620,"mc":[{"id":"1.230178306","rc":[{"atb":[[5,0]],"id":47801105},{"atl":[[1000,0.16]],"id":47801105}],"con":true,"img":false}]}
{"op":"mcm","clk":"11540450974","pt":1719494657727,"mc":[{"id":"1.230178306","rc":[{"atl":[[13,1.3]],"id":47801105}],"con":true,"img":false}]}
{"op":"mcm","clk":"11540450992","pt":1719494657937,"mc":[{"id":"1.230178306","rc":[{"atl":[[14,1],[14.5,7.41]],"id":47801105}],"con":true,"img":false}]}
{"op":"mcm","clk":"11540450998","pt":1719494658034,"mc":[{"id":"1.230178306","rc":[{"atb":[[4.8,1.69]],"id":47801105}],"con":true,"img":false}]}
{"op":"mcm","clk":"11540451032","pt":1719494658346,"mc":[{"id":"1.230178306","rc":[{"atb":[[5.1,0],[5.2,1.62]],"id":47801105}],"con":true,"img":false}]}
{"op":"mcm","clk":"11540451054","pt":1719494658656,"mc":[{"id":"1.230178306","rc":[{"atb":[[4.8,0]],"id":47801105}],"con":true,"img":false}]}
{"op":"mcm","clk":"11540451220","pt":1719494660842,"mc":[{"id":"1.230178306","rc":[{"atb":[[3.8,15.83],[3.25,0]],"id":66596720}],"con":true,"img":false}]}
{"op":"mcm","clk":"11540451262","pt":1719494661256,"mc":[{"id":"1.230178306","rc":[{"atl":[[5.1,0]],"id":53893973}],"con":true,"img":false}]}
{"op":"mcm","clk":"11540451333","pt":1719494662049,"mc":[{"id":"1.230178306","rc":[{"atb":[[5.7,0]],"id":66596720}],"con":true,"img":false}]}
{"op":"mcm","clk":"11540451345","pt":1719494662148,"mc":[{"id":"1.230178306","rc":[{"atl":[[5,0]],"id":53893973},{"atb":[[5.9,10.6]],"id":66596720}],"con":true,"img":false}]}
{"op":"mcm","clk":"11540451355","pt":1719494662257,"mc":[{"id":"1.230178306","rc":[{"atl":[[17,6.25],[5.4,0]],"id":53893973}],"con":true,"img":false}]}
{"op":"mcm","clk":"11540451382","pt":1719494662568,"mc":[{"id":"1.230178306","rc":[{"atb":[[5.8,0.84]],"id":66596720}],"con":true,"img":false}]}
{"op":"mcm","clk":"11540451446","pt":1719494663249,"mc":[{"id":"1.230178306","rc":[{"atl":[[5.1,2]],"id":53893973}],"con":true,"img":false}]}
{"op":"mcm","clk":"11540451480","pt":1719494663668,"mc":[{"id":"1.230178306","rc":[{"atl":[[5,0.84]],"id":53893973}],"con":true,"img":false}]}
{"op":"mcm","clk":"11540451524","pt":1719494664244,"mc":[{"id":"1.230178306","rc":[{"atl":[[17,0],[5.4,8]],"id":53893973}],"con":true,"img":false}]}
{"op":"mcm","clk":"11540451583","pt":1719494665135,"mc":[{"id":"1.230178306","rc":[{"atb":[[3.5,12.44]],"id":66596720}],"con":true,"img":false}]}
{"op":"mcm","clk":"11540451719","pt":1719494666854,"mc":[{"id":"1.230178306","rc":[{"atb":[[2.82,0]],"id":47801105},{"atb":[[2.44,0]],"id":66596720}],"con":true,"img":false}]}
{"op":"mcm","clk":"11540451819","pt":1719494668047,"mc":[{"id":"1.230178306","rc":[{"atb":[[4.7,0.85]],"id":47801105}],"con":true,"img":false}]}
{"op":"mcm","clk":"11540451836","pt":1719494668250,"mc":[{"id":"1.230178306","rc":[{"atb":[[4.7,0.06]],"id":47801105},{"atb":[[3.5,0]],"id":66596720}],"con":true,"img":false}]}
{"op":"mcm","clk":"11540451855","pt":1719494668464,"mc":[{"id":"1.230178306","rc":[{"atb":[[5.2,0]],"id":47801105}],"con":true,"img":false}]}
{"op":"mcm","clk":"11540451876","pt":1719494668670,"mc":[{"id":"1.230178306","rc":[{"atl":[[5.1,0]],"id":53893973}],"con":true,"img":false}]}
{"op":"mcm","clk":"11540451887","pt":1719494668772,"mc":[{"id":"1.230178306","rc":[{"atb":[[4.7,1.69]],"id":47801105}],"con":true,"img":false}]}
{"op":"mcm","clk":"11540451898","pt":1719494668881,"mc":[{"id":"1.230178306","rc":[{"atb":[[4.1,0],[4.2,6.51]],"id":47801105}],"con":true,"img":false}]}
{"op":"mcm","clk":"11540451916","pt":1719494668985,"mc":[{"id":"1.230178306","rc":[{"atb":[[4.8,0.84]],"id":47801105}],"con":true,"img":false}]}
{"op":"mcm","clk":"11540451926","pt":1719494669078,"mc":[{"id":"1.230178306","rc":[{"atl":[[5,0]],"id":53893973}],"con":true,"img":false}]}
{"op":"mcm","clk":"11540451951","pt":1719494669344,"mc":[{"id":"1.230178306","rc":[{"atl":[[17,6.25],[5.4,0]],"id":53893973}],"con":true,"img":false}]}
{"op":"mcm","clk":"11540451983","pt":1719494669756,"mc":[{"id":"1.230178306","rc":[{"atb":[[1.08,1]],"id":47801105}],"con":true,"img":false}]}
{"op":"mcm","clk":"11540452007","pt":1719494669962,"mc":[{"id":"1.230178306","rc":[{"atb":[[1.08,0.26]],"id":47801105}],"con":true,"img":false}]}
{"op":"mcm","clk":"11540452026","pt":1719494670172,"mc":[{"id":"1.230178306","rc":[{"atb":[[1.08,0]],"id":47801105}],"con":true,"img":false}]}
{"op":"mcm","clk":"11540452038","pt":1719494670278,"mc":[{"id":"1.230178306","rc":[{"atb":[[4.8,1.1]],"id":47801105}],"con":true,"img":false}]}
{"op":"mcm","clk":"11540452109","pt":1719494671168,"mc":[{"id":"1.230178306","rc":[{"atb":[[4.4,2.64]],"id":47801105}],"con":true,"img":false}]}
{"op":"mcm","clk":"11540452153","pt":1719494671580,"mc":[{"id":"1.230178306","rc":[{"atl":[[5.1,2]],"id":53893973}],"con":true,"img":false}]}
{"op":"mcm","clk":"11540452194","pt":1719494671941,"mc":[{"id":"1.230178306","rc":[{"atl":[[5,0.84]],"id":53893973}],"con":true,"img":false}]}
{"op":"mcm","clk":"11540452226","pt":1719494672252,"mc":[{"id":"1.230178306","rc":[{"atb":[[4.4,0]],"id":47801105}],"con":true,"img":false}]}
{"op":"mcm","clk":"11540452626","pt":1719494676773,"mc":[{"id":"1.230178306","rc":[{"atl":[[5.1,0]],"id":53893973}],"con":true,"img":false}]}
{"op":"mcm","clk":"11540452656","pt":1719494677090,"mc":[{"id":"1.230178306","rc":[{"atl":[[5,0]],"id":53893973}],"con":true,"img":false}]}
{"op":"mcm","clk":"11540452783","pt":1719494678642,"mc":[{"id":"1.230178306","rc":[{"atb":[[5.9,9.53]],"id":66596720},{"trd":[[5.9,2.14]],"ltp":5.9,"tv":2.14,"id":66596720}],"con":true,"img":false}]}
{"op":"mcm","clk":"11540452800","pt":1719494678851,"mc":[{"id":"1.230178306","rc":[{"atl":[[5.1,2]],"id":53893973}],"con":true,"img":false}]}
{"op":"mcm","clk":"11540452819","pt":1719494679061,"mc":[{"id":"1.230178306","rc":[{"atl":[[17,0],[5.4,8]],"id":53893973},{"atb":[[5.9,7.51]],"id":66596720},{"trd":[[5.9,6.18]],"ltp":5.9,"tv":6.18,"id":66596720}],"con":true,"img":false}]}
{"op":"mcm","clk":"11540452829","pt":1719494679170,"mc":[{"id":"1.230178306","rc":[{"atb":[[5.9,6.51]],"id":66596720},{"trd":[[5.9,8.18]],"ltp":5.9,"tv":8.18,"id":66596720}],"con":true,"img":false}]}
{"op":"mcm","clk":"11540452853","pt":1719494679539,"mc":[{"id":"1.230178306","rc":[{"atl":[[5,0.84]],"id":53893973}],"con":true,"img":false}]}
{"op":"mcm","clk":"11540452887","pt":1719494680061,"mc":[{"id":"1.230178306","rc":[{"atb":[[3.6,4.55]],"id":66596720}],"con":true,"img":false}]}
{"op":"mcm","clk":"11540452898","pt":1719494680164,"mc":[{"id":"1.230178306","rc":[{"atl":[[8.2,6.11]],"id":66596720}],"con":true,"img":false}]}
{"op":"mcm","clk":"11540453216","pt":1719494684164,"mc":[{"id":"1.230178306","rc":[{"atl":[[5.1,0]],"id":53893973},{"atb":[[8,2]],"id":47095746},{"atb":[[5.4,2.9]],"id":53987475}],"con":true,"img":false}]}
{"op":"mcm","clk":"11540453225","pt":1719494684264,"mc":[{"id":"1.230178306","rc":[{"atb":[[5.8,0]],"id":47095746},{"atb":[[5.3,1.02]],"id":53987475}],"con":true,"img":false}]}
{"op":"mcm","clk":"11540453234","pt":1719494684367,"mc":[{"id":"1.230178306","rc":[{"atl":[[13.5,3.44],[14.5,0]],"id":47801105},{"atl":[[5.1,1]],"id":53893973},{"atb":[[2.44,9.56],[3.25,0]],"id":47095746},{"atl":[[130,2],[10.5,0],[85,0],[12.5,1]],"id":47095746}],"con":true,"img":false}]}
{"op":"mcm","clk":"11540453243","pt":1719494684472,"mc":[{"id":"1.230178306","rc":[{"atl":[[5.2,0]],"id":53893973},{"atl":[[130,0],[85,2]],"id":47095746}],"con":true,"img":false}]}
{"op":"mcm","clk":"11540453251","pt":1719494684575,"mc":[{"id":"1.230178306","rc":[{"atl":[[5,0]],"id":53893973},{"atb":[[8.2,0.84],[5.9,0]],"id":47095746},{"atl":[[130,2],[85,0]],"id":47095746},{"atl":[[9.6,1],[9.4,0]],"id":61496663}],"con":true,"img":false}]}
{"op":"mcm","clk":"11540453260","pt":1719494684678,"mc":[{"id":"1.230178306","rc":[{"atl":[[16.5,6.45],[5.4,0]],"id":53893973},{"atl":[[8,6],[8.6,0]],"id":66596720}],"con":true,"img":false}]}
{"op":"mcm","clk":"11540453354","pt":1719494685563,"mc":[{"id":"1.230178306","rc":[{"atb":[[4.8,0.84]],"id":47801105}],"con":true,"img":false}]}
{"op":"mcm","clk":"11540453398","pt":1719494686180,"mc":[{"id":"1.230178306","rc":[{"atl":[[5,2]],"id":53893973}],"con":true,"img":false}]}
{"op":"mcm","clk":"11540453441","pt":1719494686622,"mc":[{"id":"1.230178306","rc":[{"atl":[[17.5,1]],"id":47801105},{"atl":[[12.5,0],[13,1]],"id":47095746}],"con":true,"img":false}]}
{"op":"mcm","clk":"11540453445","pt":1719494686647,"mc":[{"id":"1.230178306","rc":[{"atl":[[14,0]],"id":47801105}],"con":true,"img":false}]}
{"op":"mcm","clk":"11540453451","pt":1719494686754,"mc":[{"id":"1.230178306","rc":[{"atb":[[2.44,0],[2.56,9.56]],"id":47095746}],"con":true,"img":false}]}
{"op":"mcm","clk":"11540453459","pt":1719494686855,"mc":[{"id":"1.230178306","rc":[{"atb":[[3.1,13.09],[2.94,0]],"id":61496663},{"atl":[[14,7.69]],"id":66596720}],"con":true,"img":false}]}
{"op":"mcm","clk":"11540453468","pt":1719494686958,"mc":[{"id":"1.230178306","rc":[{"atl":[[13.5,0.84],[14,7.69]],"id":47801105},{"atl":[[16.5,0],[5.3,8],[4.9,0.84]],"id":53893973},{"atl":[[16.5,0]],"id":66596720}],"con":true,"img":false}]}
{"op":"mcm","clk":"11540453488","pt":1719494687167,"mc":[{"id":"1.230178306","rc":[{"atb":[[1.08,1]],"id":47801105}],"con":true,"img":false}]}
{"op":"mcm","clk":"11540453519","pt":1719494687376,"mc":[{"id":"1.230178306","rc":[{"atb":[[1.08,0.26]],"id":47801105}],"con":true,"img":false}]}
{"op":"mcm","clk":"11540453534","pt":1719494687480,"mc":[{"id":"1.230178306","rc":[{"atb":[[1.08,0]],"id":47801105}],"con":true,"img":false}]}
{"op":"mcm","clk":"11540453547","pt":1719494687583,"mc":[{"id":"1.230178306","rc":[{"atb":[[4.8,1.1]],"id":47801105}],"con":true,"img":false}]}
{"op":"mcm","clk":"11540453666","pt":1719494688793,"mc":[{"id":"1.230178306","rc":[{"atl":[[13.5,1]],"id":47095746},{"atl":[[9,1],[9.2,0]],"id":53987475}],"con":true,"img":false}]}
{"op":"mcm","clk":"11540453673","pt":1719494688897,"mc":[{"id":"1.230178306","rc":[{"atl":[[13.5,3.44],[14,0]],"id":47801105},{"atb":[[2.56,0],[2.88,9.56]],"id":47095746},{"atl":[[13,0]],"id":47095746}],"con":true,"img":false}]}
{"op":"mcm","clk":"11540453903","pt":1719494691383,"mc":[{"id":"1.230178306","rc":[{"atl":[[5,0]],"id":53893973}],"con":true,"img":false}]}
{"op":"mcm","clk":"11540453913","pt":1719494691487,"mc":[{"id":"1.230178306","rc":[{"atb":[[4.6,0]],"id":47801105}],"con":true,"img":false}]}
{"op":"mcm","clk":"11540453975","pt":1719494692167,"mc":[{"id":"1.230178306","rc":[{"atl":[[4.9,0]],"id":53893973}],"con":true,"img":false}]}
{"op":"mcm","clk":"11540453994","pt":1719494692374,"mc":[{"id":"1.230178306","rc":[{"atl":[[16.5,6.45]],"id":53893973}],"con":true,"img":false}]}
{"op":"mcm","clk":"11540454005","pt":1719494692476,"mc":[{"id":"1.230178306","rc":[{"atl":[[5.3,0]],"id":53893973}],"con":true,"img":false}]}
{"op":"mcm","clk":"11540454027","pt":1719494692785,"mc":[{"id":"1.230178306","rc":[{"atb":[[2.48,0]],"id":53893973},{"atb":[[3.5,4.74]],"id":61496663}],"con":true,"img":false}]}
{"op":"mcm","clk":"11540454070","pt":1719494693356,"mc":[{"id":"1.230178306","rc":[{"atl":[[5,2]],"id":53893973}],"con":true,"img":false}]}
{"op":"mcm","clk":"11540454081","pt":1719494693460,"mc":[{"id":"1.230178306","rc":[{"atl":[[16.5,0],[5.3,8]],"id":53893973}],"con":true,"img":false}]}
{"op":"mcm","clk":"11540454122","pt":1719494693972,"mc":[{"id":"1.230178306","rc":[{"spn":4.8,"spf":1.0,"id":47801105},{"atl":[[4.9,0.84]],"id":53893973},{"spn":3.14,"spf":1.0,"id":53893973},{"spn":10.85,"spf":"NaN","id":47095746},{"spn":7.65,"spf":"NaN","id":61496663},{"spn":5.95,"spf":"NaN","id":66596720},{"spn":7.2,"spf":"NaN","id":53987475}],"con":true,"img":false}]}
{"op":"mcm","clk":"11540454152","pt":1719494694388,"mc":[{"id":"1.230178306","rc":[{"atl":[[5.1,0],[5.4,1]],"id":53893973}],"con":true,"img":false}]}
{"op":"mcm","clk":"11540454316","pt":1719494696559,"mc":[{"id":"1.230178306","rc":[{"atb":[[2.24,0]],"id":47095746},{"atb":[[3.5,0]],"id":61496663},{"atb":[[2.22,0]],"id":53987475}],"con":true,"img":false}]}
{"op":"mcm","clk":"11540454470","pt":1719494698675,"mc":[{"id":"1.230178306","rc":[{"atl":[[5,0]],"id":53893973}],"con":true,"img":false}]}
{"op":"mcm","clk":"11540454481","pt":1719494698777,"mc":[{"id":"1.230178306","rc":[{"atl":[[5.3,0],[5.4,9.85]],"id":53893973},{"atl":[[13.5,0],[15.5,1]],"id":47095746},{"atl":[[9,0],[11.5,1]],"id":53987475}],"con":true,"img":false}]}
{"op":"mcm","clk":"11540454499","pt":1719494698984,"mc":[{"id":"1.230178306","rc":[{"atb":[[4,0]],"id":47801105},{"atl":[[16.5,6.45],[4.9,0],[5.4,1]],"id":53893973}],"con":true,"img":false}]}
{"op":"mcm","clk":"11540454510","pt":1719494699086,"mc":[{"id":"1.230178306","rc":[{"atb":[[4.8,24.43]],"id":47801105}],"con":true,"img":false}]}
{"op":"mcm","clk":"11540454526","pt":1719494699292,"mc":[{"id":"1.230178306","rc":[{"atb":[[4.9,5.18]],"id":47801105}],"con":true,"img":false}]}
{"op":"mcm","clk":"11540454542","pt":1719494699503,"mc":[{"id":"1.230178306","rc":[{"atb":[[5,0.84]],"id":47801105}],"con":true,"img":false}]}
{"op":"mcm","clk":"11540454573","pt":1719494699970,"mc":[{"id":"1.230178306","rc":[{"atb":[[4.9,0]],"id":47801105}],"con":true,"img":false}]}
{"op":"mcm","clk":"11540454626","pt":1719494700490,"mc":[{"id":"1.230178306","rc":[{"atb":[[5,0]],"id":47801105}],"con":true,"img":false}]}
{"op":"mcm","clk":"11540454649","pt":1719494700698,"mc":[{"id":"1.230178306","rc":[{"atb":[[4.9,5.18]],"id":47801105},{"atl":[[5.3,2]],"id":53893973}],"con":true,"img":false}]}
{"op":"mcm","clk":"11540454660","pt":1719494700801,"mc":[{"id":"1.230178306","rc":[{"atl":[[16.5,0],[5.3,4]],"id":53893973}],"con":true,"img":false}]}
{"op":"mcm","clk":"11540454686","pt":1719494701063,"mc":[{"id":"1.230178306","rc":[{"atl":[[5.2,0.84]],"id":53893973}],"con":true,"img":false}]}
{"op":"mcm","clk":"11540454743","pt":1719494701790,"mc":[{"id":"1.230178306","rc":[{"atl":[[17.5,0],[17,1]],"id":47801105},{"atl":[[5.3,5],[5.4,0]],"id":53893973},{"atl":[[9.6,0],[9.2,1]],"id":61496663}],"con":true,"img":false}]}
{"op":"mcm","clk":"11540454764","pt":1719494702000,"mc":[{"id":"1.230178306","rc":[{"atb":[[5,5.18],[4.2,0]],"id":47801105},{"atl":[[13.5,0.84],[14.5,7.41]],"id":47801105},{"atb":[[2.46,12.57],[2.28,0]],"id":53893973},{"atb":[[4.3,6],[2.88,0]],"id":47095746},{"atb":[[3.1,0],[3.5,13.09]],"id":61496663},{"atb":[[3.8,0],[4.6,7.36]],"id":66596720},{"atl":[[8,0]],"id":66596720},{"atb":[[3.1,0],[3.55,17.81]],"id":53987475}],"con":true,"img":false}]}
{"op":"mcm","clk":"11540454778","pt":1719494702104,"mc":[{"id":"1.230178306","rc":[{"atl":[[18.5,5.71]],"id":47801105},{"atb":[[3.9,7.36]],"id":66596720}],"con":true,"img":false}]}
{"op":"mcm","clk":"11540454788","pt":1719494702209,"mc":[{"id":"1.230178306","rc":[{"atl":[[14.5,0]],"id":47801105},{"atb":[[4.6,0]],"id":66596720}],"con":true,"img":false}]}
{"op":"mcm","clk":"11540454809","pt":1719494702368,"mc":[{"id":"1.230178306","rc":[{"atb":[[4.9,0]],"id":47801105}],"con":true,"img":false}]}
{"op":"mcm","clk":"11540454818","pt":1719494702471,"mc":[{"id":"1.230178306","rc":[{"atb":[[4.8,23.59],[4.9,10.36],[5,0]],"id":47801105}],"con":true,"img":false}]}
{"op":"mcm","clk":"11540454844","pt":1719494702779,"mc":[{"id":"1.230178306","rc":[{"atb":[[4.8,23.33]],"id":47801105}],"con":true,"img":false}]}
{"op":"mcm","clk":"11540454879","pt":1719494703091,"mc":[{"id":"1.230178306","rc":[{"atb":[[5,5.08]],"id":47801105},{"atb":[[2.52,9.19]],"id":53893973}],"con":true,"img":false}]}
{"op":"mcm","clk":"11540454893","pt":1719494703195,"mc":[{"id":"1.230178306","rc":[{"atb":[[4.9,0],[5,15.44]],"id":47801105}],"con":true,"img":false}]}
{"op":"mcm","clk":"11540454911","pt":1719494703402,"mc":[{"id":"1.230178306","rc":[{"atb":[[3.6,9.93]],"id":66596720}],"con":true,"img":false}]}
{"op":"mcm","clk":"11540454916","pt":1719494703505,"mc":[{"id":"1.230178306","rc":[{"atb":[[3.15,6.5]],"id":53987475}],"con":true,"img":false}]}
{"op":"mcm","clk":"11540454954","pt":1719494703874,"mc":[{"id":"1.230178306","rc":[{"atb":[[2.46,10.47],[2.66,2.1]],"id":53893973}],"con":true,"img":false}]}
{"op":"mcm","clk":"11540454988","pt":1719494704184,"mc":[{"id":"1.230178306","rc":[{"atb":[[3.05,4.62]],"id":66596720}],"con":true,"img":false}]}
{"op":"mcm","clk":"11540455006","pt":1719494704392,"mc":[{"id":"1.230178306","rc":[{"atb":[[2.74,6.81]],"id":47801105}],"con":true,"img":false}]}
{"op":"mcm","clk":"11540455022","pt":1719494704600,"mc":[{"id":"1.230178306","rc":[{"atb":[[4.7,1.62]],"id":47801105},{"atb":[[3.05,5.78]],"id":61496663}],"con":true,"img":false}]}
{"op":"mcm","clk":"11540455048","pt":1719494704908,"mc":[{"id":"1.230178306","rc":[{"atb":[[3.15,0.84]],"id":53893973},{"atb":[[5.4,2.84]],"id":53987475}],"con":true,"img":false}]}
{"op":"mcm","clk":"11540455074","pt":1719494705168,"mc":[{"id":"1.230178306","rc":[{"atb":[[1.12,1.69]],"id":47801105}],"con":true,"img":false}]}
{"op":"mcm","clk":"11540455109","pt":1719494705581,"mc":[{"id":"1.230178306","rc":[{"atb":[[1.12,0.05]],"id":47801105}],"con":true,"img":false}]}
{"op":"mcm","clk":"11540455143","pt":1719494705995,"mc":[{"id":"1.230178306","rc":[{"atb":[[1.12,0]],"id":47801105},{"atl":[[5.3,3]],"id":53893973}],"con":true,"img":false}]}
{"op":"mcm","clk":"11540455150","pt":1719494706098,"mc":[{"id":"1.230178306","rc":[{"atb":[[5,15.5]],"id":47801105},{"atl":[[5.3,1],[12.5,8]],"id":53893973}],"con":true,"img":false}]}
{"op":"mcm","clk":"11540455176","pt":1719494706472,"mc":[{"id":"1.230178306","rc":[{"atb":[[5.1,0.84]],"id":47801105},{"atb":[[6,0]],"id":47095746},{"atb":[[1.12,1.69]],"id":53987475}],"con":true,"img":false}]}
{"op":"mcm","clk":"11540455196","pt":1719494706681,"mc":[{"id":"1.230178306","rc":[{"atb":[[5,10.41]],"id":47801105}],"con":true,"img":false}]}
{"op":"mcm","clk":"11540455207","pt":1719494706775,"mc":[{"id":"1.230178306","rc":[{"atb":[[1.08,1.69]],"id":53893973}],"con":true,"img":false}]}
{"op":"mcm","clk":"11540455228","pt":1719494707084,"mc":[{"id":"1.230178306","rc":[{"atb":[[1.08,0.09]],"id":53893973},{"atb":[[1.12,0.05]],"id":53987475}],"con":true,"img":false}]}
{"op":"mcm","clk":"11540455266","pt":1719494707501,"mc":[{"id":"1.230178306","rc":[{"atb":[[1.12,0]],"id":53987475}],"con":true,"img":false}]}
{"op":"mcm","clk":"11540455280","pt":1719494707605,"mc":[{"id":"1.230178306","rc":[{"atb":[[5.5,0.05]],"id":53987475}],"con":true,"img":false}]}
{"op":"mcm","clk":"11540455305","pt":1719494707876,"mc":[{"id":"1.230178306","rc":[{"atb":[[1.08,0]],"id":53893973},{"atl":[[5.2,2.84]],"id":53893973}],"con":true,"img":false}]}
{"op":"mcm","clk":"11540455314","pt":1719494707970,"mc":[{"id":"1.230178306","rc":[{"atb":[[3.15,0.94]],"id":53893973}],"con":true,"img":false}]}
{"op":"mcm","clk":"11540455340","pt":1719494708281,"mc":[{"id":"1.230178306","rc":[{"atb":[[4.9,11.27],[5,0.05]],"id":47801105}],"con":true,"img":false}]}
{"op":"mcm","clk":"11540455419","pt":1719494709106,"mc":[{"id":"1.230178306","rc":[{"atb":[[5.1,0]],"id":47801105}],"con":true,"img":false}]}
{"op":"mcm","clk":"11540455437","pt":1719494709276,"mc":[{"id":"1.230178306","rc":[{"atb":[[5,5.14]],"id":47801105}],"con":true,"img":false}]}
{"op":"mcm","clk":"11540455447","pt":1719494709377,"mc":[{"id":"1.230178306","rc":[{"atl":[[5.2,7.84]],"id":53893973}],"con":true,"img":false}]}
{"op":"mcm","clk":"11540455469","pt":1719494709679,"mc":[{"id":"1.230178306","rc":[{"atl":[[5.2,2.84]],"id":53893973}],"con":true,"img":false}]}
{"op":"mcm","clk":"11540455498","pt":1719494710193,"mc":[{"id":"1.230178306","rc":[{"atb":[[1.06,1.7],[1.05,1.7]],"id":47801105},{"atl":[[1000,5.27]],"id":47801105},{"atb":[[1.06,1.7]],"id":47095746},{"atl":[[1000,1.87]],"id":47095746},{"atb":[[1.04,1.7]],"id":61496663},{"atl":[[1000,1.7]],"id":61496663}],"con":true,"img":false}]}
{"op":"mcm","clk":"11540455503","pt":1719494710296,"mc":[{"id":"1.230178306","rc":[{"atb":[[1.05,3.4]],"id":47801105}],"con":true,"img":false}]}
{"op":"mcm","clk":"11540455518","pt":1719494710503,"mc":[{"id":"1.230178306","rc":[{"atb":[[1.06,0.04],[1.05,1.75]],"id":47801105},{"atl":[[1000,0.21]],"id":47801105},{"atb":[[1.06,0.04]],"id":47095746},{"atl":[[1000,0.16]],"id":47095746},{"atb":[[1.04,0.06]],"id":61496663},{"atl":[[1000,0.01]],"id":61496663}],"con":true,"img":false}]}
{"op":"mcm","clk":"11540455528","pt":1719494710607,"mc":[{"id":"1.230178306","rc":[{"atb":[[1.05,0.09]],"id":47801105}],"con":true,"img":false}]}
{"op":"mcm","clk":"11540455538","pt":1719494710777,"mc":[{"id":"1.230178306","rc":[{"atb":[[1.06,0],[1.05,0]],"id":47801105},{"atl":[[1000,0.16]],"id":47801105},{"atb":[[1.06,0]],"id":47095746},{"atb":[[1.04,0]],"id":61496663},{"atl":[[1000,0]],"id":61496663}],"con":true,"img":false}]}
{"op":"mcm","clk":"11540455543","pt":1719494710876,"mc":[{"id":"1.230178306","rc":[{"atb":[[4.9,0],[5.1,0.14],[5,16.41]],"id":47801105},{"atl":[[13,1.35]],"id":47801105},{"atb":[[8.2,0.88]],"id":47095746},{"atb":[[5.7,0.9]],"id":61496663},{"atl":[[26,0.01]],"id":61496663}],"con":true,"img":false}]}
{"op":"mcm","clk":"11540455714","pt":1719494713197,"mc":[{"id":"1.230178306","rc":[{"atl":[[5.2,0.84]],"id":53893973}],"con":true,"img":false}]}
{"op":"mcm","clk":"11540455743","pt":1719494713610,"mc":[{"id":"1.230178306","rc":[{"atb":[[5.1,0.98]],"id":47801105}],"con":true,"img":false}]}
{"op":"mcm","clk":"11540455791","pt":1719494714077,"mc":[{"id":"1.230178306","rc":[{"atb":[[5,11.32]],"id":47801105}],"con":true,"img":false}]}
{"op":"mcm","clk":"11540455802","pt":1719494714182,"mc":[{"id":"1.230178306","rc":[{"atb":[[4.9,12.32],[5,0.05]],"id":47801105}],"con":true,"img":false}]}
{"op":"mcm","clk":"11540455827","pt":1719494714389,"mc":[{"id":"1.230178306","rc":[{"atl":[[17,0],[17.5,1]],"id":47801105},{"atl":[[5.3,0],[5.4,1]],"id":53893973},{"atl":[[16,1],[15.5,0]],"id":47095746},{"atl":[[11,1],[11.5,0]],"id":53987475}],"con":true,"img":false}]}
{"op":"mcm","clk":"11540455840","pt":1719494714492,"mc":[{"id":"1.230178306","rc":[{"atb":[[4.9,0],[4.4,6],[5.1,0.14]],"id":47801105},{"atl":[[18.5,0],[21,5]],"id":47801105},{"atl":[[5.4,9]],"id":53893973},{"atl":[[100,2]],"id":47095746}],"con":true,"img":false}]}
{"op":"mcm","clk":"11540455849","pt":1719494714596,"mc":[{"id":"1.230178306","rc":[{"atb":[[4.9,12.32],[4.4,0]],"id":47801105},{"atl":[[12.5,0]],"id":53893973},{"atl":[[130,0]],"id":47095746},{"atb":[[3.15,13.02],[3.9,0]],"id":66596720},{"atl":[[8,6]],"id":66596720},{"atl":[[11,0],[11.5,1]],"id":53987475}],"con":true,"img":false}]}
{"op":"mcm","clk":"11540455855","pt":1719494714700,"mc":[{"id":"1.230178306","rc":[{"atb":[[4.9,17.5]],"id":47801105},{"atl":[[12.5,8.7]],"id":53893973},{"atb":[[3.7,13.02],[3.15,0]],"id":66596720}],"con":true,"img":false}]}
{"op":"mcm","clk":"11540455869","pt":1719494714804,"mc":[{"id":"1.230178306","rc":[{"atl":[[5.4,1]],"id":53893973}],"con":true,"img":false}]}
{"op":"mcm","clk":"11540455909","pt":1719494715180,"mc":[{"id":"1.230178306","rc":[{"atl":[[5.3,2],[5.2,0]],"id":53893973}],"con":true,"img":false}]}
{"op":"mcm","clk":"11540455921","pt":1719494715279,"mc":[{"id":"1.230178306","rc":[{"atl":[[5.3,4],[12.5,0]],"id":53893973}],"con":true,"img":false}]}
{"op":"mcm","clk":"11540455951","pt":1719494715481,"mc":[{"id":"1.230178306","rc":[{"atl":[[5.2,0.84]],"id":53893973}],"con":true,"img":false}]}
{"op":"mcm","clk":"11540456083","pt":1719494717089,"mc":[{"id":"1.230178306","rc":[{"atb":[[4.3,1]],"id":47801105}],"con":true,"img":false}]}
{"op":"mcm","clk":"11540456130","pt":1719494717711,"mc":[{"id":"1.230178306","rc":[{"atb":[[4.8,0]],"id":47801105}],"con":true,"img":false}]}
{"op":"mcm","clk":"11540456179","pt":1719494718189,"mc":[{"id":"1.230178306","rc":[{"atb":[[3.55,14.91]],"id":53987475}],"con":true,"img":false}]}
{"op":"mcm","clk":"11540456383","pt":1719494720512,"mc":[{"id":"1.230178306","rc":[{"atl":[[5.3,2]],"id":53893973},{"atb":[[5.1,2.87]],"id":66596720}],"con":true,"img":false}]}
{"op":"mcm","clk":"11540456391","pt":1719494720615,"mc":[{"id":"1.230178306","rc":[{"atb":[[5,0.9]],"id":47801105}],"con":true,"img":false}]}
{"op":"mcm","clk":"11540456399","pt":1719494720717,"mc":[{"id":"1.230178306","rc":[{"atl":[[5.3,0],[5.4,9]],"id":53893973}],"con":true,"img":false}]}
{"op":"mcm","clk":"11540456413","pt":1719494720880,"mc":[{"id":"1.230178306","rc":[{"atb":[[4.9,12.32]],"id":47801105}],"con":true,"img":false}]}
{"op":"mcm","clk":"11540456428","pt":1719494721083,"mc":[{"id":"1.230178306","rc":[{"atl":[[5.2,0]],"id":53893973}],"con":true,"img":false}]}
{"op":"mcm","clk":"11540456437","pt":1719494721186,"mc":[{"id":"1.230178306","rc":[{"atl":[[12.5,8.7],[5.4,1]],"id":53893973}],"con":true,"img":false}]}
{"op":"mcm","clk":"11540456537","pt":1719494722522,"mc":[{"id":"1.230178306","rc":[{"atl":[[5.3,2]],"id":53893973}],"con":true,"img":false}]}
{"op":"mcm","clk":"11540456562","pt":1719494722887,"mc":[{"id":"1.230178306","rc":[{"atl":[[5.3,4],[12.5,0]],"id":53893973}],"con":true,"img":false}]}
{"op":"mcm","clk":"11540456571","pt":1719494722990,"mc":[{"id":"1.230178306","rc":[{"atl":[[5.2,0.84]],"id":53893973}],"con":true,"img":false}]}
{"op":"mcm","clk":"11540456684","pt":1719494724389,"mc":[{"id":"1.230178306","rc":[{"atl":[[5,1],[5.4,0]],"id":53893973},{"atl":[[16,0],[13.5,1]],"id":47095746}],"con":true,"img":false}]}
{"op":"mcm","clk":"11540456703","pt":1719494724597,"mc":[{"id":"1.230178306","rc":[{"atl":[[9.2,1],[11.5,0]],"id":53987475}],"con":true,"img":false}]}
{"op":"mcm","clk":"11540456729","pt":1719494724905,"mc":[{"id":"1.230178306","rc":[{"atb":[[5.1,1.8],[4.7,0]],"id":47801105}],"con":true,"img":false}]}
{"op":"mcm","clk":"11540456734","pt":1719494725009,"mc":[{"id":"1.230178306","rc":[{"atb":[[4.9,0],[5.1,3.8]],"id":47801105}],"con":true,"img":false}]}
{"op":"mcm","clk":"11540456754","pt":1719494725215,"mc":[{"id":"1.230178306","rc":[{"atb":[[5.1,2.14],[5,2.56]],"id":47801105}],"con":true,"img":false}]}
{"op":"mcm","clk":"11540456762","pt":1719494725319,"mc":[{"id":"1.230178306","rc":[{"atb":[[5.2,4.88]],"id":47801105},{"atb":[[2.5,0]],"id":53893973}],"con":true,"img":false}]}
{"op":"mcm","clk":"11540456801","pt":1719494725807,"mc":[{"id":"1.230178306","rc":[{"atl":[[5.3,2]],"id":53893973}],"con":true,"img":false}]}
{"op":"mcm","clk":"11540456818","pt":1719494726100,"mc":[{"id":"1.230178306","rc":[{"atb":[[5,1.71]],"id":47801105}],"con":true,"img":false}]}
{"op":"mcm","clk":"11540456943","pt":1719494727600,"mc":[{"id":"1.230178306","rc":[{"atb":[[5.3,0.84]],"id":47801105}],"con":true,"img":false}]}
{"op":"mcm","clk":"11540456953","pt":1719494727701,"mc":[{"id":"1.230178306","rc":[{"atb":[[2.48,8.01]],"id":53893973}],"con":true,"img":false}]}
