{"op":"mcm","clk":"11536833040","pt":1719431776484,"mc":[{"id":"1.230180135","marketDefinition":{"bspMarket":true,"turnInPlayEnabled":false,"persistenceEnabled":false,"marketBaseRate":5.0,"eventId":"33376437","eventTypeId":"4339","numberOfWinners":2,"bettingType":"ODDS","marketType":"PLACE","marketTime":"2024-06-27T16:54:00.000Z","suspendTime":"2024-06-27T16:54:00.000Z","bspReconciled":false,"complete":true,"inPlay":false,"crossMatching":false,"runnersVoidable":false,"numberOfActiveRunners":5,"betDelay":0,"status":"OPEN","runners":[{"status":"ACTIVE","sortPriority":1,"id":4065261,"name":"2. Manx Storm"},{"status":"ACTIVE","sortPriority":2,"id":69176457,"name":"3. Franco Eve"},{"status":"ACTIVE","sortPriority":3,"id":41401491,"name":"4. Connors Bullet"},{"status":"ACTIVE","sortPriority":4,"id":65040144,"name":"5. Diegos Talavara"},{"status":"ACTIVE","sortPriority":5,"id":52032624,"name":"6. Limekiln Chic"}],"regulators":["MR_INT"],"venue":"Towcester","countryCode":"GB","discountAllowed":false,"timezone":"Europe/London","openDate":"2024-06-27T13:33:00.000Z","version":5994767139,"name":"To Be Placed","eventName":"Towcester 27th Jun"},"rc":[],"con":true,"img":false}]}
{"op":"mcm","clk":"11536833153","pt":1719431777537,"mc":[{"id":"1.230180135","marketDefinition":{"bspMarket":true,"turnInPlayEnabled":false,"persistenceEnabled":false,"marketBaseRate":5.0,"eventId":"33376437","eventTypeId":"4339","numberOfWinners":2,"bettingType":"ODDS","marketType":"PLACE","marketTime":"2024-06-27T16:54:00.000Z","suspendTime":"2024-06-27T16:54:00.000Z","bspReconciled":false,"complete":true,"inPlay":false,"crossMatching":false,"runnersVoidable":false,"numberOfActiveRunners":5,"betDelay":0,"status":"OPEN","runners":[{"status":"ACTIVE","sortPriority":1,"id":4065261,"name":"2. Manx Storm"},{"status":"ACTIVE","sortPriority":2,"id":69176457,"name":"3. Franco Eve"},{"status":"ACTIVE","sortPriority":3,"id":41401491,"name":"4. Connors Bullet"},{"status":"ACTIVE","sortPriority":4,"id":65040144,"name":"5. Diegos Talavara"},{"status":"ACTIVE","sortPriority":5,"id":52032624,"name":"6. Limekiln Chic"}],"regulators":["MR_INT"],"venue":"Towcester","countryCode":"GB","discountAllowed":true,"timezone":"Europe/London","openDate":"2024-06-27T13:33:00.000Z","version":5994767139,"name":"To Be Placed","eventName":"Towcester 27th Jun"},"rc":[],"con":true,"img":false}]}
{"op":"mcm","clk":"11537083930","pt":1719435434089,"mc":[{"id":"1.230180135","rc":[{"atb":[[1.01,51.84]],"id":41401491},{"atl":[[1000,0.84]],"id":41401491},{"spn":500.5,"spf":"NaN","id":41401491},{"atb":[[1.02,25.92]],"id":52032624},{"atl":[[990,0.84]],"id":52032624},{"spn":495.51,"spf":"NaN","id":52032624},{"atb":[[1.01,51.84]],"id":4065261},{"atl":[[1000,0.84]],"id":4065261},{"spn":500.5,"spf":"NaN","id":4065261},{"atb":[[1.02,25.92]],"id":69176457},{"atl":[[1000,0.84]],"id":69176457},{"spn":500.51,"spf":"NaN","id":69176457},{"atb":[[1.02,25.92]],"id":65040144},{"atl":[[1000,0.84]],"id":65040144},{"spn":500.51,"spf":"NaN","id":65040144}],"con":true,"img":false}]}
{"op":"mcm","clk":"11537235636","pt":1719437882799,"mc":[{"id":"1.230180135","marketDefinition":{"bspMarket":true,"turnInPlayEnabled":false,"persistenceEnabled":false,"marketBaseRate":5.0,"eventId":"33376437","eventTypeId":"4339","numberOfWinners":2,"bettingType":"ODDS","marketType":"PLACE","marketTime":"2024-06-27T16:54:00.000Z","suspendTime":"2024-06-27T16:54:00.000Z","bspReconciled":false,"complete":true,"inPlay":false,"crossMatching":false,"runnersVoidable":false,"numberOfActiveRunners":5,"betDelay":0,"status":"OPEN","runners":[{"status":"ACTIVE","sortPriority":1,"id":4065261,"name":"2. Manx Storm"},{"status":"ACTIVE","sortPriority":2,"id":69176457,"name":"3. Franco Eve"},{"status":"ACTIVE","sortPriority":3,"id":41401491,"name":"4. Connors Bullet"},{"status":"ACTIVE","sortPriority":4,"id":65040144,"name":"5. Diegos Talavara"},{"status":"ACTIVE","sortPriority":5,"id":52032624,"name":"6. Limekiln Chic"}],"regulators":["MR_INT"],"venue":"Towcester","countryCode":"GB","discountAllowed":true,"timezone":"Europe/London","openDate":"2024-06-27T13:33:00.000Z","version":5994767139,"name":"To Be Placed","eventName":"Towcester 27th Jun"},"rc":[{"atb":[[1.01,51.85]],"id":41401491},{"atl":[[1000,0.84]],"id":41401491},{"spn":500.5,"spf":"NaN","id":41401491},{"atb":[[1.02,25.92]],"id":52032624},{"atl":[[990,0.84]],"id":52032624},{"spn":495.51,"spf":"NaN","id":52032624},{"atb":[[1.01,51.85]],"id":4065261},{"atl":[[1000,0.84]],"id":4065261},{"spn":500.5,"spf":"NaN","id":4065261},{"atb":[[1.02,25.92]],"id":69176457},{"atl":[[1000,0.84]],"id":69176457},{"spn":500.51,"spf":"NaN","id":69176457},{"atb":[[1.02,25.92]],"id":65040144},{"atl":[[1000,0.84]],"id":65040144},{"spn":500.51,"spf":"NaN","id":65040144}],"con":true,"img":true}]}
{"op":"mcm","clk":"11537302420","pt":1719439036854,"mc":[{"id":"1.230180135","rc":[{"atb":[[1.01,51.85]],"id":41401491},{"atl":[[1000,0.23]],"id":41401491},{"atb":[[1.02,25.92]],"id":52032624},{"atl":[[990,0.23]],"id":52032624},{"atb":[[1.01,51.85]],"id":4065261},{"atl":[[1000,0.23]],"id":4065261},{"atb":[[1.02,25.92]],"id":69176457},{"atl":[[1000,0.23]],"id":69176457},{"atb":[[1.02,25.92]],"id":65040144},{"atl":[[1000,0.23]],"id":65040144}],"con":true,"img":false}]}
{"op":"mcm","clk":"11537576924","pt":1719443282843,"mc":[{"id":"1.230180135","marketDefinition":{"bspMarket":true,"turnInPlayEnabled":false,"persistenceEnabled":false,"marketBaseRate":5.0,"eventId":"33376437","eventTypeId":"4339","numberOfWinners":2,"bettingType":"ODDS","marketType":"PLACE","marketTime":"2024-06-27T16:54:00.000Z","suspendTime":"2024-06-27T16:54:00.000Z","bspReconciled":false,"complete":true,"inPlay":false,"crossMatching":false,"runnersVoidable":false,"numberOfActiveRunners":5,"betDelay":0,"status":"OPEN","runners":[{"status":"ACTIVE","sortPriority":1,"id":4065261,"name":"2. Manx Storm"},{"status":"ACTIVE","sortPriority":2,"id":69176457,"name":"3. Franco Eve"},{"status":"ACTIVE","sortPriority":3,"id":41401491,"name":"4. Connors Bullet"},{"status":"ACTIVE","sortPriority":4,"id":65040144,"name":"5. Diegos Talavara"},{"status":"ACTIVE","sortPriority":5,"id":52032624,"name":"6. Limekiln Chic"}],"regulators":["MR_INT"],"venue":"Towcester","countryCode":"GB","discountAllowed":true,"timezone":"Europe/London","openDate":"2024-06-27T13:33:00.000Z","version":5994767139,"name":"To Be Placed","eventName":"Towcester 27th Jun"},"rc":[{"atb":[[1.01,51.85]],"id":41401491},{"atl":[[1000,0.23]],"id":41401491},{"spn":500.5,"spf":"NaN","id":41401491},{"atb":[[1.02,25.92]],"id":52032624},{"atl":[[990,0.23]],"id":52032624},{"spn":495.51,"spf":"NaN","id":52032624},{"atb":[[1.01,51.85]],"id":4065261},{"atl":[[1000,0.23]],"id":4065261},{"spn":500.5,"spf":"NaN","id":4065261},{"atb":[[1.02,25.92]],"id":69176457},{"atl":[[1000,0.23]],"id":69176457},{"spn":500.51,"spf":"NaN","id":69176457},{"atb":[[1.02,25.92]],"id":65040144},{"atl":[[1000,0.23]],"id":65040144},{"spn":500.51,"spf":"NaN","id":65040144}],"con":true,"img":true}]}
{"op":"mcm","clk":"11537958612","pt":1719448682890,"mc":[{"id":"1.230180135","marketDefinition":{"bspMarket":true,"turnInPlayEnabled":false,"persistenceEnabled":false,"marketBaseRate":5.0,"eventId":"33376437","eventTypeId":"4339","numberOfWinners":2,"bettingType":"ODDS","marketType":"PLACE","marketTime":"2024-06-27T16:54:00.000Z","suspendTime":"2024-06-27T16:54:00.000Z","bspReconciled":false,"complete":true,"inPlay":false,"crossMatching":false,"runnersVoidable":false,"numberOfActiveRunners":5,"betDelay":0,"status":"OPEN","runners":[{"status":"ACTIVE","sortPriority":1,"id":4065261,"name":"2. Manx Storm"},{"status":"ACTIVE","sortPriority":2,"id":69176457,"name":"3. Franco Eve"},{"status":"ACTIVE","sortPriority":3,"id":41401491,"name":"4. Connors Bullet"},{"status":"ACTIVE","sortPriority":4,"id":65040144,"name":"5. Diegos Talavara"},{"status":"ACTIVE","sortPriority":5,"id":52032624,"name":"6. Limekiln Chic"}],"regulators":["MR_INT"],"venue":"Towcester","countryCode":"GB","discountAllowed":true,"timezone":"Europe/London","openDate":"2024-06-27T13:33:00.000Z","version":5994767139,"name":"To Be Placed","eventName":"Towcester 27th Jun"},"rc":[{"atb":[[1.01,51.85]],"id":41401491},{"atl":[[1000,0.23]],"id":41401491},{"spn":500.5,"spf":"NaN","id":41401491},{"atb":[[1.02,25.92]],"id":52032624},{"atl":[[990,0.23]],"id":52032624},{"spn":495.51,"spf":"NaN","id":52032624},{"atb":[[1.01,51.85]],"id":4065261},{"atl":[[1000,0.23]],"id":4065261},{"spn":500.5,"spf":"NaN","id":4065261},{"atb":[[1.02,25.92]],"id":69176457},{"atl":[[1000,0.23]],"id":69176457},{"spn":500.51,"spf":"NaN","id":69176457},{"atb":[[1.02,25.92]],"id":65040144},{"atl":[[1000,0.23]],"id":65040144},{"spn":500.51,"spf":"NaN","id":65040144}],"con":true,"img":true}]}
{"op":"mcm","clk":"11538174188","pt":1719454082861,"mc":[{"id":"1.230180135","marketDefinition":{"bspMarket":true,"turnInPlayEnabled":false,"persistenceEnabled":false,"marketBaseRate":5.0,"eventId":"33376437","eventTypeId":"4339","numberOfWinners":2,"bettingType":"ODDS","marketType":"PLACE","marketTime":"2024-06-27T16:54:00.000Z","suspendTime":"2024-06-27T16:54:00.000Z","bspReconciled":false,"complete":true,"inPlay":false,"crossMatching":false,"runnersVoidable":false,"numberOfActiveRunners":5,"betDelay":0,"status":"OPEN","runners":[{"status":"ACTIVE","sortPriority":1,"id":4065261,"name":"2. Manx Storm"},{"status":"ACTIVE","sortPriority":2,"id":69176457,"name":"3. Franco Eve"},{"status":"ACTIVE","sortPriority":3,"id":41401491,"name":"4. Connors Bullet"},{"status":"ACTIVE","sortPriority":4,"id":65040144,"name":"5. Diegos Talavara"},{"status":"ACTIVE","sortPriority":5,"id":52032624,"name":"6. Limekiln Chic"}],"regulators":["MR_INT"],"venue":"Towcester","countryCode":"GB","discountAllowed":true,"timezone":"Europe/London","openDate":"2024-06-27T13:33:00.000Z","version":5994767139,"name":"To Be Placed","eventName":"Towcester 27th Jun"},"rc":[{"atb":[[1.01,51.86]],"id":41401491},{"atl":[[1000,0.23]],"id":41401491},{"spn":500.5,"spf":"NaN","id":41401491},{"atb":[[1.02,25.93]],"id":52032624},{"atl":[[990,0.23]],"id":52032624},{"spn":495.51,"spf":"NaN","id":52032624},{"atb":[[1.01,51.86]],"id":4065261},{"atl":[[1000,0.23]],"id":4065261},{"spn":500.5,"spf":"NaN","id":4065261},{"atb":[[1.02,25.93]],"id":69176457},{"atl":[[1000,0.23]],"id":69176457},{"spn":500.51,"spf":"NaN","id":69176457},{"atb":[[1.02,25.93]],"id":65040144},{"atl":[[1000,0.23]],"id":65040144},{"spn":500.51,"spf":"NaN","id":65040144}],"con":true,"img":true}]}
{"op":"mcm","clk":"11538371901","pt":1719459482935,"mc":[{"id":"1.230180135","marketDefinition":{"bspMarket":true,"turnInPlayEnabled":false,"persistenceEnabled":false,"marketBaseRate":5.0,"eventId":"33376437","eventTypeId":"4339","numberOfWinners":2,"bettingType":"ODDS","marketType":"PLACE","marketTime":"2024-06-27T16:54:00.000Z","suspendTime":"2024-06-27T16:54:00.000Z","bspReconciled":false,"complete":true,"inPlay":false,"crossMatching":false,"runnersVoidable":false,"numberOfActiveRunners":5,"betDelay":0,"status":"OPEN","runners":[{"status":"ACTIVE","sortPriority":1,"id":4065261,"name":"2. Manx Storm"},{"status":"ACTIVE","sortPriority":2,"id":69176457,"name":"3. Franco Eve"},{"status":"ACTIVE","sortPriority":3,"id":41401491,"name":"4. Connors Bullet"},{"status":"ACTIVE","sortPriority":4,"id":65040144,"name":"5. Diegos Talavara"},{"status":"ACTIVE","sortPriority":5,"id":52032624,"name":"6. Limekiln Chic"}],"regulators":["MR_INT"],"venue":"Towcester","countryCode":"GB","discountAllowed":true,"timezone":"Europe/London","openDate":"2024-06-27T13:33:00.000Z","version":5994767139,"name":"To Be Placed","eventName":"Towcester 27th Jun"},"rc":[{"atb":[[1.01,51.87]],"id":41401491},{"atl":[[1000,0.23]],"id":41401491},{"spn":500.5,"spf":"NaN","id":41401491},{"atb":[[1.02,25.93]],"id":52032624},{"atl":[[990,0.23]],"id":52032624},{"spn":495.51,"spf":"NaN","id":52032624},{"atb":[[1.01,51.87]],"id":4065261},{"atl":[[1000,0.23]],"id":4065261},{"spn":500.5,"spf":"NaN","id":4065261},{"atb":[[1.02,25.93]],"id":69176457},{"atl":[[1000,0.23]],"id":69176457},{"spn":500.51,"spf":"NaN","id":69176457},{"atb":[[1.02,25.93]],"id":65040144},{"atl":[[1000,0.23]],"id":65040144},{"spn":500.51,"spf":"NaN","id":65040144}],"con":true,"img":true}]}
{"op":"mcm","clk":"11538598978","pt":1719464882861,"mc":[{"id":"1.230180135","marketDefinition":{"bspMarket":true,"turnInPlayEnabled":false,"persistenceEnabled":false,"marketBaseRate":5.0,"eventId":"33376437","eventTypeId":"4339","numberOfWinners":2,"bettingType":"ODDS","marketType":"PLACE","marketTime":"2024-06-27T16:54:00.000Z","suspendTime":"2024-06-27T16:54:00.000Z","bspReconciled":false,"complete":true,"inPlay":false,"crossMatching":false,"runnersVoidable":false,"numberOfActiveRunners":5,"betDelay":0,"status":"OPEN","runners":[{"status":"ACTIVE","sortPriority":1,"id":4065261,"name":"2. Manx Storm"},{"status":"ACTIVE","sortPriority":2,"id":69176457,"name":"3. Franco Eve"},{"status":"ACTIVE","sortPriority":3,"id":41401491,"name":"4. Connors Bullet"},{"status":"ACTIVE","sortPriority":4,"id":65040144,"name":"5. Diegos Talavara"},{"status":"ACTIVE","sortPriority":5,"id":52032624,"name":"6. Limekiln Chic"}],"regulators":["MR_INT"],"venue":"Towcester","countryCode":"GB","discountAllowed":true,"timezone":"Europe/London","openDate":"2024-06-27T13:33:00.000Z","version":5994767139,"name":"To Be Placed","eventName":"Towcester 27th Jun"},"rc":[{"atb":[[1.01,51.86]],"id":41401491},{"atl":[[1000,0.23]],"id":41401491},{"spn":500.5,"spf":"NaN","id":41401491},{"atb":[[1.02,25.93]],"id":52032624},{"atl":[[990,0.23]],"id":52032624},{"spn":495.51,"spf":"NaN","id":52032624},{"atb":[[1.01,51.86]],"id":4065261},{"atl":[[1000,0.23]],"id":4065261},{"spn":500.5,"spf":"NaN","id":4065261},{"atb":[[1.02,25.93]],"id":69176457},{"atl":[[1000,0.23]],"id":69176457},{"spn":500.51,"spf":"NaN","id":69176457},{"atb":[[1.02,25.93]],"id":65040144},{"atl":[[1000,0.23]],"id":65040144},{"spn":500.51,"spf":"NaN","id":65040144}],"con":true,"img":true}]}
{"op":"mcm","clk":"11538906716","pt":1719471498275,"mc":[{"id":"1.230180135","rc":[{"atb":[[1.01,51.86],[1.07,2.48]],"id":41401491},{"atl":[[1000,1.23]],"id":41401491},{"spn":500.53,"spf":"NaN","id":41401491},{"atb":[[1.02,25.93],[1.07,2.48]],"id":52032624},{"atl":[[1000,1]],"id":52032624},{"spn":495.53,"spf":"NaN","id":52032624},{"atb":[[1.01,51.86],[1.07,2.48]],"id":4065261},{"atl":[[1000,1.23]],"id":4065261},{"spn":500.53,"spf":"NaN","id":4065261},{"atb":[[1.02,25.93],[1.07,2.48]],"id":69176457},{"atl":[[1000,1.23]],"id":69176457},{"spn":500.53,"spf":"NaN","id":69176457},{"atb":[[1.02,25.93],[1.07,2.48]],"id":65040144},{"atl":[[1000,1.23]],"id":65040144},{"spn":500.53,"spf":"NaN","id":65040144}],"con":true,"img":false}]}
{"op":"mcm","clk":"11538906724","pt":1719471498379,"mc":[{"id":"1.230180135","rc":[{"atl":[[1000,0.71]],"id":41401491},{"atl":[[1000,0.48]],"id":52032624},{"atl":[[1000,0.71]],"id":4065261},{"atl":[[1000,0.71]],"id":69176457},{"atl":[[1000,0.71]],"id":65040144}],"con":true,"img":false}]}
{"op":"mcm","clk":"11538906737","pt":1719471498581,"mc":[{"id":"1.230180135","rc":[{"atl":[[1000,0.23]],"id":41401491},{"atl":[[1000,0]],"id":52032624},{"atl":[[1000,0.23]],"id":4065261},{"atl":[[1000,0.23]],"id":69176457},{"atl":[[1000,0.23]],"id":65040144}],"con":true,"img":false}]}
{"op":"mcm","clk":"11538906744","pt":1719471498682,"mc":[{"id":"1.230180135","rc":[{"atl":[[75,0.48]],"id":41401491},{"atl":[[75,0.48]],"id":52032624},{"atl":[[75,0.48]],"id":4065261},{"atl":[[75,0.48]],"id":69176457},{"atl":[[75,0.48]],"id":65040144}],"con":true,"img":false}]}
{"op":"mcm","clk":"11539126210","pt":1719475682883,"mc":[{"id":"1.230180135","marketDefinition":{"bspMarket":true,"turnInPlayEnabled":false,"persistenceEnabled":false,"marketBaseRate":5.0,"eventId":"33376437","eventTypeId":"4339","numberOfWinners":2,"bettingType":"ODDS","marketType":"PLACE","marketTime":"2024-06-27T16:54:00.000Z","suspendTime":"2024-06-27T16:54:00.000Z","bspReconciled":false,"complete":true,"inPlay":false,"crossMatching":false,"runnersVoidable":false,"numberOfActiveRunners":5,"betDelay":0,"status":"OPEN","runners":[{"status":"ACTIVE","sortPriority":1,"id":4065261,"name":"2. Manx Storm"},{"status":"ACTIVE","sortPriority":2,"id":69176457,"name":"3. Franco Eve"},{"status":"ACTIVE","sortPriority":3,"id":41401491,"name":"4. Connors Bullet"},{"status":"ACTIVE","sortPriority":4,"id":65040144,"name":"5. Diegos Talavara"},{"status":"ACTIVE","sortPriority":5,"id":52032624,"name":"6. Limekiln Chic"}],"regulators":["MR_INT"],"venue":"Towcester","countryCode":"GB","discountAllowed":true,"timezone":"Europe/London","openDate":"2024-06-27T13:33:00.000Z","version":5994767139,"name":"To Be Placed","eventName":"Towcester 27th Jun"},"rc":[{"atb":[[1.01,51.84],[1.07,2.48]],"id":41401491},{"atl":[[75,0.48],[1000,0.23]],"id":41401491},{"spn":38.03,"spf":"NaN","id":41401491},{"atb":[[1.02,25.92],[1.07,2.48]],"id":52032624},{"atl":[[75,0.48],[990,0.23]],"id":52032624},{"spn":38.03,"spf":"NaN","id":52032624},{"atb":[[1.01,51.84],[1.07,2.48]],"id":4065261},{"atl":[[75,0.48],[1000,0.23]],"id":4065261},{"spn":38.03,"spf":"NaN","id":4065261},{"atb":[[1.02,25.92],[1.07,2.48]],"id":69176457},{"atl":[[75,0.48],[1000,0.23]],"id":69176457},{"spn":38.03,"spf":"NaN","id":69176457},{"atb":[[1.02,25.92],[1.07,2.48]],"id":65040144},{"atl":[[75,0.48],[1000,0.23]],"id":65040144},{"spn":38.03,"spf":"NaN","id":65040144}],"con":true,"img":true}]}
{"op":"mcm","clk":"11539442377","pt":1719481082823,"mc":[{"id":"1.230180135","marketDefinition":{"bspMarket":true,"turnInPlayEnabled":false,"persistenceEnabled":false,"marketBaseRate":5.0,"eventId":"33376437","eventTypeId":"4339","numberOfWinners":2,"bettingType":"ODDS","marketType":"PLACE","marketTime":"2024-06-27T16:54:00.000Z","suspendTime":"2024-06-27T16:54:00.000Z","bspReconciled":false,"complete":true,"inPlay":false,"crossMatching":false,"runnersVoidable":false,"numberOfActiveRunners":5,"betDelay":0,"status":"OPEN","runners":[{"status":"ACTIVE","sortPriority":1,"id":4065261,"name":"2. Manx Storm"},{"status":"ACTIVE","sortPriority":2,"id":69176457,"name":"3. Franco Eve"},{"status":"ACTIVE","sortPriority":3,"id":41401491,"name":"4. Connors Bullet"},{"status":"ACTIVE","sortPriority":4,"id":65040144,"name":"5. Diegos Talavara"},{"status":"ACTIVE","sortPriority":5,"id":52032624,"name":"6. Limekiln Chic"}],"regulators":["MR_INT"],"venue":"Towcester","countryCode":"GB","discountAllowed":true,"timezone":"Europe/London","openDate":"2024-06-27T13:33:00.000Z","version":5994767139,"name":"To Be Placed","eventName":"Towcester 27th Jun"},"rc":[{"atb":[[1.01,51.83],[1.07,2.48]],"id":41401491},{"atl":[[75,0.48],[1000,0.23]],"id":41401491},{"spn":38.03,"spf":"NaN","id":41401491},{"atb":[[1.02,25.91],[1.07,2.48]],"id":52032624},{"atl":[[75,0.48],[990,0.23]],"id":52032624},{"spn":38.03,"spf":"NaN","id":52032624},{"atb":[[1.01,51.83],[1.07,2.48]],"id":4065261},{"atl":[[75,0.48],[1000,0.23]],"id":4065261},{"spn":38.03,"spf":"NaN","id":4065261},{"atb":[[1.02,25.91],[1.07,2.48]],"id":69176457},{"atl":[[75,0.48],[1000,0.23]],"id":69176457},{"spn":38.03,"spf":"NaN","id":69176457},{"atb":[[1.02,25.91],[1.07,2.48]],"id":65040144},{"atl":[[75,0.48],[1000,0.23]],"id":65040144},{"spn":38.03,"spf":"NaN","id":65040144}],"con":true,"img":true}]}
{"op":"mcm","clk":"11539793321","pt":1719486286459,"mc":[{"id":"1.230180135","rc":[{"atb":[[1.01,51.83]],"id":41401491},{"atl":[[1000,0.23]],"id":41401491},{"spn":38.03,"spf":"NaN","id":41401491},{"atb":[[1.02,25.91]],"id":52032624},{"atl":[[990,0.23]],"id":52032624},{"spn":38.03,"spf":"NaN","id":52032624},{"atb":[[1.01,51.83]],"id":4065261},{"atl":[[1000,0.23]],"id":4065261},{"spn":38.03,"spf":"NaN","id":4065261},{"atb":[[1.02,25.91]],"id":69176457},{"atl":[[1000,0.23]],"id":69176457},{"spn":38.03,"spf":"NaN","id":69176457},{"atb":[[1.02,25.91]],"id":65040144},{"atl":[[1000,0.23]],"id":65040144},{"spb":[[1000,71.59]],"id":65040144},{"spn":139.72,"spf":"Infinity","id":65040144}],"con":true,"img":false}]}
{"op":"mcm","clk":"11540251897","pt":1719491882799,"mc":[{"id":"1.230180135","marketDefinition":{"bspMarket":true,"turnInPlayEnabled":false,"persistenceEnabled":false,"marketBaseRate":5.0,"eventId":"33376437","eventTypeId":"4339","numberOfWinners":2,"bettingType":"ODDS","marketType":"PLACE","marketTime":"2024-06-27T16:54:00.000Z","suspendTime":"2024-06-27T16:54:00.000Z","bspReconciled":false,"complete":true,"inPlay":false,"crossMatching":false,"runnersVoidable":false,"numberOfActiveRunners":5,"betDelay":0,"status":"OPEN","runners":[{"status":"ACTIVE","sortPriority":1,"id":4065261,"name":"2. Manx Storm"},{"status":"ACTIVE","sortPriority":2,"id":69176457,"name":"3. Franco Eve"},{"status":"ACTIVE","sortPriority":3,"id":41401491,"name":"4. Connors Bullet"},{"status":"ACTIVE","sortPriority":4,"id":65040144,"name":"5. Diegos Talavara"},{"status":"ACTIVE","sortPriority":5,"id":52032624,"name":"6. Limekiln Chic"}],"regulators":["MR_INT"],"venue":"Towcester","countryCode":"GB","discountAllowed":true,"timezone":"Europe/London","openDate":"2024-06-27T13:33:00.000Z","version":5994767139,"name":"To Be Placed","eventName":"Towcester 27th Jun"},"rc":[{"atb":[[1.01,51.83],[1.07,2.48]],"id":41401491},{"atl":[[75,0.48],[1000,0.23]],"id":41401491},{"spn":38.03,"spf":"NaN","id":41401491},{"atb":[[1.02,25.91],[1.07,2.48]],"id":52032624},{"atl":[[75,0.48],[990,0.23]],"id":52032624},{"spn":38.03,"spf":"NaN","id":52032624},{"atb":[[1.01,51.83],[1.07,2.48]],"id":4065261},{"atl":[[75,0.48],[1000,0.23]],"id":4065261},{"spn":38.03,"spf":"NaN","id":4065261},{"atb":[[1.02,25.91],[1.07,2.48]],"id":69176457},{"atl":[[75,0.48],[1000,0.23]],"id":69176457},{"spn":38.03,"spf":"NaN","id":69176457},{"atb":[[1.02,25.91],[1.07,2.48]],"id":65040144},{"atl":[[75,0.48],[1000,0.23]],"id":65040144},{"spb":[[1000,71.71]],"id":65040144},{"spn":139.91,"spf":"Infinity","id":65040144}],"con":true,"img":true}]}
{"op":"mcm","clk":"11540687359","pt":1719497282744,"mc":[{"id":"1.230180135","marketDefinition":{"bspMarket":true,"turnInPlayEnabled":false,"persistenceEnabled":false,"marketBaseRate":5.0,"eventId":"33376437","eventTypeId":"4339","numberOfWinners":2,"bettingType":"ODDS","marketType":"PLACE","marketTime":"2024-06-27T16:54:00.000Z","suspendTime":"2024-06-27T16:54:00.000Z","bspReconciled":false,"complete":true,"inPlay":false,"crossMatching":false,"runnersVoidable":false,"numberOfActiveRunners":5,"betDelay":0,"status":"OPEN","runners":[{"status":"ACTIVE","sortPriority":1,"id":4065261,"name":"2. Manx Storm"},{"status":"ACTIVE","sortPriority":2,"id":69176457,"name":"3. Franco Eve"},{"status":"ACTIVE","sortPriority":3,"id":41401491,"name":"4. Connors Bullet"},{"status":"ACTIVE","sortPriority":4,"id":65040144,"name":"5. Diegos Talavara"},{"status":"ACTIVE","sortPriority":5,"id":52032624,"name":"6. Limekiln Chic"}],"regulators":["MR_INT"],"venue":"Towcester","countryCode":"GB","discountAllowed":true,"timezone":"Europe/London","openDate":"2024-06-27T13:33:00.000Z","version":5994767139,"name":"To Be Placed","eventName":"Towcester 27th Jun"},"rc":[{"atb":[[1.01,51.87],[1.07,2.48]],"id":41401491},{"atl":[[75,0.48],[1000,0.23]],"id":41401491},{"spn":38.03,"spf":"NaN","id":41401491},{"atb":[[1.02,25.93],[1.07,2.48]],"id":52032624},{"atl":[[75,0.48],[990,0.23]],"id":52032624},{"spn":38.03,"spf":"NaN","id":52032624},{"atb":[[1.01,51.87],[1.07,2.48]],"id":4065261},{"atl":[[75,0.48],[1000,0.23]],"id":4065261},{"spn":38.03,"spf":"NaN","id":4065261},{"atb":[[1.02,25.93],[1.07,2.48]],"id":69176457},{"atl":[[75,0.48],[1000,0.23]],"id":69176457},{"spn":38.03,"spf":"NaN","id":69176457},{"atb":[[1.02,25.93],[1.07,2.48]],"id":65040144},{"atl":[[75,0.48],[1000,0.23]],"id":65040144},{"spb":[[1000,71.63]],"id":65040144},{"spn":139.78,"spf":"Infinity","id":65040144}],"con":true,"img":true}]}
{"op":"mcm","clk":"11540934447","pt":1719500157212,"mc":[{"id":"1.230180135","rc":[{"atb":[[1.01,51.87]],"id":41401491},{"atl":[[990,0.88],[1000,0.23]],"id":41401491},{"atb":[[1.02,25.93]],"id":52032624},{"atl":[[990,0.23],[960,2.1]],"id":52032624},{"atb":[[1.01,51.87]],"id":4065261},{"atl":[[980,0.85],[1000,0.23]],"id":4065261},{"atb":[[1.02,25.93]],"id":69176457},{"atl":[[980,0.9],[1000,0.23]],"id":69176457},{"atb":[[1.02,25.93]],"id":65040144},{"atl":[[960,2.12],[1000,0.23]],"id":65040144},{"spb":[[1000,71.63]],"id":65040144},{"spn":139.37,"spf":"Infinity","id":65040144}],"con":true,"img":false}]}
{"op":"mcm","clk":"11541142966","pt":1719502682762,"mc":[{"id":"1.230180135","marketDefinition":{"bspMarket":true,"turnInPlayEnabled":false,"persistenceEnabled":false,"marketBaseRate":5.0,"eventId":"33376437","eventTypeId":"4339","numberOfWinners":2,"bettingType":"ODDS","marketType":"PLACE","marketTime":"2024-06-27T16:54:00.000Z","suspendTime":"2024-06-27T16:54:00.000Z","bspReconciled":false,"complete":true,"inPlay":false,"crossMatching":false,"runnersVoidable":false,"numberOfActiveRunners":5,"betDelay":0,"status":"OPEN","runners":[{"status":"ACTIVE","sortPriority":1,"id":4065261,"name":"2. Manx Storm"},{"status":"ACTIVE","sortPriority":2,"id":69176457,"name":"3. Franco Eve"},{"status":"ACTIVE","sortPriority":3,"id":41401491,"name":"4. Connors Bullet"},{"status":"ACTIVE","sortPriority":4,"id":65040144,"name":"5. Diegos Talavara"},{"status":"ACTIVE","sortPriority":5,"id":52032624,"name":"6. Limekiln Chic"}],"regulators":["MR_INT"],"venue":"Towcester","countryCode":"GB","discountAllowed":true,"timezone":"Europe/London","openDate":"2024-06-27T13:33:00.000Z","version":5994767139,"name":"To Be Placed","eventName":"Towcester 27th Jun"},"rc":[{"atb":[[1.01,51.88],[1.07,2.48]],"id":41401491},{"atl":[[75,0.48],[990,0.88],[1000,0.23]],"id":41401491},{"spn":38.03,"spf":"NaN","id":41401491},{"atb":[[1.02,25.94],[1.07,2.48]],"id":52032624},{"atl":[[75,0.48],[960,2.1],[990,0.23]],"id":52032624},{"spn":38.03,"spf":"NaN","id":52032624},{"atb":[[1.01,51.88],[1.07,2.48]],"id":4065261},{"atl":[[75,0.48],[980,0.85],[1000,0.23]],"id":4065261},{"spn":38.03,"spf":"NaN","id":4065261},{"atb":[[1.02,25.94],[1.07,2.48]],"id":69176457},{"atl":[[75,0.48],[980,0.9],[1000,0.23]],"id":69176457},{"spn":38.03,"spf":"NaN","id":69176457},{"atb":[[1.02,25.94],[1.07,2.48]],"id":65040144},{"atl":[[75,0.48],[960,2.12],[1000,0.23]],"id":65040144},{"spb":[[1000,71.51]],"id":65040144},{"spn":139.18,"spf":"Infinity","id":65040144}],"con":true,"img":true}]}
{"op":"mcm","clk":"11541413484","pt":1719505485892,"mc":[{"id":"1.230180135","rc":[{"atb":[[1.01,51.86]],"id":41401491},{"atl":[[990,0.88]],"id":41401491},{"atb":[[1.02,25.93],[1.09,43.91]],"id":52032624},{"atl":[[960,2.1]],"id":52032624},{"spn":38.04,"spf":"NaN","id":52032624},{"atb":[[1.01,51.86]],"id":4065261},{"atl":[[980,0.85]],"id":4065261},{"atb":[[1.02,25.93]],"id":69176457},{"atl":[[980,0.9]],"id":69176457},{"atb":[[1.02,25.93]],"id":65040144},{"atl":[[960,2.12]],"id":65040144},{"spb":[[1000,71.47]],"id":65040144},{"spn":139.11,"spf":"Infinity","id":65040144}],"con":true,"img":false}]}
{"op":"mcm","clk":"11541414827","pt":1719505502193,"mc":[{"id":"1.230180135","rc":[{"atb":[[1.04,1]],"id":41401491},{"atb":[[1.04,1]],"id":52032624},{"atb":[[1.04,1]],"id":4065261},{"atb":[[1.04,1]],"id":69176457},{"atb":[[1.04,1]],"id":65040144}],"con":true,"img":false}]}
{"op":"mcm","clk":"11541414853","pt":1719505502500,"mc":[{"id":"1.230180135","rc":[{"atb":[[1.04,0.25]],"id":41401491},{"atb":[[1.04,0.25]],"id":52032624},{"atb":[[1.04,0.25]],"id":4065261},{"atb":[[1.04,0.25]],"id":69176457},{"atb":[[1.04,0.25]],"id":65040144}],"con":true,"img":false}]}
{"op":"mcm","clk":"11541414879","pt":1719505502713,"mc":[{"id":"1.230180135","rc":[{"atb":[[1.04,0]],"id":41401491},{"atb":[[1.04,0]],"id":52032624},{"atb":[[1.04,0]],"id":4065261},{"atb":[[1.04,0]],"id":69176457},{"atb":[[1.04,0]],"id":65040144}],"con":true,"img":false}]}
{"op":"mcm","clk":"11541414891","pt":1719505502820,"mc":[{"id":"1.230180135","rc":[{"atb":[[1.2,0.25]],"id":41401491},{"atb":[[1.2,0.25]],"id":52032624},{"atb":[[1.2,0.25]],"id":4065261},{"atb":[[1.2,0.25]],"id":69176457},{"atb":[[1.2,0.25]],"id":65040144}],"con":true,"img":false}]}
{"op":"mcm","clk":"11541415787","pt":1719505512463,"mc":[{"id":"1.230180135","marketDefinition":{"bspMarket":true,"turnInPlayEnabled":false,"persistenceEnabled":false,"marketBaseRate":5.0,"eventId":"33376437","eventTypeId":"4339","numberOfWinners":2,"bettingType":"ODDS","marketType":"PLACE","marketTime":"2024-06-27T16:54:00.000Z","suspendTime":"2024-06-27T16:54:00.000Z","bspReconciled":false,"complete":true,"inPlay":false,"crossMatching":true,"runnersVoidable":false,"numberOfActiveRunners":5,"betDelay":0,"status":"OPEN","runners":[{"status":"ACTIVE","sortPriority":1,"id":4065261,"name":"2. Manx Storm"},{"status":"ACTIVE","sortPriority":2,"id":69176457,"name":"3. Franco Eve"},{"status":"ACTIVE","sortPriority":3,"id":41401491,"name":"4. Connors Bullet"},{"status":"ACTIVE","sortPriority":4,"id":65040144,"name":"5. Diegos Talavara"},{"status":"ACTIVE","sortPriority":5,"id":52032624,"name":"6. Limekiln Chic"}],"regulators":["MR_INT"],"venue":"Towcester","countryCode":"GB","discountAllowed":true,"timezone":"Europe/London","openDate":"2024-06-27T13:33:00.000Z","version":5994767139,"name":"To Be Placed","eventName":"Towcester 27th Jun"},"rc":[],"con":true,"img":false}]}
{"op":"mcm","clk":"11541437701","pt":1719505750417,"mc":[{"id":"1.230180135","rc":[{"spn":38.1,"spf":"NaN","id":41401491},{"atb":[[1.11,38.46]],"id":52032624},{"spn":38.1,"spf":"NaN","id":52032624},{"spn":38.1,"spf":"NaN","id":4065261},{"spn":38.1,"spf":"NaN","id":69176457}],"con":true,"img":false}]}
{"op":"mcm","clk":"11541439244","pt":1719505766641,"mc":[{"id":"1.230180135","rc":[{"atb":[[1.09,0]],"id":52032624}],"con":true,"img":false}]}
{"op":"mcm","clk":"11541439263","pt":1719505766832,"mc":[{"id":"1.230180135","rc":[{"atb":[[1.13,30.39]],"id":52032624}],"con":true,"img":false}]}
{"op":"mcm","clk":"11541440938","pt":1719505785670,"mc":[{"id":"1.230180135","rc":[{"atb":[[1.11,0]],"id":52032624}],"con":true,"img":false}]}
{"op":"mcm","clk":"11541440964","pt":1719505785979,"mc":[{"id":"1.230180135","rc":[{"atb":[[1.15,28.2]],"id":52032624}],"con":true,"img":false}]}
{"op":"mcm","clk":"11541442560","pt":1719505802903,"mc":[{"id":"1.230180135","rc":[{"atb":[[1.13,0]],"id":52032624}],"con":true,"img":false}]}
{"op":"mcm","clk":"11541442577","pt":1719505803110,"mc":[{"id":"1.230180135","rc":[{"atb":[[1.17,23.24]],"id":52032624}],"con":true,"img":false}]}
{"op":"mcm","clk":"11541444363","pt":1719505820536,"mc":[{"id":"1.230180135","rc":[{"atb":[[1.15,0]],"id":52032624}],"con":true,"img":false}]}
{"op":"mcm","clk":"11541444458","pt":1719505821419,"mc":[{"id":"1.230180135","rc":[{"atb":[[1.19,22.27]],"id":52032624}],"con":true,"img":false}]}
{"op":"mcm","clk":"11541446309","pt":1719505840736,"mc":[{"id":"1.230180135","rc":[{"atb":[[1.17,0]],"id":52032624}],"con":true,"img":false}]}
{"op":"mcm","clk":"11541446329","pt":1719505840946,"mc":[{"id":"1.230180135","rc":[{"atb":[[1.21,18.81]],"id":52032624}],"con":true,"img":false}]}
{"op":"mcm","clk":"11541447451","pt":1719505851970,"mc":[{"id":"1.230180135","rc":[{"atb":[[1.19,0]],"id":52032624}],"con":true,"img":false}]}
{"op":"mcm","clk":"11541447514","pt":1719505852546,"mc":[{"id":"1.230180135","rc":[{"atb":[[1.23,18.39]],"id":52032624}],"con":true,"img":false}]}
{"op":"mcm","clk":"11541448204","pt":1719505858867,"mc":[{"id":"1.230180135","rc":[{"atb":[[1.21,0]],"id":52032624}],"con":true,"img":false}]}
{"op":"mcm","clk":"11541448227","pt":1719505859072,"mc":[{"id":"1.230180135","rc":[{"atb":[[1.25,15.8]],"id":52032624}],"con":true,"img":false}]}
{"op":"mcm","clk":"11541451017","pt":1719505888525,"mc":[{"id":"1.230180135","rc":[{"atb":[[1.23,0]],"id":52032624},{"spn":38.12,"spf":"NaN","id":52032624}],"con":true,"img":false}]}
{"op":"mcm","clk":"11541451082","pt":1719505889105,"mc":[{"id":"1.230180135","rc":[{"atb":[[1.27,15.67]],"id":52032624}],"con":true,"img":false}]}
{"op":"mcm","clk":"11541452214","pt":1719505902502,"mc":[{"id":"1.230180135","rc":[{"atb":[[1.25,0]],"id":52032624}],"con":true,"img":false}]}
{"op":"mcm","clk":"11541452248","pt":1719505902920,"mc":[{"id":"1.230180135","rc":[{"atb":[[1.29,13.62]],"id":52032624}],"con":true,"img":false}]}
{"op":"mcm","clk":"11541453956","pt":1719505921557,"mc":[{"id":"1.230180135","rc":[{"atb":[[1.27,0]],"id":52032624}],"con":true,"img":false}]}
{"op":"mcm","clk":"11541454004","pt":1719505922140,"mc":[{"id":"1.230180135","rc":[{"atb":[[1.31,13.65]],"id":52032624}],"con":true,"img":false}]}
{"op":"mcm","clk":"11541455915","pt":1719505941471,"mc":[{"id":"1.230180135","rc":[{"atb":[[1.29,0]],"id":52032624}],"con":true,"img":false}]}
{"op":"mcm","clk":"11541455940","pt":1719505941639,"mc":[{"id":"1.230180135","rc":[{"atb":[[1.33,11.97]],"id":52032624}],"con":true,"img":false}]}
{"op":"mcm","clk":"11541457140","pt":1719505954270,"mc":[{"id":"1.230180135","rc":[{"atb":[[1.31,0]],"id":52032624},{"spn":38.16,"spf":"NaN","id":52032624}],"con":true,"img":false}]}
{"op":"mcm","clk":"11541457191","pt":1719505954872,"mc":[{"id":"1.230180135","rc":[{"atb":[[1.35,12.09]],"id":52032624}],"con":true,"img":false}]}
{"op":"mcm","clk":"11541457765","pt":1719505960874,"mc":[{"id":"1.230180135","rc":[{"atb":[[1.33,0]],"id":52032624}],"con":true,"img":false}]}
{"op":"mcm","clk":"11541457804","pt":1719505961288,"mc":[{"id":"1.230180135","rc":[{"atb":[[1.37,10.67]],"id":52032624}],"con":true,"img":false}]}
{"op":"mcm","clk":"11541460831","pt":1719505992506,"mc":[{"id":"1.230180135","rc":[{"atb":[[1.35,0]],"id":52032624}],"con":true,"img":false}]}
{"op":"mcm","clk":"11541460954","pt":1719505993489,"mc":[{"id":"1.230180135","rc":[{"atb":[[1.39,10.84]],"id":52032624}],"con":true,"img":false}]}
{"op":"mcm","clk":"11541466410","pt":1719506049433,"mc":[{"id":"1.230180135","rc":[{"atb":[[1.37,0]],"id":52032624},{"spn":38.19,"spf":"NaN","id":52032624}],"con":true,"img":false}]}
{"op":"mcm","clk":"11541466432","pt":1719506049644,"mc":[{"id":"1.230180135","rc":[{"atb":[[1.41,9.64]],"id":52032624}],"con":true,"img":false}]}
{"op":"mcm","clk":"11541467595","pt":1719506060474,"mc":[{"id":"1.230180135","rc":[{"atb":[[1.39,0]],"id":52032624}],"con":true,"img":false}]}
{"op":"mcm","clk":"11541467624","pt":1719506060727,"mc":[{"id":"1.230180135","rc":[{"atb":[[1.43,9.84]],"id":52032624}],"con":true,"img":false}]}
{"op":"mcm","clk":"11541468394","pt":1719506068244,"mc":[{"id":"1.230180135","rc":[{"atb":[[1.41,0]],"id":52032624}],"con":true,"img":false}]}
{"op":"mcm","clk":"11541468417","pt":1719506068445,"mc":[{"id":"1.230180135","rc":[{"atb":[[1.45,8.78]],"id":52032624}],"con":true,"img":false}]}
{"op":"mcm","clk":"11541470970","pt":1719506094002,"mc":[{"id":"1.230180135","rc":[{"atb":[[1.43,0]],"id":52032624}],"con":true,"img":false}]}
{"op":"mcm","clk":"11541470998","pt":1719506094276,"mc":[{"id":"1.230180135","rc":[{"atb":[[1.47,9]],"id":52032624}],"con":true,"img":false}]}
{"op":"mcm","clk":"11541481399","pt":1719506195573,"mc":[{"id":"1.230180135","rc":[{"atb":[[1.45,0]],"id":52032624},{"spn":38.23,"spf":"NaN","id":52032624}],"con":true,"img":false}]}
{"op":"mcm","clk":"11541481431","pt":1719506195885,"mc":[{"id":"1.230180135","rc":[{"atb":[[1.49,8.06]],"id":52032624}],"con":true,"img":false}]}
{"op":"mcm","clk":"11541481655","pt":1719506197908,"mc":[{"id":"1.230180135","rc":[{"atb":[[1.47,0]],"id":52032624}],"con":true,"img":false}]}
{"op":"mcm","clk":"11541481742","pt":1719506198594,"mc":[{"id":"1.230180135","rc":[{"atb":[[1.51,8.29]],"id":52032624}],"con":true,"img":false}]}
{"op":"mcm","clk":"11541483303","pt":1719506212808,"mc":[{"id":"1.230180135","rc":[{"atb":[[1.49,0]],"id":52032624}],"con":true,"img":false}]}
{"op":"mcm","clk":"11541483330","pt":1719506213011,"mc":[{"id":"1.230180135","rc":[{"atb":[[1.53,7.45]],"id":52032624}],"con":true,"img":false}]}
{"op":"mcm","clk":"11541485146","pt":1719506229843,"mc":[{"id":"1.230180135","rc":[{"atb":[[1.51,0]],"id":52032624}],"con":true,"img":false}]}
{"op":"mcm","clk":"11541485186","pt":1719506230109,"mc":[{"id":"1.230180135","rc":[{"atb":[[1.55,7.69]],"id":52032624}],"con":true,"img":false}]}
{"op":"mcm","clk":"11541485337","pt":1719506231296,"mc":[{"id":"1.230180135","rc":[{"atb":[[1.53,0]],"id":52032624}],"con":true,"img":false}]}
{"op":"mcm","clk":"11541485358","pt":1719506231503,"mc":[{"id":"1.230180135","rc":[{"atb":[[1.57,6.93]],"id":52032624}],"con":true,"img":false}]}
{"op":"mcm","clk":"11541488461","pt":1719506260859,"mc":[{"id":"1.230180135","rc":[{"atb":[[1.55,0]],"id":52032624},{"spn":38.28,"spf":"NaN","id":52032624}],"con":true,"img":false}]}
{"op":"mcm","clk":"11541488497","pt":1719506261121,"mc":[{"id":"1.230180135","rc":[{"atb":[[1.59,7.16]],"id":52032624}],"con":true,"img":false}]}
{"op":"mcm","clk":"11541490531","pt":1719506281749,"mc":[{"id":"1.230180135","rc":[{"atb":[[1.57,0]],"id":52032624}],"con":true,"img":false}]}
{"op":"mcm","clk":"11541490551","pt":1719506281970,"mc":[{"id":"1.230180135","rc":[{"atb":[[1.61,6.48]],"id":52032624}],"con":true,"img":false}]}
{"op":"mcm","clk":"11541491858","pt":1719506292797,"mc":[{"id":"1.230180135","rc":[{"atb":[[1.59,0]],"id":52032624}],"con":true,"img":false}]}
{"op":"mcm","clk":"11541491897","pt":1719506293070,"mc":[{"id":"1.230180135","rc":[{"atb":[[1.63,6.71]],"id":52032624}],"con":true,"img":false}]}
{"op":"mcm","clk":"11541493002","pt":1719506302886,"mc":[{"id":"1.230180135","rc":[{"atb":[[1.61,0]],"id":52032624}],"con":true,"img":false}]}
{"op":"mcm","clk":"11541493032","pt":1719506303100,"mc":[{"id":"1.230180135","rc":[{"atb":[[1.65,6.07]],"id":52032624}],"con":true,"img":false}]}
{"op":"mcm","clk":"11541495524","pt":1719506325725,"mc":[{"id":"1.230180135","rc":[{"atb":[[1.63,0]],"id":52032624},{"spn":38.32,"spf":"NaN","id":52032624}],"con":true,"img":false}]}
{"op":"mcm","clk":"11541495550","pt":1719506326032,"mc":[{"id":"1.230180135","rc":[{"atb":[[1.67,6.31]],"id":52032624}],"con":true,"img":false}]}
{"op":"mcm","clk":"11541497055","pt":1719506340259,"mc":[{"id":"1.230180135","rc":[{"atb":[[1.85,6.08],[1.65,7.07]],"id":52032624},{"atl":[[300,2],[85,1]],"id":52032624},{"atb":[[1.18,1]],"id":4065261},{"atl":[[36,2],[85,1]],"id":4065261},{"atb":[[1.18,1]],"id":69176457},{"atl":[[19,2],[85,1]],"id":69176457},{"atb":[[1.18,1]],"id":65040144},{"atl":[[36,2],[85,1]],"id":65040144}],"con":true,"img":false}]}
{"op":"mcm","clk":"11541497066","pt":1719506340353,"mc":[{"id":"1.230180135","rc":[{"atl":[[12.5,2]],"id":41401491}],"con":true,"img":false}]}
{"op":"mcm","clk":"11541497081","pt":1719506340470,"mc":[{"id":"1.230180135","rc":[{"atb":[[1.83,1],[1.65,6.07]],"id":52032624},{"atl":[[40,1],[85,0]],"id":4065261},{"atl":[[20,1],[85,0]],"id":69176457},{"atl":[[40,1],[85,0]],"id":65040144}],"con":true,"img":false}]}
{"op":"mcm","clk":"11541499030","pt":1719506358504,"mc":[{"id":"1.230180135","rc":[{"atb":[[1.67,0]],"id":52032624}],"con":true,"img":false}]}
{"op":"mcm","clk":"11541499072","pt":1719506358775,"mc":[{"id":"1.230180135","rc":[{"atb":[[1.87,4.86]],"id":52032624}],"con":true,"img":false}]}
{"op":"mcm","clk":"11541499083","pt":1719506358874,"mc":[{"id":"1.230180135","rc":[{"atb":[[1.85,0],[1.88,4.87]],"id":52032624}],"con":true,"img":false}]}
{"op":"mcm","clk":"11541499748","pt":1719506364696,"mc":[{"id":"1.230180135","rc":[{"atb":[[1.83,0],[1.86,1]],"id":52032624}],"con":true,"img":false}]}
{"op":"mcm","clk":"11541502324","pt":1719506386802,"mc":[{"id":"1.230180135","rc":[{"atb":[[1.16,1]],"id":41401491},{"atl":[[13.5,1]],"id":41401491},{"spn":6.85,"spf":"NaN","id":41401491},{"spn":38.44,"spf":"NaN","id":52032624},{"spn":18.6,"spf":"NaN","id":4065261},{"spn":10.1,"spf":"NaN","id":69176457},{"spn":36.07,"spf":"Infinity","id":65040144}],"con":true,"img":false}]}
{"op":"mcm","clk":"11541502605","pt":1719506389285,"mc":[{"id":"1.230180135","rc":[{"atb":[[1.87,0]],"id":52032624}],"con":true,"img":false}]}
{"op":"mcm","clk":"11541502628","pt":1719506389480,"mc":[{"id":"1.230180135","rc":[{"atb":[[1.85,5.87]],"id":52032624}],"con":true,"img":false}]}
{"op":"mcm","clk":"11541502637","pt":1719506389575,"mc":[{"id":"1.230180135","rc":[{"atb":[[1.88,0],[1.9,4.7]],"id":52032624}],"con":true,"img":false}]}
{"op":"mcm","clk":"11541503341","pt":1719506396038,"mc":[{"id":"1.230180135","rc":[{"atb":[[1.88,1],[1.86,0]],"id":52032624}],"con":true,"img":false}]}
{"op":"mcm","clk":"11541503685","pt":1719506399127,"mc":[{"id":"1.230180135","rc":[{"atb":[[1.85,0],[1.91,4.71]],"id":52032624}],"con":true,"img":false}]}
{"op":"mcm","clk":"11541504232","pt":1719506404408,"mc":[{"id":"1.230180135","rc":[{"atb":[[1.89,1],[1.88,0]],"id":52032624}],"con":true,"img":false}]}
{"op":"mcm","clk":"11541506022","pt":1719506421168,"mc":[{"id":"1.230180135","rc":[{"atb":[[1.9,0]],"id":52032624}],"con":true,"img":false}]}
{"op":"mcm","clk":"11541506032","pt":1719506421269,"mc":[{"id":"1.230180135","rc":[{"atb":[[1.85,5.71],[1.91,0]],"id":52032624}],"con":true,"img":false}]}
{"op":"mcm","clk":"11541506095","pt":1719506421949,"mc":[{"id":"1.230180135","rc":[{"atb":[[1.89,0],[1.93,4.55],[1.87,1]],"id":52032624}],"con":true,"img":false}]}
{"op":"mcm","clk":"11541506117","pt":1719506422145,"mc":[{"id":"1.230180135","rc":[{"atb":[[1.85,0],[1.94,4.55]],"id":52032624}],"con":true,"img":false}]}
{"op":"mcm","clk":"11541506133","pt":1719506422266,"mc":[{"id":"1.230180135","rc":[{"atb":[[1.91,1],[1.87,0]],"id":52032624}],"con":true,"img":false}]}
{"op":"mcm","clk":"11541506551","pt":1719506426240,"mc":[{"id":"1.230180135","rc":[{"atb":[[1.92,1],[1.91,0]],"id":52032624}],"con":true,"img":false}]}
{"op":"mcm","clk":"11541508330","pt":1719506445859,"mc":[{"id":"1.230180135","rc":[{"atl":[[12,0.84]],"id":41401491},{"atl":[[34,0.84]],"id":4065261},{"atl":[[18.5,0.84]],"id":69176457},{"atl":[[34,0.84]],"id":65040144}],"con":true,"img":false}]}
{"op":"mcm","clk":"11541508340","pt":1719506445962,"mc":[{"id":"1.230180135","rc":[{"atl":[[38,1],[40,0]],"id":4065261},{"atl":[[20,0]],"id":69176457},{"atl":[[38,1]],"id":65040144}],"con":true,"img":false}]}
{"op":"mcm","clk":"11541508350","pt":1719506446065,"mc":[{"id":"1.230180135","rc":[{"atl":[[19.5,1]],"id":69176457},{"atl":[[40,0]],"id":65040144}],"con":true,"img":false}]}
{"op":"mcm","clk":"11541508391","pt":1719506446581,"mc":[{"id":"1.230180135","rc":[{"atl":[[13,1],[13.5,0]],"id":41401491}],"con":true,"img":false}]}
{"op":"mcm","clk":"11541509304","pt":1719506456627,"mc":[{"id":"1.230180135","rc":[{"spn":6.6,"spf":"NaN","id":41401491},{"atb":[[1.93,0]],"id":52032624},{"spn":38.47,"spf":"NaN","id":52032624},{"spn":17.6,"spf":"NaN","id":4065261},{"spn":9.85,"spf":"NaN","id":69176457},{"spn":35.19,"spf":"Infinity","id":65040144}],"con":true,"img":false}]}
{"op":"mcm","clk":"11541509325","pt":1719506456836,"mc":[{"id":"1.230180135","rc":[{"atb":[[1.85,5.55]],"id":52032624}],"con":true,"img":false}]}
{"op":"mcm","clk":"11541509331","pt":1719506456885,"mc":[{"id":"1.230180135","rc":[{"atb":[[1.94,0]],"id":52032624}],"con":true,"img":false}]}
{"op":"mcm","clk":"11541509744","pt":1719506460994,"mc":[{"id":"1.230180135","rc":[{"atb":[[1.92,0],[1.9,1]],"id":52032624}],"con":true,"img":false}]}
{"op":"mcm","clk":"11541509847","pt":1719506462021,"mc":[{"id":"1.230180135","rc":[{"atb":[[1.88,1],[1.9,0]],"id":52032624}],"con":true,"img":false}]}
{"op":"mcm","clk":"11541509888","pt":1719506462390,"mc":[{"id":"1.230180135","rc":[{"atb":[[1.88,0],[1.86,1]],"id":52032624}],"con":true,"img":false}]}
{"op":"mcm","clk":"11541509908","pt":1719506462606,"mc":[{"id":"1.230180135","rc":[{"atb":[[1.84,1]],"id":52032624}],"con":true,"img":false}]}
{"op":"mcm","clk":"11541509919","pt":1719506462712,"mc":[{"id":"1.230180135","rc":[{"atb":[[1.86,0]],"id":52032624}],"con":true,"img":false}]}
{"op":"mcm","clk":"11541509964","pt":1719506463121,"mc":[{"id":"1.230180135","rc":[{"atb":[[1.83,1],[1.84,0]],"id":52032624}],"con":true,"img":false}]}
{"op":"mcm","clk":"11541512538","pt":1719506488555,"mc":[{"id":"1.230180135","rc":[{"atb":[[1.87,4.86]],"id":52032624}],"con":true,"img":false}]}
{"op":"mcm","clk":"11541512546","pt":1719506488659,"mc":[{"id":"1.230180135","rc":[{"atb":[[1.85,0],[1.88,4.87]],"id":52032624}],"con":true,"img":false}]}
{"op":"mcm","clk":"11541513490","pt":1719506498549,"mc":[{"id":"1.230180135","rc":[{"atb":[[1.83,0],[1.86,1]],"id":52032624}],"con":true,"img":false}]}
{"op":"mcm","clk":"11541515421","pt":1719506519375,"mc":[{"id":"1.230180135","rc":[{"atb":[[1.87,0]],"id":52032624},{"spn":38.44,"spf":"NaN","id":52032624}],"con":true,"img":false}]}
{"op":"mcm","clk":"11541515430","pt":1719506519479,"mc":[{"id":"1.230180135","rc":[{"atb":[[1.85,5.87]],"id":52032624}],"con":true,"img":false}]}
{"op":"mcm","clk":"11541515440","pt":1719506519582,"mc":[{"id":"1.230180135","rc":[{"atb":[[1.88,0]],"id":52032624}],"con":true,"img":false}]}
{"op":"mcm","clk":"11541515449","pt":1719506519685,"mc":[{"id":"1.230180135","rc":[{"atb":[[1.9,4.7]],"id":52032624}],"con":true,"img":false}]}
{"op":"mcm","clk":"11541515553","pt":1719506520574,"mc":[{"id":"1.230180135","rc":[{"atb":[[1.88,1],[1.86,0]],"id":52032624}],"con":true,"img":false}]}
{"op":"mcm","clk":"11541516239","pt":1719506527800,"mc":[{"id":"1.230180135","rc":[{"atb":[[1.91,4.71]],"id":52032624}],"con":true,"img":false}]}
{"op":"mcm","clk":"11541516260","pt":1719506528004,"mc":[{"id":"1.230180135","rc":[{"atb":[[1.85,0]],"id":52032624}],"con":true,"img":false}]}
{"op":"mcm","clk":"11541516538","pt":1719506530605,"mc":[{"id":"1.230180135","rc":[{"atb":[[1.89,1],[1.88,0]],"id":52032624}],"con":true,"img":false}]}
{"op":"mcm","clk":"11541518854","pt":1719506553229,"mc":[{"id":"1.230180135","rc":[{"atb":[[1.9,0]],"id":52032624}],"con":true,"img":false}]}
{"op":"mcm","clk":"11541518864","pt":1719506553332,"mc":[{"id":"1.230180135","rc":[{"atb":[[1.85,5.71]],"id":52032624}],"con":true,"img":false}]}
{"op":"mcm","clk":"11541518874","pt":1719506553436,"mc":[{"id":"1.230180135","rc":[{"atb":[[1.91,0]],"id":52032624}],"con":true,"img":false}]}
{"op":"mcm","clk":"11541518886","pt":1719506553543,"mc":[{"id":"1.230180135","rc":[{"atb":[[1.93,4.55]],"id":52032624}],"con":true,"img":false}]}
{"op":"mcm","clk":"11541518896","pt":1719506553641,"mc":[{"id":"1.230180135","rc":[{"atb":[[1.94,4.55]],"id":52032624}],"con":true,"img":false}]}
{"op":"mcm","clk":"11541518905","pt":1719506553745,"mc":[{"id":"1.230180135","rc":[{"atb":[[1.85,0]],"id":52032624}],"con":true,"img":false}]}
{"op":"mcm","clk":"11541519721","pt":1719506562054,"mc":[{"id":"1.230180135","rc":[{"atb":[[1.92,1],[1.89,0]],"id":52032624}],"con":true,"img":false}]}
{"op":"mcm","clk":"11541527506","pt":1719506651711,"mc":[{"id":"1.230180135","rc":[{"atb":[[1.08,50]],"id":41401491},{"atb":[[1.08,50]],"id":52032624},{"spn":38.47,"spf":"NaN","id":52032624},{"atb":[[1.08,50]],"id":4065261},{"atb":[[1.08,50]],"id":69176457},{"atb":[[1.08,50]],"id":65040144}],"con":true,"img":false}]}
{"op":"mcm","clk":"11541530230","pt":1719506686911,"mc":[{"id":"1.230180135","rc":[{"atb":[[1.1,42.31]],"id":69176457}],"con":true,"img":false}]}
{"op":"mcm","clk":"11541533064","pt":1719506721372,"mc":[{"id":"1.230180135","rc":[{"atb":[[1.09,65.82]],"id":41401491}],"con":true,"img":false}]}
{"op":"mcm","clk":"11541533071","pt":1719506721477,"mc":[{"id":"1.230180135","rc":[{"atb":[[1.1,42.31]],"id":41401491}],"con":true,"img":false}]}
{"op":"mcm","clk":"11541538508","pt":1719506785856,"mc":[{"id":"1.230180135","rc":[{"atb":[[1.08,52.5]],"id":41401491},{"atb":[[1.07,6.23]],"id":52032624},{"atb":[[1.06,2.5]],"id":4065261},{"atb":[[1.07,4.98]],"id":69176457},{"atb":[[1.06,2.5]],"id":65040144}],"con":true,"img":false}]}
{"op":"mcm","clk":"11541538600","pt":1719506786938,"mc":[{"id":"1.230180135","rc":[{"atb":[[1.09,65.82]],"id":69176457}],"con":true,"img":false}]}
{"op":"mcm","clk":"11541538695","pt":1719506788026,"mc":[{"id":"1.230180135","rc":[{"atb":[[1.08,50]],"id":41401491},{"atb":[[1.07,2.48]],"id":52032624},{"atb":[[1.06,0]],"id":4065261},{"atb":[[1.06,0]],"id":65040144}],"con":true,"img":false}]}
{"op":"mcm","clk":"11541539722","pt":1719506800145,"mc":[{"id":"1.230180135","rc":[{"atb":[[1.07,2.48]],"id":69176457}],"con":true,"img":false}]}
{"op":"mcm","clk":"11541540411","pt":1719506808573,"mc":[{"id":"1.230180135","rc":[{"atb":[[1.06,2.5]],"id":4065261},{"atb":[[1.06,2.5]],"id":65040144}],"con":true,"img":false}]}
{"op":"mcm","clk":"11541540508","pt":1719506809567,"mc":[{"id":"1.230180135","rc":[{"atb":[[1.07,4.98]],"id":41401491},{"atb":[[1.08,52.5]],"id":69176457}],"con":true,"img":false}]}
{"op":"mcm","clk":"11541540766","pt":1719506812665,"mc":[{"id":"1.230180135","rc":[{"atb":[[1.07,2.48]],"id":41401491},{"atb":[[1.06,0]],"id":4065261},{"atb":[[1.08,50]],"id":69176457},{"atb":[[1.06,0]],"id":65040144}],"con":true,"img":false}]}
{"op":"mcm","clk":"11541541540","pt":1719506821688,"mc":[{"id":"1.230180135","rc":[{"atb":[[1.09,0]],"id":69176457},{"atb":[[1.09,65.82]],"id":65040144}],"con":true,"img":false}]}
{"op":"mcm","clk":"11541541564","pt":1719506822003,"mc":[{"id":"1.230180135","rc":[{"atb":[[1.1,42.31]],"id":65040144}],"con":true,"img":false}]}
{"op":"mcm","clk":"11541541575","pt":1719506822102,"mc":[{"id":"1.230180135","rc":[{"atb":[[1.1,0]],"id":69176457}],"con":true,"img":false}]}
{"op":"mcm","clk":"11541541601","pt":1719506822381,"mc":[{"id":"1.230180135","rc":[{"atb":[[1.11,38.46]],"id":69176457}],"con":true,"img":false}]}
{"op":"mcm","clk":"11541541834","pt":1719506824922,"mc":[{"id":"1.230180135","rc":[{"atb":[[1.08,52.5]],"id":65040144}],"con":true,"img":false}]}
{"op":"mcm","clk":"11541542384","pt":1719506831111,"mc":[{"id":"1.230180135","rc":[{"atb":[[1.08,52.5]],"id":69176457}],"con":true,"img":false}]}
{"op":"mcm","clk":"11541542395","pt":1719506831212,"mc":[{"id":"1.230180135","rc":[{"atb":[[1.06,2.5]],"id":4065261},{"atb":[[1.07,4.98]],"id":65040144}],"con":true,"img":false}]}
{"op":"mcm","clk":"11541542476","pt":1719506832217,"mc":[{"id":"1.230180135","rc":[{"atb":[[1.06,2.5]],"id":41401491}],"con":true,"img":false}]}
{"op":"mcm","clk":"11541542665","pt":1719506834706,"mc":[{"id":"1.230180135","rc":[{"atb":[[1.06,0]],"id":41401491},{"atb":[[1.06,0]],"id":4065261},{"atb":[[1.08,50]],"id":69176457},{"atb":[[1.07,2.48]],"id":65040144}],"con":true,"img":false}]}
{"op":"mcm","clk":"11541543958","pt":1719506850417,"mc":[{"id":"1.230180135","rc":[{"atb":[[1.09,65.82]],"id":69176457},{"atb":[[1.09,0]],"id":65040144}],"con":true,"img":false}]}
{"op":"mcm","clk":"11541543995","pt":1719506850732,"mc":[{"id":"1.230180135","rc":[{"atb":[[1.1,42.31]],"id":4065261}],"con":true,"img":false}]}
{"op":"mcm","clk":"11541544004","pt":1719506850835,"mc":[{"id":"1.230180135","rc":[{"atb":[[1.1,0]],"id":65040144}],"con":true,"img":false}]}
{"op":"mcm","clk":"11541544032","pt":1719506851140,"mc":[{"id":"1.230180135","rc":[{"atb":[[1.11,38.46]],"id":65040144}],"con":true,"img":false}]}
{"op":"mcm","clk":"11541544076","pt":1719506851625,"mc":[{"id":"1.230180135","rc":[{"atb":[[1.08,50]],"id":65040144}],"con":true,"img":false}]}
{"op":"mcm","clk":"11541544161","pt":1719506852620,"mc":[{"id":"1.230180135","rc":[{"atb":[[1.07,4.98]],"id":69176457}],"con":true,"img":false}]}
{"op":"mcm","clk":"11541544179","pt":1719506852853,"mc":[{"id":"1.230180135","rc":[{"atb":[[1.06,2.5]],"id":4065261},{"atb":[[1.1,2.5]],"id":65040144}],"con":true,"img":false}]}
{"op":"mcm","clk":"11541544190","pt":1719506852944,"mc":[{"id":"1.230180135","rc":[{"atb":[[1.09,2.5]],"id":4065261}],"con":true,"img":false}]}
{"op":"mcm","clk":"11541544248","pt":1719506853518,"mc":[{"id":"1.230180135","rc":[{"atb":[[1.06,2.5]],"id":41401491}],"con":true,"img":false}]}
{"op":"mcm","clk":"11541544258","pt":1719506853620,"mc":[{"id":"1.230180135","rc":[{"atb":[[1.08,52.5]],"id":65040144}],"con":true,"img":false}]}
{"op":"mcm","clk":"11541544265","pt":1719506853734,"mc":[{"id":"1.230180135","rc":[{"atb":[[1.06,0]],"id":4065261}],"con":true,"img":false}]}
{"op":"mcm","clk":"11541544496","pt":1719506856737,"mc":[{"id":"1.230180135","rc":[{"atb":[[1.08,50]],"id":65040144}],"con":true,"img":false}]}
{"op":"mcm","clk":"11541544909","pt":1719506862253,"mc":[{"id":"1.230180135","rc":[{"atb":[[1.07,2.48]],"id":69176457}],"con":true,"img":false}]}
{"op":"mcm","clk":"11541545717","pt":1719506872963,"mc":[{"id":"1.230180135","rc":[{"atb":[[1.08,52.5]],"id":69176457}],"con":true,"img":false}]}
{"op":"mcm","clk":"11541545729","pt":1719506873072,"mc":[{"id":"1.230180135","rc":[{"atb":[[1.08,52.5]],"id":4065261}],"con":true,"img":false}]}
{"op":"mcm","clk":"11541545788","pt":1719506874062,"mc":[{"id":"1.230180135","rc":[{"atb":[[1.09,2.5]],"id":65040144}],"con":true,"img":false}]}
{"op":"mcm","clk":"11541546300","pt":1719506881276,"mc":[{"id":"1.230180135","rc":[{"atb":[[1.09,0]],"id":69176457}],"con":true,"img":false}]}
{"op":"mcm","clk":"11541546416","pt":1719506882530,"mc":[{"id":"1.230180135","rc":[{"atb":[[1.1,0]],"id":4065261},{"atb":[[1.11,0]],"id":65040144}],"con":true,"img":false}]}
{"op":"mcm","clk":"11541546437","pt":1719506882811,"mc":[{"id":"1.230180135","rc":[{"atb":[[1.09,0]],"id":4065261},{"atb":[[1.1,59.24]],"id":69176457},{"atb":[[1.1,0]],"id":65040144}],"con":true,"img":false}]}
{"op":"mcm","clk":"11541546495","pt":1719506883284,"mc":[{"id":"1.230180135","rc":[{"atb":[[1.12,35.26]],"id":65040144}],"con":true,"img":false}]}
{"op":"mcm","clk":"11541546529","pt":1719506883594,"mc":[{"id":"1.230180135","rc":[{"atb":[[1.11,38.46]],"id":4065261}],"con":true,"img":false}]}
{"op":"mcm","clk":"11541546614","pt":1719506884392,"mc":[{"id":"1.230180135","rc":[{"atb":[[1.06,0]],"id":41401491}],"con":true,"img":false}]}
{"op":"mcm","clk":"11541546663","pt":1719506884914,"mc":[{"id":"1.230180135","rc":[{"atb":[[1.11,2.5]],"id":65040144}],"con":true,"img":false}]}
{"op":"mcm","clk":"11541546723","pt":1719506885482,"mc":[{"id":"1.230180135","rc":[{"atb":[[1.05,2.5]],"id":41401491}],"con":true,"img":false}]}
{"op":"mcm","clk":"11541546762","pt":1719506886006,"mc":[{"id":"1.230180135","rc":[{"atb":[[1.05,0]],"id":41401491},{"atb":[[1.1,2.5]],"id":4065261},{"atb":[[1.09,0]],"id":65040144}],"con":true,"img":false}]}
{"op":"mcm","clk":"11541546813","pt":1719506886483,"mc":[{"id":"1.230180135","rc":[{"atb":[[1.08,50]],"id":4065261}],"con":true,"img":false}]}
{"op":"mcm","clk":"11541546842","pt":1719506886898,"mc":[{"id":"1.230180135","rc":[{"atb":[[1.1,0]],"id":4065261}],"con":true,"img":false}]}
{"op":"mcm","clk":"11541547282","pt":1719506892397,"mc":[{"id":"1.230180135","rc":[{"atb":[[1.09,2.5]],"id":4065261}],"con":true,"img":false}]}
{"op":"mcm","clk":"11541547377","pt":1719506893408,"mc":[{"id":"1.230180135","rc":[{"atb":[[1.1,2.5]],"id":65040144}],"con":true,"img":false}]}
{"op":"mcm","clk":"11541547506","pt":1719506894880,"mc":[{"id":"1.230180135","rc":[{"atb":[[1.08,50]],"id":69176457}],"con":true,"img":false}]}
{"op":"mcm","clk":"11541547599","pt":1719506895983,"mc":[{"id":"1.230180135","rc":[{"atb":[[1.09,2.5]],"id":69176457}],"con":true,"img":false}]}
{"op":"mcm","clk":"11541548121","pt":1719506903719,"mc":[{"id":"1.230180135","rc":[{"atb":[[1.1,2.5]],"id":4065261}],"con":true,"img":false}]}
{"op":"mcm","clk":"11541548164","pt":1719506904283,"mc":[{"id":"1.230180135","rc":[{"atb":[[1.08,52.5]],"id":41401491}],"con":true,"img":false}]}
{"op":"mcm","clk":"11541548935","pt":1719506914326,"mc":[{"id":"1.230180135","rc":[{"atb":[[1.11,0]],"id":69176457}],"con":true,"img":false}]}
{"op":"mcm","clk":"11541549207","pt":1719506917605,"mc":[{"id":"1.230180135","rc":[{"atb":[[1.11,0]],"id":4065261},{"atb":[[1.12,0]],"id":65040144}],"con":true,"img":false}]}
{"op":"mcm","clk":"11541549234","pt":1719506917921,"mc":[{"id":"1.230180135","rc":[{"atb":[[1.11,38.46]],"id":69176457},{"atb":[[1.13,32.54]],"id":65040144}],"con":true,"img":false}]}
{"op":"mcm","clk":"11541549248","pt":1719506918124,"mc":[{"id":"1.230180135","rc":[{"atb":[[1.1,0]],"id":4065261},{"atb":[[1.11,0]],"id":65040144}],"con":true,"img":false}]}
{"op":"mcm","clk":"11541549256","pt":1719506918230,"mc":[{"id":"1.230180135","rc":[{"atb":[[1.12,35.26]],"id":4065261}],"con":true,"img":false}]}
{"op":"mcm","clk":"11541549300","pt":1719506918748,"mc":[{"id":"1.230180135","rc":[{"atb":[[1.65,0]],"id":52032624}],"con":true,"img":false}]}
{"op":"mcm","clk":"11541549355","pt":1719506919326,"mc":[{"id":"1.230180135","rc":[{"atb":[[1.12,2.5]],"id":65040144}],"con":true,"img":false}]}
{"op":"mcm","clk":"11541549372","pt":1719506919532,"mc":[{"id":"1.230180135","rc":[{"atb":[[1.1,0]],"id":65040144}],"con":true,"img":false}]}
{"op":"mcm","clk":"11541549470","pt":1719506920527,"mc":[{"id":"1.230180135","rc":[{"atb":[[1.06,3.75]],"id":52032624}],"con":true,"img":false}]}
{"op":"mcm","clk":"11541549487","pt":1719506920652,"mc":[{"id":"1.230180135","rc":[{"atb":[[1.11,2.5]],"id":65040144}],"con":true,"img":false}]}
{"op":"mcm","clk":"11541549526","pt":1719506921017,"mc":[{"id":"1.230180135","rc":[{"atb":[[1.09,0]],"id":4065261}],"con":true,"img":false}]}
{"op":"mcm","clk":"11541549569","pt":1719506921541,"mc":[{"id":"1.230180135","rc":[{"atb":[[1.11,2.5]],"id":4065261}],"con":true,"img":false}]}
{"op":"mcm","clk":"11541549619","pt":1719506922123,"mc":[{"id":"1.230180135","rc":[{"atb":[[1.1,2.5]],"id":4065261}],"con":true,"img":false}]}
{"op":"mcm","clk":"11541551026","pt":1719506940545,"mc":[{"id":"1.230180135","rc":[{"atb":[[1.1,0]],"id":4065261},{"atb":[[1.09,0]],"id":69176457},{"atb":[[1.11,0]],"id":65040144}],"con":true,"img":false}]}
{"op":"mcm","clk":"11541551114","pt":1719506941554,"mc":[{"id":"1.230180135","rc":[{"atb":[[1.08,50]],"id":41401491}],"con":true,"img":false}]}
{"op":"mcm","clk":"11541551151","pt":1719506941934,"mc":[{"id":"1.230180135","rc":[{"atb":[[1.18,1],[1.16,0]],"id":41401491},{"atl":[[12.5,0],[13,3.85]],"id":41401491},{"atl":[[300,0],[230,2]],"id":52032624},{"atl":[[36,0],[38,3.7]],"id":4065261},{"atl":[[16.5,2],[19,0]],"id":69176457},{"atb":[[1.06,25.93]],"id":65040144},{"atl":[[38,3.7]],"id":65040144}],"con":true,"img":false}]}
{"op":"mcm","clk":"11541551157","pt":1719506942045,"mc":[{"id":"1.230180135","rc":[{"atb":[[1.12,3.75]],"id":65040144},{"atl":[[36,0]],"id":65040144}],"con":true,"img":false}]}
{"op":"mcm","clk":"11541551191","pt":1719506942460,"mc":[{"id":"1.230180135","rc":[{"atl":[[12,0]],"id":41401491},{"atl":[[34,0]],"id":4065261},{"atl":[[16,0.84],[18.5,0]],"id":69176457},{"atl":[[34,0]],"id":65040144}],"con":true,"img":false}]}
{"op":"mcm","clk":"11541551210","pt":1719506942666,"mc":[{"id":"1.230180135","rc":[{"atb":[[1.09,68.17]],"id":41401491},{"atl":[[13,0],[14,1],[14.5,7.41]],"id":41401491},{"atl":[[38,2.7],[42,1]],"id":4065261},{"atb":[[1.1,61.74]],"id":69176457},{"atl":[[17,1],[19.5,0]],"id":69176457},{"atb":[[1.12,7.65]],"id":65040144},{"atl":[[38,0],[42,1],[46,2.22]],"id":65040144}],"con":true,"img":false}]}
{"op":"mcm","clk":"11541551234","pt":1719506942933,"mc":[{"id":"1.230180135","rc":[{"atl":[[12.5,0.84]],"id":41401491},{"atl":[[36,0.84]],"id":4065261},{"atl":[[36,0.84]],"id":65040144}],"con":true,"img":false}]}
{"op":"mcm","clk":"11541551281","pt":1719506943452,"mc":[{"id":"1.230180135","rc":[{"atl":[[12.5,0],[13.5,1],[14,0]],"id":41401491},{"atl":[[40,1],[42,0]],"id":4065261},{"atl":[[36,0],[40,1],[42,0]],"id":65040144}],"con":true,"img":false}]}
{"op":"mcm","clk":"11541551293","pt":1719506943646,"mc":[{"id":"1.230180135","rc":[{"atl":[[40,0],[44,1]],"id":65040144}],"con":true,"img":false}]}
{"op":"mcm","clk":"11541551413","pt":1719506945062,"mc":[{"id":"1.230180135","rc":[{"atb":[[1.17,2.5]],"id":41401491}],"con":true,"img":false}]}
{"op":"mcm","clk":"11541551443","pt":1719506945367,"mc":[{"id":"1.230180135","rc":[{"atl":[[44,0],[48,1]],"id":65040144}],"con":true,"img":false}]}
{"op":"mcm","clk":"11541551468","pt":1719506945648,"mc":[{"id":"1.230180135","rc":[{"atb":[[1.09,65.82]],"id":41401491}],"con":true,"img":false}]}
{"op":"mcm","clk":"11541551675","pt":1719506948169,"mc":[{"id":"1.230180135","rc":[{"atl":[[13.5,0]],"id":41401491},{"atl":[[50,1]],"id":65040144}],"con":true,"img":false}]}
{"op":"mcm","clk":"11541551683","pt":1719506948270,"mc":[{"id":"1.230180135","rc":[{"atl":[[14.5,8.41]],"id":41401491},{"atl":[[48,0]],"id":65040144}],"con":true,"img":false}]}
{"op":"mcm","clk":"11541551820","pt":1719506949989,"mc":[{"id":"1.230180135","rc":[{"atl":[[14,0.84]],"id":41401491},{"atb":[[1.1,2.5]],"id":69176457}],"con":true,"img":false}]}
{"op":"mcm","clk":"11541551858","pt":1719506950457,"mc":[{"id":"1.230180135","rc":[{"atb":[[1.09,65.82]],"id":65040144}],"con":true,"img":false}]}
{"op":"mcm","clk":"11541551888","pt":1719506950877,"mc":[{"id":"1.230180135","rc":[{"atb":[[1.11,0]],"id":69176457}],"con":true,"img":false}]}
{"op":"mcm","clk":"11541551910","pt":1719506951140,"mc":[{"id":"1.230180135","rc":[{"atl":[[14.5,7.41],[15,1]],"id":41401491},{"atb":[[1.12,3.75]],"id":65040144}],"con":true,"img":false}]}
{"op":"mcm","clk":"11541551924","pt":1719506951347,"mc":[{"id":"1.230180135","rc":[{"atb":[[1.17,0]],"id":41401491}],"con":true,"img":false}]}
{"op":"mcm","clk":"11541551930","pt":1719506951452,"mc":[{"id":"1.230180135","rc":[{"atb":[[1.13,0]],"id":65040144}],"con":true,"img":false}]}
{"op":"mcm","clk":"11541551942","pt":1719506951664,"mc":[{"id":"1.230180135","rc":[{"atb":[[1.12,0]],"id":4065261}],"con":true,"img":false}]}
{"op":"mcm","clk":"11541551963","pt":1719506951971,"mc":[{"id":"1.230180135","rc":[{"atb":[[1.1,0]],"id":41401491}],"con":true,"img":false}]}
{"op":"mcm","clk":"11541551984","pt":1719506952274,"mc":[{"id":"1.230180135","rc":[{"atb":[[1.14,30.22]],"id":65040144}],"con":true,"img":false}]}
{"op":"mcm","clk":"11541551999","pt":1719506952481,"mc":[{"id":"1.230180135","rc":[{"atb":[[1.11,0],[1.13,32.54]],"id":4065261},{"atb":[[1.12,0]],"id":65040144}],"con":true,"img":false}]}
{"op":"mcm","clk":"11541552009","pt":1719506952545,"mc":[{"id":"1.230180135","rc":[{"atb":[[1.12,35.26]],"id":69176457}],"con":true,"img":false}]}
{"op":"mcm","clk":"11541552061","pt":1719506953266,"mc":[{"id":"1.230180135","rc":[{"atb":[[1.1,0]],"id":69176457}],"con":true,"img":false}]}
{"op":"mcm","clk":"11541552073","pt":1719506953369,"mc":[{"id":"1.230180135","rc":[{"atb":[[1.19,22.27]],"id":41401491}],"con":true,"img":false}]}
{"op":"mcm","clk":"11541552204","pt":1719506955272,"mc":[{"id":"1.230180135","rc":[{"atb":[[1.12,2.5]],"id":4065261}],"con":true,"img":false}]}
{"op":"mcm","clk":"11541552460","pt":1719506958572,"mc":[{"id":"1.230180135","rc":[{"atb":[[1.18,3.5]],"id":41401491},{"atb":[[1.11,2.5]],"id":69176457},{"atb":[[1.13,2.5]],"id":65040144}],"con":true,"img":false}]}
{"op":"mcm","clk":"11541552521","pt":1719506959296,"mc":[{"id":"1.230180135","rc":[{"atb":[[1.18,1]],"id":41401491},{"atb":[[1.13,0]],"id":65040144}],"con":true,"img":false}]}
{"op":"mcm","clk":"11541553197","pt":1719506967964,"mc":[{"id":"1.230180135","rc":[{"atb":[[1.13,2.5]],"id":65040144}],"con":true,"img":false}]}
{"op":"mcm","clk":"11541553592","pt":1719506972664,"mc":[{"id":"1.230180135","rc":[{"atb":[[1.18,3.5]],"id":41401491}],"con":true,"img":false}]}
{"op":"mcm","clk":"11541553645","pt":1719506973283,"mc":[{"id":"1.230180135","rc":[{"atb":[[1.18,1]],"id":41401491}],"con":true,"img":false}]}
{"op":"mcm","clk":"11541553672","pt":1719506973658,"mc":[{"id":"1.230180135","rc":[{"atb":[[1.07,4.98]],"id":65040144}],"con":true,"img":false}]}
{"op":"mcm","clk":"11541554158","pt":1719506979581,"mc":[{"id":"1.230180135","rc":[{"spn":7.6,"spf":"NaN","id":41401491},{"spn":18.6,"spf":"NaN","id":4065261},{"atb":[[1.12,0]],"id":69176457},{"spn":8.6,"spf":"NaN","id":69176457},{"spn":46.0,"spf":"Infinity","id":65040144}],"con":true,"img":false}]}
{"op":"mcm","clk":"11541554443","pt":1719506983283,"mc":[{"id":"1.230180135","rc":[{"atb":[[1.09,0]],"id":65040144}],"con":true,"img":false}]}
{"op":"mcm","clk":"11541554461","pt":1719506983596,"mc":[{"id":"1.230180135","rc":[{"atb":[[1.13,0]],"id":4065261}],"con":true,"img":false}]}
{"op":"mcm","clk":"11541554476","pt":1719506983805,"mc":[{"id":"1.230180135","rc":[{"atb":[[1.12,0]],"id":4065261},{"atb":[[1.07,2.48]],"id":65040144}],"con":true,"img":false}]}
{"op":"mcm","clk":"11541554488","pt":1719506983868,"mc":[{"id":"1.230180135","rc":[{"atb":[[1.09,65.82],[1.13,32.54]],"id":69176457}],"con":true,"img":false}]}
{"op":"mcm","clk":"11541554508","pt":1719506984179,"mc":[{"id":"1.230180135","rc":[{"atb":[[1.14,30.22]],"id":4065261},{"atb":[[1.14,0]],"id":65040144}],"con":true,"img":false}]}
{"op":"mcm","clk":"11541554513","pt":1719506984276,"mc":[{"id":"1.230180135","rc":[{"atb":[[1.11,0]],"id":69176457}],"con":true,"img":false}]}
{"op":"mcm","clk":"11541554534","pt":1719506984490,"mc":[{"id":"1.230180135","rc":[{"atb":[[1.15,28.2]],"id":65040144}],"con":true,"img":false}]}
{"op":"mcm","clk":"11541554555","pt":1719506984797,"mc":[{"id":"1.230180135","rc":[{"atb":[[1.13,0]],"id":65040144}],"con":true,"img":false}]}
{"op":"mcm","clk":"11541554629","pt":1719506985889,"mc":[{"id":"1.230180135","rc":[{"atb":[[1.14,2.5]],"id":65040144}],"con":true,"img":false}]}
{"op":"mcm","clk":"11541554634","pt":1719506985993,"mc":[{"id":"1.230180135","rc":[{"atb":[[1.18,3.5]],"id":41401491},{"atb":[[1.13,2.5]],"id":4065261}],"con":true,"img":false}]}
{"op":"mcm","clk":"11541554662","pt":1719506986384,"mc":[{"id":"1.230180135","rc":[{"atb":[[1.18,1]],"id":41401491},{"atb":[[1.12,2.5]],"id":69176457}],"con":true,"img":false}]}
{"op":"mcm","clk":"11541554695","pt":1719506986880,"mc":[{"id":"1.230180135","rc":[{"atb":[[1.12,0]],"id":69176457}],"con":true,"img":false}]}
{"op":"mcm","clk":"11541554773","pt":1719506987984,"mc":[{"id":"1.230180135","rc":[{"atb":[[1.14,5]],"id":65040144}],"con":true,"img":false}]}
{"op":"mcm","clk":"11541555226","pt":1719506994424,"mc":[{"id":"1.230180135","rc":[{"atb":[[1.13,0]],"id":69176457}],"con":true,"img":false}]}
{"op":"mcm","clk":"11541555306","pt":1719506995604,"mc":[{"id":"1.230180135","rc":[{"atb":[[1.13,0]],"id":4065261}],"con":true,"img":false}]}
{"op":"mcm","clk":"11541555474","pt":1719506998704,"mc":[{"id":"1.230180135","rc":[{"atb":[[1.18,3.5]],"id":41401491}],"con":true,"img":false}]}
{"op":"mcm","clk":"11541555477","pt":1719506998811,"mc":[{"id":"1.230180135","rc":[{"atb":[[1.13,2.5]],"id":4065261}],"con":true,"img":false}]}
{"op":"mcm","clk":"11541555490","pt":1719506999122,"mc":[{"id":"1.230180135","rc":[{"atb":[[1.12,2.5]],"id":69176457}],"con":true,"img":false}]}
{"op":"mcm","clk":"11541555506","pt":1719506999380,"mc":[{"id":"1.230180135","rc":[{"atb":[[1.18,1]],"id":41401491},{"atb":[[1.13,0]],"id":4065261}],"con":true,"img":false}]}
{"op":"mcm","clk":"11541555524","pt":1719506999699,"mc":[{"id":"1.230180135","rc":[{"atb":[[1.13,2.5]],"id":4065261}],"con":true,"img":false}]}
{"op":"mcm","clk":"11541555617","pt":1719507001388,"mc":[{"id":"1.230180135","rc":[{"atb":[[1.06,0]],"id":52032624}],"con":true,"img":false}]}
{"op":"mcm","clk":"11541555622","pt":1719507001494,"mc":[{"id":"1.230180135","rc":[{"atb":[[1.2,12.87],[1.19,47.53]],"id":41401491},{"atb":[[1.94,9.09],[1.93,13.64]],"id":52032624},{"atl":[[36,6.8]],"id":4065261},{"atl":[[16,12.76]],"id":69176457},{"atb":[[1.2,4.81],[1.18,10.13]],"id":65040144}],"con":true,"img":false}]}
{"op":"mcm","clk":"11541555630","pt":1719507001596,"mc":[{"id":"1.230180135","rc":[{"atl":[[34,2.7],[38,0]],"id":4065261},{"atl":[[16.5,0],[15.5,2]],"id":69176457},{"atb":[[1.14,11.99]],"id":65040144}],"con":true,"img":false}]}
{"op":"mcm","clk":"11541555653","pt":1719507001916,"mc":[{"id":"1.230180135","rc":[{"atl":[[38,1],[40,0]],"id":4065261},{"atl":[[16.5,1],[17,0]],"id":69176457},{"atb":[[1.14,6.12]],"id":65040144}],"con":true,"img":false}]}
{"op":"mcm","clk":"11541555659","pt":1719507002015,"mc":[{"id":"1.230180135","rc":[{"atl":[[32,0.84]],"id":4065261},{"atl":[[15,0.84]],"id":69176457}],"con":true,"img":false}]}
{"op":"mcm","clk":"11541555769","pt":1719507003633,"mc":[{"id":"1.230180135","rc":[{"atb":[[1.92,4.75]],"id":52032624}],"con":true,"img":false}]}
{"op":"mcm","clk":"11541555792","pt":1719507003842,"mc":[{"id":"1.230180135","rc":[{"atb":[[1.92,1]],"id":52032624}],"con":true,"img":false}]}
{"op":"mcm","clk":"11541555812","pt":1719507003999,"mc":[{"id":"1.230180135","rc":[{"atl":[[36,7.8],[38,0]],"id":4065261},{"atl":[[16,13.76],[16.5,0]],"id":69176457}],"con":true,"img":false}]}
{"op":"mcm","clk":"11541555819","pt":1719507004104,"mc":[{"id":"1.230180135","rc":[{"atl":[[14,13.37]],"id":41401491},{"atb":[[1.2,6.23],[1.18,12.97]],"id":4065261},{"atl":[[15,12.76]],"id":69176457},{"atl":[[46,6.74]],"id":65040144}],"con":true,"img":false}]}
{"op":"mcm","clk":"11541555828","pt":1719507004205,"mc":[{"id":"1.230180135","rc":[{"atl":[[13.5,7.41],[14.5,0]],"id":41401491},{"atl":[[14.5,7.41],[15.5,0]],"id":69176457}],"con":true,"img":false}]}
{"op":"mcm","clk":"11541555843","pt":1719507004413,"mc":[{"id":"1.230180135","rc":[{"atb":[[1.19,68.54]],"id":41401491},{"atl":[[14,18.63]],"id":41401491},{"atb":[[1.94,30.11]],"id":52032624},{"atl":[[75,1.4]],"id":52032624},{"atl":[[16,12.91]],"id":69176457}],"con":true,"img":false}]}
{"op":"mcm","clk":"11541555851","pt":1719507004517,"mc":[{"id":"1.230180135","rc":[{"atl":[[75,3.4],[230,0]],"id":52032624}],"con":true,"img":false}]}
{"op":"mcm","clk":"11541555858","pt":1719507004620,"mc":[{"id":"1.230180135","rc":[{"atl":[[13,12.54]],"id":41401491},{"atl":[[75,1.4],[230,2]],"id":52032624},{"atl":[[16,1],[14,11.93]],"id":69176457}],"con":true,"img":false}]}
{"op":"mcm","clk":"11541555863","pt":1719507004727,"mc":[{"id":"1.230180135","rc":[{"atl":[[75,3.4],[230,0]],"id":52032624}],"con":true,"img":false}]}
{"op":"mcm","clk":"11541555872","pt":1719507004830,"mc":[{"id":"1.230180135","rc":[{"atb":[[1.91,4.1]],"id":52032624},{"atl":[[230,2]],"id":52032624}],"con":true,"img":false}]}
{"op":"mcm","clk":"11541555878","pt":1719507004935,"mc":[{"id":"1.230180135","rc":[{"atl":[[75,1.4]],"id":52032624}],"con":true,"img":false}]}
{"op":"mcm","clk":"11541555885","pt":1719507004986,"mc":[{"id":"1.230180135","rc":[{"atl":[[12.5,0.84],[14,17.78]],"id":41401491},{"atb":[[1.91,0]],"id":52032624},{"atl":[[15,11.92]],"id":69176457},{"atb":[[1.14,4.1]],"id":65040144}],"con":true,"img":false}]}
{"op":"mcm","clk":"11541555891","pt":1719507005094,"mc":[{"id":"1.230180135","rc":[{"atl":[[75,3.4],[230,0]],"id":52032624}],"con":true,"img":false}]}
{"op":"mcm","clk":"11541555943","pt":1719507005933,"mc":[{"id":"1.230180135","rc":[{"atl":[[12.5,13.39],[14,5.25]],"id":41401491},{"atb":[[1.95,4.53]],"id":52032624},{"atl":[[32,6.75]],"id":4065261}],"con":true,"img":false}]}
{"op":"mcm","clk":"11541555952","pt":1719507006036,"mc":[{"id":"1.230180135","rc":[{"atb":[[1.96,13.65],[1.94,25.56]],"id":52032624},{"atl":[[34,0],[30,3.45]],"id":4065261},{"atl":[[16,0],[15,12.92]],"id":69176457}],"con":true,"img":false}]}
{"op":"mcm","clk":"11541555970","pt":1719507006245,"mc":[{"id":"1.230180135","rc":[{"atb":[[1.92,0],[1.94,26.56]],"id":52032624},{"atl":[[34,1],[36,6.8]],"id":4065261}],"con":true,"img":false}]}
{"op":"mcm","clk":"11541555995","pt":1719507006511,"mc":[{"id":"1.230180135","rc":[{"atl":[[36,5.96]],"id":4065261}],"con":true,"img":false}]}
{"op":"mcm","clk":"11541555999","pt":1719507006612,"mc":[{"id":"1.230180135","rc":[{"atl":[[13.5,8.41],[15,0]],"id":41401491},{"atb":[[1.97,4.53]],"id":52032624},{"atb":[[1.2,12.39],[1.18,25.29]],"id":69176457}],"con":true,"img":false}]}
{"op":"mcm","clk":"11541556005","pt":1719507006718,"mc":[{"id":"1.230180135","rc":[{"atb":[[1.98,4.54],[1.96,0]],"id":52032624}],"con":true,"img":false}]}
{"op":"mcm","clk":"11541556011","pt":1719507006830,"mc":[{"id":"1.230180135","rc":[{"atb":[[1.94,25.56],[1.95,5.53]],"id":52032624}],"con":true,"img":false}]}
{"op":"mcm","clk":"11541556021","pt":1719507006926,"mc":[{"id":"1.230180135","rc":[{"atb":[[1.12,0]],"id":69176457}],"con":true,"img":false}]}
{"op":"mcm","clk":"11541556156","pt":1719507008907,"mc":[{"id":"1.230180135","rc":[{"atb":[[1.08,66.88]],"id":69176457}],"con":true,"img":false}]}
{"op":"mcm","clk":"11541556175","pt":1719507009111,"mc":[{"id":"1.230180135","rc":[{"atl":[[14,0]],"id":41401491}],"con":true,"img":false}]}
{"op":"mcm","clk":"11541556191","pt":1719507009316,"mc":[{"id":"1.230180135","rc":[{"atl":[[12,9.09],[12.5,19.33],[13.5,1]],"id":41401491},{"atl":[[13.5,8],[14.5,0]],"id":69176457}],"con":true,"img":false}]}
{"op":"mcm","clk":"11541556203","pt":1719507009527,"mc":[{"id":"1.230180135","rc":[{"atl":[[29,0.84]],"id":4065261},{"atl":[[13.5,8.84]],"id":69176457}],"con":true,"img":false}]}
{"op":"mcm","clk":"11541556298","pt":1719507010929,"mc":[{"id":"1.230180135","rc":[{"atl":[[14.5,1],[15,11.92]],"id":69176457}],"con":true,"img":false}]}
{"op":"mcm","clk":"11541556304","pt":1719507011038,"mc":[{"id":"1.230180135","rc":[{"atb":[[1.08,50]],"id":69176457}],"con":true,"img":false}]}
{"op":"mcm","clk":"11541556315","pt":1719507011142,"mc":[{"id":"1.230180135","rc":[{"atl":[[32,7.75],[34,0]],"id":4065261}],"con":true,"img":false}]}
{"op":"mcm","clk":"11541556344","pt":1719507011554,"mc":[{"id":"1.230180135","rc":[{"atl":[[13,13.54],[13.5,0]],"id":41401491}],"con":true,"img":false}]}
{"op":"mcm","clk":"11541556359","pt":1719507011713,"mc":[{"id":"1.230180135","rc":[{"atb":[[1.96,1],[1.95,4.53]],"id":52032624},{"atb":[[1.13,5.75]],"id":4065261}],"con":true,"img":false}]}
{"op":"mcm","clk":"11541556368","pt":1719507011811,"mc":[{"id":"1.230180135","rc":[{"atb":[[1.07,10.36]],"id":41401491}],"con":true,"img":false}]}
{"op":"mcm","clk":"11541556373","pt":1719507011919,"mc":[{"id":"1.230180135","rc":[{"atb":[[1.07,10.86]],"id":4065261}],"con":true,"img":false}]}
{"op":"mcm","clk":"11541556383","pt":1719507012122,"mc":[{"id":"1.230180135","rc":[{"atl":[[11.5,0.84]],"id":41401491},{"atb":[[1.14,0]],"id":65040144}],"con":true,"img":false}]}
{"op":"mcm","clk":"11541556388","pt":1719507012221,"mc":[{"id":"1.230180135","rc":[{"atb":[[1.07,12.86]],"id":69176457}],"con":true,"img":false}]}
{"op":"mcm","clk":"11541556397","pt":1719507012430,"mc":[{"id":"1.230180135","rc":[{"atb":[[1.07,2.47]],"id":4065261}],"con":true,"img":false}]}
{"op":"mcm","clk":"11541556483","pt":1719507013935,"mc":[{"id":"1.230180135","rc":[{"atl":[[12.5,13.39]],"id":41401491}],"con":true,"img":false}]}
{"op":"mcm","clk":"11541556496","pt":1719507014142,"mc":[{"id":"1.230180135","rc":[{"atl":[[11.5,7.35]],"id":41401491}],"con":true,"img":false}]}
{"op":"mcm","clk":"11541556504","pt":1719507014247,"mc":[{"id":"1.230180135","rc":[{"atl":[[11,9.09],[12,0]],"id":41401491}],"con":true,"img":false}]}
{"op":"mcm","clk":"11541556531","pt":1719507014510,"mc":[{"id":"1.230180135","rc":[{"atl":[[12.5,12.55]],"id":41401491}],"con":true,"img":false}]}
{"op":"mcm","clk":"11541556547","pt":1719507014718,"mc":[{"id":"1.230180135","rc":[{"atb":[[1.14,6.12]],"id":65040144}],"con":true,"img":false}]}
{"op":"mcm","clk":"11541556557","pt":1719507014920,"mc":[{"id":"1.230180135","rc":[{"atb":[[1.07,13.64]],"id":65040144}],"con":true,"img":false}]}
{"op":"mcm","clk":"11541556589","pt":1719507015442,"mc":[{"id":"1.230180135","rc":[{"atb":[[1.07,2.48]],"id":65040144}],"con":true,"img":false}]}
{"op":"mcm","clk":"11541556633","pt":1719507016110,"mc":[{"id":"1.230180135","rc":[{"atb":[[1.09,0]],"id":69176457}],"con":true,"img":false}]}
{"op":"mcm","clk":"11541556649","pt":1719507016333,"mc":[{"id":"1.230180135","rc":[{"atl":[[12,1],[13,12.54]],"id":41401491}],"con":true,"img":false}]}
{"op":"mcm","clk":"11541556660","pt":1719507016423,"mc":[{"id":"1.230180135","rc":[{"atb":[[1.93,20.53]],"id":52032624},{"atb":[[1.19,31.17]],"id":4065261},{"atb":[[1.07,2.48]],"id":69176457},{"atb":[[1.09,65.82]],"id":65040144}],"con":true,"img":false}]}
{"op":"mcm","clk":"11541556669","pt":1719507016525,"mc":[{"id":"1.230180135","rc":[{"atl":[[10.5,12.6],[11.5,32.56],[13,0]],"id":41401491},{"atb":[[1.98,9.06]],"id":52032624},{"atl":[[36,0],[29,6.74]],"id":4065261},{"atl":[[13,11.93]],"id":69176457}],"con":true,"img":false}]}
{"op":"mcm","clk":"11541556675","pt":1719507016628,"mc":[{"id":"1.230180135","rc":[{"atl":[[15,0]],"id":69176457}],"con":true,"img":false}]}
{"op":"mcm","clk":"11541556680","pt":1719507016731,"mc":[{"id":"1.230180135","rc":[{"atb":[[1.09,0]],"id":41401491},{"atl":[[10,11.11],[11,0]],"id":41401491},{"atb":[[1.14,0]],"id":4065261},{"atl":[[28,3.7],[30,0]],"id":4065261},{"atl":[[12.5,8.7],[13.5,0.84]],"id":69176457}],"con":true,"img":false}]}
{"op":"mcm","clk":"11541556688","pt":1719507016937,"mc":[{"id":"1.230180135","rc":[{"atb":[[1.07,2.48]],"id":41401491},{"atl":[[12.5,9.54]],"id":69176457}],"con":true,"img":false}]}
{"op":"mcm","clk":"11541556691","pt":1719507017040,"mc":[{"id":"1.230180135","rc":[{"atl":[[11.5,31.72]],"id":41401491},{"atb":[[2,5.92]],"id":52032624},{"atl":[[32,6.9]],"id":4065261},{"atb":[[1.14,0]],"id":65040144}],"con":true,"img":false}]}
{"op":"mcm","clk":"11541556695","pt":1719507017145,"mc":[{"id":"1.230180135","rc":[{"atb":[[2,11.84],[1.98,4.52]],"id":52032624},{"atb":[[1.13,0]],"id":4065261}],"con":true,"img":false}]}
{"op":"mcm","clk":"11541556705","pt":1719507017354,"mc":[{"id":"1.230180135","rc":[{"atb":[[1.22,19.23]],"id":4065261},{"atb":[[1.22,19.23]],"id":69176457}],"con":true,"img":false}]}
{"op":"mcm","clk":"11541556710","pt":1719507017454,"mc":[{"id":"1.230180135","rc":[{"atl":[[27,0.84]],"id":4065261}],"con":true,"img":false}]}
{"op":"mcm","clk":"11541556715","pt":1719507017558,"mc":[{"id":"1.230180135","rc":[{"atb":[[1.98,5.52],[1.96,0]],"id":52032624},{"atb":[[1.2,7.23],[1.18,11.97]],"id":4065261},{"atl":[[32,5.9],[29,7.74]],"id":4065261},{"atb":[[1.2,13.39],[1.18,24.29]],"id":69176457},{"atl":[[13.5,1],[14.5,0]],"id":69176457}],"con":true,"img":false}]}
{"op":"mcm","clk":"11541556721","pt":1719507017614,"mc":[{"id":"1.230180135","rc":[{"atb":[[1.15,0]],"id":65040144}],"con":true,"img":false}]}
{"op":"mcm","clk":"11541556726","pt":1719507017716,"mc":[{"id":"1.230180135","rc":[{"atb":[[1.19,46.27]],"id":41401491}],"con":true,"img":false}]}
{"op":"mcm","clk":"11541556738","pt":1719507017923,"mc":[{"id":"1.230180135","rc":[{"atb":[[1.21,28.2]],"id":41401491}],"con":true,"img":false}]}
{"op":"mcm","clk":"11541556749","pt":1719507018034,"mc":[{"id":"1.230180135","rc":[{"atb":[[1.22,19.23]],"id":41401491}],"con":true,"img":false}]}
{"op":"mcm","clk":"11541556768","pt":1719507018237,"mc":[{"id":"1.230180135","rc":[{"atb":[[1.22,19.23]],"id":65040144}],"con":true,"img":false}]}
{"op":"mcm","clk":"11541556801","pt":1719507018647,"mc":[{"id":"1.230180135","rc":[{"atb":[[1.2,13.87],[1.21,53.89],[1.23,12.84]],"id":41401491},{"atl":[[11,1]],"id":41401491},{"atb":[[1.23,5.96]],"id":4065261},{"atb":[[1.23,12.14]],"id":69176457},{"atb":[[1.2,5.81],[1.23,4.56]],"id":65040144}],"con":true,"img":false}]}
{"op":"mcm","clk":"11541556807","pt":1719507018752,"mc":[{"id":"1.230180135","rc":[{"atb":[[1.18,0]],"id":41401491},{"atl":[[11.5,25.21],[12,0]],"id":41401491},{"atb":[[1.94,4.54]],"id":52032624},{"atb":[[1.18,9.13]],"id":65040144}],"con":true,"img":false}]}
{"op":"mcm","clk":"11541556824","pt":1719507018958,"mc":[{"id":"1.230180135","rc":[{"atl":[[10,18.69]],"id":41401491},{"atb":[[2,32.86]],"id":52032624}],"con":true,"img":false}]}
{"op":"mcm","clk":"11541556832","pt":1719507019013,"mc":[{"id":"1.230180135","rc":[{"atb":[[1.2,6.23],[1.21,1]],"id":4065261},{"atb":[[1.2,12.39],[1.21,1]],"id":69176457},{"atb":[[1.21,1]],"id":65040144}],"con":true,"img":false}]}
{"op":"mcm","clk":"11541556839","pt":1719507019133,"mc":[{"id":"1.230180135","rc":[{"atb":[[2.02,4.54]],"id":52032624},{"atl":[[12,11.92],[14,0]],"id":69176457},{"atb":[[1.2,4.81]],"id":65040144}],"con":true,"img":false}]}
{"op":"mcm","clk":"11541556844","pt":1719507019224,"mc":[{"id":"1.230180135","rc":[{"atb":[[1.94,0]],"id":52032624},{"atl":[[11.5,9.52]],"id":69176457}],"con":true,"img":false}]}
{"op":"mcm","clk":"11541556853","pt":1719507019322,"mc":[{"id":"1.230180135","rc":[{"atl":[[12.5,0.84]],"id":69176457}],"con":true,"img":false}]}
{"op":"mcm","clk":"11541556863","pt":1719507019424,"mc":[{"id":"1.230180135","rc":[{"atl":[[9.8,0.84]],"id":41401491}],"con":true,"img":false}]}
{"op":"mcm","clk":"11541556874","pt":1719507019533,"mc":[{"id":"1.230180135","rc":[{"atl":[[11,11.95]],"id":69176457}],"con":true,"img":false}]}
{"op":"mcm","clk":"11541556893","pt":1719507019837,"mc":[{"id":"1.230180135","rc":[{"spl":[[75,0.01],[11,0.03],[11.5,0.06],[12,0.06],[12.5,0.06],[13,0.06],[13.5,0.05],[980,0.01]],"id":69176457}],"con":true,"img":false}]}
{"op":"mcm","clk":"11541556906","pt":1719507020044,"mc":[{"id":"1.230180135","rc":[{"atl":[[12.5,0]],"id":69176457}],"con":true,"img":false}]}
{"op":"mcm","clk":"11541556919","pt":1719507020250,"mc":[{"id":"1.230180135","rc":[{"atb":[[1.19,60.65]],"id":41401491}],"con":true,"img":false}]}
{"op":"mcm","clk":"11541556930","pt":1719507020406,"mc":[{"id":"1.230180135","rc":[{"atb":[[1.93,13.64]],"id":52032624}],"con":true,"img":false}]}
{"op":"mcm","clk":"11541556944","pt":1719507020614,"mc":[{"id":"1.230180135","rc":[{"atb":[[1.97,13.78]],"id":52032624}],"con":true,"img":false}]}
{"op":"mcm","clk":"11541557091","pt":1719507022331,"mc":[{"id":"1.230180135","rc":[{"atb":[[1.99,1],[1.98,4.52],[1.97,4.53]],"id":52032624}],"con":true,"img":false}]}
{"op":"mcm","clk":"11541557162","pt":1719507023355,"mc":[{"id":"1.230180135","rc":[{"atb":[[1.21,54.89],[1.19,46.27]],"id":41401491},{"atl":[[10.5,13.6]],"id":41401491}],"con":true,"img":false}]}
{"op":"mcm","clk":"11541557168","pt":1719507023457,"mc":[{"id":"1.230180135","rc":[{"atb":[[1.2,12.87]],"id":41401491},{"atl":[[11,0]],"id":41401491}],"con":true,"img":false}]}
{"op":"mcm","clk":"11541557175","pt":1719507023562,"mc":[{"id":"1.230180135","rc":[{"atb":[[1.19,25.25]],"id":41401491}],"con":true,"img":false}]}
{"op":"mcm","clk":"11541557188","pt":1719507023616,"mc":[{"id":"1.230180135","rc":[{"atb":[[1.21,75.91]],"id":41401491}],"con":true,"img":false}]}
{"op":"mcm","clk":"11541557196","pt":1719507023775,"mc":[{"id":"1.230180135","rc":[{"atl":[[12,12.92],[13.5,0]],"id":69176457}],"con":true,"img":false}]}
{"op":"mcm","clk":"11541557208","pt":1719507023931,"mc":[{"id":"1.230180135","rc":[{"atl":[[10.5,0.84]],"id":69176457}],"con":true,"img":false}]}
{"op":"mcm","clk":"11541557228","pt":1719507024238,"mc":[{"id":"1.230180135","rc":[{"atb":[[1.21,81.45]],"id":41401491}],"con":true,"img":false}]}
{"op":"mcm","clk":"11541557238","pt":1719507024342,"mc":[{"id":"1.230180135","rc":[{"atb":[[1.21,6.24]],"id":4065261},{"atl":[[10.5,10.36],[11.5,0]],"id":69176457}],"con":true,"img":false}]}
{"op":"mcm","clk":"11541557262","pt":1719507024656,"mc":[{"id":"1.230180135","rc":[{"atb":[[1.21,6]],"id":69176457}],"con":true,"img":false}]}
{"op":"mcm","clk":"11541557282","pt":1719507024965,"mc":[{"id":"1.230180135","rc":[{"atb":[[1.21,1]],"id":4065261},{"atl":[[10,11.98],[13,0]],"id":69176457}],"con":true,"img":false}]}
{"op":"mcm","clk":"11541557313","pt":1719507025335,"mc":[{"id":"1.230180135","rc":[{"atl":[[11,12.95],[12,11.92]],"id":69176457}],"con":true,"img":false}]}
{"op":"mcm","clk":"11541557324","pt":1719507025433,"mc":[{"id":"1.230180135","rc":[{"atb":[[1.21,1]],"id":69176457}],"con":true,"img":false}]}
{"op":"mcm","clk":"11541557330","pt":1719507025536,"mc":[{"id":"1.230180135","rc":[{"atl":[[10,43.87],[9.8,13.43]],"id":41401491},{"atl":[[32,0],[27,6.74]],"id":4065261}],"con":true,"img":false}]}
{"op":"mcm","clk":"11541557337","pt":1719507025638,"mc":[{"id":"1.230180135","rc":[{"atl":[[9.6,11.63]],"id":41401491},{"atl":[[26,4],[28,0]],"id":4065261}],"con":true,"img":false}]}
{"op":"mcm","clk":"11541557347","pt":1719507025741,"mc":[{"id":"1.230180135","rc":[{"atl":[[10,32.76]],"id":41401491}],"con":true,"img":false}]}
{"op":"mcm","clk":"11541557358","pt":1719507025851,"mc":[{"id":"1.230180135","rc":[{"atl":[[12.5,0],[9.4,12.59]],"id":41401491},{"atl":[[26,9.9],[29,1.84]],"id":4065261}],"con":true,"img":false}]}
{"op":"mcm","clk":"11541557368","pt":1719507025952,"mc":[{"id":"1.230180135","rc":[{"atb":[[1.21,75.91]],"id":41401491},{"atl":[[10,33.76],[10.5,12.6]],"id":41401491},{"atl":[[28,1],[29,0]],"id":4065261}],"con":true,"img":false}]}
{"op":"mcm","clk":"11541557376","pt":1719507026056,"mc":[{"id":"1.230180135","rc":[{"atl":[[9.6,0],[9.2,12.2],[9.8,14.43]],"id":41401491}],"con":true,"img":false}]}
{"op":"mcm","clk":"11541557384","pt":1719507026154,"mc":[{"id":"1.230180135","rc":[{"atl":[[10,32.76]],"id":41401491}],"con":true,"img":false}]}
{"op":"mcm","clk":"11541557401","pt":1719507026359,"mc":[{"id":"1.230180135","rc":[{"atl":[[9.6,1],[9.8,13.43]],"id":41401491}],"con":true,"img":false}]}
{"op":"mcm","clk":"11541557408","pt":1719507026464,"mc":[{"id":"1.230180135","rc":[{"atl":[[9,13.44],[10.5,0],[9.8,12.58]],"id":41401491},{"atl":[[25,0.84]],"id":4065261}],"con":true,"img":false}]}
{"op":"mcm","clk":"11541557414","pt":1719507026577,"mc":[{"id":"1.230180135","rc":[{"atl":[[9.2,0],[8.8,12.6]],"id":41401491}],"con":true,"img":false}]}
{"op":"mcm","clk":"11541557422","pt":1719507026620,"mc":[{"id":"1.230180135","rc":[{"atl":[[25,6.83]],"id":4065261}],"con":true,"img":false}]}
{"op":"mcm","clk":"11541557430","pt":1719507026726,"mc":[{"id":"1.230180135","rc":[{"atl":[[24,4.35],[26,5.9]],"id":4065261}],"con":true,"img":false}]}
{"op":"mcm","clk":"11541557454","pt":1719507027035,"mc":[{"id":"1.230180135","rc":[{"atl":[[27,5.9]],"id":4065261},{"atb":[[1.19,6.12]],"id":65040144}],"con":true,"img":false}]}
{"op":"mcm","clk":"11541557464","pt":1719507027135,"mc":[{"id":"1.230180135","rc":[{"atl":[[8.6,12.64],[9.8,0]],"id":41401491},{"atl":[[24,10.33],[27,0]],"id":4065261}],"con":true,"img":false}]}
{"op":"mcm","clk":"11541557473","pt":1719507027240,"mc":[{"id":"1.230180135","rc":[{"atl":[[26,6.9],[28,0]],"id":4065261},{"atb":[[1.21,6.75]],"id":65040144}],"con":true,"img":false}]}
{"op":"mcm","clk":"11541557491","pt":1719507027445,"mc":[{"id":"1.230180135","rc":[{"atb":[[1.19,0]],"id":65040144}],"con":true,"img":false}]}
{"op":"mcm","clk":"11541557531","pt":1719507027960,"mc":[{"id":"1.230180135","rc":[{"atl":[[9,12.59]],"id":41401491}],"con":true,"img":false}]}
{"op":"mcm","clk":"11541557538","pt":1719507028060,"mc":[{"id":"1.230180135","rc":[{"atb":[[1.22,0]],"id":69176457}],"con":true,"img":false}]}
{"op":"mcm","clk":"11541557556","pt":1719507028371,"mc":[{"id":"1.230180135","rc":[{"atl":[[10,25.17]],"id":41401491}],"con":true,"img":false}]}
{"op":"mcm","clk":"11541557567","pt":1719507028527,"mc":[{"id":"1.230180135","rc":[{"atl":[[8.6,21.63]],"id":41401491}],"con":true,"img":false}]}
{"op":"mcm","clk":"11541557572","pt":1719507028630,"mc":[{"id":"1.230180135","rc":[{"atb":[[1.99,6.16]],"id":52032624}],"con":true,"img":false}]}
{"op":"mcm","clk":"11541557604","pt":1719507028842,"mc":[{"id":"1.230180135","rc":[{"atb":[[1.21,5.37]],"id":4065261}],"con":true,"img":false}]}
{"op":"mcm","clk":"11541557652","pt":1719507029562,"mc":[{"id":"1.230180135","rc":[{"atb":[[1.21,1]],"id":4065261},{"atl":[[10.5,0.84],[9.8,11.36]],"id":69176457}],"con":true,"img":false}]}
{"op":"mcm","clk":"11541557677","pt":1719507029931,"mc":[{"id":"1.230180135","rc":[{"atl":[[10.5,1],[11,11.95]],"id":69176457}],"con":true,"img":false}]}
{"op":"mcm","clk":"11541557720","pt":1719507030754,"mc":[{"id":"1.230180135","rc":[{"atl":[[8.4,12.62],[9.4,0]],"id":41401491}],"con":true,"img":false}]}
{"op":"mcm","clk":"11541557732","pt":1719507030962,"mc":[{"id":"1.230180135","rc":[{"atl":[[9.6,0],[8.8,13.6]],"id":41401491}],"con":true,"img":false}]}
{"op":"mcm","clk":"11541557751","pt":1719507031272,"mc":[{"id":"1.230180135","rc":[{"atb":[[1.19,39.63]],"id":41401491}],"con":true,"img":false}]}
{"op":"mcm","clk":"11541557762","pt":1719507031434,"mc":[{"id":"1.230180135","rc":[{"atl":[[9.6,0.84]],"id":69176457}],"con":true,"img":false}]}
{"op":"mcm","clk":"11541557769","pt":1719507031534,"mc":[{"id":"1.230180135","rc":[{"atb":[[1.2,23.01]],"id":69176457}],"con":true,"img":false}]}
{"op":"mcm","clk":"11541557779","pt":1719507031641,"mc":[{"id":"1.230180135","rc":[{"atl":[[8.2,13.6],[8.8,1]],"id":41401491},{"atb":[[1.97,13.78]],"id":52032624}],"con":true,"img":false}]}
{"op":"mcm","clk":"11541557828","pt":1719507032251,"mc":[{"id":"1.230180135","rc":[{"atl":[[9.6,12.85],[9.8,35.38]],"id":69176457}],"con":true,"img":false}]}
{"op":"mcm","clk":"11541557834","pt":1719507032356,"mc":[{"id":"1.230180135","rc":[{"atl":[[12,0]],"id":69176457}],"con":true,"img":false}]}
{"op":"mcm","clk":"11541557840","pt":1719507032460,"mc":[{"id":"1.230180135","rc":[{"atl":[[8,12.62],[9,0]],"id":41401491}],"con":true,"img":false}]}
{"op":"mcm","clk":"11541557853","pt":1719507032665,"mc":[{"id":"1.230180135","rc":[{"atl":[[8.8,0],[8.4,13.62]],"id":41401491},{"atl":[[10,12.98],[10.5,0]],"id":69176457}],"con":true,"img":false}]}
{"op":"mcm","clk":"11541557885","pt":1719507033185,"mc":[{"id":"1.230180135","rc":[{"atl":[[8.6,12.64]],"id":41401491}],"con":true,"img":false}]}
{"op":"mcm","clk":"11541557896","pt":1719507033233,"mc":[{"id":"1.230180135","rc":[{"atl":[[8,22.37]],"id":41401491}],"con":true,"img":false}]}
{"op":"mcm","clk":"11541557909","pt":1719507033442,"mc":[{"id":"1.230180135","rc":[{"atl":[[8.6,0],[7.8,12.68]],"id":41401491}],"con":true,"img":false}]}
{"op":"mcm","clk":"11541557923","pt":1719507033646,"mc":[{"id":"1.230180135","rc":[{"atb":[[1.19,25.25]],"id":41401491}],"con":true,"img":false}]}
{"op":"mcm","clk":"11541557943","pt":1719507033957,"mc":[{"id":"1.230180135","rc":[{"atl":[[7.6,0.84]],"id":41401491},{"atl":[[23,0.84]],"id":4065261}],"con":true,"img":false}]}
{"op":"mcm","clk":"11541557978","pt":1719507034697,"mc":[{"id":"1.230180135","rc":[{"atl":[[9.8,24.02],[9.4,11.9]],"id":69176457}],"con":true,"img":false}]}
{"op":"mcm","clk":"11541558007","pt":1719507035052,"mc":[{"id":"1.230180135","rc":[{"atl":[[7.6,13.55]],"id":41401491},{"atl":[[23,6.86],[26,1]],"id":4065261},{"atl":[[9.2,12.06],[11,0]],"id":69176457}],"con":true,"img":false}]}
{"op":"mcm","clk":"11541558017","pt":1719507035150,"mc":[{"id":"1.230180135","rc":[{"atb":[[1.21,6.24]],"id":4065261},{"atl":[[22,4.76]],"id":4065261}],"con":true,"img":false}]}
{"op":"mcm","clk":"11541558022","pt":1719507035254,"mc":[{"id":"1.230180135","rc":[{"atl":[[24,5.98]],"id":4065261}],"con":true,"img":false}]}
{"op":"mcm","clk":"11541558030","pt":1719507035357,"mc":[{"id":"1.230180135","rc":[{"atl":[[22,10.77],[25,0.84]],"id":4065261}],"con":true,"img":false}]}
{"op":"mcm","clk":"11541558039","pt":1719507035462,"mc":[{"id":"1.230180135","rc":[{"atb":[[1.21,1]],"id":4065261}],"con":true,"img":false}]}
{"op":"mcm","clk":"11541558045","pt":1719507035566,"mc":[{"id":"1.230180135","rc":[{"atl":[[25,0]],"id":4065261},{"atl":[[9.6,12.01]],"id":69176457}],"con":true,"img":false}]}
{"op":"mcm","clk":"11541558101","pt":1719507036347,"mc":[{"id":"1.230180135","rc":[{"atb":[[1.2,21.76],[1.21,6]],"id":69176457}],"con":true,"img":false}]}
{"op":"mcm","clk":"11541558128","pt":1719507036759,"mc":[{"id":"1.230180135","rc":[{"atl":[[8.2,0],[7.4,13.55]],"id":41401491}],"con":true,"img":false}]}
{"op":"mcm","clk":"11541558143","pt":1719507037070,"mc":[{"id":"1.230180135","rc":[{"atl":[[7.8,13.68],[8.4,12.62]],"id":41401491},{"atl":[[24,6.98],[26,0]],"id":4065261},{"atl":[[9.6,13.01],[10,11.98]],"id":69176457}],"con":true,"img":false}]}
{"op":"mcm","clk":"11541558174","pt":1719507037642,"mc":[{"id":"1.230180135","rc":[{"atb":[[1.19,8.62]],"id":65040144}],"con":true,"img":false}]}
{"op":"mcm","clk":"11541558192","pt":1719507037855,"mc":[{"id":"1.230180135","rc":[{"atb":[[1.19,6.11]],"id":65040144}],"con":true,"img":false}]}
{"op":"mcm","clk":"11541558202","pt":1719507037951,"mc":[{"id":"1.230180135","rc":[{"atl":[[7.2,12.72],[8.4,0]],"id":41401491}],"con":true,"img":false}]}
{"op":"mcm","clk":"11541558210","pt":1719507038058,"mc":[{"id":"1.230180135","rc":[{"atl":[[8,12.62],[7.4,0],[7,13.55]],"id":41401491}],"con":true,"img":false}]}
{"op":"mcm","clk":"11541558221","pt":1719507038262,"mc":[{"id":"1.230180135","rc":[{"atl":[[7.4,10.67]],"id":41401491}],"con":true,"img":false}]}
{"op":"mcm","clk":"11541558236","pt":1719507038468,"mc":[{"id":"1.230180135","rc":[{"atl":[[7.6,12.7]],"id":41401491},{"atl":[[9,0.84]],"id":69176457}],"con":true,"img":false}]}
{"op":"mcm","clk":"11541558263","pt":1719507038881,"mc":[{"id":"1.230180135","rc":[{"atl":[[9,12.89]],"id":69176457}],"con":true,"img":false}]}
{"op":"mcm","clk":"11541558271","pt":1719507038983,"mc":[{"id":"1.230180135","rc":[{"atl":[[10,0]],"id":69176457}],"con":true,"img":false}]}
{"op":"mcm","clk":"11541558275","pt":1719507039088,"mc":[{"id":"1.230180135","rc":[{"atl":[[8,0],[6.8,12.71]],"id":41401491}],"con":true,"img":false}]}
{"op":"mcm","clk":"11541558292","pt":1719507039245,"mc":[{"id":"1.230180135","rc":[{"atl":[[7,0],[6.6,12.72]],"id":41401491},{"atl":[[9.6,12.01],[9.4,12.9]],"id":69176457}],"con":true,"img":false}]}
{"op":"mcm","clk":"11541558307","pt":1719507039451,"mc":[{"id":"1.230180135","rc":[{"atl":[[7.8,12.68],[7,1]],"id":41401491}],"con":true,"img":false}]}
{"op":"mcm","clk":"11541558328","pt":1719507039768,"mc":[{"id":"1.230180135","rc":[{"spn":3.91,"spf":"NaN","id":41401491},{"spn":38.51,"spf":"NaN","id":52032624},{"spn":11.61,"spf":"NaN","id":4065261},{"atl":[[8.8,12.82],[9.4,1]],"id":69176457},{"spn":5.01,"spf":1.0,"id":69176457}],"con":true,"img":false}]}
{"op":"mcm","clk":"11541558346","pt":1719507039864,"mc":[{"id":"1.230180135","rc":[{"atl":[[6.4,12.74],[7.8,0]],"id":41401491}],"con":true,"img":false}]}
{"op":"mcm","clk":"11541558385","pt":1719507040180,"mc":[{"id":"1.230180135","rc":[{"atl":[[6.8,13.71],[7,0]],"id":41401491},{"atl":[[9.2,13.06],[9.4,0]],"id":69176457}],"con":true,"img":false}]}
{"op":"mcm","clk":"11541558402","pt":1719507040383,"mc":[{"id":"1.230180135","rc":[{"atb":[[1.21,5.37]],"id":4065261}],"con":true,"img":false}]}
{"op":"mcm","clk":"11541558411","pt":1719507040489,"mc":[{"id":"1.230180135","rc":[{"atb":[[1.21,81.45]],"id":41401491}],"con":true,"img":false}]}
{"op":"mcm","clk":"11541558415","pt":1719507040543,"mc":[{"id":"1.230180135","rc":[{"atb":[[1.21,75.91]],"id":41401491}],"con":true,"img":false}]}
{"op":"mcm","clk":"11541558423","pt":1719507040649,"mc":[{"id":"1.230180135","rc":[{"atb":[[1.23,13.84]],"id":4065261},{"atl":[[22,18.65]],"id":4065261},{"atl":[[9.6,0],[8.6,12.09]],"id":69176457}],"con":true,"img":false}]}
{"op":"mcm","clk":"11541558430","pt":1719507040750,"mc":[{"id":"1.230180135","rc":[{"atb":[[1.23,20.72]],"id":41401491},{"atl":[[6.4,20.62]],"id":41401491},{"atb":[[2.02,12.42]],"id":52032624},{"atl":[[75,11.28]],"id":52032624},{"atb":[[1.23,20.02]],"id":69176457},{"atl":[[8.8,20.7]],"id":69176457},{"atb":[[1.23,12.44]],"id":65040144},{"atl":[[46,14.62]],"id":65040144}],"con":true,"img":false}]}
{"op":"mcm","clk":"11541558440","pt":1719507040857,"mc":[{"id":"1.230180135","rc":[{"atb":[[1.21,1]],"id":4065261},{"atl":[[8.8,7.88],[8.4,12.82]],"id":69176457}],"con":true,"img":false}]}
{"op":"mcm","clk":"11541558497","pt":1719507041470,"mc":[{"id":"1.230180135","rc":[{"atl":[[6.2,0.84]],"id":41401491},{"atl":[[21,0.84]],"id":4065261},{"atl":[[9,12.04],[8.8,0]],"id":69176457}],"con":true,"img":false}]}
{"op":"mcm","clk":"11541558501","pt":1719507041573,"mc":[{"id":"1.230180135","rc":[{"atl":[[8.4,20.7]],"id":69176457}],"con":true,"img":false}]}
{"op":"mcm","clk":"11541558534","pt":1719507041995,"mc":[{"id":"1.230180135","rc":[{"atb":[[1.99,5.66]],"id":52032624},{"atb":[[1.2,23.01]],"id":69176457}],"con":true,"img":false}]}
{"op":"mcm","clk":"11541558563","pt":1719507042354,"mc":[{"id":"1.230180135","rc":[{"atb":[[1.24,4.39]],"id":65040144}],"con":true,"img":false}]}
{"op":"mcm","clk":"11541558570","pt":1719507042457,"mc":[{"id":"1.230180135","rc":[{"atl":[[6.4,12.74]],"id":41401491},{"atl":[[22,10.77]],"id":4065261}],"con":true,"img":false}]}
{"op":"mcm","clk":"11541558578","pt":1719507042561,"mc":[{"id":"1.230180135","rc":[{"atl":[[6.2,8.72]],"id":41401491},{"atl":[[21,8.72]],"id":4065261}],"con":true,"img":false}]}
{"op":"mcm","clk":"11541558584","pt":1719507042664,"mc":[{"id":"1.230180135","rc":[{"atb":[[1.19,39.63]],"id":41401491},{"atl":[[20,5.26],[22,6.01]],"id":4065261},{"atb":[[1.21,5.75],[1.22,20.23]],"id":65040144}],"con":true,"img":false}]}
{"op":"mcm","clk":"11541558596","pt":1719507042871,"mc":[{"id":"1.230180135","rc":[{"atl":[[7.4,0]],"id":41401491},{"atb":[[2,11.84],[1.97,4.53]],"id":52032624},{"atb":[[1.19,0]],"id":65040144}],"con":true,"img":false}]}
{"op":"mcm","clk":"11541558605","pt":1719507042974,"mc":[{"id":"1.230180135","rc":[{"atl":[[23,6.01]],"id":4065261},{"atb":[[1.21,1]],"id":69176457}],"con":true,"img":false}]}
{"op":"mcm","clk":"11541558612","pt":1719507043078,"mc":[{"id":"1.230180135","rc":[{"atl":[[6.4,25.38]],"id":41401491},{"atb":[[2.02,33.44]],"id":52032624},{"atb":[[1.21,0]],"id":65040144}],"con":true,"img":false}]}
{"op":"mcm","clk":"11541558633","pt":1719507043391,"mc":[{"id":"1.230180135","rc":[{"atb":[[1.24,12.87]],"id":41401491},{"atl":[[19.5,6.01],[21,20.76],[24,1]],"id":4065261},{"atb":[[1.24,12.21]],"id":69176457}],"con":true,"img":false}]}
{"op":"mcm","clk":"11541558643","pt":1719507043492,"mc":[{"id":"1.230180135","rc":[{"atb":[[2.04,4.53],[1.95,0]],"id":52032624},{"atb":[[1.24,6.04]],"id":4065261},{"atl":[[19,5.56],[20,0],[21,12.88]],"id":4065261},{"atb":[[1.23,4.56]],"id":65040144},{"atl":[[44,4.39]],"id":65040144}],"con":true,"img":false}]}
{"op":"mcm","clk":"11541558649","pt":1719507043546,"mc":[{"id":"1.230180135","rc":[{"atb":[[1.99,6.73]],"id":52032624},{"atl":[[20,7.88]],"id":4065261},{"atb":[[1.24,12.27]],"id":65040144},{"atl":[[42,2.44],[46,12.4]],"id":65040144}],"con":true,"img":false}]}
{"op":"mcm","clk":"11541558674","pt":1719507043860,"mc":[{"id":"1.230180135","rc":[{"atb":[[1.19,25.25]],"id":41401491},{"atb":[[1.2,12.39]],"id":69176457},{"atl":[[42,6.84],[46,7.88]],"id":65040144}],"con":true,"img":false}]}
{"op":"mcm","clk":"11541558682","pt":1719507043964,"mc":[{"id":"1.230180135","rc":[{"spl":[[7.2,0.11],[6.4,0.12],[10,0.07],[6.2,0.06],[11.5,0.07],[6.8,0.11],[7.6,0.1],[6.6,0.12]],"id":41401491},{"atl":[[6,12.71]],"id":41401491},{"atb":[[1.99,1]],"id":52032624},{"spl":[[75,0.03],[19,0.02],[19.5,0.04],[20,0.04],[21,0.03],[22,0.03],[23,0.03],[24,0.03]],"id":4065261},{"atl":[[18.5,6.01],[21,12.03],[23,0]],"id":4065261},{"atl":[[8.2,12.07]],"id":69176457},{"atb":[[1.25,4.41]],"id":65040144},{"atl":[[40,0.84]],"id":65040144}],"con":true,"img":false}]}
{"op":"mcm","clk":"11541558686","pt":1719507044067,"mc":[{"id":"1.230180135","rc":[{"atl":[[7.6,0]],"id":41401491},{"atl":[[9.2,1]],"id":69176457}],"con":true,"img":false}]}
{"op":"mcm","clk":"11541558692","pt":1719507044174,"mc":[{"id":"1.230180135","rc":[{"atl":[[18,5.88],[19,0]],"id":4065261},{"atl":[[8,12.1]],"id":69176457}],"con":true,"img":false}]}
{"op":"mcm","clk":"11541558696","pt":1719507044275,"mc":[{"id":"1.230180135","rc":[{"atl":[[8.4,7.88]],"id":69176457}],"con":true,"img":false}]}
{"op":"mcm","clk":"11541558704","pt":1719507044377,"mc":[{"id":"1.230180135","rc":[{"atl":[[6.6,0],[5.9,12.72]],"id":41401491}],"con":true,"img":false}]}
{"op":"mcm","clk":"11541558712","pt":1719507044480,"mc":[{"id":"1.230180135","rc":[{"atb":[[1.21,74.91],[1.22,20.23]],"id":41401491},{"atl":[[6.4,26.38],[6.8,12.71]],"id":41401491},{"atb":[[1.23,5.96]],"id":4065261},{"atl":[[20,0]],"id":4065261},{"atb":[[1.21,0],[1.23,12.14],[1.22,1]],"id":69176457},{"atl":[[9.2,0],[8.4,8.88]],"id":69176457},{"atb":[[1.22,25.98]],"id":65040144}],"con":true,"img":false}]}
{"op":"mcm","clk":"11541558720","pt":1719507044582,"mc":[{"id":"1.230180135","rc":[{"atb":[[1.23,12.84]],"id":41401491},{"atl":[[6.2,0.84]],"id":41401491},{"atb":[[2.02,25.56]],"id":52032624},{"atb":[[1.24,13.92]],"id":4065261},{"atl":[[18.5,13.89]],"id":4065261},{"atb":[[1.24,20.09]],"id":69176457},{"atl":[[8.4,1]],"id":69176457},{"atb":[[1.24,4.39]],"id":65040144},{"atl":[[46,0]],"id":65040144}],"con":true,"img":false}]}
{"op":"mcm","clk":"11541558724","pt":1719507044688,"mc":[{"id":"1.230180135","rc":[{"atb":[[1.24,20.75]],"id":41401491},{"atl":[[6,20.59]],"id":41401491},{"atb":[[2.04,12.41]],"id":52032624},{"atl":[[8.2,19.96]],"id":69176457},{"atb":[[1.25,12.29]],"id":65040144},{"atl":[[40,8.72]],"id":65040144}],"con":true,"img":false}]}
{"op":"mcm","clk":"11541558732","pt":1719507044792,"mc":[{"id":"1.230180135","rc":[{"atl":[[38,2.7],[42,4.4]],"id":65040144}],"con":true,"img":false}]}
{"op":"mcm","clk":"11541558756","pt":1719507044997,"mc":[{"id":"1.230180135","rc":[{"atl":[[6.2,0]],"id":41401491}],"con":true,"img":false}]}
{"op":"mcm","clk":"11541558763","pt":1719507045101,"mc":[{"id":"1.230180135","rc":[{"atl":[[7.2,0],[6.4,25.38],[5.8,12.74],[6.2,1]],"id":41401491},{"atb":[[2,22.72],[2.06,4.53],[1.97,0]],"id":52032624},{"atb":[[1.25,6.04]],"id":4065261},{"atb":[[1.25,12.2]],"id":69176457},{"atb":[[1.2,0.25],[1.26,4.41]],"id":65040144}],"con":true,"img":false}]}
{"op":"mcm","clk":"11541558772","pt":1719507045164,"mc":[{"id":"1.230180135","rc":[{"atb":[[1.25,12.8]],"id":41401491},{"atb":[[2,23.72],[1.99,0]],"id":52032624},{"atb":[[1.21,0],[1.22,20.23]],"id":4065261},{"atl":[[17.5,6.01],[19,1],[22,0],[24,0]],"id":4065261},{"atl":[[7.8,12.1]],"id":69176457},{"atb":[[1.23,5.56],[1.22,24.98]],"id":65040144},{"atl":[[38,7.09],[42,5.4],[44,0],[50,0]],"id":65040144}],"con":true,"img":false}]}
{"op":"mcm","clk":"11541558782","pt":1719507045260,"mc":[{"id":"1.230180135","rc":[{"atl":[[6.2,0],[6,21.59]],"id":41401491},{"atb":[[2,12.84],[2.02,26.56]],"id":52032624},{"atb":[[1.23,6.96]],"id":4065261},{"atb":[[1.24,5.39]],"id":65040144}],"con":true,"img":false}]}
{"op":"mcm","clk":"11541558792","pt":1719507045362,"mc":[{"id":"1.230180135","rc":[{"atl":[[18.5,14.89]],"id":4065261},{"atb":[[1.23,13.14],[1.22,0]],"id":69176457},{"atl":[[8.2,20.96],[8.4,0]],"id":69176457}],"con":true,"img":false}]}
{"op":"mcm","clk":"11541558801","pt":1719507045465,"mc":[{"id":"1.230180135","rc":[{"atb":[[2,11.84]],"id":52032624},{"atb":[[1.22,19.23]],"id":4065261},{"atl":[[19,0]],"id":4065261},{"atl":[[7.8,12.95]],"id":69176457},{"atb":[[1.23,4.56]],"id":65040144}],"con":true,"img":false}]}
{"op":"mcm","clk":"11541558808","pt":1719507045568,"mc":[{"id":"1.230180135","rc":[{"atl":[[6,13.71]],"id":41401491},{"atl":[[18.5,7.01]],"id":4065261},{"atl":[[8.2,13.07]],"id":69176457},{"atb":[[1.22,19.23]],"id":65040144},{"atl":[[40,0.84]],"id":65040144}],"con":true,"img":false}]}
{"op":"mcm","clk":"11541558812","pt":1719507045672,"mc":[{"id":"1.230180135","rc":[{"atl":[[5.9,20.6]],"id":41401491},{"atl":[[18,13.76]],"id":4065261},{"atl":[[8,19.98]],"id":69176457},{"atl":[[38,14.97]],"id":65040144}],"con":true,"img":false}]}
{"op":"mcm","clk":"11541558835","pt":1719507045983,"mc":[{"id":"1.230180135","rc":[{"atl":[[36,4.38],[42,1]],"id":65040144}],"con":true,"img":false}]}
{"op":"mcm","clk":"11541558860","pt":1719507046399,"mc":[{"id":"1.230180135","rc":[{"atb":[[1.22,25.33]],"id":4065261}],"con":true,"img":false}]}
{"op":"mcm","clk":"11541558871","pt":1719507046554,"mc":[{"id":"1.230180135","rc":[{"atb":[[1.24,12.87]],"id":41401491},{"atl":[[5.9,12.72]],"id":41401491},{"atb":[[2.04,4.53]],"id":52032624},{"atb":[[1.22,19.23],[1.24,6.04]],"id":4065261},{"atl":[[18,5.88]],"id":4065261},{"atb":[[1.24,12.21]],"id":69176457},{"atl":[[8,12.1]],"id":69176457},{"atb":[[1.25,4.41]],"id":65040144},{"atl":[[38,7.09],[40,0]],"id":65040144}],"con":true,"img":false}]}
{"op":"mcm","clk":"11541558877","pt":1719507046653,"mc":[{"id":"1.230180135","rc":[{"atb":[[1.25,20.68]],"id":41401491},{"atl":[[5.8,20.62]],"id":41401491},{"atb":[[2.06,12.41]],"id":52032624},{"atb":[[1.25,13.92]],"id":4065261},{"atl":[[17.5,13.89]],"id":4065261},{"atb":[[1.25,20.08]],"id":69176457},{"atl":[[7.8,20.83]],"id":69176457},{"atb":[[1.26,12.29]],"id":65040144},{"atl":[[36,12.26]],"id":65040144}],"con":true,"img":false}]}
{"op":"mcm","clk":"11541558953","pt":1719507047693,"mc":[{"id":"1.230180135","rc":[{"atl":[[6.4,12.74]],"id":41401491},{"atb":[[2.02,5.54]],"id":52032624}],"con":true,"img":false}]}
{"op":"mcm","clk":"11541558961","pt":1719507047796,"mc":[{"id":"1.230180135","rc":[{"atl":[[5.8,34.85]],"id":41401491},{"atb":[[2.06,33.43]],"id":52032624}],"con":true,"img":false}]}
{"op":"mcm","clk":"11541558999","pt":1719507048465,"mc":[{"id":"1.230180135","rc":[{"atl":[[6.8,0],[5.7,13.58]],"id":41401491},{"atb":[[1.98,0],[2.08,4.52]],"id":52032624},{"atb":[[1.19,0]],"id":4065261},{"atl":[[17,6.83],[19.5,0]],"id":4065261},{"atl":[[9,0],[7.6,12.16]],"id":69176457},{"atl":[[34,4.39],[38,2.7]],"id":65040144}],"con":true,"img":false}]}
{"op":"mcm","clk":"11541559007","pt":1719507048567,"mc":[{"id":"1.230180135","rc":[{"atb":[[1.26,12.86]],"id":41401491},{"atb":[[1.26,6.02]],"id":4065261}],"con":true,"img":false}]}
{"op":"mcm","clk":"11541559015","pt":1719507048672,"mc":[{"id":"1.230180135","rc":[{"atb":[[1.2,0.25]],"id":41401491},{"atb":[[1.2,0.25]],"id":4065261}],"con":true,"img":false}]}
{"op":"mcm","clk":"11541559021","pt":1719507048774,"mc":[{"id":"1.230180135","rc":[{"atb":[[1.21,46.7]],"id":41401491},{"atb":[[1.27,21.94]],"id":69176457},{"atb":[[1.23,16.06]],"id":65040144}],"con":true,"img":false}]}
{"op":"mcm","clk":"11541559034","pt":1719507048987,"mc":[{"id":"1.230180135","rc":[{"atb":[[1.23,11.5],[1.27,4.4]],"id":65040144}],"con":true,"img":false}]}
{"op":"mcm","clk":"11541559041","pt":1719507049082,"mc":[{"id":"1.230180135","rc":[{"atb":[[2,5.92]],"id":52032624}],"con":true,"img":false}]}
{"op":"mcm","clk":"11541559048","pt":1719507049191,"mc":[{"id":"1.230180135","rc":[{"atb":[[1.22,0]],"id":4065261}],"con":true,"img":false}]}
{"op":"mcm","clk":"11541559064","pt":1719507049392,"mc":[{"id":"1.230180135","rc":[{"atl":[[16.5,6.45],[18,0]],"id":4065261},{"atl":[[8,0],[7.4,12.17]],"id":69176457},{"atb":[[1.22,0]],"id":65040144}],"con":true,"img":false}]}
{"op":"mcm","clk":"11541559073","pt":1719507049496,"mc":[{"id":"1.230180135","rc":[{"atl":[[5.6,13.58],[6,12.71],[5.9,1]],"id":41401491},{"atb":[[2.02,4.54],[2.04,5.53]],"id":52032624},{"atl":[[7.8,12.95]],"id":69176457},{"atb":[[1.25,5.41],[1.09,0],[1.24,4.39]],"id":65040144},{"atl":[[38,3.7],[42,0]],"id":65040144}],"con":true,"img":false}]}
{"op":"mcm","clk":"11541559081","pt":1719507049608,"mc":[{"id":"1.230180135","rc":[{"atb":[[1.25,12.8]],"id":41401491},{"atl":[[5.8,26.97]],"id":41401491},{"atb":[[2.06,25.55]],"id":52032624},{"atb":[[1.25,6.04],[1.24,7.04]],"id":4065261},{"atl":[[17.5,7.01]],"id":4065261},{"atb":[[1.25,13.2]],"id":69176457},{"atl":[[7.6,20.05],[7.8,13.95]],"id":69176457},{"atb":[[1.26,4.41]],"id":65040144},{"atl":[[36,4.38]],"id":65040144}],"con":true,"img":false}]}
{"op":"mcm","clk":"11541559090","pt":1719507049701,"mc":[{"id":"1.230180135","rc":[{"atb":[[1.26,20.74],[1.22,1]],"id":41401491},{"atl":[[5.7,21.46]],"id":41401491},{"atb":[[2.08,12.4]],"id":52032624},{"atb":[[1.26,13.9],[1.23,5.96]],"id":4065261},{"atl":[[17,14.71],[18.5,6.01]],"id":4065261},{"atb":[[1.27,29.82],[1.23,12.14]],"id":69176457},{"atl":[[8.2,12.07]],"id":69176457},{"atb":[[1.27,12.28]],"id":65040144},{"atl":[[34,12.27]],"id":65040144}],"con":true,"img":false}]}
{"op":"mcm","clk":"11541559094","pt":1719507049760,"mc":[{"id":"1.230180135","rc":[{"atb":[[1.27,21.94]],"id":41401491},{"atl":[[16,5.98],[18.5,0]],"id":4065261},{"atb":[[1.28,12.3]],"id":69176457}],"con":true,"img":false}]}
{"op":"mcm","clk":"11541559102","pt":1719507049856,"mc":[{"id":"1.230180135","rc":[{"atb":[[1.2,0.25]],"id":69176457},{"atl":[[32,3.23],[38,1]],"id":65040144}],"con":true,"img":false}]}
{"op":"mcm","clk":"11541559108","pt":1719507049967,"mc":[{"id":"1.230180135","rc":[{"atb":[[2.12,5.28]],"id":52032624},{"atl":[[16.5,0],[15.5,6.45]],"id":4065261},{"atl":[[7.8,13.1]],"id":69176457}],"con":true,"img":false}]}
{"op":"mcm","clk":"11541559116","pt":1719507050067,"mc":[{"id":"1.230180135","rc":[{"atb":[[1.27,45.49]],"id":69176457}],"con":true,"img":false}]}
{"op":"mcm","clk":"11541559130","pt":1719507050273,"mc":[{"id":"1.230180135","rc":[{"atb":[[1.27,21.94]],"id":4065261}],"con":true,"img":false}]}
{"op":"mcm","clk":"11541559137","pt":1719507050382,"mc":[{"id":"1.230180135","rc":[{"atb":[[1.28,15.11]],"id":65040144}],"con":true,"img":false}]}
{"op":"mcm","clk":"11541559144","pt":1719507050482,"mc":[{"id":"1.230180135","rc":[{"atb":[[1.26,12.86]],"id":41401491},{"atl":[[5.7,13.58]],"id":41401491},{"atb":[[2.08,4.52]],"id":52032624},{"atl":[[17,5.98]],"id":4065261},{"atb":[[1.27,37.61]],"id":69176457},{"atl":[[7.6,12.16]],"id":69176457},{"atl":[[34,4.39]],"id":65040144}],"con":true,"img":false}]}
{"op":"mcm","clk":"11541559153","pt":1719507050579,"mc":[{"id":"1.230180135","rc":[{"atb":[[1.27,29.82]],"id":41401491},{"atl":[[5.6,21.46]],"id":41401491},{"atb":[[2.12,13.17]],"id":52032624},{"atb":[[1.27,37.61]],"id":4065261},{"atl":[[15,5.98],[15.5,14.33]],"id":4065261},{"atb":[[1.28,20.18]],"id":69176457},{"atl":[[7.4,20.05]],"id":69176457},{"atb":[[1.29,4.4],[1.24,0]],"id":65040144},{"atl":[[32,11.11]],"id":65040144}],"con":true,"img":false}]}
{"op":"mcm","clk":"11541559159","pt":1719507050688,"mc":[{"id":"1.230180135","rc":[{"atb":[[1.27,45.49]],"id":41401491},{"atl":[[14.5,5.99],[15.5,7.88]],"id":4065261}],"con":true,"img":false}]}
{"op":"mcm","clk":"11541559165","pt":1719507050785,"mc":[{"id":"1.230180135","rc":[{"atl":[[5.5,12.76]],"id":41401491},{"atb":[[1.28,6],[1.23,0]],"id":4065261},{"atl":[[7.2,12.19],[8.6,0]],"id":69176457},{"atb":[[1.23,0]],"id":65040144},{"atl":[[30,4.38]],"id":65040144}],"con":true,"img":false}]}
{"op":"mcm","clk":"11541559172","pt":1719507050893,"mc":[{"id":"1.230180135","rc":[{"atl":[[6.4,0],[5.4,13.58],[5.6,7.88]],"id":41401491},{"atl":[[7.4,7.88],[7,12.2]],"id":69176457},{"atb":[[1.28,36.27]],"id":65040144},{"atl":[[32,7.88],[29,3.57]],"id":65040144}],"con":true,"img":false}]}
{"op":"mcm","clk":"11541559178","pt":1719507050992,"mc":[{"id":"1.230180135","rc":[{"atl":[[30,5.22]],"id":65040144}],"con":true,"img":false}]}
{"op":"mcm","clk":"11541559214","pt":1719507051515,"mc":[{"id":"1.230180135","rc":[{"atl":[[5.7,12.73]],"id":41401491},{"atb":[[1.26,6.02]],"id":4065261},{"atl":[[15.5,0]],"id":4065261}],"con":true,"img":false}]}
{"op":"mcm","clk":"11541559221","pt":1719507051563,"mc":[{"id":"1.230180135","rc":[{"atl":[[5.6,0]],"id":41401491},{"atb":[[1.28,13.88]],"id":4065261},{"atl":[[14.5,13.87]],"id":4065261},{"atl":[[7.4,0]],"id":69176457},{"atb":[[1.27,4.4]],"id":65040144},{"atl":[[32,0]],"id":65040144}],"con":true,"img":false}]}
{"op":"mcm","clk":"11541559227","pt":1719507051664,"mc":[{"id":"1.230180135","rc":[{"atl":[[5.4,21.46]],"id":41401491},{"atl":[[7,20.08]],"id":69176457},{"atb":[[1.29,12.28]],"id":65040144},{"atl":[[29,11.45]],"id":65040144}],"con":true,"img":false}]}
{"op":"mcm","clk":"11541559245","pt":1719507051878,"mc":[{"id":"1.230180135","rc":[{"spl":[[32,0.02],[34,0.02],[36,0.02],[75,0.01],[38,0.02],[29,0.01],[30,0.02],[960,0.01]],"id":65040144}],"con":true,"img":false}]}
{"op":"mcm","clk":"11541559273","pt":1719507052283,"mc":[{"id":"1.230180135","rc":[{"atl":[[17.5,1],[14,5.97]],"id":4065261},{"atb":[[1.25,1],[1.3,4.4]],"id":65040144}],"con":true,"img":false}]}
{"op":"mcm","clk":"11541559278","pt":1719507052385,"mc":[{"id":"1.230180135","rc":[{"atb":[[1.21,25.68]],"id":41401491},{"atl":[[5.8,12.74],[5.3,12.77],[6,0]],"id":41401491},{"atb":[[2.06,4.53]],"id":52032624},{"atb":[[1.26,20.4],[1.29,6],[1.24,1]],"id":4065261},{"atl":[[13.5,5.99]],"id":4065261},{"atl":[[8.2,0],[6.8,12.2]],"id":69176457},{"atl":[[36,0],[28,4.38]],"id":65040144}],"con":true,"img":false}]}
{"op":"mcm","clk":"11541559284","pt":1719507052495,"mc":[{"id":"1.230180135","rc":[{"atb":[[1.27,66.51]],"id":41401491},{"atl":[[5.2,12.77],[5.4,23.4]],"id":41401491},{"atb":[[2.12,34.18]],"id":52032624},{"atb":[[1.27,58.63]],"id":4065261},{"atl":[[14.5,12.94]],"id":4065261},{"atb":[[1.27,58.63]],"id":69176457},{"atl":[[7,19.26],[6.6,12.21]],"id":69176457},{"atb":[[1.28,57.29]],"id":65040144},{"atl":[[27,3.85],[29,10.31]],"id":65040144}],"con":true,"img":false}]}
{"op":"mcm","clk":"11541559308","pt":1719507052808,"mc":[{"id":"1.230180135","rc":[{"atb":[[1.26,6.02]],"id":4065261}],"con":true,"img":false}]}
{"op":"mcm","clk":"11541559333","pt":1719507053010,"mc":[{"id":"1.230180135","rc":[{"atl":[[6.4,0.84]],"id":69176457},{"atl":[[30,4.38]],"id":65040144}],"con":true,"img":false}]}
{"op":"mcm","clk":"11541559377","pt":1719507053482,"mc":[{"id":"1.230180135","rc":[{"atl":[[5.4,15.52]],"id":41401491},{"atb":[[1.28,6]],"id":4065261},{"atl":[[14.5,5.05]],"id":4065261},{"atb":[[1.26,5]],"id":69176457},{"atl":[[7,11.38]],"id":69176457},{"atb":[[1.29,4.4]],"id":65040144},{"atl":[[29,2.43]],"id":65040144}],"con":true,"img":false}]}
{"op":"mcm","clk":"11541559387","pt":1719507053586,"mc":[{"id":"1.230180135","rc":[{"atb":[[1.25,22.42]],"id":41401491},{"atl":[[5.2,20.65]],"id":41401491},{"atb":[[1.29,13.88]],"id":4065261},{"atl":[[13.5,13.87]],"id":4065261},{"atl":[[6.4,8.72]],"id":69176457},{"atb":[[1.3,12.28]],"id":65040144},{"atl":[[27,11.73]],"id":65040144}],"con":true,"img":false}]}
{"op":"mcm","clk":"11541559395","pt":1719507053697,"mc":[{"id":"1.230180135","rc":[{"atl":[[5.8,0],[5.9,0],[5.4,16.52],[5.1,12.8]],"id":41401491},{"atb":[[2.04,4.53],[2.08,5.52]],"id":52032624},{"atb":[[1.27,59.63]],"id":4065261},{"atl":[[17,0],[13,5.97],[14.5,6.05]],"id":4065261},{"atb":[[1.25,12.2],[1.23,0],[1.29,12.23]],"id":69176457},{"atl":[[7.8,12.1]],"id":69176457},{"atb":[[1.28,58.29],[1.25,0]],"id":65040144},{"atl":[[34,0],[38,0],[27,16.11],[29,3.43]],"id":65040144}],"con":true,"img":false}]}
{"op":"mcm","clk":"11541559408","pt":1719507053795,"mc":[{"id":"1.230180135","rc":[{"atb":[[1.24,0]],"id":4065261},{"atl":[[17.5,0]],"id":4065261},{"atb":[[1.27,59.63],[1.26,6]],"id":69176457},{"atl":[[6.8,13.2]],"id":69176457}],"con":true,"img":false}]}
{"op":"mcm","clk":"11541559414","pt":1719507053899,"mc":[{"id":"1.230180135","rc":[{"atl":[[5.3,13.77],[5.4,15.52]],"id":41401491},{"atl":[[14,6.97],[14.5,5.05]],"id":4065261}],"con":true,"img":false}]}
{"op":"mcm","clk":"11541559422","pt":1719507054005,"mc":[{"id":"1.230180135","rc":[{"atb":[[1.26,0],[1.31,4.4]],"id":65040144}],"con":true,"img":false}]}
{"op":"mcm","clk":"11541559430","pt":1719507054108,"mc":[{"id":"1.230180135","rc":[{"atb":[[1.26,1]],"id":69176457}],"con":true,"img":false}]}
{"op":"mcm","clk":"11541559440","pt":1719507054211,"mc":[{"id":"1.230180135","rc":[{"atb":[[2.02,0],[2.14,4.45]],"id":52032624},{"atl":[[6.2,12.2],[6.6,36.62],[7.8,0]],"id":69176457},{"atl":[[26,4.39],[30,0]],"id":65040144}],"con":true,"img":false}]}
{"op":"mcm","clk":"11541559448","pt":1719507054315,"mc":[{"id":"1.230180135","rc":[{"atl":[[70,4.44]],"id":52032624},{"atb":[[1.26,0]],"id":69176457},{"atb":[[1.28,57.29],[1.29,5.4]],"id":65040144}],"con":true,"img":false}]}
{"op":"mcm","clk":"11541559453","pt":1719507054370,"mc":[{"id":"1.230180135","rc":[{"atb":[[2.1,1],[2.08,4.52]],"id":52032624},{"atl":[[6.8,12.2],[6.6,37.62]],"id":69176457},{"atl":[[28,5.38],[29,2.43]],"id":65040144}],"con":true,"img":false}]}
{"op":"mcm","clk":"11541559462","pt":1719507054479,"mc":[{"id":"1.230180135","rc":[{"atb":[[1.23,0]],"id":41401491},{"atl":[[5.2,12.77]],"id":41401491},{"atl":[[65,2],[75,9.28],[80,1],[85,0]],"id":52032624},{"atl":[[13.5,5.99]],"id":4065261},{"atb":[[1.28,12.3]],"id":69176457},{"atb":[[1.3,4.4]],"id":65040144}],"con":true,"img":false}]}
{"op":"mcm","clk":"11541559469","pt":1719507054576,"mc":[{"id":"1.230180135","rc":[{"atb":[[1.28,13.02]],"id":41401491},{"atl":[[5.1,20.68]],"id":41401491},{"atb":[[1.25,0],[1.3,6.05]],"id":4065261},{"atl":[[13,13.86]],"id":4065261},{"atb":[[1.29,20.11]],"id":69176457},{"atb":[[1.31,12.28]],"id":65040144}],"con":true,"img":false}]}
{"op":"mcm","clk":"11541559482","pt":1719507054791,"mc":[{"id":"1.230180135","rc":[{"atb":[[1.25,12.8]],"id":41401491},{"atl":[[75,10.28],[80,0]],"id":52032624},{"atb":[[1.28,7],[1.27,58.63]],"id":4065261}],"con":true,"img":false}]}
{"op":"mcm","clk":"11541559491","pt":1719507054889,"mc":[{"id":"1.230180135","rc":[{"atb":[[1.3,12.07],[1.24,0]],"id":69176457}],"con":true,"img":false}]}
{"op":"mcm","clk":"11541559496","pt":1719507054997,"mc":[{"id":"1.230180135","rc":[{"atl":[[5,12.84],[5.7,0]],"id":41401491},{"atl":[[65,6.43]],"id":52032624},{"atl":[[16,0],[12.5,6.01]],"id":4065261},{"atb":[[1.28,13.3],[1.27,58.63]],"id":69176457}],"con":true,"img":false}]}
{"op":"mcm","clk":"11541559511","pt":1719507055199,"mc":[{"id":"1.230180135","rc":[{"atl":[[14,5.97]],"id":4065261}],"con":true,"img":false}]}
{"op":"mcm","clk":"11541559517","pt":1719507055326,"mc":[{"id":"1.230180135","rc":[{"atl":[[5.3,12.77],[5.2,13.77]],"id":41401491},{"atl":[[13.5,6.99]],"id":4065261}],"con":true,"img":false}]}
{"op":"mcm","clk":"11541559531","pt":1719507055564,"mc":[{"id":"1.230180135","rc":[{"atl":[[5.1,12.8]],"id":41401491},{"atb":[[2.12,26.3]],"id":52032624},{"atl":[[75,2.4]],"id":52032624},{"atb":[[1.29,6]],"id":4065261},{"atl":[[13,5.97]],"id":4065261},{"atb":[[1.29,12.23]],"id":69176457},{"atl":[[6.4,0.84]],"id":69176457},{"atl":[[27,8.23]],"id":65040144}],"con":true,"img":false}]}
{"op":"mcm","clk":"11541559536","pt":1719507055675,"mc":[{"id":"1.230180135","rc":[{"atl":[[5,20.72]],"id":41401491},{"atb":[[2.14,12.33]],"id":52032624},{"atl":[[65,14.31]],"id":52032624},{"atb":[[1.3,13.93]],"id":4065261},{"atl":[[12.5,13.89]],"id":4065261},{"atb":[[1.3,19.96]],"id":69176457},{"atl":[[6.2,20.08]],"id":69176457},{"atl":[[26,12.27]],"id":65040144}],"con":true,"img":false}]}
{"op":"mcm","clk":"11541559544","pt":1719507055774,"mc":[{"id":"1.230180135","rc":[{"atb":[[2.1,10]],"id":52032624}],"con":true,"img":false}]}
{"op":"mcm","clk":"11541559549","pt":1719507055872,"mc":[{"id":"1.230180135","rc":[{"atl":[[4.9,12.84]],"id":41401491},{"atl":[[12,6.01],[15,0]],"id":4065261},{"atb":[[1.25,0],[1.31,11.91]],"id":69176457},{"atl":[[25,4.49],[28,1]],"id":65040144}],"con":true,"img":false}]}
{"op":"mcm","clk":"11541559555","pt":1719507055979,"mc":[{"id":"1.230180135","rc":[{"atl":[[5.5,0],[4.9,13.69]],"id":41401491},{"atb":[[2.04,0],[2.16,4.47]],"id":52032624},{"atl":[[70,0],[60,4.45]],"id":52032624},{"atl":[[12,6.86]],"id":4065261},{"atl":[[7.6,0],[6,11.81]],"id":69176457}],"con":true,"img":false}]}
{"op":"mcm","clk":"11541559567","pt":1719507056081,"mc":[{"id":"1.230180135","rc":[{"atl":[[5.1,13.8],[5.2,12.77]],"id":41401491},{"atl":[[65,12.31],[55,2]],"id":52032624},{"atl":[[13,6.97],[13.5,5.99]],"id":4065261}],"con":true,"img":false}]}
{"op":"mcm","clk":"11541559582","pt":1719507056289,"mc":[{"id":"1.230180135","rc":[{"atb":[[2.12,27.3],[2.1,9]],"id":52032624},{"atl":[[65,13.31],[75,1.4]],"id":52032624},{"atb":[[1.29,11.15]],"id":65040144}],"con":true,"img":false}]}
{"op":"mcm","clk":"11541559595","pt":1719507056497,"mc":[{"id":"1.230180135","rc":[{"atl":[[5,12.84]],"id":41401491},{"atl":[[12.5,6.01]],"id":4065261},{"atb":[[1.3,12.07]],"id":69176457},{"atl":[[6.4,0],[6.2,12.2]],"id":69176457}],"con":true,"img":false}]}
{"op":"mcm","clk":"11541559604","pt":1719507056608,"mc":[{"id":"1.230180135","rc":[{"atl":[[4.9,21.57]],"id":41401491},{"atb":[[2.14,4.45]],"id":52032624},{"atl":[[65,5.43]],"id":52032624},{"atl":[[12,14.74]],"id":4065261},{"atb":[[1.31,19.79]],"id":69176457},{"atl":[[6,19.69]],"id":69176457},{"atl":[[26,4.39]],"id":65040144}],"con":true,"img":false}]}
{"op":"mcm","clk":"11541559614","pt":1719507056707,"mc":[{"id":"1.230180135","rc":[{"atb":[[2.16,12.35]],"id":52032624},{"atl":[[60,12.33]],"id":52032624},{"atl":[[25,12.37]],"id":65040144}],"con":true,"img":false}]}
{"op":"mcm","clk":"11541559625","pt":1719507056812,"mc":[{"id":"1.230180135","rc":[{"atl":[[65,1],[55,6.46]],"id":52032624},{"atb":[[1.26,0],[1.31,6.04]],"id":4065261},{"atb":[[1.32,11.9]],"id":69176457},{"atb":[[1.27,0],[1.32,4.51]],"id":65040144}],"con":true,"img":false}]}
{"op":"mcm","clk":"11541559635","pt":1719507056922,"mc":[{"id":"1.230180135","rc":[{"atb":[[1.28,1]],"id":69176457},{"atl":[[27,9.23],[28,0]],"id":65040144}],"con":true,"img":false}]}
{"op":"mcm","clk":"11541559645","pt":1719507056978,"mc":[{"id":"1.230180135","rc":[{"atb":[[2.1,0]],"id":52032624},{"atb":[[1.28,6],[1.29,7]],"id":4065261},{"atl":[[6.4,1],[6.6,36.62]],"id":69176457},{"atb":[[1.3,5.4],[1.29,4.4]],"id":65040144}],"con":true,"img":false}]}
{"op":"mcm","clk":"11541559656","pt":1719507057071,"mc":[{"id":"1.230180135","rc":[{"atl":[[5.4,0]],"id":41401491},{"atb":[[2.12,6.28]],"id":52032624},{"atl":[[75,0.48]],"id":52032624},{"atl":[[14.5,0]],"id":4065261},{"atl":[[7,0]],"id":69176457},{"atl":[[29,0]],"id":65040144}],"con":true,"img":false}]}
{"op":"mcm","clk":"11541559677","pt":1719507057277,"mc":[{"id":"1.230180135","rc":[{"atl":[[4.9,39.08]],"id":41401491},{"atb":[[2.14,25.47]],"id":52032624},{"atl":[[55,7.73]],"id":52032624},{"atl":[[12,20.95]],"id":4065261},{"atl":[[6,33.35]],"id":69176457},{"atl":[[25,15.22]],"id":65040144}],"con":true,"img":false}]}
{"op":"mcm","clk":"11541559691","pt":1719507057482,"mc":[{"id":"1.230180135","rc":[{"atl":[[60,4.45]],"id":52032624},{"atb":[[1.3,6.05]],"id":4065261},{"atl":[[11.5,6.98],[13.5,0]],"id":4065261},{"atb":[[1.31,11.91]],"id":69176457},{"atb":[[1.31,4.4]],"id":65040144}],"con":true,"img":false}]}
{"op":"mcm","clk":"11541559698","pt":1719507057591,"mc":[{"id":"1.230180135","rc":[{"atl":[[4.9,52.88],[5.2,0]],"id":41401491},{"atl":[[55,15.61]],"id":52032624},{"atb":[[1.31,13.92]],"id":4065261},{"atl":[[11.5,12.99],[14,0]],"id":4065261},{"atb":[[1.32,19.78]],"id":69176457},{"atl":[[6.6,24.41],[5.9,12.21]],"id":69176457},{"atb":[[1.32,12.4]],"id":65040144},{"atl":[[24,4.35],[27,5.38]],"id":65040144}],"con":true,"img":false}]}
{"op":"mcm","clk":"11541559711","pt":1719507057893,"mc":[{"id":"1.230180135","rc":[{"atb":[[1.29,21.73]],"id":69176457}],"con":true,"img":false}]}
{"op":"mcm","clk":"11541559754","pt":1719507058460,"mc":[{"id":"1.230180135","rc":[{"atl":[[23,0.84]],"id":65040144}],"con":true,"img":false}]}
{"op":"mcm","clk":"11541559760","pt":1719507058572,"mc":[{"id":"1.230180135","rc":[{"atl":[[12,13.07]],"id":4065261},{"atl":[[6,25.47]],"id":69176457},{"atl":[[25,7.34]],"id":65040144}],"con":true,"img":false}]}
{"op":"mcm","clk":"11541559769","pt":1719507058712,"mc":[{"id":"1.230180135","rc":[{"atl":[[11.5,20.87]],"id":4065261},{"atl":[[5.9,20.09]],"id":69176457},{"atl":[[24,12.23]],"id":65040144}],"con":true,"img":false}]}
{"op":"mcm","clk":"11541559789","pt":1719507058979,"mc":[{"id":"1.230180135","rc":[{"atb":[[2.04,6.07]],"id":52032624}],"con":true,"img":false}]}
{"op":"mcm","clk":"11541559794","pt":1719507059095,"mc":[{"id":"1.230180135","rc":[{"atb":[[2.04,0]],"id":52032624}],"con":true,"img":false}]}
{"op":"mcm","clk":"11541559801","pt":1719507059198,"mc":[{"id":"1.230180135","rc":[{"atl":[[4.8,12.82],[5.3,0]],"id":41401491},{"atl":[[50,4.49],[60,0]],"id":52032624},{"atl":[[11,6.01],[13,1]],"id":4065261},{"atb":[[1.33,11.83],[1.29,9.5]],"id":69176457},{"atl":[[23,5.34],[24,21.22],[27,1]],"id":65040144}],"con":true,"img":false}]}
{"op":"mcm","clk":"11541559809","pt":1719507059287,"mc":[{"id":"1.230180135","rc":[{"atl":[[5,13.84]],"id":41401491},{"atb":[[1.28,0],[1.32,6.03]],"id":4065261},{"atl":[[12,14.07]],"id":4065261},{"atl":[[7.2,0],[5.8,11.75]],"id":69176457},{"atl":[[22,4.76],[24,16.87]],"id":65040144}],"con":true,"img":false}]}
{"op":"mcm","clk":"11541559815","pt":1719507059390,"mc":[{"id":"1.230180135","rc":[{"atl":[[5.1,12.8]],"id":41401491},{"atl":[[65,0],[60,1]],"id":52032624},{"atl":[[13,0]],"id":4065261},{"atb":[[1.29,0]],"id":69176457},{"atl":[[5.7,20.09],[5.9,7.88]],"id":69176457},{"atb":[[1.3,17.28]],"id":65040144},{"atl":[[25,8.34],[27,0]],"id":65040144}],"con":true,"img":false}]}
{"op":"mcm","clk":"11541559821","pt":1719507059503,"mc":[{"id":"1.230180135","rc":[{"atl":[[22,9.26],[24,8.99],[26,0]],"id":65040144}],"con":true,"img":false}]}
{"op":"mcm","clk":"11541559828","pt":1719507059596,"mc":[{"id":"1.230180135","rc":[{"atb":[[1.3,7.05],[1.29,6]],"id":4065261},{"atl":[[6.4,0],[5.9,8.88]],"id":69176457},{"atl":[[23,13.22],[24,9.99],[25,7.34]],"id":65040144}],"con":true,"img":false}]}
{"op":"mcm","clk":"11541559848","pt":1719507060007,"mc":[{"id":"1.230180135","rc":[{"atl":[[12,13.22]],"id":4065261}],"con":true,"img":false}]}
{"op":"mcm","clk":"11541559876","pt":1719507060473,"mc":[{"id":"1.230180135","rc":[{"atl":[[11.5,12.99]],"id":4065261},{"atl":[[5.6,0.84]],"id":69176457}],"con":true,"img":false}]}
{"op":"mcm","clk":"11541559884","pt":1719507060589,"mc":[{"id":"1.230180135","rc":[{"atl":[[4.9,45]],"id":41401491},{"atl":[[55,7.73]],"id":52032624},{"atb":[[1.31,6.04]],"id":4065261},{"atl":[[11,13.89]],"id":4065261},{"atb":[[1.32,11.9]],"id":69176457},{"atl":[[5.9,1]],"id":69176457},{"atl":[[23,5.34]],"id":65040144}],"con":true,"img":false}]}
{"op":"mcm","clk":"11541559895","pt":1719507060788,"mc":[{"id":"1.230180135","rc":[{"atl":[[4.8,20.7]],"id":41401491},{"atl":[[50,12.37]],"id":52032624},{"atb":[[1.32,13.91]],"id":4065261},{"atb":[[1.33,19.71]],"id":69176457},{"atl":[[5.7,27.97]],"id":69176457},{"atl":[[22,17.14]],"id":65040144}],"con":true,"img":false}]}
{"op":"mcm","clk":"11541559911","pt":1719507060988,"mc":[{"id":"1.230180135","rc":[{"atl":[[48,4.51],[55,3.26]],"id":52032624},{"atb":[[1.3,0],[1.34,11.85]],"id":69176457},{"atl":[[5.6,12.6],[5.8,12.75],[6.8,0],[9.8,0],[5.7,51.48],[5.9,0]],"id":69176457}],"con":true,"img":false}]}
{"op":"mcm","clk":"11541559914","pt":1719507061092,"mc":[{"id":"1.230180135","rc":[{"atl":[[5.1,0],[4.7,12.88]],"id":41401491},{"atb":[[1.33,5.97],[1.29,0]],"id":4065261},{"atl":[[21,4.5]],"id":65040144}],"con":true,"img":false}]}
{"op":"mcm","clk":"11541559921","pt":1719507061199,"mc":[{"id":"1.230180135","rc":[{"atl":[[46,2.22],[55,1.26]],"id":52032624}],"con":true,"img":false}]}
{"op":"mcm","clk":"11541559934","pt":1719507061406,"mc":[{"id":"1.230180135","rc":[{"atl":[[5,12.84],[4.9,46]],"id":41401491},{"atl":[[50,13.37],[60,0]],"id":52032624},{"atb":[[1.3,6.05],[1.31,7.04]],"id":4065261},{"atl":[[23,6.34],[24,8.99]],"id":65040144}],"con":true,"img":false}]}
{"op":"mcm","clk":"11541559940","pt":1719507061510,"mc":[{"id":"1.230180135","rc":[{"atl":[[4.9,45.15]],"id":41401491},{"atb":[[2.06,0],[2.18,4.53]],"id":52032624},{"atl":[[50,5.49]],"id":52032624},{"atb":[[1.33,4.52],[1.29,0]],"id":65040144},{"atl":[[23,5.49]],"id":65040144}],"con":true,"img":false}]}
{"op":"mcm","clk":"11541559947","pt":1719507061614,"mc":[{"id":"1.230180135","rc":[{"atl":[[48,12.39]],"id":52032624},{"atb":[[1.33,11.83]],"id":69176457},{"atl":[[5.7,43.6]],"id":69176457}],"con":true,"img":false}]}
{"op":"mcm","clk":"11541559954","pt":1719507061669,"mc":[{"id":"1.230180135","rc":[{"atb":[[1.34,19.74]],"id":69176457},{"atl":[[5.6,20.48]],"id":69176457},{"atb":[[1.3,5.4]],"id":65040144}],"con":true,"img":false}]}
{"op":"mcm","clk":"11541559961","pt":1719507061777,"mc":[{"id":"1.230180135","rc":[{"atb":[[2.12,5.28],[2.14,26.47]],"id":52032624},{"atb":[[1.3,4.4],[1.31,5.4]],"id":65040144}],"con":true,"img":false}]}
{"op":"mcm","clk":"11541559968","pt":1719507061876,"mc":[{"id":"1.230180135","rc":[{"atb":[[1.31,0],[1.35,11.84]],"id":69176457}],"con":true,"img":false}]}
{"op":"mcm","clk":"11541559999","pt":1719507062300,"mc":[{"id":"1.230180135","rc":[{"atl":[[46,6.73],[50,1]],"id":52032624},{"atl":[[10.5,5.94],[12.5,0]],"id":4065261}],"con":true,"img":false}]}
{"op":"mcm","clk":"11541560011","pt":1719507062393,"mc":[{"id":"1.230180135","rc":[{"atl":[[4.9,27.64]],"id":41401491},{"atb":[[2.14,5.45]],"id":52032624},{"atl":[[55,0]],"id":52032624},{"atl":[[12,7.01]],"id":4065261},{"atl":[[6.2,0],[5.5,11.65],[6,11.81]],"id":69176457},{"atl":[[25,4.49]],"id":65040144}],"con":true,"img":false}]}
{"op":"mcm","clk":"11541560020","pt":1719507062497,"mc":[{"id":"1.230180135","rc":[{"atl":[[11.5,13.99],[12,6.01]],"id":4065261}],"con":true,"img":false}]}
{"op":"mcm","clk":"11541560026","pt":1719507062600,"mc":[{"id":"1.230180135","rc":[{"atl":[[4.8,12.82],[4.7,31.35]],"id":41401491},{"atb":[[2.16,25.49]],"id":52032624},{"atl":[[46,8.25],[48,4.51]],"id":52032624},{"atb":[[1.32,6.03]],"id":4065261},{"atl":[[10,11.11],[11,20.72],[11.5,7.01]],"id":4065261},{"atb":[[1.34,11.85]],"id":69176457},{"atl":[[5.6,35.33]],"id":69176457},{"atb":[[1.32,4.51]],"id":65040144},{"atl":[[21,7.92],[22,9.26]],"id":65040144}],"con":true,"img":false}]}
{"op":"mcm","clk":"11541560037","pt":1719507062705,"mc":[{"id":"1.230180135","rc":[{"atl":[[4.7,39.23]],"id":41401491},{"atb":[[2.18,12.41]],"id":52032624},{"atl":[[46,16.13]],"id":52032624},{"atb":[[1.33,13.85]],"id":4065261},{"atb":[[1.35,19.72]],"id":69176457},{"atb":[[1.33,12.41]],"id":65040144},{"atl":[[21,15.8]],"id":65040144}],"con":true,"img":false}]}
{"op":"mcm","clk":"11541560051","pt":1719507062819,"mc":[{"id":"1.230180135","rc":[{"atb":[[1.31,22.66]],"id":4065261}],"con":true,"img":false}]}
{"op":"mcm","clk":"11541560064","pt":1719507062986,"mc":[{"id":"1.230180135","rc":[{"atl":[[44,4.52],[48,0]],"id":52032624},{"atb":[[1.3,0],[1.34,5.98]],"id":4065261},{"atl":[[11,21.72],[11.5,6.01]],"id":4065261},{"atl":[[5.8,11.75],[5.7,44.6]],"id":69176457},{"atb":[[1.3,0],[1.34,4.53]],"id":65040144}],"con":true,"img":false}]}
{"op":"mcm","clk":"11541560076","pt":1719507063093,"mc":[{"id":"1.230180135","rc":[{"atl":[[42,2.44],[46,13.91]],"id":52032624}],"con":true,"img":false}]}
{"op":"mcm","clk":"11541560084","pt":1719507063185,"mc":[{"id":"1.230180135","rc":[{"atl":[[48,1]],"id":52032624},{"atb":[[1.32,7.03],[1.31,21.66]],"id":4065261},{"atb":[[1.32,5.51],[1.31,4.4]],"id":65040144}],"con":true,"img":false}]}
{"op":"mcm","clk":"11541560091","pt":1719507063298,"mc":[{"id":"1.230180135","rc":[{"atl":[[50,0]],"id":52032624}],"con":true,"img":false}]}
{"op":"mcm","clk":"11541560100","pt":1719507063496,"mc":[{"id":"1.230180135","rc":[{"atl":[[4.6,0.84]],"id":41401491},{"atl":[[40,0.84]],"id":52032624},{"atl":[[9.8,0.84]],"id":4065261}],"con":true,"img":false}]}
{"op":"mcm","clk":"11541560106","pt":1719507063609,"mc":[{"id":"1.230180135","rc":[{"atl":[[46,6.03]],"id":52032624},{"atb":[[1.33,5.97],[1.31,6.04]],"id":4065261},{"atl":[[11,13.84]],"id":4065261},{"atl":[[5.6,27.45]],"id":69176457},{"atb":[[1.33,4.52]],"id":65040144}],"con":true,"img":false}]}
{"op":"mcm","clk":"11541560115","pt":1719507063702,"mc":[{"id":"1.230180135","rc":[{"atl":[[44,12.41]],"id":52032624},{"atb":[[1.34,13.86]],"id":4065261},{"atl":[[10,18.99]],"id":4065261},{"atl":[[5.5,19.54]],"id":69176457},{"atb":[[1.34,12.42]],"id":65040144}],"con":true,"img":false}]}
{"op":"mcm","clk":"11541560137","pt":1719507064011,"mc":[{"id":"1.230180135","rc":[{"atb":[[1.26,26.11]],"id":41401491}],"con":true,"img":false}]}
{"op":"mcm","clk":"11541560148","pt":1719507064121,"mc":[{"id":"1.230180135","rc":[{"spl":[[75,0.01],[40,0.01],[42,0.02],[44,0.01],[46,0.01],[48,0.01]],"id":52032624}],"con":true,"img":false}]}
{"op":"mcm","clk":"11541560159","pt":1719507064220,"mc":[{"id":"1.230180135","rc":[{"atl":[[4.6,13.87],[5,0]],"id":41401491},{"atb":[[1.31,0],[1.35,5.98]],"id":4065261},{"atl":[[6,0],[5.4,11.55]],"id":69176457}],"con":true,"img":false}]}
{"op":"mcm","clk":"11541560165","pt":1719507064325,"mc":[{"id":"1.230180135","rc":[{"atl":[[4.8,13.82],[4.9,26.64]],"id":41401491},{"atl":[[40,5.38],[44,13.41],[46,1.51],[48,0]],"id":52032624},{"atb":[[1.33,6.97],[1.32,6.03]],"id":4065261},{"atl":[[10.5,6.94],[11,12.84]],"id":4065261},{"atl":[[5.6,28.45],[5.7,43.6]],"id":69176457},{"atl":[[20,4.52]],"id":65040144}],"con":true,"img":false}]}
{"op":"mcm","clk":"11541560176","pt":1719507064428,"mc":[{"id":"1.230180135","rc":[{"atl":[[20,9.78],[22,4.5],[25,0]],"id":65040144}],"con":true,"img":false}]}
{"op":"mcm","clk":"11541560185","pt":1719507064489,"mc":[{"id":"1.230180135","rc":[{"atl":[[10,11.11]],"id":4065261},{"atl":[[5.3,19.54],[5.7,23.51]],"id":69176457}],"con":true,"img":false}]}
{"op":"mcm","clk":"11541560193","pt":1719507064596,"mc":[{"id":"1.230180135","rc":[{"atl":[[4.7,31.35]],"id":41401491},{"atl":[[44,5.52]],"id":52032624},{"atl":[[9.8,8.72]],"id":4065261},{"atl":[[19.5,4.52],[23,1]],"id":65040144}],"con":true,"img":false}]}
{"op":"mcm","clk":"11541560200","pt":1719507064688,"mc":[{"id":"1.230180135","rc":[{"atl":[[4.6,21.75]],"id":41401491},{"atl":[[40,13.26]],"id":52032624}],"con":true,"img":false}]}
{"op":"mcm","clk":"11541560209","pt":1719507064797,"mc":[{"id":"1.230180135","rc":[{"atl":[[19,5.56],[20,4.52]],"id":65040144}],"con":true,"img":false}]}
{"op":"mcm","clk":"11541560222","pt":1719507065011,"mc":[{"id":"1.230180135","rc":[{"atl":[[4.5,13.1],[4.9,13.8]],"id":41401491},{"atb":[[2.1,11.75]],"id":52032624},{"atb":[[1.36,11.7]],"id":69176457},{"atl":[[5.6,27.6]],"id":69176457}],"con":true,"img":false}]}
{"op":"mcm","clk":"11541560230","pt":1719507065103,"mc":[{"id":"1.230180135","rc":[{"atb":[[1.32,0]],"id":69176457},{"atl":[[20,5.52],[23,0]],"id":65040144}],"con":true,"img":false}]}
{"op":"mcm","clk":"11541560253","pt":1719507065424,"mc":[{"id":"1.230180135","rc":[{"atb":[[1.26,12.86]],"id":41401491},{"atb":[[2.08,0],[2.2,4.55]],"id":52032624},{"atl":[[9.6,5.89],[10,22.9],[12,0]],"id":4065261},{"atb":[[1.31,0],[1.35,4.54]],"id":65040144}],"con":true,"img":false}]}
{"op":"mcm","clk":"11541560261","pt":1719507065519,"mc":[{"id":"1.230180135","rc":[{"atl":[[4.8,12.82],[4.7,32.35]],"id":41401491},{"atl":[[38,4.53],[44,1]],"id":52032624},{"atl":[[5.6,26.6],[5.8,0],[5.5,20.54],[5.2,11.6]],"id":69176457},{"atl":[[18.5,5.37],[22,0]],"id":65040144}],"con":true,"img":false}]}
{"op":"mcm","clk":"11541560267","pt":1719507065575,"mc":[{"id":"1.230180135","rc":[{"atl":[[4.6,13.87]],"id":41401491},{"atb":[[1.34,5.98]],"id":4065261},{"atb":[[1.35,11.84]],"id":69176457},{"atl":[[5.5,12.65]],"id":69176457},{"atl":[[18,5.38],[19,0],[21,7.92]],"id":65040144}],"con":true,"img":false}]}
{"op":"mcm","clk":"11541560274","pt":1719507065678,"mc":[{"id":"1.230180135","rc":[{"atl":[[4.5,20.98]],"id":41401491},{"atb":[[1.35,13.86]],"id":4065261},{"atb":[[1.36,19.58]],"id":69176457},{"atl":[[5.3,27.42]],"id":69176457},{"atl":[[19,7.88]],"id":65040144}],"con":true,"img":false}]}
{"op":"mcm","clk":"11541560302","pt":1719507066091,"mc":[{"id":"1.230180135","rc":[{"atb":[[1.37,11.69],[1.33,0]],"id":69176457}],"con":true,"img":false}]}
{"op":"mcm","clk":"11541560310","pt":1719507066193,"mc":[{"id":"1.230180135","rc":[{"atl":[[4.4,13.13]],"id":41401491},{"atb":[[2.1,0]],"id":52032624},{"atl":[[17.5,4.52],[21,3.41]],"id":65040144}],"con":true,"img":false}]}
{"op":"mcm","clk":"11541560316","pt":1719507066306,"mc":[{"id":"1.230180135","rc":[{"atl":[[4.8,0]],"id":41401491},{"atb":[[2.16,26.49],[2.14,4.45]],"id":52032624},{"atl":[[42,3.44],[44,0]],"id":52032624},{"atl":[[10,23.9],[10.5,5.94]],"id":4065261},{"atl":[[5.5,11.65],[5.4,12.55]],"id":69176457},{"atb":[[1.33,5.52],[1.32,4.51]],"id":65040144},{"atl":[[19,8.88],[20,4.52]],"id":65040144}],"con":true,"img":false}]}
{"op":"mcm","clk":"11541560323","pt":1719507066400,"mc":[{"id":"1.230180135","rc":[{"atl":[[4.6,14.87],[4.7,31.35]],"id":41401491},{"atb":[[1.36,5.89]],"id":4065261},{"atl":[[18.5,6.37]],"id":65040144}],"con":true,"img":false}]}
{"op":"mcm","clk":"11541560331","pt":1719507066503,"mc":[{"id":"1.230180135","rc":[{"atl":[[40,5.38]],"id":52032624},{"atb":[[1.32,0]],"id":4065261},{"atl":[[9.8,0.84]],"id":4065261},{"atl":[[5.3,19.54]],"id":69176457},{"atb":[[1.34,4.53]],"id":65040144},{"atl":[[19,0]],"id":65040144}],"con":true,"img":false}]}
{"op":"mcm","clk":"11541560341","pt":1719507066618,"mc":[{"id":"1.230180135","rc":[{"atl":[[38,12.41]],"id":52032624},{"atb":[[1.33,5.97],[1.34,6.98]],"id":4065261},{"atl":[[9.6,13.77]],"id":4065261},{"atl":[[5.2,19.48]],"id":69176457},{"atb":[[1.35,12.42]],"id":65040144},{"atl":[[18,13.26]],"id":65040144}],"con":true,"img":false}]}
{"op":"mcm","clk":"11541560353","pt":1719507066831,"mc":[{"id":"1.230180135","rc":[{"atb":[[2.18,4.53]],"id":52032624},{"atb":[[1.36,4.52]],"id":65040144}],"con":true,"img":false}]}
{"op":"mcm","clk":"11541560362","pt":1719507066924,"mc":[{"id":"1.230180135","rc":[{"atb":[[2.2,12.43]],"id":52032624},{"atb":[[1.32,0]],"id":65040144}],"con":true,"img":false}]}
{"op":"mcm","clk":"11541560368","pt":1719507067026,"mc":[{"id":"1.230180135","rc":[{"atl":[[4.6,14.02]],"id":41401491},{"atl":[[11.5,0],[9.4,5.86]],"id":4065261},{"atl":[[5.6,14.84],[5.1,11.59]],"id":69176457},{"atl":[[18.5,5.52]],"id":65040144}],"con":true,"img":false}]}
{"op":"mcm","clk":"11541560376","pt":1719507067077,"mc":[{"id":"1.230180135","rc":[{"atb":[[2.22,4.56],[2.14,0]],"id":52032624},{"atl":[[10,22.9],[9.8,1.84]],"id":4065261},{"atb":[[1.34,5.53]],"id":65040144}],"con":true,"img":false}]}
{"op":"mcm","clk":"11541560382","pt":1719507067180,"mc":[{"id":"1.230180135","rc":[{"atb":[[1.33,4.52]],"id":65040144}],"con":true,"img":false}]}
{"op":"mcm","clk":"11541560393","pt":1719507067304,"mc":[{"id":"1.230180135","rc":[{"atl":[[4.7,12.88]],"id":41401491},{"atb":[[2.16,5.47]],"id":52032624},{"atl":[[46,0]],"id":52032624},{"atl":[[11,6.01]],"id":4065261},{"atl":[[5.6,0]],"id":69176457},{"atl":[[21,0]],"id":65040144}],"con":true,"img":false}]}
{"op":"mcm","clk":"11541560401","pt":1719507067397,"mc":[{"id":"1.230180135","rc":[{"atl":[[4.4,33.22]],"id":41401491},{"atb":[[2.18,25.1]],"id":52032624},{"atl":[[38,14.26]],"id":52032624},{"atl":[[9.6,21.72]],"id":4065261},{"atl":[[5.2,35.74]],"id":69176457},{"atl":[[17.5,8.66]],"id":65040144}],"con":true,"img":false}]}
{"op":"mcm","clk":"11541560411","pt":1719507067490,"mc":[{"id":"1.230180135","rc":[{"atl":[[4.5,13.1]],"id":41401491},{"atb":[[1.35,5.98]],"id":4065261},{"atl":[[9.6,13.83],[9.8,1]],"id":4065261},{"atb":[[1.36,11.7]],"id":69176457},{"atl":[[5.2,27.86]],"id":69176457},{"atb":[[1.33,10.27],[1.35,4.54]],"id":65040144},{"atl":[[18,5.38]],"id":65040144}],"con":true,"img":false}]}
{"op":"mcm","clk":"11541560420","pt":1719507067593,"mc":[{"id":"1.230180135","rc":[{"atl":[[4.4,41.1]],"id":41401491},{"atb":[[2.18,26.1],[2.16,4.47]],"id":52032624},{"atb":[[1.36,13.77]],"id":4065261},{"atl":[[9.4,13.75]],"id":4065261},{"atb":[[1.37,19.57]],"id":69176457},{"atl":[[5.1,19.47]],"id":69176457},{"atb":[[1.36,12.4]],"id":65040144},{"atl":[[17.5,16.55]],"id":65040144}],"con":true,"img":false}]}
{"op":"mcm","clk":"11541560424","pt":1719507067712,"mc":[{"id":"1.230180135","rc":[{"atl":[[10,11.79],[9.2,5.87]],"id":4065261},{"atb":[[1.33,4.52]],"id":65040144}],"con":true,"img":false}]}
{"op":"mcm","clk":"11541560437","pt":1719507067818,"mc":[{"id":"1.230180135","rc":[{"atl":[[4.3,13.4],[4.7,0]],"id":41401491},{"atb":[[1.37,5.87],[1.33,0]],"id":4065261},{"atb":[[1.38,11.63]],"id":69176457},{"atb":[[1.33,0]],"id":65040144}],"con":true,"img":false}]}
{"op":"mcm","clk":"11541560449","pt":1719507067910,"mc":[{"id":"1.230180135","rc":[{"atl":[[9.6,14.83],[9.8,0]],"id":4065261},{"atb":[[1.34,0]],"id":69176457},{"atb":[[1.37,4.51]],"id":65040144}],"con":true,"img":false}]}
{"op":"mcm","clk":"11541560462","pt":1719507068010,"mc":[{"id":"1.230180135","rc":[{"atl":[[36,4.53],[40,0.84]],"id":52032624},{"atb":[[1.35,19.47]],"id":69176457},{"atl":[[5,12.4],[5.5,0]],"id":69176457},{"atl":[[17,4.49],[20,0]],"id":65040144}],"con":true,"img":false}]}
{"op":"mcm","clk":"11541560489","pt":1719507068218,"mc":[{"id":"1.230180135","rc":[{"atl":[[4.5,14.1],[4.6,13.02]],"id":41401491},{"atl":[[34,3.03],[40,1.84],[42,0]],"id":52032624},{"atb":[[1.34,5.98],[1.35,6.98]],"id":4065261},{"atl":[[9,5.85],[11,0]],"id":4065261},{"atb":[[1.34,4.53],[1.35,5.54]],"id":65040144},{"atl":[[18,6.38],[18.5,4.52]],"id":65040144}],"con":true,"img":false}]}
{"op":"mcm","clk":"11541560509","pt":1719507068425,"mc":[{"id":"1.230180135","rc":[{"atl":[[34,7.56],[38,10.72],[40,0.84]],"id":52032624},{"atl":[[9.6,13.83],[9.4,14.75]],"id":4065261},{"atl":[[5.2,28.86],[5.4,11.55]],"id":69176457}],"con":true,"img":false}]}
{"op":"mcm","clk":"11541560520","pt":1719507068482,"mc":[{"id":"1.230180135","rc":[{"atl":[[40,0]],"id":52032624},{"atb":[[1.36,5.89]],"id":4065261},{"atl":[[5.1,11.59]],"id":69176457}],"con":true,"img":false}]}
{"op":"mcm","clk":"11541560527","pt":1719507068583,"mc":[{"id":"1.230180135","rc":[{"atl":[[4.4,33.22]],"id":41401491},{"atb":[[2.2,4.55]],"id":52032624},{"atl":[[38,2.84]],"id":52032624},{"atb":[[1.37,13.76],[1.29,6.98]],"id":4065261},{"atl":[[9.4,6.86]],"id":4065261},{"atb":[[1.37,11.69]],"id":69176457},{"atl":[[5,20.28]],"id":69176457},{"atb":[[1.36,4.52]],"id":65040144},{"atl":[[17.5,8.66]],"id":65040144}],"con":true,"img":false}]}
{"op":"mcm","clk":"11541560534","pt":1719507068687,"mc":[{"id":"1.230180135","rc":[{"atl":[[4.3,21.29]],"id":41401491},{"atb":[[2.22,12.44]],"id":52032624},{"atl":[[36,12.41]],"id":52032624},{"atl":[[9.2,13.75]],"id":4065261},{"atb":[[1.38,19.51]],"id":69176457},{"atb":[[1.37,12.39]],"id":65040144},{"atl":[[17,12.37]],"id":65040144}],"con":true,"img":false}]}
{"op":"mcm","clk":"11541560541","pt":1719507068787,"mc":[{"id":"1.230180135","rc":[{"atb":[[1.29,0]],"id":4065261}],"con":true,"img":false}]}
{"op":"mcm","clk":"11541560589","pt":1719507069520,"mc":[{"id":"1.230180135","rc":[{"atb":[[1.34,0],[1.38,5.9]],"id":4065261}],"con":true,"img":false}]}
{"op":"mcm","clk":"11541560597","pt":1719507069622,"mc":[{"id":"1.230180135","rc":[{"atl":[[4.2,13.36]],"id":41401491},{"atl":[[36,4.53]],"id":52032624},{"atl":[[9.2,5.87]],"id":4065261},{"atl":[[4.9,11.55],[5.4,0]],"id":69176457},{"atl":[[16.5,4.49]],"id":65040144}],"con":true,"img":false}]}
{"op":"mcm","clk":"11541560606","pt":1719507069723,"mc":[{"id":"1.230180135","rc":[{"atl":[[4.6,0]],"id":41401491},{"atl":[[34,15.45]],"id":52032624},{"atl":[[19.5,0]],"id":65040144}],"con":true,"img":false}]}
{"op":"mcm","clk":"11541560614","pt":1719507069816,"mc":[{"id":"1.230180135","rc":[{"atl":[[9,13.73]],"id":4065261}],"con":true,"img":false}]}
{"op":"mcm","clk":"11541560620","pt":1719507069920,"mc":[{"id":"1.230180135","rc":[{"atl":[[4.5,13.1],[4.4,34.22]],"id":41401491},{"atb":[[1.36,6.89],[1.35,5.98]],"id":4065261},{"atl":[[5.1,12.59],[5.2,27.86]],"id":69176457},{"atl":[[17.5,9.66],[18,5.38]],"id":65040144}],"con":true,"img":false}]}
{"op":"mcm","clk":"11541560637","pt":1719507070126,"mc":[{"id":"1.230180135","rc":[{"atb":[[2.1,5.86],[2.24,4.54],[2.16,0]],"id":52032624},{"atl":[[10.5,0],[8.8,5.83]],"id":4065261}],"con":true,"img":false}]}
{"op":"mcm","clk":"11541560661","pt":1719507070385,"mc":[{"id":"1.230180135","rc":[{"atl":[[32,4.53],[36,0]],"id":52032624},{"atb":[[1.35,15.29]],"id":65040144}],"con":true,"img":false}]}
{"op":"mcm","clk":"11541560670","pt":1719507070488,"mc":[{"id":"1.230180135","rc":[{"atl":[[4.1,0.84]],"id":41401491},{"atl":[[32,5.38]],"id":52032624},{"atl":[[8.6,0.84]],"id":4065261}],"con":true,"img":false}]}
{"op":"mcm","clk":"11541560678","pt":1719507070592,"mc":[{"id":"1.230180135","rc":[{"atl":[[4.3,13.4]],"id":41401491},{"atb":[[2.18,25.1],[2.2,5.55]],"id":52032624},{"atl":[[36,1],[38,1.84]],"id":52032624},{"atb":[[1.37,5.87]],"id":4065261},{"atl":[[9.2,6.87],[9.4,5.86]],"id":4065261},{"atl":[[5,12.4]],"id":69176457},{"atl":[[17,4.49]],"id":65040144}],"con":true,"img":false}]}
{"op":"mcm","clk":"11541560686","pt":1719507070697,"mc":[{"id":"1.230180135","rc":[{"atl":[[4.2,21.24]],"id":41401491},{"atb":[[1.38,13.78]],"id":4065261},{"atl":[[9,14.73],[9.2,5.87]],"id":4065261},{"atl":[[4.9,19.43]],"id":69176457},{"atl":[[16.5,12.37],[16,6.67],[18,0]],"id":65040144}],"con":true,"img":false}]}
{"op":"mcm","clk":"11541560698","pt":1719507070908,"mc":[{"id":"1.230180135","rc":[{"atl":[[4.5,0],[4.1,14.32]],"id":41401491},{"atb":[[1.39,5.79],[1.35,0]],"id":4065261},{"atl":[[4.8,11.64],[5.2,16.26]],"id":69176457},{"atl":[[18.5,0],[15.5,4.51]],"id":65040144}],"con":true,"img":false}]}
{"op":"mcm","clk":"11541560706","pt":1719507071007,"mc":[{"id":"1.230180135","rc":[{"atl":[[4.3,14.4],[4.4,33.22]],"id":41401491},{"atl":[[17,5.49],[17.5,8.66]],"id":65040144}],"con":true,"img":false}]}
{"op":"mcm","clk":"11541560713","pt":1719507071124,"mc":[{"id":"1.230180135","rc":[{"atl":[[16,0],[15,6.67]],"id":65040144}],"con":true,"img":false}]}
{"op":"mcm","clk":"11541560723","pt":1719507071228,"mc":[{"id":"1.230180135","rc":[{"atb":[[1.36,5.89],[1.37,6.87]],"id":4065261},{"atl":[[16.5,13.37],[17,4.49]],"id":65040144}],"con":true,"img":false}]}
{"op":"mcm","clk":"11541560743","pt":1719507071524,"mc":[{"id":"1.230180135","rc":[{"atl":[[4.2,13.36]],"id":41401491},{"atb":[[2.22,4.56]],"id":52032624},{"atl":[[34,7.56]],"id":52032624},{"atb":[[1.38,5.9]],"id":4065261},{"atl":[[9,6.85]],"id":4065261},{"atl":[[5,11.55],[4.9,11.55]],"id":69176457},{"atl":[[16.5,5.49]],"id":65040144}],"con":true,"img":false}]}
{"op":"mcm","clk":"11541560750","pt":1719507071627,"mc":[{"id":"1.230180135","rc":[{"atl":[[4.1,22.2]],"id":41401491},{"atb":[[2.24,12.42]],"id":52032624},{"atl":[[32,13.26]],"id":52032624},{"atb":[[1.39,13.67]],"id":4065261},{"atl":[[8.6,8.72]],"id":4065261},{"atl":[[4.8,19.53]],"id":69176457},{"atl":[[15.5,12.39]],"id":65040144}],"con":true,"img":false}]}
{"op":"mcm","clk":"11541560759","pt":1719507071732,"mc":[{"id":"1.230180135","rc":[{"atb":[[2.1,0]],"id":52032624},{"atl":[[5.1,11.59],[5,12.55]],"id":69176457},{"atl":[[16.5,4.49],[16,1]],"id":65040144}],"con":true,"img":false}]}
{"op":"mcm","clk":"11541560775","pt":1719507071893,"mc":[{"id":"1.230180135","rc":[{"atl":[[4,13.5],[4.4,20.09]],"id":41401491},{"atl":[[30,4.55]],"id":52032624},{"atb":[[1.4,5.76],[1.36,0]],"id":4065261},{"atl":[[5.1,0],[4.7,11.67]],"id":69176457},{"atb":[[1.34,0],[1.38,4.53]],"id":65040144}],"con":true,"img":false}]}
{"op":"mcm","clk":"11541560784","pt":1719507071998,"mc":[{"id":"1.230180135","rc":[{"atl":[[4.4,0]],"id":41401491},{"atb":[[2.18,4.53]],"id":52032624},{"atl":[[38,0]],"id":52032624},{"atl":[[9.6,5.89]],"id":4065261},{"atl":[[5.2,0]],"id":69176457},{"atl":[[17.5,4.52]],"id":65040144}],"con":true,"img":false}]}
{"op":"mcm","clk":"11541560794","pt":1719507072147,"mc":[{"id":"1.230180135","rc":[{"atl":[[4.3,13.4],[4.2,14.36]],"id":41401491},{"atb":[[1.36,5.52],[1.35,14.29]],"id":65040144}],"con":true,"img":false}]}
{"op":"mcm","clk":"11541560802","pt":1719507072231,"mc":[{"id":"1.230180135","rc":[{"atl":[[4.1,42.85]],"id":41401491},{"atb":[[2.22,24.22]],"id":52032624},{"atl":[[32,15.46],[34,8.56],[36,0]],"id":52032624},{"atb":[[1.37,5.87],[1.38,6.9]],"id":4065261},{"atl":[[9.6,0],[8.8,14.4],[8.4,5.73]],"id":4065261},{"atl":[[4.8,37.5]],"id":69176457},{"atl":[[15,11.55]],"id":65040144}],"con":true,"img":false}]}
{"op":"mcm","clk":"11541560830","pt":1719507072515,"mc":[{"id":"1.230180135","rc":[{"atl":[[4.1,34.97]],"id":41401491},{"atl":[[32,7.58]],"id":52032624},{"atb":[[1.39,5.79]],"id":4065261},{"atl":[[4.8,29.62]],"id":69176457},{"atb":[[1.37,4.51]],"id":65040144},{"atl":[[15.5,4.51]],"id":65040144}],"con":true,"img":false}]}
{"op":"mcm","clk":"11541560839","pt":1719507072627,"mc":[{"id":"1.230180135","rc":[{"atl":[[4,21.39]],"id":41401491},{"atl":[[30,12.43]],"id":52032624},{"atb":[[1.4,13.64]],"id":4065261},{"atl":[[4.7,19.55]],"id":69176457},{"atb":[[1.38,12.41]],"id":65040144},{"atl":[[15,19.43]],"id":65040144}],"con":true,"img":false}]}
{"op":"mcm","clk":"11541560849","pt":1719507072729,"mc":[{"id":"1.230180135","rc":[{"atb":[[1.35,5.25]],"id":4065261}],"con":true,"img":false}]}
{"op":"mcm","clk":"11541560858","pt":1719507072842,"mc":[{"id":"1.230180135","rc":[{"atb":[[1.26,26.11]],"id":41401491},{"atb":[[1.35,0]],"id":4065261},{"atl":[[9.2,0],[8.8,27.22]],"id":4065261},{"atb":[[1.35,4.54]],"id":65040144}],"con":true,"img":false}]}
{"op":"mcm","clk":"11541560876","pt":1719507073033,"mc":[{"id":"1.230180135","rc":[{"atl":[[14.5,0.84]],"id":65040144}],"con":true,"img":false}]}
{"op":"mcm","clk":"11541560900","pt":1719507073293,"mc":[{"id":"1.230180135","rc":[{"atl":[[34,5.53],[29,3.57]],"id":52032624}],"con":true,"img":false}]}
{"op":"mcm","clk":"11541560917","pt":1719507073506,"mc":[{"id":"1.230180135","rc":[{"atl":[[8.6,0.84]],"id":4065261},{"atl":[[15,11.55]],"id":65040144}],"con":true,"img":false}]}
{"op":"mcm","clk":"11541560928","pt":1719507073608,"mc":[{"id":"1.230180135","rc":[{"atl":[[8.4,13.61]],"id":4065261},{"atl":[[14.5,8.72]],"id":65040144}],"con":true,"img":false}]}
{"op":"mcm","clk":"11541560938","pt":1719507073711,"mc":[{"id":"1.230180135","rc":[{"atl":[[14,7.69],[15,4.88]],"id":65040144}],"con":true,"img":false}]}
{"op":"mcm","clk":"11541560963","pt":1719507074020,"mc":[{"id":"1.230180135","rc":[{"atl":[[32,6.73]],"id":52032624}],"con":true,"img":false}]}
{"op":"mcm","clk":"11541561009","pt":1719507074590,"mc":[{"id":"1.230180135","rc":[{"atl":[[30,4.55]],"id":52032624},{"atl":[[14.5,0.84]],"id":65040144}],"con":true,"img":false}]}
{"op":"mcm","clk":"11541561015","pt":1719507074698,"mc":[{"id":"1.230180135","rc":[{"atl":[[29,11.45]],"id":52032624},{"atl":[[14,15.57]],"id":65040144}],"con":true,"img":false}]}
{"op":"mcm","clk":"11541561022","pt":1719507074804,"mc":[{"id":"1.230180135","rc":[{"atb":[[2.18,12.03]],"id":52032624}],"con":true,"img":false}]}
{"op":"mcm","clk":"11541561081","pt":1719507075516,"mc":[{"id":"1.230180135","rc":[{"atl":[[5,11.55],[4.6,0.84],[4.9,12.55]],"id":69176457}],"con":true,"img":false}]}
{"op":"mcm","clk":"11541561107","pt":1719507075945,"mc":[{"id":"1.230180135","rc":[{"atl":[[16,0],[15,5.88]],"id":65040144}],"con":true,"img":false}]}
{"op":"mcm","clk":"11541561116","pt":1719507076031,"mc":[{"id":"1.230180135","rc":[{"atl":[[32,7.73],[34,4.53]],"id":52032624},{"atl":[[9,5.85],[8.8,28.22]],"id":4065261}],"con":true,"img":false}]}
{"op":"mcm","clk":"11541561131","pt":1719507076192,"mc":[{"id":"1.230180135","rc":[{"atb":[[2.18,4.53]],"id":52032624}],"con":true,"img":false}]}
{"op":"mcm","clk":"11541561155","pt":1719507076494,"mc":[{"id":"1.230180135","rc":[{"atl":[[4.7,11.67]],"id":69176457}],"con":true,"img":false}]}
{"op":"mcm","clk":"11541561164","pt":1719507076598,"mc":[{"id":"1.230180135","rc":[{"atl":[[4.6,8.72]],"id":69176457}],"con":true,"img":false}]}
{"op":"mcm","clk":"11541561170","pt":1719507076699,"mc":[{"id":"1.230180135","rc":[{"atb":[[1.35,23.34]],"id":69176457}],"con":true,"img":false}]}
{"op":"mcm","clk":"11541561187","pt":1719507076931,"mc":[{"id":"1.230180135","rc":[{"atl":[[4.1,14.32]],"id":41401491},{"atb":[[2.22,4.56]],"id":52032624},{"atl":[[32,5.53]],"id":52032624},{"atl":[[8.8,19.65]],"id":4065261},{"atb":[[1.35,20.84]],"id":69176457},{"atl":[[4.8,11.64]],"id":69176457},{"atl":[[15,1]],"id":65040144}],"con":true,"img":false}]}
{"op":"mcm","clk":"11541561198","pt":1719507077027,"mc":[{"id":"1.230180135","rc":[{"atl":[[34,0],[28,4.55]],"id":52032624},{"atb":[[1.41,5.76],[1.37,0]],"id":4065261},{"atb":[[1.39,11.77],[1.35,9]],"id":69176457},{"atl":[[17.5,0],[13.5,4.5],[14.5,9.86]],"id":65040144}],"con":true,"img":false}]}
{"op":"mcm","clk":"11541561204","pt":1719507077130,"mc":[{"id":"1.230180135","rc":[{"atl":[[4,41.89],[4.3,0],[3.95,13.51]],"id":41401491},{"atb":[[2.24,31.66]],"id":52032624},{"atl":[[27,3.85],[29,10.31]],"id":52032624},{"atl":[[8.2,5.74],[8.4,21.98],[9.4,0]],"id":4065261},{"atl":[[4.8,12.64],[4.9,11.55],[4.7,30.13]],"id":69176457},{"atl":[[14,20.82]],"id":65040144}],"con":true,"img":false}]}
{"op":"mcm","clk":"11541561213","pt":1719507077233,"mc":[{"id":"1.230180135","rc":[{"atb":[[1.32,6.25]],"id":65040144}],"con":true,"img":false}]}
{"op":"mcm","clk":"11541561220","pt":1719507077336,"mc":[{"id":"1.230180135","rc":[{"atl":[[4.5,11.6]],"id":69176457}],"con":true,"img":false}]}
{"op":"mcm","clk":"11541561231","pt":1719507077396,"mc":[{"id":"1.230180135","rc":[{"atl":[[5,0]],"id":69176457}],"con":true,"img":false}]}
{"op":"mcm","clk":"11541561245","pt":1719507077497,"mc":[{"id":"1.230180135","rc":[{"atl":[[4.1,13.47]],"id":41401491},{"atl":[[29,2.43]],"id":52032624},{"atb":[[1.4,5.76]],"id":4065261},{"atl":[[8.6,0]],"id":4065261},{"atb":[[1.38,11.63]],"id":69176457},{"atl":[[14,12.94],[14.5,9.01]],"id":65040144}],"con":true,"img":false}]}
{"op":"mcm","clk":"11541561251","pt":1719507077697,"mc":[{"id":"1.230180135","rc":[{"atl":[[4.1,14.47],[4.2,13.36]],"id":41401491},{"atl":[[32,4.53],[27,8.42],[28,12.43],[29,3.43]],"id":52032624},{"atb":[[1.41,13.64],[1.39,6.79],[1.38,5.9]],"id":4065261},{"atl":[[8.6,1],[8.8,18.65]],"id":4065261},{"atb":[[1.39,19.65]],"id":69176457},{"atl":[[13.5,12.38],[14.5,10.01],[15,0]],"id":65040144}],"con":true,"img":false}]}
{"op":"mcm","clk":"11541561261","pt":1719507077765,"mc":[{"id":"1.230180135","rc":[{"atl":[[32,0]],"id":52032624},{"atl":[[4.8,11.64],[4.7,31.13]],"id":69176457}],"con":true,"img":false}]}
{"op":"mcm","clk":"11541561276","pt":1719507077908,"mc":[{"id":"1.230180135","rc":[{"atb":[[1.35,0]],"id":69176457}],"con":true,"img":false}]}
{"op":"mcm","clk":"11541561286","pt":1719507078010,"mc":[{"id":"1.230180135","rc":[{"atl":[[3.9,0.84]],"id":41401491},{"atl":[[26,0.84]],"id":52032624},{"atl":[[8,0.84]],"id":4065261}],"con":true,"img":false}]}
{"op":"mcm","clk":"11541561294","pt":1719507078115,"mc":[{"id":"1.230180135","rc":[{"atb":[[1.39,4.55],[1.35,0]],"id":65040144}],"con":true,"img":false}]}
{"op":"mcm","clk":"11541561303","pt":1719507078218,"mc":[{"id":"1.230180135","rc":[{"atl":[[4,42.89],[3.9,14.47],[4.2,0]],"id":41401491},{"atb":[[2.18,0],[2.26,4.59]],"id":52032624},{"atl":[[28,13.43],[29,2.43]],"id":52032624},{"atb":[[1.42,5.8],[1.38,0]],"id":4065261},{"atl":[[8.6,0],[8.4,22.98]],"id":4065261},{"atb":[[1.4,11.47],[1.36,0]],"id":69176457},{"atb":[[1.36,4.52],[1.37,5.51]],"id":65040144}],"con":true,"img":false}]}
{"op":"mcm","clk":"11541561307","pt":1719507078320,"mc":[{"id":"1.230180135","rc":[{"atl":[[4.1,13.47]],"id":41401491},{"atb":[[2.22,5.56],[2.2,4.55]],"id":52032624},{"atb":[[1.4,6.76],[1.39,5.79]],"id":4065261}],"con":true,"img":false}]}
{"op":"mcm","clk":"11541561334","pt":1719507078630,"mc":[{"id":"1.230180135","rc":[{"atl":[[4,35.01]],"id":41401491},{"atb":[[1.93,9.09]],"id":52032624},{"atl":[[28,5.55]],"id":52032624},{"atl":[[8,6.65],[9,0],[8.4,15.1]],"id":4065261},{"atl":[[4.6,0.84]],"id":69176457},{"atl":[[17,0],[13,4.52]],"id":65040144}],"con":true,"img":false}]}
{"op":"mcm","clk":"11541561344","pt":1719507078733,"mc":[{"id":"1.230180135","rc":[{"atl":[[3.9,22.35]],"id":41401491},{"atl":[[26,8.72]],"id":52032624},{"atl":[[8,14.53]],"id":4065261},{"atl":[[4.5,19.48]],"id":69176457}],"con":true,"img":false}]}
{"op":"mcm","clk":"11541561354","pt":1719507078836,"mc":[{"id":"1.230180135","rc":[{"atl":[[25,4.17]],"id":52032624}],"con":true,"img":false}]}
{"op":"mcm","clk":"11541561363","pt":1719507078941,"mc":[{"id":"1.230180135","rc":[{"atl":[[3.85,13.58],[4.1,0]],"id":41401491},{"atl":[[25,8.73],[27,4.57],[30,0]],"id":52032624},{"atl":[[8.8,12.82],[7.8,5.81]],"id":4065261},{"atl":[[12.5,8.7],[14,5.25]],"id":65040144}],"con":true,"img":false}]}
{"op":"mcm","clk":"11541561388","pt":1719507079203,"mc":[{"id":"1.230180135","rc":[{"atl":[[4,34.01],[3.95,14.51]],"id":41401491},{"atl":[[27,5.57],[28,4.55]],"id":52032624},{"atl":[[8.2,6.74]],"id":4065261},{"atl":[[13.5,13.38]],"id":65040144}],"con":true,"img":false}]}
{"op":"mcm","clk":"11541561393","pt":1719507079302,"mc":[{"id":"1.230180135","rc":[{"atl":[[8.4,14.1]],"id":4065261},{"atl":[[14.5,9.01]],"id":65040144}],"con":true,"img":false}]}
{"op":"mcm","clk":"11541561406","pt":1719507079508,"mc":[{"id":"1.230180135","rc":[{"atl":[[3.9,14.47]],"id":41401491},{"atb":[[1.41,5.76]],"id":4065261},{"atl":[[8,6.65]],"id":4065261},{"atb":[[1.39,11.77]],"id":69176457},{"atb":[[1.38,4.53]],"id":65040144},{"atl":[[13.5,5.5]],"id":65040144}],"con":true,"img":false}]}
{"op":"mcm","clk":"11541561413","pt":1719507079615,"mc":[{"id":"1.230180135","rc":[{"atl":[[3.85,21.46]],"id":41401491},{"atb":[[2.24,23.78],[2.12,12.29]],"id":52032624},{"atl":[[26,0.84]],"id":52032624},{"atb":[[1.42,13.68]],"id":4065261},{"atl":[[7.8,13.69]],"id":4065261},{"atb":[[1.4,19.35]],"id":69176457},{"atb":[[1.39,12.43]],"id":65040144},{"atl":[[12.5,16.58]],"id":65040144}],"con":true,"img":false}]}
{"op":"mcm","clk":"11541561420","pt":1719507079714,"mc":[{"id":"1.230180135","rc":[{"atb":[[2.26,12.47]],"id":52032624},{"atl":[[25,16.61]],"id":52032624},{"atb":[[1.32,0]],"id":65040144},{"atl":[[16.5,0],[12,4.53]],"id":65040144}],"con":true,"img":false}]}
{"op":"mcm","clk":"11541561428","pt":1719507079822,"mc":[{"id":"1.230180135","rc":[{"atl":[[7.6,5.83],[8.4,8.37]],"id":4065261},{"atb":[[1.41,11.34],[1.37,0]],"id":69176457},{"atb":[[1.4,4.55],[1.36,0]],"id":65040144}],"con":true,"img":false}]}
{"op":"mcm","clk":"11541561437","pt":1719507079924,"mc":[{"id":"1.230180135","rc":[{"atb":[[1.37,16.87]],"id":65040144}],"con":true,"img":false}]}
{"op":"mcm","clk":"11541561453","pt":1719507080231,"mc":[{"id":"1.230180135","rc":[{"atb":[[2.12,5.28]],"id":52032624}],"con":true,"img":false}]}
{"op":"mcm","clk":"11541561467","pt":1719507080443,"mc":[{"id":"1.230180135","rc":[{"atl":[[8,5.81]],"id":4065261},{"atl":[[11.5,0.84]],"id":65040144}],"con":true,"img":false}]}
{"op":"mcm","clk":"11541561474","pt":1719507080540,"mc":[{"id":"1.230180135","rc":[{"atl":[[7.8,5.81]],"id":4065261},{"atb":[[1.4,11.47]],"id":69176457},{"atl":[[12.5,8.7]],"id":65040144}],"con":true,"img":false}]}
{"op":"mcm","clk":"11541561488","pt":1719507080744,"mc":[{"id":"1.230180135","rc":[{"atl":[[7.6,13.71]],"id":4065261},{"atb":[[1.41,19.22]],"id":69176457},{"atb":[[1.39,4.55]],"id":65040144},{"atl":[[12,12.41]],"id":65040144}],"con":true,"img":false}]}
{"op":"mcm","clk":"11541561496","pt":1719507080797,"mc":[{"id":"1.230180135","rc":[{"atb":[[1.4,12.43]],"id":65040144}],"con":true,"img":false}]}
{"op":"mcm","clk":"11541561501","pt":1719507080905,"mc":[{"id":"1.230180135","rc":[{"atb":[[1.37,5.51]],"id":65040144}],"con":true,"img":false}]}
{"op":"mcm","clk":"11541561520","pt":1719507081214,"mc":[{"id":"1.230180135","rc":[{"atb":[[1.36,6.95]],"id":4065261}],"con":true,"img":false}]}
{"op":"mcm","clk":"11541561541","pt":1719507081522,"mc":[{"id":"1.230180135","rc":[{"atl":[[12,4.53]],"id":65040144}],"con":true,"img":false}]}
{"op":"mcm","clk":"11541561546","pt":1719507081625,"mc":[{"id":"1.230180135","rc":[{"atl":[[11.5,8.72]],"id":65040144}],"con":true,"img":false}]}
{"op":"mcm","clk":"11541561552","pt":1719507081734,"mc":[{"id":"1.230180135","rc":[{"atl":[[4,20.5],[3.8,13.59]],"id":41401491}],"con":true,"img":false}]}
{"op":"mcm","clk":"11541561558","pt":1719507081837,"mc":[{"id":"1.230180135","rc":[{"atl":[[4,0]],"id":41401491},{"atb":[[2.24,4.54]],"id":52032624},{"atl":[[29,0]],"id":52032624},{"atl":[[8.4,0]],"id":4065261},{"atb":[[1.27,37.61]],"id":69176457},{"atl":[[4.7,12.67]],"id":69176457},{"atl":[[14,0]],"id":65040144}],"con":true,"img":false}]}
{"op":"mcm","clk":"11541561569","pt":1719507082039,"mc":[{"id":"1.230180135","rc":[{"atl":[[3.85,41.71]],"id":41401491},{"atb":[[2.26,31.29]],"id":52032624},{"atl":[[25,19.46]],"id":52032624},{"atl":[[7.6,21.64]],"id":4065261},{"atb":[[1.41,24.44]],"id":69176457},{"atl":[[4.5,39]],"id":69176457},{"atl":[[11.5,13.89]],"id":65040144}],"con":true,"img":false}]}
{"op":"mcm","clk":"11541561583","pt":1719507082245,"mc":[{"id":"1.230180135","rc":[{"atb":[[2.28,4.58]],"id":52032624},{"atb":[[1.43,5.85],[1.39,0]],"id":4065261},{"atb":[[1.42,11.33],[1.38,0]],"id":69176457},{"atb":[[1.41,4.55]],"id":65040144}],"con":true,"img":false}]}
{"op":"mcm","clk":"11541561590","pt":1719507082351,"mc":[{"id":"1.230180135","rc":[{"atb":[[2.2,0]],"id":52032624},{"atb":[[1.37,1]],"id":65040144}],"con":true,"img":false}]}
{"op":"mcm","clk":"11541561600","pt":1719507082456,"mc":[{"id":"1.230180135","rc":[{"atb":[[1.27,44.57]],"id":41401491},{"atl":[[3.9,13.62]],"id":41401491},{"atl":[[4.4,0.84]],"id":69176457}],"con":true,"img":false}]}
{"op":"mcm","clk":"11541561607","pt":1719507082506,"mc":[{"id":"1.230180135","rc":[{"atl":[[3.85,33.83]],"id":41401491},{"atb":[[2.24,5.54],[2.22,4.56]],"id":52032624}],"con":true,"img":false}]}
{"op":"mcm","clk":"11541561613","pt":1719507082611,"mc":[{"id":"1.230180135","rc":[{"atl":[[3.95,13.51],[3.8,21.47],[3.9,14.62]],"id":41401491},{"atl":[[24,4.56]],"id":52032624},{"atb":[[1.41,6.76],[1.4,5.76]],"id":4065261},{"atl":[[8,6.81],[8.2,5.74]],"id":4065261},{"atl":[[4.4,12.08]],"id":69176457},{"atb":[[1.37,0],[1.39,5.55]],"id":65040144},{"atl":[[12.5,9.7],[13.5,4.5]],"id":65040144}],"con":true,"img":false}]}
{"op":"mcm","clk":"11541561617","pt":1719507082722,"mc":[{"id":"1.230180135","rc":[{"atb":[[1.27,28.89]],"id":41401491},{"atl":[[28,0]],"id":52032624},{"atb":[[1.36,5.95]],"id":4065261},{"atl":[[4.6,1.84],[4.9,0],[4.7,11.67]],"id":69176457},{"atl":[[11,4.52],[15.5,0]],"id":65040144}],"con":true,"img":false}]}
{"op":"mcm","clk":"11541561635","pt":1719507082931,"mc":[{"id":"1.230180135","rc":[{"atl":[[3.95,0],[3.75,13.68]],"id":41401491}],"con":true,"img":false}]}
{"op":"mcm","clk":"11541561647","pt":1719507083028,"mc":[{"id":"1.230180135","rc":[{"atb":[[1.27,42.96]],"id":4065261}],"con":true,"img":false}]}
{"op":"mcm","clk":"11541561666","pt":1719507083236,"mc":[{"id":"1.230180135","rc":[{"atl":[[26,1.84],[27,4.57]],"id":52032624},{"atl":[[12,5.53],[12.5,8.7]],"id":65040144}],"con":true,"img":false}]}
{"op":"mcm","clk":"11541561679","pt":1719507083340,"mc":[{"id":"1.230180135","rc":[{"atl":[[3.85,34.83],[3.9,13.62]],"id":41401491},{"atb":[[1.27,0]],"id":69176457}],"con":true,"img":false}]}
{"op":"mcm","clk":"11541561689","pt":1719507083442,"mc":[{"id":"1.230180135","rc":[{"atl":[[8.2,0],[7.4,5.81]],"id":4065261}],"con":true,"img":false}]}
{"op":"mcm","clk":"11541561701","pt":1719507083547,"mc":[{"id":"1.230180135","rc":[{"atl":[[3.8,13.59]],"id":41401491},{"atl":[[26,1]],"id":52032624},{"atl":[[4.5,31.12],[4.6,1]],"id":69176457}],"con":true,"img":false}]}
{"op":"mcm","clk":"11541561712","pt":1719507083658,"mc":[{"id":"1.230180135","rc":[{"atl":[[3.75,21.56]],"id":41401491},{"atb":[[2.26,23.41]],"id":52032624},{"atl":[[25,11.58]],"id":52032624},{"atb":[[1.42,5.8]],"id":4065261},{"atb":[[1.41,16.56]],"id":69176457},{"atl":[[4.4,19.96]],"id":69176457},{"atb":[[1.4,4.55],[1.28,21.01]],"id":65040144},{"atl":[[11.5,6.01]],"id":65040144}],"con":true,"img":false}]}
{"op":"mcm","clk":"11541561723","pt":1719507083755,"mc":[{"id":"1.230180135","rc":[{"atb":[[2.28,12.46]],"id":52032624},{"atl":[[24,12.44]],"id":52032624},{"atb":[[1.43,13.74]],"id":4065261},{"atb":[[1.42,19.21]],"id":69176457},{"atb":[[1.41,12.43]],"id":65040144},{"atl":[[11,12.41]],"id":65040144}],"con":true,"img":false}]}
{"op":"mcm","clk":"11541561745","pt":1719507083909,"mc":[{"id":"1.230180135","rc":[{"atb":[[1.3,14.1]],"id":41401491},{"atl":[[23,4.55],[25,7.41]],"id":52032624},{"atb":[[1.41,12.38]],"id":4065261}],"con":true,"img":false}]}
{"op":"mcm","clk":"11541561756","pt":1719507084014,"mc":[{"id":"1.230180135","rc":[{"atb":[[1.36,0],[1.27,21.01]],"id":4065261},{"atl":[[10.5,6.01],[12.5,0]],"id":65040144}],"con":true,"img":false}]}
{"op":"mcm","clk":"11541561764","pt":1719507084117,"mc":[{"id":"1.230180135","rc":[{"atb":[[1.26,12.86],[1.31,13.83],[1.24,0]],"id":41401491},{"atl":[[4.3,11.24]],"id":69176457},{"atl":[[10.5,10.53]],"id":65040144}],"con":true,"img":false}]}
{"op":"mcm","clk":"11541561774","pt":1719507084221,"mc":[{"id":"1.230180135","rc":[{"atl":[[4.8,0]],"id":69176457},{"atl":[[13.5,0]],"id":65040144}],"con":true,"img":false}]}
{"op":"mcm","clk":"11541561787","pt":1719507084324,"mc":[{"id":"1.230180135","rc":[{"atb":[[1.44,9.61]],"id":4065261}],"con":true,"img":false}]}
{"op":"mcm","clk":"11541561807","pt":1719507084540,"mc":[{"id":"1.230180135","rc":[{"atl":[[24,4.56]],"id":52032624},{"atl":[[7.6,13.76]],"id":4065261},{"atb":[[1.42,14.1]],"id":65040144},{"atl":[[11,4.52],[11.5,5.16]],"id":65040144}],"con":true,"img":false}]}
{"op":"mcm","clk":"11541561817","pt":1719507084633,"mc":[{"id":"1.230180135","rc":[{"atl":[[23,12.43]],"id":52032624},{"atl":[[7.4,13.69]],"id":4065261},{"atb":[[1.42,24.17]],"id":65040144},{"atl":[[10.5,18.42]],"id":65040144}],"con":true,"img":false}]}
{"op":"mcm","clk":"11541561830","pt":1719507084839,"mc":[{"id":"1.230180135","rc":[{"atb":[[1.43,13.77]],"id":69176457}],"con":true,"img":false}]}
{"op":"mcm","clk":"11541561839","pt":1719507084942,"mc":[{"id":"1.230180135","rc":[{"atb":[[1.43,23.62]],"id":69176457}],"con":true,"img":false}]}
{"op":"mcm","clk":"11541561856","pt":1719507085150,"mc":[{"id":"1.230180135","rc":[{"atl":[[3.7,13.73],[3.9,0]],"id":41401491},{"atl":[[22,4.55],[25,8.41],[26,0],[27,0]],"id":52032624},{"atb":[[1.41,11.38],[1.42,6.8]],"id":4065261},{"atl":[[8,0],[7.2,5.83],[7.8,6.81]],"id":4065261},{"atl":[[4.5,32.12],[4.6,0]],"id":69176457},{"atb":[[1.43,4.52],[1.39,4.55],[1.4,5.55],[1.38,0]],"id":65040144},{"atl":[[11.5,6.16],[12,4.53]],"id":65040144}],"con":true,"img":false}]}
{"op":"mcm","clk":"11541561868","pt":1719507085254,"mc":[{"id":"1.230180135","rc":[{"atb":[[1.45,13.16]],"id":4065261}],"con":true,"img":false}]}
{"op":"mcm","clk":"11541561878","pt":1719507085359,"mc":[{"id":"1.230180135","rc":[{"atb":[[2.3,4.57],[2.22,0]],"id":52032624},{"atl":[[24,5.56]],"id":52032624},{"atb":[[1.4,0],[1.45,19.02],[1.43,14.74],[1.42,5.8]],"id":4065261},{"atl":[[7.6,14.76],[7.8,5.81]],"id":4065261},{"atb":[[1.44,11.33],[1.39,0]],"id":69176457},{"atb":[[1.41,13.43],[1.4,4.55]],"id":65040144},{"atl":[[10,4.51],[13,0]],"id":65040144}],"con":true,"img":false}]}
{"op":"mcm","clk":"11541561886","pt":1719507085412,"mc":[{"id":"1.230180135","rc":[{"atl":[[3.7,14.58]],"id":41401491},{"atl":[[22,5.4],[25,7.41]],"id":52032624},{"atl":[[7.2,6.67]],"id":4065261}],"con":true,"img":false}]}
{"op":"mcm","clk":"11541561894","pt":1719507085514,"mc":[{"id":"1.230180135","rc":[{"atb":[[1.43,6.85]],"id":4065261}],"con":true,"img":false}]}
{"op":"mcm","clk":"11541561897","pt":1719507085619,"mc":[{"id":"1.230180135","rc":[{"atb":[[1.44,17.49]],"id":4065261},{"atb":[[1.42,11.33]],"id":69176457},{"atl":[[4.4,12.08]],"id":69176457},{"atb":[[1.41,5.55]],"id":65040144}],"con":true,"img":false}]}
{"op":"mcm","clk":"11541561909","pt":1719507085825,"mc":[{"id":"1.230180135","rc":[{"atb":[[1.43,31.5]],"id":69176457},{"atl":[[4.3,19.12]],"id":69176457},{"atb":[[1.42,32.06]],"id":65040144}],"con":true,"img":false}]}
{"op":"mcm","clk":"11541561923","pt":1719507085979,"mc":[{"id":"1.230180135","rc":[{"atb":[[1.41,5.76]],"id":4065261}],"con":true,"img":false}]}
{"op":"mcm","clk":"11541561928","pt":1719507086082,"mc":[{"id":"1.230180135","rc":[{"atl":[[4.2,11.27],[4.7,0]],"id":69176457}],"con":true,"img":false}]}
{"op":"mcm","clk":"11541561952","pt":1719507086446,"mc":[{"id":"1.230180135","rc":[{"atl":[[4.4,11.23]],"id":69176457}],"con":true,"img":false}]}
{"op":"mcm","clk":"11541561960","pt":1719507086548,"mc":[{"id":"1.230180135","rc":[{"atl":[[3.75,13.68]],"id":41401491},{"atb":[[2.28,4.58]],"id":52032624},{"atl":[[23,4.55]],"id":52032624},{"atb":[[1.44,9.61]],"id":4065261},{"atl":[[7.4,5.81]],"id":4065261},{"atb":[[1.43,23.62]],"id":69176457},{"atl":[[4.3,11.24]],"id":69176457},{"atb":[[1.42,24.17]],"id":65040144},{"atl":[[10.5,10.53]],"id":65040144}],"con":true,"img":false}]}
{"op":"mcm","clk":"11541561967","pt":1719507086660,"mc":[{"id":"1.230180135","rc":[{"atl":[[3.7,22.46]],"id":41401491},{"atb":[[2.24,4.54],[2.3,12.45],[2.26,24.41]],"id":52032624},{"atl":[[22,13.28]],"id":52032624},{"atb":[[1.45,26.9]],"id":4065261},{"atl":[[7.2,14.56]],"id":4065261},{"atb":[[1.44,19.21]],"id":69176457},{"atl":[[4.5,31.12],[4.4,12.23],[4.2,19.15]],"id":69176457},{"atb":[[1.43,12.41]],"id":65040144},{"atl":[[10,12.4],[11,5.52],[11.5,5.16]],"id":65040144}],"con":true,"img":false}]}
{"op":"mcm","clk":"11541561980","pt":1719507086756,"mc":[{"id":"1.230180135","rc":[{"atb":[[1.27,7.88]],"id":41401491},{"atl":[[3.85,14.58]],"id":41401491},{"atb":[[2.26,5.59]],"id":52032624},{"atl":[[25,4.56]],"id":52032624},{"atb":[[1.27,0]],"id":4065261},{"atl":[[7.6,6.83]],"id":4065261},{"atb":[[1.41,11.34]],"id":69176457},{"atl":[[4.5,11.6]],"id":69176457},{"atb":[[1.28,0]],"id":65040144},{"atl":[[11.5,0]],"id":65040144}],"con":true,"img":false}]}
{"op":"mcm","clk":"11541561993","pt":1719507086963,"mc":[{"id":"1.230180135","rc":[{"atl":[[3.85,13.58],[3.8,14.59]],"id":41401491},{"atb":[[2.28,23]],"id":52032624},{"atl":[[22,16.53]],"id":52032624},{"atb":[[1.45,47.92]],"id":4065261},{"atl":[[7.2,22.22]],"id":4065261},{"atl":[[4.2,40.16]],"id":69176457},{"atb":[[1.42,45.19]],"id":65040144},{"atl":[[10,17.07]],"id":65040144}],"con":true,"img":false}]}
{"op":"mcm","clk":"11541561999","pt":1719507087067,"mc":[{"id":"1.230180135","rc":[{"atl":[[3.85,0],[3.65,13.67]],"id":41401491},{"atb":[[2.26,12.72]],"id":52032624},{"atl":[[21,4.56],[25,0]],"id":52032624},{"atb":[[1.41,0],[1.46,5.85]],"id":4065261},{"atl":[[4.5,0],[4.1,11.27]],"id":69176457},{"atl":[[12,0]],"id":65040144}],"con":true,"img":false}]}
{"op":"mcm","clk":"11541562006","pt":1719507087170,"mc":[{"id":"1.230180135","rc":[{"atb":[[1.4,0],[1.45,11.34]],"id":69176457},{"atl":[[9.8,4.51]],"id":65040144}],"con":true,"img":false}]}
{"op":"mcm","clk":"11541562012","pt":1719507087273,"mc":[{"id":"1.230180135","rc":[{"atb":[[2.24,0],[2.32,4.58]],"id":52032624},{"atl":[[23,5.55],[24,4.56]],"id":52032624},{"atb":[[1.44,10.61],[1.43,5.85]],"id":4065261},{"atl":[[4.3,12.24],[4.4,11.23]],"id":69176457},{"atb":[[1.44,4.53],[1.39,0]],"id":65040144},{"atl":[[10.5,11.53],[11,4.52]],"id":65040144}],"con":true,"img":false}]}
{"op":"mcm","clk":"11541562028","pt":1719507087480,"mc":[{"id":"1.230180135","rc":[{"atl":[[9.8,5.35]],"id":65040144}],"con":true,"img":false}]}
{"op":"mcm","clk":"11541562033","pt":1719507087536,"mc":[{"id":"1.230180135","rc":[{"atl":[[4.2,32.28]],"id":69176457}],"con":true,"img":false}]}
{"op":"mcm","clk":"11541562044","pt":1719507087639,"mc":[{"id":"1.230180135","rc":[{"atl":[[3.7,14.58]],"id":41401491},{"atb":[[2.26,11.22]],"id":52032624},{"atl":[[22,8.65]],"id":52032624},{"atb":[[1.45,40.04]],"id":4065261},{"atl":[[7.8,0],[7,5.81]],"id":4065261},{"atl":[[4.1,19.15]],"id":69176457}],"con":true,"img":false}]}
{"op":"mcm","clk":"11541562052","pt":1719507087752,"mc":[{"id":"1.230180135","rc":[{"atl":[[3.65,21.55]],"id":41401491},{"atl":[[21,12.44]],"id":52032624},{"atb":[[1.46,13.74]],"id":4065261}],"con":true,"img":false}]}
{"op":"mcm","clk":"11541562089","pt":1719507088154,"mc":[{"id":"1.230180135","rc":[{"atb":[[2.26,5.59]],"id":52032624}],"con":true,"img":false}]}
{"op":"mcm","clk":"11541562128","pt":1719507088577,"mc":[{"id":"1.230180135","rc":[{"atb":[[2.3,4.57]],"id":52032624},{"atl":[[7.2,14.33]],"id":4065261},{"atb":[[1.44,11.33]],"id":69176457},{"atb":[[1.43,4.52]],"id":65040144},{"atl":[[10,9.18]],"id":65040144}],"con":true,"img":false}]}
{"op":"mcm","clk":"11541562138","pt":1719507088671,"mc":[{"id":"1.230180135","rc":[{"atb":[[2.32,12.46]],"id":52032624},{"atl":[[7,13.69]],"id":4065261},{"atb":[[1.45,19.23]],"id":69176457},{"atb":[[1.44,12.41]],"id":65040144},{"atl":[[9.8,13.24]],"id":65040144}],"con":true,"img":false}]}
{"op":"mcm","clk":"11541562162","pt":1719507088927,"mc":[{"id":"1.230180135","rc":[{"atb":[[1.41,14.43],[1.37,8.68]],"id":65040144}],"con":true,"img":false}]}
{"op":"mcm","clk":"11541562181","pt":1719507089136,"mc":[{"id":"1.230180135","rc":[{"atb":[[1.41,5.55]],"id":65040144},{"atl":[[9.6,11.54],[10.5,5.52]],"id":65040144}],"con":true,"img":false}]}
{"op":"mcm","clk":"11541562187","pt":1719507089245,"mc":[{"id":"1.230180135","rc":[{"atl":[[3.8,13.59]],"id":41401491},{"atl":[[20,4.55]],"id":52032624},{"atl":[[7.4,6.81],[7.6,1],[6.8,5.82]],"id":4065261},{"atb":[[1.41,4.55]],"id":65040144},{"atl":[[9.6,16.05],[10.5,4.52],[11,0]],"id":65040144}],"con":true,"img":false}]}
{"op":"mcm","clk":"11541562195","pt":1719507089343,"mc":[{"id":"1.230180135","rc":[{"atl":[[3.6,13.66],[3.75,14.68]],"id":41401491},{"atb":[[2.28,24],[2.26,4.59]],"id":52032624},{"atb":[[1.47,5.84]],"id":4065261},{"atl":[[7.6,0]],"id":4065261},{"atb":[[1.45,4.53],[1.4,0],[1.42,46.19]],"id":65040144},{"atl":[[10,10.18]],"id":65040144}],"con":true,"img":false}]}
{"op":"mcm","clk":"11541562202","pt":1719507089447,"mc":[{"id":"1.230180135","rc":[{"atl":[[3.8,0]],"id":41401491},{"atl":[[22,9.65],[23,4.55]],"id":52032624},{"atb":[[1.42,0]],"id":4065261},{"atl":[[7.2,15.33],[7.4,5.81]],"id":4065261}],"con":true,"img":false}]}
{"op":"mcm","clk":"11541562218","pt":1719507089647,"mc":[{"id":"1.230180135","rc":[{"atb":[[2.18,5.59]],"id":52032624}],"con":true,"img":false}]}
{"op":"mcm","clk":"11541562231","pt":1719507089865,"mc":[{"id":"1.230180135","rc":[{"atb":[[2.18,0]],"id":52032624}],"con":true,"img":false}]}
{"op":"mcm","clk":"11541562238","pt":1719507089958,"mc":[{"id":"1.230180135","rc":[{"atl":[[3.7,13.73]],"id":41401491},{"atl":[[22,8.8]],"id":52032624},{"atl":[[7.2,14.49]],"id":4065261},{"atl":[[4,0.84]],"id":69176457}],"con":true,"img":false}]}
{"op":"mcm","clk":"11541562257","pt":1719507090164,"mc":[{"id":"1.230180135","rc":[{"atb":[[2.26,0],[2.34,4.57]],"id":52032624},{"atb":[[1.39,7.43]],"id":4065261},{"atb":[[1.41,0],[1.46,11.39]],"id":69176457}],"con":true,"img":false}]}
{"op":"mcm","clk":"11541562265","pt":1719507090268,"mc":[{"id":"1.230180135","rc":[{"atl":[[4,12.15]],"id":69176457},{"atb":[[1.37,0]],"id":65040144}],"con":true,"img":false}]}
{"op":"mcm","clk":"11541562271","pt":1719507090371,"mc":[{"id":"1.230180135","rc":[{"atb":[[1.39,0]],"id":4065261},{"atl":[[4.4,0]],"id":69176457}],"con":true,"img":false}]}
{"op":"mcm","clk":"11541562280","pt":1719507090477,"mc":[{"id":"1.230180135","rc":[{"atb":[[2.3,5.57]],"id":52032624},{"atb":[[1.44,9.61],[1.45,41.04]],"id":4065261},{"atl":[[4.3,11.24],[4.2,33.28]],"id":69176457},{"atb":[[1.43,5.52],[1.42,45.19]],"id":65040144}],"con":true,"img":false}]}
{"op":"mcm","clk":"11541562285","pt":1719507090579,"mc":[{"id":"1.230180135","rc":[{"atb":[[2.28,23]],"id":52032624}],"con":true,"img":false}]}
{"op":"mcm","clk":"11541562296","pt":1719507090684,"mc":[{"id":"1.230180135","rc":[{"atl":[[3.65,13.67]],"id":41401491},{"atl":[[21,4.56]],"id":52032624},{"atb":[[1.46,5.85]],"id":4065261},{"atl":[[7,5.81]],"id":4065261},{"atl":[[4.1,11.27]],"id":69176457},{"atb":[[1.44,4.53]],"id":65040144},{"atl":[[9.8,5.35]],"id":65040144}],"con":true,"img":false}]}
{"op":"mcm","clk":"11541562304","pt":1719507090790,"mc":[{"id":"1.230180135","rc":[{"atl":[[3.6,21.54]],"id":41401491},{"atl":[[20,12.43]],"id":52032624},{"atb":[[1.47,13.72]],"id":4065261},{"atl":[[6.8,13.7]],"id":4065261},{"atl":[[4,20.03]],"id":69176457},{"atb":[[1.45,12.42]],"id":65040144},{"atl":[[9.6,23.94]],"id":65040144}],"con":true,"img":false}]}
{"op":"mcm","clk":"11541562333","pt":1719507091048,"mc":[{"id":"1.230180135","rc":[{"atl":[[19.5,4.55],[24,0]],"id":52032624},{"atl":[[7.4,0],[6.6,5.82]],"id":4065261},{"atl":[[4.3,0],[3.95,11.32]],"id":69176457},{"atl":[[10.5,0],[9.4,4.5]],"id":65040144}],"con":true,"img":false}]}
{"op":"mcm","clk":"11541562341","pt":1719507091144,"mc":[{"id":"1.230180135","rc":[{"atb":[[1.43,0],[1.48,5.83]],"id":4065261},{"atb":[[1.43,30.49]],"id":69176457}],"con":true,"img":false}]}
{"op":"mcm","clk":"11541562350","pt":1719507091269,"mc":[{"id":"1.230180135","rc":[{"atl":[[3.55,13.67],[3.75,1]],"id":41401491},{"atb":[[1.43,26.99]],"id":69176457}],"con":true,"img":false}]}
{"op":"mcm","clk":"11541562357","pt":1719507091371,"mc":[{"id":"1.230180135","rc":[{"atl":[[21,5.56],[22,7.8]],"id":52032624},{"atb":[[1.46,6.85],[1.45,40.04]],"id":4065261},{"atl":[[7.2,13.49],[7,6.81]],"id":4065261},{"atl":[[10,9.18],[9.8,6.35]],"id":65040144}],"con":true,"img":false}]}
{"op":"mcm","clk":"11541562366","pt":1719507091474,"mc":[{"id":"1.230180135","rc":[{"atl":[[9.8,5.51]],"id":65040144}],"con":true,"img":false}]}
{"op":"mcm","clk":"11541562373","pt":1719507091580,"mc":[{"id":"1.230180135","rc":[{"atb":[[2.32,4.58],[2.28,4.58]],"id":52032624},{"atl":[[22,4.55]],"id":52032624},{"atl":[[7.2,5.83]],"id":4065261},{"atb":[[1.45,11.34]],"id":69176457},{"atl":[[4.2,12.27]],"id":69176457},{"atl":[[10,4.51]],"id":65040144}],"con":true,"img":false}]}
{"op":"mcm","clk":"11541562384","pt":1719507091687,"mc":[{"id":"1.230180135","rc":[{"atb":[[2.32,22.23],[2.34,12.45]],"id":52032624},{"atl":[[20,16.03]],"id":52032624},{"atl":[[6.8,21.05]],"id":4065261},{"atb":[[1.46,19.27]],"id":69176457},{"atl":[[4,41.05]],"id":69176457},{"atb":[[1.41,0],[1.46,4.54]],"id":65040144},{"atl":[[9.6,28.44]],"id":65040144}],"con":true,"img":false}]}
{"op":"mcm","clk":"11541562415","pt":1719507092152,"mc":[{"id":"1.230180135","rc":[{"atb":[[2.36,4.59],[2.28,0]],"id":52032624},{"atb":[[1.42,0],[1.47,11.42]],"id":69176457}],"con":true,"img":false}]}
{"op":"mcm","clk":"11541562424","pt":1719507092359,"mc":[{"id":"1.230180135","rc":[{"atb":[[1.43,23.62]],"id":69176457}],"con":true,"img":false}]}
{"op":"mcm","clk":"11541562428","pt":1719507092465,"mc":[{"id":"1.230180135","rc":[{"atb":[[1.47,5.84]],"id":4065261}],"con":true,"img":false}]}
{"op":"mcm","clk":"11541562434","pt":1719507092569,"mc":[{"id":"1.230180135","rc":[{"atl":[[3.6,13.66],[3.5,0.84]],"id":41401491},{"atl":[[19,0.84],[20,8.14]],"id":52032624},{"atb":[[1.48,13.71]],"id":4065261},{"atl":[[6.4,0.84],[6.8,13.17]],"id":4065261},{"atl":[[4,33.17]],"id":69176457},{"atb":[[1.45,4.53]],"id":65040144},{"atl":[[9.6,20.56]],"id":65040144}],"con":true,"img":false}]}
{"op":"mcm","clk":"11541562439","pt":1719507092672,"mc":[{"id":"1.230180135","rc":[{"atl":[[3.55,21.55]],"id":41401491},{"atl":[[19.5,12.43]],"id":52032624},{"atl":[[6.6,13.7]],"id":4065261},{"atl":[[3.95,19.2]],"id":69176457},{"atb":[[1.46,12.42]],"id":65040144},{"atl":[[9.4,12.38]],"id":65040144}],"con":true,"img":false}]}
{"op":"mcm","clk":"11541562446","pt":1719507092781,"mc":[{"id":"1.230180135","rc":[{"atb":[[1.45,44.66]],"id":4065261}],"con":true,"img":false}]}
{"op":"mcm","clk":"11541562455","pt":1719507092883,"mc":[{"id":"1.230180135","rc":[{"atl":[[3.6,14.66],[3.75,0]],"id":41401491}],"con":true,"img":false}]}
{"op":"mcm","clk":"11541562466","pt":1719507093040,"mc":[{"id":"1.230180135","rc":[{"atl":[[3.7,0],[3.5,14.57]],"id":41401491},{"spl":[[75,0.02],[960,0.01]],"id":52032624}],"con":true,"img":false}]}
{"op":"mcm","clk":"11541562478","pt":1719507093252,"mc":[{"id":"1.230180135","rc":[{"atb":[[1.45,40.04]],"id":4065261}],"con":true,"img":false}]}
{"op":"mcm","clk":"11541562495","pt":1719507093562,"mc":[{"id":"1.230180135","rc":[{"atl":[[3.55,13.67]],"id":41401491},{"atb":[[2.34,4.57]],"id":52032624},{"atl":[[19.5,4.55]],"id":52032624},{"atl":[[6.6,5.82]],"id":4065261},{"atb":[[1.46,11.39]],"id":69176457}],"con":true,"img":false}]}
{"op":"mcm","clk":"11541562506","pt":1719507093675,"mc":[{"id":"1.230180135","rc":[{"atl":[[3.5,22.45]],"id":41401491},{"atb":[[2.36,12.47]],"id":52032624},{"atl":[[19,8.72]],"id":52032624},{"atl":[[6.4,8.72]],"id":4065261},{"atb":[[1.47,19.3]],"id":69176457}],"con":true,"img":false}]}
{"op":"mcm","clk":"11541562526","pt":1719507093984,"mc":[{"id":"1.230180135","rc":[{"atl":[[4.1,12.27],[4.2,11.27]],"id":69176457}],"con":true,"img":false}]}
{"op":"mcm","clk":"11541562538","pt":1719507094134,"mc":[{"id":"1.230180135","rc":[{"atl":[[18.5,4.57],[22,0]],"id":52032624},{"atl":[[7.2,0],[6.2,5.76]],"id":4065261}],"con":true,"img":false}]}
{"op":"mcm","clk":"11541562546","pt":1719507094238,"mc":[{"id":"1.230180135","rc":[{"atb":[[1.29,6.38]],"id":41401491}],"con":true,"img":false}]}
{"op":"mcm","clk":"11541562557","pt":1719507094442,"mc":[{"id":"1.230180135","rc":[{"atb":[[1.29,0]],"id":41401491}],"con":true,"img":false}]}
{"op":"mcm","clk":"11541562568","pt":1719507094648,"mc":[{"id":"1.230180135","rc":[{"atb":[[2.3,1],[2.38,4.58]],"id":52032624},{"atb":[[1.45,34.18],[1.49,5.77]],"id":4065261},{"atl":[[3.9,11.48],[4.2,0]],"id":69176457},{"atb":[[1.43,1],[1.47,4.52]],"id":65040144}],"con":true,"img":false}]}
{"op":"mcm","clk":"11541562575","pt":1719507094751,"mc":[{"id":"1.230180135","rc":[{"atl":[[3.45,13.7],[3.65,0]],"id":41401491},{"atb":[[2.32,23.23],[2.3,0]],"id":52032624},{"atl":[[19.5,5.55],[21,4.56]],"id":52032624},{"atl":[[6.6,6.82],[7,5.81]],"id":4065261},{"atb":[[1.44,5.53],[1.43,0]],"id":65040144},{"atl":[[10,0],[9.2,4.51]],"id":65040144}],"con":true,"img":false}]}
{"op":"mcm","clk":"11541562583","pt":1719507094859,"mc":[{"id":"1.230180135","rc":[{"atb":[[2.34,5.57]],"id":52032624},{"atb":[[1.46,5.85],[1.47,6.84]],"id":4065261},{"atl":[[4,34.17],[4.1,11.27]],"id":69176457},{"atb":[[1.45,5.53]],"id":65040144}],"con":true,"img":false}]}
{"op":"mcm","clk":"11541562593","pt":1719507094957,"mc":[{"id":"1.230180135","rc":[{"atb":[[2.32,22.23]],"id":52032624},{"atb":[[1.44,4.53]],"id":65040144},{"atl":[[9.6,21.56],[9.2,5.35],[9.8,4.51]],"id":65040144}],"con":true,"img":false}]}
{"op":"mcm","clk":"11541562599","pt":1719507095059,"mc":[{"id":"1.230180135","rc":[{"atl":[[3.6,13.66],[3.55,14.67]],"id":41401491}],"con":true,"img":false}]}
{"op":"mcm","clk":"11541562623","pt":1719507095370,"mc":[{"id":"1.230180135","rc":[{"atb":[[1.44,0],[1.48,11.54]],"id":69176457}],"con":true,"img":false}]}
{"op":"mcm","clk":"11541562634","pt":1719507095574,"mc":[{"id":"1.230180135","rc":[{"atl":[[3.5,14.57]],"id":41401491},{"atb":[[2.36,4.59]],"id":52032624},{"atl":[[19,0.84]],"id":52032624},{"atb":[[1.48,5.83]],"id":4065261},{"atl":[[6.4,0.84]],"id":4065261},{"atl":[[3.95,11.32]],"id":69176457},{"atb":[[1.46,4.54]],"id":65040144},{"atl":[[9.4,4.5]],"id":65040144}],"con":true,"img":false}]}
{"op":"mcm","clk":"11541562642","pt":1719507095681,"mc":[{"id":"1.230180135","rc":[{"atl":[[3.45,21.58]],"id":41401491},{"atb":[[2.3,7.25],[2.38,12.46]],"id":52032624},{"atl":[[18.5,12.45]],"id":52032624},{"atb":[[1.49,13.65]],"id":4065261},{"atl":[[6.2,13.64]],"id":4065261},{"atl":[[4,33.32],[3.9,19.36]],"id":69176457},{"atb":[[1.47,12.41]],"id":65040144},{"atl":[[9.2,13.24]],"id":65040144}],"con":true,"img":false}]}
{"op":"mcm","clk":"11541562675","pt":1719507096052,"mc":[{"id":"1.230180135","rc":[{"atl":[[18,4.55],[21,0]],"id":52032624},{"atl":[[6,5.74],[7,0]],"id":4065261},{"atl":[[3.85,11.44]],"id":69176457}],"con":true,"img":false}]}
{"op":"mcm","clk":"11541562683","pt":1719507096145,"mc":[{"id":"1.230180135","rc":[{"atl":[[3.6,0],[3.4,13.7]],"id":41401491},{"atl":[[4.1,0]],"id":69176457},{"atl":[[9.8,0]],"id":65040144}],"con":true,"img":false}]}
{"op":"mcm","clk":"11541562689","pt":1719507096250,"mc":[{"id":"1.230180135","rc":[{"atl":[[19,1.84],[19.5,4.55]],"id":52032624},{"atl":[[6.4,1.84],[6.6,5.82]],"id":4065261},{"atl":[[4,32.32],[3.95,12.32]],"id":69176457},{"atl":[[9,4.51]],"id":65040144}],"con":true,"img":false}]}
{"op":"mcm","clk":"11541562697","pt":1719507096352,"mc":[{"id":"1.230180135","rc":[{"atb":[[2.32,4.58]],"id":52032624},{"atl":[[20,4.55]],"id":52032624},{"atl":[[6.8,5.82]],"id":4065261},{"atl":[[4,11.3]],"id":69176457},{"atl":[[9.6,17.05]],"id":65040144}],"con":true,"img":false}]}
{"op":"mcm","clk":"11541562706","pt":1719507096455,"mc":[{"id":"1.230180135","rc":[{"atl":[[19,1]],"id":52032624},{"atl":[[6.4,1]],"id":4065261}],"con":true,"img":false}]}
{"op":"mcm","clk":"11541562715","pt":1719507096577,"mc":[{"id":"1.230180135","rc":[{"atb":[[2.38,29.04]],"id":52032624},{"atl":[[18.5,16.35]],"id":52032624},{"atl":[[6.2,20.46]],"id":4065261},{"atb":[[1.47,11.42]],"id":69176457},{"atl":[[3.9,40.38]],"id":69176457},{"atl":[[9.2,17.57]],"id":65040144}],"con":true,"img":false}]}
{"op":"mcm","clk":"11541562721","pt":1719507096660,"mc":[{"id":"1.230180135","rc":[{"atb":[[1.48,19.43]],"id":69176457}],"con":true,"img":false}]}
{"op":"mcm","clk":"11541562737","pt":1719507096970,"mc":[{"id":"1.230180135","rc":[{"atl":[[3.5,13.72]],"id":41401491}],"con":true,"img":false}]}
{"op":"mcm","clk":"11541562769","pt":1719507097484,"mc":[{"id":"1.230180135","rc":[{"atl":[[3.8,0.84]],"id":69176457}],"con":true,"img":false}]}
{"op":"mcm","clk":"11541562777","pt":1719507097593,"mc":[{"id":"1.230180135","rc":[{"atl":[[3.45,13.7],[3.55,13.67],[3.5,14.72]],"id":41401491},{"atb":[[2.32,0],[2.4,4.58]],"id":52032624},{"atl":[[18.5,8.47]],"id":52032624},{"atb":[[1.46,0],[1.5,5.79]],"id":4065261},{"atl":[[6.2,12.57]],"id":4065261},{"atl":[[3.9,32.5]],"id":69176457},{"atb":[[1.44,0],[1.45,11.03],[1.48,4.54]],"id":65040144},{"atl":[[9.6,16.05],[9.2,9.68],[9.4,5.5]],"id":65040144}],"con":true,"img":false}]}
{"op":"mcm","clk":"11541562784","pt":1719507097647,"mc":[{"id":"1.230180135","rc":[{"atl":[[3.4,21.58]],"id":41401491},{"atl":[[18,12.43]],"id":52032624},{"atl":[[6,13.62]],"id":4065261},{"atl":[[3.85,19.33],[3.95,11.32],[3.9,33.5]],"id":69176457},{"atl":[[9,12.39]],"id":65040144}],"con":true,"img":false}]}
{"op":"mcm","clk":"11541562797","pt":1719507097848,"mc":[{"id":"1.230180135","rc":[{"atl":[[3.35,13.67],[3.55,0]],"id":41401491},{"atl":[[17.5,4.56],[20,0]],"id":52032624},{"atl":[[6.8,0],[5.9,5.74]],"id":4065261},{"atb":[[1.45,0]],"id":69176457},{"atl":[[9.6,11.54],[8.8,4.51]],"id":65040144}],"con":true,"img":false}]}
{"op":"mcm","clk":"11541562804","pt":1719507097952,"mc":[{"id":"1.230180135","rc":[{"atb":[[2.3,4.75]],"id":52032624},{"atb":[[1.49,11.53]],"id":69176457},{"atl":[[4,0],[3.8,12.25]],"id":69176457}],"con":true,"img":false}]}
{"op":"mcm","clk":"11541562835","pt":1719507098059,"mc":[{"id":"1.230180135","rc":[{"atb":[[2.3,0]],"id":52032624},{"atl":[[5.4,2.83]],"id":4065261},{"atb":[[1.45,5.53]],"id":65040144}],"con":true,"img":false}]}
{"op":"mcm","clk":"11541562844","pt":1719507098159,"mc":[{"id":"1.230180135","rc":[{"atb":[[2.34,9.37]],"id":52032624}],"con":true,"img":false}]}
{"op":"mcm","clk":"11541562866","pt":1719507098470,"mc":[{"id":"1.230180135","rc":[{"atb":[[2.34,5.57]],"id":52032624},{"atl":[[9.2,8.84]],"id":65040144}],"con":true,"img":false}]}
{"op":"mcm","clk":"11541562875","pt":1719507098573,"mc":[{"id":"1.230180135","rc":[{"atl":[[3.4,13.7]],"id":41401491},{"atb":[[2.38,21.16]],"id":52032624},{"atl":[[18,4.55]],"id":52032624},{"atb":[[1.49,5.77]],"id":4065261},{"atl":[[6,5.74]],"id":4065261},{"atb":[[1.48,11.54]],"id":69176457},{"atl":[[3.85,11.44]],"id":69176457},{"atb":[[1.41,6.25],[1.47,4.52]],"id":65040144},{"atl":[[9,4.51]],"id":65040144}],"con":true,"img":false}]}
{"op":"mcm","clk":"11541562882","pt":1719507098676,"mc":[{"id":"1.230180135","rc":[{"atl":[[3.35,21.55]],"id":41401491},{"atb":[[2.4,12.46]],"id":52032624},{"atl":[[17.5,12.44]],"id":52032624},{"atb":[[1.5,13.67]],"id":4065261},{"atl":[[5.9,13.62]],"id":4065261},{"atb":[[1.49,19.41]],"id":69176457},{"atl":[[3.8,20.14]],"id":69176457},{"atb":[[1.48,12.42]],"id":65040144},{"atl":[[8.8,12.39]],"id":65040144}],"con":true,"img":false}]}
{"op":"mcm","clk":"11541562891","pt":1719507098784,"mc":[{"id":"1.230180135","rc":[{"atb":[[2.36,5.59],[2.34,4.57]],"id":52032624},{"atl":[[18.5,9.47],[19,0]],"id":52032624},{"atb":[[1.48,6.83],[1.47,5.84]],"id":4065261},{"atl":[[6.4,0],[5.6,1]],"id":4065261},{"atb":[[1.46,5.54]],"id":65040144},{"atl":[[9.2,9.84]],"id":65040144}],"con":true,"img":false}]}
{"op":"mcm","clk":"11541562899","pt":1719507098887,"mc":[{"id":"1.230180135","rc":[{"atb":[[1.45,4.53]],"id":65040144},{"atl":[[9.4,4.5]],"id":65040144}],"con":true,"img":false}]}
{"op":"mcm","clk":"11541562907","pt":1719507098985,"mc":[{"id":"1.230180135","rc":[{"atl":[[3.5,1],[3.3,13.72]],"id":41401491},{"atl":[[17,4.56],[19.5,0]],"id":52032624},{"atb":[[1.51,5.76],[1.47,0]],"id":4065261},{"atl":[[3.95,0],[3.75,11.44]],"id":69176457},{"atl":[[8.6,4.51],[9.4,0]],"id":65040144}],"con":true,"img":false}]}
{"op":"mcm","clk":"11541562939","pt":1719507099450,"mc":[{"id":"1.230180135","rc":[{"atl":[[5.6,12.47],[21,0],[5.4,8.56]],"id":4065261}],"con":true,"img":false}]}
{"op":"mcm","clk":"11541562945","pt":1719507099553,"mc":[{"id":"1.230180135","rc":[{"atl":[[3.35,13.67]],"id":41401491},{"atl":[[17.5,4.56]],"id":52032624},{"atb":[[1.5,5.79]],"id":4065261},{"atl":[[6.6,0],[5.9,5.74]],"id":4065261},{"atl":[[3.8,12.25]],"id":69176457}],"con":true,"img":false}]}
{"op":"mcm","clk":"11541562949","pt":1719507099654,"mc":[{"id":"1.230180135","rc":[{"atl":[[3.4,14.7],[3.3,21.6],[3.5,0]],"id":41401491},{"atl":[[17,12.44],[18,5.55],[18.5,8.47]],"id":52032624},{"atb":[[1.49,6.77],[1.51,13.64],[1.48,5.83]],"id":4065261},{"atl":[[5.4,16.44]],"id":4065261},{"atl":[[3.85,12.44],[3.9,32.5],[3.75,19.32]],"id":69176457},{"atl":[[9,5.51],[9.2,8.84],[8.8,4.51]],"id":65040144}],"con":true,"img":false}]}
{"op":"mcm","clk":"11541562954","pt":1719507099758,"mc":[{"id":"1.230180135","rc":[{"atl":[[8.6,12.4]],"id":65040144}],"con":true,"img":false}]}
{"op":"mcm","clk":"11541562969","pt":1719507099964,"mc":[{"id":"1.230180135","rc":[{"atl":[[3.25,0.84]],"id":41401491},{"spn":2.28,"spf":1.0,"id":41401491},{"atl":[[16.5,0.84]],"id":52032624},{"spn":9.45,"spf":1.0,"id":52032624},{"atl":[[5.3,0.84]],"id":4065261},{"spn":3.4,"spf":1.0,"id":4065261},{"spn":2.62,"spf":1.0,"id":69176457},{"atb":[[1.41,0]],"id":65040144},{"spn":8.6,"spf":504.82,"id":65040144}],"con":true,"img":false}]}
{"op":"mcm","clk":"11541563001","pt":1719507100377,"mc":[{"id":"1.230180135","rc":[{"atl":[[3.45,0],[3.35,14.67],[3.4,13.7],[3.25,14.58]],"id":41401491},{"atb":[[2.42,4.58],[2.34,0]],"id":52032624},{"atl":[[17.5,5.56],[18,4.55]],"id":52032624},{"atb":[[1.48,0],[1.52,5.76]],"id":4065261},{"atl":[[5.6,11.47],[5.5,1]],"id":4065261},{"atb":[[1.46,0],[1.5,11.54]],"id":69176457},{"atb":[[1.45,0],[1.49,4.53]],"id":65040144}],"con":true,"img":false}]}
{"op":"mcm","clk":"11541563009","pt":1719507100480,"mc":[{"id":"1.230180135","rc":[{"atl":[[6.2,6.81],[5.3,6.58]],"id":4065261},{"atl":[[9.2,4.32],[8.4,4.51]],"id":65040144}],"con":true,"img":false}]}
{"op":"mcm","clk":"11541563016","pt":1719507100583,"mc":[{"id":"1.230180135","rc":[{"atl":[[3.3,13.72]],"id":41401491},{"atb":[[2.36,4.59],[2.38,22.16]],"id":52032624},{"atl":[[17,4.56]],"id":52032624},{"atb":[[1.5,6.79],[1.49,5.77]],"id":4065261},{"atl":[[5.4,8.56]],"id":4065261},{"atb":[[1.46,4.54],[1.47,5.52]],"id":65040144}],"con":true,"img":false}]}
{"op":"mcm","clk":"11541563022","pt":1719507100686,"mc":[{"id":"1.230180135","rc":[{"atl":[[3.25,22.46]],"id":41401491},{"atl":[[16.5,13.28],[18.5,3.9]],"id":52032624},{"atl":[[5.3,14.46]],"id":4065261},{"atl":[[3.7,11.38],[3.9,21.01]],"id":69176457}],"con":true,"img":false}]}
{"op":"mcm","clk":"11541563032","pt":1719507100739,"mc":[{"id":"1.230180135","rc":[{"atl":[[9,4.51],[8.8,5.51]],"id":65040144}],"con":true,"img":false}]}
{"op":"mcm","clk":"11541563059","pt":1719507101150,"mc":[{"id":"1.230180135","rc":[{"atl":[[3.4,0]],"id":41401491}],"con":true,"img":false}]}
{"op":"mcm","clk":"11541563068","pt":1719507101253,"mc":[{"id":"1.230180135","rc":[{"atl":[[3.2,13.98]],"id":41401491},{"atb":[[2.38,5.58]],"id":52032624},{"atl":[[18.5,0]],"id":52032624},{"atl":[[6.2,0]],"id":4065261},{"atl":[[3.9,0]],"id":69176457},{"atl":[[9.2,0]],"id":65040144}],"con":true,"img":false}]}
{"op":"mcm","clk":"11541563079","pt":1719507101357,"mc":[{"id":"1.230180135","rc":[{"atl":[[16,4.55],[18,0]],"id":52032624}],"con":true,"img":false}]}
{"op":"mcm","clk":"11541563087","pt":1719507101459,"mc":[{"id":"1.230180135","rc":[{"atb":[[2.4,28.71]],"id":52032624},{"atl":[[16.5,17.69]],"id":52032624},{"atl":[[5.3,20.17]],"id":4065261},{"atb":[[1.5,1.55]],"id":69176457},{"atl":[[3.8,11.41],[3.75,40.34]],"id":69176457},{"trd":[[1.5,19.99]],"ltp":1.5,"tv":19.99,"id":69176457},{"atl":[[8.4,8.43]],"id":65040144}],"con":true,"img":false}]}
{"op":"mcm","clk":"11541563092","pt":1719507101563,"mc":[{"id":"1.230180135","rc":[{"atb":[[2.4,20.83]],"id":52032624},{"atb":[[1.51,5.76]],"id":4065261},{"atb":[[1.49,11.53]],"id":69176457},{"atl":[[3.75,32.46]],"id":69176457},{"atb":[[1.48,4.54]],"id":65040144},{"atl":[[8.6,4.51]],"id":65040144}],"con":true,"img":false}]}
{"op":"mcm","clk":"11541563100","pt":1719507101666,"mc":[{"id":"1.230180135","rc":[{"atb":[[2.42,12.46]],"id":52032624},{"atl":[[17,5.56],[17.5,4.56]],"id":52032624},{"atb":[[1.52,13.64]],"id":4065261},{"atl":[[5.4,5.73]],"id":4065261},{"atb":[[1.5,9.43]],"id":69176457},{"atl":[[3.85,11.44],[3.7,19.26],[3.8,12.41],[3.65,3]],"id":69176457},{"atb":[[1.49,12.42]],"id":65040144},{"atl":[[8.4,16.31]],"id":65040144}],"con":true,"img":false}]}
{"op":"mcm","clk":"11541563107","pt":1719507101771,"mc":[{"id":"1.230180135","rc":[{"atb":[[1.49,0],[1.53,5.69]],"id":4065261},{"atl":[[3.85,0],[3.65,14.52]],"id":69176457},{"atl":[[9,0],[8.2,4.49]],"id":65040144}],"con":true,"img":false}]}
{"op":"mcm","clk":"11541563114","pt":1719507101878,"mc":[{"id":"1.230180135","rc":[{"atl":[[5.5,3]],"id":4065261}],"con":true,"img":false}]}
{"op":"mcm","clk":"11541563135","pt":1719507102078,"mc":[{"id":"1.230180135","rc":[{"atb":[[1.5,12.03]],"id":4065261}],"con":true,"img":false}]}
{"op":"mcm","clk":"11541563160","pt":1719507102389,"mc":[{"id":"1.230180135","rc":[{"atb":[[2.44,1.94]],"id":52032624}],"con":true,"img":false}]}
{"op":"mcm","clk":"11541563170","pt":1719507102440,"mc":[{"id":"1.230180135","rc":[{"atb":[[2.46,2.81]],"id":52032624},{"atl":[[15.5,1.14]],"id":52032624},{"atb":[[1.5,6.79]],"id":4065261},{"atl":[[8,0.84]],"id":65040144}],"con":true,"img":false}]}
{"op":"mcm","clk":"11541563180","pt":1719507102543,"mc":[{"id":"1.230180135","rc":[{"atb":[[1.29,6.38]],"id":41401491},{"atl":[[3.25,14.58]],"id":41401491},{"atl":[[16.5,9.81]],"id":52032624},{"atb":[[1.52,5.76]],"id":4065261},{"atl":[[3.7,11.38]],"id":69176457},{"atl":[[8.4,8.43]],"id":65040144}],"con":true,"img":false}]}
{"op":"mcm","clk":"11541563188","pt":1719507102649,"mc":[{"id":"1.230180135","rc":[{"atl":[[3.2,21.86]],"id":41401491},{"atl":[[16,12.43]],"id":52032624},{"atb":[[1.53,13.57]],"id":4065261},{"atl":[[3.65,22.4]],"id":69176457},{"atl":[[8.2,12.37]],"id":65040144}],"con":true,"img":false}]}
{"op":"mcm","clk":"11541563198","pt":1719507102760,"mc":[{"id":"1.230180135","rc":[{"atb":[[1.29,0]],"id":41401491}],"con":true,"img":false}]}
{"op":"mcm","clk":"11541563204","pt":1719507102854,"mc":[{"id":"1.230180135","rc":[{"atb":[[1.47,17.67]],"id":69176457}],"con":true,"img":false}]}
{"op":"mcm","clk":"11541563252","pt":1719507103576,"mc":[{"id":"1.230180135","rc":[{"atb":[[2.42,4.58]],"id":52032624},{"atl":[[16,4.55]],"id":52032624},{"atl":[[8.2,4.49]],"id":65040144}],"con":true,"img":false}]}
{"op":"mcm","clk":"11541563258","pt":1719507103679,"mc":[{"id":"1.230180135","rc":[{"atb":[[2.46,10.69]],"id":52032624},{"atl":[[15.5,9.02]],"id":52032624},{"atl":[[8,8.72]],"id":65040144}],"con":true,"img":false}]}
{"op":"mcm","clk":"11541563268","pt":1719507103787,"mc":[{"id":"1.230180135","rc":[{"atl":[[3.35,13.67],[3.3,14.72]],"id":41401491}],"con":true,"img":false}]}
{"op":"mcm","clk":"11541563276","pt":1719507103891,"mc":[{"id":"1.230180135","rc":[{"atb":[[1.5,5.79],[1.51,6.76]],"id":4065261}],"con":true,"img":false}]}
{"op":"mcm","clk":"11541563296","pt":1719507104047,"mc":[{"id":"1.230180135","rc":[{"atb":[[2.38,10.58]],"id":52032624},{"atl":[[8.8,4.51],[8.4,9.43]],"id":65040144}],"con":true,"img":false}]}
{"op":"mcm","clk":"11541563303","pt":1719507104145,"mc":[{"id":"1.230180135","rc":[{"atl":[[3.35,0],[3.15,13.99]],"id":41401491},{"atl":[[17.5,0],[15,4.55]],"id":52032624},{"atb":[[1.54,5.68],[1.5,0]],"id":4065261},{"atl":[[3.6,11.53],[3.8,1]],"id":69176457},{"atl":[[7.8,4.49]],"id":65040144}],"con":true,"img":false}]}
{"op":"mcm","clk":"11541563306","pt":1719507104246,"mc":[{"id":"1.230180135","rc":[{"atl":[[14.5,1.33]],"id":52032624},{"atl":[[8.8,0]],"id":65040144}],"con":true,"img":false}]}
{"op":"mcm","clk":"11541563315","pt":1719507104351,"mc":[{"id":"1.230180135","rc":[{"atl":[[3.65,21.4]],"id":69176457}],"con":true,"img":false}]}
{"op":"mcm","clk":"11541563324","pt":1719507104453,"mc":[{"id":"1.230180135","rc":[{"atl":[[16.5,8.96]],"id":52032624}],"con":true,"img":false}]}
{"op":"mcm","clk":"11541563325","pt":1719507104556,"mc":[{"id":"1.230180135","rc":[{"atb":[[2.42,5.58],[2.38,9.58]],"id":52032624},{"atl":[[17,4.56],[15.5,10.02]],"id":52032624},{"atb":[[1.51,5.76],[1.52,6.76]],"id":4065261},{"atb":[[1.51,11.62],[1.47,6.25]],"id":69176457},{"atl":[[3.7,12.38],[3.8,0]],"id":69176457},{"atl":[[8.2,5.49],[8.4,8.43]],"id":65040144}],"con":true,"img":false}]}
{"op":"mcm","clk":"11541563337","pt":1719507104761,"mc":[{"id":"1.230180135","rc":[{"atl":[[3.65,19.4]],"id":69176457}],"con":true,"img":false}]}
{"op":"mcm","clk":"11541563346","pt":1719507104871,"mc":[{"id":"1.230180135","rc":[{"atb":[[2.38,4.58]],"id":52032624},{"atl":[[3.55,2]],"id":69176457}],"con":true,"img":false}]}
{"op":"mcm","clk":"11541563352","pt":1719507104975,"mc":[{"id":"1.230180135","rc":[{"atl":[[3.25,13.73]],"id":41401491},{"atl":[[3.55,2.84]],"id":69176457}],"con":true,"img":false}]}
{"op":"mcm","clk":"11541563367","pt":1719507105176,"mc":[{"id":"1.230180135","rc":[{"atb":[[1.47,0]],"id":69176457}],"con":true,"img":false}]}
{"op":"mcm","clk":"11541563392","pt":1719507105492,"mc":[{"id":"1.230180135","rc":[{"atb":[[2.44,0]],"id":52032624}],"con":true,"img":false}]}
{"op":"mcm","clk":"11541563405","pt":1719507105607,"mc":[{"id":"1.230180135","rc":[{"atl":[[3.2,13.98]],"id":41401491},{"atb":[[2.48,1.94]],"id":52032624},{"atl":[[15.5,2.14]],"id":52032624},{"atb":[[1.53,5.69]],"id":4065261},{"atb":[[1.5,1.55]],"id":69176457},{"atl":[[3.65,11.52]],"id":69176457},{"atl":[[8,0.84]],"id":65040144}],"con":true,"img":false}]}
{"op":"mcm","clk":"11541563414","pt":1719507105656,"mc":[{"id":"1.230180135","rc":[{"atl":[[3.15,21.87]],"id":41401491},{"atb":[[2.5,2.69]],"id":52032624},{"atl":[[14.5,9.21]],"id":52032624},{"atb":[[1.54,13.56]],"id":4065261},{"atb":[[1.51,19.5]],"id":69176457},{"atl":[[3.55,10.72]],"id":69176457},{"atl":[[7.8,12.37]],"id":65040144}],"con":true,"img":false}]}
{"op":"mcm","clk":"11541563436","pt":1719507105868,"mc":[{"id":"1.230180135","rc":[{"atb":[[2.5,7.26],[2.48,11.09],[2.36,0]],"id":52032624},{"atb":[[1.55,5.68]],"id":4065261},{"atb":[[1.48,0],[1.52,11.61]],"id":69176457},{"atl":[[8.6,0],[7.6,4.51]],"id":65040144}],"con":true,"img":false}]}
{"op":"mcm","clk":"11541563442","pt":1719507105968,"mc":[{"id":"1.230180135","rc":[{"atb":[[2.42,4.58],[2.46,11.69]],"id":52032624},{"atb":[[1.51,0]],"id":4065261},{"atl":[[3.7,11.38],[3.65,12.52]],"id":69176457}],"con":true,"img":false}]}
{"op":"mcm","clk":"11541563452","pt":1719507106072,"mc":[{"id":"1.230180135","rc":[{"atb":[[2.4,4.58]],"id":52032624},{"atl":[[16.5,4.55]],"id":52032624},{"atb":[[1.53,6.69],[1.52,5.76]],"id":4065261},{"atl":[[3.75,11.44]],"id":69176457},{"atl":[[8,1.84],[8.2,4.49],[8.4,4.51]],"id":65040144}],"con":true,"img":false}]}
{"op":"mcm","clk":"11541563462","pt":1719507106177,"mc":[{"id":"1.230180135","rc":[{"atb":[[2.46,26.98]],"id":52032624},{"atl":[[14.5,13.74]],"id":52032624},{"atl":[[3.6,32.55]],"id":69176457},{"atl":[[7.8,15.92]],"id":65040144}],"con":true,"img":false}]}
{"op":"mcm","clk":"11541563481","pt":1719507106382,"mc":[{"id":"1.230180135","rc":[{"atl":[[3.5,1]],"id":69176457}],"con":true,"img":false}]}
{"op":"mcm","clk":"11541563498","pt":1719507106591,"mc":[{"id":"1.230180135","rc":[{"atb":[[1.54,5.68]],"id":4065261},{"atb":[[1.51,11.62]],"id":69176457},{"atl":[[8,1],[7.8,8.04]],"id":65040144}],"con":true,"img":false}]}
{"op":"mcm","clk":"11541563504","pt":1719507106694,"mc":[{"id":"1.230180135","rc":[{"atb":[[2.46,19.1]],"id":52032624},{"atb":[[1.55,13.56]],"id":4065261},{"atb":[[1.52,19.49]],"id":69176457},{"atl":[[7.6,12.39]],"id":65040144}],"con":true,"img":false}]}
{"op":"mcm","clk":"11541563511","pt":1719507106755,"mc":[{"id":"1.230180135","rc":[{"atb":[[2.5,15.14]],"id":52032624}],"con":true,"img":false}]}
{"op":"mcm","clk":"11541563522","pt":1719507106951,"mc":[{"id":"1.230180135","rc":[{"atl":[[3.1,0.84],[3.25,14.73],[3.3,13.72]],"id":41401491},{"atl":[[14,0.84]],"id":52032624}],"con":true,"img":false}]}
{"op":"mcm","clk":"11541563528","pt":1719507107055,"mc":[{"id":"1.230180135","rc":[{"atb":[[1.49,16.53]],"id":69176457},{"atb":[[1.45,4.88]],"id":65040144}],"con":true,"img":false}]}
{"op":"mcm","clk":"11541563539","pt":1719507107261,"mc":[{"id":"1.230180135","rc":[{"atl":[[5.2,5.65]],"id":4065261},{"atl":[[3.55,33.75],[3.5,12.51],[3.75,0]],"id":69176457},{"atb":[[1.45,0]],"id":65040144}],"con":true,"img":false}]}
{"op":"mcm","clk":"11541563543","pt":1719507107362,"mc":[{"id":"1.230180135","rc":[{"atl":[[6,0]],"id":4065261}],"con":true,"img":false}]}
{"op":"mcm","clk":"11541563547","pt":1719507107472,"mc":[{"id":"1.230180135","rc":[{"atl":[[3.15,13.99]],"id":41401491},{"atb":[[2.4,9.46]],"id":52032624},{"atl":[[14.5,5.86]],"id":52032624},{"atl":[[3.45,0.52],[3.55,25.87]],"id":69176457}],"con":true,"img":false}]}
{"op":"mcm","clk":"11541563554","pt":1719507107570,"mc":[{"id":"1.230180135","rc":[{"atl":[[3.1,8.72]],"id":41401491},{"atl":[[14,8.72]],"id":52032624},{"atl":[[3.5,20.39]],"id":69176457}],"con":true,"img":false}]}
