{"op":"mcm","clk":"11547086383","pt":1719432856302,"mc":[{"id":"1.230178167","marketDefinition":{"bspMarket":false,"turnInPlayEnabled":false,"persistenceEnabled":false,"marketBaseRate":5.0,"eventId":"33376048","eventTypeId":"4339","numberOfWinners":1,"bettingType":"ODDS","marketType":"FORECAST","marketTime":"2024-06-27T13:48:00.000Z","suspendTime":"2024-06-27T13:48:00.000Z","bspReconciled":false,"complete":true,"inPlay":false,"crossMatching":false,"runnersVoidable":false,"numberOfActiveRunners":30,"betDelay":0,"status":"OPEN","runners":[{"status":"ACTIVE","sortPriority":1,"id":52385882,"name":"1 - 2"},{"status":"ACTIVE","sortPriority":2,"id":52385883,"name":"1 - 3"},{"status":"ACTIVE","sortPriority":3,"id":52385884,"name":"1 - 4"},{"status":"ACTIVE","sortPriority":4,"id":52385885,"name":"1 - 5"},{"status":"ACTIVE","sortPriority":5,"id":52385886,"name":"1 - 6"},{"status":"ACTIVE","sortPriority":6,"id":52385889,"name":"2 - 1"},{"status":"ACTIVE","sortPriority":7,"id":52385890,"name":"2 - 3"},{"status":"ACTIVE","sortPriority":8,"id":52385891,"name":"2 - 4"},{"status":"ACTIVE","sortPriority":9,"id":52385892,"name":"2 - 5"},{"status":"ACTIVE","sortPriority":10,"id":52385893,"name":"2 - 6"},{"status":"ACTIVE","sortPriority":11,"id":52385896,"name":"3 - 1"},{"status":"ACTIVE","sortPriority":12,"id":52385897,"name":"3 - 2"},{"status":"ACTIVE","sortPriority":13,"id":52385898,"name":"3 - 4"},{"status":"ACTIVE","sortPriority":14,"id":52385899,"name":"3 - 5"},{"status":"ACTIVE","sortPriority":15,"id":52385900,"name":"3 - 6"},{"status":"ACTIVE","sortPriority":16,"id":52385903,"name":"4 - 1"},{"status":"ACTIVE","sortPriority":17,"id":52385904,"name":"4 - 2"},{"status":"ACTIVE","sortPriority":18,"id":52385905,"name":"4 - 3"},{"status":"ACTIVE","sortPriority":19,"id":52385906,"name":"4 - 5"},{"status":"ACTIVE","sortPriority":20,"id":52385907,"name":"4 - 6"},{"status":"ACTIVE","sortPriority":21,"id":52385910,"name":"5 - 1"},{"status":"ACTIVE","sortPriority":22,"id":52385911,"name":"5 - 2"},{"status":"ACTIVE","sortPriority":23,"id":52385912,"name":"5 - 3"},{"status":"ACTIVE","sortPriority":24,"id":52385913,"name":"5 - 4"},{"status":"ACTIVE","sortPriority":25,"id":52385914,"name":"5 - 6"},{"status":"ACTIVE","sortPriority":26,"id":52385917,"name":"6 - 1"},{"status":"ACTIVE","sortPriority":27,"id":52385918,"name":"6 - 2"},{"status":"ACTIVE","sortPriority":28,"id":52385919,"name":"6 - 3"},{"status":"ACTIVE","sortPriority":29,"id":52385920,"name":"6 - 4"},{"status":"ACTIVE","sortPriority":30,"id":52385921,"name":"6 - 5"}],"regulators":["MR_INT"],"venue":"Perry Barr","countryCode":"GB","discountAllowed":false,"timezone":"Europe/London","openDate":"2024-06-27T13:29:00.000Z","version":5994794108,"name":"Forecast","eventName":"Perry Barr (F/C) 27th Jun"},"rc":[],"con":true,"img":false}]}
{"op":"mcm","clk":"11547086542","pt":1719432858308,"mc":[{"id":"1.230178167","marketDefinition":{"bspMarket":false,"turnInPlayEnabled":false,"persistenceEnabled":false,"marketBaseRate":5.0,"eventId":"33376048","eventTypeId":"4339","numberOfWinners":1,"bettingType":"ODDS","marketType":"FORECAST","marketTime":"2024-06-27T13:48:00.000Z","suspendTime":"2024-06-27T13:48:00.000Z","bspReconciled":false,"complete":true,"inPlay":false,"crossMatching":false,"runnersVoidable":false,"numberOfActiveRunners":30,"betDelay":0,"status":"OPEN","runners":[{"status":"ACTIVE","sortPriority":1,"id":52385882,"name":"1 - 2"},{"status":"ACTIVE","sortPriority":2,"id":52385883,"name":"1 - 3"},{"status":"ACTIVE","sortPriority":3,"id":52385884,"name":"1 - 4"},{"status":"ACTIVE","sortPriority":4,"id":52385885,"name":"1 - 5"},{"status":"ACTIVE","sortPriority":5,"id":52385886,"name":"1 - 6"},{"status":"ACTIVE","sortPriority":6,"id":52385889,"name":"2 - 1"},{"status":"ACTIVE","sortPriority":7,"id":52385890,"name":"2 - 3"},{"status":"ACTIVE","sortPriority":8,"id":52385891,"name":"2 - 4"},{"status":"ACTIVE","sortPriority":9,"id":52385892,"name":"2 - 5"},{"status":"ACTIVE","sortPriority":10,"id":52385893,"name":"2 - 6"},{"status":"ACTIVE","sortPriority":11,"id":52385896,"name":"3 - 1"},{"status":"ACTIVE","sortPriority":12,"id":52385897,"name":"3 - 2"},{"status":"ACTIVE","sortPriority":13,"id":52385898,"name":"3 - 4"},{"status":"ACTIVE","sortPriority":14,"id":52385899,"name":"3 - 5"},{"status":"ACTIVE","sortPriority":15,"id":52385900,"name":"3 - 6"},{"status":"ACTIVE","sortPriority":16,"id":52385903,"name":"4 - 1"},{"status":"ACTIVE","sortPriority":17,"id":52385904,"name":"4 - 2"},{"status":"ACTIVE","sortPriority":18,"id":52385905,"name":"4 - 3"},{"status":"ACTIVE","sortPriority":19,"id":52385906,"name":"4 - 5"},{"status":"ACTIVE","sortPriority":20,"id":52385907,"name":"4 - 6"},{"status":"ACTIVE","sortPriority":21,"id":52385910,"name":"5 - 1"},{"status":"ACTIVE","sortPriority":22,"id":52385911,"name":"5 - 2"},{"status":"ACTIVE","sortPriority":23,"id":52385912,"name":"5 - 3"},{"status":"ACTIVE","sortPriority":24,"id":52385913,"name":"5 - 4"},{"status":"ACTIVE","sortPriority":25,"id":52385914,"name":"5 - 6"},{"status":"ACTIVE","sortPriority":26,"id":52385917,"name":"6 - 1"},{"status":"ACTIVE","sortPriority":27,"id":52385918,"name":"6 - 2"},{"status":"ACTIVE","sortPriority":28,"id":52385919,"name":"6 - 3"},{"status":"ACTIVE","sortPriority":29,"id":52385920,"name":"6 - 4"},{"status":"ACTIVE","sortPriority":30,"id":52385921,"name":"6 - 5"}],"regulators":["MR_INT"],"venue":"Perry Barr","countryCode":"GB","discountAllowed":true,"timezone":"Europe/London","openDate":"2024-06-27T13:29:00.000Z","version":5994794108,"name":"Forecast","eventName":"Perry Barr (F/C) 27th Jun"},"rc":[],"con":true,"img":false}]}
{"op":"mcm","clk":"11547344368","pt":1719439058488,"mc":[{"id":"1.230178167","rc":[{"atb":[[1.03,7.81]],"id":52385910},{"atb":[[1.02,11.71]],"id":52385912},{"atb":[[1.01,23.42]],"id":52385906},{"atb":[[1.03,7.81]],"id":52385918},{"atb":[[1.01,23.42]],"id":52385920},{"atb":[[1.01,23.42]],"id":52385889},{"atb":[[1.02,11.71]],"id":52385914},{"atb":[[1.01,23.42]],"id":52385883},{"atb":[[1.02,11.71]],"id":52385885},{"atb":[[1.02,11.71]],"id":52385896},{"atb":[[1.01,23.42]],"id":52385890},{"atb":[[1.03,7.81]],"id":52385892},{"atb":[[1.02,11.71]],"id":52385904},{"atb":[[1.02,11.71]],"id":52385898},{"atb":[[1.02,11.71]],"id":52385900},{"atb":[[1.01,23.42]],"id":52385911},{"atb":[[1.02,11.71]],"id":52385913},{"atb":[[1.01,23.42]],"id":52385907},{"atb":[[1.02,11.71]],"id":52385886},{"atb":[[1.01,23.42]],"id":52385919},{"atb":[[1.01,23.42]],"id":52385921},{"atb":[[1.03,7.81]],"id":52385882},{"atb":[[1.03,7.81]],"id":52385884},{"atb":[[1.02,11.71]],"id":52385917},{"atb":[[1.01,23.42]],"id":52385897},{"atb":[[1.02,11.71]],"id":52385891},{"atb":[[1.02,11.71]],"id":52385893},{"atb":[[1.01,23.42]],"id":52385903},{"atb":[[1.01,23.42]],"id":52385905},{"atb":[[1.03,7.81]],"id":52385899}],"con":true,"img":false}]}
{"op":"mcm","clk":"11547371377","pt":1719439682622,"mc":[{"id":"1.230178167","marketDefinition":{"bspMarket":false,"turnInPlayEnabled":false,"persistenceEnabled":false,"marketBaseRate":5.0,"eventId":"33376048","eventTypeId":"4339","numberOfWinners":1,"bettingType":"ODDS","marketType":"FORECAST","marketTime":"2024-06-27T13:48:00.000Z","suspendTime":"2024-06-27T13:48:00.000Z","bspReconciled":false,"complete":true,"inPlay":false,"crossMatching":false,"runnersVoidable":false,"numberOfActiveRunners":30,"betDelay":0,"status":"OPEN","runners":[{"status":"ACTIVE","sortPriority":1,"id":52385882,"name":"1 - 2"},{"status":"ACTIVE","sortPriority":2,"id":52385883,"name":"1 - 3"},{"status":"ACTIVE","sortPriority":3,"id":52385884,"name":"1 - 4"},{"status":"ACTIVE","sortPriority":4,"id":52385885,"name":"1 - 5"},{"status":"ACTIVE","sortPriority":5,"id":52385886,"name":"1 - 6"},{"status":"ACTIVE","sortPriority":6,"id":52385889,"name":"2 - 1"},{"status":"ACTIVE","sortPriority":7,"id":52385890,"name":"2 - 3"},{"status":"ACTIVE","sortPriority":8,"id":52385891,"name":"2 - 4"},{"status":"ACTIVE","sortPriority":9,"id":52385892,"name":"2 - 5"},{"status":"ACTIVE","sortPriority":10,"id":52385893,"name":"2 - 6"},{"status":"ACTIVE","sortPriority":11,"id":52385896,"name":"3 - 1"},{"status":"ACTIVE","sortPriority":12,"id":52385897,"name":"3 - 2"},{"status":"ACTIVE","sortPriority":13,"id":52385898,"name":"3 - 4"},{"status":"ACTIVE","sortPriority":14,"id":52385899,"name":"3 - 5"},{"status":"ACTIVE","sortPriority":15,"id":52385900,"name":"3 - 6"},{"status":"ACTIVE","sortPriority":16,"id":52385903,"name":"4 - 1"},{"status":"ACTIVE","sortPriority":17,"id":52385904,"name":"4 - 2"},{"status":"ACTIVE","sortPriority":18,"id":52385905,"name":"4 - 3"},{"status":"ACTIVE","sortPriority":19,"id":52385906,"name":"4 - 5"},{"status":"ACTIVE","sortPriority":20,"id":52385907,"name":"4 - 6"},{"status":"ACTIVE","sortPriority":21,"id":52385910,"name":"5 - 1"},{"status":"ACTIVE","sortPriority":22,"id":52385911,"name":"5 - 2"},{"status":"ACTIVE","sortPriority":23,"id":52385912,"name":"5 - 3"},{"status":"ACTIVE","sortPriority":24,"id":52385913,"name":"5 - 4"},{"status":"ACTIVE","sortPriority":25,"id":52385914,"name":"5 - 6"},{"status":"ACTIVE","sortPriority":26,"id":52385917,"name":"6 - 1"},{"status":"ACTIVE","sortPriority":27,"id":52385918,"name":"6 - 2"},{"status":"ACTIVE","sortPriority":28,"id":52385919,"name":"6 - 3"},{"status":"ACTIVE","sortPriority":29,"id":52385920,"name":"6 - 4"},{"status":"ACTIVE","sortPriority":30,"id":52385921,"name":"6 - 5"}],"regulators":["MR_INT"],"venue":"Perry Barr","countryCode":"GB","discountAllowed":true,"timezone":"Europe/London","openDate":"2024-06-27T13:29:00.000Z","version":5994794108,"name":"Forecast","eventName":"Perry Barr (F/C) 27th Jun"},"rc":[{"atb":[[1.03,7.8]],"id":52385910},{"atb":[[1.02,11.7]],"id":52385912},{"atb":[[1.01,23.41]],"id":52385906},{"atb":[[1.03,7.8]],"id":52385918},{"atb":[[1.01,23.41]],"id":52385920},{"atb":[[1.01,23.41]],"id":52385889},{"atb":[[1.02,11.7]],"id":52385914},{"atb":[[1.01,23.41]],"id":52385883},{"atb":[[1.02,11.7]],"id":52385885},{"atb":[[1.02,11.7]],"id":52385896},{"atb":[[1.01,23.41]],"id":52385890},{"atb":[[1.03,7.8]],"id":52385892},{"atb":[[1.02,11.7]],"id":52385904},{"atb":[[1.02,11.7]],"id":52385898},{"atb":[[1.02,11.7]],"id":52385900},{"atb":[[1.01,23.41]],"id":52385911},{"atb":[[1.02,11.7]],"id":52385913},{"atb":[[1.01,23.41]],"id":52385907},{"atb":[[1.02,11.7]],"id":52385886},{"atb":[[1.01,23.41]],"id":52385919},{"atb":[[1.01,23.41]],"id":52385921},{"atb":[[1.03,7.8]],"id":52385882},{"atb":[[1.03,7.8]],"id":52385884},{"atb":[[1.02,11.7]],"id":52385917},{"atb":[[1.01,23.41]],"id":52385897},{"atb":[[1.02,11.7]],"id":52385891},{"atb":[[1.02,11.7]],"id":52385893},{"atb":[[1.01,23.41]],"id":52385903},{"atb":[[1.01,23.41]],"id":52385905},{"atb":[[1.03,7.8]],"id":52385899}],"con":true,"img":true}]}
{"op":"mcm","clk":"11547660055","pt":1719445082636,"mc":[{"id":"1.230178167","marketDefinition":{"bspMarket":false,"turnInPlayEnabled":false,"persistenceEnabled":false,"marketBaseRate":5.0,"eventId":"33376048","eventTypeId":"4339","numberOfWinners":1,"bettingType":"ODDS","marketType":"FORECAST","marketTime":"2024-06-27T13:48:00.000Z","suspendTime":"2024-06-27T13:48:00.000Z","bspReconciled":false,"complete":true,"inPlay":false,"crossMatching":false,"runnersVoidable":false,"numberOfActiveRunners":30,"betDelay":0,"status":"OPEN","runners":[{"status":"ACTIVE","sortPriority":1,"id":52385882,"name":"1 - 2"},{"status":"ACTIVE","sortPriority":2,"id":52385883,"name":"1 - 3"},{"status":"ACTIVE","sortPriority":3,"id":52385884,"name":"1 - 4"},{"status":"ACTIVE","sortPriority":4,"id":52385885,"name":"1 - 5"},{"status":"ACTIVE","sortPriority":5,"id":52385886,"name":"1 - 6"},{"status":"ACTIVE","sortPriority":6,"id":52385889,"name":"2 - 1"},{"status":"ACTIVE","sortPriority":7,"id":52385890,"name":"2 - 3"},{"status":"ACTIVE","sortPriority":8,"id":52385891,"name":"2 - 4"},{"status":"ACTIVE","sortPriority":9,"id":52385892,"name":"2 - 5"},{"status":"ACTIVE","sortPriority":10,"id":52385893,"name":"2 - 6"},{"status":"ACTIVE","sortPriority":11,"id":52385896,"name":"3 - 1"},{"status":"ACTIVE","sortPriority":12,"id":52385897,"name":"3 - 2"},{"status":"ACTIVE","sortPriority":13,"id":52385898,"name":"3 - 4"},{"status":"ACTIVE","sortPriority":14,"id":52385899,"name":"3 - 5"},{"status":"ACTIVE","sortPriority":15,"id":52385900,"name":"3 - 6"},{"status":"ACTIVE","sortPriority":16,"id":52385903,"name":"4 - 1"},{"status":"ACTIVE","sortPriority":17,"id":52385904,"name":"4 - 2"},{"status":"ACTIVE","sortPriority":18,"id":52385905,"name":"4 - 3"},{"status":"ACTIVE","sortPriority":19,"id":52385906,"name":"4 - 5"},{"status":"ACTIVE","sortPriority":20,"id":52385907,"name":"4 - 6"},{"status":"ACTIVE","sortPriority":21,"id":52385910,"name":"5 - 1"},{"status":"ACTIVE","sortPriority":22,"id":52385911,"name":"5 - 2"},{"status":"ACTIVE","sortPriority":23,"id":52385912,"name":"5 - 3"},{"status":"ACTIVE","sortPriority":24,"id":52385913,"name":"5 - 4"},{"status":"ACTIVE","sortPriority":25,"id":52385914,"name":"5 - 6"},{"status":"ACTIVE","sortPriority":26,"id":52385917,"name":"6 - 1"},{"status":"ACTIVE","sortPriority":27,"id":52385918,"name":"6 - 2"},{"status":"ACTIVE","sortPriority":28,"id":52385919,"name":"6 - 3"},{"status":"ACTIVE","sortPriority":29,"id":52385920,"name":"6 - 4"},{"status":"ACTIVE","sortPriority":30,"id":52385921,"name":"6 - 5"}],"regulators":["MR_INT"],"venue":"Perry Barr","countryCode":"GB","discountAllowed":true,"timezone":"Europe/London","openDate":"2024-06-27T13:29:00.000Z","version":5994794108,"name":"Forecast","eventName":"Perry Barr (F/C) 27th Jun"},"rc":[{"atb":[[1.03,7.81]],"id":52385910},{"atb":[[1.02,11.71]],"id":52385912},{"atb":[[1.01,23.42]],"id":52385906},{"atb":[[1.03,7.81]],"id":52385918},{"atb":[[1.01,23.42]],"id":52385920},{"atb":[[1.01,23.42]],"id":52385889},{"atb":[[1.02,11.71]],"id":52385914},{"atb":[[1.01,23.42]],"id":52385883},{"atb":[[1.02,11.71]],"id":52385885},{"atb":[[1.02,11.71]],"id":52385896},{"atb":[[1.01,23.42]],"id":52385890},{"atb":[[1.03,7.81]],"id":52385892},{"atb":[[1.02,11.71]],"id":52385904},{"atb":[[1.02,11.71]],"id":52385898},{"atb":[[1.02,11.71]],"id":52385900},{"atb":[[1.01,23.42]],"id":52385911},{"atb":[[1.02,11.71]],"id":52385913},{"atb":[[1.01,23.42]],"id":52385907},{"atb":[[1.02,11.71]],"id":52385886},{"atb":[[1.01,23.42]],"id":52385919},{"atb":[[1.01,23.42]],"id":52385921},{"atb":[[1.03,7.81]],"id":52385882},{"atb":[[1.03,7.81]],"id":52385884},{"atb":[[1.02,11.71]],"id":52385917},{"atb":[[1.01,23.42]],"id":52385897},{"atb":[[1.02,11.71]],"id":52385891},{"atb":[[1.02,11.71]],"id":52385893},{"atb":[[1.01,23.42]],"id":52385903},{"atb":[[1.01,23.42]],"id":52385905},{"atb":[[1.03,7.81]],"id":52385899}],"con":true,"img":true}]}
{"op":"mcm","clk":"11548032130","pt":1719450482665,"mc":[{"id":"1.230178167","marketDefinition":{"bspMarket":false,"turnInPlayEnabled":false,"persistenceEnabled":false,"marketBaseRate":5.0,"eventId":"33376048","eventTypeId":"4339","numberOfWinners":1,"bettingType":"ODDS","marketType":"FORECAST","marketTime":"2024-06-27T13:48:00.000Z","suspendTime":"2024-06-27T13:48:00.000Z","bspReconciled":false,"complete":true,"inPlay":false,"crossMatching":false,"runnersVoidable":false,"numberOfActiveRunners":30,"betDelay":0,"status":"OPEN","runners":[{"status":"ACTIVE","sortPriority":1,"id":52385882,"name":"1 - 2"},{"status":"ACTIVE","sortPriority":2,"id":52385883,"name":"1 - 3"},{"status":"ACTIVE","sortPriority":3,"id":52385884,"name":"1 - 4"},{"status":"ACTIVE","sortPriority":4,"id":52385885,"name":"1 - 5"},{"status":"ACTIVE","sortPriority":5,"id":52385886,"name":"1 - 6"},{"status":"ACTIVE","sortPriority":6,"id":52385889,"name":"2 - 1"},{"status":"ACTIVE","sortPriority":7,"id":52385890,"name":"2 - 3"},{"status":"ACTIVE","sortPriority":8,"id":52385891,"name":"2 - 4"},{"status":"ACTIVE","sortPriority":9,"id":52385892,"name":"2 - 5"},{"status":"ACTIVE","sortPriority":10,"id":52385893,"name":"2 - 6"},{"status":"ACTIVE","sortPriority":11,"id":52385896,"name":"3 - 1"},{"status":"ACTIVE","sortPriority":12,"id":52385897,"name":"3 - 2"},{"status":"ACTIVE","sortPriority":13,"id":52385898,"name":"3 - 4"},{"status":"ACTIVE","sortPriority":14,"id":52385899,"name":"3 - 5"},{"status":"ACTIVE","sortPriority":15,"id":52385900,"name":"3 - 6"},{"status":"ACTIVE","sortPriority":16,"id":52385903,"name":"4 - 1"},{"status":"ACTIVE","sortPriority":17,"id":52385904,"name":"4 - 2"},{"status":"ACTIVE","sortPriority":18,"id":52385905,"name":"4 - 3"},{"status":"ACTIVE","sortPriority":19,"id":52385906,"name":"4 - 5"},{"status":"ACTIVE","sortPriority":20,"id":52385907,"name":"4 - 6"},{"status":"ACTIVE","sortPriority":21,"id":52385910,"name":"5 - 1"},{"status":"ACTIVE","sortPriority":22,"id":52385911,"name":"5 - 2"},{"status":"ACTIVE","sortPriority":23,"id":52385912,"name":"5 - 3"},{"status":"ACTIVE","sortPriority":24,"id":52385913,"name":"5 - 4"},{"status":"ACTIVE","sortPriority":25,"id":52385914,"name":"5 - 6"},{"status":"ACTIVE","sortPriority":26,"id":52385917,"name":"6 - 1"},{"status":"ACTIVE","sortPriority":27,"id":52385918,"name":"6 - 2"},{"status":"ACTIVE","sortPriority":28,"id":52385919,"name":"6 - 3"},{"status":"ACTIVE","sortPriority":29,"id":52385920,"name":"6 - 4"},{"status":"ACTIVE","sortPriority":30,"id":52385921,"name":"6 - 5"}],"regulators":["MR_INT"],"venue":"Perry Barr","countryCode":"GB","discountAllowed":true,"timezone":"Europe/London","openDate":"2024-06-27T13:29:00.000Z","version":5994794108,"name":"Forecast","eventName":"Perry Barr (F/C) 27th Jun"},"rc":[{"atb":[[1.03,7.81]],"id":52385910},{"atb":[[1.02,11.71]],"id":52385912},{"atb":[[1.01,23.42]],"id":52385906},{"atb":[[1.03,7.81]],"id":52385918},{"atb":[[1.01,23.42]],"id":52385920},{"atb":[[1.01,23.42]],"id":52385889},{"atb":[[1.02,11.71]],"id":52385914},{"atb":[[1.01,23.42]],"id":52385883},{"atb":[[1.02,11.71]],"id":52385885},{"atb":[[1.02,11.71]],"id":52385896},{"atb":[[1.01,23.42]],"id":52385890},{"atb":[[1.03,7.81]],"id":52385892},{"atb":[[1.02,11.71]],"id":52385904},{"atb":[[1.02,11.71]],"id":52385898},{"atb":[[1.02,11.71]],"id":52385900},{"atb":[[1.01,23.42]],"id":52385911},{"atb":[[1.02,11.71]],"id":52385913},{"atb":[[1.01,23.42]],"id":52385907},{"atb":[[1.02,11.71]],"id":52385886},{"atb":[[1.01,23.42]],"id":52385919},{"atb":[[1.01,23.42]],"id":52385921},{"atb":[[1.03,7.81]],"id":52385882},{"atb":[[1.03,7.81]],"id":52385884},{"atb":[[1.02,11.71]],"id":52385917},{"atb":[[1.01,23.42]],"id":52385897},{"atb":[[1.02,11.71]],"id":52385891},{"atb":[[1.02,11.71]],"id":52385893},{"atb":[[1.01,23.42]],"id":52385903},{"atb":[[1.01,23.42]],"id":52385905},{"atb":[[1.03,7.81]],"id":52385899}],"con":true,"img":true}]}
{"op":"mcm","clk":"11548271167","pt":1719455882674,"mc":[{"id":"1.230178167","marketDefinition":{"bspMarket":false,"turnInPlayEnabled":false,"persistenceEnabled":false,"marketBaseRate":5.0,"eventId":"33376048","eventTypeId":"4339","numberOfWinners":1,"bettingType":"ODDS","marketType":"FORECAST","marketTime":"2024-06-27T13:48:00.000Z","suspendTime":"2024-06-27T13:48:00.000Z","bspReconciled":false,"complete":true,"inPlay":false,"crossMatching":false,"runnersVoidable":false,"numberOfActiveRunners":30,"betDelay":0,"status":"OPEN","runners":[{"status":"ACTIVE","sortPriority":1,"id":52385882,"name":"1 - 2"},{"status":"ACTIVE","sortPriority":2,"id":52385883,"name":"1 - 3"},{"status":"ACTIVE","sortPriority":3,"id":52385884,"name":"1 - 4"},{"status":"ACTIVE","sortPriority":4,"id":52385885,"name":"1 - 5"},{"status":"ACTIVE","sortPriority":5,"id":52385886,"name":"1 - 6"},{"status":"ACTIVE","sortPriority":6,"id":52385889,"name":"2 - 1"},{"status":"ACTIVE","sortPriority":7,"id":52385890,"name":"2 - 3"},{"status":"ACTIVE","sortPriority":8,"id":52385891,"name":"2 - 4"},{"status":"ACTIVE","sortPriority":9,"id":52385892,"name":"2 - 5"},{"status":"ACTIVE","sortPriority":10,"id":52385893,"name":"2 - 6"},{"status":"ACTIVE","sortPriority":11,"id":52385896,"name":"3 - 1"},{"status":"ACTIVE","sortPriority":12,"id":52385897,"name":"3 - 2"},{"status":"ACTIVE","sortPriority":13,"id":52385898,"name":"3 - 4"},{"status":"ACTIVE","sortPriority":14,"id":52385899,"name":"3 - 5"},{"status":"ACTIVE","sortPriority":15,"id":52385900,"name":"3 - 6"},{"status":"ACTIVE","sortPriority":16,"id":52385903,"name":"4 - 1"},{"status":"ACTIVE","sortPriority":17,"id":52385904,"name":"4 - 2"},{"status":"ACTIVE","sortPriority":18,"id":52385905,"name":"4 - 3"},{"status":"ACTIVE","sortPriority":19,"id":52385906,"name":"4 - 5"},{"status":"ACTIVE","sortPriority":20,"id":52385907,"name":"4 - 6"},{"status":"ACTIVE","sortPriority":21,"id":52385910,"name":"5 - 1"},{"status":"ACTIVE","sortPriority":22,"id":52385911,"name":"5 - 2"},{"status":"ACTIVE","sortPriority":23,"id":52385912,"name":"5 - 3"},{"status":"ACTIVE","sortPriority":24,"id":52385913,"name":"5 - 4"},{"status":"ACTIVE","sortPriority":25,"id":52385914,"name":"5 - 6"},{"status":"ACTIVE","sortPriority":26,"id":52385917,"name":"6 - 1"},{"status":"ACTIVE","sortPriority":27,"id":52385918,"name":"6 - 2"},{"status":"ACTIVE","sortPriority":28,"id":52385919,"name":"6 - 3"},{"status":"ACTIVE","sortPriority":29,"id":52385920,"name":"6 - 4"},{"status":"ACTIVE","sortPriority":30,"id":52385921,"name":"6 - 5"}],"regulators":["MR_INT"],"venue":"Perry Barr","countryCode":"GB","discountAllowed":true,"timezone":"Europe/London","openDate":"2024-06-27T13:29:00.000Z","version":5994794108,"name":"Forecast","eventName":"Perry Barr (F/C) 27th Jun"},"rc":[{"atb":[[1.03,7.81]],"id":52385910},{"atb":[[1.02,11.71]],"id":52385912},{"atb":[[1.01,23.42]],"id":52385906},{"atb":[[1.03,7.81]],"id":52385918},{"atb":[[1.01,23.42]],"id":52385920},{"atb":[[1.01,23.42]],"id":52385889},{"atb":[[1.02,11.71]],"id":52385914},{"atb":[[1.01,23.42]],"id":52385883},{"atb":[[1.02,11.71]],"id":52385885},{"atb":[[1.02,11.71]],"id":52385896},{"atb":[[1.01,23.42]],"id":52385890},{"atb":[[1.03,7.81]],"id":52385892},{"atb":[[1.02,11.71]],"id":52385904},{"atb":[[1.02,11.71]],"id":52385898},{"atb":[[1.02,11.71]],"id":52385900},{"atb":[[1.01,23.42]],"id":52385911},{"atb":[[1.02,11.71]],"id":52385913},{"atb":[[1.01,23.42]],"id":52385907},{"atb":[[1.02,11.71]],"id":52385886},{"atb":[[1.01,23.42]],"id":52385919},{"atb":[[1.01,23.42]],"id":52385921},{"atb":[[1.03,7.81]],"id":52385882},{"atb":[[1.03,7.81]],"id":52385884},{"atb":[[1.02,11.71]],"id":52385917},{"atb":[[1.01,23.42]],"id":52385897},{"atb":[[1.02,11.71]],"id":52385891},{"atb":[[1.02,11.71]],"id":52385893},{"atb":[[1.01,23.42]],"id":52385903},{"atb":[[1.01,23.42]],"id":52385905},{"atb":[[1.03,7.81]],"id":52385899}],"con":true,"img":true}]}
{"op":"mcm","clk":"11548413110","pt":1719460857714,"mc":[{"id":"1.230178167","rc":[{"atb":[[1.03,7.81],[1.16,100]],"id":52385910},{"atb":[[1.16,100],[1.02,11.71]],"id":52385912},{"atb":[[1.01,23.42],[1.16,100]],"id":52385906},{"atb":[[1.03,7.81],[1.16,100]],"id":52385918},{"atb":[[1.01,23.42],[1.16,100]],"id":52385920},{"atb":[[1.01,23.42],[1.16,100]],"id":52385889},{"atb":[[1.16,100],[1.02,11.71]],"id":52385914},{"atb":[[1.01,23.42],[1.16,100]],"id":52385883},{"atb":[[1.16,100],[1.02,11.71]],"id":52385885},{"atb":[[1.16,100],[1.02,11.71]],"id":52385896},{"atb":[[1.01,23.42],[1.16,100]],"id":52385890},{"atb":[[1.03,7.81],[1.16,100]],"id":52385892},{"atb":[[1.16,100],[1.02,11.71]],"id":52385904},{"atb":[[1.16,100],[1.02,11.71]],"id":52385898},{"atb":[[1.16,100],[1.02,11.71]],"id":52385900},{"atb":[[1.01,23.42],[1.16,100]],"id":52385911},{"atb":[[1.16,100],[1.02,11.71]],"id":52385913},{"atb":[[1.01,23.42],[1.16,100]],"id":52385907},{"atb":[[1.16,100],[1.02,11.71]],"id":52385886},{"atb":[[1.01,23.42],[1.16,100]],"id":52385919},{"atb":[[1.01,23.42],[1.16,100]],"id":52385921},{"atb":[[1.03,7.81],[1.16,100]],"id":52385882},{"atb":[[1.03,7.81],[1.16,100]],"id":52385884},{"atb":[[1.16,100],[1.02,11.71]],"id":52385917},{"atb":[[1.01,23.42],[1.16,100]],"id":52385897},{"atb":[[1.16,100],[1.02,11.71]],"id":52385891},{"atb":[[1.16,100],[1.02,11.71]],"id":52385893},{"atb":[[1.01,23.42],[1.16,100]],"id":52385903},{"atb":[[1.01,23.42],[1.16,100]],"id":52385905},{"atb":[[1.03,7.81],[1.16,100]],"id":52385899}],"con":true,"img":false}]}
{"op":"mcm","clk":"11548536094","pt":1719466682836,"mc":[{"id":"1.230178167","marketDefinition":{"bspMarket":false,"turnInPlayEnabled":false,"persistenceEnabled":false,"marketBaseRate":5.0,"eventId":"33376048","eventTypeId":"4339","numberOfWinners":1,"bettingType":"ODDS","marketType":"FORECAST","marketTime":"2024-06-27T13:48:00.000Z","suspendTime":"2024-06-27T13:48:00.000Z","bspReconciled":false,"complete":true,"inPlay":false,"crossMatching":false,"runnersVoidable":false,"numberOfActiveRunners":30,"betDelay":0,"status":"OPEN","runners":[{"status":"ACTIVE","sortPriority":1,"id":52385882,"name":"1 - 2"},{"status":"ACTIVE","sortPriority":2,"id":52385883,"name":"1 - 3"},{"status":"ACTIVE","sortPriority":3,"id":52385884,"name":"1 - 4"},{"status":"ACTIVE","sortPriority":4,"id":52385885,"name":"1 - 5"},{"status":"ACTIVE","sortPriority":5,"id":52385886,"name":"1 - 6"},{"status":"ACTIVE","sortPriority":6,"id":52385889,"name":"2 - 1"},{"status":"ACTIVE","sortPriority":7,"id":52385890,"name":"2 - 3"},{"status":"ACTIVE","sortPriority":8,"id":52385891,"name":"2 - 4"},{"status":"ACTIVE","sortPriority":9,"id":52385892,"name":"2 - 5"},{"status":"ACTIVE","sortPriority":10,"id":52385893,"name":"2 - 6"},{"status":"ACTIVE","sortPriority":11,"id":52385896,"name":"3 - 1"},{"status":"ACTIVE","sortPriority":12,"id":52385897,"name":"3 - 2"},{"status":"ACTIVE","sortPriority":13,"id":52385898,"name":"3 - 4"},{"status":"ACTIVE","sortPriority":14,"id":52385899,"name":"3 - 5"},{"status":"ACTIVE","sortPriority":15,"id":52385900,"name":"3 - 6"},{"status":"ACTIVE","sortPriority":16,"id":52385903,"name":"4 - 1"},{"status":"ACTIVE","sortPriority":17,"id":52385904,"name":"4 - 2"},{"status":"ACTIVE","sortPriority":18,"id":52385905,"name":"4 - 3"},{"status":"ACTIVE","sortPriority":19,"id":52385906,"name":"4 - 5"},{"status":"ACTIVE","sortPriority":20,"id":52385907,"name":"4 - 6"},{"status":"ACTIVE","sortPriority":21,"id":52385910,"name":"5 - 1"},{"status":"ACTIVE","sortPriority":22,"id":52385911,"name":"5 - 2"},{"status":"ACTIVE","sortPriority":23,"id":52385912,"name":"5 - 3"},{"status":"ACTIVE","sortPriority":24,"id":52385913,"name":"5 - 4"},{"status":"ACTIVE","sortPriority":25,"id":52385914,"name":"5 - 6"},{"status":"ACTIVE","sortPriority":26,"id":52385917,"name":"6 - 1"},{"status":"ACTIVE","sortPriority":27,"id":52385918,"name":"6 - 2"},{"status":"ACTIVE","sortPriority":28,"id":52385919,"name":"6 - 3"},{"status":"ACTIVE","sortPriority":29,"id":52385920,"name":"6 - 4"},{"status":"ACTIVE","sortPriority":30,"id":52385921,"name":"6 - 5"}],"regulators":["MR_INT"],"venue":"Perry Barr","countryCode":"GB","discountAllowed":true,"timezone":"Europe/London","openDate":"2024-06-27T13:29:00.000Z","version":5994794108,"name":"Forecast","eventName":"Perry Barr (F/C) 27th Jun"},"rc":[{"atb":[[1.16,100],[1.03,7.81]],"id":52385910},{"atb":[[1.16,100],[1.02,11.71]],"id":52385912},{"atb":[[1.01,23.42],[1.16,100]],"id":52385906},{"atb":[[1.16,100],[1.03,7.81]],"id":52385918},{"atb":[[1.01,23.42],[1.16,100]],"id":52385920},{"atb":[[1.01,23.42],[1.16,100]],"id":52385889},{"atb":[[1.16,100],[1.02,11.71]],"id":52385914},{"atb":[[1.01,23.42],[1.16,100]],"id":52385883},{"atb":[[1.16,100],[1.02,11.71]],"id":52385885},{"atb":[[1.16,100],[1.02,11.71]],"id":52385896},{"atb":[[1.01,23.42],[1.16,100]],"id":52385890},{"atb":[[1.16,100],[1.03,7.81]],"id":52385892},{"atb":[[1.16,100],[1.02,11.71]],"id":52385904},{"atb":[[1.16,100],[1.02,11.71]],"id":52385898},{"atb":[[1.16,100],[1.02,11.71]],"id":52385900},{"atb":[[1.01,23.42],[1.16,100]],"id":52385911},{"atb":[[1.16,100],[1.02,11.71]],"id":52385913},{"atb":[[1.01,23.42],[1.16,100]],"id":52385907},{"atb":[[1.16,100],[1.02,11.71]],"id":52385886},{"atb":[[1.01,23.42],[1.16,100]],"id":52385919},{"atb":[[1.01,23.42],[1.16,100]],"id":52385921},{"atb":[[1.16,100],[1.03,7.81]],"id":52385882},{"atb":[[1.16,100],[1.03,7.81]],"id":52385884},{"atb":[[1.16,100],[1.02,11.71]],"id":52385917},{"atb":[[1.01,23.42],[1.16,100]],"id":52385897},{"atb":[[1.16,100],[1.02,11.71]],"id":52385891},{"atb":[[1.16,100],[1.02,11.71]],"id":52385893},{"atb":[[1.01,23.42],[1.16,100]],"id":52385903},{"atb":[[1.01,23.42],[1.16,100]],"id":52385905},{"atb":[[1.16,100],[1.03,7.81]],"id":52385899}],"con":true,"img":true}]}
{"op":"mcm","clk":"11548656556","pt":1719472082607,"mc":[{"id":"1.230178167","marketDefinition":{"bspMarket":false,"turnInPlayEnabled":false,"persistenceEnabled":false,"marketBaseRate":5.0,"eventId":"33376048","eventTypeId":"4339","numberOfWinners":1,"bettingType":"ODDS","marketType":"FORECAST","marketTime":"2024-06-27T13:48:00.000Z","suspendTime":"2024-06-27T13:48:00.000Z","bspReconciled":false,"complete":true,"inPlay":false,"crossMatching":false,"runnersVoidable":false,"numberOfActiveRunners":30,"betDelay":0,"status":"OPEN","runners":[{"status":"ACTIVE","sortPriority":1,"id":52385882,"name":"1 - 2"},{"status":"ACTIVE","sortPriority":2,"id":52385883,"name":"1 - 3"},{"status":"ACTIVE","sortPriority":3,"id":52385884,"name":"1 - 4"},{"status":"ACTIVE","sortPriority":4,"id":52385885,"name":"1 - 5"},{"status":"ACTIVE","sortPriority":5,"id":52385886,"name":"1 - 6"},{"status":"ACTIVE","sortPriority":6,"id":52385889,"name":"2 - 1"},{"status":"ACTIVE","sortPriority":7,"id":52385890,"name":"2 - 3"},{"status":"ACTIVE","sortPriority":8,"id":52385891,"name":"2 - 4"},{"status":"ACTIVE","sortPriority":9,"id":52385892,"name":"2 - 5"},{"status":"ACTIVE","sortPriority":10,"id":52385893,"name":"2 - 6"},{"status":"ACTIVE","sortPriority":11,"id":52385896,"name":"3 - 1"},{"status":"ACTIVE","sortPriority":12,"id":52385897,"name":"3 - 2"},{"status":"ACTIVE","sortPriority":13,"id":52385898,"name":"3 - 4"},{"status":"ACTIVE","sortPriority":14,"id":52385899,"name":"3 - 5"},{"status":"ACTIVE","sortPriority":15,"id":52385900,"name":"3 - 6"},{"status":"ACTIVE","sortPriority":16,"id":52385903,"name":"4 - 1"},{"status":"ACTIVE","sortPriority":17,"id":52385904,"name":"4 - 2"},{"status":"ACTIVE","sortPriority":18,"id":52385905,"name":"4 - 3"},{"status":"ACTIVE","sortPriority":19,"id":52385906,"name":"4 - 5"},{"status":"ACTIVE","sortPriority":20,"id":52385907,"name":"4 - 6"},{"status":"ACTIVE","sortPriority":21,"id":52385910,"name":"5 - 1"},{"status":"ACTIVE","sortPriority":22,"id":52385911,"name":"5 - 2"},{"status":"ACTIVE","sortPriority":23,"id":52385912,"name":"5 - 3"},{"status":"ACTIVE","sortPriority":24,"id":52385913,"name":"5 - 4"},{"status":"ACTIVE","sortPriority":25,"id":52385914,"name":"5 - 6"},{"status":"ACTIVE","sortPriority":26,"id":52385917,"name":"6 - 1"},{"status":"ACTIVE","sortPriority":27,"id":52385918,"name":"6 - 2"},{"status":"ACTIVE","sortPriority":28,"id":52385919,"name":"6 - 3"},{"status":"ACTIVE","sortPriority":29,"id":52385920,"name":"6 - 4"},{"status":"ACTIVE","sortPriority":30,"id":52385921,"name":"6 - 5"}],"regulators":["MR_INT"],"venue":"Perry Barr","countryCode":"GB","discountAllowed":true,"timezone":"Europe/London","openDate":"2024-06-27T13:29:00.000Z","version":5994794108,"name":"Forecast","eventName":"Perry Barr (F/C) 27th Jun"},"rc":[{"atb":[[1.16,100],[1.03,7.8]],"id":52385910},{"atb":[[1.16,100],[1.02,11.7]],"id":52385912},{"atb":[[1.01,23.41],[1.16,100]],"id":52385906},{"atb":[[1.16,100],[1.03,7.8]],"id":52385918},{"atb":[[1.01,23.41],[1.16,100]],"id":52385920},{"atb":[[1.01,23.41],[1.16,100]],"id":52385889},{"atb":[[1.16,100],[1.02,11.7]],"id":52385914},{"atb":[[1.01,23.41],[1.16,100]],"id":52385883},{"atb":[[1.16,100],[1.02,11.7]],"id":52385885},{"atb":[[1.16,100],[1.02,11.7]],"id":52385896},{"atb":[[1.01,23.41],[1.16,100]],"id":52385890},{"atb":[[1.16,100],[1.03,7.8]],"id":52385892},{"atb":[[1.16,100],[1.02,11.7]],"id":52385904},{"atb":[[1.16,100],[1.02,11.7]],"id":52385898},{"atb":[[1.16,100],[1.02,11.7]],"id":52385900},{"atb":[[1.01,23.41],[1.16,100]],"id":52385911},{"atb":[[1.16,100],[1.02,11.7]],"id":52385913},{"atb":[[1.01,23.41],[1.16,100]],"id":52385907},{"atb":[[1.16,100],[1.02,11.7]],"id":52385886},{"atb":[[1.01,23.41],[1.16,100]],"id":52385919},{"atb":[[1.01,23.41],[1.16,100]],"id":52385921},{"atb":[[1.16,100],[1.03,7.8]],"id":52385882},{"atb":[[1.16,100],[1.03,7.8]],"id":52385884},{"atb":[[1.16,100],[1.02,11.7]],"id":52385917},{"atb":[[1.01,23.41],[1.16,100]],"id":52385897},{"atb":[[1.16,100],[1.02,11.7]],"id":52385891},{"atb":[[1.16,100],[1.02,11.7]],"id":52385893},{"atb":[[1.01,23.41],[1.16,100]],"id":52385903},{"atb":[[1.01,23.41],[1.16,100]],"id":52385905},{"atb":[[1.16,100],[1.03,7.8]],"id":52385899}],"con":true,"img":true}]}
{"op":"mcm","clk":"11548862324","pt":1719477482605,"mc":[{"id":"1.230178167","marketDefinition":{"bspMarket":false,"turnInPlayEnabled":false,"persistenceEnabled":false,"marketBaseRate":5.0,"eventId":"33376048","eventTypeId":"4339","numberOfWinners":1,"bettingType":"ODDS","marketType":"FORECAST","marketTime":"2024-06-27T13:48:00.000Z","suspendTime":"2024-06-27T13:48:00.000Z","bspReconciled":false,"complete":true,"inPlay":false,"crossMatching":false,"runnersVoidable":false,"numberOfActiveRunners":30,"betDelay":0,"status":"OPEN","runners":[{"status":"ACTIVE","sortPriority":1,"id":52385882,"name":"1 - 2"},{"status":"ACTIVE","sortPriority":2,"id":52385883,"name":"1 - 3"},{"status":"ACTIVE","sortPriority":3,"id":52385884,"name":"1 - 4"},{"status":"ACTIVE","sortPriority":4,"id":52385885,"name":"1 - 5"},{"status":"ACTIVE","sortPriority":5,"id":52385886,"name":"1 - 6"},{"status":"ACTIVE","sortPriority":6,"id":52385889,"name":"2 - 1"},{"status":"ACTIVE","sortPriority":7,"id":52385890,"name":"2 - 3"},{"status":"ACTIVE","sortPriority":8,"id":52385891,"name":"2 - 4"},{"status":"ACTIVE","sortPriority":9,"id":52385892,"name":"2 - 5"},{"status":"ACTIVE","sortPriority":10,"id":52385893,"name":"2 - 6"},{"status":"ACTIVE","sortPriority":11,"id":52385896,"name":"3 - 1"},{"status":"ACTIVE","sortPriority":12,"id":52385897,"name":"3 - 2"},{"status":"ACTIVE","sortPriority":13,"id":52385898,"name":"3 - 4"},{"status":"ACTIVE","sortPriority":14,"id":52385899,"name":"3 - 5"},{"status":"ACTIVE","sortPriority":15,"id":52385900,"name":"3 - 6"},{"status":"ACTIVE","sortPriority":16,"id":52385903,"name":"4 - 1"},{"status":"ACTIVE","sortPriority":17,"id":52385904,"name":"4 - 2"},{"status":"ACTIVE","sortPriority":18,"id":52385905,"name":"4 - 3"},{"status":"ACTIVE","sortPriority":19,"id":52385906,"name":"4 - 5"},{"status":"ACTIVE","sortPriority":20,"id":52385907,"name":"4 - 6"},{"status":"ACTIVE","sortPriority":21,"id":52385910,"name":"5 - 1"},{"status":"ACTIVE","sortPriority":22,"id":52385911,"name":"5 - 2"},{"status":"ACTIVE","sortPriority":23,"id":52385912,"name":"5 - 3"},{"status":"ACTIVE","sortPriority":24,"id":52385913,"name":"5 - 4"},{"status":"ACTIVE","sortPriority":25,"id":52385914,"name":"5 - 6"},{"status":"ACTIVE","sortPriority":26,"id":52385917,"name":"6 - 1"},{"status":"ACTIVE","sortPriority":27,"id":52385918,"name":"6 - 2"},{"status":"ACTIVE","sortPriority":28,"id":52385919,"name":"6 - 3"},{"status":"ACTIVE","sortPriority":29,"id":52385920,"name":"6 - 4"},{"status":"ACTIVE","sortPriority":30,"id":52385921,"name":"6 - 5"}],"regulators":["MR_INT"],"venue":"Perry Barr","countryCode":"GB","discountAllowed":true,"timezone":"Europe/London","openDate":"2024-06-27T13:29:00.000Z","version":5994794108,"name":"Forecast","eventName":"Perry Barr (F/C) 27th Jun"},"rc":[{"atb":[[1.16,100],[1.03,7.8]],"id":52385910},{"atb":[[1.16,100],[1.02,11.7]],"id":52385912},{"atb":[[1.01,23.41],[1.16,100]],"id":52385906},{"atb":[[1.16,100],[1.03,7.8]],"id":52385918},{"atb":[[1.01,23.41],[1.16,100]],"id":52385920},{"atb":[[1.01,23.41],[1.16,100]],"id":52385889},{"atb":[[1.16,100],[1.02,11.7]],"id":52385914},{"atb":[[1.01,23.41],[1.16,100]],"id":52385883},{"atb":[[1.16,100],[1.02,11.7]],"id":52385885},{"atb":[[1.16,100],[1.02,11.7]],"id":52385896},{"atb":[[1.01,23.41],[1.16,100]],"id":52385890},{"atb":[[1.16,100],[1.03,7.8]],"id":52385892},{"atb":[[1.16,100],[1.02,11.7]],"id":52385904},{"atb":[[1.16,100],[1.02,11.7]],"id":52385898},{"atb":[[1.16,100],[1.02,11.7]],"id":52385900},{"atb":[[1.01,23.41],[1.16,100]],"id":52385911},{"atb":[[1.16,100],[1.02,11.7]],"id":52385913},{"atb":[[1.01,23.41],[1.16,100]],"id":52385907},{"atb":[[1.16,100],[1.02,11.7]],"id":52385886},{"atb":[[1.01,23.41],[1.16,100]],"id":52385919},{"atb":[[1.01,23.41],[1.16,100]],"id":52385921},{"atb":[[1.16,100],[1.03,7.8]],"id":52385882},{"atb":[[1.16,100],[1.03,7.8]],"id":52385884},{"atb":[[1.16,100],[1.02,11.7]],"id":52385917},{"atb":[[1.01,23.41],[1.16,100]],"id":52385897},{"atb":[[1.16,100],[1.02,11.7]],"id":52385891},{"atb":[[1.16,100],[1.02,11.7]],"id":52385893},{"atb":[[1.01,23.41],[1.16,100]],"id":52385903},{"atb":[[1.01,23.41],[1.16,100]],"id":52385905},{"atb":[[1.16,100],[1.03,7.8]],"id":52385899}],"con":true,"img":true}]}
{"op":"mcm","clk":"11549140666","pt":1719482882609,"mc":[{"id":"1.230178167","marketDefinition":{"bspMarket":false,"turnInPlayEnabled":false,"persistenceEnabled":false,"marketBaseRate":5.0,"eventId":"33376048","eventTypeId":"4339","numberOfWinners":1,"bettingType":"ODDS","marketType":"FORECAST","marketTime":"2024-06-27T13:48:00.000Z","suspendTime":"2024-06-27T13:48:00.000Z","bspReconciled":false,"complete":true,"inPlay":false,"crossMatching":false,"runnersVoidable":false,"numberOfActiveRunners":30,"betDelay":0,"status":"OPEN","runners":[{"status":"ACTIVE","sortPriority":1,"id":52385882,"name":"1 - 2"},{"status":"ACTIVE","sortPriority":2,"id":52385883,"name":"1 - 3"},{"status":"ACTIVE","sortPriority":3,"id":52385884,"name":"1 - 4"},{"status":"ACTIVE","sortPriority":4,"id":52385885,"name":"1 - 5"},{"status":"ACTIVE","sortPriority":5,"id":52385886,"name":"1 - 6"},{"status":"ACTIVE","sortPriority":6,"id":52385889,"name":"2 - 1"},{"status":"ACTIVE","sortPriority":7,"id":52385890,"name":"2 - 3"},{"status":"ACTIVE","sortPriority":8,"id":52385891,"name":"2 - 4"},{"status":"ACTIVE","sortPriority":9,"id":52385892,"name":"2 - 5"},{"status":"ACTIVE","sortPriority":10,"id":52385893,"name":"2 - 6"},{"status":"ACTIVE","sortPriority":11,"id":52385896,"name":"3 - 1"},{"status":"ACTIVE","sortPriority":12,"id":52385897,"name":"3 - 2"},{"status":"ACTIVE","sortPriority":13,"id":52385898,"name":"3 - 4"},{"status":"ACTIVE","sortPriority":14,"id":52385899,"name":"3 - 5"},{"status":"ACTIVE","sortPriority":15,"id":52385900,"name":"3 - 6"},{"status":"ACTIVE","sortPriority":16,"id":52385903,"name":"4 - 1"},{"status":"ACTIVE","sortPriority":17,"id":52385904,"name":"4 - 2"},{"status":"ACTIVE","sortPriority":18,"id":52385905,"name":"4 - 3"},{"status":"ACTIVE","sortPriority":19,"id":52385906,"name":"4 - 5"},{"status":"ACTIVE","sortPriority":20,"id":52385907,"name":"4 - 6"},{"status":"ACTIVE","sortPriority":21,"id":52385910,"name":"5 - 1"},{"status":"ACTIVE","sortPriority":22,"id":52385911,"name":"5 - 2"},{"status":"ACTIVE","sortPriority":23,"id":52385912,"name":"5 - 3"},{"status":"ACTIVE","sortPriority":24,"id":52385913,"name":"5 - 4"},{"status":"ACTIVE","sortPriority":25,"id":52385914,"name":"5 - 6"},{"status":"ACTIVE","sortPriority":26,"id":52385917,"name":"6 - 1"},{"status":"ACTIVE","sortPriority":27,"id":52385918,"name":"6 - 2"},{"status":"ACTIVE","sortPriority":28,"id":52385919,"name":"6 - 3"},{"status":"ACTIVE","sortPriority":29,"id":52385920,"name":"6 - 4"},{"status":"ACTIVE","sortPriority":30,"id":52385921,"name":"6 - 5"}],"regulators":["MR_INT"],"venue":"Perry Barr","countryCode":"GB","discountAllowed":true,"timezone":"Europe/London","openDate":"2024-06-27T13:29:00.000Z","version":5994794108,"name":"Forecast","eventName":"Perry Barr (F/C) 27th Jun"},"rc":[{"atb":[[1.16,100],[1.03,7.8]],"id":52385910},{"atb":[[1.16,100],[1.02,11.7]],"id":52385912},{"atb":[[1.01,23.41],[1.16,100]],"id":52385906},{"atb":[[1.16,100],[1.03,7.8]],"id":52385918},{"atb":[[1.01,23.41],[1.16,100]],"id":52385920},{"atb":[[1.01,23.41],[1.16,100]],"id":52385889},{"atb":[[1.16,100],[1.02,11.7]],"id":52385914},{"atb":[[1.01,23.41],[1.16,100]],"id":52385883},{"atb":[[1.16,100],[1.02,11.7]],"id":52385885},{"atb":[[1.16,100],[1.02,11.7]],"id":52385896},{"atb":[[1.01,23.41],[1.16,100]],"id":52385890},{"atb":[[1.16,100],[1.03,7.8]],"id":52385892},{"atb":[[1.16,100],[1.02,11.7]],"id":52385904},{"atb":[[1.16,100],[1.02,11.7]],"id":52385898},{"atb":[[1.16,100],[1.02,11.7]],"id":52385900},{"atb":[[1.01,23.41],[1.16,100]],"id":52385911},{"atb":[[1.16,100],[1.02,11.7]],"id":52385913},{"atb":[[1.01,23.41],[1.16,100]],"id":52385907},{"atb":[[1.16,100],[1.02,11.7]],"id":52385886},{"atb":[[1.01,23.41],[1.16,100]],"id":52385919},{"atb":[[1.01,23.41],[1.16,100]],"id":52385921},{"atb":[[1.16,100],[1.03,7.8]],"id":52385882},{"atb":[[1.16,100],[1.03,7.8]],"id":52385884},{"atb":[[1.16,100],[1.02,11.7]],"id":52385917},{"atb":[[1.01,23.41],[1.16,100]],"id":52385897},{"atb":[[1.16,100],[1.02,11.7]],"id":52385891},{"atb":[[1.16,100],[1.02,11.7]],"id":52385893},{"atb":[[1.01,23.41],[1.16,100]],"id":52385903},{"atb":[[1.01,23.41],[1.16,100]],"id":52385905},{"atb":[[1.16,100],[1.03,7.8]],"id":52385899}],"con":true,"img":true}]}
{"op":"mcm","clk":"11549376453","pt":1719485498418,"mc":[{"id":"1.230178167","rc":[{"atb":[[1.03,7.8]],"id":52385910},{"atb":[[1.02,11.7]],"id":52385912},{"atb":[[1.01,23.41]],"id":52385906},{"atb":[[1.03,7.8]],"id":52385918},{"atb":[[1.01,23.41]],"id":52385920},{"atb":[[1.01,329.53]],"id":52385889},{"atb":[[1.02,11.7]],"id":52385914},{"atb":[[1.01,329.53]],"id":52385883},{"atb":[[1.01,306.12],[1.02,11.7]],"id":52385885},{"atb":[[1.01,306.12],[1.02,11.7]],"id":52385896},{"atb":[[1.01,329.53]],"id":52385890},{"atb":[[1.01,306.12],[1.03,7.8]],"id":52385892},{"atb":[[1.02,11.7]],"id":52385904},{"atb":[[1.01,306.12],[1.02,11.7]],"id":52385898},{"atb":[[1.02,11.7]],"id":52385900},{"atb":[[1.01,23.41]],"id":52385911},{"atb":[[1.02,11.7]],"id":52385913},{"atb":[[1.01,23.41]],"id":52385907},{"atb":[[1.01,306.12],[1.02,11.7]],"id":52385886},{"atb":[[1.01,23.41]],"id":52385919},{"atb":[[1.01,23.41]],"id":52385921},{"atb":[[1.01,306.12],[1.03,7.8]],"id":52385882},{"atb":[[1.01,306.12],[1.03,7.8]],"id":52385884},{"atb":[[1.02,11.7]],"id":52385917},{"atb":[[1.01,329.53]],"id":52385897},{"atb":[[1.01,306.12],[1.02,11.7]],"id":52385891},{"atb":[[1.01,306.12],[1.02,11.7]],"id":52385893},{"atb":[[1.01,23.41]],"id":52385903},{"atb":[[1.01,23.41]],"id":52385905},{"atb":[[1.01,306.12],[1.03,7.8]],"id":52385899}],"con":true,"img":false}]}
{"op":"mcm","clk":"11549376465","pt":1719485498524,"mc":[{"id":"1.230178167","rc":[{"atb":[[1.01,306.12]],"id":52385900}],"con":true,"img":false}]}
{"op":"mcm","clk":"11549376490","pt":1719485498730,"mc":[{"id":"1.230178167","rc":[{"atb":[[1.01,329.53]],"id":52385906},{"atb":[[1.01,306.12]],"id":52385904},{"atb":[[1.01,329.53]],"id":52385907},{"atb":[[1.01,329.53]],"id":52385903},{"atb":[[1.01,329.53]],"id":52385905}],"con":true,"img":false}]}
{"op":"mcm","clk":"11549376515","pt":1719485499059,"mc":[{"id":"1.230178167","rc":[{"atb":[[1.01,306.12]],"id":52385910},{"atb":[[1.01,306.12]],"id":52385912},{"atb":[[1.01,306.12]],"id":52385918},{"atb":[[1.01,329.53]],"id":52385920},{"atb":[[1.01,306.12]],"id":52385914},{"atb":[[1.01,329.53]],"id":52385911},{"atb":[[1.01,306.12]],"id":52385913},{"atb":[[1.01,329.53]],"id":52385919},{"atb":[[1.01,329.53]],"id":52385921},{"atb":[[1.01,306.12]],"id":52385917}],"con":true,"img":false}]}
{"op":"mcm","clk":"11549376581","pt":1719485499717,"mc":[{"id":"1.230178167","rc":[{"atb":[[1.17,120.05]],"id":52385883},{"atb":[[1.17,120.05]],"id":52385885},{"atb":[[1.17,120.05]],"id":52385886},{"atb":[[1.17,120.05]],"id":52385882},{"atb":[[1.17,120.05]],"id":52385884}],"con":true,"img":false}]}
{"op":"mcm","clk":"11549376626","pt":1719485500129,"mc":[{"id":"1.230178167","rc":[{"atb":[[1.17,120.05]],"id":52385906},{"atb":[[1.17,120.05]],"id":52385889},{"atb":[[1.17,120.05]],"id":52385896},{"atb":[[1.17,120.05]],"id":52385890},{"atb":[[1.17,120.05]],"id":52385892},{"atb":[[1.17,120.05]],"id":52385904},{"atb":[[1.17,120.05]],"id":52385898},{"atb":[[1.17,120.05]],"id":52385900},{"atb":[[1.17,120.05]],"id":52385897},{"atb":[[1.17,120.05]],"id":52385891},{"atb":[[1.17,120.05]],"id":52385893},{"atb":[[1.17,120.05]],"id":52385903},{"atb":[[1.17,120.05]],"id":52385905},{"atb":[[1.17,120.05]],"id":52385899}],"con":true,"img":false}]}
{"op":"mcm","clk":"11549376638","pt":1719485500228,"mc":[{"id":"1.230178167","rc":[{"atb":[[1.17,120.05]],"id":52385910},{"atb":[[1.17,120.05]],"id":52385912},{"atb":[[1.17,120.05]],"id":52385918},{"atb":[[1.17,120.05]],"id":52385914},{"atb":[[1.17,120.05]],"id":52385911},{"atb":[[1.17,120.05]],"id":52385913},{"atb":[[1.17,120.05]],"id":52385907},{"atb":[[1.17,120.05]],"id":52385917}],"con":true,"img":false}]}
{"op":"mcm","clk":"11549376643","pt":1719485500329,"mc":[{"id":"1.230178167","rc":[{"atb":[[1.17,120.05]],"id":52385919}],"con":true,"img":false}]}
{"op":"mcm","clk":"11549376663","pt":1719485500539,"mc":[{"id":"1.230178167","rc":[{"atb":[[1.17,120.05]],"id":52385920},{"atb":[[1.17,120.05]],"id":52385921}],"con":true,"img":false}]}
{"op":"mcm","clk":"11549607139","pt":1719488282625,"mc":[{"id":"1.230178167","marketDefinition":{"bspMarket":false,"turnInPlayEnabled":false,"persistenceEnabled":false,"marketBaseRate":5.0,"eventId":"33376048","eventTypeId":"4339","numberOfWinners":1,"bettingType":"ODDS","marketType":"FORECAST","marketTime":"2024-06-27T13:48:00.000Z","suspendTime":"2024-06-27T13:48:00.000Z","bspReconciled":false,"complete":true,"inPlay":false,"crossMatching":false,"runnersVoidable":false,"numberOfActiveRunners":30,"betDelay":0,"status":"OPEN","runners":[{"status":"ACTIVE","sortPriority":1,"id":52385882,"name":"1 - 2"},{"status":"ACTIVE","sortPriority":2,"id":52385883,"name":"1 - 3"},{"status":"ACTIVE","sortPriority":3,"id":52385884,"name":"1 - 4"},{"status":"ACTIVE","sortPriority":4,"id":52385885,"name":"1 - 5"},{"status":"ACTIVE","sortPriority":5,"id":52385886,"name":"1 - 6"},{"status":"ACTIVE","sortPriority":6,"id":52385889,"name":"2 - 1"},{"status":"ACTIVE","sortPriority":7,"id":52385890,"name":"2 - 3"},{"status":"ACTIVE","sortPriority":8,"id":52385891,"name":"2 - 4"},{"status":"ACTIVE","sortPriority":9,"id":52385892,"name":"2 - 5"},{"status":"ACTIVE","sortPriority":10,"id":52385893,"name":"2 - 6"},{"status":"ACTIVE","sortPriority":11,"id":52385896,"name":"3 - 1"},{"status":"ACTIVE","sortPriority":12,"id":52385897,"name":"3 - 2"},{"status":"ACTIVE","sortPriority":13,"id":52385898,"name":"3 - 4"},{"status":"ACTIVE","sortPriority":14,"id":52385899,"name":"3 - 5"},{"status":"ACTIVE","sortPriority":15,"id":52385900,"name":"3 - 6"},{"status":"ACTIVE","sortPriority":16,"id":52385903,"name":"4 - 1"},{"status":"ACTIVE","sortPriority":17,"id":52385904,"name":"4 - 2"},{"status":"ACTIVE","sortPriority":18,"id":52385905,"name":"4 - 3"},{"status":"ACTIVE","sortPriority":19,"id":52385906,"name":"4 - 5"},{"status":"ACTIVE","sortPriority":20,"id":52385907,"name":"4 - 6"},{"status":"ACTIVE","sortPriority":21,"id":52385910,"name":"5 - 1"},{"status":"ACTIVE","sortPriority":22,"id":52385911,"name":"5 - 2"},{"status":"ACTIVE","sortPriority":23,"id":52385912,"name":"5 - 3"},{"status":"ACTIVE","sortPriority":24,"id":52385913,"name":"5 - 4"},{"status":"ACTIVE","sortPriority":25,"id":52385914,"name":"5 - 6"},{"status":"ACTIVE","sortPriority":26,"id":52385917,"name":"6 - 1"},{"status":"ACTIVE","sortPriority":27,"id":52385918,"name":"6 - 2"},{"status":"ACTIVE","sortPriority":28,"id":52385919,"name":"6 - 3"},{"status":"ACTIVE","sortPriority":29,"id":52385920,"name":"6 - 4"},{"status":"ACTIVE","sortPriority":30,"id":52385921,"name":"6 - 5"}],"regulators":["MR_INT"],"venue":"Perry Barr","countryCode":"GB","discountAllowed":true,"timezone":"Europe/London","openDate":"2024-06-27T13:29:00.000Z","version":5994794108,"name":"Forecast","eventName":"Perry Barr (F/C) 27th Jun"},"rc":[{"atb":[[1.01,306.12],[1.16,100],[1.03,7.8],[1.17,120.05]],"id":52385910},{"atb":[[1.01,306.12],[1.16,100],[1.02,11.7],[1.17,120.05]],"id":52385912},{"atb":[[1.01,329.53],[1.16,100],[1.17,120.05]],"id":52385906},{"atb":[[1.01,306.12],[1.16,100],[1.03,7.8],[1.17,120.05]],"id":52385918},{"atb":[[1.01,329.53],[1.16,100],[1.17,120.05]],"id":52385920},{"atb":[[1.01,329.53],[1.16,100],[1.17,120.05]],"id":52385889},{"atb":[[1.01,306.12],[1.16,100],[1.02,11.7],[1.17,120.05]],"id":52385914},{"atb":[[1.01,329.53],[1.16,100],[1.17,120.05]],"id":52385883},{"atb":[[1.01,306.12],[1.16,100],[1.02,11.7],[1.17,120.05]],"id":52385885},{"atb":[[1.01,306.12],[1.16,100],[1.02,11.7],[1.17,120.05]],"id":52385896},{"atb":[[1.01,329.53],[1.16,100],[1.17,120.05]],"id":52385890},{"atb":[[1.01,306.12],[1.16,100],[1.03,7.8],[1.17,120.05]],"id":52385892},{"atb":[[1.01,306.12],[1.16,100],[1.02,11.7],[1.17,120.05]],"id":52385904},{"atb":[[1.01,306.12],[1.16,100],[1.02,11.7],[1.17,120.05]],"id":52385898},{"atb":[[1.01,306.12],[1.16,100],[1.02,11.7],[1.17,120.05]],"id":52385900},{"atb":[[1.01,329.53],[1.16,100],[1.17,120.05]],"id":52385911},{"atb":[[1.01,306.12],[1.16,100],[1.02,11.7],[1.17,120.05]],"id":52385913},{"atb":[[1.01,329.53],[1.16,100],[1.17,120.05]],"id":52385907},{"atb":[[1.01,306.12],[1.16,100],[1.02,11.7],[1.17,120.05]],"id":52385886},{"atb":[[1.01,329.53],[1.16,100],[1.17,120.05]],"id":52385919},{"atb":[[1.01,329.53],[1.16,100],[1.17,120.05]],"id":52385921},{"atb":[[1.01,306.12],[1.16,100],[1.03,7.8],[1.17,120.05]],"id":52385882},{"atb":[[1.01,306.12],[1.16,100],[1.03,7.8],[1.17,120.05]],"id":52385884},{"atb":[[1.01,306.12],[1.16,100],[1.02,11.7],[1.17,120.05]],"id":52385917},{"atb":[[1.01,329.53],[1.16,100],[1.17,120.05]],"id":52385897},{"atb":[[1.01,306.12],[1.16,100],[1.02,11.7],[1.17,120.05]],"id":52385891},{"atb":[[1.01,306.12],[1.16,100],[1.02,11.7],[1.17,120.05]],"id":52385893},{"atb":[[1.01,329.53],[1.16,100],[1.17,120.05]],"id":52385903},{"atb":[[1.01,329.53],[1.16,100],[1.17,120.05]],"id":52385905},{"atb":[[1.01,306.12],[1.16,100],[1.03,7.8],[1.17,120.05]],"id":52385899}],"con":true,"img":true}]}
{"op":"mcm","clk":"11549970538","pt":1719493209487,"mc":[{"id":"1.230178167","rc":[{"atb":[[1.16,0],[1.03,7.81]],"id":52385910},{"atb":[[1.16,0],[1.02,11.72]],"id":52385912},{"atb":[[1.01,329.56],[1.16,0]],"id":52385906},{"atb":[[1.16,0],[1.03,7.81]],"id":52385918},{"atb":[[1.01,329.56],[1.16,0]],"id":52385920},{"atb":[[1.01,329.56],[1.16,0]],"id":52385889},{"atb":[[1.16,0],[1.02,11.72]],"id":52385914},{"atb":[[1.01,329.56],[1.16,0]],"id":52385883},{"atb":[[1.16,0],[1.02,11.72]],"id":52385885},{"atb":[[1.16,0],[1.02,11.72]],"id":52385896},{"atb":[[1.01,329.56],[1.16,0]],"id":52385890},{"atb":[[1.16,0],[1.03,7.81]],"id":52385892},{"atb":[[1.16,0],[1.02,11.72]],"id":52385904},{"atb":[[1.16,0],[1.02,11.72]],"id":52385898},{"atb":[[1.16,0],[1.02,11.72]],"id":52385900},{"atb":[[1.01,329.56],[1.16,0]],"id":52385911},{"atb":[[1.16,0],[1.02,11.72]],"id":52385913},{"atb":[[1.01,329.56],[1.16,0]],"id":52385907},{"atb":[[1.16,0],[1.02,11.72]],"id":52385886},{"atb":[[1.01,329.56],[1.16,0]],"id":52385919},{"atb":[[1.01,329.56],[1.16,0]],"id":52385921},{"atb":[[1.16,0],[1.03,7.81]],"id":52385882},{"atb":[[1.16,0],[1.03,7.81]],"id":52385884},{"atb":[[1.16,0],[1.02,11.72]],"id":52385917},{"atb":[[1.01,329.56],[1.16,0]],"id":52385897},{"atb":[[1.16,0],[1.02,11.72]],"id":52385891},{"atb":[[1.16,0],[1.02,11.72]],"id":52385893},{"atb":[[1.01,329.56],[1.16,0]],"id":52385903},{"atb":[[1.01,329.56],[1.16,0]],"id":52385905},{"atb":[[1.16,0],[1.03,7.81]],"id":52385899}],"con":true,"img":false}]}
{"op":"mcm","clk":"11549975785","pt":1719493273024,"mc":[{"id":"1.230178167","rc":[{"atb":[[1.18,150]],"id":52385910},{"atb":[[1.18,150]],"id":52385912},{"atb":[[1.18,150]],"id":52385906},{"atb":[[1.18,150]],"id":52385918},{"atb":[[1.18,150]],"id":52385920},{"atb":[[1.18,150]],"id":52385889},{"atb":[[1.18,150]],"id":52385914},{"atb":[[1.18,150]],"id":52385883},{"atb":[[1.18,150]],"id":52385885},{"atb":[[1.18,150]],"id":52385896},{"atb":[[1.18,150]],"id":52385890},{"atb":[[1.18,150]],"id":52385892},{"atb":[[1.18,150]],"id":52385904},{"atb":[[1.18,150]],"id":52385898},{"atb":[[1.18,150]],"id":52385900},{"atb":[[1.18,150]],"id":52385911},{"atb":[[1.18,150]],"id":52385913},{"atb":[[1.18,150]],"id":52385907},{"atb":[[1.18,150]],"id":52385886},{"atb":[[1.18,150]],"id":52385919},{"atb":[[1.18,150]],"id":52385921},{"atb":[[1.18,150]],"id":52385882},{"atb":[[1.18,150]],"id":52385884},{"atb":[[1.18,150]],"id":52385917},{"atb":[[1.18,150]],"id":52385897},{"atb":[[1.18,150]],"id":52385891},{"atb":[[1.18,150]],"id":52385893},{"atb":[[1.18,150]],"id":52385903},{"atb":[[1.18,150]],"id":52385905},{"atb":[[1.18,150]],"id":52385899}],"con":true,"img":false}]}
{"op":"mcm","clk":"11549987576","pt":1719493410920,"mc":[{"id":"1.230178167","rc":[{"atb":[[1.17,0]],"id":52385884}],"con":true,"img":false}]}
{"op":"mcm","clk":"11550007609","pt":1719493621094,"mc":[{"id":"1.230178167","rc":[{"atb":[[1.17,0]],"id":52385886}],"con":true,"img":false}]}
{"op":"mcm","clk":"11550037589","pt":1719493851082,"mc":[{"id":"1.230178167","rc":[{"atb":[[1.17,0]],"id":52385882}],"con":true,"img":false}]}
{"op":"mcm","clk":"11550068389","pt":1719494153859,"mc":[{"id":"1.230178167","rc":[{"atb":[[1.3,20]],"id":52385892}],"con":true,"img":false}]}
{"op":"mcm","clk":"11550068654","pt":1719494156762,"mc":[{"id":"1.230178167","rc":[{"atb":[[3.5,50]],"id":52385892}],"con":true,"img":false}]}
{"op":"mcm","clk":"11550069160","pt":1719494162049,"mc":[{"id":"1.230178167","rc":[{"atb":[[3.5,0]],"id":52385892}],"con":true,"img":false}]}
{"op":"mcm","clk":"11550070107","pt":1719494172565,"mc":[{"id":"1.230178167","marketDefinition":{"bspMarket":false,"turnInPlayEnabled":false,"persistenceEnabled":false,"marketBaseRate":5.0,"eventId":"33376048","eventTypeId":"4339","numberOfWinners":1,"bettingType":"ODDS","marketType":"FORECAST","marketTime":"2024-06-27T13:48:00.000Z","suspendTime":"2024-06-27T13:48:00.000Z","bspReconciled":false,"complete":true,"inPlay":false,"crossMatching":true,"runnersVoidable":false,"numberOfActiveRunners":30,"betDelay":0,"status":"OPEN","runners":[{"status":"ACTIVE","sortPriority":1,"id":52385882,"name":"1 - 2"},{"status":"ACTIVE","sortPriority":2,"id":52385883,"name":"1 - 3"},{"status":"ACTIVE","sortPriority":3,"id":52385884,"name":"1 - 4"},{"status":"ACTIVE","sortPriority":4,"id":52385885,"name":"1 - 5"},{"status":"ACTIVE","sortPriority":5,"id":52385886,"name":"1 - 6"},{"status":"ACTIVE","sortPriority":6,"id":52385889,"name":"2 - 1"},{"status":"ACTIVE","sortPriority":7,"id":52385890,"name":"2 - 3"},{"status":"ACTIVE","sortPriority":8,"id":52385891,"name":"2 - 4"},{"status":"ACTIVE","sortPriority":9,"id":52385892,"name":"2 - 5"},{"status":"ACTIVE","sortPriority":10,"id":52385893,"name":"2 - 6"},{"status":"ACTIVE","sortPriority":11,"id":52385896,"name":"3 - 1"},{"status":"ACTIVE","sortPriority":12,"id":52385897,"name":"3 - 2"},{"status":"ACTIVE","sortPriority":13,"id":52385898,"name":"3 - 4"},{"status":"ACTIVE","sortPriority":14,"id":52385899,"name":"3 - 5"},{"status":"ACTIVE","sortPriority":15,"id":52385900,"name":"3 - 6"},{"status":"ACTIVE","sortPriority":16,"id":52385903,"name":"4 - 1"},{"status":"ACTIVE","sortPriority":17,"id":52385904,"name":"4 - 2"},{"status":"ACTIVE","sortPriority":18,"id":52385905,"name":"4 - 3"},{"status":"ACTIVE","sortPriority":19,"id":52385906,"name":"4 - 5"},{"status":"ACTIVE","sortPriority":20,"id":52385907,"name":"4 - 6"},{"status":"ACTIVE","sortPriority":21,"id":52385910,"name":"5 - 1"},{"status":"ACTIVE","sortPriority":22,"id":52385911,"name":"5 - 2"},{"status":"ACTIVE","sortPriority":23,"id":52385912,"name":"5 - 3"},{"status":"ACTIVE","sortPriority":24,"id":52385913,"name":"5 - 4"},{"status":"ACTIVE","sortPriority":25,"id":52385914,"name":"5 - 6"},{"status":"ACTIVE","sortPriority":26,"id":52385917,"name":"6 - 1"},{"status":"ACTIVE","sortPriority":27,"id":52385918,"name":"6 - 2"},{"status":"ACTIVE","sortPriority":28,"id":52385919,"name":"6 - 3"},{"status":"ACTIVE","sortPriority":29,"id":52385920,"name":"6 - 4"},{"status":"ACTIVE","sortPriority":30,"id":52385921,"name":"6 - 5"}],"regulators":["MR_INT"],"venue":"Perry Barr","countryCode":"GB","discountAllowed":true,"timezone":"Europe/London","openDate":"2024-06-27T13:29:00.000Z","version":5994794108,"name":"Forecast","eventName":"Perry Barr (F/C) 27th Jun"},"rc":[],"con":true,"img":false}]}
{"op":"mcm","clk":"11550070435","pt":1719494176216,"mc":[{"id":"1.230178167","rc":[{"atb":[[1.3,0]],"id":52385892},{"atl":[[1.3,10]],"id":52385892},{"trd":[[1.3,40]],"ltp":1.3,"tv":40.0,"id":52385892}],"con":true,"img":false}]}
{"op":"mcm","clk":"11550070446","pt":1719494176270,"mc":[{"id":"1.230178167","rc":[{"atl":[[1.3,0]],"id":52385892},{"trd":[[1.3,60]],"ltp":1.3,"tv":60.0,"id":52385892}],"con":true,"img":false}]}
{"op":"mcm","clk":"11550070496","pt":1719494176789,"mc":[{"id":"1.230178167","rc":[{"atl":[[1000,1.22]],"id":52385910},{"atl":[[1000,1.35]],"id":52385912},{"atl":[[1000,1.31]],"id":52385906},{"atl":[[1000,1.23]],"id":52385918},{"atl":[[1000,1.36]],"id":52385920},{"atl":[[1000,1.22]],"id":52385889},{"atl":[[1000,1.31]],"id":52385914},{"atl":[[1000,1.35]],"id":52385883},{"atl":[[1000,1.31]],"id":52385885},{"atl":[[1000,1.34]],"id":52385896},{"atl":[[1000,1.28]],"id":52385890},{"atl":[[1000,1.24]],"id":52385892},{"atl":[[1000,1.35]],"id":52385904},{"atl":[[1000,1.3]],"id":52385898},{"atl":[[1000,1.25]],"id":52385900},{"atl":[[1000,1.28]],"id":52385911},{"atl":[[1000,1.24]],"id":52385913},{"atl":[[1000,1.2]],"id":52385907},{"atl":[[1000,1.2]],"id":52385886},{"atl":[[1000,1.3]],"id":52385919},{"atl":[[1000,1.25]],"id":52385921},{"atl":[[1000,1.27]],"id":52385882},{"atl":[[1000,1.24]],"id":52385884},{"atl":[[1000,1.34]],"id":52385917},{"atl":[[1000,1.23]],"id":52385897},{"atl":[[1000,1.35]],"id":52385891},{"atl":[[1000,1.31]],"id":52385893},{"atl":[[1000,1.27]],"id":52385903},{"atl":[[1000,1.24]],"id":52385905},{"atl":[[1000,1.36]],"id":52385899}],"con":true,"img":false}]}
{"op":"mcm","clk":"11550074032","pt":1719494212218,"mc":[{"id":"1.230178167","rc":[{"atb":[[1.3,26]],"id":52385911}],"con":true,"img":false}]}
{"op":"mcm","clk":"11550074138","pt":1719494213467,"mc":[{"id":"1.230178167","rc":[{"atb":[[3.5,50]],"id":52385911}],"con":true,"img":false}]}
{"op":"mcm","clk":"11550074754","pt":1719494218926,"mc":[{"id":"1.230178167","rc":[{"atb":[[3.5,0]],"id":52385911}],"con":true,"img":false}]}
{"op":"mcm","clk":"11550075627","pt":1719494226877,"mc":[{"id":"1.230178167","rc":[{"atb":[[1.3,0]],"id":52385911},{"trd":[[1.3,52]],"ltp":1.3,"tv":52.0,"id":52385911}],"con":true,"img":false}]}
{"op":"mcm","clk":"11550075698","pt":1719494227450,"mc":[{"id":"1.230178167","rc":[{"atb":[[1.19,1.4]],"id":52385910},{"atb":[[1.19,1.49]],"id":52385912},{"atb":[[1.19,1.43]],"id":52385906},{"atb":[[1.19,1.54]],"id":52385918},{"atb":[[1.19,1.42]],"id":52385920},{"atb":[[1.19,1.43]],"id":52385889},{"atb":[[1.19,1.37]],"id":52385914},{"atb":[[1.19,1.38]],"id":52385883},{"atb":[[1.19,1.46]],"id":52385885},{"atb":[[1.19,1.42]],"id":52385896},{"atb":[[1.19,1.37]],"id":52385890},{"atb":[[1.19,1.45]],"id":52385892},{"atb":[[1.19,1.35]],"id":52385904},{"atb":[[1.19,1.5]],"id":52385898},{"atb":[[1.19,1.38]],"id":52385900},{"atb":[[1.19,1.54]],"id":52385911},{"atb":[[1.19,1.43]],"id":52385913},{"atb":[[1.19,1.38]],"id":52385907},{"atb":[[1.19,1.4]],"id":52385886},{"atb":[[1.19,1.48]],"id":52385919},{"atb":[[1.19,1.36]],"id":52385921},{"atb":[[1.19,1.43]],"id":52385882},{"atb":[[1.19,1.52]],"id":52385884},{"atb":[[1.19,1.39]],"id":52385917},{"atb":[[1.19,1.36]],"id":52385897},{"atb":[[1.19,1.51]],"id":52385891},{"atb":[[1.19,1.39]],"id":52385893},{"atb":[[1.19,1.41]],"id":52385903},{"atb":[[1.19,1.49]],"id":52385905},{"atb":[[1.19,1.44]],"id":52385899}],"con":true,"img":false}]}
{"op":"mcm","clk":"11550076000","pt":1719494229945,"mc":[{"id":"1.230178167","rc":[{"atb":[[3.5,50]],"id":52385883},{"atb":[[3.5,50]],"id":52385882}],"con":true,"img":false}]}
{"op":"mcm","clk":"11550076014","pt":1719494230052,"mc":[{"id":"1.230178167","rc":[{"atb":[[3.5,50]],"id":52385910},{"atb":[[3.5,50]],"id":52385906},{"atb":[[3.5,50]],"id":52385889},{"atb":[[3.5,50]],"id":52385885},{"atb":[[3.5,50]],"id":52385896},{"atb":[[3.5,50]],"id":52385890},{"atb":[[3.5,50]],"id":52385904},{"atb":[[3.5,50]],"id":52385898},{"atb":[[3.5,50]],"id":52385886},{"atb":[[3.5,50]],"id":52385884},{"atb":[[3.5,50]],"id":52385897},{"atb":[[3.5,50]],"id":52385891},{"atb":[[3.5,50]],"id":52385893},{"atb":[[3.5,50]],"id":52385903},{"atb":[[3.5,50]],"id":52385905}],"con":true,"img":false}]}
{"op":"mcm","clk":"11550076038","pt":1719494230256,"mc":[{"id":"1.230178167","rc":[{"atb":[[3.5,50]],"id":52385912},{"atb":[[3.5,50]],"id":52385918},{"atb":[[3.5,50]],"id":52385920},{"atb":[[3.5,50]],"id":52385900},{"atb":[[3.5,50]],"id":52385919},{"atb":[[3.5,50]],"id":52385921},{"atb":[[3.5,50]],"id":52385917}],"con":true,"img":false}]}
{"op":"mcm","clk":"11550076054","pt":1719494230360,"mc":[{"id":"1.230178167","rc":[{"atb":[[3.5,50]],"id":52385907},{"atb":[[3.5,50]],"id":52385899}],"con":true,"img":false}]}
{"op":"mcm","clk":"11550076064","pt":1719494230464,"mc":[{"id":"1.230178167","rc":[{"atb":[[3.5,50]],"id":52385914},{"atb":[[3.5,50]],"id":52385913}],"con":true,"img":false}]}
{"op":"mcm","clk":"11550076600","pt":1719494235588,"mc":[{"id":"1.230178167","rc":[{"atb":[[3.5,0]],"id":52385883}],"con":true,"img":false}]}
{"op":"mcm","clk":"11550076657","pt":1719494236052,"mc":[{"id":"1.230178167","rc":[{"atb":[[3.5,0]],"id":52385882}],"con":true,"img":false}]}
{"op":"mcm","clk":"11550076691","pt":1719494236365,"mc":[{"id":"1.230178167","rc":[{"atb":[[3.5,0]],"id":52385913}],"con":true,"img":false}]}
{"op":"mcm","clk":"11550076728","pt":1719494236681,"mc":[{"id":"1.230178167","rc":[{"atb":[[3.5,0]],"id":52385914}],"con":true,"img":false}]}
{"op":"mcm","clk":"11550076750","pt":1719494236881,"mc":[{"id":"1.230178167","rc":[{"atb":[[3.5,0]],"id":52385899}],"con":true,"img":false}]}
{"op":"mcm","clk":"11550076777","pt":1719494237087,"mc":[{"id":"1.230178167","rc":[{"atb":[[3.5,0]],"id":52385907}],"con":true,"img":false}]}
{"op":"mcm","clk":"11550076802","pt":1719494237293,"mc":[{"id":"1.230178167","rc":[{"atb":[[3.5,0]],"id":52385900}],"con":true,"img":false}]}
{"op":"mcm","clk":"11550076828","pt":1719494237453,"mc":[{"id":"1.230178167","rc":[{"atb":[[3.5,0]],"id":52385921}],"con":true,"img":false}]}
{"op":"mcm","clk":"11550076846","pt":1719494237662,"mc":[{"id":"1.230178167","rc":[{"atb":[[3.5,0]],"id":52385920}],"con":true,"img":false}]}
{"op":"mcm","clk":"11550076866","pt":1719494237872,"mc":[{"id":"1.230178167","rc":[{"atb":[[3.5,0]],"id":52385919}],"con":true,"img":false}]}
{"op":"mcm","clk":"11550076881","pt":1719494237977,"mc":[{"id":"1.230178167","rc":[{"atb":[[3.5,0]],"id":52385912}],"con":true,"img":false}]}
{"op":"mcm","clk":"11550076892","pt":1719494238080,"mc":[{"id":"1.230178167","rc":[{"atb":[[3.5,0]],"id":52385918}],"con":true,"img":false}]}
{"op":"mcm","clk":"11550076954","pt":1719494238597,"mc":[{"id":"1.230178167","rc":[{"atb":[[3.5,0]],"id":52385917}],"con":true,"img":false}]}
{"op":"mcm","clk":"11550076993","pt":1719494238859,"mc":[{"id":"1.230178167","rc":[{"atb":[[3.5,0]],"id":52385906}],"con":true,"img":false}]}
{"op":"mcm","clk":"11550077025","pt":1719494239167,"mc":[{"id":"1.230178167","rc":[{"atb":[[3.5,0]],"id":52385891}],"con":true,"img":false}]}
{"op":"mcm","clk":"11550077040","pt":1719494239274,"mc":[{"id":"1.230178167","rc":[{"atb":[[3.5,0]],"id":52385896}],"con":true,"img":false}]}
{"op":"mcm","clk":"11550077051","pt":1719494239374,"mc":[{"id":"1.230178167","rc":[{"atb":[[3.5,0]],"id":52385884}],"con":true,"img":false}]}
{"op":"mcm","clk":"11550077073","pt":1719494239581,"mc":[{"id":"1.230178167","rc":[{"atb":[[3.5,0]],"id":52385885}],"con":true,"img":false}]}
{"op":"mcm","clk":"11550077093","pt":1719494239786,"mc":[{"id":"1.230178167","rc":[{"atb":[[3.5,0]],"id":52385903}],"con":true,"img":false}]}
{"op":"mcm","clk":"11550077113","pt":1719494239993,"mc":[{"id":"1.230178167","rc":[{"atb":[[3.5,0]],"id":52385905}],"con":true,"img":false}]}
{"op":"mcm","clk":"11550077140","pt":1719494240252,"mc":[{"id":"1.230178167","rc":[{"atb":[[3.5,0]],"id":52385893}],"con":true,"img":false}]}
{"op":"mcm","clk":"11550077166","pt":1719494240561,"mc":[{"id":"1.230178167","rc":[{"atb":[[3.5,0]],"id":52385890}],"con":true,"img":false}]}
{"op":"mcm","clk":"11550077187","pt":1719494240769,"mc":[{"id":"1.230178167","rc":[{"atb":[[3.5,0]],"id":52385897}],"con":true,"img":false}]}
{"op":"mcm","clk":"11550077207","pt":1719494240976,"mc":[{"id":"1.230178167","rc":[{"atb":[[3.5,0]],"id":52385904}],"con":true,"img":false}]}
{"op":"mcm","clk":"11550077232","pt":1719494241186,"mc":[{"id":"1.230178167","rc":[{"atb":[[3.5,0]],"id":52385898}],"con":true,"img":false}]}
{"op":"mcm","clk":"11550077252","pt":1719494241391,"mc":[{"id":"1.230178167","rc":[{"atb":[[3.5,0]],"id":52385910}],"con":true,"img":false}]}
{"op":"mcm","clk":"11550077270","pt":1719494241549,"mc":[{"id":"1.230178167","rc":[{"atb":[[3.5,0]],"id":52385886}],"con":true,"img":false}]}
{"op":"mcm","clk":"11550077303","pt":1719494241859,"mc":[{"id":"1.230178167","rc":[{"atb":[[3.5,0]],"id":52385889}],"con":true,"img":false}]}
{"op":"mcm","clk":"11550082695","pt":1719494292664,"mc":[{"id":"1.230178167","rc":[{"atb":[[1.19,2.75]],"id":52385892},{"atb":[[1.19,2.88]],"id":52385911}],"con":true,"img":false}]}
{"op":"mcm","clk":"11550084776","pt":1719494311203,"mc":[{"id":"1.230178167","rc":[{"atb":[[1.17,0]],"id":52385885}],"con":true,"img":false}]}
{"op":"mcm","clk":"11550088609","pt":1719494342412,"mc":[{"id":"1.230178167","rc":[{"atb":[[28,8.62]],"id":52385912}],"con":true,"img":false}]}
{"op":"mcm","clk":"11550088650","pt":1719494342726,"mc":[{"id":"1.230178167","rc":[{"atb":[[28,0]],"id":52385912}],"con":true,"img":false}]}
{"op":"mcm","clk":"11550104710","pt":1719494486624,"mc":[{"id":"1.230178167","rc":[{"atl":[[980,0.84]],"id":52385892},{"atl":[[980,0.84]],"id":52385911}],"con":true,"img":false}]}
{"op":"mcm","clk":"11550111744","pt":1719494551419,"mc":[{"id":"1.230178167","rc":[{"atb":[[1.17,0]],"id":52385883}],"con":true,"img":false}]}
{"op":"mcm","clk":"11550135899","pt":1719494771479,"mc":[{"id":"1.230178167","rc":[{"atb":[[1.17,0]],"id":52385896}],"con":true,"img":false}]}
{"op":"mcm","clk":"11550136089","pt":1719494773597,"mc":[{"id":"1.230178167","rc":[{"atb":[[1.19,2.25]],"id":52385910},{"atb":[[1.19,2.33]],"id":52385912},{"atb":[[1.19,2.28]],"id":52385906},{"atb":[[1.19,2.38]],"id":52385918},{"atb":[[1.19,2.26]],"id":52385920},{"atb":[[1.19,2.27]],"id":52385889},{"atb":[[1.19,2.21]],"id":52385914},{"atb":[[1.19,2.22]],"id":52385883},{"atb":[[1.19,2.31]],"id":52385885},{"atb":[[1.19,2.26]],"id":52385896},{"atb":[[1.19,2.21]],"id":52385890},{"atb":[[1.19,3.59]],"id":52385892},{"atb":[[1.19,2.2]],"id":52385904},{"atb":[[1.19,2.35]],"id":52385898},{"atb":[[1.19,2.23]],"id":52385900},{"atb":[[1.19,3.73]],"id":52385911},{"atb":[[1.19,2.27]],"id":52385913},{"atb":[[1.19,2.22]],"id":52385907},{"atb":[[1.19,2.25]],"id":52385886},{"atb":[[1.19,2.32]],"id":52385919},{"atb":[[1.19,2.21]],"id":52385921},{"atb":[[1.19,2.28]],"id":52385882},{"atb":[[1.19,2.37]],"id":52385884},{"atb":[[1.19,2.24]],"id":52385917},{"atb":[[1.19,2.21]],"id":52385897},{"atb":[[1.19,2.36]],"id":52385891},{"atb":[[1.19,2.24]],"id":52385893},{"atb":[[1.19,2.26]],"id":52385903},{"atb":[[1.19,2.34]],"id":52385905},{"atb":[[1.19,2.29]],"id":52385899}],"con":true,"img":false}]}
{"op":"mcm","clk":"11550136283","pt":1719494775624,"mc":[{"id":"1.230178167","rc":[{"atb":[[1.19,1.67]],"id":52385910},{"atb":[[1.19,1.74]],"id":52385912},{"atb":[[1.19,1.71]],"id":52385906},{"atb":[[1.19,1.81]],"id":52385918},{"atb":[[1.19,1.67]],"id":52385920},{"atb":[[1.19,1.69]],"id":52385889},{"atb":[[1.19,1.64]],"id":52385914},{"atb":[[1.19,1.66]],"id":52385883},{"atb":[[1.19,1.72]],"id":52385885},{"atb":[[1.19,1.67]],"id":52385896},{"atb":[[1.19,1.64]],"id":52385890},{"atb":[[1.19,3]],"id":52385892},{"atb":[[1.19,1.6]],"id":52385904},{"atb":[[1.19,1.77]],"id":52385898},{"atb":[[1.19,1.64]],"id":52385900},{"atb":[[1.19,3.16]],"id":52385911},{"atb":[[1.19,1.69]],"id":52385913},{"atb":[[1.19,1.66]],"id":52385907},{"atb":[[1.19,1.67]],"id":52385886},{"atb":[[1.19,1.76]],"id":52385919},{"atb":[[1.19,1.62]],"id":52385921},{"atb":[[1.19,1.71]],"id":52385882},{"atb":[[1.19,1.77]],"id":52385884},{"atb":[[1.19,1.66]],"id":52385917},{"atb":[[1.19,1.62]],"id":52385897},{"atb":[[1.19,1.79]],"id":52385891},{"atb":[[1.19,1.66]],"id":52385893},{"atb":[[1.19,1.69]],"id":52385903},{"atb":[[1.19,1.76]],"id":52385905},{"atb":[[1.19,1.72]],"id":52385899}],"con":true,"img":false}]}
{"op":"mcm","clk":"11550152831","pt":1719494944442,"mc":[{"id":"1.230178167","rc":[{"atb":[[20,5]],"id":52385910},{"atb":[[20,5]],"id":52385912},{"atb":[[20,5]],"id":52385906},{"atb":[[16,6]],"id":52385918},{"atb":[[16,6]],"id":52385920},{"atb":[[12,8]],"id":52385889},{"atb":[[18,5]],"id":52385914},{"atb":[[9,11]],"id":52385883},{"atb":[[16,6]],"id":52385885},{"atb":[[7,12]],"id":52385896},{"atb":[[16,6]],"id":52385890},{"atb":[[20,5]],"id":52385892},{"atb":[[20,5]],"id":52385904},{"atb":[[9,11]],"id":52385898},{"atb":[[9,11]],"id":52385900},{"atb":[[24,4]],"id":52385911},{"atb":[[24,4]],"id":52385913},{"atb":[[20,5]],"id":52385907},{"atb":[[11,9]],"id":52385886},{"atb":[[11,9]],"id":52385919},{"atb":[[16,6]],"id":52385921},{"atb":[[9,11]],"id":52385882},{"atb":[[15,6]],"id":52385884},{"atb":[[12,8]],"id":52385917},{"atb":[[9,11]],"id":52385897},{"atb":[[20,5]],"id":52385891},{"atb":[[20,5]],"id":52385893},{"atb":[[16,6]],"id":52385903},{"atb":[[16,6]],"id":52385905},{"atb":[[12,8]],"id":52385899}],"con":true,"img":false}]}
{"op":"mcm","clk":"11550152872","pt":1719494945017,"mc":[{"id":"1.230178167","rc":[{"atb":[[1.19,1.54]],"id":52385892}],"con":true,"img":false}]}
{"op":"mcm","clk":"11550152945","pt":1719494945855,"mc":[{"id":"1.230178167","rc":[{"atb":[[1.19,1.29]],"id":52385892}],"con":true,"img":false}]}
{"op":"mcm","clk":"11550152957","pt":1719494945908,"mc":[{"id":"1.230178167","rc":[{"atb":[[1.14,0.25]],"id":52385892}],"con":true,"img":false}]}
{"op":"mcm","clk":"11550157308","pt":1719495001578,"mc":[{"id":"1.230178167","rc":[{"atb":[[1.17,0]],"id":52385890}],"con":true,"img":false}]}
{"op":"mcm","clk":"11550170589","pt":1719495175554,"mc":[{"id":"1.230178167","rc":[{"atb":[[24,0]],"id":52385913},{"atb":[[12,0]],"id":52385917}],"con":true,"img":false}]}
{"op":"mcm","clk":"11550170599","pt":1719495175657,"mc":[{"id":"1.230178167","rc":[{"atb":[[20,4]],"id":52385913},{"atb":[[11,8]],"id":52385917}],"con":true,"img":false}]}
{"op":"mcm","clk":"11550170987","pt":1719495180734,"mc":[{"id":"1.230178167","rc":[{"atb":[[9.6,11.63]],"id":52385910},{"atl":[[620,2]],"id":52385910},{"atb":[[19,5.56]],"id":52385912},{"atl":[[890,2]],"id":52385912},{"atb":[[12.5,8.7]],"id":52385906},{"atl":[[790,2]],"id":52385906},{"atb":[[6.8,17.24]],"id":52385918},{"atl":[[520,2]],"id":52385918},{"atb":[[8.6,13.16]],"id":52385920},{"atl":[[570,2]],"id":52385920},{"atb":[[5.2,23.81]],"id":52385889},{"atl":[[430,2]],"id":52385889},{"atb":[[10.5,10.53]],"id":52385914},{"atl":[[720,2]],"id":52385914},{"atb":[[5.4,22.73]],"id":52385883},{"atl":[[450,2]],"id":52385883},{"atb":[[8.8,12]],"id":52385885},{"atl":[[570,2]],"id":52385885},{"atb":[[4.8,24]],"id":52385896},{"atl":[[390,2]],"id":52385896},{"atb":[[9.2,12.2]],"id":52385890},{"atl":[[600,2]],"id":52385890},{"atb":[[15,7.14]],"id":52385892},{"atl":[[830,2]],"id":52385892},{"atb":[[9,12.5]],"id":52385904},{"atl":[[580,2]],"id":52385904},{"atb":[[9.2,11]],"id":52385898},{"atl":[[600,2]],"id":52385898},{"atb":[[6,20]],"id":52385900},{"atl":[[490,2]],"id":52385900},{"atb":[[17,6.25]],"id":52385911},{"atl":[[860,2]],"id":52385911},{"atb":[[21,4]],"id":52385913},{"atl":[[960,2]],"id":52385913},{"atb":[[7.4,15.62]],"id":52385907},{"atl":[[530,2]],"id":52385907},{"atb":[[4.9,18]],"id":52385886},{"atl":[[410,2]],"id":52385886},{"atb":[[7.2,16.13]],"id":52385919},{"atl":[[530,2]],"id":52385919},{"atb":[[9.6,11.63]],"id":52385921},{"atl":[[620,2]],"id":52385921},{"atb":[[5,22]],"id":52385882},{"atl":[[410,2]],"id":52385882},{"atb":[[6.8,12]],"id":52385884},{"atl":[[520,2]],"id":52385884},{"atb":[[4.8,26.32]],"id":52385917},{"atl":[[380,2]],"id":52385917},{"atb":[[7,16.67]],"id":52385897},{"atl":[[520,2]],"id":52385897},{"atb":[[10.5,10.53]],"id":52385891},{"atl":[[710,2]],"id":52385891},{"atb":[[7.8,14.71]],"id":52385893},{"atl":[[540,2]],"id":52385893},{"atb":[[5.5,22.22]],"id":52385903},{"atl":[[470,2]],"id":52385903},{"atb":[[9.4,11.9]],"id":52385905},{"atl":[[600,2]],"id":52385905},{"atb":[[10.5,10.53]],"id":52385899},{"atl":[[710,2]],"id":52385899}],"con":true,"img":false}]}
{"op":"mcm","clk":"11550171049","pt":1719495181460,"mc":[{"id":"1.230178167","rc":[{"atb":[[1.19,0.27]],"id":52385898},{"atb":[[1.19,1.61]],"id":52385911},{"atb":[[1.19,0.27]],"id":52385899}],"con":true,"img":false}]}
{"op":"mcm","clk":"11550171061","pt":1719495181563,"mc":[{"id":"1.230178167","rc":[{"atb":[[9.4,1.5]],"id":52385898},{"atb":[[12.5,1.44]],"id":52385899}],"con":true,"img":false}]}
{"op":"mcm","clk":"11550171100","pt":1719495181929,"mc":[{"id":"1.230178167","rc":[{"atb":[[1.19,1.33]],"id":52385911}],"con":true,"img":false}]}
{"op":"mcm","clk":"11550171108","pt":1719495182038,"mc":[{"id":"1.230178167","rc":[{"atb":[[1.13,0.27]],"id":52385911}],"con":true,"img":false}]}
{"op":"mcm","clk":"11550171387","pt":1719495185531,"mc":[{"id":"1.230178167","rc":[{"atb":[[20,0]],"id":52385913}],"con":true,"img":false}]}
{"op":"mcm","clk":"11550171395","pt":1719495185630,"mc":[{"id":"1.230178167","rc":[{"atb":[[24,4]],"id":52385913}],"con":true,"img":false}]}
{"op":"mcm","clk":"11550171770","pt":1719495190869,"mc":[{"id":"1.230178167","rc":[{"atb":[[21,0],[25,4]],"id":52385913}],"con":true,"img":false}]}
{"op":"mcm","clk":"11550172426","pt":1719495198682,"mc":[{"id":"1.230178167","rc":[{"atl":[[590,2],[620,0]],"id":52385910},{"atb":[[19,0],[20,10]],"id":52385912},{"atl":[[840,2],[890,0]],"id":52385912},{"atb":[[12.5,0],[14.5,7.41]],"id":52385906},{"atl":[[750,2],[790,0]],"id":52385906},{"atb":[[6.8,0],[7.8,14.71]],"id":52385918},{"atl":[[520,0],[510,2]],"id":52385918},{"atb":[[8.6,0],[10,11.11]],"id":52385920},{"atl":[[570,0],[560,2]],"id":52385920},{"atb":[[5.2,0],[5.7,21.28]],"id":52385889},{"atl":[[430,0],[420,2]],"id":52385889},{"atb":[[10.5,0],[12,9.09]],"id":52385914},{"atl":[[670,2],[720,0]],"id":52385914},{"atb":[[6,20],[5.4,0]],"id":52385883},{"atl":[[440,2],[450,0]],"id":52385883},{"atb":[[9.8,11.36],[8.8,0]],"id":52385885},{"atl":[[570,0],[550,2]],"id":52385885},{"atb":[[4.8,0],[5.1,24]],"id":52385896},{"atl":[[370,2],[390,0]],"id":52385896},{"atb":[[9.2,0],[10,11.11]],"id":52385890},{"atl":[[570,2],[600,0]],"id":52385890},{"atl":[[780,2],[830,0]],"id":52385892},{"atb":[[9,0],[10,11.11]],"id":52385904},{"atl":[[570,2],[580,0]],"id":52385904},{"atl":[[600,0],[590,2]],"id":52385898},{"atb":[[6,0],[7,16.67]],"id":52385900},{"atl":[[490,0],[480,2]],"id":52385900},{"atl":[[800,2],[860,0]],"id":52385911},{"atl":[[900,2],[960,0]],"id":52385913},{"atb":[[7.4,0],[8.4,13.51]],"id":52385907},{"atl":[[530,0],[520,2]],"id":52385907},{"atb":[[4.9,0],[5.4,18]],"id":52385886},{"atl":[[390,2],[410,0]],"id":52385886},{"atb":[[7.2,0],[8.4,13.51]],"id":52385919},{"atl":[[530,0],[520,2]],"id":52385919},{"atb":[[9.6,0],[10.5,10.53]],"id":52385921},{"atl":[[600,2],[620,0]],"id":52385921},{"atb":[[5,0],[5.5,22]],"id":52385882},{"atl":[[410,0],[400,2]],"id":52385882},{"atb":[[6.8,0],[7.8,12]],"id":52385884},{"atl":[[520,0],[510,2]],"id":52385884},{"atb":[[4.8,0],[5.3,23.26]],"id":52385917},{"atl":[[380,0],[370,2]],"id":52385917},{"atb":[[7,0],[7.8,14.71]],"id":52385897},{"atl":[[520,0],[510,2]],"id":52385897},{"atl":[[670,2],[710,0]],"id":52385891},{"atb":[[8.8,12.82],[7.8,0]],"id":52385893},{"atl":[[540,0],[530,2]],"id":52385893},{"atb":[[6.2,19.23],[5.5,0]],"id":52385903},{"atl":[[450,2],[470,0]],"id":52385903},{"atb":[[10.5,10.53],[9.4,0]],"id":52385905},{"atl":[[600,0],[590,2]],"id":52385905},{"atb":[[10.5,0],[12,16]],"id":52385899},{"atl":[[680,2],[710,0]],"id":52385899}],"con":true,"img":false}]}
{"op":"mcm","clk":"11550172441","pt":1719495198878,"mc":[{"id":"1.230178167","rc":[{"atl":[[830,2],[840,0]],"id":52385912}],"con":true,"img":false}]}
{"op":"mcm","clk":"11550172503","pt":1719495199551,"mc":[{"id":"1.230178167","rc":[{"atb":[[12.5,0]],"id":52385899}],"con":true,"img":false}]}
{"op":"mcm","clk":"11550172748","pt":1719495202444,"mc":[{"id":"1.230178167","rc":[{"atb":[[9,0]],"id":52385898},{"atb":[[24,0]],"id":52385913},{"atb":[[15,0]],"id":52385884}],"con":true,"img":false}]}
{"op":"mcm","clk":"11550172758","pt":1719495202551,"mc":[{"id":"1.230178167","rc":[{"atb":[[11,11]],"id":52385898},{"atb":[[20,4],[7.4,15.62],[25,0]],"id":52385913},{"atb":[[14,6]],"id":52385884}],"con":true,"img":false}]}
{"op":"mcm","clk":"11550172766","pt":1719495202652,"mc":[{"id":"1.230178167","rc":[{"atb":[[9.2,0],[10.5,10.53]],"id":52385898},{"atb":[[21,4],[7.4,0]],"id":52385913}],"con":true,"img":false}]}
{"op":"mcm","clk":"11550172820","pt":1719495203219,"mc":[{"id":"1.230178167","rc":[{"atb":[[9.4,0]],"id":52385898}],"con":true,"img":false}]}
{"op":"mcm","clk":"11550172834","pt":1719495203388,"mc":[{"id":"1.230178167","rc":[{"atb":[[11.5,1.5]],"id":52385898}],"con":true,"img":false}]}
{"op":"mcm","clk":"11550173129","pt":1719495206891,"mc":[{"id":"1.230178167","rc":[{"atl":[[430,2],[450,0]],"id":52385903}],"con":true,"img":false}]}
{"op":"mcm","clk":"11550173137","pt":1719495206941,"mc":[{"id":"1.230178167","rc":[{"atl":[[620,2],[670,0]],"id":52385914},{"atl":[[620,2],[670,0]],"id":52385891}],"con":true,"img":false}]}
{"op":"mcm","clk":"11550173287","pt":1719495208701,"mc":[{"id":"1.230178167","rc":[{"atl":[[550,2],[590,0]],"id":52385910},{"atl":[[680,2],[750,0]],"id":52385906},{"atl":[[470,2],[510,0]],"id":52385918},{"atl":[[530,2],[560,0]],"id":52385920},{"atl":[[380,2],[420,0]],"id":52385889},{"atl":[[420,2],[440,0]],"id":52385883},{"atl":[[520,2],[550,0]],"id":52385885},{"atl":[[340,2],[370,0]],"id":52385896},{"atl":[[540,2],[570,0]],"id":52385890},{"atl":[[690,2],[780,0]],"id":52385892},{"atl":[[530,2],[570,0]],"id":52385904},{"atl":[[550,2],[590,0]],"id":52385898},{"atl":[[450,2],[480,0]],"id":52385900},{"atl":[[710,2],[800,0]],"id":52385911},{"atl":[[790,2],[900,0]],"id":52385913},{"atl":[[520,0],[490,2]],"id":52385907},{"atl":[[350,2],[390,0]],"id":52385886},{"atl":[[520,0],[490,2]],"id":52385919},{"atl":[[560,2],[600,0]],"id":52385921},{"atl":[[350,2],[400,0]],"id":52385882},{"atl":[[470,2],[510,0]],"id":52385884},{"atl":[[330,2],[370,0]],"id":52385917},{"atl":[[470,2],[510,0]],"id":52385897},{"atl":[[530,0],[500,2]],"id":52385893},{"atl":[[550,2],[590,0]],"id":52385905},{"atl":[[620,2],[680,0]],"id":52385899}],"con":true,"img":false}]}
{"op":"mcm","clk":"11550173302","pt":1719495208755,"mc":[{"id":"1.230178167","rc":[{"atl":[[740,2],[830,0]],"id":52385912}],"con":true,"img":false}]}
{"op":"mcm","clk":"11550174762","pt":1719495226888,"mc":[{"id":"1.230178167","rc":[{"atl":[[590,2]],"id":52385910},{"atl":[[680,0]],"id":52385906},{"atl":[[510,2]],"id":52385918},{"atl":[[560,2]],"id":52385920},{"atl":[[670,2]],"id":52385914},{"atl":[[440,2]],"id":52385883},{"atl":[[340,0],[370,2]],"id":52385896},{"atl":[[770,2]],"id":52385892},{"atl":[[570,2]],"id":52385904},{"atl":[[550,0],[590,2]],"id":52385898},{"atl":[[480,2]],"id":52385900},{"atl":[[710,0],[800,2]],"id":52385911},{"atl":[[890,2]],"id":52385913},{"atl":[[350,0]],"id":52385886},{"atl":[[490,0]],"id":52385919},{"atl":[[400,2]],"id":52385882},{"atl":[[510,2]],"id":52385884},{"atl":[[330,0],[370,2]],"id":52385917},{"atl":[[620,0],[670,2]],"id":52385891},{"atl":[[530,2]],"id":52385893},{"atl":[[450,2]],"id":52385903},{"atl":[[590,2]],"id":52385905},{"atl":[[620,0]],"id":52385899}],"con":true,"img":false}]}
{"op":"mcm","clk":"11550174772","pt":1719495226994,"mc":[{"id":"1.230178167","rc":[{"atl":[[550,0]],"id":52385910},{"atl":[[740,0],[830,2]],"id":52385912},{"atl":[[750,2]],"id":52385906},{"atl":[[470,0]],"id":52385918},{"atl":[[530,0]],"id":52385920},{"atl":[[380,0],[420,2]],"id":52385889},{"atl":[[620,0]],"id":52385914},{"atl":[[420,0]],"id":52385883},{"atl":[[520,0],[550,2]],"id":52385885},{"atl":[[540,0],[570,2]],"id":52385890},{"atl":[[690,0]],"id":52385892},{"atl":[[530,0]],"id":52385904},{"atl":[[450,0]],"id":52385900},{"atl":[[790,0]],"id":52385913},{"atl":[[520,2],[490,0]],"id":52385907},{"atl":[[390,2]],"id":52385886},{"atl":[[520,2]],"id":52385919},{"atl":[[560,0],[600,2]],"id":52385921},{"atl":[[350,0]],"id":52385882},{"atl":[[470,0]],"id":52385884},{"atl":[[470,0],[510,2]],"id":52385897},{"atl":[[500,0]],"id":52385893},{"atl":[[430,0]],"id":52385903},{"atl":[[550,0]],"id":52385905},{"atl":[[680,2]],"id":52385899}],"con":true,"img":false}]}
{"op":"mcm","clk":"11550174956","pt":1719495229528,"mc":[{"id":"1.230178167","rc":[{"atb":[[11,0]],"id":52385898}],"con":true,"img":false}]}
{"op":"mcm","clk":"11550174982","pt":1719495229787,"mc":[{"id":"1.230178167","rc":[{"atb":[[20,0]],"id":52385913}],"con":true,"img":false}]}
{"op":"mcm","clk":"11550174992","pt":1719495229888,"mc":[{"id":"1.230178167","rc":[{"atb":[[21,0],[7.4,15.62],[24,4]],"id":52385913}],"con":true,"img":false}]}
{"op":"mcm","clk":"11550175002","pt":1719495229993,"mc":[{"id":"1.230178167","rc":[{"atb":[[11.5,0]],"id":52385898},{"atb":[[7.4,0],[25,4]],"id":52385913}],"con":true,"img":false}]}
{"op":"mcm","clk":"11550175009","pt":1719495230107,"mc":[{"id":"1.230178167","rc":[{"atb":[[10.5,0],[4.1,32.26]],"id":52385898}],"con":true,"img":false}]}
{"op":"mcm","clk":"11550175032","pt":1719495230506,"mc":[{"id":"1.230178167","rc":[{"atb":[[10,10]],"id":52385898}],"con":true,"img":false}]}
{"op":"mcm","clk":"11550175041","pt":1719495230611,"mc":[{"id":"1.230178167","rc":[{"atb":[[10.5,10]],"id":52385898}],"con":true,"img":false}]}
{"op":"mcm","clk":"11550175050","pt":1719495230713,"mc":[{"id":"1.230178167","rc":[{"atb":[[4.1,0]],"id":52385898}],"con":true,"img":false}]}
{"op":"mcm","clk":"11550175084","pt":1719495231182,"mc":[{"id":"1.230178167","rc":[{"atb":[[11,1.5]],"id":52385898}],"con":true,"img":false}]}
{"op":"mcm","clk":"11550175110","pt":1719495231696,"mc":[{"id":"1.230178167","rc":[{"atb":[[1.17,0]],"id":52385904}],"con":true,"img":false}]}
{"op":"mcm","clk":"11550175717","pt":1719495239495,"mc":[{"id":"1.230178167","rc":[{"atb":[[24,0]],"id":52385913}],"con":true,"img":false}]}
{"op":"mcm","clk":"11550175724","pt":1719495239600,"mc":[{"id":"1.230178167","rc":[{"atb":[[20,4]],"id":52385913}],"con":true,"img":false}]}
{"op":"mcm","clk":"11550175731","pt":1719495239705,"mc":[{"id":"1.230178167","rc":[{"atb":[[7.4,15.62],[25,0]],"id":52385913}],"con":true,"img":false}]}
{"op":"mcm","clk":"11550175738","pt":1719495239805,"mc":[{"id":"1.230178167","rc":[{"atb":[[21,5],[7.4,0]],"id":52385913}],"con":true,"img":false}]}
{"op":"mcm","clk":"11550175795","pt":1719495240633,"mc":[{"id":"1.230178167","rc":[{"atb":[[10,0]],"id":52385898}],"con":true,"img":false}]}
{"op":"mcm","clk":"11550175804","pt":1719495240690,"mc":[{"id":"1.230178167","rc":[{"atb":[[11,11.5]],"id":52385898}],"con":true,"img":false}]}
{"op":"mcm","clk":"11550175817","pt":1719495240895,"mc":[{"id":"1.230178167","rc":[{"atb":[[11,10]],"id":52385898}],"con":true,"img":false}]}
{"op":"mcm","clk":"11550175859","pt":1719495241412,"mc":[{"id":"1.230178167","rc":[{"atb":[[11.5,1.5]],"id":52385898}],"con":true,"img":false}]}
{"op":"mcm","clk":"11550176438","pt":1719495249537,"mc":[{"id":"1.230178167","rc":[{"atb":[[20,0]],"id":52385913}],"con":true,"img":false}]}
{"op":"mcm","clk":"11550176446","pt":1719495249639,"mc":[{"id":"1.230178167","rc":[{"atb":[[24,4]],"id":52385913}],"con":true,"img":false}]}
{"op":"mcm","clk":"11550176452","pt":1719495249744,"mc":[{"id":"1.230178167","rc":[{"atb":[[21,0],[7.4,15.62]],"id":52385913}],"con":true,"img":false}]}
{"op":"mcm","clk":"11550176474","pt":1719495250004,"mc":[{"id":"1.230178167","rc":[{"atb":[[1.19,0]],"id":52385898}],"con":true,"img":false}]}
{"op":"mcm","clk":"11550176481","pt":1719495250104,"mc":[{"id":"1.230178167","rc":[{"atb":[[11.5,1.77]],"id":52385898}],"con":true,"img":false}]}
{"op":"mcm","clk":"11550176513","pt":1719495250517,"mc":[{"id":"1.230178167","rc":[{"atb":[[11,0]],"id":52385898}],"con":true,"img":false}]}
{"op":"mcm","clk":"11550176561","pt":1719495251239,"mc":[{"id":"1.230178167","rc":[{"atb":[[11.5,0.27]],"id":52385898}],"con":true,"img":false}]}
{"op":"mcm","clk":"11550176574","pt":1719495251446,"mc":[{"id":"1.230178167","rc":[{"atb":[[10.5,0],[4.1,32.26]],"id":52385898}],"con":true,"img":false}]}
{"op":"mcm","clk":"11550176622","pt":1719495252020,"mc":[{"id":"1.230178167","rc":[{"atb":[[11.5,0]],"id":52385898}],"con":true,"img":false}]}
{"op":"mcm","clk":"11550176633","pt":1719495252123,"mc":[{"id":"1.230178167","rc":[{"atb":[[1.13,0.27]],"id":52385898}],"con":true,"img":false}]}
{"op":"mcm","clk":"11550176670","pt":1719495252533,"mc":[{"id":"1.230178167","rc":[{"atb":[[10,10]],"id":52385898}],"con":true,"img":false}]}
{"op":"mcm","clk":"11550177132","pt":1719495259134,"mc":[{"id":"1.230178167","rc":[{"atb":[[7.4,0],[25,4]],"id":52385913}],"con":true,"img":false}]}
{"op":"mcm","clk":"11550177163","pt":1719495259549,"mc":[{"id":"1.230178167","rc":[{"atb":[[24,0]],"id":52385913}],"con":true,"img":false}]}
{"op":"mcm","clk":"11550177172","pt":1719495259651,"mc":[{"id":"1.230178167","rc":[{"atb":[[20,4],[7.4,15.62],[25,0]],"id":52385913}],"con":true,"img":false}]}
{"op":"mcm","clk":"11550177190","pt":1719495259856,"mc":[{"id":"1.230178167","rc":[{"atb":[[21,4],[7.4,0]],"id":52385913}],"con":true,"img":false}]}
{"op":"mcm","clk":"11550177255","pt":1719495260841,"mc":[{"id":"1.230178167","rc":[{"atb":[[10.5,10.53],[4.1,0]],"id":52385898}],"con":true,"img":false}]}
{"op":"mcm","clk":"11550177294","pt":1719495261325,"mc":[{"id":"1.230178167","rc":[{"atb":[[11,1.5]],"id":52385898}],"con":true,"img":false}]}
{"op":"mcm","clk":"11550177398","pt":1719495262550,"mc":[{"id":"1.230178167","rc":[{"atb":[[10,0]],"id":52385898}],"con":true,"img":false}]}
{"op":"mcm","clk":"11550177411","pt":1719495262655,"mc":[{"id":"1.230178167","rc":[{"atb":[[11,11.5]],"id":52385898}],"con":true,"img":false}]}
{"op":"mcm","clk":"11550178867","pt":1719495280559,"mc":[{"id":"1.230178167","rc":[{"atb":[[11,1.5]],"id":52385898},{"atb":[[20,0]],"id":52385913}],"con":true,"img":false}]}
{"op":"mcm","clk":"11550178878","pt":1719495280663,"mc":[{"id":"1.230178167","rc":[{"atb":[[10,10]],"id":52385898},{"atb":[[24,4]],"id":52385913}],"con":true,"img":false}]}
{"op":"mcm","clk":"11550178886","pt":1719495280766,"mc":[{"id":"1.230178167","rc":[{"atb":[[21,0],[7.4,15.62]],"id":52385913}],"con":true,"img":false}]}
{"op":"mcm","clk":"11550179741","pt":1719495289877,"mc":[{"id":"1.230178167","rc":[{"atb":[[7.4,0],[25,4]],"id":52385913}],"con":true,"img":false}]}
{"op":"mcm","clk":"11550179794","pt":1719495290449,"mc":[{"id":"1.230178167","rc":[{"atb":[[10,0]],"id":52385898},{"atb":[[24,0]],"id":52385913}],"con":true,"img":false}]}
{"op":"mcm","clk":"11550179803","pt":1719495290550,"mc":[{"id":"1.230178167","rc":[{"atb":[[11,11.5]],"id":52385898},{"atb":[[20,4]],"id":52385913}],"con":true,"img":false}]}
{"op":"mcm","clk":"11550180178","pt":1719495294975,"mc":[{"id":"1.230178167","rc":[{"atb":[[21,5],[25,0]],"id":52385913}],"con":true,"img":false}]}
{"op":"mcm","clk":"11550180594","pt":1719495300585,"mc":[{"id":"1.230178167","rc":[{"atb":[[11,1.5]],"id":52385898},{"atb":[[20,0]],"id":52385913}],"con":true,"img":false}]}
{"op":"mcm","clk":"11550180602","pt":1719495300689,"mc":[{"id":"1.230178167","rc":[{"atb":[[10,10]],"id":52385898},{"atb":[[21,0],[7.4,15.62],[24,4]],"id":52385913}],"con":true,"img":false}]}
{"op":"mcm","clk":"11550181263","pt":1719495309574,"mc":[{"id":"1.230178167","rc":[{"atb":[[25,4]],"id":52385913}],"con":true,"img":false}]}
{"op":"mcm","clk":"11550181274","pt":1719495309679,"mc":[{"id":"1.230178167","rc":[{"atb":[[7.4,0]],"id":52385913}],"con":true,"img":false}]}
{"op":"mcm","clk":"11550181338","pt":1719495310510,"mc":[{"id":"1.230178167","rc":[{"atb":[[10,0]],"id":52385898},{"atb":[[24,0]],"id":52385913}],"con":true,"img":false}]}
{"op":"mcm","clk":"11550181347","pt":1719495310617,"mc":[{"id":"1.230178167","rc":[{"atb":[[11,11.5]],"id":52385898},{"atb":[[20,4],[7.4,15.62]],"id":52385913}],"con":true,"img":false}]}
{"op":"mcm","clk":"11550181355","pt":1719495310717,"mc":[{"id":"1.230178167","rc":[{"atb":[[21,5],[7.4,0],[25,0]],"id":52385913}],"con":true,"img":false}]}
{"op":"mcm","clk":"11550181808","pt":1719495316487,"mc":[{"id":"1.230178167","rc":[{"atb":[[20,0]],"id":52385893}],"con":true,"img":false}]}
{"op":"mcm","clk":"11550181816","pt":1719495316590,"mc":[{"id":"1.230178167","rc":[{"atb":[[18,5],[3.7,37.04],[8.8,0]],"id":52385893}],"con":true,"img":false}]}
{"op":"mcm","clk":"11550181824","pt":1719495316742,"mc":[{"id":"1.230178167","rc":[{"atb":[[8.8,12.82]],"id":52385893}],"con":true,"img":false}]}
{"op":"mcm","clk":"11550181830","pt":1719495316795,"mc":[{"id":"1.230178167","rc":[{"atb":[[3.7,0]],"id":52385893}],"con":true,"img":false}]}
{"op":"mcm","clk":"11550181977","pt":1719495318734,"mc":[{"id":"1.230178167","rc":[{"atl":[[590,0],[610,2]],"id":52385910},{"atb":[[18,5.88],[20,5]],"id":52385912},{"atl":[[830,0],[880,2]],"id":52385912},{"atb":[[12.5,8.7],[14.5,0]],"id":52385906},{"atl":[[750,0],[790,2]],"id":52385906},{"atl":[[520,2],[510,0]],"id":52385918},{"atb":[[10,0],[8.8,12.82]],"id":52385920},{"atl":[[560,0],[570,2]],"id":52385920},{"atb":[[5.1,24.39],[5.7,0]],"id":52385889},{"atl":[[420,0],[430,2]],"id":52385889},{"atl":[[670,0],[700,2]],"id":52385914},{"atb":[[6,0],[5.4,22.73]],"id":52385883},{"atl":[[440,0],[450,2]],"id":52385883},{"atb":[[8.6,13.16],[9.8,0]],"id":52385885},{"atl":[[550,0],[560,2]],"id":52385885},{"atl":[[370,0],[390,2]],"id":52385896},{"atl":[[570,0],[590,2]],"id":52385890},{"atl":[[770,0],[810,2]],"id":52385892},{"atl":[[570,0],[580,2]],"id":52385904},{"atb":[[10.5,0],[9.4,11.9]],"id":52385898},{"atl":[[590,0],[610,2]],"id":52385898},{"atb":[[6.2,19.23],[7,0]],"id":52385900},{"atl":[[480,0],[500,2]],"id":52385900},{"atl":[[840,2]],"id":52385911},{"atl":[[890,0],[940,2]],"id":52385913},{"atl":[[520,0],[530,2]],"id":52385907},{"atl":[[390,0],[410,2]],"id":52385886},{"atb":[[7.4,15.62],[8.4,0]],"id":52385919},{"atl":[[520,0],[530,2]],"id":52385919},{"atl":[[600,0],[620,2]],"id":52385921},{"atl":[[410,2]],"id":52385882},{"atl":[[520,2],[510,0]],"id":52385884},{"atl":[[370,0],[390,2]],"id":52385917},{"atb":[[7.8,0],[7,16.67]],"id":52385897},{"atl":[[520,2],[510,0]],"id":52385897},{"atl":[[670,0],[700,2]],"id":52385891},{"atl":[[530,0],[540,2]],"id":52385893},{"atb":[[6.2,0],[5.5,22.22]],"id":52385903},{"atl":[[450,0],[470,2]],"id":52385903},{"atb":[[10.5,0],[9.4,11.9]],"id":52385905},{"atl":[[590,0],[610,2]],"id":52385905},{"atb":[[10.5,10.53],[12,8]],"id":52385899},{"atl":[[680,0],[710,2]],"id":52385899}],"con":true,"img":false}]}
{"op":"mcm","clk":"11550181983","pt":1719495318785,"mc":[{"id":"1.230178167","rc":[{"atl":[[800,0]],"id":52385911},{"atl":[[400,0]],"id":52385882}],"con":true,"img":false}]}
{"op":"mcm","clk":"11550181991","pt":1719495318891,"mc":[{"id":"1.230178167","rc":[{"atb":[[12.5,1.44]],"id":52385899}],"con":true,"img":false}]}
{"op":"mcm","clk":"11550182036","pt":1719495319615,"mc":[{"id":"1.230178167","rc":[{"atb":[[12,0]],"id":52385899}],"con":true,"img":false}]}
{"op":"mcm","clk":"11550182045","pt":1719495319720,"mc":[{"id":"1.230178167","rc":[{"atb":[[16,8]],"id":52385899}],"con":true,"img":false}]}
{"op":"mcm","clk":"11550184552","pt":1719495349641,"mc":[{"id":"1.230178167","rc":[{"atb":[[11,1.5]],"id":52385898},{"atb":[[16,0]],"id":52385899}],"con":true,"img":false}]}
{"op":"mcm","clk":"11550184562","pt":1719495349745,"mc":[{"id":"1.230178167","rc":[{"atb":[[10,10]],"id":52385898},{"atb":[[13,8]],"id":52385899}],"con":true,"img":false}]}
{"op":"mcm","clk":"11550184602","pt":1719495350218,"mc":[{"id":"1.230178167","rc":[{"atb":[[11,0]],"id":52385898}],"con":true,"img":false}]}
{"op":"mcm","clk":"11550184616","pt":1719495350321,"mc":[{"id":"1.230178167","rc":[{"atb":[[10.5,1.5]],"id":52385898}],"con":true,"img":false}]}
{"op":"mcm","clk":"11550185438","pt":1719495359635,"mc":[{"id":"1.230178167","rc":[{"atb":[[10,0]],"id":52385898}],"con":true,"img":false}]}
{"op":"mcm","clk":"11550185445","pt":1719495359739,"mc":[{"id":"1.230178167","rc":[{"atb":[[11,10]],"id":52385898}],"con":true,"img":false}]}
{"op":"mcm","clk":"11550185453","pt":1719495359845,"mc":[{"id":"1.230178167","rc":[{"atb":[[10.5,0]],"id":52385898}],"con":true,"img":false}]}
{"op":"mcm","clk":"11550185509","pt":1719495360426,"mc":[{"id":"1.230178167","rc":[{"atb":[[11.5,1.5]],"id":52385898}],"con":true,"img":false}]}
{"op":"mcm","clk":"11550188698","pt":1719495398478,"mc":[{"id":"1.230178167","rc":[{"atb":[[11,0]],"id":52385898},{"atb":[[20,0]],"id":52385913}],"con":true,"img":false}]}
{"op":"mcm","clk":"11550188709","pt":1719495398584,"mc":[{"id":"1.230178167","rc":[{"atb":[[10,10]],"id":52385898},{"atb":[[21,0],[24,4],[6.8,17.24]],"id":52385913}],"con":true,"img":false}]}
{"op":"mcm","clk":"11550188769","pt":1719495399303,"mc":[{"id":"1.230178167","rc":[{"atb":[[11.5,0]],"id":52385898}],"con":true,"img":false}]}
{"op":"mcm","clk":"11550188777","pt":1719495399406,"mc":[{"id":"1.230178167","rc":[{"atb":[[10.5,1.5]],"id":52385898}],"con":true,"img":false}]}
{"op":"mcm","clk":"11550189347","pt":1719495406525,"mc":[{"id":"1.230178167","rc":[{"atb":[[24,8],[6.8,0]],"id":52385913}],"con":true,"img":false}]}
{"op":"mcm","clk":"11550189359","pt":1719495406622,"mc":[{"id":"1.230178167","rc":[{"atb":[[24,4],[6.8,17.24]],"id":52385913}],"con":true,"img":false}]}
{"op":"mcm","clk":"11550189397","pt":1719495407036,"mc":[{"id":"1.230178167","rc":[{"atl":[[570,2],[610,0]],"id":52385910},{"atl":[[790,2],[880,0]],"id":52385912},{"atl":[[710,2],[790,0]],"id":52385906},{"atl":[[520,0],[490,2]],"id":52385918},{"atl":[[540,2],[570,0]],"id":52385920},{"atl":[[410,2],[430,0]],"id":52385889},{"atl":[[640,2],[700,0]],"id":52385914},{"atl":[[430,2],[450,0]],"id":52385883},{"atl":[[530,2],[560,0]],"id":52385885},{"atl":[[360,2],[390,0]],"id":52385896},{"atl":[[560,2],[590,0]],"id":52385890},{"atl":[[730,2],[810,0]],"id":52385892},{"atl":[[550,2],[580,0]],"id":52385904},{"atl":[[570,2],[610,0]],"id":52385898},{"atl":[[470,2],[500,0]],"id":52385900},{"atl":[[760,2],[840,0]],"id":52385911},{"atl":[[840,2]],"id":52385913},{"atl":[[530,0],[510,2]],"id":52385907},{"atl":[[370,2],[410,0]],"id":52385886},{"atl":[[530,0],[510,2]],"id":52385919},{"atl":[[580,2],[620,0]],"id":52385921},{"atl":[[370,2],[410,0]],"id":52385882},{"atl":[[520,0],[490,2]],"id":52385884},{"atl":[[350,2],[390,0]],"id":52385917},{"atl":[[520,0],[490,2]],"id":52385897},{"atl":[[640,2],[700,0]],"id":52385891},{"atl":[[540,0],[520,2]],"id":52385893},{"atl":[[440,2],[470,0]],"id":52385903},{"atl":[[570,2],[610,0]],"id":52385905},{"atl":[[650,2],[710,0]],"id":52385899}],"con":true,"img":false}]}
{"op":"mcm","clk":"11550189408","pt":1719495407136,"mc":[{"id":"1.230178167","rc":[{"atl":[[940,0]],"id":52385913}],"con":true,"img":false}]}
{"op":"mcm","clk":"11550189551","pt":1719495408634,"mc":[{"id":"1.230178167","rc":[{"atb":[[10,0]],"id":52385898},{"atb":[[24,0]],"id":52385913}],"con":true,"img":false}]}
{"op":"mcm","clk":"11550189563","pt":1719495408738,"mc":[{"id":"1.230178167","rc":[{"atb":[[11,10]],"id":52385898},{"atb":[[20,4]],"id":52385913}],"con":true,"img":false}]}
{"op":"mcm","clk":"11550189573","pt":1719495408790,"mc":[{"id":"1.230178167","rc":[{"atb":[[10.5,0]],"id":52385898}],"con":true,"img":false}]}
{"op":"mcm","clk":"11550189625","pt":1719495409417,"mc":[{"id":"1.230178167","rc":[{"atb":[[11.5,1.5]],"id":52385898}],"con":true,"img":false}]}
{"op":"mcm","clk":"11550189724","pt":1719495410655,"mc":[{"id":"1.230178167","rc":[{"atb":[[12,0]],"id":52385889},{"atb":[[11,0]],"id":52385886}],"con":true,"img":false}]}
{"op":"mcm","clk":"11550189731","pt":1719495410747,"mc":[{"id":"1.230178167","rc":[{"atb":[[2.82,54.95],[5.1,0],[11,8]],"id":52385889},{"atb":[[10,9],[2.78,36]],"id":52385886}],"con":true,"img":false}]}
{"op":"mcm","clk":"11550189744","pt":1719495410809,"mc":[{"id":"1.230178167","rc":[{"atb":[[5.4,0]],"id":52385886}],"con":true,"img":false}]}
{"op":"mcm","clk":"11550189957","pt":1719495413634,"mc":[{"id":"1.230178167","rc":[{"atb":[[20,0]],"id":52385907}],"con":true,"img":false}]}
{"op":"mcm","clk":"11550189965","pt":1719495413737,"mc":[{"id":"1.230178167","rc":[{"atb":[[18,5]],"id":52385907}],"con":true,"img":false}]}
{"op":"mcm","clk":"11550189974","pt":1719495413839,"mc":[{"id":"1.230178167","rc":[{"atb":[[3.35,42.55],[8.4,0]],"id":52385907}],"con":true,"img":false}]}
{"op":"mcm","clk":"11550190021","pt":1719495414512,"mc":[{"id":"1.230178167","rc":[{"atb":[[21,4],[6.8,0]],"id":52385913}],"con":true,"img":false}]}
{"op":"mcm","clk":"11550190333","pt":1719495418530,"mc":[{"id":"1.230178167","rc":[{"atb":[[5.1,24.39]],"id":52385889},{"atb":[[20,0]],"id":52385913},{"atb":[[4.9,25.64],[2.78,0]],"id":52385886}],"con":true,"img":false}]}
{"op":"mcm","clk":"11550190343","pt":1719495418633,"mc":[{"id":"1.230178167","rc":[{"atb":[[2.82,0]],"id":52385889},{"atb":[[24,4]],"id":52385913}],"con":true,"img":false}]}
{"op":"mcm","clk":"11550190352","pt":1719495418731,"mc":[{"id":"1.230178167","rc":[{"atb":[[6.8,17.24]],"id":52385913}],"con":true,"img":false}]}
{"op":"mcm","clk":"11550190359","pt":1719495418834,"mc":[{"id":"1.230178167","rc":[{"atb":[[21,0]],"id":52385913}],"con":true,"img":false}]}
{"op":"mcm","clk":"11550190575","pt":1719495421626,"mc":[{"id":"1.230178167","rc":[{"atb":[[3.35,0],[7.4,15.62]],"id":52385907}],"con":true,"img":false}]}
{"op":"mcm","clk":"11550190902","pt":1719495426564,"mc":[{"id":"1.230178167","rc":[{"atb":[[24,8],[6.8,0]],"id":52385913}],"con":true,"img":false}]}
{"op":"mcm","clk":"11550190910","pt":1719495426666,"mc":[{"id":"1.230178167","rc":[{"atb":[[24,4],[6.8,17.24]],"id":52385913}],"con":true,"img":false}]}
{"op":"mcm","clk":"11550190915","pt":1719495426729,"mc":[{"id":"1.230178167","rc":[{"atb":[[24,8.35],[6.8,0]],"id":52385913}],"con":true,"img":false}]}
{"op":"mcm","clk":"11550190927","pt":1719495426824,"mc":[{"id":"1.230178167","rc":[{"atb":[[24,4],[6.8,17.24]],"id":52385913}],"con":true,"img":false}]}
{"op":"mcm","clk":"11550190939","pt":1719495426933,"mc":[{"id":"1.230178167","rc":[{"atb":[[24,8.35],[6.8,0]],"id":52385913}],"con":true,"img":false}]}
{"op":"mcm","clk":"11550190948","pt":1719495427039,"mc":[{"id":"1.230178167","rc":[{"atb":[[24,4],[6.8,17.24]],"id":52385913}],"con":true,"img":false}]}
{"op":"mcm","clk":"11550190957","pt":1719495427136,"mc":[{"id":"1.230178167","rc":[{"atb":[[24,8.35],[6.8,0]],"id":52385913}],"con":true,"img":false}]}
{"op":"mcm","clk":"11550190965","pt":1719495427249,"mc":[{"id":"1.230178167","rc":[{"atb":[[24,4],[6.8,17.24]],"id":52385913}],"con":true,"img":false}]}
{"op":"mcm","clk":"11550190983","pt":1719495427453,"mc":[{"id":"1.230178167","rc":[{"atb":[[24,8.35]],"id":52385913}],"con":true,"img":false}]}
{"op":"mcm","clk":"11550190994","pt":1719495427558,"mc":[{"id":"1.230178167","rc":[{"atb":[[6.8,0]],"id":52385913}],"con":true,"img":false}]}
{"op":"mcm","clk":"11550193637","pt":1719495461762,"mc":[{"id":"1.230178167","rc":[{"atb":[[1.17,0]],"id":52385897}],"con":true,"img":false}]}
{"op":"mcm","clk":"11550194172","pt":1719495467601,"mc":[{"id":"1.230178167","rc":[{"atb":[[11,0]],"id":52385898}],"con":true,"img":false}]}
{"op":"mcm","clk":"11550194184","pt":1719495467661,"mc":[{"id":"1.230178167","rc":[{"atb":[[10,10]],"id":52385898}],"con":true,"img":false}]}
{"op":"mcm","clk":"11550194216","pt":1719495467966,"mc":[{"id":"1.230178167","rc":[{"atb":[[11.5,0]],"id":52385898}],"con":true,"img":false}]}
{"op":"mcm","clk":"11550194224","pt":1719495468069,"mc":[{"id":"1.230178167","rc":[{"atb":[[10.5,1.5]],"id":52385898}],"con":true,"img":false}]}
{"op":"mcm","clk":"11550194647","pt":1719495472490,"mc":[{"id":"1.230178167","rc":[{"atb":[[20,0]],"id":52385912},{"atb":[[20,0]],"id":52385906},{"atb":[[18,0]],"id":52385914},{"atb":[[16,0]],"id":52385885},{"atb":[[7,0]],"id":52385896},{"atb":[[20,0]],"id":52385892},{"atb":[[24,0]],"id":52385911},{"atb":[[11,0]],"id":52385919},{"atb":[[9,0]],"id":52385897}],"con":true,"img":false}]}
{"op":"mcm","clk":"11550194659","pt":1719495472598,"mc":[{"id":"1.230178167","rc":[{"atb":[[5.6,21.74],[18,0],[24,5]],"id":52385912},{"atb":[[4.5,28.57],[24,5],[12.5,0]],"id":52385906},{"atb":[[20,5],[4.1,32.26],[12,0]],"id":52385914},{"atb":[[8.6,0],[18,6],[3.65,26.32]],"id":52385885},{"atb":[[5.1,0],[9,12],[2.76,48]],"id":52385896},{"atb":[[24,5],[15,0],[4.7,27.03]],"id":52385892},{"atb":[[17,0],[5.1,24.39],[38,4]],"id":52385911},{"atb":[[7.4,0],[3.35,42.55],[12,9]],"id":52385919},{"atb":[[11,11],[3.25,44.44],[7,0]],"id":52385897}],"con":true,"img":false}]}
{"op":"mcm","clk":"11550194680","pt":1719495472799,"mc":[{"id":"1.230178167","rc":[{"atb":[[5.6,0],[18,5.88]],"id":52385912},{"atb":[[4.5,0],[12.5,8.7]],"id":52385906},{"atb":[[10.5,10.53],[4.1,0]],"id":52385914},{"atb":[[8.6,13.16],[3.65,0]],"id":52385885},{"atb":[[4.8,26.32],[2.76,0]],"id":52385896},{"atb":[[13.5,8],[4.7,0]],"id":52385892},{"atb":[[5.1,0],[15.5,6.9]],"id":52385911},{"atb":[[3.35,0],[7.4,15.62]],"id":52385919},{"atb":[[3.25,0],[7,16.67]],"id":52385897}],"con":true,"img":false}]}
{"op":"mcm","clk":"11550195066","pt":1719495477605,"mc":[{"id":"1.230178167","rc":[{"atb":[[10,0]],"id":52385898}],"con":true,"img":false}]}
{"op":"mcm","clk":"11550195077","pt":1719495477706,"mc":[{"id":"1.230178167","rc":[{"atb":[[11,10]],"id":52385898}],"con":true,"img":false}]}
{"op":"mcm","clk":"11550195092","pt":1719495477916,"mc":[{"id":"1.230178167","rc":[{"atb":[[10.5,0]],"id":52385898}],"con":true,"img":false}]}
{"op":"mcm","clk":"11550195103","pt":1719495477968,"mc":[{"id":"1.230178167","rc":[{"atb":[[11.5,1.5]],"id":52385898}],"con":true,"img":false}]}
{"op":"mcm","clk":"11550195649","pt":1719495484228,"mc":[{"id":"1.230178167","rc":[{"atb":[[1.31,100]],"id":52385906},{"atb":[[1.31,100]],"id":52385889},{"atb":[[1.31,100]],"id":52385883},{"atb":[[1.31,100]],"id":52385885},{"atb":[[1.31,100]],"id":52385896},{"atb":[[1.31,100]],"id":52385890},{"atb":[[1.31,100]],"id":52385892},{"atb":[[1.31,100]],"id":52385904},{"atb":[[1.31,100]],"id":52385886},{"atb":[[1.31,100]],"id":52385882},{"atb":[[1.31,100]],"id":52385884},{"atb":[[1.31,100]],"id":52385891},{"atb":[[1.31,100]],"id":52385893},{"atb":[[1.31,100]],"id":52385903},{"atb":[[1.31,100]],"id":52385899}],"con":true,"img":false}]}
{"op":"mcm","clk":"11550195657","pt":1719495484285,"mc":[{"id":"1.230178167","rc":[{"atb":[[1.31,100]],"id":52385910},{"atb":[[1.31,100]],"id":52385914},{"atb":[[1.31,100]],"id":52385919},{"atb":[[1.31,100]],"id":52385917},{"atb":[[1.31,100]],"id":52385897}],"con":true,"img":false}]}
{"op":"mcm","clk":"11550195667","pt":1719495484383,"mc":[{"id":"1.230178167","rc":[{"atb":[[1.31,100]],"id":52385912},{"atb":[[1.31,100]],"id":52385918},{"atb":[[1.31,100]],"id":52385920},{"atb":[[1.31,100]],"id":52385911},{"atb":[[1.31,100]],"id":52385905}],"con":true,"img":false}]}
{"op":"mcm","clk":"11550195677","pt":1719495484490,"mc":[{"id":"1.230178167","rc":[{"atb":[[1.31,100]],"id":52385898},{"atb":[[1.31,100]],"id":52385921}],"con":true,"img":false}]}
{"op":"mcm","clk":"11550195686","pt":1719495484596,"mc":[{"id":"1.230178167","rc":[{"atb":[[1.31,100]],"id":52385913}],"con":true,"img":false}]}
{"op":"mcm","clk":"11550195693","pt":1719495484693,"mc":[{"id":"1.230178167","rc":[{"atb":[[1.31,100]],"id":52385900},{"atb":[[1.31,100]],"id":52385907}],"con":true,"img":false}]}
{"op":"mcm","clk":"11550195765","pt":1719495485629,"mc":[{"id":"1.230178167","rc":[{"atb":[[13,0]],"id":52385899}],"con":true,"img":false}]}
{"op":"mcm","clk":"11550195784","pt":1719495485795,"mc":[{"id":"1.230178167","rc":[{"atb":[[20,0]],"id":52385910},{"atb":[[24,0]],"id":52385912},{"atb":[[24,0]],"id":52385906},{"atb":[[20,0]],"id":52385914},{"atb":[[9,0]],"id":52385883},{"atb":[[18,0]],"id":52385885},{"atb":[[16,0]],"id":52385890},{"atb":[[24,0]],"id":52385892},{"atb":[[9,0]],"id":52385900},{"atb":[[38,0]],"id":52385911},{"atb":[[24,4.35]],"id":52385913},{"atb":[[16,0]],"id":52385921},{"atb":[[9,0]],"id":52385882},{"atb":[[16,0]],"id":52385905}],"con":true,"img":false}]}
{"op":"mcm","clk":"11550195794","pt":1719495485894,"mc":[{"id":"1.230178167","rc":[{"atb":[[9,5]],"id":52385910},{"atb":[[9,5]],"id":52385912},{"atb":[[16,5]],"id":52385906},{"atb":[[9,5]],"id":52385914},{"atb":[[10,11]],"id":52385883},{"atb":[[10,6]],"id":52385885},{"atb":[[18,6]],"id":52385890},{"atb":[[16,5]],"id":52385892},{"atb":[[11,11]],"id":52385900},{"atb":[[13,4]],"id":52385911},{"atb":[[12,4]],"id":52385913},{"atb":[[10,6]],"id":52385921},{"atb":[[10,11]],"id":52385882},{"atb":[[19,6]],"id":52385905}],"con":true,"img":false}]}
{"op":"mcm","clk":"11550195803","pt":1719495486013,"mc":[{"id":"1.230178167","rc":[{"atb":[[3.85,35.09]],"id":52385910},{"atb":[[5.6,21.74],[18,0]],"id":52385912},{"atb":[[4.5,28.57],[12.5,0]],"id":52385906},{"atb":[[4.1,32.26]],"id":52385914},{"atb":[[2.88,53.19],[5.4,0]],"id":52385883},{"atb":[[8.6,0],[3.65,37.74]],"id":52385885},{"atb":[[10,0],[3.8,35.71]],"id":52385890},{"atb":[[13.5,0],[4.7,27.03]],"id":52385892},{"atb":[[6.2,0],[3.05,48.78]],"id":52385900},{"atb":[[5.1,24.39],[15.5,0]],"id":52385911},{"atb":[[24,0],[6.8,17.24]],"id":52385913},{"atb":[[10.5,0],[3.9,34.48]],"id":52385921},{"atb":[[2.8,55.56],[5.5,0]],"id":52385882},{"atb":[[3.85,35.09],[9.4,0]],"id":52385905}],"con":true,"img":false}]}
{"op":"mcm","clk":"11550195815","pt":1719495486122,"mc":[{"id":"1.230178167","rc":[{"atb":[[9.6,0],[3.85,0],[9.2,12.2]],"id":52385910},{"atb":[[9.2,11.76]],"id":52385912},{"atb":[[12.5,8.7]],"id":52385906},{"atb":[[9.2,12.2],[10.5,0]],"id":52385914},{"atb":[[2.88,0],[5.4,22.73]],"id":52385883},{"atb":[[8.6,13.16],[3.65,0]],"id":52385885},{"atb":[[9.2,12.2],[3.8,0]],"id":52385890},{"atb":[[13.5,8]],"id":52385892},{"atb":[[6.2,19.23],[3.05,0]],"id":52385900},{"atb":[[5.1,0],[13.5,8]],"id":52385911},{"atb":[[6.8,0],[12.5,8.7]],"id":52385913},{"atb":[[9.6,11.63],[3.9,0]],"id":52385921},{"atb":[[5,25]],"id":52385882},{"atb":[[3.85,0],[9.4,11.9]],"id":52385905}],"con":true,"img":false}]}
{"op":"mcm","clk":"11550195825","pt":1719495486224,"mc":[{"id":"1.230178167","rc":[{"atb":[[5.6,0]],"id":52385912},{"atb":[[4.5,0]],"id":52385906},{"atb":[[4.1,0]],"id":52385914},{"atb":[[4.7,0]],"id":52385892}],"con":true,"img":false}]}
{"op":"mcm","clk":"11550195835","pt":1719495486328,"mc":[{"id":"1.230178167","rc":[{"atb":[[2.8,0]],"id":52385882}],"con":true,"img":false}]}
{"op":"mcm","clk":"11550195849","pt":1719495486393,"mc":[{"id":"1.230178167","rc":[{"atb":[[1.19,0.27]],"id":52385910},{"atb":[[12.5,0]],"id":52385899}],"con":true,"img":false}]}
{"op":"mcm","clk":"11550195859","pt":1719495486503,"mc":[{"id":"1.230178167","rc":[{"atb":[[9.8,1.4]],"id":52385910},{"atb":[[10.5,0],[4.1,32.26]],"id":52385899}],"con":true,"img":false}]}
{"op":"mcm","clk":"11550195869","pt":1719495486599,"mc":[{"id":"1.230178167","rc":[{"atb":[[9.2,0],[9.4,11.9]],"id":52385910}],"con":true,"img":false}]}
{"op":"mcm","clk":"11550195894","pt":1719495486907,"mc":[{"id":"1.230178167","rc":[{"atb":[[9.8,0]],"id":52385910},{"atb":[[1.19,0.25]],"id":52385912},{"atb":[[1.19,0.27]],"id":52385914},{"atb":[[1.19,0.26]],"id":52385913},{"atb":[[1.19,0.26]],"id":52385921}],"con":true,"img":false}]}
{"op":"mcm","clk":"11550195909","pt":1719495487015,"mc":[{"id":"1.230178167","rc":[{"atb":[[9.6,1.4],[9.2,12.2]],"id":52385910},{"atb":[[9.4,1.49]],"id":52385912},{"atb":[[9.4,1.37]],"id":52385914},{"atb":[[13,1.43]],"id":52385913},{"atb":[[10.5,1.36]],"id":52385921}],"con":true,"img":false}]}
{"op":"mcm","clk":"11550195918","pt":1719495487112,"mc":[{"id":"1.230178167","rc":[{"atb":[[9.4,0]],"id":52385910}],"con":true,"img":false}]}
{"op":"mcm","clk":"11550195938","pt":1719495487328,"mc":[{"id":"1.230178167","rc":[{"atb":[[9.2,0],[9.4,11.9]],"id":52385910}],"con":true,"img":false}]}
{"op":"mcm","clk":"11550195958","pt":1719495487530,"mc":[{"id":"1.230178167","rc":[{"atb":[[9.6,0]],"id":52385910},{"atb":[[10,10]],"id":52385899}],"con":true,"img":false}]}
{"op":"mcm","clk":"11550195964","pt":1719495487601,"mc":[{"id":"1.230178167","rc":[{"atb":[[9.2,12.2],[9.4,13.3]],"id":52385910},{"atb":[[10.5,10.53],[4.1,0]],"id":52385899}],"con":true,"img":false}]}
{"op":"mcm","clk":"11550195972","pt":1719495487703,"mc":[{"id":"1.230178167","rc":[{"atb":[[9.4,1.4]],"id":52385910}],"con":true,"img":false}]}
{"op":"mcm","clk":"11550195983","pt":1719495487807,"mc":[{"id":"1.230178167","rc":[{"atb":[[11,0]],"id":52385898}],"con":true,"img":false}]}
{"op":"mcm","clk":"11550195989","pt":1719495487900,"mc":[{"id":"1.230178167","rc":[{"atb":[[12,10]],"id":52385898}],"con":true,"img":false}]}
{"op":"mcm","clk":"11550196010","pt":1719495488111,"mc":[{"id":"1.230178167","rc":[{"atb":[[11,1.44]],"id":52385899}],"con":true,"img":false}]}
{"op":"mcm","clk":"11550196022","pt":1719495488208,"mc":[{"id":"1.230178167","rc":[{"atb":[[23,5]],"id":52385910},{"atb":[[23,5]],"id":52385912},{"atl":[[55,5.4]],"id":52385918},{"atl":[[23,10.34]],"id":52385896},{"atb":[[36,4.06]],"id":52385892},{"atl":[[46,5]],"id":52385882}],"con":true,"img":false}]}
{"op":"mcm","clk":"11550196031","pt":1719495488313,"mc":[{"id":"1.230178167","rc":[{"atb":[[17,13.76]],"id":52385885},{"atl":[[44,5.86]],"id":52385897}],"con":true,"img":false}]}
{"op":"mcm","clk":"11550196042","pt":1719495488416,"mc":[{"id":"1.230178167","rc":[{"atb":[[23,0]],"id":52385910},{"atb":[[23,0]],"id":52385912},{"atl":[[55,0]],"id":52385918},{"atl":[[23,0]],"id":52385896},{"atb":[[36,0]],"id":52385892},{"atl":[[46,0]],"id":52385882}],"con":true,"img":false}]}
{"op":"mcm","clk":"11550196053","pt":1719495488526,"mc":[{"id":"1.230178167","rc":[{"atb":[[17,0]],"id":52385885},{"atl":[[44,0]],"id":52385897}],"con":true,"img":false}]}
{"op":"mcm","clk":"11550196063","pt":1719495488628,"mc":[{"id":"1.230178167","rc":[{"atb":[[16,0]],"id":52385918},{"atb":[[16,0]],"id":52385920},{"atb":[[20,0]],"id":52385904},{"atb":[[16,0]],"id":52385903}],"con":true,"img":false}]}
{"op":"mcm","clk":"11550196073","pt":1719495488735,"mc":[{"id":"1.230178167","rc":[{"atb":[[20,6]],"id":52385918},{"atb":[[20,6]],"id":52385920},{"atb":[[24,5]],"id":52385904},{"atb":[[20,6]],"id":52385903}],"con":true,"img":false}]}
{"op":"mcm","clk":"11550196084","pt":1719495488830,"mc":[{"id":"1.230178167","rc":[{"atb":[[3.2,45.45],[7.8,0]],"id":52385918},{"atb":[[3.7,37.04],[8.8,0]],"id":52385920},{"atb":[[10,0],[3.75,36.36]],"id":52385904},{"atb":[[2.9,52.63],[5.5,0]],"id":52385903}],"con":true,"img":false}]}
{"op":"mcm","clk":"11550196092","pt":1719495488891,"mc":[{"id":"1.230178167","rc":[{"atb":[[3.2,0],[6.8,17.24]],"id":52385918},{"atb":[[3.7,0],[8.8,12.82]],"id":52385920},{"atb":[[9,12.5],[3.75,0]],"id":52385904},{"atb":[[2.9,0],[5.5,22.22]],"id":52385903}],"con":true,"img":false}]}
{"op":"mcm","clk":"11550196352","pt":1719495492137,"mc":[{"id":"1.230178167","rc":[{"atl":[[520,2]],"id":52385918},{"atl":[[700,2]],"id":52385914},{"atl":[[500,2]],"id":52385900},{"atb":[[4.6,27.78]],"id":52385917},{"atl":[[390,2]],"id":52385917},{"atl":[[470,2]],"id":52385903},{"atb":[[10,21.11]],"id":52385899},{"atl":[[710,2]],"id":52385899}],"con":true,"img":false}]}
{"op":"mcm","clk":"11550196361","pt":1719495492242,"mc":[{"id":"1.230178167","rc":[{"atb":[[5.1,5],[5.5,2.5],[9.4,7.04]],"id":52385910},{"atl":[[570,0],[70,2.5],[560,1.07],[610,2],[90,5]],"id":52385910},{"atb":[[6.4,2.5],[5.8,5],[9.4,7.45]],"id":52385912},{"atl":[[150,2.5],[190,5],[790,0],[780,0.77],[880,2]],"id":52385912},{"atb":[[16.5,8],[12,5],[12.5,0],[13,8.33],[14,2.5]],"id":52385906},{"atl":[[150,5],[700,0.86],[710,0],[790,2],[110,2.5]],"id":52385906},{"atb":[[9.6,5],[20,14],[11,2.5]],"id":52385918},{"atl":[[85,2.5],[110,5],[490,0],[480,1.25]],"id":52385918},{"atb":[[16,5],[18,2.5],[21,8]],"id":52385920},{"atl":[[540,0],[530,1.13],[570,2],[75,2.5],[95,5]],"id":52385920},{"atb":[[11.5,32],[7.6,2.5],[6.8,5]],"id":52385889},{"atl":[[85,2.5],[410,0],[400,1.5],[430,2],[110,5]],"id":52385889},{"atb":[[9.6,8],[7.2,2.5],[6.4,5]],"id":52385914},{"atl":[[630,0.95],[640,0],[90,2.5],[120,5]],"id":52385914},{"atb":[[8,5],[10.5,44],[8.8,2.5]],"id":52385883},{"atl":[[46,2.5],[430,0],[420,1.43],[450,2],[60,5]],"id":52385883},{"atb":[[8.6,2.5],[9,12.5],[10.5,24],[7.8,5]],"id":52385885},{"atl":[[530,0],[520,1.16],[560,2],[75,5],[55,2.5]],"id":52385885},{"atb":[[9.2,28],[6.2,2.5],[5.7,5]],"id":52385896},{"atl":[[360,0],[46,2.5],[390,2],[60,5],[990,0.61]],"id":52385896},{"atb":[[16,5],[18,8.5],[18.5,24]],"id":52385890},{"atl":[[130,5],[560,0],[550,1.09],[590,2],[95,2.5]],"id":52385890},{"atb":[[1.26,5],[13,8.33],[13.5,0],[16.5,6.5],[1.3,2.5]],"id":52385892},{"atl":[[160,5],[730,0],[720,4.33],[810,2],[120,2.5]],"id":52385892},{"atb":[[18.5,5],[21,2.5],[25,8]],"id":52385904},{"atl":[[540,1.11],[550,0],[150,5],[580,2],[110,2.5]],"id":52385904},{"atb":[[12.5,8],[9.4,0],[16,5],[18,2.5],[8.8,12.82]],"id":52385898},{"atl":[[570,0],[70,2.5],[560,1.07],[610,2],[90,5]],"id":52385898},{"atb":[[10,2.5],[9.2,5],[11.5,44]],"id":52385900},{"atl":[[80,5],[460,1.31],[470,0],[60,2.5]],"id":52385900},{"atb":[[1.26,5],[1.3,2.5],[14,12]],"id":52385911},{"atl":[[140,2.5],[180,5],[760,0],[750,0.8],[840,2]],"id":52385911},{"atb":[[8.6,5],[13.5,8],[9.4,2.5]],"id":52385913},{"atl":[[190,2.5],[830,0.72],[840,0],[230,5],[940,2]],"id":52385913},{"atb":[[18.5,20],[10,5],[12,2.5]],"id":52385907},{"atl":[[530,2],[85,2.5],[110,5],[510,0],[500,1.2]],"id":52385907},{"atb":[[10,45],[7.6,2.5],[6.8,5]],"id":52385886},{"atl":[[70,5],[360,1.67],[370,0],[50,2.5],[410,2]],"id":52385886},{"atb":[[12.5,41],[14.5,2.5]],"id":52385919},{"atl":[[530,2],[80,5],[60,2.5],[510,0],[500,1.2]],"id":52385919},{"atb":[[9.6,0],[9,17.5],[11,8],[9.8,2.5]],"id":52385921},{"atl":[[70,2.5],[570,1.05],[580,0],[620,2],[90,5]],"id":52385921},{"atb":[[10,37],[6.6,2.5],[5.9,5]],"id":52385882},{"atl":[[65,2.5],[85,5],[370,0],[410,2],[990,0.61]],"id":52385882},{"atb":[[6.4,18.52],[10.5,2.5],[7.8,0],[14.5,24],[9.4,5]],"id":52385884},{"atl":[[520,2],[80,5],[490,0],[60,2.5],[480,1.25]],"id":52385884},{"atb":[[5.3,0],[6.6,2.5],[5.9,5]],"id":52385917},{"atl":[[75,5],[350,0],[340,1.77],[55,2.5]],"id":52385917},{"atb":[[10.5,5],[11.5,44],[12.5,2.5]],"id":52385897},{"atl":[[520,2],[75,2.5],[95,5],[490,0],[480,1.25]],"id":52385897},{"atb":[[21,20],[22,5],[26,2.5]],"id":52385891},{"atl":[[630,0.95],[640,0],[160,5],[700,2],[120,2.5]],"id":52385891},{"atb":[[16,2.5],[18.5,20],[7.4,15.62],[8.8,0],[14,5]],"id":52385893},{"atl":[[520,0],[130,5],[540,2],[95,2.5],[510,1.18]],"id":52385893},{"atb":[[10.5,2.5],[9.4,5]],"id":52385903},{"atl":[[75,2.5],[95,5],[430,1.4],[440,0]],"id":52385903},{"atb":[[17.5,2.5],[19.5,24],[15.5,5]],"id":52385905},{"atl":[[570,0],[560,1.07],[610,2],[80,2.5],[100,5]],"id":52385905},{"atb":[[9,5],[10.5,0],[11.5,8],[9.8,2.5]],"id":52385899},{"atl":[[650,0],[640,0.94],[90,2.5],[120,5]],"id":52385899}],"con":true,"img":false}]}
{"op":"mcm","clk":"11550196382","pt":1719495492454,"mc":[{"id":"1.230178167","rc":[{"atl":[[610,0],[190,2]],"id":52385910},{"atb":[[9.6,7.45],[9.2,0]],"id":52385912},{"atl":[[430,2],[880,0]],"id":52385912},{"atl":[[350,2],[790,0]],"id":52385906},{"atl":[[570,0],[150,2]],"id":52385920},{"atl":[[85,4.5],[430,0]],"id":52385889},{"atb":[[9.2,0],[9.8,8]],"id":52385914},{"atl":[[70,2],[450,0]],"id":52385883},{"atl":[[560,0],[150,2]],"id":52385885},{"atl":[[46,4.72],[390,0]],"id":52385896},{"atl":[[590,0],[180,2]],"id":52385890},{"atb":[[13,0],[15.5,6.9]],"id":52385892},{"atl":[[380,2],[810,0]],"id":52385892},{"atl":[[580,0],[170,2]],"id":52385904},{"atb":[[10,11.11],[8.8,0]],"id":52385898},{"atl":[[610,0],[190,2]],"id":52385898},{"atb":[[13.5,0],[14.5,7.41]],"id":52385911},{"atl":[[400,2],[840,0]],"id":52385911},{"atb":[[12.5,0],[14,7.69]],"id":52385913},{"atl":[[940,0],[490,2]],"id":52385913},{"atl":[[530,0],[120,2]],"id":52385907},{"atl":[[50,4.54],[410,0]],"id":52385886},{"atl":[[530,0],[120,2]],"id":52385919},{"atb":[[9,5],[10,15.36]],"id":52385921},{"atl":[[620,0],[190,2]],"id":52385921},{"atl":[[65,4.5],[410,0]],"id":52385882},{"atl":[[520,0],[110,2]],"id":52385884},{"atl":[[520,0],[110,2]],"id":52385897},{"atl":[[290,2],[700,0]],"id":52385891},{"atb":[[7.4,0],[8.4,13.51]],"id":52385893},{"atl":[[130,7],[540,0]],"id":52385893},{"atl":[[610,0],[190,2]],"id":52385905}],"con":true,"img":false}]}
{"op":"mcm","clk":"11550196398","pt":1719495492621,"mc":[{"id":"1.230178167","rc":[{"atl":[[560,3.07],[190,0]],"id":52385910},{"atb":[[9.6,0],[9.4,14.9]],"id":52385912},{"atl":[[780,2.77],[430,0]],"id":52385912},{"atl":[[350,0],[700,2.86]],"id":52385906},{"atl":[[530,3.13],[150,0]],"id":52385920},{"atl":[[85,2.5],[400,3.5]],"id":52385889},{"atb":[[9.8,0],[9.4,13.27]],"id":52385914},{"atl":[[70,0],[420,3.43]],"id":52385883},{"atl":[[520,3.16],[150,0]],"id":52385885},{"atl":[[360,2],[46,2.49]],"id":52385896},{"atl":[[550,3.09],[180,0]],"id":52385890},{"atl":[[720,6.33],[380,0]],"id":52385892},{"atl":[[540,3.11],[170,0]],"id":52385904},{"atl":[[560,3.07],[190,0]],"id":52385898},{"atb":[[13.5,8],[14.5,0]],"id":52385911},{"atl":[[750,2.8],[400,0]],"id":52385911},{"atb":[[13,9.76]],"id":52385913},{"atl":[[830,2.72]],"id":52385913},{"atl":[[120,0],[500,3.2]],"id":52385907},{"atl":[[360,3.67],[50,2.5]],"id":52385886},{"atl":[[120,0],[500,3.2]],"id":52385919},{"atl":[[570,3.05],[190,0]],"id":52385921},{"atl":[[65,2.5],[370,2]],"id":52385882},{"atl":[[110,0],[480,3.25]],"id":52385884},{"atl":[[110,0],[480,3.25]],"id":52385897},{"atb":[[20,0]],"id":52385891},{"atl":[[630,2.95]],"id":52385891},{"atl":[[130,5],[510,3.18]],"id":52385893},{"atl":[[560,3.07],[190,0]],"id":52385905}],"con":true,"img":false}]}
{"op":"mcm","clk":"11550196410","pt":1719495492724,"mc":[{"id":"1.230178167","rc":[{"atl":[[560,1.07]],"id":52385910},{"atb":[[9.2,12.2],[9.4,7.45]],"id":52385912},{"atl":[[780,0.77],[430,2]],"id":52385912},{"atl":[[700,0.86],[350,2]],"id":52385906},{"atl":[[530,1.13],[150,2]],"id":52385920},{"atl":[[70,2],[420,1.43]],"id":52385883},{"atl":[[520,1.16],[150,2]],"id":52385885},{"atl":[[550,1.09],[180,2]],"id":52385890},{"atl":[[720,4.33],[380,2]],"id":52385892},{"atl":[[170,2]],"id":52385904},{"atl":[[190,2]],"id":52385898},{"atl":[[750,0.8],[400,2]],"id":52385911},{"atb":[[14,0]],"id":52385913},{"atl":[[490,0]],"id":52385913},{"atl":[[120,2],[500,1.2]],"id":52385907},{"atl":[[120,2],[500,1.2]],"id":52385919},{"atl":[[570,1.05],[190,2]],"id":52385921},{"atl":[[110,2]],"id":52385884},{"atl":[[110,2],[480,1.25]],"id":52385897},{"atl":[[290,0]],"id":52385891},{"atl":[[560,1.07],[190,2]],"id":52385905}],"con":true,"img":false}]}
{"op":"mcm","clk":"11550196419","pt":1719495492823,"mc":[{"id":"1.230178167","rc":[{"atl":[[190,2]],"id":52385910},{"atl":[[780,2.77],[430,0]],"id":52385912},{"atl":[[350,0],[700,2.86]],"id":52385906},{"atl":[[530,3.13],[150,0]],"id":52385920},{"atl":[[420,3.43]],"id":52385883},{"atl":[[520,3.16],[150,0]],"id":52385885},{"atl":[[550,3.09],[180,0]],"id":52385890},{"atl":[[720,6.33],[380,0]],"id":52385892},{"atl":[[540,1.11]],"id":52385904},{"atl":[[560,1.07]],"id":52385898},{"atl":[[750,2.8],[400,0]],"id":52385911},{"atb":[[12,0]],"id":52385913},{"atl":[[830,0.72],[490,2]],"id":52385913},{"atl":[[500,3.2]],"id":52385907},{"atl":[[120,0],[500,3.2]],"id":52385919},{"atl":[[570,3.05],[190,0]],"id":52385921},{"atl":[[480,1.25]],"id":52385884},{"atl":[[110,0],[480,3.25]],"id":52385897},{"atl":[[290,2],[630,0.95]],"id":52385891},{"atl":[[560,3.07]],"id":52385905}],"con":true,"img":false}]}
{"op":"mcm","clk":"11550196428","pt":1719495492929,"mc":[{"id":"1.230178167","rc":[{"atl":[[560,3.07],[190,0]],"id":52385910},{"atl":[[780,0.77],[430,2]],"id":52385912},{"atb":[[1.19,0.27]],"id":52385906},{"atl":[[700,0.86],[350,2]],"id":52385906},{"atb":[[1.19,0.25]],"id":52385920},{"atl":[[530,1.13],[150,2]],"id":52385920},{"atb":[[1.19,0.26]],"id":52385889},{"atb":[[9.4,11.9]],"id":52385914},{"atb":[[1.19,0.27]],"id":52385883},{"atl":[[70,0]],"id":52385883},{"atb":[[1.19,0.26]],"id":52385885},{"atl":[[520,1.16],[150,2]],"id":52385885},{"atb":[[1.19,0.25]],"id":52385896},{"atb":[[1.19,0.27]],"id":52385890},{"atl":[[550,1.09],[180,2]],"id":52385890},{"atl":[[720,4.33],[380,2]],"id":52385892},{"atb":[[1.19,0.25]],"id":52385904},{"atb":[[1.19,0.25]],"id":52385900},{"atl":[[750,0.8],[400,2]],"id":52385911},{"atb":[[13,8.33]],"id":52385913},{"atl":[[830,2.72]],"id":52385913},{"atb":[[1.19,0.27]],"id":52385907},{"atl":[[120,0]],"id":52385907},{"atb":[[1.19,0.27]],"id":52385919},{"atl":[[120,2],[500,1.2]],"id":52385919},{"atb":[[10.5,0]],"id":52385921},{"atb":[[1.19,0.25]],"id":52385884},{"atb":[[1.19,0.26]],"id":52385897},{"atb":[[1.19,0.27]],"id":52385891},{"atl":[[290,0],[630,2.95]],"id":52385891},{"atb":[[1.19,0.26]],"id":52385893},{"atb":[[1.19,0.26]],"id":52385905},{"atl":[[190,0]],"id":52385905},{"atb":[[11,0]],"id":52385899}],"con":true,"img":false}]}
{"op":"mcm","clk":"11550196440","pt":1719495493030,"mc":[{"id":"1.230178167","rc":[{"atl":[[560,1.07],[190,2]],"id":52385910},{"atl":[[780,2.77],[430,0]],"id":52385912},{"atb":[[17,1.43]],"id":52385906},{"atl":[[350,0]],"id":52385906},{"atb":[[22,1.42]],"id":52385920},{"atl":[[530,3.13]],"id":52385920},{"atb":[[12,1.43]],"id":52385889},{"atb":[[9,0],[9.8,1.37],[9.4,0]],"id":52385914},{"atb":[[11,1.38]],"id":52385883},{"atl":[[70,2],[420,1.43]],"id":52385883},{"atb":[[11,1.46]],"id":52385885},{"atl":[[520,3.16]],"id":52385885},{"atb":[[9.4,1.42]],"id":52385896},{"atb":[[19,1.37]],"id":52385890},{"atl":[[550,3.09]],"id":52385890},{"atl":[[720,6.33],[380,0]],"id":52385892},{"atb":[[26,1.35]],"id":52385904},{"atb":[[12,1.38]],"id":52385900},{"atl":[[750,2.8],[400,0]],"id":52385911},{"atb":[[14,1.43]],"id":52385913},{"atl":[[490,0]],"id":52385913},{"atb":[[19,1.38]],"id":52385907},{"atl":[[120,2],[500,1.2]],"id":52385907},{"atb":[[13,1.48]],"id":52385919},{"atl":[[120,0]],"id":52385919},{"atb":[[11.5,1.36]],"id":52385921},{"atl":[[570,1.05],[190,2]],"id":52385921},{"atb":[[15,1.52]],"id":52385884},{"atb":[[12,1.36]],"id":52385897},{"atl":[[110,2],[480,1.25]],"id":52385897},{"atb":[[22,6.51]],"id":52385891},{"atl":[[290,2],[630,0.95]],"id":52385891},{"atb":[[19,1.39]],"id":52385893},{"atb":[[20,1.49]],"id":52385905},{"atl":[[560,1.07],[190,2]],"id":52385905},{"atb":[[12,1.44]],"id":52385899}],"con":true,"img":false}]}
{"op":"mcm","clk":"11550196447","pt":1719495493138,"mc":[{"id":"1.230178167","rc":[{"atl":[[780,0.77],[430,2]],"id":52385912},{"atl":[[700,2.86]],"id":52385906},{"atl":[[150,0]],"id":52385920},{"atb":[[9.2,12.2]],"id":52385914},{"atl":[[150,0]],"id":52385885},{"atl":[[180,0]],"id":52385890},{"atl":[[380,2]],"id":52385892},{"atb":[[13,0],[9.4,14.4]],"id":52385913},{"atl":[[490,2]],"id":52385913},{"atl":[[500,3.2]],"id":52385919}],"con":true,"img":false}]}
{"op":"mcm","clk":"11550196461","pt":1719495493238,"mc":[{"id":"1.230178167","rc":[{"atl":[[150,2]],"id":52385920},{"atb":[[11,0]],"id":52385889},{"atl":[[150,2]],"id":52385885},{"atb":[[9,0]],"id":52385896},{"atl":[[720,4.33]],"id":52385892},{"atl":[[750,0.8],[400,2]],"id":52385911},{"atl":[[830,0.72]],"id":52385913},{"atb":[[18,0]],"id":52385907},{"atb":[[12,0]],"id":52385919},{"atb":[[14,0]],"id":52385884},{"atb":[[11,0]],"id":52385897},{"atb":[[18,0]],"id":52385893}],"con":true,"img":false}]}
{"op":"mcm","clk":"11550196467","pt":1719495493294,"mc":[{"id":"1.230178167","rc":[{"atl":[[530,1.13]],"id":52385920},{"atb":[[12,9.43]],"id":52385889},{"atl":[[520,1.16]],"id":52385885},{"atb":[[13,12]],"id":52385896},{"atl":[[550,1.09],[180,2]],"id":52385890},{"atb":[[24,5]],"id":52385907},{"atb":[[19,9]],"id":52385919},{"atb":[[19,6]],"id":52385884},{"atb":[[16,11]],"id":52385897},{"atb":[[20,5]],"id":52385893}],"con":true,"img":false}]}
{"op":"mcm","clk":"11550196476","pt":1719495493399,"mc":[{"id":"1.230178167","rc":[{"atb":[[14.5,7.41],[15.5,0]],"id":52385892},{"atb":[[9.6,10.5],[10,6]],"id":52385921},{"atb":[[11,23]],"id":52385917}],"con":true,"img":false}]}
{"op":"mcm","clk":"11550196485","pt":1719495493503,"mc":[{"id":"1.230178167","rc":[{"atb":[[9,0],[9.2,12]],"id":52385885},{"atb":[[15.5,6.9]],"id":52385892},{"atb":[[14,0]],"id":52385913},{"atb":[[9.6,0],[10,15.36]],"id":52385921},{"atb":[[8.4,0],[7.2,16.13]],"id":52385893}],"con":true,"img":false}]}
{"op":"mcm","clk":"11550196494","pt":1719495493622,"mc":[{"id":"1.230178167","rc":[{"atb":[[8.6,15.66],[9.2,0]],"id":52385885},{"atb":[[14.5,0]],"id":52385892},{"atb":[[11,8]],"id":52385917},{"atb":[[8.4,13.51],[7.2,0]],"id":52385893}],"con":true,"img":false}]}
{"op":"mcm","clk":"11550196502","pt":1719495493716,"mc":[{"id":"1.230178167","rc":[{"atb":[[9,12.5]],"id":52385885},{"atb":[[12,9.09],[15.5,0]],"id":52385892},{"atb":[[9.6,10.5],[10,6]],"id":52385921}],"con":true,"img":false}]}
{"op":"mcm","clk":"11550196511","pt":1719495493820,"mc":[{"id":"1.230178167","rc":[{"atb":[[8.6,2.5]],"id":52385885},{"atb":[[12,0],[15.5,6.9]],"id":52385892},{"atb":[[9.6,0],[10,15.36]],"id":52385921}],"con":true,"img":false}]}
{"op":"mcm","clk":"11550196536","pt":1719495494228,"mc":[{"id":"1.230178167","rc":[{"atb":[[14.5,7.41],[15.5,0]],"id":52385892},{"atb":[[11,23]],"id":52385917}],"con":true,"img":false}]}
{"op":"mcm","clk":"11550196543","pt":1719495494332,"mc":[{"id":"1.230178167","rc":[{"atb":[[7.2,16.13],[13,0]],"id":52385906},{"atb":[[9,0],[8.4,12]],"id":52385885},{"atb":[[9,0],[6,20]],"id":52385904},{"atb":[[8.2,13.89]],"id":52385898},{"atb":[[5.5,22.22],[7.4,0]],"id":52385907},{"atl":[[130,2],[120,0]],"id":52385907},{"atb":[[9.8,13.86]],"id":52385921},{"atb":[[6.4,0],[7.4,15.62]],"id":52385884},{"atb":[[11,8]],"id":52385917},{"atb":[[5.5,0],[4.2,31.25]],"id":52385903},{"atb":[[6,20],[9.4,0]],"id":52385905}],"con":true,"img":false}]}
{"op":"mcm","clk":"11550196549","pt":1719495494436,"mc":[{"id":"1.230178167","rc":[{"atb":[[10,0]],"id":52385898}],"con":true,"img":false}]}
{"op":"mcm","clk":"11550196558","pt":1719495494540,"mc":[{"id":"1.230178167","rc":[{"atb":[[7.2,0],[14,10.19]],"id":52385906},{"atb":[[10,11.11],[12,0]],"id":52385898},{"atb":[[8.6,13.16],[5.5,0]],"id":52385907},{"atb":[[10,6]],"id":52385921},{"atb":[[6.8,15]],"id":52385917},{"atb":[[10.5,10.53],[6,0]],"id":52385905}],"con":true,"img":false}]}
{"op":"mcm","clk":"11550196565","pt":1719495494604,"mc":[{"id":"1.230178167","rc":[{"atb":[[8.2,0]],"id":52385898},{"atb":[[10,17.11],[9.8,2.5]],"id":52385921}],"con":true,"img":false}]}
{"op":"mcm","clk":"11550196573","pt":1719495494706,"mc":[{"id":"1.230178167","rc":[{"atb":[[12,8]],"id":52385914},{"atb":[[18,5]],"id":52385913}],"con":true,"img":false}]}
{"op":"mcm","clk":"11550196654","pt":1719495495640,"mc":[{"id":"1.230178167","rc":[{"atb":[[9,0]],"id":52385910},{"atb":[[9,0]],"id":52385912},{"atb":[[16,0]],"id":52385906},{"atb":[[10,0]],"id":52385885},{"atb":[[11,0]],"id":52385900},{"atb":[[13,0]],"id":52385911},{"atb":[[10,11.11]],"id":52385921}],"con":true,"img":false}]}
{"op":"mcm","clk":"11550196662","pt":1719495495708,"mc":[{"id":"1.230178167","rc":[{"atb":[[12,5]],"id":52385910},{"atb":[[13,5]],"id":52385912},{"atb":[[20,5]],"id":52385906},{"atb":[[13,6]],"id":52385885},{"atb":[[12,12.38]],"id":52385900},{"atb":[[16,4]],"id":52385911},{"atb":[[14,6]],"id":52385921}],"con":true,"img":false}]}
{"op":"mcm","clk":"11550196671","pt":1719495495807,"mc":[{"id":"1.230178167","rc":[{"atb":[[4.9,20],[13.5,0]],"id":52385911}],"con":true,"img":false}]}
{"op":"mcm","clk":"11550196676","pt":1719495495904,"mc":[{"id":"1.230178167","rc":[{"atb":[[9.2,0],[13.5,7.45]],"id":52385912},{"atb":[[17,0]],"id":52385906},{"atb":[[11,0]],"id":52385885},{"atb":[[10,11.11]],"id":52385904},{"atb":[[6.2,19.23],[4.2,0]],"id":52385903}],"con":true,"img":false}]}
{"op":"mcm","clk":"11550196685","pt":1719495496003,"mc":[{"id":"1.230178167","rc":[{"atb":[[6,0]],"id":52385904}],"con":true,"img":false}]}
{"op":"mcm","clk":"11550196726","pt":1719495496524,"mc":[{"id":"1.230178167","rc":[{"atb":[[9.4,5.96]],"id":52385912}],"con":true,"img":false}]}
{"op":"mcm","clk":"11550196734","pt":1719495496632,"mc":[{"id":"1.230178167","rc":[{"atb":[[14,1.49]],"id":52385912}],"con":true,"img":false}]}
{"op":"mcm","clk":"11550196818","pt":1719495497636,"mc":[{"id":"1.230178167","rc":[{"atb":[[16,0]],"id":52385892},{"atb":[[10,11.11]],"id":52385899}],"con":true,"img":false}]}
{"op":"mcm","clk":"11550196826","pt":1719495497738,"mc":[{"id":"1.230178167","rc":[{"atb":[[18,5]],"id":52385892},{"atb":[[12,11.44]],"id":52385899}],"con":true,"img":false}]}
{"op":"mcm","clk":"11550196947","pt":1719495499108,"mc":[{"id":"1.230178167","rc":[{"atl":[[630,2.95],[700,0]],"id":52385914},{"atb":[[5.1,24.39]],"id":52385917},{"atl":[[340,3.77]],"id":52385917},{"atb":[[10,0],[11,10]],"id":52385899},{"atl":[[640,2.94],[710,0]],"id":52385899}],"con":true,"img":false}]}
{"op":"mcm","clk":"11550196957","pt":1719495499217,"mc":[{"id":"1.230178167","rc":[{"atb":[[4.6,0]],"id":52385917},{"atl":[[390,0]],"id":52385917}],"con":true,"img":false}]}
{"op":"mcm","clk":"11550197024","pt":1719495500138,"mc":[{"id":"1.230178167","rc":[{"atb":[[10.5,10.53]],"id":52385914},{"atb":[[18.5,5.71]],"id":52385913}],"con":true,"img":false}]}
{"op":"mcm","clk":"11550197030","pt":1719495500241,"mc":[{"id":"1.230178167","rc":[{"atb":[[9.2,0]],"id":52385914},{"atb":[[9.4,2.5]],"id":52385913}],"con":true,"img":false}]}
{"op":"mcm","clk":"11550197073","pt":1719495500608,"mc":[{"id":"1.230178167","rc":[{"atb":[[10,0]],"id":52385883},{"atb":[[19,1.43]],"id":52385913}],"con":true,"img":false}]}
{"op":"mcm","clk":"11550197096","pt":1719495500819,"mc":[{"id":"1.230178167","rc":[{"atb":[[9.8,0]],"id":52385914}],"con":true,"img":false}]}
{"op":"mcm","clk":"11550197106","pt":1719495500918,"mc":[{"id":"1.230178167","rc":[{"atb":[[12.5,1.37]],"id":52385914},{"atb":[[18,2.5]],"id":52385890}],"con":true,"img":false}]}
{"op":"mcm","clk":"11550197138","pt":1719495501229,"mc":[{"id":"1.230178167","rc":[{"atb":[[20,8]],"id":52385918},{"atb":[[10,36]],"id":52385886},{"atb":[[10,26]],"id":52385882}],"con":true,"img":false}]}
{"op":"mcm","clk":"11550197148","pt":1719495501338,"mc":[{"id":"1.230178167","rc":[{"atb":[[18,6],[20,0]],"id":52385918},{"atb":[[11,0]],"id":52385883},{"atb":[[9,9]],"id":52385886},{"atb":[[8,11],[10,0]],"id":52385882}],"con":true,"img":false}]}
{"op":"mcm","clk":"11550197159","pt":1719495501439,"mc":[{"id":"1.230178167","rc":[{"atb":[[10,0]],"id":52385886}],"con":true,"img":false}]}
{"op":"mcm","clk":"11550197166","pt":1719495501541,"mc":[{"id":"1.230178167","rc":[{"atb":[[19.5,10]],"id":52385918},{"atb":[[9.2,17.34]],"id":52385886},{"atb":[[9.8,10]],"id":52385882}],"con":true,"img":false}]}
{"op":"mcm","clk":"11550197201","pt":1719495502008,"mc":[{"id":"1.230178167","rc":[{"atb":[[1.19,0.27]],"id":52385918},{"atb":[[1.19,0.27]],"id":52385886}],"con":true,"img":false}]}
{"op":"mcm","clk":"11550197210","pt":1719495502112,"mc":[{"id":"1.230178167","rc":[{"atb":[[20,1.54]],"id":52385918},{"atb":[[9.4,1.4]],"id":52385886}],"con":true,"img":false}]}
{"op":"mcm","clk":"11550197268","pt":1719495502834,"mc":[{"id":"1.230178167","rc":[{"atb":[[4.9,0],[14.5,7.41]],"id":52385911}],"con":true,"img":false}]}
{"op":"mcm","clk":"11550197274","pt":1719495502937,"mc":[{"id":"1.230178167","rc":[{"atb":[[14,19.69],[14.5,0]],"id":52385911}],"con":true,"img":false}]}
{"op":"mcm","clk":"11550197280","pt":1719495503058,"mc":[{"id":"1.230178167","rc":[{"atb":[[9.8,11.36],[8.8,0]],"id":52385920},{"atb":[[10.5,0],[11,9.37]],"id":52385914},{"atb":[[14,12],[14.5,7.41]],"id":52385911}],"con":true,"img":false}]}
{"op":"mcm","clk":"11550197331","pt":1719495503615,"mc":[{"id":"1.230178167","rc":[{"atb":[[19,0]],"id":52385884}],"con":true,"img":false}]}
{"op":"mcm","clk":"11550197356","pt":1719495503920,"mc":[{"id":"1.230178167","rc":[{"atb":[[13,0]],"id":52385896}],"con":true,"img":false}]}
{"op":"mcm","clk":"11550197373","pt":1719495504127,"mc":[{"id":"1.230178167","rc":[{"atb":[[16,0]],"id":52385897}],"con":true,"img":false}]}
{"op":"mcm","clk":"11550197386","pt":1719495504334,"mc":[{"id":"1.230178167","rc":[{"atb":[[12,1.43]],"id":52385889},{"atb":[[9.4,0]],"id":52385896},{"atb":[[19,0]],"id":52385919},{"atb":[[15,0]],"id":52385884}],"con":true,"img":false}]}
{"op":"mcm","clk":"11550197393","pt":1719495504439,"mc":[{"id":"1.230178167","rc":[{"atb":[[6,2]],"id":52385910},{"atb":[[6,2]],"id":52385912},{"atb":[[6,2]],"id":52385906},{"atb":[[6,2]],"id":52385918},{"atb":[[6,2]],"id":52385920},{"atb":[[10,8],[6,2]],"id":52385889},{"atb":[[6,2]],"id":52385914},{"atb":[[6,2]],"id":52385883},{"atb":[[6,2]],"id":52385885},{"atb":[[6,2]],"id":52385896},{"atb":[[6,2]],"id":52385890},{"atb":[[6,2]],"id":52385892},{"atb":[[6,2]],"id":52385904},{"atb":[[6,2]],"id":52385898},{"atb":[[6,2]],"id":52385900},{"atb":[[6,2]],"id":52385911},{"atb":[[6,2]],"id":52385913},{"atb":[[6,2]],"id":52385907},{"atb":[[6,2]],"id":52385886},{"atb":[[16,9],[6,2]],"id":52385919},{"atb":[[6,2]],"id":52385921},{"atb":[[6,2]],"id":52385882},{"atb":[[6,2]],"id":52385884},{"atb":[[6,2]],"id":52385917},{"atb":[[6,2]],"id":52385897},{"atb":[[6,2]],"id":52385891},{"atb":[[6,2]],"id":52385893},{"atb":[[6,2]],"id":52385903},{"atb":[[6,2]],"id":52385905},{"atb":[[6,2]],"id":52385899}],"con":true,"img":false}]}
{"op":"mcm","clk":"11550197402","pt":1719495504547,"mc":[{"id":"1.230178167","rc":[{"atb":[[9.2,0]],"id":52385896}],"con":true,"img":false}]}
{"op":"mcm","clk":"11550197412","pt":1719495504648,"mc":[{"id":"1.230178167","rc":[{"atb":[[6.2,11.5]],"id":52385896}],"con":true,"img":false}]}
{"op":"mcm","clk":"11550197427","pt":1719495504853,"mc":[{"id":"1.230178167","rc":[{"atb":[[12,0]],"id":52385914},{"atb":[[6.4,1.42]],"id":52385896},{"atb":[[18,0]],"id":52385913}],"con":true,"img":false}]}
{"op":"mcm","clk":"11550197436","pt":1719495504920,"mc":[{"id":"1.230178167","rc":[{"atb":[[20,8]],"id":52385914},{"atb":[[42,5]],"id":52385913},{"atb":[[13,0]],"id":52385919}],"con":true,"img":false}]}
{"op":"mcm","clk":"11550197442","pt":1719495505012,"mc":[{"id":"1.230178167","rc":[{"atb":[[23,4.55]],"id":52385913},{"atb":[[16.5,1.48]],"id":52385919}],"con":true,"img":false}]}
{"op":"mcm","clk":"11550197448","pt":1719495505114,"mc":[{"id":"1.230178167","rc":[{"atb":[[18.5,0]],"id":52385913}],"con":true,"img":false}]}
{"op":"mcm","clk":"11550197480","pt":1719495505532,"mc":[{"id":"1.230178167","rc":[{"atb":[[9,11]],"id":52385896}],"con":true,"img":false}]}
{"op":"mcm","clk":"11550197505","pt":1719495505842,"mc":[{"id":"1.230178167","rc":[{"atb":[[13,0]],"id":52385912},{"atb":[[10.5,0],[11,15]],"id":52385883}],"con":true,"img":false}]}
{"op":"mcm","clk":"11550197516","pt":1719495505945,"mc":[{"id":"1.230178167","rc":[{"atb":[[24,5]],"id":52385912}],"con":true,"img":false}]}
{"op":"mcm","clk":"11550197524","pt":1719495506048,"mc":[{"id":"1.230178167","rc":[{"atb":[[13.5,0],[16,6.67]],"id":52385912}],"con":true,"img":false}]}
{"op":"mcm","clk":"11550197557","pt":1719495506519,"mc":[{"id":"1.230178167","rc":[{"atb":[[15,6]],"id":52385884},{"atb":[[13,8]],"id":52385897}],"con":true,"img":false}]}
{"op":"mcm","clk":"11550197563","pt":1719495506622,"mc":[{"id":"1.230178167","rc":[{"atb":[[15.5,1.52]],"id":52385884}],"con":true,"img":false}]}
{"op":"mcm","clk":"11550197570","pt":1719495506731,"mc":[{"id":"1.230178167","rc":[{"atb":[[12,0]],"id":52385897}],"con":true,"img":false}]}
{"op":"mcm","clk":"11550197580","pt":1719495506829,"mc":[{"id":"1.230178167","rc":[{"atb":[[13.5,1.36]],"id":52385897},{"atb":[[19,0]],"id":52385905}],"con":true,"img":false}]}
{"op":"mcm","clk":"11550197590","pt":1719495506934,"mc":[{"id":"1.230178167","rc":[{"atb":[[24,6]],"id":52385905}],"con":true,"img":false}]}
{"op":"mcm","clk":"11550197611","pt":1719495507140,"mc":[{"id":"1.230178167","rc":[{"atb":[[12.5,20]],"id":52385910},{"atl":[[65,9.38]],"id":52385910},{"atb":[[25,15]],"id":52385912},{"atl":[[140,4.32]],"id":52385912},{"atb":[[29,20]],"id":52385906},{"atl":[[100,6.06]],"id":52385906},{"atb":[[20,16.54]],"id":52385918},{"atl":[[48,12.77]],"id":52385918},{"atb":[[28,15]],"id":52385920},{"atl":[[70,8.7]],"id":52385920},{"atb":[[12,18.43]],"id":52385889},{"atl":[[36,17]],"id":52385889},{"atb":[[21,15.9]],"id":52385914},{"atl":[[85,7.14]],"id":52385914},{"atl":[[44,13.95]],"id":52385883},{"atb":[[17,15]],"id":52385885},{"atl":[[50,12.24]],"id":52385885},{"atb":[[9,26]],"id":52385896},{"atl":[[19.5,15]],"id":52385896},{"atb":[[23,10]],"id":52385890},{"atl":[[90,6.74]],"id":52385890},{"atb":[[29,20]],"id":52385892},{"atl":[[110,10.5]],"id":52385892},{"atb":[[30,15]],"id":52385904},{"atl":[[100,6.06]],"id":52385904},{"atb":[[24,15]],"id":52385898},{"atl":[[65,9.38]],"id":52385898},{"atb":[[12.5,15]],"id":52385900},{"atl":[[42,14.63]],"id":52385900},{"atb":[[18.5,18]],"id":52385911},{"atl":[[130,4.65]],"id":52385911},{"atb":[[44,13.95]],"id":52385913},{"atl":[[180,3.35]],"id":52385913},{"atb":[[24,20]],"id":52385907},{"atl":[[80,7.59]],"id":52385907},{"atb":[[9.6,17.34]],"id":52385886},{"atl":[[48,12.77]],"id":52385886},{"atb":[[19,11.4]],"id":52385919},{"atl":[[46,11.4]],"id":52385919},{"atb":[[21,15]],"id":52385921},{"atl":[[65,9.38]],"id":52385921},{"atl":[[22,15]],"id":52385882},{"atb":[[17.5,15]],"id":52385884},{"atl":[[34,15]],"id":52385884},{"atl":[[25,17.54]],"id":52385917},{"atb":[[15.5,10]],"id":52385897},{"atl":[[34,10]],"id":52385897},{"atb":[[29,15]],"id":52385891},{"atl":[[110,5.5]],"id":52385891},{"atb":[[22,16.36]],"id":52385893},{"atl":[[85,7.14]],"id":52385893},{"atl":[[55,11.11]],"id":52385903},{"atb":[[26,15]],"id":52385905},{"atl":[[75,8.11]],"id":52385905},{"atb":[[14,26]],"id":52385899},{"atl":[[85,7.14]],"id":52385899}],"con":true,"img":false}]}
{"op":"mcm","clk":"11550197622","pt":1719495507246,"mc":[{"id":"1.230178167","rc":[{"atl":[[700,0.86]],"id":52385906},{"atb":[[21,0]],"id":52385920},{"atl":[[530,0]],"id":52385920},{"atl":[[400,1.5],[110,7]],"id":52385889},{"atl":[[65,2],[420,0]],"id":52385883},{"atb":[[18.5,0]],"id":52385907},{"atl":[[500,0]],"id":52385907},{"atb":[[12.5,5]],"id":52385919},{"atl":[[500,2]],"id":52385919},{"atl":[[85,7],[370,0],[990,0]],"id":52385882},{"atb":[[14.5,0]],"id":52385884},{"atl":[[480,0]],"id":52385884},{"atb":[[21,0]],"id":52385891},{"atl":[[630,0]],"id":52385891}],"con":true,"img":false}]}
{"op":"mcm","clk":"11550197635","pt":1719495507353,"mc":[{"id":"1.230178167","rc":[{"atb":[[9.4,1.4]],"id":52385910},{"atl":[[560,0],[160,2],[190,0]],"id":52385910},{"atb":[[9.4,0]],"id":52385912},{"atl":[[780,0]],"id":52385912},{"atb":[[16.5,0]],"id":52385906},{"atl":[[700,0],[360,2]],"id":52385906},{"atb":[[19.5,0]],"id":52385918},{"atl":[[520,0],[110,7],[480,0]],"id":52385918},{"atb":[[11.5,0]],"id":52385889},{"atl":[[400,0]],"id":52385889},{"atb":[[9.6,0]],"id":52385914},{"atl":[[630,0],[240,2]],"id":52385914},{"atl":[[70,0]],"id":52385883},{"atb":[[10.5,0]],"id":52385885},{"atl":[[520,0]],"id":52385885},{"atb":[[6.2,2.5]],"id":52385896},{"atl":[[360,0],[60,7],[990,0]],"id":52385896},{"atb":[[18.5,0]],"id":52385890},{"atl":[[550,0]],"id":52385890},{"atb":[[16.5,0]],"id":52385892},{"atl":[[720,0]],"id":52385892},{"atb":[[25,0]],"id":52385904},{"atl":[[540,0]],"id":52385904},{"atb":[[12.5,0]],"id":52385898},{"atl":[[560,0]],"id":52385898},{"atb":[[11.5,0]],"id":52385900},{"atl":[[85,2],[460,0],[500,0]],"id":52385900},{"atb":[[14,0]],"id":52385911},{"atl":[[750,0]],"id":52385911},{"atb":[[13.5,0]],"id":52385913},{"atl":[[830,0]],"id":52385913},{"atb":[[9.2,0]],"id":52385886},{"atl":[[70,7],[360,0]],"id":52385886},{"atl":[[120,2],[500,0]],"id":52385919},{"atb":[[11,0]],"id":52385921},{"atl":[[570,0]],"id":52385921},{"atl":[[75,7],[340,0]],"id":52385917},{"atb":[[11.5,0]],"id":52385897},{"atl":[[480,0]],"id":52385897},{"atb":[[18.5,0]],"id":52385893},{"atl":[[130,7],[510,0]],"id":52385893},{"atl":[[95,7],[430,0],[470,0]],"id":52385903},{"atb":[[19.5,0]],"id":52385905},{"atl":[[560,0]],"id":52385905},{"atb":[[11.5,0]],"id":52385899},{"atl":[[640,0],[240,2]],"id":52385899}],"con":true,"img":false}]}
{"op":"mcm","clk":"11550197652","pt":1719495507523,"mc":[{"id":"1.230178167","rc":[{"atb":[[24,0]],"id":52385904}],"con":true,"img":false}]}
{"op":"mcm","clk":"11550197680","pt":1719495507826,"mc":[{"id":"1.230178167","rc":[{"atb":[[12,0]],"id":52385910},{"atl":[[1000,0]],"id":52385910},{"atb":[[20,0]],"id":52385906},{"atl":[[1000,0]],"id":52385906},{"atl":[[1000,0]],"id":52385920},{"atl":[[1000,0]],"id":52385914},{"atl":[[1000,0]],"id":52385883},{"atl":[[1000,0]],"id":52385885},{"atl":[[1000,0]],"id":52385890},{"atb":[[18,0]],"id":52385892},{"atl":[[1000,0]],"id":52385892},{"atl":[[1000,0]],"id":52385904},{"atl":[[1000,0]],"id":52385898},{"atb":[[12,1.38]],"id":52385900},{"atb":[[16,0]],"id":52385911},{"atl":[[1000,0]],"id":52385907},{"atl":[[1000,0]],"id":52385886},{"atl":[[1000,0]],"id":52385919},{"atb":[[14,0]],"id":52385921},{"atl":[[1000,0]],"id":52385921},{"atl":[[1000,0]],"id":52385893},{"atl":[[1000,0]],"id":52385903},{"atl":[[1000,0]],"id":52385905},{"atb":[[12,1.44]],"id":52385899},{"atl":[[1000,0]],"id":52385899}],"con":true,"img":false}]}
{"op":"mcm","clk":"11550197690","pt":1719495507936,"mc":[{"id":"1.230178167","rc":[{"atb":[[12.5,0],[9.4,0],[18,5]],"id":52385910},{"atl":[[60,1.22]],"id":52385910},{"atb":[[14,0]],"id":52385912},{"atb":[[24,5]],"id":52385906},{"atl":[[95,1.31]],"id":52385906},{"atl":[[65,1.36]],"id":52385920},{"atb":[[12.5,0]],"id":52385914},{"atl":[[80,1.31]],"id":52385914},{"atl":[[42,1.35]],"id":52385883},{"atl":[[48,1.31]],"id":52385885},{"atl":[[85,1.28]],"id":52385890},{"atb":[[14.5,0],[20,5],[6.2,19.23]],"id":52385892},{"atl":[[100,1.24]],"id":52385892},{"atl":[[95,1.35]],"id":52385904},{"atl":[[60,1.3]],"id":52385898},{"atb":[[12,0],[14,11]],"id":52385900},{"atb":[[14.5,0],[6.2,19.23],[24,4]],"id":52385911},{"atb":[[19,0]],"id":52385913},{"atl":[[75,1.2]],"id":52385907},{"atb":[[9.4,0]],"id":52385886},{"atl":[[46,1.2]],"id":52385886},{"atl":[[44,1.3]],"id":52385919},{"atb":[[18,6]],"id":52385921},{"atl":[[60,1.25]],"id":52385921},{"atb":[[15.5,0]],"id":52385884},{"atb":[[13.5,0]],"id":52385897},{"atb":[[22,5]],"id":52385891},{"atb":[[19,0]],"id":52385893},{"atl":[[80,1.31]],"id":52385893},{"atl":[[50,1.27]],"id":52385903},{"atb":[[20,0]],"id":52385905},{"atl":[[70,1.24]],"id":52385905},{"atb":[[12,0],[18,10]],"id":52385899},{"atl":[[80,1.36]],"id":52385899}],"con":true,"img":false}]}
{"op":"mcm","clk":"11550197699","pt":1719495508032,"mc":[{"id":"1.230178167","rc":[{"atb":[[12,28.76],[13,1.4]],"id":52385910},{"atb":[[26,1.49]],"id":52385912},{"atb":[[22,1.37]],"id":52385914},{"atb":[[14,7.69],[6.2,0]],"id":52385892},{"atb":[[13,1.38]],"id":52385900},{"atb":[[14.5,7.41],[6.2,0]],"id":52385911},{"atb":[[46,1.43]],"id":52385913},{"atb":[[9.6,0],[9.8,1.4]],"id":52385886},{"atl":[[48,14.9]],"id":52385886},{"atb":[[18,1.52]],"id":52385884},{"atb":[[16,1.36]],"id":52385897},{"atb":[[30,1.51]],"id":52385891},{"atb":[[23,1.39]],"id":52385893},{"atl":[[85,2]],"id":52385903},{"atb":[[27,1.49]],"id":52385905},{"atb":[[14.5,1.44]],"id":52385899}],"con":true,"img":false}]}
{"op":"mcm","clk":"11550197707","pt":1719495508136,"mc":[{"id":"1.230178167","rc":[{"atb":[[9.2,23]],"id":52385886},{"atl":[[70,5]],"id":52385886},{"atl":[[95,5]],"id":52385903}],"con":true,"img":false}]}
{"op":"mcm","clk":"11550197717","pt":1719495508251,"mc":[{"id":"1.230178167","rc":[{"atb":[[11,38]],"id":52385917}],"con":true,"img":false}]}
{"op":"mcm","clk":"11550197722","pt":1719495508350,"mc":[{"id":"1.230178167","rc":[{"atl":[[980,0.66]],"id":52385892}],"con":true,"img":false}]}
{"op":"mcm","clk":"11550197732","pt":1719495508448,"mc":[{"id":"1.230178167","rc":[{"atb":[[30,1.43]],"id":52385906},{"atb":[[8,14.29],[6.8,0]],"id":52385918},{"atb":[[5.1,0],[5.8,20.83]],"id":52385889},{"atb":[[5.9,20.41],[5.4,0]],"id":52385883},{"atb":[[4.9,0],[5.4,22.73]],"id":52385886},{"atb":[[7.4,0],[8.4,13.51]],"id":52385919},{"atb":[[5,0],[5.5,22.22]],"id":52385882},{"atb":[[6.8,0]],"id":52385917}],"con":true,"img":false}]}
{"op":"mcm","clk":"11550197740","pt":1719495508552,"mc":[{"id":"1.230178167","rc":[{"atb":[[13,0]],"id":52385900},{"atb":[[9.8,0]],"id":52385886},{"atb":[[11.5,0]],"id":52385921}],"con":true,"img":false}]}
{"op":"mcm","clk":"11550197748","pt":1719495508654,"mc":[{"id":"1.230178167","rc":[{"atl":[[48,0]],"id":52385918},{"atl":[[36,0]],"id":52385889},{"atb":[[11,0]],"id":52385883},{"atb":[[14.5,1.38]],"id":52385900},{"atb":[[9.4,1.4]],"id":52385886},{"atb":[[22,1.36]],"id":52385921},{"atl":[[34,0]],"id":52385897}],"con":true,"img":false}]}
{"op":"mcm","clk":"11550197756","pt":1719495508758,"mc":[{"id":"1.230178167","rc":[{"atl":[[50,12.24],[110,5],[510,2]],"id":52385918},{"atl":[[38,16.22],[420,2],[110,5]],"id":52385889},{"atb":[[10,15]],"id":52385883},{"atl":[[36,17.14]],"id":52385897}],"con":true,"img":false}]}
{"op":"mcm","clk":"11550197769","pt":1719495508916,"mc":[{"id":"1.230178167","rc":[{"atl":[[980,0]],"id":52385892},{"atl":[[36,0]],"id":52385897}],"con":true,"img":false}]}
{"op":"mcm","clk":"11550197780","pt":1719495509020,"mc":[{"id":"1.230178167","rc":[{"atl":[[100,1.91]],"id":52385892},{"atl":[[70,8.7]],"id":52385897}],"con":true,"img":false}]}
{"op":"mcm","clk":"11550197826","pt":1719495509642,"mc":[{"id":"1.230178167","rc":[{"atl":[[1000,0]],"id":52385897}],"con":true,"img":false}]}
{"op":"mcm","clk":"11550197835","pt":1719495509745,"mc":[{"id":"1.230178167","rc":[{"atl":[[65,1.23]],"id":52385897}],"con":true,"img":false}]}
{"op":"mcm","clk":"11550197984","pt":1719495511662,"mc":[{"id":"1.230178167","rc":[{"atb":[[9,0]],"id":52385886}],"con":true,"img":false}]}
{"op":"mcm","clk":"11550197999","pt":1719495511773,"mc":[{"id":"1.230178167","rc":[{"atb":[[10,9]],"id":52385886}],"con":true,"img":false}]}
{"op":"mcm","clk":"11550198033","pt":1719495512137,"mc":[{"id":"1.230178167","rc":[{"atb":[[9.4,0]],"id":52385886}],"con":true,"img":false}]}
{"op":"mcm","clk":"11550198047","pt":1719495512238,"mc":[{"id":"1.230178167","rc":[{"atb":[[10.5,1.4]],"id":52385886}],"con":true,"img":false}]}
{"op":"mcm","clk":"11550198238","pt":1719495514535,"mc":[{"id":"1.230178167","rc":[{"atb":[[42,0]],"id":52385913}],"con":true,"img":false}]}
{"op":"mcm","clk":"11550198261","pt":1719495514845,"mc":[{"id":"1.230178167","rc":[{"atl":[[370,2],[430,0]],"id":52385912},{"atl":[[350,2],[400,0]],"id":52385911}],"con":true,"img":false}]}
{"op":"mcm","clk":"11550198285","pt":1719495515154,"mc":[{"id":"1.230178167","rc":[{"atb":[[46,0]],"id":52385913}],"con":true,"img":false}]}
{"op":"mcm","clk":"11550198294","pt":1719495515259,"mc":[{"id":"1.230178167","rc":[{"atb":[[23,0],[9.4,14.4]],"id":52385913}],"con":true,"img":false}]}
{"op":"mcm","clk":"11550198316","pt":1719495515568,"mc":[{"id":"1.230178167","rc":[{"atb":[[24,0]],"id":52385912},{"atl":[[110,7],[510,0]],"id":52385918},{"atl":[[420,0],[110,7]],"id":52385889}],"con":true,"img":false}]}
{"op":"mcm","clk":"11550198347","pt":1719495515883,"mc":[{"id":"1.230178167","rc":[{"atb":[[44,0]],"id":52385913}],"con":true,"img":false}]}
{"op":"mcm","clk":"11550198363","pt":1719495516038,"mc":[{"id":"1.230178167","rc":[{"atb":[[42,14.63]],"id":52385913}],"con":true,"img":false}]}
{"op":"mcm","clk":"11550198383","pt":1719495516253,"mc":[{"id":"1.230178167","rc":[{"atb":[[42,0]],"id":52385913},{"atb":[[10.5,24.4]],"id":52385886}],"con":true,"img":false}]}
{"op":"mcm","clk":"11550198391","pt":1719495516348,"mc":[{"id":"1.230178167","rc":[{"atb":[[26,0]],"id":52385912},{"atb":[[24,16.7]],"id":52385913}],"con":true,"img":false}]}
{"op":"mcm","clk":"11550198399","pt":1719495516451,"mc":[{"id":"1.230178167","rc":[{"atb":[[16,0],[6.4,21.02]],"id":52385912},{"atb":[[9.2,0]],"id":52385886}],"con":true,"img":false}]}
{"op":"mcm","clk":"11550198411","pt":1719495516554,"mc":[{"id":"1.230178167","rc":[{"atb":[[13,0]],"id":52385897}],"con":true,"img":false}]}
{"op":"mcm","clk":"11550198427","pt":1719495516760,"mc":[{"id":"1.230178167","rc":[{"atb":[[24,0]],"id":52385905}],"con":true,"img":false}]}
{"op":"mcm","clk":"11550198447","pt":1719495516969,"mc":[{"id":"1.230178167","rc":[{"atb":[[25,0]],"id":52385912},{"atb":[[24,20.7]],"id":52385913},{"atb":[[16,0]],"id":52385897}],"con":true,"img":false}]}
{"op":"mcm","clk":"11550198455","pt":1719495517026,"mc":[{"id":"1.230178167","rc":[{"atb":[[6.2,19.23],[24,18.64]],"id":52385912}],"con":true,"img":false}]}
{"op":"mcm","clk":"11550198465","pt":1719495517125,"mc":[{"id":"1.230178167","rc":[{"atb":[[6.4,2.5]],"id":52385912}],"con":true,"img":false}]}
{"op":"mcm","clk":"11550198474","pt":1719495517227,"mc":[{"id":"1.230178167","rc":[{"atb":[[24,0],[25,25]],"id":52385912}],"con":true,"img":false}]}
{"op":"mcm","clk":"11550198500","pt":1719495517539,"mc":[{"id":"1.230178167","rc":[{"atb":[[27,0]],"id":52385905}],"con":true,"img":false}]}
{"op":"mcm","clk":"11550198506","pt":1719495517642,"mc":[{"id":"1.230178167","rc":[{"atb":[[14,0]],"id":52385900}],"con":true,"img":false}]}
{"op":"mcm","clk":"11550198548","pt":1719495518164,"mc":[{"id":"1.230178167","rc":[{"atb":[[14.5,0]],"id":52385900}],"con":true,"img":false}]}
{"op":"mcm","clk":"11550198568","pt":1719495518266,"mc":[{"id":"1.230178167","rc":[{"atb":[[13,1.38]],"id":52385900}],"con":true,"img":false}]}
{"op":"mcm","clk":"11550198583","pt":1719495518367,"mc":[{"id":"1.230178167","rc":[{"atb":[[12.5,0]],"id":52385900}],"con":true,"img":false}]}
{"op":"mcm","clk":"11550198595","pt":1719495518473,"mc":[{"id":"1.230178167","rc":[{"atb":[[13.5,15]],"id":52385900}],"con":true,"img":false}]}
{"op":"mcm","clk":"11550198778","pt":1719495520456,"mc":[{"id":"1.230178167","rc":[{"atb":[[12,15]],"id":52385883}],"con":true,"img":false}]}
{"op":"mcm","clk":"11550198796","pt":1719495520662,"mc":[{"id":"1.230178167","rc":[{"atb":[[10,0]],"id":52385883}],"con":true,"img":false}]}
{"op":"mcm","clk":"11550198881","pt":1719495521755,"mc":[{"id":"1.230178167","rc":[{"atb":[[18.5,15]],"id":52385910},{"atl":[[55,11.11]],"id":52385910},{"atb":[[32,15]],"id":52385906},{"atl":[[95,7.69]],"id":52385906},{"atl":[[42,14.63]],"id":52385918},{"atl":[[60,10.17]],"id":52385920},{"atl":[[29,21.43]],"id":52385889},{"atb":[[23,19.28]],"id":52385914},{"atl":[[75,8.11]],"id":52385914},{"atl":[[40,15]],"id":52385883},{"atb":[[17.5,17]],"id":52385885},{"atl":[[40,15.38]],"id":52385885},{"atl":[[19,19]],"id":52385896},{"atb":[[24,10]],"id":52385890},{"atl":[[80,7.59]],"id":52385890},{"atb":[[30,20.69]],"id":52385892},{"atl":[[95,12.73]],"id":52385892},{"atl":[[90,6.74]],"id":52385904},{"atb":[[25,15]],"id":52385898},{"atl":[[55,11.11]],"id":52385898},{"atl":[[40,15]],"id":52385900},{"atb":[[25,19.3]],"id":52385911},{"atl":[[70,8.7]],"id":52385907},{"atl":[[18.5,23]],"id":52385886},{"atl":[[42,14.63]],"id":52385919},{"atb":[[23,17]],"id":52385921},{"atl":[[55,11.11]],"id":52385921},{"atl":[[21,30]],"id":52385882},{"atb":[[18.5,22]],"id":52385884},{"atl":[[24,19]],"id":52385917},{"atl":[[60,10.17]],"id":52385897},{"atb":[[32,15]],"id":52385891},{"atb":[[23,16.39]],"id":52385893},{"atl":[[70,8.7]],"id":52385893},{"atl":[[48,12.77]],"id":52385903},{"atb":[[27,15]],"id":52385905},{"atl":[[65,9.38]],"id":52385905},{"atb":[[18.5,19.28]],"id":52385899},{"atl":[[75,8.11]],"id":52385899}],"con":true,"img":false}]}
{"op":"mcm","clk":"11550198891","pt":1719495521858,"mc":[{"id":"1.230178167","rc":[{"atl":[[85,4.5]],"id":52385889},{"atb":[[24,0]],"id":52385898},{"atl":[[65,0]],"id":52385898},{"atb":[[18.5,0]],"id":52385911},{"atl":[[48,2.13]],"id":52385886},{"atl":[[46,0]],"id":52385919},{"atb":[[21,0]],"id":52385921},{"atl":[[25,0]],"id":52385917},{"atb":[[26,0]],"id":52385905}],"con":true,"img":false}]}
{"op":"mcm","clk":"11550198899","pt":1719495521964,"mc":[{"id":"1.230178167","rc":[{"atb":[[12,0]],"id":52385910},{"atl":[[65,0]],"id":52385910},{"atb":[[29,0]],"id":52385906},{"atl":[[100,0]],"id":52385906},{"atl":[[50,0]],"id":52385918},{"atl":[[70,0]],"id":52385920},{"atl":[[38,0],[110,5]],"id":52385889},{"atb":[[21,0]],"id":52385914},{"atl":[[85,0]],"id":52385914},{"atb":[[17,0]],"id":52385885},{"atl":[[50,0]],"id":52385885},{"atl":[[19.5,0]],"id":52385896},{"atb":[[23,0]],"id":52385890},{"atl":[[90,0]],"id":52385890},{"atb":[[29,0]],"id":52385892},{"atl":[[110,0]],"id":52385892},{"atl":[[42,0]],"id":52385900},{"atl":[[80,0]],"id":52385907},{"atl":[[65,0]],"id":52385921},{"atl":[[22,0]],"id":52385882},{"atb":[[17.5,0]],"id":52385884},{"atl":[[70,0]],"id":52385897},{"atb":[[29,0]],"id":52385891},{"atb":[[22,0]],"id":52385893},{"atl":[[85,0]],"id":52385893},{"atl":[[55,0]],"id":52385903},{"atl":[[75,0]],"id":52385905},{"atb":[[14,0]],"id":52385899},{"atl":[[85,0]],"id":52385899}],"con":true,"img":false}]}
{"op":"mcm","clk":"11550198909","pt":1719495522064,"mc":[{"id":"1.230178167","rc":[{"atl":[[44,0]],"id":52385883},{"atl":[[100,0]],"id":52385904},{"atb":[[23,4.55],[9.4,2.5]],"id":52385913}],"con":true,"img":false}]}
{"op":"mcm","clk":"11550198916","pt":1719495522168,"mc":[{"id":"1.230178167","rc":[{"atl":[[95,6.38]],"id":52385906},{"atl":[[100,1.24]],"id":52385892}],"con":true,"img":false}]}
{"op":"mcm","clk":"11550198926","pt":1719495522276,"mc":[{"id":"1.230178167","rc":[{"atl":[[60,0]],"id":52385910},{"atl":[[80,0]],"id":52385914},{"atl":[[42,0]],"id":52385883},{"atl":[[85,0]],"id":52385890},{"atl":[[90,0.66],[100,0]],"id":52385892},{"atl":[[95,0]],"id":52385904},{"atl":[[75,0]],"id":52385907},{"atl":[[60,0]],"id":52385921},{"atl":[[65,0]],"id":52385897},{"atl":[[80,0]],"id":52385893},{"atl":[[80,0]],"id":52385899}],"con":true,"img":false}]}
{"op":"mcm","clk":"11550198933","pt":1719495522386,"mc":[{"id":"1.230178167","rc":[{"atb":[[13,0]],"id":52385910},{"atl":[[50,1.22]],"id":52385910},{"atl":[[95,0]],"id":52385906},{"atb":[[22,0]],"id":52385914},{"atl":[[70,1.31]],"id":52385914},{"atl":[[38,1.35]],"id":52385883},{"atl":[[75,1.28]],"id":52385890},{"atl":[[90,1.91]],"id":52385892},{"atl":[[85,1.35]],"id":52385904},{"atb":[[25,1.43]],"id":52385913},{"atl":[[65,1.2]],"id":52385907},{"atl":[[50,1.25]],"id":52385921},{"atl":[[55,1.23]],"id":52385897},{"atb":[[30,0]],"id":52385891},{"atl":[[65,1.31]],"id":52385893},{"atb":[[14.5,0]],"id":52385899},{"atl":[[70,1.36]],"id":52385899}],"con":true,"img":false}]}
{"op":"mcm","clk":"11550198945","pt":1719495522485,"mc":[{"id":"1.230178167","rc":[{"atb":[[19,1.4]],"id":52385910},{"atl":[[55,0]],"id":52385910},{"atl":[[100,6.06]],"id":52385906},{"atb":[[24,1.37]],"id":52385914},{"atl":[[75,0]],"id":52385914},{"atl":[[40,0]],"id":52385883},{"atl":[[80,0]],"id":52385890},{"atl":[[70,0]],"id":52385907},{"atl":[[55,0]],"id":52385921},{"atl":[[60,0]],"id":52385897},{"atb":[[34,1.51]],"id":52385891},{"atb":[[19,1.44]],"id":52385899},{"atl":[[75,0]],"id":52385899}],"con":true,"img":false}]}
{"op":"mcm","clk":"11550198957","pt":1719495522585,"mc":[{"id":"1.230178167","rc":[{"atl":[[48,12.77]],"id":52385910},{"atb":[[11,4]],"id":52385912},{"atl":[[70,2.18]],"id":52385912},{"atb":[[21,2.9]],"id":52385918},{"atl":[[75,2]],"id":52385918},{"atb":[[21,2.9]],"id":52385920},{"atl":[[55,3]],"id":52385920},{"atb":[[12.5,4]],"id":52385889},{"atl":[[60,3]],"id":52385889},{"atb":[[23,0]],"id":52385914},{"atl":[[65,9.38]],"id":52385914},{"atb":[[12.5,4.3]],"id":52385883},{"atl":[[34,2],[36,15]],"id":52385883},{"atb":[[9.2,4.8]],"id":52385896},{"atl":[[28,3.5]],"id":52385896},{"atb":[[18.5,3.9]],"id":52385890},{"atl":[[65,2],[70,8.7]],"id":52385890},{"atb":[[32,3]],"id":52385904},{"atl":[[85,3.35]],"id":52385904},{"atb":[[16.5,4.56]],"id":52385898},{"atl":[[48,3]],"id":52385898},{"atb":[[14,4.4]],"id":52385900},{"atl":[[38,3]],"id":52385900},{"atb":[[26,15.8]],"id":52385913},{"atb":[[25,3.8]],"id":52385907},{"atl":[[65,3.2],[60,10]],"id":52385907},{"atb":[[11,4]],"id":52385886},{"atl":[[40,2.7]],"id":52385919},{"atl":[[50,13.49]],"id":52385921},{"atb":[[10,6]],"id":52385882},{"atb":[[19,4.5]],"id":52385884},{"atl":[[55,2]],"id":52385884},{"atb":[[11.5,4.5]],"id":52385917},{"atl":[[42,2.5]],"id":52385917},{"atb":[[16,3.3]],"id":52385897},{"atl":[[50,14.74]],"id":52385897},{"atb":[[32,0],[34,4.71]],"id":52385891},{"atl":[[100,2]],"id":52385891},{"atb":[[24,3.2]],"id":52385893},{"atb":[[9.6,5]],"id":52385903},{"atl":[[46,2.67]],"id":52385903},{"atb":[[16,3.65]],"id":52385905},{"atl":[[60,2.71]],"id":52385905},{"atb":[[16,4.3]],"id":52385899},{"atl":[[65,9.38],[50,2]],"id":52385899}],"con":true,"img":false}]}
{"op":"mcm","clk":"11550198966","pt":1719495522692,"mc":[{"id":"1.230178167","rc":[{"atb":[[19.5,15]],"id":52385910},{"atb":[[25,0]],"id":52385912},{"atb":[[21,20.7]],"id":52385918},{"atb":[[12.5,29]],"id":52385889},{"atb":[[25,15]],"id":52385914},{"atb":[[25,17.8]],"id":52385907},{"atb":[[10,40]],"id":52385882},{"atb":[[16.5,11.6]],"id":52385897},{"atb":[[36,15]],"id":52385891}],"con":true,"img":false}]}
{"op":"mcm","clk":"11550198977","pt":1719495522748,"mc":[{"id":"1.230178167","rc":[{"atl":[[50,0]],"id":52385910},{"atl":[[70,2.33]],"id":52385912},{"atl":[[95,1.31]],"id":52385906},{"atl":[[70,0]],"id":52385914},{"atl":[[38,0]],"id":52385883},{"atb":[[9.2,21.4]],"id":52385896},{"atl":[[42,2.44],[60,5]],"id":52385896},{"atl":[[75,0]],"id":52385890},{"atb":[[32,15.7]],"id":52385904},{"atl":[[85,2]],"id":52385904},{"atb":[[14.5,14.8]],"id":52385900},{"atb":[[24,4]],"id":52385913},{"atl":[[65,2]],"id":52385907},{"atb":[[11,30]],"id":52385886},{"atb":[[11.5,18.5]],"id":52385917},{"atl":[[75,5],[46,2.22]],"id":52385917},{"atl":[[55,0]],"id":52385897},{"atl":[[95,6.38]],"id":52385891},{"atl":[[70,0]],"id":52385899}],"con":true,"img":false}]}
{"op":"mcm","clk":"11550198987","pt":1719495522852,"mc":[{"id":"1.230178167","rc":[{"atb":[[18.5,0],[19,0]],"id":52385910},{"atl":[[46,1.22]],"id":52385910},{"atb":[[6.4,3.99],[23,13]],"id":52385912},{"atb":[[20,0]],"id":52385918},{"atb":[[12,0]],"id":52385889},{"atb":[[24,0]],"id":52385914},{"atl":[[60,1.31]],"id":52385914},{"atl":[[34,3.35]],"id":52385883},{"atb":[[4.8,0],[6.4,0],[5.3,23.26]],"id":52385896},{"atb":[[10.5,10.53]],"id":52385890},{"atl":[[65,3.28]],"id":52385890},{"atb":[[25,0]],"id":52385913},{"atl":[[440,2],[490,0]],"id":52385913},{"atb":[[19,0],[24,5]],"id":52385907},{"atl":[[55,1.2]],"id":52385907},{"atb":[[1.19,0.27],[9.8,0]],"id":52385882},{"atl":[[34,0]],"id":52385884},{"atb":[[17,1.36],[15.5,0]],"id":52385897},{"atl":[[48,1.23]],"id":52385897},{"atb":[[34,3.2]],"id":52385891},{"atl":[[60,1.36]],"id":52385899}],"con":true,"img":false}]}
{"op":"mcm","clk":"11550198999","pt":1719495522953,"mc":[{"id":"1.230178167","rc":[{"atb":[[20,1.4]],"id":52385910},{"atl":[[48,0]],"id":52385910},{"atl":[[140,0]],"id":52385912},{"atb":[[22,1.54]],"id":52385918},{"atb":[[13,1.43]],"id":52385889},{"atb":[[26,1.37]],"id":52385914},{"atl":[[65,0]],"id":52385914},{"atl":[[40,0]],"id":52385885},{"atb":[[9,11],[9.2,22.82]],"id":52385896},{"atb":[[9.2,0]],"id":52385890},{"atb":[[30,0]],"id":52385904},{"atb":[[13.5,0]],"id":52385900},{"atb":[[27,1.43]],"id":52385913},{"atb":[[26,1.38]],"id":52385907},{"atb":[[10.5,1.4]],"id":52385886},{"atb":[[10.5,1.43]],"id":52385882},{"atl":[[50,12.24]],"id":52385884},{"atb":[[11,8]],"id":52385917},{"atb":[[38,1.51]],"id":52385891},{"atl":[[110,0]],"id":52385891}],"con":true,"img":false}]}
{"op":"mcm","clk":"11550199012","pt":1719495523062,"mc":[{"id":"1.230178167","rc":[{"atb":[[19.5,0]],"id":52385910},{"atl":[[44,13.95]],"id":52385910},{"atb":[[23,0]],"id":52385912},{"atb":[[25,0]],"id":52385914},{"atl":[[42,14.63]],"id":52385885},{"atb":[[26,0]],"id":52385913}],"con":true,"img":false}]}
{"op":"mcm","clk":"11550199016","pt":1719495523160,"mc":[{"id":"1.230178167","rc":[{"atb":[[21,15]],"id":52385910},{"atb":[[13.5,15.98]],"id":52385912},{"atb":[[27,15]],"id":52385914},{"atb":[[28,14.7]],"id":52385913}],"con":true,"img":false}]}
{"op":"mcm","clk":"11550199029","pt":1719495523264,"mc":[{"id":"1.230178167","rc":[{"atb":[[12.5,19.6]],"id":52385883},{"atl":[[42,0]],"id":52385885}],"con":true,"img":false}]}
{"op":"mcm","clk":"11550199040","pt":1719495523368,"mc":[{"id":"1.230178167","rc":[{"atl":[[60,0]],"id":52385914},{"atb":[[12,0]],"id":52385883},{"atl":[[46,13.33],[48,0]],"id":52385885},{"atl":[[170,3.55]],"id":52385913},{"atl":[[1000,0]],"id":52385884},{"atl":[[46,11.6]],"id":52385897}],"con":true,"img":false}]}
{"op":"mcm","clk":"11550199049","pt":1719495523470,"mc":[{"id":"1.230178167","rc":[{"atb":[[20,0]],"id":52385910},{"atb":[[6.4,2.5]],"id":52385912},{"atl":[[65,9.38]],"id":52385914},{"atb":[[13,1.38]],"id":52385883},{"atl":[[40,1.31]],"id":52385885},{"atb":[[13,0]],"id":52385900},{"atb":[[27,0]],"id":52385913},{"atl":[[180,0]],"id":52385913},{"atb":[[10.5,0]],"id":52385886},{"atb":[[10.5,0]],"id":52385882},{"atl":[[48,1.24]],"id":52385884},{"atb":[[1.19,0.26]],"id":52385917}],"con":true,"img":false}]}
{"op":"mcm","clk":"11550199054","pt":1719495523574,"mc":[{"id":"1.230178167","rc":[{"atb":[[21,0],[22,1.4]],"id":52385910},{"atb":[[14,1.49]],"id":52385912},{"atl":[[200,2],[240,0]],"id":52385914},{"atl":[[40,16.69],[46,0]],"id":52385885},{"atb":[[15,1.38]],"id":52385900},{"atb":[[29,1.43]],"id":52385913},{"atb":[[11.5,1.4]],"id":52385886},{"atb":[[15,0]],"id":52385884},{"atb":[[12,1.39]],"id":52385917},{"atl":[[50,2.5]],"id":52385897}],"con":true,"img":false}]}
{"op":"mcm","clk":"11550199070","pt":1719495523679,"mc":[{"id":"1.230178167","rc":[{"atb":[[22,9.22]],"id":52385910},{"atl":[[65,0]],"id":52385914},{"atb":[[28,0],[30,15.1]],"id":52385913}],"con":true,"img":false}]}
{"op":"mcm","clk":"11550199079","pt":1719495523781,"mc":[{"id":"1.230178167","rc":[{"atb":[[20,0]],"id":52385920}],"con":true,"img":false}]}
{"op":"mcm","clk":"11550199086","pt":1719495523849,"mc":[{"id":"1.230178167","rc":[{"atb":[[14,5.49],[6.2,0]],"id":52385912},{"atl":[[80,7.59]],"id":52385914}],"con":true,"img":false}]}
{"op":"mcm","clk":"11550199097","pt":1719495523951,"mc":[{"id":"1.230178167","rc":[{"atb":[[20,5]],"id":52385912},{"atl":[[40,15.38]],"id":52385885},{"atl":[[48,0]],"id":52385897}],"con":true,"img":false}]}
{"op":"mcm","clk":"11550199107","pt":1719495524046,"mc":[{"id":"1.230178167","rc":[{"atl":[[80,0]],"id":52385914},{"atl":[[44,1.23]],"id":52385897}],"con":true,"img":false}]}
{"op":"mcm","clk":"11550199117","pt":1719495524150,"mc":[{"id":"1.230178167","rc":[{"atb":[[22,7.82]],"id":52385910},{"atl":[[85,7.14]],"id":52385914},{"atb":[[13,0]],"id":52385883},{"atl":[[40,0]],"id":52385885},{"atb":[[11,0]],"id":52385917},{"atl":[[46,0]],"id":52385897}],"con":true,"img":false}]}
{"op":"mcm","clk":"11550199123","pt":1719495524256,"mc":[{"id":"1.230178167","rc":[{"atl":[[48,12.77]],"id":52385885},{"atb":[[12,9.39]],"id":52385917},{"atl":[[42,11.6]],"id":52385897}],"con":true,"img":false}]}
{"op":"mcm","clk":"11550199137","pt":1719495524354,"mc":[{"id":"1.230178167","rc":[{"atb":[[22,0]],"id":52385910}],"con":true,"img":false}]}
{"op":"mcm","clk":"11550199141","pt":1719495524457,"mc":[{"id":"1.230178167","rc":[{"atb":[[21,25.64]],"id":52385910},{"atl":[[120,5.04]],"id":52385911}],"con":true,"img":false}]}
{"op":"mcm","clk":"11550199153","pt":1719495524572,"mc":[{"id":"1.230178167","rc":[{"atl":[[80,1.31]],"id":52385914},{"atl":[[46,1.31]],"id":52385885},{"atl":[[44,0]],"id":52385897}],"con":true,"img":false}]}
{"op":"mcm","clk":"11550199166","pt":1719495524667,"mc":[{"id":"1.230178167","rc":[{"atb":[[21,0],[22,1.4]],"id":52385910},{"atl":[[130,0]],"id":52385911},{"atl":[[40,1.23],[42,0]],"id":52385897}],"con":true,"img":false}]}
{"op":"mcm","clk":"11550199178","pt":1719495524770,"mc":[{"id":"1.230178167","rc":[{"atb":[[22,9.22]],"id":52385910},{"atl":[[38,7.72]],"id":52385897}],"con":true,"img":false}]}
{"op":"mcm","clk":"11550199230","pt":1719495525306,"mc":[{"id":"1.230178167","rc":[{"atb":[[22,7.82]],"id":52385910}],"con":true,"img":false}]}
{"op":"mcm","clk":"11550199256","pt":1719495525572,"mc":[{"id":"1.230178167","rc":[{"atb":[[22,0]],"id":52385910}],"con":true,"img":false}]}
{"op":"mcm","clk":"11550199266","pt":1719495525673,"mc":[{"id":"1.230178167","rc":[{"atb":[[18.5,25.64]],"id":52385910}],"con":true,"img":false}]}
{"op":"mcm","clk":"11550199374","pt":1719495526975,"mc":[{"id":"1.230178167","rc":[{"atb":[[9.2,0],[18.5,0],[6.2,19.23]],"id":52385910},{"atl":[[160,0],[90,7]],"id":52385910},{"atb":[[14,1.49]],"id":52385912},{"atl":[[370,0],[200,2]],"id":52385912},{"atb":[[8,0],[4.1,32.26]],"id":52385918},{"atb":[[12,9.09],[9.8,0]],"id":52385920},{"atl":[[260,2],[75,0],[150,0],[95,0]],"id":52385920},{"atb":[[5.8,0],[5.2,23.81]],"id":52385889},{"atb":[[11,0],[8.2,13.89],[27,0]],"id":52385914},{"atb":[[5.2,23.81],[5.9,0]],"id":52385883},{"atb":[[7.2,12],[8.4,0]],"id":52385885},{"atl":[[150,0],[110,2]],"id":52385885},{"atb":[[14,0]],"id":52385892},{"atl":[[260,2],[380,0]],"id":52385892},{"atb":[[10,0]],"id":52385904},{"atl":[[270,2],[170,0]],"id":52385904},{"atb":[[10,0],[7.6,15.15]],"id":52385898},{"atb":[[10,11.11],[14.5,0]],"id":52385911},{"atl":[[350,0],[190,2]],"id":52385911},{"atb":[[23,0]],"id":52385913},{"atl":[[340,2],[440,0]],"id":52385913},{"atb":[[11,7.5],[8.6,0]],"id":52385907},{"atl":[[130,0],[210,2]],"id":52385907},{"atb":[[3.25,44.44],[5.4,0]],"id":52385886},{"atl":[[18.5,0]],"id":52385886},{"atb":[[8.4,0],[5,25]],"id":52385919},{"atl":[[150,2],[190,0]],"id":52385921},{"atb":[[4.6,27.78],[5.5,0]],"id":52385882},{"atb":[[7.4,0],[3.5,40]],"id":52385884},{"atb":[[5.1,0],[2.66,60.24]],"id":52385917},{"atb":[[10.5,0],[6,10.2]],"id":52385891},{"atl":[[290,0],[350,2]],"id":52385891},{"atb":[[6.4,10],[8.4,0]],"id":52385893},{"atb":[[20,21.34],[6.2,0],[1.78,100]],"id":52385903},{"atl":[[85,0],[120,2]],"id":52385903},{"atb":[[2.06,94.34],[10.5,0]],"id":52385905},{"atl":[[280,2],[190,0]],"id":52385905},{"atl":[[150,2],[240,0]],"id":52385899}],"con":true,"img":false}]}
{"op":"mcm","clk":"11550199427","pt":1719495527079,"mc":[{"id":"1.230178167","rc":[{"atb":[[10,10.49]],"id":52385912},{"atl":[[85,2.5],[110,5]],"id":52385920},{"atb":[[24,0]],"id":52385890},{"atb":[[11.5,9.52]],"id":52385892},{"atb":[[12,9.09]],"id":52385904},{"atb":[[12.5,8]],"id":52385913},{"atl":[[65,2],[44,13.95],[48,0]],"id":52385886}],"con":true,"img":false}]}
{"op":"mcm","clk":"11550199433","pt":1719495527182,"mc":[{"id":"1.230178167","rc":[{"atb":[[23,14.38]],"id":52385890}],"con":true,"img":false}]}
{"op":"mcm","clk":"11550199450","pt":1719495527287,"mc":[{"id":"1.230178167","rc":[{"atl":[[170,0]],"id":52385913}],"con":true,"img":false}]}
{"op":"mcm","clk":"11550199464","pt":1719495527403,"mc":[{"id":"1.230178167","rc":[{"atb":[[23,0]],"id":52385890},{"atl":[[180,3.35]],"id":52385913}],"con":true,"img":false}]}
{"op":"mcm","clk":"11550199476","pt":1719495527459,"mc":[{"id":"1.230178167","rc":[{"atb":[[21,14.38]],"id":52385890}],"con":true,"img":false}]}
{"op":"mcm","clk":"11550199482","pt":1719495527551,"mc":[{"id":"1.230178167","rc":[{"atl":[[46,0]],"id":52385886},{"atb":[[18,0]],"id":52385899}],"con":true,"img":false}]}
{"op":"mcm","clk":"11550199495","pt":1719495527664,"mc":[{"id":"1.230178167","rc":[{"atl":[[42,1.2]],"id":52385886}],"con":true,"img":false}]}
{"op":"mcm","clk":"11550199501","pt":1719495527767,"mc":[{"id":"1.230178167","rc":[{"atb":[[26,0]],"id":52385914},{"atb":[[19,0]],"id":52385890},{"atb":[[24,0]],"id":52385913}],"con":true,"img":false}]}
{"op":"mcm","clk":"11550199515","pt":1719495527861,"mc":[{"id":"1.230178167","rc":[{"atb":[[22,1.37]],"id":52385890}],"con":true,"img":false}]}
{"op":"mcm","clk":"11550199524","pt":1719495527965,"mc":[{"id":"1.230178167","rc":[{"atb":[[20,27.28]],"id":52385914},{"atb":[[18,0]],"id":52385921}],"con":true,"img":false}]}
{"op":"mcm","clk":"11550199557","pt":1719495528174,"mc":[{"id":"1.230178167","rc":[{"atb":[[18,0]],"id":52385910},{"atb":[[20,19.28]],"id":52385914},{"atb":[[13,0]],"id":52385885},{"atb":[[24,0]],"id":52385911}],"con":true,"img":false}]}
{"op":"mcm","clk":"11550199563","pt":1719495528274,"mc":[{"id":"1.230178167","rc":[{"atb":[[6.4,10],[14,5]],"id":52385910},{"atb":[[16,8]],"id":52385914},{"atb":[[11,6]],"id":52385885},{"atb":[[20,4]],"id":52385911}],"con":true,"img":false}]}
{"op":"mcm","clk":"11550199575","pt":1719495528381,"mc":[{"id":"1.230178167","rc":[{"atb":[[25,0]],"id":52385911}],"con":true,"img":false}]}
{"op":"mcm","clk":"11550199584","pt":1719495528486,"mc":[{"id":"1.230178167","rc":[{"atb":[[24,20.08]],"id":52385911}],"con":true,"img":false}]}
{"op":"mcm","clk":"11550199593","pt":1719495528587,"mc":[{"id":"1.230178167","rc":[{"atl":[[65,2],[85,2.5]],"id":52385889},{"atb":[[7.2,16.13],[6.2,0]],"id":52385900}],"con":true,"img":false}]}
{"op":"mcm","clk":"11550199600","pt":1719495528642,"mc":[{"id":"1.230178167","rc":[{"atb":[[24,0]],"id":52385911}],"con":true,"img":false}]}
{"op":"mcm","clk":"11550199606","pt":1719495528749,"mc":[{"id":"1.230178167","rc":[{"atl":[[310,2],[360,0]],"id":52385906},{"atb":[[21,20.08]],"id":52385911},{"atl":[[21,0]],"id":52385882},{"atb":[[9.2,8.6],[11,0]],"id":52385899}],"con":true,"img":false}]}
{"op":"mcm","clk":"11550199616","pt":1719495528853,"mc":[{"id":"1.230178167","rc":[{"atl":[[22,28.57],[420,2]],"id":52385882}],"con":true,"img":false}]}
{"op":"mcm","clk":"11550199621","pt":1719495528953,"mc":[{"id":"1.230178167","rc":[{"atl":[[85,5]],"id":52385882}],"con":true,"img":false}]}
{"op":"mcm","clk":"11550199687","pt":1719495529684,"mc":[{"id":"1.230178167","rc":[{"atl":[[22,0]],"id":52385882}],"con":true,"img":false}]}
{"op":"mcm","clk":"11550199702","pt":1719495529800,"mc":[{"id":"1.230178167","rc":[{"atl":[[24,26.09]],"id":52385882}],"con":true,"img":false}]}
{"op":"mcm","clk":"11550199721","pt":1719495529950,"mc":[{"id":"1.230178167","rc":[{"atb":[[14,2.5]],"id":52385906}],"con":true,"img":false}]}
{"op":"mcm","clk":"11550199737","pt":1719495530070,"mc":[{"id":"1.230178167","rc":[{"atb":[[12.5,8.7]],"id":52385906},{"atl":[[70,2],[46,0]],"id":52385917}],"con":true,"img":false}]}
{"op":"mcm","clk":"11550199746","pt":1719495530173,"mc":[{"id":"1.230178167","rc":[{"atb":[[6.2,0]],"id":52385910},{"atb":[[10,0],[6,11]],"id":52385912},{"atb":[[8.2,0]],"id":52385914},{"atb":[[11.5,0],[8.6,13.16]],"id":52385892},{"atb":[[10,0]],"id":52385911},{"atb":[[6,12],[12.5,0]],"id":52385913},{"atb":[[8.6,10],[10,0]],"id":52385921},{"atb":[[9.2,0],[7.4,9.3]],"id":52385899}],"con":true,"img":false}]}
{"op":"mcm","clk":"11550199758","pt":1719495530267,"mc":[{"id":"1.230178167","rc":[{"atb":[[6,22]],"id":52385910},{"atb":[[8,14.29]],"id":52385914},{"atl":[[200,0],[120,7]],"id":52385914},{"atb":[[10,11.11]],"id":52385911},{"atb":[[7.4,0],[9.4,6.8]],"id":52385899}],"con":true,"img":false}]}
{"op":"mcm","clk":"11550199788","pt":1719495530673,"mc":[{"id":"1.230178167","rc":[{"atb":[[12,23]],"id":52385886}],"con":true,"img":false}]}
{"op":"mcm","clk":"11550199804","pt":1719495530879,"mc":[{"id":"1.230178167","rc":[{"atb":[[11,4]],"id":52385886}],"con":true,"img":false}]}
{"op":"mcm","clk":"11550199831","pt":1719495531362,"mc":[{"id":"1.230178167","rc":[{"atb":[[11.5,0]],"id":52385886}],"con":true,"img":false}]}
{"op":"mcm","clk":"11550199838","pt":1719495531467,"mc":[{"id":"1.230178167","rc":[{"atb":[[21,15]],"id":52385912},{"atl":[[29,0]],"id":52385889},{"atb":[[12.5,1.4]],"id":52385886}],"con":true,"img":false}]}
{"op":"mcm","clk":"11550199847","pt":1719495531570,"mc":[{"id":"1.230178167","rc":[{"atb":[[13.5,0]],"id":52385912},{"atl":[[65,0],[70,2],[30,20.69]],"id":52385889},{"atb":[[10,0]],"id":52385886}],"con":true,"img":false}]}
{"op":"mcm","clk":"11550199863","pt":1719495531774,"mc":[{"id":"1.230178167","rc":[{"atl":[[24,0]],"id":52385882}],"con":true,"img":false}]}
{"op":"mcm","clk":"11550199872","pt":1719495531875,"mc":[{"id":"1.230178167","rc":[{"atb":[[14,0]],"id":52385912},{"atl":[[30,0]],"id":52385889},{"atl":[[25,25]],"id":52385882}],"con":true,"img":false}]}
{"op":"mcm","clk":"11550199882","pt":1719495531984,"mc":[{"id":"1.230178167","rc":[{"atb":[[22,1.49]],"id":52385912},{"atl":[[34,18.18]],"id":52385889}],"con":true,"img":false}]}
{"op":"mcm","clk":"11550199895","pt":1719495532087,"mc":[{"id":"1.230178167","rc":[{"atb":[[23,15]],"id":52385912}],"con":true,"img":false}]}
{"op":"mcm","clk":"11550199903","pt":1719495532190,"mc":[{"id":"1.230178167","rc":[{"atl":[[34,0]],"id":52385889}],"con":true,"img":false}]}
{"op":"mcm","clk":"11550199910","pt":1719495532293,"mc":[{"id":"1.230178167","rc":[{"atb":[[21,0]],"id":52385912},{"atl":[[48,12.77]],"id":52385889}],"con":true,"img":false}]}
{"op":"mcm","clk":"11550199939","pt":1719495532559,"mc":[{"id":"1.230178167","rc":[{"atb":[[22,0]],"id":52385912}],"con":true,"img":false}]}
{"op":"mcm","clk":"11550199947","pt":1719495532660,"mc":[{"id":"1.230178167","rc":[{"atb":[[20,0],[24,1.49]],"id":52385912}],"con":true,"img":false}]}
{"op":"mcm","clk":"11550199964","pt":1719495532786,"mc":[{"id":"1.230178167","rc":[{"atb":[[23,0],[24,14.49]],"id":52385912}],"con":true,"img":false}]}
{"op":"mcm","clk":"11550199968","pt":1719495532876,"mc":[{"id":"1.230178167","rc":[{"atb":[[18.5,14.8]],"id":52385900}],"con":true,"img":false}]}
{"op":"mcm","clk":"11550199990","pt":1719495533101,"mc":[{"id":"1.230178167","rc":[{"atl":[[1000,0]],"id":52385889},{"atb":[[14.5,0]],"id":52385900}],"con":true,"img":false}]}
{"op":"mcm","clk":"11550200001","pt":1719495533167,"mc":[{"id":"1.230178167","rc":[{"atb":[[6,2]],"id":52385910},{"atb":[[24,13]],"id":52385912},{"atl":[[46,1.22],[48,0]],"id":52385889},{"atb":[[8,0]],"id":52385914},{"atb":[[10,0]],"id":52385911}],"con":true,"img":false}]}
{"op":"mcm","clk":"11550200016","pt":1719495533276,"mc":[{"id":"1.230178167","rc":[{"atb":[[6,17]],"id":52385910},{"atb":[[24,0]],"id":52385912},{"atl":[[55,11.11]],"id":52385889},{"atb":[[7.6,15.15]],"id":52385914},{"atb":[[9.4,11.9]],"id":52385911}],"con":true,"img":false}]}
{"op":"mcm","clk":"11550200028","pt":1719495533374,"mc":[{"id":"1.230178167","rc":[{"atb":[[23,13]],"id":52385912}],"con":true,"img":false}]}
{"op":"mcm","clk":"11550200047","pt":1719495533577,"mc":[{"id":"1.230178167","rc":[{"atb":[[20,5],[23,0]],"id":52385912},{"atl":[[46,0]],"id":52385889}],"con":true,"img":false}]}
{"op":"mcm","clk":"11550200055","pt":1719495533677,"mc":[{"id":"1.230178167","rc":[{"atl":[[70,4.5],[90,5]],"id":52385910},{"atl":[[150,4.5],[200,0]],"id":52385912},{"atb":[[9.6,13.5],[4.1,0]],"id":52385918},{"atb":[[6,22],[5.2,0]],"id":52385889},{"atl":[[50,1.22]],"id":52385889},{"atb":[[6.2,19.23],[5.2,0]],"id":52385883},{"atl":[[260,0],[220,2]],"id":52385892},{"atb":[[11,10],[7.6,0]],"id":52385898},{"atl":[[260,2],[340,0]],"id":52385913},{"atb":[[6,22],[3.25,0]],"id":52385886},{"atb":[[5,0],[9.8,11.36]],"id":52385919},{"atb":[[4.6,0],[5.8,20.83]],"id":52385882},{"atb":[[3.5,0],[9.8,7]],"id":52385884},{"atb":[[6,20.8],[2.66,0]],"id":52385917},{"atb":[[14.5,7.41],[6,2]],"id":52385891},{"atb":[[6.4,0],[10,10]],"id":52385893},{"atb":[[1.78,0],[8.4,13.51]],"id":52385903},{"atb":[[2.06,0],[12,9.09]],"id":52385905}],"con":true,"img":false}]}
{"op":"mcm","clk":"11550200059","pt":1719495533779,"mc":[{"id":"1.230178167","rc":[{"atb":[[21,13]],"id":52385912}],"con":true,"img":false}]}
{"op":"mcm","clk":"11550200099","pt":1719495534266,"mc":[{"id":"1.230178167","rc":[{"atb":[[22,1.49]],"id":52385912},{"atl":[[24,0]],"id":52385917}],"con":true,"img":false}]}
{"op":"mcm","clk":"11550200104","pt":1719495534368,"mc":[{"id":"1.230178167","rc":[{"atl":[[25,23.8]],"id":52385917}],"con":true,"img":false}]}
{"op":"mcm","clk":"11550200130","pt":1719495534562,"mc":[{"id":"1.230178167","rc":[{"atl":[[25,0]],"id":52385917}],"con":true,"img":false}]}
{"op":"mcm","clk":"11550200133","pt":1719495534662,"mc":[{"id":"1.230178167","rc":[{"atl":[[26,23.8]],"id":52385917}],"con":true,"img":false}]}
{"op":"mcm","clk":"11550200143","pt":1719495534776,"mc":[{"id":"1.230178167","rc":[{"atb":[[13.5,16.7]],"id":52385883}],"con":true,"img":false}]}
{"op":"mcm","clk":"11550200151","pt":1719495534976,"mc":[{"id":"1.230178167","rc":[{"atb":[[12.5,4.3]],"id":52385883}],"con":true,"img":false}]}
{"op":"mcm","clk":"11550200200","pt":1719495535497,"mc":[{"id":"1.230178167","rc":[{"atb":[[14,1.38]],"id":52385883},{"atl":[[85,7],[420,0]],"id":52385882}],"con":true,"img":false}]}
{"op":"mcm","clk":"11550200214","pt":1719495535672,"mc":[{"id":"1.230178167","rc":[{"atb":[[6,2]],"id":52385912},{"atl":[[150,2.5],[230,2]],"id":52385912},{"atb":[[8,12]],"id":52385918},{"atl":[[42,0]],"id":52385918},{"atb":[[1.5,100]],"id":52385914},{"atb":[[5,25]],"id":52385885},{"atl":[[36,2.86]],"id":52385896},{"atb":[[10.5,0]],"id":52385890},{"atl":[[360,2]],"id":52385892},{"atb":[[7.4,10]],"id":52385921},{"atb":[[7.4,8.2]],"id":52385891},{"atl":[[280,0],[230,2]],"id":52385905},{"atb":[[9.4,0],[5.1,24.39]],"id":52385899}],"con":true,"img":false}]}
{"op":"mcm","clk":"11550200224","pt":1719495535773,"mc":[{"id":"1.230178167","rc":[{"atb":[[6,2],[1.61,100]],"id":52385910},{"atl":[[70,2.5],[110,2]],"id":52385910},{"atb":[[6,12],[12.5,0]],"id":52385906},{"atl":[[310,0],[250,2]],"id":52385906},{"atb":[[9.6,5]],"id":52385918},{"atl":[[70,8.7]],"id":52385918},{"atb":[[12,0],[14.5,7.41]],"id":52385920},{"atl":[[260,0],[180,2]],"id":52385920},{"atb":[[6,2],[4.7,27.03]],"id":52385889},{"atb":[[7.6,0]],"id":52385914},{"atb":[[13.5,0]],"id":52385883},{"atl":[[65,0],[46,4.72]],"id":52385883},{"atb":[[7.2,0]],"id":52385885},{"atl":[[80,2],[110,0]],"id":52385885},{"atb":[[9.2,6.22]],"id":52385896},{"atl":[[42,0]],"id":52385896},{"atb":[[6.8,8.9]],"id":52385890},{"atl":[[150,2],[180,0]],"id":52385890},{"atb":[[8.6,0]],"id":52385892},{"atl":[[220,0]],"id":52385892},{"atb":[[12,0],[15.5,6.9]],"id":52385904},{"atl":[[270,0],[200,2]],"id":52385904},{"atl":[[140,2],[190,0]],"id":52385898},{"atb":[[18.5,0]],"id":52385900},{"atl":[[65,2],[85,0]],"id":52385900},{"atb":[[9.4,0]],"id":52385911},{"atl":[[270,2],[190,0]],"id":52385911},{"atb":[[6,2]],"id":52385913},{"atl":[[260,0],[370,2]],"id":52385913},{"atl":[[140,2],[210,0]],"id":52385907},{"atb":[[6,2],[7,16.67]],"id":52385886},{"atl":[[65,0],[48,2.13]],"id":52385886},{"atb":[[8.6,0]],"id":52385921},{"atl":[[150,0],[120,2]],"id":52385921},{"atb":[[5.8,0],[6.6,20.36]],"id":52385882},{"atb":[[8.6,9.5],[9.8,0]],"id":52385884},{"atl":[[95,2],[110,0]],"id":52385884},{"atb":[[7.2,16.13],[6,2]],"id":52385917},{"atl":[[70,0],[50,2.04]],"id":52385917},{"atb":[[9.2,12.2],[7,0]],"id":52385897},{"atl":[[75,4.5],[110,0]],"id":52385897},{"atb":[[14.5,0]],"id":52385891},{"atl":[[290,2],[350,0]],"id":52385891},{"atb":[[10,0],[4.5,28.57]],"id":52385893},{"atl":[[130,5],[190,2]],"id":52385893},{"atb":[[8.4,0],[9.4,15]],"id":52385903},{"atl":[[80,2],[120,0]],"id":52385903},{"atb":[[12,0],[14.5,7.41]],"id":52385905},{"atl":[[150,0],[120,7]],"id":52385899}],"con":true,"img":false}]}
{"op":"mcm","clk":"11550200227","pt":1719495535865,"mc":[{"id":"1.230178167","rc":[{"atb":[[15,16.18]],"id":52385900}],"con":true,"img":false}]}
{"op":"mcm","clk":"11550200254","pt":1719495536078,"mc":[{"id":"1.230178167","rc":[{"atb":[[14.5,15]],"id":52385910},{"atl":[[34,15]],"id":52385910},{"atl":[[90,6.74]],"id":52385906},{"atl":[[1000,0]],"id":52385918},{"atl":[[55,10.2]],"id":52385920},{"atl":[[48,12.77]],"id":52385889},{"atl":[[48,12.77]],"id":52385914},{"atl":[[19,15.3]],"id":52385883},{"atl":[[36,17]],"id":52385885},{"atb":[[25,14.38]],"id":52385890},{"atl":[[60,10.17]],"id":52385890},{"atl":[[85,3.75],[90,8.65]],"id":52385892},{"atl":[[80,7.59]],"id":52385904},{"atl":[[48,14.82]],"id":52385898},{"atl":[[28,14.8]],"id":52385900},{"atl":[[55,12.31]],"id":52385907},{"atl":[[23,12.26]],"id":52385886},{"atl":[[40,18.08]],"id":52385919},{"atl":[[24,26.09]],"id":52385882},{"atb":[[19.5,13]],"id":52385884},{"atl":[[25,25]],"id":52385917},{"atl":[[34,11.6]],"id":52385897},{"atb":[[40,11.4]],"id":52385891},{"atb":[[28,16.4]],"id":52385893},{"atl":[[60,10.17]],"id":52385893},{"atl":[[44,13.95]],"id":52385903},{"atl":[[60,12.88]],"id":52385905},{"atb":[[19.5,12.6]],"id":52385899},{"atl":[[44,12.6]],"id":52385899}],"con":true,"img":false}]}
{"op":"mcm","clk":"11550200262","pt":1719495536185,"mc":[{"id":"1.230178167","rc":[{"atl":[[65,1.23]],"id":52385918},{"atb":[[14,0]],"id":52385883}],"con":true,"img":false}]}
{"op":"mcm","clk":"11550200274","pt":1719495536285,"mc":[{"id":"1.230178167","rc":[{"atb":[[6.4,0]],"id":52385910},{"atl":[[34,0],[44,0]],"id":52385910},{"atl":[[100,0]],"id":52385906},{"atl":[[60,0]],"id":52385920},{"atl":[[55,0]],"id":52385889},{"atl":[[85,0],[48,0]],"id":52385914},{"atl":[[36,0]],"id":52385883},{"atl":[[48,0]],"id":52385885},{"atb":[[21,0]],"id":52385890},{"atl":[[70,0]],"id":52385890},{"atl":[[95,0]],"id":52385892},{"atl":[[90,0]],"id":52385904},{"atl":[[55,0]],"id":52385898},{"atl":[[40,0],[28,0]],"id":52385900},{"atl":[[60,0]],"id":52385907},{"atl":[[44,0]],"id":52385886},{"atl":[[42,0]],"id":52385919},{"atl":[[25,0]],"id":52385882},{"atb":[[18.5,0]],"id":52385884},{"atl":[[26,0]],"id":52385917},{"atl":[[34,0],[38,0]],"id":52385897},{"atb":[[36,0]],"id":52385891},{"atb":[[23,1.39]],"id":52385893},{"atl":[[70,0]],"id":52385893},{"atl":[[48,0]],"id":52385903},{"atl":[[65,0]],"id":52385905},{"atb":[[18.5,0]],"id":52385899},{"atl":[[65,0]],"id":52385899}],"con":true,"img":false}]}
{"op":"mcm","clk":"11550200286","pt":1719495536386,"mc":[{"id":"1.230178167","rc":[{"atl":[[60,10.17]],"id":52385918},{"atl":[[75,8.11]],"id":52385914},{"atb":[[12.5,22.9]],"id":52385883},{"atl":[[38,16.22]],"id":52385897}],"con":true,"img":false}]}
{"op":"mcm","clk":"11550200296","pt":1719495536489,"mc":[{"id":"1.230178167","rc":[{"atl":[[44,13.95]],"id":52385910},{"atl":[[36,17.14]],"id":52385900}],"con":true,"img":false}]}
{"op":"mcm","clk":"11550200308","pt":1719495536596,"mc":[{"id":"1.230178167","rc":[{"atl":[[46,0]],"id":52385910},{"atl":[[65,0],[70,0]],"id":52385918},{"atl":[[50,0]],"id":52385889},{"atl":[[80,0]],"id":52385914},{"atl":[[65,2]],"id":52385890},{"atl":[[90,6.74]],"id":52385892},{"atl":[[60,0]],"id":52385898},{"atb":[[20,0]],"id":52385893},{"atl":[[50,0]],"id":52385903},{"atl":[[70,0]],"id":52385905},{"atl":[[60,0]],"id":52385899}],"con":true,"img":false}]}
{"op":"mcm","clk":"11550200317","pt":1719495536697,"mc":[{"id":"1.230178167","rc":[{"atb":[[15,1.4]],"id":52385910},{"atl":[[55,1.23]],"id":52385918},{"atl":[[46,1.22],[48,0]],"id":52385889},{"atl":[[70,1.31]],"id":52385914},{"atl":[[55,1.28]],"id":52385890},{"atl":[[80,0.66]],"id":52385892},{"atl":[[46,1.3]],"id":52385898},{"atb":[[18,0]],"id":52385884},{"atb":[[38,0]],"id":52385891},{"atb":[[23,0]],"id":52385893},{"atl":[[42,1.27]],"id":52385903},{"atl":[[55,1.24]],"id":52385905},{"atl":[[42,1.36]],"id":52385899}],"con":true,"img":false}]}
{"op":"mcm","clk":"11550200327","pt":1719495536781,"mc":[{"id":"1.230178167","rc":[{"atl":[[44,0]],"id":52385910},{"atl":[[50,12.24],[60,0]],"id":52385918},{"atl":[[55,11.11]],"id":52385889},{"atl":[[65,9.38],[75,0]],"id":52385914},{"atb":[[20,1.52]],"id":52385884},{"atb":[[40,0],[42,1.51]],"id":52385891},{"atb":[[29,1.39]],"id":52385893}],"con":true,"img":false}]}
{"op":"mcm","clk":"11550200338","pt":1719495536895,"mc":[{"id":"1.230178167","rc":[{"atl":[[36,17.14]],"id":52385910},{"atl":[[55,12.39]],"id":52385890},{"atl":[[25,0]],"id":52385917},{"atb":[[38,11.4]],"id":52385891},{"atb":[[5.1,0],[7.6,15.15]],"id":52385899},{"atl":[[42,12.05]],"id":52385899}],"con":true,"img":false}]}
{"op":"mcm","clk":"11550200348","pt":1719495536980,"mc":[{"id":"1.230178167","rc":[{"atb":[[15.5,15]],"id":52385910},{"atb":[[26,16]],"id":52385918},{"atb":[[13,23.43]],"id":52385889},{"atb":[[29,15]],"id":52385907},{"atb":[[11,60]],"id":52385882},{"atl":[[27,23.08]],"id":52385917},{"atb":[[18,11.6]],"id":52385897}],"con":true,"img":false}]}
{"op":"mcm","clk":"11550200352","pt":1719495537062,"mc":[{"id":"1.230178167","rc":[{"atl":[[60,10.17]],"id":52385912},{"atl":[[60,0]],"id":52385890},{"atb":[[36,10]],"id":52385904},{"atb":[[13,12.26]],"id":52385886},{"atb":[[12,33.19]],"id":52385917},{"atl":[[44,0]],"id":52385899}],"con":true,"img":false}]}
{"op":"mcm","clk":"11550200365","pt":1719495537172,"mc":[{"id":"1.230178167","rc":[{"atb":[[14.5,0]],"id":52385910},{"atb":[[23,15]],"id":52385912},{"atl":[[70,2.18]],"id":52385912},{"atb":[[21,2.9]],"id":52385918},{"atb":[[12.5,4]],"id":52385889},{"atl":[[46,0]],"id":52385889},{"atl":[[70,0]],"id":52385914},{"atl":[[80,1.91]],"id":52385892},{"atb":[[32,3]],"id":52385904},{"atl":[[1000,0]],"id":52385900},{"atb":[[25,3.8]],"id":52385907},{"atl":[[55,11.11]],"id":52385907},{"atb":[[12,0]],"id":52385886},{"atb":[[10,6]],"id":52385882},{"atb":[[11.5,4.5]],"id":52385917},{"atl":[[27,0]],"id":52385917},{"atb":[[16.5,0]],"id":52385897}],"con":true,"img":false}]}
{"op":"mcm","clk":"11550200373","pt":1719495537275,"mc":[{"id":"1.230178167","rc":[{"atb":[[15,0]],"id":52385910},{"atb":[[21,0]],"id":52385912},{"atb":[[22,0]],"id":52385918},{"atl":[[50,1.22]],"id":52385889},{"atl":[[60,1.31]],"id":52385914},{"atb":[[26,0]],"id":52385904},{"atl":[[34,1.25]],"id":52385900},{"atb":[[26,0]],"id":52385907},{"atb":[[12.5,0]],"id":52385886},{"atb":[[11.5,1.43]],"id":52385882},{"atl":[[46,13]],"id":52385884},{"atl":[[29,21.43]],"id":52385917},{"atb":[[17,0]],"id":52385897},{"atb":[[42,0]],"id":52385891}],"con":true,"img":false}]}
{"op":"mcm","clk":"11550200381","pt":1719495537380,"mc":[{"id":"1.230178167","rc":[{"atb":[[16,1.4]],"id":52385910},{"atb":[[27,1.54]],"id":52385918},{"atb":[[38,1.35]],"id":52385904},{"atb":[[30,1.38]],"id":52385907},{"atl":[[55,0]],"id":52385907},{"atb":[[13.5,1.4]],"id":52385886},{"atl":[[50,0]],"id":52385884},{"atb":[[18.5,1.36]],"id":52385897},{"atb":[[40,1.51]],"id":52385891}],"con":true,"img":false}]}
{"op":"mcm","clk":"11550200387","pt":1719495537480,"mc":[{"id":"1.230178167","rc":[{"atb":[[15.5,0]],"id":52385910},{"atl":[[60,10.17]],"id":52385907}],"con":true,"img":false}]}
{"op":"mcm","clk":"11550200397","pt":1719495537585,"mc":[{"id":"1.230178167","rc":[{"atb":[[16.5,20]],"id":52385910},{"atb":[[24,0]],"id":52385907}],"con":true,"img":false}]}
{"op":"mcm","clk":"11550200408","pt":1719495537686,"mc":[{"id":"1.230178167","rc":[{"atl":[[140,4.32]],"id":52385913}],"con":true,"img":false}]}
{"op":"mcm","clk":"11550200419","pt":1719495537792,"mc":[{"id":"1.230178167","rc":[{"atl":[[55,11.11]],"id":52385914},{"atl":[[80,1.24]],"id":52385892}],"con":true,"img":false}]}
{"op":"mcm","clk":"11550200430","pt":1719495537896,"mc":[{"id":"1.230178167","rc":[{"atl":[[1000,0]],"id":52385912},{"atb":[[18,0]],"id":52385918},{"atl":[[55,11.11]],"id":52385890},{"atl":[[80,0],[85,4.41]],"id":52385892},{"atl":[[180,0]],"id":52385913},{"atl":[[48,0]],"id":52385884},{"atl":[[42,10.69]],"id":52385899}],"con":true,"img":false}]}
{"op":"mcm","clk":"11550200441","pt":1719495537999,"mc":[{"id":"1.230178167","rc":[{"atb":[[16,0]],"id":52385910},{"atb":[[22,0]],"id":52385912},{"atl":[[55,1.35]],"id":52385912},{"atl":[[65,0]],"id":52385914},{"atl":[[55,0]],"id":52385890},{"atl":[[44,1.24],[46,0]],"id":52385884},{"atl":[[42,0]],"id":52385899}],"con":true,"img":false}]}
{"op":"mcm","clk":"11550200449","pt":1719495538101,"mc":[{"id":"1.230178167","rc":[{"atb":[[16.5,0],[17,1.4]],"id":52385910},{"atb":[[23,0],[24,1.49]],"id":52385912},{"atl":[[60,10.17]],"id":52385890},{"atl":[[48,12.77]],"id":52385884},{"atl":[[44,13.6]],"id":52385899}],"con":true,"img":false}]}
{"op":"mcm","clk":"11550200462","pt":1719495538175,"mc":[{"id":"1.230178167","rc":[{"atb":[[16,20]],"id":52385910},{"atb":[[21,18]],"id":52385912},{"atl":[[70,0],[60,5]],"id":52385889}],"con":true,"img":false}]}
{"op":"mcm","clk":"11550200475","pt":1719495538364,"mc":[{"id":"1.230178167","rc":[{"atl":[[55,1.28]],"id":52385890},{"atl":[[44,0]],"id":52385884},{"atl":[[42,1.36]],"id":52385899}],"con":true,"img":false}]}
{"op":"mcm","clk":"11550200488","pt":1719495538474,"mc":[{"id":"1.230178167","rc":[{"atl":[[46,1.24]],"id":52385884}],"con":true,"img":false}]}
{"op":"mcm","clk":"11550200492","pt":1719495538584,"mc":[{"id":"1.230178167","rc":[{"atb":[[17,0]],"id":52385910},{"atb":[[24,0]],"id":52385912},{"atb":[[8,0]],"id":52385882},{"atl":[[44,13],[48,0]],"id":52385884}],"con":true,"img":false}]}
{"op":"mcm","clk":"11550200504","pt":1719495538682,"mc":[{"id":"1.230178167","rc":[{"atb":[[16.5,1.4],[17.5,20]],"id":52385910},{"atb":[[22,1.49]],"id":52385912},{"atl":[[100,6.06]],"id":52385911}],"con":true,"img":false}]}
{"op":"mcm","clk":"11550200520","pt":1719495538888,"mc":[{"id":"1.230178167","rc":[{"atb":[[14,0],[16,0],[17.5,0]],"id":52385910},{"atb":[[16,0]],"id":52385914},{"atl":[[50,12.24]],"id":52385914},{"atb":[[11,0]],"id":52385885},{"atb":[[20,0]],"id":52385911},{"atl":[[120,0]],"id":52385911}],"con":true,"img":false}]}
{"op":"mcm","clk":"11550200530","pt":1719495538988,"mc":[{"id":"1.230178167","rc":[{"atb":[[17,42.5]],"id":52385910},{"atb":[[19,8]],"id":52385914},{"atb":[[13,6]],"id":52385885},{"atb":[[24,4]],"id":52385911},{"atl":[[1000,0]],"id":52385911},{"atl":[[46,0]],"id":52385884}],"con":true,"img":false}]}
{"op":"mcm","clk":"11550200537","pt":1719495539094,"mc":[{"id":"1.230178167","rc":[{"atl":[[55,0]],"id":52385914},{"atb":[[21,0]],"id":52385911},{"atl":[[95,1.28]],"id":52385911},{"atl":[[42,1.24]],"id":52385884}],"con":true,"img":false}]}
{"op":"mcm","clk":"11550200548","pt":1719495539197,"mc":[{"id":"1.230178167","rc":[{"atb":[[16.5,0]],"id":52385910},{"atb":[[25,18]],"id":52385911},{"atl":[[40,13],[44,0]],"id":52385884}],"con":true,"img":false}]}
{"op":"mcm","clk":"11550200584","pt":1719495539569,"mc":[{"id":"1.230178167","rc":[{"atl":[[95,0]],"id":52385911}],"con":true,"img":false}]}
{"op":"mcm","clk":"11550200597","pt":1719495539677,"mc":[{"id":"1.230178167","rc":[{"atb":[[21,1.37]],"id":52385914}],"con":true,"img":false}]}
{"op":"mcm","clk":"11550200610","pt":1719495539786,"mc":[{"id":"1.230178167","rc":[{"atb":[[22,21]],"id":52385914}],"con":true,"img":false}]}
{"op":"mcm","clk":"11550200623","pt":1719495539976,"mc":[{"id":"1.230178167","rc":[{"atb":[[20,0]],"id":52385914}],"con":true,"img":false}]}
{"op":"mcm","clk":"11550200662","pt":1719495540448,"mc":[{"id":"1.230178167","rc":[{"atb":[[21,0]],"id":52385914}],"con":true,"img":false}]}
{"op":"mcm","clk":"11550200679","pt":1719495540605,"mc":[{"id":"1.230178167","rc":[{"atb":[[22,0],[23,1.37]],"id":52385914},{"atb":[[9.2,25.66]],"id":52385896}],"con":true,"img":false}]}
{"op":"mcm","clk":"11550200683","pt":1719495540653,"mc":[{"id":"1.230178167","rc":[{"atb":[[23,9.11]],"id":52385914}],"con":true,"img":false}]}
{"op":"mcm","clk":"11550200704","pt":1719495540864,"mc":[{"id":"1.230178167","rc":[{"atb":[[1.61,0]],"id":52385910},{"atb":[[9.2,6.22]],"id":52385896},{"atl":[[100,0]],"id":52385911},{"atl":[[140,0]],"id":52385913}],"con":true,"img":false}]}
{"op":"mcm","clk":"11550200715","pt":1719495540972,"mc":[{"id":"1.230178167","rc":[{"atb":[[23,7.74]],"id":52385914},{"atl":[[36,0]],"id":52385885},{"atl":[[110,5.5]],"id":52385911},{"atl":[[150,4.03]],"id":52385913}],"con":true,"img":false}]}
{"op":"mcm","clk":"11550200728","pt":1719495541173,"mc":[{"id":"1.230178167","rc":[{"atb":[[23,0]],"id":52385914},{"atl":[[38,10]],"id":52385885}],"con":true,"img":false}]}
{"op":"mcm","clk":"11550200733","pt":1719495541278,"mc":[{"id":"1.230178167","rc":[{"atb":[[22,20.48]],"id":52385914}],"con":true,"img":false}]}
{"op":"mcm","clk":"11550200748","pt":1719495541486,"mc":[{"id":"1.230178167","rc":[{"atb":[[22,0],[23,1.37]],"id":52385914}],"con":true,"img":false}]}
{"op":"mcm","clk":"11550200760","pt":1719495541589,"mc":[{"id":"1.230178167","rc":[{"atb":[[19.5,21]],"id":52385914},{"atl":[[140,4.32]],"id":52385913}],"con":true,"img":false}]}
{"op":"mcm","clk":"11550200777","pt":1719495541796,"mc":[{"id":"1.230178167","rc":[{"atb":[[21,7.14]],"id":52385914},{"atl":[[150,0]],"id":52385913}],"con":true,"img":false}]}
{"op":"mcm","clk":"11550200799","pt":1719495542058,"mc":[{"id":"1.230178167","rc":[{"atb":[[21,0]],"id":52385914}],"con":true,"img":false}]}
{"op":"mcm","clk":"11550200805","pt":1719495542164,"mc":[{"id":"1.230178167","rc":[{"atb":[[23,0],[24,19.28]],"id":52385914}],"con":true,"img":false}]}
{"op":"mcm","clk":"11550200816","pt":1719495542271,"mc":[{"id":"1.230178167","rc":[{"atb":[[8,0],[11,8.3]],"id":52385918},{"atb":[[22,1.37],[1.74,100],[1.5,0]],"id":52385914},{"atb":[[5,0],[5.9,20.41]],"id":52385885},{"atl":[[36,0],[27,3.85]],"id":52385896},{"atl":[[280,2],[360,0]],"id":52385892},{"atb":[[9,10],[7.4,0]],"id":52385921},{"atb":[[7.4,0],[13,8.2]],"id":52385891},{"atl":[[170,2],[230,0]],"id":52385905}],"con":true,"img":false}]}
{"op":"mcm","clk":"11550200833","pt":1719495542374,"mc":[{"id":"1.230178167","rc":[{"atl":[[90,7],[110,0]],"id":52385910},{"atb":[[8.2,12],[6,2]],"id":52385906},{"atb":[[6.2,19.23]],"id":52385889},{"atb":[[19.5,0],[24,0]],"id":52385914},{"atb":[[10.5,8.9],[6.8,0]],"id":52385890},{"atl":[[270,0],[220,2]],"id":52385911},{"atl":[[300,2],[370,0]],"id":52385913},{"atb":[[10.5,11.5]],"id":52385884},{"atb":[[8,14.29],[4.5,0]],"id":52385893},{"atl":[[140,2]],"id":52385893}],"con":true,"img":false}]}
{"op":"mcm","clk":"11550200837","pt":1719495542479,"mc":[{"id":"1.230178167","rc":[{"atb":[[4.7,0]],"id":52385889},{"atb":[[23,27.27]],"id":52385914},{"atb":[[8.6,0]],"id":52385884},{"atl":[[190,0]],"id":52385893}],"con":true,"img":false}]}
{"op":"mcm","clk":"11550200891","pt":1719495543056,"mc":[{"id":"1.230178167","rc":[{"atl":[[50,0]],"id":52385914}],"con":true,"img":false}]}
{"op":"mcm","clk":"11550200909","pt":1719495543164,"mc":[{"id":"1.230178167","rc":[{"atl":[[55,11.11]],"id":52385914}],"con":true,"img":false}]}
{"op":"mcm","clk":"11550200978","pt":1719495543992,"mc":[{"id":"1.230178167","rc":[{"atl":[[34,11.6]],"id":52385897}],"con":true,"img":false}]}
{"op":"mcm","clk":"11550200986","pt":1719495544094,"mc":[{"id":"1.230178167","rc":[{"atl":[[36,0]],"id":52385910}],"con":true,"img":false}]}
{"op":"mcm","clk":"11550200995","pt":1719495544198,"mc":[{"id":"1.230178167","rc":[{"atl":[[40,15.38]],"id":52385910},{"atl":[[38,0]],"id":52385897}],"con":true,"img":false}]}
{"op":"mcm","clk":"11550201039","pt":1719495544775,"mc":[{"id":"1.230178167","rc":[{"atb":[[13.5,13.66]],"id":52385886}],"con":true,"img":false}]}
{"op":"mcm","clk":"11550201060","pt":1719495544986,"mc":[{"id":"1.230178167","rc":[{"atb":[[13,0]],"id":52385886}],"con":true,"img":false}]}
{"op":"mcm","clk":"11550201074","pt":1719495545191,"mc":[{"id":"1.230178167","rc":[{"atb":[[22,0]],"id":52385914}],"con":true,"img":false}]}
{"op":"mcm","clk":"11550201085","pt":1719495545297,"mc":[{"id":"1.230178167","rc":[{"atb":[[24,1.37]],"id":52385914}],"con":true,"img":false}]}
{"op":"mcm","clk":"11550201090","pt":1719495545399,"mc":[{"id":"1.230178167","rc":[{"atb":[[23,0],[24,22.37]],"id":52385914}],"con":true,"img":false}]}
{"op":"mcm","clk":"11550201101","pt":1719495545456,"mc":[{"id":"1.230178167","rc":[{"atb":[[38,2]],"id":52385913}],"con":true,"img":false}]}
{"op":"mcm","clk":"11550201108","pt":1719495545565,"mc":[{"id":"1.230178167","rc":[{"atb":[[23,14.36]],"id":52385912}],"con":true,"img":false}]}
{"op":"mcm","clk":"11550201121","pt":1719495545672,"mc":[{"id":"1.230178167","rc":[{"atb":[[20,0],[21,0]],"id":52385912},{"atb":[[24,0]],"id":52385906},{"atl":[[48,12.77]],"id":52385889},{"atb":[[24,21]],"id":52385914},{"atb":[[40,13.64]],"id":52385913}],"con":true,"img":false}]}
{"op":"mcm","clk":"11550201125","pt":1719495545775,"mc":[{"id":"1.230178167","rc":[{"atb":[[24,5]],"id":52385912},{"atb":[[38,5],[6.4,10],[8.2,0]],"id":52385906},{"atb":[[1.74,0]],"id":52385914},{"atb":[[12.5,4.29]],"id":52385883},{"atb":[[5,25]],"id":52385885},{"atb":[[7.2,12.5],[9,5]],"id":52385921},{"atb":[[9.2,6.8],[7.6,0]],"id":52385899}],"con":true,"img":false}]}
{"op":"mcm","clk":"11550201141","pt":1719495545875,"mc":[{"id":"1.230178167","rc":[{"atb":[[40,15]],"id":52385906},{"atl":[[55,0]],"id":52385889},{"atb":[[24,0]],"id":52385914},{"atb":[[5.9,0]],"id":52385885},{"atb":[[30,0]],"id":52385913}],"con":true,"img":false}]}
{"op":"mcm","clk":"11550201149","pt":1719495545980,"mc":[{"id":"1.230178167","rc":[{"atb":[[21,21]],"id":52385914}],"con":true,"img":false}]}
{"op":"mcm","clk":"11550201152","pt":1719495546083,"mc":[{"id":"1.230178167","rc":[{"atb":[[32,0]],"id":52385906}],"con":true,"img":false}]}
{"op":"mcm","clk":"11550201164","pt":1719495546195,"mc":[{"id":"1.230178167","rc":[{"atb":[[25,14.36]],"id":52385912},{"atl":[[50,0]],"id":52385889},{"atb":[[21,0]],"id":52385914}],"con":true,"img":false}]}
{"op":"mcm","clk":"11550201174","pt":1719495546292,"mc":[{"id":"1.230178167","rc":[{"atb":[[30,0]],"id":52385906},{"atl":[[46,1.22]],"id":52385889},{"atb":[[19.5,21],[22,1.37]],"id":52385914},{"atb":[[29,0]],"id":52385913}],"con":true,"img":false}]}
{"op":"mcm","clk":"11550201181","pt":1719495546394,"mc":[{"id":"1.230178167","rc":[{"atb":[[23,0]],"id":52385912},{"atb":[[42,1.43]],"id":52385906},{"atl":[[48,0]],"id":52385889},{"atb":[[42,1.43]],"id":52385913}],"con":true,"img":false}]}
{"op":"mcm","clk":"11550201186","pt":1719495546497,"mc":[{"id":"1.230178167","rc":[{"atl":[[44,13.95]],"id":52385889}],"con":true,"img":false}]}
{"op":"mcm","clk":"11550201226","pt":1719495546866,"mc":[{"id":"1.230178167","rc":[{"atl":[[55,0]],"id":52385912},{"atl":[[46,0]],"id":52385889}],"con":true,"img":false}]}
{"op":"mcm","clk":"11550201232","pt":1719495546971,"mc":[{"id":"1.230178167","rc":[{"atb":[[22,0]],"id":52385912},{"atl":[[42,1.22]],"id":52385889},{"atb":[[22,0]],"id":52385914}],"con":true,"img":false}]}
{"op":"mcm","clk":"11550201248","pt":1719495547078,"mc":[{"id":"1.230178167","rc":[{"atb":[[26,1.49]],"id":52385912},{"atl":[[60,0]],"id":52385912},{"atl":[[40,15.38],[44,0]],"id":52385889},{"atb":[[20,1.37]],"id":52385914}],"con":true,"img":false}]}
{"op":"mcm","clk":"11550201259","pt":1719495547180,"mc":[{"id":"1.230178167","rc":[{"atb":[[27,15]],"id":52385912},{"atl":[[70,10.88],[190,7],[230,0]],"id":52385912}],"con":true,"img":false}]}
{"op":"mcm","clk":"11550201282","pt":1719495547492,"mc":[{"id":"1.230178167","rc":[{"atb":[[25,0]],"id":52385912}],"con":true,"img":false}]}
{"op":"mcm","clk":"11550201293","pt":1719495547595,"mc":[{"id":"1.230178167","rc":[{"atb":[[26,0]],"id":52385912}],"con":true,"img":false}]}
{"op":"mcm","clk":"11550201300","pt":1719495547698,"mc":[{"id":"1.230178167","rc":[{"atb":[[28,1.49]],"id":52385912}],"con":true,"img":false}]}
{"op":"mcm","clk":"11550201315","pt":1719495547805,"mc":[{"id":"1.230178167","rc":[{"atb":[[27,0],[29,21.43]],"id":52385912}],"con":true,"img":false}]}
{"op":"mcm","clk":"11550201346","pt":1719495548171,"mc":[{"id":"1.230178167","rc":[{"atb":[[28,0]],"id":52385912}],"con":true,"img":false}]}
{"op":"mcm","clk":"11550201361","pt":1719495548277,"mc":[{"id":"1.230178167","rc":[{"atb":[[30,1.49]],"id":52385912}],"con":true,"img":false}]}
{"op":"mcm","clk":"11550201367","pt":1719495548380,"mc":[{"id":"1.230178167","rc":[{"atb":[[32,19.35],[29,0]],"id":52385912},{"atl":[[28,22.22]],"id":52385917}],"con":true,"img":false}]}
{"op":"mcm","clk":"11550201386","pt":1719495548585,"mc":[{"id":"1.230178167","rc":[{"atl":[[29,0]],"id":52385917}],"con":true,"img":false}]}
{"op":"mcm","clk":"11550201398","pt":1719495548690,"mc":[{"id":"1.230178167","rc":[{"atb":[[10,0]],"id":52385889},{"atb":[[13,0]],"id":52385885},{"atl":[[1000,0]],"id":52385917}],"con":true,"img":false}]}
{"op":"mcm","clk":"11550201410","pt":1719495548821,"mc":[{"id":"1.230178167","rc":[{"atb":[[11,8]],"id":52385889},{"atb":[[16,6]],"id":52385885},{"atl":[[27,1.34]],"id":52385917}],"con":true,"img":false}]}
{"op":"mcm","clk":"11550201416","pt":1719495548864,"mc":[{"id":"1.230178167","rc":[{"atl":[[26,24]],"id":52385917}],"con":true,"img":false}]}
{"op":"mcm","clk":"11550201440","pt":1719495549079,"mc":[{"id":"1.230178167","rc":[{"atl":[[28,0]],"id":52385917}],"con":true,"img":false}]}
{"op":"mcm","clk":"11550201458","pt":1719495549284,"mc":[{"id":"1.230178167","rc":[{"atb":[[18,1.46]],"id":52385885},{"atl":[[27,0]],"id":52385917}],"con":true,"img":false}]}
{"op":"mcm","clk":"11550201462","pt":1719495549394,"mc":[{"id":"1.230178167","rc":[{"atl":[[25,1.34]],"id":52385917}],"con":true,"img":false}]}
{"op":"mcm","clk":"11550201479","pt":1719495549498,"mc":[{"id":"1.230178167","rc":[{"atb":[[18.5,17]],"id":52385885},{"atl":[[25,26.34],[26,0]],"id":52385917}],"con":true,"img":false}]}
