{"op":"mcm","clk":"11536832978","pt":1719431775510,"mc":[{"id":"1.230180127","marketDefinition":{"bspMarket":true,"turnInPlayEnabled":false,"persistenceEnabled":false,"marketBaseRate":5.0,"eventId":"33376437","eventTypeId":"4339","numberOfWinners":2,"bettingType":"ODDS","marketType":"PLACE","marketTime":"2024-06-27T15:44:00.000Z","suspendTime":"2024-06-27T15:44:00.000Z","bspReconciled":false,"complete":true,"inPlay":false,"crossMatching":false,"runnersVoidable":false,"numberOfActiveRunners":6,"betDelay":0,"status":"OPEN","runners":[{"status":"ACTIVE","sortPriority":1,"id":62886137,"name":"1. Walk On Gaffer"},{"status":"ACTIVE","sortPriority":2,"id":49823335,"name":"2. Orange Sydney"},{"status":"ACTIVE","sortPriority":3,"id":66993945,"name":"3. Essjay Alfred"},{"status":"ACTIVE","sortPriority":4,"id":64851267,"name":"4. Pro Cooper"},{"status":"ACTIVE","sortPriority":5,"id":69475504,"name":"5. Golden Wind"},{"status":"ACTIVE","sortPriority":6,"id":61941224,"name":"6. Salacres Sydney"}],"regulators":["MR_INT"],"venue":"Towcester","countryCode":"GB","discountAllowed":false,"timezone":"Europe/London","openDate":"2024-06-27T13:33:00.000Z","version":5994767111,"name":"To Be Placed","eventName":"Towcester 27th Jun"},"rc":[],"con":true,"img":false}]}
{"op":"mcm","clk":"11536833149","pt":1719431777535,"mc":[{"id":"1.230180127","marketDefinition":{"bspMarket":true,"turnInPlayEnabled":false,"persistenceEnabled":false,"marketBaseRate":5.0,"eventId":"33376437","eventTypeId":"4339","numberOfWinners":2,"bettingType":"ODDS","marketType":"PLACE","marketTime":"2024-06-27T15:44:00.000Z","suspendTime":"2024-06-27T15:44:00.000Z","bspReconciled":false,"complete":true,"inPlay":false,"crossMatching":false,"runnersVoidable":false,"numberOfActiveRunners":6,"betDelay":0,"status":"OPEN","runners":[{"status":"ACTIVE","sortPriority":1,"id":62886137,"name":"1. Walk On Gaffer"},{"status":"ACTIVE","sortPriority":2,"id":49823335,"name":"2. Orange Sydney"},{"status":"ACTIVE","sortPriority":3,"id":66993945,"name":"3. Essjay Alfred"},{"status":"ACTIVE","sortPriority":4,"id":64851267,"name":"4. Pro Cooper"},{"status":"ACTIVE","sortPriority":5,"id":69475504,"name":"5. Golden Wind"},{"status":"ACTIVE","sortPriority":6,"id":61941224,"name":"6. Salacres Sydney"}],"regulators":["MR_INT"],"venue":"Towcester","countryCode":"GB","discountAllowed":true,"timezone":"Europe/London","openDate":"2024-06-27T13:33:00.000Z","version":5994767111,"name":"To Be Placed","eventName":"Towcester 27th Jun"},"rc":[],"con":true,"img":false}]}
{"op":"mcm","clk":"11537084014","pt":1719435435824,"mc":[{"id":"1.230180127","rc":[{"atb":[[1.03,17.28]],"id":66993945},{"atl":[[990,0.84]],"id":66993945},{"spn":495.51,"spf":"NaN","id":66993945},{"atb":[[1.01,51.84]],"id":49823335},{"atl":[[1000,0.84]],"id":49823335},{"spn":500.5,"spf":"NaN","id":49823335},{"atb":[[1.01,51.84]],"id":64851267},{"atl":[[990,0.84]],"id":64851267},{"spn":495.5,"spf":"NaN","id":64851267},{"atb":[[1.03,17.28]],"id":62886137},{"atl":[[1000,0.84]],"id":62886137},{"spn":500.51,"spf":"NaN","id":62886137},{"atb":[[1.01,51.84]],"id":61941224},{"atl":[[1000,0.84]],"id":61941224},{"spn":500.5,"spf":"NaN","id":61941224},{"atb":[[1.02,25.92]],"id":69475504},{"atl":[[990,0.84]],"id":69475504},{"spn":495.51,"spf":"NaN","id":69475504}],"con":true,"img":false}]}
{"op":"mcm","clk":"11537233731","pt":1719437882652,"mc":[{"id":"1.230180127","marketDefinition":{"bspMarket":true,"turnInPlayEnabled":false,"persistenceEnabled":false,"marketBaseRate":5.0,"eventId":"33376437","eventTypeId":"4339","numberOfWinners":2,"bettingType":"ODDS","marketType":"PLACE","marketTime":"2024-06-27T15:44:00.000Z","suspendTime":"2024-06-27T15:44:00.000Z","bspReconciled":false,"complete":true,"inPlay":false,"crossMatching":false,"runnersVoidable":false,"numberOfActiveRunners":6,"betDelay":0,"status":"OPEN","runners":[{"status":"ACTIVE","sortPriority":1,"id":62886137,"name":"1. Walk On Gaffer"},{"status":"ACTIVE","sortPriority":2,"id":49823335,"name":"2. Orange Sydney"},{"status":"ACTIVE","sortPriority":3,"id":66993945,"name":"3. Essjay Alfred"},{"status":"ACTIVE","sortPriority":4,"id":64851267,"name":"4. Pro Cooper"},{"status":"ACTIVE","sortPriority":5,"id":69475504,"name":"5. Golden Wind"},{"status":"ACTIVE","sortPriority":6,"id":61941224,"name":"6. Salacres Sydney"}],"regulators":["MR_INT"],"venue":"Towcester","countryCode":"GB","discountAllowed":true,"timezone":"Europe/London","openDate":"2024-06-27T13:33:00.000Z","version":5994767111,"name":"To Be Placed","eventName":"Towcester 27th Jun"},"rc":[{"atb":[[1.03,17.28]],"id":66993945},{"atl":[[990,0.84]],"id":66993945},{"spn":495.51,"spf":"NaN","id":66993945},{"atb":[[1.01,51.85]],"id":49823335},{"atl":[[1000,0.84]],"id":49823335},{"spn":500.5,"spf":"NaN","id":49823335},{"atb":[[1.01,51.85]],"id":64851267},{"atl":[[990,0.84]],"id":64851267},{"spn":495.5,"spf":"NaN","id":64851267},{"atb":[[1.03,17.28]],"id":62886137},{"atl":[[1000,0.84]],"id":62886137},{"spn":500.51,"spf":"NaN","id":62886137},{"atb":[[1.01,51.85]],"id":61941224},{"atl":[[1000,0.84]],"id":61941224},{"spn":500.5,"spf":"NaN","id":61941224},{"atb":[[1.02,25.92]],"id":69475504},{"atl":[[990,0.84]],"id":69475504},{"spn":495.51,"spf":"NaN","id":69475504}],"con":true,"img":true}]}
{"op":"mcm","clk":"11537302601","pt":1719439040244,"mc":[{"id":"1.230180127","rc":[{"atb":[[1.03,17.28]],"id":66993945},{"atl":[[990,0.23]],"id":66993945},{"atb":[[1.01,51.85]],"id":49823335},{"atl":[[1000,0.23]],"id":49823335},{"atb":[[1.01,51.85]],"id":64851267},{"atl":[[990,0.23]],"id":64851267},{"atb":[[1.03,17.28]],"id":62886137},{"atl":[[1000,0.23]],"id":62886137},{"atb":[[1.01,51.85]],"id":61941224},{"atl":[[1000,0.23]],"id":61941224},{"atb":[[1.02,25.92]],"id":69475504},{"atl":[[990,0.23]],"id":69475504}],"con":true,"img":false}]}
{"op":"mcm","clk":"11537574882","pt":1719443282703,"mc":[{"id":"1.230180127","marketDefinition":{"bspMarket":true,"turnInPlayEnabled":false,"persistenceEnabled":false,"marketBaseRate":5.0,"eventId":"33376437","eventTypeId":"4339","numberOfWinners":2,"bettingType":"ODDS","marketType":"PLACE","marketTime":"2024-06-27T15:44:00.000Z","suspendTime":"2024-06-27T15:44:00.000Z","bspReconciled":false,"complete":true,"inPlay":false,"crossMatching":false,"runnersVoidable":false,"numberOfActiveRunners":6,"betDelay":0,"status":"OPEN","runners":[{"status":"ACTIVE","sortPriority":1,"id":62886137,"name":"1. Walk On Gaffer"},{"status":"ACTIVE","sortPriority":2,"id":49823335,"name":"2. Orange Sydney"},{"status":"ACTIVE","sortPriority":3,"id":66993945,"name":"3. Essjay Alfred"},{"status":"ACTIVE","sortPriority":4,"id":64851267,"name":"4. Pro Cooper"},{"status":"ACTIVE","sortPriority":5,"id":69475504,"name":"5. Golden Wind"},{"status":"ACTIVE","sortPriority":6,"id":61941224,"name":"6. Salacres Sydney"}],"regulators":["MR_INT"],"venue":"Towcester","countryCode":"GB","discountAllowed":true,"timezone":"Europe/London","openDate":"2024-06-27T13:33:00.000Z","version":5994767111,"name":"To Be Placed","eventName":"Towcester 27th Jun"},"rc":[{"atb":[[1.03,17.28]],"id":66993945},{"atl":[[990,0.23]],"id":66993945},{"spn":495.51,"spf":"NaN","id":66993945},{"atb":[[1.01,51.85]],"id":49823335},{"atl":[[1000,0.23]],"id":49823335},{"spn":500.5,"spf":"NaN","id":49823335},{"atb":[[1.01,51.85]],"id":64851267},{"atl":[[990,0.23]],"id":64851267},{"spn":495.5,"spf":"NaN","id":64851267},{"atb":[[1.03,17.28]],"id":62886137},{"atl":[[1000,0.23]],"id":62886137},{"spn":500.51,"spf":"NaN","id":62886137},{"atb":[[1.01,51.85]],"id":61941224},{"atl":[[1000,0.23]],"id":61941224},{"spn":500.5,"spf":"NaN","id":61941224},{"atb":[[1.02,25.92]],"id":69475504},{"atl":[[990,0.23]],"id":69475504},{"spn":495.51,"spf":"NaN","id":69475504}],"con":true,"img":true}]}
{"op":"mcm","clk":"11537956502","pt":1719448682744,"mc":[{"id":"1.230180127","marketDefinition":{"bspMarket":true,"turnInPlayEnabled":false,"persistenceEnabled":false,"marketBaseRate":5.0,"eventId":"33376437","eventTypeId":"4339","numberOfWinners":2,"bettingType":"ODDS","marketType":"PLACE","marketTime":"2024-06-27T15:44:00.000Z","suspendTime":"2024-06-27T15:44:00.000Z","bspReconciled":false,"complete":true,"inPlay":false,"crossMatching":false,"runnersVoidable":false,"numberOfActiveRunners":6,"betDelay":0,"status":"OPEN","runners":[{"status":"ACTIVE","sortPriority":1,"id":62886137,"name":"1. Walk On Gaffer"},{"status":"ACTIVE","sortPriority":2,"id":49823335,"name":"2. Orange Sydney"},{"status":"ACTIVE","sortPriority":3,"id":66993945,"name":"3. Essjay Alfred"},{"status":"ACTIVE","sortPriority":4,"id":64851267,"name":"4. Pro Cooper"},{"status":"ACTIVE","sortPriority":5,"id":69475504,"name":"5. Golden Wind"},{"status":"ACTIVE","sortPriority":6,"id":61941224,"name":"6. Salacres Sydney"}],"regulators":["MR_INT"],"venue":"Towcester","countryCode":"GB","discountAllowed":true,"timezone":"Europe/London","openDate":"2024-06-27T13:33:00.000Z","version":5994767111,"name":"To Be Placed","eventName":"Towcester 27th Jun"},"rc":[{"atb":[[1.03,17.28]],"id":66993945},{"atl":[[990,0.23]],"id":66993945},{"spn":495.51,"spf":"NaN","id":66993945},{"atb":[[1.01,51.85]],"id":49823335},{"atl":[[1000,0.23]],"id":49823335},{"spn":500.5,"spf":"NaN","id":49823335},{"atb":[[1.01,51.85]],"id":64851267},{"atl":[[990,0.23]],"id":64851267},{"spn":495.5,"spf":"NaN","id":64851267},{"atb":[[1.03,17.28]],"id":62886137},{"atl":[[1000,0.23]],"id":62886137},{"spn":500.51,"spf":"NaN","id":62886137},{"atb":[[1.01,51.85]],"id":61941224},{"atl":[[1000,0.23]],"id":61941224},{"spn":500.5,"spf":"NaN","id":61941224},{"atb":[[1.02,25.92]],"id":69475504},{"atl":[[990,0.23]],"id":69475504},{"spn":495.51,"spf":"NaN","id":69475504}],"con":true,"img":true}]}
{"op":"mcm","clk":"11538172119","pt":1719454082687,"mc":[{"id":"1.230180127","marketDefinition":{"bspMarket":true,"turnInPlayEnabled":false,"persistenceEnabled":false,"marketBaseRate":5.0,"eventId":"33376437","eventTypeId":"4339","numberOfWinners":2,"bettingType":"ODDS","marketType":"PLACE","marketTime":"2024-06-27T15:44:00.000Z","suspendTime":"2024-06-27T15:44:00.000Z","bspReconciled":false,"complete":true,"inPlay":false,"crossMatching":false,"runnersVoidable":false,"numberOfActiveRunners":6,"betDelay":0,"status":"OPEN","runners":[{"status":"ACTIVE","sortPriority":1,"id":62886137,"name":"1. Walk On Gaffer"},{"status":"ACTIVE","sortPriority":2,"id":49823335,"name":"2. Orange Sydney"},{"status":"ACTIVE","sortPriority":3,"id":66993945,"name":"3. Essjay Alfred"},{"status":"ACTIVE","sortPriority":4,"id":64851267,"name":"4. Pro Cooper"},{"status":"ACTIVE","sortPriority":5,"id":69475504,"name":"5. Golden Wind"},{"status":"ACTIVE","sortPriority":6,"id":61941224,"name":"6. Salacres Sydney"}],"regulators":["MR_INT"],"venue":"Towcester","countryCode":"GB","discountAllowed":true,"timezone":"Europe/London","openDate":"2024-06-27T13:33:00.000Z","version":5994767111,"name":"To Be Placed","eventName":"Towcester 27th Jun"},"rc":[{"atb":[[1.03,17.29]],"id":66993945},{"atl":[[990,0.23]],"id":66993945},{"spn":495.51,"spf":"NaN","id":66993945},{"atb":[[1.01,51.86]],"id":49823335},{"atl":[[1000,0.23]],"id":49823335},{"spn":500.5,"spf":"NaN","id":49823335},{"atb":[[1.01,51.86]],"id":64851267},{"atl":[[990,0.23]],"id":64851267},{"spn":495.5,"spf":"NaN","id":64851267},{"atb":[[1.03,17.29]],"id":62886137},{"atl":[[1000,0.23]],"id":62886137},{"spn":500.51,"spf":"NaN","id":62886137},{"atb":[[1.01,51.86]],"id":61941224},{"atl":[[1000,0.23]],"id":61941224},{"spn":500.5,"spf":"NaN","id":61941224},{"atb":[[1.02,25.93]],"id":69475504},{"atl":[[990,0.23]],"id":69475504},{"spn":495.51,"spf":"NaN","id":69475504}],"con":true,"img":true}]}
{"op":"mcm","clk":"11538369786","pt":1719459482772,"mc":[{"id":"1.230180127","marketDefinition":{"bspMarket":true,"turnInPlayEnabled":false,"persistenceEnabled":false,"marketBaseRate":5.0,"eventId":"33376437","eventTypeId":"4339","numberOfWinners":2,"bettingType":"ODDS","marketType":"PLACE","marketTime":"2024-06-27T15:44:00.000Z","suspendTime":"2024-06-27T15:44:00.000Z","bspReconciled":false,"complete":true,"inPlay":false,"crossMatching":false,"runnersVoidable":false,"numberOfActiveRunners":6,"betDelay":0,"status":"OPEN","runners":[{"status":"ACTIVE","sortPriority":1,"id":62886137,"name":"1. Walk On Gaffer"},{"status":"ACTIVE","sortPriority":2,"id":49823335,"name":"2. Orange Sydney"},{"status":"ACTIVE","sortPriority":3,"id":66993945,"name":"3. Essjay Alfred"},{"status":"ACTIVE","sortPriority":4,"id":64851267,"name":"4. Pro Cooper"},{"status":"ACTIVE","sortPriority":5,"id":69475504,"name":"5. Golden Wind"},{"status":"ACTIVE","sortPriority":6,"id":61941224,"name":"6. Salacres Sydney"}],"regulators":["MR_INT"],"venue":"Towcester","countryCode":"GB","discountAllowed":true,"timezone":"Europe/London","openDate":"2024-06-27T13:33:00.000Z","version":5994767111,"name":"To Be Placed","eventName":"Towcester 27th Jun"},"rc":[{"atb":[[1.03,17.29]],"id":66993945},{"atl":[[990,0.23]],"id":66993945},{"spn":495.51,"spf":"NaN","id":66993945},{"atb":[[1.01,51.87]],"id":49823335},{"atl":[[1000,0.23]],"id":49823335},{"spn":500.5,"spf":"NaN","id":49823335},{"atb":[[1.01,51.87]],"id":64851267},{"atl":[[990,0.23]],"id":64851267},{"spn":495.5,"spf":"NaN","id":64851267},{"atb":[[1.03,17.29]],"id":62886137},{"atl":[[1000,0.23]],"id":62886137},{"spn":500.51,"spf":"NaN","id":62886137},{"atb":[[1.01,51.87]],"id":61941224},{"atl":[[1000,0.23]],"id":61941224},{"spn":500.5,"spf":"NaN","id":61941224},{"atb":[[1.02,25.93]],"id":69475504},{"atl":[[990,0.23]],"id":69475504},{"spn":495.51,"spf":"NaN","id":69475504}],"con":true,"img":true}]}
{"op":"mcm","clk":"11538596916","pt":1719464882716,"mc":[{"id":"1.230180127","marketDefinition":{"bspMarket":true,"turnInPlayEnabled":false,"persistenceEnabled":false,"marketBaseRate":5.0,"eventId":"33376437","eventTypeId":"4339","numberOfWinners":2,"bettingType":"ODDS","marketType":"PLACE","marketTime":"2024-06-27T15:44:00.000Z","suspendTime":"2024-06-27T15:44:00.000Z","bspReconciled":false,"complete":true,"inPlay":false,"crossMatching":false,"runnersVoidable":false,"numberOfActiveRunners":6,"betDelay":0,"status":"OPEN","runners":[{"status":"ACTIVE","sortPriority":1,"id":62886137,"name":"1. Walk On Gaffer"},{"status":"ACTIVE","sortPriority":2,"id":49823335,"name":"2. Orange Sydney"},{"status":"ACTIVE","sortPriority":3,"id":66993945,"name":"3. Essjay Alfred"},{"status":"ACTIVE","sortPriority":4,"id":64851267,"name":"4. Pro Cooper"},{"status":"ACTIVE","sortPriority":5,"id":69475504,"name":"5. Golden Wind"},{"status":"ACTIVE","sortPriority":6,"id":61941224,"name":"6. Salacres Sydney"}],"regulators":["MR_INT"],"venue":"Towcester","countryCode":"GB","discountAllowed":true,"timezone":"Europe/London","openDate":"2024-06-27T13:33:00.000Z","version":5994767111,"name":"To Be Placed","eventName":"Towcester 27th Jun"},"rc":[{"atb":[[1.03,17.29]],"id":66993945},{"atl":[[990,0.23]],"id":66993945},{"spn":495.51,"spf":"NaN","id":66993945},{"atb":[[1.01,51.86]],"id":49823335},{"atl":[[1000,0.23]],"id":49823335},{"spn":500.5,"spf":"NaN","id":49823335},{"atb":[[1.01,51.86]],"id":64851267},{"atl":[[990,0.23]],"id":64851267},{"spn":495.5,"spf":"NaN","id":64851267},{"atb":[[1.03,17.29]],"id":62886137},{"atl":[[1000,0.23]],"id":62886137},{"spn":500.51,"spf":"NaN","id":62886137},{"atb":[[1.01,51.86]],"id":61941224},{"atl":[[1000,0.23]],"id":61941224},{"spn":500.5,"spf":"NaN","id":61941224},{"atb":[[1.02,25.93]],"id":69475504},{"atl":[[990,0.23]],"id":69475504},{"spn":495.51,"spf":"NaN","id":69475504}],"con":true,"img":true}]}
{"op":"mcm","clk":"11538906747","pt":1719471498785,"mc":[{"id":"1.230180127","rc":[{"atb":[[1.03,17.29]],"id":66993945},{"atl":[[1000,1]],"id":66993945},{"atb":[[1.01,51.86]],"id":49823335},{"atl":[[1000,1.23]],"id":49823335},{"atb":[[1.01,51.86]],"id":64851267},{"atl":[[1000,1]],"id":64851267},{"atb":[[1.03,17.29]],"id":62886137},{"atl":[[1000,1.23]],"id":62886137},{"atb":[[1.01,51.86]],"id":61941224},{"atl":[[1000,1.23]],"id":61941224},{"atb":[[1.02,25.93]],"id":69475504},{"atl":[[1000,1]],"id":69475504}],"con":true,"img":false}]}
{"op":"mcm","clk":"11538906751","pt":1719471498887,"mc":[{"id":"1.230180127","rc":[{"atb":[[1.07,2.48]],"id":66993945},{"atb":[[1.07,2.48]],"id":49823335},{"atb":[[1.07,2.48]],"id":64851267},{"atb":[[1.07,2.48]],"id":62886137},{"atb":[[1.07,2.48]],"id":61941224},{"atb":[[1.07,2.48]],"id":69475504}],"con":true,"img":false}]}
{"op":"mcm","clk":"11538906756","pt":1719471498990,"mc":[{"id":"1.230180127","rc":[{"atl":[[1000,0.48]],"id":66993945},{"atl":[[1000,0.71]],"id":49823335},{"atl":[[1000,0.48]],"id":64851267},{"atl":[[1000,0.71]],"id":62886137},{"atl":[[1000,0.71]],"id":61941224},{"atl":[[1000,0.48]],"id":69475504}],"con":true,"img":false}]}
{"op":"mcm","clk":"11538906767","pt":1719471499194,"mc":[{"id":"1.230180127","rc":[{"atl":[[1000,0]],"id":66993945},{"atl":[[1000,0.23]],"id":49823335},{"atl":[[1000,0]],"id":64851267},{"atl":[[1000,0.23]],"id":62886137},{"atl":[[1000,0.23]],"id":61941224},{"atl":[[1000,0]],"id":69475504}],"con":true,"img":false}]}
{"op":"mcm","clk":"11538906770","pt":1719471499300,"mc":[{"id":"1.230180127","rc":[{"atl":[[75,0.48]],"id":66993945},{"atl":[[75,0.48]],"id":49823335},{"atl":[[75,0.48]],"id":64851267},{"atl":[[75,0.48]],"id":62886137},{"atl":[[75,0.48]],"id":61941224},{"atl":[[75,0.48]],"id":69475504}],"con":true,"img":false}]}
{"op":"mcm","clk":"11539124104","pt":1719475682703,"mc":[{"id":"1.230180127","marketDefinition":{"bspMarket":true,"turnInPlayEnabled":false,"persistenceEnabled":false,"marketBaseRate":5.0,"eventId":"33376437","eventTypeId":"4339","numberOfWinners":2,"bettingType":"ODDS","marketType":"PLACE","marketTime":"2024-06-27T15:44:00.000Z","suspendTime":"2024-06-27T15:44:00.000Z","bspReconciled":false,"complete":true,"inPlay":false,"crossMatching":false,"runnersVoidable":false,"numberOfActiveRunners":6,"betDelay":0,"status":"OPEN","runners":[{"status":"ACTIVE","sortPriority":1,"id":62886137,"name":"1. Walk On Gaffer"},{"status":"ACTIVE","sortPriority":2,"id":49823335,"name":"2. Orange Sydney"},{"status":"ACTIVE","sortPriority":3,"id":66993945,"name":"3. Essjay Alfred"},{"status":"ACTIVE","sortPriority":4,"id":64851267,"name":"4. Pro Cooper"},{"status":"ACTIVE","sortPriority":5,"id":69475504,"name":"5. Golden Wind"},{"status":"ACTIVE","sortPriority":6,"id":61941224,"name":"6. Salacres Sydney"}],"regulators":["MR_INT"],"venue":"Towcester","countryCode":"GB","discountAllowed":true,"timezone":"Europe/London","openDate":"2024-06-27T13:33:00.000Z","version":5994767111,"name":"To Be Placed","eventName":"Towcester 27th Jun"},"rc":[{"atb":[[1.03,17.28],[1.07,2.48]],"id":66993945},{"atl":[[75,0.48],[990,0.23]],"id":66993945},{"spn":38.03,"spf":"NaN","id":66993945},{"atb":[[1.01,51.84],[1.07,2.48]],"id":49823335},{"atl":[[75,0.48],[1000,0.23]],"id":49823335},{"spn":38.03,"spf":"NaN","id":49823335},{"atb":[[1.01,51.84],[1.07,2.48]],"id":64851267},{"atl":[[75,0.48],[990,0.23]],"id":64851267},{"spn":38.03,"spf":"NaN","id":64851267},{"atb":[[1.03,17.28],[1.07,2.48]],"id":62886137},{"atl":[[75,0.48],[1000,0.23]],"id":62886137},{"spn":38.03,"spf":"NaN","id":62886137},{"atb":[[1.01,51.84],[1.07,2.48]],"id":61941224},{"atl":[[75,0.48],[1000,0.23]],"id":61941224},{"spn":38.03,"spf":"NaN","id":61941224},{"atb":[[1.02,25.92],[1.07,2.48]],"id":69475504},{"atl":[[75,0.48],[990,0.23]],"id":69475504},{"spn":38.03,"spf":"NaN","id":69475504}],"con":true,"img":true}]}
{"op":"mcm","clk":"11539440211","pt":1719481082676,"mc":[{"id":"1.230180127","marketDefinition":{"bspMarket":true,"turnInPlayEnabled":false,"persistenceEnabled":false,"marketBaseRate":5.0,"eventId":"33376437","eventTypeId":"4339","numberOfWinners":2,"bettingType":"ODDS","marketType":"PLACE","marketTime":"2024-06-27T15:44:00.000Z","suspendTime":"2024-06-27T15:44:00.000Z","bspReconciled":false,"complete":true,"inPlay":false,"crossMatching":false,"runnersVoidable":false,"numberOfActiveRunners":6,"betDelay":0,"status":"OPEN","runners":[{"status":"ACTIVE","sortPriority":1,"id":62886137,"name":"1. Walk On Gaffer"},{"status":"ACTIVE","sortPriority":2,"id":49823335,"name":"2. Orange Sydney"},{"status":"ACTIVE","sortPriority":3,"id":66993945,"name":"3. Essjay Alfred"},{"status":"ACTIVE","sortPriority":4,"id":64851267,"name":"4. Pro Cooper"},{"status":"ACTIVE","sortPriority":5,"id":69475504,"name":"5. Golden Wind"},{"status":"ACTIVE","sortPriority":6,"id":61941224,"name":"6. Salacres Sydney"}],"regulators":["MR_INT"],"venue":"Towcester","countryCode":"GB","discountAllowed":true,"timezone":"Europe/London","openDate":"2024-06-27T13:33:00.000Z","version":5994767111,"name":"To Be Placed","eventName":"Towcester 27th Jun"},"rc":[{"atb":[[1.03,17.28],[1.07,2.48]],"id":66993945},{"atl":[[75,0.48],[990,0.23]],"id":66993945},{"spn":38.03,"spf":"NaN","id":66993945},{"atb":[[1.01,51.83],[1.07,2.48]],"id":49823335},{"atl":[[75,0.48],[1000,0.23]],"id":49823335},{"spn":38.03,"spf":"NaN","id":49823335},{"atb":[[1.01,51.83],[1.07,2.48]],"id":64851267},{"atl":[[75,0.48],[990,0.23]],"id":64851267},{"spn":38.03,"spf":"NaN","id":64851267},{"atb":[[1.03,17.28],[1.07,2.48]],"id":62886137},{"atl":[[75,0.48],[1000,0.23]],"id":62886137},{"spn":38.03,"spf":"NaN","id":62886137},{"atb":[[1.01,51.83],[1.07,2.48]],"id":61941224},{"atl":[[75,0.48],[1000,0.23]],"id":61941224},{"spn":38.03,"spf":"NaN","id":61941224},{"atb":[[1.02,25.91],[1.07,2.48]],"id":69475504},{"atl":[[75,0.48],[990,0.23]],"id":69475504},{"spn":38.03,"spf":"NaN","id":69475504}],"con":true,"img":true}]}
{"op":"mcm","clk":"11540685092","pt":1719497282628,"mc":[{"id":"1.230180127","marketDefinition":{"bspMarket":true,"turnInPlayEnabled":false,"persistenceEnabled":false,"marketBaseRate":5.0,"eventId":"33376437","eventTypeId":"4339","numberOfWinners":2,"bettingType":"ODDS","marketType":"PLACE","marketTime":"2024-06-27T15:44:00.000Z","suspendTime":"2024-06-27T15:44:00.000Z","bspReconciled":false,"complete":true,"inPlay":false,"crossMatching":false,"runnersVoidable":false,"numberOfActiveRunners":6,"betDelay":0,"status":"OPEN","runners":[{"status":"ACTIVE","sortPriority":1,"id":62886137,"name":"1. Walk On Gaffer"},{"status":"ACTIVE","sortPriority":2,"id":49823335,"name":"2. Orange Sydney"},{"status":"ACTIVE","sortPriority":3,"id":66993945,"name":"3. Essjay Alfred"},{"status":"ACTIVE","sortPriority":4,"id":64851267,"name":"4. Pro Cooper"},{"status":"ACTIVE","sortPriority":5,"id":69475504,"name":"5. Golden Wind"},{"status":"ACTIVE","sortPriority":6,"id":61941224,"name":"6. Salacres Sydney"}],"regulators":["MR_INT"],"venue":"Towcester","countryCode":"GB","discountAllowed":true,"timezone":"Europe/London","openDate":"2024-06-27T13:33:00.000Z","version":5994767111,"name":"To Be Placed","eventName":"Towcester 27th Jun"},"rc":[{"atb":[[1.03,17.29],[1.07,2.48]],"id":66993945},{"atl":[[75,0.48],[990,0.23]],"id":66993945},{"spn":38.03,"spf":"NaN","id":66993945},{"atb":[[1.01,51.87],[1.07,2.48]],"id":49823335},{"atl":[[75,0.48],[1000,0.23]],"id":49823335},{"spn":38.03,"spf":"NaN","id":49823335},{"atb":[[1.01,51.87],[1.07,2.48]],"id":64851267},{"atl":[[75,0.48],[990,0.23]],"id":64851267},{"spn":38.03,"spf":"NaN","id":64851267},{"atb":[[1.03,17.29],[1.07,2.48]],"id":62886137},{"atl":[[75,0.48],[1000,0.23]],"id":62886137},{"spn":38.03,"spf":"NaN","id":62886137},{"atb":[[1.01,51.87],[1.07,2.48]],"id":61941224},{"atl":[[75,0.48],[1000,0.23]],"id":61941224},{"spn":38.03,"spf":"NaN","id":61941224},{"atb":[[1.02,25.93],[1.07,2.48]],"id":69475504},{"atl":[[75,0.48],[990,0.23]],"id":69475504},{"spn":38.03,"spf":"NaN","id":69475504}],"con":true,"img":true}]}
{"op":"mcm","clk":"11541027059","pt":1719501302206,"mc":[{"id":"1.230180127","rc":[{"atb":[[1.03,17.29],[1.04,1]],"id":66993945},{"atl":[[990,0.23]],"id":66993945},{"spn":38.03,"spf":"NaN","id":66993945},{"atb":[[1.01,51.88],[1.04,1]],"id":49823335},{"atl":[[1000,0.23]],"id":49823335},{"spn":38.03,"spf":"NaN","id":49823335},{"atb":[[1.01,51.88],[1.04,1]],"id":64851267},{"atl":[[990,0.23]],"id":64851267},{"spn":38.03,"spf":"NaN","id":64851267},{"atb":[[1.03,17.29],[1.04,1]],"id":62886137},{"atl":[[1000,0.23]],"id":62886137},{"spn":38.03,"spf":"NaN","id":62886137},{"atb":[[1.01,51.88],[1.04,1]],"id":61941224},{"atl":[[1000,0.23]],"id":61941224},{"spn":38.03,"spf":"NaN","id":61941224},{"atb":[[1.02,25.94],[1.04,1]],"id":69475504},{"atl":[[990,0.23]],"id":69475504},{"spn":38.03,"spf":"NaN","id":69475504}],"con":true,"img":false}]}
{"op":"mcm","clk":"11541027090","pt":1719501302510,"mc":[{"id":"1.230180127","rc":[{"atb":[[1.04,0.25]],"id":66993945},{"atb":[[1.04,0.25]],"id":49823335},{"atb":[[1.04,0.25]],"id":64851267},{"atb":[[1.04,0.25]],"id":62886137},{"atb":[[1.04,0.25]],"id":61941224},{"atb":[[1.04,0.25]],"id":69475504}],"con":true,"img":false}]}
{"op":"mcm","clk":"11541027115","pt":1719501302717,"mc":[{"id":"1.230180127","rc":[{"atb":[[1.04,0]],"id":66993945},{"atb":[[1.04,0]],"id":49823335},{"atb":[[1.04,0]],"id":64851267},{"atb":[[1.04,0]],"id":62886137},{"atb":[[1.04,0]],"id":61941224},{"atb":[[1.04,0]],"id":69475504}],"con":true,"img":false}]}
{"op":"mcm","clk":"11541027127","pt":1719501302821,"mc":[{"id":"1.230180127","rc":[{"atb":[[1.2,0.25]],"id":66993945},{"atb":[[1.2,0.25]],"id":49823335},{"atb":[[1.2,0.25]],"id":64851267},{"atb":[[1.2,0.25]],"id":62886137},{"atb":[[1.2,0.25]],"id":61941224},{"atb":[[1.2,0.25]],"id":69475504}],"con":true,"img":false}]}
{"op":"mcm","clk":"11541027241","pt":1719501303812,"mc":[{"id":"1.230180127","rc":[{"atb":[[1.09,43.92]],"id":69475504}],"con":true,"img":false}]}
{"op":"mcm","clk":"11541044821","pt":1719501513236,"mc":[{"id":"1.230180127","rc":[{"spn":38.1,"spf":"NaN","id":66993945},{"spn":38.1,"spf":"NaN","id":49823335},{"spn":38.1,"spf":"NaN","id":64851267},{"spn":38.1,"spf":"NaN","id":62886137},{"spn":38.1,"spf":"NaN","id":61941224},{"atb":[[1.11,38.48]],"id":69475504},{"spn":38.1,"spf":"NaN","id":69475504}],"con":true,"img":false}]}
{"op":"mcm","clk":"11541045399","pt":1719501520358,"mc":[{"id":"1.230180127","rc":[{"atb":[[1.09,0]],"id":69475504}],"con":true,"img":false}]}
{"op":"mcm","clk":"11541045455","pt":1719501521030,"mc":[{"id":"1.230180127","rc":[{"atb":[[1.13,30.4]],"id":69475504}],"con":true,"img":false}]}
{"op":"mcm","clk":"11541045537","pt":1719501521981,"mc":[{"id":"1.230180127","marketDefinition":{"bspMarket":true,"turnInPlayEnabled":false,"persistenceEnabled":false,"marketBaseRate":5.0,"eventId":"33376437","eventTypeId":"4339","numberOfWinners":2,"bettingType":"ODDS","marketType":"PLACE","marketTime":"2024-06-27T15:44:00.000Z","suspendTime":"2024-06-27T15:44:00.000Z","bspReconciled":false,"complete":true,"inPlay":false,"crossMatching":true,"runnersVoidable":false,"numberOfActiveRunners":6,"betDelay":0,"status":"OPEN","runners":[{"status":"ACTIVE","sortPriority":1,"id":62886137,"name":"1. Walk On Gaffer"},{"status":"ACTIVE","sortPriority":2,"id":49823335,"name":"2. Orange Sydney"},{"status":"ACTIVE","sortPriority":3,"id":66993945,"name":"3. Essjay Alfred"},{"status":"ACTIVE","sortPriority":4,"id":64851267,"name":"4. Pro Cooper"},{"status":"ACTIVE","sortPriority":5,"id":69475504,"name":"5. Golden Wind"},{"status":"ACTIVE","sortPriority":6,"id":61941224,"name":"6. Salacres Sydney"}],"regulators":["MR_INT"],"venue":"Towcester","countryCode":"GB","discountAllowed":true,"timezone":"Europe/London","openDate":"2024-06-27T13:33:00.000Z","version":5994767111,"name":"To Be Placed","eventName":"Towcester 27th Jun"},"rc":[],"con":true,"img":false}]}
{"op":"mcm","clk":"11541047737","pt":1719501549583,"mc":[{"id":"1.230180127","rc":[{"atb":[[1.11,0]],"id":69475504}],"con":true,"img":false}]}
{"op":"mcm","clk":"11541047819","pt":1719501550284,"mc":[{"id":"1.230180127","rc":[{"atb":[[1.15,28.22]],"id":69475504}],"con":true,"img":false}]}
{"op":"mcm","clk":"11541048080","pt":1719501553390,"mc":[{"id":"1.230180127","rc":[{"atb":[[1.13,0]],"id":69475504}],"con":true,"img":false}]}
{"op":"mcm","clk":"11541048130","pt":1719501553969,"mc":[{"id":"1.230180127","rc":[{"atb":[[1.17,23.25]],"id":69475504}],"con":true,"img":false}]}
{"op":"mcm","clk":"11541050883","pt":1719501586046,"mc":[{"id":"1.230180127","rc":[{"atb":[[1.15,0]],"id":69475504}],"con":true,"img":false}]}
{"op":"mcm","clk":"11541050991","pt":1719501587128,"mc":[{"id":"1.230180127","rc":[{"atb":[[1.19,22.28]],"id":69475504}],"con":true,"img":false}]}
{"op":"mcm","clk":"11541051221","pt":1719501590494,"mc":[{"id":"1.230180127","rc":[{"atb":[[1.17,0]],"id":69475504}],"con":true,"img":false}]}
{"op":"mcm","clk":"11541051296","pt":1719501591371,"mc":[{"id":"1.230180127","rc":[{"atb":[[1.21,18.82]],"id":69475504}],"con":true,"img":false}]}
{"op":"mcm","clk":"11541053673","pt":1719501618677,"mc":[{"id":"1.230180127","rc":[{"atb":[[1.19,0]],"id":69475504}],"con":true,"img":false}]}
{"op":"mcm","clk":"11541053772","pt":1719501619866,"mc":[{"id":"1.230180127","rc":[{"atb":[[1.23,18.4]],"id":69475504}],"con":true,"img":false}]}
{"op":"mcm","clk":"11541054670","pt":1719501629102,"mc":[{"id":"1.230180127","rc":[{"atb":[[1.21,0]],"id":69475504}],"con":true,"img":false}]}
{"op":"mcm","clk":"11541054719","pt":1719501629721,"mc":[{"id":"1.230180127","rc":[{"atb":[[1.25,15.81]],"id":69475504}],"con":true,"img":false}]}
{"op":"mcm","clk":"11541056962","pt":1719501656653,"mc":[{"id":"1.230180127","rc":[{"atb":[[1.23,0]],"id":69475504},{"spn":38.12,"spf":"NaN","id":69475504}],"con":true,"img":false}]}
{"op":"mcm","clk":"11541057033","pt":1719501657537,"mc":[{"id":"1.230180127","rc":[{"atb":[[1.27,15.68]],"id":69475504}],"con":true,"img":false}]}
{"op":"mcm","clk":"11541057659","pt":1719501664676,"mc":[{"id":"1.230180127","rc":[{"atb":[[1.25,0]],"id":69475504}],"con":true,"img":false}]}
{"op":"mcm","clk":"11541057753","pt":1719501665765,"mc":[{"id":"1.230180127","rc":[{"atb":[[1.29,13.62]],"id":69475504}],"con":true,"img":false}]}
{"op":"mcm","clk":"11541060078","pt":1719501693264,"mc":[{"id":"1.230180127","rc":[{"atb":[[1.27,0]],"id":69475504}],"con":true,"img":false}]}
{"op":"mcm","clk":"11541060119","pt":1719501694001,"mc":[{"id":"1.230180127","rc":[{"atb":[[1.31,13.65]],"id":69475504}],"con":true,"img":false}]}
{"op":"mcm","clk":"11541060694","pt":1719501701396,"mc":[{"id":"1.230180127","rc":[{"atb":[[1.29,0]],"id":69475504}],"con":true,"img":false}]}
{"op":"mcm","clk":"11541060724","pt":1719501701813,"mc":[{"id":"1.230180127","rc":[{"atb":[[1.33,11.97]],"id":69475504}],"con":true,"img":false}]}
{"op":"mcm","clk":"11541063014","pt":1719501729813,"mc":[{"id":"1.230180127","rc":[{"atb":[[1.31,0]],"id":69475504},{"spn":38.16,"spf":"NaN","id":69475504}],"con":true,"img":false}]}
{"op":"mcm","clk":"11541063087","pt":1719501730736,"mc":[{"id":"1.230180127","rc":[{"atb":[[1.35,12.09]],"id":69475504}],"con":true,"img":false}]}
{"op":"mcm","clk":"11541063640","pt":1719501737145,"mc":[{"id":"1.230180127","rc":[{"atb":[[1.33,0]],"id":69475504}],"con":true,"img":false}]}
{"op":"mcm","clk":"11541063666","pt":1719501737450,"mc":[{"id":"1.230180127","rc":[{"atb":[[1.37,10.68]],"id":69475504}],"con":true,"img":false}]}
{"op":"mcm","clk":"11541065644","pt":1719501761481,"mc":[{"id":"1.230180127","rc":[{"atb":[[1.35,0]],"id":69475504}],"con":true,"img":false}]}
{"op":"mcm","clk":"11541065679","pt":1719501761946,"mc":[{"id":"1.230180127","rc":[{"atb":[[1.39,10.85]],"id":69475504}],"con":true,"img":false}]}
{"op":"mcm","clk":"11541066709","pt":1719501775257,"mc":[{"id":"1.230180127","rc":[{"atb":[[1.37,0]],"id":69475504}],"con":true,"img":false}]}
{"op":"mcm","clk":"11541066753","pt":1719501776034,"mc":[{"id":"1.230180127","rc":[{"atb":[[1.41,9.64]],"id":69475504}],"con":true,"img":false}]}
{"op":"mcm","clk":"11541068519","pt":1719501797495,"mc":[{"id":"1.230180127","rc":[{"atb":[[1.39,0]],"id":69475504},{"spn":38.2,"spf":"NaN","id":69475504}],"con":true,"img":false}]}
{"op":"mcm","clk":"11541068569","pt":1719501798009,"mc":[{"id":"1.230180127","rc":[{"atb":[[1.43,9.84]],"id":69475504}],"con":true,"img":false}]}
{"op":"mcm","clk":"11541069627","pt":1719501810107,"mc":[{"id":"1.230180127","rc":[{"atb":[[1.41,0]],"id":69475504}],"con":true,"img":false}]}
{"op":"mcm","clk":"11541069664","pt":1719501810524,"mc":[{"id":"1.230180127","rc":[{"atb":[[1.45,8.78]],"id":69475504}],"con":true,"img":false}]}
{"op":"mcm","clk":"11541071548","pt":1719501833813,"mc":[{"id":"1.230180127","rc":[{"atb":[[1.43,0]],"id":69475504}],"con":true,"img":false}]}
{"op":"mcm","clk":"11541071597","pt":1719501834436,"mc":[{"id":"1.230180127","rc":[{"atb":[[1.47,9]],"id":69475504}],"con":true,"img":false}]}
{"op":"mcm","clk":"11541072582","pt":1719501845788,"mc":[{"id":"1.230180127","rc":[{"atb":[[1.45,0]],"id":69475504}],"con":true,"img":false}]}
{"op":"mcm","clk":"11541072638","pt":1719501846260,"mc":[{"id":"1.230180127","rc":[{"atb":[[1.49,8.06]],"id":69475504}],"con":true,"img":false}]}
{"op":"mcm","clk":"11541074431","pt":1719501866967,"mc":[{"id":"1.230180127","rc":[{"atb":[[1.47,0]],"id":69475504},{"spn":38.24,"spf":"NaN","id":69475504}],"con":true,"img":false}]}
{"op":"mcm","clk":"11541074474","pt":1719501867599,"mc":[{"id":"1.230180127","rc":[{"atb":[[1.51,8.29]],"id":69475504}],"con":true,"img":false}]}
{"op":"mcm","clk":"11541075685","pt":1719501881787,"mc":[{"id":"1.230180127","rc":[{"atb":[[1.49,0]],"id":69475504}],"con":true,"img":false}]}
{"op":"mcm","clk":"11541075698","pt":1719501881992,"mc":[{"id":"1.230180127","rc":[{"atb":[[1.53,7.45]],"id":69475504}],"con":true,"img":false}]}
{"op":"mcm","clk":"11541077027","pt":1719501899008,"mc":[{"id":"1.230180127","rc":[{"atb":[[1.51,0]],"id":69475504}],"con":true,"img":false}]}
{"op":"mcm","clk":"11541077076","pt":1719501899628,"mc":[{"id":"1.230180127","rc":[{"atb":[[1.55,7.69]],"id":69475504}],"con":true,"img":false}]}
{"op":"mcm","clk":"11541078707","pt":1719501917938,"mc":[{"id":"1.230180127","rc":[{"atb":[[1.53,0]],"id":69475504}],"con":true,"img":false}]}
{"op":"mcm","clk":"11541078730","pt":1719501918146,"mc":[{"id":"1.230180127","rc":[{"atb":[[1.57,6.93]],"id":69475504}],"con":true,"img":false}]}
{"op":"mcm","clk":"11541080033","pt":1719501932359,"mc":[{"id":"1.230180127","rc":[{"atb":[[1.55,0]],"id":69475504},{"spn":38.28,"spf":"NaN","id":69475504}],"con":true,"img":false}]}
{"op":"mcm","clk":"11541080066","pt":1719501932669,"mc":[{"id":"1.230180127","rc":[{"atb":[[1.59,7.17]],"id":69475504}],"con":true,"img":false}]}
{"op":"mcm","clk":"11541080368","pt":1719501935738,"mc":[{"id":"1.230180127","rc":[{"atb":[[1.57,0]],"id":69475504}],"con":true,"img":false}]}
{"op":"mcm","clk":"11541080388","pt":1719501935949,"mc":[{"id":"1.230180127","rc":[{"atb":[[1.61,6.48]],"id":69475504}],"con":true,"img":false}]}
{"op":"mcm","clk":"11541083182","pt":1719501965891,"mc":[{"id":"1.230180127","rc":[{"atb":[[1.59,0]],"id":69475504}],"con":true,"img":false}]}
{"op":"mcm","clk":"11541083215","pt":1719501966200,"mc":[{"id":"1.230180127","rc":[{"atb":[[1.63,6.72]],"id":69475504}],"con":true,"img":false}]}
{"op":"mcm","clk":"11541083863","pt":1719501973488,"mc":[{"id":"1.230180127","rc":[{"atb":[[1.61,0]],"id":69475504}],"con":true,"img":false}]}
{"op":"mcm","clk":"11541083881","pt":1719501973694,"mc":[{"id":"1.230180127","rc":[{"atb":[[1.65,6.07]],"id":69475504}],"con":true,"img":false}]}
{"op":"mcm","clk":"11541085717","pt":1719501996907,"mc":[{"id":"1.230180127","rc":[{"atb":[[1.63,0]],"id":69475504},{"spn":38.32,"spf":"NaN","id":69475504}],"con":true,"img":false}]}
{"op":"mcm","clk":"11541085741","pt":1719501997216,"mc":[{"id":"1.230180127","rc":[{"atb":[[1.67,6.31]],"id":69475504}],"con":true,"img":false}]}
{"op":"mcm","clk":"11541086543","pt":1719502008228,"mc":[{"id":"1.230180127","rc":[{"atb":[[1.65,0]],"id":69475504}],"con":true,"img":false}]}
{"op":"mcm","clk":"11541086559","pt":1719502008431,"mc":[{"id":"1.230180127","rc":[{"atb":[[1.69,5.73]],"id":69475504}],"con":true,"img":false}]}
{"op":"mcm","clk":"11541088081","pt":1719502028669,"mc":[{"id":"1.230180127","rc":[{"atb":[[1.67,0]],"id":69475504}],"con":true,"img":false}]}
{"op":"mcm","clk":"11541088107","pt":1719502028978,"mc":[{"id":"1.230180127","rc":[{"atb":[[1.71,5.96]],"id":69475504}],"con":true,"img":false}]}
{"op":"mcm","clk":"11541089236","pt":1719502044617,"mc":[{"id":"1.230180127","rc":[{"atb":[[1.69,0]],"id":69475504}],"con":true,"img":false}]}
{"op":"mcm","clk":"11541089255","pt":1719502044825,"mc":[{"id":"1.230180127","rc":[{"atb":[[1.73,5.41]],"id":69475504}],"con":true,"img":false}]}
{"op":"mcm","clk":"11541090384","pt":1719502059713,"mc":[{"id":"1.230180127","rc":[{"atb":[[1.71,0]],"id":69475504},{"spn":38.36,"spf":"NaN","id":69475504}],"con":true,"img":false}]}
{"op":"mcm","clk":"11541090407","pt":1719502060022,"mc":[{"id":"1.230180127","rc":[{"atb":[[1.75,5.64]],"id":69475504}],"con":true,"img":false}]}
{"op":"mcm","clk":"11541090701","pt":1719502063239,"mc":[{"id":"1.230180127","rc":[{"atb":[[1.73,0]],"id":69475504}],"con":true,"img":false}]}
{"op":"mcm","clk":"11541090715","pt":1719502063446,"mc":[{"id":"1.230180127","rc":[{"atb":[[1.77,5.13]],"id":69475504}],"con":true,"img":false}]}
{"op":"mcm","clk":"11541092003","pt":1719502080252,"mc":[{"id":"1.230180127","rc":[{"atb":[[1.09,43.92]],"id":66993945}],"con":true,"img":false}]}
{"op":"mcm","clk":"11541093150","pt":1719502094197,"mc":[{"id":"1.230180127","rc":[{"atb":[[1.75,0]],"id":69475504}],"con":true,"img":false}]}
{"op":"mcm","clk":"11541093187","pt":1719502094569,"mc":[{"id":"1.230180127","rc":[{"atb":[[1.11,38.48]],"id":66993945}],"con":true,"img":false}]}
{"op":"mcm","clk":"11541093199","pt":1719502094670,"mc":[{"id":"1.230180127","rc":[{"atb":[[1.79,5.35]],"id":69475504}],"con":true,"img":false}]}
{"op":"mcm","clk":"11541093485","pt":1719502099285,"mc":[{"id":"1.230180127","rc":[{"atb":[[1.09,0]],"id":66993945},{"atb":[[1.77,0]],"id":69475504}],"con":true,"img":false}]}
{"op":"mcm","clk":"11541093510","pt":1719502099786,"mc":[{"id":"1.230180127","rc":[{"atb":[[1.81,4.87]],"id":69475504}],"con":true,"img":false}]}
{"op":"mcm","clk":"11541093521","pt":1719502099991,"mc":[{"id":"1.230180127","rc":[{"atb":[[1.13,30.4]],"id":66993945}],"con":true,"img":false}]}
{"op":"mcm","clk":"11541095369","pt":1719502129524,"mc":[{"id":"1.230180127","rc":[{"atb":[[1.11,0]],"id":66993945},{"spn":38.4,"spf":"NaN","id":69475504}],"con":true,"img":false}]}
{"op":"mcm","clk":"11541095437","pt":1719502130339,"mc":[{"id":"1.230180127","rc":[{"atb":[[1.79,0]],"id":69475504}],"con":true,"img":false}]}
{"op":"mcm","clk":"11541095464","pt":1719502130713,"mc":[{"id":"1.230180127","rc":[{"atb":[[1.83,5.09]],"id":69475504}],"con":true,"img":false}]}
{"op":"mcm","clk":"11541095478","pt":1719502130919,"mc":[{"id":"1.230180127","rc":[{"atb":[[1.15,28.22]],"id":66993945}],"con":true,"img":false}]}
{"op":"mcm","clk":"11541095839","pt":1719502136029,"mc":[{"id":"1.230180127","rc":[{"atb":[[1.81,0]],"id":69475504}],"con":true,"img":false}]}
{"op":"mcm","clk":"11541095881","pt":1719502136546,"mc":[{"id":"1.230180127","rc":[{"atb":[[1.13,0]],"id":66993945}],"con":true,"img":false}]}
{"op":"mcm","clk":"11541095905","pt":1719502136813,"mc":[{"id":"1.230180127","rc":[{"atb":[[1.17,23.25]],"id":66993945},{"atb":[[1.85,4.64]],"id":69475504}],"con":true,"img":false}]}
{"op":"mcm","clk":"11541096185","pt":1719502140858,"mc":[{"id":"1.230180127","rc":[{"atb":[[1.41,1],[1.18,23.25]],"id":66993945},{"atl":[[8.6,2],[3.55,1]],"id":66993945},{"atb":[[1.86,1],[1.65,2.48]],"id":49823335},{"atl":[[5.8,1],[21,2]],"id":49823335},{"atb":[[1.41,1],[1.39,2.48]],"id":64851267},{"atl":[[10.5,2],[3.55,1]],"id":64851267},{"atb":[[1.86,1],[1.69,2.48]],"id":62886137},{"atl":[[5.8,1],[25,2]],"id":62886137},{"atb":[[2.24,1],[1.75,2.48]],"id":61941224},{"atl":[[7.6,1],[30,2]],"id":61941224},{"atb":[[1.86,4.65]],"id":69475504},{"atl":[[4.3,1],[14.5,2]],"id":69475504}],"con":true,"img":false}]}
{"op":"mcm","clk":"11541096323","pt":1719502142947,"mc":[{"id":"1.230180127","rc":[{"atl":[[4.3,0],[4.4,1]],"id":69475504}],"con":true,"img":false}]}
{"op":"mcm","clk":"11541096352","pt":1719502143358,"mc":[{"id":"1.230180127","rc":[{"atb":[[1.86,6.76]],"id":69475504}],"con":true,"img":false}]}
{"op":"mcm","clk":"11541096521","pt":1719502145748,"mc":[{"id":"1.230180127","rc":[{"atb":[[1.01,1.7]],"id":66993945},{"atl":[[1000,1.7]],"id":66993945},{"atb":[[1.01,53.59]],"id":49823335},{"atl":[[1000,1.94]],"id":49823335},{"atb":[[1.01,1.7]],"id":62886137},{"atl":[[1000,1.94]],"id":62886137}],"con":true,"img":false}]}
{"op":"mcm","clk":"11541096543","pt":1719502145957,"mc":[{"id":"1.230180127","rc":[{"atb":[[1.01,1.67]],"id":66993945},{"atl":[[1000,0.04]],"id":66993945},{"atb":[[1.01,52.36]],"id":49823335},{"atl":[[1000,0.25]],"id":49823335},{"atb":[[1.01,0.45]],"id":62886137},{"atl":[[1000,0.25]],"id":62886137}],"con":true,"img":false}]}
{"op":"mcm","clk":"11541096559","pt":1719502146162,"mc":[{"id":"1.230180127","rc":[{"atb":[[1.01,0]],"id":66993945},{"atl":[[1000,0]],"id":66993945},{"atb":[[1.01,51.88]],"id":49823335},{"atl":[[1000,0.23]],"id":49823335},{"atb":[[1.01,0]],"id":62886137},{"atl":[[1000,0.23]],"id":62886137}],"con":true,"img":false}]}
{"op":"mcm","clk":"11541096565","pt":1719502146218,"mc":[{"id":"1.230180127","rc":[{"atb":[[1.19,1.67]],"id":66993945},{"atl":[[8.4,0.04]],"id":66993945},{"atb":[[1.66,0.48]],"id":49823335},{"atl":[[20,0.01]],"id":49823335},{"atb":[[1.7,0.45]],"id":62886137},{"atl":[[24,0.01]],"id":62886137}],"con":true,"img":false}]}
{"op":"mcm","clk":"11541097076","pt":1719502153346,"mc":[{"id":"1.230180127","rc":[{"atb":[[1.85,0]],"id":69475504}],"con":true,"img":false}]}
{"op":"mcm","clk":"11541097087","pt":1719502153548,"mc":[{"id":"1.230180127","rc":[{"atb":[[1.88,4.49]],"id":69475504}],"con":true,"img":false}]}
{"op":"mcm","clk":"11541097092","pt":1719502153652,"mc":[{"id":"1.230180127","rc":[{"atb":[[1.89,5.1],[1.86,2.11]],"id":69475504}],"con":true,"img":false}]}
{"op":"mcm","clk":"11541097606","pt":1719502160863,"mc":[{"id":"1.230180127","rc":[{"atb":[[1.73,2],[1.65,0]],"id":49823335},{"atb":[[1.5,2],[1.39,0]],"id":64851267},{"atb":[[1.79,2],[1.69,0]],"id":62886137},{"atb":[[1.85,2.48],[1.75,0]],"id":61941224}],"con":true,"img":false}]}
{"op":"mcm","clk":"11541097688","pt":1719502162055,"mc":[{"id":"1.230180127","rc":[{"atb":[[1.83,0]],"id":69475504}],"con":true,"img":false}]}
{"op":"mcm","clk":"11541097705","pt":1719502162268,"mc":[{"id":"1.230180127","rc":[{"atl":[[5.8,0],[6.8,1]],"id":49823335},{"atl":[[3.55,0],[4.2,1]],"id":64851267},{"atl":[[6.8,1]],"id":62886137},{"atl":[[9,1],[7.6,0]],"id":61941224}],"con":true,"img":false}]}
{"op":"mcm","clk":"11541097716","pt":1719502162362,"mc":[{"id":"1.230180127","rc":[{"atl":[[5.8,0]],"id":62886137}],"con":true,"img":false}]}
{"op":"mcm","clk":"11541097800","pt":1719502163458,"mc":[{"id":"1.230180127","rc":[{"atb":[[1.91,4.64]],"id":69475504}],"con":true,"img":false}]}
{"op":"mcm","clk":"11541097816","pt":1719502163660,"mc":[{"id":"1.230180127","rc":[{"atb":[[1.92,4.65],[1.89,0]],"id":69475504}],"con":true,"img":false}]}
{"op":"mcm","clk":"11541097881","pt":1719502164552,"mc":[{"id":"1.230180127","rc":[{"atl":[[5,1],[4.4,0]],"id":69475504}],"con":true,"img":false}]}
{"op":"mcm","clk":"11541098335","pt":1719502171266,"mc":[{"id":"1.230180127","rc":[{"atb":[[1.17,0]],"id":66993945}],"con":true,"img":false}]}
{"op":"mcm","clk":"11541098420","pt":1719502172663,"mc":[{"id":"1.230180127","rc":[{"atb":[[1.75,5.27]],"id":49823335},{"atb":[[1.81,4.87]],"id":62886137}],"con":true,"img":false}]}
{"op":"mcm","clk":"11541098426","pt":1719502172766,"mc":[{"id":"1.230180127","rc":[{"atb":[[1.73,0],[1.76,2]],"id":49823335},{"atb":[[1.82,2],[1.79,0]],"id":62886137}],"con":true,"img":false}]}
{"op":"mcm","clk":"11541098487","pt":1719502173487,"mc":[{"id":"1.230180127","rc":[{"atb":[[1.88,0]],"id":69475504}],"con":true,"img":false}]}
{"op":"mcm","clk":"11541098520","pt":1719502173959,"mc":[{"id":"1.230180127","rc":[{"atb":[[1.94,4.2]],"id":69475504}],"con":true,"img":false}]}
{"op":"mcm","clk":"11541098530","pt":1719502174057,"mc":[{"id":"1.230180127","rc":[{"atb":[[1.92,0],[1.95,4.65]],"id":69475504}],"con":true,"img":false}]}
{"op":"mcm","clk":"11541098912","pt":1719502179491,"mc":[{"id":"1.230180127","rc":[{"atb":[[1.82,3.75]],"id":69475504}],"con":true,"img":false}]}
{"op":"mcm","clk":"11541098955","pt":1719502180058,"mc":[{"id":"1.230180127","rc":[{"atb":[[1.02,2]],"id":62886137}],"con":true,"img":false}]}
{"op":"mcm","clk":"11541098976","pt":1719502180371,"mc":[{"id":"1.230180127","rc":[{"atb":[[1.02,2]],"id":49823335}],"con":true,"img":false}]}
{"op":"mcm","clk":"11541099003","pt":1719502180787,"mc":[{"id":"1.230180127","rc":[{"atb":[[1.2,2.25]],"id":66993945}],"con":true,"img":false}]}
{"op":"mcm","clk":"11541099022","pt":1719502181091,"mc":[{"id":"1.230180127","rc":[{"atb":[[1.02,2]],"id":64851267}],"con":true,"img":false}]}
{"op":"mcm","clk":"11541099039","pt":1719502181403,"mc":[{"id":"1.230180127","rc":[{"atb":[[1.93,2]],"id":69475504}],"con":true,"img":false}]}
{"op":"mcm","clk":"11541099059","pt":1719502181665,"mc":[{"id":"1.230180127","rc":[{"atb":[[1.02,2]],"id":61941224}],"con":true,"img":false}]}
{"op":"mcm","clk":"11541099086","pt":1719502182078,"mc":[{"id":"1.230180127","rc":[{"atb":[[1.82,0]],"id":69475504}],"con":true,"img":false}]}
{"op":"mcm","clk":"11541099190","pt":1719502183783,"mc":[{"id":"1.230180127","rc":[{"atb":[[1.2,0.25]],"id":66993945}],"con":true,"img":false}]}
{"op":"mcm","clk":"11541099201","pt":1719502183895,"mc":[{"id":"1.230180127","rc":[{"atb":[[1.19,3.67]],"id":66993945}],"con":true,"img":false}]}
{"op":"mcm","clk":"11541099240","pt":1719502184255,"mc":[{"id":"1.230180127","rc":[{"atb":[[1.93,0]],"id":69475504}],"con":true,"img":false}]}
{"op":"mcm","clk":"11541099249","pt":1719502184358,"mc":[{"id":"1.230180127","rc":[{"atb":[[1.96,2]],"id":69475504}],"con":true,"img":false}]}
{"op":"mcm","clk":"11541099690","pt":1719502190006,"mc":[{"id":"1.230180127","rc":[{"atb":[[1.19,2]],"id":66993945},{"atl":[[8.4,0]],"id":66993945},{"spn":2.48,"spf":"NaN","id":66993945},{"atb":[[1.66,0]],"id":49823335},{"atl":[[20,0]],"id":49823335},{"spn":4.33,"spf":"NaN","id":49823335},{"spn":2.85,"spf":"NaN","id":64851267},{"atb":[[1.7,0]],"id":62886137},{"atl":[[24,0]],"id":62886137},{"spn":4.33,"spf":"NaN","id":62886137},{"spn":5.62,"spf":"NaN","id":61941224},{"spn":3.48,"spf":"NaN","id":69475504}],"con":true,"img":false}]}
{"op":"mcm","clk":"11541099870","pt":1719502192405,"mc":[{"id":"1.230180127","rc":[{"atb":[[1.75,0]],"id":49823335}],"con":true,"img":false}]}
{"op":"mcm","clk":"11541099905","pt":1719502192880,"mc":[{"id":"1.230180127","rc":[{"atb":[[1.78,5.06]],"id":49823335}],"con":true,"img":false}]}
{"op":"mcm","clk":"11541099922","pt":1719502193086,"mc":[{"id":"1.230180127","rc":[{"atb":[[1.79,2],[1.76,0]],"id":49823335}],"con":true,"img":false}]}
{"op":"mcm","clk":"11541100393","pt":1719502198995,"mc":[{"id":"1.230180127","rc":[{"atb":[[1.15,0]],"id":66993945}],"con":true,"img":false}]}
{"op":"mcm","clk":"11541100454","pt":1719502199780,"mc":[{"id":"1.230180127","rc":[{"atb":[[1.81,5.22]],"id":49823335}],"con":true,"img":false}]}
{"op":"mcm","clk":"11541100464","pt":1719502199881,"mc":[{"id":"1.230180127","rc":[{"atb":[[1.82,5.07],[1.79,0]],"id":49823335}],"con":true,"img":false}]}
{"op":"mcm","clk":"11541100487","pt":1719502200306,"mc":[{"id":"1.230180127","rc":[{"atb":[[1.84,2.11],[1.02,0]],"id":49823335}],"con":true,"img":false}]}
{"op":"mcm","clk":"11541100500","pt":1719502200408,"mc":[{"id":"1.230180127","rc":[{"atb":[[1.82,7.07]],"id":49823335}],"con":true,"img":false}]}
{"op":"mcm","clk":"11541100511","pt":1719502200511,"mc":[{"id":"1.230180127","rc":[{"atb":[[1.82,2],[1.84,7.18]],"id":49823335}],"con":true,"img":false}]}
{"op":"mcm","clk":"11541100598","pt":1719502201303,"mc":[{"id":"1.230180127","rc":[{"atl":[[3.55,0],[4.2,1]],"id":66993945}],"con":true,"img":false}]}
{"op":"mcm","clk":"11541100703","pt":1719502202401,"mc":[{"id":"1.230180127","rc":[{"atb":[[1.82,0]],"id":49823335}],"con":true,"img":false}]}
{"op":"mcm","clk":"11541100713","pt":1719502202508,"mc":[{"id":"1.230180127","rc":[{"atb":[[1.85,2]],"id":49823335}],"con":true,"img":false}]}
{"op":"mcm","clk":"11541105786","pt":1719502262942,"mc":[{"id":"1.230180127","rc":[{"spn":2.8,"spf":"NaN","id":66993945},{"atb":[[1.91,0]],"id":69475504}],"con":true,"img":false}]}
{"op":"mcm","clk":"11541106014","pt":1719502265840,"mc":[{"id":"1.230180127","rc":[{"atb":[[1.81,0]],"id":62886137},{"atb":[[1.94,0]],"id":69475504}],"con":true,"img":false}]}
{"op":"mcm","clk":"11541106021","pt":1719502265971,"mc":[{"id":"1.230180127","rc":[{"atb":[[1.82,0],[1.79,3]],"id":62886137}],"con":true,"img":false}]}
{"op":"mcm","clk":"11541106103","pt":1719502266872,"mc":[{"id":"1.230180127","rc":[{"atb":[[1.01,1.7]],"id":66993945},{"atl":[[1000,1.7]],"id":66993945},{"atb":[[1.01,53.59]],"id":49823335},{"atl":[[1000,1.94]],"id":49823335},{"atb":[[1.01,1.7]],"id":62886137},{"atl":[[1000,1.94]],"id":62886137}],"con":true,"img":false}]}
{"op":"mcm","clk":"11541106117","pt":1719502267083,"mc":[{"id":"1.230180127","rc":[{"atb":[[1.01,1.53]],"id":66993945},{"atl":[[1000,0.04]],"id":66993945},{"atb":[[1.01,52.24]],"id":49823335},{"atl":[[1000,0.25]],"id":49823335},{"atb":[[1.01,0.38]],"id":62886137},{"atl":[[1000,0.25]],"id":62886137}],"con":true,"img":false}]}
{"op":"mcm","clk":"11541106135","pt":1719502267345,"mc":[{"id":"1.230180127","rc":[{"atb":[[1.01,0]],"id":66993945},{"atl":[[1000,0]],"id":66993945},{"atb":[[1.01,51.88]],"id":49823335},{"atl":[[1000,0.23]],"id":49823335},{"atb":[[1.01,0]],"id":62886137},{"atl":[[1000,0.23]],"id":62886137}],"con":true,"img":false}]}
{"op":"mcm","clk":"11541106145","pt":1719502267444,"mc":[{"id":"1.230180127","rc":[{"atb":[[1.2,1.78]],"id":66993945},{"atl":[[8.4,0.04]],"id":66993945},{"atb":[[1.86,1.35]],"id":49823335},{"atl":[[20,0.01]],"id":49823335},{"atb":[[1.8,0.38]],"id":62886137},{"atl":[[24,0.01]],"id":62886137}],"con":true,"img":false}]}
{"op":"mcm","clk":"11541106173","pt":1719502267854,"mc":[{"id":"1.230180127","rc":[{"atb":[[1.81,4.87]],"id":62886137}],"con":true,"img":false}]}
{"op":"mcm","clk":"11541106187","pt":1719502268066,"mc":[{"id":"1.230180127","rc":[{"atb":[[1.82,3],[1.79,0]],"id":62886137}],"con":true,"img":false}]}
{"op":"mcm","clk":"11541106241","pt":1719502268695,"mc":[{"id":"1.230180127","rc":[{"atb":[[1.19,0]],"id":66993945}],"con":true,"img":false}]}
{"op":"mcm","clk":"11541106252","pt":1719502268761,"mc":[{"id":"1.230180127","rc":[{"atb":[[1.21,2]],"id":66993945}],"con":true,"img":false}]}
{"op":"mcm","clk":"11541106370","pt":1719502270206,"mc":[{"id":"1.230180127","rc":[{"atb":[[1.21,0]],"id":66993945}],"con":true,"img":false}]}
{"op":"mcm","clk":"11541106380","pt":1719502270264,"mc":[{"id":"1.230180127","rc":[{"atb":[[1.19,2]],"id":66993945}],"con":true,"img":false}]}
{"op":"mcm","clk":"11541106515","pt":1719502271654,"mc":[{"id":"1.230180127","rc":[{"atb":[[1.19,0]],"id":66993945}],"con":true,"img":false}]}
{"op":"mcm","clk":"11541106529","pt":1719502271760,"mc":[{"id":"1.230180127","rc":[{"atb":[[1.21,2]],"id":66993945}],"con":true,"img":false}]}
{"op":"mcm","clk":"11541106643","pt":1719502273061,"mc":[{"id":"1.230180127","rc":[{"atb":[[1.21,0]],"id":66993945}],"con":true,"img":false}]}
{"op":"mcm","clk":"11541106651","pt":1719502273164,"mc":[{"id":"1.230180127","rc":[{"atb":[[1.19,2]],"id":66993945}],"con":true,"img":false}]}
{"op":"mcm","clk":"11541106759","pt":1719502274660,"mc":[{"id":"1.230180127","rc":[{"atb":[[1.19,0]],"id":66993945}],"con":true,"img":false}]}
{"op":"mcm","clk":"11541106769","pt":1719502274759,"mc":[{"id":"1.230180127","rc":[{"atb":[[1.21,2]],"id":66993945}],"con":true,"img":false}]}
{"op":"mcm","clk":"11541106879","pt":1719502276355,"mc":[{"id":"1.230180127","rc":[{"atb":[[1.21,0]],"id":66993945}],"con":true,"img":false}]}
{"op":"mcm","clk":"11541106885","pt":1719502276457,"mc":[{"id":"1.230180127","rc":[{"atb":[[1.19,2]],"id":66993945}],"con":true,"img":false}]}
{"op":"mcm","clk":"11541106957","pt":1719502277547,"mc":[{"id":"1.230180127","rc":[{"atb":[[1.19,0]],"id":66993945}],"con":true,"img":false}]}
{"op":"mcm","clk":"11541106963","pt":1719502277655,"mc":[{"id":"1.230180127","rc":[{"atb":[[1.21,2]],"id":66993945}],"con":true,"img":false}]}
{"op":"mcm","clk":"11541107075","pt":1719502279352,"mc":[{"id":"1.230180127","rc":[{"atb":[[1.21,0]],"id":66993945}],"con":true,"img":false}]}
{"op":"mcm","clk":"11541107085","pt":1719502279459,"mc":[{"id":"1.230180127","rc":[{"atb":[[1.19,2]],"id":66993945}],"con":true,"img":false}]}
{"op":"mcm","clk":"11541107243","pt":1719502281170,"mc":[{"id":"1.230180127","rc":[{"atb":[[1.19,0]],"id":66993945}],"con":true,"img":false}]}
{"op":"mcm","clk":"11541107248","pt":1719502281272,"mc":[{"id":"1.230180127","rc":[{"atb":[[1.21,2]],"id":66993945}],"con":true,"img":false}]}
{"op":"mcm","clk":"11541107367","pt":1719502282671,"mc":[{"id":"1.230180127","rc":[{"atb":[[1.21,0]],"id":66993945}],"con":true,"img":false}]}
{"op":"mcm","clk":"11541107376","pt":1719502282780,"mc":[{"id":"1.230180127","rc":[{"atb":[[1.19,2]],"id":66993945}],"con":true,"img":false}]}
{"op":"mcm","clk":"11541107393","pt":1719502282983,"mc":[{"id":"1.230180127","rc":[{"atb":[[1.78,0]],"id":49823335}],"con":true,"img":false}]}
{"op":"mcm","clk":"11541107615","pt":1719502285882,"mc":[{"id":"1.230180127","rc":[{"atb":[[1.19,0]],"id":66993945}],"con":true,"img":false}]}
{"op":"mcm","clk":"11541107627","pt":1719502285984,"mc":[{"id":"1.230180127","rc":[{"atb":[[1.21,2]],"id":66993945}],"con":true,"img":false}]}
{"op":"mcm","clk":"11541107740","pt":1719502287577,"mc":[{"id":"1.230180127","rc":[{"atb":[[1.21,0]],"id":66993945}],"con":true,"img":false}]}
{"op":"mcm","clk":"11541107750","pt":1719502287682,"mc":[{"id":"1.230180127","rc":[{"atb":[[1.19,2]],"id":66993945}],"con":true,"img":false}]}
{"op":"mcm","clk":"11541107831","pt":1719502288663,"mc":[{"id":"1.230180127","rc":[{"atb":[[1.19,0]],"id":66993945}],"con":true,"img":false}]}
{"op":"mcm","clk":"11541107838","pt":1719502288768,"mc":[{"id":"1.230180127","rc":[{"atb":[[1.21,2]],"id":66993945}],"con":true,"img":false}]}
{"op":"mcm","clk":"11541107925","pt":1719502289961,"mc":[{"id":"1.230180127","rc":[{"atb":[[1.21,0]],"id":66993945}],"con":true,"img":false}]}
{"op":"mcm","clk":"11541107934","pt":1719502290064,"mc":[{"id":"1.230180127","rc":[{"atb":[[1.19,2]],"id":66993945}],"con":true,"img":false}]}
{"op":"mcm","clk":"11541108012","pt":1719502291095,"mc":[{"id":"1.230180127","rc":[{"atb":[[1.19,0]],"id":66993945}],"con":true,"img":false}]}
{"op":"mcm","clk":"11541108020","pt":1719502291194,"mc":[{"id":"1.230180127","rc":[{"atb":[[1.21,2]],"id":66993945}],"con":true,"img":false}]}
{"op":"mcm","clk":"11541108087","pt":1719502291974,"mc":[{"id":"1.230180127","rc":[{"atb":[[1.21,0]],"id":66993945}],"con":true,"img":false}]}
{"op":"mcm","clk":"11541108097","pt":1719502292075,"mc":[{"id":"1.230180127","rc":[{"atb":[[1.19,2]],"id":66993945}],"con":true,"img":false}]}
{"op":"mcm","clk":"11541108172","pt":1719502293208,"mc":[{"id":"1.230180127","rc":[{"atb":[[1.19,0]],"id":66993945}],"con":true,"img":false}]}
{"op":"mcm","clk":"11541108183","pt":1719502293259,"mc":[{"id":"1.230180127","rc":[{"atb":[[1.21,2]],"id":66993945}],"con":true,"img":false}]}
{"op":"mcm","clk":"11541108256","pt":1719502294194,"mc":[{"id":"1.230180127","rc":[{"atb":[[1.21,0]],"id":66993945}],"con":true,"img":false}]}
{"op":"mcm","clk":"11541108265","pt":1719502294297,"mc":[{"id":"1.230180127","rc":[{"atb":[[1.19,2]],"id":66993945}],"con":true,"img":false}]}
{"op":"mcm","clk":"11541108346","pt":1719502295384,"mc":[{"id":"1.230180127","rc":[{"atb":[[1.19,0]],"id":66993945}],"con":true,"img":false}]}
{"op":"mcm","clk":"11541108353","pt":1719502295488,"mc":[{"id":"1.230180127","rc":[{"atb":[[1.21,2]],"id":66993945}],"con":true,"img":false}]}
{"op":"mcm","clk":"11541108420","pt":1719502296369,"mc":[{"id":"1.230180127","rc":[{"atb":[[1.21,0]],"id":66993945}],"con":true,"img":false}]}
{"op":"mcm","clk":"11541108428","pt":1719502296471,"mc":[{"id":"1.230180127","rc":[{"atb":[[1.19,2]],"id":66993945}],"con":true,"img":false}]}
{"op":"mcm","clk":"11541108436","pt":1719502296575,"mc":[{"id":"1.230180127","rc":[{"atb":[[1.81,0]],"id":49823335}],"con":true,"img":false}]}
{"op":"mcm","clk":"11541108496","pt":1719502297301,"mc":[{"id":"1.230180127","rc":[{"atb":[[1.85,0]],"id":49823335}],"con":true,"img":false}]}
{"op":"mcm","clk":"11541108501","pt":1719502297373,"mc":[{"id":"1.230180127","rc":[{"atb":[[1.02,2]],"id":49823335}],"con":true,"img":false}]}
{"op":"mcm","clk":"11541108527","pt":1719502297678,"mc":[{"id":"1.230180127","rc":[{"atb":[[1.19,0]],"id":66993945}],"con":true,"img":false}]}
{"op":"mcm","clk":"11541108535","pt":1719502297770,"mc":[{"id":"1.230180127","rc":[{"atb":[[1.21,2]],"id":66993945}],"con":true,"img":false}]}
{"op":"mcm","clk":"11541108621","pt":1719502298804,"mc":[{"id":"1.230180127","rc":[{"atb":[[1.02,0]],"id":49823335}],"con":true,"img":false}]}
{"op":"mcm","clk":"11541108632","pt":1719502298905,"mc":[{"id":"1.230180127","rc":[{"atb":[[1.85,2]],"id":49823335}],"con":true,"img":false}]}
{"op":"mcm","clk":"11541108648","pt":1719502299075,"mc":[{"id":"1.230180127","rc":[{"atb":[[1.21,0]],"id":66993945}],"con":true,"img":false}]}
{"op":"mcm","clk":"11541108658","pt":1719502299173,"mc":[{"id":"1.230180127","rc":[{"atb":[[1.19,2]],"id":66993945}],"con":true,"img":false}]}
{"op":"mcm","clk":"11541108719","pt":1719502299994,"mc":[{"id":"1.230180127","rc":[{"atb":[[1.85,0]],"id":49823335}],"con":true,"img":false}]}
{"op":"mcm","clk":"11541108728","pt":1719502300103,"mc":[{"id":"1.230180127","rc":[{"atb":[[1.02,2]],"id":49823335}],"con":true,"img":false}]}
{"op":"mcm","clk":"11541108754","pt":1719502300414,"mc":[{"id":"1.230180127","rc":[{"atb":[[1.19,0]],"id":66993945}],"con":true,"img":false}]}
{"op":"mcm","clk":"11541108764","pt":1719502300516,"mc":[{"id":"1.230180127","rc":[{"atb":[[1.21,2]],"id":66993945}],"con":true,"img":false}]}
{"op":"mcm","clk":"11541108827","pt":1719502301196,"mc":[{"id":"1.230180127","rc":[{"atb":[[1.02,0]],"id":49823335}],"con":true,"img":false}]}
{"op":"mcm","clk":"11541108838","pt":1719502301299,"mc":[{"id":"1.230180127","rc":[{"atb":[[1.85,2]],"id":49823335}],"con":true,"img":false}]}
{"op":"mcm","clk":"11541108866","pt":1719502301679,"mc":[{"id":"1.230180127","rc":[{"atb":[[1.21,0]],"id":66993945}],"con":true,"img":false}]}
{"op":"mcm","clk":"11541108872","pt":1719502301766,"mc":[{"id":"1.230180127","rc":[{"atb":[[1.19,2]],"id":66993945}],"con":true,"img":false}]}
{"op":"mcm","clk":"11541108929","pt":1719502302491,"mc":[{"id":"1.230180127","rc":[{"atb":[[1.85,0]],"id":49823335}],"con":true,"img":false}]}
{"op":"mcm","clk":"11541108938","pt":1719502302608,"mc":[{"id":"1.230180127","rc":[{"atb":[[1.02,2]],"id":49823335}],"con":true,"img":false}]}
{"op":"mcm","clk":"11541108970","pt":1719502303083,"mc":[{"id":"1.230180127","rc":[{"atb":[[1.19,0]],"id":66993945}],"con":true,"img":false}]}
{"op":"mcm","clk":"11541108978","pt":1719502303174,"mc":[{"id":"1.230180127","rc":[{"atb":[[1.21,2]],"id":66993945}],"con":true,"img":false}]}
{"op":"mcm","clk":"11541109040","pt":1719502304007,"mc":[{"id":"1.230180127","rc":[{"atb":[[1.02,0]],"id":49823335}],"con":true,"img":false}]}
{"op":"mcm","clk":"11541109048","pt":1719502304122,"mc":[{"id":"1.230180127","rc":[{"atb":[[1.85,2]],"id":49823335}],"con":true,"img":false}]}
{"op":"mcm","clk":"11541109076","pt":1719502304500,"mc":[{"id":"1.230180127","rc":[{"atb":[[1.21,0]],"id":66993945}],"con":true,"img":false}]}
{"op":"mcm","clk":"11541109083","pt":1719502304597,"mc":[{"id":"1.230180127","rc":[{"atb":[[1.19,2]],"id":66993945}],"con":true,"img":false}]}
{"op":"mcm","clk":"11541109149","pt":1719502305707,"mc":[{"id":"1.230180127","rc":[{"atb":[[1.85,0]],"id":49823335}],"con":true,"img":false}]}
{"op":"mcm","clk":"11541109155","pt":1719502305814,"mc":[{"id":"1.230180127","rc":[{"atb":[[1.02,2]],"id":49823335}],"con":true,"img":false}]}
{"op":"mcm","clk":"11541109190","pt":1719502306172,"mc":[{"id":"1.230180127","rc":[{"atb":[[1.19,0]],"id":66993945}],"con":true,"img":false}]}
{"op":"mcm","clk":"11541109197","pt":1719502306275,"mc":[{"id":"1.230180127","rc":[{"atb":[[1.21,2]],"id":66993945}],"con":true,"img":false}]}
{"op":"mcm","clk":"11541109250","pt":1719502307215,"mc":[{"id":"1.230180127","rc":[{"atb":[[1.02,0]],"id":49823335}],"con":true,"img":false}]}
{"op":"mcm","clk":"11541109261","pt":1719502307281,"mc":[{"id":"1.230180127","rc":[{"atb":[[1.85,2]],"id":49823335}],"con":true,"img":false}]}
{"op":"mcm","clk":"11541109287","pt":1719502307582,"mc":[{"id":"1.230180127","rc":[{"atb":[[1.21,0]],"id":66993945}],"con":true,"img":false}]}
{"op":"mcm","clk":"11541109298","pt":1719502307683,"mc":[{"id":"1.230180127","rc":[{"atb":[[1.19,2]],"id":66993945}],"con":true,"img":false}]}
{"op":"mcm","clk":"11541109359","pt":1719502308516,"mc":[{"id":"1.230180127","rc":[{"atb":[[1.85,0]],"id":49823335}],"con":true,"img":false}]}
{"op":"mcm","clk":"11541109366","pt":1719502308574,"mc":[{"id":"1.230180127","rc":[{"atb":[[1.02,2]],"id":49823335}],"con":true,"img":false}]}
{"op":"mcm","clk":"11541109383","pt":1719502308888,"mc":[{"id":"1.230180127","rc":[{"atb":[[1.19,0]],"id":66993945}],"con":true,"img":false}]}
{"op":"mcm","clk":"11541109391","pt":1719502308991,"mc":[{"id":"1.230180127","rc":[{"atb":[[1.21,2]],"id":66993945}],"con":true,"img":false}]}
{"op":"mcm","clk":"11541109460","pt":1719502309977,"mc":[{"id":"1.230180127","rc":[{"atb":[[1.2,0.25]],"id":66993945},{"atl":[[8.4,0]],"id":66993945},{"atb":[[1.86,1]],"id":49823335},{"atl":[[20,0]],"id":49823335},{"atb":[[1.8,0]],"id":62886137},{"atl":[[24,0]],"id":62886137}],"con":true,"img":false}]}
{"op":"mcm","clk":"11541109476","pt":1719502310187,"mc":[{"id":"1.230180127","rc":[{"atb":[[1.02,0]],"id":49823335}],"con":true,"img":false}]}
{"op":"mcm","clk":"11541109485","pt":1719502310280,"mc":[{"id":"1.230180127","rc":[{"atb":[[1.85,2]],"id":49823335}],"con":true,"img":false}]}
{"op":"mcm","clk":"11541109515","pt":1719502310695,"mc":[{"id":"1.230180127","rc":[{"atb":[[1.21,0]],"id":66993945}],"con":true,"img":false}]}
{"op":"mcm","clk":"11541109522","pt":1719502310801,"mc":[{"id":"1.230180127","rc":[{"atb":[[1.19,2]],"id":66993945}],"con":true,"img":false}]}
{"op":"mcm","clk":"11541109582","pt":1719502311686,"mc":[{"id":"1.230180127","rc":[{"atb":[[1.85,0]],"id":49823335}],"con":true,"img":false}]}
{"op":"mcm","clk":"11541109589","pt":1719502311789,"mc":[{"id":"1.230180127","rc":[{"atb":[[1.02,2]],"id":49823335}],"con":true,"img":false}]}
{"op":"mcm","clk":"11541109669","pt":1719502312999,"mc":[{"id":"1.230180127","rc":[{"atb":[[1.02,0]],"id":49823335}],"con":true,"img":false}]}
{"op":"mcm","clk":"11541109676","pt":1719502313088,"mc":[{"id":"1.230180127","rc":[{"atb":[[1.85,2]],"id":49823335}],"con":true,"img":false}]}
{"op":"mcm","clk":"11541109752","pt":1719502314092,"mc":[{"id":"1.230180127","rc":[{"atb":[[1.85,0]],"id":49823335}],"con":true,"img":false}]}
{"op":"mcm","clk":"11541109763","pt":1719502314195,"mc":[{"id":"1.230180127","rc":[{"atb":[[1.02,2]],"id":49823335}],"con":true,"img":false}]}
{"op":"mcm","clk":"11541109814","pt":1719502315017,"mc":[{"id":"1.230180127","rc":[{"atb":[[1.02,0]],"id":49823335}],"con":true,"img":false}]}
{"op":"mcm","clk":"11541109824","pt":1719502315121,"mc":[{"id":"1.230180127","rc":[{"atb":[[1.85,2]],"id":49823335}],"con":true,"img":false}]}
{"op":"mcm","clk":"11541109884","pt":1719502316003,"mc":[{"id":"1.230180127","rc":[{"atb":[[1.85,0]],"id":49823335}],"con":true,"img":false}]}
{"op":"mcm","clk":"11541109892","pt":1719502316111,"mc":[{"id":"1.230180127","rc":[{"atb":[[1.02,2]],"id":49823335}],"con":true,"img":false}]}
{"op":"mcm","clk":"11541109988","pt":1719502317206,"mc":[{"id":"1.230180127","rc":[{"atb":[[1.02,0]],"id":49823335}],"con":true,"img":false}]}
{"op":"mcm","clk":"11541110000","pt":1719502317305,"mc":[{"id":"1.230180127","rc":[{"atb":[[1.85,2]],"id":49823335}],"con":true,"img":false}]}
{"op":"mcm","clk":"11541110068","pt":1719502318133,"mc":[{"id":"1.230180127","rc":[{"atb":[[1.85,0]],"id":49823335}],"con":true,"img":false}]}
{"op":"mcm","clk":"11541110078","pt":1719502318190,"mc":[{"id":"1.230180127","rc":[{"atb":[[1.02,2]],"id":49823335}],"con":true,"img":false}]}
{"op":"mcm","clk":"11541110147","pt":1719502319220,"mc":[{"id":"1.230180127","rc":[{"atb":[[1.02,0]],"id":49823335}],"con":true,"img":false}]}
{"op":"mcm","clk":"11541110156","pt":1719502319332,"mc":[{"id":"1.230180127","rc":[{"atb":[[1.85,2]],"id":49823335}],"con":true,"img":false}]}
{"op":"mcm","clk":"11541110225","pt":1719502320109,"mc":[{"id":"1.230180127","rc":[{"atb":[[1.85,0]],"id":49823335}],"con":true,"img":false}]}
{"op":"mcm","clk":"11541110239","pt":1719502320215,"mc":[{"id":"1.230180127","rc":[{"atb":[[1.02,2]],"id":49823335}],"con":true,"img":false}]}
{"op":"mcm","clk":"11541110345","pt":1719502321300,"mc":[{"id":"1.230180127","rc":[{"atb":[[1.02,0]],"id":49823335}],"con":true,"img":false}]}
{"op":"mcm","clk":"11541110354","pt":1719502321405,"mc":[{"id":"1.230180127","rc":[{"atb":[[1.85,2]],"id":49823335}],"con":true,"img":false}]}
{"op":"mcm","clk":"11541110468","pt":1719502322606,"mc":[{"id":"1.230180127","rc":[{"atb":[[1.85,0]],"id":49823335}],"con":true,"img":false}]}
{"op":"mcm","clk":"11541110477","pt":1719502322711,"mc":[{"id":"1.230180127","rc":[{"atb":[[1.02,2]],"id":49823335}],"con":true,"img":false}]}
{"op":"mcm","clk":"11541110554","pt":1719502323702,"mc":[{"id":"1.230180127","rc":[{"atb":[[1.02,0]],"id":49823335}],"con":true,"img":false}]}
{"op":"mcm","clk":"11541110561","pt":1719502323793,"mc":[{"id":"1.230180127","rc":[{"atb":[[1.85,2]],"id":49823335}],"con":true,"img":false}]}
{"op":"mcm","clk":"11541110811","pt":1719502327018,"mc":[{"id":"1.230180127","rc":[{"atb":[[1.85,0]],"id":49823335}],"con":true,"img":false}]}
{"op":"mcm","clk":"11541110818","pt":1719502327129,"mc":[{"id":"1.230180127","rc":[{"atb":[[1.02,2]],"id":49823335}],"con":true,"img":false}]}
{"op":"mcm","clk":"11541110978","pt":1719502329015,"mc":[{"id":"1.230180127","rc":[{"atb":[[1.02,0]],"id":49823335}],"con":true,"img":false}]}
{"op":"mcm","clk":"11541110991","pt":1719502329111,"mc":[{"id":"1.230180127","rc":[{"atb":[[1.85,2]],"id":49823335}],"con":true,"img":false}]}
{"op":"mcm","clk":"11541111232","pt":1719502332017,"mc":[{"id":"1.230180127","rc":[{"atb":[[1.85,0]],"id":49823335}],"con":true,"img":false}]}
{"op":"mcm","clk":"11541111239","pt":1719502332121,"mc":[{"id":"1.230180127","rc":[{"atb":[[1.02,2]],"id":49823335}],"con":true,"img":false}]}
{"op":"mcm","clk":"11541111439","pt":1719502335041,"mc":[{"id":"1.230180127","rc":[{"atb":[[1.02,0]],"id":49823335}],"con":true,"img":false}]}
{"op":"mcm","clk":"11541111447","pt":1719502335143,"mc":[{"id":"1.230180127","rc":[{"atb":[[1.85,2]],"id":49823335}],"con":true,"img":false}]}
{"op":"mcm","clk":"11541111704","pt":1719502338965,"mc":[{"id":"1.230180127","rc":[{"atb":[[1.85,0]],"id":49823335}],"con":true,"img":false}]}
{"op":"mcm","clk":"11541111713","pt":1719502339063,"mc":[{"id":"1.230180127","rc":[{"atb":[[1.02,2]],"id":49823335}],"con":true,"img":false}]}
{"op":"mcm","clk":"11541111916","pt":1719502341468,"mc":[{"id":"1.230180127","rc":[{"atb":[[1.02,0]],"id":49823335}],"con":true,"img":false}]}
{"op":"mcm","clk":"11541111922","pt":1719502341573,"mc":[{"id":"1.230180127","rc":[{"atb":[[1.85,2]],"id":49823335}],"con":true,"img":false}]}
{"op":"mcm","clk":"11541112012","pt":1719502342832,"mc":[{"id":"1.230180127","rc":[{"atb":[[1.85,0]],"id":49823335}],"con":true,"img":false}]}
{"op":"mcm","clk":"11541112018","pt":1719502342881,"mc":[{"id":"1.230180127","rc":[{"atb":[[1.02,2]],"id":49823335}],"con":true,"img":false}]}
{"op":"mcm","clk":"11541112189","pt":1719502344827,"mc":[{"id":"1.230180127","rc":[{"atb":[[1.02,0]],"id":49823335}],"con":true,"img":false}]}
{"op":"mcm","clk":"11541112204","pt":1719502344941,"mc":[{"id":"1.230180127","rc":[{"atb":[[1.85,2]],"id":49823335}],"con":true,"img":false}]}
{"op":"mcm","clk":"11541112292","pt":1719502346034,"mc":[{"id":"1.230180127","rc":[{"atb":[[1.85,0]],"id":49823335}],"con":true,"img":false}]}
{"op":"mcm","clk":"11541112302","pt":1719502346135,"mc":[{"id":"1.230180127","rc":[{"atb":[[1.02,2]],"id":49823335}],"con":true,"img":false}]}
{"op":"mcm","clk":"11541112384","pt":1719502347130,"mc":[{"id":"1.230180127","rc":[{"atb":[[1.02,0]],"id":49823335}],"con":true,"img":false}]}
{"op":"mcm","clk":"11541112394","pt":1719502347242,"mc":[{"id":"1.230180127","rc":[{"atb":[[1.85,2]],"id":49823335}],"con":true,"img":false}]}
{"op":"mcm","clk":"11541112488","pt":1719502348444,"mc":[{"id":"1.230180127","rc":[{"atb":[[1.85,0]],"id":49823335}],"con":true,"img":false}]}
{"op":"mcm","clk":"11541112493","pt":1719502348544,"mc":[{"id":"1.230180127","rc":[{"atb":[[1.02,2]],"id":49823335}],"con":true,"img":false}]}
{"op":"mcm","clk":"11541112578","pt":1719502349655,"mc":[{"id":"1.230180127","rc":[{"atb":[[1.02,0]],"id":49823335}],"con":true,"img":false}]}
{"op":"mcm","clk":"11541112584","pt":1719502349752,"mc":[{"id":"1.230180127","rc":[{"atb":[[1.85,2]],"id":49823335}],"con":true,"img":false}]}
{"op":"mcm","clk":"11541112711","pt":1719502351479,"mc":[{"id":"1.230180127","rc":[{"atb":[[1.85,0]],"id":49823335}],"con":true,"img":false}]}
{"op":"mcm","clk":"11541112718","pt":1719502351543,"mc":[{"id":"1.230180127","rc":[{"atb":[[1.02,2]],"id":49823335}],"con":true,"img":false}]}
{"op":"mcm","clk":"11541112802","pt":1719502352864,"mc":[{"id":"1.230180127","rc":[{"atb":[[1.02,0]],"id":49823335}],"con":true,"img":false}]}
{"op":"mcm","clk":"11541112810","pt":1719502352964,"mc":[{"id":"1.230180127","rc":[{"atb":[[1.85,2]],"id":49823335}],"con":true,"img":false}]}
{"op":"mcm","clk":"11541113028","pt":1719502355978,"mc":[{"id":"1.230180127","rc":[{"atb":[[1.81,0]],"id":62886137}],"con":true,"img":false}]}
{"op":"mcm","clk":"11541113043","pt":1719502356143,"mc":[{"id":"1.230180127","rc":[{"atb":[[1.82,0],[1.79,4]],"id":62886137}],"con":true,"img":false}]}
{"op":"mcm","clk":"11541113114","pt":1719502357174,"mc":[{"id":"1.230180127","rc":[{"atb":[[1.81,4.87]],"id":62886137}],"con":true,"img":false}]}
{"op":"mcm","clk":"11541113367","pt":1719502360541,"mc":[{"id":"1.230180127","rc":[{"atb":[[1.83,5.09]],"id":62886137}],"con":true,"img":false}]}
{"op":"mcm","clk":"11541113570","pt":1719502362993,"mc":[{"id":"1.230180127","rc":[{"atb":[[1.84,2.11]],"id":62886137}],"con":true,"img":false}]}
{"op":"mcm","clk":"11541113636","pt":1719502364186,"mc":[{"id":"1.230180127","rc":[{"atb":[[1.79,0],[1.84,6.99]],"id":62886137}],"con":true,"img":false}]}
{"op":"mcm","clk":"11541113944","pt":1719502368471,"mc":[{"id":"1.230180127","rc":[{"atb":[[1.02,0]],"id":62886137}],"con":true,"img":false}]}
{"op":"mcm","clk":"11541113951","pt":1719502368570,"mc":[{"id":"1.230180127","rc":[{"atb":[[1.85,2]],"id":62886137}],"con":true,"img":false}]}
{"op":"mcm","clk":"11541113963","pt":1719502368774,"mc":[{"id":"1.230180127","rc":[{"atb":[[1.85,0]],"id":49823335}],"con":true,"img":false}]}
{"op":"mcm","clk":"11541113968","pt":1719502368882,"mc":[{"id":"1.230180127","rc":[{"atb":[[1.02,2]],"id":49823335}],"con":true,"img":false}]}
{"op":"mcm","clk":"11541114105","pt":1719502370761,"mc":[{"id":"1.230180127","rc":[{"atb":[[1.02,0]],"id":49823335}],"con":true,"img":false}]}
{"op":"mcm","clk":"11541114110","pt":1719502370867,"mc":[{"id":"1.230180127","rc":[{"atb":[[1.85,2]],"id":49823335}],"con":true,"img":false}]}
{"op":"mcm","clk":"11541114167","pt":1719502371121,"mc":[{"id":"1.230180127","rc":[{"atb":[[1.66,3.75]],"id":49823335}],"con":true,"img":false}]}
{"op":"mcm","clk":"11541114185","pt":1719502371286,"mc":[{"id":"1.230180127","rc":[{"atb":[[1.66,0]],"id":49823335}],"con":true,"img":false}]}
{"op":"mcm","clk":"11541114266","pt":1719502372370,"mc":[{"id":"1.230180127","rc":[{"atb":[[1.85,0]],"id":49823335}],"con":true,"img":false}]}
{"op":"mcm","clk":"11541114273","pt":1719502372480,"mc":[{"id":"1.230180127","rc":[{"atb":[[1.02,2]],"id":49823335}],"con":true,"img":false}]}
{"op":"mcm","clk":"11541114395","pt":1719502373983,"mc":[{"id":"1.230180127","rc":[{"atb":[[1.02,0]],"id":49823335}],"con":true,"img":false}]}
{"op":"mcm","clk":"11541114403","pt":1719502374080,"mc":[{"id":"1.230180127","rc":[{"atb":[[1.85,2]],"id":49823335}],"con":true,"img":false}]}
{"op":"mcm","clk":"11541114503","pt":1719502375273,"mc":[{"id":"1.230180127","rc":[{"atb":[[1.85,0]],"id":49823335}],"con":true,"img":false}]}
{"op":"mcm","clk":"11541114512","pt":1719502375372,"mc":[{"id":"1.230180127","rc":[{"atb":[[1.02,2]],"id":49823335}],"con":true,"img":false}]}
{"op":"mcm","clk":"11541114621","pt":1719502376973,"mc":[{"id":"1.230180127","rc":[{"atb":[[1.02,0]],"id":49823335}],"con":true,"img":false}]}
{"op":"mcm","clk":"11541114629","pt":1719502377084,"mc":[{"id":"1.230180127","rc":[{"atb":[[1.85,2]],"id":49823335}],"con":true,"img":false}]}
{"op":"mcm","clk":"11541114806","pt":1719502379089,"mc":[{"id":"1.230180127","rc":[{"atb":[[1.85,0]],"id":49823335}],"con":true,"img":false}]}
{"op":"mcm","clk":"11541114812","pt":1719502379193,"mc":[{"id":"1.230180127","rc":[{"atb":[[1.02,2]],"id":49823335}],"con":true,"img":false}]}
{"op":"mcm","clk":"11541114919","pt":1719502380702,"mc":[{"id":"1.230180127","rc":[{"atb":[[1.02,0]],"id":49823335},{"spl":[[1.01,10]],"id":64851267}],"con":true,"img":false}]}
{"op":"mcm","clk":"11541114929","pt":1719502380799,"mc":[{"id":"1.230180127","rc":[{"atb":[[1.85,2]],"id":49823335}],"con":true,"img":false}]}
{"op":"mcm","clk":"11541115015","pt":1719502381886,"mc":[{"id":"1.230180127","rc":[{"atb":[[1.85,0]],"id":49823335}],"con":true,"img":false}]}
{"op":"mcm","clk":"11541115022","pt":1719502381990,"mc":[{"id":"1.230180127","rc":[{"atb":[[1.02,2]],"id":49823335}],"con":true,"img":false}]}
{"op":"mcm","clk":"11541115103","pt":1719502383180,"mc":[{"id":"1.230180127","rc":[{"atb":[[1.02,0]],"id":49823335}],"con":true,"img":false}]}
{"op":"mcm","clk":"11541115113","pt":1719502383285,"mc":[{"id":"1.230180127","rc":[{"atb":[[1.85,2]],"id":49823335}],"con":true,"img":false}]}
{"op":"mcm","clk":"11541115248","pt":1719502384518,"mc":[{"id":"1.230180127","rc":[{"atb":[[1.85,0]],"id":49823335},{"spn":1.16,"spf":1.0,"id":64851267}],"con":true,"img":false}]}
{"op":"mcm","clk":"11541115254","pt":1719502384571,"mc":[{"id":"1.230180127","rc":[{"atb":[[1.02,2]],"id":49823335}],"con":true,"img":false}]}
{"op":"mcm","clk":"11541115290","pt":1719502385088,"mc":[{"id":"1.230180127","rc":[{"atl":[[1000,1.7]],"id":66993945},{"atb":[[1.01,53.59]],"id":49823335},{"atl":[[1000,1.94]],"id":49823335},{"atb":[[1.01,1.7]],"id":62886137},{"atl":[[1000,1.94]],"id":62886137}],"con":true,"img":false}]}
{"op":"mcm","clk":"11541115299","pt":1719502385196,"mc":[{"id":"1.230180127","rc":[{"atb":[[1.01,1.7]],"id":66993945}],"con":true,"img":false}]}
{"op":"mcm","clk":"11541115305","pt":1719502385300,"mc":[{"id":"1.230180127","rc":[{"atl":[[1000,0.03]],"id":66993945},{"atb":[[1.01,52.23]],"id":49823335},{"atl":[[1000,0.25]],"id":49823335},{"atb":[[1.01,0.34]],"id":62886137},{"atl":[[1000,0.24]],"id":62886137}],"con":true,"img":false}]}
{"op":"mcm","clk":"11541115313","pt":1719502385402,"mc":[{"id":"1.230180127","rc":[{"atb":[[1.01,1.47]],"id":66993945}],"con":true,"img":false}]}
{"op":"mcm","clk":"11541115330","pt":1719502385603,"mc":[{"id":"1.230180127","rc":[{"atl":[[1000,0]],"id":66993945},{"atb":[[1.01,51.88]],"id":49823335},{"atl":[[1000,0.23]],"id":49823335},{"atb":[[1.01,0]],"id":62886137},{"atl":[[1000,0.23]],"id":62886137}],"con":true,"img":false}]}
{"op":"mcm","clk":"11541115338","pt":1719502385712,"mc":[{"id":"1.230180127","rc":[{"atb":[[1.01,0]],"id":66993945},{"atl":[[8.4,0.03]],"id":66993945},{"atb":[[1.85,0.34]],"id":49823335},{"atl":[[20,0.01]],"id":49823335},{"atb":[[1.86,1.34]],"id":62886137},{"atl":[[24,0.01]],"id":62886137}],"con":true,"img":false}]}
{"op":"mcm","clk":"11541115346","pt":1719502385809,"mc":[{"id":"1.230180127","rc":[{"atb":[[1.2,1.72]],"id":66993945}],"con":true,"img":false}]}
{"op":"mcm","clk":"11541115395","pt":1719502386380,"mc":[{"id":"1.230180127","rc":[{"atb":[[1.02,0]],"id":49823335}],"con":true,"img":false}]}
{"op":"mcm","clk":"11541115403","pt":1719502386484,"mc":[{"id":"1.230180127","rc":[{"atb":[[1.85,2.34]],"id":49823335}],"con":true,"img":false}]}
{"op":"mcm","clk":"11541115429","pt":1719502386802,"mc":[{"id":"1.230180127","rc":[{"atb":[[1.19,0]],"id":66993945}],"con":true,"img":false}]}
{"op":"mcm","clk":"11541115437","pt":1719502386898,"mc":[{"id":"1.230180127","rc":[{"atb":[[1.21,2]],"id":66993945}],"con":true,"img":false}]}
{"op":"mcm","clk":"11541115601","pt":1719502388296,"mc":[{"id":"1.230180127","rc":[{"atb":[[1.85,0.34]],"id":49823335}],"con":true,"img":false}]}
{"op":"mcm","clk":"11541115609","pt":1719502388401,"mc":[{"id":"1.230180127","rc":[{"atb":[[1.02,2]],"id":49823335}],"con":true,"img":false}]}
{"op":"mcm","clk":"11541115627","pt":1719502388712,"mc":[{"id":"1.230180127","rc":[{"atb":[[1.21,0]],"id":66993945}],"con":true,"img":false}]}
{"op":"mcm","clk":"11541115634","pt":1719502388815,"mc":[{"id":"1.230180127","rc":[{"atb":[[1.19,2]],"id":66993945}],"con":true,"img":false}]}
{"op":"mcm","clk":"11541115773","pt":1719502390717,"mc":[{"id":"1.230180127","rc":[{"atb":[[1.02,0]],"id":49823335}],"con":true,"img":false}]}
{"op":"mcm","clk":"11541115782","pt":1719502390820,"mc":[{"id":"1.230180127","rc":[{"atb":[[1.85,2.34]],"id":49823335}],"con":true,"img":false}]}
{"op":"mcm","clk":"11541115814","pt":1719502391296,"mc":[{"id":"1.230180127","rc":[{"atb":[[1.19,0]],"id":66993945}],"con":true,"img":false}]}
{"op":"mcm","clk":"11541115821","pt":1719502391396,"mc":[{"id":"1.230180127","rc":[{"atb":[[1.21,2]],"id":66993945}],"con":true,"img":false}]}
{"op":"mcm","clk":"11541115984","pt":1719502393820,"mc":[{"id":"1.230180127","rc":[{"atb":[[1.85,0.34]],"id":49823335}],"con":true,"img":false}]}
{"op":"mcm","clk":"11541115993","pt":1719502393921,"mc":[{"id":"1.230180127","rc":[{"atb":[[1.02,2]],"id":49823335}],"con":true,"img":false}]}
{"op":"mcm","clk":"11541116020","pt":1719502394285,"mc":[{"id":"1.230180127","rc":[{"atb":[[1.21,0]],"id":66993945}],"con":true,"img":false}]}
{"op":"mcm","clk":"11541116027","pt":1719502394392,"mc":[{"id":"1.230180127","rc":[{"atb":[[1.19,2]],"id":66993945}],"con":true,"img":false}]}
{"op":"mcm","clk":"11541116124","pt":1719502396089,"mc":[{"id":"1.230180127","rc":[{"atb":[[1.02,0]],"id":49823335}],"con":true,"img":false}]}
{"op":"mcm","clk":"11541116131","pt":1719502396197,"mc":[{"id":"1.230180127","rc":[{"atb":[[1.85,2.34]],"id":49823335}],"con":true,"img":false}]}
{"op":"mcm","clk":"11541116155","pt":1719502396613,"mc":[{"id":"1.230180127","rc":[{"atb":[[1.19,0]],"id":66993945}],"con":true,"img":false}]}
{"op":"mcm","clk":"11541116160","pt":1719502396714,"mc":[{"id":"1.230180127","rc":[{"atb":[[1.21,2]],"id":66993945}],"con":true,"img":false}]}
{"op":"mcm","clk":"11541116283","pt":1719502398216,"mc":[{"id":"1.230180127","rc":[{"atb":[[1.85,0.34]],"id":49823335}],"con":true,"img":false}]}
{"op":"mcm","clk":"11541116295","pt":1719502398322,"mc":[{"id":"1.230180127","rc":[{"atb":[[1.02,2]],"id":49823335}],"con":true,"img":false}]}
{"op":"mcm","clk":"11541116328","pt":1719502398722,"mc":[{"id":"1.230180127","rc":[{"atb":[[1.21,0]],"id":66993945}],"con":true,"img":false}]}
{"op":"mcm","clk":"11541116338","pt":1719502398829,"mc":[{"id":"1.230180127","rc":[{"atb":[[1.19,2]],"id":66993945}],"con":true,"img":false}]}
{"op":"mcm","clk":"11541116422","pt":1719502400118,"mc":[{"id":"1.230180127","rc":[{"atb":[[1.02,0]],"id":49823335}],"con":true,"img":false}]}
{"op":"mcm","clk":"11541116430","pt":1719502400217,"mc":[{"id":"1.230180127","rc":[{"atb":[[1.85,2.34]],"id":49823335}],"con":true,"img":false}]}
{"op":"mcm","clk":"11541116454","pt":1719502400527,"mc":[{"id":"1.230180127","rc":[{"atb":[[1.19,0]],"id":66993945}],"con":true,"img":false}]}
{"op":"mcm","clk":"11541116463","pt":1719502400632,"mc":[{"id":"1.230180127","rc":[{"atb":[[1.21,2]],"id":66993945}],"con":true,"img":false}]}
{"op":"mcm","clk":"11541116580","pt":1719502402240,"mc":[{"id":"1.230180127","rc":[{"atb":[[1.85,0.34]],"id":49823335}],"con":true,"img":false}]}
{"op":"mcm","clk":"11541116589","pt":1719502402304,"mc":[{"id":"1.230180127","rc":[{"atb":[[1.02,2]],"id":49823335}],"con":true,"img":false}]}
{"op":"mcm","clk":"11541116615","pt":1719502402706,"mc":[{"id":"1.230180127","rc":[{"atb":[[1.21,0]],"id":66993945}],"con":true,"img":false}]}
{"op":"mcm","clk":"11541116625","pt":1719502402810,"mc":[{"id":"1.230180127","rc":[{"atb":[[1.19,2]],"id":66993945}],"con":true,"img":false}]}
{"op":"mcm","clk":"11541116720","pt":1719502404409,"mc":[{"id":"1.230180127","rc":[{"atb":[[1.02,0]],"id":49823335}],"con":true,"img":false}]}
{"op":"mcm","clk":"11541116727","pt":1719502404521,"mc":[{"id":"1.230180127","rc":[{"atb":[[1.85,2.34]],"id":49823335}],"con":true,"img":false}]}
{"op":"mcm","clk":"11541116762","pt":1719502404928,"mc":[{"id":"1.230180127","rc":[{"atb":[[1.19,0]],"id":66993945}],"con":true,"img":false}]}
{"op":"mcm","clk":"11541116773","pt":1719502405026,"mc":[{"id":"1.230180127","rc":[{"atb":[[1.21,2]],"id":66993945}],"con":true,"img":false}]}
{"op":"mcm","clk":"11541116898","pt":1719502406630,"mc":[{"id":"1.230180127","rc":[{"atb":[[1.85,0.34]],"id":49823335}],"con":true,"img":false}]}
{"op":"mcm","clk":"11541116906","pt":1719502406731,"mc":[{"id":"1.230180127","rc":[{"atb":[[1.02,2]],"id":49823335}],"con":true,"img":false}]}
{"op":"mcm","clk":"11541116923","pt":1719502407035,"mc":[{"id":"1.230180127","rc":[{"atb":[[1.21,0]],"id":66993945}],"con":true,"img":false}]}
{"op":"mcm","clk":"11541116933","pt":1719502407142,"mc":[{"id":"1.230180127","rc":[{"atb":[[1.19,2]],"id":66993945}],"con":true,"img":false}]}
{"op":"mcm","clk":"11541117004","pt":1719502408336,"mc":[{"id":"1.230180127","rc":[{"atb":[[1.02,0]],"id":49823335}],"con":true,"img":false}]}
{"op":"mcm","clk":"11541117013","pt":1719502408433,"mc":[{"id":"1.230180127","rc":[{"atb":[[1.85,2.34]],"id":49823335}],"con":true,"img":false}]}
{"op":"mcm","clk":"11541117030","pt":1719502408841,"mc":[{"id":"1.230180127","rc":[{"atb":[[1.19,0]],"id":66993945}],"con":true,"img":false}]}
{"op":"mcm","clk":"11541117037","pt":1719502408944,"mc":[{"id":"1.230180127","rc":[{"atb":[[1.21,2]],"id":66993945}],"con":true,"img":false}]}
{"op":"mcm","clk":"11541117112","pt":1719502410028,"mc":[{"id":"1.230180127","rc":[{"atb":[[1.85,0.34]],"id":49823335}],"con":true,"img":false}]}
{"op":"mcm","clk":"11541117119","pt":1719502410129,"mc":[{"id":"1.230180127","rc":[{"atb":[[1.02,2]],"id":49823335}],"con":true,"img":false}]}
{"op":"mcm","clk":"11541117156","pt":1719502410648,"mc":[{"id":"1.230180127","rc":[{"atb":[[1.21,0]],"id":66993945}],"con":true,"img":false}]}
{"op":"mcm","clk":"11541117165","pt":1719502410753,"mc":[{"id":"1.230180127","rc":[{"atb":[[1.19,2]],"id":66993945}],"con":true,"img":false}]}
{"op":"mcm","clk":"11541117271","pt":1719502412144,"mc":[{"id":"1.230180127","rc":[{"atb":[[1.02,0]],"id":49823335}],"con":true,"img":false}]}
{"op":"mcm","clk":"11541117276","pt":1719502412254,"mc":[{"id":"1.230180127","rc":[{"atb":[[1.85,2.34]],"id":49823335}],"con":true,"img":false}]}
{"op":"mcm","clk":"11541117311","pt":1719502412562,"mc":[{"id":"1.230180127","rc":[{"atb":[[1.19,0]],"id":66993945}],"con":true,"img":false}]}
{"op":"mcm","clk":"11541117320","pt":1719502412622,"mc":[{"id":"1.230180127","rc":[{"atb":[[1.21,2]],"id":66993945}],"con":true,"img":false}]}
{"op":"mcm","clk":"11541117442","pt":1719502414125,"mc":[{"id":"1.230180127","rc":[{"atb":[[1.85,0.34]],"id":49823335}],"con":true,"img":false}]}
{"op":"mcm","clk":"11541117451","pt":1719502414220,"mc":[{"id":"1.230180127","rc":[{"atb":[[1.02,2]],"id":49823335}],"con":true,"img":false}]}
{"op":"mcm","clk":"11541117470","pt":1719502414537,"mc":[{"id":"1.230180127","rc":[{"atb":[[1.21,0]],"id":66993945}],"con":true,"img":false}]}
{"op":"mcm","clk":"11541117479","pt":1719502414634,"mc":[{"id":"1.230180127","rc":[{"atb":[[1.19,2]],"id":66993945}],"con":true,"img":false}]}
{"op":"mcm","clk":"11541117572","pt":1719502415978,"mc":[{"id":"1.230180127","rc":[{"atb":[[1.02,0]],"id":49823335}],"con":true,"img":false}]}
{"op":"mcm","clk":"11541117583","pt":1719502416133,"mc":[{"id":"1.230180127","rc":[{"atb":[[1.85,2.34]],"id":49823335}],"con":true,"img":false}]}
{"op":"mcm","clk":"11541117604","pt":1719502416441,"mc":[{"id":"1.230180127","rc":[{"atb":[[1.19,0]],"id":66993945}],"con":true,"img":false}]}
{"op":"mcm","clk":"11541117610","pt":1719502416604,"mc":[{"id":"1.230180127","rc":[{"atb":[[1.21,2]],"id":66993945}],"con":true,"img":false}]}
{"op":"mcm","clk":"11541117709","pt":1719502418046,"mc":[{"id":"1.230180127","rc":[{"atb":[[1.85,0.34]],"id":49823335}],"con":true,"img":false}]}
{"op":"mcm","clk":"11541117714","pt":1719502418145,"mc":[{"id":"1.230180127","rc":[{"atb":[[1.02,2]],"id":49823335}],"con":true,"img":false}]}
{"op":"mcm","clk":"11541117746","pt":1719502418557,"mc":[{"id":"1.230180127","rc":[{"atb":[[1.21,0]],"id":66993945}],"con":true,"img":false}]}
{"op":"mcm","clk":"11541117752","pt":1719502418663,"mc":[{"id":"1.230180127","rc":[{"atb":[[1.19,2]],"id":66993945}],"con":true,"img":false}]}
{"op":"mcm","clk":"11541117819","pt":1719502419753,"mc":[{"id":"1.230180127","rc":[{"atb":[[1.02,0]],"id":49823335}],"con":true,"img":false}]}
{"op":"mcm","clk":"11541117823","pt":1719502419855,"mc":[{"id":"1.230180127","rc":[{"atb":[[1.85,2.34]],"id":49823335}],"con":true,"img":false}]}
{"op":"mcm","clk":"11541117854","pt":1719502420223,"mc":[{"id":"1.230180127","rc":[{"atb":[[1.19,0]],"id":66993945}],"con":true,"img":false}]}
{"op":"mcm","clk":"11541117861","pt":1719502420324,"mc":[{"id":"1.230180127","rc":[{"atb":[[1.21,2]],"id":66993945}],"con":true,"img":false}]}
{"op":"mcm","clk":"11541117933","pt":1719502421563,"mc":[{"id":"1.230180127","rc":[{"atb":[[1.2,0.25]],"id":66993945},{"atl":[[8.4,0]],"id":66993945},{"atb":[[1.85,2]],"id":49823335},{"atl":[[20,0]],"id":49823335},{"atb":[[1.86,1]],"id":62886137},{"atl":[[24,0]],"id":62886137}],"con":true,"img":false}]}
{"op":"mcm","clk":"11541117948","pt":1719502421824,"mc":[{"id":"1.230180127","rc":[{"atb":[[1.85,0]],"id":49823335}],"con":true,"img":false}]}
{"op":"mcm","clk":"11541117953","pt":1719502421933,"mc":[{"id":"1.230180127","rc":[{"atb":[[1.02,2]],"id":49823335}],"con":true,"img":false}]}
{"op":"mcm","clk":"11541117971","pt":1719502422237,"mc":[{"id":"1.230180127","rc":[{"atb":[[1.21,0]],"id":66993945}],"con":true,"img":false}]}
{"op":"mcm","clk":"11541117977","pt":1719502422341,"mc":[{"id":"1.230180127","rc":[{"atb":[[1.19,2]],"id":66993945}],"con":true,"img":false}]}
{"op":"mcm","clk":"11541118043","pt":1719502423368,"mc":[{"id":"1.230180127","rc":[{"atb":[[1.02,0]],"id":49823335}],"con":true,"img":false}]}
{"op":"mcm","clk":"11541118052","pt":1719502423466,"mc":[{"id":"1.230180127","rc":[{"atb":[[1.85,2]],"id":49823335}],"con":true,"img":false}]}
{"op":"mcm","clk":"11541118196","pt":1719502425068,"mc":[{"id":"1.230180127","rc":[{"atb":[[1.85,0]],"id":49823335}],"con":true,"img":false}]}
{"op":"mcm","clk":"11541118208","pt":1719502425185,"mc":[{"id":"1.230180127","rc":[{"atb":[[1.02,2]],"id":49823335}],"con":true,"img":false}]}
{"op":"mcm","clk":"11541118297","pt":1719502426268,"mc":[{"id":"1.230180127","rc":[{"atb":[[1.02,0]],"id":49823335}],"con":true,"img":false}]}
{"op":"mcm","clk":"11541118306","pt":1719502426381,"mc":[{"id":"1.230180127","rc":[{"atb":[[1.85,2]],"id":49823335}],"con":true,"img":false}]}
{"op":"mcm","clk":"11541118422","pt":1719502427766,"mc":[{"id":"1.230180127","rc":[{"atb":[[1.85,0]],"id":49823335}],"con":true,"img":false}]}
{"op":"mcm","clk":"11541118433","pt":1719502427868,"mc":[{"id":"1.230180127","rc":[{"atb":[[1.02,2]],"id":49823335}],"con":true,"img":false}]}
{"op":"mcm","clk":"11541118536","pt":1719502429060,"mc":[{"id":"1.230180127","rc":[{"atb":[[1.02,0]],"id":49823335}],"con":true,"img":false}]}
{"op":"mcm","clk":"11541118544","pt":1719502429165,"mc":[{"id":"1.230180127","rc":[{"atb":[[1.85,2]],"id":49823335}],"con":true,"img":false}]}
{"op":"mcm","clk":"11541118674","pt":1719502430669,"mc":[{"id":"1.230180127","rc":[{"atb":[[1.85,0]],"id":49823335}],"con":true,"img":false}]}
{"op":"mcm","clk":"11541118685","pt":1719502430774,"mc":[{"id":"1.230180127","rc":[{"atb":[[1.02,2]],"id":49823335}],"con":true,"img":false}]}
{"op":"mcm","clk":"11541118749","pt":1719502431662,"mc":[{"id":"1.230180127","rc":[{"atb":[[1.02,0]],"id":49823335}],"con":true,"img":false}]}
{"op":"mcm","clk":"11541118758","pt":1719502431765,"mc":[{"id":"1.230180127","rc":[{"atb":[[1.85,2]],"id":49823335}],"con":true,"img":false}]}
{"op":"mcm","clk":"11541118844","pt":1719502432957,"mc":[{"id":"1.230180127","rc":[{"atb":[[1.85,0]],"id":49823335}],"con":true,"img":false}]}
{"op":"mcm","clk":"11541118851","pt":1719502433056,"mc":[{"id":"1.230180127","rc":[{"atb":[[1.02,2]],"id":49823335}],"con":true,"img":false}]}
{"op":"mcm","clk":"11541118979","pt":1719502434662,"mc":[{"id":"1.230180127","rc":[{"atb":[[1.02,0]],"id":49823335}],"con":true,"img":false}]}
{"op":"mcm","clk":"11541118987","pt":1719502434766,"mc":[{"id":"1.230180127","rc":[{"atb":[[1.85,2]],"id":49823335}],"con":true,"img":false}]}
{"op":"mcm","clk":"11541119094","pt":1719502436062,"mc":[{"id":"1.230180127","rc":[{"atb":[[1.85,0]],"id":49823335}],"con":true,"img":false}]}
{"op":"mcm","clk":"11541119102","pt":1719502436165,"mc":[{"id":"1.230180127","rc":[{"atb":[[1.02,2]],"id":49823335}],"con":true,"img":false}]}
{"op":"mcm","clk":"11541119202","pt":1719502437452,"mc":[{"id":"1.230180127","rc":[{"atb":[[1.02,0]],"id":49823335}],"con":true,"img":false}]}
{"op":"mcm","clk":"11541119210","pt":1719502437556,"mc":[{"id":"1.230180127","rc":[{"atb":[[1.85,2]],"id":49823335}],"con":true,"img":false}]}
{"op":"mcm","clk":"11541119318","pt":1719502438755,"mc":[{"id":"1.230180127","rc":[{"atb":[[1.85,0]],"id":49823335}],"con":true,"img":false}]}
{"op":"mcm","clk":"11541119327","pt":1719502438858,"mc":[{"id":"1.230180127","rc":[{"atb":[[1.02,2]],"id":49823335}],"con":true,"img":false}]}
{"op":"mcm","clk":"11541119422","pt":1719502439985,"mc":[{"id":"1.230180127","rc":[{"atb":[[1.02,0]],"id":49823335}],"con":true,"img":false}]}
{"op":"mcm","clk":"11541119433","pt":1719502440046,"mc":[{"id":"1.230180127","rc":[{"atb":[[1.85,2]],"id":49823335}],"con":true,"img":false}]}
{"op":"mcm","clk":"11541119565","pt":1719502441663,"mc":[{"id":"1.230180127","rc":[{"atb":[[1.85,0]],"id":49823335}],"con":true,"img":false}]}
{"op":"mcm","clk":"11541119578","pt":1719502441765,"mc":[{"id":"1.230180127","rc":[{"atb":[[1.02,2]],"id":49823335}],"con":true,"img":false}]}
{"op":"mcm","clk":"11541119624","pt":1719502442380,"mc":[{"id":"1.230180127","rc":[{"atb":[[1.81,0]],"id":62886137}],"con":true,"img":false}]}
{"op":"mcm","clk":"11541119684","pt":1719502443154,"mc":[{"id":"1.230180127","rc":[{"atb":[[1.02,0]],"id":49823335}],"con":true,"img":false}]}
{"op":"mcm","clk":"11541119697","pt":1719502443263,"mc":[{"id":"1.230180127","rc":[{"atb":[[1.85,2]],"id":49823335}],"con":true,"img":false}]}
{"op":"mcm","clk":"11541119859","pt":1719502444976,"mc":[{"id":"1.230180127","rc":[{"atb":[[1.85,0]],"id":49823335}],"con":true,"img":false}]}
{"op":"mcm","clk":"11541119864","pt":1719502445073,"mc":[{"id":"1.230180127","rc":[{"atb":[[1.02,2]],"id":49823335}],"con":true,"img":false}]}
{"op":"mcm","clk":"11541119978","pt":1719502446585,"mc":[{"id":"1.230180127","rc":[{"atb":[[1.02,0]],"id":49823335}],"con":true,"img":false}]}
{"op":"mcm","clk":"11541119990","pt":1719502446688,"mc":[{"id":"1.230180127","rc":[{"atb":[[1.85,2]],"id":49823335}],"con":true,"img":false}]}
{"op":"mcm","clk":"11541120086","pt":1719502447890,"mc":[{"id":"1.230180127","rc":[{"atb":[[1.85,0]],"id":49823335}],"con":true,"img":false}]}
{"op":"mcm","clk":"11541120098","pt":1719502447993,"mc":[{"id":"1.230180127","rc":[{"atb":[[1.02,2]],"id":49823335}],"con":true,"img":false}]}
{"op":"mcm","clk":"11541120242","pt":1719502449649,"mc":[{"id":"1.230180127","rc":[{"atb":[[1.02,0]],"id":49823335}],"con":true,"img":false}]}
{"op":"mcm","clk":"11541120251","pt":1719502449751,"mc":[{"id":"1.230180127","rc":[{"atb":[[1.85,2]],"id":49823335}],"con":true,"img":false}]}
{"op":"mcm","clk":"11541120306","pt":1719502450475,"mc":[{"id":"1.230180127","rc":[{"atb":[[1.08,50]],"id":66993945},{"atb":[[1.08,50]],"id":49823335},{"atb":[[1.08,50]],"id":64851267},{"atb":[[1.08,50]],"id":62886137},{"atb":[[1.08,50]],"id":61941224},{"atb":[[1.08,50]],"id":69475504}],"con":true,"img":false}]}
{"op":"mcm","clk":"11541120397","pt":1719502451794,"mc":[{"id":"1.230180127","rc":[{"atb":[[1.85,0]],"id":49823335}],"con":true,"img":false}]}
{"op":"mcm","clk":"11541120406","pt":1719502451858,"mc":[{"id":"1.230180127","rc":[{"atb":[[1.02,2]],"id":49823335}],"con":true,"img":false}]}
{"op":"mcm","clk":"11541120498","pt":1719502453301,"mc":[{"id":"1.230180127","rc":[{"atb":[[1.02,0]],"id":49823335}],"con":true,"img":false}]}
{"op":"mcm","clk":"11541120505","pt":1719502453349,"mc":[{"id":"1.230180127","rc":[{"atb":[[1.85,2]],"id":49823335}],"con":true,"img":false}]}
{"op":"mcm","clk":"11541120598","pt":1719502454697,"mc":[{"id":"1.230180127","rc":[{"atb":[[1.85,0]],"id":49823335}],"con":true,"img":false}]}
{"op":"mcm","clk":"11541120605","pt":1719502454796,"mc":[{"id":"1.230180127","rc":[{"atb":[[1.02,2]],"id":49823335}],"con":true,"img":false}]}
{"op":"mcm","clk":"11541120698","pt":1719502455884,"mc":[{"id":"1.230180127","rc":[{"atb":[[1.83,0]],"id":62886137}],"con":true,"img":false}]}
{"op":"mcm","clk":"11541120725","pt":1719502456295,"mc":[{"id":"1.230180127","rc":[{"atb":[[1.02,0]],"id":49823335}],"con":true,"img":false}]}
{"op":"mcm","clk":"11541120732","pt":1719502456399,"mc":[{"id":"1.230180127","rc":[{"atb":[[1.85,2]],"id":49823335}],"con":true,"img":false}]}
{"op":"mcm","clk":"11541120896","pt":1719502458688,"mc":[{"id":"1.230180127","rc":[{"atb":[[1.85,0]],"id":62886137}],"con":true,"img":false}]}
{"op":"mcm","clk":"11541120904","pt":1719502458787,"mc":[{"id":"1.230180127","rc":[{"atb":[[1.02,2]],"id":62886137}],"con":true,"img":false}]}
{"op":"mcm","clk":"11541120925","pt":1719502459098,"mc":[{"id":"1.230180127","rc":[{"atb":[[1.85,0]],"id":49823335}],"con":true,"img":false}]}
{"op":"mcm","clk":"11541120934","pt":1719502459200,"mc":[{"id":"1.230180127","rc":[{"atb":[[1.02,2]],"id":49823335}],"con":true,"img":false}]}
{"op":"mcm","clk":"11541121011","pt":1719502460385,"mc":[{"id":"1.230180127","rc":[{"atb":[[1.02,0]],"id":62886137}],"con":true,"img":false}]}
{"op":"mcm","clk":"11541121020","pt":1719502460488,"mc":[{"id":"1.230180127","rc":[{"atb":[[1.85,2]],"id":62886137}],"con":true,"img":false}]}
{"op":"mcm","clk":"11541121046","pt":1719502460903,"mc":[{"id":"1.230180127","rc":[{"atb":[[1.02,0]],"id":49823335}],"con":true,"img":false}]}
{"op":"mcm","clk":"11541121053","pt":1719502460958,"mc":[{"id":"1.230180127","rc":[{"atb":[[1.85,2]],"id":49823335}],"con":true,"img":false}]}
{"op":"mcm","clk":"11541121184","pt":1719502462980,"mc":[{"id":"1.230180127","rc":[{"atb":[[1.85,0]],"id":62886137}],"con":true,"img":false}]}
{"op":"mcm","clk":"11541121195","pt":1719502463089,"mc":[{"id":"1.230180127","rc":[{"atb":[[1.02,2]],"id":62886137}],"con":true,"img":false}]}
{"op":"mcm","clk":"11541121249","pt":1719502463702,"mc":[{"id":"1.230180127","rc":[{"atb":[[1.85,0]],"id":49823335}],"con":true,"img":false}]}
{"op":"mcm","clk":"11541121260","pt":1719502463760,"mc":[{"id":"1.230180127","rc":[{"atb":[[1.02,2]],"id":49823335}],"con":true,"img":false}]}
{"op":"mcm","clk":"11541121433","pt":1719502466188,"mc":[{"id":"1.230180127","rc":[{"atb":[[1.02,0]],"id":62886137}],"con":true,"img":false}]}
{"op":"mcm","clk":"11541121441","pt":1719502466287,"mc":[{"id":"1.230180127","rc":[{"atb":[[1.85,2]],"id":62886137}],"con":true,"img":false}]}
{"op":"mcm","clk":"11541121456","pt":1719502466609,"mc":[{"id":"1.230180127","rc":[{"atb":[[1.02,0]],"id":49823335}],"con":true,"img":false}]}
{"op":"mcm","clk":"11541121469","pt":1719502466707,"mc":[{"id":"1.230180127","rc":[{"atb":[[1.85,2]],"id":49823335}],"con":true,"img":false}]}
{"op":"mcm","clk":"11541121564","pt":1719502467994,"mc":[{"id":"1.230180127","rc":[{"atb":[[1.85,0]],"id":62886137}],"con":true,"img":false}]}
{"op":"mcm","clk":"11541121571","pt":1719502468102,"mc":[{"id":"1.230180127","rc":[{"atb":[[1.02,2]],"id":62886137}],"con":true,"img":false}]}
{"op":"mcm","clk":"11541121592","pt":1719502468359,"mc":[{"id":"1.230180127","rc":[{"atb":[[1.85,0]],"id":49823335}],"con":true,"img":false}]}
{"op":"mcm","clk":"11541121599","pt":1719502468466,"mc":[{"id":"1.230180127","rc":[{"atb":[[1.02,2]],"id":49823335}],"con":true,"img":false}]}
{"op":"mcm","clk":"11541121684","pt":1719502469696,"mc":[{"id":"1.230180127","rc":[{"atb":[[1.02,0]],"id":62886137}],"con":true,"img":false}]}
{"op":"mcm","clk":"11541121692","pt":1719502469798,"mc":[{"id":"1.230180127","rc":[{"atb":[[1.85,2]],"id":62886137}],"con":true,"img":false}]}
{"op":"mcm","clk":"11541121707","pt":1719502470006,"mc":[{"id":"1.230180127","rc":[{"atb":[[1.02,0]],"id":49823335}],"con":true,"img":false}]}
{"op":"mcm","clk":"11541121718","pt":1719502470109,"mc":[{"id":"1.230180127","rc":[{"atb":[[1.85,2]],"id":49823335}],"con":true,"img":false}]}
{"op":"mcm","clk":"11541121786","pt":1719502471195,"mc":[{"id":"1.230180127","rc":[{"atb":[[1.85,0]],"id":62886137}],"con":true,"img":false}]}
{"op":"mcm","clk":"11541121790","pt":1719502471301,"mc":[{"id":"1.230180127","rc":[{"atb":[[1.02,2]],"id":62886137}],"con":true,"img":false}]}
{"op":"mcm","clk":"11541121828","pt":1719502471714,"mc":[{"id":"1.230180127","rc":[{"atb":[[1.85,0]],"id":49823335}],"con":true,"img":false}]}
{"op":"mcm","clk":"11541121837","pt":1719502471772,"mc":[{"id":"1.230180127","rc":[{"atb":[[1.02,2]],"id":49823335}],"con":true,"img":false}]}
{"op":"mcm","clk":"11541121944","pt":1719502473315,"mc":[{"id":"1.230180127","rc":[{"atb":[[1.02,0]],"id":62886137}],"con":true,"img":false}]}
{"op":"mcm","clk":"11541121954","pt":1719502473370,"mc":[{"id":"1.230180127","rc":[{"atb":[[1.85,2]],"id":62886137}],"con":true,"img":false}]}
{"op":"mcm","clk":"11541121959","pt":1719502473478,"mc":[{"id":"1.230180127","rc":[{"atb":[[1.81,2.5]],"id":49823335}],"con":true,"img":false}]}
{"op":"mcm","clk":"11541121971","pt":1719502473684,"mc":[{"id":"1.230180127","rc":[{"atb":[[1.81,0]],"id":49823335}],"con":true,"img":false}]}
{"op":"mcm","clk":"11541121999","pt":1719502473994,"mc":[{"id":"1.230180127","rc":[{"atb":[[1.02,0]],"id":49823335}],"con":true,"img":false}]}
{"op":"mcm","clk":"11541122006","pt":1719502474101,"mc":[{"id":"1.230180127","rc":[{"atb":[[1.85,2]],"id":49823335}],"con":true,"img":false}]}
{"op":"mcm","clk":"11541122107","pt":1719502475491,"mc":[{"id":"1.230180127","rc":[{"atb":[[1.85,0]],"id":62886137}],"con":true,"img":false}]}
{"op":"mcm","clk":"11541122120","pt":1719502475691,"mc":[{"id":"1.230180127","rc":[{"atb":[[1.02,2]],"id":62886137}],"con":true,"img":false}]}
{"op":"mcm","clk":"11541122163","pt":1719502476208,"mc":[{"id":"1.230180127","rc":[{"atb":[[1.85,0]],"id":49823335}],"con":true,"img":false}]}
{"op":"mcm","clk":"11541122174","pt":1719502476311,"mc":[{"id":"1.230180127","rc":[{"atb":[[1.02,2]],"id":49823335}],"con":true,"img":false}]}
{"op":"mcm","clk":"11541122311","pt":1719502478217,"mc":[{"id":"1.230180127","rc":[{"atb":[[1.02,0]],"id":62886137}],"con":true,"img":false}]}
{"op":"mcm","clk":"11541122316","pt":1719502478325,"mc":[{"id":"1.230180127","rc":[{"atb":[[1.85,2]],"id":62886137}],"con":true,"img":false}]}
{"op":"mcm","clk":"11541122339","pt":1719502478578,"mc":[{"id":"1.230180127","rc":[{"atb":[[1.02,0]],"id":49823335}],"con":true,"img":false}]}
{"op":"mcm","clk":"11541122347","pt":1719502478689,"mc":[{"id":"1.230180127","rc":[{"atb":[[1.85,2]],"id":49823335}],"con":true,"img":false}]}
{"op":"mcm","clk":"11541122449","pt":1719502480292,"mc":[{"id":"1.230180127","rc":[{"atb":[[1.85,0]],"id":62886137}],"con":true,"img":false}]}
{"op":"mcm","clk":"11541122457","pt":1719502480390,"mc":[{"id":"1.230180127","rc":[{"atb":[[1.02,2]],"id":62886137}],"con":true,"img":false}]}
{"op":"mcm","clk":"11541122486","pt":1719502480696,"mc":[{"id":"1.230180127","rc":[{"atb":[[1.85,0]],"id":49823335}],"con":true,"img":false}]}
{"op":"mcm","clk":"11541122495","pt":1719502480799,"mc":[{"id":"1.230180127","rc":[{"atb":[[1.02,2]],"id":49823335}],"con":true,"img":false}]}
{"op":"mcm","clk":"11541122684","pt":1719502483222,"mc":[{"id":"1.230180127","rc":[{"atb":[[1.02,0]],"id":62886137}],"con":true,"img":false}]}
{"op":"mcm","clk":"11541122695","pt":1719502483324,"mc":[{"id":"1.230180127","rc":[{"atb":[[1.85,2]],"id":62886137}],"con":true,"img":false}]}
{"op":"mcm","clk":"11541122737","pt":1719502483893,"mc":[{"id":"1.230180127","rc":[{"atb":[[1.02,0]],"id":49823335}],"con":true,"img":false}]}
{"op":"mcm","clk":"11541122747","pt":1719502483996,"mc":[{"id":"1.230180127","rc":[{"atb":[[1.85,2]],"id":49823335}],"con":true,"img":false}]}
{"op":"mcm","clk":"11541122874","pt":1719502486013,"mc":[{"id":"1.230180127","rc":[{"atb":[[1.85,0]],"id":62886137}],"con":true,"img":false}]}
{"op":"mcm","clk":"11541122882","pt":1719502486117,"mc":[{"id":"1.230180127","rc":[{"atb":[[1.02,2]],"id":62886137}],"con":true,"img":false}]}
{"op":"mcm","clk":"11541122917","pt":1719502486536,"mc":[{"id":"1.230180127","rc":[{"atb":[[1.85,0]],"id":49823335}],"con":true,"img":false}]}
{"op":"mcm","clk":"11541122928","pt":1719502486587,"mc":[{"id":"1.230180127","rc":[{"atb":[[1.02,2]],"id":49823335}],"con":true,"img":false}]}
{"op":"mcm","clk":"11541123005","pt":1719502487721,"mc":[{"id":"1.230180127","rc":[{"atb":[[1.02,0]],"id":62886137}],"con":true,"img":false}]}
{"op":"mcm","clk":"11541123011","pt":1719502487819,"mc":[{"id":"1.230180127","rc":[{"atb":[[1.85,2]],"id":62886137}],"con":true,"img":false}]}
{"op":"mcm","clk":"11541123046","pt":1719502488289,"mc":[{"id":"1.230180127","rc":[{"atb":[[1.02,0]],"id":49823335}],"con":true,"img":false}]}
{"op":"mcm","clk":"11541123055","pt":1719502488388,"mc":[{"id":"1.230180127","rc":[{"atb":[[1.85,2]],"id":49823335}],"con":true,"img":false}]}
{"op":"mcm","clk":"11541123156","pt":1719502489724,"mc":[{"id":"1.230180127","rc":[{"atb":[[1.85,0]],"id":62886137}],"con":true,"img":false}]}
{"op":"mcm","clk":"11541123163","pt":1719502489836,"mc":[{"id":"1.230180127","rc":[{"atb":[[1.02,2]],"id":62886137}],"con":true,"img":false}]}
{"op":"mcm","clk":"11541123188","pt":1719502490093,"mc":[{"id":"1.230180127","rc":[{"atb":[[1.85,0]],"id":49823335}],"con":true,"img":false}]}
{"op":"mcm","clk":"11541123195","pt":1719502490199,"mc":[{"id":"1.230180127","rc":[{"atb":[[1.02,2]],"id":49823335}],"con":true,"img":false}]}
{"op":"mcm","clk":"11541123323","pt":1719502491796,"mc":[{"id":"1.230180127","rc":[{"atb":[[1.02,0]],"id":62886137}],"con":true,"img":false}]}
{"op":"mcm","clk":"11541123332","pt":1719502491907,"mc":[{"id":"1.230180127","rc":[{"atb":[[1.85,2]],"id":62886137}],"con":true,"img":false}]}
{"op":"mcm","clk":"11541123351","pt":1719502492210,"mc":[{"id":"1.230180127","rc":[{"atb":[[1.02,0]],"id":49823335}],"con":true,"img":false}]}
{"op":"mcm","clk":"11541123358","pt":1719502492315,"mc":[{"id":"1.230180127","rc":[{"atb":[[1.85,2]],"id":49823335}],"con":true,"img":false}]}
{"op":"mcm","clk":"11541123547","pt":1719502494431,"mc":[{"id":"1.230180127","rc":[{"atb":[[1.85,0]],"id":62886137}],"con":true,"img":false}]}
{"op":"mcm","clk":"11541123556","pt":1719502494538,"mc":[{"id":"1.230180127","rc":[{"atb":[[1.02,2]],"id":62886137}],"con":true,"img":false}]}
{"op":"mcm","clk":"11541123584","pt":1719502494899,"mc":[{"id":"1.230180127","rc":[{"atb":[[1.85,0]],"id":49823335}],"con":true,"img":false}]}
{"op":"mcm","clk":"11541123591","pt":1719502495001,"mc":[{"id":"1.230180127","rc":[{"atb":[[1.02,2]],"id":49823335}],"con":true,"img":false}]}
{"op":"mcm","clk":"11541123794","pt":1719502497430,"mc":[{"id":"1.230180127","rc":[{"atb":[[1.02,0]],"id":62886137}],"con":true,"img":false}]}
{"op":"mcm","clk":"11541123803","pt":1719502497538,"mc":[{"id":"1.230180127","rc":[{"atb":[[1.85,2]],"id":62886137}],"con":true,"img":false}]}
{"op":"mcm","clk":"11541123819","pt":1719502497744,"mc":[{"id":"1.230180127","rc":[{"atb":[[1.02,0]],"id":49823335}],"con":true,"img":false}]}
{"op":"mcm","clk":"11541123828","pt":1719502497846,"mc":[{"id":"1.230180127","rc":[{"atb":[[1.85,2]],"id":49823335}],"con":true,"img":false}]}
{"op":"mcm","clk":"11541123959","pt":1719502499700,"mc":[{"id":"1.230180127","rc":[{"atb":[[1.85,0]],"id":62886137}],"con":true,"img":false}]}
{"op":"mcm","clk":"11541123968","pt":1719502499803,"mc":[{"id":"1.230180127","rc":[{"atb":[[1.02,2]],"id":62886137}],"con":true,"img":false}]}
{"op":"mcm","clk":"11541123992","pt":1719502500218,"mc":[{"id":"1.230180127","rc":[{"atb":[[1.85,0]],"id":49823335}],"con":true,"img":false}]}
{"op":"mcm","clk":"11541124003","pt":1719502500320,"mc":[{"id":"1.230180127","rc":[{"atb":[[1.02,2]],"id":49823335}],"con":true,"img":false}]}
{"op":"mcm","clk":"11541124235","pt":1719502503017,"mc":[{"id":"1.230180127","rc":[{"atb":[[1.02,0]],"id":62886137}],"con":true,"img":false}]}
{"op":"mcm","clk":"11541124240","pt":1719502503120,"mc":[{"id":"1.230180127","rc":[{"atb":[[1.85,2]],"id":62886137}],"con":true,"img":false}]}
{"op":"mcm","clk":"11541124259","pt":1719502503328,"mc":[{"id":"1.230180127","rc":[{"atb":[[1.02,0]],"id":49823335}],"con":true,"img":false}]}
{"op":"mcm","clk":"11541124267","pt":1719502503431,"mc":[{"id":"1.230180127","rc":[{"atb":[[1.85,2]],"id":49823335}],"con":true,"img":false}]}
{"op":"mcm","clk":"11541124362","pt":1719502504542,"mc":[{"id":"1.230180127","rc":[{"atb":[[1.85,0]],"id":62886137}],"con":true,"img":false}]}
{"op":"mcm","clk":"11541124372","pt":1719502504640,"mc":[{"id":"1.230180127","rc":[{"atb":[[1.01,1.7]],"id":66993945},{"atl":[[1000,1.7]],"id":66993945},{"atb":[[1.01,53.59]],"id":49823335},{"atl":[[1000,1.94]],"id":49823335},{"atb":[[1.01,1.7],[1.02,2]],"id":62886137},{"atl":[[1000,1.94]],"id":62886137}],"con":true,"img":false}]}
{"op":"mcm","clk":"11541124397","pt":1719502504948,"mc":[{"id":"1.230180127","rc":[{"atb":[[1.01,1.41]],"id":66993945},{"atl":[[1000,0.25]],"id":49823335},{"atl":[[1000,0.24]],"id":62886137}],"con":true,"img":false}]}
{"op":"mcm","clk":"11541124405","pt":1719502505006,"mc":[{"id":"1.230180127","rc":[{"atl":[[1000,0.03]],"id":66993945},{"atb":[[1.01,52.21],[1.85,0]],"id":49823335},{"spn":1.2,"spf":1.0,"id":64851267},{"atb":[[1.01,0.33]],"id":62886137}],"con":true,"img":false}]}
{"op":"mcm","clk":"11541124415","pt":1719502505107,"mc":[{"id":"1.230180127","rc":[{"atb":[[1.01,0]],"id":66993945},{"atb":[[1.02,2]],"id":49823335},{"atl":[[1000,0.23]],"id":49823335},{"atl":[[1000,0.23]],"id":62886137}],"con":true,"img":false}]}
{"op":"mcm","clk":"11541124425","pt":1719502505213,"mc":[{"id":"1.230180127","rc":[{"atb":[[1.2,1.66]],"id":66993945},{"atl":[[1000,0]],"id":66993945},{"atb":[[1.01,51.88]],"id":49823335},{"atl":[[20,0.01]],"id":49823335},{"atb":[[1.01,0]],"id":62886137},{"atl":[[24,0.01]],"id":62886137}],"con":true,"img":false}]}
{"op":"mcm","clk":"11541124436","pt":1719502505316,"mc":[{"id":"1.230180127","rc":[{"atl":[[8.4,0.03]],"id":66993945},{"atb":[[1.86,1.33]],"id":49823335},{"atb":[[1.86,1.33]],"id":62886137}],"con":true,"img":false}]}
{"op":"mcm","clk":"11541124531","pt":1719502506613,"mc":[{"id":"1.230180127","rc":[{"atb":[[1.02,0]],"id":62886137}],"con":true,"img":false}]}
{"op":"mcm","clk":"11541124538","pt":1719502506724,"mc":[{"id":"1.230180127","rc":[{"atb":[[1.85,2]],"id":62886137}],"con":true,"img":false}]}
{"op":"mcm","clk":"11541124556","pt":1719502506919,"mc":[{"id":"1.230180127","rc":[{"atb":[[1.02,0]],"id":49823335}],"con":true,"img":false}]}
{"op":"mcm","clk":"11541124567","pt":1719502507020,"mc":[{"id":"1.230180127","rc":[{"atb":[[1.85,2]],"id":49823335}],"con":true,"img":false}]}
{"op":"mcm","clk":"11541124586","pt":1719502507334,"mc":[{"id":"1.230180127","rc":[{"atb":[[1.19,0]],"id":66993945}],"con":true,"img":false}]}
{"op":"mcm","clk":"11541124591","pt":1719502507433,"mc":[{"id":"1.230180127","rc":[{"atb":[[1.21,2]],"id":66993945}],"con":true,"img":false}]}
{"op":"mcm","clk":"11541124669","pt":1719502508423,"mc":[{"id":"1.230180127","rc":[{"atb":[[1.85,0]],"id":62886137}],"con":true,"img":false}]}
{"op":"mcm","clk":"11541124674","pt":1719502508524,"mc":[{"id":"1.230180127","rc":[{"atb":[[1.02,2]],"id":62886137}],"con":true,"img":false}]}
{"op":"mcm","clk":"11541124699","pt":1719502508937,"mc":[{"id":"1.230180127","rc":[{"atb":[[1.85,0]],"id":49823335}],"con":true,"img":false}]}
{"op":"mcm","clk":"11541124708","pt":1719502509039,"mc":[{"id":"1.230180127","rc":[{"atb":[[1.02,2]],"id":49823335}],"con":true,"img":false}]}
{"op":"mcm","clk":"11541124739","pt":1719502509445,"mc":[{"id":"1.230180127","rc":[{"atb":[[1.21,0]],"id":66993945}],"con":true,"img":false}]}
{"op":"mcm","clk":"11541124749","pt":1719502509555,"mc":[{"id":"1.230180127","rc":[{"atb":[[1.19,2]],"id":66993945}],"con":true,"img":false}]}
{"op":"mcm","clk":"11541124926","pt":1719502511826,"mc":[{"id":"1.230180127","rc":[{"atb":[[1.02,0]],"id":62886137}],"con":true,"img":false}]}
{"op":"mcm","clk":"11541124935","pt":1719502511923,"mc":[{"id":"1.230180127","rc":[{"atb":[[1.85,2]],"id":62886137}],"con":true,"img":false}]}
{"op":"mcm","clk":"11541124949","pt":1719502512237,"mc":[{"id":"1.230180127","rc":[{"atb":[[1.02,0]],"id":49823335}],"con":true,"img":false}]}
{"op":"mcm","clk":"11541124957","pt":1719502512336,"mc":[{"id":"1.230180127","rc":[{"atb":[[1.85,2]],"id":49823335}],"con":true,"img":false}]}
{"op":"mcm","clk":"11541124994","pt":1719502512953,"mc":[{"id":"1.230180127","rc":[{"atb":[[1.19,0]],"id":66993945}],"con":true,"img":false}]}
{"op":"mcm","clk":"11541125000","pt":1719502513056,"mc":[{"id":"1.230180127","rc":[{"atb":[[1.21,2]],"id":66993945}],"con":true,"img":false}]}
{"op":"mcm","clk":"11541125179","pt":1719502515538,"mc":[{"id":"1.230180127","rc":[{"atb":[[1.85,0]],"id":62886137}],"con":true,"img":false}]}
{"op":"mcm","clk":"11541125186","pt":1719502515645,"mc":[{"id":"1.230180127","rc":[{"atb":[[1.02,2]],"id":62886137}],"con":true,"img":false}]}
{"op":"mcm","clk":"11541125211","pt":1719502515955,"mc":[{"id":"1.230180127","rc":[{"atb":[[1.85,0]],"id":49823335}],"con":true,"img":false}]}
{"op":"mcm","clk":"11541125221","pt":1719502516051,"mc":[{"id":"1.230180127","rc":[{"atb":[[1.02,2]],"id":49823335}],"con":true,"img":false}]}
{"op":"mcm","clk":"11541125266","pt":1719502516515,"mc":[{"id":"1.230180127","rc":[{"atb":[[1.21,0]],"id":66993945}],"con":true,"img":false}]}
{"op":"mcm","clk":"11541125274","pt":1719502516620,"mc":[{"id":"1.230180127","rc":[{"atb":[[1.19,2]],"id":66993945}],"con":true,"img":false}]}
{"op":"mcm","clk":"11541125312","pt":1719502517135,"mc":[{"id":"1.230180127","rc":[{"atb":[[1.52,7.6]],"id":64851267},{"atb":[[1.86,5.92]],"id":62886137}],"con":true,"img":false}]}
{"op":"mcm","clk":"11541125317","pt":1719502517246,"mc":[{"id":"1.230180127","rc":[{"atb":[[1.5,0],[1.53,2]],"id":64851267},{"atb":[[1.87,5.92]],"id":62886137}],"con":true,"img":false}]}
{"op":"mcm","clk":"11541125325","pt":1719502517341,"mc":[{"id":"1.230180127","rc":[{"atb":[[1.84,2.11]],"id":62886137}],"con":true,"img":false}]}
{"op":"mcm","clk":"11541125343","pt":1719502517650,"mc":[{"id":"1.230180127","rc":[{"atb":[[1.44,2.11]],"id":64851267}],"con":true,"img":false}]}
{"op":"mcm","clk":"11541125357","pt":1719502517861,"mc":[{"id":"1.230180127","rc":[{"atb":[[1.02,0]],"id":62886137}],"con":true,"img":false}]}
{"op":"mcm","clk":"11541125365","pt":1719502517959,"mc":[{"id":"1.230180127","rc":[{"atb":[[1.88,2]],"id":62886137}],"con":true,"img":false}]}
{"op":"mcm","clk":"11541125386","pt":1719502518221,"mc":[{"id":"1.230180127","rc":[{"atb":[[1.02,0]],"id":49823335}],"con":true,"img":false}]}
{"op":"mcm","clk":"11541125392","pt":1719502518321,"mc":[{"id":"1.230180127","rc":[{"atb":[[1.85,2]],"id":49823335}],"con":true,"img":false}]}
{"op":"mcm","clk":"11541125408","pt":1719502518529,"mc":[{"id":"1.230180127","rc":[{"atb":[[1.19,0]],"id":66993945}],"con":true,"img":false}]}
{"op":"mcm","clk":"11541125415","pt":1719502518633,"mc":[{"id":"1.230180127","rc":[{"atb":[[1.21,2]],"id":66993945}],"con":true,"img":false}]}
{"op":"mcm","clk":"11541125485","pt":1719502519654,"mc":[{"id":"1.230180127","rc":[{"atb":[[1.25,3]],"id":66993945},{"atb":[[1.53,4]],"id":64851267},{"atb":[[1.86,2.3]],"id":61941224}],"con":true,"img":false}]}
{"op":"mcm","clk":"11541125492","pt":1719502519763,"mc":[{"id":"1.230180127","rc":[{"atb":[[1.25,5]],"id":66993945}],"con":true,"img":false}]}
{"op":"mcm","clk":"11541125502","pt":1719502519859,"mc":[{"id":"1.230180127","rc":[{"atb":[[1.18,0]],"id":66993945}],"con":true,"img":false}]}
{"op":"mcm","clk":"11541125509","pt":1719502519968,"mc":[{"id":"1.230180127","rc":[{"atb":[[1.85,0]],"id":49823335}],"con":true,"img":false}]}
{"op":"mcm","clk":"11541125518","pt":1719502520065,"mc":[{"id":"1.230180127","rc":[{"atb":[[1.02,2]],"id":49823335}],"con":true,"img":false}]}
{"op":"mcm","clk":"11541125547","pt":1719502520429,"mc":[{"id":"1.230180127","rc":[{"atb":[[1.21,0]],"id":66993945}],"con":true,"img":false}]}
{"op":"mcm","clk":"11541125552","pt":1719502520528,"mc":[{"id":"1.230180127","rc":[{"atb":[[1.19,2]],"id":66993945}],"con":true,"img":false}]}
{"op":"mcm","clk":"11541125629","pt":1719502521565,"mc":[{"id":"1.230180127","rc":[{"atb":[[1.02,0]],"id":49823335}],"con":true,"img":false}]}
{"op":"mcm","clk":"11541125637","pt":1719502521662,"mc":[{"id":"1.230180127","rc":[{"atb":[[1.85,2]],"id":49823335}],"con":true,"img":false}]}
{"op":"mcm","clk":"11541125656","pt":1719502521922,"mc":[{"id":"1.230180127","rc":[{"atb":[[1.19,0]],"id":66993945}],"con":true,"img":false}]}
{"op":"mcm","clk":"11541125663","pt":1719502522026,"mc":[{"id":"1.230180127","rc":[{"atb":[[1.26,2]],"id":66993945}],"con":true,"img":false}]}
{"op":"mcm","clk":"11541125729","pt":1719502523258,"mc":[{"id":"1.230180127","rc":[{"atb":[[1.85,0]],"id":49823335}],"con":true,"img":false}]}
{"op":"mcm","clk":"11541125736","pt":1719502523360,"mc":[{"id":"1.230180127","rc":[{"atb":[[1.02,2]],"id":49823335}],"con":true,"img":false}]}
{"op":"mcm","clk":"11541125844","pt":1719502524654,"mc":[{"id":"1.230180127","rc":[{"atb":[[1.02,0]],"id":49823335}],"con":true,"img":false}]}
{"op":"mcm","clk":"11541125858","pt":1719502524757,"mc":[{"id":"1.230180127","rc":[{"atb":[[1.85,2]],"id":49823335}],"con":true,"img":false}]}
{"op":"mcm","clk":"11541126006","pt":1719502526872,"mc":[{"id":"1.230180127","rc":[{"atb":[[1.85,0]],"id":49823335}],"con":true,"img":false}]}
{"op":"mcm","clk":"11541126012","pt":1719502526972,"mc":[{"id":"1.230180127","rc":[{"atb":[[1.02,2]],"id":49823335}],"con":true,"img":false}]}
{"op":"mcm","clk":"11541126157","pt":1719502529240,"mc":[{"id":"1.230180127","rc":[{"atb":[[1.02,0]],"id":49823335}],"con":true,"img":false}]}
{"op":"mcm","clk":"11541126163","pt":1719502529341,"mc":[{"id":"1.230180127","rc":[{"atb":[[1.85,2]],"id":49823335}],"con":true,"img":false}]}
{"op":"mcm","clk":"11541126311","pt":1719502531259,"mc":[{"id":"1.230180127","rc":[{"atb":[[1.85,0]],"id":49823335}],"con":true,"img":false}]}
{"op":"mcm","clk":"11541126321","pt":1719502531360,"mc":[{"id":"1.230180127","rc":[{"atb":[[1.02,2]],"id":49823335}],"con":true,"img":false}]}
{"op":"mcm","clk":"11541126486","pt":1719502532974,"mc":[{"id":"1.230180127","rc":[{"atb":[[1.02,0]],"id":49823335}],"con":true,"img":false}]}
{"op":"mcm","clk":"11541126495","pt":1719502533080,"mc":[{"id":"1.230180127","rc":[{"atb":[[1.85,2]],"id":49823335}],"con":true,"img":false}]}
{"op":"mcm","clk":"11541126540","pt":1719502533758,"mc":[{"id":"1.230180127","rc":[{"atb":[[1.25,2]],"id":66993945},{"atb":[[1.53,2]],"id":64851267},{"atb":[[1.86,0]],"id":61941224}],"con":true,"img":false}]}
{"op":"mcm","clk":"11541126599","pt":1719502534678,"mc":[{"id":"1.230180127","rc":[{"atb":[[1.85,0]],"id":49823335}],"con":true,"img":false}]}
{"op":"mcm","clk":"11541126606","pt":1719502534786,"mc":[{"id":"1.230180127","rc":[{"atb":[[1.02,2]],"id":49823335}],"con":true,"img":false}]}
{"op":"mcm","clk":"11541126658","pt":1719502535557,"mc":[{"id":"1.230180127","rc":[{"atb":[[1.86,1.33]],"id":62886137}],"con":true,"img":false}]}
{"op":"mcm","clk":"11541126691","pt":1719502535973,"mc":[{"id":"1.230180127","rc":[{"atb":[[1.28,14.11]],"id":66993945}],"con":true,"img":false}]}
{"op":"mcm","clk":"11541126700","pt":1719502536076,"mc":[{"id":"1.230180127","rc":[{"atb":[[1.25,0],[1.29,2]],"id":66993945}],"con":true,"img":false}]}
{"op":"mcm","clk":"11541126765","pt":1719502537058,"mc":[{"id":"1.230180127","rc":[{"atb":[[1.02,0]],"id":49823335},{"atb":[[1.9,4.39]],"id":62886137}],"con":true,"img":false}]}
{"op":"mcm","clk":"11541126772","pt":1719502537163,"mc":[{"id":"1.230180127","rc":[{"atb":[[1.85,2]],"id":49823335},{"atb":[[1.91,4.4],[1.87,0]],"id":62886137}],"con":true,"img":false}]}
{"op":"mcm","clk":"11541126792","pt":1719502537468,"mc":[{"id":"1.230180127","rc":[{"atb":[[1.26,0]],"id":66993945}],"con":true,"img":false}]}
{"op":"mcm","clk":"11541126798","pt":1719502537576,"mc":[{"id":"1.230180127","rc":[{"atb":[[1.3,2]],"id":66993945}],"con":true,"img":false}]}
{"op":"mcm","clk":"11541126906","pt":1719502539171,"mc":[{"id":"1.230180127","rc":[{"atb":[[1.88,0]],"id":62886137}],"con":true,"img":false}]}
{"op":"mcm","clk":"11541126913","pt":1719502539274,"mc":[{"id":"1.230180127","rc":[{"atb":[[1.92,2]],"id":62886137}],"con":true,"img":false}]}
{"op":"mcm","clk":"11541126935","pt":1719502539586,"mc":[{"id":"1.230180127","rc":[{"atb":[[1.85,0]],"id":49823335}],"con":true,"img":false}]}
{"op":"mcm","clk":"11541126938","pt":1719502539648,"mc":[{"id":"1.230180127","rc":[{"atb":[[1.02,2]],"id":49823335}],"con":true,"img":false}]}
{"op":"mcm","clk":"11541127026","pt":1719502541245,"mc":[{"id":"1.230180127","rc":[{"atb":[[1.02,0]],"id":49823335}],"con":true,"img":false}]}
{"op":"mcm","clk":"11541127031","pt":1719502541351,"mc":[{"id":"1.230180127","rc":[{"atb":[[1.85,2]],"id":49823335}],"con":true,"img":false}]}
{"op":"mcm","clk":"11541127098","pt":1719502542661,"mc":[{"id":"1.230180127","rc":[{"atb":[[1.81,5],[1.85,2.5],[1.42,2.25],[1.77,10]],"id":66993945},{"atl":[[8.6,0],[5.1,5],[4.1,2.25],[5.5,10],[6.8,2],[4.7,2.5]],"id":66993945},{"atb":[[2.36,10],[1.84,2.11],[2.52,2.5],[2.44,5],[1.87,4.5]],"id":49823335},{"atl":[[21,0],[7.4,10],[6.6,7.5],[5.9,2.5],[15,2]],"id":49823335},{"atb":[[1.57,10],[1.53,5],[1.65,2.5],[1.61,5]],"id":64851267},{"atl":[[8,2],[4.3,5],[10.5,0],[3.95,2.5],[4.1,3],[4.7,10]],"id":64851267},{"atb":[[2.44,2.5],[1.93,3],[2.36,5],[2.28,10]],"id":62886137},{"atl":[[17,2],[6.8,6],[6,2.5],[7.6,10],[25,0],[6.6,3]],"id":62886137},{"atb":[[2.92,10],[3.2,2.5],[1.85,0],[3,5],[1.78,3.48],[2.26,1.5]],"id":61941224},{"atl":[[9,3.5],[11.5,10],[9.8,5],[8.8,1.5]],"id":61941224},{"atb":[[1.97,3],[2.28,2.5],[2.12,10],[2.2,5]],"id":69475504},{"atl":[[5.6,5],[6,10],[12,2],[4.9,3],[5.2,2.5],[14.5,0]],"id":69475504}],"con":true,"img":false}]}
{"op":"mcm","clk":"11541127113","pt":1719502542867,"mc":[{"id":"1.230180127","rc":[{"atb":[[1.29,0],[1.66,10]],"id":66993945},{"atb":[[1.65,7.5],[1.53,3]],"id":64851267},{"atb":[[2.44,7.5],[1.91,0]],"id":62886137},{"atl":[[8.8,5],[30,0]],"id":61941224},{"atb":[[2.24,5],[1.95,0]],"id":69475504}],"con":true,"img":false}]}
{"op":"mcm","clk":"11541127117","pt":1719502542972,"mc":[{"id":"1.230180127","rc":[{"atb":[[1.85,0]],"id":49823335},{"atb":[[1.57,17.61],[1.65,2.5]],"id":64851267},{"atb":[[2.28,17.5],[2.44,2.5]],"id":62886137},{"atl":[[9.8,10],[8.8,1.5]],"id":61941224},{"atb":[[2.12,17.5]],"id":69475504},{"atl":[[5.2,4.84]],"id":69475504}],"con":true,"img":false}]}
{"op":"mcm","clk":"11541127123","pt":1719502543075,"mc":[{"id":"1.230180127","rc":[{"atb":[[1.02,2]],"id":49823335},{"atb":[[2.24,0],[2.12,10],[2.2,12.5]],"id":69475504}],"con":true,"img":false}]}
{"op":"mcm","clk":"11541127128","pt":1719502543179,"mc":[{"id":"1.230180127","rc":[{"atb":[[2.12,25],[2.2,5]],"id":69475504}],"con":true,"img":false}]}
{"op":"mcm","clk":"11541127141","pt":1719502543384,"mc":[{"id":"1.230180127","rc":[{"atl":[[4,0.84]],"id":66993945},{"atl":[[5.8,0.84]],"id":49823335},{"atl":[[3.9,0.84]],"id":64851267},{"atl":[[5.9,0.84]],"id":62886137},{"atl":[[4.8,0.84]],"id":69475504}],"con":true,"img":false}]}
{"op":"mcm","clk":"11541127151","pt":1719502543591,"mc":[{"id":"1.230180127","rc":[{"atl":[[6.8,8.53]],"id":62886137}],"con":true,"img":false}]}
{"op":"mcm","clk":"11541127200","pt":1719502544471,"mc":[{"id":"1.230180127","rc":[{"atl":[[6.8,6]],"id":62886137}],"con":true,"img":false}]}
{"op":"mcm","clk":"11541127211","pt":1719502544780,"mc":[{"id":"1.230180127","rc":[{"atb":[[1.92,0]],"id":62886137}],"con":true,"img":false}]}
{"op":"mcm","clk":"11541127216","pt":1719502544878,"mc":[{"id":"1.230180127","rc":[{"atb":[[2.46,2]],"id":62886137}],"con":true,"img":false}]}
{"op":"mcm","clk":"11541127222","pt":1719502544983,"mc":[{"id":"1.230180127","rc":[{"atb":[[2.46,4.5],[2.28,10]],"id":62886137},{"atl":[[6.6,5.63]],"id":62886137}],"con":true,"img":false}]}
{"op":"mcm","clk":"11541127226","pt":1719502545085,"mc":[{"id":"1.230180127","rc":[{"atb":[[2.36,10],[2.46,2]],"id":62886137}],"con":true,"img":false}]}
{"op":"mcm","clk":"11541127252","pt":1719502545452,"mc":[{"id":"1.230180127","rc":[{"atb":[[1.02,0]],"id":49823335}],"con":true,"img":false}]}
{"op":"mcm","clk":"11541127258","pt":1719502545560,"mc":[{"id":"1.230180127","rc":[{"atb":[[2.54,2]],"id":49823335}],"con":true,"img":false}]}
{"op":"mcm","clk":"11541127271","pt":1719502545763,"mc":[{"id":"1.230180127","rc":[{"atb":[[1.3,0]],"id":66993945}],"con":true,"img":false}]}
{"op":"mcm","clk":"11541127278","pt":1719502545873,"mc":[{"id":"1.230180127","rc":[{"atb":[[1.86,2]],"id":66993945}],"con":true,"img":false}]}
{"op":"mcm","clk":"11541127285","pt":1719502545965,"mc":[{"id":"1.230180127","rc":[{"atb":[[1.44,0],[1.6,2.11]],"id":64851267}],"con":true,"img":false}]}
{"op":"mcm","clk":"11541127294","pt":1719502546070,"mc":[{"id":"1.230180127","rc":[{"atb":[[1.8,2.11]],"id":66993945},{"atb":[[1.57,10],[1.61,10]],"id":64851267}],"con":true,"img":false}]}
{"op":"mcm","clk":"11541127300","pt":1719502546173,"mc":[{"id":"1.230180127","rc":[{"atl":[[6.6,3]],"id":62886137}],"con":true,"img":false}]}
{"op":"mcm","clk":"11541127307","pt":1719502546276,"mc":[{"id":"1.230180127","rc":[{"atb":[[1.96,0]],"id":69475504}],"con":true,"img":false}]}
{"op":"mcm","clk":"11541127316","pt":1719502546378,"mc":[{"id":"1.230180127","rc":[{"atb":[[1.02,27.94]],"id":69475504}],"con":true,"img":false}]}
{"op":"mcm","clk":"11541127375","pt":1719502547257,"mc":[{"id":"1.230180127","rc":[{"atl":[[6.4,2.75]],"id":62886137}],"con":true,"img":false}]}
{"op":"mcm","clk":"11541127389","pt":1719502547468,"mc":[{"id":"1.230180127","rc":[{"atb":[[1.2,0.25]],"id":66993945},{"atl":[[8.4,0]],"id":66993945},{"atb":[[1.86,1]],"id":49823335},{"atl":[[20,0]],"id":49823335},{"atb":[[1.86,1]],"id":62886137},{"atl":[[24,0]],"id":62886137}],"con":true,"img":false}]}
{"op":"mcm","clk":"11541127484","pt":1719502548867,"mc":[{"id":"1.230180127","rc":[{"atl":[[6.8,0],[4.2,4.1]],"id":66993945},{"atb":[[2.54,4.5],[1.87,2.5]],"id":49823335},{"atl":[[6.6,15],[15,0]],"id":49823335},{"atl":[[8,0],[4.1,6.35]],"id":64851267},{"atl":[[17,0],[6.2,3.35]],"id":62886137},{"atb":[[2.74,10],[1.78,0]],"id":61941224},{"atl":[[5,5.84],[12,0]],"id":69475504}],"con":true,"img":false}]}
{"op":"mcm","clk":"11541127498","pt":1719502549068,"mc":[{"id":"1.230180127","rc":[{"atl":[[6.4,0]],"id":62886137}],"con":true,"img":false}]}
{"op":"mcm","clk":"11541127640","pt":1719502551179,"mc":[{"id":"1.230180127","rc":[{"atb":[[2.36,5],[2.46,4.5]],"id":62886137}],"con":true,"img":false}]}
{"op":"mcm","clk":"11541127647","pt":1719502551283,"mc":[{"id":"1.230180127","rc":[{"atb":[[2.36,15],[2.46,2]],"id":62886137}],"con":true,"img":false}]}
{"op":"mcm","clk":"11541127659","pt":1719502551489,"mc":[{"id":"1.230180127","rc":[{"atb":[[2.36,5],[2.46,6.5]],"id":62886137}],"con":true,"img":false}]}
{"op":"mcm","clk":"11541127677","pt":1719502551805,"mc":[{"id":"1.230180127","rc":[{"atb":[[1.82,7.23]],"id":66993945}],"con":true,"img":false}]}
{"op":"mcm","clk":"11541127787","pt":1719502553199,"mc":[{"id":"1.230180127","rc":[{"atb":[[1.9,0]],"id":62886137}],"con":true,"img":false}]}
{"op":"mcm","clk":"11541127831","pt":1719502553769,"mc":[{"id":"1.230180127","rc":[{"atb":[[1.65,11.01]],"id":64851267}],"con":true,"img":false}]}
{"op":"mcm","clk":"11541127840","pt":1719502553873,"mc":[{"id":"1.230180127","rc":[{"atb":[[1.61,5]],"id":64851267}],"con":true,"img":false}]}
{"op":"mcm","clk":"11541127851","pt":1719502553976,"mc":[{"id":"1.230180127","rc":[{"atb":[[1.66,10]],"id":64851267}],"con":true,"img":false}]}
{"op":"mcm","clk":"11541127859","pt":1719502554079,"mc":[{"id":"1.230180127","rc":[{"atb":[[2.18,4.68]],"id":69475504}],"con":true,"img":false}]}
{"op":"mcm","clk":"11541127866","pt":1719502554183,"mc":[{"id":"1.230180127","rc":[{"atb":[[2.12,10],[2.2,10]],"id":69475504}],"con":true,"img":false}]}
{"op":"mcm","clk":"11541127874","pt":1719502554284,"mc":[{"id":"1.230180127","rc":[{"atb":[[1.28,0]],"id":66993945}],"con":true,"img":false}]}
{"op":"mcm","clk":"11541127881","pt":1719502554388,"mc":[{"id":"1.230180127","rc":[{"atb":[[1.82,13.98]],"id":66993945}],"con":true,"img":false}]}
{"op":"mcm","clk":"11541127949","pt":1719502555265,"mc":[{"id":"1.230180127","rc":[{"atb":[[1.88,4.49]],"id":66993945}],"con":true,"img":false}]}
{"op":"mcm","clk":"11541127987","pt":1719502555788,"mc":[{"id":"1.230180127","rc":[{"atb":[[1.88,8.05]],"id":66993945},{"atl":[[4,4.4]],"id":66993945},{"atb":[[2.54,9.75]],"id":49823335},{"atl":[[5.7,5.25]],"id":49823335},{"atb":[[1.66,18.51]],"id":64851267},{"atl":[[3.9,9.35]],"id":64851267},{"atb":[[2.5,4.39]],"id":62886137},{"atl":[[5.9,5.23]],"id":62886137},{"atb":[[3.2,8.88]],"id":61941224},{"atb":[[2.32,5.77]],"id":69475504},{"atl":[[4.8,6.61]],"id":69475504}],"con":true,"img":false}]}
{"op":"mcm","clk":"11541127998","pt":1719502555884,"mc":[{"id":"1.230180127","rc":[{"atb":[[1.42,0]],"id":66993945},{"atl":[[4.1,0]],"id":66993945},{"atb":[[2.54,7.25],[2.44,12],[1.87,0]],"id":49823335},{"atl":[[6.6,5],[5.9,5]],"id":49823335},{"atb":[[1.53,0]],"id":64851267},{"atl":[[4.1,3.35]],"id":64851267},{"atb":[[1.93,0]],"id":62886137},{"atl":[[6.6,0]],"id":62886137},{"atb":[[2.26,0]],"id":61941224},{"atb":[[1.97,0]],"id":69475504},{"atl":[[4.9,0]],"id":69475504}],"con":true,"img":false}]}
{"op":"mcm","clk":"11541128027","pt":1719502556299,"mc":[{"id":"1.230180127","rc":[{"atl":[[5.6,0.84]],"id":49823335}],"con":true,"img":false}]}
{"op":"mcm","clk":"11541128035","pt":1719502556401,"mc":[{"id":"1.230180127","rc":[{"atb":[[2.54,14.5],[2.44,5]],"id":49823335}],"con":true,"img":false}]}
{"op":"mcm","clk":"11541128048","pt":1719502556607,"mc":[{"id":"1.230180127","rc":[{"atb":[[2.46,2],[2.44,13.39]],"id":62886137}],"con":true,"img":false}]}
{"op":"mcm","clk":"11541128057","pt":1719502556770,"mc":[{"id":"1.230180127","rc":[{"atb":[[2.46,0]],"id":62886137}],"con":true,"img":false}]}
{"op":"mcm","clk":"11541128067","pt":1719502556871,"mc":[{"id":"1.230180127","rc":[{"atb":[[2.36,22.78],[2.52,2],[2.44,2.5]],"id":62886137}],"con":true,"img":false}]}
{"op":"mcm","clk":"11541128082","pt":1719502557075,"mc":[{"id":"1.230180127","rc":[{"atb":[[1.86,0]],"id":66993945}],"con":true,"img":false}]}
{"op":"mcm","clk":"11541128093","pt":1719502557178,"mc":[{"id":"1.230180127","rc":[{"atb":[[1.89,2]],"id":66993945},{"atl":[[4.2,1],[4.7,11.01]],"id":66993945},{"atl":[[5.2,2.5]],"id":69475504}],"con":true,"img":false}]}
{"op":"mcm","clk":"11541128104","pt":1719502557280,"mc":[{"id":"1.230180127","rc":[{"atl":[[5,1],[5.2,14.96]],"id":69475504}],"con":true,"img":false}]}
{"op":"mcm","clk":"11541128111","pt":1719502557383,"mc":[{"id":"1.230180127","rc":[{"atl":[[5,6.01]],"id":69475504}],"con":true,"img":false}]}
{"op":"mcm","clk":"11541128118","pt":1719502557486,"mc":[{"id":"1.230180127","rc":[{"atb":[[2.36,5],[2.44,12.5]],"id":62886137}],"con":true,"img":false}]}
{"op":"mcm","clk":"11541128130","pt":1719502557590,"mc":[{"id":"1.230180127","rc":[{"atl":[[5.2,2.5],[4.9,13.24]],"id":69475504}],"con":true,"img":false}]}
{"op":"mcm","clk":"11541128139","pt":1719502557692,"mc":[{"id":"1.230180127","rc":[{"atb":[[2.74,0],[2.6,18.88]],"id":61941224}],"con":true,"img":false}]}
{"op":"mcm","clk":"11541128148","pt":1719502557795,"mc":[{"id":"1.230180127","rc":[{"atl":[[5,1]],"id":69475504}],"con":true,"img":false}]}
{"op":"mcm","clk":"11541128159","pt":1719502557899,"mc":[{"id":"1.230180127","rc":[{"atl":[[5,20.86],[4.9,0]],"id":69475504}],"con":true,"img":false}]}
{"op":"mcm","clk":"11541128170","pt":1719502558002,"mc":[{"id":"1.230180127","rc":[{"atl":[[4.9,5.45]],"id":69475504}],"con":true,"img":false}]}
{"op":"mcm","clk":"11541128179","pt":1719502558108,"mc":[{"id":"1.230180127","rc":[{"atl":[[4.8,13.23],[5,1]],"id":69475504}],"con":true,"img":false}]}
{"op":"mcm","clk":"11541128192","pt":1719502558265,"mc":[{"id":"1.230180127","rc":[{"atb":[[1.8,0],[1.88,10.16]],"id":66993945},{"atb":[[1.6,0],[1.69,2.11]],"id":64851267},{"atb":[[1.86,0],[2.26,2.11]],"id":69475504}],"con":true,"img":false}]}
{"op":"mcm","clk":"11541128198","pt":1719502558388,"mc":[{"id":"1.230180127","rc":[{"atb":[[1.66,8.51],[1.69,13.12]],"id":64851267},{"atb":[[2.24,10]],"id":69475504},{"atl":[[4.9,0]],"id":69475504}],"con":true,"img":false}]}
{"op":"mcm","clk":"11541128205","pt":1719502558470,"mc":[{"id":"1.230180127","rc":[{"atb":[[1.66,19.52],[1.69,2.11]],"id":64851267},{"atb":[[2.2,5]],"id":69475504},{"atl":[[5.2,16.74]],"id":69475504}],"con":true,"img":false}]}
{"op":"mcm","clk":"11541128210","pt":1719502558573,"mc":[{"id":"1.230180127","rc":[{"atb":[[1.66,8.51],[1.69,13.12]],"id":64851267},{"atl":[[4.8,6.61]],"id":69475504}],"con":true,"img":false}]}
{"op":"mcm","clk":"11541128218","pt":1719502558676,"mc":[{"id":"1.230180127","rc":[{"atb":[[1.66,19.52],[1.69,2.11]],"id":64851267}],"con":true,"img":false}]}
{"op":"mcm","clk":"11541128227","pt":1719502558779,"mc":[{"id":"1.230180127","rc":[{"atb":[[1.66,8.51],[1.69,13.12]],"id":64851267},{"atl":[[4.8,8.6]],"id":69475504}],"con":true,"img":false}]}
{"op":"mcm","clk":"11541128234","pt":1719502558885,"mc":[{"id":"1.230180127","rc":[{"atb":[[1.66,19.52],[1.69,2.11]],"id":64851267},{"atl":[[4.8,17.21],[5.2,2.5]],"id":69475504}],"con":true,"img":false}]}
{"op":"mcm","clk":"11541128245","pt":1719502558991,"mc":[{"id":"1.230180127","rc":[{"atb":[[1.66,8.51]],"id":64851267},{"atl":[[4.8,15.22],[5.2,12.5]],"id":69475504}],"con":true,"img":false}]}
{"op":"mcm","clk":"11541128257","pt":1719502559088,"mc":[{"id":"1.230180127","rc":[{"atb":[[1.69,13.12]],"id":64851267},{"atl":[[4.8,6.61]],"id":69475504}],"con":true,"img":false}]}
{"op":"mcm","clk":"11541128265","pt":1719502559192,"mc":[{"id":"1.230180127","rc":[{"atb":[[1.66,17.02],[1.69,2.11]],"id":64851267}],"con":true,"img":false}]}
{"op":"mcm","clk":"11541128280","pt":1719502559399,"mc":[{"id":"1.230180127","rc":[{"atb":[[1.66,8.51],[1.69,13.12]],"id":64851267},{"atl":[[4.7,4.99]],"id":69475504}],"con":true,"img":false}]}
{"op":"mcm","clk":"11541128288","pt":1719502559502,"mc":[{"id":"1.230180127","rc":[{"atl":[[4.6,4.99]],"id":69475504}],"con":true,"img":false}]}
{"op":"mcm","clk":"11541128295","pt":1719502559604,"mc":[{"id":"1.230180127","rc":[{"atl":[[5.2,2.5]],"id":69475504}],"con":true,"img":false}]}
{"op":"mcm","clk":"11541128302","pt":1719502559708,"mc":[{"id":"1.230180127","rc":[{"atl":[[4.6,5.83],[4.7,0]],"id":69475504}],"con":true,"img":false}]}
{"op":"mcm","clk":"11541128311","pt":1719502559816,"mc":[{"id":"1.230180127","rc":[{"atl":[[4.6,0.84],[5,13.46]],"id":69475504}],"con":true,"img":false}]}
{"op":"mcm","clk":"11541128343","pt":1719502560279,"mc":[{"id":"1.230180127","rc":[{"atb":[[1.65,14.39]],"id":64851267}],"con":true,"img":false}]}
{"op":"mcm","clk":"11541128349","pt":1719502560381,"mc":[{"id":"1.230180127","rc":[{"atb":[[1.65,11.01]],"id":64851267},{"atl":[[4.6,0]],"id":69475504}],"con":true,"img":false}]}
{"op":"mcm","clk":"11541128359","pt":1719502560484,"mc":[{"id":"1.230180127","rc":[{"atl":[[5,1],[5.2,22.58]],"id":69475504}],"con":true,"img":false}]}
{"op":"mcm","clk":"11541128380","pt":1719502560797,"mc":[{"id":"1.230180127","rc":[{"atl":[[4.5,1.98]],"id":66993945}],"con":true,"img":false}]}
{"op":"mcm","clk":"11541128395","pt":1719502560998,"mc":[{"id":"1.230180127","rc":[{"atl":[[4.4,5.41],[4.7,2.5]],"id":66993945}],"con":true,"img":false}]}
{"op":"mcm","clk":"11541128417","pt":1719502561307,"mc":[{"id":"1.230180127","rc":[{"atl":[[4.5,0]],"id":66993945}],"con":true,"img":false}]}
{"op":"mcm","clk":"11541128449","pt":1719502561618,"mc":[{"id":"1.230180127","rc":[{"atl":[[3.95,3.99]],"id":66993945}],"con":true,"img":false}]}
{"op":"mcm","clk":"11541128458","pt":1719502561728,"mc":[{"id":"1.230180127","rc":[{"atl":[[4.4,0],[3.9,3.99]],"id":66993945}],"con":true,"img":false}]}
{"op":"mcm","clk":"11541128467","pt":1719502561781,"mc":[{"id":"1.230180127","rc":[{"atl":[[3.95,0]],"id":66993945}],"con":true,"img":false}]}
{"op":"mcm","clk":"11541128473","pt":1719502561880,"mc":[{"id":"1.230180127","rc":[{"atb":[[1.89,5]],"id":66993945},{"atl":[[3.9,0],[4.2,9.4]],"id":66993945},{"atb":[[2.56,3.39]],"id":49823335},{"atb":[[1.7,4]],"id":64851267},{"atb":[[2.34,2]],"id":69475504}],"con":true,"img":false}]}
{"op":"mcm","clk":"11541128490","pt":1719502562188,"mc":[{"id":"1.230180127","rc":[{"atl":[[4.5,1.98]],"id":66993945}],"con":true,"img":false}]}
{"op":"mcm","clk":"11541128508","pt":1719502562396,"mc":[{"id":"1.230180127","rc":[{"atb":[[2.54,7.25],[2.58,3.39]],"id":49823335}],"con":true,"img":false}]}
{"op":"mcm","clk":"11541128523","pt":1719502562602,"mc":[{"id":"1.230180127","rc":[{"atb":[[2.54,5.25]],"id":49823335}],"con":true,"img":false}]}
{"op":"mcm","clk":"11541128533","pt":1719502562704,"mc":[{"id":"1.230180127","rc":[{"atl":[[4.5,0]],"id":66993945},{"atb":[[2.58,5.39]],"id":49823335}],"con":true,"img":false}]}
{"op":"mcm","clk":"11541128553","pt":1719502563017,"mc":[{"id":"1.230180127","rc":[{"atl":[[4.4,2.71]],"id":66993945},{"atb":[[2.26,7.11]],"id":69475504}],"con":true,"img":false}]}
{"op":"mcm","clk":"11541128558","pt":1719502563125,"mc":[{"id":"1.230180127","rc":[{"atb":[[2.5,9.39],[2.44,2.5]],"id":62886137},{"atb":[[2.24,0]],"id":69475504}],"con":true,"img":false}]}
{"op":"mcm","clk":"11541128571","pt":1719502563276,"mc":[{"id":"1.230180127","rc":[{"atl":[[4.4,0]],"id":66993945}],"con":true,"img":false}]}
{"op":"mcm","clk":"11541128584","pt":1719502563585,"mc":[{"id":"1.230180127","rc":[{"atl":[[4.4,1.72]],"id":66993945}],"con":true,"img":false}]}
{"op":"mcm","clk":"11541128619","pt":1719502564098,"mc":[{"id":"1.230180127","rc":[{"atl":[[4.4,0]],"id":66993945}],"con":true,"img":false}]}
{"op":"mcm","clk":"11541128641","pt":1719502564406,"mc":[{"id":"1.230180127","rc":[{"atl":[[4.5,1.84]],"id":66993945}],"con":true,"img":false}]}
{"op":"mcm","clk":"11541128707","pt":1719502565286,"mc":[{"id":"1.230180127","rc":[{"spn":2.94,"spf":"NaN","id":66993945},{"spn":4.09,"spf":"NaN","id":49823335},{"atb":[[1.71,8.51],[1.69,2.11]],"id":64851267},{"spn":1.7,"spf":1.0,"id":64851267},{"spn":4.21,"spf":"NaN","id":62886137},{"spn":6.0,"spf":"NaN","id":61941224},{"spn":3.57,"spf":"NaN","id":69475504}],"con":true,"img":false}]}
{"op":"mcm","clk":"11541128746","pt":1719502565802,"mc":[{"id":"1.230180127","rc":[{"atl":[[4.5,0]],"id":66993945},{"atl":[[4.8,8.21]],"id":69475504}],"con":true,"img":false}]}
{"op":"mcm","clk":"11541128798","pt":1719502566419,"mc":[{"id":"1.230180127","rc":[{"atl":[[4.8,16.43],[5.2,2.5]],"id":69475504}],"con":true,"img":false}]}
{"op":"mcm","clk":"11541128839","pt":1719502566784,"mc":[{"id":"1.230180127","rc":[{"atl":[[4.8,14.83]],"id":69475504}],"con":true,"img":false}]}
{"op":"mcm","clk":"11541128856","pt":1719502566986,"mc":[{"id":"1.230180127","rc":[{"atl":[[4.7,16.31]],"id":66993945},{"atl":[[4.7,4.74]],"id":69475504}],"con":true,"img":false}]}
{"op":"mcm","clk":"11541128861","pt":1719502567088,"mc":[{"id":"1.230180127","rc":[{"atl":[[4.2,1]],"id":66993945}],"con":true,"img":false}]}
{"op":"mcm","clk":"11541128884","pt":1719502567399,"mc":[{"id":"1.230180127","rc":[{"atl":[[4.6,0.84]],"id":69475504}],"con":true,"img":false}]}
{"op":"mcm","clk":"11541128910","pt":1719502567607,"mc":[{"id":"1.230180127","rc":[{"atl":[[4.7,0]],"id":69475504}],"con":true,"img":false}]}
{"op":"mcm","clk":"11541128985","pt":1719502567987,"mc":[{"id":"1.230180127","rc":[{"atl":[[4.5,2.28]],"id":69475504}],"con":true,"img":false}]}
{"op":"mcm","clk":"11541129019","pt":1719502568346,"mc":[{"id":"1.230180127","rc":[{"atb":[[2.5,4.39],[2.46,11.39]],"id":62886137}],"con":true,"img":false}]}
{"op":"mcm","clk":"11541129029","pt":1719502568407,"mc":[{"id":"1.230180127","rc":[{"atl":[[4.8,13.99]],"id":69475504}],"con":true,"img":false}]}
{"op":"mcm","clk":"11541129045","pt":1719502568500,"mc":[{"id":"1.230180127","rc":[{"atl":[[4.5,0]],"id":69475504}],"con":true,"img":false}]}
{"op":"mcm","clk":"11541129056","pt":1719502568600,"mc":[{"id":"1.230180127","rc":[{"atb":[[1.89,12.06]],"id":66993945},{"atb":[[2.58,11.87]],"id":49823335},{"atl":[[5.6,7.32]],"id":49823335},{"atb":[[1.71,14.02]],"id":64851267},{"atl":[[3.85,5.51]],"id":64851267},{"atb":[[2.52,7.8]],"id":62886137},{"atb":[[2.34,5.58]],"id":69475504},{"atl":[[4.4,3.58]],"id":69475504}],"con":true,"img":false}]}
{"op":"mcm","clk":"11541129066","pt":1719502568703,"mc":[{"id":"1.230180127","rc":[{"atl":[[5.5,5.25]],"id":49823335},{"atl":[[3.8,5.51]],"id":64851267},{"atl":[[5.8,5.8]],"id":62886137}],"con":true,"img":false}]}
{"op":"mcm","clk":"11541129074","pt":1719502568804,"mc":[{"id":"1.230180127","rc":[{"atb":[[1.88,6.6]],"id":66993945},{"atb":[[2.54,0]],"id":49823335},{"atl":[[5.5,0],[5.7,0],[5.9,2.5]],"id":49823335},{"atb":[[1.66,0]],"id":64851267},{"atl":[[3.95,17.37],[4.1,0],[3.8,0],[3.9,0.84]],"id":64851267},{"atb":[[2.5,0]],"id":62886137},{"atl":[[5.9,0.84]],"id":62886137},{"atb":[[2.32,0]],"id":69475504},{"atl":[[4.8,8.22],[4.5,1.48],[4.4,0]],"id":69475504}],"con":true,"img":false}]}
{"op":"mcm","clk":"11541129082","pt":1719502568909,"mc":[{"id":"1.230180127","rc":[{"atl":[[5.8,13.42]],"id":49823335},{"atl":[[4.7,6.87]],"id":69475504}],"con":true,"img":false}]}
{"op":"mcm","clk":"11541129093","pt":1719502569013,"mc":[{"id":"1.230180127","rc":[{"atl":[[5.8,0.84],[5.9,10.68]],"id":49823335},{"atl":[[4.5,0]],"id":69475504}],"con":true,"img":false}]}
{"op":"mcm","clk":"11541129111","pt":1719502569273,"mc":[{"id":"1.230180127","rc":[{"atl":[[5.8,0]],"id":49823335},{"atl":[[3.8,0.84]],"id":64851267},{"atl":[[5.7,0.84]],"id":62886137}],"con":true,"img":false}]}
{"op":"mcm","clk":"11541129117","pt":1719502569381,"mc":[{"id":"1.230180127","rc":[{"atl":[[6.6,22.86]],"id":49823335},{"atl":[[6.2,0],[5.9,7.49]],"id":62886137}],"con":true,"img":false}]}
{"op":"mcm","clk":"11541129125","pt":1719502569478,"mc":[{"id":"1.230180127","rc":[{"atl":[[5.9,2.5]],"id":49823335}],"con":true,"img":false}]}
{"op":"mcm","clk":"11541129146","pt":1719502569786,"mc":[{"id":"1.230180127","rc":[{"atl":[[4.5,2.83]],"id":69475504}],"con":true,"img":false}]}
{"op":"mcm","clk":"11541129188","pt":1719502570508,"mc":[{"id":"1.230180127","rc":[{"atl":[[4.5,0]],"id":69475504}],"con":true,"img":false}]}
{"op":"mcm","clk":"11541129201","pt":1719502570822,"mc":[{"id":"1.230180127","rc":[{"atl":[[4.5,1.84]],"id":66993945},{"atl":[[4.4,3.22]],"id":69475504}],"con":true,"img":false}]}
{"op":"mcm","clk":"11541129208","pt":1719502570930,"mc":[{"id":"1.230180127","rc":[{"atb":[[1.92,2.11],[1.88,4.49]],"id":66993945},{"atb":[[1.84,0],[2.64,2.11]],"id":49823335},{"atb":[[1.69,0],[1.74,2.11]],"id":64851267}],"con":true,"img":false}]}
{"op":"mcm","clk":"11541129218","pt":1719502571024,"mc":[{"id":"1.230180127","rc":[{"atl":[[4.4,5.41],[4.7,2.5]],"id":66993945}],"con":true,"img":false}]}
{"op":"mcm","clk":"11541129228","pt":1719502571183,"mc":[{"id":"1.230180127","rc":[{"atb":[[1.71,5.51],[1.74,6.11]],"id":64851267}],"con":true,"img":false}]}
{"op":"mcm","clk":"11541129235","pt":1719502571285,"mc":[{"id":"1.230180127","rc":[{"atl":[[4.6,0]],"id":69475504}],"con":true,"img":false}]}
{"op":"mcm","clk":"11541129308","pt":1719502572212,"mc":[{"id":"1.230180127","rc":[{"atb":[[1.82,7.23]],"id":66993945}],"con":true,"img":false}]}
{"op":"mcm","clk":"11541129320","pt":1719502572314,"mc":[{"id":"1.230180127","rc":[{"atl":[[4.8,0],[4.3,6.87]],"id":69475504}],"con":true,"img":false}]}
{"op":"mcm","clk":"11541129334","pt":1719502572520,"mc":[{"id":"1.230180127","rc":[{"atb":[[1.88,0]],"id":66993945},{"atb":[[2.58,9.87]],"id":49823335}],"con":true,"img":false}]}
{"op":"mcm","clk":"11541129344","pt":1719502572628,"mc":[{"id":"1.230180127","rc":[{"atb":[[2.66,2]],"id":49823335}],"con":true,"img":false}]}
{"op":"mcm","clk":"11541129368","pt":1719502572781,"mc":[{"id":"1.230180127","rc":[{"atb":[[1.94,10.09]],"id":66993945}],"con":true,"img":false}]}
{"op":"mcm","clk":"11541129376","pt":1719502572883,"mc":[{"id":"1.230180127","rc":[{"atb":[[1.89,10.06]],"id":66993945}],"con":true,"img":false}]}
{"op":"mcm","clk":"11541129385","pt":1719502572987,"mc":[{"id":"1.230180127","rc":[{"atb":[[1.93,2]],"id":66993945}],"con":true,"img":false}]}
{"op":"mcm","clk":"11541129443","pt":1719502573604,"mc":[{"id":"1.230180127","rc":[{"atb":[[2.58,6.48],[2.62,4.12]],"id":49823335},{"atb":[[2.46,0],[2.44,21.69]],"id":62886137}],"con":true,"img":false}]}
{"op":"mcm","clk":"11541129553","pt":1719502574689,"mc":[{"id":"1.230180127","rc":[{"atl":[[4.2,0.84]],"id":69475504}],"con":true,"img":false}]}
{"op":"mcm","clk":"11541129570","pt":1719502574903,"mc":[{"id":"1.230180127","rc":[{"atb":[[1.93,0]],"id":66993945}],"con":true,"img":false}]}
{"op":"mcm","clk":"11541129575","pt":1719502575000,"mc":[{"id":"1.230180127","rc":[{"atb":[[1.95,2]],"id":66993945}],"con":true,"img":false}]}
{"op":"mcm","clk":"11541129624","pt":1719502575619,"mc":[{"id":"1.230180127","rc":[{"atl":[[4.4,0]],"id":69475504}],"con":true,"img":false}]}
{"op":"mcm","clk":"11541129688","pt":1719502575828,"mc":[{"id":"1.230180127","rc":[{"atl":[[4.3,0],[4.2,2.99],[4.7,14.59]],"id":69475504}],"con":true,"img":false}]}
{"op":"mcm","clk":"11541129699","pt":1719502575982,"mc":[{"id":"1.230180127","rc":[{"atl":[[4.1,3],[4.7,6.87]],"id":69475504}],"con":true,"img":false}]}
{"op":"mcm","clk":"11541129704","pt":1719502576086,"mc":[{"id":"1.230180127","rc":[{"atb":[[1.89,7.06]],"id":66993945},{"atb":[[2.56,0]],"id":49823335},{"atb":[[1.7,0]],"id":64851267},{"atl":[[4.1,0],[4.2,8.99]],"id":69475504}],"con":true,"img":false}]}
{"op":"mcm","clk":"11541129716","pt":1719502576293,"mc":[{"id":"1.230180127","rc":[{"atb":[[1.95,5]],"id":66993945},{"atb":[[2.66,4]],"id":49823335},{"atb":[[1.75,3]],"id":64851267},{"atb":[[3.25,2.6]],"id":61941224}],"con":true,"img":false}]}
{"op":"mcm","clk":"11541129723","pt":1719502576396,"mc":[{"id":"1.230180127","rc":[{"atb":[[3.3,6.38]],"id":61941224}],"con":true,"img":false}]}
{"op":"mcm","clk":"11541129738","pt":1719502576599,"mc":[{"id":"1.230180127","rc":[{"atb":[[3.2,2.5]],"id":61941224}],"con":true,"img":false}]}
{"op":"mcm","clk":"11541129767","pt":1719502577010,"mc":[{"id":"1.230180127","rc":[{"atb":[[1.76,5.51],[1.74,2.11]],"id":64851267}],"con":true,"img":false}]}
{"op":"mcm","clk":"11541129774","pt":1719502577113,"mc":[{"id":"1.230180127","rc":[{"atb":[[1.76,0],[1.75,8.51]],"id":64851267}],"con":true,"img":false}]}
{"op":"mcm","clk":"11541129883","pt":1719502578712,"mc":[{"id":"1.230180127","rc":[{"atb":[[2.4,29.49],[2.44,2.49]],"id":62886137},{"atb":[[2.28,13.66],[2.26,2.11]],"id":69475504}],"con":true,"img":false}]}
{"op":"mcm","clk":"11541129951","pt":1719502579592,"mc":[{"id":"1.230180127","rc":[{"atb":[[1.03,1.7]],"id":49823335}],"con":true,"img":false}]}
{"op":"mcm","clk":"11541129964","pt":1719502579900,"mc":[{"id":"1.230180127","rc":[{"atb":[[1.03,0.1]],"id":49823335}],"con":true,"img":false}]}
{"op":"mcm","clk":"11541129977","pt":1719502580104,"mc":[{"id":"1.230180127","rc":[{"atb":[[1.03,0]],"id":49823335}],"con":true,"img":false}]}
{"op":"mcm","clk":"11541129982","pt":1719502580207,"mc":[{"id":"1.230180127","rc":[{"atb":[[2.68,0.1]],"id":49823335}],"con":true,"img":false}]}
{"op":"mcm","clk":"11541130062","pt":1719502581190,"mc":[{"id":"1.230180127","rc":[{"atb":[[1.95,12.06]],"id":66993945},{"atl":[[4.5,0],[3.95,2.19]],"id":66993945},{"atb":[[2.66,8.88]],"id":49823335},{"atl":[[5.5,2.06]],"id":49823335},{"atb":[[1.75,14.23]],"id":64851267},{"atl":[[3.8,8.95]],"id":64851267},{"atl":[[5.7,12.72]],"id":62886137},{"atl":[[8.6,1.57]],"id":61941224},{"atl":[[4.1,11.94]],"id":69475504}],"con":true,"img":false}]}
{"op":"mcm","clk":"11541130068","pt":1719502581290,"mc":[{"id":"1.230180127","rc":[{"atb":[[1.89,0]],"id":66993945},{"atb":[[2.58,0]],"id":49823335},{"atb":[[1.71,0]],"id":64851267},{"atl":[[3.85,0]],"id":64851267},{"atl":[[5.8,0]],"id":62886137},{"atl":[[4.7,0]],"id":69475504}],"con":true,"img":false}]}
{"op":"mcm","clk":"11541130075","pt":1719502581400,"mc":[{"id":"1.230180127","rc":[{"atl":[[3.95,4.38],[4.4,0],[3.9,4.95]],"id":66993945},{"atl":[[5.5,4.56],[6.6,5],[5.4,3.46]],"id":49823335},{"atl":[[3.95,2.5],[3.75,5.51]],"id":64851267},{"atl":[[5.7,20.22],[5.9,0.84]],"id":62886137},{"atl":[[8.6,3.57],[9.8,5],[8.4,3.82]],"id":61941224}],"con":true,"img":false}]}
{"op":"mcm","clk":"11541130091","pt":1719502581600,"mc":[{"id":"1.230180127","rc":[{"atl":[[4,0.84]],"id":66993945},{"atl":[[5.6,0.84]],"id":49823335},{"atl":[[8.8,0]],"id":61941224}],"con":true,"img":false}]}
{"op":"mcm","clk":"11541130102","pt":1719502581703,"mc":[{"id":"1.230180127","rc":[{"atl":[[4,0],[3.85,0.84]],"id":66993945},{"atl":[[5.6,0],[5.3,0.84]],"id":49823335},{"atl":[[3.7,0.84],[3.9,0]],"id":64851267},{"atl":[[5.9,0]],"id":62886137},{"atl":[[8.2,0.84]],"id":61941224}],"con":true,"img":false}]}
{"op":"mcm","clk":"11541130113","pt":1719502581809,"mc":[{"id":"1.230180127","rc":[{"atl":[[4,0.84]],"id":69475504}],"con":true,"img":false}]}
{"op":"mcm","clk":"11541130123","pt":1719502581914,"mc":[{"id":"1.230180127","rc":[{"atl":[[4,11.78]],"id":69475504}],"con":true,"img":false}]}
{"op":"mcm","clk":"11541130132","pt":1719502582013,"mc":[{"id":"1.230180127","rc":[{"atl":[[4.1,2.6]],"id":69475504}],"con":true,"img":false}]}
{"op":"mcm","clk":"11541130142","pt":1719502582116,"mc":[{"id":"1.230180127","rc":[{"atl":[[4.2,6.84]],"id":69475504}],"con":true,"img":false}]}
{"op":"mcm","clk":"11541130169","pt":1719502582426,"mc":[{"id":"1.230180127","rc":[{"atl":[[4.2,9.8]],"id":69475504}],"con":true,"img":false}]}
{"op":"mcm","clk":"11541130178","pt":1719502582533,"mc":[{"id":"1.230180127","rc":[{"atb":[[1.98,2.11],[1.92,0]],"id":66993945},{"atb":[[2.5,2.11],[1.84,0]],"id":62886137},{"atb":[[2.26,0],[2.34,7.69]],"id":69475504}],"con":true,"img":false}]}
{"op":"mcm","clk":"11541130189","pt":1719502582690,"mc":[{"id":"1.230180127","rc":[{"atl":[[4.2,6]],"id":69475504}],"con":true,"img":false}]}
{"op":"mcm","clk":"11541130218","pt":1719502583000,"mc":[{"id":"1.230180127","rc":[{"atl":[[4.1,4.83]],"id":69475504}],"con":true,"img":false}]}
{"op":"mcm","clk":"11541130226","pt":1719502583101,"mc":[{"id":"1.230180127","rc":[{"atl":[[4,17.78]],"id":69475504}],"con":true,"img":false}]}
{"op":"mcm","clk":"11541130237","pt":1719502583212,"mc":[{"id":"1.230180127","rc":[{"atl":[[4.2,0]],"id":69475504}],"con":true,"img":false}]}
{"op":"mcm","clk":"11541130284","pt":1719502583940,"mc":[{"id":"1.230180127","rc":[{"atb":[[1.95,10.06]],"id":66993945}],"con":true,"img":false}]}
{"op":"mcm","clk":"11541130293","pt":1719502583986,"mc":[{"id":"1.230180127","rc":[{"atb":[[1.99,2]],"id":66993945}],"con":true,"img":false}]}
{"op":"mcm","clk":"11541130316","pt":1719502584403,"mc":[{"id":"1.230180127","rc":[{"atb":[[2.3,15.4],[2.28,2.5]],"id":69475504}],"con":true,"img":false}]}
{"op":"mcm","clk":"11541130325","pt":1719502584500,"mc":[{"id":"1.230180127","rc":[{"atb":[[1.82,0]],"id":66993945}],"con":true,"img":false}]}
{"op":"mcm","clk":"11541130386","pt":1719502585330,"mc":[{"id":"1.230180127","rc":[{"atl":[[4.1,2.6]],"id":69475504}],"con":true,"img":false}]}
{"op":"mcm","clk":"11541130395","pt":1719502585428,"mc":[{"id":"1.230180127","rc":[{"atb":[[2,5.92]],"id":66993945}],"con":true,"img":false}]}
{"op":"mcm","clk":"11541130402","pt":1719502585535,"mc":[{"id":"1.230180127","rc":[{"atl":[[4,11.78],[4.1,34.86]],"id":69475504}],"con":true,"img":false}]}
{"op":"mcm","clk":"11541130436","pt":1719502585996,"mc":[{"id":"1.230180127","rc":[{"atb":[[1.99,0]],"id":66993945}],"con":true,"img":false}]}
{"op":"mcm","clk":"11541130447","pt":1719502586099,"mc":[{"id":"1.230180127","rc":[{"atb":[[1.93,5.65],[2.02,2]],"id":66993945},{"atb":[[2.64,5.56]],"id":49823335},{"atb":[[1.74,7.67]],"id":64851267},{"atb":[[2.48,3.51]],"id":62886137},{"atb":[[2.32,3.78]],"id":69475504}],"con":true,"img":false}]}
{"op":"mcm","clk":"11541130577","pt":1719502587602,"mc":[{"id":"1.230180127","rc":[{"atl":[[4.5,4.41]],"id":69475504}],"con":true,"img":false}]}
{"op":"mcm","clk":"11541130675","pt":1719502589102,"mc":[{"id":"1.230180127","rc":[{"atl":[[4.5,0]],"id":69475504}],"con":true,"img":false}]}
{"op":"mcm","clk":"11541130705","pt":1719502589410,"mc":[{"id":"1.230180127","rc":[{"atl":[[4.4,2.2]],"id":69475504}],"con":true,"img":false}]}
{"op":"mcm","clk":"11541130713","pt":1719502589511,"mc":[{"id":"1.230180127","rc":[{"atb":[[2.3,0],[2.26,11.48]],"id":69475504}],"con":true,"img":false}]}
{"op":"mcm","clk":"11541130721","pt":1719502589616,"mc":[{"id":"1.230180127","rc":[{"atb":[[1.94,4.2]],"id":66993945},{"atb":[[2.32,0]],"id":69475504}],"con":true,"img":false}]}
{"op":"mcm","clk":"11541130729","pt":1719502589717,"mc":[{"id":"1.230180127","rc":[{"atb":[[1.93,4.89]],"id":66993945}],"con":true,"img":false}]}
{"op":"mcm","clk":"11541130755","pt":1719502590028,"mc":[{"id":"1.230180127","rc":[{"atb":[[1.95,7.06]],"id":66993945},{"atb":[[2.66,6.88]],"id":49823335},{"atb":[[3.25,0]],"id":61941224}],"con":true,"img":false}]}
{"op":"mcm","clk":"11541130769","pt":1719502590241,"mc":[{"id":"1.230180127","rc":[{"atb":[[2.1,3.16]],"id":66993945},{"atb":[[2.68,3.29]],"id":49823335},{"atb":[[2.54,2.9]],"id":62886137},{"atb":[[3.35,2.1],[3.3,0]],"id":61941224}],"con":true,"img":false}]}
{"op":"mcm","clk":"11541130779","pt":1719502590337,"mc":[{"id":"1.230180127","rc":[{"atb":[[2.54,9.58]],"id":62886137},{"atb":[[3.25,5.54]],"id":61941224}],"con":true,"img":false}]}
{"op":"mcm","clk":"11541130789","pt":1719502590392,"mc":[{"id":"1.230180127","rc":[{"atb":[[2.52,2]],"id":62886137},{"atl":[[4.4,0]],"id":69475504}],"con":true,"img":false}]}
{"op":"mcm","clk":"11541130802","pt":1719502590599,"mc":[{"id":"1.230180127","rc":[{"atb":[[2,11.46]],"id":66993945}],"con":true,"img":false}]}
{"op":"mcm","clk":"11541130823","pt":1719502590911,"mc":[{"id":"1.230180127","rc":[{"atb":[[2.48,0]],"id":62886137}],"con":true,"img":false}]}
{"op":"mcm","clk":"11541130893","pt":1719502591695,"mc":[{"id":"1.230180127","rc":[{"atb":[[2.52,0]],"id":62886137}],"con":true,"img":false}]}
{"op":"mcm","clk":"11541130902","pt":1719502591798,"mc":[{"id":"1.230180127","rc":[{"atb":[[2.56,2]],"id":62886137}],"con":true,"img":false}]}
{"op":"mcm","clk":"11541130917","pt":1719502592005,"mc":[{"id":"1.230180127","rc":[{"atb":[[2.66,4.88]],"id":49823335}],"con":true,"img":false}]}
{"op":"mcm","clk":"11541130924","pt":1719502592109,"mc":[{"id":"1.230180127","rc":[{"atb":[[2.7,2]],"id":49823335}],"con":true,"img":false}]}
{"op":"mcm","clk":"11541130941","pt":1719502592315,"mc":[{"id":"1.230180127","rc":[{"atb":[[2.02,0]],"id":66993945}],"con":true,"img":false}]}
{"op":"mcm","clk":"11541130950","pt":1719502592418,"mc":[{"id":"1.230180127","rc":[{"atb":[[2.12,2]],"id":66993945}],"con":true,"img":false}]}
{"op":"mcm","clk":"11541131046","pt":1719502593504,"mc":[{"id":"1.230180127","rc":[{"atb":[[2.12,7.66]],"id":66993945},{"atb":[[2.7,7.07]],"id":49823335},{"atl":[[3.65,12.48]],"id":64851267}],"con":true,"img":false}]}
{"op":"mcm","clk":"11541131057","pt":1719502593605,"mc":[{"id":"1.230180127","rc":[{"atb":[[1.95,0]],"id":66993945},{"atb":[[2.66,0]],"id":49823335},{"atl":[[3.6,5.51],[3.8,3.23],[3.75,0]],"id":64851267}],"con":true,"img":false}]}
{"op":"mcm","clk":"11541131066","pt":1719502593708,"mc":[{"id":"1.230180127","rc":[{"atl":[[3.85,7.84]],"id":66993945},{"atl":[[5.3,6.86]],"id":49823335},{"atl":[[3.6,0],[3.75,13.33]],"id":64851267},{"atl":[[8.2,5.39]],"id":61941224}],"con":true,"img":false}]}
{"op":"mcm","clk":"11541131074","pt":1719502593817,"mc":[{"id":"1.230180127","rc":[{"atb":[[1.93,0]],"id":66993945},{"atl":[[3.9,0]],"id":66993945},{"atb":[[2.64,2.11]],"id":49823335},{"atl":[[5.4,0]],"id":49823335},{"atl":[[8.4,0]],"id":61941224}],"con":true,"img":false}]}
{"op":"mcm","clk":"11541131111","pt":1719502594325,"mc":[{"id":"1.230180127","rc":[{"atl":[[3.6,0.84]],"id":64851267}],"con":true,"img":false}]}
{"op":"mcm","clk":"11541131119","pt":1719502594430,"mc":[{"id":"1.230180127","rc":[{"atl":[[3.8,2.39]],"id":64851267},{"atl":[[4.3,3.99]],"id":69475504}],"con":true,"img":false}]}
{"op":"mcm","clk":"11541131144","pt":1719502594693,"mc":[{"id":"1.230180127","rc":[{"atb":[[2.6,7.42]],"id":49823335}],"con":true,"img":false}]}
{"op":"mcm","clk":"11541131153","pt":1719502594798,"mc":[{"id":"1.230180127","rc":[{"atb":[[1.98,0],[2.16,2.11]],"id":66993945},{"atb":[[2.62,0]],"id":49823335},{"atb":[[2.5,0],[2.6,2.11]],"id":62886137}],"con":true,"img":false}]}
{"op":"mcm","clk":"11541131215","pt":1719502595719,"mc":[{"id":"1.230180127","rc":[{"atb":[[2.56,0]],"id":62886137}],"con":true,"img":false}]}
{"op":"mcm","clk":"11541131224","pt":1719502595821,"mc":[{"id":"1.230180127","rc":[{"atb":[[2.62,2]],"id":62886137}],"con":true,"img":false}]}
{"op":"mcm","clk":"11541131231","pt":1719502595925,"mc":[{"id":"1.230180127","rc":[{"atl":[[4.3,0]],"id":69475504}],"con":true,"img":false}]}
{"op":"mcm","clk":"11541131247","pt":1719502596131,"mc":[{"id":"1.230180127","rc":[{"atb":[[2.12,5.66]],"id":66993945}],"con":true,"img":false}]}
{"op":"mcm","clk":"11541131253","pt":1719502596237,"mc":[{"id":"1.230180127","rc":[{"atb":[[2.18,2]],"id":66993945}],"con":true,"img":false}]}
{"op":"mcm","clk":"11541131347","pt":1719502597529,"mc":[{"id":"1.230180127","rc":[{"atb":[[1.85,0],[1.81,0],[1.77,0]],"id":66993945},{"atb":[[2.44,0],[2.62,2.5],[2.36,0],[2.52,0]],"id":49823335},{"atl":[[4.3,0],[3.95,0],[4.7,0]],"id":64851267},{"atl":[[6.4,10],[5.8,5],[6,0],[6.8,1],[7.6,0],[5.4,2.5]],"id":62886137},{"atb":[[3,0],[3.25,10.54],[3.05,10],[2.92,0],[3.45,2.5],[3.2,0]],"id":61941224},{"atb":[[2.3,2.5],[2.22,5],[2.28,0],[2.12,0],[2.2,0]],"id":69475504}],"con":true,"img":false}]}
{"op":"mcm","clk":"11541131353","pt":1719502597631,"mc":[{"id":"1.230180127","rc":[{"atl":[[5.6,3.09]],"id":62886137}],"con":true,"img":false}]}
{"op":"mcm","clk":"11541131359","pt":1719502597735,"mc":[{"id":"1.230180127","rc":[{"atl":[[5.6,0],[5.1,2.5],[6,0],[5.2,0]],"id":69475504}],"con":true,"img":false}]}
{"op":"mcm","clk":"11541131366","pt":1719502597837,"mc":[{"id":"1.230180127","rc":[{"atl":[[5.7,10.24]],"id":62886137}],"con":true,"img":false}]}
{"op":"mcm","clk":"11541131395","pt":1719502598207,"mc":[{"id":"1.230180127","rc":[{"atl":[[5.3,0.84]],"id":62886137}],"con":true,"img":false}]}
{"op":"mcm","clk":"11541131404","pt":1719502598305,"mc":[{"id":"1.230180127","rc":[{"atl":[[5.7,9.4]],"id":62886137}],"con":true,"img":false}]}
{"op":"mcm","clk":"11541131519","pt":1719502599696,"mc":[{"id":"1.230180127","rc":[{"atb":[[2.24,15.4],[2.26,0]],"id":69475504}],"con":true,"img":false}]}
{"op":"mcm","clk":"11541131702","pt":1719502602117,"mc":[{"id":"1.230180127","rc":[{"atb":[[1.52,0]],"id":64851267}],"con":true,"img":false}]}
{"op":"mcm","clk":"11541131726","pt":1719502602427,"mc":[{"id":"1.230180127","rc":[{"atb":[[2.62,5.46]],"id":62886137},{"atb":[[3.45,7.8]],"id":61941224}],"con":true,"img":false}]}
{"op":"mcm","clk":"11541131743","pt":1719502602633,"mc":[{"id":"1.230180127","rc":[{"atb":[[2.54,2.9]],"id":62886137},{"atb":[[3.25,5]],"id":61941224}],"con":true,"img":false}]}
{"op":"mcm","clk":"11541131847","pt":1719502604228,"mc":[{"id":"1.230180127","rc":[{"atb":[[2.1,0]],"id":66993945},{"atb":[[2.68,0.1]],"id":49823335},{"atb":[[2.54,0]],"id":62886137},{"atb":[[3.35,0]],"id":61941224}],"con":true,"img":false}]}
{"op":"mcm","clk":"11541131853","pt":1719502604330,"mc":[{"id":"1.230180127","rc":[{"atb":[[2.18,5]],"id":66993945},{"atb":[[2.72,2.6]],"id":49823335},{"atb":[[3.5,2.54]],"id":61941224}],"con":true,"img":false}]}
{"op":"mcm","clk":"11541131937","pt":1719502605515,"mc":[{"id":"1.230180127","rc":[{"atb":[[2.18,12.03]],"id":66993945},{"atb":[[2.7,5.07]],"id":49823335}],"con":true,"img":false}]}
{"op":"mcm","clk":"11541131940","pt":1719502605620,"mc":[{"id":"1.230180127","rc":[{"atb":[[2.72,7.97],[2.74,2]],"id":49823335},{"atl":[[3.55,14.02]],"id":64851267}],"con":true,"img":false}]}
{"op":"mcm","clk":"11541131946","pt":1719502605731,"mc":[{"id":"1.230180127","rc":[{"atb":[[2.12,0]],"id":66993945},{"atl":[[5.2,7.22]],"id":49823335},{"atl":[[3.75,0]],"id":64851267}],"con":true,"img":false}]}
{"op":"mcm","clk":"11541131952","pt":1719502605824,"mc":[{"id":"1.230180127","rc":[{"atb":[[1.99,2.5],[1.95,5]],"id":66993945},{"atb":[[2.7,0]],"id":49823335},{"atl":[[5.3,0.84]],"id":49823335}],"con":true,"img":false}]}
{"op":"mcm","clk":"11541131985","pt":1719502606340,"mc":[{"id":"1.230180127","rc":[{"atl":[[5.1,0.84]],"id":49823335},{"atl":[[3.7,0],[3.5,0.84]],"id":64851267}],"con":true,"img":false}]}
{"op":"mcm","clk":"11541131996","pt":1719502606442,"mc":[{"id":"1.230180127","rc":[{"atl":[[5.3,8.91],[5.5,2.06]],"id":49823335}],"con":true,"img":false}]}
{"op":"mcm","clk":"11541132036","pt":1719502606914,"mc":[{"id":"1.230180127","rc":[{"atb":[[2.46,2.11],[2.6,0]],"id":62886137}],"con":true,"img":false}]}
{"op":"mcm","clk":"11541132163","pt":1719502608819,"mc":[{"id":"1.230180127","rc":[{"atb":[[2.32,3.78]],"id":69475504}],"con":true,"img":false}]}
{"op":"mcm","clk":"11541132219","pt":1719502609634,"mc":[{"id":"1.230180127","rc":[{"atl":[[5.3,4.59]],"id":62886137}],"con":true,"img":false}]}
{"op":"mcm","clk":"11541132234","pt":1719502609738,"mc":[{"id":"1.230180127","rc":[{"atl":[[5.6,0],[5.2,3.09],[5.7,1.9]],"id":62886137}],"con":true,"img":false}]}
{"op":"mcm","clk":"11541132242","pt":1719502609847,"mc":[{"id":"1.230180127","rc":[{"atb":[[2.16,6.94]],"id":66993945},{"atb":[[2.7,3.33]],"id":49823335},{"atb":[[2.6,3.27]],"id":62886137},{"atl":[[5.2,0],[5.4,10.19]],"id":62886137}],"con":true,"img":false}]}
{"op":"mcm","clk":"11541132315","pt":1719502610723,"mc":[{"id":"1.230180127","rc":[{"atb":[[2.24,0],[2.26,7.56]],"id":69475504}],"con":true,"img":false}]}
{"op":"mcm","clk":"11541132333","pt":1719502610929,"mc":[{"id":"1.230180127","rc":[{"atl":[[4.2,0]],"id":64851267},{"atb":[[2.82,12.8],[2.6,0]],"id":61941224},{"atl":[[9,2.5],[9.4,1]],"id":61941224},{"atb":[[2.24,11.34],[2.26,0]],"id":69475504},{"atl":[[5,0],[4.9,1]],"id":69475504}],"con":true,"img":false}]}
{"op":"mcm","clk":"11541132343","pt":1719502611045,"mc":[{"id":"1.230180127","rc":[{"atb":[[2.6,0],[2.62,6.74]],"id":49823335},{"atl":[[4.1,1]],"id":64851267}],"con":true,"img":false}]}
{"op":"mcm","clk":"11541132455","pt":1719502612629,"mc":[{"id":"1.230180127","rc":[{"atl":[[3.8,2.39]],"id":66993945},{"atl":[[5.1,3.28]],"id":49823335},{"atl":[[3.5,3.74]],"id":64851267},{"atl":[[5.2,2.34]],"id":62886137},{"atl":[[8,1.84]],"id":61941224},{"atl":[[3.95,2.19]],"id":69475504}],"con":true,"img":false}]}
{"op":"mcm","clk":"11541132463","pt":1719502612732,"mc":[{"id":"1.230180127","rc":[{"atl":[[3.95,2.19],[3.8,6.77],[3.75,11.1]],"id":66993945},{"atl":[[5,7.22],[5.3,0.84]],"id":49823335},{"atl":[[3.45,3.75],[3.65,0]],"id":64851267},{"atl":[[8,5.41],[8.6,1.57],[7.8,6.43]],"id":61941224},{"atl":[[3.95,10.8]],"id":69475504}],"con":true,"img":false}]}
{"op":"mcm","clk":"11541132471","pt":1719502612836,"mc":[{"id":"1.230180127","rc":[{"atl":[[3.85,12.62],[3.95,4.18],[3.8,2.39]],"id":66993945},{"atl":[[5.2,6.94],[5.4,2.5]],"id":62886137},{"atl":[[8.2,4.52]],"id":61941224}],"con":true,"img":false}]}
{"op":"mcm","clk":"11541132478","pt":1719502612938,"mc":[{"id":"1.230180127","rc":[{"atl":[[3.85,5.62],[3.7,2.54]],"id":66993945},{"atl":[[4.9,2.68]],"id":49823335},{"atl":[[3.4,3.11]],"id":64851267},{"atl":[[8,1.84],[7.6,2.04]],"id":61941224},{"atl":[[4,0.84]],"id":69475504}],"con":true,"img":false}]}
{"op":"mcm","clk":"11541132484","pt":1719502613052,"mc":[{"id":"1.230180127","rc":[{"atl":[[3.85,0.84],[3.7,5.08]],"id":66993945},{"atl":[[3.45,0],[3.35,3.75]],"id":64851267},{"atl":[[5.2,2.34],[5.4,9.44]],"id":62886137},{"atl":[[8.2,0.84],[7.6,4.08]],"id":61941224}],"con":true,"img":false}]}
{"op":"mcm","clk":"11541132494","pt":1719502613145,"mc":[{"id":"1.230180127","rc":[{"atl":[[3.7,2.54],[3.75,16.73]],"id":66993945},{"atl":[[5.2,6.94],[5.4,2.5]],"id":62886137},{"atl":[[8,10.31],[7.6,2.04]],"id":61941224}],"con":true,"img":false}]}
{"op":"mcm","clk":"11541132501","pt":1719502613249,"mc":[{"id":"1.230180127","rc":[{"atl":[[3.3,3.35]],"id":64851267}],"con":true,"img":false}]}
{"op":"mcm","clk":"11541132508","pt":1719502613359,"mc":[{"id":"1.230180127","rc":[{"atl":[[3.85,0],[3.65,0.84]],"id":66993945},{"atl":[[4.8,0.84],[5.3,0],[5.1,2.44]],"id":49823335},{"atl":[[3.6,0],[3.35,0.84],[3.25,3.35],[3.5,2.9]],"id":64851267},{"atl":[[5.1,0.84]],"id":62886137},{"atl":[[8.2,0],[7.4,0.84]],"id":61941224},{"atl":[[3.9,0.84]],"id":69475504}],"con":true,"img":false}]}
{"op":"mcm","clk":"11541132515","pt":1719502613407,"mc":[{"id":"1.230180127","rc":[{"atl":[[3.2,3.61]],"id":64851267}],"con":true,"img":false}]}
{"op":"mcm","clk":"11541132529","pt":1719502613614,"mc":[{"id":"1.230180127","rc":[{"atb":[[3.5,12.56]],"id":61941224},{"atl":[[7.4,4.82]],"id":61941224}],"con":true,"img":false}]}
{"op":"mcm","clk":"11541132535","pt":1719502613718,"mc":[{"id":"1.230180127","rc":[{"atl":[[7.2,2.31]],"id":61941224}],"con":true,"img":false}]}
{"op":"mcm","clk":"11541132545","pt":1719502613819,"mc":[{"id":"1.230180127","rc":[{"atl":[[3.35,0]],"id":64851267}],"con":true,"img":false}]}
{"op":"mcm","clk":"11541132576","pt":1719502614340,"mc":[{"id":"1.230180127","rc":[{"atb":[[3.55,7.37]],"id":61941224}],"con":true,"img":false}]}
{"op":"mcm","clk":"11541132592","pt":1719502614543,"mc":[{"id":"1.230180127","rc":[{"atb":[[3.45,2.5]],"id":61941224}],"con":true,"img":false}]}
{"op":"mcm","clk":"11541132600","pt":1719502614648,"mc":[{"id":"1.230180127","rc":[{"atb":[[3.5,11.32]],"id":61941224},{"atl":[[7.4,4.38]],"id":61941224}],"con":true,"img":false}]}
{"op":"mcm","clk":"11541132613","pt":1719502614815,"mc":[{"id":"1.230180127","rc":[{"atb":[[3.5,2.54]],"id":61941224},{"atl":[[7.4,0.84]],"id":61941224}],"con":true,"img":false}]}
{"op":"mcm","clk":"11541132620","pt":1719502614911,"mc":[{"id":"1.230180127","rc":[{"atb":[[3.55,16.15]],"id":61941224},{"atl":[[7.2,5.85]],"id":61941224}],"con":true,"img":false}]}
{"op":"mcm","clk":"11541132796","pt":1719502617437,"mc":[{"id":"1.230180127","rc":[{"atb":[[2.74,6.51],[2.7,0]],"id":49823335},{"atl":[[3.15,8.47]],"id":64851267}],"con":true,"img":false}]}
{"op":"mcm","clk":"11541132804","pt":1719502617540,"mc":[{"id":"1.230180127","rc":[{"atb":[[2.72,2.6]],"id":49823335},{"atl":[[4.8,5.35]],"id":49823335},{"atl":[[3.1,3.91]],"id":64851267}],"con":true,"img":false}]}
{"op":"mcm","clk":"11541132814","pt":1719502617641,"mc":[{"id":"1.230180127","rc":[{"atl":[[5.2,0]],"id":49823335},{"atl":[[3.55,0]],"id":64851267}],"con":true,"img":false}]}
{"op":"mcm","clk":"11541132820","pt":1719502617746,"mc":[{"id":"1.230180127","rc":[{"atl":[[4.8,8.15]],"id":49823335}],"con":true,"img":false}]}
{"op":"mcm","clk":"11541132827","pt":1719502617850,"mc":[{"id":"1.230180127","rc":[{"atb":[[2.18,5]],"id":66993945},{"atb":[[2.64,7.31],[2.62,2.5]],"id":49823335},{"atl":[[5,0],[4.7,7.22]],"id":49823335},{"atl":[[9.4,0]],"id":61941224}],"con":true,"img":false}]}
{"op":"mcm","clk":"11541132836","pt":1719502617953,"mc":[{"id":"1.230180127","rc":[{"atb":[[2.82,0],[2.98,10]],"id":61941224},{"atb":[[2.24,0],[2.32,0],[2.22,16.48]],"id":69475504}],"con":true,"img":false}]}
{"op":"mcm","clk":"11541132857","pt":1719502618115,"mc":[{"id":"1.230180127","rc":[{"atl":[[3.95,2.19]],"id":66993945}],"con":true,"img":false}]}
{"op":"mcm","clk":"11541132880","pt":1719502618428,"mc":[{"id":"1.230180127","rc":[{"atb":[[2.72,0]],"id":49823335},{"atb":[[3.5,0]],"id":61941224}],"con":true,"img":false}]}
{"op":"mcm","clk":"11541132888","pt":1719502618526,"mc":[{"id":"1.230180127","rc":[{"atl":[[3.7,37.37]],"id":66993945},{"atb":[[2.76,3]],"id":49823335},{"atb":[[3.6,3.6]],"id":61941224},{"atl":[[8,1.83],[7.4,12.54]],"id":61941224}],"con":true,"img":false}]}
{"op":"mcm","clk":"11541132894","pt":1719502618629,"mc":[{"id":"1.230180127","rc":[{"atl":[[3.65,17.57],[3.75,11.1]],"id":66993945}],"con":true,"img":false}]}
{"op":"mcm","clk":"11541132900","pt":1719502618731,"mc":[{"id":"1.230180127","rc":[{"atl":[[3.6,2.71]],"id":66993945},{"atl":[[3.1,7.82],[3.25,0]],"id":64851267}],"con":true,"img":false}]}
{"op":"mcm","clk":"11541132908","pt":1719502618834,"mc":[{"id":"1.230180127","rc":[{"atl":[[3.1,3.91],[3.15,16.29]],"id":64851267}],"con":true,"img":false}]}
{"op":"mcm","clk":"11541132915","pt":1719502618937,"mc":[{"id":"1.230180127","rc":[{"atb":[[2.74,4.51]],"id":49823335},{"atl":[[3.1,11.73],[3.15,8.47]],"id":64851267}],"con":true,"img":false}]}
{"op":"mcm","clk":"11541132923","pt":1719502619038,"mc":[{"id":"1.230180127","rc":[{"atb":[[2.78,2]],"id":49823335},{"atl":[[3.15,16.29]],"id":64851267}],"con":true,"img":false}]}
{"op":"mcm","clk":"11541132930","pt":1719502619142,"mc":[{"id":"1.230180127","rc":[{"atl":[[3.1,3.91]],"id":64851267}],"con":true,"img":false}]}
{"op":"mcm","clk":"11541132938","pt":1719502619244,"mc":[{"id":"1.230180127","rc":[{"atl":[[3.1,15.64],[3.15,8.47]],"id":64851267},{"atb":[[3.55,7.37]],"id":61941224}],"con":true,"img":false}]}
{"op":"mcm","clk":"11541132984","pt":1719502619711,"mc":[{"id":"1.230180127","rc":[{"atb":[[2.76,17.74]],"id":49823335},{"atl":[[4.7,13.18]],"id":49823335},{"atb":[[3.6,12.89]],"id":61941224}],"con":true,"img":false}]}
{"op":"mcm","clk":"11541133072","pt":1719502620848,"mc":[{"id":"1.230180127","rc":[{"atl":[[3.55,0.84]],"id":66993945},{"atl":[[4.6,0.84]],"id":49823335},{"atl":[[3.05,0.84]],"id":64851267},{"atl":[[7,0.84]],"id":61941224}],"con":true,"img":false}]}
{"op":"mcm","clk":"11541133108","pt":1719502621317,"mc":[{"id":"1.230180127","rc":[{"atl":[[5.1,6.74]],"id":62886137}],"con":true,"img":false}]}
{"op":"mcm","clk":"11541133115","pt":1719502621424,"mc":[{"id":"1.230180127","rc":[{"atl":[[5,9.31],[5.3,0.84],[5.2,2.34]],"id":62886137}],"con":true,"img":false}]}
{"op":"mcm","clk":"11541133136","pt":1719502621741,"mc":[{"id":"1.230180127","rc":[{"atl":[[5.3,0],[4.9,0.84]],"id":62886137}],"con":true,"img":false}]}
{"op":"mcm","clk":"11541133237","pt":1719502623135,"mc":[{"id":"1.230180127","rc":[{"atb":[[2.86,17.37]],"id":61941224},{"atl":[[7.8,14.32]],"id":61941224}],"con":true,"img":false}]}
{"op":"mcm","clk":"11541133242","pt":1719502623240,"mc":[{"id":"1.230180127","rc":[{"atb":[[2.64,2.11],[2.58,7.01]],"id":49823335},{"atl":[[4.8,22.18],[4.7,5.96]],"id":49823335},{"atb":[[2.98,0]],"id":61941224},{"atl":[[7.4,0.84]],"id":61941224}],"con":true,"img":false}]}
{"op":"mcm","clk":"11541133319","pt":1719502624434,"mc":[{"id":"1.230180127","rc":[{"atl":[[3.55,9.8]],"id":66993945},{"atl":[[7,7.1]],"id":61941224}],"con":true,"img":false}]}
{"op":"mcm","clk":"11541133325","pt":1719502624534,"mc":[{"id":"1.230180127","rc":[{"atl":[[3.5,12.71],[3.65,0.84]],"id":66993945},{"atl":[[6.8,2.62]],"id":61941224}],"con":true,"img":false}]}
{"op":"mcm","clk":"11541133329","pt":1719502624638,"mc":[{"id":"1.230180127","rc":[{"atl":[[3.75,0]],"id":66993945},{"atl":[[7.8,7.89]],"id":61941224}],"con":true,"img":false}]}
{"op":"mcm","clk":"11541133333","pt":1719502624740,"mc":[{"id":"1.230180127","rc":[{"atl":[[7.2,5.73]],"id":61941224}],"con":true,"img":false}]}
{"op":"mcm","clk":"11541133340","pt":1719502624852,"mc":[{"id":"1.230180127","rc":[{"atl":[[5.1,0],[5.5,0],[3.65,0],[4.7,0]],"id":66993945},{"atl":[[4.7,8.9]],"id":49823335},{"atl":[[7.4,0]],"id":61941224}],"con":true,"img":false}]}
{"op":"mcm","clk":"11541133349","pt":1719502624946,"mc":[{"id":"1.230180127","rc":[{"atl":[[7.2,2.31]],"id":61941224}],"con":true,"img":false}]}
{"op":"mcm","clk":"11541133356","pt":1719502625047,"mc":[{"id":"1.230180127","rc":[{"atl":[[3.7,2.54]],"id":66993945},{"atl":[[7,10.52]],"id":61941224}],"con":true,"img":false}]}
{"op":"mcm","clk":"11541133382","pt":1719502625420,"mc":[{"id":"1.230180127","rc":[{"atl":[[3.65,1.99]],"id":66993945},{"spn":2.84,"spf":"NaN","id":66993945},{"spn":3.69,"spf":"NaN","id":49823335},{"spn":1.75,"spf":1.0,"id":64851267},{"spn":3.76,"spf":"NaN","id":62886137},{"spn":5.2,"spf":"NaN","id":61941224},{"spn":3.12,"spf":"NaN","id":69475504}],"con":true,"img":false}]}
{"op":"mcm","clk":"11541133389","pt":1719502625516,"mc":[{"id":"1.230180127","rc":[{"atl":[[7,7.1]],"id":61941224}],"con":true,"img":false}]}
{"op":"mcm","clk":"11541133397","pt":1719502625623,"mc":[{"id":"1.230180127","rc":[{"atb":[[2,5.92]],"id":66993945},{"atl":[[3.65,0]],"id":66993945}],"con":true,"img":false}]}
{"op":"mcm","clk":"11541133414","pt":1719502625824,"mc":[{"id":"1.230180127","rc":[{"atl":[[3.7,37.37]],"id":66993945}],"con":true,"img":false}]}
{"op":"mcm","clk":"11541133420","pt":1719502625935,"mc":[{"id":"1.230180127","rc":[{"atb":[[3.65,7.3]],"id":61941224}],"con":true,"img":false}]}
{"op":"mcm","clk":"11541133429","pt":1719502626035,"mc":[{"id":"1.230180127","rc":[{"atb":[[3.55,0]],"id":61941224}],"con":true,"img":false}]}
{"op":"mcm","clk":"11541133478","pt":1719502626515,"mc":[{"id":"1.230180127","rc":[{"atb":[[3.6,11.27]],"id":61941224}],"con":true,"img":false}]}
{"op":"mcm","clk":"11541133489","pt":1719502626618,"mc":[{"id":"1.230180127","rc":[{"atl":[[6.8,6.85]],"id":61941224}],"con":true,"img":false}]}
{"op":"mcm","clk":"11541133497","pt":1719502626721,"mc":[{"id":"1.230180127","rc":[{"atb":[[3.6,3.6]],"id":61941224}],"con":true,"img":false}]}
{"op":"mcm","clk":"11541133502","pt":1719502626830,"mc":[{"id":"1.230180127","rc":[{"atb":[[3.65,14.97]],"id":61941224}],"con":true,"img":false}]}
{"op":"mcm","clk":"11541133517","pt":1719502626929,"mc":[{"id":"1.230180127","rc":[{"atb":[[2.76,14.74]],"id":49823335},{"atb":[[3.6,0]],"id":61941224}],"con":true,"img":false}]}
{"op":"mcm","clk":"11541133526","pt":1719502627035,"mc":[{"id":"1.230180127","rc":[{"atb":[[2.78,4.5]],"id":49823335},{"atb":[[3.7,2.9]],"id":61941224}],"con":true,"img":false}]}
{"op":"mcm","clk":"11541133556","pt":1719502627448,"mc":[{"id":"1.230180127","rc":[{"atb":[[1.94,0]],"id":66993945},{"atb":[[3.65,7.3]],"id":61941224}],"con":true,"img":false}]}
{"op":"mcm","clk":"11541133614","pt":1719502628336,"mc":[{"id":"1.230180127","rc":[{"atl":[[3.45,0.84]],"id":66993945},{"atl":[[6.6,0.84]],"id":61941224}],"con":true,"img":false}]}
{"op":"mcm","clk":"11541133624","pt":1719502628429,"mc":[{"id":"1.230180127","rc":[{"atb":[[3.7,12.13]],"id":61941224}],"con":true,"img":false}]}
{"op":"mcm","clk":"11541133657","pt":1719502629049,"mc":[{"id":"1.230180127","rc":[{"atb":[[2.78,14.56]],"id":49823335},{"atl":[[3.05,15.45]],"id":64851267}],"con":true,"img":false}]}
{"op":"mcm","clk":"11541133665","pt":1719502629152,"mc":[{"id":"1.230180127","rc":[{"atb":[[2.74,0]],"id":49823335},{"atl":[[4.6,10.9]],"id":49823335},{"atl":[[3,1.68],[3.15,0]],"id":64851267}],"con":true,"img":false}]}
{"op":"mcm","clk":"11541133678","pt":1719502629359,"mc":[{"id":"1.230180127","rc":[{"atb":[[1.99,0],[1.95,0]],"id":66993945},{"atl":[[4.8,17.67]],"id":49823335}],"con":true,"img":false}]}
{"op":"mcm","clk":"11541133685","pt":1719502629422,"mc":[{"id":"1.230180127","rc":[{"atb":[[1.8,2.5],[1.72,10],[1.76,5]],"id":66993945}],"con":true,"img":false}]}
{"op":"mcm","clk":"11541133699","pt":1719502629627,"mc":[{"id":"1.230180127","rc":[{"atl":[[4.4,3.26]],"id":69475504}],"con":true,"img":false}]}
{"op":"mcm","clk":"11541133719","pt":1719502629834,"mc":[{"id":"1.230180127","rc":[{"atl":[[4.8,16.83]],"id":49823335}],"con":true,"img":false}]}
{"op":"mcm","clk":"11541133772","pt":1719502630445,"mc":[{"id":"1.230180127","rc":[{"atl":[[4.7,2.94]],"id":49823335}],"con":true,"img":false}]}
{"op":"mcm","clk":"11541133785","pt":1719502630652,"mc":[{"id":"1.230180127","rc":[{"atl":[[1000,1.94]],"id":49823335}],"con":true,"img":false}]}
{"op":"mcm","clk":"11541133792","pt":1719502630754,"mc":[{"id":"1.230180127","rc":[{"atb":[[1.03,5.1],[1.02,1.7]],"id":49823335},{"atl":[[1000,7.04]],"id":49823335}],"con":true,"img":false}]}
{"op":"mcm","clk":"11541133799","pt":1719502630858,"mc":[{"id":"1.230180127","rc":[{"atl":[[4.6,17.64],[1000,5.4]],"id":49823335},{"atl":[[4.4,0]],"id":69475504}],"con":true,"img":false}]}
{"op":"mcm","clk":"11541133813","pt":1719502631018,"mc":[{"id":"1.230180127","rc":[{"atb":[[1.03,0.3],[1.02,0.11]],"id":49823335},{"atl":[[1000,0.39]],"id":49823335},{"atl":[[4.3,1.84]],"id":69475504}],"con":true,"img":false}]}
{"op":"mcm","clk":"11541133822","pt":1719502631125,"mc":[{"id":"1.230180127","rc":[{"atl":[[4.5,0.05]],"id":49823335}],"con":true,"img":false}]}
{"op":"mcm","clk":"11541133828","pt":1719502631234,"mc":[{"id":"1.230180127","rc":[{"atb":[[1.03,0],[1.02,0]],"id":49823335},{"atl":[[1000,0.23]],"id":49823335}],"con":true,"img":false}]}
{"op":"mcm","clk":"11541133835","pt":1719502631325,"mc":[{"id":"1.230180127","rc":[{"atb":[[2.8,0.41]],"id":49823335},{"atl":[[4.5,0.21]],"id":49823335}],"con":true,"img":false}]}
{"op":"mcm","clk":"11541133839","pt":1719502631427,"mc":[{"id":"1.230180127","rc":[{"atb":[[2.32,3.75]],"id":69475504}],"con":true,"img":false}]}
{"op":"mcm","clk":"11541133866","pt":1719502631845,"mc":[{"id":"1.230180127","rc":[{"atl":[[4.3,0]],"id":69475504}],"con":true,"img":false}]}
{"op":"mcm","clk":"11541133875","pt":1719502632052,"mc":[{"id":"1.230180127","rc":[{"atb":[[2.86,0],[3.05,22.3]],"id":61941224}],"con":true,"img":false}]}
{"op":"mcm","clk":"11541133894","pt":1719502632257,"mc":[{"id":"1.230180127","rc":[{"atl":[[4.4,3.94]],"id":69475504}],"con":true,"img":false}]}
{"op":"mcm","clk":"11541133899","pt":1719502632361,"mc":[{"id":"1.230180127","rc":[{"atb":[[2.76,17.96]],"id":49823335}],"con":true,"img":false}]}
{"op":"mcm","clk":"11541133932","pt":1719502632826,"mc":[{"id":"1.230180127","rc":[{"atl":[[4.9,7.39]],"id":62886137}],"con":true,"img":false}]}
{"op":"mcm","clk":"11541133939","pt":1719502632930,"mc":[{"id":"1.230180127","rc":[{"atl":[[4.8,10.2],[5.1,0.84],[5,2.56]],"id":62886137}],"con":true,"img":false}]}
{"op":"mcm","clk":"11541133945","pt":1719502633033,"mc":[{"id":"1.230180127","rc":[{"atl":[[4.4,1.99]],"id":62886137}],"con":true,"img":false}]}
{"op":"mcm","clk":"11541133952","pt":1719502633139,"mc":[{"id":"1.230180127","rc":[{"atl":[[4.8,2.8],[4.3,2.98],[4.6,7.4]],"id":62886137}],"con":true,"img":false}]}
{"op":"mcm","clk":"11541133971","pt":1719502633346,"mc":[{"id":"1.230180127","rc":[{"atl":[[5.1,0],[4.7,0.84]],"id":62886137}],"con":true,"img":false}]}
{"op":"mcm","clk":"11541133998","pt":1719502633756,"mc":[{"id":"1.230180127","rc":[{"atl":[[4.9,6.55],[4.7,0]],"id":62886137}],"con":true,"img":false}]}
{"op":"mcm","clk":"11541134120","pt":1719502635518,"mc":[{"id":"1.230180127","rc":[{"atl":[[4.8,2.8],[4.9,22.45]],"id":49823335},{"atl":[[4.6,0],[4.7,5.96]],"id":62886137},{"atb":[[2.22,5]],"id":69475504},{"atl":[[4.1,2.6]],"id":69475504}],"con":true,"img":false}]}
{"op":"mcm","clk":"11541134123","pt":1719502635625,"mc":[{"id":"1.230180127","rc":[{"atb":[[2.78,12.06]],"id":49823335},{"atb":[[2.24,7.5],[2.32,0]],"id":69475504},{"atl":[[3.95,21.6]],"id":69475504}],"con":true,"img":false}]}
{"op":"mcm","clk":"11541134128","pt":1719502635727,"mc":[{"id":"1.230180127","rc":[{"atb":[[2.8,4.01]],"id":49823335},{"atl":[[4,12.49]],"id":69475504}],"con":true,"img":false}]}
{"op":"mcm","clk":"11541134134","pt":1719502635828,"mc":[{"id":"1.230180127","rc":[{"atl":[[3.95,10.8]],"id":69475504}],"con":true,"img":false}]}
{"op":"mcm","clk":"11541134138","pt":1719502635931,"mc":[{"id":"1.230180127","rc":[{"atl":[[3.45,10.5]],"id":66993945},{"atl":[[6.6,11.31]],"id":61941224}],"con":true,"img":false}]}
{"op":"mcm","clk":"11541134150","pt":1719502636139,"mc":[{"id":"1.230180127","rc":[{"atl":[[3.4,3.11],[3.55,0.84]],"id":66993945},{"atl":[[6.4,2.99],[7,0.84]],"id":61941224}],"con":true,"img":false}]}
{"op":"mcm","clk":"11541134156","pt":1719502636239,"mc":[{"id":"1.230180127","rc":[{"atl":[[3.35,10.51],[3.5,2.9]],"id":66993945}],"con":true,"img":false}]}
{"op":"mcm","clk":"11541134166","pt":1719502636345,"mc":[{"id":"1.230180127","rc":[{"atl":[[3.55,0],[3.3,3.35]],"id":66993945},{"atl":[[7,0]],"id":61941224}],"con":true,"img":false}]}
{"op":"mcm","clk":"11541134172","pt":1719502636451,"mc":[{"id":"1.230180127","rc":[{"atl":[[3.35,0],[3.25,3.35]],"id":66993945},{"atb":[[2.78,10.06]],"id":49823335}],"con":true,"img":false}]}
{"op":"mcm","clk":"11541134180","pt":1719502636550,"mc":[{"id":"1.230180127","rc":[{"atl":[[3.2,3.42]],"id":66993945},{"atb":[[2.82,2]],"id":49823335},{"atl":[[6.8,6.83]],"id":61941224}],"con":true,"img":false}]}
{"op":"mcm","clk":"11541134189","pt":1719502636652,"mc":[{"id":"1.230180127","rc":[{"atl":[[3.25,0],[3.15,3.35]],"id":66993945}],"con":true,"img":false}]}
{"op":"mcm","clk":"11541134194","pt":1719502636755,"mc":[{"id":"1.230180127","rc":[{"atl":[[3.1,3.41]],"id":66993945},{"atl":[[6.8,2.62]],"id":61941224}],"con":true,"img":false}]}
{"op":"mcm","clk":"11541134203","pt":1719502636857,"mc":[{"id":"1.230180127","rc":[{"atl":[[3.05,3.41],[3.45,9.66],[3.2,4.26],[3.15,0]],"id":66993945},{"atl":[[6.4,7.2],[6.2,0.84]],"id":61941224}],"con":true,"img":false}]}
{"op":"mcm","clk":"11541134212","pt":1719502636966,"mc":[{"id":"1.230180127","rc":[{"atl":[[3,1.68]],"id":66993945}],"con":true,"img":false}]}
{"op":"mcm","clk":"11541134238","pt":1719502637326,"mc":[{"id":"1.230180127","rc":[{"atl":[[3.2,3.42]],"id":66993945},{"atb":[[3.75,10.88]],"id":61941224}],"con":true,"img":false}]}
{"op":"mcm","clk":"11541134248","pt":1719502637428,"mc":[{"id":"1.230180127","rc":[{"atb":[[3.65,0]],"id":61941224}],"con":true,"img":false}]}
{"op":"mcm","clk":"11541134270","pt":1719502637738,"mc":[{"id":"1.230180127","rc":[{"atb":[[2.76,16.64]],"id":49823335}],"con":true,"img":false}]}
{"op":"mcm","clk":"11541134288","pt":1719502637953,"mc":[{"id":"1.230180127","rc":[{"atb":[[2.76,3.22]],"id":49823335}],"con":true,"img":false}]}
{"op":"mcm","clk":"11541134297","pt":1719502638049,"mc":[{"id":"1.230180127","rc":[{"atb":[[2.78,23.48]],"id":49823335}],"con":true,"img":false}]}
{"op":"mcm","clk":"11541134364","pt":1719502639035,"mc":[{"id":"1.230180127","rc":[{"atb":[[3.7,11.35]],"id":61941224}],"con":true,"img":false}]}
{"op":"mcm","clk":"11541134379","pt":1719502639244,"mc":[{"id":"1.230180127","rc":[{"atb":[[3.7,2.9]],"id":61941224}],"con":true,"img":false}]}
{"op":"mcm","clk":"11541134387","pt":1719502639340,"mc":[{"id":"1.230180127","rc":[{"atb":[[3.75,19.33]],"id":61941224}],"con":true,"img":false}]}
{"op":"mcm","clk":"11541134456","pt":1719502640166,"mc":[{"id":"1.230180127","rc":[{"atb":[[2.76,0]],"id":49823335}],"con":true,"img":false}]}
{"op":"mcm","clk":"11541134471","pt":1719502640379,"mc":[{"id":"1.230180127","rc":[{"atl":[[3,20.61]],"id":64851267}],"con":true,"img":false}]}
{"op":"mcm","clk":"11541134483","pt":1719502640430,"mc":[{"id":"1.230180127","rc":[{"atb":[[2.82,7.22]],"id":49823335},{"atl":[[4.5,5.43]],"id":49823335},{"atl":[[3.05,0.84]],"id":64851267}],"con":true,"img":false}]}
{"op":"mcm","clk":"11541134495","pt":1719502640630,"mc":[{"id":"1.230180127","rc":[{"atb":[[2.78,13.42]],"id":49823335},{"atl":[[4.8,13.66],[4.6,7.58]],"id":49823335},{"atb":[[2.24,0],[2.22,20]],"id":69475504}],"con":true,"img":false}]}
{"op":"mcm","clk":"11541134502","pt":1719502640749,"mc":[{"id":"1.230180127","rc":[{"atl":[[3.7,2.54]],"id":66993945},{"atl":[[4.9,2.68]],"id":49823335}],"con":true,"img":false}]}
{"op":"mcm","clk":"11541134512","pt":1719502640841,"mc":[{"id":"1.230180127","rc":[{"atl":[[4.4,0.84]],"id":49823335},{"atl":[[2.98,0.84]],"id":64851267},{"atl":[[4.2,0.84]],"id":62886137}],"con":true,"img":false}]}
{"op":"mcm","clk":"11541134518","pt":1719502640953,"mc":[{"id":"1.230180127","rc":[{"atl":[[4.4,0]],"id":69475504}],"con":true,"img":false}]}
{"op":"mcm","clk":"11541134547","pt":1719502641351,"mc":[{"id":"1.230180127","rc":[{"atl":[[4.6,0.84]],"id":49823335}],"con":true,"img":false}]}
{"op":"mcm","clk":"11541134562","pt":1719502641555,"mc":[{"id":"1.230180127","rc":[{"atl":[[4.4,1.84]],"id":69475504}],"con":true,"img":false}]}
{"op":"mcm","clk":"11541134617","pt":1719502642228,"mc":[{"id":"1.230180127","rc":[{"atb":[[1.65,2.5]],"id":64851267},{"atb":[[2.18,0]],"id":69475504}],"con":true,"img":false}]}
{"op":"mcm","clk":"11541134632","pt":1719502642434,"mc":[{"id":"1.230180127","rc":[{"atl":[[4.4,7.83]],"id":49823335}],"con":true,"img":false}]}
{"op":"mcm","clk":"11541134671","pt":1719502642850,"mc":[{"id":"1.230180127","rc":[{"atl":[[4.6,0]],"id":49823335}],"con":true,"img":false}]}
{"op":"mcm","clk":"11541134733","pt":1719502643677,"mc":[{"id":"1.230180127","rc":[{"atl":[[3.1,3.91],[3.05,22.3]],"id":64851267},{"atb":[[2.84,10],[3.05,10]],"id":61941224}],"con":true,"img":false}]}
{"op":"mcm","clk":"11541134772","pt":1719502644147,"mc":[{"id":"1.230180127","rc":[{"atl":[[4.2,4.66]],"id":62886137}],"con":true,"img":false}]}
{"op":"mcm","clk":"11541134789","pt":1719502644349,"mc":[{"id":"1.230180127","rc":[{"atl":[[4.9,0],[4.1,2.63]],"id":62886137}],"con":true,"img":false}]}
{"op":"mcm","clk":"11541134807","pt":1719502644659,"mc":[{"id":"1.230180127","rc":[{"atb":[[2.8,0.41]],"id":49823335},{"atb":[[3.7,0]],"id":61941224}],"con":true,"img":false}]}
{"op":"mcm","clk":"11541134813","pt":1719502644760,"mc":[{"id":"1.230180127","rc":[{"atb":[[2.84,3.02]],"id":49823335},{"atb":[[3.8,3.02]],"id":61941224}],"con":true,"img":false}]}
{"op":"mcm","clk":"11541134818","pt":1719502644861,"mc":[{"id":"1.230180127","rc":[{"atb":[[3.75,10.88]],"id":61941224}],"con":true,"img":false}]}
{"op":"mcm","clk":"11541134857","pt":1719502645377,"mc":[{"id":"1.230180127","rc":[{"atl":[[4.4,0]],"id":69475504}],"con":true,"img":false}]}
{"op":"mcm","clk":"11541134873","pt":1719502645535,"mc":[{"id":"1.230180127","rc":[{"atl":[[4.3,1.84]],"id":69475504}],"con":true,"img":false}]}
{"op":"mcm","clk":"11541134880","pt":1719502645639,"mc":[{"id":"1.230180127","rc":[{"atb":[[3.8,10.95]],"id":61941224}],"con":true,"img":false}]}
{"op":"mcm","clk":"11541134890","pt":1719502645744,"mc":[{"id":"1.230180127","rc":[{"atb":[[2.24,20]],"id":69475504}],"con":true,"img":false}]}
{"op":"mcm","clk":"11541134896","pt":1719502645840,"mc":[{"id":"1.230180127","rc":[{"atb":[[2.22,5]],"id":69475504}],"con":true,"img":false}]}
{"op":"mcm","clk":"11541134908","pt":1719502645949,"mc":[{"id":"1.230180127","rc":[{"atb":[[2.82,5.22]],"id":49823335}],"con":true,"img":false}]}
{"op":"mcm","clk":"11541134920","pt":1719502646047,"mc":[{"id":"1.230180127","rc":[{"atb":[[2.86,2]],"id":49823335}],"con":true,"img":false}]}
{"op":"mcm","clk":"11541135002","pt":1719502647177,"mc":[{"id":"1.230180127","rc":[{"atl":[[3,7.99]],"id":66993945},{"atl":[[6.2,11.41]],"id":61941224}],"con":true,"img":false}]}
{"op":"mcm","clk":"11541135012","pt":1719502647280,"mc":[{"id":"1.230180127","rc":[{"atl":[[2.98,3.41],[3.05,0]],"id":66993945},{"atl":[[4.8,2.8],[4.9,15.95]],"id":49823335},{"atb":[[2.4,0],[2.44,9.03]],"id":62886137},{"atl":[[6,1.7],[6.6,0.84]],"id":61941224}],"con":true,"img":false}]}
{"op":"mcm","clk":"11541135021","pt":1719502647334,"mc":[{"id":"1.230180127","rc":[{"atl":[[3.45,0],[2.96,1.74]],"id":66993945}],"con":true,"img":false}]}
{"op":"mcm","clk":"11541135055","pt":1719502647848,"mc":[{"id":"1.230180127","rc":[{"atb":[[2,0]],"id":66993945},{"atl":[[2.94,0.84]],"id":66993945},{"atl":[[5.9,0.84],[6.6,0]],"id":61941224}],"con":true,"img":false}]}
{"op":"mcm","clk":"11541135071","pt":1719502648053,"mc":[{"id":"1.230180127","rc":[{"atl":[[6.4,2.99]],"id":61941224}],"con":true,"img":false}]}
{"op":"mcm","clk":"11541135078","pt":1719502648156,"mc":[{"id":"1.230180127","rc":[{"atb":[[2.18,22.93]],"id":66993945},{"atl":[[2.94,11.81]],"id":66993945}],"con":true,"img":false}]}
{"op":"mcm","clk":"11541135093","pt":1719502648371,"mc":[{"id":"1.230180127","rc":[{"atl":[[4,0.84]],"id":62886137}],"con":true,"img":false}]}
{"op":"mcm","clk":"11541135113","pt":1719502648569,"mc":[{"id":"1.230180127","rc":[{"atb":[[3.85,10.04]],"id":61941224}],"con":true,"img":false}]}
{"op":"mcm","clk":"11541135120","pt":1719502648672,"mc":[{"id":"1.230180127","rc":[{"atb":[[3.75,0]],"id":61941224}],"con":true,"img":false}]}
{"op":"mcm","clk":"11541135128","pt":1719502648777,"mc":[{"id":"1.230180127","rc":[{"atl":[[5.9,5.64]],"id":61941224}],"con":true,"img":false}]}
{"op":"mcm","clk":"11541135137","pt":1719502648875,"mc":[{"id":"1.230180127","rc":[{"atl":[[5.8,1.83]],"id":61941224}],"con":true,"img":false}]}
{"op":"mcm","clk":"11541135150","pt":1719502649080,"mc":[{"id":"1.230180127","rc":[{"atb":[[1.66,0],[1.75,11.95]],"id":66993945},{"atl":[[4.2,0]],"id":66993945},{"atl":[[4.9,0]],"id":69475504}],"con":true,"img":false}]}
{"op":"mcm","clk":"11541135167","pt":1719502649444,"mc":[{"id":"1.230180127","rc":[{"atl":[[6.2,10.57]],"id":61941224}],"con":true,"img":false}]}
{"op":"mcm","clk":"11541135175","pt":1719502649557,"mc":[{"id":"1.230180127","rc":[{"atl":[[5.9,5.42]],"id":61941224}],"con":true,"img":false}]}
{"op":"mcm","clk":"11541135183","pt":1719502649650,"mc":[{"id":"1.230180127","rc":[{"atb":[[3.35,5],[3.25,0],[3.55,2.5],[3.05,0],[3.45,0]],"id":61941224}],"con":true,"img":false}]}
{"op":"mcm","clk":"11541135188","pt":1719502649757,"mc":[{"id":"1.230180127","rc":[{"atb":[[2.62,0]],"id":49823335},{"atl":[[5.9,0.84]],"id":61941224}],"con":true,"img":false}]}
{"op":"mcm","clk":"11541135195","pt":1719502649855,"mc":[{"id":"1.230180127","rc":[{"atl":[[5.8,6.41]],"id":61941224}],"con":true,"img":false}]}
{"op":"mcm","clk":"11541135203","pt":1719502649960,"mc":[{"id":"1.230180127","rc":[{"atb":[[2.32,5.14],[2.58,0]],"id":49823335}],"con":true,"img":false}]}
{"op":"mcm","clk":"11541135207","pt":1719502650070,"mc":[{"id":"1.230180127","rc":[{"atl":[[4.5,5.26],[4.7,0]],"id":62886137},{"atb":[[2.84,0],[2.94,15.04]],"id":61941224}],"con":true,"img":false}]}
{"op":"mcm","clk":"11541135268","pt":1719502650987,"mc":[{"id":"1.230180127","rc":[{"atb":[[2.24,0],[2.36,7.7]],"id":69475504}],"con":true,"img":false}]}
{"op":"mcm","clk":"11541135276","pt":1719502651045,"mc":[{"id":"1.230180127","rc":[{"atb":[[2.38,11.55]],"id":69475504}],"con":true,"img":false}]}
{"op":"mcm","clk":"11541135288","pt":1719502651243,"mc":[{"id":"1.230180127","rc":[{"atb":[[2.34,4.11]],"id":69475504}],"con":true,"img":false}]}
{"op":"mcm","clk":"11541135309","pt":1719502651552,"mc":[{"id":"1.230180127","rc":[{"atb":[[2.86,8.18]],"id":49823335},{"atl":[[4.3,6.18]],"id":49823335}],"con":true,"img":false}]}
{"op":"mcm","clk":"11541135320","pt":1719502651660,"mc":[{"id":"1.230180127","rc":[{"atb":[[2.82,0]],"id":49823335},{"atl":[[4.5,0.21]],"id":49823335},{"atb":[[2.44,2.11],[2.34,2]],"id":69475504}],"con":true,"img":false}]}
{"op":"mcm","clk":"11541135342","pt":1719502652084,"mc":[{"id":"1.230180127","rc":[{"atl":[[4.4,0.84]],"id":49823335}],"con":true,"img":false}]}
{"op":"mcm","clk":"11541135371","pt":1719502652380,"mc":[{"id":"1.230180127","rc":[{"atl":[[2.98,0],[2.92,3.41]],"id":66993945},{"atl":[[4.2,0.84]],"id":49823335},{"atl":[[4.3,0]],"id":69475504}],"con":true,"img":false}]}
{"op":"mcm","clk":"11541135408","pt":1719502652845,"mc":[{"id":"1.230180127","rc":[{"atb":[[2.36,11.36]],"id":69475504}],"con":true,"img":false}]}
{"op":"mcm","clk":"11541135413","pt":1719502652948,"mc":[{"id":"1.230180127","rc":[{"atl":[[4.6,4.84]],"id":49823335}],"con":true,"img":false}]}
{"op":"mcm","clk":"11541135437","pt":1719502653257,"mc":[{"id":"1.230180127","rc":[{"atl":[[2.94,0.84]],"id":66993945}],"con":true,"img":false}]}
{"op":"mcm","clk":"11541135444","pt":1719502653363,"mc":[{"id":"1.230180127","rc":[{"atb":[[2.18,19.93]],"id":66993945},{"atb":[[2.84,0]],"id":49823335},{"atl":[[4.6,0]],"id":49823335},{"atb":[[3.8,7.93]],"id":61941224},{"atb":[[2.34,0]],"id":69475504}],"con":true,"img":false}]}
{"op":"mcm","clk":"11541135452","pt":1719502653468,"mc":[{"id":"1.230180127","rc":[{"atb":[[2.2,3.1]],"id":66993945},{"atb":[[2.88,3.2]],"id":49823335},{"atl":[[4.2,8.26]],"id":49823335},{"atb":[[3.9,2.78]],"id":61941224},{"atb":[[2.44,6.15]],"id":69475504}],"con":true,"img":false}]}
{"op":"mcm","clk":"11541135457","pt":1719502653568,"mc":[{"id":"1.230180127","rc":[{"atl":[[4.4,0]],"id":62886137}],"con":true,"img":false}]}
{"op":"mcm","clk":"11541135468","pt":1719502653776,"mc":[{"id":"1.230180127","rc":[{"atb":[[2.18,2]],"id":66993945}],"con":true,"img":false}]}
{"op":"mcm","clk":"11541135477","pt":1719502653877,"mc":[{"id":"1.230180127","rc":[{"atl":[[4.4,0]],"id":49823335},{"atl":[[4.5,6.73]],"id":62886137}],"con":true,"img":false}]}
{"op":"mcm","clk":"11541135488","pt":1719502653980,"mc":[{"id":"1.230180127","rc":[{"atl":[[2.92,14.56]],"id":66993945}],"con":true,"img":false}]}
{"op":"mcm","clk":"11541135517","pt":1719502654290,"mc":[{"id":"1.230180127","rc":[{"atb":[[2.86,6.18]],"id":49823335},{"atl":[[4.5,5.26]],"id":62886137}],"con":true,"img":false}]}
{"op":"mcm","clk":"11541135525","pt":1719502654394,"mc":[{"id":"1.230180127","rc":[{"atl":[[2.92,16.36]],"id":66993945},{"atb":[[2.9,2]],"id":49823335}],"con":true,"img":false}]}
{"op":"mcm","clk":"11541135544","pt":1719502654562,"mc":[{"id":"1.230180127","rc":[{"atb":[[2.2,20.75]],"id":66993945}],"con":true,"img":false}]}
{"op":"mcm","clk":"11541135551","pt":1719502654653,"mc":[{"id":"1.230180127","rc":[{"atb":[[2.18,0]],"id":66993945}],"con":true,"img":false}]}
{"op":"mcm","clk":"11541135563","pt":1719502654766,"mc":[{"id":"1.230180127","rc":[{"atb":[[2.22,2]],"id":66993945}],"con":true,"img":false}]}
{"op":"mcm","clk":"11541135599","pt":1719502655270,"mc":[{"id":"1.230180127","rc":[{"atl":[[4,5.27]],"id":62886137}],"con":true,"img":false}]}
{"op":"mcm","clk":"11541135609","pt":1719502655387,"mc":[{"id":"1.230180127","rc":[{"atl":[[2.9,0.84]],"id":66993945},{"atl":[[3.95,2.19],[4.2,0.84]],"id":62886137},{"atl":[[5.7,0.84]],"id":61941224}],"con":true,"img":false}]}
{"op":"mcm","clk":"11541135617","pt":1719502655486,"mc":[{"id":"1.230180127","rc":[{"atb":[[2.2,3.1]],"id":66993945}],"con":true,"img":false}]}
{"op":"mcm","clk":"11541135640","pt":1719502655794,"mc":[{"id":"1.230180127","rc":[{"atb":[[2.78,16.6]],"id":49823335}],"con":true,"img":false}]}
{"op":"mcm","clk":"11541135646","pt":1719502655890,"mc":[{"id":"1.230180127","rc":[{"atl":[[3.9,0.84],[4.2,0]],"id":62886137}],"con":true,"img":false}]}
{"op":"mcm","clk":"11541135660","pt":1719502656150,"mc":[{"id":"1.230180127","rc":[{"atl":[[1000,6.81]],"id":66993945},{"atl":[[1000,7.04]],"id":62886137}],"con":true,"img":false}]}
{"op":"mcm","clk":"11541135665","pt":1719502656260,"mc":[{"id":"1.230180127","rc":[{"atb":[[1.02,5.1]],"id":66993945},{"atb":[[1.03,20.7],[1.02,3.4]],"id":62886137}],"con":true,"img":false}]}
{"op":"mcm","clk":"11541135671","pt":1719502656367,"mc":[{"id":"1.230180127","rc":[{"atl":[[1000,0.39]],"id":66993945},{"atl":[[1000,0.49]],"id":62886137}],"con":true,"img":false}]}
{"op":"mcm","clk":"11541135679","pt":1719502656473,"mc":[{"id":"1.230180127","rc":[{"atb":[[2.22,18.63],[1.02,0.45]],"id":66993945},{"atb":[[1.03,17.51],[1.02,0.24],[2.62,19.95]],"id":62886137},{"atl":[[3.9,9.12]],"id":62886137}],"con":true,"img":false}]}
{"op":"mcm","clk":"11541135685","pt":1719502656582,"mc":[{"id":"1.230180127","rc":[{"atl":[[1000,0]],"id":66993945},{"atl":[[3.85,2.27],[1000,0.23]],"id":62886137}],"con":true,"img":false}]}
{"op":"mcm","clk":"11541135689","pt":1719502656667,"mc":[{"id":"1.230180127","rc":[{"atb":[[1.02,0]],"id":66993945},{"atl":[[2.9,1.24]],"id":66993945},{"atb":[[1.03,17.29],[1.02,0]],"id":62886137},{"atl":[[3.9,9.38]],"id":62886137}],"con":true,"img":false}]}
{"op":"mcm","clk":"11541135696","pt":1719502656780,"mc":[{"id":"1.230180127","rc":[{"atb":[[2.24,0.45]],"id":66993945},{"atb":[[2.64,0.45]],"id":62886137}],"con":true,"img":false}]}
{"op":"mcm","clk":"11541135702","pt":1719502656892,"mc":[{"id":"1.230180127","rc":[{"atl":[[4,4.43]],"id":62886137}],"con":true,"img":false}]}
{"op":"mcm","clk":"11541135710","pt":1719502656986,"mc":[{"id":"1.230180127","rc":[{"atb":[[2.64,4.61]],"id":62886137}],"con":true,"img":false}]}
{"op":"mcm","clk":"11541135717","pt":1719502657086,"mc":[{"id":"1.230180127","rc":[{"atl":[[2.92,5.21]],"id":66993945},{"atb":[[2.6,4.04],[2.62,5.46]],"id":62886137},{"atl":[[3.9,1.1]],"id":62886137}],"con":true,"img":false}]}
{"op":"mcm","clk":"11541135724","pt":1719502657188,"mc":[{"id":"1.230180127","rc":[{"atb":[[2.62,2]],"id":62886137}],"con":true,"img":false}]}
{"op":"mcm","clk":"11541135731","pt":1719502657292,"mc":[{"id":"1.230180127","rc":[{"atb":[[2.6,3.27]],"id":62886137}],"con":true,"img":false}]}
{"op":"mcm","clk":"11541135739","pt":1719502657396,"mc":[{"id":"1.230180127","rc":[{"atb":[[2.62,0]],"id":62886137}],"con":true,"img":false}]}
{"op":"mcm","clk":"11541135746","pt":1719502657450,"mc":[{"id":"1.230180127","rc":[{"atb":[[2.66,2]],"id":62886137}],"con":true,"img":false}]}
{"op":"mcm","clk":"11541135754","pt":1719502657557,"mc":[{"id":"1.230180127","rc":[{"atb":[[2.32,0],[2.42,4.24]],"id":49823335},{"atl":[[4.9,2.68],[4.7,15.3]],"id":49823335},{"atb":[[2.44,2.49],[2.48,7.89]],"id":62886137}],"con":true,"img":false}]}
{"op":"mcm","clk":"11541135767","pt":1719502657763,"mc":[{"id":"1.230180127","rc":[{"atb":[[2.6,0]],"id":62886137}],"con":true,"img":false}]}
{"op":"mcm","clk":"11541135771","pt":1719502657865,"mc":[{"id":"1.230180127","rc":[{"atl":[[2.9,12.34]],"id":66993945},{"atb":[[2.66,15.48]],"id":62886137},{"atl":[[3.85,11.16]],"id":62886137}],"con":true,"img":false}]}
{"op":"mcm","clk":"11541135776","pt":1719502657968,"mc":[{"id":"1.230180127","rc":[{"atl":[[2.92,1.8],[2.88,5.21]],"id":66993945}],"con":true,"img":false}]}
{"op":"mcm","clk":"11541135787","pt":1719502658174,"mc":[{"id":"1.230180127","rc":[{"atl":[[2.88,11.44]],"id":66993945}],"con":true,"img":false}]}
{"op":"mcm","clk":"11541135793","pt":1719502658281,"mc":[{"id":"1.230180127","rc":[{"atl":[[3,1.68]],"id":66993945}],"con":true,"img":false}]}
{"op":"mcm","clk":"11541135800","pt":1719502658379,"mc":[{"id":"1.230180127","rc":[{"atl":[[2.94,0]],"id":66993945}],"con":true,"img":false}]}
{"op":"mcm","clk":"11541135843","pt":1719502658955,"mc":[{"id":"1.230180127","rc":[{"atl":[[2.9,1.24]],"id":66993945}],"con":true,"img":false}]}
{"op":"mcm","clk":"11541135885","pt":1719502659464,"mc":[{"id":"1.230180127","rc":[{"atb":[[3.9,9.67]],"id":61941224}],"con":true,"img":false}]}
{"op":"mcm","clk":"11541135894","pt":1719502659577,"mc":[{"id":"1.230180127","rc":[{"atb":[[3.85,0]],"id":61941224}],"con":true,"img":false}]}
{"op":"mcm","clk":"11541135915","pt":1719502659774,"mc":[{"id":"1.230180127","rc":[{"atl":[[2.88,23.47]],"id":66993945}],"con":true,"img":false}]}
{"op":"mcm","clk":"11541136053","pt":1719502661989,"mc":[{"id":"1.230180127","rc":[{"atb":[[2.2,0]],"id":66993945},{"atb":[[2.88,0]],"id":49823335},{"atb":[[2.44,22.77]],"id":69475504}],"con":true,"img":false}]}
{"op":"mcm","clk":"11541136062","pt":1719502662102,"mc":[{"id":"1.230180127","rc":[{"atb":[[2.24,4.45]],"id":66993945},{"atb":[[2.9,4.1]],"id":49823335},{"atb":[[2.38,0]],"id":69475504}],"con":true,"img":false}]}
{"op":"mcm","clk":"11541136075","pt":1719502662253,"mc":[{"id":"1.230180127","rc":[{"atb":[[2.36,7.7]],"id":69475504}],"con":true,"img":false}]}
{"op":"mcm","clk":"11541136087","pt":1719502662457,"mc":[{"id":"1.230180127","rc":[{"atb":[[2.9,11.81]],"id":49823335},{"atl":[[4.1,7.71]],"id":49823335}],"con":true,"img":false}]}
{"op":"mcm","clk":"11541136092","pt":1719502662561,"mc":[{"id":"1.230180127","rc":[{"atb":[[2.86,0]],"id":49823335},{"atl":[[4.3,0]],"id":49823335}],"con":true,"img":false}]}
{"op":"mcm","clk":"11541136103","pt":1719502662769,"mc":[{"id":"1.230180127","rc":[{"atb":[[2.22,2]],"id":66993945}],"con":true,"img":false}]}
{"op":"mcm","clk":"11541136109","pt":1719502662871,"mc":[{"id":"1.230180127","rc":[{"atb":[[2.22,0]],"id":66993945},{"atl":[[2.86,0.84]],"id":66993945},{"atl":[[4,0.84]],"id":49823335},{"atl":[[3.8,0.84]],"id":62886137}],"con":true,"img":false}]}
{"op":"mcm","clk":"11541136113","pt":1719502662974,"mc":[{"id":"1.230180127","rc":[{"atb":[[2.26,2]],"id":66993945}],"con":true,"img":false}]}
{"op":"mcm","clk":"11541136127","pt":1719502663181,"mc":[{"id":"1.230180127","rc":[{"atb":[[1.76,0],[1.8,0],[1.72,0],[1.81,2.5]],"id":66993945}],"con":true,"img":false}]}
{"op":"mcm","clk":"11541136141","pt":1719502663392,"mc":[{"id":"1.230180127","rc":[{"atb":[[2.26,20.25]],"id":66993945}],"con":true,"img":false}]}
{"op":"mcm","clk":"11541136163","pt":1719502663798,"mc":[{"id":"1.230180127","rc":[{"atb":[[2.78,13.42]],"id":49823335}],"con":true,"img":false}]}
{"op":"mcm","clk":"11541136169","pt":1719502663859,"mc":[{"id":"1.230180127","rc":[{"atb":[[2.32,2.11],[2.16,4.83]],"id":66993945}],"con":true,"img":false}]}
{"op":"mcm","clk":"11541136193","pt":1719502664369,"mc":[{"id":"1.230180127","rc":[{"atb":[[1.81,11.79],[1.75,0]],"id":66993945},{"atl":[[4.5,0],[4.2,4.82]],"id":62886137},{"atb":[[2.36,0],[2.38,45.56]],"id":69475504},{"atl":[[4,0.84],[4.1,24.2]],"id":69475504}],"con":true,"img":false}]}
{"op":"mcm","clk":"11541136203","pt":1719502664576,"mc":[{"id":"1.230180127","rc":[{"atb":[[2.26,19.31]],"id":66993945}],"con":true,"img":false}]}
{"op":"mcm","clk":"11541136213","pt":1719502664776,"mc":[{"id":"1.230180127","rc":[{"atb":[[2.26,2]],"id":66993945}],"con":true,"img":false}]}
{"op":"mcm","clk":"11541136222","pt":1719502664883,"mc":[{"id":"1.230180127","rc":[{"atb":[[2.32,19.42],[2.26,0]],"id":66993945}],"con":true,"img":false}]}
{"op":"mcm","clk":"11541136227","pt":1719502664979,"mc":[{"id":"1.230180127","rc":[{"atb":[[2.34,2]],"id":66993945}],"con":true,"img":false}]}
{"op":"mcm","clk":"11541136264","pt":1719502665602,"mc":[{"id":"1.230180127","rc":[{"atb":[[2.32,2.11]],"id":66993945}],"con":true,"img":false}]}
{"op":"mcm","clk":"11541136270","pt":1719502665700,"mc":[{"id":"1.230180127","rc":[{"atb":[[2.36,6.38]],"id":69475504}],"con":true,"img":false}]}
{"op":"mcm","clk":"11541136297","pt":1719502666066,"mc":[{"id":"1.230180127","rc":[{"atl":[[3.8,10.22]],"id":62886137}],"con":true,"img":false}]}
{"op":"mcm","clk":"11541136304","pt":1719502666166,"mc":[{"id":"1.230180127","rc":[{"atl":[[3.75,2.38],[4,0]],"id":62886137}],"con":true,"img":false}]}
{"op":"mcm","clk":"11541136320","pt":1719502666372,"mc":[{"id":"1.230180127","rc":[{"atb":[[2.36,0]],"id":69475504}],"con":true,"img":false}]}
{"op":"mcm","clk":"11541136324","pt":1719502666475,"mc":[{"id":"1.230180127","rc":[{"atl":[[3.85,10.96]],"id":62886137}],"con":true,"img":false}]}
{"op":"mcm","clk":"11541136333","pt":1719502666680,"mc":[{"id":"1.230180127","rc":[{"atl":[[3.85,2.27]],"id":62886137}],"con":true,"img":false}]}
{"op":"mcm","clk":"11541136339","pt":1719502666789,"mc":[{"id":"1.230180127","rc":[{"atl":[[3.75,11.07],[3.9,0.25]],"id":62886137}],"con":true,"img":false}]}
{"op":"mcm","clk":"11541136354","pt":1719502666892,"mc":[{"id":"1.230180127","rc":[{"atb":[[2.34,19.02]],"id":66993945}],"con":true,"img":false}]}
{"op":"mcm","clk":"11541136411","pt":1719502667768,"mc":[{"id":"1.230180127","rc":[{"atb":[[2.68,13.59]],"id":62886137}],"con":true,"img":false}]}
{"op":"mcm","clk":"11541136421","pt":1719502667873,"mc":[{"id":"1.230180127","rc":[{"atb":[[2.64,0.45]],"id":62886137}],"con":true,"img":false}]}
{"op":"mcm","clk":"11541136452","pt":1719502668288,"mc":[{"id":"1.230180127","rc":[{"atb":[[2.66,13.93]],"id":62886137}],"con":true,"img":false}]}
{"op":"mcm","clk":"11541136460","pt":1719502668397,"mc":[{"id":"1.230180127","rc":[{"atl":[[2.88,18.26],[2.9,25.56]],"id":66993945}],"con":true,"img":false}]}
