{"op":"mcm","clk":"11547086391","pt":1719432856314,"mc":[{"id":"1.230178171","marketDefinition":{"bspMarket":false,"turnInPlayEnabled":false,"persistenceEnabled":false,"marketBaseRate":5.0,"eventId":"33376048","eventTypeId":"4339","numberOfWinners":1,"bettingType":"ODDS","marketType":"FORECAST","marketTime":"2024-06-27T15:03:00.000Z","suspendTime":"2024-06-27T15:03:00.000Z","bspReconciled":false,"complete":true,"inPlay":false,"crossMatching":false,"runnersVoidable":false,"numberOfActiveRunners":30,"betDelay":0,"status":"OPEN","runners":[{"status":"ACTIVE","sortPriority":1,"id":52385882,"name":"1 - 2"},{"status":"ACTIVE","sortPriority":2,"id":52385883,"name":"1 - 3"},{"status":"ACTIVE","sortPriority":3,"id":52385884,"name":"1 - 4"},{"status":"ACTIVE","sortPriority":4,"id":52385885,"name":"1 - 5"},{"status":"ACTIVE","sortPriority":5,"id":52385886,"name":"1 - 6"},{"status":"ACTIVE","sortPriority":6,"id":52385889,"name":"2 - 1"},{"status":"ACTIVE","sortPriority":7,"id":52385890,"name":"2 - 3"},{"status":"ACTIVE","sortPriority":8,"id":52385891,"name":"2 - 4"},{"status":"ACTIVE","sortPriority":9,"id":52385892,"name":"2 - 5"},{"status":"ACTIVE","sortPriority":10,"id":52385893,"name":"2 - 6"},{"status":"ACTIVE","sortPriority":11,"id":52385896,"name":"3 - 1"},{"status":"ACTIVE","sortPriority":12,"id":52385897,"name":"3 - 2"},{"status":"ACTIVE","sortPriority":13,"id":52385898,"name":"3 - 4"},{"status":"ACTIVE","sortPriority":14,"id":52385899,"name":"3 - 5"},{"status":"ACTIVE","sortPriority":15,"id":52385900,"name":"3 - 6"},{"status":"ACTIVE","sortPriority":16,"id":52385903,"name":"4 - 1"},{"status":"ACTIVE","sortPriority":17,"id":52385904,"name":"4 - 2"},{"status":"ACTIVE","sortPriority":18,"id":52385905,"name":"4 - 3"},{"status":"ACTIVE","sortPriority":19,"id":52385906,"name":"4 - 5"},{"status":"ACTIVE","sortPriority":20,"id":52385907,"name":"4 - 6"},{"status":"ACTIVE","sortPriority":21,"id":52385910,"name":"5 - 1"},{"status":"ACTIVE","sortPriority":22,"id":52385911,"name":"5 - 2"},{"status":"ACTIVE","sortPriority":23,"id":52385912,"name":"5 - 3"},{"status":"ACTIVE","sortPriority":24,"id":52385913,"name":"5 - 4"},{"status":"ACTIVE","sortPriority":25,"id":52385914,"name":"5 - 6"},{"status":"ACTIVE","sortPriority":26,"id":52385917,"name":"6 - 1"},{"status":"ACTIVE","sortPriority":27,"id":52385918,"name":"6 - 2"},{"status":"ACTIVE","sortPriority":28,"id":52385919,"name":"6 - 3"},{"status":"ACTIVE","sortPriority":29,"id":52385920,"name":"6 - 4"},{"status":"ACTIVE","sortPriority":30,"id":52385921,"name":"6 - 5"}],"regulators":["MR_INT"],"venue":"Perry Barr","countryCode":"GB","discountAllowed":false,"timezone":"Europe/London","openDate":"2024-06-27T13:29:00.000Z","version":5994794136,"name":"Forecast","eventName":"Perry Barr (F/C) 27th Jun"},"rc":[],"con":true,"img":false}]}
{"op":"mcm","clk":"11547086552","pt":1719432858320,"mc":[{"id":"1.230178171","marketDefinition":{"bspMarket":false,"turnInPlayEnabled":false,"persistenceEnabled":false,"marketBaseRate":5.0,"eventId":"33376048","eventTypeId":"4339","numberOfWinners":1,"bettingType":"ODDS","marketType":"FORECAST","marketTime":"2024-06-27T15:03:00.000Z","suspendTime":"2024-06-27T15:03:00.000Z","bspReconciled":false,"complete":true,"inPlay":false,"crossMatching":false,"runnersVoidable":false,"numberOfActiveRunners":30,"betDelay":0,"status":"OPEN","runners":[{"status":"ACTIVE","sortPriority":1,"id":52385882,"name":"1 - 2"},{"status":"ACTIVE","sortPriority":2,"id":52385883,"name":"1 - 3"},{"status":"ACTIVE","sortPriority":3,"id":52385884,"name":"1 - 4"},{"status":"ACTIVE","sortPriority":4,"id":52385885,"name":"1 - 5"},{"status":"ACTIVE","sortPriority":5,"id":52385886,"name":"1 - 6"},{"status":"ACTIVE","sortPriority":6,"id":52385889,"name":"2 - 1"},{"status":"ACTIVE","sortPriority":7,"id":52385890,"name":"2 - 3"},{"status":"ACTIVE","sortPriority":8,"id":52385891,"name":"2 - 4"},{"status":"ACTIVE","sortPriority":9,"id":52385892,"name":"2 - 5"},{"status":"ACTIVE","sortPriority":10,"id":52385893,"name":"2 - 6"},{"status":"ACTIVE","sortPriority":11,"id":52385896,"name":"3 - 1"},{"status":"ACTIVE","sortPriority":12,"id":52385897,"name":"3 - 2"},{"status":"ACTIVE","sortPriority":13,"id":52385898,"name":"3 - 4"},{"status":"ACTIVE","sortPriority":14,"id":52385899,"name":"3 - 5"},{"status":"ACTIVE","sortPriority":15,"id":52385900,"name":"3 - 6"},{"status":"ACTIVE","sortPriority":16,"id":52385903,"name":"4 - 1"},{"status":"ACTIVE","sortPriority":17,"id":52385904,"name":"4 - 2"},{"status":"ACTIVE","sortPriority":18,"id":52385905,"name":"4 - 3"},{"status":"ACTIVE","sortPriority":19,"id":52385906,"name":"4 - 5"},{"status":"ACTIVE","sortPriority":20,"id":52385907,"name":"4 - 6"},{"status":"ACTIVE","sortPriority":21,"id":52385910,"name":"5 - 1"},{"status":"ACTIVE","sortPriority":22,"id":52385911,"name":"5 - 2"},{"status":"ACTIVE","sortPriority":23,"id":52385912,"name":"5 - 3"},{"status":"ACTIVE","sortPriority":24,"id":52385913,"name":"5 - 4"},{"status":"ACTIVE","sortPriority":25,"id":52385914,"name":"5 - 6"},{"status":"ACTIVE","sortPriority":26,"id":52385917,"name":"6 - 1"},{"status":"ACTIVE","sortPriority":27,"id":52385918,"name":"6 - 2"},{"status":"ACTIVE","sortPriority":28,"id":52385919,"name":"6 - 3"},{"status":"ACTIVE","sortPriority":29,"id":52385920,"name":"6 - 4"},{"status":"ACTIVE","sortPriority":30,"id":52385921,"name":"6 - 5"}],"regulators":["MR_INT"],"venue":"Perry Barr","countryCode":"GB","discountAllowed":true,"timezone":"Europe/London","openDate":"2024-06-27T13:29:00.000Z","version":5994794136,"name":"Forecast","eventName":"Perry Barr (F/C) 27th Jun"},"rc":[],"con":true,"img":false}]}
{"op":"mcm","clk":"11547344212","pt":1719439055693,"mc":[{"id":"1.230178171","rc":[{"atb":[[1.02,8.9]],"id":52385910},{"atb":[[1.01,17.8]],"id":52385912},{"atb":[[1.01,17.8]],"id":52385906},{"atb":[[1.03,5.93]],"id":52385918},{"atb":[[1.02,8.9]],"id":52385920},{"atb":[[1.03,5.93]],"id":52385889},{"atb":[[1.02,8.9]],"id":52385914},{"atb":[[1.03,5.93]],"id":52385883},{"atb":[[1.03,5.93]],"id":52385885},{"atb":[[1.01,17.8]],"id":52385896},{"atb":[[1.01,17.8]],"id":52385890},{"atb":[[1.01,17.8]],"id":52385892},{"atb":[[1.02,8.9]],"id":52385904},{"atb":[[1.03,5.93]],"id":52385898},{"atb":[[1.03,5.93]],"id":52385900},{"atb":[[1.02,8.9]],"id":52385911},{"atb":[[1.02,8.9]],"id":52385913},{"atb":[[1.03,5.93]],"id":52385907},{"atb":[[1.01,17.8]],"id":52385886},{"atb":[[1.03,5.93]],"id":52385919},{"atb":[[1.02,8.9]],"id":52385921},{"atb":[[1.01,17.8]],"id":52385882},{"atb":[[1.03,5.93]],"id":52385884},{"atb":[[1.02,8.9]],"id":52385917},{"atb":[[1.02,8.9]],"id":52385897},{"atb":[[1.01,17.8]],"id":52385891},{"atb":[[1.03,5.93]],"id":52385893},{"atb":[[1.01,17.8]],"id":52385903},{"atb":[[1.01,17.8]],"id":52385905},{"atb":[[1.02,8.9]],"id":52385899}],"con":true,"img":false}]}
{"op":"mcm","clk":"11547371012","pt":1719439682592,"mc":[{"id":"1.230178171","marketDefinition":{"bspMarket":false,"turnInPlayEnabled":false,"persistenceEnabled":false,"marketBaseRate":5.0,"eventId":"33376048","eventTypeId":"4339","numberOfWinners":1,"bettingType":"ODDS","marketType":"FORECAST","marketTime":"2024-06-27T15:03:00.000Z","suspendTime":"2024-06-27T15:03:00.000Z","bspReconciled":false,"complete":true,"inPlay":false,"crossMatching":false,"runnersVoidable":false,"numberOfActiveRunners":30,"betDelay":0,"status":"OPEN","runners":[{"status":"ACTIVE","sortPriority":1,"id":52385882,"name":"1 - 2"},{"status":"ACTIVE","sortPriority":2,"id":52385883,"name":"1 - 3"},{"status":"ACTIVE","sortPriority":3,"id":52385884,"name":"1 - 4"},{"status":"ACTIVE","sortPriority":4,"id":52385885,"name":"1 - 5"},{"status":"ACTIVE","sortPriority":5,"id":52385886,"name":"1 - 6"},{"status":"ACTIVE","sortPriority":6,"id":52385889,"name":"2 - 1"},{"status":"ACTIVE","sortPriority":7,"id":52385890,"name":"2 - 3"},{"status":"ACTIVE","sortPriority":8,"id":52385891,"name":"2 - 4"},{"status":"ACTIVE","sortPriority":9,"id":52385892,"name":"2 - 5"},{"status":"ACTIVE","sortPriority":10,"id":52385893,"name":"2 - 6"},{"status":"ACTIVE","sortPriority":11,"id":52385896,"name":"3 - 1"},{"status":"ACTIVE","sortPriority":12,"id":52385897,"name":"3 - 2"},{"status":"ACTIVE","sortPriority":13,"id":52385898,"name":"3 - 4"},{"status":"ACTIVE","sortPriority":14,"id":52385899,"name":"3 - 5"},{"status":"ACTIVE","sortPriority":15,"id":52385900,"name":"3 - 6"},{"status":"ACTIVE","sortPriority":16,"id":52385903,"name":"4 - 1"},{"status":"ACTIVE","sortPriority":17,"id":52385904,"name":"4 - 2"},{"status":"ACTIVE","sortPriority":18,"id":52385905,"name":"4 - 3"},{"status":"ACTIVE","sortPriority":19,"id":52385906,"name":"4 - 5"},{"status":"ACTIVE","sortPriority":20,"id":52385907,"name":"4 - 6"},{"status":"ACTIVE","sortPriority":21,"id":52385910,"name":"5 - 1"},{"status":"ACTIVE","sortPriority":22,"id":52385911,"name":"5 - 2"},{"status":"ACTIVE","sortPriority":23,"id":52385912,"name":"5 - 3"},{"status":"ACTIVE","sortPriority":24,"id":52385913,"name":"5 - 4"},{"status":"ACTIVE","sortPriority":25,"id":52385914,"name":"5 - 6"},{"status":"ACTIVE","sortPriority":26,"id":52385917,"name":"6 - 1"},{"status":"ACTIVE","sortPriority":27,"id":52385918,"name":"6 - 2"},{"status":"ACTIVE","sortPriority":28,"id":52385919,"name":"6 - 3"},{"status":"ACTIVE","sortPriority":29,"id":52385920,"name":"6 - 4"},{"status":"ACTIVE","sortPriority":30,"id":52385921,"name":"6 - 5"}],"regulators":["MR_INT"],"venue":"Perry Barr","countryCode":"GB","discountAllowed":true,"timezone":"Europe/London","openDate":"2024-06-27T13:29:00.000Z","version":5994794136,"name":"Forecast","eventName":"Perry Barr (F/C) 27th Jun"},"rc":[{"atb":[[1.02,8.9]],"id":52385910},{"atb":[[1.01,17.8]],"id":52385912},{"atb":[[1.01,17.8]],"id":52385906},{"atb":[[1.03,5.93]],"id":52385918},{"atb":[[1.02,8.9]],"id":52385920},{"atb":[[1.03,5.93]],"id":52385889},{"atb":[[1.02,8.9]],"id":52385914},{"atb":[[1.03,5.93]],"id":52385883},{"atb":[[1.03,5.93]],"id":52385885},{"atb":[[1.01,17.8]],"id":52385896},{"atb":[[1.01,17.8]],"id":52385890},{"atb":[[1.01,17.8]],"id":52385892},{"atb":[[1.02,8.9]],"id":52385904},{"atb":[[1.03,5.93]],"id":52385898},{"atb":[[1.03,5.93]],"id":52385900},{"atb":[[1.02,8.9]],"id":52385911},{"atb":[[1.02,8.9]],"id":52385913},{"atb":[[1.03,5.93]],"id":52385907},{"atb":[[1.01,17.8]],"id":52385886},{"atb":[[1.03,5.93]],"id":52385919},{"atb":[[1.02,8.9]],"id":52385921},{"atb":[[1.01,17.8]],"id":52385882},{"atb":[[1.03,5.93]],"id":52385884},{"atb":[[1.02,8.9]],"id":52385917},{"atb":[[1.02,8.9]],"id":52385897},{"atb":[[1.01,17.8]],"id":52385891},{"atb":[[1.03,5.93]],"id":52385893},{"atb":[[1.01,17.8]],"id":52385903},{"atb":[[1.01,17.8]],"id":52385905},{"atb":[[1.02,8.9]],"id":52385899}],"con":true,"img":true}]}
{"op":"mcm","clk":"11547659680","pt":1719445082619,"mc":[{"id":"1.230178171","marketDefinition":{"bspMarket":false,"turnInPlayEnabled":false,"persistenceEnabled":false,"marketBaseRate":5.0,"eventId":"33376048","eventTypeId":"4339","numberOfWinners":1,"bettingType":"ODDS","marketType":"FORECAST","marketTime":"2024-06-27T15:03:00.000Z","suspendTime":"2024-06-27T15:03:00.000Z","bspReconciled":false,"complete":true,"inPlay":false,"crossMatching":false,"runnersVoidable":false,"numberOfActiveRunners":30,"betDelay":0,"status":"OPEN","runners":[{"status":"ACTIVE","sortPriority":1,"id":52385882,"name":"1 - 2"},{"status":"ACTIVE","sortPriority":2,"id":52385883,"name":"1 - 3"},{"status":"ACTIVE","sortPriority":3,"id":52385884,"name":"1 - 4"},{"status":"ACTIVE","sortPriority":4,"id":52385885,"name":"1 - 5"},{"status":"ACTIVE","sortPriority":5,"id":52385886,"name":"1 - 6"},{"status":"ACTIVE","sortPriority":6,"id":52385889,"name":"2 - 1"},{"status":"ACTIVE","sortPriority":7,"id":52385890,"name":"2 - 3"},{"status":"ACTIVE","sortPriority":8,"id":52385891,"name":"2 - 4"},{"status":"ACTIVE","sortPriority":9,"id":52385892,"name":"2 - 5"},{"status":"ACTIVE","sortPriority":10,"id":52385893,"name":"2 - 6"},{"status":"ACTIVE","sortPriority":11,"id":52385896,"name":"3 - 1"},{"status":"ACTIVE","sortPriority":12,"id":52385897,"name":"3 - 2"},{"status":"ACTIVE","sortPriority":13,"id":52385898,"name":"3 - 4"},{"status":"ACTIVE","sortPriority":14,"id":52385899,"name":"3 - 5"},{"status":"ACTIVE","sortPriority":15,"id":52385900,"name":"3 - 6"},{"status":"ACTIVE","sortPriority":16,"id":52385903,"name":"4 - 1"},{"status":"ACTIVE","sortPriority":17,"id":52385904,"name":"4 - 2"},{"status":"ACTIVE","sortPriority":18,"id":52385905,"name":"4 - 3"},{"status":"ACTIVE","sortPriority":19,"id":52385906,"name":"4 - 5"},{"status":"ACTIVE","sortPriority":20,"id":52385907,"name":"4 - 6"},{"status":"ACTIVE","sortPriority":21,"id":52385910,"name":"5 - 1"},{"status":"ACTIVE","sortPriority":22,"id":52385911,"name":"5 - 2"},{"status":"ACTIVE","sortPriority":23,"id":52385912,"name":"5 - 3"},{"status":"ACTIVE","sortPriority":24,"id":52385913,"name":"5 - 4"},{"status":"ACTIVE","sortPriority":25,"id":52385914,"name":"5 - 6"},{"status":"ACTIVE","sortPriority":26,"id":52385917,"name":"6 - 1"},{"status":"ACTIVE","sortPriority":27,"id":52385918,"name":"6 - 2"},{"status":"ACTIVE","sortPriority":28,"id":52385919,"name":"6 - 3"},{"status":"ACTIVE","sortPriority":29,"id":52385920,"name":"6 - 4"},{"status":"ACTIVE","sortPriority":30,"id":52385921,"name":"6 - 5"}],"regulators":["MR_INT"],"venue":"Perry Barr","countryCode":"GB","discountAllowed":true,"timezone":"Europe/London","openDate":"2024-06-27T13:29:00.000Z","version":5994794136,"name":"Forecast","eventName":"Perry Barr (F/C) 27th Jun"},"rc":[{"atb":[[1.02,8.9]],"id":52385910},{"atb":[[1.01,17.8]],"id":52385912},{"atb":[[1.01,17.8]],"id":52385906},{"atb":[[1.03,5.93]],"id":52385918},{"atb":[[1.02,8.9]],"id":52385920},{"atb":[[1.03,5.93]],"id":52385889},{"atb":[[1.02,8.9]],"id":52385914},{"atb":[[1.03,5.93]],"id":52385883},{"atb":[[1.03,5.93]],"id":52385885},{"atb":[[1.01,17.8]],"id":52385896},{"atb":[[1.01,17.8]],"id":52385890},{"atb":[[1.01,17.8]],"id":52385892},{"atb":[[1.02,8.9]],"id":52385904},{"atb":[[1.03,5.93]],"id":52385898},{"atb":[[1.03,5.93]],"id":52385900},{"atb":[[1.02,8.9]],"id":52385911},{"atb":[[1.02,8.9]],"id":52385913},{"atb":[[1.03,5.93]],"id":52385907},{"atb":[[1.01,17.8]],"id":52385886},{"atb":[[1.03,5.93]],"id":52385919},{"atb":[[1.02,8.9]],"id":52385921},{"atb":[[1.01,17.8]],"id":52385882},{"atb":[[1.03,5.93]],"id":52385884},{"atb":[[1.02,8.9]],"id":52385917},{"atb":[[1.02,8.9]],"id":52385897},{"atb":[[1.01,17.8]],"id":52385891},{"atb":[[1.03,5.93]],"id":52385893},{"atb":[[1.01,17.8]],"id":52385903},{"atb":[[1.01,17.8]],"id":52385905},{"atb":[[1.02,8.9]],"id":52385899}],"con":true,"img":true}]}
{"op":"mcm","clk":"11548031724","pt":1719450482634,"mc":[{"id":"1.230178171","marketDefinition":{"bspMarket":false,"turnInPlayEnabled":false,"persistenceEnabled":false,"marketBaseRate":5.0,"eventId":"33376048","eventTypeId":"4339","numberOfWinners":1,"bettingType":"ODDS","marketType":"FORECAST","marketTime":"2024-06-27T15:03:00.000Z","suspendTime":"2024-06-27T15:03:00.000Z","bspReconciled":false,"complete":true,"inPlay":false,"crossMatching":false,"runnersVoidable":false,"numberOfActiveRunners":30,"betDelay":0,"status":"OPEN","runners":[{"status":"ACTIVE","sortPriority":1,"id":52385882,"name":"1 - 2"},{"status":"ACTIVE","sortPriority":2,"id":52385883,"name":"1 - 3"},{"status":"ACTIVE","sortPriority":3,"id":52385884,"name":"1 - 4"},{"status":"ACTIVE","sortPriority":4,"id":52385885,"name":"1 - 5"},{"status":"ACTIVE","sortPriority":5,"id":52385886,"name":"1 - 6"},{"status":"ACTIVE","sortPriority":6,"id":52385889,"name":"2 - 1"},{"status":"ACTIVE","sortPriority":7,"id":52385890,"name":"2 - 3"},{"status":"ACTIVE","sortPriority":8,"id":52385891,"name":"2 - 4"},{"status":"ACTIVE","sortPriority":9,"id":52385892,"name":"2 - 5"},{"status":"ACTIVE","sortPriority":10,"id":52385893,"name":"2 - 6"},{"status":"ACTIVE","sortPriority":11,"id":52385896,"name":"3 - 1"},{"status":"ACTIVE","sortPriority":12,"id":52385897,"name":"3 - 2"},{"status":"ACTIVE","sortPriority":13,"id":52385898,"name":"3 - 4"},{"status":"ACTIVE","sortPriority":14,"id":52385899,"name":"3 - 5"},{"status":"ACTIVE","sortPriority":15,"id":52385900,"name":"3 - 6"},{"status":"ACTIVE","sortPriority":16,"id":52385903,"name":"4 - 1"},{"status":"ACTIVE","sortPriority":17,"id":52385904,"name":"4 - 2"},{"status":"ACTIVE","sortPriority":18,"id":52385905,"name":"4 - 3"},{"status":"ACTIVE","sortPriority":19,"id":52385906,"name":"4 - 5"},{"status":"ACTIVE","sortPriority":20,"id":52385907,"name":"4 - 6"},{"status":"ACTIVE","sortPriority":21,"id":52385910,"name":"5 - 1"},{"status":"ACTIVE","sortPriority":22,"id":52385911,"name":"5 - 2"},{"status":"ACTIVE","sortPriority":23,"id":52385912,"name":"5 - 3"},{"status":"ACTIVE","sortPriority":24,"id":52385913,"name":"5 - 4"},{"status":"ACTIVE","sortPriority":25,"id":52385914,"name":"5 - 6"},{"status":"ACTIVE","sortPriority":26,"id":52385917,"name":"6 - 1"},{"status":"ACTIVE","sortPriority":27,"id":52385918,"name":"6 - 2"},{"status":"ACTIVE","sortPriority":28,"id":52385919,"name":"6 - 3"},{"status":"ACTIVE","sortPriority":29,"id":52385920,"name":"6 - 4"},{"status":"ACTIVE","sortPriority":30,"id":52385921,"name":"6 - 5"}],"regulators":["MR_INT"],"venue":"Perry Barr","countryCode":"GB","discountAllowed":true,"timezone":"Europe/London","openDate":"2024-06-27T13:29:00.000Z","version":5994794136,"name":"Forecast","eventName":"Perry Barr (F/C) 27th Jun"},"rc":[{"atb":[[1.02,8.9]],"id":52385910},{"atb":[[1.01,17.8]],"id":52385912},{"atb":[[1.01,17.8]],"id":52385906},{"atb":[[1.03,5.93]],"id":52385918},{"atb":[[1.02,8.9]],"id":52385920},{"atb":[[1.03,5.93]],"id":52385889},{"atb":[[1.02,8.9]],"id":52385914},{"atb":[[1.03,5.93]],"id":52385883},{"atb":[[1.03,5.93]],"id":52385885},{"atb":[[1.01,17.8]],"id":52385896},{"atb":[[1.01,17.8]],"id":52385890},{"atb":[[1.01,17.8]],"id":52385892},{"atb":[[1.02,8.9]],"id":52385904},{"atb":[[1.03,5.93]],"id":52385898},{"atb":[[1.03,5.93]],"id":52385900},{"atb":[[1.02,8.9]],"id":52385911},{"atb":[[1.02,8.9]],"id":52385913},{"atb":[[1.03,5.93]],"id":52385907},{"atb":[[1.01,17.8]],"id":52385886},{"atb":[[1.03,5.93]],"id":52385919},{"atb":[[1.02,8.9]],"id":52385921},{"atb":[[1.01,17.8]],"id":52385882},{"atb":[[1.03,5.93]],"id":52385884},{"atb":[[1.02,8.9]],"id":52385917},{"atb":[[1.02,8.9]],"id":52385897},{"atb":[[1.01,17.8]],"id":52385891},{"atb":[[1.03,5.93]],"id":52385893},{"atb":[[1.01,17.8]],"id":52385903},{"atb":[[1.01,17.8]],"id":52385905},{"atb":[[1.02,8.9]],"id":52385899}],"con":true,"img":true}]}
{"op":"mcm","clk":"11548270788","pt":1719455882653,"mc":[{"id":"1.230178171","marketDefinition":{"bspMarket":false,"turnInPlayEnabled":false,"persistenceEnabled":false,"marketBaseRate":5.0,"eventId":"33376048","eventTypeId":"4339","numberOfWinners":1,"bettingType":"ODDS","marketType":"FORECAST","marketTime":"2024-06-27T15:03:00.000Z","suspendTime":"2024-06-27T15:03:00.000Z","bspReconciled":false,"complete":true,"inPlay":false,"crossMatching":false,"runnersVoidable":false,"numberOfActiveRunners":30,"betDelay":0,"status":"OPEN","runners":[{"status":"ACTIVE","sortPriority":1,"id":52385882,"name":"1 - 2"},{"status":"ACTIVE","sortPriority":2,"id":52385883,"name":"1 - 3"},{"status":"ACTIVE","sortPriority":3,"id":52385884,"name":"1 - 4"},{"status":"ACTIVE","sortPriority":4,"id":52385885,"name":"1 - 5"},{"status":"ACTIVE","sortPriority":5,"id":52385886,"name":"1 - 6"},{"status":"ACTIVE","sortPriority":6,"id":52385889,"name":"2 - 1"},{"status":"ACTIVE","sortPriority":7,"id":52385890,"name":"2 - 3"},{"status":"ACTIVE","sortPriority":8,"id":52385891,"name":"2 - 4"},{"status":"ACTIVE","sortPriority":9,"id":52385892,"name":"2 - 5"},{"status":"ACTIVE","sortPriority":10,"id":52385893,"name":"2 - 6"},{"status":"ACTIVE","sortPriority":11,"id":52385896,"name":"3 - 1"},{"status":"ACTIVE","sortPriority":12,"id":52385897,"name":"3 - 2"},{"status":"ACTIVE","sortPriority":13,"id":52385898,"name":"3 - 4"},{"status":"ACTIVE","sortPriority":14,"id":52385899,"name":"3 - 5"},{"status":"ACTIVE","sortPriority":15,"id":52385900,"name":"3 - 6"},{"status":"ACTIVE","sortPriority":16,"id":52385903,"name":"4 - 1"},{"status":"ACTIVE","sortPriority":17,"id":52385904,"name":"4 - 2"},{"status":"ACTIVE","sortPriority":18,"id":52385905,"name":"4 - 3"},{"status":"ACTIVE","sortPriority":19,"id":52385906,"name":"4 - 5"},{"status":"ACTIVE","sortPriority":20,"id":52385907,"name":"4 - 6"},{"status":"ACTIVE","sortPriority":21,"id":52385910,"name":"5 - 1"},{"status":"ACTIVE","sortPriority":22,"id":52385911,"name":"5 - 2"},{"status":"ACTIVE","sortPriority":23,"id":52385912,"name":"5 - 3"},{"status":"ACTIVE","sortPriority":24,"id":52385913,"name":"5 - 4"},{"status":"ACTIVE","sortPriority":25,"id":52385914,"name":"5 - 6"},{"status":"ACTIVE","sortPriority":26,"id":52385917,"name":"6 - 1"},{"status":"ACTIVE","sortPriority":27,"id":52385918,"name":"6 - 2"},{"status":"ACTIVE","sortPriority":28,"id":52385919,"name":"6 - 3"},{"status":"ACTIVE","sortPriority":29,"id":52385920,"name":"6 - 4"},{"status":"ACTIVE","sortPriority":30,"id":52385921,"name":"6 - 5"}],"regulators":["MR_INT"],"venue":"Perry Barr","countryCode":"GB","discountAllowed":true,"timezone":"Europe/London","openDate":"2024-06-27T13:29:00.000Z","version":5994794136,"name":"Forecast","eventName":"Perry Barr (F/C) 27th Jun"},"rc":[{"atb":[[1.02,8.9]],"id":52385910},{"atb":[[1.01,17.8]],"id":52385912},{"atb":[[1.01,17.8]],"id":52385906},{"atb":[[1.03,5.93]],"id":52385918},{"atb":[[1.02,8.9]],"id":52385920},{"atb":[[1.03,5.93]],"id":52385889},{"atb":[[1.02,8.9]],"id":52385914},{"atb":[[1.03,5.93]],"id":52385883},{"atb":[[1.03,5.93]],"id":52385885},{"atb":[[1.01,17.8]],"id":52385896},{"atb":[[1.01,17.8]],"id":52385890},{"atb":[[1.01,17.8]],"id":52385892},{"atb":[[1.02,8.9]],"id":52385904},{"atb":[[1.03,5.93]],"id":52385898},{"atb":[[1.03,5.93]],"id":52385900},{"atb":[[1.02,8.9]],"id":52385911},{"atb":[[1.02,8.9]],"id":52385913},{"atb":[[1.03,5.93]],"id":52385907},{"atb":[[1.01,17.8]],"id":52385886},{"atb":[[1.03,5.93]],"id":52385919},{"atb":[[1.02,8.9]],"id":52385921},{"atb":[[1.01,17.8]],"id":52385882},{"atb":[[1.03,5.93]],"id":52385884},{"atb":[[1.02,8.9]],"id":52385917},{"atb":[[1.02,8.9]],"id":52385897},{"atb":[[1.01,17.8]],"id":52385891},{"atb":[[1.03,5.93]],"id":52385893},{"atb":[[1.01,17.8]],"id":52385903},{"atb":[[1.01,17.8]],"id":52385905},{"atb":[[1.02,8.9]],"id":52385899}],"con":true,"img":true}]}
{"op":"mcm","clk":"11548413760","pt":1719460886503,"mc":[{"id":"1.230178171","rc":[{"atb":[[1.16,100],[1.02,8.9]],"id":52385910},{"atb":[[1.01,17.8],[1.16,100]],"id":52385912},{"atb":[[1.01,17.8],[1.16,100]],"id":52385906},{"atb":[[1.03,5.93],[1.16,100]],"id":52385918},{"atb":[[1.16,100],[1.02,8.9]],"id":52385920},{"atb":[[1.03,5.93],[1.16,100]],"id":52385889},{"atb":[[1.16,100],[1.02,8.9]],"id":52385914},{"atb":[[1.03,5.93],[1.16,100]],"id":52385883},{"atb":[[1.03,5.93],[1.16,100]],"id":52385885},{"atb":[[1.01,17.8],[1.16,100]],"id":52385896},{"atb":[[1.01,17.8],[1.16,100]],"id":52385890},{"atb":[[1.01,17.8],[1.16,100]],"id":52385892},{"atb":[[1.16,100],[1.02,8.9]],"id":52385904},{"atb":[[1.03,5.93],[1.16,100]],"id":52385898},{"atb":[[1.03,5.93],[1.16,100]],"id":52385900},{"atb":[[1.16,100],[1.02,8.9]],"id":52385911},{"atb":[[1.16,100],[1.02,8.9]],"id":52385913},{"atb":[[1.03,5.93],[1.16,100]],"id":52385907},{"atb":[[1.01,17.8],[1.16,100]],"id":52385886},{"atb":[[1.03,5.93],[1.16,100]],"id":52385919},{"atb":[[1.16,100],[1.02,8.9]],"id":52385921},{"atb":[[1.01,17.8],[1.16,100]],"id":52385882},{"atb":[[1.03,5.93],[1.16,100]],"id":52385884},{"atb":[[1.16,100],[1.02,8.9]],"id":52385917},{"atb":[[1.16,100],[1.02,8.9]],"id":52385897},{"atb":[[1.01,17.8],[1.16,100]],"id":52385891},{"atb":[[1.03,5.93],[1.16,100]],"id":52385893},{"atb":[[1.01,17.8],[1.16,100]],"id":52385903},{"atb":[[1.01,17.8],[1.16,100]],"id":52385905},{"atb":[[1.16,100],[1.02,8.9]],"id":52385899}],"con":true,"img":false}]}
{"op":"mcm","clk":"11548535724","pt":1719466682820,"mc":[{"id":"1.230178171","marketDefinition":{"bspMarket":false,"turnInPlayEnabled":false,"persistenceEnabled":false,"marketBaseRate":5.0,"eventId":"33376048","eventTypeId":"4339","numberOfWinners":1,"bettingType":"ODDS","marketType":"FORECAST","marketTime":"2024-06-27T15:03:00.000Z","suspendTime":"2024-06-27T15:03:00.000Z","bspReconciled":false,"complete":true,"inPlay":false,"crossMatching":false,"runnersVoidable":false,"numberOfActiveRunners":30,"betDelay":0,"status":"OPEN","runners":[{"status":"ACTIVE","sortPriority":1,"id":52385882,"name":"1 - 2"},{"status":"ACTIVE","sortPriority":2,"id":52385883,"name":"1 - 3"},{"status":"ACTIVE","sortPriority":3,"id":52385884,"name":"1 - 4"},{"status":"ACTIVE","sortPriority":4,"id":52385885,"name":"1 - 5"},{"status":"ACTIVE","sortPriority":5,"id":52385886,"name":"1 - 6"},{"status":"ACTIVE","sortPriority":6,"id":52385889,"name":"2 - 1"},{"status":"ACTIVE","sortPriority":7,"id":52385890,"name":"2 - 3"},{"status":"ACTIVE","sortPriority":8,"id":52385891,"name":"2 - 4"},{"status":"ACTIVE","sortPriority":9,"id":52385892,"name":"2 - 5"},{"status":"ACTIVE","sortPriority":10,"id":52385893,"name":"2 - 6"},{"status":"ACTIVE","sortPriority":11,"id":52385896,"name":"3 - 1"},{"status":"ACTIVE","sortPriority":12,"id":52385897,"name":"3 - 2"},{"status":"ACTIVE","sortPriority":13,"id":52385898,"name":"3 - 4"},{"status":"ACTIVE","sortPriority":14,"id":52385899,"name":"3 - 5"},{"status":"ACTIVE","sortPriority":15,"id":52385900,"name":"3 - 6"},{"status":"ACTIVE","sortPriority":16,"id":52385903,"name":"4 - 1"},{"status":"ACTIVE","sortPriority":17,"id":52385904,"name":"4 - 2"},{"status":"ACTIVE","sortPriority":18,"id":52385905,"name":"4 - 3"},{"status":"ACTIVE","sortPriority":19,"id":52385906,"name":"4 - 5"},{"status":"ACTIVE","sortPriority":20,"id":52385907,"name":"4 - 6"},{"status":"ACTIVE","sortPriority":21,"id":52385910,"name":"5 - 1"},{"status":"ACTIVE","sortPriority":22,"id":52385911,"name":"5 - 2"},{"status":"ACTIVE","sortPriority":23,"id":52385912,"name":"5 - 3"},{"status":"ACTIVE","sortPriority":24,"id":52385913,"name":"5 - 4"},{"status":"ACTIVE","sortPriority":25,"id":52385914,"name":"5 - 6"},{"status":"ACTIVE","sortPriority":26,"id":52385917,"name":"6 - 1"},{"status":"ACTIVE","sortPriority":27,"id":52385918,"name":"6 - 2"},{"status":"ACTIVE","sortPriority":28,"id":52385919,"name":"6 - 3"},{"status":"ACTIVE","sortPriority":29,"id":52385920,"name":"6 - 4"},{"status":"ACTIVE","sortPriority":30,"id":52385921,"name":"6 - 5"}],"regulators":["MR_INT"],"venue":"Perry Barr","countryCode":"GB","discountAllowed":true,"timezone":"Europe/London","openDate":"2024-06-27T13:29:00.000Z","version":5994794136,"name":"Forecast","eventName":"Perry Barr (F/C) 27th Jun"},"rc":[{"atb":[[1.16,100],[1.02,8.9]],"id":52385910},{"atb":[[1.01,17.8],[1.16,100]],"id":52385912},{"atb":[[1.01,17.8],[1.16,100]],"id":52385906},{"atb":[[1.16,100],[1.03,5.93]],"id":52385918},{"atb":[[1.16,100],[1.02,8.9]],"id":52385920},{"atb":[[1.16,100],[1.03,5.93]],"id":52385889},{"atb":[[1.16,100],[1.02,8.9]],"id":52385914},{"atb":[[1.16,100],[1.03,5.93]],"id":52385883},{"atb":[[1.16,100],[1.03,5.93]],"id":52385885},{"atb":[[1.01,17.8],[1.16,100]],"id":52385896},{"atb":[[1.01,17.8],[1.16,100]],"id":52385890},{"atb":[[1.01,17.8],[1.16,100]],"id":52385892},{"atb":[[1.16,100],[1.02,8.9]],"id":52385904},{"atb":[[1.16,100],[1.03,5.93]],"id":52385898},{"atb":[[1.16,100],[1.03,5.93]],"id":52385900},{"atb":[[1.16,100],[1.02,8.9]],"id":52385911},{"atb":[[1.16,100],[1.02,8.9]],"id":52385913},{"atb":[[1.16,100],[1.03,5.93]],"id":52385907},{"atb":[[1.01,17.8],[1.16,100]],"id":52385886},{"atb":[[1.16,100],[1.03,5.93]],"id":52385919},{"atb":[[1.16,100],[1.02,8.9]],"id":52385921},{"atb":[[1.01,17.8],[1.16,100]],"id":52385882},{"atb":[[1.16,100],[1.03,5.93]],"id":52385884},{"atb":[[1.16,100],[1.02,8.9]],"id":52385917},{"atb":[[1.16,100],[1.02,8.9]],"id":52385897},{"atb":[[1.01,17.8],[1.16,100]],"id":52385891},{"atb":[[1.16,100],[1.03,5.93]],"id":52385893},{"atb":[[1.01,17.8],[1.16,100]],"id":52385903},{"atb":[[1.01,17.8],[1.16,100]],"id":52385905},{"atb":[[1.16,100],[1.02,8.9]],"id":52385899}],"con":true,"img":true}]}
{"op":"mcm","clk":"11548656205","pt":1719472082590,"mc":[{"id":"1.230178171","marketDefinition":{"bspMarket":false,"turnInPlayEnabled":false,"persistenceEnabled":false,"marketBaseRate":5.0,"eventId":"33376048","eventTypeId":"4339","numberOfWinners":1,"bettingType":"ODDS","marketType":"FORECAST","marketTime":"2024-06-27T15:03:00.000Z","suspendTime":"2024-06-27T15:03:00.000Z","bspReconciled":false,"complete":true,"inPlay":false,"crossMatching":false,"runnersVoidable":false,"numberOfActiveRunners":30,"betDelay":0,"status":"OPEN","runners":[{"status":"ACTIVE","sortPriority":1,"id":52385882,"name":"1 - 2"},{"status":"ACTIVE","sortPriority":2,"id":52385883,"name":"1 - 3"},{"status":"ACTIVE","sortPriority":3,"id":52385884,"name":"1 - 4"},{"status":"ACTIVE","sortPriority":4,"id":52385885,"name":"1 - 5"},{"status":"ACTIVE","sortPriority":5,"id":52385886,"name":"1 - 6"},{"status":"ACTIVE","sortPriority":6,"id":52385889,"name":"2 - 1"},{"status":"ACTIVE","sortPriority":7,"id":52385890,"name":"2 - 3"},{"status":"ACTIVE","sortPriority":8,"id":52385891,"name":"2 - 4"},{"status":"ACTIVE","sortPriority":9,"id":52385892,"name":"2 - 5"},{"status":"ACTIVE","sortPriority":10,"id":52385893,"name":"2 - 6"},{"status":"ACTIVE","sortPriority":11,"id":52385896,"name":"3 - 1"},{"status":"ACTIVE","sortPriority":12,"id":52385897,"name":"3 - 2"},{"status":"ACTIVE","sortPriority":13,"id":52385898,"name":"3 - 4"},{"status":"ACTIVE","sortPriority":14,"id":52385899,"name":"3 - 5"},{"status":"ACTIVE","sortPriority":15,"id":52385900,"name":"3 - 6"},{"status":"ACTIVE","sortPriority":16,"id":52385903,"name":"4 - 1"},{"status":"ACTIVE","sortPriority":17,"id":52385904,"name":"4 - 2"},{"status":"ACTIVE","sortPriority":18,"id":52385905,"name":"4 - 3"},{"status":"ACTIVE","sortPriority":19,"id":52385906,"name":"4 - 5"},{"status":"ACTIVE","sortPriority":20,"id":52385907,"name":"4 - 6"},{"status":"ACTIVE","sortPriority":21,"id":52385910,"name":"5 - 1"},{"status":"ACTIVE","sortPriority":22,"id":52385911,"name":"5 - 2"},{"status":"ACTIVE","sortPriority":23,"id":52385912,"name":"5 - 3"},{"status":"ACTIVE","sortPriority":24,"id":52385913,"name":"5 - 4"},{"status":"ACTIVE","sortPriority":25,"id":52385914,"name":"5 - 6"},{"status":"ACTIVE","sortPriority":26,"id":52385917,"name":"6 - 1"},{"status":"ACTIVE","sortPriority":27,"id":52385918,"name":"6 - 2"},{"status":"ACTIVE","sortPriority":28,"id":52385919,"name":"6 - 3"},{"status":"ACTIVE","sortPriority":29,"id":52385920,"name":"6 - 4"},{"status":"ACTIVE","sortPriority":30,"id":52385921,"name":"6 - 5"}],"regulators":["MR_INT"],"venue":"Perry Barr","countryCode":"GB","discountAllowed":true,"timezone":"Europe/London","openDate":"2024-06-27T13:29:00.000Z","version":5994794136,"name":"Forecast","eventName":"Perry Barr (F/C) 27th Jun"},"rc":[{"atb":[[1.16,100],[1.02,8.89]],"id":52385910},{"atb":[[1.01,17.79],[1.16,100]],"id":52385912},{"atb":[[1.01,17.79],[1.16,100]],"id":52385906},{"atb":[[1.16,100],[1.03,5.92]],"id":52385918},{"atb":[[1.16,100],[1.02,8.89]],"id":52385920},{"atb":[[1.16,100],[1.03,5.92]],"id":52385889},{"atb":[[1.16,100],[1.02,8.89]],"id":52385914},{"atb":[[1.16,100],[1.03,5.92]],"id":52385883},{"atb":[[1.16,100],[1.03,5.92]],"id":52385885},{"atb":[[1.01,17.79],[1.16,100]],"id":52385896},{"atb":[[1.01,17.79],[1.16,100]],"id":52385890},{"atb":[[1.01,17.79],[1.16,100]],"id":52385892},{"atb":[[1.16,100],[1.02,8.89]],"id":52385904},{"atb":[[1.16,100],[1.03,5.92]],"id":52385898},{"atb":[[1.16,100],[1.03,5.92]],"id":52385900},{"atb":[[1.16,100],[1.02,8.89]],"id":52385911},{"atb":[[1.16,100],[1.02,8.89]],"id":52385913},{"atb":[[1.16,100],[1.03,5.92]],"id":52385907},{"atb":[[1.01,17.79],[1.16,100]],"id":52385886},{"atb":[[1.16,100],[1.03,5.92]],"id":52385919},{"atb":[[1.16,100],[1.02,8.89]],"id":52385921},{"atb":[[1.01,17.79],[1.16,100]],"id":52385882},{"atb":[[1.16,100],[1.03,5.92]],"id":52385884},{"atb":[[1.16,100],[1.02,8.89]],"id":52385917},{"atb":[[1.16,100],[1.02,8.89]],"id":52385897},{"atb":[[1.01,17.79],[1.16,100]],"id":52385891},{"atb":[[1.16,100],[1.03,5.92]],"id":52385893},{"atb":[[1.01,17.79],[1.16,100]],"id":52385903},{"atb":[[1.01,17.79],[1.16,100]],"id":52385905},{"atb":[[1.16,100],[1.02,8.89]],"id":52385899}],"con":true,"img":true}]}
{"op":"mcm","clk":"11548861951","pt":1719477482591,"mc":[{"id":"1.230178171","marketDefinition":{"bspMarket":false,"turnInPlayEnabled":false,"persistenceEnabled":false,"marketBaseRate":5.0,"eventId":"33376048","eventTypeId":"4339","numberOfWinners":1,"bettingType":"ODDS","marketType":"FORECAST","marketTime":"2024-06-27T15:03:00.000Z","suspendTime":"2024-06-27T15:03:00.000Z","bspReconciled":false,"complete":true,"inPlay":false,"crossMatching":false,"runnersVoidable":false,"numberOfActiveRunners":30,"betDelay":0,"status":"OPEN","runners":[{"status":"ACTIVE","sortPriority":1,"id":52385882,"name":"1 - 2"},{"status":"ACTIVE","sortPriority":2,"id":52385883,"name":"1 - 3"},{"status":"ACTIVE","sortPriority":3,"id":52385884,"name":"1 - 4"},{"status":"ACTIVE","sortPriority":4,"id":52385885,"name":"1 - 5"},{"status":"ACTIVE","sortPriority":5,"id":52385886,"name":"1 - 6"},{"status":"ACTIVE","sortPriority":6,"id":52385889,"name":"2 - 1"},{"status":"ACTIVE","sortPriority":7,"id":52385890,"name":"2 - 3"},{"status":"ACTIVE","sortPriority":8,"id":52385891,"name":"2 - 4"},{"status":"ACTIVE","sortPriority":9,"id":52385892,"name":"2 - 5"},{"status":"ACTIVE","sortPriority":10,"id":52385893,"name":"2 - 6"},{"status":"ACTIVE","sortPriority":11,"id":52385896,"name":"3 - 1"},{"status":"ACTIVE","sortPriority":12,"id":52385897,"name":"3 - 2"},{"status":"ACTIVE","sortPriority":13,"id":52385898,"name":"3 - 4"},{"status":"ACTIVE","sortPriority":14,"id":52385899,"name":"3 - 5"},{"status":"ACTIVE","sortPriority":15,"id":52385900,"name":"3 - 6"},{"status":"ACTIVE","sortPriority":16,"id":52385903,"name":"4 - 1"},{"status":"ACTIVE","sortPriority":17,"id":52385904,"name":"4 - 2"},{"status":"ACTIVE","sortPriority":18,"id":52385905,"name":"4 - 3"},{"status":"ACTIVE","sortPriority":19,"id":52385906,"name":"4 - 5"},{"status":"ACTIVE","sortPriority":20,"id":52385907,"name":"4 - 6"},{"status":"ACTIVE","sortPriority":21,"id":52385910,"name":"5 - 1"},{"status":"ACTIVE","sortPriority":22,"id":52385911,"name":"5 - 2"},{"status":"ACTIVE","sortPriority":23,"id":52385912,"name":"5 - 3"},{"status":"ACTIVE","sortPriority":24,"id":52385913,"name":"5 - 4"},{"status":"ACTIVE","sortPriority":25,"id":52385914,"name":"5 - 6"},{"status":"ACTIVE","sortPriority":26,"id":52385917,"name":"6 - 1"},{"status":"ACTIVE","sortPriority":27,"id":52385918,"name":"6 - 2"},{"status":"ACTIVE","sortPriority":28,"id":52385919,"name":"6 - 3"},{"status":"ACTIVE","sortPriority":29,"id":52385920,"name":"6 - 4"},{"status":"ACTIVE","sortPriority":30,"id":52385921,"name":"6 - 5"}],"regulators":["MR_INT"],"venue":"Perry Barr","countryCode":"GB","discountAllowed":true,"timezone":"Europe/London","openDate":"2024-06-27T13:29:00.000Z","version":5994794136,"name":"Forecast","eventName":"Perry Barr (F/C) 27th Jun"},"rc":[{"atb":[[1.16,100],[1.02,8.9]],"id":52385910},{"atb":[[1.01,17.8],[1.16,100]],"id":52385912},{"atb":[[1.01,17.8],[1.16,100]],"id":52385906},{"atb":[[1.16,100],[1.03,5.93]],"id":52385918},{"atb":[[1.16,100],[1.02,8.9]],"id":52385920},{"atb":[[1.16,100],[1.03,5.93]],"id":52385889},{"atb":[[1.16,100],[1.02,8.9]],"id":52385914},{"atb":[[1.16,100],[1.03,5.93]],"id":52385883},{"atb":[[1.16,100],[1.03,5.93]],"id":52385885},{"atb":[[1.01,17.8],[1.16,100]],"id":52385896},{"atb":[[1.01,17.8],[1.16,100]],"id":52385890},{"atb":[[1.01,17.8],[1.16,100]],"id":52385892},{"atb":[[1.16,100],[1.02,8.9]],"id":52385904},{"atb":[[1.16,100],[1.03,5.93]],"id":52385898},{"atb":[[1.16,100],[1.03,5.93]],"id":52385900},{"atb":[[1.16,100],[1.02,8.9]],"id":52385911},{"atb":[[1.16,100],[1.02,8.9]],"id":52385913},{"atb":[[1.16,100],[1.03,5.93]],"id":52385907},{"atb":[[1.01,17.8],[1.16,100]],"id":52385886},{"atb":[[1.16,100],[1.03,5.93]],"id":52385919},{"atb":[[1.16,100],[1.02,8.9]],"id":52385921},{"atb":[[1.01,17.8],[1.16,100]],"id":52385882},{"atb":[[1.16,100],[1.03,5.93]],"id":52385884},{"atb":[[1.16,100],[1.02,8.9]],"id":52385917},{"atb":[[1.16,100],[1.02,8.9]],"id":52385897},{"atb":[[1.01,17.8],[1.16,100]],"id":52385891},{"atb":[[1.16,100],[1.03,5.93]],"id":52385893},{"atb":[[1.01,17.8],[1.16,100]],"id":52385903},{"atb":[[1.01,17.8],[1.16,100]],"id":52385905},{"atb":[[1.16,100],[1.02,8.9]],"id":52385899}],"con":true,"img":true}]}
{"op":"mcm","clk":"11549140215","pt":1719482882591,"mc":[{"id":"1.230178171","marketDefinition":{"bspMarket":false,"turnInPlayEnabled":false,"persistenceEnabled":false,"marketBaseRate":5.0,"eventId":"33376048","eventTypeId":"4339","numberOfWinners":1,"bettingType":"ODDS","marketType":"FORECAST","marketTime":"2024-06-27T15:03:00.000Z","suspendTime":"2024-06-27T15:03:00.000Z","bspReconciled":false,"complete":true,"inPlay":false,"crossMatching":false,"runnersVoidable":false,"numberOfActiveRunners":30,"betDelay":0,"status":"OPEN","runners":[{"status":"ACTIVE","sortPriority":1,"id":52385882,"name":"1 - 2"},{"status":"ACTIVE","sortPriority":2,"id":52385883,"name":"1 - 3"},{"status":"ACTIVE","sortPriority":3,"id":52385884,"name":"1 - 4"},{"status":"ACTIVE","sortPriority":4,"id":52385885,"name":"1 - 5"},{"status":"ACTIVE","sortPriority":5,"id":52385886,"name":"1 - 6"},{"status":"ACTIVE","sortPriority":6,"id":52385889,"name":"2 - 1"},{"status":"ACTIVE","sortPriority":7,"id":52385890,"name":"2 - 3"},{"status":"ACTIVE","sortPriority":8,"id":52385891,"name":"2 - 4"},{"status":"ACTIVE","sortPriority":9,"id":52385892,"name":"2 - 5"},{"status":"ACTIVE","sortPriority":10,"id":52385893,"name":"2 - 6"},{"status":"ACTIVE","sortPriority":11,"id":52385896,"name":"3 - 1"},{"status":"ACTIVE","sortPriority":12,"id":52385897,"name":"3 - 2"},{"status":"ACTIVE","sortPriority":13,"id":52385898,"name":"3 - 4"},{"status":"ACTIVE","sortPriority":14,"id":52385899,"name":"3 - 5"},{"status":"ACTIVE","sortPriority":15,"id":52385900,"name":"3 - 6"},{"status":"ACTIVE","sortPriority":16,"id":52385903,"name":"4 - 1"},{"status":"ACTIVE","sortPriority":17,"id":52385904,"name":"4 - 2"},{"status":"ACTIVE","sortPriority":18,"id":52385905,"name":"4 - 3"},{"status":"ACTIVE","sortPriority":19,"id":52385906,"name":"4 - 5"},{"status":"ACTIVE","sortPriority":20,"id":52385907,"name":"4 - 6"},{"status":"ACTIVE","sortPriority":21,"id":52385910,"name":"5 - 1"},{"status":"ACTIVE","sortPriority":22,"id":52385911,"name":"5 - 2"},{"status":"ACTIVE","sortPriority":23,"id":52385912,"name":"5 - 3"},{"status":"ACTIVE","sortPriority":24,"id":52385913,"name":"5 - 4"},{"status":"ACTIVE","sortPriority":25,"id":52385914,"name":"5 - 6"},{"status":"ACTIVE","sortPriority":26,"id":52385917,"name":"6 - 1"},{"status":"ACTIVE","sortPriority":27,"id":52385918,"name":"6 - 2"},{"status":"ACTIVE","sortPriority":28,"id":52385919,"name":"6 - 3"},{"status":"ACTIVE","sortPriority":29,"id":52385920,"name":"6 - 4"},{"status":"ACTIVE","sortPriority":30,"id":52385921,"name":"6 - 5"}],"regulators":["MR_INT"],"venue":"Perry Barr","countryCode":"GB","discountAllowed":true,"timezone":"Europe/London","openDate":"2024-06-27T13:29:00.000Z","version":5994794136,"name":"Forecast","eventName":"Perry Barr (F/C) 27th Jun"},"rc":[{"atb":[[1.16,100],[1.02,8.89]],"id":52385910},{"atb":[[1.01,17.79],[1.16,100]],"id":52385912},{"atb":[[1.01,17.79],[1.16,100]],"id":52385906},{"atb":[[1.16,100],[1.03,5.92]],"id":52385918},{"atb":[[1.16,100],[1.02,8.89]],"id":52385920},{"atb":[[1.16,100],[1.03,5.92]],"id":52385889},{"atb":[[1.16,100],[1.02,8.89]],"id":52385914},{"atb":[[1.16,100],[1.03,5.92]],"id":52385883},{"atb":[[1.16,100],[1.03,5.92]],"id":52385885},{"atb":[[1.01,17.79],[1.16,100]],"id":52385896},{"atb":[[1.01,17.79],[1.16,100]],"id":52385890},{"atb":[[1.01,17.79],[1.16,100]],"id":52385892},{"atb":[[1.16,100],[1.02,8.89]],"id":52385904},{"atb":[[1.16,100],[1.03,5.92]],"id":52385898},{"atb":[[1.16,100],[1.03,5.92]],"id":52385900},{"atb":[[1.16,100],[1.02,8.89]],"id":52385911},{"atb":[[1.16,100],[1.02,8.89]],"id":52385913},{"atb":[[1.16,100],[1.03,5.92]],"id":52385907},{"atb":[[1.01,17.79],[1.16,100]],"id":52385886},{"atb":[[1.16,100],[1.03,5.92]],"id":52385919},{"atb":[[1.16,100],[1.02,8.89]],"id":52385921},{"atb":[[1.01,17.79],[1.16,100]],"id":52385882},{"atb":[[1.16,100],[1.03,5.92]],"id":52385884},{"atb":[[1.16,100],[1.02,8.89]],"id":52385917},{"atb":[[1.16,100],[1.02,8.89]],"id":52385897},{"atb":[[1.01,17.79],[1.16,100]],"id":52385891},{"atb":[[1.16,100],[1.03,5.92]],"id":52385893},{"atb":[[1.01,17.79],[1.16,100]],"id":52385903},{"atb":[[1.01,17.79],[1.16,100]],"id":52385905},{"atb":[[1.16,100],[1.02,8.89]],"id":52385899}],"con":true,"img":true}]}
{"op":"mcm","clk":"11549606650","pt":1719488282608,"mc":[{"id":"1.230178171","marketDefinition":{"bspMarket":false,"turnInPlayEnabled":false,"persistenceEnabled":false,"marketBaseRate":5.0,"eventId":"33376048","eventTypeId":"4339","numberOfWinners":1,"bettingType":"ODDS","marketType":"FORECAST","marketTime":"2024-06-27T15:03:00.000Z","suspendTime":"2024-06-27T15:03:00.000Z","bspReconciled":false,"complete":true,"inPlay":false,"crossMatching":false,"runnersVoidable":false,"numberOfActiveRunners":30,"betDelay":0,"status":"OPEN","runners":[{"status":"ACTIVE","sortPriority":1,"id":52385882,"name":"1 - 2"},{"status":"ACTIVE","sortPriority":2,"id":52385883,"name":"1 - 3"},{"status":"ACTIVE","sortPriority":3,"id":52385884,"name":"1 - 4"},{"status":"ACTIVE","sortPriority":4,"id":52385885,"name":"1 - 5"},{"status":"ACTIVE","sortPriority":5,"id":52385886,"name":"1 - 6"},{"status":"ACTIVE","sortPriority":6,"id":52385889,"name":"2 - 1"},{"status":"ACTIVE","sortPriority":7,"id":52385890,"name":"2 - 3"},{"status":"ACTIVE","sortPriority":8,"id":52385891,"name":"2 - 4"},{"status":"ACTIVE","sortPriority":9,"id":52385892,"name":"2 - 5"},{"status":"ACTIVE","sortPriority":10,"id":52385893,"name":"2 - 6"},{"status":"ACTIVE","sortPriority":11,"id":52385896,"name":"3 - 1"},{"status":"ACTIVE","sortPriority":12,"id":52385897,"name":"3 - 2"},{"status":"ACTIVE","sortPriority":13,"id":52385898,"name":"3 - 4"},{"status":"ACTIVE","sortPriority":14,"id":52385899,"name":"3 - 5"},{"status":"ACTIVE","sortPriority":15,"id":52385900,"name":"3 - 6"},{"status":"ACTIVE","sortPriority":16,"id":52385903,"name":"4 - 1"},{"status":"ACTIVE","sortPriority":17,"id":52385904,"name":"4 - 2"},{"status":"ACTIVE","sortPriority":18,"id":52385905,"name":"4 - 3"},{"status":"ACTIVE","sortPriority":19,"id":52385906,"name":"4 - 5"},{"status":"ACTIVE","sortPriority":20,"id":52385907,"name":"4 - 6"},{"status":"ACTIVE","sortPriority":21,"id":52385910,"name":"5 - 1"},{"status":"ACTIVE","sortPriority":22,"id":52385911,"name":"5 - 2"},{"status":"ACTIVE","sortPriority":23,"id":52385912,"name":"5 - 3"},{"status":"ACTIVE","sortPriority":24,"id":52385913,"name":"5 - 4"},{"status":"ACTIVE","sortPriority":25,"id":52385914,"name":"5 - 6"},{"status":"ACTIVE","sortPriority":26,"id":52385917,"name":"6 - 1"},{"status":"ACTIVE","sortPriority":27,"id":52385918,"name":"6 - 2"},{"status":"ACTIVE","sortPriority":28,"id":52385919,"name":"6 - 3"},{"status":"ACTIVE","sortPriority":29,"id":52385920,"name":"6 - 4"},{"status":"ACTIVE","sortPriority":30,"id":52385921,"name":"6 - 5"}],"regulators":["MR_INT"],"venue":"Perry Barr","countryCode":"GB","discountAllowed":true,"timezone":"Europe/London","openDate":"2024-06-27T13:29:00.000Z","version":5994794136,"name":"Forecast","eventName":"Perry Barr (F/C) 27th Jun"},"rc":[{"atb":[[1.16,100],[1.02,8.89]],"id":52385910},{"atb":[[1.01,17.79],[1.16,100]],"id":52385912},{"atb":[[1.01,17.79],[1.16,100]],"id":52385906},{"atb":[[1.16,100],[1.03,5.93]],"id":52385918},{"atb":[[1.16,100],[1.02,8.89]],"id":52385920},{"atb":[[1.16,100],[1.03,5.93]],"id":52385889},{"atb":[[1.16,100],[1.02,8.89]],"id":52385914},{"atb":[[1.16,100],[1.03,5.93]],"id":52385883},{"atb":[[1.16,100],[1.03,5.93]],"id":52385885},{"atb":[[1.01,17.79],[1.16,100]],"id":52385896},{"atb":[[1.01,17.79],[1.16,100]],"id":52385890},{"atb":[[1.01,17.79],[1.16,100]],"id":52385892},{"atb":[[1.16,100],[1.02,8.89]],"id":52385904},{"atb":[[1.16,100],[1.03,5.93]],"id":52385898},{"atb":[[1.16,100],[1.03,5.93]],"id":52385900},{"atb":[[1.16,100],[1.02,8.89]],"id":52385911},{"atb":[[1.16,100],[1.02,8.89]],"id":52385913},{"atb":[[1.16,100],[1.03,5.93]],"id":52385907},{"atb":[[1.01,17.79],[1.16,100]],"id":52385886},{"atb":[[1.16,100],[1.03,5.93]],"id":52385919},{"atb":[[1.16,100],[1.02,8.89]],"id":52385921},{"atb":[[1.01,17.79],[1.16,100]],"id":52385882},{"atb":[[1.16,100],[1.03,5.93]],"id":52385884},{"atb":[[1.16,100],[1.02,8.89]],"id":52385917},{"atb":[[1.16,100],[1.02,8.89]],"id":52385897},{"atb":[[1.01,17.79],[1.16,100]],"id":52385891},{"atb":[[1.16,100],[1.03,5.93]],"id":52385893},{"atb":[[1.01,17.79],[1.16,100]],"id":52385903},{"atb":[[1.01,17.79],[1.16,100]],"id":52385905},{"atb":[[1.16,100],[1.02,8.89]],"id":52385899}],"con":true,"img":true}]}
{"op":"mcm","clk":"11549730417","pt":1719489929323,"mc":[{"id":"1.230178171","rc":[{"atb":[[1.02,8.89]],"id":52385910},{"atb":[[1.01,17.79]],"id":52385912},{"atb":[[1.01,17.79]],"id":52385906},{"atb":[[1.03,5.93]],"id":52385918},{"atb":[[1.02,8.89]],"id":52385920},{"atb":[[1.03,5.93]],"id":52385889},{"atb":[[1.02,8.89]],"id":52385914},{"atb":[[1.01,306.12],[1.03,5.93]],"id":52385883},{"atb":[[1.03,5.93]],"id":52385885},{"atb":[[1.01,17.79]],"id":52385896},{"atb":[[1.01,17.79]],"id":52385890},{"atb":[[1.01,17.79]],"id":52385892},{"atb":[[1.02,8.89]],"id":52385904},{"atb":[[1.03,5.93]],"id":52385898},{"atb":[[1.03,5.93]],"id":52385900},{"atb":[[1.02,8.89]],"id":52385911},{"atb":[[1.02,8.89]],"id":52385913},{"atb":[[1.03,5.93]],"id":52385907},{"atb":[[1.01,17.79]],"id":52385886},{"atb":[[1.03,5.93]],"id":52385919},{"atb":[[1.02,8.89]],"id":52385921},{"atb":[[1.01,323.91]],"id":52385882},{"atb":[[1.01,306.12],[1.03,5.93]],"id":52385884},{"atb":[[1.02,8.89]],"id":52385917},{"atb":[[1.02,8.89]],"id":52385897},{"atb":[[1.01,17.79]],"id":52385891},{"atb":[[1.03,5.93]],"id":52385893},{"atb":[[1.01,17.79]],"id":52385903},{"atb":[[1.01,17.79]],"id":52385905},{"atb":[[1.02,8.89]],"id":52385899}],"con":true,"img":false}]}
{"op":"mcm","clk":"11549730434","pt":1719489929530,"mc":[{"id":"1.230178171","rc":[{"atb":[[1.01,306.12]],"id":52385889},{"atb":[[1.01,306.12]],"id":52385885},{"atb":[[1.01,323.91]],"id":52385886}],"con":true,"img":false}]}
{"op":"mcm","clk":"11549730446","pt":1719489929737,"mc":[{"id":"1.230178171","rc":[{"atb":[[1.01,323.91]],"id":52385890},{"atb":[[1.01,323.91]],"id":52385891}],"con":true,"img":false}]}
{"op":"mcm","clk":"11549730451","pt":1719489929840,"mc":[{"id":"1.230178171","rc":[{"atb":[[1.01,323.91]],"id":52385892}],"con":true,"img":false}]}
{"op":"mcm","clk":"11549730458","pt":1719489929942,"mc":[{"id":"1.230178171","rc":[{"atb":[[1.01,323.91]],"id":52385896},{"atb":[[1.01,306.12]],"id":52385893}],"con":true,"img":false}]}
{"op":"mcm","clk":"11549730478","pt":1719489930149,"mc":[{"id":"1.230178171","rc":[{"atb":[[1.01,306.12]],"id":52385897}],"con":true,"img":false}]}
{"op":"mcm","clk":"11549730489","pt":1719489930252,"mc":[{"id":"1.230178171","rc":[{"atb":[[1.01,306.12]],"id":52385898}],"con":true,"img":false}]}
{"op":"mcm","clk":"11549730498","pt":1719489930355,"mc":[{"id":"1.230178171","rc":[{"atb":[[1.01,306.12]],"id":52385899}],"con":true,"img":false}]}
{"op":"mcm","clk":"11549730514","pt":1719489930515,"mc":[{"id":"1.230178171","rc":[{"atb":[[1.01,306.12]],"id":52385900}],"con":true,"img":false}]}
{"op":"mcm","clk":"11549730519","pt":1719489930615,"mc":[{"id":"1.230178171","rc":[{"atb":[[1.01,323.91]],"id":52385903}],"con":true,"img":false}]}
{"op":"mcm","clk":"11549730524","pt":1719489930717,"mc":[{"id":"1.230178171","rc":[{"atb":[[1.01,306.12]],"id":52385904}],"con":true,"img":false}]}
{"op":"mcm","clk":"11549730531","pt":1719489930825,"mc":[{"id":"1.230178171","rc":[{"atb":[[1.01,323.91]],"id":52385905}],"con":true,"img":false}]}
{"op":"mcm","clk":"11549730537","pt":1719489930927,"mc":[{"id":"1.230178171","rc":[{"atb":[[1.01,323.91]],"id":52385906},{"atb":[[1.01,306.12]],"id":52385907}],"con":true,"img":false}]}
{"op":"mcm","clk":"11549730544","pt":1719489931030,"mc":[{"id":"1.230178171","rc":[{"atb":[[1.01,306.12]],"id":52385910}],"con":true,"img":false}]}
{"op":"mcm","clk":"11549730553","pt":1719489931136,"mc":[{"id":"1.230178171","rc":[{"atb":[[1.01,306.12]],"id":52385911}],"con":true,"img":false}]}
{"op":"mcm","clk":"11549730561","pt":1719489931240,"mc":[{"id":"1.230178171","rc":[{"atb":[[1.01,323.91]],"id":52385912},{"atb":[[1.01,306.12]],"id":52385913}],"con":true,"img":false}]}
{"op":"mcm","clk":"11549730576","pt":1719489931343,"mc":[{"id":"1.230178171","rc":[{"atb":[[1.01,306.12]],"id":52385914}],"con":true,"img":false}]}
{"op":"mcm","clk":"11549730587","pt":1719489931445,"mc":[{"id":"1.230178171","rc":[{"atb":[[1.01,306.12]],"id":52385917}],"con":true,"img":false}]}
{"op":"mcm","clk":"11549730594","pt":1719489931548,"mc":[{"id":"1.230178171","rc":[{"atb":[[1.01,306.12]],"id":52385918}],"con":true,"img":false}]}
{"op":"mcm","clk":"11549730601","pt":1719489931654,"mc":[{"id":"1.230178171","rc":[{"atb":[[1.01,306.12]],"id":52385919}],"con":true,"img":false}]}
{"op":"mcm","clk":"11549730610","pt":1719489931753,"mc":[{"id":"1.230178171","rc":[{"atb":[[1.01,306.12]],"id":52385920}],"con":true,"img":false}]}
{"op":"mcm","clk":"11549730619","pt":1719489931857,"mc":[{"id":"1.230178171","rc":[{"atb":[[1.01,306.12]],"id":52385921}],"con":true,"img":false}]}
{"op":"mcm","clk":"11549730630","pt":1719489932016,"mc":[{"id":"1.230178171","rc":[{"atb":[[1.17,120.05]],"id":52385883},{"atb":[[1.17,120.05]],"id":52385882}],"con":true,"img":false}]}
{"op":"mcm","clk":"11549730641","pt":1719489932122,"mc":[{"id":"1.230178171","rc":[{"atb":[[1.17,120.05]],"id":52385884}],"con":true,"img":false}]}
{"op":"mcm","clk":"11549730650","pt":1719489932221,"mc":[{"id":"1.230178171","rc":[{"atb":[[1.17,120.05]],"id":52385885},{"atb":[[1.17,120.05]],"id":52385886}],"con":true,"img":false}]}
{"op":"mcm","clk":"11549730658","pt":1719489932327,"mc":[{"id":"1.230178171","rc":[{"atb":[[1.17,120.05]],"id":52385889}],"con":true,"img":false}]}
{"op":"mcm","clk":"11549730668","pt":1719489932429,"mc":[{"id":"1.230178171","rc":[{"atb":[[1.17,120.05]],"id":52385890}],"con":true,"img":false}]}
{"op":"mcm","clk":"11549730674","pt":1719489932535,"mc":[{"id":"1.230178171","rc":[{"atb":[[1.17,120.05]],"id":52385891}],"con":true,"img":false}]}
{"op":"mcm","clk":"11549730690","pt":1719489932739,"mc":[{"id":"1.230178171","rc":[{"atb":[[1.17,120.05]],"id":52385892},{"atb":[[1.17,120.05]],"id":52385893}],"con":true,"img":false}]}
{"op":"mcm","clk":"11549730711","pt":1719489933050,"mc":[{"id":"1.230178171","rc":[{"atb":[[1.17,120.05]],"id":52385896},{"atb":[[1.17,120.05]],"id":52385897}],"con":true,"img":false}]}
{"op":"mcm","clk":"11549730729","pt":1719489933214,"mc":[{"id":"1.230178171","rc":[{"atb":[[1.17,120.05]],"id":52385898}],"con":true,"img":false}]}
{"op":"mcm","clk":"11549730738","pt":1719489933314,"mc":[{"id":"1.230178171","rc":[{"atb":[[1.17,120.05]],"id":52385900},{"atb":[[1.17,120.05]],"id":52385899}],"con":true,"img":false}]}
{"op":"mcm","clk":"11549730750","pt":1719489933416,"mc":[{"id":"1.230178171","rc":[{"atb":[[1.17,120.05]],"id":52385903}],"con":true,"img":false}]}
{"op":"mcm","clk":"11549730758","pt":1719489933519,"mc":[{"id":"1.230178171","rc":[{"atb":[[1.17,120.05]],"id":52385904}],"con":true,"img":false}]}
{"op":"mcm","clk":"11549730766","pt":1719489933622,"mc":[{"id":"1.230178171","rc":[{"atb":[[1.17,120.05]],"id":52385906},{"atb":[[1.17,120.05]],"id":52385905}],"con":true,"img":false}]}
{"op":"mcm","clk":"11549730774","pt":1719489933724,"mc":[{"id":"1.230178171","rc":[{"atb":[[1.17,120.05]],"id":52385907}],"con":true,"img":false}]}
{"op":"mcm","clk":"11549730781","pt":1719489933828,"mc":[{"id":"1.230178171","rc":[{"atb":[[1.17,120.05]],"id":52385910}],"con":true,"img":false}]}
{"op":"mcm","clk":"11549730790","pt":1719489933930,"mc":[{"id":"1.230178171","rc":[{"atb":[[1.17,120.05]],"id":52385912},{"atb":[[1.17,120.05]],"id":52385911}],"con":true,"img":false}]}
{"op":"mcm","clk":"11549730797","pt":1719489934041,"mc":[{"id":"1.230178171","rc":[{"atb":[[1.17,120.05]],"id":52385913}],"con":true,"img":false}]}
{"op":"mcm","clk":"11549730805","pt":1719489934144,"mc":[{"id":"1.230178171","rc":[{"atb":[[1.17,120.05]],"id":52385914}],"con":true,"img":false}]}
{"op":"mcm","clk":"11549730812","pt":1719489934246,"mc":[{"id":"1.230178171","rc":[{"atb":[[1.17,120.05]],"id":52385917}],"con":true,"img":false}]}
{"op":"mcm","clk":"11549730820","pt":1719489934353,"mc":[{"id":"1.230178171","rc":[{"atb":[[1.17,120.05]],"id":52385918}],"con":true,"img":false}]}
{"op":"mcm","clk":"11549730830","pt":1719489934454,"mc":[{"id":"1.230178171","rc":[{"atb":[[1.17,120.05]],"id":52385920},{"atb":[[1.17,120.05]],"id":52385919}],"con":true,"img":false}]}
{"op":"mcm","clk":"11549730839","pt":1719489934556,"mc":[{"id":"1.230178171","rc":[{"atb":[[1.17,120.05]],"id":52385921}],"con":true,"img":false}]}
{"op":"mcm","clk":"11549966955","pt":1719493166008,"mc":[{"id":"1.230178171","rc":[{"atb":[[1.03,92.2]],"id":52385910},{"atl":[[960,1.49]],"id":52385910},{"atb":[[1.02,72.75]],"id":52385912},{"atl":[[980,1.59]],"id":52385912},{"atb":[[1.02,107.43]],"id":52385906},{"atl":[[980,0.85]],"id":52385906},{"atb":[[1.04,105.74]],"id":52385889},{"atl":[[970,1.3]],"id":52385889},{"atb":[[1.04,136.19]],"id":52385914},{"atl":[[990,0.85]],"id":52385914},{"atb":[[1.03,132.82]],"id":52385883},{"atl":[[970,0.85]],"id":52385883},{"atb":[[1.03,79.52]],"id":52385885},{"atl":[[970,1.31]],"id":52385885},{"atb":[[1.04,120.97]],"id":52385896},{"atl":[[970,2.06]],"id":52385896},{"atb":[[1.03,101.51]],"id":52385890},{"atl":[[990,0.85]],"id":52385890},{"atb":[[1.04,130.27]],"id":52385892},{"atl":[[970,1.3]],"id":52385892},{"atb":[[1.04,118.43]],"id":52385904},{"atl":[[990,1.98]],"id":52385904},{"atb":[[1.04,83.74]],"id":52385898},{"atl":[[990,1.85]],"id":52385898},{"atb":[[1.04,75.28]],"id":52385900},{"atl":[[960,2.11]],"id":52385900},{"atb":[[1.03,67.67]],"id":52385911},{"atl":[[960,1.75]],"id":52385911},{"atb":[[1.04,85.44]],"id":52385913},{"atl":[[980,1.79]],"id":52385913},{"atb":[[1.02,132.81]],"id":52385907},{"atl":[[960,1.59]],"id":52385907},{"atb":[[1.04,129.43]],"id":52385886},{"atl":[[960,0.85]],"id":52385886},{"atb":[[1.02,140.42]],"id":52385882},{"atl":[[970,1.09]],"id":52385882},{"atb":[[1.04,146.34]],"id":52385884},{"atl":[[970,1.25]],"id":52385884},{"atb":[[1.03,94.74]],"id":52385897},{"atl":[[980,0.93]],"id":52385897},{"atb":[[1.03,148.04]],"id":52385891},{"atl":[[970,1.04]],"id":52385891},{"atb":[[1.04,73.59]],"id":52385893},{"atl":[[990,2.07]],"id":52385893},{"atb":[[1.03,93.9]],"id":52385903},{"atl":[[990,1.86]],"id":52385903},{"atb":[[1.02,152.27]],"id":52385905},{"atl":[[990,0.85]],"id":52385905},{"atb":[[1.03,167.49]],"id":52385899},{"atl":[[970,0.85]],"id":52385899}],"con":true,"img":false}]}
{"op":"mcm","clk":"11549968444","pt":1719493183905,"mc":[{"id":"1.230178171","marketDefinition":{"bspMarket":false,"turnInPlayEnabled":false,"persistenceEnabled":false,"marketBaseRate":5.0,"eventId":"33376048","eventTypeId":"4339","numberOfWinners":1,"bettingType":"ODDS","marketType":"FORECAST","marketTime":"2024-06-27T15:03:00.000Z","suspendTime":"2024-06-27T15:03:00.000Z","bspReconciled":false,"complete":true,"inPlay":false,"crossMatching":true,"runnersVoidable":false,"numberOfActiveRunners":30,"betDelay":0,"status":"OPEN","runners":[{"status":"ACTIVE","sortPriority":1,"id":52385882,"name":"1 - 2"},{"status":"ACTIVE","sortPriority":2,"id":52385883,"name":"1 - 3"},{"status":"ACTIVE","sortPriority":3,"id":52385884,"name":"1 - 4"},{"status":"ACTIVE","sortPriority":4,"id":52385885,"name":"1 - 5"},{"status":"ACTIVE","sortPriority":5,"id":52385886,"name":"1 - 6"},{"status":"ACTIVE","sortPriority":6,"id":52385889,"name":"2 - 1"},{"status":"ACTIVE","sortPriority":7,"id":52385890,"name":"2 - 3"},{"status":"ACTIVE","sortPriority":8,"id":52385891,"name":"2 - 4"},{"status":"ACTIVE","sortPriority":9,"id":52385892,"name":"2 - 5"},{"status":"ACTIVE","sortPriority":10,"id":52385893,"name":"2 - 6"},{"status":"ACTIVE","sortPriority":11,"id":52385896,"name":"3 - 1"},{"status":"ACTIVE","sortPriority":12,"id":52385897,"name":"3 - 2"},{"status":"ACTIVE","sortPriority":13,"id":52385898,"name":"3 - 4"},{"status":"ACTIVE","sortPriority":14,"id":52385899,"name":"3 - 5"},{"status":"ACTIVE","sortPriority":15,"id":52385900,"name":"3 - 6"},{"status":"ACTIVE","sortPriority":16,"id":52385903,"name":"4 - 1"},{"status":"ACTIVE","sortPriority":17,"id":52385904,"name":"4 - 2"},{"status":"ACTIVE","sortPriority":18,"id":52385905,"name":"4 - 3"},{"status":"ACTIVE","sortPriority":19,"id":52385906,"name":"4 - 5"},{"status":"ACTIVE","sortPriority":20,"id":52385907,"name":"4 - 6"},{"status":"ACTIVE","sortPriority":21,"id":52385910,"name":"5 - 1"},{"status":"ACTIVE","sortPriority":22,"id":52385911,"name":"5 - 2"},{"status":"ACTIVE","sortPriority":23,"id":52385912,"name":"5 - 3"},{"status":"ACTIVE","sortPriority":24,"id":52385913,"name":"5 - 4"},{"status":"ACTIVE","sortPriority":25,"id":52385914,"name":"5 - 6"},{"status":"ACTIVE","sortPriority":26,"id":52385917,"name":"6 - 1"},{"status":"ACTIVE","sortPriority":27,"id":52385918,"name":"6 - 2"},{"status":"ACTIVE","sortPriority":28,"id":52385919,"name":"6 - 3"},{"status":"ACTIVE","sortPriority":29,"id":52385920,"name":"6 - 4"},{"status":"ACTIVE","sortPriority":30,"id":52385921,"name":"6 - 5"}],"regulators":["MR_INT"],"venue":"Perry Barr","countryCode":"GB","discountAllowed":true,"timezone":"Europe/London","openDate":"2024-06-27T13:29:00.000Z","version":5994794136,"name":"Forecast","eventName":"Perry Barr (F/C) 27th Jun"},"rc":[],"con":true,"img":false}]}
{"op":"mcm","clk":"11549970626","pt":1719493210268,"mc":[{"id":"1.230178171","rc":[{"atb":[[1.16,0],[1.03,92.31],[1.02,8.9]],"id":52385910},{"atl":[[960,1.49]],"id":52385910},{"atb":[[1.01,323.93],[1.16,0],[1.02,72.83]],"id":52385912},{"atl":[[980,1.59]],"id":52385912},{"atb":[[1.01,323.93],[1.16,0],[1.02,107.56]],"id":52385906},{"atl":[[980,0.85]],"id":52385906},{"atb":[[1.16,0],[1.03,5.93]],"id":52385918},{"atb":[[1.16,0],[1.02,8.9]],"id":52385920},{"atb":[[1.16,0],[1.03,5.93],[1.04,105.86]],"id":52385889},{"atl":[[970,1.3]],"id":52385889},{"atb":[[1.16,0],[1.02,8.9],[1.04,136.35]],"id":52385914},{"atl":[[990,0.85]],"id":52385914},{"atb":[[1.16,0],[1.03,132.98]],"id":52385883},{"atl":[[970,0.85]],"id":52385883},{"atb":[[1.16,0],[1.03,79.62]],"id":52385885},{"atl":[[970,1.32]],"id":52385885},{"atb":[[1.01,323.93],[1.16,0],[1.04,121.11]],"id":52385896},{"atl":[[970,2.06]],"id":52385896},{"atb":[[1.01,323.93],[1.16,0],[1.03,101.63]],"id":52385890},{"atl":[[990,0.85]],"id":52385890},{"atb":[[1.01,323.93],[1.16,0],[1.04,130.43]],"id":52385892},{"atl":[[970,1.3]],"id":52385892},{"atb":[[1.16,0],[1.02,8.9],[1.04,118.57]],"id":52385904},{"atl":[[990,1.99]],"id":52385904},{"atb":[[1.16,0],[1.03,5.93],[1.04,83.84]],"id":52385898},{"atl":[[990,1.85]],"id":52385898},{"atb":[[1.16,0],[1.03,5.93],[1.04,75.37]],"id":52385900},{"atl":[[960,2.11]],"id":52385900},{"atb":[[1.16,0],[1.03,67.75],[1.02,8.9]],"id":52385911},{"atl":[[960,1.75]],"id":52385911},{"atb":[[1.16,0],[1.02,8.9],[1.04,85.54]],"id":52385913},{"atl":[[980,1.79]],"id":52385913},{"atb":[[1.16,0],[1.03,5.93],[1.02,132.97]],"id":52385907},{"atl":[[960,1.59]],"id":52385907},{"atb":[[1.01,323.93],[1.16,0],[1.04,129.58]],"id":52385886},{"atl":[[960,0.85]],"id":52385886},{"atb":[[1.16,0],[1.03,5.93]],"id":52385919},{"atb":[[1.16,0],[1.02,8.9]],"id":52385921},{"atb":[[1.01,323.93],[1.16,0],[1.02,140.59]],"id":52385882},{"atl":[[970,1.1]],"id":52385882},{"atb":[[1.16,0],[1.03,5.93],[1.04,146.52]],"id":52385884},{"atl":[[970,1.25]],"id":52385884},{"atb":[[1.16,0],[1.02,8.9]],"id":52385917},{"atb":[[1.16,0],[1.03,94.85],[1.02,8.9]],"id":52385897},{"atl":[[980,0.94]],"id":52385897},{"atb":[[1.01,323.93],[1.16,0],[1.03,148.21]],"id":52385891},{"atl":[[970,1.04]],"id":52385891},{"atb":[[1.16,0],[1.03,5.93],[1.04,73.68]],"id":52385893},{"atl":[[990,2.07]],"id":52385893},{"atb":[[1.01,323.93],[1.16,0],[1.03,94.01]],"id":52385903},{"atl":[[990,1.87]],"id":52385903},{"atb":[[1.01,323.93],[1.16,0],[1.02,152.45]],"id":52385905},{"atl":[[990,0.85]],"id":52385905},{"atb":[[1.16,0],[1.03,167.69],[1.02,8.9]],"id":52385899},{"atl":[[970,0.85]],"id":52385899}],"con":true,"img":false}]}
{"op":"mcm","clk":"11549974904","pt":1719493263828,"mc":[{"id":"1.230178171","rc":[{"atb":[[1.18,150]],"id":52385910},{"atb":[[1.18,150]],"id":52385912},{"atb":[[1.18,150]],"id":52385906},{"atb":[[1.18,150]],"id":52385918},{"atb":[[1.18,150]],"id":52385920},{"atb":[[1.18,150]],"id":52385889},{"atb":[[1.18,150]],"id":52385914},{"atb":[[1.18,150]],"id":52385883},{"atb":[[1.18,150]],"id":52385885},{"atb":[[1.18,150]],"id":52385896},{"atb":[[1.18,150]],"id":52385890},{"atb":[[1.18,150]],"id":52385892},{"atb":[[1.18,150]],"id":52385904},{"atb":[[1.18,150]],"id":52385898},{"atb":[[1.18,150]],"id":52385900},{"atb":[[1.18,150]],"id":52385911},{"atb":[[1.18,150]],"id":52385913},{"atb":[[1.18,150]],"id":52385907},{"atb":[[1.18,150]],"id":52385886},{"atb":[[1.18,150]],"id":52385919},{"atb":[[1.18,150]],"id":52385921},{"atb":[[1.18,150]],"id":52385882},{"atb":[[1.18,150]],"id":52385884},{"atb":[[1.18,150]],"id":52385917},{"atb":[[1.18,150]],"id":52385897},{"atb":[[1.18,150]],"id":52385891},{"atb":[[1.18,150]],"id":52385893},{"atb":[[1.18,150]],"id":52385903},{"atb":[[1.18,150]],"id":52385905},{"atb":[[1.18,150]],"id":52385899}],"con":true,"img":false}]}
{"op":"mcm","clk":"11549975547","pt":1719493270744,"mc":[{"id":"1.230178171","rc":[{"atb":[[1.17,0]],"id":52385883}],"con":true,"img":false}]}
{"op":"mcm","clk":"11549993758","pt":1719493480984,"mc":[{"id":"1.230178171","rc":[{"atb":[[1.17,0]],"id":52385882}],"con":true,"img":false}]}
{"op":"mcm","clk":"11550046012","pt":1719493931089,"mc":[{"id":"1.230178171","rc":[{"atb":[[1.17,0]],"id":52385884}],"con":true,"img":false}]}
{"op":"mcm","clk":"11550069075","pt":1719494161065,"mc":[{"id":"1.230178171","rc":[{"atb":[[1.17,0]],"id":52385886}],"con":true,"img":false}]}
{"op":"mcm","clk":"11550094201","pt":1719494391294,"mc":[{"id":"1.230178171","rc":[{"atb":[[1.17,0]],"id":52385885}],"con":true,"img":false}]}
{"op":"mcm","clk":"11550120025","pt":1719494621328,"mc":[{"id":"1.230178171","rc":[{"atb":[[1.17,0]],"id":52385889}],"con":true,"img":false}]}
{"op":"mcm","clk":"11550144065","pt":1719494851615,"mc":[{"id":"1.230178171","rc":[{"atb":[[1.17,0]],"id":52385890}],"con":true,"img":false}]}
{"op":"mcm","clk":"11550163486","pt":1719495081526,"mc":[{"id":"1.230178171","rc":[{"atb":[[1.17,0]],"id":52385891}],"con":true,"img":false}]}
{"op":"mcm","clk":"11550181410","pt":1719495311601,"mc":[{"id":"1.230178171","rc":[{"atb":[[1.17,0]],"id":52385892}],"con":true,"img":false}]}
{"op":"mcm","clk":"11550200777","pt":1719495541796,"mc":[{"id":"1.230178171","rc":[{"atb":[[1.17,0]],"id":52385893}],"con":true,"img":false}]}
{"op":"mcm","clk":"11550221669","pt":1719495781886,"mc":[{"id":"1.230178171","rc":[{"atb":[[1.17,0]],"id":52385897}],"con":true,"img":false}]}
{"op":"mcm","clk":"11550243449","pt":1719496021974,"mc":[{"id":"1.230178171","rc":[{"atb":[[1.17,0]],"id":52385896}],"con":true,"img":false}]}
{"op":"mcm","clk":"11550261825","pt":1719496262137,"mc":[{"id":"1.230178171","rc":[{"atb":[[1.17,0]],"id":52385898}],"con":true,"img":false}]}
{"op":"mcm","clk":"11550276190","pt":1719496492246,"mc":[{"id":"1.230178171","rc":[{"atb":[[1.17,0]],"id":52385900}],"con":true,"img":false}]}
{"op":"mcm","clk":"11550295199","pt":1719496742311,"mc":[{"id":"1.230178171","rc":[{"atb":[[1.17,0]],"id":52385899}],"con":true,"img":false}]}
{"op":"mcm","clk":"11550317625","pt":1719496992738,"mc":[{"id":"1.230178171","rc":[{"atb":[[1.03,92.27],[1.02,8.9]],"id":52385910},{"atl":[[960,1.49]],"id":52385910},{"atb":[[1.01,323.93],[1.02,72.8]],"id":52385912},{"atl":[[980,1.59]],"id":52385912},{"atb":[[1.01,323.93],[1.02,107.51]],"id":52385906},{"atl":[[980,0.85]],"id":52385906},{"atb":[[1.03,5.93]],"id":52385918},{"atb":[[1.02,8.9]],"id":52385920},{"atb":[[1.03,5.93],[1.04,105.82]],"id":52385889},{"atl":[[970,1.3]],"id":52385889},{"atb":[[1.02,8.9],[1.04,136.3]],"id":52385914},{"atl":[[990,0.85]],"id":52385914},{"atb":[[1.03,132.92]],"id":52385883},{"atl":[[970,0.85]],"id":52385883},{"atb":[[1.03,79.58]],"id":52385885},{"atl":[[970,1.32]],"id":52385885},{"atb":[[1.01,323.93],[1.04,121.06]],"id":52385896},{"atl":[[970,2.06]],"id":52385896},{"atb":[[1.01,323.93],[1.03,101.59]],"id":52385890},{"atl":[[990,0.85]],"id":52385890},{"atb":[[1.01,323.93],[1.04,130.37]],"id":52385892},{"atl":[[970,1.3]],"id":52385892},{"atb":[[1.02,8.9],[1.04,118.52]],"id":52385904},{"atl":[[990,1.98]],"id":52385904},{"atb":[[1.03,5.93],[1.04,83.81]],"id":52385898},{"atl":[[990,1.85]],"id":52385898},{"atb":[[1.03,5.93],[1.04,75.34]],"id":52385900},{"atl":[[960,2.11]],"id":52385900},{"atb":[[1.03,67.72],[1.02,8.9]],"id":52385911},{"atl":[[960,1.75]],"id":52385911},{"atb":[[1.02,8.9],[1.04,85.5]],"id":52385913},{"atl":[[980,1.79]],"id":52385913},{"atb":[[1.03,5.93],[1.02,132.91]],"id":52385907},{"atl":[[960,1.59]],"id":52385907},{"atb":[[1.01,323.93],[1.04,129.52]],"id":52385886},{"atl":[[960,0.85]],"id":52385886},{"atb":[[1.03,5.93]],"id":52385919},{"atb":[[1.02,8.9]],"id":52385921},{"atb":[[1.01,323.93],[1.02,140.53]],"id":52385882},{"atl":[[970,1.1]],"id":52385882},{"atb":[[1.03,5.93],[1.04,146.46]],"id":52385884},{"atl":[[970,1.25]],"id":52385884},{"atb":[[1.02,8.9]],"id":52385917},{"atb":[[1.03,94.81],[1.02,8.9]],"id":52385897},{"atl":[[980,0.93]],"id":52385897},{"atb":[[1.01,323.93],[1.03,148.15]],"id":52385891},{"atl":[[970,1.04]],"id":52385891},{"atb":[[1.03,5.93],[1.04,73.65]],"id":52385893},{"atl":[[990,2.07]],"id":52385893},{"atb":[[1.01,323.93],[1.03,93.97],[1.17,0]],"id":52385903},{"atl":[[990,1.87]],"id":52385903},{"atb":[[1.01,323.93],[1.02,152.38]],"id":52385905},{"atl":[[990,0.85]],"id":52385905},{"atb":[[1.03,167.62],[1.02,8.9]],"id":52385899},{"atl":[[970,0.85]],"id":52385899}],"con":true,"img":false}]}
{"op":"mcm","clk":"11550339885","pt":1719497232536,"mc":[{"id":"1.230178171","rc":[{"atb":[[1.17,0]],"id":52385904}],"con":true,"img":false}]}
{"op":"mcm","clk":"11550360158","pt":1719497482712,"mc":[{"id":"1.230178171","rc":[{"atb":[[1.17,0]],"id":52385905}],"con":true,"img":false}]}
{"op":"mcm","clk":"11550379305","pt":1719497722666,"mc":[{"id":"1.230178171","rc":[{"atb":[[1.17,0]],"id":52385906}],"con":true,"img":false}]}
{"op":"mcm","clk":"11550400061","pt":1719497962881,"mc":[{"id":"1.230178171","rc":[{"atb":[[1.17,0]],"id":52385907}],"con":true,"img":false}]}
{"op":"mcm","clk":"11550419474","pt":1719498213038,"mc":[{"id":"1.230178171","rc":[{"atb":[[1.17,0]],"id":52385910}],"con":true,"img":false}]}
{"op":"mcm","clk":"11550438637","pt":1719498463100,"mc":[{"id":"1.230178171","rc":[{"atb":[[1.17,0]],"id":52385912}],"con":true,"img":false}]}
{"op":"mcm","clk":"11550456500","pt":1719498703407,"mc":[{"id":"1.230178171","rc":[{"atb":[[1.17,0]],"id":52385911}],"con":true,"img":false}]}
{"op":"mcm","clk":"11550467832","pt":1719498843157,"mc":[{"id":"1.230178171","rc":[{"atb":[[16,15.15]],"id":52385900}],"con":true,"img":false}]}
{"op":"mcm","clk":"11550467871","pt":1719498843764,"mc":[{"id":"1.230178171","rc":[{"atb":[[16,0]],"id":52385900}],"con":true,"img":false}]}
{"op":"mcm","clk":"11550476152","pt":1719498943333,"mc":[{"id":"1.230178171","rc":[{"atb":[[1.17,0]],"id":52385913}],"con":true,"img":false}]}
{"op":"mcm","clk":"11550498280","pt":1719499143400,"mc":[{"id":"1.230178171","rc":[{"atb":[[1.17,0]],"id":52385914}],"con":true,"img":false}]}
{"op":"mcm","clk":"11550512783","pt":1719499323862,"mc":[{"id":"1.230178171","rc":[{"atl":[[32,9.29]],"id":52385912}],"con":true,"img":false}]}
{"op":"mcm","clk":"11550512810","pt":1719499324273,"mc":[{"id":"1.230178171","rc":[{"atl":[[32,0]],"id":52385912}],"con":true,"img":false}]}
{"op":"mcm","clk":"11550516378","pt":1719499373526,"mc":[{"id":"1.230178171","rc":[{"atb":[[1.17,0]],"id":52385917}],"con":true,"img":false}]}
{"op":"mcm","clk":"11550521443","pt":1719499443512,"mc":[{"id":"1.230178171","rc":[{"atb":[[13,8]],"id":52385910},{"atb":[[10,10]],"id":52385912},{"atb":[[12,8]],"id":52385906},{"atb":[[17,6]],"id":52385918},{"atb":[[16,6]],"id":52385920},{"atb":[[12,8]],"id":52385889},{"atb":[[11,9]],"id":52385914},{"atb":[[12,8]],"id":52385883},{"atb":[[16,6]],"id":52385885},{"atb":[[9,11]],"id":52385896},{"atb":[[13,8]],"id":52385890},{"atb":[[15,6]],"id":52385892},{"atb":[[14,7]],"id":52385904},{"atb":[[7,12]],"id":52385898},{"atb":[[9,11]],"id":52385900},{"atb":[[15,6]],"id":52385911},{"atb":[[12,8]],"id":52385913},{"atb":[[15,6]],"id":52385907},{"atb":[[17,6]],"id":52385886},{"atb":[[14,7]],"id":52385919},{"atb":[[13,8]],"id":52385921},{"atb":[[12,8]],"id":52385882},{"atb":[[16,6]],"id":52385884},{"atb":[[16,6]],"id":52385917},{"atb":[[8,12]],"id":52385897},{"atb":[[15,6]],"id":52385891},{"atb":[[18,5]],"id":52385893},{"atb":[[13,8]],"id":52385903},{"atb":[[10,10]],"id":52385905},{"atb":[[9,11]],"id":52385899}],"con":true,"img":false}]}
{"op":"mcm","clk":"11550529625","pt":1719499558854,"mc":[{"id":"1.230178171","rc":[{"atb":[[38,6.36]],"id":52385918},{"atb":[[36,5.22]],"id":52385920},{"atb":[[32,6.02]],"id":52385914},{"atb":[[28,7.1]],"id":52385907},{"atb":[[30,8.1]],"id":52385921},{"atb":[[38,6.42]],"id":52385893}],"con":true,"img":false}]}
{"op":"mcm","clk":"11550529697","pt":1719499560049,"mc":[{"id":"1.230178171","rc":[{"atl":[[50,4.08]],"id":52385910},{"atl":[[70,3.23]],"id":52385892},{"atl":[[44,4.8]],"id":52385904},{"atb":[[14.5,18.78]],"id":52385900},{"atl":[[50,4.18]],"id":52385911},{"atl":[[38,6.16]],"id":52385913},{"atb":[[23,10.79]],"id":52385919},{"atl":[[60,3.48]],"id":52385891},{"atl":[[55,5.01]],"id":52385903}],"con":true,"img":false}]}
{"op":"mcm","clk":"11550529718","pt":1719499560354,"mc":[{"id":"1.230178171","rc":[{"atb":[[38,0]],"id":52385893}],"con":true,"img":false}]}
{"op":"mcm","clk":"11550529726","pt":1719499560461,"mc":[{"id":"1.230178171","rc":[{"atb":[[36,0]],"id":52385920},{"atb":[[32,0]],"id":52385914},{"atb":[[28,0]],"id":52385907}],"con":true,"img":false}]}
{"op":"mcm","clk":"11550529733","pt":1719499560561,"mc":[{"id":"1.230178171","rc":[{"atb":[[13,0]],"id":52385910},{"atb":[[12,0]],"id":52385906},{"atb":[[17,0]],"id":52385918},{"atb":[[11,0]],"id":52385914},{"atb":[[12,0]],"id":52385883},{"atb":[[9,0]],"id":52385896},{"atb":[[13,0]],"id":52385890},{"atb":[[14,0]],"id":52385904},{"atb":[[9,0]],"id":52385900},{"atb":[[15,0]],"id":52385911},{"atb":[[12,0]],"id":52385913},{"atb":[[18,0]],"id":52385893},{"atb":[[13,0]],"id":52385903},{"atb":[[10,0]],"id":52385905},{"atb":[[9,0]],"id":52385899}],"con":true,"img":false}]}
{"op":"mcm","clk":"11550529741","pt":1719499560670,"mc":[{"id":"1.230178171","rc":[{"atb":[[12,8]],"id":52385910},{"atb":[[11,8]],"id":52385906},{"atb":[[20,6]],"id":52385918},{"atb":[[12,9]],"id":52385914},{"atb":[[11,8]],"id":52385883},{"atb":[[8,11]],"id":52385896},{"atb":[[12,8]],"id":52385890},{"atb":[[13,7]],"id":52385904},{"atb":[[10,11]],"id":52385900},{"atb":[[14,6]],"id":52385911},{"atb":[[11,8]],"id":52385913},{"atb":[[20,5]],"id":52385893},{"atb":[[12,8]],"id":52385903},{"atb":[[9,10]],"id":52385905},{"atb":[[8,11]],"id":52385899}],"con":true,"img":false}]}
{"op":"mcm","clk":"11550529755","pt":1719499560871,"mc":[{"id":"1.230178171","rc":[{"atb":[[16,0]],"id":52385920},{"atb":[[14,0]],"id":52385919},{"atb":[[13,0]],"id":52385921}],"con":true,"img":false}]}
{"op":"mcm","clk":"11550529761","pt":1719499560987,"mc":[{"id":"1.230178171","rc":[{"atb":[[20,6]],"id":52385920},{"atb":[[18,7]],"id":52385919},{"atb":[[16,8]],"id":52385921}],"con":true,"img":false}]}
{"op":"mcm","clk":"11550529789","pt":1719499561351,"mc":[{"id":"1.230178171","rc":[{"atb":[[38,6.64]],"id":52385886},{"atb":[[38,6.24]],"id":52385917}],"con":true,"img":false}]}
{"op":"mcm","clk":"11550529821","pt":1719499561766,"mc":[{"id":"1.230178171","rc":[{"atl":[[50,0]],"id":52385910},{"atb":[[38,0]],"id":52385918},{"atl":[[70,0]],"id":52385892},{"atl":[[44,0]],"id":52385904},{"atb":[[14.5,0]],"id":52385900},{"atl":[[50,0]],"id":52385911},{"atl":[[38,0]],"id":52385913},{"atb":[[38,0]],"id":52385886},{"atb":[[23,0]],"id":52385919},{"atb":[[30,0]],"id":52385921},{"atb":[[38,0]],"id":52385917},{"atl":[[60,0]],"id":52385891},{"atl":[[55,0]],"id":52385903}],"con":true,"img":false}]}
{"op":"mcm","clk":"11550530537","pt":1719499570573,"mc":[{"id":"1.230178171","rc":[{"atb":[[20,0]],"id":52385918},{"atb":[[20,0]],"id":52385920},{"atb":[[12,0]],"id":52385914},{"atb":[[10,0]],"id":52385900},{"atb":[[18,0]],"id":52385919},{"atb":[[16,0]],"id":52385921},{"atb":[[20,0]],"id":52385893}],"con":true,"img":false}]}
{"op":"mcm","clk":"11550530546","pt":1719499570678,"mc":[{"id":"1.230178171","rc":[{"atb":[[17,6]],"id":52385918},{"atb":[[16,6]],"id":52385920},{"atb":[[11,9]],"id":52385914},{"atb":[[9,11]],"id":52385900},{"atb":[[14,7]],"id":52385919},{"atb":[[13,8]],"id":52385921},{"atb":[[18,5]],"id":52385893}],"con":true,"img":false}]}
{"op":"mcm","clk":"11550533147","pt":1719499603633,"mc":[{"id":"1.230178171","rc":[{"atb":[[1.17,0]],"id":52385918}],"con":true,"img":false}]}
{"op":"mcm","clk":"11550533764","pt":1719499611431,"mc":[{"id":"1.230178171","rc":[{"atb":[[15,0]],"id":52385907}],"con":true,"img":false}]}
{"op":"mcm","clk":"11550533774","pt":1719499611543,"mc":[{"id":"1.230178171","rc":[{"atb":[[14,6]],"id":52385907}],"con":true,"img":false}]}
{"op":"mcm","clk":"11550536011","pt":1719499641474,"mc":[{"id":"1.230178171","rc":[{"atb":[[11,0]],"id":52385914}],"con":true,"img":false}]}
{"op":"mcm","clk":"11550536016","pt":1719499641578,"mc":[{"id":"1.230178171","rc":[{"atb":[[10,9]],"id":52385914}],"con":true,"img":false}]}
{"op":"mcm","clk":"11550538900","pt":1719499680330,"mc":[{"id":"1.230178171","rc":[{"atb":[[5.2,23.81]],"id":52385912},{"atl":[[460,2]],"id":52385912},{"atb":[[4.3,30.3]],"id":52385906},{"atl":[[330,2]],"id":52385906},{"atb":[[17.5,6]],"id":52385918},{"atl":[[1000,2]],"id":52385918},{"atb":[[16.5,6.45]],"id":52385920},{"atl":[[990,2]],"id":52385920},{"atb":[[6.4,18.52]],"id":52385889},{"atl":[[510,2]],"id":52385889},{"atb":[[8.8,12.82]],"id":52385914},{"atl":[[600,2]],"id":52385914},{"atb":[[9,12.5]],"id":52385883},{"atl":[[620,2]],"id":52385883},{"atb":[[6,20]],"id":52385885},{"atl":[[500,2]],"id":52385885},{"atb":[[5.6,21.74]],"id":52385896},{"atl":[[490,2]],"id":52385896},{"atb":[[7.8,14.71]],"id":52385890},{"atl":[[550,2]],"id":52385890},{"atb":[[5.1,24.39]],"id":52385892},{"atl":[[450,2]],"id":52385892},{"atb":[[6.8,17.24]],"id":52385904},{"atl":[[530,2]],"id":52385904},{"atb":[[5.9,20.41]],"id":52385898},{"atl":[[500,2]],"id":52385898},{"atb":[[9.2,12.2]],"id":52385900},{"atl":[[790,2]],"id":52385900},{"atb":[[5.7,21.28]],"id":52385911},{"atl":[[490,2]],"id":52385911},{"atb":[[4.8,26.32]],"id":52385913},{"atl":[[420,2]],"id":52385913},{"atb":[[10,11.11]],"id":52385907},{"atl":[[720,2]],"id":52385907},{"atb":[[17.5,6.06]],"id":52385886},{"atl":[[960,2.85]],"id":52385886},{"atb":[[14.5,7.41]],"id":52385919},{"atl":[[1000,2]],"id":52385919},{"atb":[[11,10]],"id":52385921},{"atl":[[770,2]],"id":52385921},{"atb":[[9.2,12.2]],"id":52385882},{"atl":[[630,2]],"id":52385882},{"atb":[[8.6,13.16]],"id":52385884},{"atl":[[590,2]],"id":52385884},{"atb":[[16.5,6.45]],"id":52385917},{"atl":[[1000,2]],"id":52385917},{"atb":[[7.2,16.13]],"id":52385897},{"atl":[[530,2]],"id":52385897},{"atb":[[7.2,16.13]],"id":52385891},{"atl":[[540,2]],"id":52385891},{"atb":[[17,6.25]],"id":52385893},{"atl":[[880,2]],"id":52385893},{"atb":[[5.4,22.73]],"id":52385903},{"atl":[[480,2]],"id":52385903},{"atb":[[6,20]],"id":52385905},{"atl":[[510,2]],"id":52385905},{"atb":[[4.6,27.78]],"id":52385899},{"atl":[[390,2]],"id":52385899}],"con":true,"img":false}]}
{"op":"mcm","clk":"11550538909","pt":1719499680429,"mc":[{"id":"1.230178171","rc":[{"atb":[[4.9,25.64]],"id":52385910},{"atl":[[430,2]],"id":52385910}],"con":true,"img":false}]}
{"op":"mcm","clk":"11550539378","pt":1719499686527,"mc":[{"id":"1.230178171","rc":[{"atb":[[9,0]],"id":52385900}],"con":true,"img":false}]}
{"op":"mcm","clk":"11550539382","pt":1719499686628,"mc":[{"id":"1.230178171","rc":[{"atb":[[9.2,0],[10,11],[4.4,29.41]],"id":52385900}],"con":true,"img":false}]}
{"op":"mcm","clk":"11550539394","pt":1719499686843,"mc":[{"id":"1.230178171","rc":[{"atb":[[10.5,10.53]],"id":52385900}],"con":true,"img":false}]}
{"op":"mcm","clk":"11550539400","pt":1719499686937,"mc":[{"id":"1.230178171","rc":[{"atb":[[4.4,0]],"id":52385900}],"con":true,"img":false}]}
{"op":"mcm","clk":"11550540670","pt":1719499704775,"mc":[{"id":"1.230178171","rc":[{"atl":[[430,0],[420,2]],"id":52385910},{"atl":[[460,0],[450,2]],"id":52385912},{"atl":[[330,0]],"id":52385906},{"atl":[[900,2],[990,0]],"id":52385920},{"atb":[[8.8,0],[9.4,11.9]],"id":52385914},{"atl":[[560,2],[600,0]],"id":52385914},{"atb":[[9,0],[9.4,11.9]],"id":52385883},{"atl":[[600,2],[620,0]],"id":52385883},{"atl":[[490,2],[500,0]],"id":52385885},{"atb":[[5.6,0],[5.9,20.41]],"id":52385896},{"atl":[[470,2],[490,0]],"id":52385896},{"atb":[[7.8,0],[8.4,13.51]],"id":52385890},{"atl":[[540,2],[550,0]],"id":52385890},{"atl":[[450,0]],"id":52385892},{"atl":[[520,2]],"id":52385904},{"atb":[[6.2,19.23],[5.9,0]],"id":52385898},{"atl":[[490,2],[500,0]],"id":52385898},{"atl":[[730,2],[790,0]],"id":52385900},{"atl":[[490,0],[480,2]],"id":52385911},{"atl":[[410,2],[420,0]],"id":52385913},{"atb":[[10,0],[11,10]],"id":52385907},{"atl":[[660,2],[720,0]],"id":52385907},{"atl":[[900,2]],"id":52385886},{"atl":[[970,2],[1000,0]],"id":52385919},{"atl":[[680,2],[770,0]],"id":52385921},{"atb":[[9.6,11.63],[9.2,0]],"id":52385882},{"atl":[[630,0],[610,2]],"id":52385882},{"atl":[[590,0],[580,2]],"id":52385884},{"atl":[[920,2],[1000,0]],"id":52385917},{"atb":[[7.2,0],[7.6,15.15]],"id":52385897},{"atl":[[530,0],[520,2]],"id":52385897},{"atl":[[540,0],[530,2]],"id":52385891},{"atb":[[17,0]],"id":52385893},{"atl":[[880,0]],"id":52385893},{"atl":[[460,2]],"id":52385903},{"atl":[[500,2]],"id":52385905},{"atl":[[380,2],[390,0]],"id":52385899}],"con":true,"img":false}]}
{"op":"mcm","clk":"11550540675","pt":1719499704829,"mc":[{"id":"1.230178171","rc":[{"atb":[[5.5,22.22],[4.9,0]],"id":52385910},{"atb":[[5.8,20.83],[5.2,0]],"id":52385912},{"atl":[[320,2]],"id":52385906},{"atb":[[5.6,21.74],[5.1,0]],"id":52385892},{"atl":[[440,2]],"id":52385892},{"atb":[[6.8,0],[7.8,14.71]],"id":52385904},{"atl":[[530,0]],"id":52385904},{"atb":[[6.4,18.52],[5.7,0]],"id":52385911},{"atb":[[4.8,0],[5.3,23.26]],"id":52385913},{"atl":[[960,0.85]],"id":52385886},{"atb":[[8.6,0],[9.8,11.36]],"id":52385884},{"atb":[[7.2,0],[8.2,13.89]],"id":52385891},{"atb":[[16.5,6.45]],"id":52385893},{"atl":[[810,2]],"id":52385893},{"atb":[[6,20],[5.4,0]],"id":52385903},{"atl":[[480,0]],"id":52385903},{"atb":[[6,0],[6.8,17.24]],"id":52385905},{"atl":[[510,0]],"id":52385905},{"atb":[[5.1,24.39],[4.6,0]],"id":52385899}],"con":true,"img":false}]}
{"op":"mcm","clk":"11550540680","pt":1719499704932,"mc":[{"id":"1.230178171","rc":[{"atl":[[940,2],[970,0]],"id":52385919},{"atb":[[9.6,0],[10.5,10.53]],"id":52385882}],"con":true,"img":false}]}
{"op":"mcm","clk":"11550540686","pt":1719499705033,"mc":[{"id":"1.230178171","rc":[{"atl":[[810,0],[800,2]],"id":52385893}],"con":true,"img":false}]}
{"op":"mcm","clk":"11550540847","pt":1719499707557,"mc":[{"id":"1.230178171","rc":[{"atb":[[17,0]],"id":52385918},{"atb":[[16,0]],"id":52385920},{"atb":[[15,0]],"id":52385892},{"atb":[[10,0]],"id":52385900},{"atb":[[17,0]],"id":52385886},{"atb":[[14,0]],"id":52385919},{"atb":[[16,0]],"id":52385917},{"atb":[[15,0]],"id":52385891}],"con":true,"img":false}]}
{"op":"mcm","clk":"11550540858","pt":1719499707661,"mc":[{"id":"1.230178171","rc":[{"atb":[[20,6]],"id":52385918},{"atb":[[18,6]],"id":52385920},{"atb":[[14,6]],"id":52385892},{"atb":[[11,11]],"id":52385900},{"atb":[[20,6]],"id":52385886},{"atb":[[18,7]],"id":52385919},{"atb":[[20,6]],"id":52385917},{"atb":[[14,6]],"id":52385891}],"con":true,"img":false}]}
{"op":"mcm","clk":"11550540863","pt":1719499707764,"mc":[{"id":"1.230178171","rc":[{"atb":[[17.5,0],[9,12.5]],"id":52385918},{"atb":[[16.5,0],[6.6,17.86]],"id":52385920},{"atb":[[10.5,0],[4.4,29.41]],"id":52385900},{"atb":[[17.5,0],[7,16.67]],"id":52385886},{"atb":[[8.2,13.89],[14.5,0]],"id":52385919},{"atb":[[16.5,0],[7,16.67]],"id":52385917}],"con":true,"img":false}]}
{"op":"mcm","clk":"11550540870","pt":1719499707866,"mc":[{"id":"1.230178171","rc":[{"atb":[[18.5,5.71]],"id":52385920},{"atb":[[21,5]],"id":52385886}],"con":true,"img":false}]}
{"op":"mcm","clk":"11550540876","pt":1719499707969,"mc":[{"id":"1.230178171","rc":[{"atb":[[9,0],[21,5]],"id":52385918},{"atb":[[6.6,0]],"id":52385920},{"atb":[[11.5,9.52],[4.4,0]],"id":52385900},{"atb":[[7,0]],"id":52385886},{"atb":[[18.5,5.71],[8.2,0]],"id":52385919},{"atb":[[21,5],[7,0]],"id":52385917}],"con":true,"img":false}]}
{"op":"mcm","clk":"11550541318","pt":1719499714660,"mc":[{"id":"1.230178171","rc":[{"atl":[[880,2],[900,0]],"id":52385920},{"atb":[[10,11.11],[9.4,0]],"id":52385883},{"atb":[[6.4,18.52],[5.9,0]],"id":52385896},{"atb":[[9,12.5],[8.4,0]],"id":52385890},{"atb":[[6.2,0],[6.6,17.86]],"id":52385898},{"atl":[[730,0],[720,2]],"id":52385900},{"atl":[[660,0],[650,2]],"id":52385907},{"atl":[[890,2],[900,0]],"id":52385886},{"atl":[[660,2],[680,0]],"id":52385921},{"atl":[[890,2],[920,0]],"id":52385917},{"atb":[[8,26.29],[7.6,0]],"id":52385897}],"con":true,"img":false}]}
{"op":"mcm","clk":"11550541538","pt":1719499717565,"mc":[{"id":"1.230178171","rc":[{"atb":[[11,0]],"id":52385900}],"con":true,"img":false}]}
{"op":"mcm","clk":"11550541546","pt":1719499717670,"mc":[{"id":"1.230178171","rc":[{"atb":[[11.5,0],[12,11],[4.4,29.41]],"id":52385900}],"con":true,"img":false}]}
{"op":"mcm","clk":"11550541559","pt":1719499717876,"mc":[{"id":"1.230178171","rc":[{"atb":[[12,20.09],[4.4,0]],"id":52385900}],"con":true,"img":false}]}
{"op":"mcm","clk":"11550542354","pt":1719499728494,"mc":[{"id":"1.230178171","rc":[{"atb":[[13,0]],"id":52385904},{"atb":[[14,0]],"id":52385911},{"atb":[[11,0]],"id":52385913},{"atb":[[18,0]],"id":52385919}],"con":true,"img":false}]}
{"op":"mcm","clk":"11550542361","pt":1719499728599,"mc":[{"id":"1.230178171","rc":[{"atb":[[3.45,40.82],[12,7],[7.8,0]],"id":52385904},{"atb":[[6.4,0],[3.1,47.62],[13,6]],"id":52385911},{"atb":[[10,8],[2.86,53.76],[5.3,0]],"id":52385913},{"atb":[[18.5,0],[20,7],[8.2,13.89]],"id":52385919}],"con":true,"img":false}]}
{"op":"mcm","clk":"11550542372","pt":1719499728702,"mc":[{"id":"1.230178171","rc":[{"atb":[[6.4,18.52],[3.1,0]],"id":52385911}],"con":true,"img":false}]}
{"op":"mcm","clk":"11550543073","pt":1719499738193,"mc":[{"id":"1.230178171","rc":[{"atb":[[3.45,0],[7.8,14.71]],"id":52385904},{"atb":[[2.86,0],[5.3,23.26]],"id":52385913},{"atb":[[21,5],[8.2,0]],"id":52385919}],"con":true,"img":false}]}
{"op":"mcm","clk":"11550548713","pt":1719499816083,"mc":[{"id":"1.230178171","rc":[{"atb":[[4.3,0],[4.9,25.64]],"id":52385906},{"atb":[[6.4,0],[7.6,15.15]],"id":52385889},{"atb":[[10,20.11],[9.4,0]],"id":52385914},{"atb":[[10,0],[11,18]],"id":52385883},{"atb":[[7.2,16.13],[6,0]],"id":52385885},{"atb":[[6.8,17.24]],"id":52385896},{"atb":[[9.6,11.63],[9,0]],"id":52385890},{"atb":[[7,28.67],[6.6,0]],"id":52385898},{"atb":[[11,0],[12,9.09]],"id":52385907},{"atb":[[11,0],[12,9.09]],"id":52385921},{"atb":[[10.5,0],[11,10]],"id":52385882},{"atb":[[8.2,0],[8.8,12.82]],"id":52385891},{"atb":[[16.5,0],[18,10.88]],"id":52385893},{"atb":[[7.4,15.62],[6.8,0]],"id":52385905}],"con":true,"img":false}]}
{"op":"mcm","clk":"11550548719","pt":1719499816184,"mc":[{"id":"1.230178171","rc":[{"atb":[[6.4,0]],"id":52385896}],"con":true,"img":false}]}
{"op":"mcm","clk":"11550549269","pt":1719499824800,"mc":[{"id":"1.230178171","rc":[{"atl":[[420,0],[430,2]],"id":52385910},{"atl":[[450,0],[470,2]],"id":52385912},{"atl":[[320,0],[340,2]],"id":52385906},{"atl":[[880,0],[900,2]],"id":52385920},{"atl":[[520,2],[510,0]],"id":52385889},{"atb":[[10,9],[8.8,12.82]],"id":52385914},{"atl":[[560,0],[580,2]],"id":52385914},{"atb":[[9.6,11.63],[11,8]],"id":52385883},{"atl":[[600,0],[620,2]],"id":52385883},{"atl":[[490,0],[510,2]],"id":52385885},{"atb":[[6.8,0],[6,20]],"id":52385896},{"atl":[[470,0],[490,2]],"id":52385896},{"atb":[[9.6,0],[8.4,13.51]],"id":52385890},{"atl":[[540,0],[560,2]],"id":52385890},{"atl":[[440,0],[450,2]],"id":52385892},{"atl":[[520,0],[530,2]],"id":52385904},{"atb":[[6.2,19.23],[7,11.99]],"id":52385898},{"atl":[[490,0],[500,2]],"id":52385898},{"atb":[[11,10],[12,11]],"id":52385900},{"atl":[[720,0],[760,2]],"id":52385900},{"atl":[[480,0],[500,2]],"id":52385911},{"atl":[[410,0],[420,2]],"id":52385913},{"atb":[[10.5,10.53],[12,0]],"id":52385907},{"atl":[[650,0],[680,2]],"id":52385907},{"atl":[[890,0],[940,2]],"id":52385886},{"atb":[[10.5,10.53],[12,0]],"id":52385921},{"atb":[[11,0],[9.8,11.36]],"id":52385882},{"atl":[[610,0],[630,2]],"id":52385882},{"atl":[[580,0],[600,2]],"id":52385884},{"atl":[[890,0],[920,2]],"id":52385917},{"atb":[[8,12],[7.6,15.15]],"id":52385897},{"atl":[[520,0],[540,2]],"id":52385897},{"atl":[[530,0],[540,2]],"id":52385891},{"atb":[[15.5,6.9]],"id":52385893},{"atl":[[840,2]],"id":52385893},{"atl":[[460,0],[480,2]],"id":52385903},{"atb":[[6.4,18.52],[7.4,0]],"id":52385905},{"atl":[[500,0],[510,2]],"id":52385905},{"atl":[[380,0],[400,2]],"id":52385899}],"con":true,"img":false}]}
{"op":"mcm","clk":"11550549275","pt":1719499824899,"mc":[{"id":"1.230178171","rc":[{"atb":[[18,5]],"id":52385893},{"atl":[[800,0]],"id":52385893}],"con":true,"img":false}]}
{"op":"mcm","clk":"11550549826","pt":1719499833715,"mc":[{"id":"1.230178171","rc":[{"atb":[[1.17,0]],"id":52385920}],"con":true,"img":false}]}
{"op":"mcm","clk":"11550550552","pt":1719499845536,"mc":[{"id":"1.230178171","rc":[{"atb":[[18,0]],"id":52385920},{"atb":[[12,0]],"id":52385889},{"atb":[[14,0]],"id":52385892}],"con":true,"img":false}]}
{"op":"mcm","clk":"11550550563","pt":1719499845638,"mc":[{"id":"1.230178171","rc":[{"atb":[[6.4,18.52],[20,6]],"id":52385920},{"atb":[[3.2,45.45],[11,8],[7.6,0]],"id":52385889},{"atb":[[5.6,0],[2.86,53.76],[13,6]],"id":52385892}],"con":true,"img":false}]}
{"op":"mcm","clk":"11550550569","pt":1719499845742,"mc":[{"id":"1.230178171","rc":[{"atb":[[18.5,0],[6.4,0],[21,5]],"id":52385920},{"atb":[[3.2,0]],"id":52385889},{"atb":[[2.86,0],[5.3,23.26]],"id":52385892}],"con":true,"img":false}]}
{"op":"mcm","clk":"11550550578","pt":1719499845846,"mc":[{"id":"1.230178171","rc":[{"atb":[[5.5,0],[4.9,25.64]],"id":52385910},{"atb":[[5.8,0],[5.2,23.81]],"id":52385912},{"atb":[[4.3,30.3],[4.9,0]],"id":52385906},{"atb":[[20,11.26],[21,0]],"id":52385920},{"atb":[[6.8,17.24]],"id":52385889},{"atb":[[9.6,0],[9.2,12.2]],"id":52385883},{"atb":[[7.2,0],[6,20]],"id":52385885},{"atb":[[6.2,0],[6,20]],"id":52385898},{"atb":[[10.5,10.53],[11,0]],"id":52385900},{"atb":[[10,11.11],[10.5,0]],"id":52385921},{"atb":[[9.2,12.2],[9.8,0]],"id":52385882},{"atb":[[7.2,16.13],[7.6,0]],"id":52385897},{"atb":[[7.4,15.62],[8.8,0]],"id":52385891}],"con":true,"img":false}]}
{"op":"mcm","clk":"11550550583","pt":1719499845947,"mc":[{"id":"1.230178171","rc":[{"atb":[[6,20]],"id":52385920}],"con":true,"img":false}]}
{"op":"mcm","clk":"11550550589","pt":1719499846000,"mc":[{"id":"1.230178171","rc":[{"atb":[[20,6]],"id":52385920}],"con":true,"img":false}]}
{"op":"mcm","clk":"11550550594","pt":1719499846104,"mc":[{"id":"1.230178171","rc":[{"atb":[[6,0]],"id":52385920}],"con":true,"img":false}]}
{"op":"mcm","clk":"11550550598","pt":1719499846205,"mc":[{"id":"1.230178171","rc":[{"atb":[[20,11.26]],"id":52385920}],"con":true,"img":false}]}
{"op":"mcm","clk":"11550551536","pt":1719499860612,"mc":[{"id":"1.230178171","rc":[{"atl":[[27,23.08]],"id":52385906},{"atb":[[16,30]],"id":52385885},{"atl":[[65,9.38]],"id":52385885}],"con":true,"img":false}]}
{"op":"mcm","clk":"11550551546","pt":1719499860768,"mc":[{"id":"1.230178171","rc":[{"atb":[[7.2,2.5],[6.4,5],[12,40]],"id":52385910},{"atl":[[34,18.18],[42,2.5],[50,5]],"id":52385910},{"atb":[[8,5],[8.8,2.5],[14.5,40]],"id":52385912},{"atl":[[38,5],[460,1.31],[30,2.5]],"id":52385912},{"atb":[[6.4,2.5],[5.8,5]],"id":52385906},{"atl":[[34,2.5],[42,5]],"id":52385906},{"atb":[[44,13.95],[26,5],[30,2.5]],"id":52385918},{"atl":[[270,2.23],[240,2.5]],"id":52385918},{"atb":[[32,21.85],[27,5]],"id":52385920},{"atl":[[170,2.5],[190,3.17]],"id":52385920},{"atb":[[10.5,5],[11.5,32],[12.5,2.5]],"id":52385889},{"atl":[[70,8.7],[80,5],[60,2.5]],"id":52385889},{"atb":[[18,5],[20,2.5],[10.5,36]],"id":52385914},{"atl":[[75,8.11],[80,5],[60,2.5]],"id":52385914},{"atb":[[11.5,5],[13.5,2.5],[28,22.22]],"id":52385883},{"atl":[[75,2.5],[80,7.59],[95,5]],"id":52385883},{"atb":[[10.5,5],[6,0],[3,50],[12.5,2.5]],"id":52385885},{"atl":[[70,5],[50,2.5]],"id":52385885},{"atb":[[8.6,2.5],[8.2,44],[7.8,5]],"id":52385896},{"atl":[[36,2.5],[44,5],[55,11.11]],"id":52385896},{"atb":[[9.6,5],[19.5,32],[11,2.5]],"id":52385890},{"atl":[[550,1.09],[75,5],[55,2.5]],"id":52385890},{"atb":[[8.6,5],[13,30],[9.4,2.5]],"id":52385892},{"atl":[[36,17.14],[46,2.5],[60,5]],"id":52385892},{"atb":[[11.5,2.5],[9.8,5],[14.5,28]],"id":52385904},{"atl":[[46,2.5],[210,2.87],[60,5]],"id":52385904},{"atb":[[8.6,2.5],[13.5,48],[7.8,5]],"id":52385898},{"atl":[[38,2.5],[46,5],[490,1.23]],"id":52385898},{"atb":[[11.5,5],[13.5,2.5],[29,21.43]],"id":52385900},{"atl":[[150,5],[110,2.5],[120,5.04]],"id":52385900},{"atb":[[16.5,24],[8.6,5],[9.4,2.5]],"id":52385911},{"atl":[[40,2.5],[48,5],[30,20.69]],"id":52385911},{"atb":[[8.6,2.5],[12,32],[7.8,5]],"id":52385913},{"atl":[[34,2.5],[42,5],[27,23.08]],"id":52385913},{"atb":[[19.5,5],[23,2.5],[28,22.22]],"id":52385907},{"atl":[[85,2.5],[95,6.38],[110,5]],"id":52385907},{"atb":[[23,5],[55,11.11],[27,2.5]],"id":52385886},{"atl":[[170,2.5],[200,3.02]],"id":52385886},{"atb":[[19,5],[22,2.5]],"id":52385919},{"atl":[[220,2.5]],"id":52385919},{"atb":[[36,17.14],[26,5],[30,2.5]],"id":52385921},{"atl":[[140,5],[160,3.77],[100,2.5]],"id":52385921},{"atb":[[16,2.5],[14,5],[30,20.69]],"id":52385882},{"atl":[[75,2.5],[85,7.14],[95,5]],"id":52385882},{"atb":[[23,24],[12.5,5],[14.5,2.5]],"id":52385884},{"atl":[[65,2.5],[75,8.11],[85,5]],"id":52385884},{"atb":[[34,5],[42,2.5],[55,11.11]],"id":52385917},{"atl":[[180,2.5],[240,2.51]],"id":52385917},{"atb":[[19,33.33],[7.6,5],[8.4,2.5]],"id":52385897},{"atl":[[530,1.13],[70,5],[50,2.5]],"id":52385897},{"atb":[[16.5,2.5],[14.5,5],[15.5,24]],"id":52385891},{"atl":[[70,5],[50,2.5],[220,2.74]],"id":52385891},{"atb":[[40,15.38]],"id":52385893},{"atl":[[150,4.03]],"id":52385893},{"atb":[[8.6,2.5],[12.5,32],[7.8,5]],"id":52385903},{"atl":[[36,17.14],[44,2.5],[55,5]],"id":52385903},{"atb":[[10,2.5],[9.2,5],[13.5,40]],"id":52385905},{"atl":[[38,2.5],[46,5],[500,1.2]],"id":52385905},{"atb":[[6.2,5],[8.2,44],[7,2.5]],"id":52385899},{"atl":[[23,27.27],[24,2.5],[28,5]],"id":52385899}],"con":true,"img":false}]}
{"op":"mcm","clk":"11550551552","pt":1719499860821,"mc":[{"id":"1.230178171","rc":[{"atl":[[85,2]],"id":52385912},{"atl":[[38,2.7]],"id":52385906},{"atl":[[180,2]],"id":52385914},{"atl":[[220,2]],"id":52385883},{"atl":[[110,2]],"id":52385885},{"atl":[[95,2]],"id":52385896},{"atl":[[530,0]],"id":52385904},{"atl":[[500,0]],"id":52385898},{"atl":[[760,0]],"id":52385900},{"atl":[[100,2]],"id":52385911},{"atb":[[40,14]],"id":52385919},{"atl":[[230,2.62]],"id":52385919},{"atl":[[200,2]],"id":52385884},{"atl":[[540,2]],"id":52385917},{"atl":[[540,0]],"id":52385897},{"atb":[[25,5],[29,2.5]],"id":52385893},{"atl":[[140,2.5],[180,5],[440,2]],"id":52385893},{"atl":[[110,2]],"id":52385905},{"atl":[[400,0]],"id":52385899}],"con":true,"img":false}]}
{"op":"mcm","clk":"11550551559","pt":1719499860924,"mc":[{"id":"1.230178171","rc":[{"atl":[[65,2],[430,0]],"id":52385910},{"atl":[[470,0]],"id":52385912},{"atl":[[340,0]],"id":52385906},{"atb":[[36,2.86],[21,0]],"id":52385918},{"atl":[[650,2],[1000,0]],"id":52385918},{"atl":[[520,2],[900,0]],"id":52385920},{"atl":[[520,0],[120,2]],"id":52385889},{"atl":[[580,0]],"id":52385914},{"atl":[[620,0]],"id":52385883},{"atb":[[3,0],[6,20]],"id":52385885},{"atl":[[510,0]],"id":52385885},{"atl":[[490,0]],"id":52385896},{"atl":[[560,0],[160,2]],"id":52385890},{"atl":[[75,2],[450,0]],"id":52385892},{"atl":[[130,2]],"id":52385904},{"atl":[[100,2]],"id":52385898},{"atl":[[360,2]],"id":52385900},{"atl":[[500,0]],"id":52385911},{"atl":[[420,0],[60,2]],"id":52385913},{"atl":[[280,2],[680,0]],"id":52385907},{"atl":[[540,2],[940,0]],"id":52385886},{"atl":[[590,2],[940,0]],"id":52385919},{"atl":[[290,2],[660,0]],"id":52385921},{"atl":[[630,0],[230,2]],"id":52385882},{"atl":[[600,0]],"id":52385884},{"atl":[[920,0]],"id":52385917},{"atl":[[140,2]],"id":52385897},{"atl":[[540,0],[140,2]],"id":52385891},{"atl":[[840,0]],"id":52385893},{"atl":[[90,2],[480,0]],"id":52385903},{"atl":[[510,0]],"id":52385905},{"atl":[[50,2.04]],"id":52385899}],"con":true,"img":false}]}
{"op":"mcm","clk":"11550551568","pt":1719499861027,"mc":[{"id":"1.230178171","rc":[{"atl":[[85,0],[460,3.31]],"id":52385912},{"atb":[[36,0],[26,9]],"id":52385918},{"atl":[[650,0],[1000,2]],"id":52385918},{"atl":[[900,2]],"id":52385920},{"atl":[[550,3.09],[160,0]],"id":52385890},{"atl":[[210,4.87]],"id":52385904},{"atl":[[100,0],[490,3.23]],"id":52385898},{"atl":[[940,2]],"id":52385886},{"atl":[[590,0],[940,2]],"id":52385919},{"atl":[[530,3.13],[140,0]],"id":52385897},{"atl":[[140,0],[220,4.74]],"id":52385891},{"atl":[[110,0],[500,3.2]],"id":52385905}],"con":true,"img":false}]}
{"op":"mcm","clk":"11550551575","pt":1719499861129,"mc":[{"id":"1.230178171","rc":[{"atl":[[520,0]],"id":52385920},{"atl":[[130,0]],"id":52385904},{"atl":[[540,0]],"id":52385886}],"con":true,"img":false}]}
{"op":"mcm","clk":"11550551581","pt":1719499861231,"mc":[{"id":"1.230178171","rc":[{"atb":[[26,5],[30,5.95]],"id":52385918},{"atl":[[650,2],[1000,0]],"id":52385918}],"con":true,"img":false}]}
{"op":"mcm","clk":"11550551590","pt":1719499861339,"mc":[{"id":"1.230178171","rc":[{"atb":[[12,0]],"id":52385882}],"con":true,"img":false}]}
{"op":"mcm","clk":"11550551614","pt":1719499861650,"mc":[{"id":"1.230178171","rc":[{"atb":[[11,0]],"id":52385883}],"con":true,"img":false}]}
{"op":"mcm","clk":"11550551627","pt":1719499861858,"mc":[{"id":"1.230178171","rc":[{"atb":[[20,0]],"id":52385886}],"con":true,"img":false}]}
{"op":"mcm","clk":"11550551645","pt":1719499862120,"mc":[{"id":"1.230178171","rc":[{"atb":[[14,0]],"id":52385891}],"con":true,"img":false}]}
{"op":"mcm","clk":"11550551662","pt":1719499862431,"mc":[{"id":"1.230178171","rc":[{"atb":[[18,0]],"id":52385893}],"con":true,"img":false}]}
{"op":"mcm","clk":"11550551679","pt":1719499862744,"mc":[{"id":"1.230178171","rc":[{"atb":[[7,0]],"id":52385898}],"con":true,"img":false}]}
{"op":"mcm","clk":"11550551701","pt":1719499863055,"mc":[{"id":"1.230178171","rc":[{"atb":[[9,0]],"id":52385905}],"con":true,"img":false}]}
{"op":"mcm","clk":"11550551718","pt":1719499863363,"mc":[{"id":"1.230178171","rc":[{"atb":[[14,0]],"id":52385907}],"con":true,"img":false}]}
{"op":"mcm","clk":"11550551733","pt":1719499863622,"mc":[{"id":"1.230178171","rc":[{"atb":[[10,0]],"id":52385914}],"con":true,"img":false}]}
{"op":"mcm","clk":"11550551747","pt":1719499863829,"mc":[{"id":"1.230178171","rc":[{"atb":[[20,0]],"id":52385917}],"con":true,"img":false}]}
{"op":"mcm","clk":"11550551758","pt":1719499864137,"mc":[{"id":"1.230178171","rc":[{"atb":[[20,0]],"id":52385918}],"con":true,"img":false}]}
{"op":"mcm","clk":"11550551771","pt":1719499864344,"mc":[{"id":"1.230178171","rc":[{"atb":[[20,0]],"id":52385919}],"con":true,"img":false}]}
{"op":"mcm","clk":"11550551787","pt":1719499864652,"mc":[{"id":"1.230178171","rc":[{"atb":[[13,0]],"id":52385921}],"con":true,"img":false}]}
{"op":"mcm","clk":"11550551801","pt":1719499864960,"mc":[{"id":"1.230178171","rc":[{"atb":[[10,0]],"id":52385912},{"atb":[[8,0]],"id":52385896},{"atb":[[12,0]],"id":52385890},{"atb":[[12,0]],"id":52385904},{"atb":[[12,0]],"id":52385900},{"atb":[[10,0]],"id":52385913},{"atb":[[16,0]],"id":52385884},{"atb":[[8,0]],"id":52385897},{"atb":[[12,0]],"id":52385903},{"atb":[[8,0]],"id":52385899}],"con":true,"img":false}]}
{"op":"mcm","clk":"11550551807","pt":1719499865063,"mc":[{"id":"1.230178171","rc":[{"atb":[[11,10]],"id":52385912},{"atb":[[11,11]],"id":52385896},{"atb":[[14,8]],"id":52385890},{"atb":[[15,7]],"id":52385904},{"atb":[[13,11]],"id":52385900},{"atb":[[11,8]],"id":52385913},{"atb":[[18,6]],"id":52385884},{"atb":[[10,12]],"id":52385897},{"atb":[[14,8]],"id":52385903},{"atb":[[10,11]],"id":52385899}],"con":true,"img":false}]}
{"op":"mcm","clk":"11550551811","pt":1719499865169,"mc":[{"id":"1.230178171","rc":[{"atb":[[12.5,0],[14,34]],"id":52385903},{"atb":[[10,43],[8.2,0]],"id":52385899}],"con":true,"img":false}]}
{"op":"mcm","clk":"11550551868","pt":1719499866352,"mc":[{"id":"1.230178171","rc":[{"atb":[[26,9]],"id":52385918}],"con":true,"img":false}]}
{"op":"mcm","clk":"11550551873","pt":1719499866455,"mc":[{"id":"1.230178171","rc":[{"atb":[[30,2.5]],"id":52385918}],"con":true,"img":false}]}
{"op":"mcm","clk":"11550552147","pt":1719499870732,"mc":[{"id":"1.230178171","rc":[{"atb":[[29,0]],"id":52385900}],"con":true,"img":false}]}
{"op":"mcm","clk":"11550552153","pt":1719499870834,"mc":[{"id":"1.230178171","rc":[{"atl":[[36,0]],"id":52385892},{"atb":[[10.5,0],[11,10],[15.5,15]],"id":52385900},{"atb":[[55,0]],"id":52385886}],"con":true,"img":false}]}
{"op":"mcm","clk":"11550552157","pt":1719499870937,"mc":[{"id":"1.230178171","rc":[{"atl":[[50,12.24]],"id":52385892},{"atb":[[34,10],[21,0],[23,9.55]],"id":52385886}],"con":true,"img":false}]}
{"op":"mcm","clk":"11550552170","pt":1719499871145,"mc":[{"id":"1.230178171","rc":[{"atl":[[34,0]],"id":52385910},{"atl":[[30,0]],"id":52385911}],"con":true,"img":false}]}
{"op":"mcm","clk":"11550552177","pt":1719499871246,"mc":[{"id":"1.230178171","rc":[{"atl":[[36,17.14]],"id":52385910},{"atl":[[34,18.18]],"id":52385911}],"con":true,"img":false}]}
{"op":"mcm","clk":"11550552252","pt":1719499872637,"mc":[{"id":"1.230178171","rc":[{"atb":[[20,5.26]],"id":52385920}],"con":true,"img":false}]}
{"op":"mcm","clk":"11550552266","pt":1719499872947,"mc":[{"id":"1.230178171","rc":[{"atb":[[11,0]],"id":52385889}],"con":true,"img":false}]}
{"op":"mcm","clk":"11550552271","pt":1719499873049,"mc":[{"id":"1.230178171","rc":[{"atb":[[12,8]],"id":52385889}],"con":true,"img":false}]}
{"op":"mcm","clk":"11550552391","pt":1719499875676,"mc":[{"id":"1.230178171","rc":[{"atb":[[11,0]],"id":52385912},{"atb":[[15,0]],"id":52385904},{"atb":[[13,0]],"id":52385900},{"atb":[[11,0]],"id":52385913},{"atb":[[18,0]],"id":52385884},{"atb":[[10,0]],"id":52385897},{"atb":[[14,26]],"id":52385903}],"con":true,"img":false}]}
{"op":"mcm","clk":"11550552397","pt":1719499875776,"mc":[{"id":"1.230178171","rc":[{"atb":[[12,10]],"id":52385912},{"atb":[[12,7]],"id":52385904},{"atb":[[14,11]],"id":52385900},{"atb":[[10,8]],"id":52385913},{"atb":[[16,6]],"id":52385884},{"atb":[[11,12]],"id":52385897},{"atb":[[12,8]],"id":52385903}],"con":true,"img":false}]}
{"op":"mcm","clk":"11550552407","pt":1719499875880,"mc":[{"id":"1.230178171","rc":[{"atb":[[14,0]],"id":52385903}],"con":true,"img":false}]}
{"op":"mcm","clk":"11550552423","pt":1719499876087,"mc":[{"id":"1.230178171","rc":[{"atb":[[12.5,26]],"id":52385903}],"con":true,"img":false}]}
{"op":"mcm","clk":"11550552527","pt":1719499878149,"mc":[{"id":"1.230178171","rc":[{"atl":[[26,15.4]],"id":52385906},{"atl":[[48,12.77]],"id":52385885}],"con":true,"img":false}]}
{"op":"mcm","clk":"11550552538","pt":1719499878253,"mc":[{"id":"1.230178171","rc":[{"atl":[[34,18.18]],"id":52385910},{"atl":[[29,16.62]],"id":52385912},{"atl":[[27,0]],"id":52385906},{"atb":[[46,10]],"id":52385918},{"atl":[[230,2.62]],"id":52385918},{"atb":[[34,16.34]],"id":52385920},{"atl":[[160,3.77]],"id":52385920},{"atb":[[13,26]],"id":52385889},{"atl":[[55,11.11]],"id":52385889},{"atb":[[21,20]],"id":52385914},{"atl":[[55,11.11]],"id":52385914},{"atl":[[70,8.7]],"id":52385883},{"atl":[[65,0]],"id":52385885},{"atb":[[11.5,32]],"id":52385896},{"atl":[[34,18.18]],"id":52385896},{"atb":[[20,16.18]],"id":52385890},{"atl":[[50,12.24]],"id":52385890},{"atl":[[38,16.22]],"id":52385892},{"atb":[[15,19.74]],"id":52385904},{"atl":[[44,13.95]],"id":52385904},{"atb":[[14,16.46]],"id":52385898},{"atl":[[36,16.46]],"id":52385898},{"atb":[[26,20.08]],"id":52385900},{"atl":[[100,6.06]],"id":52385900},{"atl":[[32,19.35]],"id":52385911},{"atl":[[26,24]],"id":52385913},{"atb":[[29,20]],"id":52385907},{"atl":[[80,7.59]],"id":52385907},{"atb":[[50,11.04]],"id":52385886},{"atl":[[160,3.77]],"id":52385886},{"atl":[[95,6.38]],"id":52385921},{"atl":[[70,8.7]],"id":52385882},{"atb":[[24,22]],"id":52385884},{"atl":[[60,10.17]],"id":52385884},{"atb":[[60,10.02]],"id":52385917},{"atl":[[170,3.55]],"id":52385917},{"atb":[[19.5,16.26]],"id":52385897},{"atl":[[48,12.77]],"id":52385897},{"atb":[[17,19.48]],"id":52385891},{"atl":[[48,12.77]],"id":52385891},{"atb":[[42,14.63]],"id":52385893},{"atl":[[130,4.65]],"id":52385893},{"atl":[[34,18.18]],"id":52385903},{"atb":[[14,16.4]],"id":52385905},{"atl":[[36,16.4]],"id":52385905},{"atl":[[22,15]],"id":52385899}],"con":true,"img":false}]}
{"op":"mcm","clk":"11550552543","pt":1719499878357,"mc":[{"id":"1.230178171","rc":[{"atl":[[460,1.31]],"id":52385912},{"atb":[[38,2.7],[26,5]],"id":52385918},{"atb":[[20,0],[22,4.76]],"id":52385920},{"atl":[[520,2],[900,0]],"id":52385920},{"atl":[[550,1.09],[160,2]],"id":52385890},{"atl":[[130,2],[210,2.87]],"id":52385904},{"atl":[[490,1.23]],"id":52385898},{"atl":[[540,2],[940,0]],"id":52385886},{"atl":[[530,1.13],[140,2]],"id":52385897},{"atl":[[140,2],[220,2.74]],"id":52385891},{"atl":[[500,1.2]],"id":52385905}],"con":true,"img":false}]}
{"op":"mcm","clk":"11550552549","pt":1719499878459,"mc":[{"id":"1.230178171","rc":[{"atl":[[36,0]],"id":52385910},{"atl":[[85,2],[460,0]],"id":52385912},{"atb":[[38,0],[44,0],[30,5.95]],"id":52385918},{"atl":[[270,0]],"id":52385918},{"atb":[[32,2.49]],"id":52385920},{"atl":[[190,0]],"id":52385920},{"atb":[[11.5,0]],"id":52385889},{"atl":[[70,0]],"id":52385889},{"atb":[[10.5,0]],"id":52385914},{"atl":[[75,0]],"id":52385914},{"atl":[[80,0]],"id":52385883},{"atb":[[8.2,0]],"id":52385896},{"atl":[[55,0]],"id":52385896},{"atb":[[19.5,0]],"id":52385890},{"atl":[[550,0]],"id":52385890},{"atl":[[50,0]],"id":52385892},{"atb":[[14.5,0]],"id":52385904},{"atl":[[210,0]],"id":52385904},{"atb":[[13.5,0]],"id":52385898},{"atl":[[100,2],[490,0]],"id":52385898},{"atb":[[15.5,0]],"id":52385900},{"atl":[[120,0]],"id":52385900},{"atl":[[34,0]],"id":52385911},{"atl":[[27,0]],"id":52385913},{"atb":[[28,0]],"id":52385907},{"atl":[[95,0]],"id":52385907},{"atb":[[34,0]],"id":52385886},{"atl":[[200,0]],"id":52385886},{"atl":[[210,2.87]],"id":52385919},{"atl":[[160,0]],"id":52385921},{"atl":[[85,0]],"id":52385882},{"atb":[[23,0]],"id":52385884},{"atl":[[75,0]],"id":52385884},{"atb":[[55,0]],"id":52385917},{"atl":[[240,0]],"id":52385917},{"atb":[[19,0]],"id":52385897},{"atl":[[530,0]],"id":52385897},{"atb":[[15.5,0]],"id":52385891},{"atl":[[220,0]],"id":52385891},{"atb":[[40,0]],"id":52385893},{"atl":[[150,0]],"id":52385893},{"atl":[[36,0]],"id":52385903},{"atb":[[13.5,0]],"id":52385905},{"atl":[[110,2],[500,0]],"id":52385905},{"atl":[[23,0]],"id":52385899}],"con":true,"img":false}]}
{"op":"mcm","clk":"11550552555","pt":1719499878563,"mc":[{"id":"1.230178171","rc":[{"atb":[[38,2.7],[30,2.5]],"id":52385918},{"atl":[[590,2],[230,0],[940,0]],"id":52385919},{"atb":[[17,25.48]],"id":52385891}],"con":true,"img":false}]}
{"op":"mcm","clk":"11550552564","pt":1719499878667,"mc":[{"id":"1.230178171","rc":[{"atb":[[38,0],[26,9]],"id":52385918},{"atl":[[34,0]],"id":52385903}],"con":true,"img":false}]}
{"op":"mcm","clk":"11550552570","pt":1719499878769,"mc":[{"id":"1.230178171","rc":[{"atb":[[11,0]],"id":52385906},{"atb":[[26,5],[30,5.95]],"id":52385918},{"atb":[[11,0]],"id":52385896},{"atb":[[14,0]],"id":52385890},{"atb":[[13,0]],"id":52385911},{"atl":[[36,17.14]],"id":52385903}],"con":true,"img":false}]}
{"op":"mcm","clk":"11550552578","pt":1719499878872,"mc":[{"id":"1.230178171","rc":[{"atb":[[10,8]],"id":52385906},{"atb":[[26,9],[30,2.5]],"id":52385918},{"atb":[[12,11]],"id":52385896},{"atb":[[17,8]],"id":52385890},{"atb":[[15,6]],"id":52385911}],"con":true,"img":false}]}
{"op":"mcm","clk":"11550552582","pt":1719499878973,"mc":[{"id":"1.230178171","rc":[{"atb":[[6.6,15.4]],"id":52385906},{"atb":[[11.5,0],[12.5,32]],"id":52385896}],"con":true,"img":false}]}
{"op":"mcm","clk":"11550552587","pt":1719499879075,"mc":[{"id":"1.230178171","rc":[{"atb":[[29,20]],"id":52385883}],"con":true,"img":false}]}
{"op":"mcm","clk":"11550552602","pt":1719499879282,"mc":[{"id":"1.230178171","rc":[{"atb":[[28,0]],"id":52385883}],"con":true,"img":false}]}
{"op":"mcm","clk":"11550552898","pt":1719499883673,"mc":[{"id":"1.230178171","rc":[{"atb":[[12,0]],"id":52385889}],"con":true,"img":false}]}
{"op":"mcm","clk":"11550552908","pt":1719499883774,"mc":[{"id":"1.230178171","rc":[{"atb":[[16,8]],"id":52385889}],"con":true,"img":false}]}
{"op":"mcm","clk":"11550553028","pt":1719499885688,"mc":[{"id":"1.230178171","rc":[{"atb":[[14,0]],"id":52385900}],"con":true,"img":false}]}
{"op":"mcm","clk":"11550553043","pt":1719499885999,"mc":[{"id":"1.230178171","rc":[{"atb":[[12,0]],"id":52385912},{"atb":[[12,0]],"id":52385904},{"atb":[[16,0]],"id":52385884},{"atb":[[11,0]],"id":52385897},{"atb":[[12,0]],"id":52385903}],"con":true,"img":false}]}
{"op":"mcm","clk":"11550553052","pt":1719499886050,"mc":[{"id":"1.230178171","rc":[{"atb":[[11,10]],"id":52385912},{"atb":[[14,7]],"id":52385904},{"atb":[[20,6]],"id":52385884},{"atb":[[12,12]],"id":52385897},{"atb":[[13,8]],"id":52385903}],"con":true,"img":false}]}
{"op":"mcm","clk":"11550553062","pt":1719499886256,"mc":[{"id":"1.230178171","rc":[{"atb":[[12.5,0],[13.5,26]],"id":52385903}],"con":true,"img":false}]}
{"op":"mcm","clk":"11550553173","pt":1719499888263,"mc":[{"id":"1.230178171","rc":[{"atb":[[55,11.11]],"id":52385886}],"con":true,"img":false}]}
{"op":"mcm","clk":"11550553183","pt":1719499888466,"mc":[{"id":"1.230178171","rc":[{"atb":[[50,0]],"id":52385886}],"con":true,"img":false}]}
{"op":"mcm","clk":"11550553197","pt":1719499888673,"mc":[{"id":"1.230178171","rc":[{"atb":[[12,0]],"id":52385896}],"con":true,"img":false}]}
{"op":"mcm","clk":"11550553207","pt":1719499888776,"mc":[{"id":"1.230178171","rc":[{"atb":[[13,11]],"id":52385896}],"con":true,"img":false}]}
{"op":"mcm","clk":"11550553212","pt":1719499888878,"mc":[{"id":"1.230178171","rc":[{"atb":[[12.5,0],[13.5,32]],"id":52385896}],"con":true,"img":false}]}
{"op":"mcm","clk":"11550553231","pt":1719499889086,"mc":[{"id":"1.230178171","rc":[{"atb":[[27,20]],"id":52385900}],"con":true,"img":false}]}
{"op":"mcm","clk":"11550553244","pt":1719499889187,"mc":[{"id":"1.230178171","rc":[{"atb":[[26,0]],"id":52385900}],"con":true,"img":false}]}
{"op":"mcm","clk":"11550553591","pt":1719499895486,"mc":[{"id":"1.230178171","rc":[{"atb":[[16.5,26]],"id":52385889}],"con":true,"img":false}]}
{"op":"mcm","clk":"11550553603","pt":1719499895686,"mc":[{"id":"1.230178171","rc":[{"atb":[[13,0]],"id":52385889}],"con":true,"img":false}]}
{"op":"mcm","clk":"11550554102","pt":1719499904000,"mc":[{"id":"1.230178171","rc":[{"atl":[[38,0]],"id":52385892}],"con":true,"img":false}]}
{"op":"mcm","clk":"11550554107","pt":1719499904104,"mc":[{"id":"1.230178171","rc":[{"atl":[[40,15.38]],"id":52385892}],"con":true,"img":false}]}
{"op":"mcm","clk":"11550554209","pt":1719499905601,"mc":[{"id":"1.230178171","rc":[{"atb":[[13,0]],"id":52385896},{"atb":[[12,0]],"id":52385897}],"con":true,"img":false}]}
{"op":"mcm","clk":"11550554216","pt":1719499905703,"mc":[{"id":"1.230178171","rc":[{"atb":[[12,11]],"id":52385896},{"atb":[[11,12]],"id":52385897}],"con":true,"img":false}]}
{"op":"mcm","clk":"11550554223","pt":1719499905805,"mc":[{"id":"1.230178171","rc":[{"atb":[[13.5,0]],"id":52385896}],"con":true,"img":false}]}
{"op":"mcm","clk":"11550554231","pt":1719499905907,"mc":[{"id":"1.230178171","rc":[{"atb":[[12.5,32]],"id":52385896}],"con":true,"img":false}]}
{"op":"mcm","clk":"11550554506","pt":1719499910207,"mc":[{"id":"1.230178171","rc":[{"atb":[[7.2,0],[6.4,0],[12,8]],"id":52385910},{"atl":[[34,0],[42,0],[50,0]],"id":52385910},{"atb":[[8,0],[8.8,0],[14.5,0]],"id":52385912},{"atl":[[38,0],[29,0],[30,0]],"id":52385912},{"atb":[[6.4,0],[5.8,0],[6.6,0]],"id":52385906},{"atl":[[34,0],[42,0],[26,0]],"id":52385906},{"atb":[[46,0],[26,4],[30,0]],"id":52385918},{"atl":[[230,0],[240,0]],"id":52385918},{"atb":[[32,0],[34,0],[27,0]],"id":52385920},{"atl":[[160,0],[170,0]],"id":52385920},{"atb":[[16.5,0],[10.5,0],[12.5,0]],"id":52385889},{"atl":[[80,0],[55,0],[60,0]],"id":52385889},{"atb":[[18,0],[20,0],[21,0]],"id":52385914},{"atl":[[80,0],[55,0],[60,0]],"id":52385914},{"atb":[[11.5,0],[13.5,0],[29,0]],"id":52385883},{"atl":[[70,0],[75,0],[95,0]],"id":52385883},{"atb":[[16,6],[10.5,0],[12.5,0]],"id":52385885},{"atl":[[70,0],[48,0],[50,0]],"id":52385885},{"atb":[[8.6,0],[12.5,0],[7.8,0]],"id":52385896},{"atl":[[34,0],[36,0],[44,0]],"id":52385896},{"atb":[[9.6,0],[20,0],[11,0]],"id":52385890},{"atl":[[75,0],[50,0],[55,0]],"id":52385890},{"atb":[[8.6,0],[13,6],[9.4,0]],"id":52385892},{"atl":[[40,0],[46,0],[60,0]],"id":52385892},{"atb":[[11.5,0],[9.8,0],[15,0]],"id":52385904},{"atl":[[44,0],[46,0],[60,0]],"id":52385904},{"atb":[[8.6,0],[14,0],[7.8,0]],"id":52385898},{"atl":[[36,0],[38,0],[46,0]],"id":52385898},{"atb":[[11.5,0],[27,0],[13.5,0]],"id":52385900},{"atl":[[150,0],[100,0],[110,0]],"id":52385900},{"atb":[[16.5,0],[8.6,0],[9.4,0]],"id":52385911},{"atl":[[32,0],[40,0],[48,0]],"id":52385911},{"atb":[[8.6,0],[12,0],[7.8,0]],"id":52385913},{"atl":[[34,0],[42,0],[26,0]],"id":52385913},{"atb":[[19.5,0],[23,0],[29,0]],"id":52385907},{"atl":[[80,0],[85,0],[110,0]],"id":52385907},{"atb":[[23,4.55],[55,0],[27,0]],"id":52385886},{"atl":[[160,0],[170,0]],"id":52385886},{"atb":[[19,0],[40,0],[22,0]],"id":52385919},{"atl":[[210,0],[220,0]],"id":52385919},{"atb":[[36,0],[26,0],[30,0]],"id":52385921},{"atl":[[140,0],[95,0],[100,0]],"id":52385921},{"atb":[[16,0],[14,0],[30,0]],"id":52385882},{"atl":[[70,0],[75,0],[95,0]],"id":52385882},{"atb":[[24,0],[12.5,0],[14.5,0]],"id":52385884},{"atl":[[65,0],[85,0],[60,0]],"id":52385884},{"atb":[[34,0],[42,0],[60,0]],"id":52385917},{"atl":[[170,0],[180,0]],"id":52385917},{"atb":[[19.5,0],[7.6,0],[8.4,0]],"id":52385897},{"atl":[[70,0],[48,0],[50,0]],"id":52385897},{"atb":[[16.5,0],[17,6],[14.5,0]],"id":52385891},{"atl":[[70,0],[48,0],[50,0]],"id":52385891},{"atb":[[42,0],[25,0],[29,0]],"id":52385893},{"atl":[[130,0],[140,0],[180,0]],"id":52385893},{"atb":[[8.6,0],[13.5,0],[7.8,0]],"id":52385903},{"atl":[[36,0],[44,0],[55,0]],"id":52385903},{"atb":[[10,0],[9.2,0],[14,0]],"id":52385905},{"atl":[[36,0],[38,0],[46,0]],"id":52385905},{"atb":[[10,11],[6.2,0],[7,0]],"id":52385899},{"atl":[[22,0],[24,0],[28,0]],"id":52385899}],"con":true,"img":false}]}
{"op":"mcm","clk":"11550554510","pt":1719499910308,"mc":[{"id":"1.230178171","rc":[{"atb":[[9.6,11.63]],"id":52385883},{"atb":[[6.2,19.23]],"id":52385898},{"atb":[[10,0],[10.5,10.53]],"id":52385921},{"atb":[[9.2,0],[9.8,11.36]],"id":52385882},{"atb":[[21,0],[24,4.35]],"id":52385917}],"con":true,"img":false}]}
{"op":"mcm","clk":"11550554514","pt":1719499910409,"mc":[{"id":"1.230178171","rc":[{"atb":[[4.9,0],[5.2,23.81]],"id":52385910},{"atb":[[9.6,0],[9.2,0],[3.9,34.48]],"id":52385883},{"atl":[[620,2],[220,0]],"id":52385883},{"atb":[[6.4,18.52],[6,0]],"id":52385885},{"atb":[[6,0]],"id":52385898},{"atl":[[100,0],[500,2]],"id":52385898},{"atl":[[630,2],[230,0]],"id":52385882},{"atb":[[24,0]],"id":52385917},{"atb":[[7.4,0],[7.8,14.71]],"id":52385891},{"atb":[[4.8,26.32],[5.1,0]],"id":52385899}],"con":true,"img":false}]}
{"op":"mcm","clk":"11550554523","pt":1719499910515,"mc":[{"id":"1.230178171","rc":[{"atl":[[65,0],[430,2]],"id":52385910},{"atl":[[110,0],[510,2]],"id":52385885},{"atb":[[6.8,17.24]],"id":52385917},{"atl":[[540,2],[140,0]],"id":52385891},{"atl":[[50,0]],"id":52385899}],"con":true,"img":false}]}
{"op":"mcm","clk":"11550554531","pt":1719499910616,"mc":[{"id":"1.230178171","rc":[{"atb":[[12,8]],"id":52385914},{"atb":[[17,6]],"id":52385883},{"atb":[[9,11]],"id":52385898},{"atb":[[14,7]],"id":52385900},{"atb":[[16,6]],"id":52385907},{"atb":[[24,4]],"id":52385886},{"atb":[[16,6]],"id":52385921},{"atb":[[16,6]],"id":52385882},{"atb":[[20,5]],"id":52385893},{"atb":[[10,10]],"id":52385905},{"atl":[[400,2]],"id":52385899}],"con":true,"img":false}]}
{"op":"mcm","clk":"11550554540","pt":1719499910718,"mc":[{"id":"1.230178171","rc":[{"atl":[[760,2]],"id":52385900},{"atl":[[680,2]],"id":52385907},{"atl":[[940,2]],"id":52385886},{"atl":[[840,2]],"id":52385893},{"atl":[[110,0]],"id":52385905}],"con":true,"img":false}]}
{"op":"mcm","clk":"11550554549","pt":1719499910821,"mc":[{"id":"1.230178171","rc":[{"atl":[[580,2],[180,0]],"id":52385914},{"atb":[[9.6,11.63],[3.9,0]],"id":52385883},{"atl":[[360,0]],"id":52385900},{"atl":[[280,0]],"id":52385907},{"atl":[[540,0]],"id":52385886},{"atl":[[440,0]],"id":52385893},{"atl":[[510,2]],"id":52385905}],"con":true,"img":false}]}
{"op":"mcm","clk":"11550554574","pt":1719499911085,"mc":[{"id":"1.230178171","rc":[{"atl":[[26,2]],"id":52385906}],"con":true,"img":false}]}
{"op":"mcm","clk":"11550554589","pt":1719499911289,"mc":[{"id":"1.230178171","rc":[{"atl":[[38,0],[340,2],[26,0]],"id":52385906}],"con":true,"img":false}]}
{"op":"mcm","clk":"11550554609","pt":1719499911598,"mc":[{"id":"1.230178171","rc":[{"atb":[[20,5]],"id":52385917}],"con":true,"img":false}]}
{"op":"mcm","clk":"11550554758","pt":1719499913819,"mc":[{"id":"1.230178171","rc":[{"atb":[[17.5,2]],"id":52385897}],"con":true,"img":false}]}
{"op":"mcm","clk":"11550554795","pt":1719499914027,"mc":[{"id":"1.230178171","rc":[{"atl":[[540,2],[140,0]],"id":52385897}],"con":true,"img":false}]}
{"op":"mcm","clk":"11550554806","pt":1719499914233,"mc":[{"id":"1.230178171","rc":[{"atb":[[12,40]],"id":52385910},{"atl":[[420,1.43]],"id":52385910},{"atl":[[330,3.82]],"id":52385906},{"atb":[[20,5.26],[22,0]],"id":52385920},{"atb":[[12.5,20]],"id":52385914},{"atl":[[980,0.61]],"id":52385914},{"atb":[[5.1,24.39],[5.3,0],[5.4,1]],"id":52385892},{"atb":[[6.6,1]],"id":52385911},{"atl":[[90,2],[950,0.02]],"id":52385911},{"atb":[[22,4.76],[23,0]],"id":52385886},{"atb":[[10,1],[13.5,5],[15.5,2.5]],"id":52385884},{"atl":[[70,2.5],[90,5],[960,0.02]],"id":52385884},{"atb":[[32,2.5],[27,5]],"id":52385917},{"atl":[[180,2.5],[220,5]],"id":52385917},{"atb":[[18,8]],"id":52385897},{"atl":[[530,1.13]],"id":52385897},{"atb":[[8,5],[6.2,1],[8.8,2.5]],"id":52385903},{"atl":[[65,5],[48,2.5],[980,0.02]],"id":52385903},{"atb":[[10.5,40]],"id":52385905},{"atl":[[500,1.2]],"id":52385905},{"atb":[[10,55]],"id":52385899},{"atl":[[390,1.54]],"id":52385899}],"con":true,"img":false}]}
{"op":"mcm","clk":"11550554817","pt":1719499914337,"mc":[{"id":"1.230178171","rc":[{"atb":[[2.9,52.63],[7.4,2.5],[5.2,0],[6.6,5]],"id":52385910},{"atl":[[44,2.5],[55,5]],"id":52385910},{"atb":[[8.6,5],[5.3,1],[5.2,0],[5.7,21.28],[9.4,2.5]],"id":52385912},{"atl":[[36,5],[75,2],[85,0],[29,2.5],[970,0.02]],"id":52385912},{"atb":[[4.8,26.32],[4.3,0],[6.4,2.5],[5.8,5]],"id":52385906},{"atl":[[34,2.5],[340,0],[42,5]],"id":52385906},{"atb":[[19.5,5],[23,2.5],[1.19,1]],"id":52385918},{"atl":[[240,2.5],[1000,0.02]],"id":52385918},{"atb":[[20,0],[21,5],[1.19,1],[24,4.35],[25,2.5]],"id":52385920},{"atl":[[180,2.5],[220,5],[1000,0.02]],"id":52385920},{"atb":[[10.5,5],[12.5,2.5],[7,1]],"id":52385889},{"atl":[[80,5],[110,2],[120,0],[60,2.5],[960,0.02]],"id":52385889},{"atb":[[16,5],[9.6,11.63],[18,2.5],[8.8,0]],"id":52385914},{"atl":[[570,2],[580,0],[80,5],[60,2.5]],"id":52385914},{"atb":[[17.5,8],[13,5],[15,2.5]],"id":52385883},{"atl":[[75,2.5],[600,2],[620,0],[610,0.99],[95,5]],"id":52385883},{"atb":[[16.5,24],[11,5],[13,2.5]],"id":52385885},{"atl":[[75,5],[55,2.5],[500,1.2]],"id":52385885},{"atb":[[8,5],[8.8,2.5]],"id":52385896},{"atl":[[38,2.5],[85,2],[95,0],[46,5],[960,0.02]],"id":52385896},{"atb":[[8.6,1],[11.5,2.5],[9.8,5]],"id":52385890},{"atl":[[140,2],[75,5],[160,0],[55,2.5],[980,0.02]],"id":52385890},{"atb":[[9.6,2.5],[5.1,0],[8.8,5],[5.7,21.28]],"id":52385892},{"atl":[[70,2],[75,0],[46,2.5],[60,5]],"id":52385892},{"atb":[[8,1],[11.5,2.5],[9.8,5]],"id":52385904},{"atl":[[130,0],[65,5],[48,2.5],[120,2],[980,0.02]],"id":52385904},{"atb":[[9.2,46.5],[8.4,5]],"id":52385898},{"atl":[[36,2.5],[44,5],[480,2],[490,1.23],[500,0]],"id":52385898},{"atb":[[10.5,5],[11,0],[11.5,9.52],[12.5,2.5],[14.5,18.24]],"id":52385900},{"atl":[[140,5],[100,2.5],[950,0.63]],"id":52385900},{"atb":[[9.6,2.5],[8.8,5]],"id":52385911},{"atl":[[40,2.5],[48,5],[100,0]],"id":52385911},{"atb":[[8,5],[8.8,2.5],[5.4,1]],"id":52385913},{"atl":[[36,2.5],[44,5],[970,0.02]],"id":52385913},{"atb":[[16.5,16],[17.5,5],[19.5,2.5]],"id":52385907},{"atl":[[660,2],[680,0],[85,2.5],[110,5],[950,0.63]],"id":52385907},{"atb":[[20,5],[22,0],[24,6.5],[25,16.17]],"id":52385886},{"atl":[[180,2.5],[220,5],[900,2],[940,0],[950,0.63]],"id":52385886},{"atb":[[17.5,2.5],[1.19,1],[15.5,5]],"id":52385919},{"atl":[[210,2.5],[1000,0.02]],"id":52385919},{"atb":[[16.5,33.06],[22,5],[26,2.5]],"id":52385921},{"atl":[[280,2.15],[90,2.5],[120,5]],"id":52385921},{"atb":[[16.5,24],[17,2.5],[15,5]],"id":52385882},{"atl":[[75,2.5],[630,0],[620,2.97],[95,5]],"id":52385882},{"atl":[[190,2],[200,0]],"id":52385884},{"atb":[[21,30]],"id":52385917},{"atl":[[530,1.13]],"id":52385917},{"atb":[[9,2.5],[8.2,5]],"id":52385897},{"atl":[[46,2.5],[60,5]],"id":52385897},{"atb":[[16.5,2.5],[17.5,24],[14.5,5]],"id":52385891},{"atl":[[530,1.13],[70,5],[50,2.5]],"id":52385891},{"atb":[[17.5,6.06],[20,10],[21,14.14],[24,2.5],[15.5,0]],"id":52385893},{"atl":[[140,2.5],[180,5],[980,0.61]],"id":52385893},{"atl":[[85,2],[90,0]],"id":52385903},{"atb":[[10.5,42.5],[9.4,5]],"id":52385905},{"atl":[[36,2.5],[44,5],[490,2],[510,0]],"id":52385905},{"atb":[[4.8,0],[6.6,2.5],[2.78,56.18],[5.9,5]],"id":52385899},{"atl":[[32,5],[360,2],[400,0],[27,2.5]],"id":52385899}],"con":true,"img":false}]}
{"op":"mcm","clk":"11550554825","pt":1719499914391,"mc":[{"id":"1.230178171","rc":[{"atl":[[90,0],[480,2]],"id":52385911}],"con":true,"img":false}]}
{"op":"mcm","clk":"11550554833","pt":1719499914494,"mc":[{"id":"1.230178171","rc":[{"atl":[[36,2.86],[330,1.82]],"id":52385906},{"atb":[[23,7.05],[26,0]],"id":52385918},{"atl":[[650,0],[1000,2.02]],"id":52385918},{"atl":[[520,0],[880,2]],"id":52385920},{"atb":[[17.5,8.56],[21,0]],"id":52385919},{"atl":[[530,2],[590,0]],"id":52385919}],"con":true,"img":false}]}
{"op":"mcm","clk":"11550554842","pt":1719499914597,"mc":[{"id":"1.230178171","rc":[{"atb":[[20,5]],"id":52385920},{"atl":[[38,5.52]],"id":52385911}],"con":true,"img":false}]}
{"op":"mcm","clk":"11550554863","pt":1719499914812,"mc":[{"id":"1.230178171","rc":[{"atb":[[15,0]],"id":52385911}],"con":true,"img":false}]}
{"op":"mcm","clk":"11550554870","pt":1719499914909,"mc":[{"id":"1.230178171","rc":[{"atb":[[14,6]],"id":52385911}],"con":true,"img":false}]}
{"op":"mcm","clk":"11550554908","pt":1719499915322,"mc":[{"id":"1.230178171","rc":[{"atb":[[9.6,9.82]],"id":52385906},{"atb":[[18,9.38]],"id":52385889},{"atb":[[17,9.38]],"id":52385885},{"atb":[[13,15.38]],"id":52385892},{"atb":[[15.5,9.38]],"id":52385903}],"con":true,"img":false}]}
{"op":"mcm","clk":"11550554933","pt":1719499915635,"mc":[{"id":"1.230178171","rc":[{"atb":[[20,5]],"id":52385919}],"con":true,"img":false}]}
{"op":"mcm","clk":"11550554950","pt":1719499915790,"mc":[{"id":"1.230178171","rc":[{"atb":[[16,0]],"id":52385885},{"atb":[[11,0]],"id":52385897},{"atb":[[13,0]],"id":52385903}],"con":true,"img":false}]}
{"op":"mcm","clk":"11550554958","pt":1719499915894,"mc":[{"id":"1.230178171","rc":[{"atb":[[9.6,0]],"id":52385906},{"atb":[[18,0]],"id":52385889},{"atb":[[17,0],[19,6]],"id":52385885},{"atb":[[13,5.99]],"id":52385892},{"atl":[[38,0]],"id":52385911},{"atb":[[17.5,0],[12,12]],"id":52385897},{"atb":[[15,8],[15.5,0]],"id":52385903}],"con":true,"img":false}]}
{"op":"mcm","clk":"11550555080","pt":1719499917591,"mc":[{"id":"1.230178171","rc":[{"atb":[[16,0]],"id":52385907}],"con":true,"img":false}]}
{"op":"mcm","clk":"11550555093","pt":1719499917799,"mc":[{"id":"1.230178171","rc":[{"atb":[[12,0]],"id":52385914}],"con":true,"img":false}]}
{"op":"mcm","clk":"11550555107","pt":1719499918004,"mc":[{"id":"1.230178171","rc":[{"atb":[[16,0]],"id":52385921}],"con":true,"img":false}]}
{"op":"mcm","clk":"11550555122","pt":1719499918211,"mc":[{"id":"1.230178171","rc":[{"atb":[[11,0]],"id":52385912}],"con":true,"img":false}]}
{"op":"mcm","clk":"11550555128","pt":1719499918312,"mc":[{"id":"1.230178171","rc":[{"atb":[[10,10]],"id":52385912},{"atb":[[21,35]],"id":52385917}],"con":true,"img":false}]}
{"op":"mcm","clk":"11550555131","pt":1719499918415,"mc":[{"id":"1.230178171","rc":[{"atb":[[6.8,0]],"id":52385917}],"con":true,"img":false}]}
{"op":"mcm","clk":"11550555137","pt":1719499918518,"mc":[{"id":"1.230178171","rc":[{"atl":[[700,2],[760,0]],"id":52385900}],"con":true,"img":false}]}
{"op":"mcm","clk":"11550555145","pt":1719499918725,"mc":[{"id":"1.230178171","rc":[{"atb":[[20,0]],"id":52385917}],"con":true,"img":false}]}
{"op":"mcm","clk":"11550555188","pt":1719499919499,"mc":[{"id":"1.230178171","rc":[{"atb":[[21,10],[24,0]],"id":52385920}],"con":true,"img":false}]}
{"op":"mcm","clk":"11550555194","pt":1719499919603,"mc":[{"id":"1.230178171","rc":[{"atl":[[36,0],[42,7.44]],"id":52385906},{"atb":[[9,12.05]],"id":52385918},{"atl":[[530,0],[930,2]],"id":52385919}],"con":true,"img":false}]}
{"op":"mcm","clk":"11550555206","pt":1719499919811,"mc":[{"id":"1.230178171","rc":[{"atb":[[23,2.5]],"id":52385918}],"con":true,"img":false}]}
{"op":"mcm","clk":"11550555267","pt":1719499920692,"mc":[{"id":"1.230178171","rc":[{"atl":[[36,15]],"id":52385892},{"atb":[[24,2.5]],"id":52385886},{"atb":[[10,0]],"id":52385905}],"con":true,"img":false}]}
{"op":"mcm","clk":"11550555274","pt":1719499920798,"mc":[{"id":"1.230178171","rc":[{"atb":[[20,14.26]],"id":52385886},{"atb":[[12,10]],"id":52385905}],"con":true,"img":false}]}
{"op":"mcm","clk":"11550555280","pt":1719499920902,"mc":[{"id":"1.230178171","rc":[{"atb":[[25,12]],"id":52385886}],"con":true,"img":false}]}
{"op":"mcm","clk":"11550555328","pt":1719499921422,"mc":[{"id":"1.230178171","rc":[{"atl":[[40,5.28]],"id":52385910}],"con":true,"img":false}]}
{"op":"mcm","clk":"11550555335","pt":1719499921522,"mc":[{"id":"1.230178171","rc":[{"atl":[[65,2],[430,0]],"id":52385910},{"atb":[[48,3.06]],"id":52385886}],"con":true,"img":false}]}
{"op":"mcm","clk":"11550555384","pt":1719499922095,"mc":[{"id":"1.230178171","rc":[{"atb":[[2.9,0],[5.5,22.22]],"id":52385910},{"atb":[[4.9,25.64],[2.78,0]],"id":52385899}],"con":true,"img":false}]}
{"op":"mcm","clk":"11550555396","pt":1719499922302,"mc":[{"id":"1.230178171","rc":[{"atb":[[17.5,2.5],[21,5]],"id":52385919}],"con":true,"img":false}]}
{"op":"mcm","clk":"11550555404","pt":1719499922405,"mc":[{"id":"1.230178171","rc":[{"atl":[[40,0]],"id":52385910},{"atb":[[48,0]],"id":52385886}],"con":true,"img":false}]}
{"op":"mcm","clk":"11550555411","pt":1719499922510,"mc":[{"id":"1.230178171","rc":[{"atb":[[12.5,15]],"id":52385896}],"con":true,"img":false}]}
{"op":"mcm","clk":"11550555559","pt":1719499924726,"mc":[{"id":"1.230178171","rc":[{"atl":[[330,3.82],[42,5]],"id":52385906}],"con":true,"img":false}]}
{"op":"mcm","clk":"11550555620","pt":1719499925606,"mc":[{"id":"1.230178171","rc":[{"atb":[[12,0]],"id":52385897},{"atb":[[15,0]],"id":52385903}],"con":true,"img":false}]}
{"op":"mcm","clk":"11550555627","pt":1719499925709,"mc":[{"id":"1.230178171","rc":[{"atb":[[11,12]],"id":52385897},{"atb":[[13,8]],"id":52385903}],"con":true,"img":false}]}
{"op":"mcm","clk":"11550555696","pt":1719499926741,"mc":[{"id":"1.230178171","rc":[{"atl":[[42,2.5],[44,0],[50,5],[55,0]],"id":52385910},{"atl":[[32,2.5],[34,0],[40,5],[42,0]],"id":52385906},{"atb":[[19.5,0],[20,5],[23,0],[24,2.5]],"id":52385918},{"atb":[[13,0],[13.5,5],[15,0],[15.5,2.5]],"id":52385883},{"atb":[[10,5],[11.5,0],[12,2.5],[9.8,0]],"id":52385890},{"atb":[[8.6,5],[9.2,44],[8.4,0],[9.4,2.5]],"id":52385898},{"atb":[[10.5,0],[12.5,0],[13,2.5]],"id":52385900},{"atl":[[34,2.5],[36,0],[42,5],[44,0]],"id":52385913},{"atb":[[20,9.26],[21,5],[24,0],[25,14.5]],"id":52385886},{"atb":[[16,5],[17.5,0],[18,2.5],[15.5,0]],"id":52385919},{"atb":[[16,11],[17,0],[18,2.5],[15,0]],"id":52385882},{"atb":[[32,0],[34,2.5],[27,0],[28,5]],"id":52385917},{"atb":[[9.6,2.5],[9,0],[8.2,0],[8.8,5]],"id":52385897},{"atb":[[16.5,0],[17,8.5],[14.5,0],[15,5]],"id":52385891},{"atb":[[20,5],[21,19.14],[24,0],[25,2.5]],"id":52385893},{"atl":[[65,0],[46,2.5],[48,0],[60,5]],"id":52385903}],"con":true,"img":false}]}
{"op":"mcm","clk":"11550555715","pt":1719499926948,"mc":[{"id":"1.230178171","rc":[{"atb":[[21,30],[26,4]],"id":52385917}],"con":true,"img":false}]}
{"op":"mcm","clk":"11550555804","pt":1719499927929,"mc":[{"id":"1.230178171","rc":[{"atb":[[6.8,0],[7.8,14.71]],"id":52385889},{"atb":[[9.6,0],[11,10]],"id":52385883},{"atb":[[6.4,0],[7.4,15.62]],"id":52385885},{"atb":[[8.4,0],[9.4,11.9]],"id":52385890},{"atb":[[6.2,0],[6.8,17.24]],"id":52385898},{"atb":[[11.5,0],[12.5,8.7]],"id":52385900},{"atb":[[10.5,0],[12,9.09]],"id":52385907},{"atb":[[11,10],[9.8,0]],"id":52385882},{"atb":[[7.2,0],[8.2,13.89]],"id":52385897},{"atb":[[9,12.5],[7.8,0]],"id":52385891},{"atb":[[17.5,0],[18.5,5.71]],"id":52385893}],"con":true,"img":false}]}
{"op":"mcm","clk":"11550555862","pt":1719499928602,"mc":[{"id":"1.230178171","rc":[{"atl":[[32,0],[26,2.5],[27,0],[30,5]],"id":52385899}],"con":true,"img":false}]}
{"op":"mcm","clk":"11550555871","pt":1719499928706,"mc":[{"id":"1.230178171","rc":[{"atl":[[42,2.44],[360,0]],"id":52385899}],"con":true,"img":false}]}
{"op":"mcm","clk":"11550556015","pt":1719499930619,"mc":[{"id":"1.230178171","rc":[{"atl":[[34,15]],"id":52385910},{"atl":[[25,17.64]],"id":52385906},{"atb":[[30,15]],"id":52385914},{"atl":[[55,11.11]],"id":52385914},{"atb":[[13,26]],"id":52385892},{"atb":[[16.5,15]],"id":52385911},{"atl":[[30,15]],"id":52385911},{"atb":[[20,5.26]],"id":52385886},{"atb":[[24,15]],"id":52385884},{"atl":[[65,9.38]],"id":52385884},{"atb":[[19,15]],"id":52385897},{"atl":[[36,15]],"id":52385897},{"atb":[[15,15]],"id":52385903},{"atl":[[36,15]],"id":52385903},{"atb":[[12,0],[14,20]],"id":52385905},{"atl":[[34,18.18]],"id":52385905},{"atl":[[20,15]],"id":52385899}],"con":true,"img":false}]}
{"op":"mcm","clk":"11550556022","pt":1719499930723,"mc":[{"id":"1.230178171","rc":[{"atl":[[420,0]],"id":52385910},{"atl":[[330,2]],"id":52385906},{"atl":[[570,0],[170,2],[980,0]],"id":52385914},{"atb":[[5.4,0]],"id":52385892},{"atb":[[6.6,0]],"id":52385911},{"atl":[[90,2],[950,0],[480,0]],"id":52385911},{"atb":[[24,4]],"id":52385886},{"atb":[[10,0]],"id":52385884},{"atl":[[960,0]],"id":52385884},{"atb":[[18,0]],"id":52385897},{"atl":[[530,0],[540,0],[120,2]],"id":52385897},{"atb":[[6.2,0]],"id":52385903},{"atl":[[980,0]],"id":52385903},{"atb":[[10,10],[10.5,2.5]],"id":52385905},{"atl":[[95,2],[500,0]],"id":52385905}],"con":true,"img":false}]}
{"op":"mcm","clk":"11550556032","pt":1719499930827,"mc":[{"id":"1.230178171","rc":[{"atb":[[14.5,15]],"id":52385912},{"atl":[[24,15]],"id":52385912},{"atb":[[46,10]],"id":52385918},{"atl":[[230,2.62]],"id":52385918},{"atb":[[34,15]],"id":52385920},{"atl":[[170,3.55]],"id":52385920},{"atb":[[17.5,15]],"id":52385889},{"atl":[[55,11.11]],"id":52385889},{"atb":[[12.5,0]],"id":52385914},{"atb":[[29,15]],"id":52385883},{"atl":[[70,8.7]],"id":52385883},{"atb":[[19,21]],"id":52385885},{"atl":[[50,12.24]],"id":52385885},{"atl":[[36,15]],"id":52385896},{"atb":[[20,15]],"id":52385890},{"atl":[[42,14.63]],"id":52385890},{"atb":[[15,15]],"id":52385904},{"atl":[[46,13.33]],"id":52385904},{"atb":[[14,15]],"id":52385898},{"atl":[[34,15]],"id":52385898},{"atb":[[27,15]],"id":52385900},{"atl":[[95,6.38]],"id":52385900},{"atb":[[12,15]],"id":52385913},{"atl":[[24,15]],"id":52385913},{"atb":[[29,15]],"id":52385907},{"atl":[[80,7.59]],"id":52385907},{"atb":[[50,12.24]],"id":52385886},{"atl":[[170,3.55]],"id":52385886},{"atb":[[40,10]],"id":52385919},{"atl":[[200,3.02]],"id":52385919},{"atb":[[36,15]],"id":52385921},{"atl":[[85,7.14]],"id":52385921},{"atb":[[30,15.94]],"id":52385882},{"atl":[[70,8.7]],"id":52385882},{"atb":[[55,11.11]],"id":52385917},{"atl":[[170,3.55]],"id":52385917},{"atl":[[48,12.77]],"id":52385891},{"atb":[[42,14.63]],"id":52385893},{"atl":[[130,4.65]],"id":52385893},{"atl":[[490,0]],"id":52385905},{"atl":[[390,0]],"id":52385899}],"con":true,"img":false}]}
{"op":"mcm","clk":"11550556042","pt":1719499930932,"mc":[{"id":"1.230178171","rc":[{"atb":[[5.3,0]],"id":52385912},{"atl":[[970,0]],"id":52385912},{"atb":[[1.19,0]],"id":52385918},{"atl":[[1000,2]],"id":52385918},{"atb":[[1.19,0]],"id":52385920},{"atl":[[880,0],[480,2],[1000,0]],"id":52385920},{"atb":[[7,0]],"id":52385889},{"atl":[[960,0]],"id":52385889},{"atb":[[17.5,0]],"id":52385883},{"atl":[[600,0],[610,0],[200,2]],"id":52385883},{"atb":[[16.5,0]],"id":52385885},{"atl":[[100,2],[500,0],[510,0]],"id":52385885},{"atl":[[960,0]],"id":52385896},{"atb":[[8.6,0]],"id":52385890},{"atl":[[980,0]],"id":52385890},{"atb":[[8,0]],"id":52385904},{"atl":[[980,0]],"id":52385904},{"atb":[[9.2,0]],"id":52385898},{"atl":[[90,2],[480,0],[490,0]],"id":52385898},{"atb":[[14.5,0]],"id":52385900},{"atl":[[300,2],[700,0],[950,0]],"id":52385900},{"atb":[[5.4,0]],"id":52385913},{"atl":[[970,0]],"id":52385913},{"atb":[[16.5,0]],"id":52385907},{"atl":[[260,2],[660,0],[950,0]],"id":52385907},{"atb":[[20,0],[25,6.67]],"id":52385886},{"atl":[[950,0],[500,2]],"id":52385886},{"atb":[[1.19,0]],"id":52385919},{"atl":[[1000,0]],"id":52385919},{"atb":[[16.5,0]],"id":52385921},{"atl":[[280,0]],"id":52385921},{"atb":[[16.5,0]],"id":52385882},{"atl":[[620,0],[220,2]],"id":52385882},{"atb":[[21,0],[26,0],[28,8.7]],"id":52385917},{"atl":[[530,0]],"id":52385917},{"atl":[[530,0],[540,0],[130,2]],"id":52385891},{"atb":[[21,5]],"id":52385893},{"atl":[[410,2],[840,0],[980,0]],"id":52385893}],"con":true,"img":false}]}
{"op":"mcm","clk":"11550556053","pt":1719499931036,"mc":[{"id":"1.230178171","rc":[{"atb":[[9,0],[20,10]],"id":52385918},{"atl":[[900,0]],"id":52385886}],"con":true,"img":false}]}
{"op":"mcm","clk":"11550556095","pt":1719499931607,"mc":[{"id":"1.230178171","rc":[{"atb":[[20,0]],"id":52385893}],"con":true,"img":false}]}
{"op":"mcm","clk":"11550556111","pt":1719499931813,"mc":[{"id":"1.230178171","rc":[{"atb":[[20,0]],"id":52385920}],"con":true,"img":false}]}
{"op":"mcm","clk":"11550556135","pt":1719499932124,"mc":[{"id":"1.230178171","rc":[{"atb":[[10,0]],"id":52385912}],"con":true,"img":false}]}
{"op":"mcm","clk":"11550556143","pt":1719499932227,"mc":[{"id":"1.230178171","rc":[{"atb":[[11,10]],"id":52385912}],"con":true,"img":false}]}
{"op":"mcm","clk":"11550556155","pt":1719499932432,"mc":[{"id":"1.230178171","rc":[{"atl":[[40,7.56],[330,0]],"id":52385906}],"con":true,"img":false}]}
{"op":"mcm","clk":"11550556378","pt":1719499935730,"mc":[{"id":"1.230178171","rc":[{"atb":[[12,0]],"id":52385896},{"atb":[[14,0]],"id":52385900},{"atb":[[11,0]],"id":52385897},{"atb":[[13,0]],"id":52385903}],"con":true,"img":false}]}
{"op":"mcm","clk":"11550556383","pt":1719499935835,"mc":[{"id":"1.230178171","rc":[{"atb":[[13,11]],"id":52385896},{"atb":[[13,9.5]],"id":52385900},{"atb":[[12,12]],"id":52385897},{"atb":[[14,8]],"id":52385903}],"con":true,"img":false}]}
{"op":"mcm","clk":"11550556391","pt":1719499935938,"mc":[{"id":"1.230178171","rc":[{"atb":[[12.5,0],[13.5,32]],"id":52385896}],"con":true,"img":false}]}
{"op":"mcm","clk":"11550556666","pt":1719499940618,"mc":[{"id":"1.230178171","rc":[{"atb":[[24,0]],"id":52385886}],"con":true,"img":false}]}
{"op":"mcm","clk":"11550556682","pt":1719499940929,"mc":[{"id":"1.230178171","rc":[{"atb":[[10,0]],"id":52385905}],"con":true,"img":false}]}
{"op":"mcm","clk":"11550556691","pt":1719499941028,"mc":[{"id":"1.230178171","rc":[{"atb":[[11,10]],"id":52385905}],"con":true,"img":false}]}
{"op":"mcm","clk":"11550556993","pt":1719499945627,"mc":[{"id":"1.230178171","rc":[{"atb":[[13,2.5]],"id":52385900},{"atb":[[14,0]],"id":52385903}],"con":true,"img":false}]}
{"op":"mcm","clk":"11550557000","pt":1719499945729,"mc":[{"id":"1.230178171","rc":[{"atb":[[14,7]],"id":52385900},{"atb":[[13,8]],"id":52385903}],"con":true,"img":false}]}
{"op":"mcm","clk":"11550557061","pt":1719499946758,"mc":[{"id":"1.230178171","rc":[{"atl":[[19.5,20]],"id":52385899}],"con":true,"img":false}]}
{"op":"mcm","clk":"11550557081","pt":1719499947017,"mc":[{"id":"1.230178171","rc":[{"atl":[[20,0]],"id":52385899}],"con":true,"img":false}]}
{"op":"mcm","clk":"11550557676","pt":1719499956925,"mc":[{"id":"1.230178171","rc":[{"atb":[[9.6,5],[11,12.5]],"id":52385905}],"con":true,"img":false}]}
{"op":"mcm","clk":"11550557683","pt":1719499957032,"mc":[{"id":"1.230178171","rc":[{"atb":[[10.5,0],[9.4,0]],"id":52385905}],"con":true,"img":false}]}
{"op":"mcm","clk":"11550557693","pt":1719499957238,"mc":[{"id":"1.230178171","rc":[{"atl":[[34,0]],"id":52385910},{"atb":[[30,0]],"id":52385914},{"atl":[[50,0]],"id":52385885},{"atl":[[42,2.5],[46,0],[50,5],[60,0]],"id":52385892},{"atl":[[38,2.5],[40,0],[46,5],[48,0]],"id":52385911},{"atb":[[40,0]],"id":52385919},{"atb":[[16,5],[18,2.5],[13.5,0],[15.5,0]],"id":52385884},{"atl":[[36,0]],"id":52385903}],"con":true,"img":false}]}
{"op":"mcm","clk":"11550557698","pt":1719499957341,"mc":[{"id":"1.230178171","rc":[{"atl":[[24,25.12],[25,0]],"id":52385906},{"atb":[[29,15]],"id":52385914},{"atl":[[32,19.35],[36,0]],"id":52385892},{"atb":[[27,0]],"id":52385900},{"atl":[[23,26],[24,0]],"id":52385913},{"atb":[[42,0]],"id":52385893}],"con":true,"img":false}]}
{"op":"mcm","clk":"11550557706","pt":1719499957444,"mc":[{"id":"1.230178171","rc":[{"atl":[[36,15]],"id":52385910},{"atl":[[36,2.86]],"id":52385906},{"atl":[[55,13.61]],"id":52385885},{"atb":[[21,16.04]],"id":52385919},{"atl":[[55,11.11]],"id":52385903}],"con":true,"img":false}]}
{"op":"mcm","clk":"11550557712","pt":1719499957546,"mc":[{"id":"1.230178171","rc":[{"atl":[[40,5]],"id":52385906},{"atb":[[26,15]],"id":52385900},{"atb":[[40,14.3]],"id":52385893}],"con":true,"img":false}]}
{"op":"mcm","clk":"11550557719","pt":1719499957649,"mc":[{"id":"1.230178171","rc":[{"atl":[[36,0]],"id":52385910},{"atb":[[29,0]],"id":52385914}],"con":true,"img":false}]}
{"op":"mcm","clk":"11550557727","pt":1719499957751,"mc":[{"id":"1.230178171","rc":[{"atl":[[40,15.38]],"id":52385910},{"atb":[[27,20]],"id":52385914},{"atb":[[26,0]],"id":52385900}],"con":true,"img":false}]}
{"op":"mcm","clk":"11550557733","pt":1719499957853,"mc":[{"id":"1.230178171","rc":[{"atb":[[25,22.76]],"id":52385900}],"con":true,"img":false}]}
{"op":"mcm","clk":"11550557875","pt":1719499959660,"mc":[{"id":"1.230178171","rc":[{"atb":[[17,0]],"id":52385883},{"atb":[[13,0]],"id":52385896},{"atb":[[14,0]],"id":52385904},{"atb":[[14,0]],"id":52385900},{"atb":[[16,5]],"id":52385882},{"atb":[[13,0]],"id":52385903}],"con":true,"img":false}]}
{"op":"mcm","clk":"11550557882","pt":1719499959762,"mc":[{"id":"1.230178171","rc":[{"atb":[[20,6]],"id":52385883},{"atb":[[15,11]],"id":52385896},{"atb":[[13,7]],"id":52385904},{"atb":[[13,9.5]],"id":52385900},{"atb":[[19,6]],"id":52385882},{"atb":[[15,23]],"id":52385903}],"con":true,"img":false}]}
{"op":"mcm","clk":"11550557888","pt":1719499959867,"mc":[{"id":"1.230178171","rc":[{"atb":[[13.5,0],[15,43]],"id":52385896}],"con":true,"img":false}]}
{"op":"mcm","clk":"11550558075","pt":1719499962859,"mc":[{"id":"1.230178171","rc":[{"atb":[[12.5,6]],"id":52385910},{"atb":[[9.6,7]],"id":52385912},{"atl":[[23,3.94]],"id":52385912},{"atb":[[5.9,7]],"id":52385906},{"atl":[[23,4.3]],"id":52385906},{"atb":[[18,3.56]],"id":52385889},{"atl":[[50,2.2]],"id":52385914},{"atb":[[18,3.01]],"id":52385883},{"atb":[[19.5,3]],"id":52385885},{"atb":[[8.2,4.72]],"id":52385896},{"atb":[[15.5,3.53]],"id":52385890},{"atb":[[13.5,3.64]],"id":52385892},{"atb":[[12,5]],"id":52385904},{"atl":[[44,2.41]],"id":52385904},{"atl":[[25,2.35]],"id":52385898},{"atb":[[13.5,5]],"id":52385900},{"atl":[[70,2.7]],"id":52385900},{"atb":[[12.5,4.22]],"id":52385911},{"atl":[[22,4]],"id":52385913},{"atb":[[18,4]],"id":52385907},{"atl":[[75,2.09]],"id":52385907},{"atb":[[23,3]],"id":52385921},{"atb":[[18.5,2.9]],"id":52385882},{"atb":[[25,2.7]],"id":52385884},{"atb":[[29,4]],"id":52385917},{"atb":[[12.5,5.11]],"id":52385897},{"atl":[[34,3.27]],"id":52385897},{"atb":[[18,4]],"id":52385891},{"atb":[[22,3.59]],"id":52385893},{"atb":[[15.5,5]],"id":52385903},{"atb":[[9.8,6.1]],"id":52385905},{"atl":[[30,3]],"id":52385905},{"atb":[[6,6.5]],"id":52385899},{"atl":[[19,3.5]],"id":52385899}],"con":true,"img":false}]}
{"op":"mcm","clk":"11550558081","pt":1719499962963,"mc":[{"id":"1.230178171","rc":[{"atb":[[12.5,28]],"id":52385910},{"atl":[[23,27.22]],"id":52385912},{"atb":[[18,29.56]],"id":52385889},{"atl":[[50,14.44]],"id":52385914},{"atb":[[19.5,19]],"id":52385885},{"atb":[[13.5,20.92]],"id":52385892},{"atl":[[42,14.63]],"id":52385904},{"atl":[[25,15.58]],"id":52385898},{"atl":[[70,9]],"id":52385900},{"atl":[[75,10.2]],"id":52385907},{"atb":[[26,22]],"id":52385884},{"atl":[[34,19.23]],"id":52385897},{"atb":[[18.5,27]],"id":52385891},{"atb":[[15.5,25]],"id":52385903},{"atl":[[30,23.69]],"id":52385905},{"atl":[[18.5,20]],"id":52385899}],"con":true,"img":false}]}
{"op":"mcm","clk":"11550558096","pt":1719499963169,"mc":[{"id":"1.230178171","rc":[{"atb":[[12,8]],"id":52385910},{"atl":[[24,0]],"id":52385912},{"atb":[[17.5,0]],"id":52385889},{"atl":[[55,0]],"id":52385914},{"atb":[[19,6]],"id":52385885},{"atb":[[13,6]],"id":52385892},{"atl":[[46,0]],"id":52385904},{"atl":[[34,0]],"id":52385898},{"atl":[[95,0]],"id":52385900},{"atl":[[80,0]],"id":52385907},{"atb":[[24,0]],"id":52385884},{"atl":[[36,0]],"id":52385897},{"atb":[[17.5,0]],"id":52385891},{"atb":[[15,8]],"id":52385903},{"atl":[[34,0]],"id":52385905},{"atl":[[19.5,0]],"id":52385899}],"con":true,"img":false}]}
{"op":"mcm","clk":"11550558119","pt":1719499963634,"mc":[{"id":"1.230178171","rc":[{"atb":[[12,0]],"id":52385910},{"atb":[[13,0]],"id":52385892}],"con":true,"img":false}]}
{"op":"mcm","clk":"11550558125","pt":1719499963739,"mc":[{"id":"1.230178171","rc":[{"atb":[[15,8]],"id":52385910},{"atb":[[16,6]],"id":52385892}],"con":true,"img":false}]}
{"op":"mcm","clk":"11550558353","pt":1719499968052,"mc":[{"id":"1.230178171","rc":[{"atl":[[32,0]],"id":52385892}],"con":true,"img":false}]}
{"op":"mcm","clk":"11550558360","pt":1719499968155,"mc":[{"id":"1.230178171","rc":[{"atl":[[34,15]],"id":52385892}],"con":true,"img":false}]}
{"op":"mcm","clk":"11550558387","pt":1719499968771,"mc":[{"id":"1.230178171","rc":[{"atl":[[29,21.43]],"id":52385911}],"con":true,"img":false}]}
{"op":"mcm","clk":"11550558400","pt":1719499968975,"mc":[{"id":"1.230178171","rc":[{"atl":[[30,0]],"id":52385911}],"con":true,"img":false}]}
{"op":"mcm","clk":"11550558509","pt":1719499970875,"mc":[{"id":"1.230178171","rc":[{"atb":[[21,5],[23,5],[25,0],[27,2.5]],"id":52385920},{"atl":[[70,5],[75,0],[50,2.5],[55,11.11]],"id":52385885},{"atb":[[17.5,0],[18,9],[19.5,0],[20,2.5]],"id":52385907},{"atb":[[22,0],[23,8],[26,0],[27,2.5]],"id":52385921}],"con":true,"img":false}]}
{"op":"mcm","clk":"11550558515","pt":1719499970978,"mc":[{"id":"1.230178171","rc":[{"atb":[[21,0],[26,4]],"id":52385920}],"con":true,"img":false}]}
{"op":"mcm","clk":"11550558546","pt":1719499971648,"mc":[{"id":"1.230178171","rc":[{"atb":[[19,0]],"id":52385882}],"con":true,"img":false}]}
{"op":"mcm","clk":"11550558562","pt":1719499971955,"mc":[{"id":"1.230178171","rc":[{"atb":[[20,0]],"id":52385883},{"atb":[[15,32]],"id":52385896},{"atb":[[13,0]],"id":52385904},{"atb":[[13,2.5]],"id":52385900},{"atb":[[15,0]],"id":52385903}],"con":true,"img":false}]}
{"op":"mcm","clk":"11550558566","pt":1719499972061,"mc":[{"id":"1.230178171","rc":[{"atb":[[18,9.01]],"id":52385883},{"atb":[[14,11]],"id":52385896},{"atb":[[14,7]],"id":52385904},{"atb":[[14,7]],"id":52385900},{"atb":[[14,8]],"id":52385903}],"con":true,"img":false}]}
{"op":"mcm","clk":"11550558580","pt":1719499972268,"mc":[{"id":"1.230178171","rc":[{"atb":[[15,0]],"id":52385896}],"con":true,"img":false}]}
{"op":"mcm","clk":"11550558586","pt":1719499972370,"mc":[{"id":"1.230178171","rc":[{"atb":[[9,15]],"id":52385896}],"con":true,"img":false}]}
{"op":"mcm","clk":"11550558617","pt":1719499972987,"mc":[{"id":"1.230178171","rc":[{"atl":[[22,22.6]],"id":52385906},{"atb":[[29,20]],"id":52385914},{"atl":[[22,28]],"id":52385913}],"con":true,"img":false}]}
{"op":"mcm","clk":"11550558630","pt":1719499973096,"mc":[{"id":"1.230178171","rc":[{"atl":[[32,19.35]],"id":52385910},{"atl":[[24,0]],"id":52385906},{"atb":[[27,0]],"id":52385914},{"atl":[[48,12.77]],"id":52385885},{"atb":[[42,11.04]],"id":52385919},{"atl":[[34,18.18]],"id":52385903}],"con":true,"img":false}]}
{"op":"mcm","clk":"11550558635","pt":1719499973144,"mc":[{"id":"1.230178171","rc":[{"atb":[[29,21.43]],"id":52385900},{"atl":[[23,0]],"id":52385913}],"con":true,"img":false}]}
{"op":"mcm","clk":"11550558643","pt":1719499973300,"mc":[{"id":"1.230178171","rc":[{"atl":[[40,0]],"id":52385910},{"atl":[[55,0]],"id":52385885},{"atb":[[25,0]],"id":52385900},{"atb":[[34,3.03],[21,0]],"id":52385919},{"atl":[[55,0]],"id":52385903}],"con":true,"img":false}]}
{"op":"mcm","clk":"11550558665","pt":1719499973672,"mc":[{"id":"1.230178171","rc":[{"atb":[[15,0]],"id":52385910}],"con":true,"img":false}]}
{"op":"mcm","clk":"11550558668","pt":1719499973767,"mc":[{"id":"1.230178171","rc":[{"atb":[[14,8]],"id":52385910}],"con":true,"img":false}]}
{"op":"mcm","clk":"11550558741","pt":1719499975361,"mc":[{"id":"1.230178171","rc":[{"atb":[[14,43]],"id":52385896}],"con":true,"img":false}]}
{"op":"mcm","clk":"11550558758","pt":1719499975567,"mc":[{"id":"1.230178171","rc":[{"atb":[[9,0]],"id":52385896}],"con":true,"img":false}]}
{"op":"mcm","clk":"11550558885","pt":1719499977568,"mc":[{"id":"1.230178171","rc":[{"atl":[[40,2.5],[42,0],[48,5],[50,0]],"id":52385910},{"atb":[[20,5],[22,5],[24,0],[26,2.5]],"id":52385918},{"atb":[[9.6,2.5],[8.6,0],[8.8,5],[9.4,0]],"id":52385898},{"atb":[[13,0],[13.5,7.5]],"id":52385900},{"atb":[[16,0],[20,7.5]],"id":52385919},{"atb":[[34,0],[36,2.5],[28,3.7],[29,9]],"id":52385917}],"con":true,"img":false}]}
{"op":"mcm","clk":"11550558894","pt":1719499977670,"mc":[{"id":"1.230178171","rc":[{"atb":[[20,0],[26,6.5]],"id":52385918}],"con":true,"img":false}]}
{"op":"mcm","clk":"11550558948","pt":1719499978498,"mc":[{"id":"1.230178171","rc":[{"atb":[[34,0],[21,5]],"id":52385919}],"con":true,"img":false}]}
{"op":"mcm","clk":"11550559094","pt":1719499980967,"mc":[{"id":"1.230178171","rc":[{"atl":[[22,0]],"id":52385906},{"atb":[[23,0],[24,5],[27,0],[28,2.5]],"id":52385920},{"atb":[[16,0],[16.5,5],[18,0],[18.5,2.5]],"id":52385914},{"atb":[[24,5],[28,2.5]],"id":52385921},{"atb":[[21,0],[22,8.59],[25,0],[26,2.5]],"id":52385893}],"con":true,"img":false}]}
{"op":"mcm","clk":"11550559100","pt":1719499981073,"mc":[{"id":"1.230178171","rc":[{"atl":[[23,26.9]],"id":52385906},{"atb":[[23,3],[27,0]],"id":52385921}],"con":true,"img":false}]}
{"op":"mcm","clk":"11550559142","pt":1719499981793,"mc":[{"id":"1.230178171","rc":[{"atb":[[1.31,100]],"id":52385906},{"atb":[[1.31,100]],"id":52385889},{"atb":[[1.31,100]],"id":52385883},{"atb":[[1.31,100]],"id":52385885},{"atb":[[1.31,100]],"id":52385896},{"atb":[[1.31,100]],"id":52385890},{"atb":[[1.31,100]],"id":52385892},{"atb":[[1.31,100]],"id":52385904},{"atb":[[1.31,100]],"id":52385898},{"atb":[[1.31,100]],"id":52385900},{"atb":[[1.31,100]],"id":52385907},{"atb":[[1.31,100]],"id":52385886},{"atb":[[1.31,100]],"id":52385882},{"atb":[[1.31,100]],"id":52385884},{"atb":[[1.31,100]],"id":52385897},{"atb":[[1.31,100]],"id":52385891},{"atb":[[1.31,100]],"id":52385893},{"atb":[[1.31,100]],"id":52385903},{"atb":[[1.31,100]],"id":52385905},{"atb":[[1.31,100]],"id":52385899}],"con":true,"img":false}]}
{"op":"mcm","clk":"11550559151","pt":1719499981896,"mc":[{"id":"1.230178171","rc":[{"atb":[[1.31,100]],"id":52385912},{"atb":[[1.31,100]],"id":52385918},{"atb":[[1.31,100]],"id":52385914},{"atb":[[1.31,100]],"id":52385911},{"atb":[[1.31,100]],"id":52385919},{"atb":[[1.31,100]],"id":52385921},{"atb":[[1.31,100]],"id":52385917}],"con":true,"img":false}]}
{"op":"mcm","clk":"11550559159","pt":1719499981998,"mc":[{"id":"1.230178171","rc":[{"atb":[[1.31,100]],"id":52385910},{"atb":[[1.31,100]],"id":52385913}],"con":true,"img":false}]}
{"op":"mcm","clk":"11550559174","pt":1719499982206,"mc":[{"id":"1.230178171","rc":[{"atb":[[1.31,100]],"id":52385920}],"con":true,"img":false}]}
{"op":"mcm","clk":"11550559198","pt":1719499982568,"mc":[{"id":"1.230178171","rc":[{"atb":[[14,32]],"id":52385896},{"atb":[[14,0]],"id":52385904},{"atb":[[14,0]],"id":52385903}],"con":true,"img":false}]}
{"op":"mcm","clk":"11550559208","pt":1719499982670,"mc":[{"id":"1.230178171","rc":[{"atb":[[13,11]],"id":52385896},{"atb":[[13,7]],"id":52385904},{"atb":[[13,8]],"id":52385903}],"con":true,"img":false}]}
{"op":"mcm","clk":"11550559216","pt":1719499982774,"mc":[{"id":"1.230178171","rc":[{"atb":[[14,0]],"id":52385896}],"con":true,"img":false}]}
{"op":"mcm","clk":"11550559226","pt":1719499982879,"mc":[{"id":"1.230178171","rc":[{"atb":[[9,15]],"id":52385896}],"con":true,"img":false}]}
{"op":"mcm","clk":"11550559278","pt":1719499983704,"mc":[{"id":"1.230178171","rc":[{"atb":[[14,0]],"id":52385910}],"con":true,"img":false}]}
{"op":"mcm","clk":"11550559285","pt":1719499983756,"mc":[{"id":"1.230178171","rc":[{"atb":[[13,8]],"id":52385910}],"con":true,"img":false}]}
{"op":"mcm","clk":"11550559294","pt":1719499983861,"mc":[{"id":"1.230178171","rc":[{"atb":[[13,34]],"id":52385910}],"con":true,"img":false}]}
{"op":"mcm","clk":"11550559306","pt":1719499984014,"mc":[{"id":"1.230178171","rc":[{"atb":[[12.5,6]],"id":52385910}],"con":true,"img":false}]}
{"op":"mcm","clk":"11550559376","pt":1719499985196,"mc":[{"id":"1.230178171","rc":[{"atb":[[21,0],[22,5],[25,4.17],[26,2.5]],"id":52385886}],"con":true,"img":false}]}
{"op":"mcm","clk":"11550559494","pt":1719499987305,"mc":[{"id":"1.230178171","rc":[{"atl":[[32,2.5],[34,0],[40,5],[42,0]],"id":52385913}],"con":true,"img":false}]}
{"op":"mcm","clk":"11550559525","pt":1719499987666,"mc":[{"id":"1.230178171","rc":[{"atb":[[13.5,32]],"id":52385896}],"con":true,"img":false}]}
{"op":"mcm","clk":"11550559538","pt":1719499987870,"mc":[{"id":"1.230178171","rc":[{"atb":[[9,0]],"id":52385896}],"con":true,"img":false}]}
{"op":"mcm","clk":"11550559594","pt":1719499988693,"mc":[{"id":"1.230178171","rc":[{"atl":[[34,0]],"id":52385903}],"con":true,"img":false}]}
{"op":"mcm","clk":"11550559601","pt":1719499988802,"mc":[{"id":"1.230178171","rc":[{"atb":[[18,4],[18.5,5],[20,0],[21,2.5]],"id":52385907},{"atl":[[36,15]],"id":52385903},{"atl":[[25,2.5],[26,0],[29,5],[30,0]],"id":52385899}],"con":true,"img":false}]}
{"op":"mcm","clk":"11550559649","pt":1719499989417,"mc":[{"id":"1.230178171","rc":[{"atb":[[22,0],[23,5],[26,4],[27,2.5]],"id":52385918},{"atb":[[36,0],[38,2.5],[29,4],[30,5]],"id":52385917},{"atb":[[22,3.59],[23,5],[26,0],[27,2.5]],"id":52385893}],"con":true,"img":false}]}
{"op":"mcm","clk":"11550559721","pt":1719499990497,"mc":[{"id":"1.230178171","rc":[{"atb":[[12.5,0]],"id":52385910},{"atb":[[18,6]],"id":52385883},{"atb":[[8.2,0]],"id":52385896},{"atb":[[13.5,17.28]],"id":52385892},{"atl":[[44,0]],"id":52385904},{"atb":[[18,0]],"id":52385907},{"atb":[[23,0]],"id":52385921},{"atb":[[25,0]],"id":52385884},{"atb":[[29,0]],"id":52385917},{"atb":[[18,0]],"id":52385891},{"atb":[[22,0]],"id":52385893},{"atl":[[19,0]],"id":52385899}],"con":true,"img":false}]}
{"op":"mcm","clk":"11550559727","pt":1719499990600,"mc":[{"id":"1.230178171","rc":[{"atb":[[13.5,3.3]],"id":52385910},{"atb":[[30,2]],"id":52385883},{"atb":[[14,4.3]],"id":52385896},{"atl":[[55,4.5]],"id":52385890},{"atb":[[16.5,2.95]],"id":52385892},{"atl":[[40,3],[42,0]],"id":52385904},{"atb":[[18.5,9]],"id":52385907},{"atb":[[25,3]],"id":52385921},{"atb":[[26,0],[27,3.27]],"id":52385884},{"atb":[[32,3.35]],"id":52385917},{"atb":[[18.5,0],[19,4]],"id":52385891},{"atb":[[24,2.8]],"id":52385893},{"atl":[[18.5,0],[18,4]],"id":52385899}],"con":true,"img":false}]}
{"op":"mcm","clk":"11550559735","pt":1719499990700,"mc":[{"id":"1.230178171","rc":[{"atb":[[30,22.69]],"id":52385883},{"atb":[[14,36.3]],"id":52385896},{"atl":[[38,16]],"id":52385904},{"atb":[[28,16.54]],"id":52385884},{"atb":[[19.5,18]],"id":52385891},{"atl":[[17.5,13]],"id":52385899}],"con":true,"img":false}]}
{"op":"mcm","clk":"11550559748","pt":1719499990910,"mc":[{"id":"1.230178171","rc":[{"atb":[[29,0]],"id":52385883},{"atb":[[13.5,0]],"id":52385896}],"con":true,"img":false}]}
{"op":"mcm","clk":"11550559874","pt":1719499992723,"mc":[{"id":"1.230178171","rc":[{"atb":[[6,2]],"id":52385910},{"atb":[[6,2]],"id":52385912},{"atb":[[6,2]],"id":52385906},{"atb":[[6,2]],"id":52385918},{"atb":[[6,2]],"id":52385920},{"atb":[[6,2]],"id":52385889},{"atb":[[6,2]],"id":52385914},{"atb":[[6,2]],"id":52385883},{"atb":[[6,2]],"id":52385885},{"atb":[[6,22]],"id":52385896},{"atb":[[6,2]],"id":52385890},{"atb":[[6,2]],"id":52385892},{"atb":[[6,2]],"id":52385904},{"atb":[[6,2]],"id":52385898},{"atb":[[6,2]],"id":52385900},{"atb":[[6,2]],"id":52385911},{"atb":[[6,2]],"id":52385913},{"atb":[[6,2]],"id":52385907},{"atb":[[6,2]],"id":52385886},{"atb":[[6,2]],"id":52385919},{"atb":[[6,2]],"id":52385921},{"atb":[[6,2]],"id":52385882},{"atb":[[6,2]],"id":52385884},{"atb":[[6,2]],"id":52385917},{"atb":[[6,2]],"id":52385897},{"atb":[[6,2]],"id":52385891},{"atb":[[6,2]],"id":52385893},{"atb":[[6,22]],"id":52385903},{"atb":[[6,2]],"id":52385905},{"atb":[[6,8.5]],"id":52385899}],"con":true,"img":false}]}
{"op":"mcm","clk":"11550560238","pt":1719499998990,"mc":[{"id":"1.230178171","rc":[{"atb":[[13.5,19.9]],"id":52385910}],"con":true,"img":false}]}
{"op":"mcm","clk":"11550560248","pt":1719499999101,"mc":[{"id":"1.230178171","rc":[{"atb":[[13,8]],"id":52385910}],"con":true,"img":false}]}
{"op":"mcm","clk":"11550560704","pt":1719500007982,"mc":[{"id":"1.230178171","rc":[{"atb":[[29,0]],"id":52385900},{"atb":[[42,0]],"id":52385919}],"con":true,"img":false}]}
{"op":"mcm","clk":"11550560708","pt":1719500008087,"mc":[{"id":"1.230178171","rc":[{"atb":[[28,22.22]],"id":52385900},{"atb":[[40,15.38]],"id":52385919}],"con":true,"img":false}]}
{"op":"mcm","clk":"11550561051","pt":1719500014028,"mc":[{"id":"1.230178171","rc":[{"atb":[[11.5,0],[12,7.5],[9.8,0]],"id":52385904}],"con":true,"img":false}]}
{"op":"mcm","clk":"11550561059","pt":1719500014134,"mc":[{"id":"1.230178171","rc":[{"atb":[[6.4,0],[5.8,0]],"id":52385906},{"atl":[[32,0],[40,0],[23,4.3]],"id":52385906},{"atb":[[46,0]],"id":52385918},{"atl":[[230,0]],"id":52385918},{"atb":[[19.5,3],[11,0],[13,0]],"id":52385885},{"atl":[[70,0],[48,0],[50,0]],"id":52385885},{"atb":[[12,5]],"id":52385904},{"atl":[[65,0],[48,0]],"id":52385904},{"atb":[[18,0],[40,0],[20,5]],"id":52385919},{"atl":[[200,0],[210,0]],"id":52385919},{"atb":[[55,0]],"id":52385917},{"atl":[[170,0]],"id":52385917}],"con":true,"img":false}]}
{"op":"mcm","clk":"11550561066","pt":1719500014247,"mc":[{"id":"1.230178171","rc":[{"atb":[[7.4,0],[13.5,3.3],[6.6,0]],"id":52385910},{"atl":[[32,0],[40,0],[48,0]],"id":52385910},{"atb":[[8.6,0],[14.5,0],[9.4,0]],"id":52385912},{"atl":[[36,0],[23,3.94],[29,0]],"id":52385912},{"atb":[[23,0],[27,0]],"id":52385918},{"atl":[[240,0]],"id":52385918},{"atb":[[34,0],[24,0],[28,0]],"id":52385920},{"atl":[[170,0],[180,0],[220,0]],"id":52385920},{"atb":[[18,3.56],[10.5,0],[12.5,0]],"id":52385889},{"atl":[[80,0],[55,0],[60,0]],"id":52385889},{"atb":[[16.5,0],[18.5,0],[29,0]],"id":52385914},{"atl":[[80,0],[50,2.2],[60,0]],"id":52385914},{"atb":[[13.5,0],[30,2],[15.5,0]],"id":52385883},{"atl":[[70,0],[75,0],[95,0]],"id":52385883},{"atb":[[8,0],[8.8,0],[14,4.3]],"id":52385896},{"atl":[[36,0],[38,0],[46,0]],"id":52385896},{"atb":[[20,0],[10,0],[12,0]],"id":52385890},{"atl":[[75,0],[42,0],[55,2]],"id":52385890},{"atb":[[9.6,0],[13.5,0],[8.8,0]],"id":52385892},{"atl":[[34,0],[42,0],[50,0]],"id":52385892},{"atb":[[15,0]],"id":52385904},{"atl":[[38,0]],"id":52385904},{"atb":[[9.6,0],[8.8,0],[14,0]],"id":52385898},{"atl":[[36,0],[44,0],[25,2.35]],"id":52385898},{"atb":[[13.5,5],[28,0]],"id":52385900},{"atl":[[70,2.7],[140,0],[100,0]],"id":52385900},{"atb":[[16.5,0],[9.6,0],[8.8,0]],"id":52385911},{"atl":[[38,0],[46,0],[29,0]],"id":52385911},{"atb":[[8,0],[12,0],[8.8,0]],"id":52385913},{"atl":[[32,0],[40,0],[22,4]],"id":52385913},{"atb":[[18.5,4],[21,0],[29,0]],"id":52385907},{"atl":[[75,2.09],[85,0],[110,0]],"id":52385907},{"atb":[[22,0],[50,0],[26,0]],"id":52385886},{"atl":[[170,0],[180,0],[220,0]],"id":52385886},{"atb":[[36,0],[24,0],[28,0]],"id":52385921},{"atl":[[85,0],[90,0],[120,0]],"id":52385921},{"atb":[[16,0],[18,0],[30,0]],"id":52385882},{"atl":[[70,0],[75,0],[95,0]],"id":52385882},{"atb":[[16,0],[18,0],[28,0]],"id":52385884},{"atl":[[65,0],[70,0],[90,0]],"id":52385884},{"atb":[[38,0],[30,0]],"id":52385917},{"atl":[[180,0],[220,0]],"id":52385917},{"atb":[[9.6,0],[19,0],[8.8,0]],"id":52385897},{"atl":[[34,3.27],[46,0],[60,0]],"id":52385897},{"atb":[[17,6],[19.5,0],[15,0]],"id":52385891},{"atl":[[70,0],[48,0],[50,0]],"id":52385891},{"atb":[[40,0],[23,0],[27,0]],"id":52385893},{"atl":[[130,0],[140,0],[180,0]],"id":52385893},{"atb":[[8,0],[8.8,0],[15.5,5]],"id":52385903},{"atl":[[36,0],[46,0],[60,0]],"id":52385903},{"atb":[[9.6,0],[11,10],[14,0]],"id":52385905},{"atl":[[36,0],[44,0],[30,3]],"id":52385905},{"atb":[[10,11],[6.6,0],[5.9,0]],"id":52385899},{"atl":[[17.5,0],[25,0],[29,0]],"id":52385899}],"con":true,"img":false}]}
{"op":"mcm","clk":"11550561070","pt":1719500014341,"mc":[{"id":"1.230178171","rc":[{"atb":[[23,4.55],[26,0]],"id":52385918},{"atl":[[100,0],[500,2]],"id":52385885}],"con":true,"img":false}]}
{"op":"mcm","clk":"11550561074","pt":1719500014393,"mc":[{"id":"1.230178171","rc":[{"atb":[[9.6,0],[10,11.11]],"id":52385914},{"atl":[[80,2],[85,0]],"id":52385896},{"atb":[[7.8,0],[8.4,13.51]],"id":52385904},{"atl":[[270,2],[290,0]],"id":52385921},{"atb":[[4.9,0],[5.2,23.81]],"id":52385899}],"con":true,"img":false}]}
{"op":"mcm","clk":"11550561082","pt":1719500014498,"mc":[{"id":"1.230178171","rc":[{"atb":[[23,0],[9.4,11.9]],"id":52385918}],"con":true,"img":false}]}
{"op":"mcm","clk":"11550561088","pt":1719500014601,"mc":[{"id":"1.230178171","rc":[{"atb":[[24,4]],"id":52385918},{"atb":[[12,8]],"id":52385914}],"con":true,"img":false}]}
{"op":"mcm","clk":"11550561195","pt":1719500016712,"mc":[{"id":"1.230178171","rc":[{"atb":[[14,0]],"id":52385900}],"con":true,"img":false}]}
{"op":"mcm","clk":"11550561206","pt":1719500016921,"mc":[{"id":"1.230178171","rc":[{"atb":[[13,0]],"id":52385910},{"atb":[[13,0]],"id":52385896},{"atb":[[20,0]],"id":52385919},{"atb":[[13,0]],"id":52385903}],"con":true,"img":false}]}
{"op":"mcm","clk":"11550561213","pt":1719500017024,"mc":[{"id":"1.230178171","rc":[{"atb":[[14,8]],"id":52385910},{"atl":[[65,0],[430,2]],"id":52385910},{"atb":[[14,15.3]],"id":52385896},{"atb":[[8.4,13.51],[15,5]],"id":52385919},{"atb":[[16,8]],"id":52385903},{"atl":[[470,2]],"id":52385903}],"con":true,"img":false}]}
{"op":"mcm","clk":"11550561219","pt":1719500017125,"mc":[{"id":"1.230178171","rc":[{"atb":[[21,0],[8.4,0],[15.5,6.9]],"id":52385919},{"atl":[[85,0]],"id":52385903}],"con":true,"img":false}]}
{"op":"mcm","clk":"11550561267","pt":1719500017948,"mc":[{"id":"1.230178171","rc":[{"atb":[[13.5,0]],"id":52385910},{"atb":[[9.6,0]],"id":52385912},{"atl":[[23,0]],"id":52385912},{"atl":[[23,0]],"id":52385906},{"atb":[[18,0]],"id":52385889},{"atl":[[50,0]],"id":52385914},{"atb":[[30,0]],"id":52385883},{"atb":[[19.5,0]],"id":52385885},{"atb":[[14,11]],"id":52385896},{"atb":[[15.5,0]],"id":52385890},{"atl":[[55,0]],"id":52385890},{"atb":[[16.5,0]],"id":52385892},{"atb":[[12,0]],"id":52385904},{"atl":[[40,0]],"id":52385904},{"atb":[[13.5,0]],"id":52385900},{"atl":[[70,0]],"id":52385900},{"atb":[[12.5,0]],"id":52385911},{"atl":[[22,0]],"id":52385913},{"atb":[[18.5,0]],"id":52385907},{"atl":[[75,0]],"id":52385907},{"atb":[[36,2]],"id":52385886},{"atb":[[25,0]],"id":52385921},{"atb":[[18.5,0]],"id":52385882},{"atb":[[27,0]],"id":52385884},{"atb":[[32,0]],"id":52385917},{"atb":[[12.5,0]],"id":52385897},{"atl":[[34,0]],"id":52385897},{"atb":[[19,0]],"id":52385891},{"atb":[[24,0]],"id":52385893},{"atb":[[15.5,0]],"id":52385903},{"atb":[[9.8,0]],"id":52385905},{"atl":[[18,0]],"id":52385899}],"con":true,"img":false}]}
{"op":"mcm","clk":"11550561276","pt":1719500018000,"mc":[{"id":"1.230178171","rc":[{"atl":[[510,2]],"id":52385889},{"atl":[[520,2]],"id":52385897},{"atl":[[42,0]],"id":52385899}],"con":true,"img":false}]}
{"op":"mcm","clk":"11550561280","pt":1719500018102,"mc":[{"id":"1.230178171","rc":[{"atb":[[8.8,4.37]],"id":52385912},{"atl":[[75,0],[28,2.64],[450,2]],"id":52385912},{"atl":[[36,0],[330,2],[28,4]],"id":52385906},{"atl":[[110,0]],"id":52385889},{"atl":[[570,2],[170,0]],"id":52385914},{"atl":[[600,2],[200,0]],"id":52385883},{"atl":[[540,2]],"id":52385890},{"atl":[[70,0],[440,2]],"id":52385892},{"atl":[[520,2]],"id":52385904},{"atb":[[9.2,6]],"id":52385898},{"atb":[[6,22],[12.5,0]],"id":52385900},{"atl":[[300,0],[700,2]],"id":52385900},{"atl":[[90,0],[480,2]],"id":52385911},{"atb":[[5.6,7]],"id":52385913},{"atl":[[420,2],[28,3],[60,0]],"id":52385913},{"atb":[[12,0],[6,22]],"id":52385907},{"atl":[[260,0],[660,2]],"id":52385907},{"atb":[[7.4,15.62],[25,0]],"id":52385886},{"atl":[[900,2],[500,0]],"id":52385886},{"atb":[[10.5,0],[6,22]],"id":52385921},{"atb":[[11,0],[6,22]],"id":52385882},{"atl":[[620,2],[220,0]],"id":52385882},{"atl":[[590,2],[190,0]],"id":52385884},{"atb":[[7.6,15.15],[28,0]],"id":52385917},{"atl":[[120,0]],"id":52385897},{"atl":[[130,0],[530,2]],"id":52385891},{"atb":[[18.5,0],[6,22]],"id":52385893},{"atl":[[410,0],[810,2]],"id":52385893},{"atb":[[11.5,4]],"id":52385905},{"atl":[[360,2],[26,3.4]],"id":52385899}],"con":true,"img":false}]}
{"op":"mcm","clk":"11550561285","pt":1719500018207,"mc":[{"id":"1.230178171","rc":[{"atl":[[140,0]],"id":52385890},{"atl":[[120,0]],"id":52385904},{"atb":[[4.5,28.57]],"id":52385900},{"atb":[[6,2],[4.4,29.41]],"id":52385907},{"atb":[[36,0]],"id":52385886},{"atb":[[6,2],[4.4,29.41]],"id":52385921},{"atb":[[6,2],[4.2,31.25]],"id":52385882},{"atb":[[6,2],[5.7,21.28]],"id":52385893}],"con":true,"img":false}]}
{"op":"mcm","clk":"11550561294","pt":1719500018309,"mc":[{"id":"1.230178171","rc":[{"atl":[[75,2]],"id":52385912},{"atl":[[36,2.86]],"id":52385906},{"atb":[[6,2]],"id":52385900},{"atl":[[420,0],[60,2]],"id":52385913},{"atl":[[42,2.44]],"id":52385899}],"con":true,"img":false}]}
{"op":"mcm","clk":"11550561303","pt":1719500018414,"mc":[{"id":"1.230178171","rc":[{"atl":[[450,0]],"id":52385912},{"atl":[[330,0]],"id":52385906},{"atl":[[360,0]],"id":52385899}],"con":true,"img":false}]}
{"op":"mcm","clk":"11550561317","pt":1719500018620,"mc":[{"id":"1.230178171","rc":[{"atb":[[12,8]],"id":52385900},{"atb":[[15,6]],"id":52385907},{"atb":[[20,5]],"id":52385886},{"atb":[[11,9]],"id":52385921},{"atb":[[16,6]],"id":52385882},{"atb":[[17,6]],"id":52385917},{"atb":[[20,5]],"id":52385893}],"con":true,"img":false}]}
{"op":"mcm","clk":"11550561322","pt":1719500018721,"mc":[{"id":"1.230178171","rc":[{"atb":[[4.5,0],[12.5,8]],"id":52385900},{"atb":[[12,9.09],[4.4,0]],"id":52385907},{"atb":[[21,5],[7.4,0]],"id":52385886},{"atb":[[11.5,9],[4.4,0]],"id":52385921},{"atb":[[11,10],[4.2,0]],"id":52385882},{"atb":[[17.5,6],[7.6,0]],"id":52385917},{"atb":[[18.5,5.71],[5.7,0],[29,5.18]],"id":52385893}],"con":true,"img":false}]}
{"op":"mcm","clk":"11550561331","pt":1719500018926,"mc":[{"id":"1.230178171","rc":[{"atb":[[9,0]],"id":52385898},{"atb":[[11,0]],"id":52385905}],"con":true,"img":false}]}
{"op":"mcm","clk":"11550561336","pt":1719500019028,"mc":[{"id":"1.230178171","rc":[{"atb":[[10,11]],"id":52385898},{"atb":[[13,10]],"id":52385905}],"con":true,"img":false}]}
{"op":"mcm","clk":"11550561350","pt":1719500019237,"mc":[{"id":"1.230178171","rc":[{"atb":[[29,0]],"id":52385893}],"con":true,"img":false}]}
{"op":"mcm","clk":"11550561362","pt":1719500019440,"mc":[{"id":"1.230178171","rc":[{"atb":[[24,4.35],[26,0]],"id":52385920},{"atb":[[11.5,9.52]],"id":52385900},{"atb":[[17.5,6.06],[18.5,0]],"id":52385893}],"con":true,"img":false}]}
{"op":"mcm","clk":"11550561367","pt":1719500019492,"mc":[{"id":"1.230178171","rc":[{"atb":[[6.8,17.24]],"id":52385920},{"atb":[[9.6,11.63],[10,0]],"id":52385914},{"atl":[[80,0],[460,2]],"id":52385896},{"atb":[[12.5,0]],"id":52385900}],"con":true,"img":false}]}
{"op":"mcm","clk":"11550561374","pt":1719500019595,"mc":[{"id":"1.230178171","rc":[{"atb":[[24,0]],"id":52385920}],"con":true,"img":false}]}
{"op":"mcm","clk":"11550561426","pt":1719500020621,"mc":[{"id":"1.230178171","rc":[{"atb":[[12,8]],"id":52385920}],"con":true,"img":false}]}
{"op":"mcm","clk":"11550561436","pt":1719500020725,"mc":[{"id":"1.230178171","rc":[{"atb":[[6.8,0],[12.5,8]],"id":52385920}],"con":true,"img":false}]}
{"op":"mcm","clk":"11550561467","pt":1719500021342,"mc":[{"id":"1.230178171","rc":[{"atb":[[25,4],[9.4,0]],"id":52385918}],"con":true,"img":false}]}
{"op":"mcm","clk":"11550561664","pt":1719500024638,"mc":[{"id":"1.230178171","rc":[{"atb":[[24,0]],"id":52385918},{"atb":[[12,0]],"id":52385914}],"con":true,"img":false}]}
{"op":"mcm","clk":"11550561673","pt":1719500024742,"mc":[{"id":"1.230178171","rc":[{"atb":[[16,4],[9,12.5],[25,0]],"id":52385918},{"atb":[[11,8],[6,22]],"id":52385914}],"con":true,"img":false}]}
{"op":"mcm","clk":"11550561682","pt":1719500024844,"mc":[{"id":"1.230178171","rc":[{"atb":[[9.6,0]],"id":52385914}],"con":true,"img":false}]}
{"op":"mcm","clk":"11550561951","pt":1719500028612,"mc":[{"id":"1.230178171","rc":[{"atb":[[11,0]],"id":52385921}],"con":true,"img":false}]}
{"op":"mcm","clk":"11550561958","pt":1719500028717,"mc":[{"id":"1.230178171","rc":[{"atb":[[12,9]],"id":52385921}],"con":true,"img":false}]}
{"op":"mcm","clk":"11550561962","pt":1719500028818,"mc":[{"id":"1.230178171","rc":[{"atb":[[6,22]],"id":52385921}],"con":true,"img":false}]}
{"op":"mcm","clk":"11550561964","pt":1719500028920,"mc":[{"id":"1.230178171","rc":[{"atb":[[11.5,0]],"id":52385921}],"con":true,"img":false}]}
{"op":"mcm","clk":"11550561969","pt":1719500029024,"mc":[{"id":"1.230178171","rc":[{"atb":[[11.5,9.52],[6,2]],"id":52385921}],"con":true,"img":false}]}
{"op":"mcm","clk":"11550562075","pt":1719500030717,"mc":[{"id":"1.230178171","rc":[{"atb":[[12,0]],"id":52385920}],"con":true,"img":false}]}
{"op":"mcm","clk":"11550562081","pt":1719500030822,"mc":[{"id":"1.230178171","rc":[{"atb":[[15,8]],"id":52385920}],"con":true,"img":false}]}
{"op":"mcm","clk":"11550562088","pt":1719500030921,"mc":[{"id":"1.230178171","rc":[{"atb":[[6.8,17.24],[12.5,0]],"id":52385920}],"con":true,"img":false}]}
{"op":"mcm","clk":"11550562113","pt":1719500031438,"mc":[{"id":"1.230178171","rc":[{"atb":[[16.5,4],[9,0]],"id":52385918},{"atb":[[9.6,11.63],[6,2]],"id":52385914}],"con":true,"img":false}]}
{"op":"mcm","clk":"11550562130","pt":1719500031644,"mc":[{"id":"1.230178171","rc":[{"atb":[[20,0]],"id":52385893}],"con":true,"img":false}]}
{"op":"mcm","clk":"11550562135","pt":1719500031748,"mc":[{"id":"1.230178171","rc":[{"atb":[[17.5,0],[18,5],[6,22]],"id":52385893}],"con":true,"img":false}]}
{"op":"mcm","clk":"11550562142","pt":1719500031951,"mc":[{"id":"1.230178171","rc":[{"atb":[[5.5,22.22],[6,2]],"id":52385893}],"con":true,"img":false}]}
{"op":"mcm","clk":"11550562231","pt":1719500033757,"mc":[{"id":"1.230178171","rc":[{"atb":[[10.5,2.5],[9.4,5]],"id":52385912},{"atl":[[38,2.5],[46,5]],"id":52385912},{"atl":[[85,2]],"id":52385906},{"atb":[[17,12],[12.5,5],[14.5,2.5]],"id":52385918},{"atl":[[80,5],[60,2.5],[990,0.61]],"id":52385918},{"atb":[[4.3,30.3]],"id":52385889},{"atl":[[530,2]],"id":52385889},{"atb":[[9.6,0]],"id":52385914},{"atl":[[570,0]],"id":52385914},{"atb":[[18.5,8]],"id":52385883},{"atl":[[590,1.02]],"id":52385883},{"atb":[[8,5],[8.8,2.5],[14,55]],"id":52385896},{"atl":[[44,2.5],[55,5],[450,1.34]],"id":52385896},{"atb":[[17.5,8]],"id":52385890},{"atl":[[980,0.61]],"id":52385890},{"atb":[[10.5,5],[12.5,2.5]],"id":52385904},{"atl":[[85,2.5],[110,5]],"id":52385904},{"atb":[[10.5,2.5],[9.4,5]],"id":52385900},{"atl":[[38,2.5],[46,5]],"id":52385900},{"atb":[[14.5,8]],"id":52385911},{"atl":[[470,1.28]],"id":52385911},{"atb":[[10.5,10]],"id":52385913},{"atl":[[110,2],[28,10.28]],"id":52385913},{"atb":[[16.5,5],[18.5,2.5],[11,0]],"id":52385882},{"atl":[[130,5],[620,0],[95,2.5]],"id":52385882},{"atb":[[21,8]],"id":52385884},{"atl":[[580,1.04]],"id":52385884},{"atb":[[13.5,5],[15.5,2.5]],"id":52385917},{"atl":[[65,2.5],[85,5]],"id":52385917},{"atb":[[10.5,2.5],[9.4,5]],"id":52385897},{"atl":[[65,5],[48,2.5]],"id":52385897},{"atb":[[13.5,14]],"id":52385905},{"atb":[[10,34.8],[7.4,2.5],[6.6,5]],"id":52385899},{"atl":[[32,2.5],[40,5],[25,23.8]],"id":52385899}],"con":true,"img":false}]}
{"op":"mcm","clk":"11550562237","pt":1719500033867,"mc":[{"id":"1.230178171","rc":[{"atb":[[5.5,0],[11.5,2.5],[9.8,5],[14.5,8]],"id":52385910},{"atl":[[65,5],[48,2.5],[430,0],[420,1.43],[510,2]],"id":52385910},{"atb":[[11.5,9.28],[1.14,198.37],[5.7,0]],"id":52385912},{"atl":[[28,11.92]],"id":52385912},{"atb":[[4.8,0],[10,13],[10.5,13.72],[12,2.5]],"id":52385906},{"atl":[[36,0],[38,2.5],[46,5],[28,17.72]],"id":52385906},{"atb":[[16.5,0]],"id":52385918},{"atl":[[690,2],[1000,0]],"id":52385918},{"atb":[[13,5],[15,10.5],[15.5,20]],"id":52385920},{"atl":[[70,5],[50,2.5],[470,1.28]],"id":52385920},{"atb":[[16.5,8],[12.5,5],[7.8,0],[14.5,2.5]],"id":52385889},{"atl":[[65,2.5],[85,5],[510,0],[500,1.2]],"id":52385889},{"atb":[[5.8,20.83],[10.5,2.5],[11.5,8],[9.4,5]],"id":52385914},{"atl":[[560,1.07],[40,2.5],[48,5],[490,2]],"id":52385914},{"atb":[[17,2.5],[11,0],[1.54,132.92],[15,5]],"id":52385883},{"atl":[[600,0],[660,2],[90,2.5],[120,5]],"id":52385883},{"atb":[[18,5],[19.5,8],[20,2.5],[7.4,0]],"id":52385885},{"atl":[[560,2],[80,5],[60,2.5],[490,1.23],[500,0]],"id":52385885},{"atb":[[6,2],[7.8,14.71]],"id":52385896},{"atl":[[430,2],[460,0]],"id":52385896},{"atb":[[10.5,5],[12.5,2.5],[9.4,0],[5.4,22.73]],"id":52385890},{"atl":[[540,0],[560,2],[80,5],[60,2.5]],"id":52385890},{"atb":[[16.5,8],[11,5],[13,2.5],[5.7,0],[2.78,56.18]],"id":52385892},{"atl":[[70,5],[50,2.5],[430,1.4],[440,0],[500,2]],"id":52385892},{"atb":[[13.5,8],[8.4,0]],"id":52385904},{"atl":[[520,0],[640,2],[980,0.61]],"id":52385904},{"atb":[[10.5,16.7],[11,2.5],[6.8,0],[9.6,5],[3.4,41.67]],"id":52385898},{"atl":[[42,2.5],[25,2.78],[50,5]],"id":52385898},{"atb":[[11.5,0],[12.5,8.48],[6.6,17.86]],"id":52385900},{"atl":[[530,2],[700,0],[690,0.87]],"id":52385900},{"atb":[[6.4,0],[1.27,67.73],[11.5,2.5],[9.8,5]],"id":52385911},{"atl":[[540,2],[75,5],[55,2.5],[480,0]],"id":52385911},{"atb":[[5.3,0],[11,5],[13,2.5]],"id":52385913},{"atl":[[42,2.5],[50,5],[60,0]],"id":52385913},{"atb":[[9.2,12.2],[12,0],[13.5,5],[15.5,10.5]],"id":52385907},{"atl":[[570,2],[75,5],[660,0],[650,0.92],[55,2.5]],"id":52385907},{"atb":[[17,5],[19,2.5],[21,0],[22,8],[11.5,9.52]],"id":52385886},{"atl":[[130,5],[95,2.5],[750,2],[890,0.67],[900,0]],"id":52385886},{"atb":[[16,14],[11.5,2.5],[7.6,15.15],[9.8,5],[15.5,0]],"id":52385919},{"atl":[[620,2],[46,2.5],[920,0.65],[930,0],[60,5]],"id":52385919},{"atb":[[5,25],[11.5,0],[7.6,2.5],[6.8,5]],"id":52385921},{"atl":[[260,2.32],[46,2.5],[60,5]],"id":52385921},{"atb":[[16.5,13],[4.9,25.64]],"id":52385882},{"atl":[[610,0.99],[690,2]],"id":52385882},{"atb":[[17.5,2.5],[9.8,0],[15.5,5]],"id":52385884},{"atl":[[590,0],[150,5],[730,2],[110,2.5]],"id":52385884},{"atb":[[17.5,0],[18,16],[7.8,14.71]],"id":52385917},{"atl":[[540,0],[530,1.13],[180,2]],"id":52385917},{"atb":[[10,11.11],[8.2,0],[12.5,8]],"id":52385897},{"atl":[[520,0],[470,2],[510,1.18]],"id":52385897},{"atb":[[16,5],[17.5,8],[9,0],[18,2.5]],"id":52385891},{"atl":[[530,0],[520,1.16],[75,2.5],[610,2],[95,5]],"id":52385891},{"atb":[[17,5],[18.5,8.28],[19,2.5]],"id":52385893},{"atl":[[65,2.5],[630,2],[85,5],[810,0],[800,0.75]],"id":52385893},{"atb":[[16.5,32],[6,2],[12,5],[14,2.5]],"id":52385903},{"atl":[[570,2],[80,5],[460,1.31],[470,0],[60,2.5]],"id":52385903},{"atb":[[6.4,0],[10,5],[12,2.5]],"id":52385905},{"atl":[[80,5],[170,2],[95,0],[60,2.5]],"id":52385905},{"atb":[[5.2,0],[3.9,34.48]],"id":52385899},{"atl":[[36,2.86],[42,0]],"id":52385899}],"con":true,"img":false}]}
{"op":"mcm","clk":"11550562245","pt":1719500034016,"mc":[{"id":"1.230178171","rc":[{"atb":[[13,8]],"id":52385918},{"atb":[[8.6,13.16]],"id":52385900},{"atb":[[10.5,10.53]],"id":52385917}],"con":true,"img":false}]}
{"op":"mcm","clk":"11550562249","pt":1719500034121,"mc":[{"id":"1.230178171","rc":[{"atb":[[17,0]],"id":52385918},{"atb":[[6.6,0]],"id":52385900},{"atb":[[7.8,0]],"id":52385917}],"con":true,"img":false}]}
{"op":"mcm","clk":"11550562261","pt":1719500034325,"mc":[{"id":"1.230178171","rc":[{"atb":[[15,10]],"id":52385918},{"atb":[[18,0]],"id":52385917}],"con":true,"img":false}]}
{"op":"mcm","clk":"11550562267","pt":1719500034427,"mc":[{"id":"1.230178171","rc":[{"atb":[[17.5,10]],"id":52385917}],"con":true,"img":false}]}
{"op":"mcm","clk":"11550562274","pt":1719500034530,"mc":[{"id":"1.230178171","rc":[{"atb":[[10,0]],"id":52385913}],"con":true,"img":false}]}
{"op":"mcm","clk":"11550562296","pt":1719500034838,"mc":[{"id":"1.230178171","rc":[{"atb":[[14,0]],"id":52385910},{"atb":[[11,0]],"id":52385912},{"atb":[[10,5]],"id":52385906},{"atb":[[11,0]],"id":52385914},{"atb":[[18,0]],"id":52385883},{"atb":[[17,0]],"id":52385890},{"atb":[[13,0]],"id":52385904},{"atb":[[10,0]],"id":52385898},{"atb":[[12,0]],"id":52385900},{"atb":[[14,0]],"id":52385911},{"atb":[[15,0]],"id":52385919},{"atb":[[12,0]],"id":52385897},{"atb":[[13,0]],"id":52385905}],"con":true,"img":false}]}
{"op":"mcm","clk":"11550562302","pt":1719500034941,"mc":[{"id":"1.230178171","rc":[{"atb":[[16,8]],"id":52385910},{"atb":[[16,10]],"id":52385912},{"atb":[[15,8]],"id":52385906},{"atb":[[12,8]],"id":52385914},{"atb":[[20,6]],"id":52385883},{"atb":[[19,8]],"id":52385890},{"atb":[[16,7]],"id":52385904},{"atb":[[14,11]],"id":52385898},{"atb":[[15,8]],"id":52385900},{"atb":[[17,6]],"id":52385911},{"atb":[[17,5]],"id":52385919},{"atb":[[15,12]],"id":52385897},{"atb":[[16,10]],"id":52385905}],"con":true,"img":false}]}
{"op":"mcm","clk":"11550562308","pt":1719500035044,"mc":[{"id":"1.230178171","rc":[{"atb":[[11.5,0],[12.5,15]],"id":52385914},{"atb":[[16,0],[17.5,15]],"id":52385919}],"con":true,"img":false}]}
{"op":"mcm","clk":"11550562344","pt":1719500035616,"mc":[{"id":"1.230178171","rc":[{"atb":[[14,7]],"id":52385913}],"con":true,"img":false}]}
{"op":"mcm","clk":"11550562449","pt":1719500037517,"mc":[{"id":"1.230178171","rc":[{"atb":[[10.5,10.53]],"id":52385920}],"con":true,"img":false}]}
{"op":"mcm","clk":"11550562453","pt":1719500037620,"mc":[{"id":"1.230178171","rc":[{"atb":[[6.8,0]],"id":52385920}],"con":true,"img":false}]}
{"op":"mcm","clk":"11550562455","pt":1719500037723,"mc":[{"id":"1.230178171","rc":[{"atb":[[15,0]],"id":52385907},{"atb":[[17,0]],"id":52385917}],"con":true,"img":false}]}
{"op":"mcm","clk":"11550562457","pt":1719500037826,"mc":[{"id":"1.230178171","rc":[{"atb":[[17,6]],"id":52385907},{"atb":[[20,6]],"id":52385917}],"con":true,"img":false}]}
{"op":"mcm","clk":"11550562463","pt":1719500037929,"mc":[{"id":"1.230178171","rc":[{"atb":[[17.5,0],[20,21]],"id":52385917}],"con":true,"img":false}]}
{"op":"mcm","clk":"11550562498","pt":1719500038546,"mc":[{"id":"1.230178171","rc":[{"atb":[[13.5,8]],"id":52385893}],"con":true,"img":false}]}
{"op":"mcm","clk":"11550562508","pt":1719500038648,"mc":[{"id":"1.230178171","rc":[{"atb":[[5.5,0]],"id":52385893}],"con":true,"img":false}]}
{"op":"mcm","clk":"11550562522","pt":1719500038856,"mc":[{"id":"1.230178171","rc":[{"atb":[[1.42,100]],"id":52385910},{"atl":[[80,0],[85,2.5],[110,5],[60,0]],"id":52385918},{"atl":[[90,5],[50,0]],"id":52385920},{"atb":[[1.25,150]],"id":52385885},{"atb":[[1.54,100]],"id":52385913},{"atl":[[65,2.5],[75,0],[85,5],[55,0]],"id":52385907},{"atl":[[130,0],[150,5],[95,0],[110,2.5]],"id":52385886},{"atl":[[70,2.5],[90,5],[46,0],[60,0]],"id":52385919},{"atb":[[12.5,15]],"id":52385921},{"atb":[[18.5,5],[10.5,0],[21,2.5],[13.5,8],[15.5,0]],"id":52385917},{"atb":[[6.2,19.23]],"id":52385891},{"atb":[[2.26,79.37]],"id":52385905}],"con":true,"img":false}]}
{"op":"mcm","clk":"11550562530","pt":1719500038958,"mc":[{"id":"1.230178171","rc":[{"atl":[[210,2],[480,0]],"id":52385920}],"con":true,"img":false}]}
{"op":"mcm","clk":"11550562535","pt":1719500039009,"mc":[{"id":"1.230178171","rc":[{"atb":[[9,12.5],[10,0]],"id":52385897}],"con":true,"img":false}]}
{"op":"mcm","clk":"11550562578","pt":1719500039631,"mc":[{"id":"1.230178171","rc":[{"atb":[[12,0]],"id":52385921}],"con":true,"img":false}]}
{"op":"mcm","clk":"11550562587","pt":1719500039735,"mc":[{"id":"1.230178171","rc":[{"atb":[[15,9]],"id":52385921}],"con":true,"img":false}]}
{"op":"mcm","clk":"11550562594","pt":1719500039838,"mc":[{"id":"1.230178171","rc":[{"atb":[[12.5,0]],"id":52385921}],"con":true,"img":false}]}
{"op":"mcm","clk":"11550562602","pt":1719500039942,"mc":[{"id":"1.230178171","rc":[{"atb":[[15,24]],"id":52385921}],"con":true,"img":false}]}
{"op":"mcm","clk":"11550562618","pt":1719500040374,"mc":[{"id":"1.230178171","rc":[{"atl":[[85,0],[60,2]],"id":52385906},{"atb":[[9.6,11.63],[4.3,0]],"id":52385889},{"atl":[[530,0],[460,2]],"id":52385889},{"atl":[[70,2],[110,0]],"id":52385913}],"con":true,"img":false}]}
{"op":"mcm","clk":"11550562626","pt":1719500040431,"mc":[{"id":"1.230178171","rc":[{"atl":[[420,3.43],[510,0]],"id":52385910},{"atb":[[5.1,24.39]],"id":52385912},{"atl":[[690,0]],"id":52385918},{"atb":[[5.8,0]],"id":52385914},{"atb":[[9.2,12.2]],"id":52385883},{"atl":[[570,2],[660,0]],"id":52385883},{"atl":[[560,0]],"id":52385885},{"atl":[[500,2]],"id":52385890},{"atb":[[2.78,0]],"id":52385892},{"atl":[[550,2]],"id":52385904},{"atb":[[8.2,13.89],[3.4,0]],"id":52385898},{"atb":[[4,33.33],[1.27,0]],"id":52385911},{"atl":[[540,0]],"id":52385911},{"atl":[[570,0],[150,2]],"id":52385907},{"atb":[[19,8.06],[11.5,0]],"id":52385886},{"atl":[[300,2]],"id":52385886},{"atb":[[13.5,8]],"id":52385919},{"atb":[[9.2,12.2],[4.9,0]],"id":52385882},{"atl":[[590,2],[690,0]],"id":52385882},{"atl":[[580,3.04],[730,0]],"id":52385884},{"atl":[[610,0]],"id":52385891},{"atl":[[570,0],[460,3.31]],"id":52385903},{"atl":[[170,0],[110,2]],"id":52385905},{"atb":[[6,28.5]],"id":52385899},{"atl":[[36,0]],"id":52385899}],"con":true,"img":false}]}
{"op":"mcm","clk":"11550562631","pt":1719500040530,"mc":[{"id":"1.230178171","rc":[{"atb":[[1.14,0]],"id":52385912},{"atl":[[300,2]],"id":52385918},{"atb":[[8.4,13.51]],"id":52385914},{"atb":[[1.54,0]],"id":52385883},{"atl":[[490,3.23]],"id":52385885},{"atb":[[11,10],[5.4,0]],"id":52385890},{"atl":[[560,0]],"id":52385890},{"atb":[[5.4,22.73]],"id":52385892},{"atl":[[430,3.4],[500,0]],"id":52385892},{"atl":[[640,0]],"id":52385904},{"atl":[[470,3.28]],"id":52385911},{"atb":[[9.2,0],[13,8.33]],"id":52385907},{"atl":[[750,0]],"id":52385886},{"atb":[[7.6,0]],"id":52385919},{"atl":[[620,0],[230,2]],"id":52385919},{"atb":[[5,0],[7.6,17.65]],"id":52385921},{"atl":[[520,3.16]],"id":52385891},{"atb":[[3.9,0]],"id":52385899},{"atl":[[32,5.73]],"id":52385899}],"con":true,"img":false}]}
{"op":"mcm","clk":"11550562642","pt":1719500040636,"mc":[{"id":"1.230178171","rc":[{"atb":[[13,0],[15.5,6.9]],"id":52385918},{"atb":[[8.6,0],[10,11.11]],"id":52385900}],"con":true,"img":false}]}
{"op":"mcm","clk":"11550562671","pt":1719500040947,"mc":[{"id":"1.230178171","rc":[{"atb":[[13,0],[13.5,5],[15,8],[15.5,22.5]],"id":52385920},{"atb":[[10,5],[10.5,0],[12,10.5],[9.4,0]],"id":52385914},{"atb":[[9.6,5],[11,2.5],[7.6,15.15],[6.8,0]],"id":52385921}],"con":true,"img":false}]}
{"op":"mcm","clk":"11550562865","pt":1719500043526,"mc":[{"id":"1.230178171","rc":[{"atb":[[16,0]],"id":52385889}],"con":true,"img":false}]}
{"op":"mcm","clk":"11550562877","pt":1719500043733,"mc":[{"id":"1.230178171","rc":[{"atl":[[28,4]],"id":52385906}],"con":true,"img":false}]}
{"op":"mcm","clk":"11550562886","pt":1719500043835,"mc":[{"id":"1.230178171","rc":[{"atb":[[15,0]],"id":52385920},{"atb":[[16,0]],"id":52385892},{"atb":[[20,0]],"id":52385886},{"atb":[[20,0]],"id":52385884},{"atb":[[16,0]],"id":52385903}],"con":true,"img":false}]}
{"op":"mcm","clk":"11550562892","pt":1719500043937,"mc":[{"id":"1.230178171","rc":[{"atb":[[1.42,0]],"id":52385910},{"atb":[[5.1,0]],"id":52385912},{"atb":[[14.5,9.91],[15.5,0]],"id":52385918},{"atb":[[20,8]],"id":52385920},{"atb":[[1.25,0]],"id":52385885},{"atb":[[14,6]],"id":52385892},{"atl":[[65,2],[90,0]],"id":52385898},{"atb":[[10,0],[9.2,12.2]],"id":52385900},{"atb":[[4,0]],"id":52385911},{"atb":[[1.54,0]],"id":52385913},{"atb":[[24,5]],"id":52385886},{"atb":[[24,6]],"id":52385884},{"atl":[[580,2],[630,0]],"id":52385893},{"atb":[[20,8]],"id":52385903}],"con":true,"img":false}]}
{"op":"mcm","clk":"11550562900","pt":1719500044041,"mc":[{"id":"1.230178171","rc":[{"atb":[[3.7,37.04]],"id":52385912},{"atb":[[16.5,0]],"id":52385889},{"atb":[[2.56,64.1]],"id":52385911}],"con":true,"img":false}]}
{"op":"mcm","clk":"11550562906","pt":1719500044146,"mc":[{"id":"1.230178171","rc":[{"atb":[[10.5,0],[13,8.33]],"id":52385920},{"atb":[[16,10]],"id":52385889}],"con":true,"img":false}]}
{"op":"mcm","clk":"11550562912","pt":1719500044245,"mc":[{"id":"1.230178171","rc":[{"atl":[[28,3]],"id":52385913}],"con":true,"img":false}]}
{"op":"mcm","clk":"11550562921","pt":1719500044350,"mc":[{"id":"1.230178171","rc":[{"atb":[[16,0]],"id":52385889},{"atl":[[40,15.38]],"id":52385913}],"con":true,"img":false}]}
{"op":"mcm","clk":"11550562928","pt":1719500044452,"mc":[{"id":"1.230178171","rc":[{"atb":[[15.5,10]],"id":52385889}],"con":true,"img":false}]}
{"op":"mcm","clk":"11550562952","pt":1719500044762,"mc":[{"id":"1.230178171","rc":[{"atb":[[12,2.5]],"id":52385914},{"atb":[[19,0]],"id":52385890},{"atb":[[17,0]],"id":52385911},{"atb":[[17,0]],"id":52385919},{"atb":[[15,0]],"id":52385897}],"con":true,"img":false}]}
{"op":"mcm","clk":"11550562961","pt":1719500044865,"mc":[{"id":"1.230178171","rc":[{"atb":[[8.8,0]],"id":52385912},{"atb":[[5.9,0]],"id":52385906},{"atl":[[28,0]],"id":52385906},{"atb":[[13,8]],"id":52385914},{"atb":[[16,8]],"id":52385890},{"atb":[[9.2,0]],"id":52385898},{"atl":[[25,0.43]],"id":52385898},{"atb":[[15,6]],"id":52385911},{"atb":[[5.6,0]],"id":52385913},{"atb":[[20,5]],"id":52385919},{"atb":[[13,12]],"id":52385897},{"atb":[[11.5,0]],"id":52385905},{"atl":[[30,0]],"id":52385905},{"atb":[[6,22]],"id":52385899},{"atl":[[26,0]],"id":52385899}],"con":true,"img":false}]}
{"op":"mcm","clk":"11550562967","pt":1719500044966,"mc":[{"id":"1.230178171","rc":[{"atl":[[29,15]],"id":52385906},{"atb":[[17,0],[18,5],[19,5.56],[20,2.5]],"id":52385886},{"atb":[[12.5,0],[13.5,15]],"id":52385897},{"atl":[[55,11.11]],"id":52385905}],"con":true,"img":false}]}
{"op":"mcm","clk":"11550562972","pt":1719500045069,"mc":[{"id":"1.230178171","rc":[{"atb":[[12,4.62]],"id":52385912},{"atb":[[11,5.53]],"id":52385906},{"atl":[[36,2]],"id":52385906},{"atb":[[13,13.4]],"id":52385914},{"atl":[[40,5.5]],"id":52385914},{"atb":[[21,3.06]],"id":52385883},{"atl":[[75,2]],"id":52385883},{"atb":[[14.5,3.8]],"id":52385896},{"atl":[[44,5.04]],"id":52385896},{"atb":[[19,4]],"id":52385890},{"atl":[[50,2]],"id":52385890},{"atb":[[11,5.3],[11.5,2.5],[9.6,0],[9.8,5]],"id":52385898},{"atl":[[32,2.57],[25,0]],"id":52385898},{"atb":[[15.5,4.6]],"id":52385900},{"atl":[[44,2]],"id":52385900},{"atb":[[11.5,5.6]],"id":52385913},{"atb":[[18,3]],"id":52385919},{"atl":[[80,2]],"id":52385919},{"atb":[[11,6.06]],"id":52385897},{"atl":[[38,3.09]],"id":52385897},{"atb":[[14,4.33]],"id":52385905},{"atl":[[40,2.53]],"id":52385905},{"atb":[[10.5,5]],"id":52385899},{"atl":[[24,2.9]],"id":52385899}],"con":true,"img":false}]}
{"op":"mcm","clk":"11550562979","pt":1719500045121,"mc":[{"id":"1.230178171","rc":[{"atl":[[29,0]],"id":52385906},{"atl":[[85,2]],"id":52385914},{"atl":[[60,2]],"id":52385896},{"atl":[[530,0],[110,2]],"id":52385900},{"atl":[[75,2],[470,0]],"id":52385897}],"con":true,"img":false}]}
{"op":"mcm","clk":"11550562985","pt":1719500045225,"mc":[{"id":"1.230178171","rc":[{"atl":[[490,0]],"id":52385914},{"atl":[[430,0]],"id":52385896},{"atl":[[30,10.14]],"id":52385898}],"con":true,"img":false}]}
{"op":"mcm","clk":"11550562991","pt":1719500045333,"mc":[{"id":"1.230178171","rc":[{"atl":[[34,10]],"id":52385906},{"atb":[[9,12.5]],"id":52385891},{"atb":[[3.1,47.62],[2.26,0]],"id":52385905}],"con":true,"img":false}]}
{"op":"mcm","clk":"11550562997","pt":1719500045432,"mc":[{"id":"1.230178171","rc":[{"atb":[[6.2,0]],"id":52385891}],"con":true,"img":false}]}
{"op":"mcm","clk":"11550563011","pt":1719500045636,"mc":[{"id":"1.230178171","rc":[{"atb":[[14,44]],"id":52385896},{"atb":[[10,23.8]],"id":52385899}],"con":true,"img":false}]}
{"op":"mcm","clk":"11550563021","pt":1719500045746,"mc":[{"id":"1.230178171","rc":[{"atb":[[17,11]],"id":52385896},{"atb":[[16,11]],"id":52385899}],"con":true,"img":false}]}
{"op":"mcm","clk":"11550563074","pt":1719500046668,"mc":[{"id":"1.230178171","rc":[{"atb":[[16,6]],"id":52385889}],"con":true,"img":false}]}
{"op":"mcm","clk":"11550563088","pt":1719500046925,"mc":[{"id":"1.230178171","rc":[{"atl":[[570,0],[170,2]],"id":52385883},{"atl":[[95,2],[500,0]],"id":52385890},{"atb":[[9.2,0],[11,10]],"id":52385882},{"atb":[[17,0]],"id":52385891},{"atb":[[18,0]],"id":52385893}],"con":true,"img":false}]}
{"op":"mcm","clk":"11550563095","pt":1719500047028,"mc":[{"id":"1.230178171","rc":[{"atb":[[9,12.5],[8.4,0]],"id":52385914},{"atb":[[6,22],[5.4,0]],"id":52385892},{"atl":[[190,2],[230,0]],"id":52385919},{"atb":[[19,6]],"id":52385891},{"atb":[[20,5]],"id":52385893}],"con":true,"img":false}]}
{"op":"mcm","clk":"11550563139","pt":1719500047851,"mc":[{"id":"1.230178171","rc":[{"atb":[[28,13]],"id":52385918},{"atl":[[80,7.59]],"id":52385918},{"atb":[[29,16.12]],"id":52385883},{"atl":[[70,8.7]],"id":52385883},{"atl":[[42,14.63]],"id":52385896},{"atb":[[19.5,18]],"id":52385890},{"atl":[[42,14.63]],"id":52385890},{"atb":[[17,16.56]],"id":52385911},{"atl":[[50,12.24]],"id":52385911},{"atb":[[14.5,17.2]],"id":52385913},{"atb":[[25,16.08]],"id":52385884},{"atl":[[100,6.06]],"id":52385884},{"atb":[[16.5,28.66]],"id":52385905},{"atl":[[23,27.27]],"id":52385899}],"con":true,"img":false}]}
{"op":"mcm","clk":"11550563145","pt":1719500047956,"mc":[{"id":"1.230178171","rc":[{"atb":[[21,16.86]],"id":52385910},{"atl":[[46,13.33]],"id":52385910},{"atb":[[16.5,28.56]],"id":52385912},{"atb":[[15,24.06]],"id":52385906},{"atl":[[300,0],[250,2]],"id":52385918},{"atb":[[28,20]],"id":52385920},{"atl":[[65,9.38]],"id":52385920},{"atb":[[16.5,15]],"id":52385889},{"atl":[[60,10.17]],"id":52385889},{"atb":[[14,21]],"id":52385914},{"atl":[[38,16.22]],"id":52385914},{"atb":[[23,16.46]],"id":52385885},{"atl":[[55,11.11]],"id":52385885},{"atb":[[17,16.8]],"id":52385892},{"atl":[[38,16.22]],"id":52385892},{"atb":[[16.5,15]],"id":52385904},{"atl":[[55,11.11]],"id":52385904},{"atb":[[14.5,15.74]],"id":52385898},{"atl":[[28,15.74]],"id":52385898},{"atb":[[17.5,19.2]],"id":52385900},{"atl":[[36,17.14]],"id":52385900},{"atl":[[100,2],[470,1.28]],"id":52385911},{"atb":[[26,20]],"id":52385907},{"atl":[[60,10.17]],"id":52385907},{"atb":[[44,13.95]],"id":52385886},{"atl":[[100,6.06]],"id":52385886},{"atb":[[23,16]],"id":52385919},{"atl":[[65,9.38]],"id":52385919},{"atl":[[44,13.95]],"id":52385921},{"atb":[[32,15]],"id":52385882},{"atl":[[90,6.74]],"id":52385882},{"atl":[[580,1.04],[230,2]],"id":52385884},{"atb":[[22,15]],"id":52385917},{"atl":[[60,10.17]],"id":52385917},{"atl":[[29,21.43]],"id":52385897},{"atb":[[19.5,16.32]],"id":52385891},{"atl":[[70,8.7]],"id":52385891},{"atb":[[28,15]],"id":52385893},{"atl":[[60,10.17]],"id":52385893},{"atb":[[21,16.62]],"id":52385903},{"atl":[[50,12.24]],"id":52385903}],"con":true,"img":false}]}
{"op":"mcm","clk":"11550563147","pt":1719500048057,"mc":[{"id":"1.230178171","rc":[{"atl":[[85,2],[420,1.43]],"id":52385910},{"atb":[[10.5,0]],"id":52385906},{"atb":[[15,0]],"id":52385918},{"atl":[[990,0]],"id":52385918},{"atl":[[170,2],[210,0],[470,0]],"id":52385920},{"atl":[[80,2],[460,0]],"id":52385889},{"atb":[[18.5,0]],"id":52385883},{"atl":[[590,0]],"id":52385883},{"atl":[[490,1.23],[120,2]],"id":52385885},{"atl":[[450,0]],"id":52385896},{"atb":[[17.5,0]],"id":52385890},{"atl":[[980,0]],"id":52385890},{"atl":[[65,2],[430,1.4]],"id":52385892},{"atl":[[550,0],[140,2]],"id":52385904},{"atb":[[14.5,0]],"id":52385911},{"atl":[[470,0]],"id":52385911},{"atb":[[10.5,0]],"id":52385913},{"atl":[[650,0]],"id":52385907},{"atb":[[17.5,0]],"id":52385919},{"atl":[[270,0],[85,2]],"id":52385921},{"atl":[[590,0],[190,2]],"id":52385882},{"atb":[[21,0]],"id":52385884},{"atl":[[580,0]],"id":52385884},{"atb":[[20,6]],"id":52385917},{"atl":[[530,0]],"id":52385917},{"atl":[[520,1.16],[110,2]],"id":52385891},{"atl":[[110,2],[460,0]],"id":52385903},{"atb":[[13.5,0]],"id":52385905},{"atl":[[25,0]],"id":52385899}],"con":true,"img":false}]}
{"op":"mcm","clk":"11550563151","pt":1719500048163,"mc":[{"id":"1.230178171","rc":[{"atb":[[14.5,0]],"id":52385910},{"atl":[[420,0]],"id":52385910},{"atb":[[11.5,0]],"id":52385912},{"atb":[[15.5,2.5]],"id":52385920},{"atb":[[15.5,0]],"id":52385889},{"atl":[[500,0]],"id":52385889},{"atb":[[12.5,0]],"id":52385914},{"atl":[[560,0]],"id":52385914},{"atb":[[19.5,0]],"id":52385885},{"atl":[[490,0]],"id":52385885},{"atb":[[16.5,0]],"id":52385892},{"atl":[[430,0]],"id":52385892},{"atb":[[13.5,0]],"id":52385904},{"atl":[[980,0]],"id":52385904},{"atb":[[10.5,0]],"id":52385898},{"atl":[[30,0]],"id":52385898},{"atb":[[12.5,0]],"id":52385900},{"atl":[[690,0]],"id":52385900},{"atb":[[15.5,2.5]],"id":52385907},{"atb":[[22,0]],"id":52385886},{"atl":[[890,0]],"id":52385886},{"atl":[[920,0]],"id":52385919},{"atl":[[260,0]],"id":52385921},{"atb":[[16.5,5]],"id":52385882},{"atl":[[610,0]],"id":52385882},{"atl":[[510,0]],"id":52385897},{"atb":[[17.5,0]],"id":52385891},{"atl":[[520,0]],"id":52385891},{"atb":[[18.5,0]],"id":52385893},{"atl":[[800,0]],"id":52385893},{"atb":[[16.5,0]],"id":52385903}],"con":true,"img":false}]}
{"op":"mcm","clk":"11550563160","pt":1719500048369,"mc":[{"id":"1.230178171","rc":[{"atb":[[13.5,0],[14,5],[15.5,0],[16,2.5]],"id":52385907}],"con":true,"img":false}]}
{"op":"mcm","clk":"11550563176","pt":1719500048625,"mc":[{"id":"1.230178171","rc":[{"atb":[[16,0]],"id":52385882}],"con":true,"img":false}]}
{"op":"mcm","clk":"11550563183","pt":1719500048732,"mc":[{"id":"1.230178171","rc":[{"atb":[[28,0]],"id":52385918},{"atb":[[28,0]],"id":52385920},{"atb":[[17.5,0]],"id":52385900},{"atb":[[23,0]],"id":52385919}],"con":true,"img":false}]}
{"op":"mcm","clk":"11550563188","pt":1719500048834,"mc":[{"id":"1.230178171","rc":[{"atb":[[16,20]],"id":52385920}],"con":true,"img":false}]}
{"op":"mcm","clk":"11550563196","pt":1719500048936,"mc":[{"id":"1.230178171","rc":[{"atb":[[16,18],[14.5,2.5],[15,7.14]],"id":52385918},{"atb":[[9.2,0],[11,10]],"id":52385883},{"atl":[[55,7],[60,0]],"id":52385896},{"atb":[[7.4,15.62]],"id":52385892},{"atb":[[16,0]],"id":52385904},{"atb":[[17,14.2]],"id":52385900},{"atb":[[17,0]],"id":52385907},{"atb":[[20,16]],"id":52385919},{"atb":[[34,18.18]],"id":52385917},{"atb":[[16,0],[14,15.44]],"id":52385905}],"con":true,"img":false}]}
{"op":"mcm","clk":"11550563200","pt":1719500049037,"mc":[{"id":"1.230178171","rc":[{"atb":[[20,4]],"id":52385918},{"atb":[[6,2]],"id":52385892},{"atb":[[19,7],[1.66,118.52]],"id":52385904},{"atb":[[20,6]],"id":52385907},{"atb":[[18,10]],"id":52385905}],"con":true,"img":false}]}
{"op":"mcm","clk":"11550563205","pt":1719500049144,"mc":[{"id":"1.230178171","rc":[{"atb":[[14.5,9.91],[15,0]],"id":52385918},{"atb":[[17,0]],"id":52385892},{"atb":[[16.5,0],[19.5,24]],"id":52385904},{"atb":[[34,0],[22,0]],"id":52385917},{"atb":[[16.5,0],[18.5,34.29],[14,4.33]],"id":52385905}],"con":true,"img":false}]}
{"op":"mcm","clk":"11550563211","pt":1719500049245,"mc":[{"id":"1.230178171","rc":[{"atb":[[14,23]],"id":52385892},{"atb":[[22,28.57]],"id":52385917}],"con":true,"img":false}]}
{"op":"mcm","clk":"11550563221","pt":1719500049452,"mc":[{"id":"1.230178171","rc":[{"atb":[[19,5],[22,31.07]],"id":52385917}],"con":true,"img":false}]}
{"op":"mcm","clk":"11550563226","pt":1719500049553,"mc":[{"id":"1.230178171","rc":[{"atb":[[18.5,0],[21,0]],"id":52385917}],"con":true,"img":false}]}
{"op":"mcm","clk":"11550563230","pt":1719500049653,"mc":[{"id":"1.230178171","rc":[{"atb":[[22,11.4]],"id":52385918},{"atb":[[14,0]],"id":52385898}],"con":true,"img":false}]}
{"op":"mcm","clk":"11550563234","pt":1719500049756,"mc":[{"id":"1.230178171","rc":[{"atb":[[13,11]],"id":52385898},{"atb":[[21,10.44]],"id":52385919}],"con":true,"img":false}]}
{"op":"mcm","clk":"11550563241","pt":1719500049858,"mc":[{"id":"1.230178171","rc":[{"atb":[[14.5,0]],"id":52385898}],"con":true,"img":false}]}
{"op":"mcm","clk":"11550563248","pt":1719500049963,"mc":[{"id":"1.230178171","rc":[{"atb":[[14,10.14]],"id":52385898}],"con":true,"img":false}]}
{"op":"mcm","clk":"11550563256","pt":1719500050064,"mc":[{"id":"1.230178171","rc":[{"atb":[[22,0]],"id":52385918},{"atb":[[21,0]],"id":52385919}],"con":true,"img":false}]}
{"op":"mcm","clk":"11550563271","pt":1719500050427,"mc":[{"id":"1.230178171","rc":[{"atl":[[170,2]],"id":52385893}],"con":true,"img":false}]}
{"op":"mcm","clk":"11550563276","pt":1719500050530,"mc":[{"id":"1.230178171","rc":[{"atb":[[2.56,0],[3.5,40]],"id":52385911},{"atl":[[580,0]],"id":52385893}],"con":true,"img":false}]}
{"op":"mcm","clk":"11550563325","pt":1719500051872,"mc":[{"id":"1.230178171","rc":[{"atb":[[15.5,36.12]],"id":52385897},{"atb":[[9,0],[11.5,9.52]],"id":52385891},{"atb":[[3.1,0],[3.35,42.55]],"id":52385905}],"con":true,"img":false}]}
{"op":"mcm","clk":"11550563335","pt":1719500052076,"mc":[{"id":"1.230178171","rc":[{"atb":[[16.5,5],[18.5,2.5],[12.5,0],[14.5,7.41]],"id":52385918},{"atl":[[38,0],[40,3],[80,5],[48,0],[60,2.5]],"id":52385914},{"atb":[[10.5,0],[11.5,2.5],[9.4,0]],"id":52385900},{"atb":[[11.5,0],[14,5],[16,2.5],[9.8,0]],"id":52385919},{"atl":[[75,2.5],[44,0],[46,0],[60,0]],"id":52385921},{"atl":[[60,0]],"id":52385917},{"atb":[[13.5,0]],"id":52385897},{"atl":[[32,3.23],[34,5],[40,0],[28,2.5]],"id":52385899}],"con":true,"img":false}]}
{"op":"mcm","clk":"11550563341","pt":1719500052179,"mc":[{"id":"1.230178171","rc":[{"atl":[[38,16.22]],"id":52385914},{"atl":[[38,0]],"id":52385892},{"atl":[[80,2],[46,13.33]],"id":52385921},{"atl":[[60,10.17]],"id":52385917},{"atl":[[50,0]],"id":52385903}],"con":true,"img":false}]}
{"op":"mcm","clk":"11550563346","pt":1719500052282,"mc":[{"id":"1.230178171","rc":[{"atl":[[48,12.77]],"id":52385892},{"atl":[[85,0],[46,0]],"id":52385921},{"atb":[[15.5,0]],"id":52385897},{"atb":[[28,0]],"id":52385893},{"atl":[[55,11.11]],"id":52385903}],"con":true,"img":false}]}
{"op":"mcm","clk":"11550563352","pt":1719500052335,"mc":[{"id":"1.230178171","rc":[{"atl":[[70,8.7]],"id":52385921},{"atb":[[9,0],[8.2,13.89],[13.5,36.12]],"id":52385897},{"atb":[[24,20]],"id":52385893}],"con":true,"img":false}]}
{"op":"mcm","clk":"11550563375","pt":1719500052771,"mc":[{"id":"1.230178171","rc":[{"atb":[[16,0]],"id":52385912}],"con":true,"img":false}]}
{"op":"mcm","clk":"11550563385","pt":1719500052879,"mc":[{"id":"1.230178171","rc":[{"atb":[[14,10]],"id":52385912}],"con":true,"img":false}]}
{"op":"mcm","clk":"11550563391","pt":1719500052978,"mc":[{"id":"1.230178171","rc":[{"atb":[[16.5,0]],"id":52385912}],"con":true,"img":false}]}
{"op":"mcm","clk":"11550563400","pt":1719500053083,"mc":[{"id":"1.230178171","rc":[{"atb":[[16,30]],"id":52385912},{"atl":[[44,5.12]],"id":52385913}],"con":true,"img":false}]}
{"op":"mcm","clk":"11550563409","pt":1719500053236,"mc":[{"id":"1.230178171","rc":[{"atl":[[44,0]],"id":52385913}],"con":true,"img":false}]}
{"op":"mcm","clk":"11550563417","pt":1719500053337,"mc":[{"id":"1.230178171","rc":[{"atl":[[38,0]],"id":52385914},{"atl":[[60,0]],"id":52385917}],"con":true,"img":false}]}
{"op":"mcm","clk":"11550563421","pt":1719500053441,"mc":[{"id":"1.230178171","rc":[{"atl":[[34,0]],"id":52385906},{"atl":[[38,16.22]],"id":52385914},{"atb":[[11,0],[14,7.69]],"id":52385882},{"atl":[[60,10.17]],"id":52385917},{"atb":[[24,0]],"id":52385893}],"con":true,"img":false}]}
{"op":"mcm","clk":"11550563426","pt":1719500053544,"mc":[{"id":"1.230178171","rc":[{"atl":[[46,0]],"id":52385910},{"atl":[[36,12]],"id":52385906},{"atl":[[55,0]],"id":52385885}],"con":true,"img":false}]}
{"op":"mcm","clk":"11550563432","pt":1719500053646,"mc":[{"id":"1.230178171","rc":[{"atl":[[50,12.24]],"id":52385910},{"atl":[[38,0]],"id":52385914},{"atl":[[60,12.67]],"id":52385885},{"atb":[[19.5,15]],"id":52385893}],"con":true,"img":false}]}
{"op":"mcm","clk":"11550563437","pt":1719500053749,"mc":[{"id":"1.230178171","rc":[{"atl":[[40,18.38]],"id":52385914},{"atb":[[1.17,0]],"id":52385919}],"con":true,"img":false}]}
{"op":"mcm","clk":"11550563454","pt":1719500053959,"mc":[{"id":"1.230178171","rc":[{"atb":[[3.95,33.9],[3.7,0]],"id":52385912},{"atb":[[13,0],[14.5,7.41]],"id":52385920},{"atb":[[9,0],[10,16.11],[23,27.27]],"id":52385914},{"atb":[[1.43,100]],"id":52385885},{"atb":[[14,0]],"id":52385896},{"atl":[[50,2.04],[55,5]],"id":52385896},{"atb":[[9,12.5],[11,0]],"id":52385890},{"atb":[[1.26,118.52],[1.66,0]],"id":52385904},{"atb":[[2.44,69.44],[3.5,0]],"id":52385911},{"atb":[[18,15],[7.6,0],[8.8,12.82]],"id":52385921},{"atl":[[80,0],[85,2]],"id":52385921},{"atb":[[36,17.14]],"id":52385917},{"atb":[[10,0]],"id":52385899},{"atl":[[32,0],[29,3.57]],"id":52385899}],"con":true,"img":false}]}
{"op":"mcm","clk":"11550563458","pt":1719500054058,"mc":[{"id":"1.230178171","rc":[{"atb":[[3.65,37.74]],"id":52385912},{"atb":[[14,0]],"id":52385914},{"atb":[[11,0],[14.5,7.41]],"id":52385883},{"atl":[[50,0],[55,7]],"id":52385896},{"atb":[[2.44,0],[2.08,92.59]],"id":52385911},{"atb":[[15,9]],"id":52385921},{"atb":[[1.16,146.46]],"id":52385884},{"atb":[[22,2.5]],"id":52385917}],"con":true,"img":false}]}
{"op":"mcm","clk":"11550563464","pt":1719500054161,"mc":[{"id":"1.230178171","rc":[{"atl":[[65,0],[70,2.5],[48,0]],"id":52385910},{"atb":[[16,9.68],[3.95,0]],"id":52385912},{"atb":[[23,0]],"id":52385914},{"atb":[[1.26,0]],"id":52385904},{"atb":[[18,0]],"id":52385921},{"atb":[[36,0]],"id":52385917}],"con":true,"img":false}]}
{"op":"mcm","clk":"11550563470","pt":1719500054265,"mc":[{"id":"1.230178171","rc":[{"atb":[[15,30]],"id":52385912},{"atl":[[36,2]],"id":52385906},{"atb":[[22,28.57]],"id":52385914},{"atb":[[17.5,22.4]],"id":52385921},{"atb":[[34,18.18]],"id":52385917}],"con":true,"img":false}]}
{"op":"mcm","clk":"11550563477","pt":1719500054368,"mc":[{"id":"1.230178171","rc":[{"atl":[[65,2.5],[70,0],[85,7],[50,0]],"id":52385910},{"atl":[[34,18.18]],"id":52385906},{"atl":[[40,3]],"id":52385914},{"atb":[[19.5,0]],"id":52385890},{"atl":[[65,0],[130,5],[85,0],[95,2.5]],"id":52385917}],"con":true,"img":false}]}
{"op":"mcm","clk":"11550563482","pt":1719500054470,"mc":[{"id":"1.230178171","rc":[{"atl":[[85,5],[95,2],[55,11.11]],"id":52385910},{"atl":[[34,0]],"id":52385906},{"atb":[[19,28]],"id":52385890},{"atl":[[60,0]],"id":52385917}],"con":true,"img":false}]}
{"op":"mcm","clk":"11550563489","pt":1719500054576,"mc":[{"id":"1.230178171","rc":[{"atl":[[490,2]],"id":52385910},{"atl":[[36,18.06]],"id":52385906},{"atb":[[17,0]],"id":52385900},{"atl":[[70,8.7]],"id":52385917}],"con":true,"img":false}]}
{"op":"mcm","clk":"11550563493","pt":1719500054678,"mc":[{"id":"1.230178171","rc":[{"atl":[[95,0]],"id":52385910},{"atl":[[40,18.38]],"id":52385914},{"atb":[[13,0]],"id":52385897}],"con":true,"img":false}]}
{"op":"mcm","clk":"11550563501","pt":1719500054784,"mc":[{"id":"1.230178171","rc":[{"atb":[[16,25.2]],"id":52385900},{"atl":[[70,0]],"id":52385917},{"atb":[[12,12]],"id":52385897}],"con":true,"img":false}]}
{"op":"mcm","clk":"11550563507","pt":1719500054890,"mc":[{"id":"1.230178171","rc":[{"atl":[[95,2],[490,0]],"id":52385910},{"atl":[[40,3]],"id":52385914},{"atl":[[75,8.11]],"id":52385917}],"con":true,"img":false}]}
{"op":"mcm","clk":"11550563525","pt":1719500055241,"mc":[{"id":"1.230178171","rc":[{"atb":[[16,0]],"id":52385912}],"con":true,"img":false}]}
{"op":"mcm","clk":"11550563545","pt":1719500055549,"mc":[{"id":"1.230178171","rc":[{"atb":[[15.5,6.9]],"id":52385918}],"con":true,"img":false}]}
{"op":"mcm","clk":"11550563551","pt":1719500055652,"mc":[{"id":"1.230178171","rc":[{"atb":[[14.5,0]],"id":52385918},{"atb":[[16,0]],"id":52385890}],"con":true,"img":false}]}
{"op":"mcm","clk":"11550563563","pt":1719500055858,"mc":[{"id":"1.230178171","rc":[{"atb":[[15,0]],"id":52385900}],"con":true,"img":false}]}
{"op":"mcm","clk":"11550563581","pt":1719500056168,"mc":[{"id":"1.230178171","rc":[{"atb":[[13,5.4]],"id":52385914},{"atb":[[17,0]],"id":52385896},{"atb":[[14,0]],"id":52385913},{"atb":[[15,0]],"id":52385921},{"atb":[[20,0]],"id":52385917},{"atb":[[16,0]],"id":52385899}],"con":true,"img":false}]}
{"op":"mcm","clk":"11550563588","pt":1719500056267,"mc":[{"id":"1.230178171","rc":[{"atb":[[14,8]],"id":52385914},{"atb":[[13,11]],"id":52385896},{"atb":[[16,7]],"id":52385913},{"atb":[[18,9]],"id":52385921},{"atb":[[24,6]],"id":52385917},{"atb":[[11,11]],"id":52385899}],"con":true,"img":false}]}
{"op":"mcm","clk":"11550563598","pt":1719500056374,"mc":[{"id":"1.230178171","rc":[{"atb":[[16.5,20],[14.5,0]],"id":52385913}],"con":true,"img":false}]}
{"op":"mcm","clk":"11550563621","pt":1719500056680,"mc":[{"id":"1.230178171","rc":[{"atb":[[16,0]],"id":52385889}],"con":true,"img":false}]}
{"op":"mcm","clk":"11550563691","pt":1719500057661,"mc":[{"id":"1.230178171","rc":[{"atb":[[19,0]],"id":52385891}],"con":true,"img":false}]}
{"op":"mcm","clk":"11550563700","pt":1719500057768,"mc":[{"id":"1.230178171","rc":[{"atb":[[19.5,0]],"id":52385891}],"con":true,"img":false}]}
{"op":"mcm","clk":"11550563711","pt":1719500057866,"mc":[{"id":"1.230178171","rc":[{"atb":[[19,15]],"id":52385891},{"atb":[[20,0]],"id":52385893}],"con":true,"img":false}]}
{"op":"mcm","clk":"11550563718","pt":1719500057971,"mc":[{"id":"1.230178171","rc":[{"atb":[[17.5,15]],"id":52385889},{"atb":[[19,0]],"id":52385891}],"con":true,"img":false}]}
{"op":"mcm","clk":"11550563733","pt":1719500058176,"mc":[{"id":"1.230178171","rc":[{"atb":[[16.5,0]],"id":52385889},{"atb":[[18,17.5]],"id":52385891}],"con":true,"img":false}]}
{"op":"mcm","clk":"11550563738","pt":1719500058277,"mc":[{"id":"1.230178171","rc":[{"atb":[[4,33.33],[3.35,0]],"id":52385905}],"con":true,"img":false}]}
{"op":"mcm","clk":"11550563762","pt":1719500058641,"mc":[{"id":"1.230178171","rc":[{"atb":[[18,22.5]],"id":52385891},{"atb":[[20,5]],"id":52385893}],"con":true,"img":false}]}
{"op":"mcm","clk":"11550563767","pt":1719500058745,"mc":[{"id":"1.230178171","rc":[{"atb":[[15,36.12]],"id":52385897},{"atl":[[40,17.91]],"id":52385905}],"con":true,"img":false}]}
{"op":"mcm","clk":"11550563780","pt":1719500058946,"mc":[{"id":"1.230178171","rc":[{"atl":[[80,7]],"id":52385890},{"atb":[[1.91,109.89]],"id":52385904},{"atb":[[2.88,53.19]],"id":52385911},{"atb":[[13.5,0]],"id":52385897},{"atl":[[55,0]],"id":52385905}],"con":true,"img":false}]}
