{"op":"mcm","clk":"11536380647","pt":1719425245583,"mc":[{"id":"1.230178315","marketDefinition":{"bspMarket":true,"turnInPlayEnabled":false,"persistenceEnabled":false,"marketBaseRate":5.0,"eventId":"33376062","eventTypeId":"4339","numberOfWinners":2,"bettingType":"ODDS","marketType":"PLACE","marketTime":"2024-06-27T14:51:00.000Z","suspendTime":"2024-06-27T14:51:00.000Z","bspReconciled":false,"complete":true,"inPlay":false,"crossMatching":false,"runnersVoidable":false,"numberOfActiveRunners":6,"betDelay":0,"status":"OPEN","runners":[{"status":"ACTIVE","sortPriority":1,"id":45375136,"name":"1. Canya Sunset"},{"status":"ACTIVE","sortPriority":2,"id":70466763,"name":"2. Takeiteasytiger"},{"status":"ACTIVE","sortPriority":3,"id":47030762,"name":"3. Dysert Rachael"},{"status":"ACTIVE","sortPriority":4,"id":46251065,"name":"4. Mustang Luca"},{"status":"ACTIVE","sortPriority":5,"id":69979804,"name":"5. Canal View Blue"},{"status":"ACTIVE","sortPriority":6,"id":63994056,"name":"6. Pyle Driver"}],"regulators":["MR_INT"],"venue":"Kinsley","countryCode":"GB","discountAllowed":false,"timezone":"Europe/London","openDate":"2024-06-27T13:36:00.000Z","version":5994643749,"name":"To Be Placed","eventName":"Kinsley 27th Jun"},"rc":[],"con":true,"img":false}]}
{"op":"mcm","clk":"11536381010","pt":1719425248523,"mc":[{"id":"1.230178315","marketDefinition":{"bspMarket":true,"turnInPlayEnabled":false,"persistenceEnabled":false,"marketBaseRate":5.0,"eventId":"33376062","eventTypeId":"4339","numberOfWinners":2,"bettingType":"ODDS","marketType":"PLACE","marketTime":"2024-06-27T14:51:00.000Z","suspendTime":"2024-06-27T14:51:00.000Z","bspReconciled":false,"complete":true,"inPlay":false,"crossMatching":false,"runnersVoidable":false,"numberOfActiveRunners":6,"betDelay":0,"status":"OPEN","runners":[{"status":"ACTIVE","sortPriority":1,"id":45375136,"name":"1. Canya Sunset"},{"status":"ACTIVE","sortPriority":2,"id":70466763,"name":"2. Takeiteasytiger"},{"status":"ACTIVE","sortPriority":3,"id":47030762,"name":"3. Dysert Rachael"},{"status":"ACTIVE","sortPriority":4,"id":46251065,"name":"4. Mustang Luca"},{"status":"ACTIVE","sortPriority":5,"id":69979804,"name":"5. Canal View Blue"},{"status":"ACTIVE","sortPriority":6,"id":63994056,"name":"6. Pyle Driver"}],"regulators":["MR_INT"],"venue":"Kinsley","countryCode":"GB","discountAllowed":true,"timezone":"Europe/London","openDate":"2024-06-27T13:36:00.000Z","version":5994643749,"name":"To Be Placed","eventName":"Kinsley 27th Jun"},"rc":[],"con":true,"img":false}]}
{"op":"mcm","clk":"11536615582","pt":1719428251411,"mc":[{"id":"1.230178315","rc":[{"atb":[[1.03,15.09]],"id":47030762},{"atl":[[990,0.84]],"id":47030762},{"spn":495.51,"spf":"NaN","id":47030762},{"atb":[[1.03,15.09]],"id":70466763},{"atl":[[1000,0.84]],"id":70466763},{"spn":500.51,"spf":"NaN","id":70466763},{"atb":[[1.03,15.09]],"id":45375136},{"atl":[[1000,0.84]],"id":45375136},{"spn":500.51,"spf":"NaN","id":45375136},{"atb":[[1.03,15.09]],"id":63994056},{"atl":[[1000,0.84]],"id":63994056},{"spn":500.51,"spf":"NaN","id":63994056},{"atb":[[1.01,45.27]],"id":69979804},{"atl":[[1000,0.84]],"id":69979804},{"spn":500.5,"spf":"NaN","id":69979804},{"atb":[[1.02,22.63]],"id":46251065},{"atl":[[1000,0.84]],"id":46251065},{"spn":500.51,"spf":"NaN","id":46251065}],"con":true,"img":false}]}
{"op":"mcm","clk":"11536837613","pt":1719431863950,"mc":[{"id":"1.230178315","rc":[{"atb":[[1.03,15.09]],"id":47030762},{"atl":[[990,0.26]],"id":47030762},{"atb":[[1.03,15.09]],"id":70466763},{"atl":[[1000,0.26]],"id":70466763},{"atb":[[1.03,15.09]],"id":45375136},{"atl":[[1000,0.26]],"id":45375136},{"atb":[[1.03,15.09]],"id":63994056},{"atl":[[1000,0.26]],"id":63994056},{"atb":[[1.01,45.28]],"id":69979804},{"atl":[[1000,0.26]],"id":69979804},{"atb":[[1.02,22.64]],"id":46251065},{"atl":[[1000,0.26]],"id":46251065}],"con":true,"img":false}]}
{"op":"mcm","clk":"11537232247","pt":1719437882516,"mc":[{"id":"1.230178315","marketDefinition":{"bspMarket":true,"turnInPlayEnabled":false,"persistenceEnabled":false,"marketBaseRate":5.0,"eventId":"33376062","eventTypeId":"4339","numberOfWinners":2,"bettingType":"ODDS","marketType":"PLACE","marketTime":"2024-06-27T14:51:00.000Z","suspendTime":"2024-06-27T14:51:00.000Z","bspReconciled":false,"complete":true,"inPlay":false,"crossMatching":false,"runnersVoidable":false,"numberOfActiveRunners":6,"betDelay":0,"status":"OPEN","runners":[{"status":"ACTIVE","sortPriority":1,"id":45375136,"name":"1. Canya Sunset"},{"status":"ACTIVE","sortPriority":2,"id":70466763,"name":"2. Takeiteasytiger"},{"status":"ACTIVE","sortPriority":3,"id":47030762,"name":"3. Dysert Rachael"},{"status":"ACTIVE","sortPriority":4,"id":46251065,"name":"4. Mustang Luca"},{"status":"ACTIVE","sortPriority":5,"id":69979804,"name":"5. Canal View Blue"},{"status":"ACTIVE","sortPriority":6,"id":63994056,"name":"6. Pyle Driver"}],"regulators":["MR_INT"],"venue":"Kinsley","countryCode":"GB","discountAllowed":true,"timezone":"Europe/London","openDate":"2024-06-27T13:36:00.000Z","version":5994643749,"name":"To Be Placed","eventName":"Kinsley 27th Jun"},"rc":[{"atb":[[1.03,15.09]],"id":47030762},{"atl":[[990,0.26]],"id":47030762},{"spn":495.51,"spf":"NaN","id":47030762},{"atb":[[1.03,15.09]],"id":70466763},{"atl":[[1000,0.26]],"id":70466763},{"spn":500.51,"spf":"NaN","id":70466763},{"atb":[[1.03,15.09]],"id":45375136},{"atl":[[1000,0.26]],"id":45375136},{"spn":500.51,"spf":"NaN","id":45375136},{"atb":[[1.03,15.09]],"id":63994056},{"atl":[[1000,0.26]],"id":63994056},{"spn":500.51,"spf":"NaN","id":63994056},{"atb":[[1.01,45.28]],"id":69979804},{"atl":[[1000,0.26]],"id":69979804},{"spn":500.5,"spf":"NaN","id":69979804},{"atb":[[1.02,22.64]],"id":46251065},{"atl":[[1000,0.26]],"id":46251065},{"spn":500.51,"spf":"NaN","id":46251065}],"con":true,"img":true}]}
{"op":"mcm","clk":"11537573374","pt":1719443282536,"mc":[{"id":"1.230178315","marketDefinition":{"bspMarket":true,"turnInPlayEnabled":false,"persistenceEnabled":false,"marketBaseRate":5.0,"eventId":"33376062","eventTypeId":"4339","numberOfWinners":2,"bettingType":"ODDS","marketType":"PLACE","marketTime":"2024-06-27T14:51:00.000Z","suspendTime":"2024-06-27T14:51:00.000Z","bspReconciled":false,"complete":true,"inPlay":false,"crossMatching":false,"runnersVoidable":false,"numberOfActiveRunners":6,"betDelay":0,"status":"OPEN","runners":[{"status":"ACTIVE","sortPriority":1,"id":45375136,"name":"1. Canya Sunset"},{"status":"ACTIVE","sortPriority":2,"id":70466763,"name":"2. Takeiteasytiger"},{"status":"ACTIVE","sortPriority":3,"id":47030762,"name":"3. Dysert Rachael"},{"status":"ACTIVE","sortPriority":4,"id":46251065,"name":"4. Mustang Luca"},{"status":"ACTIVE","sortPriority":5,"id":69979804,"name":"5. Canal View Blue"},{"status":"ACTIVE","sortPriority":6,"id":63994056,"name":"6. Pyle Driver"}],"regulators":["MR_INT"],"venue":"Kinsley","countryCode":"GB","discountAllowed":true,"timezone":"Europe/London","openDate":"2024-06-27T13:36:00.000Z","version":5994643749,"name":"To Be Placed","eventName":"Kinsley 27th Jun"},"rc":[{"atb":[[1.03,15.09]],"id":47030762},{"atl":[[990,0.26]],"id":47030762},{"spn":495.51,"spf":"NaN","id":47030762},{"atb":[[1.03,15.09]],"id":70466763},{"atl":[[1000,0.26]],"id":70466763},{"spn":500.51,"spf":"NaN","id":70466763},{"atb":[[1.03,15.09]],"id":45375136},{"atl":[[1000,0.26]],"id":45375136},{"spn":500.51,"spf":"NaN","id":45375136},{"atb":[[1.03,15.09]],"id":63994056},{"atl":[[1000,0.26]],"id":63994056},{"spn":500.51,"spf":"NaN","id":63994056},{"atb":[[1.01,45.29]],"id":69979804},{"atl":[[1000,0.26]],"id":69979804},{"spn":500.5,"spf":"NaN","id":69979804},{"atb":[[1.02,22.64]],"id":46251065},{"atl":[[1000,0.26]],"id":46251065},{"spn":500.51,"spf":"NaN","id":46251065}],"con":true,"img":true}]}
{"op":"mcm","clk":"11537954934","pt":1719448682559,"mc":[{"id":"1.230178315","marketDefinition":{"bspMarket":true,"turnInPlayEnabled":false,"persistenceEnabled":false,"marketBaseRate":5.0,"eventId":"33376062","eventTypeId":"4339","numberOfWinners":2,"bettingType":"ODDS","marketType":"PLACE","marketTime":"2024-06-27T14:51:00.000Z","suspendTime":"2024-06-27T14:51:00.000Z","bspReconciled":false,"complete":true,"inPlay":false,"crossMatching":false,"runnersVoidable":false,"numberOfActiveRunners":6,"betDelay":0,"status":"OPEN","runners":[{"status":"ACTIVE","sortPriority":1,"id":45375136,"name":"1. Canya Sunset"},{"status":"ACTIVE","sortPriority":2,"id":70466763,"name":"2. Takeiteasytiger"},{"status":"ACTIVE","sortPriority":3,"id":47030762,"name":"3. Dysert Rachael"},{"status":"ACTIVE","sortPriority":4,"id":46251065,"name":"4. Mustang Luca"},{"status":"ACTIVE","sortPriority":5,"id":69979804,"name":"5. Canal View Blue"},{"status":"ACTIVE","sortPriority":6,"id":63994056,"name":"6. Pyle Driver"}],"regulators":["MR_INT"],"venue":"Kinsley","countryCode":"GB","discountAllowed":true,"timezone":"Europe/London","openDate":"2024-06-27T13:36:00.000Z","version":5994643749,"name":"To Be Placed","eventName":"Kinsley 27th Jun"},"rc":[{"atb":[[1.03,15.09]],"id":47030762},{"atl":[[990,0.26]],"id":47030762},{"spn":495.51,"spf":"NaN","id":47030762},{"atb":[[1.03,15.09]],"id":70466763},{"atl":[[1000,0.26]],"id":70466763},{"spn":500.51,"spf":"NaN","id":70466763},{"atb":[[1.03,15.09]],"id":45375136},{"atl":[[1000,0.26]],"id":45375136},{"spn":500.51,"spf":"NaN","id":45375136},{"atb":[[1.03,15.09]],"id":63994056},{"atl":[[1000,0.26]],"id":63994056},{"spn":500.51,"spf":"NaN","id":63994056},{"atb":[[1.01,45.28]],"id":69979804},{"atl":[[1000,0.26]],"id":69979804},{"spn":500.5,"spf":"NaN","id":69979804},{"atb":[[1.02,22.64]],"id":46251065},{"atl":[[1000,0.26]],"id":46251065},{"spn":500.51,"spf":"NaN","id":46251065}],"con":true,"img":true}]}
{"op":"mcm","clk":"11538170597","pt":1719454082542,"mc":[{"id":"1.230178315","marketDefinition":{"bspMarket":true,"turnInPlayEnabled":false,"persistenceEnabled":false,"marketBaseRate":5.0,"eventId":"33376062","eventTypeId":"4339","numberOfWinners":2,"bettingType":"ODDS","marketType":"PLACE","marketTime":"2024-06-27T14:51:00.000Z","suspendTime":"2024-06-27T14:51:00.000Z","bspReconciled":false,"complete":true,"inPlay":false,"crossMatching":false,"runnersVoidable":false,"numberOfActiveRunners":6,"betDelay":0,"status":"OPEN","runners":[{"status":"ACTIVE","sortPriority":1,"id":45375136,"name":"1. Canya Sunset"},{"status":"ACTIVE","sortPriority":2,"id":70466763,"name":"2. Takeiteasytiger"},{"status":"ACTIVE","sortPriority":3,"id":47030762,"name":"3. Dysert Rachael"},{"status":"ACTIVE","sortPriority":4,"id":46251065,"name":"4. Mustang Luca"},{"status":"ACTIVE","sortPriority":5,"id":69979804,"name":"5. Canal View Blue"},{"status":"ACTIVE","sortPriority":6,"id":63994056,"name":"6. Pyle Driver"}],"regulators":["MR_INT"],"venue":"Kinsley","countryCode":"GB","discountAllowed":true,"timezone":"Europe/London","openDate":"2024-06-27T13:36:00.000Z","version":5994643749,"name":"To Be Placed","eventName":"Kinsley 27th Jun"},"rc":[{"atb":[[1.03,15.09]],"id":47030762},{"atl":[[990,0.26]],"id":47030762},{"spn":495.51,"spf":"NaN","id":47030762},{"atb":[[1.03,15.09]],"id":70466763},{"atl":[[1000,0.26]],"id":70466763},{"spn":500.51,"spf":"NaN","id":70466763},{"atb":[[1.03,15.09]],"id":45375136},{"atl":[[1000,0.26]],"id":45375136},{"spn":500.51,"spf":"NaN","id":45375136},{"atb":[[1.03,15.09]],"id":63994056},{"atl":[[1000,0.26]],"id":63994056},{"spn":500.51,"spf":"NaN","id":63994056},{"atb":[[1.01,45.29]],"id":69979804},{"atl":[[1000,0.26]],"id":69979804},{"spn":500.5,"spf":"NaN","id":69979804},{"atb":[[1.02,22.64]],"id":46251065},{"atl":[[1000,0.26]],"id":46251065},{"spn":500.51,"spf":"NaN","id":46251065}],"con":true,"img":true}]}
{"op":"mcm","clk":"11538368255","pt":1719459482571,"mc":[{"id":"1.230178315","marketDefinition":{"bspMarket":true,"turnInPlayEnabled":false,"persistenceEnabled":false,"marketBaseRate":5.0,"eventId":"33376062","eventTypeId":"4339","numberOfWinners":2,"bettingType":"ODDS","marketType":"PLACE","marketTime":"2024-06-27T14:51:00.000Z","suspendTime":"2024-06-27T14:51:00.000Z","bspReconciled":false,"complete":true,"inPlay":false,"crossMatching":false,"runnersVoidable":false,"numberOfActiveRunners":6,"betDelay":0,"status":"OPEN","runners":[{"status":"ACTIVE","sortPriority":1,"id":45375136,"name":"1. Canya Sunset"},{"status":"ACTIVE","sortPriority":2,"id":70466763,"name":"2. Takeiteasytiger"},{"status":"ACTIVE","sortPriority":3,"id":47030762,"name":"3. Dysert Rachael"},{"status":"ACTIVE","sortPriority":4,"id":46251065,"name":"4. Mustang Luca"},{"status":"ACTIVE","sortPriority":5,"id":69979804,"name":"5. Canal View Blue"},{"status":"ACTIVE","sortPriority":6,"id":63994056,"name":"6. Pyle Driver"}],"regulators":["MR_INT"],"venue":"Kinsley","countryCode":"GB","discountAllowed":true,"timezone":"Europe/London","openDate":"2024-06-27T13:36:00.000Z","version":5994643749,"name":"To Be Placed","eventName":"Kinsley 27th Jun"},"rc":[{"atb":[[1.03,15.1]],"id":47030762},{"atl":[[990,0.26]],"id":47030762},{"spn":495.51,"spf":"NaN","id":47030762},{"atb":[[1.03,15.1]],"id":70466763},{"atl":[[1000,0.26]],"id":70466763},{"spn":500.51,"spf":"NaN","id":70466763},{"atb":[[1.03,15.1]],"id":45375136},{"atl":[[1000,0.26]],"id":45375136},{"spn":500.51,"spf":"NaN","id":45375136},{"atb":[[1.03,15.1]],"id":63994056},{"atl":[[1000,0.26]],"id":63994056},{"spn":500.51,"spf":"NaN","id":63994056},{"atb":[[1.01,45.3]],"id":69979804},{"atl":[[1000,0.26]],"id":69979804},{"spn":500.5,"spf":"NaN","id":69979804},{"atb":[[1.02,22.65]],"id":46251065},{"atl":[[1000,0.26]],"id":46251065},{"spn":500.51,"spf":"NaN","id":46251065}],"con":true,"img":true}]}
{"op":"mcm","clk":"11538595381","pt":1719464882541,"mc":[{"id":"1.230178315","marketDefinition":{"bspMarket":true,"turnInPlayEnabled":false,"persistenceEnabled":false,"marketBaseRate":5.0,"eventId":"33376062","eventTypeId":"4339","numberOfWinners":2,"bettingType":"ODDS","marketType":"PLACE","marketTime":"2024-06-27T14:51:00.000Z","suspendTime":"2024-06-27T14:51:00.000Z","bspReconciled":false,"complete":true,"inPlay":false,"crossMatching":false,"runnersVoidable":false,"numberOfActiveRunners":6,"betDelay":0,"status":"OPEN","runners":[{"status":"ACTIVE","sortPriority":1,"id":45375136,"name":"1. Canya Sunset"},{"status":"ACTIVE","sortPriority":2,"id":70466763,"name":"2. Takeiteasytiger"},{"status":"ACTIVE","sortPriority":3,"id":47030762,"name":"3. Dysert Rachael"},{"status":"ACTIVE","sortPriority":4,"id":46251065,"name":"4. Mustang Luca"},{"status":"ACTIVE","sortPriority":5,"id":69979804,"name":"5. Canal View Blue"},{"status":"ACTIVE","sortPriority":6,"id":63994056,"name":"6. Pyle Driver"}],"regulators":["MR_INT"],"venue":"Kinsley","countryCode":"GB","discountAllowed":true,"timezone":"Europe/London","openDate":"2024-06-27T13:36:00.000Z","version":5994643749,"name":"To Be Placed","eventName":"Kinsley 27th Jun"},"rc":[{"atb":[[1.03,15.09]],"id":47030762},{"atl":[[990,0.26]],"id":47030762},{"spn":495.51,"spf":"NaN","id":47030762},{"atb":[[1.03,15.09]],"id":70466763},{"atl":[[1000,0.26]],"id":70466763},{"spn":500.51,"spf":"NaN","id":70466763},{"atb":[[1.03,15.09]],"id":45375136},{"atl":[[1000,0.26]],"id":45375136},{"spn":500.51,"spf":"NaN","id":45375136},{"atb":[[1.03,15.09]],"id":63994056},{"atl":[[1000,0.26]],"id":63994056},{"spn":500.51,"spf":"NaN","id":63994056},{"atb":[[1.01,45.29]],"id":69979804},{"atl":[[1000,0.26]],"id":69979804},{"spn":500.5,"spf":"NaN","id":69979804},{"atb":[[1.02,22.64]],"id":46251065},{"atl":[[1000,0.26]],"id":46251065},{"spn":500.51,"spf":"NaN","id":46251065}],"con":true,"img":true}]}
{"op":"mcm","clk":"11538905662","pt":1719471477109,"mc":[{"id":"1.230178315","rc":[{"atb":[[1.03,15.09]],"id":47030762},{"atl":[[990,0.16]],"id":47030762},{"atb":[[1.03,15.09]],"id":70466763},{"atl":[[1000,0.16]],"id":70466763},{"atb":[[1.03,15.09]],"id":45375136},{"atl":[[1000,0.16]],"id":45375136},{"atb":[[1.03,15.09]],"id":63994056},{"atl":[[1000,0.16]],"id":63994056},{"atb":[[1.01,45.29]],"id":69979804},{"atl":[[1000,0.16]],"id":69979804},{"atb":[[1.02,22.64]],"id":46251065},{"atl":[[1000,0.16]],"id":46251065}],"con":true,"img":false}]}
{"op":"mcm","clk":"11538907343","pt":1719471508878,"mc":[{"id":"1.230178315","rc":[{"atl":[[1000,1]],"id":47030762},{"atl":[[1000,1.16]],"id":70466763},{"atl":[[1000,1.16]],"id":45375136},{"atl":[[1000,1.16]],"id":63994056},{"atl":[[1000,1.16]],"id":69979804},{"atl":[[1000,1.16]],"id":46251065}],"con":true,"img":false}]}
{"op":"mcm","clk":"11538907348","pt":1719471508981,"mc":[{"id":"1.230178315","rc":[{"atb":[[1.07,2.48]],"id":47030762},{"atb":[[1.07,2.48]],"id":70466763},{"atb":[[1.07,2.48]],"id":45375136},{"atb":[[1.07,2.48]],"id":63994056},{"atb":[[1.07,2.48]],"id":69979804},{"atb":[[1.07,2.48]],"id":46251065}],"con":true,"img":false}]}
{"op":"mcm","clk":"11538907355","pt":1719471509086,"mc":[{"id":"1.230178315","rc":[{"atl":[[1000,0.48]],"id":47030762},{"atl":[[1000,0.64]],"id":70466763},{"atl":[[1000,0.64]],"id":45375136},{"atl":[[1000,0.64]],"id":63994056},{"atl":[[1000,0.64]],"id":69979804},{"atl":[[1000,0.64]],"id":46251065}],"con":true,"img":false}]}
{"op":"mcm","clk":"11538907368","pt":1719471509292,"mc":[{"id":"1.230178315","rc":[{"atl":[[1000,0]],"id":47030762},{"atl":[[1000,0.16]],"id":70466763},{"atl":[[1000,0.16]],"id":45375136},{"atl":[[1000,0.16]],"id":63994056},{"atl":[[1000,0.16]],"id":69979804},{"atl":[[1000,0.16]],"id":46251065}],"con":true,"img":false}]}
{"op":"mcm","clk":"11538907374","pt":1719471509350,"mc":[{"id":"1.230178315","rc":[{"atl":[[75,0.48]],"id":47030762},{"atl":[[75,0.48]],"id":70466763},{"atl":[[75,0.48]],"id":45375136},{"atl":[[75,0.48]],"id":63994056},{"atl":[[75,0.48]],"id":69979804},{"atl":[[75,0.48]],"id":46251065}],"con":true,"img":false}]}
{"op":"mcm","clk":"11539122528","pt":1719475682547,"mc":[{"id":"1.230178315","marketDefinition":{"bspMarket":true,"turnInPlayEnabled":false,"persistenceEnabled":false,"marketBaseRate":5.0,"eventId":"33376062","eventTypeId":"4339","numberOfWinners":2,"bettingType":"ODDS","marketType":"PLACE","marketTime":"2024-06-27T14:51:00.000Z","suspendTime":"2024-06-27T14:51:00.000Z","bspReconciled":false,"complete":true,"inPlay":false,"crossMatching":false,"runnersVoidable":false,"numberOfActiveRunners":6,"betDelay":0,"status":"OPEN","runners":[{"status":"ACTIVE","sortPriority":1,"id":45375136,"name":"1. Canya Sunset"},{"status":"ACTIVE","sortPriority":2,"id":70466763,"name":"2. Takeiteasytiger"},{"status":"ACTIVE","sortPriority":3,"id":47030762,"name":"3. Dysert Rachael"},{"status":"ACTIVE","sortPriority":4,"id":46251065,"name":"4. Mustang Luca"},{"status":"ACTIVE","sortPriority":5,"id":69979804,"name":"5. Canal View Blue"},{"status":"ACTIVE","sortPriority":6,"id":63994056,"name":"6. Pyle Driver"}],"regulators":["MR_INT"],"venue":"Kinsley","countryCode":"GB","discountAllowed":true,"timezone":"Europe/London","openDate":"2024-06-27T13:36:00.000Z","version":5994643749,"name":"To Be Placed","eventName":"Kinsley 27th Jun"},"rc":[{"atb":[[1.03,15.09],[1.07,2.48]],"id":47030762},{"atl":[[75,0.48],[990,0.16]],"id":47030762},{"spn":38.03,"spf":"NaN","id":47030762},{"atb":[[1.03,15.09],[1.07,2.48]],"id":70466763},{"atl":[[75,0.48],[1000,0.16]],"id":70466763},{"spn":38.03,"spf":"NaN","id":70466763},{"atb":[[1.03,15.09],[1.07,2.48]],"id":45375136},{"atl":[[75,0.48],[1000,0.16]],"id":45375136},{"spn":38.03,"spf":"NaN","id":45375136},{"atb":[[1.03,15.09],[1.07,2.48]],"id":63994056},{"atl":[[75,0.48],[1000,0.16]],"id":63994056},{"spn":38.03,"spf":"NaN","id":63994056},{"atb":[[1.01,45.28],[1.07,2.48]],"id":69979804},{"atl":[[75,0.48],[1000,0.16]],"id":69979804},{"spn":38.03,"spf":"NaN","id":69979804},{"atb":[[1.02,22.64],[1.07,2.48]],"id":46251065},{"atl":[[75,0.48],[1000,0.16]],"id":46251065},{"spn":38.03,"spf":"NaN","id":46251065}],"con":true,"img":true}]}
{"op":"mcm","clk":"11539336072","pt":1719479210320,"mc":[{"id":"1.230178315","rc":[{"atb":[[1.03,15.09]],"id":47030762},{"spn":38.03,"spf":"NaN","id":47030762},{"atb":[[1.03,15.09]],"id":70466763},{"spn":38.03,"spf":"NaN","id":70466763},{"atb":[[1.03,15.09]],"id":45375136},{"spn":38.03,"spf":"NaN","id":45375136},{"atb":[[1.03,15.09]],"id":63994056},{"spn":38.03,"spf":"NaN","id":63994056},{"atb":[[1.01,45.27]],"id":69979804},{"spn":38.03,"spf":"NaN","id":69979804},{"spl":[[1.71,6]],"id":46251065},{"atb":[[1.02,22.63]],"id":46251065},{"spn":1.39,"spf":1.0,"id":46251065}],"con":true,"img":false}]}
{"op":"mcm","clk":"11540325643","pt":1719493038492,"mc":[{"id":"1.230178315","marketDefinition":{"bspMarket":true,"turnInPlayEnabled":false,"persistenceEnabled":false,"marketBaseRate":5.0,"eventId":"33376062","eventTypeId":"4339","numberOfWinners":2,"bettingType":"ODDS","marketType":"PLACE","marketTime":"2024-06-27T14:51:00.000Z","suspendTime":"2024-06-27T14:51:00.000Z","bspReconciled":false,"complete":true,"inPlay":false,"crossMatching":false,"runnersVoidable":false,"numberOfActiveRunners":6,"betDelay":0,"status":"SUSPENDED","runners":[{"status":"ACTIVE","sortPriority":1,"id":45375136,"name":"1. Canya Sunset"},{"status":"ACTIVE","sortPriority":2,"id":70466763,"name":"2. Takeiteasytiger"},{"status":"ACTIVE","sortPriority":3,"id":47030762,"name":"3. Dysert Rachael"},{"status":"ACTIVE","sortPriority":4,"id":46251065,"name":"4. Mustang Luca"},{"status":"ACTIVE","sortPriority":5,"id":69979804,"name":"5. Canal View Blue"},{"status":"ACTIVE","sortPriority":6,"id":63994056,"name":"6. Pyle Driver"}],"regulators":["MR_INT"],"venue":"Kinsley","countryCode":"GB","discountAllowed":true,"timezone":"Europe/London","openDate":"2024-06-27T13:36:00.000Z","version":5995379647,"name":"To Be Placed","eventName":"Kinsley 27th Jun"},"rc":[],"con":true,"img":false}]}
{"op":"mcm","clk":"11540325668","pt":1719493038742,"mc":[{"id":"1.230178315","marketDefinition":{"bspMarket":true,"turnInPlayEnabled":false,"persistenceEnabled":false,"marketBaseRate":5.0,"eventId":"33376062","eventTypeId":"4339","numberOfWinners":2,"bettingType":"ODDS","marketType":"PLACE","marketTime":"2024-06-27T14:51:00.000Z","suspendTime":"2024-06-27T14:51:00.000Z","bspReconciled":false,"complete":true,"inPlay":false,"crossMatching":false,"runnersVoidable":false,"numberOfActiveRunners":6,"betDelay":0,"status":"SUSPENDED","runners":[{"status":"ACTIVE","sortPriority":1,"id":45375136,"name":"1. Canya Sunset"},{"status":"ACTIVE","sortPriority":2,"id":70466763,"name":"2. Takeiteasytiger"},{"status":"ACTIVE","sortPriority":3,"id":47030762,"name":"3. Dysert Rachael"},{"status":"ACTIVE","sortPriority":4,"id":46251065,"name":"4. Mustang Luca"},{"status":"ACTIVE","sortPriority":5,"id":69979804,"name":"5. Canal View Blue"},{"status":"ACTIVE","sortPriority":6,"id":63994056,"name":"6. Pyle Driver"}],"regulators":["MR_INT"],"venue":"Kinsley","countryCode":"GB","discountAllowed":true,"timezone":"Europe/London","openDate":"2024-06-27T13:36:00.000Z","version":5995379691,"name":"To Be Placed","eventName":"Kinsley 27th Jun"},"rc":[],"con":true,"img":false}]}
{"op":"mcm","clk":"11540325668","pt":1719493038742,"mc":[{"id":"1.230178315","rc":[{"atb":[[1.03,0],[1.07,0]],"id":47030762},{"atl":[[75,0],[990,0]],"id":47030762},{"atb":[[1.03,0],[1.07,0]],"id":70466763},{"atl":[[75,0],[1000,0]],"id":70466763},{"atb":[[1.03,0],[1.07,0]],"id":45375136},{"atl":[[75,0],[1000,0]],"id":45375136},{"atb":[[1.03,0],[1.07,0]],"id":63994056},{"atl":[[75,0],[1000,0]],"id":63994056},{"atb":[[1.01,0],[1.07,0]],"id":69979804},{"atl":[[75,0],[1000,0]],"id":69979804},{"atb":[[1.02,0],[1.07,0]],"id":46251065},{"atl":[[75,0],[1000,0]],"id":46251065}],"con":true,"img":false}]}
{"op":"mcm","clk":"11540325745","pt":1719493039507,"mc":[{"id":"1.230178315","marketDefinition":{"bspMarket":true,"turnInPlayEnabled":false,"persistenceEnabled":false,"marketBaseRate":5.0,"eventId":"33376062","eventTypeId":"4339","numberOfWinners":2,"bettingType":"ODDS","marketType":"PLACE","marketTime":"2024-06-27T14:51:00.000Z","suspendTime":"2024-06-27T14:51:00.000Z","bspReconciled":false,"complete":true,"inPlay":false,"crossMatching":false,"runnersVoidable":false,"numberOfActiveRunners":5,"betDelay":0,"status":"SUSPENDED","runners":[{"status":"ACTIVE","sortPriority":1,"id":45375136,"name":"1. Canya Sunset"},{"status":"ACTIVE","sortPriority":2,"id":70466763,"name":"2. Takeiteasytiger"},{"status":"ACTIVE","sortPriority":3,"id":46251065,"name":"4. Mustang Luca"},{"status":"ACTIVE","sortPriority":4,"id":69979804,"name":"5. Canal View Blue"},{"status":"ACTIVE","sortPriority":5,"id":63994056,"name":"6. Pyle Driver"},{"status":"REMOVED","sortPriority":6,"removalDate":"2024-06-27T12:57:18.000Z","id":47030762,"name":"3. Dysert Rachael"}],"regulators":["MR_INT"],"venue":"Kinsley","countryCode":"GB","discountAllowed":true,"timezone":"Europe/London","openDate":"2024-06-27T13:36:00.000Z","version":5995379691,"name":"To Be Placed","eventName":"Kinsley 27th Jun"},"rc":[],"con":true,"img":false}]}
{"op":"mcm","clk":"11540326001","pt":1719493042964,"mc":[{"id":"1.230178315","marketDefinition":{"bspMarket":true,"turnInPlayEnabled":false,"persistenceEnabled":false,"marketBaseRate":5.0,"eventId":"33376062","eventTypeId":"4339","numberOfWinners":2,"bettingType":"ODDS","marketType":"PLACE","marketTime":"2024-06-27T14:51:00.000Z","suspendTime":"2024-06-27T14:51:00.000Z","bspReconciled":false,"complete":true,"inPlay":false,"crossMatching":false,"runnersVoidable":false,"numberOfActiveRunners":6,"betDelay":0,"status":"SUSPENDED","runners":[{"status":"ACTIVE","sortPriority":1,"id":45375136,"name":"1. Canya Sunset"},{"status":"ACTIVE","sortPriority":2,"id":70466763,"name":"2. Takeiteasytiger"},{"status":"ACTIVE","sortPriority":3,"id":70940946,"name":"3. Boherduff Biker (res)"},{"status":"ACTIVE","sortPriority":4,"id":46251065,"name":"4. Mustang Luca"},{"status":"ACTIVE","sortPriority":5,"id":69979804,"name":"5. Canal View Blue"},{"status":"ACTIVE","sortPriority":6,"id":63994056,"name":"6. Pyle Driver"},{"status":"REMOVED","sortPriority":7,"removalDate":"2024-06-27T12:57:18.000Z","id":47030762,"name":"3. Dysert Rachael"}],"regulators":["MR_INT"],"venue":"Kinsley","countryCode":"GB","discountAllowed":true,"timezone":"Europe/London","openDate":"2024-06-27T13:36:00.000Z","version":5995379750,"name":"To Be Placed","eventName":"Kinsley 27th Jun"},"rc":[],"con":true,"img":false}]}
{"op":"mcm","clk":"11540326041","pt":1719493043506,"mc":[{"id":"1.230178315","marketDefinition":{"bspMarket":true,"turnInPlayEnabled":false,"persistenceEnabled":false,"marketBaseRate":5.0,"eventId":"33376062","eventTypeId":"4339","numberOfWinners":2,"bettingType":"ODDS","marketType":"PLACE","marketTime":"2024-06-27T14:51:00.000Z","suspendTime":"2024-06-27T14:51:00.000Z","bspReconciled":false,"complete":true,"inPlay":false,"crossMatching":false,"runnersVoidable":false,"numberOfActiveRunners":6,"betDelay":0,"status":"OPEN","runners":[{"status":"ACTIVE","sortPriority":1,"id":45375136,"name":"1. Canya Sunset"},{"status":"ACTIVE","sortPriority":2,"id":70466763,"name":"2. Takeiteasytiger"},{"status":"ACTIVE","sortPriority":3,"id":70940946,"name":"3. Boherduff Biker (res)"},{"status":"ACTIVE","sortPriority":4,"id":46251065,"name":"4. Mustang Luca"},{"status":"ACTIVE","sortPriority":5,"id":69979804,"name":"5. Canal View Blue"},{"status":"ACTIVE","sortPriority":6,"id":63994056,"name":"6. Pyle Driver"},{"status":"REMOVED","sortPriority":7,"removalDate":"2024-06-27T12:57:18.000Z","id":47030762,"name":"3. Dysert Rachael"}],"regulators":["MR_INT"],"venue":"Kinsley","countryCode":"GB","discountAllowed":true,"timezone":"Europe/London","openDate":"2024-06-27T13:36:00.000Z","version":5995379779,"name":"To Be Placed","eventName":"Kinsley 27th Jun"},"rc":[],"con":true,"img":false}]}
{"op":"mcm","clk":"11540327630","pt":1719493066048,"mc":[{"id":"1.230178315","rc":[{"atl":[[960,0.94]],"id":70466763},{"spn":1.0,"spf":"NaN","id":70466763},{"atl":[[960,1.32]],"id":45375136},{"spn":1.0,"spf":"NaN","id":45375136},{"atl":[[970,0.86]],"id":63994056},{"spn":1.0,"spf":"NaN","id":63994056},{"atl":[[980,0.86]],"id":69979804},{"spn":1.0,"spf":"NaN","id":69979804},{"atl":[[960,0.92]],"id":70940946},{"spn":1.0,"spf":"NaN","id":70940946},{"atl":[[990,1.47]],"id":46251065},{"spn":1.0,"spf":1.0,"id":46251065}],"con":true,"img":false}]}
{"op":"mcm","clk":"11540629336","pt":1719496639815,"mc":[{"id":"1.230178315","rc":[{"atb":[[1.01,18.42]],"id":70466763},{"atl":[[960,0.94],[1000,0.84]],"id":70466763},{"spn":480.5,"spf":"NaN","id":70466763},{"atb":[[1.03,6.14]],"id":45375136},{"atl":[[960,1.32],[990,0.84]],"id":45375136},{"spn":480.51,"spf":"NaN","id":45375136},{"atb":[[1.01,18.42]],"id":63994056},{"atl":[[970,0.86],[990,0.84]],"id":63994056},{"spn":485.5,"spf":"NaN","id":63994056},{"atb":[[1.03,6.14]],"id":69979804},{"atl":[[980,0.86],[1000,0.84]],"id":69979804},{"spn":490.51,"spf":"NaN","id":69979804},{"atb":[[1.02,9.21]],"id":70940946},{"atl":[[960,0.92],[1000,0.84]],"id":70940946},{"spn":480.51,"spf":"NaN","id":70940946},{"atb":[[1.03,6.14]],"id":46251065},{"atl":[[990,2.32]],"id":46251065},{"spn":1.37,"spf":1.0,"id":46251065}],"con":true,"img":false}]}
{"op":"mcm","clk":"11540683338","pt":1719497282514,"mc":[{"id":"1.230178315","marketDefinition":{"bspMarket":true,"turnInPlayEnabled":false,"persistenceEnabled":false,"marketBaseRate":5.0,"eventId":"33376062","eventTypeId":"4339","numberOfWinners":2,"bettingType":"ODDS","marketType":"PLACE","marketTime":"2024-06-27T14:51:00.000Z","suspendTime":"2024-06-27T14:51:00.000Z","bspReconciled":false,"complete":true,"inPlay":false,"crossMatching":false,"runnersVoidable":false,"numberOfActiveRunners":6,"betDelay":0,"status":"OPEN","runners":[{"status":"ACTIVE","sortPriority":1,"id":45375136,"name":"1. Canya Sunset"},{"status":"ACTIVE","sortPriority":2,"id":70466763,"name":"2. Takeiteasytiger"},{"status":"ACTIVE","sortPriority":3,"id":70940946,"name":"3. Boherduff Biker (res)"},{"status":"ACTIVE","sortPriority":4,"id":46251065,"name":"4. Mustang Luca"},{"status":"ACTIVE","sortPriority":5,"id":69979804,"name":"5. Canal View Blue"},{"status":"ACTIVE","sortPriority":6,"id":63994056,"name":"6. Pyle Driver"},{"status":"REMOVED","sortPriority":7,"removalDate":"2024-06-27T12:57:18.000Z","id":47030762,"name":"3. Dysert Rachael"}],"regulators":["MR_INT"],"venue":"Kinsley","countryCode":"GB","discountAllowed":true,"timezone":"Europe/London","openDate":"2024-06-27T13:36:00.000Z","version":5995379779,"name":"To Be Placed","eventName":"Kinsley 27th Jun"},"rc":[{"atb":[[1.01,18.42]],"id":70466763},{"atl":[[960,0.94],[1000,0.84]],"id":70466763},{"spn":480.5,"spf":"NaN","id":70466763},{"atb":[[1.03,6.13]],"id":45375136},{"atl":[[960,1.32],[990,0.84]],"id":45375136},{"spn":480.51,"spf":"NaN","id":45375136},{"atb":[[1.01,18.42]],"id":63994056},{"atl":[[970,0.86],[990,0.84]],"id":63994056},{"spn":485.5,"spf":"NaN","id":63994056},{"atb":[[1.03,6.13]],"id":69979804},{"atl":[[980,0.86],[1000,0.84]],"id":69979804},{"spn":490.51,"spf":"NaN","id":69979804},{"atb":[[1.02,9.21]],"id":70940946},{"atl":[[960,0.92],[1000,0.84]],"id":70940946},{"spn":480.51,"spf":"NaN","id":70940946},{"spl":[[1.71,6]],"id":46251065},{"atb":[[1.03,6.13]],"id":46251065},{"atl":[[990,2.31]],"id":46251065},{"spn":1.37,"spf":1.0,"id":46251065}],"con":true,"img":true}]}
{"op":"mcm","clk":"11540839330","pt":1719498960234,"mc":[{"id":"1.230178315","rc":[{"atb":[[1.01,18.42],[1.55,18.43]],"id":70466763},{"atl":[[17,2],[960,0.94],[1000,0.84]],"id":70466763},{"spn":9.27,"spf":"NaN","id":70466763},{"atb":[[1.03,6.13],[1.67,6.14]],"id":45375136},{"atl":[[25,2],[960,1.32],[990,0.84]],"id":45375136},{"spn":13.33,"spf":"NaN","id":45375136},{"atb":[[1.01,18.42],[1.32,18.43]],"id":63994056},{"atl":[[10.5,2],[970,0.86],[990,0.84]],"id":63994056},{"spn":5.91,"spf":"NaN","id":63994056},{"atb":[[1.41,6.14],[1.03,6.13]],"id":69979804},{"atl":[[980,0.86],[1000,0.84],[9.4,2]],"id":69979804},{"spn":5.4,"spf":"NaN","id":69979804},{"atb":[[1.03,9.21],[1.02,9.21]],"id":70940946},{"atl":[[46,2],[960,0.92],[1000,0.84]],"id":70940946},{"spn":23.51,"spf":"NaN","id":70940946},{"atb":[[1.03,6.13],[1.68,6.14]],"id":46251065},{"atl":[[20,2.32],[990,2.31]],"id":46251065},{"spn":1.69,"spf":1.0,"id":46251065}],"con":true,"img":false}]}
{"op":"mcm","clk":"11540839341","pt":1719498960290,"mc":[{"id":"1.230178315","rc":[{"atb":[[2.32,1]],"id":70466763},{"atl":[[5.5,1]],"id":70466763},{"atb":[[2.12,1]],"id":45375136},{"atl":[[5.3,1]],"id":45375136},{"atb":[[1.74,1]],"id":63994056},{"atl":[[3.9,1]],"id":63994056},{"atb":[[1.83,1]],"id":69979804},{"atl":[[4.2,1]],"id":69979804},{"atb":[[1.89,1]],"id":46251065},{"atl":[[5,1]],"id":46251065}],"con":true,"img":false}]}
{"op":"mcm","clk":"11540839352","pt":1719498960389,"mc":[{"id":"1.230178315","rc":[{"atl":[[50,1]],"id":70940946},{"atb":[[1.94,1]],"id":46251065}],"con":true,"img":false}]}
{"op":"mcm","clk":"11540839493","pt":1719498961801,"mc":[{"id":"1.230178315","rc":[{"atb":[[1.89,0]],"id":46251065}],"con":true,"img":false}]}
{"op":"mcm","clk":"11540839614","pt":1719498962936,"mc":[{"id":"1.230178315","rc":[{"atb":[[1.94,0],[1.93,1]],"id":46251065}],"con":true,"img":false}]}
{"op":"mcm","clk":"11540839687","pt":1719498963607,"mc":[{"id":"1.230178315","rc":[{"atb":[[1.58,2.11]],"id":70466763},{"atb":[[1.35,2.11]],"id":63994056}],"con":true,"img":false}]}
{"op":"mcm","clk":"11540839700","pt":1719498963710,"mc":[{"id":"1.230178315","rc":[{"atb":[[1.92,1],[1.93,0]],"id":46251065}],"con":true,"img":false}]}
{"op":"mcm","clk":"11540839879","pt":1719498965720,"mc":[{"id":"1.230178315","rc":[{"atb":[[1.92,0],[2.12,1]],"id":46251065}],"con":true,"img":false}]}
{"op":"mcm","clk":"11540839890","pt":1719498965823,"mc":[{"id":"1.230178315","rc":[{"atb":[[1.92,6.14],[1.68,0]],"id":46251065}],"con":true,"img":false}]}
{"op":"mcm","clk":"11540839901","pt":1719498965928,"mc":[{"id":"1.230178315","rc":[{"atb":[[1.92,0],[1.68,6.14]],"id":46251065}],"con":true,"img":false}]}
{"op":"mcm","clk":"11540840459","pt":1719498971669,"mc":[{"id":"1.230178315","marketDefinition":{"bspMarket":true,"turnInPlayEnabled":false,"persistenceEnabled":false,"marketBaseRate":5.0,"eventId":"33376062","eventTypeId":"4339","numberOfWinners":2,"bettingType":"ODDS","marketType":"PLACE","marketTime":"2024-06-27T14:51:00.000Z","suspendTime":"2024-06-27T14:51:00.000Z","bspReconciled":false,"complete":true,"inPlay":false,"crossMatching":true,"runnersVoidable":false,"numberOfActiveRunners":6,"betDelay":0,"status":"OPEN","runners":[{"status":"ACTIVE","sortPriority":1,"id":45375136,"name":"1. Canya Sunset"},{"status":"ACTIVE","sortPriority":2,"id":70466763,"name":"2. Takeiteasytiger"},{"status":"ACTIVE","sortPriority":3,"id":70940946,"name":"3. Boherduff Biker (res)"},{"status":"ACTIVE","sortPriority":4,"id":46251065,"name":"4. Mustang Luca"},{"status":"ACTIVE","sortPriority":5,"id":69979804,"name":"5. Canal View Blue"},{"status":"ACTIVE","sortPriority":6,"id":63994056,"name":"6. Pyle Driver"},{"status":"REMOVED","sortPriority":7,"removalDate":"2024-06-27T12:57:18.000Z","id":47030762,"name":"3. Dysert Rachael"}],"regulators":["MR_INT"],"venue":"Kinsley","countryCode":"GB","discountAllowed":true,"timezone":"Europe/London","openDate":"2024-06-27T13:36:00.000Z","version":5995379779,"name":"To Be Placed","eventName":"Kinsley 27th Jun"},"rc":[],"con":true,"img":false}]}
{"op":"mcm","clk":"11540841375","pt":1719498982642,"mc":[{"id":"1.230178315","rc":[{"atb":[[2.32,0]],"id":70466763},{"atl":[[5.5,0],[5.7,1]],"id":70466763},{"atb":[[1.67,0],[1.78,6.14]],"id":45375136},{"atb":[[1.74,0]],"id":63994056},{"atb":[[1.41,0]],"id":69979804},{"atl":[[4.4,1],[4.2,0]],"id":69979804},{"atb":[[1.68,0],[1.78,6.14]],"id":46251065}],"con":true,"img":false}]}
{"op":"mcm","clk":"11540841384","pt":1719498982747,"mc":[{"id":"1.230178315","rc":[{"atb":[[1.55,0],[1.66,18.42],[2.08,1]],"id":70466763},{"atb":[[1.97,1],[2.12,0]],"id":45375136},{"atb":[[1.45,18.42],[1.32,0],[1.66,1]],"id":63994056},{"atl":[[4,1],[3.9,0]],"id":63994056},{"atb":[[1.52,6.14]],"id":69979804},{"atl":[[46,0],[48,2.13]],"id":70940946},{"atl":[[5,0],[5.3,1]],"id":46251065}],"con":true,"img":false}]}
{"op":"mcm","clk":"11540841393","pt":1719498982811,"mc":[{"id":"1.230178315","rc":[{"atb":[[1.8,6.14],[1.78,0]],"id":45375136},{"atl":[[4.6,1],[4.4,0]],"id":69979804}],"con":true,"img":false}]}
{"op":"mcm","clk":"11540841400","pt":1719498982913,"mc":[{"id":"1.230178315","rc":[{"atl":[[50,0],[55,1]],"id":70940946}],"con":true,"img":false}]}
{"op":"mcm","clk":"11540863705","pt":1719499276828,"mc":[{"id":"1.230178315","rc":[{"atb":[[1.08,50]],"id":70466763},{"spn":3.89,"spf":"NaN","id":70466763},{"atb":[[1.08,50]],"id":45375136},{"spn":3.63,"spf":"NaN","id":45375136},{"atb":[[1.08,50]],"id":63994056},{"spn":2.83,"spf":"NaN","id":63994056},{"atb":[[1.08,50]],"id":69979804},{"spn":3.21,"spf":"NaN","id":69979804},{"atb":[[1.08,50]],"id":70940946},{"spn":24.54,"spf":"NaN","id":70940946},{"atb":[[1.08,50]],"id":46251065},{"spn":1.83,"spf":1.0,"id":46251065}],"con":true,"img":false}]}
{"op":"mcm","clk":"11540863715","pt":1719499276929,"mc":[{"id":"1.230178315","rc":[{"atb":[[1.03,0],[1.09,9.21]],"id":70940946}],"con":true,"img":false}]}
{"op":"mcm","clk":"11540863880","pt":1719499279095,"mc":[{"id":"1.230178315","rc":[{"atb":[[1.07,1]],"id":70940946}],"con":true,"img":false}]}
{"op":"mcm","clk":"11540864937","pt":1719499291829,"mc":[{"id":"1.230178315","rc":[{"atb":[[1.07,4.16]],"id":45375136}],"con":true,"img":false}]}
{"op":"mcm","clk":"11540864956","pt":1719499292036,"mc":[{"id":"1.230178315","rc":[{"atb":[[1.07,3.12]],"id":69979804},{"atb":[[1.07,5.8]],"id":46251065}],"con":true,"img":false}]}
{"op":"mcm","clk":"11540865056","pt":1719499293234,"mc":[{"id":"1.230178315","rc":[{"atb":[[1.07,0]],"id":46251065}],"con":true,"img":false}]}
{"op":"mcm","clk":"11540865085","pt":1719499293647,"mc":[{"id":"1.230178315","rc":[{"atb":[[1.07,0]],"id":69979804}],"con":true,"img":false}]}
{"op":"mcm","clk":"11540866167","pt":1719499308560,"mc":[{"id":"1.230178315","rc":[{"atb":[[1.07,4.91]],"id":70940946}],"con":true,"img":false}]}
{"op":"mcm","clk":"11540866192","pt":1719499308869,"mc":[{"id":"1.230178315","rc":[{"atb":[[1.07,1]],"id":70940946}],"con":true,"img":false}]}
{"op":"mcm","clk":"11540867142","pt":1719499321481,"mc":[{"id":"1.230178315","rc":[{"atb":[[1.07,3.12]],"id":69979804},{"atb":[[1.07,5.8]],"id":46251065}],"con":true,"img":false}]}
{"op":"mcm","clk":"11540867186","pt":1719499321952,"mc":[{"id":"1.230178315","rc":[{"atb":[[1.07,0]],"id":69979804}],"con":true,"img":false}]}
{"op":"mcm","clk":"11540867967","pt":1719499331973,"mc":[{"id":"1.230178315","rc":[{"atb":[[1.07,5.2]],"id":46251065}],"con":true,"img":false}]}
{"op":"mcm","clk":"11540868257","pt":1719499336106,"mc":[{"id":"1.230178315","rc":[{"atb":[[1.07,4.91]],"id":70940946}],"con":true,"img":false}]}
{"op":"mcm","clk":"11540868314","pt":1719499336777,"mc":[{"id":"1.230178315","rc":[{"atb":[[1.07,1]],"id":70940946}],"con":true,"img":false}]}
{"op":"mcm","clk":"11540869241","pt":1719499348190,"mc":[{"id":"1.230178315","rc":[{"atb":[[2.08,4.08]],"id":70466763},{"atb":[[1.97,3.9]],"id":45375136},{"atb":[[1.46,5]],"id":63994056},{"atb":[[1.59,3.87]],"id":69979804},{"spn":24.54,"spf":"NaN","id":70940946},{"atb":[[1.82,2.83]],"id":46251065},{"spn":1.85,"spf":1.0,"id":46251065}],"con":true,"img":false}]}
{"op":"mcm","clk":"11540869248","pt":1719499348289,"mc":[{"id":"1.230178315","rc":[{"atb":[[1.66,0],[2.1,4.08]],"id":70466763},{"atb":[[1.8,0],[1.97,10.04],[1.07,6.75]],"id":45375136},{"atb":[[1.6,6.14],[1.52,0]],"id":69979804}],"con":true,"img":false}]}
{"op":"mcm","clk":"11540869255","pt":1719499348393,"mc":[{"id":"1.230178315","rc":[{"atb":[[1.07,5.8]],"id":46251065}],"con":true,"img":false}]}
{"op":"mcm","clk":"11540869273","pt":1719499348700,"mc":[{"id":"1.230178315","rc":[{"atb":[[1.07,0]],"id":45375136},{"atb":[[1.07,0]],"id":46251065}],"con":true,"img":false}]}
{"op":"mcm","clk":"11540869369","pt":1719499350014,"mc":[{"id":"1.230178315","rc":[{"atb":[[1.62,2.11]],"id":69979804}],"con":true,"img":false}]}
{"op":"mcm","clk":"11540870377","pt":1719499362108,"mc":[{"id":"1.230178315","rc":[{"atb":[[2.08,1]],"id":70466763},{"atb":[[1.59,0]],"id":69979804}],"con":true,"img":false}]}
{"op":"mcm","clk":"11540870391","pt":1719499362210,"mc":[{"id":"1.230178315","rc":[{"atb":[[1.67,18.42],[2.12,2],[2.1,0]],"id":70466763},{"atb":[[1.63,4]],"id":69979804}],"con":true,"img":false}]}
{"op":"mcm","clk":"11540870401","pt":1719499362314,"mc":[{"id":"1.230178315","rc":[{"atb":[[1.07,4.91]],"id":70940946}],"con":true,"img":false}]}
{"op":"mcm","clk":"11540870448","pt":1719499362931,"mc":[{"id":"1.230178315","rc":[{"atb":[[1.07,1]],"id":70940946}],"con":true,"img":false}]}
{"op":"mcm","clk":"11540870856","pt":1719499368306,"mc":[{"id":"1.230178315","rc":[{"atb":[[1.67,0],[2.12,4]],"id":70466763}],"con":true,"img":false}]}
{"op":"mcm","clk":"11540871368","pt":1719499374406,"mc":[{"id":"1.230178315","rc":[{"atb":[[1.07,4.16]],"id":45375136}],"con":true,"img":false}]}
{"op":"mcm","clk":"11540871410","pt":1719499374919,"mc":[{"id":"1.230178315","rc":[{"atb":[[1.07,0]],"id":45375136}],"con":true,"img":false}]}
{"op":"mcm","clk":"11540872434","pt":1719499387206,"mc":[{"id":"1.230178315","rc":[{"atb":[[1.07,4.91]],"id":70940946}],"con":true,"img":false}]}
{"op":"mcm","clk":"11540872552","pt":1719499388934,"mc":[{"id":"1.230178315","rc":[{"atb":[[1.07,1]],"id":70940946}],"con":true,"img":false}]}
{"op":"mcm","clk":"11540873278","pt":1719499397942,"mc":[{"id":"1.230178315","rc":[{"atb":[[2.02,5.41]],"id":45375136}],"con":true,"img":false}]}
{"op":"mcm","clk":"11540873284","pt":1719499398047,"mc":[{"id":"1.230178315","rc":[{"atb":[[1.97,3.9],[2.04,10.04]],"id":45375136}],"con":true,"img":false}]}
{"op":"mcm","clk":"11540873338","pt":1719499398724,"mc":[{"id":"1.230178315","rc":[{"atb":[[2.08,2.11]],"id":45375136}],"con":true,"img":false}]}
{"op":"mcm","clk":"11540873348","pt":1719499398829,"mc":[{"id":"1.230178315","rc":[{"atb":[[2.04,0],[2.08,7.53]],"id":45375136}],"con":true,"img":false}]}
{"op":"mcm","clk":"11540873776","pt":1719499404441,"mc":[{"id":"1.230178315","rc":[{"atb":[[1.97,1]],"id":45375136}],"con":true,"img":false}]}
{"op":"mcm","clk":"11540873785","pt":1719499404549,"mc":[{"id":"1.230178315","rc":[{"atb":[[2.1,2.13]],"id":45375136}],"con":true,"img":false}]}
{"op":"mcm","clk":"11540873877","pt":1719499405686,"mc":[{"id":"1.230178315","rc":[{"atb":[[1.74,3.75]],"id":70466763},{"atb":[[1.45,22.17]],"id":63994056},{"atb":[[1.6,9.89]],"id":69979804},{"atb":[[1.06,3.91]],"id":70940946},{"atb":[[1.81,5.74]],"id":46251065}],"con":true,"img":false}]}
{"op":"mcm","clk":"11540873893","pt":1719499405748,"mc":[{"id":"1.230178315","rc":[{"atb":[[1.99,5.16]],"id":45375136}],"con":true,"img":false}]}
{"op":"mcm","clk":"11540874007","pt":1719499406886,"mc":[{"id":"1.230178315","rc":[{"atb":[[1.81,7.85]],"id":46251065}],"con":true,"img":false}]}
{"op":"mcm","clk":"11540874352","pt":1719499410876,"mc":[{"id":"1.230178315","rc":[{"atb":[[1.74,0]],"id":70466763},{"spn":3.91,"spf":"NaN","id":70466763},{"spn":3.7,"spf":"NaN","id":45375136},{"atb":[[1.07,4.91]],"id":70940946},{"spn":1.86,"spf":1.0,"id":46251065}],"con":true,"img":false}]}
{"op":"mcm","clk":"11540874360","pt":1719499410980,"mc":[{"id":"1.230178315","rc":[{"atb":[[1.06,3.3]],"id":70940946}],"con":true,"img":false}]}
{"op":"mcm","clk":"11540874380","pt":1719499411236,"mc":[{"id":"1.230178315","rc":[{"atb":[[1.07,1]],"id":70940946}],"con":true,"img":false}]}
{"op":"mcm","clk":"11540874435","pt":1719499411966,"mc":[{"id":"1.230178315","rc":[{"atb":[[1.99,0]],"id":45375136}],"con":true,"img":false}]}
{"op":"mcm","clk":"11540874613","pt":1719499413841,"mc":[{"id":"1.230178315","rc":[{"atb":[[1.45,18.42]],"id":63994056},{"atb":[[1.6,6.14]],"id":69979804},{"atb":[[1.81,2.11]],"id":46251065}],"con":true,"img":false}]}
{"op":"mcm","clk":"11540874768","pt":1719499415852,"mc":[{"id":"1.230178315","rc":[{"atb":[[2.02,0]],"id":45375136}],"con":true,"img":false}]}
{"op":"mcm","clk":"11540874787","pt":1719499416066,"mc":[{"id":"1.230178315","rc":[{"atb":[[2.14,4.84]],"id":45375136}],"con":true,"img":false}]}
{"op":"mcm","clk":"11540874807","pt":1719499416271,"mc":[{"id":"1.230178315","rc":[{"atb":[[2.16,4.85]],"id":45375136}],"con":true,"img":false}]}
{"op":"mcm","clk":"11540874817","pt":1719499416376,"mc":[{"id":"1.230178315","rc":[{"atb":[[2.08,2.11]],"id":45375136}],"con":true,"img":false}]}
{"op":"mcm","clk":"11540874973","pt":1719499418189,"mc":[{"id":"1.230178315","rc":[{"atl":[[5.5,1]],"id":46251065}],"con":true,"img":false}]}
{"op":"mcm","clk":"11540874984","pt":1719499418245,"mc":[{"id":"1.230178315","rc":[{"atl":[[5.4,1]],"id":70466763},{"atl":[[5.3,0]],"id":46251065}],"con":true,"img":false}]}
{"op":"mcm","clk":"11540874992","pt":1719499418349,"mc":[{"id":"1.230178315","rc":[{"atl":[[5.7,0]],"id":70466763}],"con":true,"img":false}]}
{"op":"mcm","clk":"11540875013","pt":1719499418553,"mc":[{"id":"1.230178315","rc":[{"atl":[[5.7,1],[5.4,0]],"id":70466763},{"atl":[[5.5,0],[5.3,1]],"id":46251065}],"con":true,"img":false}]}
{"op":"mcm","clk":"11540875024","pt":1719499418657,"mc":[{"id":"1.230178315","rc":[{"atl":[[20,0],[21,3.32]],"id":46251065}],"con":true,"img":false}]}
{"op":"mcm","clk":"11540875101","pt":1719499419746,"mc":[{"id":"1.230178315","rc":[{"atl":[[5.7,0],[5.4,1]],"id":70466763},{"atl":[[5.3,0],[5.5,1]],"id":46251065}],"con":true,"img":false}]}
{"op":"mcm","clk":"11540875186","pt":1719499420886,"mc":[{"id":"1.230178315","rc":[{"atl":[[5.7,1],[5.4,0]],"id":70466763},{"atl":[[5.5,0],[5.3,1]],"id":46251065}],"con":true,"img":false}]}
{"op":"mcm","clk":"11540875232","pt":1719499421560,"mc":[{"id":"1.230178315","rc":[{"atb":[[2.1,0]],"id":45375136}],"con":true,"img":false}]}
{"op":"mcm","clk":"11540875238","pt":1719499421662,"mc":[{"id":"1.230178315","rc":[{"atb":[[2.18,2.03]],"id":45375136}],"con":true,"img":false}]}
{"op":"mcm","clk":"11540875751","pt":1719499428360,"mc":[{"id":"1.230178315","rc":[{"atb":[[1.06,3.91]],"id":70940946}],"con":true,"img":false}]}
{"op":"mcm","clk":"11540875830","pt":1719499429395,"mc":[{"id":"1.230178315","rc":[{"atb":[[2.02,5.04]],"id":45375136}],"con":true,"img":false}]}
{"op":"mcm","clk":"11540875841","pt":1719499429500,"mc":[{"id":"1.230178315","rc":[{"atb":[[1.75,3.75]],"id":70466763},{"atb":[[1.44,3.75]],"id":63994056},{"atb":[[1.59,3.75]],"id":69979804},{"atb":[[1.8,5.55]],"id":46251065}],"con":true,"img":false}]}
{"op":"mcm","clk":"11540875884","pt":1719499430072,"mc":[{"id":"1.230178315","rc":[{"atb":[[2.02,0]],"id":45375136}],"con":true,"img":false}]}
{"op":"mcm","clk":"11540875968","pt":1719499431271,"mc":[{"id":"1.230178315","rc":[{"atl":[[5.6,1],[5.7,0]],"id":70466763},{"atb":[[2.02,1],[1.97,0]],"id":45375136},{"atl":[[5.3,0],[5.2,1]],"id":46251065}],"con":true,"img":false}]}
{"op":"mcm","clk":"11540875973","pt":1719499431376,"mc":[{"id":"1.230178315","rc":[{"atb":[[2.02,1],[2.08,0]],"id":70466763}],"con":true,"img":false}]}
{"op":"mcm","clk":"11540876046","pt":1719499432370,"mc":[{"id":"1.230178315","rc":[{"atl":[[5.4,1]],"id":70466763},{"atl":[[5.5,1],[5.2,0]],"id":46251065}],"con":true,"img":false}]}
{"op":"mcm","clk":"11540876053","pt":1719499432473,"mc":[{"id":"1.230178315","rc":[{"atl":[[5.6,0]],"id":70466763}],"con":true,"img":false}]}
{"op":"mcm","clk":"11540876109","pt":1719499433360,"mc":[{"id":"1.230178315","rc":[{"atb":[[1.07,4.91]],"id":70940946}],"con":true,"img":false}]}
{"op":"mcm","clk":"11540876173","pt":1719499434294,"mc":[{"id":"1.230178315","rc":[{"atb":[[1.07,1]],"id":70940946}],"con":true,"img":false}]}
{"op":"mcm","clk":"11540876978","pt":1719499444181,"mc":[{"id":"1.230178315","rc":[{"atb":[[1.44,0]],"id":63994056},{"atb":[[1.59,0]],"id":69979804},{"atb":[[1.8,0]],"id":46251065}],"con":true,"img":false}]}
{"op":"mcm","clk":"11540877587","pt":1719499452010,"mc":[{"id":"1.230178315","rc":[{"atb":[[2,5.04]],"id":45375136},{"atb":[[1.47,3.75]],"id":63994056},{"atb":[[1.6,9.89]],"id":69979804},{"atb":[[1.95,5.55]],"id":46251065}],"con":true,"img":false}]}
{"op":"mcm","clk":"11540877595","pt":1719499452114,"mc":[{"id":"1.230178315","rc":[{"atb":[[1.83,2.83]],"id":46251065}],"con":true,"img":false}]}
{"op":"mcm","clk":"11540877604","pt":1719499452217,"mc":[{"id":"1.230178315","rc":[{"atb":[[1.78,0]],"id":46251065}],"con":true,"img":false}]}
{"op":"mcm","clk":"11540877785","pt":1719499454700,"mc":[{"id":"1.230178315","rc":[{"atb":[[1.07,4.91]],"id":70940946}],"con":true,"img":false}]}
{"op":"mcm","clk":"11540877823","pt":1719499455220,"mc":[{"id":"1.230178315","rc":[{"atb":[[1.06,5.26]],"id":70940946}],"con":true,"img":false}]}
{"op":"mcm","clk":"11540877876","pt":1719499455999,"mc":[{"id":"1.230178315","rc":[{"atb":[[2.14,0]],"id":45375136}],"con":true,"img":false}]}
{"op":"mcm","clk":"11540877891","pt":1719499456206,"mc":[{"id":"1.230178315","rc":[{"atb":[[2,0]],"id":45375136},{"atb":[[1.49,8.05],[1.47,0]],"id":63994056},{"atb":[[1.6,6.14]],"id":69979804},{"atb":[[1.95,0]],"id":46251065}],"con":true,"img":false}]}
{"op":"mcm","clk":"11540877897","pt":1719499456309,"mc":[{"id":"1.230178315","rc":[{"atb":[[1.46,0],[1.45,0],[1.5,8.05]],"id":63994056},{"atb":[[1.82,0]],"id":46251065}],"con":true,"img":false}]}
{"op":"mcm","clk":"11540877904","pt":1719499456411,"mc":[{"id":"1.230178315","rc":[{"atb":[[1.48,3.4]],"id":63994056},{"atb":[[1.96,3]],"id":46251065}],"con":true,"img":false}]}
{"op":"mcm","clk":"11540877909","pt":1719499456515,"mc":[{"id":"1.230178315","rc":[{"atb":[[1.83,0],[1.96,5.83]],"id":46251065}],"con":true,"img":false}]}
{"op":"mcm","clk":"11540877992","pt":1719499457393,"mc":[{"id":"1.230178315","rc":[{"atb":[[1.07,1]],"id":70940946}],"con":true,"img":false}]}
{"op":"mcm","clk":"11540878538","pt":1719499464997,"mc":[{"id":"1.230178315","rc":[{"atb":[[1.48,0]],"id":63994056},{"atb":[[1.96,2.83]],"id":46251065}],"con":true,"img":false}]}
{"op":"mcm","clk":"11540878546","pt":1719499465100,"mc":[{"id":"1.230178315","rc":[{"atb":[[1.51,4]],"id":63994056},{"atb":[[1.82,6.14],[1.97,2.75],[1.96,0]],"id":46251065}],"con":true,"img":false}]}
{"op":"mcm","clk":"11540878692","pt":1719499467122,"mc":[{"id":"1.230178315","rc":[{"atb":[[1.53,7.98]],"id":63994056}],"con":true,"img":false}]}
{"op":"mcm","clk":"11540878704","pt":1719499467176,"mc":[{"id":"1.230178315","rc":[{"atb":[[1.54,7.98],[1.5,0]],"id":63994056}],"con":true,"img":false}]}
{"op":"mcm","clk":"11540878761","pt":1719499467905,"mc":[{"id":"1.230178315","rc":[{"atb":[[1.56,2.11],[1.35,0]],"id":63994056}],"con":true,"img":false}]}
{"op":"mcm","clk":"11540878767","pt":1719499468007,"mc":[{"id":"1.230178315","rc":[{"atb":[[1.56,10.09],[1.54,0]],"id":63994056}],"con":true,"img":false}]}
{"op":"mcm","clk":"11540878943","pt":1719499470184,"mc":[{"id":"1.230178315","rc":[{"atb":[[1.82,0],[1.97,5.5]],"id":46251065}],"con":true,"img":false}]}
{"op":"mcm","clk":"11540878955","pt":1719499470288,"mc":[{"id":"1.230178315","rc":[{"atb":[[1.82,6.14]],"id":46251065}],"con":true,"img":false}]}
{"op":"mcm","clk":"11540878964","pt":1719499470391,"mc":[{"id":"1.230178315","rc":[{"atb":[[1.97,2.75]],"id":46251065}],"con":true,"img":false}]}
{"op":"mcm","clk":"11540879118","pt":1719499472415,"mc":[{"id":"1.230178315","rc":[{"spn":3.76,"spf":"NaN","id":70466763},{"spn":3.74,"spf":"NaN","id":45375136},{"atb":[[1.59,9.36]],"id":63994056},{"atb":[[1.95,5.74]],"id":46251065},{"spn":1.98,"spf":1.0,"id":46251065}],"con":true,"img":false}]}
{"op":"mcm","clk":"11540879124","pt":1719499472517,"mc":[{"id":"1.230178315","rc":[{"atb":[[1.82,0],[1.95,11.88]],"id":46251065}],"con":true,"img":false}]}
{"op":"mcm","clk":"11540879132","pt":1719499472621,"mc":[{"id":"1.230178315","rc":[{"atb":[[1.49,0]],"id":63994056},{"atb":[[1.97,8.49],[1.95,5.74]],"id":46251065}],"con":true,"img":false}]}
{"op":"mcm","clk":"11540879159","pt":1719499472997,"mc":[{"id":"1.230178315","rc":[{"atb":[[1.58,6.8]],"id":63994056}],"con":true,"img":false}]}
{"op":"mcm","clk":"11540879166","pt":1719499473087,"mc":[{"id":"1.230178315","rc":[{"atb":[[1.56,2.11],[1.6,9.37]],"id":63994056}],"con":true,"img":false}]}
{"op":"mcm","clk":"11540879192","pt":1719499473397,"mc":[{"id":"1.230178315","rc":[{"atb":[[2.14,4.76]],"id":45375136},{"atb":[[1.49,3.75]],"id":63994056},{"atb":[[1.59,3.75]],"id":69979804}],"con":true,"img":false}]}
{"op":"mcm","clk":"11540879213","pt":1719499473707,"mc":[{"id":"1.230178315","rc":[{"atb":[[1.51,0]],"id":63994056},{"atb":[[1.97,5.74]],"id":46251065}],"con":true,"img":false}]}
{"op":"mcm","clk":"11540879231","pt":1719499473914,"mc":[{"id":"1.230178315","rc":[{"atb":[[1.66,3.7]],"id":63994056},{"atb":[[1.98,3]],"id":46251065}],"con":true,"img":false}]}
{"op":"mcm","clk":"11540879308","pt":1719499475005,"mc":[{"id":"1.230178315","rc":[{"atb":[[1.07,4.91]],"id":70940946}],"con":true,"img":false}]}
{"op":"mcm","clk":"11540879316","pt":1719499475107,"mc":[{"id":"1.230178315","rc":[{"atb":[[1.06,3.57]],"id":70940946}],"con":true,"img":false}]}
{"op":"mcm","clk":"11540879475","pt":1719499477221,"mc":[{"id":"1.230178315","rc":[{"atb":[[1.07,1]],"id":70940946}],"con":true,"img":false}]}
{"op":"mcm","clk":"11540879595","pt":1719499478325,"mc":[{"id":"1.230178315","rc":[{"atb":[[1.66,13.07]],"id":63994056}],"con":true,"img":false}]}
{"op":"mcm","clk":"11540879605","pt":1719499478428,"mc":[{"id":"1.230178315","rc":[{"atb":[[1.6,0]],"id":63994056}],"con":true,"img":false}]}
{"op":"mcm","clk":"11540879690","pt":1719499479415,"mc":[{"id":"1.230178315","rc":[{"atb":[[1.49,0]],"id":63994056}],"con":true,"img":false}]}
{"op":"mcm","clk":"11540879948","pt":1719499482338,"mc":[{"id":"1.230178315","rc":[{"atb":[[1.66,10.37]],"id":63994056}],"con":true,"img":false}]}
{"op":"mcm","clk":"11540879955","pt":1719499482443,"mc":[{"id":"1.230178315","rc":[{"atb":[[1.6,20.74],[1.66,1]],"id":63994056}],"con":true,"img":false}]}
{"op":"mcm","clk":"11540879966","pt":1719499482509,"mc":[{"id":"1.230178315","rc":[{"atb":[[1.67,3]],"id":63994056}],"con":true,"img":false}]}
{"op":"mcm","clk":"11540879975","pt":1719499482600,"mc":[{"id":"1.230178315","rc":[{"atb":[[1.6,0],[1.68,3]],"id":63994056}],"con":true,"img":false}]}
{"op":"mcm","clk":"11540879984","pt":1719499482703,"mc":[{"id":"1.230178315","rc":[{"atb":[[1.67,6],[1.68,0]],"id":63994056}],"con":true,"img":false}]}
{"op":"mcm","clk":"11540880103","pt":1719499484098,"mc":[{"id":"1.230178315","rc":[{"atb":[[1.56,0],[1.62,2.11]],"id":63994056}],"con":true,"img":false}]}
{"op":"mcm","clk":"11540880363","pt":1719499487413,"mc":[{"id":"1.230178315","rc":[{"atb":[[1.95,0]],"id":46251065}],"con":true,"img":false}]}
{"op":"mcm","clk":"11540880824","pt":1719499492819,"mc":[{"id":"1.230178315","rc":[{"atb":[[1.97,11.48]],"id":46251065}],"con":true,"img":false}]}
{"op":"mcm","clk":"11540880921","pt":1719499493712,"mc":[{"id":"1.230178315","rc":[{"atb":[[1.59,13.11]],"id":63994056}],"con":true,"img":false}]}
{"op":"mcm","clk":"11540880966","pt":1719499494227,"mc":[{"id":"1.230178315","rc":[{"atb":[[1.07,4.91]],"id":70940946}],"con":true,"img":false}]}
{"op":"mcm","clk":"11540880978","pt":1719499494434,"mc":[{"id":"1.230178315","rc":[{"atb":[[1.06,5.26]],"id":70940946}],"con":true,"img":false}]}
{"op":"mcm","clk":"11540880989","pt":1719499494537,"mc":[{"id":"1.230178315","rc":[{"atb":[[1.07,1]],"id":70940946}],"con":true,"img":false}]}
{"op":"mcm","clk":"11540881119","pt":1719499495943,"mc":[{"id":"1.230178315","rc":[{"atl":[[5.1,1],[5.4,0]],"id":70466763},{"atb":[[1.83,0],[1.92,1]],"id":69979804},{"atl":[[5.5,0],[5.4,1]],"id":46251065}],"con":true,"img":false}]}
{"op":"mcm","clk":"11540881161","pt":1719499496320,"mc":[{"id":"1.230178315","rc":[{"atl":[[5.1,0],[5.2,1]],"id":70466763},{"atb":[[1.83,1],[1.92,0]],"id":69979804},{"atl":[[5.3,1]],"id":46251065}],"con":true,"img":false}]}
{"op":"mcm","clk":"11540881168","pt":1719499496414,"mc":[{"id":"1.230178315","rc":[{"atl":[[5.4,2]],"id":70466763},{"atb":[[1.64,4],[1.59,0]],"id":69979804},{"atl":[[21,0],[6.2,2.82],[5.4,0]],"id":46251065}],"con":true,"img":false}]}
{"op":"mcm","clk":"11540881177","pt":1719499496515,"mc":[{"id":"1.230178315","rc":[{"atb":[[1.75,5]],"id":70466763},{"atl":[[17,0]],"id":70466763},{"atb":[[1.6,0]],"id":69979804},{"atl":[[6.2,0],[21,2.82],[5.2,2.97]],"id":46251065}],"con":true,"img":false}]}
{"op":"mcm","clk":"11540881186","pt":1719499496621,"mc":[{"id":"1.230178315","rc":[{"atl":[[17,3],[5.4,0]],"id":70466763},{"atl":[[21,0],[6.2,3.97]],"id":46251065}],"con":true,"img":false}]}
{"op":"mcm","clk":"11540881220","pt":1719499497138,"mc":[{"id":"1.230178315","rc":[{"atl":[[5.1,0.84]],"id":46251065}],"con":true,"img":false}]}
{"op":"mcm","clk":"11540881246","pt":1719499497450,"mc":[{"id":"1.230178315","rc":[{"atb":[[1.59,9.36]],"id":63994056}],"con":true,"img":false}]}
{"op":"mcm","clk":"11540881254","pt":1719499497552,"mc":[{"id":"1.230178315","rc":[{"atb":[[1.6,3.75]],"id":69979804}],"con":true,"img":false}]}
{"op":"mcm","clk":"11540881316","pt":1719499498327,"mc":[{"id":"1.230178315","rc":[{"atl":[[5.2,0],[5.4,1]],"id":70466763},{"atl":[[5.3,0],[5.5,1]],"id":46251065}],"con":true,"img":false}]}
{"op":"mcm","clk":"11540881440","pt":1719499499723,"mc":[{"id":"1.230178315","rc":[{"atb":[[1.63,0]],"id":69979804}],"con":true,"img":false}]}
{"op":"mcm","clk":"11540881453","pt":1719499499930,"mc":[{"id":"1.230178315","rc":[{"atb":[[1.65,3.4]],"id":69979804}],"con":true,"img":false}]}
{"op":"mcm","clk":"11540881805","pt":1719499503851,"mc":[{"id":"1.230178315","rc":[{"atb":[[1.83,0],[1.92,1]],"id":69979804},{"atl":[[5.4,1]],"id":46251065}],"con":true,"img":false}]}
{"op":"mcm","clk":"11540881816","pt":1719499503955,"mc":[{"id":"1.230178315","rc":[{"atl":[[5.3,1],[5.4,0]],"id":70466763},{"atb":[[2.14,0]],"id":45375136},{"atb":[[1.64,0],[1.66,3.4]],"id":69979804},{"atb":[[1.97,5.74]],"id":46251065},{"atl":[[5.5,0]],"id":46251065}],"con":true,"img":false}]}
{"op":"mcm","clk":"11540881867","pt":1719499504543,"mc":[{"id":"1.230178315","rc":[{"atb":[[1.75,0]],"id":70466763}],"con":true,"img":false}]}
{"op":"mcm","clk":"11540881912","pt":1719499505164,"mc":[{"id":"1.230178315","rc":[{"atl":[[5.3,0],[5.4,1]],"id":70466763},{"atb":[[1.83,1],[1.92,0]],"id":69979804},{"atl":[[5.3,1],[5.4,0]],"id":46251065}],"con":true,"img":false}]}
{"op":"mcm","clk":"11540881940","pt":1719499505424,"mc":[{"id":"1.230178315","rc":[{"atb":[[2.12,4.16]],"id":45375136}],"con":true,"img":false}]}
{"op":"mcm","clk":"11540882071","pt":1719499506720,"mc":[{"id":"1.230178315","rc":[{"atl":[[5.3,0],[5.5,1]],"id":46251065}],"con":true,"img":false}]}
{"op":"mcm","clk":"11540882114","pt":1719499507240,"mc":[{"id":"1.230178315","rc":[{"atb":[[1.68,6.22]],"id":69979804}],"con":true,"img":false}]}
{"op":"mcm","clk":"11540882122","pt":1719499507345,"mc":[{"id":"1.230178315","rc":[{"atb":[[1.66,0],[1.69,3.4]],"id":69979804}],"con":true,"img":false}]}
{"op":"mcm","clk":"11540882128","pt":1719499507449,"mc":[{"id":"1.230178315","rc":[{"atb":[[1.6,0]],"id":69979804}],"con":true,"img":false}]}
{"op":"mcm","clk":"11540882177","pt":1719499508022,"mc":[{"id":"1.230178315","rc":[{"atl":[[5.3,1],[5.4,0]],"id":70466763},{"atb":[[1.92,1]],"id":69979804},{"atl":[[5.5,0],[5.4,1]],"id":46251065}],"con":true,"img":false}]}
{"op":"mcm","clk":"11540882187","pt":1719499508124,"mc":[{"id":"1.230178315","rc":[{"atb":[[1.83,0]],"id":69979804}],"con":true,"img":false}]}
{"op":"mcm","clk":"11540882218","pt":1719499508437,"mc":[{"id":"1.230178315","rc":[{"atb":[[1.65,0]],"id":69979804}],"con":true,"img":false}]}
{"op":"mcm","clk":"11540882228","pt":1719499508540,"mc":[{"id":"1.230178315","rc":[{"atb":[[1.84,3.3]],"id":69979804}],"con":true,"img":false}]}
{"op":"mcm","clk":"11540882333","pt":1719499510036,"mc":[{"id":"1.230178315","rc":[{"atb":[[2.12,0]],"id":45375136}],"con":true,"img":false}]}
{"op":"mcm","clk":"11540882501","pt":1719499512265,"mc":[{"id":"1.230178315","rc":[{"atb":[[1.96,4.96]],"id":46251065}],"con":true,"img":false}]}
{"op":"mcm","clk":"11540882524","pt":1719499512539,"mc":[{"id":"1.230178315","rc":[{"atb":[[1.85,3.4],[1.69,0]],"id":69979804},{"atb":[[1.07,4.91]],"id":70940946}],"con":true,"img":false}]}
{"op":"mcm","clk":"11540882537","pt":1719499512747,"mc":[{"id":"1.230178315","rc":[{"atb":[[1.06,3.91]],"id":70940946}],"con":true,"img":false}]}
{"op":"mcm","clk":"11540882544","pt":1719499512839,"mc":[{"id":"1.230178315","rc":[{"atb":[[1.06,5.25],[1.07,1]],"id":70940946}],"con":true,"img":false}]}
{"op":"mcm","clk":"11540882565","pt":1719499513149,"mc":[{"id":"1.230178315","rc":[{"atb":[[1.58,10.55]],"id":63994056}],"con":true,"img":false}]}
{"op":"mcm","clk":"11540882715","pt":1719499514950,"mc":[{"id":"1.230178315","rc":[{"atl":[[5.2,3.97],[5.4,0]],"id":46251065}],"con":true,"img":false}]}
{"op":"mcm","clk":"11540882856","pt":1719499516863,"mc":[{"id":"1.230178315","rc":[{"atl":[[5.3,0],[5.4,1]],"id":70466763},{"atb":[[2.02,0]],"id":45375136},{"atl":[[48,0],[50,2.04]],"id":70940946}],"con":true,"img":false}]}
{"op":"mcm","clk":"11540882885","pt":1719499517234,"mc":[{"id":"1.230178315","rc":[{"atb":[[1.84,0]],"id":69979804}],"con":true,"img":false}]}
{"op":"mcm","clk":"11540882892","pt":1719499517328,"mc":[{"id":"1.230178315","rc":[{"atl":[[21,4],[5.3,1],[5.4,0]],"id":70466763},{"atb":[[1.85,0],[1.86,2],[1.69,6.22]],"id":69979804},{"atl":[[55,0],[60,1]],"id":70940946},{"atb":[[1.92,7.96],[1.97,0]],"id":46251065},{"atl":[[6.2,0],[5.9,4.82]],"id":46251065}],"con":true,"img":false}]}
{"op":"mcm","clk":"11540882903","pt":1719499517431,"mc":[{"id":"1.230178315","rc":[{"atl":[[17,0]],"id":70466763}],"con":true,"img":false}]}
{"op":"mcm","clk":"11540882911","pt":1719499517533,"mc":[{"id":"1.230178315","rc":[{"atb":[[1.57,28.07]],"id":69979804}],"con":true,"img":false}]}
{"op":"mcm","clk":"11540882917","pt":1719499517635,"mc":[{"id":"1.230178315","rc":[{"atb":[[1.69,0]],"id":69979804}],"con":true,"img":false}]}
{"op":"mcm","clk":"11540882947","pt":1719499518048,"mc":[{"id":"1.230178315","rc":[{"atb":[[1.65,3.75]],"id":69979804},{"atb":[[1.96,0]],"id":46251065}],"con":true,"img":false}]}
{"op":"mcm","clk":"11540882981","pt":1719499518460,"mc":[{"id":"1.230178315","rc":[{"atb":[[1.95,8.71]],"id":46251065}],"con":true,"img":false}]}
{"op":"mcm","clk":"11540883018","pt":1719499518870,"mc":[{"id":"1.230178315","rc":[{"atb":[[1.95,0]],"id":46251065}],"con":true,"img":false}]}
{"op":"mcm","clk":"11540883116","pt":1719499520059,"mc":[{"id":"1.230178315","rc":[{"atb":[[1.65,0]],"id":69979804}],"con":true,"img":false}]}
{"op":"mcm","clk":"11540883241","pt":1719499521656,"mc":[{"id":"1.230178315","rc":[{"atb":[[2.02,1]],"id":45375136},{"atl":[[4,0],[3.95,1]],"id":63994056}],"con":true,"img":false}]}
{"op":"mcm","clk":"11540883248","pt":1719499521759,"mc":[{"id":"1.230178315","rc":[{"atb":[[2.08,1]],"id":70466763},{"atl":[[5.1,1.84],[5.2,2.97]],"id":46251065}],"con":true,"img":false}]}
{"op":"mcm","clk":"11540883256","pt":1719499521862,"mc":[{"id":"1.230178315","rc":[{"atb":[[2.02,0]],"id":70466763}],"con":true,"img":false}]}
{"op":"mcm","clk":"11540883263","pt":1719499521965,"mc":[{"id":"1.230178315","rc":[{"atl":[[5.3,0],[5.4,1]],"id":70466763},{"atl":[[4,1],[3.95,0]],"id":63994056},{"atb":[[1.92,0],[1.88,1]],"id":69979804},{"atb":[[2.12,0],[2.08,1]],"id":46251065},{"atl":[[5.1,0.84],[5.2,3.97]],"id":46251065}],"con":true,"img":false}]}
{"op":"mcm","clk":"11540883451","pt":1719499524243,"mc":[{"id":"1.230178315","rc":[{"atb":[[2.14,4.76]],"id":45375136}],"con":true,"img":false}]}
{"op":"mcm","clk":"11540883557","pt":1719499525640,"mc":[{"id":"1.230178315","rc":[{"atb":[[1.87,3.9]],"id":70466763}],"con":true,"img":false}]}
{"op":"mcm","clk":"11540883737","pt":1719499528159,"mc":[{"id":"1.230178315","rc":[{"atb":[[2.12,5]],"id":70466763},{"atb":[[2.02,0]],"id":45375136},{"atl":[[50,0],[55,2]],"id":70940946}],"con":true,"img":false}]}
{"op":"mcm","clk":"11540883745","pt":1719499528262,"mc":[{"id":"1.230178315","rc":[{"atb":[[2.12,3],[1.87,8.9],[2.08,0]],"id":70466763},{"atl":[[5.5,1],[5.4,0]],"id":70466763},{"atb":[[1.83,1],[1.88,0]],"id":69979804},{"atl":[[4.5,1],[4.6,0]],"id":69979804},{"atl":[[60,3]],"id":70940946},{"atb":[[1.97,1],[2.08,0]],"id":46251065},{"atl":[[5.1,1.84],[5.2,2.97]],"id":46251065}],"con":true,"img":false}]}
{"op":"mcm","clk":"11540883753","pt":1719499528367,"mc":[{"id":"1.230178315","rc":[{"atb":[[2.12,6.9],[1.87,3.9]],"id":70466763},{"atl":[[9.2,2],[9.4,0]],"id":69979804},{"atl":[[55,0]],"id":70940946}],"con":true,"img":false}]}
{"op":"mcm","clk":"11540883842","pt":1719499529452,"mc":[{"id":"1.230178315","rc":[{"atb":[[1.98,8.63]],"id":46251065}],"con":true,"img":false}]}
{"op":"mcm","clk":"11540883880","pt":1719499529968,"mc":[{"id":"1.230178315","rc":[{"atb":[[1.07,6]],"id":70940946}],"con":true,"img":false}]}
{"op":"mcm","clk":"11540883889","pt":1719499530070,"mc":[{"id":"1.230178315","rc":[{"atb":[[1.06,3.69]],"id":70940946}],"con":true,"img":false}]}
{"op":"mcm","clk":"11540883936","pt":1719499530587,"mc":[{"id":"1.230178315","rc":[{"atb":[[1.97,6.74]],"id":46251065}],"con":true,"img":false}]}
{"op":"mcm","clk":"11540884099","pt":1719499532860,"mc":[{"id":"1.230178315","rc":[{"atb":[[2.12,5.9],[2.18,1]],"id":70466763},{"spn":3.84,"spf":"NaN","id":70466763},{"spn":2.83,"spf":"NaN","id":63994056},{"atl":[[4.6,1]],"id":69979804},{"spn":3.18,"spf":"NaN","id":69979804},{"atl":[[70,1],[60,2]],"id":70940946},{"spn":30.54,"spf":"NaN","id":70940946},{"spn":1.98,"spf":1.0,"id":46251065}],"con":true,"img":false}]}
{"op":"mcm","clk":"11540884110","pt":1719499532964,"mc":[{"id":"1.230178315","rc":[{"atb":[[2.12,2],[1.87,10.8]],"id":70466763},{"atb":[[1.83,0],[1.78,1]],"id":69979804},{"atl":[[4.5,0]],"id":69979804}],"con":true,"img":false}]}
{"op":"mcm","clk":"11540884343","pt":1719499536167,"mc":[{"id":"1.230178315","rc":[{"atb":[[1.67,2.5]],"id":69979804}],"con":true,"img":false}]}
{"op":"mcm","clk":"11540884515","pt":1719499539256,"mc":[{"id":"1.230178315","rc":[{"atb":[[1.87,6.9]],"id":70466763},{"atb":[[2.14,0]],"id":45375136},{"atb":[[1.58,6.8]],"id":63994056},{"atb":[[1.67,0]],"id":69979804},{"atb":[[1.06,0]],"id":70940946},{"atb":[[1.97,1]],"id":46251065}],"con":true,"img":false}]}
{"op":"mcm","clk":"11540884521","pt":1719499539366,"mc":[{"id":"1.230178315","rc":[{"atb":[[2.12,4.12],[1.87,0]],"id":70466763}],"con":true,"img":false}]}
{"op":"mcm","clk":"11540884529","pt":1719499539465,"mc":[{"id":"1.230178315","rc":[{"atb":[[2.12,2],[1.87,6.9]],"id":70466763}],"con":true,"img":false}]}
{"op":"mcm","clk":"11540884535","pt":1719499539568,"mc":[{"id":"1.230178315","rc":[{"atb":[[2.12,6.12],[1.87,0]],"id":70466763}],"con":true,"img":false}]}
{"op":"mcm","clk":"11540884542","pt":1719499539672,"mc":[{"id":"1.230178315","rc":[{"atb":[[2.12,2],[1.87,6.9]],"id":70466763}],"con":true,"img":false}]}
{"op":"mcm","clk":"11540884737","pt":1719499542169,"mc":[{"id":"1.230178315","rc":[{"atb":[[2.12,4.8]],"id":45375136},{"atb":[[1.57,3.75]],"id":63994056}],"con":true,"img":false}]}
{"op":"mcm","clk":"11540884810","pt":1719499543365,"mc":[{"id":"1.230178315","rc":[{"atb":[[1.87,10.65]],"id":70466763}],"con":true,"img":false}]}
{"op":"mcm","clk":"11540884821","pt":1719499543574,"mc":[{"id":"1.230178315","rc":[{"atb":[[2.12,4.12],[1.87,3.75]],"id":70466763}],"con":true,"img":false}]}
{"op":"mcm","clk":"11540884900","pt":1719499544769,"mc":[{"id":"1.230178315","rc":[{"atb":[[2.12,0]],"id":45375136}],"con":true,"img":false}]}
{"op":"mcm","clk":"11540884957","pt":1719499546004,"mc":[{"id":"1.230178315","rc":[{"atb":[[2.12,2.12]],"id":70466763}],"con":true,"img":false}]}
{"op":"mcm","clk":"11540884964","pt":1719499546108,"mc":[{"id":"1.230178315","rc":[{"atb":[[2.18,4.5]],"id":70466763}],"con":true,"img":false}]}
{"op":"mcm","clk":"11540884988","pt":1719499546471,"mc":[{"id":"1.230178315","rc":[{"atb":[[1.07,11]],"id":70940946}],"con":true,"img":false}]}
{"op":"mcm","clk":"11540885016","pt":1719499546987,"mc":[{"id":"1.230178315","rc":[{"atb":[[1.07,1]],"id":70940946}],"con":true,"img":false}]}
{"op":"mcm","clk":"11540885042","pt":1719499547402,"mc":[{"id":"1.230178315","rc":[{"atl":[[5.5,0],[5.7,1]],"id":70466763},{"atl":[[4.3,1],[4.6,0]],"id":69979804},{"atl":[[65,2],[60,0]],"id":70940946},{"atl":[[5.1,0.84],[4.9,1]],"id":46251065}],"con":true,"img":false}]}
{"op":"mcm","clk":"11540885053","pt":1719499547505,"mc":[{"id":"1.230178315","rc":[{"atl":[[4.4,1]],"id":69979804}],"con":true,"img":false}]}
{"op":"mcm","clk":"11540885062","pt":1719499547712,"mc":[{"id":"1.230178315","rc":[{"atl":[[4,1.84]],"id":69979804},{"atb":[[1.08,53.75]],"id":70940946}],"con":true,"img":false}]}
{"op":"mcm","clk":"11540885067","pt":1719499547766,"mc":[{"id":"1.230178315","rc":[{"atl":[[4,3.84],[9.2,0]],"id":69979804}],"con":true,"img":false}]}
{"op":"mcm","clk":"11540885073","pt":1719499547868,"mc":[{"id":"1.230178315","rc":[{"atl":[[4,1.84],[4.4,3.84]],"id":69979804}],"con":true,"img":false}]}
{"op":"mcm","clk":"11540885077","pt":1719499547971,"mc":[{"id":"1.230178315","rc":[{"atl":[[4,3.84],[4.4,1]],"id":69979804}],"con":true,"img":false}]}
{"op":"mcm","clk":"11540885080","pt":1719499548074,"mc":[{"id":"1.230178315","rc":[{"atl":[[3.95,0.84]],"id":69979804},{"atb":[[1.91,4.96]],"id":46251065}],"con":true,"img":false}]}
{"op":"mcm","clk":"11540885119","pt":1719499548693,"mc":[{"id":"1.230178315","rc":[{"atb":[[2.2,3.75]],"id":70466763}],"con":true,"img":false}]}
{"op":"mcm","clk":"11540885128","pt":1719499548795,"mc":[{"id":"1.230178315","rc":[{"atb":[[2.12,0]],"id":70466763}],"con":true,"img":false}]}
{"op":"mcm","clk":"11540885132","pt":1719499548900,"mc":[{"id":"1.230178315","rc":[{"atb":[[1.11,35.89]],"id":70940946}],"con":true,"img":false}]}
{"op":"mcm","clk":"11540885141","pt":1719499549002,"mc":[{"id":"1.230178315","rc":[{"atb":[[1.12,35.89],[1.09,0]],"id":70940946}],"con":true,"img":false}]}
{"op":"mcm","clk":"11540885230","pt":1719499550310,"mc":[{"id":"1.230178315","rc":[{"atl":[[5.5,1],[5.7,0]],"id":70466763},{"atb":[[1.07,0]],"id":70940946},{"atl":[[70,0]],"id":70940946}],"con":true,"img":false}]}
{"op":"mcm","clk":"11540885238","pt":1719499550413,"mc":[{"id":"1.230178315","rc":[{"atb":[[1.1,1]],"id":70940946},{"atl":[[75,1]],"id":70940946},{"atl":[[5.1,1.84],[4.9,0]],"id":46251065}],"con":true,"img":false}]}
{"op":"mcm","clk":"11540885321","pt":1719499551609,"mc":[{"id":"1.230178315","rc":[{"atb":[[2.18,1]],"id":70466763}],"con":true,"img":false}]}
{"op":"mcm","clk":"11540885331","pt":1719499551713,"mc":[{"id":"1.230178315","rc":[{"atb":[[2.2,0],[1.87,8.5]],"id":70466763}],"con":true,"img":false}]}
{"op":"mcm","clk":"11540885340","pt":1719499551769,"mc":[{"id":"1.230178315","rc":[{"atb":[[2.22,3]],"id":70466763}],"con":true,"img":false}]}
{"op":"mcm","clk":"11540885349","pt":1719499551875,"mc":[{"id":"1.230178315","rc":[{"atb":[[2.24,3],[1.87,3.75]],"id":70466763}],"con":true,"img":false}]}
{"op":"mcm","clk":"11540885386","pt":1719499552489,"mc":[{"id":"1.230178315","rc":[{"atl":[[60,2]],"id":70940946}],"con":true,"img":false}]}
{"op":"mcm","clk":"11540885396","pt":1719499552594,"mc":[{"id":"1.230178315","rc":[{"atl":[[65,0]],"id":70940946}],"con":true,"img":false}]}
{"op":"mcm","clk":"11540885418","pt":1719499552904,"mc":[{"id":"1.230178315","rc":[{"atl":[[70,1],[75,0]],"id":70940946}],"con":true,"img":false}]}
{"op":"mcm","clk":"11540885444","pt":1719499553374,"mc":[{"id":"1.230178315","rc":[{"atb":[[1.67,3.75]],"id":69979804}],"con":true,"img":false}]}
{"op":"mcm","clk":"11540885448","pt":1719499553477,"mc":[{"id":"1.230178315","rc":[{"atl":[[4.3,0],[4.6,1],[4.4,0]],"id":69979804}],"con":true,"img":false}]}
{"op":"mcm","clk":"11540885551","pt":1719499554873,"mc":[{"id":"1.230178315","rc":[{"atl":[[5.5,0],[5.7,1]],"id":70466763},{"atl":[[4.3,1],[4.6,0],[4.4,1]],"id":69979804},{"atl":[[65,2],[60,0]],"id":70940946},{"atl":[[4.9,1]],"id":46251065}],"con":true,"img":false}]}
{"op":"mcm","clk":"11540885560","pt":1719499554976,"mc":[{"id":"1.230178315","rc":[{"atl":[[5.1,0.84]],"id":46251065}],"con":true,"img":false}]}
{"op":"mcm","clk":"11540885635","pt":1719499556104,"mc":[{"id":"1.230178315","rc":[{"atb":[[2.24,0],[2.22,9]],"id":70466763}],"con":true,"img":false}]}
{"op":"mcm","clk":"11540885681","pt":1719499556778,"mc":[{"id":"1.230178315","rc":[{"atb":[[2.12,1],[2.18,0]],"id":70466763},{"atl":[[5.5,1],[5.7,0]],"id":70466763},{"atl":[[4.1,1]],"id":63994056},{"atl":[[4.3,0],[4.6,1],[4.4,0]],"id":69979804},{"atl":[[65,0],[70,0],[75,1],[60,2]],"id":70940946},{"atl":[[4.9,0],[5.2,3.97]],"id":46251065}],"con":true,"img":false}]}
{"op":"mcm","clk":"11540885688","pt":1719499556880,"mc":[{"id":"1.230178315","rc":[{"atl":[[5.6,1]],"id":70466763},{"atb":[[1.62,3.11],[1.66,0]],"id":63994056},{"atl":[[4,0]],"id":63994056},{"atb":[[1.92,8.96],[1.97,0]],"id":46251065},{"atl":[[5.1,1.84]],"id":46251065}],"con":true,"img":false}]}
{"op":"mcm","clk":"11540885718","pt":1719499557191,"mc":[{"id":"1.230178315","rc":[{"atl":[[5.6,6.78]],"id":70466763}],"con":true,"img":false}]}
{"op":"mcm","clk":"11540885727","pt":1719499557294,"mc":[{"id":"1.230178315","rc":[{"atl":[[21,0],[6.2,7.78]],"id":70466763},{"atb":[[1.57,0]],"id":63994056}],"con":true,"img":false}]}
{"op":"mcm","clk":"11540885801","pt":1719499558282,"mc":[{"id":"1.230178315","rc":[{"atl":[[5.6,5.78],[5.8,1],[5.5,0]],"id":70466763},{"atl":[[4.6,0],[4.4,1]],"id":69979804},{"atl":[[70,1],[75,0]],"id":70940946},{"atl":[[5.1,0.84],[5,1],[5.2,2.97]],"id":46251065}],"con":true,"img":false}]}
{"op":"mcm","clk":"11540885819","pt":1719499558587,"mc":[{"id":"1.230178315","rc":[{"atl":[[5.8,0],[5.5,1.84]],"id":70466763},{"atl":[[4,1],[4.1,0]],"id":63994056},{"atl":[[4.6,1],[4.4,0]],"id":69979804},{"atl":[[5.1,1.84],[5,0]],"id":46251065}],"con":true,"img":false}]}
{"op":"mcm","clk":"11540885837","pt":1719499558792,"mc":[{"id":"1.230178315","rc":[{"atb":[[1.59,0]],"id":63994056}],"con":true,"img":false}]}
{"op":"mcm","clk":"11540885869","pt":1719499559102,"mc":[{"id":"1.230178315","rc":[{"atl":[[5.5,0.84],[5.7,1]],"id":70466763},{"atb":[[2.14,4.76]],"id":45375136},{"atb":[[1.58,15.92],[1.67,3]],"id":63994056},{"atb":[[1.46,28.07],[1.57,0],[1.67,0]],"id":69979804},{"atl":[[4.6,0],[4.4,1]],"id":69979804},{"atb":[[1.92,1],[1.77,28.07]],"id":46251065},{"atl":[[5.1,0.84],[4.9,1]],"id":46251065}],"con":true,"img":false}]}
{"op":"mcm","clk":"11540885878","pt":1719499559205,"mc":[{"id":"1.230178315","rc":[{"atb":[[1.87,5.47]],"id":70466763}],"con":true,"img":false}]}
{"op":"mcm","clk":"11540885900","pt":1719499559519,"mc":[{"id":"1.230178315","rc":[{"atb":[[1.58,9.12]],"id":63994056}],"con":true,"img":false}]}
{"op":"mcm","clk":"11540885949","pt":1719499560089,"mc":[{"id":"1.230178315","rc":[{"atb":[[1.61,5.16]],"id":63994056}],"con":true,"img":false}]}
{"op":"mcm","clk":"11540886005","pt":1719499560818,"mc":[{"id":"1.230178315","rc":[{"atb":[[1.61,0]],"id":63994056},{"atb":[[1.08,50]],"id":70940946},{"atb":[[1.91,9.21]],"id":46251065}],"con":true,"img":false}]}
{"op":"mcm","clk":"11540886024","pt":1719499560990,"mc":[{"id":"1.230178315","rc":[{"atl":[[70,3]],"id":70940946}],"con":true,"img":false}]}
{"op":"mcm","clk":"11540886030","pt":1719499561091,"mc":[{"id":"1.230178315","rc":[{"atl":[[60,0]],"id":70940946}],"con":true,"img":false}]}
{"op":"mcm","clk":"11540886049","pt":1719499561299,"mc":[{"id":"1.230178315","rc":[{"atb":[[1.91,4.96]],"id":46251065}],"con":true,"img":false}]}
{"op":"mcm","clk":"11540886077","pt":1719499561601,"mc":[{"id":"1.230178315","rc":[{"atl":[[70,2],[80,1]],"id":70940946}],"con":true,"img":false}]}
{"op":"mcm","clk":"11540886133","pt":1719499562383,"mc":[{"id":"1.230178315","rc":[{"atl":[[6.2,0],[5.9,2]],"id":70466763},{"atb":[[2.14,0]],"id":45375136}],"con":true,"img":false}]}
{"op":"mcm","clk":"11540886208","pt":1719499563310,"mc":[{"id":"1.230178315","rc":[{"atb":[[2.22,6]],"id":70466763}],"con":true,"img":false}]}
{"op":"mcm","clk":"11540886217","pt":1719499563413,"mc":[{"id":"1.230178315","rc":[{"atb":[[2.22,0],[1.87,12.47]],"id":70466763}],"con":true,"img":false}]}
{"op":"mcm","clk":"11540886248","pt":1719499563777,"mc":[{"id":"1.230178315","rc":[{"atb":[[1.1,4.75]],"id":70940946}],"con":true,"img":false}]}
{"op":"mcm","clk":"11540886287","pt":1719499564189,"mc":[{"id":"1.230178315","rc":[{"atb":[[2.12,0],[2.08,1]],"id":70466763},{"atb":[[1.92,0],[1.97,1]],"id":46251065}],"con":true,"img":false}]}
{"op":"mcm","clk":"11540886297","pt":1719499564294,"mc":[{"id":"1.230178315","rc":[{"atb":[[1.87,5.47],[2.08,13.47]],"id":70466763}],"con":true,"img":false}]}
{"op":"mcm","clk":"11540886305","pt":1719499564397,"mc":[{"id":"1.230178315","rc":[{"atb":[[1.11,41.15]],"id":70940946}],"con":true,"img":false}]}
{"op":"mcm","clk":"11540886315","pt":1719499564502,"mc":[{"id":"1.230178315","rc":[{"atl":[[5.6,6.78],[5.7,0]],"id":70466763},{"atb":[[2.02,1]],"id":45375136},{"atl":[[5.3,0],[5.5,1]],"id":45375136},{"atl":[[4,0],[3.95,1],[4.1,1]],"id":63994056},{"atb":[[1.78,0]],"id":69979804},{"atl":[[4.3,1],[4.4,0]],"id":69979804},{"atl":[[5,1]],"id":46251065}],"con":true,"img":false}]}
{"op":"mcm","clk":"11540886325","pt":1719499564603,"mc":[{"id":"1.230178315","rc":[{"atl":[[10.5,0],[4.1,3]],"id":63994056},{"atl":[[4.9,0]],"id":46251065}],"con":true,"img":false}]}
{"op":"mcm","clk":"11540886334","pt":1719499564709,"mc":[{"id":"1.230178315","rc":[{"atl":[[10.5,2],[4.1,1]],"id":63994056}],"con":true,"img":false}]}
{"op":"mcm","clk":"11540886385","pt":1719499565226,"mc":[{"id":"1.230178315","rc":[{"atl":[[5.7,1]],"id":70466763},{"atl":[[3.95,0],[4.1,0]],"id":63994056},{"atl":[[4.3,0],[4.4,1]],"id":69979804}],"con":true,"img":false}]}
{"op":"mcm","clk":"11540886397","pt":1719499565311,"mc":[{"id":"1.230178315","rc":[{"atl":[[5.6,5.78]],"id":70466763}],"con":true,"img":false}]}
{"op":"mcm","clk":"11540886418","pt":1719499565591,"mc":[{"id":"1.230178315","rc":[{"atl":[[10,0.84]],"id":63994056}],"con":true,"img":false}]}
{"op":"mcm","clk":"11540886462","pt":1719499566104,"mc":[{"id":"1.230178315","rc":[{"atl":[[70,0],[60,2]],"id":70940946}],"con":true,"img":false}]}
{"op":"mcm","clk":"11540886544","pt":1719499567204,"mc":[{"id":"1.230178315","rc":[{"atb":[[1.61,9.06]],"id":63994056}],"con":true,"img":false}]}
{"op":"mcm","clk":"11540886556","pt":1719499567403,"mc":[{"id":"1.230178315","rc":[{"atb":[[1.11,5.26]],"id":70940946}],"con":true,"img":false}]}
{"op":"mcm","clk":"11540886562","pt":1719499567508,"mc":[{"id":"1.230178315","rc":[{"atb":[[1.12,0],[1.1,45.9]],"id":70940946},{"atl":[[70,1],[80,0]],"id":70940946}],"con":true,"img":false}]}
{"op":"mcm","clk":"11540886571","pt":1719499567612,"mc":[{"id":"1.230178315","rc":[{"atb":[[1.14,28.2]],"id":70940946}],"con":true,"img":false}]}
{"op":"mcm","clk":"11540886576","pt":1719499567716,"mc":[{"id":"1.230178315","rc":[{"atb":[[1.09,51.16],[1.1,4.75]],"id":70940946}],"con":true,"img":false}]}
{"op":"mcm","clk":"11540886583","pt":1719499567820,"mc":[{"id":"1.230178315","rc":[{"atb":[[1.15,28.2],[1.09,0]],"id":70940946}],"con":true,"img":false}]}
{"op":"mcm","clk":"11540886602","pt":1719499568029,"mc":[{"id":"1.230178315","rc":[{"atl":[[4.1,1]],"id":63994056},{"atb":[[1.1,1]],"id":70940946}],"con":true,"img":false}]}
{"op":"mcm","clk":"11540886610","pt":1719499568090,"mc":[{"id":"1.230178315","rc":[{"atl":[[5.8,1],[5.7,0]],"id":70466763},{"atb":[[1.13,1]],"id":70940946},{"atb":[[1.92,1],[1.97,0]],"id":46251065}],"con":true,"img":false}]}
{"op":"mcm","clk":"11540886618","pt":1719499568191,"mc":[{"id":"1.230178315","rc":[{"atb":[[1.1,0]],"id":70940946}],"con":true,"img":false}]}
{"op":"mcm","clk":"11540886638","pt":1719499568395,"mc":[{"id":"1.230178315","rc":[{"atb":[[1.74,18.94],[2.08,1]],"id":70466763}],"con":true,"img":false}]}
{"op":"mcm","clk":"11540886661","pt":1719499568709,"mc":[{"id":"1.230178315","rc":[{"atb":[[1.11,0]],"id":70940946}],"con":true,"img":false}]}
{"op":"mcm","clk":"11540886678","pt":1719499569018,"mc":[{"id":"1.230178315","rc":[{"atb":[[1.88,3.42]],"id":70466763}],"con":true,"img":false}]}
{"op":"mcm","clk":"11540886969","pt":1719499573510,"mc":[{"id":"1.230178315","rc":[{"atb":[[1.89,5.47],[1.74,0]],"id":70466763}],"con":true,"img":false}]}
{"op":"mcm","clk":"11540887024","pt":1719499574503,"mc":[{"id":"1.230178315","rc":[{"atb":[[2.08,0]],"id":70466763},{"atl":[[5.8,0],[5.9,3]],"id":70466763},{"atl":[[5.6,1],[5.5,0]],"id":45375136},{"atb":[[1.6,9.12],[1.58,0]],"id":63994056},{"atl":[[4.3,1],[4.4,0]],"id":69979804},{"atb":[[1.91,0]],"id":46251065}],"con":true,"img":false}]}
{"op":"mcm","clk":"11540887032","pt":1719499574610,"mc":[{"id":"1.230178315","rc":[{"atb":[[2.24,1]],"id":70466763},{"atb":[[1.92,0]],"id":46251065},{"atl":[[5,0],[4.9,1]],"id":46251065}],"con":true,"img":false}]}
{"op":"mcm","clk":"11540887050","pt":1719499574913,"mc":[{"id":"1.230178315","rc":[{"atb":[[1.87,0]],"id":70466763}],"con":true,"img":false}]}
{"op":"mcm","clk":"11540887063","pt":1719499575119,"mc":[{"id":"1.230178315","rc":[{"atb":[[2.16,9.53]],"id":45375136}],"con":true,"img":false}]}
{"op":"mcm","clk":"11540887076","pt":1719499575327,"mc":[{"id":"1.230178315","rc":[{"atb":[[1.88,0]],"id":70466763}],"con":true,"img":false}]}
{"op":"mcm","clk":"11540887083","pt":1719499575429,"mc":[{"id":"1.230178315","rc":[{"atb":[[1.89,0],[1.74,18.42]],"id":70466763}],"con":true,"img":false}]}
{"op":"mcm","clk":"11540887089","pt":1719499575532,"mc":[{"id":"1.230178315","rc":[{"atb":[[1.9,3]],"id":70466763}],"con":true,"img":false}]}
{"op":"mcm","clk":"11540887097","pt":1719499575594,"mc":[{"id":"1.230178315","rc":[{"atb":[[1.74,0],[1.9,6]],"id":70466763}],"con":true,"img":false}]}
{"op":"mcm","clk":"11540887126","pt":1719499576101,"mc":[{"id":"1.230178315","rc":[{"atb":[[1.62,8.27]],"id":63994056}],"con":true,"img":false}]}
{"op":"mcm","clk":"11540887169","pt":1719499576719,"mc":[{"id":"1.230178315","rc":[{"atb":[[1.91,2.31]],"id":46251065}],"con":true,"img":false}]}
{"op":"mcm","clk":"11540887353","pt":1719499579612,"mc":[{"id":"1.230178315","rc":[{"atb":[[1.12,3.75]],"id":70940946}],"con":true,"img":false}]}
{"op":"mcm","clk":"11540887371","pt":1719499579820,"mc":[{"id":"1.230178315","rc":[{"atb":[[1.9,3]],"id":70466763},{"atb":[[1.61,20.34]],"id":63994056}],"con":true,"img":false}]}
{"op":"mcm","clk":"11540887378","pt":1719499579923,"mc":[{"id":"1.230178315","rc":[{"atb":[[1.74,18.42],[1.9,0]],"id":70466763},{"atb":[[1.6,0]],"id":63994056}],"con":true,"img":false}]}
{"op":"mcm","clk":"11540887385","pt":1719499580027,"mc":[{"id":"1.230178315","rc":[{"atb":[[1.91,3.41]],"id":70466763},{"atl":[[6,6],[5.9,1]],"id":70466763},{"atl":[[5.6,0],[5.5,1]],"id":45375136},{"atb":[[1.68,8.28],[1.61,9.06]],"id":63994056},{"atb":[[1.46,0],[1.57,28.07]],"id":69979804},{"atl":[[4.4,1]],"id":69979804},{"atb":[[1.99,2.31],[1.77,0]],"id":46251065}],"con":true,"img":false}]}
{"op":"mcm","clk":"11540887392","pt":1719499580135,"mc":[{"id":"1.230178315","rc":[{"atl":[[4.3,0]],"id":69979804}],"con":true,"img":false}]}
{"op":"mcm","clk":"11540887399","pt":1719499580233,"mc":[{"id":"1.230178315","rc":[{"atb":[[1.67,19.56],[1.68,0]],"id":63994056},{"atb":[[1.14,31.95]],"id":70940946}],"con":true,"img":false}]}
{"op":"mcm","clk":"11540887435","pt":1719499580714,"mc":[{"id":"1.230178315","rc":[{"atb":[[1.92,3.41],[1.74,0]],"id":70466763}],"con":true,"img":false}]}
{"op":"mcm","clk":"11540887491","pt":1719499581397,"mc":[{"id":"1.230178315","rc":[{"atb":[[1.91,0]],"id":46251065}],"con":true,"img":false}]}
{"op":"mcm","clk":"11540887506","pt":1719499581598,"mc":[{"id":"1.230178315","rc":[{"atb":[[1.62,6.16],[1.7,2.11]],"id":63994056}],"con":true,"img":false}]}
{"op":"mcm","clk":"11540887516","pt":1719499581706,"mc":[{"id":"1.230178315","rc":[{"atl":[[6,3.12]],"id":69979804}],"con":true,"img":false}]}
{"op":"mcm","clk":"11540887522","pt":1719499581807,"mc":[{"id":"1.230178315","rc":[{"atl":[[5.6,0]],"id":70466763}],"con":true,"img":false}]}
{"op":"mcm","clk":"11540887546","pt":1719499582116,"mc":[{"id":"1.230178315","rc":[{"atl":[[5.6,5.78],[5.8,0.84]],"id":70466763}],"con":true,"img":false}]}
{"op":"mcm","clk":"11540887553","pt":1719499582219,"mc":[{"id":"1.230178315","rc":[{"atl":[[5.5,0]],"id":70466763}],"con":true,"img":false}]}
{"op":"mcm","clk":"11540887569","pt":1719499582424,"mc":[{"id":"1.230178315","rc":[{"atb":[[1.62,1]],"id":63994056}],"con":true,"img":false}]}
{"op":"mcm","clk":"11540887603","pt":1719499582736,"mc":[{"id":"1.230178315","rc":[{"atl":[[5.8,0]],"id":70466763}],"con":true,"img":false}]}
{"op":"mcm","clk":"11540887621","pt":1719499582941,"mc":[{"id":"1.230178315","rc":[{"atl":[[6,0]],"id":69979804}],"con":true,"img":false}]}
{"op":"mcm","clk":"11540887690","pt":1719499583925,"mc":[{"id":"1.230178315","rc":[{"atb":[[1.53,0]],"id":63994056}],"con":true,"img":false}]}
{"op":"mcm","clk":"11540887749","pt":1719499584803,"mc":[{"id":"1.230178315","rc":[{"atb":[[1.91,0]],"id":70466763},{"atb":[[1.67,16.56],[1.61,0]],"id":63994056},{"atb":[[1.98,5.63]],"id":46251065}],"con":true,"img":false}]}
{"op":"mcm","clk":"11540887755","pt":1719499584907,"mc":[{"id":"1.230178315","rc":[{"atb":[[1.74,18.42],[1.93,3.5]],"id":70466763},{"atb":[[1.7,7.11]],"id":63994056},{"atb":[[1.14,3.75]],"id":70940946},{"atb":[[1.99,6.31]],"id":46251065}],"con":true,"img":false}]}
{"op":"mcm","clk":"11540887760","pt":1719499585010,"mc":[{"id":"1.230178315","rc":[{"atb":[[1.92,0]],"id":70466763},{"atb":[[1.71,7.78]],"id":63994056},{"atb":[[1.15,0],[1.13,32.95]],"id":70940946}],"con":true,"img":false}]}
{"op":"mcm","clk":"11540887771","pt":1719499585214,"mc":[{"id":"1.230178315","rc":[{"atb":[[1.12,0],[1.17,23.22]],"id":70940946}],"con":true,"img":false}]}
{"op":"mcm","clk":"11540887774","pt":1719499585318,"mc":[{"id":"1.230178315","rc":[{"atb":[[1.67,0],[1.71,15.57]],"id":63994056},{"atb":[[1.18,23.23],[1.13,1]],"id":70940946}],"con":true,"img":false}]}
{"op":"mcm","clk":"11540887789","pt":1719499585523,"mc":[{"id":"1.230178315","rc":[{"atb":[[1.14,0]],"id":70940946}],"con":true,"img":false}]}
{"op":"mcm","clk":"11540887802","pt":1719499585834,"mc":[{"id":"1.230178315","rc":[{"atl":[[5.7,11.56]],"id":70466763}],"con":true,"img":false}]}
{"op":"mcm","clk":"11540887808","pt":1719499585937,"mc":[{"id":"1.230178315","rc":[{"atb":[[1.74,0],[1.94,3.5]],"id":70466763},{"atl":[[6,0]],"id":70466763}],"con":true,"img":false}]}
{"op":"mcm","clk":"11540887820","pt":1719499586147,"mc":[{"id":"1.230178315","rc":[{"atb":[[1.16,1],[1.13,0]],"id":70940946},{"atb":[[2.04,5.69]],"id":46251065}],"con":true,"img":false}]}
{"op":"mcm","clk":"11540887830","pt":1719499586200,"mc":[{"id":"1.230178315","rc":[{"atb":[[1.99,4],[2.06,5.7]],"id":46251065}],"con":true,"img":false}]}
{"op":"mcm","clk":"11540887842","pt":1719499586407,"mc":[{"id":"1.230178315","rc":[{"atb":[[1.17,48.12]],"id":70940946}],"con":true,"img":false}]}
{"op":"mcm","clk":"11540887878","pt":1719499587026,"mc":[{"id":"1.230178315","rc":[{"atb":[[1.71,23.92]],"id":63994056}],"con":true,"img":false}]}
{"op":"mcm","clk":"11540887941","pt":1719499587904,"mc":[{"id":"1.230178315","rc":[{"atb":[[1.67,5.15]],"id":69979804}],"con":true,"img":false}]}
{"op":"mcm","clk":"11540887956","pt":1719499588212,"mc":[{"id":"1.230178315","rc":[{"atb":[[2.02,0],[2.12,1]],"id":45375136},{"atl":[[4,1]],"id":63994056},{"atl":[[4.4,0]],"id":69979804}],"con":true,"img":false}]}
{"op":"mcm","clk":"11540887965","pt":1719499588317,"mc":[{"id":"1.230178315","rc":[{"atl":[[4.1,0]],"id":63994056},{"atl":[[4.3,1]],"id":69979804}],"con":true,"img":false}]}
{"op":"mcm","clk":"11540887974","pt":1719499588423,"mc":[{"id":"1.230178315","rc":[{"atl":[[4,2]],"id":69979804}],"con":true,"img":false}]}
{"op":"mcm","clk":"11540887982","pt":1719499588524,"mc":[{"id":"1.230178315","rc":[{"atl":[[4,0],[4.3,3.85]],"id":69979804}],"con":true,"img":false}]}
{"op":"mcm","clk":"11540887989","pt":1719499588626,"mc":[{"id":"1.230178315","rc":[{"atl":[[4.3,2.85],[4.1,1]],"id":69979804},{"atl":[[4.7,1]],"id":46251065}],"con":true,"img":false}]}
{"op":"mcm","clk":"11540887998","pt":1719499588730,"mc":[{"id":"1.230178315","rc":[{"atl":[[3.95,7.93]],"id":69979804},{"atl":[[4.9,0]],"id":46251065}],"con":true,"img":false}]}
{"op":"mcm","clk":"11540888005","pt":1719499588834,"mc":[{"id":"1.230178315","rc":[{"atb":[[2.02,1],[2.12,0]],"id":45375136},{"atl":[[4,0],[3.95,1]],"id":63994056},{"atl":[[4.1,0],[3.9,2.85],[4.2,1]],"id":69979804}],"con":true,"img":false}]}
{"op":"mcm","clk":"11540888015","pt":1719499588938,"mc":[{"id":"1.230178315","rc":[{"atb":[[2.12,1]],"id":45375136},{"atl":[[10.5,0],[4.1,2],[3.9,1]],"id":63994056},{"atl":[[4.3,1],[3.95,0.84],[4.1,1]],"id":69979804},{"atl":[[4.9,1],[4.7,0]],"id":46251065}],"con":true,"img":false}]}
{"op":"mcm","clk":"11540888020","pt":1719499589041,"mc":[{"id":"1.230178315","rc":[{"atb":[[2.02,0]],"id":45375136},{"atl":[[3.95,0],[10.5,2],[4.1,0]],"id":63994056},{"atl":[[4.1,4.7],[4.2,0]],"id":69979804}],"con":true,"img":false}]}
{"op":"mcm","clk":"11540888030","pt":1719499589144,"mc":[{"id":"1.230178315","rc":[{"atl":[[5.5,0.84]],"id":70466763},{"atl":[[4.1,2]],"id":63994056},{"atl":[[3.85,0.84],[3.9,0]],"id":69979804}],"con":true,"img":false}]}
{"op":"mcm","clk":"11540888036","pt":1719499589246,"mc":[{"id":"1.230178315","rc":[{"atl":[[5.8,1],[5.9,0]],"id":70466763},{"atb":[[2.02,1],[2.12,0]],"id":45375136},{"atl":[[10,2.84],[10.5,0],[3.95,1],[4.1,0],[3.9,0]],"id":63994056},{"atl":[[4.3,0],[4.1,3.7],[3.9,1.99],[4.2,1]],"id":69979804},{"atl":[[4.9,0],[4.7,1]],"id":46251065}],"con":true,"img":false}]}
{"op":"mcm","clk":"11540888044","pt":1719499589301,"mc":[{"id":"1.230178315","rc":[{"atl":[[10,0.84],[4.1,3]],"id":63994056},{"atl":[[4.4,1]],"id":69979804}],"con":true,"img":false}]}
{"op":"mcm","clk":"11540888049","pt":1719499589406,"mc":[{"id":"1.230178315","rc":[{"atl":[[3.95,0],[10.5,3.85],[4.1,1]],"id":63994056},{"atl":[[4.2,0]],"id":69979804}],"con":true,"img":false}]}
{"op":"mcm","clk":"11540888058","pt":1719499589611,"mc":[{"id":"1.230178315","rc":[{"atb":[[1.93,0]],"id":70466763},{"atb":[[1.7,2.11]],"id":63994056},{"atb":[[1.99,0]],"id":46251065}],"con":true,"img":false}]}
{"op":"mcm","clk":"11540888067","pt":1719499589715,"mc":[{"id":"1.230178315","rc":[{"atb":[[1.95,4]],"id":70466763},{"atb":[[1.72,3.34]],"id":63994056},{"atl":[[10,0]],"id":63994056},{"atb":[[2.08,3]],"id":46251065}],"con":true,"img":false}]}
{"op":"mcm","clk":"11540888074","pt":1719499589817,"mc":[{"id":"1.230178315","rc":[{"atb":[[1.74,18.42],[1.94,0]],"id":70466763}],"con":true,"img":false}]}
{"op":"mcm","clk":"11540888084","pt":1719499589922,"mc":[{"id":"1.230178315","rc":[{"atb":[[1.73,3.34],[1.71,16.13]],"id":63994056}],"con":true,"img":false}]}
{"op":"mcm","clk":"11540888165","pt":1719499591057,"mc":[{"id":"1.230178315","rc":[{"atb":[[1.74,0],[1.96,4]],"id":70466763}],"con":true,"img":false}]}
{"op":"mcm","clk":"11540888188","pt":1719499591317,"mc":[{"id":"1.230178315","rc":[{"atb":[[1.94,5.46]],"id":70466763},{"atb":[[2.06,0],[2.1,5.7]],"id":46251065}],"con":true,"img":false}]}
{"op":"mcm","clk":"11540888198","pt":1719499591418,"mc":[{"id":"1.230178315","rc":[{"atb":[[1.69,3.12]],"id":63994056}],"con":true,"img":false}]}
{"op":"mcm","clk":"11540888232","pt":1719499591936,"mc":[{"id":"1.230178315","rc":[{"atb":[[1.94,0]],"id":70466763},{"atb":[[1.69,0]],"id":63994056},{"atb":[[2.04,11.82]],"id":46251065}],"con":true,"img":false}]}
{"op":"mcm","clk":"11540888240","pt":1719499592039,"mc":[{"id":"1.230178315","rc":[{"atb":[[2.04,11.11]],"id":46251065}],"con":true,"img":false}]}
{"op":"mcm","clk":"11540888268","pt":1719499592507,"mc":[{"id":"1.230178315","rc":[{"atb":[[2.04,5.69]],"id":46251065}],"con":true,"img":false}]}
{"op":"mcm","clk":"11540888336","pt":1719499593449,"mc":[{"id":"1.230178315","rc":[{"spn":3.87,"spf":"NaN","id":70466763},{"spn":3.84,"spf":"NaN","id":45375136},{"atb":[[1.71,21.29]],"id":63994056},{"spn":2.91,"spf":"NaN","id":63994056},{"spn":2.85,"spf":"NaN","id":69979804},{"spn":30.59,"spf":"NaN","id":70940946},{"spn":2.09,"spf":1.0,"id":46251065}],"con":true,"img":false}]}
{"op":"mcm","clk":"11540888388","pt":1719499594129,"mc":[{"id":"1.230178315","rc":[{"atl":[[3.9,3.99]],"id":69979804}],"con":true,"img":false}]}
{"op":"mcm","clk":"11540888400","pt":1719499594232,"mc":[{"id":"1.230178315","rc":[{"atb":[[1.95,0]],"id":70466763},{"atl":[[4.1,0]],"id":69979804},{"atb":[[2.08,0]],"id":46251065}],"con":true,"img":false}]}
{"op":"mcm","clk":"11540888408","pt":1719499594334,"mc":[{"id":"1.230178315","rc":[{"atb":[[1.97,4.27]],"id":70466763},{"atb":[[2.12,3]],"id":46251065}],"con":true,"img":false}]}
{"op":"mcm","clk":"11540888431","pt":1719499594642,"mc":[{"id":"1.230178315","rc":[{"atb":[[1.15,3.75]],"id":70940946}],"con":true,"img":false}]}
{"op":"mcm","clk":"11540888438","pt":1719499594745,"mc":[{"id":"1.230178315","rc":[{"atl":[[5.8,0],[5.9,1]],"id":70466763},{"atl":[[4.9,1],[4.7,0]],"id":46251065}],"con":true,"img":false}]}
{"op":"mcm","clk":"11540888449","pt":1719499594953,"mc":[{"id":"1.230178315","rc":[{"atb":[[1.71,16.13]],"id":63994056}],"con":true,"img":false}]}
{"op":"mcm","clk":"11540888473","pt":1719499595213,"mc":[{"id":"1.230178315","rc":[{"atb":[[1.17,51.87]],"id":70940946}],"con":true,"img":false}]}
{"op":"mcm","clk":"11540888514","pt":1719499595732,"mc":[{"id":"1.230178315","rc":[{"atl":[[5.6,11.56]],"id":70466763},{"atb":[[1.51,28.07]],"id":69979804},{"atb":[[2,11.4]],"id":46251065}],"con":true,"img":false}]}
{"op":"mcm","clk":"11540888523","pt":1719499595830,"mc":[{"id":"1.230178315","rc":[{"atl":[[5.7,0]],"id":70466763},{"atb":[[1.73,0],[1.63,18.42]],"id":63994056},{"atb":[[1.57,0]],"id":69979804},{"atb":[[2.1,0]],"id":46251065}],"con":true,"img":false}]}
{"op":"mcm","clk":"11540888531","pt":1719499595934,"mc":[{"id":"1.230178315","rc":[{"atb":[[1.67,0]],"id":69979804}],"con":true,"img":false}]}
{"op":"mcm","clk":"11540888716","pt":1719499598835,"mc":[{"id":"1.230178315","rc":[{"atl":[[11.5,3.25]],"id":70466763}],"con":true,"img":false}]}
{"op":"mcm","clk":"11540888828","pt":1719499600817,"mc":[{"id":"1.230178315","rc":[{"atl":[[6,3.25]],"id":69979804},{"atb":[[2,0],[2.02,8.7]],"id":46251065},{"atl":[[5.2,0]],"id":46251065}],"con":true,"img":false}]}
{"op":"mcm","clk":"11540888839","pt":1719499600931,"mc":[{"id":"1.230178315","rc":[{"atl":[[5.8,1],[5.9,0]],"id":70466763},{"atb":[[2.02,0],[2.12,1]],"id":45375136},{"atl":[[4,1]],"id":63994056},{"atl":[[4.3,1],[4.4,0]],"id":69979804}],"con":true,"img":false}]}
{"op":"mcm","clk":"11540888844","pt":1719499601027,"mc":[{"id":"1.230178315","rc":[{"atl":[[4.1,0]],"id":63994056}],"con":true,"img":false}]}
{"op":"mcm","clk":"11540888853","pt":1719499601131,"mc":[{"id":"1.230178315","rc":[{"atl":[[11.5,0]],"id":70466763},{"atl":[[6,0],[3.9,2]],"id":69979804},{"atb":[[1.15,0]],"id":70940946},{"atl":[[5.1,0]],"id":46251065}],"con":true,"img":false}]}
{"op":"mcm","clk":"11540888861","pt":1719499601235,"mc":[{"id":"1.230178315","rc":[{"atl":[[3.95,3.69],[4.1,1],[3.9,0]],"id":69979804},{"atl":[[19.5,5.41],[4.9,0],[5.9,0],[4.7,1]],"id":46251065}],"con":true,"img":false}]}
{"op":"mcm","clk":"11540888870","pt":1719499601340,"mc":[{"id":"1.230178315","rc":[{"atl":[[5.8,0],[5.9,1]],"id":70466763},{"atb":[[2.02,1],[2.12,0]],"id":45375136},{"atl":[[4,0],[3.95,1]],"id":63994056},{"atl":[[4.3,0],[3.85,7.93],[4.1,5.55],[4.2,1]],"id":69979804},{"atl":[[19.5,0],[5.9,3.57]],"id":46251065}],"con":true,"img":false}]}
{"op":"mcm","clk":"11540888877","pt":1719499601439,"mc":[{"id":"1.230178315","rc":[{"atl":[[3.95,0.84],[3.8,5.55]],"id":69979804},{"atl":[[19.5,3.86],[5.9,0]],"id":46251065}],"con":true,"img":false}]}
{"op":"mcm","clk":"11540888881","pt":1719499601549,"mc":[{"id":"1.230178315","rc":[{"atl":[[4.1,1]],"id":69979804}],"con":true,"img":false}]}
{"op":"mcm","clk":"11540888888","pt":1719499601649,"mc":[{"id":"1.230178315","rc":[{"atl":[[3.95,0]],"id":69979804}],"con":true,"img":false}]}
{"op":"mcm","clk":"11540888911","pt":1719499602066,"mc":[{"id":"1.230178315","rc":[{"atl":[[3.85,0.84]],"id":69979804}],"con":true,"img":false}]}
{"op":"mcm","clk":"11540888917","pt":1719499602128,"mc":[{"id":"1.230178315","rc":[{"atl":[[4.1,7.4],[3.75,0.84]],"id":69979804}],"con":true,"img":false}]}
{"op":"mcm","clk":"11540888924","pt":1719499602226,"mc":[{"id":"1.230178315","rc":[{"atl":[[3.85,7.24],[4.1,0],[3.8,0],[4.4,1],[4.2,0]],"id":69979804},{"atl":[[4.9,1]],"id":46251065}],"con":true,"img":false}]}
{"op":"mcm","clk":"11540888932","pt":1719499602331,"mc":[{"id":"1.230178315","rc":[{"atl":[[4.1,1]],"id":63994056},{"atl":[[3.85,0.84],[3.8,8.84],[4.4,9.1]],"id":69979804},{"atl":[[4.7,0]],"id":46251065}],"con":true,"img":false}]}
{"op":"mcm","clk":"11540888942","pt":1719499602432,"mc":[{"id":"1.230178315","rc":[{"atl":[[3.95,0]],"id":63994056},{"atl":[[3.8,17.68],[4.4,1]],"id":69979804},{"atl":[[4.9,0]],"id":46251065}],"con":true,"img":false}]}
{"op":"mcm","clk":"11540888953","pt":1719499602535,"mc":[{"id":"1.230178315","rc":[{"atl":[[4.1,0]],"id":63994056},{"atl":[[3.85,10.53],[3.8,8.84]],"id":69979804}],"con":true,"img":false}]}
{"op":"mcm","clk":"11540888980","pt":1719499602848,"mc":[{"id":"1.230178315","rc":[{"atl":[[4.9,1]],"id":46251065}],"con":true,"img":false}]}
{"op":"mcm","clk":"11540888990","pt":1719499602953,"mc":[{"id":"1.230178315","rc":[{"atl":[[4.1,1]],"id":63994056}],"con":true,"img":false}]}
{"op":"mcm","clk":"11540889011","pt":1719499603164,"mc":[{"id":"1.230178315","rc":[{"atl":[[10,0.84]],"id":63994056}],"con":true,"img":false}]}
{"op":"mcm","clk":"11540889027","pt":1719499603334,"mc":[{"id":"1.230178315","rc":[{"atb":[[1.67,5.34]],"id":69979804}],"con":true,"img":false}]}
{"op":"mcm","clk":"11540889037","pt":1719499603425,"mc":[{"id":"1.230178315","rc":[{"atl":[[3.8,17.68]],"id":69979804}],"con":true,"img":false}]}
{"op":"mcm","clk":"11540889045","pt":1719499603529,"mc":[{"id":"1.230178315","rc":[{"atb":[[1.67,0]],"id":69979804},{"atl":[[3.85,0.84]],"id":69979804}],"con":true,"img":false}]}
{"op":"mcm","clk":"11540889063","pt":1719499603736,"mc":[{"id":"1.230178315","rc":[{"atb":[[1.98,0]],"id":46251065}],"con":true,"img":false}]}
{"op":"mcm","clk":"11540889073","pt":1719499603842,"mc":[{"id":"1.230178315","rc":[{"atb":[[1.86,0]],"id":69979804}],"con":true,"img":false}]}
{"op":"mcm","clk":"11540889079","pt":1719499603942,"mc":[{"id":"1.230178315","rc":[{"atb":[[1.71,8.34]],"id":63994056},{"atb":[[1.69,4]],"id":69979804}],"con":true,"img":false}]}
{"op":"mcm","clk":"11540889113","pt":1719499604360,"mc":[{"id":"1.230178315","rc":[{"atb":[[2.08,5.11]],"id":46251065}],"con":true,"img":false}]}
{"op":"mcm","clk":"11540889120","pt":1719499604462,"mc":[{"id":"1.230178315","rc":[{"atb":[[1.74,1],[1.7,1]],"id":69979804}],"con":true,"img":false}]}
{"op":"mcm","clk":"11540889131","pt":1719499604566,"mc":[{"id":"1.230178315","rc":[{"atl":[[6,1],[5.9,0]],"id":70466763},{"atl":[[5.6,1],[5.5,0]],"id":45375136},{"atb":[[1.62,0],[1.75,7.36]],"id":63994056},{"atl":[[4,1],[4.1,0]],"id":63994056},{"atl":[[4.3,1],[4.4,0]],"id":69979804},{"atl":[[65,2],[60,0]],"id":70940946},{"atl":[[5,1],[4.9,0]],"id":46251065}],"con":true,"img":false}]}
{"op":"mcm","clk":"11540889150","pt":1719499604829,"mc":[{"id":"1.230178315","rc":[{"atb":[[1.17,28.64]],"id":70940946}],"con":true,"img":false}]}
{"op":"mcm","clk":"11540889176","pt":1719499605238,"mc":[{"id":"1.230178315","rc":[{"atl":[[6,0],[5.9,1]],"id":70466763},{"atl":[[5.6,0],[5.5,1]],"id":45375136},{"atb":[[1.74,0]],"id":69979804},{"atb":[[1.2,19.74]],"id":70940946},{"atl":[[70,0],[75,1]],"id":70940946},{"atl":[[5,0],[4.9,1]],"id":46251065}],"con":true,"img":false}]}
{"op":"mcm","clk":"11540889185","pt":1719499605344,"mc":[{"id":"1.230178315","rc":[{"atb":[[1.18,0],[1.21,23.23],[1.17,24.89]],"id":70940946}],"con":true,"img":false}]}
{"op":"mcm","clk":"11540889190","pt":1719499605445,"mc":[{"id":"1.230178315","rc":[{"atb":[[1.16,0],[1.19,1]],"id":70940946}],"con":true,"img":false}]}
{"op":"mcm","clk":"11540889215","pt":1719499605757,"mc":[{"id":"1.230178315","rc":[{"atb":[[1.96,9.47]],"id":70466763}],"con":true,"img":false}]}
{"op":"mcm","clk":"11540889226","pt":1719499605859,"mc":[{"id":"1.230178315","rc":[{"atb":[[1.65,18.42]],"id":63994056}],"con":true,"img":false}]}
{"op":"mcm","clk":"11540889234","pt":1719499605964,"mc":[{"id":"1.230178315","rc":[{"atl":[[5.8,1],[5.9,0]],"id":70466763},{"atb":[[2.02,0],[2.12,1]],"id":45375136},{"atb":[[1.63,0],[1.7,0],[1.75,9.48]],"id":63994056},{"atl":[[4,0],[3.95,1]],"id":63994056}],"con":true,"img":false}]}
{"op":"mcm","clk":"11540889263","pt":1719499606337,"mc":[{"id":"1.230178315","rc":[{"atb":[[2.08,10.33]],"id":46251065}],"con":true,"img":false}]}
{"op":"mcm","clk":"11540889280","pt":1719499606643,"mc":[{"id":"1.230178315","rc":[{"atl":[[3.85,1]],"id":63994056},{"atl":[[4.9,0]],"id":46251065}],"con":true,"img":false}]}
{"op":"mcm","clk":"11540889286","pt":1719499606741,"mc":[{"id":"1.230178315","rc":[{"atl":[[3.95,0]],"id":63994056},{"atl":[[4.3,0],[4.1,1]],"id":69979804},{"atl":[[4.7,1]],"id":46251065}],"con":true,"img":false}]}
{"op":"mcm","clk":"11540889324","pt":1719499607261,"mc":[{"id":"1.230178315","rc":[{"atl":[[5.8,0],[5.9,1]],"id":70466763},{"atb":[[2.02,1]],"id":45375136},{"atl":[[3.85,0],[3.9,1]],"id":63994056}],"con":true,"img":false}]}
{"op":"mcm","clk":"11540889328","pt":1719499607362,"mc":[{"id":"1.230178315","rc":[{"atb":[[2.12,0]],"id":45375136},{"atl":[[10.5,0],[4.1,2]],"id":63994056}],"con":true,"img":false}]}
{"op":"mcm","clk":"11540889334","pt":1719499607466,"mc":[{"id":"1.230178315","rc":[{"atl":[[4,1],[3.9,0]],"id":63994056},{"atl":[[4.3,1],[4.1,0]],"id":69979804},{"atl":[[4.9,1],[4.7,0]],"id":46251065}],"con":true,"img":false}]}
{"op":"mcm","clk":"11540889347","pt":1719499607735,"mc":[{"id":"1.230178315","rc":[{"atb":[[1.07,6.68]],"id":63994056},{"atl":[[10,0]],"id":63994056}],"con":true,"img":false}]}
{"op":"mcm","clk":"11540889365","pt":1719499608043,"mc":[{"id":"1.230178315","rc":[{"atb":[[1.07,0]],"id":63994056}],"con":true,"img":false}]}
{"op":"mcm","clk":"11540889382","pt":1719499608252,"mc":[{"id":"1.230178315","rc":[{"atl":[[65,0],[75,3]],"id":70940946}],"con":true,"img":false}]}
{"op":"mcm","clk":"11540889414","pt":1719499608663,"mc":[{"id":"1.230178315","rc":[{"atb":[[1.72,0]],"id":63994056}],"con":true,"img":false}]}
{"op":"mcm","clk":"11540889426","pt":1719499608872,"mc":[{"id":"1.230178315","rc":[{"atl":[[75,2],[85,1]],"id":70940946}],"con":true,"img":false}]}
{"op":"mcm","clk":"11540889432","pt":1719499608977,"mc":[{"id":"1.230178315","rc":[{"atb":[[1.19,6]],"id":70940946}],"con":true,"img":false}]}
{"op":"mcm","clk":"11540889440","pt":1719499609039,"mc":[{"id":"1.230178315","rc":[{"atb":[[1.96,4]],"id":70466763},{"atb":[[2.16,4.85]],"id":45375136},{"atb":[[2.08,5.11]],"id":46251065}],"con":true,"img":false}]}
{"op":"mcm","clk":"11540889457","pt":1719499609239,"mc":[{"id":"1.230178315","rc":[{"atl":[[5.8,1],[5.9,0]],"id":70466763},{"atl":[[5.5,0],[5.4,1]],"id":45375136},{"atl":[[4.1,3]],"id":63994056},{"atl":[[4.4,1]],"id":69979804}],"con":true,"img":false}]}
{"op":"mcm","clk":"11540889467","pt":1719499609341,"mc":[{"id":"1.230178315","rc":[{"atl":[[4,0]],"id":63994056},{"atl":[[4.3,0]],"id":69979804}],"con":true,"img":false}]}
{"op":"mcm","clk":"11540889478","pt":1719499609448,"mc":[{"id":"1.230178315","rc":[{"atb":[[1.2,25],[1.19,1]],"id":70940946}],"con":true,"img":false}]}
{"op":"mcm","clk":"11540889492","pt":1719499609650,"mc":[{"id":"1.230178315","rc":[{"atl":[[75,0],[60,2]],"id":70940946}],"con":true,"img":false}]}
{"op":"mcm","clk":"11540889499","pt":1719499609757,"mc":[{"id":"1.230178315","rc":[{"atl":[[5.6,5.78],[5.8,0],[5.9,1]],"id":70466763},{"atb":[[2.12,1]],"id":45375136},{"atl":[[4,1]],"id":63994056},{"atl":[[4.3,1],[4.4,0]],"id":69979804},{"atl":[[70,1]],"id":70940946}],"con":true,"img":false}]}
{"op":"mcm","clk":"11540889508","pt":1719499609859,"mc":[{"id":"1.230178315","rc":[{"atl":[[5.6,0],[5.8,6.63]],"id":70466763},{"atb":[[2.02,0]],"id":45375136},{"atl":[[5.5,1],[5.4,0]],"id":45375136},{"atl":[[4,0],[4.1,2],[3.9,1]],"id":63994056},{"atl":[[4.1,1]],"id":69979804},{"atl":[[85,0]],"id":70940946},{"atl":[[4.7,1]],"id":46251065}],"con":true,"img":false}]}
{"op":"mcm","clk":"11540889515","pt":1719499609963,"mc":[{"id":"1.230178315","rc":[{"atl":[[5.8,0],[5.9,8.48]],"id":70466763},{"atl":[[4.3,0]],"id":69979804},{"atl":[[4.9,0]],"id":46251065}],"con":true,"img":false}]}
{"op":"mcm","clk":"11540889528","pt":1719499610066,"mc":[{"id":"1.230178315","rc":[{"atl":[[5.6,3.23]],"id":70466763},{"atb":[[1.2,19.74]],"id":70940946}],"con":true,"img":false}]}
{"op":"mcm","clk":"11540889537","pt":1719499610171,"mc":[{"id":"1.230178315","rc":[{"atl":[[5.6,6.46],[5.5,0],[5.7,0.84],[5.9,1]],"id":70466763}],"con":true,"img":false}]}
{"op":"mcm","clk":"11540889633","pt":1719499611058,"mc":[{"id":"1.230178315","rc":[{"atl":[[10.5,3],[4.1,0]],"id":63994056}],"con":true,"img":false}]}
{"op":"mcm","clk":"11540889647","pt":1719499611163,"mc":[{"id":"1.230178315","rc":[{"atl":[[5.6,3.23]],"id":70466763},{"atb":[[2.02,1],[2.12,0],[2.14,4.16]],"id":45375136},{"atl":[[4,1],[3.95,1],[3.9,0]],"id":63994056},{"atl":[[4.3,1],[4.1,0],[4.2,1]],"id":69979804},{"atl":[[4.9,1],[4.7,0]],"id":46251065}],"con":true,"img":false}]}
{"op":"mcm","clk":"11540889659","pt":1719499611267,"mc":[{"id":"1.230178315","rc":[{"atb":[[2.02,0],[2.12,1]],"id":45375136},{"atl":[[4,0],[3.95,0],[3.9,1]],"id":63994056},{"atl":[[4.3,0],[4.2,0]],"id":69979804},{"atl":[[4.9,0],[4.7,1]],"id":46251065}],"con":true,"img":false}]}
{"op":"mcm","clk":"11540889667","pt":1719499611371,"mc":[{"id":"1.230178315","rc":[{"atl":[[4.1,1]],"id":69979804}],"con":true,"img":false}]}
{"op":"mcm","clk":"11540889693","pt":1719499611645,"mc":[{"id":"1.230178315","rc":[{"atb":[[2.14,0]],"id":45375136}],"con":true,"img":false}]}
{"op":"mcm","clk":"11540889768","pt":1719499612676,"mc":[{"id":"1.230178315","rc":[{"atl":[[3.8,8.84]],"id":69979804}],"con":true,"img":false}]}
{"op":"mcm","clk":"11540889775","pt":1719499612779,"mc":[{"id":"1.230178315","rc":[{"atl":[[3.85,10.53],[3.8,0]],"id":69979804}],"con":true,"img":false}]}
{"op":"mcm","clk":"11540889781","pt":1719499612839,"mc":[{"id":"1.230178315","rc":[{"atl":[[3.7,6.1]],"id":69979804}],"con":true,"img":false}]}
{"op":"mcm","clk":"11540889789","pt":1719499612941,"mc":[{"id":"1.230178315","rc":[{"atl":[[16,3.38]],"id":70466763}],"con":true,"img":false}]}
{"op":"mcm","clk":"11540889808","pt":1719499613144,"mc":[{"id":"1.230178315","rc":[{"atl":[[3.65,0.84]],"id":69979804}],"con":true,"img":false}]}
{"op":"mcm","clk":"11540889815","pt":1719499613247,"mc":[{"id":"1.230178315","rc":[{"atl":[[3.85,9.69]],"id":69979804}],"con":true,"img":false}]}
{"op":"mcm","clk":"11540889835","pt":1719499613454,"mc":[{"id":"1.230178315","rc":[{"atl":[[16,0],[6.2,1.98]],"id":70466763}],"con":true,"img":false}]}
{"op":"mcm","clk":"11540889855","pt":1719499613764,"mc":[{"id":"1.230178315","rc":[{"atl":[[5.9,5.08]],"id":70466763}],"con":true,"img":false}]}
{"op":"mcm","clk":"11540889861","pt":1719499613868,"mc":[{"id":"1.230178315","rc":[{"atl":[[5.6,0]],"id":70466763}],"con":true,"img":false}]}
{"op":"mcm","clk":"11540889882","pt":1719499614179,"mc":[{"id":"1.230178315","rc":[{"atl":[[5.7,0]],"id":70466763},{"atl":[[3.7,0]],"id":69979804}],"con":true,"img":false}]}
{"op":"mcm","clk":"11540889905","pt":1719499614447,"mc":[{"id":"1.230178315","rc":[{"atl":[[3.65,2.83]],"id":69979804}],"con":true,"img":false}]}
{"op":"mcm","clk":"11540889920","pt":1719499614648,"mc":[{"id":"1.230178315","rc":[{"atl":[[3.65,1.99]],"id":69979804}],"con":true,"img":false}]}
{"op":"mcm","clk":"11540889969","pt":1719499615268,"mc":[{"id":"1.230178315","rc":[{"atl":[[3.75,0]],"id":69979804}],"con":true,"img":false}]}
{"op":"mcm","clk":"11540890050","pt":1719499616361,"mc":[{"id":"1.230178315","rc":[{"atb":[[1.55,28.07]],"id":69979804},{"atb":[[2.02,0],[2.04,13.81]],"id":46251065}],"con":true,"img":false}]}
{"op":"mcm","clk":"11540890058","pt":1719499616465,"mc":[{"id":"1.230178315","rc":[{"atb":[[1.51,0]],"id":69979804}],"con":true,"img":false}]}
{"op":"mcm","clk":"11540890124","pt":1719499617254,"mc":[{"id":"1.230178315","rc":[{"atb":[[1.68,11.56]],"id":69979804}],"con":true,"img":false}]}
{"op":"mcm","clk":"11540890131","pt":1719499617356,"mc":[{"id":"1.230178315","rc":[{"atl":[[6.2,12.14],[5.9,1]],"id":70466763}],"con":true,"img":false}]}
{"op":"mcm","clk":"11540890166","pt":1719499617870,"mc":[{"id":"1.230178315","rc":[{"atl":[[3.85,0],[3.8,3.98]],"id":69979804}],"con":true,"img":false}]}
{"op":"mcm","clk":"11540890193","pt":1719499618183,"mc":[{"id":"1.230178315","rc":[{"atb":[[1.68,6.22]],"id":69979804}],"con":true,"img":false}]}
{"op":"mcm","clk":"11540890226","pt":1719499618567,"mc":[{"id":"1.230178315","rc":[{"atl":[[6.4,3.25]],"id":69979804}],"con":true,"img":false}]}
{"op":"mcm","clk":"11540890241","pt":1719499618770,"mc":[{"id":"1.230178315","rc":[{"atl":[[6.4,0]],"id":69979804}],"con":true,"img":false}]}
{"op":"mcm","clk":"11540890288","pt":1719499619446,"mc":[{"id":"1.230178315","rc":[{"atb":[[1.95,5.46]],"id":70466763}],"con":true,"img":false}]}
{"op":"mcm","clk":"11540890331","pt":1719499620072,"mc":[{"id":"1.230178315","rc":[{"atl":[[5.8,1],[5.9,0]],"id":70466763},{"atl":[[5.6,1],[5.5,0]],"id":45375136},{"atb":[[1.67,18.42]],"id":63994056},{"atl":[[3.85,1],[3.9,0]],"id":63994056},{"atl":[[4.1,0],[4.2,1]],"id":69979804},{"atl":[[70,3],[60,0]],"id":70940946},{"atb":[[1.07,7.12]],"id":46251065}],"con":true,"img":false}]}
{"op":"mcm","clk":"11540890340","pt":1719499620165,"mc":[{"id":"1.230178315","rc":[{"atl":[[5.8,6.6]],"id":70466763},{"atb":[[2.16,15.21]],"id":45375136},{"atl":[[25,11.69]],"id":45375136},{"atb":[[1.72,16.13],[1.65,0],[1.76,8.06]],"id":63994056},{"atl":[[3.6,0.84]],"id":69979804},{"atb":[[1.2,29.73],[1.22,4.99]],"id":70940946},{"atb":[[2.12,9.34]],"id":46251065}],"con":true,"img":false}]}
{"op":"mcm","clk":"11540890350","pt":1719499620268,"mc":[{"id":"1.230178315","rc":[{"atb":[[2.24,7.01],[1.98,12.03]],"id":70466763},{"atl":[[6,11.2]],"id":70466763},{"atb":[[2.18,7.21]],"id":45375136},{"atl":[[5.6,5.84],[5.5,1]],"id":45375136},{"atl":[[3.85,8.42],[10,14.84]],"id":63994056},{"atb":[[1.7,8.24],[1.69,18.49]],"id":69979804},{"atl":[[3.6,7.55],[4.2,0],[3.65,8.69],[3.75,13.4]],"id":69979804},{"atb":[[1.2,30.73],[1.21,0],[1.23,23.23]],"id":70940946},{"atl":[[80,1]],"id":70940946},{"atb":[[2.1,12.69]],"id":46251065},{"atl":[[19,11.81],[4.7,6.9]],"id":46251065}],"con":true,"img":false}]}
{"op":"mcm","clk":"11540890356","pt":1719499620371,"mc":[{"id":"1.230178315","rc":[{"atb":[[2.26,7.02]],"id":70466763},{"atb":[[2.2,7.21],[2.16,10.36]],"id":45375136},{"atl":[[5.6,4.84],[25,9.69],[7,6.85]],"id":45375136},{"atl":[[10.5,0],[4.1,16.84]],"id":63994056},{"atl":[[4.1,1]],"id":69979804},{"atb":[[1.19,0]],"id":70940946},{"atl":[[70,2]],"id":70940946},{"atl":[[5.9,13.82]],"id":46251065}],"con":true,"img":false}]}
{"op":"mcm","clk":"11540890363","pt":1719499620474,"mc":[{"id":"1.230178315","rc":[{"atb":[[1.96,0]],"id":70466763},{"atl":[[19.5,0]],"id":46251065}],"con":true,"img":false}]}
{"op":"mcm","clk":"11540890373","pt":1719499620578,"mc":[{"id":"1.230178315","rc":[{"atb":[[2.28,6]],"id":70466763},{"atb":[[2.22,5.16]],"id":45375136},{"atb":[[1.2,29.73],[1.21,1],[1.24,4.98]],"id":70940946},{"atb":[[1.07,0]],"id":46251065},{"atl":[[5,2.27]],"id":46251065}],"con":true,"img":false}]}
{"op":"mcm","clk":"11540890380","pt":1719499620682,"mc":[{"id":"1.230178315","rc":[{"atb":[[2.28,13.02],[2.26,0]],"id":70466763},{"atl":[[5.7,0.84]],"id":70466763},{"atb":[[2.24,7.21],[2.2,0]],"id":45375136},{"atl":[[3.8,0.84]],"id":63994056},{"atb":[[1.25,4.99],[1.23,0]],"id":70940946},{"atl":[[4.6,0.84]],"id":46251065}],"con":true,"img":false}]}
{"op":"mcm","clk":"11540890387","pt":1719499620785,"mc":[{"id":"1.230178315","rc":[{"atb":[[2.3,5.99]],"id":70466763},{"atb":[[2.26,5.16]],"id":45375136},{"atb":[[1.25,9.96]],"id":70940946},{"atl":[[5,0]],"id":46251065}],"con":true,"img":false}]}
{"op":"mcm","clk":"11540890401","pt":1719499620960,"mc":[{"id":"1.230178315","rc":[{"atl":[[4.6,6.8]],"id":46251065}],"con":true,"img":false}]}
{"op":"mcm","clk":"11540890410","pt":1719499621057,"mc":[{"id":"1.230178315","rc":[{"atb":[[1.95,0]],"id":70466763},{"atb":[[1.21,0],[1.23,1]],"id":70940946}],"con":true,"img":false}]}
{"op":"mcm","clk":"11540890420","pt":1719499621158,"mc":[{"id":"1.230178315","rc":[{"atl":[[4.4,3.49]],"id":46251065}],"con":true,"img":false}]}
{"op":"mcm","clk":"11540890429","pt":1719499621256,"mc":[{"id":"1.230178315","rc":[{"atl":[[4.4,9.49]],"id":46251065}],"con":true,"img":false}]}
{"op":"mcm","clk":"11540890441","pt":1719499621364,"mc":[{"id":"1.230178315","rc":[{"atl":[[4.4,6]],"id":46251065}],"con":true,"img":false}]}
{"op":"mcm","clk":"11540890472","pt":1719499621670,"mc":[{"id":"1.230178315","rc":[{"atl":[[4.6,5.96]],"id":46251065}],"con":true,"img":false}]}
{"op":"mcm","clk":"11540890478","pt":1719499621781,"mc":[{"id":"1.230178315","rc":[{"atl":[[4.2,2.63]],"id":46251065}],"con":true,"img":false}]}
{"op":"mcm","clk":"11540890487","pt":1719499621878,"mc":[{"id":"1.230178315","rc":[{"atl":[[5.7,6.44]],"id":70466763},{"atl":[[5.5,5.84]],"id":45375136},{"atb":[[1.75,2.11]],"id":63994056},{"atl":[[3.8,8.25]],"id":63994056}],"con":true,"img":false}]}
{"op":"mcm","clk":"11540890498","pt":1719499621981,"mc":[{"id":"1.230178315","rc":[{"atb":[[2.08,0]],"id":46251065}],"con":true,"img":false}]}
{"op":"mcm","clk":"11540890512","pt":1719499622187,"mc":[{"id":"1.230178315","rc":[{"atl":[[5.4,0.84]],"id":45375136},{"atb":[[1.76,15.33]],"id":63994056},{"atb":[[1.2,9.99]],"id":70940946},{"atl":[[4.2,8.58]],"id":46251065}],"con":true,"img":false}]}
{"op":"mcm","clk":"11540890518","pt":1719499622246,"mc":[{"id":"1.230178315","rc":[{"atb":[[2.3,2.11],[2.08,0]],"id":45375136},{"atb":[[1.71,12.84]],"id":63994056},{"atb":[[1.81,0],[2.16,2.11]],"id":46251065}],"con":true,"img":false}]}
{"op":"mcm","clk":"11540890523","pt":1719499622349,"mc":[{"id":"1.230178315","rc":[{"atl":[[5.4,5.71]],"id":45375136},{"atb":[[1.77,7.98]],"id":63994056},{"atb":[[2.18,4.68]],"id":46251065}],"con":true,"img":false}]}
{"op":"mcm","clk":"11540890530","pt":1719499622459,"mc":[{"id":"1.230178315","rc":[{"atb":[[2.3,7.26]],"id":45375136},{"atb":[[1.72,5.48],[1.68,0]],"id":69979804}],"con":true,"img":false}]}
{"op":"mcm","clk":"11540890536","pt":1719499622561,"mc":[{"id":"1.230178315","rc":[{"atl":[[5.6,6.6],[6.2,1.98]],"id":70466763},{"atb":[[1.73,7.57]],"id":69979804},{"atb":[[1.21,3.75]],"id":70940946},{"atl":[[4.2,5.95]],"id":46251065}],"con":true,"img":false}]}
{"op":"mcm","clk":"11540890544","pt":1719499622654,"mc":[{"id":"1.230178315","rc":[{"atb":[[2.26,3]],"id":70466763},{"atb":[[1.72,19.9],[1.74,7.2]],"id":69979804}],"con":true,"img":false}]}
{"op":"mcm","clk":"11540890551","pt":1719499622760,"mc":[{"id":"1.230178315","rc":[{"atl":[[6.2,0]],"id":70466763},{"atb":[[1.71,8.34]],"id":63994056},{"atb":[[1.27,14.62]],"id":70940946},{"atl":[[4.1,2.72]],"id":46251065}],"con":true,"img":false}]}
{"op":"mcm","clk":"11540890560","pt":1719499622863,"mc":[{"id":"1.230178315","rc":[{"atl":[[5.5,5.63]],"id":70466763},{"atb":[[2.18,11.02],[2.16,14.79]],"id":46251065}],"con":true,"img":false}]}
{"op":"mcm","clk":"11540890565","pt":1719499622967,"mc":[{"id":"1.230178315","rc":[{"atb":[[1.97,0]],"id":70466763},{"atb":[[2.18,5.18]],"id":45375136},{"atb":[[1.69,14.49]],"id":69979804},{"atb":[[1.25,10.96],[1.23,0]],"id":70940946},{"atb":[[2.12,6.34]],"id":46251065}],"con":true,"img":false}]}
{"op":"mcm","clk":"11540890576","pt":1719499623070,"mc":[{"id":"1.230178315","rc":[{"atb":[[2.32,2.5]],"id":45375136},{"atb":[[1.75,5]],"id":69979804},{"atb":[[2.2,2.55]],"id":46251065},{"atl":[[4.1,0]],"id":46251065}],"con":true,"img":false}]}
{"op":"mcm","clk":"11540890584","pt":1719499623174,"mc":[{"id":"1.230178315","rc":[{"atl":[[5.7,5.59]],"id":70466763}],"con":true,"img":false}]}
{"op":"mcm","clk":"11540890591","pt":1719499623277,"mc":[{"id":"1.230178315","rc":[{"atb":[[2.32,7.63],[2.18,0]],"id":45375136},{"atb":[[1.75,12.21]],"id":69979804},{"atb":[[1.28,4.95],[1.26,9.91]],"id":70940946},{"atb":[[2.2,8.87]],"id":46251065}],"con":true,"img":false}]}
{"op":"mcm","clk":"11540890623","pt":1719499623753,"mc":[{"id":"1.230178315","rc":[{"atb":[[1.71,5.48]],"id":69979804}],"con":true,"img":false}]}
{"op":"mcm","clk":"11540890631","pt":1719499623855,"mc":[{"id":"1.230178315","rc":[{"atb":[[1.71,3.62]],"id":69979804},{"atb":[[1.25,9.96],[1.21,0],[1.26,10.91]],"id":70940946}],"con":true,"img":false}]}
{"op":"mcm","clk":"11540890640","pt":1719499623962,"mc":[{"id":"1.230178315","rc":[{"atl":[[3.85,7.42],[3.9,1]],"id":63994056}],"con":true,"img":false}]}
{"op":"mcm","clk":"11540890645","pt":1719499624067,"mc":[{"id":"1.230178315","rc":[{"atb":[[1.23,5.26]],"id":70940946}],"con":true,"img":false}]}
{"op":"mcm","clk":"11540890656","pt":1719499624168,"mc":[{"id":"1.230178315","rc":[{"atb":[[2.14,4.38]],"id":46251065}],"con":true,"img":false}]}
{"op":"mcm","clk":"11540890663","pt":1719499624265,"mc":[{"id":"1.230178315","rc":[{"atb":[[2.24,6.01]],"id":70466763},{"atl":[[5.8,5.6],[5.7,6.59]],"id":70466763},{"atl":[[5.6,5.84],[5.5,4.84]],"id":45375136},{"atl":[[3.95,1],[3.9,0]],"id":63994056},{"atb":[[1.23,0]],"id":70940946},{"atl":[[70,0],[75,2]],"id":70940946}],"con":true,"img":false}]}
{"op":"mcm","clk":"11540890681","pt":1719499624468,"mc":[{"id":"1.230178315","rc":[{"atl":[[5.6,0],[5.7,18.82]],"id":70466763},{"atb":[[1.67,0],[1.78,7.99]],"id":63994056},{"atb":[[1.55,0],[1.65,28.07]],"id":69979804},{"atl":[[80,0],[85,1]],"id":70940946},{"atb":[[2.04,5.69],[2.12,26.24]],"id":46251065}],"con":true,"img":false}]}
{"op":"mcm","clk":"11540890717","pt":1719499624880,"mc":[{"id":"1.230178315","rc":[{"atb":[[2.26,0]],"id":70466763}],"con":true,"img":false}]}
{"op":"mcm","clk":"11540890763","pt":1719499625562,"mc":[{"id":"1.230178315","rc":[{"atb":[[1.71,0]],"id":63994056}],"con":true,"img":false}]}
{"op":"mcm","clk":"11540890777","pt":1719499625768,"mc":[{"id":"1.230178315","rc":[{"atb":[[2.24,0],[2.34,7.26]],"id":45375136},{"atb":[[1.8,7.4]],"id":69979804},{"atb":[[1.25,4.97],[1.29,10.91]],"id":70940946}],"con":true,"img":false}]}
{"op":"mcm","clk":"11540890787","pt":1719499625997,"mc":[{"id":"1.230178315","rc":[{"atb":[[1.17,0]],"id":70940946}],"con":true,"img":false}]}
{"op":"mcm","clk":"11540890800","pt":1719499626170,"mc":[{"id":"1.230178315","rc":[{"atb":[[2.14,0]],"id":46251065}],"con":true,"img":false}]}
{"op":"mcm","clk":"11540890823","pt":1719499626582,"mc":[{"id":"1.230178315","rc":[{"atb":[[1.77,5.49]],"id":69979804}],"con":true,"img":false}]}
{"op":"mcm","clk":"11540890847","pt":1719499626961,"mc":[{"id":"1.230178315","rc":[{"atb":[[2.32,2.12]],"id":70466763},{"atb":[[2.36,1.14]],"id":45375136},{"atb":[[1.79,1.82]],"id":63994056},{"atb":[[1.71,0],[1.81,1.83]],"id":69979804},{"atb":[[1.27,15.62],[1.26,9.91]],"id":70940946},{"atb":[[2.22,2]],"id":46251065}],"con":true,"img":false}]}
{"op":"mcm","clk":"11540890862","pt":1719499627160,"mc":[{"id":"1.230178315","rc":[{"atl":[[5.6,11.26]],"id":70466763},{"atb":[[1.78,0],[1.68,34.21]],"id":63994056},{"atb":[[1.57,28.07]],"id":69979804},{"atb":[[2,28.07],[2.12,6.34]],"id":46251065}],"con":true,"img":false}]}
{"op":"mcm","clk":"11540890872","pt":1719499627264,"mc":[{"id":"1.230178315","rc":[{"atl":[[5.7,6.59]],"id":70466763},{"atb":[[1.65,0]],"id":69979804}],"con":true,"img":false}]}
{"op":"mcm","clk":"11540890881","pt":1719499627470,"mc":[{"id":"1.230178315","rc":[{"atb":[[1.3,14.11]],"id":70940946}],"con":true,"img":false}]}
{"op":"mcm","clk":"11540890900","pt":1719499627775,"mc":[{"id":"1.230178315","rc":[{"atb":[[2.32,5.13]],"id":45375136},{"atb":[[1.75,7.21]],"id":69979804},{"atb":[[1.28,5.95],[1.27,14.62]],"id":70940946},{"atb":[[2.22,8.29],[2.2,6.32]],"id":46251065}],"con":true,"img":false}]}
{"op":"mcm","clk":"11540890908","pt":1719499627874,"mc":[{"id":"1.230178315","rc":[{"atb":[[2.32,5.05]],"id":70466763},{"atb":[[2.36,3.41]],"id":45375136},{"atb":[[1.81,5.33]],"id":69979804},{"atb":[[2.22,12.29]],"id":46251065}],"con":true,"img":false}]}
{"op":"mcm","clk":"11540890917","pt":1719499627979,"mc":[{"id":"1.230178315","rc":[{"atb":[[2.24,6.27],[2.12,0]],"id":46251065}],"con":true,"img":false}]}
{"op":"mcm","clk":"11540890932","pt":1719499628186,"mc":[{"id":"1.230178315","rc":[{"atl":[[5.4,0.84]],"id":70466763},{"atb":[[1.81,7.31]],"id":63994056},{"atl":[[4.1,0.84]],"id":46251065}],"con":true,"img":false}]}
{"op":"mcm","clk":"11540890968","pt":1719499628560,"mc":[{"id":"1.230178315","rc":[{"atl":[[5.4,6.31]],"id":70466763}],"con":true,"img":false}]}
{"op":"mcm","clk":"11540891020","pt":1719499629273,"mc":[{"id":"1.230178315","rc":[{"atb":[[2.3,17.54],[2.34,0]],"id":45375136}],"con":true,"img":false}]}
{"op":"mcm","clk":"11540891032","pt":1719499629378,"mc":[{"id":"1.230178315","rc":[{"atl":[[5.6,4.84],[5.5,5.84]],"id":45375136},{"atb":[[1.72,22.29]],"id":63994056},{"atl":[[3.95,0],[3.9,1]],"id":63994056},{"atl":[[70,2],[75,0]],"id":70940946}],"con":true,"img":false}]}
{"op":"mcm","clk":"11540891049","pt":1719499629586,"mc":[{"id":"1.230178315","rc":[{"atl":[[80,1],[85,0]],"id":70940946}],"con":true,"img":false}]}
{"op":"mcm","clk":"11540891116","pt":1719499630276,"mc":[{"id":"1.230178315","rc":[{"atb":[[2.32,10.82]],"id":70466763},{"atb":[[2.36,8.59],[2.22,0]],"id":45375136},{"atb":[[1.82,8.09],[1.79,18.01]],"id":63994056},{"atb":[[1.8,22.04],[1.82,7.31]],"id":69979804},{"atb":[[1.22,0],[1.29,20.9],[1.31,4.99]],"id":70940946}],"con":true,"img":false}]}
{"op":"mcm","clk":"11540891124","pt":1719499630377,"mc":[{"id":"1.230178315","rc":[{"atb":[[1.33,2.11]],"id":70940946}],"con":true,"img":false}]}
{"op":"mcm","clk":"11540891153","pt":1719499630681,"mc":[{"id":"1.230178315","rc":[{"atl":[[5.6,0],[5.7,19.21]],"id":70466763},{"atb":[[1.72,16.13]],"id":63994056}],"con":true,"img":false}]}
{"op":"mcm","clk":"11540891170","pt":1719499630886,"mc":[{"id":"1.230178315","rc":[{"atb":[[2.3,7.26],[2.34,17.2]],"id":45375136},{"atb":[[1.33,7.1],[1.29,9.99]],"id":70940946}],"con":true,"img":false}]}
{"op":"mcm","clk":"11540891242","pt":1719499631974,"mc":[{"id":"1.230178315","rc":[{"atb":[[1.83,1.85]],"id":63994056},{"atb":[[1.83,2.15]],"id":69979804},{"atb":[[1.28,4.95]],"id":70940946},{"atb":[[2.26,2.09]],"id":46251065}],"con":true,"img":false}]}
{"op":"mcm","clk":"11540891250","pt":1719499632080,"mc":[{"id":"1.230178315","rc":[{"atb":[[1.83,9.49],[1.7,1]],"id":69979804},{"atb":[[1.34,5],[1.31,5.99],[1.24,0]],"id":70940946},{"atb":[[2.18,4.68],[2.26,8.3]],"id":46251065}],"con":true,"img":false}]}
{"op":"mcm","clk":"11540891269","pt":1719499632291,"mc":[{"id":"1.230178315","rc":[{"atb":[[1.68,0],[1.78,15.41]],"id":63994056},{"atb":[[1.57,0]],"id":69979804},{"atb":[[1.32,1],[1.31,4.99]],"id":70940946},{"atb":[[2,0],[2.18,19.32]],"id":46251065},{"atl":[[4.1,6.74],[4.7,1]],"id":46251065}],"con":true,"img":false}]}
{"op":"mcm","clk":"11540891279","pt":1719499632354,"mc":[{"id":"1.230178315","rc":[{"atb":[[1.65,28.07]],"id":69979804}],"con":true,"img":false}]}
{"op":"mcm","clk":"11540891296","pt":1719499632564,"mc":[{"id":"1.230178315","rc":[{"atb":[[1.81,1.83]],"id":69979804},{"atb":[[2.22,8.29]],"id":46251065}],"con":true,"img":false}]}
{"op":"mcm","clk":"11540891302","pt":1719499632667,"mc":[{"id":"1.230178315","rc":[{"atb":[[1.84,5]],"id":69979804},{"atb":[[1.35,4.92]],"id":70940946},{"atb":[[2.28,4]],"id":46251065}],"con":true,"img":false}]}
{"op":"mcm","clk":"11540891353","pt":1719499633284,"mc":[{"id":"1.230178315","rc":[{"atb":[[1.33,8.1],[1.32,0]],"id":70940946}],"con":true,"img":false}]}
{"op":"mcm","clk":"11540891451","pt":1719499634274,"mc":[{"id":"1.230178315","rc":[{"atb":[[2.28,15.86],[2.34,0]],"id":45375136},{"atb":[[2.28,10.17]],"id":46251065}],"con":true,"img":false}]}
{"op":"mcm","clk":"11540891458","pt":1719499634377,"mc":[{"id":"1.230178315","rc":[{"atb":[[2.38,2.11]],"id":70466763},{"atb":[[2.4,2.11]],"id":45375136},{"atb":[[1.84,2.11]],"id":63994056},{"atb":[[1.86,2.11]],"id":69979804},{"atb":[[2.32,2.11],[2.2,0]],"id":46251065}],"con":true,"img":false}]}
{"op":"mcm","clk":"11540891466","pt":1719499634478,"mc":[{"id":"1.230178315","rc":[{"atb":[[1.58,0]],"id":70466763},{"atb":[[2.3,5.14]],"id":45375136},{"atb":[[1.75,0]],"id":63994056},{"atb":[[1.62,0]],"id":69979804},{"atb":[[2.16,12.67]],"id":46251065}],"con":true,"img":false}]}
{"op":"mcm","clk":"11540891474","pt":1719499634581,"mc":[{"id":"1.230178315","rc":[{"atb":[[2.32,8.27],[2.3,12.31],[2.22,2]],"id":46251065}],"con":true,"img":false}]}
{"op":"mcm","clk":"11540891532","pt":1719499635371,"mc":[{"id":"1.230178315","rc":[{"atb":[[1.33,16.1]],"id":70940946}],"con":true,"img":false}]}
{"op":"mcm","clk":"11540891551","pt":1719499635677,"mc":[{"id":"1.230178315","rc":[{"atb":[[1.68,34.21]],"id":63994056},{"atb":[[2.06,20.36],[2.18,4.68]],"id":46251065}],"con":true,"img":false}]}
{"op":"mcm","clk":"11540891561","pt":1719499635780,"mc":[{"id":"1.230178315","rc":[{"atl":[[5.6,11.94],[5.7,6.59]],"id":70466763},{"atb":[[1.78,0]],"id":63994056},{"atb":[[1.57,28.07],[1.65,0]],"id":69979804}],"con":true,"img":false}]}
{"op":"mcm","clk":"11540891574","pt":1719499635985,"mc":[{"id":"1.230178315","rc":[{"atb":[[1.33,11.11],[1.35,9.92]],"id":70940946}],"con":true,"img":false}]}
{"op":"mcm","clk":"11540891592","pt":1719499636192,"mc":[{"id":"1.230178315","rc":[{"atb":[[1.82,12.65]],"id":69979804}],"con":true,"img":false}]}
{"op":"mcm","clk":"11540891647","pt":1719499636868,"mc":[{"id":"1.230178315","rc":[{"atb":[[1.33,16.37]],"id":70940946}],"con":true,"img":false}]}
{"op":"mcm","clk":"11540891662","pt":1719499637081,"mc":[{"id":"1.230178315","rc":[{"atb":[[2.24,0],[2.4,2.88],[2.38,7.74],[2.34,11.24]],"id":70466763},{"atb":[[2.42,1.48]],"id":45375136},{"atb":[[1.85,1.88]],"id":63994056},{"atb":[[1.87,2.63]],"id":69979804},{"atb":[[2.34,2.23]],"id":46251065}],"con":true,"img":false}]}
{"op":"mcm","clk":"11540891675","pt":1719499637292,"mc":[{"id":"1.230178315","rc":[{"atb":[[1.82,7.31]],"id":69979804},{"atb":[[1.33,11.11]],"id":70940946}],"con":true,"img":false}]}
{"op":"mcm","clk":"11540891683","pt":1719499637386,"mc":[{"id":"1.230178315","rc":[{"atb":[[2.32,7.89]],"id":70466763},{"atb":[[2.36,6.31]],"id":45375136},{"atb":[[1.84,0]],"id":69979804},{"atb":[[2.28,6.17]],"id":46251065}],"con":true,"img":false}]}
{"op":"mcm","clk":"11540891694","pt":1719499637492,"mc":[{"id":"1.230178315","rc":[{"atb":[[2.38,11.74]],"id":70466763},{"atb":[[2.4,4.41]],"id":45375136},{"atb":[[1.84,4.57]],"id":63994056},{"atb":[[1.86,5.01]],"id":69979804},{"atb":[[2.34,5.63]],"id":46251065}],"con":true,"img":false}]}
{"op":"mcm","clk":"11540891732","pt":1719499637761,"mc":[{"id":"1.230178315","rc":[{"atb":[[2.4,8.48],[2.28,7.02]],"id":70466763}],"con":true,"img":false}]}
{"op":"mcm","clk":"11540891820","pt":1719499638993,"mc":[{"id":"1.230178315","rc":[{"atl":[[5.8,6.6],[5.7,5.59],[5.9,1]],"id":70466763},{"atl":[[5.6,5.84],[5.5,4.84]],"id":45375136},{"atl":[[3.95,1],[3.9,0]],"id":63994056},{"atb":[[1.7,0]],"id":69979804},{"atl":[[3.65,6.7]],"id":69979804},{"atl":[[70,0],[75,2]],"id":70940946},{"atl":[[4.8,1],[4.7,0]],"id":46251065}],"con":true,"img":false}]}
{"op":"mcm","clk":"11540891857","pt":1719499639362,"mc":[{"id":"1.230178315","rc":[{"atl":[[3.6,14.96]],"id":69979804}],"con":true,"img":false}]}
{"op":"mcm","clk":"11540891864","pt":1719499639467,"mc":[{"id":"1.230178315","rc":[{"atb":[[2.3,14.7],[2.28,0]],"id":45375136}],"con":true,"img":false}]}
{"op":"mcm","clk":"11540891886","pt":1719499639774,"mc":[{"id":"1.230178315","rc":[{"atb":[[1.27,0]],"id":70940946}],"con":true,"img":false}]}
{"op":"mcm","clk":"11540891899","pt":1719499639980,"mc":[{"id":"1.230178315","rc":[{"atb":[[1.35,25.71]],"id":70940946}],"con":true,"img":false}]}
{"op":"mcm","clk":"11540891920","pt":1719499640193,"mc":[{"id":"1.230178315","rc":[{"atl":[[5.8,5.6]],"id":70466763},{"atb":[[1.37,10.66]],"id":70940946},{"atl":[[80,0],[85,1]],"id":70940946},{"atl":[[4.7,1]],"id":46251065}],"con":true,"img":false}]}
{"op":"mcm","clk":"11540891930","pt":1719499640293,"mc":[{"id":"1.230178315","rc":[{"atb":[[2.32,10.89]],"id":70466763},{"atl":[[4.8,0]],"id":46251065}],"con":true,"img":false}]}
{"op":"mcm","clk":"11540891964","pt":1719499640697,"mc":[{"id":"1.230178315","rc":[{"atb":[[2.4,14.68],[2.42,6.61],[2.26,0]],"id":45375136},{"atb":[[1.85,10.07]],"id":63994056},{"atb":[[1.73,0],[1.87,10.02],[1.69,0],[1.74,0],[1.86,19.8]],"id":69979804},{"atl":[[3.55,7.01]],"id":69979804},{"atb":[[1.2,0],[1.36,10.04],[1.25,0],[1.38,5.01]],"id":70940946},{"atb":[[2.24,0],[2.36,6.14]],"id":46251065}],"con":true,"img":false}]}
{"op":"mcm","clk":"11540891974","pt":1719499640801,"mc":[{"id":"1.230178315","rc":[{"atb":[[1.84,20.96]],"id":63994056},{"atb":[[2.38,2.25]],"id":46251065}],"con":true,"img":false}]}
{"op":"mcm","clk":"11540892000","pt":1719499641073,"mc":[{"id":"1.230178315","rc":[{"atb":[[2.38,7.74]],"id":70466763},{"atb":[[2.4,12.38]],"id":45375136},{"atb":[[1.84,18.5]],"id":63994056},{"atb":[[1.86,16.9]],"id":69979804},{"atl":[[3.5,0.84]],"id":69979804},{"atb":[[1.35,20.79]],"id":70940946},{"atb":[[2.34,2.23]],"id":46251065}],"con":true,"img":false}]}
{"op":"mcm","clk":"11540892010","pt":1719499641177,"mc":[{"id":"1.230178315","rc":[{"atb":[[2.42,5]],"id":70466763},{"atb":[[2.44,4.21]],"id":45375136},{"atb":[[1.86,3.04]],"id":63994056},{"atb":[[1.88,10.68]],"id":69979804},{"atb":[[1.33,10.11],[1.39,6.25],[1.36,11.04]],"id":70940946},{"atb":[[2.38,4.97]],"id":46251065}],"con":true,"img":false}]}
{"op":"mcm","clk":"11540892022","pt":1719499641279,"mc":[{"id":"1.230178315","rc":[{"atb":[[2.44,2.87]],"id":70466763},{"atb":[[2.46,1.59]],"id":45375136},{"atb":[[1.87,1.9]],"id":63994056},{"atb":[[1.89,2.85]],"id":69979804},{"atb":[[1.33,2.11]],"id":70940946}],"con":true,"img":false}]}
{"op":"mcm","clk":"11540892085","pt":1719499641995,"mc":[{"id":"1.230178315","rc":[{"atb":[[2.32,7.89]],"id":70466763},{"atb":[[2.38,3.5]],"id":45375136}],"con":true,"img":false}]}
{"op":"mcm","clk":"11540892090","pt":1719499642097,"mc":[{"id":"1.230178315","rc":[{"atb":[[2.3,0],[2.42,16.19],[2.44,8.46]],"id":70466763},{"atb":[[2.3,9.56],[2.46,6.68],[2.44,14.41]],"id":45375136},{"atb":[[1.87,10.09],[1.76,7.27],[1.72,0],[1.86,19.43]],"id":63994056},{"atb":[[1.89,10.24],[1.72,5.48],[1.88,25.48],[1.75,0]],"id":69979804},{"atl":[[3.5,7.88]],"id":69979804},{"atb":[[1.28,0],[1.4,5.01]],"id":70940946},{"atb":[[2.26,2.09],[2.38,11.11]],"id":46251065}],"con":true,"img":false}]}
{"op":"mcm","clk":"11540892110","pt":1719499642308,"mc":[{"id":"1.230178315","rc":[{"atb":[[2.38,0]],"id":45375136}],"con":true,"img":false}]}
{"op":"mcm","clk":"11540892152","pt":1719499642678,"mc":[{"id":"1.230178315","rc":[{"atl":[[3.6,14.11]],"id":69979804}],"con":true,"img":false}]}
{"op":"mcm","clk":"11540892163","pt":1719499642783,"mc":[{"id":"1.230178315","rc":[{"atb":[[1.36,10.04],[1.38,6.01]],"id":70940946}],"con":true,"img":false}]}
{"op":"mcm","clk":"11540892242","pt":1719499643728,"mc":[{"id":"1.230178315","rc":[{"atl":[[3.95,0],[3.9,1]],"id":63994056}],"con":true,"img":false}]}
{"op":"mcm","clk":"11540892284","pt":1719499644174,"mc":[{"id":"1.230178315","rc":[{"atl":[[5.8,6.6],[5.9,0]],"id":70466763},{"atl":[[5.6,4.84],[5.5,5.84]],"id":45375136},{"atl":[[3.85,8.42],[3.9,0]],"id":63994056},{"atl":[[70,2],[75,0]],"id":70940946}],"con":true,"img":false}]}
{"op":"mcm","clk":"11540892309","pt":1719499644479,"mc":[{"id":"1.230178315","rc":[{"atb":[[2.42,11.19]],"id":70466763},{"atl":[[5.8,5.6],[5.9,1]],"id":70466763},{"atb":[[2.44,10.2]],"id":45375136},{"atb":[[1.86,16.39]],"id":63994056},{"atl":[[3.85,7.42],[3.9,1]],"id":63994056},{"atb":[[1.68,28.07],[1.88,21.07]],"id":69979804},{"atb":[[1.39,0]],"id":70940946},{"atl":[[80,1],[85,0]],"id":70940946},{"atb":[[2.38,8.39]],"id":46251065}],"con":true,"img":false}]}
{"op":"mcm","clk":"11540892316","pt":1719499644585,"mc":[{"id":"1.230178315","rc":[{"atb":[[2.46,3.33]],"id":70466763},{"atl":[[5.6,0],[5.7,18.21]],"id":70466763},{"atb":[[2.36,25.39],[2.48,4.1]],"id":45375136},{"atb":[[1.68,0],[1.8,20.16],[1.88,2.7]],"id":63994056},{"atb":[[1.57,0],[1.9,4.61]],"id":69979804},{"atb":[[1.41,4.4]],"id":70940946},{"atb":[[2.14,12.7],[2.4,3.7],[2.06,0]],"id":46251065}],"con":true,"img":false}]}
{"op":"mcm","clk":"11540892324","pt":1719499644691,"mc":[{"id":"1.230178315","rc":[{"atb":[[2.48,2.75]],"id":70466763},{"atb":[[2.3,0],[2.5,1.65]],"id":45375136},{"atb":[[1.89,1.92]],"id":63994056},{"atb":[[1.91,2.9]],"id":69979804},{"atb":[[2.42,2.33]],"id":46251065}],"con":true,"img":false}]}
{"op":"mcm","clk":"11540892334","pt":1719499644888,"mc":[{"id":"1.230178315","rc":[{"atb":[[2.46,14.37],[2.48,8.27]],"id":70466763}],"con":true,"img":false}]}
{"op":"mcm","clk":"11540892343","pt":1719499644990,"mc":[{"id":"1.230178315","rc":[{"atb":[[2.32,2.12],[1.98,0]],"id":70466763},{"atb":[[1.89,0],[1.87,8.71],[1.88,0]],"id":63994056},{"trd":[[1.87,2.76],[1.89,3.84],[1.88,5.4]],"ltp":1.87,"tv":12.0,"id":63994056}],"con":true,"img":false}]}
{"op":"mcm","clk":"11540892352","pt":1719499645092,"mc":[{"id":"1.230178315","rc":[{"atb":[[1.88,1.92]],"id":63994056},{"atl":[[3.75,1]],"id":63994056}],"con":true,"img":false}]}
{"op":"mcm","clk":"11540892369","pt":1719499645297,"mc":[{"id":"1.230178315","rc":[{"atl":[[3.75,8.83]],"id":63994056}],"con":true,"img":false}]}
{"op":"mcm","clk":"11540892375","pt":1719499645399,"mc":[{"id":"1.230178315","rc":[{"atb":[[2.5,6.7],[2.16,0],[2.48,14.21]],"id":45375136},{"atb":[[1.88,10.17],[1.77,0]],"id":63994056},{"atb":[[1.82,0],[1.8,7.4],[1.91,10.31],[1.9,19.45]],"id":69979804},{"atb":[[1.39,1],[1.41,9.42],[1.38,5.01]],"id":70940946},{"atb":[[2.1,0],[2.4,16.1],[2.42,8.53],[2.28,0]],"id":46251065}],"con":true,"img":false}]}
{"op":"mcm","clk":"11540892383","pt":1719499645502,"mc":[{"id":"1.230178315","rc":[{"atb":[[2.32,0]],"id":45375136},{"atb":[[1.31,0]],"id":70940946}],"con":true,"img":false}]}
{"op":"mcm","clk":"11540892401","pt":1719499645665,"mc":[{"id":"1.230178315","rc":[{"atl":[[3.7,0.84]],"id":63994056}],"con":true,"img":false}]}
{"op":"mcm","clk":"11540892420","pt":1719499645870,"mc":[{"id":"1.230178315","rc":[{"atb":[[1.84,23]],"id":63994056},{"atl":[[3.75,7.83]],"id":63994056}],"con":true,"img":false}]}
{"op":"mcm","clk":"11540892436","pt":1719499646074,"mc":[{"id":"1.230178315","rc":[{"atb":[[1.84,18.5]],"id":63994056}],"con":true,"img":false}]}
{"op":"mcm","clk":"11540892450","pt":1719499646278,"mc":[{"id":"1.230178315","rc":[{"atl":[[3.6,6.7]],"id":69979804},{"atl":[[65,0.17]],"id":70940946}],"con":true,"img":false}]}
{"op":"mcm","clk":"11540892458","pt":1719499646384,"mc":[{"id":"1.230178315","rc":[{"atl":[[5.9,2.98]],"id":70466763}],"con":true,"img":false}]}
{"op":"mcm","clk":"11540892477","pt":1719499646596,"mc":[{"id":"1.230178315","rc":[{"atb":[[2.5,2.53]],"id":70466763},{"atb":[[2.52,2.53]],"id":45375136},{"atb":[[1.89,2.53]],"id":63994056},{"atb":[[1.92,2.53]],"id":69979804},{"atb":[[1.42,2.53]],"id":70940946},{"atb":[[2.44,2.53]],"id":46251065}],"con":true,"img":false}]}
{"op":"mcm","clk":"11540892487","pt":1719499646692,"mc":[{"id":"1.230178315","rc":[{"atb":[[2.52,4.75]],"id":70466763},{"atb":[[2.54,3.82]],"id":45375136},{"atb":[[1.91,2.11],[1.9,1.98]],"id":63994056},{"atb":[[1.94,2.11],[1.93,2.81]],"id":69979804},{"atb":[[1.43,2.11]],"id":70940946},{"atb":[[2.46,4.48]],"id":46251065}],"con":true,"img":false}]}
{"op":"mcm","clk":"11540892493","pt":1719499646791,"mc":[{"id":"1.230178315","rc":[{"atb":[[2.38,5.62]],"id":70466763},{"atb":[[2.4,10.26]],"id":45375136},{"atb":[[1.84,16.39],[1.92,1.98]],"id":63994056},{"atb":[[1.95,2.72],[1.86,14.79]],"id":69979804},{"atl":[[3.55,19.58]],"id":69979804},{"atb":[[1.33,0],[1.39,0],[1.41,10.42]],"id":70940946},{"atl":[[75,1],[80,0]],"id":70940946},{"atb":[[2.32,6.15]],"id":46251065}],"con":true,"img":false}]}
{"op":"mcm","clk":"11540892502","pt":1719499646892,"mc":[{"id":"1.230178315","rc":[{"atb":[[1.89,14]],"id":69979804}],"con":true,"img":false}]}
{"op":"mcm","clk":"11540892517","pt":1719499647101,"mc":[{"id":"1.230178315","rc":[{"atl":[[5.9,1]],"id":70466763},{"atb":[[1.89,10.24]],"id":69979804}],"con":true,"img":false}]}
{"op":"mcm","clk":"11540892544","pt":1719499647406,"mc":[{"id":"1.230178315","rc":[{"atl":[[5.8,7.82]],"id":70466763}],"con":true,"img":false}]}
{"op":"mcm","clk":"11540892574","pt":1719499647773,"mc":[{"id":"1.230178315","rc":[{"atb":[[2.54,1.94]],"id":70466763},{"atb":[[2.56,1.94]],"id":45375136},{"atb":[[2.48,1.94]],"id":46251065}],"con":true,"img":false}]}
{"op":"mcm","clk":"11540892581","pt":1719499647900,"mc":[{"id":"1.230178315","rc":[{"atb":[[2.56,2.52],[2.46,11.04]],"id":70466763},{"atb":[[2.58,1.74],[2.48,10.11]],"id":45375136},{"atl":[[3.65,1]],"id":63994056},{"atb":[[1.9,14.84]],"id":69979804},{"atb":[[1.41,6.02]],"id":70940946},{"atb":[[2.5,2.38],[2.4,12.4]],"id":46251065}],"con":true,"img":false}]}
{"op":"mcm","clk":"11540892585","pt":1719499647978,"mc":[{"id":"1.230178315","rc":[{"atb":[[2.54,6.34],[2.5,0]],"id":70466763},{"atb":[[2.56,5.33],[2.52,0]],"id":45375136},{"atb":[[1.89,0]],"id":63994056},{"atb":[[1.96,2.7],[1.92,0]],"id":69979804},{"atb":[[1.43,6.11],[1.42,0]],"id":70940946},{"atb":[[2.44,0],[2.48,5.94]],"id":46251065}],"con":true,"img":false}]}
{"op":"mcm","clk":"11540892592","pt":1719499648084,"mc":[{"id":"1.230178315","rc":[{"atb":[[1.97,2.63]],"id":69979804}],"con":true,"img":false}]}
{"op":"mcm","clk":"11540892600","pt":1719499648183,"mc":[{"id":"1.230178315","rc":[{"atb":[[1.81,12.26]],"id":63994056}],"con":true,"img":false}]}
{"op":"mcm","clk":"11540892620","pt":1719499648389,"mc":[{"id":"1.230178315","rc":[{"atl":[[5.6,11.94],[5.8,5.6],[5.7,5.59]],"id":70466763},{"atb":[[1.71,34.21],[1.8,0]],"id":63994056},{"atb":[[1.6,28.07],[1.68,0]],"id":69979804}],"con":true,"img":false}]}
{"op":"mcm","clk":"11540892641","pt":1719499648600,"mc":[{"id":"1.230178315","rc":[{"atl":[[5.7,9.69]],"id":70466763}],"con":true,"img":false}]}
{"op":"mcm","clk":"11540892655","pt":1719499648798,"mc":[{"id":"1.230178315","rc":[{"atb":[[1.81,7.31]],"id":63994056}],"con":true,"img":false}]}
{"op":"mcm","clk":"11540892673","pt":1719499649007,"mc":[{"id":"1.230178315","rc":[{"atb":[[2.58,2.53]],"id":70466763},{"atb":[[2.6,2.53]],"id":45375136},{"atb":[[1.93,2.53]],"id":63994056},{"atb":[[1.96,5.23]],"id":69979804},{"atb":[[1.44,2.53]],"id":70940946},{"atb":[[2.52,2.53]],"id":46251065}],"con":true,"img":false}]}
{"op":"mcm","clk":"11540892689","pt":1719499649107,"mc":[{"id":"1.230178315","rc":[{"atb":[[2.6,2.44]],"id":70466763},{"atb":[[2.62,1.77]],"id":45375136},{"atb":[[1.94,2.11]],"id":63994056},{"atb":[[2.54,2.4]],"id":46251065}],"con":true,"img":false}]}
{"op":"mcm","clk":"11540892697","pt":1719499649211,"mc":[{"id":"1.230178315","rc":[{"atb":[[2.6,7.59],[2.58,11.84],[2.4,0],[2.36,20.22]],"id":45375136},{"atb":[[1.93,10.78],[1.82,0],[1.92,18.46],[1.79,1.82]],"id":63994056},{"atl":[[3.7,16.51],[3.65,8.83]],"id":63994056},{"atb":[[1.83,2.15],[1.96,20.06],[1.97,10.04],[1.86,0]],"id":69979804},{"atb":[[1.44,7.55],[1.43,16.15],[1.26,0],[1.34,0]],"id":70940946},{"atl":[[65,4.98]],"id":70940946},{"atb":[[2.5,14.77],[2.32,0],[2.52,8.73],[2.16,0]],"id":46251065}],"con":true,"img":false}]}
{"op":"mcm","clk":"11540892709","pt":1719499649270,"mc":[{"id":"1.230178315","rc":[{"atl":[[5.7,5.59]],"id":70466763},{"atl":[[70,0],[60,2]],"id":70940946}],"con":true,"img":false}]}
{"op":"mcm","clk":"11540892734","pt":1719499649587,"mc":[{"id":"1.230178315","rc":[{"atl":[[5.6,13.93]],"id":70466763}],"con":true,"img":false}]}
{"op":"mcm","clk":"11540892742","pt":1719499649688,"mc":[{"id":"1.230178315","rc":[{"atb":[[2.42,1.48]],"id":45375136},{"atb":[[1.85,1.88],[1.94,10.34]],"id":63994056},{"atl":[[3.8,7.41]],"id":63994056},{"atb":[[2.54,8.59],[2.36,0]],"id":46251065}],"con":true,"img":false}]}
{"op":"mcm","clk":"11540892748","pt":1719499649790,"mc":[{"id":"1.230178315","rc":[{"atb":[[2.62,6.82]],"id":45375136},{"atb":[[1.41,5.02],[1.42,1]],"id":70940946},{"atl":[[70,1],[75,0]],"id":70940946}],"con":true,"img":false}]}
{"op":"mcm","clk":"11540892755","pt":1719499649893,"mc":[{"id":"1.230178315","rc":[{"atb":[[1.96,17.52]],"id":69979804}],"con":true,"img":false}]}
{"op":"mcm","clk":"11540892813","pt":1719499650869,"mc":[{"id":"1.230178315","rc":[{"atb":[[2.54,4.4]],"id":70466763},{"atb":[[2.56,3.39]],"id":45375136},{"atb":[[2.48,4]],"id":46251065}],"con":true,"img":false}]}
{"op":"mcm","clk":"11540892824","pt":1719499651074,"mc":[{"id":"1.230178315","rc":[{"atb":[[2.62,1.94]],"id":70466763},{"atb":[[2.64,1.94]],"id":45375136},{"atb":[[2.56,1.94]],"id":46251065}],"con":true,"img":false}]}
{"op":"mcm","clk":"11540892832","pt":1719499651177,"mc":[{"id":"1.230178315","rc":[{"atb":[[2.54,0],[2.64,2.33]],"id":70466763},{"atb":[[2.56,0],[2.66,1.82]],"id":45375136},{"atb":[[1.96,14.82]],"id":69979804},{"atb":[[1.43,12.15]],"id":70940946},{"atb":[[2.58,2.44],[2.48,0]],"id":46251065}],"con":true,"img":false}]}
{"op":"mcm","clk":"11540892848","pt":1719499651385,"mc":[{"id":"1.230178315","rc":[{"atb":[[2.62,5.14]],"id":70466763},{"atb":[[2.64,5.43]],"id":45375136},{"atb":[[1.98,5]],"id":69979804},{"atb":[[1.45,3.9]],"id":70940946},{"atb":[[2.56,4.94]],"id":46251065}],"con":true,"img":false}]}
{"op":"mcm","clk":"11540892854","pt":1719499651488,"mc":[{"id":"1.230178315","rc":[{"atb":[[1.99,2.56]],"id":69979804},{"atb":[[1.41,12.64]],"id":70940946}],"con":true,"img":false}]}
{"op":"mcm","clk":"11540892862","pt":1719499651594,"mc":[{"id":"1.230178315","rc":[{"atb":[[2.58,0]],"id":70466763},{"atb":[[2.6,5.05]],"id":45375136},{"atb":[[1.93,8.24]],"id":63994056},{"atb":[[2.52,6.19]],"id":46251065}],"con":true,"img":false}]}
{"op":"mcm","clk":"11540892946","pt":1719499652684,"mc":[{"id":"1.230178315","rc":[{"atb":[[1.42,6.26]],"id":70940946}],"con":true,"img":false}]}
{"op":"mcm","clk":"11540892953","pt":1719499652777,"mc":[{"id":"1.230178315","rc":[{"atb":[[2,2.53]],"id":69979804},{"atb":[[1.41,5.02]],"id":70940946}],"con":true,"img":false}]}
{"op":"mcm","clk":"11540892961","pt":1719499652881,"mc":[{"id":"1.230178315","rc":[{"atb":[[2.02,3.62]],"id":69979804}],"con":true,"img":false}]}
{"op":"mcm","clk":"11540892972","pt":1719499653094,"mc":[{"id":"1.230178315","rc":[{"atl":[[3.6,0.84]],"id":63994056}],"con":true,"img":false}]}
{"op":"mcm","clk":"11540892995","pt":1719499653402,"mc":[{"id":"1.230178315","rc":[{"atl":[[3.65,7.83]],"id":63994056}],"con":true,"img":false}]}
{"op":"mcm","clk":"11540893027","pt":1719499653803,"mc":[{"id":"1.230178315","rc":[{"spn":4.02,"spf":"NaN","id":70466763},{"spn":4.03,"spf":"NaN","id":45375136},{"spn":2.77,"spf":"NaN","id":63994056},{"spn":2.76,"spf":"NaN","id":69979804},{"atb":[[1.42,1]],"id":70940946},{"spn":30.72,"spf":"NaN","id":70940946},{"spn":2.56,"spf":1.0,"id":46251065}],"con":true,"img":false}]}
{"op":"mcm","clk":"11540893044","pt":1719499654008,"mc":[{"id":"1.230178315","rc":[{"atb":[[2.62,3.2]],"id":70466763},{"atb":[[2.56,3]],"id":46251065}],"con":true,"img":false}]}
{"op":"mcm","clk":"11540893059","pt":1719499654171,"mc":[{"id":"1.230178315","rc":[{"atb":[[2.66,1.94]],"id":70466763},{"atb":[[2.04,1.94]],"id":69979804}],"con":true,"img":false}]}
{"op":"mcm","clk":"11540893066","pt":1719499654272,"mc":[{"id":"1.230178315","rc":[{"atb":[[2.68,2.25]],"id":70466763},{"atb":[[2,0],[2.06,3.71]],"id":69979804},{"atb":[[1.44,5.01],[1.43,13.15],[1.42,0]],"id":70940946}],"con":true,"img":false}]}
{"op":"mcm","clk":"11540893076","pt":1719499654377,"mc":[{"id":"1.230178315","rc":[{"atl":[[5.6,5.84],[5.5,4.84]],"id":45375136}],"con":true,"img":false}]}
{"op":"mcm","clk":"11540893086","pt":1719499654480,"mc":[{"id":"1.230178315","rc":[{"atl":[[5.6,1.99],[5.7,18.21]],"id":70466763},{"atb":[[1.71,0],[1.8,16.96]],"id":63994056},{"atb":[[1.6,0],[1.68,28.07]],"id":69979804}],"con":true,"img":false}]}
{"op":"mcm","clk":"11540893099","pt":1719499654691,"mc":[{"id":"1.230178315","rc":[{"atb":[[2.62,0]],"id":70466763},{"atb":[[2.64,1.94]],"id":45375136},{"atb":[[1.98,0]],"id":69979804},{"atb":[[2.56,0]],"id":46251065}],"con":true,"img":false}]}
{"op":"mcm","clk":"11540893107","pt":1719499654792,"mc":[{"id":"1.230178315","rc":[{"atb":[[2.68,6.25]],"id":70466763},{"atb":[[2.66,4.22]],"id":45375136},{"atb":[[1.95,3.53]],"id":63994056},{"atb":[[2.08,2.77]],"id":69979804},{"atb":[[2.58,5.54]],"id":46251065}],"con":true,"img":false}]}
{"op":"mcm","clk":"11540893118","pt":1719499654893,"mc":[{"id":"1.230178315","rc":[{"atb":[[1.96,2.67]],"id":63994056},{"atb":[[2.1,3.8]],"id":69979804}],"con":true,"img":false}]}
{"op":"mcm","clk":"11540893149","pt":1719499655297,"mc":[{"id":"1.230178315","rc":[{"atb":[[1.99,7.9]],"id":69979804}],"con":true,"img":false}]}
{"op":"mcm","clk":"11540893159","pt":1719499655406,"mc":[{"id":"1.230178315","rc":[{"atb":[[2.68,8.78]],"id":70466763},{"atb":[[2.68,2.53]],"id":45375136},{"atb":[[1.95,6.06]],"id":63994056},{"atl":[[3.55,1]],"id":63994056},{"atb":[[2.6,2.53]],"id":46251065}],"con":true,"img":false}]}
{"op":"mcm","clk":"11540893165","pt":1719499655508,"mc":[{"id":"1.230178315","rc":[{"atb":[[2.34,0],[2.38,0],[2.66,13.01],[2.7,5.52]],"id":70466763},{"atb":[[2.7,1.9]],"id":45375136},{"atb":[[1.84,0],[1.96,10.88],[1.87,0.52]],"id":63994056},{"atb":[[1.87,2.63],[2.1,11.18],[2.08,17.54],[1.88,6.27]],"id":69979804},{"atb":[[1.45,8.9],[1.38,0]],"id":70940946},{"atl":[[65,4.81]],"id":70940946},{"atb":[[2.6,8.71],[2.62,2.38],[2.38,2.25]],"id":46251065}],"con":true,"img":false}]}
{"op":"mcm","clk":"11540893173","pt":1719499655617,"mc":[{"id":"1.230178315","rc":[{"atb":[[2.72,2.16]],"id":70466763},{"atb":[[1.95,22.49]],"id":63994056},{"atl":[[55,0.21]],"id":70940946}],"con":true,"img":false}]}
{"op":"mcm","clk":"11540893181","pt":1719499655710,"mc":[{"id":"1.230178315","rc":[{"atb":[[1.99,2.56]],"id":69979804}],"con":true,"img":false}]}
{"op":"mcm","clk":"11540893187","pt":1719499655772,"mc":[{"id":"1.230178315","rc":[{"atb":[[2.36,1.14],[2.42,13.22]],"id":45375136},{"atl":[[65,5.81],[70,0]],"id":70940946}],"con":true,"img":false}]}
{"op":"mcm","clk":"11540893202","pt":1719499655976,"mc":[{"id":"1.230178315","rc":[{"atb":[[2.14,0],[2.28,14.73]],"id":46251065}],"con":true,"img":false}]}
{"op":"mcm","clk":"11540893253","pt":1719499656802,"mc":[{"id":"1.230178315","rc":[{"atl":[[3.55,3.53]],"id":63994056},{"atl":[[3.45,2.53]],"id":69979804},{"atb":[[1.37,0],[1.35,5]],"id":70940946}],"con":true,"img":false}]}
{"op":"mcm","clk":"11540893265","pt":1719499656899,"mc":[{"id":"1.230178315","rc":[{"atb":[[2.68,6.25]],"id":70466763},{"atb":[[2.68,0]],"id":45375136},{"atb":[[1.95,19.95]],"id":63994056},{"atb":[[2.6,6.17]],"id":46251065}],"con":true,"img":false}]}
{"op":"mcm","clk":"11540893273","pt":1719499657003,"mc":[{"id":"1.230178315","rc":[{"atb":[[2.66,11.06]],"id":70466763},{"atb":[[2.64,0]],"id":45375136},{"atb":[[2.04,0]],"id":69979804},{"atb":[[1.46,12.01],[1.47,8.4]],"id":70940946}],"con":true,"img":false}]}
{"op":"mcm","clk":"11540893288","pt":1719499657211,"mc":[{"id":"1.230178315","rc":[{"atb":[[2.74,1.94]],"id":70466763},{"atb":[[2.7,3.84]],"id":45375136},{"atl":[[3.6,16.53],[3.85,0],[3.55,11.38]],"id":63994056},{"atl":[[3.45,9.61],[3.65,0]],"id":69979804},{"atl":[[55,5.03]],"id":70940946},{"atb":[[2.62,8.48],[2.42,2.33]],"id":46251065}],"con":true,"img":false}]}
{"op":"mcm","clk":"11540893297","pt":1719499657306,"mc":[{"id":"1.230178315","rc":[{"atb":[[2.76,2.08]],"id":70466763},{"atl":[[3.4,0.84]],"id":69979804},{"atb":[[1.45,9.9],[1.43,12.15]],"id":70940946},{"atl":[[50,2.04],[60,0]],"id":70940946}],"con":true,"img":false}]}
{"op":"mcm","clk":"11540893312","pt":1719499657512,"mc":[{"id":"1.230178315","rc":[{"atb":[[2.76,7.61],[2.4,2.88],[2.74,13.02]],"id":70466763},{"atl":[[3.7,15.66]],"id":63994056},{"atb":[[1.46,22.05],[1.48,5.01],[1.4,0],[1.29,0]],"id":70940946}],"con":true,"img":false}]}
{"op":"mcm","clk":"11540893318","pt":1719499657572,"mc":[{"id":"1.230178315","rc":[{"atb":[[2.42,0]],"id":70466763}],"con":true,"img":false}]}
{"op":"mcm","clk":"11540893325","pt":1719499657677,"mc":[{"id":"1.230178315","rc":[{"atl":[[5.7,5.59],[5.9,12.26]],"id":70466763}],"con":true,"img":false}]}
{"op":"mcm","clk":"11540893340","pt":1719499657881,"mc":[{"id":"1.230178315","rc":[{"atl":[[65,1],[50,6.86]],"id":70940946}],"con":true,"img":false}]}
{"op":"mcm","clk":"11540893349","pt":1719499657981,"mc":[{"id":"1.230178315","rc":[{"atb":[[2.68,2.25]],"id":70466763},{"atb":[[2.66,1.82]],"id":45375136},{"atb":[[1.95,16.42]],"id":63994056},{"atb":[[2.08,14.77]],"id":69979804},{"atb":[[1.45,6]],"id":70940946},{"atb":[[2.58,2.44]],"id":46251065}],"con":true,"img":false}]}
{"op":"mcm","clk":"11540893355","pt":1719499658085,"mc":[{"id":"1.230178315","rc":[{"atb":[[2.78,3.79]],"id":70466763},{"atb":[[2.72,3]],"id":45375136},{"atb":[[1.97,2.92]],"id":63994056},{"atb":[[2.12,3.79]],"id":69979804},{"atb":[[1.46,23.05],[1.45,5],[1.48,9.01]],"id":70940946},{"atl":[[65,0],[60,1]],"id":70940946},{"atb":[[2.64,4.2]],"id":46251065}],"con":true,"img":false}]}
{"op":"mcm","clk":"11540893365","pt":1719499658187,"mc":[{"id":"1.230178315","rc":[{"atb":[[2.8,2]],"id":70466763},{"atb":[[2.74,1.94]],"id":45375136},{"atb":[[1.98,2.59]],"id":63994056},{"atb":[[2.14,3.97]],"id":69979804},{"atb":[[2.66,2.29]],"id":46251065}],"con":true,"img":false}]}
{"op":"mcm","clk":"11540893383","pt":1719499658394,"mc":[{"id":"1.230178315","rc":[{"atb":[[2.72,13.18],[2.74,7.03],[2.46,1.59]],"id":45375136},{"atl":[[3.6,0],[3.4,7.9]],"id":69979804}],"con":true,"img":false}]}
{"op":"mcm","clk":"11540893394","pt":1719499658501,"mc":[{"id":"1.230178315","rc":[{"atb":[[2.44,0]],"id":45375136},{"atl":[[5.6,4.84],[5.7,1]],"id":45375136}],"con":true,"img":false}]}
{"op":"mcm","clk":"11540893411","pt":1719499658703,"mc":[{"id":"1.230178315","rc":[{"atl":[[5.6,5.84],[5.7,0]],"id":45375136},{"atl":[[55,4.82]],"id":70940946}],"con":true,"img":false}]}
{"op":"mcm","clk":"11540893418","pt":1719499658806,"mc":[{"id":"1.230178315","rc":[{"atb":[[1.99,2.11],[1.91,0]],"id":63994056},{"atb":[[2.16,2.11],[1.94,0]],"id":69979804},{"atb":[[1.43,10.04],[1.5,2.11]],"id":70940946},{"atl":[[48,0.23]],"id":70940946},{"atb":[[2.66,15.86]],"id":46251065},{"atl":[[4.1,14.47]],"id":46251065}],"con":true,"img":false}]}
{"op":"mcm","clk":"11540893422","pt":1719499658907,"mc":[{"id":"1.230178315","rc":[{"atb":[[1.99,4.67]],"id":63994056}],"con":true,"img":false}]}
{"op":"mcm","clk":"11540893429","pt":1719499659009,"mc":[{"id":"1.230178315","rc":[{"atb":[[1.69,34.21],[1.8,0]],"id":63994056},{"atb":[[1.68,0]],"id":69979804}],"con":true,"img":false}]}
{"op":"mcm","clk":"11540893436","pt":1719499659114,"mc":[{"id":"1.230178315","rc":[{"atb":[[1.59,28.07]],"id":69979804},{"atb":[[1.46,22.05],[1.48,10.01]],"id":70940946},{"atl":[[55,5.82],[60,0]],"id":70940946}],"con":true,"img":false}]}
{"op":"mcm","clk":"11540893441","pt":1719499659218,"mc":[{"id":"1.230178315","rc":[{"atl":[[3.5,7.03]],"id":69979804},{"atb":[[2.12,10.86],[2.28,0]],"id":46251065}],"con":true,"img":false}]}
{"op":"mcm","clk":"11540893460","pt":1719499659414,"mc":[{"id":"1.230178315","rc":[{"atb":[[2.72,6.55]],"id":70466763}],"con":true,"img":false}]}
{"op":"mcm","clk":"11540893479","pt":1719499659580,"mc":[{"id":"1.230178315","rc":[{"atb":[[2.56,8]],"id":46251065}],"con":true,"img":false}]}
{"op":"mcm","clk":"11540893510","pt":1719499660008,"mc":[{"id":"1.230178315","rc":[{"atb":[[2.74,11.07]],"id":70466763},{"atb":[[2.7,1.9]],"id":45375136}],"con":true,"img":false}]}
{"op":"mcm","clk":"11540893523","pt":1719499660095,"mc":[{"id":"1.230178315","rc":[{"atl":[[3.5,0.84]],"id":63994056}],"con":true,"img":false}]}
{"op":"mcm","clk":"11540893532","pt":1719499660199,"mc":[{"id":"1.230178315","rc":[{"atb":[[2.8,3.94]],"id":70466763},{"atb":[[2.76,1.94]],"id":45375136}],"con":true,"img":false}]}
{"op":"mcm","clk":"11540893541","pt":1719499660302,"mc":[{"id":"1.230178315","rc":[{"atl":[[3.55,10.38]],"id":63994056}],"con":true,"img":false}]}
{"op":"mcm","clk":"11540893553","pt":1719499660410,"mc":[{"id":"1.230178315","rc":[{"atb":[[2.78,1.99]],"id":45375136},{"atl":[[3.45,7.07]],"id":69979804}],"con":true,"img":false}]}
{"op":"mcm","clk":"11540893569","pt":1719499660611,"mc":[{"id":"1.230178315","rc":[{"atb":[[2.8,9.48],[2.44,2.87],[2.46,0],[2.78,14.87]],"id":70466763},{"atb":[[2.48,0],[2.76,12.17],[2.78,7.1]],"id":45375136},{"atb":[[1.98,19.05],[1.99,12.9],[1.88,1.92],[1.86,0]],"id":63994056},{"atl":[[3.8,0],[3.5,8.71]],"id":63994056},{"atb":[[2.14,18.74],[1.9,0],[2.16,9.5],[1.89,2.85]],"id":69979804},{"atb":[[1.41,0],[1.36,0],[1.5,7.13],[1.49,10.04]],"id":70940946},{"atb":[[2.3,0],[2.64,16.41],[2.52,0],[2.68,6.1]],"id":46251065}],"con":true,"img":false}]}
{"op":"mcm","clk":"11540893576","pt":1719499660711,"mc":[{"id":"1.230178315","rc":[{"atb":[[2.5,1.65]],"id":45375136}],"con":true,"img":false}]}
{"op":"mcm","clk":"11540893581","pt":1719499660815,"mc":[{"id":"1.230178315","rc":[{"atb":[[2.72,2.16]],"id":70466763},{"atl":[[5.6,0]],"id":70466763},{"atb":[[1.98,16.46],[1.96,8.21],[1.99,10.34]],"id":63994056},{"atl":[[48,5.04],[55,1]],"id":70940946},{"atb":[[2.7,2.21]],"id":46251065},{"atl":[[4,5.84],[4.6,0]],"id":46251065}],"con":true,"img":false}]}
{"op":"mcm","clk":"11540893589","pt":1719499660918,"mc":[{"id":"1.230178315","rc":[{"atb":[[2.42,1.48],[2.52,13.85]],"id":45375136},{"atl":[[46,2.22]],"id":70940946}],"con":true,"img":false}]}
{"op":"mcm","clk":"11540893597","pt":1719499661018,"mc":[{"id":"1.230178315","rc":[{"atl":[[3.55,7.01]],"id":69979804},{"atl":[[50,4.82]],"id":70940946}],"con":true,"img":false}]}
{"op":"mcm","clk":"11540893603","pt":1719499661115,"mc":[{"id":"1.230178315","rc":[{"atl":[[5.4,8.28]],"id":70466763},{"atl":[[3.6,15.69]],"id":63994056},{"atl":[[50,5.82],[55,0]],"id":70940946},{"atl":[[3.95,0.84]],"id":46251065}],"con":true,"img":false}]}
{"op":"mcm","clk":"11540893606","pt":1719499661177,"mc":[{"id":"1.230178315","rc":[{"atl":[[5.4,16.17]],"id":70466763},{"atl":[[5.4,13.6]],"id":45375136},{"atb":[[1.99,18.23]],"id":63994056},{"atl":[[3.5,16.6]],"id":63994056},{"atl":[[3.4,15.79]],"id":69979804},{"atb":[[1.5,15.02]],"id":70940946},{"atl":[[48,12.93]],"id":70940946},{"atb":[[2.56,0],[2.68,13.99],[2.7,8.3]],"id":46251065}],"con":true,"img":false}]}
{"op":"mcm","clk":"11540893614","pt":1719499661281,"mc":[{"id":"1.230178315","rc":[{"atl":[[5.3,4.93]],"id":45375136},{"atb":[[2,8.27],[1.93,0]],"id":63994056},{"atb":[[1.44,0],[1.51,5]],"id":70940946},{"atb":[[2.54,2.4],[2.66,2.29]],"id":46251065},{"atl":[[4.1,6.74]],"id":46251065}],"con":true,"img":false}]}
{"op":"mcm","clk":"11540893622","pt":1719499661385,"mc":[{"id":"1.230178315","rc":[{"atb":[[2.78,11.08]],"id":70466763},{"atb":[[2.72,10.18]],"id":45375136},{"atb":[[1.97,0]],"id":63994056},{"atb":[[2.12,0]],"id":69979804},{"atb":[[1.48,6.01]],"id":70940946},{"atb":[[2.64,12.21]],"id":46251065}],"con":true,"img":false}]}
{"op":"mcm","clk":"11540893629","pt":1719499661488,"mc":[{"id":"1.230178315","rc":[{"atb":[[2.82,4]],"id":70466763},{"atl":[[5.8,0],[5.3,5.34]],"id":70466763},{"atb":[[2.8,3]],"id":45375136},{"atb":[[2,12.27]],"id":63994056},{"atb":[[2.18,3.71]],"id":69979804},{"atl":[[3.35,7.02],[3.55,0],[3.5,18.89]],"id":69979804},{"atb":[[1.49,11.04],[1.51,9.81],[1.48,5.01]],"id":70940946},{"atb":[[2.7,12.5]],"id":46251065}],"con":true,"img":false}]}
{"op":"mcm","clk":"11540893637","pt":1719499661588,"mc":[{"id":"1.230178315","rc":[{"atl":[[5.2,0.84]],"id":45375136},{"atl":[[3.45,7.86],[3.75,0]],"id":63994056}],"con":true,"img":false}]}
{"op":"mcm","clk":"11540893658","pt":1719499661896,"mc":[{"id":"1.230178315","rc":[{"atl":[[48,12.7]],"id":70940946}],"con":true,"img":false}]}
{"op":"mcm","clk":"11540893663","pt":1719499661994,"mc":[{"id":"1.230178315","rc":[{"atl":[[44,0.34]],"id":70940946}],"con":true,"img":false}]}
{"op":"mcm","clk":"11540893671","pt":1719499662100,"mc":[{"id":"1.230178315","rc":[{"atl":[[5.2,0.84]],"id":70466763}],"con":true,"img":false}]}
{"op":"mcm","clk":"11540893680","pt":1719499662211,"mc":[{"id":"1.230178315","rc":[{"atl":[[5.2,6.2],[5.7,0]],"id":70466763},{"atl":[[44,5.16],[50,1]],"id":70940946},{"atb":[[2.7,27.58]],"id":46251065},{"atl":[[3.95,15.32],[4.4,0]],"id":46251065}],"con":true,"img":false}]}
{"op":"mcm","clk":"11540893688","pt":1719499662307,"mc":[{"id":"1.230178315","rc":[{"atb":[[2.82,9.55],[2.84,1.93],[2.48,2.75]],"id":70466763},{"atl":[[5.4,8.28]],"id":70466763},{"atb":[[2.8,8.11],[2.82,1.97]],"id":45375136},{"atl":[[5.6,1],[5.2,5.79],[5.4,5.71]],"id":45375136},{"atb":[[1.99,10.34]],"id":63994056},{"atl":[[3.5,8.71]],"id":63994056},{"atb":[[1.91,2.9],[2.18,11.04]],"id":69979804},{"atl":[[3.4,7.9]],"id":69979804},{"atb":[[1.5,7.13]],"id":70940946},{"atl":[[48,5.81],[50,0]],"id":70940946},{"atb":[[2.72,6.06]],"id":46251065}],"con":true,"img":false}]}
{"op":"mcm","clk":"11540893700","pt":1719499662414,"mc":[{"id":"1.230178315","rc":[{"atl":[[5.3,13.23]],"id":70466763},{"atb":[[2.6,0]],"id":45375136},{"atl":[[5.2,13.68]],"id":45375136},{"atb":[[2,20.16]],"id":63994056},{"atl":[[3.45,15.76],[3.4,1]],"id":63994056},{"atl":[[3.35,14.91]],"id":69979804},{"atb":[[1.51,17.7]],"id":70940946},{"atl":[[42,2.44],[46,7.89]],"id":70940946},{"atb":[[2.6,0],[2.68,6.1]],"id":46251065}],"con":true,"img":false}]}
{"op":"mcm","clk":"11540893706","pt":1719499662517,"mc":[{"id":"1.230178315","rc":[{"atb":[[2.7,35.47]],"id":46251065}],"con":true,"img":false}]}
{"op":"mcm","clk":"11540893717","pt":1719499662620,"mc":[{"id":"1.230178315","rc":[{"atb":[[2.84,7.47],[2.7,0]],"id":70466763},{"atl":[[5.4,7.43]],"id":70466763},{"atl":[[5.1,4.99],[5.4,4.86]],"id":45375136},{"atb":[[1.94,2.11],[2.02,8.28]],"id":63994056},{"atb":[[1.45,0],[1.52,4.98]],"id":70940946},{"atl":[[4.1,5.9]],"id":46251065}],"con":true,"img":false}]}
{"op":"mcm","clk":"11540893723","pt":1719499662714,"mc":[{"id":"1.230178315","rc":[{"atl":[[5.5,0]],"id":45375136},{"atl":[[46,8.89],[48,4.81]],"id":70940946}],"con":true,"img":false}]}
{"op":"mcm","clk":"11540893731","pt":1719499662818,"mc":[{"id":"1.230178315","rc":[{"atl":[[5.7,13.65],[5.9,1]],"id":70466763},{"atl":[[3.3,2.53]],"id":69979804}],"con":true,"img":false}]}
{"op":"mcm","clk":"11540893747","pt":1719499662982,"mc":[{"id":"1.230178315","rc":[{"atb":[[2.7,34.61]],"id":46251065}],"con":true,"img":false}]}
{"op":"mcm","clk":"11540893754","pt":1719499663090,"mc":[{"id":"1.230178315","rc":[{"atb":[[2.8,7.53]],"id":70466763},{"atb":[[2.76,10.22]],"id":45375136},{"atl":[[40,0.84]],"id":70940946}],"con":true,"img":false}]}
{"op":"mcm","clk":"11540893758","pt":1719499663191,"mc":[{"id":"1.230178315","rc":[{"atb":[[2.86,1.94]],"id":70466763},{"atl":[[5.3,5.34]],"id":70466763},{"atb":[[2.82,3.91]],"id":45375136},{"atl":[[5.2,5.79]],"id":45375136},{"atb":[[2,12.27]],"id":63994056},{"atl":[[3.4,7.05]],"id":69979804},{"atb":[[1.51,9.81]],"id":70940946},{"atl":[[46,1]],"id":70940946},{"atb":[[2.7,12.5]],"id":46251065}],"con":true,"img":false}]}
{"op":"mcm","clk":"11540893768","pt":1719499663291,"mc":[{"id":"1.230178315","rc":[{"atl":[[5.2,14.09]],"id":70466763},{"atl":[[5.1,12.88]],"id":45375136},{"atb":[[2.02,16.17]],"id":63994056},{"atb":[[1.52,12.87]],"id":70940946},{"atl":[[42,10.33]],"id":70940946},{"atb":[[2.72,28.17]],"id":46251065}],"con":true,"img":false}]}
{"op":"mcm","clk":"11540893772","pt":1719499663395,"mc":[{"id":"1.230178315","rc":[{"atb":[[2.76,2.08],[2.86,7.47]],"id":70466763},{"atl":[[5,5.09]],"id":45375136},{"atb":[[2.04,8.22],[1.96,0]],"id":63994056},{"atb":[[1.48,0],[1.53,4.95]],"id":70940946},{"atb":[[2.62,2.38],[2.74,6]],"id":46251065}],"con":true,"img":false}]}
{"op":"mcm","clk":"11540893779","pt":1719499663498,"mc":[{"id":"1.230178315","rc":[{"atl":[[5.4,0]],"id":45375136}],"con":true,"img":false}]}
{"op":"mcm","clk":"11540893785","pt":1719499663600,"mc":[{"id":"1.230178315","rc":[{"atl":[[5.2,4.94]],"id":45375136},{"atb":[[2.14,14.77]],"id":69979804},{"atb":[[2.72,26.38]],"id":46251065}],"con":true,"img":false}]}
{"op":"mcm","clk":"11540893793","pt":1719499663706,"mc":[{"id":"1.230178315","rc":[{"atb":[[2.72,14.57]],"id":45375136},{"atb":[[1.49,10.04],[1.51,10.81]],"id":70940946},{"atl":[[44,6.16],[46,0]],"id":70940946}],"con":true,"img":false}]}
{"op":"mcm","clk":"11540893804","pt":1719499663814,"mc":[{"id":"1.230178315","rc":[{"atb":[[2.72,10.18]],"id":45375136},{"atb":[[2.72,13.95]],"id":46251065}],"con":true,"img":false}]}
{"op":"mcm","clk":"11540893815","pt":1719499663916,"mc":[{"id":"1.230178315","rc":[{"atb":[[1.48,20.61]],"id":70940946},{"atb":[[2.74,18.43]],"id":46251065}],"con":true,"img":false}]}
{"op":"mcm","clk":"11540893825","pt":1719499664015,"mc":[{"id":"1.230178315","rc":[{"atl":[[5.1,7.44],[5.7,0]],"id":70466763},{"atl":[[6.2,9.9],[7,0]],"id":45375136},{"atb":[[1.81,0]],"id":63994056},{"atl":[[4.1,0],[3.7,34.76]],"id":63994056},{"atb":[[1.8,0],[1.77,0]],"id":69979804},{"atl":[[3.45,21.19],[3.8,0]],"id":69979804},{"atl":[[5.2,11.82],[3.9,5.79],[5.9,0]],"id":46251065}],"con":true,"img":false}]}
{"op":"mcm","clk":"11540893833","pt":1719499664116,"mc":[{"id":"1.230178315","rc":[{"atl":[[3.55,7.84]],"id":63994056},{"atb":[[1.49,16.3]],"id":70940946},{"atl":[[4.2,0]],"id":46251065}],"con":true,"img":false}]}
{"op":"mcm","clk":"11540893838","pt":1719499664215,"mc":[{"id":"1.230178315","rc":[{"atl":[[5.1,4.99]],"id":45375136},{"atb":[[2.02,8.28]],"id":63994056},{"atl":[[3.35,7.02]],"id":69979804},{"atb":[[1.52,4.98]],"id":70940946},{"atl":[[42,2.44]],"id":70940946},{"atb":[[2.72,6.06]],"id":46251065}],"con":true,"img":false}]}
{"op":"mcm","clk":"11540893844","pt":1719499664318,"mc":[{"id":"1.230178315","rc":[{"atl":[[5,12.98]],"id":45375136},{"atb":[[2.04,16.11]],"id":63994056},{"atl":[[3.3,10.43]],"id":69979804},{"atb":[[1.53,12.84],[1.48,0],[1.49,15.3]],"id":70940946},{"atl":[[40,8.73]],"id":70940946},{"atb":[[2.74,26.32]],"id":46251065}],"con":true,"img":false}]}
{"op":"mcm","clk":"11540893849","pt":1719499664380,"mc":[{"id":"1.230178315","rc":[{"atb":[[2.82,9.21],[2.62,1.77]],"id":45375136},{"atb":[[1.54,4.94],[1.5,2.11]],"id":70940946},{"atl":[[38,2.7],[42,0]],"id":70940946}],"con":true,"img":false}]}
{"op":"mcm","clk":"11540893863","pt":1719499664583,"mc":[{"id":"1.230178315","rc":[{"atb":[[1.98,23.49]],"id":63994056},{"atl":[[3.25,0.84]],"id":69979804},{"atl":[[3.95,14.45]],"id":46251065}],"con":true,"img":false}]}
{"op":"mcm","clk":"11540893870","pt":1719499664687,"mc":[{"id":"1.230178315","rc":[{"atb":[[2.82,5.55]],"id":70466763},{"atb":[[2.8,5.11]],"id":45375136},{"atb":[[2,8.27]],"id":63994056},{"atb":[[1.51,5],[1.52,5.98]],"id":70940946},{"atl":[[42,1],[44,5.16]],"id":70940946},{"atb":[[2.7,8.3]],"id":46251065}],"con":true,"img":false}]}
{"op":"mcm","clk":"11540893876","pt":1719499664792,"mc":[{"id":"1.230178315","rc":[{"atb":[[2.88,4]],"id":70466763},{"atl":[[5.1,12.38]],"id":70466763},{"atb":[[2.84,3.7]],"id":45375136},{"atb":[[1.55,5],[1.3,0],[1.49,10.04]],"id":70940946},{"atb":[[2.76,3.2]],"id":46251065},{"atl":[[3.95,6.69]],"id":46251065}],"con":true,"img":false}]}
{"op":"mcm","clk":"11540893884","pt":1719499664892,"mc":[{"id":"1.230178315","rc":[{"atl":[[3.9,13.55]],"id":46251065}],"con":true,"img":false}]}
{"op":"mcm","clk":"11540893888","pt":1719499664998,"mc":[{"id":"1.230178315","rc":[{"atb":[[1.98,16.46]],"id":63994056},{"atl":[[44,4.82]],"id":70940946}],"con":true,"img":false}]}
{"op":"mcm","clk":"11540893899","pt":1719499665101,"mc":[{"id":"1.230178315","rc":[{"atb":[[2,11.39]],"id":63994056},{"atl":[[36,0.36]],"id":70940946}],"con":true,"img":false}]}
{"op":"mcm","clk":"11540893907","pt":1719499665205,"mc":[{"id":"1.230178315","rc":[{"atl":[[5.2,6.2]],"id":70466763},{"atl":[[3.3,2.53]],"id":69979804},{"atb":[[1.53,4.95]],"id":70940946}],"con":true,"img":false}]}
{"op":"mcm","clk":"11540893916","pt":1719499665310,"mc":[{"id":"1.230178315","rc":[{"atl":[[5.1,20.27]],"id":70466763},{"atl":[[3.25,8.73]],"id":69979804},{"atb":[[1.54,12.83]],"id":70940946},{"atl":[[40,0.84]],"id":70940946}],"con":true,"img":false}]}
{"op":"mcm","clk":"11540893922","pt":1719499665410,"mc":[{"id":"1.230178315","rc":[{"atl":[[38,7.89],[40,3.4]],"id":70940946},{"atb":[[2.74,13.89]],"id":46251065}],"con":true,"img":false}]}
{"op":"mcm","clk":"11540893936","pt":1719499665613,"mc":[{"id":"1.230178315","rc":[{"atb":[[2.84,17.52]],"id":45375136},{"atl":[[5,19.25]],"id":45375136},{"atl":[[3.4,3.53]],"id":63994056},{"atb":[[1.54,20.67]],"id":70940946}],"con":true,"img":false}]}
{"op":"mcm","clk":"11540893969","pt":1719499666020,"mc":[{"id":"1.230178315","rc":[{"atb":[[2.86,5.52]],"id":70466763},{"atb":[[2.82,7.27]],"id":45375136},{"atb":[[1.53,5.95],[1.52,4.98]],"id":70940946},{"atl":[[40,4.4],[42,0]],"id":70940946},{"atb":[[2.76,16.64]],"id":46251065}],"con":true,"img":false}]}
{"op":"mcm","clk":"11540893977","pt":1719499666078,"mc":[{"id":"1.230178315","rc":[{"atl":[[3.5,7.86]],"id":63994056}],"con":true,"img":false}]}
{"op":"mcm","clk":"11540893983","pt":1719499666185,"mc":[{"id":"1.230178315","rc":[{"atb":[[2.8,2],[2.88,9.51],[2.9,1.94]],"id":70466763},{"atl":[[5,5.35],[5.5,0]],"id":70466763},{"atb":[[2.74,1.94],[2.86,7.24]],"id":45375136},{"atl":[[5.3,0],[4.9,5.14]],"id":45375136},{"atl":[[3.4,11.43],[3.65,0]],"id":63994056},{"atl":[[3.2,6.99],[3.3,16.52],[3.5,11.86]],"id":69979804},{"atb":[[1.51,0],[1.55,9.92],[1.54,12.78]],"id":70940946},{"atl":[[38,0]],"id":70940946},{"atb":[[2.74,6],[2.78,5.99],[2.68,0]],"id":46251065},{"atl":[[3.85,5.81],[4.1,0]],"id":46251065}],"con":true,"img":false}]}
{"op":"mcm","clk":"11540893991","pt":1719499666283,"mc":[{"id":"1.230178315","rc":[{"atb":[[1.55,17.81]],"id":70940946},{"atl":[[36,8.25]],"id":70940946},{"atb":[[2.76,24.53]],"id":46251065}],"con":true,"img":false}]}
{"op":"mcm","clk":"11540894005","pt":1719499666497,"mc":[{"id":"1.230178315","rc":[{"atl":[[5.8,1],[5.9,0]],"id":70466763},{"atl":[[5.6,0],[5.5,1]],"id":45375136}],"con":true,"img":false}]}
{"op":"mcm","clk":"11540894020","pt":1719499666698,"mc":[{"id":"1.230178315","rc":[{"atl":[[5.2,5.36]],"id":70466763},{"atl":[[40,3.56]],"id":70940946},{"atl":[[3.95,5.84]],"id":46251065}],"con":true,"img":false}]}
{"op":"mcm","clk":"11540894029","pt":1719499666802,"mc":[{"id":"1.230178315","rc":[{"atl":[[5.1,15.33]],"id":70466763},{"atb":[[2.84,14.85]],"id":45375136},{"atl":[[5,19.18]],"id":45375136},{"atb":[[2,8.27]],"id":63994056},{"atl":[[3.3,13.98]],"id":69979804},{"atb":[[1.56,4.89],[1.52,0]],"id":70940946},{"atb":[[2.76,24.52]],"id":46251065},{"atl":[[3.9,13.51]],"id":46251065}],"con":true,"img":false}]}
{"op":"mcm","clk":"11540894044","pt":1719499667002,"mc":[{"id":"1.230178315","rc":[{"atb":[[2.84,3.7]],"id":45375136},{"atl":[[5,12.98]],"id":45375136},{"atb":[[2.76,11.09]],"id":46251065},{"atl":[[3.9,5.79]],"id":46251065}],"con":true,"img":false}]}
{"op":"mcm","clk":"11540894054","pt":1719499667107,"mc":[{"id":"1.230178315","rc":[{"atb":[[2.86,18.39]],"id":45375136},{"atl":[[4.9,11.34]],"id":45375136},{"atb":[[2.78,19.42]],"id":46251065},{"atl":[[3.85,13.53]],"id":46251065}],"con":true,"img":false}]}
{"op":"mcm","clk":"11540894064","pt":1719499667209,"mc":[{"id":"1.230178315","rc":[{"atb":[[2.82,0]],"id":70466763},{"atl":[[5.1,7.44]],"id":70466763},{"atb":[[2.88,5.29],[2.78,1.99]],"id":45375136},{"atl":[[4.8,5.15],[5,5.09],[5.2,0]],"id":45375136},{"atl":[[3.25,0.84]],"id":69979804},{"atl":[[34,4.76]],"id":70940946},{"atb":[[2.8,6],[2.76,3.2],[2.7,2.21]],"id":46251065},{"atl":[[4,0],[3.8,5.82]],"id":46251065}],"con":true,"img":false}]}
{"op":"mcm","clk":"11540894072","pt":1719499667313,"mc":[{"id":"1.230178315","rc":[{"atb":[[2.9,7.46]],"id":70466763},{"atl":[[5,13.24]],"id":70466763},{"atl":[[4.9,19.23]],"id":45375136},{"atl":[[3.2,14.88]],"id":69979804},{"atl":[[48,0]],"id":70940946},{"atb":[[2.78,27.31]],"id":46251065}],"con":true,"img":false}]}
{"op":"mcm","clk":"11540894080","pt":1719499667413,"mc":[{"id":"1.230178315","rc":[{"atl":[[4.9,5.37],[5.4,1.97]],"id":70466763},{"atl":[[3.45,14.12],[3.15,7.01]],"id":69979804}],"con":true,"img":false}]}
{"op":"mcm","clk":"11540894089","pt":1719499667515,"mc":[{"id":"1.230178315","rc":[{"atb":[[1.54,13.78],[1.53,4.95]],"id":70940946},{"atl":[[38,1],[40,2.56]],"id":70940946}],"con":true,"img":false}]}
{"op":"mcm","clk":"11540894099","pt":1719499667621,"mc":[{"id":"1.230178315","rc":[{"atb":[[2.86,7.24]],"id":45375136},{"atl":[[4.9,13.03]],"id":45375136},{"atl":[[3.35,0.84]],"id":63994056},{"atb":[[2.78,25.37]],"id":46251065},{"atl":[[3.85,12.97]],"id":46251065}],"con":true,"img":false}]}
{"op":"mcm","clk":"11540894113","pt":1719499667820,"mc":[{"id":"1.230178315","rc":[{"atb":[[2.78,13.88]],"id":46251065},{"atl":[[3.85,5.81]],"id":46251065}],"con":true,"img":false}]}
{"op":"mcm","clk":"11540894119","pt":1719499667922,"mc":[{"id":"1.230178315","rc":[{"atl":[[3.4,10.43]],"id":63994056},{"atb":[[2.8,17.49]],"id":46251065},{"atl":[[3.8,12.98]],"id":46251065}],"con":true,"img":false}]}
{"op":"mcm","clk":"11540894127","pt":1719499668024,"mc":[{"id":"1.230178315","rc":[{"atl":[[4.9,11.3]],"id":70466763}],"con":true,"img":false}]}
{"op":"mcm","clk":"11540894135","pt":1719499668129,"mc":[{"id":"1.230178315","rc":[{"atb":[[2.88,5.51]],"id":70466763},{"atl":[[4.8,5.37]],"id":70466763},{"atb":[[2.84,0]],"id":45375136},{"atl":[[3.35,8.77],[3.55,0]],"id":63994056},{"atl":[[3.15,9.55],[3.25,0]],"id":69979804},{"atb":[[1.55,12.81]],"id":70940946},{"atl":[[36,7.89]],"id":70940946},{"atb":[[2.76,0]],"id":46251065},{"atl":[[3.95,0],[3.75,6.68]],"id":46251065}],"con":true,"img":false}]}
{"op":"mcm","clk":"11540894143","pt":1719499668193,"mc":[{"id":"1.230178315","rc":[{"atl":[[5,5.35],[5.3,0]],"id":70466763},{"atl":[[4.9,5.14]],"id":45375136},{"atl":[[3.2,6.99]],"id":69979804},{"atb":[[1.55,4.92]],"id":70940946},{"atl":[[32,0.36],[36,0]],"id":70940946},{"atb":[[2.78,5.99]],"id":46251065}],"con":true,"img":false}]}
{"op":"mcm","clk":"11540894150","pt":1719499668291,"mc":[{"id":"1.230178315","rc":[{"atb":[[2.92,3.7]],"id":70466763},{"atl":[[4.9,19.19]],"id":70466763},{"atb":[[2.9,2.58]],"id":45375136},{"atl":[[4.8,13.04]],"id":45375136},{"atl":[[3.15,17.44]],"id":69979804},{"atb":[[1.56,12.78],[1.67,4.74]],"id":70940946},{"atl":[[34,12.65]],"id":70940946},{"atb":[[2.8,25.38],[2.82,2.53]],"id":46251065}],"con":true,"img":false}]}
{"op":"mcm","clk":"11540894158","pt":1719499668395,"mc":[{"id":"1.230178315","rc":[{"atl":[[4.9,19.13]],"id":70466763},{"atb":[[2.58,23.69],[2.52,0]],"id":45375136},{"atb":[[1.69,0],[1.74,34.21]],"id":63994056},{"atl":[[3.1,11.66]],"id":63994056},{"atb":[[1.64,28.07],[1.59,0]],"id":69979804},{"atl":[[3.8,5.82]],"id":46251065}],"con":true,"img":false}]}
{"op":"mcm","clk":"11540894165","pt":1719499668493,"mc":[{"id":"1.230178315","rc":[{"atl":[[4.7,5.17]],"id":45375136},{"atl":[[3.5,0],[3.05,7.94]],"id":63994056},{"atl":[[3.1,7.03],[3.4,0]],"id":69979804},{"atb":[[1.43,0],[1.53,0],[1.57,9.66],[1.67,9.56],[1.54,12.78],[1.65,1]],"id":70940946},{"atl":[[36,1],[38,0]],"id":70940946}],"con":true,"img":false}]}
{"op":"mcm","clk":"11540894176","pt":1719499668601,"mc":[{"id":"1.230178315","rc":[{"atl":[[4.9,13.26]],"id":70466763},{"atl":[[5.1,0],[4.7,6.01]],"id":45375136}],"con":true,"img":false}]}
{"op":"mcm","clk":"11540894184","pt":1719499668702,"mc":[{"id":"1.230178315","rc":[{"atl":[[4.8,11.24]],"id":70466763},{"atl":[[3.35,7.93]],"id":63994056}],"con":true,"img":false}]}
{"op":"mcm","clk":"11540894191","pt":1719499668809,"mc":[{"id":"1.230178315","rc":[{"atb":[[2.88,17.88]],"id":45375136},{"atl":[[4.8,19.8]],"id":45375136}],"con":true,"img":false}]}
{"op":"mcm","clk":"11540894199","pt":1719499668907,"mc":[{"id":"1.230178315","rc":[{"atl":[[5.2,0],[4.7,5.38]],"id":70466763}],"con":true,"img":false}]}
{"op":"mcm","clk":"11540894206","pt":1719499669008,"mc":[{"id":"1.230178315","rc":[{"atb":[[2.9,5.51]],"id":70466763},{"atl":[[5.8,0]],"id":70466763},{"atb":[[2.12,0],[2.86,5.29]],"id":45375136}],"con":true,"img":false}]}
{"op":"mcm","clk":"11540894217","pt":1719499669119,"mc":[{"id":"1.230178315","rc":[{"atl":[[4.6,0.84]],"id":70466763}],"con":true,"img":false}]}
{"op":"mcm","clk":"11540894229","pt":1719499669219,"mc":[{"id":"1.230178315","rc":[{"atb":[[2.94,1.94]],"id":70466763},{"atl":[[4.8,10.86],[4.9,5.37]],"id":70466763},{"atb":[[2.92,1.94],[2.88,17.37]],"id":45375136},{"atl":[[4.8,10.86]],"id":45375136},{"atl":[[3.15,9.55]],"id":69979804},{"atb":[[1.56,4.89]],"id":70940946},{"atl":[[34,4.76]],"id":70940946},{"atb":[[2.8,17.43]],"id":46251065}],"con":true,"img":false}]}
{"op":"mcm","clk":"11540894237","pt":1719499669320,"mc":[{"id":"1.230178315","rc":[{"atl":[[4.8,18.75],[4.6,6.23]],"id":70466763},{"atl":[[4.7,13.9]],"id":45375136},{"atl":[[3.1,14.92]],"id":69979804},{"atb":[[1.67,17.46]],"id":70940946},{"atl":[[32,8.25]],"id":70940946},{"atb":[[2.82,10.42]],"id":46251065}],"con":true,"img":false}]}
{"op":"mcm","clk":"11540894244","pt":1719499669421,"mc":[{"id":"1.230178315","rc":[{"atl":[[4.8,13.26],[5,0]],"id":70466763},{"atb":[[2.88,5.29]],"id":45375136},{"atl":[[4.8,5.15],[5.5,0],[5.3,1]],"id":45375136},{"atb":[[2.8,6]],"id":46251065}],"con":true,"img":false}]}
{"op":"mcm","clk":"11540894253","pt":1719499669521,"mc":[{"id":"1.230178315","rc":[{"atl":[[4.7,10.87]],"id":70466763},{"atb":[[2.9,14.66]],"id":45375136},{"atl":[[4.7,19.61]],"id":45375136},{"atb":[[2.82,21.85]],"id":46251065}],"con":true,"img":false}]}
{"op":"mcm","clk":"11540894263","pt":1719499669622,"mc":[{"id":"1.230178315","rc":[{"atl":[[3.75,15.95]],"id":46251065}],"con":true,"img":false}]}
{"op":"mcm","clk":"11540894294","pt":1719499669988,"mc":[{"id":"1.230178315","rc":[{"atl":[[4.7,5.38]],"id":70466763},{"atb":[[2.9,2.58]],"id":45375136}],"con":true,"img":false}]}
{"op":"mcm","clk":"11540894304","pt":1719499670099,"mc":[{"id":"1.230178315","rc":[{"atl":[[3,1]],"id":63994056},{"atl":[[30,0.84]],"id":70940946}],"con":true,"img":false}]}
{"op":"mcm","clk":"11540894312","pt":1719499670196,"mc":[{"id":"1.230178315","rc":[{"atl":[[4.8,5.37]],"id":70466763}],"con":true,"img":false}]}
{"op":"mcm","clk":"11540894320","pt":1719499670298,"mc":[{"id":"1.230178315","rc":[{"atl":[[4.6,14.12]],"id":70466763}],"con":true,"img":false}]}
{"op":"mcm","clk":"11540894335","pt":1719499670502,"mc":[{"id":"1.230178315","rc":[{"atl":[[34,5.76],[36,0],[40,0],[30,4.29]],"id":70940946}],"con":true,"img":false}]}
{"op":"mcm","clk":"11540894349","pt":1719499670705,"mc":[{"id":"1.230178315","rc":[{"atl":[[3.4,7.89]],"id":63994056},{"atl":[[3.15,7.01]],"id":69979804}],"con":true,"img":false}]}
{"op":"mcm","clk":"11540894360","pt":1719499670909,"mc":[{"id":"1.230178315","rc":[{"atl":[[4.6,20.47]],"id":70466763},{"atb":[[2.92,14.32]],"id":45375136},{"atb":[[2.1,2.11],[1.99,8.22]],"id":63994056},{"atb":[[2.24,2.11],[2.16,7.38]],"id":69979804}],"con":true,"img":false}]}
{"op":"mcm","clk":"11540894389","pt":1719499671322,"mc":[{"id":"1.230178315","rc":[{"atb":[[2.84,1.93],[2.94,7.46]],"id":70466763},{"atl":[[4.5,5.39],[4.9,0]],"id":70466763},{"atb":[[2.8,0],[2.58,13.59],[2.94,5.3],[2.9,13.19]],"id":45375136},{"atl":[[5,0],[4.6,5.18]],"id":45375136},{"atl":[[3.45,7.89],[3,8.96]],"id":63994056},{"atb":[[1.96,0],[2.24,9.36],[1.97,2.63],[2.2,14.49]],"id":69979804},{"atl":[[3.05,7.05]],"id":69979804},{"atb":[[1.68,4.79],[1.54,7.83]],"id":70940946},{"atl":[[32,9.37],[44,0],[30,8.98]],"id":70940946},{"atb":[[2.72,0],[2.84,5.99]],"id":46251065},{"atl":[[3.7,5.85],[3.9,0]],"id":46251065}],"con":true,"img":false}]}
{"op":"mcm","clk":"11540894396","pt":1719499671425,"mc":[{"id":"1.230178315","rc":[{"atb":[[2.92,14.73],[2.66,0]],"id":70466763},{"atl":[[3.35,0]],"id":69979804},{"atl":[[30,16.87]],"id":70940946}],"con":true,"img":false}]}
{"op":"mcm","clk":"11540894409","pt":1719499671527,"mc":[{"id":"1.230178315","rc":[{"atb":[[2.92,11.03]],"id":70466763},{"atb":[[2.9,10.61]],"id":45375136},{"atb":[[2.18,7.33]],"id":69979804},{"atb":[[1.67,12.72]],"id":70940946},{"atl":[[29,0.36]],"id":70940946}],"con":true,"img":false}]}
{"op":"mcm","clk":"11540894415","pt":1719499671623,"mc":[{"id":"1.230178315","rc":[{"atl":[[3,0.84]],"id":69979804}],"con":true,"img":false}]}
{"op":"mcm","clk":"11540894424","pt":1719499671726,"mc":[{"id":"1.230178315","rc":[{"atb":[[2.94,10.76]],"id":70466763},{"atl":[[4.6,20.14]],"id":70466763},{"atb":[[2.94,9.5],[2.92,1.94]],"id":45375136},{"atl":[[4.7,19.56]],"id":45375136},{"atb":[[2.2,17.99]],"id":69979804},{"atb":[[1.87,4.52],[1.65,0],[1.66,1]],"id":70940946},{"atl":[[32,10.37],[34,4.76]],"id":70940946},{"atb":[[2.82,21.49]],"id":46251065},{"atl":[[3.75,14.12]],"id":46251065}],"con":true,"img":false}]}
{"op":"mcm","clk":"11540894437","pt":1719499671894,"mc":[{"id":"1.230178315","rc":[{"atl":[[4.6,14.12]],"id":70466763},{"atl":[[4.7,13.9]],"id":45375136},{"atb":[[2.82,10.42]],"id":46251065},{"atl":[[3.75,6.68]],"id":46251065}],"con":true,"img":false}]}
{"op":"mcm","clk":"11540894441","pt":1719499672003,"mc":[{"id":"1.230178315","rc":[{"atl":[[4.5,11.41]],"id":70466763},{"atb":[[2.92,0]],"id":45375136},{"atl":[[4.6,10.84]],"id":45375136},{"atb":[[1.85,1],[1.66,0]],"id":70940946},{"atb":[[2.84,17.06]],"id":46251065},{"atl":[[3.7,13.29]],"id":46251065}],"con":true,"img":false}]}
{"op":"mcm","clk":"11540894446","pt":1719499672097,"mc":[{"id":"1.230178315","rc":[{"atb":[[2.96,1.94]],"id":45375136}],"con":true,"img":false}]}
{"op":"mcm","clk":"11540894453","pt":1719499672198,"mc":[{"id":"1.230178315","rc":[{"atl":[[4.6,6.23]],"id":70466763},{"atl":[[4.7,6.01]],"id":45375136},{"atl":[[3.1,7.03]],"id":69979804},{"atb":[[1.67,4.82]],"id":70940946},{"atb":[[2.82,2.53]],"id":46251065}],"con":true,"img":false}]}
{"op":"mcm","clk":"11540894462","pt":1719499672302,"mc":[{"id":"1.230178315","rc":[{"atl":[[4.5,19.3]],"id":70466763},{"atl":[[4.6,18.73]],"id":45375136},{"atb":[[2.04,8.22]],"id":63994056},{"atl":[[3,8.73]],"id":69979804},{"atb":[[1.87,12.41]],"id":70940946},{"atl":[[30,8.98]],"id":70940946},{"atb":[[2.84,24.95]],"id":46251065}],"con":true,"img":false}]}
{"op":"mcm","clk":"11540894473","pt":1719499672403,"mc":[{"id":"1.230178315","rc":[{"atb":[[2.96,14.1]],"id":45375136},{"atb":[[2.1,10]],"id":63994056},{"atl":[[3,19.31]],"id":69979804},{"atl":[[29,8.25]],"id":70940946}],"con":true,"img":false}]}
{"op":"mcm","clk":"11540894481","pt":1719499672503,"mc":[{"id":"1.230178315","rc":[{"atl":[[4.5,5.22],[4.9,0]],"id":45375136},{"atb":[[1.46,12.01],[1.85,10.57],[1.55,0],[1.88,4.78]],"id":70940946},{"atl":[[28,3.7],[30,5.53]],"id":70940946},{"atb":[[2.74,0],[2.86,5.98]],"id":46251065}],"con":true,"img":false}]}
{"op":"mcm","clk":"11540894531","pt":1719499673120,"mc":[{"id":"1.230178315","rc":[{"atl":[[2.98,2.53]],"id":63994056},{"atl":[[3,21.85]],"id":69979804}],"con":true,"img":false}]}
{"op":"mcm","clk":"11540894538","pt":1719499673224,"mc":[{"id":"1.230178315","rc":[{"atl":[[4.7,5.17]],"id":45375136},{"atl":[[30,4.68]],"id":70940946}],"con":true,"img":false}]}
{"op":"mcm","clk":"11540894548","pt":1719499673327,"mc":[{"id":"1.230178315","rc":[{"atl":[[4.6,5.18]],"id":45375136},{"atl":[[3,7.96]],"id":63994056},{"atb":[[1.87,4.52]],"id":70940946},{"atl":[[29,0.36]],"id":70940946},{"atb":[[2.84,5.99]],"id":46251065}],"con":true,"img":false}]}
{"op":"mcm","clk":"11540894560","pt":1719499673429,"mc":[{"id":"1.230178315","rc":[{"atl":[[4.5,13.12]],"id":45375136},{"atb":[[1.88,12.67]],"id":70940946},{"atl":[[28,11.59]],"id":70940946},{"atb":[[2.86,13.87]],"id":46251065}],"con":true,"img":false}]}
{"op":"mcm","clk":"11540894571","pt":1719499673527,"mc":[{"id":"1.230178315","rc":[{"atl":[[28,7.89],[29,3.93]],"id":70940946}],"con":true,"img":false}]}
{"op":"mcm","clk":"11540894617","pt":1719499674099,"mc":[{"id":"1.230178315","rc":[{"atl":[[5.1,0],[5,11.61]],"id":70466763},{"atl":[[4.5,19.34]],"id":45375136},{"atb":[[2.86,25.06]],"id":46251065}],"con":true,"img":false}]}
{"op":"mcm","clk":"11540894648","pt":1719499674614,"mc":[{"id":"1.230178315","rc":[{"atl":[[2.96,0.84]],"id":63994056}],"con":true,"img":false}]}
{"op":"mcm","clk":"11540894661","pt":1719499674817,"mc":[{"id":"1.230178315","rc":[{"atb":[[1.85,9.57],[1.86,1]],"id":70940946},{"atl":[[32,9.37],[30,5.68]],"id":70940946}],"con":true,"img":false}]}
{"op":"mcm","clk":"11540894667","pt":1719499674919,"mc":[{"id":"1.230178315","rc":[{"atb":[[2.94,5.3]],"id":45375136},{"atb":[[2.2,14.49]],"id":69979804},{"atb":[[1.87,0],[1.86,6.26]],"id":70940946},{"atb":[[2.82,0]],"id":46251065}],"con":true,"img":false}]}
{"op":"mcm","clk":"11540894681","pt":1719499675126,"mc":[{"id":"1.230178315","rc":[{"atb":[[2.98,3.2]],"id":45375136},{"atb":[[2.16,4.3]],"id":70940946},{"atl":[[3.65,0.84]],"id":46251065}],"con":true,"img":false}]}
{"op":"mcm","clk":"11540894721","pt":1719499675689,"mc":[{"id":"1.230178315","rc":[{"atb":[[2.96,13.24]],"id":45375136}],"con":true,"img":false}]}
{"op":"mcm","clk":"11540894729","pt":1719499675793,"mc":[{"id":"1.230178315","rc":[{"atb":[[1.99,14.75]],"id":63994056},{"atl":[[2.94,1]],"id":63994056}],"con":true,"img":false}]}
{"op":"mcm","clk":"11540894737","pt":1719499675900,"mc":[{"id":"1.230178315","rc":[{"atb":[[2.96,1.94]],"id":45375136}],"con":true,"img":false}]}
{"op":"mcm","clk":"11540894743","pt":1719499676000,"mc":[{"id":"1.230178315","rc":[{"atl":[[4.8,0],[4.4,5.46]],"id":70466763},{"atb":[[2.82,1.97],[2.72,0],[2.98,19.82],[2.96,12.61]],"id":45375136},{"atb":[[1.89,9.55],[1.56,0],[1.49,0],[2.16,9.07]],"id":70940946},{"atb":[[2.88,5.96],[2.78,0]],"id":46251065}],"con":true,"img":false}]}
{"op":"mcm","clk":"11540894750","pt":1719499676101,"mc":[{"id":"1.230178315","rc":[{"atl":[[4.4,6.3]],"id":70466763},{"atl":[[4.4,0.84]],"id":45375136}],"con":true,"img":false}]}
{"op":"mcm","clk":"11540894766","pt":1719499676311,"mc":[{"id":"1.230178315","rc":[{"atb":[[1.88,4.78]],"id":70940946}],"con":true,"img":false}]}
{"op":"mcm","clk":"11540894777","pt":1719499676414,"mc":[{"id":"1.230178315","rc":[{"atb":[[2.16,16.96]],"id":70940946}],"con":true,"img":false}]}
{"op":"mcm","clk":"11540894799","pt":1719499676724,"mc":[{"id":"1.230178315","rc":[{"atl":[[4.5,13.28],[4.6,5.38]],"id":70466763},{"atb":[[2.86,13.87]],"id":46251065}],"con":true,"img":false}]}
{"op":"mcm","clk":"11540894809","pt":1719499676827,"mc":[{"id":"1.230178315","rc":[{"atb":[[1.88,0]],"id":69979804}],"con":true,"img":false}]}
{"op":"mcm","clk":"11540894841","pt":1719499677196,"mc":[{"id":"1.230178315","rc":[{"atl":[[4.5,5.39]],"id":70466763},{"atb":[[3,5.32]],"id":45375136},{"atl":[[4.5,11.44]],"id":45375136},{"atb":[[2.18,4.77]],"id":70940946},{"atb":[[2.86,5.98]],"id":46251065}],"con":true,"img":false}]}
{"op":"mcm","clk":"11540894848","pt":1719499677297,"mc":[{"id":"1.230178315","rc":[{"atl":[[4.4,20.94]],"id":70466763},{"atb":[[2.86,0]],"id":45375136},{"atl":[[4.4,8.73]],"id":45375136},{"atb":[[1.46,0],[1.67,0]],"id":70940946},{"atb":[[2.88,26.81]],"id":46251065}],"con":true,"img":false}]}
{"op":"mcm","clk":"11540894853","pt":1719499677392,"mc":[{"id":"1.230178315","rc":[{"atl":[[2.94,8.92],[2.96,16.7]],"id":63994056}],"con":true,"img":false}]}
{"op":"mcm","clk":"11540894859","pt":1719499677502,"mc":[{"id":"1.230178315","rc":[{"atl":[[3.4,0]],"id":63994056}],"con":true,"img":false}]}
{"op":"mcm","clk":"11540894863","pt":1719499677599,"mc":[{"id":"1.230178315","rc":[{"atl":[[10,0]],"id":63994056},{"atb":[[2.22,4.53]],"id":70940946}],"con":true,"img":false}]}
{"op":"mcm","clk":"11540894876","pt":1719499677805,"mc":[{"id":"1.230178315","rc":[{"atb":[[1.87,10],[1.86,4.75]],"id":70940946}],"con":true,"img":false}]}
{"op":"mcm","clk":"11540894883","pt":1719499677907,"mc":[{"id":"1.230178315","rc":[{"atb":[[1.99,8.22]],"id":63994056},{"atb":[[1.86,1]],"id":70940946}],"con":true,"img":false}]}
{"op":"mcm","clk":"11540894896","pt":1719499678113,"mc":[{"id":"1.230178315","rc":[{"atb":[[2.96,10.66]],"id":45375136},{"atl":[[2.98,0]],"id":63994056}],"con":true,"img":false}]}
{"op":"mcm","clk":"11540894915","pt":1719499678319,"mc":[{"id":"1.230178315","rc":[{"atb":[[2.98,5.32],[3.05,1.94]],"id":45375136},{"atl":[[4.5,5.22]],"id":45375136},{"atb":[[2.24,1.94],[2.16,12.66]],"id":70940946}],"con":true,"img":false}]}
{"op":"mcm","clk":"11540894926","pt":1719499678422,"mc":[{"id":"1.230178315","rc":[{"atb":[[3,9.32]],"id":45375136},{"atb":[[2.24,12.82]],"id":69979804},{"atb":[[2.44,4.7],[2.16,4.77]],"id":70940946}],"con":true,"img":false}]}
{"op":"mcm","clk":"11540894938","pt":1719499678525,"mc":[{"id":"1.230178315","rc":[{"atb":[[2.22,12.42]],"id":70940946}],"con":true,"img":false}]}
{"op":"mcm","clk":"11540894945","pt":1719499678629,"mc":[{"id":"1.230178315","rc":[{"atl":[[27,3.85],[29,0.36]],"id":70940946}],"con":true,"img":false}]}
{"op":"mcm","clk":"11540894968","pt":1719499678953,"mc":[{"id":"1.230178315","rc":[{"atb":[[2.4,1],[1.86,0]],"id":70940946},{"atl":[[29,1.36],[30,4.68]],"id":70940946}],"con":true,"img":false}]}
{"op":"mcm","clk":"11540894978","pt":1719499679041,"mc":[{"id":"1.230178315","rc":[{"atb":[[1.87,0]],"id":70940946}],"con":true,"img":false}]}
{"op":"mcm","clk":"11540894985","pt":1719499679091,"mc":[{"id":"1.230178315","rc":[{"atb":[[3.05,11.91]],"id":45375136},{"atl":[[4.4,16.22]],"id":45375136}],"con":true,"img":false}]}
{"op":"mcm","clk":"11540894994","pt":1719499679192,"mc":[{"id":"1.230178315","rc":[{"atl":[[2.92,2.53]],"id":63994056},{"atb":[[2.22,4.53]],"id":70940946},{"atl":[[28,0]],"id":70940946}],"con":true,"img":false}]}
{"op":"mcm","clk":"11540895003","pt":1719499679300,"mc":[{"id":"1.230178315","rc":[{"atl":[[2.94,7.92]],"id":63994056},{"atb":[[2.44,12.59]],"id":70940946},{"atl":[[27,7.89],[29,4.93]],"id":70940946}],"con":true,"img":false}]}
{"op":"mcm","clk":"11540895013","pt":1719499679406,"mc":[{"id":"1.230178315","rc":[{"atl":[[4.5,33.96],[5,0]],"id":70466763},{"atl":[[6.2,0],[5.4,10.36]],"id":45375136},{"atl":[[3.3,15.91],[3.7,15.66]],"id":63994056},{"atl":[[3.45,0],[3.15,21.13]],"id":69979804},{"atl":[[4.6,11.82],[5.2,0]],"id":46251065}],"con":true,"img":false}]}
{"op":"mcm","clk":"11540895023","pt":1719499679501,"mc":[{"id":"1.230178315","rc":[{"atl":[[4.3,5.48],[4.7,0]],"id":70466763},{"atl":[[4.8,0],[4.3,5.22]],"id":45375136},{"atl":[[3.35,0],[2.92,10.47]],"id":63994056},{"atl":[[3.2,0],[2.98,7.03]],"id":69979804},{"atb":[[1.68,0],[2.4,10.51],[1.57,0],[2.46,4.75]],"id":70940946},{"atl":[[3.85,0],[3.65,6.68]],"id":46251065}],"con":true,"img":false}]}
{"op":"mcm","clk":"11540895034","pt":1719499679706,"mc":[{"id":"1.230178315","rc":[{"atl":[[2.96,15.85]],"id":63994056}],"con":true,"img":false}]}
{"op":"mcm","clk":"11540895053","pt":1719499679914,"mc":[{"id":"1.230178315","rc":[{"atb":[[2.96,1.74]],"id":70466763},{"atl":[[4.4,14.19]],"id":70466763},{"atb":[[3.05,14.57]],"id":45375136},{"atl":[[4.4,15.5]],"id":45375136},{"atl":[[3,11.27]],"id":69979804},{"atb":[[2.9,1.83]],"id":46251065}],"con":true,"img":false}]}
{"op":"mcm","clk":"11540895075","pt":1719499680123,"mc":[{"id":"1.230178315","rc":[{"atl":[[4.4,8.73]],"id":45375136},{"atb":[[1.64,0],[1.75,28.07]],"id":69979804},{"atl":[[2.96,0.84]],"id":69979804},{"atb":[[2.12,0],[2.34,9.16]],"id":46251065},{"atl":[[3.75,5.83]],"id":46251065}],"con":true,"img":false}]}
{"op":"mcm","clk":"11540895088","pt":1719499680230,"mc":[{"id":"1.230178315","rc":[{"atl":[[4.4,6.3]],"id":70466763},{"atl":[[4.3,11.99],[4.4,0.84]],"id":45375136},{"atl":[[3,3.38]],"id":69979804},{"atb":[[2.44,4.7]],"id":70940946}],"con":true,"img":false}]}
{"op":"mcm","clk":"11540895101","pt":1719499680331,"mc":[{"id":"1.230178315","rc":[{"atl":[[4.3,13.37]],"id":70466763},{"atl":[[4.3,19.88]],"id":45375136},{"atl":[[2.98,14.92]],"id":69979804},{"atb":[[2.46,12.64]],"id":70940946}],"con":true,"img":false}]}
{"op":"mcm","clk":"11540895122","pt":1719499680534,"mc":[{"id":"1.230178315","rc":[{"atl":[[5.4,0]],"id":70466763}],"con":true,"img":false}]}
{"op":"mcm","clk":"11540895133","pt":1719499680636,"mc":[{"id":"1.230178315","rc":[{"atl":[[4.6,0]],"id":70466763},{"atb":[[3.1,5.32],[2.88,0]],"id":45375136},{"atb":[[2.26,7.19]],"id":69979804},{"atb":[[2.48,4.75]],"id":70940946}],"con":true,"img":false}]}
{"op":"mcm","clk":"11540895143","pt":1719499680739,"mc":[{"id":"1.230178315","rc":[{"atl":[[4.2,5.5]],"id":70466763},{"atb":[[2.1,3.8]],"id":69979804},{"atb":[[1.88,0]],"id":70940946},{"atl":[[28,9.31]],"id":70940946}],"con":true,"img":false}]}
{"op":"mcm","clk":"11540895149","pt":1719499680800,"mc":[{"id":"1.230178315","rc":[{"atl":[[4.2,5.22],[4.7,0]],"id":45375136},{"atl":[[3.15,14.12],[2.96,7.88]],"id":69979804},{"atl":[[26,4.65]],"id":70940946}],"con":true,"img":false}]}
{"op":"mcm","clk":"11540895160","pt":1719499680903,"mc":[{"id":"1.230178315","rc":[{"atb":[[2.88,26.1]],"id":46251065}],"con":true,"img":false}]}
{"op":"mcm","clk":"11540895179","pt":1719499681107,"mc":[{"id":"1.230178315","rc":[{"atl":[[4.3,20.05]],"id":70466763},{"atl":[[2.96,20.22]],"id":69979804}],"con":true,"img":false}]}
{"op":"mcm","clk":"11540895187","pt":1719499681215,"mc":[{"id":"1.230178315","rc":[{"atl":[[4.3,12.16],[4.4,5.46]],"id":70466763},{"atl":[[4.4,0]],"id":45375136},{"atl":[[3,2.53],[2.98,7.03]],"id":69979804},{"atb":[[2.46,4.75]],"id":70940946},{"atb":[[2.88,5.96]],"id":46251065}],"con":true,"img":false}]}
{"op":"mcm","clk":"11540895196","pt":1719499681317,"mc":[{"id":"1.230178315","rc":[{"atl":[[4.2,13.39]],"id":70466763},{"atl":[[2.9,1]],"id":63994056},{"atl":[[2.96,28.11]],"id":69979804},{"atb":[[2.48,12.64]],"id":70940946},{"atb":[[2.9,21.97]],"id":46251065}],"con":true,"img":false}]}
{"op":"mcm","clk":"11540895204","pt":1719499681413,"mc":[{"id":"1.230178315","rc":[{"atl":[[4.5,28.57],[4.1,5.52]],"id":70466763},{"atb":[[2.5,4.74],[2.16,0]],"id":70940946}],"con":true,"img":false}]}
{"op":"mcm","clk":"11540895212","pt":1719499681875,"mc":[{"id":"1.230178315","rc":[{"atl":[[4.3,5.48]],"id":70466763},{"atb":[[3.05,4.6]],"id":45375136},{"atl":[[4.3,13.11]],"id":45375136}],"con":true,"img":false}]}
{"op":"mcm","clk":"11540895222","pt":1719499681892,"mc":[{"id":"1.230178315","rc":[{"atl":[[3,0]],"id":69979804},{"atl":[[28,10.31],[29,3.93]],"id":70940946}],"con":true,"img":false}]}
{"op":"mcm","clk":"11540895239","pt":1719499681925,"mc":[{"id":"1.230178315","rc":[{"atb":[[2.94,7.46]],"id":70466763},{"atb":[[3,5.32]],"id":45375136},{"atb":[[2.24,9.36]],"id":69979804},{"atb":[[2.44,0]],"id":70940946}],"con":true,"img":false}]}
{"op":"mcm","clk":"11540895250","pt":1719499682031,"mc":[{"id":"1.230178315","rc":[{"atb":[[2.96,4.84]],"id":70466763},{"atb":[[3.1,8.02]],"id":45375136},{"atb":[[2.58,4.19]],"id":70940946}],"con":true,"img":false}]}
{"op":"mcm","clk":"11540895276","pt":1719499682239,"mc":[{"id":"1.230178315","rc":[{"atl":[[4.2,5.5]],"id":70466763},{"atl":[[4.3,5.22]],"id":45375136},{"atb":[[2.48,4.75]],"id":70940946},{"atl":[[27,0]],"id":70940946}],"con":true,"img":false}]}
{"op":"mcm","clk":"11540895286","pt":1719499682300,"mc":[{"id":"1.230178315","rc":[{"atl":[[4.5,0],[4.1,20.44],[4.7,11.04]],"id":70466763},{"atb":[[3.1,18.49]],"id":45375136},{"atl":[[4.2,19.59]],"id":45375136},{"atb":[[2.5,12.63]],"id":70940946},{"atl":[[26,12.54]],"id":70940946}],"con":true,"img":false}]}
{"op":"mcm","clk":"11540895293","pt":1719499682404,"mc":[{"id":"1.230178315","rc":[{"atb":[[2.86,0],[2.96,10.46]],"id":70466763},{"atb":[[2.58,8.92]],"id":70940946}],"con":true,"img":false}]}
{"op":"mcm","clk":"11540895305","pt":1719499682508,"mc":[{"id":"1.230178315","rc":[{"atb":[[2.18,0]],"id":70940946}],"con":true,"img":false}]}
{"op":"mcm","clk":"11540895312","pt":1719499682603,"mc":[{"id":"1.230178315","rc":[{"atl":[[4,5.51],[4.4,0]],"id":70466763},{"atl":[[4.1,5.25]],"id":45375136},{"atl":[[3.1,0],[2.94,7.01]],"id":69979804},{"atl":[[34,0],[25,4.65]],"id":70940946}],"con":true,"img":false}]}
{"op":"mcm","clk":"11540895322","pt":1719499682713,"mc":[{"id":"1.230178315","rc":[{"atl":[[4.6,0]],"id":45375136}],"con":true,"img":false}]}
{"op":"mcm","clk":"11540895349","pt":1719499683031,"mc":[{"id":"1.230178315","rc":[{"atl":[[4.6,6.75],[4.1,13.41]],"id":70466763},{"atb":[[2.94,0],[3.15,5.35]],"id":45375136},{"atl":[[4.2,13.11]],"id":45375136},{"atl":[[2.96,15.77]],"id":69979804},{"atl":[[27,1],[28,9.31]],"id":70940946}],"con":true,"img":false}]}
{"op":"mcm","clk":"11540895357","pt":1719499683128,"mc":[{"id":"1.230178315","rc":[{"atl":[[4,0.84]],"id":45375136},{"atb":[[2.56,2.11],[1.5,0]],"id":70940946}],"con":true,"img":false}]}
{"op":"mcm","clk":"11540895368","pt":1719499683241,"mc":[{"id":"1.230178315","rc":[{"atl":[[4.6,0],[4.1,5.52]],"id":70466763},{"atl":[[4.2,5.22]],"id":45375136},{"atl":[[2.96,7.88]],"id":69979804},{"atb":[[2.5,4.74]],"id":70940946},{"atl":[[26,4.65]],"id":70940946}],"con":true,"img":false}]}
{"op":"mcm","clk":"11540895377","pt":1719499683336,"mc":[{"id":"1.230178315","rc":[{"atl":[[4,13.4]],"id":70466763},{"atl":[[4.1,13.14]],"id":45375136},{"atl":[[2.94,14.9]],"id":69979804},{"atb":[[2.58,16.82]],"id":70940946},{"atl":[[25,12.54]],"id":70940946}],"con":true,"img":false}]}
{"op":"mcm","clk":"11540895389","pt":1719499683444,"mc":[{"id":"1.230178315","rc":[{"atb":[[1.94,0]],"id":63994056}],"con":true,"img":false}]}
{"op":"mcm","clk":"11540895405","pt":1719499683536,"mc":[{"id":"1.230178315","rc":[{"atl":[[4.3,0],[3.95,5.53]],"id":70466763},{"atb":[[2.6,4.73],[2.46,0]],"id":70940946}],"con":true,"img":false}]}
{"op":"mcm","clk":"11540895419","pt":1719499683641,"mc":[{"id":"1.230178315","rc":[{"atl":[[3.95,6.38]],"id":70466763},{"atb":[[1.92,16.48]],"id":63994056}],"con":true,"img":false}]}
{"op":"mcm","clk":"11540895442","pt":1719499683805,"mc":[{"id":"1.230178315","rc":[{"atl":[[2.92,2.53]],"id":69979804}],"con":true,"img":false}]}
{"op":"mcm","clk":"11540895471","pt":1719499684113,"mc":[{"id":"1.230178315","rc":[{"atb":[[2.94,5.51]],"id":70466763},{"atb":[[3.1,8.02],[3.05,2.65]],"id":45375136},{"atl":[[2.96,7.03]],"id":69979804},{"atb":[[2.24,0]],"id":70940946}],"con":true,"img":false}]}
{"op":"mcm","clk":"11540895482","pt":1719499684221,"mc":[{"id":"1.230178315","rc":[{"atl":[[4,5.51]],"id":70466763},{"atl":[[4.1,5.25]],"id":45375136},{"atb":[[2.58,8.92]],"id":70940946}],"con":true,"img":false}]}
{"op":"mcm","clk":"11540895492","pt":1719499684322,"mc":[{"id":"1.230178315","rc":[{"atl":[[3.95,23.08]],"id":70466763},{"atl":[[4,16.58]],"id":45375136},{"atl":[[2.94,26.47]],"id":69979804},{"atb":[[2.6,12.63],[2.62,1.94]],"id":70940946}],"con":true,"img":false}]}
{"op":"mcm","clk":"11540895503","pt":1719499684435,"mc":[{"id":"1.230178315","rc":[{"atl":[[3.05,0],[2.9,8.91]],"id":63994056}],"con":true,"img":false}]}
{"op":"mcm","clk":"11540895518","pt":1719499684528,"mc":[{"id":"1.230178315","rc":[{"atl":[[3.1,0]],"id":63994056},{"atb":[[1.68,28.07],[1.75,0]],"id":69979804},{"atl":[[24,4.35],[29,0.36]],"id":70940946}],"con":true,"img":false}]}
{"op":"mcm","clk":"11540895541","pt":1719499684733,"mc":[{"id":"1.230178315","rc":[{"atl":[[2.94,14.9]],"id":69979804}],"con":true,"img":false}]}
{"op":"mcm","clk":"11540895557","pt":1719499684941,"mc":[{"id":"1.230178315","rc":[{"atb":[[3.15,15.39]],"id":45375136}],"con":true,"img":false}]}
{"op":"mcm","clk":"11540895569","pt":1719499685043,"mc":[{"id":"1.230178315","rc":[{"atb":[[3.1,5.32]],"id":45375136},{"atb":[[2.58,4.73]],"id":70940946}],"con":true,"img":false}]}
{"op":"mcm","clk":"11540895578","pt":1719499685140,"mc":[{"id":"1.230178315","rc":[{"atl":[[2.88,0.84]],"id":63994056},{"atb":[[2.7,4]],"id":70940946}],"con":true,"img":false}]}
{"op":"mcm","clk":"11540895590","pt":1719499685239,"mc":[{"id":"1.230178315","rc":[{"atl":[[2.94,7.01]],"id":69979804},{"atb":[[2.6,4.73],[2.48,9.5]],"id":70940946}],"con":true,"img":false}]}
{"op":"mcm","clk":"11540895599","pt":1719499685302,"mc":[{"id":"1.230178315","rc":[{"atl":[[2.9,7.91]],"id":63994056},{"atl":[[2.92,10.43]],"id":69979804},{"atb":[[2.62,9.83]],"id":70940946},{"atl":[[25,4.65]],"id":70940946}],"con":true,"img":false}]}
{"op":"mcm","clk":"11540895608","pt":1719499685408,"mc":[{"id":"1.230178315","rc":[{"atb":[[2.48,4.75]],"id":70940946},{"atl":[[24,12.24]],"id":70940946}],"con":true,"img":false}]}
{"op":"mcm","clk":"11540895617","pt":1719499685508,"mc":[{"id":"1.230178315","rc":[{"atl":[[2.92,22.4]],"id":69979804}],"con":true,"img":false}]}
{"op":"mcm","clk":"11540895691","pt":1719499686325,"mc":[{"id":"1.230178315","rc":[{"atb":[[1.99,14.75]],"id":63994056},{"atl":[[2.92,7.93]],"id":63994056},{"atb":[[2.62,1.94]],"id":70940946}],"con":true,"img":false}]}
{"op":"mcm","clk":"11540895702","pt":1719499686432,"mc":[{"id":"1.230178315","rc":[{"atb":[[1.68,0],[1.74,28.07]],"id":69979804},{"atb":[[2.7,11.89]],"id":70940946},{"atl":[[26,5.65],[27,0]],"id":70940946}],"con":true,"img":false}]}
{"op":"mcm","clk":"11540895723","pt":1719499686636,"mc":[{"id":"1.230178315","rc":[{"atb":[[1.79,18.38],[1.74,0]],"id":63994056}],"con":true,"img":false}]}
{"op":"mcm","clk":"11540895753","pt":1719499686943,"mc":[{"id":"1.230178315","rc":[{"atl":[[3.9,5.53],[4.2,0]],"id":70466763},{"atl":[[4.5,0],[3.95,5.25]],"id":45375136},{"atl":[[2.88,8.76]],"id":63994056},{"atl":[[3.05,0],[2.9,7]],"id":69979804},{"atb":[[2.72,1.81]],"id":70940946},{"atb":[[2.8,0]],"id":46251065}],"con":true,"img":false}]}
{"op":"mcm","clk":"11540895757","pt":1719499687041,"mc":[{"id":"1.230178315","rc":[{"atb":[[2.98,0],[3.2,5.36]],"id":45375136},{"atl":[[3,0]],"id":63994056},{"atb":[[2.72,6.54],[1.85,0],[2.7,21.37]],"id":70940946},{"atb":[[2.92,5.91]],"id":46251065}],"con":true,"img":false}]}
{"op":"mcm","clk":"11540895769","pt":1719499687148,"mc":[{"id":"1.230178315","rc":[{"atb":[[2.48,0]],"id":70940946}],"con":true,"img":false}]}
{"op":"mcm","clk":"11540895779","pt":1719499687248,"mc":[{"id":"1.230178315","rc":[{"atl":[[3.95,22.11]],"id":70466763},{"atb":[[3.15,5.35]],"id":45375136},{"atl":[[4,8.73]],"id":45375136},{"atl":[[2.86,1]],"id":63994056},{"atl":[[2.92,10.43]],"id":69979804},{"atb":[[2.62,0]],"id":70940946},{"atb":[[2.9,20.31]],"id":46251065}],"con":true,"img":false}]}
{"op":"mcm","clk":"11540895790","pt":1719499687304,"mc":[{"id":"1.230178315","rc":[{"atl":[[2.94,0],[2.86,9]],"id":63994056},{"atb":[[2.72,8.49]],"id":70940946}],"con":true,"img":false}]}
{"op":"mcm","clk":"11540895798","pt":1719499687406,"mc":[{"id":"1.230178315","rc":[{"atl":[[4.5,11.06],[3.85,2.31],[3.95,14.27],[4.7,0]],"id":70466763},{"atb":[[3.25,2.77]],"id":45375136},{"atb":[[1.99,8.22]],"id":63994056},{"atl":[[2.84,1.93]],"id":63994056},{"atl":[[2.88,1.86]],"id":69979804},{"atl":[[23,5.67]],"id":70940946},{"atb":[[2.94,1.77],[2.9,9.72]],"id":46251065}],"con":true,"img":false}]}
{"op":"mcm","clk":"11540895809","pt":1719499687518,"mc":[{"id":"1.230178315","rc":[{"atl":[[3.9,13.37]],"id":70466763},{"atl":[[22,4.76],[30,0]],"id":70940946},{"atb":[[2.92,16.5]],"id":46251065}],"con":true,"img":false}]}
{"op":"mcm","clk":"11540895817","pt":1719499687613,"mc":[{"id":"1.230178315","rc":[{"atl":[[2.88,2.7]],"id":69979804},{"atl":[[24,7.89]],"id":70940946}],"con":true,"img":false}]}
{"op":"mcm","clk":"11540895826","pt":1719499687723,"mc":[{"id":"1.230178315","rc":[{"atb":[[3,0],[3.25,8.1]],"id":45375136},{"atl":[[2.84,9.96],[2.92,0]],"id":63994056},{"atl":[[21,1.26],[24,8.89],[26,4.65]],"id":70940946},{"atb":[[2.84,0],[2.94,7.66]],"id":46251065}],"con":true,"img":false}]}
{"op":"mcm","clk":"11540895844","pt":1719499687926,"mc":[{"id":"1.230178315","rc":[{"atl":[[2.86,8]],"id":63994056}],"con":true,"img":false}]}
{"op":"mcm","clk":"11540895859","pt":1719499688132,"mc":[{"id":"1.230178315","rc":[{"atl":[[3.95,13.43],[3.9,5.53]],"id":70466763},{"atl":[[2.88,7.92]],"id":63994056},{"atb":[[2.92,5.91]],"id":46251065},{"atl":[[3.7,5.85]],"id":46251065}],"con":true,"img":false}]}
{"op":"mcm","clk":"11540895869","pt":1719499688236,"mc":[{"id":"1.230178315","rc":[{"atl":[[3.95,5.53]],"id":70466763},{"atl":[[4,0.84]],"id":45375136},{"atl":[[2.92,2.53]],"id":69979804},{"atb":[[2.7,13.48]],"id":70940946},{"atl":[[24,1]],"id":70940946},{"atb":[[2.9,1.83]],"id":46251065}],"con":true,"img":false}]}
{"op":"mcm","clk":"11540895872","pt":1719499688342,"mc":[{"id":"1.230178315","rc":[{"atl":[[3.85,10.2]],"id":70466763},{"atl":[[3.95,20.96]],"id":45375136},{"atl":[[2.84,23.57]],"id":63994056},{"atl":[[2.88,23.38]],"id":69979804},{"atb":[[2.72,16.38]],"id":70940946},{"atl":[[21,9.15]],"id":70940946},{"atb":[[2.94,15.55]],"id":46251065}],"con":true,"img":false}]}
{"op":"mcm","clk":"11540895880","pt":1719499688444,"mc":[{"id":"1.230178315","rc":[{"atb":[[2.7,9.48]],"id":70940946},{"atl":[[20,5.26],[22,0]],"id":70940946}],"con":true,"img":false}]}
{"op":"mcm","clk":"11540895888","pt":1719499688544,"mc":[{"id":"1.230178315","rc":[{"atb":[[2.28,3.28]],"id":69979804},{"atb":[[2.74,3.2]],"id":70940946},{"atl":[[19.5,0.72]],"id":70940946}],"con":true,"img":false}]}
{"op":"mcm","clk":"11540895899","pt":1719499688649,"mc":[{"id":"1.230178315","rc":[{"atb":[[2.76,1.83]],"id":70940946}],"con":true,"img":false}]}
