{"op":"mcm","clk":"11536380643","pt":1719425245580,"mc":[{"id":"1.230178311","marketDefinition":{"bspMarket":true,"turnInPlayEnabled":false,"persistenceEnabled":false,"marketBaseRate":5.0,"eventId":"33376062","eventTypeId":"4339","numberOfWinners":2,"bettingType":"ODDS","marketType":"PLACE","marketTime":"2024-06-27T14:13:00.000Z","suspendTime":"2024-06-27T14:13:00.000Z","bspReconciled":false,"complete":true,"inPlay":false,"crossMatching":false,"runnersVoidable":false,"numberOfActiveRunners":6,"betDelay":0,"status":"OPEN","runners":[{"status":"ACTIVE","sortPriority":1,"id":57087188,"name":"1. Ballymac Boomer"},{"status":"ACTIVE","sortPriority":2,"id":57088863,"name":"2. Ferryfort Native"},{"status":"ACTIVE","sortPriority":3,"id":55302014,"name":"3. Blue The Woofoff"},{"status":"ACTIVE","sortPriority":4,"id":65436514,"name":"4. Leticias Pride"},{"status":"ACTIVE","sortPriority":5,"id":68392143,"name":"5. Springfield Best"},{"status":"ACTIVE","sortPriority":6,"id":69142441,"name":"6. Ferndale Tok"}],"regulators":["MR_INT"],"venue":"Kinsley","countryCode":"GB","discountAllowed":false,"timezone":"Europe/London","openDate":"2024-06-27T13:36:00.000Z","version":5994643761,"name":"To Be Placed","eventName":"Kinsley 27th Jun"},"rc":[],"con":true,"img":false}]}
{"op":"mcm","clk":"11536381018","pt":1719425248523,"mc":[{"id":"1.230178311","marketDefinition":{"bspMarket":true,"turnInPlayEnabled":false,"persistenceEnabled":false,"marketBaseRate":5.0,"eventId":"33376062","eventTypeId":"4339","numberOfWinners":2,"bettingType":"ODDS","marketType":"PLACE","marketTime":"2024-06-27T14:13:00.000Z","suspendTime":"2024-06-27T14:13:00.000Z","bspReconciled":false,"complete":true,"inPlay":false,"crossMatching":false,"runnersVoidable":false,"numberOfActiveRunners":6,"betDelay":0,"status":"OPEN","runners":[{"status":"ACTIVE","sortPriority":1,"id":57087188,"name":"1. Ballymac Boomer"},{"status":"ACTIVE","sortPriority":2,"id":57088863,"name":"2. Ferryfort Native"},{"status":"ACTIVE","sortPriority":3,"id":55302014,"name":"3. Blue The Woofoff"},{"status":"ACTIVE","sortPriority":4,"id":65436514,"name":"4. Leticias Pride"},{"status":"ACTIVE","sortPriority":5,"id":68392143,"name":"5. Springfield Best"},{"status":"ACTIVE","sortPriority":6,"id":69142441,"name":"6. Ferndale Tok"}],"regulators":["MR_INT"],"venue":"Kinsley","countryCode":"GB","discountAllowed":true,"timezone":"Europe/London","openDate":"2024-06-27T13:36:00.000Z","version":5994643761,"name":"To Be Placed","eventName":"Kinsley 27th Jun"},"rc":[],"con":true,"img":false}]}
{"op":"mcm","clk":"11536615610","pt":1719428251829,"mc":[{"id":"1.230178311","rc":[{"atb":[[1.03,15.09]],"id":57087188},{"atl":[[1000,0.84]],"id":57087188},{"spn":500.51,"spf":"NaN","id":57087188},{"atb":[[1.01,45.27]],"id":65436514},{"atl":[[1000,0.84]],"id":65436514},{"spn":500.5,"spf":"NaN","id":65436514},{"atb":[[1.02,22.63]],"id":69142441},{"atl":[[990,0.84]],"id":69142441},{"spn":495.51,"spf":"NaN","id":69142441},{"atb":[[1.02,22.63]],"id":55302014},{"atl":[[1000,0.84]],"id":55302014},{"spn":500.51,"spf":"NaN","id":55302014},{"atb":[[1.03,15.09]],"id":68392143},{"atl":[[990,0.84]],"id":68392143},{"spn":495.51,"spf":"NaN","id":68392143},{"atb":[[1.02,22.63]],"id":57088863},{"atl":[[1000,0.84]],"id":57088863},{"spn":500.51,"spf":"NaN","id":57088863}],"con":true,"img":false}]}
{"op":"mcm","clk":"11536837641","pt":1719431864421,"mc":[{"id":"1.230178311","rc":[{"atb":[[1.03,15.09]],"id":57087188},{"atl":[[1000,0.26]],"id":57087188},{"atb":[[1.01,45.28]],"id":65436514},{"atl":[[1000,0.26]],"id":65436514},{"atb":[[1.02,22.64]],"id":69142441},{"atl":[[990,0.26]],"id":69142441},{"atb":[[1.02,22.64]],"id":55302014},{"atl":[[1000,0.26]],"id":55302014},{"atb":[[1.03,15.09]],"id":68392143},{"atl":[[990,0.26]],"id":68392143},{"atb":[[1.02,22.64]],"id":57088863},{"atl":[[1000,0.26]],"id":57088863}],"con":true,"img":false}]}
{"op":"mcm","clk":"11537232249","pt":1719437882518,"mc":[{"id":"1.230178311","marketDefinition":{"bspMarket":true,"turnInPlayEnabled":false,"persistenceEnabled":false,"marketBaseRate":5.0,"eventId":"33376062","eventTypeId":"4339","numberOfWinners":2,"bettingType":"ODDS","marketType":"PLACE","marketTime":"2024-06-27T14:13:00.000Z","suspendTime":"2024-06-27T14:13:00.000Z","bspReconciled":false,"complete":true,"inPlay":false,"crossMatching":false,"runnersVoidable":false,"numberOfActiveRunners":6,"betDelay":0,"status":"OPEN","runners":[{"status":"ACTIVE","sortPriority":1,"id":57087188,"name":"1. Ballymac Boomer"},{"status":"ACTIVE","sortPriority":2,"id":57088863,"name":"2. Ferryfort Native"},{"status":"ACTIVE","sortPriority":3,"id":55302014,"name":"3. Blue The Woofoff"},{"status":"ACTIVE","sortPriority":4,"id":65436514,"name":"4. Leticias Pride"},{"status":"ACTIVE","sortPriority":5,"id":68392143,"name":"5. Springfield Best"},{"status":"ACTIVE","sortPriority":6,"id":69142441,"name":"6. Ferndale Tok"}],"regulators":["MR_INT"],"venue":"Kinsley","countryCode":"GB","discountAllowed":true,"timezone":"Europe/London","openDate":"2024-06-27T13:36:00.000Z","version":5994643761,"name":"To Be Placed","eventName":"Kinsley 27th Jun"},"rc":[{"atb":[[1.03,15.09]],"id":57087188},{"atl":[[1000,0.26]],"id":57087188},{"spn":500.51,"spf":"NaN","id":57087188},{"atb":[[1.01,45.28]],"id":65436514},{"atl":[[1000,0.26]],"id":65436514},{"spn":500.5,"spf":"NaN","id":65436514},{"atb":[[1.02,22.64]],"id":69142441},{"atl":[[990,0.26]],"id":69142441},{"spn":495.51,"spf":"NaN","id":69142441},{"atb":[[1.02,22.64]],"id":55302014},{"atl":[[1000,0.26]],"id":55302014},{"spn":500.51,"spf":"NaN","id":55302014},{"atb":[[1.03,15.09]],"id":68392143},{"atl":[[990,0.26]],"id":68392143},{"spn":495.51,"spf":"NaN","id":68392143},{"atb":[[1.02,22.64]],"id":57088863},{"atl":[[1000,0.26]],"id":57088863},{"spn":500.51,"spf":"NaN","id":57088863}],"con":true,"img":true}]}
{"op":"mcm","clk":"11537573376","pt":1719443282536,"mc":[{"id":"1.230178311","marketDefinition":{"bspMarket":true,"turnInPlayEnabled":false,"persistenceEnabled":false,"marketBaseRate":5.0,"eventId":"33376062","eventTypeId":"4339","numberOfWinners":2,"bettingType":"ODDS","marketType":"PLACE","marketTime":"2024-06-27T14:13:00.000Z","suspendTime":"2024-06-27T14:13:00.000Z","bspReconciled":false,"complete":true,"inPlay":false,"crossMatching":false,"runnersVoidable":false,"numberOfActiveRunners":6,"betDelay":0,"status":"OPEN","runners":[{"status":"ACTIVE","sortPriority":1,"id":57087188,"name":"1. Ballymac Boomer"},{"status":"ACTIVE","sortPriority":2,"id":57088863,"name":"2. Ferryfort Native"},{"status":"ACTIVE","sortPriority":3,"id":55302014,"name":"3. Blue The Woofoff"},{"status":"ACTIVE","sortPriority":4,"id":65436514,"name":"4. Leticias Pride"},{"status":"ACTIVE","sortPriority":5,"id":68392143,"name":"5. Springfield Best"},{"status":"ACTIVE","sortPriority":6,"id":69142441,"name":"6. Ferndale Tok"}],"regulators":["MR_INT"],"venue":"Kinsley","countryCode":"GB","discountAllowed":true,"timezone":"Europe/London","openDate":"2024-06-27T13:36:00.000Z","version":5994643761,"name":"To Be Placed","eventName":"Kinsley 27th Jun"},"rc":[{"atb":[[1.03,15.09]],"id":57087188},{"atl":[[1000,0.26]],"id":57087188},{"spn":500.51,"spf":"NaN","id":57087188},{"atb":[[1.01,45.29]],"id":65436514},{"atl":[[1000,0.26]],"id":65436514},{"spn":500.5,"spf":"NaN","id":65436514},{"atb":[[1.02,22.64]],"id":69142441},{"atl":[[990,0.26]],"id":69142441},{"spn":495.51,"spf":"NaN","id":69142441},{"atb":[[1.02,22.64]],"id":55302014},{"atl":[[1000,0.26]],"id":55302014},{"spn":500.51,"spf":"NaN","id":55302014},{"atb":[[1.03,15.09]],"id":68392143},{"atl":[[990,0.26]],"id":68392143},{"spn":495.51,"spf":"NaN","id":68392143},{"atb":[[1.02,22.64]],"id":57088863},{"atl":[[1000,0.26]],"id":57088863},{"spn":500.51,"spf":"NaN","id":57088863}],"con":true,"img":true}]}
{"op":"mcm","clk":"11537954936","pt":1719448682561,"mc":[{"id":"1.230178311","marketDefinition":{"bspMarket":true,"turnInPlayEnabled":false,"persistenceEnabled":false,"marketBaseRate":5.0,"eventId":"33376062","eventTypeId":"4339","numberOfWinners":2,"bettingType":"ODDS","marketType":"PLACE","marketTime":"2024-06-27T14:13:00.000Z","suspendTime":"2024-06-27T14:13:00.000Z","bspReconciled":false,"complete":true,"inPlay":false,"crossMatching":false,"runnersVoidable":false,"numberOfActiveRunners":6,"betDelay":0,"status":"OPEN","runners":[{"status":"ACTIVE","sortPriority":1,"id":57087188,"name":"1. Ballymac Boomer"},{"status":"ACTIVE","sortPriority":2,"id":57088863,"name":"2. Ferryfort Native"},{"status":"ACTIVE","sortPriority":3,"id":55302014,"name":"3. Blue The Woofoff"},{"status":"ACTIVE","sortPriority":4,"id":65436514,"name":"4. Leticias Pride"},{"status":"ACTIVE","sortPriority":5,"id":68392143,"name":"5. Springfield Best"},{"status":"ACTIVE","sortPriority":6,"id":69142441,"name":"6. Ferndale Tok"}],"regulators":["MR_INT"],"venue":"Kinsley","countryCode":"GB","discountAllowed":true,"timezone":"Europe/London","openDate":"2024-06-27T13:36:00.000Z","version":5994643761,"name":"To Be Placed","eventName":"Kinsley 27th Jun"},"rc":[{"atb":[[1.03,15.09]],"id":57087188},{"atl":[[1000,0.26]],"id":57087188},{"spn":500.51,"spf":"NaN","id":57087188},{"atb":[[1.01,45.28]],"id":65436514},{"atl":[[1000,0.26]],"id":65436514},{"spn":500.5,"spf":"NaN","id":65436514},{"atb":[[1.02,22.64]],"id":69142441},{"atl":[[990,0.26]],"id":69142441},{"spn":495.51,"spf":"NaN","id":69142441},{"atb":[[1.02,22.64]],"id":55302014},{"atl":[[1000,0.26]],"id":55302014},{"spn":500.51,"spf":"NaN","id":55302014},{"atb":[[1.03,15.09]],"id":68392143},{"atl":[[990,0.26]],"id":68392143},{"spn":495.51,"spf":"NaN","id":68392143},{"atb":[[1.02,22.64]],"id":57088863},{"atl":[[1000,0.26]],"id":57088863},{"spn":500.51,"spf":"NaN","id":57088863}],"con":true,"img":true}]}
{"op":"mcm","clk":"11538170599","pt":1719454082544,"mc":[{"id":"1.230178311","marketDefinition":{"bspMarket":true,"turnInPlayEnabled":false,"persistenceEnabled":false,"marketBaseRate":5.0,"eventId":"33376062","eventTypeId":"4339","numberOfWinners":2,"bettingType":"ODDS","marketType":"PLACE","marketTime":"2024-06-27T14:13:00.000Z","suspendTime":"2024-06-27T14:13:00.000Z","bspReconciled":false,"complete":true,"inPlay":false,"crossMatching":false,"runnersVoidable":false,"numberOfActiveRunners":6,"betDelay":0,"status":"OPEN","runners":[{"status":"ACTIVE","sortPriority":1,"id":57087188,"name":"1. Ballymac Boomer"},{"status":"ACTIVE","sortPriority":2,"id":57088863,"name":"2. Ferryfort Native"},{"status":"ACTIVE","sortPriority":3,"id":55302014,"name":"3. Blue The Woofoff"},{"status":"ACTIVE","sortPriority":4,"id":65436514,"name":"4. Leticias Pride"},{"status":"ACTIVE","sortPriority":5,"id":68392143,"name":"5. Springfield Best"},{"status":"ACTIVE","sortPriority":6,"id":69142441,"name":"6. Ferndale Tok"}],"regulators":["MR_INT"],"venue":"Kinsley","countryCode":"GB","discountAllowed":true,"timezone":"Europe/London","openDate":"2024-06-27T13:36:00.000Z","version":5994643761,"name":"To Be Placed","eventName":"Kinsley 27th Jun"},"rc":[{"atb":[[1.03,15.09]],"id":57087188},{"atl":[[1000,0.26]],"id":57087188},{"spn":500.51,"spf":"NaN","id":57087188},{"atb":[[1.01,45.29]],"id":65436514},{"atl":[[1000,0.26]],"id":65436514},{"spn":500.5,"spf":"NaN","id":65436514},{"atb":[[1.02,22.64]],"id":69142441},{"atl":[[990,0.26]],"id":69142441},{"spn":495.51,"spf":"NaN","id":69142441},{"atb":[[1.02,22.64]],"id":55302014},{"atl":[[1000,0.26]],"id":55302014},{"spn":500.51,"spf":"NaN","id":55302014},{"atb":[[1.03,15.09]],"id":68392143},{"atl":[[990,0.26]],"id":68392143},{"spn":495.51,"spf":"NaN","id":68392143},{"atb":[[1.02,22.64]],"id":57088863},{"atl":[[1000,0.26]],"id":57088863},{"spn":500.51,"spf":"NaN","id":57088863}],"con":true,"img":true}]}
{"op":"mcm","clk":"11538368257","pt":1719459482573,"mc":[{"id":"1.230178311","marketDefinition":{"bspMarket":true,"turnInPlayEnabled":false,"persistenceEnabled":false,"marketBaseRate":5.0,"eventId":"33376062","eventTypeId":"4339","numberOfWinners":2,"bettingType":"ODDS","marketType":"PLACE","marketTime":"2024-06-27T14:13:00.000Z","suspendTime":"2024-06-27T14:13:00.000Z","bspReconciled":false,"complete":true,"inPlay":false,"crossMatching":false,"runnersVoidable":false,"numberOfActiveRunners":6,"betDelay":0,"status":"OPEN","runners":[{"status":"ACTIVE","sortPriority":1,"id":57087188,"name":"1. Ballymac Boomer"},{"status":"ACTIVE","sortPriority":2,"id":57088863,"name":"2. Ferryfort Native"},{"status":"ACTIVE","sortPriority":3,"id":55302014,"name":"3. Blue The Woofoff"},{"status":"ACTIVE","sortPriority":4,"id":65436514,"name":"4. Leticias Pride"},{"status":"ACTIVE","sortPriority":5,"id":68392143,"name":"5. Springfield Best"},{"status":"ACTIVE","sortPriority":6,"id":69142441,"name":"6. Ferndale Tok"}],"regulators":["MR_INT"],"venue":"Kinsley","countryCode":"GB","discountAllowed":true,"timezone":"Europe/London","openDate":"2024-06-27T13:36:00.000Z","version":5994643761,"name":"To Be Placed","eventName":"Kinsley 27th Jun"},"rc":[{"atb":[[1.03,15.1]],"id":57087188},{"atl":[[1000,0.26]],"id":57087188},{"spn":500.51,"spf":"NaN","id":57087188},{"atb":[[1.01,45.3]],"id":65436514},{"atl":[[1000,0.26]],"id":65436514},{"spn":500.5,"spf":"NaN","id":65436514},{"atb":[[1.02,22.65]],"id":69142441},{"atl":[[990,0.26]],"id":69142441},{"spn":495.51,"spf":"NaN","id":69142441},{"atb":[[1.02,22.65]],"id":55302014},{"atl":[[1000,0.26]],"id":55302014},{"spn":500.51,"spf":"NaN","id":55302014},{"atb":[[1.03,15.1]],"id":68392143},{"atl":[[990,0.26]],"id":68392143},{"spn":495.51,"spf":"NaN","id":68392143},{"atb":[[1.02,22.65]],"id":57088863},{"atl":[[1000,0.26]],"id":57088863},{"spn":500.51,"spf":"NaN","id":57088863}],"con":true,"img":true}]}
{"op":"mcm","clk":"11538595383","pt":1719464882543,"mc":[{"id":"1.230178311","marketDefinition":{"bspMarket":true,"turnInPlayEnabled":false,"persistenceEnabled":false,"marketBaseRate":5.0,"eventId":"33376062","eventTypeId":"4339","numberOfWinners":2,"bettingType":"ODDS","marketType":"PLACE","marketTime":"2024-06-27T14:13:00.000Z","suspendTime":"2024-06-27T14:13:00.000Z","bspReconciled":false,"complete":true,"inPlay":false,"crossMatching":false,"runnersVoidable":false,"numberOfActiveRunners":6,"betDelay":0,"status":"OPEN","runners":[{"status":"ACTIVE","sortPriority":1,"id":57087188,"name":"1. Ballymac Boomer"},{"status":"ACTIVE","sortPriority":2,"id":57088863,"name":"2. Ferryfort Native"},{"status":"ACTIVE","sortPriority":3,"id":55302014,"name":"3. Blue The Woofoff"},{"status":"ACTIVE","sortPriority":4,"id":65436514,"name":"4. Leticias Pride"},{"status":"ACTIVE","sortPriority":5,"id":68392143,"name":"5. Springfield Best"},{"status":"ACTIVE","sortPriority":6,"id":69142441,"name":"6. Ferndale Tok"}],"regulators":["MR_INT"],"venue":"Kinsley","countryCode":"GB","discountAllowed":true,"timezone":"Europe/London","openDate":"2024-06-27T13:36:00.000Z","version":5994643761,"name":"To Be Placed","eventName":"Kinsley 27th Jun"},"rc":[{"atb":[[1.03,15.09]],"id":57087188},{"atl":[[1000,0.26]],"id":57087188},{"spn":500.51,"spf":"NaN","id":57087188},{"atb":[[1.01,45.29]],"id":65436514},{"atl":[[1000,0.26]],"id":65436514},{"spn":500.5,"spf":"NaN","id":65436514},{"atb":[[1.02,22.64]],"id":69142441},{"atl":[[990,0.26]],"id":69142441},{"spn":495.51,"spf":"NaN","id":69142441},{"atb":[[1.02,22.64]],"id":55302014},{"atl":[[1000,0.26]],"id":55302014},{"spn":500.51,"spf":"NaN","id":55302014},{"atb":[[1.03,15.09]],"id":68392143},{"atl":[[990,0.26]],"id":68392143},{"spn":495.51,"spf":"NaN","id":68392143},{"atb":[[1.02,22.64]],"id":57088863},{"atl":[[1000,0.26]],"id":57088863},{"spn":500.51,"spf":"NaN","id":57088863}],"con":true,"img":true}]}
{"op":"mcm","clk":"11538905691","pt":1719471477726,"mc":[{"id":"1.230178311","rc":[{"atb":[[1.03,15.09]],"id":57087188},{"atl":[[1000,0.16]],"id":57087188},{"atb":[[1.01,45.29]],"id":65436514},{"atl":[[1000,0.16]],"id":65436514},{"atb":[[1.02,22.64]],"id":69142441},{"atl":[[990,0.16]],"id":69142441},{"atb":[[1.02,22.64]],"id":55302014},{"atl":[[1000,0.16]],"id":55302014},{"atb":[[1.03,15.09]],"id":68392143},{"atl":[[990,0.16]],"id":68392143},{"atb":[[1.02,22.64]],"id":57088863},{"atl":[[1000,0.16]],"id":57088863}],"con":true,"img":false}]}
{"op":"mcm","clk":"11538907362","pt":1719471509188,"mc":[{"id":"1.230178311","rc":[{"atl":[[1000,1.16]],"id":57087188},{"atl":[[1000,1.16]],"id":65436514},{"atl":[[1000,1]],"id":69142441},{"atl":[[1000,1.16]],"id":55302014},{"atl":[[1000,1]],"id":68392143},{"atl":[[1000,1.16]],"id":57088863}],"con":true,"img":false}]}
{"op":"mcm","clk":"11538907368","pt":1719471509292,"mc":[{"id":"1.230178311","rc":[{"atb":[[1.07,2.48]],"id":57087188},{"atl":[[1000,0.64]],"id":57087188},{"atb":[[1.07,2.48]],"id":65436514},{"atl":[[1000,0.64]],"id":65436514},{"atb":[[1.07,2.48]],"id":69142441},{"atl":[[1000,0.48]],"id":69142441},{"atb":[[1.07,2.48]],"id":55302014},{"atl":[[1000,0.64]],"id":55302014},{"atb":[[1.07,2.48]],"id":68392143},{"atl":[[1000,0.48]],"id":68392143},{"atb":[[1.07,2.48]],"id":57088863},{"atl":[[1000,0.64]],"id":57088863}],"con":true,"img":false}]}
{"op":"mcm","clk":"11538907381","pt":1719471509499,"mc":[{"id":"1.230178311","rc":[{"atl":[[1000,0.16]],"id":57087188},{"atl":[[1000,0.16]],"id":65436514},{"atl":[[1000,0]],"id":69142441},{"atl":[[1000,0.16]],"id":55302014},{"atl":[[1000,0]],"id":68392143},{"atl":[[1000,0.16]],"id":57088863}],"con":true,"img":false}]}
{"op":"mcm","clk":"11538907388","pt":1719471509554,"mc":[{"id":"1.230178311","rc":[{"atl":[[75,0.48]],"id":57087188},{"atl":[[75,0.48]],"id":65436514},{"atl":[[75,0.48]],"id":69142441},{"atl":[[75,0.48]],"id":55302014},{"atl":[[75,0.48]],"id":68392143},{"atl":[[75,0.48]],"id":57088863}],"con":true,"img":false}]}
{"op":"mcm","clk":"11539122530","pt":1719475682549,"mc":[{"id":"1.230178311","marketDefinition":{"bspMarket":true,"turnInPlayEnabled":false,"persistenceEnabled":false,"marketBaseRate":5.0,"eventId":"33376062","eventTypeId":"4339","numberOfWinners":2,"bettingType":"ODDS","marketType":"PLACE","marketTime":"2024-06-27T14:13:00.000Z","suspendTime":"2024-06-27T14:13:00.000Z","bspReconciled":false,"complete":true,"inPlay":false,"crossMatching":false,"runnersVoidable":false,"numberOfActiveRunners":6,"betDelay":0,"status":"OPEN","runners":[{"status":"ACTIVE","sortPriority":1,"id":57087188,"name":"1. Ballymac Boomer"},{"status":"ACTIVE","sortPriority":2,"id":57088863,"name":"2. Ferryfort Native"},{"status":"ACTIVE","sortPriority":3,"id":55302014,"name":"3. Blue The Woofoff"},{"status":"ACTIVE","sortPriority":4,"id":65436514,"name":"4. Leticias Pride"},{"status":"ACTIVE","sortPriority":5,"id":68392143,"name":"5. Springfield Best"},{"status":"ACTIVE","sortPriority":6,"id":69142441,"name":"6. Ferndale Tok"}],"regulators":["MR_INT"],"venue":"Kinsley","countryCode":"GB","discountAllowed":true,"timezone":"Europe/London","openDate":"2024-06-27T13:36:00.000Z","version":5994643761,"name":"To Be Placed","eventName":"Kinsley 27th Jun"},"rc":[{"atb":[[1.03,15.09],[1.07,2.48]],"id":57087188},{"atl":[[75,0.48],[1000,0.16]],"id":57087188},{"spn":38.03,"spf":"NaN","id":57087188},{"atb":[[1.01,45.28],[1.07,2.48]],"id":65436514},{"atl":[[75,0.48],[1000,0.16]],"id":65436514},{"spn":38.03,"spf":"NaN","id":65436514},{"atb":[[1.02,22.64],[1.07,2.48]],"id":69142441},{"atl":[[75,0.48],[990,0.16]],"id":69142441},{"spn":38.03,"spf":"NaN","id":69142441},{"atb":[[1.02,22.64],[1.07,2.48]],"id":55302014},{"atl":[[75,0.48],[1000,0.16]],"id":55302014},{"spn":38.03,"spf":"NaN","id":55302014},{"atb":[[1.03,15.09],[1.07,2.48]],"id":68392143},{"atl":[[75,0.48],[990,0.16]],"id":68392143},{"spn":38.03,"spf":"NaN","id":68392143},{"atb":[[1.02,22.64],[1.07,2.48]],"id":57088863},{"atl":[[75,0.48],[1000,0.16]],"id":57088863},{"spn":38.03,"spf":"NaN","id":57088863}],"con":true,"img":true}]}
{"op":"mcm","clk":"11539438506","pt":1719481082545,"mc":[{"id":"1.230178311","marketDefinition":{"bspMarket":true,"turnInPlayEnabled":false,"persistenceEnabled":false,"marketBaseRate":5.0,"eventId":"33376062","eventTypeId":"4339","numberOfWinners":2,"bettingType":"ODDS","marketType":"PLACE","marketTime":"2024-06-27T14:13:00.000Z","suspendTime":"2024-06-27T14:13:00.000Z","bspReconciled":false,"complete":true,"inPlay":false,"crossMatching":false,"runnersVoidable":false,"numberOfActiveRunners":6,"betDelay":0,"status":"OPEN","runners":[{"status":"ACTIVE","sortPriority":1,"id":57087188,"name":"1. Ballymac Boomer"},{"status":"ACTIVE","sortPriority":2,"id":57088863,"name":"2. Ferryfort Native"},{"status":"ACTIVE","sortPriority":3,"id":55302014,"name":"3. Blue The Woofoff"},{"status":"ACTIVE","sortPriority":4,"id":65436514,"name":"4. Leticias Pride"},{"status":"ACTIVE","sortPriority":5,"id":68392143,"name":"5. Springfield Best"},{"status":"ACTIVE","sortPriority":6,"id":69142441,"name":"6. Ferndale Tok"}],"regulators":["MR_INT"],"venue":"Kinsley","countryCode":"GB","discountAllowed":true,"timezone":"Europe/London","openDate":"2024-06-27T13:36:00.000Z","version":5994643761,"name":"To Be Placed","eventName":"Kinsley 27th Jun"},"rc":[{"atb":[[1.03,15.09],[1.07,2.48]],"id":57087188},{"atl":[[75,0.48],[1000,0.16]],"id":57087188},{"spn":38.03,"spf":"NaN","id":57087188},{"atb":[[1.01,45.27],[1.07,2.48]],"id":65436514},{"atl":[[75,0.48],[1000,0.16]],"id":65436514},{"spn":38.03,"spf":"NaN","id":65436514},{"atb":[[1.02,22.63],[1.07,2.48]],"id":69142441},{"atl":[[75,0.48],[990,0.16]],"id":69142441},{"spn":38.03,"spf":"NaN","id":69142441},{"atb":[[1.02,22.63],[1.07,2.48]],"id":55302014},{"atl":[[75,0.48],[1000,0.16]],"id":55302014},{"spn":38.03,"spf":"NaN","id":55302014},{"atb":[[1.03,15.09],[1.07,2.48]],"id":68392143},{"atl":[[75,0.48],[990,0.16]],"id":68392143},{"spn":38.03,"spf":"NaN","id":68392143},{"atb":[[1.02,22.63],[1.07,2.48]],"id":57088863},{"atl":[[75,0.48],[1000,0.16]],"id":57088863},{"spn":38.03,"spf":"NaN","id":57088863}],"con":true,"img":true}]}
{"op":"mcm","clk":"11540326597","pt":1719493050852,"mc":[{"id":"1.230178311","rc":[{"atb":[[1.03,15.09]],"id":57087188},{"atl":[[960,1.11]],"id":57087188},{"spn":38.03,"spf":"NaN","id":57087188},{"atb":[[1.01,45.27]],"id":65436514},{"atl":[[970,1.73]],"id":65436514},{"spn":38.03,"spf":"NaN","id":65436514},{"atb":[[1.02,22.63]],"id":69142441},{"atl":[[980,1.58]],"id":69142441},{"spn":38.03,"spf":"NaN","id":69142441},{"atb":[[1.02,22.63]],"id":55302014},{"atl":[[990,1.5]],"id":55302014},{"spn":38.03,"spf":"NaN","id":55302014},{"atb":[[1.03,15.09]],"id":68392143},{"atl":[[960,0.87]],"id":68392143},{"spn":38.03,"spf":"NaN","id":68392143},{"atb":[[1.02,22.63]],"id":57088863},{"atl":[[970,0.87]],"id":57088863},{"spn":38.03,"spf":"NaN","id":57088863}],"con":true,"img":false}]}
{"op":"mcm","clk":"11540522786","pt":1719495483703,"mc":[{"id":"1.230178311","rc":[{"atb":[[1.03,15.1],[1.04,1]],"id":57087188},{"atl":[[960,1.11],[1000,0.16]],"id":57087188},{"atb":[[1.01,45.32],[1.04,1]],"id":65436514},{"atl":[[970,1.73],[1000,0.16]],"id":65436514},{"atb":[[1.02,22.66],[1.04,1]],"id":69142441},{"atl":[[980,1.58],[990,0.16]],"id":69142441},{"atb":[[1.02,22.66],[1.04,1]],"id":55302014},{"atl":[[990,1.5],[1000,0.16]],"id":55302014},{"atb":[[1.03,15.1],[1.04,1]],"id":68392143},{"atl":[[960,0.87],[990,0.16]],"id":68392143},{"atb":[[1.02,22.66],[1.04,1]],"id":57088863},{"atl":[[970,0.87],[1000,0.16]],"id":57088863}],"con":true,"img":false}]}
{"op":"mcm","clk":"11540522803","pt":1719495483909,"mc":[{"id":"1.230178311","rc":[{"atb":[[1.04,0.25]],"id":57087188},{"atb":[[1.04,0.25]],"id":65436514},{"atb":[[1.04,0.25]],"id":69142441},{"atb":[[1.04,0.25]],"id":55302014},{"atb":[[1.04,0.25]],"id":68392143},{"atb":[[1.04,0.25]],"id":57088863}],"con":true,"img":false}]}
{"op":"mcm","clk":"11540522813","pt":1719495484014,"mc":[{"id":"1.230178311","rc":[{"atb":[[1.04,0]],"id":57087188},{"atb":[[1.04,0]],"id":65436514},{"atb":[[1.04,0]],"id":69142441},{"atb":[[1.04,0]],"id":55302014},{"atb":[[1.04,0]],"id":68392143},{"atb":[[1.04,0]],"id":57088863}],"con":true,"img":false}]}
{"op":"mcm","clk":"11540522825","pt":1719495484120,"mc":[{"id":"1.230178311","rc":[{"atb":[[1.2,0.25]],"id":57087188},{"atb":[[1.2,0.25]],"id":65436514},{"atb":[[1.2,0.25]],"id":69142441},{"atb":[[1.2,0.25]],"id":55302014},{"atb":[[1.2,0.25]],"id":68392143},{"atb":[[1.2,0.25]],"id":57088863}],"con":true,"img":false}]}
{"op":"mcm","clk":"11540557470","pt":1719495875975,"mc":[{"id":"1.230178311","rc":[{"spn":38.1,"spf":"NaN","id":57087188},{"spn":38.1,"spf":"NaN","id":65436514},{"spn":38.1,"spf":"NaN","id":69142441},{"spn":38.1,"spf":"NaN","id":55302014},{"spn":38.1,"spf":"NaN","id":68392143},{"atb":[[1.09,43.89]],"id":57088863},{"spn":38.1,"spf":"NaN","id":57088863}],"con":true,"img":false}]}
{"op":"mcm","clk":"11540557485","pt":1719495876177,"mc":[{"id":"1.230178311","rc":[{"atb":[[1.09,43.89]],"id":65436514},{"atb":[[1.09,43.89]],"id":69142441}],"con":true,"img":false}]}
{"op":"mcm","clk":"11540558057","pt":1719495882831,"mc":[{"id":"1.230178311","marketDefinition":{"bspMarket":true,"turnInPlayEnabled":false,"persistenceEnabled":false,"marketBaseRate":5.0,"eventId":"33376062","eventTypeId":"4339","numberOfWinners":2,"bettingType":"ODDS","marketType":"PLACE","marketTime":"2024-06-27T14:13:00.000Z","suspendTime":"2024-06-27T14:13:00.000Z","bspReconciled":false,"complete":true,"inPlay":false,"crossMatching":true,"runnersVoidable":false,"numberOfActiveRunners":6,"betDelay":0,"status":"OPEN","runners":[{"status":"ACTIVE","sortPriority":1,"id":57087188,"name":"1. Ballymac Boomer"},{"status":"ACTIVE","sortPriority":2,"id":57088863,"name":"2. Ferryfort Native"},{"status":"ACTIVE","sortPriority":3,"id":55302014,"name":"3. Blue The Woofoff"},{"status":"ACTIVE","sortPriority":4,"id":65436514,"name":"4. Leticias Pride"},{"status":"ACTIVE","sortPriority":5,"id":68392143,"name":"5. Springfield Best"},{"status":"ACTIVE","sortPriority":6,"id":69142441,"name":"6. Ferndale Tok"}],"regulators":["MR_INT"],"venue":"Kinsley","countryCode":"GB","discountAllowed":true,"timezone":"Europe/London","openDate":"2024-06-27T13:36:00.000Z","version":5994643761,"name":"To Be Placed","eventName":"Kinsley 27th Jun"},"rc":[],"con":true,"img":false}]}
{"op":"mcm","clk":"11540574868","pt":1719496061808,"mc":[{"id":"1.230178311","rc":[{"atb":[[1.09,0]],"id":69142441},{"atb":[[1.09,0]],"id":57088863}],"con":true,"img":false}]}
{"op":"mcm","clk":"11540579547","pt":1719496109368,"mc":[{"id":"1.230178311","rc":[{"atb":[[1.11,38.49]],"id":65436514}],"con":true,"img":false}]}
{"op":"mcm","clk":"11540580130","pt":1719496115572,"mc":[{"id":"1.230178311","rc":[{"atb":[[1.09,0]],"id":65436514}],"con":true,"img":false}]}
{"op":"mcm","clk":"11540580168","pt":1719496115984,"mc":[{"id":"1.230178311","rc":[{"atb":[[1.13,30.38]],"id":65436514}],"con":true,"img":false}]}
{"op":"mcm","clk":"11540583128","pt":1719496146186,"mc":[{"id":"1.230178311","rc":[{"atb":[[1.11,0]],"id":65436514}],"con":true,"img":false}]}
{"op":"mcm","clk":"11540583204","pt":1719496146897,"mc":[{"id":"1.230178311","rc":[{"atb":[[1.15,28.22]],"id":65436514}],"con":true,"img":false}]}
{"op":"mcm","clk":"11540583830","pt":1719496152379,"mc":[{"id":"1.230178311","rc":[{"atb":[[1.13,0]],"id":65436514}],"con":true,"img":false}]}
{"op":"mcm","clk":"11540583890","pt":1719496152897,"mc":[{"id":"1.230178311","rc":[{"atb":[[1.17,23.23]],"id":65436514}],"con":true,"img":false}]}
{"op":"mcm","clk":"11540586883","pt":1719496182344,"mc":[{"id":"1.230178311","rc":[{"atb":[[1.15,0]],"id":65436514}],"con":true,"img":false}]}
{"op":"mcm","clk":"11540586907","pt":1719496182604,"mc":[{"id":"1.230178311","rc":[{"atb":[[1.19,22.29]],"id":65436514}],"con":true,"img":false}]}
{"op":"mcm","clk":"11540587714","pt":1719496190808,"mc":[{"id":"1.230178311","rc":[{"atb":[[1.17,0]],"id":65436514}],"con":true,"img":false}]}
{"op":"mcm","clk":"11540587731","pt":1719496191018,"mc":[{"id":"1.230178311","rc":[{"atb":[[1.21,18.81]],"id":65436514}],"con":true,"img":false}]}
{"op":"mcm","clk":"11540590727","pt":1719496219658,"mc":[{"id":"1.230178311","rc":[{"atb":[[1.19,0]],"id":65436514},{"spn":38.1,"spf":"NaN","id":65436514}],"con":true,"img":false}]}
{"op":"mcm","clk":"11540590787","pt":1719496220277,"mc":[{"id":"1.230178311","rc":[{"atb":[[1.23,18.41]],"id":65436514}],"con":true,"img":false}]}
{"op":"mcm","clk":"11540591491","pt":1719496227236,"mc":[{"id":"1.230178311","rc":[{"atb":[[1.21,0]],"id":65436514}],"con":true,"img":false}]}
{"op":"mcm","clk":"11540591506","pt":1719496227448,"mc":[{"id":"1.230178311","rc":[{"atb":[[1.25,15.8]],"id":65436514}],"con":true,"img":false}]}
{"op":"mcm","clk":"11540594425","pt":1719496255314,"mc":[{"id":"1.230178311","rc":[{"atb":[[1.23,0]],"id":65436514}],"con":true,"img":false}]}
{"op":"mcm","clk":"11540594459","pt":1719496255581,"mc":[{"id":"1.230178311","rc":[{"atb":[[1.27,15.68]],"id":65436514}],"con":true,"img":false}]}
{"op":"mcm","clk":"11540595341","pt":1719496264320,"mc":[{"id":"1.230178311","rc":[{"atb":[[1.25,0]],"id":65436514}],"con":true,"img":false}]}
{"op":"mcm","clk":"11540595369","pt":1719496264528,"mc":[{"id":"1.230178311","rc":[{"atb":[[1.29,13.62]],"id":65436514}],"con":true,"img":false}]}
{"op":"mcm","clk":"11540598061","pt":1719496291749,"mc":[{"id":"1.230178311","rc":[{"atb":[[1.27,0]],"id":65436514},{"spn":38.14,"spf":"NaN","id":65436514}],"con":true,"img":false}]}
{"op":"mcm","clk":"11540598108","pt":1719496292262,"mc":[{"id":"1.230178311","rc":[{"atb":[[1.31,13.66]],"id":65436514}],"con":true,"img":false}]}
{"op":"mcm","clk":"11540598183","pt":1719496293140,"mc":[{"id":"1.230178311","rc":[{"atb":[[1.2,3.02]],"id":65436514}],"con":true,"img":false}]}
{"op":"mcm","clk":"11540599113","pt":1719496302842,"mc":[{"id":"1.230178311","rc":[{"atb":[[1.29,0]],"id":65436514}],"con":true,"img":false}]}
{"op":"mcm","clk":"11540599135","pt":1719496303043,"mc":[{"id":"1.230178311","rc":[{"atb":[[1.33,11.96]],"id":65436514}],"con":true,"img":false}]}
{"op":"mcm","clk":"11540600056","pt":1719496311866,"mc":[{"id":"1.230178311","rc":[{"atb":[[1.2,0.25]],"id":65436514}],"con":true,"img":false}]}
{"op":"mcm","clk":"11540601462","pt":1719496326087,"mc":[{"id":"1.230178311","rc":[{"atb":[[1.31,0]],"id":65436514}],"con":true,"img":false}]}
{"op":"mcm","clk":"11540601494","pt":1719496326350,"mc":[{"id":"1.230178311","rc":[{"atb":[[1.35,12.1]],"id":65436514}],"con":true,"img":false}]}
{"op":"mcm","clk":"11540602877","pt":1719496341203,"mc":[{"id":"1.230178311","rc":[{"atb":[[1.33,0]],"id":65436514}],"con":true,"img":false}]}
{"op":"mcm","clk":"11540602894","pt":1719496341359,"mc":[{"id":"1.230178311","rc":[{"atb":[[1.37,10.67]],"id":65436514}],"con":true,"img":false}]}
{"op":"mcm","clk":"11540605008","pt":1719496362730,"mc":[{"id":"1.230178311","rc":[{"atb":[[1.35,0]],"id":65436514},{"spn":38.18,"spf":"NaN","id":65436514}],"con":true,"img":false}]}
{"op":"mcm","clk":"11540605067","pt":1719496363305,"mc":[{"id":"1.230178311","rc":[{"atb":[[1.39,10.85]],"id":65436514}],"con":true,"img":false}]}
{"op":"mcm","clk":"11540606484","pt":1719496378349,"mc":[{"id":"1.230178311","rc":[{"atb":[[1.37,0]],"id":65436514}],"con":true,"img":false}]}
{"op":"mcm","clk":"11540606509","pt":1719496378554,"mc":[{"id":"1.230178311","rc":[{"atb":[[1.41,9.63]],"id":65436514}],"con":true,"img":false}]}
{"op":"mcm","clk":"11540606833","pt":1719496381862,"mc":[{"id":"1.230178311","rc":[{"atb":[[1.42,2.11]],"id":65436514}],"con":true,"img":false}]}
{"op":"mcm","clk":"11540608159","pt":1719496395757,"mc":[{"id":"1.230178311","rc":[{"atb":[[1.41,0]],"id":65436514}],"con":true,"img":false}]}
{"op":"mcm","clk":"11540608178","pt":1719496395963,"mc":[{"id":"1.230178311","rc":[{"atb":[[1.44,8.97]],"id":65436514}],"con":true,"img":false}]}
{"op":"mcm","clk":"11540608317","pt":1719496397455,"mc":[{"id":"1.230178311","rc":[{"atb":[[1.39,0]],"id":65436514}],"con":true,"img":false}]}
{"op":"mcm","clk":"11540608359","pt":1719496397969,"mc":[{"id":"1.230178311","rc":[{"atb":[[1.46,9.2]],"id":65436514}],"con":true,"img":false}]}
{"op":"mcm","clk":"11540609761","pt":1719496414392,"mc":[{"id":"1.230178311","rc":[{"atb":[[1.44,0]],"id":65436514}],"con":true,"img":false}]}
{"op":"mcm","clk":"11540609786","pt":1719496414657,"mc":[{"id":"1.230178311","rc":[{"atb":[[1.48,8.23]],"id":65436514}],"con":true,"img":false}]}
{"op":"mcm","clk":"11540611427","pt":1719496431902,"mc":[{"id":"1.230178311","rc":[{"atb":[[1.46,0]],"id":65436514},{"spn":38.24,"spf":"NaN","id":65436514}],"con":true,"img":false}]}
{"op":"mcm","clk":"11540611457","pt":1719496432211,"mc":[{"id":"1.230178311","rc":[{"atb":[[1.5,8.46]],"id":65436514}],"con":true,"img":false}]}
{"op":"mcm","clk":"11540613074","pt":1719496449020,"mc":[{"id":"1.230178311","rc":[{"atb":[[1.48,0]],"id":65436514}],"con":true,"img":false}]}
{"op":"mcm","clk":"11540613095","pt":1719496449181,"mc":[{"id":"1.230178311","rc":[{"atb":[[1.52,7.6]],"id":65436514}],"con":true,"img":false}]}
{"op":"mcm","clk":"11540620686","pt":1719496536691,"mc":[{"id":"1.230178311","rc":[{"atb":[[1.5,0]],"id":65436514},{"spn":38.26,"spf":"NaN","id":65436514}],"con":true,"img":false}]}
{"op":"mcm","clk":"11540622425","pt":1719496558335,"mc":[{"id":"1.230178311","rc":[{"atb":[[1.09,43.89]],"id":68392143}],"con":true,"img":false}]}
{"op":"mcm","clk":"11540623852","pt":1719496574862,"mc":[{"id":"1.230178311","rc":[{"atb":[[1.1,59.28]],"id":68392143}],"con":true,"img":false}]}
{"op":"mcm","clk":"11540623865","pt":1719496574966,"mc":[{"id":"1.230178311","rc":[{"atb":[[1.11,38.49]],"id":68392143}],"con":true,"img":false}]}
{"op":"mcm","clk":"11540624037","pt":1719496577130,"mc":[{"id":"1.230178311","rc":[{"atb":[[1.12,46.08]],"id":68392143}],"con":true,"img":false}]}
{"op":"mcm","clk":"11540624053","pt":1719496577335,"mc":[{"id":"1.230178311","rc":[{"atb":[[1.09,0]],"id":68392143}],"con":true,"img":false}]}
{"op":"mcm","clk":"11540624073","pt":1719496577550,"mc":[{"id":"1.230178311","rc":[{"atb":[[1.13,30.38]],"id":68392143}],"con":true,"img":false}]}
{"op":"mcm","clk":"11540627006","pt":1719496611168,"mc":[{"id":"1.230178311","rc":[{"atb":[[1.52,0]],"id":65436514},{"spn":38.21,"spf":"NaN","id":65436514}],"con":true,"img":false}]}
{"op":"mcm","clk":"11540627086","pt":1719496612095,"mc":[{"id":"1.230178311","rc":[{"atb":[[1.11,0],[1.1,0]],"id":68392143}],"con":true,"img":false}]}
{"op":"mcm","clk":"11540627109","pt":1719496612259,"mc":[{"id":"1.230178311","rc":[{"atb":[[1.44,8.97]],"id":65436514}],"con":true,"img":false}]}
{"op":"mcm","clk":"11540627117","pt":1719496612362,"mc":[{"id":"1.230178311","rc":[{"atb":[[1.44,18.59]],"id":65436514},{"atb":[[1.15,28.22]],"id":68392143}],"con":true,"img":false}]}
{"op":"mcm","clk":"11540627141","pt":1719496612675,"mc":[{"id":"1.230178311","rc":[{"atb":[[1.14,42.34]],"id":68392143}],"con":true,"img":false}]}
{"op":"mcm","clk":"11540628524","pt":1719496629582,"mc":[{"id":"1.230178311","rc":[{"atb":[[1.44,9.62]],"id":65436514},{"atb":[[1.12,0]],"id":68392143}],"con":true,"img":false}]}
{"op":"mcm","clk":"11540628548","pt":1719496629787,"mc":[{"id":"1.230178311","rc":[{"atb":[[1.16,34.56],[1.13,0]],"id":68392143}],"con":true,"img":false}]}
{"op":"mcm","clk":"11540628563","pt":1719496629994,"mc":[{"id":"1.230178311","rc":[{"atb":[[1.46,8.58]],"id":65436514}],"con":true,"img":false}]}
{"op":"mcm","clk":"11540628579","pt":1719496630197,"mc":[{"id":"1.230178311","rc":[{"atb":[[1.17,23.23]],"id":68392143}],"con":true,"img":false}]}
{"op":"mcm","clk":"11540630218","pt":1719496651014,"mc":[{"id":"1.230178311","rc":[{"atb":[[1.14,0]],"id":68392143}],"con":true,"img":false}]}
{"op":"mcm","clk":"11540630234","pt":1719496651220,"mc":[{"id":"1.230178311","rc":[{"atb":[[1.44,0]],"id":65436514}],"con":true,"img":false}]}
{"op":"mcm","clk":"11540630252","pt":1719496651401,"mc":[{"id":"1.230178311","rc":[{"atb":[[1.15,0]],"id":68392143}],"con":true,"img":false}]}
{"op":"mcm","clk":"11540630281","pt":1719496651713,"mc":[{"id":"1.230178311","rc":[{"atb":[[1.18,32.93]],"id":68392143}],"con":true,"img":false}]}
{"op":"mcm","clk":"11540630292","pt":1719496651824,"mc":[{"id":"1.230178311","rc":[{"atb":[[1.48,8.82]],"id":65436514}],"con":true,"img":false}]}
{"op":"mcm","clk":"11540630305","pt":1719496652026,"mc":[{"id":"1.230178311","rc":[{"atb":[[1.19,22.29]],"id":68392143}],"con":true,"img":false}]}
{"op":"mcm","clk":"11540631434","pt":1719496666115,"mc":[{"id":"1.230178311","rc":[{"atb":[[1.16,0]],"id":68392143}],"con":true,"img":false}]}
{"op":"mcm","clk":"11540631442","pt":1719496666216,"mc":[{"id":"1.230178311","rc":[{"atb":[[1.17,0]],"id":68392143}],"con":true,"img":false}]}
{"op":"mcm","clk":"11540631456","pt":1719496666419,"mc":[{"id":"1.230178311","rc":[{"atb":[[1.46,0]],"id":65436514}],"con":true,"img":false}]}
{"op":"mcm","clk":"11540631464","pt":1719496666525,"mc":[{"id":"1.230178311","rc":[{"atb":[[1.21,18.81]],"id":68392143}],"con":true,"img":false}]}
{"op":"mcm","clk":"11540631475","pt":1719496666627,"mc":[{"id":"1.230178311","rc":[{"atb":[[1.2,27.9]],"id":68392143}],"con":true,"img":false}]}
{"op":"mcm","clk":"11540631493","pt":1719496666832,"mc":[{"id":"1.230178311","rc":[{"atb":[[1.5,7.9]],"id":65436514}],"con":true,"img":false}]}
{"op":"mcm","clk":"11540632549","pt":1719496680259,"mc":[{"id":"1.230178311","rc":[{"atb":[[1.51,7.9]],"id":65436514},{"atl":[[9.6,2]],"id":65436514},{"spn":5.55,"spf":"NaN","id":65436514},{"spn":38.1,"spf":"NaN","id":68392143}],"con":true,"img":false}]}
{"op":"mcm","clk":"11540632557","pt":1719496680312,"mc":[{"id":"1.230178311","rc":[{"atb":[[2.14,2.48]],"id":69142441},{"atl":[[120,2]],"id":69142441},{"atb":[[1.66,22.29]],"id":68392143},{"atl":[[23,2]],"id":68392143},{"atb":[[1.76,2.48]],"id":57088863},{"atl":[[32,2]],"id":57088863}],"con":true,"img":false}]}
{"op":"mcm","clk":"11540632567","pt":1719496680418,"mc":[{"id":"1.230178311","rc":[{"atb":[[1.25,2.48]],"id":57087188},{"atl":[[9.4,2]],"id":57087188},{"atb":[[1.07,15.05]],"id":55302014},{"atl":[[7.6,2]],"id":55302014}],"con":true,"img":false}]}
{"op":"mcm","clk":"11540632577","pt":1719496680523,"mc":[{"id":"1.230178311","rc":[{"atb":[[1.66,1]],"id":57087188},{"atl":[[4,1]],"id":57087188},{"atb":[[1.59,1]],"id":65436514},{"atl":[[4.1,1]],"id":65436514},{"atb":[[3.25,1]],"id":69142441},{"atl":[[11.5,1]],"id":69142441},{"atb":[[1.51,1]],"id":55302014},{"atl":[[3.65,1]],"id":55302014},{"atb":[[1.92,1]],"id":68392143},{"atl":[[5,1]],"id":68392143},{"atb":[[2.46,1]],"id":57088863},{"atl":[[6.8,1]],"id":57088863}],"con":true,"img":false}]}
{"op":"mcm","clk":"11540632801","pt":1719496683357,"mc":[{"id":"1.230178311","rc":[{"atb":[[1.69,2.11]],"id":68392143}],"con":true,"img":false}]}
{"op":"mcm","clk":"11540632906","pt":1719496684621,"mc":[{"id":"1.230178311","rc":[{"atb":[[1.2,0.25]],"id":68392143}],"con":true,"img":false}]}
{"op":"mcm","clk":"11540633149","pt":1719496687234,"mc":[{"id":"1.230178311","rc":[{"atb":[[1.18,0]],"id":68392143}],"con":true,"img":false}]}
{"op":"mcm","clk":"11540633200","pt":1719496687757,"mc":[{"id":"1.230178311","rc":[{"atl":[[1000,1.87]],"id":57087188}],"con":true,"img":false}]}
{"op":"mcm","clk":"11540633203","pt":1719496687860,"mc":[{"id":"1.230178311","rc":[{"atb":[[1.01,1.7]],"id":57087188},{"atb":[[1.08,3.97]],"id":55302014},{"atl":[[1000,1.87]],"id":55302014},{"atb":[[1.01,1.7]],"id":57088863},{"atl":[[1000,1.87]],"id":57088863}],"con":true,"img":false}]}
{"op":"mcm","clk":"11540633217","pt":1719496688068,"mc":[{"id":"1.230178311","rc":[{"atb":[[1.01,1.22]],"id":57087188},{"atl":[[1000,0.2]],"id":57087188},{"atl":[[1000,0.21]],"id":55302014},{"atb":[[1.01,0.41]],"id":57088863},{"atl":[[1000,0.18]],"id":57088863}],"con":true,"img":false}]}
{"op":"mcm","clk":"11540633242","pt":1719496688335,"mc":[{"id":"1.230178311","rc":[{"atb":[[1.01,0]],"id":57087188},{"atl":[[1000,0.16]],"id":57087188},{"atl":[[1000,0.16]],"id":55302014},{"atb":[[1.01,0]],"id":57088863},{"atl":[[1000,0.16]],"id":57088863}],"con":true,"img":false}]}
{"op":"mcm","clk":"11540633252","pt":1719496688440,"mc":[{"id":"1.230178311","rc":[{"atb":[[1.26,1.22]],"id":57087188},{"atl":[[9.2,0.03]],"id":57087188},{"atl":[[7.4,0.04]],"id":55302014},{"atb":[[1.77,0.41]],"id":57088863},{"atl":[[30,0.01]],"id":57088863}],"con":true,"img":false}]}
{"op":"mcm","clk":"11540634370","pt":1719496702935,"mc":[{"id":"1.230178311","rc":[{"atb":[[1.21,0]],"id":68392143}],"con":true,"img":false}]}
{"op":"mcm","clk":"11540634473","pt":1719496704290,"mc":[{"id":"1.230178311","rc":[{"atb":[[1.25,0],[1.34,2]],"id":57087188},{"atl":[[4,0],[3.85,1]],"id":57087188},{"atb":[[1.54,7.9],[1.51,0]],"id":65436514},{"atl":[[4,1],[3.6,1],[4.1,0]],"id":65436514},{"atb":[[2.32,2.48],[3.25,0],[3.3,1],[2.14,0]],"id":69142441},{"atl":[[3.35,1],[3.65,0]],"id":55302014},{"atb":[[1.92,0],[2.02,1],[1.66,0],[1.75,2.12]],"id":68392143},{"atb":[[1.86,2],[1.76,0]],"id":57088863},{"atl":[[6.8,0],[6.6,1]],"id":57088863}],"con":true,"img":false}]}
{"op":"mcm","clk":"11540634482","pt":1719496704346,"mc":[{"id":"1.230178311","rc":[{"atl":[[8.8,2],[9.4,0]],"id":57087188},{"atl":[[9.6,0],[9.4,2]],"id":65436514},{"atl":[[7.6,0],[7,2]],"id":55302014},{"atl":[[32,0],[28,2]],"id":57088863}],"con":true,"img":false}]}
{"op":"mcm","clk":"11540634492","pt":1719496704449,"mc":[{"id":"1.230178311","rc":[{"atl":[[4,0]],"id":65436514}],"con":true,"img":false}]}
{"op":"mcm","clk":"11540634852","pt":1719496708659,"mc":[{"id":"1.230178311","rc":[{"atb":[[1.27,2]],"id":57087188}],"con":true,"img":false}]}
{"op":"mcm","clk":"11540634882","pt":1719496708975,"mc":[{"id":"1.230178311","rc":[{"atb":[[1.02,24.66]],"id":57088863}],"con":true,"img":false}]}
{"op":"mcm","clk":"11540634913","pt":1719496709286,"mc":[{"id":"1.230178311","rc":[{"atb":[[1.09,2]],"id":55302014}],"con":true,"img":false}]}
{"op":"mcm","clk":"11540634930","pt":1719496709443,"mc":[{"id":"1.230178311","rc":[{"atb":[[1.52,2]],"id":65436514}],"con":true,"img":false}]}
{"op":"mcm","clk":"11540634952","pt":1719496709759,"mc":[{"id":"1.230178311","rc":[{"atb":[[1.02,2]],"id":68392143}],"con":true,"img":false}]}
{"op":"mcm","clk":"11540634987","pt":1719496710274,"mc":[{"id":"1.230178311","rc":[{"atb":[[1.02,24.66]],"id":69142441}],"con":true,"img":false}]}
{"op":"mcm","clk":"11540635108","pt":1719496711785,"mc":[{"id":"1.230178311","rc":[{"atb":[[1.55,2.11],[1.42,0]],"id":65436514}],"con":true,"img":false}]}
{"op":"mcm","clk":"11540635116","pt":1719496711853,"mc":[{"id":"1.230178311","rc":[{"atb":[[1.27,0]],"id":57087188}],"con":true,"img":false}]}
{"op":"mcm","clk":"11540635123","pt":1719496711944,"mc":[{"id":"1.230178311","rc":[{"atb":[[1.35,2]],"id":57087188}],"con":true,"img":false}]}
{"op":"mcm","clk":"11540635142","pt":1719496712257,"mc":[{"id":"1.230178311","rc":[{"atb":[[1.52,0]],"id":65436514}],"con":true,"img":false}]}
{"op":"mcm","clk":"11540635154","pt":1719496712365,"mc":[{"id":"1.230178311","rc":[{"atb":[[1.55,4.11]],"id":65436514}],"con":true,"img":false}]}
{"op":"mcm","clk":"11540635285","pt":1719496713869,"mc":[{"id":"1.230178311","rc":[{"atb":[[1.35,0]],"id":57087188}],"con":true,"img":false}]}
{"op":"mcm","clk":"11540635291","pt":1719496713973,"mc":[{"id":"1.230178311","rc":[{"atb":[[1.02,2]],"id":57087188}],"con":true,"img":false}]}
{"op":"mcm","clk":"11540635306","pt":1719496714184,"mc":[{"id":"1.230178311","rc":[{"atb":[[1.56,7.9],[1.54,0]],"id":65436514},{"atb":[[1.91,2]],"id":57088863}],"con":true,"img":false}]}
{"op":"mcm","clk":"11540635315","pt":1719496714284,"mc":[{"id":"1.230178311","rc":[{"atb":[[1.86,0]],"id":57088863}],"con":true,"img":false}]}
{"op":"mcm","clk":"11540635490","pt":1719496716153,"mc":[{"id":"1.230178311","rc":[{"atb":[[1.55,2.11]],"id":65436514}],"con":true,"img":false}]}
{"op":"mcm","clk":"11540635501","pt":1719496716261,"mc":[{"id":"1.230178311","rc":[{"atb":[[1.57,2]],"id":65436514}],"con":true,"img":false}]}
{"op":"mcm","clk":"11540635911","pt":1719496721800,"mc":[{"id":"1.230178311","rc":[{"atb":[[1.19,0]],"id":68392143}],"con":true,"img":false}]}
{"op":"mcm","clk":"11540636280","pt":1719496726106,"mc":[{"id":"1.230178311","rc":[{"atb":[[1.26,0]],"id":57087188},{"atl":[[9.2,0]],"id":57087188},{"atb":[[1.08,0]],"id":55302014},{"atl":[[7.4,0]],"id":55302014},{"atb":[[1.77,0]],"id":57088863},{"atl":[[30,0]],"id":57088863}],"con":true,"img":false}]}
{"op":"mcm","clk":"11540636391","pt":1719496727402,"mc":[{"id":"1.230178311","rc":[{"atb":[[1.09,0]],"id":55302014}],"con":true,"img":false}]}
{"op":"mcm","clk":"11540636399","pt":1719496727505,"mc":[{"id":"1.230178311","rc":[{"atb":[[1.08,2]],"id":55302014}],"con":true,"img":false}]}
{"op":"mcm","clk":"11540639654","pt":1719496768518,"mc":[{"id":"1.230178311","rc":[{"spn":2.75,"spf":"NaN","id":57087188},{"spn":2.59,"spf":"NaN","id":65436514},{"spn":7.4,"spf":"NaN","id":69142441},{"spn":2.43,"spf":"NaN","id":55302014},{"atb":[[1.15,3.75]],"id":68392143},{"spn":3.51,"spf":"NaN","id":68392143},{"spn":4.53,"spf":"NaN","id":57088863}],"con":true,"img":false}]}
{"op":"mcm","clk":"11540639661","pt":1719496768632,"mc":[{"id":"1.230178311","rc":[{"atb":[[1.15,0]],"id":68392143}],"con":true,"img":false}]}
{"op":"mcm","clk":"11540640735","pt":1719496782234,"mc":[{"id":"1.230178311","rc":[{"atb":[[3.25,1]],"id":69142441},{"atb":[[1.92,1],[2.02,0]],"id":68392143}],"con":true,"img":false}]}
{"op":"mcm","clk":"11540640741","pt":1719496782341,"mc":[{"id":"1.230178311","rc":[{"atb":[[3.3,0]],"id":69142441},{"atb":[[1.79,2.12]],"id":68392143}],"con":true,"img":false}]}
{"op":"mcm","clk":"11540640748","pt":1719496782441,"mc":[{"id":"1.230178311","rc":[{"atb":[[1.75,0]],"id":68392143}],"con":true,"img":false}]}
{"op":"mcm","clk":"11540640851","pt":1719496783651,"mc":[{"id":"1.230178311","rc":[{"atl":[[4,1],[3.85,0]],"id":57087188},{"atl":[[4,1],[3.6,0]],"id":65436514},{"atl":[[3.35,0],[3.65,1]],"id":55302014}],"con":true,"img":false}]}
{"op":"mcm","clk":"11540641669","pt":1719496792950,"mc":[{"id":"1.230178311","rc":[{"atb":[[1.48,0]],"id":65436514}],"con":true,"img":false}]}
{"op":"mcm","clk":"11540641809","pt":1719496795071,"mc":[{"id":"1.230178311","rc":[{"atb":[[1.5,0]],"id":65436514}],"con":true,"img":false}]}
{"op":"mcm","clk":"11540642433","pt":1719496802696,"mc":[{"id":"1.230178311","rc":[{"atb":[[1.01,1.7]],"id":57087188},{"atl":[[1000,1.87]],"id":57087188},{"atl":[[1000,1.87]],"id":55302014},{"atl":[[1000,1.87]],"id":57088863}],"con":true,"img":false}]}
{"op":"mcm","clk":"11540642440","pt":1719496802785,"mc":[{"id":"1.230178311","rc":[{"atb":[[1.09,3.4]],"id":55302014},{"atb":[[1.01,1.7]],"id":57088863}],"con":true,"img":false}]}
{"op":"mcm","clk":"11540642450","pt":1719496802889,"mc":[{"id":"1.230178311","rc":[{"atb":[[1.01,0.87]],"id":57087188},{"atl":[[1000,0.21]],"id":57087188},{"atl":[[1000,0.22]],"id":55302014},{"atl":[[1000,0.18]],"id":57088863}],"con":true,"img":false}]}
{"op":"mcm","clk":"11540642455","pt":1719496802943,"mc":[{"id":"1.230178311","rc":[{"atb":[[1.01,0.33]],"id":57088863}],"con":true,"img":false}]}
{"op":"mcm","clk":"11540642466","pt":1719496803057,"mc":[{"id":"1.230178311","rc":[{"atb":[[1.01,0]],"id":57087188},{"atl":[[1000,0.16]],"id":57087188},{"atl":[[1000,0.16]],"id":55302014},{"atl":[[1000,0.16]],"id":57088863}],"con":true,"img":false}]}
{"op":"mcm","clk":"11540642471","pt":1719496803162,"mc":[{"id":"1.230178311","rc":[{"atb":[[1.35,0.87]],"id":57087188},{"atl":[[8.6,0.04]],"id":57087188},{"atl":[[6.8,0.05]],"id":55302014},{"atb":[[1.01,0]],"id":57088863},{"atl":[[27,0.01]],"id":57088863}],"con":true,"img":false}]}
{"op":"mcm","clk":"11540642479","pt":1719496803272,"mc":[{"id":"1.230178311","rc":[{"atb":[[1.92,0.33]],"id":57088863}],"con":true,"img":false}]}
{"op":"mcm","clk":"11540642895","pt":1719496808269,"mc":[{"id":"1.230178311","rc":[{"atb":[[1.03,15.1],[1.35,0.87]],"id":57087188},{"atl":[[960,1.11]],"id":57087188},{"atb":[[1.01,45.3],[1.55,2.11]],"id":65436514},{"atl":[[970,1.73]],"id":65436514},{"atb":[[1.02,24.65]],"id":69142441},{"atl":[[980,1.58]],"id":69142441},{"atb":[[1.02,22.65],[1.09,3.4],[1.08,0]],"id":55302014},{"atl":[[990,1.5]],"id":55302014},{"atb":[[1.03,15.1],[1.69,2.11]],"id":68392143},{"atl":[[960,0.87]],"id":68392143},{"atb":[[1.92,0.33],[1.02,24.65]],"id":57088863},{"atl":[[970,0.87]],"id":57088863}],"con":true,"img":false}]}
{"op":"mcm","clk":"11540642908","pt":1719496808376,"mc":[{"id":"1.230178311","rc":[{"atb":[[1.1,2]],"id":55302014}],"con":true,"img":false}]}
{"op":"mcm","clk":"11540645034","pt":1719496833631,"mc":[{"id":"1.230178311","rc":[{"atl":[[4,0],[3.95,1]],"id":57087188},{"spn":2.8,"spf":"NaN","id":57087188},{"spn":2.79,"spf":"NaN","id":65436514},{"atb":[[3.45,1],[3.25,0]],"id":69142441},{"spn":7.47,"spf":"NaN","id":69142441},{"atl":[[3.6,1],[3.65,0]],"id":55302014},{"spn":2.55,"spf":"NaN","id":55302014},{"spn":3.46,"spf":"NaN","id":68392143}],"con":true,"img":false}]}
{"op":"mcm","clk":"11540645058","pt":1719496833808,"mc":[{"id":"1.230178311","rc":[{"atb":[[1.44,1],[1.51,0]],"id":55302014},{"atb":[[1.92,0],[2.02,1]],"id":68392143}],"con":true,"img":false}]}
{"op":"mcm","clk":"11540645068","pt":1719496833904,"mc":[{"id":"1.230178311","rc":[{"atl":[[3.95,0],[4.1,1]],"id":57087188},{"atl":[[3.6,0],[3.3,1]],"id":55302014},{"atl":[[6.6,0],[7,1]],"id":57088863}],"con":true,"img":false}]}
{"op":"mcm","clk":"11540645077","pt":1719496834015,"mc":[{"id":"1.230178311","rc":[{"atl":[[4.1,3],[8.8,0]],"id":57087188},{"atb":[[1.11,3.41],[1.07,2.48]],"id":55302014},{"atl":[[6.8,2.05],[7,0]],"id":55302014},{"atb":[[1.8,2.12],[1.79,0]],"id":68392143}],"con":true,"img":false}]}
{"op":"mcm","clk":"11540645130","pt":1719496834628,"mc":[{"id":"1.230178311","rc":[{"atl":[[4,0.84]],"id":57087188},{"atb":[[1.1,0]],"id":55302014}],"con":true,"img":false}]}
{"op":"mcm","clk":"11540645141","pt":1719496834720,"mc":[{"id":"1.230178311","rc":[{"atb":[[1.12,2]],"id":55302014}],"con":true,"img":false}]}
{"op":"mcm","clk":"11540645168","pt":1719496834989,"mc":[{"id":"1.230178311","rc":[{"atb":[[1.73,3.75]],"id":68392143},{"atb":[[1.84,2.5]],"id":57088863}],"con":true,"img":false}]}
{"op":"mcm","clk":"11540645197","pt":1719496835304,"mc":[{"id":"1.230178311","rc":[{"atb":[[1.73,0]],"id":68392143},{"atb":[[1.84,0]],"id":57088863}],"con":true,"img":false}]}
{"op":"mcm","clk":"11540645504","pt":1719496839120,"mc":[{"id":"1.230178311","rc":[{"atl":[[8.6,3.89],[4.1,1]],"id":57087188}],"con":true,"img":false}]}
{"op":"mcm","clk":"11540645643","pt":1719496840932,"mc":[{"id":"1.230178311","rc":[{"atb":[[1.35,0]],"id":57087188},{"atl":[[8.6,3.85]],"id":57087188},{"atb":[[1.09,0]],"id":55302014},{"atl":[[6.8,2]],"id":55302014},{"atb":[[1.92,0]],"id":57088863},{"atl":[[27,0]],"id":57088863}],"con":true,"img":false}]}
{"op":"mcm","clk":"11540645653","pt":1719496841035,"mc":[{"id":"1.230178311","rc":[{"atb":[[3.45,0],[3.25,1]],"id":69142441},{"atb":[[1.44,0],[1.51,1]],"id":55302014},{"atl":[[3.35,1],[3.3,0]],"id":55302014},{"atb":[[1.92,1],[2.02,0]],"id":68392143}],"con":true,"img":false}]}
{"op":"mcm","clk":"11540645665","pt":1719496841140,"mc":[{"id":"1.230178311","rc":[{"atl":[[4,1.84],[4.1,0]],"id":57087188},{"atb":[[2.4,2.48],[2.32,0]],"id":69142441},{"atl":[[6.8,0],[3.65,1]],"id":55302014},{"atb":[[1.8,0],[1.79,3.12]],"id":68392143},{"atl":[[7,0],[6.6,1]],"id":57088863}],"con":true,"img":false}]}
{"op":"mcm","clk":"11540645675","pt":1719496841208,"mc":[{"id":"1.230178311","rc":[{"atl":[[3.35,0],[7,3]],"id":55302014}],"con":true,"img":false}]}
{"op":"mcm","clk":"11540645687","pt":1719496841309,"mc":[{"id":"1.230178311","rc":[{"atl":[[3.65,0]],"id":55302014}],"con":true,"img":false}]}
{"op":"mcm","clk":"11540645710","pt":1719496841526,"mc":[{"id":"1.230178311","rc":[{"atl":[[6.8,0.84]],"id":55302014}],"con":true,"img":false}]}
{"op":"mcm","clk":"11540645897","pt":1719496843838,"mc":[{"id":"1.230178311","rc":[{"atl":[[3.95,1]],"id":57087188},{"atb":[[3.45,1]],"id":69142441},{"atl":[[3.6,1]],"id":55302014},{"atl":[[6.8,1],[6.6,0]],"id":57088863}],"con":true,"img":false}]}
{"op":"mcm","clk":"11540645909","pt":1719496843943,"mc":[{"id":"1.230178311","rc":[{"atl":[[4,0.84]],"id":57087188},{"atb":[[3.25,0]],"id":69142441},{"atl":[[3.65,1]],"id":55302014}],"con":true,"img":false}]}
{"op":"mcm","clk":"11540645920","pt":1719496844007,"mc":[{"id":"1.230178311","rc":[{"atb":[[1.92,0],[2.02,1]],"id":68392143}],"con":true,"img":false}]}
{"op":"mcm","clk":"11540645930","pt":1719496844106,"mc":[{"id":"1.230178311","rc":[{"atl":[[4,0],[4.2,1]],"id":65436514},{"atb":[[3.45,0],[3.25,1]],"id":69142441},{"atb":[[1.41,1],[1.51,0]],"id":55302014},{"atl":[[3.6,0],[3.3,1],[3.65,0]],"id":55302014}],"con":true,"img":false}]}
{"op":"mcm","clk":"11540645938","pt":1719496844211,"mc":[{"id":"1.230178311","rc":[{"atl":[[3.95,0],[4.1,1]],"id":57087188},{"atb":[[1.2,2.25],[1.11,0]],"id":55302014},{"atb":[[1.92,1],[2.02,0]],"id":68392143},{"atl":[[6.8,0],[7,1]],"id":57088863}],"con":true,"img":false}]}
{"op":"mcm","clk":"11540645946","pt":1719496844314,"mc":[{"id":"1.230178311","rc":[{"atl":[[4.2,0]],"id":65436514},{"atb":[[3.45,1],[3.25,0]],"id":69142441}],"con":true,"img":false}]}
{"op":"mcm","clk":"11540645956","pt":1719496844424,"mc":[{"id":"1.230178311","rc":[{"atl":[[9.6,4],[4.2,1],[9.4,0]],"id":65436514},{"atb":[[1.92,0],[2.02,1]],"id":68392143}],"con":true,"img":false}]}
{"op":"mcm","clk":"11540645973","pt":1719496844627,"mc":[{"id":"1.230178311","rc":[{"atl":[[9.2,0.84]],"id":65436514}],"con":true,"img":false}]}
{"op":"mcm","clk":"11540646001","pt":1719496845033,"mc":[{"id":"1.230178311","rc":[{"atl":[[9.2,0]],"id":65436514},{"atb":[[1.12,0]],"id":55302014}],"con":true,"img":false}]}
{"op":"mcm","clk":"11540646013","pt":1719496845134,"mc":[{"id":"1.230178311","rc":[{"atb":[[1.21,2]],"id":55302014}],"con":true,"img":false}]}
{"op":"mcm","clk":"11540646152","pt":1719496846744,"mc":[{"id":"1.230178311","rc":[{"atl":[[4,1.84],[4.1,0]],"id":57087188},{"atl":[[4,1],[4.2,0]],"id":65436514},{"atb":[[3.45,0],[3.25,1]],"id":69142441},{"atb":[[1.41,0],[1.51,1]],"id":55302014},{"atl":[[3.35,1],[3.3,0],[3.65,1]],"id":55302014},{"atb":[[1.92,1],[2.02,0]],"id":68392143},{"atl":[[6.6,1]],"id":57088863}],"con":true,"img":false}]}
{"op":"mcm","clk":"11540646166","pt":1719496846809,"mc":[{"id":"1.230178311","rc":[{"atl":[[9.6,0],[9.4,2]],"id":65436514},{"atl":[[7.6,2],[7,0],[28,0]],"id":57088863}],"con":true,"img":false}]}
{"op":"mcm","clk":"11540646172","pt":1719496846910,"mc":[{"id":"1.230178311","rc":[{"atl":[[3.35,0],[3.65,0]],"id":55302014}],"con":true,"img":false}]}
{"op":"mcm","clk":"11540646190","pt":1719496847114,"mc":[{"id":"1.230178311","rc":[{"atl":[[6.8,0]],"id":55302014}],"con":true,"img":false}]}
{"op":"mcm","clk":"11540646303","pt":1719496848513,"mc":[{"id":"1.230178311","rc":[{"atl":[[6.8,0.84]],"id":55302014}],"con":true,"img":false}]}
{"op":"mcm","clk":"11540646716","pt":1719496853211,"mc":[{"id":"1.230178311","rc":[{"atl":[[3.65,1]],"id":55302014}],"con":true,"img":false}]}
{"op":"mcm","clk":"11540647329","pt":1719496860269,"mc":[{"id":"1.230178311","rc":[{"atb":[[1.92,2.5],[1.84,10],[1.88,5],[1.66,3.14]],"id":57087188},{"atl":[[4.6,2.5],[5,5],[3.95,2.14],[5.4,10]],"id":57087188},{"atb":[[1.99,5],[1.6,2.25],[2.06,2.5],[1.95,10]],"id":65436514},{"atl":[[4.5,2.5],[3.95,2.25],[5.3,10],[4.9,5]],"id":65436514},{"atb":[[3.6,2.5],[3.2,10],[3.4,5],[3.3,1.5]],"id":69142441},{"atl":[[16,10],[11,1.5],[12,2.5],[14,5]],"id":69142441},{"atb":[[1.46,10],[1.54,2.5],[1.5,5],[1.51,3.25]],"id":55302014},{"atl":[[3.6,2.25],[3.7,2.5],[3.9,5],[4.2,10]],"id":55302014},{"atb":[[2.3,5],[1.98,2.25],[2.22,10],[2.38,2.5]],"id":68392143},{"atl":[[6.2,2.5],[4.9,2.25],[7,5],[7.8,10]],"id":68392143},{"atb":[[2.6,10],[2.68,5],[2.48,1.5],[2.76,2.5]],"id":57088863},{"atl":[[8.6,10],[6.4,1.5],[7,2.5],[7.8,5]],"id":57088863}],"con":true,"img":false}]}
{"op":"mcm","clk":"11540647338","pt":1719496860332,"mc":[{"id":"1.230178311","rc":[{"atb":[[1.77,10],[1.34,0]],"id":57087188},{"atl":[[8.6,0],[3.95,4.28]],"id":57087188},{"atb":[[1.58,2.12]],"id":65436514},{"atl":[[4.4,5]],"id":65436514},{"atb":[[3.5,5]],"id":69142441},{"atl":[[14.5,4]],"id":69142441},{"atb":[[1.2,0.25],[1.46,16.5]],"id":55302014},{"atl":[[7,0],[3.65,5.5]],"id":55302014},{"atb":[[1.79,0],[2.38,7.5]],"id":68392143},{"atl":[[6.2,7.5],[23,0]],"id":68392143},{"atb":[[1.91,0],[2.6,12]],"id":57088863}],"con":true,"img":false}]}
{"op":"mcm","clk":"11540647348","pt":1719496860437,"mc":[{"id":"1.230178311","rc":[{"atl":[[4.6,7.5],[3.95,2.14]],"id":57087188},{"atb":[[1.94,10],[1.56,0]],"id":65436514},{"atl":[[4.5,7.5],[9.4,0]],"id":65436514},{"atb":[[2.4,0],[3.5,0],[3.3,9]],"id":69142441},{"atl":[[120,0]],"id":69142441},{"atl":[[3.7,7.5],[3.65,1]],"id":55302014},{"atb":[[2.22,17.5],[2.38,2.5]],"id":68392143}],"con":true,"img":false}]}
{"op":"mcm","clk":"11540647361","pt":1719496860544,"mc":[{"id":"1.230178311","rc":[{"atl":[[3.9,0.84]],"id":57087188},{"atb":[[1.58,0]],"id":65436514},{"atl":[[4.4,0],[3.9,0.84]],"id":65436514},{"atb":[[3.4,12.5],[3.3,1.5]],"id":69142441},{"atl":[[6.8,0],[3.55,0.84]],"id":55302014},{"atl":[[4.8,0.84]],"id":68392143}],"con":true,"img":false}]}
{"op":"mcm","clk":"11540647372","pt":1719496860642,"mc":[{"id":"1.230178311","rc":[{"atb":[[3.4,5],[3.3,10.5]],"id":69142441}],"con":true,"img":false}]}
{"op":"mcm","clk":"11540647386","pt":1719496860748,"mc":[{"id":"1.230178311","rc":[{"atl":[[4,6.84],[4.6,2.5]],"id":57087188},{"atl":[[4,6],[4.5,2.5]],"id":65436514}],"con":true,"img":false}]}
{"op":"mcm","clk":"11540647458","pt":1719496861632,"mc":[{"id":"1.230178311","rc":[{"atb":[[1.02,0]],"id":57087188}],"con":true,"img":false}]}
{"op":"mcm","clk":"11540647464","pt":1719496861735,"mc":[{"id":"1.230178311","rc":[{"atb":[[1.93,2]],"id":57087188}],"con":true,"img":false}]}
{"op":"mcm","clk":"11540647498","pt":1719496862146,"mc":[{"id":"1.230178311","rc":[{"atb":[[1.21,0]],"id":55302014}],"con":true,"img":false}]}
{"op":"mcm","clk":"11540647505","pt":1719496862251,"mc":[{"id":"1.230178311","rc":[{"atb":[[1.87,2.11]],"id":57087188},{"atb":[[3.25,0]],"id":69142441},{"atb":[[1.55,2],[1.53,2.11],[1.48,1]],"id":55302014},{"atl":[[5.4,7.5]],"id":68392143},{"atl":[[7,5]],"id":57088863}],"con":true,"img":false}]}
{"op":"mcm","clk":"11540647516","pt":1719496862354,"mc":[{"id":"1.230178311","rc":[{"atb":[[3.3,11.5]],"id":69142441},{"atl":[[12.5,5],[14.5,0]],"id":69142441},{"atb":[[1.51,2.25]],"id":55302014},{"atb":[[1.92,0],[2.02,1]],"id":68392143},{"atl":[[6.2,2.5]],"id":68392143},{"atl":[[7.6,0]],"id":57088863}],"con":true,"img":false}]}
{"op":"mcm","clk":"11540647524","pt":1719496862462,"mc":[{"id":"1.230178311","rc":[{"atl":[[4,5.84],[3.85,1]],"id":57087188},{"atl":[[4,5],[3.6,1]],"id":65436514},{"atl":[[3.35,1],[3.65,0]],"id":55302014},{"atl":[[5,0],[5.4,8.5]],"id":68392143}],"con":true,"img":false}]}
{"op":"mcm","clk":"11540647531","pt":1719496862558,"mc":[{"id":"1.230178311","rc":[{"atl":[[3.6,4.5],[3.7,2.5]],"id":55302014}],"con":true,"img":false}]}
{"op":"mcm","clk":"11540647539","pt":1719496862670,"mc":[{"id":"1.230178311","rc":[{"atb":[[1.57,0]],"id":65436514},{"atb":[[1.46,10],[1.42,4.5]],"id":55302014}],"con":true,"img":false}]}
{"op":"mcm","clk":"11540647546","pt":1719496862766,"mc":[{"id":"1.230178311","rc":[{"atb":[[2.08,2]],"id":65436514}],"con":true,"img":false}]}
{"op":"mcm","clk":"11540647573","pt":1719496863040,"mc":[{"id":"1.230178311","rc":[{"atb":[[1.02,0]],"id":68392143}],"con":true,"img":false}]}
{"op":"mcm","clk":"11540647583","pt":1719496863140,"mc":[{"id":"1.230178311","rc":[{"atb":[[2.4,2]],"id":68392143}],"con":true,"img":false}]}
{"op":"mcm","clk":"11540647607","pt":1719496863350,"mc":[{"id":"1.230178311","rc":[{"atb":[[2.4,4.5],[2.22,10]],"id":68392143}],"con":true,"img":false}]}
{"op":"mcm","clk":"11540647623","pt":1719496863552,"mc":[{"id":"1.230178311","rc":[{"atb":[[1.02,22.65]],"id":69142441},{"atb":[[2.4,2],[2.3,10]],"id":68392143}],"con":true,"img":false}]}
{"op":"mcm","clk":"11540647634","pt":1719496863656,"mc":[{"id":"1.230178311","rc":[{"atb":[[3.65,2]],"id":69142441}],"con":true,"img":false}]}
{"op":"mcm","clk":"11540647652","pt":1719496863854,"mc":[{"id":"1.230178311","rc":[{"atb":[[3.45,10],[3.3,2.5]],"id":69142441}],"con":true,"img":false}]}
{"op":"mcm","clk":"11540647713","pt":1719496864652,"mc":[{"id":"1.230178311","rc":[{"atl":[[3.85,0],[3.9,1.84]],"id":57087188},{"atb":[[1.48,0]],"id":55302014},{"atl":[[3.35,0],[3.3,1]],"id":55302014}],"con":true,"img":false}]}
{"op":"mcm","clk":"11540647723","pt":1719496864747,"mc":[{"id":"1.230178311","rc":[{"atl":[[4,0.84],[3.9,3.98]],"id":57087188}],"con":true,"img":false}]}
{"op":"mcm","clk":"11540647742","pt":1719496865057,"mc":[{"id":"1.230178311","rc":[{"atl":[[4,0]],"id":57087188}],"con":true,"img":false}]}
{"op":"mcm","clk":"11540647806","pt":1719496865833,"mc":[{"id":"1.230178311","rc":[{"atl":[[4.1,1],[3.9,2.98]],"id":57087188},{"atl":[[3.6,0],[4.2,1]],"id":65436514},{"atl":[[11.5,0],[12,3.5]],"id":69142441},{"atb":[[1.48,1]],"id":55302014},{"atl":[[3.35,1],[3.3,0]],"id":55302014},{"atl":[[6.8,1],[6.6,0]],"id":57088863}],"con":true,"img":false}]}
{"op":"mcm","clk":"11540647817","pt":1719496866001,"mc":[{"id":"1.230178311","rc":[{"atl":[[3.85,1],[4.1,0]],"id":57087188},{"atl":[[3.6,1],[4.2,0]],"id":65436514},{"atl":[[11,0],[11.5,1]],"id":69142441},{"atl":[[6.4,0],[6.6,1]],"id":57088863}],"con":true,"img":false}]}
{"op":"mcm","clk":"11540647830","pt":1719496866045,"mc":[{"id":"1.230178311","rc":[{"atl":[[12,2.5]],"id":69142441},{"atl":[[6.8,0]],"id":57088863}],"con":true,"img":false}]}
{"op":"mcm","clk":"11540647846","pt":1719496866151,"mc":[{"id":"1.230178311","rc":[{"atl":[[11.5,5.5]],"id":69142441},{"atl":[[6.6,6.62]],"id":57088863}],"con":true,"img":false}]}
{"op":"mcm","clk":"11540647891","pt":1719496866559,"mc":[{"id":"1.230178311","rc":[{"atl":[[11,0.84]],"id":69142441},{"atl":[[6.4,0.84]],"id":57088863}],"con":true,"img":false}]}
{"op":"mcm","clk":"11540647968","pt":1719496867351,"mc":[{"id":"1.230178311","rc":[{"atl":[[6,5],[5.4,1]],"id":68392143}],"con":true,"img":false}]}
{"op":"mcm","clk":"11540648169","pt":1719496869366,"mc":[{"id":"1.230178311","rc":[{"atl":[[3.85,0],[3.9,3.98]],"id":57087188},{"atl":[[3.6,0],[3.65,1]],"id":65436514},{"atb":[[1.48,0]],"id":55302014},{"atl":[[3.35,0],[3.3,1]],"id":55302014}],"con":true,"img":false}]}
{"op":"mcm","clk":"11540648178","pt":1719496869442,"mc":[{"id":"1.230178311","rc":[{"atl":[[3.9,3.09]],"id":65436514}],"con":true,"img":false}]}
{"op":"mcm","clk":"11540648186","pt":1719496869534,"mc":[{"id":"1.230178311","rc":[{"atb":[[1.96,10],[1.94,0]],"id":65436514},{"atl":[[4,0]],"id":65436514},{"atl":[[3.25,1],[3.3,0]],"id":55302014}],"con":true,"img":false}]}
{"op":"mcm","clk":"11540648209","pt":1719496869845,"mc":[{"id":"1.230178311","rc":[{"atl":[[4.6,8.63],[3.9,1.84]],"id":57087188}],"con":true,"img":false}]}
{"op":"mcm","clk":"11540648368","pt":1719496871836,"mc":[{"id":"1.230178311","rc":[{"atb":[[2.4,4.5],[2.3,5]],"id":68392143}],"con":true,"img":false}]}
{"op":"mcm","clk":"11540648566","pt":1719496874639,"mc":[{"id":"1.230178311","rc":[{"atl":[[3.95,6.35],[3.9,0.84]],"id":65436514}],"con":true,"img":false}]}
{"op":"mcm","clk":"11540648571","pt":1719496874738,"mc":[{"id":"1.230178311","rc":[{"atb":[[1.49,11.28]],"id":55302014}],"con":true,"img":false}]}
{"op":"mcm","clk":"11540648591","pt":1719496874975,"mc":[{"id":"1.230178311","rc":[{"atl":[[3.95,3.14],[3.9,0.84]],"id":57087188},{"atb":[[3.45,11],[3.3,1.5]],"id":69142441},{"atl":[[11.5,4.5],[12,3.5]],"id":69142441},{"atl":[[3.2,1],[3.25,0]],"id":55302014},{"atl":[[5.5,1],[5.4,0]],"id":68392143},{"atl":[[6.8,1],[6.6,5.62]],"id":57088863}],"con":true,"img":false}]}
{"op":"mcm","clk":"11540648600","pt":1719496875079,"mc":[{"id":"1.230178311","rc":[{"atl":[[3.2,0],[3.1,1]],"id":55302014}],"con":true,"img":false}]}
{"op":"mcm","clk":"11540648778","pt":1719496877283,"mc":[{"id":"1.230178311","rc":[{"atl":[[3.95,2.14],[4.2,1]],"id":57087188},{"atl":[[4.3,1],[3.65,0]],"id":65436514},{"atl":[[12,2.5],[12.5,6]],"id":69142441},{"atl":[[5.5,0],[5.2,1]],"id":68392143},{"atl":[[6.8,0],[7,6]],"id":57088863}],"con":true,"img":false}]}
{"op":"mcm","clk":"11540648794","pt":1719496877379,"mc":[{"id":"1.230178311","rc":[{"atl":[[4.6,2.5],[4.2,9.63]],"id":57087188},{"atl":[[4.3,8.2],[3.95,2.25]],"id":65436514}],"con":true,"img":false}]}
{"op":"mcm","clk":"11540648831","pt":1719496877794,"mc":[{"id":"1.230178311","rc":[{"atl":[[3.9,4.32]],"id":57087188},{"atb":[[2.08,5.56]],"id":65436514},{"atl":[[4.2,3.56]],"id":65436514},{"atb":[[3.7,3.75]],"id":69142441},{"atl":[[11,4.59]],"id":69142441},{"atb":[[1.55,5.09]],"id":55302014},{"atl":[[3.05,3.09]],"id":55302014},{"atb":[[2.42,3.56]],"id":68392143},{"atb":[[2.84,7.97]],"id":57088863},{"atl":[[6.4,8.81]],"id":57088863}],"con":true,"img":false}]}
{"op":"mcm","clk":"11540648841","pt":1719496877895,"mc":[{"id":"1.230178311","rc":[{"atb":[[1.93,5.48]],"id":57087188},{"atl":[[3.95,0]],"id":57087188},{"atb":[[1.6,0]],"id":65436514},{"atl":[[4.2,0]],"id":65436514},{"atb":[[3.3,0]],"id":69142441},{"atl":[[11.5,0]],"id":69142441},{"atb":[[1.51,0]],"id":55302014},{"atl":[[3.6,2.25]],"id":55302014},{"atb":[[1.98,0]],"id":68392143},{"atb":[[2.48,0]],"id":57088863},{"atl":[[6.6,0]],"id":57088863}],"con":true,"img":false}]}
{"op":"mcm","clk":"11540648853","pt":1719496877999,"mc":[{"id":"1.230178311","rc":[{"atb":[[1.66,1]],"id":57087188},{"atl":[[7,3.5],[7.8,19.71]],"id":57088863}],"con":true,"img":false}]}
{"op":"mcm","clk":"11540648867","pt":1719496878103,"mc":[{"id":"1.230178311","rc":[{"atl":[[3,0.84],[3.55,0]],"id":55302014}],"con":true,"img":false}]}
{"op":"mcm","clk":"11540648886","pt":1719496878265,"mc":[{"id":"1.230178311","rc":[{"atl":[[3.6,0],[3.1,4.94]],"id":55302014}],"con":true,"img":false}]}
{"op":"mcm","clk":"11540648894","pt":1719496878371,"mc":[{"id":"1.230178311","rc":[{"atb":[[1.91,2.11],[1.87,0]],"id":57087188},{"atb":[[1.55,0],[2.04,2.11]],"id":65436514}],"con":true,"img":false}]}
{"op":"mcm","clk":"11540648949","pt":1719496879086,"mc":[{"id":"1.230178311","rc":[{"atl":[[4.1,1],[4.2,8.63]],"id":57087188},{"atb":[[1.96,0]],"id":65436514},{"atb":[[3.6,8.25],[3.45,1],[3.3,1]],"id":69142441},{"atl":[[12,3.5],[12.5,5]],"id":69142441},{"atb":[[1.45,10.09],[1.42,0]],"id":55302014},{"atl":[[3.1,3.94],[3.25,1]],"id":55302014},{"atb":[[2.6,10],[2.68,15.47]],"id":57088863}],"con":true,"img":false}]}
{"op":"mcm","clk":"11540648958","pt":1719496879190,"mc":[{"id":"1.230178311","rc":[{"atb":[[2,10]],"id":65436514},{"atb":[[3.45,0]],"id":69142441}],"con":true,"img":false}]}
{"op":"mcm","clk":"11540649055","pt":1719496880286,"mc":[{"id":"1.230178311","rc":[{"atb":[[2.4,2.5]],"id":68392143}],"con":true,"img":false}]}
{"op":"mcm","clk":"11540649065","pt":1719496880388,"mc":[{"id":"1.230178311","rc":[{"atb":[[2.4,0],[2.38,8.56],[2.44,2]],"id":68392143}],"con":true,"img":false}]}
{"op":"mcm","clk":"11540649091","pt":1719496880795,"mc":[{"id":"1.230178311","rc":[{"atb":[[3.65,0]],"id":69142441}],"con":true,"img":false}]}
{"op":"mcm","clk":"11540649096","pt":1719496880898,"mc":[{"id":"1.230178311","rc":[{"atb":[[3.6,2.5],[3.7,0],[3.4,17],[3.75,2]],"id":69142441}],"con":true,"img":false}]}
{"op":"mcm","clk":"11540649101","pt":1719496880998,"mc":[{"id":"1.230178311","rc":[{"atb":[[3.8,4.5]],"id":69142441}],"con":true,"img":false}]}
{"op":"mcm","clk":"11540649210","pt":1719496882397,"mc":[{"id":"1.230178311","rc":[{"atb":[[3.75,0]],"id":69142441}],"con":true,"img":false}]}
{"op":"mcm","clk":"11540649216","pt":1719496882498,"mc":[{"id":"1.230178311","rc":[{"atb":[[3.85,2],[3.8,0]],"id":69142441}],"con":true,"img":false}]}
{"op":"mcm","clk":"11540649224","pt":1719496882601,"mc":[{"id":"1.230178311","rc":[{"atb":[[3.65,6.82]],"id":69142441}],"con":true,"img":false}]}
{"op":"mcm","clk":"11540649355","pt":1719496884312,"mc":[{"id":"1.230178311","rc":[{"atl":[[3.9,5.32]],"id":57087188},{"atl":[[4.3,7.2]],"id":65436514},{"atl":[[11.5,1],[12,2.5]],"id":69142441},{"atl":[[5.4,1]],"id":68392143},{"atl":[[6.6,1]],"id":57088863}],"con":true,"img":false}]}
{"op":"mcm","clk":"11540649364","pt":1719496884376,"mc":[{"id":"1.230178311","rc":[{"atl":[[4.1,0]],"id":57087188},{"atl":[[3.65,1]],"id":65436514},{"atl":[[5.2,0]],"id":68392143},{"atl":[[7,12.5],[7.8,5]],"id":57088863}],"con":true,"img":false}]}
{"op":"mcm","clk":"11540649408","pt":1719496884882,"mc":[{"id":"1.230178311","rc":[{"atb":[[3.85,0]],"id":69142441}],"con":true,"img":false}]}
{"op":"mcm","clk":"11540649415","pt":1719496884985,"mc":[{"id":"1.230178311","rc":[{"atb":[[3.7,2]],"id":69142441}],"con":true,"img":false}]}
{"op":"mcm","clk":"11540649445","pt":1719496885606,"mc":[{"id":"1.230178311","rc":[{"atl":[[4.3,0],[3.95,4.75]],"id":65436514}],"con":true,"img":false}]}
{"op":"mcm","clk":"11540649660","pt":1719496888597,"mc":[{"id":"1.230178311","rc":[{"atb":[[2.38,2.5],[2.44,5.56]],"id":68392143}],"con":true,"img":false}]}
{"op":"mcm","clk":"11540649687","pt":1719496889007,"mc":[{"id":"1.230178311","rc":[{"atb":[[3.6,11.32],[3.4,5]],"id":69142441}],"con":true,"img":false}]}
{"op":"mcm","clk":"11540650090","pt":1719496894990,"mc":[{"id":"1.230178311","rc":[{"spn":2.91,"spf":"NaN","id":57087188},{"atl":[[3.6,3.46]],"id":65436514},{"spn":2.84,"spf":"NaN","id":65436514},{"atb":[[3.75,5.32]],"id":69142441},{"spn":7.37,"spf":"NaN","id":69142441},{"atl":[[3,5.03]],"id":55302014},{"spn":2.27,"spf":"NaN","id":55302014},{"atb":[[2.46,3.56]],"id":68392143},{"spn":3.63,"spf":"NaN","id":68392143},{"spn":4.62,"spf":"NaN","id":57088863}],"con":true,"img":false}]}
{"op":"mcm","clk":"11540650103","pt":1719496895187,"mc":[{"id":"1.230178311","rc":[{"atl":[[3.6,5.46],[3.95,0]],"id":65436514},{"atb":[[3.65,0]],"id":69142441},{"atl":[[3.05,0]],"id":55302014},{"atb":[[2.42,0]],"id":68392143}],"con":true,"img":false}]}
{"op":"mcm","clk":"11540650114","pt":1719496895391,"mc":[{"id":"1.230178311","rc":[{"atl":[[3.25,9.98]],"id":55302014}],"con":true,"img":false}]}
{"op":"mcm","clk":"11540650120","pt":1719496895490,"mc":[{"id":"1.230178311","rc":[{"atl":[[3.1,0]],"id":55302014}],"con":true,"img":false}]}
{"op":"mcm","clk":"11540650129","pt":1719496895593,"mc":[{"id":"1.230178311","rc":[{"atl":[[3.55,0.84],[3.9,0]],"id":65436514},{"atl":[[3.7,17.52],[3.25,1]],"id":55302014}],"con":true,"img":false}]}
{"op":"mcm","clk":"11540650277","pt":1719496897708,"mc":[{"id":"1.230178311","rc":[{"atb":[[2.44,3.56]],"id":68392143}],"con":true,"img":false}]}
{"op":"mcm","clk":"11540650285","pt":1719496897812,"mc":[{"id":"1.230178311","rc":[{"atb":[[2.38,9.62],[2.44,0],[2.48,2]],"id":68392143}],"con":true,"img":false}]}
{"op":"mcm","clk":"11540650307","pt":1719496898119,"mc":[{"id":"1.230178311","rc":[{"atb":[[3.7,0]],"id":69142441}],"con":true,"img":false}]}
{"op":"mcm","clk":"11540650317","pt":1719496898190,"mc":[{"id":"1.230178311","rc":[{"atb":[[3.6,2.5],[3.4,21.64],[3.8,2],[3.75,0]],"id":69142441}],"con":true,"img":false}]}
{"op":"mcm","clk":"11540650325","pt":1719496898291,"mc":[{"id":"1.230178311","rc":[{"atb":[[3.65,7.2]],"id":69142441}],"con":true,"img":false}]}
{"op":"mcm","clk":"11540650404","pt":1719496899721,"mc":[{"id":"1.230178311","rc":[{"atb":[[3.85,3.75]],"id":69142441}],"con":true,"img":false}]}
{"op":"mcm","clk":"11540650414","pt":1719496899885,"mc":[{"id":"1.230178311","rc":[{"atb":[[3.65,0]],"id":69142441}],"con":true,"img":false}]}
{"op":"mcm","clk":"11540650438","pt":1719496900403,"mc":[{"id":"1.230178311","rc":[{"atl":[[3.6,3.46],[3.65,7.31]],"id":65436514}],"con":true,"img":false}]}
{"op":"mcm","clk":"11540650448","pt":1719496900499,"mc":[{"id":"1.230178311","rc":[{"atb":[[3.8,0]],"id":69142441}],"con":true,"img":false}]}
{"op":"mcm","clk":"11540650455","pt":1719496900602,"mc":[{"id":"1.230178311","rc":[{"atb":[[3.85,0],[3.9,2]],"id":69142441}],"con":true,"img":false}]}
{"op":"mcm","clk":"11540650469","pt":1719496900809,"mc":[{"id":"1.230178311","rc":[{"atb":[[3.7,4.69]],"id":69142441}],"con":true,"img":false}]}
{"op":"mcm","clk":"11540650642","pt":1719496903192,"mc":[{"id":"1.230178311","rc":[{"atb":[[3.9,0]],"id":69142441}],"con":true,"img":false}]}
{"op":"mcm","clk":"11540650650","pt":1719496903297,"mc":[{"id":"1.230178311","rc":[{"atb":[[3.75,2]],"id":69142441}],"con":true,"img":false}]}
{"op":"mcm","clk":"11540650659","pt":1719496903414,"mc":[{"id":"1.230178311","rc":[{"atb":[[3.7,0],[3.8,3.75]],"id":69142441}],"con":true,"img":false}]}
{"op":"mcm","clk":"11540650783","pt":1719496905103,"mc":[{"id":"1.230178311","rc":[{"atb":[[3.75,0]],"id":69142441}],"con":true,"img":false}]}
{"op":"mcm","clk":"11540650789","pt":1719496905199,"mc":[{"id":"1.230178311","rc":[{"atb":[[3.85,2]],"id":69142441}],"con":true,"img":false}]}
{"op":"mcm","clk":"11540650794","pt":1719496905303,"mc":[{"id":"1.230178311","rc":[{"atb":[[3.8,0]],"id":69142441}],"con":true,"img":false}]}
{"op":"mcm","clk":"11540650799","pt":1719496905406,"mc":[{"id":"1.230178311","rc":[{"atb":[[3.9,3.75]],"id":69142441}],"con":true,"img":false}]}
{"op":"mcm","clk":"11540650818","pt":1719496905715,"mc":[{"id":"1.230178311","rc":[{"atb":[[2.38,2.5],[2.48,5.56]],"id":68392143}],"con":true,"img":false}]}
{"op":"mcm","clk":"11540650861","pt":1719496906227,"mc":[{"id":"1.230178311","rc":[{"atb":[[3.6,8.25],[3.4,5]],"id":69142441}],"con":true,"img":false}]}
{"op":"mcm","clk":"11540650896","pt":1719496906602,"mc":[{"id":"1.230178311","rc":[{"atb":[[3.85,0]],"id":69142441}],"con":true,"img":false}]}
{"op":"mcm","clk":"11540650902","pt":1719496906698,"mc":[{"id":"1.230178311","rc":[{"atb":[[3.6,2.5],[3.95,2],[3.4,17],[3.9,0]],"id":69142441}],"con":true,"img":false}]}
{"op":"mcm","clk":"11540650909","pt":1719496906828,"mc":[{"id":"1.230178311","rc":[{"atb":[[4,3.38],[3.6,6.5]],"id":69142441}],"con":true,"img":false}]}
{"op":"mcm","clk":"11540650919","pt":1719496906910,"mc":[{"id":"1.230178311","rc":[{"atb":[[3.4,5]],"id":69142441}],"con":true,"img":false}]}
{"op":"mcm","clk":"11540651061","pt":1719496908806,"mc":[{"id":"1.230178311","rc":[{"atb":[[3.95,0]],"id":69142441}],"con":true,"img":false}]}
{"op":"mcm","clk":"11540651068","pt":1719496908910,"mc":[{"id":"1.230178311","rc":[{"atb":[[4.1,2]],"id":69142441}],"con":true,"img":false}]}
{"op":"mcm","clk":"11540651076","pt":1719496909013,"mc":[{"id":"1.230178311","rc":[{"atb":[[4,0],[3.6,2.5],[3.4,14.88],[4.2,4.41]],"id":69142441}],"con":true,"img":false}]}
{"op":"mcm","clk":"11540651083","pt":1719496909115,"mc":[{"id":"1.230178311","rc":[{"atb":[[3.6,7.88],[3.4,4.99]],"id":69142441}],"con":true,"img":false}]}
{"op":"mcm","clk":"11540651169","pt":1719496910309,"mc":[{"id":"1.230178311","rc":[{"atb":[[4.1,0]],"id":69142441}],"con":true,"img":false}]}
{"op":"mcm","clk":"11540651177","pt":1719496910424,"mc":[{"id":"1.230178311","rc":[{"atb":[[1.02,24.65]],"id":69142441}],"con":true,"img":false}]}
{"op":"mcm","clk":"11540651187","pt":1719496910514,"mc":[{"id":"1.230178311","rc":[{"atb":[[3.4,17.29],[4.2,0]],"id":69142441}],"con":true,"img":false}]}
{"op":"mcm","clk":"11540651195","pt":1719496910619,"mc":[{"id":"1.230178311","rc":[{"atb":[[3.6,2.5],[3.7,6.76],[3.4,5],[3.3,26.17]],"id":69142441}],"con":true,"img":false}]}
{"op":"mcm","clk":"11540651204","pt":1719496910722,"mc":[{"id":"1.230178311","rc":[{"atb":[[3.4,20.76],[3.3,1]],"id":69142441}],"con":true,"img":false}]}
{"op":"mcm","clk":"11540651212","pt":1719496910824,"mc":[{"id":"1.230178311","rc":[{"atb":[[3.7,0]],"id":69142441}],"con":true,"img":false}]}
{"op":"mcm","clk":"11540651221","pt":1719496910927,"mc":[{"id":"1.230178311","rc":[{"atb":[[3.65,3.75]],"id":69142441}],"con":true,"img":false}]}
{"op":"mcm","clk":"11540651227","pt":1719496911029,"mc":[{"id":"1.230178311","rc":[{"atb":[[3.6,5],[3.4,5]],"id":69142441}],"con":true,"img":false}]}
{"op":"mcm","clk":"11540651243","pt":1719496911235,"mc":[{"id":"1.230178311","rc":[{"atb":[[1.52,11.39]],"id":55302014}],"con":true,"img":false}]}
{"op":"mcm","clk":"11540651287","pt":1719496911819,"mc":[{"id":"1.230178311","rc":[{"atl":[[3.55,5.31]],"id":65436514},{"atb":[[1.02,22.65]],"id":69142441},{"atb":[[2.48,9.12]],"id":68392143}],"con":true,"img":false}]}
{"op":"mcm","clk":"11540651296","pt":1719496911916,"mc":[{"id":"1.230178311","rc":[{"atl":[[3.6,0]],"id":65436514},{"atb":[[3.7,2]],"id":69142441},{"atb":[[2.38,11.62],[2.46,0],[2.48,5.56]],"id":68392143}],"con":true,"img":false}]}
{"op":"mcm","clk":"11540651304","pt":1719496912017,"mc":[{"id":"1.230178311","rc":[{"atb":[[3.75,4.69]],"id":69142441}],"con":true,"img":false}]}
{"op":"mcm","clk":"11540651320","pt":1719496912225,"mc":[{"id":"1.230178311","rc":[{"atb":[[3.65,0]],"id":69142441}],"con":true,"img":false}]}
{"op":"mcm","clk":"11540651539","pt":1719496915011,"mc":[{"id":"1.230178311","rc":[{"atb":[[3.7,0]],"id":69142441}],"con":true,"img":false}]}
{"op":"mcm","clk":"11540651554","pt":1719496915116,"mc":[{"id":"1.230178311","rc":[{"atb":[[3.8,2]],"id":69142441}],"con":true,"img":false}]}
{"op":"mcm","clk":"11540651560","pt":1719496915218,"mc":[{"id":"1.230178311","rc":[{"atb":[[3.75,0]],"id":69142441}],"con":true,"img":false}]}
{"op":"mcm","clk":"11540651565","pt":1719496915321,"mc":[{"id":"1.230178311","rc":[{"atb":[[3.85,5.32]],"id":69142441}],"con":true,"img":false}]}
{"op":"mcm","clk":"11540651706","pt":1719496917331,"mc":[{"id":"1.230178311","rc":[{"atb":[[3.8,0]],"id":69142441}],"con":true,"img":false}]}
{"op":"mcm","clk":"11540651715","pt":1719496917436,"mc":[{"id":"1.230178311","rc":[{"atb":[[3.6,2.5],[3.85,0],[3.4,15.32],[3.9,2]],"id":69142441}],"con":true,"img":false}]}
{"op":"mcm","clk":"11540651722","pt":1719496917537,"mc":[{"id":"1.230178311","rc":[{"atb":[[3.95,3.38]],"id":69142441}],"con":true,"img":false}]}
{"op":"mcm","clk":"11540651826","pt":1719496918830,"mc":[{"id":"1.230178311","rc":[{"atb":[[3.6,7.88]],"id":69142441}],"con":true,"img":false}]}
{"op":"mcm","clk":"11540651834","pt":1719496918932,"mc":[{"id":"1.230178311","rc":[{"atb":[[3.4,5]],"id":69142441}],"con":true,"img":false}]}
{"op":"mcm","clk":"11540651857","pt":1719496919242,"mc":[{"id":"1.230178311","rc":[{"atb":[[3.9,0]],"id":69142441}],"con":true,"img":false}]}
{"op":"mcm","clk":"11540651864","pt":1719496919345,"mc":[{"id":"1.230178311","rc":[{"atb":[[4,2],[3.95,0],[3.4,16.26]],"id":69142441}],"con":true,"img":false}]}
{"op":"mcm","clk":"11540651870","pt":1719496919447,"mc":[{"id":"1.230178311","rc":[{"atb":[[3.6,2.5],[3.75,5.98]],"id":69142441}],"con":true,"img":false}]}
{"op":"mcm","clk":"11540651919","pt":1719496920136,"mc":[{"id":"1.230178311","rc":[{"atb":[[4.1,3.75]],"id":69142441}],"con":true,"img":false}]}
{"op":"mcm","clk":"11540651929","pt":1719496920328,"mc":[{"id":"1.230178311","rc":[{"atb":[[3.75,0]],"id":69142441}],"con":true,"img":false}]}
{"op":"mcm","clk":"11540651956","pt":1719496920746,"mc":[{"id":"1.230178311","rc":[{"atb":[[1.01,1.7]],"id":57087188},{"atl":[[1000,1.87]],"id":57087188},{"atb":[[1.01,1.7]],"id":55302014},{"atl":[[1000,1.87]],"id":55302014},{"atb":[[1.03,1.7],[1.02,26.35]],"id":57088863},{"atl":[[1000,1.87]],"id":57088863}],"con":true,"img":false}]}
{"op":"mcm","clk":"11540651962","pt":1719496920850,"mc":[{"id":"1.230178311","rc":[{"atl":[[4.6,16.46],[4.2,0]],"id":57087188}],"con":true,"img":false}]}
{"op":"mcm","clk":"11540651977","pt":1719496921015,"mc":[{"id":"1.230178311","rc":[{"atb":[[1.01,0.31]],"id":57087188},{"atl":[[1000,0.27]],"id":57087188},{"atb":[[1.01,0.52]],"id":55302014},{"atl":[[1000,0.31]],"id":55302014},{"atb":[[1.03,0.09],[1.02,24.81]],"id":57088863},{"atl":[[1000,0.22]],"id":57088863}],"con":true,"img":false}]}
{"op":"mcm","clk":"11540651999","pt":1719496921324,"mc":[{"id":"1.230178311","rc":[{"atb":[[1.01,0]],"id":57087188},{"atl":[[1000,0.16]],"id":57087188},{"atb":[[1.01,0]],"id":55302014},{"atl":[[1000,0.16]],"id":55302014},{"atb":[[1.03,0],[1.02,24.65]],"id":57088863},{"atl":[[1000,0.16]],"id":57088863}],"con":true,"img":false}]}
{"op":"mcm","clk":"11540652010","pt":1719496921418,"mc":[{"id":"1.230178311","rc":[{"atb":[[1.94,0.31]],"id":57087188},{"atl":[[3.85,0.1]],"id":57087188},{"atb":[[1.56,0.52]],"id":55302014},{"atl":[[2.98,0.14]],"id":55302014},{"atb":[[2.86,0.25]],"id":57088863},{"atl":[[6.2,0.05]],"id":57088863}],"con":true,"img":false}]}
{"op":"mcm","clk":"11540652022","pt":1719496921520,"mc":[{"id":"1.230178311","rc":[{"atl":[[6.2,2.67]],"id":57088863}],"con":true,"img":false}]}
{"op":"mcm","clk":"11540652030","pt":1719496921624,"mc":[{"id":"1.230178311","rc":[{"atl":[[3.85,5.97]],"id":57087188},{"atl":[[3.7,2.5],[2.98,2.76],[3.25,6.19]],"id":55302014},{"atl":[[6.6,9.88],[7,2.5]],"id":57088863}],"con":true,"img":false}]}
{"op":"mcm","clk":"11540652037","pt":1719496921729,"mc":[{"id":"1.230178311","rc":[{"atl":[[3.9,1.84]],"id":57087188},{"atl":[[3,0.84],[2.98,7.8],[3.25,1]],"id":55302014},{"atl":[[6.4,0.84]],"id":57088863}],"con":true,"img":false}]}
{"op":"mcm","clk":"11540652050","pt":1719496921829,"mc":[{"id":"1.230178311","rc":[{"atl":[[2.98,2.76],[3.25,9.66]],"id":55302014}],"con":true,"img":false}]}
{"op":"mcm","clk":"11540652067","pt":1719496922037,"mc":[{"id":"1.230178311","rc":[{"atl":[[3.8,0.84]],"id":57087188},{"atl":[[2.96,0.84]],"id":55302014},{"atl":[[6,0.84]],"id":57088863}],"con":true,"img":false}]}
{"op":"mcm","clk":"11540652077","pt":1719496922242,"mc":[{"id":"1.230178311","rc":[{"atl":[[3,4.46],[3.25,1]],"id":55302014}],"con":true,"img":false}]}
{"op":"mcm","clk":"11540652100","pt":1719496922551,"mc":[{"id":"1.230178311","rc":[{"atb":[[4,0]],"id":69142441}],"con":true,"img":false}]}
{"op":"mcm","clk":"11540652107","pt":1719496922621,"mc":[{"id":"1.230178311","rc":[{"atb":[[1.02,24.65]],"id":69142441}],"con":true,"img":false}]}
{"op":"mcm","clk":"11540652117","pt":1719496922715,"mc":[{"id":"1.230178311","rc":[{"atb":[[4.1,0]],"id":69142441}],"con":true,"img":false}]}
{"op":"mcm","clk":"11540652121","pt":1719496922820,"mc":[{"id":"1.230178311","rc":[{"atb":[[3.95,4.69]],"id":69142441}],"con":true,"img":false}]}
{"op":"mcm","clk":"11540652137","pt":1719496923132,"mc":[{"id":"1.230178311","rc":[{"atb":[[3.95,0]],"id":69142441}],"con":true,"img":false}]}
{"op":"mcm","clk":"11540652145","pt":1719496923226,"mc":[{"id":"1.230178311","rc":[{"atb":[[3.65,5.32]],"id":69142441}],"con":true,"img":false}]}
{"op":"mcm","clk":"11540652217","pt":1719496924226,"mc":[{"id":"1.230178311","rc":[{"atb":[[1.02,22.65]],"id":69142441}],"con":true,"img":false}]}
{"op":"mcm","clk":"11540652226","pt":1719496924321,"mc":[{"id":"1.230178311","rc":[{"atb":[[3.7,2]],"id":69142441}],"con":true,"img":false}]}
{"op":"mcm","clk":"11540652234","pt":1719496924425,"mc":[{"id":"1.230178311","rc":[{"atb":[[3.75,3.75]],"id":69142441}],"con":true,"img":false}]}
{"op":"mcm","clk":"11540652253","pt":1719496924630,"mc":[{"id":"1.230178311","rc":[{"atb":[[3.65,0]],"id":69142441}],"con":true,"img":false}]}
{"op":"mcm","clk":"11540652376","pt":1719496926228,"mc":[{"id":"1.230178311","rc":[{"atl":[[4.5,2.5],[4.6,13.96],[5,0],[5.4,0]],"id":57087188},{"atb":[[2,15],[1.99,0],[2.06,0],[1.95,0],[2.08,8.06]],"id":65436514},{"atb":[[3.6,0],[3.2,0],[3.4,11.26],[3.55,5],[3.75,6.25]],"id":69142441},{"atl":[[4.2,0]],"id":55302014},{"atb":[[2.3,0],[2.22,0],[2.42,2.5],[2.38,9.12],[2.26,10],[2.34,5]],"id":68392143},{"atb":[[2.82,2.5],[2.74,5],[2.6,0],[2.68,10.47],[2.76,0]],"id":57088863}],"con":true,"img":false}]}
{"op":"mcm","clk":"11540652384","pt":1719496926331,"mc":[{"id":"1.230178311","rc":[{"atl":[[16,0],[11.5,3.5],[12,0],[14,0]],"id":69142441},{"atb":[[2.42,13.62],[2.38,0]],"id":68392143}],"con":true,"img":false}]}
{"op":"mcm","clk":"11540652393","pt":1719496926430,"mc":[{"id":"1.230178311","rc":[{"atb":[[2.1,9.47]],"id":65436514},{"atl":[[4.5,15.13],[3.65,1]],"id":65436514},{"atb":[[2.86,2.76]],"id":57088863}],"con":true,"img":false}]}
{"op":"mcm","clk":"11540652409","pt":1719496926636,"mc":[{"id":"1.230178311","rc":[{"atb":[[2.08,4.5]],"id":65436514},{"atb":[[2.84,0]],"id":57088863}],"con":true,"img":false}]}
{"op":"mcm","clk":"11540652447","pt":1719496927043,"mc":[{"id":"1.230178311","rc":[{"atb":[[3.6,8.25],[3.7,0],[3.4,0]],"id":69142441}],"con":true,"img":false}]}
{"op":"mcm","clk":"11540652458","pt":1719496927144,"mc":[{"id":"1.230178311","rc":[{"atb":[[2.04,0],[2.14,2.11]],"id":65436514},{"atb":[[3.8,2]],"id":69142441}],"con":true,"img":false}]}
{"op":"mcm","clk":"11540652469","pt":1719496927246,"mc":[{"id":"1.230178311","rc":[{"atb":[[3.85,7.2]],"id":69142441}],"con":true,"img":false}]}
{"op":"mcm","clk":"11540652476","pt":1719496927350,"mc":[{"id":"1.230178311","rc":[{"atb":[[3.75,2.5]],"id":69142441}],"con":true,"img":false}]}
{"op":"mcm","clk":"11540652543","pt":1719496928432,"mc":[{"id":"1.230178311","rc":[{"atb":[[1.49,0]],"id":55302014}],"con":true,"img":false}]}
{"op":"mcm","clk":"11540652554","pt":1719496928537,"mc":[{"id":"1.230178311","rc":[{"atl":[[4.6,0],[3.9,8.66]],"id":57087188}],"con":true,"img":false}]}
{"op":"mcm","clk":"11540652570","pt":1719496928747,"mc":[{"id":"1.230178311","rc":[{"atb":[[1.55,15.14]],"id":55302014}],"con":true,"img":false}]}
{"op":"mcm","clk":"11540652584","pt":1719496928952,"mc":[{"id":"1.230178311","rc":[{"atb":[[2.08,2.5]],"id":65436514}],"con":true,"img":false}]}
{"op":"mcm","clk":"11540652588","pt":1719496929056,"mc":[{"id":"1.230178311","rc":[{"atb":[[2.16,2]],"id":65436514}],"con":true,"img":false}]}
{"op":"mcm","clk":"11540652608","pt":1719496929325,"mc":[{"id":"1.230178311","rc":[{"atb":[[3.8,0]],"id":69142441}],"con":true,"img":false}]}
{"op":"mcm","clk":"11540652614","pt":1719496929425,"mc":[{"id":"1.230178311","rc":[{"atb":[[3.9,2]],"id":69142441}],"con":true,"img":false}]}
{"op":"mcm","clk":"11540652620","pt":1719496929531,"mc":[{"id":"1.230178311","rc":[{"atb":[[3.85,0],[3.95,6.07]],"id":69142441}],"con":true,"img":false}]}
{"op":"mcm","clk":"11540652756","pt":1719496931238,"mc":[{"id":"1.230178311","rc":[{"atl":[[3.85,6.97],[3.9,7.66]],"id":57087188},{"atl":[[3.6,1],[3.65,0]],"id":65436514},{"atl":[[3.2,1],[3.25,0]],"id":55302014},{"atl":[[5.5,1],[5.4,0]],"id":68392143}],"con":true,"img":false}]}
{"op":"mcm","clk":"11540652766","pt":1719496931341,"mc":[{"id":"1.230178311","rc":[{"atl":[[3.65,10.64]],"id":65436514}],"con":true,"img":false}]}
{"op":"mcm","clk":"11540652779","pt":1719496931445,"mc":[{"id":"1.230178311","rc":[{"atl":[[4.5,2.5]],"id":65436514}],"con":true,"img":false}]}
{"op":"mcm","clk":"11540652968","pt":1719496933863,"mc":[{"id":"1.230178311","rc":[{"atb":[[3.9,0]],"id":69142441}],"con":true,"img":false}]}
{"op":"mcm","clk":"11540652977","pt":1719496933929,"mc":[{"id":"1.230178311","rc":[{"atb":[[4,2],[3.95,0]],"id":69142441}],"con":true,"img":false}]}
{"op":"mcm","clk":"11540652987","pt":1719496934030,"mc":[{"id":"1.230178311","rc":[{"atb":[[3.85,7.2]],"id":69142441},{"atb":[[2.42,2.5],[2.48,11.12]],"id":68392143}],"con":true,"img":false}]}
{"op":"mcm","clk":"11540653106","pt":1719496935726,"mc":[{"id":"1.230178311","rc":[{"atb":[[4.1,6.07]],"id":69142441}],"con":true,"img":false}]}
{"op":"mcm","clk":"11540653120","pt":1719496935933,"mc":[{"id":"1.230178311","rc":[{"atb":[[3.85,0]],"id":69142441}],"con":true,"img":false}]}
{"op":"mcm","clk":"11540653241","pt":1719496937837,"mc":[{"id":"1.230178311","rc":[{"atl":[[6,4.72]],"id":57088863}],"con":true,"img":false}]}
{"op":"mcm","clk":"11540653246","pt":1719496937940,"mc":[{"id":"1.230178311","rc":[{"atl":[[3.8,6.82]],"id":57087188},{"atl":[[2.96,4.79]],"id":55302014}],"con":true,"img":false}]}
{"op":"mcm","clk":"11540653251","pt":1719496938043,"mc":[{"id":"1.230178311","rc":[{"atl":[[3.85,1.1]],"id":57087188},{"atb":[[4,0]],"id":69142441},{"atl":[[2.98,0.14]],"id":55302014},{"atl":[[6.2,0.05]],"id":57088863}],"con":true,"img":false}]}
{"op":"mcm","clk":"11540653258","pt":1719496938146,"mc":[{"id":"1.230178311","rc":[{"atb":[[1.02,24.65]],"id":69142441}],"con":true,"img":false}]}
{"op":"mcm","clk":"11540653264","pt":1719496938251,"mc":[{"id":"1.230178311","rc":[{"atb":[[4.1,0]],"id":69142441}],"con":true,"img":false}]}
{"op":"mcm","clk":"11540653271","pt":1719496938357,"mc":[{"id":"1.230178311","rc":[{"atb":[[3.95,6.07]],"id":69142441}],"con":true,"img":false}]}
{"op":"mcm","clk":"11540653290","pt":1719496938553,"mc":[{"id":"1.230178311","rc":[{"atl":[[3.9,6.82]],"id":57087188},{"atb":[[3.95,0]],"id":69142441},{"atl":[[3,3.62]],"id":55302014},{"atl":[[6.4,0]],"id":57088863}],"con":true,"img":false}]}
{"op":"mcm","clk":"11540653298","pt":1719496938655,"mc":[{"id":"1.230178311","rc":[{"atb":[[3.75,8.57]],"id":69142441}],"con":true,"img":false}]}
{"op":"mcm","clk":"11540653308","pt":1719496938758,"mc":[{"id":"1.230178311","rc":[{"atl":[[5.6,1]],"id":68392143}],"con":true,"img":false}]}
{"op":"mcm","clk":"11540653314","pt":1719496938860,"mc":[{"id":"1.230178311","rc":[{"atb":[[3.6,0],[3.55,21.82]],"id":69142441},{"atl":[[5.5,0]],"id":68392143}],"con":true,"img":false}]}
{"op":"mcm","clk":"11540653324","pt":1719496939069,"mc":[{"id":"1.230178311","rc":[{"atb":[[3.55,5],[3.3,31.39]],"id":69142441}],"con":true,"img":false}]}
{"op":"mcm","clk":"11540653331","pt":1719496939169,"mc":[{"id":"1.230178311","rc":[{"atb":[[3.8,7.2]],"id":69142441}],"con":true,"img":false}]}
{"op":"mcm","clk":"11540653340","pt":1719496939272,"mc":[{"id":"1.230178311","rc":[{"atb":[[3.55,22.14],[3.3,1],[3.75,2.5]],"id":69142441}],"con":true,"img":false}]}
{"op":"mcm","clk":"11540653342","pt":1719496939331,"mc":[{"id":"1.230178311","rc":[{"atb":[[1.58,2.11],[1.53,0]],"id":55302014}],"con":true,"img":false}]}
{"op":"mcm","clk":"11540653351","pt":1719496939437,"mc":[{"id":"1.230178311","rc":[{"atb":[[1.58,6.41]],"id":55302014}],"con":true,"img":false}]}
{"op":"mcm","clk":"11540653360","pt":1719496939651,"mc":[{"id":"1.230178311","rc":[{"atb":[[1.55,12.05]],"id":55302014}],"con":true,"img":false}]}
{"op":"mcm","clk":"11540653400","pt":1719496940559,"mc":[{"id":"1.230178311","rc":[{"atb":[[1.55,10.05]],"id":55302014}],"con":true,"img":false}]}
{"op":"mcm","clk":"11540653408","pt":1719496940664,"mc":[{"id":"1.230178311","rc":[{"atb":[[1.59,2]],"id":55302014}],"con":true,"img":false}]}
{"op":"mcm","clk":"11540653445","pt":1719496941238,"mc":[{"id":"1.230178311","rc":[{"atb":[[1.02,22.65]],"id":69142441}],"con":true,"img":false}]}
{"op":"mcm","clk":"11540653449","pt":1719496941338,"mc":[{"id":"1.230178311","rc":[{"atb":[[3.85,2]],"id":69142441}],"con":true,"img":false}]}
{"op":"mcm","clk":"11540653457","pt":1719496941444,"mc":[{"id":"1.230178311","rc":[{"atb":[[3.9,6.07]],"id":69142441}],"con":true,"img":false}]}
{"op":"mcm","clk":"11540653469","pt":1719496941647,"mc":[{"id":"1.230178311","rc":[{"atb":[[3.8,0]],"id":69142441}],"con":true,"img":false}]}
{"op":"mcm","clk":"11540653533","pt":1719496942672,"mc":[{"id":"1.230178311","rc":[{"atb":[[2.16,7.58]],"id":65436514},{"atb":[[2.9,5.62]],"id":57088863}],"con":true,"img":false}]}
{"op":"mcm","clk":"11540653541","pt":1719496942773,"mc":[{"id":"1.230178311","rc":[{"atb":[[2.1,0]],"id":65436514},{"atb":[[2.86,0.25]],"id":57088863}],"con":true,"img":false}]}
{"op":"mcm","clk":"11540653607","pt":1719496943867,"mc":[{"id":"1.230178311","rc":[{"atb":[[3.85,0]],"id":69142441}],"con":true,"img":false}]}
{"op":"mcm","clk":"11540653614","pt":1719496943961,"mc":[{"id":"1.230178311","rc":[{"atb":[[3.95,2],[3.9,0]],"id":69142441}],"con":true,"img":false}]}
{"op":"mcm","clk":"11540653619","pt":1719496944064,"mc":[{"id":"1.230178311","rc":[{"atb":[[4,4.5]],"id":69142441}],"con":true,"img":false}]}
{"op":"mcm","clk":"11540653722","pt":1719496945466,"mc":[{"id":"1.230178311","rc":[{"atb":[[3.95,0]],"id":69142441}],"con":true,"img":false}]}
{"op":"mcm","clk":"11540653732","pt":1719496945573,"mc":[{"id":"1.230178311","rc":[{"atb":[[4.1,2]],"id":69142441}],"con":true,"img":false}]}
{"op":"mcm","clk":"11540653740","pt":1719496945662,"mc":[{"id":"1.230178311","rc":[{"atb":[[4,0],[4.2,6]],"id":69142441}],"con":true,"img":false}]}
{"op":"mcm","clk":"11540653823","pt":1719496946857,"mc":[{"id":"1.230178311","rc":[{"atb":[[4.1,0]],"id":69142441}],"con":true,"img":false}]}
{"op":"mcm","clk":"11540653830","pt":1719496946964,"mc":[{"id":"1.230178311","rc":[{"atb":[[1.02,24.65]],"id":69142441}],"con":true,"img":false}]}
{"op":"mcm","clk":"11540653838","pt":1719496947059,"mc":[{"id":"1.230178311","rc":[{"atb":[[4.2,0]],"id":69142441}],"con":true,"img":false}]}
{"op":"mcm","clk":"11540653845","pt":1719496947164,"mc":[{"id":"1.230178311","rc":[{"atb":[[4,7.2],[3.55,5],[3.3,25.64]],"id":69142441}],"con":true,"img":false}]}
{"op":"mcm","clk":"11540653853","pt":1719496947266,"mc":[{"id":"1.230178311","rc":[{"atb":[[3.55,10],[3.3,1]],"id":69142441}],"con":true,"img":false}]}
{"op":"mcm","clk":"11540653859","pt":1719496947366,"mc":[{"id":"1.230178311","rc":[{"atb":[[4,0]],"id":69142441}],"con":true,"img":false}]}
{"op":"mcm","clk":"11540653866","pt":1719496947470,"mc":[{"id":"1.230178311","rc":[{"atb":[[3.8,7.2],[3.3,13.5]],"id":69142441}],"con":true,"img":false}]}
{"op":"mcm","clk":"11540653876","pt":1719496947573,"mc":[{"id":"1.230178311","rc":[{"atb":[[3.6,10],[3.55,5],[3.3,1]],"id":69142441}],"con":true,"img":false}]}
{"op":"mcm","clk":"11540653985","pt":1719496949377,"mc":[{"id":"1.230178311","rc":[{"atb":[[1.52,0]],"id":55302014}],"con":true,"img":false}]}
{"op":"mcm","clk":"11540653995","pt":1719496949479,"mc":[{"id":"1.230178311","rc":[{"atb":[[1.02,22.65]],"id":69142441}],"con":true,"img":false}]}
{"op":"mcm","clk":"11540653999","pt":1719496949582,"mc":[{"id":"1.230178311","rc":[{"atb":[[3.85,2]],"id":69142441}],"con":true,"img":false}]}
{"op":"mcm","clk":"11540654002","pt":1719496949645,"mc":[{"id":"1.230178311","rc":[{"atb":[[1.58,16.63]],"id":55302014}],"con":true,"img":false}]}
{"op":"mcm","clk":"11540654034","pt":1719496950059,"mc":[{"id":"1.230178311","rc":[{"atb":[[3.9,6.07]],"id":69142441}],"con":true,"img":false}]}
{"op":"mcm","clk":"11540654050","pt":1719496950265,"mc":[{"id":"1.230178311","rc":[{"atb":[[3.8,0]],"id":69142441}],"con":true,"img":false}]}
{"op":"mcm","clk":"11540654192","pt":1719496952452,"mc":[{"id":"1.230178311","rc":[{"atb":[[3.85,0]],"id":69142441}],"con":true,"img":false}]}
{"op":"mcm","clk":"11540654200","pt":1719496952546,"mc":[{"id":"1.230178311","rc":[{"atb":[[3.95,2]],"id":69142441}],"con":true,"img":false}]}
{"op":"mcm","clk":"11540654208","pt":1719496952654,"mc":[{"id":"1.230178311","rc":[{"atb":[[4,6.07],[3.9,0]],"id":69142441}],"con":true,"img":false}]}
{"op":"mcm","clk":"11540654345","pt":1719496954776,"mc":[{"id":"1.230178311","rc":[{"atb":[[3.95,0]],"id":69142441}],"con":true,"img":false}]}
{"op":"mcm","clk":"11540654354","pt":1719496954863,"mc":[{"id":"1.230178311","rc":[{"atb":[[4.1,2]],"id":69142441}],"con":true,"img":false}]}
{"op":"mcm","clk":"11540654363","pt":1719496954997,"mc":[{"id":"1.230178311","rc":[{"spn":2.87,"spf":"NaN","id":57087188},{"spn":2.85,"spf":"NaN","id":65436514},{"atb":[[4,0],[4.2,6.07]],"id":69142441},{"spn":7.6,"spf":"NaN","id":69142441},{"spn":3.64,"spf":"NaN","id":68392143},{"spn":4.45,"spf":"NaN","id":57088863}],"con":true,"img":false}]}
{"op":"mcm","clk":"11540654393","pt":1719496955358,"mc":[{"id":"1.230178311","rc":[{"atb":[[1.59,6.22]],"id":55302014}],"con":true,"img":false}]}
{"op":"mcm","clk":"11540654403","pt":1719496955464,"mc":[{"id":"1.230178311","rc":[{"atb":[[1.58,12.33]],"id":55302014}],"con":true,"img":false}]}
{"op":"mcm","clk":"11540654717","pt":1719496960058,"mc":[{"id":"1.230178311","rc":[{"atb":[[4.1,0]],"id":69142441}],"con":true,"img":false}]}
{"op":"mcm","clk":"11540654724","pt":1719496960165,"mc":[{"id":"1.230178311","rc":[{"atb":[[1.02,24.65]],"id":69142441}],"con":true,"img":false}]}
{"op":"mcm","clk":"11540654730","pt":1719496960277,"mc":[{"id":"1.230178311","rc":[{"atb":[[4.2,0]],"id":69142441}],"con":true,"img":false}]}
{"op":"mcm","clk":"11540654744","pt":1719496960474,"mc":[{"id":"1.230178311","rc":[{"atb":[[4,7.2],[3.6,0],[3.55,17.5]],"id":69142441}],"con":true,"img":false}]}
{"op":"mcm","clk":"11540654754","pt":1719496960678,"mc":[{"id":"1.230178311","rc":[{"atb":[[4,0]],"id":69142441}],"con":true,"img":false}]}
{"op":"mcm","clk":"11540654760","pt":1719496960783,"mc":[{"id":"1.230178311","rc":[{"atb":[[3.8,7.2]],"id":69142441}],"con":true,"img":false}]}
{"op":"mcm","clk":"11540654938","pt":1719496963368,"mc":[{"id":"1.230178311","rc":[{"atb":[[1.02,22.65]],"id":69142441}],"con":true,"img":false}]}
{"op":"mcm","clk":"11540654945","pt":1719496963468,"mc":[{"id":"1.230178311","rc":[{"atb":[[3.85,2]],"id":69142441}],"con":true,"img":false}]}
{"op":"mcm","clk":"11540654954","pt":1719496963575,"mc":[{"id":"1.230178311","rc":[{"atb":[[3.9,6.07]],"id":69142441}],"con":true,"img":false}]}
{"op":"mcm","clk":"11540654964","pt":1719496963775,"mc":[{"id":"1.230178311","rc":[{"atb":[[3.8,0]],"id":69142441}],"con":true,"img":false}]}
{"op":"mcm","clk":"11540655193","pt":1719496967079,"mc":[{"id":"1.230178311","rc":[{"atb":[[3.85,0]],"id":69142441}],"con":true,"img":false}]}
{"op":"mcm","clk":"11540655201","pt":1719496967180,"mc":[{"id":"1.230178311","rc":[{"atb":[[3.95,2]],"id":69142441}],"con":true,"img":false}]}
{"op":"mcm","clk":"11540655213","pt":1719496967287,"mc":[{"id":"1.230178311","rc":[{"atb":[[4,6.07],[3.9,0]],"id":69142441}],"con":true,"img":false}]}
{"op":"mcm","clk":"11540655235","pt":1719496967489,"mc":[{"id":"1.230178311","rc":[{"atl":[[3.7,0],[3.9,0]],"id":55302014}],"con":true,"img":false}]}
{"op":"mcm","clk":"11540655321","pt":1719496968371,"mc":[{"id":"1.230178311","rc":[{"atb":[[1.94,0]],"id":57087188},{"atl":[[3.85,1]],"id":57087188},{"atb":[[1.56,0]],"id":55302014},{"atl":[[2.98,0]],"id":55302014},{"atb":[[2.86,0]],"id":57088863},{"atl":[[6.2,0]],"id":57088863}],"con":true,"img":false}]}
{"op":"mcm","clk":"11540655329","pt":1719496968473,"mc":[{"id":"1.230178311","rc":[{"atl":[[4,10],[3.6,2.5],[3.2,9.42],[3,0],[3.8,5]],"id":55302014},{"atl":[[6.6,1],[7,17.11]],"id":57088863}],"con":true,"img":false}]}
{"op":"mcm","clk":"11540655336","pt":1719496968583,"mc":[{"id":"1.230178311","rc":[{"atl":[[3.6,16.72]],"id":55302014}],"con":true,"img":false}]}
{"op":"mcm","clk":"11540655347","pt":1719496968682,"mc":[{"id":"1.230178311","rc":[{"atl":[[3.2,1]],"id":55302014}],"con":true,"img":false}]}
{"op":"mcm","clk":"11540655458","pt":1719496970385,"mc":[{"id":"1.230178311","rc":[{"atb":[[3.95,0]],"id":69142441}],"con":true,"img":false}]}
{"op":"mcm","clk":"11540655467","pt":1719496970485,"mc":[{"id":"1.230178311","rc":[{"atb":[[4,0],[4.1,2]],"id":69142441}],"con":true,"img":false}]}
{"op":"mcm","clk":"11540655479","pt":1719496970590,"mc":[{"id":"1.230178311","rc":[{"atb":[[4.2,4.5]],"id":69142441}],"con":true,"img":false}]}
{"op":"mcm","clk":"11540655746","pt":1719496973787,"mc":[{"id":"1.230178311","rc":[{"atb":[[4.1,0]],"id":69142441}],"con":true,"img":false}]}
{"op":"mcm","clk":"11540655757","pt":1719496973889,"mc":[{"id":"1.230178311","rc":[{"atb":[[1.02,24.65]],"id":69142441}],"con":true,"img":false}]}
{"op":"mcm","clk":"11540655769","pt":1719496973994,"mc":[{"id":"1.230178311","rc":[{"atb":[[4.2,0]],"id":69142441}],"con":true,"img":false}]}
{"op":"mcm","clk":"11540655774","pt":1719496974098,"mc":[{"id":"1.230178311","rc":[{"atb":[[3.95,6.07]],"id":69142441}],"con":true,"img":false}]}
{"op":"mcm","clk":"11540655786","pt":1719496974202,"mc":[{"id":"1.230178311","rc":[{"atb":[[3.6,5],[3.55,5]],"id":69142441}],"con":true,"img":false}]}
{"op":"mcm","clk":"11540655793","pt":1719496974296,"mc":[{"id":"1.230178311","rc":[{"atb":[[3.95,0]],"id":69142441}],"con":true,"img":false}]}
{"op":"mcm","clk":"11540655801","pt":1719496974398,"mc":[{"id":"1.230178311","rc":[{"atb":[[3.8,7.2]],"id":69142441}],"con":true,"img":false}]}
{"op":"mcm","clk":"11540655959","pt":1719496976193,"mc":[{"id":"1.230178311","rc":[{"atb":[[1.92,0],[1.84,0],[1.88,0],[1.93,2]],"id":57087188},{"atl":[[4.5,0],[3.8,0.84]],"id":57087188},{"atb":[[2,10],[2.16,2],[2.08,0]],"id":65436514},{"atl":[[4.5,0],[5.3,0],[4.9,0],[3.55,0.84]],"id":65436514},{"atb":[[3.8,0],[3.55,0],[3.75,0]],"id":69142441},{"atl":[[11,0.84],[11.5,1]],"id":69142441},{"atb":[[1.59,2],[1.46,0],[1.54,0],[1.5,0]],"id":55302014},{"atl":[[4,0],[3.6,14.22],[3.8,0],[2.96,0.84]],"id":55302014},{"atb":[[2.42,0],[2.26,0],[2.48,7.56],[2.34,0]],"id":68392143},{"atl":[[6.2,0],[4.9,0],[7,0],[7.8,0]],"id":68392143},{"atb":[[2.82,0],[2.9,0],[2.74,0]],"id":57088863},{"atl":[[8.6,0],[6,0.84],[7,14.61],[7.8,0]],"id":57088863}],"con":true,"img":false}]}
{"op":"mcm","clk":"11540655977","pt":1719496976393,"mc":[{"id":"1.230178311","rc":[{"atb":[[1.02,22.65]],"id":69142441}],"con":true,"img":false}]}
{"op":"mcm","clk":"11540655987","pt":1719496976494,"mc":[{"id":"1.230178311","rc":[{"atb":[[3.85,2]],"id":69142441},{"atb":[[1.94,11.47],[2.68,0]],"id":57088863}],"con":true,"img":false}]}
{"op":"mcm","clk":"11540655993","pt":1719496976599,"mc":[{"id":"1.230178311","rc":[{"atl":[[3.15,0.84],[2.96,0]],"id":55302014},{"atl":[[4.8,0],[5.5,0.84]],"id":68392143},{"atl":[[6.4,0.84],[6,0]],"id":57088863}],"con":true,"img":false}]}
{"op":"mcm","clk":"11540656174","pt":1719496978600,"mc":[{"id":"1.230178311","rc":[{"atb":[[1.93,0]],"id":57087188}],"con":true,"img":false}]}
{"op":"mcm","clk":"11540656183","pt":1719496978704,"mc":[{"id":"1.230178311","rc":[{"atb":[[1.92,2]],"id":57087188}],"con":true,"img":false}]}
{"op":"mcm","clk":"11540656200","pt":1719496978976,"mc":[{"id":"1.230178311","rc":[{"atb":[[1.02,22.65]],"id":57088863}],"con":true,"img":false}]}
{"op":"mcm","clk":"11540656208","pt":1719496979072,"mc":[{"id":"1.230178311","rc":[{"atb":[[1.95,2]],"id":57088863}],"con":true,"img":false}]}
{"op":"mcm","clk":"11540656234","pt":1719496979485,"mc":[{"id":"1.230178311","rc":[{"atb":[[2.48,5.56]],"id":68392143}],"con":true,"img":false}]}
{"op":"mcm","clk":"11540656240","pt":1719496979584,"mc":[{"id":"1.230178311","rc":[{"atb":[[1.02,2],[2.48,0]],"id":68392143}],"con":true,"img":false}]}
{"op":"mcm","clk":"11540656250","pt":1719496979693,"mc":[{"id":"1.230178311","rc":[{"atb":[[1.88,6.56]],"id":68392143}],"con":true,"img":false}]}
{"op":"mcm","clk":"11540656273","pt":1719496979997,"mc":[{"id":"1.230178311","rc":[{"atb":[[3.85,0]],"id":69142441},{"atb":[[1.97,2.11]],"id":57088863}],"con":true,"img":false}]}
{"op":"mcm","clk":"11540656280","pt":1719496980099,"mc":[{"id":"1.230178311","rc":[{"atb":[[3.65,2]],"id":69142441},{"atb":[[2.18,1]],"id":68392143}],"con":true,"img":false}]}
{"op":"mcm","clk":"11540656289","pt":1719496980202,"mc":[{"id":"1.230178311","rc":[{"atb":[[3.6,0],[2.44,6]],"id":69142441},{"atb":[[2.02,0]],"id":68392143}],"con":true,"img":false}]}
{"op":"mcm","clk":"11540656415","pt":1719496981494,"mc":[{"id":"1.230178311","rc":[{"atb":[[1.01,1]],"id":57087188}],"con":true,"img":false}]}
{"op":"mcm","clk":"11540656468","pt":1719496982113,"mc":[{"id":"1.230178311","rc":[{"atb":[[1.55,0]],"id":55302014},{"atb":[[1.95,0]],"id":57088863}],"con":true,"img":false}]}
{"op":"mcm","clk":"11540656477","pt":1719496982172,"mc":[{"id":"1.230178311","rc":[{"atb":[[1.98,2]],"id":57088863}],"con":true,"img":false}]}
{"op":"mcm","clk":"11540656507","pt":1719496982494,"mc":[{"id":"1.230178311","rc":[{"atb":[[3.65,0]],"id":69142441}],"con":true,"img":false}]}
{"op":"mcm","clk":"11540656519","pt":1719496982589,"mc":[{"id":"1.230178311","rc":[{"atb":[[2.46,2]],"id":69142441}],"con":true,"img":false}]}
{"op":"mcm","clk":"11540656689","pt":1719496984499,"mc":[{"id":"1.230178311","rc":[{"atb":[[1.58,2.11]],"id":55302014}],"con":true,"img":false}]}
{"op":"mcm","clk":"11540656813","pt":1719496985896,"mc":[{"id":"1.230178311","rc":[{"atb":[[2.46,0]],"id":69142441}],"con":true,"img":false}]}
{"op":"mcm","clk":"11540656827","pt":1719496986007,"mc":[{"id":"1.230178311","rc":[{"atb":[[1.02,24.65]],"id":69142441}],"con":true,"img":false}]}
{"op":"mcm","clk":"11540657068","pt":1719496988597,"mc":[{"id":"1.230178311","rc":[{"atb":[[1.02,22.65]],"id":69142441}],"con":true,"img":false}]}
{"op":"mcm","clk":"11540657088","pt":1719496988709,"mc":[{"id":"1.230178311","rc":[{"atb":[[2.46,2]],"id":69142441}],"con":true,"img":false}]}
{"op":"mcm","clk":"11540657169","pt":1719496989493,"mc":[{"id":"1.230178311","rc":[{"atb":[[1.77,0],[1.69,4.24]],"id":57087188},{"atb":[[2,0],[1.89,4.24]],"id":65436514},{"atl":[[4.1,2],[3.65,0]],"id":65436514},{"atl":[[12.5,0],[15.5,2]],"id":69142441},{"atb":[[1.39,4.24]],"id":55302014},{"atb":[[1.79,7.56],[1.88,0]],"id":68392143},{"atl":[[7.2,2],[6,0]],"id":68392143},{"atl":[[7,0],[7.8,2]],"id":57088863}],"con":true,"img":false}]}
{"op":"mcm","clk":"11540657177","pt":1719496989590,"mc":[{"id":"1.230178311","rc":[{"atb":[[1.45,0]],"id":55302014}],"con":true,"img":false}]}
{"op":"mcm","clk":"11540657284","pt":1719496990680,"mc":[{"id":"1.230178311","rc":[{"atb":[[2.46,0]],"id":69142441}],"con":true,"img":false}]}
{"op":"mcm","clk":"11540657297","pt":1719496990784,"mc":[{"id":"1.230178311","rc":[{"atb":[[2.3,7],[1.02,24.65],[2.44,0]],"id":69142441}],"con":true,"img":false}]}
{"op":"mcm","clk":"11540657354","pt":1719496991403,"mc":[{"id":"1.230178311","rc":[{"atb":[[1.99,2.31]],"id":65436514}],"con":true,"img":false}]}
{"op":"mcm","clk":"11540657399","pt":1719496991776,"mc":[{"id":"1.230178311","rc":[{"atb":[[1.99,0]],"id":65436514}],"con":true,"img":false}]}
{"op":"mcm","clk":"11540657481","pt":1719496992724,"mc":[{"id":"1.230178311","rc":[{"atb":[[1.77,3.75]],"id":57087188}],"con":true,"img":false}]}
{"op":"mcm","clk":"11540657490","pt":1719496992812,"mc":[{"id":"1.230178311","rc":[{"atb":[[1.77,0]],"id":57087188}],"con":true,"img":false}]}
{"op":"mcm","clk":"11540657530","pt":1719496993285,"mc":[{"id":"1.230178311","rc":[{"atb":[[1.08,50]],"id":57087188},{"atb":[[1.08,50]],"id":65436514},{"atb":[[1.08,50]],"id":69142441},{"atb":[[1.08,50]],"id":55302014},{"atb":[[1.08,50]],"id":68392143},{"atb":[[1.08,50]],"id":57088863}],"con":true,"img":false}]}
{"op":"mcm","clk":"11540657591","pt":1719496993991,"mc":[{"id":"1.230178311","rc":[{"atb":[[1.02,22.65]],"id":69142441}],"con":true,"img":false}]}
{"op":"mcm","clk":"11540657600","pt":1719496994093,"mc":[{"id":"1.230178311","rc":[{"atb":[[2.32,2]],"id":69142441}],"con":true,"img":false}]}
{"op":"mcm","clk":"11540657766","pt":1719496995816,"mc":[{"id":"1.230178311","rc":[{"atb":[[2.4,3.75]],"id":69142441}],"con":true,"img":false}]}
{"op":"mcm","clk":"11540657774","pt":1719496995867,"mc":[{"id":"1.230178311","rc":[{"atb":[[2.4,0]],"id":69142441}],"con":true,"img":false}]}
{"op":"mcm","clk":"11540657916","pt":1719496997484,"mc":[{"id":"1.230178311","rc":[{"atb":[[2.32,0]],"id":69142441}],"con":true,"img":false}]}
{"op":"mcm","clk":"11540657933","pt":1719496997600,"mc":[{"id":"1.230178311","rc":[{"atb":[[1.02,24.65]],"id":69142441}],"con":true,"img":false}]}
{"op":"mcm","clk":"11540658298","pt":1719497001411,"mc":[{"id":"1.230178311","rc":[{"atb":[[1.02,22.65]],"id":69142441}],"con":true,"img":false}]}
{"op":"mcm","clk":"11540658306","pt":1719497001505,"mc":[{"id":"1.230178311","rc":[{"atb":[[2.32,2]],"id":69142441}],"con":true,"img":false}]}
{"op":"mcm","clk":"11540658595","pt":1719497004610,"mc":[{"id":"1.230178311","rc":[{"atb":[[2.32,0]],"id":69142441}],"con":true,"img":false}]}
{"op":"mcm","clk":"11540658609","pt":1719497004709,"mc":[{"id":"1.230178311","rc":[{"atb":[[1.02,24.65]],"id":69142441}],"con":true,"img":false}]}
{"op":"mcm","clk":"11540658865","pt":1719497007627,"mc":[{"id":"1.230178311","rc":[{"atb":[[1.02,22.65]],"id":69142441}],"con":true,"img":false}]}
{"op":"mcm","clk":"11540658874","pt":1719497007681,"mc":[{"id":"1.230178311","rc":[{"atb":[[2.32,2]],"id":69142441}],"con":true,"img":false}]}
{"op":"mcm","clk":"11540659053","pt":1719497010091,"mc":[{"id":"1.230178311","rc":[{"atb":[[2.32,0]],"id":69142441}],"con":true,"img":false}]}
{"op":"mcm","clk":"11540659064","pt":1719497010199,"mc":[{"id":"1.230178311","rc":[{"atb":[[1.02,24.65]],"id":69142441}],"con":true,"img":false}]}
{"op":"mcm","clk":"11540659081","pt":1719497010405,"mc":[{"id":"1.230178311","rc":[{"atl":[[3.85,0],[3.9,7.82]],"id":57087188},{"atb":[[3.45,1],[3.3,0]],"id":69142441},{"atb":[[2.02,1],[2.18,0]],"id":68392143}],"con":true,"img":false}]}
{"op":"mcm","clk":"11540659102","pt":1719497010720,"mc":[{"id":"1.230178311","rc":[{"atl":[[4.1,1]],"id":57087188},{"atl":[[4.2,1]],"id":65436514},{"atl":[[6.8,1],[6.6,0]],"id":57088863}],"con":true,"img":false}]}
{"op":"mcm","clk":"11540659111","pt":1719497010825,"mc":[{"id":"1.230178311","rc":[{"atl":[[4,8.67],[3.9,0]],"id":57087188},{"atl":[[3.6,0]],"id":65436514},{"atl":[[11.5,0],[12,1]],"id":69142441},{"atl":[[3.2,0],[3.1,1]],"id":55302014}],"con":true,"img":false}]}
{"op":"mcm","clk":"11540659128","pt":1719497010983,"mc":[{"id":"1.230178311","rc":[{"atl":[[3.6,6.51],[3.3,2]],"id":55302014}],"con":true,"img":false}]}
{"op":"mcm","clk":"11540659137","pt":1719497011140,"mc":[{"id":"1.230178311","rc":[{"atl":[[3.95,0.84],[3.8,0]],"id":57087188},{"atl":[[4,0.84],[3.55,0]],"id":65436514},{"atl":[[11,0],[11.5,0.84]],"id":69142441},{"atl":[[3.6,8.51],[3.15,0]],"id":55302014},{"atl":[[6.4,0],[6.6,0.84]],"id":57088863}],"con":true,"img":false}]}
{"op":"mcm","clk":"11540659145","pt":1719497011190,"mc":[{"id":"1.230178311","rc":[{"atl":[[3.3,0]],"id":55302014}],"con":true,"img":false}]}
{"op":"mcm","clk":"11540659157","pt":1719497011303,"mc":[{"id":"1.230178311","rc":[{"atl":[[4.1,0],[4.2,3.85]],"id":65436514}],"con":true,"img":false}]}
{"op":"mcm","clk":"11540659173","pt":1719497011498,"mc":[{"id":"1.230178311","rc":[{"atl":[[10.5,4.7],[4.2,1]],"id":65436514}],"con":true,"img":false}]}
{"op":"mcm","clk":"11540659180","pt":1719497011606,"mc":[{"id":"1.230178311","rc":[{"atl":[[4,0]],"id":65436514},{"atl":[[3.6,2]],"id":55302014}],"con":true,"img":false}]}
{"op":"mcm","clk":"11540659190","pt":1719497011712,"mc":[{"id":"1.230178311","rc":[{"atl":[[3.6,0],[7.2,3]],"id":55302014}],"con":true,"img":false}]}
{"op":"mcm","clk":"11540659220","pt":1719497012123,"mc":[{"id":"1.230178311","rc":[{"atb":[[1.02,22.65]],"id":69142441}],"con":true,"img":false}]}
{"op":"mcm","clk":"11540659222","pt":1719497012226,"mc":[{"id":"1.230178311","rc":[{"atb":[[2.32,2]],"id":69142441}],"con":true,"img":false}]}
{"op":"mcm","clk":"11540659298","pt":1719497013418,"mc":[{"id":"1.230178311","rc":[{"atb":[[2.32,0]],"id":69142441}],"con":true,"img":false}]}
{"op":"mcm","clk":"11540659305","pt":1719497013521,"mc":[{"id":"1.230178311","rc":[{"atb":[[1.02,24.65]],"id":69142441}],"con":true,"img":false}]}
{"op":"mcm","clk":"11540659403","pt":1719497015027,"mc":[{"id":"1.230178311","rc":[{"spn":2.93,"spf":"NaN","id":57087188},{"spn":3.18,"spf":"NaN","id":65436514},{"atb":[[3.3,1]],"id":69142441},{"spn":7.47,"spf":"NaN","id":69142441},{"atl":[[3.2,1],[3.1,0]],"id":55302014},{"spn":2.39,"spf":"NaN","id":55302014},{"atb":[[2.02,0],[2.18,1]],"id":68392143},{"spn":3.84,"spf":"NaN","id":68392143},{"spn":4.53,"spf":"NaN","id":57088863}],"con":true,"img":false}]}
{"op":"mcm","clk":"11540659413","pt":1719497015128,"mc":[{"id":"1.230178311","rc":[{"atb":[[3.45,0]],"id":69142441}],"con":true,"img":false}]}
{"op":"mcm","clk":"11540659479","pt":1719497016011,"mc":[{"id":"1.230178311","rc":[{"atl":[[4,0],[4.1,10.52]],"id":57087188}],"con":true,"img":false}]}
{"op":"mcm","clk":"11540659502","pt":1719497016321,"mc":[{"id":"1.230178311","rc":[{"atb":[[1.02,22.65]],"id":69142441}],"con":true,"img":false}]}
{"op":"mcm","clk":"11540659513","pt":1719497016423,"mc":[{"id":"1.230178311","rc":[{"atb":[[2.32,2]],"id":69142441}],"con":true,"img":false}]}
{"op":"mcm","clk":"11540659535","pt":1719497016689,"mc":[{"id":"1.230178311","rc":[{"atl":[[3.95,0]],"id":57087188}],"con":true,"img":false}]}
{"op":"mcm","clk":"11540659549","pt":1719497016890,"mc":[{"id":"1.230178311","rc":[{"atl":[[4.1,9.52],[3.9,1]],"id":57087188},{"atl":[[3.6,1],[4.2,0]],"id":65436514},{"atb":[[3.45,1],[3.3,0]],"id":69142441},{"atl":[[11.5,1.84],[12,0]],"id":69142441},{"atb":[[2.02,1],[2.18,0]],"id":68392143},{"atl":[[6.8,0],[6.6,1.84]],"id":57088863}],"con":true,"img":false}]}
{"op":"mcm","clk":"11540659613","pt":1719497017819,"mc":[{"id":"1.230178311","rc":[{"atl":[[3.2,0],[3.1,1]],"id":55302014},{"atb":[[2.02,0],[2.18,1]],"id":68392143}],"con":true,"img":false}]}
{"op":"mcm","clk":"11540659647","pt":1719497018238,"mc":[{"id":"1.230178311","rc":[{"atb":[[3.45,0],[2.32,0],[3.3,1]],"id":69142441}],"con":true,"img":false}]}
{"op":"mcm","clk":"11540659658","pt":1719497018289,"mc":[{"id":"1.230178311","rc":[{"atb":[[1.02,24.65]],"id":69142441}],"con":true,"img":false}]}
{"op":"mcm","clk":"11540659665","pt":1719497018391,"mc":[{"id":"1.230178311","rc":[{"atl":[[75,2.48],[15.5,0]],"id":69142441}],"con":true,"img":false}]}
{"op":"mcm","clk":"11540659672","pt":1719497018496,"mc":[{"id":"1.230178311","rc":[{"atl":[[110,2]],"id":69142441}],"con":true,"img":false}]}
{"op":"mcm","clk":"11540659685","pt":1719497018601,"mc":[{"id":"1.230178311","rc":[{"atl":[[75,0.48]],"id":69142441}],"con":true,"img":false}]}
{"op":"mcm","clk":"11540659761","pt":1719497019788,"mc":[{"id":"1.230178311","rc":[{"atl":[[3.2,1],[3.1,0]],"id":55302014}],"con":true,"img":false}]}
{"op":"mcm","clk":"11540659800","pt":1719497020306,"mc":[{"id":"1.230178311","rc":[{"atb":[[1.02,22.65]],"id":69142441}],"con":true,"img":false}]}
{"op":"mcm","clk":"11540659808","pt":1719497020414,"mc":[{"id":"1.230178311","rc":[{"atb":[[2.32,2]],"id":69142441}],"con":true,"img":false}]}
{"op":"mcm","clk":"11540659823","pt":1719497020721,"mc":[{"id":"1.230178311","rc":[{"atb":[[3.45,1],[3.3,0]],"id":69142441}],"con":true,"img":false}]}
{"op":"mcm","clk":"11540659831","pt":1719497020825,"mc":[{"id":"1.230178311","rc":[{"atl":[[3.2,0]],"id":55302014},{"atb":[[2.02,1],[2.18,0]],"id":68392143}],"con":true,"img":false}]}
{"op":"mcm","clk":"11540659842","pt":1719497020929,"mc":[{"id":"1.230178311","rc":[{"atl":[[3.1,1]],"id":55302014}],"con":true,"img":false}]}
{"op":"mcm","clk":"11540659849","pt":1719497021032,"mc":[{"id":"1.230178311","rc":[{"atl":[[7,0.84]],"id":55302014}],"con":true,"img":false}]}
{"op":"mcm","clk":"11540659859","pt":1719497021139,"mc":[{"id":"1.230178311","rc":[{"atl":[[4.1,1],[3.9,0],[9.4,10.52]],"id":57087188},{"atl":[[3.6,0],[4.2,1]],"id":65436514},{"atb":[[3.45,0],[3.3,1]],"id":69142441},{"atl":[[11.5,0.84],[12,1]],"id":69142441},{"atl":[[3.2,1],[3.1,0]],"id":55302014},{"atb":[[2.02,0],[2.18,1]],"id":68392143},{"atl":[[6.8,1],[6.6,0.84]],"id":57088863}],"con":true,"img":false}]}
{"op":"mcm","clk":"11540659872","pt":1719497021193,"mc":[{"id":"1.230178311","rc":[{"atb":[[2.3,0],[2.34,2]],"id":69142441},{"atl":[[75,2.48],[110,0]],"id":69142441}],"con":true,"img":false}]}
{"op":"mcm","clk":"11540659945","pt":1719497021940,"mc":[{"id":"1.230178311","rc":[{"atl":[[3.85,1],[4.1,0]],"id":57087188},{"atl":[[3.6,1],[4.2,0]],"id":65436514},{"atb":[[2.32,0]],"id":69142441},{"atl":[[11.5,1.84],[12,0]],"id":69142441},{"atl":[[6.6,1.84]],"id":57088863}],"con":true,"img":false}]}
{"op":"mcm","clk":"11540659957","pt":1719497021999,"mc":[{"id":"1.230178311","rc":[{"atb":[[1.02,24.65]],"id":69142441},{"atl":[[75,0.48],[110,2]],"id":69142441},{"atl":[[6.8,0]],"id":57088863}],"con":true,"img":false}]}
{"op":"mcm","clk":"11540660054","pt":1719497022939,"mc":[{"id":"1.230178311","rc":[{"atl":[[3.9,1]],"id":57087188},{"atb":[[3.45,1],[3.3,0]],"id":69142441},{"atb":[[2.02,1]],"id":68392143}],"con":true,"img":false}]}
{"op":"mcm","clk":"11540660065","pt":1719497023032,"mc":[{"id":"1.230178311","rc":[{"atl":[[3.85,0]],"id":57087188},{"atb":[[2.18,0]],"id":68392143}],"con":true,"img":false}]}
{"op":"mcm","clk":"11540660077","pt":1719497023136,"mc":[{"id":"1.230178311","rc":[{"atl":[[4.1,1],[3.9,0]],"id":57087188},{"atl":[[3.6,0],[4.2,1]],"id":65436514},{"atb":[[3.45,0],[3.3,1]],"id":69142441},{"atl":[[11.5,0.84],[12,1]],"id":69142441},{"atb":[[2.02,0]],"id":68392143},{"atl":[[6.8,1],[6.6,0.84]],"id":57088863}],"con":true,"img":false}]}
{"op":"mcm","clk":"11540660086","pt":1719497023194,"mc":[{"id":"1.230178311","rc":[{"atl":[[75,2.48],[110,0]],"id":69142441}],"con":true,"img":false}]}
{"op":"mcm","clk":"11540660236","pt":1719497024901,"mc":[{"id":"1.230178311","rc":[{"atl":[[4.1,0],[3.9,1]],"id":57087188},{"atl":[[3.6,1],[4.2,0]],"id":65436514},{"atl":[[11.5,1.84],[12,0]],"id":69142441},{"atb":[[2.18,1]],"id":68392143},{"atl":[[6.8,0],[6.6,1.84]],"id":57088863}],"con":true,"img":false}]}
{"op":"mcm","clk":"11540660248","pt":1719497025006,"mc":[{"id":"1.230178311","rc":[{"atl":[[75,0.48],[15.5,3.7]],"id":69142441}],"con":true,"img":false}]}
{"op":"mcm","clk":"11540660287","pt":1719497025624,"mc":[{"id":"1.230178311","rc":[{"atb":[[3.45,1]],"id":69142441},{"atb":[[2.02,1]],"id":68392143}],"con":true,"img":false}]}
{"op":"mcm","clk":"11540660296","pt":1719497025728,"mc":[{"id":"1.230178311","rc":[{"atb":[[3.3,0]],"id":69142441},{"atb":[[2.18,0]],"id":68392143}],"con":true,"img":false}]}
{"op":"mcm","clk":"11540660418","pt":1719497027337,"mc":[{"id":"1.230178311","rc":[{"atl":[[4.1,1],[3.9,0]],"id":57087188},{"atl":[[3.6,0],[4.2,1]],"id":65436514},{"atb":[[3.45,0],[3.3,1]],"id":69142441},{"atl":[[11.5,0.84],[12,1]],"id":69142441},{"atl":[[3.2,0],[3.1,1]],"id":55302014},{"atb":[[2.02,0],[2.18,1]],"id":68392143},{"atl":[[6.8,1],[6.6,0.84]],"id":57088863}],"con":true,"img":false}]}
{"op":"mcm","clk":"11540660424","pt":1719497027441,"mc":[{"id":"1.230178311","rc":[{"atl":[[3.85,1]],"id":57087188},{"atb":[[2.3,3],[2.34,0]],"id":69142441}],"con":true,"img":false}]}
{"op":"mcm","clk":"11540660485","pt":1719497028220,"mc":[{"id":"1.230178311","rc":[{"atl":[[4.1,0]],"id":57087188},{"atl":[[3.6,1]],"id":65436514},{"atl":[[11.5,1.84],[12,0]],"id":69142441},{"atl":[[3.2,1],[3.1,0]],"id":55302014},{"atl":[[6.8,0],[6.6,1.84]],"id":57088863}],"con":true,"img":false}]}
{"op":"mcm","clk":"11540660492","pt":1719497028323,"mc":[{"id":"1.230178311","rc":[{"atl":[[4.2,0]],"id":65436514},{"atl":[[29,3.57]],"id":57088863}],"con":true,"img":false}]}
{"op":"mcm","clk":"11540660504","pt":1719497028432,"mc":[{"id":"1.230178311","rc":[{"atl":[[7.8,0]],"id":57088863}],"con":true,"img":false}]}
{"op":"mcm","clk":"11540660519","pt":1719497028633,"mc":[{"id":"1.230178311","rc":[{"atl":[[3.85,0],[3.9,1]],"id":57087188},{"atb":[[3.45,1],[3.3,0]],"id":69142441},{"atb":[[2.02,1],[2.18,0]],"id":68392143}],"con":true,"img":false}]}
{"op":"mcm","clk":"11540660602","pt":1719497029928,"mc":[{"id":"1.230178311","rc":[{"atl":[[4.1,1],[3.9,0]],"id":57087188},{"atl":[[3.6,0],[4.2,1]],"id":65436514},{"atl":[[11.5,0.84],[12,1]],"id":69142441},{"atl":[[3.2,0],[3.1,1]],"id":55302014},{"atl":[[6.8,1],[6.6,0.84]],"id":57088863}],"con":true,"img":false}]}
{"op":"mcm","clk":"11540660777","pt":1719497031757,"mc":[{"id":"1.230178311","rc":[{"atb":[[3.45,0],[3.3,1]],"id":69142441},{"atl":[[3.2,1],[3.1,0]],"id":55302014},{"atb":[[2.02,0],[2.18,1]],"id":68392143}],"con":true,"img":false}]}
{"op":"mcm","clk":"11540660783","pt":1719497031849,"mc":[{"id":"1.230178311","rc":[{"atl":[[3.9,1]],"id":57087188},{"atl":[[3.6,1]],"id":65436514},{"atl":[[11.5,1.84]],"id":69142441},{"atl":[[6.8,0],[6.6,1.84]],"id":57088863}],"con":true,"img":false}]}
{"op":"mcm","clk":"11540660795","pt":1719497031918,"mc":[{"id":"1.230178311","rc":[{"atl":[[4.1,0]],"id":57087188},{"atl":[[4.2,0]],"id":65436514},{"atl":[[12,0]],"id":69142441},{"atl":[[11,3.25]],"id":55302014}],"con":true,"img":false}]}
{"op":"mcm","clk":"11540660813","pt":1719497032129,"mc":[{"id":"1.230178311","rc":[{"atl":[[75,2.48],[15.5,0]],"id":69142441}],"con":true,"img":false}]}
{"op":"mcm","clk":"11540660839","pt":1719497032543,"mc":[{"id":"1.230178311","rc":[{"atl":[[11,0]],"id":55302014}],"con":true,"img":false}]}
{"op":"mcm","clk":"11540660929","pt":1719497033738,"mc":[{"id":"1.230178311","rc":[{"atl":[[4.1,1],[3.9,0]],"id":57087188},{"atl":[[4.2,1]],"id":65436514},{"atb":[[3.45,1],[3.3,0]],"id":69142441},{"atl":[[11.5,0.84],[12,1]],"id":69142441},{"atb":[[2.02,1],[2.18,0]],"id":68392143},{"atl":[[6.8,1],[6.6,0.84]],"id":57088863}],"con":true,"img":false}]}
{"op":"mcm","clk":"11540660937","pt":1719497033836,"mc":[{"id":"1.230178311","rc":[{"atl":[[3.6,0]],"id":65436514}],"con":true,"img":false}]}
{"op":"mcm","clk":"11540661088","pt":1719497035837,"mc":[{"id":"1.230178311","rc":[{"atl":[[3.85,1],[4.1,0]],"id":57087188},{"atl":[[3.6,1]],"id":65436514},{"atb":[[3.45,0],[3.3,1]],"id":69142441},{"atl":[[11.5,1.84],[12,0]],"id":69142441},{"atb":[[2.02,0],[2.18,1]],"id":68392143},{"atl":[[6.8,0],[6.6,1.84]],"id":57088863}],"con":true,"img":false}]}
{"op":"mcm","clk":"11540661094","pt":1719497035943,"mc":[{"id":"1.230178311","rc":[{"atl":[[4.2,0]],"id":65436514},{"atl":[[75,0.48],[15.5,3.7]],"id":69142441},{"atl":[[7.8,3.7],[29,0]],"id":57088863}],"con":true,"img":false}]}
{"op":"mcm","clk":"11540661107","pt":1719497036150,"mc":[{"id":"1.230178311","rc":[{"atl":[[3.85,0],[3.9,1]],"id":57087188},{"atb":[[3.45,1],[3.3,0]],"id":69142441},{"atb":[[2.02,1],[2.18,0]],"id":68392143}],"con":true,"img":false}]}
{"op":"mcm","clk":"11540661115","pt":1719497036206,"mc":[{"id":"1.230178311","rc":[{"atl":[[4.1,2],[9.4,0]],"id":57087188}],"con":true,"img":false}]}
{"op":"mcm","clk":"11540661174","pt":1719497037342,"mc":[{"id":"1.230178311","rc":[{"atl":[[4.1,3],[3.9,0]],"id":57087188},{"atl":[[4.2,1]],"id":65436514},{"atl":[[11.5,0.84],[12,1]],"id":69142441},{"atl":[[3.2,0],[3.1,1]],"id":55302014},{"atl":[[6.8,1],[6.6,0.84]],"id":57088863}],"con":true,"img":false}]}
{"op":"mcm","clk":"11540661181","pt":1719497037448,"mc":[{"id":"1.230178311","rc":[{"atl":[[3.6,0]],"id":65436514}],"con":true,"img":false}]}
{"op":"mcm","clk":"11540661188","pt":1719497037552,"mc":[{"id":"1.230178311","rc":[{"atl":[[4,0.84]],"id":57087188}],"con":true,"img":false}]}
{"op":"mcm","clk":"11540661271","pt":1719497038750,"mc":[{"id":"1.230178311","rc":[{"atb":[[3.45,0],[3.3,1]],"id":69142441},{"atl":[[3.2,1],[3.1,0]],"id":55302014},{"atb":[[2.02,0],[2.18,1]],"id":68392143}],"con":true,"img":false}]}
{"op":"mcm","clk":"11540661453","pt":1719497041060,"mc":[{"id":"1.230178311","rc":[{"atl":[[3.85,1],[4.1,2]],"id":57087188},{"atl":[[3.6,1],[4.2,0]],"id":65436514},{"atl":[[11.5,1.84],[12,0]],"id":69142441},{"atl":[[6.8,0],[6.6,1.84]],"id":57088863}],"con":true,"img":false}]}
{"op":"mcm","clk":"11540661467","pt":1719497041217,"mc":[{"id":"1.230178311","rc":[{"atl":[[3.9,1]],"id":57087188},{"atb":[[3.45,1]],"id":69142441},{"atb":[[2.02,1]],"id":68392143}],"con":true,"img":false}]}
{"op":"mcm","clk":"11540661478","pt":1719497041328,"mc":[{"id":"1.230178311","rc":[{"atl":[[3.85,0],[4.1,3]],"id":57087188},{"atl":[[3.6,0],[4.2,1]],"id":65436514},{"atb":[[3.3,0]],"id":69142441},{"atl":[[75,2.48],[11.5,0.84],[12,1],[15.5,0]],"id":69142441},{"atb":[[2.18,0]],"id":68392143},{"atl":[[6.8,1],[6.6,0.84]],"id":57088863}],"con":true,"img":false}]}
{"op":"mcm","clk":"11540661555","pt":1719497042466,"mc":[{"id":"1.230178311","rc":[{"atb":[[3.3,1]],"id":69142441},{"atb":[[2.18,1]],"id":68392143}],"con":true,"img":false}]}
{"op":"mcm","clk":"11540661563","pt":1719497042520,"mc":[{"id":"1.230178311","rc":[{"atl":[[3.9,0]],"id":57087188},{"atb":[[3.45,0]],"id":69142441},{"atb":[[2.02,0]],"id":68392143}],"con":true,"img":false}]}
{"op":"mcm","clk":"11540661602","pt":1719497043045,"mc":[{"id":"1.230178311","rc":[{"atl":[[3.85,1]],"id":57087188},{"atl":[[3.6,1],[4.2,0]],"id":65436514},{"atl":[[11.5,1.84]],"id":69142441},{"atl":[[6.8,0],[6.6,1.84]],"id":57088863}],"con":true,"img":false}]}
{"op":"mcm","clk":"11540661611","pt":1719497043146,"mc":[{"id":"1.230178311","rc":[{"atl":[[4.1,2]],"id":57087188},{"atl":[[12,0]],"id":69142441}],"con":true,"img":false}]}
{"op":"mcm","clk":"11540661620","pt":1719497043249,"mc":[{"id":"1.230178311","rc":[{"atl":[[29,3.57]],"id":57088863}],"con":true,"img":false}]}
{"op":"mcm","clk":"11540661627","pt":1719497043353,"mc":[{"id":"1.230178311","rc":[{"atl":[[7.8,0]],"id":57088863}],"con":true,"img":false}]}
{"op":"mcm","clk":"11540661643","pt":1719497043523,"mc":[{"id":"1.230178311","rc":[{"atb":[[1.01,2.7]],"id":57087188},{"atl":[[1000,1.87]],"id":57087188},{"atb":[[1.01,1.7]],"id":55302014},{"atl":[[1000,1.87]],"id":55302014},{"atb":[[1.01,1.7]],"id":57088863},{"atl":[[1000,1.87]],"id":57088863}],"con":true,"img":false}]}
{"op":"mcm","clk":"11540661669","pt":1719497043825,"mc":[{"id":"1.230178311","rc":[{"atb":[[1.01,1.3]],"id":57087188},{"atl":[[1000,0.26]],"id":57087188},{"atb":[[1.01,0.47]],"id":55302014},{"atl":[[1000,0.21]],"id":55302014},{"atb":[[1.01,0.28]],"id":57088863},{"atl":[[1000,0.22]],"id":57088863}],"con":true,"img":false}]}
{"op":"mcm","clk":"11540661682","pt":1719497044032,"mc":[{"id":"1.230178311","rc":[{"atb":[[1.01,1]],"id":57087188},{"atl":[[1000,0.16]],"id":57087188},{"atb":[[1.01,0]],"id":55302014},{"atl":[[1000,0.16]],"id":55302014},{"atb":[[1.01,0]],"id":57088863},{"atl":[[1000,0.16]],"id":57088863}],"con":true,"img":false}]}
{"op":"mcm","clk":"11540661693","pt":1719497044140,"mc":[{"id":"1.230178311","rc":[{"atb":[[1.93,0.3]],"id":57087188},{"atl":[[3.95,0.09]],"id":57087188},{"atb":[[1.6,0.47]],"id":55302014},{"atl":[[6.8,0.04]],"id":55302014},{"atb":[[1.99,0.28]],"id":57088863},{"atl":[[6.4,0.05]],"id":57088863}],"con":true,"img":false}]}
{"op":"mcm","clk":"11540661703","pt":1719497044247,"mc":[{"id":"1.230178311","rc":[{"atb":[[1.99,2.28],[1.94,0]],"id":57088863}],"con":true,"img":false}]}
{"op":"mcm","clk":"11540661757","pt":1719497044965,"mc":[{"id":"1.230178311","rc":[{"atb":[[1.98,0]],"id":57088863}],"con":true,"img":false}]}
{"op":"mcm","clk":"11540661766","pt":1719497045027,"mc":[{"id":"1.230178311","rc":[{"atb":[[2,2]],"id":57088863}],"con":true,"img":false}]}
{"op":"mcm","clk":"11540661894","pt":1719497046420,"mc":[{"id":"1.230178311","rc":[{"atl":[[75,0.48],[110,2]],"id":69142441}],"con":true,"img":false}]}
{"op":"mcm","clk":"11540661913","pt":1719497046639,"mc":[{"id":"1.230178311","rc":[{"atl":[[3.85,0],[3.9,1]],"id":57087188},{"atb":[[3.45,1],[3.3,0]],"id":69142441},{"atb":[[2.02,1],[2.18,0]],"id":68392143}],"con":true,"img":false}]}
{"op":"mcm","clk":"11540661922","pt":1719497046737,"mc":[{"id":"1.230178311","rc":[{"atl":[[3.95,2.09],[4.1,1],[3.9,0]],"id":57087188},{"atl":[[4.2,1]],"id":65436514},{"atl":[[11.5,0.84],[12,1]],"id":69142441},{"atl":[[3.2,0],[3.1,1]],"id":55302014},{"atl":[[6.8,1],[6.6,0.84]],"id":57088863}],"con":true,"img":false}]}
{"op":"mcm","clk":"11540661930","pt":1719497046836,"mc":[{"id":"1.230178311","rc":[{"atl":[[3.6,0]],"id":65436514},{"atl":[[7.2,0],[6.8,2.04]],"id":55302014},{"atl":[[7.8,2],[29,0]],"id":57088863}],"con":true,"img":false}]}
{"op":"mcm","clk":"11540661947","pt":1719497047045,"mc":[{"id":"1.230178311","rc":[{"atl":[[3.9,0.84]],"id":57087188}],"con":true,"img":false}]}
{"op":"mcm","clk":"11540661953","pt":1719497047154,"mc":[{"id":"1.230178311","rc":[{"atb":[[3.45,0],[3.3,1]],"id":69142441},{"atl":[[3.2,1]],"id":55302014},{"atb":[[2.02,0],[2.18,1]],"id":68392143}],"con":true,"img":false}]}
{"op":"mcm","clk":"11540661959","pt":1719497047250,"mc":[{"id":"1.230178311","rc":[{"atl":[[3.1,0]],"id":55302014}],"con":true,"img":false}]}
{"op":"mcm","clk":"11540662007","pt":1719497047827,"mc":[{"id":"1.230178311","rc":[{"atl":[[75,2.48],[110,0]],"id":69142441}],"con":true,"img":false}]}
{"op":"mcm","clk":"11540662011","pt":1719497047929,"mc":[{"id":"1.230178311","rc":[{"atl":[[3.85,1],[4.1,0]],"id":57087188},{"atl":[[3.6,1],[4.2,0]],"id":65436514},{"atl":[[11.5,1.84],[12,0]],"id":69142441},{"atl":[[6.8,0],[6.6,1.84]],"id":57088863}],"con":true,"img":false}]}
{"op":"mcm","clk":"11540662025","pt":1719497048137,"mc":[{"id":"1.230178311","rc":[{"atl":[[75,0.48],[110,2]],"id":69142441}],"con":true,"img":false}]}
{"op":"mcm","clk":"11540662059","pt":1719497048554,"mc":[{"id":"1.230178311","rc":[{"atl":[[11,3.76]],"id":65436514}],"con":true,"img":false}]}
{"op":"mcm","clk":"11540662074","pt":1719497048761,"mc":[{"id":"1.230178311","rc":[{"atl":[[11,0]],"id":65436514}],"con":true,"img":false}]}
{"op":"mcm","clk":"11540662346","pt":1719497052142,"mc":[{"id":"1.230178311","rc":[{"atl":[[3.85,0],[3.9,1.84]],"id":57087188},{"atb":[[3.45,1],[3.3,0]],"id":69142441},{"atb":[[2.02,1],[2.18,0]],"id":68392143}],"con":true,"img":false}]}
{"op":"mcm","clk":"11540662351","pt":1719497052242,"mc":[{"id":"1.230178311","rc":[{"atl":[[4,4.79],[3.95,0.09]],"id":57087188}],"con":true,"img":false}]}
{"op":"mcm","clk":"11540662379","pt":1719497052553,"mc":[{"id":"1.230178311","rc":[{"atl":[[4,3.95],[4.1,1]],"id":57087188},{"atl":[[3.6,0],[4.2,1]],"id":65436514},{"atl":[[12,1]],"id":69142441},{"atl":[[6.8,1],[6.6,0.84]],"id":57088863}],"con":true,"img":false}]}
{"op":"mcm","clk":"11540662386","pt":1719497052658,"mc":[{"id":"1.230178311","rc":[{"atl":[[11.5,0.84]],"id":69142441},{"atl":[[3.2,0],[3.1,1]],"id":55302014}],"con":true,"img":false}]}
{"op":"mcm","clk":"11540662395","pt":1719497052760,"mc":[{"id":"1.230178311","rc":[{"atl":[[3.9,0.84]],"id":57087188},{"atb":[[3.3,1]],"id":69142441},{"atb":[[2.02,0],[2.18,1]],"id":68392143}],"con":true,"img":false}]}
{"op":"mcm","clk":"11540662405","pt":1719497052863,"mc":[{"id":"1.230178311","rc":[{"atb":[[3.45,0]],"id":69142441}],"con":true,"img":false}]}
{"op":"mcm","clk":"11540662443","pt":1719497053230,"mc":[{"id":"1.230178311","rc":[{"atl":[[3.9,0]],"id":57087188}],"con":true,"img":false}]}
{"op":"mcm","clk":"11540662459","pt":1719497053438,"mc":[{"id":"1.230178311","rc":[{"atl":[[4,0],[3.85,1],[4.1,5.05]],"id":57087188},{"atl":[[3.6,1],[4.2,0]],"id":65436514},{"atl":[[11.5,1.84],[12,0]],"id":69142441},{"atl":[[3.2,1],[3.1,0]],"id":55302014},{"atl":[[6.8,0],[6.6,1.84]],"id":57088863}],"con":true,"img":false}]}
{"op":"mcm","clk":"11540662470","pt":1719497053541,"mc":[{"id":"1.230178311","rc":[{"atl":[[4.1,4.05]],"id":57087188}],"con":true,"img":false}]}
{"op":"mcm","clk":"11540662802","pt":1719497057244,"mc":[{"id":"1.230178311","rc":[{"atl":[[3.85,0],[3.9,1]],"id":57087188},{"atb":[[3.45,1],[3.3,0]],"id":69142441},{"atb":[[2.02,1],[2.18,0]],"id":68392143}],"con":true,"img":false}]}
{"op":"mcm","clk":"11540662812","pt":1719497057340,"mc":[{"id":"1.230178311","rc":[{"atl":[[3.95,2.09],[4.1,0]],"id":57087188}],"con":true,"img":false}]}
{"op":"mcm","clk":"11540662819","pt":1719497057443,"mc":[{"id":"1.230178311","rc":[{"atl":[[4.1,1],[3.9,0]],"id":57087188},{"atl":[[3.6,0],[4.2,1]],"id":65436514},{"atb":[[3.3,1]],"id":69142441},{"atl":[[11.5,0.84],[12,1]],"id":69142441},{"atb":[[2.02,0],[2.18,1]],"id":68392143},{"atl":[[6.8,1]],"id":57088863}],"con":true,"img":false}]}
{"op":"mcm","clk":"11540662830","pt":1719497057548,"mc":[{"id":"1.230178311","rc":[{"atb":[[3.45,0]],"id":69142441},{"atl":[[75,2.48],[110,0]],"id":69142441},{"atl":[[6.6,0.84]],"id":57088863}],"con":true,"img":false}]}
{"op":"mcm","clk":"11540662877","pt":1719497058067,"mc":[{"id":"1.230178311","rc":[{"atl":[[3.9,0.84]],"id":57087188}],"con":true,"img":false}]}
{"op":"mcm","clk":"11540662997","pt":1719497059466,"mc":[{"id":"1.230178311","rc":[{"atl":[[3.85,1],[4.1,0]],"id":57087188},{"atl":[[3.6,1]],"id":65436514},{"atl":[[11.5,1.84],[12,0]],"id":69142441},{"atl":[[6.6,1.84]],"id":57088863}],"con":true,"img":false}]}
{"op":"mcm","clk":"11540663005","pt":1719497059570,"mc":[{"id":"1.230178311","rc":[{"atl":[[4.2,0]],"id":65436514},{"atl":[[6.8,0]],"id":57088863}],"con":true,"img":false}]}
{"op":"mcm","clk":"11540663225","pt":1719497062265,"mc":[{"id":"1.230178311","rc":[{"atb":[[1.93,3.3]],"id":57087188},{"atb":[[2.16,5]],"id":65436514},{"atb":[[3.3,3.18]],"id":69142441},{"atb":[[1.59,4.4]],"id":55302014},{"atb":[[1.83,3.59]],"id":68392143},{"atb":[[2.02,3.4]],"id":57088863}],"con":true,"img":false}]}
{"op":"mcm","clk":"11540663237","pt":1719497062370,"mc":[{"id":"1.230178311","rc":[{"atb":[[2.3,0],[3.25,6.36]],"id":69142441},{"atb":[[1.79,0],[1.84,3.59]],"id":68392143}],"con":true,"img":false}]}
{"op":"mcm","clk":"11540663260","pt":1719497062531,"mc":[{"id":"1.230178311","rc":[{"atl":[[3.85,0],[3.9,1.84]],"id":57087188},{"atb":[[3.45,1],[3.3,2.18]],"id":69142441},{"atb":[[2.02,1],[2.18,0]],"id":68392143}],"con":true,"img":false}]}
{"op":"mcm","clk":"11540663266","pt":1719497062633,"mc":[{"id":"1.230178311","rc":[{"atl":[[3.95,0.09],[9.4,3.95]],"id":57087188},{"atl":[[110,2]],"id":69142441}],"con":true,"img":false}]}
{"op":"mcm","clk":"11540663275","pt":1719497062740,"mc":[{"id":"1.230178311","rc":[{"atl":[[4.1,1],[3.9,0.84]],"id":57087188},{"atl":[[3.6,0],[4.2,1]],"id":65436514},{"atb":[[3.45,0],[3.3,3.18]],"id":69142441},{"atl":[[75,0.48],[11.5,0.84],[12,1]],"id":69142441},{"atb":[[2.02,0],[2.18,1]],"id":68392143},{"atl":[[6.8,1],[6.6,0.84]],"id":57088863}],"con":true,"img":false}]}
{"op":"mcm","clk":"11540663288","pt":1719497062952,"mc":[{"id":"1.230178311","rc":[{"atb":[[1.92,0]],"id":57087188}],"con":true,"img":false}]}
{"op":"mcm","clk":"11540663298","pt":1719497063047,"mc":[{"id":"1.230178311","rc":[{"atb":[[1.94,2]],"id":57087188},{"atl":[[3.85,1],[3.9,0]],"id":57087188},{"atl":[[3.6,1],[4.2,0]],"id":65436514},{"atl":[[11.5,1.84],[12,0]],"id":69142441},{"atl":[[6.8,0]],"id":57088863}],"con":true,"img":false}]}
{"op":"mcm","clk":"11540663308","pt":1719497063154,"mc":[{"id":"1.230178311","rc":[{"atl":[[4.1,0]],"id":57087188},{"atl":[[6.6,1.84]],"id":57088863}],"con":true,"img":false}]}
{"op":"mcm","clk":"11540663343","pt":1719497063564,"mc":[{"id":"1.230178311","rc":[{"atb":[[2,0]],"id":57088863}],"con":true,"img":false}]}
{"op":"mcm","clk":"11540663351","pt":1719497063670,"mc":[{"id":"1.230178311","rc":[{"atb":[[2.04,2]],"id":57088863}],"con":true,"img":false}]}
{"op":"mcm","clk":"11540663363","pt":1719497063782,"mc":[{"id":"1.230178311","rc":[{"atb":[[1.94,5.09],[1.95,10],[1.69,0],[1.99,5],[2.06,2.5],[1.75,4.24]],"id":57087188},{"atl":[[4.6,2.5],[5,5],[3.8,3.09],[5.4,10]],"id":57087188},{"atb":[[1.89,0],[1.98,10],[1.81,8.48],[2.04,5],[2.12,2.5],[2.16,9.77]],"id":65436514},{"atl":[[3.6,4.77],[5.1,2.5],[3.95,1],[5.5,5],[5.9,10]],"id":65436514},{"atb":[[3.6,5],[3.35,2.89],[3.8,2.5],[3.4,10]],"id":69142441},{"atl":[[16,10],[11,2.89],[12,2.5],[14,5]],"id":69142441},{"atb":[[1.4,5],[1.59,6.69],[1.44,2.5],[1.39,0],[1.47,4.24]],"id":55302014},{"atl":[[3.6,10],[3.2,3.5],[5.8,2],[6.8,0.04],[3.4,5],[3.15,2.29]],"id":55302014},{"atb":[[2.5,2.5],[2.34,10],[2.42,5],[2.2,2.25]],"id":68392143},{"atl":[[5.5,3.09],[7.4,10],[6.6,5],[5.9,2.5]],"id":68392143},{"atb":[[2.8,5],[2.72,10],[2.1,2.29],[2.48,2.89],[1.99,0.28],[2.88,2.5]],"id":57088863},{"atl":[[8.6,10],[6.4,2.94],[7.8,7],[7,2.5]],"id":57088863}],"con":true,"img":false}]}
{"op":"mcm","clk":"11540663383","pt":1719497063984,"mc":[{"id":"1.230178311","rc":[{"atl":[[3.6,0],[5.1,4.5],[10.5,0]],"id":65436514},{"atl":[[5.9,4.5]],"id":68392143},{"atl":[[7,4.5]],"id":57088863}],"con":true,"img":false}]}
{"op":"mcm","clk":"11540663396","pt":1719497064040,"mc":[{"id":"1.230178311","rc":[{"atl":[[3.55,0.84],[3.65,3.75]],"id":65436514},{"atl":[[10.5,0.84]],"id":69142441},{"atl":[[3.1,0.84],[7,0]],"id":55302014},{"atb":[[1.02,0]],"id":68392143},{"atl":[[7.2,0]],"id":68392143},{"atl":[[6.2,0.84],[7.8,5]],"id":57088863}],"con":true,"img":false}]}
{"op":"mcm","clk":"11540663406","pt":1719497064152,"mc":[{"id":"1.230178311","rc":[{"atl":[[5.1,2.5],[4.1,5]],"id":65436514},{"atb":[[1.85,2]],"id":68392143},{"atl":[[6.6,6.34],[7,2.5]],"id":57088863}],"con":true,"img":false}]}
{"op":"mcm","clk":"11540663461","pt":1719497064662,"mc":[{"id":"1.230178311","rc":[{"atl":[[3.55,0]],"id":65436514}],"con":true,"img":false}]}
{"op":"mcm","clk":"11540663499","pt":1719497065136,"mc":[{"id":"1.230178311","rc":[{"atl":[[3.65,0]],"id":65436514}],"con":true,"img":false}]}
{"op":"mcm","clk":"11540663512","pt":1719497065237,"mc":[{"id":"1.230178311","rc":[{"atl":[[3.7,3.46]],"id":65436514}],"con":true,"img":false}]}
{"op":"mcm","clk":"11540663529","pt":1719497065453,"mc":[{"id":"1.230178311","rc":[{"atb":[[1.98,2.11],[1.91,0]],"id":57087188}],"con":true,"img":false}]}
{"op":"mcm","clk":"11540663536","pt":1719497065548,"mc":[{"id":"1.230178311","rc":[{"atl":[[3.75,0.84]],"id":57087188},{"atl":[[3.7,0]],"id":65436514}],"con":true,"img":false}]}
{"op":"mcm","clk":"11540663542","pt":1719497065650,"mc":[{"id":"1.230178311","rc":[{"atl":[[3.75,4.47]],"id":65436514}],"con":true,"img":false}]}
{"op":"mcm","clk":"11540663577","pt":1719497066170,"mc":[{"id":"1.230178311","rc":[{"atl":[[3.75,0]],"id":65436514}],"con":true,"img":false}]}
{"op":"mcm","clk":"11540663584","pt":1719497066275,"mc":[{"id":"1.230178311","rc":[{"atl":[[3.8,5.23]],"id":65436514}],"con":true,"img":false}]}
{"op":"mcm","clk":"11540663611","pt":1719497066541,"mc":[{"id":"1.230178311","rc":[{"atl":[[3.8,0]],"id":65436514}],"con":true,"img":false}]}
{"op":"mcm","clk":"11540663617","pt":1719497066644,"mc":[{"id":"1.230178311","rc":[{"atl":[[3.85,5.62]],"id":65436514}],"con":true,"img":false}]}
{"op":"mcm","clk":"11540663642","pt":1719497066955,"mc":[{"id":"1.230178311","rc":[{"atb":[[1.94,3.09]],"id":57087188}],"con":true,"img":false}]}
{"op":"mcm","clk":"11540663654","pt":1719497067069,"mc":[{"id":"1.230178311","rc":[{"atb":[[2.08,2]],"id":57087188}],"con":true,"img":false}]}
{"op":"mcm","clk":"11540663664","pt":1719497067163,"mc":[{"id":"1.230178311","rc":[{"atl":[[3.85,0]],"id":65436514}],"con":true,"img":false}]}
{"op":"mcm","clk":"11540663675","pt":1719497067269,"mc":[{"id":"1.230178311","rc":[{"atl":[[3.9,5.62]],"id":65436514}],"con":true,"img":false}]}
{"op":"mcm","clk":"11540663693","pt":1719497067479,"mc":[{"id":"1.230178311","rc":[{"atb":[[2.04,0]],"id":57088863}],"con":true,"img":false}]}
{"op":"mcm","clk":"11540663703","pt":1719497067542,"mc":[{"id":"1.230178311","rc":[{"atb":[[1.02,24.65]],"id":57088863}],"con":true,"img":false}]}
{"op":"mcm","clk":"11540663733","pt":1719497067954,"mc":[{"id":"1.230178311","rc":[{"atl":[[3.85,0],[3.9,1]],"id":57087188},{"atb":[[3.45,1],[3.3,2.18]],"id":69142441},{"atb":[[2.02,1],[2.18,0]],"id":68392143}],"con":true,"img":false}]}
{"op":"mcm","clk":"11540663742","pt":1719497068060,"mc":[{"id":"1.230178311","rc":[{"atl":[[4.1,1]],"id":57087188},{"atl":[[3.95,0],[4.2,1]],"id":65436514},{"atl":[[11.5,0.84],[12,3.5]],"id":69142441},{"atb":[[1.85,0]],"id":68392143},{"atl":[[6.8,1],[6.6,5.34]],"id":57088863}],"con":true,"img":false}]}
{"op":"mcm","clk":"11540663756","pt":1719497068161,"mc":[{"id":"1.230178311","rc":[{"atl":[[3.9,0]],"id":65436514},{"atb":[[2.52,2]],"id":68392143}],"con":true,"img":false}]}
{"op":"mcm","clk":"11540663766","pt":1719497068264,"mc":[{"id":"1.230178311","rc":[{"atl":[[3.95,5.62]],"id":65436514}],"con":true,"img":false}]}
{"op":"mcm","clk":"11540663788","pt":1719497068466,"mc":[{"id":"1.230178311","rc":[{"atb":[[1.02,22.65]],"id":69142441}],"con":true,"img":false}]}
{"op":"mcm","clk":"11540663797","pt":1719497068570,"mc":[{"id":"1.230178311","rc":[{"atl":[[3.95,0]],"id":65436514},{"atb":[[3.85,2]],"id":69142441}],"con":true,"img":false}]}
{"op":"mcm","clk":"11540663809","pt":1719497068674,"mc":[{"id":"1.230178311","rc":[{"atl":[[4,5.62]],"id":65436514},{"atb":[[3.45,8.5],[3.25,0]],"id":69142441},{"atb":[[1.84,0],[2.52,4.5]],"id":68392143}],"con":true,"img":false}]}
{"op":"mcm","clk":"11540663819","pt":1719497068777,"mc":[{"id":"1.230178311","rc":[{"atb":[[3.45,1],[3.85,4.5]],"id":69142441},{"atb":[[2.42,10],[2.52,2]],"id":68392143}],"con":true,"img":false}]}
{"op":"mcm","clk":"11540663825","pt":1719497068879,"mc":[{"id":"1.230178311","rc":[{"atb":[[3.6,13.5]],"id":69142441},{"atb":[[2.42,5],[2.52,6.5]],"id":68392143}],"con":true,"img":false}]}
{"op":"mcm","clk":"11540663830","pt":1719497068935,"mc":[{"id":"1.230178311","rc":[{"atl":[[3.9,4.94],[9.4,0]],"id":57087188},{"atb":[[3.85,2]],"id":69142441},{"atl":[[11.5,4.58],[110,0]],"id":69142441},{"atb":[[2.42,15],[2.52,2]],"id":68392143}],"con":true,"img":false}]}
{"op":"mcm","clk":"11540663848","pt":1719497069248,"mc":[{"id":"1.230178311","rc":[{"atl":[[4.1,0],[4.2,11.62]],"id":65436514}],"con":true,"img":false}]}
{"op":"mcm","clk":"11540663893","pt":1719497069967,"mc":[{"id":"1.230178311","rc":[{"atl":[[3.85,1],[4.1,0],[3.9,3.94]],"id":57087188},{"atl":[[3.95,1],[4.2,10.62]],"id":65436514},{"atb":[[3.45,0]],"id":69142441},{"atl":[[11.5,5.58],[12,2.5]],"id":69142441},{"atb":[[2.02,0],[2.18,1]],"id":68392143},{"atl":[[6.8,0],[6.6,6.34]],"id":57088863}],"con":true,"img":false}]}
{"op":"mcm","clk":"11540663904","pt":1719497070078,"mc":[{"id":"1.230178311","rc":[{"atb":[[1.9,6.18],[1.75,0]],"id":57087188},{"atb":[[2,8.48],[1.81,0]],"id":65436514},{"atb":[[3.6,5],[3.85,4.5]],"id":69142441},{"atl":[[3.2,8.5],[5.8,0]],"id":55302014},{"atb":[[2.42,5],[2.52,4.5]],"id":68392143},{"atb":[[2.72,17.5],[2.1,0]],"id":57088863}],"con":true,"img":false}]}
{"op":"mcm","clk":"11540663907","pt":1719497070174,"mc":[{"id":"1.230178311","rc":[{"atb":[[3.6,15]],"id":69142441},{"atb":[[2.52,2]],"id":68392143}],"con":true,"img":false}]}
{"op":"mcm","clk":"11540663914","pt":1719497070278,"mc":[{"id":"1.230178311","rc":[{"atb":[[3.85,2]],"id":69142441},{"atb":[[2.42,15]],"id":68392143}],"con":true,"img":false}]}
{"op":"mcm","clk":"11540663924","pt":1719497070382,"mc":[{"id":"1.230178311","rc":[{"atb":[[3.6,5]],"id":69142441},{"atb":[[2.42,5],[2.52,4.5]],"id":68392143}],"con":true,"img":false}]}
{"op":"mcm","clk":"11540663936","pt":1719497070437,"mc":[{"id":"1.230178311","rc":[{"atb":[[3.85,6.5]],"id":69142441},{"atb":[[2.42,15],[2.52,2]],"id":68392143}],"con":true,"img":false}]}
{"op":"mcm","clk":"11540663953","pt":1719497070648,"mc":[{"id":"1.230178311","rc":[{"atb":[[3.6,10]],"id":69142441}],"con":true,"img":false}]}
{"op":"mcm","clk":"11540663965","pt":1719497070807,"mc":[{"id":"1.230178311","rc":[{"atb":[[3.85,2]],"id":69142441}],"con":true,"img":false}]}
{"op":"mcm","clk":"11540663975","pt":1719497070963,"mc":[{"id":"1.230178311","rc":[{"atb":[[3.6,5],[3.85,8.5]],"id":69142441}],"con":true,"img":false}]}
{"op":"mcm","clk":"11540664187","pt":1719497073250,"mc":[{"id":"1.230178311","rc":[{"atl":[[3.85,0],[4.1,1],[3.9,4.94]],"id":57087188},{"atl":[[3.95,0],[4.2,11.62]],"id":65436514},{"atb":[[3.45,1]],"id":69142441},{"atl":[[11.5,4.58],[12,3.5]],"id":69142441},{"atb":[[2.18,0]],"id":68392143},{"atl":[[6.8,1],[6.6,5.34]],"id":57088863}],"con":true,"img":false}]}
{"op":"mcm","clk":"11540664212","pt":1719497073568,"mc":[{"id":"1.230178311","rc":[{"atl":[[3.95,0.84]],"id":65436514}],"con":true,"img":false}]}
{"op":"mcm","clk":"11540664323","pt":1719497074766,"mc":[{"id":"1.230178311","rc":[{"atl":[[3.85,1],[4.1,0],[3.9,3.94]],"id":57087188},{"atl":[[3.95,1.84],[4.2,10.62]],"id":65436514},{"atb":[[3.45,0]],"id":69142441},{"atl":[[11.5,5.58],[12,2.5]],"id":69142441},{"atl":[[6.6,6.34]],"id":57088863}],"con":true,"img":false}]}
{"op":"mcm","clk":"11540664334","pt":1719497074869,"mc":[{"id":"1.230178311","rc":[{"atl":[[6.8,0]],"id":57088863}],"con":true,"img":false}]}
{"op":"mcm","clk":"11540664345","pt":1719497074975,"mc":[{"id":"1.230178311","rc":[{"atl":[[4,6.62],[3.95,0.84]],"id":65436514}],"con":true,"img":false}]}
{"op":"mcm","clk":"11540664500","pt":1719497076577,"mc":[{"id":"1.230178311","rc":[{"atb":[[1.93,0.3]],"id":57087188},{"spn":2.91,"spf":"NaN","id":57087188},{"spn":3.05,"spf":"NaN","id":65436514},{"atb":[[3.3,0]],"id":69142441},{"spn":7.17,"spf":"NaN","id":69142441},{"spn":2.35,"spf":"NaN","id":55302014},{"atb":[[1.83,0]],"id":68392143},{"spn":4.01,"spf":"NaN","id":68392143},{"atb":[[2.02,0]],"id":57088863},{"spn":4.54,"spf":"NaN","id":57088863}],"con":true,"img":false}]}
{"op":"mcm","clk":"11540664510","pt":1719497076680,"mc":[{"id":"1.230178311","rc":[{"atb":[[3.9,2.1]],"id":69142441},{"atb":[[2.42,5],[2.52,4.5]],"id":68392143}],"con":true,"img":false}]}
{"op":"mcm","clk":"11540664563","pt":1719497077252,"mc":[{"id":"1.230178311","rc":[{"atb":[[2.08,5.38]],"id":57087188},{"atl":[[3.75,4.22]],"id":57087188},{"atl":[[3.95,7.68]],"id":65436514},{"atb":[[3.95,4.04]],"id":69142441},{"atl":[[10.5,4.88]],"id":69142441},{"atl":[[2.82,3.31]],"id":55302014},{"atb":[[2.52,10.2]],"id":68392143},{"atb":[[2.98,5.96]],"id":57088863},{"atl":[[6.2,6.8]],"id":57088863}],"con":true,"img":false}]}
{"op":"mcm","clk":"11540664573","pt":1719497077358,"mc":[{"id":"1.230178311","rc":[{"atb":[[1.94,0]],"id":57087188},{"atl":[[3.8,0]],"id":57087188},{"atb":[[3.85,6.5],[3.35,0]],"id":69142441},{"atl":[[11,0]],"id":69142441},{"atl":[[3.15,0]],"id":55302014},{"atb":[[2.2,0]],"id":68392143},{"atb":[[2.8,10],[2.48,0]],"id":57088863},{"atl":[[6.4,0.05]],"id":57088863}],"con":true,"img":false}]}
{"op":"mcm","clk":"11540664583","pt":1719497077461,"mc":[{"id":"1.230178311","rc":[{"atl":[[4,1]],"id":65436514},{"atb":[[3.95,6.04]],"id":69142441},{"atb":[[2.72,10]],"id":57088863}],"con":true,"img":false}]}
{"op":"mcm","clk":"11540664590","pt":1719497077563,"mc":[{"id":"1.230178311","rc":[{"atl":[[11.5,1],[12,11.59]],"id":69142441},{"atl":[[2.8,0.84],[3.1,0]],"id":55302014},{"atl":[[6.6,5.5]],"id":57088863}],"con":true,"img":false}]}
{"op":"mcm","clk":"11540664603","pt":1719497077673,"mc":[{"id":"1.230178311","rc":[{"atb":[[1.98,0],[2.04,2.11]],"id":57087188},{"atb":[[3.85,0],[3.9,14.18]],"id":69142441}],"con":true,"img":false}]}
{"op":"mcm","clk":"11540664676","pt":1719497078579,"mc":[{"id":"1.230178311","rc":[{"atl":[[3.9,4.94]],"id":57087188}],"con":true,"img":false}]}
{"op":"mcm","clk":"11540664684","pt":1719497078677,"mc":[{"id":"1.230178311","rc":[{"atl":[[3.85,0]],"id":57087188}],"con":true,"img":false}]}
{"op":"mcm","clk":"11540664753","pt":1719497079194,"mc":[{"id":"1.230178311","rc":[{"atl":[[4.1,1]],"id":57087188},{"atl":[[6.6,4.5]],"id":57088863}],"con":true,"img":false}]}
{"op":"mcm","clk":"11540664764","pt":1719497079255,"mc":[{"id":"1.230178311","rc":[{"atl":[[3.95,9.26],[3.9,0]],"id":57087188},{"atl":[[4,0],[4.2,11.62]],"id":65436514},{"atl":[[11.5,0],[12,12.59]],"id":69142441},{"atl":[[6.8,1]],"id":57088863}],"con":true,"img":false}]}
{"op":"mcm","clk":"11540664816","pt":1719497079873,"mc":[{"id":"1.230178311","rc":[{"atl":[[4.1,0],[3.9,1]],"id":57087188},{"atl":[[4,1],[4.2,10.62]],"id":65436514},{"atl":[[11.5,1],[12,11.59]],"id":69142441},{"atl":[[6.8,0],[6.6,5.5]],"id":57088863}],"con":true,"img":false}]}
{"op":"mcm","clk":"11540664843","pt":1719497080289,"mc":[{"id":"1.230178311","rc":[{"atb":[[1.8,10],[1.9,0]],"id":57087188},{"atb":[[2,0],[2.08,8.48]],"id":65436514},{"atl":[[4,0],[3.6,1]],"id":65436514},{"atl":[[12,2.5],[12.5,8.7]],"id":69142441},{"atb":[[1.53,4.24],[1.47,0]],"id":55302014},{"atl":[[3.2,7.5],[3.1,1]],"id":55302014},{"atb":[[2.8,5],[2.68,15.96]],"id":57088863}],"con":true,"img":false}]}
{"op":"mcm","clk":"11540664847","pt":1719497080390,"mc":[{"id":"1.230178311","rc":[{"atb":[[1.99,10],[2.08,0]],"id":65436514},{"atl":[[4,15.38],[3.9,3.46],[4.2,0]],"id":65436514},{"atb":[[1.45,6.36],[1.53,0]],"id":55302014}],"con":true,"img":false}]}
{"op":"mcm","clk":"11540664861","pt":1719497080547,"mc":[{"id":"1.230178311","rc":[{"atl":[[3.95,0.84]],"id":65436514}],"con":true,"img":false}]}
{"op":"mcm","clk":"11540664864","pt":1719497080649,"mc":[{"id":"1.230178311","rc":[{"atl":[[3.55,4.47]],"id":65436514}],"con":true,"img":false}]}
{"op":"mcm","clk":"11540664873","pt":1719497080756,"mc":[{"id":"1.230178311","rc":[{"atl":[[4,0],[3.6,9.94],[3.9,0]],"id":65436514}],"con":true,"img":false}]}
{"op":"mcm","clk":"11540664932","pt":1719497081065,"mc":[{"id":"1.230178311","rc":[{"atl":[[3.95,0],[3.5,0.84]],"id":65436514}],"con":true,"img":false}]}
{"op":"mcm","clk":"11540664972","pt":1719497081584,"mc":[{"id":"1.230178311","rc":[{"atl":[[3.5,6.07]],"id":65436514}],"con":true,"img":false}]}
{"op":"mcm","clk":"11540664992","pt":1719497081791,"mc":[{"id":"1.230178311","rc":[{"atl":[[3.55,0]],"id":65436514}],"con":true,"img":false}]}
{"op":"mcm","clk":"11540665069","pt":1719497082782,"mc":[{"id":"1.230178311","rc":[{"atb":[[3.6,17.08]],"id":69142441}],"con":true,"img":false}]}
{"op":"mcm","clk":"11540665079","pt":1719497082886,"mc":[{"id":"1.230178311","rc":[{"atb":[[3.9,2.1]],"id":69142441}],"con":true,"img":false}]}
{"op":"mcm","clk":"11540665145","pt":1719497083777,"mc":[{"id":"1.230178311","rc":[{"atl":[[3.85,1],[3.9,0]],"id":57087188},{"atl":[[3.2,8.5],[3.1,0]],"id":55302014}],"con":true,"img":false}]}
{"op":"mcm","clk":"11540665183","pt":1719497084082,"mc":[{"id":"1.230178311","rc":[{"atl":[[3.85,0],[4.1,1]],"id":57087188},{"atl":[[3.6,8.94],[4.2,1]],"id":65436514},{"atl":[[11.5,0],[12,3.5]],"id":69142441},{"atl":[[3.2,7.5],[3.1,1]],"id":55302014},{"atl":[[6.8,1],[6.6,4.5]],"id":57088863}],"con":true,"img":false}]}
{"op":"mcm","clk":"11540665193","pt":1719497084181,"mc":[{"id":"1.230178311","rc":[{"atl":[[3.2,2.5],[3.05,5]],"id":55302014}],"con":true,"img":false}]}
{"op":"mcm","clk":"11540665309","pt":1719497085493,"mc":[{"id":"1.230178311","rc":[{"atl":[[3.85,1],[4.1,0]],"id":57087188},{"atl":[[3.6,9.94],[4.2,0]],"id":65436514},{"atl":[[11.5,1],[12,2.5]],"id":69142441},{"atl":[[3.2,3.5],[3.1,0]],"id":55302014},{"atl":[[6.8,0],[6.6,5.5]],"id":57088863}],"con":true,"img":false}]}
{"op":"mcm","clk":"11540665329","pt":1719497085872,"mc":[{"id":"1.230178311","rc":[{"atl":[[3.6,1],[4.2,16.02]],"id":65436514}],"con":true,"img":false}]}
{"op":"mcm","clk":"11540665382","pt":1719497086586,"mc":[{"id":"1.230178311","rc":[{"atb":[[1.93,0]],"id":57087188},{"atl":[[3.95,9.17]],"id":57087188},{"atb":[[1.6,0]],"id":55302014},{"atl":[[6.8,0]],"id":55302014},{"atb":[[1.99,0]],"id":57088863},{"atl":[[6.4,0]],"id":57088863}],"con":true,"img":false}]}
{"op":"mcm","clk":"11540665388","pt":1719497086689,"mc":[{"id":"1.230178311","rc":[{"atl":[[7,14.81]],"id":57088863}],"con":true,"img":false}]}
{"op":"mcm","clk":"11540665397","pt":1719497086802,"mc":[{"id":"1.230178311","rc":[{"atl":[[6.6,1]],"id":57088863}],"con":true,"img":false}]}
{"op":"mcm","clk":"11540665599","pt":1719497089190,"mc":[{"id":"1.230178311","rc":[{"atl":[[3.85,0],[3.9,1]],"id":57087188}],"con":true,"img":false}]}
{"op":"mcm","clk":"11540665604","pt":1719497089287,"mc":[{"id":"1.230178311","rc":[{"atl":[[3.85,8.46],[3.95,0],[4.1,1]],"id":57087188},{"atl":[[3.6,0],[4.2,17.02]],"id":65436514},{"atl":[[11.5,0],[12,3.5]],"id":69142441},{"atl":[[3.2,2.5],[3.1,1]],"id":55302014},{"atl":[[6,6.2],[5.9,2.5]],"id":68392143},{"atl":[[6.8,1],[6.6,0]],"id":57088863}],"con":true,"img":false}]}
{"op":"mcm","clk":"11540665612","pt":1719497089392,"mc":[{"id":"1.230178311","rc":[{"atl":[[3.85,0],[3.9,13.69]],"id":57087188},{"atl":[[7,2.5],[6.6,13.62]],"id":57088863}],"con":true,"img":false}]}
{"op":"mcm","clk":"11540665621","pt":1719497089494,"mc":[{"id":"1.230178311","rc":[{"atl":[[3.9,12.69]],"id":57087188},{"atl":[[6.8,18.24],[6.6,0]],"id":57088863}],"con":true,"img":false}]}
{"op":"mcm","clk":"11540665631","pt":1719497089609,"mc":[{"id":"1.230178311","rc":[{"atl":[[4.1,17.92],[3.9,0]],"id":57087188}],"con":true,"img":false}]}
{"op":"mcm","clk":"11540665698","pt":1719497090492,"mc":[{"id":"1.230178311","rc":[{"atl":[[2.8,7.07]],"id":55302014}],"con":true,"img":false}]}
{"op":"mcm","clk":"11540665705","pt":1719497090590,"mc":[{"id":"1.230178311","rc":[{"atb":[[3.9,0]],"id":69142441},{"atl":[[2.78,5],[3.05,0]],"id":55302014}],"con":true,"img":false}]}
{"op":"mcm","clk":"11540665711","pt":1719497090693,"mc":[{"id":"1.230178311","rc":[{"atl":[[2.82,12.08],[3.2,3.5],[3.1,0]],"id":55302014}],"con":true,"img":false}]}
{"op":"mcm","clk":"11540665718","pt":1719497090797,"mc":[{"id":"1.230178311","rc":[{"atl":[[3.85,1],[4.1,16.92]],"id":57087188},{"atl":[[3.6,1],[4.2,16.02]],"id":65436514},{"atl":[[11.5,1],[12,2.5]],"id":69142441},{"atl":[[2.78,0]],"id":55302014},{"atl":[[6.8,17.24],[6.6,1]],"id":57088863}],"con":true,"img":false}]}
{"op":"mcm","clk":"11540665789","pt":1719497091698,"mc":[{"id":"1.230178311","rc":[{"atl":[[2.82,0],[3.2,22.66]],"id":55302014}],"con":true,"img":false}]}
{"op":"mcm","clk":"11540665838","pt":1719497092285,"mc":[{"id":"1.230178311","rc":[{"atb":[[3.75,3]],"id":69142441}],"con":true,"img":false}]}
{"op":"mcm","clk":"11540666009","pt":1719497094607,"mc":[{"id":"1.230178311","rc":[{"atl":[[3.85,0],[3.9,1]],"id":57087188},{"atl":[[3.6,0],[4.2,17.02]],"id":65436514},{"atl":[[11.5,0],[12,3.5]],"id":69142441},{"atl":[[3.2,21.66],[3.1,1]],"id":55302014}],"con":true,"img":false}]}
{"op":"mcm","clk":"11540666016","pt":1719497094669,"mc":[{"id":"1.230178311","rc":[{"atl":[[4.1,17.92]],"id":57087188},{"atl":[[6.8,18.24],[6.6,0]],"id":57088863}],"con":true,"img":false}]}
{"op":"mcm","clk":"11540666025","pt":1719497094766,"mc":[{"id":"1.230178311","rc":[{"atl":[[5.1,25.6],[4.2,1]],"id":65436514},{"atl":[[6.8,1],[7,19.17]],"id":57088863}],"con":true,"img":false}]}
{"op":"mcm","clk":"11540666046","pt":1719497095181,"mc":[{"id":"1.230178311","rc":[{"atl":[[11.5,1],[12,2.5]],"id":69142441}],"con":true,"img":false}]}
{"op":"mcm","clk":"11540666063","pt":1719497095390,"mc":[{"id":"1.230178311","rc":[{"atl":[[4.1,16.92]],"id":57087188},{"atl":[[3.6,1]],"id":65436514},{"atl":[[6.6,1]],"id":57088863}],"con":true,"img":false}]}
{"op":"mcm","clk":"11540666073","pt":1719497095490,"mc":[{"id":"1.230178311","rc":[{"atl":[[5.1,2.5],[4.2,12.16]],"id":65436514},{"atb":[[3.6,5],[3.25,12.08]],"id":69142441},{"atl":[[12.5,0],[13.5,7.39]],"id":69142441},{"atl":[[6.8,0]],"id":57088863}],"con":true,"img":false}]}
{"op":"mcm","clk":"11540666623","pt":1719497101493,"mc":[{"id":"1.230178311","rc":[{"atb":[[2.14,6.46]],"id":65436514},{"atb":[[3.6,15],[3.25,0]],"id":69142441},{"atl":[[12.5,7.39],[13.5,0]],"id":69142441},{"atb":[[2.5,6.27]],"id":68392143}],"con":true,"img":false}]}
{"op":"mcm","clk":"11540666649","pt":1719497101798,"mc":[{"id":"1.230178311","rc":[{"atb":[[3.75,0]],"id":69142441}],"con":true,"img":false}]}
{"op":"mcm","clk":"11540666673","pt":1719497102005,"mc":[{"id":"1.230178311","rc":[{"atb":[[2.06,7.78]],"id":57087188},{"atb":[[2.58,2.11],[1.69,0]],"id":68392143}],"con":true,"img":false}]}
{"op":"mcm","clk":"11540666686","pt":1719497102113,"mc":[{"id":"1.230178311","rc":[{"atb":[[2.56,6.27],[2.52,7.7],[2.58,6.31]],"id":68392143}],"con":true,"img":false}]}
{"op":"mcm","clk":"11540666702","pt":1719497102211,"mc":[{"id":"1.230178311","rc":[{"atb":[[2.52,2]],"id":68392143}],"con":true,"img":false}]}
{"op":"mcm","clk":"11540666715","pt":1719497102314,"mc":[{"id":"1.230178311","rc":[{"atl":[[4.1,17.92],[3.9,0]],"id":57087188},{"atl":[[3.6,0],[4.2,13.16]],"id":65436514},{"atl":[[11.5,0],[12,3.5]],"id":69142441},{"atl":[[6.8,1],[6.6,0]],"id":57088863}],"con":true,"img":false}]}
{"op":"mcm","clk":"11540666723","pt":1719497102417,"mc":[{"id":"1.230178311","rc":[{"atb":[[3.6,5],[3.75,10]],"id":69142441},{"atl":[[12.5,0],[13,7.39]],"id":69142441}],"con":true,"img":false}]}
{"op":"mcm","clk":"11540666732","pt":1719497102521,"mc":[{"id":"1.230178311","rc":[{"atl":[[4.6,24.65],[4.1,1]],"id":57087188},{"atl":[[5.1,21.74],[4.2,1]],"id":65436514},{"atl":[[13.5,8]],"id":69142441},{"atl":[[2.82,3.12]],"id":55302014},{"atb":[[2.5,2.5]],"id":68392143}],"con":true,"img":false}]}
{"op":"mcm","clk":"11540666741","pt":1719497102574,"mc":[{"id":"1.230178311","rc":[{"atl":[[13,0]],"id":69142441}],"con":true,"img":false}]}
{"op":"mcm","clk":"11540666770","pt":1719497102992,"mc":[{"id":"1.230178311","rc":[{"atb":[[2.52,0]],"id":68392143}],"con":true,"img":false}]}
{"op":"mcm","clk":"11540666779","pt":1719497103096,"mc":[{"id":"1.230178311","rc":[{"atb":[[2.6,2]],"id":68392143}],"con":true,"img":false}]}
{"op":"mcm","clk":"11540666812","pt":1719497103508,"mc":[{"id":"1.230178311","rc":[{"atl":[[3.7,7.21]],"id":57087188}],"con":true,"img":false}]}
{"op":"mcm","clk":"11540666821","pt":1719497103608,"mc":[{"id":"1.230178311","rc":[{"atl":[[4.6,2.5],[3.75,0.84]],"id":57087188}],"con":true,"img":false}]}
{"op":"mcm","clk":"11540666830","pt":1719497103710,"mc":[{"id":"1.230178311","rc":[{"atl":[[4.1,9.46]],"id":57087188}],"con":true,"img":false}]}
{"op":"mcm","clk":"11540666885","pt":1719497104180,"mc":[{"id":"1.230178311","rc":[{"atl":[[3.65,0.84]],"id":57087188}],"con":true,"img":false}]}
{"op":"mcm","clk":"11540666904","pt":1719497104389,"mc":[{"id":"1.230178311","rc":[{"atl":[[3.75,8.9]],"id":57087188}],"con":true,"img":false}]}
{"op":"mcm","clk":"11540666915","pt":1719497104489,"mc":[{"id":"1.230178311","rc":[{"atb":[[2.06,2.5]],"id":57087188},{"atl":[[4.1,1]],"id":57087188}],"con":true,"img":false}]}
{"op":"mcm","clk":"11540666928","pt":1719497104698,"mc":[{"id":"1.230178311","rc":[{"atl":[[4.1,0],[3.9,1]],"id":57087188},{"atl":[[3.6,1],[4.2,0]],"id":65436514},{"atl":[[11.5,1]],"id":69142441},{"atl":[[6.8,0],[6.6,1]],"id":57088863}],"con":true,"img":false}]}
{"op":"mcm","clk":"11540666934","pt":1719497104795,"mc":[{"id":"1.230178311","rc":[{"atl":[[4.2,12.16]],"id":65436514},{"atl":[[12,2.5]],"id":69142441}],"con":true,"img":false}]}
{"op":"mcm","clk":"11540666951","pt":1719497105001,"mc":[{"id":"1.230178311","rc":[{"atl":[[5.1,2.5]],"id":65436514}],"con":true,"img":false}]}
{"op":"mcm","clk":"11540666965","pt":1719497105205,"mc":[{"id":"1.230178311","rc":[{"atl":[[4.1,1],[3.9,0]],"id":57087188},{"atl":[[3.6,0],[4.2,13.16]],"id":65436514},{"atl":[[11.5,0],[12,3.5]],"id":69142441},{"atl":[[6.8,1],[6.6,0]],"id":57088863}],"con":true,"img":false}]}
{"op":"mcm","clk":"11540666976","pt":1719497105317,"mc":[{"id":"1.230178311","rc":[{"atl":[[5.1,21.74],[4.2,1]],"id":65436514}],"con":true,"img":false}]}
{"op":"mcm","clk":"11540667022","pt":1719497106080,"mc":[{"id":"1.230178311","rc":[{"atl":[[4.1,0],[3.9,1]],"id":57087188},{"atl":[[3.6,1],[4.2,0]],"id":65436514},{"atl":[[6.8,0],[6.6,1]],"id":57088863}],"con":true,"img":false}]}
{"op":"mcm","clk":"11540667026","pt":1719497106184,"mc":[{"id":"1.230178311","rc":[{"atb":[[1.89,10],[1.8,0]],"id":57087188},{"atb":[[1.99,0],[1.78,16.24]],"id":65436514},{"atb":[[3.4,21.04],[3.75,0]],"id":69142441},{"atl":[[11.5,1],[12,2.5]],"id":69142441},{"atb":[[1.59,4.4],[1.45,0],[1.34,10]],"id":55302014},{"atb":[[2.46,12.92],[2.68,0]],"id":57088863},{"atl":[[7.4,13.62],[7,2.5]],"id":57088863}],"con":true,"img":false}]}
{"op":"mcm","clk":"11540667037","pt":1719497106291,"mc":[{"id":"1.230178311","rc":[{"atb":[[1.78,0],[1.95,16.24]],"id":65436514},{"atl":[[5.1,2.5],[4.2,12.16]],"id":65436514},{"atb":[[3.85,12.08],[3.4,10]],"id":69142441},{"atl":[[12,11.59],[13.5,0]],"id":69142441},{"atb":[[1.4,13.86],[1.34,0]],"id":55302014},{"atb":[[2.46,1],[2.76,10]],"id":57088863},{"atl":[[7.4,0],[7,12.5]],"id":57088863}],"con":true,"img":false}]}
{"op":"mcm","clk":"11540667046","pt":1719497106404,"mc":[{"id":"1.230178311","rc":[{"atl":[[3.6,0],[5.1,12.5],[4.2,1]],"id":65436514}],"con":true,"img":false}]}
{"op":"mcm","clk":"11540667054","pt":1719497106500,"mc":[{"id":"1.230178311","rc":[{"atl":[[2.72,4.22]],"id":55302014}],"con":true,"img":false}]}
{"op":"mcm","clk":"11540667062","pt":1719497106601,"mc":[{"id":"1.230178311","rc":[{"atl":[[2.8,0.84],[3.2,2.5],[2.7,4.22]],"id":55302014}],"con":true,"img":false}]}
{"op":"mcm","clk":"11540667099","pt":1719497107115,"mc":[{"id":"1.230178311","rc":[{"atl":[[2.82,0]],"id":55302014}],"con":true,"img":false}]}
{"op":"mcm","clk":"11540667107","pt":1719497107219,"mc":[{"id":"1.230178311","rc":[{"atl":[[2.8,0],[2.68,0.85]],"id":55302014}],"con":true,"img":false}]}
{"op":"mcm","clk":"11540667184","pt":1719497107997,"mc":[{"id":"1.230178311","rc":[{"atb":[[2.56,0],[2.6,8.27]],"id":68392143}],"con":true,"img":false}]}
{"op":"mcm","clk":"11540667397","pt":1719497110683,"mc":[{"id":"1.230178311","rc":[{"atl":[[4.1,1],[3.9,0]],"id":57087188},{"atl":[[11.5,0],[12,12.59]],"id":69142441},{"atl":[[6.8,1],[6.6,0]],"id":57088863}],"con":true,"img":false}]}
{"op":"mcm","clk":"11540667411","pt":1719497110884,"mc":[{"id":"1.230178311","rc":[{"atl":[[7,2.5],[6.6,13.62]],"id":57088863}],"con":true,"img":false}]}
{"op":"mcm","clk":"11540667461","pt":1719497111503,"mc":[{"id":"1.230178311","rc":[{"atb":[[1.89,0],[1.92,10]],"id":57087188},{"atb":[[1.89,16.24],[1.95,0]],"id":65436514},{"atl":[[4.3,1],[4.2,0]],"id":65436514},{"atb":[[2.8,15],[2.76,0]],"id":57088863}],"con":true,"img":false}]}
{"op":"mcm","clk":"11540667487","pt":1719497111720,"mc":[{"id":"1.230178311","rc":[{"atl":[[2.72,9.3],[2.7,0]],"id":55302014}],"con":true,"img":false}]}
{"op":"mcm","clk":"11540667500","pt":1719497111917,"mc":[{"id":"1.230178311","rc":[{"atl":[[2.72,4.22],[3.1,11.16]],"id":55302014}],"con":true,"img":false}]}
{"op":"mcm","clk":"11540667514","pt":1719497112125,"mc":[{"id":"1.230178311","rc":[{"atl":[[2.68,0]],"id":55302014}],"con":true,"img":false}]}
{"op":"mcm","clk":"11540667579","pt":1719497112701,"mc":[{"id":"1.230178311","rc":[{"atb":[[1.79,8.4]],"id":55302014}],"con":true,"img":false}]}
{"op":"mcm","clk":"11540667629","pt":1719497113211,"mc":[{"id":"1.230178311","rc":[{"atb":[[1.59,2.4]],"id":55302014}],"con":true,"img":false}]}
{"op":"mcm","clk":"11540667641","pt":1719497113313,"mc":[{"id":"1.230178311","rc":[{"atb":[[1.8,2]],"id":55302014}],"con":true,"img":false}]}
{"op":"mcm","clk":"11540667759","pt":1719497114612,"mc":[{"id":"1.230178311","rc":[{"atl":[[2.7,0.85]],"id":55302014}],"con":true,"img":false}]}
{"op":"mcm","clk":"11540667776","pt":1719497114816,"mc":[{"id":"1.230178311","rc":[{"atb":[[2.6,12.47]],"id":68392143}],"con":true,"img":false}]}
{"op":"mcm","clk":"11540667787","pt":1719497114921,"mc":[{"id":"1.230178311","rc":[{"atb":[[2.6,6.2],[2.58,18.65]],"id":68392143}],"con":true,"img":false}]}
{"op":"mcm","clk":"11540667880","pt":1719497116018,"mc":[{"id":"1.230178311","rc":[{"atl":[[6.8,18.24],[6.6,0]],"id":57088863}],"con":true,"img":false}]}
{"op":"mcm","clk":"11540667901","pt":1719497116220,"mc":[{"id":"1.230178311","rc":[{"atl":[[3.6,5.91]],"id":57087188}],"con":true,"img":false}]}
{"op":"mcm","clk":"11540667921","pt":1719497116425,"mc":[{"id":"1.230178311","rc":[{"atl":[[3.7,0]],"id":57087188}],"con":true,"img":false}]}
{"op":"mcm","clk":"11540667936","pt":1719497116632,"mc":[{"id":"1.230178311","rc":[{"atl":[[4,1],[4.1,0],[3.55,0.84],[3.75,8.06]],"id":57087188},{"atl":[[4.3,0],[4.4,1]],"id":65436514},{"atb":[[3.85,0],[3.8,20.62]],"id":69142441},{"atl":[[11.5,1],[12,11.59]],"id":69142441},{"atl":[[3.1,10.16],[3.55,1]],"id":55302014},{"atl":[[6.8,17.24],[6.6,1]],"id":57088863}],"con":true,"img":false}]}
{"op":"mcm","clk":"11540667947","pt":1719497116685,"mc":[{"id":"1.230178311","rc":[{"atl":[[3.65,7.6],[3.75,0]],"id":57087188},{"atl":[[5.1,2.5]],"id":65436514}],"con":true,"img":false}]}
{"op":"mcm","clk":"11540667956","pt":1719497116791,"mc":[{"id":"1.230178311","rc":[{"atl":[[4.3,12.16]],"id":65436514}],"con":true,"img":false}]}
{"op":"mcm","clk":"11540668053","pt":1719497117821,"mc":[{"id":"1.230178311","rc":[{"atl":[[4,0],[4.1,1]],"id":57087188},{"atl":[[13,1]],"id":69142441},{"atl":[[6.6,0],[7,3.5]],"id":57088863}],"con":true,"img":false}]}
{"op":"mcm","clk":"11540668060","pt":1719497117923,"mc":[{"id":"1.230178311","rc":[{"atl":[[11.5,0]],"id":69142441}],"con":true,"img":false}]}
{"op":"mcm","clk":"11540668076","pt":1719497118129,"mc":[{"id":"1.230178311","rc":[{"atl":[[12,2.5],[13,9.33]],"id":69142441}],"con":true,"img":false}]}
{"op":"mcm","clk":"11540668144","pt":1719497119006,"mc":[{"id":"1.230178311","rc":[{"atb":[[2.16,6.77]],"id":65436514}],"con":true,"img":false}]}
{"op":"mcm","clk":"11540668153","pt":1719497119112,"mc":[{"id":"1.230178311","rc":[{"atb":[[2.1,2.29]],"id":57087188},{"atb":[[2.18,3.3]],"id":65436514},{"atb":[[4,3.24]],"id":69142441},{"atl":[[2.7,5.81]],"id":55302014},{"atb":[[3,3.4]],"id":57088863}],"con":true,"img":false}]}
{"op":"mcm","clk":"11540668160","pt":1719497119211,"mc":[{"id":"1.230178311","rc":[{"atb":[[2.1,8.2]],"id":57087188},{"atb":[[2.18,12.71]],"id":65436514},{"atb":[[4,11.44]],"id":69142441},{"atl":[[12,3.5],[13,8.33]],"id":69142441},{"atl":[[2.72,0],[3.1,0],[2.68,5.82]],"id":55302014},{"atb":[[3,10.5]],"id":57088863},{"atl":[[6.8,1],[7,19.17]],"id":57088863}],"con":true,"img":false}]}
{"op":"mcm","clk":"11540668174","pt":1719497119418,"mc":[{"id":"1.230178311","rc":[{"atb":[[2.08,2]],"id":57087188},{"atb":[[2.16,2]],"id":65436514},{"atb":[[3.95,2]],"id":69142441},{"atb":[[2.98,0]],"id":57088863}],"con":true,"img":false}]}
{"op":"mcm","clk":"11540668188","pt":1719497119627,"mc":[{"id":"1.230178311","rc":[{"atl":[[4.6,0],[5,0],[5.4,0]],"id":57087188},{"atb":[[1.98,0],[2.04,0],[2.28,2.5],[2.2,5]],"id":65436514},{"atl":[[16,0],[11.5,2.5],[12,1],[13.5,5],[14,0]],"id":69142441},{"atl":[[3.6,0],[3.2,0],[3.4,0],[3.25,10],[2.94,2.5],[3.05,5]],"id":55302014},{"atb":[[2.8,10],[2.72,0],[2.92,5],[2.88,0],[3,13],[2.84,10]],"id":57088863}],"con":true,"img":false}]}
{"op":"mcm","clk":"11540668203","pt":1719497119734,"mc":[{"id":"1.230178311","rc":[{"atl":[[12,10.09],[13,0]],"id":69142441}],"con":true,"img":false}]}
{"op":"mcm","clk":"11540668213","pt":1719497119832,"mc":[{"id":"1.230178311","rc":[{"atl":[[3.1,1],[3.55,0]],"id":55302014}],"con":true,"img":false}]}
{"op":"mcm","clk":"11540668233","pt":1719497119988,"mc":[{"id":"1.230178311","rc":[{"atb":[[2.08,0]],"id":57087188}],"con":true,"img":false}]}
{"op":"mcm","clk":"11540668246","pt":1719497120096,"mc":[{"id":"1.230178311","rc":[{"atb":[[2.12,2]],"id":57087188},{"atb":[[2.14,2.11]],"id":65436514}],"con":true,"img":false}]}
{"op":"mcm","clk":"11540668274","pt":1719497120504,"mc":[{"id":"1.230178311","rc":[{"atb":[[2.16,0]],"id":65436514}],"con":true,"img":false}]}
{"op":"mcm","clk":"11540668282","pt":1719497120608,"mc":[{"id":"1.230178311","rc":[{"atb":[[2.2,7]],"id":65436514}],"con":true,"img":false}]}
{"op":"mcm","clk":"11540668301","pt":1719497120820,"mc":[{"id":"1.230178311","rc":[{"atb":[[3.95,0]],"id":69142441},{"atl":[[11.5,3.5],[12,9.09]],"id":69142441},{"atl":[[3.1,0]],"id":55302014}],"con":true,"img":false}]}
{"op":"mcm","clk":"11540668310","pt":1719497120917,"mc":[{"id":"1.230178311","rc":[{"atb":[[4.1,2]],"id":69142441},{"atl":[[12,10.09]],"id":69142441}],"con":true,"img":false}]}
{"op":"mcm","clk":"11540668319","pt":1719497121019,"mc":[{"id":"1.230178311","rc":[{"atl":[[11.5,2.5]],"id":69142441}],"con":true,"img":false}]}
{"op":"mcm","clk":"11540668386","pt":1719497121802,"mc":[{"id":"1.230178311","rc":[{"atb":[[3.85,13.44]],"id":69142441},{"atl":[[3.1,1]],"id":55302014},{"atb":[[2.8,0],[2.88,18]],"id":57088863}],"con":true,"img":false}]}
{"op":"mcm","clk":"11540668399","pt":1719497121898,"mc":[{"id":"1.230178311","rc":[{"atb":[[3.8,2.5]],"id":69142441}],"con":true,"img":false}]}
{"op":"mcm","clk":"11540668409","pt":1719497122008,"mc":[{"id":"1.230178311","rc":[{"atl":[[2.66,0.84]],"id":55302014}],"con":true,"img":false}]}
{"op":"mcm","clk":"11540668455","pt":1719497122629,"mc":[{"id":"1.230178311","rc":[{"atb":[[2.2,5]],"id":65436514}],"con":true,"img":false}]}
{"op":"mcm","clk":"11540668466","pt":1719497122728,"mc":[{"id":"1.230178311","rc":[{"atb":[[2.3,2]],"id":65436514}],"con":true,"img":false}]}
{"op":"mcm","clk":"11540668612","pt":1719497124290,"mc":[{"id":"1.230178311","rc":[{"atl":[[2.7,12.48]],"id":55302014}],"con":true,"img":false}]}
{"op":"mcm","clk":"11540668625","pt":1719497124394,"mc":[{"id":"1.230178311","rc":[{"atl":[[2.68,0]],"id":55302014}],"con":true,"img":false}]}
{"op":"mcm","clk":"11540668677","pt":1719497125121,"mc":[{"id":"1.230178311","rc":[{"atl":[[2.66,0]],"id":55302014}],"con":true,"img":false}]}
{"op":"mcm","clk":"11540668697","pt":1719497125326,"mc":[{"id":"1.230178311","rc":[{"atl":[[3.05,19.99],[2.7,5.81]],"id":55302014}],"con":true,"img":false}]}
{"op":"mcm","clk":"11540668713","pt":1719497125530,"mc":[{"id":"1.230178311","rc":[{"atb":[[1.64,5.61]],"id":55302014}],"con":true,"img":false}]}
{"op":"mcm","clk":"11540668784","pt":1719497126414,"mc":[{"id":"1.230178311","rc":[{"atb":[[2.28,6.38]],"id":65436514},{"atb":[[2.58,22.23]],"id":68392143}],"con":true,"img":false}]}
{"op":"mcm","clk":"11540668791","pt":1719497126520,"mc":[{"id":"1.230178311","rc":[{"atl":[[11.5,3.5],[12,9.09]],"id":69142441},{"atl":[[3.1,0],[3.55,1]],"id":55302014}],"con":true,"img":false}]}
{"op":"mcm","clk":"11540668808","pt":1719497126728,"mc":[{"id":"1.230178311","rc":[{"atl":[[12,10.09]],"id":69142441},{"atl":[[3.1,1],[3.55,0]],"id":55302014}],"con":true,"img":false}]}
{"op":"mcm","clk":"11540668816","pt":1719497126833,"mc":[{"id":"1.230178311","rc":[{"atl":[[11.5,2.5]],"id":69142441}],"con":true,"img":false}]}
{"op":"mcm","clk":"11540668828","pt":1719497126944,"mc":[{"id":"1.230178311","rc":[{"atb":[[2.04,7.49]],"id":57087188}],"con":true,"img":false}]}
{"op":"mcm","clk":"11540668864","pt":1719497127405,"mc":[{"id":"1.230178311","rc":[{"atl":[[2.72,3.3]],"id":55302014}],"con":true,"img":false}]}
{"op":"mcm","clk":"11540668881","pt":1719497127612,"mc":[{"id":"1.230178311","rc":[{"atb":[[2.1,5.91]],"id":57087188},{"atb":[[2.18,9.41]],"id":65436514},{"atb":[[4,8.2]],"id":69142441},{"atb":[[1.59,0]],"id":55302014}],"con":true,"img":false}]}
{"op":"mcm","clk":"11540668891","pt":1719497127718,"mc":[{"id":"1.230178311","rc":[{"atb":[[2.12,5]],"id":57087188},{"atb":[[2.3,4.5]],"id":65436514},{"atb":[[4.1,5.49]],"id":69142441}],"con":true,"img":false}]}
{"op":"mcm","clk":"11540668944","pt":1719497128640,"mc":[{"id":"1.230178311","rc":[{"atl":[[3.5,8.18]],"id":57087188}],"con":true,"img":false}]}
{"op":"mcm","clk":"11540668953","pt":1719497128696,"mc":[{"id":"1.230178311","rc":[{"atl":[[3.45,5.91]],"id":57087188}],"con":true,"img":false}]}
{"op":"mcm","clk":"11540668962","pt":1719497128801,"mc":[{"id":"1.230178311","rc":[{"atl":[[3.6,0],[3.65,0.84]],"id":57087188}],"con":true,"img":false}]}
{"op":"mcm","clk":"11540668969","pt":1719497128901,"mc":[{"id":"1.230178311","rc":[{"atl":[[3.45,0],[3.55,14.93]],"id":57087188}],"con":true,"img":false}]}
{"op":"mcm","clk":"11540668978","pt":1719497129008,"mc":[{"id":"1.230178311","rc":[{"atl":[[3.4,0.84]],"id":57087188}],"con":true,"img":false}]}
{"op":"mcm","clk":"11540668995","pt":1719497129240,"mc":[{"id":"1.230178311","rc":[{"atl":[[3.55,14.09],[3.65,0]],"id":57087188}],"con":true,"img":false}]}
{"op":"mcm","clk":"11540669024","pt":1719497129627,"mc":[{"id":"1.230178311","rc":[{"atl":[[3.4,0]],"id":57087188}],"con":true,"img":false}]}
{"op":"mcm","clk":"11540669032","pt":1719497129731,"mc":[{"id":"1.230178311","rc":[{"atl":[[4.6,2.5],[5,5],[5.4,10]],"id":57087188}],"con":true,"img":false}]}
{"op":"mcm","clk":"11540669042","pt":1719497129828,"mc":[{"id":"1.230178311","rc":[{"atl":[[4.1,23.27],[3.55,0]],"id":57087188}],"con":true,"img":false}]}
{"op":"mcm","clk":"11540669072","pt":1719497130346,"mc":[{"id":"1.230178311","rc":[{"atb":[[2.04,5.38],[2.16,2.11]],"id":57087188},{"atb":[[2.14,0],[2.34,2.11]],"id":65436514}],"con":true,"img":false}]}
{"op":"mcm","clk":"11540669114","pt":1719497131019,"mc":[{"id":"1.230178311","rc":[{"atl":[[2.94,11.62]],"id":55302014}],"con":true,"img":false}]}
{"op":"mcm","clk":"11540669120","pt":1719497131116,"mc":[{"id":"1.230178311","rc":[{"atl":[[3.05,5]],"id":55302014}],"con":true,"img":false}]}
{"op":"mcm","clk":"11540669133","pt":1719497131226,"mc":[{"id":"1.230178311","rc":[{"atb":[[2.28,2.5]],"id":65436514}],"con":true,"img":false}]}
{"op":"mcm","clk":"11540669141","pt":1719497131326,"mc":[{"id":"1.230178311","rc":[{"atb":[[2.12,3]],"id":57087188}],"con":true,"img":false}]}
{"op":"mcm","clk":"11540669149","pt":1719497131427,"mc":[{"id":"1.230178311","rc":[{"atb":[[2.18,2]],"id":57087188}],"con":true,"img":false}]}
{"op":"mcm","clk":"11540669156","pt":1719497131530,"mc":[{"id":"1.230178311","rc":[{"atb":[[2.16,8.79]],"id":57087188},{"atb":[[4.2,10.27]],"id":69142441},{"atb":[[3.05,14.86]],"id":57088863}],"con":true,"img":false}]}
{"op":"mcm","clk":"11540669163","pt":1719497131634,"mc":[{"id":"1.230178311","rc":[{"atb":[[2.34,7.36]],"id":65436514}],"con":true,"img":false}]}
{"op":"mcm","clk":"11540669174","pt":1719497131739,"mc":[{"id":"1.230178311","rc":[{"atb":[[2.1,0]],"id":57087188},{"atb":[[4,0]],"id":69142441},{"atb":[[3,5.9]],"id":57088863}],"con":true,"img":false}]}
{"op":"mcm","clk":"11540669178","pt":1719497131839,"mc":[{"id":"1.230178311","rc":[{"atb":[[2.3,2.5],[2.18,0]],"id":65436514}],"con":true,"img":false}]}
{"op":"mcm","clk":"11540669191","pt":1719497131944,"mc":[{"id":"1.230178311","rc":[{"atb":[[2.36,2]],"id":65436514}],"con":true,"img":false}]}
{"op":"mcm","clk":"11540669198","pt":1719497132049,"mc":[{"id":"1.230178311","rc":[{"atl":[[11.5,3.5],[12,9.09]],"id":69142441},{"atl":[[3.1,0]],"id":55302014}],"con":true,"img":false}]}
{"op":"mcm","clk":"11540669253","pt":1719497132822,"mc":[{"id":"1.230178311","rc":[{"atb":[[2.98,3.12]],"id":57088863}],"con":true,"img":false}]}
{"op":"mcm","clk":"11540669304","pt":1719497133644,"mc":[{"id":"1.230178311","rc":[{"atb":[[4.1,3.49]],"id":69142441}],"con":true,"img":false}]}
{"op":"mcm","clk":"11540669308","pt":1719497133748,"mc":[{"id":"1.230178311","rc":[{"atb":[[1.02,24.65]],"id":69142441},{"atl":[[11.5,2.5],[12,10.09]],"id":69142441},{"atl":[[3.1,1]],"id":55302014}],"con":true,"img":false}]}
{"op":"mcm","clk":"11540669324","pt":1719497133853,"mc":[{"id":"1.230178311","rc":[{"atb":[[1.78,10.38],[1.92,0],[2.16,2.11]],"id":57087188},{"atl":[[4,1],[4.1,22.27]],"id":57087188},{"atb":[[1.89,0]],"id":65436514},{"atl":[[4,1],[4.4,0]],"id":65436514},{"atb":[[3.6,0],[3.85,0],[3.95,2.5],[3.8,0],[3.4,0],[4.2,20.54]],"id":69142441},{"atl":[[11.5,3.5],[12,9.09]],"id":69142441},{"atb":[[1.48,7.73]],"id":55302014},{"atl":[[3.1,0]],"id":55302014},{"atb":[[2.56,28.44],[2.58,5.69]],"id":68392143},{"atb":[[2.94,11.8],[2.88,0]],"id":57088863},{"atl":[[6.8,0],[6.6,1]],"id":57088863}],"con":true,"img":false}]}
{"op":"mcm","clk":"11540669329","pt":1719497133906,"mc":[{"id":"1.230178311","rc":[{"atb":[[2.08,5]],"id":65436514},{"atb":[[3.75,6.98]],"id":69142441},{"atb":[[1.4,5]],"id":55302014},{"atb":[[2.68,15.9]],"id":57088863}],"con":true,"img":false}]}
{"op":"mcm","clk":"11540669346","pt":1719497134013,"mc":[{"id":"1.230178311","rc":[{"atl":[[5,2.5]],"id":65436514},{"atb":[[4.2,10.27]],"id":69142441},{"atl":[[3.55,1]],"id":55302014},{"atb":[[2.54,2.5]],"id":68392143},{"atb":[[2.94,0]],"id":57088863}],"con":true,"img":false}]}
{"op":"mcm","clk":"11540669353","pt":1719497134115,"mc":[{"id":"1.230178311","rc":[{"atl":[[5.1,0],[5.5,0],[5.9,0]],"id":65436514},{"atb":[[2.5,0],[2.42,0],[2.34,0]],"id":68392143}],"con":true,"img":false}]}
{"op":"mcm","clk":"11540669518","pt":1719497136017,"mc":[{"id":"1.230178311","rc":[{"atl":[[3.45,0.84]],"id":57087188}],"con":true,"img":false}]}
{"op":"mcm","clk":"11540669524","pt":1719497136122,"mc":[{"id":"1.230178311","rc":[{"atb":[[1.79,14.29]],"id":55302014}],"con":true,"img":false}]}
{"op":"mcm","clk":"11540669536","pt":1719497136329,"mc":[{"id":"1.230178311","rc":[{"atb":[[2.12,0]],"id":57087188},{"atb":[[2.3,0]],"id":65436514},{"atb":[[4.1,0]],"id":69142441},{"atb":[[3,2.5]],"id":57088863}],"con":true,"img":false}]}
{"op":"mcm","clk":"11540669542","pt":1719497136432,"mc":[{"id":"1.230178311","rc":[{"atb":[[2.18,4.68]],"id":57087188},{"atb":[[2.36,4]],"id":65436514},{"atb":[[4.3,2.88]],"id":69142441}],"con":true,"img":false}]}
{"op":"mcm","clk":"11540669577","pt":1719497136850,"mc":[{"id":"1.230178311","rc":[{"atb":[[2.04,0]],"id":57087188},{"spn":2.81,"spf":"NaN","id":57087188},{"spn":2.93,"spf":"NaN","id":65436514},{"spn":7.4,"spf":"NaN","id":69142441},{"spn":2.25,"spf":"NaN","id":55302014},{"spn":4.05,"spf":"NaN","id":68392143},{"spn":4.62,"spf":"NaN","id":57088863}],"con":true,"img":false}]}
{"op":"mcm","clk":"11540669592","pt":1719497137048,"mc":[{"id":"1.230178311","rc":[{"atb":[[4.3,9.84]],"id":69142441},{"atl":[[10.5,7.3]],"id":69142441}],"con":true,"img":false}]}
{"op":"mcm","clk":"11540669602","pt":1719497137254,"mc":[{"id":"1.230178311","rc":[{"atb":[[1.78,0],[1.95,0],[2.1,2.5],[1.99,0],[2.02,5],[2.06,0],[1.88,9.36],[2.18,8.14]],"id":57087188},{"atb":[[1.74,9],[2.08,0]],"id":65436514},{"atl":[[4,0],[4.3,13.16]],"id":65436514},{"atb":[[3.4,16.82],[3.75,0]],"id":69142441},{"atl":[[11.5,13.02],[12,0]],"id":69142441},{"atb":[[1.48,0],[1.34,10]],"id":55302014},{"atb":[[2.56,0],[2.42,11.9]],"id":68392143},{"atb":[[2.88,10],[2.68,0]],"id":57088863}],"con":true,"img":false}]}
{"op":"mcm","clk":"11540669617","pt":1719497137318,"mc":[{"id":"1.230178311","rc":[{"atb":[[1.92,9]],"id":65436514},{"atb":[[3.85,19.68],[3.4,0]],"id":69142441},{"atl":[[10.5,14.61],[11.5,3.5]],"id":69142441},{"atb":[[1.4,13.11],[1.34,0]],"id":55302014},{"atb":[[2.42,0],[2.6,12.4]],"id":68392143}],"con":true,"img":false}]}
{"op":"mcm","clk":"11540669623","pt":1719497137419,"mc":[{"id":"1.230178311","rc":[{"atl":[[4.1,23.27]],"id":57087188},{"atb":[[1.74,0]],"id":65436514},{"atl":[[4.3,1],[5,21.74]],"id":65436514},{"atl":[[12,1]],"id":69142441},{"atl":[[3.1,1],[3.55,0]],"id":55302014},{"atl":[[6.8,1],[6.6,0]],"id":57088863}],"con":true,"img":false}]}
{"op":"mcm","clk":"11540669634","pt":1719497137525,"mc":[{"id":"1.230178311","rc":[{"atl":[[4,0]],"id":57087188},{"atl":[[11.5,2.5]],"id":69142441}],"con":true,"img":false}]}
{"op":"mcm","clk":"11540669704","pt":1719497138246,"mc":[{"id":"1.230178311","rc":[{"atl":[[11.5,3.5],[12,0]],"id":69142441},{"atl":[[3.1,0]],"id":55302014}],"con":true,"img":false}]}
{"op":"mcm","clk":"11540669746","pt":1719497138810,"mc":[{"id":"1.230178311","rc":[{"atb":[[4.1,4.25]],"id":69142441},{"atl":[[12,1]],"id":69142441}],"con":true,"img":false}]}
{"op":"mcm","clk":"11540669756","pt":1719497138912,"mc":[{"id":"1.230178311","rc":[{"atl":[[11.5,2.5]],"id":69142441}],"con":true,"img":false}]}
{"op":"mcm","clk":"11540669793","pt":1719497139335,"mc":[{"id":"1.230178311","rc":[{"atb":[[2.58,2.11]],"id":68392143}],"con":true,"img":false}]}
{"op":"mcm","clk":"11540669801","pt":1719497139433,"mc":[{"id":"1.230178311","rc":[{"atl":[[3.1,1]],"id":55302014}],"con":true,"img":false}]}
{"op":"mcm","clk":"11540669848","pt":1719497140107,"mc":[{"id":"1.230178311","rc":[{"atl":[[4,1],[4.1,22.27]],"id":57087188},{"atl":[[11.5,3.5],[12,0]],"id":69142441},{"atl":[[6.8,0],[6.6,1]],"id":57088863}],"con":true,"img":false}]}
{"op":"mcm","clk":"11540669880","pt":1719497140523,"mc":[{"id":"1.230178311","rc":[{"atl":[[12,1]],"id":69142441},{"atl":[[3.1,0]],"id":55302014}],"con":true,"img":false}]}
{"op":"mcm","clk":"11540669890","pt":1719497140635,"mc":[{"id":"1.230178311","rc":[{"atl":[[11.5,2.5]],"id":69142441}],"con":true,"img":false}]}
{"op":"mcm","clk":"11540669905","pt":1719497140834,"mc":[{"id":"1.230178311","rc":[{"atl":[[3.45,4.3]],"id":57087188}],"con":true,"img":false}]}
{"op":"mcm","clk":"11540669913","pt":1719497140938,"mc":[{"id":"1.230178311","rc":[{"atl":[[3.4,4.31]],"id":57087188}],"con":true,"img":false}]}
{"op":"mcm","clk":"11540669923","pt":1719497141041,"mc":[{"id":"1.230178311","rc":[{"atl":[[4.1,0],[3.5,0]],"id":57087188}],"con":true,"img":false}]}
{"op":"mcm","clk":"11540669974","pt":1719497141712,"mc":[{"id":"1.230178311","rc":[{"atl":[[11.5,3.5]],"id":69142441}],"con":true,"img":false}]}
{"op":"mcm","clk":"11540669983","pt":1719497141817,"mc":[{"id":"1.230178311","rc":[{"atl":[[12,0]],"id":69142441}],"con":true,"img":false}]}
{"op":"mcm","clk":"11540670070","pt":1719497142749,"mc":[{"id":"1.230178311","rc":[{"atl":[[2.72,0],[2.68,8.57]],"id":55302014}],"con":true,"img":false}]}
{"op":"mcm","clk":"11540670082","pt":1719497142852,"mc":[{"id":"1.230178311","rc":[{"atl":[[2.72,11.64],[2.94,2.5],[2.7,0.85]],"id":55302014}],"con":true,"img":false}]}
{"op":"mcm","clk":"11540670095","pt":1719497142907,"mc":[{"id":"1.230178311","rc":[{"atl":[[2.72,0],[2.94,16.89]],"id":55302014}],"con":true,"img":false}]}
{"op":"mcm","clk":"11540670108","pt":1719497143012,"mc":[{"id":"1.230178311","rc":[{"atl":[[11.5,2.5],[12,1]],"id":69142441},{"atl":[[3.1,1],[2.66,0.84]],"id":55302014}],"con":true,"img":false}]}
{"op":"mcm","clk":"11540670150","pt":1719497143486,"mc":[{"id":"1.230178311","rc":[{"atb":[[1.82,9],[1.92,0]],"id":65436514},{"atl":[[4.3,0],[4.6,1]],"id":65436514},{"atl":[[11.5,3.5],[12,0]],"id":69142441},{"atl":[[3.1,0]],"id":55302014},{"atb":[[2.6,6.2],[2.58,26.91]],"id":68392143},{"atb":[[2.88,0],[2.9,10]],"id":57088863}],"con":true,"img":false}]}
{"op":"mcm","clk":"11540670155","pt":1719497143541,"mc":[{"id":"1.230178311","rc":[{"atl":[[3.35,0.84]],"id":57087188}],"con":true,"img":false}]}
{"op":"mcm","clk":"11540670161","pt":1719497143643,"mc":[{"id":"1.230178311","rc":[{"atb":[[4.4,11.13]],"id":69142441}],"con":true,"img":false}]}
{"op":"mcm","clk":"11540670171","pt":1719497143737,"mc":[{"id":"1.230178311","rc":[{"atb":[[2.36,11.56]],"id":65436514},{"atb":[[4.2,0]],"id":69142441}],"con":true,"img":false}]}
{"op":"mcm","clk":"11540670181","pt":1719497143840,"mc":[{"id":"1.230178311","rc":[{"atb":[[2.34,2.11]],"id":65436514},{"atb":[[2.46,0]],"id":57088863}],"con":true,"img":false}]}
{"op":"mcm","clk":"11540670191","pt":1719497143942,"mc":[{"id":"1.230178311","rc":[{"atb":[[4.1,0]],"id":69142441}],"con":true,"img":false}]}
{"op":"mcm","clk":"11540670255","pt":1719497144722,"mc":[{"id":"1.230178311","rc":[{"atb":[[4.3,9.83]],"id":69142441},{"atl":[[11.5,2.5],[13,1]],"id":69142441}],"con":true,"img":false}]}
{"op":"mcm","clk":"11540670271","pt":1719497144940,"mc":[{"id":"1.230178311","rc":[{"atb":[[2.18,5.46]],"id":57087188},{"atl":[[3.5,5.38]],"id":57087188},{"atb":[[2.36,9.56]],"id":65436514},{"atb":[[4.3,6.95]],"id":69142441}],"con":true,"img":false}]}
{"op":"mcm","clk":"11540670277","pt":1719497145036,"mc":[{"id":"1.230178311","rc":[{"atb":[[2.2,2.7]],"id":57087188},{"atb":[[2.38,3.8]],"id":65436514},{"atb":[[4.5,2]],"id":69142441},{"atb":[[2.6,10]],"id":68392143},{"atb":[[3.1,2.6]],"id":57088863}],"con":true,"img":false}]}
{"op":"mcm","clk":"11540670286","pt":1719497145136,"mc":[{"id":"1.230178311","rc":[{"atb":[[2.2,7.96]],"id":57087188},{"atb":[[4.3,0]],"id":69142441}],"con":true,"img":false}]}
{"op":"mcm","clk":"11540670297","pt":1719497145240,"mc":[{"id":"1.230178311","rc":[{"atb":[[4.4,18.08]],"id":69142441},{"atb":[[3.1,9.66]],"id":57088863}],"con":true,"img":false}]}
{"op":"mcm","clk":"11540670312","pt":1719497145343,"mc":[{"id":"1.230178311","rc":[{"atl":[[3.5,0]],"id":57087188}],"con":true,"img":false}]}
{"op":"mcm","clk":"11540670321","pt":1719497145450,"mc":[{"id":"1.230178311","rc":[{"atb":[[2.18,2]],"id":57087188},{"atb":[[3.05,0]],"id":57088863}],"con":true,"img":false}]}
{"op":"mcm","clk":"11540670330","pt":1719497145550,"mc":[{"id":"1.230178311","rc":[{"atb":[[2.98,0]],"id":57088863}],"con":true,"img":false}]}
{"op":"mcm","clk":"11540670381","pt":1719497146166,"mc":[{"id":"1.230178311","rc":[{"atl":[[3.45,9.46],[3.4,0]],"id":57087188},{"atl":[[10.5,7.3],[11,10]],"id":69142441}],"con":true,"img":false}]}
{"op":"mcm","clk":"11540670394","pt":1719497146220,"mc":[{"id":"1.230178311","rc":[{"atb":[[3.85,20.68],[4.4,11.13]],"id":69142441},{"atl":[[13,0],[13.5,6]],"id":69142441},{"atl":[[5.6,0],[5.5,4.09]],"id":68392143}],"con":true,"img":false}]}
{"op":"mcm","clk":"11540670400","pt":1719497146321,"mc":[{"id":"1.230178311","rc":[{"atl":[[4,11.32],[3.45,4.3]],"id":57087188}],"con":true,"img":false}]}
{"op":"mcm","clk":"11540670415","pt":1719497146427,"mc":[{"id":"1.230178311","rc":[{"atl":[[4,10.32]],"id":57087188},{"atb":[[3.85,19.68]],"id":69142441},{"atl":[[13,1],[13.5,5]],"id":69142441},{"atl":[[5.6,1]],"id":68392143},{"atl":[[7,20.17]],"id":57088863}],"con":true,"img":false}]}
{"op":"mcm","clk":"11540670421","pt":1719497146526,"mc":[{"id":"1.230178311","rc":[{"atl":[[3.35,0]],"id":57087188},{"atl":[[5.5,3.09]],"id":68392143},{"atl":[[6.6,0]],"id":57088863}],"con":true,"img":false}]}
{"op":"mcm","clk":"11540670443","pt":1719497146836,"mc":[{"id":"1.230178311","rc":[{"atb":[[4.5,8.2]],"id":69142441}],"con":true,"img":false}]}
{"op":"mcm","clk":"11540670455","pt":1719497147042,"mc":[{"id":"1.230178311","rc":[{"atb":[[2.18,0]],"id":57087188}],"con":true,"img":false}]}
{"op":"mcm","clk":"11540670461","pt":1719497147143,"mc":[{"id":"1.230178311","rc":[{"atb":[[2.22,2]],"id":57087188}],"con":true,"img":false}]}
{"op":"mcm","clk":"11540670477","pt":1719497147352,"mc":[{"id":"1.230178311","rc":[{"atl":[[4,11.32]],"id":57087188},{"atb":[[2.36,7.56]],"id":65436514},{"atl":[[6.6,1]],"id":57088863}],"con":true,"img":false}]}
{"op":"mcm","clk":"11540670485","pt":1719497147456,"mc":[{"id":"1.230178311","rc":[{"atb":[[2.4,2]],"id":65436514},{"atl":[[7,19.17]],"id":57088863}],"con":true,"img":false}]}
{"op":"mcm","clk":"11540670529","pt":1719497147921,"mc":[{"id":"1.230178311","rc":[{"atl":[[4,10.32],[3.95,1]],"id":57087188},{"atl":[[13,0],[13.5,6]],"id":69142441}],"con":true,"img":false}]}
{"op":"mcm","clk":"11540670535","pt":1719497148021,"mc":[{"id":"1.230178311","rc":[{"atl":[[4.1,1]],"id":57087188},{"atl":[[6.8,1],[6.6,0]],"id":57088863}],"con":true,"img":false}]}
{"op":"mcm","clk":"11540670562","pt":1719497148443,"mc":[{"id":"1.230178311","rc":[{"atl":[[2.94,2.5],[2.7,10.27]],"id":55302014}],"con":true,"img":false}]}
{"op":"mcm","clk":"11540670604","pt":1719497149159,"mc":[{"id":"1.230178311","rc":[{"atb":[[2.58,30.49]],"id":68392143}],"con":true,"img":false}]}
{"op":"mcm","clk":"11540670616","pt":1719497149263,"mc":[{"id":"1.230178311","rc":[{"atb":[[2.22,6.82]],"id":57087188}],"con":true,"img":false}]}
{"op":"mcm","clk":"11540670639","pt":1719497149419,"mc":[{"id":"1.230178311","rc":[{"atb":[[2.2,2.7]],"id":57087188}],"con":true,"img":false}]}
{"op":"mcm","clk":"11540670667","pt":1719497149727,"mc":[{"id":"1.230178311","rc":[{"atl":[[4,11.32],[3.95,0],[4.1,0]],"id":57087188},{"atb":[[1.82,0],[1.72,6.3]],"id":65436514},{"atl":[[4.8,1],[4.6,0]],"id":65436514},{"atl":[[13,1],[13.5,5]],"id":69142441},{"atb":[[2.54,43],[2.58,5.69]],"id":68392143},{"atl":[[7.4,0],[5.7,2.5],[6.6,0],[5.9,0]],"id":68392143},{"atl":[[6.8,0],[6.6,1]],"id":57088863}],"con":true,"img":false}]}
{"op":"mcm","clk":"11540670679","pt":1719497149832,"mc":[{"id":"1.230178311","rc":[{"atl":[[6,0],[5.7,7.5]],"id":68392143}],"con":true,"img":false}]}
{"op":"mcm","clk":"11540670702","pt":1719497150141,"mc":[{"id":"1.230178311","rc":[{"atb":[[2.34,5.85]],"id":65436514}],"con":true,"img":false}]}
{"op":"mcm","clk":"11540670789","pt":1719497151071,"mc":[{"id":"1.230178311","rc":[{"atl":[[2.68,11.95]],"id":55302014}],"con":true,"img":false}]}
{"op":"mcm","clk":"11540670798","pt":1719497151121,"mc":[{"id":"1.230178311","rc":[{"atl":[[3.95,1]],"id":57087188},{"atb":[[3.85,20.68]],"id":69142441},{"atl":[[13.5,6]],"id":69142441},{"atl":[[5.6,0],[5.5,4.09]],"id":68392143}],"con":true,"img":false}]}
{"op":"mcm","clk":"11540670802","pt":1719497151223,"mc":[{"id":"1.230178311","rc":[{"atl":[[4,10.32]],"id":57087188},{"atl":[[13,0]],"id":69142441}],"con":true,"img":false}]}
{"op":"mcm","clk":"11540670822","pt":1719497151441,"mc":[{"id":"1.230178311","rc":[{"atl":[[4.1,1]],"id":57087188},{"atb":[[3.85,19.68]],"id":69142441},{"atl":[[13,1],[13.5,5]],"id":69142441},{"atl":[[5.6,1]],"id":68392143},{"atl":[[6.6,0],[7,20.17]],"id":57088863}],"con":true,"img":false}]}
{"op":"mcm","clk":"11540670830","pt":1719497151535,"mc":[{"id":"1.230178311","rc":[{"atl":[[3.95,0]],"id":57087188},{"atl":[[5.5,3.09]],"id":68392143}],"con":true,"img":false}]}
{"op":"mcm","clk":"11540670840","pt":1719497151638,"mc":[{"id":"1.230178311","rc":[{"atl":[[7,3.5],[7.8,19.71]],"id":57088863}],"con":true,"img":false}]}
{"op":"mcm","clk":"11540671007","pt":1719497153751,"mc":[{"id":"1.230178311","rc":[{"atb":[[2.2,0]],"id":57087188},{"atb":[[2.38,0]],"id":65436514},{"atb":[[2.6,6.2]],"id":68392143}],"con":true,"img":false}]}
{"op":"mcm","clk":"11540671028","pt":1719497153956,"mc":[{"id":"1.230178311","rc":[{"atb":[[2.4,4]],"id":65436514}],"con":true,"img":false}]}
{"op":"mcm","clk":"11540671082","pt":1719497154473,"mc":[{"id":"1.230178311","rc":[{"atl":[[3.95,1],[4.1,0]],"id":57087188},{"atl":[[13.5,6]],"id":69142441},{"atl":[[7,2.5],[6.6,1]],"id":57088863}],"con":true,"img":false}]}
{"op":"mcm","clk":"11540671091","pt":1719497154525,"mc":[{"id":"1.230178311","rc":[{"atl":[[13,0]],"id":69142441}],"con":true,"img":false}]}
{"op":"mcm","clk":"11540671095","pt":1719497154627,"mc":[{"id":"1.230178311","rc":[{"atl":[[2.66,12.76]],"id":55302014}],"con":true,"img":false}]}
{"op":"mcm","clk":"11540671108","pt":1719497154730,"mc":[{"id":"1.230178311","rc":[{"atl":[[2.68,8.57]],"id":55302014}],"con":true,"img":false}]}
{"op":"mcm","clk":"11540671118","pt":1719497154835,"mc":[{"id":"1.230178311","rc":[{"atl":[[2.68,0]],"id":55302014}],"con":true,"img":false}]}
{"op":"mcm","clk":"11540671127","pt":1719497154940,"mc":[{"id":"1.230178311","rc":[{"atl":[[3.95,0],[4.1,1]],"id":57087188},{"atb":[[1.72,0],[1.66,10]],"id":65436514},{"atl":[[4.8,0],[4.9,1]],"id":65436514},{"atl":[[2.94,25.55],[2.7,0.85]],"id":55302014},{"atb":[[2.92,17.16],[2.9,0]],"id":57088863},{"atl":[[6.8,1],[6.6,0]],"id":57088863}],"con":true,"img":false}]}
{"op":"mcm","clk":"11540671148","pt":1719497155147,"mc":[{"id":"1.230178311","rc":[{"atl":[[2.7,0]],"id":55302014}],"con":true,"img":false}]}
{"op":"mcm","clk":"11540671175","pt":1719497155457,"mc":[{"id":"1.230178311","rc":[{"atb":[[4.6,11.63]],"id":69142441},{"atl":[[13,1],[13.5,5]],"id":69142441},{"atl":[[3.1,1]],"id":55302014}],"con":true,"img":false}]}
{"op":"mcm","clk":"11540671189","pt":1719497155568,"mc":[{"id":"1.230178311","rc":[{"atb":[[2.4,12.96]],"id":65436514},{"atb":[[4.4,0]],"id":69142441}],"con":true,"img":false}]}
{"op":"mcm","clk":"11540671204","pt":1719497155770,"mc":[{"id":"1.230178311","rc":[{"atb":[[2.36,0]],"id":65436514}],"con":true,"img":false}]}
{"op":"mcm","clk":"11540671234","pt":1719497156330,"mc":[{"id":"1.230178311","rc":[{"atb":[[2.34,2.11]],"id":65436514},{"atb":[[4.5,8.01]],"id":69142441}],"con":true,"img":false}]}
{"op":"mcm","clk":"11540671251","pt":1719497156541,"mc":[{"id":"1.230178311","rc":[{"atb":[[4.5,2]],"id":69142441}],"con":true,"img":false}]}
{"op":"mcm","clk":"11540671263","pt":1719497156644,"mc":[{"id":"1.230178311","rc":[{"atb":[[4.6,17.64]],"id":69142441}],"con":true,"img":false}]}
{"op":"mcm","clk":"11540671292","pt":1719497157054,"mc":[{"id":"1.230178311","rc":[{"atl":[[7,12.5]],"id":57088863}],"con":true,"img":false}]}
{"op":"mcm","clk":"11540671301","pt":1719497157159,"mc":[{"id":"1.230178311","rc":[{"atl":[[7.8,5]],"id":57088863}],"con":true,"img":false}]}
{"op":"mcm","clk":"11540671408","pt":1719497158657,"mc":[{"id":"1.230178311","rc":[{"atl":[[3.95,1],[4.1,0]],"id":57087188},{"atl":[[13,0],[13.5,6]],"id":69142441},{"atl":[[3.1,0],[3.55,1]],"id":55302014},{"atl":[[6.8,0],[6.6,1]],"id":57088863}],"con":true,"img":false}]}
{"op":"mcm","clk":"11540671456","pt":1719497159181,"mc":[{"id":"1.230178311","rc":[{"atl":[[3.95,0],[4.1,1]],"id":57087188},{"atl":[[6.8,1],[6.6,0]],"id":57088863}],"con":true,"img":false}]}
{"op":"mcm","clk":"11540671523","pt":1719497159854,"mc":[{"id":"1.230178311","rc":[{"atl":[[13,1],[13.5,5]],"id":69142441},{"atl":[[3.1,1],[3.55,0]],"id":55302014}],"con":true,"img":false}]}
{"op":"mcm","clk":"11540671733","pt":1719497162386,"mc":[{"id":"1.230178311","rc":[{"atb":[[2.4,10.96]],"id":65436514},{"atb":[[4.5,0]],"id":69142441}],"con":true,"img":false}]}
{"op":"mcm","clk":"11540671741","pt":1719497162443,"mc":[{"id":"1.230178311","rc":[{"atb":[[2.42,3.38]],"id":65436514}],"con":true,"img":false}]}
{"op":"mcm","clk":"11540671788","pt":1719497162960,"mc":[{"id":"1.230178311","rc":[{"atl":[[5.6,6.56]],"id":68392143}],"con":true,"img":false}]}
{"op":"mcm","clk":"11540671796","pt":1719497163066,"mc":[{"id":"1.230178311","rc":[{"atb":[[4.6,11.63]],"id":69142441},{"atl":[[5.6,1]],"id":68392143}],"con":true,"img":false}]}
{"op":"mcm","clk":"11540671816","pt":1719497163275,"mc":[{"id":"1.230178311","rc":[{"atb":[[4.6,0]],"id":69142441}],"con":true,"img":false}]}
{"op":"mcm","clk":"11540671828","pt":1719497163374,"mc":[{"id":"1.230178311","rc":[{"atb":[[4.5,12.98],[3.7,23.26]],"id":69142441}],"con":true,"img":false}]}
{"op":"mcm","clk":"11540671838","pt":1719497163476,"mc":[{"id":"1.230178311","rc":[{"atb":[[3.85,0]],"id":69142441}],"con":true,"img":false}]}
{"op":"mcm","clk":"11540671856","pt":1719497163681,"mc":[{"id":"1.230178311","rc":[{"atl":[[3.95,1],[4.1,0]],"id":57087188},{"atb":[[2.4,8.96]],"id":65436514},{"atb":[[3.85,1],[3.25,1]],"id":69142441},{"atl":[[13,0],[13.5,6]],"id":69142441},{"atl":[[3.1,0],[3.55,1]],"id":55302014},{"atl":[[5.6,0],[5.5,4.09]],"id":68392143},{"atl":[[6.8,0],[6.6,1]],"id":57088863}],"con":true,"img":false}]}
{"op":"mcm","clk":"11540671865","pt":1719497163786,"mc":[{"id":"1.230178311","rc":[{"atb":[[2.44,2]],"id":65436514},{"atl":[[3.05,6]],"id":55302014},{"atb":[[2.54,2.5],[2.52,12.4]],"id":68392143},{"atl":[[5.5,8.19],[5.7,2.5]],"id":68392143},{"atl":[[7,13.5]],"id":57088863}],"con":true,"img":false}]}
{"op":"mcm","clk":"11540671876","pt":1719497163840,"mc":[{"id":"1.230178311","rc":[{"atb":[[1.64,0]],"id":55302014}],"con":true,"img":false}]}
{"op":"mcm","clk":"11540671887","pt":1719497163944,"mc":[{"id":"1.230178311","rc":[{"atl":[[3.95,0],[4.1,1]],"id":57087188},{"atb":[[3.25,0]],"id":69142441},{"atl":[[6.6,0],[7,12.5]],"id":57088863}],"con":true,"img":false}]}
{"op":"mcm","clk":"11540671905","pt":1719497164150,"mc":[{"id":"1.230178311","rc":[{"atb":[[3.6,1],[3.85,0],[3.9,3.5]],"id":69142441},{"atl":[[3.55,0]],"id":55302014},{"atl":[[5.6,1],[5.5,7.19]],"id":68392143},{"atl":[[7,13.5]],"id":57088863}],"con":true,"img":false}]}
{"op":"mcm","clk":"11540671917","pt":1719497164258,"mc":[{"id":"1.230178311","rc":[{"atl":[[7,3.5],[7.8,19.71]],"id":57088863}],"con":true,"img":false}]}
{"op":"mcm","clk":"11540671956","pt":1719497164765,"mc":[{"id":"1.230178311","rc":[{"atb":[[1.79,19.75]],"id":55302014}],"con":true,"img":false}]}
{"op":"mcm","clk":"11540672006","pt":1719497165437,"mc":[{"id":"1.230178311","rc":[{"atl":[[13,1],[13.5,5]],"id":69142441},{"atl":[[3.1,1],[3.05,5]],"id":55302014},{"atl":[[6.8,1],[7,2.5]],"id":57088863}],"con":true,"img":false}]}
{"op":"mcm","clk":"11540672016","pt":1719497165541,"mc":[{"id":"1.230178311","rc":[{"atb":[[3.6,0]],"id":69142441}],"con":true,"img":false}]}
{"op":"mcm","clk":"11540672159","pt":1719497167183,"mc":[{"id":"1.230178311","rc":[{"atb":[[2.44,9.1]],"id":65436514},{"atb":[[3.25,1]],"id":69142441},{"atl":[[6.6,1]],"id":57088863}],"con":true,"img":false}]}
{"op":"mcm","clk":"11540672167","pt":1719497167286,"mc":[{"id":"1.230178311","rc":[{"atl":[[6.8,0]],"id":57088863}],"con":true,"img":false}]}
{"op":"mcm","clk":"11540672173","pt":1719497167389,"mc":[{"id":"1.230178311","rc":[{"atb":[[2.4,0]],"id":65436514},{"atb":[[1.62,5.61]],"id":55302014}],"con":true,"img":false}]}
{"op":"mcm","clk":"11540672236","pt":1719497168068,"mc":[{"id":"1.230178311","rc":[{"atl":[[4,11.32],[4.1,0]],"id":57087188}],"con":true,"img":false}]}
{"op":"mcm","clk":"11540672254","pt":1719497168279,"mc":[{"id":"1.230178311","rc":[{"atl":[[4,1],[4.6,18.13]],"id":57087188}],"con":true,"img":false}]}
{"op":"mcm","clk":"11540672289","pt":1719497168685,"mc":[{"id":"1.230178311","rc":[{"atb":[[3.9,0]],"id":69142441}],"con":true,"img":false}]}
{"op":"mcm","clk":"11540672292","pt":1719497168739,"mc":[{"id":"1.230178311","rc":[{"atl":[[3.55,1]],"id":55302014}],"con":true,"img":false}]}
{"op":"mcm","clk":"11540672306","pt":1719497168844,"mc":[{"id":"1.230178311","rc":[{"atb":[[1.6,6.76],[1.66,0]],"id":65436514},{"atl":[[5,22.74],[4.9,0]],"id":65436514},{"atl":[[3.1,0]],"id":55302014},{"atb":[[2.58,2.11]],"id":68392143}],"con":true,"img":false}]}
{"op":"mcm","clk":"11540672314","pt":1719497168999,"mc":[{"id":"1.230178311","rc":[{"atl":[[5,3.5],[15,7.14]],"id":65436514},{"atb":[[2.5,11.9],[2.52,0]],"id":68392143},{"atl":[[5.5,3.09],[5.7,10.7]],"id":68392143}],"con":true,"img":false}]}
{"op":"mcm","clk":"11540672357","pt":1719497169274,"mc":[{"id":"1.230178311","rc":[{"atl":[[4,0],[3.95,1]],"id":57087188},{"atb":[[3.6,1],[3.25,0]],"id":69142441},{"atl":[[13,0],[13.5,6]],"id":69142441}],"con":true,"img":false}]}
{"op":"mcm","clk":"11540672380","pt":1719497169477,"mc":[{"id":"1.230178311","rc":[{"atl":[[3.95,0],[4.1,1]],"id":57087188},{"atl":[[6.8,1],[6.6,0]],"id":57088863}],"con":true,"img":false}]}
{"op":"mcm","clk":"11540672393","pt":1719497169579,"mc":[{"id":"1.230178311","rc":[{"atl":[[6.8,11],[7.8,5]],"id":57088863}],"con":true,"img":false}]}
{"op":"mcm","clk":"11540672426","pt":1719497169889,"mc":[{"id":"1.230178311","rc":[{"atl":[[4.1,4.7]],"id":57087188},{"atb":[[2.44,25.82]],"id":65436514},{"atb":[[3.25,1]],"id":69142441},{"atl":[[13,1],[13.5,5]],"id":69142441},{"atl":[[3.1,1]],"id":55302014}],"con":true,"img":false}]}
{"op":"mcm","clk":"11540672438","pt":1719497169991,"mc":[{"id":"1.230178311","rc":[{"atb":[[3.6,0]],"id":69142441},{"atl":[[3.55,0]],"id":55302014}],"con":true,"img":false}]}
{"op":"mcm","clk":"11540672451","pt":1719497170095,"mc":[{"id":"1.230178311","rc":[{"atl":[[4,1],[4.1,3.7]],"id":57087188},{"atl":[[6.6,1]],"id":57088863}],"con":true,"img":false}]}
{"op":"mcm","clk":"11540672464","pt":1719497170151,"mc":[{"id":"1.230178311","rc":[{"atl":[[4.1,0]],"id":57087188},{"atl":[[6.8,10]],"id":57088863}],"con":true,"img":false}]}
{"op":"mcm","clk":"11540672489","pt":1719497170406,"mc":[{"id":"1.230178311","rc":[{"atb":[[1.62,0]],"id":55302014}],"con":true,"img":false}]}
{"op":"mcm","clk":"11540672520","pt":1719497170675,"mc":[{"id":"1.230178311","rc":[{"atb":[[2.58,5.69]],"id":68392143}],"con":true,"img":false}]}
{"op":"mcm","clk":"11540672558","pt":1719497171083,"mc":[{"id":"1.230178311","rc":[{"atb":[[2.42,0]],"id":65436514}],"con":true,"img":false}]}
{"op":"mcm","clk":"11540672570","pt":1719497171186,"mc":[{"id":"1.230178311","rc":[{"atb":[[2.24,2.33]],"id":57087188},{"atb":[[2.46,3]],"id":65436514},{"atb":[[4.6,2.32]],"id":69142441},{"atl":[[3.1,0],[3.55,1]],"id":55302014}],"con":true,"img":false}]}
{"op":"mcm","clk":"11540672593","pt":1719497171390,"mc":[{"id":"1.230178311","rc":[{"atb":[[2.24,7.31]],"id":57087188},{"atb":[[4.6,9.68]],"id":69142441}],"con":true,"img":false}]}
{"op":"mcm","clk":"11540672603","pt":1719497171444,"mc":[{"id":"1.230178311","rc":[{"atb":[[2.44,24.09]],"id":65436514}],"con":true,"img":false}]}
{"op":"mcm","clk":"11540672610","pt":1719497171549,"mc":[{"id":"1.230178311","rc":[{"atb":[[2.22,2]],"id":57087188},{"atb":[[4.5,0],[4.6,15.28]],"id":69142441}],"con":true,"img":false}]}
{"op":"mcm","clk":"11540672623","pt":1719497171654,"mc":[{"id":"1.230178311","rc":[{"atb":[[2.44,9.1]],"id":65436514}],"con":true,"img":false}]}
{"op":"mcm","clk":"11540672631","pt":1719497171756,"mc":[{"id":"1.230178311","rc":[{"atb":[[2.46,17.99]],"id":65436514}],"con":true,"img":false}]}
{"op":"mcm","clk":"11540672687","pt":1719497172378,"mc":[{"id":"1.230178311","rc":[{"atb":[[4.6,9.68]],"id":69142441}],"con":true,"img":false}]}
{"op":"mcm","clk":"11540672700","pt":1719497172583,"mc":[{"id":"1.230178311","rc":[{"atb":[[2.22,0]],"id":57087188}],"con":true,"img":false}]}
{"op":"mcm","clk":"11540672710","pt":1719497172686,"mc":[{"id":"1.230178311","rc":[{"atb":[[2.26,2]],"id":57087188},{"atb":[[2.12,0],[2.48,5],[2.56,2.5],[2.4,10],[2.42,3.53],[2.28,0],[2.2,0]],"id":65436514},{"atl":[[11,12.5],[11.5,0],[13,6],[13.5,0]],"id":69142441}],"con":true,"img":false}]}
{"op":"mcm","clk":"11540672750","pt":1719497173152,"mc":[{"id":"1.230178311","rc":[{"atb":[[2.44,7.1]],"id":65436514}],"con":true,"img":false}]}
{"op":"mcm","clk":"11540672755","pt":1719497173255,"mc":[{"id":"1.230178311","rc":[{"atb":[[2.48,7]],"id":65436514}],"con":true,"img":false}]}
{"op":"mcm","clk":"11540672776","pt":1719497173461,"mc":[{"id":"1.230178311","rc":[{"atb":[[2.42,0]],"id":65436514}],"con":true,"img":false}]}
{"op":"mcm","clk":"11540672784","pt":1719497173565,"mc":[{"id":"1.230178311","rc":[{"atl":[[2.68,3.38]],"id":55302014}],"con":true,"img":false}]}
{"op":"mcm","clk":"11540672794","pt":1719497173669,"mc":[{"id":"1.230178311","rc":[{"atl":[[2.66,25.53]],"id":55302014}],"con":true,"img":false}]}
{"op":"mcm","clk":"11540672805","pt":1719497173770,"mc":[{"id":"1.230178311","rc":[{"atl":[[2.94,2.5]],"id":55302014}],"con":true,"img":false}]}
{"op":"mcm","clk":"11540672814","pt":1719497173873,"mc":[{"id":"1.230178311","rc":[{"atl":[[2.66,12.76],[2.94,31.42]],"id":55302014}],"con":true,"img":false}]}
{"op":"mcm","clk":"11540672845","pt":1719497174287,"mc":[{"id":"1.230178311","rc":[{"atl":[[5,1],[6.8,2.5],[7.6,5],[5.2,1],[8.4,10]],"id":65436514},{"atl":[[8.6,0],[6.8,12.5],[7,0],[7.8,0]],"id":57088863}],"con":true,"img":false}]}
{"op":"mcm","clk":"11540672857","pt":1719497174392,"mc":[{"id":"1.230178311","rc":[{"atl":[[5,0],[6.8,12.08],[15,0]],"id":65436514}],"con":true,"img":false}]}
{"op":"mcm","clk":"11540672868","pt":1719497174447,"mc":[{"id":"1.230178311","rc":[{"atl":[[5.2,0]],"id":65436514}],"con":true,"img":false}]}
{"op":"mcm","clk":"11540672876","pt":1719497174550,"mc":[{"id":"1.230178311","rc":[{"atl":[[4,0]],"id":57087188},{"atb":[[2.48,5]],"id":65436514},{"atl":[[5.2,1]],"id":65436514},{"atl":[[13.5,1]],"id":69142441}],"con":true,"img":false}]}
{"op":"mcm","clk":"11540672888","pt":1719497174653,"mc":[{"id":"1.230178311","rc":[{"atl":[[3.95,1]],"id":57087188},{"atb":[[2.58,2]],"id":65436514},{"atl":[[13,5]],"id":69142441}],"con":true,"img":false}]}
