{"op":"mcm","clk":"11547086384","pt":1719432856302,"mc":[{"id":"1.230178130","marketDefinition":{"bspMarket":false,"turnInPlayEnabled":false,"persistenceEnabled":false,"marketBaseRate":5.0,"eventId":"33376048","eventTypeId":"4339","numberOfWinners":1,"bettingType":"ODDS","marketType":"FORECAST","marketTime":"2024-06-27T13:29:00.000Z","suspendTime":"2024-06-27T13:29:00.000Z","bspReconciled":false,"complete":true,"inPlay":false,"crossMatching":false,"runnersVoidable":false,"numberOfActiveRunners":20,"betDelay":0,"status":"OPEN","runners":[{"status":"ACTIVE","sortPriority":1,"id":52385882,"name":"1 - 2"},{"status":"ACTIVE","sortPriority":2,"id":52385883,"name":"1 - 3"},{"status":"ACTIVE","sortPriority":3,"id":52385884,"name":"1 - 4"},{"status":"ACTIVE","sortPriority":4,"id":52385885,"name":"1 - 5"},{"status":"ACTIVE","sortPriority":5,"id":52385889,"name":"2 - 1"},{"status":"ACTIVE","sortPriority":6,"id":52385890,"name":"2 - 3"},{"status":"ACTIVE","sortPriority":7,"id":52385891,"name":"2 - 4"},{"status":"ACTIVE","sortPriority":8,"id":52385892,"name":"2 - 5"},{"status":"ACTIVE","sortPriority":9,"id":52385896,"name":"3 - 1"},{"status":"ACTIVE","sortPriority":10,"id":52385897,"name":"3 - 2"},{"status":"ACTIVE","sortPriority":11,"id":52385898,"name":"3 - 4"},{"status":"ACTIVE","sortPriority":12,"id":52385899,"name":"3 - 5"},{"status":"ACTIVE","sortPriority":13,"id":52385903,"name":"4 - 1"},{"status":"ACTIVE","sortPriority":14,"id":52385904,"name":"4 - 2"},{"status":"ACTIVE","sortPriority":15,"id":52385905,"name":"4 - 3"},{"status":"ACTIVE","sortPriority":16,"id":52385906,"name":"4 - 5"},{"status":"ACTIVE","sortPriority":17,"id":52385910,"name":"5 - 1"},{"status":"ACTIVE","sortPriority":18,"id":52385911,"name":"5 - 2"},{"status":"ACTIVE","sortPriority":19,"id":52385912,"name":"5 - 3"},{"status":"ACTIVE","sortPriority":20,"id":52385913,"name":"5 - 4"}],"regulators":["MR_INT"],"venue":"Perry Barr","countryCode":"GB","discountAllowed":false,"timezone":"Europe/London","openDate":"2024-06-27T13:29:00.000Z","version":5994794114,"name":"Forecast","eventName":"Perry Barr (F/C) 27th Jun"},"rc":[],"con":true,"img":false}]}
{"op":"mcm","clk":"11547086545","pt":1719432858310,"mc":[{"id":"1.230178130","marketDefinition":{"bspMarket":false,"turnInPlayEnabled":false,"persistenceEnabled":false,"marketBaseRate":5.0,"eventId":"33376048","eventTypeId":"4339","numberOfWinners":1,"bettingType":"ODDS","marketType":"FORECAST","marketTime":"2024-06-27T13:29:00.000Z","suspendTime":"2024-06-27T13:29:00.000Z","bspReconciled":false,"complete":true,"inPlay":false,"crossMatching":false,"runnersVoidable":false,"numberOfActiveRunners":20,"betDelay":0,"status":"OPEN","runners":[{"status":"ACTIVE","sortPriority":1,"id":52385882,"name":"1 - 2"},{"status":"ACTIVE","sortPriority":2,"id":52385883,"name":"1 - 3"},{"status":"ACTIVE","sortPriority":3,"id":52385884,"name":"1 - 4"},{"status":"ACTIVE","sortPriority":4,"id":52385885,"name":"1 - 5"},{"status":"ACTIVE","sortPriority":5,"id":52385889,"name":"2 - 1"},{"status":"ACTIVE","sortPriority":6,"id":52385890,"name":"2 - 3"},{"status":"ACTIVE","sortPriority":7,"id":52385891,"name":"2 - 4"},{"status":"ACTIVE","sortPriority":8,"id":52385892,"name":"2 - 5"},{"status":"ACTIVE","sortPriority":9,"id":52385896,"name":"3 - 1"},{"status":"ACTIVE","sortPriority":10,"id":52385897,"name":"3 - 2"},{"status":"ACTIVE","sortPriority":11,"id":52385898,"name":"3 - 4"},{"status":"ACTIVE","sortPriority":12,"id":52385899,"name":"3 - 5"},{"status":"ACTIVE","sortPriority":13,"id":52385903,"name":"4 - 1"},{"status":"ACTIVE","sortPriority":14,"id":52385904,"name":"4 - 2"},{"status":"ACTIVE","sortPriority":15,"id":52385905,"name":"4 - 3"},{"status":"ACTIVE","sortPriority":16,"id":52385906,"name":"4 - 5"},{"status":"ACTIVE","sortPriority":17,"id":52385910,"name":"5 - 1"},{"status":"ACTIVE","sortPriority":18,"id":52385911,"name":"5 - 2"},{"status":"ACTIVE","sortPriority":19,"id":52385912,"name":"5 - 3"},{"status":"ACTIVE","sortPriority":20,"id":52385913,"name":"5 - 4"}],"regulators":["MR_INT"],"venue":"Perry Barr","countryCode":"GB","discountAllowed":true,"timezone":"Europe/London","openDate":"2024-06-27T13:29:00.000Z","version":5994794114,"name":"Forecast","eventName":"Perry Barr (F/C) 27th Jun"},"rc":[],"con":true,"img":false}]}
{"op":"mcm","clk":"11547146276","pt":1719434094266,"mc":[{"id":"1.230178130","rc":[{"atb":[[1.1,200]],"id":52385910},{"atb":[[1.1,200]],"id":52385911},{"atb":[[1.1,200]],"id":52385912},{"atb":[[1.1,200]],"id":52385913},{"atb":[[1.1,200]],"id":52385906},{"atb":[[1.1,200]],"id":52385889},{"atb":[[1.1,200]],"id":52385882},{"atb":[[1.1,200]],"id":52385883},{"atb":[[1.1,200]],"id":52385884},{"atb":[[1.1,200]],"id":52385885},{"atb":[[1.1,200]],"id":52385896},{"atb":[[1.1,200]],"id":52385897},{"atb":[[1.1,200]],"id":52385890},{"atb":[[1.1,200]],"id":52385891},{"atb":[[1.1,200]],"id":52385892},{"atb":[[1.1,200]],"id":52385903},{"atb":[[1.1,200]],"id":52385904},{"atb":[[1.1,200]],"id":52385905},{"atb":[[1.1,200]],"id":52385898},{"atb":[[1.1,200]],"id":52385899}],"con":true,"img":false}]}
{"op":"mcm","clk":"11547210536","pt":1719435442619,"mc":[{"id":"1.230178130","rc":[{"atb":[[1.02,25.92]],"id":52385910},{"atl":[[990,0.84]],"id":52385910},{"atb":[[1.01,51.84]],"id":52385911},{"atl":[[1000,0.84]],"id":52385911},{"atb":[[1.01,51.84]],"id":52385912},{"atl":[[990,0.84]],"id":52385912},{"atb":[[1.02,25.92]],"id":52385913},{"atl":[[990,0.84]],"id":52385913},{"atb":[[1.03,17.28]],"id":52385906},{"atl":[[990,0.84]],"id":52385906},{"atb":[[1.02,25.92]],"id":52385889},{"atl":[[1000,0.84]],"id":52385889},{"atb":[[1.03,17.28]],"id":52385882},{"atl":[[990,0.84]],"id":52385882},{"atb":[[1.02,25.92]],"id":52385883},{"atl":[[990,0.84]],"id":52385883},{"atb":[[1.02,25.92]],"id":52385884},{"atl":[[1000,0.84]],"id":52385884},{"atb":[[1.01,51.84]],"id":52385885},{"atl":[[1000,0.84]],"id":52385885},{"atb":[[1.02,25.92]],"id":52385896},{"atl":[[1000,0.84]],"id":52385896},{"atb":[[1.03,17.28]],"id":52385897},{"atl":[[1000,0.84]],"id":52385897},{"atb":[[1.01,51.84]],"id":52385890},{"atl":[[1000,0.84]],"id":52385890},{"atb":[[1.02,25.92]],"id":52385891},{"atl":[[1000,0.84]],"id":52385891},{"atb":[[1.03,17.28]],"id":52385892},{"atl":[[990,0.84]],"id":52385892},{"atb":[[1.03,17.28]],"id":52385903},{"atl":[[1000,0.84]],"id":52385903},{"atb":[[1.03,17.28]],"id":52385904},{"atl":[[990,0.84]],"id":52385904},{"atb":[[1.03,17.28]],"id":52385905},{"atl":[[1000,0.84]],"id":52385905},{"atb":[[1.03,17.28]],"id":52385898},{"atl":[[1000,0.84]],"id":52385898},{"atb":[[1.02,25.92]],"id":52385899},{"atl":[[1000,0.84]],"id":52385899}],"con":true,"img":false}]}
{"op":"mcm","clk":"11547344178","pt":1719439054816,"mc":[{"id":"1.230178130","rc":[{"atb":[[1.02,25.92]],"id":52385910},{"atl":[[990,0.23]],"id":52385910},{"atb":[[1.01,51.85]],"id":52385911},{"atl":[[1000,0.23]],"id":52385911},{"atb":[[1.01,51.85]],"id":52385912},{"atl":[[990,0.23]],"id":52385912},{"atb":[[1.02,25.92]],"id":52385913},{"atl":[[990,0.23]],"id":52385913},{"atb":[[1.03,17.28]],"id":52385906},{"atl":[[990,0.23]],"id":52385906},{"atb":[[1.02,25.92]],"id":52385889},{"atl":[[1000,0.23]],"id":52385889},{"atb":[[1.03,17.28]],"id":52385882},{"atl":[[990,0.23]],"id":52385882},{"atb":[[1.02,25.92]],"id":52385883},{"atl":[[990,0.23]],"id":52385883},{"atb":[[1.02,25.92]],"id":52385884},{"atl":[[1000,0.23]],"id":52385884},{"atb":[[1.01,51.85]],"id":52385885},{"atl":[[1000,0.23]],"id":52385885},{"atb":[[1.02,25.92]],"id":52385896},{"atl":[[1000,0.23]],"id":52385896},{"atb":[[1.03,17.28]],"id":52385897},{"atl":[[1000,0.23]],"id":52385897},{"atb":[[1.01,51.85]],"id":52385890},{"atl":[[1000,0.23]],"id":52385890},{"atb":[[1.02,25.92]],"id":52385891},{"atl":[[1000,0.23]],"id":52385891},{"atb":[[1.03,17.28]],"id":52385892},{"atl":[[990,0.23]],"id":52385892},{"atb":[[1.03,17.28]],"id":52385903},{"atl":[[1000,0.23]],"id":52385903},{"atb":[[1.03,17.28]],"id":52385904},{"atl":[[990,0.23]],"id":52385904},{"atb":[[1.03,17.28]],"id":52385905},{"atl":[[1000,0.23]],"id":52385905},{"atb":[[1.03,17.28]],"id":52385898},{"atl":[[1000,0.23]],"id":52385898},{"atb":[[1.02,25.92]],"id":52385899},{"atl":[[1000,0.23]],"id":52385899}],"con":true,"img":false}]}
{"op":"mcm","clk":"11547371366","pt":1719439682622,"mc":[{"id":"1.230178130","marketDefinition":{"bspMarket":false,"turnInPlayEnabled":false,"persistenceEnabled":false,"marketBaseRate":5.0,"eventId":"33376048","eventTypeId":"4339","numberOfWinners":1,"bettingType":"ODDS","marketType":"FORECAST","marketTime":"2024-06-27T13:29:00.000Z","suspendTime":"2024-06-27T13:29:00.000Z","bspReconciled":false,"complete":true,"inPlay":false,"crossMatching":false,"runnersVoidable":false,"numberOfActiveRunners":20,"betDelay":0,"status":"OPEN","runners":[{"status":"ACTIVE","sortPriority":1,"id":52385882,"name":"1 - 2"},{"status":"ACTIVE","sortPriority":2,"id":52385883,"name":"1 - 3"},{"status":"ACTIVE","sortPriority":3,"id":52385884,"name":"1 - 4"},{"status":"ACTIVE","sortPriority":4,"id":52385885,"name":"1 - 5"},{"status":"ACTIVE","sortPriority":5,"id":52385889,"name":"2 - 1"},{"status":"ACTIVE","sortPriority":6,"id":52385890,"name":"2 - 3"},{"status":"ACTIVE","sortPriority":7,"id":52385891,"name":"2 - 4"},{"status":"ACTIVE","sortPriority":8,"id":52385892,"name":"2 - 5"},{"status":"ACTIVE","sortPriority":9,"id":52385896,"name":"3 - 1"},{"status":"ACTIVE","sortPriority":10,"id":52385897,"name":"3 - 2"},{"status":"ACTIVE","sortPriority":11,"id":52385898,"name":"3 - 4"},{"status":"ACTIVE","sortPriority":12,"id":52385899,"name":"3 - 5"},{"status":"ACTIVE","sortPriority":13,"id":52385903,"name":"4 - 1"},{"status":"ACTIVE","sortPriority":14,"id":52385904,"name":"4 - 2"},{"status":"ACTIVE","sortPriority":15,"id":52385905,"name":"4 - 3"},{"status":"ACTIVE","sortPriority":16,"id":52385906,"name":"4 - 5"},{"status":"ACTIVE","sortPriority":17,"id":52385910,"name":"5 - 1"},{"status":"ACTIVE","sortPriority":18,"id":52385911,"name":"5 - 2"},{"status":"ACTIVE","sortPriority":19,"id":52385912,"name":"5 - 3"},{"status":"ACTIVE","sortPriority":20,"id":52385913,"name":"5 - 4"}],"regulators":["MR_INT"],"venue":"Perry Barr","countryCode":"GB","discountAllowed":true,"timezone":"Europe/London","openDate":"2024-06-27T13:29:00.000Z","version":5994794114,"name":"Forecast","eventName":"Perry Barr (F/C) 27th Jun"},"rc":[{"atb":[[1.02,25.92],[1.1,200]],"id":52385910},{"atl":[[990,0.23]],"id":52385910},{"atb":[[1.01,51.84],[1.1,200]],"id":52385911},{"atl":[[1000,0.23]],"id":52385911},{"atb":[[1.01,51.84],[1.1,200]],"id":52385912},{"atl":[[990,0.23]],"id":52385912},{"atb":[[1.02,25.92],[1.1,200]],"id":52385913},{"atl":[[990,0.23]],"id":52385913},{"atb":[[1.03,17.28],[1.1,200]],"id":52385906},{"atl":[[990,0.23]],"id":52385906},{"atb":[[1.02,25.92],[1.1,200]],"id":52385889},{"atl":[[1000,0.23]],"id":52385889},{"atb":[[1.03,17.28],[1.1,200]],"id":52385882},{"atl":[[990,0.23]],"id":52385882},{"atb":[[1.02,25.92],[1.1,200]],"id":52385883},{"atl":[[990,0.23]],"id":52385883},{"atb":[[1.02,25.92],[1.1,200]],"id":52385884},{"atl":[[1000,0.23]],"id":52385884},{"atb":[[1.01,51.84],[1.1,200]],"id":52385885},{"atl":[[1000,0.23]],"id":52385885},{"atb":[[1.02,25.92],[1.1,200]],"id":52385896},{"atl":[[1000,0.23]],"id":52385896},{"atb":[[1.03,17.28],[1.1,200]],"id":52385897},{"atl":[[1000,0.23]],"id":52385897},{"atb":[[1.01,51.84],[1.1,200]],"id":52385890},{"atl":[[1000,0.23]],"id":52385890},{"atb":[[1.02,25.92],[1.1,200]],"id":52385891},{"atl":[[1000,0.23]],"id":52385891},{"atb":[[1.03,17.28],[1.1,200]],"id":52385892},{"atl":[[990,0.23]],"id":52385892},{"atb":[[1.03,17.28],[1.1,200]],"id":52385903},{"atl":[[1000,0.23]],"id":52385903},{"atb":[[1.03,17.28],[1.1,200]],"id":52385904},{"atl":[[990,0.23]],"id":52385904},{"atb":[[1.03,17.28],[1.1,200]],"id":52385905},{"atl":[[1000,0.23]],"id":52385905},{"atb":[[1.03,17.28],[1.1,200]],"id":52385898},{"atl":[[1000,0.23]],"id":52385898},{"atb":[[1.02,25.92],[1.1,200]],"id":52385899},{"atl":[[1000,0.23]],"id":52385899}],"con":true,"img":true}]}
{"op":"mcm","clk":"11547660044","pt":1719445082635,"mc":[{"id":"1.230178130","marketDefinition":{"bspMarket":false,"turnInPlayEnabled":false,"persistenceEnabled":false,"marketBaseRate":5.0,"eventId":"33376048","eventTypeId":"4339","numberOfWinners":1,"bettingType":"ODDS","marketType":"FORECAST","marketTime":"2024-06-27T13:29:00.000Z","suspendTime":"2024-06-27T13:29:00.000Z","bspReconciled":false,"complete":true,"inPlay":false,"crossMatching":false,"runnersVoidable":false,"numberOfActiveRunners":20,"betDelay":0,"status":"OPEN","runners":[{"status":"ACTIVE","sortPriority":1,"id":52385882,"name":"1 - 2"},{"status":"ACTIVE","sortPriority":2,"id":52385883,"name":"1 - 3"},{"status":"ACTIVE","sortPriority":3,"id":52385884,"name":"1 - 4"},{"status":"ACTIVE","sortPriority":4,"id":52385885,"name":"1 - 5"},{"status":"ACTIVE","sortPriority":5,"id":52385889,"name":"2 - 1"},{"status":"ACTIVE","sortPriority":6,"id":52385890,"name":"2 - 3"},{"status":"ACTIVE","sortPriority":7,"id":52385891,"name":"2 - 4"},{"status":"ACTIVE","sortPriority":8,"id":52385892,"name":"2 - 5"},{"status":"ACTIVE","sortPriority":9,"id":52385896,"name":"3 - 1"},{"status":"ACTIVE","sortPriority":10,"id":52385897,"name":"3 - 2"},{"status":"ACTIVE","sortPriority":11,"id":52385898,"name":"3 - 4"},{"status":"ACTIVE","sortPriority":12,"id":52385899,"name":"3 - 5"},{"status":"ACTIVE","sortPriority":13,"id":52385903,"name":"4 - 1"},{"status":"ACTIVE","sortPriority":14,"id":52385904,"name":"4 - 2"},{"status":"ACTIVE","sortPriority":15,"id":52385905,"name":"4 - 3"},{"status":"ACTIVE","sortPriority":16,"id":52385906,"name":"4 - 5"},{"status":"ACTIVE","sortPriority":17,"id":52385910,"name":"5 - 1"},{"status":"ACTIVE","sortPriority":18,"id":52385911,"name":"5 - 2"},{"status":"ACTIVE","sortPriority":19,"id":52385912,"name":"5 - 3"},{"status":"ACTIVE","sortPriority":20,"id":52385913,"name":"5 - 4"}],"regulators":["MR_INT"],"venue":"Perry Barr","countryCode":"GB","discountAllowed":true,"timezone":"Europe/London","openDate":"2024-06-27T13:29:00.000Z","version":5994794114,"name":"Forecast","eventName":"Perry Barr (F/C) 27th Jun"},"rc":[{"atb":[[1.02,25.92],[1.1,200]],"id":52385910},{"atl":[[990,0.23]],"id":52385910},{"atb":[[1.01,51.85],[1.1,200]],"id":52385911},{"atl":[[1000,0.23]],"id":52385911},{"atb":[[1.01,51.85],[1.1,200]],"id":52385912},{"atl":[[990,0.23]],"id":52385912},{"atb":[[1.02,25.92],[1.1,200]],"id":52385913},{"atl":[[990,0.23]],"id":52385913},{"atb":[[1.03,17.28],[1.1,200]],"id":52385906},{"atl":[[990,0.23]],"id":52385906},{"atb":[[1.02,25.92],[1.1,200]],"id":52385889},{"atl":[[1000,0.23]],"id":52385889},{"atb":[[1.03,17.28],[1.1,200]],"id":52385882},{"atl":[[990,0.23]],"id":52385882},{"atb":[[1.02,25.92],[1.1,200]],"id":52385883},{"atl":[[990,0.23]],"id":52385883},{"atb":[[1.02,25.92],[1.1,200]],"id":52385884},{"atl":[[1000,0.23]],"id":52385884},{"atb":[[1.01,51.85],[1.1,200]],"id":52385885},{"atl":[[1000,0.23]],"id":52385885},{"atb":[[1.02,25.92],[1.1,200]],"id":52385896},{"atl":[[1000,0.23]],"id":52385896},{"atb":[[1.03,17.28],[1.1,200]],"id":52385897},{"atl":[[1000,0.23]],"id":52385897},{"atb":[[1.01,51.85],[1.1,200]],"id":52385890},{"atl":[[1000,0.23]],"id":52385890},{"atb":[[1.02,25.92],[1.1,200]],"id":52385891},{"atl":[[1000,0.23]],"id":52385891},{"atb":[[1.03,17.28],[1.1,200]],"id":52385892},{"atl":[[990,0.23]],"id":52385892},{"atb":[[1.03,17.28],[1.1,200]],"id":52385903},{"atl":[[1000,0.23]],"id":52385903},{"atb":[[1.03,17.28],[1.1,200]],"id":52385904},{"atl":[[990,0.23]],"id":52385904},{"atb":[[1.03,17.28],[1.1,200]],"id":52385905},{"atl":[[1000,0.23]],"id":52385905},{"atb":[[1.03,17.28],[1.1,200]],"id":52385898},{"atl":[[1000,0.23]],"id":52385898},{"atb":[[1.02,25.92],[1.1,200]],"id":52385899},{"atl":[[1000,0.23]],"id":52385899}],"con":true,"img":true}]}
{"op":"mcm","clk":"11548032119","pt":1719450482664,"mc":[{"id":"1.230178130","marketDefinition":{"bspMarket":false,"turnInPlayEnabled":false,"persistenceEnabled":false,"marketBaseRate":5.0,"eventId":"33376048","eventTypeId":"4339","numberOfWinners":1,"bettingType":"ODDS","marketType":"FORECAST","marketTime":"2024-06-27T13:29:00.000Z","suspendTime":"2024-06-27T13:29:00.000Z","bspReconciled":false,"complete":true,"inPlay":false,"crossMatching":false,"runnersVoidable":false,"numberOfActiveRunners":20,"betDelay":0,"status":"OPEN","runners":[{"status":"ACTIVE","sortPriority":1,"id":52385882,"name":"1 - 2"},{"status":"ACTIVE","sortPriority":2,"id":52385883,"name":"1 - 3"},{"status":"ACTIVE","sortPriority":3,"id":52385884,"name":"1 - 4"},{"status":"ACTIVE","sortPriority":4,"id":52385885,"name":"1 - 5"},{"status":"ACTIVE","sortPriority":5,"id":52385889,"name":"2 - 1"},{"status":"ACTIVE","sortPriority":6,"id":52385890,"name":"2 - 3"},{"status":"ACTIVE","sortPriority":7,"id":52385891,"name":"2 - 4"},{"status":"ACTIVE","sortPriority":8,"id":52385892,"name":"2 - 5"},{"status":"ACTIVE","sortPriority":9,"id":52385896,"name":"3 - 1"},{"status":"ACTIVE","sortPriority":10,"id":52385897,"name":"3 - 2"},{"status":"ACTIVE","sortPriority":11,"id":52385898,"name":"3 - 4"},{"status":"ACTIVE","sortPriority":12,"id":52385899,"name":"3 - 5"},{"status":"ACTIVE","sortPriority":13,"id":52385903,"name":"4 - 1"},{"status":"ACTIVE","sortPriority":14,"id":52385904,"name":"4 - 2"},{"status":"ACTIVE","sortPriority":15,"id":52385905,"name":"4 - 3"},{"status":"ACTIVE","sortPriority":16,"id":52385906,"name":"4 - 5"},{"status":"ACTIVE","sortPriority":17,"id":52385910,"name":"5 - 1"},{"status":"ACTIVE","sortPriority":18,"id":52385911,"name":"5 - 2"},{"status":"ACTIVE","sortPriority":19,"id":52385912,"name":"5 - 3"},{"status":"ACTIVE","sortPriority":20,"id":52385913,"name":"5 - 4"}],"regulators":["MR_INT"],"venue":"Perry Barr","countryCode":"GB","discountAllowed":true,"timezone":"Europe/London","openDate":"2024-06-27T13:29:00.000Z","version":5994794114,"name":"Forecast","eventName":"Perry Barr (F/C) 27th Jun"},"rc":[{"atb":[[1.02,25.93],[1.1,200]],"id":52385910},{"atl":[[990,0.23]],"id":52385910},{"atb":[[1.01,51.87],[1.1,200]],"id":52385911},{"atl":[[1000,0.23]],"id":52385911},{"atb":[[1.01,51.87],[1.1,200]],"id":52385912},{"atl":[[990,0.23]],"id":52385912},{"atb":[[1.02,25.93],[1.1,200]],"id":52385913},{"atl":[[990,0.23]],"id":52385913},{"atb":[[1.03,17.29],[1.1,200]],"id":52385906},{"atl":[[990,0.23]],"id":52385906},{"atb":[[1.02,25.93],[1.1,200]],"id":52385889},{"atl":[[1000,0.23]],"id":52385889},{"atb":[[1.03,17.29],[1.1,200]],"id":52385882},{"atl":[[990,0.23]],"id":52385882},{"atb":[[1.02,25.93],[1.1,200]],"id":52385883},{"atl":[[990,0.23]],"id":52385883},{"atb":[[1.02,25.93],[1.1,200]],"id":52385884},{"atl":[[1000,0.23]],"id":52385884},{"atb":[[1.01,51.87],[1.1,200]],"id":52385885},{"atl":[[1000,0.23]],"id":52385885},{"atb":[[1.02,25.93],[1.1,200]],"id":52385896},{"atl":[[1000,0.23]],"id":52385896},{"atb":[[1.03,17.29],[1.1,200]],"id":52385897},{"atl":[[1000,0.23]],"id":52385897},{"atb":[[1.01,51.87],[1.1,200]],"id":52385890},{"atl":[[1000,0.23]],"id":52385890},{"atb":[[1.02,25.93],[1.1,200]],"id":52385891},{"atl":[[1000,0.23]],"id":52385891},{"atb":[[1.03,17.29],[1.1,200]],"id":52385892},{"atl":[[990,0.23]],"id":52385892},{"atb":[[1.03,17.29],[1.1,200]],"id":52385903},{"atl":[[1000,0.23]],"id":52385903},{"atb":[[1.03,17.29],[1.1,200]],"id":52385904},{"atl":[[990,0.23]],"id":52385904},{"atb":[[1.03,17.29],[1.1,200]],"id":52385905},{"atl":[[1000,0.23]],"id":52385905},{"atb":[[1.03,17.29],[1.1,200]],"id":52385898},{"atl":[[1000,0.23]],"id":52385898},{"atb":[[1.02,25.93],[1.1,200]],"id":52385899},{"atl":[[1000,0.23]],"id":52385899}],"con":true,"img":true}]}
{"op":"mcm","clk":"11548271156","pt":1719455882674,"mc":[{"id":"1.230178130","marketDefinition":{"bspMarket":false,"turnInPlayEnabled":false,"persistenceEnabled":false,"marketBaseRate":5.0,"eventId":"33376048","eventTypeId":"4339","numberOfWinners":1,"bettingType":"ODDS","marketType":"FORECAST","marketTime":"2024-06-27T13:29:00.000Z","suspendTime":"2024-06-27T13:29:00.000Z","bspReconciled":false,"complete":true,"inPlay":false,"crossMatching":false,"runnersVoidable":false,"numberOfActiveRunners":20,"betDelay":0,"status":"OPEN","runners":[{"status":"ACTIVE","sortPriority":1,"id":52385882,"name":"1 - 2"},{"status":"ACTIVE","sortPriority":2,"id":52385883,"name":"1 - 3"},{"status":"ACTIVE","sortPriority":3,"id":52385884,"name":"1 - 4"},{"status":"ACTIVE","sortPriority":4,"id":52385885,"name":"1 - 5"},{"status":"ACTIVE","sortPriority":5,"id":52385889,"name":"2 - 1"},{"status":"ACTIVE","sortPriority":6,"id":52385890,"name":"2 - 3"},{"status":"ACTIVE","sortPriority":7,"id":52385891,"name":"2 - 4"},{"status":"ACTIVE","sortPriority":8,"id":52385892,"name":"2 - 5"},{"status":"ACTIVE","sortPriority":9,"id":52385896,"name":"3 - 1"},{"status":"ACTIVE","sortPriority":10,"id":52385897,"name":"3 - 2"},{"status":"ACTIVE","sortPriority":11,"id":52385898,"name":"3 - 4"},{"status":"ACTIVE","sortPriority":12,"id":52385899,"name":"3 - 5"},{"status":"ACTIVE","sortPriority":13,"id":52385903,"name":"4 - 1"},{"status":"ACTIVE","sortPriority":14,"id":52385904,"name":"4 - 2"},{"status":"ACTIVE","sortPriority":15,"id":52385905,"name":"4 - 3"},{"status":"ACTIVE","sortPriority":16,"id":52385906,"name":"4 - 5"},{"status":"ACTIVE","sortPriority":17,"id":52385910,"name":"5 - 1"},{"status":"ACTIVE","sortPriority":18,"id":52385911,"name":"5 - 2"},{"status":"ACTIVE","sortPriority":19,"id":52385912,"name":"5 - 3"},{"status":"ACTIVE","sortPriority":20,"id":52385913,"name":"5 - 4"}],"regulators":["MR_INT"],"venue":"Perry Barr","countryCode":"GB","discountAllowed":true,"timezone":"Europe/London","openDate":"2024-06-27T13:29:00.000Z","version":5994794114,"name":"Forecast","eventName":"Perry Barr (F/C) 27th Jun"},"rc":[{"atb":[[1.02,25.93],[1.1,200]],"id":52385910},{"atl":[[990,0.23]],"id":52385910},{"atb":[[1.01,51.86],[1.1,200]],"id":52385911},{"atl":[[1000,0.23]],"id":52385911},{"atb":[[1.01,51.86],[1.1,200]],"id":52385912},{"atl":[[990,0.23]],"id":52385912},{"atb":[[1.02,25.93],[1.1,200]],"id":52385913},{"atl":[[990,0.23]],"id":52385913},{"atb":[[1.03,17.29],[1.1,200]],"id":52385906},{"atl":[[990,0.23]],"id":52385906},{"atb":[[1.02,25.93],[1.1,200]],"id":52385889},{"atl":[[1000,0.23]],"id":52385889},{"atb":[[1.03,17.29],[1.1,200]],"id":52385882},{"atl":[[990,0.23]],"id":52385882},{"atb":[[1.02,25.93],[1.1,200]],"id":52385883},{"atl":[[990,0.23]],"id":52385883},{"atb":[[1.02,25.93],[1.1,200]],"id":52385884},{"atl":[[1000,0.23]],"id":52385884},{"atb":[[1.01,51.86],[1.1,200]],"id":52385885},{"atl":[[1000,0.23]],"id":52385885},{"atb":[[1.02,25.93],[1.1,200]],"id":52385896},{"atl":[[1000,0.23]],"id":52385896},{"atb":[[1.03,17.29],[1.1,200]],"id":52385897},{"atl":[[1000,0.23]],"id":52385897},{"atb":[[1.01,51.86],[1.1,200]],"id":52385890},{"atl":[[1000,0.23]],"id":52385890},{"atb":[[1.02,25.93],[1.1,200]],"id":52385891},{"atl":[[1000,0.23]],"id":52385891},{"atb":[[1.03,17.29],[1.1,200]],"id":52385892},{"atl":[[990,0.23]],"id":52385892},{"atb":[[1.03,17.29],[1.1,200]],"id":52385903},{"atl":[[1000,0.23]],"id":52385903},{"atb":[[1.03,17.29],[1.1,200]],"id":52385904},{"atl":[[990,0.23]],"id":52385904},{"atb":[[1.03,17.29],[1.1,200]],"id":52385905},{"atl":[[1000,0.23]],"id":52385905},{"atb":[[1.03,17.29],[1.1,200]],"id":52385898},{"atl":[[1000,0.23]],"id":52385898},{"atb":[[1.02,25.93],[1.1,200]],"id":52385899},{"atl":[[1000,0.23]],"id":52385899}],"con":true,"img":true}]}
{"op":"mcm","clk":"11548426602","pt":1719461282639,"mc":[{"id":"1.230178130","marketDefinition":{"bspMarket":false,"turnInPlayEnabled":false,"persistenceEnabled":false,"marketBaseRate":5.0,"eventId":"33376048","eventTypeId":"4339","numberOfWinners":1,"bettingType":"ODDS","marketType":"FORECAST","marketTime":"2024-06-27T13:29:00.000Z","suspendTime":"2024-06-27T13:29:00.000Z","bspReconciled":false,"complete":true,"inPlay":false,"crossMatching":false,"runnersVoidable":false,"numberOfActiveRunners":20,"betDelay":0,"status":"OPEN","runners":[{"status":"ACTIVE","sortPriority":1,"id":52385882,"name":"1 - 2"},{"status":"ACTIVE","sortPriority":2,"id":52385883,"name":"1 - 3"},{"status":"ACTIVE","sortPriority":3,"id":52385884,"name":"1 - 4"},{"status":"ACTIVE","sortPriority":4,"id":52385885,"name":"1 - 5"},{"status":"ACTIVE","sortPriority":5,"id":52385889,"name":"2 - 1"},{"status":"ACTIVE","sortPriority":6,"id":52385890,"name":"2 - 3"},{"status":"ACTIVE","sortPriority":7,"id":52385891,"name":"2 - 4"},{"status":"ACTIVE","sortPriority":8,"id":52385892,"name":"2 - 5"},{"status":"ACTIVE","sortPriority":9,"id":52385896,"name":"3 - 1"},{"status":"ACTIVE","sortPriority":10,"id":52385897,"name":"3 - 2"},{"status":"ACTIVE","sortPriority":11,"id":52385898,"name":"3 - 4"},{"status":"ACTIVE","sortPriority":12,"id":52385899,"name":"3 - 5"},{"status":"ACTIVE","sortPriority":13,"id":52385903,"name":"4 - 1"},{"status":"ACTIVE","sortPriority":14,"id":52385904,"name":"4 - 2"},{"status":"ACTIVE","sortPriority":15,"id":52385905,"name":"4 - 3"},{"status":"ACTIVE","sortPriority":16,"id":52385906,"name":"4 - 5"},{"status":"ACTIVE","sortPriority":17,"id":52385910,"name":"5 - 1"},{"status":"ACTIVE","sortPriority":18,"id":52385911,"name":"5 - 2"},{"status":"ACTIVE","sortPriority":19,"id":52385912,"name":"5 - 3"},{"status":"ACTIVE","sortPriority":20,"id":52385913,"name":"5 - 4"}],"regulators":["MR_INT"],"venue":"Perry Barr","countryCode":"GB","discountAllowed":true,"timezone":"Europe/London","openDate":"2024-06-27T13:29:00.000Z","version":5994794114,"name":"Forecast","eventName":"Perry Barr (F/C) 27th Jun"},"rc":[{"atb":[[1.02,25.93],[1.1,200]],"id":52385910},{"atl":[[990,0.23]],"id":52385910},{"atb":[[1.01,51.87],[1.1,200]],"id":52385911},{"atl":[[1000,0.23]],"id":52385911},{"atb":[[1.01,51.87],[1.1,200]],"id":52385912},{"atl":[[990,0.23]],"id":52385912},{"atb":[[1.02,25.93],[1.1,200]],"id":52385913},{"atl":[[990,0.23]],"id":52385913},{"atb":[[1.03,17.29],[1.1,200]],"id":52385906},{"atl":[[990,0.23]],"id":52385906},{"atb":[[1.02,25.93],[1.1,200]],"id":52385889},{"atl":[[1000,0.23]],"id":52385889},{"atb":[[1.03,17.29],[1.1,200]],"id":52385882},{"atl":[[990,0.23]],"id":52385882},{"atb":[[1.02,25.93],[1.1,200]],"id":52385883},{"atl":[[990,0.23]],"id":52385883},{"atb":[[1.02,25.93],[1.1,200]],"id":52385884},{"atl":[[1000,0.23]],"id":52385884},{"atb":[[1.01,51.87],[1.1,200]],"id":52385885},{"atl":[[1000,0.23]],"id":52385885},{"atb":[[1.02,25.93],[1.1,200]],"id":52385896},{"atl":[[1000,0.23]],"id":52385896},{"atb":[[1.03,17.29],[1.1,200]],"id":52385897},{"atl":[[1000,0.23]],"id":52385897},{"atb":[[1.01,51.87],[1.1,200]],"id":52385890},{"atl":[[1000,0.23]],"id":52385890},{"atb":[[1.02,25.93],[1.1,200]],"id":52385891},{"atl":[[1000,0.23]],"id":52385891},{"atb":[[1.03,17.29],[1.1,200]],"id":52385892},{"atl":[[990,0.23]],"id":52385892},{"atb":[[1.03,17.29],[1.1,200]],"id":52385903},{"atl":[[1000,0.23]],"id":52385903},{"atb":[[1.03,17.29],[1.1,200]],"id":52385904},{"atl":[[990,0.23]],"id":52385904},{"atb":[[1.03,17.29],[1.1,200]],"id":52385905},{"atl":[[1000,0.23]],"id":52385905},{"atb":[[1.03,17.29],[1.1,200]],"id":52385898},{"atl":[[1000,0.23]],"id":52385898},{"atb":[[1.02,25.93],[1.1,200]],"id":52385899},{"atl":[[1000,0.23]],"id":52385899}],"con":true,"img":true}]}
{"op":"mcm","clk":"11548536083","pt":1719466682835,"mc":[{"id":"1.230178130","marketDefinition":{"bspMarket":false,"turnInPlayEnabled":false,"persistenceEnabled":false,"marketBaseRate":5.0,"eventId":"33376048","eventTypeId":"4339","numberOfWinners":1,"bettingType":"ODDS","marketType":"FORECAST","marketTime":"2024-06-27T13:29:00.000Z","suspendTime":"2024-06-27T13:29:00.000Z","bspReconciled":false,"complete":true,"inPlay":false,"crossMatching":false,"runnersVoidable":false,"numberOfActiveRunners":20,"betDelay":0,"status":"OPEN","runners":[{"status":"ACTIVE","sortPriority":1,"id":52385882,"name":"1 - 2"},{"status":"ACTIVE","sortPriority":2,"id":52385883,"name":"1 - 3"},{"status":"ACTIVE","sortPriority":3,"id":52385884,"name":"1 - 4"},{"status":"ACTIVE","sortPriority":4,"id":52385885,"name":"1 - 5"},{"status":"ACTIVE","sortPriority":5,"id":52385889,"name":"2 - 1"},{"status":"ACTIVE","sortPriority":6,"id":52385890,"name":"2 - 3"},{"status":"ACTIVE","sortPriority":7,"id":52385891,"name":"2 - 4"},{"status":"ACTIVE","sortPriority":8,"id":52385892,"name":"2 - 5"},{"status":"ACTIVE","sortPriority":9,"id":52385896,"name":"3 - 1"},{"status":"ACTIVE","sortPriority":10,"id":52385897,"name":"3 - 2"},{"status":"ACTIVE","sortPriority":11,"id":52385898,"name":"3 - 4"},{"status":"ACTIVE","sortPriority":12,"id":52385899,"name":"3 - 5"},{"status":"ACTIVE","sortPriority":13,"id":52385903,"name":"4 - 1"},{"status":"ACTIVE","sortPriority":14,"id":52385904,"name":"4 - 2"},{"status":"ACTIVE","sortPriority":15,"id":52385905,"name":"4 - 3"},{"status":"ACTIVE","sortPriority":16,"id":52385906,"name":"4 - 5"},{"status":"ACTIVE","sortPriority":17,"id":52385910,"name":"5 - 1"},{"status":"ACTIVE","sortPriority":18,"id":52385911,"name":"5 - 2"},{"status":"ACTIVE","sortPriority":19,"id":52385912,"name":"5 - 3"},{"status":"ACTIVE","sortPriority":20,"id":52385913,"name":"5 - 4"}],"regulators":["MR_INT"],"venue":"Perry Barr","countryCode":"GB","discountAllowed":true,"timezone":"Europe/London","openDate":"2024-06-27T13:29:00.000Z","version":5994794114,"name":"Forecast","eventName":"Perry Barr (F/C) 27th Jun"},"rc":[{"atb":[[1.02,25.93],[1.1,200]],"id":52385910},{"atl":[[990,0.23]],"id":52385910},{"atb":[[1.01,51.86],[1.1,200]],"id":52385911},{"atl":[[1000,0.23]],"id":52385911},{"atb":[[1.01,51.86],[1.1,200]],"id":52385912},{"atl":[[990,0.23]],"id":52385912},{"atb":[[1.02,25.93],[1.1,200]],"id":52385913},{"atl":[[990,0.23]],"id":52385913},{"atb":[[1.03,17.29],[1.1,200]],"id":52385906},{"atl":[[990,0.23]],"id":52385906},{"atb":[[1.02,25.93],[1.1,200]],"id":52385889},{"atl":[[1000,0.23]],"id":52385889},{"atb":[[1.03,17.29],[1.1,200]],"id":52385882},{"atl":[[990,0.23]],"id":52385882},{"atb":[[1.02,25.93],[1.1,200]],"id":52385883},{"atl":[[990,0.23]],"id":52385883},{"atb":[[1.02,25.93],[1.1,200]],"id":52385884},{"atl":[[1000,0.23]],"id":52385884},{"atb":[[1.01,51.86],[1.1,200]],"id":52385885},{"atl":[[1000,0.23]],"id":52385885},{"atb":[[1.02,25.93],[1.1,200]],"id":52385896},{"atl":[[1000,0.23]],"id":52385896},{"atb":[[1.03,17.29],[1.1,200]],"id":52385897},{"atl":[[1000,0.23]],"id":52385897},{"atb":[[1.01,51.86],[1.1,200]],"id":52385890},{"atl":[[1000,0.23]],"id":52385890},{"atb":[[1.02,25.93],[1.1,200]],"id":52385891},{"atl":[[1000,0.23]],"id":52385891},{"atb":[[1.03,17.29],[1.1,200]],"id":52385892},{"atl":[[990,0.23]],"id":52385892},{"atb":[[1.03,17.29],[1.1,200]],"id":52385903},{"atl":[[1000,0.23]],"id":52385903},{"atb":[[1.03,17.29],[1.1,200]],"id":52385904},{"atl":[[990,0.23]],"id":52385904},{"atb":[[1.03,17.29],[1.1,200]],"id":52385905},{"atl":[[1000,0.23]],"id":52385905},{"atb":[[1.03,17.29],[1.1,200]],"id":52385898},{"atl":[[1000,0.23]],"id":52385898},{"atb":[[1.02,25.93],[1.1,200]],"id":52385899},{"atl":[[1000,0.23]],"id":52385899}],"con":true,"img":true}]}
{"op":"mcm","clk":"11548656545","pt":1719472082606,"mc":[{"id":"1.230178130","marketDefinition":{"bspMarket":false,"turnInPlayEnabled":false,"persistenceEnabled":false,"marketBaseRate":5.0,"eventId":"33376048","eventTypeId":"4339","numberOfWinners":1,"bettingType":"ODDS","marketType":"FORECAST","marketTime":"2024-06-27T13:29:00.000Z","suspendTime":"2024-06-27T13:29:00.000Z","bspReconciled":false,"complete":true,"inPlay":false,"crossMatching":false,"runnersVoidable":false,"numberOfActiveRunners":20,"betDelay":0,"status":"OPEN","runners":[{"status":"ACTIVE","sortPriority":1,"id":52385882,"name":"1 - 2"},{"status":"ACTIVE","sortPriority":2,"id":52385883,"name":"1 - 3"},{"status":"ACTIVE","sortPriority":3,"id":52385884,"name":"1 - 4"},{"status":"ACTIVE","sortPriority":4,"id":52385885,"name":"1 - 5"},{"status":"ACTIVE","sortPriority":5,"id":52385889,"name":"2 - 1"},{"status":"ACTIVE","sortPriority":6,"id":52385890,"name":"2 - 3"},{"status":"ACTIVE","sortPriority":7,"id":52385891,"name":"2 - 4"},{"status":"ACTIVE","sortPriority":8,"id":52385892,"name":"2 - 5"},{"status":"ACTIVE","sortPriority":9,"id":52385896,"name":"3 - 1"},{"status":"ACTIVE","sortPriority":10,"id":52385897,"name":"3 - 2"},{"status":"ACTIVE","sortPriority":11,"id":52385898,"name":"3 - 4"},{"status":"ACTIVE","sortPriority":12,"id":52385899,"name":"3 - 5"},{"status":"ACTIVE","sortPriority":13,"id":52385903,"name":"4 - 1"},{"status":"ACTIVE","sortPriority":14,"id":52385904,"name":"4 - 2"},{"status":"ACTIVE","sortPriority":15,"id":52385905,"name":"4 - 3"},{"status":"ACTIVE","sortPriority":16,"id":52385906,"name":"4 - 5"},{"status":"ACTIVE","sortPriority":17,"id":52385910,"name":"5 - 1"},{"status":"ACTIVE","sortPriority":18,"id":52385911,"name":"5 - 2"},{"status":"ACTIVE","sortPriority":19,"id":52385912,"name":"5 - 3"},{"status":"ACTIVE","sortPriority":20,"id":52385913,"name":"5 - 4"}],"regulators":["MR_INT"],"venue":"Perry Barr","countryCode":"GB","discountAllowed":true,"timezone":"Europe/London","openDate":"2024-06-27T13:29:00.000Z","version":5994794114,"name":"Forecast","eventName":"Perry Barr (F/C) 27th Jun"},"rc":[{"atb":[[1.02,25.91],[1.1,200]],"id":52385910},{"atl":[[990,0.23]],"id":52385910},{"atb":[[1.01,51.82],[1.1,200]],"id":52385911},{"atl":[[1000,0.23]],"id":52385911},{"atb":[[1.01,51.82],[1.1,200]],"id":52385912},{"atl":[[990,0.23]],"id":52385912},{"atb":[[1.02,25.91],[1.1,200]],"id":52385913},{"atl":[[990,0.23]],"id":52385913},{"atb":[[1.03,17.27],[1.1,200]],"id":52385906},{"atl":[[990,0.23]],"id":52385906},{"atb":[[1.02,25.91],[1.1,200]],"id":52385889},{"atl":[[1000,0.23]],"id":52385889},{"atb":[[1.03,17.27],[1.1,200]],"id":52385882},{"atl":[[990,0.23]],"id":52385882},{"atb":[[1.02,25.91],[1.1,200]],"id":52385883},{"atl":[[990,0.23]],"id":52385883},{"atb":[[1.02,25.91],[1.1,200]],"id":52385884},{"atl":[[1000,0.23]],"id":52385884},{"atb":[[1.01,51.82],[1.1,200]],"id":52385885},{"atl":[[1000,0.23]],"id":52385885},{"atb":[[1.02,25.91],[1.1,200]],"id":52385896},{"atl":[[1000,0.23]],"id":52385896},{"atb":[[1.03,17.27],[1.1,200]],"id":52385897},{"atl":[[1000,0.23]],"id":52385897},{"atb":[[1.01,51.82],[1.1,200]],"id":52385890},{"atl":[[1000,0.23]],"id":52385890},{"atb":[[1.02,25.91],[1.1,200]],"id":52385891},{"atl":[[1000,0.23]],"id":52385891},{"atb":[[1.03,17.27],[1.1,200]],"id":52385892},{"atl":[[990,0.23]],"id":52385892},{"atb":[[1.03,17.27],[1.1,200]],"id":52385903},{"atl":[[1000,0.23]],"id":52385903},{"atb":[[1.03,17.27],[1.1,200]],"id":52385904},{"atl":[[990,0.23]],"id":52385904},{"atb":[[1.03,17.27],[1.1,200]],"id":52385905},{"atl":[[1000,0.23]],"id":52385905},{"atb":[[1.03,17.27],[1.1,200]],"id":52385898},{"atl":[[1000,0.23]],"id":52385898},{"atb":[[1.02,25.91],[1.1,200]],"id":52385899},{"atl":[[1000,0.23]],"id":52385899}],"con":true,"img":true}]}
{"op":"mcm","clk":"11548862313","pt":1719477482604,"mc":[{"id":"1.230178130","marketDefinition":{"bspMarket":false,"turnInPlayEnabled":false,"persistenceEnabled":false,"marketBaseRate":5.0,"eventId":"33376048","eventTypeId":"4339","numberOfWinners":1,"bettingType":"ODDS","marketType":"FORECAST","marketTime":"2024-06-27T13:29:00.000Z","suspendTime":"2024-06-27T13:29:00.000Z","bspReconciled":false,"complete":true,"inPlay":false,"crossMatching":false,"runnersVoidable":false,"numberOfActiveRunners":20,"betDelay":0,"status":"OPEN","runners":[{"status":"ACTIVE","sortPriority":1,"id":52385882,"name":"1 - 2"},{"status":"ACTIVE","sortPriority":2,"id":52385883,"name":"1 - 3"},{"status":"ACTIVE","sortPriority":3,"id":52385884,"name":"1 - 4"},{"status":"ACTIVE","sortPriority":4,"id":52385885,"name":"1 - 5"},{"status":"ACTIVE","sortPriority":5,"id":52385889,"name":"2 - 1"},{"status":"ACTIVE","sortPriority":6,"id":52385890,"name":"2 - 3"},{"status":"ACTIVE","sortPriority":7,"id":52385891,"name":"2 - 4"},{"status":"ACTIVE","sortPriority":8,"id":52385892,"name":"2 - 5"},{"status":"ACTIVE","sortPriority":9,"id":52385896,"name":"3 - 1"},{"status":"ACTIVE","sortPriority":10,"id":52385897,"name":"3 - 2"},{"status":"ACTIVE","sortPriority":11,"id":52385898,"name":"3 - 4"},{"status":"ACTIVE","sortPriority":12,"id":52385899,"name":"3 - 5"},{"status":"ACTIVE","sortPriority":13,"id":52385903,"name":"4 - 1"},{"status":"ACTIVE","sortPriority":14,"id":52385904,"name":"4 - 2"},{"status":"ACTIVE","sortPriority":15,"id":52385905,"name":"4 - 3"},{"status":"ACTIVE","sortPriority":16,"id":52385906,"name":"4 - 5"},{"status":"ACTIVE","sortPriority":17,"id":52385910,"name":"5 - 1"},{"status":"ACTIVE","sortPriority":18,"id":52385911,"name":"5 - 2"},{"status":"ACTIVE","sortPriority":19,"id":52385912,"name":"5 - 3"},{"status":"ACTIVE","sortPriority":20,"id":52385913,"name":"5 - 4"}],"regulators":["MR_INT"],"venue":"Perry Barr","countryCode":"GB","discountAllowed":true,"timezone":"Europe/London","openDate":"2024-06-27T13:29:00.000Z","version":5994794114,"name":"Forecast","eventName":"Perry Barr (F/C) 27th Jun"},"rc":[{"atb":[[1.02,25.92],[1.1,200]],"id":52385910},{"atl":[[990,0.23]],"id":52385910},{"atb":[[1.01,51.84],[1.1,200]],"id":52385911},{"atl":[[1000,0.23]],"id":52385911},{"atb":[[1.01,51.84],[1.1,200]],"id":52385912},{"atl":[[990,0.23]],"id":52385912},{"atb":[[1.02,25.92],[1.1,200]],"id":52385913},{"atl":[[990,0.23]],"id":52385913},{"atb":[[1.03,17.28],[1.1,200]],"id":52385906},{"atl":[[990,0.23]],"id":52385906},{"atb":[[1.02,25.92],[1.1,200]],"id":52385889},{"atl":[[1000,0.23]],"id":52385889},{"atb":[[1.03,17.28],[1.1,200]],"id":52385882},{"atl":[[990,0.23]],"id":52385882},{"atb":[[1.02,25.92],[1.1,200]],"id":52385883},{"atl":[[990,0.23]],"id":52385883},{"atb":[[1.02,25.92],[1.1,200]],"id":52385884},{"atl":[[1000,0.23]],"id":52385884},{"atb":[[1.01,51.84],[1.1,200]],"id":52385885},{"atl":[[1000,0.23]],"id":52385885},{"atb":[[1.02,25.92],[1.1,200]],"id":52385896},{"atl":[[1000,0.23]],"id":52385896},{"atb":[[1.03,17.28],[1.1,200]],"id":52385897},{"atl":[[1000,0.23]],"id":52385897},{"atb":[[1.01,51.84],[1.1,200]],"id":52385890},{"atl":[[1000,0.23]],"id":52385890},{"atb":[[1.02,25.92],[1.1,200]],"id":52385891},{"atl":[[1000,0.23]],"id":52385891},{"atb":[[1.03,17.28],[1.1,200]],"id":52385892},{"atl":[[990,0.23]],"id":52385892},{"atb":[[1.03,17.28],[1.1,200]],"id":52385903},{"atl":[[1000,0.23]],"id":52385903},{"atb":[[1.03,17.28],[1.1,200]],"id":52385904},{"atl":[[990,0.23]],"id":52385904},{"atb":[[1.03,17.28],[1.1,200]],"id":52385905},{"atl":[[1000,0.23]],"id":52385905},{"atb":[[1.03,17.28],[1.1,200]],"id":52385898},{"atl":[[1000,0.23]],"id":52385898},{"atb":[[1.02,25.92],[1.1,200]],"id":52385899},{"atl":[[1000,0.23]],"id":52385899}],"con":true,"img":true}]}
{"op":"mcm","clk":"11549140650","pt":1719482882608,"mc":[{"id":"1.230178130","marketDefinition":{"bspMarket":false,"turnInPlayEnabled":false,"persistenceEnabled":false,"marketBaseRate":5.0,"eventId":"33376048","eventTypeId":"4339","numberOfWinners":1,"bettingType":"ODDS","marketType":"FORECAST","marketTime":"2024-06-27T13:29:00.000Z","suspendTime":"2024-06-27T13:29:00.000Z","bspReconciled":false,"complete":true,"inPlay":false,"crossMatching":false,"runnersVoidable":false,"numberOfActiveRunners":20,"betDelay":0,"status":"OPEN","runners":[{"status":"ACTIVE","sortPriority":1,"id":52385882,"name":"1 - 2"},{"status":"ACTIVE","sortPriority":2,"id":52385883,"name":"1 - 3"},{"status":"ACTIVE","sortPriority":3,"id":52385884,"name":"1 - 4"},{"status":"ACTIVE","sortPriority":4,"id":52385885,"name":"1 - 5"},{"status":"ACTIVE","sortPriority":5,"id":52385889,"name":"2 - 1"},{"status":"ACTIVE","sortPriority":6,"id":52385890,"name":"2 - 3"},{"status":"ACTIVE","sortPriority":7,"id":52385891,"name":"2 - 4"},{"status":"ACTIVE","sortPriority":8,"id":52385892,"name":"2 - 5"},{"status":"ACTIVE","sortPriority":9,"id":52385896,"name":"3 - 1"},{"status":"ACTIVE","sortPriority":10,"id":52385897,"name":"3 - 2"},{"status":"ACTIVE","sortPriority":11,"id":52385898,"name":"3 - 4"},{"status":"ACTIVE","sortPriority":12,"id":52385899,"name":"3 - 5"},{"status":"ACTIVE","sortPriority":13,"id":52385903,"name":"4 - 1"},{"status":"ACTIVE","sortPriority":14,"id":52385904,"name":"4 - 2"},{"status":"ACTIVE","sortPriority":15,"id":52385905,"name":"4 - 3"},{"status":"ACTIVE","sortPriority":16,"id":52385906,"name":"4 - 5"},{"status":"ACTIVE","sortPriority":17,"id":52385910,"name":"5 - 1"},{"status":"ACTIVE","sortPriority":18,"id":52385911,"name":"5 - 2"},{"status":"ACTIVE","sortPriority":19,"id":52385912,"name":"5 - 3"},{"status":"ACTIVE","sortPriority":20,"id":52385913,"name":"5 - 4"}],"regulators":["MR_INT"],"venue":"Perry Barr","countryCode":"GB","discountAllowed":true,"timezone":"Europe/London","openDate":"2024-06-27T13:29:00.000Z","version":5994794114,"name":"Forecast","eventName":"Perry Barr (F/C) 27th Jun"},"rc":[{"atb":[[1.02,25.91],[1.1,200]],"id":52385910},{"atl":[[990,0.23]],"id":52385910},{"atb":[[1.01,51.83],[1.1,200]],"id":52385911},{"atl":[[1000,0.23]],"id":52385911},{"atb":[[1.01,51.83],[1.1,200]],"id":52385912},{"atl":[[990,0.23]],"id":52385912},{"atb":[[1.02,25.91],[1.1,200]],"id":52385913},{"atl":[[990,0.23]],"id":52385913},{"atb":[[1.03,17.27],[1.1,200]],"id":52385906},{"atl":[[990,0.23]],"id":52385906},{"atb":[[1.02,25.91],[1.1,200]],"id":52385889},{"atl":[[1000,0.23]],"id":52385889},{"atb":[[1.03,17.27],[1.1,200]],"id":52385882},{"atl":[[990,0.23]],"id":52385882},{"atb":[[1.02,25.91],[1.1,200]],"id":52385883},{"atl":[[990,0.23]],"id":52385883},{"atb":[[1.02,25.91],[1.1,200]],"id":52385884},{"atl":[[1000,0.23]],"id":52385884},{"atb":[[1.01,51.83],[1.1,200]],"id":52385885},{"atl":[[1000,0.23]],"id":52385885},{"atb":[[1.02,25.91],[1.1,200]],"id":52385896},{"atl":[[1000,0.23]],"id":52385896},{"atb":[[1.03,17.27],[1.1,200]],"id":52385897},{"atl":[[1000,0.23]],"id":52385897},{"atb":[[1.01,51.83],[1.1,200]],"id":52385890},{"atl":[[1000,0.23]],"id":52385890},{"atb":[[1.02,25.91],[1.1,200]],"id":52385891},{"atl":[[1000,0.23]],"id":52385891},{"atb":[[1.03,17.27],[1.1,200]],"id":52385892},{"atl":[[990,0.23]],"id":52385892},{"atb":[[1.03,17.27],[1.1,200]],"id":52385903},{"atl":[[1000,0.23]],"id":52385903},{"atb":[[1.03,17.27],[1.1,200]],"id":52385904},{"atl":[[990,0.23]],"id":52385904},{"atb":[[1.03,17.27],[1.1,200]],"id":52385905},{"atl":[[1000,0.23]],"id":52385905},{"atb":[[1.03,17.27],[1.1,200]],"id":52385898},{"atl":[[1000,0.23]],"id":52385898},{"atb":[[1.02,25.91],[1.1,200]],"id":52385899},{"atl":[[1000,0.23]],"id":52385899}],"con":true,"img":true}]}
{"op":"mcm","clk":"11549374387","pt":1719485477596,"mc":[{"id":"1.230178130","rc":[{"atb":[[1.01,204.08],[1.02,25.91]],"id":52385910},{"atl":[[990,0.23]],"id":52385910},{"atb":[[1.01,255.91]],"id":52385911},{"atl":[[1000,0.23]],"id":52385911},{"atb":[[1.01,51.83]],"id":52385912},{"atl":[[990,0.23]],"id":52385912},{"atb":[[1.02,25.91]],"id":52385913},{"atl":[[990,0.23]],"id":52385913},{"atb":[[1.01,204.08],[1.03,17.27]],"id":52385906},{"atl":[[990,0.23]],"id":52385906},{"atb":[[1.01,204.08],[1.02,25.91]],"id":52385889},{"atl":[[1000,0.23]],"id":52385889},{"atb":[[1.01,204.08],[1.03,17.27]],"id":52385882},{"atl":[[990,0.23]],"id":52385882},{"atb":[[1.01,204.08],[1.02,25.91]],"id":52385883},{"atl":[[990,0.23]],"id":52385883},{"atb":[[1.01,204.08],[1.02,25.91]],"id":52385884},{"atl":[[1000,0.23]],"id":52385884},{"atb":[[1.01,255.91]],"id":52385885},{"atl":[[1000,0.23]],"id":52385885},{"atb":[[1.01,204.08],[1.02,25.91]],"id":52385896},{"atl":[[1000,0.23]],"id":52385896},{"atb":[[1.01,204.08],[1.03,17.27]],"id":52385897},{"atl":[[1000,0.23]],"id":52385897},{"atb":[[1.01,255.91]],"id":52385890},{"atl":[[1000,0.23]],"id":52385890},{"atb":[[1.01,204.08],[1.02,25.91]],"id":52385891},{"atl":[[1000,0.23]],"id":52385891},{"atb":[[1.01,204.08],[1.03,17.27]],"id":52385892},{"atl":[[990,0.23]],"id":52385892},{"atb":[[1.01,204.08],[1.03,17.27]],"id":52385903},{"atl":[[1000,0.23]],"id":52385903},{"atb":[[1.01,204.08],[1.03,17.27]],"id":52385904},{"atl":[[990,0.23]],"id":52385904},{"atb":[[1.03,17.27]],"id":52385905},{"atl":[[1000,0.23]],"id":52385905},{"atb":[[1.01,204.08],[1.03,17.27]],"id":52385898},{"atl":[[1000,0.23]],"id":52385898},{"atb":[[1.01,204.08],[1.02,25.91]],"id":52385899},{"atl":[[1000,0.23]],"id":52385899}],"con":true,"img":false}]}
{"op":"mcm","clk":"11549374394","pt":1719485477697,"mc":[{"id":"1.230178130","rc":[{"atb":[[1.01,255.91]],"id":52385912},{"atb":[[1.01,204.08]],"id":52385905}],"con":true,"img":false}]}
{"op":"mcm","clk":"11549374423","pt":1719485478010,"mc":[{"id":"1.230178130","rc":[{"atb":[[1.01,204.08]],"id":52385913}],"con":true,"img":false}]}
{"op":"mcm","clk":"11549607109","pt":1719488282624,"mc":[{"id":"1.230178130","marketDefinition":{"bspMarket":false,"turnInPlayEnabled":false,"persistenceEnabled":false,"marketBaseRate":5.0,"eventId":"33376048","eventTypeId":"4339","numberOfWinners":1,"bettingType":"ODDS","marketType":"FORECAST","marketTime":"2024-06-27T13:29:00.000Z","suspendTime":"2024-06-27T13:29:00.000Z","bspReconciled":false,"complete":true,"inPlay":false,"crossMatching":false,"runnersVoidable":false,"numberOfActiveRunners":20,"betDelay":0,"status":"OPEN","runners":[{"status":"ACTIVE","sortPriority":1,"id":52385882,"name":"1 - 2"},{"status":"ACTIVE","sortPriority":2,"id":52385883,"name":"1 - 3"},{"status":"ACTIVE","sortPriority":3,"id":52385884,"name":"1 - 4"},{"status":"ACTIVE","sortPriority":4,"id":52385885,"name":"1 - 5"},{"status":"ACTIVE","sortPriority":5,"id":52385889,"name":"2 - 1"},{"status":"ACTIVE","sortPriority":6,"id":52385890,"name":"2 - 3"},{"status":"ACTIVE","sortPriority":7,"id":52385891,"name":"2 - 4"},{"status":"ACTIVE","sortPriority":8,"id":52385892,"name":"2 - 5"},{"status":"ACTIVE","sortPriority":9,"id":52385896,"name":"3 - 1"},{"status":"ACTIVE","sortPriority":10,"id":52385897,"name":"3 - 2"},{"status":"ACTIVE","sortPriority":11,"id":52385898,"name":"3 - 4"},{"status":"ACTIVE","sortPriority":12,"id":52385899,"name":"3 - 5"},{"status":"ACTIVE","sortPriority":13,"id":52385903,"name":"4 - 1"},{"status":"ACTIVE","sortPriority":14,"id":52385904,"name":"4 - 2"},{"status":"ACTIVE","sortPriority":15,"id":52385905,"name":"4 - 3"},{"status":"ACTIVE","sortPriority":16,"id":52385906,"name":"4 - 5"},{"status":"ACTIVE","sortPriority":17,"id":52385910,"name":"5 - 1"},{"status":"ACTIVE","sortPriority":18,"id":52385911,"name":"5 - 2"},{"status":"ACTIVE","sortPriority":19,"id":52385912,"name":"5 - 3"},{"status":"ACTIVE","sortPriority":20,"id":52385913,"name":"5 - 4"}],"regulators":["MR_INT"],"venue":"Perry Barr","countryCode":"GB","discountAllowed":true,"timezone":"Europe/London","openDate":"2024-06-27T13:29:00.000Z","version":5994794114,"name":"Forecast","eventName":"Perry Barr (F/C) 27th Jun"},"rc":[{"atb":[[1.01,204.08],[1.02,25.91],[1.1,200]],"id":52385910},{"atl":[[990,0.23]],"id":52385910},{"atb":[[1.01,255.91],[1.1,200]],"id":52385911},{"atl":[[1000,0.23]],"id":52385911},{"atb":[[1.01,255.91],[1.1,200]],"id":52385912},{"atl":[[990,0.23]],"id":52385912},{"atb":[[1.01,204.08],[1.02,25.91],[1.1,200]],"id":52385913},{"atl":[[990,0.23]],"id":52385913},{"atb":[[1.01,204.08],[1.03,17.28],[1.1,200]],"id":52385906},{"atl":[[990,0.23]],"id":52385906},{"atb":[[1.01,204.08],[1.02,25.91],[1.1,200]],"id":52385889},{"atl":[[1000,0.23]],"id":52385889},{"atb":[[1.01,204.08],[1.03,17.28],[1.1,200]],"id":52385882},{"atl":[[990,0.23]],"id":52385882},{"atb":[[1.01,204.08],[1.02,25.91],[1.1,200]],"id":52385883},{"atl":[[990,0.23]],"id":52385883},{"atb":[[1.01,204.08],[1.02,25.91],[1.1,200]],"id":52385884},{"atl":[[1000,0.23]],"id":52385884},{"atb":[[1.01,255.91],[1.1,200]],"id":52385885},{"atl":[[1000,0.23]],"id":52385885},{"atb":[[1.01,204.08],[1.02,25.91],[1.1,200]],"id":52385896},{"atl":[[1000,0.23]],"id":52385896},{"atb":[[1.01,204.08],[1.03,17.28],[1.1,200]],"id":52385897},{"atl":[[1000,0.23]],"id":52385897},{"atb":[[1.01,255.91],[1.1,200]],"id":52385890},{"atl":[[1000,0.23]],"id":52385890},{"atb":[[1.01,204.08],[1.02,25.91],[1.1,200]],"id":52385891},{"atl":[[1000,0.23]],"id":52385891},{"atb":[[1.01,204.08],[1.03,17.28],[1.1,200]],"id":52385892},{"atl":[[990,0.23]],"id":52385892},{"atb":[[1.01,204.08],[1.03,17.28],[1.1,200]],"id":52385903},{"atl":[[1000,0.23]],"id":52385903},{"atb":[[1.01,204.08],[1.03,17.28],[1.1,200]],"id":52385904},{"atl":[[990,0.23]],"id":52385904},{"atb":[[1.01,204.08],[1.03,17.28],[1.1,200]],"id":52385905},{"atl":[[1000,0.23]],"id":52385905},{"atb":[[1.01,204.08],[1.03,17.28],[1.1,200]],"id":52385898},{"atl":[[1000,0.23]],"id":52385898},{"atb":[[1.01,204.08],[1.02,25.91],[1.1,200]],"id":52385899},{"atl":[[1000,0.23]],"id":52385899}],"con":true,"img":true}]}
{"op":"mcm","clk":"11549990476","pt":1719493445354,"mc":[{"id":"1.230178130","rc":[{"atb":[[8,12],[1.02,25.95]],"id":52385910},{"atl":[[990,0.23]],"id":52385910},{"atb":[[9,11],[1.01,255.98]],"id":52385911},{"atl":[[1000,0.23]],"id":52385911},{"atb":[[9,11],[1.01,255.98]],"id":52385912},{"atl":[[990,0.23]],"id":52385912},{"atb":[[9,11],[1.02,25.95]],"id":52385913},{"atl":[[990,0.23]],"id":52385913},{"atb":[[1.03,17.3],[10,10]],"id":52385906},{"atl":[[990,0.23]],"id":52385906},{"atb":[[1.02,25.95],[6,12]],"id":52385889},{"atl":[[1000,0.23]],"id":52385889},{"atb":[[1.03,17.3],[6,12]],"id":52385882},{"atl":[[990,0.23]],"id":52385882},{"atb":[[1.02,25.95],[6,12]],"id":52385883},{"atl":[[990,0.23]],"id":52385883},{"atb":[[9,11],[1.02,25.95]],"id":52385884},{"atl":[[1000,0.23]],"id":52385884},{"atb":[[8,12],[1.01,255.98]],"id":52385885},{"atl":[[1000,0.23]],"id":52385885},{"atb":[[5,12],[1.02,25.95]],"id":52385896},{"atl":[[1000,0.23]],"id":52385896},{"atb":[[1.03,17.3],[6,12]],"id":52385897},{"atl":[[1000,0.23]],"id":52385897},{"atb":[[8,12],[1.01,255.98]],"id":52385890},{"atl":[[1000,0.23]],"id":52385890},{"atb":[[10,10],[1.02,25.95]],"id":52385891},{"atl":[[1000,0.23]],"id":52385891},{"atb":[[9,11],[1.03,17.3]],"id":52385892},{"atl":[[990,0.23]],"id":52385892},{"atb":[[9,11],[1.03,17.3]],"id":52385903},{"atl":[[1000,0.23]],"id":52385903},{"atb":[[1.03,17.3],[10,10]],"id":52385904},{"atl":[[990,0.23]],"id":52385904},{"atb":[[9,11],[1.03,17.3]],"id":52385905},{"atl":[[1000,0.23]],"id":52385905},{"atb":[[1.03,17.3],[7,12]],"id":52385898},{"atl":[[1000,0.23]],"id":52385898},{"atb":[[1.02,25.95],[7,12]],"id":52385899},{"atl":[[1000,0.23]],"id":52385899}],"con":true,"img":false}]}
{"op":"mcm","clk":"11549991011","pt":1719493451687,"mc":[{"id":"1.230178130","marketDefinition":{"bspMarket":false,"turnInPlayEnabled":false,"persistenceEnabled":false,"marketBaseRate":5.0,"eventId":"33376048","eventTypeId":"4339","numberOfWinners":1,"bettingType":"ODDS","marketType":"FORECAST","marketTime":"2024-06-27T13:29:00.000Z","suspendTime":"2024-06-27T13:29:00.000Z","bspReconciled":false,"complete":true,"inPlay":false,"crossMatching":true,"runnersVoidable":false,"numberOfActiveRunners":20,"betDelay":0,"status":"OPEN","runners":[{"status":"ACTIVE","sortPriority":1,"id":52385882,"name":"1 - 2"},{"status":"ACTIVE","sortPriority":2,"id":52385883,"name":"1 - 3"},{"status":"ACTIVE","sortPriority":3,"id":52385884,"name":"1 - 4"},{"status":"ACTIVE","sortPriority":4,"id":52385885,"name":"1 - 5"},{"status":"ACTIVE","sortPriority":5,"id":52385889,"name":"2 - 1"},{"status":"ACTIVE","sortPriority":6,"id":52385890,"name":"2 - 3"},{"status":"ACTIVE","sortPriority":7,"id":52385891,"name":"2 - 4"},{"status":"ACTIVE","sortPriority":8,"id":52385892,"name":"2 - 5"},{"status":"ACTIVE","sortPriority":9,"id":52385896,"name":"3 - 1"},{"status":"ACTIVE","sortPriority":10,"id":52385897,"name":"3 - 2"},{"status":"ACTIVE","sortPriority":11,"id":52385898,"name":"3 - 4"},{"status":"ACTIVE","sortPriority":12,"id":52385899,"name":"3 - 5"},{"status":"ACTIVE","sortPriority":13,"id":52385903,"name":"4 - 1"},{"status":"ACTIVE","sortPriority":14,"id":52385904,"name":"4 - 2"},{"status":"ACTIVE","sortPriority":15,"id":52385905,"name":"4 - 3"},{"status":"ACTIVE","sortPriority":16,"id":52385906,"name":"4 - 5"},{"status":"ACTIVE","sortPriority":17,"id":52385910,"name":"5 - 1"},{"status":"ACTIVE","sortPriority":18,"id":52385911,"name":"5 - 2"},{"status":"ACTIVE","sortPriority":19,"id":52385912,"name":"5 - 3"},{"status":"ACTIVE","sortPriority":20,"id":52385913,"name":"5 - 4"}],"regulators":["MR_INT"],"venue":"Perry Barr","countryCode":"GB","discountAllowed":true,"timezone":"Europe/London","openDate":"2024-06-27T13:29:00.000Z","version":5994794114,"name":"Forecast","eventName":"Perry Barr (F/C) 27th Jun"},"rc":[],"con":true,"img":false}]}
{"op":"mcm","clk":"11550019444","pt":1719493687871,"mc":[{"id":"1.230178130","rc":[{"atb":[[10.5,22.7]],"id":52385897},{"atb":[[10.5,22.7]],"id":52385898}],"con":true,"img":false}]}
{"op":"mcm","clk":"11550019488","pt":1719493688257,"mc":[{"id":"1.230178130","rc":[{"atb":[[10.5,0]],"id":52385897},{"atb":[[10.5,0]],"id":52385898}],"con":true,"img":false}]}
{"op":"mcm","clk":"11550057220","pt":1719494040350,"mc":[{"id":"1.230178130","rc":[{"atb":[[5.4,22.73]],"id":52385910},{"atl":[[430,2]],"id":52385910},{"atb":[[8.2,13.89]],"id":52385911},{"atl":[[520,2]],"id":52385911},{"atb":[[5.4,22.73]],"id":52385912},{"atl":[[430,2]],"id":52385912},{"atb":[[8.2,13.89]],"id":52385913},{"atl":[[520,2]],"id":52385913},{"atb":[[7.6,15.15]],"id":52385906},{"atl":[[510,2]],"id":52385906},{"atb":[[5.1,24.39]],"id":52385889},{"atl":[[410,2]],"id":52385889},{"atb":[[5.6,21.74]],"id":52385882},{"atl":[[440,2]],"id":52385882},{"atb":[[4.7,27.03]],"id":52385883},{"atl":[[330,2]],"id":52385883},{"atb":[[6.8,17.24]],"id":52385884},{"atl":[[490,2]],"id":52385884},{"atb":[[6.6,17.86]],"id":52385885},{"atl":[[480,2]],"id":52385885},{"atb":[[4,33.33]],"id":52385896},{"atl":[[220,2]],"id":52385896},{"atb":[[5.1,24.39]],"id":52385897},{"atl":[[390,2]],"id":52385897},{"atb":[[5.3,23.26]],"id":52385890},{"atl":[[420,2]],"id":52385890},{"atb":[[8.6,13.16]],"id":52385891},{"atl":[[530,2]],"id":52385891},{"atb":[[8.4,13.51]],"id":52385892},{"atl":[[530,2]],"id":52385892},{"atb":[[5.3,23.26]],"id":52385903},{"atl":[[420,2]],"id":52385903},{"atb":[[7.8,14.71]],"id":52385904},{"atl":[[520,2]],"id":52385904},{"atb":[[5.3,23.26]],"id":52385905},{"atl":[[420,2]],"id":52385905},{"atb":[[5.3,23.26]],"id":52385898},{"atl":[[420,2]],"id":52385898},{"atb":[[5.2,23.81]],"id":52385899},{"atl":[[410,2]],"id":52385899}],"con":true,"img":false}]}
{"op":"mcm","clk":"11550057463","pt":1719494042546,"mc":[{"id":"1.230178130","rc":[{"atb":[[8,0]],"id":52385910},{"atb":[[9,0]],"id":52385911},{"atb":[[9,0]],"id":52385913},{"atb":[[6,0]],"id":52385889},{"atb":[[6,0]],"id":52385883},{"atb":[[8,0]],"id":52385885},{"atb":[[5,0]],"id":52385896},{"atb":[[6,0]],"id":52385897},{"atb":[[8,0]],"id":52385890},{"atb":[[10,0]],"id":52385891},{"atb":[[9,0]],"id":52385892},{"atb":[[10,0]],"id":52385904},{"atb":[[7,0]],"id":52385899}],"con":true,"img":false}]}
{"op":"mcm","clk":"11550057475","pt":1719494042603,"mc":[{"id":"1.230178130","rc":[{"atb":[[9,12]],"id":52385910},{"atb":[[11,11]],"id":52385911},{"atb":[[10,11]],"id":52385913},{"atb":[[7,12]],"id":52385889},{"atb":[[7,12]],"id":52385883},{"atb":[[9,12]],"id":52385885},{"atb":[[6,12]],"id":52385896},{"atb":[[7,12]],"id":52385897},{"atb":[[9,12]],"id":52385890},{"atb":[[11,10]],"id":52385891},{"atb":[[10,11]],"id":52385892},{"atb":[[11,10]],"id":52385904},{"atb":[[8,12]],"id":52385899}],"con":true,"img":false}]}
{"op":"mcm","clk":"11550057486","pt":1719494042712,"mc":[{"id":"1.230178130","rc":[{"atb":[[2.74,57.47],[4.7,0]],"id":52385883},{"atb":[[8.6,0],[3.65,37.74]],"id":52385891}],"con":true,"img":false}]}
{"op":"mcm","clk":"11550057886","pt":1719494046343,"mc":[{"id":"1.230178130","rc":[{"atl":[[430,0],[460,2]],"id":52385910},{"atl":[[520,0],[550,2]],"id":52385911},{"atl":[[430,0],[450,2]],"id":52385912},{"atl":[[520,0],[550,2]],"id":52385913},{"atl":[[530,2]],"id":52385906},{"atl":[[410,0]],"id":52385889},{"atl":[[440,0],[470,2]],"id":52385882},{"atl":[[370,2]],"id":52385883},{"atl":[[520,2],[490,0]],"id":52385884},{"atl":[[480,0]],"id":52385885},{"atl":[[260,2],[220,0]],"id":52385896},{"atl":[[420,0],[440,2]],"id":52385890},{"atl":[[530,0],[560,2]],"id":52385891},{"atl":[[530,0]],"id":52385892},{"atl":[[420,0],[450,2]],"id":52385903},{"atl":[[540,2]],"id":52385904},{"atl":[[420,0],[440,2]],"id":52385905},{"atl":[[440,2]],"id":52385898},{"atl":[[410,0],[440,2]],"id":52385899}],"con":true,"img":false}]}
{"op":"mcm","clk":"11550057900","pt":1719494046449,"mc":[{"id":"1.230178130","rc":[{"atl":[[510,0]],"id":52385906},{"atl":[[430,2]],"id":52385889},{"atl":[[330,0]],"id":52385883},{"atl":[[510,2]],"id":52385885},{"atl":[[390,0],[420,2]],"id":52385897},{"atl":[[560,2]],"id":52385892},{"atl":[[520,0]],"id":52385904},{"atl":[[420,0]],"id":52385898}],"con":true,"img":false}]}
{"op":"mcm","clk":"11550058565","pt":1719494052865,"mc":[{"id":"1.230178130","rc":[{"atb":[[2.74,0],[4.7,27.03]],"id":52385883},{"atb":[[8.6,13.16],[3.65,0]],"id":52385891}],"con":true,"img":false}]}
{"op":"mcm","clk":"11550058690","pt":1719494054055,"mc":[{"id":"1.230178130","rc":[{"atl":[[20,5]],"id":52385883}],"con":true,"img":false}]}
{"op":"mcm","clk":"11550058732","pt":1719494054531,"mc":[{"id":"1.230178130","rc":[{"atb":[[8,0]],"id":52385899}],"con":true,"img":false}]}
{"op":"mcm","clk":"11550058745","pt":1719494054629,"mc":[{"id":"1.230178130","rc":[{"atb":[[7,12]],"id":52385899}],"con":true,"img":false}]}
{"op":"mcm","clk":"11550058751","pt":1719494054733,"mc":[{"id":"1.230178130","rc":[{"atb":[[5.2,0],[2.84,54.35]],"id":52385899}],"con":true,"img":false}]}
{"op":"mcm","clk":"11550058788","pt":1719494055045,"mc":[{"id":"1.230178130","rc":[{"atl":[[20,0]],"id":52385883}],"con":true,"img":false}]}
{"op":"mcm","clk":"11550059590","pt":1719494063449,"mc":[{"id":"1.230178130","rc":[{"atb":[[7,0]],"id":52385897}],"con":true,"img":false}]}
{"op":"mcm","clk":"11550059602","pt":1719494063551,"mc":[{"id":"1.230178130","rc":[{"atb":[[2.82,54.95],[5.1,0],[6,12]],"id":52385897}],"con":true,"img":false}]}
{"op":"mcm","clk":"11550059709","pt":1719494064734,"mc":[{"id":"1.230178130","rc":[{"atb":[[5.2,23.81],[2.84,0]],"id":52385899}],"con":true,"img":false}]}
{"op":"mcm","clk":"11550060295","pt":1719494071279,"mc":[{"id":"1.230178130","rc":[{"atl":[[430,2],[460,0]],"id":52385910},{"atl":[[520,2],[550,0]],"id":52385911},{"atl":[[430,2],[450,0]],"id":52385912},{"atl":[[520,2],[550,0]],"id":52385913},{"atl":[[530,0],[510,2]],"id":52385906},{"atl":[[410,2],[430,0]],"id":52385889},{"atl":[[440,2]],"id":52385882},{"atl":[[330,2],[370,0]],"id":52385883},{"atl":[[520,0],[490,2]],"id":52385884},{"atl":[[480,2],[510,0]],"id":52385885},{"atl":[[260,0],[220,2]],"id":52385896},{"atl":[[390,2],[420,0]],"id":52385897},{"atl":[[420,2],[440,0]],"id":52385890},{"atl":[[530,2],[560,0]],"id":52385891},{"atl":[[530,2],[560,0]],"id":52385892},{"atl":[[420,2],[450,0]],"id":52385903},{"atl":[[540,0],[520,2]],"id":52385904},{"atl":[[420,2],[440,0]],"id":52385905},{"atl":[[420,2],[440,0]],"id":52385898},{"atl":[[410,2],[440,0]],"id":52385899}],"con":true,"img":false}]}
{"op":"mcm","clk":"11550060305","pt":1719494071385,"mc":[{"id":"1.230178130","rc":[{"atl":[[470,0]],"id":52385882}],"con":true,"img":false}]}
{"op":"mcm","clk":"11550060527","pt":1719494073472,"mc":[{"id":"1.230178130","rc":[{"atb":[[2.82,0],[5.1,24.39]],"id":52385897}],"con":true,"img":false}]}
{"op":"mcm","clk":"11550061038","pt":1719494078573,"mc":[{"id":"1.230178130","rc":[{"atb":[[6,0]],"id":52385882},{"atb":[[11,0]],"id":52385891}],"con":true,"img":false}]}
{"op":"mcm","clk":"11550061048","pt":1719494078678,"mc":[{"id":"1.230178130","rc":[{"atb":[[5.6,0],[2.92,52.08],[7,12]],"id":52385882},{"atb":[[8.6,0],[10,10],[3.65,37.74]],"id":52385891}],"con":true,"img":false}]}
{"op":"mcm","clk":"11550062023","pt":1719494088397,"mc":[{"id":"1.230178130","rc":[{"atb":[[5.6,21.74],[2.92,0]],"id":52385882},{"atb":[[8.6,13.16],[3.65,0]],"id":52385891}],"con":true,"img":false}]}
{"op":"mcm","clk":"11550062240","pt":1719494090515,"mc":[{"id":"1.230178130","rc":[{"atb":[[10,0]],"id":52385906}],"con":true,"img":false}]}
{"op":"mcm","clk":"11550062252","pt":1719494090573,"mc":[{"id":"1.230178130","rc":[{"atb":[[11,10]],"id":52385906}],"con":true,"img":false}]}
{"op":"mcm","clk":"11550062264","pt":1719494090685,"mc":[{"id":"1.230178130","rc":[{"atb":[[7.6,0],[3.4,41.67]],"id":52385906},{"atl":[[17.5,16.43]],"id":52385896},{"atl":[[28,9.48]],"id":52385905}],"con":true,"img":false}]}
{"op":"mcm","clk":"11550062275","pt":1719494090778,"mc":[{"id":"1.230178130","rc":[{"atl":[[22,4.76],[220,0]],"id":52385896},{"atl":[[420,0],[60,2]],"id":52385905}],"con":true,"img":false}]}
{"op":"mcm","clk":"11550062287","pt":1719494090873,"mc":[{"id":"1.230178130","rc":[{"atl":[[17.5,0]],"id":52385896}],"con":true,"img":false}]}
{"op":"mcm","clk":"11550062298","pt":1719494090987,"mc":[{"id":"1.230178130","rc":[{"atl":[[28,0]],"id":52385905}],"con":true,"img":false}]}
{"op":"mcm","clk":"11550062526","pt":1719494093568,"mc":[{"id":"1.230178130","rc":[{"atb":[[7,0]],"id":52385882},{"atb":[[9,0]],"id":52385905}],"con":true,"img":false}]}
{"op":"mcm","clk":"11550062536","pt":1719494093675,"mc":[{"id":"1.230178130","rc":[{"atb":[[6,12]],"id":52385882},{"atb":[[10,11]],"id":52385905}],"con":true,"img":false}]}
{"op":"mcm","clk":"11550062549","pt":1719494093777,"mc":[{"id":"1.230178130","rc":[{"atb":[[5.6,0],[2.92,52.08]],"id":52385882},{"atb":[[2.86,53.76],[5.3,0]],"id":52385905}],"con":true,"img":false}]}
{"op":"mcm","clk":"11550062788","pt":1719494095989,"mc":[{"id":"1.230178130","rc":[{"atl":[[22,0],[220,2]],"id":52385896},{"atl":[[420,2],[60,0]],"id":52385905}],"con":true,"img":false}]}
{"op":"mcm","clk":"11550063201","pt":1719494100297,"mc":[{"id":"1.230178130","rc":[{"atb":[[3.4,0],[7.6,15.15]],"id":52385906}],"con":true,"img":false}]}
{"op":"mcm","clk":"11550063529","pt":1719494103406,"mc":[{"id":"1.230178130","rc":[{"atb":[[5.6,21.74],[2.92,0]],"id":52385882},{"atb":[[2.86,0],[5.3,23.26]],"id":52385905}],"con":true,"img":false}]}
{"op":"mcm","clk":"11550064487","pt":1719494112817,"mc":[{"id":"1.230178130","rc":[{"atl":[[42,6.6]],"id":52385889},{"atl":[[36,7.81]],"id":52385882},{"atb":[[9.6,27.5]],"id":52385905}],"con":true,"img":false}]}
{"op":"mcm","clk":"11550064499","pt":1719494112918,"mc":[{"id":"1.230178130","rc":[{"atl":[[48,6.02]],"id":52385910},{"atl":[[36,6.39]],"id":52385912},{"atb":[[15,18.21]],"id":52385906},{"atl":[[36,7.5]],"id":52385890},{"atb":[[17,15.98]],"id":52385891},{"atb":[[10.5,26.71]],"id":52385903},{"atb":[[13,19.1]],"id":52385904},{"atl":[[30,8.96]],"id":52385899}],"con":true,"img":false}]}
{"op":"mcm","clk":"11550064510","pt":1719494113022,"mc":[{"id":"1.230178130","rc":[{"atl":[[42,0]],"id":52385889},{"atl":[[36,0]],"id":52385882},{"atb":[[9.6,0]],"id":52385905}],"con":true,"img":false}]}
{"op":"mcm","clk":"11550064519","pt":1719494113127,"mc":[{"id":"1.230178130","rc":[{"atl":[[48,0]],"id":52385910},{"atl":[[36,0]],"id":52385912},{"atb":[[15,0]],"id":52385906},{"atl":[[36,0]],"id":52385890},{"atb":[[17,0]],"id":52385891},{"atb":[[10.5,0]],"id":52385903},{"atb":[[13,0]],"id":52385904},{"atl":[[30,0]],"id":52385899}],"con":true,"img":false}]}
{"op":"mcm","clk":"11550073915","pt":1719494210814,"mc":[{"id":"1.230178130","rc":[{"atb":[[7,0]],"id":52385883},{"atb":[[9,0]],"id":52385884},{"atb":[[9,0]],"id":52385903},{"atb":[[7,0]],"id":52385898}],"con":true,"img":false}]}
{"op":"mcm","clk":"11550073924","pt":1719494210917,"mc":[{"id":"1.230178130","rc":[{"atb":[[2.74,57.47],[6,12]],"id":52385883},{"atb":[[3.2,45.45],[10,11],[6.8,0]],"id":52385884},{"atb":[[2.86,53.76],[5.3,0],[12,11]],"id":52385903},{"atb":[[8,12],[2.86,53.76],[5.3,0]],"id":52385898}],"con":true,"img":false}]}
{"op":"mcm","clk":"11550073937","pt":1719494211020,"mc":[{"id":"1.230178130","rc":[{"atb":[[4.7,0]],"id":52385883}],"con":true,"img":false}]}
{"op":"mcm","clk":"11550074798","pt":1719494219340,"mc":[{"id":"1.230178130","rc":[{"atb":[[4.7,27.03]],"id":52385883},{"atb":[[3.2,0],[6.8,17.24]],"id":52385884},{"atb":[[2.86,0],[5.3,23.26]],"id":52385903},{"atb":[[5.3,23.26]],"id":52385898}],"con":true,"img":false}]}
{"op":"mcm","clk":"11550074813","pt":1719494219444,"mc":[{"id":"1.230178130","rc":[{"atb":[[2.74,0]],"id":52385883},{"atb":[[2.86,0]],"id":52385898}],"con":true,"img":false}]}
{"op":"mcm","clk":"11550077207","pt":1719494240976,"mc":[{"id":"1.230178130","rc":[{"atb":[[9,0]],"id":52385885}],"con":true,"img":false}]}
{"op":"mcm","clk":"11550077221","pt":1719494241080,"mc":[{"id":"1.230178130","rc":[{"atb":[[8,12],[3.15,46.51],[6.6,0]],"id":52385885}],"con":true,"img":false}]}
{"op":"mcm","clk":"11550077232","pt":1719494241186,"mc":[{"id":"1.230178130","rc":[{"atb":[[3.15,0],[6.6,17.86]],"id":52385885}],"con":true,"img":false}]}
{"op":"mcm","clk":"11550077303","pt":1719494241859,"mc":[{"id":"1.230178130","rc":[{"atl":[[38,5]],"id":52385903}],"con":true,"img":false}]}
{"op":"mcm","clk":"11550077334","pt":1719494242168,"mc":[{"id":"1.230178130","rc":[{"atl":[[38,0]],"id":52385903}],"con":true,"img":false}]}
{"op":"mcm","clk":"11550077432","pt":1719494243049,"mc":[{"id":"1.230178130","rc":[{"atl":[[34,7.46]],"id":52385910},{"atl":[[95,3.01]],"id":52385904}],"con":true,"img":false}]}
{"op":"mcm","clk":"11550077456","pt":1719494243256,"mc":[{"id":"1.230178130","rc":[{"atl":[[65,2],[430,0]],"id":52385910},{"atl":[[520,0],[120,2]],"id":52385904}],"con":true,"img":false}]}
{"op":"mcm","clk":"11550077475","pt":1719494243462,"mc":[{"id":"1.230178130","rc":[{"atl":[[65,0],[430,2]],"id":52385910},{"atl":[[520,2],[120,0]],"id":52385904},{"atl":[[30,5]],"id":52385905}],"con":true,"img":false}]}
{"op":"mcm","clk":"11550077563","pt":1719494244289,"mc":[{"id":"1.230178130","rc":[{"atl":[[30,0]],"id":52385905}],"con":true,"img":false}]}
{"op":"mcm","clk":"11550077575","pt":1719494244393,"mc":[{"id":"1.230178130","rc":[{"atl":[[34,0]],"id":52385910},{"atl":[[95,0]],"id":52385904}],"con":true,"img":false}]}
{"op":"mcm","clk":"11550077786","pt":1719494246355,"mc":[{"id":"1.230178130","rc":[{"atl":[[90,3.15]],"id":52385906}],"con":true,"img":false}]}
{"op":"mcm","clk":"11550077982","pt":1719494248264,"mc":[{"id":"1.230178130","rc":[{"atl":[[90,0]],"id":52385906}],"con":true,"img":false}]}
{"op":"mcm","clk":"11550081931","pt":1719494285836,"mc":[{"id":"1.230178130","rc":[{"atb":[[9,0]],"id":52385910},{"atb":[[11,0]],"id":52385911}],"con":true,"img":false}]}
{"op":"mcm","clk":"11550081943","pt":1719494285957,"mc":[{"id":"1.230178130","rc":[{"atb":[[8,12],[2.88,53.19],[5.4,0]],"id":52385910},{"atb":[[10,11],[8.2,0],[3.55,39.22]],"id":52385911}],"con":true,"img":false}]}
{"op":"mcm","clk":"11550082786","pt":1719494293590,"mc":[{"id":"1.230178130","rc":[{"atb":[[2.88,0],[5.4,22.73]],"id":52385910}],"con":true,"img":false}]}
{"op":"mcm","clk":"11550082800","pt":1719494293653,"mc":[{"id":"1.230178130","rc":[{"atb":[[8.2,13.89],[3.55,0]],"id":52385911}],"con":true,"img":false}]}
{"op":"mcm","clk":"11550088676","pt":1719494342933,"mc":[{"id":"1.230178130","rc":[{"atb":[[9,0]],"id":52385912}],"con":true,"img":false}]}
{"op":"mcm","clk":"11550088689","pt":1719494343037,"mc":[{"id":"1.230178130","rc":[{"atb":[[2.88,53.19],[10,11],[5.4,0]],"id":52385912}],"con":true,"img":false}]}
{"op":"mcm","clk":"11550088709","pt":1719494343192,"mc":[{"id":"1.230178130","rc":[{"atb":[[2.88,0],[5.4,22.73]],"id":52385912}],"con":true,"img":false}]}
{"op":"mcm","clk":"11550089029","pt":1719494345941,"mc":[{"id":"1.230178130","rc":[{"atb":[[10,0]],"id":52385884},{"atb":[[12,0]],"id":52385903},{"atb":[[10,0]],"id":52385905},{"atb":[[8,0]],"id":52385898}],"con":true,"img":false}]}
{"op":"mcm","clk":"11550089038","pt":1719494346046,"mc":[{"id":"1.230178130","rc":[{"atb":[[9,11],[3.2,45.45],[6.8,0]],"id":52385884},{"atb":[[9,11],[2.86,53.76],[5.3,0]],"id":52385903},{"atb":[[9,11],[2.86,53.76],[5.3,0]],"id":52385905},{"atb":[[2.86,53.76],[5.3,0],[7,12]],"id":52385898}],"con":true,"img":false}]}
{"op":"mcm","clk":"11550089068","pt":1719494346148,"mc":[{"id":"1.230178130","rc":[{"atb":[[3.2,0],[6.8,17.24]],"id":52385884},{"atb":[[2.86,0],[5.3,23.26]],"id":52385903},{"atb":[[2.86,0],[5.3,23.26]],"id":52385905},{"atb":[[2.86,0],[5.3,23.26]],"id":52385898}],"con":true,"img":false}]}
{"op":"mcm","clk":"11550089434","pt":1719494348907,"mc":[{"id":"1.230178130","rc":[{"atb":[[11,0]],"id":52385906}],"con":true,"img":false}]}
{"op":"mcm","clk":"11550089450","pt":1719494349063,"mc":[{"id":"1.230178130","rc":[{"atb":[[10,10],[7.6,0],[3.4,41.67]],"id":52385906}],"con":true,"img":false}]}
{"op":"mcm","clk":"11550090222","pt":1719494356170,"mc":[{"id":"1.230178130","rc":[{"atb":[[3.4,0],[7.6,15.15]],"id":52385906}],"con":true,"img":false}]}
{"op":"mcm","clk":"11550090529","pt":1719494359470,"mc":[{"id":"1.230178130","rc":[{"atb":[[4,2]],"id":52385910},{"atb":[[4,2]],"id":52385911},{"atb":[[4,2]],"id":52385912},{"atb":[[4,2]],"id":52385913},{"atb":[[4,2]],"id":52385906},{"atb":[[4,2]],"id":52385889},{"atb":[[4,2]],"id":52385882},{"atb":[[4,2]],"id":52385883},{"atb":[[4,2]],"id":52385884},{"atb":[[4,2]],"id":52385885},{"atb":[[4,35.33]],"id":52385896},{"atb":[[4,2]],"id":52385897},{"atb":[[4,2]],"id":52385890},{"atb":[[4,2]],"id":52385891},{"atb":[[4,2]],"id":52385892},{"atb":[[4,2]],"id":52385903},{"atb":[[4,2]],"id":52385904},{"atb":[[4,2]],"id":52385905},{"atb":[[4,2]],"id":52385898},{"atb":[[4,2]],"id":52385899}],"con":true,"img":false}]}
{"op":"mcm","clk":"11550097660","pt":1719494422150,"mc":[{"id":"1.230178130","rc":[{"atb":[[10.5,5],[8.2,8],[12.5,2.5],[1.66,151.52],[5.4,0]],"id":52385910},{"atl":[[80,5],[430,0],[420,1.43],[60,2.5],[480,2]],"id":52385910},{"atb":[[18,5],[20,2.5],[10.5,8],[8.2,0]],"id":52385911},{"atl":[[520,0],[590,2],[85,2.5],[110,5],[510,1.18]],"id":52385911},{"atb":[[10.5,10.5],[2.22,81.97],[5.4,0],[9.4,5]],"id":52385912},{"atl":[[46,2.5],[430,0],[420,1.43],[470,2],[60,5]],"id":52385912},{"atb":[[18,5],[20,2.5],[10.5,8],[8.2,0]],"id":52385913},{"atl":[[520,0],[570,2],[75,2.5],[95,5],[510,1.18]],"id":52385913},{"atb":[[10.5,8],[7.6,0],[12,5],[14,2.5],[4.7,25.15]],"id":52385906},{"atl":[[65,2.5],[520,2],[85,5],[510,0],[500,1.2]],"id":52385906},{"atb":[[7.2,8],[5.1,0],[5.5,22.22],[7.6,5],[8.4,2.5]],"id":52385889},{"atl":[[36,2.5],[44,5],[390,2],[410,0],[400,1.5]],"id":52385889},{"atb":[[5.6,0],[9,2.5],[6.2,8],[8.2,5],[5.9,20.41]],"id":52385882},{"atl":[[34,5],[410,2],[430,1.4],[440,0],[28,2.5]],"id":52385882},{"atb":[[5.6,21.74],[5.1,2.5],[6.2,8],[4.7,5]],"id":52385883},{"atl":[[16.5,2.5],[280,2],[18.5,5],[330,0],[320,1.88]],"id":52385883},{"atb":[[8,2.5],[7.2,5],[8.6,13.16],[9.2,8]],"id":52385884},{"atl":[[36,2.5],[44,5],[450,2],[490,0],[480,1.25]],"id":52385884},{"atb":[[9.6,5],[11,2.5],[8.2,8],[6.8,17.24],[6.6,0]],"id":52385885},{"atl":[[40,2.5],[48,5],[470,3.28],[480,0]],"id":52385885},{"atb":[[4.5,28.57],[3.85,5],[4.1,2.5],[6,60]],"id":52385896},{"atl":[[140,2],[210,2.87],[220,0],[13.5,2.5],[15.5,5]],"id":52385896},{"atb":[[5.1,0],[5.8,2.5],[6.2,8],[5.3,23.26],[5.4,5]],"id":52385897},{"atl":[[340,2],[23,2.5],[380,1.58],[390,0],[27,5]],"id":52385897},{"atb":[[8.6,2.5],[9.2,8],[5.3,0],[6.8,17.24],[7.8,5]],"id":52385890},{"atl":[[38,5],[410,3.47],[420,0],[30,2.5]],"id":52385890},{"atb":[[16.5,2.5],[5.6,21.74],[8.6,0],[10.5,8],[14.5,5]],"id":52385891},{"atl":[[530,0],[65,2.5],[520,1.16],[540,2],[85,5]],"id":52385891},{"atb":[[16.5,2.5],[10.5,8],[3.95,33.9],[8.4,0],[14.5,5]],"id":52385892},{"atl":[[530,0],[520,1.16],[560,2],[75,2.5],[95,5]],"id":52385892},{"atb":[[8,2.5],[7.2,5],[9.2,8],[5.3,0],[6.8,17.24]],"id":52385903},{"atl":[[36,2.5],[44,5],[410,3.47],[420,0]],"id":52385903},{"atb":[[5.3,23.26],[11.5,13],[13.5,2.5],[7.8,0]],"id":52385904},{"atl":[[520,0],[75,5],[55,2.5],[480,2],[510,1.18]],"id":52385904},{"atb":[[7.2,2.5],[6.4,5],[9.2,8],[5.8,20.83],[5.3,0]],"id":52385905},{"atl":[[34,5],[400,2],[410,1.47],[420,0],[28,2.5]],"id":52385905},{"atb":[[7.2,8],[5.1,2.5],[5.3,0],[5.5,22.22],[4.7,5]],"id":52385898},{"atl":[[360,2],[23,2.5],[410,1.47],[420,0],[27,5]],"id":52385898},{"atb":[[7.2,8],[5.8,20.83],[7.4,2.5],[5.2,0],[6.6,5]],"id":52385899},{"atl":[[390,2],[410,0],[25,2.5],[400,1.5],[29,5]],"id":52385899}],"con":true,"img":false}]}
{"op":"mcm","clk":"11550097672","pt":1719494422256,"mc":[{"id":"1.230178130","rc":[{"atb":[[6.8,0]],"id":52385884},{"atb":[[4,2]],"id":52385896}],"con":true,"img":false}]}
{"op":"mcm","clk":"11550097685","pt":1719494422361,"mc":[{"id":"1.230178130","rc":[{"atb":[[5.3,0],[7.8,14.71]],"id":52385904},{"atb":[[5.8,0],[7,16]],"id":52385905},{"atl":[[340,2],[400,0]],"id":52385905},{"atb":[[5.8,0],[7,24]],"id":52385899},{"atl":[[340,2],[390,0]],"id":52385899}],"con":true,"img":false}]}
{"op":"mcm","clk":"11550097745","pt":1719494422980,"mc":[{"id":"1.230178130","rc":[{"atb":[[6,0]],"id":52385882}],"con":true,"img":false}]}
{"op":"mcm","clk":"11550097774","pt":1719494423136,"mc":[{"id":"1.230178130","rc":[{"atb":[[8,0]],"id":52385885}],"con":true,"img":false}]}
{"op":"mcm","clk":"11550097791","pt":1719494423344,"mc":[{"id":"1.230178130","rc":[{"atb":[[7,0]],"id":52385889}],"con":true,"img":false}]}
{"op":"mcm","clk":"11550097815","pt":1719494423559,"mc":[{"id":"1.230178130","rc":[{"atb":[[10,0]],"id":52385891}],"con":true,"img":false}]}
{"op":"mcm","clk":"11550097835","pt":1719494423759,"mc":[{"id":"1.230178130","rc":[{"atb":[[10,0]],"id":52385892}],"con":true,"img":false}]}
{"op":"mcm","clk":"11550097862","pt":1719494424071,"mc":[{"id":"1.230178130","rc":[{"atb":[[10,0]],"id":52385906}],"con":true,"img":false}]}
{"op":"mcm","clk":"11550097885","pt":1719494424280,"mc":[{"id":"1.230178130","rc":[{"atb":[[8,0]],"id":52385910}],"con":true,"img":false}]}
{"op":"mcm","clk":"11550097914","pt":1719494424542,"mc":[{"id":"1.230178130","rc":[{"atb":[[10,0]],"id":52385911}],"con":true,"img":false}]}
{"op":"mcm","clk":"11550097936","pt":1719494424748,"mc":[{"id":"1.230178130","rc":[{"atb":[[10,0]],"id":52385913}],"con":true,"img":false}]}
{"op":"mcm","clk":"11550097967","pt":1719494425063,"mc":[{"id":"1.230178130","rc":[{"atb":[[10,0]],"id":52385912},{"atb":[[6,0]],"id":52385883},{"atb":[[9,0]],"id":52385884},{"atb":[[6,0]],"id":52385897},{"atb":[[9,0]],"id":52385890},{"atb":[[9,0]],"id":52385903},{"atb":[[11,0]],"id":52385904},{"atb":[[9,0]],"id":52385905},{"atb":[[7,0]],"id":52385898},{"atb":[[7,12]],"id":52385899}],"con":true,"img":false}]}
{"op":"mcm","clk":"11550097978","pt":1719494425160,"mc":[{"id":"1.230178130","rc":[{"atb":[[12,11]],"id":52385912},{"atb":[[7,12]],"id":52385883},{"atb":[[11,11]],"id":52385884},{"atb":[[8,12]],"id":52385897},{"atb":[[13,12]],"id":52385890},{"atb":[[13,11]],"id":52385903},{"atb":[[18,10]],"id":52385904},{"atb":[[13,11]],"id":52385905},{"atb":[[8,12]],"id":52385898},{"atb":[[9,12]],"id":52385899}],"con":true,"img":false}]}
{"op":"mcm","clk":"11550097990","pt":1719494425267,"mc":[{"id":"1.230178130","rc":[{"atb":[[7.2,26],[6.2,0]],"id":52385883},{"atb":[[6.2,0],[8.2,15]],"id":52385897},{"atb":[[9.2,0],[13,27.94]],"id":52385903},{"atb":[[9.2,0],[13,26]],"id":52385905}],"con":true,"img":false}]}
{"op":"mcm","clk":"11550098007","pt":1719494425471,"mc":[{"id":"1.230178130","rc":[{"atb":[[17,6]],"id":52385906},{"atb":[[9,11]],"id":52385889},{"atb":[[18,5]],"id":52385891}],"con":true,"img":false}]}
{"op":"mcm","clk":"11550098160","pt":1719494426969,"mc":[{"id":"1.230178130","rc":[{"atb":[[11,11.5]],"id":52385885}],"con":true,"img":false}]}
{"op":"mcm","clk":"11550098207","pt":1719494427384,"mc":[{"id":"1.230178130","rc":[{"atb":[[1.66,0]],"id":52385910},{"atb":[[2.22,0]],"id":52385912},{"atb":[[2.9,52.63],[3.95,0]],"id":52385892}],"con":true,"img":false}]}
{"op":"mcm","clk":"11550098315","pt":1719494428479,"mc":[{"id":"1.230178130","rc":[{"atl":[[420,3.43],[480,0]],"id":52385910},{"atl":[[590,0],[510,3.18]],"id":52385911},{"atl":[[420,3.43],[470,0]],"id":52385912},{"atl":[[570,0],[510,3.18]],"id":52385913},{"atb":[[6.2,19.23],[4.7,0]],"id":52385906},{"atb":[[5.5,0],[7,16.67]],"id":52385889},{"atl":[[330,2],[390,0]],"id":52385889},{"atl":[[360,2],[410,0]],"id":52385882},{"atl":[[280,0],[220,2]],"id":52385883},{"atb":[[6.8,0],[7.6,15.15]],"id":52385885},{"atl":[[140,0],[90,2]],"id":52385896},{"atb":[[6.2,19.23],[5.3,0]],"id":52385897},{"atl":[[290,2],[340,0]],"id":52385897},{"atl":[[350,2],[410,1.47]],"id":52385890},{"atb":[[5.6,0],[9.2,12.2]],"id":52385891},{"atl":[[410,1.47]],"id":52385903},{"atb":[[6.4,18.52],[5.5,0]],"id":52385898}],"con":true,"img":false}]}
{"op":"mcm","clk":"11550098330","pt":1719494428579,"mc":[{"id":"1.230178130","rc":[{"atl":[[360,2]],"id":52385903}],"con":true,"img":false}]}
{"op":"mcm","clk":"11550098473","pt":1719494429988,"mc":[{"id":"1.230178130","rc":[{"atb":[[9,13.5]],"id":52385882}],"con":true,"img":false}]}
{"op":"mcm","clk":"11550098490","pt":1719494430184,"mc":[{"id":"1.230178130","rc":[{"atb":[[7.2,16.13]],"id":52385882}],"con":true,"img":false}]}
{"op":"mcm","clk":"11550098501","pt":1719494430286,"mc":[{"id":"1.230178130","rc":[{"atb":[[5.9,0]],"id":52385882}],"con":true,"img":false}]}
{"op":"mcm","clk":"11550098719","pt":1719494432471,"mc":[{"id":"1.230178130","rc":[{"atb":[[6.2,0],[5.4,17.3]],"id":52385906},{"atb":[[9.2,0],[11,10]],"id":52385891},{"atl":[[540,0],[490,2]],"id":52385891},{"atb":[[2.9,0],[4.6,27.78]],"id":52385892},{"atb":[[9,12.5],[7.8,0]],"id":52385904}],"con":true,"img":false}]}
{"op":"mcm","clk":"11550099057","pt":1719494435696,"mc":[{"id":"1.230178130","rc":[{"atb":[[17,16.86]],"id":52385910},{"atl":[[50,12.24]],"id":52385910},{"atb":[[23,16.36]],"id":52385911},{"atl":[[80,7.59]],"id":52385911},{"atb":[[14.5,20]],"id":52385912},{"atl":[[40,15.38]],"id":52385912},{"atb":[[23,16.36]],"id":52385913},{"atl":[[70,8.7]],"id":52385913},{"atb":[[22,15]],"id":52385906},{"atl":[[60,10.17]],"id":52385906},{"atb":[[9.2,15]],"id":52385889},{"atl":[[28,15]],"id":52385889},{"atb":[[9.2,20]],"id":52385882},{"atl":[[23,20]],"id":52385882},{"atb":[[8.6,34]],"id":52385883},{"atl":[[16,34]],"id":52385883},{"atb":[[15,26]],"id":52385884},{"atl":[[34,18.18]],"id":52385884},{"atb":[[15.5,20]],"id":52385885},{"atl":[[38,16.22]],"id":52385885},{"atl":[[11.5,15]],"id":52385896},{"atb":[[10.5,34]],"id":52385897},{"atl":[[16,34]],"id":52385897},{"atb":[[13,27]],"id":52385890},{"atl":[[23,15]],"id":52385890},{"atb":[[24,15]],"id":52385891},{"atl":[[60,10.17]],"id":52385891},{"atb":[[22,15]],"id":52385892},{"atl":[[70,8.7]],"id":52385892},{"atl":[[28,15]],"id":52385903},{"atb":[[23,15]],"id":52385904},{"atl":[[50,12.24]],"id":52385904},{"atl":[[23,15]],"id":52385905},{"atb":[[11,26]],"id":52385898},{"atl":[[22,26]],"id":52385898},{"atb":[[12,15]],"id":52385899},{"atl":[[21,15]],"id":52385899}],"con":true,"img":false}]}
{"op":"mcm","clk":"11550099067","pt":1719494435801,"mc":[{"id":"1.230178130","rc":[{"atb":[[8.2,0]],"id":52385910},{"atl":[[75,2],[420,0]],"id":52385910},{"atl":[[160,2],[510,2]],"id":52385911},{"atb":[[10.5,2.5]],"id":52385912},{"atl":[[70,2],[420,0]],"id":52385912},{"atl":[[150,2]],"id":52385913},{"atb":[[10.5,0]],"id":52385906},{"atl":[[520,0],[95,2],[500,0]],"id":52385906},{"atb":[[7.2,0]],"id":52385889},{"atl":[[34,3.03],[400,0]],"id":52385889},{"atl":[[42,2.44],[360,0]],"id":52385882},{"atb":[[7.2,0]],"id":52385883},{"atl":[[23,4.55],[220,0]],"id":52385883},{"atb":[[9.2,0]],"id":52385884},{"atl":[[480,0],[60,2]],"id":52385884},{"atb":[[8.2,0]],"id":52385885},{"atl":[[70,2],[470,1.28]],"id":52385885},{"atl":[[90,0],[210,0],[14,7.69]],"id":52385896},{"atl":[[290,0],[28,3.7]],"id":52385897},{"atl":[[38,7.7],[350,0],[410,0]],"id":52385890},{"atl":[[520,0]],"id":52385891},{"atl":[[560,0],[120,2]],"id":52385892},{"atl":[[44,7.33],[360,0],[410,0]],"id":52385903},{"atl":[[85,2]],"id":52385904},{"atl":[[38,2.7],[340,0]],"id":52385905},{"atl":[[34,3.03],[360,0],[410,0]],"id":52385898},{"atb":[[7.2,0]],"id":52385899},{"atl":[[40,2.56],[340,0],[400,0]],"id":52385899}],"con":true,"img":false}]}
{"op":"mcm","clk":"11550099076","pt":1719494435906,"mc":[{"id":"1.230178130","rc":[{"atb":[[10.5,0]],"id":52385911},{"atl":[[510,0]],"id":52385911},{"atb":[[10.5,0]],"id":52385913},{"atl":[[510,0]],"id":52385913},{"atl":[[330,0]],"id":52385889},{"atl":[[430,0]],"id":52385882},{"atl":[[450,0]],"id":52385884},{"atb":[[8.2,0]],"id":52385897},{"atl":[[380,0]],"id":52385897},{"atb":[[9.2,0]],"id":52385890},{"atb":[[10.5,0]],"id":52385891},{"atb":[[10.5,0]],"id":52385892},{"atl":[[520,0]],"id":52385892},{"atb":[[11.5,5]],"id":52385904},{"atl":[[480,0],[510,0]],"id":52385904},{"atl":[[410,0]],"id":52385905},{"atb":[[7.2,0]],"id":52385898}],"con":true,"img":false}]}
{"op":"mcm","clk":"11550099087","pt":1719494436003,"mc":[{"id":"1.230178130","rc":[{"atb":[[6.2,0]],"id":52385882},{"atl":[[320,0]],"id":52385883},{"atl":[[470,0]],"id":52385885},{"atb":[[8,0]],"id":52385897}],"con":true,"img":false}]}
{"op":"mcm","clk":"11550099112","pt":1719494436263,"mc":[{"id":"1.230178130","rc":[{"atb":[[9,0]],"id":52385889},{"atb":[[7,0]],"id":52385883},{"atb":[[11,0]],"id":52385884},{"atb":[[13,15]],"id":52385890},{"atb":[[13,15]],"id":52385905},{"atb":[[9,0]],"id":52385899}],"con":true,"img":false}]}
{"op":"mcm","clk":"11550099121","pt":1719494436370,"mc":[{"id":"1.230178130","rc":[{"atb":[[10,11]],"id":52385889},{"atb":[[8,12]],"id":52385883},{"atb":[[13,11]],"id":52385884},{"atb":[[12,12]],"id":52385890},{"atb":[[12,11]],"id":52385905},{"atb":[[8,12]],"id":52385899}],"con":true,"img":false}]}
{"op":"mcm","clk":"11550099130","pt":1719494436472,"mc":[{"id":"1.230178130","rc":[{"atb":[[9.2,0]],"id":52385889}],"con":true,"img":false}]}
{"op":"mcm","clk":"11550099140","pt":1719494436577,"mc":[{"id":"1.230178130","rc":[{"atb":[[10.5,28.06]],"id":52385889},{"atb":[[13,0]],"id":52385890},{"atb":[[13,0]],"id":52385905}],"con":true,"img":false}]}
{"op":"mcm","clk":"11550099155","pt":1719494436683,"mc":[{"id":"1.230178130","rc":[{"atb":[[7.4,15]],"id":52385905}],"con":true,"img":false}]}
{"op":"mcm","clk":"11550099166","pt":1719494436785,"mc":[{"id":"1.230178130","rc":[{"atb":[[8.8,20.4]],"id":52385890}],"con":true,"img":false}]}
{"op":"mcm","clk":"11550099210","pt":1719494437069,"mc":[{"id":"1.230178130","rc":[{"atb":[[11,2.5]],"id":52385885}],"con":true,"img":false}]}
{"op":"mcm","clk":"11550099227","pt":1719494437172,"mc":[{"id":"1.230178130","rc":[{"atb":[[12,9]],"id":52385885}],"con":true,"img":false}]}
{"op":"mcm","clk":"11550099392","pt":1719494438674,"mc":[{"id":"1.230178130","rc":[{"atl":[[90,2],[490,0]],"id":52385891},{"atb":[[5.1,24.39],[4.6,0]],"id":52385892},{"atb":[[12,43]],"id":52385905}],"con":true,"img":false}]}
{"op":"mcm","clk":"11550099409","pt":1719494438869,"mc":[{"id":"1.230178130","rc":[{"atb":[[7.4,0]],"id":52385905}],"con":true,"img":false}]}
{"op":"mcm","clk":"11550099645","pt":1719494440990,"mc":[{"id":"1.230178130","rc":[{"atl":[[75,0],[80,7]],"id":52385910},{"atl":[[34,0],[36,5.36]],"id":52385889}],"con":true,"img":false}]}
{"op":"mcm","clk":"11550099726","pt":1719494441789,"mc":[{"id":"1.230178130","rc":[{"atl":[[50,0]],"id":52385910}],"con":true,"img":false}]}
{"op":"mcm","clk":"11550099741","pt":1719494441879,"mc":[{"id":"1.230178130","rc":[{"atl":[[55,11.11]],"id":52385910}],"con":true,"img":false}]}
{"op":"mcm","clk":"11550099752","pt":1719494441981,"mc":[{"id":"1.230178130","rc":[{"atl":[[80,5],[460,2]],"id":52385910}],"con":true,"img":false}]}
{"op":"mcm","clk":"11550099813","pt":1719494442614,"mc":[{"id":"1.230178130","rc":[{"atb":[[5.4,0],[4.7,17.3]],"id":52385906},{"atb":[[6.2,19.23],[7.6,0]],"id":52385885},{"atl":[[40,0],[46,2.5],[48,0],[60,5]],"id":52385885},{"atb":[[10.5,0]],"id":52385897},{"atb":[[5.1,0],[5.8,20.83]],"id":52385892}],"con":true,"img":false}]}
{"op":"mcm","clk":"11550099827","pt":1719494442723,"mc":[{"id":"1.230178130","rc":[{"atb":[[6.4,48.46],[5.8,23.33]],"id":52385897}],"con":true,"img":false}]}
{"op":"mcm","clk":"11550099837","pt":1719494442825,"mc":[{"id":"1.230178130","rc":[{"atl":[[38,0]],"id":52385885},{"atb":[[6.2,0]],"id":52385897}],"con":true,"img":false}]}
{"op":"mcm","clk":"11550099857","pt":1719494443020,"mc":[{"id":"1.230178130","rc":[{"atl":[[55,11.11]],"id":52385885}],"con":true,"img":false}]}
{"op":"mcm","clk":"11550099885","pt":1719494443279,"mc":[{"id":"1.230178130","rc":[{"atl":[[26,24],[28,0]],"id":52385889}],"con":true,"img":false}]}
{"op":"mcm","clk":"11550099897","pt":1719494443399,"mc":[{"id":"1.230178130","rc":[{"atl":[[36,2.5],[44,7.33]],"id":52385889}],"con":true,"img":false}]}
{"op":"mcm","clk":"11550099927","pt":1719494443694,"mc":[{"id":"1.230178130","rc":[{"atb":[[7,12]],"id":52385897}],"con":true,"img":false}]}
{"op":"mcm","clk":"11550099991","pt":1719494444416,"mc":[{"id":"1.230178130","rc":[{"atl":[[23,0]],"id":52385905}],"con":true,"img":false}]}
{"op":"mcm","clk":"11550100008","pt":1719494444531,"mc":[{"id":"1.230178130","rc":[{"atl":[[24,26.09]],"id":52385905}],"con":true,"img":false}]}
{"op":"mcm","clk":"11550100413","pt":1719494447998,"mc":[{"id":"1.230178130","rc":[{"atb":[[8.6,0],[9.2,12.2]],"id":52385884},{"atl":[[14,0],[14.5,7.41]],"id":52385896},{"atb":[[9,0],[10,11.11]],"id":52385904},{"atl":[[80,2],[85,0]],"id":52385904},{"atl":[[21,0]],"id":52385899}],"con":true,"img":false}]}
{"op":"mcm","clk":"11550100427","pt":1719494448104,"mc":[{"id":"1.230178130","rc":[{"atl":[[80,7],[460,0]],"id":52385910},{"atl":[[24,26.09]],"id":52385899}],"con":true,"img":false}]}
{"op":"mcm","clk":"11550100437","pt":1719494448208,"mc":[{"id":"1.230178130","rc":[{"atb":[[17,0]],"id":52385910},{"atb":[[15.5,0]],"id":52385885},{"atl":[[23,0]],"id":52385890},{"atb":[[22,0]],"id":52385892}],"con":true,"img":false}]}
{"op":"mcm","clk":"11550100451","pt":1719494448312,"mc":[{"id":"1.230178130","rc":[{"atb":[[19.5,24]],"id":52385910},{"atb":[[23,0],[29,20]],"id":52385913},{"atb":[[22,0],[29,21.43]],"id":52385906},{"atb":[[17.5,36.36],[15,0]],"id":52385884},{"atb":[[16,28]],"id":52385885},{"atl":[[23,27.27]],"id":52385890},{"atb":[[23,20]],"id":52385892}],"con":true,"img":false}]}
{"op":"mcm","clk":"11550100467","pt":1719494448419,"mc":[{"id":"1.230178130","rc":[{"atl":[[38,5],[330,2]],"id":52385890}],"con":true,"img":false}]}
{"op":"mcm","clk":"11550100495","pt":1719494448626,"mc":[{"id":"1.230178130","rc":[{"atb":[[16,0]],"id":52385885},{"atl":[[38,7.7],[330,0]],"id":52385890},{"atb":[[23,0]],"id":52385892}],"con":true,"img":false}]}
{"op":"mcm","clk":"11550100511","pt":1719494448688,"mc":[{"id":"1.230178130","rc":[{"atb":[[12.5,28]],"id":52385885},{"atb":[[17,20],[5.8,0],[6.8,17.24]],"id":52385892}],"con":true,"img":false}]}
{"op":"mcm","clk":"11550100523","pt":1719494448786,"mc":[{"id":"1.230178130","rc":[{"atb":[[9,67.48]],"id":52385883},{"atb":[[5.8,2.5],[6,20]],"id":52385897},{"atb":[[5.8,20.83],[6.8,0]],"id":52385892}],"con":true,"img":false}]}
{"op":"mcm","clk":"11550100537","pt":1719494448885,"mc":[{"id":"1.230178130","rc":[{"atb":[[25,20]],"id":52385911},{"atb":[[8.6,0]],"id":52385883},{"atl":[[14,46.15]],"id":52385883},{"atb":[[17.5,28]],"id":52385885},{"atl":[[44,13.95]],"id":52385885},{"atb":[[10,34]],"id":52385897},{"atb":[[12.5,39.4]],"id":52385890},{"atl":[[19.5,32.43]],"id":52385890},{"atb":[[5.8,0],[24,20],[6.8,17.24]],"id":52385892},{"atb":[[25,25]],"id":52385904},{"atl":[[23,27.27]],"id":52385905}],"con":true,"img":false}]}
{"op":"mcm","clk":"11550100563","pt":1719494449095,"mc":[{"id":"1.230178130","rc":[{"atb":[[23,0]],"id":52385911},{"atl":[[16,0]],"id":52385883},{"atb":[[12.5,0]],"id":52385885},{"atl":[[55,0]],"id":52385885},{"atb":[[6.4,0]],"id":52385897},{"atb":[[8.8,0]],"id":52385890},{"atl":[[23,0]],"id":52385890},{"atb":[[17,0]],"id":52385892},{"atb":[[23,0]],"id":52385904},{"atl":[[24,0]],"id":52385905}],"con":true,"img":false}]}
{"op":"mcm","clk":"11550100922","pt":1719494452301,"mc":[{"id":"1.230178130","rc":[{"atl":[[25,25],[26,0]],"id":52385889}],"con":true,"img":false}]}
{"op":"mcm","clk":"11550100934","pt":1719494452407,"mc":[{"id":"1.230178130","rc":[{"atl":[[36,5.36],[44,5]],"id":52385889}],"con":true,"img":false}]}
{"op":"mcm","clk":"11550100987","pt":1719494453035,"mc":[{"id":"1.230178130","rc":[{"atb":[[2.26,79.37]],"id":52385910},{"atb":[[1.09,255.98]],"id":52385912},{"atb":[[4.1,25.95]],"id":52385913},{"atl":[[130,5]],"id":52385913},{"atb":[[3.5,40],[4.7,0]],"id":52385906},{"atb":[[9.2,12.2],[6.2,0]],"id":52385885},{"atb":[[12.5,0]],"id":52385890},{"atb":[[6.8,0],[9.8,11.36]],"id":52385892},{"atb":[[4.8,25.95],[7,0]],"id":52385899},{"atl":[[34,5],[25,0],[28,2.5],[29,0]],"id":52385899}],"con":true,"img":false}]}
{"op":"mcm","clk":"11550100998","pt":1719494453083,"mc":[{"id":"1.230178130","rc":[{"atl":[[75,0]],"id":52385913},{"atb":[[12.5,8.7],[3.5,0]],"id":52385906},{"atb":[[12,51.4]],"id":52385890}],"con":true,"img":false}]}
{"op":"mcm","clk":"11550101016","pt":1719494453292,"mc":[{"id":"1.230178130","rc":[{"atl":[[70,0]],"id":52385913},{"atl":[[22,28.57]],"id":52385882},{"atl":[[24,0]],"id":52385899}],"con":true,"img":false}]}
{"op":"mcm","clk":"11550101029","pt":1719494453410,"mc":[{"id":"1.230178130","rc":[{"atl":[[75,8.11]],"id":52385913},{"atl":[[32,15]],"id":52385899}],"con":true,"img":false}]}
{"op":"mcm","clk":"11550101038","pt":1719494453495,"mc":[{"id":"1.230178130","rc":[{"atl":[[23,0]],"id":52385882}],"con":true,"img":false}]}
{"op":"mcm","clk":"11550101081","pt":1719494454007,"mc":[{"id":"1.230178130","rc":[{"atl":[[75,0]],"id":52385913}],"con":true,"img":false}]}
{"op":"mcm","clk":"11550101089","pt":1719494454110,"mc":[{"id":"1.230178130","rc":[{"atl":[[85,7.14]],"id":52385913}],"con":true,"img":false}]}
{"op":"mcm","clk":"11550101375","pt":1719494456389,"mc":[{"id":"1.230178130","rc":[{"atl":[[24,26.09]],"id":52385889}],"con":true,"img":false}]}
{"op":"mcm","clk":"11550101398","pt":1719494456597,"mc":[{"id":"1.230178130","rc":[{"atl":[[25,0]],"id":52385889}],"con":true,"img":false}]}
{"op":"mcm","clk":"11550101905","pt":1719494461107,"mc":[{"id":"1.230178130","rc":[{"atb":[[20,24]],"id":52385910},{"atb":[[30,20]],"id":52385913},{"atl":[[27,23.08]],"id":52385899}],"con":true,"img":false}]}
{"op":"mcm","clk":"11550101922","pt":1719494461215,"mc":[{"id":"1.230178130","rc":[{"atb":[[19.5,0]],"id":52385910},{"atl":[[32,0]],"id":52385899}],"con":true,"img":false}]}
{"op":"mcm","clk":"11550101934","pt":1719494461312,"mc":[{"id":"1.230178130","rc":[{"atb":[[29,0]],"id":52385913},{"atb":[[18,28]],"id":52385885},{"atb":[[25,20]],"id":52385892}],"con":true,"img":false}]}
{"op":"mcm","clk":"11550101961","pt":1719494461520,"mc":[{"id":"1.230178130","rc":[{"atb":[[1.09,0]],"id":52385912},{"atb":[[3.6,38.46]],"id":52385913},{"atb":[[17.5,0]],"id":52385885},{"atb":[[24,0]],"id":52385892}],"con":true,"img":false}]}
{"op":"mcm","clk":"11550101974","pt":1719494461626,"mc":[{"id":"1.230178130","rc":[{"atb":[[4.1,0]],"id":52385913}],"con":true,"img":false}]}
{"op":"mcm","clk":"11550101994","pt":1719494461836,"mc":[{"id":"1.230178130","rc":[{"atb":[[12.5,25.4]],"id":52385890}],"con":true,"img":false}]}
{"op":"mcm","clk":"11550102001","pt":1719494461891,"mc":[{"id":"1.230178130","rc":[{"atb":[[26,20]],"id":52385911}],"con":true,"img":false}]}
{"op":"mcm","clk":"11550102012","pt":1719494461991,"mc":[{"id":"1.230178130","rc":[{"atb":[[12,12]],"id":52385890}],"con":true,"img":false}]}
{"op":"mcm","clk":"11550102024","pt":1719494462104,"mc":[{"id":"1.230178130","rc":[{"atb":[[25,0]],"id":52385911}],"con":true,"img":false}]}
{"op":"mcm","clk":"11550102782","pt":1719494468825,"mc":[{"id":"1.230178130","rc":[{"atb":[[2.46,68.49],[2.26,0]],"id":52385910},{"atb":[[3.6,0],[3.95,33.9]],"id":52385913}],"con":true,"img":false}]}
{"op":"mcm","clk":"11550103722","pt":1719494477427,"mc":[{"id":"1.230178130","rc":[{"atb":[[2.46,0],[2.26,79.37]],"id":52385910},{"atb":[[3.6,38.46],[3.95,0]],"id":52385913}],"con":true,"img":false}]}
{"op":"mcm","clk":"11550103789","pt":1719494478055,"mc":[{"id":"1.230178130","rc":[{"atb":[[10.5,0],[12.5,0],[13,5],[15,2.5]],"id":52385910},{"atb":[[18,0],[18.5,5],[20,0],[21,2.5]],"id":52385911},{"atb":[[10.5,0],[11,5],[13,2.5],[9.4,0]],"id":52385912},{"atb":[[18,0],[24,2.5]],"id":52385913},{"atb":[[16,2.5],[12,0]],"id":52385906},{"atl":[[36,2.86],[38,5],[44,0],[30,2.5]],"id":52385889},{"atl":[[34,0],[26,2.5],[28,0],[30,5]],"id":52385882},{"atb":[[5.1,0],[5.3,2.5],[4.7,0]],"id":52385883},{"atb":[[8,0],[7.2,0],[8.6,2.5]],"id":52385884},{"atb":[[9.6,0],[10.5,5],[11,0],[12.5,2.5]],"id":52385885},{"atb":[[3.85,0],[4.1,0],[4.2,2.5]],"id":52385896},{"atl":[[20,2.5],[23,0],[24,5],[27,0]],"id":52385897},{"atl":[[38,2.7],[25,2.5],[29,5],[30,0]],"id":52385890},{"atl":[[65,0],[75,5],[85,0],[55,2.5]],"id":52385891},{"atl":[[70,11.2],[75,0],[90,5],[95,0]],"id":52385892},{"atb":[[8,0],[7.2,0],[7.6,5],[8.4,2.5]],"id":52385903},{"atl":[[70,5],[75,0],[50,14.74],[55,0]],"id":52385904},{"atb":[[7.2,0],[6.4,0],[7.6,2.5],[6.8,5],[15,42]],"id":52385905},{"atb":[[5.1,0],[5.3,2.5],[4.7,0]],"id":52385898},{"atb":[[7.4,0],[7.6,5],[6.6,0],[8.4,2.5]],"id":52385899}],"con":true,"img":false}]}
{"op":"mcm","clk":"11550103799","pt":1719494478154,"mc":[{"id":"1.230178130","rc":[{"atb":[[16.5,32]],"id":52385912},{"atl":[[36,0]],"id":52385889},{"atl":[[25,4.17]],"id":52385897},{"atl":[[32,3.23]],"id":52385890},{"atb":[[12,11]],"id":52385905}],"con":true,"img":false}]}
{"op":"mcm","clk":"11550103815","pt":1719494478267,"mc":[{"id":"1.230178130","rc":[{"atb":[[14.5,0]],"id":52385912},{"atl":[[130,0],[90,2.5],[95,0],[120,5]],"id":52385913},{"atl":[[32,3.23]],"id":52385889},{"atl":[[28,0]],"id":52385897},{"atl":[[38,0]],"id":52385890},{"atl":[[55,13.61]],"id":52385891}],"con":true,"img":false}]}
{"op":"mcm","clk":"11550103830","pt":1719494478371,"mc":[{"id":"1.230178130","rc":[{"atl":[[60,0]],"id":52385891}],"con":true,"img":false}]}
{"op":"mcm","clk":"11550104261","pt":1719494482525,"mc":[{"id":"1.230178130","rc":[{"atb":[[2.5,66.67]],"id":52385910},{"atb":[[1.06,255.98]],"id":52385912},{"atb":[[4.1,32.26]],"id":52385913}],"con":true,"img":false}]}
{"op":"mcm","clk":"11550104272","pt":1719494482621,"mc":[{"id":"1.230178130","rc":[{"atb":[[2.26,0]],"id":52385910},{"atb":[[3.6,0]],"id":52385913}],"con":true,"img":false}]}
{"op":"mcm","clk":"11550105191","pt":1719494490736,"mc":[{"id":"1.230178130","rc":[{"atb":[[17,32]],"id":52385912},{"atl":[[65,9.38]],"id":52385892}],"con":true,"img":false}]}
{"op":"mcm","clk":"11550105211","pt":1719494490939,"mc":[{"id":"1.230178130","rc":[{"atb":[[16.5,0]],"id":52385912},{"atl":[[70,2.5]],"id":52385892}],"con":true,"img":false}]}
{"op":"mcm","clk":"11550105876","pt":1719494497544,"mc":[{"id":"1.230178130","rc":[{"atb":[[2.5,0],[2.96,51.02]],"id":52385910},{"atb":[[1.32,227.99]],"id":52385911},{"atb":[[1.27,255.98],[1.06,0]],"id":52385912},{"atb":[[5.1,24.39]],"id":52385913}],"con":true,"img":false}]}
{"op":"mcm","clk":"11550105887","pt":1719494497649,"mc":[{"id":"1.230178130","rc":[{"atb":[[4.1,0]],"id":52385913}],"con":true,"img":false}]}
{"op":"mcm","clk":"11550106311","pt":1719494501953,"mc":[{"id":"1.230178130","rc":[{"atl":[[34,18.18]],"id":52385885}],"con":true,"img":false}]}
{"op":"mcm","clk":"11550106331","pt":1719494502160,"mc":[{"id":"1.230178130","rc":[{"atl":[[44,0]],"id":52385885}],"con":true,"img":false}]}
{"op":"mcm","clk":"11550106372","pt":1719494502680,"mc":[{"id":"1.230178130","rc":[{"atb":[[1.14,227.99],[1.32,0]],"id":52385911}],"con":true,"img":false}]}
{"op":"mcm","clk":"11550106973","pt":1719494508656,"mc":[{"id":"1.230178130","rc":[{"atb":[[2.54,64.94],[2.96,0]],"id":52385910},{"atb":[[1.14,0]],"id":52385911},{"atb":[[1.2,227.99],[1.27,0]],"id":52385912},{"atb":[[4.3,25.95]],"id":52385913}],"con":true,"img":false}]}
{"op":"mcm","clk":"11550106983","pt":1719494508757,"mc":[{"id":"1.230178130","rc":[{"atb":[[5.1,0]],"id":52385913}],"con":true,"img":false}]}
{"op":"mcm","clk":"11550107273","pt":1719494511667,"mc":[{"id":"1.230178130","rc":[{"atl":[[13,2.5],[15,5]],"id":52385896},{"atl":[[28,0]],"id":52385903},{"atb":[[11.5,0],[12.5,5],[13.5,0],[14.5,2.5]],"id":52385904}],"con":true,"img":false}]}
{"op":"mcm","clk":"11550107281","pt":1719494511768,"mc":[{"id":"1.230178130","rc":[{"atl":[[20,31.58]],"id":52385882},{"atl":[[11,44.82],[11.5,0],[13.5,8],[14.5,0],[15.5,0]],"id":52385896},{"atl":[[44,5],[48,2.13],[29,21.43]],"id":52385903},{"atl":[[23,0]],"id":52385905}],"con":true,"img":false}]}
{"op":"mcm","clk":"11550107293","pt":1719494511872,"mc":[{"id":"1.230178130","rc":[{"atl":[[24,26.09]],"id":52385905}],"con":true,"img":false}]}
{"op":"mcm","clk":"11550107305","pt":1719494511970,"mc":[{"id":"1.230178130","rc":[{"atl":[[22,0]],"id":52385882}],"con":true,"img":false}]}
{"op":"mcm","clk":"11550107314","pt":1719494512074,"mc":[{"id":"1.230178130","rc":[{"atl":[[20,0]],"id":52385882},{"atl":[[29,0]],"id":52385903}],"con":true,"img":false}]}
{"op":"mcm","clk":"11550107327","pt":1719494512180,"mc":[{"id":"1.230178130","rc":[{"atl":[[22,28.57]],"id":52385882},{"atl":[[34,18.18]],"id":52385903}],"con":true,"img":false}]}
{"op":"mcm","clk":"11550107377","pt":1719494512699,"mc":[{"id":"1.230178130","rc":[{"atl":[[24,0]],"id":52385905}],"con":true,"img":false}]}
{"op":"mcm","clk":"11550107388","pt":1719494512756,"mc":[{"id":"1.230178130","rc":[{"atl":[[26,15]],"id":52385905}],"con":true,"img":false}]}
{"op":"mcm","clk":"11550107541","pt":1719494513995,"mc":[{"id":"1.230178130","rc":[{"atb":[[1.36,227.99]],"id":52385911},{"atb":[[4.3,0],[3.2,45.45]],"id":52385913},{"atb":[[12.5,0]],"id":52385906},{"atl":[[14,46.15]],"id":52385897},{"atb":[[8,14.29],[17,20],[6.8,0]],"id":52385903},{"atb":[[4.8,0],[5.3,23.26]],"id":52385899},{"atl":[[32,5],[34,0],[21,30],[27,25.58],[28,0]],"id":52385899}],"con":true,"img":false}]}
{"op":"mcm","clk":"11550107553","pt":1719494514047,"mc":[{"id":"1.230178130","rc":[{"atb":[[2.96,51.02]],"id":52385910},{"atb":[[1.2,0],[1.69,144.93]],"id":52385912}],"con":true,"img":false}]}
{"op":"mcm","clk":"11550107561","pt":1719494514151,"mc":[{"id":"1.230178130","rc":[{"atb":[[2.54,0]],"id":52385910},{"atb":[[10,11.11]],"id":52385906}],"con":true,"img":false}]}
{"op":"mcm","clk":"11550107576","pt":1719494514262,"mc":[{"id":"1.230178130","rc":[{"atl":[[16,0]],"id":52385897},{"atb":[[17,0],[13,10.99]],"id":52385903},{"atl":[[27,2.5]],"id":52385899}],"con":true,"img":false}]}
{"op":"mcm","clk":"11550107591","pt":1719494514364,"mc":[{"id":"1.230178130","rc":[{"atb":[[13.5,46.36]],"id":52385903}],"con":true,"img":false}]}
{"op":"mcm","clk":"11550107666","pt":1719494514979,"mc":[{"id":"1.230178130","rc":[{"atb":[[13,0]],"id":52385903}],"con":true,"img":false}]}
{"op":"mcm","clk":"11550107679","pt":1719494515081,"mc":[{"id":"1.230178130","rc":[{"atb":[[14,11]],"id":52385903}],"con":true,"img":false}]}
{"op":"mcm","clk":"11550107700","pt":1719494515288,"mc":[{"id":"1.230178130","rc":[{"atb":[[13.5,0],[14,43]],"id":52385903}],"con":true,"img":false}]}
{"op":"mcm","clk":"11550108086","pt":1719494519165,"mc":[{"id":"1.230178130","rc":[{"atb":[[1.36,0],[1.61,163.93]],"id":52385911},{"atb":[[1.8,125]],"id":52385912},{"atl":[[46,0],[60,0]],"id":52385885},{"atl":[[100,2],[120,0]],"id":52385892},{"atl":[[46,2.22]],"id":52385905}],"con":true,"img":false}]}
{"op":"mcm","clk":"11550108097","pt":1719494519267,"mc":[{"id":"1.230178130","rc":[{"atb":[[1.69,0]],"id":52385912},{"atl":[[44,2.5],[55,5]],"id":52385885},{"atl":[[38,0]],"id":52385905}],"con":true,"img":false}]}
{"op":"mcm","clk":"11550108539","pt":1719494523576,"mc":[{"id":"1.230178130","rc":[{"atl":[[25,25]],"id":52385905}],"con":true,"img":false}]}
{"op":"mcm","clk":"11550108561","pt":1719494523786,"mc":[{"id":"1.230178130","rc":[{"atl":[[26,0]],"id":52385905}],"con":true,"img":false}]}
{"op":"mcm","clk":"11550108761","pt":1719494525616,"mc":[{"id":"1.230178130","rc":[{"atb":[[2.96,0],[3.75,36.36]],"id":52385910},{"atb":[[2.86,53.76],[1.61,0]],"id":52385911},{"atb":[[2,100],[1.8,0]],"id":52385912},{"atb":[[3.2,0],[4.4,29.41]],"id":52385913},{"atb":[[11.5,37]],"id":52385882},{"atl":[[14,0]],"id":52385897}],"con":true,"img":false}]}
{"op":"mcm","clk":"11550108773","pt":1719494525667,"mc":[{"id":"1.230178130","rc":[{"atb":[[9.2,0]],"id":52385882},{"atl":[[19.5,32.43]],"id":52385897}],"con":true,"img":false}]}
{"op":"mcm","clk":"11550109067","pt":1719494528314,"mc":[{"id":"1.230178130","rc":[{"atl":[[50,12.24]],"id":52385910},{"atl":[[13,50]],"id":52385883},{"atl":[[19,33.33]],"id":52385890}],"con":true,"img":false}]}
{"op":"mcm","clk":"11550109082","pt":1719494528371,"mc":[{"id":"1.230178130","rc":[{"atl":[[75,2],[80,5],[55,0]],"id":52385910},{"atl":[[14,0]],"id":52385883},{"atl":[[19.5,0]],"id":52385890}],"con":true,"img":false}]}
{"op":"mcm","clk":"11550109162","pt":1719494528990,"mc":[{"id":"1.230178130","rc":[{"atb":[[7,0]],"id":52385897}],"con":true,"img":false}]}
{"op":"mcm","clk":"11550109175","pt":1719494529093,"mc":[{"id":"1.230178130","rc":[{"atb":[[8,12]],"id":52385897}],"con":true,"img":false}]}
{"op":"mcm","clk":"11550109377","pt":1719494531002,"mc":[{"id":"1.230178130","rc":[{"atb":[[4,35.33]],"id":52385910},{"atb":[[2.24,80.65]],"id":52385911},{"atb":[[2,0],[2.46,68.49]],"id":52385912},{"atb":[[5.2,23.81]],"id":52385913},{"atl":[[75,5],[55,2.5]],"id":52385904}],"con":true,"img":false}]}
{"op":"mcm","clk":"11550109390","pt":1719494531106,"mc":[{"id":"1.230178130","rc":[{"atb":[[3.75,0]],"id":52385910},{"atb":[[2.86,0]],"id":52385911},{"atb":[[4.4,0]],"id":52385913},{"atb":[[16.5,2.5],[14.5,5]],"id":52385906},{"atb":[[8.6,0],[8.8,2.5]],"id":52385884},{"atb":[[9,2.5],[8.2,5],[7.6,0],[8.4,0]],"id":52385903},{"atl":[[70,0],[50,12.24]],"id":52385904},{"atb":[[8.2,2.5],[7.4,5],[7.6,0],[6.8,0]],"id":52385905}],"con":true,"img":false}]}
{"op":"mcm","clk":"11550109401","pt":1719494531208,"mc":[{"id":"1.230178130","rc":[{"atb":[[16,0],[14,0]],"id":52385906},{"atb":[[5.4,2.5]],"id":52385898},{"atl":[[18,35.29]],"id":52385898}],"con":true,"img":false}]}
{"op":"mcm","clk":"11550109415","pt":1719494531314,"mc":[{"id":"1.230178130","rc":[{"atb":[[5.3,0]],"id":52385898},{"atl":[[22,0]],"id":52385898}],"con":true,"img":false}]}
{"op":"mcm","clk":"11550109886","pt":1719494535279,"mc":[{"id":"1.230178130","rc":[{"atb":[[30,0]],"id":52385913}],"con":true,"img":false}]}
{"op":"mcm","clk":"11550109898","pt":1719494535384,"mc":[{"id":"1.230178130","rc":[{"atb":[[29,15]],"id":52385913}],"con":true,"img":false}]}
{"op":"mcm","clk":"11550109914","pt":1719494535491,"mc":[{"id":"1.230178130","rc":[{"atb":[[32,19.35]],"id":52385906},{"atb":[[18.5,34.29]],"id":52385884},{"atl":[[44,13.95]],"id":52385891},{"atl":[[48,12.77]],"id":52385892},{"atb":[[12,54.55]],"id":52385898}],"con":true,"img":false}]}
{"op":"mcm","clk":"11550109937","pt":1719494535700,"mc":[{"id":"1.230178130","rc":[{"atb":[[29,0]],"id":52385906},{"atl":[[65,0]],"id":52385892}],"con":true,"img":false}]}
{"op":"mcm","clk":"11550109953","pt":1719494535797,"mc":[{"id":"1.230178130","rc":[{"atb":[[17.5,0]],"id":52385884},{"atl":[[55,2.5]],"id":52385891},{"atb":[[11,0]],"id":52385898}],"con":true,"img":false}]}
{"op":"mcm","clk":"11550110089","pt":1719494536998,"mc":[{"id":"1.230178130","rc":[{"atb":[[13,37]],"id":52385882}],"con":true,"img":false}]}
{"op":"mcm","clk":"11550110116","pt":1719494537205,"mc":[{"id":"1.230178130","rc":[{"atb":[[11.5,0]],"id":52385882}],"con":true,"img":false}]}
{"op":"mcm","clk":"11550110488","pt":1719494540624,"mc":[{"id":"1.230178130","rc":[{"atl":[[20,31.58]],"id":52385882},{"atl":[[48,0]],"id":52385892}],"con":true,"img":false}]}
{"op":"mcm","clk":"11550110500","pt":1719494540676,"mc":[{"id":"1.230178130","rc":[{"atl":[[50,12.24]],"id":52385892}],"con":true,"img":false}]}
{"op":"mcm","clk":"11550110509","pt":1719494540830,"mc":[{"id":"1.230178130","rc":[{"atl":[[22,0]],"id":52385882}],"con":true,"img":false}]}
{"op":"mcm","clk":"11550110568","pt":1719494541513,"mc":[{"id":"1.230178130","rc":[{"atb":[[4,2],[2.06,94.34]],"id":52385910},{"atb":[[2.24,0],[18.5,0],[19.5,5],[21,0],[23,2.5]],"id":52385911},{"atb":[[11,0],[11.5,5],[2.46,0],[1.3,227.99],[13,0],[13.5,2.5]],"id":52385912},{"atb":[[6.4,18.52],[20,0],[21,5],[24,0],[5.2,0],[25,2.5]],"id":52385913},{"atb":[[10,0],[13.5,8]],"id":52385906},{"atl":[[95,0],[120,2]],"id":52385906},{"atb":[[5.1,24.39],[7,0]],"id":52385889},{"atl":[[42,0],[25,2.5],[26,0],[29,5],[30,0]],"id":52385882},{"atb":[[9,0]],"id":52385883},{"atl":[[16.5,0],[17.5,5],[18.5,0],[15.5,2.5]],"id":52385883},{"atb":[[6,0],[5.2,23.81]],"id":52385897},{"atb":[[3.8,35.71]],"id":52385890},{"atb":[[8.2,13.89]],"id":52385891},{"atb":[[8,14.29],[9.8,0]],"id":52385892},{"atb":[[10,0],[12.5,13.7]],"id":52385904},{"atb":[[4.5,25.95],[5.3,0]],"id":52385899},{"atl":[[21,0]],"id":52385899}],"con":true,"img":false}]}
{"op":"mcm","clk":"11550110578","pt":1719494541608,"mc":[{"id":"1.230178130","rc":[{"atl":[[36,2.86]],"id":52385882},{"atb":[[8,79.48]],"id":52385883},{"atb":[[6.8,0]],"id":52385890},{"atb":[[11,0]],"id":52385891}],"con":true,"img":false}]}
{"op":"mcm","clk":"11550110588","pt":1719494541710,"mc":[{"id":"1.230178130","rc":[{"atb":[[3.45,40.82]],"id":52385910},{"atb":[[8,0]],"id":52385892},{"atb":[[4.5,0],[5.4,22.73]],"id":52385899},{"atl":[[26,24]],"id":52385899}],"con":true,"img":false}]}
{"op":"mcm","clk":"11550110599","pt":1719494541815,"mc":[{"id":"1.230178130","rc":[{"atb":[[2.06,0]],"id":52385910}],"con":true,"img":false}]}
{"op":"mcm","clk":"11550110876","pt":1719494544315,"mc":[{"id":"1.230178130","rc":[{"atb":[[17,2.5],[15,5]],"id":52385892},{"atb":[[8.6,2.5],[7.6,0],[7.8,5],[8.4,0]],"id":52385899}],"con":true,"img":false}]}
{"op":"mcm","clk":"11550110887","pt":1719494544417,"mc":[{"id":"1.230178130","rc":[{"atl":[[40,0]],"id":52385912},{"atb":[[18.5,0]],"id":52385884},{"atb":[[16.5,0],[14.5,0]],"id":52385892},{"atl":[[50,0]],"id":52385892}],"con":true,"img":false}]}
{"op":"mcm","clk":"11550110899","pt":1719494544520,"mc":[{"id":"1.230178130","rc":[{"atl":[[42,14.63]],"id":52385912},{"atb":[[18,32]],"id":52385884},{"atl":[[65,9.38]],"id":52385892}],"con":true,"img":false}]}
{"op":"mcm","clk":"11550110921","pt":1719494544733,"mc":[{"id":"1.230178130","rc":[{"atl":[[42,0]],"id":52385912},{"atb":[[18,0]],"id":52385884}],"con":true,"img":false}]}
{"op":"mcm","clk":"11550110933","pt":1719494544831,"mc":[{"id":"1.230178130","rc":[{"atl":[[44,13.95]],"id":52385912},{"atb":[[18,35.29]],"id":52385884}],"con":true,"img":false}]}
{"op":"mcm","clk":"11550111163","pt":1719494546596,"mc":[{"id":"1.230178130","rc":[{"atb":[[32,19.35]],"id":52385913}],"con":true,"img":false}]}
{"op":"mcm","clk":"11550111177","pt":1719494546704,"mc":[{"id":"1.230178130","rc":[{"atb":[[29,0]],"id":52385913}],"con":true,"img":false}]}
{"op":"mcm","clk":"11550111189","pt":1719494546804,"mc":[{"id":"1.230178130","rc":[{"atl":[[60,10.17]],"id":52385892}],"con":true,"img":false}]}
{"op":"mcm","clk":"11550111202","pt":1719494546907,"mc":[{"id":"1.230178130","rc":[{"atb":[[3.45,0],[2.72,58.14],[13,0],[13.5,5],[15,0],[15.5,2.5]],"id":52385910},{"atb":[[1.3,0]],"id":52385912},{"atb":[[6.4,0],[3.95,33.9]],"id":52385913},{"atl":[[65,0]],"id":52385892},{"atl":[[80,0],[95,2]],"id":52385904}],"con":true,"img":false}]}
{"op":"mcm","clk":"11550111228","pt":1719494547113,"mc":[{"id":"1.230178130","rc":[{"atl":[[27,23.08]],"id":52385884}],"con":true,"img":false}]}
{"op":"mcm","clk":"11550111251","pt":1719494547321,"mc":[{"id":"1.230178130","rc":[{"atl":[[34,0]],"id":52385884}],"con":true,"img":false}]}
{"op":"mcm","clk":"11550111886","pt":1719494552815,"mc":[{"id":"1.230178130","rc":[{"atl":[[23,27.27]],"id":52385899}],"con":true,"img":false}]}
{"op":"mcm","clk":"11550111912","pt":1719494553022,"mc":[{"id":"1.230178130","rc":[{"atl":[[26,0]],"id":52385899}],"con":true,"img":false}]}
{"op":"mcm","clk":"11550112387","pt":1719494557106,"mc":[{"id":"1.230178130","rc":[{"atb":[[2.72,0],[2.86,53.76]],"id":52385910}],"con":true,"img":false}]}
{"op":"mcm","clk":"11550112402","pt":1719494557213,"mc":[{"id":"1.230178130","rc":[{"atb":[[4.5,28.57],[3.95,0]],"id":52385913},{"atl":[[19,33.33]],"id":52385882},{"atb":[[18,0]],"id":52385884}],"con":true,"img":false}]}
{"op":"mcm","clk":"11550112416","pt":1719494557313,"mc":[{"id":"1.230178130","rc":[{"atb":[[17.5,36.36],[8.4,13.51]],"id":52385884}],"con":true,"img":false}]}
{"op":"mcm","clk":"11550112431","pt":1719494557419,"mc":[{"id":"1.230178130","rc":[{"atl":[[20,0]],"id":52385882},{"atb":[[9.2,0]],"id":52385884}],"con":true,"img":false}]}
{"op":"mcm","clk":"11550112753","pt":1719494560212,"mc":[{"id":"1.230178130","rc":[{"atl":[[36,5],[38,0],[29,2.5],[30,0]],"id":52385889}],"con":true,"img":false}]}
{"op":"mcm","clk":"11550112769","pt":1719494560318,"mc":[{"id":"1.230178130","rc":[{"atb":[[17.5,0]],"id":52385884}],"con":true,"img":false}]}
{"op":"mcm","clk":"11550112784","pt":1719494560420,"mc":[{"id":"1.230178130","rc":[{"atb":[[16.5,32]],"id":52385884}],"con":true,"img":false}]}
{"op":"mcm","clk":"11550112969","pt":1719494562028,"mc":[{"id":"1.230178130","rc":[{"atb":[[12,0]],"id":52385885}],"con":true,"img":false}]}
{"op":"mcm","clk":"11550112991","pt":1719494562239,"mc":[{"id":"1.230178130","rc":[{"atl":[[70,0],[85,2],[46,0]],"id":52385912},{"atb":[[3.45,40.82],[4.5,0]],"id":52385913},{"atb":[[13,0]],"id":52385882},{"atb":[[13,0]],"id":52385884},{"atl":[[34,2.5],[36,0],[42,5],[44,0]],"id":52385884},{"atb":[[12,0],[3.8,0],[3.4,41.67]],"id":52385890},{"atb":[[14,32]],"id":52385903},{"atb":[[12,0]],"id":52385905},{"atb":[[5.4,0],[4.7,25.95]],"id":52385899}],"con":true,"img":false}]}
{"op":"mcm","clk":"11550113004","pt":1719494562341,"mc":[{"id":"1.230178130","rc":[{"atl":[[80,5]],"id":52385912},{"atb":[[8.4,20]],"id":52385882},{"atb":[[12,11]],"id":52385884},{"atb":[[13,12]],"id":52385890},{"atb":[[13,11]],"id":52385903},{"atb":[[13,11]],"id":52385905}],"con":true,"img":false}]}
{"op":"mcm","clk":"11550113015","pt":1719494562446,"mc":[{"id":"1.230178130","rc":[{"atb":[[13,46]],"id":52385890},{"atb":[[14,0]],"id":52385903}],"con":true,"img":false}]}
{"op":"mcm","clk":"11550113025","pt":1719494562545,"mc":[{"id":"1.230178130","rc":[{"atl":[[44,0]],"id":52385912}],"con":true,"img":false}]}
{"op":"mcm","clk":"11550113034","pt":1719494562652,"mc":[{"id":"1.230178130","rc":[{"atl":[[46,13.33]],"id":52385912},{"atb":[[12.5,0]],"id":52385890},{"atb":[[13,26]],"id":52385903}],"con":true,"img":false}]}
{"op":"mcm","clk":"11550113255","pt":1719494564623,"mc":[{"id":"1.230178130","rc":[{"atb":[[26,0]],"id":52385911},{"atb":[[25,0]],"id":52385892}],"con":true,"img":false}]}
{"op":"mcm","clk":"11550113270","pt":1719494564725,"mc":[{"id":"1.230178130","rc":[{"atb":[[25,20]],"id":52385911},{"atb":[[24,20]],"id":52385892}],"con":true,"img":false}]}
{"op":"mcm","clk":"11550113292","pt":1719494564934,"mc":[{"id":"1.230178130","rc":[{"atl":[[12,53.48]],"id":52385883},{"atb":[[28,20]],"id":52385891},{"atb":[[29,21.43]],"id":52385904},{"atb":[[16,32]],"id":52385905}],"con":true,"img":false}]}
{"op":"mcm","clk":"11550113315","pt":1719494565142,"mc":[{"id":"1.230178130","rc":[{"atl":[[13,0]],"id":52385883},{"atb":[[24,0]],"id":52385891},{"atb":[[25,0]],"id":52385904},{"atb":[[15,0]],"id":52385905}],"con":true,"img":false}]}
{"op":"mcm","clk":"11550113778","pt":1719494569127,"mc":[{"id":"1.230178130","rc":[{"atb":[[2.86,0]],"id":52385910},{"atb":[[3.45,0],[2.28,78.13]],"id":52385913},{"atb":[[5.1,0],[6.4,18.52]],"id":52385889},{"atl":[[18.5,5.71],[23,0]],"id":52385883},{"atb":[[6,20],[5.2,0]],"id":52385897},{"atb":[[3.4,0],[6.8,17.24]],"id":52385890},{"atb":[[12.5,8.7]],"id":52385891},{"atb":[[3.15,46.51],[4.7,0]],"id":52385899}],"con":true,"img":false}]}
{"op":"mcm","clk":"11550113791","pt":1719494569238,"mc":[{"id":"1.230178130","rc":[{"atb":[[8.2,0]],"id":52385891},{"atb":[[9.4,11.9]],"id":52385892}],"con":true,"img":false}]}
{"op":"mcm","clk":"11550113923","pt":1719494570261,"mc":[{"id":"1.230178130","rc":[{"atl":[[42,2.5],[44,0],[50,5],[55,0]],"id":52385885}],"con":true,"img":false}]}
{"op":"mcm","clk":"11550114274","pt":1719494573028,"mc":[{"id":"1.230178130","rc":[{"atb":[[9.2,37]],"id":52385882},{"atb":[[12,0]],"id":52385884},{"atb":[[13,34]],"id":52385890},{"atb":[[28,0]],"id":52385891},{"atb":[[13,0]],"id":52385905}],"con":true,"img":false}]}
{"op":"mcm","clk":"11550114291","pt":1719494573138,"mc":[{"id":"1.230178130","rc":[{"atb":[[8.4,0]],"id":52385882},{"atb":[[13,11]],"id":52385884},{"atb":[[12,12]],"id":52385890},{"atb":[[27,20]],"id":52385891},{"atb":[[12,11]],"id":52385905}],"con":true,"img":false}]}
{"op":"mcm","clk":"11550114303","pt":1719494573239,"mc":[{"id":"1.230178130","rc":[{"atb":[[13,0]],"id":52385890}],"con":true,"img":false}]}
{"op":"mcm","clk":"11550114317","pt":1719494573341,"mc":[{"id":"1.230178130","rc":[{"atb":[[12.5,34]],"id":52385890},{"atb":[[27,0]],"id":52385891}],"con":true,"img":false}]}
{"op":"mcm","clk":"11550114328","pt":1719494573443,"mc":[{"id":"1.230178130","rc":[{"atb":[[18.5,20]],"id":52385891}],"con":true,"img":false}]}
{"op":"mcm","clk":"11550114396","pt":1719494574121,"mc":[{"id":"1.230178130","rc":[{"atb":[[1.16,200]],"id":52385913},{"atl":[[190,2]],"id":52385913},{"atb":[[2.78,56.18]],"id":52385899},{"atl":[[38,5],[23,0],[30,2.5]],"id":52385899}],"con":true,"img":false}]}
{"op":"mcm","clk":"11550114404","pt":1719494574224,"mc":[{"id":"1.230178130","rc":[{"atb":[[2.28,0]],"id":52385913},{"atl":[[150,0]],"id":52385913},{"atb":[[3.15,0]],"id":52385899},{"atl":[[32,0],[48,2.13],[27,23.08]],"id":52385899}],"con":true,"img":false}]}
{"op":"mcm","clk":"11550114416","pt":1719494574332,"mc":[{"id":"1.230178130","rc":[{"atl":[[40,0]],"id":52385899}],"con":true,"img":false}]}
{"op":"mcm","clk":"11550114425","pt":1719494574434,"mc":[{"id":"1.230178130","rc":[{"atl":[[27,0]],"id":52385899}],"con":true,"img":false}]}
{"op":"mcm","clk":"11550114441","pt":1719494574547,"mc":[{"id":"1.230178130","rc":[{"atl":[[29,21.43]],"id":52385899}],"con":true,"img":false}]}
{"op":"mcm","clk":"11550114547","pt":1719494575332,"mc":[{"id":"1.230178130","rc":[{"atb":[[27,20]],"id":52385911},{"atb":[[26,20]],"id":52385892}],"con":true,"img":false}]}
{"op":"mcm","clk":"11550114577","pt":1719494575544,"mc":[{"id":"1.230178130","rc":[{"atb":[[25,0]],"id":52385911},{"atb":[[27,20]],"id":52385891},{"atb":[[24,0]],"id":52385892}],"con":true,"img":false}]}
{"op":"mcm","clk":"11550114587","pt":1719494575642,"mc":[{"id":"1.230178130","rc":[{"atb":[[18.5,0]],"id":52385891}],"con":true,"img":false}]}
{"op":"mcm","clk":"11550115041","pt":1719494579232,"mc":[{"id":"1.230178130","rc":[{"atb":[[1.16,0],[1.35,200]],"id":52385913},{"atb":[[4.5,0],[6.2,73.14]],"id":52385896},{"atb":[[11,10],[9.4,0]],"id":52385892}],"con":true,"img":false}]}
{"op":"mcm","clk":"11550115057","pt":1719494579337,"mc":[{"id":"1.230178130","rc":[{"atb":[[4,35.33]],"id":52385896}],"con":true,"img":false}]}
{"op":"mcm","clk":"11550115070","pt":1719494579446,"mc":[{"id":"1.230178130","rc":[{"atb":[[6,12]],"id":52385896}],"con":true,"img":false}]}
{"op":"mcm","clk":"11550115316","pt":1719494581269,"mc":[{"id":"1.230178130","rc":[{"atl":[[18,0]],"id":52385898}],"con":true,"img":false}]}
{"op":"mcm","clk":"11550115334","pt":1719494581380,"mc":[{"id":"1.230178130","rc":[{"atl":[[26,24]],"id":52385898}],"con":true,"img":false}]}
{"op":"mcm","clk":"11550115361","pt":1719494581531,"mc":[{"id":"1.230178130","rc":[{"atb":[[8.6,2.5],[8.2,0],[7.4,0],[7.8,5]],"id":52385905},{"atb":[[5.7,2.5],[5.4,0]],"id":52385898}],"con":true,"img":false}]}
{"op":"mcm","clk":"11550115375","pt":1719494581636,"mc":[{"id":"1.230178130","rc":[{"atb":[[18.5,2.5],[14.5,0]],"id":52385906}],"con":true,"img":false}]}
{"op":"mcm","clk":"11550115562","pt":1719494583044,"mc":[{"id":"1.230178130","rc":[{"atb":[[9,2.5]],"id":52385882}],"con":true,"img":false}]}
{"op":"mcm","clk":"11550115595","pt":1719494583252,"mc":[{"id":"1.230178130","rc":[{"atb":[[24,4]],"id":52385910},{"atb":[[40,2]],"id":52385911},{"atb":[[40,2]],"id":52385913}],"con":true,"img":false}]}
{"op":"mcm","clk":"11550115623","pt":1719494583464,"mc":[{"id":"1.230178130","rc":[{"atb":[[24,17]],"id":52385910},{"atb":[[12,0]],"id":52385912},{"atb":[[42,14.63]],"id":52385913},{"atb":[[17,0]],"id":52385906},{"atb":[[10,0]],"id":52385889},{"atb":[[8,67.48]],"id":52385883},{"atb":[[6,0]],"id":52385896},{"atb":[[8,0]],"id":52385897},{"atb":[[18,0]],"id":52385904},{"atb":[[8,0]],"id":52385899}],"con":true,"img":false}]}
{"op":"mcm","clk":"11550115634","pt":1719494583565,"mc":[{"id":"1.230178130","rc":[{"atb":[[20,0]],"id":52385910},{"atb":[[24,11]],"id":52385912},{"atb":[[24,6]],"id":52385906},{"atb":[[9,11]],"id":52385889},{"atb":[[7,12]],"id":52385883},{"atb":[[5,12]],"id":52385896},{"atb":[[7,12]],"id":52385897},{"atb":[[20,10]],"id":52385904},{"atb":[[12,27]],"id":52385899}],"con":true,"img":false}]}
{"op":"mcm","clk":"11550115648","pt":1719494583670,"mc":[{"id":"1.230178130","rc":[{"atb":[[24,37.09]],"id":52385912},{"atb":[[32,0]],"id":52385913},{"atb":[[8,0]],"id":52385883}],"con":true,"img":false}]}
{"op":"mcm","clk":"11550115663","pt":1719494583778,"mc":[{"id":"1.230178130","rc":[{"atb":[[7.8,67.48]],"id":52385883}],"con":true,"img":false}]}
{"op":"mcm","clk":"11550115679","pt":1719494583880,"mc":[{"id":"1.230178130","rc":[{"atb":[[17,0]],"id":52385912}],"con":true,"img":false}]}
{"op":"mcm","clk":"11550115691","pt":1719494583932,"mc":[{"id":"1.230178130","rc":[{"atb":[[12,0]],"id":52385890},{"atb":[[12,0]],"id":52385905}],"con":true,"img":false}]}
{"op":"mcm","clk":"11550115704","pt":1719494584035,"mc":[{"id":"1.230178130","rc":[{"atb":[[11,12]],"id":52385890},{"atb":[[14,11]],"id":52385905}],"con":true,"img":false}]}
{"op":"mcm","clk":"11550115776","pt":1719494584662,"mc":[{"id":"1.230178130","rc":[{"atb":[[1.16,200],[1.35,0]],"id":52385913}],"con":true,"img":false}]}
{"op":"mcm","clk":"11550115786","pt":1719494584759,"mc":[{"id":"1.230178130","rc":[{"atb":[[16.5,3.75]],"id":52385912}],"con":true,"img":false}]}
{"op":"mcm","clk":"11550115818","pt":1719494585073,"mc":[{"id":"1.230178130","rc":[{"atb":[[16.5,0]],"id":52385912}],"con":true,"img":false}]}
{"op":"mcm","clk":"11550115906","pt":1719494585751,"mc":[{"id":"1.230178130","rc":[{"atb":[[42,14.63]],"id":52385911}],"con":true,"img":false}]}
{"op":"mcm","clk":"11550115936","pt":1719494585951,"mc":[{"id":"1.230178130","rc":[{"atb":[[27,0]],"id":52385911}],"con":true,"img":false}]}
{"op":"mcm","clk":"11550116629","pt":1719494591452,"mc":[{"id":"1.230178130","rc":[{"atb":[[19.5,0],[20,5],[23,0],[24,2.5]],"id":52385911},{"atb":[[11.5,0],[12.5,5],[13.5,0],[14.5,2.5]],"id":52385912},{"atb":[[21,0],[23,5],[25,0],[27,2.5]],"id":52385913},{"atl":[[23,2.5],[25,0],[27,5],[29,0]],"id":52385882},{"atl":[[16.5,5],[17.5,0],[14.5,2.5],[15.5,0]],"id":52385883}],"con":true,"img":false}]}
{"op":"mcm","clk":"11550116659","pt":1719494591661,"mc":[{"id":"1.230178130","rc":[{"atl":[[22,28.57]],"id":52385898}],"con":true,"img":false}]}
{"op":"mcm","clk":"11550116686","pt":1719494591868,"mc":[{"id":"1.230178130","rc":[{"atl":[[26,0]],"id":52385898}],"con":true,"img":false}]}
{"op":"mcm","clk":"11550116805","pt":1719494592857,"mc":[{"id":"1.230178130","rc":[{"atb":[[14,7.69]],"id":52385910},{"atl":[[75,2.5],[80,0],[50,0],[60,0],[120,2]],"id":52385910},{"atb":[[21,5]],"id":52385911},{"atl":[[130,2.5],[160,0],[85,0],[110,0],[220,2]],"id":52385911},{"atb":[[12.5,13.7]],"id":52385912},{"atl":[[130,2],[85,0]],"id":52385912},{"atb":[[1.16,0],[25,4.17]],"id":52385913},{"atl":[[140,2.5],[90,0],[180,5],[190,0],[120,0],[250,2]],"id":52385913},{"atb":[[2.82,54.95],[13.5,0]],"id":52385906},{"atl":[[65,0],[85,0],[170,2],[95,2.5],[120,0]],"id":52385906},{"atb":[[11.5,28.46]],"id":52385889},{"atl":[[32,0],[40,2.56]],"id":52385889},{"atb":[[13,15]],"id":52385882},{"atl":[[34,5],[36,0],[19,0],[23,0],[27,0],[55,2],[28,2.5]],"id":52385882},{"atl":[[18.5,0],[23,4.55]],"id":52385883},{"atb":[[9.6,11.63],[8.4,0]],"id":52385884},{"atl":[[34,0],[50,5],[27,0]],"id":52385884},{"atb":[[9.2,0],[1.37,227.99]],"id":52385885},{"atl":[[130,2],[34,0],[70,0],[42,0],[50,0],[60,2.5]],"id":52385885},{"atb":[[6.2,0],[4.2,0]],"id":52385896},{"atb":[[10,0]],"id":52385897},{"atl":[[18,2.5],[24,0],[14,46.15]],"id":52385897},{"atb":[[12.5,0]],"id":52385890},{"atl":[[120,2]],"id":52385891},{"atb":[[11,0],[3.5,40]],"id":52385892},{"atl":[[70,0],[140,2],[85,2.5],[90,0],[100,0]],"id":52385892},{"atl":[[65,2]],"id":52385903},{"atb":[[16,0]],"id":52385905},{"atl":[[40,2.56],[46,0]],"id":52385905},{"atb":[[12,0]],"id":52385898},{"atl":[[34,0],[22,31.07],[23,0],[26,5],[27,0],[28,3.7]],"id":52385898},{"atb":[[2.78,0],[3.3,43.48]],"id":52385899},{"atl":[[36,5],[38,0],[23,20],[29,23.93],[30,0]],"id":52385899}],"con":true,"img":false}]}
{"op":"mcm","clk":"11550116817","pt":1719494592961,"mc":[{"id":"1.230178130","rc":[{"atl":[[220,0]],"id":52385911},{"atl":[[19,8.9]],"id":52385882},{"atl":[[990,0.61]],"id":52385885},{"atb":[[5.6,21.74],[6,0]],"id":52385897},{"atl":[[19.5,0]],"id":52385897},{"atl":[[90,0]],"id":52385891},{"atb":[[3.5,0],[15,12.14]],"id":52385892},{"atl":[[60,0]],"id":52385892},{"atb":[[15.5,20]],"id":52385903},{"atl":[[48,0]],"id":52385903},{"atb":[[14,43]],"id":52385905},{"atb":[[11.5,57.14]],"id":52385898},{"atb":[[7.4,15.62]],"id":52385899},{"atl":[[29,2.5]],"id":52385899}],"con":true,"img":false}]}
{"op":"mcm","clk":"11550116830","pt":1719494593064,"mc":[{"id":"1.230178130","rc":[{"atl":[[160,2],[120,0],[980,0.61]],"id":52385910},{"atl":[[300,2],[80,0]],"id":52385911},{"atl":[[330,2],[85,0],[250,0]],"id":52385913},{"atb":[[2.82,0],[16,6.67]],"id":52385906},{"atl":[[170,0],[230,2],[60,0]],"id":52385906},{"atb":[[10.5,0],[11.5,0]],"id":52385889},{"atl":[[23,27.27]],"id":52385889},{"atb":[[9.2,0]],"id":52385882},{"atl":[[40,15.38],[85,2],[60,0]],"id":52385884},{"atb":[[1.37,0],[10.5,15.53],[23,20]],"id":52385885},{"atl":[[130,0],[530,2]],"id":52385885},{"atb":[[3.2,5],[5,52],[3.4,2.5]],"id":52385896},{"atb":[[7,76]],"id":52385897},{"atb":[[11,46]],"id":52385890},{"atl":[[190,2]],"id":52385892},{"atl":[[32,19.35]],"id":52385903},{"atl":[[40,0],[55,2]],"id":52385905},{"atl":[[36,2.86],[28,0]],"id":52385898},{"atb":[[3.3,0]],"id":52385899},{"atl":[[23,0]],"id":52385899}],"con":true,"img":false}]}
{"op":"mcm","clk":"11550116846","pt":1719494593170,"mc":[{"id":"1.230178130","rc":[{"atb":[[11,10],[14,0]],"id":52385910},{"atl":[[290,2.08]],"id":52385911},{"atb":[[12.5,5]],"id":52385912},{"atl":[[46,0]],"id":52385912},{"atl":[[130,2.5],[140,0],[290,2],[170,8.55],[180,0]],"id":52385913},{"atl":[[90,2.5],[95,0],[120,5]],"id":52385906},{"atb":[[10,27]],"id":52385889},{"atl":[[19,0]],"id":52385882},{"atb":[[5.6,0],[4.8,26.32]],"id":52385883},{"atl":[[18.5,5],[12,0],[14.5,0]],"id":52385883},{"atl":[[75,2]],"id":52385884},{"atb":[[4,2],[3.65,37.74]],"id":52385896},{"atb":[[5.6,0],[5.1,24.39]],"id":52385897},{"atl":[[140,0],[80,7.59]],"id":52385892},{"atb":[[13,11],[15.5,0]],"id":52385903},{"atl":[[65,0],[55,2]],"id":52385903},{"atb":[[12.5,5],[29,0]],"id":52385904},{"atl":[[65,5],[75,0],[48,2.5],[55,0]],"id":52385904},{"atb":[[14,11]],"id":52385905},{"atb":[[11.5,0]],"id":52385898},{"atl":[[32,3.23]],"id":52385898},{"atb":[[8,14.29],[7.4,0]],"id":52385899},{"atl":[[65,2],[48,0]],"id":52385899}],"con":true,"img":false}]}
{"op":"mcm","clk":"11550116857","pt":1719494593275,"mc":[{"id":"1.230178130","rc":[{"atb":[[17,6.25],[21,0]],"id":52385911},{"atb":[[10.5,10.53]],"id":52385912},{"atb":[[17.5,6.06],[25,0]],"id":52385913},{"atl":[[310,2],[330,0]],"id":52385913},{"atb":[[16,0],[42,10],[11.5,9.52]],"id":52385906},{"atl":[[65,9.38],[170,2],[230,0]],"id":52385906},{"atb":[[6.4,0],[5.5,22.22]],"id":52385889},{"atl":[[24,0]],"id":52385889},{"atb":[[7.2,0],[6,20]],"id":52385882},{"atl":[[16,40]],"id":52385883},{"atb":[[9.6,0],[7.4,15.62]],"id":52385884},{"atl":[[85,0]],"id":52385884},{"atb":[[18,0],[10.5,5],[13,8.33]],"id":52385885},{"atb":[[6.8,0],[5.4,22.73]],"id":52385890},{"atb":[[9.2,12.2],[12.5,0]],"id":52385891},{"atb":[[38,10],[12,9.09],[15,5]],"id":52385892},{"atb":[[8,0],[5.9,20.41],[15,42.86]],"id":52385903},{"atl":[[34,0]],"id":52385903},{"atb":[[20,35],[8.4,13.51]],"id":52385904},{"atl":[[48,15.27]],"id":52385904},{"atb":[[5.5,21],[7,0]],"id":52385905},{"atl":[[38,2.7],[55,0]],"id":52385905},{"atb":[[9.6,61.04],[6.4,0],[5.2,23.81]],"id":52385898},{"atl":[[36,0]],"id":52385898},{"atb":[[17.5,15]],"id":52385899},{"atl":[[30,15]],"id":52385899}],"con":true,"img":false}]}
{"op":"mcm","clk":"11550116868","pt":1719494593379,"mc":[{"id":"1.230178130","rc":[{"atl":[[580,2],[160,0]],"id":52385910},{"atl":[[55,11.11]],"id":52385912},{"atl":[[290,0]],"id":52385913},{"atl":[[27,15]],"id":52385882},{"atb":[[8,0],[6.4,18.52]],"id":52385899}],"con":true,"img":false}]}
{"op":"mcm","clk":"11550116881","pt":1719494593485,"mc":[{"id":"1.230178130","rc":[{"atb":[[32,0]],"id":52385906},{"atl":[[65,0]],"id":52385906},{"atb":[[13,0]],"id":52385885},{"atl":[[11,0]],"id":52385896},{"atl":[[44,0]],"id":52385891},{"atb":[[26,0]],"id":52385892},{"atb":[[15,0]],"id":52385903},{"atl":[[50,0]],"id":52385904},{"atb":[[12,12]],"id":52385899}],"con":true,"img":false}]}
{"op":"mcm","clk":"11550116894","pt":1719494593589,"mc":[{"id":"1.230178130","rc":[{"atl":[[85,7.14]],"id":52385906},{"atb":[[10.5,15.53]],"id":52385885},{"atl":[[11.5,57.14],[13.5,0],[15,12.14]],"id":52385896},{"atl":[[46,13.33]],"id":52385891},{"atb":[[13,38]],"id":52385903}],"con":true,"img":false}]}
{"op":"mcm","clk":"11550116903","pt":1719494593694,"mc":[{"id":"1.230178130","rc":[{"atb":[[48,10]],"id":52385913},{"atl":[[13.5,5],[15,5]],"id":52385896}],"con":true,"img":false}]}
{"op":"mcm","clk":"11550116917","pt":1719494593793,"mc":[{"id":"1.230178130","rc":[{"atb":[[42,0]],"id":52385913},{"atl":[[11.5,0],[15,12.14]],"id":52385896},{"atl":[[46,0]],"id":52385891}],"con":true,"img":false}]}
{"op":"mcm","clk":"11550116924","pt":1719494593847,"mc":[{"id":"1.230178130","rc":[{"atl":[[12.5,52.17],[13.5,0]],"id":52385896},{"atl":[[50,12.24]],"id":52385891}],"con":true,"img":false}]}
{"op":"mcm","clk":"11550116936","pt":1719494593946,"mc":[{"id":"1.230178130","rc":[{"atb":[[27,20]],"id":52385912},{"atl":[[13.5,5]],"id":52385896},{"atb":[[21,9.38]],"id":52385891}],"con":true,"img":false}]}
{"op":"mcm","clk":"11550116947","pt":1719494594052,"mc":[{"id":"1.230178130","rc":[{"atb":[[36,10]],"id":52385910},{"atb":[[8.4,34]],"id":52385883},{"atl":[[15,5]],"id":52385896},{"atl":[[18,20]],"id":52385890},{"atb":[[8.6,0],[9.2,2.5],[7.8,0],[8.4,5]],"id":52385899}],"con":true,"img":false}]}
{"op":"mcm","clk":"11550116960","pt":1719494594156,"mc":[{"id":"1.230178130","rc":[{"atb":[[24,11]],"id":52385912},{"atb":[[21,0]],"id":52385891}],"con":true,"img":false}]}
{"op":"mcm","clk":"11550116973","pt":1719494594266,"mc":[{"id":"1.230178130","rc":[{"atb":[[24,4]],"id":52385910},{"atb":[[7.8,0]],"id":52385883},{"atl":[[19,0]],"id":52385890}],"con":true,"img":false}]}
{"op":"mcm","clk":"11550117160","pt":1719494595970,"mc":[{"id":"1.230178130","rc":[{"atb":[[50,9.16]],"id":52385911}],"con":true,"img":false}]}
{"op":"mcm","clk":"11550117168","pt":1719494596072,"mc":[{"id":"1.230178130","rc":[{"atb":[[42,0]],"id":52385911}],"con":true,"img":false}]}
{"op":"mcm","clk":"11550117218","pt":1719494596595,"mc":[{"id":"1.230178130","rc":[{"atb":[[18,5],[20,2.5],[13.5,0],[15.5,0]],"id":52385910}],"con":true,"img":false}]}
{"op":"mcm","clk":"11550117280","pt":1719494597059,"mc":[{"id":"1.230178130","rc":[{"atb":[[36,0]],"id":52385910},{"atl":[[70,2.5],[75,0],[90,5]],"id":52385910},{"atb":[[17,0],[12.5,8.7]],"id":52385911},{"atl":[[130,0],[140,5],[100,2.5]],"id":52385911},{"atl":[[130,0],[110,2]],"id":52385912},{"atb":[[17.5,0],[12.5,8.7]],"id":52385913},{"atb":[[42,0]],"id":52385906},{"atl":[[34,3.03],[40,0]],"id":52385889},{"atb":[[13,0]],"id":52385882},{"atl":[[42,2.44],[55,0]],"id":52385882},{"atb":[[8.4,0]],"id":52385883},{"atb":[[8,14.29],[10.5,5]],"id":52385885},{"atb":[[3.25,40.24],[3.65,0]],"id":52385896},{"atl":[[13.5,0],[14,7.69]],"id":52385896},{"atb":[[5.1,0],[3.55,39.22]],"id":52385897},{"atl":[[14,0]],"id":52385897},{"atb":[[4.4,29.41],[5.4,0]],"id":52385890},{"atb":[[9.2,0],[6.8,17.24]],"id":52385891},{"atb":[[38,0]],"id":52385892},{"atl":[[70,2.5],[85,0],[90,5]],"id":52385892},{"atb":[[3.3,43.48],[5.9,0]],"id":52385903},{"atb":[[2.56,64.1],[8.4,0]],"id":52385904},{"atl":[[65,0],[75,5],[48,12.77],[55,2.5]],"id":52385904},{"atb":[[5.5,0],[14,31]],"id":52385905},{"atl":[[38,0],[60,2]],"id":52385905},{"atb":[[5.2,0],[2.64,60.98]],"id":52385898},{"atl":[[32,0],[42,2.44]],"id":52385898},{"atb":[[17.5,0]],"id":52385899}],"con":true,"img":false}]}
{"op":"mcm","clk":"11550117293","pt":1719494597164,"mc":[{"id":"1.230178130","rc":[{"atb":[[24,14]],"id":52385910},{"atb":[[50,0]],"id":52385911},{"atl":[[300,0],[200,2]],"id":52385911},{"atb":[[11.5,0],[25,22],[14,7.69]],"id":52385906},{"atl":[[130,2],[170,0]],"id":52385906},{"atb":[[6.2,19.23],[5.5,0]],"id":52385889},{"atb":[[6,0],[12.5,20],[6.6,17.86]],"id":52385882},{"atb":[[4.8,0],[5.3,25.76],[7,46]],"id":52385883},{"atl":[[18.5,10.71],[23,0]],"id":52385883},{"atl":[[75,0],[55,2]],"id":52385884},{"atl":[[530,0],[460,2]],"id":52385885},{"atl":[[17.5,15]],"id":52385897},{"atl":[[90,2],[120,0]],"id":52385891},{"atb":[[17.5,15],[12,0],[13.5,8]],"id":52385892},{"atl":[[130,2],[190,0]],"id":52385892},{"atl":[[48,2.13],[55,0]],"id":52385903},{"atb":[[2.36,73.53]],"id":52385905},{"atb":[[12.5,34]],"id":52385899},{"atl":[[65,0],[48,2.13]],"id":52385899}],"con":true,"img":false}]}
{"op":"mcm","clk":"11550117306","pt":1719494597270,"mc":[{"id":"1.230178130","rc":[{"atb":[[48,9]],"id":52385911},{"atl":[[48,0]],"id":52385904}],"con":true,"img":false}]}
{"op":"mcm","clk":"11550117320","pt":1719494597373,"mc":[{"id":"1.230178130","rc":[{"atb":[[12.5,0]],"id":52385882},{"atl":[[50,12.24]],"id":52385904}],"con":true,"img":false}]}
{"op":"mcm","clk":"11550117334","pt":1719494597478,"mc":[{"id":"1.230178130","rc":[{"atb":[[12,20]],"id":52385882}],"con":true,"img":false}]}
{"op":"mcm","clk":"11550117394","pt":1719494597997,"mc":[{"id":"1.230178130","rc":[{"atb":[[20,5]],"id":52385892}],"con":true,"img":false}]}
{"op":"mcm","clk":"11550117444","pt":1719494598462,"mc":[{"id":"1.230178130","rc":[{"atl":[[580,0],[500,2]],"id":52385910},{"atb":[[7.6,15.15]],"id":52385899}],"con":true,"img":false}]}
{"op":"mcm","clk":"11550117460","pt":1719494598570,"mc":[{"id":"1.230178130","rc":[{"atb":[[6.4,0]],"id":52385899}],"con":true,"img":false}]}
{"op":"mcm","clk":"11550117884","pt":1719494602213,"mc":[{"id":"1.230178130","rc":[{"atb":[[16,6.67],[12.5,0]],"id":52385911},{"atl":[[90,2]],"id":52385912},{"atb":[[16.5,6.45],[12.5,0]],"id":52385913},{"atl":[[36,2.86],[42,0]],"id":52385882},{"atb":[[8,0],[10,11.11]],"id":52385885},{"atb":[[3.25,0],[3.75,36.36]],"id":52385896},{"atb":[[4.5,28.57],[3.55,0]],"id":52385897},{"atb":[[4.4,0],[5.7,21.28]],"id":52385890},{"atb":[[9.6,11.63],[6.8,0]],"id":52385891},{"atb":[[4.8,26.32],[3.3,0]],"id":52385903},{"atb":[[2.56,0],[5.4,22.73]],"id":52385904},{"atl":[[46,2.22],[60,0]],"id":52385905},{"atb":[[3.7,37.04],[2.64,0]],"id":52385898},{"atl":[[22,28.57],[25,2.5],[26,0],[29,5]],"id":52385898}],"con":true,"img":false}]}
{"op":"mcm","clk":"11550117899","pt":1719494602405,"mc":[{"id":"1.230178130","rc":[{"atl":[[110,0]],"id":52385912},{"atl":[[36,2.86],[42,0]],"id":52385898}],"con":true,"img":false}]}
{"op":"mcm","clk":"11550117964","pt":1719494602976,"mc":[{"id":"1.230178130","rc":[{"atb":[[11,28.06]],"id":52385889},{"atl":[[24,26.09]],"id":52385899}],"con":true,"img":false}]}
{"op":"mcm","clk":"11550117977","pt":1719494603077,"mc":[{"id":"1.230178130","rc":[{"atl":[[19,20]],"id":52385882},{"atl":[[55,10]],"id":52385885},{"atb":[[17,20]],"id":52385903}],"con":true,"img":false}]}
{"op":"mcm","clk":"11550117991","pt":1719494603183,"mc":[{"id":"1.230178130","rc":[{"atl":[[65,9.38]],"id":52385910},{"atb":[[10,0]],"id":52385889},{"atl":[[26,24]],"id":52385884},{"atl":[[80,2],[460,0]],"id":52385885},{"atb":[[5.6,88.1]],"id":52385896},{"atb":[[9.6,15]],"id":52385897},{"atb":[[11.5,20]],"id":52385890},{"atl":[[30,0]],"id":52385899}],"con":true,"img":false}]}
{"op":"mcm","clk":"11550118005","pt":1719494603293,"mc":[{"id":"1.230178130","rc":[{"atl":[[100,2],[500,0]],"id":52385910},{"atl":[[95,6.38]],"id":52385911},{"atl":[[120,5.04]],"id":52385913},{"atl":[[27,0]],"id":52385882},{"atl":[[990,0]],"id":52385885},{"atl":[[65,9.38]],"id":52385892},{"atb":[[13,11]],"id":52385903}],"con":true,"img":false}]}
{"op":"mcm","clk":"11550118021","pt":1719494603391,"mc":[{"id":"1.230178130","rc":[{"atl":[[980,0]],"id":52385910},{"atb":[[34,18.18]],"id":52385906},{"atl":[[12,54.55]],"id":52385883},{"atl":[[40,0]],"id":52385884},{"atb":[[5,12]],"id":52385896},{"atb":[[7,12]],"id":52385897},{"atb":[[11,12]],"id":52385890},{"atb":[[21,20]],"id":52385892},{"atb":[[22,20]],"id":52385904}],"con":true,"img":false}]}
{"op":"mcm","clk":"11550118036","pt":1719494603494,"mc":[{"id":"1.230178130","rc":[{"atl":[[290,0]],"id":52385911},{"atl":[[310,0],[170,5],[210,2]],"id":52385913},{"atl":[[80,0]],"id":52385892}],"con":true,"img":false}]}
{"op":"mcm","clk":"11550118042","pt":1719494603599,"mc":[{"id":"1.230178130","rc":[{"atb":[[25,0]],"id":52385906}],"con":true,"img":false}]}
{"op":"mcm","clk":"11550118056","pt":1719494603701,"mc":[{"id":"1.230178130","rc":[{"atl":[[16,0]],"id":52385883},{"atl":[[10.5,39.38]],"id":52385896},{"atl":[[42,14.63]],"id":52385891},{"atb":[[17.5,0]],"id":52385892},{"atb":[[20,10]],"id":52385904}],"con":true,"img":false}]}
{"op":"mcm","clk":"11550118069","pt":1719494603803,"mc":[{"id":"1.230178130","rc":[{"atl":[[12.5,0],[13,10.83],[14,0]],"id":52385896},{"atl":[[50,0]],"id":52385891}],"con":true,"img":false}]}
{"op":"mcm","clk":"11550118097","pt":1719494604010,"mc":[{"id":"1.230178130","rc":[{"atb":[[13,0]],"id":52385903}],"con":true,"img":false}]}
{"op":"mcm","clk":"11550118112","pt":1719494604063,"mc":[{"id":"1.230178130","rc":[{"atb":[[15,11]],"id":52385903}],"con":true,"img":false}]}
{"op":"mcm","clk":"11550118461","pt":1719494607089,"mc":[{"id":"1.230178130","rc":[{"atb":[[13,0]],"id":52385884},{"atb":[[5,0]],"id":52385896},{"atb":[[12,0]],"id":52385899}],"con":true,"img":false}]}
{"op":"mcm","clk":"11550118473","pt":1719494607187,"mc":[{"id":"1.230178130","rc":[{"atb":[[12,11]],"id":52385884},{"atb":[[6,12]],"id":52385896},{"atl":[[42,14.63]],"id":52385904},{"atb":[[17.5,20],[12.5,0],[13,12]],"id":52385899}],"con":true,"img":false}]}
{"op":"mcm","clk":"11550118484","pt":1719494607290,"mc":[{"id":"1.230178130","rc":[{"atl":[[50,0]],"id":52385904}],"con":true,"img":false}]}
{"op":"mcm","clk":"11550118583","pt":1719494608276,"mc":[{"id":"1.230178130","rc":[{"atl":[[13,2.5],[15,12.14]],"id":52385896}],"con":true,"img":false}]}
{"op":"mcm","clk":"11550118684","pt":1719494609312,"mc":[{"id":"1.230178130","rc":[{"atl":[[32,5],[36,0],[27,2.5],[29,0]],"id":52385889}],"con":true,"img":false}]}
{"op":"mcm","clk":"11550118696","pt":1719494609416,"mc":[{"id":"1.230178130","rc":[{"atl":[[34,0],[29,3.57]],"id":52385889}],"con":true,"img":false}]}
{"op":"mcm","clk":"11550118890","pt":1719494611090,"mc":[{"id":"1.230178130","rc":[{"atl":[[34,2.5],[50,0]],"id":52385884}],"con":true,"img":false}]}
{"op":"mcm","clk":"11550119123","pt":1719494613102,"mc":[{"id":"1.230178130","rc":[{"atb":[[6.4,48.28]],"id":52385896}],"con":true,"img":false}]}
{"op":"mcm","clk":"11550119142","pt":1719494613310,"mc":[{"id":"1.230178130","rc":[{"atb":[[5.6,0]],"id":52385896}],"con":true,"img":false}]}
{"op":"mcm","clk":"11550119745","pt":1719494618799,"mc":[{"id":"1.230178130","rc":[{"atl":[[42,2.5],[50,5],[60,0]],"id":52385885}],"con":true,"img":false}]}
{"op":"mcm","clk":"11550119759","pt":1719494618898,"mc":[{"id":"1.230178130","rc":[{"atl":[[50,17.24]],"id":52385885}],"con":true,"img":false}]}
{"op":"mcm","clk":"11550119783","pt":1719494619105,"mc":[{"id":"1.230178130","rc":[{"atb":[[12,0]],"id":52385884},{"atl":[[55,0]],"id":52385885}],"con":true,"img":false}]}
{"op":"mcm","clk":"11550119798","pt":1719494619214,"mc":[{"id":"1.230178130","rc":[{"atb":[[13,11]],"id":52385884}],"con":true,"img":false}]}
{"op":"mcm","clk":"11550120286","pt":1719494623726,"mc":[{"id":"1.230178130","rc":[{"atb":[[6.4,0]],"id":52385896}],"con":true,"img":false}]}
{"op":"mcm","clk":"11550120316","pt":1719494623936,"mc":[{"id":"1.230178130","rc":[{"atb":[[4.1,29]],"id":52385896}],"con":true,"img":false}]}
{"op":"mcm","clk":"11550120737","pt":1719494627799,"mc":[{"id":"1.230178130","rc":[{"atl":[[24,2.5],[25,0],[28,5],[29,0]],"id":52385890},{"atb":[[12.5,0],[13.5,5],[14.5,0],[15.5,2.5]],"id":52385904}],"con":true,"img":false}]}
{"op":"mcm","clk":"11550120830","pt":1719494628414,"mc":[{"id":"1.230178130","rc":[{"atl":[[40,15]],"id":52385885}],"con":true,"img":false}]}
{"op":"mcm","clk":"11550120854","pt":1719494628616,"mc":[{"id":"1.230178130","rc":[{"atl":[[50,5]],"id":52385885}],"con":true,"img":false}]}
{"op":"mcm","clk":"11550120864","pt":1719494628724,"mc":[{"id":"1.230178130","rc":[{"atb":[[8.4,13.51]],"id":52385884},{"atb":[[1.95,105.26]],"id":52385905},{"atb":[[17.5,0]],"id":52385899}],"con":true,"img":false}]}
{"op":"mcm","clk":"11550120878","pt":1719494628830,"mc":[{"id":"1.230178130","rc":[{"atb":[[7.4,0]],"id":52385884},{"atb":[[4.8,20],[5.4,0]],"id":52385904},{"atl":[[42,0]],"id":52385904},{"atb":[[2.36,0]],"id":52385905},{"atb":[[9.4,15]],"id":52385899}],"con":true,"img":false}]}
{"op":"mcm","clk":"11550120886","pt":1719494628926,"mc":[{"id":"1.230178130","rc":[{"atl":[[70,8.7]],"id":52385904}],"con":true,"img":false}]}
{"op":"mcm","clk":"11550120947","pt":1719494629508,"mc":[{"id":"1.230178130","rc":[{"atb":[[8,5],[8.6,0],[8.8,2.5],[7.8,0]],"id":52385905},{"atb":[[5.5,5],[5.7,0],[5.9,2.5]],"id":52385898}],"con":true,"img":false}]}
{"op":"mcm","clk":"11550121002","pt":1719494630133,"mc":[{"id":"1.230178130","rc":[{"atb":[[13,0]],"id":52385884}],"con":true,"img":false}]}
{"op":"mcm","clk":"11550121012","pt":1719494630230,"mc":[{"id":"1.230178130","rc":[{"atb":[[12,11]],"id":52385884}],"con":true,"img":false}]}
{"op":"mcm","clk":"11550121344","pt":1719494633302,"mc":[{"id":"1.230178130","rc":[{"atb":[[6,60.28]],"id":52385896}],"con":true,"img":false}]}
{"op":"mcm","clk":"11550121362","pt":1719494633512,"mc":[{"id":"1.230178130","rc":[{"atb":[[4.1,0]],"id":52385896}],"con":true,"img":false}]}
{"op":"mcm","clk":"11550121403","pt":1719494633927,"mc":[{"id":"1.230178130","rc":[{"atb":[[1.84,119.05],[1.95,0]],"id":52385905},{"atl":[[42,5],[28,0]],"id":52385905},{"atb":[[3.7,0],[3.4,41.67]],"id":52385898}],"con":true,"img":false}]}
{"op":"mcm","clk":"11550121819","pt":1719494638234,"mc":[{"id":"1.230178130","rc":[{"atb":[[13.5,34]],"id":52385899}],"con":true,"img":false}]}
{"op":"mcm","clk":"11550121825","pt":1719494638333,"mc":[{"id":"1.230178130","rc":[{"atl":[[50,12.24]],"id":52385904}],"con":true,"img":false}]}
{"op":"mcm","clk":"11550121833","pt":1719494638435,"mc":[{"id":"1.230178130","rc":[{"atb":[[9.4,0]],"id":52385899}],"con":true,"img":false}]}
{"op":"mcm","clk":"11550121852","pt":1719494638539,"mc":[{"id":"1.230178130","rc":[{"atl":[[70,0]],"id":52385904}],"con":true,"img":false}]}
{"op":"mcm","clk":"11550121896","pt":1719494638953,"mc":[{"id":"1.230178130","rc":[{"atl":[[34,0],[23,2.5],[27,5],[28,0]],"id":52385882},{"atl":[[18.5,5.71],[14.5,2.5]],"id":52385883}],"con":true,"img":false}]}
{"op":"mcm","clk":"11550122042","pt":1719494640411,"mc":[{"id":"1.230178130","rc":[{"atb":[[4,4.5],[3.8,5]],"id":52385896}],"con":true,"img":false}]}
{"op":"mcm","clk":"11550122053","pt":1719494640515,"mc":[{"id":"1.230178130","rc":[{"atl":[[130,0],[150,5],[170,0],[110,2.5]],"id":52385913},{"atb":[[3.2,0],[3.4,0]],"id":52385896}],"con":true,"img":false}]}
{"op":"mcm","clk":"11550122066","pt":1719494640619,"mc":[{"id":"1.230178130","rc":[{"atl":[[110,8]],"id":52385913}],"con":true,"img":false}]}
{"op":"mcm","clk":"11550122091","pt":1719494640829,"mc":[{"id":"1.230178130","rc":[{"atl":[[120,0]],"id":52385913}],"con":true,"img":false}]}
{"op":"mcm","clk":"11550122114","pt":1719494641033,"mc":[{"id":"1.230178130","rc":[{"atb":[[12,0]],"id":52385884}],"con":true,"img":false}]}
{"op":"mcm","clk":"11550122126","pt":1719494641144,"mc":[{"id":"1.230178130","rc":[{"atb":[[13,11]],"id":52385884}],"con":true,"img":false}]}
{"op":"mcm","clk":"11550122192","pt":1719494641932,"mc":[{"id":"1.230178130","rc":[{"atb":[[8.6,5],[9.2,0],[8.4,0],[9.4,2.5]],"id":52385899}],"con":true,"img":false}]}
{"op":"mcm","clk":"11550122203","pt":1719494642030,"mc":[{"id":"1.230178130","rc":[{"atl":[[90,7],[100,0]],"id":52385910},{"atl":[[180,2],[200,0]],"id":52385911},{"atb":[[10.5,0],[13,8.33]],"id":52385912},{"atl":[[85,2],[90,0]],"id":52385912},{"atb":[[5.6,21.74],[5.3,2.5]],"id":52385883},{"atb":[[4,37.83],[3.75,0]],"id":52385896},{"atb":[[4.5,0],[5,25]],"id":52385897},{"atl":[[80,2],[90,0]],"id":52385891},{"atb":[[13.5,0],[15,12.14]],"id":52385892},{"atl":[[130,0],[110,2]],"id":52385892},{"atb":[[4.8,0],[5.9,20]],"id":52385904},{"atl":[[85,2],[95,0]],"id":52385904},{"atb":[[1.84,0],[2.58,63.29]],"id":52385905},{"atb":[[4,35.33],[3.4,0]],"id":52385898},{"atb":[[7.6,0],[8.4,13.51]],"id":52385899}],"con":true,"img":false}]}
{"op":"mcm","clk":"11550122266","pt":1719494642655,"mc":[{"id":"1.230178130","rc":[{"atl":[[21,3]],"id":52385896}],"con":true,"img":false}]}
{"op":"mcm","clk":"11550122291","pt":1719494642917,"mc":[{"id":"1.230178130","rc":[{"atl":[[24,0]],"id":52385899}],"con":true,"img":false}]}
{"op":"mcm","clk":"11550122302","pt":1719494643023,"mc":[{"id":"1.230178130","rc":[{"atb":[[8,0]],"id":52385898},{"atl":[[44,2.33],[25,25]],"id":52385899}],"con":true,"img":false}]}
{"op":"mcm","clk":"11550122320","pt":1719494643135,"mc":[{"id":"1.230178130","rc":[{"atb":[[9,12]],"id":52385898},{"atl":[[48,0]],"id":52385899}],"con":true,"img":false}]}
{"op":"mcm","clk":"11550122325","pt":1719494643231,"mc":[{"id":"1.230178130","rc":[{"atl":[[21,0]],"id":52385896}],"con":true,"img":false}]}
{"op":"mcm","clk":"11550122336","pt":1719494643335,"mc":[{"id":"1.230178130","rc":[{"atl":[[25,0]],"id":52385899}],"con":true,"img":false}]}
{"op":"mcm","clk":"11550122345","pt":1719494643443,"mc":[{"id":"1.230178130","rc":[{"atl":[[26,24]],"id":52385899}],"con":true,"img":false}]}
{"op":"mcm","clk":"11550122351","pt":1719494643544,"mc":[{"id":"1.230178130","rc":[{"atb":[[42,0.49]],"id":52385913}],"con":true,"img":false}]}
{"op":"mcm","clk":"11550122362","pt":1719494643648,"mc":[{"id":"1.230178130","rc":[{"atb":[[23,0.89]],"id":52385912}],"con":true,"img":false}]}
{"op":"mcm","clk":"11550122378","pt":1719494643753,"mc":[{"id":"1.230178130","rc":[{"atb":[[42,0.49]],"id":52385911}],"con":true,"img":false}]}
{"op":"mcm","clk":"11550122391","pt":1719494643857,"mc":[{"id":"1.230178130","rc":[{"atb":[[21,0.98]],"id":52385910}],"con":true,"img":false}]}
{"op":"mcm","clk":"11550122415","pt":1719494644015,"mc":[{"id":"1.230178130","rc":[{"atb":[[30,0.68]],"id":52385906}],"con":true,"img":false}]}
{"op":"mcm","clk":"11550122436","pt":1719494644223,"mc":[{"id":"1.230178130","rc":[{"atl":[[130,5],[95,8.88]],"id":52385911},{"atb":[[27,20]],"id":52385892},{"atb":[[12,1.71]],"id":52385905}],"con":true,"img":false}]}
{"op":"mcm","clk":"11550122447","pt":1719494644326,"mc":[{"id":"1.230178130","rc":[{"atl":[[140,0],[100,0]],"id":52385911}],"con":true,"img":false}]}
{"op":"mcm","clk":"11550122457","pt":1719494644435,"mc":[{"id":"1.230178130","rc":[{"atb":[[11,0],[13.5,8],[30,19]],"id":52385910},{"atb":[[12.5,0],[14.5,0],[15,2.5]],"id":52385912},{"atb":[[16.5,0],[19,5.56],[23,0],[27,0],[28,2.5]],"id":52385913},{"atb":[[16.5,0],[18.5,0],[19,2.5],[40,15.38]],"id":52385906},{"atb":[[11,0],[7.6,0],[8.4,0]],"id":52385889},{"atb":[[9,0],[8.2,0],[12,0],[6.6,20.36]],"id":52385882},{"atb":[[5.7,0],[6.6,17.86]],"id":52385890},{"atl":[[32,0],[28,8.7]],"id":52385890},{"atb":[[9.6,0],[12,9.09]],"id":52385891},{"atb":[[21,0]],"id":52385892},{"atb":[[4.8,0],[5.3,23.26]],"id":52385903},{"atb":[[19,1.08]],"id":52385904},{"atl":[[34,2.5],[36,0],[42,5],[29,0]],"id":52385899}],"con":true,"img":false}]}
{"op":"mcm","clk":"11550122466","pt":1719494644533,"mc":[{"id":"1.230178130","rc":[{"atb":[[24,4]],"id":52385910},{"atb":[[34,0]],"id":52385906},{"atb":[[9,40.14],[6.2,21.73],[5.7,5]],"id":52385889},{"atb":[[11.5,20],[6.8,17.24],[6.6,2.5]],"id":52385882}],"con":true,"img":false}]}
{"op":"mcm","clk":"11550122476","pt":1719494644638,"mc":[{"id":"1.230178130","rc":[{"atb":[[4,35.33],[6.8,0]],"id":52385882},{"atb":[[15,12.37]],"id":52385903}],"con":true,"img":false}]}
{"op":"mcm","clk":"11550122489","pt":1719494644741,"mc":[{"id":"1.230178130","rc":[{"atb":[[4,2],[11.5,0],[6.6,20.36]],"id":52385882},{"atb":[[27,0]],"id":52385891},{"atb":[[11.5,1.78]],"id":52385899}],"con":true,"img":false}]}
{"op":"mcm","clk":"11550122502","pt":1719494644845,"mc":[{"id":"1.230178130","rc":[{"atb":[[11,50],[4.1,32.26],[6.6,2.5]],"id":52385882},{"atb":[[26,20]],"id":52385891}],"con":true,"img":false}]}
{"op":"mcm","clk":"11550122511","pt":1719494644947,"mc":[{"id":"1.230178130","rc":[{"atb":[[8.4,2.44]],"id":52385898}],"con":true,"img":false}]}
{"op":"mcm","clk":"11550122526","pt":1719494645054,"mc":[{"id":"1.230178130","rc":[{"atb":[[8,12]],"id":52385882},{"atb":[[6.4,99.94]],"id":52385896},{"atb":[[8.4,2.44]],"id":52385897},{"atb":[[26,0]],"id":52385891},{"atl":[[40,15.38]],"id":52385891}],"con":true,"img":false}]}
{"op":"mcm","clk":"11550122541","pt":1719494645159,"mc":[{"id":"1.230178130","rc":[{"atb":[[4.1,0],[6.8,17.24]],"id":52385882},{"atb":[[6,12],[5.2,3.94]],"id":52385896},{"atb":[[24,15]],"id":52385891},{"atl":[[42,0]],"id":52385891}],"con":true,"img":false}]}
{"op":"mcm","clk":"11550122566","pt":1719494645331,"mc":[{"id":"1.230178130","rc":[{"atb":[[18.5,1.11]],"id":52385892}],"con":true,"img":false}]}
{"op":"mcm","clk":"11550122589","pt":1719494645531,"mc":[{"id":"1.230178130","rc":[{"atb":[[23,0.89]],"id":52385891}],"con":true,"img":false}]}
{"op":"mcm","clk":"11550122601","pt":1719494645636,"mc":[{"id":"1.230178130","rc":[{"atb":[[10,2.05]],"id":52385890}],"con":true,"img":false}]}
{"op":"mcm","clk":"11550122616","pt":1719494645747,"mc":[{"id":"1.230178130","rc":[{"atb":[[9.6,2.13]],"id":52385889}],"con":true,"img":false}]}
{"op":"mcm","clk":"11550122629","pt":1719494645848,"mc":[{"id":"1.230178130","rc":[{"atb":[[20,1.02]],"id":52385885}],"con":true,"img":false}]}
{"op":"mcm","clk":"11550122640","pt":1719494645947,"mc":[{"id":"1.230178130","rc":[{"atb":[[14.5,1.41]],"id":52385884}],"con":true,"img":false}]}
{"op":"mcm","clk":"11550122654","pt":1719494646051,"mc":[{"id":"1.230178130","rc":[{"atb":[[11,0]],"id":52385890}],"con":true,"img":false}]}
{"op":"mcm","clk":"11550122664","pt":1719494646155,"mc":[{"id":"1.230178130","rc":[{"atl":[[90,5],[95,2]],"id":52385910},{"atb":[[6,3.41]],"id":52385883},{"atb":[[10,14.05]],"id":52385890},{"atb":[[2.58,0],[2.34,74.63]],"id":52385905},{"atb":[[4,2],[3.4,41.67]],"id":52385898}],"con":true,"img":false}]}
{"op":"mcm","clk":"11550122693","pt":1719494646367,"mc":[{"id":"1.230178130","rc":[{"atb":[[10.5,1.95]],"id":52385882}],"con":true,"img":false}]}
{"op":"mcm","clk":"11550122788","pt":1719494647151,"mc":[{"id":"1.230178130","rc":[{"atb":[[6.8,17.24],[5.9,0]],"id":52385904}],"con":true,"img":false}]}
{"op":"mcm","clk":"11550122821","pt":1719494647454,"mc":[{"id":"1.230178130","rc":[{"atb":[[17.5,34]],"id":52385899}],"con":true,"img":false}]}
{"op":"mcm","clk":"11550122846","pt":1719494647612,"mc":[{"id":"1.230178130","rc":[{"atb":[[13.5,0]],"id":52385899}],"con":true,"img":false}]}
{"op":"mcm","clk":"11550123015","pt":1719494649020,"mc":[{"id":"1.230178130","rc":[{"atb":[[18,0]],"id":52385891}],"con":true,"img":false}]}
{"op":"mcm","clk":"11550123067","pt":1719494649435,"mc":[{"id":"1.230178130","rc":[{"atl":[[65,11.88],[85,5]],"id":52385892},{"atl":[[44,7.33]],"id":52385903},{"atl":[[80,2],[42,14.63]],"id":52385904},{"atb":[[2.48,67.57]],"id":52385905}],"con":true,"img":false}]}
{"op":"mcm","clk":"11550123079","pt":1719494649538,"mc":[{"id":"1.230178130","rc":[{"atb":[[6.4,0]],"id":52385896},{"atl":[[70,0],[90,0]],"id":52385892},{"atl":[[48,0]],"id":52385903},{"atl":[[85,0]],"id":52385904},{"atb":[[2.34,0]],"id":52385905}],"con":true,"img":false}]}
{"op":"mcm","clk":"11550123091","pt":1719494649644,"mc":[{"id":"1.230178130","rc":[{"atb":[[6.2,48.28]],"id":52385896},{"atl":[[50,0]],"id":52385904}],"con":true,"img":false}]}
{"op":"mcm","clk":"11550123326","pt":1719494652036,"mc":[{"id":"1.230178130","rc":[{"atb":[[23,0]],"id":52385885}],"con":true,"img":false}]}
{"op":"mcm","clk":"11550123335","pt":1719494652144,"mc":[{"id":"1.230178130","rc":[{"atb":[[22,10]],"id":52385885},{"atb":[[13,0]],"id":52385899}],"con":true,"img":false}]}
{"op":"mcm","clk":"11550123343","pt":1719494652245,"mc":[{"id":"1.230178130","rc":[{"atb":[[14,12]],"id":52385899}],"con":true,"img":false}]}
{"op":"mcm","clk":"11550123447","pt":1719494653261,"mc":[{"id":"1.230178130","rc":[{"atb":[[32,19.35]],"id":52385892}],"con":true,"img":false}]}
{"op":"mcm","clk":"11550123467","pt":1719494653467,"mc":[{"id":"1.230178130","rc":[{"atb":[[27,0]],"id":52385892}],"con":true,"img":false}]}
{"op":"mcm","clk":"11550123477","pt":1719494653523,"mc":[{"id":"1.230178130","rc":[{"atb":[[9.6,52.73]],"id":52385889}],"con":true,"img":false}]}
{"op":"mcm","clk":"11550123497","pt":1719494653729,"mc":[{"id":"1.230178130","rc":[{"atb":[[9,11]],"id":52385889}],"con":true,"img":false}]}
{"op":"mcm","clk":"11550123564","pt":1719494654455,"mc":[{"id":"1.230178130","rc":[{"atb":[[30,0]],"id":52385910},{"atb":[[48,0]],"id":52385911},{"atl":[[70,2]],"id":52385885},{"atb":[[9,0],[8.6,5],[8.2,0],[9.4,2.5]],"id":52385903},{"atl":[[42,0]],"id":52385904},{"atb":[[1.93,107.53],[2.48,0]],"id":52385905},{"atl":[[25,0]],"id":52385905},{"atb":[[3.4,0],[3,50]],"id":52385898},{"atl":[[32,2.5],[34,0],[40,5],[42,0]],"id":52385899}],"con":true,"img":false}]}
{"op":"mcm","clk":"11550123577","pt":1719494654569,"mc":[{"id":"1.230178130","rc":[{"atb":[[24,22]],"id":52385910},{"atb":[[46,13.33]],"id":52385911},{"atl":[[80,0]],"id":52385885},{"atl":[[70,8.7],[85,2]],"id":52385904},{"atl":[[32,19.35]],"id":52385905}],"con":true,"img":false}]}
{"op":"mcm","clk":"11550123587","pt":1719494654663,"mc":[{"id":"1.230178130","rc":[{"atl":[[80,0]],"id":52385904}],"con":true,"img":false}]}
{"op":"mcm","clk":"11550123602","pt":1719494654768,"mc":[{"id":"1.230178130","rc":[{"atl":[[65,11.88],[70,0],[85,5],[90,0]],"id":52385910},{"atb":[[46,0]],"id":52385911},{"atl":[[85,9.64],[90,0],[110,5],[120,0]],"id":52385906}],"con":true,"img":false}]}
{"op":"mcm","clk":"11550123613","pt":1719494654869,"mc":[{"id":"1.230178130","rc":[{"atl":[[90,2],[95,0]],"id":52385910},{"atb":[[44,13.95]],"id":52385911},{"atl":[[130,0],[120,2]],"id":52385906}],"con":true,"img":false}]}
{"op":"mcm","clk":"11550123627","pt":1719494654930,"mc":[{"id":"1.230178130","rc":[{"atl":[[90,0],[95,2]],"id":52385910},{"atl":[[130,2]],"id":52385906}],"con":true,"img":false}]}
{"op":"mcm","clk":"11550123635","pt":1719494655028,"mc":[{"id":"1.230178130","rc":[{"atl":[[120,0]],"id":52385906},{"atb":[[8,0]],"id":52385882}],"con":true,"img":false}]}
{"op":"mcm","clk":"11550123651","pt":1719494655136,"mc":[{"id":"1.230178130","rc":[{"atb":[[32,0]],"id":52385892}],"con":true,"img":false}]}
{"op":"mcm","clk":"11550123661","pt":1719494655235,"mc":[{"id":"1.230178130","rc":[{"atb":[[30,20]],"id":52385892}],"con":true,"img":false}]}
{"op":"mcm","clk":"11550123674","pt":1719494655343,"mc":[{"id":"1.230178130","rc":[{"atl":[[90,6.74]],"id":52385911},{"atb":[[22,0]],"id":52385885}],"con":true,"img":false}]}
{"op":"mcm","clk":"11550123685","pt":1719494655440,"mc":[{"id":"1.230178130","rc":[{"atl":[[160,2],[95,2.5]],"id":52385911},{"atb":[[21,15]],"id":52385885}],"con":true,"img":false}]}
{"op":"mcm","clk":"11550123695","pt":1719494655549,"mc":[{"id":"1.230178130","rc":[{"atl":[[180,0]],"id":52385911}],"con":true,"img":false}]}
{"op":"mcm","clk":"11550123728","pt":1719494655856,"mc":[{"id":"1.230178130","rc":[{"atl":[[32,0],[25,2.5],[27,0],[29,8.57]],"id":52385889}],"con":true,"img":false}]}
{"op":"mcm","clk":"11550123760","pt":1719494656070,"mc":[{"id":"1.230178130","rc":[{"atl":[[25,6.67],[29,5]],"id":52385889}],"con":true,"img":false}]}
{"op":"mcm","clk":"11550123783","pt":1719494656375,"mc":[{"id":"1.230178130","rc":[{"atb":[[25,9.62]],"id":52385892}],"con":true,"img":false}]}
{"op":"mcm","clk":"11550123801","pt":1719494656545,"mc":[{"id":"1.230178130","rc":[{"atb":[[25,0]],"id":52385892}],"con":true,"img":false}]}
{"op":"mcm","clk":"11550123893","pt":1719494657673,"mc":[{"id":"1.230178130","rc":[{"atl":[[170,3]],"id":52385913}],"con":true,"img":false}]}
{"op":"mcm","clk":"11550123906","pt":1719494657775,"mc":[{"id":"1.230178130","rc":[{"atl":[[180,2],[210,0]],"id":52385913}],"con":true,"img":false}]}
{"op":"mcm","clk":"11550123945","pt":1719494658044,"mc":[{"id":"1.230178130","rc":[{"atb":[[40,0]],"id":52385911},{"atl":[[75,5],[80,0],[55,13.61],[60,0]],"id":52385912},{"atl":[[26,0]],"id":52385884}],"con":true,"img":false}]}
{"op":"mcm","clk":"11550123954","pt":1719494658144,"mc":[{"id":"1.230178130","rc":[{"atb":[[38,2]],"id":52385911},{"atl":[[80,2]],"id":52385912},{"atl":[[32,19.35]],"id":52385884},{"atl":[[26,0]],"id":52385899}],"con":true,"img":false}]}
{"op":"mcm","clk":"11550123964","pt":1719494658248,"mc":[{"id":"1.230178130","rc":[{"atl":[[85,0]],"id":52385912},{"atl":[[27,15]],"id":52385899}],"con":true,"img":false}]}
{"op":"mcm","clk":"11550123981","pt":1719494658456,"mc":[{"id":"1.230178130","rc":[{"atl":[[50,12.24]],"id":52385904}],"con":true,"img":false}]}
{"op":"mcm","clk":"11550123993","pt":1719494658560,"mc":[{"id":"1.230178130","rc":[{"atl":[[22,3]],"id":52385896}],"con":true,"img":false}]}
{"op":"mcm","clk":"11550124004","pt":1719494658660,"mc":[{"id":"1.230178130","rc":[{"atl":[[70,0]],"id":52385904}],"con":true,"img":false}]}
{"op":"mcm","clk":"11550124100","pt":1719494659544,"mc":[{"id":"1.230178130","rc":[{"atb":[[8.4,0],[9.4,11.9]],"id":52385884},{"atb":[[4.5,24.74]],"id":52385903},{"atb":[[5.6,17.3]],"id":52385904},{"atb":[[1.83,120.48],[1.93,0]],"id":52385905},{"atb":[[17.5,0]],"id":52385899}],"con":true,"img":false}]}
{"op":"mcm","clk":"11550124112","pt":1719494659645,"mc":[{"id":"1.230178130","rc":[{"atb":[[27,0]],"id":52385912},{"atb":[[5.3,0]],"id":52385903},{"atb":[[6.8,0]],"id":52385904},{"atb":[[14,46]],"id":52385899}],"con":true,"img":false}]}
{"op":"mcm","clk":"11550124120","pt":1719494659748,"mc":[{"id":"1.230178130","rc":[{"atb":[[24,37.09]],"id":52385912},{"atb":[[8.4,53.48]],"id":52385883}],"con":true,"img":false}]}
{"op":"mcm","clk":"11550124135","pt":1719494659954,"mc":[{"id":"1.230178130","rc":[{"atb":[[7,12]],"id":52385883}],"con":true,"img":false}]}
{"op":"mcm","clk":"11550124146","pt":1719494660058,"mc":[{"id":"1.230178130","rc":[{"atl":[[25,2.5],[29,8.57]],"id":52385889}],"con":true,"img":false}]}
{"op":"mcm","clk":"11550124238","pt":1719494661050,"mc":[{"id":"1.230178130","rc":[{"atb":[[10,2.05]],"id":52385890}],"con":true,"img":false}]}
{"op":"mcm","clk":"11550124251","pt":1719494661158,"mc":[{"id":"1.230178130","rc":[{"atb":[[11,12]],"id":52385890}],"con":true,"img":false}]}
{"op":"mcm","clk":"11550124301","pt":1719494661674,"mc":[{"id":"1.230178130","rc":[{"atb":[[24,46.47]],"id":52385912}],"con":true,"img":false}]}
{"op":"mcm","clk":"11550124322","pt":1719494661894,"mc":[{"id":"1.230178130","rc":[{"atb":[[24,37.09]],"id":52385912}],"con":true,"img":false}]}
{"op":"mcm","clk":"11550124352","pt":1719494662152,"mc":[{"id":"1.230178130","rc":[{"atl":[[27,0]],"id":52385899}],"con":true,"img":false}]}
{"op":"mcm","clk":"11550124360","pt":1719494662261,"mc":[{"id":"1.230178130","rc":[{"atl":[[30,15]],"id":52385899}],"con":true,"img":false}]}
{"op":"mcm","clk":"11550124373","pt":1719494662359,"mc":[{"id":"1.230178130","rc":[{"atb":[[10.5,63.16]],"id":52385889}],"con":true,"img":false}]}
{"op":"mcm","clk":"11550124394","pt":1719494662569,"mc":[{"id":"1.230178130","rc":[{"atb":[[9.6,2.13]],"id":52385889}],"con":true,"img":false}]}
{"op":"mcm","clk":"11550124471","pt":1719494663356,"mc":[{"id":"1.230178130","rc":[{"atl":[[30,20]],"id":52385905}],"con":true,"img":false}]}
{"op":"mcm","clk":"11550124492","pt":1719494663565,"mc":[{"id":"1.230178130","rc":[{"atl":[[32,0]],"id":52385905}],"con":true,"img":false}]}
{"op":"mcm","clk":"11550124589","pt":1719494664662,"mc":[{"id":"1.230178130","rc":[{"atb":[[8.4,0]],"id":52385883},{"atb":[[4,4.5],[3.7,37.04]],"id":52385896},{"atl":[[18,0],[20,0],[22,2.5]],"id":52385897},{"atb":[[1.83,0],[1.89,112.36]],"id":52385905},{"atb":[[2.56,64.1],[3,0]],"id":52385898},{"atl":[[25,0],[29,0],[30,2.5]],"id":52385898}],"con":true,"img":false}]}
{"op":"mcm","clk":"11550124598","pt":1719494664765,"mc":[{"id":"1.230178130","rc":[{"atb":[[10.5,0]],"id":52385889},{"atl":[[36,0],[30,3.45]],"id":52385882},{"atb":[[6.2,16.82]],"id":52385883},{"atb":[[5.6,0],[6.8,17.24]],"id":52385904}],"con":true,"img":false}]}
{"op":"mcm","clk":"11550124610","pt":1719494664873,"mc":[{"id":"1.230178130","rc":[{"atb":[[9,50.14]],"id":52385889},{"atl":[[40,17.5],[42,0],[48,5],[50,0]],"id":52385885}],"con":true,"img":false}]}
{"op":"mcm","clk":"11550124717","pt":1719494665756,"mc":[{"id":"1.230178130","rc":[{"atb":[[11,64.29]],"id":52385882},{"atl":[[17.5,36.36]],"id":52385890}],"con":true,"img":false}]}
{"op":"mcm","clk":"11550124729","pt":1719494665870,"mc":[{"id":"1.230178130","rc":[{"atb":[[11,50]],"id":52385882},{"atl":[[18,0]],"id":52385890}],"con":true,"img":false}]}
{"op":"mcm","clk":"11550124810","pt":1719494666752,"mc":[{"id":"1.230178130","rc":[{"atb":[[9.6,27.64]],"id":52385889},{"atl":[[14.5,6.76]],"id":52385897}],"con":true,"img":false}]}
{"op":"mcm","clk":"11550124831","pt":1719494666959,"mc":[{"id":"1.230178130","rc":[{"atb":[[9.6,2.13]],"id":52385889},{"atl":[[26,24]],"id":52385884},{"atl":[[14.5,21.5]],"id":52385897}],"con":true,"img":false}]}
{"op":"mcm","clk":"11550124840","pt":1719494667064,"mc":[{"id":"1.230178130","rc":[{"atl":[[28,15]],"id":52385899}],"con":true,"img":false}]}
{"op":"mcm","clk":"11550124849","pt":1719494667164,"mc":[{"id":"1.230178130","rc":[{"atb":[[9,39.14]],"id":52385889},{"atl":[[32,0]],"id":52385884},{"atl":[[17.5,0],[14.5,0]],"id":52385897}],"con":true,"img":false}]}
{"op":"mcm","clk":"11550124859","pt":1719494667267,"mc":[{"id":"1.230178130","rc":[{"atb":[[8,11]],"id":52385889},{"atl":[[18,35.29]],"id":52385897},{"atl":[[30,0]],"id":52385899}],"con":true,"img":false}]}
{"op":"mcm","clk":"11550124868","pt":1719494667377,"mc":[{"id":"1.230178130","rc":[{"atl":[[25,0],[250,2]],"id":52385897}],"con":true,"img":false}]}
{"op":"mcm","clk":"11550124934","pt":1719494668154,"mc":[{"id":"1.230178130","rc":[{"atb":[[30,0]],"id":52385892}],"con":true,"img":false}]}
{"op":"mcm","clk":"11550124943","pt":1719494668251,"mc":[{"id":"1.230178130","rc":[{"atb":[[29,20]],"id":52385892}],"con":true,"img":false}]}
{"op":"mcm","clk":"11550124951","pt":1719494668360,"mc":[{"id":"1.230178130","rc":[{"atb":[[17.5,15]],"id":52385899}],"con":true,"img":false}]}
{"op":"mcm","clk":"11550124961","pt":1719494668465,"mc":[{"id":"1.230178130","rc":[{"atb":[[27,15]],"id":52385912},{"atb":[[7,46]],"id":52385883},{"atb":[[29,0]],"id":52385892}],"con":true,"img":false}]}
{"op":"mcm","clk":"11550124975","pt":1719494668571,"mc":[{"id":"1.230178130","rc":[{"atb":[[28,20]],"id":52385892},{"atb":[[14,12]],"id":52385899}],"con":true,"img":false}]}
{"op":"mcm","clk":"11550124981","pt":1719494668671,"mc":[{"id":"1.230178130","rc":[{"atb":[[24,11]],"id":52385912},{"atb":[[6.2,0]],"id":52385883}],"con":true,"img":false}]}
{"op":"mcm","clk":"11550125018","pt":1719494669182,"mc":[{"id":"1.230178130","rc":[{"atb":[[38,0]],"id":52385911}],"con":true,"img":false}]}
{"op":"mcm","clk":"11550125027","pt":1719494669289,"mc":[{"id":"1.230178130","rc":[{"atb":[[24,4.5]],"id":52385911}],"con":true,"img":false}]}
{"op":"mcm","clk":"11550125071","pt":1719494669757,"mc":[{"id":"1.230178130","rc":[{"atl":[[80,0]],"id":52385912},{"atl":[[70,5],[50,2.5]],"id":52385891},{"atb":[[2.18,84.75]],"id":52385898}],"con":true,"img":false}]}
{"op":"mcm","clk":"11550125085","pt":1719494669864,"mc":[{"id":"1.230178130","rc":[{"atl":[[85,2]],"id":52385912},{"atl":[[12,0]],"id":52385883},{"atb":[[7,48.28]],"id":52385896},{"atb":[[11.5,0]],"id":52385890},{"atl":[[70,7],[75,0],[80,0],[55,0]],"id":52385891},{"atl":[[42,14.63]],"id":52385904},{"atb":[[1.73,136.99],[1.89,0]],"id":52385905},{"atb":[[2.56,0]],"id":52385898},{"atl":[[22,0]],"id":52385898}],"con":true,"img":false}]}
{"op":"mcm","clk":"11550125092","pt":1719494669964,"mc":[{"id":"1.230178130","rc":[{"atl":[[12.5,16.82]],"id":52385883},{"atb":[[6.2,0]],"id":52385896},{"atl":[[10.5,0],[22,0]],"id":52385896},{"atb":[[11,41]],"id":52385890},{"atl":[[36,0],[42,2.44],[29,21.43]],"id":52385898}],"con":true,"img":false}]}
{"op":"mcm","clk":"11550125096","pt":1719494670068,"mc":[{"id":"1.230178130","rc":[{"atl":[[85,0],[470,2]],"id":52385912},{"atl":[[50,0]],"id":52385904}],"con":true,"img":false}]}
{"op":"mcm","clk":"11550125107","pt":1719494670173,"mc":[{"id":"1.230178130","rc":[{"atl":[[12.5,0]],"id":52385883},{"atl":[[26,0]],"id":52385884},{"atl":[[85,2],[11,60],[15,5]],"id":52385896},{"atl":[[42,0],[360,2]],"id":52385898}],"con":true,"img":false}]}
{"op":"mcm","clk":"11550125113","pt":1719494670280,"mc":[{"id":"1.230178130","rc":[{"atl":[[13,43.64]],"id":52385883},{"atl":[[32,19.35]],"id":52385884}],"con":true,"img":false}]}
{"op":"mcm","clk":"11550125123","pt":1719494670379,"mc":[{"id":"1.230178130","rc":[{"atl":[[11,0]],"id":52385896}],"con":true,"img":false}]}
{"op":"mcm","clk":"11550125131","pt":1719494670483,"mc":[{"id":"1.230178130","rc":[{"atl":[[12.5,34]],"id":52385896}],"con":true,"img":false}]}
{"op":"mcm","clk":"11550125173","pt":1719494670853,"mc":[{"id":"1.230178130","rc":[{"atl":[[12,14.28]],"id":52385883},{"atb":[[11.5,13.64]],"id":52385890},{"atb":[[24,0]],"id":52385891},{"atl":[[36,17.14]],"id":52385891},{"atl":[[48,4.47]],"id":52385904}],"con":true,"img":false}]}
{"op":"mcm","clk":"11550125188","pt":1719494670954,"mc":[{"id":"1.230178130","rc":[{"atb":[[11.5,0]],"id":52385890},{"atb":[[23,10.89]],"id":52385891},{"atl":[[48,0]],"id":52385904}],"con":true,"img":false}]}
{"op":"mcm","clk":"11550125193","pt":1719494671053,"mc":[{"id":"1.230178130","rc":[{"atl":[[12,0]],"id":52385883},{"atl":[[40,0]],"id":52385891}],"con":true,"img":false}]}
{"op":"mcm","clk":"11550125265","pt":1719494671887,"mc":[{"id":"1.230178130","rc":[{"atb":[[23,15.27]],"id":52385891}],"con":true,"img":false}]}
{"op":"mcm","clk":"11550125283","pt":1719494672096,"mc":[{"id":"1.230178130","rc":[{"atb":[[23,10.89]],"id":52385891}],"con":true,"img":false}]}
{"op":"mcm","clk":"11550125296","pt":1719494672154,"mc":[{"id":"1.230178130","rc":[{"atb":[[11,29]],"id":52385890}],"con":true,"img":false}]}
{"op":"mcm","clk":"11550125307","pt":1719494672254,"mc":[{"id":"1.230178130","rc":[{"atb":[[9,12]],"id":52385890}],"con":true,"img":false}]}
{"op":"mcm","clk":"11550125315","pt":1719494672358,"mc":[{"id":"1.230178130","rc":[{"atb":[[11,0]],"id":52385890}],"con":true,"img":false}]}
{"op":"mcm","clk":"11550125326","pt":1719494672464,"mc":[{"id":"1.230178130","rc":[{"atl":[[25,4.17]],"id":52385897},{"atb":[[10,43.45]],"id":52385890}],"con":true,"img":false}]}
{"op":"mcm","clk":"11550125336","pt":1719494672567,"mc":[{"id":"1.230178130","rc":[{"atl":[[250,0]],"id":52385897}],"con":true,"img":false}]}
{"op":"mcm","clk":"11550125366","pt":1719494672884,"mc":[{"id":"1.230178130","rc":[{"atb":[[28,0]],"id":52385892}],"con":true,"img":false}]}
{"op":"mcm","clk":"11550125381","pt":1719494672990,"mc":[{"id":"1.230178130","rc":[{"atb":[[22,15]],"id":52385885},{"atb":[[13,8.33],[29,20],[15,5]],"id":52385892}],"con":true,"img":false}]}
{"op":"mcm","clk":"11550125397","pt":1719494673191,"mc":[{"id":"1.230178130","rc":[{"atb":[[21,0]],"id":52385885},{"atb":[[6,0]],"id":52385896},{"atb":[[23,0.89]],"id":52385891},{"atb":[[14,0]],"id":52385899}],"con":true,"img":false}]}
{"op":"mcm","clk":"11550125408","pt":1719494673294,"mc":[{"id":"1.230178130","rc":[{"atb":[[7,60.28]],"id":52385896},{"atl":[[21,2.5],[24,0],[25,5],[28,3.7]],"id":52385890},{"atb":[[16,12]],"id":52385899}],"con":true,"img":false}]}
{"op":"mcm","clk":"11550125416","pt":1719494673351,"mc":[{"id":"1.230178130","rc":[{"atb":[[8.4,53.48]],"id":52385883}],"con":true,"img":false}]}
{"op":"mcm","clk":"11550125437","pt":1719494673558,"mc":[{"id":"1.230178130","rc":[{"atb":[[7,12]],"id":52385883}],"con":true,"img":false}]}
{"op":"mcm","clk":"11550125446","pt":1719494673660,"mc":[{"id":"1.230178130","rc":[{"atb":[[23,15.89]],"id":52385891}],"con":true,"img":false}]}
{"op":"mcm","clk":"11550125466","pt":1719494673874,"mc":[{"id":"1.230178130","rc":[{"atb":[[23,0.89]],"id":52385891}],"con":true,"img":false}]}
{"op":"mcm","clk":"11550125517","pt":1719494674387,"mc":[{"id":"1.230178130","rc":[{"atl":[[16.5,29]],"id":52385890}],"con":true,"img":false}]}
{"op":"mcm","clk":"11550125539","pt":1719494674596,"mc":[{"id":"1.230178130","rc":[{"atl":[[17.5,0]],"id":52385890}],"con":true,"img":false}]}
{"op":"mcm","clk":"11550125565","pt":1719494674924,"mc":[{"id":"1.230178130","rc":[{"atb":[[44,0]],"id":52385911},{"atb":[[9,0]],"id":52385889},{"atb":[[11,0]],"id":52385882},{"atb":[[3.7,0],[3.35,42.55]],"id":52385896},{"atb":[[8.6,0],[7.8,0]],"id":52385890},{"atl":[[25,9.17],[28,0]],"id":52385890},{"atb":[[29,0]],"id":52385892},{"atb":[[6.8,0],[8.4,13.51]],"id":52385904},{"atb":[[1.73,0],[1.55,181.82]],"id":52385905},{"atb":[[2.18,0],[1.65,153.85]],"id":52385898},{"atb":[[7.2,16.13],[8.4,0]],"id":52385899},{"atl":[[32,0],[36,2.5],[40,0],[44,5],[55,2]],"id":52385899}],"con":true,"img":false}]}
{"op":"mcm","clk":"11550125577","pt":1719494674963,"mc":[{"id":"1.230178130","rc":[{"atb":[[7,15]],"id":52385882},{"atb":[[5.5,5],[5.9,2.5]],"id":52385890},{"atb":[[19,14]],"id":52385892}],"con":true,"img":false}]}
{"op":"mcm","clk":"11550125588","pt":1719494675062,"mc":[{"id":"1.230178130","rc":[{"atb":[[25,14]],"id":52385911},{"atb":[[8,0],[10,2.5],[9.2,5],[8.8,0]],"id":52385905},{"atb":[[5.5,0],[7.6,2.5],[6.8,5],[5.9,0]],"id":52385898}],"con":true,"img":false}]}
{"op":"mcm","clk":"11550125613","pt":1719494675274,"mc":[{"id":"1.230178130","rc":[{"atl":[[85,2],[470,0]],"id":52385912},{"atl":[[85,0],[15,12.14]],"id":52385896}],"con":true,"img":false}]}
{"op":"mcm","clk":"11550125675","pt":1719494675791,"mc":[{"id":"1.230178130","rc":[{"atb":[[25,1.58]],"id":52385910},{"atb":[[28,1.4]],"id":52385911},{"atb":[[28,1.4]],"id":52385912},{"atb":[[7.4,5.92]],"id":52385889},{"atb":[[7.2,6.11]],"id":52385882},{"atb":[[7.2,6.11]],"id":52385896},{"atb":[[7.2,3.37]],"id":52385897},{"atb":[[9,4.74]],"id":52385891},{"atb":[[17.5,2.29]],"id":52385903},{"atb":[[14.5,2.8]],"id":52385905},{"atb":[[9.8,4.3]],"id":52385898}],"con":true,"img":false}]}
{"op":"mcm","clk":"11550125696","pt":1719494675997,"mc":[{"id":"1.230178130","rc":[{"atb":[[28,14]],"id":52385910},{"atl":[[18,0]],"id":52385897},{"atb":[[17.5,38.65]],"id":52385903},{"atb":[[15,20]],"id":52385905},{"atb":[[10,32.62]],"id":52385898}],"con":true,"img":false}]}
{"op":"mcm","clk":"11550125707","pt":1719494676061,"mc":[{"id":"1.230178130","rc":[{"atl":[[21,15.08]],"id":52385897},{"atb":[[20,0]],"id":52385904},{"atb":[[14,11]],"id":52385905}],"con":true,"img":false}]}
{"op":"mcm","clk":"11550125720","pt":1719494676159,"mc":[{"id":"1.230178130","rc":[{"atb":[[24,4]],"id":52385910},{"atb":[[17,0]],"id":52385903},{"atb":[[9.6,0]],"id":52385898}],"con":true,"img":false}]}
{"op":"mcm","clk":"11550125730","pt":1719494676261,"mc":[{"id":"1.230178130","rc":[{"atb":[[7,0]],"id":52385883}],"con":true,"img":false}]}
{"op":"mcm","clk":"11550125741","pt":1719494676362,"mc":[{"id":"1.230178130","rc":[{"atb":[[7.4,0]],"id":52385889},{"atb":[[8,12]],"id":52385883},{"atb":[[9,0]],"id":52385891}],"con":true,"img":false}]}
{"op":"mcm","clk":"11550125751","pt":1719494676465,"mc":[{"id":"1.230178130","rc":[{"atb":[[7.2,5.92]],"id":52385889},{"atb":[[8.8,4.74]],"id":52385891}],"con":true,"img":false}]}
{"op":"mcm","clk":"11550125778","pt":1719494676774,"mc":[{"id":"1.230178130","rc":[{"atb":[[21,20]],"id":52385892}],"con":true,"img":false}]}
{"op":"mcm","clk":"11550125785","pt":1719494676883,"mc":[{"id":"1.230178130","rc":[{"atb":[[1.61,163.93]],"id":52385905},{"atb":[[1.7,142.86],[1.65,0]],"id":52385898}],"con":true,"img":false}]}
{"op":"mcm","clk":"11550125791","pt":1719494676981,"mc":[{"id":"1.230178130","rc":[{"atb":[[19,0]],"id":52385892},{"atb":[[1.55,0]],"id":52385905}],"con":true,"img":false}]}
{"op":"mcm","clk":"11550125802","pt":1719494677092,"mc":[{"id":"1.230178130","rc":[{"atb":[[28,23.62]],"id":52385912},{"atb":[[7,0]],"id":52385897}],"con":true,"img":false}]}
{"op":"mcm","clk":"11550125814","pt":1719494677189,"mc":[{"id":"1.230178130","rc":[{"atb":[[27,0]],"id":52385912}],"con":true,"img":false}]}
{"op":"mcm","clk":"11550125832","pt":1719494677396,"mc":[{"id":"1.230178130","rc":[{"atb":[[14,0]],"id":52385905}],"con":true,"img":false}]}
{"op":"mcm","clk":"11550125844","pt":1719494677451,"mc":[{"id":"1.230178130","rc":[{"atb":[[17,11]],"id":52385905}],"con":true,"img":false}]}
{"op":"mcm","clk":"11550125889","pt":1719494677972,"mc":[{"id":"1.230178130","rc":[{"atl":[[22,28.57]],"id":52385889}],"con":true,"img":false}]}
{"op":"mcm","clk":"11550125899","pt":1719494678075,"mc":[{"id":"1.230178130","rc":[{"atb":[[8,0]],"id":52385889},{"atl":[[23,0],[25,6.67]],"id":52385889}],"con":true,"img":false}]}
{"op":"mcm","clk":"11550125907","pt":1719494678173,"mc":[{"id":"1.230178130","rc":[{"atl":[[29,5]],"id":52385889}],"con":true,"img":false}]}
{"op":"mcm","clk":"11550125929","pt":1719494678384,"mc":[{"id":"1.230178130","rc":[{"atb":[[7.2,42.61]],"id":52385896}],"con":true,"img":false}]}
{"op":"mcm","clk":"11550125947","pt":1719494678589,"mc":[{"id":"1.230178130","rc":[{"atl":[[12.5,34]],"id":52385883},{"atb":[[7,12]],"id":52385896}],"con":true,"img":false}]}
{"op":"mcm","clk":"11550125970","pt":1719494678799,"mc":[{"id":"1.230178130","rc":[{"atl":[[13,0]],"id":52385883}],"con":true,"img":false}]}
{"op":"mcm","clk":"11550125996","pt":1719494678962,"mc":[{"id":"1.230178130","rc":[{"atb":[[22,20]],"id":52385892}],"con":true,"img":false}]}
{"op":"mcm","clk":"11550126009","pt":1719494679063,"mc":[{"id":"1.230178130","rc":[{"atb":[[21,0]],"id":52385892},{"atb":[[1.68,147.06],[1.61,0]],"id":52385905},{"atb":[[9,0],[1.7,0],[1.76,131.58]],"id":52385898}],"con":true,"img":false}]}
{"op":"mcm","clk":"11550126024","pt":1719494679172,"mc":[{"id":"1.230178130","rc":[{"atb":[[10,44.62]],"id":52385898}],"con":true,"img":false}]}
{"op":"mcm","clk":"11550126046","pt":1719494679388,"mc":[{"id":"1.230178130","rc":[{"atl":[[34,15]],"id":52385891}],"con":true,"img":false}]}
{"op":"mcm","clk":"11550126059","pt":1719494679487,"mc":[{"id":"1.230178130","rc":[{"atl":[[36,0]],"id":52385891}],"con":true,"img":false}]}
{"op":"mcm","clk":"11550126096","pt":1719494679907,"mc":[{"id":"1.230178130","rc":[{"atb":[[16.5,6.45],[14,0]],"id":52385906},{"atb":[[5.6,0],[5.9,20.41]],"id":52385883},{"atb":[[3.6,38.46],[3.35,0]],"id":52385896},{"atl":[[20,2.5],[22,0],[24,5]],"id":52385897},{"atl":[[75,7],[85,0]],"id":52385904},{"atl":[[24,13.62]],"id":52385898}],"con":true,"img":false}]}
{"op":"mcm","clk":"11550126108","pt":1719494679965,"mc":[{"id":"1.230178130","rc":[{"atb":[[28,0]],"id":52385910},{"atb":[[22,0],[23,15]],"id":52385885},{"atl":[[23,4.55],[25,0]],"id":52385897},{"atb":[[4.5,0],[5.4,22.73]],"id":52385903},{"atl":[[40,15.38]],"id":52385904},{"atl":[[40,2.56],[360,0],[29,0]],"id":52385898}],"con":true,"img":false}]}
{"op":"mcm","clk":"11550126114","pt":1719494680063,"mc":[{"id":"1.230178130","rc":[{"atb":[[27,18]],"id":52385910},{"atl":[[75,3]],"id":52385885}],"con":true,"img":false}]}
{"op":"mcm","clk":"11550126123","pt":1719494680165,"mc":[{"id":"1.230178130","rc":[{"atl":[[42,0]],"id":52385904}],"con":true,"img":false}]}
{"op":"mcm","clk":"11550126147","pt":1719494680376,"mc":[{"id":"1.230178130","rc":[{"atl":[[75,0]],"id":52385885},{"atb":[[7.2,0]],"id":52385897}],"con":true,"img":false}]}
{"op":"mcm","clk":"11550126161","pt":1719494680479,"mc":[{"id":"1.230178130","rc":[{"atb":[[7,3.37]],"id":52385897}],"con":true,"img":false}]}
{"op":"mcm","clk":"11550126262","pt":1719494681410,"mc":[{"id":"1.230178130","rc":[{"atb":[[7,3.36]],"id":52385889},{"atb":[[8.6,5]],"id":52385883}],"con":true,"img":false}]}
{"op":"mcm","clk":"11550126268","pt":1719494681464,"mc":[{"id":"1.230178130","rc":[{"atb":[[7.2,0]],"id":52385889},{"atb":[[8.6,39.02]],"id":52385883},{"atb":[[28,20]],"id":52385892}],"con":true,"img":false}]}
{"op":"mcm","clk":"11550126290","pt":1719494681672,"mc":[{"id":"1.230178130","rc":[{"atb":[[8.4,0]],"id":52385883},{"atb":[[22,0]],"id":52385892}],"con":true,"img":false}]}
{"op":"mcm","clk":"11550126313","pt":1719494681880,"mc":[{"id":"1.230178130","rc":[{"atl":[[25,2.5],[29,8.57]],"id":52385889}],"con":true,"img":false}]}
{"op":"mcm","clk":"11550126335","pt":1719494682087,"mc":[{"id":"1.230178130","rc":[{"atl":[[16.5,22.22],[19,0]],"id":52385882}],"con":true,"img":false}]}
{"op":"mcm","clk":"11550126345","pt":1719494682192,"mc":[{"id":"1.230178130","rc":[{"atb":[[24,2.5]],"id":52385911},{"atl":[[29,3.57],[30,0]],"id":52385882},{"atb":[[13,0]],"id":52385884}],"con":true,"img":false}]}
{"op":"mcm","clk":"11550126357","pt":1719494682294,"mc":[{"id":"1.230178130","rc":[{"atb":[[38,2]],"id":52385911},{"atb":[[14,11]],"id":52385884}],"con":true,"img":false}]}
{"op":"mcm","clk":"11550126414","pt":1719494682869,"mc":[{"id":"1.230178130","rc":[{"atb":[[28,0]],"id":52385911}],"con":true,"img":false}]}
{"op":"mcm","clk":"11550126427","pt":1719494682976,"mc":[{"id":"1.230178130","rc":[{"atb":[[27,1.4]],"id":52385911}],"con":true,"img":false}]}
{"op":"mcm","clk":"11550126462","pt":1719494683412,"mc":[{"id":"1.230178130","rc":[{"atb":[[10.5,24.17]],"id":52385882}],"con":true,"img":false}]}
{"op":"mcm","clk":"11550126473","pt":1719494683490,"mc":[{"id":"1.230178130","rc":[{"atb":[[42,9.49]],"id":52385911},{"atb":[[7,0]],"id":52385882}],"con":true,"img":false}]}
{"op":"mcm","clk":"11550126495","pt":1719494683699,"mc":[{"id":"1.230178130","rc":[{"atb":[[25,0]],"id":52385911}],"con":true,"img":false}]}
{"op":"mcm","clk":"11550126526","pt":1719494684010,"mc":[{"id":"1.230178130","rc":[{"atl":[[21,2.5],[23,0],[25,5],[27,0]],"id":52385882}],"con":true,"img":false}]}
{"op":"mcm","clk":"11550126533","pt":1719494684111,"mc":[{"id":"1.230178130","rc":[{"atb":[[42,14.63]],"id":52385906}],"con":true,"img":false}]}
{"op":"mcm","clk":"11550126547","pt":1719494684170,"mc":[{"id":"1.230178130","rc":[{"atb":[[40,0]],"id":52385906},{"atb":[[2.74,57.47],[1.68,0]],"id":52385905},{"atb":[[3.1,47.62],[1.76,0]],"id":52385898}],"con":true,"img":false}]}
{"op":"mcm","clk":"11550126581","pt":1719494684374,"mc":[{"id":"1.230178130","rc":[{"atb":[[17,43]],"id":52385905}],"con":true,"img":false}]}
{"op":"mcm","clk":"11550126589","pt":1719494684478,"mc":[{"id":"1.230178130","rc":[{"atl":[[15.5,15.84]],"id":52385897}],"con":true,"img":false}]}
{"op":"mcm","clk":"11550126605","pt":1719494684579,"mc":[{"id":"1.230178130","rc":[{"atl":[[21,0]],"id":52385897},{"atb":[[15,0]],"id":52385905}],"con":true,"img":false}]}
{"op":"mcm","clk":"11550126622","pt":1719494684784,"mc":[{"id":"1.230178130","rc":[{"atb":[[42,0]],"id":52385906}],"con":true,"img":false}]}
{"op":"mcm","clk":"11550126639","pt":1719494684888,"mc":[{"id":"1.230178130","rc":[{"atb":[[40,15.38]],"id":52385906}],"con":true,"img":false}]}
{"op":"mcm","clk":"11550126654","pt":1719494685095,"mc":[{"id":"1.230178130","rc":[{"atb":[[18.5,29]],"id":52385899}],"con":true,"img":false}]}
{"op":"mcm","clk":"11550126671","pt":1719494685200,"mc":[{"id":"1.230178130","rc":[{"atb":[[17.5,0]],"id":52385899}],"con":true,"img":false}]}
{"op":"mcm","clk":"11550126682","pt":1719494685304,"mc":[{"id":"1.230178130","rc":[{"atb":[[3.6,0],[4.2,24]],"id":52385896},{"atb":[[5,0],[5.7,5.87]],"id":52385897},{"atb":[[4.6,24.74]],"id":52385903},{"atb":[[7,16.67],[8.4,0]],"id":52385904},{"atl":[[70,5],[75,2],[50,2.5],[55,0]],"id":52385904},{"atb":[[7.2,0],[9.2,12.2]],"id":52385899},{"atl":[[28,0]],"id":52385899}],"con":true,"img":false}]}
{"op":"mcm","clk":"11550126690","pt":1719494685405,"mc":[{"id":"1.230178130","rc":[{"atb":[[4,2],[4.8,2.5],[3.8,0],[4.4,5]],"id":52385896},{"atb":[[5.4,0]],"id":52385903},{"atl":[[34,18.18]],"id":52385899}],"con":true,"img":false}]}
{"op":"mcm","clk":"11550126791","pt":1719494686390,"mc":[{"id":"1.230178130","rc":[{"atl":[[18.5,23.88]],"id":52385889},{"atb":[[8.6,34.02]],"id":52385883}],"con":true,"img":false}]}
{"op":"mcm","clk":"11550126799","pt":1719494686498,"mc":[{"id":"1.230178130","rc":[{"atl":[[25,6.67],[29,5]],"id":52385889}],"con":true,"img":false}]}
{"op":"mcm","clk":"11550126808","pt":1719494686605,"mc":[{"id":"1.230178130","rc":[{"atl":[[22,0]],"id":52385889},{"atb":[[8.6,0]],"id":52385883}],"con":true,"img":false}]}
{"op":"mcm","clk":"11550126818","pt":1719494686702,"mc":[{"id":"1.230178130","rc":[{"atb":[[8.4,34]],"id":52385883}],"con":true,"img":false}]}
{"op":"mcm","clk":"11550126828","pt":1719494686806,"mc":[{"id":"1.230178130","rc":[{"atl":[[25,2.5],[29,8.57]],"id":52385889}],"con":true,"img":false}]}
{"op":"mcm","clk":"11550126839","pt":1719494686910,"mc":[{"id":"1.230178130","rc":[{"atb":[[9.6,5],[11,2.5]],"id":52385899}],"con":true,"img":false}]}
{"op":"mcm","clk":"11550126845","pt":1719494687010,"mc":[{"id":"1.230178130","rc":[{"atb":[[8.6,0],[9.4,0]],"id":52385899}],"con":true,"img":false}]}
{"op":"mcm","clk":"11550126879","pt":1719494687176,"mc":[{"id":"1.230178130","rc":[{"atl":[[12.5,0]],"id":52385883}],"con":true,"img":false}]}
{"op":"mcm","clk":"11550126898","pt":1719494687279,"mc":[{"id":"1.230178130","rc":[{"atb":[[29,21.43]],"id":52385912},{"atl":[[13,34]],"id":52385883}],"con":true,"img":false}]}
{"op":"mcm","clk":"11550126917","pt":1719494687485,"mc":[{"id":"1.230178130","rc":[{"atb":[[28,1.4]],"id":52385912}],"con":true,"img":false}]}
{"op":"mcm","clk":"11550127016","pt":1719494688107,"mc":[{"id":"1.230178130","rc":[{"atb":[[9,0]],"id":52385890}],"con":true,"img":false}]}
{"op":"mcm","clk":"11550127031","pt":1719494688211,"mc":[{"id":"1.230178130","rc":[{"atb":[[10,55.45]],"id":52385890}],"con":true,"img":false}]}
{"op":"mcm","clk":"11550127053","pt":1719494688386,"mc":[{"id":"1.230178130","rc":[{"atb":[[27,0]],"id":52385911}],"con":true,"img":false}]}
{"op":"mcm","clk":"11550127064","pt":1719494688489,"mc":[{"id":"1.230178130","rc":[{"atb":[[26,1.4]],"id":52385911}],"con":true,"img":false}]}
{"op":"mcm","clk":"11550127087","pt":1719494688804,"mc":[{"id":"1.230178130","rc":[{"atb":[[6.8,6.58]],"id":52385897}],"con":true,"img":false}]}
{"op":"mcm","clk":"11550127096","pt":1719494688903,"mc":[{"id":"1.230178130","rc":[{"atb":[[7,0]],"id":52385897},{"atb":[[23,15.89]],"id":52385891}],"con":true,"img":false}]}
{"op":"mcm","clk":"11550127113","pt":1719494689108,"mc":[{"id":"1.230178130","rc":[{"atl":[[130,0],[90,9.24],[95,0],[120,5]],"id":52385911}],"con":true,"img":false}]}
{"op":"mcm","clk":"11550127125","pt":1719494689213,"mc":[{"id":"1.230178130","rc":[{"atb":[[15,0]],"id":52385912},{"atb":[[28,0],[29,2.5]],"id":52385913},{"atb":[[20,2.5]],"id":52385906}],"con":true,"img":false}]}
{"op":"mcm","clk":"11550127135","pt":1719494689315,"mc":[{"id":"1.230178130","rc":[{"atb":[[19,0]],"id":52385906},{"atb":[[6.8,0]],"id":52385897},{"atb":[[2.74,0],[2.96,51.02]],"id":52385905},{"atb":[[3.1,0],[3.8,35.71]],"id":52385898}],"con":true,"img":false}]}
{"op":"mcm","clk":"11550127146","pt":1719494689370,"mc":[{"id":"1.230178130","rc":[{"atb":[[6.6,6.58]],"id":52385897},{"atl":[[55,11.11]],"id":52385892}],"con":true,"img":false}]}
{"op":"mcm","clk":"11550127154","pt":1719494689475,"mc":[{"id":"1.230178130","rc":[{"atl":[[65,2.49],[85,7]],"id":52385892}],"con":true,"img":false}]}
{"op":"mcm","clk":"11550127169","pt":1719494689582,"mc":[{"id":"1.230178130","rc":[{"atl":[[110,0]],"id":52385892}],"con":true,"img":false}]}
{"op":"mcm","clk":"11550127192","pt":1719494689782,"mc":[{"id":"1.230178130","rc":[{"atb":[[9,34]],"id":52385883}],"con":true,"img":false}]}
{"op":"mcm","clk":"11550127202","pt":1719494689895,"mc":[{"id":"1.230178130","rc":[{"atb":[[7,0]],"id":52385889}],"con":true,"img":false}]}
{"op":"mcm","clk":"11550127212","pt":1719494689994,"mc":[{"id":"1.230178130","rc":[{"atb":[[6.8,3.36]],"id":52385889},{"atb":[[8.4,0]],"id":52385883}],"con":true,"img":false}]}
{"op":"mcm","clk":"11550127232","pt":1719494690198,"mc":[{"id":"1.230178130","rc":[{"atb":[[23,0.89]],"id":52385891},{"atl":[[44,5],[50,2.04]],"id":52385903},{"atb":[[4.1,32.26],[3.8,0]],"id":52385898}],"con":true,"img":false}]}
{"op":"mcm","clk":"11550127241","pt":1719494690306,"mc":[{"id":"1.230178130","rc":[{"atb":[[9.6,11.63],[22,15],[12,0]],"id":52385891},{"atl":[[40,0]],"id":52385904},{"atb":[[3.25,44.44],[2.96,0]],"id":52385905}],"con":true,"img":false}]}
{"op":"mcm","clk":"11550127251","pt":1719494690402,"mc":[{"id":"1.230178130","rc":[{"atl":[[65,9.38],[75,0],[80,2]],"id":52385904}],"con":true,"img":false}]}
{"op":"mcm","clk":"11550127316","pt":1719494691079,"mc":[{"id":"1.230178130","rc":[{"atb":[[15,1.37]],"id":52385903},{"atb":[[10,32.62]],"id":52385898}],"con":true,"img":false}]}
{"op":"mcm","clk":"11550127328","pt":1719494691184,"mc":[{"id":"1.230178130","rc":[{"atb":[[17,11]],"id":52385903},{"atb":[[9,12]],"id":52385898}],"con":true,"img":false}]}
{"op":"mcm","clk":"11550127337","pt":1719494691280,"mc":[{"id":"1.230178130","rc":[{"atb":[[18.5,0]],"id":52385899}],"con":true,"img":false}]}
{"op":"mcm","clk":"11550127352","pt":1719494691392,"mc":[{"id":"1.230178130","rc":[{"atb":[[6.8,0]],"id":52385889},{"atb":[[16,46]],"id":52385899}],"con":true,"img":false}]}
{"op":"mcm","clk":"11550127360","pt":1719494691490,"mc":[{"id":"1.230178130","rc":[{"atb":[[6.6,3.36]],"id":52385889}],"con":true,"img":false}]}
{"op":"mcm","clk":"11550127526","pt":1719494693099,"mc":[{"id":"1.230178130","rc":[{"atb":[[38,0]],"id":52385911}],"con":true,"img":false}]}
{"op":"mcm","clk":"11550127580","pt":1719494693614,"mc":[{"id":"1.230178130","rc":[{"atl":[[30,15]],"id":52385899}],"con":true,"img":false}]}
{"op":"mcm","clk":"11550127602","pt":1719494693819,"mc":[{"id":"1.230178130","rc":[{"atl":[[34,0]],"id":52385899}],"con":true,"img":false}]}
{"op":"mcm","clk":"11550127621","pt":1719494693975,"mc":[{"id":"1.230178130","rc":[{"atl":[[65,0],[75,5],[85,2],[55,13.61]],"id":52385892}],"con":true,"img":false}]}
{"op":"mcm","clk":"11550127657","pt":1719494694288,"mc":[{"id":"1.230178130","rc":[{"atb":[[8.8,0]],"id":52385891}],"con":true,"img":false}]}
{"op":"mcm","clk":"11550127668","pt":1719494694392,"mc":[{"id":"1.230178130","rc":[{"atb":[[9.6,16.37]],"id":52385891}],"con":true,"img":false}]}
{"op":"mcm","clk":"11550127687","pt":1719494694601,"mc":[{"id":"1.230178130","rc":[{"atl":[[17.5,23.88]],"id":52385889}],"con":true,"img":false}]}
{"op":"mcm","clk":"11550127696","pt":1719494694700,"mc":[{"id":"1.230178130","rc":[{"atl":[[18.5,0],[25,6.67]],"id":52385889}],"con":true,"img":false}]}
{"op":"mcm","clk":"11550127702","pt":1719494694807,"mc":[{"id":"1.230178130","rc":[{"atl":[[29,5]],"id":52385889}],"con":true,"img":false}]}
{"op":"mcm","clk":"11550127748","pt":1719494695319,"mc":[{"id":"1.230178130","rc":[{"atl":[[16.5,0],[17,2.5],[14.5,0]],"id":52385883},{"atl":[[14.5,22.28]],"id":52385897},{"atb":[[4.6,27.78]],"id":52385898}],"con":true,"img":false}]}
{"op":"mcm","clk":"11550127756","pt":1719494695420,"mc":[{"id":"1.230178130","rc":[{"atb":[[28,0]],"id":52385892},{"atb":[[4.1,0]],"id":52385898}],"con":true,"img":false}]}
{"op":"mcm","clk":"11550127767","pt":1719494695522,"mc":[{"id":"1.230178130","rc":[{"atl":[[15.5,0]],"id":52385897},{"atb":[[21,20]],"id":52385892}],"con":true,"img":false}]}
{"op":"mcm","clk":"11550127790","pt":1719494695680,"mc":[{"id":"1.230178130","rc":[{"atb":[[10.5,4.03]],"id":52385892}],"con":true,"img":false}]}
{"op":"mcm","clk":"11550127839","pt":1719494696201,"mc":[{"id":"1.230178130","rc":[{"atb":[[11.5,46.7]],"id":52385882}],"con":true,"img":false}]}
{"op":"mcm","clk":"11550127855","pt":1719494696412,"mc":[{"id":"1.230178130","rc":[{"atb":[[10.5,1.95]],"id":52385882},{"atb":[[6.6,0]],"id":52385897},{"atb":[[9.8,0]],"id":52385898}],"con":true,"img":false}]}
{"op":"mcm","clk":"11550127864","pt":1719494696508,"mc":[{"id":"1.230178130","rc":[{"atb":[[6.4,6.58]],"id":52385897},{"atb":[[10.5,4.3]],"id":52385898}],"con":true,"img":false}]}
{"op":"mcm","clk":"11550127872","pt":1719494696612,"mc":[{"id":"1.230178130","rc":[{"atb":[[11,32.62]],"id":52385898}],"con":true,"img":false}]}
{"op":"mcm","clk":"11550127888","pt":1719494696817,"mc":[{"id":"1.230178130","rc":[{"atb":[[6.6,0]],"id":52385889},{"atb":[[9.6,11.63]],"id":52385891},{"atb":[[10,0]],"id":52385898}],"con":true,"img":false}]}
{"op":"mcm","clk":"11550127900","pt":1719494696918,"mc":[{"id":"1.230178130","rc":[{"atb":[[6.4,3.36]],"id":52385889},{"atb":[[9.4,4.74]],"id":52385891}],"con":true,"img":false}]}
{"op":"mcm","clk":"11550127919","pt":1719494697076,"mc":[{"id":"1.230178130","rc":[{"atb":[[7.2,0]],"id":52385882}],"con":true,"img":false}]}
{"op":"mcm","clk":"11550127936","pt":1719494697182,"mc":[{"id":"1.230178130","rc":[{"atb":[[9,33]],"id":52385883},{"trd":[[9,2]],"ltp":9.0,"tv":2.0,"id":52385883}],"con":true,"img":false}]}
{"op":"mcm","clk":"11550127940","pt":1719494697285,"mc":[{"id":"1.230178130","rc":[{"atl":[[12.5,1]],"id":52385883}],"con":true,"img":false}]}
{"op":"mcm","clk":"11550127956","pt":1719494697406,"mc":[{"id":"1.230178130","rc":[{"atl":[[12.5,31.82]],"id":52385883}],"con":true,"img":false}]}
{"op":"mcm","clk":"11550127973","pt":1719494697924,"mc":[{"id":"1.230178130","rc":[{"atl":[[13,0]],"id":52385883}],"con":true,"img":false}]}
{"op":"mcm","clk":"11550128033","pt":1719494698312,"mc":[{"id":"1.230178130","rc":[{"atl":[[29,8.57]],"id":52385889}],"con":true,"img":false}]}
{"op":"mcm","clk":"11550128047","pt":1719494698417,"mc":[{"id":"1.230178130","rc":[{"atl":[[25,2.5]],"id":52385889}],"con":true,"img":false}]}
{"op":"mcm","clk":"11550128054","pt":1719494698517,"mc":[{"id":"1.230178130","rc":[{"atl":[[40,15]],"id":52385904}],"con":true,"img":false}]}
{"op":"mcm","clk":"11550128079","pt":1719494698679,"mc":[{"id":"1.230178130","rc":[{"atl":[[65,0]],"id":52385904}],"con":true,"img":false}]}
{"op":"mcm","clk":"11550128087","pt":1719494698783,"mc":[{"id":"1.230178130","rc":[{"atb":[[8.6,0],[9.8,2.5],[9.4,0]],"id":52385903},{"atl":[[34,2.5],[42,5]],"id":52385899}],"con":true,"img":false}]}
{"op":"mcm","clk":"11550128100","pt":1719494698882,"mc":[{"id":"1.230178130","rc":[{"atl":[[36,0],[44,0]],"id":52385899}],"con":true,"img":false}]}
{"op":"mcm","clk":"11550128121","pt":1719494699090,"mc":[{"id":"1.230178130","rc":[{"atl":[[85,7.14]],"id":52385911},{"atb":[[10,43.45]],"id":52385890}],"con":true,"img":false}]}
{"op":"mcm","clk":"11550128136","pt":1719494699193,"mc":[{"id":"1.230178130","rc":[{"atb":[[25,0]],"id":52385910},{"atb":[[9,12]],"id":52385890}],"con":true,"img":false}]}
{"op":"mcm","clk":"11550128143","pt":1719494699294,"mc":[{"id":"1.230178130","rc":[{"atb":[[28,1.58]],"id":52385910},{"atl":[[90,2.5]],"id":52385911}],"con":true,"img":false}]}
{"op":"mcm","clk":"11550128160","pt":1719494699409,"mc":[{"id":"1.230178130","rc":[{"atb":[[28,19.58]],"id":52385910}],"con":true,"img":false}]}
{"op":"mcm","clk":"11550128178","pt":1719494699609,"mc":[{"id":"1.230178130","rc":[{"atb":[[27,0]],"id":52385910}],"con":true,"img":false}]}
{"op":"mcm","clk":"11550128202","pt":1719494699915,"mc":[{"id":"1.230178130","rc":[{"atb":[[14.5,0]],"id":52385905}],"con":true,"img":false}]}
{"op":"mcm","clk":"11550128214","pt":1719494700022,"mc":[{"id":"1.230178130","rc":[{"atl":[[22,2.5],[25,0],[26,5],[29,3.57]],"id":52385889},{"atb":[[17.5,2.8]],"id":52385905}],"con":true,"img":false}]}
{"op":"mcm","clk":"11550128225","pt":1719494700124,"mc":[{"id":"1.230178130","rc":[{"atl":[[25,4.17],[29,0]],"id":52385889},{"atb":[[17.5,22.8]],"id":52385905}],"con":true,"img":false}]}
{"op":"mcm","clk":"11550128252","pt":1719494700288,"mc":[{"id":"1.230178130","rc":[{"atb":[[17,11]],"id":52385905}],"con":true,"img":false}]}
{"op":"mcm","clk":"11550128303","pt":1719494700807,"mc":[{"id":"1.230178130","rc":[{"atb":[[9,39.18]],"id":52385890}],"con":true,"img":false}]}
{"op":"mcm","clk":"11550128323","pt":1719494701010,"mc":[{"id":"1.230178130","rc":[{"atb":[[9,12]],"id":52385890}],"con":true,"img":false}]}
{"op":"mcm","clk":"11550128393","pt":1719494701585,"mc":[{"id":"1.230178130","rc":[{"atl":[[28,10]],"id":52385899}],"con":true,"img":false}]}
{"op":"mcm","clk":"11550128412","pt":1719494701794,"mc":[{"id":"1.230178130","rc":[{"atl":[[15.5,41.38]],"id":52385890},{"atl":[[30,0]],"id":52385899}],"con":true,"img":false}]}
{"op":"mcm","clk":"11550128434","pt":1719494702009,"mc":[{"id":"1.230178130","rc":[{"atl":[[16.5,0],[22,4.76],[25,5]],"id":52385890}],"con":true,"img":false}]}
{"op":"mcm","clk":"11550128467","pt":1719494702317,"mc":[{"id":"1.230178130","rc":[{"atb":[[3.6,38.46],[3.25,0]],"id":52385905}],"con":true,"img":false}]}
{"op":"mcm","clk":"11550128652","pt":1719494704290,"mc":[{"id":"1.230178130","rc":[{"atb":[[8.8,0]],"id":52385884},{"atb":[[7.2,41.36]],"id":52385896},{"trd":[[7.2,2.49]],"ltp":7.2,"tv":2.49,"id":52385896}],"con":true,"img":false}]}
{"op":"mcm","clk":"11550128720","pt":1719494704911,"mc":[{"id":"1.230178130","rc":[{"atb":[[6.8,19.74],[6.6,0]],"id":52385882}],"con":true,"img":false}]}
{"op":"mcm","clk":"11550128778","pt":1719494705426,"mc":[{"id":"1.230178130","rc":[{"atb":[[10.5,0]],"id":52385898}],"con":true,"img":false}]}
{"op":"mcm","clk":"11550128792","pt":1719494705533,"mc":[{"id":"1.230178130","rc":[{"atb":[[11.5,0]],"id":52385882},{"atb":[[25,15]],"id":52385885},{"atl":[[40,15],[46,2.5],[48,0],[60,5]],"id":52385885},{"atb":[[7.2,4.86]],"id":52385896},{"atb":[[28,20]],"id":52385892},{"atb":[[5.1,24.39],[4.6,0]],"id":52385903},{"atb":[[3.6,0],[3.9,34.48]],"id":52385905},{"atb":[[4.6,0],[11,0],[5.2,23.81]],"id":52385898},{"atl":[[36,5],[22,28.57],[29,2.5],[30,0]],"id":52385898}],"con":true,"img":false}]}
{"op":"mcm","clk":"11550128804","pt":1719494705634,"mc":[{"id":"1.230178130","rc":[{"atb":[[11,15]],"id":52385882},{"atl":[[40,0]],"id":52385885},{"atb":[[7,45.74]],"id":52385896},{"atb":[[10.5,29]],"id":52385898}],"con":true,"img":false}]}
{"op":"mcm","clk":"11550128814","pt":1719494705690,"mc":[{"id":"1.230178130","rc":[{"atb":[[23,0]],"id":52385885},{"atl":[[42,14.63]],"id":52385885},{"atb":[[21,0]],"id":52385892},{"atl":[[24,0]],"id":52385898}],"con":true,"img":false}]}
{"op":"mcm","clk":"11550128841","pt":1719494706006,"mc":[{"id":"1.230178130","rc":[{"atl":[[42,0]],"id":52385885}],"con":true,"img":false}]}
{"op":"mcm","clk":"11550128853","pt":1719494706104,"mc":[{"id":"1.230178130","rc":[{"atb":[[8,5.51]],"id":52385882},{"atl":[[44,13.95]],"id":52385885}],"con":true,"img":false}]}
{"op":"mcm","clk":"11550128878","pt":1719494706422,"mc":[{"id":"1.230178130","rc":[{"atb":[[28,0]],"id":52385912}],"con":true,"img":false}]}
{"op":"mcm","clk":"11550128889","pt":1719494706516,"mc":[{"id":"1.230178130","rc":[{"atb":[[30,1.4]],"id":52385912}],"con":true,"img":false}]}
{"op":"mcm","clk":"11550128899","pt":1719494706621,"mc":[{"id":"1.230178130","rc":[{"atb":[[13,13.33],[15,2.5]],"id":52385912}],"con":true,"img":false}]}
{"op":"mcm","clk":"11550128909","pt":1719494706724,"mc":[{"id":"1.230178130","rc":[{"atb":[[30,22.09]],"id":52385912}],"con":true,"img":false}]}
{"op":"mcm","clk":"11550128919","pt":1719494706827,"mc":[{"id":"1.230178130","rc":[{"atl":[[42,3.84]],"id":52385885}],"con":true,"img":false}]}
{"op":"mcm","clk":"11550128931","pt":1719494706931,"mc":[{"id":"1.230178130","rc":[{"atb":[[29,0]],"id":52385912},{"atb":[[8,0]],"id":52385882},{"atl":[[16.5,2.5],[17,0],[18.5,10.71]],"id":52385883}],"con":true,"img":false}]}
{"op":"mcm","clk":"11550128941","pt":1719494707041,"mc":[{"id":"1.230178130","rc":[{"atb":[[7.8,5.51]],"id":52385882},{"atl":[[42,0]],"id":52385885},{"atb":[[9.6,21.25]],"id":52385898}],"con":true,"img":false}]}
{"op":"mcm","clk":"11550128957","pt":1719494707201,"mc":[{"id":"1.230178130","rc":[{"atb":[[9.6,0]],"id":52385898}],"con":true,"img":false}]}
{"op":"mcm","clk":"11550129089","pt":1719494708596,"mc":[{"id":"1.230178130","rc":[{"atb":[[23,19.89]],"id":52385891}],"con":true,"img":false}]}
{"op":"mcm","clk":"11550129106","pt":1719494708802,"mc":[{"id":"1.230178130","rc":[{"atb":[[22,0]],"id":52385891}],"con":true,"img":false}]}
{"op":"mcm","clk":"11550129117","pt":1719494708910,"mc":[{"id":"1.230178130","rc":[{"atb":[[7.8,0]],"id":52385882}],"con":true,"img":false}]}
{"op":"mcm","clk":"11550129125","pt":1719494709013,"mc":[{"id":"1.230178130","rc":[{"atb":[[7.6,5.51]],"id":52385882}],"con":true,"img":false}]}
{"op":"mcm","clk":"11550129150","pt":1719494709320,"mc":[{"id":"1.230178130","rc":[{"atb":[[7.6,0]],"id":52385882},{"atb":[[10.5,4.07]],"id":52385890}],"con":true,"img":false}]}
{"op":"mcm","clk":"11550129165","pt":1719494709421,"mc":[{"id":"1.230178130","rc":[{"atb":[[7.4,5.51]],"id":52385882}],"con":true,"img":false}]}
{"op":"mcm","clk":"11550129266","pt":1719494710411,"mc":[{"id":"1.230178130","rc":[{"atb":[[26,0]],"id":52385911}],"con":true,"img":false}]}
{"op":"mcm","clk":"11550129276","pt":1719494710508,"mc":[{"id":"1.230178130","rc":[{"atb":[[27,1.4]],"id":52385911}],"con":true,"img":false}]}
{"op":"mcm","clk":"11550129408","pt":1719494711699,"mc":[{"id":"1.230178130","rc":[{"atb":[[9,0]],"id":52385883},{"atl":[[44,16.45],[55,5]],"id":52385885},{"atb":[[10.5,37.59]],"id":52385890}],"con":true,"img":false}]}
{"op":"mcm","clk":"11550129420","pt":1719494711852,"mc":[{"id":"1.230178130","rc":[{"atb":[[27,0]],"id":52385911},{"atb":[[8,42.82]],"id":52385883},{"atb":[[25,0]],"id":52385885},{"atl":[[46,0],[60,0]],"id":52385885},{"atb":[[10,2.05]],"id":52385890}],"con":true,"img":false}]}
{"op":"mcm","clk":"11550129429","pt":1719494711906,"mc":[{"id":"1.230178130","rc":[{"atb":[[26,1.4]],"id":52385911},{"atb":[[20,16.02]],"id":52385885}],"con":true,"img":false}]}
{"op":"mcm","clk":"11550129495","pt":1719494712534,"mc":[{"id":"1.230178130","rc":[{"atb":[[13,3.23]],"id":52385885}],"con":true,"img":false}]}
{"op":"mcm","clk":"11550129534","pt":1719494712840,"mc":[{"id":"1.230178130","rc":[{"atb":[[7.2,6.11]],"id":52385896}],"con":true,"img":false}]}
{"op":"mcm","clk":"11550129602","pt":1719494713310,"mc":[{"id":"1.230178130","rc":[{"atl":[[65,5],[34,0],[70,2],[48,2.5],[50,0]],"id":52385891},{"atb":[[29,20]],"id":52385892}],"con":true,"img":false}]}
{"op":"mcm","clk":"11550129619","pt":1719494713411,"mc":[{"id":"1.230178130","rc":[{"atl":[[65,7],[70,0]],"id":52385891}],"con":true,"img":false}]}
{"op":"mcm","clk":"11550129631","pt":1719494713511,"mc":[{"id":"1.230178130","rc":[{"atl":[[60,10]],"id":52385891},{"atb":[[28,0]],"id":52385892}],"con":true,"img":false}]}
{"op":"mcm","clk":"11550129645","pt":1719494713614,"mc":[{"id":"1.230178130","rc":[{"atb":[[23,0.89]],"id":52385891},{"atl":[[65,5],[70,2]],"id":52385891}],"con":true,"img":false}]}
{"op":"mcm","clk":"11550129676","pt":1719494713926,"mc":[{"id":"1.230178130","rc":[{"atb":[[13,0]],"id":52385885}],"con":true,"img":false}]}
{"op":"mcm","clk":"11550129682","pt":1719494714031,"mc":[{"id":"1.230178130","rc":[{"atb":[[23,16.46],[12.5,5.73]],"id":52385885}],"con":true,"img":false}]}
{"op":"mcm","clk":"11550129696","pt":1719494714132,"mc":[{"id":"1.230178130","rc":[{"atb":[[20,1.02]],"id":52385885}],"con":true,"img":false}]}
{"op":"mcm","clk":"11550129723","pt":1719494714338,"mc":[{"id":"1.230178130","rc":[{"atb":[[23,15.89]],"id":52385891}],"con":true,"img":false}]}
{"op":"mcm","clk":"11550129798","pt":1719494715120,"mc":[{"id":"1.230178130","rc":[{"atb":[[9,0]],"id":52385890},{"atb":[[9,0]],"id":52385898}],"con":true,"img":false}]}
{"op":"mcm","clk":"11550129810","pt":1719494715227,"mc":[{"id":"1.230178130","rc":[{"atb":[[10,14.05]],"id":52385890},{"atb":[[10,12]],"id":52385898}],"con":true,"img":false}]}
{"op":"mcm","clk":"11550129822","pt":1719494715328,"mc":[{"id":"1.230178130","rc":[{"atb":[[8.2,5.39]],"id":52385883}],"con":true,"img":false}]}
{"op":"mcm","clk":"11550129867","pt":1719494715844,"mc":[{"id":"1.230178130","rc":[{"atb":[[23,0.89]],"id":52385891}],"con":true,"img":false}]}
{"op":"mcm","clk":"11550129881","pt":1719494715949,"mc":[{"id":"1.230178130","rc":[{"atb":[[22,15]],"id":52385891}],"con":true,"img":false}]}
{"op":"mcm","clk":"11550129953","pt":1719494716522,"mc":[{"id":"1.230178130","rc":[{"atb":[[23,15.89]],"id":52385891}],"con":true,"img":false}]}
{"op":"mcm","clk":"11550129980","pt":1719494716732,"mc":[{"id":"1.230178130","rc":[{"atb":[[11,0]],"id":52385882},{"atl":[[26,4]],"id":52385882},{"atl":[[26,24]],"id":52385884},{"atb":[[23,0]],"id":52385885},{"atb":[[7.2,42.61]],"id":52385896},{"atb":[[5.5,0],[6,2.5],[5.9,0]],"id":52385890},{"atb":[[22,0],[9.4,0]],"id":52385891},{"atb":[[5.7,21.28]],"id":52385903},{"atl":[[46,2.22]],"id":52385903},{"atb":[[4.3,17.3],[5.2,0]],"id":52385898},{"atl":[[22,0]],"id":52385898},{"atb":[[19.5,15]],"id":52385899},{"atl":[[28,0]],"id":52385899}],"con":true,"img":false}]}
{"op":"mcm","clk":"11550129996","pt":1719494716834,"mc":[{"id":"1.230178130","rc":[{"atb":[[10.5,22.99]],"id":52385882},{"atl":[[29,0]],"id":52385882},{"atl":[[32,0]],"id":52385884},{"atb":[[20,22.48],[12.5,2.5]],"id":52385885},{"atb":[[7,12]],"id":52385896},{"atl":[[14.5,0]],"id":52385897},{"atb":[[11.5,4.74]],"id":52385891},{"atb":[[5.1,0]],"id":52385903},{"atl":[[50,0]],"id":52385903},{"atl":[[28,22.22]],"id":52385898},{"atb":[[16,12]],"id":52385899},{"atl":[[32,15]],"id":52385899}],"con":true,"img":false}]}
{"op":"mcm","clk":"11550130006","pt":1719494716936,"mc":[{"id":"1.230178130","rc":[{"atb":[[12,3.23]],"id":52385885},{"atl":[[19.5,22.28],[26,4]],"id":52385897}],"con":true,"img":false}]}
{"op":"mcm","clk":"11550130013","pt":1719494717044,"mc":[{"id":"1.230178130","rc":[{"atl":[[23,0]],"id":52385897}],"con":true,"img":false}]}
{"op":"mcm","clk":"11550130030","pt":1719494717146,"mc":[{"id":"1.230178130","rc":[{"atl":[[42,14.63]],"id":52385885}],"con":true,"img":false}]}
{"op":"mcm","clk":"11550130056","pt":1719494717347,"mc":[{"id":"1.230178130","rc":[{"atl":[[44,2.5]],"id":52385885}],"con":true,"img":false}]}
{"op":"mcm","clk":"11550130065","pt":1719494717453,"mc":[{"id":"1.230178130","rc":[{"atb":[[6.4,0]],"id":52385889},{"atb":[[6.4,0]],"id":52385897}],"con":true,"img":false}]}
{"op":"mcm","clk":"11550130081","pt":1719494717508,"mc":[{"id":"1.230178130","rc":[{"atb":[[7.6,3.36]],"id":52385889},{"atb":[[7.2,6.58]],"id":52385897}],"con":true,"img":false}]}
{"op":"mcm","clk":"11550130091","pt":1719494717611,"mc":[{"id":"1.230178130","rc":[{"atl":[[13,2]],"id":52385889}],"con":true,"img":false}]}
{"op":"mcm","clk":"11550130108","pt":1719494717716,"mc":[{"id":"1.230178130","rc":[{"atl":[[19,5.56],[25,0]],"id":52385889}],"con":true,"img":false}]}
{"op":"mcm","clk":"11550130130","pt":1719494717922,"mc":[{"id":"1.230178130","rc":[{"atb":[[17.5,20]],"id":52385905}],"con":true,"img":false}]}
{"op":"mcm","clk":"11550130144","pt":1719494718032,"mc":[{"id":"1.230178130","rc":[{"atb":[[28,18]],"id":52385910},{"atb":[[14,0]],"id":52385884},{"atb":[[18,2.8]],"id":52385905}],"con":true,"img":false}]}
{"op":"mcm","clk":"11550130156","pt":1719494718130,"mc":[{"id":"1.230178130","rc":[{"atb":[[29,1.58]],"id":52385910},{"atb":[[7.8,2.5],[7,5]],"id":52385884},{"atb":[[18,34.8]],"id":52385905},{"atl":[[50,3]],"id":52385899}],"con":true,"img":false}]}
{"op":"mcm","clk":"11550130169","pt":1719494718240,"mc":[{"id":"1.230178130","rc":[{"atb":[[28,0],[29,19.58]],"id":52385910},{"atb":[[17.5,0]],"id":52385905},{"atl":[[50,0]],"id":52385899}],"con":true,"img":false}]}
{"op":"mcm","clk":"11550130289","pt":1719494719531,"mc":[{"id":"1.230178130","rc":[{"atb":[[8.2,37.61]],"id":52385883}],"con":true,"img":false}]}
{"op":"mcm","clk":"11550130307","pt":1719494719736,"mc":[{"id":"1.230178130","rc":[{"atb":[[8,12]],"id":52385883}],"con":true,"img":false}]}
{"op":"mcm","clk":"11550130429","pt":1719494720726,"mc":[{"id":"1.230178130","rc":[{"atb":[[22,16.46]],"id":52385885}],"con":true,"img":false}]}
{"op":"mcm","clk":"11550130453","pt":1719494720929,"mc":[{"id":"1.230178130","rc":[{"atb":[[7.4,0]],"id":52385882},{"atb":[[20,1.02]],"id":52385885},{"atb":[[10.5,0]],"id":52385892}],"con":true,"img":false}]}
{"op":"mcm","clk":"11550130466","pt":1719494721032,"mc":[{"id":"1.230178130","rc":[{"atb":[[7.2,5.51]],"id":52385882}],"con":true,"img":false}]}
