{"op":"mcm","clk":"11536832983","pt":1719431775519,"mc":[{"id":"1.230180112","marketDefinition":{"bspMarket":true,"turnInPlayEnabled":false,"persistenceEnabled":false,"marketBaseRate":5.0,"eventId":"33376437","eventTypeId":"4339","numberOfWinners":1,"bettingType":"ODDS","marketType":"WIN","marketTime":"2024-06-27T13:33:00.000Z","suspendTime":"2024-06-27T13:33:00.000Z","bspReconciled":false,"complete":true,"inPlay":false,"crossMatching":false,"runnersVoidable":false,"numberOfActiveRunners":6,"betDelay":0,"status":"OPEN","runners":[{"status":"ACTIVE","sortPriority":1,"id":68870841,"name":"1. Milton Daisy"},{"status":"ACTIVE","sortPriority":2,"id":58974183,"name":"2. Ballymac Diverse"},{"status":"ACTIVE","sortPriority":3,"id":58462129,"name":"3. Rapido Junior"},{"status":"ACTIVE","sortPriority":4,"id":50281437,"name":"4. Browns Girl"},{"status":"ACTIVE","sortPriority":5,"id":68579508,"name":"5. Ivy Hill Willow"},{"status":"ACTIVE","sortPriority":6,"id":68169358,"name":"6. Spiridon Zelus"}],"regulators":["MR_INT"],"venue":"Towcester","countryCode":"GB","discountAllowed":false,"timezone":"Europe/London","openDate":"2024-06-27T13:33:00.000Z","version":5994767126,"name":"A2 500m","eventName":"Towcester 27th Jun"},"rc":[],"con":true,"img":false}]}
{"op":"mcm","clk":"11536833134","pt":1719431777518,"mc":[{"id":"1.230180112","marketDefinition":{"bspMarket":true,"turnInPlayEnabled":false,"persistenceEnabled":false,"marketBaseRate":5.0,"eventId":"33376437","eventTypeId":"4339","numberOfWinners":1,"bettingType":"ODDS","marketType":"WIN","marketTime":"2024-06-27T13:33:00.000Z","suspendTime":"2024-06-27T13:33:00.000Z","bspReconciled":false,"complete":true,"inPlay":false,"crossMatching":false,"runnersVoidable":false,"numberOfActiveRunners":6,"betDelay":0,"status":"OPEN","runners":[{"status":"ACTIVE","sortPriority":1,"id":68870841,"name":"1. Milton Daisy"},{"status":"ACTIVE","sortPriority":2,"id":58974183,"name":"2. Ballymac Diverse"},{"status":"ACTIVE","sortPriority":3,"id":58462129,"name":"3. Rapido Junior"},{"status":"ACTIVE","sortPriority":4,"id":50281437,"name":"4. Browns Girl"},{"status":"ACTIVE","sortPriority":5,"id":68579508,"name":"5. Ivy Hill Willow"},{"status":"ACTIVE","sortPriority":6,"id":68169358,"name":"6. Spiridon Zelus"}],"regulators":["MR_INT"],"venue":"Towcester","countryCode":"GB","discountAllowed":true,"timezone":"Europe/London","openDate":"2024-06-27T13:33:00.000Z","version":5994767126,"name":"A2 500m","eventName":"Towcester 27th Jun"},"rc":[],"con":true,"img":false}]}
{"op":"mcm","clk":"11537083967","pt":1719435434906,"mc":[{"id":"1.230180112","rc":[{"atb":[[1.02,25.92]],"id":58974183},{"atl":[[990,0.84]],"id":58974183},{"spn":495.51,"spf":"NaN","id":58974183},{"atb":[[1.03,17.28]],"id":58462129},{"atl":[[990,0.84]],"id":58462129},{"spn":495.51,"spf":"NaN","id":58462129},{"atb":[[1.02,25.92]],"id":68169358},{"atl":[[1000,0.84]],"id":68169358},{"spn":500.51,"spf":"NaN","id":68169358},{"atb":[[1.03,17.28]],"id":68870841},{"atl":[[990,0.84]],"id":68870841},{"spn":495.51,"spf":"NaN","id":68870841},{"atb":[[1.03,17.28]],"id":68579508},{"atl":[[990,0.84]],"id":68579508},{"spn":495.51,"spf":"NaN","id":68579508},{"atb":[[1.01,51.84]],"id":50281437},{"atl":[[990,0.84]],"id":50281437},{"spn":495.5,"spf":"NaN","id":50281437}],"con":true,"img":false}]}
{"op":"mcm","clk":"11537233753","pt":1719437882662,"mc":[{"id":"1.230180112","marketDefinition":{"bspMarket":true,"turnInPlayEnabled":false,"persistenceEnabled":false,"marketBaseRate":5.0,"eventId":"33376437","eventTypeId":"4339","numberOfWinners":1,"bettingType":"ODDS","marketType":"WIN","marketTime":"2024-06-27T13:33:00.000Z","suspendTime":"2024-06-27T13:33:00.000Z","bspReconciled":false,"complete":true,"inPlay":false,"crossMatching":false,"runnersVoidable":false,"numberOfActiveRunners":6,"betDelay":0,"status":"OPEN","runners":[{"status":"ACTIVE","sortPriority":1,"id":68870841,"name":"1. Milton Daisy"},{"status":"ACTIVE","sortPriority":2,"id":58974183,"name":"2. Ballymac Diverse"},{"status":"ACTIVE","sortPriority":3,"id":58462129,"name":"3. Rapido Junior"},{"status":"ACTIVE","sortPriority":4,"id":50281437,"name":"4. Browns Girl"},{"status":"ACTIVE","sortPriority":5,"id":68579508,"name":"5. Ivy Hill Willow"},{"status":"ACTIVE","sortPriority":6,"id":68169358,"name":"6. Spiridon Zelus"}],"regulators":["MR_INT"],"venue":"Towcester","countryCode":"GB","discountAllowed":true,"timezone":"Europe/London","openDate":"2024-06-27T13:33:00.000Z","version":5994767126,"name":"A2 500m","eventName":"Towcester 27th Jun"},"rc":[{"atb":[[1.02,25.92]],"id":58974183},{"atl":[[990,0.84]],"id":58974183},{"spn":495.51,"spf":"NaN","id":58974183},{"atb":[[1.03,17.28]],"id":58462129},{"atl":[[990,0.84]],"id":58462129},{"spn":495.51,"spf":"NaN","id":58462129},{"atb":[[1.02,25.92]],"id":68169358},{"atl":[[1000,0.84]],"id":68169358},{"spn":500.51,"spf":"NaN","id":68169358},{"atb":[[1.03,17.28]],"id":68870841},{"atl":[[990,0.84]],"id":68870841},{"spn":495.51,"spf":"NaN","id":68870841},{"atb":[[1.03,17.28]],"id":68579508},{"atl":[[990,0.84]],"id":68579508},{"spn":495.51,"spf":"NaN","id":68579508},{"atb":[[1.01,51.85]],"id":50281437},{"atl":[[990,0.84]],"id":50281437},{"spn":495.5,"spf":"NaN","id":50281437}],"con":true,"img":true}]}
{"op":"mcm","clk":"11537302515","pt":1719439038653,"mc":[{"id":"1.230180112","rc":[{"atb":[[1.02,25.92]],"id":58974183},{"atl":[[990,0.23]],"id":58974183},{"atb":[[1.03,17.28]],"id":58462129},{"atl":[[990,0.23]],"id":58462129},{"atb":[[1.02,25.92]],"id":68169358},{"atl":[[1000,0.23]],"id":68169358},{"atb":[[1.03,17.28]],"id":68870841},{"atl":[[990,0.23]],"id":68870841},{"atb":[[1.03,17.28]],"id":68579508},{"atl":[[990,0.23]],"id":68579508},{"atb":[[1.01,51.85]],"id":50281437},{"atl":[[990,0.23]],"id":50281437}],"con":true,"img":false}]}
{"op":"mcm","clk":"11537574906","pt":1719443282712,"mc":[{"id":"1.230180112","marketDefinition":{"bspMarket":true,"turnInPlayEnabled":false,"persistenceEnabled":false,"marketBaseRate":5.0,"eventId":"33376437","eventTypeId":"4339","numberOfWinners":1,"bettingType":"ODDS","marketType":"WIN","marketTime":"2024-06-27T13:33:00.000Z","suspendTime":"2024-06-27T13:33:00.000Z","bspReconciled":false,"complete":true,"inPlay":false,"crossMatching":false,"runnersVoidable":false,"numberOfActiveRunners":6,"betDelay":0,"status":"OPEN","runners":[{"status":"ACTIVE","sortPriority":1,"id":68870841,"name":"1. Milton Daisy"},{"status":"ACTIVE","sortPriority":2,"id":58974183,"name":"2. Ballymac Diverse"},{"status":"ACTIVE","sortPriority":3,"id":58462129,"name":"3. Rapido Junior"},{"status":"ACTIVE","sortPriority":4,"id":50281437,"name":"4. Browns Girl"},{"status":"ACTIVE","sortPriority":5,"id":68579508,"name":"5. Ivy Hill Willow"},{"status":"ACTIVE","sortPriority":6,"id":68169358,"name":"6. Spiridon Zelus"}],"regulators":["MR_INT"],"venue":"Towcester","countryCode":"GB","discountAllowed":true,"timezone":"Europe/London","openDate":"2024-06-27T13:33:00.000Z","version":5994767126,"name":"A2 500m","eventName":"Towcester 27th Jun"},"rc":[{"atb":[[1.02,25.92]],"id":58974183},{"atl":[[990,0.23]],"id":58974183},{"spn":495.51,"spf":"NaN","id":58974183},{"atb":[[1.03,17.28]],"id":58462129},{"atl":[[990,0.23]],"id":58462129},{"spn":495.51,"spf":"NaN","id":58462129},{"atb":[[1.02,25.92]],"id":68169358},{"atl":[[1000,0.23]],"id":68169358},{"spn":500.51,"spf":"NaN","id":68169358},{"atb":[[1.03,17.28]],"id":68870841},{"atl":[[990,0.23]],"id":68870841},{"spn":495.51,"spf":"NaN","id":68870841},{"atb":[[1.03,17.28]],"id":68579508},{"atl":[[990,0.23]],"id":68579508},{"spn":495.51,"spf":"NaN","id":68579508},{"atb":[[1.01,51.85]],"id":50281437},{"atl":[[990,0.23]],"id":50281437},{"spn":495.5,"spf":"NaN","id":50281437}],"con":true,"img":true}]}
{"op":"mcm","clk":"11537956526","pt":1719448682754,"mc":[{"id":"1.230180112","marketDefinition":{"bspMarket":true,"turnInPlayEnabled":false,"persistenceEnabled":false,"marketBaseRate":5.0,"eventId":"33376437","eventTypeId":"4339","numberOfWinners":1,"bettingType":"ODDS","marketType":"WIN","marketTime":"2024-06-27T13:33:00.000Z","suspendTime":"2024-06-27T13:33:00.000Z","bspReconciled":false,"complete":true,"inPlay":false,"crossMatching":false,"runnersVoidable":false,"numberOfActiveRunners":6,"betDelay":0,"status":"OPEN","runners":[{"status":"ACTIVE","sortPriority":1,"id":68870841,"name":"1. Milton Daisy"},{"status":"ACTIVE","sortPriority":2,"id":58974183,"name":"2. Ballymac Diverse"},{"status":"ACTIVE","sortPriority":3,"id":58462129,"name":"3. Rapido Junior"},{"status":"ACTIVE","sortPriority":4,"id":50281437,"name":"4. Browns Girl"},{"status":"ACTIVE","sortPriority":5,"id":68579508,"name":"5. Ivy Hill Willow"},{"status":"ACTIVE","sortPriority":6,"id":68169358,"name":"6. Spiridon Zelus"}],"regulators":["MR_INT"],"venue":"Towcester","countryCode":"GB","discountAllowed":true,"timezone":"Europe/London","openDate":"2024-06-27T13:33:00.000Z","version":5994767126,"name":"A2 500m","eventName":"Towcester 27th Jun"},"rc":[{"atb":[[1.02,25.92]],"id":58974183},{"atl":[[990,0.23]],"id":58974183},{"spn":495.51,"spf":"NaN","id":58974183},{"atb":[[1.03,17.28]],"id":58462129},{"atl":[[990,0.23]],"id":58462129},{"spn":495.51,"spf":"NaN","id":58462129},{"atb":[[1.02,25.92]],"id":68169358},{"atl":[[1000,0.23]],"id":68169358},{"spn":500.51,"spf":"NaN","id":68169358},{"atb":[[1.03,17.28]],"id":68870841},{"atl":[[990,0.23]],"id":68870841},{"spn":495.51,"spf":"NaN","id":68870841},{"atb":[[1.03,17.28]],"id":68579508},{"atl":[[990,0.23]],"id":68579508},{"spn":495.51,"spf":"NaN","id":68579508},{"atb":[[1.01,51.85]],"id":50281437},{"atl":[[990,0.23]],"id":50281437},{"spn":495.5,"spf":"NaN","id":50281437}],"con":true,"img":true}]}
{"op":"mcm","clk":"11538172143","pt":1719454082697,"mc":[{"id":"1.230180112","marketDefinition":{"bspMarket":true,"turnInPlayEnabled":false,"persistenceEnabled":false,"marketBaseRate":5.0,"eventId":"33376437","eventTypeId":"4339","numberOfWinners":1,"bettingType":"ODDS","marketType":"WIN","marketTime":"2024-06-27T13:33:00.000Z","suspendTime":"2024-06-27T13:33:00.000Z","bspReconciled":false,"complete":true,"inPlay":false,"crossMatching":false,"runnersVoidable":false,"numberOfActiveRunners":6,"betDelay":0,"status":"OPEN","runners":[{"status":"ACTIVE","sortPriority":1,"id":68870841,"name":"1. Milton Daisy"},{"status":"ACTIVE","sortPriority":2,"id":58974183,"name":"2. Ballymac Diverse"},{"status":"ACTIVE","sortPriority":3,"id":58462129,"name":"3. Rapido Junior"},{"status":"ACTIVE","sortPriority":4,"id":50281437,"name":"4. Browns Girl"},{"status":"ACTIVE","sortPriority":5,"id":68579508,"name":"5. Ivy Hill Willow"},{"status":"ACTIVE","sortPriority":6,"id":68169358,"name":"6. Spiridon Zelus"}],"regulators":["MR_INT"],"venue":"Towcester","countryCode":"GB","discountAllowed":true,"timezone":"Europe/London","openDate":"2024-06-27T13:33:00.000Z","version":5994767126,"name":"A2 500m","eventName":"Towcester 27th Jun"},"rc":[{"atb":[[1.02,25.93]],"id":58974183},{"atl":[[990,0.23]],"id":58974183},{"spn":495.51,"spf":"NaN","id":58974183},{"atb":[[1.03,17.29]],"id":58462129},{"atl":[[990,0.23]],"id":58462129},{"spn":495.51,"spf":"NaN","id":58462129},{"atb":[[1.02,25.93]],"id":68169358},{"atl":[[1000,0.23]],"id":68169358},{"spn":500.51,"spf":"NaN","id":68169358},{"atb":[[1.03,17.29]],"id":68870841},{"atl":[[990,0.23]],"id":68870841},{"spn":495.51,"spf":"NaN","id":68870841},{"atb":[[1.03,17.29]],"id":68579508},{"atl":[[990,0.23]],"id":68579508},{"spn":495.51,"spf":"NaN","id":68579508},{"atb":[[1.01,51.86]],"id":50281437},{"atl":[[990,0.23]],"id":50281437},{"spn":495.5,"spf":"NaN","id":50281437}],"con":true,"img":true}]}
{"op":"mcm","clk":"11538369810","pt":1719459482783,"mc":[{"id":"1.230180112","marketDefinition":{"bspMarket":true,"turnInPlayEnabled":false,"persistenceEnabled":false,"marketBaseRate":5.0,"eventId":"33376437","eventTypeId":"4339","numberOfWinners":1,"bettingType":"ODDS","marketType":"WIN","marketTime":"2024-06-27T13:33:00.000Z","suspendTime":"2024-06-27T13:33:00.000Z","bspReconciled":false,"complete":true,"inPlay":false,"crossMatching":false,"runnersVoidable":false,"numberOfActiveRunners":6,"betDelay":0,"status":"OPEN","runners":[{"status":"ACTIVE","sortPriority":1,"id":68870841,"name":"1. Milton Daisy"},{"status":"ACTIVE","sortPriority":2,"id":58974183,"name":"2. Ballymac Diverse"},{"status":"ACTIVE","sortPriority":3,"id":58462129,"name":"3. Rapido Junior"},{"status":"ACTIVE","sortPriority":4,"id":50281437,"name":"4. Browns Girl"},{"status":"ACTIVE","sortPriority":5,"id":68579508,"name":"5. Ivy Hill Willow"},{"status":"ACTIVE","sortPriority":6,"id":68169358,"name":"6. Spiridon Zelus"}],"regulators":["MR_INT"],"venue":"Towcester","countryCode":"GB","discountAllowed":true,"timezone":"Europe/London","openDate":"2024-06-27T13:33:00.000Z","version":5994767126,"name":"A2 500m","eventName":"Towcester 27th Jun"},"rc":[{"atb":[[1.02,25.93]],"id":58974183},{"atl":[[990,0.23]],"id":58974183},{"spn":495.51,"spf":"NaN","id":58974183},{"atb":[[1.03,17.29]],"id":58462129},{"atl":[[990,0.23]],"id":58462129},{"spn":495.51,"spf":"NaN","id":58462129},{"atb":[[1.02,25.93]],"id":68169358},{"atl":[[1000,0.23]],"id":68169358},{"spn":500.51,"spf":"NaN","id":68169358},{"atb":[[1.03,17.29]],"id":68870841},{"atl":[[990,0.23]],"id":68870841},{"spn":495.51,"spf":"NaN","id":68870841},{"atb":[[1.03,17.29]],"id":68579508},{"atl":[[990,0.23]],"id":68579508},{"spn":495.51,"spf":"NaN","id":68579508},{"atb":[[1.01,51.87]],"id":50281437},{"atl":[[990,0.23]],"id":50281437},{"spn":495.5,"spf":"NaN","id":50281437}],"con":true,"img":true}]}
{"op":"mcm","clk":"11538499334","pt":1719462793192,"mc":[{"id":"1.230180112","rc":[{"atb":[[1.02,25.93]],"id":58974183},{"atl":[[150,4]],"id":58974183},{"spn":75.51,"spf":"NaN","id":58974183},{"atb":[[1.03,17.29]],"id":58462129},{"atl":[[150,4]],"id":58462129},{"spn":75.51,"spf":"NaN","id":58462129},{"atb":[[1.02,25.93]],"id":68169358},{"atl":[[150,4]],"id":68169358},{"spn":75.51,"spf":"NaN","id":68169358},{"atb":[[1.03,17.29]],"id":68870841},{"atl":[[150,4]],"id":68870841},{"spn":75.51,"spf":"NaN","id":68870841},{"atb":[[1.03,17.29]],"id":68579508},{"atl":[[150,4]],"id":68579508},{"spn":75.51,"spf":"NaN","id":68579508},{"atb":[[1.01,51.87]],"id":50281437},{"atl":[[150,4]],"id":50281437},{"spn":75.5,"spf":"NaN","id":50281437}],"con":true,"img":false}]}
{"op":"mcm","clk":"11538596940","pt":1719464882726,"mc":[{"id":"1.230180112","marketDefinition":{"bspMarket":true,"turnInPlayEnabled":false,"persistenceEnabled":false,"marketBaseRate":5.0,"eventId":"33376437","eventTypeId":"4339","numberOfWinners":1,"bettingType":"ODDS","marketType":"WIN","marketTime":"2024-06-27T13:33:00.000Z","suspendTime":"2024-06-27T13:33:00.000Z","bspReconciled":false,"complete":true,"inPlay":false,"crossMatching":false,"runnersVoidable":false,"numberOfActiveRunners":6,"betDelay":0,"status":"OPEN","runners":[{"status":"ACTIVE","sortPriority":1,"id":68870841,"name":"1. Milton Daisy"},{"status":"ACTIVE","sortPriority":2,"id":58974183,"name":"2. Ballymac Diverse"},{"status":"ACTIVE","sortPriority":3,"id":58462129,"name":"3. Rapido Junior"},{"status":"ACTIVE","sortPriority":4,"id":50281437,"name":"4. Browns Girl"},{"status":"ACTIVE","sortPriority":5,"id":68579508,"name":"5. Ivy Hill Willow"},{"status":"ACTIVE","sortPriority":6,"id":68169358,"name":"6. Spiridon Zelus"}],"regulators":["MR_INT"],"venue":"Towcester","countryCode":"GB","discountAllowed":true,"timezone":"Europe/London","openDate":"2024-06-27T13:33:00.000Z","version":5994767126,"name":"A2 500m","eventName":"Towcester 27th Jun"},"rc":[{"atb":[[1.02,25.93]],"id":58974183},{"atl":[[150,4],[990,0.23]],"id":58974183},{"spn":75.51,"spf":"NaN","id":58974183},{"atb":[[1.03,17.29]],"id":58462129},{"atl":[[150,4],[990,0.23]],"id":58462129},{"spn":75.51,"spf":"NaN","id":58462129},{"atb":[[1.02,25.93]],"id":68169358},{"atl":[[150,4],[1000,0.23]],"id":68169358},{"spn":75.51,"spf":"NaN","id":68169358},{"atb":[[1.03,17.29]],"id":68870841},{"atl":[[150,4],[990,0.23]],"id":68870841},{"spn":75.51,"spf":"NaN","id":68870841},{"atb":[[1.03,17.29]],"id":68579508},{"atl":[[150,4],[990,0.23]],"id":68579508},{"spn":75.51,"spf":"NaN","id":68579508},{"atb":[[1.01,51.86]],"id":50281437},{"atl":[[150,4],[990,0.23]],"id":50281437},{"spn":75.5,"spf":"NaN","id":50281437}],"con":true,"img":true}]}
{"op":"mcm","clk":"11538748461","pt":1719468201678,"mc":[{"id":"1.230180112","rc":[{"atb":[[1.02,25.93],[2.1,12.55]],"id":58974183},{"spn":76.05,"spf":"NaN","id":58974183},{"atb":[[2,10.25],[1.03,17.29]],"id":58462129},{"spn":76.0,"spf":"NaN","id":58462129},{"atb":[[1.02,25.93],[2.1,8.97]],"id":68169358},{"spn":76.05,"spf":"NaN","id":68169358},{"atb":[[1.03,17.29],[2.08,12.44]],"id":68870841},{"spn":76.04,"spf":"NaN","id":68870841},{"atb":[[2.02,12.08],[1.03,17.29]],"id":68579508},{"spn":76.01,"spf":"NaN","id":68579508},{"atb":[[2,10.25],[1.01,51.86]],"id":50281437},{"spn":76.0,"spf":"NaN","id":50281437}],"con":true,"img":false}]}
{"op":"mcm","clk":"11538751285","pt":1719468259353,"mc":[{"id":"1.230180112","rc":[{"atb":[[2.02,3.16]],"id":50281437}],"con":true,"img":false}]}
{"op":"mcm","clk":"11538751298","pt":1719468259555,"mc":[{"id":"1.230180112","rc":[{"atb":[[2.12,3.16]],"id":68169358}],"con":true,"img":false}]}
{"op":"mcm","clk":"11538751309","pt":1719468259759,"mc":[{"id":"1.230180112","rc":[{"atb":[[2.12,3.16]],"id":58974183}],"con":true,"img":false}]}
{"op":"mcm","clk":"11538751319","pt":1719468259962,"mc":[{"id":"1.230180112","rc":[{"atb":[[2.04,3.16]],"id":68579508}],"con":true,"img":false}]}
{"op":"mcm","clk":"11538751334","pt":1719468260172,"mc":[{"id":"1.230180112","rc":[{"atb":[[2.02,3.16]],"id":58462129}],"con":true,"img":false}]}
{"op":"mcm","clk":"11538751351","pt":1719468260382,"mc":[{"id":"1.230180112","rc":[{"atb":[[2.1,3.16]],"id":68870841}],"con":true,"img":false}]}
{"op":"mcm","clk":"11538752362","pt":1719468281717,"mc":[{"id":"1.230180112","marketDefinition":{"bspMarket":true,"turnInPlayEnabled":false,"persistenceEnabled":false,"marketBaseRate":5.0,"eventId":"33376437","eventTypeId":"4339","numberOfWinners":1,"bettingType":"ODDS","marketType":"WIN","marketTime":"2024-06-27T13:33:00.000Z","suspendTime":"2024-06-27T13:33:00.000Z","bspReconciled":false,"complete":true,"inPlay":false,"crossMatching":true,"runnersVoidable":false,"numberOfActiveRunners":6,"betDelay":0,"status":"OPEN","runners":[{"status":"ACTIVE","sortPriority":1,"id":68870841,"name":"1. Milton Daisy"},{"status":"ACTIVE","sortPriority":2,"id":58974183,"name":"2. Ballymac Diverse"},{"status":"ACTIVE","sortPriority":3,"id":58462129,"name":"3. Rapido Junior"},{"status":"ACTIVE","sortPriority":4,"id":50281437,"name":"4. Browns Girl"},{"status":"ACTIVE","sortPriority":5,"id":68579508,"name":"5. Ivy Hill Willow"},{"status":"ACTIVE","sortPriority":6,"id":68169358,"name":"6. Spiridon Zelus"}],"regulators":["MR_INT"],"venue":"Towcester","countryCode":"GB","discountAllowed":true,"timezone":"Europe/London","openDate":"2024-06-27T13:33:00.000Z","version":5994767126,"name":"A2 500m","eventName":"Towcester 27th Jun"},"rc":[],"con":true,"img":false}]}
{"op":"mcm","clk":"11538753640","pt":1719468304221,"mc":[{"id":"1.230180112","rc":[{"spn":76.06,"spf":"NaN","id":58974183},{"spn":76.01,"spf":"NaN","id":58462129},{"atb":[[2.12,6.55]],"id":68169358},{"spn":76.06,"spf":"NaN","id":68169358},{"spn":76.05,"spf":"NaN","id":68870841},{"spn":76.02,"spf":"NaN","id":68579508},{"spn":76.01,"spf":"NaN","id":50281437}],"con":true,"img":false}]}
{"op":"mcm","clk":"11538753646","pt":1719468304331,"mc":[{"id":"1.230180112","rc":[{"atb":[[2.04,6.55]],"id":68579508}],"con":true,"img":false}]}
{"op":"mcm","clk":"11538753658","pt":1719468304530,"mc":[{"id":"1.230180112","rc":[{"atb":[[2.02,6.55]],"id":50281437}],"con":true,"img":false}]}
{"op":"mcm","clk":"11538753661","pt":1719468304632,"mc":[{"id":"1.230180112","rc":[{"atb":[[2.02,6.55]],"id":58462129}],"con":true,"img":false}]}
{"op":"mcm","clk":"11538753691","pt":1719468305146,"mc":[{"id":"1.230180112","rc":[{"atb":[[2.12,6.55]],"id":58974183}],"con":true,"img":false}]}
{"op":"mcm","clk":"11538753750","pt":1719468306127,"mc":[{"id":"1.230180112","rc":[{"atb":[[2.1,6.55]],"id":68870841}],"con":true,"img":false}]}
{"op":"mcm","clk":"11538940301","pt":1719472105993,"mc":[{"id":"1.230180112","rc":[{"atb":[[1.02,25.91],[2.12,6.54],[2.1,0]],"id":58974183},{"atl":[[990,0.23]],"id":58974183},{"atb":[[2,0],[2.02,6.54],[1.03,17.27]],"id":58462129},{"atl":[[990,0.23]],"id":58462129},{"atb":[[1.02,25.91],[2.12,6.54],[2.1,0]],"id":68169358},{"atl":[[1000,0.23]],"id":68169358},{"atb":[[1.03,17.27],[2.1,6.54],[2.08,0]],"id":68870841},{"atl":[[990,0.23]],"id":68870841},{"atb":[[2.02,0],[1.03,17.27],[2.04,6.54]],"id":68579508},{"atl":[[990,0.23]],"id":68579508},{"atb":[[2,0],[2.02,6.54],[1.01,51.82]],"id":50281437},{"atl":[[990,0.23]],"id":50281437}],"con":true,"img":false}]}
{"op":"mcm","clk":"11538940308","pt":1719472106092,"mc":[{"id":"1.230180112","rc":[{"atb":[[2.14,12.55]],"id":58974183},{"atb":[[2.04,10.25]],"id":58462129},{"atb":[[2.14,8.96]],"id":68169358},{"atb":[[2.12,12.43]],"id":68870841},{"atb":[[2.06,12.07]],"id":68579508},{"atb":[[2.04,10.25]],"id":50281437}],"con":true,"img":false}]}
{"op":"mcm","clk":"11538944787","pt":1719472178214,"mc":[{"id":"1.230180112","rc":[{"spn":76.07,"spf":"NaN","id":58974183},{"spn":76.02,"spf":"NaN","id":58462129},{"spn":76.07,"spf":"NaN","id":68169358},{"spn":76.06,"spf":"NaN","id":68870841},{"spn":76.03,"spf":"NaN","id":68579508},{"atb":[[2.02,3.38]],"id":50281437},{"spn":76.02,"spf":"NaN","id":50281437}],"con":true,"img":false}]}
{"op":"mcm","clk":"11538944820","pt":1719472178725,"mc":[{"id":"1.230180112","rc":[{"atb":[[2.02,3.38]],"id":58462129}],"con":true,"img":false}]}
{"op":"mcm","clk":"11538944843","pt":1719472179137,"mc":[{"id":"1.230180112","rc":[{"atb":[[2.12,3.38]],"id":68169358}],"con":true,"img":false}]}
{"op":"mcm","clk":"11538944862","pt":1719472179392,"mc":[{"id":"1.230180112","rc":[{"atb":[[2.12,3.38]],"id":58974183}],"con":true,"img":false}]}
{"op":"mcm","clk":"11538944873","pt":1719472179597,"mc":[{"id":"1.230180112","rc":[{"atb":[[2.06,3.16]],"id":50281437}],"con":true,"img":false}]}
{"op":"mcm","clk":"11538944899","pt":1719472180007,"mc":[{"id":"1.230180112","rc":[{"atb":[[2.06,3.16]],"id":58462129}],"con":true,"img":false}]}
{"op":"mcm","clk":"11538944905","pt":1719472180110,"mc":[{"id":"1.230180112","rc":[{"atb":[[2.04,3.38]],"id":68579508}],"con":true,"img":false}]}
{"op":"mcm","clk":"11538944919","pt":1719472180319,"mc":[{"id":"1.230180112","rc":[{"atb":[[2.16,3.16]],"id":58974183}],"con":true,"img":false}]}
{"op":"mcm","clk":"11538944946","pt":1719472180824,"mc":[{"id":"1.230180112","rc":[{"atb":[[2.16,3.16]],"id":68169358}],"con":true,"img":false}]}
{"op":"mcm","clk":"11538944955","pt":1719472181028,"mc":[{"id":"1.230180112","rc":[{"atb":[[2.1,3.38]],"id":68870841}],"con":true,"img":false}]}
{"op":"mcm","clk":"11538944964","pt":1719472181232,"mc":[{"id":"1.230180112","rc":[{"atb":[[2.08,3.16]],"id":68579508}],"con":true,"img":false}]}
{"op":"mcm","clk":"11538944992","pt":1719472181696,"mc":[{"id":"1.230180112","rc":[{"atb":[[2.14,3.16]],"id":68870841}],"con":true,"img":false}]}
{"op":"mcm","clk":"11538946608","pt":1719472208043,"mc":[{"id":"1.230180112","rc":[{"atb":[[2.12,0]],"id":58974183}],"con":true,"img":false}]}
{"op":"mcm","clk":"11538946648","pt":1719472208658,"mc":[{"id":"1.230180112","rc":[{"atb":[[2.02,0]],"id":50281437}],"con":true,"img":false}]}
{"op":"mcm","clk":"11538946677","pt":1719472209068,"mc":[{"id":"1.230180112","rc":[{"atb":[[2.12,0]],"id":68169358}],"con":true,"img":false}]}
{"op":"mcm","clk":"11538946814","pt":1719472211269,"mc":[{"id":"1.230180112","rc":[{"atb":[[2.1,0]],"id":68870841}],"con":true,"img":false}]}
{"op":"mcm","clk":"11538946877","pt":1719472212346,"mc":[{"id":"1.230180112","rc":[{"atb":[[2.04,0]],"id":68579508}],"con":true,"img":false}]}
{"op":"mcm","clk":"11538946899","pt":1719472212757,"mc":[{"id":"1.230180112","rc":[{"atb":[[2.02,0]],"id":58462129}],"con":true,"img":false}]}
{"op":"mcm","clk":"11538947526","pt":1719472223987,"mc":[{"id":"1.230180112","rc":[{"atb":[[2.16,6.54]],"id":68169358}],"con":true,"img":false}]}
{"op":"mcm","clk":"11538947619","pt":1719472225575,"mc":[{"id":"1.230180112","rc":[{"atb":[[2.14,6.54]],"id":68870841}],"con":true,"img":false}]}
{"op":"mcm","clk":"11538947641","pt":1719472225987,"mc":[{"id":"1.230180112","rc":[{"atb":[[2.16,6.54]],"id":58974183}],"con":true,"img":false}]}
{"op":"mcm","clk":"11538947695","pt":1719472226957,"mc":[{"id":"1.230180112","rc":[{"atb":[[2.06,6.54]],"id":58462129}],"con":true,"img":false}]}
{"op":"mcm","clk":"11538947714","pt":1719472227265,"mc":[{"id":"1.230180112","rc":[{"atb":[[2.06,6.54]],"id":50281437}],"con":true,"img":false}]}
{"op":"mcm","clk":"11538947850","pt":1719472229472,"mc":[{"id":"1.230180112","rc":[{"atb":[[2.08,6.54]],"id":68579508}],"con":true,"img":false}]}
{"op":"mcm","clk":"11539124128","pt":1719475682712,"mc":[{"id":"1.230180112","marketDefinition":{"bspMarket":true,"turnInPlayEnabled":false,"persistenceEnabled":false,"marketBaseRate":5.0,"eventId":"33376437","eventTypeId":"4339","numberOfWinners":1,"bettingType":"ODDS","marketType":"WIN","marketTime":"2024-06-27T13:33:00.000Z","suspendTime":"2024-06-27T13:33:00.000Z","bspReconciled":false,"complete":true,"inPlay":false,"crossMatching":true,"runnersVoidable":false,"numberOfActiveRunners":6,"betDelay":0,"status":"OPEN","runners":[{"status":"ACTIVE","sortPriority":1,"id":68870841,"name":"1. Milton Daisy"},{"status":"ACTIVE","sortPriority":2,"id":58974183,"name":"2. Ballymac Diverse"},{"status":"ACTIVE","sortPriority":3,"id":58462129,"name":"3. Rapido Junior"},{"status":"ACTIVE","sortPriority":4,"id":50281437,"name":"4. Browns Girl"},{"status":"ACTIVE","sortPriority":5,"id":68579508,"name":"5. Ivy Hill Willow"},{"status":"ACTIVE","sortPriority":6,"id":68169358,"name":"6. Spiridon Zelus"}],"regulators":["MR_INT"],"venue":"Towcester","countryCode":"GB","discountAllowed":true,"timezone":"Europe/London","openDate":"2024-06-27T13:33:00.000Z","version":5994767126,"name":"A2 500m","eventName":"Towcester 27th Jun"},"rc":[{"atb":[[1.02,25.92],[2.16,6.55],[2.14,12.55]],"id":58974183},{"atl":[[150,4],[990,0.23]],"id":58974183},{"spn":76.08,"spf":"NaN","id":58974183},{"atb":[[2.06,6.55],[1.03,17.28],[2.04,10.25]],"id":58462129},{"atl":[[150,4],[990,0.23]],"id":58462129},{"spn":76.03,"spf":"NaN","id":58462129},{"atb":[[1.02,25.92],[2.16,6.55],[2.14,8.96]],"id":68169358},{"atl":[[150,4],[1000,0.23]],"id":68169358},{"spn":76.08,"spf":"NaN","id":68169358},{"atb":[[1.03,17.28],[2.12,12.43],[2.14,6.55]],"id":68870841},{"atl":[[150,4],[990,0.23]],"id":68870841},{"spn":76.07,"spf":"NaN","id":68870841},{"atb":[[2.06,12.08],[1.03,17.28],[2.08,6.55]],"id":68579508},{"atl":[[150,4],[990,0.23]],"id":68579508},{"spn":76.04,"spf":"NaN","id":68579508},{"atb":[[1.01,51.84],[2.06,6.55],[2.04,10.25]],"id":50281437},{"atl":[[150,4],[990,0.23]],"id":50281437},{"spn":76.03,"spf":"NaN","id":50281437}],"con":true,"img":true}]}
{"op":"mcm","clk":"11539127630","pt":1719475706523,"mc":[{"id":"1.230180112","rc":[{"atb":[[1.02,25.92],[2.16,6.55],[2.14,0]],"id":58974183},{"atl":[[990,0.23]],"id":58974183},{"spn":76.08,"spf":"NaN","id":58974183},{"atb":[[2.06,6.55],[1.03,17.28],[2.04,0]],"id":58462129},{"atl":[[990,0.23]],"id":58462129},{"spn":76.03,"spf":"NaN","id":58462129},{"atb":[[1.02,25.92],[2.16,6.55],[2.14,0]],"id":68169358},{"atl":[[1000,0.23]],"id":68169358},{"spn":76.08,"spf":"NaN","id":68169358},{"atb":[[1.03,17.28],[2.12,0],[2.14,6.55]],"id":68870841},{"atl":[[990,0.23]],"id":68870841},{"spn":76.07,"spf":"NaN","id":68870841},{"atb":[[2.06,0],[1.03,17.28],[2.08,6.55]],"id":68579508},{"atl":[[990,0.23]],"id":68579508},{"spn":76.04,"spf":"NaN","id":68579508},{"atb":[[1.01,51.84],[2.06,6.55],[2.04,0]],"id":50281437},{"atl":[[990,0.23]],"id":50281437},{"spn":76.03,"spf":"NaN","id":50281437}],"con":true,"img":false}]}
{"op":"mcm","clk":"11539127637","pt":1719475706627,"mc":[{"id":"1.230180112","rc":[{"atb":[[2.18,12.55]],"id":58974183},{"atb":[[2.08,10.25]],"id":58462129},{"atb":[[2.18,8.96]],"id":68169358},{"atb":[[2.16,12.43]],"id":68870841},{"atb":[[2.1,12.08]],"id":68579508},{"atb":[[2.08,10.25]],"id":50281437}],"con":true,"img":false}]}
{"op":"mcm","clk":"11539129093","pt":1719475728648,"mc":[{"id":"1.230180112","rc":[{"atb":[[2.08,3.38]],"id":68579508}],"con":true,"img":false}]}
{"op":"mcm","clk":"11539129100","pt":1719475728751,"mc":[{"id":"1.230180112","rc":[{"atb":[[2.16,3.38]],"id":68169358}],"con":true,"img":false}]}
{"op":"mcm","clk":"11539129131","pt":1719475729162,"mc":[{"id":"1.230180112","rc":[{"atb":[[2.14,3.38]],"id":68870841}],"con":true,"img":false}]}
{"op":"mcm","clk":"11539129150","pt":1719475729440,"mc":[{"id":"1.230180112","rc":[{"atb":[[2.2,3.16]],"id":68169358}],"con":true,"img":false}]}
{"op":"mcm","clk":"11539129156","pt":1719475729547,"mc":[{"id":"1.230180112","rc":[{"atb":[[2.06,3.38]],"id":58462129}],"con":true,"img":false}]}
{"op":"mcm","clk":"11539129190","pt":1719475730155,"mc":[{"id":"1.230180112","rc":[{"atb":[[2.06,3.38]],"id":50281437}],"con":true,"img":false}]}
{"op":"mcm","clk":"11539129196","pt":1719475730258,"mc":[{"id":"1.230180112","rc":[{"atb":[[2.1,3.16]],"id":58462129}],"con":true,"img":false}]}
{"op":"mcm","clk":"11539129207","pt":1719475730466,"mc":[{"id":"1.230180112","rc":[{"atb":[[2.16,3.38]],"id":58974183},{"atb":[[2.18,3.16]],"id":68870841}],"con":true,"img":false}]}
{"op":"mcm","clk":"11539129238","pt":1719475730978,"mc":[{"id":"1.230180112","rc":[{"atb":[[2.12,3.16]],"id":68579508}],"con":true,"img":false}]}
{"op":"mcm","clk":"11539129244","pt":1719475731082,"mc":[{"id":"1.230180112","rc":[{"atb":[[2.1,3.16]],"id":50281437}],"con":true,"img":false}]}
{"op":"mcm","clk":"11539129258","pt":1719475731387,"mc":[{"id":"1.230180112","rc":[{"atb":[[2.2,3.16]],"id":58974183}],"con":true,"img":false}]}
{"op":"mcm","clk":"11539136535","pt":1719475844704,"mc":[{"id":"1.230180112","rc":[{"spn":76.1,"spf":"NaN","id":58974183},{"spn":76.05,"spf":"NaN","id":58462129},{"spn":76.1,"spf":"NaN","id":68169358},{"atb":[[2.14,0]],"id":68870841},{"spn":76.09,"spf":"NaN","id":68870841},{"spn":76.06,"spf":"NaN","id":68579508},{"spn":76.05,"spf":"NaN","id":50281437}],"con":true,"img":false}]}
{"op":"mcm","clk":"11539136549","pt":1719475844915,"mc":[{"id":"1.230180112","rc":[{"atb":[[2.08,0]],"id":68579508}],"con":true,"img":false}]}
{"op":"mcm","clk":"11539136610","pt":1719475846004,"mc":[{"id":"1.230180112","rc":[{"atb":[[2.06,0]],"id":50281437}],"con":true,"img":false}]}
{"op":"mcm","clk":"11539136643","pt":1719475846619,"mc":[{"id":"1.230180112","rc":[{"atb":[[2.16,0]],"id":68169358},{"atb":[[2.18,6.55]],"id":68870841}],"con":true,"img":false}]}
{"op":"mcm","clk":"11539136722","pt":1719475848007,"mc":[{"id":"1.230180112","rc":[{"atb":[[2.16,0]],"id":58974183}],"con":true,"img":false}]}
{"op":"mcm","clk":"11539136756","pt":1719475848624,"mc":[{"id":"1.230180112","rc":[{"atb":[[2.06,0]],"id":58462129}],"con":true,"img":false}]}
{"op":"mcm","clk":"11539136769","pt":1719475848931,"mc":[{"id":"1.230180112","rc":[{"atb":[[2.12,6.55]],"id":68579508}],"con":true,"img":false}]}
{"op":"mcm","clk":"11539136788","pt":1719475849190,"mc":[{"id":"1.230180112","rc":[{"atb":[[2.1,6.55]],"id":50281437}],"con":true,"img":false}]}
{"op":"mcm","clk":"11539136795","pt":1719475849296,"mc":[{"id":"1.230180112","rc":[{"atb":[[2.2,6.55]],"id":68169358}],"con":true,"img":false}]}
{"op":"mcm","clk":"11539155163","pt":1719476146079,"mc":[{"id":"1.230180112","rc":[{"atb":[[2.2,6.55]],"id":58974183},{"atb":[[2.1,6.55]],"id":58462129}],"con":true,"img":false}]}
{"op":"mcm","clk":"11539211493","pt":1719477197629,"mc":[{"id":"1.230180112","rc":[{"atl":[[19.5,8]],"id":68169358},{"spn":10.85,"spf":"NaN","id":68169358},{"atl":[[32,8]],"id":68870841},{"spn":17.09,"spf":"NaN","id":68870841},{"atl":[[36,8]],"id":68579508},{"spn":19.06,"spf":"NaN","id":68579508},{"atl":[[28,8]],"id":50281437},{"spn":15.05,"spf":"NaN","id":50281437}],"con":true,"img":false}]}
{"op":"mcm","clk":"11539211498","pt":1719477197726,"mc":[{"id":"1.230180112","rc":[{"atl":[[34,12]],"id":68169358},{"atl":[[55,12]],"id":68870841},{"atl":[[60,12]],"id":68579508},{"atl":[[48,12]],"id":50281437}],"con":true,"img":false}]}
{"op":"mcm","clk":"11539341094","pt":1719479305353,"mc":[{"id":"1.230180112","rc":[{"atb":[[1.02,25.91],[2.18,0],[2.2,6.54]],"id":58974183},{"atb":[[1.03,17.28],[2.1,6.54],[2.08,0]],"id":58462129},{"atb":[[1.02,25.91],[2.18,0],[2.2,6.54]],"id":68169358},{"atb":[[1.03,17.28],[2.18,6.54],[2.16,0]],"id":68870841},{"atb":[[1.03,17.28],[2.12,6.54],[2.1,0]],"id":68579508},{"atb":[[1.01,51.83],[2.1,6.54],[2.08,0]],"id":50281437}],"con":true,"img":false}]}
{"op":"mcm","clk":"11539341098","pt":1719479305450,"mc":[{"id":"1.230180112","rc":[{"atb":[[2.22,12.55]],"id":58974183},{"atb":[[2.12,10.25]],"id":58462129},{"atb":[[2.22,8.96]],"id":68169358},{"atb":[[2.2,12.43]],"id":68870841},{"atb":[[2.14,12.08]],"id":68579508},{"atb":[[2.12,10.25]],"id":50281437}],"con":true,"img":false}]}
{"op":"mcm","clk":"11539347831","pt":1719479412315,"mc":[{"id":"1.230180112","rc":[{"atb":[[2.2,3.38]],"id":58974183},{"spn":76.11,"spf":"NaN","id":58974183},{"atb":[[2.1,3.38]],"id":58462129},{"spn":76.06,"spf":"NaN","id":58462129},{"atb":[[2.2,3.38]],"id":68169358},{"spn":10.86,"spf":"NaN","id":68169358},{"atb":[[2.18,3.38]],"id":68870841},{"spn":17.1,"spf":"NaN","id":68870841},{"atb":[[2.12,3.38]],"id":68579508},{"spn":19.07,"spf":"NaN","id":68579508},{"atb":[[2.1,3.38]],"id":50281437},{"spn":15.06,"spf":"NaN","id":50281437}],"con":true,"img":false}]}
{"op":"mcm","clk":"11539350930","pt":1719479460146,"mc":[{"id":"1.230180112","rc":[{"atb":[[2.2,0]],"id":58974183},{"atb":[[2.1,0]],"id":58462129},{"atb":[[2.2,0]],"id":68169358},{"atb":[[2.18,0]],"id":68870841},{"atb":[[2.12,0]],"id":68579508},{"atb":[[2.1,0]],"id":50281437}],"con":true,"img":false}]}
{"op":"mcm","clk":"11539368931","pt":1719479721950,"mc":[{"id":"1.230180112","rc":[{"atb":[[2.24,3.16]],"id":58974183},{"spn":76.12,"spf":"NaN","id":58974183}],"con":true,"img":false}]}
{"op":"mcm","clk":"11539368947","pt":1719479722153,"mc":[{"id":"1.230180112","rc":[{"atb":[[2.14,3.16]],"id":50281437}],"con":true,"img":false}]}
{"op":"mcm","clk":"11539368955","pt":1719479722256,"mc":[{"id":"1.230180112","rc":[{"atb":[[2.14,3.16]],"id":58462129}],"con":true,"img":false}]}
{"op":"mcm","clk":"11539368973","pt":1719479722461,"mc":[{"id":"1.230180112","rc":[{"atb":[[2.22,3.16]],"id":68870841}],"con":true,"img":false}]}
{"op":"mcm","clk":"11539368993","pt":1719479722665,"mc":[{"id":"1.230180112","rc":[{"atb":[[2.16,3.16]],"id":68579508}],"con":true,"img":false}]}
{"op":"mcm","clk":"11539369053","pt":1719479723493,"mc":[{"id":"1.230180112","rc":[{"atb":[[2.24,3.16]],"id":68169358}],"con":true,"img":false}]}
{"op":"mcm","clk":"11539370619","pt":1719479744606,"mc":[{"id":"1.230180112","rc":[{"atb":[[2.24,6.54]],"id":58974183}],"con":true,"img":false}]}
{"op":"mcm","clk":"11539370695","pt":1719479745477,"mc":[{"id":"1.230180112","rc":[{"atb":[[2.24,6.54]],"id":68169358}],"con":true,"img":false}]}
{"op":"mcm","clk":"11539370720","pt":1719479745785,"mc":[{"id":"1.230180112","rc":[{"atb":[[2.14,6.54]],"id":58462129}],"con":true,"img":false}]}
{"op":"mcm","clk":"11539370747","pt":1719479746094,"mc":[{"id":"1.230180112","rc":[{"atb":[[2.22,6.54]],"id":68870841}],"con":true,"img":false}]}
{"op":"mcm","clk":"11539370770","pt":1719479746406,"mc":[{"id":"1.230180112","rc":[{"atb":[[2.16,6.54]],"id":68579508}],"con":true,"img":false}]}
{"op":"mcm","clk":"11539370788","pt":1719479746613,"mc":[{"id":"1.230180112","rc":[{"atb":[[2.14,6.54]],"id":50281437}],"con":true,"img":false}]}
{"op":"mcm","clk":"11539440241","pt":1719481082686,"mc":[{"id":"1.230180112","marketDefinition":{"bspMarket":true,"turnInPlayEnabled":false,"persistenceEnabled":false,"marketBaseRate":5.0,"eventId":"33376437","eventTypeId":"4339","numberOfWinners":1,"bettingType":"ODDS","marketType":"WIN","marketTime":"2024-06-27T13:33:00.000Z","suspendTime":"2024-06-27T13:33:00.000Z","bspReconciled":false,"complete":true,"inPlay":false,"crossMatching":true,"runnersVoidable":false,"numberOfActiveRunners":6,"betDelay":0,"status":"OPEN","runners":[{"status":"ACTIVE","sortPriority":1,"id":68870841,"name":"1. Milton Daisy"},{"status":"ACTIVE","sortPriority":2,"id":58974183,"name":"2. Ballymac Diverse"},{"status":"ACTIVE","sortPriority":3,"id":58462129,"name":"3. Rapido Junior"},{"status":"ACTIVE","sortPriority":4,"id":50281437,"name":"4. Browns Girl"},{"status":"ACTIVE","sortPriority":5,"id":68579508,"name":"5. Ivy Hill Willow"},{"status":"ACTIVE","sortPriority":6,"id":68169358,"name":"6. Spiridon Zelus"}],"regulators":["MR_INT"],"venue":"Towcester","countryCode":"GB","discountAllowed":true,"timezone":"Europe/London","openDate":"2024-06-27T13:33:00.000Z","version":5994767126,"name":"A2 500m","eventName":"Towcester 27th Jun"},"rc":[{"atb":[[2.24,6.54],[2.22,12.55],[1.02,25.91]],"id":58974183},{"atl":[[150,4],[990,0.23]],"id":58974183},{"spn":76.12,"spf":"NaN","id":58974183},{"atb":[[1.03,17.28],[2.12,10.25],[2.14,6.54]],"id":58462129},{"atl":[[150,4],[990,0.23]],"id":58462129},{"spn":76.07,"spf":"NaN","id":58462129},{"atb":[[2.24,6.54],[2.22,8.96],[1.02,25.91]],"id":68169358},{"atl":[[34,12],[150,4],[19.5,8],[1000,0.23]],"id":68169358},{"spn":10.87,"spf":"NaN","id":68169358},{"atb":[[1.03,17.28],[2.22,6.54],[2.2,12.43]],"id":68870841},{"atl":[[32,8],[150,4],[55,12],[990,0.23]],"id":68870841},{"spn":17.11,"spf":"NaN","id":68870841},{"atb":[[1.03,17.28],[2.16,6.54],[2.14,12.08]],"id":68579508},{"atl":[[36,8],[150,4],[60,12],[990,0.23]],"id":68579508},{"spn":19.08,"spf":"NaN","id":68579508},{"atb":[[1.01,51.83],[2.12,10.25],[2.14,6.54]],"id":50281437},{"atl":[[150,4],[48,12],[28,8],[990,0.23]],"id":50281437},{"spn":15.07,"spf":"NaN","id":50281437}],"con":true,"img":true}]}
{"op":"mcm","clk":"11539495194","pt":1719482070447,"mc":[{"id":"1.230180112","rc":[{"atb":[[8,2]],"id":58974183},{"spn":79.0,"spf":"NaN","id":58974183},{"atb":[[7,2]],"id":58462129},{"spn":78.5,"spf":"NaN","id":58462129},{"atb":[[3.35,2]],"id":68169358},{"spn":11.42,"spf":"NaN","id":68169358},{"atb":[[8,2]],"id":68870841},{"spn":20.0,"spf":"NaN","id":68870841},{"atb":[[4.7,2]],"id":68579508},{"spn":20.35,"spf":"NaN","id":68579508},{"atb":[[4.7,2]],"id":50281437},{"spn":16.35,"spf":"NaN","id":50281437}],"con":true,"img":false}]}
{"op":"mcm","clk":"11539495430","pt":1719482076030,"mc":[{"id":"1.230180112","rc":[{"atb":[[2.24,3.38]],"id":58974183},{"atb":[[2.22,3.38]],"id":68870841}],"con":true,"img":false}]}
{"op":"mcm","clk":"11539545035","pt":1719482905059,"mc":[{"id":"1.230180112","rc":[{"atb":[[2.24,3.38],[2.22,0],[1.02,25.91]],"id":58974183},{"atb":[[1.03,17.27],[2.12,0],[2.14,6.54]],"id":58462129},{"atb":[[2.24,6.54],[2.22,0],[1.02,25.91]],"id":68169358},{"atb":[[1.03,17.27],[2.22,3.38],[2.2,0]],"id":68870841},{"atb":[[1.03,17.27],[2.16,6.54],[2.14,0]],"id":68579508},{"atb":[[1.01,51.83],[2.12,0],[2.14,6.54]],"id":50281437}],"con":true,"img":false}]}
{"op":"mcm","clk":"11539545041","pt":1719482905159,"mc":[{"id":"1.230180112","rc":[{"atb":[[2.26,12.55]],"id":58974183},{"atb":[[2.16,10.25]],"id":58462129},{"atb":[[2.26,8.96]],"id":68169358},{"atb":[[2.24,12.43]],"id":68870841},{"atb":[[2.18,12.07]],"id":68579508},{"atb":[[2.16,10.25]],"id":50281437}],"con":true,"img":false}]}
{"op":"mcm","clk":"11539545692","pt":1719482913807,"mc":[{"id":"1.230180112","rc":[{"atb":[[2.16,3.38]],"id":68579508},{"atb":[[2.14,3.38]],"id":50281437}],"con":true,"img":false}]}
{"op":"mcm","clk":"11539545780","pt":1719482915201,"mc":[{"id":"1.230180112","rc":[{"atb":[[2.24,3.38]],"id":68169358}],"con":true,"img":false}]}
{"op":"mcm","clk":"11539545809","pt":1719482915711,"mc":[{"id":"1.230180112","rc":[{"atb":[[2.14,3.38]],"id":58462129}],"con":true,"img":false}]}
{"op":"mcm","clk":"11539545906","pt":1719482916899,"mc":[{"id":"1.230180112","rc":[{"atb":[[2.18,3.16]],"id":50281437}],"con":true,"img":false}]}
{"op":"mcm","clk":"11539545943","pt":1719482917311,"mc":[{"id":"1.230180112","rc":[{"atb":[[2.2,3.16]],"id":68579508}],"con":true,"img":false}]}
{"op":"mcm","clk":"11539546139","pt":1719482920001,"mc":[{"id":"1.230180112","rc":[{"atb":[[2.18,3.16]],"id":58462129}],"con":true,"img":false}]}
{"op":"mcm","clk":"11539546149","pt":1719482920099,"mc":[{"id":"1.230180112","rc":[{"atb":[[2.28,3.16]],"id":68169358}],"con":true,"img":false}]}
{"op":"mcm","clk":"11539550980","pt":1719482995479,"mc":[{"id":"1.230180112","rc":[{"atb":[[2.24,0]],"id":68169358}],"con":true,"img":false}]}
{"op":"mcm","clk":"11539551025","pt":1719482996306,"mc":[{"id":"1.230180112","rc":[{"atb":[[2.24,0]],"id":58974183}],"con":true,"img":false}]}
{"op":"mcm","clk":"11539551038","pt":1719482996623,"mc":[{"id":"1.230180112","rc":[{"atb":[[2.14,0]],"id":50281437}],"con":true,"img":false}]}
{"op":"mcm","clk":"11539551119","pt":1719482998021,"mc":[{"id":"1.230180112","rc":[{"atb":[[2.14,0]],"id":58462129}],"con":true,"img":false}]}
{"op":"mcm","clk":"11539551138","pt":1719482998426,"mc":[{"id":"1.230180112","rc":[{"atb":[[2.22,0]],"id":68870841},{"atb":[[2.16,0]],"id":68579508}],"con":true,"img":false}]}
{"op":"mcm","clk":"11539551278","pt":1719483000615,"mc":[{"id":"1.230180112","rc":[{"atb":[[2.18,6.54]],"id":58462129},{"atb":[[2.18,6.54]],"id":50281437}],"con":true,"img":false}]}
{"op":"mcm","clk":"11539551297","pt":1719483000922,"mc":[{"id":"1.230180112","rc":[{"atb":[[2.28,6.54]],"id":68169358}],"con":true,"img":false}]}
{"op":"mcm","clk":"11539551335","pt":1719483001594,"mc":[{"id":"1.230180112","rc":[{"atb":[[2.2,6.54]],"id":68579508}],"con":true,"img":false}]}
{"op":"mcm","clk":"11539551364","pt":1719483002118,"mc":[{"id":"1.230180112","rc":[{"atb":[[2.28,3.38]],"id":58974183}],"con":true,"img":false}]}
{"op":"mcm","clk":"11539551385","pt":1719483002434,"mc":[{"id":"1.230180112","rc":[{"atb":[[2.26,3.38]],"id":68870841}],"con":true,"img":false}]}
{"op":"mcm","clk":"11539555777","pt":1719483067091,"mc":[{"id":"1.230180112","rc":[{"atb":[[2.02,30.3],[1.51,196.08]],"id":58974183},{"atb":[[1.51,196.08]],"id":58462129},{"atb":[[1.51,196.08]],"id":68169358},{"atb":[[2.02,30.3],[1.51,196.08]],"id":68870841},{"atb":[[1.51,196.08]],"id":68579508},{"atb":[[1.51,196.08]],"id":50281437}],"con":true,"img":false}]}
{"op":"mcm","clk":"11539636784","pt":1719484172176,"mc":[{"id":"1.230180112","rc":[{"atb":[[3.75,6]],"id":58974183},{"atb":[[3.75,6]],"id":58462129},{"atb":[[3.75,6]],"id":68870841}],"con":true,"img":false}]}
{"op":"mcm","clk":"11539636787","pt":1719484172273,"mc":[{"id":"1.230180112","rc":[{"atb":[[2.44,6]],"id":68169358},{"atb":[[2.86,6]],"id":68579508},{"atb":[[2.86,6]],"id":50281437}],"con":true,"img":false}]}
{"op":"mcm","clk":"11539638094","pt":1719484193743,"mc":[{"id":"1.230180112","rc":[{"atb":[[2.12,89.29]],"id":58974183},{"atb":[[2.12,89.29]],"id":68870841}],"con":true,"img":false}]}
{"op":"mcm","clk":"11539638101","pt":1719484193796,"mc":[{"id":"1.230180112","rc":[{"atb":[[2.12,89.29]],"id":58462129}],"con":true,"img":false}]}
{"op":"mcm","clk":"11539638137","pt":1719484194420,"mc":[{"id":"1.230180112","rc":[{"atb":[[2.18,3.38]],"id":50281437}],"con":true,"img":false}]}
{"op":"mcm","clk":"11539638155","pt":1719484194731,"mc":[{"id":"1.230180112","rc":[{"atb":[[2.2,3.38]],"id":68579508}],"con":true,"img":false}]}
{"op":"mcm","clk":"11539638168","pt":1719484194931,"mc":[{"id":"1.230180112","rc":[{"atb":[[2.18,3.38]],"id":58462129}],"con":true,"img":false}]}
{"op":"mcm","clk":"11539638558","pt":1719484200931,"mc":[{"id":"1.230180112","rc":[{"atb":[[2.18,0]],"id":50281437}],"con":true,"img":false}]}
{"op":"mcm","clk":"11539638566","pt":1719484201139,"mc":[{"id":"1.230180112","rc":[{"atb":[[2.2,0]],"id":68579508}],"con":true,"img":false}]}
{"op":"mcm","clk":"11539638577","pt":1719484201341,"mc":[{"id":"1.230180112","rc":[{"atb":[[2.28,0]],"id":58974183},{"atb":[[2.18,0]],"id":58462129},{"atb":[[2.26,0]],"id":68870841}],"con":true,"img":false}]}
{"op":"mcm","clk":"11539638591","pt":1719484201658,"mc":[{"id":"1.230180112","rc":[{"atb":[[2.88,3.38]],"id":50281437}],"con":true,"img":false}]}
{"op":"mcm","clk":"11539638610","pt":1719484202023,"mc":[{"id":"1.230180112","rc":[{"atb":[[2.88,3.38]],"id":68579508}],"con":true,"img":false}]}
{"op":"mcm","clk":"11539640763","pt":1719484231986,"mc":[{"id":"1.230180112","rc":[{"atb":[[2.88,6.54]],"id":68579508},{"atb":[[2.88,6.54]],"id":50281437}],"con":true,"img":false}]}
{"op":"mcm","clk":"11539812654","pt":1719486482673,"mc":[{"id":"1.230180112","marketDefinition":{"bspMarket":true,"turnInPlayEnabled":false,"persistenceEnabled":false,"marketBaseRate":5.0,"eventId":"33376437","eventTypeId":"4339","numberOfWinners":1,"bettingType":"ODDS","marketType":"WIN","marketTime":"2024-06-27T13:33:00.000Z","suspendTime":"2024-06-27T13:33:00.000Z","bspReconciled":false,"complete":true,"inPlay":false,"crossMatching":true,"runnersVoidable":false,"numberOfActiveRunners":6,"betDelay":0,"status":"OPEN","runners":[{"status":"ACTIVE","sortPriority":1,"id":68870841,"name":"1. Milton Daisy"},{"status":"ACTIVE","sortPriority":2,"id":58974183,"name":"2. Ballymac Diverse"},{"status":"ACTIVE","sortPriority":3,"id":58462129,"name":"3. Rapido Junior"},{"status":"ACTIVE","sortPriority":4,"id":50281437,"name":"4. Browns Girl"},{"status":"ACTIVE","sortPriority":5,"id":68579508,"name":"5. Ivy Hill Willow"},{"status":"ACTIVE","sortPriority":6,"id":68169358,"name":"6. Spiridon Zelus"}],"regulators":["MR_INT"],"venue":"Towcester","countryCode":"GB","discountAllowed":true,"timezone":"Europe/London","openDate":"2024-06-27T13:33:00.000Z","version":5994767126,"name":"A2 500m","eventName":"Towcester 27th Jun"},"rc":[{"atb":[[8,2],[2.02,30.3],[1.02,25.91],[2.12,89.29],[2.26,12.55],[1.51,196.08],[3.75,6]],"id":58974183},{"atl":[[150,4],[990,0.23]],"id":58974183},{"spn":79.0,"spf":"NaN","id":58974183},{"atb":[[1.03,17.28],[2.12,89.29],[1.51,196.08],[7,2],[2.16,10.25],[3.75,6]],"id":58462129},{"atl":[[150,4],[990,0.23]],"id":58462129},{"spn":78.5,"spf":"NaN","id":58462129},{"atb":[[3.35,2],[1.02,25.91],[2.28,6.54],[2.44,6],[2.26,8.96],[1.51,196.08]],"id":68169358},{"atl":[[34,12],[150,4],[19.5,8],[1000,0.23]],"id":68169358},{"spn":11.42,"spf":"NaN","id":68169358},{"atb":[[8,2],[2.24,12.43],[2.02,30.3],[1.03,17.28],[2.12,89.29],[1.51,196.08],[3.75,6]],"id":68870841},{"atl":[[32,8],[150,4],[55,12],[990,0.23]],"id":68870841},{"spn":20.0,"spf":"NaN","id":68870841},{"atb":[[2.88,6.54],[2.86,6],[1.03,17.28],[2.18,12.08],[1.51,196.08],[4.7,2]],"id":68579508},{"atl":[[36,8],[150,4],[60,12],[990,0.23]],"id":68579508},{"spn":20.35,"spf":"NaN","id":68579508},{"atb":[[2.88,6.54],[1.01,51.83],[2.86,6],[1.51,196.08],[2.16,10.25],[4.7,2]],"id":50281437},{"atl":[[150,4],[48,12],[28,8],[990,0.23]],"id":50281437},{"spn":16.35,"spf":"NaN","id":50281437}],"con":true,"img":true}]}
{"op":"mcm","clk":"11539817090","pt":1719486503611,"mc":[{"id":"1.230180112","rc":[{"atb":[[1.02,25.91],[2.26,12.55]],"id":58974183},{"atb":[[1.03,17.28],[2.16,10.25]],"id":58462129},{"atb":[[1.02,25.91],[2.28,6.54],[2.26,0]],"id":68169358},{"atb":[[2.24,12.43],[1.03,17.28]],"id":68870841},{"atb":[[2.88,6.54],[1.03,17.28],[2.18,12.08]],"id":68579508},{"atb":[[2.88,6.54],[1.01,51.83],[2.16,10.25]],"id":50281437}],"con":true,"img":false}]}
{"op":"mcm","clk":"11539817096","pt":1719486503711,"mc":[{"id":"1.230180112","rc":[{"atb":[[2.3,8.96]],"id":68169358}],"con":true,"img":false}]}
{"op":"mcm","clk":"11539820084","pt":1719486537384,"mc":[{"id":"1.230180112","rc":[{"atb":[[2.28,3.38]],"id":68169358}],"con":true,"img":false}]}
{"op":"mcm","clk":"11539820130","pt":1719486537954,"mc":[{"id":"1.230180112","rc":[{"atb":[[2.32,3.16]],"id":68169358}],"con":true,"img":false}]}
{"op":"mcm","clk":"11539826235","pt":1719486610673,"mc":[{"id":"1.230180112","rc":[{"atb":[[2.28,0]],"id":68169358}],"con":true,"img":false}]}
{"op":"mcm","clk":"11539826282","pt":1719486611286,"mc":[{"id":"1.230180112","rc":[{"atb":[[2.32,6.54]],"id":68169358}],"con":true,"img":false}]}
{"op":"mcm","clk":"11539840406","pt":1719486803098,"mc":[{"id":"1.230180112","rc":[{"atb":[[2.3,0]],"id":68169358}],"con":true,"img":false}]}
{"op":"mcm","clk":"11539840412","pt":1719486803199,"mc":[{"id":"1.230180112","rc":[{"atb":[[2.34,8.96]],"id":68169358}],"con":true,"img":false}]}
{"op":"mcm","clk":"11539842003","pt":1719486828859,"mc":[{"id":"1.230180112","rc":[{"atb":[[2.32,3.38]],"id":68169358}],"con":true,"img":false}]}
{"op":"mcm","clk":"11539843470","pt":1719486850448,"mc":[{"id":"1.230180112","rc":[{"atb":[[2.32,0]],"id":68169358}],"con":true,"img":false}]}
{"op":"mcm","clk":"11539849212","pt":1719486930993,"mc":[{"id":"1.230180112","rc":[{"atb":[[2.36,3.38]],"id":68169358}],"con":true,"img":false}]}
{"op":"mcm","clk":"11539850457","pt":1719486946531,"mc":[{"id":"1.230180112","rc":[{"atb":[[2.36,6.54]],"id":68169358}],"con":true,"img":false}]}
{"op":"mcm","clk":"11540014163","pt":1719488996827,"mc":[{"id":"1.230180112","rc":[{"atb":[[1.16,150]],"id":58974183},{"atl":[[390,2]],"id":58974183},{"atb":[[1.16,150]],"id":58462129},{"atl":[[550,2]],"id":58462129},{"atb":[[1.16,150]],"id":68169358},{"atl":[[500,2]],"id":68169358},{"atb":[[1.16,150]],"id":68870841},{"atl":[[370,2]],"id":68870841},{"atb":[[1.16,150]],"id":68579508},{"atl":[[560,2]],"id":68579508},{"atb":[[1.16,150]],"id":50281437},{"atl":[[270,2]],"id":50281437}],"con":true,"img":false}]}
{"op":"mcm","clk":"11540041977","pt":1719489332032,"mc":[{"id":"1.230180112","rc":[{"atb":[[1.02,107.13]],"id":58974183},{"atl":[[980,0.87]],"id":58974183},{"atb":[[1.03,167.01]],"id":58462129},{"atl":[[970,0.87]],"id":58462129},{"atb":[[1.04,167.49]],"id":68169358},{"atl":[[980,1.83]],"id":68169358},{"atb":[[1.03,118.79]],"id":68870841},{"atl":[[980,2.13]],"id":68870841},{"atb":[[1.02,141.27]],"id":68579508},{"atl":[[970,1.48]],"id":68579508},{"atb":[[1.02,102.36]],"id":50281437},{"atl":[[970,1]],"id":50281437}],"con":true,"img":false}]}
{"op":"mcm","clk":"11540150263","pt":1719490535476,"mc":[{"id":"1.230180112","rc":[{"atb":[[8,0]],"id":58974183},{"spn":76.87,"spf":"NaN","id":58974183},{"atb":[[7,0]],"id":58462129},{"spn":76.87,"spf":"NaN","id":58462129},{"atb":[[2.36,6.54],[3.35,0]],"id":68169358},{"spn":10.97,"spf":"NaN","id":68169358},{"atb":[[8,0]],"id":68870841},{"spn":17.87,"spf":"NaN","id":68870841},{"atb":[[2.88,6.54],[4.7,0]],"id":68579508},{"spn":19.44,"spf":"NaN","id":68579508},{"atb":[[2.88,6.54],[4.7,0]],"id":50281437},{"spn":15.44,"spf":"NaN","id":50281437}],"con":true,"img":false}]}
{"op":"mcm","clk":"11540153944","pt":1719490574059,"mc":[{"id":"1.230180112","marketDefinition":{"bspMarket":true,"turnInPlayEnabled":false,"persistenceEnabled":false,"marketBaseRate":5.0,"eventId":"33376437","eventTypeId":"4339","numberOfWinners":1,"bettingType":"ODDS","marketType":"WIN","marketTime":"2024-06-27T13:33:00.000Z","suspendTime":"2024-06-27T13:33:00.000Z","bspReconciled":false,"complete":true,"inPlay":false,"crossMatching":true,"runnersVoidable":false,"numberOfActiveRunners":6,"betDelay":0,"status":"SUSPENDED","runners":[{"status":"ACTIVE","sortPriority":1,"id":68870841,"name":"1. Milton Daisy"},{"status":"ACTIVE","sortPriority":2,"id":58974183,"name":"2. Ballymac Diverse"},{"status":"ACTIVE","sortPriority":3,"id":58462129,"name":"3. Rapido Junior"},{"status":"ACTIVE","sortPriority":4,"id":50281437,"name":"4. Browns Girl"},{"status":"ACTIVE","sortPriority":5,"id":68579508,"name":"5. Ivy Hill Willow"},{"status":"ACTIVE","sortPriority":6,"id":68169358,"name":"6. Spiridon Zelus"}],"regulators":["MR_INT"],"venue":"Towcester","countryCode":"GB","discountAllowed":true,"timezone":"Europe/London","openDate":"2024-06-27T13:33:00.000Z","version":5995358120,"name":"A2 500m","eventName":"Towcester 27th Jun"},"rc":[],"con":true,"img":false}]}
{"op":"mcm","clk":"11540153984","pt":1719490574645,"mc":[{"id":"1.230180112","marketDefinition":{"bspMarket":true,"turnInPlayEnabled":false,"persistenceEnabled":false,"marketBaseRate":5.0,"eventId":"33376437","eventTypeId":"4339","numberOfWinners":1,"bettingType":"ODDS","marketType":"WIN","marketTime":"2024-06-27T13:33:00.000Z","suspendTime":"2024-06-27T13:33:00.000Z","bspReconciled":false,"complete":true,"inPlay":false,"crossMatching":true,"runnersVoidable":false,"numberOfActiveRunners":6,"betDelay":0,"status":"SUSPENDED","runners":[{"status":"ACTIVE","sortPriority":1,"id":68870841,"name":"1. Milton Daisy"},{"status":"ACTIVE","sortPriority":2,"id":58974183,"name":"2. Ballymac Diverse"},{"status":"ACTIVE","sortPriority":3,"id":58462129,"name":"3. Rapido Junior"},{"status":"ACTIVE","sortPriority":4,"id":50281437,"name":"4. Browns Girl"},{"status":"ACTIVE","sortPriority":5,"id":68579508,"name":"5. Ivy Hill Willow"},{"status":"ACTIVE","sortPriority":6,"id":68169358,"name":"6. Spiridon Zelus"}],"regulators":["MR_INT"],"venue":"Towcester","countryCode":"GB","discountAllowed":true,"timezone":"Europe/London","openDate":"2024-06-27T13:33:00.000Z","version":5995358124,"name":"A2 500m","eventName":"Towcester 27th Jun"},"rc":[],"con":true,"img":false}]}
{"op":"mcm","clk":"11540153984","pt":1719490574645,"mc":[{"id":"1.230180112","rc":[{"atb":[[2.02,0],[1.16,0],[1.02,0],[2.12,0],[2.26,0],[1.51,0],[3.75,0]],"id":58974183},{"atl":[[150,0],[390,0],[980,0],[990,0]],"id":58974183},{"atb":[[1.16,0],[1.03,0],[2.12,0],[1.51,0],[2.16,0],[3.75,0]],"id":58462129},{"atl":[[550,0],[150,0],[970,0],[990,0]],"id":58462129},{"atb":[[2.36,0],[1.16,0],[1.02,0],[2.44,0],[1.51,0],[2.34,0],[1.04,0]],"id":68169358},{"atl":[[34,0],[150,0],[19.5,0],[980,0],[500,0],[1000,0]],"id":68169358},{"atb":[[2.24,0],[2.02,0],[1.16,0],[1.03,0],[2.12,0],[1.51,0],[3.75,0]],"id":68870841},{"atl":[[32,0],[150,0],[370,0],[55,0],[980,0],[990,0]],"id":68870841},{"atb":[[2.88,0],[2.86,0],[1.16,0],[1.03,0],[1.02,0],[2.18,0],[1.51,0]],"id":68579508},{"atl":[[560,0],[36,0],[150,0],[60,0],[970,0],[990,0]],"id":68579508},{"atb":[[2.88,0],[1.01,0],[2.86,0],[1.16,0],[1.02,0],[1.51,0],[2.16,0]],"id":50281437},{"atl":[[270,0],[150,0],[48,0],[28,0],[970,0],[990,0]],"id":50281437}],"con":true,"img":false}]}
{"op":"mcm","clk":"11540154014","pt":1719490575026,"mc":[{"id":"1.230180112","marketDefinition":{"bspMarket":true,"turnInPlayEnabled":false,"persistenceEnabled":false,"marketBaseRate":5.0,"eventId":"33376437","eventTypeId":"4339","numberOfWinners":1,"bettingType":"ODDS","marketType":"WIN","marketTime":"2024-06-27T13:33:00.000Z","suspendTime":"2024-06-27T13:33:00.000Z","bspReconciled":false,"complete":true,"inPlay":false,"crossMatching":true,"runnersVoidable":false,"numberOfActiveRunners":5,"betDelay":0,"status":"OPEN","runners":[{"status":"ACTIVE","sortPriority":1,"id":68870841,"name":"1. Milton Daisy"},{"status":"ACTIVE","sortPriority":2,"id":58974183,"name":"2. Ballymac Diverse"},{"status":"ACTIVE","sortPriority":3,"id":50281437,"name":"4. Browns Girl"},{"status":"ACTIVE","sortPriority":4,"id":68579508,"name":"5. Ivy Hill Willow"},{"status":"ACTIVE","sortPriority":5,"id":68169358,"name":"6. Spiridon Zelus"},{"status":"REMOVED","sortPriority":6,"removalDate":"2024-06-27T12:16:14.000Z","id":58462129,"name":"3. Rapido Junior"}],"regulators":["MR_INT"],"venue":"Towcester","countryCode":"GB","discountAllowed":true,"timezone":"Europe/London","openDate":"2024-06-27T13:33:00.000Z","version":5995358138,"name":"A2 500m","eventName":"Towcester 27th Jun"},"rc":[],"con":true,"img":false}]}
{"op":"mcm","clk":"11540154346","pt":1719490579019,"mc":[{"id":"1.230180112","rc":[{"atb":[[1.16,150]],"id":58974183},{"atl":[[390,2]],"id":58974183},{"spn":76.87,"spf":"NaN","id":58974183},{"atb":[[1.16,150]],"id":68169358},{"atl":[[560,2]],"id":68169358},{"spn":10.97,"spf":"NaN","id":68169358},{"atb":[[1.16,150]],"id":68870841},{"atl":[[370,2]],"id":68870841},{"spn":17.87,"spf":"NaN","id":68870841},{"atb":[[1.16,150]],"id":68579508},{"atl":[[270,2]],"id":68579508},{"spn":19.44,"spf":"NaN","id":68579508},{"atb":[[1.16,150]],"id":50281437},{"atl":[[550,2]],"id":50281437},{"spn":15.44,"spf":"NaN","id":50281437}],"con":true,"img":false}]}
{"op":"mcm","clk":"11540156202","pt":1719490595252,"mc":[{"id":"1.230180112","rc":[{"atb":[[1.51,196.08]],"id":58974183},{"atb":[[1.51,196.08]],"id":68870841}],"con":true,"img":false}]}
{"op":"mcm","clk":"11540156212","pt":1719490595351,"mc":[{"id":"1.230180112","rc":[{"atl":[[150,4]],"id":58974183},{"atl":[[150,4]],"id":68169358},{"atl":[[150,4]],"id":68870841},{"atl":[[150,4]],"id":68579508},{"atl":[[150,4]],"id":50281437}],"con":true,"img":false}]}
{"op":"mcm","clk":"11540164541","pt":1719490696074,"mc":[{"id":"1.230180112","rc":[{"atb":[[1.7,14.46]],"id":58974183},{"spn":75.85,"spf":"NaN","id":58974183},{"atb":[[1.7,15.91]],"id":68169358},{"spn":75.85,"spf":"NaN","id":68169358},{"atb":[[1.7,17.35]],"id":68870841},{"spn":75.85,"spf":"NaN","id":68870841},{"atb":[[1.7,14.46]],"id":68579508},{"spn":75.85,"spf":"NaN","id":68579508},{"atb":[[1.74,19.24]],"id":50281437},{"spn":75.87,"spf":"NaN","id":50281437}],"con":true,"img":false}]}
{"op":"mcm","clk":"11540172607","pt":1719490803121,"mc":[{"id":"1.230180112","rc":[{"atl":[[140,1.9]],"id":68870841},{"spn":70.85,"spf":"NaN","id":68870841}],"con":true,"img":false}]}
{"op":"mcm","clk":"11540293079","pt":1719492589751,"mc":[{"id":"1.230180112","rc":[{"spl":[[1.01,1]],"id":68169358},{"spn":1.7,"spf":1.0,"id":68169358}],"con":true,"img":false}]}
{"op":"mcm","clk":"11540317669","pt":1719492921553,"mc":[{"id":"1.230180112","rc":[{"atb":[[1.03,73.59]],"id":58974183},{"atl":[[990,2.03]],"id":58974183},{"atb":[[1.03,109.12]],"id":68169358},{"atl":[[990,0.86]],"id":68169358},{"atb":[[1.02,89.67]],"id":68870841},{"atl":[[960,1.99]],"id":68870841},{"atb":[[1.02,158.19]],"id":68579508},{"atl":[[960,1.34]],"id":68579508},{"atb":[[1.02,109.12]],"id":50281437},{"atl":[[970,1.76]],"id":50281437}],"con":true,"img":false}]}
{"op":"mcm","clk":"11540325276","pt":1719493032717,"mc":[{"id":"1.230180112","rc":[{"atb":[[1.02,8.46]],"id":58974183},{"atl":[[1000,0.84]],"id":58974183},{"atb":[[1.01,16.93]],"id":68169358},{"atl":[[990,1.7]],"id":68169358},{"atb":[[1.01,16.93]],"id":68870841},{"atl":[[990,0.84]],"id":68870841},{"atb":[[1.01,16.93]],"id":68579508},{"atl":[[990,0.84]],"id":68579508},{"atb":[[1.01,16.93]],"id":50281437},{"atl":[[1000,0.84]],"id":50281437}],"con":true,"img":false}]}
{"op":"mcm","clk":"11540327034","pt":1719493057430,"mc":[{"id":"1.230180112","rc":[{"atb":[[1.71,1.65]],"id":68169358}],"con":true,"img":false}]}
{"op":"mcm","clk":"11540327057","pt":1719493057738,"mc":[{"id":"1.230180112","rc":[{"atb":[[1.71,1.75]],"id":68579508}],"con":true,"img":false}]}
{"op":"mcm","clk":"11540327077","pt":1719493058046,"mc":[{"id":"1.230180112","rc":[{"atb":[[1.75,1.66]],"id":50281437}],"con":true,"img":false}]}
{"op":"mcm","clk":"11540327099","pt":1719493058361,"mc":[{"id":"1.230180112","rc":[{"atb":[[1.71,1.8]],"id":58974183}],"con":true,"img":false}]}
{"op":"mcm","clk":"11540327122","pt":1719493058667,"mc":[{"id":"1.230180112","rc":[{"atb":[[1.71,1.94]],"id":68870841}],"con":true,"img":false}]}
{"op":"mcm","clk":"11540374435","pt":1719493702049,"mc":[{"id":"1.230180112","rc":[{"atb":[[1.03,73.68],[1.02,8.47],[1.7,14.48]],"id":58974183},{"atl":[[190,4],[990,2.03],[1000,0.84]],"id":58974183},{"spn":75.85,"spf":"NaN","id":58974183},{"atb":[[1.01,16.95],[1.03,109.25],[1.7,15.93]],"id":68169358},{"atl":[[990,1.71]],"id":68169358},{"spn":1.71,"spf":1.0,"id":68169358},{"atb":[[1.01,16.95],[1.02,89.77],[1.7,17.37]],"id":68870841},{"atl":[[190,4],[960,1.99],[990,0.84]],"id":68870841},{"spn":70.85,"spf":"NaN","id":68870841},{"atb":[[1.01,16.95],[1.02,158.38],[1.7,14.48]],"id":68579508},{"atl":[[190,4],[960,1.34],[990,0.84]],"id":68579508},{"spn":75.85,"spf":"NaN","id":68579508},{"atb":[[1.01,16.95],[1.74,19.26],[1.02,109.25]],"id":50281437},{"atl":[[190,4],[970,1.77],[1000,0.84]],"id":50281437},{"spn":75.87,"spf":"NaN","id":50281437}],"con":true,"img":false}]}
{"op":"mcm","clk":"11540374443","pt":1719493702151,"mc":[{"id":"1.230180112","rc":[{"atl":[[190,4]],"id":68169358}],"con":true,"img":false}]}
{"op":"mcm","clk":"11540375014","pt":1719493710468,"mc":[{"id":"1.230180112","rc":[{"atb":[[1.72,2]],"id":68870841}],"con":true,"img":false}]}
{"op":"mcm","clk":"11540375052","pt":1719493710980,"mc":[{"id":"1.230180112","rc":[{"atb":[[1.72,2]],"id":58974183},{"atb":[[1.71,0]],"id":68870841}],"con":true,"img":false}]}
{"op":"mcm","clk":"11540375081","pt":1719493711247,"mc":[{"id":"1.230180112","rc":[{"atb":[[1.02,111.25]],"id":50281437}],"con":true,"img":false}]}
{"op":"mcm","clk":"11540375100","pt":1719493711459,"mc":[{"id":"1.230180112","rc":[{"atb":[[1.02,160.38]],"id":68579508}],"con":true,"img":false}]}
{"op":"mcm","clk":"11540375113","pt":1719493711662,"mc":[{"id":"1.230180112","rc":[{"atb":[[1.02,2]],"id":68169358}],"con":true,"img":false}]}
{"op":"mcm","clk":"11540375258","pt":1719493713264,"mc":[{"id":"1.230180112","rc":[{"atb":[[1.72,0]],"id":68870841}],"con":true,"img":false}]}
{"op":"mcm","clk":"11540375265","pt":1719493713376,"mc":[{"id":"1.230180112","rc":[{"atb":[[1.71,2]],"id":68870841}],"con":true,"img":false}]}
{"op":"mcm","clk":"11540375312","pt":1719493714044,"mc":[{"id":"1.230180112","rc":[{"atb":[[1.71,0]],"id":58974183}],"con":true,"img":false}]}
{"op":"mcm","clk":"11540375333","pt":1719493714359,"mc":[{"id":"1.230180112","rc":[{"atb":[[1.72,1.58]],"id":68870841}],"con":true,"img":false}]}
{"op":"mcm","clk":"11540375347","pt":1719493714569,"mc":[{"id":"1.230180112","rc":[{"atb":[[1.72,0]],"id":58974183}],"con":true,"img":false}]}
{"op":"mcm","clk":"11540375358","pt":1719493714665,"mc":[{"id":"1.230180112","rc":[{"atb":[[1.71,2]],"id":58974183}],"con":true,"img":false}]}
{"op":"mcm","clk":"11540375435","pt":1719493715759,"mc":[{"id":"1.230180112","rc":[{"atb":[[1.71,0]],"id":68870841}],"con":true,"img":false}]}
{"op":"mcm","clk":"11540375444","pt":1719493715911,"mc":[{"id":"1.230180112","rc":[{"atb":[[1.73,2]],"id":68870841}],"con":true,"img":false}]}
{"op":"mcm","clk":"11540375511","pt":1719493716945,"mc":[{"id":"1.230180112","rc":[{"atb":[[1.72,1.98]],"id":58974183}],"con":true,"img":false}]}
{"op":"mcm","clk":"11540375536","pt":1719493717357,"mc":[{"id":"1.230180112","rc":[{"atb":[[1.72,0]],"id":68870841}],"con":true,"img":false}]}
{"op":"mcm","clk":"11540375548","pt":1719493717567,"mc":[{"id":"1.230180112","rc":[{"atb":[[1.71,0]],"id":58974183}],"con":true,"img":false}]}
{"op":"mcm","clk":"11540375555","pt":1719493717670,"mc":[{"id":"1.230180112","rc":[{"atb":[[1.73,2]],"id":58974183}],"con":true,"img":false}]}
{"op":"mcm","clk":"11540375642","pt":1719493718759,"mc":[{"id":"1.230180112","rc":[{"atb":[[1.73,0]],"id":68870841}],"con":true,"img":false}]}
{"op":"mcm","clk":"11540375651","pt":1719493718855,"mc":[{"id":"1.230180112","rc":[{"atb":[[1.71,2]],"id":68870841}],"con":true,"img":false}]}
{"op":"mcm","clk":"11540375749","pt":1719493720057,"mc":[{"id":"1.230180112","rc":[{"atb":[[1.72,0]],"id":58974183}],"con":true,"img":false}]}
{"op":"mcm","clk":"11540375773","pt":1719493720368,"mc":[{"id":"1.230180112","rc":[{"atb":[[1.72,1.83]],"id":68870841}],"con":true,"img":false}]}
{"op":"mcm","clk":"11540375826","pt":1719493720991,"mc":[{"id":"1.230180112","rc":[{"atb":[[1.71,0]],"id":68870841}],"con":true,"img":false}]}
{"op":"mcm","clk":"11540375837","pt":1719493721106,"mc":[{"id":"1.230180112","rc":[{"atb":[[1.73,2]],"id":68870841}],"con":true,"img":false}]}
{"op":"mcm","clk":"11540375864","pt":1719493721456,"mc":[{"id":"1.230180112","rc":[{"atb":[[1.73,0]],"id":58974183}],"con":true,"img":false}]}
{"op":"mcm","clk":"11540375868","pt":1719493721560,"mc":[{"id":"1.230180112","rc":[{"atb":[[1.71,2]],"id":58974183}],"con":true,"img":false}]}
{"op":"mcm","clk":"11540375963","pt":1719493722966,"mc":[{"id":"1.230180112","rc":[{"atb":[[1.72,1.84]],"id":58974183}],"con":true,"img":false}]}
{"op":"mcm","clk":"11540375993","pt":1719493723395,"mc":[{"id":"1.230180112","rc":[{"atb":[[1.72,0]],"id":68870841}],"con":true,"img":false}]}
{"op":"mcm","clk":"11540376006","pt":1719493723590,"mc":[{"id":"1.230180112","rc":[{"atb":[[1.71,0]],"id":58974183}],"con":true,"img":false}]}
{"op":"mcm","clk":"11540376013","pt":1719493723693,"mc":[{"id":"1.230180112","rc":[{"atb":[[1.73,2]],"id":58974183}],"con":true,"img":false}]}
{"op":"mcm","clk":"11540376139","pt":1719493725356,"mc":[{"id":"1.230180112","rc":[{"atb":[[1.73,0]],"id":68870841}],"con":true,"img":false}]}
{"op":"mcm","clk":"11540376148","pt":1719493725461,"mc":[{"id":"1.230180112","rc":[{"atb":[[1.71,2]],"id":68870841}],"con":true,"img":false}]}
{"op":"mcm","clk":"11540376205","pt":1719493726179,"mc":[{"id":"1.230180112","rc":[{"atb":[[1.72,0]],"id":58974183}],"con":true,"img":false}]}
{"op":"mcm","clk":"11540376226","pt":1719493726489,"mc":[{"id":"1.230180112","rc":[{"atb":[[1.72,1.74]],"id":68870841}],"con":true,"img":false}]}
{"op":"mcm","clk":"11540376309","pt":1719493727593,"mc":[{"id":"1.230180112","rc":[{"atb":[[1.71,0]],"id":68870841}],"con":true,"img":false}]}
{"op":"mcm","clk":"11540376315","pt":1719493727681,"mc":[{"id":"1.230180112","rc":[{"atb":[[1.73,2]],"id":68870841}],"con":true,"img":false}]}
{"op":"mcm","clk":"11540376364","pt":1719493728374,"mc":[{"id":"1.230180112","rc":[{"atb":[[1.73,0]],"id":58974183}],"con":true,"img":false}]}
{"op":"mcm","clk":"11540376385","pt":1719493728482,"mc":[{"id":"1.230180112","rc":[{"atb":[[1.71,2]],"id":58974183}],"con":true,"img":false}]}
{"op":"mcm","clk":"11540376495","pt":1719493729473,"mc":[{"id":"1.230180112","rc":[{"atb":[[1.72,1.64]],"id":58974183}],"con":true,"img":false}]}
{"op":"mcm","clk":"11540376530","pt":1719493729901,"mc":[{"id":"1.230180112","rc":[{"atb":[[1.72,0]],"id":68870841}],"con":true,"img":false}]}
{"op":"mcm","clk":"11540376551","pt":1719493730198,"mc":[{"id":"1.230180112","rc":[{"atb":[[1.71,0]],"id":58974183}],"con":true,"img":false}]}
{"op":"mcm","clk":"11540376556","pt":1719493730259,"mc":[{"id":"1.230180112","rc":[{"atb":[[1.73,2]],"id":58974183}],"con":true,"img":false}]}
{"op":"mcm","clk":"11540376637","pt":1719493731504,"mc":[{"id":"1.230180112","rc":[{"atb":[[1.73,0]],"id":68870841}],"con":true,"img":false}]}
{"op":"mcm","clk":"11540376644","pt":1719493731551,"mc":[{"id":"1.230180112","rc":[{"atb":[[1.71,2]],"id":68870841}],"con":true,"img":false}]}
{"op":"mcm","clk":"11540376682","pt":1719493732085,"mc":[{"id":"1.230180112","rc":[{"atb":[[1.72,0]],"id":58974183}],"con":true,"img":false}]}
{"op":"mcm","clk":"11540376712","pt":1719493732591,"mc":[{"id":"1.230180112","rc":[{"atb":[[1.73,0]],"id":58974183}],"con":true,"img":false}]}
{"op":"mcm","clk":"11540376720","pt":1719493732690,"mc":[{"id":"1.230180112","rc":[{"atb":[[1.71,2]],"id":58974183}],"con":true,"img":false}]}
{"op":"mcm","clk":"11540376902","pt":1719493735082,"mc":[{"id":"1.230180112","rc":[{"atb":[[1.72,1.67]],"id":58974183}],"con":true,"img":false}]}
{"op":"mcm","clk":"11540376921","pt":1719493735393,"mc":[{"id":"1.230180112","rc":[{"atb":[[1.72,1.96]],"id":68870841}],"con":true,"img":false}]}
{"op":"mcm","clk":"11540376975","pt":1719493736273,"mc":[{"id":"1.230180112","rc":[{"atb":[[1.71,0]],"id":68870841}],"con":true,"img":false}]}
{"op":"mcm","clk":"11540376983","pt":1719493736376,"mc":[{"id":"1.230180112","rc":[{"atb":[[1.73,2]],"id":68870841}],"con":true,"img":false}]}
{"op":"mcm","clk":"11540376999","pt":1719493736685,"mc":[{"id":"1.230180112","rc":[{"atb":[[1.71,0]],"id":58974183}],"con":true,"img":false}]}
{"op":"mcm","clk":"11540377006","pt":1719493736788,"mc":[{"id":"1.230180112","rc":[{"atb":[[1.73,2]],"id":58974183}],"con":true,"img":false}]}
{"op":"mcm","clk":"11540377092","pt":1719493738193,"mc":[{"id":"1.230180112","rc":[{"atb":[[1.72,0]],"id":58974183}],"con":true,"img":false}]}
{"op":"mcm","clk":"11540377113","pt":1719493738509,"mc":[{"id":"1.230180112","rc":[{"atb":[[1.72,0]],"id":68870841}],"con":true,"img":false}]}
{"op":"mcm","clk":"11540377157","pt":1719493739084,"mc":[{"id":"1.230180112","rc":[{"atb":[[1.73,0]],"id":68870841}],"con":true,"img":false}]}
{"op":"mcm","clk":"11540377165","pt":1719493739185,"mc":[{"id":"1.230180112","rc":[{"atb":[[1.71,2]],"id":68870841}],"con":true,"img":false}]}
{"op":"mcm","clk":"11540377193","pt":1719493739602,"mc":[{"id":"1.230180112","rc":[{"atb":[[1.73,0]],"id":58974183}],"con":true,"img":false}]}
{"op":"mcm","clk":"11540377201","pt":1719493739705,"mc":[{"id":"1.230180112","rc":[{"atb":[[1.71,2]],"id":58974183}],"con":true,"img":false}]}
{"op":"mcm","clk":"11540377317","pt":1719493741368,"mc":[{"id":"1.230180112","rc":[{"atb":[[1.72,1.78]],"id":58974183}],"con":true,"img":false}]}
{"op":"mcm","clk":"11540377339","pt":1719493741678,"mc":[{"id":"1.230180112","rc":[{"atb":[[1.72,1.82]],"id":68870841}],"con":true,"img":false}]}
{"op":"mcm","clk":"11540377369","pt":1719493742094,"mc":[{"id":"1.230180112","rc":[{"atb":[[1.71,0]],"id":68870841}],"con":true,"img":false}]}
{"op":"mcm","clk":"11540377381","pt":1719493742203,"mc":[{"id":"1.230180112","rc":[{"atb":[[1.73,2]],"id":68870841}],"con":true,"img":false}]}
{"op":"mcm","clk":"11540377415","pt":1719493742511,"mc":[{"id":"1.230180112","rc":[{"atb":[[1.71,0]],"id":58974183}],"con":true,"img":false}]}
{"op":"mcm","clk":"11540377427","pt":1719493742567,"mc":[{"id":"1.230180112","rc":[{"atb":[[1.73,2]],"id":58974183}],"con":true,"img":false}]}
{"op":"mcm","clk":"11540377545","pt":1719493744181,"mc":[{"id":"1.230180112","rc":[{"atb":[[1.72,0]],"id":58974183}],"con":true,"img":false}]}
{"op":"mcm","clk":"11540377574","pt":1719493744597,"mc":[{"id":"1.230180112","rc":[{"atb":[[1.72,0]],"id":68870841}],"con":true,"img":false}]}
{"op":"mcm","clk":"11540377587","pt":1719493744800,"mc":[{"id":"1.230180112","rc":[{"atb":[[1.73,0]],"id":58974183}],"con":true,"img":false}]}
{"op":"mcm","clk":"11540377593","pt":1719493744908,"mc":[{"id":"1.230180112","rc":[{"atb":[[1.71,2]],"id":58974183}],"con":true,"img":false}]}
{"op":"mcm","clk":"11540377683","pt":1719493745994,"mc":[{"id":"1.230180112","rc":[{"atb":[[1.73,0]],"id":68870841}],"con":true,"img":false}]}
{"op":"mcm","clk":"11540377694","pt":1719493746099,"mc":[{"id":"1.230180112","rc":[{"atb":[[1.71,2]],"id":68870841}],"con":true,"img":false}]}
{"op":"mcm","clk":"11540377766","pt":1719493747089,"mc":[{"id":"1.230180112","rc":[{"atb":[[1.72,1.9]],"id":58974183}],"con":true,"img":false}]}
{"op":"mcm","clk":"11540377868","pt":1719493748694,"mc":[{"id":"1.230180112","rc":[{"atb":[[1.71,0]],"id":58974183}],"con":true,"img":false}]}
{"op":"mcm","clk":"11540377879","pt":1719493748794,"mc":[{"id":"1.230180112","rc":[{"atb":[[1.73,2]],"id":58974183}],"con":true,"img":false}]}
{"op":"mcm","clk":"11540378007","pt":1719493750191,"mc":[{"id":"1.230180112","rc":[{"atb":[[1.72,0]],"id":58974183}],"con":true,"img":false}]}
{"op":"mcm","clk":"11540378031","pt":1719493750504,"mc":[{"id":"1.230180112","rc":[{"atb":[[1.72,1.76]],"id":68870841}],"con":true,"img":false}]}
{"op":"mcm","clk":"11540378124","pt":1719493751383,"mc":[{"id":"1.230180112","rc":[{"atb":[[1.71,0]],"id":68870841}],"con":true,"img":false}]}
{"op":"mcm","clk":"11540378132","pt":1719493751492,"mc":[{"id":"1.230180112","rc":[{"atb":[[1.73,2]],"id":68870841}],"con":true,"img":false}]}
{"op":"mcm","clk":"11540378165","pt":1719493751794,"mc":[{"id":"1.230180112","rc":[{"atb":[[1.73,0]],"id":58974183}],"con":true,"img":false}]}
{"op":"mcm","clk":"11540378173","pt":1719493751897,"mc":[{"id":"1.230180112","rc":[{"atb":[[1.71,2]],"id":58974183}],"con":true,"img":false}]}
{"op":"mcm","clk":"11540378264","pt":1719493753097,"mc":[{"id":"1.230180112","rc":[{"atb":[[1.72,0]],"id":68870841}],"con":true,"img":false}]}
{"op":"mcm","clk":"11540378375","pt":1719493754598,"mc":[{"id":"1.230180112","rc":[{"atb":[[1.73,0]],"id":68870841}],"con":true,"img":false}]}
{"op":"mcm","clk":"11540378381","pt":1719493754695,"mc":[{"id":"1.230180112","rc":[{"atb":[[1.71,2]],"id":68870841}],"con":true,"img":false}]}
{"op":"mcm","clk":"11540378495","pt":1719493756104,"mc":[{"id":"1.230180112","rc":[{"atb":[[1.72,1.67]],"id":58974183}],"con":true,"img":false}]}
{"op":"mcm","clk":"11540378519","pt":1719493756409,"mc":[{"id":"1.230180112","rc":[{"atb":[[1.72,1.76]],"id":68870841}],"con":true,"img":false}]}
{"op":"mcm","clk":"11540378553","pt":1719493756832,"mc":[{"id":"1.230180112","rc":[{"atb":[[1.71,0]],"id":68870841}],"con":true,"img":false}]}
{"op":"mcm","clk":"11540378561","pt":1719493756883,"mc":[{"id":"1.230180112","rc":[{"atb":[[1.73,2]],"id":68870841}],"con":true,"img":false}]}
{"op":"mcm","clk":"11540378592","pt":1719493757302,"mc":[{"id":"1.230180112","rc":[{"atb":[[1.71,0]],"id":58974183}],"con":true,"img":false}]}
{"op":"mcm","clk":"11540378601","pt":1719493757406,"mc":[{"id":"1.230180112","rc":[{"atb":[[1.73,2]],"id":58974183}],"con":true,"img":false}]}
{"op":"mcm","clk":"11540378748","pt":1719493759188,"mc":[{"id":"1.230180112","rc":[{"atb":[[1.72,0]],"id":58974183}],"con":true,"img":false}]}
{"op":"mcm","clk":"11540378788","pt":1719493759610,"mc":[{"id":"1.230180112","rc":[{"atb":[[1.72,0]],"id":68870841}],"con":true,"img":false}]}
{"op":"mcm","clk":"11540378838","pt":1719493760236,"mc":[{"id":"1.230180112","rc":[{"atb":[[1.73,0]],"id":68870841}],"con":true,"img":false}]}
{"op":"mcm","clk":"11540378851","pt":1719493760287,"mc":[{"id":"1.230180112","rc":[{"atb":[[1.71,2]],"id":68870841}],"con":true,"img":false}]}
{"op":"mcm","clk":"11540378941","pt":1719493760704,"mc":[{"id":"1.230180112","rc":[{"atb":[[1.73,0]],"id":58974183}],"con":true,"img":false}]}
{"op":"mcm","clk":"11540378948","pt":1719493760814,"mc":[{"id":"1.230180112","rc":[{"atb":[[1.71,2]],"id":58974183}],"con":true,"img":false}]}
{"op":"mcm","clk":"11540379089","pt":1719493762527,"mc":[{"id":"1.230180112","rc":[{"atb":[[1.72,1.95]],"id":58974183},{"spn":75.86,"spf":"NaN","id":58974183}],"con":true,"img":false}]}
{"op":"mcm","clk":"11540379184","pt":1719493762790,"mc":[{"id":"1.230180112","rc":[{"atb":[[1.72,1.57]],"id":68870841}],"con":true,"img":false}]}
{"op":"mcm","clk":"11540379270","pt":1719493764001,"mc":[{"id":"1.230180112","rc":[{"atb":[[1.71,0]],"id":68870841}],"con":true,"img":false}]}
{"op":"mcm","clk":"11540379280","pt":1719493764097,"mc":[{"id":"1.230180112","rc":[{"atb":[[1.73,2]],"id":68870841}],"con":true,"img":false}]}
{"op":"mcm","clk":"11540379302","pt":1719493764405,"mc":[{"id":"1.230180112","rc":[{"atb":[[1.71,0]],"id":58974183}],"con":true,"img":false}]}
{"op":"mcm","clk":"11540379312","pt":1719493764509,"mc":[{"id":"1.230180112","rc":[{"atb":[[1.73,2]],"id":58974183}],"con":true,"img":false}]}
{"op":"mcm","clk":"11540379388","pt":1719493765496,"mc":[{"id":"1.230180112","rc":[{"atb":[[1.72,0]],"id":58974183}],"con":true,"img":false}]}
{"op":"mcm","clk":"11540379423","pt":1719493765908,"mc":[{"id":"1.230180112","rc":[{"atb":[[1.72,0]],"id":68870841}],"con":true,"img":false}]}
{"op":"mcm","clk":"11540379462","pt":1719493766323,"mc":[{"id":"1.230180112","rc":[{"atb":[[1.73,0]],"id":68870841}],"con":true,"img":false}]}
{"op":"mcm","clk":"11540379473","pt":1719493766426,"mc":[{"id":"1.230180112","rc":[{"atb":[[1.71,2]],"id":68870841}],"con":true,"img":false}]}
{"op":"mcm","clk":"11540379503","pt":1719493766741,"mc":[{"id":"1.230180112","rc":[{"atb":[[1.73,0]],"id":58974183}],"con":true,"img":false}]}
{"op":"mcm","clk":"11540379513","pt":1719493766844,"mc":[{"id":"1.230180112","rc":[{"atb":[[1.71,2]],"id":58974183}],"con":true,"img":false}]}
{"op":"mcm","clk":"11540379856","pt":1719493771211,"mc":[{"id":"1.230180112","rc":[{"atb":[[1.72,1.92]],"id":58974183}],"con":true,"img":false}]}
{"op":"mcm","clk":"11540379880","pt":1719493771527,"mc":[{"id":"1.230180112","rc":[{"atb":[[1.72,1.73]],"id":68870841}],"con":true,"img":false}]}
{"op":"mcm","clk":"11540379967","pt":1719493772617,"mc":[{"id":"1.230180112","rc":[{"atb":[[1.71,0]],"id":68870841}],"con":true,"img":false}]}
{"op":"mcm","clk":"11540379976","pt":1719493772723,"mc":[{"id":"1.230180112","rc":[{"atb":[[1.73,2]],"id":68870841}],"con":true,"img":false}]}
{"op":"mcm","clk":"11540380009","pt":1719493773131,"mc":[{"id":"1.230180112","rc":[{"atb":[[1.71,0]],"id":58974183}],"con":true,"img":false}]}
{"op":"mcm","clk":"11540380017","pt":1719493773235,"mc":[{"id":"1.230180112","rc":[{"atb":[[1.73,2]],"id":58974183}],"con":true,"img":false}]}
{"op":"mcm","clk":"11540380129","pt":1719493774340,"mc":[{"id":"1.230180112","rc":[{"atb":[[1.72,0]],"id":58974183}],"con":true,"img":false}]}
{"op":"mcm","clk":"11540380167","pt":1719493774603,"mc":[{"id":"1.230180112","rc":[{"atb":[[1.72,0]],"id":68870841}],"con":true,"img":false}]}
{"op":"mcm","clk":"11540380309","pt":1719493776061,"mc":[{"id":"1.230180112","rc":[{"atb":[[1.73,0]],"id":68870841}],"con":true,"img":false}]}
{"op":"mcm","clk":"11540380319","pt":1719493776110,"mc":[{"id":"1.230180112","rc":[{"atb":[[1.71,2]],"id":68870841}],"con":true,"img":false}]}
{"op":"mcm","clk":"11540380345","pt":1719493776421,"mc":[{"id":"1.230180112","rc":[{"atb":[[1.73,0]],"id":58974183}],"con":true,"img":false}]}
{"op":"mcm","clk":"11540380357","pt":1719493776528,"mc":[{"id":"1.230180112","rc":[{"atb":[[1.71,2]],"id":58974183}],"con":true,"img":false}]}
{"op":"mcm","clk":"11540380427","pt":1719493777310,"mc":[{"id":"1.230180112","rc":[{"atb":[[1.72,1.9]],"id":58974183}],"con":true,"img":false}]}
{"op":"mcm","clk":"11540380535","pt":1719493778561,"mc":[{"id":"1.230180112","rc":[{"atb":[[1.71,0]],"id":58974183}],"con":true,"img":false}]}
{"op":"mcm","clk":"11540380543","pt":1719493778611,"mc":[{"id":"1.230180112","rc":[{"atb":[[1.73,2]],"id":58974183}],"con":true,"img":false}]}
{"op":"mcm","clk":"11540380670","pt":1719493780324,"mc":[{"id":"1.230180112","rc":[{"atb":[[1.72,0]],"id":58974183}],"con":true,"img":false}]}
{"op":"mcm","clk":"11540380688","pt":1719493780634,"mc":[{"id":"1.230180112","rc":[{"atb":[[1.72,1.83]],"id":68870841}],"con":true,"img":false}]}
{"op":"mcm","clk":"11540380760","pt":1719493781732,"mc":[{"id":"1.230180112","rc":[{"atb":[[1.71,0]],"id":68870841}],"con":true,"img":false}]}
{"op":"mcm","clk":"11540380771","pt":1719493781835,"mc":[{"id":"1.230180112","rc":[{"atb":[[1.73,2]],"id":68870841}],"con":true,"img":false}]}
{"op":"mcm","clk":"11540380793","pt":1719493782146,"mc":[{"id":"1.230180112","rc":[{"atb":[[1.73,0]],"id":58974183}],"con":true,"img":false}]}
{"op":"mcm","clk":"11540380803","pt":1719493782248,"mc":[{"id":"1.230180112","rc":[{"atb":[[1.71,2]],"id":58974183}],"con":true,"img":false}]}
{"op":"mcm","clk":"11540380915","pt":1719493783446,"mc":[{"id":"1.230180112","rc":[{"atb":[[1.72,1.9]],"id":58974183}],"con":true,"img":false}]}
{"op":"mcm","clk":"11540380939","pt":1719493783752,"mc":[{"id":"1.230180112","rc":[{"atb":[[1.72,0]],"id":68870841}],"con":true,"img":false}]}
{"op":"mcm","clk":"11540381040","pt":1719493785053,"mc":[{"id":"1.230180112","rc":[{"atb":[[1.73,0]],"id":68870841}],"con":true,"img":false}]}
{"op":"mcm","clk":"11540381049","pt":1719493785160,"mc":[{"id":"1.230180112","rc":[{"atb":[[1.71,2]],"id":68870841}],"con":true,"img":false}]}
{"op":"mcm","clk":"11540381084","pt":1719493785530,"mc":[{"id":"1.230180112","rc":[{"atb":[[1.71,0]],"id":58974183}],"con":true,"img":false}]}
{"op":"mcm","clk":"11540381097","pt":1719493785625,"mc":[{"id":"1.230180112","rc":[{"atb":[[1.73,2]],"id":58974183}],"con":true,"img":false}]}
{"op":"mcm","clk":"11540381164","pt":1719493786353,"mc":[{"id":"1.230180112","rc":[{"atb":[[1.72,0]],"id":58974183}],"con":true,"img":false}]}
{"op":"mcm","clk":"11540381228","pt":1719493786926,"mc":[{"id":"1.230180112","rc":[{"atb":[[1.73,0]],"id":58974183}],"con":true,"img":false}]}
{"op":"mcm","clk":"11540381240","pt":1719493787033,"mc":[{"id":"1.230180112","rc":[{"atb":[[1.71,2]],"id":58974183}],"con":true,"img":false}]}
{"op":"mcm","clk":"11540381412","pt":1719493789265,"mc":[{"id":"1.230180112","rc":[{"atb":[[1.72,1.54]],"id":58974183}],"con":true,"img":false}]}
{"op":"mcm","clk":"11540381437","pt":1719493789529,"mc":[{"id":"1.230180112","rc":[{"atb":[[1.72,1.54]],"id":68870841}],"con":true,"img":false}]}
{"op":"mcm","clk":"11540381540","pt":1719493791030,"mc":[{"id":"1.230180112","rc":[{"atb":[[1.71,0]],"id":68870841}],"con":true,"img":false}]}
{"op":"mcm","clk":"11540381548","pt":1719493791139,"mc":[{"id":"1.230180112","rc":[{"atb":[[1.73,2]],"id":68870841}],"con":true,"img":false}]}
{"op":"mcm","clk":"11540381565","pt":1719493791348,"mc":[{"id":"1.230180112","rc":[{"atb":[[1.71,0]],"id":58974183}],"con":true,"img":false}]}
{"op":"mcm","clk":"11540381574","pt":1719493791448,"mc":[{"id":"1.230180112","rc":[{"atb":[[1.73,2]],"id":58974183}],"con":true,"img":false}]}
{"op":"mcm","clk":"11540381657","pt":1719493792338,"mc":[{"id":"1.230180112","rc":[{"atb":[[1.72,0]],"id":58974183}],"con":true,"img":false}]}
{"op":"mcm","clk":"11540381682","pt":1719493792647,"mc":[{"id":"1.230180112","rc":[{"atb":[[1.72,0]],"id":68870841}],"con":true,"img":false}]}
{"op":"mcm","clk":"11540381718","pt":1719493793060,"mc":[{"id":"1.230180112","rc":[{"atb":[[1.73,0]],"id":68870841}],"con":true,"img":false}]}
{"op":"mcm","clk":"11540381736","pt":1719493793267,"mc":[{"id":"1.230180112","rc":[{"atb":[[1.71,2]],"id":68870841}],"con":true,"img":false}]}
{"op":"mcm","clk":"11540381766","pt":1719493793530,"mc":[{"id":"1.230180112","rc":[{"atb":[[1.73,0]],"id":58974183}],"con":true,"img":false}]}
{"op":"mcm","clk":"11540381777","pt":1719493793631,"mc":[{"id":"1.230180112","rc":[{"atb":[[1.71,2]],"id":58974183}],"con":true,"img":false}]}
{"op":"mcm","clk":"11540381907","pt":1719493795348,"mc":[{"id":"1.230180112","rc":[{"atb":[[1.72,1.95]],"id":58974183}],"con":true,"img":false}]}
{"op":"mcm","clk":"11540381933","pt":1719493795662,"mc":[{"id":"1.230180112","rc":[{"atb":[[1.72,1.8]],"id":68870841}],"con":true,"img":false}]}
{"op":"mcm","clk":"11540381986","pt":1719493796236,"mc":[{"id":"1.230180112","rc":[{"atb":[[1.71,0]],"id":68870841}],"con":true,"img":false}]}
{"op":"mcm","clk":"11540381998","pt":1719493796339,"mc":[{"id":"1.230180112","rc":[{"atb":[[1.73,2]],"id":68870841}],"con":true,"img":false}]}
{"op":"mcm","clk":"11540382035","pt":1719493796653,"mc":[{"id":"1.230180112","rc":[{"atb":[[1.71,0]],"id":58974183}],"con":true,"img":false}]}
{"op":"mcm","clk":"11540382045","pt":1719493796752,"mc":[{"id":"1.230180112","rc":[{"atb":[[1.73,2]],"id":58974183}],"con":true,"img":false}]}
{"op":"mcm","clk":"11540382200","pt":1719493798365,"mc":[{"id":"1.230180112","rc":[{"atb":[[1.72,0]],"id":58974183}],"con":true,"img":false}]}
{"op":"mcm","clk":"11540382229","pt":1719493798688,"mc":[{"id":"1.230180112","rc":[{"atb":[[1.72,0]],"id":68870841}],"con":true,"img":false}]}
{"op":"mcm","clk":"11540382243","pt":1719493798878,"mc":[{"id":"1.230180112","rc":[{"atb":[[1.73,0]],"id":58974183}],"con":true,"img":false}]}
{"op":"mcm","clk":"11540382254","pt":1719493798981,"mc":[{"id":"1.230180112","rc":[{"atb":[[1.71,2]],"id":58974183}],"con":true,"img":false}]}
{"op":"mcm","clk":"11540382323","pt":1719493799862,"mc":[{"id":"1.230180112","rc":[{"atb":[[1.73,0]],"id":68870841}],"con":true,"img":false}]}
{"op":"mcm","clk":"11540382330","pt":1719493799971,"mc":[{"id":"1.230180112","rc":[{"atb":[[1.71,2]],"id":68870841}],"con":true,"img":false}]}
{"op":"mcm","clk":"11540382451","pt":1719493801338,"mc":[{"id":"1.230180112","rc":[{"atb":[[1.72,1.86]],"id":58974183}],"con":true,"img":false}]}
{"op":"mcm","clk":"11540382517","pt":1719493802173,"mc":[{"id":"1.230180112","rc":[{"atb":[[1.71,0]],"id":58974183}],"con":true,"img":false}]}
{"op":"mcm","clk":"11540382526","pt":1719493802272,"mc":[{"id":"1.230180112","rc":[{"atb":[[1.73,2]],"id":58974183}],"con":true,"img":false}]}
{"op":"mcm","clk":"11540382716","pt":1719493804468,"mc":[{"id":"1.230180112","rc":[{"atb":[[1.72,0]],"id":58974183}],"con":true,"img":false}]}
{"op":"mcm","clk":"11540382747","pt":1719493804777,"mc":[{"id":"1.230180112","rc":[{"atb":[[1.72,1.79]],"id":68870841}],"con":true,"img":false}]}
{"op":"mcm","clk":"11540382772","pt":1719493805042,"mc":[{"id":"1.230180112","rc":[{"atb":[[1.73,0]],"id":58974183}],"con":true,"img":false}]}
{"op":"mcm","clk":"11540382779","pt":1719493805143,"mc":[{"id":"1.230180112","rc":[{"atb":[[1.71,2]],"id":58974183}],"con":true,"img":false}]}
{"op":"mcm","clk":"11540382929","pt":1719493806766,"mc":[{"id":"1.230180112","rc":[{"atb":[[1.71,0]],"id":68870841}],"con":true,"img":false}]}
{"op":"mcm","clk":"11540382937","pt":1719493806862,"mc":[{"id":"1.230180112","rc":[{"atb":[[1.73,2]],"id":68870841}],"con":true,"img":false}]}
{"op":"mcm","clk":"11540382984","pt":1719493807388,"mc":[{"id":"1.230180112","rc":[{"atb":[[1.72,1.73]],"id":58974183}],"con":true,"img":false}]}
{"op":"mcm","clk":"11540383021","pt":1719493807750,"mc":[{"id":"1.230180112","rc":[{"atb":[[1.72,0]],"id":68870841}],"con":true,"img":false}]}
{"op":"mcm","clk":"11540383027","pt":1719493807855,"mc":[{"id":"1.230180112","rc":[{"atb":[[1.71,0]],"id":58974183}],"con":true,"img":false}]}
{"op":"mcm","clk":"11540383036","pt":1719493807953,"mc":[{"id":"1.230180112","rc":[{"atb":[[1.73,2]],"id":58974183}],"con":true,"img":false}]}
{"op":"mcm","clk":"11540383115","pt":1719493808891,"mc":[{"id":"1.230180112","rc":[{"atb":[[1.73,0]],"id":68870841}],"con":true,"img":false}]}
{"op":"mcm","clk":"11540383125","pt":1719493808996,"mc":[{"id":"1.230180112","rc":[{"atb":[[1.71,2]],"id":68870841}],"con":true,"img":false}]}
{"op":"mcm","clk":"11540383245","pt":1719493810401,"mc":[{"id":"1.230180112","rc":[{"atb":[[1.72,0]],"id":58974183}],"con":true,"img":false}]}
{"op":"mcm","clk":"11540383274","pt":1719493810661,"mc":[{"id":"1.230180112","rc":[{"atb":[[1.72,1.56]],"id":68870841}],"con":true,"img":false}]}
{"op":"mcm","clk":"11540383360","pt":1719493811697,"mc":[{"id":"1.230180112","rc":[{"atb":[[1.71,0]],"id":68870841}],"con":true,"img":false}]}
{"op":"mcm","clk":"11540383370","pt":1719493811758,"mc":[{"id":"1.230180112","rc":[{"atb":[[1.73,2]],"id":68870841}],"con":true,"img":false}]}
{"op":"mcm","clk":"11540383395","pt":1719493812062,"mc":[{"id":"1.230180112","rc":[{"atb":[[1.73,0]],"id":58974183}],"con":true,"img":false}]}
{"op":"mcm","clk":"11540383404","pt":1719493812165,"mc":[{"id":"1.230180112","rc":[{"atb":[[1.71,2]],"id":58974183}],"con":true,"img":false}]}
{"op":"mcm","clk":"11540383515","pt":1719493813465,"mc":[{"id":"1.230180112","rc":[{"atb":[[1.72,0]],"id":68870841}],"con":true,"img":false}]}
{"op":"mcm","clk":"11540383577","pt":1719493814194,"mc":[{"id":"1.230180112","rc":[{"atb":[[1.73,0]],"id":68870841}],"con":true,"img":false}]}
{"op":"mcm","clk":"11540383592","pt":1719493814298,"mc":[{"id":"1.230180112","rc":[{"atb":[[1.71,2]],"id":68870841}],"con":true,"img":false}]}
{"op":"mcm","clk":"11540383770","pt":1719493816579,"mc":[{"id":"1.230180112","rc":[{"atb":[[1.72,1.72]],"id":58974183}],"con":true,"img":false}]}
{"op":"mcm","clk":"11540383794","pt":1719493816894,"mc":[{"id":"1.230180112","rc":[{"atb":[[1.72,1.79]],"id":68870841}],"con":true,"img":false}]}
{"op":"mcm","clk":"11540383850","pt":1719493817461,"mc":[{"id":"1.230180112","rc":[{"atb":[[1.71,0]],"id":58974183}],"con":true,"img":false}]}
{"op":"mcm","clk":"11540383861","pt":1719493817565,"mc":[{"id":"1.230180112","rc":[{"atb":[[1.73,2]],"id":58974183}],"con":true,"img":false}]}
{"op":"mcm","clk":"11540383935","pt":1719493818600,"mc":[{"id":"1.230180112","rc":[{"atb":[[1.71,0]],"id":68870841}],"con":true,"img":false}]}
{"op":"mcm","clk":"11540383942","pt":1719493818653,"mc":[{"id":"1.230180112","rc":[{"atb":[[1.73,2]],"id":68870841}],"con":true,"img":false}]}
{"op":"mcm","clk":"11540384023","pt":1719493819590,"mc":[{"id":"1.230180112","rc":[{"atb":[[1.72,0]],"id":58974183}],"con":true,"img":false}]}
{"op":"mcm","clk":"11540384060","pt":1719493819999,"mc":[{"id":"1.230180112","rc":[{"atb":[[1.72,0]],"id":68870841}],"con":true,"img":false}]}
{"op":"mcm","clk":"11540384124","pt":1719493820676,"mc":[{"id":"1.230180112","rc":[{"atb":[[1.73,0]],"id":68870841}],"con":true,"img":false}]}
{"op":"mcm","clk":"11540384139","pt":1719493820783,"mc":[{"id":"1.230180112","rc":[{"atb":[[1.71,2]],"id":68870841}],"con":true,"img":false}]}
{"op":"mcm","clk":"11540384164","pt":1719493821089,"mc":[{"id":"1.230180112","rc":[{"atb":[[1.73,0]],"id":58974183}],"con":true,"img":false}]}
{"op":"mcm","clk":"11540384173","pt":1719493821196,"mc":[{"id":"1.230180112","rc":[{"atb":[[1.71,2]],"id":58974183}],"con":true,"img":false}]}
{"op":"mcm","clk":"11540384279","pt":1719493822494,"mc":[{"id":"1.230180112","rc":[{"atb":[[1.72,1.98]],"id":58974183}],"con":true,"img":false}]}
{"op":"mcm","clk":"11540384321","pt":1719493823067,"mc":[{"id":"1.230180112","rc":[{"atb":[[1.71,0]],"id":58974183}],"con":true,"img":false}]}
{"op":"mcm","clk":"11540384332","pt":1719493823171,"mc":[{"id":"1.230180112","rc":[{"atb":[[1.73,2]],"id":58974183}],"con":true,"img":false}]}
{"op":"mcm","clk":"11540384514","pt":1719493825594,"mc":[{"id":"1.230180112","rc":[{"atb":[[1.72,0]],"id":58974183}],"con":true,"img":false}]}
{"op":"mcm","clk":"11540384537","pt":1719493825902,"mc":[{"id":"1.230180112","rc":[{"atb":[[1.72,1.94]],"id":68870841}],"con":true,"img":false}]}
{"op":"mcm","clk":"11540384583","pt":1719493826472,"mc":[{"id":"1.230180112","rc":[{"atb":[[1.71,0]],"id":68870841}],"con":true,"img":false}]}
{"op":"mcm","clk":"11540384593","pt":1719493826580,"mc":[{"id":"1.230180112","rc":[{"atb":[[1.73,2]],"id":68870841}],"con":true,"img":false}]}
{"op":"mcm","clk":"11540384656","pt":1719493827090,"mc":[{"id":"1.230180112","rc":[{"atb":[[1.73,0]],"id":58974183}],"con":true,"img":false}]}
{"op":"mcm","clk":"11540384664","pt":1719493827198,"mc":[{"id":"1.230180112","rc":[{"atb":[[1.71,2]],"id":58974183}],"con":true,"img":false}]}
{"op":"mcm","clk":"11540384772","pt":1719493828489,"mc":[{"id":"1.230180112","rc":[{"atb":[[1.72,0]],"id":68870841}],"con":true,"img":false}]}
{"op":"mcm","clk":"11540384809","pt":1719493828904,"mc":[{"id":"1.230180112","rc":[{"atb":[[1.73,0]],"id":68870841}],"con":true,"img":false}]}
{"op":"mcm","clk":"11540384820","pt":1719493829006,"mc":[{"id":"1.230180112","rc":[{"atb":[[1.71,2]],"id":68870841}],"con":true,"img":false}]}
{"op":"mcm","clk":"11540385030","pt":1719493831527,"mc":[{"id":"1.230180112","rc":[{"atb":[[1.72,1.81]],"id":58974183}],"con":true,"img":false}]}
{"op":"mcm","clk":"11540385060","pt":1719493831790,"mc":[{"id":"1.230180112","rc":[{"atb":[[1.72,1.53]],"id":68870841}],"con":true,"img":false}]}
{"op":"mcm","clk":"11540385093","pt":1719493832099,"mc":[{"id":"1.230180112","rc":[{"atb":[[1.71,0]],"id":58974183}],"con":true,"img":false}]}
{"op":"mcm","clk":"11540385103","pt":1719493832205,"mc":[{"id":"1.230180112","rc":[{"atb":[[1.73,2]],"id":58974183}],"con":true,"img":false}]}
{"op":"mcm","clk":"11540385156","pt":1719493832888,"mc":[{"id":"1.230180112","rc":[{"atb":[[1.71,0]],"id":68870841}],"con":true,"img":false}]}
{"op":"mcm","clk":"11540385169","pt":1719493832983,"mc":[{"id":"1.230180112","rc":[{"atb":[[1.73,2]],"id":68870841}],"con":true,"img":false}]}
{"op":"mcm","clk":"11540385291","pt":1719493834602,"mc":[{"id":"1.230180112","rc":[{"atb":[[1.72,0]],"id":58974183}],"con":true,"img":false}]}
{"op":"mcm","clk":"11540385316","pt":1719493834911,"mc":[{"id":"1.230180112","rc":[{"atb":[[1.72,0]],"id":68870841}],"con":true,"img":false}]}
{"op":"mcm","clk":"11540385376","pt":1719493835486,"mc":[{"id":"1.230180112","rc":[{"atb":[[1.73,0]],"id":68870841}],"con":true,"img":false}]}
{"op":"mcm","clk":"11540385388","pt":1719493835588,"mc":[{"id":"1.230180112","rc":[{"atb":[[1.71,2]],"id":68870841}],"con":true,"img":false}]}
{"op":"mcm","clk":"11540385429","pt":1719493835999,"mc":[{"id":"1.230180112","rc":[{"atb":[[1.73,0]],"id":58974183}],"con":true,"img":false}]}
{"op":"mcm","clk":"11540385442","pt":1719493836108,"mc":[{"id":"1.230180112","rc":[{"atb":[[1.71,2]],"id":58974183}],"con":true,"img":false}]}
{"op":"mcm","clk":"11540385595","pt":1719493837619,"mc":[{"id":"1.230180112","rc":[{"atb":[[1.72,1.73]],"id":58974183}],"con":true,"img":false}]}
{"op":"mcm","clk":"11540385619","pt":1719493837931,"mc":[{"id":"1.230180112","rc":[{"atb":[[1.72,1.59]],"id":68870841}],"con":true,"img":false}]}
{"op":"mcm","clk":"11540385682","pt":1719493838605,"mc":[{"id":"1.230180112","rc":[{"atb":[[1.71,0]],"id":68870841}],"con":true,"img":false}]}
{"op":"mcm","clk":"11540385689","pt":1719493838714,"mc":[{"id":"1.230180112","rc":[{"atb":[[1.73,2]],"id":68870841}],"con":true,"img":false}]}
{"op":"mcm","clk":"11540385740","pt":1719493839386,"mc":[{"id":"1.230180112","rc":[{"atb":[[1.71,0]],"id":58974183}],"con":true,"img":false}]}
{"op":"mcm","clk":"11540385746","pt":1719493839492,"mc":[{"id":"1.230180112","rc":[{"atb":[[1.73,2]],"id":58974183}],"con":true,"img":false}]}
{"op":"mcm","clk":"11540385837","pt":1719493840641,"mc":[{"id":"1.230180112","rc":[{"atb":[[1.72,0]],"id":58974183}],"con":true,"img":false}]}
{"op":"mcm","clk":"11540385884","pt":1719493841071,"mc":[{"id":"1.230180112","rc":[{"atb":[[1.72,0]],"id":68870841}],"con":true,"img":false}]}
{"op":"mcm","clk":"11540385944","pt":1719493841739,"mc":[{"id":"1.230180112","rc":[{"atb":[[1.73,0]],"id":68870841}],"con":true,"img":false}]}
{"op":"mcm","clk":"11540385952","pt":1719493841793,"mc":[{"id":"1.230180112","rc":[{"atb":[[1.71,2]],"id":68870841}],"con":true,"img":false}]}
{"op":"mcm","clk":"11540385987","pt":1719493842219,"mc":[{"id":"1.230180112","rc":[{"atb":[[1.73,0]],"id":58974183}],"con":true,"img":false}]}
{"op":"mcm","clk":"11540385993","pt":1719493842315,"mc":[{"id":"1.230180112","rc":[{"atb":[[1.71,2]],"id":58974183}],"con":true,"img":false}]}
{"op":"mcm","clk":"11540386105","pt":1719493843613,"mc":[{"id":"1.230180112","rc":[{"atb":[[1.72,1.65]],"id":58974183}],"con":true,"img":false}]}
{"op":"mcm","clk":"11540386141","pt":1719493844135,"mc":[{"id":"1.230180112","rc":[{"atb":[[1.71,0]],"id":58974183}],"con":true,"img":false}]}
{"op":"mcm","clk":"11540386151","pt":1719493844237,"mc":[{"id":"1.230180112","rc":[{"atb":[[1.73,2]],"id":58974183}],"con":true,"img":false}]}
{"op":"mcm","clk":"11540386333","pt":1719493846721,"mc":[{"id":"1.230180112","rc":[{"atb":[[1.72,0]],"id":58974183}],"con":true,"img":false}]}
{"op":"mcm","clk":"11540386363","pt":1719493847032,"mc":[{"id":"1.230180112","rc":[{"atb":[[1.72,1.95]],"id":68870841}],"con":true,"img":false}]}
{"op":"mcm","clk":"11540386385","pt":1719493847233,"mc":[{"id":"1.230180112","rc":[{"atb":[[1.73,0]],"id":58974183}],"con":true,"img":false}]}
{"op":"mcm","clk":"11540386395","pt":1719493847336,"mc":[{"id":"1.230180112","rc":[{"atb":[[1.71,2]],"id":58974183}],"con":true,"img":false}]}
{"op":"mcm","clk":"11540386451","pt":1719493847920,"mc":[{"id":"1.230180112","rc":[{"atb":[[1.71,0]],"id":68870841}],"con":true,"img":false}]}
{"op":"mcm","clk":"11540386460","pt":1719493848017,"mc":[{"id":"1.230180112","rc":[{"atb":[[1.73,2]],"id":68870841}],"con":true,"img":false}]}
{"op":"mcm","clk":"11540386596","pt":1719493849732,"mc":[{"id":"1.230180112","rc":[{"atb":[[1.72,0]],"id":68870841}],"con":true,"img":false}]}
{"op":"mcm","clk":"11540386703","pt":1719493851133,"mc":[{"id":"1.230180112","rc":[{"atb":[[1.73,0]],"id":68870841}],"con":true,"img":false}]}
{"op":"mcm","clk":"11540386715","pt":1719493851241,"mc":[{"id":"1.230180112","rc":[{"atb":[[1.71,2]],"id":68870841}],"con":true,"img":false}]}
{"op":"mcm","clk":"11540386851","pt":1719493852854,"mc":[{"id":"1.230180112","rc":[{"atb":[[1.72,1.62]],"id":58974183}],"con":true,"img":false}]}
{"op":"mcm","clk":"11540386886","pt":1719493853212,"mc":[{"id":"1.230180112","rc":[{"atb":[[1.72,1.75]],"id":68870841}],"con":true,"img":false}]}
{"op":"mcm","clk":"11540386935","pt":1719493853731,"mc":[{"id":"1.230180112","rc":[{"atb":[[1.71,0]],"id":68870841}],"con":true,"img":false}]}
{"op":"mcm","clk":"11540386944","pt":1719493853840,"mc":[{"id":"1.230180112","rc":[{"atb":[[1.73,2]],"id":68870841}],"con":true,"img":false}]}
{"op":"mcm","clk":"11540386967","pt":1719493854146,"mc":[{"id":"1.230180112","rc":[{"atb":[[1.71,0]],"id":58974183}],"con":true,"img":false}]}
{"op":"mcm","clk":"11540386976","pt":1719493854248,"mc":[{"id":"1.230180112","rc":[{"atb":[[1.73,2]],"id":58974183}],"con":true,"img":false}]}
{"op":"mcm","clk":"11540387085","pt":1719493855719,"mc":[{"id":"1.230180112","rc":[{"atb":[[1.72,0]],"id":58974183}],"con":true,"img":false}]}
{"op":"mcm","clk":"11540387108","pt":1719493856028,"mc":[{"id":"1.230180112","rc":[{"atb":[[1.72,0]],"id":68870841}],"con":true,"img":false}]}
{"op":"mcm","clk":"11540387139","pt":1719493856453,"mc":[{"id":"1.230180112","rc":[{"atb":[[1.73,0]],"id":68870841}],"con":true,"img":false}]}
{"op":"mcm","clk":"11540387152","pt":1719493856553,"mc":[{"id":"1.230180112","rc":[{"atb":[[1.71,2]],"id":68870841}],"con":true,"img":false}]}
{"op":"mcm","clk":"11540387175","pt":1719493856821,"mc":[{"id":"1.230180112","rc":[{"atb":[[1.73,0]],"id":58974183}],"con":true,"img":false}]}
{"op":"mcm","clk":"11540387186","pt":1719493856921,"mc":[{"id":"1.230180112","rc":[{"atb":[[1.71,2]],"id":58974183}],"con":true,"img":false}]}
{"op":"mcm","clk":"11540387644","pt":1719493861724,"mc":[{"id":"1.230180112","rc":[{"atb":[[1.72,1.86]],"id":58974183}],"con":true,"img":false}]}
{"op":"mcm","clk":"11540387678","pt":1719493862027,"mc":[{"id":"1.230180112","rc":[{"atb":[[1.72,1.99]],"id":68870841}],"con":true,"img":false}]}
{"op":"mcm","clk":"11540387735","pt":1719493862859,"mc":[{"id":"1.230180112","rc":[{"atb":[[1.71,0]],"id":68870841}],"con":true,"img":false}]}
{"op":"mcm","clk":"11540387745","pt":1719493862970,"mc":[{"id":"1.230180112","rc":[{"atb":[[1.73,2]],"id":68870841}],"con":true,"img":false}]}
{"op":"mcm","clk":"11540387782","pt":1719493863226,"mc":[{"id":"1.230180112","rc":[{"atb":[[1.71,0]],"id":58974183}],"con":true,"img":false}]}
{"op":"mcm","clk":"11540387793","pt":1719493863329,"mc":[{"id":"1.230180112","rc":[{"atb":[[1.73,2]],"id":58974183}],"con":true,"img":false}]}
{"op":"mcm","clk":"11540387918","pt":1719493864733,"mc":[{"id":"1.230180112","rc":[{"atb":[[1.72,0]],"id":58974183}],"con":true,"img":false}]}
{"op":"mcm","clk":"11540387945","pt":1719493865043,"mc":[{"id":"1.230180112","rc":[{"atb":[[1.72,0]],"id":68870841}],"con":true,"img":false}]}
{"op":"mcm","clk":"11540387995","pt":1719493865723,"mc":[{"id":"1.230180112","rc":[{"atb":[[1.73,0]],"id":68870841}],"con":true,"img":false}]}
{"op":"mcm","clk":"11540388007","pt":1719493865823,"mc":[{"id":"1.230180112","rc":[{"atb":[[1.71,2]],"id":68870841}],"con":true,"img":false}]}
{"op":"mcm","clk":"11540388046","pt":1719493866335,"mc":[{"id":"1.230180112","rc":[{"atb":[[1.73,0]],"id":58974183}],"con":true,"img":false}]}
{"op":"mcm","clk":"11540388053","pt":1719493866439,"mc":[{"id":"1.230180112","rc":[{"atb":[[1.71,2]],"id":58974183}],"con":true,"img":false}]}
{"op":"mcm","clk":"11540388440","pt":1719493870743,"mc":[{"id":"1.230180112","rc":[{"atb":[[1.72,1.64]],"id":58974183}],"con":true,"img":false}]}
{"op":"mcm","clk":"11540388461","pt":1719493871051,"mc":[{"id":"1.230180112","rc":[{"atb":[[1.72,1.8]],"id":68870841}],"con":true,"img":false}]}
{"op":"mcm","clk":"11540388496","pt":1719493871725,"mc":[{"id":"1.230180112","rc":[{"atb":[[1.71,0]],"id":68870841}],"con":true,"img":false}]}
{"op":"mcm","clk":"11540388505","pt":1719493871839,"mc":[{"id":"1.230180112","rc":[{"atb":[[1.73,2]],"id":68870841}],"con":true,"img":false}]}
{"op":"mcm","clk":"11540388528","pt":1719493872138,"mc":[{"id":"1.230180112","rc":[{"atb":[[1.71,0]],"id":58974183}],"con":true,"img":false}]}
{"op":"mcm","clk":"11540388539","pt":1719493872247,"mc":[{"id":"1.230180112","rc":[{"atb":[[1.73,2]],"id":58974183}],"con":true,"img":false}]}
{"op":"mcm","clk":"11540388661","pt":1719493873762,"mc":[{"id":"1.230180112","rc":[{"atb":[[1.72,0]],"id":58974183}],"con":true,"img":false}]}
{"op":"mcm","clk":"11540388690","pt":1719493874021,"mc":[{"id":"1.230180112","rc":[{"atb":[[1.72,0]],"id":68870841}],"con":true,"img":false}]}
{"op":"mcm","clk":"11540388754","pt":1719493874743,"mc":[{"id":"1.230180112","rc":[{"atb":[[1.73,0]],"id":68870841}],"con":true,"img":false}]}
{"op":"mcm","clk":"11540388767","pt":1719493874848,"mc":[{"id":"1.230180112","rc":[{"atb":[[1.71,2]],"id":68870841}],"con":true,"img":false}]}
{"op":"mcm","clk":"11540388791","pt":1719493875161,"mc":[{"id":"1.230180112","rc":[{"atb":[[1.73,0]],"id":58974183}],"con":true,"img":false}]}
{"op":"mcm","clk":"11540388801","pt":1719493875261,"mc":[{"id":"1.230180112","rc":[{"atb":[[1.71,2]],"id":58974183}],"con":true,"img":false}]}
{"op":"mcm","clk":"11540388915","pt":1719493876767,"mc":[{"id":"1.230180112","rc":[{"atb":[[1.72,1.53]],"id":58974183}],"con":true,"img":false}]}
{"op":"mcm","clk":"11540388934","pt":1719493877074,"mc":[{"id":"1.230180112","rc":[{"atb":[[1.72,1.52]],"id":68870841}],"con":true,"img":false}]}
{"op":"mcm","clk":"11540389016","pt":1719493878371,"mc":[{"id":"1.230180112","rc":[{"atb":[[1.71,0]],"id":68870841}],"con":true,"img":false}]}
{"op":"mcm","clk":"11540389025","pt":1719493878476,"mc":[{"id":"1.230180112","rc":[{"atb":[[1.73,2]],"id":68870841}],"con":true,"img":false}]}
{"op":"mcm","clk":"11540389049","pt":1719493878740,"mc":[{"id":"1.230180112","rc":[{"atb":[[1.71,0]],"id":58974183}],"con":true,"img":false}]}
{"op":"mcm","clk":"11540389060","pt":1719493878841,"mc":[{"id":"1.230180112","rc":[{"atb":[[1.73,2]],"id":58974183}],"con":true,"img":false}]}
{"op":"mcm","clk":"11540389151","pt":1719493879884,"mc":[{"id":"1.230180112","rc":[{"atb":[[1.72,0]],"id":58974183}],"con":true,"img":false}]}
{"op":"mcm","clk":"11540389175","pt":1719493880139,"mc":[{"id":"1.230180112","rc":[{"atb":[[1.72,0]],"id":68870841}],"con":true,"img":false}]}
{"op":"mcm","clk":"11540389204","pt":1719493880554,"mc":[{"id":"1.230180112","rc":[{"atb":[[1.73,0]],"id":58974183}],"con":true,"img":false}]}
{"op":"mcm","clk":"11540389210","pt":1719493880658,"mc":[{"id":"1.230180112","rc":[{"atb":[[1.71,2]],"id":58974183}],"con":true,"img":false}]}
{"op":"mcm","clk":"11540389252","pt":1719493881341,"mc":[{"id":"1.230180112","rc":[{"atb":[[1.73,0]],"id":68870841}],"con":true,"img":false}]}
{"op":"mcm","clk":"11540389258","pt":1719493881446,"mc":[{"id":"1.230180112","rc":[{"atb":[[1.71,2]],"id":68870841}],"con":true,"img":false}]}
{"op":"mcm","clk":"11540389370","pt":1719493882853,"mc":[{"id":"1.230180112","rc":[{"atb":[[1.72,1.9]],"id":58974183}],"con":true,"img":false}]}
{"op":"mcm","clk":"11540389395","pt":1719493883161,"mc":[{"id":"1.230180112","rc":[{"atb":[[1.72,1.84]],"id":68870841},{"spn":70.86,"spf":"NaN","id":68870841}],"con":true,"img":false}]}
{"op":"mcm","clk":"11540389484","pt":1719493884251,"mc":[{"id":"1.230180112","rc":[{"atb":[[1.71,0]],"id":68870841}],"con":true,"img":false}]}
{"op":"mcm","clk":"11540389493","pt":1719493884354,"mc":[{"id":"1.230180112","rc":[{"atb":[[1.73,2]],"id":68870841}],"con":true,"img":false}]}
{"op":"mcm","clk":"11540389512","pt":1719493884669,"mc":[{"id":"1.230180112","rc":[{"atb":[[1.71,0]],"id":58974183}],"con":true,"img":false}]}
{"op":"mcm","clk":"11540389521","pt":1719493884769,"mc":[{"id":"1.230180112","rc":[{"atb":[[1.73,2]],"id":58974183}],"con":true,"img":false}]}
{"op":"mcm","clk":"11540389627","pt":1719493885862,"mc":[{"id":"1.230180112","rc":[{"atb":[[1.72,0]],"id":58974183}],"con":true,"img":false}]}
{"op":"mcm","clk":"11540389643","pt":1719493886170,"mc":[{"id":"1.230180112","rc":[{"atb":[[1.72,0]],"id":68870841}],"con":true,"img":false}]}
{"op":"mcm","clk":"11540389673","pt":1719493886640,"mc":[{"id":"1.230180112","rc":[{"atb":[[1.73,0]],"id":68870841}],"con":true,"img":false}]}
{"op":"mcm","clk":"11540389686","pt":1719493886798,"mc":[{"id":"1.230180112","rc":[{"atb":[[1.71,2]],"id":68870841}],"con":true,"img":false}]}
{"op":"mcm","clk":"11540389711","pt":1719493887163,"mc":[{"id":"1.230180112","rc":[{"atb":[[1.73,0]],"id":58974183}],"con":true,"img":false}]}
{"op":"mcm","clk":"11540389719","pt":1719493887261,"mc":[{"id":"1.230180112","rc":[{"atb":[[1.71,2]],"id":58974183}],"con":true,"img":false}]}
{"op":"mcm","clk":"11540389863","pt":1719493888875,"mc":[{"id":"1.230180112","rc":[{"atb":[[1.72,1.82]],"id":58974183}],"con":true,"img":false}]}
{"op":"mcm","clk":"11540389878","pt":1719493889192,"mc":[{"id":"1.230180112","rc":[{"atb":[[1.72,1.89]],"id":68870841}],"con":true,"img":false}]}
{"op":"mcm","clk":"11540389909","pt":1719493889559,"mc":[{"id":"1.230180112","rc":[{"atb":[[1.71,0]],"id":58974183}],"con":true,"img":false}]}
{"op":"mcm","clk":"11540389918","pt":1719493889660,"mc":[{"id":"1.230180112","rc":[{"atb":[[1.73,2]],"id":58974183}],"con":true,"img":false}]}
{"op":"mcm","clk":"11540390062","pt":1719493891273,"mc":[{"id":"1.230180112","rc":[{"atb":[[1.71,0]],"id":68870841}],"con":true,"img":false}]}
{"op":"mcm","clk":"11540390068","pt":1719493891381,"mc":[{"id":"1.230180112","rc":[{"atb":[[1.73,2]],"id":68870841}],"con":true,"img":false}]}
{"op":"mcm","clk":"11540390106","pt":1719493891897,"mc":[{"id":"1.230180112","rc":[{"atb":[[1.72,0]],"id":58974183}],"con":true,"img":false}]}
{"op":"mcm","clk":"11540390131","pt":1719493892153,"mc":[{"id":"1.230180112","rc":[{"atb":[[1.72,0]],"id":68870841}],"con":true,"img":false}]}
{"op":"mcm","clk":"11540390150","pt":1719493892569,"mc":[{"id":"1.230180112","rc":[{"atb":[[1.73,0]],"id":58974183}],"con":true,"img":false}]}
{"op":"mcm","clk":"11540390158","pt":1719493892672,"mc":[{"id":"1.230180112","rc":[{"atb":[[1.71,2]],"id":58974183}],"con":true,"img":false}]}
{"op":"mcm","clk":"11540390331","pt":1719493895099,"mc":[{"id":"1.230180112","rc":[{"atb":[[1.72,1.83]],"id":58974183}],"con":true,"img":false}]}
{"op":"mcm","clk":"11540390346","pt":1719493895354,"mc":[{"id":"1.230180112","rc":[{"atb":[[1.74,1.62]],"id":68870841}],"con":true,"img":false}]}
{"op":"mcm","clk":"11540390389","pt":1719493895980,"mc":[{"id":"1.230180112","rc":[{"atb":[[1.73,0]],"id":68870841}],"con":true,"img":false}]}
{"op":"mcm","clk":"11540390397","pt":1719493896083,"mc":[{"id":"1.230180112","rc":[{"atb":[[1.75,2]],"id":68870841}],"con":true,"img":false}]}
{"op":"mcm","clk":"11540390417","pt":1719493896399,"mc":[{"id":"1.230180112","rc":[{"atb":[[1.71,0]],"id":58974183}],"con":true,"img":false}]}
{"op":"mcm","clk":"11540390425","pt":1719493896505,"mc":[{"id":"1.230180112","rc":[{"atb":[[1.73,2]],"id":58974183}],"con":true,"img":false}]}
{"op":"mcm","clk":"11540390901","pt":1719493903895,"mc":[{"id":"1.230180112","rc":[{"atb":[[1.72,0]],"id":58974183}],"con":true,"img":false}]}
{"op":"mcm","clk":"11540390929","pt":1719493904265,"mc":[{"id":"1.230180112","rc":[{"atb":[[1.74,0]],"id":68870841}],"con":true,"img":false}]}
{"op":"mcm","clk":"11540391044","pt":1719493906074,"mc":[{"id":"1.230180112","rc":[{"atb":[[1.75,0]],"id":68870841}],"con":true,"img":false}]}
{"op":"mcm","clk":"11540391051","pt":1719493906177,"mc":[{"id":"1.230180112","rc":[{"atb":[[1.71,2]],"id":68870841}],"con":true,"img":false}]}
{"op":"mcm","clk":"11540391072","pt":1719493906586,"mc":[{"id":"1.230180112","rc":[{"atb":[[1.73,0]],"id":58974183}],"con":true,"img":false}]}
{"op":"mcm","clk":"11540391078","pt":1719493906685,"mc":[{"id":"1.230180112","rc":[{"atb":[[1.71,2]],"id":58974183}],"con":true,"img":false}]}
{"op":"mcm","clk":"11540391112","pt":1719493907201,"mc":[{"id":"1.230180112","rc":[{"atb":[[1.72,1.7]],"id":58974183}],"con":true,"img":false}]}
{"op":"mcm","clk":"11540391129","pt":1719493907470,"mc":[{"id":"1.230180112","rc":[{"atb":[[1.72,1.99]],"id":68870841}],"con":true,"img":false}]}
{"op":"mcm","clk":"11540391148","pt":1719493907672,"mc":[{"id":"1.230180112","rc":[{"atb":[[1.71,0]],"id":58974183}],"con":true,"img":false}]}
{"op":"mcm","clk":"11540391157","pt":1719493907776,"mc":[{"id":"1.230180112","rc":[{"atb":[[1.73,2]],"id":58974183}],"con":true,"img":false}]}
{"op":"mcm","clk":"11540391215","pt":1719493908708,"mc":[{"id":"1.230180112","rc":[{"atb":[[1.71,0]],"id":68870841}],"con":true,"img":false}]}
{"op":"mcm","clk":"11540391222","pt":1719493908774,"mc":[{"id":"1.230180112","rc":[{"atb":[[1.73,2]],"id":68870841}],"con":true,"img":false}]}
{"op":"mcm","clk":"11540391306","pt":1719493910009,"mc":[{"id":"1.230180112","rc":[{"atb":[[1.72,0]],"id":58974183}],"con":true,"img":false}]}
{"op":"mcm","clk":"11540391326","pt":1719493910276,"mc":[{"id":"1.230180112","rc":[{"atb":[[1.72,0]],"id":68870841}],"con":true,"img":false}]}
{"op":"mcm","clk":"11540391378","pt":1719493910997,"mc":[{"id":"1.230180112","rc":[{"atb":[[1.73,0]],"id":68870841}],"con":true,"img":false}]}
{"op":"mcm","clk":"11540391387","pt":1719493911094,"mc":[{"id":"1.230180112","rc":[{"atb":[[1.71,2]],"id":68870841}],"con":true,"img":false}]}
{"op":"mcm","clk":"11540391409","pt":1719493911410,"mc":[{"id":"1.230180112","rc":[{"atb":[[1.73,0]],"id":58974183}],"con":true,"img":false}]}
{"op":"mcm","clk":"11540391416","pt":1719493911508,"mc":[{"id":"1.230180112","rc":[{"atb":[[1.71,2]],"id":58974183}],"con":true,"img":false}]}
{"op":"mcm","clk":"11540391506","pt":1719493913019,"mc":[{"id":"1.230180112","rc":[{"atb":[[1.72,1.86]],"id":58974183}],"con":true,"img":false}]}
{"op":"mcm","clk":"11540391557","pt":1719493913794,"mc":[{"id":"1.230180112","rc":[{"atb":[[1.71,0]],"id":58974183}],"con":true,"img":false}]}
{"op":"mcm","clk":"11540391564","pt":1719493913900,"mc":[{"id":"1.230180112","rc":[{"atb":[[1.73,2]],"id":58974183}],"con":true,"img":false}]}
{"op":"mcm","clk":"11540391724","pt":1719493916083,"mc":[{"id":"1.230180112","rc":[{"atb":[[1.72,0]],"id":58974183}],"con":true,"img":false}]}
{"op":"mcm","clk":"11540391742","pt":1719493916392,"mc":[{"id":"1.230180112","rc":[{"atb":[[1.72,1.53]],"id":68870841}],"con":true,"img":false}]}
{"op":"mcm","clk":"11540391778","pt":1719493916908,"mc":[{"id":"1.230180112","rc":[{"atb":[[1.71,0]],"id":68870841}],"con":true,"img":false}]}
{"op":"mcm","clk":"11540391783","pt":1719493917016,"mc":[{"id":"1.230180112","rc":[{"atb":[[1.73,2]],"id":68870841}],"con":true,"img":false}]}
{"op":"mcm","clk":"11540391801","pt":1719493917287,"mc":[{"id":"1.230180112","rc":[{"atb":[[1.73,0]],"id":58974183}],"con":true,"img":false}]}
{"op":"mcm","clk":"11540391807","pt":1719493917376,"mc":[{"id":"1.230180112","rc":[{"atb":[[1.71,2]],"id":58974183}],"con":true,"img":false}]}
{"op":"mcm","clk":"11540391925","pt":1719493918989,"mc":[{"id":"1.230180112","rc":[{"atb":[[1.72,0]],"id":68870841}],"con":true,"img":false}]}
{"op":"mcm","clk":"11540392026","pt":1719493920382,"mc":[{"id":"1.230180112","rc":[{"atb":[[1.73,0]],"id":68870841}],"con":true,"img":false}]}
{"op":"mcm","clk":"11540392036","pt":1719493920489,"mc":[{"id":"1.230180112","rc":[{"atb":[[1.71,2]],"id":68870841}],"con":true,"img":false}]}
{"op":"mcm","clk":"11540392148","pt":1719493922097,"mc":[{"id":"1.230180112","rc":[{"atb":[[1.72,1.73]],"id":58974183}],"con":true,"img":false}]}
{"op":"mcm","clk":"11540392178","pt":1719493922418,"mc":[{"id":"1.230180112","rc":[{"atb":[[1.72,1.62]],"id":68870841}],"con":true,"img":false}]}
{"op":"mcm","clk":"11540392205","pt":1719493922784,"mc":[{"id":"1.230180112","rc":[{"atb":[[1.71,0]],"id":68870841}],"con":true,"img":false}]}
{"op":"mcm","clk":"11540392211","pt":1719493922895,"mc":[{"id":"1.230180112","rc":[{"atb":[[1.73,2]],"id":68870841}],"con":true,"img":false}]}
{"op":"mcm","clk":"11540392236","pt":1719493923199,"mc":[{"id":"1.230180112","rc":[{"atb":[[1.71,0]],"id":58974183}],"con":true,"img":false}]}
{"op":"mcm","clk":"11540392243","pt":1719493923309,"mc":[{"id":"1.230180112","rc":[{"atb":[[1.73,2]],"id":58974183}],"con":true,"img":false}]}
{"op":"mcm","clk":"11540392392","pt":1719493925118,"mc":[{"id":"1.230180112","rc":[{"atb":[[1.72,0]],"id":58974183}],"con":true,"img":false}]}
{"op":"mcm","clk":"11540392420","pt":1719493925429,"mc":[{"id":"1.230180112","rc":[{"atb":[[1.72,0]],"id":68870841}],"con":true,"img":false}]}
{"op":"mcm","clk":"11540392489","pt":1719493926209,"mc":[{"id":"1.230180112","rc":[{"atb":[[1.73,0]],"id":68870841}],"con":true,"img":false}]}
{"op":"mcm","clk":"11540392496","pt":1719493926313,"mc":[{"id":"1.230180112","rc":[{"atb":[[1.71,2]],"id":68870841}],"con":true,"img":false}]}
{"op":"mcm","clk":"11540392532","pt":1719493926833,"mc":[{"id":"1.230180112","rc":[{"atb":[[1.73,0]],"id":58974183}],"con":true,"img":false}]}
{"op":"mcm","clk":"11540392540","pt":1719493926939,"mc":[{"id":"1.230180112","rc":[{"atb":[[1.71,2]],"id":58974183}],"con":true,"img":false}]}
{"op":"mcm","clk":"11540392893","pt":1719493931042,"mc":[{"id":"1.230180112","rc":[{"atb":[[1.72,1.52]],"id":58974183}],"con":true,"img":false}]}
{"op":"mcm","clk":"11540392917","pt":1719493931307,"mc":[{"id":"1.230180112","rc":[{"atb":[[1.72,1.6]],"id":68870841}],"con":true,"img":false}]}
{"op":"mcm","clk":"11540392971","pt":1719493932229,"mc":[{"id":"1.230180112","rc":[{"atb":[[1.71,0]],"id":68870841}],"con":true,"img":false}]}
{"op":"mcm","clk":"11540392979","pt":1719493932338,"mc":[{"id":"1.230180112","rc":[{"atb":[[1.73,2]],"id":68870841}],"con":true,"img":false}]}
{"op":"mcm","clk":"11540393005","pt":1719493932797,"mc":[{"id":"1.230180112","rc":[{"atb":[[1.71,0]],"id":58974183}],"con":true,"img":false}]}
{"op":"mcm","clk":"11540393011","pt":1719493932902,"mc":[{"id":"1.230180112","rc":[{"atb":[[1.73,2]],"id":58974183}],"con":true,"img":false}]}
{"op":"mcm","clk":"11540393082","pt":1719493934040,"mc":[{"id":"1.230180112","rc":[{"atb":[[1.72,0]],"id":58974183}],"con":true,"img":false}]}
{"op":"mcm","clk":"11540393103","pt":1719493934304,"mc":[{"id":"1.230180112","rc":[{"atb":[[1.72,0]],"id":68870841}],"con":true,"img":false}]}
{"op":"mcm","clk":"11540393146","pt":1719493935025,"mc":[{"id":"1.230180112","rc":[{"atb":[[1.73,0]],"id":68870841}],"con":true,"img":false}]}
{"op":"mcm","clk":"11540393154","pt":1719493935124,"mc":[{"id":"1.230180112","rc":[{"atb":[[1.71,2]],"id":68870841}],"con":true,"img":false}]}
{"op":"mcm","clk":"11540393229","pt":1719493936109,"mc":[{"id":"1.230180112","rc":[{"atb":[[1.73,0]],"id":58974183}],"con":true,"img":false}]}
{"op":"mcm","clk":"11540393238","pt":1719493936215,"mc":[{"id":"1.230180112","rc":[{"atb":[[1.71,2]],"id":58974183}],"con":true,"img":false}]}
{"op":"mcm","clk":"11540393307","pt":1719493937044,"mc":[{"id":"1.230180112","rc":[{"atb":[[1.72,1.89]],"id":58974183}],"con":true,"img":false}]}
{"op":"mcm","clk":"11540393330","pt":1719493937310,"mc":[{"id":"1.230180112","rc":[{"atb":[[1.72,1.92]],"id":68870841}],"con":true,"img":false}]}
{"op":"mcm","clk":"11540393482","pt":1719493939324,"mc":[{"id":"1.230180112","rc":[{"atb":[[1.71,0]],"id":68870841}],"con":true,"img":false}]}
{"op":"mcm","clk":"11540393489","pt":1719493939428,"mc":[{"id":"1.230180112","rc":[{"atb":[[1.73,2]],"id":68870841}],"con":true,"img":false}]}
{"op":"mcm","clk":"11540393519","pt":1719493939842,"mc":[{"id":"1.230180112","rc":[{"atb":[[1.71,0]],"id":58974183}],"con":true,"img":false}]}
{"op":"mcm","clk":"11540393528","pt":1719493939947,"mc":[{"id":"1.230180112","rc":[{"atb":[[1.73,2]],"id":58974183}],"con":true,"img":false}]}
{"op":"mcm","clk":"11540393551","pt":1719493940161,"mc":[{"id":"1.230180112","rc":[{"atb":[[1.72,0]],"id":68870841}],"con":true,"img":false}]}
{"op":"mcm","clk":"11540393622","pt":1719493941039,"mc":[{"id":"1.230180112","rc":[{"atb":[[1.73,0]],"id":68870841}],"con":true,"img":false}]}
{"op":"mcm","clk":"11540393632","pt":1719493941148,"mc":[{"id":"1.230180112","rc":[{"atb":[[1.71,2]],"id":68870841}],"con":true,"img":false}]}
{"op":"mcm","clk":"11540393792","pt":1719493943120,"mc":[{"id":"1.230180112","rc":[{"atb":[[1.72,0]],"id":58974183}],"con":true,"img":false}]}
{"op":"mcm","clk":"11540393844","pt":1719493943840,"mc":[{"id":"1.230180112","rc":[{"atb":[[1.73,0]],"id":58974183},{"spn":75.85,"spf":"NaN","id":58974183},{"spn":70.85,"spf":"NaN","id":68870841}],"con":true,"img":false}]}
{"op":"mcm","clk":"11540393853","pt":1719493943944,"mc":[{"id":"1.230180112","rc":[{"atb":[[1.71,2]],"id":58974183}],"con":true,"img":false}]}
{"op":"mcm","clk":"11540394793","pt":1719493956139,"mc":[{"id":"1.230180112","rc":[{"atb":[[1.72,1.72]],"id":58974183}],"con":true,"img":false}]}
{"op":"mcm","clk":"11540394820","pt":1719493956446,"mc":[{"id":"1.230180112","rc":[{"atb":[[1.72,1.62]],"id":68870841}],"con":true,"img":false}]}
{"op":"mcm","clk":"11540394877","pt":1719493957283,"mc":[{"id":"1.230180112","rc":[{"atb":[[1.71,0]],"id":68870841}],"con":true,"img":false}]}
{"op":"mcm","clk":"11540394889","pt":1719493957341,"mc":[{"id":"1.230180112","rc":[{"atb":[[1.73,2]],"id":68870841}],"con":true,"img":false}]}
{"op":"mcm","clk":"11540394904","pt":1719493957549,"mc":[{"id":"1.230180112","rc":[{"atb":[[1.71,0]],"id":58974183}],"con":true,"img":false}]}
{"op":"mcm","clk":"11540394914","pt":1719493957647,"mc":[{"id":"1.230180112","rc":[{"atb":[[1.73,2]],"id":58974183}],"con":true,"img":false}]}
{"op":"mcm","clk":"11540395049","pt":1719493959053,"mc":[{"id":"1.230180112","rc":[{"atb":[[1.72,0]],"id":58974183}],"con":true,"img":false}]}
{"op":"mcm","clk":"11540395071","pt":1719493959364,"mc":[{"id":"1.230180112","rc":[{"atb":[[1.72,0]],"id":68870841}],"con":true,"img":false}]}
{"op":"mcm","clk":"11540395117","pt":1719493960048,"mc":[{"id":"1.230180112","rc":[{"atb":[[1.73,0]],"id":68870841}],"con":true,"img":false}]}
{"op":"mcm","clk":"11540395124","pt":1719493960154,"mc":[{"id":"1.230180112","rc":[{"atb":[[1.71,2]],"id":68870841}],"con":true,"img":false}]}
{"op":"mcm","clk":"11540395145","pt":1719493960462,"mc":[{"id":"1.230180112","rc":[{"atb":[[1.73,0]],"id":58974183}],"con":true,"img":false}]}
{"op":"mcm","clk":"11540395153","pt":1719493960572,"mc":[{"id":"1.230180112","rc":[{"atb":[[1.71,2]],"id":58974183}],"con":true,"img":false}]}
{"op":"mcm","clk":"11540395410","pt":1719493964042,"mc":[{"id":"1.230180112","rc":[{"atb":[[1.72,1.95]],"id":58974183}],"con":true,"img":false}]}
{"op":"mcm","clk":"11540395440","pt":1719493964354,"mc":[{"id":"1.230180112","rc":[{"atb":[[1.72,1.97]],"id":68870841}],"con":true,"img":false}]}
{"op":"mcm","clk":"11540395481","pt":1719493964771,"mc":[{"id":"1.230180112","rc":[{"atb":[[1.71,0]],"id":58974183}],"con":true,"img":false}]}
{"op":"mcm","clk":"11540395494","pt":1719493964875,"mc":[{"id":"1.230180112","rc":[{"atb":[[1.73,2]],"id":58974183}],"con":true,"img":false}]}
{"op":"mcm","clk":"11540395618","pt":1719493966484,"mc":[{"id":"1.230180112","rc":[{"atb":[[1.71,0]],"id":68870841}],"con":true,"img":false}]}
{"op":"mcm","clk":"11540395623","pt":1719493966592,"mc":[{"id":"1.230180112","rc":[{"atb":[[1.73,2]],"id":68870841}],"con":true,"img":false}]}
{"op":"mcm","clk":"11540395667","pt":1719493967158,"mc":[{"id":"1.230180112","rc":[{"atb":[[1.72,0]],"id":58974183}],"con":true,"img":false}]}
{"op":"mcm","clk":"11540395689","pt":1719493967477,"mc":[{"id":"1.230180112","rc":[{"atb":[[1.72,0]],"id":68870841}],"con":true,"img":false}]}
{"op":"mcm","clk":"11540395698","pt":1719493967573,"mc":[{"id":"1.230180112","rc":[{"atb":[[1.73,0]],"id":58974183}],"con":true,"img":false}]}
{"op":"mcm","clk":"11540395707","pt":1719493967683,"mc":[{"id":"1.230180112","rc":[{"atb":[[1.71,2]],"id":58974183}],"con":true,"img":false}]}
{"op":"mcm","clk":"11540395783","pt":1719493968870,"mc":[{"id":"1.230180112","rc":[{"atb":[[1.73,0]],"id":68870841}],"con":true,"img":false}]}
{"op":"mcm","clk":"11540395791","pt":1719493968973,"mc":[{"id":"1.230180112","rc":[{"atb":[[1.71,2]],"id":68870841}],"con":true,"img":false}]}
{"op":"mcm","clk":"11540395864","pt":1719493970074,"mc":[{"id":"1.230180112","rc":[{"atb":[[1.72,1.76]],"id":58974183}],"con":true,"img":false}]}
{"op":"mcm","clk":"11540395968","pt":1719493971369,"mc":[{"id":"1.230180112","rc":[{"atb":[[1.71,0]],"id":58974183}],"con":true,"img":false}]}
{"op":"mcm","clk":"11540395975","pt":1719493971467,"mc":[{"id":"1.230180112","rc":[{"atb":[[1.73,2]],"id":58974183}],"con":true,"img":false}]}
{"op":"mcm","clk":"11540396097","pt":1719493973193,"mc":[{"id":"1.230180112","rc":[{"atb":[[1.72,0]],"id":58974183}],"con":true,"img":false}]}
{"op":"mcm","clk":"11540396120","pt":1719493973467,"mc":[{"id":"1.230180112","rc":[{"atb":[[1.72,1.73]],"id":68870841}],"con":true,"img":false}]}
{"op":"mcm","clk":"11540396178","pt":1719493974299,"mc":[{"id":"1.230180112","rc":[{"atb":[[1.71,0]],"id":68870841}],"con":true,"img":false}]}
{"op":"mcm","clk":"11540396190","pt":1719493974355,"mc":[{"id":"1.230180112","rc":[{"atb":[[1.73,2]],"id":68870841}],"con":true,"img":false}]}
{"op":"mcm","clk":"11540396228","pt":1719493974770,"mc":[{"id":"1.230180112","rc":[{"atb":[[1.73,0]],"id":58974183}],"con":true,"img":false}]}
{"op":"mcm","clk":"11540396237","pt":1719493974865,"mc":[{"id":"1.230180112","rc":[{"atb":[[1.71,2]],"id":58974183}],"con":true,"img":false}]}
{"op":"mcm","clk":"11540396348","pt":1719493976165,"mc":[{"id":"1.230180112","rc":[{"atb":[[1.72,1.51]],"id":58974183}],"con":true,"img":false}]}
{"op":"mcm","clk":"11540396374","pt":1719493976476,"mc":[{"id":"1.230180112","rc":[{"atb":[[1.72,0]],"id":68870841}],"con":true,"img":false}]}
{"op":"mcm","clk":"11540396382","pt":1719493976581,"mc":[{"id":"1.230180112","rc":[{"atb":[[1.71,0]],"id":58974183}],"con":true,"img":false}]}
{"op":"mcm","clk":"11540396391","pt":1719493976684,"mc":[{"id":"1.230180112","rc":[{"atb":[[1.73,2]],"id":58974183}],"con":true,"img":false}]}
{"op":"mcm","clk":"11540396480","pt":1719493977984,"mc":[{"id":"1.230180112","rc":[{"atb":[[1.73,0]],"id":68870841}],"con":true,"img":false}]}
{"op":"mcm","clk":"11540396489","pt":1719493978087,"mc":[{"id":"1.230180112","rc":[{"atb":[[1.71,2]],"id":68870841}],"con":true,"img":false}]}
{"op":"mcm","clk":"11540396563","pt":1719493979284,"mc":[{"id":"1.230180112","rc":[{"atb":[[1.72,0]],"id":58974183}],"con":true,"img":false}]}
{"op":"mcm","clk":"11540396591","pt":1719493979597,"mc":[{"id":"1.230180112","rc":[{"atb":[[1.72,1.75]],"id":68870841}],"con":true,"img":false}]}
{"op":"mcm","clk":"11540396621","pt":1719493980068,"mc":[{"id":"1.230180112","rc":[{"atb":[[1.71,0]],"id":68870841}],"con":true,"img":false}]}
{"op":"mcm","clk":"11540396629","pt":1719493980172,"mc":[{"id":"1.230180112","rc":[{"atb":[[1.73,2]],"id":68870841}],"con":true,"img":false}]}
{"op":"mcm","clk":"11540396647","pt":1719493980484,"mc":[{"id":"1.230180112","rc":[{"atb":[[1.73,0]],"id":58974183}],"con":true,"img":false}]}
{"op":"mcm","clk":"11540396662","pt":1719493980583,"mc":[{"id":"1.230180112","rc":[{"atb":[[1.71,2]],"id":58974183}],"con":true,"img":false}]}
{"op":"mcm","clk":"11540396782","pt":1719493982301,"mc":[{"id":"1.230180112","rc":[{"atb":[[1.72,1.89]],"id":58974183}],"con":true,"img":false}]}
{"op":"mcm","clk":"11540396812","pt":1719493982605,"mc":[{"id":"1.230180112","rc":[{"atb":[[1.72,0]],"id":68870841}],"con":true,"img":false}]}
{"op":"mcm","clk":"11540396897","pt":1719493983697,"mc":[{"id":"1.230180112","rc":[{"atb":[[1.73,0]],"id":68870841}],"con":true,"img":false}]}
{"op":"mcm","clk":"11540396905","pt":1719493983805,"mc":[{"id":"1.230180112","rc":[{"atb":[[1.71,2]],"id":68870841}],"con":true,"img":false}]}
{"op":"mcm","clk":"11540396923","pt":1719493984013,"mc":[{"id":"1.230180112","rc":[{"atb":[[1.71,0]],"id":58974183}],"con":true,"img":false}]}
{"op":"mcm","clk":"11540396930","pt":1719493984066,"mc":[{"id":"1.230180112","rc":[{"atb":[[1.73,2]],"id":58974183}],"con":true,"img":false}]}
{"op":"mcm","clk":"11540397013","pt":1719493985214,"mc":[{"id":"1.230180112","rc":[{"atb":[[1.72,0]],"id":58974183}],"con":true,"img":false}]}
{"op":"mcm","clk":"11540397146","pt":1719493986981,"mc":[{"id":"1.230180112","rc":[{"atb":[[1.73,0]],"id":58974183}],"con":true,"img":false}]}
{"op":"mcm","clk":"11540397155","pt":1719493987085,"mc":[{"id":"1.230180112","rc":[{"atb":[[1.71,2]],"id":58974183}],"con":true,"img":false}]}
{"op":"mcm","clk":"11540397231","pt":1719493988165,"mc":[{"id":"1.230180112","rc":[{"atb":[[1.72,1.95]],"id":58974183}],"con":true,"img":false}]}
{"op":"mcm","clk":"11540397250","pt":1719493988473,"mc":[{"id":"1.230180112","rc":[{"atb":[[1.72,1.59]],"id":68870841}],"con":true,"img":false}]}
{"op":"mcm","clk":"11540397279","pt":1719493988888,"mc":[{"id":"1.230180112","rc":[{"atb":[[1.71,0]],"id":58974183}],"con":true,"img":false}]}
{"op":"mcm","clk":"11540397286","pt":1719493988991,"mc":[{"id":"1.230180112","rc":[{"atb":[[1.73,2]],"id":58974183}],"con":true,"img":false}]}
{"op":"mcm","clk":"11540397454","pt":1719493991381,"mc":[{"id":"1.230180112","rc":[{"atb":[[1.71,0]],"id":68870841}],"con":true,"img":false}]}
{"op":"mcm","clk":"11540397460","pt":1719493991481,"mc":[{"id":"1.230180112","rc":[{"atb":[[1.73,2]],"id":68870841}],"con":true,"img":false}]}
{"op":"mcm","clk":"11540397468","pt":1719493991580,"mc":[{"id":"1.230180112","rc":[{"atb":[[1.72,0]],"id":58974183}],"con":true,"img":false}]}
{"op":"mcm","clk":"11540397575","pt":1719493992982,"mc":[{"id":"1.230180112","rc":[{"atb":[[1.73,0]],"id":58974183}],"con":true,"img":false}]}
{"op":"mcm","clk":"11540397586","pt":1719493993090,"mc":[{"id":"1.230180112","rc":[{"atb":[[1.71,2]],"id":58974183}],"con":true,"img":false}]}
{"op":"mcm","clk":"11540397688","pt":1719493994282,"mc":[{"id":"1.230180112","rc":[{"atb":[[1.72,0]],"id":68870841}],"con":true,"img":false}]}
{"op":"mcm","clk":"11540397753","pt":1719493995099,"mc":[{"id":"1.230180112","rc":[{"atb":[[1.73,0]],"id":68870841}],"con":true,"img":false}]}
{"op":"mcm","clk":"11540397759","pt":1719493995207,"mc":[{"id":"1.230180112","rc":[{"atb":[[1.71,2]],"id":68870841}],"con":true,"img":false}]}
{"op":"mcm","clk":"11540397926","pt":1719493997176,"mc":[{"id":"1.230180112","rc":[{"atb":[[1.72,1.8]],"id":58974183}],"con":true,"img":false}]}
{"op":"mcm","clk":"11540397943","pt":1719493997495,"mc":[{"id":"1.230180112","rc":[{"atb":[[1.72,1.76]],"id":68870841}],"con":true,"img":false}]}
{"op":"mcm","clk":"11540398053","pt":1719493998775,"mc":[{"id":"1.230180112","rc":[{"atb":[[1.71,0]],"id":68870841}],"con":true,"img":false}]}
{"op":"mcm","clk":"11540398060","pt":1719493998877,"mc":[{"id":"1.230180112","rc":[{"atb":[[1.73,2]],"id":68870841}],"con":true,"img":false}]}
{"op":"mcm","clk":"11540398100","pt":1719493999297,"mc":[{"id":"1.230180112","rc":[{"atb":[[1.71,0]],"id":58974183}],"con":true,"img":false}]}
{"op":"mcm","clk":"11540398114","pt":1719493999401,"mc":[{"id":"1.230180112","rc":[{"atb":[[1.73,2]],"id":58974183}],"con":true,"img":false}]}
{"op":"mcm","clk":"11540398201","pt":1719494000279,"mc":[{"id":"1.230180112","rc":[{"atb":[[1.72,0]],"id":58974183}],"con":true,"img":false}]}
{"op":"mcm","clk":"11540398233","pt":1719494000591,"mc":[{"id":"1.230180112","rc":[{"atb":[[1.72,0]],"id":68870841}],"con":true,"img":false}]}
{"op":"mcm","clk":"11540398307","pt":1719494001531,"mc":[{"id":"1.230180112","rc":[{"atb":[[1.73,0]],"id":68870841}],"con":true,"img":false}]}
{"op":"mcm","clk":"11540398316","pt":1719494001584,"mc":[{"id":"1.230180112","rc":[{"atb":[[1.71,2]],"id":68870841}],"con":true,"img":false}]}
{"op":"mcm","clk":"11540398344","pt":1719494001888,"mc":[{"id":"1.230180112","rc":[{"atb":[[1.73,0]],"id":58974183}],"con":true,"img":false}]}
{"op":"mcm","clk":"11540398352","pt":1719494001999,"mc":[{"id":"1.230180112","rc":[{"atb":[[1.71,2]],"id":58974183}],"con":true,"img":false}]}
{"op":"mcm","clk":"11540398474","pt":1719494003593,"mc":[{"id":"1.230180112","rc":[{"atb":[[1.72,1.56]],"id":58974183}],"con":true,"img":false}]}
{"op":"mcm","clk":"11540398499","pt":1719494003902,"mc":[{"id":"1.230180112","rc":[{"spn":75.86,"spf":"NaN","id":58974183},{"atb":[[1.72,1.6]],"id":68870841},{"spn":70.86,"spf":"NaN","id":68870841}],"con":true,"img":false}]}
{"op":"mcm","clk":"11540398588","pt":1719494005089,"mc":[{"id":"1.230180112","rc":[{"atb":[[1.71,0]],"id":68870841}],"con":true,"img":false}]}
{"op":"mcm","clk":"11540398591","pt":1719494005191,"mc":[{"id":"1.230180112","rc":[{"atb":[[1.73,2]],"id":68870841}],"con":true,"img":false}]}
{"op":"mcm","clk":"11540398614","pt":1719494005614,"mc":[{"id":"1.230180112","rc":[{"atb":[[1.71,0]],"id":58974183}],"con":true,"img":false}]}
{"op":"mcm","clk":"11540398628","pt":1719494005715,"mc":[{"id":"1.230180112","rc":[{"atb":[[1.73,2]],"id":58974183}],"con":true,"img":false}]}
{"op":"mcm","clk":"11540398724","pt":1719494006903,"mc":[{"id":"1.230180112","rc":[{"atb":[[1.72,0]],"id":58974183}],"con":true,"img":false}]}
{"op":"mcm","clk":"11540398754","pt":1719494007211,"mc":[{"id":"1.230180112","rc":[{"atb":[[1.72,0]],"id":68870841}],"con":true,"img":false}]}
{"op":"mcm","clk":"11540398783","pt":1719494007618,"mc":[{"id":"1.230180112","rc":[{"atb":[[1.73,0]],"id":68870841}],"con":true,"img":false}]}
{"op":"mcm","clk":"11540398791","pt":1719494007722,"mc":[{"id":"1.230180112","rc":[{"atb":[[1.71,2]],"id":68870841}],"con":true,"img":false}]}
{"op":"mcm","clk":"11540398816","pt":1719494008033,"mc":[{"id":"1.230180112","rc":[{"atb":[[1.73,0]],"id":58974183}],"con":true,"img":false}]}
{"op":"mcm","clk":"11540398828","pt":1719494008093,"mc":[{"id":"1.230180112","rc":[{"atb":[[1.71,2]],"id":58974183}],"con":true,"img":false}]}
{"op":"mcm","clk":"11540399170","pt":1719494012430,"mc":[{"id":"1.230180112","rc":[{"atb":[[1.72,1.6]],"id":58974183}],"con":true,"img":false}]}
{"op":"mcm","clk":"11540399196","pt":1719494012737,"mc":[{"id":"1.230180112","rc":[{"atb":[[1.72,1.9]],"id":68870841}],"con":true,"img":false}]}
{"op":"mcm","clk":"11540399280","pt":1719494013623,"mc":[{"id":"1.230180112","rc":[{"atb":[[1.71,0]],"id":68870841}],"con":true,"img":false}]}
{"op":"mcm","clk":"11540399289","pt":1719494013723,"mc":[{"id":"1.230180112","rc":[{"atb":[[1.73,2]],"id":68870841}],"con":true,"img":false}]}
{"op":"mcm","clk":"11540399348","pt":1719494014449,"mc":[{"id":"1.230180112","rc":[{"atb":[[1.71,0]],"id":58974183}],"con":true,"img":false}]}
{"op":"mcm","clk":"11540399358","pt":1719494014553,"mc":[{"id":"1.230180112","rc":[{"atb":[[1.73,2]],"id":58974183}],"con":true,"img":false}]}
{"op":"mcm","clk":"11540399426","pt":1719494015324,"mc":[{"id":"1.230180112","rc":[{"atb":[[1.72,0]],"id":58974183}],"con":true,"img":false}]}
{"op":"mcm","clk":"11540399456","pt":1719494015635,"mc":[{"id":"1.230180112","rc":[{"atb":[[1.72,0]],"id":68870841}],"con":true,"img":false}]}
{"op":"mcm","clk":"11540399474","pt":1719494015837,"mc":[{"id":"1.230180112","rc":[{"atb":[[1.73,0]],"id":58974183}],"con":true,"img":false}]}
{"op":"mcm","clk":"11540399484","pt":1719494015941,"mc":[{"id":"1.230180112","rc":[{"atb":[[1.71,2]],"id":58974183}],"con":true,"img":false}]}
{"op":"mcm","clk":"11540399634","pt":1719494017713,"mc":[{"id":"1.230180112","rc":[{"atb":[[1.73,0]],"id":68870841}],"con":true,"img":false}]}
{"op":"mcm","clk":"11540399645","pt":1719494017811,"mc":[{"id":"1.230180112","rc":[{"atb":[[1.71,2]],"id":68870841}],"con":true,"img":false}]}
{"op":"mcm","clk":"11540399939","pt":1719494021437,"mc":[{"id":"1.230180112","rc":[{"atb":[[1.72,1.77]],"id":58974183}],"con":true,"img":false}]}
{"op":"mcm","clk":"11540399965","pt":1719494021750,"mc":[{"id":"1.230180112","rc":[{"atb":[[1.72,1.54]],"id":68870841}],"con":true,"img":false}]}
{"op":"mcm","clk":"11540400012","pt":1719494022226,"mc":[{"id":"1.230180112","rc":[{"atb":[[1.71,0]],"id":68870841}],"con":true,"img":false}]}
{"op":"mcm","clk":"11540400023","pt":1719494022324,"mc":[{"id":"1.230180112","rc":[{"atb":[[1.73,2]],"id":68870841}],"con":true,"img":false}]}
{"op":"mcm","clk":"11540400039","pt":1719494022740,"mc":[{"id":"1.230180112","rc":[{"atb":[[1.71,0]],"id":58974183}],"con":true,"img":false}]}
{"op":"mcm","clk":"11540400051","pt":1719494022843,"mc":[{"id":"1.230180112","rc":[{"atb":[[1.73,2]],"id":58974183}],"con":true,"img":false}]}
{"op":"mcm","clk":"11540400194","pt":1719494024535,"mc":[{"id":"1.230180112","rc":[{"atb":[[1.72,0]],"id":58974183}],"con":true,"img":false}]}
{"op":"mcm","clk":"11540400221","pt":1719494024842,"mc":[{"id":"1.230180112","rc":[{"atb":[[1.72,0]],"id":68870841}],"con":true,"img":false}]}
{"op":"mcm","clk":"11540400257","pt":1719494025260,"mc":[{"id":"1.230180112","rc":[{"atb":[[1.73,0]],"id":58974183}],"con":true,"img":false}]}
{"op":"mcm","clk":"11540400268","pt":1719494025315,"mc":[{"id":"1.230180112","rc":[{"atb":[[1.71,2]],"id":58974183}],"con":true,"img":false}]}
{"op":"mcm","clk":"11540400340","pt":1719494026033,"mc":[{"id":"1.230180112","rc":[{"atb":[[1.73,0]],"id":68870841}],"con":true,"img":false}]}
{"op":"mcm","clk":"11540400344","pt":1719494026141,"mc":[{"id":"1.230180112","rc":[{"atb":[[1.71,2]],"id":68870841}],"con":true,"img":false}]}
{"op":"mcm","clk":"11540400461","pt":1719494027535,"mc":[{"id":"1.230180112","rc":[{"atb":[[1.72,1.66]],"id":58974183}],"con":true,"img":false}]}
{"op":"mcm","clk":"11540400484","pt":1719494027854,"mc":[{"id":"1.230180112","rc":[{"atb":[[1.72,1.59]],"id":68870841}],"con":true,"img":false}]}
{"op":"mcm","clk":"11540400518","pt":1719494028333,"mc":[{"id":"1.230180112","rc":[{"atb":[[1.71,0]],"id":58974183}],"con":true,"img":false}]}
{"op":"mcm","clk":"11540400526","pt":1719494028440,"mc":[{"id":"1.230180112","rc":[{"atb":[[1.73,2]],"id":58974183}],"con":true,"img":false}]}
{"op":"mcm","clk":"11540400581","pt":1719494029054,"mc":[{"id":"1.230180112","rc":[{"atb":[[1.71,0]],"id":68870841}],"con":true,"img":false}]}
{"op":"mcm","clk":"11540400589","pt":1719494029157,"mc":[{"id":"1.230180112","rc":[{"atb":[[1.73,2]],"id":68870841}],"con":true,"img":false}]}
{"op":"mcm","clk":"11540400708","pt":1719494030555,"mc":[{"id":"1.230180112","rc":[{"atb":[[1.72,0]],"id":58974183}],"con":true,"img":false}]}
{"op":"mcm","clk":"11540400724","pt":1719494030762,"mc":[{"id":"1.230180112","rc":[{"atb":[[1.72,0]],"id":68870841}],"con":true,"img":false}]}
{"op":"mcm","clk":"11540400769","pt":1719494031336,"mc":[{"id":"1.230180112","rc":[{"atb":[[1.73,0]],"id":68870841}],"con":true,"img":false}]}
{"op":"mcm","clk":"11540400779","pt":1719494031435,"mc":[{"id":"1.230180112","rc":[{"atb":[[1.71,2]],"id":68870841}],"con":true,"img":false}]}
{"op":"mcm","clk":"11540400804","pt":1719494031749,"mc":[{"id":"1.230180112","rc":[{"atb":[[1.73,0]],"id":58974183}],"con":true,"img":false}]}
{"op":"mcm","clk":"11540400813","pt":1719494031856,"mc":[{"id":"1.230180112","rc":[{"atb":[[1.71,2]],"id":58974183}],"con":true,"img":false}]}
{"op":"mcm","clk":"11540400971","pt":1719494033467,"mc":[{"id":"1.230180112","rc":[{"atb":[[1.72,1.74]],"id":58974183}],"con":true,"img":false}]}
{"op":"mcm","clk":"11540401013","pt":1719494033830,"mc":[{"id":"1.230180112","rc":[{"atb":[[1.71,0]],"id":58974183}],"con":true,"img":false}]}
{"op":"mcm","clk":"11540401017","pt":1719494033937,"mc":[{"id":"1.230180112","rc":[{"atb":[[1.73,2]],"id":58974183}],"con":true,"img":false}]}
{"op":"mcm","clk":"11540401278","pt":1719494036627,"mc":[{"id":"1.230180112","rc":[{"atb":[[1.72,0]],"id":58974183}],"con":true,"img":false}]}
{"op":"mcm","clk":"11540401301","pt":1719494036937,"mc":[{"id":"1.230180112","rc":[{"atb":[[1.72,1.95]],"id":68870841}],"con":true,"img":false}]}
{"op":"mcm","clk":"11540401369","pt":1719494037875,"mc":[{"id":"1.230180112","rc":[{"atb":[[1.73,0]],"id":58974183}],"con":true,"img":false}]}
{"op":"mcm","clk":"11540401377","pt":1719494037966,"mc":[{"id":"1.230180112","rc":[{"atb":[[1.71,2]],"id":58974183}],"con":true,"img":false}]}
{"op":"mcm","clk":"11540401425","pt":1719494039128,"mc":[{"id":"1.230180112","rc":[{"atb":[[1.71,0]],"id":68870841}],"con":true,"img":false}]}
{"op":"mcm","clk":"11540401435","pt":1719494039135,"mc":[{"id":"1.230180112","rc":[{"atb":[[1.73,2]],"id":68870841}],"con":true,"img":false}]}
{"op":"mcm","clk":"11540401517","pt":1719494039835,"mc":[{"id":"1.230180112","rc":[{"atb":[[1.72,1.75]],"id":58974183}],"con":true,"img":false}]}
{"op":"mcm","clk":"11540401542","pt":1719494040148,"mc":[{"id":"1.230180112","rc":[{"atb":[[1.72,0]],"id":68870841}],"con":true,"img":false}]}
{"op":"mcm","clk":"11540401593","pt":1719494040767,"mc":[{"id":"1.230180112","rc":[{"atb":[[1.73,0]],"id":68870841}],"con":true,"img":false}]}
{"op":"mcm","clk":"11540401602","pt":1719494040876,"mc":[{"id":"1.230180112","rc":[{"atb":[[1.71,2]],"id":68870841}],"con":true,"img":false}]}
{"op":"mcm","clk":"11540401628","pt":1719494041138,"mc":[{"id":"1.230180112","rc":[{"atb":[[1.71,0]],"id":58974183}],"con":true,"img":false}]}
{"op":"mcm","clk":"11540401633","pt":1719494041260,"mc":[{"id":"1.230180112","rc":[{"atb":[[1.73,2]],"id":58974183}],"con":true,"img":false}]}
{"op":"mcm","clk":"11540401766","pt":1719494042860,"mc":[{"id":"1.230180112","rc":[{"atb":[[1.72,0]],"id":58974183}],"con":true,"img":false}]}
{"op":"mcm","clk":"11540401803","pt":1719494043477,"mc":[{"id":"1.230180112","rc":[{"atb":[[1.73,0]],"id":58974183}],"con":true,"img":false}]}
{"op":"mcm","clk":"11540401813","pt":1719494043535,"mc":[{"id":"1.230180112","rc":[{"atb":[[1.71,2]],"id":58974183}],"con":true,"img":false}]}
{"op":"mcm","clk":"11540402019","pt":1719494045451,"mc":[{"id":"1.230180112","rc":[{"atb":[[1.72,1.91]],"id":68870841}],"con":true,"img":false}]}
{"op":"mcm","clk":"11540402135","pt":1719494046648,"mc":[{"id":"1.230180112","rc":[{"atb":[[1.71,0]],"id":68870841}],"con":true,"img":false}]}
{"op":"mcm","clk":"11540402144","pt":1719494046751,"mc":[{"id":"1.230180112","rc":[{"atb":[[1.73,2]],"id":68870841}],"con":true,"img":false}]}
{"op":"mcm","clk":"11540402310","pt":1719494048798,"mc":[{"id":"1.230180112","rc":[{"atb":[[1.72,1.76]],"id":58974183}],"con":true,"img":false}]}
{"op":"mcm","clk":"11540402339","pt":1719494049141,"mc":[{"id":"1.230180112","rc":[{"atb":[[1.72,0]],"id":68870841}],"con":true,"img":false}]}
{"op":"mcm","clk":"11540402427","pt":1719494050385,"mc":[{"id":"1.230180112","rc":[{"atb":[[1.73,0]],"id":68870841}],"con":true,"img":false}]}
{"op":"mcm","clk":"11540402436","pt":1719494050484,"mc":[{"id":"1.230180112","rc":[{"atb":[[1.71,2]],"id":68870841}],"con":true,"img":false}]}
{"op":"mcm","clk":"11540402466","pt":1719494050848,"mc":[{"id":"1.230180112","rc":[{"atb":[[1.71,0]],"id":58974183}],"con":true,"img":false}]}
{"op":"mcm","clk":"11540402476","pt":1719494050950,"mc":[{"id":"1.230180112","rc":[{"atb":[[1.73,2]],"id":58974183}],"con":true,"img":false}]}
{"op":"mcm","clk":"11540402525","pt":1719494051463,"mc":[{"id":"1.230180112","rc":[{"atb":[[1.72,0]],"id":58974183}],"con":true,"img":false}]}
{"op":"mcm","clk":"11540402583","pt":1719494052290,"mc":[{"id":"1.230180112","rc":[{"atb":[[1.73,0]],"id":58974183}],"con":true,"img":false}]}
{"op":"mcm","clk":"11540402590","pt":1719494052343,"mc":[{"id":"1.230180112","rc":[{"atb":[[1.71,2]],"id":58974183}],"con":true,"img":false}]}
{"op":"mcm","clk":"11540402777","pt":1719494054877,"mc":[{"id":"1.230180112","rc":[{"atb":[[1.72,1.75]],"id":58974183}],"con":true,"img":false}]}
{"op":"mcm","clk":"11540402799","pt":1719494055195,"mc":[{"id":"1.230180112","rc":[{"atb":[[1.72,1.66]],"id":68870841}],"con":true,"img":false}]}
{"op":"mcm","clk":"11540402815","pt":1719494055352,"mc":[{"id":"1.230180112","rc":[{"atb":[[1.71,0]],"id":58974183}],"con":true,"img":false}]}
{"op":"mcm","clk":"11540402824","pt":1719494055461,"mc":[{"id":"1.230180112","rc":[{"atb":[[1.73,2]],"id":58974183}],"con":true,"img":false}]}
{"op":"mcm","clk":"11540402873","pt":1719494056077,"mc":[{"id":"1.230180112","rc":[{"atb":[[1.71,0]],"id":68870841}],"con":true,"img":false}]}
{"op":"mcm","clk":"11540402881","pt":1719494056186,"mc":[{"id":"1.230180112","rc":[{"atb":[[1.73,2]],"id":68870841}],"con":true,"img":false}]}
{"op":"mcm","clk":"11540403008","pt":1719494057991,"mc":[{"id":"1.230180112","rc":[{"atb":[[1.72,0]],"id":58974183}],"con":true,"img":false}]}
{"op":"mcm","clk":"11540403034","pt":1719494058360,"mc":[{"id":"1.230180112","rc":[{"atb":[[1.72,0]],"id":68870841}],"con":true,"img":false}]}
{"op":"mcm","clk":"11540403062","pt":1719494058868,"mc":[{"id":"1.230180112","rc":[{"atb":[[1.73,0]],"id":68870841}],"con":true,"img":false}]}
{"op":"mcm","clk":"11540403067","pt":1719494058971,"mc":[{"id":"1.230180112","rc":[{"atb":[[1.71,2]],"id":68870841}],"con":true,"img":false}]}
{"op":"mcm","clk":"11540403083","pt":1719494059280,"mc":[{"id":"1.230180112","rc":[{"atb":[[1.73,0]],"id":58974183}],"con":true,"img":false}]}
{"op":"mcm","clk":"11540403090","pt":1719494059383,"mc":[{"id":"1.230180112","rc":[{"atb":[[1.71,2]],"id":58974183}],"con":true,"img":false}]}
{"op":"mcm","clk":"11540403424","pt":1719494064062,"mc":[{"id":"1.230180112","rc":[{"atb":[[1.72,1.87]],"id":58974183},{"spn":70.85,"spf":"NaN","id":68870841}],"con":true,"img":false}]}
{"op":"mcm","clk":"11540403450","pt":1719494064376,"mc":[{"id":"1.230180112","rc":[{"atb":[[1.72,1.75]],"id":68870841}],"con":true,"img":false}]}
{"op":"mcm","clk":"11540403469","pt":1719494064585,"mc":[{"id":"1.230180112","rc":[{"atb":[[1.71,0]],"id":58974183}],"con":true,"img":false}]}
{"op":"mcm","clk":"11540403480","pt":1719494064682,"mc":[{"id":"1.230180112","rc":[{"atb":[[1.73,2]],"id":58974183}],"con":true,"img":false}]}
{"op":"mcm","clk":"11540403533","pt":1719494065505,"mc":[{"id":"1.230180112","rc":[{"atb":[[1.71,0]],"id":68870841}],"con":true,"img":false}]}
{"op":"mcm","clk":"11540403542","pt":1719494065604,"mc":[{"id":"1.230180112","rc":[{"atb":[[1.73,2]],"id":68870841}],"con":true,"img":false}]}
{"op":"mcm","clk":"11540403596","pt":1719494066590,"mc":[{"id":"1.230180112","rc":[{"atb":[[1.72,0]],"id":58974183}],"con":true,"img":false}]}
{"op":"mcm","clk":"11540403623","pt":1719494067003,"mc":[{"id":"1.230180112","rc":[{"atb":[[1.72,0]],"id":68870841}],"con":true,"img":false}]}
{"op":"mcm","clk":"11540403633","pt":1719494067110,"mc":[{"id":"1.230180112","rc":[{"atb":[[1.73,0]],"id":58974183}],"con":true,"img":false}]}
{"op":"mcm","clk":"11540403639","pt":1719494067209,"mc":[{"id":"1.230180112","rc":[{"atb":[[1.71,2]],"id":58974183}],"con":true,"img":false}]}
{"op":"mcm","clk":"11540403699","pt":1719494067879,"mc":[{"id":"1.230180112","rc":[{"atb":[[1.73,0]],"id":68870841}],"con":true,"img":false}]}
{"op":"mcm","clk":"11540403713","pt":1719494067986,"mc":[{"id":"1.230180112","rc":[{"atb":[[1.71,2]],"id":68870841}],"con":true,"img":false}]}
{"op":"mcm","clk":"11540403857","pt":1719494069888,"mc":[{"id":"1.230180112","rc":[{"atb":[[1.72,1.78]],"id":58974183}],"con":true,"img":false}]}
{"op":"mcm","clk":"11540403882","pt":1719494070201,"mc":[{"id":"1.230180112","rc":[{"atb":[[1.72,1.75]],"id":68870841}],"con":true,"img":false}]}
{"op":"mcm","clk":"11540403941","pt":1719494070971,"mc":[{"id":"1.230180112","rc":[{"atb":[[1.71,0]],"id":68870841}],"con":true,"img":false}]}
{"op":"mcm","clk":"11540403946","pt":1719494071080,"mc":[{"id":"1.230180112","rc":[{"atb":[[1.73,2]],"id":68870841}],"con":true,"img":false}]}
{"op":"mcm","clk":"11540403966","pt":1719494071280,"mc":[{"id":"1.230180112","rc":[{"atb":[[1.71,0]],"id":58974183}],"con":true,"img":false}]}
{"op":"mcm","clk":"11540403977","pt":1719494071385,"mc":[{"id":"1.230180112","rc":[{"atb":[[1.73,2]],"id":58974183}],"con":true,"img":false}]}
{"op":"mcm","clk":"11540404066","pt":1719494072678,"mc":[{"id":"1.230180112","rc":[{"atb":[[1.72,0]],"id":58974183}],"con":true,"img":false}]}
{"op":"mcm","clk":"11540404094","pt":1719494073094,"mc":[{"id":"1.230180112","rc":[{"atb":[[1.73,0]],"id":58974183},{"atb":[[1.72,0]],"id":68870841}],"con":true,"img":false}]}
{"op":"mcm","clk":"11540404106","pt":1719494073200,"mc":[{"id":"1.230180112","rc":[{"atb":[[1.71,2]],"id":58974183}],"con":true,"img":false}]}
{"op":"mcm","clk":"11540404158","pt":1719494073973,"mc":[{"id":"1.230180112","rc":[{"atb":[[1.73,0]],"id":68870841}],"con":true,"img":false}]}
{"op":"mcm","clk":"11540404163","pt":1719494074077,"mc":[{"id":"1.230180112","rc":[{"atb":[[1.71,2]],"id":68870841}],"con":true,"img":false}]}
{"op":"mcm","clk":"11540404562","pt":1719494078996,"mc":[{"id":"1.230180112","rc":[{"atb":[[1.72,1.64]],"id":58974183}],"con":true,"img":false}]}
{"op":"mcm","clk":"11540404587","pt":1719494079303,"mc":[{"id":"1.230180112","rc":[{"atb":[[1.72,1.93]],"id":68870841}],"con":true,"img":false}]}
{"op":"mcm","clk":"11540404621","pt":1719494079823,"mc":[{"id":"1.230180112","rc":[{"atb":[[1.71,0]],"id":58974183}],"con":true,"img":false}]}
{"op":"mcm","clk":"11540404629","pt":1719494079929,"mc":[{"id":"1.230180112","rc":[{"atb":[[1.73,2]],"id":58974183}],"con":true,"img":false}]}
{"op":"mcm","clk":"11540404678","pt":1719494080702,"mc":[{"id":"1.230180112","rc":[{"atb":[[1.71,0]],"id":68870841}],"con":true,"img":false}]}
{"op":"mcm","clk":"11540404689","pt":1719494080803,"mc":[{"id":"1.230180112","rc":[{"atb":[[1.73,2]],"id":68870841}],"con":true,"img":false}]}
{"op":"mcm","clk":"11540404802","pt":1719494082110,"mc":[{"id":"1.230180112","rc":[{"atb":[[1.72,0]],"id":58974183}],"con":true,"img":false}]}
{"op":"mcm","clk":"11540404831","pt":1719494082512,"mc":[{"id":"1.230180112","rc":[{"atb":[[1.73,0]],"id":58974183},{"atb":[[1.72,0]],"id":68870841}],"con":true,"img":false}]}
{"op":"mcm","clk":"11540404838","pt":1719494082610,"mc":[{"id":"1.230180112","rc":[{"atb":[[1.71,2]],"id":58974183}],"con":true,"img":false}]}
{"op":"mcm","clk":"11540404891","pt":1719494083488,"mc":[{"id":"1.230180112","rc":[{"atb":[[1.73,0]],"id":68870841}],"con":true,"img":false}]}
{"op":"mcm","clk":"11540404900","pt":1719494083597,"mc":[{"id":"1.230180112","rc":[{"atb":[[1.71,2]],"id":68870841}],"con":true,"img":false}]}
{"op":"mcm","clk":"11540405010","pt":1719494085192,"mc":[{"id":"1.230180112","rc":[{"atb":[[1.72,1.61]],"id":58974183}],"con":true,"img":false}]}
{"op":"mcm","clk":"11540405026","pt":1719494085506,"mc":[{"id":"1.230180112","rc":[{"atb":[[1.72,1.99]],"id":68870841}],"con":true,"img":false}]}
{"op":"mcm","clk":"11540405040","pt":1719494085708,"mc":[{"id":"1.230180112","rc":[{"atb":[[1.71,0]],"id":58974183}],"con":true,"img":false}]}
{"op":"mcm","clk":"11540405048","pt":1719494085811,"mc":[{"id":"1.230180112","rc":[{"atb":[[1.73,2]],"id":58974183}],"con":true,"img":false}]}
{"op":"mcm","clk":"11540405091","pt":1719494086439,"mc":[{"id":"1.230180112","rc":[{"atb":[[1.71,0]],"id":68870841}],"con":true,"img":false}]}
{"op":"mcm","clk":"11540405098","pt":1719494086493,"mc":[{"id":"1.230180112","rc":[{"atb":[[1.73,2]],"id":68870841}],"con":true,"img":false}]}
{"op":"mcm","clk":"11540405175","pt":1719494087732,"mc":[{"id":"1.230180112","rc":[{"atb":[[1.72,0]],"id":58974183}],"con":true,"img":false}]}
{"op":"mcm","clk":"11540405195","pt":1719494088093,"mc":[{"id":"1.230180112","rc":[{"atb":[[1.72,0]],"id":68870841}],"con":true,"img":false}]}
{"op":"mcm","clk":"11540405209","pt":1719494088298,"mc":[{"id":"1.230180112","rc":[{"atb":[[1.73,0]],"id":58974183}],"con":true,"img":false}]}
{"op":"mcm","clk":"11540405218","pt":1719494088399,"mc":[{"id":"1.230180112","rc":[{"atb":[[1.71,2]],"id":58974183}],"con":true,"img":false}]}
{"op":"mcm","clk":"11540405301","pt":1719494089530,"mc":[{"id":"1.230180112","rc":[{"atb":[[1.73,0]],"id":68870841}],"con":true,"img":false}]}
{"op":"mcm","clk":"11540405308","pt":1719494089637,"mc":[{"id":"1.230180112","rc":[{"atb":[[1.71,2]],"id":68870841}],"con":true,"img":false}]}
{"op":"mcm","clk":"11540405397","pt":1719494091033,"mc":[{"id":"1.230180112","rc":[{"atb":[[1.72,1.93]],"id":58974183}],"con":true,"img":false}]}
{"op":"mcm","clk":"11540405419","pt":1719494091242,"mc":[{"id":"1.230180112","rc":[{"atb":[[1.72,1.85]],"id":68870841}],"con":true,"img":false}]}
{"op":"mcm","clk":"11540405443","pt":1719494091508,"mc":[{"id":"1.230180112","rc":[{"atb":[[1.71,0]],"id":58974183}],"con":true,"img":false}]}
{"op":"mcm","clk":"11540405451","pt":1719494091602,"mc":[{"id":"1.230180112","rc":[{"atb":[[1.73,2]],"id":58974183}],"con":true,"img":false}]}
{"op":"mcm","clk":"11540405499","pt":1719494092532,"mc":[{"id":"1.230180112","rc":[{"atb":[[1.71,0]],"id":68870841}],"con":true,"img":false}]}
{"op":"mcm","clk":"11540405506","pt":1719494092635,"mc":[{"id":"1.230180112","rc":[{"atb":[[1.73,2]],"id":68870841}],"con":true,"img":false}]}
{"op":"mcm","clk":"11540405608","pt":1719494094234,"mc":[{"id":"1.230180112","rc":[{"atb":[[1.72,0]],"id":58974183}],"con":true,"img":false}]}
{"op":"mcm","clk":"11540405641","pt":1719494094596,"mc":[{"id":"1.230180112","rc":[{"atb":[[1.72,0]],"id":68870841}],"con":true,"img":false}]}
{"op":"mcm","clk":"11540405663","pt":1719494094911,"mc":[{"id":"1.230180112","rc":[{"atb":[[1.73,0]],"id":58974183}],"con":true,"img":false}]}
{"op":"mcm","clk":"11540405667","pt":1719494095009,"mc":[{"id":"1.230180112","rc":[{"atb":[[1.71,2]],"id":58974183}],"con":true,"img":false}]}
{"op":"mcm","clk":"11540405727","pt":1719494096152,"mc":[{"id":"1.230180112","rc":[{"atb":[[1.73,0]],"id":68870841}],"con":true,"img":false}]}
{"op":"mcm","clk":"11540405735","pt":1719494096197,"mc":[{"id":"1.230180112","rc":[{"atb":[[1.71,2]],"id":68870841}],"con":true,"img":false}]}
{"op":"mcm","clk":"11540405960","pt":1719494100022,"mc":[{"id":"1.230180112","rc":[{"atb":[[1.72,1.7]],"id":58974183}],"con":true,"img":false}]}
{"op":"mcm","clk":"11540405984","pt":1719494100330,"mc":[{"id":"1.230180112","rc":[{"atb":[[1.72,1.61]],"id":68870841}],"con":true,"img":false}]}
{"op":"mcm","clk":"11540406045","pt":1719494101320,"mc":[{"id":"1.230180112","rc":[{"atb":[[1.71,0]],"id":68870841}],"con":true,"img":false}]}
{"op":"mcm","clk":"11540406054","pt":1719494101422,"mc":[{"id":"1.230180112","rc":[{"atb":[[1.73,2]],"id":68870841}],"con":true,"img":false}]}
{"op":"mcm","clk":"11540406075","pt":1719494101737,"mc":[{"id":"1.230180112","rc":[{"atb":[[1.71,0]],"id":58974183}],"con":true,"img":false}]}
{"op":"mcm","clk":"11540406082","pt":1719494101836,"mc":[{"id":"1.230180112","rc":[{"atb":[[1.73,2]],"id":58974183}],"con":true,"img":false}]}
{"op":"mcm","clk":"11540406150","pt":1719494102822,"mc":[{"id":"1.230180112","rc":[{"atb":[[1.72,0]],"id":58974183}],"con":true,"img":false}]}
{"op":"mcm","clk":"11540406166","pt":1719494103134,"mc":[{"id":"1.230180112","rc":[{"atb":[[1.73,0]],"id":58974183},{"atb":[[1.72,0]],"id":68870841}],"con":true,"img":false}]}
{"op":"mcm","clk":"11540406173","pt":1719494103237,"mc":[{"id":"1.230180112","rc":[{"atb":[[1.71,2]],"id":58974183}],"con":true,"img":false}]}
{"op":"mcm","clk":"11540406225","pt":1719494103917,"mc":[{"id":"1.230180112","rc":[{"atb":[[1.73,0]],"id":68870841}],"con":true,"img":false}]}
{"op":"mcm","clk":"11540406237","pt":1719494104019,"mc":[{"id":"1.230180112","rc":[{"atb":[[1.71,2]],"id":68870841}],"con":true,"img":false}]}
{"op":"mcm","clk":"11540406369","pt":1719494105845,"mc":[{"id":"1.230180112","rc":[{"atb":[[1.72,1.56]],"id":58974183}],"con":true,"img":false}]}
{"op":"mcm","clk":"11540406394","pt":1719494106154,"mc":[{"id":"1.230180112","rc":[{"atb":[[1.72,1.61]],"id":68870841}],"con":true,"img":false}]}
{"op":"mcm","clk":"11540406463","pt":1719494107062,"mc":[{"id":"1.230180112","rc":[{"atb":[[1.71,0]],"id":68870841}],"con":true,"img":false}]}
{"op":"mcm","clk":"11540406470","pt":1719494107159,"mc":[{"id":"1.230180112","rc":[{"atb":[[1.73,2]],"id":68870841}],"con":true,"img":false}]}
{"op":"mcm","clk":"11540406491","pt":1719494107529,"mc":[{"id":"1.230180112","rc":[{"atb":[[1.71,0]],"id":58974183}],"con":true,"img":false}]}
{"op":"mcm","clk":"11540406499","pt":1719494107627,"mc":[{"id":"1.230180112","rc":[{"atb":[[1.73,2]],"id":58974183}],"con":true,"img":false}]}
{"op":"mcm","clk":"11540406598","pt":1719494109234,"mc":[{"id":"1.230180112","rc":[{"atb":[[1.72,0]],"id":58974183}],"con":true,"img":false}]}
{"op":"mcm","clk":"11540406625","pt":1719494109650,"mc":[{"id":"1.230180112","rc":[{"atb":[[1.72,0]],"id":68870841}],"con":true,"img":false}]}
{"op":"mcm","clk":"11540406674","pt":1719494110600,"mc":[{"id":"1.230180112","rc":[{"atb":[[1.73,0]],"id":68870841}],"con":true,"img":false}]}
{"op":"mcm","clk":"11540406684","pt":1719494110649,"mc":[{"id":"1.230180112","rc":[{"atb":[[1.71,2]],"id":68870841}],"con":true,"img":false}]}
{"op":"mcm","clk":"11540406699","pt":1719494110957,"mc":[{"id":"1.230180112","rc":[{"atb":[[1.73,0]],"id":58974183}],"con":true,"img":false}]}
{"op":"mcm","clk":"11540406705","pt":1719494111058,"mc":[{"id":"1.230180112","rc":[{"atb":[[1.71,2]],"id":58974183}],"con":true,"img":false}]}
{"op":"mcm","clk":"11540406765","pt":1719494112247,"mc":[{"id":"1.230180112","rc":[{"atb":[[1.72,1.92]],"id":58974183}],"con":true,"img":false}]}
{"op":"mcm","clk":"11540406800","pt":1719494112764,"mc":[{"id":"1.230180112","rc":[{"atb":[[1.71,0]],"id":58974183}],"con":true,"img":false}]}
{"op":"mcm","clk":"11540406805","pt":1719494112867,"mc":[{"id":"1.230180112","rc":[{"atb":[[1.73,2]],"id":58974183}],"con":true,"img":false}]}
{"op":"mcm","clk":"11540406935","pt":1719494114835,"mc":[{"id":"1.230180112","rc":[{"atb":[[1.72,0]],"id":58974183}],"con":true,"img":false}]}
{"op":"mcm","clk":"11540406950","pt":1719494115143,"mc":[{"id":"1.230180112","rc":[{"atb":[[1.72,1.79]],"id":68870841}],"con":true,"img":false}]}
{"op":"mcm","clk":"11540406968","pt":1719494115558,"mc":[{"id":"1.230180112","rc":[{"atb":[[1.73,0]],"id":58974183}],"con":true,"img":false}]}
{"op":"mcm","clk":"11540406973","pt":1719494115656,"mc":[{"id":"1.230180112","rc":[{"atb":[[1.71,2]],"id":58974183}],"con":true,"img":false}]}
{"op":"mcm","clk":"11540407054","pt":1719494117052,"mc":[{"id":"1.230180112","rc":[{"atb":[[1.71,0]],"id":68870841}],"con":true,"img":false}]}
{"op":"mcm","clk":"11540407060","pt":1719494117154,"mc":[{"id":"1.230180112","rc":[{"atb":[[1.73,2]],"id":68870841}],"con":true,"img":false}]}
{"op":"mcm","clk":"11540407109","pt":1719494118038,"mc":[{"id":"1.230180112","rc":[{"atb":[[1.72,1.52]],"id":58974183}],"con":true,"img":false}]}
{"op":"mcm","clk":"11540407126","pt":1719494118356,"mc":[{"id":"1.230180112","rc":[{"atb":[[1.72,0]],"id":68870841}],"con":true,"img":false}]}
{"op":"mcm","clk":"11540407135","pt":1719494118450,"mc":[{"id":"1.230180112","rc":[{"atb":[[1.71,0]],"id":58974183}],"con":true,"img":false}]}
{"op":"mcm","clk":"11540407142","pt":1719494118552,"mc":[{"id":"1.230180112","rc":[{"atb":[[1.73,2]],"id":58974183}],"con":true,"img":false}]}
{"op":"mcm","clk":"11540407180","pt":1719494119171,"mc":[{"id":"1.230180112","rc":[{"atb":[[1.73,0]],"id":68870841}],"con":true,"img":false}]}
{"op":"mcm","clk":"11540407183","pt":1719494119274,"mc":[{"id":"1.230180112","rc":[{"atb":[[1.71,2]],"id":68870841}],"con":true,"img":false}]}
{"op":"mcm","clk":"11540407310","pt":1719494121344,"mc":[{"id":"1.230180112","rc":[{"atb":[[1.72,0]],"id":58974183}],"con":true,"img":false}]}
{"op":"mcm","clk":"11540407330","pt":1719494121654,"mc":[{"id":"1.230180112","rc":[{"atb":[[1.72,1.59]],"id":68870841}],"con":true,"img":false}]}
{"op":"mcm","clk":"11540407358","pt":1719494122169,"mc":[{"id":"1.230180112","rc":[{"atb":[[1.73,0]],"id":58974183}],"con":true,"img":false}]}
{"op":"mcm","clk":"11540407363","pt":1719494122271,"mc":[{"id":"1.230180112","rc":[{"atb":[[1.71,2]],"id":58974183}],"con":true,"img":false}]}
{"op":"mcm","clk":"11540407415","pt":1719494122946,"mc":[{"id":"1.230180112","rc":[{"atb":[[1.71,0]],"id":68870841}],"con":true,"img":false}]}
{"op":"mcm","clk":"11540407420","pt":1719494123050,"mc":[{"id":"1.230180112","rc":[{"atb":[[1.73,2]],"id":68870841}],"con":true,"img":false}]}
{"op":"mcm","clk":"11540407491","pt":1719494124293,"mc":[{"id":"1.230180112","rc":[{"atb":[[1.72,1.52]],"id":58974183},{"spn":70.86,"spf":"NaN","id":68870841}],"con":true,"img":false}]}
{"op":"mcm","clk":"11540407518","pt":1719494124653,"mc":[{"id":"1.230180112","rc":[{"atb":[[1.72,0]],"id":68870841}],"con":true,"img":false}]}
{"op":"mcm","clk":"11540407534","pt":1719494125067,"mc":[{"id":"1.230180112","rc":[{"atb":[[1.73,0]],"id":68870841}],"con":true,"img":false}]}
{"op":"mcm","clk":"11540407540","pt":1719494125167,"mc":[{"id":"1.230180112","rc":[{"atb":[[1.71,2]],"id":68870841}],"con":true,"img":false}]}
{"op":"mcm","clk":"11540407555","pt":1719494125476,"mc":[{"id":"1.230180112","rc":[{"atb":[[1.71,0]],"id":58974183}],"con":true,"img":false}]}
{"op":"mcm","clk":"11540407561","pt":1719494125586,"mc":[{"id":"1.230180112","rc":[{"atb":[[1.73,2]],"id":58974183}],"con":true,"img":false}]}
{"op":"mcm","clk":"11540407664","pt":1719494127388,"mc":[{"id":"1.230180112","rc":[{"atb":[[1.72,0]],"id":58974183}],"con":true,"img":false}]}
{"op":"mcm","clk":"11540407689","pt":1719494127649,"mc":[{"id":"1.230180112","rc":[{"atb":[[1.72,1.91]],"id":68870841}],"con":true,"img":false}]}
{"op":"mcm","clk":"11540407695","pt":1719494127752,"mc":[{"id":"1.230180112","rc":[{"atb":[[1.73,0]],"id":58974183}],"con":true,"img":false}]}
{"op":"mcm","clk":"11540407702","pt":1719494127853,"mc":[{"id":"1.230180112","rc":[{"atb":[[1.71,2]],"id":58974183}],"con":true,"img":false}]}
{"op":"mcm","clk":"11540407761","pt":1719494129296,"mc":[{"id":"1.230180112","rc":[{"atb":[[1.71,0]],"id":68870841}],"con":true,"img":false}]}
{"op":"mcm","clk":"11540407766","pt":1719494129352,"mc":[{"id":"1.230180112","rc":[{"atb":[[1.73,2]],"id":68870841}],"con":true,"img":false}]}
{"op":"mcm","clk":"11540407790","pt":1719494129869,"mc":[{"id":"1.230180112","rc":[{"atb":[[1.72,0]],"id":68870841}],"con":true,"img":false}]}
{"op":"mcm","clk":"11540407845","pt":1719494130854,"mc":[{"id":"1.230180112","rc":[{"atb":[[1.73,0]],"id":68870841}],"con":true,"img":false}]}
{"op":"mcm","clk":"11540407850","pt":1719494130958,"mc":[{"id":"1.230180112","rc":[{"atb":[[1.71,2]],"id":68870841}],"con":true,"img":false}]}
{"op":"mcm","clk":"11540407964","pt":1719494133231,"mc":[{"id":"1.230180112","rc":[{"atb":[[1.72,1.87]],"id":58974183}],"con":true,"img":false}]}
{"op":"mcm","clk":"11540407981","pt":1719494133546,"mc":[{"id":"1.230180112","rc":[{"atb":[[1.72,1.9]],"id":68870841}],"con":true,"img":false}]}
{"op":"mcm","clk":"11540408007","pt":1719494133953,"mc":[{"id":"1.230180112","rc":[{"atb":[[1.71,0]],"id":68870841}],"con":true,"img":false}]}
{"op":"mcm","clk":"11540408014","pt":1719494134055,"mc":[{"id":"1.230180112","rc":[{"atb":[[1.73,2]],"id":68870841}],"con":true,"img":false}]}
{"op":"mcm","clk":"11540408030","pt":1719494134317,"mc":[{"id":"1.230180112","rc":[{"atb":[[1.71,0]],"id":58974183}],"con":true,"img":false}]}
{"op":"mcm","clk":"11540408034","pt":1719494134471,"mc":[{"id":"1.230180112","rc":[{"atb":[[1.73,2]],"id":58974183}],"con":true,"img":false}]}
{"op":"mcm","clk":"11540408182","pt":1719494136455,"mc":[{"id":"1.230180112","rc":[{"atb":[[1.72,0]],"id":58974183}],"con":true,"img":false}]}
{"op":"mcm","clk":"11540408218","pt":1719494136860,"mc":[{"id":"1.230180112","rc":[{"atb":[[1.72,0]],"id":68870841}],"con":true,"img":false}]}
{"op":"mcm","clk":"11540408223","pt":1719494136963,"mc":[{"id":"1.230180112","rc":[{"atb":[[1.73,0]],"id":58974183}],"con":true,"img":false}]}
{"op":"mcm","clk":"11540408232","pt":1719494137074,"mc":[{"id":"1.230180112","rc":[{"atb":[[1.71,2]],"id":58974183}],"con":true,"img":false}]}
{"op":"mcm","clk":"11540408309","pt":1719494138158,"mc":[{"id":"1.230180112","rc":[{"atb":[[1.73,0]],"id":68870841}],"con":true,"img":false}]}
{"op":"mcm","clk":"11540408316","pt":1719494138259,"mc":[{"id":"1.230180112","rc":[{"atb":[[1.71,2]],"id":68870841}],"con":true,"img":false}]}
{"op":"mcm","clk":"11540408533","pt":1719494142347,"mc":[{"id":"1.230180112","rc":[{"atb":[[1.72,1.93]],"id":58974183}],"con":true,"img":false}]}
{"op":"mcm","clk":"11540408553","pt":1719494142652,"mc":[{"id":"1.230180112","rc":[{"atb":[[1.72,1.52]],"id":68870841}],"con":true,"img":false}]}
{"op":"mcm","clk":"11540408577","pt":1719494143165,"mc":[{"id":"1.230180112","rc":[{"atb":[[1.71,0]],"id":68870841}],"con":true,"img":false}]}
{"op":"mcm","clk":"11540408584","pt":1719494143267,"mc":[{"id":"1.230180112","rc":[{"atb":[[1.73,2]],"id":68870841}],"con":true,"img":false}]}
{"op":"mcm","clk":"11540408603","pt":1719494143635,"mc":[{"id":"1.230180112","rc":[{"atb":[[1.71,0]],"id":58974183}],"con":true,"img":false}]}
{"op":"mcm","clk":"11540408612","pt":1719494143737,"mc":[{"id":"1.230180112","rc":[{"atb":[[1.73,2]],"id":58974183}],"con":true,"img":false}]}
{"op":"mcm","clk":"11540408697","pt":1719494145076,"mc":[{"id":"1.230180112","rc":[{"atb":[[1.72,0]],"id":58974183}],"con":true,"img":false}]}
{"op":"mcm","clk":"11540408726","pt":1719494145437,"mc":[{"id":"1.230180112","rc":[{"atb":[[1.72,0]],"id":68870841}],"con":true,"img":false}]}
{"op":"mcm","clk":"11540408743","pt":1719494145649,"mc":[{"id":"1.230180112","rc":[{"atb":[[1.73,0]],"id":58974183}],"con":true,"img":false}]}
{"op":"mcm","clk":"11540408752","pt":1719494145747,"mc":[{"id":"1.230180112","rc":[{"atb":[[1.71,2]],"id":58974183}],"con":true,"img":false}]}
{"op":"mcm","clk":"11540408792","pt":1719494146272,"mc":[{"id":"1.230180112","rc":[{"atb":[[1.73,0]],"id":68870841}],"con":true,"img":false}]}
{"op":"mcm","clk":"11540408800","pt":1719494146368,"mc":[{"id":"1.230180112","rc":[{"atb":[[1.71,2]],"id":68870841}],"con":true,"img":false}]}
{"op":"mcm","clk":"11540408915","pt":1719494148348,"mc":[{"id":"1.230180112","rc":[{"atb":[[1.72,1.67]],"id":58974183}],"con":true,"img":false}]}
{"op":"mcm","clk":"11540408931","pt":1719494148655,"mc":[{"id":"1.230180112","rc":[{"atb":[[1.72,1.55]],"id":68870841}],"con":true,"img":false}]}
{"op":"mcm","clk":"11540408954","pt":1719494149068,"mc":[{"id":"1.230180112","rc":[{"atb":[[1.71,0]],"id":58974183}],"con":true,"img":false}]}
{"op":"mcm","clk":"11540408962","pt":1719494149172,"mc":[{"id":"1.230180112","rc":[{"atb":[[1.73,2]],"id":58974183}],"con":true,"img":false}]}
{"op":"mcm","clk":"11540409030","pt":1719494149949,"mc":[{"id":"1.230180112","rc":[{"atb":[[1.71,0]],"id":68870841}],"con":true,"img":false}]}
{"op":"mcm","clk":"11540409037","pt":1719494150052,"mc":[{"id":"1.230180112","rc":[{"atb":[[1.73,2]],"id":68870841}],"con":true,"img":false}]}
{"op":"mcm","clk":"11540409105","pt":1719494150952,"mc":[{"id":"1.230180112","rc":[{"atb":[[1.72,0]],"id":58974183}],"con":true,"img":false}]}
{"op":"mcm","clk":"11540409126","pt":1719494151265,"mc":[{"id":"1.230180112","rc":[{"atb":[[1.72,0]],"id":68870841}],"con":true,"img":false}]}
{"op":"mcm","clk":"11540409148","pt":1719494151680,"mc":[{"id":"1.230180112","rc":[{"atb":[[1.73,0]],"id":68870841}],"con":true,"img":false}]}
{"op":"mcm","clk":"11540409154","pt":1719494151780,"mc":[{"id":"1.230180112","rc":[{"atb":[[1.71,2]],"id":68870841}],"con":true,"img":false}]}
{"op":"mcm","clk":"11540409194","pt":1719494152353,"mc":[{"id":"1.230180112","rc":[{"atb":[[1.73,0]],"id":58974183}],"con":true,"img":false}]}
{"op":"mcm","clk":"11540409205","pt":1719494152461,"mc":[{"id":"1.230180112","rc":[{"atb":[[1.71,2]],"id":58974183}],"con":true,"img":false}]}
{"op":"mcm","clk":"11540409330","pt":1719494154272,"mc":[{"id":"1.230180112","rc":[{"atb":[[1.72,1.94]],"id":58974183}],"con":true,"img":false}]}
{"op":"mcm","clk":"11540409355","pt":1719494154594,"mc":[{"id":"1.230180112","rc":[{"atb":[[1.72,1.91]],"id":68870841}],"con":true,"img":false}]}
{"op":"mcm","clk":"11540409422","pt":1719494155465,"mc":[{"id":"1.230180112","rc":[{"atb":[[1.71,0]],"id":68870841}],"con":true,"img":false}]}
{"op":"mcm","clk":"11540409432","pt":1719494155570,"mc":[{"id":"1.230180112","rc":[{"atb":[[1.73,2]],"id":68870841}],"con":true,"img":false}]}
{"op":"mcm","clk":"11540409446","pt":1719494155782,"mc":[{"id":"1.230180112","rc":[{"atb":[[1.71,0]],"id":58974183}],"con":true,"img":false}]}
{"op":"mcm","clk":"11540409454","pt":1719494155881,"mc":[{"id":"1.230180112","rc":[{"atb":[[1.73,2]],"id":58974183}],"con":true,"img":false}]}
{"op":"mcm","clk":"11540409524","pt":1719494156970,"mc":[{"id":"1.230180112","rc":[{"atb":[[1.72,0]],"id":58974183}],"con":true,"img":false}]}
{"op":"mcm","clk":"11540409553","pt":1719494157390,"mc":[{"id":"1.230180112","rc":[{"atb":[[1.72,0]],"id":68870841}],"con":true,"img":false}]}
{"op":"mcm","clk":"11540409564","pt":1719494157499,"mc":[{"id":"1.230180112","rc":[{"atb":[[1.73,0]],"id":58974183}],"con":true,"img":false}]}
{"op":"mcm","clk":"11540409570","pt":1719494157589,"mc":[{"id":"1.230180112","rc":[{"atb":[[1.71,2]],"id":58974183}],"con":true,"img":false}]}
{"op":"mcm","clk":"11540409609","pt":1719494158379,"mc":[{"id":"1.230180112","rc":[{"atb":[[1.73,0]],"id":68870841}],"con":true,"img":false}]}
{"op":"mcm","clk":"11540409613","pt":1719494158476,"mc":[{"id":"1.230180112","rc":[{"atb":[[1.71,2]],"id":68870841}],"con":true,"img":false}]}
{"op":"mcm","clk":"11540409943","pt":1719494163398,"mc":[{"id":"1.230180112","rc":[{"atb":[[1.72,1.8]],"id":58974183}],"con":true,"img":false}]}
{"op":"mcm","clk":"11540409961","pt":1719494163709,"mc":[{"id":"1.230180112","rc":[{"atb":[[1.72,1.88]],"id":68870841}],"con":true,"img":false}]}
{"op":"mcm","clk":"11540409976","pt":1719494163867,"mc":[{"id":"1.230180112","rc":[{"atb":[[1.71,0]],"id":58974183}],"con":true,"img":false}]}
{"op":"mcm","clk":"11540409981","pt":1719494163971,"mc":[{"id":"1.230180112","rc":[{"atb":[[1.73,2]],"id":58974183}],"con":true,"img":false}]}
{"op":"mcm","clk":"11540410034","pt":1719494165005,"mc":[{"id":"1.230180112","rc":[{"atb":[[1.71,0]],"id":68870841}],"con":true,"img":false}]}
{"op":"mcm","clk":"11540410043","pt":1719494165112,"mc":[{"id":"1.230180112","rc":[{"atb":[[1.73,2]],"id":68870841}],"con":true,"img":false}]}
{"op":"mcm","clk":"11540410120","pt":1719494166098,"mc":[{"id":"1.230180112","rc":[{"atb":[[1.72,0]],"id":58974183}],"con":true,"img":false}]}
{"op":"mcm","clk":"11540410142","pt":1719494166418,"mc":[{"id":"1.230180112","rc":[{"atb":[[1.72,0]],"id":68870841}],"con":true,"img":false}]}
{"op":"mcm","clk":"11540410156","pt":1719494166627,"mc":[{"id":"1.230180112","rc":[{"atb":[[1.73,0]],"id":58974183}],"con":true,"img":false}]}
{"op":"mcm","clk":"11540410164","pt":1719494166727,"mc":[{"id":"1.230180112","rc":[{"atb":[[1.71,2]],"id":58974183}],"con":true,"img":false}]}
{"op":"mcm","clk":"11540410193","pt":1719494167293,"mc":[{"id":"1.230180112","rc":[{"atb":[[1.73,0]],"id":68870841}],"con":true,"img":false}]}
{"op":"mcm","clk":"11540410199","pt":1719494167391,"mc":[{"id":"1.230180112","rc":[{"atb":[[1.71,2]],"id":68870841}],"con":true,"img":false}]}
{"op":"mcm","clk":"11540410331","pt":1719494169325,"mc":[{"id":"1.230180112","rc":[{"atb":[[1.72,1.55]],"id":58974183}],"con":true,"img":false}]}
{"op":"mcm","clk":"11540410346","pt":1719494169582,"mc":[{"id":"1.230180112","rc":[{"atb":[[1.72,1.59]],"id":68870841}],"con":true,"img":false}]}
{"op":"mcm","clk":"11540410370","pt":1719494169990,"mc":[{"id":"1.230180112","rc":[{"atb":[[1.71,0]],"id":58974183}],"con":true,"img":false}]}
{"op":"mcm","clk":"11540410376","pt":1719494170096,"mc":[{"id":"1.230180112","rc":[{"atb":[[1.73,2]],"id":58974183}],"con":true,"img":false}]}
{"op":"mcm","clk":"11540410440","pt":1719494171082,"mc":[{"id":"1.230180112","rc":[{"atb":[[1.71,0]],"id":68870841}],"con":true,"img":false}]}
{"op":"mcm","clk":"11540410449","pt":1719494171184,"mc":[{"id":"1.230180112","rc":[{"atb":[[1.73,2]],"id":68870841}],"con":true,"img":false}]}
{"op":"mcm","clk":"11540410505","pt":1719494172132,"mc":[{"id":"1.230180112","rc":[{"atb":[[1.72,0]],"id":58974183}],"con":true,"img":false}]}
{"op":"mcm","clk":"11540410519","pt":1719494172481,"mc":[{"id":"1.230180112","rc":[{"atb":[[1.73,0]],"id":58974183},{"atb":[[1.72,0]],"id":68870841}],"con":true,"img":false}]}
{"op":"mcm","clk":"11540410525","pt":1719494172584,"mc":[{"id":"1.230180112","rc":[{"atb":[[1.71,2]],"id":58974183}],"con":true,"img":false}]}
{"op":"mcm","clk":"11540410576","pt":1719494173410,"mc":[{"id":"1.230180112","rc":[{"atb":[[1.73,0]],"id":68870841}],"con":true,"img":false}]}
{"op":"mcm","clk":"11540410584","pt":1719494173513,"mc":[{"id":"1.230180112","rc":[{"atb":[[1.71,2]],"id":68870841}],"con":true,"img":false}]}
{"op":"mcm","clk":"11540410738","pt":1719494176114,"mc":[{"id":"1.230180112","rc":[{"atb":[[1.72,1.82]],"id":58974183}],"con":true,"img":false}]}
{"op":"mcm","clk":"11540410749","pt":1719494176428,"mc":[{"id":"1.230180112","rc":[{"atb":[[1.72,1.67]],"id":68870841}],"con":true,"img":false}]}
{"op":"mcm","clk":"11540410778","pt":1719494176798,"mc":[{"id":"1.230180112","rc":[{"atb":[[1.71,0]],"id":68870841}],"con":true,"img":false}]}
{"op":"mcm","clk":"11540410783","pt":1719494176892,"mc":[{"id":"1.230180112","rc":[{"atb":[[1.73,2]],"id":68870841}],"con":true,"img":false}]}
{"op":"mcm","clk":"11540410807","pt":1719494177317,"mc":[{"id":"1.230180112","rc":[{"atb":[[1.71,0]],"id":58974183}],"con":true,"img":false}]}
{"op":"mcm","clk":"11540410812","pt":1719494177466,"mc":[{"id":"1.230180112","rc":[{"atb":[[1.73,2]],"id":58974183}],"con":true,"img":false}]}
{"op":"mcm","clk":"11540410916","pt":1719494178922,"mc":[{"id":"1.230180112","rc":[{"atb":[[1.72,0]],"id":58974183}],"con":true,"img":false}]}
{"op":"mcm","clk":"11540410943","pt":1719494179335,"mc":[{"id":"1.230180112","rc":[{"atb":[[1.72,0]],"id":68870841}],"con":true,"img":false}]}
{"op":"mcm","clk":"11540410948","pt":1719494179390,"mc":[{"id":"1.230180112","rc":[{"atb":[[1.73,0]],"id":58974183}],"con":true,"img":false}]}
{"op":"mcm","clk":"11540410953","pt":1719494179493,"mc":[{"id":"1.230180112","rc":[{"atb":[[1.71,2]],"id":58974183}],"con":true,"img":false}]}
{"op":"mcm","clk":"11540411036","pt":1719494180638,"mc":[{"id":"1.230180112","rc":[{"atb":[[1.73,0]],"id":68870841}],"con":true,"img":false}]}
{"op":"mcm","clk":"11540411046","pt":1719494180735,"mc":[{"id":"1.230180112","rc":[{"atb":[[1.71,2]],"id":68870841}],"con":true,"img":false}]}
{"op":"mcm","clk":"11540411312","pt":1719494184540,"mc":[{"id":"1.230180112","rc":[{"atb":[[1.72,1.84]],"id":58974183},{"spn":70.85,"spf":"NaN","id":68870841}],"con":true,"img":false}]}
{"op":"mcm","clk":"11540411334","pt":1719494184850,"mc":[{"id":"1.230180112","rc":[{"atb":[[1.72,1.51]],"id":68870841}],"con":true,"img":false}]}
{"op":"mcm","clk":"11540411351","pt":1719494185018,"mc":[{"id":"1.230180112","rc":[{"atb":[[1.71,0]],"id":58974183}],"con":true,"img":false}]}
{"op":"mcm","clk":"11540411356","pt":1719494185217,"mc":[{"id":"1.230180112","rc":[{"atb":[[1.73,2]],"id":58974183}],"con":true,"img":false}]}
{"op":"mcm","clk":"11540411442","pt":1719494186054,"mc":[{"id":"1.230180112","rc":[{"atb":[[1.71,0]],"id":68870841}],"con":true,"img":false}]}
{"op":"mcm","clk":"11540411448","pt":1719494186106,"mc":[{"id":"1.230180112","rc":[{"atb":[[1.73,2]],"id":68870841}],"con":true,"img":false}]}
{"op":"mcm","clk":"11540411515","pt":1719494187253,"mc":[{"id":"1.230180112","rc":[{"atb":[[1.72,0]],"id":58974183}],"con":true,"img":false}]}
{"op":"mcm","clk":"11540411547","pt":1719494187622,"mc":[{"id":"1.230180112","rc":[{"atb":[[1.73,0]],"id":58974183},{"atb":[[1.72,0]],"id":68870841}],"con":true,"img":false}]}
{"op":"mcm","clk":"11540411554","pt":1719494187719,"mc":[{"id":"1.230180112","rc":[{"atb":[[1.71,2]],"id":58974183}],"con":true,"img":false}]}
{"op":"mcm","clk":"11540411585","pt":1719494188348,"mc":[{"id":"1.230180112","rc":[{"atb":[[1.73,0]],"id":68870841}],"con":true,"img":false}]}
{"op":"mcm","clk":"11540411592","pt":1719494188452,"mc":[{"id":"1.230180112","rc":[{"atb":[[1.71,2]],"id":68870841}],"con":true,"img":false}]}
{"op":"mcm","clk":"11540411720","pt":1719494190330,"mc":[{"id":"1.230180112","rc":[{"atb":[[1.72,1.51]],"id":58974183}],"con":true,"img":false}]}
{"op":"mcm","clk":"11540411736","pt":1719494190539,"mc":[{"id":"1.230180112","rc":[{"atb":[[1.72,1.79]],"id":68870841}],"con":true,"img":false}]}
{"op":"mcm","clk":"11540411765","pt":1719494190905,"mc":[{"id":"1.230180112","rc":[{"atb":[[1.71,0]],"id":68870841}],"con":true,"img":false}]}
{"op":"mcm","clk":"11540411773","pt":1719494191011,"mc":[{"id":"1.230180112","rc":[{"atb":[[1.73,2]],"id":68870841}],"con":true,"img":false}]}
{"op":"mcm","clk":"11540411799","pt":1719494191436,"mc":[{"id":"1.230180112","rc":[{"atb":[[1.71,0]],"id":58974183}],"con":true,"img":false}]}
{"op":"mcm","clk":"11540411806","pt":1719494191532,"mc":[{"id":"1.230180112","rc":[{"atb":[[1.73,2]],"id":58974183}],"con":true,"img":false}]}
{"op":"mcm","clk":"11540411953","pt":1719494193621,"mc":[{"id":"1.230180112","rc":[{"atb":[[1.72,0]],"id":58974183}],"con":true,"img":false}]}
{"op":"mcm","clk":"11540411975","pt":1719494193926,"mc":[{"id":"1.230180112","rc":[{"atb":[[1.72,0]],"id":68870841}],"con":true,"img":false}]}
{"op":"mcm","clk":"11540412091","pt":1719494195551,"mc":[{"id":"1.230180112","rc":[{"atb":[[1.73,0]],"id":68870841}],"con":true,"img":false}]}
{"op":"mcm","clk":"11540412099","pt":1719494195649,"mc":[{"id":"1.230180112","rc":[{"atb":[[1.71,2]],"id":68870841}],"con":true,"img":false}]}
{"op":"mcm","clk":"11540412159","pt":1719494196527,"mc":[{"id":"1.230180112","rc":[{"atb":[[1.73,0]],"id":58974183}],"con":true,"img":false}]}
{"op":"mcm","clk":"11540412163","pt":1719494196630,"mc":[{"id":"1.230180112","rc":[{"atb":[[1.71,2]],"id":58974183}],"con":true,"img":false}]}
{"op":"mcm","clk":"11540412350","pt":1719494199435,"mc":[{"id":"1.230180112","rc":[{"atb":[[1.72,1.74]],"id":58974183}],"con":true,"img":false}]}
{"op":"mcm","clk":"11540412372","pt":1719494199751,"mc":[{"id":"1.230180112","rc":[{"atb":[[1.72,1.58]],"id":68870841}],"con":true,"img":false}]}
{"op":"mcm","clk":"11540412411","pt":1719494200321,"mc":[{"id":"1.230180112","rc":[{"atb":[[1.71,0]],"id":68870841}],"con":true,"img":false}]}
{"op":"mcm","clk":"11540412421","pt":1719494200425,"mc":[{"id":"1.230180112","rc":[{"atb":[[1.73,2]],"id":68870841}],"con":true,"img":false}]}
{"op":"mcm","clk":"11540412447","pt":1719494200838,"mc":[{"id":"1.230180112","rc":[{"atb":[[1.71,0]],"id":58974183}],"con":true,"img":false}]}
{"op":"mcm","clk":"11540412455","pt":1719494200942,"mc":[{"id":"1.230180112","rc":[{"atb":[[1.73,2]],"id":58974183}],"con":true,"img":false}]}
{"op":"mcm","clk":"11540412562","pt":1719494202659,"mc":[{"id":"1.230180112","rc":[{"atb":[[1.72,0]],"id":58974183}],"con":true,"img":false}]}
{"op":"mcm","clk":"11540412585","pt":1719494203022,"mc":[{"id":"1.230180112","rc":[{"atb":[[1.72,0]],"id":68870841}],"con":true,"img":false}]}
{"op":"mcm","clk":"11540412622","pt":1719494203652,"mc":[{"id":"1.230180112","rc":[{"atb":[[1.73,0]],"id":68870841}],"con":true,"img":false}]}
{"op":"mcm","clk":"11540412630","pt":1719494203769,"mc":[{"id":"1.230180112","rc":[{"atb":[[1.71,2]],"id":68870841}],"con":true,"img":false}]}
{"op":"mcm","clk":"11540412655","pt":1719494204170,"mc":[{"id":"1.230180112","rc":[{"atb":[[1.73,0]],"id":58974183}],"con":true,"img":false}]}
{"op":"mcm","clk":"11540412662","pt":1719494204231,"mc":[{"id":"1.230180112","rc":[{"atb":[[1.71,2]],"id":58974183}],"con":true,"img":false}]}
{"op":"mcm","clk":"11540412939","pt":1719494208456,"mc":[{"id":"1.230180112","rc":[{"atb":[[1.72,1.51]],"id":58974183}],"con":true,"img":false}]}
{"op":"mcm","clk":"11540412959","pt":1719494208754,"mc":[{"id":"1.230180112","rc":[{"atb":[[1.72,1.83]],"id":68870841}],"con":true,"img":false}]}
{"op":"mcm","clk":"11540412996","pt":1719494209374,"mc":[{"id":"1.230180112","rc":[{"atb":[[1.71,0]],"id":68870841}],"con":true,"img":false}]}
{"op":"mcm","clk":"11540413001","pt":1719494209466,"mc":[{"id":"1.230180112","rc":[{"atb":[[1.73,2]],"id":68870841}],"con":true,"img":false}]}
{"op":"mcm","clk":"11540413020","pt":1719494209793,"mc":[{"id":"1.230180112","rc":[{"atb":[[1.71,0]],"id":58974183}],"con":true,"img":false}]}
{"op":"mcm","clk":"11540413029","pt":1719494209890,"mc":[{"id":"1.230180112","rc":[{"atb":[[1.73,2]],"id":58974183}],"con":true,"img":false}]}
{"op":"mcm","clk":"11540413127","pt":1719494211296,"mc":[{"id":"1.230180112","rc":[{"atb":[[1.72,0]],"id":58974183}],"con":true,"img":false}]}
{"op":"mcm","clk":"11540413149","pt":1719494211547,"mc":[{"id":"1.230180112","rc":[{"atb":[[1.72,0]],"id":68870841}],"con":true,"img":false}]}
{"op":"mcm","clk":"11540413200","pt":1719494212279,"mc":[{"id":"1.230180112","rc":[{"atb":[[1.73,0]],"id":68870841}],"con":true,"img":false}]}
{"op":"mcm","clk":"11540413207","pt":1719494212378,"mc":[{"id":"1.230180112","rc":[{"atb":[[1.71,2]],"id":68870841}],"con":true,"img":false}]}
{"op":"mcm","clk":"11540413248","pt":1719494212896,"mc":[{"id":"1.230180112","rc":[{"atb":[[1.73,0]],"id":58974183}],"con":true,"img":false}]}
{"op":"mcm","clk":"11540413254","pt":1719494212953,"mc":[{"id":"1.230180112","rc":[{"atb":[[1.71,2]],"id":58974183}],"con":true,"img":false}]}
{"op":"mcm","clk":"11540413374","pt":1719494214984,"mc":[{"id":"1.230180112","rc":[{"atb":[[1.72,1.51]],"id":58974183}],"con":true,"img":false}]}
{"op":"mcm","clk":"11540413390","pt":1719494215298,"mc":[{"id":"1.230180112","rc":[{"atb":[[1.72,1.58]],"id":68870841}],"con":true,"img":false}]}
{"op":"mcm","clk":"11540413430","pt":1719494215874,"mc":[{"id":"1.230180112","rc":[{"atb":[[1.71,0]],"id":68870841}],"con":true,"img":false}]}
{"op":"mcm","clk":"11540413435","pt":1719494215974,"mc":[{"id":"1.230180112","rc":[{"atb":[[1.73,2]],"id":68870841}],"con":true,"img":false}]}
{"op":"mcm","clk":"11540413468","pt":1719494216394,"mc":[{"id":"1.230180112","rc":[{"atb":[[1.71,0]],"id":58974183}],"con":true,"img":false}]}
{"op":"mcm","clk":"11540413479","pt":1719494216498,"mc":[{"id":"1.230180112","rc":[{"atb":[[1.73,2]],"id":58974183}],"con":true,"img":false}]}
{"op":"mcm","clk":"11540413588","pt":1719494218199,"mc":[{"id":"1.230180112","rc":[{"atb":[[1.72,0]],"id":58974183}],"con":true,"img":false}]}
{"op":"mcm","clk":"11540413620","pt":1719494218679,"mc":[{"id":"1.230180112","rc":[{"atb":[[1.72,0]],"id":68870841}],"con":true,"img":false}]}
{"op":"mcm","clk":"11540413646","pt":1719494219191,"mc":[{"id":"1.230180112","rc":[{"atb":[[1.73,0]],"id":58974183}],"con":true,"img":false}]}
{"op":"mcm","clk":"11540413651","pt":1719494219297,"mc":[{"id":"1.230180112","rc":[{"atb":[[1.71,2]],"id":58974183}],"con":true,"img":false}]}
{"op":"mcm","clk":"11540413719","pt":1719494220497,"mc":[{"id":"1.230180112","rc":[{"atb":[[1.73,0]],"id":68870841}],"con":true,"img":false}]}
{"op":"mcm","clk":"11540413730","pt":1719494220595,"mc":[{"id":"1.230180112","rc":[{"atb":[[1.71,2]],"id":68870841}],"con":true,"img":false}]}
{"op":"mcm","clk":"11540413924","pt":1719494223392,"mc":[{"id":"1.230180112","rc":[{"atb":[[1.72,1.64]],"id":58974183}],"con":true,"img":false}]}
{"op":"mcm","clk":"11540413946","pt":1719494223666,"mc":[{"id":"1.230180112","rc":[{"atb":[[1.72,1.76]],"id":68870841}],"con":true,"img":false}]}
{"op":"mcm","clk":"11540413976","pt":1719494224175,"mc":[{"id":"1.230180112","rc":[{"atb":[[1.71,0]],"id":68870841}],"con":true,"img":false}]}
{"op":"mcm","clk":"11540413983","pt":1719494224277,"mc":[{"id":"1.230180112","rc":[{"atb":[[1.73,2]],"id":68870841}],"con":true,"img":false}]}
{"op":"mcm","clk":"11540414007","pt":1719494225029,"mc":[{"id":"1.230180112","rc":[{"atb":[[1.71,0]],"id":58974183}],"con":true,"img":false}]}
{"op":"mcm","clk":"11540414015","pt":1719494225056,"mc":[{"id":"1.230180112","rc":[{"atb":[[1.73,2]],"id":58974183}],"con":true,"img":false}]}
{"op":"mcm","clk":"11540414187","pt":1719494226582,"mc":[{"id":"1.230180112","rc":[{"atb":[[1.72,0]],"id":58974183}],"con":true,"img":false}]}
{"op":"mcm","clk":"11540414209","pt":1719494226884,"mc":[{"id":"1.230180112","rc":[{"atb":[[1.72,0]],"id":68870841}],"con":true,"img":false}]}
{"op":"mcm","clk":"11540414217","pt":1719494226991,"mc":[{"id":"1.230180112","rc":[{"atb":[[2,5]],"id":68870841}],"con":true,"img":false}]}
{"op":"mcm","clk":"11540414294","pt":1719494228084,"mc":[{"id":"1.230180112","rc":[{"atb":[[1.73,0]],"id":68870841}],"con":true,"img":false}]}
{"op":"mcm","clk":"11540414302","pt":1719494228189,"mc":[{"id":"1.230180112","rc":[{"atb":[[2.02,2]],"id":68870841}],"con":true,"img":false}]}
{"op":"mcm","clk":"11540414318","pt":1719494228501,"mc":[{"id":"1.230180112","rc":[{"atb":[[1.73,0]],"id":58974183}],"con":true,"img":false}]}
{"op":"mcm","clk":"11540414328","pt":1719494228601,"mc":[{"id":"1.230180112","rc":[{"atb":[[1.71,2]],"id":58974183}],"con":true,"img":false}]}
{"op":"mcm","clk":"11540414417","pt":1719494229805,"mc":[{"id":"1.230180112","rc":[{"atb":[[1.72,1.54]],"id":58974183}],"con":true,"img":false}]}
{"op":"mcm","clk":"11540414448","pt":1719494230201,"mc":[{"id":"1.230180112","rc":[{"atb":[[2.04,1.54]],"id":68870841}],"con":true,"img":false}]}
{"op":"mcm","clk":"11540414583","pt":1719494232079,"mc":[{"id":"1.230180112","rc":[{"atb":[[2.02,0]],"id":68870841}],"con":true,"img":false}]}
{"op":"mcm","clk":"11540414592","pt":1719494232189,"mc":[{"id":"1.230180112","rc":[{"atb":[[2.06,2]],"id":68870841}],"con":true,"img":false}]}
{"op":"mcm","clk":"11540414645","pt":1719494233005,"mc":[{"id":"1.230180112","rc":[{"atb":[[1.71,0]],"id":58974183}],"con":true,"img":false}]}
{"op":"mcm","clk":"11540414653","pt":1719494233111,"mc":[{"id":"1.230180112","rc":[{"atb":[[1.73,2]],"id":58974183}],"con":true,"img":false}]}
{"op":"mcm","clk":"11540414755","pt":1719494234507,"mc":[{"id":"1.230180112","rc":[{"atl":[[44,1]],"id":68870841}],"con":true,"img":false}]}
{"op":"mcm","clk":"11540414862","pt":1719494235806,"mc":[{"id":"1.230180112","rc":[{"atb":[[1.72,0]],"id":58974183}],"con":true,"img":false}]}
{"op":"mcm","clk":"11540414886","pt":1719494236109,"mc":[{"id":"1.230180112","rc":[{"atb":[[2.04,0]],"id":68870841}],"con":true,"img":false}]}
{"op":"mcm","clk":"11540414924","pt":1719494236576,"mc":[{"id":"1.230180112","rc":[{"atb":[[1.73,0]],"id":58974183}],"con":true,"img":false}]}
{"op":"mcm","clk":"11540414932","pt":1719494236730,"mc":[{"id":"1.230180112","rc":[{"atb":[[1.71,2]],"id":58974183}],"con":true,"img":false}]}
{"op":"mcm","clk":"11540415124","pt":1719494239385,"mc":[{"id":"1.230180112","rc":[{"atb":[[2.06,0]],"id":68870841}],"con":true,"img":false}]}
{"op":"mcm","clk":"11540415135","pt":1719494239487,"mc":[{"id":"1.230180112","rc":[{"atb":[[2.02,2]],"id":68870841}],"con":true,"img":false}]}
{"op":"mcm","clk":"11540415194","pt":1719494240206,"mc":[{"id":"1.230180112","rc":[{"atl":[[40,1]],"id":68169358}],"con":true,"img":false}]}
{"op":"mcm","clk":"11540415287","pt":1719494241496,"mc":[{"id":"1.230180112","rc":[{"atb":[[1.72,1.86]],"id":58974183}],"con":true,"img":false}]}
{"op":"mcm","clk":"11540415321","pt":1719494241820,"mc":[{"id":"1.230180112","rc":[{"atb":[[2.04,1.7]],"id":68870841}],"con":true,"img":false}]}
{"op":"mcm","clk":"11540415364","pt":1719494242327,"mc":[{"id":"1.230180112","rc":[{"atb":[[1.71,0]],"id":58974183}],"con":true,"img":false}]}
{"op":"mcm","clk":"11540415375","pt":1719494242388,"mc":[{"id":"1.230180112","rc":[{"atb":[[1.73,2]],"id":58974183}],"con":true,"img":false}]}
{"op":"mcm","clk":"11540415450","pt":1719494243414,"mc":[{"id":"1.230180112","rc":[{"atb":[[2.02,0]],"id":68870841}],"con":true,"img":false}]}
{"op":"mcm","clk":"11540415457","pt":1719494243518,"mc":[{"id":"1.230180112","rc":[{"atb":[[2.06,2]],"id":68870841}],"con":true,"img":false}]}
{"op":"mcm","clk":"11540415554","pt":1719494244918,"mc":[{"id":"1.230180112","rc":[{"atb":[[1.72,0]],"id":58974183},{"spn":75.86,"spf":"NaN","id":58974183},{"spn":23.03,"spf":"NaN","id":68870841},{"atl":[[140,0.84]],"id":68579508},{"spn":70.85,"spf":"NaN","id":68579508}],"con":true,"img":false}]}
{"op":"mcm","clk":"11540415585","pt":1719494245328,"mc":[{"id":"1.230180112","rc":[{"atb":[[2.04,0]],"id":68870841}],"con":true,"img":false}]}
{"op":"mcm","clk":"11540415607","pt":1719494245590,"mc":[{"id":"1.230180112","rc":[{"atb":[[1.73,0]],"id":58974183}],"con":true,"img":false}]}
{"op":"mcm","clk":"11540415617","pt":1719494245694,"mc":[{"id":"1.230180112","rc":[{"atb":[[1.71,2]],"id":58974183}],"con":true,"img":false}]}
{"op":"mcm","clk":"11540415668","pt":1719494246616,"mc":[{"id":"1.230180112","rc":[{"atb":[[2.06,0]],"id":68870841}],"con":true,"img":false}]}
{"op":"mcm","clk":"11540415678","pt":1719494246723,"mc":[{"id":"1.230180112","rc":[{"atb":[[2.02,2]],"id":68870841}],"con":true,"img":false}]}
{"op":"mcm","clk":"11540415703","pt":1719494247028,"mc":[{"id":"1.230180112","rc":[{"atb":[[2.04,4]],"id":68169358}],"con":true,"img":false}]}
{"op":"mcm","clk":"11540415736","pt":1719494247606,"mc":[{"id":"1.230180112","rc":[{"atb":[[1.71,0]],"id":68169358}],"con":true,"img":false}]}
{"op":"mcm","clk":"11540416058","pt":1719494252507,"mc":[{"id":"1.230180112","rc":[{"atb":[[2.08,5]],"id":50281437}],"con":true,"img":false}]}
{"op":"mcm","clk":"11540416086","pt":1719494253021,"mc":[{"id":"1.230180112","rc":[{"atb":[[4.3,7.5]],"id":68870841}],"con":true,"img":false}]}
{"op":"mcm","clk":"11540416150","pt":1719494254214,"mc":[{"id":"1.230180112","rc":[{"atl":[[11.5,7.5]],"id":68870841}],"con":true,"img":false}]}
{"op":"mcm","clk":"11540416166","pt":1719494254425,"mc":[{"id":"1.230180112","rc":[{"atb":[[4.3,0],[2.02,0]],"id":68870841},{"atl":[[11.5,0]],"id":68870841}],"con":true,"img":false}]}
{"op":"mcm","clk":"11540416171","pt":1719494254522,"mc":[{"id":"1.230180112","rc":[{"atb":[[1.02,91.77]],"id":68870841}],"con":true,"img":false}]}
{"op":"mcm","clk":"11540416240","pt":1719494255825,"mc":[{"id":"1.230180112","rc":[{"atb":[[2.06,1.91]],"id":68169358},{"atb":[[1.02,89.77]],"id":68870841}],"con":true,"img":false}]}
{"op":"mcm","clk":"11540416247","pt":1719494255926,"mc":[{"id":"1.230180112","rc":[{"atb":[[2.02,2]],"id":68870841}],"con":true,"img":false}]}
{"op":"mcm","clk":"11540416267","pt":1719494256232,"mc":[{"id":"1.230180112","rc":[{"atb":[[1.75,0]],"id":50281437}],"con":true,"img":false}]}
{"op":"mcm","clk":"11540416286","pt":1719494256542,"mc":[{"id":"1.230180112","rc":[{"atb":[[1.72,1.64]],"id":58974183}],"con":true,"img":false}]}
{"op":"mcm","clk":"11540416309","pt":1719494256811,"mc":[{"id":"1.230180112","rc":[{"atb":[[2.02,3.98]],"id":68870841}],"con":true,"img":false}]}
{"op":"mcm","clk":"11540416338","pt":1719494257120,"mc":[{"id":"1.230180112","rc":[{"atb":[[1.71,0]],"id":58974183}],"con":true,"img":false}]}
{"op":"mcm","clk":"11540416349","pt":1719494257218,"mc":[{"id":"1.230180112","rc":[{"atb":[[1.73,2]],"id":58974183}],"con":true,"img":false}]}
{"op":"mcm","clk":"11540416421","pt":1719494258244,"mc":[{"id":"1.230180112","rc":[{"atb":[[1.72,0]],"id":58974183}],"con":true,"img":false}]}
{"op":"mcm","clk":"11540416468","pt":1719494258919,"mc":[{"id":"1.230180112","rc":[{"atb":[[1.73,0]],"id":58974183}],"con":true,"img":false}]}
{"op":"mcm","clk":"11540416478","pt":1719494259036,"mc":[{"id":"1.230180112","rc":[{"atb":[[1.71,2]],"id":58974183}],"con":true,"img":false}]}
{"op":"mcm","clk":"11540416521","pt":1719494259642,"mc":[{"id":"1.230180112","rc":[{"atb":[[2.1,1.8]],"id":50281437}],"con":true,"img":false}]}
{"op":"mcm","clk":"11540416581","pt":1719494260430,"mc":[{"id":"1.230180112","rc":[{"atl":[[32,2]],"id":50281437}],"con":true,"img":false}]}
{"op":"mcm","clk":"11540416759","pt":1719494262946,"mc":[{"id":"1.230180112","rc":[{"atb":[[1.72,1.66]],"id":58974183}],"con":true,"img":false}]}
{"op":"mcm","clk":"11540416811","pt":1719494263728,"mc":[{"id":"1.230180112","rc":[{"atb":[[1.71,0]],"id":58974183}],"con":true,"img":false}]}
{"op":"mcm","clk":"11540416819","pt":1719494263823,"mc":[{"id":"1.230180112","rc":[{"atb":[[1.73,2]],"id":58974183}],"con":true,"img":false}]}
{"op":"mcm","clk":"11540416976","pt":1719494266344,"mc":[{"id":"1.230180112","rc":[{"atb":[[1.72,0],[2.06,5]],"id":58974183}],"con":true,"img":false}]}
{"op":"mcm","clk":"11540417025","pt":1719494267012,"mc":[{"id":"1.230180112","rc":[{"atb":[[1.73,0]],"id":58974183}],"con":true,"img":false}]}
{"op":"mcm","clk":"11540417037","pt":1719494267114,"mc":[{"id":"1.230180112","rc":[{"atb":[[2.08,2]],"id":58974183}],"con":true,"img":false}]}
{"op":"mcm","clk":"11540417105","pt":1719494268250,"mc":[{"id":"1.230180112","rc":[{"atb":[[2.08,0]],"id":58974183}],"con":true,"img":false}]}
{"op":"mcm","clk":"11540417111","pt":1719494268353,"mc":[{"id":"1.230180112","rc":[{"atb":[[1.02,10.47]],"id":58974183}],"con":true,"img":false}]}
{"op":"mcm","clk":"11540417381","pt":1719494272234,"mc":[{"id":"1.230180112","rc":[{"atb":[[2.08,1.73]],"id":58974183}],"con":true,"img":false}]}
{"op":"mcm","clk":"11540417403","pt":1719494272445,"mc":[{"id":"1.230180112","rc":[{"atl":[[18,2]],"id":58974183}],"con":true,"img":false}]}
{"op":"mcm","clk":"11540417954","pt":1719494279740,"mc":[{"id":"1.230180112","rc":[{"atb":[[1.05,1.69]],"id":58974183},{"atb":[[1.05,1.69]],"id":68870841}],"con":true,"img":false}]}
{"op":"mcm","clk":"11540417972","pt":1719494279952,"mc":[{"id":"1.230180112","rc":[{"atb":[[1.05,1.69]],"id":50281437}],"con":true,"img":false}]}
{"op":"mcm","clk":"11540417979","pt":1719494280055,"mc":[{"id":"1.230180112","rc":[{"atb":[[1.05,1.69]],"id":68169358}],"con":true,"img":false}]}
{"op":"mcm","clk":"11540417995","pt":1719494280256,"mc":[{"id":"1.230180112","rc":[{"atb":[[2.6,5]],"id":58974183},{"atl":[[25,4]],"id":58974183},{"atb":[[2.06,5.91]],"id":68169358},{"atl":[[32,3.23]],"id":68169358},{"atb":[[2.46,5]],"id":68870841},{"atl":[[140,3.9]],"id":68870841},{"atb":[[2.24,14.48],[1.04,1.69]],"id":68579508},{"atl":[[75,2]],"id":68579508},{"atb":[[2.1,6.8]],"id":50281437},{"atl":[[32,5.23]],"id":50281437}],"con":true,"img":false}]}
{"op":"mcm","clk":"11540417999","pt":1719494280360,"mc":[{"id":"1.230180112","rc":[{"atb":[[1.05,0.14]],"id":58974183},{"atl":[[32,2],[50,2.04]],"id":50281437}],"con":true,"img":false}]}
{"op":"mcm","clk":"11540418008","pt":1719494280465,"mc":[{"id":"1.230180112","rc":[{"atl":[[32,5.23],[50,0]],"id":50281437}],"con":true,"img":false}]}
{"op":"mcm","clk":"11540418015","pt":1719494280564,"mc":[{"id":"1.230180112","rc":[{"atb":[[1.05,0.14]],"id":50281437}],"con":true,"img":false}]}
{"op":"mcm","clk":"11540418021","pt":1719494280620,"mc":[{"id":"1.230180112","rc":[{"atb":[[1.05,0.14]],"id":68169358},{"atb":[[2.1,4]],"id":68579508}],"con":true,"img":false}]}
{"op":"mcm","clk":"11540418027","pt":1719494280727,"mc":[{"id":"1.230180112","rc":[{"atb":[[2.02,1.98]],"id":68870841}],"con":true,"img":false}]}
{"op":"mcm","clk":"11540418034","pt":1719494280832,"mc":[{"id":"1.230180112","rc":[{"atb":[[1.02,91.77],[1.05,0.15]],"id":68870841}],"con":true,"img":false}]}
{"op":"mcm","clk":"11540418051","pt":1719494281147,"mc":[{"id":"1.230180112","rc":[{"atb":[[1.05,0]],"id":58974183},{"atl":[[30,2]],"id":68169358},{"atb":[[1.71,0],[1.04,0.17]],"id":68579508}],"con":true,"img":false}]}
{"op":"mcm","clk":"11540418060","pt":1719494281244,"mc":[{"id":"1.230180112","rc":[{"atb":[[2.1,0.14]],"id":58974183}],"con":true,"img":false}]}
{"op":"mcm","clk":"11540418075","pt":1719494281453,"mc":[{"id":"1.230180112","rc":[{"atb":[[1.02,12.18],[2.08,0]],"id":58974183},{"atl":[[1000,2.55]],"id":58974183},{"atb":[[1.02,93.48]],"id":68870841},{"atl":[[1000,1.7]],"id":68870841},{"atl":[[1000,2.55]],"id":50281437}],"con":true,"img":false}]}
{"op":"mcm","clk":"11540418084","pt":1719494281553,"mc":[{"id":"1.230180112","rc":[{"atb":[[1.01,18.65]],"id":50281437}],"con":true,"img":false}]}
{"op":"mcm","clk":"11540418091","pt":1719494281659,"mc":[{"id":"1.230180112","rc":[{"atb":[[1.02,10.67]],"id":58974183},{"atl":[[1000,0.86]],"id":58974183},{"atb":[[1.02,91.99]],"id":68870841},{"atl":[[1000,0]],"id":68870841},{"atb":[[1.05,0]],"id":50281437},{"atl":[[1000,0.85]],"id":50281437}],"con":true,"img":false}]}
{"op":"mcm","clk":"11540418102","pt":1719494281762,"mc":[{"id":"1.230180112","rc":[{"atb":[[2.02,0]],"id":68870841},{"atb":[[1.01,17.23],[2.12,0.14]],"id":50281437}],"con":true,"img":false}]}
{"op":"mcm","clk":"11540418116","pt":1719494281920,"mc":[{"id":"1.230180112","rc":[{"atb":[[1.02,10.47]],"id":58974183},{"atl":[[1000,0.84]],"id":58974183},{"atb":[[1.02,91.77]],"id":68870841},{"atb":[[1.01,16.95]],"id":50281437},{"atl":[[1000,0.84]],"id":50281437}],"con":true,"img":false}]}
{"op":"mcm","clk":"11540418126","pt":1719494282027,"mc":[{"id":"1.230180112","rc":[{"atb":[[2.62,0.19]],"id":58974183},{"atl":[[17.5,0.01]],"id":58974183},{"atb":[[2.48,0.21]],"id":68870841},{"atb":[[2.12,0.42]],"id":50281437},{"atl":[[30,0.01]],"id":50281437}],"con":true,"img":false}]}
{"op":"mcm","clk":"11540418137","pt":1719494282127,"mc":[{"id":"1.230180112","rc":[{"atb":[[1.05,0]],"id":68169358}],"con":true,"img":false}]}
{"op":"mcm","clk":"11540418151","pt":1719494282238,"mc":[{"id":"1.230180112","rc":[{"atb":[[2.08,0.14]],"id":68169358}],"con":true,"img":false}]}
{"op":"mcm","clk":"11540418164","pt":1719494282335,"mc":[{"id":"1.230180112","rc":[{"atb":[[2.1,1]],"id":68169358},{"atl":[[5.7,1]],"id":68169358}],"con":true,"img":false}]}
{"op":"mcm","clk":"11540418223","pt":1719494283061,"mc":[{"id":"1.230180112","rc":[{"atb":[[1.05,0]],"id":68870841}],"con":true,"img":false}]}
{"op":"mcm","clk":"11540418231","pt":1719494283164,"mc":[{"id":"1.230180112","rc":[{"atb":[[2.04,0.15]],"id":68870841}],"con":true,"img":false}]}
{"op":"mcm","clk":"11540418263","pt":1719494283536,"mc":[{"id":"1.230180112","rc":[{"atb":[[1.04,0]],"id":68579508}],"con":true,"img":false}]}
{"op":"mcm","clk":"11540418275","pt":1719494283644,"mc":[{"id":"1.230180112","rc":[{"atb":[[1.72,0.17]],"id":68579508}],"con":true,"img":false}]}
{"op":"mcm","clk":"11540418366","pt":1719494284841,"mc":[{"id":"1.230180112","rc":[{"atb":[[2.06,4]],"id":68169358}],"con":true,"img":false}]}
{"op":"mcm","clk":"11540418401","pt":1719494285265,"mc":[{"id":"1.230180112","rc":[{"atb":[[2.26,1.58]],"id":68579508}],"con":true,"img":false}]}
{"op":"mcm","clk":"11540418428","pt":1719494285525,"mc":[{"id":"1.230180112","rc":[{"atb":[[2.6,0],[2.62,2.04],[2.7,2]],"id":58974183},{"atb":[[2.46,0],[2.62,2]],"id":68870841},{"atb":[[2.24,0],[2.36,4]],"id":68579508},{"atb":[[2.24,5],[2.1,1.8]],"id":50281437}],"con":true,"img":false}]}
{"op":"mcm","clk":"11540418508","pt":1719494286462,"mc":[{"id":"1.230180112","rc":[{"atl":[[30,0]],"id":68169358}],"con":true,"img":false}]}
{"op":"mcm","clk":"11540418515","pt":1719494286468,"mc":[{"id":"1.230180112","rc":[{"atb":[[2.48,1.72]],"id":68870841}],"con":true,"img":false}]}
{"op":"mcm","clk":"11540418526","pt":1719494286565,"mc":[{"id":"1.230180112","rc":[{"atb":[[4.6,1],[4.9,1]],"id":58974183},{"atl":[[15.5,1]],"id":58974183},{"atl":[[15.5,1]],"id":68870841},{"atb":[[2.8,1]],"id":68579508},{"atl":[[8,1]],"id":68579508},{"atb":[[2.98,1]],"id":50281437},{"atl":[[8,1]],"id":50281437}],"con":true,"img":false}]}
{"op":"mcm","clk":"11540418550","pt":1719494286886,"mc":[{"id":"1.230180112","rc":[{"atl":[[32,2]],"id":68579508}],"con":true,"img":false}]}
{"op":"mcm","clk":"11540418568","pt":1719494287041,"mc":[{"id":"1.230180112","rc":[{"atl":[[32,4],[75,0]],"id":68579508}],"con":true,"img":false}]}
{"op":"mcm","clk":"11540418622","pt":1719494287668,"mc":[{"id":"1.230180112","rc":[{"atb":[[2.26,0]],"id":68579508}],"con":true,"img":false}]}
{"op":"mcm","clk":"11540418654","pt":1719494288046,"mc":[{"id":"1.230180112","rc":[{"atb":[[2.1,0]],"id":50281437}],"con":true,"img":false}]}
{"op":"mcm","clk":"11540418673","pt":1719494288354,"mc":[{"id":"1.230180112","rc":[{"atb":[[2.48,0.21]],"id":68870841}],"con":true,"img":false}]}
{"op":"mcm","clk":"11540419025","pt":1719494292554,"mc":[{"id":"1.230180112","rc":[{"atl":[[5.6,2]],"id":68169358}],"con":true,"img":false}]}
{"op":"mcm","clk":"11540419034","pt":1719494292661,"mc":[{"id":"1.230180112","rc":[{"atl":[[32,0],[8.2,3.23]],"id":68169358}],"con":true,"img":false}]}
{"op":"mcm","clk":"11540419094","pt":1719494293380,"mc":[{"id":"1.230180112","rc":[{"atb":[[2.64,1.77]],"id":68870841}],"con":true,"img":false}]}
{"op":"mcm","clk":"11540419335","pt":1719494296658,"mc":[{"id":"1.230180112","rc":[{"atb":[[4.9,0]],"id":58974183}],"con":true,"img":false}]}
{"op":"mcm","clk":"11540419370","pt":1719494297017,"mc":[{"id":"1.230180112","rc":[{"atb":[[2.1,0.93]],"id":58974183},{"atb":[[2.1,1.9]],"id":68169358},{"atb":[[2.12,1.21]],"id":50281437}],"con":true,"img":false}]}
{"op":"mcm","clk":"11540419440","pt":1719494297804,"mc":[{"id":"1.230180112","rc":[{"atl":[[5.6,0]],"id":68169358}],"con":true,"img":false}]}
{"op":"mcm","clk":"11540419446","pt":1719494297907,"mc":[{"id":"1.230180112","rc":[{"atl":[[32,3.23],[8.2,0]],"id":68169358}],"con":true,"img":false}]}
{"op":"mcm","clk":"11540419563","pt":1719494299307,"mc":[{"id":"1.230180112","rc":[{"atb":[[2.62,0.19]],"id":58974183}],"con":true,"img":false}]}
{"op":"mcm","clk":"11540419697","pt":1719494300866,"mc":[{"id":"1.230180112","rc":[{"atl":[[5.6,2]],"id":68169358}],"con":true,"img":false}]}
{"op":"mcm","clk":"11540420127","pt":1719494306215,"mc":[{"id":"1.230180112","rc":[{"spn":10.05,"spf":"NaN","id":58974183},{"atl":[[5.6,0]],"id":68169358},{"spn":2.1,"spf":1.0,"id":68169358},{"spn":9.07,"spf":"NaN","id":68870841},{"spn":5.4,"spf":"NaN","id":68579508},{"spn":5.49,"spf":"NaN","id":50281437}],"con":true,"img":false}]}
{"op":"mcm","clk":"11540420316","pt":1719494308185,"mc":[{"id":"1.230180112","rc":[{"atl":[[5.6,2]],"id":68169358}],"con":true,"img":false}]}
{"op":"mcm","clk":"11540420325","pt":1719494308291,"mc":[{"id":"1.230180112","rc":[{"atl":[[32,0],[8.2,3.23]],"id":68169358}],"con":true,"img":false}]}
{"op":"mcm","clk":"11540420806","pt":1719494313497,"mc":[{"id":"1.230180112","rc":[{"atl":[[5.6,0]],"id":68169358}],"con":true,"img":false}]}
{"op":"mcm","clk":"11540420813","pt":1719494313602,"mc":[{"id":"1.230180112","rc":[{"atl":[[32,3.23],[8.2,0]],"id":68169358}],"con":true,"img":false}]}
{"op":"mcm","clk":"11540421063","pt":1719494316622,"mc":[{"id":"1.230180112","rc":[{"atl":[[5.6,2]],"id":68169358}],"con":true,"img":false}]}
{"op":"mcm","clk":"11540421182","pt":1719494318200,"mc":[{"id":"1.230180112","rc":[{"atl":[[8.2,3.23]],"id":68169358}],"con":true,"img":false}]}
{"op":"mcm","clk":"11540421191","pt":1719494318296,"mc":[{"id":"1.230180112","rc":[{"atl":[[32,0]],"id":68169358}],"con":true,"img":false}]}
{"op":"mcm","clk":"11540421266","pt":1719494319423,"mc":[{"id":"1.230180112","rc":[{"atb":[[2.1,0.14]],"id":58974183}],"con":true,"img":false}]}
{"op":"mcm","clk":"11540421459","pt":1719494321912,"mc":[{"id":"1.230180112","rc":[{"atl":[[5.6,0]],"id":68169358}],"con":true,"img":false}]}
{"op":"mcm","clk":"11540421471","pt":1719494322118,"mc":[{"id":"1.230180112","rc":[{"atl":[[32,3.23],[8.2,0]],"id":68169358}],"con":true,"img":false}]}
{"op":"mcm","clk":"11540421610","pt":1719494323932,"mc":[{"id":"1.230180112","rc":[{"atl":[[5.6,2]],"id":68169358}],"con":true,"img":false}]}
{"op":"mcm","clk":"11540421663","pt":1719494324509,"mc":[{"id":"1.230180112","rc":[{"atb":[[2.62,0]],"id":58974183},{"atl":[[17.5,0]],"id":58974183},{"atb":[[2.48,0]],"id":68870841},{"atb":[[2.12,0.93]],"id":50281437},{"atl":[[30,0]],"id":50281437}],"con":true,"img":false}]}
{"op":"mcm","clk":"11540422050","pt":1719494329233,"mc":[{"id":"1.230180112","rc":[{"atl":[[5.6,0]],"id":68169358}],"con":true,"img":false}]}
{"op":"mcm","clk":"11540422178","pt":1719494330943,"mc":[{"id":"1.230180112","rc":[{"atb":[[4.6,2.02]],"id":58974183}],"con":true,"img":false}]}
{"op":"mcm","clk":"11540422199","pt":1719494331145,"mc":[{"id":"1.230180112","rc":[{"atb":[[4.5,4.04],[2.7,0]],"id":58974183}],"con":true,"img":false}]}
{"op":"mcm","clk":"11540422316","pt":1719494332341,"mc":[{"id":"1.230180112","rc":[{"atl":[[5.6,2]],"id":68169358}],"con":true,"img":false}]}
{"op":"mcm","clk":"11540422325","pt":1719494332448,"mc":[{"id":"1.230180112","rc":[{"atl":[[32,0],[8.2,3.23]],"id":68169358}],"con":true,"img":false}]}
{"op":"mcm","clk":"11540422809","pt":1719494337536,"mc":[{"id":"1.230180112","rc":[{"atl":[[5.6,0]],"id":68169358}],"con":true,"img":false}]}
{"op":"mcm","clk":"11540422820","pt":1719494337643,"mc":[{"id":"1.230180112","rc":[{"atl":[[32,3.23],[8.2,0]],"id":68169358}],"con":true,"img":false}]}
{"op":"mcm","clk":"11540422982","pt":1719494339549,"mc":[{"id":"1.230180112","rc":[{"atl":[[5.6,2]],"id":68169358}],"con":true,"img":false}]}
{"op":"mcm","clk":"11540423462","pt":1719494344751,"mc":[{"id":"1.230180112","rc":[{"atl":[[5.6,0]],"id":68169358}],"con":true,"img":false}]}
{"op":"mcm","clk":"11540423787","pt":1719494347983,"mc":[{"id":"1.230180112","rc":[{"atl":[[5.6,2]],"id":68169358}],"con":true,"img":false}]}
{"op":"mcm","clk":"11540423801","pt":1719494348028,"mc":[{"id":"1.230180112","rc":[{"atl":[[32,0],[8.2,3.23]],"id":68169358}],"con":true,"img":false}]}
{"op":"mcm","clk":"11540424154","pt":1719494352173,"mc":[{"id":"1.230180112","rc":[{"atb":[[2.06,0]],"id":58974183},{"atl":[[18,0]],"id":58974183},{"atb":[[2.04,0]],"id":68169358},{"atl":[[40,0]],"id":68169358},{"atb":[[2,0]],"id":68870841},{"atl":[[44,0]],"id":68870841},{"atb":[[2.1,0]],"id":68579508},{"atl":[[32,2]],"id":68579508},{"atb":[[2.08,0]],"id":50281437},{"atl":[[32,3.23]],"id":50281437}],"con":true,"img":false}]}
{"op":"mcm","clk":"11540424167","pt":1719494352276,"mc":[{"id":"1.230180112","rc":[{"atl":[[140,2],[25,0]],"id":58974183},{"atl":[[32,0],[75,2]],"id":68579508},{"atl":[[32,0],[50,2.04]],"id":50281437}],"con":true,"img":false}]}
{"op":"mcm","clk":"11540424240","pt":1719494353159,"mc":[{"id":"1.230180112","rc":[{"atl":[[5.6,0]],"id":68169358}],"con":true,"img":false}]}
