{"op":"mcm","clk":"11547086389","pt":1719432856312,"mc":[{"id":"1.230178176","marketDefinition":{"bspMarket":false,"turnInPlayEnabled":false,"persistenceEnabled":false,"marketBaseRate":5.0,"eventId":"33376048","eventTypeId":"4339","numberOfWinners":1,"bettingType":"ODDS","marketType":"FORECAST","marketTime":"2024-06-27T16:37:00.000Z","suspendTime":"2024-06-27T16:37:00.000Z","bspReconciled":false,"complete":true,"inPlay":false,"crossMatching":false,"runnersVoidable":false,"numberOfActiveRunners":30,"betDelay":0,"status":"OPEN","runners":[{"status":"ACTIVE","sortPriority":1,"id":52385882,"name":"1 - 2"},{"status":"ACTIVE","sortPriority":2,"id":52385883,"name":"1 - 3"},{"status":"ACTIVE","sortPriority":3,"id":52385884,"name":"1 - 4"},{"status":"ACTIVE","sortPriority":4,"id":52385885,"name":"1 - 5"},{"status":"ACTIVE","sortPriority":5,"id":52385886,"name":"1 - 6"},{"status":"ACTIVE","sortPriority":6,"id":52385889,"name":"2 - 1"},{"status":"ACTIVE","sortPriority":7,"id":52385890,"name":"2 - 3"},{"status":"ACTIVE","sortPriority":8,"id":52385891,"name":"2 - 4"},{"status":"ACTIVE","sortPriority":9,"id":52385892,"name":"2 - 5"},{"status":"ACTIVE","sortPriority":10,"id":52385893,"name":"2 - 6"},{"status":"ACTIVE","sortPriority":11,"id":52385896,"name":"3 - 1"},{"status":"ACTIVE","sortPriority":12,"id":52385897,"name":"3 - 2"},{"status":"ACTIVE","sortPriority":13,"id":52385898,"name":"3 - 4"},{"status":"ACTIVE","sortPriority":14,"id":52385899,"name":"3 - 5"},{"status":"ACTIVE","sortPriority":15,"id":52385900,"name":"3 - 6"},{"status":"ACTIVE","sortPriority":16,"id":52385903,"name":"4 - 1"},{"status":"ACTIVE","sortPriority":17,"id":52385904,"name":"4 - 2"},{"status":"ACTIVE","sortPriority":18,"id":52385905,"name":"4 - 3"},{"status":"ACTIVE","sortPriority":19,"id":52385906,"name":"4 - 5"},{"status":"ACTIVE","sortPriority":20,"id":52385907,"name":"4 - 6"},{"status":"ACTIVE","sortPriority":21,"id":52385910,"name":"5 - 1"},{"status":"ACTIVE","sortPriority":22,"id":52385911,"name":"5 - 2"},{"status":"ACTIVE","sortPriority":23,"id":52385912,"name":"5 - 3"},{"status":"ACTIVE","sortPriority":24,"id":52385913,"name":"5 - 4"},{"status":"ACTIVE","sortPriority":25,"id":52385914,"name":"5 - 6"},{"status":"ACTIVE","sortPriority":26,"id":52385917,"name":"6 - 1"},{"status":"ACTIVE","sortPriority":27,"id":52385918,"name":"6 - 2"},{"status":"ACTIVE","sortPriority":28,"id":52385919,"name":"6 - 3"},{"status":"ACTIVE","sortPriority":29,"id":52385920,"name":"6 - 4"},{"status":"ACTIVE","sortPriority":30,"id":52385921,"name":"6 - 5"}],"regulators":["MR_INT"],"venue":"Perry Barr","countryCode":"GB","discountAllowed":false,"timezone":"Europe/London","openDate":"2024-06-27T13:29:00.000Z","version":5994794126,"name":"Forecast","eventName":"Perry Barr (F/C) 27th Jun"},"rc":[],"con":true,"img":false}]}
{"op":"mcm","clk":"11547086549","pt":1719432858318,"mc":[{"id":"1.230178176","marketDefinition":{"bspMarket":false,"turnInPlayEnabled":false,"persistenceEnabled":false,"marketBaseRate":5.0,"eventId":"33376048","eventTypeId":"4339","numberOfWinners":1,"bettingType":"ODDS","marketType":"FORECAST","marketTime":"2024-06-27T16:37:00.000Z","suspendTime":"2024-06-27T16:37:00.000Z","bspReconciled":false,"complete":true,"inPlay":false,"crossMatching":false,"runnersVoidable":false,"numberOfActiveRunners":30,"betDelay":0,"status":"OPEN","runners":[{"status":"ACTIVE","sortPriority":1,"id":52385882,"name":"1 - 2"},{"status":"ACTIVE","sortPriority":2,"id":52385883,"name":"1 - 3"},{"status":"ACTIVE","sortPriority":3,"id":52385884,"name":"1 - 4"},{"status":"ACTIVE","sortPriority":4,"id":52385885,"name":"1 - 5"},{"status":"ACTIVE","sortPriority":5,"id":52385886,"name":"1 - 6"},{"status":"ACTIVE","sortPriority":6,"id":52385889,"name":"2 - 1"},{"status":"ACTIVE","sortPriority":7,"id":52385890,"name":"2 - 3"},{"status":"ACTIVE","sortPriority":8,"id":52385891,"name":"2 - 4"},{"status":"ACTIVE","sortPriority":9,"id":52385892,"name":"2 - 5"},{"status":"ACTIVE","sortPriority":10,"id":52385893,"name":"2 - 6"},{"status":"ACTIVE","sortPriority":11,"id":52385896,"name":"3 - 1"},{"status":"ACTIVE","sortPriority":12,"id":52385897,"name":"3 - 2"},{"status":"ACTIVE","sortPriority":13,"id":52385898,"name":"3 - 4"},{"status":"ACTIVE","sortPriority":14,"id":52385899,"name":"3 - 5"},{"status":"ACTIVE","sortPriority":15,"id":52385900,"name":"3 - 6"},{"status":"ACTIVE","sortPriority":16,"id":52385903,"name":"4 - 1"},{"status":"ACTIVE","sortPriority":17,"id":52385904,"name":"4 - 2"},{"status":"ACTIVE","sortPriority":18,"id":52385905,"name":"4 - 3"},{"status":"ACTIVE","sortPriority":19,"id":52385906,"name":"4 - 5"},{"status":"ACTIVE","sortPriority":20,"id":52385907,"name":"4 - 6"},{"status":"ACTIVE","sortPriority":21,"id":52385910,"name":"5 - 1"},{"status":"ACTIVE","sortPriority":22,"id":52385911,"name":"5 - 2"},{"status":"ACTIVE","sortPriority":23,"id":52385912,"name":"5 - 3"},{"status":"ACTIVE","sortPriority":24,"id":52385913,"name":"5 - 4"},{"status":"ACTIVE","sortPriority":25,"id":52385914,"name":"5 - 6"},{"status":"ACTIVE","sortPriority":26,"id":52385917,"name":"6 - 1"},{"status":"ACTIVE","sortPriority":27,"id":52385918,"name":"6 - 2"},{"status":"ACTIVE","sortPriority":28,"id":52385919,"name":"6 - 3"},{"status":"ACTIVE","sortPriority":29,"id":52385920,"name":"6 - 4"},{"status":"ACTIVE","sortPriority":30,"id":52385921,"name":"6 - 5"}],"regulators":["MR_INT"],"venue":"Perry Barr","countryCode":"GB","discountAllowed":true,"timezone":"Europe/London","openDate":"2024-06-27T13:29:00.000Z","version":5994794126,"name":"Forecast","eventName":"Perry Barr (F/C) 27th Jun"},"rc":[],"con":true,"img":false}]}
{"op":"mcm","clk":"11547344266","pt":1719439056623,"mc":[{"id":"1.230178176","rc":[{"atb":[[1.03,7.81]],"id":52385910},{"atb":[[1.03,7.81]],"id":52385912},{"atb":[[1.03,7.81]],"id":52385906},{"atb":[[1.01,23.42]],"id":52385918},{"atb":[[1.02,11.71]],"id":52385920},{"atb":[[1.03,7.81]],"id":52385889},{"atb":[[1.02,11.71]],"id":52385914},{"atb":[[1.01,23.42]],"id":52385883},{"atb":[[1.03,7.81]],"id":52385885},{"atb":[[1.03,7.81]],"id":52385896},{"atb":[[1.02,11.71]],"id":52385890},{"atb":[[1.02,11.71]],"id":52385892},{"atb":[[1.02,11.71]],"id":52385904},{"atb":[[1.01,23.42]],"id":52385898},{"atb":[[1.01,23.42]],"id":52385900},{"atb":[[1.02,11.71]],"id":52385911},{"atb":[[1.03,7.81]],"id":52385913},{"atb":[[1.03,7.81]],"id":52385907},{"atb":[[1.03,7.81]],"id":52385886},{"atb":[[1.02,11.71]],"id":52385919},{"atb":[[1.03,7.81]],"id":52385921},{"atb":[[1.02,11.71]],"id":52385882},{"atb":[[1.02,11.71]],"id":52385884},{"atb":[[1.03,7.81]],"id":52385917},{"atb":[[1.02,11.71]],"id":52385897},{"atb":[[1.03,7.81]],"id":52385891},{"atb":[[1.03,7.81]],"id":52385893},{"atb":[[1.01,23.42]],"id":52385903},{"atb":[[1.01,23.42]],"id":52385905},{"atb":[[1.03,7.81]],"id":52385899}],"con":true,"img":false}]}
{"op":"mcm","clk":"11547371011","pt":1719439682592,"mc":[{"id":"1.230178176","marketDefinition":{"bspMarket":false,"turnInPlayEnabled":false,"persistenceEnabled":false,"marketBaseRate":5.0,"eventId":"33376048","eventTypeId":"4339","numberOfWinners":1,"bettingType":"ODDS","marketType":"FORECAST","marketTime":"2024-06-27T16:37:00.000Z","suspendTime":"2024-06-27T16:37:00.000Z","bspReconciled":false,"complete":true,"inPlay":false,"crossMatching":false,"runnersVoidable":false,"numberOfActiveRunners":30,"betDelay":0,"status":"OPEN","runners":[{"status":"ACTIVE","sortPriority":1,"id":52385882,"name":"1 - 2"},{"status":"ACTIVE","sortPriority":2,"id":52385883,"name":"1 - 3"},{"status":"ACTIVE","sortPriority":3,"id":52385884,"name":"1 - 4"},{"status":"ACTIVE","sortPriority":4,"id":52385885,"name":"1 - 5"},{"status":"ACTIVE","sortPriority":5,"id":52385886,"name":"1 - 6"},{"status":"ACTIVE","sortPriority":6,"id":52385889,"name":"2 - 1"},{"status":"ACTIVE","sortPriority":7,"id":52385890,"name":"2 - 3"},{"status":"ACTIVE","sortPriority":8,"id":52385891,"name":"2 - 4"},{"status":"ACTIVE","sortPriority":9,"id":52385892,"name":"2 - 5"},{"status":"ACTIVE","sortPriority":10,"id":52385893,"name":"2 - 6"},{"status":"ACTIVE","sortPriority":11,"id":52385896,"name":"3 - 1"},{"status":"ACTIVE","sortPriority":12,"id":52385897,"name":"3 - 2"},{"status":"ACTIVE","sortPriority":13,"id":52385898,"name":"3 - 4"},{"status":"ACTIVE","sortPriority":14,"id":52385899,"name":"3 - 5"},{"status":"ACTIVE","sortPriority":15,"id":52385900,"name":"3 - 6"},{"status":"ACTIVE","sortPriority":16,"id":52385903,"name":"4 - 1"},{"status":"ACTIVE","sortPriority":17,"id":52385904,"name":"4 - 2"},{"status":"ACTIVE","sortPriority":18,"id":52385905,"name":"4 - 3"},{"status":"ACTIVE","sortPriority":19,"id":52385906,"name":"4 - 5"},{"status":"ACTIVE","sortPriority":20,"id":52385907,"name":"4 - 6"},{"status":"ACTIVE","sortPriority":21,"id":52385910,"name":"5 - 1"},{"status":"ACTIVE","sortPriority":22,"id":52385911,"name":"5 - 2"},{"status":"ACTIVE","sortPriority":23,"id":52385912,"name":"5 - 3"},{"status":"ACTIVE","sortPriority":24,"id":52385913,"name":"5 - 4"},{"status":"ACTIVE","sortPriority":25,"id":52385914,"name":"5 - 6"},{"status":"ACTIVE","sortPriority":26,"id":52385917,"name":"6 - 1"},{"status":"ACTIVE","sortPriority":27,"id":52385918,"name":"6 - 2"},{"status":"ACTIVE","sortPriority":28,"id":52385919,"name":"6 - 3"},{"status":"ACTIVE","sortPriority":29,"id":52385920,"name":"6 - 4"},{"status":"ACTIVE","sortPriority":30,"id":52385921,"name":"6 - 5"}],"regulators":["MR_INT"],"venue":"Perry Barr","countryCode":"GB","discountAllowed":true,"timezone":"Europe/London","openDate":"2024-06-27T13:29:00.000Z","version":5994794126,"name":"Forecast","eventName":"Perry Barr (F/C) 27th Jun"},"rc":[{"atb":[[1.03,7.8]],"id":52385910},{"atb":[[1.03,7.8]],"id":52385912},{"atb":[[1.03,7.8]],"id":52385906},{"atb":[[1.01,23.41]],"id":52385918},{"atb":[[1.02,11.7]],"id":52385920},{"atb":[[1.03,7.8]],"id":52385889},{"atb":[[1.02,11.7]],"id":52385914},{"atb":[[1.01,23.41]],"id":52385883},{"atb":[[1.03,7.8]],"id":52385885},{"atb":[[1.03,7.8]],"id":52385896},{"atb":[[1.02,11.7]],"id":52385890},{"atb":[[1.02,11.7]],"id":52385892},{"atb":[[1.02,11.7]],"id":52385904},{"atb":[[1.01,23.41]],"id":52385898},{"atb":[[1.01,23.41]],"id":52385900},{"atb":[[1.02,11.7]],"id":52385911},{"atb":[[1.03,7.8]],"id":52385913},{"atb":[[1.03,7.8]],"id":52385907},{"atb":[[1.03,7.8]],"id":52385886},{"atb":[[1.02,11.7]],"id":52385919},{"atb":[[1.03,7.8]],"id":52385921},{"atb":[[1.02,11.7]],"id":52385882},{"atb":[[1.02,11.7]],"id":52385884},{"atb":[[1.03,7.8]],"id":52385917},{"atb":[[1.02,11.7]],"id":52385897},{"atb":[[1.03,7.8]],"id":52385891},{"atb":[[1.03,7.8]],"id":52385893},{"atb":[[1.01,23.41]],"id":52385903},{"atb":[[1.01,23.41]],"id":52385905},{"atb":[[1.03,7.8]],"id":52385899}],"con":true,"img":true}]}
{"op":"mcm","clk":"11547659679","pt":1719445082619,"mc":[{"id":"1.230178176","marketDefinition":{"bspMarket":false,"turnInPlayEnabled":false,"persistenceEnabled":false,"marketBaseRate":5.0,"eventId":"33376048","eventTypeId":"4339","numberOfWinners":1,"bettingType":"ODDS","marketType":"FORECAST","marketTime":"2024-06-27T16:37:00.000Z","suspendTime":"2024-06-27T16:37:00.000Z","bspReconciled":false,"complete":true,"inPlay":false,"crossMatching":false,"runnersVoidable":false,"numberOfActiveRunners":30,"betDelay":0,"status":"OPEN","runners":[{"status":"ACTIVE","sortPriority":1,"id":52385882,"name":"1 - 2"},{"status":"ACTIVE","sortPriority":2,"id":52385883,"name":"1 - 3"},{"status":"ACTIVE","sortPriority":3,"id":52385884,"name":"1 - 4"},{"status":"ACTIVE","sortPriority":4,"id":52385885,"name":"1 - 5"},{"status":"ACTIVE","sortPriority":5,"id":52385886,"name":"1 - 6"},{"status":"ACTIVE","sortPriority":6,"id":52385889,"name":"2 - 1"},{"status":"ACTIVE","sortPriority":7,"id":52385890,"name":"2 - 3"},{"status":"ACTIVE","sortPriority":8,"id":52385891,"name":"2 - 4"},{"status":"ACTIVE","sortPriority":9,"id":52385892,"name":"2 - 5"},{"status":"ACTIVE","sortPriority":10,"id":52385893,"name":"2 - 6"},{"status":"ACTIVE","sortPriority":11,"id":52385896,"name":"3 - 1"},{"status":"ACTIVE","sortPriority":12,"id":52385897,"name":"3 - 2"},{"status":"ACTIVE","sortPriority":13,"id":52385898,"name":"3 - 4"},{"status":"ACTIVE","sortPriority":14,"id":52385899,"name":"3 - 5"},{"status":"ACTIVE","sortPriority":15,"id":52385900,"name":"3 - 6"},{"status":"ACTIVE","sortPriority":16,"id":52385903,"name":"4 - 1"},{"status":"ACTIVE","sortPriority":17,"id":52385904,"name":"4 - 2"},{"status":"ACTIVE","sortPriority":18,"id":52385905,"name":"4 - 3"},{"status":"ACTIVE","sortPriority":19,"id":52385906,"name":"4 - 5"},{"status":"ACTIVE","sortPriority":20,"id":52385907,"name":"4 - 6"},{"status":"ACTIVE","sortPriority":21,"id":52385910,"name":"5 - 1"},{"status":"ACTIVE","sortPriority":22,"id":52385911,"name":"5 - 2"},{"status":"ACTIVE","sortPriority":23,"id":52385912,"name":"5 - 3"},{"status":"ACTIVE","sortPriority":24,"id":52385913,"name":"5 - 4"},{"status":"ACTIVE","sortPriority":25,"id":52385914,"name":"5 - 6"},{"status":"ACTIVE","sortPriority":26,"id":52385917,"name":"6 - 1"},{"status":"ACTIVE","sortPriority":27,"id":52385918,"name":"6 - 2"},{"status":"ACTIVE","sortPriority":28,"id":52385919,"name":"6 - 3"},{"status":"ACTIVE","sortPriority":29,"id":52385920,"name":"6 - 4"},{"status":"ACTIVE","sortPriority":30,"id":52385921,"name":"6 - 5"}],"regulators":["MR_INT"],"venue":"Perry Barr","countryCode":"GB","discountAllowed":true,"timezone":"Europe/London","openDate":"2024-06-27T13:29:00.000Z","version":5994794126,"name":"Forecast","eventName":"Perry Barr (F/C) 27th Jun"},"rc":[{"atb":[[1.03,7.81]],"id":52385910},{"atb":[[1.03,7.81]],"id":52385912},{"atb":[[1.03,7.81]],"id":52385906},{"atb":[[1.01,23.42]],"id":52385918},{"atb":[[1.02,11.71]],"id":52385920},{"atb":[[1.03,7.81]],"id":52385889},{"atb":[[1.02,11.71]],"id":52385914},{"atb":[[1.01,23.42]],"id":52385883},{"atb":[[1.03,7.81]],"id":52385885},{"atb":[[1.03,7.81]],"id":52385896},{"atb":[[1.02,11.71]],"id":52385890},{"atb":[[1.02,11.71]],"id":52385892},{"atb":[[1.02,11.71]],"id":52385904},{"atb":[[1.01,23.42]],"id":52385898},{"atb":[[1.01,23.42]],"id":52385900},{"atb":[[1.02,11.71]],"id":52385911},{"atb":[[1.03,7.81]],"id":52385913},{"atb":[[1.03,7.81]],"id":52385907},{"atb":[[1.03,7.81]],"id":52385886},{"atb":[[1.02,11.71]],"id":52385919},{"atb":[[1.03,7.81]],"id":52385921},{"atb":[[1.02,11.71]],"id":52385882},{"atb":[[1.02,11.71]],"id":52385884},{"atb":[[1.03,7.81]],"id":52385917},{"atb":[[1.02,11.71]],"id":52385897},{"atb":[[1.03,7.81]],"id":52385891},{"atb":[[1.03,7.81]],"id":52385893},{"atb":[[1.01,23.42]],"id":52385903},{"atb":[[1.01,23.42]],"id":52385905},{"atb":[[1.03,7.81]],"id":52385899}],"con":true,"img":true}]}
{"op":"mcm","clk":"11548031723","pt":1719450482634,"mc":[{"id":"1.230178176","marketDefinition":{"bspMarket":false,"turnInPlayEnabled":false,"persistenceEnabled":false,"marketBaseRate":5.0,"eventId":"33376048","eventTypeId":"4339","numberOfWinners":1,"bettingType":"ODDS","marketType":"FORECAST","marketTime":"2024-06-27T16:37:00.000Z","suspendTime":"2024-06-27T16:37:00.000Z","bspReconciled":false,"complete":true,"inPlay":false,"crossMatching":false,"runnersVoidable":false,"numberOfActiveRunners":30,"betDelay":0,"status":"OPEN","runners":[{"status":"ACTIVE","sortPriority":1,"id":52385882,"name":"1 - 2"},{"status":"ACTIVE","sortPriority":2,"id":52385883,"name":"1 - 3"},{"status":"ACTIVE","sortPriority":3,"id":52385884,"name":"1 - 4"},{"status":"ACTIVE","sortPriority":4,"id":52385885,"name":"1 - 5"},{"status":"ACTIVE","sortPriority":5,"id":52385886,"name":"1 - 6"},{"status":"ACTIVE","sortPriority":6,"id":52385889,"name":"2 - 1"},{"status":"ACTIVE","sortPriority":7,"id":52385890,"name":"2 - 3"},{"status":"ACTIVE","sortPriority":8,"id":52385891,"name":"2 - 4"},{"status":"ACTIVE","sortPriority":9,"id":52385892,"name":"2 - 5"},{"status":"ACTIVE","sortPriority":10,"id":52385893,"name":"2 - 6"},{"status":"ACTIVE","sortPriority":11,"id":52385896,"name":"3 - 1"},{"status":"ACTIVE","sortPriority":12,"id":52385897,"name":"3 - 2"},{"status":"ACTIVE","sortPriority":13,"id":52385898,"name":"3 - 4"},{"status":"ACTIVE","sortPriority":14,"id":52385899,"name":"3 - 5"},{"status":"ACTIVE","sortPriority":15,"id":52385900,"name":"3 - 6"},{"status":"ACTIVE","sortPriority":16,"id":52385903,"name":"4 - 1"},{"status":"ACTIVE","sortPriority":17,"id":52385904,"name":"4 - 2"},{"status":"ACTIVE","sortPriority":18,"id":52385905,"name":"4 - 3"},{"status":"ACTIVE","sortPriority":19,"id":52385906,"name":"4 - 5"},{"status":"ACTIVE","sortPriority":20,"id":52385907,"name":"4 - 6"},{"status":"ACTIVE","sortPriority":21,"id":52385910,"name":"5 - 1"},{"status":"ACTIVE","sortPriority":22,"id":52385911,"name":"5 - 2"},{"status":"ACTIVE","sortPriority":23,"id":52385912,"name":"5 - 3"},{"status":"ACTIVE","sortPriority":24,"id":52385913,"name":"5 - 4"},{"status":"ACTIVE","sortPriority":25,"id":52385914,"name":"5 - 6"},{"status":"ACTIVE","sortPriority":26,"id":52385917,"name":"6 - 1"},{"status":"ACTIVE","sortPriority":27,"id":52385918,"name":"6 - 2"},{"status":"ACTIVE","sortPriority":28,"id":52385919,"name":"6 - 3"},{"status":"ACTIVE","sortPriority":29,"id":52385920,"name":"6 - 4"},{"status":"ACTIVE","sortPriority":30,"id":52385921,"name":"6 - 5"}],"regulators":["MR_INT"],"venue":"Perry Barr","countryCode":"GB","discountAllowed":true,"timezone":"Europe/London","openDate":"2024-06-27T13:29:00.000Z","version":5994794126,"name":"Forecast","eventName":"Perry Barr (F/C) 27th Jun"},"rc":[{"atb":[[1.03,7.81]],"id":52385910},{"atb":[[1.03,7.81]],"id":52385912},{"atb":[[1.03,7.81]],"id":52385906},{"atb":[[1.01,23.42]],"id":52385918},{"atb":[[1.02,11.71]],"id":52385920},{"atb":[[1.03,7.81]],"id":52385889},{"atb":[[1.02,11.71]],"id":52385914},{"atb":[[1.01,23.42]],"id":52385883},{"atb":[[1.03,7.81]],"id":52385885},{"atb":[[1.03,7.81]],"id":52385896},{"atb":[[1.02,11.71]],"id":52385890},{"atb":[[1.02,11.71]],"id":52385892},{"atb":[[1.02,11.71]],"id":52385904},{"atb":[[1.01,23.42]],"id":52385898},{"atb":[[1.01,23.42]],"id":52385900},{"atb":[[1.02,11.71]],"id":52385911},{"atb":[[1.03,7.81]],"id":52385913},{"atb":[[1.03,7.81]],"id":52385907},{"atb":[[1.03,7.81]],"id":52385886},{"atb":[[1.02,11.71]],"id":52385919},{"atb":[[1.03,7.81]],"id":52385921},{"atb":[[1.02,11.71]],"id":52385882},{"atb":[[1.02,11.71]],"id":52385884},{"atb":[[1.03,7.81]],"id":52385917},{"atb":[[1.02,11.71]],"id":52385897},{"atb":[[1.03,7.81]],"id":52385891},{"atb":[[1.03,7.81]],"id":52385893},{"atb":[[1.01,23.42]],"id":52385903},{"atb":[[1.01,23.42]],"id":52385905},{"atb":[[1.03,7.81]],"id":52385899}],"con":true,"img":true}]}
{"op":"mcm","clk":"11548270787","pt":1719455882653,"mc":[{"id":"1.230178176","marketDefinition":{"bspMarket":false,"turnInPlayEnabled":false,"persistenceEnabled":false,"marketBaseRate":5.0,"eventId":"33376048","eventTypeId":"4339","numberOfWinners":1,"bettingType":"ODDS","marketType":"FORECAST","marketTime":"2024-06-27T16:37:00.000Z","suspendTime":"2024-06-27T16:37:00.000Z","bspReconciled":false,"complete":true,"inPlay":false,"crossMatching":false,"runnersVoidable":false,"numberOfActiveRunners":30,"betDelay":0,"status":"OPEN","runners":[{"status":"ACTIVE","sortPriority":1,"id":52385882,"name":"1 - 2"},{"status":"ACTIVE","sortPriority":2,"id":52385883,"name":"1 - 3"},{"status":"ACTIVE","sortPriority":3,"id":52385884,"name":"1 - 4"},{"status":"ACTIVE","sortPriority":4,"id":52385885,"name":"1 - 5"},{"status":"ACTIVE","sortPriority":5,"id":52385886,"name":"1 - 6"},{"status":"ACTIVE","sortPriority":6,"id":52385889,"name":"2 - 1"},{"status":"ACTIVE","sortPriority":7,"id":52385890,"name":"2 - 3"},{"status":"ACTIVE","sortPriority":8,"id":52385891,"name":"2 - 4"},{"status":"ACTIVE","sortPriority":9,"id":52385892,"name":"2 - 5"},{"status":"ACTIVE","sortPriority":10,"id":52385893,"name":"2 - 6"},{"status":"ACTIVE","sortPriority":11,"id":52385896,"name":"3 - 1"},{"status":"ACTIVE","sortPriority":12,"id":52385897,"name":"3 - 2"},{"status":"ACTIVE","sortPriority":13,"id":52385898,"name":"3 - 4"},{"status":"ACTIVE","sortPriority":14,"id":52385899,"name":"3 - 5"},{"status":"ACTIVE","sortPriority":15,"id":52385900,"name":"3 - 6"},{"status":"ACTIVE","sortPriority":16,"id":52385903,"name":"4 - 1"},{"status":"ACTIVE","sortPriority":17,"id":52385904,"name":"4 - 2"},{"status":"ACTIVE","sortPriority":18,"id":52385905,"name":"4 - 3"},{"status":"ACTIVE","sortPriority":19,"id":52385906,"name":"4 - 5"},{"status":"ACTIVE","sortPriority":20,"id":52385907,"name":"4 - 6"},{"status":"ACTIVE","sortPriority":21,"id":52385910,"name":"5 - 1"},{"status":"ACTIVE","sortPriority":22,"id":52385911,"name":"5 - 2"},{"status":"ACTIVE","sortPriority":23,"id":52385912,"name":"5 - 3"},{"status":"ACTIVE","sortPriority":24,"id":52385913,"name":"5 - 4"},{"status":"ACTIVE","sortPriority":25,"id":52385914,"name":"5 - 6"},{"status":"ACTIVE","sortPriority":26,"id":52385917,"name":"6 - 1"},{"status":"ACTIVE","sortPriority":27,"id":52385918,"name":"6 - 2"},{"status":"ACTIVE","sortPriority":28,"id":52385919,"name":"6 - 3"},{"status":"ACTIVE","sortPriority":29,"id":52385920,"name":"6 - 4"},{"status":"ACTIVE","sortPriority":30,"id":52385921,"name":"6 - 5"}],"regulators":["MR_INT"],"venue":"Perry Barr","countryCode":"GB","discountAllowed":true,"timezone":"Europe/London","openDate":"2024-06-27T13:29:00.000Z","version":5994794126,"name":"Forecast","eventName":"Perry Barr (F/C) 27th Jun"},"rc":[{"atb":[[1.03,7.81]],"id":52385910},{"atb":[[1.03,7.81]],"id":52385912},{"atb":[[1.03,7.81]],"id":52385906},{"atb":[[1.01,23.42]],"id":52385918},{"atb":[[1.02,11.71]],"id":52385920},{"atb":[[1.03,7.81]],"id":52385889},{"atb":[[1.02,11.71]],"id":52385914},{"atb":[[1.01,23.42]],"id":52385883},{"atb":[[1.03,7.81]],"id":52385885},{"atb":[[1.03,7.81]],"id":52385896},{"atb":[[1.02,11.71]],"id":52385890},{"atb":[[1.02,11.71]],"id":52385892},{"atb":[[1.02,11.71]],"id":52385904},{"atb":[[1.01,23.42]],"id":52385898},{"atb":[[1.01,23.42]],"id":52385900},{"atb":[[1.02,11.71]],"id":52385911},{"atb":[[1.03,7.81]],"id":52385913},{"atb":[[1.03,7.81]],"id":52385907},{"atb":[[1.03,7.81]],"id":52385886},{"atb":[[1.02,11.71]],"id":52385919},{"atb":[[1.03,7.81]],"id":52385921},{"atb":[[1.02,11.71]],"id":52385882},{"atb":[[1.02,11.71]],"id":52385884},{"atb":[[1.03,7.81]],"id":52385917},{"atb":[[1.02,11.71]],"id":52385897},{"atb":[[1.03,7.81]],"id":52385891},{"atb":[[1.03,7.81]],"id":52385893},{"atb":[[1.01,23.42]],"id":52385903},{"atb":[[1.01,23.42]],"id":52385905},{"atb":[[1.03,7.81]],"id":52385899}],"con":true,"img":true}]}
{"op":"mcm","clk":"11548414813","pt":1719460929664,"mc":[{"id":"1.230178176","rc":[{"atb":[[1.03,7.81],[1.16,100]],"id":52385910},{"atb":[[1.03,7.81],[1.16,100]],"id":52385912},{"atb":[[1.03,7.81],[1.16,100]],"id":52385906},{"atb":[[1.01,23.42],[1.16,100]],"id":52385918},{"atb":[[1.16,100],[1.02,11.71]],"id":52385920},{"atb":[[1.03,7.81],[1.16,100]],"id":52385889},{"atb":[[1.16,100],[1.02,11.71]],"id":52385914},{"atb":[[1.01,23.42],[1.16,100]],"id":52385883},{"atb":[[1.03,7.81],[1.16,100]],"id":52385885},{"atb":[[1.03,7.81],[1.16,100]],"id":52385896},{"atb":[[1.16,100],[1.02,11.71]],"id":52385890},{"atb":[[1.16,100],[1.02,11.71]],"id":52385892},{"atb":[[1.16,100],[1.02,11.71]],"id":52385904},{"atb":[[1.01,23.42],[1.16,100]],"id":52385898},{"atb":[[1.01,23.42],[1.16,100]],"id":52385900},{"atb":[[1.16,100],[1.02,11.71]],"id":52385911},{"atb":[[1.03,7.81],[1.16,100]],"id":52385913},{"atb":[[1.03,7.81],[1.16,100]],"id":52385907},{"atb":[[1.03,7.81],[1.16,100]],"id":52385886},{"atb":[[1.16,100],[1.02,11.71]],"id":52385919},{"atb":[[1.03,7.81],[1.16,100]],"id":52385921},{"atb":[[1.16,100],[1.02,11.71]],"id":52385882},{"atb":[[1.16,100],[1.02,11.71]],"id":52385884},{"atb":[[1.03,7.81],[1.16,100]],"id":52385917},{"atb":[[1.16,100],[1.02,11.71]],"id":52385897},{"atb":[[1.03,7.81],[1.16,100]],"id":52385891},{"atb":[[1.03,7.81],[1.16,100]],"id":52385893},{"atb":[[1.01,23.42],[1.16,100]],"id":52385903},{"atb":[[1.01,23.42],[1.16,100]],"id":52385905},{"atb":[[1.03,7.81],[1.16,100]],"id":52385899}],"con":true,"img":false}]}
{"op":"mcm","clk":"11548535723","pt":1719466682820,"mc":[{"id":"1.230178176","marketDefinition":{"bspMarket":false,"turnInPlayEnabled":false,"persistenceEnabled":false,"marketBaseRate":5.0,"eventId":"33376048","eventTypeId":"4339","numberOfWinners":1,"bettingType":"ODDS","marketType":"FORECAST","marketTime":"2024-06-27T16:37:00.000Z","suspendTime":"2024-06-27T16:37:00.000Z","bspReconciled":false,"complete":true,"inPlay":false,"crossMatching":false,"runnersVoidable":false,"numberOfActiveRunners":30,"betDelay":0,"status":"OPEN","runners":[{"status":"ACTIVE","sortPriority":1,"id":52385882,"name":"1 - 2"},{"status":"ACTIVE","sortPriority":2,"id":52385883,"name":"1 - 3"},{"status":"ACTIVE","sortPriority":3,"id":52385884,"name":"1 - 4"},{"status":"ACTIVE","sortPriority":4,"id":52385885,"name":"1 - 5"},{"status":"ACTIVE","sortPriority":5,"id":52385886,"name":"1 - 6"},{"status":"ACTIVE","sortPriority":6,"id":52385889,"name":"2 - 1"},{"status":"ACTIVE","sortPriority":7,"id":52385890,"name":"2 - 3"},{"status":"ACTIVE","sortPriority":8,"id":52385891,"name":"2 - 4"},{"status":"ACTIVE","sortPriority":9,"id":52385892,"name":"2 - 5"},{"status":"ACTIVE","sortPriority":10,"id":52385893,"name":"2 - 6"},{"status":"ACTIVE","sortPriority":11,"id":52385896,"name":"3 - 1"},{"status":"ACTIVE","sortPriority":12,"id":52385897,"name":"3 - 2"},{"status":"ACTIVE","sortPriority":13,"id":52385898,"name":"3 - 4"},{"status":"ACTIVE","sortPriority":14,"id":52385899,"name":"3 - 5"},{"status":"ACTIVE","sortPriority":15,"id":52385900,"name":"3 - 6"},{"status":"ACTIVE","sortPriority":16,"id":52385903,"name":"4 - 1"},{"status":"ACTIVE","sortPriority":17,"id":52385904,"name":"4 - 2"},{"status":"ACTIVE","sortPriority":18,"id":52385905,"name":"4 - 3"},{"status":"ACTIVE","sortPriority":19,"id":52385906,"name":"4 - 5"},{"status":"ACTIVE","sortPriority":20,"id":52385907,"name":"4 - 6"},{"status":"ACTIVE","sortPriority":21,"id":52385910,"name":"5 - 1"},{"status":"ACTIVE","sortPriority":22,"id":52385911,"name":"5 - 2"},{"status":"ACTIVE","sortPriority":23,"id":52385912,"name":"5 - 3"},{"status":"ACTIVE","sortPriority":24,"id":52385913,"name":"5 - 4"},{"status":"ACTIVE","sortPriority":25,"id":52385914,"name":"5 - 6"},{"status":"ACTIVE","sortPriority":26,"id":52385917,"name":"6 - 1"},{"status":"ACTIVE","sortPriority":27,"id":52385918,"name":"6 - 2"},{"status":"ACTIVE","sortPriority":28,"id":52385919,"name":"6 - 3"},{"status":"ACTIVE","sortPriority":29,"id":52385920,"name":"6 - 4"},{"status":"ACTIVE","sortPriority":30,"id":52385921,"name":"6 - 5"}],"regulators":["MR_INT"],"venue":"Perry Barr","countryCode":"GB","discountAllowed":true,"timezone":"Europe/London","openDate":"2024-06-27T13:29:00.000Z","version":5994794126,"name":"Forecast","eventName":"Perry Barr (F/C) 27th Jun"},"rc":[{"atb":[[1.16,100],[1.03,7.81]],"id":52385910},{"atb":[[1.16,100],[1.03,7.81]],"id":52385912},{"atb":[[1.16,100],[1.03,7.81]],"id":52385906},{"atb":[[1.01,23.42],[1.16,100]],"id":52385918},{"atb":[[1.16,100],[1.02,11.71]],"id":52385920},{"atb":[[1.16,100],[1.03,7.81]],"id":52385889},{"atb":[[1.16,100],[1.02,11.71]],"id":52385914},{"atb":[[1.01,23.42],[1.16,100]],"id":52385883},{"atb":[[1.16,100],[1.03,7.81]],"id":52385885},{"atb":[[1.16,100],[1.03,7.81]],"id":52385896},{"atb":[[1.16,100],[1.02,11.71]],"id":52385890},{"atb":[[1.16,100],[1.02,11.71]],"id":52385892},{"atb":[[1.16,100],[1.02,11.71]],"id":52385904},{"atb":[[1.01,23.42],[1.16,100]],"id":52385898},{"atb":[[1.01,23.42],[1.16,100]],"id":52385900},{"atb":[[1.16,100],[1.02,11.71]],"id":52385911},{"atb":[[1.16,100],[1.03,7.81]],"id":52385913},{"atb":[[1.16,100],[1.03,7.81]],"id":52385907},{"atb":[[1.16,100],[1.03,7.81]],"id":52385886},{"atb":[[1.16,100],[1.02,11.71]],"id":52385919},{"atb":[[1.16,100],[1.03,7.81]],"id":52385921},{"atb":[[1.16,100],[1.02,11.71]],"id":52385882},{"atb":[[1.16,100],[1.02,11.71]],"id":52385884},{"atb":[[1.16,100],[1.03,7.81]],"id":52385917},{"atb":[[1.16,100],[1.02,11.71]],"id":52385897},{"atb":[[1.16,100],[1.03,7.81]],"id":52385891},{"atb":[[1.16,100],[1.03,7.81]],"id":52385893},{"atb":[[1.01,23.42],[1.16,100]],"id":52385903},{"atb":[[1.01,23.42],[1.16,100]],"id":52385905},{"atb":[[1.16,100],[1.03,7.81]],"id":52385899}],"con":true,"img":true}]}
{"op":"mcm","clk":"11548656204","pt":1719472082590,"mc":[{"id":"1.230178176","marketDefinition":{"bspMarket":false,"turnInPlayEnabled":false,"persistenceEnabled":false,"marketBaseRate":5.0,"eventId":"33376048","eventTypeId":"4339","numberOfWinners":1,"bettingType":"ODDS","marketType":"FORECAST","marketTime":"2024-06-27T16:37:00.000Z","suspendTime":"2024-06-27T16:37:00.000Z","bspReconciled":false,"complete":true,"inPlay":false,"crossMatching":false,"runnersVoidable":false,"numberOfActiveRunners":30,"betDelay":0,"status":"OPEN","runners":[{"status":"ACTIVE","sortPriority":1,"id":52385882,"name":"1 - 2"},{"status":"ACTIVE","sortPriority":2,"id":52385883,"name":"1 - 3"},{"status":"ACTIVE","sortPriority":3,"id":52385884,"name":"1 - 4"},{"status":"ACTIVE","sortPriority":4,"id":52385885,"name":"1 - 5"},{"status":"ACTIVE","sortPriority":5,"id":52385886,"name":"1 - 6"},{"status":"ACTIVE","sortPriority":6,"id":52385889,"name":"2 - 1"},{"status":"ACTIVE","sortPriority":7,"id":52385890,"name":"2 - 3"},{"status":"ACTIVE","sortPriority":8,"id":52385891,"name":"2 - 4"},{"status":"ACTIVE","sortPriority":9,"id":52385892,"name":"2 - 5"},{"status":"ACTIVE","sortPriority":10,"id":52385893,"name":"2 - 6"},{"status":"ACTIVE","sortPriority":11,"id":52385896,"name":"3 - 1"},{"status":"ACTIVE","sortPriority":12,"id":52385897,"name":"3 - 2"},{"status":"ACTIVE","sortPriority":13,"id":52385898,"name":"3 - 4"},{"status":"ACTIVE","sortPriority":14,"id":52385899,"name":"3 - 5"},{"status":"ACTIVE","sortPriority":15,"id":52385900,"name":"3 - 6"},{"status":"ACTIVE","sortPriority":16,"id":52385903,"name":"4 - 1"},{"status":"ACTIVE","sortPriority":17,"id":52385904,"name":"4 - 2"},{"status":"ACTIVE","sortPriority":18,"id":52385905,"name":"4 - 3"},{"status":"ACTIVE","sortPriority":19,"id":52385906,"name":"4 - 5"},{"status":"ACTIVE","sortPriority":20,"id":52385907,"name":"4 - 6"},{"status":"ACTIVE","sortPriority":21,"id":52385910,"name":"5 - 1"},{"status":"ACTIVE","sortPriority":22,"id":52385911,"name":"5 - 2"},{"status":"ACTIVE","sortPriority":23,"id":52385912,"name":"5 - 3"},{"status":"ACTIVE","sortPriority":24,"id":52385913,"name":"5 - 4"},{"status":"ACTIVE","sortPriority":25,"id":52385914,"name":"5 - 6"},{"status":"ACTIVE","sortPriority":26,"id":52385917,"name":"6 - 1"},{"status":"ACTIVE","sortPriority":27,"id":52385918,"name":"6 - 2"},{"status":"ACTIVE","sortPriority":28,"id":52385919,"name":"6 - 3"},{"status":"ACTIVE","sortPriority":29,"id":52385920,"name":"6 - 4"},{"status":"ACTIVE","sortPriority":30,"id":52385921,"name":"6 - 5"}],"regulators":["MR_INT"],"venue":"Perry Barr","countryCode":"GB","discountAllowed":true,"timezone":"Europe/London","openDate":"2024-06-27T13:29:00.000Z","version":5994794126,"name":"Forecast","eventName":"Perry Barr (F/C) 27th Jun"},"rc":[{"atb":[[1.16,100],[1.03,7.8]],"id":52385910},{"atb":[[1.16,100],[1.03,7.8]],"id":52385912},{"atb":[[1.16,100],[1.03,7.8]],"id":52385906},{"atb":[[1.01,23.41],[1.16,100]],"id":52385918},{"atb":[[1.16,100],[1.02,11.7]],"id":52385920},{"atb":[[1.16,100],[1.03,7.8]],"id":52385889},{"atb":[[1.16,100],[1.02,11.7]],"id":52385914},{"atb":[[1.01,23.41],[1.16,100]],"id":52385883},{"atb":[[1.16,100],[1.03,7.8]],"id":52385885},{"atb":[[1.16,100],[1.03,7.8]],"id":52385896},{"atb":[[1.16,100],[1.02,11.7]],"id":52385890},{"atb":[[1.16,100],[1.02,11.7]],"id":52385892},{"atb":[[1.16,100],[1.02,11.7]],"id":52385904},{"atb":[[1.01,23.41],[1.16,100]],"id":52385898},{"atb":[[1.01,23.41],[1.16,100]],"id":52385900},{"atb":[[1.16,100],[1.02,11.7]],"id":52385911},{"atb":[[1.16,100],[1.03,7.8]],"id":52385913},{"atb":[[1.16,100],[1.03,7.8]],"id":52385907},{"atb":[[1.16,100],[1.03,7.8]],"id":52385886},{"atb":[[1.16,100],[1.02,11.7]],"id":52385919},{"atb":[[1.16,100],[1.03,7.8]],"id":52385921},{"atb":[[1.16,100],[1.02,11.7]],"id":52385882},{"atb":[[1.16,100],[1.02,11.7]],"id":52385884},{"atb":[[1.16,100],[1.03,7.8]],"id":52385917},{"atb":[[1.16,100],[1.02,11.7]],"id":52385897},{"atb":[[1.16,100],[1.03,7.8]],"id":52385891},{"atb":[[1.16,100],[1.03,7.8]],"id":52385893},{"atb":[[1.01,23.41],[1.16,100]],"id":52385903},{"atb":[[1.01,23.41],[1.16,100]],"id":52385905},{"atb":[[1.16,100],[1.03,7.8]],"id":52385899}],"con":true,"img":true}]}
{"op":"mcm","clk":"11548861950","pt":1719477482591,"mc":[{"id":"1.230178176","marketDefinition":{"bspMarket":false,"turnInPlayEnabled":false,"persistenceEnabled":false,"marketBaseRate":5.0,"eventId":"33376048","eventTypeId":"4339","numberOfWinners":1,"bettingType":"ODDS","marketType":"FORECAST","marketTime":"2024-06-27T16:37:00.000Z","suspendTime":"2024-06-27T16:37:00.000Z","bspReconciled":false,"complete":true,"inPlay":false,"crossMatching":false,"runnersVoidable":false,"numberOfActiveRunners":30,"betDelay":0,"status":"OPEN","runners":[{"status":"ACTIVE","sortPriority":1,"id":52385882,"name":"1 - 2"},{"status":"ACTIVE","sortPriority":2,"id":52385883,"name":"1 - 3"},{"status":"ACTIVE","sortPriority":3,"id":52385884,"name":"1 - 4"},{"status":"ACTIVE","sortPriority":4,"id":52385885,"name":"1 - 5"},{"status":"ACTIVE","sortPriority":5,"id":52385886,"name":"1 - 6"},{"status":"ACTIVE","sortPriority":6,"id":52385889,"name":"2 - 1"},{"status":"ACTIVE","sortPriority":7,"id":52385890,"name":"2 - 3"},{"status":"ACTIVE","sortPriority":8,"id":52385891,"name":"2 - 4"},{"status":"ACTIVE","sortPriority":9,"id":52385892,"name":"2 - 5"},{"status":"ACTIVE","sortPriority":10,"id":52385893,"name":"2 - 6"},{"status":"ACTIVE","sortPriority":11,"id":52385896,"name":"3 - 1"},{"status":"ACTIVE","sortPriority":12,"id":52385897,"name":"3 - 2"},{"status":"ACTIVE","sortPriority":13,"id":52385898,"name":"3 - 4"},{"status":"ACTIVE","sortPriority":14,"id":52385899,"name":"3 - 5"},{"status":"ACTIVE","sortPriority":15,"id":52385900,"name":"3 - 6"},{"status":"ACTIVE","sortPriority":16,"id":52385903,"name":"4 - 1"},{"status":"ACTIVE","sortPriority":17,"id":52385904,"name":"4 - 2"},{"status":"ACTIVE","sortPriority":18,"id":52385905,"name":"4 - 3"},{"status":"ACTIVE","sortPriority":19,"id":52385906,"name":"4 - 5"},{"status":"ACTIVE","sortPriority":20,"id":52385907,"name":"4 - 6"},{"status":"ACTIVE","sortPriority":21,"id":52385910,"name":"5 - 1"},{"status":"ACTIVE","sortPriority":22,"id":52385911,"name":"5 - 2"},{"status":"ACTIVE","sortPriority":23,"id":52385912,"name":"5 - 3"},{"status":"ACTIVE","sortPriority":24,"id":52385913,"name":"5 - 4"},{"status":"ACTIVE","sortPriority":25,"id":52385914,"name":"5 - 6"},{"status":"ACTIVE","sortPriority":26,"id":52385917,"name":"6 - 1"},{"status":"ACTIVE","sortPriority":27,"id":52385918,"name":"6 - 2"},{"status":"ACTIVE","sortPriority":28,"id":52385919,"name":"6 - 3"},{"status":"ACTIVE","sortPriority":29,"id":52385920,"name":"6 - 4"},{"status":"ACTIVE","sortPriority":30,"id":52385921,"name":"6 - 5"}],"regulators":["MR_INT"],"venue":"Perry Barr","countryCode":"GB","discountAllowed":true,"timezone":"Europe/London","openDate":"2024-06-27T13:29:00.000Z","version":5994794126,"name":"Forecast","eventName":"Perry Barr (F/C) 27th Jun"},"rc":[{"atb":[[1.16,100],[1.03,7.8]],"id":52385910},{"atb":[[1.16,100],[1.03,7.8]],"id":52385912},{"atb":[[1.16,100],[1.03,7.8]],"id":52385906},{"atb":[[1.01,23.41],[1.16,100]],"id":52385918},{"atb":[[1.16,100],[1.02,11.7]],"id":52385920},{"atb":[[1.16,100],[1.03,7.8]],"id":52385889},{"atb":[[1.16,100],[1.02,11.7]],"id":52385914},{"atb":[[1.01,23.41],[1.16,100]],"id":52385883},{"atb":[[1.16,100],[1.03,7.8]],"id":52385885},{"atb":[[1.16,100],[1.03,7.8]],"id":52385896},{"atb":[[1.16,100],[1.02,11.7]],"id":52385890},{"atb":[[1.16,100],[1.02,11.7]],"id":52385892},{"atb":[[1.16,100],[1.02,11.7]],"id":52385904},{"atb":[[1.01,23.41],[1.16,100]],"id":52385898},{"atb":[[1.01,23.41],[1.16,100]],"id":52385900},{"atb":[[1.16,100],[1.02,11.7]],"id":52385911},{"atb":[[1.16,100],[1.03,7.8]],"id":52385913},{"atb":[[1.16,100],[1.03,7.8]],"id":52385907},{"atb":[[1.16,100],[1.03,7.8]],"id":52385886},{"atb":[[1.16,100],[1.02,11.7]],"id":52385919},{"atb":[[1.16,100],[1.03,7.8]],"id":52385921},{"atb":[[1.16,100],[1.02,11.7]],"id":52385882},{"atb":[[1.16,100],[1.02,11.7]],"id":52385884},{"atb":[[1.16,100],[1.03,7.8]],"id":52385917},{"atb":[[1.16,100],[1.02,11.7]],"id":52385897},{"atb":[[1.16,100],[1.03,7.8]],"id":52385891},{"atb":[[1.16,100],[1.03,7.8]],"id":52385893},{"atb":[[1.01,23.41],[1.16,100]],"id":52385903},{"atb":[[1.01,23.41],[1.16,100]],"id":52385905},{"atb":[[1.16,100],[1.03,7.8]],"id":52385899}],"con":true,"img":true}]}
{"op":"mcm","clk":"11549140214","pt":1719482882591,"mc":[{"id":"1.230178176","marketDefinition":{"bspMarket":false,"turnInPlayEnabled":false,"persistenceEnabled":false,"marketBaseRate":5.0,"eventId":"33376048","eventTypeId":"4339","numberOfWinners":1,"bettingType":"ODDS","marketType":"FORECAST","marketTime":"2024-06-27T16:37:00.000Z","suspendTime":"2024-06-27T16:37:00.000Z","bspReconciled":false,"complete":true,"inPlay":false,"crossMatching":false,"runnersVoidable":false,"numberOfActiveRunners":30,"betDelay":0,"status":"OPEN","runners":[{"status":"ACTIVE","sortPriority":1,"id":52385882,"name":"1 - 2"},{"status":"ACTIVE","sortPriority":2,"id":52385883,"name":"1 - 3"},{"status":"ACTIVE","sortPriority":3,"id":52385884,"name":"1 - 4"},{"status":"ACTIVE","sortPriority":4,"id":52385885,"name":"1 - 5"},{"status":"ACTIVE","sortPriority":5,"id":52385886,"name":"1 - 6"},{"status":"ACTIVE","sortPriority":6,"id":52385889,"name":"2 - 1"},{"status":"ACTIVE","sortPriority":7,"id":52385890,"name":"2 - 3"},{"status":"ACTIVE","sortPriority":8,"id":52385891,"name":"2 - 4"},{"status":"ACTIVE","sortPriority":9,"id":52385892,"name":"2 - 5"},{"status":"ACTIVE","sortPriority":10,"id":52385893,"name":"2 - 6"},{"status":"ACTIVE","sortPriority":11,"id":52385896,"name":"3 - 1"},{"status":"ACTIVE","sortPriority":12,"id":52385897,"name":"3 - 2"},{"status":"ACTIVE","sortPriority":13,"id":52385898,"name":"3 - 4"},{"status":"ACTIVE","sortPriority":14,"id":52385899,"name":"3 - 5"},{"status":"ACTIVE","sortPriority":15,"id":52385900,"name":"3 - 6"},{"status":"ACTIVE","sortPriority":16,"id":52385903,"name":"4 - 1"},{"status":"ACTIVE","sortPriority":17,"id":52385904,"name":"4 - 2"},{"status":"ACTIVE","sortPriority":18,"id":52385905,"name":"4 - 3"},{"status":"ACTIVE","sortPriority":19,"id":52385906,"name":"4 - 5"},{"status":"ACTIVE","sortPriority":20,"id":52385907,"name":"4 - 6"},{"status":"ACTIVE","sortPriority":21,"id":52385910,"name":"5 - 1"},{"status":"ACTIVE","sortPriority":22,"id":52385911,"name":"5 - 2"},{"status":"ACTIVE","sortPriority":23,"id":52385912,"name":"5 - 3"},{"status":"ACTIVE","sortPriority":24,"id":52385913,"name":"5 - 4"},{"status":"ACTIVE","sortPriority":25,"id":52385914,"name":"5 - 6"},{"status":"ACTIVE","sortPriority":26,"id":52385917,"name":"6 - 1"},{"status":"ACTIVE","sortPriority":27,"id":52385918,"name":"6 - 2"},{"status":"ACTIVE","sortPriority":28,"id":52385919,"name":"6 - 3"},{"status":"ACTIVE","sortPriority":29,"id":52385920,"name":"6 - 4"},{"status":"ACTIVE","sortPriority":30,"id":52385921,"name":"6 - 5"}],"regulators":["MR_INT"],"venue":"Perry Barr","countryCode":"GB","discountAllowed":true,"timezone":"Europe/London","openDate":"2024-06-27T13:29:00.000Z","version":5994794126,"name":"Forecast","eventName":"Perry Barr (F/C) 27th Jun"},"rc":[{"atb":[[1.16,100],[1.03,7.8]],"id":52385910},{"atb":[[1.16,100],[1.03,7.8]],"id":52385912},{"atb":[[1.16,100],[1.03,7.8]],"id":52385906},{"atb":[[1.01,23.41],[1.16,100]],"id":52385918},{"atb":[[1.16,100],[1.02,11.7]],"id":52385920},{"atb":[[1.16,100],[1.03,7.8]],"id":52385889},{"atb":[[1.16,100],[1.02,11.7]],"id":52385914},{"atb":[[1.01,23.41],[1.16,100]],"id":52385883},{"atb":[[1.16,100],[1.03,7.8]],"id":52385885},{"atb":[[1.16,100],[1.03,7.8]],"id":52385896},{"atb":[[1.16,100],[1.02,11.7]],"id":52385890},{"atb":[[1.16,100],[1.02,11.7]],"id":52385892},{"atb":[[1.16,100],[1.02,11.7]],"id":52385904},{"atb":[[1.01,23.41],[1.16,100]],"id":52385898},{"atb":[[1.01,23.41],[1.16,100]],"id":52385900},{"atb":[[1.16,100],[1.02,11.7]],"id":52385911},{"atb":[[1.16,100],[1.03,7.8]],"id":52385913},{"atb":[[1.16,100],[1.03,7.8]],"id":52385907},{"atb":[[1.16,100],[1.03,7.8]],"id":52385886},{"atb":[[1.16,100],[1.02,11.7]],"id":52385919},{"atb":[[1.16,100],[1.03,7.8]],"id":52385921},{"atb":[[1.16,100],[1.02,11.7]],"id":52385882},{"atb":[[1.16,100],[1.02,11.7]],"id":52385884},{"atb":[[1.16,100],[1.03,7.8]],"id":52385917},{"atb":[[1.16,100],[1.02,11.7]],"id":52385897},{"atb":[[1.16,100],[1.03,7.8]],"id":52385891},{"atb":[[1.16,100],[1.03,7.8]],"id":52385893},{"atb":[[1.01,23.41],[1.16,100]],"id":52385903},{"atb":[[1.01,23.41],[1.16,100]],"id":52385905},{"atb":[[1.16,100],[1.03,7.8]],"id":52385899}],"con":true,"img":true}]}
{"op":"mcm","clk":"11549606645","pt":1719488282608,"mc":[{"id":"1.230178176","marketDefinition":{"bspMarket":false,"turnInPlayEnabled":false,"persistenceEnabled":false,"marketBaseRate":5.0,"eventId":"33376048","eventTypeId":"4339","numberOfWinners":1,"bettingType":"ODDS","marketType":"FORECAST","marketTime":"2024-06-27T16:37:00.000Z","suspendTime":"2024-06-27T16:37:00.000Z","bspReconciled":false,"complete":true,"inPlay":false,"crossMatching":false,"runnersVoidable":false,"numberOfActiveRunners":30,"betDelay":0,"status":"OPEN","runners":[{"status":"ACTIVE","sortPriority":1,"id":52385882,"name":"1 - 2"},{"status":"ACTIVE","sortPriority":2,"id":52385883,"name":"1 - 3"},{"status":"ACTIVE","sortPriority":3,"id":52385884,"name":"1 - 4"},{"status":"ACTIVE","sortPriority":4,"id":52385885,"name":"1 - 5"},{"status":"ACTIVE","sortPriority":5,"id":52385886,"name":"1 - 6"},{"status":"ACTIVE","sortPriority":6,"id":52385889,"name":"2 - 1"},{"status":"ACTIVE","sortPriority":7,"id":52385890,"name":"2 - 3"},{"status":"ACTIVE","sortPriority":8,"id":52385891,"name":"2 - 4"},{"status":"ACTIVE","sortPriority":9,"id":52385892,"name":"2 - 5"},{"status":"ACTIVE","sortPriority":10,"id":52385893,"name":"2 - 6"},{"status":"ACTIVE","sortPriority":11,"id":52385896,"name":"3 - 1"},{"status":"ACTIVE","sortPriority":12,"id":52385897,"name":"3 - 2"},{"status":"ACTIVE","sortPriority":13,"id":52385898,"name":"3 - 4"},{"status":"ACTIVE","sortPriority":14,"id":52385899,"name":"3 - 5"},{"status":"ACTIVE","sortPriority":15,"id":52385900,"name":"3 - 6"},{"status":"ACTIVE","sortPriority":16,"id":52385903,"name":"4 - 1"},{"status":"ACTIVE","sortPriority":17,"id":52385904,"name":"4 - 2"},{"status":"ACTIVE","sortPriority":18,"id":52385905,"name":"4 - 3"},{"status":"ACTIVE","sortPriority":19,"id":52385906,"name":"4 - 5"},{"status":"ACTIVE","sortPriority":20,"id":52385907,"name":"4 - 6"},{"status":"ACTIVE","sortPriority":21,"id":52385910,"name":"5 - 1"},{"status":"ACTIVE","sortPriority":22,"id":52385911,"name":"5 - 2"},{"status":"ACTIVE","sortPriority":23,"id":52385912,"name":"5 - 3"},{"status":"ACTIVE","sortPriority":24,"id":52385913,"name":"5 - 4"},{"status":"ACTIVE","sortPriority":25,"id":52385914,"name":"5 - 6"},{"status":"ACTIVE","sortPriority":26,"id":52385917,"name":"6 - 1"},{"status":"ACTIVE","sortPriority":27,"id":52385918,"name":"6 - 2"},{"status":"ACTIVE","sortPriority":28,"id":52385919,"name":"6 - 3"},{"status":"ACTIVE","sortPriority":29,"id":52385920,"name":"6 - 4"},{"status":"ACTIVE","sortPriority":30,"id":52385921,"name":"6 - 5"}],"regulators":["MR_INT"],"venue":"Perry Barr","countryCode":"GB","discountAllowed":true,"timezone":"Europe/London","openDate":"2024-06-27T13:29:00.000Z","version":5994794126,"name":"Forecast","eventName":"Perry Barr (F/C) 27th Jun"},"rc":[{"atb":[[1.16,100],[1.03,7.8]],"id":52385910},{"atb":[[1.16,100],[1.03,7.8]],"id":52385912},{"atb":[[1.16,100],[1.03,7.8]],"id":52385906},{"atb":[[1.01,23.41],[1.16,100]],"id":52385918},{"atb":[[1.16,100],[1.02,11.7]],"id":52385920},{"atb":[[1.16,100],[1.03,7.8]],"id":52385889},{"atb":[[1.16,100],[1.02,11.7]],"id":52385914},{"atb":[[1.01,23.41],[1.16,100]],"id":52385883},{"atb":[[1.16,100],[1.03,7.8]],"id":52385885},{"atb":[[1.16,100],[1.03,7.8]],"id":52385896},{"atb":[[1.16,100],[1.02,11.7]],"id":52385890},{"atb":[[1.16,100],[1.02,11.7]],"id":52385892},{"atb":[[1.16,100],[1.02,11.7]],"id":52385904},{"atb":[[1.01,23.41],[1.16,100]],"id":52385898},{"atb":[[1.01,23.41],[1.16,100]],"id":52385900},{"atb":[[1.16,100],[1.02,11.7]],"id":52385911},{"atb":[[1.16,100],[1.03,7.8]],"id":52385913},{"atb":[[1.16,100],[1.03,7.8]],"id":52385907},{"atb":[[1.16,100],[1.03,7.8]],"id":52385886},{"atb":[[1.16,100],[1.02,11.7]],"id":52385919},{"atb":[[1.16,100],[1.03,7.8]],"id":52385921},{"atb":[[1.16,100],[1.02,11.7]],"id":52385882},{"atb":[[1.16,100],[1.02,11.7]],"id":52385884},{"atb":[[1.16,100],[1.03,7.8]],"id":52385917},{"atb":[[1.16,100],[1.02,11.7]],"id":52385897},{"atb":[[1.16,100],[1.03,7.8]],"id":52385891},{"atb":[[1.16,100],[1.03,7.8]],"id":52385893},{"atb":[[1.01,23.41],[1.16,100]],"id":52385903},{"atb":[[1.01,23.41],[1.16,100]],"id":52385905},{"atb":[[1.16,100],[1.03,7.8]],"id":52385899}],"con":true,"img":true}]}
{"op":"mcm","clk":"11550017461","pt":1719493682608,"mc":[{"id":"1.230178176","marketDefinition":{"bspMarket":false,"turnInPlayEnabled":false,"persistenceEnabled":false,"marketBaseRate":5.0,"eventId":"33376048","eventTypeId":"4339","numberOfWinners":1,"bettingType":"ODDS","marketType":"FORECAST","marketTime":"2024-06-27T16:37:00.000Z","suspendTime":"2024-06-27T16:37:00.000Z","bspReconciled":false,"complete":true,"inPlay":false,"crossMatching":false,"runnersVoidable":false,"numberOfActiveRunners":30,"betDelay":0,"status":"OPEN","runners":[{"status":"ACTIVE","sortPriority":1,"id":52385882,"name":"1 - 2"},{"status":"ACTIVE","sortPriority":2,"id":52385883,"name":"1 - 3"},{"status":"ACTIVE","sortPriority":3,"id":52385884,"name":"1 - 4"},{"status":"ACTIVE","sortPriority":4,"id":52385885,"name":"1 - 5"},{"status":"ACTIVE","sortPriority":5,"id":52385886,"name":"1 - 6"},{"status":"ACTIVE","sortPriority":6,"id":52385889,"name":"2 - 1"},{"status":"ACTIVE","sortPriority":7,"id":52385890,"name":"2 - 3"},{"status":"ACTIVE","sortPriority":8,"id":52385891,"name":"2 - 4"},{"status":"ACTIVE","sortPriority":9,"id":52385892,"name":"2 - 5"},{"status":"ACTIVE","sortPriority":10,"id":52385893,"name":"2 - 6"},{"status":"ACTIVE","sortPriority":11,"id":52385896,"name":"3 - 1"},{"status":"ACTIVE","sortPriority":12,"id":52385897,"name":"3 - 2"},{"status":"ACTIVE","sortPriority":13,"id":52385898,"name":"3 - 4"},{"status":"ACTIVE","sortPriority":14,"id":52385899,"name":"3 - 5"},{"status":"ACTIVE","sortPriority":15,"id":52385900,"name":"3 - 6"},{"status":"ACTIVE","sortPriority":16,"id":52385903,"name":"4 - 1"},{"status":"ACTIVE","sortPriority":17,"id":52385904,"name":"4 - 2"},{"status":"ACTIVE","sortPriority":18,"id":52385905,"name":"4 - 3"},{"status":"ACTIVE","sortPriority":19,"id":52385906,"name":"4 - 5"},{"status":"ACTIVE","sortPriority":20,"id":52385907,"name":"4 - 6"},{"status":"ACTIVE","sortPriority":21,"id":52385910,"name":"5 - 1"},{"status":"ACTIVE","sortPriority":22,"id":52385911,"name":"5 - 2"},{"status":"ACTIVE","sortPriority":23,"id":52385912,"name":"5 - 3"},{"status":"ACTIVE","sortPriority":24,"id":52385913,"name":"5 - 4"},{"status":"ACTIVE","sortPriority":25,"id":52385914,"name":"5 - 6"},{"status":"ACTIVE","sortPriority":26,"id":52385917,"name":"6 - 1"},{"status":"ACTIVE","sortPriority":27,"id":52385918,"name":"6 - 2"},{"status":"ACTIVE","sortPriority":28,"id":52385919,"name":"6 - 3"},{"status":"ACTIVE","sortPriority":29,"id":52385920,"name":"6 - 4"},{"status":"ACTIVE","sortPriority":30,"id":52385921,"name":"6 - 5"}],"regulators":["MR_INT"],"venue":"Perry Barr","countryCode":"GB","discountAllowed":true,"timezone":"Europe/London","openDate":"2024-06-27T13:29:00.000Z","version":5994794126,"name":"Forecast","eventName":"Perry Barr (F/C) 27th Jun"},"rc":[{"atb":[[1.16,100],[1.03,7.81]],"id":52385910},{"atb":[[1.16,100],[1.03,7.81]],"id":52385912},{"atb":[[1.16,100],[1.03,7.81]],"id":52385906},{"atb":[[1.01,23.44],[1.16,100]],"id":52385918},{"atb":[[1.16,100],[1.02,11.72]],"id":52385920},{"atb":[[1.16,100],[1.03,7.81]],"id":52385889},{"atb":[[1.16,100],[1.02,11.72]],"id":52385914},{"atb":[[1.01,23.44],[1.16,100]],"id":52385883},{"atb":[[1.16,100],[1.03,7.81]],"id":52385885},{"atb":[[1.16,100],[1.03,7.81]],"id":52385896},{"atb":[[1.16,100],[1.02,11.72]],"id":52385890},{"atb":[[1.16,100],[1.02,11.72]],"id":52385892},{"atb":[[1.16,100],[1.02,11.72]],"id":52385904},{"atb":[[1.01,23.44],[1.16,100]],"id":52385898},{"atb":[[1.01,23.44],[1.16,100]],"id":52385900},{"atb":[[1.16,100],[1.02,11.72]],"id":52385911},{"atb":[[1.16,100],[1.03,7.81]],"id":52385913},{"atb":[[1.16,100],[1.03,7.81]],"id":52385907},{"atb":[[1.16,100],[1.03,7.81]],"id":52385886},{"atb":[[1.16,100],[1.02,11.72]],"id":52385919},{"atb":[[1.16,100],[1.03,7.81]],"id":52385921},{"atb":[[1.16,100],[1.02,11.72]],"id":52385882},{"atb":[[1.16,100],[1.02,11.72]],"id":52385884},{"atb":[[1.16,100],[1.03,7.81]],"id":52385917},{"atb":[[1.16,100],[1.02,11.72]],"id":52385897},{"atb":[[1.16,100],[1.03,7.81]],"id":52385891},{"atb":[[1.16,100],[1.03,7.81]],"id":52385893},{"atb":[[1.01,23.44],[1.16,100]],"id":52385903},{"atb":[[1.01,23.44],[1.16,100]],"id":52385905},{"atb":[[1.16,100],[1.03,7.81]],"id":52385899}],"con":true,"img":true}]}
{"op":"mcm","clk":"11550210035","pt":1719495641803,"mc":[{"id":"1.230178176","rc":[{"atb":[[1.03,7.81]],"id":52385910},{"atb":[[1.03,7.81]],"id":52385912},{"atb":[[1.03,7.81]],"id":52385906},{"atb":[[1.01,23.44]],"id":52385918},{"atb":[[1.02,11.72]],"id":52385920},{"atb":[[1.03,7.81]],"id":52385889},{"atb":[[1.02,11.72]],"id":52385914},{"atb":[[1.01,329.56]],"id":52385883},{"atb":[[1.03,7.81]],"id":52385885},{"atb":[[1.03,7.81]],"id":52385896},{"atb":[[1.02,11.72]],"id":52385890},{"atb":[[1.02,11.72]],"id":52385892},{"atb":[[1.02,11.72]],"id":52385904},{"atb":[[1.01,23.44]],"id":52385898},{"atb":[[1.01,23.44]],"id":52385900},{"atb":[[1.02,11.72]],"id":52385911},{"atb":[[1.03,7.81]],"id":52385913},{"atb":[[1.03,7.81]],"id":52385907},{"atb":[[1.03,7.81]],"id":52385886},{"atb":[[1.02,11.72]],"id":52385919},{"atb":[[1.03,7.81]],"id":52385921},{"atb":[[1.02,11.72]],"id":52385882},{"atb":[[1.02,11.72]],"id":52385884},{"atb":[[1.03,7.81]],"id":52385917},{"atb":[[1.02,11.72]],"id":52385897},{"atb":[[1.03,7.81]],"id":52385891},{"atb":[[1.03,7.81]],"id":52385893},{"atb":[[1.01,23.44]],"id":52385903},{"atb":[[1.01,23.44]],"id":52385905},{"atb":[[1.03,7.81]],"id":52385899}],"con":true,"img":false}]}
{"op":"mcm","clk":"11550210046","pt":1719495641913,"mc":[{"id":"1.230178176","rc":[{"atb":[[1.01,306.12]],"id":52385885},{"atb":[[1.01,306.12]],"id":52385886},{"atb":[[1.01,306.12]],"id":52385882},{"atb":[[1.01,306.12]],"id":52385884}],"con":true,"img":false}]}
{"op":"mcm","clk":"11550210057","pt":1719495642015,"mc":[{"id":"1.230178176","rc":[{"atb":[[1.01,306.12]],"id":52385889}],"con":true,"img":false}]}
{"op":"mcm","clk":"11550210077","pt":1719495642220,"mc":[{"id":"1.230178176","rc":[{"atb":[[1.01,306.12]],"id":52385890},{"atb":[[1.01,306.12]],"id":52385892},{"atb":[[1.01,306.12]],"id":52385891},{"atb":[[1.01,306.12]],"id":52385893}],"con":true,"img":false}]}
{"op":"mcm","clk":"11550210089","pt":1719495642330,"mc":[{"id":"1.230178176","rc":[{"atb":[[1.01,306.12]],"id":52385896}],"con":true,"img":false}]}
{"op":"mcm","clk":"11550210100","pt":1719495642431,"mc":[{"id":"1.230178176","rc":[{"atb":[[1.01,329.56]],"id":52385898},{"atb":[[1.01,306.12]],"id":52385897},{"atb":[[1.01,306.12]],"id":52385899}],"con":true,"img":false}]}
{"op":"mcm","clk":"11550210107","pt":1719495642523,"mc":[{"id":"1.230178176","rc":[{"atb":[[1.01,329.56]],"id":52385900}],"con":true,"img":false}]}
{"op":"mcm","clk":"11550210117","pt":1719495642627,"mc":[{"id":"1.230178176","rc":[{"atb":[[1.01,329.56]],"id":52385903}],"con":true,"img":false}]}
{"op":"mcm","clk":"11550210125","pt":1719495642729,"mc":[{"id":"1.230178176","rc":[{"atb":[[1.01,306.12]],"id":52385906},{"atb":[[1.01,306.12]],"id":52385904},{"atb":[[1.01,329.56]],"id":52385905}],"con":true,"img":false}]}
{"op":"mcm","clk":"11550210134","pt":1719495642831,"mc":[{"id":"1.230178176","rc":[{"atb":[[1.01,306.12]],"id":52385910},{"atb":[[1.01,306.12]],"id":52385907}],"con":true,"img":false}]}
{"op":"mcm","clk":"11550210144","pt":1719495642935,"mc":[{"id":"1.230178176","rc":[{"atb":[[1.01,306.12]],"id":52385912},{"atb":[[1.01,306.12]],"id":52385911}],"con":true,"img":false}]}
{"op":"mcm","clk":"11550210156","pt":1719495643040,"mc":[{"id":"1.230178176","rc":[{"atb":[[1.01,306.12]],"id":52385914},{"atb":[[1.01,306.12]],"id":52385913},{"atb":[[1.01,306.12]],"id":52385917}],"con":true,"img":false}]}
{"op":"mcm","clk":"11550210168","pt":1719495643112,"mc":[{"id":"1.230178176","rc":[{"atb":[[1.01,329.56]],"id":52385918},{"atb":[[1.01,306.12]],"id":52385919}],"con":true,"img":false}]}
{"op":"mcm","clk":"11550210179","pt":1719495643205,"mc":[{"id":"1.230178176","rc":[{"atb":[[1.01,306.12]],"id":52385920},{"atb":[[1.01,306.12]],"id":52385921}],"con":true,"img":false}]}
{"op":"mcm","clk":"11550210335","pt":1719495644617,"mc":[{"id":"1.230178176","rc":[{"atb":[[1.17,120.05]],"id":52385882}],"con":true,"img":false}]}
{"op":"mcm","clk":"11550210348","pt":1719495644715,"mc":[{"id":"1.230178176","rc":[{"atb":[[1.17,120.05]],"id":52385889},{"atb":[[1.17,120.05]],"id":52385883},{"atb":[[1.17,120.05]],"id":52385885},{"atb":[[1.17,120.05]],"id":52385886},{"atb":[[1.17,120.05]],"id":52385884}],"con":true,"img":false}]}
{"op":"mcm","clk":"11550210357","pt":1719495644831,"mc":[{"id":"1.230178176","rc":[{"atb":[[1.17,120.05]],"id":52385890}],"con":true,"img":false}]}
{"op":"mcm","clk":"11550210365","pt":1719495644923,"mc":[{"id":"1.230178176","rc":[{"atb":[[1.17,120.05]],"id":52385891},{"atb":[[1.17,120.05]],"id":52385893}],"con":true,"img":false}]}
{"op":"mcm","clk":"11550210375","pt":1719495645019,"mc":[{"id":"1.230178176","rc":[{"atb":[[1.17,120.05]],"id":52385896},{"atb":[[1.17,120.05]],"id":52385892},{"atb":[[1.17,120.05]],"id":52385897}],"con":true,"img":false}]}
{"op":"mcm","clk":"11550210387","pt":1719495645123,"mc":[{"id":"1.230178176","rc":[{"atb":[[1.17,120.05]],"id":52385898},{"atb":[[1.17,120.05]],"id":52385900},{"atb":[[1.17,120.05]],"id":52385899}],"con":true,"img":false}]}
{"op":"mcm","clk":"11550210397","pt":1719495645227,"mc":[{"id":"1.230178176","rc":[{"atb":[[1.17,120.05]],"id":52385904},{"atb":[[1.17,120.05]],"id":52385903},{"atb":[[1.17,120.05]],"id":52385905}],"con":true,"img":false}]}
{"op":"mcm","clk":"11550210411","pt":1719495645338,"mc":[{"id":"1.230178176","rc":[{"atb":[[1.17,120.05]],"id":52385906},{"atb":[[1.17,120.05]],"id":52385907}],"con":true,"img":false}]}
{"op":"mcm","clk":"11550210418","pt":1719495645425,"mc":[{"id":"1.230178176","rc":[{"atb":[[1.17,120.05]],"id":52385910}],"con":true,"img":false}]}
{"op":"mcm","clk":"11550210431","pt":1719495645529,"mc":[{"id":"1.230178176","rc":[{"atb":[[1.17,120.05]],"id":52385912},{"atb":[[1.17,120.05]],"id":52385914},{"atb":[[1.17,120.05]],"id":52385911},{"atb":[[1.17,120.05]],"id":52385913}],"con":true,"img":false}]}
{"op":"mcm","clk":"11550210441","pt":1719495645634,"mc":[{"id":"1.230178176","rc":[{"atb":[[1.17,120.05]],"id":52385917}],"con":true,"img":false}]}
{"op":"mcm","clk":"11550210451","pt":1719495645737,"mc":[{"id":"1.230178176","rc":[{"atb":[[1.17,120.05]],"id":52385919}],"con":true,"img":false}]}
{"op":"mcm","clk":"11550210461","pt":1719495645844,"mc":[{"id":"1.230178176","rc":[{"atb":[[1.17,120.05]],"id":52385918},{"atb":[[1.17,120.05]],"id":52385920},{"atb":[[1.17,120.05]],"id":52385921}],"con":true,"img":false}]}
{"op":"mcm","clk":"11550388704","pt":1719497830798,"mc":[{"id":"1.230178176","rc":[{"atb":[[1.16,0],[1.03,7.81]],"id":52385910},{"atb":[[1.16,0],[1.03,7.81]],"id":52385912},{"atb":[[1.16,0],[1.03,7.81]],"id":52385906},{"atb":[[1.01,329.55],[1.16,0]],"id":52385918},{"atb":[[1.16,0],[1.02,11.71]],"id":52385920},{"atb":[[1.16,0],[1.03,7.81]],"id":52385889},{"atb":[[1.16,0],[1.02,11.71]],"id":52385914},{"atb":[[1.01,329.55],[1.16,0]],"id":52385883},{"atb":[[1.16,0],[1.03,7.81]],"id":52385885},{"atb":[[1.16,0],[1.03,7.81]],"id":52385896},{"atb":[[1.16,0],[1.02,11.71]],"id":52385890},{"atb":[[1.16,0],[1.02,11.71]],"id":52385892},{"atb":[[1.16,0],[1.02,11.71]],"id":52385904},{"atb":[[1.01,329.55],[1.16,0]],"id":52385898},{"atb":[[1.01,329.55],[1.16,0]],"id":52385900},{"atb":[[1.16,0],[1.02,11.71]],"id":52385911},{"atb":[[1.16,0],[1.03,7.81]],"id":52385913},{"atb":[[1.16,0],[1.03,7.81]],"id":52385907},{"atb":[[1.16,0],[1.03,7.81]],"id":52385886},{"atb":[[1.16,0],[1.02,11.71]],"id":52385919},{"atb":[[1.16,0],[1.03,7.81]],"id":52385921},{"atb":[[1.16,0],[1.02,11.71]],"id":52385882},{"atb":[[1.16,0],[1.02,11.71]],"id":52385884},{"atb":[[1.16,0],[1.03,7.81]],"id":52385917},{"atb":[[1.16,0],[1.02,11.71]],"id":52385897},{"atb":[[1.16,0],[1.03,7.81]],"id":52385891},{"atb":[[1.16,0],[1.03,7.81]],"id":52385893},{"atb":[[1.01,329.55],[1.16,0]],"id":52385903},{"atb":[[1.01,329.55],[1.16,0]],"id":52385905},{"atb":[[1.16,0],[1.03,7.81]],"id":52385899}],"con":true,"img":false}]}
{"op":"mcm","clk":"11550389133","pt":1719497835612,"mc":[{"id":"1.230178176","rc":[{"atb":[[1.18,150]],"id":52385910},{"atb":[[1.18,150]],"id":52385912},{"atb":[[1.18,150]],"id":52385906},{"atb":[[1.18,150]],"id":52385918},{"atb":[[1.18,150]],"id":52385920},{"atb":[[1.18,150]],"id":52385889},{"atb":[[1.18,150]],"id":52385914},{"atb":[[1.18,150]],"id":52385883},{"atb":[[1.18,150]],"id":52385885},{"atb":[[1.18,150]],"id":52385896},{"atb":[[1.18,150]],"id":52385890},{"atb":[[1.18,150]],"id":52385892},{"atb":[[1.18,150]],"id":52385904},{"atb":[[1.18,150]],"id":52385898},{"atb":[[1.18,150]],"id":52385900},{"atb":[[1.18,150]],"id":52385911},{"atb":[[1.18,150]],"id":52385913},{"atb":[[1.18,150]],"id":52385907},{"atb":[[1.18,150]],"id":52385886},{"atb":[[1.18,150]],"id":52385919},{"atb":[[1.18,150]],"id":52385921},{"atb":[[1.18,150]],"id":52385882},{"atb":[[1.18,150]],"id":52385884},{"atb":[[1.18,150]],"id":52385917},{"atb":[[1.18,150]],"id":52385897},{"atb":[[1.18,150]],"id":52385891},{"atb":[[1.18,150]],"id":52385893},{"atb":[[1.18,150]],"id":52385903},{"atb":[[1.18,150]],"id":52385905},{"atb":[[1.18,150]],"id":52385899}],"con":true,"img":false}]}
{"op":"mcm","clk":"11550407694","pt":1719498062992,"mc":[{"id":"1.230178176","rc":[{"atb":[[1.17,0]],"id":52385882}],"con":true,"img":false}]}
{"op":"mcm","clk":"11550427310","pt":1719498312960,"mc":[{"id":"1.230178176","rc":[{"atb":[[1.17,0]],"id":52385889}],"con":true,"img":false}]}
{"op":"mcm","clk":"11550446241","pt":1719498563220,"mc":[{"id":"1.230178176","rc":[{"atb":[[1.17,0]],"id":52385884}],"con":true,"img":false}]}
{"op":"mcm","clk":"11550464611","pt":1719498803293,"mc":[{"id":"1.230178176","rc":[{"atb":[[1.17,0]],"id":52385886}],"con":true,"img":false}]}
{"op":"mcm","clk":"11550483644","pt":1719499023336,"mc":[{"id":"1.230178176","rc":[{"atb":[[1.17,0]],"id":52385885}],"con":true,"img":false}]}
{"op":"mcm","clk":"11550506538","pt":1719499243492,"mc":[{"id":"1.230178176","rc":[{"atb":[[1.17,0]],"id":52385883}],"con":true,"img":false}]}
{"op":"mcm","clk":"11550523701","pt":1719499473658,"mc":[{"id":"1.230178176","rc":[{"atb":[[1.17,0]],"id":52385890}],"con":true,"img":false}]}
{"op":"mcm","clk":"11550540591","pt":1719499703638,"mc":[{"id":"1.230178176","rc":[{"atb":[[1.17,0]],"id":52385893}],"con":true,"img":false}]}
{"op":"mcm","clk":"11550556248","pt":1719499933720,"mc":[{"id":"1.230178176","rc":[{"atb":[[1.17,0]],"id":52385891}],"con":true,"img":false}]}
{"op":"mcm","clk":"11550570562","pt":1719500153751,"mc":[{"id":"1.230178176","rc":[{"atb":[[1.17,0]],"id":52385897}],"con":true,"img":false}]}
{"op":"mcm","clk":"11550588743","pt":1719500403977,"mc":[{"id":"1.230178176","rc":[{"atb":[[1.17,0]],"id":52385896}],"con":true,"img":false}]}
{"op":"mcm","clk":"11550606256","pt":1719500654262,"mc":[{"id":"1.230178176","rc":[{"atb":[[1.03,7.81]],"id":52385910},{"atb":[[1.03,7.81]],"id":52385912},{"atb":[[1.03,7.81]],"id":52385906},{"atb":[[1.01,329.55]],"id":52385918},{"atb":[[1.02,11.71]],"id":52385920},{"atb":[[1.03,7.81]],"id":52385889},{"atb":[[1.02,11.71]],"id":52385914},{"atb":[[1.01,329.55]],"id":52385883},{"atb":[[1.03,7.81]],"id":52385885},{"atb":[[1.03,7.81]],"id":52385896},{"atb":[[1.02,11.71]],"id":52385890},{"atb":[[1.02,11.71],[1.17,0]],"id":52385892},{"atb":[[1.02,11.71]],"id":52385904},{"atb":[[1.01,329.55]],"id":52385898},{"atb":[[1.01,329.55]],"id":52385900},{"atb":[[1.02,11.71]],"id":52385911},{"atb":[[1.03,7.81]],"id":52385913},{"atb":[[1.03,7.81]],"id":52385907},{"atb":[[1.03,7.81]],"id":52385886},{"atb":[[1.02,11.71]],"id":52385919},{"atb":[[1.03,7.81]],"id":52385921},{"atb":[[1.02,11.71]],"id":52385882},{"atb":[[1.02,11.71]],"id":52385884},{"atb":[[1.03,7.81]],"id":52385917},{"atb":[[1.02,11.71]],"id":52385897},{"atb":[[1.03,7.81]],"id":52385891},{"atb":[[1.03,7.81]],"id":52385893},{"atb":[[1.01,329.55]],"id":52385903},{"atb":[[1.01,329.55]],"id":52385905},{"atb":[[1.03,7.81]],"id":52385899}],"con":true,"img":false}]}
{"op":"mcm","clk":"11550620270","pt":1719500885112,"mc":[{"id":"1.230178176","rc":[{"atb":[[1.03,8.81]],"id":52385910},{"atb":[[1.03,8.81]],"id":52385912},{"atb":[[1.03,8.81]],"id":52385906},{"atb":[[1.03,1]],"id":52385918},{"atb":[[1.03,1]],"id":52385920},{"atb":[[1.03,8.81]],"id":52385889},{"atb":[[1.03,1]],"id":52385914},{"atb":[[1.03,1]],"id":52385883},{"atb":[[1.03,8.81]],"id":52385885},{"atb":[[1.03,8.81]],"id":52385896},{"atb":[[1.03,1]],"id":52385890},{"atb":[[1.03,1]],"id":52385892},{"atb":[[1.03,1]],"id":52385904},{"atb":[[1.03,1]],"id":52385898},{"atb":[[1.03,1]],"id":52385900},{"atb":[[1.03,1]],"id":52385911},{"atb":[[1.03,8.81]],"id":52385913},{"atb":[[1.03,8.81]],"id":52385907},{"atb":[[1.03,8.81]],"id":52385886},{"atb":[[1.03,1]],"id":52385919},{"atb":[[1.03,8.81]],"id":52385921},{"atb":[[1.03,1]],"id":52385882},{"atb":[[1.03,1]],"id":52385884},{"atb":[[1.03,8.81]],"id":52385917},{"atb":[[1.03,1]],"id":52385897},{"atb":[[1.03,8.81]],"id":52385891},{"atb":[[1.03,8.81]],"id":52385893},{"atb":[[1.03,1]],"id":52385903},{"atb":[[1.03,1]],"id":52385905},{"atb":[[1.03,8.81]],"id":52385899}],"con":true,"img":false}]}
{"op":"mcm","clk":"11550620290","pt":1719500885421,"mc":[{"id":"1.230178176","rc":[{"atb":[[1.03,8.71]],"id":52385910},{"atb":[[1.03,8.71]],"id":52385912},{"atb":[[1.03,8.71]],"id":52385906},{"atb":[[1.03,0.9]],"id":52385918},{"atb":[[1.03,0.9]],"id":52385920},{"atb":[[1.03,8.71]],"id":52385889},{"atb":[[1.03,0.9]],"id":52385914},{"atb":[[1.03,0.9]],"id":52385883},{"atb":[[1.03,8.71]],"id":52385885},{"atb":[[1.03,8.71]],"id":52385896},{"atb":[[1.03,0.9]],"id":52385890},{"atb":[[1.03,0.9]],"id":52385892},{"atb":[[1.03,0.9]],"id":52385904},{"atb":[[1.03,0.9]],"id":52385898},{"atb":[[1.03,0.9]],"id":52385900},{"atb":[[1.03,0.9]],"id":52385911},{"atb":[[1.03,8.71]],"id":52385913},{"atb":[[1.03,8.71]],"id":52385907},{"atb":[[1.03,8.71]],"id":52385886},{"atb":[[1.03,0.9]],"id":52385919},{"atb":[[1.03,8.71]],"id":52385921},{"atb":[[1.03,0.9]],"id":52385882},{"atb":[[1.03,0.9]],"id":52385884},{"atb":[[1.03,8.71]],"id":52385917},{"atb":[[1.03,0.9]],"id":52385897},{"atb":[[1.03,8.71]],"id":52385891},{"atb":[[1.03,8.71]],"id":52385893},{"atb":[[1.03,0.9]],"id":52385903},{"atb":[[1.03,0.9]],"id":52385905},{"atb":[[1.03,8.71]],"id":52385899}],"con":true,"img":false}]}
{"op":"mcm","clk":"11550620304","pt":1719500885627,"mc":[{"id":"1.230178176","rc":[{"atb":[[1.03,7.81]],"id":52385910},{"atb":[[1.03,7.81]],"id":52385912},{"atb":[[1.03,7.81]],"id":52385906},{"atb":[[1.03,0]],"id":52385918},{"atb":[[1.03,0]],"id":52385920},{"atb":[[1.03,7.81]],"id":52385889},{"atb":[[1.03,0]],"id":52385914},{"atb":[[1.03,0]],"id":52385883},{"atb":[[1.03,7.81]],"id":52385885},{"atb":[[1.03,7.81]],"id":52385896},{"atb":[[1.03,0]],"id":52385890},{"atb":[[1.03,0]],"id":52385892},{"atb":[[1.03,0]],"id":52385904},{"atb":[[1.03,0]],"id":52385898},{"atb":[[1.03,0]],"id":52385900},{"atb":[[1.03,0]],"id":52385911},{"atb":[[1.03,7.81]],"id":52385913},{"atb":[[1.03,7.81]],"id":52385907},{"atb":[[1.03,7.81]],"id":52385886},{"atb":[[1.03,0]],"id":52385919},{"atb":[[1.03,7.81]],"id":52385921},{"atb":[[1.03,0]],"id":52385882},{"atb":[[1.03,0]],"id":52385884},{"atb":[[1.03,7.81]],"id":52385917},{"atb":[[1.03,0]],"id":52385897},{"atb":[[1.03,7.81]],"id":52385891},{"atb":[[1.03,7.81]],"id":52385893},{"atb":[[1.03,0]],"id":52385903},{"atb":[[1.03,0]],"id":52385905},{"atb":[[1.03,7.81]],"id":52385899}],"con":true,"img":false}]}
{"op":"mcm","clk":"11550620311","pt":1719500885685,"mc":[{"id":"1.230178176","rc":[{"atb":[[3.05,0.9]],"id":52385910},{"atb":[[3.05,0.9]],"id":52385912},{"atb":[[3.05,0.9]],"id":52385906},{"atb":[[3.05,0.9]],"id":52385918},{"atb":[[3.05,0.9]],"id":52385920},{"atb":[[3.05,0.9]],"id":52385889},{"atb":[[3.05,0.9]],"id":52385914},{"atb":[[3.05,0.9]],"id":52385883},{"atb":[[3.05,0.9]],"id":52385885},{"atb":[[3.05,0.9]],"id":52385896},{"atb":[[3.05,0.9]],"id":52385890},{"atb":[[3.05,0.9]],"id":52385892},{"atb":[[3.05,0.9]],"id":52385904},{"atb":[[3.05,0.9]],"id":52385898},{"atb":[[3.05,0.9]],"id":52385900},{"atb":[[3.05,0.9]],"id":52385911},{"atb":[[3.05,0.9]],"id":52385913},{"atb":[[3.05,0.9]],"id":52385907},{"atb":[[3.05,0.9]],"id":52385886},{"atb":[[3.05,0.9]],"id":52385919},{"atb":[[3.05,0.9]],"id":52385921},{"atb":[[3.05,0.9]],"id":52385882},{"atb":[[3.05,0.9]],"id":52385884},{"atb":[[3.05,0.9]],"id":52385917},{"atb":[[3.05,0.9]],"id":52385897},{"atb":[[3.05,0.9]],"id":52385891},{"atb":[[3.05,0.9]],"id":52385893},{"atb":[[3.05,0.9]],"id":52385903},{"atb":[[3.05,0.9]],"id":52385905},{"atb":[[3.05,0.9]],"id":52385899}],"con":true,"img":false}]}
{"op":"mcm","clk":"11550620832","pt":1719500893394,"mc":[{"id":"1.230178176","marketDefinition":{"bspMarket":false,"turnInPlayEnabled":false,"persistenceEnabled":false,"marketBaseRate":5.0,"eventId":"33376048","eventTypeId":"4339","numberOfWinners":1,"bettingType":"ODDS","marketType":"FORECAST","marketTime":"2024-06-27T16:37:00.000Z","suspendTime":"2024-06-27T16:37:00.000Z","bspReconciled":false,"complete":true,"inPlay":false,"crossMatching":true,"runnersVoidable":false,"numberOfActiveRunners":30,"betDelay":0,"status":"OPEN","runners":[{"status":"ACTIVE","sortPriority":1,"id":52385882,"name":"1 - 2"},{"status":"ACTIVE","sortPriority":2,"id":52385883,"name":"1 - 3"},{"status":"ACTIVE","sortPriority":3,"id":52385884,"name":"1 - 4"},{"status":"ACTIVE","sortPriority":4,"id":52385885,"name":"1 - 5"},{"status":"ACTIVE","sortPriority":5,"id":52385886,"name":"1 - 6"},{"status":"ACTIVE","sortPriority":6,"id":52385889,"name":"2 - 1"},{"status":"ACTIVE","sortPriority":7,"id":52385890,"name":"2 - 3"},{"status":"ACTIVE","sortPriority":8,"id":52385891,"name":"2 - 4"},{"status":"ACTIVE","sortPriority":9,"id":52385892,"name":"2 - 5"},{"status":"ACTIVE","sortPriority":10,"id":52385893,"name":"2 - 6"},{"status":"ACTIVE","sortPriority":11,"id":52385896,"name":"3 - 1"},{"status":"ACTIVE","sortPriority":12,"id":52385897,"name":"3 - 2"},{"status":"ACTIVE","sortPriority":13,"id":52385898,"name":"3 - 4"},{"status":"ACTIVE","sortPriority":14,"id":52385899,"name":"3 - 5"},{"status":"ACTIVE","sortPriority":15,"id":52385900,"name":"3 - 6"},{"status":"ACTIVE","sortPriority":16,"id":52385903,"name":"4 - 1"},{"status":"ACTIVE","sortPriority":17,"id":52385904,"name":"4 - 2"},{"status":"ACTIVE","sortPriority":18,"id":52385905,"name":"4 - 3"},{"status":"ACTIVE","sortPriority":19,"id":52385906,"name":"4 - 5"},{"status":"ACTIVE","sortPriority":20,"id":52385907,"name":"4 - 6"},{"status":"ACTIVE","sortPriority":21,"id":52385910,"name":"5 - 1"},{"status":"ACTIVE","sortPriority":22,"id":52385911,"name":"5 - 2"},{"status":"ACTIVE","sortPriority":23,"id":52385912,"name":"5 - 3"},{"status":"ACTIVE","sortPriority":24,"id":52385913,"name":"5 - 4"},{"status":"ACTIVE","sortPriority":25,"id":52385914,"name":"5 - 6"},{"status":"ACTIVE","sortPriority":26,"id":52385917,"name":"6 - 1"},{"status":"ACTIVE","sortPriority":27,"id":52385918,"name":"6 - 2"},{"status":"ACTIVE","sortPriority":28,"id":52385919,"name":"6 - 3"},{"status":"ACTIVE","sortPriority":29,"id":52385920,"name":"6 - 4"},{"status":"ACTIVE","sortPriority":30,"id":52385921,"name":"6 - 5"}],"regulators":["MR_INT"],"venue":"Perry Barr","countryCode":"GB","discountAllowed":true,"timezone":"Europe/London","openDate":"2024-06-27T13:29:00.000Z","version":5994794126,"name":"Forecast","eventName":"Perry Barr (F/C) 27th Jun"},"rc":[],"con":true,"img":false}]}
{"op":"mcm","clk":"11550621487","pt":1719500904334,"mc":[{"id":"1.230178176","rc":[{"atb":[[1.17,0]],"id":52385899}],"con":true,"img":false}]}
{"op":"mcm","clk":"11550636198","pt":1719501144495,"mc":[{"id":"1.230178176","rc":[{"atb":[[1.17,0]],"id":52385898}],"con":true,"img":false}]}
{"op":"mcm","clk":"11550655166","pt":1719501404507,"mc":[{"id":"1.230178176","rc":[{"atb":[[1.17,0]],"id":52385900}],"con":true,"img":false}]}
{"op":"mcm","clk":"11550672863","pt":1719501664723,"mc":[{"id":"1.230178176","rc":[{"atb":[[1.17,0]],"id":52385904}],"con":true,"img":false}]}
{"op":"mcm","clk":"11550688771","pt":1719501934783,"mc":[{"id":"1.230178176","rc":[{"atb":[[1.17,0]],"id":52385905}],"con":true,"img":false}]}
{"op":"mcm","clk":"11550704457","pt":1719502184870,"mc":[{"id":"1.230178176","rc":[{"atb":[[1.17,0]],"id":52385903}],"con":true,"img":false}]}
{"op":"mcm","clk":"11550724001","pt":1719502454956,"mc":[{"id":"1.230178176","rc":[{"atb":[[1.17,0]],"id":52385906}],"con":true,"img":false}]}
{"op":"mcm","clk":"11550741284","pt":1719502725086,"mc":[{"id":"1.230178176","rc":[{"atb":[[1.17,0]],"id":52385907}],"con":true,"img":false}]}
{"op":"mcm","clk":"11550756290","pt":1719502995167,"mc":[{"id":"1.230178176","rc":[{"atb":[[1.17,0]],"id":52385910}],"con":true,"img":false}]}
{"op":"mcm","clk":"11550770843","pt":1719503255233,"mc":[{"id":"1.230178176","rc":[{"atb":[[1.17,0]],"id":52385914}],"con":true,"img":false}]}
{"op":"mcm","clk":"11550788358","pt":1719503535365,"mc":[{"id":"1.230178176","rc":[{"atb":[[1.17,0]],"id":52385912}],"con":true,"img":false}]}
{"op":"mcm","clk":"11550802173","pt":1719503805417,"mc":[{"id":"1.230178176","rc":[{"atb":[[1.17,0]],"id":52385913}],"con":true,"img":false}]}
{"op":"mcm","clk":"11550816276","pt":1719504075593,"mc":[{"id":"1.230178176","rc":[{"atb":[[1.03,7.81]],"id":52385910},{"atb":[[1.03,7.81]],"id":52385912},{"atb":[[1.03,7.81]],"id":52385906},{"atb":[[1.01,329.54]],"id":52385918},{"atb":[[1.02,11.71]],"id":52385920},{"atb":[[1.03,7.81]],"id":52385889},{"atb":[[1.02,11.71]],"id":52385914},{"atb":[[1.01,329.54]],"id":52385883},{"atb":[[1.03,7.81]],"id":52385885},{"atb":[[1.03,7.81]],"id":52385896},{"atb":[[1.02,11.71]],"id":52385890},{"atb":[[1.02,11.71]],"id":52385892},{"atb":[[1.02,11.71]],"id":52385904},{"atb":[[1.01,329.54]],"id":52385898},{"atb":[[1.01,329.54]],"id":52385900},{"atb":[[1.02,11.71],[1.17,0]],"id":52385911},{"atb":[[1.03,7.81]],"id":52385913},{"atb":[[1.03,7.81]],"id":52385907},{"atb":[[1.03,7.81]],"id":52385886},{"atb":[[1.02,11.71]],"id":52385919},{"atb":[[1.03,7.81]],"id":52385921},{"atb":[[1.02,11.71]],"id":52385882},{"atb":[[1.02,11.71]],"id":52385884},{"atb":[[1.03,7.81]],"id":52385917},{"atb":[[1.02,11.71]],"id":52385897},{"atb":[[1.03,7.81]],"id":52385891},{"atb":[[1.03,7.81]],"id":52385893},{"atb":[[1.01,329.54]],"id":52385903},{"atb":[[1.01,329.54]],"id":52385905},{"atb":[[1.03,7.81]],"id":52385899}],"con":true,"img":false}]}
{"op":"mcm","clk":"11550830744","pt":1719504355781,"mc":[{"id":"1.230178176","rc":[{"atb":[[1.17,0]],"id":52385917}],"con":true,"img":false}]}
{"op":"mcm","clk":"11550843584","pt":1719504512851,"mc":[{"id":"1.230178176","rc":[{"atb":[[28,7.3]],"id":52385920},{"atb":[[29,9.22]],"id":52385883},{"atb":[[17.5,15.04]],"id":52385911}],"con":true,"img":false}]}
{"op":"mcm","clk":"11550843591","pt":1719504513056,"mc":[{"id":"1.230178176","rc":[{"atb":[[28,0]],"id":52385920},{"atb":[[29,0]],"id":52385883},{"atb":[[17.5,0]],"id":52385911}],"con":true,"img":false}]}
{"op":"mcm","clk":"11550846896","pt":1719504570040,"mc":[{"id":"1.230178176","rc":[{"atb":[[34,6.92]],"id":52385885},{"atb":[[27,8.06]],"id":52385921},{"atb":[[38,5.88]],"id":52385884},{"atb":[[29,9.4]],"id":52385903},{"atb":[[9.6,30.78]],"id":52385905}],"con":true,"img":false}]}
{"op":"mcm","clk":"11550846906","pt":1719504570240,"mc":[{"id":"1.230178176","rc":[{"atb":[[34,0]],"id":52385885},{"atb":[[27,0]],"id":52385921},{"atb":[[38,0]],"id":52385884},{"atb":[[29,0]],"id":52385903},{"atb":[[9.6,0]],"id":52385905}],"con":true,"img":false}]}
{"op":"mcm","clk":"11550848747","pt":1719504601089,"mc":[{"id":"1.230178176","rc":[{"atb":[[18.5,2.25]],"id":52385911}],"con":true,"img":false}]}
{"op":"mcm","clk":"11550848758","pt":1719504601193,"mc":[{"id":"1.230178176","rc":[{"atb":[[20,2.25]],"id":52385920},{"atb":[[27,2.25]],"id":52385883},{"atb":[[17.5,14.72]],"id":52385919}],"con":true,"img":false}]}
{"op":"mcm","clk":"11550848765","pt":1719504601295,"mc":[{"id":"1.230178176","rc":[{"atb":[[18.5,0]],"id":52385911}],"con":true,"img":false}]}
{"op":"mcm","clk":"11550848776","pt":1719504601401,"mc":[{"id":"1.230178176","rc":[{"atb":[[20,0]],"id":52385920},{"atb":[[27,0]],"id":52385883},{"atb":[[17.5,0]],"id":52385919}],"con":true,"img":false}]}
{"op":"mcm","clk":"11550850771","pt":1719504635936,"mc":[{"id":"1.230178176","rc":[{"atb":[[1.17,0]],"id":52385919}],"con":true,"img":false}]}
{"op":"mcm","clk":"11550854075","pt":1719504694118,"mc":[{"id":"1.230178176","rc":[{"atb":[[40,5.95]],"id":52385885}],"con":true,"img":false}]}
{"op":"mcm","clk":"11550854085","pt":1719504694325,"mc":[{"id":"1.230178176","rc":[{"atb":[[40,0]],"id":52385885}],"con":true,"img":false}]}
{"op":"mcm","clk":"11550866152","pt":1719504926109,"mc":[{"id":"1.230178176","rc":[{"atb":[[1.17,0]],"id":52385921}],"con":true,"img":false}]}
{"op":"mcm","clk":"11550872833","pt":1719505037866,"mc":[{"id":"1.230178176","rc":[{"atb":[[22,10.87]],"id":52385921},{"atb":[[9.8,25]],"id":52385905}],"con":true,"img":false}]}
{"op":"mcm","clk":"11550872845","pt":1719505038071,"mc":[{"id":"1.230178176","rc":[{"atb":[[22,0]],"id":52385921},{"atb":[[9.8,0]],"id":52385905}],"con":true,"img":false}]}
{"op":"mcm","clk":"11550873803","pt":1719505056086,"mc":[{"id":"1.230178176","rc":[{"atb":[[32,2.25]],"id":52385885}],"con":true,"img":false}]}
{"op":"mcm","clk":"11550873865","pt":1719505057003,"mc":[{"id":"1.230178176","rc":[{"atb":[[32,0]],"id":52385885}],"con":true,"img":false}]}
{"op":"mcm","clk":"11550875495","pt":1719505083702,"mc":[{"id":"1.230178176","rc":[{"atb":[[14,7]],"id":52385910},{"atb":[[11,9]],"id":52385912},{"atb":[[13,8]],"id":52385906},{"atb":[[16,6]],"id":52385918},{"atb":[[16,6]],"id":52385920},{"atb":[[13,8]],"id":52385889},{"atb":[[10,10]],"id":52385914},{"atb":[[16,6]],"id":52385883},{"atb":[[20,5]],"id":52385885},{"atb":[[10,10]],"id":52385896},{"atb":[[14,7]],"id":52385890},{"atb":[[15,6]],"id":52385892},{"atb":[[15,6]],"id":52385904},{"atb":[[9,11]],"id":52385898},{"atb":[[9,11]],"id":52385900},{"atb":[[14,7]],"id":52385911},{"atb":[[12,8]],"id":52385913},{"atb":[[16,6]],"id":52385907},{"atb":[[20,5]],"id":52385886},{"atb":[[14,7]],"id":52385919},{"atb":[[12,8]],"id":52385921},{"atb":[[15,6]],"id":52385882},{"atb":[[20,5]],"id":52385884},{"atb":[[18,5]],"id":52385917},{"atb":[[9,11]],"id":52385897},{"atb":[[16,6]],"id":52385891},{"atb":[[17,6]],"id":52385893},{"atb":[[16,6]],"id":52385903},{"atb":[[12,8]],"id":52385905},{"atb":[[9,11]],"id":52385899}],"con":true,"img":false}]}
{"op":"mcm","clk":"11550876157","pt":1719505095590,"mc":[{"id":"1.230178176","rc":[{"atb":[[13,0]],"id":52385906},{"atb":[[16,0]],"id":52385920},{"atb":[[15,0]],"id":52385904},{"atb":[[9,0]],"id":52385898},{"atb":[[12,0]],"id":52385913},{"atb":[[16,0]],"id":52385907},{"atb":[[20,0]],"id":52385884},{"atb":[[16,0]],"id":52385891},{"atb":[[16,0]],"id":52385903},{"atb":[[12,0]],"id":52385905}],"con":true,"img":false}]}
{"op":"mcm","clk":"11550876162","pt":1719505095691,"mc":[{"id":"1.230178176","rc":[{"atb":[[8,8]],"id":52385906},{"atb":[[12,6]],"id":52385920},{"atb":[[9,6]],"id":52385904},{"atb":[[7,11]],"id":52385898},{"atb":[[9,8]],"id":52385913},{"atb":[[9,6]],"id":52385907},{"atb":[[17,5]],"id":52385884},{"atb":[[12,6]],"id":52385891},{"atb":[[9,6]],"id":52385903},{"atb":[[7,8]],"id":52385905}],"con":true,"img":false}]}
{"op":"mcm","clk":"11550877233","pt":1719505116467,"mc":[{"id":"1.230178176","rc":[{"atb":[[9.6,20]],"id":52385906},{"atb":[[29,8.05]],"id":52385885},{"atb":[[17.5,14.39]],"id":52385911},{"atb":[[18.5,13.64]],"id":52385921},{"atb":[[34,6.56]],"id":52385884},{"atb":[[9.2,20]],"id":52385905}],"con":true,"img":false}]}
{"op":"mcm","clk":"11550877266","pt":1719505117239,"mc":[{"id":"1.230178176","rc":[{"atb":[[9.6,0]],"id":52385906},{"atb":[[29,0]],"id":52385885},{"atb":[[17.5,0]],"id":52385911},{"atb":[[18.5,0]],"id":52385921},{"atb":[[34,0]],"id":52385884},{"atb":[[9.2,0]],"id":52385905}],"con":true,"img":false}]}
{"op":"mcm","clk":"11550878633","pt":1719505142895,"mc":[{"id":"1.230178176","rc":[{"atb":[[21,11.62]],"id":52385920},{"atb":[[28,8.09]],"id":52385883}],"con":true,"img":false}]}
{"op":"mcm","clk":"11550878638","pt":1719505143001,"mc":[{"id":"1.230178176","rc":[{"atb":[[18,13.94]],"id":52385919}],"con":true,"img":false}]}
{"op":"mcm","clk":"11550878671","pt":1719505143671,"mc":[{"id":"1.230178176","rc":[{"atb":[[12,0]],"id":52385920}],"con":true,"img":false}]}
{"op":"mcm","clk":"11550878676","pt":1719505143773,"mc":[{"id":"1.230178176","rc":[{"atb":[[14,6]],"id":52385920}],"con":true,"img":false}]}
{"op":"mcm","clk":"11550878762","pt":1719505145603,"mc":[{"id":"1.230178176","rc":[{"atb":[[21,0]],"id":52385920},{"atb":[[28,0]],"id":52385883},{"atb":[[18,0]],"id":52385919}],"con":true,"img":false}]}
{"op":"mcm","clk":"11550882173","pt":1719505206150,"mc":[{"id":"1.230178176","rc":[{"atb":[[1.17,0]],"id":52385920}],"con":true,"img":false}]}
{"op":"mcm","clk":"11550886820","pt":1719505300589,"mc":[{"id":"1.230178176","rc":[{"atb":[[10,20]],"id":52385906},{"atb":[[23,9.79]],"id":52385920},{"atb":[[29,8.07]],"id":52385883},{"atb":[[32,7]],"id":52385885},{"atb":[[16.5,14.09]],"id":52385911},{"atb":[[25,7.9]],"id":52385921},{"atb":[[36,6.76]],"id":52385884}],"con":true,"img":false}]}
{"op":"mcm","clk":"11550886829","pt":1719505300682,"mc":[{"id":"1.230178176","rc":[{"atb":[[23,0]],"id":52385920},{"atb":[[32,0]],"id":52385885},{"atb":[[16.5,0]],"id":52385911},{"atb":[[19.5,13.28]],"id":52385919},{"atb":[[25,0]],"id":52385921},{"atb":[[36,0]],"id":52385884},{"atb":[[9.6,20]],"id":52385905}],"con":true,"img":false}]}
{"op":"mcm","clk":"11550886833","pt":1719505300792,"mc":[{"id":"1.230178176","rc":[{"atb":[[10,0]],"id":52385906},{"atb":[[29,0]],"id":52385883}],"con":true,"img":false}]}
{"op":"mcm","clk":"11550886842","pt":1719505300889,"mc":[{"id":"1.230178176","rc":[{"atb":[[19.5,0]],"id":52385919},{"atb":[[9.6,0]],"id":52385905}],"con":true,"img":false}]}
{"op":"mcm","clk":"11550887848","pt":1719505320201,"mc":[{"id":"1.230178176","rc":[{"atb":[[4.8,18]],"id":52385912},{"atl":[[410,2]],"id":52385912},{"atb":[[13.5,8]],"id":52385889},{"atl":[[930,2]],"id":52385889},{"atb":[[4.5,22]],"id":52385899},{"atl":[[370,2]],"id":52385899}],"con":true,"img":false}]}
{"op":"mcm","clk":"11550887856","pt":1719505320306,"mc":[{"id":"1.230178176","rc":[{"atb":[[9,12.5]],"id":52385910},{"atl":[[620,2]],"id":52385910},{"atb":[[4.8,16]],"id":52385906},{"atl":[[410,2]],"id":52385906},{"atb":[[16.5,6]],"id":52385918},{"atl":[[870,2]],"id":52385918},{"atb":[[8.4,12]],"id":52385920},{"atl":[[580,2]],"id":52385920},{"atb":[[5,20]],"id":52385914},{"atl":[[430,2]],"id":52385914},{"atb":[[16.5,6]],"id":52385883},{"atl":[[870,2]],"id":52385883},{"atb":[[16.5,6.45]],"id":52385885},{"atl":[[870,2]],"id":52385885},{"atb":[[8.4,13.51]],"id":52385896},{"atl":[[580,2]],"id":52385896},{"atb":[[8.8,12.82]],"id":52385890},{"atl":[[600,2]],"id":52385890},{"atb":[[8.8,12]],"id":52385892},{"atl":[[600,2]],"id":52385892},{"atb":[[7.6,12]],"id":52385904},{"atl":[[550,2]],"id":52385904},{"atb":[[4.3,30.3]],"id":52385898},{"atl":[[340,2]],"id":52385898},{"atb":[[5.1,24.39]],"id":52385900},{"atl":[[460,2]],"id":52385900},{"atb":[[6.8,14]],"id":52385911},{"atl":[[530,2]],"id":52385911},{"atb":[[4.3,16]],"id":52385913},{"atl":[[340,2]],"id":52385913},{"atb":[[5.6,12]],"id":52385907},{"atl":[[490,2]],"id":52385907},{"atb":[[21,5]],"id":52385886},{"atl":[[990,2]],"id":52385886},{"atb":[[9.4,11.9]],"id":52385919},{"atl":[[650,2]],"id":52385919},{"atb":[[8.4,13.51]],"id":52385921},{"atl":[[580,2]],"id":52385921},{"atb":[[15.5,6]],"id":52385882},{"atl":[[1000,2]],"id":52385882},{"atb":[[14,7.69]],"id":52385884},{"atl":[[830,2]],"id":52385884},{"atb":[[18.5,5]],"id":52385917},{"atl":[[1000,2]],"id":52385917},{"atb":[[6.2,19.23]],"id":52385897},{"atl":[[510,2]],"id":52385897},{"atb":[[8.4,12]],"id":52385891},{"atl":[[570,2]],"id":52385891},{"atb":[[10,11.11]],"id":52385893},{"atl":[[730,2]],"id":52385893},{"atb":[[9.2,6]],"id":52385903},{"atl":[[650,2]],"id":52385903},{"atb":[[5,25]],"id":52385905},{"atl":[[440,2]],"id":52385905}],"con":true,"img":false}]}
{"op":"mcm","clk":"11550887874","pt":1719505320675,"mc":[{"id":"1.230178176","rc":[{"atb":[[13,0]],"id":52385889},{"atb":[[9,0]],"id":52385903}],"con":true,"img":false}]}
{"op":"mcm","clk":"11550887879","pt":1719505320779,"mc":[{"id":"1.230178176","rc":[{"atb":[[6.2,16],[14,8]],"id":52385889},{"atb":[[9.2,0],[13,6]],"id":52385903}],"con":true,"img":false}]}
{"op":"mcm","clk":"11550887881","pt":1719505320881,"mc":[{"id":"1.230178176","rc":[{"atb":[[13.5,0]],"id":52385889},{"atb":[[3.9,34.48]],"id":52385903}],"con":true,"img":false}]}
{"op":"mcm","clk":"11550887896","pt":1719505321091,"mc":[{"id":"1.230178176","rc":[{"atb":[[9.6,11.63],[3.9,0]],"id":52385903}],"con":true,"img":false}]}
{"op":"mcm","clk":"11550887952","pt":1719505322123,"mc":[{"id":"1.230178176","rc":[{"atl":[[580,2],[620,0]],"id":52385910},{"atl":[[380,2],[410,0]],"id":52385912},{"atl":[[380,2],[410,0]],"id":52385906},{"atl":[[780,2]],"id":52385918},{"atl":[[550,2],[580,0]],"id":52385920},{"atl":[[830,2],[930,0]],"id":52385889},{"atl":[[790,2],[870,0]],"id":52385883},{"atl":[[790,2]],"id":52385885},{"atl":[[550,2],[580,0]],"id":52385896},{"atl":[[570,2],[600,0]],"id":52385890},{"atl":[[560,2],[600,0]],"id":52385892},{"atl":[[520,2],[550,0]],"id":52385904},{"atl":[[310,2],[340,0]],"id":52385898},{"atl":[[430,2],[460,0]],"id":52385900},{"atl":[[530,0],[510,2]],"id":52385911},{"atl":[[310,2],[340,0]],"id":52385913},{"atl":[[450,2],[490,0]],"id":52385907},{"atl":[[880,2],[990,0]],"id":52385886},{"atl":[[600,2]],"id":52385919},{"atl":[[550,2],[580,0]],"id":52385921},{"atl":[[940,2],[1000,0]],"id":52385882},{"atl":[[750,2],[830,0]],"id":52385884},{"atl":[[900,2],[1000,0]],"id":52385917},{"atl":[[540,2],[570,0]],"id":52385891},{"atl":[[660,2],[730,0]],"id":52385893},{"atl":[[610,2],[650,0]],"id":52385903},{"atl":[[410,2],[440,0]],"id":52385905},{"atl":[[340,2],[370,0]],"id":52385899}],"con":true,"img":false}]}
{"op":"mcm","clk":"11550887957","pt":1719505322177,"mc":[{"id":"1.230178176","rc":[{"atl":[[870,0]],"id":52385918},{"atl":[[410,2],[430,0]],"id":52385914},{"atl":[[870,0]],"id":52385885},{"atl":[[650,0]],"id":52385919},{"atl":[[480,2],[510,0]],"id":52385897}],"con":true,"img":false}]}
{"op":"mcm","clk":"11550888037","pt":1719505323702,"mc":[{"id":"1.230178176","rc":[{"atb":[[16,0]],"id":52385918},{"atb":[[14,0]],"id":52385890},{"atb":[[18,0]],"id":52385917}],"con":true,"img":false}]}
{"op":"mcm","clk":"11550888044","pt":1719505323805,"mc":[{"id":"1.230178176","rc":[{"atb":[[16.5,0],[19,6],[5.3,23.26]],"id":52385918},{"atb":[[3.7,25.64],[13,7],[8.8,0]],"id":52385890},{"atb":[[18.5,0],[20,5],[8.2,10]],"id":52385917}],"con":true,"img":false}]}
{"op":"mcm","clk":"11550888049","pt":1719505323906,"mc":[{"id":"1.230178176","rc":[{"atb":[[3.7,0],[8.8,12.82]],"id":52385890}],"con":true,"img":false}]}
{"op":"mcm","clk":"11550888053","pt":1719505324009,"mc":[{"id":"1.230178176","rc":[{"atb":[[16.5,6.45],[5.3,0]],"id":52385918},{"atb":[[21,5],[8.2,0]],"id":52385917}],"con":true,"img":false}]}
{"op":"mcm","clk":"11550888229","pt":1719505327212,"mc":[{"id":"1.230178176","rc":[{"atl":[[790,0],[870,2]],"id":52385885},{"atl":[[560,0],[600,2]],"id":52385892},{"atl":[[880,0],[990,2]],"id":52385886},{"atl":[[600,0],[650,2]],"id":52385919},{"atl":[[940,0],[1000,2]],"id":52385882},{"atl":[[610,0],[650,2]],"id":52385903}],"con":true,"img":false}]}
{"op":"mcm","clk":"11550888235","pt":1719505327314,"mc":[{"id":"1.230178176","rc":[{"atl":[[430,2]],"id":52385914}],"con":true,"img":false}]}
{"op":"mcm","clk":"11550888243","pt":1719505327418,"mc":[{"id":"1.230178176","rc":[{"atl":[[410,0]],"id":52385914},{"atl":[[480,0],[510,2]],"id":52385897}],"con":true,"img":false}]}
{"op":"mcm","clk":"11550888446","pt":1719505330881,"mc":[{"id":"1.230178176","rc":[{"atb":[[14.5,7.41]],"id":52385889}],"con":true,"img":false}]}
{"op":"mcm","clk":"11550888454","pt":1719505330985,"mc":[{"id":"1.230178176","rc":[{"atb":[[6.2,0]],"id":52385889}],"con":true,"img":false}]}
{"op":"mcm","clk":"11550888870","pt":1719505339210,"mc":[{"id":"1.230178176","rc":[{"atl":[[410,2],[430,0]],"id":52385914},{"atl":[[790,2],[870,0]],"id":52385885},{"atl":[[560,2],[600,0]],"id":52385892},{"atl":[[880,2],[990,0]],"id":52385886},{"atl":[[600,2],[650,0]],"id":52385919},{"atl":[[940,2],[1000,0]],"id":52385882},{"atl":[[480,2],[510,0]],"id":52385897},{"atl":[[610,2],[650,0]],"id":52385903}],"con":true,"img":false}]}
{"op":"mcm","clk":"11550889025","pt":1719505341741,"mc":[{"id":"1.230178176","rc":[{"atb":[[13,0]],"id":52385903}],"con":true,"img":false}]}
{"op":"mcm","clk":"11550889031","pt":1719505341792,"mc":[{"id":"1.230178176","rc":[{"atb":[[12,6],[3.9,34.48]],"id":52385903}],"con":true,"img":false}]}
{"op":"mcm","clk":"11550889042","pt":1719505342000,"mc":[{"id":"1.230178176","rc":[{"atb":[[9.6,0]],"id":52385903}],"con":true,"img":false}]}
{"op":"mcm","clk":"11550889551","pt":1719505351737,"mc":[{"id":"1.230178176","rc":[{"atb":[[9.6,11.63]],"id":52385903}],"con":true,"img":false}]}
{"op":"mcm","clk":"11550889557","pt":1719505351826,"mc":[{"id":"1.230178176","rc":[{"atb":[[3.9,0]],"id":52385903}],"con":true,"img":false}]}
{"op":"mcm","clk":"11550893451","pt":1719505428752,"mc":[{"id":"1.230178176","rc":[{"atb":[[11,0]],"id":52385912},{"atb":[[14,0]],"id":52385889},{"atb":[[16,0]],"id":52385883},{"atb":[[15,0]],"id":52385892},{"atb":[[20,0]],"id":52385886},{"atb":[[15,0]],"id":52385882}],"con":true,"img":false}]}
{"op":"mcm","clk":"11550893456","pt":1719505428853,"mc":[{"id":"1.230178176","rc":[{"atb":[[4.8,0],[10,9],[2.76,56.82]],"id":52385912},{"atb":[[16,8],[6.2,14.82],[14.5,0]],"id":52385889},{"atb":[[16.5,0],[20,6],[5.3,23.26]],"id":52385883},{"atb":[[3.7,24],[8.8,0],[14,6]],"id":52385892},{"atb":[[21,0],[24,5],[7.8,10]],"id":52385886},{"atb":[[19,6],[15.5,0]],"id":52385882}],"con":true,"img":false}]}
{"op":"mcm","clk":"11550893465","pt":1719505428918,"mc":[{"id":"1.230178176","rc":[{"atb":[[4.8,26.32],[2.76,0]],"id":52385912},{"atb":[[16.5,6.45],[6.2,0]],"id":52385889},{"atb":[[16.5,6.45],[5.3,0]],"id":52385883},{"atb":[[3.7,0],[8.8,12.82]],"id":52385892},{"atb":[[25,4.17],[7.8,0]],"id":52385886},{"atb":[[8.6,12]],"id":52385882}],"con":true,"img":false}]}
{"op":"mcm","clk":"11550893473","pt":1719505429024,"mc":[{"id":"1.230178176","rc":[{"atb":[[8.6,0],[19.5,5.41]],"id":52385882}],"con":true,"img":false}]}
{"op":"mcm","clk":"11550895630","pt":1719505477468,"mc":[{"id":"1.230178176","rc":[{"atb":[[8.6,16.25]],"id":52385899}],"con":true,"img":false}]}
{"op":"mcm","clk":"11550895651","pt":1719505477878,"mc":[{"id":"1.230178176","rc":[{"atb":[[8.6,0]],"id":52385899}],"con":true,"img":false}]}
{"op":"mcm","clk":"11550896071","pt":1719505485772,"mc":[{"id":"1.230178176","rc":[{"atb":[[20,0]],"id":52385917}],"con":true,"img":false}]}
{"op":"mcm","clk":"11550896076","pt":1719505485879,"mc":[{"id":"1.230178176","rc":[{"atb":[[24,5]],"id":52385917}],"con":true,"img":false}]}
{"op":"mcm","clk":"11550896084","pt":1719505485985,"mc":[{"id":"1.230178176","rc":[{"atb":[[21,0],[8.2,10]],"id":52385917}],"con":true,"img":false}]}
{"op":"mcm","clk":"11550896091","pt":1719505486085,"mc":[{"id":"1.230178176","rc":[{"atb":[[8.2,0],[25,4.17]],"id":52385917}],"con":true,"img":false}]}
{"op":"mcm","clk":"11550896511","pt":1719505495694,"mc":[{"id":"1.230178176","rc":[{"atb":[[24,0]],"id":52385917}],"con":true,"img":false}]}
{"op":"mcm","clk":"11550896517","pt":1719505495794,"mc":[{"id":"1.230178176","rc":[{"atb":[[20,5],[8.2,8.34],[25,0]],"id":52385917}],"con":true,"img":false}]}
{"op":"mcm","clk":"11550896547","pt":1719505496410,"mc":[{"id":"1.230178176","rc":[{"atb":[[1.17,0]],"id":52385918}],"con":true,"img":false}]}
{"op":"mcm","clk":"11550896936","pt":1719505504221,"mc":[{"id":"1.230178176","rc":[{"atb":[[21,5],[8.2,0]],"id":52385917}],"con":true,"img":false}]}
{"op":"mcm","clk":"11550897882","pt":1719505524755,"mc":[{"id":"1.230178176","rc":[{"atb":[[16,0]],"id":52385889}],"con":true,"img":false}]}
{"op":"mcm","clk":"11550897889","pt":1719505524859,"mc":[{"id":"1.230178176","rc":[{"atb":[[9.6,11.63],[9,0]],"id":52385910},{"atb":[[16.5,0],[17.5,6.06]],"id":52385918},{"atb":[[9,12],[8.4,0]],"id":52385920},{"atb":[[16.5,0],[18,8],[6.4,12.9]],"id":52385889},{"atb":[[16.5,0],[17.5,6.06]],"id":52385883},{"atb":[[16.5,0],[17.5,6.06]],"id":52385885},{"atb":[[8.8,12.82],[8.4,0]],"id":52385896},{"atb":[[8.8,0],[9.4,11.9]],"id":52385890},{"atb":[[8.8,0],[9.4,11.9]],"id":52385892},{"atb":[[8,12],[7.6,0]],"id":52385904},{"atb":[[10,11.11],[9.4,0]],"id":52385919},{"atb":[[8.8,12.82],[8.4,0]],"id":52385921},{"atb":[[14,0],[15,7.14]],"id":52385884},{"atb":[[8.8,12],[8.4,0]],"id":52385891},{"atb":[[9.6,0],[10,11.11]],"id":52385903}],"con":true,"img":false}]}
{"op":"mcm","clk":"11550897896","pt":1719505524961,"mc":[{"id":"1.230178176","rc":[{"atb":[[18.5,5.71],[6.4,0]],"id":52385889}],"con":true,"img":false}]}
{"op":"mcm","clk":"11550898021","pt":1719505527754,"mc":[{"id":"1.230178176","rc":[{"atb":[[20,0]],"id":52385917}],"con":true,"img":false}]}
{"op":"mcm","clk":"11550898029","pt":1719505527853,"mc":[{"id":"1.230178176","rc":[{"atb":[[24,5]],"id":52385917}],"con":true,"img":false}]}
{"op":"mcm","clk":"11550898036","pt":1719505527950,"mc":[{"id":"1.230178176","rc":[{"atb":[[21,0],[8.4,10]],"id":52385917}],"con":true,"img":false}]}
{"op":"mcm","clk":"11550898045","pt":1719505528054,"mc":[{"id":"1.230178176","rc":[{"atb":[[25,4.17],[8.4,0]],"id":52385917}],"con":true,"img":false}]}
{"op":"mcm","clk":"11550901169","pt":1719505584694,"mc":[{"id":"1.230178176","rc":[{"atb":[[10,0]],"id":52385912}],"con":true,"img":false}]}
{"op":"mcm","clk":"11550901179","pt":1719505584799,"mc":[{"id":"1.230178176","rc":[{"atb":[[9,9]],"id":52385912}],"con":true,"img":false}]}
{"op":"mcm","clk":"11550901187","pt":1719505584902,"mc":[{"id":"1.230178176","rc":[{"atb":[[4.8,0],[2.8,55.56]],"id":52385912}],"con":true,"img":false}]}
{"op":"mcm","clk":"11550901203","pt":1719505585108,"mc":[{"id":"1.230178176","rc":[{"atb":[[2.8,0],[5,25]],"id":52385912}],"con":true,"img":false}]}
{"op":"mcm","clk":"11550901348","pt":1719505587691,"mc":[{"id":"1.230178176","rc":[{"atb":[[18,0]],"id":52385889}],"con":true,"img":false}]}
{"op":"mcm","clk":"11550901355","pt":1719505587793,"mc":[{"id":"1.230178176","rc":[{"atb":[[18.5,0],[6.4,11.42],[20,8]],"id":52385889}],"con":true,"img":false}]}
{"op":"mcm","clk":"11550901367","pt":1719505587995,"mc":[{"id":"1.230178176","rc":[{"atb":[[6.4,0],[21,5]],"id":52385889}],"con":true,"img":false}]}
{"op":"mcm","clk":"11550901815","pt":1719505595596,"mc":[{"id":"1.230178176","rc":[{"atb":[[4.4,10]],"id":52385898},{"atl":[[16.5,3.9]],"id":52385898},{"atb":[[7,13.66]],"id":52385905},{"atl":[[23,4]],"id":52385905}],"con":true,"img":false}]}
{"op":"mcm","clk":"11550901822","pt":1719505595701,"mc":[{"id":"1.230178176","rc":[{"atl":[[32,3.23],[310,0]],"id":52385898},{"atl":[[410,0],[55,2]],"id":52385905}],"con":true,"img":false}]}
{"op":"mcm","clk":"11550902698","pt":1719505611764,"mc":[{"id":"1.230178176","rc":[{"atb":[[14,0]],"id":52385910},{"atb":[[10,0]],"id":52385914},{"atb":[[10,0]],"id":52385896},{"atb":[[9,0]],"id":52385900},{"atb":[[14,0]],"id":52385911},{"atb":[[14,0]],"id":52385919},{"atb":[[12,0]],"id":52385921},{"atb":[[9,0]],"id":52385897},{"atb":[[17,0]],"id":52385893}],"con":true,"img":false}]}
{"op":"mcm","clk":"11550902701","pt":1719505611864,"mc":[{"id":"1.230178176","rc":[{"atb":[[9.6,0],[16,7],[3.9,23.26]],"id":52385910},{"atb":[[12,10],[2.84,54.35]],"id":52385914},{"atb":[[3.7,25.64],[12,10],[8.8,0]],"id":52385896},{"atb":[[11,11]],"id":52385900},{"atb":[[16,7],[6.8,0],[3.3,28]],"id":52385911},{"atb":[[4,22.22],[20,7]],"id":52385919},{"atb":[[17,8]],"id":52385921},{"atb":[[10,11]],"id":52385897},{"atb":[[10,0],[24,6],[4.2,22.22]],"id":52385893}],"con":true,"img":false}]}
{"op":"mcm","clk":"11550902707","pt":1719505611919,"mc":[{"id":"1.230178176","rc":[{"atb":[[3.9,0]],"id":52385910},{"atb":[[5,0],[5.2,20],[2.84,0]],"id":52385914},{"atb":[[3.7,0],[8.8,12.82]],"id":52385896},{"atb":[[5.1,0],[2.88,53.19]],"id":52385900},{"atb":[[7.2,16.13]],"id":52385911},{"atb":[[10,0]],"id":52385919},{"atb":[[3.7,25.64],[8.8,0]],"id":52385921},{"atb":[[6.2,0],[3.1,38.46]],"id":52385897},{"atb":[[11,10],[4.2,0]],"id":52385893}],"con":true,"img":false}]}
{"op":"mcm","clk":"11550902715","pt":1719505612019,"mc":[{"id":"1.230178176","rc":[{"atb":[[9.6,11.63]],"id":52385910},{"atb":[[5.4,22.73]],"id":52385900},{"atb":[[3.3,0]],"id":52385911},{"atb":[[10,11.11]],"id":52385919},{"atb":[[8.8,12.82]],"id":52385921},{"atb":[[6.4,18.52],[3.1,0]],"id":52385897}],"con":true,"img":false}]}
{"op":"mcm","clk":"11550902724","pt":1719505612126,"mc":[{"id":"1.230178176","rc":[{"atb":[[2.88,0]],"id":52385900},{"atb":[[4,0]],"id":52385919},{"atb":[[3.7,0]],"id":52385921}],"con":true,"img":false}]}
{"op":"mcm","clk":"11550903285","pt":1719505622952,"mc":[{"id":"1.230178176","rc":[{"atl":[[16.5,0]],"id":52385898}],"con":true,"img":false}]}
{"op":"mcm","clk":"11550903294","pt":1719505623055,"mc":[{"id":"1.230178176","rc":[{"atl":[[32,0],[18,3.1],[38,2.7]],"id":52385898}],"con":true,"img":false}]}
{"op":"mcm","clk":"11550903342","pt":1719505623730,"mc":[{"id":"1.230178176","rc":[{"atb":[[8,0]],"id":52385906},{"atb":[[9,0]],"id":52385904},{"atb":[[7,0]],"id":52385898},{"atb":[[9,0]],"id":52385913},{"atb":[[9,0]],"id":52385907},{"atb":[[17,0]],"id":52385884},{"atb":[[12,0]],"id":52385891},{"atb":[[7,5.66]],"id":52385905}],"con":true,"img":false}]}
{"op":"mcm","clk":"11550903347","pt":1719505623833,"mc":[{"id":"1.230178176","rc":[{"atb":[[4.8,0],[2.8,55.56],[10,8]],"id":52385906},{"atb":[[8,0],[3.5,24],[15,6]],"id":52385904},{"atb":[[8,11],[4.5,10]],"id":52385898},{"atb":[[4.3,0],[10,8],[2.7,58.82]],"id":52385913},{"atb":[[5.6,0],[16,6],[2.98,50.51]],"id":52385907},{"atb":[[5,14.28],[24,5],[15,0]],"id":52385884},{"atb":[[20,6],[3.7,24],[8.8,0]],"id":52385891},{"atb":[[9,8]],"id":52385905}],"con":true,"img":false}]}
{"op":"mcm","clk":"11550903353","pt":1719505623938,"mc":[{"id":"1.230178176","rc":[{"atb":[[4.3,0]],"id":52385898}],"con":true,"img":false}]}
{"op":"mcm","clk":"11550903406","pt":1719505624973,"mc":[{"id":"1.230178176","rc":[{"atb":[[1.31,100]],"id":52385889},{"atb":[[1.31,100]],"id":52385883},{"atb":[[1.31,100]],"id":52385885},{"atb":[[1.31,100]],"id":52385896},{"atb":[[1.31,100]],"id":52385890},{"atb":[[1.31,100]],"id":52385892},{"atb":[[1.31,100]],"id":52385904},{"atb":[[1.31,100]],"id":52385898},{"atb":[[1.31,100]],"id":52385900},{"atb":[[1.31,100]],"id":52385886},{"atb":[[1.31,100]],"id":52385882},{"atb":[[1.31,100]],"id":52385884},{"atb":[[1.31,100]],"id":52385897},{"atb":[[1.31,100]],"id":52385891},{"atb":[[1.31,100]],"id":52385893},{"atb":[[1.31,100]],"id":52385903},{"atb":[[1.31,100]],"id":52385899}],"con":true,"img":false}]}
{"op":"mcm","clk":"11550903413","pt":1719505625079,"mc":[{"id":"1.230178176","rc":[{"atb":[[1.31,100]],"id":52385910},{"atb":[[1.31,100]],"id":52385912},{"atb":[[1.31,100]],"id":52385918},{"atb":[[1.31,100]],"id":52385920},{"atb":[[1.31,100]],"id":52385911},{"atb":[[1.31,100]],"id":52385913},{"atb":[[1.31,100]],"id":52385907},{"atb":[[1.31,100]],"id":52385921},{"atb":[[1.31,100]],"id":52385917},{"atb":[[1.31,100]],"id":52385905}],"con":true,"img":false}]}
{"op":"mcm","clk":"11550903419","pt":1719505625151,"mc":[{"id":"1.230178176","rc":[{"atb":[[1.31,100]],"id":52385906}],"con":true,"img":false}]}
{"op":"mcm","clk":"11550903427","pt":1719505625237,"mc":[{"id":"1.230178176","rc":[{"atb":[[1.31,100]],"id":52385919}],"con":true,"img":false}]}
{"op":"mcm","clk":"11550903436","pt":1719505625340,"mc":[{"id":"1.230178176","rc":[{"atb":[[1.31,100]],"id":52385914}],"con":true,"img":false}]}
{"op":"mcm","clk":"11550903772","pt":1719505630989,"mc":[{"id":"1.230178176","rc":[{"atb":[[2.8,0],[5,25]],"id":52385906},{"atb":[[8,14.29],[3.5,0]],"id":52385904},{"atb":[[4.5,28.57],[2.7,0]],"id":52385913},{"atb":[[2.98,0],[5.9,20.41]],"id":52385907},{"atb":[[5,0],[15,7.14]],"id":52385884},{"atb":[[3.7,0],[8.8,12.82]],"id":52385891}],"con":true,"img":false}]}
{"op":"mcm","clk":"11550903806","pt":1719505631462,"mc":[{"id":"1.230178176","rc":[{"atl":[[32,3.23],[38,0]],"id":52385898}],"con":true,"img":false}]}
{"op":"mcm","clk":"11550904000","pt":1719505634665,"mc":[{"id":"1.230178176","rc":[{"atb":[[6,2]],"id":52385910},{"atb":[[6,2]],"id":52385912},{"atb":[[6,2]],"id":52385906},{"atb":[[6,2]],"id":52385918},{"atb":[[6,2]],"id":52385920},{"atb":[[6,2]],"id":52385889},{"atb":[[6,2]],"id":52385914},{"atb":[[6,2]],"id":52385883},{"atb":[[6,2]],"id":52385885},{"atb":[[6,2]],"id":52385896},{"atb":[[6,2]],"id":52385890},{"atb":[[6,2]],"id":52385892},{"atb":[[6,2]],"id":52385904},{"atb":[[6,2]],"id":52385898},{"atb":[[6,2]],"id":52385900},{"atb":[[6,2]],"id":52385911},{"atb":[[6,2]],"id":52385913},{"atb":[[6,2]],"id":52385907},{"atb":[[6,2]],"id":52385886},{"atb":[[6,2]],"id":52385919},{"atb":[[6,2]],"id":52385921},{"atb":[[6,2]],"id":52385882},{"atb":[[6,2]],"id":52385884},{"atb":[[6,2]],"id":52385917},{"atb":[[6,2]],"id":52385897},{"atb":[[6,2]],"id":52385891},{"atb":[[6,2]],"id":52385893},{"atb":[[6,2]],"id":52385903},{"atb":[[6,2]],"id":52385905},{"atb":[[6,2]],"id":52385899}],"con":true,"img":false}]}
{"op":"mcm","clk":"11550904559","pt":1719505644761,"mc":[{"id":"1.230178176","rc":[{"atb":[[20,0]],"id":52385885},{"atb":[[10,0]],"id":52385913},{"atb":[[24,0]],"id":52385886},{"atb":[[19,0]],"id":52385882}],"con":true,"img":false}]}
{"op":"mcm","clk":"11550904567","pt":1719505644866,"mc":[{"id":"1.230178176","rc":[{"atb":[[17.5,0],[6,14.12],[24,5]],"id":52385885},{"atb":[[9,8]],"id":52385913},{"atb":[[8,8.34],[42,5],[25,0]],"id":52385886},{"atb":[[19.5,0],[24,6],[8.8,10.82]],"id":52385882}],"con":true,"img":false}]}
{"op":"mcm","clk":"11550904573","pt":1719505644968,"mc":[{"id":"1.230178176","rc":[{"atb":[[5.5,22.22],[6,2]],"id":52385885}],"con":true,"img":false}]}
{"op":"mcm","clk":"11550904583","pt":1719505645071,"mc":[{"id":"1.230178176","rc":[{"atb":[[17.5,6.06],[5.5,0]],"id":52385885},{"atb":[[8,0],[30,3.45]],"id":52385886},{"atb":[[25,4.17],[8.8,0]],"id":52385882}],"con":true,"img":false}]}
{"op":"mcm","clk":"11550904733","pt":1719505647807,"mc":[{"id":"1.230178176","rc":[{"atb":[[12,0]],"id":52385914}],"con":true,"img":false}]}
{"op":"mcm","clk":"11550904738","pt":1719505647862,"mc":[{"id":"1.230178176","rc":[{"atb":[[11,10]],"id":52385914}],"con":true,"img":false}]}
{"op":"mcm","clk":"11550904855","pt":1719505650086,"mc":[{"id":"1.230178176","rc":[{"atb":[[4.4,0]],"id":52385898},{"atl":[[18,0]],"id":52385898},{"atb":[[7,0]],"id":52385905},{"atl":[[23,0]],"id":52385905}],"con":true,"img":false}]}
{"op":"mcm","clk":"11550904865","pt":1719505650191,"mc":[{"id":"1.230178176","rc":[{"atb":[[9.2,5]],"id":52385912},{"atl":[[50,2.33]],"id":52385912},{"atb":[[5.7,6]],"id":52385898},{"atl":[[19,3.4]],"id":52385898},{"atb":[[6.2,6.2]],"id":52385905},{"atl":[[26,2.5]],"id":52385905},{"atb":[[5.7,5.9]],"id":52385899},{"atl":[[26,3]],"id":52385899}],"con":true,"img":false}]}
{"op":"mcm","clk":"11550904878","pt":1719505650400,"mc":[{"id":"1.230178176","rc":[{"atl":[[380,0],[50,4.37]],"id":52385912},{"atl":[[38,2.7],[340,0]],"id":52385899}],"con":true,"img":false}]}
{"op":"mcm","clk":"11550905882","pt":1719505669689,"mc":[{"id":"1.230178176","rc":[{"atl":[[50,2.33],[55,2]],"id":52385912}],"con":true,"img":false}]}
{"op":"mcm","clk":"11550905981","pt":1719505671700,"mc":[{"id":"1.230178176","rc":[{"atb":[[14,0]],"id":52385920}],"con":true,"img":false}]}
{"op":"mcm","clk":"11550905988","pt":1719505671807,"mc":[{"id":"1.230178176","rc":[{"atb":[[9,0],[20,6],[6,22]],"id":52385920}],"con":true,"img":false}]}
{"op":"mcm","clk":"11550905993","pt":1719505671907,"mc":[{"id":"1.230178176","rc":[{"atb":[[6,2],[3.75,36.36]],"id":52385920}],"con":true,"img":false}]}
{"op":"mcm","clk":"11550906297","pt":1719505677103,"mc":[{"id":"1.230178176","rc":[{"atl":[[50,0]],"id":52385912},{"atl":[[19,0]],"id":52385898},{"atl":[[26,0]],"id":52385905},{"atl":[[26,0]],"id":52385899}],"con":true,"img":false}]}
{"op":"mcm","clk":"11550906304","pt":1719505677207,"mc":[{"id":"1.230178176","rc":[{"atl":[[30,3.3]],"id":52385912},{"atb":[[13.5,5.2]],"id":52385890},{"atl":[[48,3]],"id":52385890},{"atl":[[32,0],[38,2.7],[21,3.3]],"id":52385898},{"atb":[[11.5,4]],"id":52385900},{"atl":[[40,2.4]],"id":52385900},{"atb":[[21,3.2]],"id":52385919},{"atl":[[75,2]],"id":52385919},{"atb":[[10.5,4]],"id":52385897},{"atl":[[30,2.65]],"id":52385897},{"atl":[[70,2],[29,2.59]],"id":52385905},{"atl":[[19.5,4],[44,2.33]],"id":52385899}],"con":true,"img":false}]}
{"op":"mcm","clk":"11550906311","pt":1719505677313,"mc":[{"id":"1.230178176","rc":[{"atl":[[570,0],[200,2]],"id":52385890},{"atl":[[80,2],[430,0]],"id":52385900},{"atl":[[600,0],[250,2]],"id":52385919},{"atl":[[110,2],[480,0]],"id":52385897},{"atl":[[55,0]],"id":52385905},{"atl":[[38,0]],"id":52385899}],"con":true,"img":false}]}
{"op":"mcm","clk":"11550906322","pt":1719505677619,"mc":[{"id":"1.230178176","rc":[{"atb":[[13,0]],"id":52385890}],"con":true,"img":false}]}
{"op":"mcm","clk":"11550906330","pt":1719505677721,"mc":[{"id":"1.230178176","rc":[{"atb":[[18,7]],"id":52385890}],"con":true,"img":false}]}
{"op":"mcm","clk":"11550906349","pt":1719505677930,"mc":[{"id":"1.230178176","rc":[{"atl":[[46,2.22],[55,0]],"id":52385912},{"atl":[[32,3.23],[38,0]],"id":52385898},{"atl":[[65,2],[80,0]],"id":52385900},{"atl":[[200,2],[250,0]],"id":52385919},{"atl":[[70,0],[55,2]],"id":52385905},{"atl":[[38,2.7],[44,0]],"id":52385899}],"con":true,"img":false}]}
{"op":"mcm","clk":"11550906393","pt":1719505678602,"mc":[{"id":"1.230178176","rc":[{"atb":[[9,12],[3.75,0]],"id":52385920}],"con":true,"img":false}]}
{"op":"mcm","clk":"11550906871","pt":1719505686719,"mc":[{"id":"1.230178176","rc":[{"atb":[[11,0]],"id":52385900}],"con":true,"img":false}]}
{"op":"mcm","clk":"11550906881","pt":1719505686820,"mc":[{"id":"1.230178176","rc":[{"atb":[[12,11]],"id":52385900}],"con":true,"img":false}]}
{"op":"mcm","clk":"11550907036","pt":1719505689719,"mc":[{"id":"1.230178176","rc":[{"atb":[[10,0]],"id":52385897}],"con":true,"img":false}]}
{"op":"mcm","clk":"11550907045","pt":1719505689824,"mc":[{"id":"1.230178176","rc":[{"atb":[[11,11]],"id":52385897}],"con":true,"img":false}]}
{"op":"mcm","clk":"11550907562","pt":1719505698428,"mc":[{"id":"1.230178176","rc":[{"atb":[[15.5,1.63]],"id":52385914}],"con":true,"img":false}]}
{"op":"mcm","clk":"11550907579","pt":1719505698726,"mc":[{"id":"1.230178176","rc":[{"atb":[[9,0]],"id":52385912}],"con":true,"img":false}]}
{"op":"mcm","clk":"11550907589","pt":1719505698831,"mc":[{"id":"1.230178176","rc":[{"atb":[[10,9]],"id":52385912}],"con":true,"img":false}]}
{"op":"mcm","clk":"11550907942","pt":1719505704371,"mc":[{"id":"1.230178176","rc":[{"atb":[[9.2,0]],"id":52385912},{"atl":[[30,0]],"id":52385912},{"atb":[[13.5,0]],"id":52385890},{"atl":[[48,0]],"id":52385890},{"atl":[[21,0]],"id":52385898},{"atb":[[11.5,0]],"id":52385900},{"atl":[[40,0]],"id":52385900},{"atb":[[10.5,0]],"id":52385897},{"atl":[[30,0]],"id":52385897},{"atb":[[6.2,0]],"id":52385905},{"atl":[[29,0]],"id":52385905},{"atl":[[19.5,0]],"id":52385899}],"con":true,"img":false}]}
{"op":"mcm","clk":"11550907950","pt":1719505704473,"mc":[{"id":"1.230178176","rc":[{"atb":[[10.5,5.5]],"id":52385912},{"atl":[[34,3]],"id":52385912},{"atb":[[10.5,5.62]],"id":52385906},{"atl":[[30,2.41]],"id":52385906},{"atb":[[21,4.2]],"id":52385920},{"atl":[[170,2.3]],"id":52385920},{"atb":[[18.5,4.6]],"id":52385890},{"atl":[[65,2.1]],"id":52385890},{"atl":[[17,3]],"id":52385898},{"atb":[[12.5,4]],"id":52385900},{"atl":[[34,2.8]],"id":52385900},{"atb":[[9.2,6]],"id":52385913},{"atl":[[36,2.3]],"id":52385913},{"atb":[[16.5,4.29]],"id":52385907},{"atl":[[85,2]],"id":52385907},{"atb":[[11.5,6]],"id":52385897},{"atl":[[34,2]],"id":52385897},{"atb":[[9.2,5.06]],"id":52385905},{"atl":[[22,3.65]],"id":52385905},{"atl":[[22,3]],"id":52385899}],"con":true,"img":false}]}
{"op":"mcm","clk":"11550907956","pt":1719505704531,"mc":[{"id":"1.230178176","rc":[{"atl":[[380,0],[46,2.22]],"id":52385906},{"atl":[[550,0],[170,4.3]],"id":52385920},{"atl":[[170,2],[200,0]],"id":52385890},{"atl":[[36,4.45],[310,0]],"id":52385913},{"atl":[[85,4],[450,0]],"id":52385907}],"con":true,"img":false}]}
{"op":"mcm","clk":"11550907962","pt":1719505704633,"mc":[{"id":"1.230178176","rc":[{"atl":[[550,2]],"id":52385920},{"atl":[[310,2]],"id":52385913},{"atl":[[450,2]],"id":52385907}],"con":true,"img":false}]}
{"op":"mcm","clk":"11550907968","pt":1719505704739,"mc":[{"id":"1.230178176","rc":[{"atl":[[170,2.3]],"id":52385920},{"atl":[[36,2.3]],"id":52385913},{"atl":[[85,2]],"id":52385907}],"con":true,"img":false}]}
{"op":"mcm","clk":"11550907977","pt":1719505704842,"mc":[{"id":"1.230178176","rc":[{"atl":[[550,0],[170,4.3]],"id":52385920},{"atl":[[36,5.16],[310,0]],"id":52385913},{"atl":[[85,4],[450,0]],"id":52385907}],"con":true,"img":false}]}
{"op":"mcm","clk":"11550907983","pt":1719505704948,"mc":[{"id":"1.230178176","rc":[{"atl":[[550,2]],"id":52385920},{"atl":[[36,2.3],[310,2]],"id":52385913},{"atl":[[85,2],[450,2]],"id":52385907}],"con":true,"img":false}]}
{"op":"mcm","clk":"11550907988","pt":1719505705045,"mc":[{"id":"1.230178176","rc":[{"atl":[[170,2.3]],"id":52385920},{"atl":[[36,5.16],[310,0]],"id":52385913},{"atl":[[85,4],[450,0]],"id":52385907}],"con":true,"img":false}]}
{"op":"mcm","clk":"11550907994","pt":1719505705148,"mc":[{"id":"1.230178176","rc":[{"atl":[[550,0],[170,4.3]],"id":52385920},{"atl":[[36,2.3],[310,2]],"id":52385913},{"atl":[[450,2]],"id":52385907}],"con":true,"img":false}]}
{"op":"mcm","clk":"11550908000","pt":1719505705255,"mc":[{"id":"1.230178176","rc":[{"atl":[[85,2]],"id":52385907}],"con":true,"img":false}]}
{"op":"mcm","clk":"11550908027","pt":1719505705769,"mc":[{"id":"1.230178176","rc":[{"atb":[[9,0]],"id":52385913},{"atb":[[9,0]],"id":52385905}],"con":true,"img":false}]}
{"op":"mcm","clk":"11550908036","pt":1719505705872,"mc":[{"id":"1.230178176","rc":[{"atb":[[10,8]],"id":52385913},{"atl":[[36,4.45],[310,0]],"id":52385913},{"atb":[[10,8]],"id":52385905}],"con":true,"img":false}]}
{"op":"mcm","clk":"11550908045","pt":1719505705974,"mc":[{"id":"1.230178176","rc":[{"atl":[[36,2.3],[310,2]],"id":52385913}],"con":true,"img":false}]}
{"op":"mcm","clk":"11550908149","pt":1719505707800,"mc":[{"id":"1.230178176","rc":[{"atb":[[9.6,0],[16.5,18],[21,5],[25,2.5]],"id":52385910},{"atl":[[570,1.05],[150,5],[110,2.5]],"id":52385910},{"atb":[[11,12],[7.4,2.5],[5,0],[1.57,100],[6.6,5]],"id":52385912},{"atl":[[32,14.5],[40,5],[46,0],[60,2]],"id":52385912},{"atb":[[5,0],[10.5,15.26],[6.2,18.62],[7,2.5]],"id":52385906},{"atl":[[38,2.7],[46,0],[25,2.5],[29,14.64]],"id":52385906},{"atb":[[32,2.5],[17.5,0],[19.5,21.41],[27,5]],"id":52385918},{"atl":[[130,2.5],[170,5],[720,2],[780,0],[770,0.78]],"id":52385918},{"atb":[[21,21.4],[10.5,10.2],[13.5,5],[15.5,2.5]],"id":52385920},{"atl":[[75,5],[160,3.77],[55,2.5]],"id":52385920},{"atb":[[40,5],[22,14],[48,2.5]],"id":52385889},{"atl":[[830,0],[200,2.5],[800,2],[820,0.73],[240,5]],"id":52385889},{"atb":[[8,2.5],[7.2,5],[5.2,0],[3.65,37.74],[15.5,9.63]],"id":52385914},{"atl":[[65,5],[48,2.5],[410,0],[400,1.5]],"id":52385914},{"atb":[[17.5,0],[36,2.5],[19,5.56],[21,16],[29,5]],"id":52385883},{"atl":[[160,2.5],[750,2],[790,0],[780,0.77],[200,5]],"id":52385883},{"atb":[[17.5,0],[40,5],[10.5,10.53],[48,2.5],[25,14]],"id":52385885},{"atl":[[180,2.5],[790,0],[780,2.77],[220,5]],"id":52385885},{"atb":[[7.4,15.62],[12.5,24],[13,5],[8.8,0],[15,2.5]],"id":52385896},{"atl":[[65,2.5],[540,3.11],[550,0],[85,5]],"id":52385896},{"atb":[[9.4,0],[15.5,5],[17.5,2.5],[7.2,14],[18,0],[19,18.4]],"id":52385890},{"atl":[[70,2.5],[170,0],[90,5],[60,10.17],[120,2]],"id":52385890},{"atb":[[18,5],[4.3,30.3],[20,2.5],[14.5,16],[9.4,0]],"id":52385892},{"atl":[[560,0],[550,3.09],[85,2.5],[110,5]],"id":52385892},{"atb":[[8,0],[10,11.11],[11,5],[13,2.5],[15.5,16]],"id":52385904},{"atl":[[520,0],[44,2.5],[55,5],[490,2],[510,1.18]],"id":52385904},{"atb":[[8,23.92],[4.5,0],[5.5,12]],"id":52385898},{"atl":[[32,0],[16.5,15.42],[18.5,5],[25,4.17]],"id":52385898},{"atb":[[6,17],[12.5,15.2],[7.8,2.5],[7,5],[5.4,0]],"id":52385900},{"atl":[[65,0],[32,11.2],[36,5],[55,2],[29,2.5]],"id":52385900},{"atb":[[16.5,18],[7.2,0],[1.32,100],[13.5,5],[15.5,2.5]],"id":52385911},{"atl":[[65,2.5],[85,5],[500,1.2]],"id":52385911},{"atb":[[5.6,5],[4.5,0],[10,17.2],[6,4.5],[3.55,39.22]],"id":52385913},{"atl":[[34,14.2],[28,2.5]],"id":52385913},{"atb":[[8,2.5],[7.2,5],[7,10.29],[5.9,0]],"id":52385907},{"atl":[[38,2.5],[46,5],[410,2],[440,1.37],[450,0]],"id":52385907},{"atb":[[65,2.5],[32,3.23],[44,10.9],[48,5],[30,0]],"id":52385886},{"atl":[[280,5],[830,2],[880,0],[870,0.69],[240,2.5]],"id":52385886},{"atb":[[10,0],[12.5,5],[13.5,8],[14.5,2.5],[22,12.8]],"id":52385919},{"atl":[[65,2.5],[70,8.7],[160,2],[85,5],[200,0]],"id":52385919},{"atb":[[17.5,20],[11.5,9.52],[12,5],[8.8,0],[14,2.5]],"id":52385921},{"atl":[[65,2.5],[520,2],[540,1.11],[550,0],[85,5]],"id":52385921},{"atb":[[65,2.5],[48,5],[26,12.34]],"id":52385882},{"atl":[[280,2.5],[320,5],[860,2],[940,0],[930,0.65]],"id":52385882},{"atb":[[34,5],[42,2.5],[21,5],[25,14],[15,0]],"id":52385884},{"atl":[[150,2.5],[700,2],[750,0],[190,5],[740,0.81]],"id":52385884},{"atb":[[36,5],[44,2.5],[26,12.34]],"id":52385917},{"atl":[[200,2.5],[840,2],[890,0.67],[900,0],[240,5]],"id":52385917},{"atb":[[9,2.5],[6.4,0],[11,0],[8.2,5],[12,24],[8.4,13.51]],"id":52385897},{"atl":[[34,20.18],[40,2.5],[80,2],[48,5],[110,0]],"id":52385897},{"atb":[[17.5,5],[19.5,2.5],[21,16],[9.8,11.36],[8.8,0]],"id":52385891},{"atl":[[540,0],[65,2.5],[530,3.13],[85,5]],"id":52385891},{"atb":[[11,0],[22,5],[25,16],[26,2.5],[13.5,8]],"id":52385893},{"atl":[[150,5],[660,0],[650,2.92],[110,2.5]],"id":52385893},{"atb":[[17,5],[19,2.5],[10,0],[11,10],[12.5,16]],"id":52385903},{"atl":[[570,2],[75,2.5],[600,1],[610,0],[95,5]],"id":52385903},{"atb":[[5.6,5],[6.4,13.06],[10,22.6],[5,0],[6,4.5]],"id":52385905},{"atl":[[40,2.56],[21,14.6],[22,6.15],[26,5],[55,0]],"id":52385905},{"atb":[[6.4,2.5],[3.85,35.09],[9.2,12],[5.8,5],[4.5,0]],"id":52385899},{"atl":[[38,0],[21,12],[23,2.5],[27,5],[30,3.45]],"id":52385899}],"con":true,"img":false}]}
{"op":"mcm","clk":"11550908155","pt":1719505707855,"mc":[{"id":"1.230178176","rc":[{"atl":[[580,0],[190,2]],"id":52385910},{"atb":[[9,0]],"id":52385920},{"atl":[[80,2]],"id":52385920},{"atl":[[380,2]],"id":52385914},{"atb":[[25,0]],"id":52385882},{"atb":[[42,2.44],[25,0]],"id":52385917}],"con":true,"img":false}]}
{"op":"mcm","clk":"11550908161","pt":1719505707956,"mc":[{"id":"1.230178176","rc":[{"atl":[[170,2.3]],"id":52385920},{"atb":[[21,0],[30,3.45]],"id":52385889},{"atb":[[20,7]],"id":52385890},{"atl":[[110,2],[510,0]],"id":52385911},{"atb":[[55,2]],"id":52385882},{"atb":[[12,35]],"id":52385897}],"con":true,"img":false}]}
{"op":"mcm","clk":"11550908168","pt":1719505708061,"mc":[{"id":"1.230178176","rc":[{"atb":[[22,18.76],[30,0]],"id":52385889},{"atl":[[110,0],[500,3.2]],"id":52385911},{"atb":[[26,16.34],[55,0]],"id":52385882}],"con":true,"img":false}]}
{"op":"mcm","clk":"11550908174","pt":1719505708163,"mc":[{"id":"1.230178176","rc":[{"atb":[[30,3.45]],"id":52385889},{"atl":[[110,2]],"id":52385911},{"atb":[[48,7.13],[26,12.34]],"id":52385882}],"con":true,"img":false}]}
{"op":"mcm","clk":"11550908180","pt":1719505708264,"mc":[{"id":"1.230178176","rc":[{"atb":[[22,14]],"id":52385889},{"atl":[[500,1.2]],"id":52385911},{"atb":[[48,5],[26,16.34]],"id":52385882}],"con":true,"img":false}]}
{"op":"mcm","clk":"11550908202","pt":1719505708778,"mc":[{"id":"1.230178176","rc":[{"atb":[[24,0]],"id":52385882}],"con":true,"img":false}]}
{"op":"mcm","clk":"11550908219","pt":1719505709041,"mc":[{"id":"1.230178176","rc":[{"atb":[[20,0]],"id":52385883}],"con":true,"img":false}]}
{"op":"mcm","clk":"11550908225","pt":1719505709247,"mc":[{"id":"1.230178176","rc":[{"atb":[[24,0]],"id":52385884}],"con":true,"img":false}]}
{"op":"mcm","clk":"11550908237","pt":1719505709450,"mc":[{"id":"1.230178176","rc":[{"atb":[[24,0]],"id":52385885}],"con":true,"img":false}]}
{"op":"mcm","clk":"11550908249","pt":1719505709656,"mc":[{"id":"1.230178176","rc":[{"atb":[[42,0]],"id":52385886}],"con":true,"img":false}]}
{"op":"mcm","clk":"11550908256","pt":1719505709861,"mc":[{"id":"1.230178176","rc":[{"atb":[[20,0]],"id":52385889}],"con":true,"img":false}]}
{"op":"mcm","clk":"11550908266","pt":1719505710064,"mc":[{"id":"1.230178176","rc":[{"atb":[[14,0]],"id":52385892}],"con":true,"img":false}]}
{"op":"mcm","clk":"11550908284","pt":1719505710372,"mc":[{"id":"1.230178176","rc":[{"atb":[[12,0]],"id":52385896}],"con":true,"img":false}]}
{"op":"mcm","clk":"11550908309","pt":1719505710682,"mc":[{"id":"1.230178176","rc":[{"atb":[[12,0]],"id":52385903}],"con":true,"img":false}]}
{"op":"mcm","clk":"11550908333","pt":1719505710943,"mc":[{"id":"1.230178176","rc":[{"atb":[[16,0]],"id":52385910}],"con":true,"img":false}]}
{"op":"mcm","clk":"11550908346","pt":1719505711147,"mc":[{"id":"1.230178176","rc":[{"atb":[[24,0]],"id":52385917}],"con":true,"img":false}]}
{"op":"mcm","clk":"11550908359","pt":1719505711354,"mc":[{"id":"1.230178176","rc":[{"atb":[[19,0]],"id":52385918}],"con":true,"img":false}]}
{"op":"mcm","clk":"11550908374","pt":1719505711664,"mc":[{"id":"1.230178176","rc":[{"atb":[[15,8.5]],"id":52385896},{"atb":[[20,7.5]],"id":52385892}],"con":true,"img":false}]}
{"op":"mcm","clk":"11550908409","pt":1719505712282,"mc":[{"id":"1.230178176","rc":[{"atl":[[34,17.23],[310,0]],"id":52385913}],"con":true,"img":false}]}
{"op":"mcm","clk":"11550908450","pt":1719505713062,"mc":[{"id":"1.230178176","rc":[{"atb":[[36,7.86],[42,0]],"id":52385917}],"con":true,"img":false}]}
{"op":"mcm","clk":"11550908493","pt":1719505713884,"mc":[{"id":"1.230178176","rc":[{"atb":[[12,0]],"id":52385900}],"con":true,"img":false}]}
{"op":"mcm","clk":"11550908497","pt":1719505713952,"mc":[{"id":"1.230178176","rc":[{"atb":[[13,11]],"id":52385900}],"con":true,"img":false}]}
{"op":"mcm","clk":"11550908504","pt":1719505714048,"mc":[{"id":"1.230178176","rc":[{"atb":[[4.3,0],[6.2,15]],"id":52385892}],"con":true,"img":false}]}
{"op":"mcm","clk":"11550908511","pt":1719505714155,"mc":[{"id":"1.230178176","rc":[{"atb":[[2.82,54.95],[1.57,0]],"id":52385912},{"atl":[[46,2.22],[60,0]],"id":52385912},{"atl":[[38,0],[29,18.21]],"id":52385906},{"atl":[[640,2],[720,0]],"id":52385918},{"atl":[[680,2],[800,0]],"id":52385889},{"atb":[[5.2,23.81],[3.65,0]],"id":52385914},{"atb":[[19,0],[21,21]],"id":52385883},{"atl":[[650,2]],"id":52385883},{"atb":[[20,5.26],[10.5,0]],"id":52385885},{"atl":[[670,2],[780,0.77]],"id":52385885},{"atb":[[7.4,0],[9.8,11.36]],"id":52385896},{"atb":[[11.5,9.52],[7.2,0]],"id":52385890},{"atl":[[440,2],[490,0]],"id":52385904},{"atl":[[21,5],[25,0]],"id":52385898},{"atb":[[6,2],[7,21.67]],"id":52385900},{"atl":[[44,2.33],[55,0]],"id":52385900},{"atb":[[2.4,71.43],[1.32,0]],"id":52385911},{"atb":[[3.55,0],[4.7,27.03]],"id":52385913},{"atl":[[80,2],[410,0]],"id":52385907},{"atb":[[32,0],[38,2.7]],"id":52385886},{"atl":[[720,2],[830,0]],"id":52385886},{"atl":[[160,0],[120,2]],"id":52385919},{"atl":[[520,0],[470,2]],"id":52385921},{"atl":[[750,2],[860,0]],"id":52385882},{"atl":[[620,2],[700,0]],"id":52385884},{"atl":[[730,2],[840,0]],"id":52385917},{"atl":[[65,2]],"id":52385897},{"atb":[[12,9.09],[9.8,0]],"id":52385891},{"atl":[[530,1.13],[480,2]],"id":52385891},{"atb":[[16,6.67],[13.5,0]],"id":52385893},{"atl":[[570,2],[650,0.92]],"id":52385893},{"atb":[[11,0],[12.5,24.7]],"id":52385903},{"atl":[[520,2],[570,0]],"id":52385903},{"atl":[[32,3.23],[40,0]],"id":52385905},{"atb":[[3.85,0],[4.5,28.57]],"id":52385899}],"con":true,"img":false}]}
{"op":"mcm","clk":"11550908517","pt":1719505714250,"mc":[{"id":"1.230178176","rc":[{"atl":[[750,0]],"id":52385883},{"atl":[[80,0]],"id":52385897}],"con":true,"img":false}]}
{"op":"mcm","clk":"11550908580","pt":1719505715748,"mc":[{"id":"1.230178176","rc":[{"atb":[[10,9.2]],"id":52385913}],"con":true,"img":false}]}
{"op":"mcm","clk":"11550908587","pt":1719505715846,"mc":[{"id":"1.230178176","rc":[{"atb":[[9,8],[10,0]],"id":52385913}],"con":true,"img":false}]}
{"op":"mcm","clk":"11550908592","pt":1719505715946,"mc":[{"id":"1.230178176","rc":[{"atb":[[44,4.88]],"id":52385918},{"atb":[[34,5.4]],"id":52385883},{"atb":[[24,8.56]],"id":52385896},{"atb":[[19.5,10.56]],"id":52385890},{"atb":[[9.8,21]],"id":52385913},{"atb":[[60,4.12]],"id":52385886},{"atb":[[21,9.38]],"id":52385921},{"atb":[[16,9.91]],"id":52385897},{"atb":[[36,7.31]],"id":52385893},{"atb":[[8.4,17.5]],"id":52385899}],"con":true,"img":false}]}
{"op":"mcm","clk":"11550908599","pt":1719505716049,"mc":[{"id":"1.230178176","rc":[{"atb":[[19.5,16],[21,5]],"id":52385918}],"con":true,"img":false}]}
{"op":"mcm","clk":"11550908629","pt":1719505716562,"mc":[{"id":"1.230178176","rc":[{"atb":[[44,0]],"id":52385918},{"atb":[[34,0]],"id":52385883},{"atb":[[24,0]],"id":52385896},{"atb":[[19.5,0]],"id":52385890},{"atb":[[60,0]],"id":52385886},{"atb":[[21,0]],"id":52385921},{"atb":[[16,0]],"id":52385897},{"atb":[[36,0]],"id":52385893},{"atb":[[8.4,0]],"id":52385899}],"con":true,"img":false}]}
{"op":"mcm","clk":"11550908639","pt":1719505716767,"mc":[{"id":"1.230178176","rc":[{"atb":[[24,0]],"id":52385893}],"con":true,"img":false}]}
{"op":"mcm","clk":"11550908708","pt":1719505718279,"mc":[{"id":"1.230178176","rc":[{"atb":[[36,5],[26,16.34]],"id":52385917}],"con":true,"img":false}]}
{"op":"mcm","clk":"11550908771","pt":1719505719285,"mc":[{"id":"1.230178176","rc":[{"atb":[[9,12.5]],"id":52385896}],"con":true,"img":false}]}
{"op":"mcm","clk":"11550908781","pt":1719505719390,"mc":[{"id":"1.230178176","rc":[{"atb":[[9.8,0]],"id":52385896}],"con":true,"img":false}]}
{"op":"mcm","clk":"11550908838","pt":1719505720369,"mc":[{"id":"1.230178176","rc":[{"atb":[[38,0],[42,2.44]],"id":52385886}],"con":true,"img":false}]}
{"op":"mcm","clk":"11550908894","pt":1719505721194,"mc":[{"id":"1.230178176","rc":[{"atb":[[36,15]],"id":52385910},{"atl":[[95,6.38]],"id":52385910},{"atb":[[70,8.7]],"id":52385889},{"atl":[[190,3.17]],"id":52385889},{"atb":[[29,20]],"id":52385896},{"atl":[[60,10.17]],"id":52385896},{"atb":[[17.5,15]],"id":52385904},{"atl":[[42,14.63]],"id":52385904},{"atl":[[270,2.23]],"id":52385882},{"atl":[[60,10.17]],"id":52385891},{"atb":[[48,12.77]],"id":52385893},{"atl":[[100,6.06]],"id":52385893}],"con":true,"img":false}]}
{"op":"mcm","clk":"11550908901","pt":1719505721299,"mc":[{"id":"1.230178176","rc":[{"atb":[[16.5,0]],"id":52385910},{"atl":[[570,0]],"id":52385910},{"atl":[[19,21]],"id":52385906},{"atb":[[48,12.77]],"id":52385918},{"atl":[[120,5.04]],"id":52385918},{"atl":[[50,12.24]],"id":52385920},{"atb":[[22,0]],"id":52385889},{"atl":[[290,2],[820,0]],"id":52385889},{"atl":[[40,15]],"id":52385914},{"atb":[[40,15]],"id":52385883},{"atl":[[150,4.03]],"id":52385883},{"atb":[[50,12.24]],"id":52385885},{"atl":[[170,3.55]],"id":52385885},{"atb":[[12.5,0]],"id":52385896},{"atl":[[540,2],[110,2]],"id":52385896},{"atb":[[23,23.2]],"id":52385890},{"atb":[[29,20]],"id":52385892},{"atl":[[80,7.59]],"id":52385892},{"atb":[[15.5,0]],"id":52385904},{"atl":[[70,2],[440,0],[510,0]],"id":52385904},{"atb":[[8.2,22]],"id":52385898},{"atl":[[13.5,22]],"id":52385898},{"atb":[[13,38.6]],"id":52385900},{"atl":[[25,25]],"id":52385900},{"atb":[[24,15]],"id":52385911},{"atl":[[60,10.17]],"id":52385911},{"atl":[[22,28]],"id":52385913},{"atl":[[36,13.58]],"id":52385907},{"atb":[[85,7.14]],"id":52385886},{"atl":[[230,2.62]],"id":52385886},{"atl":[[60,10.17]],"id":52385919},{"atb":[[25,15]],"id":52385921},{"atl":[[60,10.17]],"id":52385921},{"atb":[[90,6.74]],"id":52385882},{"atl":[[350,2],[750,0],[930,0]],"id":52385882},{"atb":[[50,12.24]],"id":52385884},{"atl":[[140,4.32]],"id":52385884},{"atb":[[75,8.11]],"id":52385917},{"atl":[[190,3.17]],"id":52385917},{"atb":[[18,22]],"id":52385897},{"atl":[[530,0],[90,2],[480,0]],"id":52385891},{"atb":[[25,0]],"id":52385893},{"atl":[[570,0],[650,0],[170,2]],"id":52385893},{"atb":[[19.5,15]],"id":52385903},{"atl":[[70,8.7]],"id":52385903},{"atb":[[9.8,28]],"id":52385899}],"con":true,"img":false}]}
{"op":"mcm","clk":"11550908909","pt":1719505721356,"mc":[{"id":"1.230178176","rc":[{"atl":[[640,0],[240,2]],"id":52385918},{"atl":[[160,0]],"id":52385920},{"atl":[[680,0]],"id":52385889},{"atl":[[65,7],[400,0]],"id":52385914},{"atb":[[21,5],[24,4.35]],"id":52385883},{"atl":[[260,2],[780,0]],"id":52385883},{"atl":[[280,2]],"id":52385885},{"atl":[[540,0]],"id":52385896},{"atb":[[19,0]],"id":52385890},{"atl":[[550,1.09],[140,2]],"id":52385892},{"atb":[[8,11]],"id":52385898},{"atl":[[16.5,2.5]],"id":52385898},{"atl":[[34,8.03]],"id":52385913},{"atl":[[80,0]],"id":52385907},{"atb":[[44,0]],"id":52385886},{"atl":[[320,2],[720,0],[870,0]],"id":52385886},{"atl":[[70,0]],"id":52385919},{"atb":[[17.5,0]],"id":52385921},{"atl":[[540,0],[90,2],[470,0]],"id":52385921},{"atb":[[48,7.13],[26,0]],"id":52385882},{"atb":[[25,0]],"id":52385884},{"atl":[[620,0],[740,0],[220,2]],"id":52385884},{"atb":[[26,4]],"id":52385917},{"atl":[[330,2],[730,0],[890,0]],"id":52385917},{"atb":[[12,11]],"id":52385897},{"atb":[[12.5,8.7]],"id":52385903},{"atl":[[600,0]],"id":52385903}],"con":true,"img":false}]}
{"op":"mcm","clk":"11550908915","pt":1719505721457,"mc":[{"id":"1.230178176","rc":[{"atl":[[29,8.57]],"id":52385906},{"atb":[[19.5,0]],"id":52385918},{"atl":[[770,0]],"id":52385918},{"atl":[[380,0]],"id":52385914},{"atb":[[21,0]],"id":52385883},{"atl":[[650,0]],"id":52385883},{"atb":[[25,0]],"id":52385885},{"atl":[[670,0],[780,0]],"id":52385885},{"atb":[[14.5,0]],"id":52385892},{"atl":[[550,0]],"id":52385892},{"atb":[[12.5,4]],"id":52385900},{"atl":[[32,0]],"id":52385900},{"atb":[[16.5,0]],"id":52385911},{"atl":[[500,0]],"id":52385911},{"atl":[[46,7.22],[440,0]],"id":52385907},{"atb":[[12.5,0],[14,7.5]],"id":52385903},{"atl":[[520,0],[130,2]],"id":52385903},{"atb":[[9.2,0]],"id":52385899}],"con":true,"img":false}]}
{"op":"mcm","clk":"11550908935","pt":1719505721770,"mc":[{"id":"1.230178176","rc":[{"atb":[[8,0]],"id":52385898}],"con":true,"img":false}]}
{"op":"mcm","clk":"11550908941","pt":1719505721871,"mc":[{"id":"1.230178176","rc":[{"atb":[[9,11]],"id":52385898}],"con":true,"img":false}]}
{"op":"mcm","clk":"11550909001","pt":1719505723065,"mc":[{"id":"1.230178176","rc":[{"atb":[[2.82,0],[1.76,100]],"id":52385912},{"atb":[[4.6,27.78],[5.2,0]],"id":52385914},{"atb":[[24,0],[26,4]],"id":52385883},{"atb":[[8,14.29],[6.2,0]],"id":52385892},{"atb":[[2.4,0],[1.9,100]],"id":52385911},{"atb":[[4.1,32.26]],"id":52385913},{"atb":[[48,0]],"id":52385893},{"atl":[[160,2],[170,0]],"id":52385893},{"atb":[[3.8,35.71],[4.5,0]],"id":52385899}],"con":true,"img":false}]}
{"op":"mcm","clk":"11550909010","pt":1719505723170,"mc":[{"id":"1.230178176","rc":[{"atb":[[4.7,0]],"id":52385913},{"atb":[[46,13.33]],"id":52385893}],"con":true,"img":false}]}
{"op":"mcm","clk":"11550909088","pt":1719505724501,"mc":[{"id":"1.230178176","rc":[{"atb":[[36,7.86],[26,0]],"id":52385917}],"con":true,"img":false}]}
{"op":"mcm","clk":"11550909118","pt":1719505725081,"mc":[{"id":"1.230178176","rc":[{"atl":[[40,0]],"id":52385914}],"con":true,"img":false}]}
{"op":"mcm","clk":"11550909124","pt":1719505725187,"mc":[{"id":"1.230178176","rc":[{"atl":[[42,14.63]],"id":52385914}],"con":true,"img":false}]}
{"op":"mcm","clk":"11550909204","pt":1719505726882,"mc":[{"id":"1.230178176","rc":[{"atb":[[11.5,38.42]],"id":52385905}],"con":true,"img":false}]}
{"op":"mcm","clk":"11550909213","pt":1719505727087,"mc":[{"id":"1.230178176","rc":[{"atb":[[10,8]],"id":52385905}],"con":true,"img":false}]}
{"op":"mcm","clk":"11550909280","pt":1719505728388,"mc":[{"id":"1.230178176","rc":[{"atb":[[1.76,0],[1.07,156.96]],"id":52385912},{"atl":[[46,0],[55,2]],"id":52385912},{"atl":[[220,2],[240,0]],"id":52385918},{"atb":[[70,0]],"id":52385889},{"atl":[[270,2],[290,0]],"id":52385889},{"atb":[[4,33.33],[17.5,33.28],[4.6,0]],"id":52385914},{"atb":[[17,6.25],[20,0]],"id":52385885},{"atl":[[100,2],[120,0]],"id":52385890},{"atb":[[8,0],[9.8,11.36]],"id":52385892},{"atb":[[12,32.06],[4.1,0],[3.65,37.74]],"id":52385913},{"atb":[[46,0]],"id":52385893},{"atb":[[3.8,0],[3.5,40]],"id":52385899}],"con":true,"img":false}]}
{"op":"mcm","clk":"11550909287","pt":1719505728494,"mc":[{"id":"1.230178176","rc":[{"atb":[[42,11.34],[26,4],[30,0]],"id":52385889},{"atb":[[12,0],[9.8,0]],"id":52385913},{"atb":[[23,15]],"id":52385893}],"con":true,"img":false}]}
{"op":"mcm","clk":"11550909293","pt":1719505728600,"mc":[{"id":"1.230178176","rc":[{"atb":[[17.5,0],[15.5,1.63]],"id":52385914},{"atb":[[11.5,57.14]],"id":52385913}],"con":true,"img":false}]}
{"op":"mcm","clk":"11550909297","pt":1719505728699,"mc":[{"id":"1.230178176","rc":[{"atb":[[17,37.5]],"id":52385914}],"con":true,"img":false}]}
{"op":"mcm","clk":"11550909307","pt":1719505728757,"mc":[{"id":"1.230178176","rc":[{"atb":[[9,0]],"id":52385913}],"con":true,"img":false}]}
{"op":"mcm","clk":"11550909332","pt":1719505729179,"mc":[{"id":"1.230178176","rc":[{"atl":[[29,21.43]],"id":52385897}],"con":true,"img":false}]}
{"op":"mcm","clk":"11550909346","pt":1719505729398,"mc":[{"id":"1.230178176","rc":[{"atl":[[34,2]],"id":52385897}],"con":true,"img":false}]}
{"op":"mcm","clk":"11550909433","pt":1719505731086,"mc":[{"id":"1.230178176","rc":[{"atb":[[10.5,0]],"id":52385912},{"atl":[[34,0]],"id":52385912},{"atb":[[10.5,9.64]],"id":52385906},{"atl":[[30,0]],"id":52385906},{"atl":[[170,0]],"id":52385920},{"atl":[[65,0]],"id":52385890},{"atb":[[5.7,0]],"id":52385898},{"atl":[[17,0]],"id":52385898},{"atb":[[12.5,0]],"id":52385900},{"atb":[[9.2,0]],"id":52385913},{"atl":[[36,0]],"id":52385913},{"atb":[[16.5,0]],"id":52385907},{"atl":[[85,0]],"id":52385907},{"atb":[[21,0]],"id":52385919},{"atl":[[75,0]],"id":52385919},{"atl":[[34,0]],"id":52385897},{"atl":[[22,2.5]],"id":52385905},{"atb":[[5.7,0]],"id":52385899},{"atl":[[22,0]],"id":52385899}],"con":true,"img":false}]}
{"op":"mcm","clk":"11550909445","pt":1719505731285,"mc":[{"id":"1.230178176","rc":[{"atb":[[11.5,4.1]],"id":52385912},{"atl":[[30,2.82]],"id":52385912},{"atb":[[9.2,6.16]],"id":52385906},{"atl":[[18.5,3.14]],"id":52385906},{"atl":[[55,2],[60,0]],"id":52385890},{"atb":[[13.5,3.3]],"id":52385904},{"atl":[[40,3.26]],"id":52385904},{"atb":[[7.4,6]],"id":52385898},{"atl":[[13,4]],"id":52385898},{"atb":[[13.5,4]],"id":52385900},{"atb":[[8.4,4.88]],"id":52385913},{"atl":[[21,4.4]],"id":52385913},{"atb":[[14,4]],"id":52385907},{"atl":[[34,3.12]],"id":52385907},{"atb":[[23,3]],"id":52385919},{"atl":[[55,2.7]],"id":52385919},{"atl":[[28,3]],"id":52385897},{"atb":[[22,2.8]],"id":52385891},{"atl":[[55,3]],"id":52385891},{"atl":[[20,3.2]],"id":52385905},{"atb":[[10,4.7]],"id":52385899},{"atl":[[20,3]],"id":52385899}],"con":true,"img":false}]}
{"op":"mcm","clk":"11550909450","pt":1719505731389,"mc":[{"id":"1.230178176","rc":[{"atb":[[11,0],[12,28]],"id":52385912},{"atl":[[30,23.51]],"id":52385912},{"atl":[[50,12.24]],"id":52385890},{"atl":[[40,2.56],[46,5]],"id":52385907},{"atb":[[24,20]],"id":52385919},{"atb":[[22,20.8]],"id":52385891},{"atl":[[80,2],[90,0]],"id":52385891},{"atl":[[19.5,26.12]],"id":52385905},{"atl":[[20,34.4],[21,0]],"id":52385899}],"con":true,"img":false}]}
{"op":"mcm","clk":"11550909457","pt":1719505731595,"mc":[{"id":"1.230178176","rc":[{"atl":[[32,2.5]],"id":52385912},{"atb":[[22,0]],"id":52385919},{"atb":[[21,0]],"id":52385891},{"atl":[[21,0]],"id":52385905}],"con":true,"img":false}]}
{"op":"mcm","clk":"11550909468","pt":1719505731801,"mc":[{"id":"1.230178176","rc":[{"atb":[[20,0]],"id":52385919}],"con":true,"img":false}]}
{"op":"mcm","clk":"11550909549","pt":1719505733383,"mc":[{"id":"1.230178176","rc":[{"atl":[[120,2]],"id":52385892}],"con":true,"img":false}]}
{"op":"mcm","clk":"11550909552","pt":1719505733478,"mc":[{"id":"1.230178176","rc":[{"atl":[[140,0]],"id":52385892}],"con":true,"img":false}]}
{"op":"mcm","clk":"11550909589","pt":1719505734282,"mc":[{"id":"1.230178176","rc":[{"atb":[[50,12.24]],"id":52385889},{"atl":[[180,3.35]],"id":52385889},{"atl":[[38,16.22]],"id":52385904},{"atl":[[260,2.32]],"id":52385882},{"atl":[[50,12.24]],"id":52385891},{"atb":[[27,20]],"id":52385893}],"con":true,"img":false}]}
{"op":"mcm","clk":"11550909593","pt":1719505734386,"mc":[{"id":"1.230178176","rc":[{"atl":[[18.5,31.46]],"id":52385906},{"atl":[[40,15.38]],"id":52385914},{"atl":[[160,3.77]],"id":52385885},{"atb":[[24,23.2]],"id":52385890},{"atb":[[9,45]],"id":52385898},{"atl":[[13,38]],"id":52385898},{"atb":[[13.5,17.6]],"id":52385900},{"atl":[[20,18.76]],"id":52385913},{"atl":[[32,14.24]],"id":52385907},{"atl":[[55,13.81]],"id":52385919},{"atb":[[28,20]],"id":52385903},{"atb":[[10.5,31.4]],"id":52385899}],"con":true,"img":false}]}
{"op":"mcm","clk":"11550909599","pt":1719505734487,"mc":[{"id":"1.230178176","rc":[{"atb":[[42,0]],"id":52385889},{"atl":[[190,0]],"id":52385889},{"atl":[[65,5],[50,2.04]],"id":52385914},{"atl":[[42,0]],"id":52385904},{"atl":[[270,0]],"id":52385882},{"atl":[[60,0]],"id":52385891},{"atb":[[23,0]],"id":52385893}],"con":true,"img":false}]}
{"op":"mcm","clk":"11550909605","pt":1719505734603,"mc":[{"id":"1.230178176","rc":[{"atl":[[19,0]],"id":52385906},{"atl":[[170,0]],"id":52385885},{"atb":[[23,0]],"id":52385890},{"atb":[[8.2,0]],"id":52385898},{"atl":[[13.5,0]],"id":52385898},{"atb":[[13,11]],"id":52385900},{"atl":[[22,0]],"id":52385913},{"atl":[[36,0]],"id":52385907},{"atb":[[9.8,0]],"id":52385899}],"con":true,"img":false}]}
{"op":"mcm","clk":"11550909612","pt":1719505734694,"mc":[{"id":"1.230178176","rc":[{"atl":[[42,0]],"id":52385914},{"atl":[[60,0]],"id":52385919},{"atb":[[19.5,0]],"id":52385903}],"con":true,"img":false}]}
{"op":"mcm","clk":"11550909618","pt":1719505734797,"mc":[{"id":"1.230178176","rc":[{"atb":[[9,0]],"id":52385899}],"con":true,"img":false}]}
{"op":"mcm","clk":"11550910027","pt":1719505742091,"mc":[{"id":"1.230178176","rc":[{"atl":[[28,23.25]],"id":52385897}],"con":true,"img":false}]}
{"op":"mcm","clk":"11550910038","pt":1719505742295,"mc":[{"id":"1.230178176","rc":[{"atl":[[29,0]],"id":52385897}],"con":true,"img":false}]}
{"op":"mcm","clk":"11550910106","pt":1719505743493,"mc":[{"id":"1.230178176","rc":[{"atb":[[1.07,0]],"id":52385912},{"atb":[[17,0],[19.5,5.41]],"id":52385885},{"atb":[[1.9,0],[2.08,92.59]],"id":52385911},{"atb":[[34,3.03],[42,0]],"id":52385886},{"atb":[[40,2.56],[48,5]],"id":52385882},{"atb":[[3.15,46.51],[3.5,0]],"id":52385899},{"atl":[[38,2.7],[23,0],[26,2.5],[27,0],[30,5]],"id":52385899}],"con":true,"img":false}]}
{"op":"mcm","clk":"11550910187","pt":1719505744678,"mc":[{"id":"1.230178176","rc":[{"atb":[[70,8.7]],"id":52385889},{"atb":[[11.5,0]],"id":52385905}],"con":true,"img":false}]}
{"op":"mcm","clk":"11550910196","pt":1719505744781,"mc":[{"id":"1.230178176","rc":[{"atb":[[50,0]],"id":52385889},{"atb":[[11,26.12]],"id":52385905}],"con":true,"img":false}]}
{"op":"mcm","clk":"11550910205","pt":1719505745007,"mc":[{"id":"1.230178176","rc":[{"atb":[[11,0]],"id":52385905}],"con":true,"img":false}]}
{"op":"mcm","clk":"11550910210","pt":1719505745095,"mc":[{"id":"1.230178176","rc":[{"atb":[[10,24.52]],"id":52385905}],"con":true,"img":false}]}
{"op":"mcm","clk":"11550910303","pt":1719505746591,"mc":[{"id":"1.230178176","rc":[{"atb":[[26,24]],"id":52385921}],"con":true,"img":false}]}
{"op":"mcm","clk":"11550910316","pt":1719505746795,"mc":[{"id":"1.230178176","rc":[{"atb":[[25,0]],"id":52385921}],"con":true,"img":false}]}
{"op":"mcm","clk":"11550910339","pt":1719505747304,"mc":[{"id":"1.230178176","rc":[{"atb":[[9.2,22]],"id":52385898},{"atb":[[34,18.18]],"id":52385903}],"con":true,"img":false}]}
{"op":"mcm","clk":"11550910347","pt":1719505747511,"mc":[{"id":"1.230178176","rc":[{"atb":[[9,11]],"id":52385898}],"con":true,"img":false}]}
{"op":"mcm","clk":"11550910354","pt":1719505747615,"mc":[{"id":"1.230178176","rc":[{"atb":[[28,0]],"id":52385903}],"con":true,"img":false}]}
{"op":"mcm","clk":"11550910398","pt":1719505748395,"mc":[{"id":"1.230178176","rc":[{"atb":[[1.56,100]],"id":52385912},{"atb":[[10.5,10.53]],"id":52385896}],"con":true,"img":false}]}
{"op":"mcm","clk":"11550910405","pt":1719505748497,"mc":[{"id":"1.230178176","rc":[{"atb":[[9,0]],"id":52385896}],"con":true,"img":false}]}
{"op":"mcm","clk":"11550910458","pt":1719505749422,"mc":[{"id":"1.230178176","rc":[{"atb":[[3.25,44.44],[2.08,0]],"id":52385911},{"atb":[[3.15,0],[3.65,37.74]],"id":52385899}],"con":true,"img":false}]}
{"op":"mcm","clk":"11550910539","pt":1719505750717,"mc":[{"id":"1.230178176","rc":[{"atb":[[20,18.6]],"id":52385904}],"con":true,"img":false}]}
{"op":"mcm","clk":"11550910553","pt":1719505750928,"mc":[{"id":"1.230178176","rc":[{"atb":[[17.5,0]],"id":52385904}],"con":true,"img":false}]}
{"op":"mcm","clk":"11550910664","pt":1719505752705,"mc":[{"id":"1.230178176","rc":[{"atl":[[260,0],[250,2.41]],"id":52385882}],"con":true,"img":false}]}
{"op":"mcm","clk":"11550910673","pt":1719505752915,"mc":[{"id":"1.230178176","rc":[{"atl":[[250,0]],"id":52385882}],"con":true,"img":false}]}
{"op":"mcm","clk":"11550910678","pt":1719505753012,"mc":[{"id":"1.230178176","rc":[{"atl":[[270,2.23]],"id":52385882}],"con":true,"img":false}]}
{"op":"mcm","clk":"11550910712","pt":1719505753591,"mc":[{"id":"1.230178176","rc":[{"atb":[[1.46,100],[1.56,0]],"id":52385912},{"atb":[[10,0],[8.8,11]],"id":52385904},{"atb":[[3.65,0]],"id":52385913},{"atl":[[38,5.2],[40,0]],"id":52385907}],"con":true,"img":false}]}
{"op":"mcm","clk":"11550910719","pt":1719505753695,"mc":[{"id":"1.230178176","rc":[{"atb":[[10.5,0],[8.8,12.82]],"id":52385896},{"atb":[[3.9,34.48]],"id":52385913}],"con":true,"img":false}]}
{"op":"mcm","clk":"11550910866","pt":1719505756380,"mc":[{"id":"1.230178176","rc":[{"atb":[[16.5,27.6]],"id":52385900}],"con":true,"img":false}]}
{"op":"mcm","clk":"11550910874","pt":1719505756588,"mc":[{"id":"1.230178176","rc":[{"atb":[[16.5,0],[13.5,4]],"id":52385900}],"con":true,"img":false}]}
{"op":"mcm","clk":"11550910881","pt":1719505756697,"mc":[{"id":"1.230178176","rc":[{"atb":[[16,40]],"id":52385900}],"con":true,"img":false}]}
{"op":"mcm","clk":"11550910914","pt":1719505757319,"mc":[{"id":"1.230178176","rc":[{"atb":[[16,0]],"id":52385900}],"con":true,"img":false}]}
{"op":"mcm","clk":"11550910918","pt":1719505757417,"mc":[{"id":"1.230178176","rc":[{"atb":[[15.5,30]],"id":52385900}],"con":true,"img":false}]}
{"op":"mcm","clk":"11550910951","pt":1719505758212,"mc":[{"id":"1.230178176","rc":[{"atb":[[11.5,0]],"id":52385912},{"atl":[[55,0]],"id":52385890},{"atl":[[40,0]],"id":52385904},{"atb":[[8.4,0]],"id":52385913},{"atl":[[21,0]],"id":52385913},{"atb":[[14,0]],"id":52385907},{"atl":[[34,0]],"id":52385907},{"atb":[[23,0]],"id":52385919},{"atb":[[22,18]],"id":52385891},{"atl":[[55,0]],"id":52385891},{"atb":[[9.2,0]],"id":52385905},{"atl":[[20,0]],"id":52385905},{"atb":[[10,0]],"id":52385899}],"con":true,"img":false}]}
{"op":"mcm","clk":"11550910957","pt":1719505758308,"mc":[{"id":"1.230178176","rc":[{"atb":[[12.5,4]],"id":52385912},{"atb":[[17.5,5.1]],"id":52385914},{"atl":[[48,2.2]],"id":52385890},{"atb":[[18.5,4]],"id":52385892},{"atl":[[75,2]],"id":52385892},{"atl":[[36,2.1]],"id":52385904},{"atb":[[16.5,3.3]],"id":52385911},{"atl":[[55,2.46]],"id":52385911},{"atb":[[12,5.6]],"id":52385913},{"atl":[[25,3]],"id":52385913},{"atb":[[12,5.2]],"id":52385907},{"atl":[[30,2]],"id":52385907},{"atb":[[25,2.8]],"id":52385919},{"atb":[[15.5,4.41]],"id":52385921},{"atl":[[55,2.9]],"id":52385921},{"atb":[[19.5,6.5]],"id":52385891},{"atl":[[48,2]],"id":52385891},{"atb":[[8.4,5.93]],"id":52385905},{"atl":[[19,3.47]],"id":52385905},{"atb":[[11,4.4]],"id":52385899}],"con":true,"img":false}]}
{"op":"mcm","clk":"11550910962","pt":1719505758405,"mc":[{"id":"1.230178176","rc":[{"atb":[[13,28]],"id":52385912},{"atl":[[48,14.97],[50,0]],"id":52385890},{"atl":[[70,8.7]],"id":52385892},{"atl":[[34,18.18],[38,0]],"id":52385904},{"atl":[[20,0]],"id":52385913},{"atl":[[32,0],[29,20.8]],"id":52385907},{"atb":[[24,0]],"id":52385919},{"atl":[[85,7],[90,0]],"id":52385921},{"atb":[[22,0]],"id":52385891},{"atl":[[46,13.33],[50,0]],"id":52385891},{"atl":[[18.5,34.29],[19.5,0]],"id":52385905},{"atb":[[10.5,0],[11.5,18.8]],"id":52385899}],"con":true,"img":false}]}
{"op":"mcm","clk":"11550910970","pt":1719505758524,"mc":[{"id":"1.230178176","rc":[{"atb":[[12,0]],"id":52385912},{"atb":[[17.5,20.3]],"id":52385914},{"atl":[[80,0]],"id":52385892},{"atl":[[50,12.24]],"id":52385911},{"atb":[[12,25.8]],"id":52385913},{"atl":[[32,3.23],[21,20.2]],"id":52385913},{"atb":[[26,15.6]],"id":52385919},{"atb":[[26,0]],"id":52385921},{"atl":[[50,12.24]],"id":52385921},{"atb":[[22,25]],"id":52385891}],"con":true,"img":false}]}
{"op":"mcm","clk":"11550910974","pt":1719505758621,"mc":[{"id":"1.230178176","rc":[{"atb":[[17,0]],"id":52385914},{"atl":[[60,0]],"id":52385911},{"atl":[[34,5]],"id":52385913},{"atb":[[26,24]],"id":52385921}],"con":true,"img":false}]}
{"op":"mcm","clk":"11550910980","pt":1719505758723,"mc":[{"id":"1.230178176","rc":[{"atb":[[26,0]],"id":52385889},{"atb":[[4,0],[3.65,37.74]],"id":52385914},{"atb":[[21,5]],"id":52385883},{"atb":[[19.5,0],[12,9.09]],"id":52385885},{"atb":[[3.25,0],[2.7,58.82]],"id":52385911},{"atb":[[11.5,0]],"id":52385913},{"atl":[[21,0]],"id":52385913},{"atb":[[34,0],[40,2.56]],"id":52385886},{"atl":[[60,0]],"id":52385921},{"atb":[[48,7.13]],"id":52385882},{"atb":[[12,0]],"id":52385897},{"atb":[[22,0]],"id":52385891},{"atb":[[3.65,0]],"id":52385899},{"atl":[[19.5,18.8]],"id":52385899}],"con":true,"img":false}]}
{"op":"mcm","clk":"11550910986","pt":1719505758828,"mc":[{"id":"1.230178176","rc":[{"atb":[[30,3.45]],"id":52385889},{"atb":[[26,0]],"id":52385883},{"atb":[[8.8,0]],"id":52385896},{"atb":[[9.2,0]],"id":52385898},{"atl":[[22,28.57]],"id":52385913},{"atb":[[40,0]],"id":52385882},{"atb":[[26,24]],"id":52385891},{"atb":[[4.4,29.41]],"id":52385899},{"atl":[[20,3]],"id":52385899}],"con":true,"img":false}]}
{"op":"mcm","clk":"11550910995","pt":1719505758923,"mc":[{"id":"1.230178176","rc":[{"atb":[[7.2,16.13]],"id":52385896},{"atb":[[13,0]],"id":52385900}],"con":true,"img":false}]}
{"op":"mcm","clk":"11550911002","pt":1719505759027,"mc":[{"id":"1.230178176","rc":[{"atb":[[26,0]],"id":52385921}],"con":true,"img":false}]}
{"op":"mcm","clk":"11550911008","pt":1719505759084,"mc":[{"id":"1.230178176","rc":[{"atb":[[10,0]],"id":52385912},{"atl":[[22,0]],"id":52385913},{"atb":[[24,24.82]],"id":52385921}],"con":true,"img":false}]}
{"op":"mcm","clk":"11550911016","pt":1719505759290,"mc":[{"id":"1.230178176","rc":[{"atb":[[24,0]],"id":52385921}],"con":true,"img":false}]}
{"op":"mcm","clk":"11550911025","pt":1719505759395,"mc":[{"id":"1.230178176","rc":[{"atb":[[1.46,0],[2.34,74.63]],"id":52385912},{"atb":[[11,0]],"id":52385914},{"atb":[[17,22.62]],"id":52385921}],"con":true,"img":false}]}
{"op":"mcm","clk":"11550911032","pt":1719505759496,"mc":[{"id":"1.230178176","rc":[{"atb":[[4.3,30.3],[3.9,0]],"id":52385913}],"con":true,"img":false}]}
{"op":"mcm","clk":"11550911040","pt":1719505759600,"mc":[{"id":"1.230178176","rc":[{"atb":[[9,0]],"id":52385898}],"con":true,"img":false}]}
{"op":"mcm","clk":"11550911047","pt":1719505759702,"mc":[{"id":"1.230178176","rc":[{"atb":[[8,11],[7.4,28]],"id":52385898}],"con":true,"img":false}]}
{"op":"mcm","clk":"11550911050","pt":1719505759806,"mc":[{"id":"1.230178176","rc":[{"atb":[[4,5],[4.4,2.5]],"id":52385898}],"con":true,"img":false}]}
{"op":"mcm","clk":"11550911055","pt":1719505759913,"mc":[{"id":"1.230178176","rc":[{"atb":[[8,43]],"id":52385898}],"con":true,"img":false}]}
{"op":"mcm","clk":"11550911067","pt":1719505760113,"mc":[{"id":"1.230178176","rc":[{"atb":[[7.4,6]],"id":52385898}],"con":true,"img":false}]}
{"op":"mcm","clk":"11550911211","pt":1719505762917,"mc":[{"id":"1.230178176","rc":[{"atl":[[23,15]],"id":52385913}],"con":true,"img":false}]}
{"op":"mcm","clk":"11550911231","pt":1719505763332,"mc":[{"id":"1.230178176","rc":[{"atb":[[7.8,5],[8.6,2.5]],"id":52385912},{"atb":[[36,0],[29,0]],"id":52385883},{"atl":[[80,5],[60,2.5]],"id":52385890},{"atl":[[55,0]],"id":52385904},{"atb":[[8,2.5],[7.2,5]],"id":52385900},{"atb":[[5.6,0],[6.4,2.5],[5.8,5],[6,2]],"id":52385913},{"atl":[[38,2.7],[46,0]],"id":52385907},{"atb":[[40,5],[48,2.5]],"id":52385917},{"atl":[[75,5],[55,2.5]],"id":52385891},{"atl":[[130,5],[95,2.5]],"id":52385893}],"con":true,"img":false}]}
{"op":"mcm","clk":"11550911238","pt":1719505763436,"mc":[{"id":"1.230178176","rc":[{"atb":[[21,0],[25,0],[26,5],[30,2.5]],"id":52385910},{"atb":[[7.4,0],[6.6,0]],"id":52385912},{"atl":[[130,0],[160,5],[170,0],[120,7.54]],"id":52385918},{"atl":[[180,5.85],[200,0],[220,5],[240,0]],"id":52385889},{"atb":[[8,0],[9,2.5],[8.2,5],[7.2,0]],"id":52385914},{"atb":[[34,5],[42,2.5]],"id":52385883},{"atb":[[40,0],[44,5],[48,0],[55,2.5]],"id":52385885},{"atb":[[16.5,2.5],[13,0],[14.5,5],[15,6]],"id":52385896},{"atl":[[70,0],[90,0]],"id":52385890},{"atl":[[80,2.5],[85,0],[100,5],[110,0]],"id":52385892},{"atl":[[36,4.6]],"id":52385904},{"atb":[[7.8,0],[7,16.67]],"id":52385900},{"atb":[[16,9.5],[13.5,0],[15.5,0]],"id":52385911},{"atl":[[36,2.5],[44,5]],"id":52385907},{"atb":[[65,0],[75,2.5],[48,0],[55,5]],"id":52385886},{"atb":[[12,0],[12.5,5],[14,0],[14.5,2.5]],"id":52385921},{"atb":[[34,0],[38,5],[42,0],[46,2.5]],"id":52385884},{"atb":[[36,2.86],[44,0]],"id":52385917},{"atl":[[36,2.5],[40,0],[44,5],[48,0]],"id":52385897},{"atl":[[65,0],[85,0]],"id":52385891},{"atl":[[150,0],[90,6.74],[110,0]],"id":52385893},{"atl":[[21,2.5],[22,0],[25,5],[26,0]],"id":52385905},{"atb":[[6.4,0],[5.8,0],[6.2,5],[7,2.5]],"id":52385899}],"con":true,"img":false}]}
{"op":"mcm","clk":"11550911245","pt":1719505763539,"mc":[{"id":"1.230178176","rc":[{"atb":[[42,2.44]],"id":52385917},{"atl":[[150,2]],"id":52385893}],"con":true,"img":false}]}
{"op":"mcm","clk":"11550911251","pt":1719505763633,"mc":[{"id":"1.230178176","rc":[{"atb":[[44,13.95]],"id":52385883},{"atb":[[60,10.17]],"id":52385885},{"atb":[[36,0]],"id":52385917},{"atl":[[160,0]],"id":52385893},{"atl":[[25,2.5],[29,5]],"id":52385899}],"con":true,"img":false}]}
{"op":"mcm","clk":"11550911258","pt":1719505763738,"mc":[{"id":"1.230178176","rc":[{"atl":[[100,0]],"id":52385893},{"atl":[[26,0],[30,0]],"id":52385899}],"con":true,"img":false}]}
{"op":"mcm","clk":"11550911268","pt":1719505763794,"mc":[{"id":"1.230178176","rc":[{"atb":[[40,0]],"id":52385883},{"atb":[[50,0]],"id":52385885}],"con":true,"img":false}]}
{"op":"mcm","clk":"11550911278","pt":1719505764001,"mc":[{"id":"1.230178176","rc":[{"atl":[[270,4.73],[310,5]],"id":52385882}],"con":true,"img":false}]}
{"op":"mcm","clk":"11550911286","pt":1719505764107,"mc":[{"id":"1.230178176","rc":[{"atl":[[280,0],[320,0]],"id":52385882}],"con":true,"img":false}]}
{"op":"mcm","clk":"11550911304","pt":1719505764415,"mc":[{"id":"1.230178176","rc":[{"atb":[[4,33.33],[3.65,0]],"id":52385914},{"atb":[[2.7,0]],"id":52385911}],"con":true,"img":false}]}
{"op":"mcm","clk":"11550911311","pt":1719505764521,"mc":[{"id":"1.230178176","rc":[{"atb":[[3.35,42.55]],"id":52385911}],"con":true,"img":false}]}
{"op":"mcm","clk":"11550911352","pt":1719505765233,"mc":[{"id":"1.230178176","rc":[{"atl":[[260,2.32]],"id":52385882}],"con":true,"img":false}]}
{"op":"mcm","clk":"11550911364","pt":1719505765395,"mc":[{"id":"1.230178176","rc":[{"atl":[[270,2.5]],"id":52385882}],"con":true,"img":false}]}
{"op":"mcm","clk":"11550911387","pt":1719505765704,"mc":[{"id":"1.230178176","rc":[{"atl":[[250,2.41]],"id":52385882}],"con":true,"img":false}]}
{"op":"mcm","clk":"11550911403","pt":1719505765909,"mc":[{"id":"1.230178176","rc":[{"atl":[[260,0]],"id":52385882}],"con":true,"img":false}]}
{"op":"mcm","clk":"11550911605","pt":1719505769215,"mc":[{"id":"1.230178176","rc":[{"atb":[[2.16,86.21],[2.34,0]],"id":52385912},{"atb":[[21,0],[24,4.35]],"id":52385883},{"atb":[[18.5,5.71],[12,0]],"id":52385885},{"atb":[[7.2,0],[8.6,11]],"id":52385896},{"atl":[[70,11.2],[75,0],[90,5],[95,0]],"id":52385903}],"con":true,"img":false}]}
{"op":"mcm","clk":"11550911670","pt":1719505770242,"mc":[{"id":"1.230178176","rc":[{"atb":[[3.6,38.46],[3.35,0]],"id":52385911},{"atb":[[10.5,37.98]],"id":52385905}],"con":true,"img":false}]}
{"op":"mcm","clk":"11550911684","pt":1719505770401,"mc":[{"id":"1.230178176","rc":[{"atb":[[10,8]],"id":52385905}],"con":true,"img":false}]}
{"op":"mcm","clk":"11550911692","pt":1719505770508,"mc":[{"id":"1.230178176","rc":[{"atb":[[26,0]],"id":52385891}],"con":true,"img":false}]}
{"op":"mcm","clk":"11550911695","pt":1719505770615,"mc":[{"id":"1.230178176","rc":[{"atb":[[25,25]],"id":52385891}],"con":true,"img":false}]}
{"op":"mcm","clk":"11550911703","pt":1719505770714,"mc":[{"id":"1.230178176","rc":[{"atb":[[75,8.11]],"id":52385889},{"atb":[[36,17.14]],"id":52385903}],"con":true,"img":false}]}
{"op":"mcm","clk":"11550911710","pt":1719505770820,"mc":[{"id":"1.230178176","rc":[{"atl":[[70,5],[75,0],[50,14.74],[55,0]],"id":52385920},{"atl":[[280,0],[210,2.5],[240,0],[250,5]],"id":52385886},{"atl":[[130,2.5],[150,0],[170,5],[190,0]],"id":52385884},{"atb":[[25,0]],"id":52385891}],"con":true,"img":false}]}
{"op":"mcm","clk":"11550911716","pt":1719505770922,"mc":[{"id":"1.230178176","rc":[{"atl":[[75,2],[80,0]],"id":52385920},{"atb":[[70,0]],"id":52385889},{"atl":[[220,2.74]],"id":52385886},{"atb":[[25,14.62]],"id":52385921},{"atl":[[130,7.15]],"id":52385884},{"atb":[[23,25]],"id":52385891},{"atb":[[34,0]],"id":52385903}],"con":true,"img":false}]}
{"op":"mcm","clk":"11550911720","pt":1719505771021,"mc":[{"id":"1.230178176","rc":[{"atl":[[80,2]],"id":52385920},{"atb":[[17,8]],"id":52385921},{"atl":[[140,0]],"id":52385884}],"con":true,"img":false}]}
{"op":"mcm","clk":"11550911727","pt":1719505771123,"mc":[{"id":"1.230178176","rc":[{"atl":[[75,0]],"id":52385920},{"atl":[[230,0]],"id":52385886}],"con":true,"img":false}]}
{"op":"mcm","clk":"11550911909","pt":1719505774431,"mc":[{"id":"1.230178176","rc":[{"atb":[[1.79,100],[2.16,0]],"id":52385912},{"atb":[[18.5,10],[3.2,45.45]],"id":52385914},{"atl":[[50,0],[55,2]],"id":52385914},{"atb":[[9.6,11],[8.6,0]],"id":52385896},{"atb":[[3.6,0],[2.92,52.08]],"id":52385911},{"atb":[[3.55,39.22]],"id":52385913},{"atb":[[3.85,35.09],[4.4,0]],"id":52385899}],"con":true,"img":false}]}
{"op":"mcm","clk":"11550911914","pt":1719505774536,"mc":[{"id":"1.230178176","rc":[{"atb":[[4,0]],"id":52385914},{"atb":[[4.3,0]],"id":52385913}],"con":true,"img":false}]}
{"op":"mcm","clk":"11550911922","pt":1719505774635,"mc":[{"id":"1.230178176","rc":[{"atb":[[1.79,0],[1.16,156.96]],"id":52385912},{"atb":[[17.5,5.1]],"id":52385914},{"atb":[[2.92,0]],"id":52385911}],"con":true,"img":false}]}
{"op":"mcm","clk":"11550911929","pt":1719505774742,"mc":[{"id":"1.230178176","rc":[{"atb":[[1.75,100]],"id":52385911}],"con":true,"img":false}]}
{"op":"mcm","clk":"11550911967","pt":1719505775310,"mc":[{"id":"1.230178176","rc":[{"atl":[[15.5,27.86]],"id":52385905}],"con":true,"img":false}]}
{"op":"mcm","clk":"11550911976","pt":1719505775513,"mc":[{"id":"1.230178176","rc":[{"atl":[[18.5,0]],"id":52385905}],"con":true,"img":false}]}
{"op":"mcm","clk":"11550912298","pt":1719505780126,"mc":[{"id":"1.230178176","rc":[{"atb":[[48,0]],"id":52385918}],"con":true,"img":false}]}
{"op":"mcm","clk":"11550912304","pt":1719505780229,"mc":[{"id":"1.230178176","rc":[{"atb":[[46,13.33]],"id":52385918},{"atb":[[25,0]],"id":52385921}],"con":true,"img":false}]}
{"op":"mcm","clk":"11550912308","pt":1719505780327,"mc":[{"id":"1.230178176","rc":[{"atb":[[19.5,24.82]],"id":52385921}],"con":true,"img":false}]}
{"op":"mcm","clk":"11550912316","pt":1719505780434,"mc":[{"id":"1.230178176","rc":[{"atb":[[46,0]],"id":52385918},{"atb":[[19.5,0]],"id":52385921}],"con":true,"img":false}]}
{"op":"mcm","clk":"11550912320","pt":1719505780533,"mc":[{"id":"1.230178176","rc":[{"atb":[[48,12.77]],"id":52385918},{"atb":[[27,23.08]],"id":52385921}],"con":true,"img":false}]}
{"op":"mcm","clk":"11550912327","pt":1719505780637,"mc":[{"id":"1.230178176","rc":[{"atb":[[1.16,0]],"id":52385912},{"atb":[[27,3.85]],"id":52385883},{"atb":[[1.33,100]],"id":52385911}],"con":true,"img":false}]}
{"op":"mcm","clk":"11550912336","pt":1719505780740,"mc":[{"id":"1.230178176","rc":[{"atb":[[1.09,156.96]],"id":52385912},{"atb":[[24,0]],"id":52385883},{"atb":[[1.75,0]],"id":52385911}],"con":true,"img":false}]}
{"op":"mcm","clk":"11550912352","pt":1719505781148,"mc":[{"id":"1.230178176","rc":[{"atb":[[27,0]],"id":52385921}],"con":true,"img":false}]}
{"op":"mcm","clk":"11550912356","pt":1719505781252,"mc":[{"id":"1.230178176","rc":[{"atb":[[19.5,24.82]],"id":52385921}],"con":true,"img":false}]}
{"op":"mcm","clk":"11550912362","pt":1719505781312,"mc":[{"id":"1.230178176","rc":[{"atl":[[160,0]],"id":52385885},{"atl":[[210,0],[220,0],[250,0]],"id":52385886},{"atl":[[130,0],[170,0],[210,2.5],[250,5]],"id":52385884},{"atb":[[17,0],[17.5,5],[19,0],[19.5,2.5]],"id":52385903}],"con":true,"img":false}]}
{"op":"mcm","clk":"11550912371","pt":1719505781417,"mc":[{"id":"1.230178176","rc":[{"atl":[[180,5.85]],"id":52385885},{"atl":[[310,1.94],[340,2.5],[380,5]],"id":52385886},{"atl":[[140,4.32],[220,0],[250,7]],"id":52385884}],"con":true,"img":false}]}
{"op":"mcm","clk":"11550912375","pt":1719505781516,"mc":[{"id":"1.230178176","rc":[{"atl":[[24,13.6]],"id":52385900},{"atl":[[380,7]],"id":52385886}],"con":true,"img":false}]}
{"op":"mcm","clk":"11550912380","pt":1719505781620,"mc":[{"id":"1.230178176","rc":[{"atl":[[320,0]],"id":52385886},{"atl":[[140,0]],"id":52385884}],"con":true,"img":false}]}
{"op":"mcm","clk":"11550912387","pt":1719505781724,"mc":[{"id":"1.230178176","rc":[{"atl":[[25,0]],"id":52385900},{"atl":[[150,4.03]],"id":52385884}],"con":true,"img":false}]}
{"op":"mcm","clk":"11550912391","pt":1719505781829,"mc":[{"id":"1.230178176","rc":[{"atl":[[150,0]],"id":52385883},{"atl":[[320,2.5],[180,0],[360,5],[220,0]],"id":52385885},{"atl":[[310,0]],"id":52385886},{"atl":[[270,0],[310,0],[250,0]],"id":52385882}],"con":true,"img":false}]}
{"op":"mcm","clk":"11550912397","pt":1719505781941,"mc":[{"id":"1.230178176","rc":[{"atl":[[95,0]],"id":52385910},{"atl":[[150,4.03]],"id":52385883},{"atl":[[270,2.23],[280,0],[300,2]],"id":52385885},{"atb":[[20,0]],"id":52385904},{"atl":[[330,1.82]],"id":52385886},{"atl":[[340,1.77]],"id":52385882},{"atl":[[150,0]],"id":52385884}],"con":true,"img":false}]}
{"op":"mcm","clk":"11550912405","pt":1719505782045,"mc":[{"id":"1.230178176","rc":[{"atl":[[100,6.06]],"id":52385910},{"atl":[[300,0],[360,7]],"id":52385885},{"atb":[[19.5,21.2]],"id":52385904},{"atl":[[420,2.5]],"id":52385882},{"atl":[[200,3.02]],"id":52385884}],"con":true,"img":false}]}
{"op":"mcm","clk":"11550912411","pt":1719505782148,"mc":[{"id":"1.230178176","rc":[{"atl":[[150,0]],"id":52385883},{"atl":[[320,4.5]],"id":52385885},{"atl":[[16.5,0],[16,2.5],[18.5,0],[18,5]],"id":52385898},{"atl":[[350,0],[420,4.5]],"id":52385882}],"con":true,"img":false}]}
{"op":"mcm","clk":"11550912418","pt":1719505782246,"mc":[{"id":"1.230178176","rc":[{"atl":[[170,3.55]],"id":52385883},{"atl":[[360,5]],"id":52385885},{"atb":[[19.5,0]],"id":52385904}],"con":true,"img":false}]}
{"op":"mcm","clk":"11550912421","pt":1719505782347,"mc":[{"id":"1.230178176","rc":[{"atl":[[360,7]],"id":52385885},{"atb":[[18.5,15.8]],"id":52385904},{"atb":[[11,27.86]],"id":52385905}],"con":true,"img":false}]}
{"op":"mcm","clk":"11550912426","pt":1719505782445,"mc":[{"id":"1.230178176","rc":[{"atl":[[320,2.5]],"id":52385885}],"con":true,"img":false}]}
{"op":"mcm","clk":"11550912432","pt":1719505782549,"mc":[{"id":"1.230178176","rc":[{"atl":[[270,0]],"id":52385885},{"atb":[[10.5,0]],"id":52385905}],"con":true,"img":false}]}
{"op":"mcm","clk":"11550912436","pt":1719505782651,"mc":[{"id":"1.230178176","rc":[{"atl":[[240,2.51]],"id":52385885}],"con":true,"img":false}]}
{"op":"mcm","clk":"11550912442","pt":1719505782756,"mc":[{"id":"1.230178176","rc":[{"atb":[[10,0]],"id":52385906},{"atl":[[300,2]],"id":52385885}],"con":true,"img":false}]}
{"op":"mcm","clk":"11550912448","pt":1719505782820,"mc":[{"id":"1.230178176","rc":[{"atl":[[360,5],[240,0]],"id":52385885}],"con":true,"img":false}]}
{"op":"mcm","clk":"11550912453","pt":1719505782920,"mc":[{"id":"1.230178176","rc":[{"atb":[[10.5,0]],"id":52385906},{"atl":[[280,2.15],[300,0],[320,4.5]],"id":52385885},{"atb":[[15,0]],"id":52385896}],"con":true,"img":false}]}
{"op":"mcm","clk":"11550912458","pt":1719505783024,"mc":[{"id":"1.230178176","rc":[{"atb":[[10,29.46]],"id":52385906},{"atb":[[17,6]],"id":52385896},{"atb":[[27,23.08]],"id":52385921}],"con":true,"img":false}]}
{"op":"mcm","clk":"11550912466","pt":1719505783129,"mc":[{"id":"1.230178176","rc":[{"atl":[[280,0]],"id":52385885}],"con":true,"img":false}]}
{"op":"mcm","clk":"11550912472","pt":1719505783233,"mc":[{"id":"1.230178176","rc":[{"atl":[[300,2.01]],"id":52385885},{"atb":[[19.5,0],[27,0]],"id":52385921}],"con":true,"img":false}]}
{"op":"mcm","clk":"11550912478","pt":1719505783340,"mc":[{"id":"1.230178176","rc":[{"atb":[[25,25]],"id":52385921}],"con":true,"img":false}]}
{"op":"mcm","clk":"11550912523","pt":1719505784212,"mc":[{"id":"1.230178176","rc":[{"atl":[[160,0],[200,0],[250,2.5]],"id":52385883}],"con":true,"img":false}]}
{"op":"mcm","clk":"11550912545","pt":1719505784634,"mc":[{"id":"1.230178176","rc":[{"atl":[[100,0]],"id":52385910},{"atl":[[170,0]],"id":52385883}],"con":true,"img":false}]}
{"op":"mcm","clk":"11550912554","pt":1719505784736,"mc":[{"id":"1.230178176","rc":[{"atl":[[110,8]],"id":52385910},{"atl":[[180,3.35]],"id":52385883}],"con":true,"img":false}]}
{"op":"mcm","clk":"11550912567","pt":1719505784943,"mc":[{"id":"1.230178176","rc":[{"atl":[[180,0]],"id":52385883}],"con":true,"img":false}]}
{"op":"mcm","clk":"11550912574","pt":1719505785041,"mc":[{"id":"1.230178176","rc":[{"atl":[[230,2.62]],"id":52385883},{"atl":[[330,0]],"id":52385886}],"con":true,"img":false}]}
{"op":"mcm","clk":"11550912583","pt":1719505785144,"mc":[{"id":"1.230178176","rc":[{"atl":[[340,4.27]],"id":52385886}],"con":true,"img":false}]}
{"op":"mcm","clk":"11550912591","pt":1719505785251,"mc":[{"id":"1.230178176","rc":[{"atb":[[12.5,0]],"id":52385912},{"atb":[[9.2,0]],"id":52385906},{"atb":[[17.5,0]],"id":52385914},{"atb":[[18.5,0]],"id":52385892},{"atl":[[75,0]],"id":52385892},{"atl":[[36,2.5]],"id":52385904},{"atb":[[7.4,0]],"id":52385898},{"atb":[[13.5,0]],"id":52385900},{"atb":[[16.5,0]],"id":52385911},{"atl":[[55,0]],"id":52385911},{"atl":[[25,0]],"id":52385913},{"atb":[[12,0]],"id":52385907},{"atl":[[30,0]],"id":52385907},{"atb":[[25,0]],"id":52385919},{"atb":[[15.5,0]],"id":52385921},{"atl":[[55,0]],"id":52385921},{"atb":[[11.5,0]],"id":52385897},{"atl":[[48,0]],"id":52385891},{"atl":[[19,0]],"id":52385905},{"atb":[[11,0]],"id":52385899},{"atl":[[20,0]],"id":52385899}],"con":true,"img":false}]}
{"op":"mcm","clk":"11550912599","pt":1719505785352,"mc":[{"id":"1.230178176","rc":[{"atb":[[13.5,4]],"id":52385912},{"atb":[[10.5,5.86]],"id":52385906},{"atb":[[28,3]],"id":52385918},{"atl":[[110,2]],"id":52385918},{"atl":[[70,7.61]],"id":52385920},{"atb":[[19,4.27]],"id":52385914},{"atb":[[30,2.5]],"id":52385892},{"atl":[[65,2.41]],"id":52385892},{"atl":[[32,3.22]],"id":52385904},{"atb":[[6.6,6.72]],"id":52385898},{"atb":[[11.5,4]],"id":52385900},{"atb":[[25,3.19]],"id":52385911},{"atl":[[65,4.5]],"id":52385911},{"atl":[[22,4]],"id":52385913},{"atb":[[10,3]],"id":52385907},{"atl":[[28,4]],"id":52385907},{"atb":[[27,3]],"id":52385919},{"atb":[[26,4]],"id":52385921},{"atl":[[65,4.72]],"id":52385921},{"atb":[[9.8,4.9]],"id":52385897},{"atl":[[44,2]],"id":52385891},{"atb":[[28,3]],"id":52385893},{"atl":[[85,2]],"id":52385893},{"atl":[[15,4]],"id":52385905},{"atb":[[12,5]],"id":52385899},{"atl":[[19,3.65]],"id":52385899}],"con":true,"img":false}]}
{"op":"mcm","clk":"11550912606","pt":1719505785455,"mc":[{"id":"1.230178176","rc":[{"atb":[[13,0],[14,18]],"id":52385912},{"atb":[[32,19.35]],"id":52385892},{"atl":[[65,11.79]],"id":52385892},{"atl":[[32,21.82]],"id":52385904},{"atb":[[26,24]],"id":52385911},{"atl":[[50,0]],"id":52385911},{"atb":[[13,11.46]],"id":52385913},{"atl":[[21,13]],"id":52385913},{"atb":[[28,16]],"id":52385919},{"atl":[[50,0]],"id":52385921},{"atl":[[42,14.63]],"id":52385891},{"atb":[[29,11]],"id":52385893},{"atl":[[80,7.59]],"id":52385893},{"atb":[[11,0]],"id":52385905},{"atb":[[11.5,0],[12,22.3]],"id":52385899},{"atl":[[19,20.95],[19.5,0]],"id":52385899}],"con":true,"img":false}]}
{"op":"mcm","clk":"11550912611","pt":1719505785558,"mc":[{"id":"1.230178176","rc":[{"atl":[[100,6.06]],"id":52385918},{"atl":[[75,2],[80,0]],"id":52385920},{"atb":[[24,0]],"id":52385911},{"atl":[[50,12.24]],"id":52385911},{"atl":[[27,14]],"id":52385907},{"atl":[[340,0],[380,2],[510,2.5]],"id":52385886},{"atb":[[26,0]],"id":52385919},{"atl":[[55,11.11]],"id":52385921},{"atb":[[27,0]],"id":52385893},{"atl":[[90,0]],"id":52385893}],"con":true,"img":false}]}
{"op":"mcm","clk":"11550912615","pt":1719505785619,"mc":[{"id":"1.230178176","rc":[{"atb":[[29,0]],"id":52385892},{"atl":[[70,0]],"id":52385892},{"atl":[[34,0]],"id":52385904},{"atb":[[12,5.6]],"id":52385913},{"atl":[[23,0]],"id":52385913},{"atl":[[85,5],[90,2]],"id":52385921},{"atl":[[46,0]],"id":52385891},{"atb":[[10.5,27.86]],"id":52385905}],"con":true,"img":false}]}
{"op":"mcm","clk":"11550912623","pt":1719505785719,"mc":[{"id":"1.230178176","rc":[{"atl":[[120,2.5]],"id":52385918},{"atb":[[20,2.5]],"id":52385892},{"atl":[[50,0]],"id":52385911},{"atl":[[29,0]],"id":52385907},{"atl":[[350,1.72]],"id":52385886},{"atl":[[55,0]],"id":52385921}],"con":true,"img":false}]}
{"op":"mcm","clk":"11550912629","pt":1719505785824,"mc":[{"id":"1.230178176","rc":[{"atl":[[60,10.17]],"id":52385911},{"atl":[[60,10.17]],"id":52385921}],"con":true,"img":false}]}
{"op":"mcm","clk":"11550912638","pt":1719505785972,"mc":[{"id":"1.230178176","rc":[{"atl":[[150,0],[320,2],[190,0],[210,2.5],[110,0],[250,5]],"id":52385910},{"atb":[[1.09,0],[1.65,150]],"id":52385912},{"atb":[[17,6.25],[21,0]],"id":52385918},{"atb":[[65,2.5],[40,0],[11.5,8.45],[30,0]],"id":52385889},{"atl":[[270,0],[260,2.5],[300,5],[180,3.35],[370,2],[220,0]],"id":52385889},{"atb":[[3.75,36.36],[18.5,0],[3.2,0]],"id":52385914},{"atb":[[27,0]],"id":52385883},{"atl":[[260,0],[600,2],[350,2.5],[390,5],[230,0],[250,0]],"id":52385883},{"atb":[[18.5,0]],"id":52385885},{"atl":[[300,0],[320,0],[360,0],[420,2.5]],"id":52385885},{"atb":[[9.6,0]],"id":52385896},{"atl":[[65,0],[85,0],[110,0],[220,2],[60,0]],"id":52385896},{"atb":[[9.8,0],[13.5,7.5]],"id":52385892},{"atb":[[18.5,0]],"id":52385904},{"atb":[[15.5,0]],"id":52385900},{"atl":[[34,7.8],[36,0],[28,2.5],[29,0]],"id":52385900},{"atb":[[16,2.5]],"id":52385911},{"atb":[[3.85,35.09],[13,0],[3.55,0]],"id":52385913},{"atl":[[36,5.36],[38,0]],"id":52385907},{"atb":[[40,0]],"id":52385886},{"atl":[[350,0],[380,0]],"id":52385886},{"atl":[[65,0],[80,5],[85,0],[60,2.5]],"id":52385919},{"atl":[[85,7],[90,0]],"id":52385921},{"atb":[[65,0],[90,11.74],[48,0],[100,6.06],[120,2.5]],"id":52385882},{"atl":[[340,0],[420,2.5],[880,2]],"id":52385882},{"atb":[[21,0]],"id":52385884},{"atl":[[320,2.5],[360,5],[200,0],[210,0],[250,0]],"id":52385884},{"atb":[[42,0]],"id":52385917},{"atl":[[570,2],[330,2.5],[190,0],[200,0],[240,0]],"id":52385917},{"atl":[[27,19.8]],"id":52385897},{"atb":[[17.5,0],[19.5,4],[12,0]],"id":52385891},{"atb":[[14,0]],"id":52385903},{"atl":[[130,0],[70,8.7],[160,5],[90,0],[220,2],[120,2.5]],"id":52385903},{"atb":[[3.85,0],[4.6,27.78]],"id":52385899}],"con":true,"img":false}]}
{"op":"mcm","clk":"11550912646","pt":1719505786032,"mc":[{"id":"1.230178176","rc":[{"atl":[[160,5],[120,2.5]],"id":52385896},{"atb":[[18,0]],"id":52385897},{"atb":[[23,0]],"id":52385891}],"con":true,"img":false}]}
{"op":"mcm","clk":"11550912655","pt":1719505786134,"mc":[{"id":"1.230178176","rc":[{"atl":[[240,2.51]],"id":52385910},{"atl":[[180,0]],"id":52385889},{"atl":[[260,2.32]],"id":52385883},{"atl":[[740,2],[1000,0.6]],"id":52385885},{"atl":[[1000,0.6]],"id":52385896},{"atb":[[14,11.6]],"id":52385904},{"atb":[[15,10]],"id":52385900},{"atb":[[3.8,35.71],[1.33,0]],"id":52385911},{"atb":[[6.6,13]],"id":52385913},{"atl":[[390,1.54],[800,2]],"id":52385886},{"atb":[[90,5]],"id":52385882},{"atl":[[360,1.67]],"id":52385882},{"atl":[[420,2],[220,2.74]],"id":52385884},{"atl":[[560,0.03]],"id":52385917},{"atb":[[17.5,36.36]],"id":52385897},{"atl":[[28,3]],"id":52385897},{"atb":[[10,11.11],[22,20],[12.5,5],[14.5,2.5]],"id":52385891},{"atl":[[70,0]],"id":52385903}],"con":true,"img":false}]}
{"op":"mcm","clk":"11550912663","pt":1719505786234,"mc":[{"id":"1.230178176","rc":[{"atl":[[190,3.17]],"id":52385889},{"atb":[[18,8.57]],"id":52385897},{"atl":[[150,4.03]],"id":52385903}],"con":true,"img":false}]}
{"op":"mcm","clk":"11550912670","pt":1719505786337,"mc":[{"id":"1.230178176","rc":[{"atl":[[260,0]],"id":52385883},{"atb":[[15,0]],"id":52385900},{"atl":[[390,0]],"id":52385886},{"atl":[[360,0]],"id":52385882},{"atb":[[17.5,0],[18,35.51]],"id":52385897},{"atb":[[22,0]],"id":52385891}],"con":true,"img":false}]}
{"op":"mcm","clk":"11550912679","pt":1719505786444,"mc":[{"id":"1.230178176","rc":[{"atl":[[190,0]],"id":52385889},{"atl":[[270,2.23]],"id":52385883},{"atb":[[14.5,13]],"id":52385900},{"atl":[[430,1.4]],"id":52385886},{"atl":[[410,1.47]],"id":52385882},{"atb":[[21,13]],"id":52385891}],"con":true,"img":false}]}
{"op":"mcm","clk":"11550912690","pt":1719505786546,"mc":[{"id":"1.230178176","rc":[{"atl":[[250,2.41]],"id":52385889},{"atl":[[220,0]],"id":52385884}],"con":true,"img":false}]}
{"op":"mcm","clk":"11550912700","pt":1719505786649,"mc":[{"id":"1.230178176","rc":[{"atl":[[270,0]],"id":52385883},{"atl":[[260,2.32]],"id":52385884},{"atb":[[10.5,42.86]],"id":52385905}],"con":true,"img":false}]}
{"op":"mcm","clk":"11550912707","pt":1719505786748,"mc":[{"id":"1.230178176","rc":[{"atl":[[260,2.32]],"id":52385883},{"atb":[[18,26.94]],"id":52385897},{"atb":[[38,16.22]],"id":52385903}],"con":true,"img":false}]}
{"op":"mcm","clk":"11550912714","pt":1719505786850,"mc":[{"id":"1.230178176","rc":[{"atb":[[10.5,27.86]],"id":52385905}],"con":true,"img":false}]}
{"op":"mcm","clk":"11550912722","pt":1719505786954,"mc":[{"id":"1.230178176","rc":[{"atl":[[260,0]],"id":52385883},{"atb":[[18,0]],"id":52385897},{"atb":[[36,0]],"id":52385903}],"con":true,"img":false}]}
{"op":"mcm","clk":"11550912728","pt":1719505787056,"mc":[{"id":"1.230178176","rc":[{"atl":[[340,1.77]],"id":52385883},{"atb":[[17.5,11]],"id":52385897}],"con":true,"img":false}]}
{"op":"mcm","clk":"11550912747","pt":1719505787324,"mc":[{"id":"1.230178176","rc":[{"atl":[[15,31.86]],"id":52385905}],"con":true,"img":false}]}
{"op":"mcm","clk":"11550912759","pt":1719505787531,"mc":[{"id":"1.230178176","rc":[{"atl":[[15.5,0]],"id":52385905}],"con":true,"img":false}]}
{"op":"mcm","clk":"11550912778","pt":1719505787940,"mc":[{"id":"1.230178176","rc":[{"atl":[[430,0]],"id":52385886},{"atl":[[410,0]],"id":52385882}],"con":true,"img":false}]}
{"op":"mcm","clk":"11550912785","pt":1719505788041,"mc":[{"id":"1.230178176","rc":[{"atl":[[740,0],[1000,2.6]],"id":52385885},{"atl":[[500,1.2]],"id":52385886},{"atl":[[420,3.93]],"id":52385882}],"con":true,"img":false}]}
{"op":"mcm","clk":"11550912795","pt":1719505788247,"mc":[{"id":"1.230178176","rc":[{"atb":[[17.5,0]],"id":52385897}],"con":true,"img":false}]}
{"op":"mcm","clk":"11550912801","pt":1719505788346,"mc":[{"id":"1.230178176","rc":[{"atb":[[17,11]],"id":52385897}],"con":true,"img":false}]}
{"op":"mcm","clk":"11550912820","pt":1719505788758,"mc":[{"id":"1.230178176","rc":[{"atb":[[10,0]],"id":52385905}],"con":true,"img":false}]}
{"op":"mcm","clk":"11550912826","pt":1719505788818,"mc":[{"id":"1.230178176","rc":[{"atb":[[9,8]],"id":52385905}],"con":true,"img":false}]}
{"op":"mcm","clk":"11550912831","pt":1719505788919,"mc":[{"id":"1.230178176","rc":[{"atl":[[640,2.5],[420,2.5]],"id":52385882}],"con":true,"img":false}]}
{"op":"mcm","clk":"11550912836","pt":1719505789023,"mc":[{"id":"1.230178176","rc":[{"atl":[[420,0]],"id":52385882}],"con":true,"img":false}]}
{"op":"mcm","clk":"11550912841","pt":1719505789127,"mc":[{"id":"1.230178176","rc":[{"atl":[[420,1.43]],"id":52385882}],"con":true,"img":false}]}
{"op":"mcm","clk":"11550912853","pt":1719505789355,"mc":[{"id":"1.230178176","rc":[{"atl":[[420,0]],"id":52385882}],"con":true,"img":false}]}
{"op":"mcm","clk":"11550912862","pt":1719505789442,"mc":[{"id":"1.230178176","rc":[{"atb":[[13.5,0]],"id":52385912},{"atl":[[110,0]],"id":52385918},{"atl":[[70,5]],"id":52385920},{"atb":[[30,0]],"id":52385892},{"atb":[[6.6,0]],"id":52385898},{"atb":[[11.5,0]],"id":52385900},{"atb":[[25,0]],"id":52385911},{"atl":[[65,2.5]],"id":52385911},{"atb":[[12,0]],"id":52385913},{"atl":[[22,0]],"id":52385913},{"atb":[[10,0]],"id":52385907},{"atl":[[28,0]],"id":52385907},{"atb":[[27,0]],"id":52385919},{"atl":[[65,2.49]],"id":52385921},{"atl":[[590,1.02]],"id":52385882},{"atb":[[9.8,0]],"id":52385897},{"atl":[[28,0]],"id":52385897},{"atl":[[44,0]],"id":52385891},{"atb":[[28,0]],"id":52385893},{"atl":[[85,0]],"id":52385893}],"con":true,"img":false}]}
{"op":"mcm","clk":"11550912870","pt":1719505789541,"mc":[{"id":"1.230178176","rc":[{"atl":[[44,7.33]],"id":52385907}],"con":true,"img":false}]}
{"op":"mcm","clk":"11550912878","pt":1719505789646,"mc":[{"id":"1.230178176","rc":[{"atb":[[38,2]],"id":52385910},{"atl":[[210,4.5]],"id":52385910},{"atb":[[14,0],[14.5,4]],"id":52385912},{"atl":[[95,2.64],[100,0]],"id":52385918},{"atl":[[48,2.39]],"id":52385920},{"atl":[[38,2.16]],"id":52385914},{"atb":[[46,3]],"id":52385883},{"atl":[[340,3.77]],"id":52385883},{"atb":[[65,2]],"id":52385885},{"atl":[[600,2]],"id":52385885},{"atb":[[30,2.9]],"id":52385896},{"atl":[[120,5.1]],"id":52385896},{"atb":[[32,0],[26,2.55]],"id":52385892},{"atb":[[8.2,6]],"id":52385898},{"atb":[[15,4.43]],"id":52385900},{"atb":[[26,0],[27,3.32]],"id":52385911},{"atl":[[55,2]],"id":52385911},{"atb":[[10,2]],"id":52385913},{"atl":[[20,2.9],[21,0]],"id":52385913},{"atb":[[9.2,5.43]],"id":52385907},{"atl":[[36,2.5],[26,3.3],[27,0]],"id":52385907},{"atb":[[28,0],[29,2.64]],"id":52385919},{"atl":[[55,2.45]],"id":52385921},{"atb":[[55,2.02]],"id":52385884},{"atl":[[310,2]],"id":52385884},{"atb":[[9.2,4.3]],"id":52385897},{"atl":[[26,3.7]],"id":52385897},{"atl":[[40,2.67],[42,0]],"id":52385891},{"atb":[[30,3.6]],"id":52385893},{"atl":[[75,2.48]],"id":52385893},{"atb":[[40,3.3]],"id":52385903},{"atl":[[140,2]],"id":52385903}],"con":true,"img":false}]}
{"op":"mcm","clk":"11550912887","pt":1719505789750,"mc":[{"id":"1.230178176","rc":[{"atb":[[40,14.02]],"id":52385910},{"atb":[[15,13]],"id":52385912},{"atl":[[90,6.74]],"id":52385918},{"atl":[[70,7],[46,13.33]],"id":52385920},{"atl":[[36,10],[50,2.04],[55,0]],"id":52385914},{"atb":[[48,12.77]],"id":52385883},{"atb":[[70,8.7]],"id":52385885},{"atl":[[740,2],[1000,0.6]],"id":52385885},{"atb":[[32,19.35]],"id":52385896},{"atb":[[30,10.1]],"id":52385892},{"atb":[[8.2,28]],"id":52385898},{"atb":[[27,13.32]],"id":52385911},{"atl":[[20,12.9]],"id":52385913},{"atl":[[36,5.36],[44,5],[25,11.6]],"id":52385907},{"atb":[[29,12.92]],"id":52385919},{"atb":[[60,9.64]],"id":52385884},{"atl":[[38,13.34]],"id":52385891}],"con":true,"img":false}]}
{"op":"mcm","clk":"11550912894","pt":1719505789849,"mc":[{"id":"1.230178176","rc":[{"atl":[[75,0]],"id":52385920}],"con":true,"img":false}]}
{"op":"mcm","clk":"11550912901","pt":1719505789951,"mc":[{"id":"1.230178176","rc":[{"atb":[[36,0]],"id":52385910},{"atl":[[50,2.5]],"id":52385920},{"atl":[[40,0]],"id":52385914},{"atb":[[44,0]],"id":52385883},{"atb":[[60,0]],"id":52385885},{"atb":[[29,0]],"id":52385896},{"atb":[[30,0]],"id":52385892},{"atb":[[8,11]],"id":52385898},{"atb":[[50,0]],"id":52385884}],"con":true,"img":false}]}
{"op":"mcm","clk":"11550912909","pt":1719505790048,"mc":[{"id":"1.230178176","rc":[{"atb":[[27,10.1]],"id":52385892}],"con":true,"img":false}]}
{"op":"mcm","clk":"11550913022","pt":1719505791963,"mc":[{"id":"1.230178176","rc":[{"atb":[[1.81,123.46],[1.65,0]],"id":52385912},{"atb":[[11.5,0]],"id":52385889},{"atl":[[370,0],[450,2]],"id":52385889},{"atl":[[600,0],[350,0],[390,0],[770,2],[420,2.5]],"id":52385883},{"atl":[[420,0],[510,2.5]],"id":52385885},{"atb":[[8.2,6]],"id":52385898},{"atl":[[19,5.56],[21,0]],"id":52385898},{"atb":[[3.8,0],[3.5,40]],"id":52385911},{"atl":[[800,0]],"id":52385886},{"atl":[[880,0]],"id":52385882},{"atl":[[550,2],[420,0]],"id":52385884},{"atl":[[570,0],[330,0],[700,2],[390,2.5]],"id":52385917},{"atl":[[140,4.5],[160,0],[120,0]],"id":52385903},{"atb":[[10.5,0]],"id":52385905},{"atl":[[32,3.23],[38,0]],"id":52385899}],"con":true,"img":false}]}
{"op":"mcm","clk":"11550913028","pt":1719505792025,"mc":[{"id":"1.230178176","rc":[{"atb":[[9,35.86]],"id":52385905}],"con":true,"img":false}]}
{"op":"mcm","clk":"11550913042","pt":1719505792226,"mc":[{"id":"1.230178176","rc":[{"atb":[[27,23.08]],"id":52385921}],"con":true,"img":false}]}
{"op":"mcm","clk":"11550913054","pt":1719505792448,"mc":[{"id":"1.230178176","rc":[{"atb":[[25,0]],"id":52385921}],"con":true,"img":false}]}
{"op":"mcm","clk":"11550913070","pt":1719505792758,"mc":[{"id":"1.230178176","rc":[{"atb":[[17,0]],"id":52385921}],"con":true,"img":false}]}
{"op":"mcm","clk":"11550913084","pt":1719505792957,"mc":[{"id":"1.230178176","rc":[{"atl":[[260,0]],"id":52385884}],"con":true,"img":false}]}
{"op":"mcm","clk":"11550913093","pt":1719505793059,"mc":[{"id":"1.230178176","rc":[{"atl":[[280,2.15]],"id":52385884}],"con":true,"img":false}]}
{"op":"mcm","clk":"11550913105","pt":1719505793265,"mc":[{"id":"1.230178176","rc":[{"atl":[[280,0]],"id":52385884}],"con":true,"img":false}]}
{"op":"mcm","clk":"11550913111","pt":1719505793366,"mc":[{"id":"1.230178176","rc":[{"atl":[[470,1.28]],"id":52385885},{"atl":[[300,2.01]],"id":52385884}],"con":true,"img":false}]}
{"op":"mcm","clk":"11550913116","pt":1719505793472,"mc":[{"id":"1.230178176","rc":[{"atb":[[38,0]],"id":52385910},{"atb":[[14.5,0]],"id":52385912},{"atl":[[95,0]],"id":52385918},{"atl":[[48,0]],"id":52385920},{"atb":[[19,0]],"id":52385914},{"atl":[[38,0]],"id":52385914},{"atb":[[46,0]],"id":52385883},{"atl":[[340,1.77]],"id":52385883},{"atb":[[65,0]],"id":52385885},{"atb":[[30,0]],"id":52385896},{"atb":[[26,0]],"id":52385892},{"atl":[[23,24.46]],"id":52385900},{"atl":[[26,0]],"id":52385907},{"atb":[[26,0]],"id":52385921},{"atb":[[55,0]],"id":52385884},{"atl":[[310,0]],"id":52385884},{"atb":[[9.2,0]],"id":52385897},{"atl":[[40,0]],"id":52385891},{"atb":[[8.4,0]],"id":52385905}],"con":true,"img":false}]}
{"op":"mcm","clk":"11550913120","pt":1719505793575,"mc":[{"id":"1.230178176","rc":[{"atb":[[40,0]],"id":52385910},{"atb":[[15,0]],"id":52385912},{"atb":[[15.5,11.63]],"id":52385914},{"atl":[[36,0]],"id":52385914},{"atb":[[48,0]],"id":52385883},{"atl":[[340,0]],"id":52385883},{"atb":[[70,0]],"id":52385885},{"atl":[[1000,0]],"id":52385885},{"atb":[[32,0]],"id":52385896},{"atl":[[24,0]],"id":52385900},{"atl":[[25,0]],"id":52385907},{"atb":[[60,0]],"id":52385884},{"atl":[[300,0]],"id":52385884},{"atl":[[38,0]],"id":52385891}],"con":true,"img":false}]}
{"op":"mcm","clk":"11550913126","pt":1719505793678,"mc":[{"id":"1.230178176","rc":[{"atb":[[42,2.1]],"id":52385910},{"atb":[[14.5,15],[15.5,3.5]],"id":52385912},{"atl":[[85,2.7],[90,0]],"id":52385918},{"atl":[[46,0]],"id":52385920},{"atb":[[13.5,4.6]],"id":52385914},{"atl":[[38,10],[46,2.9]],"id":52385914},{"atb":[[50,2.9]],"id":52385883},{"atl":[[410,2]],"id":52385883},{"atb":[[75,2.32],[60,9]],"id":52385885},{"atb":[[34,2.8],[30,15]],"id":52385896},{"atb":[[28,2.99]],"id":52385892},{"atl":[[24,2.7]],"id":52385907},{"atb":[[28,3.16]],"id":52385921},{"atb":[[65,2.26]],"id":52385884},{"atb":[[9,7.14]],"id":52385897},{"atl":[[36,2.6],[44,13.95]],"id":52385891},{"atb":[[9.2,6]],"id":52385905}],"con":true,"img":false}]}
{"op":"mcm","clk":"11550913135","pt":1719505793787,"mc":[{"id":"1.230178176","rc":[{"atb":[[38,14.02]],"id":52385910},{"atl":[[95,6.38]],"id":52385918},{"atl":[[48,12.77]],"id":52385920},{"atb":[[46,9]],"id":52385883},{"atl":[[350,1.72]],"id":52385883},{"atl":[[26,20.72]],"id":52385907},{"atb":[[28,14.48]],"id":52385921},{"atb":[[55,10]],"id":52385884},{"atl":[[310,1.94]],"id":52385884}],"con":true,"img":false}]}
{"op":"mcm","clk":"11550913141","pt":1719505793829,"mc":[{"id":"1.230178176","rc":[{"atl":[[580,1.04]],"id":52385882}],"con":true,"img":false}]}
{"op":"mcm","clk":"11550913151","pt":1719505793942,"mc":[{"id":"1.230178176","rc":[{"atl":[[200,3.02]],"id":52385910},{"atl":[[38,0]],"id":52385914},{"atl":[[350,0]],"id":52385883},{"atb":[[15,24.6]],"id":52385904},{"atb":[[27,0]],"id":52385921},{"atl":[[590,0]],"id":52385882}],"con":true,"img":false}]}
{"op":"mcm","clk":"11550913159","pt":1719505794045,"mc":[{"id":"1.230178176","rc":[{"atl":[[240,0]],"id":52385910},{"atl":[[42,14.63]],"id":52385914},{"atl":[[360,1.67]],"id":52385883},{"atb":[[14,0]],"id":52385904}],"con":true,"img":false}]}
{"op":"mcm","clk":"11550913172","pt":1719505794241,"mc":[{"id":"1.230178176","rc":[{"atb":[[9.2,44.12]],"id":52385905}],"con":true,"img":false}]}
{"op":"mcm","clk":"11550913184","pt":1719505794449,"mc":[{"id":"1.230178176","rc":[{"atb":[[9,8]],"id":52385905}],"con":true,"img":false}]}
{"op":"mcm","clk":"11550913212","pt":1719505794873,"mc":[{"id":"1.230178176","rc":[{"atl":[[70,5],[75,2]],"id":52385920},{"atl":[[740,0],[970,2]],"id":52385885}],"con":true,"img":false}]}
{"op":"mcm","clk":"11550913225","pt":1719505794975,"mc":[{"id":"1.230178176","rc":[{"atb":[[10.5,34.72]],"id":52385906}],"con":true,"img":false}]}
{"op":"mcm","clk":"11550913241","pt":1719505795181,"mc":[{"id":"1.230178176","rc":[{"atb":[[10,0]],"id":52385906}],"con":true,"img":false}]}
{"op":"mcm","clk":"11550913340","pt":1719505796979,"mc":[{"id":"1.230178176","rc":[{"atb":[[1.72,100],[1.81,0]],"id":52385912},{"atb":[[5.5,22.22]],"id":52385889},{"atl":[[390,2],[450,0]],"id":52385889},{"atl":[[620,2],[360,4.17],[770,0],[400,5],[420,0]],"id":52385883},{"atl":[[440,2.5],[510,0]],"id":52385885},{"atb":[[3.2,45.45],[3.5,0]],"id":52385911},{"atl":[[860,2]],"id":52385886},{"atl":[[940,2]],"id":52385882},{"atl":[[550,0],[450,2]],"id":52385884},{"atl":[[350,2.5]],"id":52385917}],"con":true,"img":false}]}
{"op":"mcm","clk":"11550913343","pt":1719505797039,"mc":[{"id":"1.230178176","rc":[{"atl":[[460,1.31]],"id":52385885},{"atl":[[610,2]],"id":52385917}],"con":true,"img":false}]}
{"op":"mcm","clk":"11550913348","pt":1719505797137,"mc":[{"id":"1.230178176","rc":[{"atl":[[700,0]],"id":52385917}],"con":true,"img":false}]}
{"op":"mcm","clk":"11550913353","pt":1719505797248,"mc":[{"id":"1.230178176","rc":[{"atb":[[15.5,20.5]],"id":52385912},{"atl":[[470,0]],"id":52385885},{"atb":[[29,15.98]],"id":52385892},{"atb":[[10,13.46]],"id":52385913},{"atl":[[36,19.74]],"id":52385891},{"atb":[[32,12.2]],"id":52385893},{"atl":[[70,8.7]],"id":52385893},{"atl":[[18.5,20]],"id":52385899}],"con":true,"img":false}]}
{"op":"mcm","clk":"11550913358","pt":1719505797348,"mc":[{"id":"1.230178176","rc":[{"atl":[[85,9.84]],"id":52385918},{"atl":[[46,10]],"id":52385911},{"atl":[[23,21.58]],"id":52385907},{"atl":[[50,12.24]],"id":52385921}],"con":true,"img":false}]}
{"op":"mcm","clk":"11550913368","pt":1719505797454,"mc":[{"id":"1.230178176","rc":[{"atl":[[210,2.5]],"id":52385910},{"atb":[[14.5,0]],"id":52385912},{"atl":[[85,7.14],[95,0]],"id":52385918},{"atb":[[13.5,0]],"id":52385914},{"atl":[[46,0]],"id":52385914},{"atb":[[27,0]],"id":52385892},{"atb":[[13.5,0]],"id":52385904},{"atl":[[60,0]],"id":52385911},{"atb":[[6.6,0]],"id":52385913},{"atl":[[24,0],[26,0]],"id":52385907},{"atl":[[60,0]],"id":52385921},{"atb":[[9,2.5]],"id":52385897},{"atl":[[36,17.14],[44,0]],"id":52385891},{"atb":[[29,0]],"id":52385893},{"atl":[[80,0]],"id":52385893},{"atb":[[10.5,42.12]],"id":52385905},{"atl":[[19,3.65]],"id":52385899}],"con":true,"img":false}]}
{"op":"mcm","clk":"11550913376","pt":1719505797561,"mc":[{"id":"1.230178176","rc":[{"atl":[[85,0]],"id":52385918},{"atl":[[44,7.33]],"id":52385907},{"atb":[[9.2,6]],"id":52385905}],"con":true,"img":false}]}
{"op":"mcm","clk":"11550913383","pt":1719505797660,"mc":[{"id":"1.230178176","rc":[{"atl":[[200,5.19]],"id":52385910},{"atl":[[90,8.74]],"id":52385918},{"atb":[[50,2]],"id":52385889},{"atl":[[250,4.51]],"id":52385889},{"atb":[[16,4.89]],"id":52385914},{"atl":[[40,2.6]],"id":52385914},{"atb":[[13,6.5]],"id":52385904},{"atl":[[36,2.5],[23,0],[25,3.8]],"id":52385907},{"atb":[[90,2]],"id":52385886},{"atb":[[120,4.85]],"id":52385882},{"atl":[[530,2]],"id":52385882},{"atb":[[80,2.3]],"id":52385917},{"atl":[[380,2.09]],"id":52385917},{"atb":[[8.6,5]],"id":52385897},{"atl":[[36,0],[42,3.12]],"id":52385891}],"con":true,"img":false}]}
{"op":"mcm","clk":"11550913390","pt":1719505797758,"mc":[{"id":"1.230178176","rc":[{"atl":[[26,22.86]],"id":52385907},{"atb":[[95,6.38]],"id":52385886},{"atb":[[140,4.32]],"id":52385882},{"atl":[[25,25]],"id":52385897}],"con":true,"img":false}]}
{"op":"mcm","clk":"11550913398","pt":1719505797874,"mc":[{"id":"1.230178176","rc":[{"atb":[[85,7.14]],"id":52385917},{"atl":[[40,14.24]],"id":52385891}],"con":true,"img":false}]}
{"op":"mcm","clk":"11550913405","pt":1719505797974,"mc":[{"id":"1.230178176","rc":[{"atl":[[430,1.4]],"id":52385885},{"atl":[[110,5.5]],"id":52385896},{"atb":[[85,0]],"id":52385886},{"atb":[[100,0]],"id":52385882},{"atl":[[520,1.16]],"id":52385882},{"atl":[[340,1.77]],"id":52385917},{"atl":[[27,0]],"id":52385897},{"atb":[[24,14.24]],"id":52385891}],"con":true,"img":false}]}
{"op":"mcm","clk":"11550913413","pt":1719505798076,"mc":[{"id":"1.230178176","rc":[{"atb":[[75,0]],"id":52385917},{"atl":[[130,4.65]],"id":52385903}],"con":true,"img":false}]}
{"op":"mcm","clk":"11550913422","pt":1719505798176,"mc":[{"id":"1.230178176","rc":[{"atl":[[460,0]],"id":52385885},{"atl":[[1000,0]],"id":52385896},{"atl":[[580,0]],"id":52385882},{"atl":[[560,0]],"id":52385917},{"atb":[[21,0]],"id":52385891}],"con":true,"img":false}]}
{"op":"mcm","clk":"11550913428","pt":1719505798279,"mc":[{"id":"1.230178176","rc":[{"atl":[[150,0]],"id":52385903}],"con":true,"img":false}]}
{"op":"mcm","clk":"11550913451","pt":1719505798545,"mc":[{"id":"1.230178176","rc":[{"atb":[[42,14.63]],"id":52385903}],"con":true,"img":false}]}
{"op":"mcm","clk":"11550913460","pt":1719505798647,"mc":[{"id":"1.230178176","rc":[{"atb":[[38,0]],"id":52385903}],"con":true,"img":false}]}
{"op":"mcm","clk":"11550913499","pt":1719505799267,"mc":[{"id":"1.230178176","rc":[{"atb":[[17,0]],"id":52385897}],"con":true,"img":false}]}
{"op":"mcm","clk":"11550913505","pt":1719505799368,"mc":[{"id":"1.230178176","rc":[{"atb":[[16.5,17.4],[7.8,10],[8.4,0]],"id":52385897}],"con":true,"img":false}]}
{"op":"mcm","clk":"11550913516","pt":1719505799569,"mc":[{"id":"1.230178176","rc":[{"atb":[[16.5,0]],"id":52385897}],"con":true,"img":false}]}
{"op":"mcm","clk":"11550913526","pt":1719505799678,"mc":[{"id":"1.230178176","rc":[{"atb":[[15.5,12.4]],"id":52385897},{"atb":[[10.5,0]],"id":52385905}],"con":true,"img":false}]}
{"op":"mcm","clk":"11550913535","pt":1719505799878,"mc":[{"id":"1.230178176","rc":[{"atb":[[9.4,22]],"id":52385905}],"con":true,"img":false}]}
{"op":"mcm","clk":"11550913556","pt":1719505800144,"mc":[{"id":"1.230178176","rc":[{"atb":[[16.5,17.4]],"id":52385897}],"con":true,"img":false}]}
{"op":"mcm","clk":"11550913565","pt":1719505800247,"mc":[{"id":"1.230178176","rc":[{"atl":[[800,2],[970,0]],"id":52385885},{"atb":[[15.5,0]],"id":52385897}],"con":true,"img":false}]}
{"op":"mcm","clk":"11550913599","pt":1719505800676,"mc":[{"id":"1.230178176","rc":[{"atb":[[38,2]],"id":52385893}],"con":true,"img":false}]}
{"op":"mcm","clk":"11550913657","pt":1719505801462,"mc":[{"id":"1.230178176","rc":[{"atb":[[36,17.14]],"id":52385896}],"con":true,"img":false}]}
{"op":"mcm","clk":"11550913665","pt":1719505801562,"mc":[{"id":"1.230178176","rc":[{"atb":[[44,13.95]],"id":52385910},{"atb":[[50,0]],"id":52385889},{"atl":[[250,2.41]],"id":52385889},{"atl":[[38,14.98]],"id":52385914},{"atb":[[55,11.11]],"id":52385883},{"atl":[[410,0]],"id":52385883},{"atb":[[80,7.59]],"id":52385885},{"atl":[[600,0]],"id":52385885},{"atb":[[30,0]],"id":52385896},{"atl":[[120,2.5]],"id":52385896},{"atb":[[28,0]],"id":52385892},{"atb":[[13,2.5]],"id":52385904},{"atl":[[55,0]],"id":52385911},{"atl":[[24,18.46]],"id":52385907},{"atb":[[90,0]],"id":52385886},{"atl":[[55,0]],"id":52385921},{"atb":[[120,2.5]],"id":52385882},{"atl":[[530,0]],"id":52385882},{"atb":[[70,8.7]],"id":52385884},{"atb":[[80,0]],"id":52385917},{"atl":[[380,0]],"id":52385917},{"atl":[[26,0]],"id":52385897},{"atl":[[42,0]],"id":52385891},{"atb":[[30,0]],"id":52385893},{"atl":[[75,0]],"id":52385893},{"atb":[[40,0]],"id":52385903},{"atl":[[140,2.5]],"id":52385903},{"atb":[[9.2,0]],"id":52385905},{"atl":[[19,0]],"id":52385899}],"con":true,"img":false}]}
{"op":"mcm","clk":"11550913677","pt":1719505801760,"mc":[{"id":"1.230178176","rc":[{"atb":[[38,0]],"id":52385910},{"atl":[[42,0]],"id":52385914},{"atb":[[46,0]],"id":52385883},{"atl":[[390,2]],"id":52385883},{"atb":[[60,0]],"id":52385885},{"atl":[[100,2]],"id":52385896},{"atb":[[29,0],[30,3.67]],"id":52385892},{"atb":[[11,10.3]],"id":52385904},{"atl":[[60,2.24]],"id":52385911},{"atl":[[26,0]],"id":52385907},{"atb":[[95,0]],"id":52385886},{"atl":[[65,5.44],[50,0]],"id":52385921},{"atl":[[520,0]],"id":52385882},{"atb":[[55,0]],"id":52385884},{"atb":[[85,0]],"id":52385917},{"atl":[[24,2.87]],"id":52385897},{"atl":[[38,2.5],[40,0]],"id":52385891},{"atb":[[34,3.19]],"id":52385893},{"atl":[[65,2]],"id":52385893},{"atb":[[42,0],[44,2.8]],"id":52385903},{"atl":[[130,6.65]],"id":52385903},{"atb":[[9.4,28.7]],"id":52385905},{"atl":[[18,3.5]],"id":52385899}],"con":true,"img":false}]}
{"op":"mcm","clk":"11550913692","pt":1719505801877,"mc":[{"id":"1.230178176","rc":[{"atb":[[28,20]],"id":52385892},{"atb":[[90,6.74]],"id":52385886},{"atl":[[55,11.11]],"id":52385921},{"atl":[[530,1.13]],"id":52385882},{"atb":[[80,7.59]],"id":52385917},{"atl":[[50,12.24]],"id":52385891},{"atb":[[40,14.3]],"id":52385903}],"con":true,"img":false}]}
{"op":"mcm","clk":"11550913716","pt":1719505802091,"mc":[{"id":"1.230178176","rc":[{"atb":[[3.75,0]],"id":52385914},{"atl":[[530,2]],"id":52385884}],"con":true,"img":false}]}
{"op":"mcm","clk":"11550913729","pt":1719505802190,"mc":[{"id":"1.230178176","rc":[{"atb":[[23,22]],"id":52385920},{"atb":[[5.5,0]],"id":52385889},{"atl":[[390,0],[460,2]],"id":52385889},{"atb":[[3.1,47.62]],"id":52385914},{"atl":[[620,0],[710,2]],"id":52385883},{"atl":[[800,0],[930,2]],"id":52385885},{"atb":[[14.5,0]],"id":52385900},{"atl":[[38,2.7],[44,0]],"id":52385900},{"atb":[[3.2,0],[2.3,76.92]],"id":52385911},{"atl":[[46,0]],"id":52385911},{"atb":[[3.85,0],[3.4,41.67],[13,11.46]],"id":52385913},{"atl":[[860,0]],"id":52385886},{"atl":[[940,0]],"id":52385882},{"atl":[[450,0]],"id":52385884},{"atl":[[610,0],[710,2]],"id":52385917},{"atb":[[12.5,0],[14.5,0],[15,2.5],[24,0]],"id":52385891},{"atb":[[4.6,0],[5.8,20.83]],"id":52385899}],"con":true,"img":false}]}
{"op":"mcm","clk":"11550913741","pt":1719505802293,"mc":[{"id":"1.230178176","rc":[{"atl":[[55,9.48]],"id":52385911},{"atb":[[90,0]],"id":52385886},{"atl":[[55,0]],"id":52385921},{"atb":[[16.5,0]],"id":52385897},{"atb":[[23,13]],"id":52385891}],"con":true,"img":false}]}
{"op":"mcm","clk":"11550913749","pt":1719505802386,"mc":[{"id":"1.230178176","rc":[{"atb":[[1.72,0],[1.98,100]],"id":52385912},{"atb":[[21,4.2]],"id":52385920},{"atb":[[10,2]],"id":52385913},{"atl":[[530,0]],"id":52385882},{"atb":[[80,0]],"id":52385917}],"con":true,"img":false}]}
{"op":"mcm","clk":"11550913759","pt":1719505802452,"mc":[{"id":"1.230178176","rc":[{"atb":[[80,7.59]],"id":52385886},{"atl":[[65,14.82],[85,5],[90,2]],"id":52385921},{"atl":[[590,1.02]],"id":52385882},{"atb":[[70,8.7]],"id":52385917},{"atb":[[16,10.74]],"id":52385897}],"con":true,"img":false}]}
{"op":"mcm","clk":"11550913775","pt":1719505802656,"mc":[{"id":"1.230178176","rc":[{"atb":[[11,9]],"id":52385897}],"con":true,"img":false}]}
{"op":"mcm","clk":"11550913801","pt":1719505802955,"mc":[{"id":"1.230178176","rc":[{"atl":[[38,2.7]],"id":52385907}],"con":true,"img":false}]}
{"op":"mcm","clk":"11550913814","pt":1719505803068,"mc":[{"id":"1.230178176","rc":[{"atl":[[44,5]],"id":52385907}],"con":true,"img":false}]}
{"op":"mcm","clk":"11550913861","pt":1719505803793,"mc":[{"id":"1.230178176","rc":[{"atb":[[10,42.12]],"id":52385905}],"con":true,"img":false}]}
{"op":"mcm","clk":"11550913876","pt":1719505803952,"mc":[{"id":"1.230178176","rc":[{"atb":[[9.4,6.7]],"id":52385905}],"con":true,"img":false}]}
{"op":"mcm","clk":"11550913979","pt":1719505805262,"mc":[{"id":"1.230178176","rc":[{"atb":[[18.5,14.98]],"id":52385914},{"atl":[[38,18.72]],"id":52385891}],"con":true,"img":false}]}
{"op":"mcm","clk":"11550913988","pt":1719505805361,"mc":[{"id":"1.230178176","rc":[{"atl":[[22,13.86]],"id":52385900},{"atl":[[50,0]],"id":52385891}],"con":true,"img":false}]}
{"op":"mcm","clk":"11550913996","pt":1719505805478,"mc":[{"id":"1.230178176","rc":[{"atb":[[15.5,1.63]],"id":52385914},{"atl":[[23,0]],"id":52385900},{"atl":[[580,1.04]],"id":52385882}],"con":true,"img":false}]}
{"op":"mcm","clk":"11550914012","pt":1719505805674,"mc":[{"id":"1.230178176","rc":[{"atl":[[590,0]],"id":52385882}],"con":true,"img":false}]}
{"op":"mcm","clk":"11550914020","pt":1719505805776,"mc":[{"id":"1.230178176","rc":[{"atb":[[42,0]],"id":52385910},{"atl":[[200,3.02]],"id":52385910},{"atb":[[21,0]],"id":52385920},{"atl":[[40,0]],"id":52385914},{"atb":[[50,0]],"id":52385883},{"atl":[[390,0]],"id":52385883},{"atb":[[75,0]],"id":52385885},{"atb":[[34,0]],"id":52385896},{"atl":[[100,0]],"id":52385896},{"atb":[[8.2,0]],"id":52385898},{"atb":[[15,0]],"id":52385900},{"atl":[[34,5]],"id":52385900},{"atl":[[60,0]],"id":52385911},{"atb":[[10,0]],"id":52385913},{"atl":[[25,0]],"id":52385907},{"atb":[[65,0]],"id":52385884},{"atb":[[8.6,0]],"id":52385897},{"atl":[[38,16.22]],"id":52385891},{"atl":[[65,0]],"id":52385893},{"atl":[[130,4.65]],"id":52385903},{"atb":[[9.4,0]],"id":52385905},{"atb":[[12,17.3]],"id":52385899}],"con":true,"img":false}]}
{"op":"mcm","clk":"11550914031","pt":1719505805985,"mc":[{"id":"1.230178176","rc":[{"atb":[[44,0],[46,2.6]],"id":52385910},{"atb":[[24,3]],"id":52385920},{"atl":[[38,0],[48,5]],"id":52385914},{"atb":[[75,2],[55,0]],"id":52385883},{"atb":[[80,0],[100,2]],"id":52385885},{"atb":[[36,0],[38,3.5]],"id":52385896},{"atb":[[7.2,7.2]],"id":52385898},{"atb":[[9.2,2],[8.2,20]],"id":52385900},{"atl":[[22,17.12]],"id":52385900},{"atl":[[50,3],[55,0]],"id":52385911},{"atb":[[13.5,3]],"id":52385913},{"atl":[[24,0],[29,3.1]],"id":52385907},{"atb":[[70,0],[85,2.16]],"id":52385884},{"atb":[[11.5,5]],"id":52385897},{"atl":[[38,0],[48,3]],"id":52385891},{"atb":[[9,14.62]],"id":52385905},{"atb":[[12,0],[8.8,5]],"id":52385899}],"con":true,"img":false}]}
{"op":"mcm","clk":"11550914036","pt":1719505806089,"mc":[{"id":"1.230178176","rc":[{"atb":[[48,10.2]],"id":52385910},{"atl":[[40,13.86],[50,0],[55,2]],"id":52385914},{"atb":[[80,7.59]],"id":52385883},{"atb":[[110,5.5]],"id":52385885},{"atb":[[40,15.38]],"id":52385896},{"atl":[[50,13]],"id":52385911},{"atl":[[25,11.2]],"id":52385907},{"atb":[[90,6.74]],"id":52385884},{"atl":[[40,14]],"id":52385891},{"atb":[[11.5,12]],"id":52385899}],"con":true,"img":false}]}
{"op":"mcm","clk":"11550914048","pt":1719505806246,"mc":[{"id":"1.230178176","rc":[{"atl":[[25,0]],"id":52385907},{"atl":[[40,0]],"id":52385891}],"con":true,"img":false}]}
{"op":"mcm","clk":"11550914060","pt":1719505806360,"mc":[{"id":"1.230178176","rc":[{"atl":[[27,17.06]],"id":52385907},{"atl":[[50,12.24]],"id":52385891}],"con":true,"img":false}]}
{"op":"mcm","clk":"11550914073","pt":1719505806568,"mc":[{"id":"1.230178176","rc":[{"atl":[[40,0]],"id":52385914},{"atl":[[27,0]],"id":52385907},{"atb":[[11.5,0]],"id":52385899}],"con":true,"img":false}]}
{"op":"mcm","clk":"11550914084","pt":1719505806668,"mc":[{"id":"1.230178176","rc":[{"atl":[[44,13.95]],"id":52385914},{"atb":[[12,8]],"id":52385900},{"atl":[[28,17.06]],"id":52385907},{"atb":[[10.5,17]],"id":52385899}],"con":true,"img":false}]}
{"op":"mcm","clk":"11550914105","pt":1719505806877,"mc":[{"id":"1.230178176","rc":[{"atl":[[44,0]],"id":52385914},{"atb":[[10.5,0]],"id":52385899}],"con":true,"img":false}]}
{"op":"mcm","clk":"11550914110","pt":1719505806973,"mc":[{"id":"1.230178176","rc":[{"atl":[[44,13.95]],"id":52385914},{"atb":[[10.5,17]],"id":52385899}],"con":true,"img":false}]}
{"op":"mcm","clk":"11550914207","pt":1719505808377,"mc":[{"id":"1.230178176","rc":[{"atb":[[19.5,25.6]],"id":52385904}],"con":true,"img":false}]}
{"op":"mcm","clk":"11550914220","pt":1719505808584,"mc":[{"id":"1.230178176","rc":[{"atl":[[290,5]],"id":52385910},{"atb":[[2.14,87.72]],"id":52385912},{"atl":[[260,0],[300,0],[330,2.5],[370,5]],"id":52385889},{"atb":[[3.1,0],[2.9,52.63]],"id":52385914},{"atl":[[530,2.5],[440,0]],"id":52385885},{"atb":[[15,5.99]],"id":52385904},{"atb":[[4.9,18.2]],"id":52385898},{"atl":[[18,10.88]],"id":52385898},{"atb":[[1.53,100]],"id":52385911},{"atl":[[20,2.9]],"id":52385913},{"atl":[[350,0],[390,0],[410,2.5]],"id":52385917},{"atl":[[28,3.7]],"id":52385899}],"con":true,"img":false}]}
{"op":"mcm","clk":"11550914226","pt":1719505808694,"mc":[{"id":"1.230178176","rc":[{"atl":[[210,0]],"id":52385910},{"atb":[[1.98,0]],"id":52385912},{"atb":[[18.5,0]],"id":52385914},{"atl":[[930,0]],"id":52385885},{"atb":[[13.5,0]],"id":52385892},{"atb":[[5.5,0]],"id":52385898},{"atl":[[19,0]],"id":52385898},{"atb":[[2.3,0]],"id":52385911},{"atl":[[20,15.36]],"id":52385913},{"atl":[[32,0]],"id":52385899}],"con":true,"img":false}]}
{"op":"mcm","clk":"11550914233","pt":1719505808740,"mc":[{"id":"1.230178176","rc":[{"atl":[[250,0]],"id":52385889},{"atb":[[17,13.78]],"id":52385914},{"atl":[[340,0]],"id":52385917}],"con":true,"img":false}]}
{"op":"mcm","clk":"11550914240","pt":1719505808844,"mc":[{"id":"1.230178176","rc":[{"atl":[[260,2.32]],"id":52385889},{"atb":[[32,17.34],[11,8.67]],"id":52385892},{"atl":[[350,1.72]],"id":52385917},{"atl":[[46,13.33]],"id":52385891},{"atb":[[42,14.63]],"id":52385893},{"atl":[[16.5,17]],"id":52385899}],"con":true,"img":false}]}
{"op":"mcm","clk":"11550914247","pt":1719505808947,"mc":[{"id":"1.230178176","rc":[{"atl":[[60,10.17]],"id":52385921}],"con":true,"img":false}]}
{"op":"mcm","clk":"11550914252","pt":1719505809052,"mc":[{"id":"1.230178176","rc":[{"atb":[[28,0]],"id":52385892},{"atl":[[350,0]],"id":52385917},{"atl":[[50,0]],"id":52385891},{"atb":[[32,0]],"id":52385893},{"atl":[[18.5,0]],"id":52385899}],"con":true,"img":false}]}
{"op":"mcm","clk":"11550914261","pt":1719505809161,"mc":[{"id":"1.230178176","rc":[{"atl":[[260,0]],"id":52385889},{"atl":[[65,5.43]],"id":52385921},{"atl":[[380,1.58]],"id":52385917}],"con":true,"img":false}]}
{"op":"mcm","clk":"11550914265","pt":1719505809257,"mc":[{"id":"1.230178176","rc":[{"atl":[[320,1.88]],"id":52385889}],"con":true,"img":false}]}
{"op":"mcm","clk":"11550914274","pt":1719505809363,"mc":[{"id":"1.230178176","rc":[{"atb":[[85,7.14]],"id":52385886},{"atb":[[150,4.03]],"id":52385882},{"atl":[[23,27.27]],"id":52385897}],"con":true,"img":false}]}
{"op":"mcm","clk":"11550914281","pt":1719505809473,"mc":[{"id":"1.230178176","rc":[{"atb":[[140,0]],"id":52385882},{"atb":[[75,8.11]],"id":52385917},{"atl":[[25,0]],"id":52385897}],"con":true,"img":false}]}
{"op":"mcm","clk":"11550914286","pt":1719505809569,"mc":[{"id":"1.230178176","rc":[{"atb":[[80,0]],"id":52385886},{"atb":[[25,20]],"id":52385891}],"con":true,"img":false}]}
{"op":"mcm","clk":"11550914293","pt":1719505809677,"mc":[{"id":"1.230178176","rc":[{"atb":[[70,0]],"id":52385917}],"con":true,"img":false}]}
{"op":"mcm","clk":"11550914296","pt":1719505809777,"mc":[{"id":"1.230178176","rc":[{"atb":[[46,0]],"id":52385910},{"atb":[[16,0]],"id":52385914},{"atl":[[48,2.5]],"id":52385914},{"atb":[[75,0]],"id":52385883},{"atb":[[100,0]],"id":52385885},{"atb":[[38,0]],"id":52385896},{"atb":[[30,0]],"id":52385892},{"atb":[[11,5]],"id":52385904},{"atb":[[7.2,0]],"id":52385898},{"atb":[[9.2,0]],"id":52385900},{"atb":[[9.2,0]],"id":52385907},{"atl":[[29,0]],"id":52385907},{"atl":[[65,2.49]],"id":52385921},{"atb":[[85,0]],"id":52385884},{"atb":[[23,0]],"id":52385891},{"atl":[[48,0]],"id":52385891},{"atb":[[9,8]],"id":52385905},{"atb":[[8.8,0]],"id":52385899},{"atl":[[18,0]],"id":52385899}],"con":true,"img":false}]}
{"op":"mcm","clk":"11550914307","pt":1719505809984,"mc":[{"id":"1.230178176","rc":[{"atb":[[48,0],[50,2.09]],"id":52385910},{"atl":[[200,0],[240,2]],"id":52385910},{"atb":[[17.5,4.6]],"id":52385914},{"atl":[[42,2.5]],"id":52385914},{"atb":[[80,0],[85,2.65]],"id":52385883},{"atb":[[110,0],[120,2.1]],"id":52385885},{"atb":[[40,0],[42,3.3]],"id":52385896},{"atl":[[110,7.8]],"id":52385896},{"atb":[[32,0],[26,3.7]],"id":52385892},{"atb":[[13.5,4.24]],"id":52385904},{"atb":[[6.4,7.8]],"id":52385898},{"atb":[[12.5,4.43]],"id":52385900},{"atb":[[16.5,4.77]],"id":52385907},{"atl":[[27,3],[28,0]],"id":52385907},{"atl":[[55,2.26]],"id":52385921},{"atb":[[90,0],[95,2.32]],"id":52385884},{"atl":[[44,2.9],[46,0]],"id":52385891},{"atl":[[90,2]],"id":52385893},{"atb":[[8.2,5.36]],"id":52385905},{"atb":[[11,4.47]],"id":52385899},{"atl":[[16,3.34]],"id":52385899}],"con":true,"img":false}]}
{"op":"mcm","clk":"11550914316","pt":1719505810089,"mc":[{"id":"1.230178176","rc":[{"atb":[[55,8.18]],"id":52385910},{"atl":[[370,2]],"id":52385910},{"atb":[[90,6.74]],"id":52385883},{"atb":[[130,4.65]],"id":52385885},{"atb":[[44,13.95]],"id":52385896},{"atl":[[26,11]],"id":52385907},{"atb":[[100,6.06]],"id":52385884},{"atl":[[42,13.8]],"id":52385891}],"con":true,"img":false}]}
{"op":"mcm","clk":"11550914324","pt":1719505810192,"mc":[{"id":"1.230178176","rc":[{"atl":[[320,0],[240,4.51]],"id":52385910},{"atb":[[29,12.4]],"id":52385892},{"atb":[[46,10.6]],"id":52385903}],"con":true,"img":false}]}
{"op":"mcm","clk":"11550914344","pt":1719505810352,"mc":[{"id":"1.230178176","rc":[{"atb":[[40,0]],"id":52385903}],"con":true,"img":false}]}
{"op":"mcm","clk":"11550914370","pt":1719505810660,"mc":[{"id":"1.230178176","rc":[{"atb":[[29,0]],"id":52385892}],"con":true,"img":false}]}
{"op":"mcm","clk":"11550914380","pt":1719505810765,"mc":[{"id":"1.230178176","rc":[{"atb":[[27,17.4]],"id":52385892}],"con":true,"img":false}]}
{"op":"mcm","clk":"11550914553","pt":1719505813088,"mc":[{"id":"1.230178176","rc":[{"atl":[[40,14.2]],"id":52385914}],"con":true,"img":false}]}
{"op":"mcm","clk":"11550914565","pt":1719505813244,"mc":[{"id":"1.230178176","rc":[{"atl":[[44,0]],"id":52385914}],"con":true,"img":false}]}
{"op":"mcm","clk":"11550914569","pt":1719505813348,"mc":[{"id":"1.230178176","rc":[{"atb":[[28,17.4]],"id":52385892},{"atl":[[50,12.24]],"id":52385921}],"con":true,"img":false}]}
{"op":"mcm","clk":"11550914575","pt":1719505813452,"mc":[{"id":"1.230178176","rc":[{"atb":[[27,0]],"id":52385892}],"con":true,"img":false}]}
{"op":"mcm","clk":"11550914580","pt":1719505813554,"mc":[{"id":"1.230178176","rc":[{"atl":[[60,0]],"id":52385921}],"con":true,"img":false}]}
{"op":"mcm","clk":"11550914587","pt":1719505813656,"mc":[{"id":"1.230178176","rc":[{"atl":[[270,5],[290,0],[330,2],[370,0],[230,2.5],[250,0]],"id":52385910},{"atb":[[1.82,100],[2.14,0]],"id":52385912},{"atb":[[23,0]],"id":52385920},{"atl":[[420,2],[460,0]],"id":52385889},{"atb":[[3.5,40],[2.9,0]],"id":52385914},{"atl":[[50,2.04],[55,0]],"id":52385914},{"atl":[[860,2]],"id":52385885},{"atb":[[19.5,0]],"id":52385904},{"atb":[[1.53,0],[2.94,51.55]],"id":52385911},{"atb":[[3.4,0],[13,0],[3.65,37.74]],"id":52385913},{"atl":[[930,2]],"id":52385886},{"atl":[[530,0],[480,2]],"id":52385884},{"atb":[[25,0]],"id":52385891},{"atb":[[42,0]],"id":52385893},{"atb":[[5.8,0],[5.2,23.81]],"id":52385899}],"con":true,"img":false}]}
{"op":"mcm","clk":"11550914594","pt":1719505813760,"mc":[{"id":"1.230178176","rc":[{"atb":[[14,13.48]],"id":52385904},{"atb":[[19.5,17.8]],"id":52385891},{"atb":[[34,12.19]],"id":52385893}],"con":true,"img":false}]}
{"op":"mcm","clk":"11550914602","pt":1719505813967,"mc":[{"id":"1.230178176","rc":[{"atb":[[50,0]],"id":52385910},{"atb":[[85,0]],"id":52385883},{"atb":[[120,0]],"id":52385885},{"atb":[[42,0]],"id":52385896},{"atb":[[26,0]],"id":52385892},{"atl":[[27,0]],"id":52385907},{"atb":[[95,0]],"id":52385884},{"atl":[[24,0]],"id":52385897},{"atl":[[44,0]],"id":52385891},{"atl":[[90,0]],"id":52385893},{"atb":[[44,0]],"id":52385903}],"con":true,"img":false}]}
{"op":"mcm","clk":"11550914606","pt":1719505814071,"mc":[{"id":"1.230178176","rc":[{"atb":[[60,2.36]],"id":52385910},{"atb":[[95,2.1]],"id":52385883},{"atb":[[140,2]],"id":52385885},{"atb":[[46,3]],"id":52385896},{"atb":[[28,21.4]],"id":52385892},{"atl":[[25,3.4]],"id":52385907},{"atb":[[110,2]],"id":52385884},{"atl":[[22,4],[23,0]],"id":52385897},{"atl":[[40,3.17],[42,0]],"id":52385891},{"atl":[[95,4.5]],"id":52385893},{"atb":[[48,2.8]],"id":52385903}],"con":true,"img":false}]}
{"op":"mcm","clk":"11550914614","pt":1719505814172,"mc":[{"id":"1.230178176","rc":[{"atb":[[65,9.38]],"id":52385910},{"atb":[[100,6.06]],"id":52385883},{"atb":[[150,4.03]],"id":52385885},{"atb":[[48,12.77]],"id":52385896},{"atl":[[24,16.34],[26,0]],"id":52385907},{"atb":[[120,5.04]],"id":52385884},{"atl":[[65,0],[34,18.18],[55,2]],"id":52385897},{"atl":[[46,13.33]],"id":52385891},{"atb":[[46,0],[50,10.6]],"id":52385903}],"con":true,"img":false}]}
{"op":"mcm","clk":"11550914629","pt":1719505814377,"mc":[{"id":"1.230178176","rc":[{"atb":[[55,0]],"id":52385910},{"atb":[[90,0]],"id":52385883},{"atb":[[130,0]],"id":52385885},{"atb":[[44,0]],"id":52385896},{"atb":[[100,0]],"id":52385884}],"con":true,"img":false}]}
{"op":"mcm","clk":"11550914710","pt":1719505815671,"mc":[{"id":"1.230178176","rc":[{"atb":[[38,0]],"id":52385893}],"con":true,"img":false}]}
{"op":"mcm","clk":"11550914727","pt":1719505815981,"mc":[{"id":"1.230178176","rc":[{"atb":[[11,0]],"id":52385897}],"con":true,"img":false}]}
{"op":"mcm","clk":"11550914736","pt":1719505816085,"mc":[{"id":"1.230178176","rc":[{"atb":[[12,9]],"id":52385897}],"con":true,"img":false}]}
{"op":"mcm","clk":"11550914744","pt":1719505816188,"mc":[{"id":"1.230178176","rc":[{"atb":[[42,5],[50,2.5],[26,0],[30,0]],"id":52385910},{"atl":[[150,5],[160,0],[110,2.5],[120,0]],"id":52385918},{"atl":[[290,2.5],[370,0]],"id":52385889},{"atb":[[34,0],[70,5],[42,0],[90,2.5]],"id":52385883},{"atb":[[130,2.5],[44,0],[95,5],[55,0]],"id":52385885},{"atb":[[21,5],[25,2.5]],"id":52385896},{"atl":[[75,5],[80,0],[55,2.5],[60,0]],"id":52385890},{"atl":[[75,2.5],[80,0],[95,5],[100,0]],"id":52385892},{"atl":[[34,2.5],[36,0],[42,5],[44,0]],"id":52385904},{"atb":[[6.4,0],[5.8,0],[6.6,2.5],[5.9,5]],"id":52385913},{"atl":[[34,2.5],[36,0],[44,0]],"id":52385907},{"atb":[[75,0],[160,2.5],[55,0],[120,5]],"id":52385886},{"atb":[[80,5],[100,2.5]],"id":52385884},{"atb":[[40,0],[80,2.5],[48,0],[60,5]],"id":52385917},{"atl":[[32,2.5],[36,0],[40,5],[44,0]],"id":52385897},{"atl":[[130,0],[90,2.5],[95,2],[120,5]],"id":52385893},{"atl":[[19.5,2.5],[21,0],[23,5],[25,0]],"id":52385905}],"con":true,"img":false}]}
