{"op":"mcm","clk":"11536832982","pt":1719431775514,"mc":[{"id":"1.230180126","marketDefinition":{"bspMarket":true,"turnInPlayEnabled":false,"persistenceEnabled":false,"marketBaseRate":5.0,"eventId":"33376437","eventTypeId":"4339","numberOfWinners":1,"bettingType":"ODDS","marketType":"WIN","marketTime":"2024-06-27T15:44:00.000Z","suspendTime":"2024-06-27T15:44:00.000Z","bspReconciled":false,"complete":true,"inPlay":false,"crossMatching":false,"runnersVoidable":false,"numberOfActiveRunners":6,"betDelay":0,"status":"OPEN","runners":[{"status":"ACTIVE","sortPriority":1,"id":62886137,"name":"1. Walk On Gaffer"},{"status":"ACTIVE","sortPriority":2,"id":49823335,"name":"2. Orange Sydney"},{"status":"ACTIVE","sortPriority":3,"id":66993945,"name":"3. Essjay Alfred"},{"status":"ACTIVE","sortPriority":4,"id":64851267,"name":"4. Pro Cooper"},{"status":"ACTIVE","sortPriority":5,"id":69475504,"name":"5. Golden Wind"},{"status":"ACTIVE","sortPriority":6,"id":61941224,"name":"6. Salacres Sydney"}],"regulators":["MR_INT"],"venue":"Towcester","countryCode":"GB","discountAllowed":false,"timezone":"Europe/London","openDate":"2024-06-27T13:33:00.000Z","version":5994767121,"name":"A3 500m","eventName":"Towcester 27th Jun"},"rc":[],"con":true,"img":false}]}
{"op":"mcm","clk":"11536833148","pt":1719431777535,"mc":[{"id":"1.230180126","marketDefinition":{"bspMarket":true,"turnInPlayEnabled":false,"persistenceEnabled":false,"marketBaseRate":5.0,"eventId":"33376437","eventTypeId":"4339","numberOfWinners":1,"bettingType":"ODDS","marketType":"WIN","marketTime":"2024-06-27T15:44:00.000Z","suspendTime":"2024-06-27T15:44:00.000Z","bspReconciled":false,"complete":true,"inPlay":false,"crossMatching":false,"runnersVoidable":false,"numberOfActiveRunners":6,"betDelay":0,"status":"OPEN","runners":[{"status":"ACTIVE","sortPriority":1,"id":62886137,"name":"1. Walk On Gaffer"},{"status":"ACTIVE","sortPriority":2,"id":49823335,"name":"2. Orange Sydney"},{"status":"ACTIVE","sortPriority":3,"id":66993945,"name":"3. Essjay Alfred"},{"status":"ACTIVE","sortPriority":4,"id":64851267,"name":"4. Pro Cooper"},{"status":"ACTIVE","sortPriority":5,"id":69475504,"name":"5. Golden Wind"},{"status":"ACTIVE","sortPriority":6,"id":61941224,"name":"6. Salacres Sydney"}],"regulators":["MR_INT"],"venue":"Towcester","countryCode":"GB","discountAllowed":true,"timezone":"Europe/London","openDate":"2024-06-27T13:33:00.000Z","version":5994767121,"name":"A3 500m","eventName":"Towcester 27th Jun"},"rc":[],"con":true,"img":false}]}
{"op":"mcm","clk":"11537083946","pt":1719435434393,"mc":[{"id":"1.230180126","rc":[{"atb":[[1.01,51.84]],"id":66993945},{"atl":[[1000,0.84]],"id":66993945},{"spn":500.5,"spf":"NaN","id":66993945},{"atb":[[1.03,17.28]],"id":49823335},{"atl":[[990,0.84]],"id":49823335},{"spn":495.51,"spf":"NaN","id":49823335},{"atb":[[1.03,17.28]],"id":64851267},{"atl":[[990,0.84]],"id":64851267},{"spn":495.51,"spf":"NaN","id":64851267},{"atb":[[1.03,17.28]],"id":62886137},{"atl":[[1000,0.84]],"id":62886137},{"spn":500.51,"spf":"NaN","id":62886137},{"atb":[[1.02,25.92]],"id":61941224},{"atl":[[990,0.84]],"id":61941224},{"spn":495.51,"spf":"NaN","id":61941224},{"atb":[[1.02,25.92]],"id":69475504},{"atl":[[990,0.84]],"id":69475504},{"spn":495.51,"spf":"NaN","id":69475504}],"con":true,"img":false}]}
{"op":"mcm","clk":"11537233730","pt":1719437882651,"mc":[{"id":"1.230180126","marketDefinition":{"bspMarket":true,"turnInPlayEnabled":false,"persistenceEnabled":false,"marketBaseRate":5.0,"eventId":"33376437","eventTypeId":"4339","numberOfWinners":1,"bettingType":"ODDS","marketType":"WIN","marketTime":"2024-06-27T15:44:00.000Z","suspendTime":"2024-06-27T15:44:00.000Z","bspReconciled":false,"complete":true,"inPlay":false,"crossMatching":false,"runnersVoidable":false,"numberOfActiveRunners":6,"betDelay":0,"status":"OPEN","runners":[{"status":"ACTIVE","sortPriority":1,"id":62886137,"name":"1. Walk On Gaffer"},{"status":"ACTIVE","sortPriority":2,"id":49823335,"name":"2. Orange Sydney"},{"status":"ACTIVE","sortPriority":3,"id":66993945,"name":"3. Essjay Alfred"},{"status":"ACTIVE","sortPriority":4,"id":64851267,"name":"4. Pro Cooper"},{"status":"ACTIVE","sortPriority":5,"id":69475504,"name":"5. Golden Wind"},{"status":"ACTIVE","sortPriority":6,"id":61941224,"name":"6. Salacres Sydney"}],"regulators":["MR_INT"],"venue":"Towcester","countryCode":"GB","discountAllowed":true,"timezone":"Europe/London","openDate":"2024-06-27T13:33:00.000Z","version":5994767121,"name":"A3 500m","eventName":"Towcester 27th Jun"},"rc":[{"atb":[[1.01,51.85]],"id":66993945},{"atl":[[1000,0.84]],"id":66993945},{"spn":500.5,"spf":"NaN","id":66993945},{"atb":[[1.03,17.28]],"id":49823335},{"atl":[[990,0.84]],"id":49823335},{"spn":495.51,"spf":"NaN","id":49823335},{"atb":[[1.03,17.28]],"id":64851267},{"atl":[[990,0.84]],"id":64851267},{"spn":495.51,"spf":"NaN","id":64851267},{"atb":[[1.03,17.28]],"id":62886137},{"atl":[[1000,0.84]],"id":62886137},{"spn":500.51,"spf":"NaN","id":62886137},{"atb":[[1.02,25.92]],"id":61941224},{"atl":[[990,0.84]],"id":61941224},{"spn":495.51,"spf":"NaN","id":61941224},{"atb":[[1.02,25.92]],"id":69475504},{"atl":[[990,0.84]],"id":69475504},{"spn":495.51,"spf":"NaN","id":69475504}],"con":true,"img":true}]}
{"op":"mcm","clk":"11537302465","pt":1719439037730,"mc":[{"id":"1.230180126","rc":[{"atb":[[1.01,51.85]],"id":66993945},{"atl":[[1000,0.23]],"id":66993945},{"atb":[[1.03,17.28]],"id":49823335},{"atl":[[990,0.23]],"id":49823335},{"atb":[[1.03,17.28]],"id":64851267},{"atl":[[990,0.23]],"id":64851267},{"atb":[[1.03,17.28]],"id":62886137},{"atl":[[1000,0.23]],"id":62886137},{"atb":[[1.02,25.92]],"id":61941224},{"atl":[[990,0.23]],"id":61941224},{"atb":[[1.02,25.92]],"id":69475504},{"atl":[[990,0.23]],"id":69475504}],"con":true,"img":false}]}
{"op":"mcm","clk":"11537574881","pt":1719443282702,"mc":[{"id":"1.230180126","marketDefinition":{"bspMarket":true,"turnInPlayEnabled":false,"persistenceEnabled":false,"marketBaseRate":5.0,"eventId":"33376437","eventTypeId":"4339","numberOfWinners":1,"bettingType":"ODDS","marketType":"WIN","marketTime":"2024-06-27T15:44:00.000Z","suspendTime":"2024-06-27T15:44:00.000Z","bspReconciled":false,"complete":true,"inPlay":false,"crossMatching":false,"runnersVoidable":false,"numberOfActiveRunners":6,"betDelay":0,"status":"OPEN","runners":[{"status":"ACTIVE","sortPriority":1,"id":62886137,"name":"1. Walk On Gaffer"},{"status":"ACTIVE","sortPriority":2,"id":49823335,"name":"2. Orange Sydney"},{"status":"ACTIVE","sortPriority":3,"id":66993945,"name":"3. Essjay Alfred"},{"status":"ACTIVE","sortPriority":4,"id":64851267,"name":"4. Pro Cooper"},{"status":"ACTIVE","sortPriority":5,"id":69475504,"name":"5. Golden Wind"},{"status":"ACTIVE","sortPriority":6,"id":61941224,"name":"6. Salacres Sydney"}],"regulators":["MR_INT"],"venue":"Towcester","countryCode":"GB","discountAllowed":true,"timezone":"Europe/London","openDate":"2024-06-27T13:33:00.000Z","version":5994767121,"name":"A3 500m","eventName":"Towcester 27th Jun"},"rc":[{"atb":[[1.01,51.85]],"id":66993945},{"atl":[[1000,0.23]],"id":66993945},{"spn":500.5,"spf":"NaN","id":66993945},{"atb":[[1.03,17.28]],"id":49823335},{"atl":[[990,0.23]],"id":49823335},{"spn":495.51,"spf":"NaN","id":49823335},{"atb":[[1.03,17.28]],"id":64851267},{"atl":[[990,0.23]],"id":64851267},{"spn":495.51,"spf":"NaN","id":64851267},{"atb":[[1.03,17.28]],"id":62886137},{"atl":[[1000,0.23]],"id":62886137},{"spn":500.51,"spf":"NaN","id":62886137},{"atb":[[1.02,25.92]],"id":61941224},{"atl":[[990,0.23]],"id":61941224},{"spn":495.51,"spf":"NaN","id":61941224},{"atb":[[1.02,25.92]],"id":69475504},{"atl":[[990,0.23]],"id":69475504},{"spn":495.51,"spf":"NaN","id":69475504}],"con":true,"img":true}]}
{"op":"mcm","clk":"11537956501","pt":1719448682743,"mc":[{"id":"1.230180126","marketDefinition":{"bspMarket":true,"turnInPlayEnabled":false,"persistenceEnabled":false,"marketBaseRate":5.0,"eventId":"33376437","eventTypeId":"4339","numberOfWinners":1,"bettingType":"ODDS","marketType":"WIN","marketTime":"2024-06-27T15:44:00.000Z","suspendTime":"2024-06-27T15:44:00.000Z","bspReconciled":false,"complete":true,"inPlay":false,"crossMatching":false,"runnersVoidable":false,"numberOfActiveRunners":6,"betDelay":0,"status":"OPEN","runners":[{"status":"ACTIVE","sortPriority":1,"id":62886137,"name":"1. Walk On Gaffer"},{"status":"ACTIVE","sortPriority":2,"id":49823335,"name":"2. Orange Sydney"},{"status":"ACTIVE","sortPriority":3,"id":66993945,"name":"3. Essjay Alfred"},{"status":"ACTIVE","sortPriority":4,"id":64851267,"name":"4. Pro Cooper"},{"status":"ACTIVE","sortPriority":5,"id":69475504,"name":"5. Golden Wind"},{"status":"ACTIVE","sortPriority":6,"id":61941224,"name":"6. Salacres Sydney"}],"regulators":["MR_INT"],"venue":"Towcester","countryCode":"GB","discountAllowed":true,"timezone":"Europe/London","openDate":"2024-06-27T13:33:00.000Z","version":5994767121,"name":"A3 500m","eventName":"Towcester 27th Jun"},"rc":[{"atb":[[1.01,51.85]],"id":66993945},{"atl":[[1000,0.23]],"id":66993945},{"spn":500.5,"spf":"NaN","id":66993945},{"atb":[[1.03,17.28]],"id":49823335},{"atl":[[990,0.23]],"id":49823335},{"spn":495.51,"spf":"NaN","id":49823335},{"atb":[[1.03,17.28]],"id":64851267},{"atl":[[990,0.23]],"id":64851267},{"spn":495.51,"spf":"NaN","id":64851267},{"atb":[[1.03,17.28]],"id":62886137},{"atl":[[1000,0.23]],"id":62886137},{"spn":500.51,"spf":"NaN","id":62886137},{"atb":[[1.02,25.92]],"id":61941224},{"atl":[[990,0.23]],"id":61941224},{"spn":495.51,"spf":"NaN","id":61941224},{"atb":[[1.02,25.92]],"id":69475504},{"atl":[[990,0.23]],"id":69475504},{"spn":495.51,"spf":"NaN","id":69475504}],"con":true,"img":true}]}
{"op":"mcm","clk":"11538172118","pt":1719454082686,"mc":[{"id":"1.230180126","marketDefinition":{"bspMarket":true,"turnInPlayEnabled":false,"persistenceEnabled":false,"marketBaseRate":5.0,"eventId":"33376437","eventTypeId":"4339","numberOfWinners":1,"bettingType":"ODDS","marketType":"WIN","marketTime":"2024-06-27T15:44:00.000Z","suspendTime":"2024-06-27T15:44:00.000Z","bspReconciled":false,"complete":true,"inPlay":false,"crossMatching":false,"runnersVoidable":false,"numberOfActiveRunners":6,"betDelay":0,"status":"OPEN","runners":[{"status":"ACTIVE","sortPriority":1,"id":62886137,"name":"1. Walk On Gaffer"},{"status":"ACTIVE","sortPriority":2,"id":49823335,"name":"2. Orange Sydney"},{"status":"ACTIVE","sortPriority":3,"id":66993945,"name":"3. Essjay Alfred"},{"status":"ACTIVE","sortPriority":4,"id":64851267,"name":"4. Pro Cooper"},{"status":"ACTIVE","sortPriority":5,"id":69475504,"name":"5. Golden Wind"},{"status":"ACTIVE","sortPriority":6,"id":61941224,"name":"6. Salacres Sydney"}],"regulators":["MR_INT"],"venue":"Towcester","countryCode":"GB","discountAllowed":true,"timezone":"Europe/London","openDate":"2024-06-27T13:33:00.000Z","version":5994767121,"name":"A3 500m","eventName":"Towcester 27th Jun"},"rc":[{"atb":[[1.01,51.86]],"id":66993945},{"atl":[[1000,0.23]],"id":66993945},{"spn":500.5,"spf":"NaN","id":66993945},{"atb":[[1.03,17.29]],"id":49823335},{"atl":[[990,0.23]],"id":49823335},{"spn":495.51,"spf":"NaN","id":49823335},{"atb":[[1.03,17.29]],"id":64851267},{"atl":[[990,0.23]],"id":64851267},{"spn":495.51,"spf":"NaN","id":64851267},{"atb":[[1.03,17.29]],"id":62886137},{"atl":[[1000,0.23]],"id":62886137},{"spn":500.51,"spf":"NaN","id":62886137},{"atb":[[1.02,25.93]],"id":61941224},{"atl":[[990,0.23]],"id":61941224},{"spn":495.51,"spf":"NaN","id":61941224},{"atb":[[1.02,25.93]],"id":69475504},{"atl":[[990,0.23]],"id":69475504},{"spn":495.51,"spf":"NaN","id":69475504}],"con":true,"img":true}]}
{"op":"mcm","clk":"11538369785","pt":1719459482771,"mc":[{"id":"1.230180126","marketDefinition":{"bspMarket":true,"turnInPlayEnabled":false,"persistenceEnabled":false,"marketBaseRate":5.0,"eventId":"33376437","eventTypeId":"4339","numberOfWinners":1,"bettingType":"ODDS","marketType":"WIN","marketTime":"2024-06-27T15:44:00.000Z","suspendTime":"2024-06-27T15:44:00.000Z","bspReconciled":false,"complete":true,"inPlay":false,"crossMatching":false,"runnersVoidable":false,"numberOfActiveRunners":6,"betDelay":0,"status":"OPEN","runners":[{"status":"ACTIVE","sortPriority":1,"id":62886137,"name":"1. Walk On Gaffer"},{"status":"ACTIVE","sortPriority":2,"id":49823335,"name":"2. Orange Sydney"},{"status":"ACTIVE","sortPriority":3,"id":66993945,"name":"3. Essjay Alfred"},{"status":"ACTIVE","sortPriority":4,"id":64851267,"name":"4. Pro Cooper"},{"status":"ACTIVE","sortPriority":5,"id":69475504,"name":"5. Golden Wind"},{"status":"ACTIVE","sortPriority":6,"id":61941224,"name":"6. Salacres Sydney"}],"regulators":["MR_INT"],"venue":"Towcester","countryCode":"GB","discountAllowed":true,"timezone":"Europe/London","openDate":"2024-06-27T13:33:00.000Z","version":5994767121,"name":"A3 500m","eventName":"Towcester 27th Jun"},"rc":[{"atb":[[1.01,51.87]],"id":66993945},{"atl":[[1000,0.23]],"id":66993945},{"spn":500.5,"spf":"NaN","id":66993945},{"atb":[[1.03,17.29]],"id":49823335},{"atl":[[990,0.23]],"id":49823335},{"spn":495.51,"spf":"NaN","id":49823335},{"atb":[[1.03,17.29]],"id":64851267},{"atl":[[990,0.23]],"id":64851267},{"spn":495.51,"spf":"NaN","id":64851267},{"atb":[[1.03,17.29]],"id":62886137},{"atl":[[1000,0.23]],"id":62886137},{"spn":500.51,"spf":"NaN","id":62886137},{"atb":[[1.02,25.93]],"id":61941224},{"atl":[[990,0.23]],"id":61941224},{"spn":495.51,"spf":"NaN","id":61941224},{"atb":[[1.02,25.93]],"id":69475504},{"atl":[[990,0.23]],"id":69475504},{"spn":495.51,"spf":"NaN","id":69475504}],"con":true,"img":true}]}
{"op":"mcm","clk":"11538596915","pt":1719464882715,"mc":[{"id":"1.230180126","marketDefinition":{"bspMarket":true,"turnInPlayEnabled":false,"persistenceEnabled":false,"marketBaseRate":5.0,"eventId":"33376437","eventTypeId":"4339","numberOfWinners":1,"bettingType":"ODDS","marketType":"WIN","marketTime":"2024-06-27T15:44:00.000Z","suspendTime":"2024-06-27T15:44:00.000Z","bspReconciled":false,"complete":true,"inPlay":false,"crossMatching":false,"runnersVoidable":false,"numberOfActiveRunners":6,"betDelay":0,"status":"OPEN","runners":[{"status":"ACTIVE","sortPriority":1,"id":62886137,"name":"1. Walk On Gaffer"},{"status":"ACTIVE","sortPriority":2,"id":49823335,"name":"2. Orange Sydney"},{"status":"ACTIVE","sortPriority":3,"id":66993945,"name":"3. Essjay Alfred"},{"status":"ACTIVE","sortPriority":4,"id":64851267,"name":"4. Pro Cooper"},{"status":"ACTIVE","sortPriority":5,"id":69475504,"name":"5. Golden Wind"},{"status":"ACTIVE","sortPriority":6,"id":61941224,"name":"6. Salacres Sydney"}],"regulators":["MR_INT"],"venue":"Towcester","countryCode":"GB","discountAllowed":true,"timezone":"Europe/London","openDate":"2024-06-27T13:33:00.000Z","version":5994767121,"name":"A3 500m","eventName":"Towcester 27th Jun"},"rc":[{"atb":[[1.01,51.86]],"id":66993945},{"atl":[[1000,0.23]],"id":66993945},{"spn":500.5,"spf":"NaN","id":66993945},{"atb":[[1.03,17.29]],"id":49823335},{"atl":[[990,0.23]],"id":49823335},{"spn":495.51,"spf":"NaN","id":49823335},{"atb":[[1.03,17.29]],"id":64851267},{"atl":[[990,0.23]],"id":64851267},{"spn":495.51,"spf":"NaN","id":64851267},{"atb":[[1.03,17.29]],"id":62886137},{"atl":[[1000,0.23]],"id":62886137},{"spn":500.51,"spf":"NaN","id":62886137},{"atb":[[1.02,25.93]],"id":61941224},{"atl":[[990,0.23]],"id":61941224},{"spn":495.51,"spf":"NaN","id":61941224},{"atb":[[1.02,25.93]],"id":69475504},{"atl":[[990,0.23]],"id":69475504},{"spn":495.51,"spf":"NaN","id":69475504}],"con":true,"img":true}]}
{"op":"mcm","clk":"11538748661","pt":1719468205577,"mc":[{"id":"1.230180126","rc":[{"atb":[[1.01,51.86],[2.04,8.71]],"id":66993945},{"spn":501.02,"spf":"NaN","id":66993945},{"atb":[[1.03,17.29],[2.06,12.32]],"id":49823335},{"spn":496.03,"spf":"NaN","id":49823335},{"atb":[[2.02,12.08],[1.03,17.29]],"id":64851267},{"spn":496.01,"spf":"NaN","id":64851267},{"atb":[[1.03,17.29],[2.08,13.32]],"id":62886137},{"spn":501.04,"spf":"NaN","id":62886137},{"atb":[[1.02,25.93],[2.1,11.66]],"id":61941224},{"spn":496.05,"spf":"NaN","id":61941224},{"atb":[[1.02,25.93],[2.08,8.88]],"id":69475504},{"spn":496.04,"spf":"NaN","id":69475504}],"con":true,"img":false}]}
{"op":"mcm","clk":"11538750565","pt":1719468245668,"mc":[{"id":"1.230180126","rc":[{"atb":[[2.1,3.16]],"id":69475504}],"con":true,"img":false}]}
{"op":"mcm","clk":"11538750575","pt":1719468245874,"mc":[{"id":"1.230180126","rc":[{"atb":[[2.1,3.16]],"id":62886137}],"con":true,"img":false}]}
{"op":"mcm","clk":"11538750586","pt":1719468246032,"mc":[{"id":"1.230180126","rc":[{"atb":[[2.12,3.16]],"id":61941224}],"con":true,"img":false}]}
{"op":"mcm","clk":"11538750608","pt":1719468246443,"mc":[{"id":"1.230180126","rc":[{"atb":[[2.04,3.16]],"id":64851267}],"con":true,"img":false}]}
{"op":"mcm","clk":"11538750630","pt":1719468246751,"mc":[{"id":"1.230180126","rc":[{"atb":[[2.06,3.16]],"id":66993945}],"con":true,"img":false}]}
{"op":"mcm","clk":"11538750633","pt":1719468246854,"mc":[{"id":"1.230180126","rc":[{"atb":[[2.08,3.16]],"id":49823335}],"con":true,"img":false}]}
{"op":"mcm","clk":"11538752554","pt":1719468284716,"mc":[{"id":"1.230180126","rc":[{"spn":501.03,"spf":"NaN","id":66993945},{"spn":496.04,"spf":"NaN","id":49823335},{"spn":496.02,"spf":"NaN","id":64851267},{"atb":[[2.1,6.55]],"id":62886137},{"spn":501.05,"spf":"NaN","id":62886137},{"spn":496.06,"spf":"NaN","id":61941224},{"spn":496.05,"spf":"NaN","id":69475504}],"con":true,"img":false}]}
{"op":"mcm","clk":"11538752560","pt":1719468284818,"mc":[{"id":"1.230180126","rc":[{"atb":[[2.06,6.55]],"id":66993945}],"con":true,"img":false}]}
{"op":"mcm","clk":"11538752572","pt":1719468285024,"mc":[{"id":"1.230180126","rc":[{"atb":[[2.08,6.55]],"id":49823335}],"con":true,"img":false}]}
{"op":"mcm","clk":"11538752591","pt":1719468285387,"mc":[{"id":"1.230180126","rc":[{"atb":[[2.12,6.55]],"id":61941224}],"con":true,"img":false}]}
{"op":"mcm","clk":"11538752610","pt":1719468285816,"mc":[{"id":"1.230180126","rc":[{"atb":[[2.1,6.55]],"id":69475504}],"con":true,"img":false}]}
{"op":"mcm","clk":"11538752620","pt":1719468286000,"mc":[{"id":"1.230180126","rc":[{"atb":[[2.04,6.55]],"id":64851267}],"con":true,"img":false}]}
{"op":"mcm","clk":"11538754059","pt":1719468311791,"mc":[{"id":"1.230180126","marketDefinition":{"bspMarket":true,"turnInPlayEnabled":false,"persistenceEnabled":false,"marketBaseRate":5.0,"eventId":"33376437","eventTypeId":"4339","numberOfWinners":1,"bettingType":"ODDS","marketType":"WIN","marketTime":"2024-06-27T15:44:00.000Z","suspendTime":"2024-06-27T15:44:00.000Z","bspReconciled":false,"complete":true,"inPlay":false,"crossMatching":true,"runnersVoidable":false,"numberOfActiveRunners":6,"betDelay":0,"status":"OPEN","runners":[{"status":"ACTIVE","sortPriority":1,"id":62886137,"name":"1. Walk On Gaffer"},{"status":"ACTIVE","sortPriority":2,"id":49823335,"name":"2. Orange Sydney"},{"status":"ACTIVE","sortPriority":3,"id":66993945,"name":"3. Essjay Alfred"},{"status":"ACTIVE","sortPriority":4,"id":64851267,"name":"4. Pro Cooper"},{"status":"ACTIVE","sortPriority":5,"id":69475504,"name":"5. Golden Wind"},{"status":"ACTIVE","sortPriority":6,"id":61941224,"name":"6. Salacres Sydney"}],"regulators":["MR_INT"],"venue":"Towcester","countryCode":"GB","discountAllowed":true,"timezone":"Europe/London","openDate":"2024-06-27T13:33:00.000Z","version":5994767121,"name":"A3 500m","eventName":"Towcester 27th Jun"},"rc":[],"con":true,"img":false}]}
{"op":"mcm","clk":"11538872134","pt":1719470646265,"mc":[{"id":"1.230180126","rc":[{"atl":[[150,4]],"id":66993945},{"spn":76.03,"spf":"NaN","id":66993945},{"atl":[[150,4]],"id":49823335},{"spn":76.04,"spf":"NaN","id":49823335},{"atl":[[150,4]],"id":64851267},{"spn":76.02,"spf":"NaN","id":64851267},{"atl":[[150,4]],"id":62886137},{"spn":76.05,"spf":"NaN","id":62886137},{"atl":[[150,4]],"id":61941224},{"spn":76.06,"spf":"NaN","id":61941224},{"atl":[[150,4]],"id":69475504},{"spn":76.05,"spf":"NaN","id":69475504}],"con":true,"img":false}]}
{"op":"mcm","clk":"11538938845","pt":1719472078369,"mc":[{"id":"1.230180126","rc":[{"atb":[[1.01,51.82],[2.06,6.54],[2.04,8.71]],"id":66993945},{"atl":[[28,0.6],[1000,0.23]],"id":66993945},{"spn":15.03,"spf":"NaN","id":66993945},{"atb":[[2.06,12.31],[1.03,17.27],[2.08,6.54]],"id":49823335},{"atl":[[990,0.23]],"id":49823335},{"atb":[[2.02,12.07],[1.03,17.27],[2.04,6.54]],"id":64851267},{"atl":[[21,4],[11.5,2],[990,0.23],[15.5,3]],"id":64851267},{"spn":6.77,"spf":"NaN","id":64851267},{"atb":[[1.03,17.27],[2.1,6.54],[2.08,13.32]],"id":62886137},{"atl":[[1000,0.23]],"id":62886137},{"atb":[[1.02,25.91],[2.12,6.54],[2.1,11.65]],"id":61941224},{"atl":[[990,0.23]],"id":61941224},{"atb":[[1.02,25.91],[6,4],[2.1,6.54],[4.2,15.62],[2.08,8.88]],"id":69475504},{"atl":[[990,0.23]],"id":69475504},{"spn":78.0,"spf":"NaN","id":69475504}],"con":true,"img":false}]}
{"op":"mcm","clk":"11538938950","pt":1719472081081,"mc":[{"id":"1.230180126","rc":[{"atb":[[2.1,3.16]],"id":69475504}],"con":true,"img":false}]}
{"op":"mcm","clk":"11538939730","pt":1719472096379,"mc":[{"id":"1.230180126","rc":[{"atb":[[2.1,0]],"id":69475504}],"con":true,"img":false}]}
{"op":"mcm","clk":"11538940759","pt":1719472113536,"mc":[{"id":"1.230180126","rc":[{"atb":[[2.04,0]],"id":66993945},{"atb":[[2.06,0]],"id":49823335},{"atb":[[2.02,0]],"id":64851267},{"atb":[[2.08,0]],"id":62886137},{"atb":[[2.1,0]],"id":61941224}],"con":true,"img":false}]}
{"op":"mcm","clk":"11538940765","pt":1719472113633,"mc":[{"id":"1.230180126","rc":[{"atb":[[2.08,8.71]],"id":66993945},{"atb":[[2.1,12.31]],"id":49823335},{"atb":[[2.06,12.07]],"id":64851267},{"atb":[[2.12,13.32]],"id":62886137},{"atb":[[2.14,11.65]],"id":61941224}],"con":true,"img":false}]}
{"op":"mcm","clk":"11538943082","pt":1719472149893,"mc":[{"id":"1.230180126","rc":[{"atb":[[2.06,3.38]],"id":66993945},{"spn":15.04,"spf":"NaN","id":66993945},{"spn":76.05,"spf":"NaN","id":49823335},{"spn":6.78,"spf":"NaN","id":64851267},{"spn":76.06,"spf":"NaN","id":62886137},{"spn":76.07,"spf":"NaN","id":61941224}],"con":true,"img":false}]}
{"op":"mcm","clk":"11538943102","pt":1719472150150,"mc":[{"id":"1.230180126","rc":[{"atb":[[2.04,3.38]],"id":64851267}],"con":true,"img":false}]}
{"op":"mcm","clk":"11538943153","pt":1719472150867,"mc":[{"id":"1.230180126","rc":[{"atb":[[2.1,3.38]],"id":62886137}],"con":true,"img":false}]}
{"op":"mcm","clk":"11538943264","pt":1719472152866,"mc":[{"id":"1.230180126","rc":[{"atb":[[2.08,3.38]],"id":49823335},{"atb":[[2.12,3.38]],"id":61941224}],"con":true,"img":false}]}
{"op":"mcm","clk":"11538943363","pt":1719472154463,"mc":[{"id":"1.230180126","rc":[{"atb":[[2.1,3.16]],"id":66993945}],"con":true,"img":false}]}
{"op":"mcm","clk":"11538943391","pt":1719472154872,"mc":[{"id":"1.230180126","rc":[{"atb":[[2.12,3.16]],"id":49823335}],"con":true,"img":false}]}
{"op":"mcm","clk":"11538943435","pt":1719472155488,"mc":[{"id":"1.230180126","rc":[{"atb":[[2.16,3.16]],"id":61941224}],"con":true,"img":false}]}
{"op":"mcm","clk":"11538943491","pt":1719472156358,"mc":[{"id":"1.230180126","rc":[{"atb":[[2.08,3.16]],"id":64851267}],"con":true,"img":false}]}
{"op":"mcm","clk":"11538943563","pt":1719472157687,"mc":[{"id":"1.230180126","rc":[{"atb":[[2.14,3.16]],"id":62886137}],"con":true,"img":false}]}
{"op":"mcm","clk":"11538943990","pt":1719472164920,"mc":[{"id":"1.230180126","rc":[{"atb":[[2.04,0]],"id":64851267}],"con":true,"img":false}]}
{"op":"mcm","clk":"11538944013","pt":1719472165279,"mc":[{"id":"1.230180126","rc":[{"atb":[[2.1,0]],"id":62886137}],"con":true,"img":false}]}
{"op":"mcm","clk":"11538944054","pt":1719472166095,"mc":[{"id":"1.230180126","rc":[{"atb":[[2.08,0]],"id":49823335}],"con":true,"img":false}]}
{"op":"mcm","clk":"11538944107","pt":1719472167019,"mc":[{"id":"1.230180126","rc":[{"atb":[[2.06,0]],"id":66993945}],"con":true,"img":false}]}
{"op":"mcm","clk":"11538944125","pt":1719472167221,"mc":[{"id":"1.230180126","rc":[{"atb":[[2.12,0]],"id":61941224}],"con":true,"img":false}]}
{"op":"mcm","clk":"11538944979","pt":1719472181490,"mc":[{"id":"1.230180126","rc":[{"atb":[[2.08,6.54]],"id":64851267}],"con":true,"img":false}]}
{"op":"mcm","clk":"11538944986","pt":1719472181593,"mc":[{"id":"1.230180126","rc":[{"atb":[[2.16,6.54]],"id":61941224}],"con":true,"img":false}]}
{"op":"mcm","clk":"11538945029","pt":1719472182212,"mc":[{"id":"1.230180126","rc":[{"atb":[[2.14,6.54]],"id":62886137}],"con":true,"img":false}]}
{"op":"mcm","clk":"11538945070","pt":1719472182933,"mc":[{"id":"1.230180126","rc":[{"atb":[[2.12,6.54]],"id":49823335}],"con":true,"img":false}]}
{"op":"mcm","clk":"11538945115","pt":1719472183504,"mc":[{"id":"1.230180126","rc":[{"atb":[[2.1,6.54]],"id":66993945}],"con":true,"img":false}]}
{"op":"mcm","clk":"11539124103","pt":1719475682702,"mc":[{"id":"1.230180126","marketDefinition":{"bspMarket":true,"turnInPlayEnabled":false,"persistenceEnabled":false,"marketBaseRate":5.0,"eventId":"33376437","eventTypeId":"4339","numberOfWinners":1,"bettingType":"ODDS","marketType":"WIN","marketTime":"2024-06-27T15:44:00.000Z","suspendTime":"2024-06-27T15:44:00.000Z","bspReconciled":false,"complete":true,"inPlay":false,"crossMatching":true,"runnersVoidable":false,"numberOfActiveRunners":6,"betDelay":0,"status":"OPEN","runners":[{"status":"ACTIVE","sortPriority":1,"id":62886137,"name":"1. Walk On Gaffer"},{"status":"ACTIVE","sortPriority":2,"id":49823335,"name":"2. Orange Sydney"},{"status":"ACTIVE","sortPriority":3,"id":66993945,"name":"3. Essjay Alfred"},{"status":"ACTIVE","sortPriority":4,"id":64851267,"name":"4. Pro Cooper"},{"status":"ACTIVE","sortPriority":5,"id":69475504,"name":"5. Golden Wind"},{"status":"ACTIVE","sortPriority":6,"id":61941224,"name":"6. Salacres Sydney"}],"regulators":["MR_INT"],"venue":"Towcester","countryCode":"GB","discountAllowed":true,"timezone":"Europe/London","openDate":"2024-06-27T13:33:00.000Z","version":5994767121,"name":"A3 500m","eventName":"Towcester 27th Jun"},"rc":[{"atb":[[1.01,51.84],[2.1,6.55],[2.08,8.71]],"id":66993945},{"atl":[[150,4],[28,0.6],[1000,0.23]],"id":66993945},{"spn":15.05,"spf":"NaN","id":66993945},{"atb":[[1.03,17.28],[2.12,6.55],[2.1,12.31]],"id":49823335},{"atl":[[150,4],[990,0.23]],"id":49823335},{"spn":76.06,"spf":"NaN","id":49823335},{"atb":[[2.06,12.08],[1.03,17.28],[2.08,6.55]],"id":64851267},{"atl":[[150,4],[21,4],[11.5,2],[990,0.23],[15.5,3]],"id":64851267},{"spn":6.79,"spf":"NaN","id":64851267},{"atb":[[1.03,17.28],[2.12,13.32],[2.14,6.55]],"id":62886137},{"atl":[[150,4],[1000,0.23]],"id":62886137},{"spn":76.07,"spf":"NaN","id":62886137},{"atb":[[1.02,25.92],[2.16,6.55],[2.14,11.65]],"id":61941224},{"atl":[[150,4],[990,0.23]],"id":61941224},{"spn":76.08,"spf":"NaN","id":61941224},{"atb":[[1.02,25.92],[6,4],[4.2,15.62],[2.08,8.88]],"id":69475504},{"atl":[[150,4],[990,0.23]],"id":69475504},{"spn":78.0,"spf":"NaN","id":69475504}],"con":true,"img":true}]}
{"op":"mcm","clk":"11539128057","pt":1719475713534,"mc":[{"id":"1.230180126","rc":[{"atb":[[1.01,51.84],[2.1,6.55],[2.08,0]],"id":66993945},{"atl":[[1000,0.23]],"id":66993945},{"spn":15.05,"spf":"NaN","id":66993945},{"atb":[[1.03,17.28],[2.12,6.55],[2.1,0]],"id":49823335},{"atl":[[990,0.23]],"id":49823335},{"spn":76.06,"spf":"NaN","id":49823335},{"atb":[[2.06,0],[1.03,17.28],[2.08,6.55]],"id":64851267},{"atl":[[990,0.23]],"id":64851267},{"spn":6.79,"spf":"NaN","id":64851267},{"atb":[[1.03,17.28],[2.12,0],[2.14,6.55]],"id":62886137},{"atl":[[1000,0.23]],"id":62886137},{"spn":76.07,"spf":"NaN","id":62886137},{"atb":[[1.02,25.92],[2.16,6.55],[2.14,0]],"id":61941224},{"atl":[[990,0.23]],"id":61941224},{"spn":76.08,"spf":"NaN","id":61941224},{"atb":[[1.02,25.92],[2.08,8.88]],"id":69475504},{"atl":[[990,0.23]],"id":69475504}],"con":true,"img":false}]}
{"op":"mcm","clk":"11539128113","pt":1719475713637,"mc":[{"id":"1.230180126","rc":[{"atb":[[2.12,8.71]],"id":66993945},{"atb":[[2.14,12.31]],"id":49823335},{"atb":[[2.1,12.08]],"id":64851267},{"atb":[[2.16,13.32]],"id":62886137},{"atb":[[2.18,11.65]],"id":61941224}],"con":true,"img":false}]}
{"op":"mcm","clk":"11539133403","pt":1719475798246,"mc":[{"id":"1.230180126","rc":[{"spn":15.06,"spf":"NaN","id":66993945},{"spn":76.07,"spf":"NaN","id":49823335},{"atb":[[2.08,3.16]],"id":64851267},{"spn":6.8,"spf":"NaN","id":64851267},{"spn":76.08,"spf":"NaN","id":62886137},{"spn":76.09,"spf":"NaN","id":61941224}],"con":true,"img":false}]}
{"op":"mcm","clk":"11539133417","pt":1719475798451,"mc":[{"id":"1.230180126","rc":[{"atb":[[2.1,3.16]],"id":66993945}],"con":true,"img":false}]}
{"op":"mcm","clk":"11539133475","pt":1719475799224,"mc":[{"id":"1.230180126","rc":[{"atb":[[2.14,3.16]],"id":62886137}],"con":true,"img":false}]}
{"op":"mcm","clk":"11539133495","pt":1719475799531,"mc":[{"id":"1.230180126","rc":[{"atb":[[2.16,3.16]],"id":61941224}],"con":true,"img":false}]}
{"op":"mcm","clk":"11539133558","pt":1719475800463,"mc":[{"id":"1.230180126","rc":[{"atb":[[2.14,3.38]],"id":66993945}],"con":true,"img":false}]}
{"op":"mcm","clk":"11539133572","pt":1719475800671,"mc":[{"id":"1.230180126","rc":[{"atb":[[2.12,3.16]],"id":49823335}],"con":true,"img":false}]}
{"op":"mcm","clk":"11539133619","pt":1719475801141,"mc":[{"id":"1.230180126","rc":[{"atb":[[2.12,3.38]],"id":64851267}],"con":true,"img":false}]}
{"op":"mcm","clk":"11539133690","pt":1719475802078,"mc":[{"id":"1.230180126","rc":[{"atb":[[2.18,3.38]],"id":62886137}],"con":true,"img":false}]}
{"op":"mcm","clk":"11539133746","pt":1719475802954,"mc":[{"id":"1.230180126","rc":[{"atb":[[2.2,3.38]],"id":61941224}],"con":true,"img":false}]}
{"op":"mcm","clk":"11539133769","pt":1719475803367,"mc":[{"id":"1.230180126","rc":[{"atb":[[2.16,3.38]],"id":49823335}],"con":true,"img":false}]}
{"op":"mcm","clk":"11539134368","pt":1719475811350,"mc":[{"id":"1.230180126","rc":[{"atb":[[2.1,0]],"id":66993945},{"atb":[[2.12,0]],"id":49823335},{"atb":[[2.08,0]],"id":64851267},{"atb":[[2.14,0]],"id":62886137},{"atb":[[2.16,0]],"id":61941224}],"con":true,"img":false}]}
{"op":"mcm","clk":"11539153387","pt":1719476118369,"mc":[{"id":"1.230180126","rc":[{"spn":15.07,"spf":"NaN","id":66993945},{"spn":76.08,"spf":"NaN","id":49823335},{"spn":6.81,"spf":"NaN","id":64851267},{"atb":[[2.18,6.55]],"id":62886137},{"spn":76.09,"spf":"NaN","id":62886137},{"spn":76.1,"spf":"NaN","id":61941224}],"con":true,"img":false}]}
{"op":"mcm","clk":"11539153401","pt":1719476118564,"mc":[{"id":"1.230180126","rc":[{"atb":[[2.14,6.55]],"id":66993945}],"con":true,"img":false}]}
{"op":"mcm","clk":"11539153408","pt":1719476118666,"mc":[{"id":"1.230180126","rc":[{"atb":[[2.16,6.55]],"id":49823335}],"con":true,"img":false}]}
{"op":"mcm","clk":"11539153414","pt":1719476118773,"mc":[{"id":"1.230180126","rc":[{"atb":[[2.2,6.55]],"id":61941224}],"con":true,"img":false}]}
{"op":"mcm","clk":"11539153420","pt":1719476118880,"mc":[{"id":"1.230180126","rc":[{"atb":[[2.12,6.55]],"id":64851267}],"con":true,"img":false}]}
{"op":"mcm","clk":"11539341511","pt":1719479311958,"mc":[{"id":"1.230180126","rc":[{"atb":[[1.01,51.83],[2.12,0],[2.14,6.54]],"id":66993945},{"atb":[[1.03,17.28],[2.16,6.54],[2.14,0]],"id":49823335},{"atb":[[1.03,17.28],[2.12,6.54],[2.1,0]],"id":64851267},{"atb":[[1.03,17.28],[2.18,6.54],[2.16,0]],"id":62886137},{"atb":[[1.02,25.91],[2.18,0],[2.2,6.54]],"id":61941224},{"atb":[[1.02,25.91],[2.08,8.88]],"id":69475504}],"con":true,"img":false}]}
{"op":"mcm","clk":"11539341517","pt":1719479312057,"mc":[{"id":"1.230180126","rc":[{"atb":[[2.16,8.71]],"id":66993945},{"atb":[[2.18,12.31]],"id":49823335},{"atb":[[2.14,12.08]],"id":64851267},{"atb":[[2.2,13.32]],"id":62886137},{"atb":[[2.22,11.65]],"id":61941224}],"con":true,"img":false}]}
{"op":"mcm","clk":"11539346819","pt":1719479397467,"mc":[{"id":"1.230180126","rc":[{"spn":15.08,"spf":"NaN","id":66993945},{"spn":76.09,"spf":"NaN","id":49823335},{"spn":6.82,"spf":"NaN","id":64851267},{"atb":[[2.18,3.38]],"id":62886137},{"spn":76.1,"spf":"NaN","id":62886137},{"spn":76.11,"spf":"NaN","id":61941224}],"con":true,"img":false}]}
{"op":"mcm","clk":"11539346862","pt":1719479398297,"mc":[{"id":"1.230180126","rc":[{"atb":[[2.2,3.38]],"id":61941224}],"con":true,"img":false}]}
{"op":"mcm","clk":"11539346875","pt":1719479398393,"mc":[{"id":"1.230180126","rc":[{"atb":[[2.12,3.38]],"id":64851267}],"con":true,"img":false}]}
{"op":"mcm","clk":"11539346902","pt":1719479398905,"mc":[{"id":"1.230180126","rc":[{"atb":[[2.16,3.38]],"id":49823335}],"con":true,"img":false}]}
{"op":"mcm","clk":"11539346927","pt":1719479399269,"mc":[{"id":"1.230180126","rc":[{"atb":[[2.14,3.38]],"id":66993945}],"con":true,"img":false}]}
{"op":"mcm","clk":"11539349220","pt":1719479434638,"mc":[{"id":"1.230180126","rc":[{"atb":[[2.18,0]],"id":62886137}],"con":true,"img":false}]}
{"op":"mcm","clk":"11539349232","pt":1719479434848,"mc":[{"id":"1.230180126","rc":[{"atb":[[2.16,0]],"id":49823335}],"con":true,"img":false}]}
{"op":"mcm","clk":"11539349258","pt":1719479435255,"mc":[{"id":"1.230180126","rc":[{"atb":[[2.14,0]],"id":66993945}],"con":true,"img":false}]}
{"op":"mcm","clk":"11539349275","pt":1719479435519,"mc":[{"id":"1.230180126","rc":[{"atb":[[2.12,0]],"id":64851267}],"con":true,"img":false}]}
{"op":"mcm","clk":"11539349281","pt":1719479435623,"mc":[{"id":"1.230180126","rc":[{"atb":[[2.2,0]],"id":61941224}],"con":true,"img":false}]}
{"op":"mcm","clk":"11539349452","pt":1719479438715,"mc":[{"id":"1.230180126","rc":[{"atb":[[2.2,3.38]],"id":49823335}],"con":true,"img":false}]}
{"op":"mcm","clk":"11539349470","pt":1719479439024,"mc":[{"id":"1.230180126","rc":[{"atb":[[2.18,3.38]],"id":66993945}],"con":true,"img":false}]}
{"op":"mcm","clk":"11539349482","pt":1719479439239,"mc":[{"id":"1.230180126","rc":[{"atb":[[2.22,3.38]],"id":62886137}],"con":true,"img":false}]}
{"op":"mcm","clk":"11539349501","pt":1719479439544,"mc":[{"id":"1.230180126","rc":[{"atb":[[2.16,3.38]],"id":64851267}],"con":true,"img":false}]}
{"op":"mcm","clk":"11539349511","pt":1719479439754,"mc":[{"id":"1.230180126","rc":[{"atb":[[2.24,3.38]],"id":61941224}],"con":true,"img":false}]}
{"op":"mcm","clk":"11539367711","pt":1719479707373,"mc":[{"id":"1.230180126","rc":[{"atb":[[2.18,6.54]],"id":66993945},{"spn":15.09,"spf":"NaN","id":66993945},{"spn":76.1,"spf":"NaN","id":49823335},{"spn":6.83,"spf":"NaN","id":64851267},{"spn":76.11,"spf":"NaN","id":62886137},{"spn":76.12,"spf":"NaN","id":61941224}],"con":true,"img":false}]}
{"op":"mcm","clk":"11539367726","pt":1719479707528,"mc":[{"id":"1.230180126","rc":[{"atb":[[2.22,6.54]],"id":62886137}],"con":true,"img":false}]}
{"op":"mcm","clk":"11539367795","pt":1719479708447,"mc":[{"id":"1.230180126","rc":[{"atb":[[2.16,6.54]],"id":64851267}],"con":true,"img":false}]}
{"op":"mcm","clk":"11539367802","pt":1719479708553,"mc":[{"id":"1.230180126","rc":[{"atb":[[2.2,6.54]],"id":49823335}],"con":true,"img":false}]}
{"op":"mcm","clk":"11539367817","pt":1719479708758,"mc":[{"id":"1.230180126","rc":[{"atb":[[2.24,6.54]],"id":61941224}],"con":true,"img":false}]}
{"op":"mcm","clk":"11539545547","pt":1719482912305,"mc":[{"id":"1.230180126","rc":[{"atb":[[1.01,51.83],[2.18,6.54],[2.16,0]],"id":66993945},{"atb":[[1.03,17.27],[2.18,0],[2.2,6.54]],"id":49823335},{"atb":[[1.03,17.27],[2.16,6.54],[2.14,0]],"id":64851267},{"atb":[[1.03,17.27],[2.22,6.54],[2.2,0]],"id":62886137},{"atb":[[2.24,6.54],[2.22,0],[1.02,25.91]],"id":61941224},{"atb":[[1.02,25.91],[2.08,8.88]],"id":69475504}],"con":true,"img":false}]}
{"op":"mcm","clk":"11539545566","pt":1719482912418,"mc":[{"id":"1.230180126","rc":[{"atb":[[2.2,8.71]],"id":66993945},{"atb":[[2.22,12.31]],"id":49823335},{"atb":[[2.18,12.07]],"id":64851267},{"atb":[[2.24,13.32]],"id":62886137},{"atb":[[2.26,11.65]],"id":61941224}],"con":true,"img":false}]}
{"op":"mcm","clk":"11539548432","pt":1719482955961,"mc":[{"id":"1.230180126","rc":[{"atb":[[2.18,3.16]],"id":66993945}],"con":true,"img":false}]}
{"op":"mcm","clk":"11539548444","pt":1719482956064,"mc":[{"id":"1.230180126","rc":[{"atb":[[2.2,3.16]],"id":49823335}],"con":true,"img":false}]}
{"op":"mcm","clk":"11539548475","pt":1719482956529,"mc":[{"id":"1.230180126","rc":[{"atb":[[2.22,3.16]],"id":62886137}],"con":true,"img":false}]}
{"op":"mcm","clk":"11539548482","pt":1719482956655,"mc":[{"id":"1.230180126","rc":[{"atb":[[2.16,3.16]],"id":64851267}],"con":true,"img":false}]}
{"op":"mcm","clk":"11539548602","pt":1719482958750,"mc":[{"id":"1.230180126","rc":[{"atb":[[2.24,3.16]],"id":61941224}],"con":true,"img":false}]}
{"op":"mcm","clk":"11539548683","pt":1719482960242,"mc":[{"id":"1.230180126","rc":[{"atb":[[2.24,3.38]],"id":49823335}],"con":true,"img":false}]}
{"op":"mcm","clk":"11539548703","pt":1719482960552,"mc":[{"id":"1.230180126","rc":[{"atb":[[2.26,3.38]],"id":62886137}],"con":true,"img":false}]}
{"op":"mcm","clk":"11539548730","pt":1719482960868,"mc":[{"id":"1.230180126","rc":[{"atb":[[2.22,3.38]],"id":66993945}],"con":true,"img":false}]}
{"op":"mcm","clk":"11539548789","pt":1719482961637,"mc":[{"id":"1.230180126","rc":[{"atb":[[2.2,3.38]],"id":64851267}],"con":true,"img":false}]}
{"op":"mcm","clk":"11539549019","pt":1719482965565,"mc":[{"id":"1.230180126","rc":[{"atb":[[2.28,3.38]],"id":61941224}],"con":true,"img":false}]}
{"op":"mcm","clk":"11539553341","pt":1719483028479,"mc":[{"id":"1.230180126","rc":[{"atb":[[2.18,0]],"id":66993945},{"spn":15.11,"spf":"NaN","id":66993945},{"atb":[[2.2,0]],"id":49823335},{"spn":76.12,"spf":"NaN","id":49823335},{"atb":[[2.16,0]],"id":64851267},{"spn":6.85,"spf":"NaN","id":64851267},{"atb":[[2.22,0]],"id":62886137},{"spn":76.13,"spf":"NaN","id":62886137},{"atb":[[2.24,0]],"id":61941224},{"spn":76.14,"spf":"NaN","id":61941224}],"con":true,"img":false}]}
{"op":"mcm","clk":"11539572950","pt":1719483322668,"mc":[{"id":"1.230180126","rc":[{"atb":[[2.2,6.54]],"id":64851267}],"con":true,"img":false}]}
{"op":"mcm","clk":"11539572979","pt":1719483323029,"mc":[{"id":"1.230180126","rc":[{"atb":[[2.24,6.54]],"id":49823335}],"con":true,"img":false}]}
{"op":"mcm","clk":"11539573043","pt":1719483323655,"mc":[{"id":"1.230180126","rc":[{"atb":[[2.26,6.54]],"id":62886137}],"con":true,"img":false}]}
{"op":"mcm","clk":"11539573058","pt":1719483323869,"mc":[{"id":"1.230180126","rc":[{"atb":[[2.28,6.54]],"id":61941224}],"con":true,"img":false}]}
{"op":"mcm","clk":"11539573309","pt":1719483326205,"mc":[{"id":"1.230180126","rc":[{"atb":[[2.22,6.54]],"id":66993945}],"con":true,"img":false}]}
{"op":"mcm","clk":"11539702136","pt":1719485057181,"mc":[{"id":"1.230180126","rc":[{"atl":[[42,12],[25,8]],"id":66993945},{"spn":13.61,"spf":"NaN","id":66993945},{"atl":[[36,8],[60,12]],"id":49823335},{"spn":19.12,"spf":"NaN","id":49823335},{"atl":[[36,12]],"id":64851267},{"atl":[[32,8],[55,12]],"id":62886137},{"spn":17.13,"spf":"NaN","id":62886137},{"atl":[[32,8],[55,12]],"id":61941224},{"spn":17.14,"spf":"NaN","id":61941224}],"con":true,"img":false}]}
{"op":"mcm","clk":"11539761395","pt":1719485809586,"mc":[{"id":"1.230180126","rc":[{"atb":[[2.58,6]],"id":66993945},{"spn":13.79,"spf":"NaN","id":66993945},{"atb":[[3.75,6]],"id":49823335},{"spn":19.87,"spf":"NaN","id":49823335},{"atb":[[2.58,6]],"id":64851267},{"spn":7.04,"spf":"NaN","id":64851267},{"atb":[[3.3,6]],"id":62886137},{"spn":17.65,"spf":"NaN","id":62886137},{"atb":[[4.2,6]],"id":61941224},{"spn":18.1,"spf":"NaN","id":61941224},{"atb":[[3,6]],"id":69475504}],"con":true,"img":false}]}
{"op":"mcm","clk":"11539762022","pt":1719485819626,"mc":[{"id":"1.230180126","rc":[{"atb":[[2.24,3.38]],"id":49823335},{"atb":[[2.26,3.38]],"id":62886137},{"atb":[[2.28,3.38]],"id":61941224}],"con":true,"img":false}]}
{"op":"mcm","clk":"11539762499","pt":1719485826103,"mc":[{"id":"1.230180126","rc":[{"atb":[[2.24,0]],"id":49823335},{"atb":[[2.26,0]],"id":62886137},{"atb":[[2.28,0]],"id":61941224}],"con":true,"img":false}]}
{"op":"mcm","clk":"11539812621","pt":1719486482663,"mc":[{"id":"1.230180126","marketDefinition":{"bspMarket":true,"turnInPlayEnabled":false,"persistenceEnabled":false,"marketBaseRate":5.0,"eventId":"33376437","eventTypeId":"4339","numberOfWinners":1,"bettingType":"ODDS","marketType":"WIN","marketTime":"2024-06-27T15:44:00.000Z","suspendTime":"2024-06-27T15:44:00.000Z","bspReconciled":false,"complete":true,"inPlay":false,"crossMatching":true,"runnersVoidable":false,"numberOfActiveRunners":6,"betDelay":0,"status":"OPEN","runners":[{"status":"ACTIVE","sortPriority":1,"id":62886137,"name":"1. Walk On Gaffer"},{"status":"ACTIVE","sortPriority":2,"id":49823335,"name":"2. Orange Sydney"},{"status":"ACTIVE","sortPriority":3,"id":66993945,"name":"3. Essjay Alfred"},{"status":"ACTIVE","sortPriority":4,"id":64851267,"name":"4. Pro Cooper"},{"status":"ACTIVE","sortPriority":5,"id":69475504,"name":"5. Golden Wind"},{"status":"ACTIVE","sortPriority":6,"id":61941224,"name":"6. Salacres Sydney"}],"regulators":["MR_INT"],"venue":"Towcester","countryCode":"GB","discountAllowed":true,"timezone":"Europe/London","openDate":"2024-06-27T13:33:00.000Z","version":5994767121,"name":"A3 500m","eventName":"Towcester 27th Jun"},"rc":[{"atb":[[1.01,51.83],[2.22,6.54],[2.58,6],[2.2,8.71]],"id":66993945},{"atl":[[150,4],[42,12],[25,8],[28,0.6],[1000,0.23]],"id":66993945},{"spn":13.79,"spf":"NaN","id":66993945},{"atb":[[1.03,17.28],[2.22,12.31],[3.75,6]],"id":49823335},{"atl":[[36,8],[150,4],[60,12],[990,0.23]],"id":49823335},{"spn":19.87,"spf":"NaN","id":49823335},{"atb":[[1.03,17.28],[2.18,12.08],[2.58,6],[2.2,6.54]],"id":64851267},{"atl":[[36,12],[150,4],[21,4],[11.5,2],[990,0.23],[15.5,3]],"id":64851267},{"spn":7.04,"spf":"NaN","id":64851267},{"atb":[[2.24,13.32],[1.03,17.28],[3.3,6]],"id":62886137},{"atl":[[32,8],[150,4],[55,12],[1000,0.23]],"id":62886137},{"spn":17.65,"spf":"NaN","id":62886137},{"atb":[[1.02,25.91],[2.26,11.65],[4.2,6]],"id":61941224},{"atl":[[32,8],[150,4],[55,12],[990,0.23]],"id":61941224},{"spn":18.1,"spf":"NaN","id":61941224},{"atb":[[1.02,25.91],[6,4],[3,6],[4.2,15.62],[2.08,8.88]],"id":69475504},{"atl":[[150,4],[990,0.23]],"id":69475504},{"spn":78.0,"spf":"NaN","id":69475504}],"con":true,"img":true}]}
{"op":"mcm","clk":"11539817397","pt":1719486507027,"mc":[{"id":"1.230180126","rc":[{"atb":[[1.01,51.83],[2.22,6.54],[2.2,0]],"id":66993945},{"atb":[[1.03,17.28],[2.22,12.31]],"id":49823335},{"atb":[[1.03,17.28],[2.18,0],[2.2,6.54]],"id":64851267},{"atb":[[2.24,13.32],[1.03,17.28]],"id":62886137},{"atb":[[1.02,25.91],[2.26,11.65]],"id":61941224},{"atb":[[1.02,25.91],[2.08,8.88]],"id":69475504}],"con":true,"img":false}]}
{"op":"mcm","clk":"11539817414","pt":1719486507135,"mc":[{"id":"1.230180126","rc":[{"atb":[[2.24,8.71]],"id":66993945},{"atb":[[2.22,12.08]],"id":64851267}],"con":true,"img":false}]}
{"op":"mcm","clk":"11539818786","pt":1719486522155,"mc":[{"id":"1.230180126","rc":[{"atb":[[2.22,3.38]],"id":66993945},{"atb":[[2.2,3.38]],"id":64851267}],"con":true,"img":false}]}
{"op":"mcm","clk":"11539818823","pt":1719486522570,"mc":[{"id":"1.230180126","rc":[{"atb":[[2.24,3.16]],"id":64851267}],"con":true,"img":false}]}
{"op":"mcm","clk":"11539818840","pt":1719486522775,"mc":[{"id":"1.230180126","rc":[{"atb":[[2.26,3.16]],"id":66993945}],"con":true,"img":false}]}
{"op":"mcm","clk":"11539824975","pt":1719486594462,"mc":[{"id":"1.230180126","rc":[{"atb":[[2.22,0]],"id":66993945}],"con":true,"img":false}]}
{"op":"mcm","clk":"11539824996","pt":1719486594775,"mc":[{"id":"1.230180126","rc":[{"atb":[[2.2,0]],"id":64851267}],"con":true,"img":false}]}
{"op":"mcm","clk":"11539825724","pt":1719486604372,"mc":[{"id":"1.230180126","rc":[{"atb":[[2.24,6.54]],"id":64851267}],"con":true,"img":false}]}
{"op":"mcm","clk":"11539825778","pt":1719486605046,"mc":[{"id":"1.230180126","rc":[{"atb":[[2.26,6.54]],"id":66993945}],"con":true,"img":false}]}
{"op":"mcm","clk":"11539840658","pt":1719486807006,"mc":[{"id":"1.230180126","rc":[{"atb":[[2.24,0]],"id":66993945},{"atb":[[2.22,0]],"id":64851267}],"con":true,"img":false}]}
{"op":"mcm","clk":"11539840665","pt":1719486807110,"mc":[{"id":"1.230180126","rc":[{"atb":[[2.28,8.71]],"id":66993945},{"atb":[[2.26,12.08]],"id":64851267}],"con":true,"img":false}]}
{"op":"mcm","clk":"11539841499","pt":1719486820839,"mc":[{"id":"1.230180126","rc":[{"atb":[[2.26,3.38]],"id":66993945},{"atb":[[2.24,3.38]],"id":64851267}],"con":true,"img":false}]}
{"op":"mcm","clk":"11539843073","pt":1719486844770,"mc":[{"id":"1.230180126","rc":[{"atb":[[2.26,0]],"id":66993945},{"atb":[[2.24,0]],"id":64851267}],"con":true,"img":false}]}
{"op":"mcm","clk":"11539848778","pt":1719486925071,"mc":[{"id":"1.230180126","rc":[{"atb":[[2.3,3.38]],"id":66993945},{"atb":[[2.28,3.38]],"id":64851267}],"con":true,"img":false}]}
{"op":"mcm","clk":"11539850232","pt":1719486943901,"mc":[{"id":"1.230180126","rc":[{"atb":[[2.28,6.54]],"id":64851267}],"con":true,"img":false}]}
{"op":"mcm","clk":"11539850239","pt":1719486944007,"mc":[{"id":"1.230180126","rc":[{"atb":[[2.3,6.54]],"id":66993945}],"con":true,"img":false}]}
{"op":"mcm","clk":"11539981946","pt":1719488642050,"mc":[{"id":"1.230180126","rc":[{"atb":[[3.9,1]],"id":66993945},{"spn":14.45,"spf":"NaN","id":66993945},{"atb":[[5,1]],"id":49823335},{"spn":20.5,"spf":"NaN","id":49823335},{"atb":[[3.9,1]],"id":64851267},{"spn":7.7,"spf":"NaN","id":64851267},{"atb":[[5,1]],"id":62886137},{"spn":18.5,"spf":"NaN","id":62886137},{"atb":[[5,1]],"id":61941224},{"spn":18.5,"spf":"NaN","id":61941224},{"atb":[[4.7,1]],"id":69475504}],"con":true,"img":false}]}
{"op":"mcm","clk":"11539983429","pt":1719488659328,"mc":[{"id":"1.230180126","rc":[{"atb":[[1.51,196.08]],"id":49823335},{"atb":[[1.51,196.08]],"id":62886137},{"atb":[[1.51,196.08]],"id":61941224},{"atb":[[2.12,89.29],[1.51,196.08]],"id":69475504}],"con":true,"img":false}]}
{"op":"mcm","clk":"11540014441","pt":1719488999968,"mc":[{"id":"1.230180126","rc":[{"atl":[[550,2]],"id":66993945},{"atb":[[1.16,150]],"id":49823335},{"atl":[[390,2]],"id":49823335},{"atl":[[270,2]],"id":64851267},{"atb":[[1.16,150]],"id":62886137},{"atl":[[370,2]],"id":62886137},{"atl":[[500,2]],"id":61941224},{"atl":[[560,2]],"id":69475504}],"con":true,"img":false}]}
{"op":"mcm","clk":"11540014452","pt":1719489000070,"mc":[{"id":"1.230180126","rc":[{"atb":[[1.16,150]],"id":66993945},{"atb":[[1.16,150]],"id":64851267},{"atb":[[1.16,150]],"id":61941224},{"atb":[[1.16,150]],"id":69475504}],"con":true,"img":false}]}
{"op":"mcm","clk":"11540064216","pt":1719489616697,"mc":[{"id":"1.230180126","rc":[{"atb":[[2.3,6.54]],"id":66993945},{"atb":[[2.12,89.29]],"id":49823335},{"atb":[[2.28,6.54]],"id":64851267},{"atb":[[2.12,89.29]],"id":62886137}],"con":true,"img":false}]}
{"op":"mcm","clk":"11540064227","pt":1719489616803,"mc":[{"id":"1.230180126","rc":[{"atb":[[1.51,196.08]],"id":66993945},{"atb":[[1.51,196.08]],"id":64851267},{"atb":[[2.12,89.29]],"id":61941224}],"con":true,"img":false}]}
{"op":"mcm","clk":"11540136488","pt":1719490402084,"mc":[{"id":"1.230180126","rc":[{"atb":[[2.28,0]],"id":66993945},{"atb":[[2.26,0]],"id":64851267},{"atb":[[2.08,0]],"id":69475504}],"con":true,"img":false}]}
{"op":"mcm","clk":"11540136499","pt":1719490402186,"mc":[{"id":"1.230180126","rc":[{"atb":[[2.32,8.71]],"id":66993945},{"atb":[[2.3,12.08]],"id":64851267},{"atb":[[2.14,8.88]],"id":69475504}],"con":true,"img":false}]}
{"op":"mcm","clk":"11540140993","pt":1719490446724,"mc":[{"id":"1.230180126","rc":[{"atb":[[2.3,3.16]],"id":66993945}],"con":true,"img":false}]}
{"op":"mcm","clk":"11540141055","pt":1719490447292,"mc":[{"id":"1.230180126","rc":[{"atb":[[2.28,3.16]],"id":64851267}],"con":true,"img":false}]}
{"op":"mcm","clk":"11540141604","pt":1719490452329,"mc":[{"id":"1.230180126","rc":[{"atb":[[2.34,3.38]],"id":66993945}],"con":true,"img":false}]}
{"op":"mcm","clk":"11540141664","pt":1719490452906,"mc":[{"id":"1.230180126","rc":[{"atb":[[2.32,3.38]],"id":64851267}],"con":true,"img":false}]}
{"op":"mcm","clk":"11540143754","pt":1719490473223,"mc":[{"id":"1.230180126","rc":[{"atb":[[2.28,0]],"id":64851267}],"con":true,"img":false}]}
{"op":"mcm","clk":"11540144194","pt":1719490477435,"mc":[{"id":"1.230180126","rc":[{"atb":[[2.3,0]],"id":66993945}],"con":true,"img":false}]}
{"op":"mcm","clk":"11540145725","pt":1719490491580,"mc":[{"id":"1.230180126","rc":[{"atb":[[2.34,6.54]],"id":66993945}],"con":true,"img":false}]}
{"op":"mcm","clk":"11540146051","pt":1719490494749,"mc":[{"id":"1.230180126","rc":[{"atb":[[2.32,6.54]],"id":64851267}],"con":true,"img":false}]}
{"op":"mcm","clk":"11540164823","pt":1719490699486,"mc":[{"id":"1.230180126","rc":[{"atb":[[2.32,0]],"id":66993945},{"atb":[[2.3,0]],"id":64851267}],"con":true,"img":false}]}
{"op":"mcm","clk":"11540164832","pt":1719490699585,"mc":[{"id":"1.230180126","rc":[{"atb":[[2.36,8.71]],"id":66993945},{"atb":[[2.34,12.08]],"id":64851267}],"con":true,"img":false}]}
{"op":"mcm","clk":"11540168581","pt":1719490746983,"mc":[{"id":"1.230180126","rc":[{"atb":[[2.34,3.38]],"id":66993945}],"con":true,"img":false}]}
{"op":"mcm","clk":"11540168605","pt":1719490747272,"mc":[{"id":"1.230180126","rc":[{"atb":[[2.32,3.38]],"id":64851267}],"con":true,"img":false}]}
{"op":"mcm","clk":"11540168619","pt":1719490747476,"mc":[{"id":"1.230180126","rc":[{"atb":[[2.38,3.16]],"id":66993945}],"con":true,"img":false}]}
{"op":"mcm","clk":"11540168633","pt":1719490747634,"mc":[{"id":"1.230180126","rc":[{"atb":[[2.36,3.16]],"id":64851267}],"con":true,"img":false}]}
{"op":"mcm","clk":"11540170904","pt":1719490780930,"mc":[{"id":"1.230180126","rc":[{"atb":[[2.32,0]],"id":64851267}],"con":true,"img":false}]}
{"op":"mcm","clk":"11540170917","pt":1719490781083,"mc":[{"id":"1.230180126","rc":[{"atb":[[2.34,0]],"id":66993945}],"con":true,"img":false}]}
{"op":"mcm","clk":"11540173125","pt":1719490810035,"mc":[{"id":"1.230180126","rc":[{"atb":[[2.36,6.54]],"id":64851267}],"con":true,"img":false}]}
{"op":"mcm","clk":"11540173215","pt":1719490811177,"mc":[{"id":"1.230180126","rc":[{"atb":[[2.38,6.54]],"id":66993945}],"con":true,"img":false}]}
{"op":"mcm","clk":"11540272197","pt":1719492244998,"mc":[{"id":"1.230180126","rc":[{"atl":[[34,18]],"id":64851267}],"con":true,"img":false}]}
{"op":"mcm","clk":"11540514963","pt":1719495383591,"mc":[{"id":"1.230180126","rc":[{"atb":[[2.36,8.72],[1.01,51.9],[2.38,6.54],[3,2]],"id":66993945},{"atl":[[1000,0.23]],"id":66993945},{"atb":[[1.03,17.3],[2.22,12.33]],"id":49823335},{"atl":[[990,0.23]],"id":49823335},{"atb":[[2.36,6.54],[1.03,17.3],[2.34,12.09]],"id":64851267},{"atl":[[990,0.23]],"id":64851267},{"atb":[[2.24,13.33],[1.03,17.3]],"id":62886137},{"atl":[[1000,0.23]],"id":62886137},{"atb":[[1.02,25.95],[2.26,11.67]],"id":61941224},{"atl":[[990,0.23]],"id":61941224},{"atb":[[1.02,25.95],[2.14,8.89]],"id":69475504},{"atl":[[990,0.23]],"id":69475504}],"con":true,"img":false}]}
{"op":"mcm","clk":"11540621351","pt":1719496545151,"mc":[{"id":"1.230180126","rc":[{"atb":[[1.03,124.5]],"id":66993945},{"atl":[[980,0.85]],"id":66993945},{"atb":[[1.04,77.07]],"id":49823335},{"atl":[[960,0.85]],"id":49823335},{"atb":[[1.02,69.45]],"id":64851267},{"atl":[[960,0.85]],"id":64851267},{"atb":[[1.03,132.48]],"id":62886137},{"atl":[[980,0.94]],"id":62886137},{"atb":[[1.04,100.78]],"id":61941224},{"atl":[[990,1.09]],"id":61941224},{"atb":[[1.02,156.38]],"id":69475504},{"atl":[[980,0.85]],"id":69475504}],"con":true,"img":false}]}
{"op":"mcm","clk":"11540685090","pt":1719497282627,"mc":[{"id":"1.230180126","marketDefinition":{"bspMarket":true,"turnInPlayEnabled":false,"persistenceEnabled":false,"marketBaseRate":5.0,"eventId":"33376437","eventTypeId":"4339","numberOfWinners":1,"bettingType":"ODDS","marketType":"WIN","marketTime":"2024-06-27T15:44:00.000Z","suspendTime":"2024-06-27T15:44:00.000Z","bspReconciled":false,"complete":true,"inPlay":false,"crossMatching":true,"runnersVoidable":false,"numberOfActiveRunners":6,"betDelay":0,"status":"OPEN","runners":[{"status":"ACTIVE","sortPriority":1,"id":62886137,"name":"1. Walk On Gaffer"},{"status":"ACTIVE","sortPriority":2,"id":49823335,"name":"2. Orange Sydney"},{"status":"ACTIVE","sortPriority":3,"id":66993945,"name":"3. Essjay Alfred"},{"status":"ACTIVE","sortPriority":4,"id":64851267,"name":"4. Pro Cooper"},{"status":"ACTIVE","sortPriority":5,"id":69475504,"name":"5. Golden Wind"},{"status":"ACTIVE","sortPriority":6,"id":61941224,"name":"6. Salacres Sydney"}],"regulators":["MR_INT"],"venue":"Towcester","countryCode":"GB","discountAllowed":true,"timezone":"Europe/London","openDate":"2024-06-27T13:33:00.000Z","version":5994767121,"name":"A3 500m","eventName":"Towcester 27th Jun"},"rc":[{"atb":[[2.36,8.71],[1.01,51.87],[1.16,150],[1.03,124.44],[2.38,6.54],[3,2],[2.58,6],[1.51,196.08],[3.9,1]],"id":66993945},{"atl":[[550,2],[150,4],[42,12],[25,8],[28,0.6],[980,0.85],[1000,0.23]],"id":66993945},{"spn":14.45,"spf":"NaN","id":66993945},{"atb":[[5,1],[1.16,150],[1.03,17.29],[2.22,12.32],[2.12,89.29],[1.51,196.08],[3.75,6],[1.04,77.04]],"id":49823335},{"atl":[[36,8],[150,4],[390,2],[60,12],[960,0.85],[990,0.23]],"id":49823335},{"spn":20.5,"spf":"NaN","id":49823335},{"atb":[[2.36,6.54],[1.16,150],[1.03,17.29],[1.02,69.42],[2.58,6],[1.51,196.08],[3.9,1],[2.34,12.08]],"id":64851267},{"atl":[[270,2],[34,18],[36,12],[150,4],[21,4],[11.5,2],[960,0.85],[990,0.23],[15.5,3]],"id":64851267},{"spn":7.7,"spf":"NaN","id":64851267},{"atb":[[2.24,13.33],[5,1],[1.16,150],[1.03,132.43],[2.12,89.29],[1.51,196.08],[3.3,6]],"id":62886137},{"atl":[[32,8],[150,4],[370,2],[55,12],[980,0.94],[1000,0.23]],"id":62886137},{"spn":18.5,"spf":"NaN","id":62886137},{"atb":[[5,1],[1.16,150],[1.02,25.93],[2.12,89.29],[2.26,11.66],[1.51,196.08],[4.2,6],[1.04,100.74]],"id":61941224},{"atl":[[32,8],[150,4],[55,12],[990,1.09],[500,2]],"id":61941224},{"spn":18.5,"spf":"NaN","id":61941224},{"atb":[[1.16,150],[1.02,156.31],[6,4],[3,6],[2.12,89.29],[1.51,196.08],[4.2,15.62],[2.14,8.88],[4.7,1]],"id":69475504},{"atl":[[560,2],[150,4],[980,0.85],[990,0.23]],"id":69475504},{"spn":78.0,"spf":"NaN","id":69475504}],"con":true,"img":true}]}
{"op":"mcm","clk":"11540722466","pt":1719497675423,"mc":[{"id":"1.230180126","rc":[{"atb":[[2.36,8.71],[1.01,51.87],[1.03,124.44],[2.38,6.54]],"id":66993945},{"atl":[[980,0.85],[1000,0.23]],"id":66993945},{"atb":[[1.03,17.29],[2.22,12.32],[1.04,77.04]],"id":49823335},{"atl":[[960,0.85],[990,0.23]],"id":49823335},{"spl":[[1.01,1]],"id":64851267},{"atb":[[2.36,6.54],[1.03,17.29],[1.02,69.42],[2.34,12.08]],"id":64851267},{"atl":[[960,0.85],[990,0.23]],"id":64851267},{"spn":3.9,"spf":1.0,"id":64851267},{"atb":[[2.24,13.33],[1.03,132.43]],"id":62886137},{"atl":[[980,0.94],[1000,0.23]],"id":62886137},{"atb":[[1.02,25.93],[2.26,11.66],[1.04,100.74]],"id":61941224},{"atl":[[990,1.09]],"id":61941224},{"atb":[[1.02,156.31],[2.14,8.88]],"id":69475504},{"atl":[[980,0.85],[990,0.23]],"id":69475504}],"con":true,"img":false}]}
{"op":"mcm","clk":"11540925620","pt":1719500049199,"mc":[{"id":"1.230180126","rc":[{"atb":[[3.1,1]],"id":66993945},{"atb":[[5.5,1]],"id":49823335},{"spn":20.75,"spf":"NaN","id":49823335},{"atb":[[3.1,1]],"id":64851267},{"atb":[[5.5,1]],"id":62886137},{"spn":18.75,"spf":"NaN","id":62886137},{"atb":[[7,1]],"id":61941224},{"spn":19.5,"spf":"NaN","id":61941224},{"atb":[[3.7,1]],"id":69475504}],"con":true,"img":false}]}
{"op":"mcm","clk":"11540991562","pt":1719500856543,"mc":[{"id":"1.230180126","rc":[{"atb":[[2.36,8.72],[1.01,51.88],[1.03,124.47],[2.38,6.54]],"id":66993945},{"atl":[[980,0.85]],"id":66993945},{"atb":[[1.03,17.29],[2.22,12.32],[1.04,77.05]],"id":49823335},{"atl":[[960,0.85]],"id":49823335},{"atb":[[2.36,6.54],[1.03,17.29],[1.02,69.43],[2.34,12.09]],"id":64851267},{"atl":[[960,0.85]],"id":64851267},{"atb":[[2.24,13.33],[1.03,132.45]],"id":62886137},{"atl":[[980,0.94]],"id":62886137},{"atb":[[1.02,25.94],[2.26,11.66],[1.04,100.76]],"id":61941224},{"atl":[[990,1.09],[30,1.54]],"id":61941224},{"spn":18.5,"spf":"NaN","id":61941224},{"atb":[[1.02,156.34],[2.14,8.89]],"id":69475504},{"atl":[[980,0.85]],"id":69475504}],"con":true,"img":false}]}
{"op":"mcm","clk":"11540991583","pt":1719500856851,"mc":[{"id":"1.230180126","rc":[{"atl":[[24,1.71]],"id":66993945}],"con":true,"img":false}]}
{"op":"mcm","clk":"11540991603","pt":1719500857162,"mc":[{"id":"1.230180126","rc":[{"atl":[[34,1.55]],"id":49823335}],"con":true,"img":false}]}
{"op":"mcm","clk":"11540991630","pt":1719500857421,"mc":[{"id":"1.230180126","rc":[{"atl":[[30,1.57]],"id":62886137}],"con":true,"img":false}]}
{"op":"mcm","clk":"11541029263","pt":1719501323320,"mc":[{"id":"1.230180126","rc":[{"spn":13.95,"spf":"NaN","id":66993945},{"spn":19.75,"spf":"NaN","id":49823335},{"atb":[[3.9,2]],"id":64851267},{"spn":17.75,"spf":"NaN","id":62886137}],"con":true,"img":false}]}
{"op":"mcm","clk":"11541047288","pt":1719501543773,"mc":[{"id":"1.230180126","rc":[{"atl":[[190,4]],"id":66993945},{"atl":[[190,4]],"id":49823335},{"atl":[[190,4]],"id":64851267},{"atl":[[190,4]],"id":62886137},{"atl":[[190,4]],"id":61941224},{"atl":[[190,4]],"id":69475504}],"con":true,"img":false}]}
{"op":"mcm","clk":"11541048496","pt":1719501558094,"mc":[{"id":"1.230180126","rc":[{"atb":[[1.02,2]],"id":62886137}],"con":true,"img":false}]}
{"op":"mcm","clk":"11541048527","pt":1719501558294,"mc":[{"id":"1.230180126","rc":[{"atb":[[1.02,2]],"id":49823335}],"con":true,"img":false}]}
{"op":"mcm","clk":"11541048545","pt":1719501558494,"mc":[{"id":"1.230180126","rc":[{"atb":[[1.02,2]],"id":66993945}],"con":true,"img":false}]}
{"op":"mcm","clk":"11541048571","pt":1719501558804,"mc":[{"id":"1.230180126","rc":[{"atb":[[1.02,71.43]],"id":64851267}],"con":true,"img":false}]}
{"op":"mcm","clk":"11541048622","pt":1719501559286,"mc":[{"id":"1.230180126","rc":[{"atb":[[1.02,158.34]],"id":69475504}],"con":true,"img":false}]}
{"op":"mcm","clk":"11541048648","pt":1719501559589,"mc":[{"id":"1.230180126","rc":[{"atb":[[1.02,27.94]],"id":61941224}],"con":true,"img":false}]}
{"op":"mcm","clk":"11541060119","pt":1719501694001,"mc":[{"id":"1.230180126","rc":[{"atb":[[3.9,0]],"id":64851267},{"atl":[[3.9,1]],"id":64851267},{"trd":[[3.9,4]],"ltp":3.9,"tv":4.0,"id":64851267},{"spn":3.1,"spf":1.0,"id":64851267}],"con":true,"img":false}]}
{"op":"mcm","clk":"11541060240","pt":1719501695789,"mc":[{"id":"1.230180126","rc":[{"atb":[[3.65,1]],"id":64851267}],"con":true,"img":false}]}
{"op":"mcm","clk":"11541060390","pt":1719501697720,"mc":[{"id":"1.230180126","rc":[{"atl":[[3.9,0]],"id":64851267}],"con":true,"img":false}]}
{"op":"mcm","clk":"11541061363","pt":1719501710327,"mc":[{"id":"1.230180126","rc":[{"atb":[[3.65,0]],"id":64851267},{"trd":[[3.65,2]],"ltp":3.65,"tv":2.0,"id":64851267}],"con":true,"img":false}]}
{"op":"mcm","clk":"11541061400","pt":1719501710903,"mc":[{"id":"1.230180126","rc":[{"atb":[[3.4,1]],"id":64851267}],"con":true,"img":false}]}
{"op":"mcm","clk":"11541062008","pt":1719501717839,"mc":[{"id":"1.230180126","rc":[{"atb":[[2.24,9.56]],"id":49823335}],"con":true,"img":false}]}
{"op":"mcm","clk":"11541062018","pt":1719501717939,"mc":[{"id":"1.230180126","rc":[{"atb":[[3.35,5.04]],"id":62886137}],"con":true,"img":false}]}
{"op":"mcm","clk":"11541062029","pt":1719501718043,"mc":[{"id":"1.230180126","rc":[{"atb":[[2.6,7.41]],"id":64851267}],"con":true,"img":false}]}
{"op":"mcm","clk":"11541062039","pt":1719501718093,"mc":[{"id":"1.230180126","rc":[{"atb":[[3.05,5.78]],"id":69475504}],"con":true,"img":false}]}
{"op":"mcm","clk":"11541062044","pt":1719501718195,"mc":[{"id":"1.230180126","rc":[{"atb":[[2.28,9.26]],"id":61941224}],"con":true,"img":false}]}
{"op":"mcm","clk":"11541062052","pt":1719501718300,"mc":[{"id":"1.230180126","rc":[{"atb":[[2.6,7.41]],"id":66993945}],"con":true,"img":false}]}
{"op":"mcm","clk":"11541062062","pt":1719501718400,"mc":[{"id":"1.230180126","rc":[{"atb":[[2.32,2.09]],"id":49823335}],"con":true,"img":false}]}
{"op":"mcm","clk":"11541062865","pt":1719501728008,"mc":[{"id":"1.230180126","rc":[{"atb":[[2.38,3.16]],"id":66993945}],"con":true,"img":false}]}
{"op":"mcm","clk":"11541062876","pt":1719501728212,"mc":[{"id":"1.230180126","rc":[{"atb":[[2.36,3.16]],"id":64851267}],"con":true,"img":false}]}
{"op":"mcm","clk":"11541062943","pt":1719501728828,"mc":[{"id":"1.230180126","rc":[{"atb":[[2.62,3.38]],"id":64851267}],"con":true,"img":false}]}
{"op":"mcm","clk":"11541062951","pt":1719501728934,"mc":[{"id":"1.230180126","rc":[{"atb":[[2.62,3.38]],"id":66993945}],"con":true,"img":false}]}
{"op":"mcm","clk":"11541064024","pt":1719501741421,"mc":[{"id":"1.230180126","rc":[{"atb":[[2.62,11.22]],"id":66993945}],"con":true,"img":false}]}
{"op":"mcm","clk":"11541064050","pt":1719501741737,"mc":[{"id":"1.230180126","rc":[{"atb":[[3.1,6.04]],"id":69475504}],"con":true,"img":false}]}
{"op":"mcm","clk":"11541064061","pt":1719501741834,"mc":[{"id":"1.230180126","rc":[{"atb":[[2.26,10.07]],"id":49823335}],"con":true,"img":false}]}
{"op":"mcm","clk":"11541064081","pt":1719501742039,"mc":[{"id":"1.230180126","rc":[{"atb":[[3.4,5.29]],"id":62886137}],"con":true,"img":false}]}
{"op":"mcm","clk":"11541064091","pt":1719501742142,"mc":[{"id":"1.230180126","rc":[{"atb":[[2.62,11.22]],"id":64851267}],"con":true,"img":false}]}
{"op":"mcm","clk":"11541064116","pt":1719501742452,"mc":[{"id":"1.230180126","rc":[{"atb":[[2.3,9.77]],"id":61941224}],"con":true,"img":false}]}
{"op":"mcm","clk":"11541065008","pt":1719501753753,"mc":[{"id":"1.230180126","rc":[{"atb":[[2.36,0]],"id":64851267}],"con":true,"img":false}]}
{"op":"mcm","clk":"11541065039","pt":1719501754166,"mc":[{"id":"1.230180126","rc":[{"atb":[[2.38,0]],"id":66993945},{"spn":3.4,"spf":1.0,"id":64851267}],"con":true,"img":false}]}
{"op":"mcm","clk":"11541065058","pt":1719501754371,"mc":[{"id":"1.230180126","rc":[{"atb":[[2.64,3.16]],"id":64851267}],"con":true,"img":false}]}
{"op":"mcm","clk":"11541065083","pt":1719501754573,"mc":[{"id":"1.230180126","rc":[{"atb":[[2.64,3.16]],"id":66993945}],"con":true,"img":false}]}
{"op":"mcm","clk":"11541066087","pt":1719501767553,"mc":[{"id":"1.230180126","rc":[{"atb":[[2.6,0]],"id":66993945}],"con":true,"img":false}]}
{"op":"mcm","clk":"11541066616","pt":1719501774071,"mc":[{"id":"1.230180126","rc":[{"atb":[[2.64,10.39]],"id":66993945}],"con":true,"img":false}]}
{"op":"mcm","clk":"11541066640","pt":1719501774378,"mc":[{"id":"1.230180126","rc":[{"atb":[[2.24,0]],"id":49823335},{"atb":[[2.28,0]],"id":61941224},{"atb":[[3.05,0]],"id":69475504}],"con":true,"img":false}]}
{"op":"mcm","clk":"11541067844","pt":1719501789507,"mc":[{"id":"1.230180126","rc":[{"atb":[[2.22,0]],"id":49823335},{"atb":[[2.26,0]],"id":61941224}],"con":true,"img":false}]}
{"op":"mcm","clk":"11541067852","pt":1719501789565,"mc":[{"id":"1.230180126","rc":[{"atb":[[2.28,12.32]],"id":49823335},{"atb":[[2.32,11.66]],"id":61941224}],"con":true,"img":false}]}
{"op":"mcm","clk":"11541067899","pt":1719501790187,"mc":[{"id":"1.230180126","rc":[{"atb":[[3.15,5.51]],"id":69475504}],"con":true,"img":false}]}
{"op":"mcm","clk":"11541068375","pt":1719501795583,"mc":[{"id":"1.230180126","rc":[{"atb":[[2.62,7.84]],"id":66993945}],"con":true,"img":false}]}
{"op":"mcm","clk":"11541068433","pt":1719501796299,"mc":[{"id":"1.230180126","rc":[{"atb":[[2.66,3.38]],"id":66993945}],"con":true,"img":false}]}
{"op":"mcm","clk":"11541069527","pt":1719501809025,"mc":[{"id":"1.230180126","rc":[{"atb":[[2.3,9.12]],"id":49823335}],"con":true,"img":false}]}
{"op":"mcm","clk":"11541069534","pt":1719501809126,"mc":[{"id":"1.230180126","rc":[{"atb":[[2.34,8.84]],"id":61941224}],"con":true,"img":false}]}
{"op":"mcm","clk":"11541070355","pt":1719501819129,"mc":[{"id":"1.230180126","rc":[{"atb":[[2.62,0]],"id":66993945},{"atb":[[2.26,0]],"id":49823335},{"atb":[[2.3,0]],"id":61941224},{"atb":[[3.1,0]],"id":69475504}],"con":true,"img":false}]}
{"op":"mcm","clk":"11541070618","pt":1719501822332,"mc":[{"id":"1.230180126","rc":[{"atb":[[2.64,7.23]],"id":66993945}],"con":true,"img":false}]}
{"op":"mcm","clk":"11541071453","pt":1719501832735,"mc":[{"id":"1.230180126","rc":[{"atb":[[2.66,11.04]],"id":66993945}],"con":true,"img":false}]}
{"op":"mcm","clk":"11541071479","pt":1719501833042,"mc":[{"id":"1.230180126","rc":[{"atb":[[3.2,5.77]],"id":69475504}],"con":true,"img":false}]}
{"op":"mcm","clk":"11541072058","pt":1719501839632,"mc":[{"id":"1.230180126","rc":[{"atb":[[2.64,0]],"id":66993945}],"con":true,"img":false}]}
{"op":"mcm","clk":"11541072362","pt":1719501843149,"mc":[{"id":"1.230180126","rc":[{"atb":[[3.15,0]],"id":69475504}],"con":true,"img":false}]}
{"op":"mcm","clk":"11541072499","pt":1719501844851,"mc":[{"id":"1.230180126","rc":[{"atb":[[2.68,7.05]],"id":66993945},{"atl":[[1000,0.1]],"id":64851267}],"con":true,"img":false}]}
{"op":"mcm","clk":"11541072506","pt":1719501844954,"mc":[{"id":"1.230180126","rc":[{"atl":[[1000,0]],"id":64851267}],"con":true,"img":false}]}
{"op":"mcm","clk":"11541072513","pt":1719501845059,"mc":[{"id":"1.230180126","rc":[{"atl":[[11,0.1]],"id":64851267}],"con":true,"img":false}]}
{"op":"mcm","clk":"11541073784","pt":1719501860182,"mc":[{"id":"1.230180126","rc":[{"atl":[[11,0]],"id":64851267}],"con":true,"img":false}]}
{"op":"mcm","clk":"11541073873","pt":1719501861062,"mc":[{"id":"1.230180126","rc":[{"atl":[[1000,0.1]],"id":64851267}],"con":true,"img":false}]}
{"op":"mcm","clk":"11541073887","pt":1719501861273,"mc":[{"id":"1.230180126","rc":[{"atl":[[1000,0]],"id":64851267}],"con":true,"img":false}]}
{"op":"mcm","clk":"11541073899","pt":1719501861371,"mc":[{"id":"1.230180126","rc":[{"atl":[[11,0.1]],"id":64851267}],"con":true,"img":false}]}
{"op":"mcm","clk":"11541074164","pt":1719501864072,"mc":[{"id":"1.230180126","rc":[{"atb":[[2.68,10.22]],"id":66993945},{"atb":[[3.25,5.27]],"id":69475504}],"con":true,"img":false}]}
{"op":"mcm","clk":"11541074236","pt":1719501864894,"mc":[{"id":"1.230180126","rc":[{"atb":[[2.32,11.71]],"id":49823335}],"con":true,"img":false}]}
{"op":"mcm","clk":"11541074254","pt":1719501865050,"mc":[{"id":"1.230180126","rc":[{"atb":[[2.36,9.33]],"id":61941224}],"con":true,"img":false}]}
{"op":"mcm","clk":"11541074297","pt":1719501865576,"mc":[{"id":"1.230180126","rc":[{"atb":[[2.66,7.65]],"id":66993945}],"con":true,"img":false}]}
{"op":"mcm","clk":"11541074328","pt":1719501865879,"mc":[{"id":"1.230180126","rc":[{"atb":[[2.7,3.38]],"id":66993945}],"con":true,"img":false}]}
{"op":"mcm","clk":"11541075262","pt":1719501876593,"mc":[{"id":"1.230180126","rc":[{"atl":[[11,0]],"id":64851267}],"con":true,"img":false}]}
{"op":"mcm","clk":"11541075384","pt":1719501877998,"mc":[{"id":"1.230180126","rc":[{"atl":[[1000,0.1]],"id":64851267}],"con":true,"img":false}]}
{"op":"mcm","clk":"11541075407","pt":1719501878311,"mc":[{"id":"1.230180126","rc":[{"atl":[[1000,0]],"id":64851267}],"con":true,"img":false}]}
{"op":"mcm","clk":"11541075412","pt":1719501878386,"mc":[{"id":"1.230180126","rc":[{"atl":[[11,0.1]],"id":64851267}],"con":true,"img":false}]}
{"op":"mcm","clk":"11541076601","pt":1719501893604,"mc":[{"id":"1.230180126","rc":[{"atl":[[11,0]],"id":64851267}],"con":true,"img":false}]}
{"op":"mcm","clk":"11541076707","pt":1719501894989,"mc":[{"id":"1.230180126","rc":[{"atl":[[1000,0.1]],"id":64851267}],"con":true,"img":false}]}
{"op":"mcm","clk":"11541076714","pt":1719501895091,"mc":[{"id":"1.230180126","rc":[{"atl":[[1000,0]],"id":64851267}],"con":true,"img":false}]}
{"op":"mcm","clk":"11541076722","pt":1719501895193,"mc":[{"id":"1.230180126","rc":[{"atl":[[11,0.1]],"id":64851267}],"con":true,"img":false}]}
{"op":"mcm","clk":"11541078074","pt":1719501910423,"mc":[{"id":"1.230180126","rc":[{"atl":[[11,0]],"id":64851267}],"con":true,"img":false}]}
{"op":"mcm","clk":"11541078090","pt":1719501910625,"mc":[{"id":"1.230180126","rc":[{"atl":[[1000,0.1]],"id":64851267}],"con":true,"img":false}]}
{"op":"mcm","clk":"11541078107","pt":1719501910832,"mc":[{"id":"1.230180126","rc":[{"atl":[[1000,0]],"id":64851267}],"con":true,"img":false}]}
{"op":"mcm","clk":"11541078114","pt":1719501910934,"mc":[{"id":"1.230180126","rc":[{"atl":[[11,0.1]],"id":64851267}],"con":true,"img":false}]}
{"op":"mcm","clk":"11541078190","pt":1719501911920,"mc":[{"id":"1.230180126","rc":[{"atb":[[2.68,3.16]],"id":66993945},{"atb":[[2.3,0]],"id":49823335},{"atb":[[2.34,0]],"id":61941224}],"con":true,"img":false}]}
{"op":"mcm","clk":"11541078644","pt":1719501917315,"mc":[{"id":"1.230180126","rc":[{"atb":[[2.72,6.89]],"id":66993945}],"con":true,"img":false}]}
{"op":"mcm","clk":"11541078665","pt":1719501917524,"mc":[{"id":"1.230180126","rc":[{"atb":[[2.34,8.84]],"id":49823335},{"atb":[[2.38,8.59]],"id":61941224}],"con":true,"img":false}]}
{"op":"mcm","clk":"11541078797","pt":1719501918918,"mc":[{"id":"1.230180126","rc":[{"atb":[[2.66,0]],"id":66993945},{"atb":[[3.2,0]],"id":69475504}],"con":true,"img":false}]}
{"op":"mcm","clk":"11541079470","pt":1719501926158,"mc":[{"id":"1.230180126","rc":[{"atl":[[11,0]],"id":64851267}],"con":true,"img":false}]}
{"op":"mcm","clk":"11541079497","pt":1719501926573,"mc":[{"id":"1.230180126","rc":[{"atl":[[1000,0.1]],"id":64851267}],"con":true,"img":false}]}
{"op":"mcm","clk":"11541079507","pt":1719501926739,"mc":[{"id":"1.230180126","rc":[{"atl":[[1000,0]],"id":64851267}],"con":true,"img":false}]}
{"op":"mcm","clk":"11541079515","pt":1719501926835,"mc":[{"id":"1.230180126","rc":[{"atl":[[11,0.1]],"id":64851267}],"con":true,"img":false}]}
{"op":"mcm","clk":"11541079818","pt":1719501930261,"mc":[{"id":"1.230180126","rc":[{"atb":[[3.3,5.52]],"id":69475504}],"con":true,"img":false}]}
{"op":"mcm","clk":"11541079840","pt":1719501930576,"mc":[{"id":"1.230180126","rc":[{"atb":[[2.7,0]],"id":66993945}],"con":true,"img":false}]}
{"op":"mcm","clk":"11541079895","pt":1719501931150,"mc":[{"id":"1.230180126","rc":[{"atb":[[2.74,3.38]],"id":66993945}],"con":true,"img":false}]}
{"op":"mcm","clk":"11541080246","pt":1719501934892,"mc":[{"id":"1.230180126","rc":[{"atb":[[2.68,0]],"id":66993945}],"con":true,"img":false}]}
{"op":"mcm","clk":"11541081022","pt":1719501942074,"mc":[{"id":"1.230180126","rc":[{"atl":[[11,0]],"id":64851267}],"con":true,"img":false}]}
{"op":"mcm","clk":"11541081079","pt":1719501942749,"mc":[{"id":"1.230180126","rc":[{"atl":[[1000,0.1]],"id":64851267}],"con":true,"img":false}]}
{"op":"mcm","clk":"11541081099","pt":1719501942957,"mc":[{"id":"1.230180126","rc":[{"atl":[[1000,0]],"id":64851267}],"con":true,"img":false}]}
{"op":"mcm","clk":"11541081106","pt":1719501943059,"mc":[{"id":"1.230180126","rc":[{"atl":[[11,0.1]],"id":64851267}],"con":true,"img":false}]}
{"op":"mcm","clk":"11541081396","pt":1719501946482,"mc":[{"id":"1.230180126","rc":[{"atb":[[2.74,10.68]],"id":66993945}],"con":true,"img":false}]}
{"op":"mcm","clk":"11541082451","pt":1719501958210,"mc":[{"id":"1.230180126","rc":[{"atl":[[11,0]],"id":64851267}],"con":true,"img":false}]}
{"op":"mcm","clk":"11541082554","pt":1719501959293,"mc":[{"id":"1.230180126","rc":[{"atl":[[1000,0.1]],"id":64851267}],"con":true,"img":false}]}
{"op":"mcm","clk":"11541082572","pt":1719501959500,"mc":[{"id":"1.230180126","rc":[{"atl":[[1000,0]],"id":64851267}],"con":true,"img":false}]}
{"op":"mcm","clk":"11541082579","pt":1719501959606,"mc":[{"id":"1.230180126","rc":[{"atl":[[11,0.1]],"id":64851267}],"con":true,"img":false}]}
{"op":"mcm","clk":"11541083173","pt":1719501965784,"mc":[{"id":"1.230180126","rc":[{"atb":[[2.72,0]],"id":66993945},{"atb":[[3.25,0]],"id":69475504}],"con":true,"img":false}]}
{"op":"mcm","clk":"11541083409","pt":1719501968319,"mc":[{"id":"1.230180126","rc":[{"atb":[[2.32,2.09]],"id":49823335},{"atb":[[2.36,0]],"id":61941224}],"con":true,"img":false}]}
{"op":"mcm","clk":"11541083769","pt":1719501972305,"mc":[{"id":"1.230180126","rc":[{"atb":[[2.76,3.16]],"id":66993945}],"con":true,"img":false}]}
{"op":"mcm","clk":"11541083805","pt":1719501972717,"mc":[{"id":"1.230180126","rc":[{"atb":[[3.35,5.04]],"id":69475504}],"con":true,"img":false}]}
{"op":"mcm","clk":"11541083814","pt":1719501972818,"mc":[{"id":"1.230180126","rc":[{"atb":[[2.76,9.89]],"id":66993945}],"con":true,"img":false}]}
{"op":"mcm","clk":"11541083978","pt":1719501974780,"mc":[{"id":"1.230180126","rc":[{"atl":[[11,0]],"id":64851267}],"con":true,"img":false}]}
{"op":"mcm","clk":"11541084051","pt":1719501975817,"mc":[{"id":"1.230180126","rc":[{"atl":[[1000,0.1]],"id":64851267}],"con":true,"img":false}]}
{"op":"mcm","clk":"11541084066","pt":1719501976024,"mc":[{"id":"1.230180126","rc":[{"atl":[[1000,0]],"id":64851267}],"con":true,"img":false}]}
{"op":"mcm","clk":"11541084074","pt":1719501976128,"mc":[{"id":"1.230180126","rc":[{"atl":[[11,0.1]],"id":64851267}],"con":true,"img":false}]}
{"op":"mcm","clk":"11541084137","pt":1719501977116,"mc":[{"id":"1.230180126","rc":[{"atl":[[32,0.84]],"id":49823335},{"atl":[[29,0.84]],"id":62886137}],"con":true,"img":false}]}
{"op":"mcm","clk":"11541084142","pt":1719501977225,"mc":[{"id":"1.230180126","rc":[{"atl":[[23,0.84]],"id":66993945},{"atl":[[11,0.94]],"id":64851267},{"atl":[[29,0.84]],"id":61941224}],"con":true,"img":false}]}
{"op":"mcm","clk":"11541085261","pt":1719501991326,"mc":[{"id":"1.230180126","rc":[{"atl":[[11,0.84]],"id":64851267}],"con":true,"img":false}]}
{"op":"mcm","clk":"11541085279","pt":1719501991531,"mc":[{"id":"1.230180126","rc":[{"atl":[[1000,0.1]],"id":64851267}],"con":true,"img":false}]}
{"op":"mcm","clk":"11541085296","pt":1719501991737,"mc":[{"id":"1.230180126","rc":[{"atl":[[1000,0]],"id":64851267}],"con":true,"img":false}]}
{"op":"mcm","clk":"11541085305","pt":1719501991840,"mc":[{"id":"1.230180126","rc":[{"atl":[[11,0.94]],"id":64851267}],"con":true,"img":false}]}
{"op":"mcm","clk":"11541085560","pt":1719501995361,"mc":[{"id":"1.230180126","rc":[{"atb":[[2.36,9.33]],"id":49823335}],"con":true,"img":false}]}
{"op":"mcm","clk":"11541085578","pt":1719501995511,"mc":[{"id":"1.230180126","rc":[{"atb":[[2.74,7.29]],"id":66993945}],"con":true,"img":false}]}
{"op":"mcm","clk":"11541085584","pt":1719501995620,"mc":[{"id":"1.230180126","rc":[{"atb":[[2.4,9.06]],"id":61941224}],"con":true,"img":false}]}
{"op":"mcm","clk":"11541085619","pt":1719501995925,"mc":[{"id":"1.230180126","rc":[{"atb":[[2.78,3.38]],"id":66993945}],"con":true,"img":false}]}
{"op":"mcm","clk":"11541086141","pt":1719502002739,"mc":[{"id":"1.230180126","rc":[{"atb":[[2.34,0]],"id":49823335},{"atb":[[2.38,0]],"id":61941224}],"con":true,"img":false}]}
{"op":"mcm","clk":"11541086449","pt":1719502007031,"mc":[{"id":"1.230180126","rc":[{"atl":[[11,0.84]],"id":64851267}],"con":true,"img":false}]}
{"op":"mcm","clk":"11541086495","pt":1719502007656,"mc":[{"id":"1.230180126","rc":[{"atl":[[1000,0.1]],"id":64851267}],"con":true,"img":false}]}
{"op":"mcm","clk":"11541086510","pt":1719502007863,"mc":[{"id":"1.230180126","rc":[{"atl":[[1000,0]],"id":64851267}],"con":true,"img":false}]}
{"op":"mcm","clk":"11541086520","pt":1719502007963,"mc":[{"id":"1.230180126","rc":[{"atl":[[11,0.94]],"id":64851267}],"con":true,"img":false}]}
{"op":"mcm","clk":"11541087188","pt":1719502016571,"mc":[{"id":"1.230180126","rc":[{"atb":[[2.74,0]],"id":66993945},{"atb":[[3.3,0]],"id":69475504}],"con":true,"img":false}]}
{"op":"mcm","clk":"11541087653","pt":1719502023090,"mc":[{"id":"1.230180126","rc":[{"spn":13.45,"spf":"NaN","id":66993945},{"spn":18.75,"spf":"NaN","id":49823335},{"atl":[[11,0.84]],"id":64851267},{"spn":17.25,"spf":"NaN","id":62886137},{"spn":18.0,"spf":"NaN","id":61941224}],"con":true,"img":false}]}
{"op":"mcm","clk":"11541087725","pt":1719502024172,"mc":[{"id":"1.230180126","rc":[{"atl":[[1000,0.1]],"id":64851267}],"con":true,"img":false}]}
{"op":"mcm","clk":"11541087736","pt":1719502024382,"mc":[{"id":"1.230180126","rc":[{"atb":[[2.76,6.73]],"id":66993945},{"atl":[[1000,0]],"id":64851267}],"con":true,"img":false}]}
{"op":"mcm","clk":"11541087742","pt":1719502024483,"mc":[{"id":"1.230180126","rc":[{"atl":[[11,0.94]],"id":64851267}],"con":true,"img":false}]}
{"op":"mcm","clk":"11541087756","pt":1719502024687,"mc":[{"id":"1.230180126","rc":[{"atb":[[2.38,8.59]],"id":49823335}],"con":true,"img":false}]}
{"op":"mcm","clk":"11541087778","pt":1719502024947,"mc":[{"id":"1.230180126","rc":[{"atb":[[2.42,8.34]],"id":61941224}],"con":true,"img":false}]}
{"op":"mcm","clk":"11541087932","pt":1719502026959,"mc":[{"id":"1.230180126","rc":[{"atb":[[2.78,10.52]],"id":66993945}],"con":true,"img":false}]}
{"op":"mcm","clk":"11541087991","pt":1719502027681,"mc":[{"id":"1.230180126","rc":[{"atb":[[3.4,5.29]],"id":69475504}],"con":true,"img":false}]}
{"op":"mcm","clk":"11541088764","pt":1719502037911,"mc":[{"id":"1.230180126","rc":[{"atb":[[2.76,0]],"id":66993945}],"con":true,"img":false}]}
{"op":"mcm","clk":"11541088896","pt":1719502039615,"mc":[{"id":"1.230180126","rc":[{"atl":[[11,0.84]],"id":64851267}],"con":true,"img":false}]}
{"op":"mcm","clk":"11541088961","pt":1719502040492,"mc":[{"id":"1.230180126","rc":[{"atl":[[1000,0.1]],"id":64851267}],"con":true,"img":false}]}
{"op":"mcm","clk":"11541088968","pt":1719502040600,"mc":[{"id":"1.230180126","rc":[{"atl":[[1000,0]],"id":64851267}],"con":true,"img":false}]}
{"op":"mcm","clk":"11541088975","pt":1719502040698,"mc":[{"id":"1.230180126","rc":[{"atl":[[11,0.94]],"id":64851267}],"con":true,"img":false}]}
{"op":"mcm","clk":"11541089151","pt":1719502043430,"mc":[{"id":"1.230180126","rc":[{"atb":[[2.8,6.58]],"id":66993945}],"con":true,"img":false}]}
{"op":"mcm","clk":"11541089495","pt":1719502047829,"mc":[{"id":"1.230180126","rc":[{"atb":[[2.36,0]],"id":49823335},{"atb":[[2.4,0]],"id":61941224}],"con":true,"img":false}]}
{"op":"mcm","clk":"11541090096","pt":1719502055933,"mc":[{"id":"1.230180126","rc":[{"atl":[[11,0.84]],"id":64851267},{"atb":[[3.35,0]],"id":69475504}],"con":true,"img":false}]}
{"op":"mcm","clk":"11541090179","pt":1719502057025,"mc":[{"id":"1.230180126","rc":[{"atl":[[1000,0.1]],"id":64851267}],"con":true,"img":false}]}
{"op":"mcm","clk":"11541090200","pt":1719502057234,"mc":[{"id":"1.230180126","rc":[{"atl":[[1000,0]],"id":64851267}],"con":true,"img":false}]}
{"op":"mcm","clk":"11541090211","pt":1719502057328,"mc":[{"id":"1.230180126","rc":[{"atl":[[11,0.94]],"id":64851267},{"atb":[[2.44,8.82]],"id":61941224}],"con":true,"img":false}]}
{"op":"mcm","clk":"11541090242","pt":1719502057848,"mc":[{"id":"1.230180126","rc":[{"atb":[[2.4,9.06]],"id":49823335}],"con":true,"img":false}]}
{"op":"mcm","clk":"11541090250","pt":1719502057951,"mc":[{"id":"1.230180126","rc":[{"atb":[[2.78,7.13]],"id":66993945}],"con":true,"img":false}]}
{"op":"mcm","clk":"11541090269","pt":1719502058256,"mc":[{"id":"1.230180126","rc":[{"atb":[[2.82,3.38]],"id":66993945}],"con":true,"img":false}]}
{"op":"mcm","clk":"11541090572","pt":1719502061747,"mc":[{"id":"1.230180126","rc":[{"atb":[[2.8,9.74]],"id":66993945}],"con":true,"img":false}]}
{"op":"mcm","clk":"11541090624","pt":1719502062261,"mc":[{"id":"1.230180126","rc":[{"atb":[[3.45,4.83]],"id":69475504}],"con":true,"img":false}]}
{"op":"mcm","clk":"11541091152","pt":1719502069271,"mc":[{"id":"1.230180126","rc":[{"atb":[[3.1,3.49]],"id":66993945},{"atb":[[3.75,8.88]],"id":49823335},{"atb":[[2.64,6.64]],"id":64851267},{"atb":[[3.4,8.88]],"id":62886137},{"atb":[[4.2,9.18]],"id":61941224}],"con":true,"img":false}]}
{"op":"mcm","clk":"11541091373","pt":1719502072442,"mc":[{"id":"1.230180126","rc":[{"atl":[[11,0.84]],"id":64851267}],"con":true,"img":false}]}
{"op":"mcm","clk":"11541091505","pt":1719502073955,"mc":[{"id":"1.230180126","rc":[{"atl":[[1000,0.1]],"id":64851267}],"con":true,"img":false}]}
{"op":"mcm","clk":"11541091520","pt":1719502074167,"mc":[{"id":"1.230180126","rc":[{"atl":[[1000,0]],"id":64851267}],"con":true,"img":false}]}
{"op":"mcm","clk":"11541091529","pt":1719502074266,"mc":[{"id":"1.230180126","rc":[{"atl":[[11,0.94]],"id":64851267}],"con":true,"img":false}]}
{"op":"mcm","clk":"11541092165","pt":1719502082474,"mc":[{"id":"1.230180126","rc":[{"atb":[[2.78,0]],"id":66993945},{"atb":[[3.4,0]],"id":69475504}],"con":true,"img":false}]}
{"op":"mcm","clk":"11541092763","pt":1719502089482,"mc":[{"id":"1.230180126","rc":[{"atl":[[11,0.84]],"id":64851267}],"con":true,"img":false}]}
{"op":"mcm","clk":"11541092834","pt":1719502090379,"mc":[{"id":"1.230180126","rc":[{"atl":[[1000,0.1]],"id":64851267}],"con":true,"img":false}]}
{"op":"mcm","clk":"11541092845","pt":1719502090478,"mc":[{"id":"1.230180126","rc":[{"atl":[[1000,0]],"id":64851267}],"con":true,"img":false}]}
{"op":"mcm","clk":"11541092855","pt":1719502090577,"mc":[{"id":"1.230180126","rc":[{"atl":[[11,0.94]],"id":64851267}],"con":true,"img":false}]}
{"op":"mcm","clk":"11541092979","pt":1719502092164,"mc":[{"id":"1.230180126","rc":[{"atb":[[2.38,0]],"id":49823335},{"atb":[[2.42,0]],"id":61941224}],"con":true,"img":false}]}
{"op":"mcm","clk":"11541093046","pt":1719502092989,"mc":[{"id":"1.230180126","rc":[{"atb":[[2.82,10.36]],"id":66993945}],"con":true,"img":false}]}
{"op":"mcm","clk":"11541093090","pt":1719502093467,"mc":[{"id":"1.230180126","rc":[{"atb":[[2.62,7.84]],"id":64851267}],"con":true,"img":false}]}
{"op":"mcm","clk":"11541093136","pt":1719502093986,"mc":[{"id":"1.230180126","rc":[{"atb":[[2.66,3.38]],"id":64851267}],"con":true,"img":false}]}
{"op":"mcm","clk":"11541093372","pt":1719502097464,"mc":[{"id":"1.230180126","rc":[{"atb":[[2.42,8.34]],"id":49823335}],"con":true,"img":false}]}
{"op":"mcm","clk":"11541093380","pt":1719502097567,"mc":[{"id":"1.230180126","rc":[{"atb":[[2.46,8.11]],"id":61941224}],"con":true,"img":false}]}
{"op":"mcm","clk":"11541093443","pt":1719502098701,"mc":[{"id":"1.230180126","rc":[{"atb":[[2.8,6.58]],"id":66993945}],"con":true,"img":false}]}
{"op":"mcm","clk":"11541093459","pt":1719502098866,"mc":[{"id":"1.230180126","rc":[{"atb":[[2.84,3.16]],"id":66993945}],"con":true,"img":false}]}
{"op":"mcm","clk":"11541093559","pt":1719502100718,"mc":[{"id":"1.230180126","rc":[{"atb":[[2.78,4.64]],"id":66993945}],"con":true,"img":false}]}
{"op":"mcm","clk":"11541093662","pt":1719502102471,"mc":[{"id":"1.230180126","rc":[{"atb":[[2.78,0]],"id":66993945}],"con":true,"img":false}]}
{"op":"mcm","clk":"11541093869","pt":1719502105692,"mc":[{"id":"1.230180126","rc":[{"atl":[[11,0.84]],"id":64851267}],"con":true,"img":false}]}
{"op":"mcm","clk":"11541093886","pt":1719502105898,"mc":[{"id":"1.230180126","rc":[{"atl":[[1000,0.1]],"id":64851267}],"con":true,"img":false}]}
{"op":"mcm","clk":"11541093896","pt":1719502106099,"mc":[{"id":"1.230180126","rc":[{"atl":[[1000,0]],"id":64851267}],"con":true,"img":false}]}
{"op":"mcm","clk":"11541093905","pt":1719502106202,"mc":[{"id":"1.230180126","rc":[{"atl":[[11,0.94]],"id":64851267}],"con":true,"img":false}]}
{"op":"mcm","clk":"11541094073","pt":1719502108493,"mc":[{"id":"1.230180126","rc":[{"atb":[[2.64,3.16]],"id":64851267}],"con":true,"img":false}]}
{"op":"mcm","clk":"11541094819","pt":1719502121493,"mc":[{"id":"1.230180126","rc":[{"atl":[[11,0.84]],"id":64851267}],"con":true,"img":false}]}
{"op":"mcm","clk":"11541094829","pt":1719502121702,"mc":[{"id":"1.230180126","rc":[{"atl":[[1000,0.1]],"id":64851267}],"con":true,"img":false}]}
{"op":"mcm","clk":"11541094842","pt":1719502121908,"mc":[{"id":"1.230180126","rc":[{"atl":[[1000,0]],"id":64851267}],"con":true,"img":false}]}
{"op":"mcm","clk":"11541094847","pt":1719502122006,"mc":[{"id":"1.230180126","rc":[{"atl":[[11,0.94]],"id":64851267}],"con":true,"img":false}]}
{"op":"mcm","clk":"11541095242","pt":1719502127807,"mc":[{"id":"1.230180126","rc":[{"atb":[[2.66,0]],"id":64851267}],"con":true,"img":false}]}
{"op":"mcm","clk":"11541095263","pt":1719502128116,"mc":[{"id":"1.230180126","rc":[{"atb":[[3.5,5.08]],"id":69475504}],"con":true,"img":false}]}
{"op":"mcm","clk":"11541095292","pt":1719502128528,"mc":[{"id":"1.230180126","rc":[{"atb":[[2.8,0]],"id":66993945},{"atb":[[3.45,0]],"id":69475504}],"con":true,"img":false}]}
{"op":"mcm","clk":"11541095732","pt":1719502134432,"mc":[{"id":"1.230180126","rc":[{"atb":[[2.6,7.41]],"id":66993945}],"con":true,"img":false}]}
{"op":"mcm","clk":"11541095951","pt":1719502137324,"mc":[{"id":"1.230180126","rc":[{"atl":[[11,0.84]],"id":64851267}],"con":true,"img":false}]}
{"op":"mcm","clk":"11541095964","pt":1719502137531,"mc":[{"id":"1.230180126","rc":[{"atl":[[1000,0.1]],"id":64851267}],"con":true,"img":false}]}
{"op":"mcm","clk":"11541095980","pt":1719502137737,"mc":[{"id":"1.230180126","rc":[{"atl":[[1000,0]],"id":64851267}],"con":true,"img":false}]}
{"op":"mcm","clk":"11541095987","pt":1719502137841,"mc":[{"id":"1.230180126","rc":[{"atl":[[11,0.94]],"id":64851267}],"con":true,"img":false}]}
{"op":"mcm","clk":"11541096087","pt":1719502139448,"mc":[{"id":"1.230180126","rc":[{"atb":[[1.09,1.69]],"id":66993945},{"atb":[[1.14,1.69]],"id":62886137}],"con":true,"img":false}]}
{"op":"mcm","clk":"11541096108","pt":1719502139713,"mc":[{"id":"1.230180126","rc":[{"atb":[[1.14,1.69]],"id":49823335},{"atb":[[1.14,1.69]],"id":69475504}],"con":true,"img":false}]}
{"op":"mcm","clk":"11541096131","pt":1719502140023,"mc":[{"id":"1.230180126","rc":[{"atb":[[1.08,1.69]],"id":64851267}],"con":true,"img":false}]}
{"op":"mcm","clk":"11541096144","pt":1719502140229,"mc":[{"id":"1.230180126","rc":[{"atb":[[1.09,0.07]],"id":66993945},{"atb":[[1.14,0.05]],"id":49823335}],"con":true,"img":false}]}
{"op":"mcm","clk":"11541096154","pt":1719502140332,"mc":[{"id":"1.230180126","rc":[{"atb":[[2.66,7.42]],"id":64851267},{"atl":[[11,2.94],[11.5,5]],"id":64851267}],"con":true,"img":false}]}
{"op":"mcm","clk":"11541096161","pt":1719502140441,"mc":[{"id":"1.230180126","rc":[{"atb":[[2.54,64.94]],"id":66993945},{"atl":[[24,3.71]],"id":66993945},{"atb":[[3.8,8.89]],"id":49823335},{"atl":[[34,4.58]],"id":49823335},{"atb":[[1.16,151.69]],"id":61941224},{"atb":[[1.14,0.05]],"id":69475504}],"con":true,"img":false}]}
{"op":"mcm","clk":"11541096180","pt":1719502140747,"mc":[{"id":"1.230180126","rc":[{"atb":[[1.14,0]],"id":49823335},{"atb":[[1.08,0.08]],"id":64851267},{"atb":[[4.3,8.82]],"id":61941224},{"atl":[[34,3.03]],"id":61941224},{"atb":[[2.82,54.95]],"id":69475504},{"atl":[[36,2.86]],"id":69475504}],"con":true,"img":false}]}
{"op":"mcm","clk":"11541096185","pt":1719502140858,"mc":[{"id":"1.230180126","rc":[{"atb":[[5.6,0.05]],"id":49823335},{"atb":[[3.45,6]],"id":62886137},{"atl":[[30,5.02]],"id":62886137}],"con":true,"img":false}]}
{"op":"mcm","clk":"11541096203","pt":1719502141121,"mc":[{"id":"1.230180126","rc":[{"atb":[[1.09,0]],"id":66993945},{"atb":[[1.14,0.05]],"id":62886137}],"con":true,"img":false}]}
{"op":"mcm","clk":"11541096211","pt":1719502141223,"mc":[{"id":"1.230180126","rc":[{"atb":[[3.95,0.07]],"id":66993945}],"con":true,"img":false}]}
{"op":"mcm","clk":"11541096237","pt":1719502141536,"mc":[{"id":"1.230180126","rc":[{"atb":[[1.14,0]],"id":69475504}],"con":true,"img":false}]}
{"op":"mcm","clk":"11541096245","pt":1719502141639,"mc":[{"id":"1.230180126","rc":[{"atb":[[6.2,0.05]],"id":69475504}],"con":true,"img":false}]}
{"op":"mcm","clk":"11541096269","pt":1719502142054,"mc":[{"id":"1.230180126","rc":[{"atb":[[1.08,0]],"id":64851267},{"atb":[[1.16,150.04]],"id":61941224}],"con":true,"img":false}]}
{"op":"mcm","clk":"11541096274","pt":1719502142158,"mc":[{"id":"1.230180126","rc":[{"atb":[[3.45,0.08]],"id":64851267}],"con":true,"img":false}]}
{"op":"mcm","clk":"11541096294","pt":1719502142526,"mc":[{"id":"1.230180126","rc":[{"atb":[[1.14,0]],"id":62886137}],"con":true,"img":false}]}
{"op":"mcm","clk":"11541096298","pt":1719502142631,"mc":[{"id":"1.230180126","rc":[{"atb":[[5.6,0.05]],"id":62886137}],"con":true,"img":false}]}
{"op":"mcm","clk":"11541096307","pt":1719502142735,"mc":[{"id":"1.230180126","rc":[{"atl":[[6.8,1]],"id":66993945},{"atl":[[6.8,1]],"id":64851267}],"con":true,"img":false}]}
{"op":"mcm","clk":"11541096330","pt":1719502143046,"mc":[{"id":"1.230180126","rc":[{"atb":[[1.16,150]],"id":61941224}],"con":true,"img":false}]}
{"op":"mcm","clk":"11541096336","pt":1719502143150,"mc":[{"id":"1.230180126","rc":[{"atb":[[7.2,0.04]],"id":61941224}],"con":true,"img":false}]}
{"op":"mcm","clk":"11541096361","pt":1719502143463,"mc":[{"id":"1.230180126","rc":[{"atl":[[11,0.94]],"id":64851267}],"con":true,"img":false}]}
{"op":"mcm","clk":"11541096447","pt":1719502144661,"mc":[{"id":"1.230180126","rc":[{"atb":[[1.02,3.7]],"id":66993945},{"atl":[[1000,1.94]],"id":66993945},{"atb":[[1.03,19]],"id":49823335},{"atl":[[1000,1.7]],"id":49823335},{"atb":[[1.03,134.15]],"id":62886137},{"atl":[[1000,1.94]],"id":62886137}],"con":true,"img":false}]}
{"op":"mcm","clk":"11541096471","pt":1719502144927,"mc":[{"id":"1.230180126","rc":[{"atb":[[1.02,2.14]],"id":66993945},{"atl":[[1000,0.25]],"id":66993945},{"atb":[[1.03,17.37]],"id":49823335},{"atl":[[1000,0.01]],"id":49823335},{"atb":[[1.03,132.53]],"id":62886137},{"atl":[[1000,0.24]],"id":62886137}],"con":true,"img":false}]}
{"op":"mcm","clk":"11541096490","pt":1719502145236,"mc":[{"id":"1.230180126","rc":[{"atb":[[1.02,2]],"id":66993945},{"atl":[[1000,0.23]],"id":66993945},{"atb":[[1.03,17.29]],"id":49823335},{"atl":[[1000,0]],"id":49823335},{"atb":[[1.03,132.45]],"id":62886137},{"atl":[[1000,0.23]],"id":62886137}],"con":true,"img":false}]}
{"op":"mcm","clk":"11541096493","pt":1719502145337,"mc":[{"id":"1.230180126","rc":[{"atb":[[3.15,0.14]],"id":66993945},{"atl":[[22,0.01]],"id":66993945},{"atb":[[5.1,0.07]],"id":49823335},{"atl":[[32,0.85]],"id":49823335},{"atb":[[5.1,0.07]],"id":62886137},{"atl":[[29,0.85]],"id":62886137}],"con":true,"img":false}]}
{"op":"mcm","clk":"11541096543","pt":1719502145957,"mc":[{"id":"1.230180126","rc":[{"atb":[[6,5.02]],"id":69475504}],"con":true,"img":false}]}
{"op":"mcm","clk":"11541096851","pt":1719502149836,"mc":[{"id":"1.230180126","rc":[{"spn":5.37,"spf":"NaN","id":66993945},{"atb":[[2.4,0]],"id":49823335},{"spn":18.8,"spf":"NaN","id":49823335},{"spn":3.4,"spf":1.0,"id":64851267},{"spn":17.3,"spf":"NaN","id":62886137},{"atb":[[2.44,0]],"id":61941224},{"spn":18.1,"spf":"NaN","id":61941224},{"spn":21.1,"spf":"NaN","id":69475504}],"con":true,"img":false}]}
{"op":"mcm","clk":"11541096923","pt":1719502150960,"mc":[{"id":"1.230180126","rc":[{"atb":[[3.8,6],[3.45,0]],"id":62886137}],"con":true,"img":false}]}
{"op":"mcm","clk":"11541096988","pt":1719502151956,"mc":[{"id":"1.230180126","rc":[{"atb":[[2.64,0]],"id":64851267}],"con":true,"img":false}]}
{"op":"mcm","clk":"11541096999","pt":1719502152154,"mc":[{"id":"1.230180126","rc":[{"atl":[[6.6,2]],"id":64851267}],"con":true,"img":false}]}
{"op":"mcm","clk":"11541097005","pt":1719502152259,"mc":[{"id":"1.230180126","rc":[{"atl":[[11.5,2],[7.8,3]],"id":64851267}],"con":true,"img":false}]}
{"op":"mcm","clk":"11541097024","pt":1719502152568,"mc":[{"id":"1.230180126","rc":[{"atb":[[2.68,3.16]],"id":64851267},{"atb":[[3.55,4.64]],"id":69475504}],"con":true,"img":false}]}
{"op":"mcm","clk":"11541097054","pt":1719502153036,"mc":[{"id":"1.230180126","rc":[{"atl":[[11,0.84]],"id":64851267}],"con":true,"img":false}]}
{"op":"mcm","clk":"11541097116","pt":1719502154065,"mc":[{"id":"1.230180126","rc":[{"atl":[[1000,0.19]],"id":64851267}],"con":true,"img":false}]}
{"op":"mcm","clk":"11541097128","pt":1719502154271,"mc":[{"id":"1.230180126","rc":[{"atl":[[1000,0]],"id":64851267}],"con":true,"img":false}]}
{"op":"mcm","clk":"11541097135","pt":1719502154326,"mc":[{"id":"1.230180126","rc":[{"atl":[[6.4,0.19]],"id":64851267}],"con":true,"img":false}]}
{"op":"mcm","clk":"11541097365","pt":1719502157379,"mc":[{"id":"1.230180126","rc":[{"atl":[[6.6,0]],"id":64851267}],"con":true,"img":false}]}
{"op":"mcm","clk":"11541097487","pt":1719502159258,"mc":[{"id":"1.230180126","rc":[{"atl":[[6.6,2]],"id":64851267}],"con":true,"img":false}]}
{"op":"mcm","clk":"11541097502","pt":1719502159465,"mc":[{"id":"1.230180126","rc":[{"atb":[[2.82,6.97]],"id":66993945}],"con":true,"img":false}]}
{"op":"mcm","clk":"11541097549","pt":1719502160037,"mc":[{"id":"1.230180126","rc":[{"atb":[[2.48,8.58]],"id":61941224}],"con":true,"img":false}]}
{"op":"mcm","clk":"11541097573","pt":1719502160353,"mc":[{"id":"1.230180126","rc":[{"atb":[[2.44,8.82]],"id":49823335}],"con":true,"img":false}]}
{"op":"mcm","clk":"11541097606","pt":1719502160863,"mc":[{"id":"1.230180126","rc":[{"atb":[[2.54,0],[2.76,7.42]],"id":66993945},{"atb":[[4.3,8.89],[3.8,0]],"id":49823335},{"atb":[[2.66,0],[2.96,7.42]],"id":64851267},{"atb":[[4.3,0]],"id":61941224},{"atb":[[2.82,0],[3.1,9.3]],"id":69475504}],"con":true,"img":false}]}
{"op":"mcm","clk":"11541097611","pt":1719502160965,"mc":[{"id":"1.230180126","rc":[{"atb":[[4.3,6],[3.8,0]],"id":62886137},{"atb":[[5.1,8.82]],"id":61941224}],"con":true,"img":false}]}
{"op":"mcm","clk":"11541097737","pt":1719502162674,"mc":[{"id":"1.230180126","rc":[{"atb":[[3.1,1]],"id":66993945},{"atb":[[3.75,6]],"id":49823335},{"atb":[[3.4,5.29]],"id":62886137},{"atb":[[4.2,6]],"id":61941224}],"con":true,"img":false}]}
{"op":"mcm","clk":"11541097881","pt":1719502164552,"mc":[{"id":"1.230180126","rc":[{"atl":[[6.6,0]],"id":64851267}],"con":true,"img":false}]}
{"op":"mcm","clk":"11541098028","pt":1719502166569,"mc":[{"id":"1.230180126","rc":[{"atl":[[6.6,2]],"id":64851267}],"con":true,"img":false}]}
{"op":"mcm","clk":"11541098227","pt":1719502169662,"mc":[{"id":"1.230180126","rc":[{"atl":[[6.4,0]],"id":64851267}],"con":true,"img":false}]}
{"op":"mcm","clk":"11541098242","pt":1719502169868,"mc":[{"id":"1.230180126","rc":[{"atl":[[1000,0.19]],"id":64851267}],"con":true,"img":false}]}
{"op":"mcm","clk":"11541098254","pt":1719502170075,"mc":[{"id":"1.230180126","rc":[{"atl":[[1000,0]],"id":64851267}],"con":true,"img":false}]}
{"op":"mcm","clk":"11541098262","pt":1719502170178,"mc":[{"id":"1.230180126","rc":[{"atl":[[6.4,0.19]],"id":64851267}],"con":true,"img":false}]}
{"op":"mcm","clk":"11541098273","pt":1719502170385,"mc":[{"id":"1.230180126","rc":[{"atb":[[2.68,0]],"id":64851267}],"con":true,"img":false}]}
{"op":"mcm","clk":"11541098292","pt":1719502170644,"mc":[{"id":"1.230180126","rc":[{"atb":[[2.98,3.16]],"id":64851267}],"con":true,"img":false}]}
{"op":"mcm","clk":"11541098372","pt":1719502171785,"mc":[{"id":"1.230180126","rc":[{"atl":[[6.6,0]],"id":64851267}],"con":true,"img":false}]}
{"op":"mcm","clk":"11541098503","pt":1719502173646,"mc":[{"id":"1.230180126","rc":[{"atl":[[6.6,2]],"id":64851267}],"con":true,"img":false}]}
{"op":"mcm","clk":"11541098867","pt":1719502178972,"mc":[{"id":"1.230180126","rc":[{"atl":[[6.6,0]],"id":64851267}],"con":true,"img":false}]}
{"op":"mcm","clk":"11541099003","pt":1719502180787,"mc":[{"id":"1.230180126","rc":[{"atl":[[6.6,2]],"id":64851267}],"con":true,"img":false}]}
{"op":"mcm","clk":"11541099221","pt":1719502184096,"mc":[{"id":"1.230180126","rc":[{"atb":[[2.6,0]],"id":66993945},{"atb":[[2.42,0]],"id":49823335},{"atb":[[2.6,0]],"id":64851267},{"atb":[[3.35,0]],"id":62886137},{"atb":[[2.46,0]],"id":61941224}],"con":true,"img":false}]}
{"op":"mcm","clk":"11541099294","pt":1719502184976,"mc":[{"id":"1.230180126","rc":[{"atb":[[2.82,0]],"id":66993945},{"atb":[[3.5,0]],"id":69475504}],"con":true,"img":false}]}
{"op":"mcm","clk":"11541099327","pt":1719502185397,"mc":[{"id":"1.230180126","rc":[{"atl":[[6.4,0]],"id":64851267}],"con":true,"img":false}]}
{"op":"mcm","clk":"11541099355","pt":1719502185702,"mc":[{"id":"1.230180126","rc":[{"atl":[[1000,0.19]],"id":64851267}],"con":true,"img":false}]}
{"op":"mcm","clk":"11541099373","pt":1719502185875,"mc":[{"id":"1.230180126","rc":[{"atl":[[1000,0]],"id":64851267}],"con":true,"img":false}]}
{"op":"mcm","clk":"11541099377","pt":1719502185963,"mc":[{"id":"1.230180126","rc":[{"atl":[[6.4,0.19],[6.6,0]],"id":64851267}],"con":true,"img":false}]}
{"op":"mcm","clk":"11541099577","pt":1719502188504,"mc":[{"id":"1.230180126","rc":[{"atl":[[6.6,2]],"id":64851267}],"con":true,"img":false}]}
{"op":"mcm","clk":"11541099605","pt":1719502188876,"mc":[{"id":"1.230180126","rc":[{"atb":[[3.15,0]],"id":66993945},{"atl":[[22,0]],"id":66993945},{"atb":[[5.1,0]],"id":49823335},{"atl":[[32,0.84]],"id":49823335},{"atb":[[5.1,0]],"id":62886137},{"atl":[[29,0.84]],"id":62886137}],"con":true,"img":false}]}
{"op":"mcm","clk":"11541099674","pt":1719502189798,"mc":[{"id":"1.230180126","rc":[{"atb":[[3.45,4.83]],"id":62886137}],"con":true,"img":false}]}
{"op":"mcm","clk":"11541099708","pt":1719502190163,"mc":[{"id":"1.230180126","rc":[{"atb":[[2.64,7.23]],"id":64851267}],"con":true,"img":false}]}
{"op":"mcm","clk":"11541099716","pt":1719502190284,"mc":[{"id":"1.230180126","rc":[{"atb":[[2.84,0]],"id":66993945}],"con":true,"img":false}]}
{"op":"mcm","clk":"11541099751","pt":1719502190683,"mc":[{"id":"1.230180126","rc":[{"atb":[[2.46,8.11]],"id":49823335}],"con":true,"img":false}]}
{"op":"mcm","clk":"11541099774","pt":1719502191101,"mc":[{"id":"1.230180126","rc":[{"atb":[[2.5,7.9]],"id":61941224}],"con":true,"img":false}]}
{"op":"mcm","clk":"11541099973","pt":1719502193701,"mc":[{"id":"1.230180126","rc":[{"atl":[[6.6,0]],"id":64851267}],"con":true,"img":false}]}
{"op":"mcm","clk":"11541100112","pt":1719502195578,"mc":[{"id":"1.230180126","rc":[{"atl":[[6.6,2]],"id":64851267}],"con":true,"img":false}]}
{"op":"mcm","clk":"11541100239","pt":1719502197075,"mc":[{"id":"1.230180126","rc":[{"atb":[[3.6,4.88]],"id":69475504}],"con":true,"img":false}]}
{"op":"mcm","clk":"11541100545","pt":1719502200777,"mc":[{"id":"1.230180126","rc":[{"atl":[[6.6,0]],"id":64851267}],"con":true,"img":false}]}
{"op":"mcm","clk":"11541100589","pt":1719502201201,"mc":[{"id":"1.230180126","rc":[{"atl":[[6.4,0]],"id":64851267}],"con":true,"img":false}]}
{"op":"mcm","clk":"11541100598","pt":1719502201303,"mc":[{"id":"1.230180126","rc":[{"atl":[[7.8,0]],"id":64851267}],"con":true,"img":false}]}
{"op":"mcm","clk":"11541100610","pt":1719502201408,"mc":[{"id":"1.230180126","rc":[{"atl":[[11,4.84]],"id":64851267}],"con":true,"img":false}]}
{"op":"mcm","clk":"11541100621","pt":1719502201509,"mc":[{"id":"1.230180126","rc":[{"atl":[[1000,0.18]],"id":64851267}],"con":true,"img":false}]}
{"op":"mcm","clk":"11541100646","pt":1719502201784,"mc":[{"id":"1.230180126","rc":[{"atl":[[1000,0]],"id":64851267}],"con":true,"img":false}]}
{"op":"mcm","clk":"11541100654","pt":1719502201889,"mc":[{"id":"1.230180126","rc":[{"atl":[[6.6,0.18]],"id":64851267}],"con":true,"img":false}]}
{"op":"mcm","clk":"11541100735","pt":1719502202713,"mc":[{"id":"1.230180126","rc":[{"atl":[[6.6,2.18]],"id":64851267}],"con":true,"img":false}]}
{"op":"mcm","clk":"11541101188","pt":1719502208025,"mc":[{"id":"1.230180126","rc":[{"atl":[[6.6,0.18]],"id":64851267}],"con":true,"img":false}]}
{"op":"mcm","clk":"11541101295","pt":1719502209319,"mc":[{"id":"1.230180126","rc":[{"atb":[[2.78,3.16]],"id":66993945}],"con":true,"img":false}]}
{"op":"mcm","clk":"11541101360","pt":1719502210103,"mc":[{"id":"1.230180126","rc":[{"atb":[[3.55,0]],"id":69475504}],"con":true,"img":false}]}
{"op":"mcm","clk":"11541101378","pt":1719502210304,"mc":[{"id":"1.230180126","rc":[{"atb":[[2.78,9.82]],"id":66993945}],"con":true,"img":false}]}
{"op":"mcm","clk":"11541101384","pt":1719502210414,"mc":[{"id":"1.230180126","rc":[{"atl":[[6.6,2.18]],"id":64851267}],"con":true,"img":false}]}
{"op":"mcm","clk":"11541101426","pt":1719502210896,"mc":[{"id":"1.230180126","rc":[{"atl":[[11,0.84],[7.8,3.18]],"id":64851267}],"con":true,"img":false}]}
{"op":"mcm","clk":"11541101821","pt":1719502215612,"mc":[{"id":"1.230180126","rc":[{"atl":[[6.6,0.18]],"id":64851267}],"con":true,"img":false}]}
{"op":"mcm","clk":"11541101950","pt":1719502217223,"mc":[{"id":"1.230180126","rc":[{"atl":[[6.6,0]],"id":64851267}],"con":true,"img":false}]}
{"op":"mcm","clk":"11541101968","pt":1719502217429,"mc":[{"id":"1.230180126","rc":[{"atl":[[11,5.02],[7.8,0]],"id":64851267}],"con":true,"img":false}]}
{"op":"mcm","clk":"11541101988","pt":1719502217591,"mc":[{"id":"1.230180126","rc":[{"atl":[[6.6,2]],"id":64851267}],"con":true,"img":false}]}
{"op":"mcm","clk":"11541102009","pt":1719502217791,"mc":[{"id":"1.230180126","rc":[{"atl":[[11,0.84],[7.8,3],[1000,0.18]],"id":64851267}],"con":true,"img":false}]}
{"op":"mcm","clk":"11541102044","pt":1719502218307,"mc":[{"id":"1.230180126","rc":[{"atl":[[1000,0]],"id":64851267}],"con":true,"img":false}]}
{"op":"mcm","clk":"11541102052","pt":1719502218412,"mc":[{"id":"1.230180126","rc":[{"atl":[[6.6,2.18]],"id":64851267}],"con":true,"img":false}]}
{"op":"mcm","clk":"11541102085","pt":1719502218828,"mc":[{"id":"1.230180126","rc":[{"atb":[[2.44,0]],"id":49823335},{"atb":[[2.62,0]],"id":64851267},{"atb":[[3.4,0]],"id":62886137},{"atb":[[2.48,0]],"id":61941224}],"con":true,"img":false}]}
{"op":"mcm","clk":"11541102438","pt":1719502222830,"mc":[{"id":"1.230180126","rc":[{"atl":[[6.6,0.18]],"id":64851267}],"con":true,"img":false}]}
{"op":"mcm","clk":"11541102605","pt":1719502224743,"mc":[{"id":"1.230180126","rc":[{"atl":[[6.6,2.18]],"id":64851267}],"con":true,"img":false}]}
{"op":"mcm","clk":"11541103012","pt":1719502229241,"mc":[{"id":"1.230180126","rc":[{"atb":[[2.98,6.54]],"id":64851267}],"con":true,"img":false}]}
{"op":"mcm","clk":"11541103030","pt":1719502229453,"mc":[{"id":"1.230180126","rc":[{"atb":[[3.35,5.4]],"id":62886137}],"con":true,"img":false}]}
{"op":"mcm","clk":"11541103043","pt":1719502229501,"mc":[{"id":"1.230180126","rc":[{"atb":[[2.52,8.35]],"id":61941224}],"con":true,"img":false}]}
{"op":"mcm","clk":"11541103092","pt":1719502230021,"mc":[{"id":"1.230180126","rc":[{"atl":[[6.6,0.18]],"id":64851267}],"con":true,"img":false}]}
{"op":"mcm","clk":"11541103124","pt":1719502230433,"mc":[{"id":"1.230180126","rc":[{"atb":[[2.48,8.58]],"id":49823335}],"con":true,"img":false}]}
{"op":"mcm","clk":"11541103129","pt":1719502230535,"mc":[{"id":"1.230180126","rc":[{"atb":[[3.1,1.79]],"id":66993945},{"atb":[[5.6,0.84]],"id":49823335},{"atb":[[3.1,1.79]],"id":64851267},{"atb":[[5.6,0.84]],"id":62886137},{"atb":[[5.1,9.61]],"id":61941224}],"con":true,"img":false}]}
{"op":"mcm","clk":"11541103140","pt":1719502230646,"mc":[{"id":"1.230180126","rc":[{"atb":[[2.6,7.94]],"id":64851267}],"con":true,"img":false}]}
{"op":"mcm","clk":"11541103295","pt":1719502231957,"mc":[{"id":"1.230180126","rc":[{"atl":[[6.6,2.18]],"id":64851267}],"con":true,"img":false}]}
{"op":"mcm","clk":"11541103449","pt":1719502233626,"mc":[{"id":"1.230180126","rc":[{"atl":[[6.6,2]],"id":64851267}],"con":true,"img":false}]}
{"op":"mcm","clk":"11541103560","pt":1719502235020,"mc":[{"id":"1.230180126","rc":[{"atl":[[1000,0.19]],"id":64851267}],"con":true,"img":false}]}
{"op":"mcm","clk":"11541103577","pt":1719502235228,"mc":[{"id":"1.230180126","rc":[{"atl":[[1000,0]],"id":64851267}],"con":true,"img":false}]}
{"op":"mcm","clk":"11541103583","pt":1719502235331,"mc":[{"id":"1.230180126","rc":[{"atl":[[6.4,0.19]],"id":64851267}],"con":true,"img":false}]}
{"op":"mcm","clk":"11541103797","pt":1719502237147,"mc":[{"id":"1.230180126","rc":[{"atl":[[6.6,0]],"id":64851267}],"con":true,"img":false}]}
{"op":"mcm","clk":"11541103965","pt":1719502239052,"mc":[{"id":"1.230180126","rc":[{"atl":[[6.6,2]],"id":64851267}],"con":true,"img":false}]}
{"op":"mcm","clk":"11541104313","pt":1719502243546,"mc":[{"id":"1.230180126","rc":[{"atb":[[3.1,1]],"id":64851267}],"con":true,"img":false}]}
{"op":"mcm","clk":"11541104372","pt":1719502244225,"mc":[{"id":"1.230180126","rc":[{"atl":[[6.6,0]],"id":64851267}],"con":true,"img":false}]}
{"op":"mcm","clk":"11541104441","pt":1719502245458,"mc":[{"id":"1.230180126","rc":[{"atb":[[5.6,1.68]],"id":49823335},{"atb":[[5.6,1.68]],"id":62886137},{"atb":[[6.2,0.89]],"id":69475504},{"atl":[[34,0.84]],"id":69475504}],"con":true,"img":false}]}
{"op":"mcm","clk":"11541104502","pt":1719502246231,"mc":[{"id":"1.230180126","rc":[{"atl":[[6.6,2]],"id":64851267}],"con":true,"img":false}]}
{"op":"mcm","clk":"11541104536","pt":1719502246744,"mc":[{"id":"1.230180126","rc":[{"atl":[[6.4,1.03]],"id":64851267}],"con":true,"img":false}]}
{"op":"mcm","clk":"11541104817","pt":1719502250569,"mc":[{"id":"1.230180126","rc":[{"atl":[[6.4,0.84]],"id":64851267}],"con":true,"img":false}]}
{"op":"mcm","clk":"11541104844","pt":1719502250837,"mc":[{"id":"1.230180126","rc":[{"atl":[[1000,0.19]],"id":64851267}],"con":true,"img":false}]}
{"op":"mcm","clk":"11541104874","pt":1719502251151,"mc":[{"id":"1.230180126","rc":[{"atl":[[1000,0]],"id":64851267}],"con":true,"img":false}]}
{"op":"mcm","clk":"11541104885","pt":1719502251253,"mc":[{"id":"1.230180126","rc":[{"atl":[[6.4,1.03]],"id":64851267}],"con":true,"img":false}]}
{"op":"mcm","clk":"11541104906","pt":1719502251457,"mc":[{"id":"1.230180126","rc":[{"atl":[[6.6,0]],"id":64851267}],"con":true,"img":false}]}
{"op":"mcm","clk":"11541104934","pt":1719502251867,"mc":[{"id":"1.230180126","rc":[{"atl":[[6.4,0.19]],"id":64851267}],"con":true,"img":false}]}
{"op":"mcm","clk":"11541105039","pt":1719502253263,"mc":[{"id":"1.230180126","rc":[{"atl":[[6.6,2]],"id":64851267}],"con":true,"img":false}]}
{"op":"mcm","clk":"11541105070","pt":1719502253633,"mc":[{"id":"1.230180126","rc":[{"atb":[[3.6,0]],"id":69475504}],"con":true,"img":false}]}
{"op":"mcm","clk":"11541105087","pt":1719502253837,"mc":[{"id":"1.230180126","rc":[{"atl":[[6.4,1.03]],"id":64851267}],"con":true,"img":false}]}
{"op":"mcm","clk":"11541105120","pt":1719502254250,"mc":[{"id":"1.230180126","rc":[{"atl":[[6.6,0]],"id":64851267}],"con":true,"img":false}]}
{"op":"mcm","clk":"11541105167","pt":1719502254872,"mc":[{"id":"1.230180126","rc":[{"atl":[[6.4,0.19]],"id":64851267}],"con":true,"img":false}]}
{"op":"mcm","clk":"11541105539","pt":1719502260342,"mc":[{"id":"1.230180126","rc":[{"atb":[[2.46,0]],"id":49823335},{"atb":[[2.64,0]],"id":64851267},{"atb":[[3.45,0]],"id":62886137},{"atb":[[2.5,0]],"id":61941224}],"con":true,"img":false}]}
{"op":"mcm","clk":"11541105548","pt":1719502260452,"mc":[{"id":"1.230180126","rc":[{"atl":[[6.6,2]],"id":64851267}],"con":true,"img":false}]}
{"op":"mcm","clk":"11541105569","pt":1719502260651,"mc":[{"id":"1.230180126","rc":[{"atb":[[5.6,1.63]],"id":62886137}],"con":true,"img":false}]}
{"op":"mcm","clk":"11541105581","pt":1719502260860,"mc":[{"id":"1.230180126","rc":[{"atb":[[5.6,1.63]],"id":49823335}],"con":true,"img":false}]}
{"op":"mcm","clk":"11541105612","pt":1719502261272,"mc":[{"id":"1.230180126","rc":[{"atb":[[3.95,0]],"id":66993945},{"atb":[[3.45,0]],"id":64851267}],"con":true,"img":false}]}
{"op":"mcm","clk":"11541105621","pt":1719502261382,"mc":[{"id":"1.230180126","rc":[{"atl":[[6.4,1.03]],"id":64851267}],"con":true,"img":false}]}
{"op":"mcm","clk":"11541105640","pt":1719502261593,"mc":[{"id":"1.230180126","rc":[{"atb":[[6.2,0.84]],"id":69475504}],"con":true,"img":false}]}
{"op":"mcm","clk":"11541105652","pt":1719502261644,"mc":[{"id":"1.230180126","rc":[{"atb":[[1.14,1.69]],"id":49823335}],"con":true,"img":false}]}
{"op":"mcm","clk":"11541105671","pt":1719502261862,"mc":[{"id":"1.230180126","rc":[{"atb":[[1.14,1.69]],"id":62886137},{"atb":[[1.14,1.69]],"id":69475504}],"con":true,"img":false}]}
{"op":"mcm","clk":"11541105695","pt":1719502262067,"mc":[{"id":"1.230180126","rc":[{"atb":[[1.08,1.69]],"id":64851267}],"con":true,"img":false}]}
{"op":"mcm","clk":"11541105707","pt":1719502262164,"mc":[{"id":"1.230180126","rc":[{"atb":[[1.14,0.05]],"id":49823335}],"con":true,"img":false}]}
{"op":"mcm","clk":"11541105729","pt":1719502262369,"mc":[{"id":"1.230180126","rc":[{"atb":[[1.14,0.05]],"id":69475504}],"con":true,"img":false}]}
{"op":"mcm","clk":"11541105747","pt":1719502262575,"mc":[{"id":"1.230180126","rc":[{"atb":[[1.09,1.69]],"id":66993945}],"con":true,"img":false}]}
{"op":"mcm","clk":"11541105756","pt":1719502262678,"mc":[{"id":"1.230180126","rc":[{"atb":[[1.08,0.08]],"id":64851267}],"con":true,"img":false}]}
{"op":"mcm","clk":"11541105775","pt":1719502262839,"mc":[{"id":"1.230180126","rc":[{"atb":[[7.2,0]],"id":61941224}],"con":true,"img":false}]}
{"op":"mcm","clk":"11541105786","pt":1719502262942,"mc":[{"id":"1.230180126","rc":[{"atb":[[1.14,0.05]],"id":62886137}],"con":true,"img":false}]}
{"op":"mcm","clk":"11541105799","pt":1719502263043,"mc":[{"id":"1.230180126","rc":[{"atb":[[2.8,3.38]],"id":66993945}],"con":true,"img":false}]}
{"op":"mcm","clk":"11541105815","pt":1719502263252,"mc":[{"id":"1.230180126","rc":[{"atb":[[2.8,10.44]],"id":66993945},{"atb":[[1.14,0]],"id":49823335}],"con":true,"img":false}]}
{"op":"mcm","clk":"11541105824","pt":1719502263358,"mc":[{"id":"1.230180126","rc":[{"atb":[[5.7,0.05]],"id":49823335},{"atb":[[3.15,5.91]],"id":69475504}],"con":true,"img":false}]}
{"op":"mcm","clk":"11541105847","pt":1719502263663,"mc":[{"id":"1.230180126","rc":[{"atb":[[1.14,0]],"id":69475504}],"con":true,"img":false}]}
{"op":"mcm","clk":"11541105854","pt":1719502263765,"mc":[{"id":"1.230180126","rc":[{"atb":[[6.2,0.89]],"id":69475504}],"con":true,"img":false}]}
{"op":"mcm","clk":"11541105868","pt":1719502264074,"mc":[{"id":"1.230180126","rc":[{"atb":[[1.09,0.07]],"id":66993945},{"atb":[[1.08,0]],"id":64851267}],"con":true,"img":false}]}
{"op":"mcm","clk":"11541105877","pt":1719502264177,"mc":[{"id":"1.230180126","rc":[{"atb":[[3.45,0.08]],"id":64851267}],"con":true,"img":false}]}
{"op":"mcm","clk":"11541105902","pt":1719502264450,"mc":[{"id":"1.230180126","rc":[{"atb":[[1.14,0]],"id":62886137}],"con":true,"img":false}]}
{"op":"mcm","clk":"11541105909","pt":1719502264545,"mc":[{"id":"1.230180126","rc":[{"atb":[[5.7,0.05]],"id":62886137}],"con":true,"img":false}]}
{"op":"mcm","clk":"11541105922","pt":1719502264756,"mc":[{"id":"1.230180126","rc":[{"atb":[[1.16,151.69]],"id":61941224}],"con":true,"img":false}]}
{"op":"mcm","clk":"11541105948","pt":1719502265064,"mc":[{"id":"1.230180126","rc":[{"atb":[[1.09,0]],"id":66993945}],"con":true,"img":false}]}
{"op":"mcm","clk":"11541105955","pt":1719502265175,"mc":[{"id":"1.230180126","rc":[{"atb":[[3.95,0.07]],"id":66993945}],"con":true,"img":false}]}
{"op":"mcm","clk":"11541105979","pt":1719502265481,"mc":[{"id":"1.230180126","rc":[{"atb":[[1.16,150.04]],"id":61941224}],"con":true,"img":false}]}
{"op":"mcm","clk":"11541105997","pt":1719502265681,"mc":[{"id":"1.230180126","rc":[{"atl":[[6.6,0]],"id":64851267}],"con":true,"img":false}]}
{"op":"mcm","clk":"11541106004","pt":1719502265735,"mc":[{"id":"1.230180126","rc":[{"atb":[[1.16,150]],"id":61941224}],"con":true,"img":false}]}
{"op":"mcm","clk":"11541106014","pt":1719502265840,"mc":[{"id":"1.230180126","rc":[{"atb":[[1.02,3.7]],"id":66993945},{"atl":[[1000,1.94]],"id":66993945},{"atb":[[1.04,78.75]],"id":49823335},{"atl":[[1000,1.7]],"id":49823335},{"atb":[[1.04,1.7]],"id":62886137},{"atl":[[1000,1.94]],"id":62886137},{"atb":[[7.2,0.04]],"id":61941224}],"con":true,"img":false}]}
{"op":"mcm","clk":"11541106031","pt":1719502266052,"mc":[{"id":"1.230180126","rc":[{"atb":[[1.02,2.14]],"id":66993945},{"atl":[[1000,0.25]],"id":66993945},{"atb":[[1.04,77.12]],"id":49823335},{"atl":[[1000,0.01]],"id":49823335},{"atb":[[1.04,0.06]],"id":62886137},{"atl":[[1000,0.24]],"id":62886137}],"con":true,"img":false}]}
{"op":"mcm","clk":"11541106050","pt":1719502266254,"mc":[{"id":"1.230180126","rc":[{"atb":[[1.02,2],[2.78,6.66]],"id":66993945},{"atl":[[1000,0.23]],"id":66993945},{"atb":[[1.04,77.05]],"id":49823335},{"atl":[[1000,0]],"id":49823335},{"atl":[[6.4,0.19]],"id":64851267},{"atb":[[3.4,4.94],[1.04,0]],"id":62886137},{"atl":[[1000,0.23]],"id":62886137}],"con":true,"img":false}]}
{"op":"mcm","clk":"11541106060","pt":1719502266376,"mc":[{"id":"1.230180126","rc":[{"atb":[[3.15,0.14]],"id":66993945},{"atl":[[22,0.01]],"id":66993945},{"atb":[[5.6,1.7]],"id":49823335},{"atl":[[32,0.85]],"id":49823335},{"atb":[[5.6,1.7]],"id":62886137},{"atl":[[29,0.85]],"id":62886137}],"con":true,"img":false}]}
{"op":"mcm","clk":"11541106074","pt":1719502266467,"mc":[{"id":"1.230180126","rc":[{"atb":[[2.5,7.9]],"id":49823335},{"atb":[[2.62,7.32]],"id":64851267},{"atl":[[6.4,0]],"id":64851267}],"con":true,"img":false}]}
{"op":"mcm","clk":"11541106087","pt":1719502266668,"mc":[{"id":"1.230180126","rc":[{"atb":[[2.82,3.16]],"id":66993945},{"atl":[[11,4.84],[7.8,0]],"id":64851267}],"con":true,"img":false}]}
{"op":"mcm","clk":"11541106098","pt":1719502266770,"mc":[{"id":"1.230180126","rc":[{"atl":[[1000,0.18]],"id":64851267}],"con":true,"img":false}]}
{"op":"mcm","clk":"11541106111","pt":1719502266976,"mc":[{"id":"1.230180126","rc":[{"atl":[[1000,0]],"id":64851267}],"con":true,"img":false}]}
{"op":"mcm","clk":"11541106117","pt":1719502267083,"mc":[{"id":"1.230180126","rc":[{"atl":[[6.6,0.18]],"id":64851267},{"atb":[[2.54,7.7]],"id":61941224}],"con":true,"img":false}]}
{"op":"mcm","clk":"11541106161","pt":1719502267652,"mc":[{"id":"1.230180126","rc":[{"atl":[[6.6,2.18]],"id":64851267}],"con":true,"img":false}]}
{"op":"mcm","clk":"11541106217","pt":1719502268377,"mc":[{"id":"1.230180126","rc":[{"atl":[[6.4,0.84]],"id":64851267}],"con":true,"img":false}]}
{"op":"mcm","clk":"11541106252","pt":1719502268761,"mc":[{"id":"1.230180126","rc":[{"spl":[[1.01,4]],"id":66993945}],"con":true,"img":false}]}
{"op":"mcm","clk":"11541106631","pt":1719502272955,"mc":[{"id":"1.230180126","rc":[{"spn":3.29,"spf":1.0,"id":66993945},{"spn":18.85,"spf":"NaN","id":49823335},{"atl":[[6.6,0.18]],"id":64851267},{"spn":17.35,"spf":"NaN","id":62886137},{"spn":20.1,"spf":"NaN","id":69475504}],"con":true,"img":false}]}
{"op":"mcm","clk":"11541106651","pt":1719502273164,"mc":[{"id":"1.230180126","rc":[{"atl":[[34,0],[30,4.57]],"id":61941224},{"atl":[[36,0],[28,2.86]],"id":69475504}],"con":true,"img":false}]}
{"op":"mcm","clk":"11541106671","pt":1719502273479,"mc":[{"id":"1.230180126","rc":[{"atl":[[6.4,0]],"id":64851267}],"con":true,"img":false}]}
{"op":"mcm","clk":"11541106700","pt":1719502273883,"mc":[{"id":"1.230180126","rc":[{"atl":[[34,0],[27,0.84]],"id":69475504}],"con":true,"img":false}]}
{"op":"mcm","clk":"11541106769","pt":1719502274759,"mc":[{"id":"1.230180126","rc":[{"atl":[[6.6,2.18]],"id":64851267}],"con":true,"img":false}]}
{"op":"mcm","clk":"11541106826","pt":1719502275581,"mc":[{"id":"1.230180126","rc":[{"atl":[[11,0.84],[7,3.18]],"id":64851267}],"con":true,"img":false}]}
{"op":"mcm","clk":"11541106842","pt":1719502275844,"mc":[{"id":"1.230180126","rc":[{"atl":[[6.4,0.84]],"id":64851267}],"con":true,"img":false}]}
{"op":"mcm","clk":"11541107126","pt":1719502279976,"mc":[{"id":"1.230180126","rc":[{"atl":[[6.6,0.18]],"id":64851267}],"con":true,"img":false}]}
{"op":"mcm","clk":"11541107160","pt":1719502280400,"mc":[{"id":"1.230180126","rc":[{"atl":[[6.4,0]],"id":64851267}],"con":true,"img":false}]}
{"op":"mcm","clk":"11541107290","pt":1719502281791,"mc":[{"id":"1.230180126","rc":[{"atl":[[6.6,2.18]],"id":64851267}],"con":true,"img":false}]}
{"op":"mcm","clk":"11541107309","pt":1719502281951,"mc":[{"id":"1.230180126","rc":[{"atl":[[23,0]],"id":66993945},{"atl":[[11,0]],"id":64851267}],"con":true,"img":false}]}
{"op":"mcm","clk":"11541107338","pt":1719502282366,"mc":[{"id":"1.230180126","rc":[{"atl":[[6.6,2]],"id":64851267}],"con":true,"img":false}]}
{"op":"mcm","clk":"11541107349","pt":1719502282465,"mc":[{"id":"1.230180126","rc":[{"atb":[[3.1,1]],"id":66993945},{"atb":[[5.6,0.91]],"id":49823335},{"atb":[[5.6,0.91]],"id":62886137}],"con":true,"img":false}]}
{"op":"mcm","clk":"11541107354","pt":1719502282568,"mc":[{"id":"1.230180126","rc":[{"atl":[[1000,0.19]],"id":64851267}],"con":true,"img":false}]}
{"op":"mcm","clk":"11541107376","pt":1719502282780,"mc":[{"id":"1.230180126","rc":[{"atl":[[1000,0]],"id":64851267}],"con":true,"img":false}]}
{"op":"mcm","clk":"11541107385","pt":1719502282877,"mc":[{"id":"1.230180126","rc":[{"atl":[[6.4,1.03]],"id":64851267}],"con":true,"img":false}]}
{"op":"mcm","clk":"11541107405","pt":1719502283188,"mc":[{"id":"1.230180126","rc":[{"atb":[[3.2,5.39]],"id":69475504}],"con":true,"img":false}]}
{"op":"mcm","clk":"11541107497","pt":1719502284591,"mc":[{"id":"1.230180126","rc":[{"atb":[[2.48,0]],"id":49823335},{"atb":[[2.52,0]],"id":61941224}],"con":true,"img":false}]}
{"op":"mcm","clk":"11541107702","pt":1719502287062,"mc":[{"id":"1.230180126","rc":[{"atl":[[6.6,0]],"id":64851267}],"con":true,"img":false}]}
{"op":"mcm","clk":"11541107771","pt":1719502287995,"mc":[{"id":"1.230180126","rc":[{"atl":[[6.4,0.19]],"id":64851267}],"con":true,"img":false}]}
{"op":"mcm","clk":"11541107854","pt":1719502288973,"mc":[{"id":"1.230180126","rc":[{"atl":[[6.6,2]],"id":64851267}],"con":true,"img":false}]}
{"op":"mcm","clk":"11541107886","pt":1719502289393,"mc":[{"id":"1.230180126","rc":[{"atl":[[1000,1]],"id":64851267}],"con":true,"img":false}]}
{"op":"mcm","clk":"11541107898","pt":1719502289594,"mc":[{"id":"1.230180126","rc":[{"atl":[[1000,0.03]],"id":64851267}],"con":true,"img":false}]}
{"op":"mcm","clk":"11541107916","pt":1719502289853,"mc":[{"id":"1.230180126","rc":[{"atl":[[1000,0]],"id":64851267}],"con":true,"img":false}]}
{"op":"mcm","clk":"11541107925","pt":1719502289961,"mc":[{"id":"1.230180126","rc":[{"atl":[[6.2,0.03]],"id":64851267}],"con":true,"img":false}]}
{"op":"mcm","clk":"11541107945","pt":1719502290270,"mc":[{"id":"1.230180126","rc":[{"atl":[[6.4,1.03]],"id":64851267}],"con":true,"img":false}]}
{"op":"mcm","clk":"11541107991","pt":1719502290782,"mc":[{"id":"1.230180126","rc":[{"atl":[[6.6,0]],"id":64851267}],"con":true,"img":false}]}
{"op":"mcm","clk":"11541108031","pt":1719502291295,"mc":[{"id":"1.230180126","rc":[{"atl":[[6.4,0.19]],"id":64851267}],"con":true,"img":false}]}
{"op":"mcm","clk":"11541108401","pt":1719502296076,"mc":[{"id":"1.230180126","rc":[{"atl":[[6.6,2]],"id":64851267}],"con":true,"img":false}]}
{"op":"mcm","clk":"11541108461","pt":1719502296888,"mc":[{"id":"1.230180126","rc":[{"atb":[[2.78,0]],"id":66993945}],"con":true,"img":false}]}
{"op":"mcm","clk":"11541108535","pt":1719502297770,"mc":[{"id":"1.230180126","rc":[{"atl":[[6.4,1.03]],"id":64851267}],"con":true,"img":false}]}
{"op":"mcm","clk":"11541108557","pt":1719502298085,"mc":[{"id":"1.230180126","rc":[{"atl":[[6.4,0.84]],"id":64851267}],"con":true,"img":false}]}
{"op":"mcm","clk":"11541108581","pt":1719502298385,"mc":[{"id":"1.230180126","rc":[{"atl":[[1000,0.19],[6.6,0]],"id":64851267}],"con":true,"img":false}]}
{"op":"mcm","clk":"11541108598","pt":1719502298595,"mc":[{"id":"1.230180126","rc":[{"atl":[[1000,0]],"id":64851267}],"con":true,"img":false}]}
{"op":"mcm","clk":"11541108608","pt":1719502298705,"mc":[{"id":"1.230180126","rc":[{"atl":[[6.4,1.03]],"id":64851267}],"con":true,"img":false}]}
{"op":"mcm","clk":"11541108632","pt":1719502298905,"mc":[{"id":"1.230180126","rc":[{"atl":[[6.4,0.19]],"id":64851267}],"con":true,"img":false}]}
{"op":"mcm","clk":"11541108958","pt":1719502302911,"mc":[{"id":"1.230180126","rc":[{"atb":[[2.82,9.67]],"id":66993945}],"con":true,"img":false}]}
{"op":"mcm","clk":"11541108978","pt":1719502303174,"mc":[{"id":"1.230180126","rc":[{"atl":[[6.6,2]],"id":64851267}],"con":true,"img":false}]}
{"op":"mcm","clk":"11541109097","pt":1719502304815,"mc":[{"id":"1.230180126","rc":[{"atl":[[6.4,1.03]],"id":64851267}],"con":true,"img":false}]}
{"op":"mcm","clk":"11541109359","pt":1719502308516,"mc":[{"id":"1.230180126","rc":[{"atl":[[6.6,0]],"id":64851267}],"con":true,"img":false}]}
{"op":"mcm","clk":"11541109376","pt":1719502308792,"mc":[{"id":"1.230180126","rc":[{"atl":[[6.4,0.19]],"id":64851267}],"con":true,"img":false}]}
{"op":"mcm","clk":"11541109383","pt":1719502308888,"mc":[{"id":"1.230180126","rc":[{"atb":[[3.15,0]],"id":66993945},{"atl":[[22,0]],"id":66993945},{"atb":[[5.6,0.84]],"id":49823335},{"atl":[[32,0.84]],"id":49823335},{"atb":[[5.6,0.84]],"id":62886137},{"atl":[[29,0.84]],"id":62886137}],"con":true,"img":false}]}
{"op":"mcm","clk":"11541109485","pt":1719502310280,"mc":[{"id":"1.230180126","rc":[{"atl":[[6.6,2]],"id":64851267}],"con":true,"img":false}]}
{"op":"mcm","clk":"11541109624","pt":1719502312310,"mc":[{"id":"1.230180126","rc":[{"atl":[[6.4,1.03]],"id":64851267}],"con":true,"img":false}]}
{"op":"mcm","clk":"11541109733","pt":1719502313922,"mc":[{"id":"1.230180126","rc":[{"atl":[[6.4,0.84]],"id":64851267}],"con":true,"img":false}]}
{"op":"mcm","clk":"11541109752","pt":1719502314092,"mc":[{"id":"1.230180126","rc":[{"atl":[[1000,0.19]],"id":64851267}],"con":true,"img":false}]}
{"op":"mcm","clk":"11541109773","pt":1719502314290,"mc":[{"id":"1.230180126","rc":[{"atl":[[1000,0]],"id":64851267}],"con":true,"img":false}]}
{"op":"mcm","clk":"11541109781","pt":1719502314404,"mc":[{"id":"1.230180126","rc":[{"atl":[[6.2,0.22]],"id":64851267}],"con":true,"img":false}]}
{"op":"mcm","clk":"11541109852","pt":1719502315485,"mc":[{"id":"1.230180126","rc":[{"atl":[[6.6,0]],"id":64851267}],"con":true,"img":false}]}
{"op":"mcm","clk":"11541109907","pt":1719502316319,"mc":[{"id":"1.230180126","rc":[{"atl":[[6.4,0]],"id":64851267}],"con":true,"img":false}]}
{"op":"mcm","clk":"11541109988","pt":1719502317206,"mc":[{"id":"1.230180126","rc":[{"atb":[[2.8,3.38]],"id":66993945},{"atb":[[2.6,0]],"id":64851267},{"atb":[[3.35,0]],"id":62886137},{"atb":[[3.15,0]],"id":69475504}],"con":true,"img":false}]}
{"op":"mcm","clk":"11541110022","pt":1719502317511,"mc":[{"id":"1.230180126","rc":[{"atl":[[6.6,2]],"id":64851267}],"con":true,"img":false}]}
{"op":"mcm","clk":"11541110156","pt":1719502319332,"mc":[{"id":"1.230180126","rc":[{"atl":[[6.4,0.84]],"id":64851267}],"con":true,"img":false}]}
{"op":"mcm","clk":"11541110191","pt":1719502319691,"mc":[{"id":"1.230180126","rc":[{"atl":[[6.6,0]],"id":64851267}],"con":true,"img":false}]}
{"op":"mcm","clk":"11541110252","pt":1719502320315,"mc":[{"id":"1.230180126","rc":[{"atl":[[6.4,0]],"id":64851267}],"con":true,"img":false}]}
{"op":"mcm","clk":"11541110354","pt":1719502321405,"mc":[{"id":"1.230180126","rc":[{"atb":[[2.82,6.51]],"id":66993945}],"con":true,"img":false}]}
{"op":"mcm","clk":"11541110619","pt":1719502324622,"mc":[{"id":"1.230180126","rc":[{"atl":[[6.6,2]],"id":64851267}],"con":true,"img":false}]}
{"op":"mcm","clk":"11541110794","pt":1719502326810,"mc":[{"id":"1.230180126","rc":[{"atl":[[6.4,0.84]],"id":64851267}],"con":true,"img":false}]}
{"op":"mcm","clk":"11541110811","pt":1719502327018,"mc":[{"id":"1.230180126","rc":[{"atb":[[2.8,0]],"id":66993945}],"con":true,"img":false}]}
{"op":"mcm","clk":"11541110818","pt":1719502327129,"mc":[{"id":"1.230180126","rc":[{"atb":[[3.45,5.18]],"id":62886137}],"con":true,"img":false}]}
{"op":"mcm","clk":"11541110835","pt":1719502327333,"mc":[{"id":"1.230180126","rc":[{"atb":[[2.52,8.35]],"id":49823335}],"con":true,"img":false}]}
{"op":"mcm","clk":"11541110841","pt":1719502327439,"mc":[{"id":"1.230180126","rc":[{"atb":[[2.84,6.9]],"id":66993945}],"con":true,"img":false}]}
{"op":"mcm","clk":"11541110855","pt":1719502327644,"mc":[{"id":"1.230180126","rc":[{"atb":[[3.25,5.64]],"id":69475504}],"con":true,"img":false}]}
{"op":"mcm","clk":"11541110865","pt":1719502327711,"mc":[{"id":"1.230180126","rc":[{"atb":[[2.64,7.74]],"id":64851267}],"con":true,"img":false}]}
{"op":"mcm","clk":"11541110883","pt":1719502327906,"mc":[{"id":"1.230180126","rc":[{"atb":[[2.84,10.28]],"id":66993945}],"con":true,"img":false}]}
{"op":"mcm","clk":"11541110891","pt":1719502328011,"mc":[{"id":"1.230180126","rc":[{"atb":[[2.56,8.14]],"id":61941224}],"con":true,"img":false}]}
{"op":"mcm","clk":"11541111031","pt":1719502329626,"mc":[{"id":"1.230180126","rc":[{"atl":[[6.2,0.03]],"id":64851267}],"con":true,"img":false}]}
{"op":"mcm","clk":"11541111046","pt":1719502329831,"mc":[{"id":"1.230180126","rc":[{"atl":[[6.6,0]],"id":64851267}],"con":true,"img":false}]}
{"op":"mcm","clk":"11541111052","pt":1719502329942,"mc":[{"id":"1.230180126","rc":[{"atl":[[1000,0.19]],"id":64851267}],"con":true,"img":false}]}
{"op":"mcm","clk":"11541111083","pt":1719502330210,"mc":[{"id":"1.230180126","rc":[{"atl":[[1000,0]],"id":64851267}],"con":true,"img":false}]}
{"op":"mcm","clk":"11541111092","pt":1719502330301,"mc":[{"id":"1.230180126","rc":[{"atl":[[6.4,0],[6.2,0.22]],"id":64851267}],"con":true,"img":false}]}
{"op":"mcm","clk":"11541111205","pt":1719502331610,"mc":[{"id":"1.230180126","rc":[{"atl":[[6.6,2]],"id":64851267}],"con":true,"img":false}]}
{"op":"mcm","clk":"11541111264","pt":1719502332537,"mc":[{"id":"1.230180126","rc":[{"atb":[[2.5,0]],"id":49823335},{"atb":[[2.54,0]],"id":61941224}],"con":true,"img":false}]}
{"op":"mcm","clk":"11541111389","pt":1719502334353,"mc":[{"id":"1.230180126","rc":[{"spn":3.26,"spf":1.0,"id":66993945},{"atl":[[6.4,0.84]],"id":64851267},{"spn":16.6,"spf":"NaN","id":69475504}],"con":true,"img":false}]}
{"op":"mcm","clk":"11541111559","pt":1719502336834,"mc":[{"id":"1.230180126","rc":[{"atl":[[6.6,0]],"id":64851267}],"con":true,"img":false}]}
{"op":"mcm","clk":"11541111598","pt":1719502337459,"mc":[{"id":"1.230180126","rc":[{"atl":[[6.4,0]],"id":64851267}],"con":true,"img":false}]}
{"op":"mcm","clk":"11541111692","pt":1719502338754,"mc":[{"id":"1.230180126","rc":[{"atl":[[6.6,2]],"id":64851267}],"con":true,"img":false}]}
{"op":"mcm","clk":"11541111815","pt":1719502340362,"mc":[{"id":"1.230180126","rc":[{"atl":[[1000,0.84]],"id":49823335},{"atl":[[1000,1.08]],"id":62886137}],"con":true,"img":false}]}
{"op":"mcm","clk":"11541111841","pt":1719502340629,"mc":[{"id":"1.230180126","rc":[{"atl":[[1000,0.27]],"id":49823335},{"atl":[[6,1.41]],"id":64851267}],"con":true,"img":false}]}
{"op":"mcm","clk":"11541111884","pt":1719502341046,"mc":[{"id":"1.230180126","rc":[{"atl":[[1000,0]],"id":49823335},{"atl":[[6.6,0]],"id":64851267},{"atl":[[1000,0.54]],"id":62886137}],"con":true,"img":false}]}
{"op":"mcm","clk":"11541111893","pt":1719502341149,"mc":[{"id":"1.230180126","rc":[{"atl":[[30,0.27]],"id":49823335}],"con":true,"img":false}]}
{"op":"mcm","clk":"11541111909","pt":1719502341357,"mc":[{"id":"1.230180126","rc":[{"atl":[[1000,0.84]],"id":69475504}],"con":true,"img":false}]}
{"op":"mcm","clk":"11541111916","pt":1719502341468,"mc":[{"id":"1.230180126","rc":[{"atl":[[1000,0.84]],"id":61941224}],"con":true,"img":false}]}
{"op":"mcm","clk":"11541111930","pt":1719502341644,"mc":[{"id":"1.230180126","rc":[{"atl":[[6.4,1.41]],"id":64851267}],"con":true,"img":false}]}
{"op":"mcm","clk":"11541111940","pt":1719502341730,"mc":[{"id":"1.230180126","rc":[{"atl":[[6.2,0.19],[6,0]],"id":64851267}],"con":true,"img":false}]}
{"op":"mcm","clk":"11541111947","pt":1719502341835,"mc":[{"id":"1.230180126","rc":[{"atl":[[5.9,0.03]],"id":64851267}],"con":true,"img":false}]}
{"op":"mcm","clk":"11541111964","pt":1719502342148,"mc":[{"id":"1.230180126","rc":[{"atl":[[1000,0.23]],"id":62886137}],"con":true,"img":false}]}
{"op":"mcm","clk":"11541111973","pt":1719502342252,"mc":[{"id":"1.230180126","rc":[{"atl":[[28,0.3]],"id":62886137}],"con":true,"img":false}]}
{"op":"mcm","clk":"11541111996","pt":1719502342566,"mc":[{"id":"1.230180126","rc":[{"atl":[[1000,0.3]],"id":61941224},{"atl":[[1000,0.32]],"id":69475504}],"con":true,"img":false}]}
{"op":"mcm","clk":"11541112018","pt":1719502342881,"mc":[{"id":"1.230180126","rc":[{"atl":[[6.4,0],[5.9,1.46]],"id":64851267}],"con":true,"img":false}]}
{"op":"mcm","clk":"11541112043","pt":1719502343263,"mc":[{"id":"1.230180126","rc":[{"atl":[[1000,0]],"id":69475504}],"con":true,"img":false}]}
{"op":"mcm","clk":"11541112052","pt":1719502343367,"mc":[{"id":"1.230180126","rc":[{"atl":[[26,0.32]],"id":69475504}],"con":true,"img":false}]}
{"op":"mcm","clk":"11541112075","pt":1719502343673,"mc":[{"id":"1.230180126","rc":[{"atl":[[1000,0]],"id":61941224}],"con":true,"img":false}]}
{"op":"mcm","clk":"11541112088","pt":1719502343777,"mc":[{"id":"1.230180126","rc":[{"atl":[[28,0.3]],"id":61941224}],"con":true,"img":false}]}
{"op":"mcm","clk":"11541112247","pt":1719502345562,"mc":[{"id":"1.230180126","rc":[{"atl":[[6.2,0]],"id":64851267}],"con":true,"img":false}]}
{"op":"mcm","clk":"11541112264","pt":1719502345772,"mc":[{"id":"1.230180126","rc":[{"atl":[[5.8,2],[1000,0.21]],"id":64851267}],"con":true,"img":false}]}
{"op":"mcm","clk":"11541112284","pt":1719502345933,"mc":[{"id":"1.230180126","rc":[{"atl":[[1000,0]],"id":64851267}],"con":true,"img":false}]}
{"op":"mcm","clk":"11541112292","pt":1719502346034,"mc":[{"id":"1.230180126","rc":[{"atl":[[5.8,2.21]],"id":64851267}],"con":true,"img":false}]}
{"op":"mcm","clk":"11541112313","pt":1719502346350,"mc":[{"id":"1.230180126","rc":[{"atl":[[5.7,0.84]],"id":64851267}],"con":true,"img":false}]}
{"op":"mcm","clk":"11541112347","pt":1719502346775,"mc":[{"id":"1.230180126","rc":[{"atl":[[5.9,1.43]],"id":64851267}],"con":true,"img":false}]}
{"op":"mcm","clk":"11541112357","pt":1719502346883,"mc":[{"id":"1.230180126","rc":[{"atl":[[5.7,0.87]],"id":64851267}],"con":true,"img":false}]}
{"op":"mcm","clk":"11541112678","pt":1719502350970,"mc":[{"id":"1.230180126","rc":[{"atb":[[2.82,0]],"id":66993945},{"atb":[[2.62,0]],"id":64851267},{"atl":[[5.8,0.21]],"id":64851267},{"atb":[[3.4,0]],"id":62886137},{"atb":[[3.2,0]],"id":69475504}],"con":true,"img":false}]}
{"op":"mcm","clk":"11541112696","pt":1719502351282,"mc":[{"id":"1.230180126","rc":[{"atl":[[5.7,0.03]],"id":64851267}],"con":true,"img":false}]}
{"op":"mcm","clk":"11541112718","pt":1719502351543,"mc":[{"id":"1.230180126","rc":[{"atl":[[5.9,0],[6.6,1.43]],"id":64851267}],"con":true,"img":false}]}
{"op":"mcm","clk":"11541112810","pt":1719502352964,"mc":[{"id":"1.230180126","rc":[{"atl":[[6.4,2]],"id":64851267}],"con":true,"img":false}]}
{"op":"mcm","clk":"11541112878","pt":1719502353858,"mc":[{"id":"1.230180126","rc":[{"atl":[[6.2,0.84]],"id":64851267}],"con":true,"img":false}]}
{"op":"mcm","clk":"11541113052","pt":1719502356348,"mc":[{"id":"1.230180126","rc":[{"atb":[[2.86,3.16]],"id":66993945}],"con":true,"img":false}]}
{"op":"mcm","clk":"11541113063","pt":1719502356457,"mc":[{"id":"1.230180126","rc":[{"atb":[[2.54,7.7]],"id":49823335}],"con":true,"img":false}]}
{"op":"mcm","clk":"11541113072","pt":1719502356561,"mc":[{"id":"1.230180126","rc":[{"atb":[[3.5,4.74]],"id":62886137}],"con":true,"img":false}]}
{"op":"mcm","clk":"11541113085","pt":1719502356768,"mc":[{"id":"1.230180126","rc":[{"atb":[[2.6,7.41]],"id":64851267},{"atb":[[2.58,7.5]],"id":61941224}],"con":true,"img":false}]}
{"op":"mcm","clk":"11541113095","pt":1719502356967,"mc":[{"id":"1.230180126","rc":[{"atb":[[2.78,6.66]],"id":66993945}],"con":true,"img":false}]}
{"op":"mcm","clk":"11541113105","pt":1719502357071,"mc":[{"id":"1.230180126","rc":[{"atb":[[3.3,5.15]],"id":69475504}],"con":true,"img":false}]}
{"op":"mcm","clk":"11541113202","pt":1719502358271,"mc":[{"id":"1.230180126","rc":[{"atl":[[6.4,0]],"id":64851267}],"con":true,"img":false}]}
{"op":"mcm","clk":"11541113247","pt":1719502358775,"mc":[{"id":"1.230180126","rc":[{"atl":[[6.2,0]],"id":64851267}],"con":true,"img":false}]}
{"op":"mcm","clk":"11541113318","pt":1719502359854,"mc":[{"id":"1.230180126","rc":[{"atb":[[2.84,6.9]],"id":66993945}],"con":true,"img":false}]}
{"op":"mcm","clk":"11541113357","pt":1719502360396,"mc":[{"id":"1.230180126","rc":[{"atl":[[6.4,2]],"id":64851267}],"con":true,"img":false}]}
{"op":"mcm","clk":"11541113445","pt":1719502361268,"mc":[{"id":"1.230180126","rc":[{"atl":[[5.8,0]],"id":64851267}],"con":true,"img":false}]}
{"op":"mcm","clk":"11541113453","pt":1719502361355,"mc":[{"id":"1.230180126","rc":[{"atl":[[6.2,0.84]],"id":64851267}],"con":true,"img":false}]}
{"op":"mcm","clk":"11541113460","pt":1719502361459,"mc":[{"id":"1.230180126","rc":[{"atl":[[1000,0.19]],"id":64851267}],"con":true,"img":false}]}
{"op":"mcm","clk":"11541113479","pt":1719502361678,"mc":[{"id":"1.230180126","rc":[{"atl":[[1000,0]],"id":64851267}],"con":true,"img":false}]}
{"op":"mcm","clk":"11541113486","pt":1719502361776,"mc":[{"id":"1.230180126","rc":[{"atl":[[6.4,2.19]],"id":64851267}],"con":true,"img":false}]}
{"op":"mcm","clk":"11541113728","pt":1719502365593,"mc":[{"id":"1.230180126","rc":[{"atl":[[6.4,0.19]],"id":64851267}],"con":true,"img":false}]}
{"op":"mcm","clk":"11541113793","pt":1719502366382,"mc":[{"id":"1.230180126","rc":[{"atl":[[6.2,0]],"id":64851267}],"con":true,"img":false}]}
{"op":"mcm","clk":"11541113865","pt":1719502367483,"mc":[{"id":"1.230180126","rc":[{"atl":[[6.4,2.19]],"id":64851267}],"con":true,"img":false}]}
{"op":"mcm","clk":"11541113936","pt":1719502368361,"mc":[{"id":"1.230180126","rc":[{"atl":[[6.2,0.84]],"id":64851267}],"con":true,"img":false}]}
{"op":"mcm","clk":"11541114286","pt":1719502372679,"mc":[{"id":"1.230180126","rc":[{"atl":[[6.4,0.19]],"id":64851267}],"con":true,"img":false}]}
{"op":"mcm","clk":"11541114343","pt":1719502373408,"mc":[{"id":"1.230180126","rc":[{"atl":[[6.2,0]],"id":64851267}],"con":true,"img":false}]}
{"op":"mcm","clk":"11541114447","pt":1719502374600,"mc":[{"id":"1.230180126","rc":[{"atl":[[6.4,2.19]],"id":64851267}],"con":true,"img":false}]}
{"op":"mcm","clk":"11541114456","pt":1719502374701,"mc":[{"id":"1.230180126","rc":[{"spl":[[1.01,11]],"id":64851267}],"con":true,"img":false}]}
{"op":"mcm","clk":"11541114540","pt":1719502375683,"mc":[{"id":"1.230180126","rc":[{"atl":[[6.2,0.84]],"id":64851267}],"con":true,"img":false}]}
{"op":"mcm","clk":"11541114629","pt":1719502377084,"mc":[{"id":"1.230180126","rc":[{"atl":[[6.4,2]],"id":64851267}],"con":true,"img":false}]}
{"op":"mcm","clk":"11541114690","pt":1719502377290,"mc":[{"id":"1.230180126","rc":[{"atl":[[1000,0.19]],"id":64851267}],"con":true,"img":false}]}
{"op":"mcm","clk":"11541114699","pt":1719502377387,"mc":[{"id":"1.230180126","rc":[{"atl":[[1000,0]],"id":64851267}],"con":true,"img":false}]}
{"op":"mcm","clk":"11541114708","pt":1719502377492,"mc":[{"id":"1.230180126","rc":[{"atl":[[6.2,1.03]],"id":64851267}],"con":true,"img":false}]}
{"op":"mcm","clk":"11541114857","pt":1719502379805,"mc":[{"id":"1.230180126","rc":[{"atl":[[6.4,0]],"id":64851267}],"con":true,"img":false}]}
{"op":"mcm","clk":"11541114890","pt":1719502380284,"mc":[{"id":"1.230180126","rc":[{"atl":[[6.2,0.19]],"id":64851267}],"con":true,"img":false}]}
{"op":"mcm","clk":"11541115015","pt":1719502381886,"mc":[{"id":"1.230180126","rc":[{"atl":[[6.4,2]],"id":64851267}],"con":true,"img":false}]}
{"op":"mcm","clk":"11541115043","pt":1719502382406,"mc":[{"id":"1.230180126","rc":[{"atb":[[5.7,0]],"id":62886137}],"con":true,"img":false}]}
{"op":"mcm","clk":"11541115069","pt":1719502382707,"mc":[{"id":"1.230180126","rc":[{"atl":[[6.2,1.03]],"id":64851267}],"con":true,"img":false}]}
{"op":"mcm","clk":"11541115091","pt":1719502382973,"mc":[{"id":"1.230180126","rc":[{"atb":[[5.7,0]],"id":49823335}],"con":true,"img":false}]}
{"op":"mcm","clk":"11541115103","pt":1719502383180,"mc":[{"id":"1.230180126","rc":[{"atl":[[6.4,0]],"id":64851267}],"con":true,"img":false}]}
{"op":"mcm","clk":"11541115113","pt":1719502383285,"mc":[{"id":"1.230180126","rc":[{"atb":[[3.45,0]],"id":64851267}],"con":true,"img":false}]}
{"op":"mcm","clk":"11541115129","pt":1719502383510,"mc":[{"id":"1.230180126","rc":[{"atb":[[6.2,0.84]],"id":69475504}],"con":true,"img":false}]}
{"op":"mcm","clk":"11541115137","pt":1719502383594,"mc":[{"id":"1.230180126","rc":[{"atb":[[1.14,1.69]],"id":62886137}],"con":true,"img":false}]}
{"op":"mcm","clk":"11541115145","pt":1719502383698,"mc":[{"id":"1.230180126","rc":[{"atb":[[1.08,1.69]],"id":64851267}],"con":true,"img":false}]}
{"op":"mcm","clk":"11541115158","pt":1719502383898,"mc":[{"id":"1.230180126","rc":[{"atb":[[1.14,1.69]],"id":49823335},{"atl":[[6.2,0.19]],"id":64851267}],"con":true,"img":false}]}
{"op":"mcm","clk":"11541115170","pt":1719502384109,"mc":[{"id":"1.230180126","rc":[{"atl":[[1000,1.94]],"id":66993945},{"atl":[[1000,1.7]],"id":49823335},{"atb":[[1.08,0.08]],"id":64851267},{"atb":[[1.04,1.7]],"id":62886137},{"atl":[[1000,1.94]],"id":62886137}],"con":true,"img":false}]}
{"op":"mcm","clk":"11541115226","pt":1719502384208,"mc":[{"id":"1.230180126","rc":[{"atb":[[1.02,3.7]],"id":66993945},{"atb":[[1.04,78.75]],"id":49823335},{"atb":[[1.14,0.05]],"id":62886137}],"con":true,"img":false}]}
{"op":"mcm","clk":"11541115242","pt":1719502384413,"mc":[{"id":"1.230180126","rc":[{"atl":[[1000,0.25]],"id":66993945},{"atl":[[1000,0]],"id":49823335},{"atb":[[1.04,0.06]],"id":62886137},{"atl":[[1000,0.24]],"id":62886137}],"con":true,"img":false}]}
{"op":"mcm","clk":"11541115248","pt":1719502384518,"mc":[{"id":"1.230180126","rc":[{"atb":[[3.95,0],[1.02,2.13]],"id":66993945},{"atb":[[1.04,77.11]],"id":49823335},{"atb":[[1.14,1.69]],"id":69475504}],"con":true,"img":false}]}
{"op":"mcm","clk":"11541115254","pt":1719502384571,"mc":[{"id":"1.230180126","rc":[{"atl":[[1000,0.23]],"id":66993945},{"atl":[[1000,0]],"id":49823335},{"atb":[[1.04,0]],"id":62886137},{"atl":[[1000,0.23]],"id":62886137}],"con":true,"img":false}]}
{"op":"mcm","clk":"11541115262","pt":1719502385033,"mc":[{"id":"1.230180126","rc":[{"atb":[[1.02,2]],"id":66993945},{"atl":[[23,0.01]],"id":66993945},{"atb":[[1.04,77.05]],"id":49823335},{"atl":[[32,0.85]],"id":49823335},{"atb":[[5.6,0.91]],"id":62886137},{"atl":[[29,0.85]],"id":62886137}],"con":true,"img":false}]}
{"op":"mcm","clk":"11541115269","pt":1719502385050,"mc":[{"id":"1.230180126","rc":[{"atb":[[3.15,0.13]],"id":66993945},{"atb":[[5.6,0.91]],"id":49823335}],"con":true,"img":false}]}
{"op":"mcm","clk":"11541115275","pt":1719502385062,"mc":[{"id":"1.230180126","rc":[{"atb":[[1.14,0.05]],"id":49823335},{"atb":[[1.08,0]],"id":64851267}],"con":true,"img":false}]}
{"op":"mcm","clk":"11541115281","pt":1719502385071,"mc":[{"id":"1.230180126","rc":[{"atb":[[3.45,0.08]],"id":64851267}],"con":true,"img":false}]}
{"op":"mcm","clk":"11541115305","pt":1719502385300,"mc":[{"id":"1.230180126","rc":[{"atb":[[1.14,0]],"id":62886137}],"con":true,"img":false}]}
{"op":"mcm","clk":"11541115313","pt":1719502385402,"mc":[{"id":"1.230180126","rc":[{"atb":[[5.6,0.96]],"id":62886137}],"con":true,"img":false}]}
{"op":"mcm","clk":"11541115346","pt":1719502385809,"mc":[{"id":"1.230180126","rc":[{"atb":[[1.09,1.69]],"id":66993945},{"atb":[[1.14,0.05]],"id":69475504}],"con":true,"img":false}]}
{"op":"mcm","clk":"11541115371","pt":1719502386120,"mc":[{"id":"1.230180126","rc":[{"atb":[[1.14,0]],"id":49823335}],"con":true,"img":false}]}
{"op":"mcm","clk":"11541115380","pt":1719502386176,"mc":[{"id":"1.230180126","rc":[{"atb":[[5.6,0.96]],"id":49823335}],"con":true,"img":false}]}
{"op":"mcm","clk":"11541115388","pt":1719502386281,"mc":[{"id":"1.230180126","rc":[{"atb":[[7.2,0]],"id":61941224}],"con":true,"img":false}]}
{"op":"mcm","clk":"11541115408","pt":1719502386591,"mc":[{"id":"1.230180126","rc":[{"atb":[[1.14,0]],"id":69475504}],"con":true,"img":false}]}
{"op":"mcm","clk":"11541115421","pt":1719502386739,"mc":[{"id":"1.230180126","rc":[{"atb":[[6.2,0.89]],"id":69475504}],"con":true,"img":false}]}
{"op":"mcm","clk":"11541115445","pt":1719502387031,"mc":[{"id":"1.230180126","rc":[{"atb":[[1.09,0.07]],"id":66993945},{"atb":[[1.16,151.69]],"id":61941224}],"con":true,"img":false}]}
{"op":"mcm","clk":"11541115507","pt":1719502387208,"mc":[{"id":"1.230180126","rc":[{"atb":[[2.84,0]],"id":66993945},{"atb":[[2.52,0]],"id":49823335},{"atb":[[2.64,0]],"id":64851267},{"atb":[[3.45,0]],"id":62886137},{"atb":[[2.56,0]],"id":61941224},{"atb":[[3.25,0]],"id":69475504}],"con":true,"img":false}]}
{"op":"mcm","clk":"11541115534","pt":1719502387517,"mc":[{"id":"1.230180126","rc":[{"atb":[[1.09,0]],"id":66993945}],"con":true,"img":false}]}
{"op":"mcm","clk":"11541115541","pt":1719502387623,"mc":[{"id":"1.230180126","rc":[{"atb":[[3.95,0.07]],"id":66993945}],"con":true,"img":false}]}
{"op":"mcm","clk":"11541115581","pt":1719502387987,"mc":[{"id":"1.230180126","rc":[{"atb":[[1.16,150.04]],"id":61941224}],"con":true,"img":false}]}
{"op":"mcm","clk":"11541115601","pt":1719502388296,"mc":[{"id":"1.230180126","rc":[{"atb":[[1.16,150]],"id":61941224}],"con":true,"img":false}]}
{"op":"mcm","clk":"11541115609","pt":1719502388401,"mc":[{"id":"1.230180126","rc":[{"atb":[[7.2,0.04]],"id":61941224}],"con":true,"img":false}]}
{"op":"mcm","clk":"11541115649","pt":1719502389012,"mc":[{"id":"1.230180126","rc":[{"atl":[[6.4,2]],"id":64851267}],"con":true,"img":false}]}
{"op":"mcm","clk":"11541115702","pt":1719502389693,"mc":[{"id":"1.230180126","rc":[{"atl":[[6.2,1.03]],"id":64851267}],"con":true,"img":false}]}
{"op":"mcm","clk":"11541115734","pt":1719502390211,"mc":[{"id":"1.230180126","rc":[{"atl":[[6.4,0]],"id":64851267}],"con":true,"img":false}]}
{"op":"mcm","clk":"11541115744","pt":1719502390316,"mc":[{"id":"1.230180126","rc":[{"atb":[[2.86,0]],"id":66993945}],"con":true,"img":false}]}
{"op":"mcm","clk":"11541115782","pt":1719502390820,"mc":[{"id":"1.230180126","rc":[{"atl":[[6.2,0.19]],"id":64851267}],"con":true,"img":false}]}
{"op":"mcm","clk":"11541115869","pt":1719502392318,"mc":[{"id":"1.230180126","rc":[{"atb":[[3.35,5.4]],"id":62886137}],"con":true,"img":false}]}
{"op":"mcm","clk":"11541115875","pt":1719502392426,"mc":[{"id":"1.230180126","rc":[{"atb":[[2.8,3.38]],"id":66993945}],"con":true,"img":false}]}
{"op":"mcm","clk":"11541115898","pt":1719502392687,"mc":[{"id":"1.230180126","rc":[{"atb":[[2.62,7.84]],"id":64851267},{"atl":[[6.2,0]],"id":64851267}],"con":true,"img":false}]}
{"op":"mcm","clk":"11541115904","pt":1719502392784,"mc":[{"id":"1.230180126","rc":[{"atb":[[2.8,10.44]],"id":66993945}],"con":true,"img":false}]}
{"op":"mcm","clk":"11541115916","pt":1719502392992,"mc":[{"id":"1.230180126","rc":[{"atl":[[1000,0.19]],"id":64851267},{"atb":[[2.6,7.94]],"id":61941224}],"con":true,"img":false}]}
{"op":"mcm","clk":"11541115924","pt":1719502393096,"mc":[{"id":"1.230180126","rc":[{"atl":[[1000,0]],"id":64851267}],"con":true,"img":false}]}
{"op":"mcm","clk":"11541115932","pt":1719502393207,"mc":[{"id":"1.230180126","rc":[{"atl":[[6.4,0.19]],"id":64851267}],"con":true,"img":false}]}
{"op":"mcm","clk":"11541115944","pt":1719502393306,"mc":[{"id":"1.230180126","rc":[{"atb":[[2.56,8.14]],"id":49823335},{"atb":[[3.35,5.4]],"id":69475504}],"con":true,"img":false}]}
{"op":"mcm","clk":"11541116117","pt":1719502395993,"mc":[{"id":"1.230180126","rc":[{"spn":3.27,"spf":1.0,"id":66993945},{"spn":17.8,"spf":"NaN","id":49823335},{"atl":[[6.4,2.19]],"id":64851267},{"spn":3.02,"spf":1.0,"id":64851267},{"spn":16.8,"spf":"NaN","id":62886137},{"spn":17.6,"spf":"NaN","id":61941224},{"spn":16.1,"spf":"NaN","id":69475504}],"con":true,"img":false}]}
{"op":"mcm","clk":"11541116168","pt":1719502396824,"mc":[{"id":"1.230180126","rc":[{"atl":[[6.2,0.84]],"id":64851267}],"con":true,"img":false}]}
{"op":"mcm","clk":"11541116515","pt":1719502401316,"mc":[{"id":"1.230180126","rc":[{"atl":[[6.4,0.19]],"id":64851267}],"con":true,"img":false}]}
{"op":"mcm","clk":"11541116536","pt":1719502401727,"mc":[{"id":"1.230180126","rc":[{"atl":[[6.2,0]],"id":64851267}],"con":true,"img":false}]}
{"op":"mcm","clk":"11541116670","pt":1719502403525,"mc":[{"id":"1.230180126","rc":[{"atb":[[2.98,7.54]],"id":64851267},{"atl":[[6.4,2.19],[7.8,3],[7,0]],"id":64851267},{"atl":[[34,3.03]],"id":61941224}],"con":true,"img":false}]}
{"op":"mcm","clk":"11541116673","pt":1719502403634,"mc":[{"id":"1.230180126","rc":[{"atl":[[30,1.54]],"id":61941224}],"con":true,"img":false}]}
{"op":"mcm","clk":"11541116693","pt":1719502403950,"mc":[{"id":"1.230180126","rc":[{"atl":[[1000,0.84]],"id":61941224}],"con":true,"img":false}]}
{"op":"mcm","clk":"11541116703","pt":1719502404001,"mc":[{"id":"1.230180126","rc":[{"atl":[[28,0]],"id":61941224}],"con":true,"img":false}]}
{"op":"mcm","clk":"11541116714","pt":1719502404312,"mc":[{"id":"1.230180126","rc":[{"atl":[[6.2,0.84]],"id":64851267},{"atl":[[1000,0.3]],"id":61941224}],"con":true,"img":false}]}
{"op":"mcm","clk":"11541116736","pt":1719502404618,"mc":[{"id":"1.230180126","rc":[{"atl":[[1000,0]],"id":61941224}],"con":true,"img":false}]}
{"op":"mcm","clk":"11541116743","pt":1719502404723,"mc":[{"id":"1.230180126","rc":[{"atl":[[29,1.15]],"id":61941224}],"con":true,"img":false}]}
{"op":"mcm","clk":"11541117013","pt":1719502408433,"mc":[{"id":"1.230180126","rc":[{"atl":[[6.4,2]],"id":64851267}],"con":true,"img":false}]}
{"op":"mcm","clk":"11541117023","pt":1719502408632,"mc":[{"id":"1.230180126","rc":[{"atl":[[1000,0.19]],"id":64851267}],"con":true,"img":false}]}
{"op":"mcm","clk":"11541117030","pt":1719502408841,"mc":[{"id":"1.230180126","rc":[{"atl":[[6.4,0],[1000,0]],"id":64851267}],"con":true,"img":false}]}
{"op":"mcm","clk":"11541117037","pt":1719502408944,"mc":[{"id":"1.230180126","rc":[{"atl":[[6.2,1.03]],"id":64851267}],"con":true,"img":false}]}
{"op":"mcm","clk":"11541117076","pt":1719502409419,"mc":[{"id":"1.230180126","rc":[{"atl":[[6.2,0.19]],"id":64851267}],"con":true,"img":false}]}
{"op":"mcm","clk":"11541117156","pt":1719502410648,"mc":[{"id":"1.230180126","rc":[{"atl":[[6.4,2]],"id":64851267}],"con":true,"img":false}]}
{"op":"mcm","clk":"11541117211","pt":1719502411328,"mc":[{"id":"1.230180126","rc":[{"atl":[[6.2,1.03]],"id":64851267}],"con":true,"img":false}]}
{"op":"mcm","clk":"11541117247","pt":1719502411835,"mc":[{"id":"1.230180126","rc":[{"atl":[[6.4,0]],"id":64851267}],"con":true,"img":false}]}
{"op":"mcm","clk":"11541117290","pt":1719502412364,"mc":[{"id":"1.230180126","rc":[{"atl":[[6.2,0.19]],"id":64851267}],"con":true,"img":false}]}
{"op":"mcm","clk":"11541117688","pt":1719502417732,"mc":[{"id":"1.230180126","rc":[{"atl":[[6.4,2]],"id":64851267}],"con":true,"img":false}]}
{"op":"mcm","clk":"11541117764","pt":1719502418820,"mc":[{"id":"1.230180126","rc":[{"atl":[[6.2,1.03]],"id":64851267}],"con":true,"img":false}]}
{"op":"mcm","clk":"11541117838","pt":1719502420062,"mc":[{"id":"1.230180126","rc":[{"atb":[[2.54,0]],"id":49823335},{"atb":[[3.5,0]],"id":62886137},{"atb":[[2.58,0]],"id":61941224},{"atb":[[3.3,0]],"id":69475504}],"con":true,"img":false}]}
{"op":"mcm","clk":"11541117861","pt":1719502420324,"mc":[{"id":"1.230180126","rc":[{"atb":[[3.15,0]],"id":66993945},{"atl":[[23,0]],"id":66993945},{"atb":[[5.6,0.89]],"id":49823335},{"atl":[[32,0.84]],"id":49823335},{"atb":[[5.6,0.89]],"id":62886137},{"atl":[[29,0.84]],"id":62886137}],"con":true,"img":false}]}
{"op":"mcm","clk":"11541118021","pt":1719502423050,"mc":[{"id":"1.230180126","rc":[{"atl":[[6.4,0]],"id":64851267}],"con":true,"img":false}]}
{"op":"mcm","clk":"11541118096","pt":1719502423876,"mc":[{"id":"1.230180126","rc":[{"atl":[[6.2,0.19]],"id":64851267}],"con":true,"img":false}]}
{"op":"mcm","clk":"11541118126","pt":1719502424136,"mc":[{"id":"1.230180126","rc":[{"atl":[[6.2,0]],"id":64851267}],"con":true,"img":false}]}
{"op":"mcm","clk":"11541118144","pt":1719502424450,"mc":[{"id":"1.230180126","rc":[{"atl":[[1000,0.2]],"id":64851267}],"con":true,"img":false}]}
{"op":"mcm","clk":"11541118151","pt":1719502424552,"mc":[{"id":"1.230180126","rc":[{"atl":[[1000,0]],"id":64851267}],"con":true,"img":false}]}
{"op":"mcm","clk":"11541118159","pt":1719502424652,"mc":[{"id":"1.230180126","rc":[{"atl":[[6,0.2]],"id":64851267}],"con":true,"img":false}]}
{"op":"mcm","clk":"11541118196","pt":1719502425068,"mc":[{"id":"1.230180126","rc":[{"atl":[[6.4,2]],"id":64851267}],"con":true,"img":false}]}
{"op":"mcm","clk":"11541118251","pt":1719502425553,"mc":[{"id":"1.230180126","rc":[{"atb":[[2.58,7.5]],"id":49823335}],"con":true,"img":false}]}
{"op":"mcm","clk":"11541118258","pt":1719502425650,"mc":[{"id":"1.230180126","rc":[{"atb":[[3.4,4.94]],"id":69475504}],"con":true,"img":false}]}
{"op":"mcm","clk":"11541118264","pt":1719502425753,"mc":[{"id":"1.230180126","rc":[{"atb":[[2.62,7.32]],"id":61941224}],"con":true,"img":false}]}
{"op":"mcm","clk":"11541118272","pt":1719502425861,"mc":[{"id":"1.230180126","rc":[{"atb":[[2.82,3.16]],"id":66993945}],"con":true,"img":false}]}
{"op":"mcm","clk":"11541118281","pt":1719502425961,"mc":[{"id":"1.230180126","rc":[{"atb":[[3.4,4.94]],"id":62886137}],"con":true,"img":false}]}
{"op":"mcm","clk":"11541118306","pt":1719502426381,"mc":[{"id":"1.230180126","rc":[{"atb":[[3.15,0.79]],"id":66993945},{"atb":[[5.6,1.76]],"id":49823335},{"atb":[[3.1,1.79]],"id":64851267},{"atl":[[6.2,0.84]],"id":64851267},{"atb":[[5.6,1.76]],"id":62886137},{"atb":[[4.7,3.07]],"id":69475504}],"con":true,"img":false}]}
{"op":"mcm","clk":"11541118342","pt":1719502426839,"mc":[{"id":"1.230180126","rc":[{"atl":[[6.4,0]],"id":64851267}],"con":true,"img":false}]}
{"op":"mcm","clk":"11541118384","pt":1719502427357,"mc":[{"id":"1.230180126","rc":[{"atl":[[6.2,0]],"id":64851267}],"con":true,"img":false}]}
{"op":"mcm","clk":"11541118782","pt":1719502432174,"mc":[{"id":"1.230180126","rc":[{"atl":[[6.4,2]],"id":64851267}],"con":true,"img":false}]}
{"op":"mcm","clk":"11541118901","pt":1719502433739,"mc":[{"id":"1.230180126","rc":[{"atl":[[6.2,0.84]],"id":64851267}],"con":true,"img":false}]}
{"op":"mcm","clk":"11541119191","pt":1719502437361,"mc":[{"id":"1.230180126","rc":[{"atb":[[2.78,0]],"id":66993945},{"atb":[[2.6,0]],"id":64851267},{"atl":[[6.4,0]],"id":64851267}],"con":true,"img":false}]}
{"op":"mcm","clk":"11541119243","pt":1719502437864,"mc":[{"id":"1.230180126","rc":[{"atl":[[6.2,0]],"id":64851267}],"con":true,"img":false}]}
{"op":"mcm","clk":"11541119360","pt":1719502439264,"mc":[{"id":"1.230180126","rc":[{"atl":[[6.4,2]],"id":64851267}],"con":true,"img":false}]}
{"op":"mcm","clk":"11541119411","pt":1719502439882,"mc":[{"id":"1.230180126","rc":[{"atl":[[6,0]],"id":64851267}],"con":true,"img":false}]}
{"op":"mcm","clk":"11541119433","pt":1719502440046,"mc":[{"id":"1.230180126","rc":[{"atl":[[1000,0.19]],"id":64851267}],"con":true,"img":false}]}
{"op":"mcm","clk":"11541119456","pt":1719502440363,"mc":[{"id":"1.230180126","rc":[{"atl":[[1000,0]],"id":64851267}],"con":true,"img":false}]}
{"op":"mcm","clk":"11541119467","pt":1719502440466,"mc":[{"id":"1.230180126","rc":[{"atl":[[6.4,2.19]],"id":64851267}],"con":true,"img":false}]}
{"op":"mcm","clk":"11541119481","pt":1719502440669,"mc":[{"id":"1.230180126","rc":[{"atl":[[40,1]],"id":66993945},{"atl":[[55,1]],"id":49823335},{"atb":[[5.2,1]],"id":61941224},{"atb":[[4.3,1]],"id":69475504}],"con":true,"img":false}]}
{"op":"mcm","clk":"11541119496","pt":1719502440869,"mc":[{"id":"1.230180126","rc":[{"atl":[[6.2,0.84]],"id":64851267}],"con":true,"img":false}]}
{"op":"mcm","clk":"11541119550","pt":1719502441471,"mc":[{"id":"1.230180126","rc":[{"atb":[[1.01,1]],"id":62886137}],"con":true,"img":false}]}
{"op":"mcm","clk":"11541119602","pt":1719502442073,"mc":[{"id":"1.230180126","rc":[{"atb":[[2.98,6.54]],"id":64851267}],"con":true,"img":false}]}
{"op":"mcm","clk":"11541119642","pt":1719502442587,"mc":[{"id":"1.230180126","rc":[{"atb":[[2.64,7.23]],"id":64851267}],"con":true,"img":false}]}
{"op":"mcm","clk":"11541119658","pt":1719502442760,"mc":[{"id":"1.230180126","rc":[{"atb":[[2.82,9.67]],"id":66993945}],"con":true,"img":false}]}
{"op":"mcm","clk":"11541119825","pt":1719502444564,"mc":[{"id":"1.230180126","rc":[{"atl":[[6.4,0.19]],"id":64851267}],"con":true,"img":false}]}
{"op":"mcm","clk":"11541119882","pt":1719502445382,"mc":[{"id":"1.230180126","rc":[{"atl":[[6.2,0]],"id":64851267}],"con":true,"img":false}]}
{"op":"mcm","clk":"11541119963","pt":1719502446380,"mc":[{"id":"1.230180126","rc":[{"atl":[[6.4,2.19]],"id":64851267}],"con":true,"img":false}]}
{"op":"mcm","clk":"11541120125","pt":1719502448353,"mc":[{"id":"1.230180126","rc":[{"atl":[[6.2,0.84]],"id":64851267}],"con":true,"img":false}]}
{"op":"mcm","clk":"11541120162","pt":1719502448768,"mc":[{"id":"1.230180126","rc":[{"atb":[[1.25,20]],"id":66993945},{"atb":[[1.25,20]],"id":49823335},{"atb":[[1.25,20]],"id":64851267},{"atb":[[1.25,20]],"id":62886137},{"atb":[[1.25,20]],"id":61941224},{"atb":[[1.25,20]],"id":69475504}],"con":true,"img":false}]}
{"op":"mcm","clk":"11541120242","pt":1719502449649,"mc":[{"id":"1.230180126","rc":[{"atb":[[3.1,1]],"id":64851267}],"con":true,"img":false}]}
{"op":"mcm","clk":"11541120390","pt":1719502451692,"mc":[{"id":"1.230180126","rc":[{"atl":[[6.4,0.19]],"id":64851267}],"con":true,"img":false}]}
{"op":"mcm","clk":"11541120448","pt":1719502452475,"mc":[{"id":"1.230180126","rc":[{"atl":[[6.2,0]],"id":64851267}],"con":true,"img":false}]}
{"op":"mcm","clk":"11541120511","pt":1719502453454,"mc":[{"id":"1.230180126","rc":[{"atl":[[6.4,2.19]],"id":64851267}],"con":true,"img":false}]}
{"op":"mcm","clk":"11541120662","pt":1719502455369,"mc":[{"id":"1.230180126","rc":[{"atl":[[6.2,0.84]],"id":64851267}],"con":true,"img":false}]}
{"op":"mcm","clk":"11541120682","pt":1719502455680,"mc":[{"id":"1.230180126","rc":[{"atl":[[6.4,2]],"id":64851267}],"con":true,"img":false}]}
{"op":"mcm","clk":"11541120698","pt":1719502455884,"mc":[{"id":"1.230180126","rc":[{"atl":[[1000,0.19]],"id":64851267}],"con":true,"img":false}]}
{"op":"mcm","clk":"11541120708","pt":1719502456090,"mc":[{"id":"1.230180126","rc":[{"spn":3.29,"spf":1.0,"id":66993945},{"atl":[[1000,0]],"id":64851267},{"spn":18.1,"spf":"NaN","id":61941224}],"con":true,"img":false}]}
{"op":"mcm","clk":"11541120718","pt":1719502456191,"mc":[{"id":"1.230180126","rc":[{"atl":[[6.2,1.03]],"id":64851267}],"con":true,"img":false}]}
{"op":"mcm","clk":"11541120840","pt":1719502457859,"mc":[{"id":"1.230180126","rc":[{"atb":[[2.8,3.38]],"id":66993945},{"atb":[[2.56,0]],"id":49823335},{"atb":[[3.35,0]],"id":62886137},{"atb":[[2.6,0]],"id":61941224},{"atb":[[3.35,0]],"id":69475504}],"con":true,"img":false}]}
{"op":"mcm","clk":"11541120896","pt":1719502458688,"mc":[{"id":"1.230180126","rc":[{"atl":[[6.4,0]],"id":64851267}],"con":true,"img":false}]}
{"op":"mcm","clk":"11541120949","pt":1719502459414,"mc":[{"id":"1.230180126","rc":[{"atl":[[6.2,0.19]],"id":64851267}],"con":true,"img":false}]}
{"op":"mcm","clk":"11541121020","pt":1719502460488,"mc":[{"id":"1.230180126","rc":[{"atl":[[6.4,2]],"id":64851267}],"con":true,"img":false}]}
{"op":"mcm","clk":"11541121134","pt":1719502462305,"mc":[{"id":"1.230180126","rc":[{"atb":[[2.82,6.51]],"id":66993945}],"con":true,"img":false}]}
{"op":"mcm","clk":"11541121169","pt":1719502462773,"mc":[{"id":"1.230180126","rc":[{"atl":[[6.2,1.03]],"id":64851267}],"con":true,"img":false}]}
{"op":"mcm","clk":"11541121352","pt":1719502464994,"mc":[{"id":"1.230180126","rc":[{"atb":[[5.1,8.82]],"id":61941224}],"con":true,"img":false}]}
{"op":"mcm","clk":"11541121408","pt":1719502465771,"mc":[{"id":"1.230180126","rc":[{"atl":[[6.4,0]],"id":64851267}],"con":true,"img":false}]}
{"op":"mcm","clk":"11541121446","pt":1719502466390,"mc":[{"id":"1.230180126","rc":[{"atl":[[6.2,0.19]],"id":64851267}],"con":true,"img":false}]}
{"op":"mcm","clk":"11541121543","pt":1719502467693,"mc":[{"id":"1.230180126","rc":[{"atl":[[6.4,2]],"id":64851267}],"con":true,"img":false}]}
{"op":"mcm","clk":"11541121613","pt":1719502468667,"mc":[{"id":"1.230180126","rc":[{"atb":[[2.8,0]],"id":66993945}],"con":true,"img":false}]}
{"op":"mcm","clk":"11541121617","pt":1719502468775,"mc":[{"id":"1.230180126","rc":[{"atb":[[3.45,5.18]],"id":62886137}],"con":true,"img":false}]}
{"op":"mcm","clk":"11541121628","pt":1719502468978,"mc":[{"id":"1.230180126","rc":[{"atb":[[2.6,7.94]],"id":49823335}],"con":true,"img":false}]}
{"op":"mcm","clk":"11541121636","pt":1719502469082,"mc":[{"id":"1.230180126","rc":[{"atb":[[2.84,6.9]],"id":66993945}],"con":true,"img":false}]}
{"op":"mcm","clk":"11541121649","pt":1719502469283,"mc":[{"id":"1.230180126","rc":[{"atb":[[3.45,5.18]],"id":69475504}],"con":true,"img":false}]}
{"op":"mcm","clk":"11541121677","pt":1719502469592,"mc":[{"id":"1.230180126","rc":[{"atb":[[2.84,10.28]],"id":66993945},{"atb":[[2.64,7.74]],"id":61941224}],"con":true,"img":false}]}
{"op":"mcm","clk":"11541121736","pt":1719502470276,"mc":[{"id":"1.230180126","rc":[{"atl":[[6.2,1.03]],"id":64851267}],"con":true,"img":false}]}
{"op":"mcm","clk":"11541121808","pt":1719502471512,"mc":[{"id":"1.230180126","rc":[{"atl":[[6.2,0.84]],"id":64851267}],"con":true,"img":false}]}
{"op":"mcm","clk":"11541121828","pt":1719502471714,"mc":[{"id":"1.230180126","rc":[{"atl":[[1000,0.2]],"id":64851267}],"con":true,"img":false}]}
{"op":"mcm","clk":"11541121845","pt":1719502471982,"mc":[{"id":"1.230180126","rc":[{"atl":[[1000,0]],"id":64851267}],"con":true,"img":false}]}
{"op":"mcm","clk":"11541121851","pt":1719502472076,"mc":[{"id":"1.230180126","rc":[{"atl":[[6,0.2]],"id":64851267}],"con":true,"img":false}]}
{"op":"mcm","clk":"11541121908","pt":1719502472907,"mc":[{"id":"1.230180126","rc":[{"atl":[[6.4,0]],"id":64851267}],"con":true,"img":false}]}
{"op":"mcm","clk":"11541121954","pt":1719502473370,"mc":[{"id":"1.230180126","rc":[{"atl":[[6.2,0]],"id":64851267}],"con":true,"img":false}]}
{"op":"mcm","clk":"11541122050","pt":1719502474813,"mc":[{"id":"1.230180126","rc":[{"atl":[[6.4,2]],"id":64851267}],"con":true,"img":false}]}
{"op":"mcm","clk":"11541122247","pt":1719502477292,"mc":[{"id":"1.230180126","rc":[{"atl":[[6.2,0.84]],"id":64851267}],"con":true,"img":false}]}
{"op":"mcm","clk":"11541122437","pt":1719502480078,"mc":[{"id":"1.230180126","rc":[{"atl":[[6.4,0]],"id":64851267}],"con":true,"img":false}]}
{"op":"mcm","clk":"11541122504","pt":1719502481004,"mc":[{"id":"1.230180126","rc":[{"atl":[[6.2,0]],"id":64851267}],"con":true,"img":false}]}
{"op":"mcm","clk":"11541122592","pt":1719502481986,"mc":[{"id":"1.230180126","rc":[{"atl":[[6.4,2]],"id":64851267}],"con":true,"img":false}]}
{"op":"mcm","clk":"11541122802","pt":1719502484823,"mc":[{"id":"1.230180126","rc":[{"atl":[[6.2,0.84]],"id":64851267}],"con":true,"img":false}]}
{"op":"mcm","clk":"11541122968","pt":1719502487200,"mc":[{"id":"1.230180126","rc":[{"atl":[[6.4,0]],"id":64851267}],"con":true,"img":false}]}
{"op":"mcm","clk":"11541122977","pt":1719502487302,"mc":[{"id":"1.230180126","rc":[{"atl":[[6,0]],"id":64851267}],"con":true,"img":false}]}
{"op":"mcm","clk":"11541122991","pt":1719502487511,"mc":[{"id":"1.230180126","rc":[{"atl":[[1000,0.2]],"id":64851267}],"con":true,"img":false}]}
{"op":"mcm","clk":"11541123005","pt":1719502487721,"mc":[{"id":"1.230180126","rc":[{"atl":[[1000,0]],"id":64851267}],"con":true,"img":false}]}
{"op":"mcm","clk":"11541123011","pt":1719502487819,"mc":[{"id":"1.230180126","rc":[{"atl":[[6.2,0],[6,0.2]],"id":64851267}],"con":true,"img":false}]}
{"op":"mcm","clk":"11541123125","pt":1719502489314,"mc":[{"id":"1.230180126","rc":[{"atl":[[6.4,2]],"id":64851267}],"con":true,"img":false}]}
{"op":"mcm","clk":"11541123195","pt":1719502490199,"mc":[{"id":"1.230180126","rc":[{"atb":[[2.62,0]],"id":64851267}],"con":true,"img":false}]}
{"op":"mcm","clk":"11541123358","pt":1719502492315,"mc":[{"id":"1.230180126","rc":[{"atl":[[6.2,0.84]],"id":64851267}],"con":true,"img":false}]}
{"op":"mcm","clk":"11541123377","pt":1719502492524,"mc":[{"id":"1.230180126","rc":[{"atb":[[2.82,0]],"id":66993945},{"atb":[[2.58,0]],"id":49823335},{"atb":[[3.4,0]],"id":62886137},{"atb":[[2.62,0]],"id":61941224},{"atb":[[3.4,0]],"id":69475504}],"con":true,"img":false}]}
{"op":"mcm","clk":"11541123547","pt":1719502494431,"mc":[{"id":"1.230180126","rc":[{"atl":[[6.4,0]],"id":64851267}],"con":true,"img":false}]}
{"op":"mcm","clk":"11541123577","pt":1719502494804,"mc":[{"id":"1.230180126","rc":[{"atl":[[6.2,0]],"id":64851267}],"con":true,"img":false}]}
{"op":"mcm","clk":"11541123704","pt":1719502496447,"mc":[{"id":"1.230180126","rc":[{"atl":[[6.4,2]],"id":64851267}],"con":true,"img":false}]}
{"op":"mcm","clk":"11541123803","pt":1719502497538,"mc":[{"id":"1.230180126","rc":[{"atb":[[2.86,3.16]],"id":66993945}],"con":true,"img":false}]}
{"op":"mcm","clk":"11541123819","pt":1719502497744,"mc":[{"id":"1.230180126","rc":[{"atb":[[3.35,5.04]],"id":62886137}],"con":true,"img":false}]}
{"op":"mcm","clk":"11541123836","pt":1719502497905,"mc":[{"id":"1.230180126","rc":[{"atb":[[2.62,7.32]],"id":49823335}],"con":true,"img":false}]}
{"op":"mcm","clk":"11541123842","pt":1719502498006,"mc":[{"id":"1.230180126","rc":[{"atb":[[2.78,6.66]],"id":66993945}],"con":true,"img":false}]}
{"op":"mcm","clk":"11541123856","pt":1719502498309,"mc":[{"id":"1.230180126","rc":[{"atb":[[3.5,4.74]],"id":69475504}],"con":true,"img":false}]}
{"op":"mcm","clk":"11541123880","pt":1719502498614,"mc":[{"id":"1.230180126","rc":[{"atb":[[2.66,7.14]],"id":61941224}],"con":true,"img":false}]}
{"op":"mcm","clk":"11541123959","pt":1719502499700,"mc":[{"id":"1.230180126","rc":[{"atl":[[6.2,0.84]],"id":64851267}],"con":true,"img":false}]}
{"op":"mcm","clk":"11541124012","pt":1719502500422,"mc":[{"id":"1.230180126","rc":[{"atb":[[3.05,11.4]],"id":66993945},{"atl":[[23,1.17]],"id":66993945},{"atl":[[6.2,5.32]],"id":64851267}],"con":true,"img":false}]}
{"op":"mcm","clk":"11541124028","pt":1719502500637,"mc":[{"id":"1.230180126","rc":[{"atl":[[40,0]],"id":66993945}],"con":true,"img":false}]}
{"op":"mcm","clk":"11541124038","pt":1719502500736,"mc":[{"id":"1.230180126","rc":[{"atl":[[24,4.71]],"id":66993945}],"con":true,"img":false}]}
{"op":"mcm","clk":"11541124053","pt":1719502500942,"mc":[{"id":"1.230180126","rc":[{"atl":[[6,4.43]],"id":64851267}],"con":true,"img":false}]}
{"op":"mcm","clk":"11541124120","pt":1719502501727,"mc":[{"id":"1.230180126","rc":[{"atl":[[6.4,0]],"id":64851267}],"con":true,"img":false}]}
{"op":"mcm","clk":"11541124127","pt":1719502501822,"mc":[{"id":"1.230180126","rc":[{"atl":[[5.9,4.67]],"id":64851267}],"con":true,"img":false}]}
{"op":"mcm","clk":"11541124147","pt":1719502502030,"mc":[{"id":"1.230180126","rc":[{"atl":[[6,0.2]],"id":64851267}],"con":true,"img":false}]}
{"op":"mcm","clk":"11541124159","pt":1719502502135,"mc":[{"id":"1.230180126","rc":[{"atb":[[6.2,0],[6,2.35]],"id":69475504},{"trd":[[6,5.34],[6.2,1.79]],"ltp":6.0,"tv":7.13,"id":69475504}],"con":true,"img":false}]}
{"op":"mcm","clk":"11541124169","pt":1719502502237,"mc":[{"id":"1.230180126","rc":[{"atb":[[6,0]],"id":69475504},{"atl":[[26,2.12]],"id":69475504},{"trd":[[6,10.04]],"ltp":6.0,"tv":10.04,"id":69475504}],"con":true,"img":false}]}
{"op":"mcm","clk":"11541124178","pt":1719502502345,"mc":[{"id":"1.230180126","rc":[{"atl":[[12.5,1]],"id":49823335},{"atl":[[6.2,4.48]],"id":64851267},{"atl":[[14.5,1]],"id":62886137},{"atl":[[19.5,1]],"id":61941224},{"atl":[[9.2,1],[26,0.32]],"id":69475504}],"con":true,"img":false}]}
{"op":"mcm","clk":"11541124183","pt":1719502502445,"mc":[{"id":"1.230180126","rc":[{"atb":[[5.7,1.48]],"id":49823335},{"atb":[[5.7,1.48]],"id":62886137}],"con":true,"img":false}]}
{"op":"mcm","clk":"11541124189","pt":1719502502505,"mc":[{"id":"1.230180126","rc":[{"atl":[[55,0]],"id":49823335}],"con":true,"img":false}]}
{"op":"mcm","clk":"11541124198","pt":1719502502605,"mc":[{"id":"1.230180126","rc":[{"atb":[[1.1,1.69]],"id":69475504}],"con":true,"img":false}]}
{"op":"mcm","clk":"11541124205","pt":1719502502706,"mc":[{"id":"1.230180126","rc":[{"atl":[[32,2.58]],"id":49823335},{"atb":[[3,13.96]],"id":64851267},{"atb":[[5.7,6.43]],"id":62886137},{"atl":[[29,1.82]],"id":62886137},{"atb":[[7.4,1.14],[5.2,7.18]],"id":61941224},{"atl":[[28,0.88]],"id":61941224},{"atl":[[27,1.74]],"id":69475504}],"con":true,"img":false}]}
{"op":"mcm","clk":"11541124213","pt":1719502502810,"mc":[{"id":"1.230180126","rc":[{"atb":[[5.1,0]],"id":61941224},{"atb":[[4.8,0.84]],"id":69475504}],"con":true,"img":false}]}
{"op":"mcm","clk":"11541124224","pt":1719502502912,"mc":[{"id":"1.230180126","rc":[{"atb":[[5.4,7.18]],"id":61941224},{"atb":[[1.1,0.06]],"id":69475504}],"con":true,"img":false}]}
{"op":"mcm","clk":"11541124235","pt":1719502503017,"mc":[{"id":"1.230180126","rc":[{"atl":[[6,0]],"id":64851267},{"atb":[[7.4,0]],"id":61941224}],"con":true,"img":false}]}
{"op":"mcm","clk":"11541124240","pt":1719502503120,"mc":[{"id":"1.230180126","rc":[{"atb":[[5.2,6.18]],"id":61941224}],"con":true,"img":false}]}
{"op":"mcm","clk":"11541124250","pt":1719502503223,"mc":[{"id":"1.230180126","rc":[{"atb":[[7.2,1.18]],"id":61941224},{"atb":[[1.1,0]],"id":69475504}],"con":true,"img":false}]}
{"op":"mcm","clk":"11541124259","pt":1719502503328,"mc":[{"id":"1.230180126","rc":[{"atb":[[5.8,0.84]],"id":62886137},{"atb":[[5.5,1]],"id":61941224},{"atb":[[4.8,0.91]],"id":69475504}],"con":true,"img":false}]}
{"op":"mcm","clk":"11541124267","pt":1719502503431,"mc":[{"id":"1.230180126","rc":[{"atl":[[5.8,2],[1000,0.21]],"id":64851267},{"atb":[[7.2,5.32]],"id":61941224},{"atb":[[4.8,7.11]],"id":69475504}],"con":true,"img":false}]}
{"op":"mcm","clk":"11541124277","pt":1719502503540,"mc":[{"id":"1.230180126","rc":[{"atl":[[1000,1.94]],"id":66993945},{"atb":[[1.04,78.75]],"id":49823335},{"atl":[[1000,1.7]],"id":49823335},{"atl":[[1000,0]],"id":64851267},{"atb":[[1.04,1.7]],"id":62886137},{"atl":[[1000,1.94]],"id":62886137}],"con":true,"img":false}]}
{"op":"mcm","clk":"11541124287","pt":1719502503639,"mc":[{"id":"1.230180126","rc":[{"atb":[[3.95,0],[1.02,3.7]],"id":66993945},{"atb":[[5.6,1.71]],"id":49823335},{"atb":[[3.45,0]],"id":64851267},{"atl":[[5.8,2.21]],"id":64851267},{"atb":[[5.6,1.71]],"id":62886137},{"atb":[[7.2,5.28]],"id":61941224}],"con":true,"img":false}]}
{"op":"mcm","clk":"11541124294","pt":1719502503759,"mc":[{"id":"1.230180126","rc":[{"atb":[[4.9,5.18]],"id":69475504}],"con":true,"img":false}]}
{"op":"mcm","clk":"11541124302","pt":1719502503815,"mc":[{"id":"1.230180126","rc":[{"atb":[[1.02,2.12]],"id":66993945},{"atl":[[1000,0.25]],"id":66993945},{"atb":[[1.04,77.11]],"id":49823335},{"atl":[[1000,0.01]],"id":49823335},{"atb":[[1.04,0.05]],"id":62886137},{"atl":[[1000,0.24]],"id":62886137},{"atb":[[7.4,0.84]],"id":61941224}],"con":true,"img":false}]}
{"op":"mcm","clk":"11541124311","pt":1719502503915,"mc":[{"id":"1.230180126","rc":[{"atb":[[4.3,0]],"id":69475504}],"con":true,"img":false}]}
{"op":"mcm","clk":"11541124322","pt":1719502504019,"mc":[{"id":"1.230180126","rc":[{"atb":[[1.02,2]],"id":66993945},{"atl":[[1000,0.23]],"id":66993945},{"atb":[[1.04,77.05]],"id":49823335},{"atl":[[1000,0]],"id":49823335},{"atb":[[1.04,0]],"id":62886137},{"atl":[[1000,0.23]],"id":62886137}],"con":true,"img":false}]}
{"op":"mcm","clk":"11541124330","pt":1719502504122,"mc":[{"id":"1.230180126","rc":[{"atb":[[3.2,0.12]],"id":66993945},{"atl":[[22,0.01]],"id":66993945},{"atb":[[5.7,1.54]],"id":49823335},{"atl":[[30,0.28]],"id":49823335},{"atb":[[5.8,0.9]],"id":62886137},{"atl":[[28,0.31]],"id":62886137},{"atb":[[5,1]],"id":69475504}],"con":true,"img":false}]}
{"op":"mcm","clk":"11541124347","pt":1719502504330,"mc":[{"id":"1.230180126","rc":[{"atl":[[5.7,4.82]],"id":64851267},{"atb":[[4.9,0],[5,6.9]],"id":69475504}],"con":true,"img":false}]}
{"op":"mcm","clk":"11541124362","pt":1719502504542,"mc":[{"id":"1.230180126","rc":[{"atb":[[2.6,7.94]],"id":64851267},{"atl":[[5.6,4.53]],"id":64851267},{"atb":[[5.1,4.97]],"id":69475504}],"con":true,"img":false}]}
{"op":"mcm","clk":"11541124372","pt":1719502504640,"mc":[{"id":"1.230180126","rc":[{"atb":[[2.84,6.9]],"id":66993945}],"con":true,"img":false}]}
{"op":"mcm","clk":"11541124388","pt":1719502504846,"mc":[{"id":"1.230180126","rc":[{"atb":[[4.8,6.26]],"id":69475504}],"con":true,"img":false}]}
{"op":"mcm","clk":"11541124397","pt":1719502504948,"mc":[{"id":"1.230180126","rc":[{"atl":[[5.8,0.21]],"id":64851267}],"con":true,"img":false}]}
{"op":"mcm","clk":"11541124405","pt":1719502505006,"mc":[{"id":"1.230180126","rc":[{"atl":[[5.6,9.77]],"id":64851267},{"atb":[[5.1,11.64]],"id":69475504}],"con":true,"img":false}]}
{"op":"mcm","clk":"11541124425","pt":1719502505213,"mc":[{"id":"1.230180126","rc":[{"atb":[[5,5.9]],"id":69475504}],"con":true,"img":false}]}
{"op":"mcm","clk":"11541124436","pt":1719502505316,"mc":[{"id":"1.230180126","rc":[{"atl":[[23,2.17]],"id":66993945},{"atl":[[30,1.28]],"id":49823335},{"atl":[[5.5,1]],"id":64851267},{"atl":[[28,1.31]],"id":62886137},{"atl":[[29,2.15]],"id":61941224},{"atl":[[26,1.32]],"id":69475504}],"con":true,"img":false}]}
{"op":"mcm","clk":"11541124442","pt":1719502505419,"mc":[{"id":"1.230180126","rc":[{"atl":[[5.7,4.79]],"id":64851267},{"atb":[[5.2,1]],"id":69475504}],"con":true,"img":false}]}
{"op":"mcm","clk":"11541124452","pt":1719502505526,"mc":[{"id":"1.230180126","rc":[{"atl":[[5.5,1.03]],"id":64851267}],"con":true,"img":false}]}
{"op":"mcm","clk":"11541124473","pt":1719502505832,"mc":[{"id":"1.230180126","rc":[{"atl":[[5.6,5.24]],"id":64851267},{"atb":[[5.1,6.67],[5.2,2.41]],"id":69475504}],"con":true,"img":false}]}
{"op":"mcm","clk":"11541124489","pt":1719502506047,"mc":[{"id":"1.230180126","rc":[{"atl":[[29,0.83]],"id":49823335},{"atl":[[27,0.86]],"id":62886137},{"atb":[[5.3,4.79]],"id":69475504},{"atl":[[25,1.11]],"id":69475504}],"con":true,"img":false}]}
{"op":"mcm","clk":"11541124503","pt":1719502506244,"mc":[{"id":"1.230180126","rc":[{"atb":[[5,0]],"id":61941224},{"atb":[[4.7,2.07]],"id":69475504}],"con":true,"img":false}]}
{"op":"mcm","clk":"11541124538","pt":1719502506724,"mc":[{"id":"1.230180126","rc":[{"atb":[[5.3,10.49]],"id":69475504},{"atl":[[27,0.9]],"id":69475504}],"con":true,"img":false}]}
{"op":"mcm","clk":"11541124556","pt":1719502506919,"mc":[{"id":"1.230180126","rc":[{"atb":[[5.2,1.41]],"id":69475504}],"con":true,"img":false}]}
{"op":"mcm","clk":"11541124574","pt":1719502507134,"mc":[{"id":"1.230180126","rc":[{"atb":[[5.4,1]],"id":69475504}],"con":true,"img":false}]}
{"op":"mcm","clk":"11541124591","pt":1719502507433,"mc":[{"id":"1.230180126","rc":[{"atl":[[26,0.32]],"id":69475504}],"con":true,"img":false}]}
{"op":"mcm","clk":"11541124596","pt":1719502507540,"mc":[{"id":"1.230180126","rc":[{"atl":[[27,1.9]],"id":69475504}],"con":true,"img":false}]}
{"op":"mcm","clk":"11541124602","pt":1719502507641,"mc":[{"id":"1.230180126","rc":[{"atb":[[5.3,5.7]],"id":69475504}],"con":true,"img":false}]}
{"op":"mcm","clk":"11541124820","pt":1719502510537,"mc":[{"id":"1.230180126","rc":[{"atl":[[5.4,2]],"id":64851267}],"con":true,"img":false}]}
{"op":"mcm","clk":"11541124834","pt":1719502510737,"mc":[{"id":"1.230180126","rc":[{"atb":[[5.3,7.56]],"id":69475504}],"con":true,"img":false}]}
{"op":"mcm","clk":"11541124845","pt":1719502510837,"mc":[{"id":"1.230180126","rc":[{"atl":[[6.2,0]],"id":64851267}],"con":true,"img":false}]}
{"op":"mcm","clk":"11541124850","pt":1719502510945,"mc":[{"id":"1.230180126","rc":[{"atl":[[5.4,7.39]],"id":64851267}],"con":true,"img":false}]}
{"op":"mcm","clk":"11541124878","pt":1719502511256,"mc":[{"id":"1.230180126","rc":[{"atl":[[5.3,4.79]],"id":64851267}],"con":true,"img":false}]}
{"op":"mcm","clk":"11541124890","pt":1719502511360,"mc":[{"id":"1.230180126","rc":[{"atl":[[5.3,5.63]],"id":64851267}],"con":true,"img":false}]}
{"op":"mcm","clk":"11541124903","pt":1719502511517,"mc":[{"id":"1.230180126","rc":[{"atl":[[5.9,0],[5.5,1]],"id":64851267}],"con":true,"img":false}]}
{"op":"mcm","clk":"11541124912","pt":1719502511622,"mc":[{"id":"1.230180126","rc":[{"atb":[[1.01,0.71]],"id":64851267},{"atl":[[5.3,5.66]],"id":64851267}],"con":true,"img":false}]}
{"op":"mcm","clk":"11541124918","pt":1719502511722,"mc":[{"id":"1.230180126","rc":[{"atl":[[5.3,11.93],[5.4,5.39]],"id":64851267}],"con":true,"img":false}]}
{"op":"mcm","clk":"11541124949","pt":1719502512237,"mc":[{"id":"1.230180126","rc":[{"atb":[[1.01,1]],"id":64851267}],"con":true,"img":false}]}
{"op":"mcm","clk":"11541124987","pt":1719502512851,"mc":[{"id":"1.230180126","rc":[{"atb":[[1.01,0.28]],"id":64851267}],"con":true,"img":false}]}
{"op":"mcm","clk":"11541124994","pt":1719502512953,"mc":[{"id":"1.230180126","rc":[{"atb":[[3.4,1.28]],"id":64851267}],"con":true,"img":false}]}
{"op":"mcm","clk":"11541125010","pt":1719502513117,"mc":[{"id":"1.230180126","rc":[{"atb":[[3.1,13.67]],"id":64851267}],"con":true,"img":false}]}
{"op":"mcm","clk":"11541125025","pt":1719502513320,"mc":[{"id":"1.230180126","rc":[{"atb":[[1.01,0]],"id":64851267}],"con":true,"img":false}]}
{"op":"mcm","clk":"11541125034","pt":1719502513424,"mc":[{"id":"1.230180126","rc":[{"atb":[[3.35,0.28]],"id":64851267}],"con":true,"img":false}]}
{"op":"mcm","clk":"11541125053","pt":1719502513734,"mc":[{"id":"1.230180126","rc":[{"atl":[[5.5,0]],"id":64851267}],"con":true,"img":false}]}
{"op":"mcm","clk":"11541125062","pt":1719502513835,"mc":[{"id":"1.230180126","rc":[{"atl":[[5.2,1]],"id":64851267}],"con":true,"img":false}]}
{"op":"mcm","clk":"11541125070","pt":1719502513936,"mc":[{"id":"1.230180126","rc":[{"atb":[[3.3,2.09]],"id":64851267}],"con":true,"img":false}]}
{"op":"mcm","clk":"11541125080","pt":1719502514145,"mc":[{"id":"1.230180126","rc":[{"atl":[[5.3,5.66],[5.4,0],[5.6,0],[5.7,0]],"id":64851267}],"con":true,"img":false}]}
{"op":"mcm","clk":"11541125087","pt":1719502514251,"mc":[{"id":"1.230180126","rc":[{"atl":[[5.3,0.87]],"id":64851267}],"con":true,"img":false}]}
{"op":"mcm","clk":"11541125128","pt":1719502514817,"mc":[{"id":"1.230180126","rc":[{"atb":[[1.01,0.71]],"id":64851267},{"atl":[[6.4,4.37],[5.2,0]],"id":64851267}],"con":true,"img":false}]}
{"op":"mcm","clk":"11541125135","pt":1719502514919,"mc":[{"id":"1.230180126","rc":[{"atl":[[7.6,1]],"id":64851267}],"con":true,"img":false}]}
{"op":"mcm","clk":"11541125157","pt":1719502515231,"mc":[{"id":"1.230180126","rc":[{"atl":[[5.3,0.03]],"id":64851267}],"con":true,"img":false}]}
{"op":"mcm","clk":"11541125166","pt":1719502515334,"mc":[{"id":"1.230180126","rc":[{"atb":[[1.01,0.28]],"id":64851267}],"con":true,"img":false}]}
{"op":"mcm","clk":"11541125194","pt":1719502515749,"mc":[{"id":"1.230180126","rc":[{"atb":[[1.01,0]],"id":64851267}],"con":true,"img":false}]}
{"op":"mcm","clk":"11541125203","pt":1719502515846,"mc":[{"id":"1.230180126","rc":[{"atb":[[3.3,2.38]],"id":64851267},{"atl":[[7.6,0]],"id":64851267}],"con":true,"img":false}]}
{"op":"mcm","clk":"11541125211","pt":1719502515955,"mc":[{"id":"1.230180126","rc":[{"atl":[[6.2,1]],"id":64851267}],"con":true,"img":false}]}
{"op":"mcm","clk":"11541125281","pt":1719502516727,"mc":[{"id":"1.230180126","rc":[{"atb":[[2.86,0]],"id":66993945},{"spn":3.29,"spf":1.0,"id":66993945},{"atb":[[5.6,0.84]],"id":49823335},{"spn":9.1,"spf":"NaN","id":49823335},{"atb":[[2.98,3.38]],"id":64851267},{"spn":3.18,"spf":1.0,"id":64851267},{"atb":[[5.6,0.84]],"id":62886137},{"spn":10.15,"spf":"NaN","id":62886137},{"spn":13.45,"spf":"NaN","id":61941224},{"atb":[[4.7,0]],"id":69475504},{"spn":7.3,"spf":"NaN","id":69475504}],"con":true,"img":false}]}
{"op":"mcm","clk":"11541125303","pt":1719502517032,"mc":[{"id":"1.230180126","rc":[{"atb":[[5.6,2.32],[5.7,0.06]],"id":49823335},{"atb":[[1.01,0.71]],"id":64851267}],"con":true,"img":false}]}
{"op":"mcm","clk":"11541125337","pt":1719502517548,"mc":[{"id":"1.230180126","rc":[{"atb":[[1.01,0.28]],"id":64851267}],"con":true,"img":false}]}
{"op":"mcm","clk":"11541125343","pt":1719502517650,"mc":[{"id":"1.230180126","rc":[{"atl":[[6,2]],"id":64851267}],"con":true,"img":false}]}
{"op":"mcm","clk":"11541125365","pt":1719502517959,"mc":[{"id":"1.230180126","rc":[{"atb":[[1.01,0]],"id":64851267}],"con":true,"img":false}]}
{"op":"mcm","clk":"11541125374","pt":1719502518062,"mc":[{"id":"1.230180126","rc":[{"atb":[[3.25,0.28]],"id":64851267},{"atl":[[5.9,5.47],[1000,0.71]],"id":64851267}],"con":true,"img":false}]}
{"op":"mcm","clk":"11541125399","pt":1719502518431,"mc":[{"id":"1.230180126","rc":[{"atl":[[5.8,4.58],[6,0]],"id":64851267}],"con":true,"img":false}]}
{"op":"mcm","clk":"11541125408","pt":1719502518529,"mc":[{"id":"1.230180126","rc":[{"atl":[[1000,0.28]],"id":64851267}],"con":true,"img":false}]}
{"op":"mcm","clk":"11541125429","pt":1719502518836,"mc":[{"id":"1.230180126","rc":[{"atl":[[5.8,4.37],[6.2,0],[5.7,0.84]],"id":64851267}],"con":true,"img":false}]}
{"op":"mcm","clk":"11541125436","pt":1719502518936,"mc":[{"id":"1.230180126","rc":[{"atl":[[5.7,1.84]],"id":64851267}],"con":true,"img":false}]}
{"op":"mcm","clk":"11541125443","pt":1719502519039,"mc":[{"id":"1.230180126","rc":[{"atl":[[5.8,0],[1000,0.92]],"id":64851267}],"con":true,"img":false}]}
{"op":"mcm","clk":"11541125451","pt":1719502519145,"mc":[{"id":"1.230180126","rc":[{"atl":[[5.3,0.31],[5.7,7.39]],"id":64851267}],"con":true,"img":false}]}
{"op":"mcm","clk":"11541125458","pt":1719502519264,"mc":[{"id":"1.230180126","rc":[{"atl":[[1000,0.71]],"id":64851267}],"con":true,"img":false}]}
{"op":"mcm","clk":"11541125467","pt":1719502519345,"mc":[{"id":"1.230180126","rc":[{"atl":[[5.7,7.6]],"id":64851267}],"con":true,"img":false}]}
{"op":"mcm","clk":"11541125475","pt":1719502519556,"mc":[{"id":"1.230180126","rc":[{"atl":[[1000,0.28]],"id":64851267}],"con":true,"img":false}]}
{"op":"mcm","clk":"11541125509","pt":1719502519968,"mc":[{"id":"1.230180126","rc":[{"atl":[[5.7,6.6]],"id":64851267}],"con":true,"img":false}]}
{"op":"mcm","clk":"11541125518","pt":1719502520065,"mc":[{"id":"1.230180126","rc":[{"atl":[[5.8,1],[1000,0.71]],"id":64851267}],"con":true,"img":false}]}
{"op":"mcm","clk":"11541125525","pt":1719502520123,"mc":[{"id":"1.230180126","rc":[{"atl":[[5.4,0.28]],"id":64851267}],"con":true,"img":false}]}
{"op":"mcm","clk":"11541125552","pt":1719502520528,"mc":[{"id":"1.230180126","rc":[{"atl":[[1000,0.28]],"id":64851267}],"con":true,"img":false}]}
{"op":"mcm","clk":"11541125557","pt":1719502520633,"mc":[{"id":"1.230180126","rc":[{"atl":[[5.6,4.53]],"id":64851267}],"con":true,"img":false}]}
{"op":"mcm","clk":"11541125577","pt":1719502520941,"mc":[{"id":"1.230180126","rc":[{"atl":[[1000,0]],"id":64851267}],"con":true,"img":false}]}
{"op":"mcm","clk":"11541125589","pt":1719502521043,"mc":[{"id":"1.230180126","rc":[{"atl":[[5.5,0.28]],"id":64851267},{"atb":[[5.3,0],[5.4,0],[5.2,1.32]],"id":69475504},{"atl":[[24,1.15]],"id":69475504},{"trd":[[5.2,0.18],[5.3,15.12],[5.4,2]],"ltp":5.2,"tv":17.29,"id":69475504}],"con":true,"img":false}]}
{"op":"mcm","clk":"11541125604","pt":1719502521250,"mc":[{"id":"1.230180126","rc":[{"atb":[[3.1,2.83]],"id":66993945},{"atl":[[24,3.71]],"id":66993945},{"atl":[[32,1.58]],"id":49823335},{"atl":[[5.6,0]],"id":64851267},{"atb":[[7.4,2.6]],"id":61941224},{"atb":[[5.2,2.94],[4.7,1]],"id":69475504},{"atl":[[24,0]],"id":69475504}],"con":true,"img":false}]}
{"op":"mcm","clk":"11541125613","pt":1719502521357,"mc":[{"id":"1.230180126","rc":[{"atb":[[3.15,12.13]],"id":66993945},{"atb":[[7.4,6.49],[7.2,4.14]],"id":61941224}],"con":true,"img":false}]}
{"op":"mcm","clk":"11541125623","pt":1719502521457,"mc":[{"id":"1.230180126","rc":[{"atb":[[7.6,3.34]],"id":61941224},{"atb":[[5.3,4.79]],"id":69475504}],"con":true,"img":false}]}
{"op":"mcm","clk":"11541125637","pt":1719502521662,"mc":[{"id":"1.230180126","rc":[{"atb":[[5.9,1.43]],"id":62886137},{"atb":[[5.5,0]],"id":61941224}],"con":true,"img":false}]}
{"op":"mcm","clk":"11541125647","pt":1719502521769,"mc":[{"id":"1.230180126","rc":[{"atl":[[24,4.5]],"id":66993945},{"atl":[[32,2.37]],"id":49823335},{"atl":[[29,2.61]],"id":62886137},{"atb":[[7.8,0.84]],"id":61941224},{"atl":[[30,2.33]],"id":61941224}],"con":true,"img":false}]}
{"op":"mcm","clk":"11541125652","pt":1719502521819,"mc":[{"id":"1.230180126","rc":[{"atb":[[3.1,1]],"id":66993945},{"atb":[[7.4,4.73],[7.8,1.84]],"id":61941224},{"atb":[[5.2,1.32]],"id":69475504}],"con":true,"img":false}]}
{"op":"mcm","clk":"11541125656","pt":1719502521922,"mc":[{"id":"1.230180126","rc":[{"atb":[[3.2,1.96]],"id":66993945},{"atb":[[7.8,3.6]],"id":61941224},{"atb":[[5.4,1.62]],"id":69475504}],"con":true,"img":false}]}
{"op":"mcm","clk":"11541125663","pt":1719502522026,"mc":[{"id":"1.230180126","rc":[{"atb":[[5.6,0.84]],"id":49823335},{"atb":[[5.7,4.95]],"id":62886137},{"atb":[[7.6,0]],"id":61941224}],"con":true,"img":false}]}
{"op":"mcm","clk":"11541125673","pt":1719502522126,"mc":[{"id":"1.230180126","rc":[{"atb":[[3.2,2.81]],"id":66993945},{"atl":[[1000,0.71]],"id":64851267},{"atb":[[5.8,1.75]],"id":62886137},{"atb":[[8,0.84]],"id":61941224},{"atb":[[5.4,2.47]],"id":69475504}],"con":true,"img":false}]}
{"op":"mcm","clk":"11541125680","pt":1719502522334,"mc":[{"id":"1.230180126","rc":[{"atb":[[5.8,1.45]],"id":49823335},{"atb":[[7.6,1.11]],"id":61941224}],"con":true,"img":false}]}
{"op":"mcm","clk":"11541125685","pt":1719502522436,"mc":[{"id":"1.230180126","rc":[{"atl":[[24,4.18]],"id":66993945},{"atl":[[32,2.11]],"id":49823335},{"atb":[[5.6,0]],"id":62886137},{"atl":[[29,2.3]],"id":62886137},{"atb":[[7.4,3.89]],"id":61941224},{"atl":[[30,2]],"id":61941224},{"atb":[[4.8,0.06],[1.03,0.52]],"id":69475504},{"atl":[[9,1.05]],"id":69475504}],"con":true,"img":false}]}
{"op":"mcm","clk":"11541125688","pt":1719502522538,"mc":[{"id":"1.230180126","rc":[{"atb":[[3.25,12.13]],"id":66993945},{"atb":[[4.4,6.76]],"id":49823335},{"atl":[[1000,0.28]],"id":64851267},{"atb":[[5.9,6.74]],"id":62886137},{"atb":[[7.8,6.43]],"id":61941224},{"atb":[[1.03,0.35],[5.4,7.79]],"id":69475504},{"atl":[[9,3.05],[28,0]],"id":69475504}],"con":true,"img":false}]}
{"op":"mcm","clk":"11541125696","pt":1719502522645,"mc":[{"id":"1.230180126","rc":[{"atb":[[8,1.84]],"id":61941224},{"atb":[[1.03,0],[5.3,0]],"id":69475504}],"con":true,"img":false}]}
{"op":"mcm","clk":"11541125701","pt":1719502522744,"mc":[{"id":"1.230180126","rc":[{"atb":[[5.5,0.35]],"id":69475504}],"con":true,"img":false}]}
{"op":"mcm","clk":"11541125706","pt":1719502522850,"mc":[{"id":"1.230180126","rc":[{"atb":[[6,4.23]],"id":62886137},{"atb":[[8.2,3.09]],"id":61941224}],"con":true,"img":false}]}
{"op":"mcm","clk":"11541125714","pt":1719502523057,"mc":[{"id":"1.230180126","rc":[{"atb":[[3.2,0.97]],"id":66993945},{"atl":[[1000,0.95]],"id":66993945},{"atl":[[1000,0]],"id":64851267},{"atb":[[7.8,4.67],[5.2,0]],"id":61941224},{"atb":[[5.4,6.16]],"id":69475504}],"con":true,"img":false}]}
{"op":"mcm","clk":"11541125722","pt":1719502523154,"mc":[{"id":"1.230180126","rc":[{"atb":[[3.3,1.83]],"id":66993945},{"atb":[[4.5,1.82]],"id":49823335},{"atl":[[5.6,0.28]],"id":64851267},{"atb":[[6.2,1.73]],"id":62886137},{"atb":[[8.4,1.76]],"id":61941224}],"con":true,"img":false}]}
{"op":"mcm","clk":"11541125729","pt":1719502523258,"mc":[{"id":"1.230180126","rc":[{"atb":[[6,9]],"id":62886137},{"atb":[[8.2,6.65]],"id":61941224},{"atl":[[9,6.2]],"id":69475504}],"con":true,"img":false}]}
{"op":"mcm","clk":"11541125736","pt":1719502523360,"mc":[{"id":"1.230180126","rc":[{"atb":[[5.8,0.9],[6.2,2.58]],"id":62886137},{"atb":[[7.8,3.83]],"id":61941224},{"atl":[[8.8,0.84]],"id":69475504}],"con":true,"img":false}]}
{"op":"mcm","clk":"11541125751","pt":1719502523566,"mc":[{"id":"1.230180126","rc":[{"atl":[[1000,0.52]],"id":66993945},{"atb":[[5.9,5.31],[6,4.77]],"id":62886137},{"atb":[[8,0.84],[8.2,3.56]],"id":61941224}],"con":true,"img":false}]}
{"op":"mcm","clk":"11541125765","pt":1719502523726,"mc":[{"id":"1.230180126","rc":[{"atb":[[6.4,3.97]],"id":62886137},{"atb":[[8,1.84]],"id":61941224}],"con":true,"img":false}]}
{"op":"mcm","clk":"11541125772","pt":1719502523828,"mc":[{"id":"1.230180126","rc":[{"atb":[[3.2,0.39]],"id":66993945},{"atb":[[5.8,0.32]],"id":62886137},{"atb":[[8,1.25]],"id":61941224},{"atb":[[5.4,5.57]],"id":69475504}],"con":true,"img":false}]}
{"op":"mcm","clk":"11541125779","pt":1719502523928,"mc":[{"id":"1.230180126","rc":[{"atl":[[1000,0.23]],"id":66993945},{"atb":[[7.2,0]],"id":61941224}],"con":true,"img":false}]}
{"op":"mcm","clk":"11541125788","pt":1719502524035,"mc":[{"id":"1.230180126","rc":[{"atb":[[3.35,9.74],[2.84,0]],"id":66993945},{"atl":[[6.8,1.28]],"id":66993945},{"atb":[[2.6,0]],"id":49823335},{"atb":[[6.4,8.72],[3.45,0]],"id":62886137},{"atb":[[2.64,0],[8.4,5.04]],"id":61941224},{"atb":[[3.45,0]],"id":69475504}],"con":true,"img":false}]}
{"op":"mcm","clk":"11541125801","pt":1719502524243,"mc":[{"id":"1.230180126","rc":[{"atb":[[1.01,52.6],[3.3,0]],"id":66993945},{"atb":[[6.2,0.84]],"id":62886137},{"atb":[[8,0.25]],"id":61941224}],"con":true,"img":false}]}
{"op":"mcm","clk":"11541125814","pt":1719502524345,"mc":[{"id":"1.230180126","rc":[{"atb":[[3.4,1.83]],"id":66993945},{"atb":[[5.8,1.75],[6.6,1.73]],"id":62886137},{"atb":[[8.6,3.95]],"id":61941224}],"con":true,"img":false}]}
{"op":"mcm","clk":"11541125844","pt":1719502524654,"mc":[{"id":"1.230180126","rc":[{"atb":[[1.01,52.17]],"id":66993945}],"con":true,"img":false}]}
{"op":"mcm","clk":"11541125858","pt":1719502524757,"mc":[{"id":"1.230180126","rc":[{"atl":[[5.8,0]],"id":64851267}],"con":true,"img":false}]}
{"op":"mcm","clk":"11541125865","pt":1719502524857,"mc":[{"id":"1.230180126","rc":[{"atb":[[3.05,0]],"id":66993945},{"atl":[[5.6,1.28],[5.5,2.28]],"id":64851267},{"atb":[[6.2,0],[5.7,0]],"id":62886137},{"atb":[[7.4,0]],"id":61941224}],"con":true,"img":false}]}
{"op":"mcm","clk":"11541125875","pt":1719502524959,"mc":[{"id":"1.230180126","rc":[{"atb":[[1.06,1.7]],"id":49823335},{"atb":[[6.4,4.75]],"id":62886137},{"atb":[[8.4,3.28]],"id":61941224}],"con":true,"img":false}]}
{"op":"mcm","clk":"11541125884","pt":1719502525063,"mc":[{"id":"1.230180126","rc":[{"atb":[[1.01,51.88],[3.45,9.01]],"id":66993945},{"atb":[[6.6,6.34]],"id":62886137},{"atb":[[8.6,7.5],[8.8,1.76]],"id":61941224}],"con":true,"img":false}]}
{"op":"mcm","clk":"11541125893","pt":1719502525167,"mc":[{"id":"1.230180126","rc":[{"atb":[[3.9,1.28]],"id":66993945},{"atb":[[1.06,0.03]],"id":49823335},{"atl":[[5.4,4.99]],"id":64851267}],"con":true,"img":false}]}
{"op":"mcm","clk":"11541125904","pt":1719502525269,"mc":[{"id":"1.230180126","rc":[{"atb":[[1.01,52.6]],"id":66993945},{"atb":[[8.6,6.5]],"id":61941224},{"atl":[[27,0.9]],"id":69475504}],"con":true,"img":false}]}
{"op":"mcm","clk":"11541125911","pt":1719502525328,"mc":[{"id":"1.230180126","rc":[{"atb":[[1.06,0]],"id":49823335},{"atl":[[5.7,5.76]],"id":64851267},{"atl":[[8.8,1.84]],"id":69475504}],"con":true,"img":false}]}
{"op":"mcm","clk":"11541125917","pt":1719502525426,"mc":[{"id":"1.230180126","rc":[{"atb":[[5.7,0.09]],"id":49823335},{"atb":[[8.8,2.76]],"id":61941224}],"con":true,"img":false}]}
{"op":"mcm","clk":"11541125925","pt":1719502525528,"mc":[{"id":"1.230180126","rc":[{"atb":[[3.2,0.12],[3.4,0]],"id":66993945},{"atb":[[5.8,1.49]],"id":62886137},{"atb":[[8,0]],"id":61941224}],"con":true,"img":false}]}
{"op":"mcm","clk":"11541125934","pt":1719502525632,"mc":[{"id":"1.230180126","rc":[{"atb":[[3.5,2.09]],"id":66993945},{"atl":[[5.6,0.28]],"id":64851267},{"atb":[[6.4,0],[6.8,0.26],[5.9,4.97],[6,0],[6.6,1.73]],"id":62886137},{"atb":[[7.8,0],[8.8,3.01]],"id":61941224}],"con":true,"img":false}]}
{"op":"mcm","clk":"11541125937","pt":1719502525735,"mc":[{"id":"1.230180126","rc":[{"atb":[[1.01,52.17]],"id":66993945},{"atl":[[5.3,6.61]],"id":64851267},{"atb":[[8.6,3.55],[8.8,6.17]],"id":61941224},{"atl":[[8.8,4.72]],"id":69475504}],"con":true,"img":false}]}
{"op":"mcm","clk":"11541125947","pt":1719502525835,"mc":[{"id":"1.230180126","rc":[{"atl":[[5.3,7.46]],"id":64851267}],"con":true,"img":false}]}
{"op":"mcm","clk":"11541125950","pt":1719502525938,"mc":[{"id":"1.230180126","rc":[{"atb":[[1.01,52.88]],"id":66993945},{"atb":[[9,2.81],[8.8,5.17]],"id":61941224}],"con":true,"img":false}]}
{"op":"mcm","clk":"11541125955","pt":1719502526042,"mc":[{"id":"1.230180126","rc":[{"atl":[[5.2,0.79]],"id":64851267},{"atb":[[6.6,0]],"id":62886137}],"con":true,"img":false}]}
{"op":"mcm","clk":"11541125961","pt":1719502526145,"mc":[{"id":"1.230180126","rc":[{"atb":[[1.01,53.31]],"id":66993945},{"atb":[[5.2,3.22]],"id":69475504}],"con":true,"img":false}]}
{"op":"mcm","clk":"11541125969","pt":1719502526249,"mc":[{"id":"1.230180126","rc":[{"atb":[[3.85,0.28]],"id":66993945},{"atb":[[9.2,1]],"id":61941224}],"con":true,"img":false}]}
{"op":"mcm","clk":"11541125975","pt":1719502526355,"mc":[{"id":"1.230180126","rc":[{"atb":[[1.01,54.03]],"id":66993945},{"atb":[[3.1,1]],"id":64851267},{"atb":[[8.2,0]],"id":61941224}],"con":true,"img":false}]}
{"op":"mcm","clk":"11541125982","pt":1719502526451,"mc":[{"id":"1.230180126","rc":[{"atb":[[1.01,53.6]],"id":66993945}],"con":true,"img":false}]}
{"op":"mcm","clk":"11541125987","pt":1719502526559,"mc":[{"id":"1.230180126","rc":[{"atb":[[3.05,12.95]],"id":64851267},{"atb":[[9,6.01]],"id":61941224}],"con":true,"img":false}]}
{"op":"mcm","clk":"11541125993","pt":1719502526659,"mc":[{"id":"1.230180126","rc":[{"atb":[[1.01,53.17]],"id":66993945},{"atl":[[5.4,0.28],[5.2,0.49]],"id":64851267},{"atb":[[6,1.73]],"id":62886137},{"atb":[[9,3.2]],"id":61941224}],"con":true,"img":false}]}
{"op":"mcm","clk":"11541125998","pt":1719502526771,"mc":[{"id":"1.230180126","rc":[{"atb":[[1.01,52.74]],"id":66993945},{"atb":[[8.8,3.41]],"id":61941224}],"con":true,"img":false}]}
{"op":"mcm","clk":"11541126006","pt":1719502526872,"mc":[{"id":"1.230180126","rc":[{"atb":[[9.2,2.76]],"id":61941224}],"con":true,"img":false}]}
{"op":"mcm","clk":"11541126012","pt":1719502526972,"mc":[{"id":"1.230180126","rc":[{"atb":[[1.01,52.46]],"id":66993945}],"con":true,"img":false}]}
{"op":"mcm","clk":"11541126020","pt":1719502527070,"mc":[{"id":"1.230180126","rc":[{"atb":[[1.01,52.17],[3.8,0.28]],"id":66993945},{"atb":[[5.6,2.3]],"id":49823335}],"con":true,"img":false}]}
{"op":"mcm","clk":"11541126025","pt":1719502527127,"mc":[{"id":"1.230180126","rc":[{"atb":[[3.7,0.28]],"id":66993945}],"con":true,"img":false}]}
{"op":"mcm","clk":"11541126030","pt":1719502527226,"mc":[{"id":"1.230180126","rc":[{"atb":[[1.01,51.88]],"id":66993945},{"atb":[[5.8,0]],"id":49823335},{"atl":[[5.2,0]],"id":64851267},{"atb":[[6.8,0]],"id":62886137},{"atb":[[8.8,3.16]],"id":61941224}],"con":true,"img":false}]}
{"op":"mcm","clk":"11541126036","pt":1719502527329,"mc":[{"id":"1.230180126","rc":[{"atb":[[3.15,0.79],[3.65,0.28]],"id":66993945},{"atl":[[5.3,6.46],[1000,0.49]],"id":64851267},{"atb":[[6,1.99]],"id":62886137},{"atb":[[9.2,3.01],[8.4,0],[9.4,2.7]],"id":61941224}],"con":true,"img":false}]}
{"op":"mcm","clk":"11541126043","pt":1719502527433,"mc":[{"id":"1.230180126","rc":[{"atl":[[1000,0.95]],"id":66993945},{"atl":[[5.4,1.28]],"id":64851267}],"con":true,"img":false}]}
{"op":"mcm","clk":"11541126050","pt":1719502527533,"mc":[{"id":"1.230180126","rc":[{"atb":[[3.9,10.86]],"id":66993945},{"atb":[[6.2,5.35]],"id":62886137},{"atb":[[9.2,6.35]],"id":61941224}],"con":true,"img":false}]}
{"op":"mcm","clk":"11541126074","pt":1719502527945,"mc":[{"id":"1.230180126","rc":[{"atb":[[3.5,0.26]],"id":66993945},{"atl":[[1000,0.52]],"id":66993945},{"atl":[[5.2,4.88]],"id":64851267},{"atb":[[6.4,3.97],[6,0.26]],"id":62886137},{"atb":[[9.2,4.59]],"id":61941224}],"con":true,"img":false}]}
{"op":"mcm","clk":"11541126080","pt":1719502528054,"mc":[{"id":"1.230180126","rc":[{"atb":[[3.95,1.83]],"id":66993945},{"atl":[[6.4,0]],"id":64851267},{"atb":[[6.4,5.7]],"id":62886137},{"atb":[[9.6,1.76],[8.6,0]],"id":61941224}],"con":true,"img":false}]}
{"op":"mcm","clk":"11541126087","pt":1719502528152,"mc":[{"id":"1.230180126","rc":[{"atl":[[1000,1.23]],"id":66993945},{"atb":[[2.64,0]],"id":64851267}],"con":true,"img":false}]}
{"op":"mcm","clk":"11541126091","pt":1719502528255,"mc":[{"id":"1.230180126","rc":[{"atb":[[3.95,2.68]],"id":66993945},{"atl":[[5.2,10.92]],"id":64851267},{"atb":[[6.4,10.57]],"id":62886137},{"atb":[[9.4,5.95]],"id":61941224}],"con":true,"img":false}]}
{"op":"mcm","clk":"11541126102","pt":1719502528462,"mc":[{"id":"1.230180126","rc":[{"atl":[[1000,0.95]],"id":66993945},{"atl":[[5.4,0.28],[1000,0],[5.5,0.28]],"id":64851267}],"con":true,"img":false}]}
{"op":"mcm","clk":"11541126107","pt":1719502528564,"mc":[{"id":"1.230180126","rc":[{"atl":[[7,0.28]],"id":66993945},{"atl":[[5.1,1.49]],"id":64851267}],"con":true,"img":false}]}
{"op":"mcm","clk":"11541126114","pt":1719502528667,"mc":[{"id":"1.230180126","rc":[{"atl":[[1000,0.52]],"id":66993945},{"atb":[[9.4,3.25]],"id":61941224},{"atl":[[8.8,5.86]],"id":69475504}],"con":true,"img":false}]}
{"op":"mcm","clk":"11541126123","pt":1719502528775,"mc":[{"id":"1.230180126","rc":[{"atl":[[1000,1.23]],"id":66993945}],"con":true,"img":false}]}
{"op":"mcm","clk":"11541126134","pt":1719502528874,"mc":[{"id":"1.230180126","rc":[{"atb":[[3.5,0]],"id":66993945},{"atb":[[6,0]],"id":62886137},{"atb":[[9.2,4.34],[9.8,3.43]],"id":61941224},{"atl":[[9,4.2],[8.6,5.87]],"id":69475504}],"con":true,"img":false}]}
{"op":"mcm","clk":"11541126141","pt":1719502528927,"mc":[{"id":"1.230180126","rc":[{"atb":[[3.25,0],[3.95,2.94]],"id":66993945},{"atl":[[5.9,0]],"id":64851267},{"atb":[[6.6,0.26]],"id":62886137},{"atb":[[9.6,2.01],[8.8,0]],"id":61941224}],"con":true,"img":false}]}
{"op":"mcm","clk":"11541126147","pt":1719502529032,"mc":[{"id":"1.230180126","rc":[{"atb":[[3.15,0]],"id":66993945}],"con":true,"img":false}]}
{"op":"mcm","clk":"11541126151","pt":1719502529133,"mc":[{"id":"1.230180126","rc":[{"atb":[[3.95,11.74]],"id":66993945},{"atl":[[6.8,5.42],[1000,0.95]],"id":66993945},{"atl":[[5.1,8.22]],"id":64851267},{"atb":[[9.2,3.34],[9.6,2.96]],"id":61941224}],"con":true,"img":false}]}
{"op":"mcm","clk":"11541126157","pt":1719502529240,"mc":[{"id":"1.230180126","rc":[{"atl":[[6.8,7.42],[1000,1.23],[7.2,0.28],[24,2.18]],"id":66993945},{"atb":[[10,1.76]],"id":61941224}],"con":true,"img":false}]}
{"op":"mcm","clk":"11541126169","pt":1719502529444,"mc":[{"id":"1.230180126","rc":[{"atb":[[10.5,1]],"id":61941224},{"atl":[[8.8,4.86]],"id":69475504}],"con":true,"img":false}]}
{"op":"mcm","clk":"11541126176","pt":1719502529545,"mc":[{"id":"1.230180126","rc":[{"atl":[[5.2,6.04]],"id":64851267},{"atb":[[9.8,0.84]],"id":61941224},{"atl":[[8.4,1]],"id":69475504}],"con":true,"img":false}]}
{"op":"mcm","clk":"11541126190","pt":1719502529752,"mc":[{"id":"1.230180126","rc":[{"atb":[[4,6.35]],"id":66993945},{"atl":[[1000,0.52]],"id":66993945},{"atl":[[5,5.08]],"id":64851267},{"atl":[[27,0]],"id":69475504}],"con":true,"img":false}]}
{"op":"mcm","clk":"11541126202","pt":1719502529856,"mc":[{"id":"1.230180126","rc":[{"atl":[[7.4,0.28],[6.6,0.84]],"id":66993945},{"atl":[[5.3,5.61]],"id":64851267}],"con":true,"img":false}]}
{"op":"mcm","clk":"11541126209","pt":1719502529955,"mc":[{"id":"1.230180126","rc":[{"atl":[[8.4,4.6]],"id":69475504}],"con":true,"img":false}]}
{"op":"mcm","clk":"11541126229","pt":1719502530264,"mc":[{"id":"1.230180126","rc":[{"atl":[[1000,0.23]],"id":66993945},{"atl":[[5.1,7.73]],"id":64851267}],"con":true,"img":false}]}
{"op":"mcm","clk":"11541126238","pt":1719502530365,"mc":[{"id":"1.230180126","rc":[{"atb":[[3.95,9.9]],"id":66993945},{"atl":[[7.6,0.28]],"id":66993945},{"atl":[[4.9,0.49]],"id":64851267},{"atb":[[6.6,1.1]],"id":62886137},{"atb":[[10,0]],"id":61941224},{"atl":[[8.2,0.84]],"id":69475504}],"con":true,"img":false}]}
{"op":"mcm","clk":"11541126244","pt":1719502530468,"mc":[{"id":"1.230180126","rc":[{"atb":[[4.1,1.83]],"id":66993945},{"atl":[[23,1.17]],"id":66993945},{"atl":[[5.1,6.73]],"id":64851267},{"atb":[[9.8,2.6]],"id":61941224},{"atl":[[8.4,5.8],[8.8,4.02]],"id":69475504}],"con":true,"img":false}]}
{"op":"mcm","clk":"11541126250","pt":1719502530575,"mc":[{"id":"1.230180126","rc":[{"atb":[[3.35,0],[3.95,9.64]],"id":66993945},{"atl":[[6.6,1.84]],"id":66993945},{"atl":[[4.9,1.49],[5.7,0.21]],"id":64851267}],"con":true,"img":false}]}
{"op":"mcm","clk":"11541126260","pt":1719502530680,"mc":[{"id":"1.230180126","rc":[{"atb":[[4.1,2.09]],"id":66993945}],"con":true,"img":false}]}
{"op":"mcm","clk":"11541126270","pt":1719502530783,"mc":[{"id":"1.230180126","rc":[{"atb":[[3.95,8.8]],"id":66993945},{"atl":[[8.2,1.63]],"id":69475504}],"con":true,"img":false}]}
{"op":"mcm","clk":"11541126280","pt":1719502530842,"mc":[{"id":"1.230180126","rc":[{"atb":[[4,0]],"id":66993945},{"atl":[[5,0]],"id":64851267},{"atb":[[6.4,6.6]],"id":62886137}],"con":true,"img":false}]}
{"op":"mcm","clk":"11541126289","pt":1719502530946,"mc":[{"id":"1.230180126","rc":[{"atb":[[1.01,52.6],[4,7.48]],"id":66993945},{"atl":[[4.9,7.5]],"id":64851267},{"atb":[[6.6,5.81]],"id":62886137}],"con":true,"img":false}]}
{"op":"mcm","clk":"11541126311","pt":1719502531259,"mc":[{"id":"1.230180126","rc":[{"atl":[[24,0.47]],"id":66993945}],"con":true,"img":false}]}
{"op":"mcm","clk":"11541126321","pt":1719502531360,"mc":[{"id":"1.230180126","rc":[{"atb":[[1.01,52.17]],"id":66993945},{"atb":[[5,0]],"id":62886137},{"atl":[[8.2,1.31]],"id":69475504}],"con":true,"img":false}]}
{"op":"mcm","clk":"11541126329","pt":1719502531465,"mc":[{"id":"1.230180126","rc":[{"atl":[[4.9,7.01]],"id":64851267},{"atb":[[6.4,4.87]],"id":62886137}],"con":true,"img":false}]}
{"op":"mcm","clk":"11541126338","pt":1719502531568,"mc":[{"id":"1.230180126","rc":[{"atb":[[3.45,0],[4.2,6.04]],"id":66993945},{"atl":[[5.3,0.31],[4.9,1],[1000,0.49],[5.1,0],[5.2,0]],"id":64851267},{"atb":[[6.8,5.46]],"id":62886137},{"atl":[[25,0]],"id":69475504}],"con":true,"img":false}]}
{"op":"mcm","clk":"11541126345","pt":1719502531674,"mc":[{"id":"1.230180126","rc":[{"atb":[[4.1,10.52]],"id":66993945},{"atl":[[6.6,6.8]],"id":66993945},{"atl":[[8.2,5.13]],"id":69475504}],"con":true,"img":false}]}
{"op":"mcm","clk":"11541126356","pt":1719502531773,"mc":[{"id":"1.230180126","rc":[{"atb":[[1.01,51.88]],"id":66993945}],"con":true,"img":false}]}
{"op":"mcm","clk":"11541126363","pt":1719502531878,"mc":[{"id":"1.230180126","rc":[{"atb":[[3.75,0.28]],"id":66993945}],"con":true,"img":false}]}
{"op":"mcm","clk":"11541126384","pt":1719502532041,"mc":[{"id":"1.230180126","rc":[{"atl":[[4.8,2]],"id":64851267}],"con":true,"img":false}]}
{"op":"mcm","clk":"11541126395","pt":1719502532146,"mc":[{"id":"1.230180126","rc":[{"atb":[[1.01,52.6],[4.1,8.69]],"id":66993945}],"con":true,"img":false}]}
{"op":"mcm","clk":"11541126407","pt":1719502532246,"mc":[{"id":"1.230180126","rc":[{"atb":[[4.3,1.83],[3.9,1.28]],"id":66993945},{"atb":[[5.9,0]],"id":62886137}],"con":true,"img":false}]}
{"op":"mcm","clk":"11541126416","pt":1719502532353,"mc":[{"id":"1.230180126","rc":[{"atb":[[4.1,8.43]],"id":66993945},{"atb":[[6.6,5.55]],"id":62886137},{"atb":[[9.6,2.71]],"id":61941224}],"con":true,"img":false}]}
{"op":"mcm","clk":"11541126426","pt":1719502532455,"mc":[{"id":"1.230180126","rc":[{"atb":[[4.3,2.09],[4.2,14.36]],"id":66993945},{"atl":[[4.8,8.84]],"id":64851267},{"atb":[[6.8,9.34],[7,0.26]],"id":62886137},{"atb":[[9.8,2.86]],"id":61941224}],"con":true,"img":false}]}
{"op":"mcm","clk":"11541126437","pt":1719502532561,"mc":[{"id":"1.230180126","rc":[{"atb":[[1.01,52.17]],"id":66993945},{"atb":[[2.98,0]],"id":64851267}],"con":true,"img":false}]}
{"op":"mcm","clk":"11541126449","pt":1719502532663,"mc":[{"id":"1.230180126","rc":[{"atb":[[1.01,52.88],[4.2,8.32]],"id":66993945}],"con":true,"img":false}]}
{"op":"mcm","clk":"11541126460","pt":1719502532766,"mc":[{"id":"1.230180126","rc":[{"atb":[[3.4,5.29]],"id":62886137}],"con":true,"img":false}]}
{"op":"mcm","clk":"11541126472","pt":1719502532870,"mc":[{"id":"1.230180126","rc":[{"atb":[[2.64,7.74]],"id":49823335}],"con":true,"img":false}]}
{"op":"mcm","clk":"11541126495","pt":1719502533080,"mc":[{"id":"1.230180126","rc":[{"atb":[[1.01,52.6]],"id":66993945},{"atb":[[3,11.94],[3.05,0]],"id":64851267}],"con":true,"img":false}]}
{"op":"mcm","clk":"11541126501","pt":1719502533181,"mc":[{"id":"1.230180126","rc":[{"atb":[[1.01,52.17],[3.95,9.08]],"id":66993945},{"atb":[[2.32,0]],"id":49823335},{"atb":[[3.3,0.28]],"id":64851267}],"con":true,"img":false}]}
{"op":"mcm","clk":"11541126506","pt":1719502533234,"mc":[{"id":"1.230180126","rc":[{"atb":[[2.8,7.05],[1.01,52.88]],"id":66993945}],"con":true,"img":false}]}
{"op":"mcm","clk":"11541126513","pt":1719502533338,"mc":[{"id":"1.230180126","rc":[{"atl":[[4.7,0.84]],"id":64851267}],"con":true,"img":false}]}
{"op":"mcm","clk":"11541126521","pt":1719502533443,"mc":[{"id":"1.230180126","rc":[{"atl":[[8,1.25]],"id":69475504}],"con":true,"img":false}]}
{"op":"mcm","clk":"11541126533","pt":1719502533648,"mc":[{"id":"1.230180126","rc":[{"atb":[[1.01,52.17]],"id":66993945}],"con":true,"img":false}]}
{"op":"mcm","clk":"11541126540","pt":1719502533758,"mc":[{"id":"1.230180126","rc":[{"atb":[[4,7.76]],"id":66993945},{"atb":[[2.62,7.32]],"id":64851267}],"con":true,"img":false}]}
{"op":"mcm","clk":"11541126547","pt":1719502533854,"mc":[{"id":"1.230180126","rc":[{"atl":[[9,1.05]],"id":69475504}],"con":true,"img":false}]}
{"op":"mcm","clk":"11541126552","pt":1719502533958,"mc":[{"id":"1.230180126","rc":[{"atb":[[5.6,8.25]],"id":49823335},{"atl":[[8,4.84]],"id":69475504}],"con":true,"img":false}]}
{"op":"mcm","clk":"11541126561","pt":1719502534167,"mc":[{"id":"1.230180126","rc":[{"atb":[[1.01,51.88]],"id":66993945}],"con":true,"img":false}]}
{"op":"mcm","clk":"11541126572","pt":1719502534266,"mc":[{"id":"1.230180126","rc":[{"atb":[[4.1,8.71]],"id":66993945},{"atb":[[5.7,4.55]],"id":49823335}],"con":true,"img":false}]}
{"op":"mcm","clk":"11541126585","pt":1719502534471,"mc":[{"id":"1.230180126","rc":[{"atl":[[8.2,4.66]],"id":69475504}],"con":true,"img":false}]}
{"op":"mcm","clk":"11541126589","pt":1719502534575,"mc":[{"id":"1.230180126","rc":[{"atb":[[4.5,0]],"id":49823335},{"atl":[[5.7,0]],"id":64851267},{"atl":[[1000,0.46]],"id":69475504}],"con":true,"img":false}]}
{"op":"mcm","clk":"11541126599","pt":1719502534678,"mc":[{"id":"1.230180126","rc":[{"atb":[[5.8,1.82]],"id":49823335},{"atl":[[4.9,0]],"id":64851267},{"atl":[[8.4,4.8]],"id":69475504}],"con":true,"img":false}]}
{"op":"mcm","clk":"11541126606","pt":1719502534786,"mc":[{"id":"1.230180126","rc":[{"atb":[[3.95,0.28]],"id":66993945},{"atb":[[5.8,2.66]],"id":49823335},{"atl":[[4.7,1.84]],"id":64851267},{"atl":[[8,5.84]],"id":69475504}],"con":true,"img":false}]}
{"op":"mcm","clk":"11541126613","pt":1719502534884,"mc":[{"id":"1.230180126","rc":[{"atb":[[5.7,0.09]],"id":49823335},{"atb":[[6.8,0],[7,0],[6.6,5.16]],"id":62886137},{"trd":[[6.6,0.77],[6.8,18.69],[7,0.52]],"ltp":6.6,"tv":19.98,"id":62886137}],"con":true,"img":false}]}
{"op":"mcm","clk":"11541126621","pt":1719502534938,"mc":[{"id":"1.230180126","rc":[{"atb":[[4.3,9.19]],"id":66993945}],"con":true,"img":false}]}
