{"op":"mcm","clk":"11536832967","pt":1719431775485,"mc":[{"id":"1.230180113","marketDefinition":{"bspMarket":true,"turnInPlayEnabled":false,"persistenceEnabled":false,"marketBaseRate":5.0,"eventId":"33376437","eventTypeId":"4339","numberOfWinners":2,"bettingType":"ODDS","marketType":"PLACE","marketTime":"2024-06-27T13:33:00.000Z","suspendTime":"2024-06-27T13:33:00.000Z","bspReconciled":false,"complete":true,"inPlay":false,"crossMatching":false,"runnersVoidable":false,"numberOfActiveRunners":6,"betDelay":0,"status":"OPEN","runners":[{"status":"ACTIVE","sortPriority":1,"id":68870841,"name":"1. Milton Daisy"},{"status":"ACTIVE","sortPriority":2,"id":58974183,"name":"2. Ballymac Diverse"},{"status":"ACTIVE","sortPriority":3,"id":58462129,"name":"3. Rapido Junior"},{"status":"ACTIVE","sortPriority":4,"id":50281437,"name":"4. Browns Girl"},{"status":"ACTIVE","sortPriority":5,"id":68579508,"name":"5. Ivy Hill Willow"},{"status":"ACTIVE","sortPriority":6,"id":68169358,"name":"6. Spiridon Zelus"}],"regulators":["MR_INT"],"venue":"Towcester","countryCode":"GB","discountAllowed":false,"timezone":"Europe/London","openDate":"2024-06-27T13:33:00.000Z","version":5994767052,"name":"To Be Placed","eventName":"Towcester 27th Jun"},"rc":[],"con":true,"img":false}]}
{"op":"mcm","clk":"11536833111","pt":1719431777486,"mc":[{"id":"1.230180113","marketDefinition":{"bspMarket":true,"turnInPlayEnabled":false,"persistenceEnabled":false,"marketBaseRate":5.0,"eventId":"33376437","eventTypeId":"4339","numberOfWinners":2,"bettingType":"ODDS","marketType":"PLACE","marketTime":"2024-06-27T13:33:00.000Z","suspendTime":"2024-06-27T13:33:00.000Z","bspReconciled":false,"complete":true,"inPlay":false,"crossMatching":false,"runnersVoidable":false,"numberOfActiveRunners":6,"betDelay":0,"status":"OPEN","runners":[{"status":"ACTIVE","sortPriority":1,"id":68870841,"name":"1. Milton Daisy"},{"status":"ACTIVE","sortPriority":2,"id":58974183,"name":"2. Ballymac Diverse"},{"status":"ACTIVE","sortPriority":3,"id":58462129,"name":"3. Rapido Junior"},{"status":"ACTIVE","sortPriority":4,"id":50281437,"name":"4. Browns Girl"},{"status":"ACTIVE","sortPriority":5,"id":68579508,"name":"5. Ivy Hill Willow"},{"status":"ACTIVE","sortPriority":6,"id":68169358,"name":"6. Spiridon Zelus"}],"regulators":["MR_INT"],"venue":"Towcester","countryCode":"GB","discountAllowed":true,"timezone":"Europe/London","openDate":"2024-06-27T13:33:00.000Z","version":5994767052,"name":"To Be Placed","eventName":"Towcester 27th Jun"},"rc":[],"con":true,"img":false}]}
{"op":"mcm","clk":"11537084062","pt":1719435436502,"mc":[{"id":"1.230180113","rc":[{"atb":[[1.02,25.92]],"id":58974183},{"atl":[[1000,0.84]],"id":58974183},{"spn":500.51,"spf":"NaN","id":58974183},{"atb":[[1.01,51.84]],"id":58462129},{"atl":[[990,0.84]],"id":58462129},{"spn":495.5,"spf":"NaN","id":58462129},{"atb":[[1.02,25.92]],"id":68169358},{"atl":[[990,0.84]],"id":68169358},{"spn":495.51,"spf":"NaN","id":68169358},{"atb":[[1.02,25.92]],"id":68870841},{"atl":[[990,0.84]],"id":68870841},{"spn":495.51,"spf":"NaN","id":68870841},{"atb":[[1.01,51.84]],"id":68579508},{"atl":[[990,0.84]],"id":68579508},{"spn":495.5,"spf":"NaN","id":68579508},{"atb":[[1.01,51.84]],"id":50281437},{"atl":[[1000,0.84]],"id":50281437},{"spn":500.5,"spf":"NaN","id":50281437}],"con":true,"img":false}]}
{"op":"mcm","clk":"11537233751","pt":1719437882660,"mc":[{"id":"1.230180113","marketDefinition":{"bspMarket":true,"turnInPlayEnabled":false,"persistenceEnabled":false,"marketBaseRate":5.0,"eventId":"33376437","eventTypeId":"4339","numberOfWinners":2,"bettingType":"ODDS","marketType":"PLACE","marketTime":"2024-06-27T13:33:00.000Z","suspendTime":"2024-06-27T13:33:00.000Z","bspReconciled":false,"complete":true,"inPlay":false,"crossMatching":false,"runnersVoidable":false,"numberOfActiveRunners":6,"betDelay":0,"status":"OPEN","runners":[{"status":"ACTIVE","sortPriority":1,"id":68870841,"name":"1. Milton Daisy"},{"status":"ACTIVE","sortPriority":2,"id":58974183,"name":"2. Ballymac Diverse"},{"status":"ACTIVE","sortPriority":3,"id":58462129,"name":"3. Rapido Junior"},{"status":"ACTIVE","sortPriority":4,"id":50281437,"name":"4. Browns Girl"},{"status":"ACTIVE","sortPriority":5,"id":68579508,"name":"5. Ivy Hill Willow"},{"status":"ACTIVE","sortPriority":6,"id":68169358,"name":"6. Spiridon Zelus"}],"regulators":["MR_INT"],"venue":"Towcester","countryCode":"GB","discountAllowed":true,"timezone":"Europe/London","openDate":"2024-06-27T13:33:00.000Z","version":5994767052,"name":"To Be Placed","eventName":"Towcester 27th Jun"},"rc":[{"atb":[[1.02,25.92]],"id":58974183},{"atl":[[1000,0.84]],"id":58974183},{"spn":500.51,"spf":"NaN","id":58974183},{"atb":[[1.01,51.85]],"id":58462129},{"atl":[[990,0.84]],"id":58462129},{"spn":495.5,"spf":"NaN","id":58462129},{"atb":[[1.02,25.92]],"id":68169358},{"atl":[[990,0.84]],"id":68169358},{"spn":495.51,"spf":"NaN","id":68169358},{"atb":[[1.02,25.92]],"id":68870841},{"atl":[[990,0.84]],"id":68870841},{"spn":495.51,"spf":"NaN","id":68870841},{"atb":[[1.01,51.85]],"id":68579508},{"atl":[[990,0.84]],"id":68579508},{"spn":495.5,"spf":"NaN","id":68579508},{"atb":[[1.01,51.85]],"id":50281437},{"atl":[[1000,0.84]],"id":50281437},{"spn":500.5,"spf":"NaN","id":50281437}],"con":true,"img":true}]}
{"op":"mcm","clk":"11537302642","pt":1719439041167,"mc":[{"id":"1.230180113","rc":[{"atb":[[1.02,25.92]],"id":58974183},{"atl":[[1000,0.23]],"id":58974183},{"atb":[[1.01,51.85]],"id":58462129},{"atl":[[990,0.23]],"id":58462129},{"atb":[[1.02,25.92]],"id":68169358},{"atl":[[990,0.23]],"id":68169358},{"atb":[[1.02,25.92]],"id":68870841},{"atl":[[990,0.23]],"id":68870841},{"atb":[[1.01,51.85]],"id":68579508},{"atl":[[990,0.23]],"id":68579508},{"atb":[[1.01,51.85]],"id":50281437},{"atl":[[1000,0.23]],"id":50281437}],"con":true,"img":false}]}
{"op":"mcm","clk":"11537574904","pt":1719443282711,"mc":[{"id":"1.230180113","marketDefinition":{"bspMarket":true,"turnInPlayEnabled":false,"persistenceEnabled":false,"marketBaseRate":5.0,"eventId":"33376437","eventTypeId":"4339","numberOfWinners":2,"bettingType":"ODDS","marketType":"PLACE","marketTime":"2024-06-27T13:33:00.000Z","suspendTime":"2024-06-27T13:33:00.000Z","bspReconciled":false,"complete":true,"inPlay":false,"crossMatching":false,"runnersVoidable":false,"numberOfActiveRunners":6,"betDelay":0,"status":"OPEN","runners":[{"status":"ACTIVE","sortPriority":1,"id":68870841,"name":"1. Milton Daisy"},{"status":"ACTIVE","sortPriority":2,"id":58974183,"name":"2. Ballymac Diverse"},{"status":"ACTIVE","sortPriority":3,"id":58462129,"name":"3. Rapido Junior"},{"status":"ACTIVE","sortPriority":4,"id":50281437,"name":"4. Browns Girl"},{"status":"ACTIVE","sortPriority":5,"id":68579508,"name":"5. Ivy Hill Willow"},{"status":"ACTIVE","sortPriority":6,"id":68169358,"name":"6. Spiridon Zelus"}],"regulators":["MR_INT"],"venue":"Towcester","countryCode":"GB","discountAllowed":true,"timezone":"Europe/London","openDate":"2024-06-27T13:33:00.000Z","version":5994767052,"name":"To Be Placed","eventName":"Towcester 27th Jun"},"rc":[{"atb":[[1.02,25.92]],"id":58974183},{"atl":[[1000,0.23]],"id":58974183},{"spn":500.51,"spf":"NaN","id":58974183},{"atb":[[1.01,51.85]],"id":58462129},{"atl":[[990,0.23]],"id":58462129},{"spn":495.5,"spf":"NaN","id":58462129},{"atb":[[1.02,25.92]],"id":68169358},{"atl":[[990,0.23]],"id":68169358},{"spn":495.51,"spf":"NaN","id":68169358},{"atb":[[1.02,25.92]],"id":68870841},{"atl":[[990,0.23]],"id":68870841},{"spn":495.51,"spf":"NaN","id":68870841},{"atb":[[1.01,51.85]],"id":68579508},{"atl":[[990,0.23]],"id":68579508},{"spn":495.5,"spf":"NaN","id":68579508},{"atb":[[1.01,51.85]],"id":50281437},{"atl":[[1000,0.23]],"id":50281437},{"spn":500.5,"spf":"NaN","id":50281437}],"con":true,"img":true}]}
{"op":"mcm","clk":"11537956524","pt":1719448682752,"mc":[{"id":"1.230180113","marketDefinition":{"bspMarket":true,"turnInPlayEnabled":false,"persistenceEnabled":false,"marketBaseRate":5.0,"eventId":"33376437","eventTypeId":"4339","numberOfWinners":2,"bettingType":"ODDS","marketType":"PLACE","marketTime":"2024-06-27T13:33:00.000Z","suspendTime":"2024-06-27T13:33:00.000Z","bspReconciled":false,"complete":true,"inPlay":false,"crossMatching":false,"runnersVoidable":false,"numberOfActiveRunners":6,"betDelay":0,"status":"OPEN","runners":[{"status":"ACTIVE","sortPriority":1,"id":68870841,"name":"1. Milton Daisy"},{"status":"ACTIVE","sortPriority":2,"id":58974183,"name":"2. Ballymac Diverse"},{"status":"ACTIVE","sortPriority":3,"id":58462129,"name":"3. Rapido Junior"},{"status":"ACTIVE","sortPriority":4,"id":50281437,"name":"4. Browns Girl"},{"status":"ACTIVE","sortPriority":5,"id":68579508,"name":"5. Ivy Hill Willow"},{"status":"ACTIVE","sortPriority":6,"id":68169358,"name":"6. Spiridon Zelus"}],"regulators":["MR_INT"],"venue":"Towcester","countryCode":"GB","discountAllowed":true,"timezone":"Europe/London","openDate":"2024-06-27T13:33:00.000Z","version":5994767052,"name":"To Be Placed","eventName":"Towcester 27th Jun"},"rc":[{"atb":[[1.02,25.92]],"id":58974183},{"atl":[[1000,0.23]],"id":58974183},{"spn":500.51,"spf":"NaN","id":58974183},{"atb":[[1.01,51.85]],"id":58462129},{"atl":[[990,0.23]],"id":58462129},{"spn":495.5,"spf":"NaN","id":58462129},{"atb":[[1.02,25.92]],"id":68169358},{"atl":[[990,0.23]],"id":68169358},{"spn":495.51,"spf":"NaN","id":68169358},{"atb":[[1.02,25.92]],"id":68870841},{"atl":[[990,0.23]],"id":68870841},{"spn":495.51,"spf":"NaN","id":68870841},{"atb":[[1.01,51.85]],"id":68579508},{"atl":[[990,0.23]],"id":68579508},{"spn":495.5,"spf":"NaN","id":68579508},{"atb":[[1.01,51.85]],"id":50281437},{"atl":[[1000,0.23]],"id":50281437},{"spn":500.5,"spf":"NaN","id":50281437}],"con":true,"img":true}]}
{"op":"mcm","clk":"11538172141","pt":1719454082695,"mc":[{"id":"1.230180113","marketDefinition":{"bspMarket":true,"turnInPlayEnabled":false,"persistenceEnabled":false,"marketBaseRate":5.0,"eventId":"33376437","eventTypeId":"4339","numberOfWinners":2,"bettingType":"ODDS","marketType":"PLACE","marketTime":"2024-06-27T13:33:00.000Z","suspendTime":"2024-06-27T13:33:00.000Z","bspReconciled":false,"complete":true,"inPlay":false,"crossMatching":false,"runnersVoidable":false,"numberOfActiveRunners":6,"betDelay":0,"status":"OPEN","runners":[{"status":"ACTIVE","sortPriority":1,"id":68870841,"name":"1. Milton Daisy"},{"status":"ACTIVE","sortPriority":2,"id":58974183,"name":"2. Ballymac Diverse"},{"status":"ACTIVE","sortPriority":3,"id":58462129,"name":"3. Rapido Junior"},{"status":"ACTIVE","sortPriority":4,"id":50281437,"name":"4. Browns Girl"},{"status":"ACTIVE","sortPriority":5,"id":68579508,"name":"5. Ivy Hill Willow"},{"status":"ACTIVE","sortPriority":6,"id":68169358,"name":"6. Spiridon Zelus"}],"regulators":["MR_INT"],"venue":"Towcester","countryCode":"GB","discountAllowed":true,"timezone":"Europe/London","openDate":"2024-06-27T13:33:00.000Z","version":5994767052,"name":"To Be Placed","eventName":"Towcester 27th Jun"},"rc":[{"atb":[[1.02,25.93]],"id":58974183},{"atl":[[1000,0.23]],"id":58974183},{"spn":500.51,"spf":"NaN","id":58974183},{"atb":[[1.01,51.86]],"id":58462129},{"atl":[[990,0.23]],"id":58462129},{"spn":495.5,"spf":"NaN","id":58462129},{"atb":[[1.02,25.93]],"id":68169358},{"atl":[[990,0.23]],"id":68169358},{"spn":495.51,"spf":"NaN","id":68169358},{"atb":[[1.02,25.93]],"id":68870841},{"atl":[[990,0.23]],"id":68870841},{"spn":495.51,"spf":"NaN","id":68870841},{"atb":[[1.01,51.86]],"id":68579508},{"atl":[[990,0.23]],"id":68579508},{"spn":495.5,"spf":"NaN","id":68579508},{"atb":[[1.01,51.86]],"id":50281437},{"atl":[[1000,0.23]],"id":50281437},{"spn":500.5,"spf":"NaN","id":50281437}],"con":true,"img":true}]}
{"op":"mcm","clk":"11538369808","pt":1719459482781,"mc":[{"id":"1.230180113","marketDefinition":{"bspMarket":true,"turnInPlayEnabled":false,"persistenceEnabled":false,"marketBaseRate":5.0,"eventId":"33376437","eventTypeId":"4339","numberOfWinners":2,"bettingType":"ODDS","marketType":"PLACE","marketTime":"2024-06-27T13:33:00.000Z","suspendTime":"2024-06-27T13:33:00.000Z","bspReconciled":false,"complete":true,"inPlay":false,"crossMatching":false,"runnersVoidable":false,"numberOfActiveRunners":6,"betDelay":0,"status":"OPEN","runners":[{"status":"ACTIVE","sortPriority":1,"id":68870841,"name":"1. Milton Daisy"},{"status":"ACTIVE","sortPriority":2,"id":58974183,"name":"2. Ballymac Diverse"},{"status":"ACTIVE","sortPriority":3,"id":58462129,"name":"3. Rapido Junior"},{"status":"ACTIVE","sortPriority":4,"id":50281437,"name":"4. Browns Girl"},{"status":"ACTIVE","sortPriority":5,"id":68579508,"name":"5. Ivy Hill Willow"},{"status":"ACTIVE","sortPriority":6,"id":68169358,"name":"6. Spiridon Zelus"}],"regulators":["MR_INT"],"venue":"Towcester","countryCode":"GB","discountAllowed":true,"timezone":"Europe/London","openDate":"2024-06-27T13:33:00.000Z","version":5994767052,"name":"To Be Placed","eventName":"Towcester 27th Jun"},"rc":[{"atb":[[1.02,25.93]],"id":58974183},{"atl":[[1000,0.23]],"id":58974183},{"spn":500.51,"spf":"NaN","id":58974183},{"atb":[[1.01,51.87]],"id":58462129},{"atl":[[990,0.23]],"id":58462129},{"spn":495.5,"spf":"NaN","id":58462129},{"atb":[[1.02,25.93]],"id":68169358},{"atl":[[990,0.23]],"id":68169358},{"spn":495.51,"spf":"NaN","id":68169358},{"atb":[[1.02,25.93]],"id":68870841},{"atl":[[990,0.23]],"id":68870841},{"spn":495.51,"spf":"NaN","id":68870841},{"atb":[[1.01,51.87]],"id":68579508},{"atl":[[990,0.23]],"id":68579508},{"spn":495.5,"spf":"NaN","id":68579508},{"atb":[[1.01,51.87]],"id":50281437},{"atl":[[1000,0.23]],"id":50281437},{"spn":500.5,"spf":"NaN","id":50281437}],"con":true,"img":true}]}
{"op":"mcm","clk":"11538596938","pt":1719464882724,"mc":[{"id":"1.230180113","marketDefinition":{"bspMarket":true,"turnInPlayEnabled":false,"persistenceEnabled":false,"marketBaseRate":5.0,"eventId":"33376437","eventTypeId":"4339","numberOfWinners":2,"bettingType":"ODDS","marketType":"PLACE","marketTime":"2024-06-27T13:33:00.000Z","suspendTime":"2024-06-27T13:33:00.000Z","bspReconciled":false,"complete":true,"inPlay":false,"crossMatching":false,"runnersVoidable":false,"numberOfActiveRunners":6,"betDelay":0,"status":"OPEN","runners":[{"status":"ACTIVE","sortPriority":1,"id":68870841,"name":"1. Milton Daisy"},{"status":"ACTIVE","sortPriority":2,"id":58974183,"name":"2. Ballymac Diverse"},{"status":"ACTIVE","sortPriority":3,"id":58462129,"name":"3. Rapido Junior"},{"status":"ACTIVE","sortPriority":4,"id":50281437,"name":"4. Browns Girl"},{"status":"ACTIVE","sortPriority":5,"id":68579508,"name":"5. Ivy Hill Willow"},{"status":"ACTIVE","sortPriority":6,"id":68169358,"name":"6. Spiridon Zelus"}],"regulators":["MR_INT"],"venue":"Towcester","countryCode":"GB","discountAllowed":true,"timezone":"Europe/London","openDate":"2024-06-27T13:33:00.000Z","version":5994767052,"name":"To Be Placed","eventName":"Towcester 27th Jun"},"rc":[{"atb":[[1.02,25.93]],"id":58974183},{"atl":[[1000,0.23]],"id":58974183},{"spn":500.51,"spf":"NaN","id":58974183},{"atb":[[1.01,51.86]],"id":58462129},{"atl":[[990,0.23]],"id":58462129},{"spn":495.5,"spf":"NaN","id":58462129},{"atb":[[1.02,25.93]],"id":68169358},{"atl":[[990,0.23]],"id":68169358},{"spn":495.51,"spf":"NaN","id":68169358},{"atb":[[1.02,25.93]],"id":68870841},{"atl":[[990,0.23]],"id":68870841},{"spn":495.51,"spf":"NaN","id":68870841},{"atb":[[1.01,51.86]],"id":68579508},{"atl":[[990,0.23]],"id":68579508},{"spn":495.5,"spf":"NaN","id":68579508},{"atb":[[1.01,51.86]],"id":50281437},{"atl":[[1000,0.23]],"id":50281437},{"spn":500.5,"spf":"NaN","id":50281437}],"con":true,"img":true}]}
{"op":"mcm","clk":"11538906792","pt":1719471499626,"mc":[{"id":"1.230180113","rc":[{"atb":[[1.02,25.93],[1.07,2.48]],"id":58974183},{"atl":[[1000,1.23]],"id":58974183},{"spn":500.53,"spf":"NaN","id":58974183},{"atb":[[1.01,51.86],[1.07,2.48]],"id":58462129},{"atl":[[1000,1]],"id":58462129},{"spn":495.53,"spf":"NaN","id":58462129},{"atb":[[1.02,25.93],[1.07,2.48]],"id":68169358},{"atl":[[1000,1]],"id":68169358},{"spn":495.53,"spf":"NaN","id":68169358},{"atb":[[1.02,25.93],[1.07,2.48]],"id":68870841},{"atl":[[1000,1]],"id":68870841},{"spn":495.53,"spf":"NaN","id":68870841},{"atb":[[1.01,51.86],[1.07,2.48]],"id":68579508},{"atl":[[1000,1]],"id":68579508},{"spn":495.53,"spf":"NaN","id":68579508},{"atb":[[1.01,51.86],[1.07,2.48]],"id":50281437},{"atl":[[1000,1.23]],"id":50281437},{"spn":500.53,"spf":"NaN","id":50281437}],"con":true,"img":false}]}
{"op":"mcm","clk":"11538906803","pt":1719471499819,"mc":[{"id":"1.230180113","rc":[{"atl":[[1000,0.71]],"id":58974183},{"atl":[[1000,0.48]],"id":58462129},{"atl":[[1000,0.48]],"id":68169358},{"atl":[[1000,0.48]],"id":68870841},{"atl":[[1000,0.48]],"id":68579508},{"atl":[[1000,0.71]],"id":50281437}],"con":true,"img":false}]}
{"op":"mcm","clk":"11538906815","pt":1719471499981,"mc":[{"id":"1.230180113","rc":[{"atl":[[1000,0.23]],"id":58974183},{"atl":[[1000,0]],"id":58462129},{"atl":[[1000,0]],"id":68169358},{"atl":[[1000,0]],"id":68870841},{"atl":[[1000,0]],"id":68579508},{"atl":[[1000,0.23]],"id":50281437}],"con":true,"img":false}]}
{"op":"mcm","clk":"11538906821","pt":1719471500081,"mc":[{"id":"1.230180113","rc":[{"atl":[[75,0.48]],"id":58974183},{"atl":[[75,0.48]],"id":58462129},{"atl":[[75,0.48]],"id":68169358},{"atl":[[75,0.48]],"id":68870841},{"atl":[[75,0.48]],"id":68579508},{"atl":[[75,0.48]],"id":50281437}],"con":true,"img":false}]}
{"op":"mcm","clk":"11539124126","pt":1719475682711,"mc":[{"id":"1.230180113","marketDefinition":{"bspMarket":true,"turnInPlayEnabled":false,"persistenceEnabled":false,"marketBaseRate":5.0,"eventId":"33376437","eventTypeId":"4339","numberOfWinners":2,"bettingType":"ODDS","marketType":"PLACE","marketTime":"2024-06-27T13:33:00.000Z","suspendTime":"2024-06-27T13:33:00.000Z","bspReconciled":false,"complete":true,"inPlay":false,"crossMatching":false,"runnersVoidable":false,"numberOfActiveRunners":6,"betDelay":0,"status":"OPEN","runners":[{"status":"ACTIVE","sortPriority":1,"id":68870841,"name":"1. Milton Daisy"},{"status":"ACTIVE","sortPriority":2,"id":58974183,"name":"2. Ballymac Diverse"},{"status":"ACTIVE","sortPriority":3,"id":58462129,"name":"3. Rapido Junior"},{"status":"ACTIVE","sortPriority":4,"id":50281437,"name":"4. Browns Girl"},{"status":"ACTIVE","sortPriority":5,"id":68579508,"name":"5. Ivy Hill Willow"},{"status":"ACTIVE","sortPriority":6,"id":68169358,"name":"6. Spiridon Zelus"}],"regulators":["MR_INT"],"venue":"Towcester","countryCode":"GB","discountAllowed":true,"timezone":"Europe/London","openDate":"2024-06-27T13:33:00.000Z","version":5994767052,"name":"To Be Placed","eventName":"Towcester 27th Jun"},"rc":[{"atb":[[1.02,25.92],[1.07,2.48]],"id":58974183},{"atl":[[75,0.48],[1000,0.23]],"id":58974183},{"spn":38.03,"spf":"NaN","id":58974183},{"atb":[[1.01,51.84],[1.07,2.48]],"id":58462129},{"atl":[[75,0.48],[990,0.23]],"id":58462129},{"spn":38.03,"spf":"NaN","id":58462129},{"atb":[[1.02,25.92],[1.07,2.48]],"id":68169358},{"atl":[[75,0.48],[990,0.23]],"id":68169358},{"spn":38.03,"spf":"NaN","id":68169358},{"atb":[[1.02,25.92],[1.07,2.48]],"id":68870841},{"atl":[[75,0.48],[990,0.23]],"id":68870841},{"spn":38.03,"spf":"NaN","id":68870841},{"atb":[[1.01,51.84],[1.07,2.48]],"id":68579508},{"atl":[[75,0.48],[990,0.23]],"id":68579508},{"spn":38.03,"spf":"NaN","id":68579508},{"atb":[[1.01,51.84],[1.07,2.48]],"id":50281437},{"atl":[[75,0.48],[1000,0.23]],"id":50281437},{"spn":38.03,"spf":"NaN","id":50281437}],"con":true,"img":true}]}
{"op":"mcm","clk":"11539440239","pt":1719481082683,"mc":[{"id":"1.230180113","marketDefinition":{"bspMarket":true,"turnInPlayEnabled":false,"persistenceEnabled":false,"marketBaseRate":5.0,"eventId":"33376437","eventTypeId":"4339","numberOfWinners":2,"bettingType":"ODDS","marketType":"PLACE","marketTime":"2024-06-27T13:33:00.000Z","suspendTime":"2024-06-27T13:33:00.000Z","bspReconciled":false,"complete":true,"inPlay":false,"crossMatching":false,"runnersVoidable":false,"numberOfActiveRunners":6,"betDelay":0,"status":"OPEN","runners":[{"status":"ACTIVE","sortPriority":1,"id":68870841,"name":"1. Milton Daisy"},{"status":"ACTIVE","sortPriority":2,"id":58974183,"name":"2. Ballymac Diverse"},{"status":"ACTIVE","sortPriority":3,"id":58462129,"name":"3. Rapido Junior"},{"status":"ACTIVE","sortPriority":4,"id":50281437,"name":"4. Browns Girl"},{"status":"ACTIVE","sortPriority":5,"id":68579508,"name":"5. Ivy Hill Willow"},{"status":"ACTIVE","sortPriority":6,"id":68169358,"name":"6. Spiridon Zelus"}],"regulators":["MR_INT"],"venue":"Towcester","countryCode":"GB","discountAllowed":true,"timezone":"Europe/London","openDate":"2024-06-27T13:33:00.000Z","version":5994767052,"name":"To Be Placed","eventName":"Towcester 27th Jun"},"rc":[{"atb":[[1.02,25.91],[1.07,2.48]],"id":58974183},{"atl":[[75,0.48],[1000,0.23]],"id":58974183},{"spn":38.03,"spf":"NaN","id":58974183},{"atb":[[1.01,51.83],[1.07,2.48]],"id":58462129},{"atl":[[75,0.48],[990,0.23]],"id":58462129},{"spn":38.03,"spf":"NaN","id":58462129},{"atb":[[1.02,25.91],[1.07,2.48]],"id":68169358},{"atl":[[75,0.48],[990,0.23]],"id":68169358},{"spn":38.03,"spf":"NaN","id":68169358},{"atb":[[1.02,25.91],[1.07,2.48]],"id":68870841},{"atl":[[75,0.48],[990,0.23]],"id":68870841},{"spn":38.03,"spf":"NaN","id":68870841},{"atb":[[1.01,51.83],[1.07,2.48]],"id":68579508},{"atl":[[75,0.48],[990,0.23]],"id":68579508},{"spn":38.03,"spf":"NaN","id":68579508},{"atb":[[1.01,51.83],[1.07,2.48]],"id":50281437},{"atl":[[75,0.48],[1000,0.23]],"id":50281437},{"spn":38.03,"spf":"NaN","id":50281437}],"con":true,"img":true}]}
{"op":"mcm","clk":"11540153945","pt":1719490574059,"mc":[{"id":"1.230180113","marketDefinition":{"bspMarket":true,"turnInPlayEnabled":false,"persistenceEnabled":false,"marketBaseRate":5.0,"eventId":"33376437","eventTypeId":"4339","numberOfWinners":2,"bettingType":"ODDS","marketType":"PLACE","marketTime":"2024-06-27T13:33:00.000Z","suspendTime":"2024-06-27T13:33:00.000Z","bspReconciled":false,"complete":true,"inPlay":false,"crossMatching":false,"runnersVoidable":false,"numberOfActiveRunners":6,"betDelay":0,"status":"SUSPENDED","runners":[{"status":"ACTIVE","sortPriority":1,"id":68870841,"name":"1. Milton Daisy"},{"status":"ACTIVE","sortPriority":2,"id":58974183,"name":"2. Ballymac Diverse"},{"status":"ACTIVE","sortPriority":3,"id":58462129,"name":"3. Rapido Junior"},{"status":"ACTIVE","sortPriority":4,"id":50281437,"name":"4. Browns Girl"},{"status":"ACTIVE","sortPriority":5,"id":68579508,"name":"5. Ivy Hill Willow"},{"status":"ACTIVE","sortPriority":6,"id":68169358,"name":"6. Spiridon Zelus"}],"regulators":["MR_INT"],"venue":"Towcester","countryCode":"GB","discountAllowed":true,"timezone":"Europe/London","openDate":"2024-06-27T13:33:00.000Z","version":5995358114,"name":"To Be Placed","eventName":"Towcester 27th Jun"},"rc":[],"con":true,"img":false}]}
{"op":"mcm","clk":"11540153984","pt":1719490574645,"mc":[{"id":"1.230180113","marketDefinition":{"bspMarket":true,"turnInPlayEnabled":false,"persistenceEnabled":false,"marketBaseRate":5.0,"eventId":"33376437","eventTypeId":"4339","numberOfWinners":2,"bettingType":"ODDS","marketType":"PLACE","marketTime":"2024-06-27T13:33:00.000Z","suspendTime":"2024-06-27T13:33:00.000Z","bspReconciled":false,"complete":true,"inPlay":false,"crossMatching":false,"runnersVoidable":false,"numberOfActiveRunners":6,"betDelay":0,"status":"SUSPENDED","runners":[{"status":"ACTIVE","sortPriority":1,"id":68870841,"name":"1. Milton Daisy"},{"status":"ACTIVE","sortPriority":2,"id":58974183,"name":"2. Ballymac Diverse"},{"status":"ACTIVE","sortPriority":3,"id":58462129,"name":"3. Rapido Junior"},{"status":"ACTIVE","sortPriority":4,"id":50281437,"name":"4. Browns Girl"},{"status":"ACTIVE","sortPriority":5,"id":68579508,"name":"5. Ivy Hill Willow"},{"status":"ACTIVE","sortPriority":6,"id":68169358,"name":"6. Spiridon Zelus"}],"regulators":["MR_INT"],"venue":"Towcester","countryCode":"GB","discountAllowed":true,"timezone":"Europe/London","openDate":"2024-06-27T13:33:00.000Z","version":5995358126,"name":"To Be Placed","eventName":"Towcester 27th Jun"},"rc":[],"con":true,"img":false}]}
{"op":"mcm","clk":"11540153984","pt":1719490574645,"mc":[{"id":"1.230180113","rc":[{"atb":[[1.02,0],[1.07,0]],"id":58974183},{"atl":[[75,0],[1000,0]],"id":58974183},{"atb":[[1.01,0],[1.07,0]],"id":58462129},{"atl":[[75,0],[990,0]],"id":58462129},{"atb":[[1.02,0],[1.07,0]],"id":68169358},{"atl":[[75,0],[990,0]],"id":68169358},{"atb":[[1.02,0],[1.07,0]],"id":68870841},{"atl":[[75,0],[990,0]],"id":68870841},{"atb":[[1.01,0],[1.07,0]],"id":68579508},{"atl":[[75,0],[990,0]],"id":68579508},{"atb":[[1.01,0],[1.07,0]],"id":50281437},{"atl":[[75,0],[1000,0]],"id":50281437}],"con":true,"img":false}]}
{"op":"mcm","clk":"11540154014","pt":1719490575026,"mc":[{"id":"1.230180113","marketDefinition":{"bspMarket":true,"turnInPlayEnabled":false,"persistenceEnabled":false,"marketBaseRate":5.0,"eventId":"33376437","eventTypeId":"4339","numberOfWinners":2,"bettingType":"ODDS","marketType":"PLACE","marketTime":"2024-06-27T13:33:00.000Z","suspendTime":"2024-06-27T13:33:00.000Z","bspReconciled":false,"complete":true,"inPlay":false,"crossMatching":false,"runnersVoidable":false,"numberOfActiveRunners":5,"betDelay":0,"status":"OPEN","runners":[{"status":"ACTIVE","sortPriority":1,"id":68870841,"name":"1. Milton Daisy"},{"status":"ACTIVE","sortPriority":2,"id":58974183,"name":"2. Ballymac Diverse"},{"status":"ACTIVE","sortPriority":3,"id":50281437,"name":"4. Browns Girl"},{"status":"ACTIVE","sortPriority":4,"id":68579508,"name":"5. Ivy Hill Willow"},{"status":"ACTIVE","sortPriority":5,"id":68169358,"name":"6. Spiridon Zelus"},{"status":"REMOVED","sortPriority":6,"removalDate":"2024-06-27T12:16:14.000Z","id":58462129,"name":"3. Rapido Junior"}],"regulators":["MR_INT"],"venue":"Towcester","countryCode":"GB","discountAllowed":true,"timezone":"Europe/London","openDate":"2024-06-27T13:33:00.000Z","version":5995358140,"name":"To Be Placed","eventName":"Towcester 27th Jun"},"rc":[],"con":true,"img":false}]}
{"op":"mcm","clk":"11540160972","pt":1719490650130,"mc":[{"id":"1.230180113","rc":[{"atb":[[1.01,102.04]],"id":58974183},{"spn":"Infinity","spf":"NaN","id":58974183},{"atb":[[1.01,102.04]],"id":68870841},{"spn":"Infinity","spf":"NaN","id":68870841}],"con":true,"img":false}]}
{"op":"mcm","clk":"11540160980","pt":1719490650236,"mc":[{"id":"1.230180113","rc":[{"atb":[[1.01,102.04]],"id":68579508},{"atb":[[1.01,102.04]],"id":50281437}],"con":true,"img":false}]}
{"op":"mcm","clk":"11540160996","pt":1719490650449,"mc":[{"id":"1.230180113","rc":[{"atb":[[1.01,102.04]],"id":68169358}],"con":true,"img":false}]}
{"op":"mcm","clk":"11540249588","pt":1719491882663,"mc":[{"id":"1.230180113","marketDefinition":{"bspMarket":true,"turnInPlayEnabled":false,"persistenceEnabled":false,"marketBaseRate":5.0,"eventId":"33376437","eventTypeId":"4339","numberOfWinners":2,"bettingType":"ODDS","marketType":"PLACE","marketTime":"2024-06-27T13:33:00.000Z","suspendTime":"2024-06-27T13:33:00.000Z","bspReconciled":false,"complete":true,"inPlay":false,"crossMatching":false,"runnersVoidable":false,"numberOfActiveRunners":5,"betDelay":0,"status":"OPEN","runners":[{"status":"ACTIVE","sortPriority":1,"id":68870841,"name":"1. Milton Daisy"},{"status":"ACTIVE","sortPriority":2,"id":58974183,"name":"2. Ballymac Diverse"},{"status":"ACTIVE","sortPriority":3,"id":50281437,"name":"4. Browns Girl"},{"status":"ACTIVE","sortPriority":4,"id":68579508,"name":"5. Ivy Hill Willow"},{"status":"ACTIVE","sortPriority":5,"id":68169358,"name":"6. Spiridon Zelus"},{"status":"REMOVED","sortPriority":6,"removalDate":"2024-06-27T12:16:14.000Z","id":58462129,"name":"3. Rapido Junior"}],"regulators":["MR_INT"],"venue":"Towcester","countryCode":"GB","discountAllowed":true,"timezone":"Europe/London","openDate":"2024-06-27T13:33:00.000Z","version":5995358140,"name":"To Be Placed","eventName":"Towcester 27th Jun"},"rc":[{"atb":[[1.01,102.04]],"id":58974183},{"spn":"Infinity","spf":"NaN","id":58974183},{"atb":[[1.01,102.04]],"id":68169358},{"spn":"Infinity","spf":"NaN","id":68169358},{"atb":[[1.01,102.04]],"id":68870841},{"spn":"Infinity","spf":"NaN","id":68870841},{"atb":[[1.01,102.04]],"id":68579508},{"spn":"Infinity","spf":"NaN","id":68579508},{"atb":[[1.01,102.04]],"id":50281437},{"spn":"Infinity","spf":"NaN","id":50281437}],"con":true,"img":true}]}
{"op":"mcm","clk":"11540325295","pt":1719493033133,"mc":[{"id":"1.230180113","rc":[{"atb":[[1.03,5.64]],"id":58974183},{"atl":[[990,0.84]],"id":58974183},{"spn":495.51,"spf":"NaN","id":58974183},{"atb":[[1.03,5.64]],"id":68169358},{"atl":[[1000,0.84]],"id":68169358},{"spn":500.51,"spf":"NaN","id":68169358},{"atb":[[1.03,5.64]],"id":68870841},{"atl":[[990,0.84]],"id":68870841},{"spn":495.51,"spf":"NaN","id":68870841},{"atb":[[1.03,5.64]],"id":68579508},{"atl":[[1000,0.84]],"id":68579508},{"spn":500.51,"spf":"NaN","id":68579508},{"atb":[[1.02,8.46]],"id":50281437},{"atl":[[990,0.84]],"id":50281437},{"spn":495.51,"spf":"NaN","id":50281437}],"con":true,"img":false}]}
{"op":"mcm","clk":"11540355216","pt":1719493457220,"mc":[{"id":"1.230180113","rc":[{"atb":[[1.03,5.64]],"id":58974183},{"atl":[[990,0.84]],"id":58974183},{"atb":[[1.03,5.64],[1.05,79]],"id":68169358},{"atl":[[1000,0.84]],"id":68169358},{"spn":500.52,"spf":"NaN","id":68169358},{"atb":[[1.03,5.64]],"id":68870841},{"atl":[[990,0.84]],"id":68870841},{"atb":[[1.03,5.64]],"id":68579508},{"atl":[[1000,0.84]],"id":68579508},{"atb":[[1.02,8.47]],"id":50281437},{"atl":[[990,0.84]],"id":50281437}],"con":true,"img":false}]}
{"op":"mcm","clk":"11540355229","pt":1719493457432,"mc":[{"id":"1.230180113","rc":[{"atb":[[1.05,79]],"id":58974183},{"atb":[[1.04,98.75]],"id":50281437}],"con":true,"img":false}]}
{"op":"mcm","clk":"11540355272","pt":1719493458045,"mc":[{"id":"1.230180113","rc":[{"atb":[[1.05,79]],"id":68870841},{"atb":[[1.05,79]],"id":68579508}],"con":true,"img":false}]}
{"op":"mcm","clk":"11540357995","pt":1719493490952,"mc":[{"id":"1.230180113","rc":[{"atb":[[1.06,98.81]],"id":68870841}],"con":true,"img":false}]}
{"op":"mcm","clk":"11540358018","pt":1719493491259,"mc":[{"id":"1.230180113","rc":[{"atb":[[1.06,98.81]],"id":58974183},{"atb":[[1.05,118.57]],"id":50281437}],"con":true,"img":false}]}
{"op":"mcm","clk":"11540358042","pt":1719493491570,"mc":[{"id":"1.230180113","rc":[{"atb":[[1.06,98.81]],"id":68579508}],"con":true,"img":false}]}
{"op":"mcm","clk":"11540358070","pt":1719493491878,"mc":[{"id":"1.230180113","rc":[{"atb":[[1.06,98.81]],"id":68169358}],"con":true,"img":false}]}
{"op":"mcm","clk":"11540358261","pt":1719493494683,"mc":[{"id":"1.230180113","rc":[{"atb":[[1.07,79]],"id":58974183},{"atb":[[1.07,79]],"id":68870841}],"con":true,"img":false}]}
{"op":"mcm","clk":"11540358278","pt":1719493494836,"mc":[{"id":"1.230180113","rc":[{"atb":[[1.07,79]],"id":68579508},{"atb":[[1.06,92.17]],"id":50281437}],"con":true,"img":false}]}
{"op":"mcm","clk":"11540358292","pt":1719493495041,"mc":[{"id":"1.230180113","rc":[{"atb":[[1.05,0]],"id":58974183},{"atb":[[1.07,79]],"id":68169358}],"con":true,"img":false}]}
{"op":"mcm","clk":"11540358315","pt":1719493495350,"mc":[{"id":"1.230180113","rc":[{"atb":[[1.05,0]],"id":68870841},{"atb":[[1.04,0]],"id":50281437}],"con":true,"img":false}]}
{"op":"mcm","clk":"11540358337","pt":1719493495663,"mc":[{"id":"1.230180113","rc":[{"atb":[[1.05,0]],"id":68579508}],"con":true,"img":false}]}
{"op":"mcm","clk":"11540358345","pt":1719493495769,"mc":[{"id":"1.230180113","rc":[{"atb":[[1.08,49.37]],"id":58974183}],"con":true,"img":false}]}
{"op":"mcm","clk":"11540358379","pt":1719493496176,"mc":[{"id":"1.230180113","rc":[{"atb":[[1.05,0]],"id":68169358}],"con":true,"img":false}]}
{"op":"mcm","clk":"11540358400","pt":1719493496490,"mc":[{"id":"1.230180113","rc":[{"atb":[[1.08,49.37]],"id":68870841}],"con":true,"img":false}]}
{"op":"mcm","clk":"11540358416","pt":1719493496646,"mc":[{"id":"1.230180113","rc":[{"atb":[[1.08,49.37]],"id":68579508}],"con":true,"img":false}]}
{"op":"mcm","clk":"11540358440","pt":1719493496949,"mc":[{"id":"1.230180113","rc":[{"atb":[[1.07,56.43]],"id":50281437}],"con":true,"img":false}]}
{"op":"mcm","clk":"11540358468","pt":1719493497361,"mc":[{"id":"1.230180113","rc":[{"atb":[[1.08,49.37]],"id":68169358}],"con":true,"img":false}]}
{"op":"mcm","clk":"11540359680","pt":1719493512900,"mc":[{"id":"1.230180113","marketDefinition":{"bspMarket":true,"turnInPlayEnabled":false,"persistenceEnabled":false,"marketBaseRate":5.0,"eventId":"33376437","eventTypeId":"4339","numberOfWinners":2,"bettingType":"ODDS","marketType":"PLACE","marketTime":"2024-06-27T13:33:00.000Z","suspendTime":"2024-06-27T13:33:00.000Z","bspReconciled":false,"complete":true,"inPlay":false,"crossMatching":true,"runnersVoidable":false,"numberOfActiveRunners":5,"betDelay":0,"status":"OPEN","runners":[{"status":"ACTIVE","sortPriority":1,"id":68870841,"name":"1. Milton Daisy"},{"status":"ACTIVE","sortPriority":2,"id":58974183,"name":"2. Ballymac Diverse"},{"status":"ACTIVE","sortPriority":3,"id":50281437,"name":"4. Browns Girl"},{"status":"ACTIVE","sortPriority":4,"id":68579508,"name":"5. Ivy Hill Willow"},{"status":"ACTIVE","sortPriority":5,"id":68169358,"name":"6. Spiridon Zelus"},{"status":"REMOVED","sortPriority":6,"removalDate":"2024-06-27T12:16:14.000Z","id":58462129,"name":"3. Rapido Junior"}],"regulators":["MR_INT"],"venue":"Towcester","countryCode":"GB","discountAllowed":true,"timezone":"Europe/London","openDate":"2024-06-27T13:33:00.000Z","version":5995358140,"name":"To Be Placed","eventName":"Towcester 27th Jun"},"rc":[],"con":true,"img":false}]}
{"op":"mcm","clk":"11540360727","pt":1719493527424,"mc":[{"id":"1.230180113","rc":[{"atb":[[1.06,0]],"id":58974183},{"spn":495.54,"spf":"NaN","id":58974183},{"spn":500.54,"spf":"NaN","id":68169358},{"atb":[[1.06,0]],"id":68870841},{"spn":495.54,"spf":"NaN","id":68870841},{"spn":500.54,"spf":"NaN","id":68579508},{"spn":495.53,"spf":"NaN","id":50281437}],"con":true,"img":false}]}
{"op":"mcm","clk":"11540360760","pt":1719493527787,"mc":[{"id":"1.230180113","rc":[{"atb":[[1.05,0]],"id":50281437}],"con":true,"img":false}]}
{"op":"mcm","clk":"11540360793","pt":1719493528198,"mc":[{"id":"1.230180113","rc":[{"atb":[[1.06,0]],"id":68169358}],"con":true,"img":false}]}
{"op":"mcm","clk":"11540360837","pt":1719493528924,"mc":[{"id":"1.230180113","rc":[{"atb":[[1.09,65.87]],"id":68870841},{"atb":[[1.06,0]],"id":68579508}],"con":true,"img":false}]}
{"op":"mcm","clk":"11540360858","pt":1719493529229,"mc":[{"id":"1.230180113","rc":[{"atb":[[1.09,65.87]],"id":58974183}],"con":true,"img":false}]}
{"op":"mcm","clk":"11540360877","pt":1719493529493,"mc":[{"id":"1.230180113","rc":[{"atb":[[1.08,74.1]],"id":50281437}],"con":true,"img":false}]}
{"op":"mcm","clk":"11540360919","pt":1719493530107,"mc":[{"id":"1.230180113","rc":[{"atb":[[1.09,65.87]],"id":68169358}],"con":true,"img":false}]}
{"op":"mcm","clk":"11540360929","pt":1719493530209,"mc":[{"id":"1.230180113","rc":[{"atb":[[1.09,65.87]],"id":68579508}],"con":true,"img":false}]}
{"op":"mcm","clk":"11540361424","pt":1719493536553,"mc":[{"id":"1.230180113","rc":[{"atb":[[1.07,0]],"id":68870841}],"con":true,"img":false}]}
{"op":"mcm","clk":"11540361445","pt":1719493536709,"mc":[{"id":"1.230180113","rc":[{"atb":[[1.07,0]],"id":68579508}],"con":true,"img":false}]}
{"op":"mcm","clk":"11540361457","pt":1719493536817,"mc":[{"id":"1.230180113","rc":[{"atb":[[1.08,0]],"id":58974183}],"con":true,"img":false}]}
{"op":"mcm","clk":"11540361467","pt":1719493536914,"mc":[{"id":"1.230180113","rc":[{"atb":[[1.08,0]],"id":68870841}],"con":true,"img":false}]}
{"op":"mcm","clk":"11540361478","pt":1719493537024,"mc":[{"id":"1.230180113","rc":[{"atb":[[1.07,0]],"id":58974183}],"con":true,"img":false}]}
{"op":"mcm","clk":"11540361489","pt":1719493537124,"mc":[{"id":"1.230180113","rc":[{"atb":[[1.06,0]],"id":50281437}],"con":true,"img":false}]}
{"op":"mcm","clk":"11540361504","pt":1719493537329,"mc":[{"id":"1.230180113","rc":[{"atb":[[1.07,0]],"id":68169358}],"con":true,"img":false}]}
{"op":"mcm","clk":"11540361523","pt":1719493537539,"mc":[{"id":"1.230180113","rc":[{"atb":[[1.08,0]],"id":68579508}],"con":true,"img":false}]}
{"op":"mcm","clk":"11540361540","pt":1719493537747,"mc":[{"id":"1.230180113","rc":[{"atb":[[1.07,0]],"id":50281437}],"con":true,"img":false}]}
{"op":"mcm","clk":"11540361555","pt":1719493537901,"mc":[{"id":"1.230180113","rc":[{"atb":[[1.1,55.3]],"id":68579508}],"con":true,"img":false}]}
{"op":"mcm","clk":"11540361571","pt":1719493538111,"mc":[{"id":"1.230180113","rc":[{"atb":[[1.11,35.9]],"id":58974183},{"atb":[[1.11,35.9]],"id":68870841}],"con":true,"img":false}]}
{"op":"mcm","clk":"11540361592","pt":1719493538324,"mc":[{"id":"1.230180113","rc":[{"atb":[[1.1,55.3]],"id":58974183}],"con":true,"img":false}]}
{"op":"mcm","clk":"11540361614","pt":1719493538526,"mc":[{"id":"1.230180113","rc":[{"atb":[[1.1,55.3]],"id":68169358},{"atb":[[1.09,61.45]],"id":50281437}],"con":true,"img":false}]}
{"op":"mcm","clk":"11540361639","pt":1719493538839,"mc":[{"id":"1.230180113","rc":[{"atb":[[1.11,35.9]],"id":68579508}],"con":true,"img":false}]}
{"op":"mcm","clk":"11540361684","pt":1719493539311,"mc":[{"id":"1.230180113","rc":[{"atb":[[1.1,55.3]],"id":68870841}],"con":true,"img":false}]}
{"op":"mcm","clk":"11540361697","pt":1719493539411,"mc":[{"id":"1.230180113","rc":[{"atb":[[1.08,0]],"id":68169358}],"con":true,"img":false}]}
{"op":"mcm","clk":"11540361707","pt":1719493539516,"mc":[{"id":"1.230180113","rc":[{"atb":[[1.1,39.5]],"id":50281437}],"con":true,"img":false}]}
{"op":"mcm","clk":"11540361754","pt":1719493540031,"mc":[{"id":"1.230180113","rc":[{"atb":[[1.11,35.9]],"id":68169358}],"con":true,"img":false}]}
{"op":"mcm","clk":"11540363947","pt":1719493568483,"mc":[{"id":"1.230180113","rc":[{"atb":[[1.09,0]],"id":58974183},{"atb":[[1.09,0]],"id":68870841}],"con":true,"img":false}]}
{"op":"mcm","clk":"11540363980","pt":1719493568854,"mc":[{"id":"1.230180113","rc":[{"atb":[[1.09,0]],"id":68169358}],"con":true,"img":false}]}
{"op":"mcm","clk":"11540364011","pt":1719493569274,"mc":[{"id":"1.230180113","rc":[{"atb":[[1.08,0]],"id":50281437}],"con":true,"img":false}]}
{"op":"mcm","clk":"11540364071","pt":1719493569889,"mc":[{"id":"1.230180113","rc":[{"atb":[[1.12,49.4]],"id":58974183}],"con":true,"img":false}]}
{"op":"mcm","clk":"11540364117","pt":1719493570463,"mc":[{"id":"1.230180113","rc":[{"atb":[[1.12,49.4]],"id":68870841}],"con":true,"img":false}]}
{"op":"mcm","clk":"11540364138","pt":1719493570662,"mc":[{"id":"1.230180113","rc":[{"atb":[[1.12,49.4]],"id":68169358}],"con":true,"img":false}]}
{"op":"mcm","clk":"11540364146","pt":1719493570771,"mc":[{"id":"1.230180113","rc":[{"atb":[[1.11,53.9]],"id":50281437}],"con":true,"img":false}]}
{"op":"mcm","clk":"11540364211","pt":1719493571491,"mc":[{"id":"1.230180113","rc":[{"atb":[[1.09,0]],"id":68579508}],"con":true,"img":false}]}
{"op":"mcm","clk":"11540364252","pt":1719493571961,"mc":[{"id":"1.230180113","rc":[{"atb":[[1.12,49.4]],"id":68579508}],"con":true,"img":false}]}
{"op":"mcm","clk":"11540364635","pt":1719493576474,"mc":[{"id":"1.230180113","rc":[{"atb":[[1.1,0]],"id":58974183}],"con":true,"img":false}]}
{"op":"mcm","clk":"11540364642","pt":1719493576582,"mc":[{"id":"1.230180113","rc":[{"atb":[[1.1,0]],"id":68870841}],"con":true,"img":false}]}
{"op":"mcm","clk":"11540364657","pt":1719493576788,"mc":[{"id":"1.230180113","rc":[{"atb":[[1.1,0]],"id":68169358},{"atb":[[1.1,0]],"id":68579508}],"con":true,"img":false}]}
{"op":"mcm","clk":"11540364681","pt":1719493577094,"mc":[{"id":"1.230180113","rc":[{"atb":[[1.09,0],[1.1,0]],"id":50281437}],"con":true,"img":false}]}
{"op":"mcm","clk":"11540364702","pt":1719493577304,"mc":[{"id":"1.230180113","rc":[{"atb":[[1.11,0]],"id":68169358},{"atb":[[1.11,0]],"id":68579508}],"con":true,"img":false}]}
{"op":"mcm","clk":"11540364717","pt":1719493577463,"mc":[{"id":"1.230180113","rc":[{"atb":[[1.13,42.54]],"id":68870841}],"con":true,"img":false}]}
{"op":"mcm","clk":"11540364723","pt":1719493577565,"mc":[{"id":"1.230180113","rc":[{"atb":[[1.13,42.54]],"id":58974183}],"con":true,"img":false}]}
{"op":"mcm","clk":"11540364739","pt":1719493577783,"mc":[{"id":"1.230180113","rc":[{"atb":[[1.11,0]],"id":58974183}],"con":true,"img":false}]}
{"op":"mcm","clk":"11540364752","pt":1719493577984,"mc":[{"id":"1.230180113","rc":[{"atb":[[1.11,0]],"id":68870841}],"con":true,"img":false}]}
{"op":"mcm","clk":"11540364785","pt":1719493578391,"mc":[{"id":"1.230180113","rc":[{"atb":[[1.13,42.54]],"id":68579508}],"con":true,"img":false}]}
{"op":"mcm","clk":"11540364799","pt":1719493578597,"mc":[{"id":"1.230180113","rc":[{"atb":[[1.12,46.08]],"id":50281437}],"con":true,"img":false}]}
{"op":"mcm","clk":"11540364805","pt":1719493578700,"mc":[{"id":"1.230180113","rc":[{"atb":[[1.13,30.38]],"id":50281437}],"con":true,"img":false}]}
{"op":"mcm","clk":"11540364810","pt":1719493578808,"mc":[{"id":"1.230180113","rc":[{"atb":[[1.14,28.21]],"id":68169358}],"con":true,"img":false}]}
{"op":"mcm","clk":"11540364826","pt":1719493578985,"mc":[{"id":"1.230180113","rc":[{"atb":[[1.13,42.54]],"id":68169358}],"con":true,"img":false}]}
{"op":"mcm","clk":"11540364847","pt":1719493579196,"mc":[{"id":"1.230180113","rc":[{"atb":[[1.14,28.21]],"id":68579508}],"con":true,"img":false}]}
{"op":"mcm","clk":"11540364891","pt":1719493579603,"mc":[{"id":"1.230180113","rc":[{"atb":[[1.14,28.21]],"id":58974183}],"con":true,"img":false}]}
{"op":"mcm","clk":"11540364914","pt":1719493579763,"mc":[{"id":"1.230180113","rc":[{"atb":[[1.14,28.21]],"id":68870841}],"con":true,"img":false}]}
{"op":"mcm","clk":"11540367327","pt":1719493609719,"mc":[{"id":"1.230180113","rc":[{"spn":495.57,"spf":"NaN","id":58974183},{"spn":500.57,"spf":"NaN","id":68169358},{"atb":[[1.12,0]],"id":68870841},{"spn":495.57,"spf":"NaN","id":68870841},{"spn":500.57,"spf":"NaN","id":68579508},{"spn":495.56,"spf":"NaN","id":50281437}],"con":true,"img":false}]}
{"op":"mcm","clk":"11540367336","pt":1719493609819,"mc":[{"id":"1.230180113","rc":[{"atb":[[1.12,0]],"id":68169358}],"con":true,"img":false}]}
{"op":"mcm","clk":"11540367364","pt":1719493610129,"mc":[{"id":"1.230180113","rc":[{"atb":[[1.12,0]],"id":68579508},{"atb":[[1.11,0]],"id":50281437}],"con":true,"img":false}]}
{"op":"mcm","clk":"11540367391","pt":1719493610440,"mc":[{"id":"1.230180113","rc":[{"atb":[[1.12,0]],"id":58974183}],"con":true,"img":false}]}
{"op":"mcm","clk":"11540367456","pt":1719493611113,"mc":[{"id":"1.230180113","rc":[{"atb":[[1.15,39.52]],"id":68870841}],"con":true,"img":false}]}
{"op":"mcm","clk":"11540367475","pt":1719493611324,"mc":[{"id":"1.230180113","rc":[{"atb":[[1.15,39.52]],"id":68169358}],"con":true,"img":false}]}
{"op":"mcm","clk":"11540367484","pt":1719493611433,"mc":[{"id":"1.230180113","rc":[{"atb":[[1.15,39.52]],"id":68579508}],"con":true,"img":false}]}
{"op":"mcm","clk":"11540367504","pt":1719493611636,"mc":[{"id":"1.230180113","rc":[{"atb":[[1.14,42.34]],"id":50281437}],"con":true,"img":false}]}
{"op":"mcm","clk":"11540367512","pt":1719493611739,"mc":[{"id":"1.230180113","rc":[{"atb":[[1.15,39.52]],"id":58974183}],"con":true,"img":false}]}
{"op":"mcm","clk":"11540367859","pt":1719493616360,"mc":[{"id":"1.230180113","rc":[{"atb":[[1.13,0]],"id":58974183},{"atb":[[1.13,0]],"id":68870841}],"con":true,"img":false}]}
{"op":"mcm","clk":"11540367871","pt":1719493616567,"mc":[{"id":"1.230180113","rc":[{"atb":[[1.14,0]],"id":68870841},{"atb":[[1.13,0]],"id":68579508}],"con":true,"img":false}]}
{"op":"mcm","clk":"11540367885","pt":1719493616724,"mc":[{"id":"1.230180113","rc":[{"atb":[[1.14,0]],"id":68579508},{"atb":[[1.12,0]],"id":50281437}],"con":true,"img":false}]}
{"op":"mcm","clk":"11540367921","pt":1719493617239,"mc":[{"id":"1.230180113","rc":[{"atb":[[1.13,0]],"id":68169358}],"con":true,"img":false}]}
{"op":"mcm","clk":"11540367941","pt":1719493617548,"mc":[{"id":"1.230180113","rc":[{"atb":[[1.16,34.56]],"id":68870841}],"con":true,"img":false}]}
{"op":"mcm","clk":"11540367949","pt":1719493617650,"mc":[{"id":"1.230180113","rc":[{"atb":[[1.13,0]],"id":50281437}],"con":true,"img":false}]}
{"op":"mcm","clk":"11540367962","pt":1719493617863,"mc":[{"id":"1.230180113","rc":[{"atb":[[1.16,34.56]],"id":68579508}],"con":true,"img":false}]}
{"op":"mcm","clk":"11540367977","pt":1719493618065,"mc":[{"id":"1.230180113","rc":[{"atb":[[1.17,23.23]],"id":68579508}],"con":true,"img":false}]}
{"op":"mcm","clk":"11540367985","pt":1719493618118,"mc":[{"id":"1.230180113","rc":[{"atb":[[1.14,0]],"id":68169358}],"con":true,"img":false}]}
{"op":"mcm","clk":"11540367991","pt":1719493618222,"mc":[{"id":"1.230180113","rc":[{"atb":[[1.16,34.56]],"id":58974183}],"con":true,"img":false}]}
{"op":"mcm","clk":"11540367997","pt":1719493618324,"mc":[{"id":"1.230180113","rc":[{"atb":[[1.17,23.23]],"id":68870841}],"con":true,"img":false}]}
{"op":"mcm","clk":"11540368006","pt":1719493618531,"mc":[{"id":"1.230180113","rc":[{"atb":[[1.15,36.87]],"id":50281437}],"con":true,"img":false}]}
{"op":"mcm","clk":"11540368016","pt":1719493618635,"mc":[{"id":"1.230180113","rc":[{"atb":[[1.14,0]],"id":58974183}],"con":true,"img":false}]}
{"op":"mcm","clk":"11540368030","pt":1719493618841,"mc":[{"id":"1.230180113","rc":[{"atb":[[1.16,34.56]],"id":68169358}],"con":true,"img":false}]}
{"op":"mcm","clk":"11540368102","pt":1719493619627,"mc":[{"id":"1.230180113","rc":[{"atb":[[1.16,24.68]],"id":50281437}],"con":true,"img":false}]}
{"op":"mcm","clk":"11540368119","pt":1719493619836,"mc":[{"id":"1.230180113","rc":[{"atb":[[1.17,23.23]],"id":68169358}],"con":true,"img":false}]}
{"op":"mcm","clk":"11540368128","pt":1719493619937,"mc":[{"id":"1.230180113","rc":[{"atb":[[1.17,23.23]],"id":58974183}],"con":true,"img":false}]}
{"op":"mcm","clk":"11540370508","pt":1719493649304,"mc":[{"id":"1.230180113","rc":[{"atb":[[1.15,0]],"id":58974183},{"atb":[[1.15,0]],"id":68870841}],"con":true,"img":false}]}
{"op":"mcm","clk":"11540370532","pt":1719493649622,"mc":[{"id":"1.230180113","rc":[{"atb":[[1.15,0]],"id":68169358}],"con":true,"img":false}]}
{"op":"mcm","clk":"11540370541","pt":1719493649664,"mc":[{"id":"1.230180113","rc":[{"atb":[[1.15,0]],"id":68579508}],"con":true,"img":false}]}
{"op":"mcm","clk":"11540370586","pt":1719493650392,"mc":[{"id":"1.230180113","rc":[{"atb":[[1.14,0]],"id":50281437}],"con":true,"img":false}]}
{"op":"mcm","clk":"11540370638","pt":1719493651068,"mc":[{"id":"1.230180113","rc":[{"atb":[[1.18,32.93]],"id":58974183},{"atb":[[1.18,32.93]],"id":68870841}],"con":true,"img":false}]}
{"op":"mcm","clk":"11540370661","pt":1719493651379,"mc":[{"id":"1.230180113","rc":[{"atb":[[1.18,32.93]],"id":68169358},{"atb":[[1.18,32.93]],"id":68579508}],"con":true,"img":false}]}
{"op":"mcm","clk":"11540370702","pt":1719493652003,"mc":[{"id":"1.230180113","rc":[{"atb":[[1.17,34.87]],"id":50281437}],"con":true,"img":false}]}
{"op":"mcm","clk":"11540371286","pt":1719493660228,"mc":[{"id":"1.230180113","rc":[{"atb":[[1.16,0]],"id":58974183},{"atb":[[1.16,0]],"id":68870841}],"con":true,"img":false}]}
{"op":"mcm","clk":"11540371310","pt":1719493660490,"mc":[{"id":"1.230180113","rc":[{"atb":[[1.16,0]],"id":68579508},{"atb":[[1.15,0]],"id":50281437}],"con":true,"img":false}]}
{"op":"mcm","clk":"11540371325","pt":1719493660703,"mc":[{"id":"1.230180113","rc":[{"atb":[[1.19,29.1]],"id":58974183}],"con":true,"img":false}]}
{"op":"mcm","clk":"11540371344","pt":1719493660911,"mc":[{"id":"1.230180113","rc":[{"atb":[[1.19,29.1]],"id":68870841},{"atb":[[1.18,30.72]],"id":50281437}],"con":true,"img":false}]}
{"op":"mcm","clk":"11540371396","pt":1719493661424,"mc":[{"id":"1.230180113","rc":[{"atb":[[1.19,29.1]],"id":68579508}],"con":true,"img":false}]}
{"op":"mcm","clk":"11540371416","pt":1719493661634,"mc":[{"id":"1.230180113","rc":[{"atb":[[1.16,0]],"id":68169358}],"con":true,"img":false}]}
{"op":"mcm","clk":"11540371470","pt":1719493662200,"mc":[{"id":"1.230180113","rc":[{"atb":[[1.19,29.1]],"id":68169358}],"con":true,"img":false}]}
{"op":"mcm","clk":"11540373670","pt":1719493691528,"mc":[{"id":"1.230180113","rc":[{"spn":495.59,"spf":"NaN","id":58974183},{"spn":500.59,"spf":"NaN","id":68169358},{"spn":495.59,"spf":"NaN","id":68870841},{"spn":500.59,"spf":"NaN","id":68579508},{"atb":[[1.17,0]],"id":50281437},{"spn":495.59,"spf":"NaN","id":50281437}],"con":true,"img":false}]}
{"op":"mcm","clk":"11540373746","pt":1719493692729,"mc":[{"id":"1.230180113","rc":[{"atb":[[1.19,31.2]],"id":50281437}],"con":true,"img":false}]}
{"op":"mcm","clk":"11540374113","pt":1719493697832,"mc":[{"id":"1.230180113","rc":[{"atb":[[1.18,0]],"id":50281437}],"con":true,"img":false}]}
{"op":"mcm","clk":"11540374166","pt":1719493698617,"mc":[{"id":"1.230180113","rc":[{"atb":[[1.2,27.65]],"id":50281437}],"con":true,"img":false}]}
{"op":"mcm","clk":"11540376747","pt":1719493733105,"mc":[{"id":"1.230180113","rc":[{"atb":[[1.17,0]],"id":58974183},{"atb":[[1.17,0]],"id":68169358},{"atb":[[1.17,0]],"id":68870841},{"atb":[[1.17,0]],"id":68579508}],"con":true,"img":false}]}
{"op":"mcm","clk":"11540379926","pt":1719493772043,"mc":[{"id":"1.230180113","rc":[{"atb":[[1.16,0]],"id":50281437},{"spn":495.6,"spf":"NaN","id":50281437}],"con":true,"img":false}]}
{"op":"mcm","clk":"11540414574","pt":1719494231876,"mc":[{"id":"1.230180113","rc":[{"atb":[[1.18,0]],"id":68870841}],"con":true,"img":false}]}
{"op":"mcm","clk":"11540414645","pt":1719494233005,"mc":[{"id":"1.230180113","rc":[{"atb":[[1.21,20.16]],"id":68870841}],"con":true,"img":false}]}
{"op":"mcm","clk":"11540415061","pt":1719494238603,"mc":[{"id":"1.230180113","rc":[{"atb":[[1.19,0]],"id":68870841}],"con":true,"img":false}]}
{"op":"mcm","clk":"11540415098","pt":1719494239116,"mc":[{"id":"1.230180113","rc":[{"atb":[[1.23,17.17]],"id":68870841}],"con":true,"img":false}]}
{"op":"mcm","clk":"11540416338","pt":1719494257120,"mc":[{"id":"1.230180113","rc":[{"atb":[[1.19,0]],"id":68169358},{"atb":[[1.2,0]],"id":50281437}],"con":true,"img":false}]}
{"op":"mcm","clk":"11540416355","pt":1719494257323,"mc":[{"id":"1.230180113","rc":[{"atb":[[1.22,17.95]],"id":50281437}],"con":true,"img":false}]}
{"op":"mcm","clk":"11540416371","pt":1719494257527,"mc":[{"id":"1.230180113","rc":[{"atb":[[1.21,18.81]],"id":68169358}],"con":true,"img":false}]}
{"op":"mcm","clk":"11540417054","pt":1719494267422,"mc":[{"id":"1.230180113","rc":[{"atb":[[1.18,0]],"id":68169358},{"atb":[[1.19,0]],"id":50281437}],"con":true,"img":false}]}
{"op":"mcm","clk":"11540417156","pt":1719494268917,"mc":[{"id":"1.230180113","rc":[{"atb":[[1.21,0]],"id":68870841}],"con":true,"img":false}]}
{"op":"mcm","clk":"11540417170","pt":1719494269230,"mc":[{"id":"1.230180113","rc":[{"atb":[[1.23,18.41]],"id":68169358},{"atb":[[1.24,17.64]],"id":50281437}],"con":true,"img":false}]}
{"op":"mcm","clk":"11540417283","pt":1719494271137,"mc":[{"id":"1.230180113","rc":[{"atb":[[1.25,16.93]],"id":68870841}],"con":true,"img":false}]}
{"op":"mcm","clk":"11540417716","pt":1719494276645,"mc":[{"id":"1.230180113","rc":[{"atb":[[1.19,0]],"id":58974183}],"con":true,"img":false}]}
{"op":"mcm","clk":"11540417771","pt":1719494277420,"mc":[{"id":"1.230180113","rc":[{"atb":[[1.21,0]],"id":68169358}],"con":true,"img":false}]}
{"op":"mcm","clk":"11540417787","pt":1719494277628,"mc":[{"id":"1.230180113","rc":[{"atb":[[1.22,0]],"id":50281437}],"con":true,"img":false}]}
{"op":"mcm","clk":"11540417833","pt":1719494278246,"mc":[{"id":"1.230180113","rc":[{"atb":[[1.21,18.81]],"id":58974183}],"con":true,"img":false}]}
{"op":"mcm","clk":"11540417883","pt":1719494278863,"mc":[{"id":"1.230180113","rc":[{"atb":[[1.25,15.8]],"id":68169358}],"con":true,"img":false}]}
{"op":"mcm","clk":"11540417908","pt":1719494279118,"mc":[{"id":"1.230180113","rc":[{"atb":[[1.26,15.19]],"id":50281437}],"con":true,"img":false}]}
{"op":"mcm","clk":"11540417995","pt":1719494280256,"mc":[{"id":"1.230180113","rc":[{"atb":[[1.74,18.81]],"id":58974183},{"atl":[[29,2]],"id":58974183},{"atb":[[1.26,15.8]],"id":68169358},{"atl":[[9.4,2]],"id":68169358},{"atb":[[1.67,16.94]],"id":68870841},{"atl":[[23,2]],"id":68870841},{"atb":[[1.45,29.11]],"id":68579508},{"atl":[[12.5,2]],"id":68579508},{"atb":[[1.34,15.19]],"id":50281437},{"atl":[[9.6,2]],"id":50281437}],"con":true,"img":false}]}
{"op":"mcm","clk":"11540418008","pt":1719494280465,"mc":[{"id":"1.230180113","rc":[{"atb":[[2.1,1]],"id":58974183},{"atl":[[6.2,1]],"id":58974183},{"atb":[[1.25,16.8]],"id":68169358},{"atl":[[3.25,1]],"id":68169358},{"atb":[[2.1,1]],"id":68870841},{"atl":[[6.2,1]],"id":68870841},{"atb":[[1.41,1]],"id":68579508},{"atl":[[3.75,1]],"id":68579508},{"atb":[[1.46,1]],"id":50281437},{"atl":[[3.55,1]],"id":50281437}],"con":true,"img":false}]}
{"op":"mcm","clk":"11540418172","pt":1719494282437,"mc":[{"id":"1.230180113","rc":[{"atl":[[1000,1.7]],"id":58974183},{"atb":[[1.01,103.74]],"id":68870841},{"atl":[[1000,1.7]],"id":68870841}],"con":true,"img":false}]}
{"op":"mcm","clk":"11540418181","pt":1719494282542,"mc":[{"id":"1.230180113","rc":[{"atb":[[1.01,103.74]],"id":58974183},{"atb":[[1.01,103.74]],"id":50281437},{"atl":[[1000,1.7]],"id":50281437}],"con":true,"img":false}]}
{"op":"mcm","clk":"11540418196","pt":1719494282749,"mc":[{"id":"1.230180113","rc":[{"atl":[[1000,0.01]],"id":58974183},{"atb":[[1.01,102.5]],"id":68870841},{"atl":[[1000,0.01]],"id":68870841}],"con":true,"img":false}]}
{"op":"mcm","clk":"11540418205","pt":1719494282857,"mc":[{"id":"1.230180113","rc":[{"atb":[[1.01,102.46]],"id":58974183},{"atb":[[1.01,102.94]],"id":50281437},{"atl":[[1000,0.03]],"id":50281437}],"con":true,"img":false}]}
{"op":"mcm","clk":"11540418223","pt":1719494283061,"mc":[{"id":"1.230180113","rc":[{"atl":[[1000,0]],"id":58974183},{"atb":[[1.01,102.04]],"id":68870841},{"atl":[[1000,0]],"id":68870841}],"con":true,"img":false}]}
{"op":"mcm","clk":"11540418231","pt":1719494283164,"mc":[{"id":"1.230180113","rc":[{"atb":[[1.01,102.04]],"id":58974183},{"atl":[[28,0.01]],"id":58974183},{"atb":[[1.68,0.46]],"id":68870841},{"atl":[[22,0.01]],"id":68870841},{"atb":[[1.01,102.04]],"id":50281437},{"atl":[[1000,0]],"id":50281437}],"con":true,"img":false}]}
{"op":"mcm","clk":"11540418241","pt":1719494283227,"mc":[{"id":"1.230180113","rc":[{"atb":[[1.75,0.42]],"id":58974183},{"atb":[[1.35,0.9]],"id":50281437},{"atl":[[9.4,0.03]],"id":50281437}],"con":true,"img":false}]}
{"op":"mcm","clk":"11540418526","pt":1719494286565,"mc":[{"id":"1.230180113","rc":[{"atb":[[1.84,18.81],[1.74,0]],"id":58974183},{"atb":[[1.67,0],[1.76,16.94]],"id":68870841},{"atb":[[1.45,0],[1.52,29.11]],"id":68579508},{"atb":[[1.44,15.19],[1.34,0]],"id":50281437}],"con":true,"img":false}]}
{"op":"mcm","clk":"11540418541","pt":1719494286773,"mc":[{"id":"1.230180113","rc":[{"atl":[[3.7,1],[3.55,0]],"id":50281437}],"con":true,"img":false}]}
{"op":"mcm","clk":"11540419469","pt":1719494298166,"mc":[{"id":"1.230180113","rc":[{"atb":[[1.21,0]],"id":58974183},{"spn":4.15,"spf":"NaN","id":58974183},{"spn":2.25,"spf":"NaN","id":68169358},{"atb":[[1.23,0]],"id":68870841},{"spn":4.15,"spf":"NaN","id":68870841},{"atb":[[1.19,0]],"id":68579508},{"spn":2.63,"spf":"NaN","id":68579508},{"atb":[[1.26,0]],"id":50281437},{"spn":2.58,"spf":"NaN","id":50281437}],"con":true,"img":false}]}
{"op":"mcm","clk":"11540420624","pt":1719494311516,"mc":[{"id":"1.230180113","rc":[{"atb":[[1.18,0]],"id":58974183},{"atb":[[1.25,0]],"id":68870841},{"atb":[[1.18,0]],"id":68579508},{"atb":[[1.24,0]],"id":50281437}],"con":true,"img":false}]}
{"op":"mcm","clk":"11540421595","pt":1719494323726,"mc":[{"id":"1.230180113","rc":[{"atb":[[1.77,2]],"id":68870841}],"con":true,"img":false}]}
{"op":"mcm","clk":"11540421663","pt":1719494324509,"mc":[{"id":"1.230180113","rc":[{"atb":[[1.85,2]],"id":58974183}],"con":true,"img":false}]}
{"op":"mcm","clk":"11540421684","pt":1719494324818,"mc":[{"id":"1.230180113","rc":[{"atb":[[1.45,2]],"id":50281437}],"con":true,"img":false}]}
{"op":"mcm","clk":"11540421712","pt":1719494325131,"mc":[{"id":"1.230180113","rc":[{"atb":[[1.53,2]],"id":68579508}],"con":true,"img":false}]}
{"op":"mcm","clk":"11540421745","pt":1719494325494,"mc":[{"id":"1.230180113","rc":[{"atb":[[1.75,0]],"id":58974183},{"atl":[[28,0]],"id":58974183},{"atb":[[1.27,2]],"id":68169358},{"atb":[[1.68,0]],"id":68870841},{"atl":[[22,0]],"id":68870841},{"atb":[[1.35,0]],"id":50281437},{"atl":[[9.4,0]],"id":50281437}],"con":true,"img":false}]}
{"op":"mcm","clk":"11540421785","pt":1719494326114,"mc":[{"id":"1.230180113","rc":[{"atb":[[1.77,0]],"id":68870841}],"con":true,"img":false}]}
{"op":"mcm","clk":"11540421792","pt":1719494326219,"mc":[{"id":"1.230180113","rc":[{"atb":[[1.02,2]],"id":68870841}],"con":true,"img":false}]}
{"op":"mcm","clk":"11540421816","pt":1719494326535,"mc":[{"id":"1.230180113","rc":[{"atb":[[1.85,0]],"id":58974183}],"con":true,"img":false}]}
{"op":"mcm","clk":"11540421825","pt":1719494326639,"mc":[{"id":"1.230180113","rc":[{"atb":[[1.02,2]],"id":58974183}],"con":true,"img":false}]}
{"op":"mcm","clk":"11540421852","pt":1719494327004,"mc":[{"id":"1.230180113","rc":[{"atb":[[1.45,0]],"id":50281437}],"con":true,"img":false}]}
{"op":"mcm","clk":"11540421859","pt":1719494327113,"mc":[{"id":"1.230180113","rc":[{"atb":[[1.02,10.47]],"id":50281437}],"con":true,"img":false}]}
{"op":"mcm","clk":"11540421898","pt":1719494327529,"mc":[{"id":"1.230180113","rc":[{"atb":[[1.53,0]],"id":68579508}],"con":true,"img":false}]}
{"op":"mcm","clk":"11540421910","pt":1719494327628,"mc":[{"id":"1.230180113","rc":[{"atb":[[1.02,2]],"id":68579508}],"con":true,"img":false}]}
{"op":"mcm","clk":"11540421941","pt":1719494328095,"mc":[{"id":"1.230180113","rc":[{"atb":[[1.02,0]],"id":68870841}],"con":true,"img":false}]}
{"op":"mcm","clk":"11540421951","pt":1719494328202,"mc":[{"id":"1.230180113","rc":[{"atb":[[1.77,2]],"id":68870841}],"con":true,"img":false}]}
{"op":"mcm","clk":"11540421982","pt":1719494328510,"mc":[{"id":"1.230180113","rc":[{"atb":[[1.02,0]],"id":58974183}],"con":true,"img":false}]}
{"op":"mcm","clk":"11540421996","pt":1719494328621,"mc":[{"id":"1.230180113","rc":[{"atb":[[1.85,2]],"id":58974183}],"con":true,"img":false}]}
{"op":"mcm","clk":"11540422037","pt":1719494329129,"mc":[{"id":"1.230180113","rc":[{"atb":[[1.02,8.47]],"id":50281437}],"con":true,"img":false}]}
{"op":"mcm","clk":"11540422050","pt":1719494329233,"mc":[{"id":"1.230180113","rc":[{"atb":[[1.45,2]],"id":50281437}],"con":true,"img":false}]}
{"op":"mcm","clk":"11540422108","pt":1719494329915,"mc":[{"id":"1.230180113","rc":[{"atb":[[1.02,0]],"id":68579508}],"con":true,"img":false}]}
{"op":"mcm","clk":"11540422118","pt":1719494330008,"mc":[{"id":"1.230180113","rc":[{"atb":[[1.53,2]],"id":68579508}],"con":true,"img":false}]}
{"op":"mcm","clk":"11540422159","pt":1719494330631,"mc":[{"id":"1.230180113","rc":[{"atb":[[1.77,0]],"id":68870841}],"con":true,"img":false}]}
{"op":"mcm","clk":"11540422169","pt":1719494330733,"mc":[{"id":"1.230180113","rc":[{"atb":[[1.02,2]],"id":68870841}],"con":true,"img":false}]}
{"op":"mcm","clk":"11540422199","pt":1719494331145,"mc":[{"id":"1.230180113","rc":[{"atb":[[1.85,0]],"id":58974183}],"con":true,"img":false}]}
{"op":"mcm","clk":"11540422214","pt":1719494331256,"mc":[{"id":"1.230180113","rc":[{"atb":[[1.02,2]],"id":58974183}],"con":true,"img":false}]}
{"op":"mcm","clk":"11540422252","pt":1719494331619,"mc":[{"id":"1.230180113","rc":[{"atb":[[1.45,0]],"id":50281437}],"con":true,"img":false}]}
{"op":"mcm","clk":"11540422261","pt":1719494331717,"mc":[{"id":"1.230180113","rc":[{"atb":[[1.02,10.47]],"id":50281437}],"con":true,"img":false}]}
{"op":"mcm","clk":"11540422298","pt":1719494332137,"mc":[{"id":"1.230180113","rc":[{"atb":[[1.53,0]],"id":68579508}],"con":true,"img":false}]}
{"op":"mcm","clk":"11540422309","pt":1719494332238,"mc":[{"id":"1.230180113","rc":[{"atb":[[1.02,2]],"id":68579508}],"con":true,"img":false}]}
{"op":"mcm","clk":"11540422437","pt":1719494333542,"mc":[{"id":"1.230180113","rc":[{"atb":[[1.02,0]],"id":68870841}],"con":true,"img":false}]}
{"op":"mcm","clk":"11540422445","pt":1719494333644,"mc":[{"id":"1.230180113","rc":[{"atb":[[1.77,2]],"id":68870841}],"con":true,"img":false}]}
{"op":"mcm","clk":"11540422483","pt":1719494334058,"mc":[{"id":"1.230180113","rc":[{"atb":[[1.02,0]],"id":58974183}],"con":true,"img":false}]}
{"op":"mcm","clk":"11540422495","pt":1719494334111,"mc":[{"id":"1.230180113","rc":[{"atb":[[1.85,2]],"id":58974183}],"con":true,"img":false}]}
{"op":"mcm","clk":"11540422523","pt":1719494334424,"mc":[{"id":"1.230180113","rc":[{"atb":[[1.02,8.47]],"id":50281437}],"con":true,"img":false}]}
{"op":"mcm","clk":"11540422537","pt":1719494334527,"mc":[{"id":"1.230180113","rc":[{"atb":[[1.45,2]],"id":50281437}],"con":true,"img":false}]}
{"op":"mcm","clk":"11540422565","pt":1719494334834,"mc":[{"id":"1.230180113","rc":[{"atb":[[1.02,0]],"id":68579508}],"con":true,"img":false}]}
{"op":"mcm","clk":"11540422573","pt":1719494334941,"mc":[{"id":"1.230180113","rc":[{"atb":[[1.53,2]],"id":68579508}],"con":true,"img":false}]}
{"op":"mcm","clk":"11540422609","pt":1719494335458,"mc":[{"id":"1.230180113","rc":[{"atb":[[1.77,0]],"id":68870841}],"con":true,"img":false}]}
{"op":"mcm","clk":"11540422620","pt":1719494335511,"mc":[{"id":"1.230180113","rc":[{"atb":[[1.02,2]],"id":68870841}],"con":true,"img":false}]}
{"op":"mcm","clk":"11540422642","pt":1719494335825,"mc":[{"id":"1.230180113","rc":[{"atb":[[1.85,0]],"id":58974183}],"con":true,"img":false}]}
{"op":"mcm","clk":"11540422652","pt":1719494335945,"mc":[{"id":"1.230180113","rc":[{"atb":[[1.02,2]],"id":58974183}],"con":true,"img":false}]}
{"op":"mcm","clk":"11540422669","pt":1719494336132,"mc":[{"id":"1.230180113","rc":[{"atb":[[1.45,0]],"id":50281437}],"con":true,"img":false}]}
{"op":"mcm","clk":"11540422681","pt":1719494336243,"mc":[{"id":"1.230180113","rc":[{"atb":[[1.02,10.47]],"id":50281437}],"con":true,"img":false}]}
{"op":"mcm","clk":"11540422709","pt":1719494336546,"mc":[{"id":"1.230180113","rc":[{"atb":[[1.53,0]],"id":68579508}],"con":true,"img":false}]}
{"op":"mcm","clk":"11540422720","pt":1719494336650,"mc":[{"id":"1.230180113","rc":[{"atb":[[1.02,2]],"id":68579508}],"con":true,"img":false}]}
{"op":"mcm","clk":"11540422800","pt":1719494337443,"mc":[{"id":"1.230180113","rc":[{"atb":[[1.02,0]],"id":68870841}],"con":true,"img":false}]}
{"op":"mcm","clk":"11540422809","pt":1719494337536,"mc":[{"id":"1.230180113","rc":[{"atb":[[1.77,2]],"id":68870841}],"con":true,"img":false}]}
{"op":"mcm","clk":"11540422833","pt":1719494337844,"mc":[{"id":"1.230180113","rc":[{"atb":[[1.02,0]],"id":58974183}],"con":true,"img":false}]}
{"op":"mcm","clk":"11540422843","pt":1719494337953,"mc":[{"id":"1.230180113","rc":[{"atb":[[1.85,2]],"id":58974183}],"con":true,"img":false}]}
{"op":"mcm","clk":"11540422870","pt":1719494338257,"mc":[{"id":"1.230180113","rc":[{"atb":[[1.02,8.47]],"id":50281437}],"con":true,"img":false}]}
{"op":"mcm","clk":"11540422882","pt":1719494338319,"mc":[{"id":"1.230180113","rc":[{"atb":[[1.45,2]],"id":50281437}],"con":true,"img":false}]}
{"op":"mcm","clk":"11540422913","pt":1719494338628,"mc":[{"id":"1.230180113","rc":[{"atb":[[1.02,0]],"id":68579508}],"con":true,"img":false}]}
{"op":"mcm","clk":"11540422921","pt":1719494338728,"mc":[{"id":"1.230180113","rc":[{"atb":[[1.53,2]],"id":68579508}],"con":true,"img":false}]}
{"op":"mcm","clk":"11540422963","pt":1719494339345,"mc":[{"id":"1.230180113","rc":[{"atb":[[1.77,0]],"id":68870841}],"con":true,"img":false}]}
{"op":"mcm","clk":"11540422970","pt":1719494339447,"mc":[{"id":"1.230180113","rc":[{"atb":[[1.02,2]],"id":68870841}],"con":true,"img":false}]}
{"op":"mcm","clk":"11540423039","pt":1719494340230,"mc":[{"id":"1.230180113","rc":[{"atb":[[1.85,0]],"id":58974183}],"con":true,"img":false}]}
{"op":"mcm","clk":"11540423051","pt":1719494340332,"mc":[{"id":"1.230180113","rc":[{"atb":[[1.02,2]],"id":58974183}],"con":true,"img":false}]}
{"op":"mcm","clk":"11540423077","pt":1719494340643,"mc":[{"id":"1.230180113","rc":[{"atb":[[1.45,0]],"id":50281437}],"con":true,"img":false}]}
{"op":"mcm","clk":"11540423084","pt":1719494340749,"mc":[{"id":"1.230180113","rc":[{"atb":[[1.02,10.47]],"id":50281437}],"con":true,"img":false}]}
{"op":"mcm","clk":"11540423127","pt":1719494341160,"mc":[{"id":"1.230180113","rc":[{"atb":[[1.53,0]],"id":68579508}],"con":true,"img":false}]}
{"op":"mcm","clk":"11540423136","pt":1719494341265,"mc":[{"id":"1.230180113","rc":[{"atb":[[1.02,2]],"id":68579508}],"con":true,"img":false}]}
{"op":"mcm","clk":"11540423208","pt":1719494342050,"mc":[{"id":"1.230180113","rc":[{"atb":[[1.02,0]],"id":68870841}],"con":true,"img":false}]}
{"op":"mcm","clk":"11540423216","pt":1719494342151,"mc":[{"id":"1.230180113","rc":[{"atb":[[1.77,2]],"id":68870841}],"con":true,"img":false}]}
{"op":"mcm","clk":"11540423242","pt":1719494342466,"mc":[{"id":"1.230180113","rc":[{"atb":[[1.02,0]],"id":58974183}],"con":true,"img":false}]}
{"op":"mcm","clk":"11540423252","pt":1719494342565,"mc":[{"id":"1.230180113","rc":[{"atb":[[1.85,2]],"id":58974183}],"con":true,"img":false}]}
{"op":"mcm","clk":"11540423278","pt":1719494342830,"mc":[{"id":"1.230180113","rc":[{"atb":[[1.02,8.47]],"id":50281437}],"con":true,"img":false}]}
{"op":"mcm","clk":"11540423288","pt":1719494342937,"mc":[{"id":"1.230180113","rc":[{"atb":[[1.45,2]],"id":50281437}],"con":true,"img":false}]}
{"op":"mcm","clk":"11540423315","pt":1719494343244,"mc":[{"id":"1.230180113","rc":[{"atb":[[1.02,0]],"id":68579508}],"con":true,"img":false}]}
{"op":"mcm","clk":"11540423322","pt":1719494343352,"mc":[{"id":"1.230180113","rc":[{"atb":[[1.53,2]],"id":68579508}],"con":true,"img":false}]}
{"op":"mcm","clk":"11540423365","pt":1719494343769,"mc":[{"id":"1.230180113","rc":[{"atb":[[1.77,0]],"id":68870841}],"con":true,"img":false}]}
{"op":"mcm","clk":"11540423376","pt":1719494343870,"mc":[{"id":"1.230180113","rc":[{"atb":[[1.02,2]],"id":68870841}],"con":true,"img":false}]}
{"op":"mcm","clk":"11540423405","pt":1719494344131,"mc":[{"id":"1.230180113","rc":[{"atb":[[1.85,0]],"id":58974183}],"con":true,"img":false}]}
{"op":"mcm","clk":"11540423415","pt":1719494344236,"mc":[{"id":"1.230180113","rc":[{"atb":[[1.02,2]],"id":58974183}],"con":true,"img":false}]}
{"op":"mcm","clk":"11540423435","pt":1719494344444,"mc":[{"id":"1.230180113","rc":[{"atb":[[1.45,0]],"id":50281437}],"con":true,"img":false}]}
{"op":"mcm","clk":"11540423445","pt":1719494344546,"mc":[{"id":"1.230180113","rc":[{"atb":[[1.02,10.47]],"id":50281437}],"con":true,"img":false}]}
{"op":"mcm","clk":"11540423462","pt":1719494344751,"mc":[{"id":"1.230180113","rc":[{"atb":[[1.53,0]],"id":68579508}],"con":true,"img":false}]}
{"op":"mcm","clk":"11540423476","pt":1719494344853,"mc":[{"id":"1.230180113","rc":[{"atb":[[1.02,2]],"id":68579508}],"con":true,"img":false}]}
{"op":"mcm","clk":"11540423555","pt":1719494345431,"mc":[{"id":"1.230180113","rc":[{"atb":[[1.02,0]],"id":68870841}],"con":true,"img":false}]}
{"op":"mcm","clk":"11540423562","pt":1719494345555,"mc":[{"id":"1.230180113","rc":[{"atb":[[1.77,2]],"id":68870841}],"con":true,"img":false}]}
{"op":"mcm","clk":"11540423607","pt":1719494346047,"mc":[{"id":"1.230180113","rc":[{"atb":[[1.02,0]],"id":58974183}],"con":true,"img":false}]}
{"op":"mcm","clk":"11540423621","pt":1719494346149,"mc":[{"id":"1.230180113","rc":[{"atb":[[1.85,2]],"id":58974183}],"con":true,"img":false}]}
{"op":"mcm","clk":"11540423658","pt":1719494346563,"mc":[{"id":"1.230180113","rc":[{"atb":[[1.02,8.47]],"id":50281437}],"con":true,"img":false}]}
{"op":"mcm","clk":"11540423668","pt":1719494346667,"mc":[{"id":"1.230180113","rc":[{"atb":[[1.45,2]],"id":50281437}],"con":true,"img":false}]}
{"op":"mcm","clk":"11540423722","pt":1719494347147,"mc":[{"id":"1.230180113","rc":[{"atb":[[1.02,0]],"id":68579508}],"con":true,"img":false}]}
{"op":"mcm","clk":"11540423732","pt":1719494347245,"mc":[{"id":"1.230180113","rc":[{"atb":[[1.53,2]],"id":68579508}],"con":true,"img":false}]}
{"op":"mcm","clk":"11540423846","pt":1719494348546,"mc":[{"id":"1.230180113","rc":[{"atb":[[1.77,0]],"id":68870841}],"con":true,"img":false}]}
{"op":"mcm","clk":"11540423854","pt":1719494348649,"mc":[{"id":"1.230180113","rc":[{"atb":[[1.02,2]],"id":68870841}],"con":true,"img":false}]}
{"op":"mcm","clk":"11540423885","pt":1719494349063,"mc":[{"id":"1.230180113","rc":[{"atb":[[1.85,0]],"id":58974183}],"con":true,"img":false}]}
{"op":"mcm","clk":"11540423892","pt":1719494349167,"mc":[{"id":"1.230180113","rc":[{"atb":[[1.02,2]],"id":58974183}],"con":true,"img":false}]}
{"op":"mcm","clk":"11540423917","pt":1719494349478,"mc":[{"id":"1.230180113","rc":[{"atb":[[1.45,0]],"id":50281437}],"con":true,"img":false}]}
{"op":"mcm","clk":"11540423930","pt":1719494349529,"mc":[{"id":"1.230180113","rc":[{"atb":[[1.02,10.47]],"id":50281437}],"con":true,"img":false}]}
{"op":"mcm","clk":"11540423960","pt":1719494349947,"mc":[{"id":"1.230180113","rc":[{"atb":[[1.53,0]],"id":68579508}],"con":true,"img":false}]}
{"op":"mcm","clk":"11540423973","pt":1719494350054,"mc":[{"id":"1.230180113","rc":[{"atb":[[1.02,2]],"id":68579508}],"con":true,"img":false}]}
{"op":"mcm","clk":"11540424022","pt":1719494350664,"mc":[{"id":"1.230180113","rc":[{"atb":[[1.02,0]],"id":68870841}],"con":true,"img":false}]}
{"op":"mcm","clk":"11540424031","pt":1719494350768,"mc":[{"id":"1.230180113","rc":[{"atb":[[1.77,2]],"id":68870841}],"con":true,"img":false}]}
{"op":"mcm","clk":"11540424060","pt":1719494351031,"mc":[{"id":"1.230180113","rc":[{"atb":[[1.02,0]],"id":58974183}],"con":true,"img":false}]}
{"op":"mcm","clk":"11540424072","pt":1719494351137,"mc":[{"id":"1.230180113","rc":[{"atb":[[1.85,2]],"id":58974183}],"con":true,"img":false}]}
{"op":"mcm","clk":"11540424097","pt":1719494351453,"mc":[{"id":"1.230180113","rc":[{"atb":[[1.02,8.47]],"id":50281437}],"con":true,"img":false}]}
{"op":"mcm","clk":"11540424107","pt":1719494351555,"mc":[{"id":"1.230180113","rc":[{"atb":[[1.45,2]],"id":50281437}],"con":true,"img":false}]}
{"op":"mcm","clk":"11540424139","pt":1719494351966,"mc":[{"id":"1.230180113","rc":[{"atb":[[1.02,0]],"id":68579508}],"con":true,"img":false}]}
{"op":"mcm","clk":"11540424146","pt":1719494352068,"mc":[{"id":"1.230180113","rc":[{"atb":[[1.53,2]],"id":68579508}],"con":true,"img":false}]}
{"op":"mcm","clk":"11540424192","pt":1719494352537,"mc":[{"id":"1.230180113","rc":[{"atb":[[1.77,0]],"id":68870841}],"con":true,"img":false}]}
{"op":"mcm","clk":"11540424198","pt":1719494352641,"mc":[{"id":"1.230180113","rc":[{"atb":[[1.02,2]],"id":68870841}],"con":true,"img":false}]}
{"op":"mcm","clk":"11540424229","pt":1719494353059,"mc":[{"id":"1.230180113","rc":[{"atb":[[1.85,0]],"id":58974183}],"con":true,"img":false}]}
{"op":"mcm","clk":"11540424240","pt":1719494353159,"mc":[{"id":"1.230180113","rc":[{"atb":[[1.02,2]],"id":58974183}],"con":true,"img":false}]}
{"op":"mcm","clk":"11540424269","pt":1719494353569,"mc":[{"id":"1.230180113","rc":[{"atb":[[1.45,0]],"id":50281437}],"con":true,"img":false}]}
{"op":"mcm","clk":"11540424277","pt":1719494353671,"mc":[{"id":"1.230180113","rc":[{"atb":[[1.02,10.47]],"id":50281437}],"con":true,"img":false}]}
{"op":"mcm","clk":"11540424307","pt":1719494354041,"mc":[{"id":"1.230180113","rc":[{"atb":[[1.53,0]],"id":68579508}],"con":true,"img":false}]}
{"op":"mcm","clk":"11540424320","pt":1719494354142,"mc":[{"id":"1.230180113","rc":[{"atb":[[1.02,2]],"id":68579508}],"con":true,"img":false}]}
{"op":"mcm","clk":"11540424425","pt":1719494355243,"mc":[{"id":"1.230180113","rc":[{"atb":[[1.02,0]],"id":68870841}],"con":true,"img":false}]}
{"op":"mcm","clk":"11540424436","pt":1719494355345,"mc":[{"id":"1.230180113","rc":[{"atb":[[1.77,2]],"id":68870841}],"con":true,"img":false}]}
{"op":"mcm","clk":"11540424472","pt":1719494355659,"mc":[{"id":"1.230180113","rc":[{"atb":[[1.02,0]],"id":58974183}],"con":true,"img":false}]}
{"op":"mcm","clk":"11540424482","pt":1719494355755,"mc":[{"id":"1.230180113","rc":[{"atb":[[1.85,2]],"id":58974183}],"con":true,"img":false}]}
{"op":"mcm","clk":"11540424496","pt":1719494355968,"mc":[{"id":"1.230180113","rc":[{"atb":[[1.02,8.47]],"id":50281437}],"con":true,"img":false}]}
{"op":"mcm","clk":"11540424504","pt":1719494356068,"mc":[{"id":"1.230180113","rc":[{"atb":[[1.45,2]],"id":50281437}],"con":true,"img":false}]}
{"op":"mcm","clk":"11540424528","pt":1719494356378,"mc":[{"id":"1.230180113","rc":[{"atb":[[1.02,0]],"id":68579508}],"con":true,"img":false}]}
{"op":"mcm","clk":"11540424540","pt":1719494356478,"mc":[{"id":"1.230180113","rc":[{"atb":[[1.53,2]],"id":68579508}],"con":true,"img":false}]}
{"op":"mcm","clk":"11540424609","pt":1719494357256,"mc":[{"id":"1.230180113","rc":[{"atb":[[1.77,0]],"id":68870841}],"con":true,"img":false}]}
{"op":"mcm","clk":"11540424619","pt":1719494357362,"mc":[{"id":"1.230180113","rc":[{"atb":[[1.02,2]],"id":68870841}],"con":true,"img":false}]}
{"op":"mcm","clk":"11540424654","pt":1719494357769,"mc":[{"id":"1.230180113","rc":[{"atb":[[1.85,0]],"id":58974183}],"con":true,"img":false}]}
{"op":"mcm","clk":"11540424662","pt":1719494357871,"mc":[{"id":"1.230180113","rc":[{"atb":[[1.02,2]],"id":58974183}],"con":true,"img":false}]}
{"op":"mcm","clk":"11540424701","pt":1719494358343,"mc":[{"id":"1.230180113","rc":[{"spn":2.26,"spf":"NaN","id":68169358},{"spn":2.64,"spf":"NaN","id":68579508},{"atb":[[1.45,0]],"id":50281437}],"con":true,"img":false}]}
{"op":"mcm","clk":"11540424710","pt":1719494358444,"mc":[{"id":"1.230180113","rc":[{"atb":[[1.02,10.47]],"id":50281437}],"con":true,"img":false}]}
{"op":"mcm","clk":"11540424735","pt":1719494358852,"mc":[{"id":"1.230180113","rc":[{"atb":[[1.53,0]],"id":68579508}],"con":true,"img":false}]}
{"op":"mcm","clk":"11540424740","pt":1719494358960,"mc":[{"id":"1.230180113","rc":[{"atb":[[1.02,2]],"id":68579508}],"con":true,"img":false}]}
{"op":"mcm","clk":"11540424781","pt":1719494359677,"mc":[{"id":"1.230180113","rc":[{"atb":[[1.02,0]],"id":68870841}],"con":true,"img":false}]}
{"op":"mcm","clk":"11540424787","pt":1719494359779,"mc":[{"id":"1.230180113","rc":[{"atb":[[1.77,2]],"id":68870841}],"con":true,"img":false}]}
{"op":"mcm","clk":"11540424817","pt":1719494360147,"mc":[{"id":"1.230180113","rc":[{"atb":[[1.02,0]],"id":58974183}],"con":true,"img":false}]}
{"op":"mcm","clk":"11540424828","pt":1719494360248,"mc":[{"id":"1.230180113","rc":[{"atb":[[1.85,2]],"id":58974183}],"con":true,"img":false}]}
{"op":"mcm","clk":"11540424863","pt":1719494360658,"mc":[{"id":"1.230180113","rc":[{"atb":[[1.02,8.47]],"id":50281437}],"con":true,"img":false}]}
{"op":"mcm","clk":"11540424872","pt":1719494360763,"mc":[{"id":"1.230180113","rc":[{"atb":[[1.45,2]],"id":50281437}],"con":true,"img":false}]}
{"op":"mcm","clk":"11540424898","pt":1719494361077,"mc":[{"id":"1.230180113","rc":[{"atb":[[1.02,0]],"id":68579508}],"con":true,"img":false}]}
{"op":"mcm","clk":"11540424908","pt":1719494361178,"mc":[{"id":"1.230180113","rc":[{"atb":[[1.53,2]],"id":68579508}],"con":true,"img":false}]}
{"op":"mcm","clk":"11540425031","pt":1719494362786,"mc":[{"id":"1.230180113","rc":[{"atb":[[1.77,0]],"id":68870841}],"con":true,"img":false}]}
{"op":"mcm","clk":"11540425036","pt":1719494362854,"mc":[{"id":"1.230180113","rc":[{"atb":[[1.02,2]],"id":68870841}],"con":true,"img":false}]}
{"op":"mcm","clk":"11540425058","pt":1719494363259,"mc":[{"id":"1.230180113","rc":[{"atb":[[1.85,0]],"id":58974183}],"con":true,"img":false}]}
{"op":"mcm","clk":"11540425066","pt":1719494363369,"mc":[{"id":"1.230180113","rc":[{"atb":[[1.02,2]],"id":58974183}],"con":true,"img":false}]}
{"op":"mcm","clk":"11540425098","pt":1719494363674,"mc":[{"id":"1.230180113","rc":[{"atb":[[1.45,0]],"id":50281437}],"con":true,"img":false}]}
{"op":"mcm","clk":"11540425109","pt":1719494363778,"mc":[{"id":"1.230180113","rc":[{"atb":[[1.02,10.47]],"id":50281437}],"con":true,"img":false}]}
{"op":"mcm","clk":"11540425138","pt":1719494364045,"mc":[{"id":"1.230180113","rc":[{"atb":[[1.53,0]],"id":68579508}],"con":true,"img":false}]}
{"op":"mcm","clk":"11540425146","pt":1719494364148,"mc":[{"id":"1.230180113","rc":[{"atb":[[1.02,2]],"id":68579508}],"con":true,"img":false}]}
{"op":"mcm","clk":"11540425195","pt":1719494364774,"mc":[{"id":"1.230180113","rc":[{"atb":[[1.02,0]],"id":68870841}],"con":true,"img":false}]}
{"op":"mcm","clk":"11540425207","pt":1719494364877,"mc":[{"id":"1.230180113","rc":[{"atb":[[1.77,2]],"id":68870841}],"con":true,"img":false}]}
{"op":"mcm","clk":"11540425236","pt":1719494365192,"mc":[{"id":"1.230180113","rc":[{"atb":[[1.02,0]],"id":58974183}],"con":true,"img":false}]}
{"op":"mcm","clk":"11540425245","pt":1719494365289,"mc":[{"id":"1.230180113","rc":[{"atb":[[1.85,2]],"id":58974183}],"con":true,"img":false}]}
{"op":"mcm","clk":"11540425277","pt":1719494365561,"mc":[{"id":"1.230180113","rc":[{"atb":[[1.02,8.47]],"id":50281437}],"con":true,"img":false}]}
{"op":"mcm","clk":"11540425287","pt":1719494365658,"mc":[{"id":"1.230180113","rc":[{"atb":[[1.45,2]],"id":50281437}],"con":true,"img":false}]}
{"op":"mcm","clk":"11540425340","pt":1719494366281,"mc":[{"id":"1.230180113","rc":[{"atb":[[1.02,0]],"id":68579508}],"con":true,"img":false}]}
{"op":"mcm","clk":"11540425350","pt":1719494366388,"mc":[{"id":"1.230180113","rc":[{"atb":[[1.53,2]],"id":68579508}],"con":true,"img":false}]}
{"op":"mcm","clk":"11540425427","pt":1719494367165,"mc":[{"id":"1.230180113","rc":[{"atb":[[1.77,0]],"id":68870841}],"con":true,"img":false}]}
{"op":"mcm","clk":"11540425431","pt":1719494367269,"mc":[{"id":"1.230180113","rc":[{"atb":[[1.02,2]],"id":68870841}],"con":true,"img":false}]}
{"op":"mcm","clk":"11540425444","pt":1719494367586,"mc":[{"id":"1.230180113","rc":[{"atb":[[1.85,0]],"id":58974183}],"con":true,"img":false}]}
{"op":"mcm","clk":"11540425452","pt":1719494367689,"mc":[{"id":"1.230180113","rc":[{"atb":[[1.02,2]],"id":58974183}],"con":true,"img":false}]}
{"op":"mcm","clk":"11540425470","pt":1719494367996,"mc":[{"id":"1.230180113","rc":[{"atb":[[1.45,0]],"id":50281437}],"con":true,"img":false}]}
{"op":"mcm","clk":"11540425479","pt":1719494368059,"mc":[{"id":"1.230180113","rc":[{"atb":[[1.02,10.47]],"id":50281437}],"con":true,"img":false}]}
{"op":"mcm","clk":"11540425500","pt":1719494368369,"mc":[{"id":"1.230180113","rc":[{"atb":[[1.53,0]],"id":68579508}],"con":true,"img":false}]}
{"op":"mcm","clk":"11540425510","pt":1719494368474,"mc":[{"id":"1.230180113","rc":[{"atb":[[1.02,2]],"id":68579508}],"con":true,"img":false}]}
{"op":"mcm","clk":"11540425551","pt":1719494368994,"mc":[{"id":"1.230180113","rc":[{"atb":[[1.02,0]],"id":68870841}],"con":true,"img":false}]}
{"op":"mcm","clk":"11540425562","pt":1719494369092,"mc":[{"id":"1.230180113","rc":[{"atb":[[1.77,2]],"id":68870841}],"con":true,"img":false}]}
{"op":"mcm","clk":"11540425576","pt":1719494369297,"mc":[{"id":"1.230180113","rc":[{"atb":[[1.02,0]],"id":58974183}],"con":true,"img":false}]}
{"op":"mcm","clk":"11540425586","pt":1719494369351,"mc":[{"id":"1.230180113","rc":[{"atb":[[1.85,2]],"id":58974183}],"con":true,"img":false}]}
{"op":"mcm","clk":"11540425598","pt":1719494369559,"mc":[{"id":"1.230180113","rc":[{"atb":[[1.02,8.47]],"id":50281437}],"con":true,"img":false}]}
{"op":"mcm","clk":"11540425605","pt":1719494369659,"mc":[{"id":"1.230180113","rc":[{"atb":[[1.45,2]],"id":50281437}],"con":true,"img":false}]}
{"op":"mcm","clk":"11540425632","pt":1719494369996,"mc":[{"id":"1.230180113","rc":[{"atb":[[1.02,0]],"id":68579508}],"con":true,"img":false}]}
{"op":"mcm","clk":"11540425642","pt":1719494370073,"mc":[{"id":"1.230180113","rc":[{"atb":[[1.53,2]],"id":68579508}],"con":true,"img":false}]}
{"op":"mcm","clk":"11540425699","pt":1719494370805,"mc":[{"id":"1.230180113","rc":[{"atb":[[1.77,0]],"id":68870841}],"con":true,"img":false}]}
{"op":"mcm","clk":"11540425709","pt":1719494370856,"mc":[{"id":"1.230180113","rc":[{"atb":[[1.02,2]],"id":68870841}],"con":true,"img":false}]}
{"op":"mcm","clk":"11540425734","pt":1719494371167,"mc":[{"id":"1.230180113","rc":[{"atb":[[1.25,1]],"id":68169358}],"con":true,"img":false}]}
{"op":"mcm","clk":"11540425744","pt":1719494371274,"mc":[{"id":"1.230180113","rc":[{"atb":[[1.85,0]],"id":58974183}],"con":true,"img":false}]}
{"op":"mcm","clk":"11540425753","pt":1719494371371,"mc":[{"id":"1.230180113","rc":[{"atb":[[1.02,2]],"id":58974183}],"con":true,"img":false}]}
{"op":"mcm","clk":"11540425786","pt":1719494371787,"mc":[{"id":"1.230180113","rc":[{"atb":[[1.45,0]],"id":50281437}],"con":true,"img":false}]}
{"op":"mcm","clk":"11540425799","pt":1719494371894,"mc":[{"id":"1.230180113","rc":[{"atb":[[1.02,10.47]],"id":50281437}],"con":true,"img":false}]}
{"op":"mcm","clk":"11540425835","pt":1719494372196,"mc":[{"id":"1.230180113","rc":[{"atb":[[1.53,0]],"id":68579508}],"con":true,"img":false}]}
{"op":"mcm","clk":"11540425847","pt":1719494372257,"mc":[{"id":"1.230180113","rc":[{"atb":[[1.02,2]],"id":68579508}],"con":true,"img":false}]}
{"op":"mcm","clk":"11540425897","pt":1719494372782,"mc":[{"id":"1.230180113","rc":[{"atb":[[1.02,0]],"id":68870841}],"con":true,"img":false}]}
{"op":"mcm","clk":"11540425914","pt":1719494372880,"mc":[{"id":"1.230180113","rc":[{"atb":[[1.77,2]],"id":68870841}],"con":true,"img":false}]}
{"op":"mcm","clk":"11540425959","pt":1719494373399,"mc":[{"id":"1.230180113","rc":[{"atb":[[1.02,0]],"id":58974183}],"con":true,"img":false}]}
{"op":"mcm","clk":"11540425969","pt":1719494373500,"mc":[{"id":"1.230180113","rc":[{"atb":[[1.85,2]],"id":58974183}],"con":true,"img":false}]}
{"op":"mcm","clk":"11540426010","pt":1719494373972,"mc":[{"id":"1.230180113","rc":[{"atb":[[1.02,8.47]],"id":50281437}],"con":true,"img":false}]}
{"op":"mcm","clk":"11540426022","pt":1719494374079,"mc":[{"id":"1.230180113","rc":[{"atb":[[1.45,2]],"id":50281437}],"con":true,"img":false}]}
{"op":"mcm","clk":"11540426050","pt":1719494374393,"mc":[{"id":"1.230180113","rc":[{"atb":[[1.02,0]],"id":68579508}],"con":true,"img":false}]}
{"op":"mcm","clk":"11540426057","pt":1719494374493,"mc":[{"id":"1.230180113","rc":[{"atb":[[1.53,2]],"id":68579508}],"con":true,"img":false}]}
{"op":"mcm","clk":"11540426128","pt":1719494375271,"mc":[{"id":"1.230180113","rc":[{"atb":[[1.77,0]],"id":68870841}],"con":true,"img":false}]}
{"op":"mcm","clk":"11540426136","pt":1719494375370,"mc":[{"id":"1.230180113","rc":[{"atb":[[1.02,2]],"id":68870841}],"con":true,"img":false}]}
{"op":"mcm","clk":"11540426157","pt":1719494375679,"mc":[{"id":"1.230180113","rc":[{"atb":[[1.85,0]],"id":58974183}],"con":true,"img":false}]}
{"op":"mcm","clk":"11540426168","pt":1719494375784,"mc":[{"id":"1.230180113","rc":[{"atb":[[1.02,2]],"id":58974183}],"con":true,"img":false}]}
{"op":"mcm","clk":"11540426218","pt":1719494376405,"mc":[{"id":"1.230180113","rc":[{"atb":[[1.45,0]],"id":50281437}],"con":true,"img":false}]}
{"op":"mcm","clk":"11540426227","pt":1719494376508,"mc":[{"id":"1.230180113","rc":[{"atb":[[1.02,10.47]],"id":50281437}],"con":true,"img":false}]}
{"op":"mcm","clk":"11540426258","pt":1719494376982,"mc":[{"id":"1.230180113","rc":[{"atb":[[1.53,0]],"id":68579508}],"con":true,"img":false}]}
{"op":"mcm","clk":"11540426268","pt":1719494377084,"mc":[{"id":"1.230180113","rc":[{"atb":[[1.02,2]],"id":68579508}],"con":true,"img":false}]}
{"op":"mcm","clk":"11540426361","pt":1719494378171,"mc":[{"id":"1.230180113","rc":[{"atb":[[1.02,0]],"id":68870841}],"con":true,"img":false}]}
{"op":"mcm","clk":"11540426368","pt":1719494378273,"mc":[{"id":"1.230180113","rc":[{"atb":[[1.77,2]],"id":68870841}],"con":true,"img":false}]}
{"op":"mcm","clk":"11540426397","pt":1719494378689,"mc":[{"id":"1.230180113","rc":[{"atb":[[1.02,0]],"id":58974183}],"con":true,"img":false}]}
{"op":"mcm","clk":"11540426407","pt":1719494378788,"mc":[{"id":"1.230180113","rc":[{"atb":[[1.85,2]],"id":58974183}],"con":true,"img":false}]}
{"op":"mcm","clk":"11540426425","pt":1719494378998,"mc":[{"id":"1.230180113","rc":[{"atb":[[1.02,8.47]],"id":50281437}],"con":true,"img":false}]}
{"op":"mcm","clk":"11540426436","pt":1719494379099,"mc":[{"id":"1.230180113","rc":[{"atb":[[1.45,2]],"id":50281437}],"con":true,"img":false}]}
{"op":"mcm","clk":"11540426455","pt":1719494379406,"mc":[{"id":"1.230180113","rc":[{"atb":[[1.02,0]],"id":68579508}],"con":true,"img":false}]}
{"op":"mcm","clk":"11540426462","pt":1719494379466,"mc":[{"id":"1.230180113","rc":[{"atb":[[1.53,2]],"id":68579508}],"con":true,"img":false}]}
{"op":"mcm","clk":"11540426535","pt":1719494380397,"mc":[{"id":"1.230180113","rc":[{"atb":[[1.77,0]],"id":68870841}],"con":true,"img":false}]}
{"op":"mcm","clk":"11540426549","pt":1719494380605,"mc":[{"id":"1.230180113","rc":[{"atb":[[1.02,2]],"id":68870841}],"con":true,"img":false}]}
{"op":"mcm","clk":"11540426572","pt":1719494380868,"mc":[{"id":"1.230180113","rc":[{"atb":[[1.85,0]],"id":58974183}],"con":true,"img":false}]}
{"op":"mcm","clk":"11540426581","pt":1719494380973,"mc":[{"id":"1.230180113","rc":[{"atb":[[1.02,2]],"id":58974183}],"con":true,"img":false}]}
{"op":"mcm","clk":"11540426619","pt":1719494381384,"mc":[{"id":"1.230180113","rc":[{"atb":[[1.45,0]],"id":50281437}],"con":true,"img":false}]}
{"op":"mcm","clk":"11540426626","pt":1719494381491,"mc":[{"id":"1.230180113","rc":[{"atb":[[1.02,10.47]],"id":50281437}],"con":true,"img":false}]}
{"op":"mcm","clk":"11540426659","pt":1719494381901,"mc":[{"id":"1.230180113","rc":[{"atb":[[1.53,0]],"id":68579508}],"con":true,"img":false}]}
{"op":"mcm","clk":"11540426668","pt":1719494382012,"mc":[{"id":"1.230180113","rc":[{"atb":[[1.02,2]],"id":68579508}],"con":true,"img":false}]}
{"op":"mcm","clk":"11540426772","pt":1719494383206,"mc":[{"id":"1.230180113","rc":[{"atb":[[1.02,0]],"id":68870841}],"con":true,"img":false}]}
{"op":"mcm","clk":"11540426781","pt":1719494383301,"mc":[{"id":"1.230180113","rc":[{"atb":[[1.77,2]],"id":68870841}],"con":true,"img":false}]}
{"op":"mcm","clk":"11540426812","pt":1719494383670,"mc":[{"id":"1.230180113","rc":[{"atb":[[1.02,0]],"id":58974183}],"con":true,"img":false}]}
{"op":"mcm","clk":"11540426821","pt":1719494383774,"mc":[{"id":"1.230180113","rc":[{"atb":[[1.85,2]],"id":58974183}],"con":true,"img":false}]}
{"op":"mcm","clk":"11540426856","pt":1719494384208,"mc":[{"id":"1.230180113","rc":[{"atb":[[1.02,8.47]],"id":50281437}],"con":true,"img":false}]}
{"op":"mcm","clk":"11540426870","pt":1719494384307,"mc":[{"id":"1.230180113","rc":[{"atb":[[1.45,2]],"id":50281437}],"con":true,"img":false}]}
{"op":"mcm","clk":"11540426906","pt":1719494384673,"mc":[{"id":"1.230180113","rc":[{"atb":[[1.02,0]],"id":68579508}],"con":true,"img":false}]}
{"op":"mcm","clk":"11540426917","pt":1719494384778,"mc":[{"id":"1.230180113","rc":[{"atb":[[1.53,2]],"id":68579508}],"con":true,"img":false}]}
{"op":"mcm","clk":"11540426973","pt":1719494385409,"mc":[{"id":"1.230180113","rc":[{"atb":[[1.77,0]],"id":68870841}],"con":true,"img":false}]}
{"op":"mcm","clk":"11540426983","pt":1719494385513,"mc":[{"id":"1.230180113","rc":[{"atb":[[1.02,2]],"id":68870841}],"con":true,"img":false}]}
{"op":"mcm","clk":"11540427011","pt":1719494385774,"mc":[{"id":"1.230180113","rc":[{"atb":[[1.85,0]],"id":58974183}],"con":true,"img":false}]}
{"op":"mcm","clk":"11540427022","pt":1719494385875,"mc":[{"id":"1.230180113","rc":[{"atb":[[1.02,2]],"id":58974183}],"con":true,"img":false}]}
{"op":"mcm","clk":"11540427056","pt":1719494386291,"mc":[{"id":"1.230180113","rc":[{"atb":[[1.45,0]],"id":50281437}],"con":true,"img":false}]}
{"op":"mcm","clk":"11540427064","pt":1719494386396,"mc":[{"id":"1.230180113","rc":[{"atb":[[1.02,10.47]],"id":50281437}],"con":true,"img":false}]}
{"op":"mcm","clk":"11540427092","pt":1719494386711,"mc":[{"id":"1.230180113","rc":[{"atb":[[1.53,0]],"id":68579508}],"con":true,"img":false}]}
{"op":"mcm","clk":"11540427100","pt":1719494386806,"mc":[{"id":"1.230180113","rc":[{"atb":[[1.02,2]],"id":68579508}],"con":true,"img":false}]}
{"op":"mcm","clk":"11540427206","pt":1719494387905,"mc":[{"id":"1.230180113","rc":[{"atb":[[1.02,0]],"id":68870841}],"con":true,"img":false}]}
{"op":"mcm","clk":"11540427215","pt":1719494388009,"mc":[{"id":"1.230180113","rc":[{"atb":[[1.77,2]],"id":68870841}],"con":true,"img":false}]}
{"op":"mcm","clk":"11540427244","pt":1719494388377,"mc":[{"id":"1.230180113","rc":[{"atb":[[1.02,0]],"id":58974183}],"con":true,"img":false}]}
{"op":"mcm","clk":"11540427249","pt":1719494388486,"mc":[{"id":"1.230180113","rc":[{"atb":[[1.85,2]],"id":58974183}],"con":true,"img":false}]}
{"op":"mcm","clk":"11540427274","pt":1719494388798,"mc":[{"id":"1.230180113","rc":[{"atb":[[1.02,8.47]],"id":50281437}],"con":true,"img":false}]}
{"op":"mcm","clk":"11540427284","pt":1719494388903,"mc":[{"id":"1.230180113","rc":[{"atb":[[1.45,2]],"id":50281437}],"con":true,"img":false}]}
{"op":"mcm","clk":"11540427319","pt":1719494389317,"mc":[{"id":"1.230180113","rc":[{"atb":[[1.02,0]],"id":68579508}],"con":true,"img":false}]}
{"op":"mcm","clk":"11540427329","pt":1719494389422,"mc":[{"id":"1.230180113","rc":[{"atb":[[1.53,2]],"id":68579508}],"con":true,"img":false}]}
{"op":"mcm","clk":"11540427369","pt":1719494389889,"mc":[{"id":"1.230180113","rc":[{"atb":[[1.77,0]],"id":68870841}],"con":true,"img":false}]}
{"op":"mcm","clk":"11540427376","pt":1719494389998,"mc":[{"id":"1.230180113","rc":[{"atb":[[1.02,2]],"id":68870841}],"con":true,"img":false}]}
{"op":"mcm","clk":"11540427438","pt":1719494390718,"mc":[{"id":"1.230180113","rc":[{"atb":[[1.85,0]],"id":58974183}],"con":true,"img":false}]}
{"op":"mcm","clk":"11540427443","pt":1719494390824,"mc":[{"id":"1.230180113","rc":[{"atb":[[1.02,2]],"id":58974183}],"con":true,"img":false}]}
{"op":"mcm","clk":"11540427481","pt":1719494391188,"mc":[{"id":"1.230180113","rc":[{"atb":[[1.45,0]],"id":50281437}],"con":true,"img":false}]}
{"op":"mcm","clk":"11540427487","pt":1719494391298,"mc":[{"id":"1.230180113","rc":[{"atb":[[1.02,10.47]],"id":50281437}],"con":true,"img":false}]}
{"op":"mcm","clk":"11540427507","pt":1719494391607,"mc":[{"id":"1.230180113","rc":[{"atb":[[1.53,0]],"id":68579508}],"con":true,"img":false}]}
{"op":"mcm","clk":"11540427518","pt":1719494391706,"mc":[{"id":"1.230180113","rc":[{"atb":[[1.02,2]],"id":68579508}],"con":true,"img":false}]}
{"op":"mcm","clk":"11540427563","pt":1719494392181,"mc":[{"id":"1.230180113","rc":[{"atb":[[1.23,0]],"id":68169358},{"atb":[[1.02,0]],"id":68870841}],"con":true,"img":false}]}
{"op":"mcm","clk":"11540427573","pt":1719494392290,"mc":[{"id":"1.230180113","rc":[{"atb":[[1.77,2]],"id":68870841}],"con":true,"img":false}]}
{"op":"mcm","clk":"11540427601","pt":1719494392598,"mc":[{"id":"1.230180113","rc":[{"atb":[[1.02,0]],"id":58974183}],"con":true,"img":false}]}
{"op":"mcm","clk":"11540427613","pt":1719494392701,"mc":[{"id":"1.230180113","rc":[{"atb":[[1.85,2]],"id":58974183}],"con":true,"img":false}]}
{"op":"mcm","clk":"11540427632","pt":1719494393019,"mc":[{"id":"1.230180113","rc":[{"atb":[[1.02,8.47]],"id":50281437}],"con":true,"img":false}]}
{"op":"mcm","clk":"11540427641","pt":1719494393129,"mc":[{"id":"1.230180113","rc":[{"atb":[[1.45,2]],"id":50281437}],"con":true,"img":false}]}
{"op":"mcm","clk":"11540427698","pt":1719494393803,"mc":[{"id":"1.230180113","rc":[{"atb":[[1.02,0]],"id":68579508}],"con":true,"img":false}]}
{"op":"mcm","clk":"11540427709","pt":1719494393907,"mc":[{"id":"1.230180113","rc":[{"atb":[[1.53,2]],"id":68579508}],"con":true,"img":false}]}
{"op":"mcm","clk":"11540427761","pt":1719494394526,"mc":[{"id":"1.230180113","rc":[{"atb":[[1.77,0]],"id":68870841}],"con":true,"img":false}]}
{"op":"mcm","clk":"11540427769","pt":1719494394630,"mc":[{"id":"1.230180113","rc":[{"atb":[[1.02,2]],"id":68870841}],"con":true,"img":false}]}
{"op":"mcm","clk":"11540427795","pt":1719494394890,"mc":[{"id":"1.230180113","rc":[{"atb":[[1.85,0]],"id":58974183}],"con":true,"img":false}]}
{"op":"mcm","clk":"11540427803","pt":1719494395003,"mc":[{"id":"1.230180113","rc":[{"atb":[[1.02,2]],"id":58974183}],"con":true,"img":false}]}
{"op":"mcm","clk":"11540427846","pt":1719494395406,"mc":[{"id":"1.230180113","rc":[{"atb":[[1.45,0]],"id":50281437}],"con":true,"img":false}]}
{"op":"mcm","clk":"11540427857","pt":1719494395510,"mc":[{"id":"1.230180113","rc":[{"atb":[[1.02,10.47]],"id":50281437}],"con":true,"img":false}]}
{"op":"mcm","clk":"11540427898","pt":1719494396034,"mc":[{"id":"1.230180113","rc":[{"atb":[[1.53,0]],"id":68579508}],"con":true,"img":false}]}
{"op":"mcm","clk":"11540427909","pt":1719494396087,"mc":[{"id":"1.230180113","rc":[{"atb":[[1.02,2]],"id":68579508}],"con":true,"img":false}]}
{"op":"mcm","clk":"11540427928","pt":1719494396402,"mc":[{"id":"1.230180113","rc":[{"atb":[[1.27,0]],"id":68169358}],"con":true,"img":false}]}
{"op":"mcm","clk":"11540427936","pt":1719494396498,"mc":[{"id":"1.230180113","rc":[{"atb":[[1.15,53.85],[1.26,0],[1.02,2]],"id":68169358}],"con":true,"img":false}]}
{"op":"mcm","clk":"11540428031","pt":1719494397595,"mc":[{"id":"1.230180113","rc":[{"atb":[[1.02,0]],"id":68870841}],"con":true,"img":false}]}
{"op":"mcm","clk":"11540428044","pt":1719494397697,"mc":[{"id":"1.230180113","rc":[{"atb":[[1.77,2]],"id":68870841}],"con":true,"img":false}]}
{"op":"mcm","clk":"11540428079","pt":1719494398108,"mc":[{"id":"1.230180113","rc":[{"atb":[[1.02,0]],"id":58974183}],"con":true,"img":false}]}
{"op":"mcm","clk":"11540428089","pt":1719494398210,"mc":[{"id":"1.230180113","rc":[{"atb":[[1.85,2]],"id":58974183}],"con":true,"img":false}]}
{"op":"mcm","clk":"11540428126","pt":1719494398629,"mc":[{"id":"1.230180113","rc":[{"atb":[[1.02,8.47]],"id":50281437}],"con":true,"img":false}]}
{"op":"mcm","clk":"11540428138","pt":1719494398727,"mc":[{"id":"1.230180113","rc":[{"atb":[[1.45,2]],"id":50281437}],"con":true,"img":false}]}
{"op":"mcm","clk":"11540428178","pt":1719494399099,"mc":[{"id":"1.230180113","rc":[{"atb":[[1.02,0]],"id":68579508}],"con":true,"img":false}]}
{"op":"mcm","clk":"11540428189","pt":1719494399197,"mc":[{"id":"1.230180113","rc":[{"atb":[[1.53,2]],"id":68579508}],"con":true,"img":false}]}
{"op":"mcm","clk":"11540428227","pt":1719494399609,"mc":[{"id":"1.230180113","rc":[{"atb":[[1.02,0]],"id":68169358}],"con":true,"img":false}]}
{"op":"mcm","clk":"11540428239","pt":1719494399715,"mc":[{"id":"1.230180113","rc":[{"atb":[[1.16,2]],"id":68169358}],"con":true,"img":false}]}
{"op":"mcm","clk":"11540428288","pt":1719494400335,"mc":[{"id":"1.230180113","rc":[{"atb":[[1.77,0]],"id":68870841}],"con":true,"img":false}]}
{"op":"mcm","clk":"11540428299","pt":1719494400441,"mc":[{"id":"1.230180113","rc":[{"atb":[[1.02,2]],"id":68870841}],"con":true,"img":false}]}
{"op":"mcm","clk":"11540428316","pt":1719494400603,"mc":[{"id":"1.230180113","rc":[{"atb":[[1.85,0]],"id":58974183}],"con":true,"img":false}]}
{"op":"mcm","clk":"11540428327","pt":1719494400720,"mc":[{"id":"1.230180113","rc":[{"atb":[[1.02,2]],"id":58974183}],"con":true,"img":false}]}
{"op":"mcm","clk":"11540428357","pt":1719494401127,"mc":[{"id":"1.230180113","rc":[{"atb":[[1.45,0]],"id":50281437}],"con":true,"img":false}]}
{"op":"mcm","clk":"11540428362","pt":1719494401231,"mc":[{"id":"1.230180113","rc":[{"atb":[[1.02,10.47]],"id":50281437}],"con":true,"img":false}]}
{"op":"mcm","clk":"11540428392","pt":1719494401500,"mc":[{"id":"1.230180113","rc":[{"atb":[[1.53,0]],"id":68579508}],"con":true,"img":false}]}
{"op":"mcm","clk":"11540428401","pt":1719494401602,"mc":[{"id":"1.230180113","rc":[{"atb":[[1.02,2]],"id":68579508}],"con":true,"img":false}]}
{"op":"mcm","clk":"11540428456","pt":1719494402329,"mc":[{"id":"1.230180113","rc":[{"atb":[[1.02,0]],"id":68870841}],"con":true,"img":false}]}
{"op":"mcm","clk":"11540428464","pt":1719494402433,"mc":[{"id":"1.230180113","rc":[{"atb":[[1.77,2]],"id":68870841}],"con":true,"img":false}]}
{"op":"mcm","clk":"11540428494","pt":1719494402701,"mc":[{"id":"1.230180113","rc":[{"atb":[[1.02,0]],"id":58974183}],"con":true,"img":false}]}
{"op":"mcm","clk":"11540428507","pt":1719494402801,"mc":[{"id":"1.230180113","rc":[{"atb":[[1.85,2]],"id":58974183}],"con":true,"img":false}]}
{"op":"mcm","clk":"11540428534","pt":1719494403110,"mc":[{"id":"1.230180113","rc":[{"atb":[[1.02,8.47]],"id":50281437}],"con":true,"img":false}]}
{"op":"mcm","clk":"11540428544","pt":1719494403214,"mc":[{"id":"1.230180113","rc":[{"atb":[[1.45,2]],"id":50281437}],"con":true,"img":false}]}
{"op":"mcm","clk":"11540428587","pt":1719494403732,"mc":[{"id":"1.230180113","rc":[{"atb":[[1.02,0]],"id":68579508}],"con":true,"img":false}]}
{"op":"mcm","clk":"11540428594","pt":1719494403841,"mc":[{"id":"1.230180113","rc":[{"atb":[[1.53,2]],"id":68579508}],"con":true,"img":false}]}
{"op":"mcm","clk":"11540428663","pt":1719494404518,"mc":[{"id":"1.230180113","rc":[{"atb":[[1.77,0]],"id":68870841}],"con":true,"img":false}]}
{"op":"mcm","clk":"11540428673","pt":1719494404615,"mc":[{"id":"1.230180113","rc":[{"atb":[[1.02,2]],"id":68870841}],"con":true,"img":false}]}
{"op":"mcm","clk":"11540428706","pt":1719494405036,"mc":[{"id":"1.230180113","rc":[{"atb":[[1.85,0]],"id":58974183}],"con":true,"img":false}]}
{"op":"mcm","clk":"11540428715","pt":1719494405136,"mc":[{"id":"1.230180113","rc":[{"atb":[[1.02,2]],"id":58974183}],"con":true,"img":false}]}
{"op":"mcm","clk":"11540428751","pt":1719494405400,"mc":[{"id":"1.230180113","rc":[{"atb":[[1.45,0]],"id":50281437}],"con":true,"img":false}]}
{"op":"mcm","clk":"11540428761","pt":1719494405510,"mc":[{"id":"1.230180113","rc":[{"atb":[[1.02,10.47]],"id":50281437}],"con":true,"img":false}]}
{"op":"mcm","clk":"11540428793","pt":1719494405824,"mc":[{"id":"1.230180113","rc":[{"atb":[[1.53,0]],"id":68579508}],"con":true,"img":false}]}
{"op":"mcm","clk":"11540428804","pt":1719494405932,"mc":[{"id":"1.230180113","rc":[{"atb":[[1.02,2]],"id":68579508}],"con":true,"img":false}]}
{"op":"mcm","clk":"11540428851","pt":1719494406337,"mc":[{"id":"1.230180113","rc":[{"atb":[[1.02,0]],"id":68870841}],"con":true,"img":false}]}
{"op":"mcm","clk":"11540428858","pt":1719494406442,"mc":[{"id":"1.230180113","rc":[{"atb":[[1.77,2]],"id":68870841}],"con":true,"img":false}]}
{"op":"mcm","clk":"11540428880","pt":1719494406715,"mc":[{"id":"1.230180113","rc":[{"atb":[[1.01,103.74],[1.02,0]],"id":58974183},{"atl":[[1000,1.7]],"id":58974183},{"atb":[[1.01,103.74]],"id":68870841},{"atl":[[1000,1.7]],"id":68870841},{"atb":[[1.01,103.74]],"id":50281437},{"atl":[[1000,1.7]],"id":50281437}],"con":true,"img":false}]}
{"op":"mcm","clk":"11540428895","pt":1719494406812,"mc":[{"id":"1.230180113","rc":[{"atb":[[1.85,2]],"id":58974183}],"con":true,"img":false}]}
{"op":"mcm","clk":"11540428915","pt":1719494407024,"mc":[{"id":"1.230180113","rc":[{"atb":[[1.01,102.4]],"id":58974183},{"atl":[[1000,0.01]],"id":58974183},{"atb":[[1.01,102.43]],"id":68870841},{"atl":[[1000,0.01]],"id":68870841},{"atb":[[1.01,102.72]],"id":50281437},{"atl":[[1000,0.03]],"id":50281437}],"con":true,"img":false}]}
{"op":"mcm","clk":"11540428926","pt":1719494407122,"mc":[{"id":"1.230180113","rc":[{"atb":[[1.02,8.47]],"id":50281437}],"con":true,"img":false}]}
{"op":"mcm","clk":"11540428938","pt":1719494407224,"mc":[{"id":"1.230180113","rc":[{"atb":[[1.01,102.04]],"id":58974183},{"atl":[[1000,0]],"id":58974183},{"atb":[[1.01,102.04]],"id":68870841},{"atl":[[1000,0]],"id":68870841},{"atb":[[1.01,102.04],[1.45,2]],"id":50281437},{"atl":[[1000,0]],"id":50281437}],"con":true,"img":false}]}
{"op":"mcm","clk":"11540428949","pt":1719494407328,"mc":[{"id":"1.230180113","rc":[{"atb":[[1.85,2.36]],"id":58974183},{"atl":[[28,0.01]],"id":58974183},{"atb":[[1.77,2.39]],"id":68870841},{"atl":[[22,0.01]],"id":68870841},{"atb":[[1.45,2.68]],"id":50281437},{"atl":[[9.4,0.03]],"id":50281437}],"con":true,"img":false}]}
{"op":"mcm","clk":"11540428966","pt":1719494407535,"mc":[{"id":"1.230180113","rc":[{"atb":[[1.02,0]],"id":68579508}],"con":true,"img":false}]}
{"op":"mcm","clk":"11540428981","pt":1719494407635,"mc":[{"id":"1.230180113","rc":[{"atb":[[1.53,2]],"id":68579508}],"con":true,"img":false}]}
{"op":"mcm","clk":"11540429027","pt":1719494408011,"mc":[{"id":"1.230180113","rc":[{"atb":[[1.77,0.39]],"id":68870841}],"con":true,"img":false}]}
{"op":"mcm","clk":"11540429038","pt":1719494408107,"mc":[{"id":"1.230180113","rc":[{"atb":[[1.02,2]],"id":68870841}],"con":true,"img":false}]}
{"op":"mcm","clk":"11540429096","pt":1719494408731,"mc":[{"id":"1.230180113","rc":[{"atb":[[1.85,0.36]],"id":58974183}],"con":true,"img":false}]}
{"op":"mcm","clk":"11540429108","pt":1719494408834,"mc":[{"id":"1.230180113","rc":[{"atb":[[1.02,2]],"id":58974183}],"con":true,"img":false}]}
{"op":"mcm","clk":"11540429165","pt":1719494409309,"mc":[{"id":"1.230180113","rc":[{"atb":[[1.45,0.68]],"id":50281437}],"con":true,"img":false}]}
{"op":"mcm","clk":"11540429175","pt":1719494409409,"mc":[{"id":"1.230180113","rc":[{"atb":[[1.02,10.47]],"id":50281437}],"con":true,"img":false}]}
{"op":"mcm","clk":"11540429261","pt":1719494410402,"mc":[{"id":"1.230180113","rc":[{"atb":[[1.53,0]],"id":68579508}],"con":true,"img":false}]}
{"op":"mcm","clk":"11540429270","pt":1719494410507,"mc":[{"id":"1.230180113","rc":[{"atb":[[1.02,2]],"id":68579508}],"con":true,"img":false}]}
{"op":"mcm","clk":"11540429314","pt":1719494411022,"mc":[{"id":"1.230180113","rc":[{"atb":[[1.02,0]],"id":68870841}],"con":true,"img":false}]}
{"op":"mcm","clk":"11540429322","pt":1719494411126,"mc":[{"id":"1.230180113","rc":[{"atb":[[1.77,2.39]],"id":68870841}],"con":true,"img":false}]}
{"op":"mcm","clk":"11540429360","pt":1719494411545,"mc":[{"id":"1.230180113","rc":[{"atb":[[1.02,0]],"id":58974183}],"con":true,"img":false}]}
{"op":"mcm","clk":"11540429369","pt":1719494411641,"mc":[{"id":"1.230180113","rc":[{"atb":[[1.85,2.36]],"id":58974183}],"con":true,"img":false}]}
{"op":"mcm","clk":"11540429386","pt":1719494411855,"mc":[{"id":"1.230180113","rc":[{"atb":[[1.02,8.47]],"id":50281437}],"con":true,"img":false}]}
{"op":"mcm","clk":"11540429393","pt":1719494411916,"mc":[{"id":"1.230180113","rc":[{"atb":[[1.45,2.68]],"id":50281437}],"con":true,"img":false}]}
{"op":"mcm","clk":"11540429427","pt":1719494412322,"mc":[{"id":"1.230180113","rc":[{"atb":[[1.02,0]],"id":68579508}],"con":true,"img":false}]}
{"op":"mcm","clk":"11540429437","pt":1719494412428,"mc":[{"id":"1.230180113","rc":[{"atb":[[1.53,2]],"id":68579508}],"con":true,"img":false}]}
{"op":"mcm","clk":"11540429486","pt":1719494412941,"mc":[{"id":"1.230180113","rc":[{"atb":[[1.77,0.39]],"id":68870841}],"con":true,"img":false}]}
{"op":"mcm","clk":"11540429492","pt":1719494413046,"mc":[{"id":"1.230180113","rc":[{"atb":[[1.02,2]],"id":68870841}],"con":true,"img":false}]}
{"op":"mcm","clk":"11540429525","pt":1719494413425,"mc":[{"id":"1.230180113","rc":[{"atb":[[1.85,0.36]],"id":58974183}],"con":true,"img":false}]}
{"op":"mcm","clk":"11540429537","pt":1719494413514,"mc":[{"id":"1.230180113","rc":[{"atb":[[1.02,2]],"id":58974183}],"con":true,"img":false}]}
{"op":"mcm","clk":"11540429551","pt":1719494413735,"mc":[{"id":"1.230180113","rc":[{"atb":[[1.45,0.68]],"id":50281437}],"con":true,"img":false}]}
{"op":"mcm","clk":"11540429562","pt":1719494413824,"mc":[{"id":"1.230180113","rc":[{"atb":[[1.02,10.47]],"id":50281437}],"con":true,"img":false}]}
{"op":"mcm","clk":"11540429577","pt":1719494414030,"mc":[{"id":"1.230180113","rc":[{"atb":[[1.53,0]],"id":68579508}],"con":true,"img":false}]}
{"op":"mcm","clk":"11540429584","pt":1719494414134,"mc":[{"id":"1.230180113","rc":[{"atb":[[1.02,2]],"id":68579508}],"con":true,"img":false}]}
{"op":"mcm","clk":"11540429669","pt":1719494414918,"mc":[{"id":"1.230180113","rc":[{"atb":[[1.18,21.94]],"id":68169358}],"con":true,"img":false}]}
{"op":"mcm","clk":"11540429676","pt":1719494415020,"mc":[{"id":"1.230180113","rc":[{"atb":[[1.19,21.95]],"id":68169358},{"atb":[[1.02,0]],"id":68870841}],"con":true,"img":false}]}
{"op":"mcm","clk":"11540429683","pt":1719494415125,"mc":[{"id":"1.230180113","rc":[{"atb":[[1.15,0]],"id":68169358},{"atb":[[1.77,2.39]],"id":68870841}],"con":true,"img":false}]}
{"op":"mcm","clk":"11540429726","pt":1719494415646,"mc":[{"id":"1.230180113","rc":[{"atb":[[1.02,0]],"id":58974183}],"con":true,"img":false}]}
{"op":"mcm","clk":"11540429739","pt":1719494415753,"mc":[{"id":"1.230180113","rc":[{"atb":[[1.85,2.36]],"id":58974183}],"con":true,"img":false}]}
{"op":"mcm","clk":"11540429759","pt":1719494416026,"mc":[{"id":"1.230180113","rc":[{"atb":[[1.02,8.47]],"id":50281437}],"con":true,"img":false}]}
{"op":"mcm","clk":"11540429769","pt":1719494416123,"mc":[{"id":"1.230180113","rc":[{"atb":[[1.45,2.68]],"id":50281437}],"con":true,"img":false}]}
{"op":"mcm","clk":"11540429798","pt":1719494416438,"mc":[{"id":"1.230180113","rc":[{"atb":[[1.02,0]],"id":68579508}],"con":true,"img":false}]}
{"op":"mcm","clk":"11540429811","pt":1719494416539,"mc":[{"id":"1.230180113","rc":[{"atb":[[1.53,2]],"id":68579508}],"con":true,"img":false}]}
{"op":"mcm","clk":"11540429871","pt":1719494417224,"mc":[{"id":"1.230180113","rc":[{"atb":[[1.77,0.39]],"id":68870841}],"con":true,"img":false}]}
{"op":"mcm","clk":"11540429885","pt":1719494417326,"mc":[{"id":"1.230180113","rc":[{"atb":[[1.02,2]],"id":68870841}],"con":true,"img":false}]}
{"op":"mcm","clk":"11540429918","pt":1719494417630,"mc":[{"id":"1.230180113","rc":[{"atb":[[1.85,0.36]],"id":58974183}],"con":true,"img":false}]}
{"op":"mcm","clk":"11540429927","pt":1719494417739,"mc":[{"id":"1.230180113","rc":[{"atb":[[1.02,2]],"id":58974183}],"con":true,"img":false}]}
{"op":"mcm","clk":"11540429951","pt":1719494418062,"mc":[{"id":"1.230180113","rc":[{"atb":[[1.45,0.68]],"id":50281437}],"con":true,"img":false}]}
{"op":"mcm","clk":"11540429960","pt":1719494418161,"mc":[{"id":"1.230180113","rc":[{"atb":[[1.02,10.47]],"id":50281437}],"con":true,"img":false}]}
{"op":"mcm","clk":"11540430038","pt":1719494418839,"mc":[{"id":"1.230180113","rc":[{"spn":2.25,"spf":"NaN","id":68169358},{"atb":[[1.53,0]],"id":68579508},{"spn":2.63,"spf":"NaN","id":68579508}],"con":true,"img":false}]}
{"op":"mcm","clk":"11540430052","pt":1719494418931,"mc":[{"id":"1.230180113","rc":[{"atb":[[1.02,2]],"id":68579508}],"con":true,"img":false}]}
{"op":"mcm","clk":"11540430082","pt":1719494419244,"mc":[{"id":"1.230180113","rc":[{"atb":[[1.16,0]],"id":68169358}],"con":true,"img":false}]}
{"op":"mcm","clk":"11540430088","pt":1719494419344,"mc":[{"id":"1.230180113","rc":[{"atb":[[1.2,2]],"id":68169358}],"con":true,"img":false}]}
{"op":"mcm","clk":"11540430136","pt":1719494419918,"mc":[{"id":"1.230180113","rc":[{"atb":[[1.02,0]],"id":68870841}],"con":true,"img":false}]}
{"op":"mcm","clk":"11540430146","pt":1719494420024,"mc":[{"id":"1.230180113","rc":[{"atb":[[1.77,2.39]],"id":68870841}],"con":true,"img":false}]}
{"op":"mcm","clk":"11540430176","pt":1719494420333,"mc":[{"id":"1.230180113","rc":[{"atb":[[1.02,0]],"id":58974183}],"con":true,"img":false}]}
{"op":"mcm","clk":"11540430189","pt":1719494420440,"mc":[{"id":"1.230180113","rc":[{"atb":[[1.85,2.36]],"id":58974183}],"con":true,"img":false}]}
{"op":"mcm","clk":"11540430217","pt":1719494420743,"mc":[{"id":"1.230180113","rc":[{"atb":[[1.02,8.47]],"id":50281437}],"con":true,"img":false}]}
{"op":"mcm","clk":"11540430223","pt":1719494420848,"mc":[{"id":"1.230180113","rc":[{"atb":[[1.45,2.68]],"id":50281437}],"con":true,"img":false}]}
{"op":"mcm","clk":"11540430253","pt":1719494421156,"mc":[{"id":"1.230180113","rc":[{"atb":[[1.02,0]],"id":68579508}],"con":true,"img":false}]}
{"op":"mcm","clk":"11540430261","pt":1719494421210,"mc":[{"id":"1.230180113","rc":[{"atb":[[1.53,2]],"id":68579508}],"con":true,"img":false}]}
{"op":"mcm","clk":"11540430344","pt":1719494422357,"mc":[{"id":"1.230180113","rc":[{"atb":[[1.77,0.39]],"id":68870841}],"con":true,"img":false}]}
{"op":"mcm","clk":"11540430356","pt":1719494422421,"mc":[{"id":"1.230180113","rc":[{"atb":[[1.02,2]],"id":68870841}],"con":true,"img":false}]}
{"op":"mcm","clk":"11540430406","pt":1719494422930,"mc":[{"id":"1.230180113","rc":[{"atb":[[1.85,0.36]],"id":58974183}],"con":true,"img":false}]}
{"op":"mcm","clk":"11540430416","pt":1719494423036,"mc":[{"id":"1.230180113","rc":[{"atb":[[1.02,2]],"id":58974183}],"con":true,"img":false}]}
{"op":"mcm","clk":"11540430437","pt":1719494423341,"mc":[{"id":"1.230180113","rc":[{"atb":[[1.45,0.68]],"id":50281437}],"con":true,"img":false}]}
{"op":"mcm","clk":"11540430444","pt":1719494423451,"mc":[{"id":"1.230180113","rc":[{"atb":[[1.02,10.47]],"id":50281437}],"con":true,"img":false}]}
{"op":"mcm","clk":"11540430473","pt":1719494423756,"mc":[{"id":"1.230180113","rc":[{"atb":[[1.53,0]],"id":68579508}],"con":true,"img":false}]}
{"op":"mcm","clk":"11540430485","pt":1719494423859,"mc":[{"id":"1.230180113","rc":[{"atb":[[1.02,2]],"id":68579508}],"con":true,"img":false}]}
{"op":"mcm","clk":"11540430543","pt":1719494424433,"mc":[{"id":"1.230180113","rc":[{"atb":[[1.02,0]],"id":68870841}],"con":true,"img":false}]}
{"op":"mcm","clk":"11540430556","pt":1719494424539,"mc":[{"id":"1.230180113","rc":[{"atb":[[1.77,2.39]],"id":68870841}],"con":true,"img":false}]}
{"op":"mcm","clk":"11540430588","pt":1719494424845,"mc":[{"id":"1.230180113","rc":[{"atb":[[1.02,0]],"id":58974183}],"con":true,"img":false}]}
{"op":"mcm","clk":"11540430598","pt":1719494424952,"mc":[{"id":"1.230180113","rc":[{"atb":[[1.85,2.36]],"id":58974183}],"con":true,"img":false}]}
{"op":"mcm","clk":"11540430654","pt":1719494425419,"mc":[{"id":"1.230180113","rc":[{"atb":[[1.02,8.47]],"id":50281437}],"con":true,"img":false}]}
{"op":"mcm","clk":"11540430663","pt":1719494425522,"mc":[{"id":"1.230180113","rc":[{"atb":[[1.45,2.68]],"id":50281437}],"con":true,"img":false}]}
{"op":"mcm","clk":"11540430711","pt":1719494426046,"mc":[{"id":"1.230180113","rc":[{"atb":[[1.02,0]],"id":68579508}],"con":true,"img":false}]}
{"op":"mcm","clk":"11540430723","pt":1719494426145,"mc":[{"id":"1.230180113","rc":[{"atb":[[1.53,2]],"id":68579508}],"con":true,"img":false}]}
{"op":"mcm","clk":"11540430779","pt":1719494426770,"mc":[{"id":"1.230180113","rc":[{"atb":[[1.77,0.39]],"id":68870841}],"con":true,"img":false}]}
{"op":"mcm","clk":"11540430792","pt":1719494426865,"mc":[{"id":"1.230180113","rc":[{"atb":[[1.02,2]],"id":68870841}],"con":true,"img":false}]}
{"op":"mcm","clk":"11540430829","pt":1719494427230,"mc":[{"id":"1.230180113","rc":[{"atb":[[1.85,0.36]],"id":58974183}],"con":true,"img":false}]}
{"op":"mcm","clk":"11540430836","pt":1719494427335,"mc":[{"id":"1.230180113","rc":[{"atb":[[1.02,2]],"id":58974183}],"con":true,"img":false}]}
{"op":"mcm","clk":"11540430883","pt":1719494427854,"mc":[{"id":"1.230180113","rc":[{"atb":[[1.45,0.68]],"id":50281437}],"con":true,"img":false}]}
{"op":"mcm","clk":"11540430894","pt":1719494427959,"mc":[{"id":"1.230180113","rc":[{"atb":[[1.02,10.47]],"id":50281437}],"con":true,"img":false}]}
{"op":"mcm","clk":"11540430926","pt":1719494428322,"mc":[{"id":"1.230180113","rc":[{"atb":[[1.53,0]],"id":68579508}],"con":true,"img":false}]}
{"op":"mcm","clk":"11540430936","pt":1719494428427,"mc":[{"id":"1.230180113","rc":[{"atb":[[1.02,2]],"id":68579508}],"con":true,"img":false}]}
{"op":"mcm","clk":"11540430972","pt":1719494428943,"mc":[{"id":"1.230180113","rc":[{"atb":[[1.02,0]],"id":68870841}],"con":true,"img":false}]}
{"op":"mcm","clk":"11540430980","pt":1719494429046,"mc":[{"id":"1.230180113","rc":[{"atb":[[1.77,2.39]],"id":68870841}],"con":true,"img":false}]}
{"op":"mcm","clk":"11540430995","pt":1719494429253,"mc":[{"id":"1.230180113","rc":[{"atb":[[1.02,0]],"id":58974183}],"con":true,"img":false}]}
{"op":"mcm","clk":"11540431005","pt":1719494429354,"mc":[{"id":"1.230180113","rc":[{"atb":[[1.85,2.36]],"id":58974183}],"con":true,"img":false}]}
{"op":"mcm","clk":"11540431017","pt":1719494429562,"mc":[{"id":"1.230180113","rc":[{"atb":[[1.02,8.47]],"id":50281437}],"con":true,"img":false}]}
{"op":"mcm","clk":"11540431025","pt":1719494429666,"mc":[{"id":"1.230180113","rc":[{"atb":[[1.45,2.68]],"id":50281437}],"con":true,"img":false}]}
{"op":"mcm","clk":"11540431051","pt":1719494429934,"mc":[{"id":"1.230180113","rc":[{"atb":[[1.02,0]],"id":68579508}],"con":true,"img":false}]}
{"op":"mcm","clk":"11540431065","pt":1719494430037,"mc":[{"id":"1.230180113","rc":[{"atb":[[1.53,2]],"id":68579508}],"con":true,"img":false}]}
{"op":"mcm","clk":"11540431110","pt":1719494430544,"mc":[{"id":"1.230180113","rc":[{"atb":[[1.77,0.39]],"id":68870841}],"con":true,"img":false}]}
{"op":"mcm","clk":"11540431118","pt":1719494430648,"mc":[{"id":"1.230180113","rc":[{"atb":[[1.02,2]],"id":68870841}],"con":true,"img":false}]}
{"op":"mcm","clk":"11540431146","pt":1719494430964,"mc":[{"id":"1.230180113","rc":[{"atb":[[1.85,0.36]],"id":58974183}],"con":true,"img":false}]}
{"op":"mcm","clk":"11540431156","pt":1719494431068,"mc":[{"id":"1.230180113","rc":[{"atb":[[1.02,2]],"id":58974183}],"con":true,"img":false}]}
{"op":"mcm","clk":"11540431181","pt":1719494431327,"mc":[{"id":"1.230180113","rc":[{"atb":[[1.45,0.68]],"id":50281437}],"con":true,"img":false}]}
{"op":"mcm","clk":"11540431190","pt":1719494431431,"mc":[{"id":"1.230180113","rc":[{"atb":[[1.02,10.47]],"id":50281437}],"con":true,"img":false}]}
{"op":"mcm","clk":"11540431227","pt":1719494431841,"mc":[{"id":"1.230180113","rc":[{"atb":[[1.53,0]],"id":68579508}],"con":true,"img":false}]}
{"op":"mcm","clk":"11540431235","pt":1719494431946,"mc":[{"id":"1.230180113","rc":[{"atb":[[1.02,2]],"id":68579508}],"con":true,"img":false}]}
{"op":"mcm","clk":"11540431272","pt":1719494432468,"mc":[{"id":"1.230180113","rc":[{"atb":[[1.02,0]],"id":68870841}],"con":true,"img":false}]}
{"op":"mcm","clk":"11540431281","pt":1719494432574,"mc":[{"id":"1.230180113","rc":[{"atb":[[1.77,2.39]],"id":68870841}],"con":true,"img":false}]}
{"op":"mcm","clk":"11540431306","pt":1719494432835,"mc":[{"id":"1.230180113","rc":[{"atb":[[1.02,0]],"id":58974183}],"con":true,"img":false}]}
{"op":"mcm","clk":"11540431321","pt":1719494432939,"mc":[{"id":"1.230180113","rc":[{"atb":[[1.85,2.36]],"id":58974183}],"con":true,"img":false}]}
{"op":"mcm","clk":"11540431392","pt":1719494433664,"mc":[{"id":"1.230180113","rc":[{"atb":[[1.02,8.47]],"id":50281437}],"con":true,"img":false}]}
{"op":"mcm","clk":"11540431402","pt":1719494433771,"mc":[{"id":"1.230180113","rc":[{"atb":[[1.45,2.68]],"id":50281437}],"con":true,"img":false}]}
{"op":"mcm","clk":"11540431470","pt":1719494434352,"mc":[{"id":"1.230180113","rc":[{"atb":[[1.02,0]],"id":68579508}],"con":true,"img":false}]}
{"op":"mcm","clk":"11540431478","pt":1719494434450,"mc":[{"id":"1.230180113","rc":[{"atb":[[1.53,2]],"id":68579508}],"con":true,"img":false}]}
{"op":"mcm","clk":"11540431518","pt":1719494434973,"mc":[{"id":"1.230180113","rc":[{"atb":[[1.77,0.39]],"id":68870841}],"con":true,"img":false}]}
{"op":"mcm","clk":"11540431528","pt":1719494435068,"mc":[{"id":"1.230180113","rc":[{"atb":[[1.02,2]],"id":68870841}],"con":true,"img":false}]}
{"op":"mcm","clk":"11540431535","pt":1719494435176,"mc":[{"id":"1.230180113","rc":[{"atb":[[1.18,0]],"id":68169358}],"con":true,"img":false}]}
{"op":"mcm","clk":"11540431558","pt":1719494435337,"mc":[{"id":"1.230180113","rc":[{"atb":[[1.85,0.36]],"id":58974183}],"con":true,"img":false}]}
{"op":"mcm","clk":"11540431573","pt":1719494435433,"mc":[{"id":"1.230180113","rc":[{"atb":[[1.02,2]],"id":58974183}],"con":true,"img":false}]}
{"op":"mcm","clk":"11540431595","pt":1719494435741,"mc":[{"id":"1.230180113","rc":[{"atb":[[1.22,17.95]],"id":68169358},{"atb":[[1.45,0.68]],"id":50281437}],"con":true,"img":false}]}
{"op":"mcm","clk":"11540431607","pt":1719494435847,"mc":[{"id":"1.230180113","rc":[{"atb":[[1.19,0],[1.23,17.96]],"id":68169358},{"atb":[[1.02,10.47]],"id":50281437}],"con":true,"img":false}]}
{"op":"mcm","clk":"11540431630","pt":1719494436056,"mc":[{"id":"1.230180113","rc":[{"atb":[[1.53,0]],"id":68579508}],"con":true,"img":false}]}
{"op":"mcm","clk":"11540431639","pt":1719494436156,"mc":[{"id":"1.230180113","rc":[{"atb":[[1.02,2]],"id":68579508}],"con":true,"img":false}]}
{"op":"mcm","clk":"11540431694","pt":1719494436731,"mc":[{"id":"1.230180113","rc":[{"atb":[[1.02,0]],"id":68870841}],"con":true,"img":false}]}
{"op":"mcm","clk":"11540431703","pt":1719494436834,"mc":[{"id":"1.230180113","rc":[{"atb":[[1.77,2.39]],"id":68870841}],"con":true,"img":false}]}
{"op":"mcm","clk":"11540431738","pt":1719494437266,"mc":[{"id":"1.230180113","rc":[{"atb":[[1.02,0]],"id":58974183}],"con":true,"img":false}]}
{"op":"mcm","clk":"11540431749","pt":1719494437365,"mc":[{"id":"1.230180113","rc":[{"atb":[[1.85,2.36]],"id":58974183}],"con":true,"img":false}]}
{"op":"mcm","clk":"11540431773","pt":1719494437680,"mc":[{"id":"1.230180113","rc":[{"atb":[[1.02,8.47]],"id":50281437}],"con":true,"img":false}]}
{"op":"mcm","clk":"11540431782","pt":1719494437735,"mc":[{"id":"1.230180113","rc":[{"atb":[[1.45,2.68]],"id":50281437}],"con":true,"img":false}]}
{"op":"mcm","clk":"11540431811","pt":1719494438045,"mc":[{"id":"1.230180113","rc":[{"atb":[[1.02,0]],"id":68579508}],"con":true,"img":false}]}
{"op":"mcm","clk":"11540431821","pt":1719494438147,"mc":[{"id":"1.230180113","rc":[{"atb":[[1.53,2]],"id":68579508}],"con":true,"img":false}]}
{"op":"mcm","clk":"11540431844","pt":1719494438451,"mc":[{"id":"1.230180113","rc":[{"atb":[[1.2,0]],"id":68169358}],"con":true,"img":false}]}
{"op":"mcm","clk":"11540431851","pt":1719494438560,"mc":[{"id":"1.230180113","rc":[{"atb":[[1.24,2]],"id":68169358}],"con":true,"img":false}]}
{"op":"mcm","clk":"11540431899","pt":1719494439078,"mc":[{"id":"1.230180113","rc":[{"atb":[[1.77,0.39]],"id":68870841}],"con":true,"img":false}]}
{"op":"mcm","clk":"11540431907","pt":1719494439181,"mc":[{"id":"1.230180113","rc":[{"atb":[[1.02,2]],"id":68870841}],"con":true,"img":false}]}
{"op":"mcm","clk":"11540431941","pt":1719494439545,"mc":[{"id":"1.230180113","rc":[{"atb":[[1.85,0.36]],"id":58974183}],"con":true,"img":false}]}
{"op":"mcm","clk":"11540431950","pt":1719494439643,"mc":[{"id":"1.230180113","rc":[{"atb":[[1.02,2]],"id":58974183}],"con":true,"img":false}]}
{"op":"mcm","clk":"11540432016","pt":1719494440370,"mc":[{"id":"1.230180113","rc":[{"atb":[[1.25,17.93]],"id":68169358}],"con":true,"img":false}]}
{"op":"mcm","clk":"11540432028","pt":1719494440473,"mc":[{"id":"1.230180113","rc":[{"atb":[[1.26,17.94],[1.23,0]],"id":68169358},{"atb":[[1.45,0.68]],"id":50281437}],"con":true,"img":false}]}
{"op":"mcm","clk":"11540432037","pt":1719494440576,"mc":[{"id":"1.230180113","rc":[{"atb":[[1.02,10.47]],"id":50281437}],"con":true,"img":false}]}
{"op":"mcm","clk":"11540432063","pt":1719494440837,"mc":[{"id":"1.230180113","rc":[{"atb":[[1.53,0]],"id":68579508}],"con":true,"img":false}]}
{"op":"mcm","clk":"11540432073","pt":1719494440943,"mc":[{"id":"1.230180113","rc":[{"atb":[[1.02,2]],"id":68579508}],"con":true,"img":false}]}
{"op":"mcm","clk":"11540432142","pt":1719494441774,"mc":[{"id":"1.230180113","rc":[{"atb":[[1.02,0]],"id":68870841}],"con":true,"img":false}]}
{"op":"mcm","clk":"11540432157","pt":1719494441876,"mc":[{"id":"1.230180113","rc":[{"atb":[[1.77,2.39]],"id":68870841}],"con":true,"img":false}]}
{"op":"mcm","clk":"11540432177","pt":1719494442087,"mc":[{"id":"1.230180113","rc":[{"atb":[[1.02,0]],"id":58974183}],"con":true,"img":false}]}
{"op":"mcm","clk":"11540432187","pt":1719494442142,"mc":[{"id":"1.230180113","rc":[{"atb":[[1.85,2.36]],"id":58974183}],"con":true,"img":false}]}
{"op":"mcm","clk":"11540432210","pt":1719494442447,"mc":[{"id":"1.230180113","rc":[{"atb":[[1.02,8.47]],"id":50281437}],"con":true,"img":false}]}
{"op":"mcm","clk":"11540432219","pt":1719494442552,"mc":[{"id":"1.230180113","rc":[{"atb":[[1.45,2.68]],"id":50281437}],"con":true,"img":false}]}
{"op":"mcm","clk":"11540432236","pt":1719494442760,"mc":[{"id":"1.230180113","rc":[{"atb":[[1.02,0]],"id":68579508}],"con":true,"img":false}]}
{"op":"mcm","clk":"11540432245","pt":1719494442863,"mc":[{"id":"1.230180113","rc":[{"atb":[[1.53,2]],"id":68579508}],"con":true,"img":false}]}
{"op":"mcm","clk":"11540432252","pt":1719494442971,"mc":[{"id":"1.230180113","rc":[{"atb":[[1.85,2]],"id":58974183},{"atl":[[28,0]],"id":58974183},{"atb":[[1.77,2]],"id":68870841},{"atl":[[22,0]],"id":68870841},{"atb":[[1.45,2]],"id":50281437},{"atl":[[9.4,0]],"id":50281437}],"con":true,"img":false}]}
{"op":"mcm","clk":"11540432262","pt":1719494443078,"mc":[{"id":"1.230180113","rc":[{"atb":[[1.24,0]],"id":68169358}],"con":true,"img":false}]}
{"op":"mcm","clk":"11540432272","pt":1719494443175,"mc":[{"id":"1.230180113","rc":[{"atb":[[1.27,2]],"id":68169358}],"con":true,"img":false}]}
{"op":"mcm","clk":"11540432335","pt":1719494443956,"mc":[{"id":"1.230180113","rc":[{"atb":[[1.77,0]],"id":68870841}],"con":true,"img":false}]}
{"op":"mcm","clk":"11540432348","pt":1719494444059,"mc":[{"id":"1.230180113","rc":[{"atb":[[1.02,2]],"id":68870841}],"con":true,"img":false}]}
{"op":"mcm","clk":"11540432376","pt":1719494444363,"mc":[{"id":"1.230180113","rc":[{"atb":[[1.85,0]],"id":58974183}],"con":true,"img":false}]}
{"op":"mcm","clk":"11540432389","pt":1719494444467,"mc":[{"id":"1.230180113","rc":[{"atb":[[1.02,2]],"id":58974183}],"con":true,"img":false}]}
{"op":"mcm","clk":"11540432409","pt":1719494444780,"mc":[{"id":"1.230180113","rc":[{"atb":[[1.45,0]],"id":50281437}],"con":true,"img":false}]}
{"op":"mcm","clk":"11540432416","pt":1719494444879,"mc":[{"id":"1.230180113","rc":[{"atb":[[1.02,10.47]],"id":50281437}],"con":true,"img":false}]}
{"op":"mcm","clk":"11540432444","pt":1719494445149,"mc":[{"id":"1.230180113","rc":[{"atb":[[1.53,0]],"id":68579508}],"con":true,"img":false}]}
{"op":"mcm","clk":"11540432451","pt":1719494445249,"mc":[{"id":"1.230180113","rc":[{"atb":[[1.02,2]],"id":68579508}],"con":true,"img":false}]}
{"op":"mcm","clk":"11540432504","pt":1719494445872,"mc":[{"id":"1.230180113","rc":[{"atb":[[1.02,0]],"id":68870841}],"con":true,"img":false}]}
{"op":"mcm","clk":"11540432512","pt":1719494445972,"mc":[{"id":"1.230180113","rc":[{"atb":[[1.77,2]],"id":68870841}],"con":true,"img":false}]}
{"op":"mcm","clk":"11540432544","pt":1719494446390,"mc":[{"id":"1.230180113","rc":[{"atb":[[1.02,0]],"id":58974183}],"con":true,"img":false}]}
{"op":"mcm","clk":"11540432551","pt":1719494446440,"mc":[{"id":"1.230180113","rc":[{"atb":[[1.85,2]],"id":58974183}],"con":true,"img":false}]}
{"op":"mcm","clk":"11540432567","pt":1719494446648,"mc":[{"id":"1.230180113","rc":[{"atb":[[1.02,8.47]],"id":50281437}],"con":true,"img":false}]}
{"op":"mcm","clk":"11540432582","pt":1719494446749,"mc":[{"id":"1.230180113","rc":[{"atb":[[1.45,2]],"id":50281437}],"con":true,"img":false}]}
{"op":"mcm","clk":"11540432599","pt":1719494446961,"mc":[{"id":"1.230180113","rc":[{"atb":[[1.02,0]],"id":68579508}],"con":true,"img":false}]}
{"op":"mcm","clk":"11540432607","pt":1719494447073,"mc":[{"id":"1.230180113","rc":[{"atb":[[1.53,2]],"id":68579508}],"con":true,"img":false}]}
{"op":"mcm","clk":"11540432662","pt":1719494447579,"mc":[{"id":"1.230180113","rc":[{"atb":[[1.77,0]],"id":68870841}],"con":true,"img":false}]}
{"op":"mcm","clk":"11540432672","pt":1719494447688,"mc":[{"id":"1.230180113","rc":[{"atb":[[1.02,2]],"id":68870841}],"con":true,"img":false}]}
{"op":"mcm","clk":"11540432742","pt":1719494448467,"mc":[{"id":"1.230180113","rc":[{"atb":[[1.85,0]],"id":58974183}],"con":true,"img":false}]}
{"op":"mcm","clk":"11540432752","pt":1719494448575,"mc":[{"id":"1.230180113","rc":[{"atb":[[1.02,2]],"id":58974183}],"con":true,"img":false}]}
{"op":"mcm","clk":"11540432786","pt":1719494448985,"mc":[{"id":"1.230180113","rc":[{"atb":[[1.45,0]],"id":50281437}],"con":true,"img":false}]}
{"op":"mcm","clk":"11540432796","pt":1719494449094,"mc":[{"id":"1.230180113","rc":[{"atb":[[1.02,10.47]],"id":50281437}],"con":true,"img":false}]}
{"op":"mcm","clk":"11540432821","pt":1719494449355,"mc":[{"id":"1.230180113","rc":[{"atb":[[1.53,0]],"id":68579508}],"con":true,"img":false}]}
{"op":"mcm","clk":"11540432829","pt":1719494449511,"mc":[{"id":"1.230180113","rc":[{"atb":[[1.02,2]],"id":68579508}],"con":true,"img":false}]}
{"op":"mcm","clk":"11540432867","pt":1719494449969,"mc":[{"id":"1.230180113","rc":[{"atb":[[1.02,0]],"id":68870841}],"con":true,"img":false}]}
{"op":"mcm","clk":"11540432876","pt":1719494450077,"mc":[{"id":"1.230180113","rc":[{"atb":[[1.77,2]],"id":68870841}],"con":true,"img":false}]}
{"op":"mcm","clk":"11540432908","pt":1719494450388,"mc":[{"id":"1.230180113","rc":[{"atb":[[1.02,0]],"id":58974183}],"con":true,"img":false}]}
{"op":"mcm","clk":"11540432922","pt":1719494450496,"mc":[{"id":"1.230180113","rc":[{"atb":[[1.85,2]],"id":58974183}],"con":true,"img":false}]}
{"op":"mcm","clk":"11540432962","pt":1719494450859,"mc":[{"id":"1.230180113","rc":[{"atb":[[1.02,8.47]],"id":50281437}],"con":true,"img":false}]}
{"op":"mcm","clk":"11540432976","pt":1719494450960,"mc":[{"id":"1.230180113","rc":[{"atb":[[1.45,2]],"id":50281437}],"con":true,"img":false}]}
{"op":"mcm","clk":"11540433015","pt":1719494451366,"mc":[{"id":"1.230180113","rc":[{"atb":[[1.02,0]],"id":68579508}],"con":true,"img":false}]}
{"op":"mcm","clk":"11540433026","pt":1719494451470,"mc":[{"id":"1.230180113","rc":[{"atb":[[1.53,2]],"id":68579508}],"con":true,"img":false}]}
{"op":"mcm","clk":"11540433067","pt":1719494451992,"mc":[{"id":"1.230180113","rc":[{"atb":[[1.77,0]],"id":68870841}],"con":true,"img":false}]}
{"op":"mcm","clk":"11540433078","pt":1719494452099,"mc":[{"id":"1.230180113","rc":[{"atb":[[1.02,2]],"id":68870841}],"con":true,"img":false}]}
{"op":"mcm","clk":"11540433100","pt":1719494452252,"mc":[{"id":"1.230180113","rc":[{"atb":[[1.85,0]],"id":58974183}],"con":true,"img":false}]}
{"op":"mcm","clk":"11540433107","pt":1719494452404,"mc":[{"id":"1.230180113","rc":[{"atb":[[1.02,2]],"id":58974183}],"con":true,"img":false}]}
{"op":"mcm","clk":"11540433137","pt":1719494452764,"mc":[{"id":"1.230180113","rc":[{"atb":[[1.45,0]],"id":50281437}],"con":true,"img":false}]}
{"op":"mcm","clk":"11540433145","pt":1719494452869,"mc":[{"id":"1.230180113","rc":[{"atb":[[1.02,10.47]],"id":50281437}],"con":true,"img":false}]}
{"op":"mcm","clk":"11540433187","pt":1719494453392,"mc":[{"id":"1.230180113","rc":[{"atb":[[1.53,0]],"id":68579508}],"con":true,"img":false}]}
{"op":"mcm","clk":"11540433198","pt":1719494453494,"mc":[{"id":"1.230180113","rc":[{"atb":[[1.02,2]],"id":68579508}],"con":true,"img":false}]}
{"op":"mcm","clk":"11540433260","pt":1719494454163,"mc":[{"id":"1.230180113","rc":[{"atb":[[1.02,0]],"id":68870841}],"con":true,"img":false}]}
{"op":"mcm","clk":"11540433268","pt":1719494454269,"mc":[{"id":"1.230180113","rc":[{"atb":[[1.77,2]],"id":68870841}],"con":true,"img":false}]}
{"op":"mcm","clk":"11540433296","pt":1719494454575,"mc":[{"id":"1.230180113","rc":[{"atb":[[1.02,0]],"id":58974183}],"con":true,"img":false}]}
{"op":"mcm","clk":"11540433304","pt":1719494454678,"mc":[{"id":"1.230180113","rc":[{"atb":[[1.85,2]],"id":58974183}],"con":true,"img":false}]}
{"op":"mcm","clk":"11540433329","pt":1719494454988,"mc":[{"id":"1.230180113","rc":[{"atb":[[1.02,8.47]],"id":50281437}],"con":true,"img":false}]}
{"op":"mcm","clk":"11540433342","pt":1719494455094,"mc":[{"id":"1.230180113","rc":[{"atb":[[1.45,2]],"id":50281437}],"con":true,"img":false}]}
{"op":"mcm","clk":"11540433376","pt":1719494455462,"mc":[{"id":"1.230180113","rc":[{"atb":[[1.02,0]],"id":68579508}],"con":true,"img":false}]}
{"op":"mcm","clk":"11540433383","pt":1719494455571,"mc":[{"id":"1.230180113","rc":[{"atb":[[1.53,2]],"id":68579508}],"con":true,"img":false}]}
{"op":"mcm","clk":"11540433433","pt":1719494456077,"mc":[{"id":"1.230180113","rc":[{"atb":[[1.77,0]],"id":68870841}],"con":true,"img":false}]}
{"op":"mcm","clk":"11540433443","pt":1719494456188,"mc":[{"id":"1.230180113","rc":[{"atb":[[1.02,2]],"id":68870841}],"con":true,"img":false}]}
{"op":"mcm","clk":"11540433469","pt":1719494456491,"mc":[{"id":"1.230180113","rc":[{"atb":[[1.85,0]],"id":58974183}],"con":true,"img":false}]}
{"op":"mcm","clk":"11540433477","pt":1719494456596,"mc":[{"id":"1.230180113","rc":[{"atb":[[1.02,2]],"id":58974183}],"con":true,"img":false}]}
{"op":"mcm","clk":"11540433504","pt":1719494456859,"mc":[{"id":"1.230180113","rc":[{"atb":[[1.45,0]],"id":50281437}],"con":true,"img":false}]}
{"op":"mcm","clk":"11540433512","pt":1719494456964,"mc":[{"id":"1.230180113","rc":[{"atb":[[1.02,10.47]],"id":50281437}],"con":true,"img":false}]}
{"op":"mcm","clk":"11540433540","pt":1719494457268,"mc":[{"id":"1.230180113","rc":[{"atb":[[1.53,0]],"id":68579508}],"con":true,"img":false}]}
{"op":"mcm","clk":"11540433545","pt":1719494457370,"mc":[{"id":"1.230180113","rc":[{"atb":[[1.02,2]],"id":68579508}],"con":true,"img":false}]}
{"op":"mcm","clk":"11540433604","pt":1719494458096,"mc":[{"id":"1.230180113","rc":[{"atb":[[1.02,0]],"id":68870841}],"con":true,"img":false}]}
{"op":"mcm","clk":"11540433615","pt":1719494458194,"mc":[{"id":"1.230180113","rc":[{"atb":[[1.77,2]],"id":68870841}],"con":true,"img":false}]}
{"op":"mcm","clk":"11540433642","pt":1719494458458,"mc":[{"id":"1.230180113","rc":[{"atb":[[1.02,0]],"id":58974183}],"con":true,"img":false}]}
{"op":"mcm","clk":"11540433652","pt":1719494458564,"mc":[{"id":"1.230180113","rc":[{"atb":[[1.85,2]],"id":58974183}],"con":true,"img":false}]}
{"op":"mcm","clk":"11540433676","pt":1719494458873,"mc":[{"id":"1.230180113","rc":[{"atb":[[1.02,8.47]],"id":50281437}],"con":true,"img":false}]}
{"op":"mcm","clk":"11540433689","pt":1719494458974,"mc":[{"id":"1.230180113","rc":[{"atb":[[1.45,2]],"id":50281437}],"con":true,"img":false}]}
{"op":"mcm","clk":"11540433711","pt":1719494459289,"mc":[{"id":"1.230180113","rc":[{"atb":[[1.02,0]],"id":68579508}],"con":true,"img":false}]}
{"op":"mcm","clk":"11540433719","pt":1719494459391,"mc":[{"id":"1.230180113","rc":[{"atb":[[1.53,2]],"id":68579508}],"con":true,"img":false}]}
{"op":"mcm","clk":"11540433790","pt":1719494460168,"mc":[{"id":"1.230180113","rc":[{"atb":[[1.77,0]],"id":68870841}],"con":true,"img":false}]}
{"op":"mcm","clk":"11540433802","pt":1719494460267,"mc":[{"id":"1.230180113","rc":[{"atb":[[1.02,2]],"id":68870841}],"con":true,"img":false}]}
{"op":"mcm","clk":"11540433829","pt":1719494460580,"mc":[{"id":"1.230180113","rc":[{"atb":[[1.85,0]],"id":58974183}],"con":true,"img":false}]}
{"op":"mcm","clk":"11540433837","pt":1719494460684,"mc":[{"id":"1.230180113","rc":[{"atb":[[1.02,2]],"id":58974183}],"con":true,"img":false}]}
{"op":"mcm","clk":"11540433889","pt":1719494461210,"mc":[{"id":"1.230180113","rc":[{"atb":[[1.45,0]],"id":50281437}],"con":true,"img":false}]}
{"op":"mcm","clk":"11540433902","pt":1719494461311,"mc":[{"id":"1.230180113","rc":[{"atb":[[1.02,10.47]],"id":50281437}],"con":true,"img":false}]}
{"op":"mcm","clk":"11540433965","pt":1719494461890,"mc":[{"id":"1.230180113","rc":[{"atb":[[1.53,0]],"id":68579508}],"con":true,"img":false}]}
{"op":"mcm","clk":"11540433977","pt":1719494461990,"mc":[{"id":"1.230180113","rc":[{"atb":[[1.02,2]],"id":68579508}],"con":true,"img":false}]}
{"op":"mcm","clk":"11540434031","pt":1719494462669,"mc":[{"id":"1.230180113","rc":[{"atb":[[1.02,0]],"id":68870841}],"con":true,"img":false}]}
{"op":"mcm","clk":"11540434037","pt":1719494462770,"mc":[{"id":"1.230180113","rc":[{"atb":[[1.77,2]],"id":68870841}],"con":true,"img":false}]}
{"op":"mcm","clk":"11540434063","pt":1719494463084,"mc":[{"id":"1.230180113","rc":[{"atb":[[1.02,0]],"id":58974183}],"con":true,"img":false}]}
{"op":"mcm","clk":"11540434074","pt":1719494463187,"mc":[{"id":"1.230180113","rc":[{"atb":[[1.85,2]],"id":58974183}],"con":true,"img":false}]}
{"op":"mcm","clk":"11540434098","pt":1719494463495,"mc":[{"id":"1.230180113","rc":[{"atb":[[1.02,8.47]],"id":50281437}],"con":true,"img":false}]}
{"op":"mcm","clk":"11540434107","pt":1719494463604,"mc":[{"id":"1.230180113","rc":[{"atb":[[1.45,2]],"id":50281437}],"con":true,"img":false}]}
{"op":"mcm","clk":"11540434135","pt":1719494463971,"mc":[{"id":"1.230180113","rc":[{"atb":[[1.02,0]],"id":68579508}],"con":true,"img":false}]}
{"op":"mcm","clk":"11540434145","pt":1719494464082,"mc":[{"id":"1.230180113","rc":[{"atb":[[1.53,2]],"id":68579508}],"con":true,"img":false}]}
{"op":"mcm","clk":"11540434200","pt":1719494464593,"mc":[{"id":"1.230180113","rc":[{"atb":[[1.77,0]],"id":68870841}],"con":true,"img":false}]}
{"op":"mcm","clk":"11540434213","pt":1719494464691,"mc":[{"id":"1.230180113","rc":[{"atb":[[1.02,2]],"id":68870841}],"con":true,"img":false}]}
{"op":"mcm","clk":"11540434246","pt":1719494465001,"mc":[{"id":"1.230180113","rc":[{"atb":[[1.85,0]],"id":58974183}],"con":true,"img":false}]}
{"op":"mcm","clk":"11540434258","pt":1719494465104,"mc":[{"id":"1.230180113","rc":[{"atb":[[1.02,2]],"id":58974183}],"con":true,"img":false}]}
{"op":"mcm","clk":"11540434301","pt":1719494465520,"mc":[{"id":"1.230180113","rc":[{"atb":[[1.45,0]],"id":50281437}],"con":true,"img":false}]}
{"op":"mcm","clk":"11540434311","pt":1719494465592,"mc":[{"id":"1.230180113","rc":[{"atb":[[1.02,10.47]],"id":50281437}],"con":true,"img":false}]}
{"op":"mcm","clk":"11540434348","pt":1719494465989,"mc":[{"id":"1.230180113","rc":[{"atb":[[1.53,0]],"id":68579508}],"con":true,"img":false}]}
{"op":"mcm","clk":"11540434361","pt":1719494466087,"mc":[{"id":"1.230180113","rc":[{"atb":[[1.02,2]],"id":68579508}],"con":true,"img":false}]}
{"op":"mcm","clk":"11540434407","pt":1719494466599,"mc":[{"id":"1.230180113","rc":[{"atb":[[1.02,0]],"id":68870841}],"con":true,"img":false}]}
{"op":"mcm","clk":"11540434414","pt":1719494466703,"mc":[{"id":"1.230180113","rc":[{"atb":[[1.77,2]],"id":68870841}],"con":true,"img":false}]}
{"op":"mcm","clk":"11540434445","pt":1719494467013,"mc":[{"id":"1.230180113","rc":[{"atb":[[1.02,0]],"id":58974183}],"con":true,"img":false}]}
{"op":"mcm","clk":"11540434457","pt":1719494467121,"mc":[{"id":"1.230180113","rc":[{"atb":[[1.85,2]],"id":58974183}],"con":true,"img":false}]}
{"op":"mcm","clk":"11540434527","pt":1719494467789,"mc":[{"id":"1.230180113","rc":[{"atb":[[1.02,8.47]],"id":50281437}],"con":true,"img":false}]}
{"op":"mcm","clk":"11540434535","pt":1719494467902,"mc":[{"id":"1.230180113","rc":[{"atb":[[1.45,2]],"id":50281437}],"con":true,"img":false}]}
{"op":"mcm","clk":"11540434559","pt":1719494468206,"mc":[{"id":"1.230180113","rc":[{"atb":[[1.02,0]],"id":68579508}],"con":true,"img":false}]}
{"op":"mcm","clk":"11540434566","pt":1719494468304,"mc":[{"id":"1.230180113","rc":[{"atb":[[1.53,2]],"id":68579508}],"con":true,"img":false}]}
{"op":"mcm","clk":"11540434612","pt":1719494468774,"mc":[{"id":"1.230180113","rc":[{"atb":[[1.77,0]],"id":68870841}],"con":true,"img":false}]}
{"op":"mcm","clk":"11540434619","pt":1719494468874,"mc":[{"id":"1.230180113","rc":[{"atb":[[1.02,2]],"id":68870841}],"con":true,"img":false}]}
{"op":"mcm","clk":"11540434663","pt":1719494469391,"mc":[{"id":"1.230180113","rc":[{"atb":[[1.85,0]],"id":58974183}],"con":true,"img":false}]}
{"op":"mcm","clk":"11540434673","pt":1719494469494,"mc":[{"id":"1.230180113","rc":[{"atb":[[1.02,2]],"id":58974183}],"con":true,"img":false}]}
{"op":"mcm","clk":"11540434710","pt":1719494470021,"mc":[{"id":"1.230180113","rc":[{"atb":[[1.45,0]],"id":50281437}],"con":true,"img":false}]}
{"op":"mcm","clk":"11540434722","pt":1719494470121,"mc":[{"id":"1.230180113","rc":[{"atb":[[1.02,10.47]],"id":50281437}],"con":true,"img":false}]}
{"op":"mcm","clk":"11540434750","pt":1719494470378,"mc":[{"id":"1.230180113","rc":[{"atb":[[1.53,0]],"id":68579508}],"con":true,"img":false}]}
{"op":"mcm","clk":"11540434760","pt":1719494470484,"mc":[{"id":"1.230180113","rc":[{"atb":[[1.02,2]],"id":68579508}],"con":true,"img":false}]}
{"op":"mcm","clk":"11540434843","pt":1719494471412,"mc":[{"id":"1.230180113","rc":[{"atb":[[1.02,0]],"id":68870841}],"con":true,"img":false}]}
{"op":"mcm","clk":"11540434851","pt":1719494471515,"mc":[{"id":"1.230180113","rc":[{"atb":[[1.77,2]],"id":68870841}],"con":true,"img":false}]}
{"op":"mcm","clk":"11540434877","pt":1719494471779,"mc":[{"id":"1.230180113","rc":[{"atb":[[1.02,0]],"id":58974183}],"con":true,"img":false}]}
{"op":"mcm","clk":"11540434887","pt":1719494471880,"mc":[{"id":"1.230180113","rc":[{"atb":[[1.85,2]],"id":58974183}],"con":true,"img":false}]}
{"op":"mcm","clk":"11540434911","pt":1719494472194,"mc":[{"id":"1.230180113","rc":[{"atb":[[1.02,8.47]],"id":50281437}],"con":true,"img":false}]}
{"op":"mcm","clk":"11540434921","pt":1719494472295,"mc":[{"id":"1.230180113","rc":[{"atb":[[1.45,2]],"id":50281437}],"con":true,"img":false}]}
{"op":"mcm","clk":"11540434965","pt":1719494472813,"mc":[{"id":"1.230180113","rc":[{"atb":[[1.02,0]],"id":68579508}],"con":true,"img":false}]}
{"op":"mcm","clk":"11540434973","pt":1719494472917,"mc":[{"id":"1.230180113","rc":[{"atb":[[1.53,2]],"id":68579508}],"con":true,"img":false}]}
{"op":"mcm","clk":"11540435013","pt":1719494473491,"mc":[{"id":"1.230180113","rc":[{"atb":[[1.77,0]],"id":68870841}],"con":true,"img":false}]}
{"op":"mcm","clk":"11540435021","pt":1719494473593,"mc":[{"id":"1.230180113","rc":[{"atb":[[1.02,2]],"id":68870841}],"con":true,"img":false}]}
{"op":"mcm","clk":"11540435074","pt":1719494474318,"mc":[{"id":"1.230180113","rc":[{"atb":[[1.85,0]],"id":58974183}],"con":true,"img":false}]}
{"op":"mcm","clk":"11540435083","pt":1719494474417,"mc":[{"id":"1.230180113","rc":[{"atb":[[1.02,2]],"id":58974183}],"con":true,"img":false}]}
{"op":"mcm","clk":"11540435120","pt":1719494474778,"mc":[{"id":"1.230180113","rc":[{"atb":[[1.45,0]],"id":50281437}],"con":true,"img":false}]}
{"op":"mcm","clk":"11540435131","pt":1719494474882,"mc":[{"id":"1.230180113","rc":[{"atb":[[1.02,10.47]],"id":50281437}],"con":true,"img":false}]}
{"op":"mcm","clk":"11540435175","pt":1719494475398,"mc":[{"id":"1.230180113","rc":[{"atb":[[1.53,0]],"id":68579508}],"con":true,"img":false}]}
{"op":"mcm","clk":"11540435184","pt":1719494475502,"mc":[{"id":"1.230180113","rc":[{"atb":[[1.02,2]],"id":68579508}],"con":true,"img":false}]}
{"op":"mcm","clk":"11540435249","pt":1719494476183,"mc":[{"id":"1.230180113","rc":[{"atb":[[1.02,0]],"id":68870841}],"con":true,"img":false}]}
{"op":"mcm","clk":"11540435257","pt":1719494476284,"mc":[{"id":"1.230180113","rc":[{"atb":[[1.77,2]],"id":68870841}],"con":true,"img":false}]}
{"op":"mcm","clk":"11540435288","pt":1719494476697,"mc":[{"id":"1.230180113","rc":[{"atb":[[1.02,0]],"id":58974183}],"con":true,"img":false}]}
{"op":"mcm","clk":"11540435297","pt":1719494476805,"mc":[{"id":"1.230180113","rc":[{"atb":[[1.85,2]],"id":58974183}],"con":true,"img":false}]}
{"op":"mcm","clk":"11540435347","pt":1719494477422,"mc":[{"id":"1.230180113","rc":[{"atb":[[1.02,8.47]],"id":50281437}],"con":true,"img":false}]}
{"op":"mcm","clk":"11540435357","pt":1719494477530,"mc":[{"id":"1.230180113","rc":[{"atb":[[1.45,2]],"id":50281437}],"con":true,"img":false}]}
{"op":"mcm","clk":"11540435390","pt":1719494477889,"mc":[{"id":"1.230180113","rc":[{"atb":[[1.02,0]],"id":68579508}],"con":true,"img":false}]}
{"op":"mcm","clk":"11540435394","pt":1719494478003,"mc":[{"id":"1.230180113","rc":[{"atb":[[1.53,2]],"id":68579508}],"con":true,"img":false}]}
{"op":"mcm","clk":"11540435440","pt":1719494478620,"mc":[{"id":"1.230180113","rc":[{"atb":[[1.77,0]],"id":68870841}],"con":true,"img":false}]}
{"op":"mcm","clk":"11540435452","pt":1719494478724,"mc":[{"id":"1.230180113","rc":[{"atb":[[1.02,2]],"id":68870841}],"con":true,"img":false}]}
{"op":"mcm","clk":"11540435477","pt":1719494478986,"mc":[{"id":"1.230180113","rc":[{"atb":[[1.85,0]],"id":58974183},{"spn":2.26,"spf":"NaN","id":68169358},{"spn":2.64,"spf":"NaN","id":68579508}],"con":true,"img":false}]}
{"op":"mcm","clk":"11540435487","pt":1719494479097,"mc":[{"id":"1.230180113","rc":[{"atb":[[1.02,2]],"id":58974183}],"con":true,"img":false}]}
{"op":"mcm","clk":"11540435511","pt":1719494479401,"mc":[{"id":"1.230180113","rc":[{"atb":[[1.45,0]],"id":50281437}],"con":true,"img":false}]}
{"op":"mcm","clk":"11540435523","pt":1719494479507,"mc":[{"id":"1.230180113","rc":[{"atb":[[1.02,10.47]],"id":50281437}],"con":true,"img":false}]}
{"op":"mcm","clk":"11540435554","pt":1719494479818,"mc":[{"id":"1.230180113","rc":[{"atb":[[1.53,0]],"id":68579508}],"con":true,"img":false}]}
{"op":"mcm","clk":"11540435566","pt":1719494479923,"mc":[{"id":"1.230180113","rc":[{"atb":[[1.02,2]],"id":68579508}],"con":true,"img":false}]}
{"op":"mcm","clk":"11540435667","pt":1719494481117,"mc":[{"id":"1.230180113","rc":[{"atb":[[1.02,0]],"id":68870841}],"con":true,"img":false}]}
{"op":"mcm","clk":"11540435677","pt":1719494481218,"mc":[{"id":"1.230180113","rc":[{"atb":[[1.77,2]],"id":68870841}],"con":true,"img":false}]}
{"op":"mcm","clk":"11540435704","pt":1719494481583,"mc":[{"id":"1.230180113","rc":[{"atb":[[1.02,0]],"id":58974183}],"con":true,"img":false}]}
{"op":"mcm","clk":"11540435713","pt":1719494481688,"mc":[{"id":"1.230180113","rc":[{"atb":[[1.85,2]],"id":58974183}],"con":true,"img":false}]}
{"op":"mcm","clk":"11540435740","pt":1719494482107,"mc":[{"id":"1.230180113","rc":[{"atb":[[1.02,8.47]],"id":50281437}],"con":true,"img":false}]}
{"op":"mcm","clk":"11540435751","pt":1719494482205,"mc":[{"id":"1.230180113","rc":[{"atb":[[1.45,2]],"id":50281437}],"con":true,"img":false}]}
{"op":"mcm","clk":"11540435778","pt":1719494482523,"mc":[{"id":"1.230180113","rc":[{"atb":[[1.02,0]],"id":68579508}],"con":true,"img":false}]}
{"op":"mcm","clk":"11540435792","pt":1719494482618,"mc":[{"id":"1.230180113","rc":[{"atb":[[1.53,2]],"id":68579508}],"con":true,"img":false}]}
{"op":"mcm","clk":"11540435834","pt":1719494483093,"mc":[{"id":"1.230180113","rc":[{"atb":[[1.77,0]],"id":68870841}],"con":true,"img":false}]}
{"op":"mcm","clk":"11540435845","pt":1719494483199,"mc":[{"id":"1.230180113","rc":[{"atb":[[1.02,2]],"id":68870841}],"con":true,"img":false}]}
{"op":"mcm","clk":"11540435880","pt":1719494483500,"mc":[{"id":"1.230180113","rc":[{"atb":[[1.85,0]],"id":58974183}],"con":true,"img":false}]}
{"op":"mcm","clk":"11540435889","pt":1719494483603,"mc":[{"id":"1.230180113","rc":[{"atb":[[1.02,2]],"id":58974183}],"con":true,"img":false}]}
{"op":"mcm","clk":"11540435901","pt":1719494483810,"mc":[{"id":"1.230180113","rc":[{"atb":[[1.45,0]],"id":50281437}],"con":true,"img":false}]}
{"op":"mcm","clk":"11540435909","pt":1719494483912,"mc":[{"id":"1.230180113","rc":[{"atb":[[1.02,10.47]],"id":50281437}],"con":true,"img":false}]}
{"op":"mcm","clk":"11540435942","pt":1719494484328,"mc":[{"id":"1.230180113","rc":[{"atb":[[1.53,0]],"id":68579508}],"con":true,"img":false}]}
{"op":"mcm","clk":"11540435949","pt":1719494484434,"mc":[{"id":"1.230180113","rc":[{"atb":[[1.02,2]],"id":68579508}],"con":true,"img":false}]}
{"op":"mcm","clk":"11540436021","pt":1719494485324,"mc":[{"id":"1.230180113","rc":[{"atb":[[1.02,0]],"id":68870841}],"con":true,"img":false}]}
{"op":"mcm","clk":"11540436032","pt":1719494485421,"mc":[{"id":"1.230180113","rc":[{"atb":[[1.77,2]],"id":68870841}],"con":true,"img":false}]}
{"op":"mcm","clk":"11540436059","pt":1719494485737,"mc":[{"id":"1.230180113","rc":[{"atb":[[1.02,0]],"id":58974183}],"con":true,"img":false}]}
{"op":"mcm","clk":"11540436068","pt":1719494485790,"mc":[{"id":"1.230180113","rc":[{"atb":[[1.85,2]],"id":58974183}],"con":true,"img":false}]}
{"op":"mcm","clk":"11540436108","pt":1719494486206,"mc":[{"id":"1.230180113","rc":[{"atb":[[1.02,8.47]],"id":50281437}],"con":true,"img":false}]}
{"op":"mcm","clk":"11540436120","pt":1719494486311,"mc":[{"id":"1.230180113","rc":[{"atb":[[1.45,2]],"id":50281437}],"con":true,"img":false}]}
{"op":"mcm","clk":"11540436147","pt":1719494486622,"mc":[{"id":"1.230180113","rc":[{"atb":[[1.02,0]],"id":68579508}],"con":true,"img":false}]}
{"op":"mcm","clk":"11540436158","pt":1719494486722,"mc":[{"id":"1.230180113","rc":[{"atb":[[1.53,2]],"id":68579508}],"con":true,"img":false}]}
{"op":"mcm","clk":"11540436208","pt":1719494487301,"mc":[{"id":"1.230180113","rc":[{"atb":[[1.77,0]],"id":68870841}],"con":true,"img":false}]}
{"op":"mcm","clk":"11540436218","pt":1719494487401,"mc":[{"id":"1.230180113","rc":[{"atb":[[1.02,2]],"id":68870841}],"con":true,"img":false}]}
{"op":"mcm","clk":"11540436245","pt":1719494487711,"mc":[{"id":"1.230180113","rc":[{"atb":[[1.85,0]],"id":58974183}],"con":true,"img":false}]}
{"op":"mcm","clk":"11540436258","pt":1719494487815,"mc":[{"id":"1.230180113","rc":[{"atb":[[1.02,2]],"id":58974183}],"con":true,"img":false}]}
{"op":"mcm","clk":"11540436288","pt":1719494488127,"mc":[{"id":"1.230180113","rc":[{"atb":[[1.45,0]],"id":50281437}],"con":true,"img":false}]}
{"op":"mcm","clk":"11540436299","pt":1719494488229,"mc":[{"id":"1.230180113","rc":[{"atb":[[1.02,10.47]],"id":50281437}],"con":true,"img":false}]}
{"op":"mcm","clk":"11540436360","pt":1719494488913,"mc":[{"id":"1.230180113","rc":[{"atb":[[1.53,0]],"id":68579508}],"con":true,"img":false}]}
{"op":"mcm","clk":"11540436371","pt":1719494489010,"mc":[{"id":"1.230180113","rc":[{"atb":[[1.02,2]],"id":68579508}],"con":true,"img":false}]}
{"op":"mcm","clk":"11540436447","pt":1719494489790,"mc":[{"id":"1.230180113","rc":[{"atb":[[1.02,0]],"id":68870841}],"con":true,"img":false}]}
{"op":"mcm","clk":"11540436455","pt":1719494489893,"mc":[{"id":"1.230180113","rc":[{"atb":[[1.77,2]],"id":68870841}],"con":true,"img":false}]}
{"op":"mcm","clk":"11540436485","pt":1719494490212,"mc":[{"id":"1.230180113","rc":[{"atb":[[1.02,0]],"id":58974183}],"con":true,"img":false}]}
{"op":"mcm","clk":"11540436495","pt":1719494490318,"mc":[{"id":"1.230180113","rc":[{"atb":[[1.85,2]],"id":58974183}],"con":true,"img":false}]}
{"op":"mcm","clk":"11540436523","pt":1719494490630,"mc":[{"id":"1.230180113","rc":[{"atb":[[1.02,8.47]],"id":50281437}],"con":true,"img":false}]}
{"op":"mcm","clk":"11540436536","pt":1719494490725,"mc":[{"id":"1.230180113","rc":[{"atb":[[1.45,2]],"id":50281437}],"con":true,"img":false}]}
{"op":"mcm","clk":"11540436565","pt":1719494491036,"mc":[{"id":"1.230180113","rc":[{"atb":[[1.02,0]],"id":68579508}],"con":true,"img":false}]}
{"op":"mcm","clk":"11540436574","pt":1719494491097,"mc":[{"id":"1.230180113","rc":[{"atb":[[1.53,2]],"id":68579508}],"con":true,"img":false}]}
{"op":"mcm","clk":"11540436634","pt":1719494491813,"mc":[{"id":"1.230180113","rc":[{"atb":[[1.77,0]],"id":68870841}],"con":true,"img":false}]}
{"op":"mcm","clk":"11540436641","pt":1719494491917,"mc":[{"id":"1.230180113","rc":[{"atb":[[1.02,2]],"id":68870841}],"con":true,"img":false}]}
{"op":"mcm","clk":"11540436666","pt":1719494492234,"mc":[{"id":"1.230180113","rc":[{"atb":[[1.85,0]],"id":58974183}],"con":true,"img":false}]}
{"op":"mcm","clk":"11540436677","pt":1719494492336,"mc":[{"id":"1.230180113","rc":[{"atb":[[1.02,2]],"id":58974183}],"con":true,"img":false}]}
{"op":"mcm","clk":"11540436727","pt":1719494492800,"mc":[{"id":"1.230180113","rc":[{"atb":[[1.45,0]],"id":50281437}],"con":true,"img":false}]}
{"op":"mcm","clk":"11540436736","pt":1719494492910,"mc":[{"id":"1.230180113","rc":[{"atb":[[1.02,10.47]],"id":50281437}],"con":true,"img":false}]}
{"op":"mcm","clk":"11540436766","pt":1719494493216,"mc":[{"id":"1.230180113","rc":[{"atb":[[1.53,0]],"id":68579508}],"con":true,"img":false}]}
{"op":"mcm","clk":"11540436775","pt":1719494493320,"mc":[{"id":"1.230180113","rc":[{"atb":[[1.02,2]],"id":68579508}],"con":true,"img":false}]}
{"op":"mcm","clk":"11540436830","pt":1719494494000,"mc":[{"id":"1.230180113","rc":[{"atb":[[1.02,0]],"id":68870841}],"con":true,"img":false}]}
{"op":"mcm","clk":"11540436839","pt":1719494494101,"mc":[{"id":"1.230180113","rc":[{"atb":[[1.77,2]],"id":68870841}],"con":true,"img":false}]}
{"op":"mcm","clk":"11540436862","pt":1719494494405,"mc":[{"id":"1.230180113","rc":[{"atb":[[1.02,0]],"id":58974183}],"con":true,"img":false}]}
{"op":"mcm","clk":"11540436870","pt":1719494494508,"mc":[{"id":"1.230180113","rc":[{"atb":[[1.85,2]],"id":58974183}],"con":true,"img":false}]}
{"op":"mcm","clk":"11540436915","pt":1719494495047,"mc":[{"id":"1.230180113","rc":[{"atb":[[1.02,8.47]],"id":50281437}],"con":true,"img":false}]}
{"op":"mcm","clk":"11540436928","pt":1719494495102,"mc":[{"id":"1.230180113","rc":[{"atb":[[1.45,2]],"id":50281437}],"con":true,"img":false}]}
{"op":"mcm","clk":"11540436976","pt":1719494495515,"mc":[{"id":"1.230180113","rc":[{"atb":[[1.02,0]],"id":68579508}],"con":true,"img":false}]}
{"op":"mcm","clk":"11540436985","pt":1719494495618,"mc":[{"id":"1.230180113","rc":[{"atb":[[1.53,2]],"id":68579508}],"con":true,"img":false}]}
{"op":"mcm","clk":"11540437054","pt":1719494496343,"mc":[{"id":"1.230180113","rc":[{"atb":[[1.77,0]],"id":68870841}],"con":true,"img":false}]}
{"op":"mcm","clk":"11540437062","pt":1719494496398,"mc":[{"id":"1.230180113","rc":[{"atb":[[1.02,2]],"id":68870841}],"con":true,"img":false}]}
{"op":"mcm","clk":"11540437093","pt":1719494496709,"mc":[{"id":"1.230180113","rc":[{"atb":[[1.85,0]],"id":58974183}],"con":true,"img":false}]}
{"op":"mcm","clk":"11540437100","pt":1719494496818,"mc":[{"id":"1.230180113","rc":[{"atb":[[1.02,2]],"id":58974183}],"con":true,"img":false}]}
{"op":"mcm","clk":"11540437140","pt":1719494497338,"mc":[{"id":"1.230180113","rc":[{"atb":[[1.45,0]],"id":50281437}],"con":true,"img":false}]}
{"op":"mcm","clk":"11540437151","pt":1719494497445,"mc":[{"id":"1.230180113","rc":[{"atb":[[1.02,10.47]],"id":50281437}],"con":true,"img":false}]}
{"op":"mcm","clk":"11540437187","pt":1719494497805,"mc":[{"id":"1.230180113","rc":[{"atb":[[1.53,0]],"id":68579508}],"con":true,"img":false}]}
{"op":"mcm","clk":"11540437194","pt":1719494497907,"mc":[{"id":"1.230180113","rc":[{"atb":[[1.02,2]],"id":68579508}],"con":true,"img":false}]}
{"op":"mcm","clk":"11540437242","pt":1719494498423,"mc":[{"id":"1.230180113","rc":[{"atb":[[1.02,0]],"id":68870841}],"con":true,"img":false}]}
{"op":"mcm","clk":"11540437255","pt":1719494498528,"mc":[{"id":"1.230180113","rc":[{"atb":[[1.77,2]],"id":68870841}],"con":true,"img":false}]}
{"op":"mcm","clk":"11540437297","pt":1719494499049,"mc":[{"id":"1.230180113","rc":[{"atb":[[1.02,0]],"id":58974183}],"con":true,"img":false}]}
{"op":"mcm","clk":"11540437309","pt":1719494499158,"mc":[{"id":"1.230180113","rc":[{"atb":[[1.85,2]],"id":58974183}],"con":true,"img":false}]}
{"op":"mcm","clk":"11540437366","pt":1719494499519,"mc":[{"id":"1.230180113","rc":[{"atb":[[1.02,8.47]],"id":50281437}],"con":true,"img":false}]}
{"op":"mcm","clk":"11540437380","pt":1719494499618,"mc":[{"id":"1.230180113","rc":[{"atb":[[1.45,2]],"id":50281437}],"con":true,"img":false}]}
{"op":"mcm","clk":"11540437414","pt":1719494500032,"mc":[{"id":"1.230180113","rc":[{"atb":[[1.02,0]],"id":68579508}],"con":true,"img":false}]}
{"op":"mcm","clk":"11540437419","pt":1719494500135,"mc":[{"id":"1.230180113","rc":[{"atb":[[1.53,2]],"id":68579508}],"con":true,"img":false}]}
{"op":"mcm","clk":"11540437465","pt":1719494500714,"mc":[{"id":"1.230180113","rc":[{"atb":[[1.77,0]],"id":68870841}],"con":true,"img":false}]}
{"op":"mcm","clk":"11540437473","pt":1719494500818,"mc":[{"id":"1.230180113","rc":[{"atb":[[1.02,2]],"id":68870841}],"con":true,"img":false}]}
{"op":"mcm","clk":"11540437513","pt":1719494501231,"mc":[{"id":"1.230180113","rc":[{"atb":[[1.85,0]],"id":58974183}],"con":true,"img":false}]}
{"op":"mcm","clk":"11540437523","pt":1719494501335,"mc":[{"id":"1.230180113","rc":[{"atb":[[1.02,2]],"id":58974183}],"con":true,"img":false}]}
{"op":"mcm","clk":"11540437582","pt":1719494502006,"mc":[{"id":"1.230180113","rc":[{"atb":[[1.45,0]],"id":50281437}],"con":true,"img":false}]}
{"op":"mcm","clk":"11540437595","pt":1719494502110,"mc":[{"id":"1.230180113","rc":[{"atb":[[1.02,10.47]],"id":50281437}],"con":true,"img":false}]}
{"op":"mcm","clk":"11540437631","pt":1719494502522,"mc":[{"id":"1.230180113","rc":[{"atb":[[1.53,0]],"id":68579508}],"con":true,"img":false}]}
{"op":"mcm","clk":"11540437635","pt":1719494502625,"mc":[{"id":"1.230180113","rc":[{"atb":[[1.02,2]],"id":68579508}],"con":true,"img":false}]}
{"op":"mcm","clk":"11540437712","pt":1719494503556,"mc":[{"id":"1.230180113","rc":[{"atb":[[1.02,0]],"id":68870841}],"con":true,"img":false}]}
{"op":"mcm","clk":"11540437722","pt":1719494503608,"mc":[{"id":"1.230180113","rc":[{"atb":[[1.77,2]],"id":68870841}],"con":true,"img":false}]}
{"op":"mcm","clk":"11540437748","pt":1719494504024,"mc":[{"id":"1.230180113","rc":[{"atb":[[1.02,0]],"id":58974183}],"con":true,"img":false}]}
{"op":"mcm","clk":"11540437755","pt":1719494504130,"mc":[{"id":"1.230180113","rc":[{"atb":[[1.85,2]],"id":58974183}],"con":true,"img":false}]}
{"op":"mcm","clk":"11540437776","pt":1719494504440,"mc":[{"id":"1.230180113","rc":[{"atb":[[1.02,8.47]],"id":50281437}],"con":true,"img":false}]}
{"op":"mcm","clk":"11540437788","pt":1719494504544,"mc":[{"id":"1.230180113","rc":[{"atb":[[1.45,2]],"id":50281437}],"con":true,"img":false}]}
{"op":"mcm","clk":"11540437829","pt":1719494505013,"mc":[{"id":"1.230180113","rc":[{"atb":[[1.02,0]],"id":68579508}],"con":true,"img":false}]}
{"op":"mcm","clk":"11540437837","pt":1719494505118,"mc":[{"id":"1.230180113","rc":[{"atb":[[1.53,2]],"id":68579508}],"con":true,"img":false}]}
{"op":"mcm","clk":"11540438484","pt":1719494513062,"mc":[{"id":"1.230180113","rc":[{"atb":[[1.77,0]],"id":68870841}],"con":true,"img":false}]}
{"op":"mcm","clk":"11540438495","pt":1719494513167,"mc":[{"id":"1.230180113","rc":[{"atb":[[1.02,2]],"id":68870841}],"con":true,"img":false}]}
{"op":"mcm","clk":"11540438511","pt":1719494513329,"mc":[{"id":"1.230180113","rc":[{"atb":[[1.85,0]],"id":58974183}],"con":true,"img":false}]}
{"op":"mcm","clk":"11540438521","pt":1719494513428,"mc":[{"id":"1.230180113","rc":[{"atb":[[1.02,2]],"id":58974183}],"con":true,"img":false}]}
{"op":"mcm","clk":"11540438552","pt":1719494513838,"mc":[{"id":"1.230180113","rc":[{"atb":[[1.45,0]],"id":50281437}],"con":true,"img":false}]}
{"op":"mcm","clk":"11540438558","pt":1719494513943,"mc":[{"id":"1.230180113","rc":[{"atb":[[1.02,10.47]],"id":50281437}],"con":true,"img":false}]}
{"op":"mcm","clk":"11540438576","pt":1719494514150,"mc":[{"id":"1.230180113","rc":[{"atb":[[1.53,0]],"id":68579508}],"con":true,"img":false}]}
{"op":"mcm","clk":"11540438585","pt":1719494514256,"mc":[{"id":"1.230180113","rc":[{"atb":[[1.02,2]],"id":68579508}],"con":true,"img":false}]}
{"op":"mcm","clk":"11540438669","pt":1719494515446,"mc":[{"id":"1.230180113","rc":[{"atb":[[1.02,0]],"id":68870841}],"con":true,"img":false}]}
{"op":"mcm","clk":"11540438677","pt":1719494515544,"mc":[{"id":"1.230180113","rc":[{"atb":[[1.77,2]],"id":68870841}],"con":true,"img":false}]}
{"op":"mcm","clk":"11540438693","pt":1719494515854,"mc":[{"id":"1.230180113","rc":[{"atb":[[1.02,0]],"id":58974183}],"con":true,"img":false}]}
{"op":"mcm","clk":"11540438700","pt":1719494515958,"mc":[{"id":"1.230180113","rc":[{"atb":[[1.85,2]],"id":58974183}],"con":true,"img":false}]}
{"op":"mcm","clk":"11540438727","pt":1719494516376,"mc":[{"id":"1.230180113","rc":[{"atb":[[1.02,8.47]],"id":50281437}],"con":true,"img":false}]}
{"op":"mcm","clk":"11540438735","pt":1719494516424,"mc":[{"id":"1.230180113","rc":[{"atb":[[1.45,2]],"id":50281437}],"con":true,"img":false}]}
{"op":"mcm","clk":"11540438764","pt":1719494516836,"mc":[{"id":"1.230180113","rc":[{"atb":[[1.02,0]],"id":68579508}],"con":true,"img":false}]}
{"op":"mcm","clk":"11540438769","pt":1719494516944,"mc":[{"id":"1.230180113","rc":[{"atb":[[1.53,2]],"id":68579508}],"con":true,"img":false}]}
{"op":"mcm","clk":"11540438816","pt":1719494517665,"mc":[{"id":"1.230180113","rc":[{"atb":[[1.77,0]],"id":68870841}],"con":true,"img":false}]}
{"op":"mcm","clk":"11540438825","pt":1719494517763,"mc":[{"id":"1.230180113","rc":[{"atb":[[1.02,2]],"id":68870841}],"con":true,"img":false}]}
{"op":"mcm","clk":"11540438855","pt":1719494518147,"mc":[{"id":"1.230180113","rc":[{"atb":[[1.85,0]],"id":58974183}],"con":true,"img":false}]}
{"op":"mcm","clk":"11540438863","pt":1719494518238,"mc":[{"id":"1.230180113","rc":[{"atb":[[1.02,2]],"id":58974183}],"con":true,"img":false}]}
{"op":"mcm","clk":"11540438897","pt":1719494518646,"mc":[{"id":"1.230180113","rc":[{"atb":[[1.45,0]],"id":50281437}],"con":true,"img":false}]}
{"op":"mcm","clk":"11540438908","pt":1719494518750,"mc":[{"id":"1.230180113","rc":[{"atb":[[1.02,10.47]],"id":50281437}],"con":true,"img":false}]}
{"op":"mcm","clk":"11540438924","pt":1719494518957,"mc":[{"id":"1.230180113","rc":[{"atb":[[1.53,0]],"id":68579508}],"con":true,"img":false}]}
{"op":"mcm","clk":"11540438931","pt":1719494519061,"mc":[{"id":"1.230180113","rc":[{"atb":[[1.02,2]],"id":68579508}],"con":true,"img":false}]}
{"op":"mcm","clk":"11540438994","pt":1719494520040,"mc":[{"id":"1.230180113","rc":[{"atb":[[1.02,0]],"id":68870841}],"con":true,"img":false}]}
{"op":"mcm","clk":"11540439002","pt":1719494520145,"mc":[{"id":"1.230180113","rc":[{"atb":[[1.77,2]],"id":68870841}],"con":true,"img":false}]}
{"op":"mcm","clk":"11540439027","pt":1719494520458,"mc":[{"id":"1.230180113","rc":[{"atb":[[1.02,0]],"id":58974183}],"con":true,"img":false}]}
{"op":"mcm","clk":"11540439036","pt":1719494520563,"mc":[{"id":"1.230180113","rc":[{"atb":[[1.85,2]],"id":58974183}],"con":true,"img":false}]}
{"op":"mcm","clk":"11540439095","pt":1719494521236,"mc":[{"id":"1.230180113","rc":[{"atb":[[1.02,8.47]],"id":50281437}],"con":true,"img":false}]}
{"op":"mcm","clk":"11540439105","pt":1719494521344,"mc":[{"id":"1.230180113","rc":[{"atb":[[1.22,0]],"id":68169358},{"atb":[[1.45,2]],"id":50281437}],"con":true,"img":false}]}
{"op":"mcm","clk":"11540439168","pt":1719494522069,"mc":[{"id":"1.230180113","rc":[{"atb":[[1.02,0]],"id":68579508}],"con":true,"img":false}]}
{"op":"mcm","clk":"11540439176","pt":1719494522171,"mc":[{"id":"1.230180113","rc":[{"atb":[[1.53,2]],"id":68579508}],"con":true,"img":false}]}
{"op":"mcm","clk":"11540439266","pt":1719494523367,"mc":[{"id":"1.230180113","rc":[{"atb":[[1.77,0]],"id":68870841}],"con":true,"img":false}]}
{"op":"mcm","clk":"11540439275","pt":1719494523472,"mc":[{"id":"1.230180113","rc":[{"atb":[[1.02,2]],"id":68870841}],"con":true,"img":false}]}
{"op":"mcm","clk":"11540439310","pt":1719494523838,"mc":[{"id":"1.230180113","rc":[{"atb":[[1.85,0]],"id":58974183}],"con":true,"img":false}]}
{"op":"mcm","clk":"11540439320","pt":1719494523941,"mc":[{"id":"1.230180113","rc":[{"atb":[[1.02,2]],"id":58974183}],"con":true,"img":false}]}
{"op":"mcm","clk":"11540439349","pt":1719494524252,"mc":[{"id":"1.230180113","rc":[{"atb":[[1.45,0]],"id":50281437}],"con":true,"img":false}]}
{"op":"mcm","clk":"11540439360","pt":1719494524354,"mc":[{"id":"1.230180113","rc":[{"atb":[[1.02,10.47]],"id":50281437}],"con":true,"img":false}]}
{"op":"mcm","clk":"11540439399","pt":1719494524768,"mc":[{"id":"1.230180113","rc":[{"atb":[[1.53,0]],"id":68579508}],"con":true,"img":false}]}
{"op":"mcm","clk":"11540439410","pt":1719494524869,"mc":[{"id":"1.230180113","rc":[{"atb":[[1.02,2]],"id":68579508}],"con":true,"img":false}]}
{"op":"mcm","clk":"11540439482","pt":1719494525771,"mc":[{"id":"1.230180113","rc":[{"atb":[[1.02,0]],"id":68870841}],"con":true,"img":false}]}
{"op":"mcm","clk":"11540439490","pt":1719494525879,"mc":[{"id":"1.230180113","rc":[{"atb":[[1.77,2]],"id":68870841}],"con":true,"img":false}]}
{"op":"mcm","clk":"11540439519","pt":1719494526291,"mc":[{"id":"1.230180113","rc":[{"atb":[[1.02,0]],"id":58974183}],"con":true,"img":false}]}
{"op":"mcm","clk":"11540439528","pt":1719494526340,"mc":[{"id":"1.230180113","rc":[{"atb":[[1.85,2]],"id":58974183}],"con":true,"img":false}]}
{"op":"mcm","clk":"11540439553","pt":1719494526653,"mc":[{"id":"1.230180113","rc":[{"atb":[[1.02,8.47]],"id":50281437}],"con":true,"img":false}]}
{"op":"mcm","clk":"11540439564","pt":1719494526759,"mc":[{"id":"1.230180113","rc":[{"atb":[[1.45,2]],"id":50281437}],"con":true,"img":false}]}
{"op":"mcm","clk":"11540439626","pt":1719494527384,"mc":[{"id":"1.230180113","rc":[{"atb":[[1.02,0]],"id":68579508}],"con":true,"img":false}]}
{"op":"mcm","clk":"11540439638","pt":1719494527483,"mc":[{"id":"1.230180113","rc":[{"atb":[[1.53,2]],"id":68579508}],"con":true,"img":false}]}
{"op":"mcm","clk":"11540439736","pt":1719494528469,"mc":[{"id":"1.230180113","rc":[{"atb":[[1.77,0]],"id":68870841}],"con":true,"img":false}]}
{"op":"mcm","clk":"11540439745","pt":1719494528574,"mc":[{"id":"1.230180113","rc":[{"atb":[[1.02,2]],"id":68870841}],"con":true,"img":false}]}
{"op":"mcm","clk":"11540439772","pt":1719494528883,"mc":[{"id":"1.230180113","rc":[{"atb":[[1.85,0]],"id":58974183}],"con":true,"img":false}]}
{"op":"mcm","clk":"11540439781","pt":1719494528986,"mc":[{"id":"1.230180113","rc":[{"atb":[[1.02,2]],"id":58974183}],"con":true,"img":false}]}
{"op":"mcm","clk":"11540439789","pt":1719494529090,"mc":[{"id":"1.230180113","rc":[{"atb":[[1.01,103.74]],"id":58974183},{"atl":[[1000,1.7]],"id":58974183},{"atb":[[1.01,103.74]],"id":68870841},{"atl":[[1000,1.7]],"id":68870841},{"atl":[[1000,1.7]],"id":50281437}],"con":true,"img":false}]}
{"op":"mcm","clk":"11540439796","pt":1719494529194,"mc":[{"id":"1.230180113","rc":[{"atb":[[1.01,103.74],[1.45,0]],"id":50281437}],"con":true,"img":false}]}
{"op":"mcm","clk":"11540439808","pt":1719494529244,"mc":[{"id":"1.230180113","rc":[{"atb":[[1.01,102.38]],"id":58974183},{"atl":[[1000,0.01]],"id":58974183},{"atb":[[1.01,102.42]],"id":68870841},{"atl":[[1000,0.01]],"id":68870841},{"atb":[[1.02,10.47]],"id":50281437},{"atl":[[1000,0.03]],"id":50281437}],"con":true,"img":false}]}
{"op":"mcm","clk":"11540439816","pt":1719494529352,"mc":[{"id":"1.230180113","rc":[{"atb":[[1.01,102.68]],"id":50281437}],"con":true,"img":false}]}
{"op":"mcm","clk":"11540439827","pt":1719494529457,"mc":[{"id":"1.230180113","rc":[{"atb":[[1.01,102.04]],"id":58974183},{"atl":[[1000,0]],"id":58974183},{"atb":[[1.01,102.04]],"id":68870841},{"atl":[[1000,0]],"id":68870841},{"atl":[[1000,0]],"id":50281437}],"con":true,"img":false}]}
{"op":"mcm","clk":"11540439836","pt":1719494529559,"mc":[{"id":"1.230180113","rc":[{"atb":[[1.86,0.34]],"id":58974183},{"atl":[[28,0.01]],"id":58974183},{"atb":[[1.77,0.38]],"id":68870841},{"atl":[[22,0.01]],"id":68870841},{"atb":[[1.01,102.04]],"id":50281437},{"atl":[[9.4,0.03]],"id":50281437}],"con":true,"img":false}]}
{"op":"mcm","clk":"11540439844","pt":1719494529657,"mc":[{"id":"1.230180113","rc":[{"atb":[[1.46,1.64]],"id":50281437}],"con":true,"img":false}]}
{"op":"mcm","clk":"11540439877","pt":1719494530078,"mc":[{"id":"1.230180113","rc":[{"atb":[[1.53,0]],"id":68579508}],"con":true,"img":false}]}
{"op":"mcm","clk":"11540439887","pt":1719494530179,"mc":[{"id":"1.230180113","rc":[{"atb":[[1.02,2]],"id":68579508}],"con":true,"img":false}]}
{"op":"mcm","clk":"11540440042","pt":1719494532264,"mc":[{"id":"1.230180113","rc":[{"atb":[[1.02,0]],"id":68870841}],"con":true,"img":false}]}
{"op":"mcm","clk":"11540440056","pt":1719494532361,"mc":[{"id":"1.230180113","rc":[{"atb":[[1.77,2.38]],"id":68870841}],"con":true,"img":false}]}
{"op":"mcm","clk":"11540440092","pt":1719494532776,"mc":[{"id":"1.230180113","rc":[{"atb":[[1.02,0]],"id":58974183}],"con":true,"img":false}]}
{"op":"mcm","clk":"11540440099","pt":1719494532881,"mc":[{"id":"1.230180113","rc":[{"atb":[[1.85,2]],"id":58974183}],"con":true,"img":false}]}
{"op":"mcm","clk":"11540440119","pt":1719494533191,"mc":[{"id":"1.230180113","rc":[{"atb":[[1.02,8.47]],"id":50281437}],"con":true,"img":false}]}
{"op":"mcm","clk":"11540440125","pt":1719494533293,"mc":[{"id":"1.230180113","rc":[{"atb":[[1.45,2]],"id":50281437}],"con":true,"img":false}]}
{"op":"mcm","clk":"11540440158","pt":1719494533658,"mc":[{"id":"1.230180113","rc":[{"atb":[[1.02,0]],"id":68579508}],"con":true,"img":false}]}
{"op":"mcm","clk":"11540440166","pt":1719494533762,"mc":[{"id":"1.230180113","rc":[{"atb":[[1.53,2]],"id":68579508}],"con":true,"img":false}]}
{"op":"mcm","clk":"11540440322","pt":1719494536004,"mc":[{"id":"1.230180113","rc":[{"atb":[[1.77,0.38]],"id":68870841}],"con":true,"img":false}]}
{"op":"mcm","clk":"11540440330","pt":1719494536074,"mc":[{"id":"1.230180113","rc":[{"atb":[[1.02,2]],"id":68870841}],"con":true,"img":false}]}
{"op":"mcm","clk":"11540440406","pt":1719494537101,"mc":[{"id":"1.230180113","rc":[{"atb":[[1.85,0]],"id":58974183}],"con":true,"img":false}]}
{"op":"mcm","clk":"11540440414","pt":1719494537205,"mc":[{"id":"1.230180113","rc":[{"atb":[[1.02,2]],"id":58974183}],"con":true,"img":false}]}
{"op":"mcm","clk":"11540440486","pt":1719494537981,"mc":[{"id":"1.230180113","rc":[{"atb":[[1.45,0]],"id":50281437}],"con":true,"img":false}]}
{"op":"mcm","clk":"11540440500","pt":1719494538085,"mc":[{"id":"1.230180113","rc":[{"atb":[[1.02,10.47]],"id":50281437}],"con":true,"img":false}]}
{"op":"mcm","clk":"11540440580","pt":1719494538868,"mc":[{"id":"1.230180113","rc":[{"atb":[[1.53,0]],"id":68579508}],"con":true,"img":false}]}
{"op":"mcm","clk":"11540440593","pt":1719494538968,"mc":[{"id":"1.230180113","rc":[{"atb":[[1.02,2]],"id":68579508}],"con":true,"img":false}]}
{"op":"mcm","clk":"11540440688","pt":1719494540107,"mc":[{"id":"1.230180113","rc":[{"atb":[[1.02,0]],"id":68870841},{"spn":2.63,"spf":"NaN","id":68579508}],"con":true,"img":false}]}
{"op":"mcm","clk":"11540440695","pt":1719494540214,"mc":[{"id":"1.230180113","rc":[{"atb":[[1.77,2.38]],"id":68870841}],"con":true,"img":false}]}
{"op":"mcm","clk":"11540440725","pt":1719494540571,"mc":[{"id":"1.230180113","rc":[{"atb":[[1.02,0]],"id":58974183}],"con":true,"img":false}]}
{"op":"mcm","clk":"11540440733","pt":1719494540675,"mc":[{"id":"1.230180113","rc":[{"atb":[[1.85,2]],"id":58974183}],"con":true,"img":false}]}
{"op":"mcm","clk":"11540440773","pt":1719494541191,"mc":[{"id":"1.230180113","rc":[{"atb":[[1.02,8.47]],"id":50281437}],"con":true,"img":false}]}
{"op":"mcm","clk":"11540440784","pt":1719494541295,"mc":[{"id":"1.230180113","rc":[{"atb":[[1.45,2]],"id":50281437}],"con":true,"img":false}]}
{"op":"mcm","clk":"11540440812","pt":1719494541606,"mc":[{"id":"1.230180113","rc":[{"atb":[[1.02,0]],"id":68579508}],"con":true,"img":false}]}
{"op":"mcm","clk":"11540440825","pt":1719494541709,"mc":[{"id":"1.230180113","rc":[{"atb":[[1.53,2]],"id":68579508}],"con":true,"img":false}]}
{"op":"mcm","clk":"11540440848","pt":1719494541971,"mc":[{"id":"1.230180113","rc":[{"atb":[[1.28,19.75]],"id":68169358}],"con":true,"img":false}]}
{"op":"mcm","clk":"11540440858","pt":1719494542073,"mc":[{"id":"1.230180113","rc":[{"atb":[[1.26,0],[1.29,17.94]],"id":68169358}],"con":true,"img":false}]}
{"op":"mcm","clk":"11540440922","pt":1719494542802,"mc":[{"id":"1.230180113","rc":[{"atb":[[1.77,0.38]],"id":68870841}],"con":true,"img":false}]}
{"op":"mcm","clk":"11540440933","pt":1719494542913,"mc":[{"id":"1.230180113","rc":[{"atb":[[1.02,2]],"id":68870841}],"con":true,"img":false}]}
{"op":"mcm","clk":"11540440975","pt":1719494543382,"mc":[{"id":"1.230180113","rc":[{"atb":[[1.85,0]],"id":58974183}],"con":true,"img":false}]}
{"op":"mcm","clk":"11540440983","pt":1719494543481,"mc":[{"id":"1.230180113","rc":[{"atb":[[1.02,2]],"id":58974183}],"con":true,"img":false}]}
{"op":"mcm","clk":"11540441017","pt":1719494543896,"mc":[{"id":"1.230180113","rc":[{"atb":[[1.45,0]],"id":50281437}],"con":true,"img":false}]}
{"op":"mcm","clk":"11540441026","pt":1719494544002,"mc":[{"id":"1.230180113","rc":[{"atb":[[1.02,10.47]],"id":50281437}],"con":true,"img":false}]}
{"op":"mcm","clk":"11540441072","pt":1719494544476,"mc":[{"id":"1.230180113","rc":[{"atb":[[1.53,0]],"id":68579508}],"con":true,"img":false}]}
{"op":"mcm","clk":"11540441085","pt":1719494544577,"mc":[{"id":"1.230180113","rc":[{"atb":[[1.02,2]],"id":68579508}],"con":true,"img":false}]}
{"op":"mcm","clk":"11540441119","pt":1719494544987,"mc":[{"id":"1.230180113","rc":[{"atb":[[1.27,0]],"id":68169358}],"con":true,"img":false}]}
{"op":"mcm","clk":"11540441127","pt":1719494545089,"mc":[{"id":"1.230180113","rc":[{"atb":[[1.3,2]],"id":68169358}],"con":true,"img":false}]}
{"op":"mcm","clk":"11540441207","pt":1719494546072,"mc":[{"id":"1.230180113","rc":[{"atb":[[1.02,0]],"id":68870841}],"con":true,"img":false}]}
{"op":"mcm","clk":"11540441219","pt":1719494546175,"mc":[{"id":"1.230180113","rc":[{"atb":[[1.77,2.38]],"id":68870841}],"con":true,"img":false}]}
{"op":"mcm","clk":"11540441257","pt":1719494546700,"mc":[{"id":"1.230180113","rc":[{"atb":[[1.02,0]],"id":58974183}],"con":true,"img":false}]}
{"op":"mcm","clk":"11540441272","pt":1719494546801,"mc":[{"id":"1.230180113","rc":[{"atb":[[1.85,2]],"id":58974183}],"con":true,"img":false}]}
{"op":"mcm","clk":"11540441311","pt":1719494547215,"mc":[{"id":"1.230180113","rc":[{"atb":[[1.02,8.47]],"id":50281437}],"con":true,"img":false}]}
{"op":"mcm","clk":"11540441318","pt":1719494547319,"mc":[{"id":"1.230180113","rc":[{"atb":[[1.45,2]],"id":50281437}],"con":true,"img":false}]}
{"op":"mcm","clk":"11540441356","pt":1719494547785,"mc":[{"id":"1.230180113","rc":[{"atb":[[1.02,0]],"id":68579508}],"con":true,"img":false}]}
{"op":"mcm","clk":"11540441367","pt":1719494547890,"mc":[{"id":"1.230180113","rc":[{"atb":[[1.53,2]],"id":68579508}],"con":true,"img":false}]}
{"op":"mcm","clk":"11540441481","pt":1719494549186,"mc":[{"id":"1.230180113","rc":[{"atb":[[1.77,0.38]],"id":68870841}],"con":true,"img":false}]}
{"op":"mcm","clk":"11540441488","pt":1719494549293,"mc":[{"id":"1.230180113","rc":[{"atb":[[1.02,2]],"id":68870841}],"con":true,"img":false}]}
{"op":"mcm","clk":"11540441515","pt":1719494549601,"mc":[{"id":"1.230180113","rc":[{"atb":[[1.85,0]],"id":58974183}],"con":true,"img":false}]}
{"op":"mcm","clk":"11540441526","pt":1719494549702,"mc":[{"id":"1.230180113","rc":[{"atb":[[1.02,2]],"id":58974183}],"con":true,"img":false}]}
{"op":"mcm","clk":"11540441543","pt":1719494549912,"mc":[{"id":"1.230180113","rc":[{"atb":[[1.45,0]],"id":50281437}],"con":true,"img":false}]}
{"op":"mcm","clk":"11540441553","pt":1719494550021,"mc":[{"id":"1.230180113","rc":[{"atb":[[1.02,10.47]],"id":50281437}],"con":true,"img":false}]}
{"op":"mcm","clk":"11540441588","pt":1719494550386,"mc":[{"id":"1.230180113","rc":[{"atb":[[1.53,0]],"id":68579508}],"con":true,"img":false}]}
{"op":"mcm","clk":"11540441594","pt":1719494550484,"mc":[{"id":"1.230180113","rc":[{"atb":[[1.02,2]],"id":68579508}],"con":true,"img":false}]}
{"op":"mcm","clk":"11540441724","pt":1719494552093,"mc":[{"id":"1.230180113","rc":[{"atb":[[1.02,0]],"id":68870841}],"con":true,"img":false}]}
{"op":"mcm","clk":"11540441737","pt":1719494552197,"mc":[{"id":"1.230180113","rc":[{"atb":[[1.77,2.38]],"id":68870841}],"con":true,"img":false}]}
{"op":"mcm","clk":"11540441763","pt":1719494552504,"mc":[{"id":"1.230180113","rc":[{"atb":[[1.02,0]],"id":58974183}],"con":true,"img":false}]}
{"op":"mcm","clk":"11540441770","pt":1719494552611,"mc":[{"id":"1.230180113","rc":[{"atb":[[1.85,2]],"id":58974183}],"con":true,"img":false}]}
{"op":"mcm","clk":"11540441791","pt":1719494552927,"mc":[{"id":"1.230180113","rc":[{"atb":[[1.02,8.47]],"id":50281437}],"con":true,"img":false}]}
{"op":"mcm","clk":"11540441801","pt":1719494553021,"mc":[{"id":"1.230180113","rc":[{"atb":[[1.45,2]],"id":50281437}],"con":true,"img":false}]}
{"op":"mcm","clk":"11540441829","pt":1719494553281,"mc":[{"id":"1.230180113","rc":[{"atb":[[1.02,0]],"id":68579508}],"con":true,"img":false}]}
{"op":"mcm","clk":"11540441836","pt":1719494553384,"mc":[{"id":"1.230180113","rc":[{"atb":[[1.53,2]],"id":68579508}],"con":true,"img":false}]}
{"op":"mcm","clk":"11540441892","pt":1719494554107,"mc":[{"id":"1.230180113","rc":[{"atb":[[1.77,0.38]],"id":68870841}],"con":true,"img":false}]}
{"op":"mcm","clk":"11540441901","pt":1719494554211,"mc":[{"id":"1.230180113","rc":[{"atb":[[1.02,2]],"id":68870841}],"con":true,"img":false}]}
{"op":"mcm","clk":"11540441921","pt":1719494554528,"mc":[{"id":"1.230180113","rc":[{"atb":[[1.25,1]],"id":68169358}],"con":true,"img":false}]}
{"op":"mcm","clk":"11540441940","pt":1719494554731,"mc":[{"id":"1.230180113","rc":[{"atb":[[1.85,0]],"id":58974183}],"con":true,"img":false}]}
{"op":"mcm","clk":"11540441949","pt":1719494554779,"mc":[{"id":"1.230180113","rc":[{"atb":[[1.02,2]],"id":58974183}],"con":true,"img":false}]}
{"op":"mcm","clk":"11540441979","pt":1719494555087,"mc":[{"id":"1.230180113","rc":[{"atb":[[1.45,0]],"id":50281437}],"con":true,"img":false}]}
{"op":"mcm","clk":"11540441987","pt":1719494555190,"mc":[{"id":"1.230180113","rc":[{"atb":[[1.02,10.47]],"id":50281437}],"con":true,"img":false}]}
{"op":"mcm","clk":"11540442017","pt":1719494555500,"mc":[{"id":"1.230180113","rc":[{"atb":[[1.53,0]],"id":68579508}],"con":true,"img":false}]}
{"op":"mcm","clk":"11540442024","pt":1719494555607,"mc":[{"id":"1.230180113","rc":[{"atb":[[1.02,2]],"id":68579508}],"con":true,"img":false}]}
{"op":"mcm","clk":"11540442123","pt":1719494556792,"mc":[{"id":"1.230180113","rc":[{"atb":[[1.02,0]],"id":68870841}],"con":true,"img":false}]}
{"op":"mcm","clk":"11540442130","pt":1719494556896,"mc":[{"id":"1.230180113","rc":[{"atb":[[1.77,2.38]],"id":68870841}],"con":true,"img":false}]}
{"op":"mcm","clk":"11540442161","pt":1719494557310,"mc":[{"id":"1.230180113","rc":[{"atb":[[1.02,0]],"id":58974183}],"con":true,"img":false}]}
{"op":"mcm","clk":"11540442170","pt":1719494557418,"mc":[{"id":"1.230180113","rc":[{"atb":[[1.85,2]],"id":58974183}],"con":true,"img":false}]}
{"op":"mcm","clk":"11540442191","pt":1719494557731,"mc":[{"id":"1.230180113","rc":[{"atb":[[1.02,8.47]],"id":50281437}],"con":true,"img":false}]}
{"op":"mcm","clk":"11540442203","pt":1719494557832,"mc":[{"id":"1.230180113","rc":[{"atb":[[1.45,2]],"id":50281437}],"con":true,"img":false}]}
{"op":"mcm","clk":"11540442236","pt":1719494558187,"mc":[{"id":"1.230180113","rc":[{"atb":[[1.02,0]],"id":68579508}],"con":true,"img":false}]}
{"op":"mcm","clk":"11540442247","pt":1719494558290,"mc":[{"id":"1.230180113","rc":[{"atb":[[1.53,2]],"id":68579508}],"con":true,"img":false}]}
{"op":"mcm","clk":"11540442304","pt":1719494559121,"mc":[{"id":"1.230180113","rc":[{"atb":[[1.77,0.38]],"id":68870841}],"con":true,"img":false}]}
{"op":"mcm","clk":"11540442313","pt":1719494559226,"mc":[{"id":"1.230180113","rc":[{"atb":[[1.02,2]],"id":68870841}],"con":true,"img":false}]}
{"op":"mcm","clk":"11540442341","pt":1719494559533,"mc":[{"id":"1.230180113","rc":[{"atb":[[1.85,0]],"id":58974183}],"con":true,"img":false}]}
{"op":"mcm","clk":"11540442349","pt":1719494559585,"mc":[{"id":"1.230180113","rc":[{"atb":[[1.02,2]],"id":58974183}],"con":true,"img":false}]}
{"op":"mcm","clk":"11540442400","pt":1719494560209,"mc":[{"id":"1.230180113","rc":[{"atb":[[1.45,0]],"id":50281437}],"con":true,"img":false}]}
{"op":"mcm","clk":"11540442412","pt":1719494560314,"mc":[{"id":"1.230180113","rc":[{"atb":[[1.02,10.47]],"id":50281437}],"con":true,"img":false}]}
{"op":"mcm","clk":"11540442470","pt":1719494560891,"mc":[{"id":"1.230180113","rc":[{"atb":[[1.53,0]],"id":68579508}],"con":true,"img":false}]}
{"op":"mcm","clk":"11540442482","pt":1719494560991,"mc":[{"id":"1.230180113","rc":[{"atb":[[1.02,2]],"id":68579508}],"con":true,"img":false}]}
{"op":"mcm","clk":"11540442509","pt":1719494561311,"mc":[{"id":"1.230180113","rc":[{"atb":[[1.86,0]],"id":58974183},{"atl":[[28,0]],"id":58974183},{"atb":[[1.77,0]],"id":68870841},{"atl":[[22,0]],"id":68870841},{"atb":[[1.46,1]],"id":50281437},{"atl":[[9.4,0]],"id":50281437}],"con":true,"img":false}]}
{"op":"mcm","clk":"11540442589","pt":1719494562136,"mc":[{"id":"1.230180113","rc":[{"atb":[[1.02,0]],"id":68870841}],"con":true,"img":false}]}
{"op":"mcm","clk":"11540442603","pt":1719494562238,"mc":[{"id":"1.230180113","rc":[{"atb":[[1.77,2]],"id":68870841}],"con":true,"img":false}]}
{"op":"mcm","clk":"11540442643","pt":1719494562599,"mc":[{"id":"1.230180113","rc":[{"atb":[[1.02,0]],"id":58974183}],"con":true,"img":false}]}
{"op":"mcm","clk":"11540442654","pt":1719494562703,"mc":[{"id":"1.230180113","rc":[{"atb":[[1.85,2]],"id":58974183}],"con":true,"img":false}]}
{"op":"mcm","clk":"11540442707","pt":1719494563330,"mc":[{"id":"1.230180113","rc":[{"atb":[[1.02,8.47]],"id":50281437}],"con":true,"img":false}]}
{"op":"mcm","clk":"11540442712","pt":1719494563430,"mc":[{"id":"1.230180113","rc":[{"atb":[[1.45,2]],"id":50281437}],"con":true,"img":false}]}
{"op":"mcm","clk":"11540442760","pt":1719494563898,"mc":[{"id":"1.230180113","rc":[{"atb":[[1.02,0]],"id":68579508}],"con":true,"img":false}]}
{"op":"mcm","clk":"11540442770","pt":1719494564005,"mc":[{"id":"1.230180113","rc":[{"atb":[[1.53,2]],"id":68579508}],"con":true,"img":false}]}
{"op":"mcm","clk":"11540442965","pt":1719494566329,"mc":[{"id":"1.230180113","rc":[{"atb":[[1.77,0]],"id":68870841}],"con":true,"img":false}]}
{"op":"mcm","clk":"11540442978","pt":1719494566428,"mc":[{"id":"1.230180113","rc":[{"atb":[[1.02,2]],"id":68870841}],"con":true,"img":false}]}
{"op":"mcm","clk":"11540443011","pt":1719494566841,"mc":[{"id":"1.230180113","rc":[{"atb":[[1.85,0]],"id":58974183}],"con":true,"img":false}]}
{"op":"mcm","clk":"11540443020","pt":1719494566946,"mc":[{"id":"1.230180113","rc":[{"atb":[[1.02,2]],"id":58974183}],"con":true,"img":false}]}
{"op":"mcm","clk":"11540443049","pt":1719494567315,"mc":[{"id":"1.230180113","rc":[{"atb":[[1.45,0]],"id":50281437}],"con":true,"img":false}]}
{"op":"mcm","clk":"11540443055","pt":1719494567415,"mc":[{"id":"1.230180113","rc":[{"atb":[[1.02,10.47]],"id":50281437}],"con":true,"img":false}]}
{"op":"mcm","clk":"11540443087","pt":1719494567827,"mc":[{"id":"1.230180113","rc":[{"atb":[[1.53,0]],"id":68579508}],"con":true,"img":false}]}
{"op":"mcm","clk":"11540443091","pt":1719494567931,"mc":[{"id":"1.230180113","rc":[{"atb":[[1.02,2]],"id":68579508}],"con":true,"img":false}]}
{"op":"mcm","clk":"11540443184","pt":1719494568912,"mc":[{"id":"1.230180113","rc":[{"atb":[[1.02,0]],"id":68870841}],"con":true,"img":false}]}
{"op":"mcm","clk":"11540443193","pt":1719494569021,"mc":[{"id":"1.230180113","rc":[{"atb":[[1.77,2]],"id":68870841}],"con":true,"img":false}]}
{"op":"mcm","clk":"11540443226","pt":1719494569436,"mc":[{"id":"1.230180113","rc":[{"atb":[[1.02,0]],"id":58974183}],"con":true,"img":false}]}
{"op":"mcm","clk":"11540443233","pt":1719494569539,"mc":[{"id":"1.230180113","rc":[{"atb":[[1.85,2]],"id":58974183}],"con":true,"img":false}]}
{"op":"mcm","clk":"11540443269","pt":1719494569950,"mc":[{"id":"1.230180113","rc":[{"atb":[[1.02,8.47]],"id":50281437}],"con":true,"img":false}]}
{"op":"mcm","clk":"11540443276","pt":1719494570054,"mc":[{"id":"1.230180113","rc":[{"atb":[[1.45,2]],"id":50281437}],"con":true,"img":false}]}
{"op":"mcm","clk":"11540443326","pt":1719494570526,"mc":[{"id":"1.230180113","rc":[{"atb":[[1.02,0]],"id":68579508}],"con":true,"img":false}]}
{"op":"mcm","clk":"11540443334","pt":1719494570630,"mc":[{"id":"1.230180113","rc":[{"atb":[[1.53,2]],"id":68579508}],"con":true,"img":false}]}
{"op":"mcm","clk":"11540443462","pt":1719494572129,"mc":[{"id":"1.230180113","rc":[{"atb":[[1.77,0]],"id":68870841}],"con":true,"img":false}]}
{"op":"mcm","clk":"11540443470","pt":1719494572231,"mc":[{"id":"1.230180113","rc":[{"atb":[[1.02,2]],"id":68870841}],"con":true,"img":false}]}
{"op":"mcm","clk":"11540443527","pt":1719494572868,"mc":[{"id":"1.230180113","rc":[{"atb":[[1.85,0]],"id":58974183}],"con":true,"img":false}]}
{"op":"mcm","clk":"11540443547","pt":1719494572924,"mc":[{"id":"1.230180113","rc":[{"atb":[[1.02,2]],"id":58974183}],"con":true,"img":false}]}
{"op":"mcm","clk":"11540443574","pt":1719494573234,"mc":[{"id":"1.230180113","rc":[{"atb":[[1.45,0]],"id":50281437}],"con":true,"img":false}]}
{"op":"mcm","clk":"11540443584","pt":1719494573342,"mc":[{"id":"1.230180113","rc":[{"atb":[[1.02,10.47]],"id":50281437}],"con":true,"img":false}]}
{"op":"mcm","clk":"11540443616","pt":1719494573755,"mc":[{"id":"1.230180113","rc":[{"atb":[[1.53,0]],"id":68579508}],"con":true,"img":false}]}
{"op":"mcm","clk":"11540443625","pt":1719494573860,"mc":[{"id":"1.230180113","rc":[{"atb":[[1.02,2]],"id":68579508}],"con":true,"img":false}]}
{"op":"mcm","clk":"11540443760","pt":1719494575120,"mc":[{"id":"1.230180113","rc":[{"atb":[[1.02,0]],"id":68870841}],"con":true,"img":false}]}
{"op":"mcm","clk":"11540443768","pt":1719494575227,"mc":[{"id":"1.230180113","rc":[{"atb":[[1.77,2]],"id":68870841}],"con":true,"img":false}]}
{"op":"mcm","clk":"11540443824","pt":1719494575651,"mc":[{"id":"1.230180113","rc":[{"atb":[[1.02,0]],"id":58974183}],"con":true,"img":false}]}
{"op":"mcm","clk":"11540443834","pt":1719494575751,"mc":[{"id":"1.230180113","rc":[{"atb":[[1.85,2]],"id":58974183}],"con":true,"img":false}]}
{"op":"mcm","clk":"11540443890","pt":1719494576269,"mc":[{"id":"1.230180113","rc":[{"atb":[[1.02,8.47]],"id":50281437}],"con":true,"img":false}]}
{"op":"mcm","clk":"11540443900","pt":1719494576379,"mc":[{"id":"1.230180113","rc":[{"atb":[[1.45,2]],"id":50281437}],"con":true,"img":false}]}
{"op":"mcm","clk":"11540443948","pt":1719494576838,"mc":[{"id":"1.230180113","rc":[{"atb":[[1.02,0]],"id":68579508}],"con":true,"img":false}]}
{"op":"mcm","clk":"11540443957","pt":1719494576944,"mc":[{"id":"1.230180113","rc":[{"atb":[[1.53,2]],"id":68579508}],"con":true,"img":false}]}
{"op":"mcm","clk":"11540444028","pt":1719494577827,"mc":[{"id":"1.230180113","rc":[{"atb":[[1.77,0]],"id":68870841}],"con":true,"img":false}]}
{"op":"mcm","clk":"11540444039","pt":1719494577931,"mc":[{"id":"1.230180113","rc":[{"atb":[[1.02,2]],"id":68870841}],"con":true,"img":false}]}
{"op":"mcm","clk":"11540444067","pt":1719494578248,"mc":[{"id":"1.230180113","rc":[{"atb":[[1.85,0]],"id":58974183}],"con":true,"img":false}]}
{"op":"mcm","clk":"11540444076","pt":1719494578346,"mc":[{"id":"1.230180113","rc":[{"atb":[[1.02,2]],"id":58974183}],"con":true,"img":false}]}
{"op":"mcm","clk":"11540444115","pt":1719494578760,"mc":[{"id":"1.230180113","rc":[{"atb":[[1.45,0]],"id":50281437}],"con":true,"img":false}]}
{"op":"mcm","clk":"11540444122","pt":1719494578865,"mc":[{"id":"1.230180113","rc":[{"atb":[[1.02,10.47]],"id":50281437}],"con":true,"img":false}]}
{"op":"mcm","clk":"11540444169","pt":1719494579444,"mc":[{"id":"1.230180113","rc":[{"atb":[[1.53,0]],"id":68579508}],"con":true,"img":false}]}
{"op":"mcm","clk":"11540444177","pt":1719494579550,"mc":[{"id":"1.230180113","rc":[{"atb":[[1.02,2]],"id":68579508}],"con":true,"img":false}]}
{"op":"mcm","clk":"11540444279","pt":1719494580750,"mc":[{"id":"1.230180113","rc":[{"atb":[[1.02,0]],"id":68870841}],"con":true,"img":false}]}
{"op":"mcm","clk":"11540444291","pt":1719494580853,"mc":[{"id":"1.230180113","rc":[{"atb":[[1.77,2]],"id":68870841}],"con":true,"img":false}]}
{"op":"mcm","clk":"11540444311","pt":1719494581164,"mc":[{"id":"1.230180113","rc":[{"atb":[[1.02,0]],"id":58974183},{"atb":[[1.27,5]],"id":68169358}],"con":true,"img":false}]}
{"op":"mcm","clk":"11540444320","pt":1719494581267,"mc":[{"id":"1.230180113","rc":[{"atb":[[1.85,2]],"id":58974183}],"con":true,"img":false}]}
{"op":"mcm","clk":"11540444326","pt":1719494581377,"mc":[{"id":"1.230180113","rc":[{"atb":[[1.27,3.63]],"id":68169358}],"con":true,"img":false}]}
{"op":"mcm","clk":"11540444351","pt":1719494581635,"mc":[{"id":"1.230180113","rc":[{"atb":[[1.02,8.47]],"id":50281437}],"con":true,"img":false}]}
{"op":"mcm","clk":"11540444360","pt":1719494581742,"mc":[{"id":"1.230180113","rc":[{"atb":[[1.45,2]],"id":50281437}],"con":true,"img":false}]}
{"op":"mcm","clk":"11540444380","pt":1719494582154,"mc":[{"id":"1.230180113","rc":[{"atb":[[1.02,0]],"id":68579508}],"con":true,"img":false}]}
{"op":"mcm","clk":"11540444388","pt":1719494582258,"mc":[{"id":"1.230180113","rc":[{"atb":[[1.53,2]],"id":68579508}],"con":true,"img":false}]}
{"op":"mcm","clk":"11540444471","pt":1719494583250,"mc":[{"id":"1.230180113","rc":[{"atb":[[1.77,0]],"id":68870841}],"con":true,"img":false}]}
{"op":"mcm","clk":"11540444481","pt":1719494583359,"mc":[{"id":"1.230180113","rc":[{"atb":[[1.02,2]],"id":68870841}],"con":true,"img":false}]}
{"op":"mcm","clk":"11540444527","pt":1719494583777,"mc":[{"id":"1.230180113","rc":[{"atb":[[1.85,0]],"id":58974183}],"con":true,"img":false}]}
{"op":"mcm","clk":"11540444535","pt":1719494583831,"mc":[{"id":"1.230180113","rc":[{"atb":[[1.02,2]],"id":58974183}],"con":true,"img":false}]}
{"op":"mcm","clk":"11540444559","pt":1719494584143,"mc":[{"id":"1.230180113","rc":[{"atb":[[1.45,0]],"id":50281437}],"con":true,"img":false}]}
{"op":"mcm","clk":"11540444567","pt":1719494584242,"mc":[{"id":"1.230180113","rc":[{"atb":[[1.02,10.47]],"id":50281437}],"con":true,"img":false}]}
{"op":"mcm","clk":"11540444591","pt":1719494584557,"mc":[{"id":"1.230180113","rc":[{"atb":[[1.53,0]],"id":68579508}],"con":true,"img":false}]}
{"op":"mcm","clk":"11540444603","pt":1719494584660,"mc":[{"id":"1.230180113","rc":[{"atb":[[1.02,2]],"id":68579508}],"con":true,"img":false}]}
{"op":"mcm","clk":"11540444720","pt":1719494585846,"mc":[{"id":"1.230180113","rc":[{"atb":[[1.02,0]],"id":68870841}],"con":true,"img":false}]}
{"op":"mcm","clk":"11540444728","pt":1719494585949,"mc":[{"id":"1.230180113","rc":[{"atb":[[1.77,2]],"id":68870841}],"con":true,"img":false}]}
{"op":"mcm","clk":"11540444751","pt":1719494586260,"mc":[{"id":"1.230180113","rc":[{"atb":[[1.02,0]],"id":58974183}],"con":true,"img":false}]}
{"op":"mcm","clk":"11540444758","pt":1719494586364,"mc":[{"id":"1.230180113","rc":[{"atb":[[1.85,2]],"id":58974183}],"con":true,"img":false}]}
{"op":"mcm","clk":"11540444791","pt":1719494586776,"mc":[{"id":"1.230180113","rc":[{"atb":[[1.02,8.47]],"id":50281437}],"con":true,"img":false}]}
{"op":"mcm","clk":"11540444804","pt":1719494586889,"mc":[{"id":"1.230180113","rc":[{"atb":[[1.45,2]],"id":50281437}],"con":true,"img":false}]}
{"op":"mcm","clk":"11540444842","pt":1719494587346,"mc":[{"id":"1.230180113","rc":[{"atb":[[1.02,0]],"id":68579508}],"con":true,"img":false}]}
{"op":"mcm","clk":"11540444853","pt":1719494587453,"mc":[{"id":"1.230180113","rc":[{"atb":[[1.53,2]],"id":68579508}],"con":true,"img":false}]}
{"op":"mcm","clk":"11540444970","pt":1719494588760,"mc":[{"id":"1.230180113","rc":[{"atb":[[1.77,0]],"id":68870841}],"con":true,"img":false}]}
{"op":"mcm","clk":"11540444977","pt":1719494588860,"mc":[{"id":"1.230180113","rc":[{"atb":[[1.02,2]],"id":68870841}],"con":true,"img":false}]}
{"op":"mcm","clk":"11540445008","pt":1719494589273,"mc":[{"id":"1.230180113","rc":[{"atb":[[1.85,0]],"id":58974183}],"con":true,"img":false}]}
{"op":"mcm","clk":"11540445016","pt":1719494589375,"mc":[{"id":"1.230180113","rc":[{"atb":[[1.02,2]],"id":58974183}],"con":true,"img":false}]}
{"op":"mcm","clk":"11540445052","pt":1719494589847,"mc":[{"id":"1.230180113","rc":[{"atb":[[1.45,0]],"id":50281437}],"con":true,"img":false}]}
{"op":"mcm","clk":"11540445057","pt":1719494589943,"mc":[{"id":"1.230180113","rc":[{"atb":[[1.02,10.47]],"id":50281437}],"con":true,"img":false}]}
{"op":"mcm","clk":"11540445083","pt":1719494590256,"mc":[{"id":"1.230180113","rc":[{"atb":[[1.53,0]],"id":68579508}],"con":true,"img":false}]}
{"op":"mcm","clk":"11540445091","pt":1719494590357,"mc":[{"id":"1.230180113","rc":[{"atb":[[1.02,2]],"id":68579508}],"con":true,"img":false}]}
{"op":"mcm","clk":"11540445219","pt":1719494591973,"mc":[{"id":"1.230180113","rc":[{"atb":[[1.02,0]],"id":68870841}],"con":true,"img":false}]}
{"op":"mcm","clk":"11540445227","pt":1719494592075,"mc":[{"id":"1.230180113","rc":[{"atb":[[1.77,2]],"id":68870841}],"con":true,"img":false}]}
{"op":"mcm","clk":"11540445250","pt":1719494592385,"mc":[{"id":"1.230180113","rc":[{"atb":[[1.02,0]],"id":58974183}],"con":true,"img":false}]}
{"op":"mcm","clk":"11540445257","pt":1719494592439,"mc":[{"id":"1.230180113","rc":[{"atb":[[1.85,2]],"id":58974183}],"con":true,"img":false}]}
{"op":"mcm","clk":"11540445294","pt":1719494592852,"mc":[{"id":"1.230180113","rc":[{"atb":[[1.02,8.47]],"id":50281437}],"con":true,"img":false}]}
{"op":"mcm","clk":"11540445303","pt":1719494592957,"mc":[{"id":"1.230180113","rc":[{"atb":[[1.45,2]],"id":50281437}],"con":true,"img":false}]}
{"op":"mcm","clk":"11540445345","pt":1719494593377,"mc":[{"id":"1.230180113","rc":[{"atb":[[1.02,0]],"id":68579508}],"con":true,"img":false}]}
{"op":"mcm","clk":"11540445355","pt":1719494593480,"mc":[{"id":"1.230180113","rc":[{"atb":[[1.53,2]],"id":68579508}],"con":true,"img":false}]}
{"op":"mcm","clk":"11540445391","pt":1719494593847,"mc":[{"id":"1.230180113","rc":[{"atb":[[1.08,50]],"id":58974183},{"atb":[[1.08,50]],"id":68169358},{"atb":[[1.08,50]],"id":68870841},{"atb":[[1.08,50]],"id":68579508},{"atb":[[1.08,50]],"id":50281437}],"con":true,"img":false}]}
{"op":"mcm","clk":"11540445456","pt":1719494594678,"mc":[{"id":"1.230180113","rc":[{"atb":[[1.77,0]],"id":68870841}],"con":true,"img":false}]}
{"op":"mcm","clk":"11540445463","pt":1719494594775,"mc":[{"id":"1.230180113","rc":[{"atb":[[1.02,2]],"id":68870841}],"con":true,"img":false}]}
{"op":"mcm","clk":"11540445485","pt":1719494595084,"mc":[{"id":"1.230180113","rc":[{"atb":[[1.85,0]],"id":58974183}],"con":true,"img":false}]}
{"op":"mcm","clk":"11540445492","pt":1719494595191,"mc":[{"id":"1.230180113","rc":[{"atb":[[1.02,2]],"id":58974183}],"con":true,"img":false}]}
{"op":"mcm","clk":"11540445520","pt":1719494595551,"mc":[{"id":"1.230180113","rc":[{"atb":[[1.45,0]],"id":50281437}],"con":true,"img":false}]}
{"op":"mcm","clk":"11540445526","pt":1719494595658,"mc":[{"id":"1.230180113","rc":[{"atb":[[1.02,10.47]],"id":50281437}],"con":true,"img":false}]}
{"op":"mcm","clk":"11540445564","pt":1719494596069,"mc":[{"id":"1.230180113","rc":[{"atb":[[1.75,3.75]],"id":68870841},{"atb":[[1.53,0]],"id":68579508}],"con":true,"img":false}]}
{"op":"mcm","clk":"11540445575","pt":1719494596173,"mc":[{"id":"1.230180113","rc":[{"atb":[[1.02,2]],"id":68579508}],"con":true,"img":false}]}
{"op":"mcm","clk":"11540445654","pt":1719494597056,"mc":[{"id":"1.230180113","rc":[{"atb":[[1.02,0]],"id":58974183},{"atb":[[1.43,3.25]],"id":50281437}],"con":true,"img":false}]}
{"op":"mcm","clk":"11540445666","pt":1719494597162,"mc":[{"id":"1.230180113","rc":[{"atb":[[1.85,2]],"id":58974183}],"con":true,"img":false}]}
{"op":"mcm","clk":"11540445676","pt":1719494597267,"mc":[{"id":"1.230180113","rc":[{"atb":[[1.83,3.75]],"id":58974183}],"con":true,"img":false}]}
{"op":"mcm","clk":"11540445700","pt":1719494597475,"mc":[{"id":"1.230180113","rc":[{"atb":[[1.02,8.47]],"id":50281437}],"con":true,"img":false}]}
{"op":"mcm","clk":"11540445713","pt":1719494597584,"mc":[{"id":"1.230180113","rc":[{"atb":[[1.45,2]],"id":50281437}],"con":true,"img":false}]}
{"op":"mcm","clk":"11540445721","pt":1719494597686,"mc":[{"id":"1.230180113","rc":[{"atb":[[1.83,0]],"id":58974183},{"atb":[[1.4,3.75]],"id":68579508},{"atb":[[1.43,0]],"id":50281437}],"con":true,"img":false}]}
{"op":"mcm","clk":"11540445746","pt":1719494597894,"mc":[{"id":"1.230180113","rc":[{"atb":[[1.02,0]],"id":68579508}],"con":true,"img":false}]}
{"op":"mcm","clk":"11540445762","pt":1719494597941,"mc":[{"id":"1.230180113","rc":[{"atb":[[1.53,2]],"id":68579508}],"con":true,"img":false}]}
{"op":"mcm","clk":"11540445862","pt":1719494598873,"mc":[{"id":"1.230180113","rc":[{"atb":[[1.4,0]],"id":68579508}],"con":true,"img":false}]}
{"op":"mcm","clk":"11540445916","pt":1719494599441,"mc":[{"id":"1.230180113","rc":[{"atb":[[1.85,0]],"id":58974183}],"con":true,"img":false}]}
{"op":"mcm","clk":"11540445927","pt":1719494599546,"mc":[{"id":"1.230180113","rc":[{"atb":[[1.02,2]],"id":58974183}],"con":true,"img":false}]}
{"op":"mcm","clk":"11540445955","pt":1719494599860,"mc":[{"id":"1.230180113","rc":[{"atb":[[1.45,0]],"id":50281437}],"con":true,"img":false}]}
{"op":"mcm","clk":"11540445962","pt":1719494599971,"mc":[{"id":"1.230180113","rc":[{"atb":[[1.02,10.47]],"id":50281437}],"con":true,"img":false}]}
{"op":"mcm","clk":"11540446039","pt":1719494600850,"mc":[{"id":"1.230180113","rc":[{"atb":[[1.02,0]],"id":58974183},{"spn":2.27,"spf":"NaN","id":68169358},{"spn":2.64,"spf":"NaN","id":68579508}],"con":true,"img":false}]}
{"op":"mcm","clk":"11540446050","pt":1719494600953,"mc":[{"id":"1.230180113","rc":[{"atb":[[1.85,2]],"id":58974183}],"con":true,"img":false}]}
{"op":"mcm","clk":"11540446078","pt":1719494601263,"mc":[{"id":"1.230180113","rc":[{"atb":[[1.02,8.47]],"id":50281437}],"con":true,"img":false}]}
{"op":"mcm","clk":"11540446085","pt":1719494601367,"mc":[{"id":"1.230180113","rc":[{"atb":[[1.45,2]],"id":50281437}],"con":true,"img":false}]}
{"op":"mcm","clk":"11540446099","pt":1719494601575,"mc":[{"id":"1.230180113","rc":[{"atb":[[1.53,0]],"id":68579508}],"con":true,"img":false}]}
{"op":"mcm","clk":"11540446109","pt":1719494601682,"mc":[{"id":"1.230180113","rc":[{"atb":[[1.02,2]],"id":68579508}],"con":true,"img":false}]}
{"op":"mcm","clk":"11540446201","pt":1719494602665,"mc":[{"id":"1.230180113","rc":[{"atb":[[1.85,0]],"id":58974183}],"con":true,"img":false}]}
{"op":"mcm","clk":"11540446211","pt":1719494602765,"mc":[{"id":"1.230180113","rc":[{"atb":[[1.02,2]],"id":58974183}],"con":true,"img":false}]}
{"op":"mcm","clk":"11540446266","pt":1719494603386,"mc":[{"id":"1.230180113","rc":[{"atb":[[1.45,0]],"id":50281437}],"con":true,"img":false}]}
{"op":"mcm","clk":"11540446275","pt":1719494603488,"mc":[{"id":"1.230180113","rc":[{"atb":[[1.02,10.47]],"id":50281437}],"con":true,"img":false}]}
{"op":"mcm","clk":"11540446307","pt":1719494603853,"mc":[{"id":"1.230180113","rc":[{"atb":[[1.02,0]],"id":68579508}],"con":true,"img":false}]}
{"op":"mcm","clk":"11540446314","pt":1719494603959,"mc":[{"id":"1.230180113","rc":[{"atb":[[1.53,2]],"id":68579508}],"con":true,"img":false}]}
{"op":"mcm","clk":"11540446459","pt":1719494605475,"mc":[{"id":"1.230180113","rc":[{"atb":[[1.02,0]],"id":58974183}],"con":true,"img":false}]}
{"op":"mcm","clk":"11540446468","pt":1719494605580,"mc":[{"id":"1.230180113","rc":[{"atb":[[1.85,2]],"id":58974183}],"con":true,"img":false}]}
{"op":"mcm","clk":"11540446515","pt":1719494606091,"mc":[{"id":"1.230180113","rc":[{"atb":[[1.02,8.47]],"id":50281437}],"con":true,"img":false}]}
{"op":"mcm","clk":"11540446522","pt":1719494606196,"mc":[{"id":"1.230180113","rc":[{"atb":[[1.45,2]],"id":50281437}],"con":true,"img":false}]}
{"op":"mcm","clk":"11540446568","pt":1719494606469,"mc":[{"id":"1.230180113","rc":[{"atb":[[1.53,0]],"id":68579508}],"con":true,"img":false}]}
{"op":"mcm","clk":"11540446579","pt":1719494606562,"mc":[{"id":"1.230180113","rc":[{"atb":[[1.02,2]],"id":68579508}],"con":true,"img":false}]}
{"op":"mcm","clk":"11540446674","pt":1719494607708,"mc":[{"id":"1.230180113","rc":[{"atb":[[1.85,0]],"id":58974183}],"con":true,"img":false}]}
{"op":"mcm","clk":"11540446684","pt":1719494607756,"mc":[{"id":"1.230180113","rc":[{"atb":[[1.02,2]],"id":58974183}],"con":true,"img":false}]}
{"op":"mcm","clk":"11540446707","pt":1719494608066,"mc":[{"id":"1.230180113","rc":[{"atb":[[1.45,0]],"id":50281437}],"con":true,"img":false}]}
{"op":"mcm","clk":"11540446716","pt":1719494608175,"mc":[{"id":"1.230180113","rc":[{"atb":[[1.02,10.47]],"id":50281437}],"con":true,"img":false}]}
{"op":"mcm","clk":"11540446752","pt":1719494608586,"mc":[{"id":"1.230180113","rc":[{"atb":[[1.02,0]],"id":68579508}],"con":true,"img":false}]}
{"op":"mcm","clk":"11540446764","pt":1719494608688,"mc":[{"id":"1.230180113","rc":[{"atb":[[1.53,2]],"id":68579508}],"con":true,"img":false}]}
{"op":"mcm","clk":"11540446853","pt":1719494609783,"mc":[{"id":"1.230180113","rc":[{"atb":[[1.02,0]],"id":58974183}],"con":true,"img":false}]}
{"op":"mcm","clk":"11540446861","pt":1719494609881,"mc":[{"id":"1.230180113","rc":[{"atb":[[1.85,2]],"id":58974183}],"con":true,"img":false}]}
{"op":"mcm","clk":"11540446892","pt":1719494610298,"mc":[{"id":"1.230180113","rc":[{"atb":[[1.02,8.47]],"id":50281437}],"con":true,"img":false}]}
{"op":"mcm","clk":"11540446900","pt":1719494610411,"mc":[{"id":"1.230180113","rc":[{"atb":[[1.45,2]],"id":50281437}],"con":true,"img":false}]}
{"op":"mcm","clk":"11540446928","pt":1719494610777,"mc":[{"id":"1.230180113","rc":[{"atb":[[1.53,0]],"id":68579508}],"con":true,"img":false}]}
{"op":"mcm","clk":"11540446935","pt":1719494610869,"mc":[{"id":"1.230180113","rc":[{"atb":[[1.02,2]],"id":68579508}],"con":true,"img":false}]}
{"op":"mcm","clk":"11540447008","pt":1719494611805,"mc":[{"id":"1.230180113","rc":[{"atb":[[1.85,0]],"id":58974183}],"con":true,"img":false}]}
{"op":"mcm","clk":"11540447021","pt":1719494611861,"mc":[{"id":"1.230180113","rc":[{"atb":[[1.02,2]],"id":58974183}],"con":true,"img":false}]}
{"op":"mcm","clk":"11540447049","pt":1719494612166,"mc":[{"id":"1.230180113","rc":[{"atb":[[1.45,0]],"id":50281437}],"con":true,"img":false}]}
{"op":"mcm","clk":"11540447059","pt":1719494612270,"mc":[{"id":"1.230180113","rc":[{"atb":[[1.02,10.47]],"id":50281437}],"con":true,"img":false}]}
{"op":"mcm","clk":"11540447096","pt":1719494612693,"mc":[{"id":"1.230180113","rc":[{"atb":[[1.02,0]],"id":68579508}],"con":true,"img":false}]}
{"op":"mcm","clk":"11540447106","pt":1719494612797,"mc":[{"id":"1.230180113","rc":[{"atb":[[1.53,2]],"id":68579508}],"con":true,"img":false}]}
{"op":"mcm","clk":"11540447206","pt":1719494613985,"mc":[{"id":"1.230180113","rc":[{"atb":[[1.02,0]],"id":58974183}],"con":true,"img":false}]}
{"op":"mcm","clk":"11540447213","pt":1719494614085,"mc":[{"id":"1.230180113","rc":[{"atb":[[1.85,2]],"id":58974183}],"con":true,"img":false}]}
{"op":"mcm","clk":"11540447229","pt":1719494614394,"mc":[{"id":"1.230180113","rc":[{"atb":[[1.02,8.47]],"id":50281437}],"con":true,"img":false}]}
{"op":"mcm","clk":"11540447237","pt":1719494614497,"mc":[{"id":"1.230180113","rc":[{"atb":[[1.45,2]],"id":50281437}],"con":true,"img":false}]}
{"op":"mcm","clk":"11540447254","pt":1719494614805,"mc":[{"id":"1.230180113","rc":[{"atb":[[1.53,0]],"id":68579508}],"con":true,"img":false}]}
{"op":"mcm","clk":"11540447263","pt":1719494614859,"mc":[{"id":"1.230180113","rc":[{"atb":[[1.02,2]],"id":68579508}],"con":true,"img":false}]}
{"op":"mcm","clk":"11540447334","pt":1719494615786,"mc":[{"id":"1.230180113","rc":[{"atb":[[1.85,0]],"id":58974183}],"con":true,"img":false}]}
{"op":"mcm","clk":"11540447345","pt":1719494615889,"mc":[{"id":"1.230180113","rc":[{"atb":[[1.02,2]],"id":58974183}],"con":true,"img":false}]}
{"op":"mcm","clk":"11540447383","pt":1719494616303,"mc":[{"id":"1.230180113","rc":[{"atb":[[1.45,0]],"id":50281437}],"con":true,"img":false}]}
{"op":"mcm","clk":"11540447398","pt":1719494616407,"mc":[{"id":"1.230180113","rc":[{"atb":[[1.02,10.47]],"id":50281437}],"con":true,"img":false}]}
{"op":"mcm","clk":"11540447428","pt":1719494616666,"mc":[{"id":"1.230180113","rc":[{"atb":[[1.02,0]],"id":68579508}],"con":true,"img":false}]}
{"op":"mcm","clk":"11540447438","pt":1719494616769,"mc":[{"id":"1.230180113","rc":[{"atb":[[1.53,2]],"id":68579508}],"con":true,"img":false}]}
{"op":"mcm","clk":"11540447519","pt":1719494617699,"mc":[{"id":"1.230180113","rc":[{"atb":[[1.02,0]],"id":58974183}],"con":true,"img":false}]}
{"op":"mcm","clk":"11540447524","pt":1719494617804,"mc":[{"id":"1.230180113","rc":[{"atb":[[1.85,2]],"id":58974183}],"con":true,"img":false}]}
{"op":"mcm","clk":"11540447546","pt":1719494618076,"mc":[{"id":"1.230180113","rc":[{"atb":[[1.02,8.47]],"id":50281437}],"con":true,"img":false}]}
{"op":"mcm","clk":"11540447552","pt":1719494618202,"mc":[{"id":"1.230180113","rc":[{"atb":[[1.45,2]],"id":50281437}],"con":true,"img":false}]}
{"op":"mcm","clk":"11540447614","pt":1719494618797,"mc":[{"id":"1.230180113","rc":[{"atb":[[1.53,0]],"id":68579508}],"con":true,"img":false}]}
{"op":"mcm","clk":"11540447625","pt":1719494618894,"mc":[{"id":"1.230180113","rc":[{"atb":[[1.02,2]],"id":68579508}],"con":true,"img":false}]}
{"op":"mcm","clk":"11540447725","pt":1719494619988,"mc":[{"id":"1.230180113","rc":[{"atb":[[1.85,0]],"id":58974183}],"con":true,"img":false}]}
{"op":"mcm","clk":"11540447731","pt":1719494620090,"mc":[{"id":"1.230180113","rc":[{"atb":[[1.02,2]],"id":58974183}],"con":true,"img":false}]}
{"op":"mcm","clk":"11540447753","pt":1719494620295,"mc":[{"id":"1.230180113","rc":[{"atb":[[1.45,0]],"id":50281437}],"con":true,"img":false}]}
{"op":"mcm","clk":"11540447759","pt":1719494620392,"mc":[{"id":"1.230180113","rc":[{"atb":[[1.02,10.47]],"id":50281437}],"con":true,"img":false}]}
{"op":"mcm","clk":"11540447800","pt":1719494620813,"mc":[{"id":"1.230180113","rc":[{"atb":[[1.02,0]],"id":68579508}],"con":true,"img":false}]}
{"op":"mcm","clk":"11540447816","pt":1719494620914,"mc":[{"id":"1.230180113","rc":[{"atb":[[1.53,2]],"id":68579508}],"con":true,"img":false}]}
{"op":"mcm","clk":"11540447944","pt":1719494622316,"mc":[{"id":"1.230180113","rc":[{"atb":[[1.02,0]],"id":58974183}],"con":true,"img":false}]}
{"op":"mcm","clk":"11540447954","pt":1719494622478,"mc":[{"id":"1.230180113","rc":[{"atb":[[1.85,2]],"id":58974183}],"con":true,"img":false}]}
{"op":"mcm","clk":"11540447989","pt":1719494622781,"mc":[{"id":"1.230180113","rc":[{"atb":[[1.02,8.47]],"id":50281437}],"con":true,"img":false}]}
{"op":"mcm","clk":"11540447999","pt":1719494622888,"mc":[{"id":"1.230180113","rc":[{"atb":[[1.45,2]],"id":50281437}],"con":true,"img":false}]}
{"op":"mcm","clk":"11540448030","pt":1719494623410,"mc":[{"id":"1.230180113","rc":[{"atb":[[1.53,0]],"id":68579508}],"con":true,"img":false}]}
{"op":"mcm","clk":"11540448044","pt":1719494623519,"mc":[{"id":"1.230180113","rc":[{"atb":[[1.02,2]],"id":68579508}],"con":true,"img":false}]}
{"op":"mcm","clk":"11540448130","pt":1719494624513,"mc":[{"id":"1.230180113","rc":[{"atb":[[1.85,0]],"id":58974183}],"con":true,"img":false}]}
