{"op":"mcm","clk":"11547086395","pt":1719432856330,"mc":[{"id":"1.230178175","marketDefinition":{"bspMarket":false,"turnInPlayEnabled":false,"persistenceEnabled":false,"marketBaseRate":5.0,"eventId":"33376048","eventTypeId":"4339","numberOfWinners":1,"bettingType":"ODDS","marketType":"FORECAST","marketTime":"2024-06-27T16:18:00.000Z","suspendTime":"2024-06-27T16:18:00.000Z","bspReconciled":false,"complete":true,"inPlay":false,"crossMatching":false,"runnersVoidable":false,"numberOfActiveRunners":30,"betDelay":0,"status":"OPEN","runners":[{"status":"ACTIVE","sortPriority":1,"id":52385882,"name":"1 - 2"},{"status":"ACTIVE","sortPriority":2,"id":52385883,"name":"1 - 3"},{"status":"ACTIVE","sortPriority":3,"id":52385884,"name":"1 - 4"},{"status":"ACTIVE","sortPriority":4,"id":52385885,"name":"1 - 5"},{"status":"ACTIVE","sortPriority":5,"id":52385886,"name":"1 - 6"},{"status":"ACTIVE","sortPriority":6,"id":52385889,"name":"2 - 1"},{"status":"ACTIVE","sortPriority":7,"id":52385890,"name":"2 - 3"},{"status":"ACTIVE","sortPriority":8,"id":52385891,"name":"2 - 4"},{"status":"ACTIVE","sortPriority":9,"id":52385892,"name":"2 - 5"},{"status":"ACTIVE","sortPriority":10,"id":52385893,"name":"2 - 6"},{"status":"ACTIVE","sortPriority":11,"id":52385896,"name":"3 - 1"},{"status":"ACTIVE","sortPriority":12,"id":52385897,"name":"3 - 2"},{"status":"ACTIVE","sortPriority":13,"id":52385898,"name":"3 - 4"},{"status":"ACTIVE","sortPriority":14,"id":52385899,"name":"3 - 5"},{"status":"ACTIVE","sortPriority":15,"id":52385900,"name":"3 - 6"},{"status":"ACTIVE","sortPriority":16,"id":52385903,"name":"4 - 1"},{"status":"ACTIVE","sortPriority":17,"id":52385904,"name":"4 - 2"},{"status":"ACTIVE","sortPriority":18,"id":52385905,"name":"4 - 3"},{"status":"ACTIVE","sortPriority":19,"id":52385906,"name":"4 - 5"},{"status":"ACTIVE","sortPriority":20,"id":52385907,"name":"4 - 6"},{"status":"ACTIVE","sortPriority":21,"id":52385910,"name":"5 - 1"},{"status":"ACTIVE","sortPriority":22,"id":52385911,"name":"5 - 2"},{"status":"ACTIVE","sortPriority":23,"id":52385912,"name":"5 - 3"},{"status":"ACTIVE","sortPriority":24,"id":52385913,"name":"5 - 4"},{"status":"ACTIVE","sortPriority":25,"id":52385914,"name":"5 - 6"},{"status":"ACTIVE","sortPriority":26,"id":52385917,"name":"6 - 1"},{"status":"ACTIVE","sortPriority":27,"id":52385918,"name":"6 - 2"},{"status":"ACTIVE","sortPriority":28,"id":52385919,"name":"6 - 3"},{"status":"ACTIVE","sortPriority":29,"id":52385920,"name":"6 - 4"},{"status":"ACTIVE","sortPriority":30,"id":52385921,"name":"6 - 5"}],"regulators":["MR_INT"],"venue":"Perry Barr","countryCode":"GB","discountAllowed":false,"timezone":"Europe/London","openDate":"2024-06-27T13:29:00.000Z","version":5994794164,"name":"Forecast","eventName":"Perry Barr (F/C) 27th Jun"},"rc":[],"con":true,"img":false}]}
{"op":"mcm","clk":"11547086606","pt":1719432859283,"mc":[{"id":"1.230178175","marketDefinition":{"bspMarket":false,"turnInPlayEnabled":false,"persistenceEnabled":false,"marketBaseRate":5.0,"eventId":"33376048","eventTypeId":"4339","numberOfWinners":1,"bettingType":"ODDS","marketType":"FORECAST","marketTime":"2024-06-27T16:18:00.000Z","suspendTime":"2024-06-27T16:18:00.000Z","bspReconciled":false,"complete":true,"inPlay":false,"crossMatching":false,"runnersVoidable":false,"numberOfActiveRunners":30,"betDelay":0,"status":"OPEN","runners":[{"status":"ACTIVE","sortPriority":1,"id":52385882,"name":"1 - 2"},{"status":"ACTIVE","sortPriority":2,"id":52385883,"name":"1 - 3"},{"status":"ACTIVE","sortPriority":3,"id":52385884,"name":"1 - 4"},{"status":"ACTIVE","sortPriority":4,"id":52385885,"name":"1 - 5"},{"status":"ACTIVE","sortPriority":5,"id":52385886,"name":"1 - 6"},{"status":"ACTIVE","sortPriority":6,"id":52385889,"name":"2 - 1"},{"status":"ACTIVE","sortPriority":7,"id":52385890,"name":"2 - 3"},{"status":"ACTIVE","sortPriority":8,"id":52385891,"name":"2 - 4"},{"status":"ACTIVE","sortPriority":9,"id":52385892,"name":"2 - 5"},{"status":"ACTIVE","sortPriority":10,"id":52385893,"name":"2 - 6"},{"status":"ACTIVE","sortPriority":11,"id":52385896,"name":"3 - 1"},{"status":"ACTIVE","sortPriority":12,"id":52385897,"name":"3 - 2"},{"status":"ACTIVE","sortPriority":13,"id":52385898,"name":"3 - 4"},{"status":"ACTIVE","sortPriority":14,"id":52385899,"name":"3 - 5"},{"status":"ACTIVE","sortPriority":15,"id":52385900,"name":"3 - 6"},{"status":"ACTIVE","sortPriority":16,"id":52385903,"name":"4 - 1"},{"status":"ACTIVE","sortPriority":17,"id":52385904,"name":"4 - 2"},{"status":"ACTIVE","sortPriority":18,"id":52385905,"name":"4 - 3"},{"status":"ACTIVE","sortPriority":19,"id":52385906,"name":"4 - 5"},{"status":"ACTIVE","sortPriority":20,"id":52385907,"name":"4 - 6"},{"status":"ACTIVE","sortPriority":21,"id":52385910,"name":"5 - 1"},{"status":"ACTIVE","sortPriority":22,"id":52385911,"name":"5 - 2"},{"status":"ACTIVE","sortPriority":23,"id":52385912,"name":"5 - 3"},{"status":"ACTIVE","sortPriority":24,"id":52385913,"name":"5 - 4"},{"status":"ACTIVE","sortPriority":25,"id":52385914,"name":"5 - 6"},{"status":"ACTIVE","sortPriority":26,"id":52385917,"name":"6 - 1"},{"status":"ACTIVE","sortPriority":27,"id":52385918,"name":"6 - 2"},{"status":"ACTIVE","sortPriority":28,"id":52385919,"name":"6 - 3"},{"status":"ACTIVE","sortPriority":29,"id":52385920,"name":"6 - 4"},{"status":"ACTIVE","sortPriority":30,"id":52385921,"name":"6 - 5"}],"regulators":["MR_INT"],"venue":"Perry Barr","countryCode":"GB","discountAllowed":true,"timezone":"Europe/London","openDate":"2024-06-27T13:29:00.000Z","version":5994794164,"name":"Forecast","eventName":"Perry Barr (F/C) 27th Jun"},"rc":[],"con":true,"img":false}]}
{"op":"mcm","clk":"11547344171","pt":1719439054609,"mc":[{"id":"1.230178175","rc":[{"atb":[[1.03,5.93]],"id":52385910},{"atb":[[1.01,17.8]],"id":52385912},{"atb":[[1.02,8.9]],"id":52385906},{"atb":[[1.03,5.93]],"id":52385918},{"atb":[[1.03,5.93]],"id":52385920},{"atb":[[1.02,8.9]],"id":52385889},{"atb":[[1.03,5.93]],"id":52385914},{"atb":[[1.02,8.9]],"id":52385883},{"atb":[[1.01,17.8]],"id":52385885},{"atb":[[1.03,5.93]],"id":52385896},{"atb":[[1.01,17.8]],"id":52385890},{"atb":[[1.01,17.8]],"id":52385892},{"atb":[[1.02,8.9]],"id":52385904},{"atb":[[1.02,8.9]],"id":52385898},{"atb":[[1.03,5.93]],"id":52385900},{"atb":[[1.01,17.8]],"id":52385911},{"atb":[[1.01,17.8]],"id":52385913},{"atb":[[1.03,5.93]],"id":52385907},{"atb":[[1.02,8.9]],"id":52385886},{"atb":[[1.01,17.8]],"id":52385919},{"atb":[[1.03,5.93]],"id":52385921},{"atb":[[1.01,17.8]],"id":52385882},{"atb":[[1.01,17.8]],"id":52385884},{"atb":[[1.03,5.93]],"id":52385917},{"atb":[[1.01,17.8]],"id":52385897},{"atb":[[1.01,17.8]],"id":52385891},{"atb":[[1.01,17.8]],"id":52385893},{"atb":[[1.01,17.8]],"id":52385903},{"atb":[[1.02,8.9]],"id":52385905},{"atb":[[1.03,5.93]],"id":52385899}],"con":true,"img":false}]}
{"op":"mcm","clk":"11547371014","pt":1719439682592,"mc":[{"id":"1.230178175","marketDefinition":{"bspMarket":false,"turnInPlayEnabled":false,"persistenceEnabled":false,"marketBaseRate":5.0,"eventId":"33376048","eventTypeId":"4339","numberOfWinners":1,"bettingType":"ODDS","marketType":"FORECAST","marketTime":"2024-06-27T16:18:00.000Z","suspendTime":"2024-06-27T16:18:00.000Z","bspReconciled":false,"complete":true,"inPlay":false,"crossMatching":false,"runnersVoidable":false,"numberOfActiveRunners":30,"betDelay":0,"status":"OPEN","runners":[{"status":"ACTIVE","sortPriority":1,"id":52385882,"name":"1 - 2"},{"status":"ACTIVE","sortPriority":2,"id":52385883,"name":"1 - 3"},{"status":"ACTIVE","sortPriority":3,"id":52385884,"name":"1 - 4"},{"status":"ACTIVE","sortPriority":4,"id":52385885,"name":"1 - 5"},{"status":"ACTIVE","sortPriority":5,"id":52385886,"name":"1 - 6"},{"status":"ACTIVE","sortPriority":6,"id":52385889,"name":"2 - 1"},{"status":"ACTIVE","sortPriority":7,"id":52385890,"name":"2 - 3"},{"status":"ACTIVE","sortPriority":8,"id":52385891,"name":"2 - 4"},{"status":"ACTIVE","sortPriority":9,"id":52385892,"name":"2 - 5"},{"status":"ACTIVE","sortPriority":10,"id":52385893,"name":"2 - 6"},{"status":"ACTIVE","sortPriority":11,"id":52385896,"name":"3 - 1"},{"status":"ACTIVE","sortPriority":12,"id":52385897,"name":"3 - 2"},{"status":"ACTIVE","sortPriority":13,"id":52385898,"name":"3 - 4"},{"status":"ACTIVE","sortPriority":14,"id":52385899,"name":"3 - 5"},{"status":"ACTIVE","sortPriority":15,"id":52385900,"name":"3 - 6"},{"status":"ACTIVE","sortPriority":16,"id":52385903,"name":"4 - 1"},{"status":"ACTIVE","sortPriority":17,"id":52385904,"name":"4 - 2"},{"status":"ACTIVE","sortPriority":18,"id":52385905,"name":"4 - 3"},{"status":"ACTIVE","sortPriority":19,"id":52385906,"name":"4 - 5"},{"status":"ACTIVE","sortPriority":20,"id":52385907,"name":"4 - 6"},{"status":"ACTIVE","sortPriority":21,"id":52385910,"name":"5 - 1"},{"status":"ACTIVE","sortPriority":22,"id":52385911,"name":"5 - 2"},{"status":"ACTIVE","sortPriority":23,"id":52385912,"name":"5 - 3"},{"status":"ACTIVE","sortPriority":24,"id":52385913,"name":"5 - 4"},{"status":"ACTIVE","sortPriority":25,"id":52385914,"name":"5 - 6"},{"status":"ACTIVE","sortPriority":26,"id":52385917,"name":"6 - 1"},{"status":"ACTIVE","sortPriority":27,"id":52385918,"name":"6 - 2"},{"status":"ACTIVE","sortPriority":28,"id":52385919,"name":"6 - 3"},{"status":"ACTIVE","sortPriority":29,"id":52385920,"name":"6 - 4"},{"status":"ACTIVE","sortPriority":30,"id":52385921,"name":"6 - 5"}],"regulators":["MR_INT"],"venue":"Perry Barr","countryCode":"GB","discountAllowed":true,"timezone":"Europe/London","openDate":"2024-06-27T13:29:00.000Z","version":5994794164,"name":"Forecast","eventName":"Perry Barr (F/C) 27th Jun"},"rc":[{"atb":[[1.03,5.93]],"id":52385910},{"atb":[[1.01,17.8]],"id":52385912},{"atb":[[1.02,8.9]],"id":52385906},{"atb":[[1.03,5.93]],"id":52385918},{"atb":[[1.03,5.93]],"id":52385920},{"atb":[[1.02,8.9]],"id":52385889},{"atb":[[1.03,5.93]],"id":52385914},{"atb":[[1.02,8.9]],"id":52385883},{"atb":[[1.01,17.8]],"id":52385885},{"atb":[[1.03,5.93]],"id":52385896},{"atb":[[1.01,17.8]],"id":52385890},{"atb":[[1.01,17.8]],"id":52385892},{"atb":[[1.02,8.9]],"id":52385904},{"atb":[[1.02,8.9]],"id":52385898},{"atb":[[1.03,5.93]],"id":52385900},{"atb":[[1.01,17.8]],"id":52385911},{"atb":[[1.01,17.8]],"id":52385913},{"atb":[[1.03,5.93]],"id":52385907},{"atb":[[1.02,8.9]],"id":52385886},{"atb":[[1.01,17.8]],"id":52385919},{"atb":[[1.03,5.93]],"id":52385921},{"atb":[[1.01,17.8]],"id":52385882},{"atb":[[1.01,17.8]],"id":52385884},{"atb":[[1.03,5.93]],"id":52385917},{"atb":[[1.01,17.8]],"id":52385897},{"atb":[[1.01,17.8]],"id":52385891},{"atb":[[1.01,17.8]],"id":52385893},{"atb":[[1.01,17.8]],"id":52385903},{"atb":[[1.02,8.9]],"id":52385905},{"atb":[[1.03,5.93]],"id":52385899}],"con":true,"img":true}]}
{"op":"mcm","clk":"11547659682","pt":1719445082619,"mc":[{"id":"1.230178175","marketDefinition":{"bspMarket":false,"turnInPlayEnabled":false,"persistenceEnabled":false,"marketBaseRate":5.0,"eventId":"33376048","eventTypeId":"4339","numberOfWinners":1,"bettingType":"ODDS","marketType":"FORECAST","marketTime":"2024-06-27T16:18:00.000Z","suspendTime":"2024-06-27T16:18:00.000Z","bspReconciled":false,"complete":true,"inPlay":false,"crossMatching":false,"runnersVoidable":false,"numberOfActiveRunners":30,"betDelay":0,"status":"OPEN","runners":[{"status":"ACTIVE","sortPriority":1,"id":52385882,"name":"1 - 2"},{"status":"ACTIVE","sortPriority":2,"id":52385883,"name":"1 - 3"},{"status":"ACTIVE","sortPriority":3,"id":52385884,"name":"1 - 4"},{"status":"ACTIVE","sortPriority":4,"id":52385885,"name":"1 - 5"},{"status":"ACTIVE","sortPriority":5,"id":52385886,"name":"1 - 6"},{"status":"ACTIVE","sortPriority":6,"id":52385889,"name":"2 - 1"},{"status":"ACTIVE","sortPriority":7,"id":52385890,"name":"2 - 3"},{"status":"ACTIVE","sortPriority":8,"id":52385891,"name":"2 - 4"},{"status":"ACTIVE","sortPriority":9,"id":52385892,"name":"2 - 5"},{"status":"ACTIVE","sortPriority":10,"id":52385893,"name":"2 - 6"},{"status":"ACTIVE","sortPriority":11,"id":52385896,"name":"3 - 1"},{"status":"ACTIVE","sortPriority":12,"id":52385897,"name":"3 - 2"},{"status":"ACTIVE","sortPriority":13,"id":52385898,"name":"3 - 4"},{"status":"ACTIVE","sortPriority":14,"id":52385899,"name":"3 - 5"},{"status":"ACTIVE","sortPriority":15,"id":52385900,"name":"3 - 6"},{"status":"ACTIVE","sortPriority":16,"id":52385903,"name":"4 - 1"},{"status":"ACTIVE","sortPriority":17,"id":52385904,"name":"4 - 2"},{"status":"ACTIVE","sortPriority":18,"id":52385905,"name":"4 - 3"},{"status":"ACTIVE","sortPriority":19,"id":52385906,"name":"4 - 5"},{"status":"ACTIVE","sortPriority":20,"id":52385907,"name":"4 - 6"},{"status":"ACTIVE","sortPriority":21,"id":52385910,"name":"5 - 1"},{"status":"ACTIVE","sortPriority":22,"id":52385911,"name":"5 - 2"},{"status":"ACTIVE","sortPriority":23,"id":52385912,"name":"5 - 3"},{"status":"ACTIVE","sortPriority":24,"id":52385913,"name":"5 - 4"},{"status":"ACTIVE","sortPriority":25,"id":52385914,"name":"5 - 6"},{"status":"ACTIVE","sortPriority":26,"id":52385917,"name":"6 - 1"},{"status":"ACTIVE","sortPriority":27,"id":52385918,"name":"6 - 2"},{"status":"ACTIVE","sortPriority":28,"id":52385919,"name":"6 - 3"},{"status":"ACTIVE","sortPriority":29,"id":52385920,"name":"6 - 4"},{"status":"ACTIVE","sortPriority":30,"id":52385921,"name":"6 - 5"}],"regulators":["MR_INT"],"venue":"Perry Barr","countryCode":"GB","discountAllowed":true,"timezone":"Europe/London","openDate":"2024-06-27T13:29:00.000Z","version":5994794164,"name":"Forecast","eventName":"Perry Barr (F/C) 27th Jun"},"rc":[{"atb":[[1.03,5.93]],"id":52385910},{"atb":[[1.01,17.8]],"id":52385912},{"atb":[[1.02,8.9]],"id":52385906},{"atb":[[1.03,5.93]],"id":52385918},{"atb":[[1.03,5.93]],"id":52385920},{"atb":[[1.02,8.9]],"id":52385889},{"atb":[[1.03,5.93]],"id":52385914},{"atb":[[1.02,8.9]],"id":52385883},{"atb":[[1.01,17.8]],"id":52385885},{"atb":[[1.03,5.93]],"id":52385896},{"atb":[[1.01,17.8]],"id":52385890},{"atb":[[1.01,17.8]],"id":52385892},{"atb":[[1.02,8.9]],"id":52385904},{"atb":[[1.02,8.9]],"id":52385898},{"atb":[[1.03,5.93]],"id":52385900},{"atb":[[1.01,17.8]],"id":52385911},{"atb":[[1.01,17.8]],"id":52385913},{"atb":[[1.03,5.93]],"id":52385907},{"atb":[[1.02,8.9]],"id":52385886},{"atb":[[1.01,17.8]],"id":52385919},{"atb":[[1.03,5.93]],"id":52385921},{"atb":[[1.01,17.8]],"id":52385882},{"atb":[[1.01,17.8]],"id":52385884},{"atb":[[1.03,5.93]],"id":52385917},{"atb":[[1.01,17.8]],"id":52385897},{"atb":[[1.01,17.8]],"id":52385891},{"atb":[[1.01,17.8]],"id":52385893},{"atb":[[1.01,17.8]],"id":52385903},{"atb":[[1.02,8.9]],"id":52385905},{"atb":[[1.03,5.93]],"id":52385899}],"con":true,"img":true}]}
{"op":"mcm","clk":"11548031726","pt":1719450482634,"mc":[{"id":"1.230178175","marketDefinition":{"bspMarket":false,"turnInPlayEnabled":false,"persistenceEnabled":false,"marketBaseRate":5.0,"eventId":"33376048","eventTypeId":"4339","numberOfWinners":1,"bettingType":"ODDS","marketType":"FORECAST","marketTime":"2024-06-27T16:18:00.000Z","suspendTime":"2024-06-27T16:18:00.000Z","bspReconciled":false,"complete":true,"inPlay":false,"crossMatching":false,"runnersVoidable":false,"numberOfActiveRunners":30,"betDelay":0,"status":"OPEN","runners":[{"status":"ACTIVE","sortPriority":1,"id":52385882,"name":"1 - 2"},{"status":"ACTIVE","sortPriority":2,"id":52385883,"name":"1 - 3"},{"status":"ACTIVE","sortPriority":3,"id":52385884,"name":"1 - 4"},{"status":"ACTIVE","sortPriority":4,"id":52385885,"name":"1 - 5"},{"status":"ACTIVE","sortPriority":5,"id":52385886,"name":"1 - 6"},{"status":"ACTIVE","sortPriority":6,"id":52385889,"name":"2 - 1"},{"status":"ACTIVE","sortPriority":7,"id":52385890,"name":"2 - 3"},{"status":"ACTIVE","sortPriority":8,"id":52385891,"name":"2 - 4"},{"status":"ACTIVE","sortPriority":9,"id":52385892,"name":"2 - 5"},{"status":"ACTIVE","sortPriority":10,"id":52385893,"name":"2 - 6"},{"status":"ACTIVE","sortPriority":11,"id":52385896,"name":"3 - 1"},{"status":"ACTIVE","sortPriority":12,"id":52385897,"name":"3 - 2"},{"status":"ACTIVE","sortPriority":13,"id":52385898,"name":"3 - 4"},{"status":"ACTIVE","sortPriority":14,"id":52385899,"name":"3 - 5"},{"status":"ACTIVE","sortPriority":15,"id":52385900,"name":"3 - 6"},{"status":"ACTIVE","sortPriority":16,"id":52385903,"name":"4 - 1"},{"status":"ACTIVE","sortPriority":17,"id":52385904,"name":"4 - 2"},{"status":"ACTIVE","sortPriority":18,"id":52385905,"name":"4 - 3"},{"status":"ACTIVE","sortPriority":19,"id":52385906,"name":"4 - 5"},{"status":"ACTIVE","sortPriority":20,"id":52385907,"name":"4 - 6"},{"status":"ACTIVE","sortPriority":21,"id":52385910,"name":"5 - 1"},{"status":"ACTIVE","sortPriority":22,"id":52385911,"name":"5 - 2"},{"status":"ACTIVE","sortPriority":23,"id":52385912,"name":"5 - 3"},{"status":"ACTIVE","sortPriority":24,"id":52385913,"name":"5 - 4"},{"status":"ACTIVE","sortPriority":25,"id":52385914,"name":"5 - 6"},{"status":"ACTIVE","sortPriority":26,"id":52385917,"name":"6 - 1"},{"status":"ACTIVE","sortPriority":27,"id":52385918,"name":"6 - 2"},{"status":"ACTIVE","sortPriority":28,"id":52385919,"name":"6 - 3"},{"status":"ACTIVE","sortPriority":29,"id":52385920,"name":"6 - 4"},{"status":"ACTIVE","sortPriority":30,"id":52385921,"name":"6 - 5"}],"regulators":["MR_INT"],"venue":"Perry Barr","countryCode":"GB","discountAllowed":true,"timezone":"Europe/London","openDate":"2024-06-27T13:29:00.000Z","version":5994794164,"name":"Forecast","eventName":"Perry Barr (F/C) 27th Jun"},"rc":[{"atb":[[1.03,5.93]],"id":52385910},{"atb":[[1.01,17.8]],"id":52385912},{"atb":[[1.02,8.9]],"id":52385906},{"atb":[[1.03,5.93]],"id":52385918},{"atb":[[1.03,5.93]],"id":52385920},{"atb":[[1.02,8.9]],"id":52385889},{"atb":[[1.03,5.93]],"id":52385914},{"atb":[[1.02,8.9]],"id":52385883},{"atb":[[1.01,17.8]],"id":52385885},{"atb":[[1.03,5.93]],"id":52385896},{"atb":[[1.01,17.8]],"id":52385890},{"atb":[[1.01,17.8]],"id":52385892},{"atb":[[1.02,8.9]],"id":52385904},{"atb":[[1.02,8.9]],"id":52385898},{"atb":[[1.03,5.93]],"id":52385900},{"atb":[[1.01,17.8]],"id":52385911},{"atb":[[1.01,17.8]],"id":52385913},{"atb":[[1.03,5.93]],"id":52385907},{"atb":[[1.02,8.9]],"id":52385886},{"atb":[[1.01,17.8]],"id":52385919},{"atb":[[1.03,5.93]],"id":52385921},{"atb":[[1.01,17.8]],"id":52385882},{"atb":[[1.01,17.8]],"id":52385884},{"atb":[[1.03,5.93]],"id":52385917},{"atb":[[1.01,17.8]],"id":52385897},{"atb":[[1.01,17.8]],"id":52385891},{"atb":[[1.01,17.8]],"id":52385893},{"atb":[[1.01,17.8]],"id":52385903},{"atb":[[1.02,8.9]],"id":52385905},{"atb":[[1.03,5.93]],"id":52385899}],"con":true,"img":true}]}
{"op":"mcm","clk":"11548270790","pt":1719455882654,"mc":[{"id":"1.230178175","marketDefinition":{"bspMarket":false,"turnInPlayEnabled":false,"persistenceEnabled":false,"marketBaseRate":5.0,"eventId":"33376048","eventTypeId":"4339","numberOfWinners":1,"bettingType":"ODDS","marketType":"FORECAST","marketTime":"2024-06-27T16:18:00.000Z","suspendTime":"2024-06-27T16:18:00.000Z","bspReconciled":false,"complete":true,"inPlay":false,"crossMatching":false,"runnersVoidable":false,"numberOfActiveRunners":30,"betDelay":0,"status":"OPEN","runners":[{"status":"ACTIVE","sortPriority":1,"id":52385882,"name":"1 - 2"},{"status":"ACTIVE","sortPriority":2,"id":52385883,"name":"1 - 3"},{"status":"ACTIVE","sortPriority":3,"id":52385884,"name":"1 - 4"},{"status":"ACTIVE","sortPriority":4,"id":52385885,"name":"1 - 5"},{"status":"ACTIVE","sortPriority":5,"id":52385886,"name":"1 - 6"},{"status":"ACTIVE","sortPriority":6,"id":52385889,"name":"2 - 1"},{"status":"ACTIVE","sortPriority":7,"id":52385890,"name":"2 - 3"},{"status":"ACTIVE","sortPriority":8,"id":52385891,"name":"2 - 4"},{"status":"ACTIVE","sortPriority":9,"id":52385892,"name":"2 - 5"},{"status":"ACTIVE","sortPriority":10,"id":52385893,"name":"2 - 6"},{"status":"ACTIVE","sortPriority":11,"id":52385896,"name":"3 - 1"},{"status":"ACTIVE","sortPriority":12,"id":52385897,"name":"3 - 2"},{"status":"ACTIVE","sortPriority":13,"id":52385898,"name":"3 - 4"},{"status":"ACTIVE","sortPriority":14,"id":52385899,"name":"3 - 5"},{"status":"ACTIVE","sortPriority":15,"id":52385900,"name":"3 - 6"},{"status":"ACTIVE","sortPriority":16,"id":52385903,"name":"4 - 1"},{"status":"ACTIVE","sortPriority":17,"id":52385904,"name":"4 - 2"},{"status":"ACTIVE","sortPriority":18,"id":52385905,"name":"4 - 3"},{"status":"ACTIVE","sortPriority":19,"id":52385906,"name":"4 - 5"},{"status":"ACTIVE","sortPriority":20,"id":52385907,"name":"4 - 6"},{"status":"ACTIVE","sortPriority":21,"id":52385910,"name":"5 - 1"},{"status":"ACTIVE","sortPriority":22,"id":52385911,"name":"5 - 2"},{"status":"ACTIVE","sortPriority":23,"id":52385912,"name":"5 - 3"},{"status":"ACTIVE","sortPriority":24,"id":52385913,"name":"5 - 4"},{"status":"ACTIVE","sortPriority":25,"id":52385914,"name":"5 - 6"},{"status":"ACTIVE","sortPriority":26,"id":52385917,"name":"6 - 1"},{"status":"ACTIVE","sortPriority":27,"id":52385918,"name":"6 - 2"},{"status":"ACTIVE","sortPriority":28,"id":52385919,"name":"6 - 3"},{"status":"ACTIVE","sortPriority":29,"id":52385920,"name":"6 - 4"},{"status":"ACTIVE","sortPriority":30,"id":52385921,"name":"6 - 5"}],"regulators":["MR_INT"],"venue":"Perry Barr","countryCode":"GB","discountAllowed":true,"timezone":"Europe/London","openDate":"2024-06-27T13:29:00.000Z","version":5994794164,"name":"Forecast","eventName":"Perry Barr (F/C) 27th Jun"},"rc":[{"atb":[[1.03,5.93]],"id":52385910},{"atb":[[1.01,17.8]],"id":52385912},{"atb":[[1.02,8.9]],"id":52385906},{"atb":[[1.03,5.93]],"id":52385918},{"atb":[[1.03,5.93]],"id":52385920},{"atb":[[1.02,8.9]],"id":52385889},{"atb":[[1.03,5.93]],"id":52385914},{"atb":[[1.02,8.9]],"id":52385883},{"atb":[[1.01,17.8]],"id":52385885},{"atb":[[1.03,5.93]],"id":52385896},{"atb":[[1.01,17.8]],"id":52385890},{"atb":[[1.01,17.8]],"id":52385892},{"atb":[[1.02,8.9]],"id":52385904},{"atb":[[1.02,8.9]],"id":52385898},{"atb":[[1.03,5.93]],"id":52385900},{"atb":[[1.01,17.8]],"id":52385911},{"atb":[[1.01,17.8]],"id":52385913},{"atb":[[1.03,5.93]],"id":52385907},{"atb":[[1.02,8.9]],"id":52385886},{"atb":[[1.01,17.8]],"id":52385919},{"atb":[[1.03,5.93]],"id":52385921},{"atb":[[1.01,17.8]],"id":52385882},{"atb":[[1.01,17.8]],"id":52385884},{"atb":[[1.03,5.93]],"id":52385917},{"atb":[[1.01,17.8]],"id":52385897},{"atb":[[1.01,17.8]],"id":52385891},{"atb":[[1.01,17.8]],"id":52385893},{"atb":[[1.01,17.8]],"id":52385903},{"atb":[[1.02,8.9]],"id":52385905},{"atb":[[1.03,5.93]],"id":52385899}],"con":true,"img":true}]}
{"op":"mcm","clk":"11548413938","pt":1719460895032,"mc":[{"id":"1.230178175","rc":[{"atb":[[1.03,5.93],[1.16,100]],"id":52385910},{"atb":[[1.01,17.8],[1.16,100]],"id":52385912},{"atb":[[1.16,100],[1.02,8.9]],"id":52385906},{"atb":[[1.03,5.93],[1.16,100]],"id":52385918},{"atb":[[1.03,5.93],[1.16,100]],"id":52385920},{"atb":[[1.16,100],[1.02,8.9]],"id":52385889},{"atb":[[1.03,5.93],[1.16,100]],"id":52385914},{"atb":[[1.16,100],[1.02,8.9]],"id":52385883},{"atb":[[1.01,17.8],[1.16,100]],"id":52385885},{"atb":[[1.03,5.93],[1.16,100]],"id":52385896},{"atb":[[1.01,17.8],[1.16,100]],"id":52385890},{"atb":[[1.01,17.8],[1.16,100]],"id":52385892},{"atb":[[1.16,100],[1.02,8.9]],"id":52385904},{"atb":[[1.16,100],[1.02,8.9]],"id":52385898},{"atb":[[1.03,5.93],[1.16,100]],"id":52385900},{"atb":[[1.01,17.8],[1.16,100]],"id":52385911},{"atb":[[1.01,17.8],[1.16,100]],"id":52385913},{"atb":[[1.03,5.93],[1.16,100]],"id":52385907},{"atb":[[1.16,100],[1.02,8.9]],"id":52385886},{"atb":[[1.01,17.8],[1.16,100]],"id":52385919},{"atb":[[1.03,5.93],[1.16,100]],"id":52385921},{"atb":[[1.01,17.8],[1.16,100]],"id":52385882},{"atb":[[1.01,17.8],[1.16,100]],"id":52385884},{"atb":[[1.03,5.93],[1.16,100]],"id":52385917},{"atb":[[1.01,17.8],[1.16,100]],"id":52385897},{"atb":[[1.01,17.8],[1.16,100]],"id":52385891},{"atb":[[1.01,17.8],[1.16,100]],"id":52385893},{"atb":[[1.01,17.8],[1.16,100]],"id":52385903},{"atb":[[1.16,100],[1.02,8.9]],"id":52385905},{"atb":[[1.03,5.93],[1.16,100]],"id":52385899}],"con":true,"img":false}]}
{"op":"mcm","clk":"11548535726","pt":1719466682820,"mc":[{"id":"1.230178175","marketDefinition":{"bspMarket":false,"turnInPlayEnabled":false,"persistenceEnabled":false,"marketBaseRate":5.0,"eventId":"33376048","eventTypeId":"4339","numberOfWinners":1,"bettingType":"ODDS","marketType":"FORECAST","marketTime":"2024-06-27T16:18:00.000Z","suspendTime":"2024-06-27T16:18:00.000Z","bspReconciled":false,"complete":true,"inPlay":false,"crossMatching":false,"runnersVoidable":false,"numberOfActiveRunners":30,"betDelay":0,"status":"OPEN","runners":[{"status":"ACTIVE","sortPriority":1,"id":52385882,"name":"1 - 2"},{"status":"ACTIVE","sortPriority":2,"id":52385883,"name":"1 - 3"},{"status":"ACTIVE","sortPriority":3,"id":52385884,"name":"1 - 4"},{"status":"ACTIVE","sortPriority":4,"id":52385885,"name":"1 - 5"},{"status":"ACTIVE","sortPriority":5,"id":52385886,"name":"1 - 6"},{"status":"ACTIVE","sortPriority":6,"id":52385889,"name":"2 - 1"},{"status":"ACTIVE","sortPriority":7,"id":52385890,"name":"2 - 3"},{"status":"ACTIVE","sortPriority":8,"id":52385891,"name":"2 - 4"},{"status":"ACTIVE","sortPriority":9,"id":52385892,"name":"2 - 5"},{"status":"ACTIVE","sortPriority":10,"id":52385893,"name":"2 - 6"},{"status":"ACTIVE","sortPriority":11,"id":52385896,"name":"3 - 1"},{"status":"ACTIVE","sortPriority":12,"id":52385897,"name":"3 - 2"},{"status":"ACTIVE","sortPriority":13,"id":52385898,"name":"3 - 4"},{"status":"ACTIVE","sortPriority":14,"id":52385899,"name":"3 - 5"},{"status":"ACTIVE","sortPriority":15,"id":52385900,"name":"3 - 6"},{"status":"ACTIVE","sortPriority":16,"id":52385903,"name":"4 - 1"},{"status":"ACTIVE","sortPriority":17,"id":52385904,"name":"4 - 2"},{"status":"ACTIVE","sortPriority":18,"id":52385905,"name":"4 - 3"},{"status":"ACTIVE","sortPriority":19,"id":52385906,"name":"4 - 5"},{"status":"ACTIVE","sortPriority":20,"id":52385907,"name":"4 - 6"},{"status":"ACTIVE","sortPriority":21,"id":52385910,"name":"5 - 1"},{"status":"ACTIVE","sortPriority":22,"id":52385911,"name":"5 - 2"},{"status":"ACTIVE","sortPriority":23,"id":52385912,"name":"5 - 3"},{"status":"ACTIVE","sortPriority":24,"id":52385913,"name":"5 - 4"},{"status":"ACTIVE","sortPriority":25,"id":52385914,"name":"5 - 6"},{"status":"ACTIVE","sortPriority":26,"id":52385917,"name":"6 - 1"},{"status":"ACTIVE","sortPriority":27,"id":52385918,"name":"6 - 2"},{"status":"ACTIVE","sortPriority":28,"id":52385919,"name":"6 - 3"},{"status":"ACTIVE","sortPriority":29,"id":52385920,"name":"6 - 4"},{"status":"ACTIVE","sortPriority":30,"id":52385921,"name":"6 - 5"}],"regulators":["MR_INT"],"venue":"Perry Barr","countryCode":"GB","discountAllowed":true,"timezone":"Europe/London","openDate":"2024-06-27T13:29:00.000Z","version":5994794164,"name":"Forecast","eventName":"Perry Barr (F/C) 27th Jun"},"rc":[{"atb":[[1.16,100],[1.03,5.93]],"id":52385910},{"atb":[[1.01,17.8],[1.16,100]],"id":52385912},{"atb":[[1.16,100],[1.02,8.9]],"id":52385906},{"atb":[[1.16,100],[1.03,5.93]],"id":52385918},{"atb":[[1.16,100],[1.03,5.93]],"id":52385920},{"atb":[[1.16,100],[1.02,8.9]],"id":52385889},{"atb":[[1.16,100],[1.03,5.93]],"id":52385914},{"atb":[[1.16,100],[1.02,8.9]],"id":52385883},{"atb":[[1.01,17.8],[1.16,100]],"id":52385885},{"atb":[[1.16,100],[1.03,5.93]],"id":52385896},{"atb":[[1.01,17.8],[1.16,100]],"id":52385890},{"atb":[[1.01,17.8],[1.16,100]],"id":52385892},{"atb":[[1.16,100],[1.02,8.9]],"id":52385904},{"atb":[[1.16,100],[1.02,8.9]],"id":52385898},{"atb":[[1.16,100],[1.03,5.93]],"id":52385900},{"atb":[[1.01,17.8],[1.16,100]],"id":52385911},{"atb":[[1.01,17.8],[1.16,100]],"id":52385913},{"atb":[[1.16,100],[1.03,5.93]],"id":52385907},{"atb":[[1.16,100],[1.02,8.9]],"id":52385886},{"atb":[[1.01,17.8],[1.16,100]],"id":52385919},{"atb":[[1.16,100],[1.03,5.93]],"id":52385921},{"atb":[[1.01,17.8],[1.16,100]],"id":52385882},{"atb":[[1.01,17.8],[1.16,100]],"id":52385884},{"atb":[[1.16,100],[1.03,5.93]],"id":52385917},{"atb":[[1.01,17.8],[1.16,100]],"id":52385897},{"atb":[[1.01,17.8],[1.16,100]],"id":52385891},{"atb":[[1.01,17.8],[1.16,100]],"id":52385893},{"atb":[[1.01,17.8],[1.16,100]],"id":52385903},{"atb":[[1.16,100],[1.02,8.9]],"id":52385905},{"atb":[[1.16,100],[1.03,5.93]],"id":52385899}],"con":true,"img":true}]}
{"op":"mcm","clk":"11548656207","pt":1719472082591,"mc":[{"id":"1.230178175","marketDefinition":{"bspMarket":false,"turnInPlayEnabled":false,"persistenceEnabled":false,"marketBaseRate":5.0,"eventId":"33376048","eventTypeId":"4339","numberOfWinners":1,"bettingType":"ODDS","marketType":"FORECAST","marketTime":"2024-06-27T16:18:00.000Z","suspendTime":"2024-06-27T16:18:00.000Z","bspReconciled":false,"complete":true,"inPlay":false,"crossMatching":false,"runnersVoidable":false,"numberOfActiveRunners":30,"betDelay":0,"status":"OPEN","runners":[{"status":"ACTIVE","sortPriority":1,"id":52385882,"name":"1 - 2"},{"status":"ACTIVE","sortPriority":2,"id":52385883,"name":"1 - 3"},{"status":"ACTIVE","sortPriority":3,"id":52385884,"name":"1 - 4"},{"status":"ACTIVE","sortPriority":4,"id":52385885,"name":"1 - 5"},{"status":"ACTIVE","sortPriority":5,"id":52385886,"name":"1 - 6"},{"status":"ACTIVE","sortPriority":6,"id":52385889,"name":"2 - 1"},{"status":"ACTIVE","sortPriority":7,"id":52385890,"name":"2 - 3"},{"status":"ACTIVE","sortPriority":8,"id":52385891,"name":"2 - 4"},{"status":"ACTIVE","sortPriority":9,"id":52385892,"name":"2 - 5"},{"status":"ACTIVE","sortPriority":10,"id":52385893,"name":"2 - 6"},{"status":"ACTIVE","sortPriority":11,"id":52385896,"name":"3 - 1"},{"status":"ACTIVE","sortPriority":12,"id":52385897,"name":"3 - 2"},{"status":"ACTIVE","sortPriority":13,"id":52385898,"name":"3 - 4"},{"status":"ACTIVE","sortPriority":14,"id":52385899,"name":"3 - 5"},{"status":"ACTIVE","sortPriority":15,"id":52385900,"name":"3 - 6"},{"status":"ACTIVE","sortPriority":16,"id":52385903,"name":"4 - 1"},{"status":"ACTIVE","sortPriority":17,"id":52385904,"name":"4 - 2"},{"status":"ACTIVE","sortPriority":18,"id":52385905,"name":"4 - 3"},{"status":"ACTIVE","sortPriority":19,"id":52385906,"name":"4 - 5"},{"status":"ACTIVE","sortPriority":20,"id":52385907,"name":"4 - 6"},{"status":"ACTIVE","sortPriority":21,"id":52385910,"name":"5 - 1"},{"status":"ACTIVE","sortPriority":22,"id":52385911,"name":"5 - 2"},{"status":"ACTIVE","sortPriority":23,"id":52385912,"name":"5 - 3"},{"status":"ACTIVE","sortPriority":24,"id":52385913,"name":"5 - 4"},{"status":"ACTIVE","sortPriority":25,"id":52385914,"name":"5 - 6"},{"status":"ACTIVE","sortPriority":26,"id":52385917,"name":"6 - 1"},{"status":"ACTIVE","sortPriority":27,"id":52385918,"name":"6 - 2"},{"status":"ACTIVE","sortPriority":28,"id":52385919,"name":"6 - 3"},{"status":"ACTIVE","sortPriority":29,"id":52385920,"name":"6 - 4"},{"status":"ACTIVE","sortPriority":30,"id":52385921,"name":"6 - 5"}],"regulators":["MR_INT"],"venue":"Perry Barr","countryCode":"GB","discountAllowed":true,"timezone":"Europe/London","openDate":"2024-06-27T13:29:00.000Z","version":5994794164,"name":"Forecast","eventName":"Perry Barr (F/C) 27th Jun"},"rc":[{"atb":[[1.16,100],[1.03,5.92]],"id":52385910},{"atb":[[1.01,17.79],[1.16,100]],"id":52385912},{"atb":[[1.16,100],[1.02,8.89]],"id":52385906},{"atb":[[1.16,100],[1.03,5.92]],"id":52385918},{"atb":[[1.16,100],[1.03,5.92]],"id":52385920},{"atb":[[1.16,100],[1.02,8.89]],"id":52385889},{"atb":[[1.16,100],[1.03,5.92]],"id":52385914},{"atb":[[1.16,100],[1.02,8.89]],"id":52385883},{"atb":[[1.01,17.79],[1.16,100]],"id":52385885},{"atb":[[1.16,100],[1.03,5.92]],"id":52385896},{"atb":[[1.01,17.79],[1.16,100]],"id":52385890},{"atb":[[1.01,17.79],[1.16,100]],"id":52385892},{"atb":[[1.16,100],[1.02,8.89]],"id":52385904},{"atb":[[1.16,100],[1.02,8.89]],"id":52385898},{"atb":[[1.16,100],[1.03,5.92]],"id":52385900},{"atb":[[1.01,17.79],[1.16,100]],"id":52385911},{"atb":[[1.01,17.79],[1.16,100]],"id":52385913},{"atb":[[1.16,100],[1.03,5.92]],"id":52385907},{"atb":[[1.16,100],[1.02,8.89]],"id":52385886},{"atb":[[1.01,17.79],[1.16,100]],"id":52385919},{"atb":[[1.16,100],[1.03,5.92]],"id":52385921},{"atb":[[1.01,17.79],[1.16,100]],"id":52385882},{"atb":[[1.01,17.79],[1.16,100]],"id":52385884},{"atb":[[1.16,100],[1.03,5.92]],"id":52385917},{"atb":[[1.01,17.79],[1.16,100]],"id":52385897},{"atb":[[1.01,17.79],[1.16,100]],"id":52385891},{"atb":[[1.01,17.79],[1.16,100]],"id":52385893},{"atb":[[1.01,17.79],[1.16,100]],"id":52385903},{"atb":[[1.16,100],[1.02,8.89]],"id":52385905},{"atb":[[1.16,100],[1.03,5.92]],"id":52385899}],"con":true,"img":true}]}
{"op":"mcm","clk":"11548861953","pt":1719477482591,"mc":[{"id":"1.230178175","marketDefinition":{"bspMarket":false,"turnInPlayEnabled":false,"persistenceEnabled":false,"marketBaseRate":5.0,"eventId":"33376048","eventTypeId":"4339","numberOfWinners":1,"bettingType":"ODDS","marketType":"FORECAST","marketTime":"2024-06-27T16:18:00.000Z","suspendTime":"2024-06-27T16:18:00.000Z","bspReconciled":false,"complete":true,"inPlay":false,"crossMatching":false,"runnersVoidable":false,"numberOfActiveRunners":30,"betDelay":0,"status":"OPEN","runners":[{"status":"ACTIVE","sortPriority":1,"id":52385882,"name":"1 - 2"},{"status":"ACTIVE","sortPriority":2,"id":52385883,"name":"1 - 3"},{"status":"ACTIVE","sortPriority":3,"id":52385884,"name":"1 - 4"},{"status":"ACTIVE","sortPriority":4,"id":52385885,"name":"1 - 5"},{"status":"ACTIVE","sortPriority":5,"id":52385886,"name":"1 - 6"},{"status":"ACTIVE","sortPriority":6,"id":52385889,"name":"2 - 1"},{"status":"ACTIVE","sortPriority":7,"id":52385890,"name":"2 - 3"},{"status":"ACTIVE","sortPriority":8,"id":52385891,"name":"2 - 4"},{"status":"ACTIVE","sortPriority":9,"id":52385892,"name":"2 - 5"},{"status":"ACTIVE","sortPriority":10,"id":52385893,"name":"2 - 6"},{"status":"ACTIVE","sortPriority":11,"id":52385896,"name":"3 - 1"},{"status":"ACTIVE","sortPriority":12,"id":52385897,"name":"3 - 2"},{"status":"ACTIVE","sortPriority":13,"id":52385898,"name":"3 - 4"},{"status":"ACTIVE","sortPriority":14,"id":52385899,"name":"3 - 5"},{"status":"ACTIVE","sortPriority":15,"id":52385900,"name":"3 - 6"},{"status":"ACTIVE","sortPriority":16,"id":52385903,"name":"4 - 1"},{"status":"ACTIVE","sortPriority":17,"id":52385904,"name":"4 - 2"},{"status":"ACTIVE","sortPriority":18,"id":52385905,"name":"4 - 3"},{"status":"ACTIVE","sortPriority":19,"id":52385906,"name":"4 - 5"},{"status":"ACTIVE","sortPriority":20,"id":52385907,"name":"4 - 6"},{"status":"ACTIVE","sortPriority":21,"id":52385910,"name":"5 - 1"},{"status":"ACTIVE","sortPriority":22,"id":52385911,"name":"5 - 2"},{"status":"ACTIVE","sortPriority":23,"id":52385912,"name":"5 - 3"},{"status":"ACTIVE","sortPriority":24,"id":52385913,"name":"5 - 4"},{"status":"ACTIVE","sortPriority":25,"id":52385914,"name":"5 - 6"},{"status":"ACTIVE","sortPriority":26,"id":52385917,"name":"6 - 1"},{"status":"ACTIVE","sortPriority":27,"id":52385918,"name":"6 - 2"},{"status":"ACTIVE","sortPriority":28,"id":52385919,"name":"6 - 3"},{"status":"ACTIVE","sortPriority":29,"id":52385920,"name":"6 - 4"},{"status":"ACTIVE","sortPriority":30,"id":52385921,"name":"6 - 5"}],"regulators":["MR_INT"],"venue":"Perry Barr","countryCode":"GB","discountAllowed":true,"timezone":"Europe/London","openDate":"2024-06-27T13:29:00.000Z","version":5994794164,"name":"Forecast","eventName":"Perry Barr (F/C) 27th Jun"},"rc":[{"atb":[[1.16,100],[1.03,5.93]],"id":52385910},{"atb":[[1.01,17.8],[1.16,100]],"id":52385912},{"atb":[[1.16,100],[1.02,8.9]],"id":52385906},{"atb":[[1.16,100],[1.03,5.93]],"id":52385918},{"atb":[[1.16,100],[1.03,5.93]],"id":52385920},{"atb":[[1.16,100],[1.02,8.9]],"id":52385889},{"atb":[[1.16,100],[1.03,5.93]],"id":52385914},{"atb":[[1.16,100],[1.02,8.9]],"id":52385883},{"atb":[[1.01,17.8],[1.16,100]],"id":52385885},{"atb":[[1.16,100],[1.03,5.93]],"id":52385896},{"atb":[[1.01,17.8],[1.16,100]],"id":52385890},{"atb":[[1.01,17.8],[1.16,100]],"id":52385892},{"atb":[[1.16,100],[1.02,8.9]],"id":52385904},{"atb":[[1.16,100],[1.02,8.9]],"id":52385898},{"atb":[[1.16,100],[1.03,5.93]],"id":52385900},{"atb":[[1.01,17.8],[1.16,100]],"id":52385911},{"atb":[[1.01,17.8],[1.16,100]],"id":52385913},{"atb":[[1.16,100],[1.03,5.93]],"id":52385907},{"atb":[[1.16,100],[1.02,8.9]],"id":52385886},{"atb":[[1.01,17.8],[1.16,100]],"id":52385919},{"atb":[[1.16,100],[1.03,5.93]],"id":52385921},{"atb":[[1.01,17.8],[1.16,100]],"id":52385882},{"atb":[[1.01,17.8],[1.16,100]],"id":52385884},{"atb":[[1.16,100],[1.03,5.93]],"id":52385917},{"atb":[[1.01,17.8],[1.16,100]],"id":52385897},{"atb":[[1.01,17.8],[1.16,100]],"id":52385891},{"atb":[[1.01,17.8],[1.16,100]],"id":52385893},{"atb":[[1.01,17.8],[1.16,100]],"id":52385903},{"atb":[[1.16,100],[1.02,8.9]],"id":52385905},{"atb":[[1.16,100],[1.03,5.93]],"id":52385899}],"con":true,"img":true}]}
{"op":"mcm","clk":"11549140217","pt":1719482882591,"mc":[{"id":"1.230178175","marketDefinition":{"bspMarket":false,"turnInPlayEnabled":false,"persistenceEnabled":false,"marketBaseRate":5.0,"eventId":"33376048","eventTypeId":"4339","numberOfWinners":1,"bettingType":"ODDS","marketType":"FORECAST","marketTime":"2024-06-27T16:18:00.000Z","suspendTime":"2024-06-27T16:18:00.000Z","bspReconciled":false,"complete":true,"inPlay":false,"crossMatching":false,"runnersVoidable":false,"numberOfActiveRunners":30,"betDelay":0,"status":"OPEN","runners":[{"status":"ACTIVE","sortPriority":1,"id":52385882,"name":"1 - 2"},{"status":"ACTIVE","sortPriority":2,"id":52385883,"name":"1 - 3"},{"status":"ACTIVE","sortPriority":3,"id":52385884,"name":"1 - 4"},{"status":"ACTIVE","sortPriority":4,"id":52385885,"name":"1 - 5"},{"status":"ACTIVE","sortPriority":5,"id":52385886,"name":"1 - 6"},{"status":"ACTIVE","sortPriority":6,"id":52385889,"name":"2 - 1"},{"status":"ACTIVE","sortPriority":7,"id":52385890,"name":"2 - 3"},{"status":"ACTIVE","sortPriority":8,"id":52385891,"name":"2 - 4"},{"status":"ACTIVE","sortPriority":9,"id":52385892,"name":"2 - 5"},{"status":"ACTIVE","sortPriority":10,"id":52385893,"name":"2 - 6"},{"status":"ACTIVE","sortPriority":11,"id":52385896,"name":"3 - 1"},{"status":"ACTIVE","sortPriority":12,"id":52385897,"name":"3 - 2"},{"status":"ACTIVE","sortPriority":13,"id":52385898,"name":"3 - 4"},{"status":"ACTIVE","sortPriority":14,"id":52385899,"name":"3 - 5"},{"status":"ACTIVE","sortPriority":15,"id":52385900,"name":"3 - 6"},{"status":"ACTIVE","sortPriority":16,"id":52385903,"name":"4 - 1"},{"status":"ACTIVE","sortPriority":17,"id":52385904,"name":"4 - 2"},{"status":"ACTIVE","sortPriority":18,"id":52385905,"name":"4 - 3"},{"status":"ACTIVE","sortPriority":19,"id":52385906,"name":"4 - 5"},{"status":"ACTIVE","sortPriority":20,"id":52385907,"name":"4 - 6"},{"status":"ACTIVE","sortPriority":21,"id":52385910,"name":"5 - 1"},{"status":"ACTIVE","sortPriority":22,"id":52385911,"name":"5 - 2"},{"status":"ACTIVE","sortPriority":23,"id":52385912,"name":"5 - 3"},{"status":"ACTIVE","sortPriority":24,"id":52385913,"name":"5 - 4"},{"status":"ACTIVE","sortPriority":25,"id":52385914,"name":"5 - 6"},{"status":"ACTIVE","sortPriority":26,"id":52385917,"name":"6 - 1"},{"status":"ACTIVE","sortPriority":27,"id":52385918,"name":"6 - 2"},{"status":"ACTIVE","sortPriority":28,"id":52385919,"name":"6 - 3"},{"status":"ACTIVE","sortPriority":29,"id":52385920,"name":"6 - 4"},{"status":"ACTIVE","sortPriority":30,"id":52385921,"name":"6 - 5"}],"regulators":["MR_INT"],"venue":"Perry Barr","countryCode":"GB","discountAllowed":true,"timezone":"Europe/London","openDate":"2024-06-27T13:29:00.000Z","version":5994794164,"name":"Forecast","eventName":"Perry Barr (F/C) 27th Jun"},"rc":[{"atb":[[1.16,100],[1.03,5.92]],"id":52385910},{"atb":[[1.01,17.79],[1.16,100]],"id":52385912},{"atb":[[1.16,100],[1.02,8.89]],"id":52385906},{"atb":[[1.16,100],[1.03,5.92]],"id":52385918},{"atb":[[1.16,100],[1.03,5.92]],"id":52385920},{"atb":[[1.16,100],[1.02,8.89]],"id":52385889},{"atb":[[1.16,100],[1.03,5.92]],"id":52385914},{"atb":[[1.16,100],[1.02,8.89]],"id":52385883},{"atb":[[1.01,17.79],[1.16,100]],"id":52385885},{"atb":[[1.16,100],[1.03,5.92]],"id":52385896},{"atb":[[1.01,17.79],[1.16,100]],"id":52385890},{"atb":[[1.01,17.79],[1.16,100]],"id":52385892},{"atb":[[1.16,100],[1.02,8.89]],"id":52385904},{"atb":[[1.16,100],[1.02,8.89]],"id":52385898},{"atb":[[1.16,100],[1.03,5.92]],"id":52385900},{"atb":[[1.01,17.79],[1.16,100]],"id":52385911},{"atb":[[1.01,17.79],[1.16,100]],"id":52385913},{"atb":[[1.16,100],[1.03,5.92]],"id":52385907},{"atb":[[1.16,100],[1.02,8.89]],"id":52385886},{"atb":[[1.01,17.79],[1.16,100]],"id":52385919},{"atb":[[1.16,100],[1.03,5.92]],"id":52385921},{"atb":[[1.01,17.79],[1.16,100]],"id":52385882},{"atb":[[1.01,17.79],[1.16,100]],"id":52385884},{"atb":[[1.16,100],[1.03,5.92]],"id":52385917},{"atb":[[1.01,17.79],[1.16,100]],"id":52385897},{"atb":[[1.01,17.79],[1.16,100]],"id":52385891},{"atb":[[1.01,17.79],[1.16,100]],"id":52385893},{"atb":[[1.01,17.79],[1.16,100]],"id":52385903},{"atb":[[1.16,100],[1.02,8.89]],"id":52385905},{"atb":[[1.16,100],[1.03,5.92]],"id":52385899}],"con":true,"img":true}]}
{"op":"mcm","clk":"11549606652","pt":1719488282608,"mc":[{"id":"1.230178175","marketDefinition":{"bspMarket":false,"turnInPlayEnabled":false,"persistenceEnabled":false,"marketBaseRate":5.0,"eventId":"33376048","eventTypeId":"4339","numberOfWinners":1,"bettingType":"ODDS","marketType":"FORECAST","marketTime":"2024-06-27T16:18:00.000Z","suspendTime":"2024-06-27T16:18:00.000Z","bspReconciled":false,"complete":true,"inPlay":false,"crossMatching":false,"runnersVoidable":false,"numberOfActiveRunners":30,"betDelay":0,"status":"OPEN","runners":[{"status":"ACTIVE","sortPriority":1,"id":52385882,"name":"1 - 2"},{"status":"ACTIVE","sortPriority":2,"id":52385883,"name":"1 - 3"},{"status":"ACTIVE","sortPriority":3,"id":52385884,"name":"1 - 4"},{"status":"ACTIVE","sortPriority":4,"id":52385885,"name":"1 - 5"},{"status":"ACTIVE","sortPriority":5,"id":52385886,"name":"1 - 6"},{"status":"ACTIVE","sortPriority":6,"id":52385889,"name":"2 - 1"},{"status":"ACTIVE","sortPriority":7,"id":52385890,"name":"2 - 3"},{"status":"ACTIVE","sortPriority":8,"id":52385891,"name":"2 - 4"},{"status":"ACTIVE","sortPriority":9,"id":52385892,"name":"2 - 5"},{"status":"ACTIVE","sortPriority":10,"id":52385893,"name":"2 - 6"},{"status":"ACTIVE","sortPriority":11,"id":52385896,"name":"3 - 1"},{"status":"ACTIVE","sortPriority":12,"id":52385897,"name":"3 - 2"},{"status":"ACTIVE","sortPriority":13,"id":52385898,"name":"3 - 4"},{"status":"ACTIVE","sortPriority":14,"id":52385899,"name":"3 - 5"},{"status":"ACTIVE","sortPriority":15,"id":52385900,"name":"3 - 6"},{"status":"ACTIVE","sortPriority":16,"id":52385903,"name":"4 - 1"},{"status":"ACTIVE","sortPriority":17,"id":52385904,"name":"4 - 2"},{"status":"ACTIVE","sortPriority":18,"id":52385905,"name":"4 - 3"},{"status":"ACTIVE","sortPriority":19,"id":52385906,"name":"4 - 5"},{"status":"ACTIVE","sortPriority":20,"id":52385907,"name":"4 - 6"},{"status":"ACTIVE","sortPriority":21,"id":52385910,"name":"5 - 1"},{"status":"ACTIVE","sortPriority":22,"id":52385911,"name":"5 - 2"},{"status":"ACTIVE","sortPriority":23,"id":52385912,"name":"5 - 3"},{"status":"ACTIVE","sortPriority":24,"id":52385913,"name":"5 - 4"},{"status":"ACTIVE","sortPriority":25,"id":52385914,"name":"5 - 6"},{"status":"ACTIVE","sortPriority":26,"id":52385917,"name":"6 - 1"},{"status":"ACTIVE","sortPriority":27,"id":52385918,"name":"6 - 2"},{"status":"ACTIVE","sortPriority":28,"id":52385919,"name":"6 - 3"},{"status":"ACTIVE","sortPriority":29,"id":52385920,"name":"6 - 4"},{"status":"ACTIVE","sortPriority":30,"id":52385921,"name":"6 - 5"}],"regulators":["MR_INT"],"venue":"Perry Barr","countryCode":"GB","discountAllowed":true,"timezone":"Europe/London","openDate":"2024-06-27T13:29:00.000Z","version":5994794164,"name":"Forecast","eventName":"Perry Barr (F/C) 27th Jun"},"rc":[{"atb":[[1.16,100],[1.03,5.93]],"id":52385910},{"atb":[[1.01,17.79],[1.16,100]],"id":52385912},{"atb":[[1.16,100],[1.02,8.89]],"id":52385906},{"atb":[[1.16,100],[1.03,5.93]],"id":52385918},{"atb":[[1.16,100],[1.03,5.93]],"id":52385920},{"atb":[[1.16,100],[1.02,8.89]],"id":52385889},{"atb":[[1.16,100],[1.03,5.93]],"id":52385914},{"atb":[[1.16,100],[1.02,8.89]],"id":52385883},{"atb":[[1.01,17.79],[1.16,100]],"id":52385885},{"atb":[[1.16,100],[1.03,5.93]],"id":52385896},{"atb":[[1.01,17.79],[1.16,100]],"id":52385890},{"atb":[[1.01,17.79],[1.16,100]],"id":52385892},{"atb":[[1.16,100],[1.02,8.89]],"id":52385904},{"atb":[[1.16,100],[1.02,8.89]],"id":52385898},{"atb":[[1.16,100],[1.03,5.93]],"id":52385900},{"atb":[[1.01,17.79],[1.16,100]],"id":52385911},{"atb":[[1.01,17.79],[1.16,100]],"id":52385913},{"atb":[[1.16,100],[1.03,5.93]],"id":52385907},{"atb":[[1.16,100],[1.02,8.89]],"id":52385886},{"atb":[[1.01,17.79],[1.16,100]],"id":52385919},{"atb":[[1.16,100],[1.03,5.93]],"id":52385921},{"atb":[[1.01,17.79],[1.16,100]],"id":52385882},{"atb":[[1.01,17.79],[1.16,100]],"id":52385884},{"atb":[[1.16,100],[1.03,5.93]],"id":52385917},{"atb":[[1.01,17.79],[1.16,100]],"id":52385897},{"atb":[[1.01,17.79],[1.16,100]],"id":52385891},{"atb":[[1.01,17.79],[1.16,100]],"id":52385893},{"atb":[[1.01,17.79],[1.16,100]],"id":52385903},{"atb":[[1.16,100],[1.02,8.89]],"id":52385905},{"atb":[[1.16,100],[1.03,5.93]],"id":52385899}],"con":true,"img":true}]}
{"op":"mcm","clk":"11550017468","pt":1719493682609,"mc":[{"id":"1.230178175","marketDefinition":{"bspMarket":false,"turnInPlayEnabled":false,"persistenceEnabled":false,"marketBaseRate":5.0,"eventId":"33376048","eventTypeId":"4339","numberOfWinners":1,"bettingType":"ODDS","marketType":"FORECAST","marketTime":"2024-06-27T16:18:00.000Z","suspendTime":"2024-06-27T16:18:00.000Z","bspReconciled":false,"complete":true,"inPlay":false,"crossMatching":false,"runnersVoidable":false,"numberOfActiveRunners":30,"betDelay":0,"status":"OPEN","runners":[{"status":"ACTIVE","sortPriority":1,"id":52385882,"name":"1 - 2"},{"status":"ACTIVE","sortPriority":2,"id":52385883,"name":"1 - 3"},{"status":"ACTIVE","sortPriority":3,"id":52385884,"name":"1 - 4"},{"status":"ACTIVE","sortPriority":4,"id":52385885,"name":"1 - 5"},{"status":"ACTIVE","sortPriority":5,"id":52385886,"name":"1 - 6"},{"status":"ACTIVE","sortPriority":6,"id":52385889,"name":"2 - 1"},{"status":"ACTIVE","sortPriority":7,"id":52385890,"name":"2 - 3"},{"status":"ACTIVE","sortPriority":8,"id":52385891,"name":"2 - 4"},{"status":"ACTIVE","sortPriority":9,"id":52385892,"name":"2 - 5"},{"status":"ACTIVE","sortPriority":10,"id":52385893,"name":"2 - 6"},{"status":"ACTIVE","sortPriority":11,"id":52385896,"name":"3 - 1"},{"status":"ACTIVE","sortPriority":12,"id":52385897,"name":"3 - 2"},{"status":"ACTIVE","sortPriority":13,"id":52385898,"name":"3 - 4"},{"status":"ACTIVE","sortPriority":14,"id":52385899,"name":"3 - 5"},{"status":"ACTIVE","sortPriority":15,"id":52385900,"name":"3 - 6"},{"status":"ACTIVE","sortPriority":16,"id":52385903,"name":"4 - 1"},{"status":"ACTIVE","sortPriority":17,"id":52385904,"name":"4 - 2"},{"status":"ACTIVE","sortPriority":18,"id":52385905,"name":"4 - 3"},{"status":"ACTIVE","sortPriority":19,"id":52385906,"name":"4 - 5"},{"status":"ACTIVE","sortPriority":20,"id":52385907,"name":"4 - 6"},{"status":"ACTIVE","sortPriority":21,"id":52385910,"name":"5 - 1"},{"status":"ACTIVE","sortPriority":22,"id":52385911,"name":"5 - 2"},{"status":"ACTIVE","sortPriority":23,"id":52385912,"name":"5 - 3"},{"status":"ACTIVE","sortPriority":24,"id":52385913,"name":"5 - 4"},{"status":"ACTIVE","sortPriority":25,"id":52385914,"name":"5 - 6"},{"status":"ACTIVE","sortPriority":26,"id":52385917,"name":"6 - 1"},{"status":"ACTIVE","sortPriority":27,"id":52385918,"name":"6 - 2"},{"status":"ACTIVE","sortPriority":28,"id":52385919,"name":"6 - 3"},{"status":"ACTIVE","sortPriority":29,"id":52385920,"name":"6 - 4"},{"status":"ACTIVE","sortPriority":30,"id":52385921,"name":"6 - 5"}],"regulators":["MR_INT"],"venue":"Perry Barr","countryCode":"GB","discountAllowed":true,"timezone":"Europe/London","openDate":"2024-06-27T13:29:00.000Z","version":5994794164,"name":"Forecast","eventName":"Perry Barr (F/C) 27th Jun"},"rc":[{"atb":[[1.16,100],[1.03,5.93]],"id":52385910},{"atb":[[1.01,17.81],[1.16,100]],"id":52385912},{"atb":[[1.16,100],[1.02,8.9]],"id":52385906},{"atb":[[1.16,100],[1.03,5.93]],"id":52385918},{"atb":[[1.16,100],[1.03,5.93]],"id":52385920},{"atb":[[1.16,100],[1.02,8.9]],"id":52385889},{"atb":[[1.16,100],[1.03,5.93]],"id":52385914},{"atb":[[1.16,100],[1.02,8.9]],"id":52385883},{"atb":[[1.01,17.81],[1.16,100]],"id":52385885},{"atb":[[1.16,100],[1.03,5.93]],"id":52385896},{"atb":[[1.01,17.81],[1.16,100]],"id":52385890},{"atb":[[1.01,17.81],[1.16,100]],"id":52385892},{"atb":[[1.16,100],[1.02,8.9]],"id":52385904},{"atb":[[1.16,100],[1.02,8.9]],"id":52385898},{"atb":[[1.16,100],[1.03,5.93]],"id":52385900},{"atb":[[1.01,17.81],[1.16,100]],"id":52385911},{"atb":[[1.01,17.81],[1.16,100]],"id":52385913},{"atb":[[1.16,100],[1.03,5.93]],"id":52385907},{"atb":[[1.16,100],[1.02,8.9]],"id":52385886},{"atb":[[1.01,17.81],[1.16,100]],"id":52385919},{"atb":[[1.16,100],[1.03,5.93]],"id":52385921},{"atb":[[1.01,17.81],[1.16,100]],"id":52385882},{"atb":[[1.01,17.81],[1.16,100]],"id":52385884},{"atb":[[1.16,100],[1.03,5.93]],"id":52385917},{"atb":[[1.01,17.81],[1.16,100]],"id":52385897},{"atb":[[1.01,17.81],[1.16,100]],"id":52385891},{"atb":[[1.01,17.81],[1.16,100]],"id":52385893},{"atb":[[1.01,17.81],[1.16,100]],"id":52385903},{"atb":[[1.16,100],[1.02,8.9]],"id":52385905},{"atb":[[1.16,100],[1.03,5.93]],"id":52385899}],"con":true,"img":true}]}
{"op":"mcm","clk":"11550103028","pt":1719494471213,"mc":[{"id":"1.230178175","rc":[{"atb":[[1.03,5.93]],"id":52385910},{"atb":[[1.01,17.81]],"id":52385912},{"atb":[[1.02,8.9]],"id":52385906},{"atb":[[1.03,5.93]],"id":52385918},{"atb":[[1.03,5.93]],"id":52385920},{"atb":[[1.02,8.9]],"id":52385889},{"atb":[[1.03,5.93]],"id":52385914},{"atb":[[1.01,306.12],[1.02,8.9]],"id":52385883},{"atb":[[1.01,17.81]],"id":52385885},{"atb":[[1.03,5.93]],"id":52385896},{"atb":[[1.01,17.81]],"id":52385890},{"atb":[[1.01,17.81]],"id":52385892},{"atb":[[1.02,8.9]],"id":52385904},{"atb":[[1.02,8.9]],"id":52385898},{"atb":[[1.03,5.93]],"id":52385900},{"atb":[[1.01,17.81]],"id":52385911},{"atb":[[1.01,17.81]],"id":52385913},{"atb":[[1.03,5.93]],"id":52385907},{"atb":[[1.02,8.9]],"id":52385886},{"atb":[[1.01,17.81]],"id":52385919},{"atb":[[1.03,5.93]],"id":52385921},{"atb":[[1.01,323.93]],"id":52385882},{"atb":[[1.01,323.93]],"id":52385884},{"atb":[[1.03,5.93]],"id":52385917},{"atb":[[1.01,17.81]],"id":52385897},{"atb":[[1.01,17.81]],"id":52385891},{"atb":[[1.01,17.81]],"id":52385893},{"atb":[[1.01,17.81]],"id":52385903},{"atb":[[1.02,8.9]],"id":52385905},{"atb":[[1.03,5.93]],"id":52385899}],"con":true,"img":false}]}
{"op":"mcm","clk":"11550103052","pt":1719494471414,"mc":[{"id":"1.230178175","rc":[{"atb":[[1.01,323.93]],"id":52385885}],"con":true,"img":false}]}
{"op":"mcm","clk":"11550103064","pt":1719494471517,"mc":[{"id":"1.230178175","rc":[{"atb":[[1.01,306.12]],"id":52385886}],"con":true,"img":false}]}
{"op":"mcm","clk":"11550103080","pt":1719494471623,"mc":[{"id":"1.230178175","rc":[{"atb":[[1.01,306.12]],"id":52385889}],"con":true,"img":false}]}
{"op":"mcm","clk":"11550103093","pt":1719494471725,"mc":[{"id":"1.230178175","rc":[{"atb":[[1.01,323.93]],"id":52385890}],"con":true,"img":false}]}
{"op":"mcm","clk":"11550103106","pt":1719494471829,"mc":[{"id":"1.230178175","rc":[{"atb":[[1.01,323.93]],"id":52385891}],"con":true,"img":false}]}
{"op":"mcm","clk":"11550103119","pt":1719494471930,"mc":[{"id":"1.230178175","rc":[{"atb":[[1.01,323.93]],"id":52385892}],"con":true,"img":false}]}
{"op":"mcm","clk":"11550103142","pt":1719494472141,"mc":[{"id":"1.230178175","rc":[{"atb":[[1.01,306.12]],"id":52385896},{"atb":[[1.01,323.93]],"id":52385893}],"con":true,"img":false}]}
{"op":"mcm","clk":"11550103168","pt":1719494472347,"mc":[{"id":"1.230178175","rc":[{"atb":[[1.01,306.12]],"id":52385898},{"atb":[[1.01,323.93]],"id":52385897}],"con":true,"img":false}]}
{"op":"mcm","clk":"11550103193","pt":1719494472503,"mc":[{"id":"1.230178175","rc":[{"atb":[[1.01,306.12]],"id":52385900},{"atb":[[1.01,323.93]],"id":52385903},{"atb":[[1.01,306.12]],"id":52385899}],"con":true,"img":false}]}
{"op":"mcm","clk":"11550103217","pt":1719494472715,"mc":[{"id":"1.230178175","rc":[{"atb":[[1.01,306.12]],"id":52385906},{"atb":[[1.01,306.12]],"id":52385904},{"atb":[[1.01,306.12]],"id":52385905}],"con":true,"img":false}]}
{"op":"mcm","clk":"11550103242","pt":1719494472920,"mc":[{"id":"1.230178175","rc":[{"atb":[[1.01,306.12]],"id":52385910},{"atb":[[1.01,306.12]],"id":52385907}],"con":true,"img":false}]}
{"op":"mcm","clk":"11550103257","pt":1719494473023,"mc":[{"id":"1.230178175","rc":[{"atb":[[1.01,323.93]],"id":52385911}],"con":true,"img":false}]}
{"op":"mcm","clk":"11550103269","pt":1719494473125,"mc":[{"id":"1.230178175","rc":[{"atb":[[1.01,323.93]],"id":52385912},{"atb":[[1.01,323.93]],"id":52385913}],"con":true,"img":false}]}
{"op":"mcm","clk":"11550103296","pt":1719494473334,"mc":[{"id":"1.230178175","rc":[{"atb":[[1.01,306.12]],"id":52385918},{"atb":[[1.01,306.12]],"id":52385914},{"atb":[[1.01,306.12]],"id":52385917}],"con":true,"img":false}]}
{"op":"mcm","clk":"11550103310","pt":1719494473540,"mc":[{"id":"1.230178175","rc":[{"atb":[[1.01,306.12]],"id":52385920},{"atb":[[1.01,323.93]],"id":52385919}],"con":true,"img":false}]}
{"op":"mcm","clk":"11550103319","pt":1719494473643,"mc":[{"id":"1.230178175","rc":[{"atb":[[1.01,306.12]],"id":52385921}],"con":true,"img":false}]}
{"op":"mcm","clk":"11550103331","pt":1719494473746,"mc":[{"id":"1.230178175","rc":[{"atb":[[1.17,120.05]],"id":52385883},{"atb":[[1.17,120.05]],"id":52385882}],"con":true,"img":false}]}
{"op":"mcm","clk":"11550103343","pt":1719494473850,"mc":[{"id":"1.230178175","rc":[{"atb":[[1.17,120.05]],"id":52385884}],"con":true,"img":false}]}
{"op":"mcm","clk":"11550103354","pt":1719494473901,"mc":[{"id":"1.230178175","rc":[{"atb":[[1.17,120.05]],"id":52385885}],"con":true,"img":false}]}
{"op":"mcm","clk":"11550103367","pt":1719494474006,"mc":[{"id":"1.230178175","rc":[{"atb":[[1.17,120.05]],"id":52385886}],"con":true,"img":false}]}
{"op":"mcm","clk":"11550103387","pt":1719494474211,"mc":[{"id":"1.230178175","rc":[{"atb":[[1.17,120.05]],"id":52385889},{"atb":[[1.17,120.05]],"id":52385890}],"con":true,"img":false}]}
{"op":"mcm","clk":"11550103407","pt":1719494474420,"mc":[{"id":"1.230178175","rc":[{"atb":[[1.17,120.05]],"id":52385891}],"con":true,"img":false}]}
{"op":"mcm","clk":"11550103416","pt":1719494474523,"mc":[{"id":"1.230178175","rc":[{"atb":[[1.17,120.05]],"id":52385892}],"con":true,"img":false}]}
{"op":"mcm","clk":"11550103426","pt":1719494474626,"mc":[{"id":"1.230178175","rc":[{"atb":[[1.17,120.05]],"id":52385893}],"con":true,"img":false}]}
{"op":"mcm","clk":"11550103445","pt":1719494474832,"mc":[{"id":"1.230178175","rc":[{"atb":[[1.17,120.05]],"id":52385896},{"atb":[[1.17,120.05]],"id":52385898},{"atb":[[1.17,120.05]],"id":52385897}],"con":true,"img":false}]}
{"op":"mcm","clk":"11550103465","pt":1719494475038,"mc":[{"id":"1.230178175","rc":[{"atb":[[1.17,120.05]],"id":52385900},{"atb":[[1.17,120.05]],"id":52385903},{"atb":[[1.17,120.05]],"id":52385899}],"con":true,"img":false}]}
{"op":"mcm","clk":"11550103486","pt":1719494475245,"mc":[{"id":"1.230178175","rc":[{"atb":[[1.17,120.05]],"id":52385904},{"atb":[[1.17,120.05]],"id":52385905}],"con":true,"img":false}]}
{"op":"mcm","clk":"11550103500","pt":1719494475347,"mc":[{"id":"1.230178175","rc":[{"atb":[[1.17,120.05]],"id":52385906}],"con":true,"img":false}]}
{"op":"mcm","clk":"11550103512","pt":1719494475451,"mc":[{"id":"1.230178175","rc":[{"atb":[[1.17,120.05]],"id":52385910},{"atb":[[1.17,120.05]],"id":52385907}],"con":true,"img":false}]}
{"op":"mcm","clk":"11550103535","pt":1719494475607,"mc":[{"id":"1.230178175","rc":[{"atb":[[1.17,120.05]],"id":52385912},{"atb":[[1.17,120.05]],"id":52385911},{"atb":[[1.17,120.05]],"id":52385913}],"con":true,"img":false}]}
{"op":"mcm","clk":"11550103561","pt":1719494475817,"mc":[{"id":"1.230178175","rc":[{"atb":[[1.17,120.05]],"id":52385918},{"atb":[[1.17,120.05]],"id":52385914},{"atb":[[1.17,120.05]],"id":52385917}],"con":true,"img":false}]}
{"op":"mcm","clk":"11550103579","pt":1719494476028,"mc":[{"id":"1.230178175","rc":[{"atb":[[1.17,120.05]],"id":52385920},{"atb":[[1.17,120.05]],"id":52385919}],"con":true,"img":false}]}
{"op":"mcm","clk":"11550103592","pt":1719494476127,"mc":[{"id":"1.230178175","rc":[{"atb":[[1.17,120.05]],"id":52385921}],"con":true,"img":false}]}
{"op":"mcm","clk":"11550154949","pt":1719494971881,"mc":[{"id":"1.230178175","rc":[{"atb":[[1.16,0]],"id":52385910},{"atb":[[1.16,0]],"id":52385912},{"atb":[[1.16,0]],"id":52385906},{"atb":[[1.16,0]],"id":52385918},{"atb":[[1.16,0]],"id":52385920},{"atb":[[1.16,0]],"id":52385889},{"atb":[[1.16,0]],"id":52385914},{"atb":[[1.16,0]],"id":52385883},{"atb":[[1.16,0]],"id":52385885},{"atb":[[1.16,0]],"id":52385896},{"atb":[[1.16,0]],"id":52385890},{"atb":[[1.16,0]],"id":52385892},{"atb":[[1.16,0]],"id":52385904},{"atb":[[1.16,0]],"id":52385898},{"atb":[[1.16,0]],"id":52385900},{"atb":[[1.16,0]],"id":52385911},{"atb":[[1.16,0]],"id":52385913},{"atb":[[1.16,0]],"id":52385907},{"atb":[[1.16,0]],"id":52385886},{"atb":[[1.16,0]],"id":52385919},{"atb":[[1.16,0]],"id":52385921},{"atb":[[1.16,0]],"id":52385882},{"atb":[[1.16,0]],"id":52385884},{"atb":[[1.16,0]],"id":52385917},{"atb":[[1.16,0]],"id":52385897},{"atb":[[1.16,0]],"id":52385891},{"atb":[[1.16,0]],"id":52385893},{"atb":[[1.16,0]],"id":52385903},{"atb":[[1.16,0]],"id":52385905},{"atb":[[1.16,0]],"id":52385899}],"con":true,"img":false}]}
{"op":"mcm","clk":"11550155342","pt":1719494976258,"mc":[{"id":"1.230178175","rc":[{"atb":[[1.18,150]],"id":52385910},{"atb":[[1.18,150]],"id":52385912},{"atb":[[1.18,150]],"id":52385906},{"atb":[[1.18,150]],"id":52385918},{"atb":[[1.18,150]],"id":52385920},{"atb":[[1.18,150]],"id":52385889},{"atb":[[1.18,150]],"id":52385914},{"atb":[[1.18,150]],"id":52385883},{"atb":[[1.18,150]],"id":52385885},{"atb":[[1.18,150]],"id":52385896},{"atb":[[1.18,150]],"id":52385890},{"atb":[[1.18,150]],"id":52385892},{"atb":[[1.18,150]],"id":52385904},{"atb":[[1.18,150]],"id":52385898},{"atb":[[1.18,150]],"id":52385900},{"atb":[[1.18,150]],"id":52385911},{"atb":[[1.18,150]],"id":52385913},{"atb":[[1.18,150]],"id":52385907},{"atb":[[1.18,150]],"id":52385886},{"atb":[[1.18,150]],"id":52385919},{"atb":[[1.18,150]],"id":52385921},{"atb":[[1.18,150]],"id":52385882},{"atb":[[1.18,150]],"id":52385884},{"atb":[[1.18,150]],"id":52385917},{"atb":[[1.18,150]],"id":52385897},{"atb":[[1.18,150]],"id":52385891},{"atb":[[1.18,150]],"id":52385893},{"atb":[[1.18,150]],"id":52385903},{"atb":[[1.18,150]],"id":52385905},{"atb":[[1.18,150]],"id":52385899}],"con":true,"img":false}]}
{"op":"mcm","clk":"11550169519","pt":1719495161645,"mc":[{"id":"1.230178175","rc":[{"atb":[[1.17,0]],"id":52385883}],"con":true,"img":false}]}
{"op":"mcm","clk":"11550188134","pt":1719495391582,"mc":[{"id":"1.230178175","rc":[{"atb":[[1.17,0]],"id":52385882}],"con":true,"img":false}]}
{"op":"mcm","clk":"11550208135","pt":1719495621813,"mc":[{"id":"1.230178175","rc":[{"atb":[[1.17,0]],"id":52385884}],"con":true,"img":false}]}
{"op":"mcm","clk":"11550228699","pt":1719495862012,"mc":[{"id":"1.230178175","rc":[{"atb":[[1.17,0]],"id":52385885}],"con":true,"img":false}]}
{"op":"mcm","clk":"11550250631","pt":1719496102170,"mc":[{"id":"1.230178175","rc":[{"atb":[[1.17,0]],"id":52385886}],"con":true,"img":false}]}
{"op":"mcm","clk":"11550267153","pt":1719496342037,"mc":[{"id":"1.230178175","rc":[{"atb":[[1.17,0]],"id":52385890}],"con":true,"img":false}]}
{"op":"mcm","clk":"11550281193","pt":1719496572135,"mc":[{"id":"1.230178175","rc":[{"atb":[[1.17,0]],"id":52385889}],"con":true,"img":false}]}
{"op":"mcm","clk":"11550325029","pt":1719497072729,"mc":[{"id":"1.230178175","rc":[{"atb":[[1.03,5.93]],"id":52385910},{"atb":[[1.01,323.93]],"id":52385912},{"atb":[[1.02,8.9]],"id":52385906},{"atb":[[1.03,5.93]],"id":52385918},{"atb":[[1.03,5.93]],"id":52385920},{"atb":[[1.02,8.9]],"id":52385889},{"atb":[[1.03,5.93]],"id":52385914},{"atb":[[1.02,8.9]],"id":52385883},{"atb":[[1.01,323.93]],"id":52385885},{"atb":[[1.03,5.93]],"id":52385896},{"atb":[[1.01,323.93]],"id":52385890},{"atb":[[1.01,323.93]],"id":52385892},{"atb":[[1.02,8.9]],"id":52385904},{"atb":[[1.02,8.9]],"id":52385898},{"atb":[[1.03,5.93]],"id":52385900},{"atb":[[1.01,323.93]],"id":52385911},{"atb":[[1.01,323.93]],"id":52385913},{"atb":[[1.03,5.93]],"id":52385907},{"atb":[[1.02,8.9]],"id":52385886},{"atb":[[1.01,323.93]],"id":52385919},{"atb":[[1.03,5.93]],"id":52385921},{"atb":[[1.01,323.93]],"id":52385882},{"atb":[[1.01,323.93]],"id":52385884},{"atb":[[1.03,5.93]],"id":52385917},{"atb":[[1.01,323.93]],"id":52385897},{"atb":[[1.01,323.93],[1.17,0]],"id":52385891},{"atb":[[1.01,323.93]],"id":52385893},{"atb":[[1.01,323.93]],"id":52385903},{"atb":[[1.02,8.9]],"id":52385905},{"atb":[[1.03,5.93]],"id":52385899}],"con":true,"img":false}]}
{"op":"mcm","clk":"11550346486","pt":1719497312600,"mc":[{"id":"1.230178175","rc":[{"atb":[[1.17,0]],"id":52385892}],"con":true,"img":false}]}
{"op":"mcm","clk":"11550366321","pt":1719497562673,"mc":[{"id":"1.230178175","rc":[{"atb":[[1.17,0]],"id":52385893}],"con":true,"img":false}]}
{"op":"mcm","clk":"11550387201","pt":1719497812811,"mc":[{"id":"1.230178175","rc":[{"atb":[[1.17,0]],"id":52385896}],"con":true,"img":false}]}
{"op":"mcm","clk":"11550406993","pt":1719498052941,"mc":[{"id":"1.230178175","rc":[{"atb":[[1.17,0]],"id":52385898}],"con":true,"img":false}]}
{"op":"mcm","clk":"11550425886","pt":1719498293039,"mc":[{"id":"1.230178175","rc":[{"atb":[[1.17,0]],"id":52385897}],"con":true,"img":false}]}
{"op":"mcm","clk":"11550444844","pt":1719498543209,"mc":[{"id":"1.230178175","rc":[{"atb":[[1.17,0]],"id":52385900}],"con":true,"img":false}]}
{"op":"mcm","clk":"11550462824","pt":1719498783283,"mc":[{"id":"1.230178175","rc":[{"atb":[[1.17,0]],"id":52385903}],"con":true,"img":false}]}
{"op":"mcm","clk":"11550482057","pt":1719499003423,"mc":[{"id":"1.230178175","rc":[{"atb":[[1.17,0]],"id":52385899}],"con":true,"img":false}]}
{"op":"mcm","clk":"11550504848","pt":1719499223450,"mc":[{"id":"1.230178175","rc":[{"atb":[[1.17,0]],"id":52385904}],"con":true,"img":false}]}
{"op":"mcm","clk":"11550539860","pt":1719499693619,"mc":[{"id":"1.230178175","rc":[{"atb":[[1.17,0]],"id":52385905}],"con":true,"img":false}]}
{"op":"mcm","clk":"11550554758","pt":1719499913819,"mc":[{"id":"1.230178175","rc":[{"atb":[[1.17,0]],"id":52385906}],"con":true,"img":false}]}
{"op":"mcm","clk":"11550569537","pt":1719500139954,"mc":[{"id":"1.230178175","rc":[{"atb":[[1.04,88.89]],"id":52385910},{"atl":[[980,1.59]],"id":52385910},{"atb":[[1.04,153.23]],"id":52385912},{"atl":[[960,0.87]],"id":52385912},{"atb":[[1.02,149.44]],"id":52385906},{"atl":[[960,1.75]],"id":52385906},{"atb":[[1.02,125.73]],"id":52385889},{"atl":[[990,1.44]],"id":52385889},{"atb":[[1.04,148.15]],"id":52385914},{"atl":[[960,1.76]],"id":52385914},{"atb":[[1.02,136.74]],"id":52385883},{"atl":[[970,0.87]],"id":52385883},{"atb":[[1.02,142.22]],"id":52385885},{"atl":[[980,2.01]],"id":52385885},{"atb":[[1.03,111.75]],"id":52385896},{"atl":[[980,1.69]],"id":52385896},{"atb":[[1.03,121.9]],"id":52385890},{"atl":[[990,2.13]],"id":52385890},{"atb":[[1.04,158.31]],"id":52385892},{"atl":[[970,1.54]],"id":52385892},{"atb":[[1.03,133.76]],"id":52385904},{"atl":[[960,1.87]],"id":52385904},{"atb":[[1.04,137.99]],"id":52385898},{"atl":[[970,1.71]],"id":52385898},{"atb":[[1.03,140.54]],"id":52385900},{"atl":[[990,1.27]],"id":52385900},{"atb":[[1.03,77.04]],"id":52385911},{"atl":[[990,0.87]],"id":52385911},{"atb":[[1.02,127.83]],"id":52385913},{"atl":[[990,0.87]],"id":52385913},{"atb":[[1.04,142.22]],"id":52385907},{"atl":[[990,1.79]],"id":52385907},{"atb":[[1.04,105.82]],"id":52385886},{"atl":[[990,1.4]],"id":52385886},{"atb":[[1.03,95.66]],"id":52385882},{"atl":[[970,0.87]],"id":52385882},{"atb":[[1.04,110.05]],"id":52385884},{"atl":[[970,1.18]],"id":52385884},{"atb":[[1.02,138.84]],"id":52385897},{"atl":[[970,2.04]],"id":52385897},{"atb":[[1.04,84.65]],"id":52385891},{"atl":[[980,1.84]],"id":52385891},{"atb":[[1.03,153.23]],"id":52385893},{"atl":[[970,1.98]],"id":52385893},{"atb":[[1.03,193.87]],"id":52385903},{"atl":[[980,1.21]],"id":52385903},{"atb":[[1.04,141.38]],"id":52385905},{"atl":[[970,2.13]],"id":52385905},{"atb":[[1.03,83.82]],"id":52385899},{"atl":[[980,1.21]],"id":52385899}],"con":true,"img":false}]}
{"op":"mcm","clk":"11550569749","pt":1719500142568,"mc":[{"id":"1.230178175","marketDefinition":{"bspMarket":false,"turnInPlayEnabled":false,"persistenceEnabled":false,"marketBaseRate":5.0,"eventId":"33376048","eventTypeId":"4339","numberOfWinners":1,"bettingType":"ODDS","marketType":"FORECAST","marketTime":"2024-06-27T16:18:00.000Z","suspendTime":"2024-06-27T16:18:00.000Z","bspReconciled":false,"complete":true,"inPlay":false,"crossMatching":true,"runnersVoidable":false,"numberOfActiveRunners":30,"betDelay":0,"status":"OPEN","runners":[{"status":"ACTIVE","sortPriority":1,"id":52385882,"name":"1 - 2"},{"status":"ACTIVE","sortPriority":2,"id":52385883,"name":"1 - 3"},{"status":"ACTIVE","sortPriority":3,"id":52385884,"name":"1 - 4"},{"status":"ACTIVE","sortPriority":4,"id":52385885,"name":"1 - 5"},{"status":"ACTIVE","sortPriority":5,"id":52385886,"name":"1 - 6"},{"status":"ACTIVE","sortPriority":6,"id":52385889,"name":"2 - 1"},{"status":"ACTIVE","sortPriority":7,"id":52385890,"name":"2 - 3"},{"status":"ACTIVE","sortPriority":8,"id":52385891,"name":"2 - 4"},{"status":"ACTIVE","sortPriority":9,"id":52385892,"name":"2 - 5"},{"status":"ACTIVE","sortPriority":10,"id":52385893,"name":"2 - 6"},{"status":"ACTIVE","sortPriority":11,"id":52385896,"name":"3 - 1"},{"status":"ACTIVE","sortPriority":12,"id":52385897,"name":"3 - 2"},{"status":"ACTIVE","sortPriority":13,"id":52385898,"name":"3 - 4"},{"status":"ACTIVE","sortPriority":14,"id":52385899,"name":"3 - 5"},{"status":"ACTIVE","sortPriority":15,"id":52385900,"name":"3 - 6"},{"status":"ACTIVE","sortPriority":16,"id":52385903,"name":"4 - 1"},{"status":"ACTIVE","sortPriority":17,"id":52385904,"name":"4 - 2"},{"status":"ACTIVE","sortPriority":18,"id":52385905,"name":"4 - 3"},{"status":"ACTIVE","sortPriority":19,"id":52385906,"name":"4 - 5"},{"status":"ACTIVE","sortPriority":20,"id":52385907,"name":"4 - 6"},{"status":"ACTIVE","sortPriority":21,"id":52385910,"name":"5 - 1"},{"status":"ACTIVE","sortPriority":22,"id":52385911,"name":"5 - 2"},{"status":"ACTIVE","sortPriority":23,"id":52385912,"name":"5 - 3"},{"status":"ACTIVE","sortPriority":24,"id":52385913,"name":"5 - 4"},{"status":"ACTIVE","sortPriority":25,"id":52385914,"name":"5 - 6"},{"status":"ACTIVE","sortPriority":26,"id":52385917,"name":"6 - 1"},{"status":"ACTIVE","sortPriority":27,"id":52385918,"name":"6 - 2"},{"status":"ACTIVE","sortPriority":28,"id":52385919,"name":"6 - 3"},{"status":"ACTIVE","sortPriority":29,"id":52385920,"name":"6 - 4"},{"status":"ACTIVE","sortPriority":30,"id":52385921,"name":"6 - 5"}],"regulators":["MR_INT"],"venue":"Perry Barr","countryCode":"GB","discountAllowed":true,"timezone":"Europe/London","openDate":"2024-06-27T13:29:00.000Z","version":5994794164,"name":"Forecast","eventName":"Perry Barr (F/C) 27th Jun"},"rc":[],"con":true,"img":false}]}
{"op":"mcm","clk":"11550569856","pt":1719500143947,"mc":[{"id":"1.230178175","rc":[{"atb":[[1.17,0]],"id":52385907}],"con":true,"img":false}]}
{"op":"mcm","clk":"11550574809","pt":1719500208212,"mc":[{"id":"1.230178175","rc":[{"atb":[[1.03,6.93]],"id":52385910},{"atb":[[1.03,1]],"id":52385912},{"atb":[[1.03,1]],"id":52385906},{"atb":[[1.03,6.93]],"id":52385918},{"atb":[[1.03,6.93]],"id":52385920},{"atb":[[1.03,1]],"id":52385889},{"atb":[[1.03,6.93]],"id":52385914},{"atb":[[1.03,1]],"id":52385883},{"atb":[[1.03,1]],"id":52385885},{"atb":[[1.03,112.75]],"id":52385896},{"atb":[[1.03,122.9]],"id":52385890},{"atb":[[1.03,1]],"id":52385892},{"atb":[[1.03,134.76]],"id":52385904},{"atb":[[1.03,1]],"id":52385898},{"atb":[[1.03,141.54]],"id":52385900},{"atb":[[1.03,78.04]],"id":52385911},{"atb":[[1.03,1]],"id":52385913},{"atb":[[1.03,6.93]],"id":52385907},{"atb":[[1.03,1]],"id":52385886},{"atb":[[1.03,1]],"id":52385919},{"atb":[[1.03,6.93]],"id":52385921},{"atb":[[1.03,96.66]],"id":52385882},{"atb":[[1.03,1]],"id":52385884},{"atb":[[1.03,6.93]],"id":52385917},{"atb":[[1.03,1]],"id":52385897},{"atb":[[1.03,1]],"id":52385891},{"atb":[[1.03,154.23]],"id":52385893},{"atb":[[1.03,194.87]],"id":52385903},{"atb":[[1.03,1]],"id":52385905},{"atb":[[1.03,84.82]],"id":52385899}],"con":true,"img":false}]}
{"op":"mcm","clk":"11550574828","pt":1719500208420,"mc":[{"id":"1.230178175","rc":[{"atb":[[1.03,6.83]],"id":52385910},{"atb":[[1.03,0.9]],"id":52385912},{"atb":[[1.03,0.9]],"id":52385906},{"atb":[[1.03,6.83]],"id":52385918},{"atb":[[1.03,6.83]],"id":52385920},{"atb":[[1.03,0.9]],"id":52385889},{"atb":[[1.03,6.83]],"id":52385914},{"atb":[[1.03,0.9]],"id":52385883},{"atb":[[1.03,0.9]],"id":52385885},{"atb":[[1.03,112.65]],"id":52385896},{"atb":[[1.03,122.8]],"id":52385890},{"atb":[[1.03,0.9]],"id":52385892},{"atb":[[1.03,134.66]],"id":52385904},{"atb":[[1.03,0.9]],"id":52385898},{"atb":[[1.03,141.44]],"id":52385900},{"atb":[[1.03,77.94]],"id":52385911},{"atb":[[1.03,0.9]],"id":52385913},{"atb":[[1.03,6.83]],"id":52385907},{"atb":[[1.03,0.9]],"id":52385886},{"atb":[[1.03,0.9]],"id":52385919},{"atb":[[1.03,6.83]],"id":52385921},{"atb":[[1.03,96.56]],"id":52385882},{"atb":[[1.03,0.9]],"id":52385884},{"atb":[[1.03,6.83]],"id":52385917},{"atb":[[1.03,0.9]],"id":52385897},{"atb":[[1.03,0.9]],"id":52385891},{"atb":[[1.03,154.13]],"id":52385893},{"atb":[[1.03,194.77]],"id":52385903},{"atb":[[1.03,0.9]],"id":52385905},{"atb":[[1.03,84.72]],"id":52385899}],"con":true,"img":false}]}
{"op":"mcm","clk":"11550574851","pt":1719500208729,"mc":[{"id":"1.230178175","rc":[{"atb":[[1.03,5.93]],"id":52385910},{"atb":[[1.03,0]],"id":52385912},{"atb":[[1.03,0]],"id":52385906},{"atb":[[1.03,5.93]],"id":52385918},{"atb":[[1.03,5.93]],"id":52385920},{"atb":[[1.03,0]],"id":52385889},{"atb":[[1.03,5.93]],"id":52385914},{"atb":[[1.03,0]],"id":52385883},{"atb":[[1.03,0]],"id":52385885},{"atb":[[1.03,111.75]],"id":52385896},{"atb":[[1.03,121.9]],"id":52385890},{"atb":[[1.03,0]],"id":52385892},{"atb":[[1.03,133.76]],"id":52385904},{"atb":[[1.03,0]],"id":52385898},{"atb":[[1.03,140.54]],"id":52385900},{"atb":[[1.03,77.04]],"id":52385911},{"atb":[[1.03,0]],"id":52385913},{"atb":[[1.03,5.93]],"id":52385907},{"atb":[[1.03,0]],"id":52385886},{"atb":[[1.03,0]],"id":52385919},{"atb":[[1.03,5.93]],"id":52385921},{"atb":[[1.03,95.66]],"id":52385882},{"atb":[[1.03,0]],"id":52385884},{"atb":[[1.03,5.93]],"id":52385917},{"atb":[[1.03,0]],"id":52385897},{"atb":[[1.03,0]],"id":52385891},{"atb":[[1.03,153.23]],"id":52385893},{"atb":[[1.03,193.87]],"id":52385903},{"atb":[[1.03,0]],"id":52385905},{"atb":[[1.03,83.82]],"id":52385899}],"con":true,"img":false}]}
{"op":"mcm","clk":"11550574859","pt":1719500208833,"mc":[{"id":"1.230178175","rc":[{"atb":[[3.05,0.9]],"id":52385910},{"atb":[[3.05,0.9]],"id":52385912},{"atb":[[3.05,0.9]],"id":52385906},{"atb":[[3.05,0.9]],"id":52385918},{"atb":[[3.05,0.9]],"id":52385920},{"atb":[[3.05,0.9]],"id":52385889},{"atb":[[3.05,0.9]],"id":52385914},{"atb":[[3.05,0.9]],"id":52385883},{"atb":[[3.05,0.9]],"id":52385885},{"atb":[[3.05,0.9]],"id":52385896},{"atb":[[3.05,0.9]],"id":52385890},{"atb":[[3.05,0.9]],"id":52385892},{"atb":[[3.05,0.9]],"id":52385904},{"atb":[[3.05,0.9]],"id":52385898},{"atb":[[3.05,0.9]],"id":52385900},{"atb":[[3.05,0.9]],"id":52385911},{"atb":[[3.05,0.9]],"id":52385913},{"atb":[[3.05,0.9]],"id":52385907},{"atb":[[3.05,0.9]],"id":52385886},{"atb":[[3.05,0.9]],"id":52385919},{"atb":[[3.05,0.9]],"id":52385921},{"atb":[[3.05,0.9]],"id":52385882},{"atb":[[3.05,0.9]],"id":52385884},{"atb":[[3.05,0.9]],"id":52385917},{"atb":[[3.05,0.9]],"id":52385897},{"atb":[[3.05,0.9]],"id":52385891},{"atb":[[3.05,0.9]],"id":52385893},{"atb":[[3.05,0.9]],"id":52385903},{"atb":[[3.05,0.9]],"id":52385905},{"atb":[[3.05,0.9]],"id":52385899}],"con":true,"img":false}]}
{"op":"mcm","clk":"11550587131","pt":1719500383952,"mc":[{"id":"1.230178175","rc":[{"atb":[[1.17,0]],"id":52385910}],"con":true,"img":false}]}
{"op":"mcm","clk":"11550604846","pt":1719500634209,"mc":[{"id":"1.230178175","rc":[{"atb":[[1.03,5.93],[1.04,88.9]],"id":52385910},{"atl":[[980,1.59]],"id":52385910},{"atb":[[1.01,323.93],[1.04,153.25]],"id":52385912},{"atl":[[960,0.87]],"id":52385912},{"atb":[[1.02,149.46]],"id":52385906},{"atl":[[960,1.75]],"id":52385906},{"atb":[[1.03,5.93]],"id":52385918},{"atb":[[1.03,5.93]],"id":52385920},{"atb":[[1.02,125.75]],"id":52385889},{"atl":[[990,1.44]],"id":52385889},{"atb":[[1.03,5.93],[1.04,148.17]],"id":52385914},{"atl":[[960,1.76]],"id":52385914},{"atb":[[1.02,136.76]],"id":52385883},{"atl":[[970,0.87]],"id":52385883},{"atb":[[1.01,323.93],[1.02,142.25]],"id":52385885},{"atl":[[980,2.01]],"id":52385885},{"atb":[[1.03,111.77]],"id":52385896},{"atl":[[980,1.69]],"id":52385896},{"atb":[[1.01,323.93],[1.03,121.93]],"id":52385890},{"atl":[[990,2.13]],"id":52385890},{"atb":[[1.01,323.93],[1.04,158.34]],"id":52385892},{"atl":[[970,1.54]],"id":52385892},{"atb":[[1.03,133.78],[1.02,8.9]],"id":52385904},{"atl":[[960,1.87]],"id":52385904},{"atb":[[1.02,8.9],[1.04,138.01]],"id":52385898},{"atl":[[970,1.71]],"id":52385898},{"atb":[[1.03,140.56]],"id":52385900},{"atl":[[990,1.27]],"id":52385900},{"atb":[[1.01,323.93],[1.03,77.05],[1.17,0]],"id":52385911},{"atl":[[990,0.87]],"id":52385911},{"atb":[[1.01,323.93],[1.02,127.85]],"id":52385913},{"atl":[[990,0.87]],"id":52385913},{"atb":[[1.03,5.93],[1.04,142.25]],"id":52385907},{"atl":[[990,1.79]],"id":52385907},{"atb":[[1.02,8.9],[1.04,105.84]],"id":52385886},{"atl":[[990,1.4]],"id":52385886},{"atb":[[1.01,323.93]],"id":52385919},{"atb":[[1.03,5.93]],"id":52385921},{"atb":[[1.01,323.93],[1.03,95.68]],"id":52385882},{"atl":[[970,0.87]],"id":52385882},{"atb":[[1.01,323.93],[1.04,110.07]],"id":52385884},{"atl":[[970,1.18]],"id":52385884},{"atb":[[1.03,5.93]],"id":52385917},{"atb":[[1.01,323.93],[1.02,138.86]],"id":52385897},{"atl":[[970,2.04]],"id":52385897},{"atb":[[1.01,323.93],[1.04,84.67]],"id":52385891},{"atl":[[980,1.84]],"id":52385891},{"atb":[[1.01,323.93],[1.03,153.25]],"id":52385893},{"atl":[[970,1.98]],"id":52385893},{"atb":[[1.01,323.93],[1.03,193.9]],"id":52385903},{"atl":[[980,1.21]],"id":52385903},{"atb":[[1.02,8.9],[1.04,141.4]],"id":52385905},{"atl":[[970,2.13]],"id":52385905},{"atb":[[1.03,83.83]],"id":52385899},{"atl":[[980,1.21]],"id":52385899}],"con":true,"img":false}]}
{"op":"mcm","clk":"11550620216","pt":1719500884328,"mc":[{"id":"1.230178175","rc":[{"atb":[[1.17,0]],"id":52385913}],"con":true,"img":false}]}
{"op":"mcm","clk":"11550635596","pt":1719501134495,"mc":[{"id":"1.230178175","rc":[{"atb":[[1.17,0]],"id":52385912}],"con":true,"img":false}]}
{"op":"mcm","clk":"11550653799","pt":1719501384513,"mc":[{"id":"1.230178175","rc":[{"atb":[[1.17,0]],"id":52385917}],"con":true,"img":false}]}
{"op":"mcm","clk":"11550672060","pt":1719501654633,"mc":[{"id":"1.230178175","rc":[{"atb":[[1.17,0]],"id":52385914}],"con":true,"img":false}]}
{"op":"mcm","clk":"11550687561","pt":1719501914732,"mc":[{"id":"1.230178175","rc":[{"atb":[[1.17,0]],"id":52385918}],"con":true,"img":false}]}
{"op":"mcm","clk":"11550703781","pt":1719502174841,"mc":[{"id":"1.230178175","rc":[{"atb":[[1.17,0]],"id":52385919}],"con":true,"img":false}]}
{"op":"mcm","clk":"11550723345","pt":1719502444918,"mc":[{"id":"1.230178175","rc":[{"atb":[[1.17,0]],"id":52385920}],"con":true,"img":false}]}
{"op":"mcm","clk":"11550740662","pt":1719502715088,"mc":[{"id":"1.230178175","rc":[{"atb":[[1.17,0]],"id":52385921}],"con":true,"img":false}]}
{"op":"mcm","clk":"11550806142","pt":1719503886545,"mc":[{"id":"1.230178175","rc":[{"atb":[[17.5,15.29]],"id":52385911}],"con":true,"img":false}]}
{"op":"mcm","clk":"11550806152","pt":1719503886752,"mc":[{"id":"1.230178175","rc":[{"atb":[[17.5,13.89]],"id":52385911}],"con":true,"img":false}]}
{"op":"mcm","clk":"11550806206","pt":1719503887675,"mc":[{"id":"1.230178175","rc":[{"atb":[[17.5,0]],"id":52385911}],"con":true,"img":false}]}
{"op":"mcm","clk":"11550809165","pt":1719503943363,"mc":[{"id":"1.230178175","rc":[{"atb":[[18,5]],"id":52385910},{"atb":[[16,6]],"id":52385912},{"atb":[[14,7]],"id":52385906},{"atb":[[11,9]],"id":52385918},{"atb":[[10,10]],"id":52385920},{"atb":[[15,6]],"id":52385889},{"atb":[[10,10]],"id":52385914},{"atb":[[20,5]],"id":52385883},{"atb":[[20,5]],"id":52385885},{"atb":[[16,6]],"id":52385896},{"atb":[[16,6]],"id":52385890},{"atb":[[16,6]],"id":52385892},{"atb":[[15,6]],"id":52385904},{"atb":[[11,9]],"id":52385898},{"atb":[[11,9]],"id":52385900},{"atb":[[17,6]],"id":52385911},{"atb":[[15,6]],"id":52385913},{"atb":[[12,8]],"id":52385907},{"atb":[[20,5]],"id":52385886},{"atb":[[11,9]],"id":52385919},{"atb":[[9,11]],"id":52385921},{"atb":[[17,6]],"id":52385882},{"atb":[[20,5]],"id":52385884},{"atb":[[14,7]],"id":52385917},{"atb":[[12,8]],"id":52385897},{"atb":[[16,6]],"id":52385891},{"atb":[[15,6]],"id":52385893},{"atb":[[16,6]],"id":52385903},{"atb":[[14,7]],"id":52385905},{"atb":[[14,7]],"id":52385899}],"con":true,"img":false}]}
{"op":"mcm","clk":"11550812075","pt":1719504003511,"mc":[{"id":"1.230178175","rc":[{"atb":[[15,0]],"id":52385913}],"con":true,"img":false}]}
{"op":"mcm","clk":"11550812079","pt":1719504003614,"mc":[{"id":"1.230178175","rc":[{"atb":[[14,6]],"id":52385913}],"con":true,"img":false}]}
{"op":"mcm","clk":"11550813743","pt":1719504030368,"mc":[{"id":"1.230178175","rc":[{"atb":[[1.03,5.93],[1.04,88.86]],"id":52385910},{"atl":[[980,1.59]],"id":52385910},{"atb":[[1.01,323.92],[1.04,153.18]],"id":52385912},{"atl":[[960,0.87]],"id":52385912},{"atb":[[1.02,149.39]],"id":52385906},{"atl":[[960,1.75]],"id":52385906},{"atb":[[1.03,5.93]],"id":52385918},{"atb":[[1.03,5.93]],"id":52385920},{"atb":[[1.02,125.69],[15,0]],"id":52385889},{"atl":[[990,1.44]],"id":52385889},{"atb":[[1.03,5.93],[1.04,148.1]],"id":52385914},{"atl":[[960,1.76]],"id":52385914},{"atb":[[1.02,136.69]],"id":52385883},{"atl":[[970,0.87]],"id":52385883},{"atb":[[1.01,323.92],[1.02,142.18]],"id":52385885},{"atl":[[980,2.01]],"id":52385885},{"atb":[[1.03,111.72]],"id":52385896},{"atl":[[980,1.69]],"id":52385896},{"atb":[[1.01,323.92],[1.03,121.86]],"id":52385890},{"atl":[[990,2.13]],"id":52385890},{"atb":[[1.01,323.92],[1.04,158.25]],"id":52385892},{"atl":[[970,1.54]],"id":52385892},{"atb":[[1.03,133.71],[1.02,8.9],[15,0]],"id":52385904},{"atl":[[960,1.87]],"id":52385904},{"atb":[[1.02,8.9],[1.04,137.94]],"id":52385898},{"atl":[[970,1.71]],"id":52385898},{"atb":[[1.03,140.49]],"id":52385900},{"atl":[[990,1.27]],"id":52385900},{"atb":[[1.01,323.92],[1.03,77.01]],"id":52385911},{"atl":[[990,0.87]],"id":52385911},{"atb":[[1.01,323.92],[1.02,127.79]],"id":52385913},{"atl":[[990,0.87]],"id":52385913},{"atb":[[1.03,5.93],[1.04,142.18]],"id":52385907},{"atl":[[990,1.79]],"id":52385907},{"atb":[[1.02,8.9],[1.04,105.78]],"id":52385886},{"atl":[[990,1.4]],"id":52385886},{"atb":[[1.01,323.92]],"id":52385919},{"atb":[[1.03,5.93]],"id":52385921},{"atb":[[1.01,323.92],[1.03,95.63]],"id":52385882},{"atl":[[970,0.87]],"id":52385882},{"atb":[[1.01,323.92],[1.04,110.02]],"id":52385884},{"atl":[[970,1.18]],"id":52385884},{"atb":[[1.03,5.93]],"id":52385917},{"atb":[[1.01,323.92],[1.02,138.79]],"id":52385897},{"atl":[[970,2.03]],"id":52385897},{"atb":[[1.01,323.92],[1.04,84.63]],"id":52385891},{"atl":[[980,1.84]],"id":52385891},{"atb":[[1.01,323.92],[1.03,153.18]],"id":52385893},{"atl":[[970,1.98]],"id":52385893},{"atb":[[1.01,323.92],[1.03,193.8]],"id":52385903},{"atl":[[980,1.21]],"id":52385903},{"atb":[[1.02,8.9],[1.04,141.33]],"id":52385905},{"atl":[[970,2.13]],"id":52385905},{"atb":[[1.03,83.79]],"id":52385899},{"atl":[[980,1.21]],"id":52385899}],"con":true,"img":false}]}
{"op":"mcm","clk":"11550813752","pt":1719504030469,"mc":[{"id":"1.230178175","rc":[{"atb":[[14,6]],"id":52385889},{"atb":[[14,6]],"id":52385904}],"con":true,"img":false}]}
{"op":"mcm","clk":"11550814974","pt":1719504051849,"mc":[{"id":"1.230178175","rc":[{"atb":[[23,9.61]],"id":52385896},{"atb":[[32,8.13]],"id":52385882}],"con":true,"img":false}]}
{"op":"mcm","clk":"11550815089","pt":1719504053771,"mc":[{"id":"1.230178175","rc":[{"atb":[[23,0]],"id":52385896},{"atb":[[32,0]],"id":52385882}],"con":true,"img":false}]}
{"op":"mcm","clk":"11550816424","pt":1719504078380,"mc":[{"id":"1.230178175","rc":[{"atb":[[14,0]],"id":52385917},{"atb":[[15,0]],"id":52385893}],"con":true,"img":false}]}
{"op":"mcm","clk":"11550816430","pt":1719504078484,"mc":[{"id":"1.230178175","rc":[{"atb":[[13,7]],"id":52385917},{"atb":[[14,6]],"id":52385893}],"con":true,"img":false}]}
{"op":"mcm","clk":"11550816740","pt":1719504084432,"mc":[{"id":"1.230178175","rc":[{"atb":[[14,0]],"id":52385906}],"con":true,"img":false}]}
{"op":"mcm","clk":"11550816745","pt":1719504084484,"mc":[{"id":"1.230178175","rc":[{"atb":[[13,7]],"id":52385906}],"con":true,"img":false}]}
{"op":"mcm","clk":"11550818799","pt":1719504125667,"mc":[{"id":"1.230178175","rc":[{"atl":[[50,5.17]],"id":52385906}],"con":true,"img":false}]}
{"op":"mcm","clk":"11550818806","pt":1719504125771,"mc":[{"id":"1.230178175","rc":[{"atl":[[30,7.82]],"id":52385918},{"atb":[[32,6.1]],"id":52385883},{"atl":[[95,3.02]],"id":52385892},{"atl":[[48,5.96]],"id":52385904},{"atl":[[55,5.02]],"id":52385913},{"atb":[[29,7.72]],"id":52385884},{"atl":[[38,6.27]],"id":52385917},{"atl":[[90,3.24]],"id":52385891}],"con":true,"img":false}]}
{"op":"mcm","clk":"11550818840","pt":1719504126254,"mc":[{"id":"1.230178175","rc":[{"atl":[[32,6.79]],"id":52385907}],"con":true,"img":false}]}
{"op":"mcm","clk":"11550818857","pt":1719504126452,"mc":[{"id":"1.230178175","rc":[{"atl":[[50,0]],"id":52385906},{"atl":[[30,0]],"id":52385918},{"atb":[[32,0]],"id":52385883},{"atl":[[95,0]],"id":52385892},{"atl":[[48,0]],"id":52385904},{"atl":[[55,0]],"id":52385913},{"atl":[[32,0]],"id":52385907},{"atb":[[29,0]],"id":52385884},{"atl":[[38,0]],"id":52385917},{"atl":[[90,0]],"id":52385891}],"con":true,"img":false}]}
{"op":"mcm","clk":"11550821694","pt":1719504180129,"mc":[{"id":"1.230178175","rc":[{"atb":[[7,16.67]],"id":52385905},{"atl":[[530,2]],"id":52385905}],"con":true,"img":false}]}
{"op":"mcm","clk":"11550821699","pt":1719504180235,"mc":[{"id":"1.230178175","rc":[{"atb":[[8.8,12.82]],"id":52385910},{"atl":[[600,2]],"id":52385910},{"atb":[[8,14.29]],"id":52385912},{"atl":[[560,2]],"id":52385912},{"atb":[[5.6,21.74]],"id":52385906},{"atl":[[490,2]],"id":52385906},{"atb":[[5.1,18]],"id":52385918},{"atl":[[450,2]],"id":52385918},{"atb":[[4.7,20]],"id":52385920},{"atl":[[410,2]],"id":52385920},{"atb":[[8.8,12.82]],"id":52385889},{"atl":[[600,2]],"id":52385889},{"atb":[[5,25]],"id":52385914},{"atl":[[440,2]],"id":52385914},{"atb":[[14.5,7.41]],"id":52385883},{"atl":[[840,2]],"id":52385883},{"atb":[[11.5,9.52]],"id":52385885},{"atl":[[780,2]],"id":52385885},{"atb":[[12,9.09]],"id":52385896},{"atl":[[790,2]],"id":52385896},{"atb":[[8.4,13.51]],"id":52385890},{"atl":[[580,2]],"id":52385890},{"atb":[[7.8,14.71]],"id":52385892},{"atl":[[550,2]],"id":52385892},{"atb":[[6,20]],"id":52385904},{"atl":[[510,2]],"id":52385904},{"atb":[[9,12.5]],"id":52385898},{"atl":[[610,2]],"id":52385898},{"atb":[[8.4,13.51]],"id":52385900},{"atl":[[580,2]],"id":52385900},{"atb":[[7,16.67]],"id":52385911},{"atl":[[530,2]],"id":52385911},{"atb":[[5.7,21.28]],"id":52385913},{"atl":[[490,2]],"id":52385913},{"atb":[[4.9,25.64]],"id":52385907},{"atl":[[430,2]],"id":52385907},{"atb":[[9.8,11.36]],"id":52385886},{"atl":[[670,2]],"id":52385886},{"atb":[[5.7,21.28]],"id":52385919},{"atl":[[490,2]],"id":52385919},{"atb":[[10,11.11]],"id":52385882},{"atl":[[730,2]],"id":52385882},{"atb":[[10,11.11]],"id":52385884},{"atl":[[730,2]],"id":52385884},{"atb":[[6.6,14]],"id":52385917},{"atl":[[520,2]],"id":52385917},{"atb":[[9.4,11.9]],"id":52385897},{"atl":[[650,2]],"id":52385897},{"atb":[[6.2,19.23]],"id":52385893},{"atl":[[510,2]],"id":52385893},{"atb":[[8,14.29]],"id":52385903},{"atl":[[560,2]],"id":52385903},{"atb":[[9.6,11.63]],"id":52385899},{"atl":[[660,2]],"id":52385899}],"con":true,"img":false}]}
{"op":"mcm","clk":"11550821702","pt":1719504180341,"mc":[{"id":"1.230178175","rc":[{"atb":[[4.7,22]],"id":52385921},{"atl":[[410,2]],"id":52385921},{"atb":[[6.8,17.24]],"id":52385891},{"atl":[[530,2]],"id":52385891}],"con":true,"img":false}]}
{"op":"mcm","clk":"11550822699","pt":1719504200856,"mc":[{"id":"1.230178175","rc":[{"atl":[[600,0],[590,2]],"id":52385910},{"atl":[[540,2],[560,0]],"id":52385912},{"atl":[[490,0],[480,2]],"id":52385906},{"atl":[[410,0],[400,2]],"id":52385920},{"atl":[[600,0],[590,2]],"id":52385889},{"atl":[[780,2]],"id":52385883},{"atl":[[760,2],[780,0]],"id":52385885},{"atl":[[700,2]],"id":52385896},{"atl":[[550,2],[580,0]],"id":52385890},{"atl":[[540,2],[550,0]],"id":52385892},{"atl":[[510,0],[500,2]],"id":52385904},{"atb":[[9,0],[9.2,12.2]],"id":52385898},{"atl":[[560,2],[610,0]],"id":52385898},{"atl":[[540,2],[580,0]],"id":52385900},{"atl":[[530,0],[520,2]],"id":52385911},{"atl":[[490,0],[480,2]],"id":52385913},{"atl":[[420,2]],"id":52385907},{"atl":[[670,0],[660,2]],"id":52385886},{"atl":[[470,2],[490,0]],"id":52385919},{"atl":[[730,0],[720,2]],"id":52385882},{"atl":[[730,0],[710,2]],"id":52385884},{"atl":[[520,0],[510,2]],"id":52385917},{"atb":[[9.8,11.36],[9.4,0]],"id":52385897},{"atl":[[590,2],[650,0]],"id":52385897},{"atl":[[530,0],[520,2]],"id":52385891},{"atl":[[510,0],[500,2]],"id":52385893},{"atl":[[560,0],[550,2]],"id":52385903},{"atl":[[510,2]],"id":52385905},{"atb":[[9.6,0],[10,11.11]],"id":52385899},{"atl":[[590,2],[660,0]],"id":52385899}],"con":true,"img":false}]}
{"op":"mcm","clk":"11550822705","pt":1719504200960,"mc":[{"id":"1.230178175","rc":[{"atb":[[10,11.11],[8.8,0]],"id":52385910},{"atb":[[5.6,0],[6.4,18.52]],"id":52385906},{"atb":[[5.1,0],[5.8,18]],"id":52385918},{"atb":[[5.2,20],[4.7,0]],"id":52385920},{"atb":[[10,11.11],[8.8,0]],"id":52385889},{"atb":[[5.6,21.74],[5,0]],"id":52385914},{"atl":[[840,0]],"id":52385883},{"atb":[[11.5,0],[14,7.69]],"id":52385885},{"atl":[[790,0]],"id":52385896},{"atb":[[9,12.5]],"id":52385892},{"atb":[[6,0],[7,16.67]],"id":52385904},{"atb":[[8,14.29],[7,0]],"id":52385911},{"atb":[[5.7,0],[6.6,17.86]],"id":52385913},{"atb":[[5.5,22.22],[4.9,0]],"id":52385907},{"atl":[[430,0]],"id":52385907},{"atb":[[5.3,22],[4.7,0]],"id":52385921},{"atb":[[10,0],[12,9.09]],"id":52385882},{"atb":[[7.6,14],[6.6,0]],"id":52385917},{"atb":[[8,14.29],[6.8,0]],"id":52385891},{"atb":[[8,0],[9.2,12.2]],"id":52385903},{"atl":[[530,0]],"id":52385905}],"con":true,"img":false}]}
{"op":"mcm","clk":"11550822709","pt":1719504201065,"mc":[{"id":"1.230178175","rc":[{"atl":[[540,0],[530,2]],"id":52385912},{"atl":[[700,0],[690,2]],"id":52385896},{"atb":[[7.8,0]],"id":52385892},{"atl":[[460,2]],"id":52385919}],"con":true,"img":false}]}
{"op":"mcm","clk":"11550822715","pt":1719504201169,"mc":[{"id":"1.230178175","rc":[{"atl":[[470,0]],"id":52385919}],"con":true,"img":false}]}
{"op":"mcm","clk":"11550823325","pt":1719504210775,"mc":[{"id":"1.230178175","rc":[{"atl":[[770,2]],"id":52385883},{"atl":[[560,0],[550,2]],"id":52385898},{"atl":[[540,0],[530,2]],"id":52385900},{"atl":[[590,0],[580,2]],"id":52385897}],"con":true,"img":false}]}
{"op":"mcm","clk":"11550823330","pt":1719504210876,"mc":[{"id":"1.230178175","rc":[{"atl":[[780,0]],"id":52385883}],"con":true,"img":false}]}
{"op":"mcm","clk":"11550823620","pt":1719504216495,"mc":[{"id":"1.230178175","rc":[{"atb":[[18,0]],"id":52385910},{"atb":[[17,0]],"id":52385882}],"con":true,"img":false}]}
{"op":"mcm","clk":"11550823629","pt":1719504216554,"mc":[{"id":"1.230178175","rc":[{"atb":[[16,5]],"id":52385910},{"atb":[[4.4,29.41],[15,6]],"id":52385882}],"con":true,"img":false}]}
{"op":"mcm","clk":"11550823635","pt":1719504216656,"mc":[{"id":"1.230178175","rc":[{"atb":[[4,33.33]],"id":52385910},{"atb":[[12,0]],"id":52385882}],"con":true,"img":false}]}
{"op":"mcm","clk":"11550823640","pt":1719504216758,"mc":[{"id":"1.230178175","rc":[{"atb":[[10,0]],"id":52385910}],"con":true,"img":false}]}
{"op":"mcm","clk":"11550823647","pt":1719504216862,"mc":[{"id":"1.230178175","rc":[{"atb":[[4,0],[10,11.11]],"id":52385910}],"con":true,"img":false}]}
{"op":"mcm","clk":"11550824073","pt":1719504225476,"mc":[{"id":"1.230178175","rc":[{"atb":[[13,0]],"id":52385906},{"atb":[[14,0]],"id":52385904},{"atb":[[14,0]],"id":52385913},{"atb":[[12,0]],"id":52385907},{"atb":[[16,0]],"id":52385891},{"atb":[[16,0]],"id":52385903},{"atb":[[14,0]],"id":52385905}],"con":true,"img":false}]}
{"op":"mcm","clk":"11550824080","pt":1719504225587,"mc":[{"id":"1.230178175","rc":[{"atb":[[3.1,47.62],[12,7]],"id":52385906},{"atb":[[12,6],[3.25,44.44],[7,0]],"id":52385904},{"atb":[[13,6],[3.15,46.51],[6.6,0]],"id":52385913},{"atb":[[2.9,52.63],[11,8]],"id":52385907},{"atb":[[8,0],[14,6],[3.5,40]],"id":52385891},{"atb":[[9.2,0],[3.8,35.71],[14,6]],"id":52385903},{"atb":[[13,7],[3.3,43.48]],"id":52385905}],"con":true,"img":false}]}
{"op":"mcm","clk":"11550824087","pt":1719504225683,"mc":[{"id":"1.230178175","rc":[{"atb":[[6.4,0]],"id":52385906},{"atb":[[7,16.67]],"id":52385904},{"atb":[[3.15,0],[6.6,17.86]],"id":52385913},{"atb":[[5.5,0]],"id":52385907},{"atb":[[8,14.29],[3.5,0]],"id":52385891},{"atb":[[9.2,12.2],[3.8,0]],"id":52385903},{"atb":[[7.2,16.13],[7,0],[3.3,0]],"id":52385905}],"con":true,"img":false}]}
{"op":"mcm","clk":"11550824095","pt":1719504225787,"mc":[{"id":"1.230178175","rc":[{"atb":[[6.4,18.52]],"id":52385906},{"atb":[[3.25,0]],"id":52385904},{"atb":[[2.9,0],[5.5,22.22]],"id":52385907}],"con":true,"img":false}]}
{"op":"mcm","clk":"11550824099","pt":1719504225889,"mc":[{"id":"1.230178175","rc":[{"atb":[[3.1,0]],"id":52385906}],"con":true,"img":false}]}
{"op":"mcm","clk":"11550824126","pt":1719504226405,"mc":[{"id":"1.230178175","rc":[{"atb":[[12,9.09],[4.4,0]],"id":52385882}],"con":true,"img":false}]}
{"op":"mcm","clk":"11550829070","pt":1719504320936,"mc":[{"id":"1.230178175","rc":[{"atl":[[590,0],[610,2]],"id":52385910},{"atl":[[530,0],[550,2]],"id":52385912},{"atl":[[480,0],[490,2]],"id":52385906},{"atb":[[5.8,0],[5.2,23.81]],"id":52385918},{"atb":[[10,0],[8.8,12.82]],"id":52385889},{"atl":[[590,0],[610,2]],"id":52385889},{"atl":[[440,0],[450,2]],"id":52385914},{"atl":[[770,0],[810,2]],"id":52385883},{"atl":[[760,0],[800,2]],"id":52385885},{"atb":[[10,11.11],[12,0]],"id":52385896},{"atl":[[690,0],[720,2]],"id":52385896},{"atl":[[550,0],[560,2]],"id":52385890},{"atl":[[540,0],[560,2]],"id":52385892},{"atl":[[500,0],[510,2]],"id":52385904},{"atb":[[9.2,0],[8.2,13.89]],"id":52385898},{"atl":[[550,0],[570,2]],"id":52385898},{"atb":[[7.4,15.62],[8.4,0]],"id":52385900},{"atl":[[530,0],[540,2]],"id":52385900},{"atl":[[520,0],[540,2]],"id":52385911},{"atl":[[480,0],[500,2]],"id":52385913},{"atl":[[420,0],[430,2]],"id":52385907},{"atl":[[660,0],[690,2]],"id":52385886},{"atb":[[10.5,10.53],[12,0]],"id":52385882},{"atl":[[720,0],[750,2]],"id":52385882},{"atl":[[710,0],[750,2]],"id":52385884},{"atb":[[9.8,0],[8.8,12.82]],"id":52385897},{"atl":[[580,0],[600,2]],"id":52385897},{"atl":[[520,0],[530,2]],"id":52385891},{"atl":[[500,0],[510,2]],"id":52385893},{"atl":[[550,0],[570,2]],"id":52385903},{"atl":[[520,2],[510,0]],"id":52385905},{"atb":[[10,0],[8.8,12.82]],"id":52385899},{"atl":[[590,0],[600,2]],"id":52385899}],"con":true,"img":false}]}
{"op":"mcm","clk":"11550834311","pt":1719504426964,"mc":[{"id":"1.230178175","rc":[{"atb":[[9.4,11.9]],"id":52385889},{"atb":[[10,0],[11,10]],"id":52385896},{"atb":[[8.6,13.16],[8.2,0]],"id":52385898},{"atb":[[9.2,12.2],[8.8,0]],"id":52385897},{"atb":[[8.8,0],[9.4,11.9]],"id":52385899}],"con":true,"img":false}]}
{"op":"mcm","clk":"11550834317","pt":1719504427169,"mc":[{"id":"1.230178175","rc":[{"atb":[[8.8,0]],"id":52385889}],"con":true,"img":false}]}
{"op":"mcm","clk":"11550835132","pt":1719504441783,"mc":[{"id":"1.230178175","rc":[{"atb":[[12,0]],"id":52385906}],"con":true,"img":false}]}
{"op":"mcm","clk":"11550835139","pt":1719504441888,"mc":[{"id":"1.230178175","rc":[{"atb":[[11,7],[3,50]],"id":52385906}],"con":true,"img":false}]}
{"op":"mcm","clk":"11550835146","pt":1719504441990,"mc":[{"id":"1.230178175","rc":[{"atb":[[6.4,0],[6,20]],"id":52385906}],"con":true,"img":false}]}
{"op":"mcm","clk":"11550835152","pt":1719504442094,"mc":[{"id":"1.230178175","rc":[{"atb":[[3,0]],"id":52385906}],"con":true,"img":false}]}
{"op":"mcm","clk":"11550835998","pt":1719504458302,"mc":[{"id":"1.230178175","rc":[{"atb":[[8.6,4.9]],"id":52385890},{"atl":[[46,2.52]],"id":52385890},{"atb":[[11.5,3.7]],"id":52385898},{"atl":[[48,2.56]],"id":52385898},{"atb":[[12,12.54]],"id":52385897},{"atl":[[60,3]],"id":52385897},{"atb":[[7.4,6.75]],"id":52385905},{"atl":[[38,2.6]],"id":52385905}],"con":true,"img":false}]}
{"op":"mcm","clk":"11550836003","pt":1719504458405,"mc":[{"id":"1.230178175","rc":[{"atl":[[560,0],[160,2]],"id":52385890},{"atl":[[570,0],[170,2]],"id":52385898},{"atl":[[600,0],[200,2]],"id":52385897},{"atl":[[520,0],[120,2]],"id":52385905}],"con":true,"img":false}]}
{"op":"mcm","clk":"11550836020","pt":1719504458713,"mc":[{"id":"1.230178175","rc":[{"atb":[[11,0]],"id":52385898}],"con":true,"img":false}]}
{"op":"mcm","clk":"11550836025","pt":1719504458816,"mc":[{"id":"1.230178175","rc":[{"atb":[[13,9]],"id":52385898}],"con":true,"img":false}]}
{"op":"mcm","clk":"11550836411","pt":1719504465772,"mc":[{"id":"1.230178175","rc":[{"atb":[[14,0]],"id":52385889},{"atb":[[16,0]],"id":52385892},{"atb":[[12,0]],"id":52385904},{"atb":[[14,0]],"id":52385891},{"atb":[[14,0]],"id":52385893}],"con":true,"img":false}]}
{"op":"mcm","clk":"11550836418","pt":1719504465825,"mc":[{"id":"1.230178175","rc":[{"atb":[[13,6]],"id":52385889},{"atb":[[14,6]],"id":52385892},{"atb":[[11,6]],"id":52385904},{"atb":[[12,6]],"id":52385891},{"atb":[[13,6]],"id":52385893}],"con":true,"img":false}]}
{"op":"mcm","clk":"11550836424","pt":1719504465926,"mc":[{"id":"1.230178175","rc":[{"atb":[[3.85,35.09],[9.4,0]],"id":52385889},{"atb":[[3.6,38.46],[9,0]],"id":52385892},{"atb":[[3.15,46.51]],"id":52385904},{"atb":[[8,0],[3.35,42.55]],"id":52385891},{"atb":[[6.2,0],[3.15,46.51]],"id":52385893}],"con":true,"img":false}]}
{"op":"mcm","clk":"11550836430","pt":1719504466029,"mc":[{"id":"1.230178175","rc":[{"atb":[[3.85,0],[9.4,11.9]],"id":52385889},{"atb":[[3.6,0],[8.4,13.51]],"id":52385892},{"atb":[[3.15,0],[7,0],[6.6,17.86]],"id":52385904},{"atb":[[3.35,0],[7.4,15.62]],"id":52385891},{"atb":[[3.15,0],[6.6,17.86]],"id":52385893}],"con":true,"img":false}]}
{"op":"mcm","clk":"11550836735","pt":1719504471700,"mc":[{"id":"1.230178175","rc":[{"atb":[[11,0]],"id":52385918},{"atb":[[10,0]],"id":52385920},{"atb":[[10,0]],"id":52385914},{"atb":[[20,0]],"id":52385883},{"atb":[[20,0]],"id":52385885},{"atb":[[16,0]],"id":52385896},{"atb":[[11,0]],"id":52385900},{"atb":[[11,0]],"id":52385919},{"atb":[[9,0]],"id":52385921},{"atb":[[12,4.54]],"id":52385897},{"atb":[[14,0]],"id":52385899}],"con":true,"img":false}]}
{"op":"mcm","clk":"11550836739","pt":1719504471803,"mc":[{"id":"1.230178175","rc":[{"atb":[[12,9]],"id":52385918},{"atb":[[11,10]],"id":52385920},{"atb":[[11,10]],"id":52385914},{"atb":[[24,5]],"id":52385883},{"atb":[[24,5]],"id":52385885},{"atb":[[20,6]],"id":52385896},{"atb":[[3.45,40.82],[15,9]],"id":52385900},{"atb":[[16,9]],"id":52385919},{"atb":[[11,11]],"id":52385921},{"atb":[[14,8]],"id":52385897},{"atb":[[18,7]],"id":52385899}],"con":true,"img":false}]}
{"op":"mcm","clk":"11550836744","pt":1719504471911,"mc":[{"id":"1.230178175","rc":[{"atb":[[2.88,53.19],[5.2,0]],"id":52385918},{"atb":[[2.8,55.56],[5.2,0]],"id":52385920},{"atb":[[5.6,0],[2.86,53.76]],"id":52385914},{"atb":[[4.8,26.32],[14.5,0]],"id":52385883},{"atb":[[4.6,27.78],[14,0]],"id":52385885},{"atb":[[11,0],[4.2,31.25]],"id":52385896},{"atb":[[7.4,0]],"id":52385900},{"atb":[[5.7,0],[2.94,51.55]],"id":52385919},{"atb":[[2.8,55.56],[5.3,0]],"id":52385921},{"atb":[[3.85,35.09],[9.4,0]],"id":52385899}],"con":true,"img":false}]}
{"op":"mcm","clk":"11550836899","pt":1719504474709,"mc":[{"id":"1.230178175","rc":[{"atb":[[20,0]],"id":52385884}],"con":true,"img":false}]}
{"op":"mcm","clk":"11550836904","pt":1719504474812,"mc":[{"id":"1.230178175","rc":[{"atb":[[10,0],[24,5],[4.2,31.25]],"id":52385884}],"con":true,"img":false}]}
{"op":"mcm","clk":"11550836911","pt":1719504474915,"mc":[{"id":"1.230178175","rc":[{"atb":[[11,10],[4.2,0]],"id":52385884}],"con":true,"img":false}]}
{"op":"mcm","clk":"11550836953","pt":1719504475742,"mc":[{"id":"1.230178175","rc":[{"atb":[[14,0]],"id":52385892}],"con":true,"img":false}]}
{"op":"mcm","clk":"11550836960","pt":1719504475844,"mc":[{"id":"1.230178175","rc":[{"atb":[[3.6,38.46],[13,6],[8.4,0]],"id":52385892}],"con":true,"img":false}]}
{"op":"mcm","clk":"11550836972","pt":1719504476008,"mc":[{"id":"1.230178175","rc":[{"atb":[[3.6,0],[8.4,13.51]],"id":52385892}],"con":true,"img":false}]}
{"op":"mcm","clk":"11550837121","pt":1719504479025,"mc":[{"id":"1.230178175","rc":[{"atb":[[3.45,0],[7.8,14.71]],"id":52385900}],"con":true,"img":false}]}
{"op":"mcm","clk":"11550837127","pt":1719504479132,"mc":[{"id":"1.230178175","rc":[{"atb":[[2.88,0],[5.4,22.73]],"id":52385918},{"atb":[[2.8,0],[5,25]],"id":52385920},{"atb":[[2.86,0],[5.3,23.26]],"id":52385914},{"atb":[[4.8,0],[14,7.69]],"id":52385883},{"atb":[[13,8.33]],"id":52385885},{"atb":[[11,10],[4.2,0]],"id":52385896},{"atb":[[5.7,21.28],[2.94,0]],"id":52385919},{"atb":[[5,25]],"id":52385921},{"atb":[[3.85,0],[9.4,11.9]],"id":52385899}],"con":true,"img":false}]}
{"op":"mcm","clk":"11550837131","pt":1719504479236,"mc":[{"id":"1.230178175","rc":[{"atb":[[4.6,0]],"id":52385885},{"atb":[[2.8,0]],"id":52385921}],"con":true,"img":false}]}
{"op":"mcm","clk":"11550841919","pt":1719504483141,"mc":[{"id":"1.230178175","rc":[{"atb":[[1.31,100]],"id":52385889},{"atb":[[1.31,100]],"id":52385883},{"atb":[[1.31,100]],"id":52385896},{"atb":[[1.31,100]],"id":52385890},{"atb":[[1.31,100]],"id":52385892},{"atb":[[1.31,100]],"id":52385904},{"atb":[[1.31,100]],"id":52385898},{"atb":[[1.31,100]],"id":52385886},{"atb":[[1.31,100]],"id":52385882},{"atb":[[1.31,100]],"id":52385884},{"atb":[[1.31,100]],"id":52385897},{"atb":[[1.31,100]],"id":52385891},{"atb":[[1.31,100]],"id":52385893},{"atb":[[1.31,100]],"id":52385905},{"atb":[[1.31,100]],"id":52385899}],"con":true,"img":false}]}
{"op":"mcm","clk":"11550841927","pt":1719504483244,"mc":[{"id":"1.230178175","rc":[{"atb":[[1.31,100]],"id":52385885},{"atb":[[1.31,100]],"id":52385900}],"con":true,"img":false}]}
{"op":"mcm","clk":"11550841933","pt":1719504483349,"mc":[{"id":"1.230178175","rc":[{"atb":[[1.31,100]],"id":52385910},{"atb":[[1.31,100]],"id":52385912},{"atb":[[1.31,100]],"id":52385906},{"atb":[[1.31,100]],"id":52385920},{"atb":[[1.31,100]],"id":52385914},{"atb":[[1.31,100]],"id":52385911},{"atb":[[1.31,100]],"id":52385913},{"atb":[[1.31,100]],"id":52385919},{"atb":[[1.31,100]],"id":52385921},{"atb":[[1.31,100]],"id":52385917},{"atb":[[1.31,100]],"id":52385903}],"con":true,"img":false}]}
{"op":"mcm","clk":"11550841941","pt":1719504483450,"mc":[{"id":"1.230178175","rc":[{"atb":[[1.31,100]],"id":52385907}],"con":true,"img":false}]}
{"op":"mcm","clk":"11550841949","pt":1719504483554,"mc":[{"id":"1.230178175","rc":[{"atb":[[1.31,100]],"id":52385918}],"con":true,"img":false}]}
{"op":"mcm","clk":"11550841962","pt":1719504483718,"mc":[{"id":"1.230178175","rc":[{"atb":[[20,0]],"id":52385886}],"con":true,"img":false}]}
{"op":"mcm","clk":"11550841970","pt":1719504483834,"mc":[{"id":"1.230178175","rc":[{"atb":[[24,5]],"id":52385886}],"con":true,"img":false}]}
{"op":"mcm","clk":"11550841979","pt":1719504483922,"mc":[{"id":"1.230178175","rc":[{"atb":[[4.1,32.26],[9.8,0]],"id":52385886}],"con":true,"img":false}]}
{"op":"mcm","clk":"11550842064","pt":1719504485536,"mc":[{"id":"1.230178175","rc":[{"atb":[[11.5,0]],"id":52385898},{"atl":[[48,0]],"id":52385898},{"atb":[[12,0]],"id":52385897},{"atl":[[60,0]],"id":52385897},{"atl":[[38,0]],"id":52385905}],"con":true,"img":false}]}
{"op":"mcm","clk":"11550842072","pt":1719504485640,"mc":[{"id":"1.230178175","rc":[{"atl":[[570,2],[170,0]],"id":52385898},{"atl":[[600,2],[200,0]],"id":52385897},{"atl":[[520,2],[120,0]],"id":52385905}],"con":true,"img":false}]}
{"op":"mcm","clk":"11550842078","pt":1719504485753,"mc":[{"id":"1.230178175","rc":[{"atb":[[9.8,5.3]],"id":52385898},{"atl":[[34,2]],"id":52385898},{"atb":[[14.5,4.1]],"id":52385897},{"atl":[[44,2]],"id":52385897},{"atl":[[32,3.28]],"id":52385905}],"con":true,"img":false}]}
{"op":"mcm","clk":"11550842087","pt":1719504485859,"mc":[{"id":"1.230178175","rc":[{"atl":[[170,2]],"id":52385898},{"atl":[[200,2]],"id":52385897},{"atl":[[520,0],[120,2]],"id":52385905}],"con":true,"img":false}]}
{"op":"mcm","clk":"11550842094","pt":1719504485954,"mc":[{"id":"1.230178175","rc":[{"atl":[[570,0]],"id":52385898},{"atl":[[600,0]],"id":52385897}],"con":true,"img":false}]}
{"op":"mcm","clk":"11550842302","pt":1719504489763,"mc":[{"id":"1.230178175","rc":[{"atb":[[17,0]],"id":52385911}],"con":true,"img":false}]}
{"op":"mcm","clk":"11550842308","pt":1719504489863,"mc":[{"id":"1.230178175","rc":[{"atb":[[15,6]],"id":52385911}],"con":true,"img":false}]}
{"op":"mcm","clk":"11550842316","pt":1719504489965,"mc":[{"id":"1.230178175","rc":[{"atb":[[8,0],[3.4,41.67]],"id":52385911}],"con":true,"img":false}]}
{"op":"mcm","clk":"11550842322","pt":1719504490070,"mc":[{"id":"1.230178175","rc":[{"atb":[[3.4,0],[7.6,15.15]],"id":52385911}],"con":true,"img":false}]}
{"op":"mcm","clk":"11550842369","pt":1719504491055,"mc":[{"id":"1.230178175","rc":[{"atb":[[10.5,10.53],[4.1,0]],"id":52385886}],"con":true,"img":false}]}
{"op":"mcm","clk":"11550842664","pt":1719504496255,"mc":[{"id":"1.230178175","rc":[{"atb":[[6,2]],"id":52385910},{"atb":[[6,2]],"id":52385912},{"atb":[[6,22]],"id":52385906},{"atb":[[6,2]],"id":52385918},{"atb":[[6,2]],"id":52385920},{"atb":[[6,2]],"id":52385889},{"atb":[[6,2]],"id":52385914},{"atb":[[6,2]],"id":52385883},{"atb":[[6,2]],"id":52385885},{"atb":[[6,2]],"id":52385896},{"atb":[[6,2]],"id":52385890},{"atb":[[6,2]],"id":52385892},{"atb":[[6,2]],"id":52385904},{"atb":[[6,2]],"id":52385898},{"atb":[[6,2]],"id":52385900},{"atb":[[6,2]],"id":52385911},{"atb":[[6,2]],"id":52385913},{"atb":[[6,2]],"id":52385907},{"atb":[[6,2]],"id":52385886},{"atb":[[6,2]],"id":52385919},{"atb":[[6,2]],"id":52385921},{"atb":[[6,2]],"id":52385882},{"atb":[[6,2]],"id":52385884},{"atb":[[6,2]],"id":52385917},{"atb":[[6,2]],"id":52385897},{"atb":[[6,2]],"id":52385891},{"atb":[[6,2]],"id":52385893},{"atb":[[6,2]],"id":52385903},{"atb":[[6,2]],"id":52385905},{"atb":[[6,2]],"id":52385899}],"con":true,"img":false}]}
{"op":"mcm","clk":"11550843565","pt":1719504512589,"mc":[{"id":"1.230178175","rc":[{"atl":[[46,0]],"id":52385890},{"atb":[[9.8,0]],"id":52385898},{"atl":[[34,0]],"id":52385898},{"atl":[[44,0]],"id":52385897},{"atl":[[32,0]],"id":52385905}],"con":true,"img":false}]}
{"op":"mcm","clk":"11550843570","pt":1719504512692,"mc":[{"id":"1.230178175","rc":[{"atl":[[560,2],[55,2]],"id":52385890},{"atb":[[13.5,4]],"id":52385898},{"atl":[[38,2],[170,0]],"id":52385898},{"atl":[[48,2.1]],"id":52385897},{"atl":[[36,3.1],[120,0]],"id":52385905}],"con":true,"img":false}]}
{"op":"mcm","clk":"11550843577","pt":1719504512752,"mc":[{"id":"1.230178175","rc":[{"atl":[[160,0]],"id":52385890},{"atl":[[570,2]],"id":52385898},{"atl":[[600,2],[200,0]],"id":52385897},{"atl":[[520,2]],"id":52385905}],"con":true,"img":false}]}
{"op":"mcm","clk":"11550843584","pt":1719504512851,"mc":[{"id":"1.230178175","rc":[{"atl":[[570,0],[170,2]],"id":52385898}],"con":true,"img":false}]}
{"op":"mcm","clk":"11550843976","pt":1719504519479,"mc":[{"id":"1.230178175","rc":[{"atl":[[160,2]],"id":52385890}],"con":true,"img":false}]}
{"op":"mcm","clk":"11550843982","pt":1719504519589,"mc":[{"id":"1.230178175","rc":[{"atl":[[560,0]],"id":52385890},{"atl":[[600,0],[200,2]],"id":52385897},{"atl":[[520,0],[120,2]],"id":52385905}],"con":true,"img":false}]}
{"op":"mcm","clk":"11550845032","pt":1719504537715,"mc":[{"id":"1.230178175","rc":[{"atb":[[16,0]],"id":52385912},{"atb":[[13,0]],"id":52385898}],"con":true,"img":false}]}
{"op":"mcm","clk":"11550845040","pt":1719504537821,"mc":[{"id":"1.230178175","rc":[{"atb":[[8,0],[18,6],[6,22]],"id":52385912},{"atb":[[14,9]],"id":52385898}],"con":true,"img":false}]}
{"op":"mcm","clk":"11550845046","pt":1719504537924,"mc":[{"id":"1.230178175","rc":[{"atb":[[8,14.29],[6,2]],"id":52385912}],"con":true,"img":false}]}
{"op":"mcm","clk":"11550845150","pt":1719504539631,"mc":[{"id":"1.230178175","rc":[{"atl":[[55,0]],"id":52385890},{"atb":[[13.5,0]],"id":52385898},{"atl":[[38,0]],"id":52385898},{"atl":[[36,0]],"id":52385905}],"con":true,"img":false}]}
{"op":"mcm","clk":"11550845160","pt":1719504539736,"mc":[{"id":"1.230178175","rc":[{"atl":[[560,2],[160,0]],"id":52385890},{"atl":[[570,2],[170,0]],"id":52385898},{"atl":[[520,2],[120,0]],"id":52385905}],"con":true,"img":false}]}
{"op":"mcm","clk":"11550845167","pt":1719504539795,"mc":[{"id":"1.230178175","rc":[{"atl":[[38,3.2]],"id":52385890},{"atb":[[14.5,3]],"id":52385898},{"atl":[[44,2.2]],"id":52385898},{"atl":[[42,3.2]],"id":52385905}],"con":true,"img":false}]}
{"op":"mcm","clk":"11550845177","pt":1719504539901,"mc":[{"id":"1.230178175","rc":[{"atl":[[560,0],[160,2]],"id":52385890},{"atl":[[570,0],[170,2]],"id":52385898},{"atl":[[520,0],[120,2]],"id":52385905}],"con":true,"img":false}]}
{"op":"mcm","clk":"11550845967","pt":1719504552639,"mc":[{"id":"1.230178175","rc":[{"atb":[[14,0]],"id":52385898},{"atb":[[12,0]],"id":52385891}],"con":true,"img":false}]}
{"op":"mcm","clk":"11550845975","pt":1719504552741,"mc":[{"id":"1.230178175","rc":[{"atb":[[13,9]],"id":52385898},{"atb":[[11,6]],"id":52385891}],"con":true,"img":false}]}
{"op":"mcm","clk":"11550845981","pt":1719504552844,"mc":[{"id":"1.230178175","rc":[{"atb":[[7.4,0],[6,22]],"id":52385891}],"con":true,"img":false}]}
{"op":"mcm","clk":"11550845990","pt":1719504552902,"mc":[{"id":"1.230178175","rc":[{"atb":[[7.4,12],[6,2]],"id":52385891}],"con":true,"img":false}]}
{"op":"mcm","clk":"11550846728","pt":1719504566835,"mc":[{"id":"1.230178175","rc":[{"atb":[[7.4,0]],"id":52385905}],"con":true,"img":false}]}
{"op":"mcm","clk":"11550846735","pt":1719504566948,"mc":[{"id":"1.230178175","rc":[{"atb":[[11.5,4]],"id":52385920},{"atl":[[60,2.8]],"id":52385920},{"atb":[[15.5,3.8]],"id":52385900},{"atl":[[42,3.2]],"id":52385900},{"atb":[[11.5,5]],"id":52385907},{"atl":[[28,3]],"id":52385907},{"atb":[[16.5,4.87]],"id":52385919},{"atl":[[46,2.79]],"id":52385919},{"atb":[[13.5,4]],"id":52385905}],"con":true,"img":false}]}
{"op":"mcm","clk":"11550846742","pt":1719504567040,"mc":[{"id":"1.230178175","rc":[{"atl":[[90,2]],"id":52385919}],"con":true,"img":false}]}
{"op":"mcm","clk":"11550846747","pt":1719504567143,"mc":[{"id":"1.230178175","rc":[{"atl":[[60,4.8]],"id":52385920},{"atl":[[540,0],[140,2]],"id":52385900},{"atl":[[65,2]],"id":52385907}],"con":true,"img":false}]}
{"op":"mcm","clk":"11550846755","pt":1719504567246,"mc":[{"id":"1.230178175","rc":[{"atl":[[400,0]],"id":52385920},{"atl":[[430,0]],"id":52385907},{"atl":[[460,0]],"id":52385919}],"con":true,"img":false}]}
{"op":"mcm","clk":"11550846780","pt":1719504567764,"mc":[{"id":"1.230178175","rc":[{"atb":[[11,0]],"id":52385920},{"atb":[[13,0]],"id":52385898},{"atb":[[11,0]],"id":52385907},{"atb":[[16,0]],"id":52385919},{"atb":[[24,0]],"id":52385884},{"atb":[[13,0]],"id":52385905}],"con":true,"img":false}]}
{"op":"mcm","clk":"11550846786","pt":1719504567867,"mc":[{"id":"1.230178175","rc":[{"atb":[[14,10]],"id":52385920},{"atb":[[14,9]],"id":52385898},{"atb":[[13,8]],"id":52385907},{"atb":[[18,9]],"id":52385919},{"atb":[[20,5],[11,0],[6,22]],"id":52385884},{"atb":[[14,7]],"id":52385905}],"con":true,"img":false}]}
{"op":"mcm","clk":"11550847016","pt":1719504572179,"mc":[{"id":"1.230178175","rc":[{"atb":[[16.5,8],[10,0],[23,5],[27,2.5]],"id":52385910},{"atl":[[150,5],[600,1],[610,0],[730,2],[110,2.5]],"id":52385910},{"atb":[[8,0],[10.5,5],[12.5,2.5]],"id":52385912},{"atl":[[550,0],[75,5],[55,2.5],[510,2]],"id":52385912},{"atb":[[10.5,5],[11.5,8],[6,2],[12.5,2.5]],"id":52385906},{"atl":[[38,2.5],[46,5],[490,0],[480,3.25]],"id":52385906},{"atb":[[11.5,2.5],[12.5,22],[9.8,5],[3.05,49.68],[5.4,0]],"id":52385918},{"atl":[[38,2.5],[46,5],[440,1.37],[450,0]],"id":52385918},{"atb":[[3.2,45.45],[5,0],[9.2,2.5],[8.4,5]],"id":52385920},{"atl":[[65,2],[36,5],[29,2.5],[60,2.8]],"id":52385920},{"atb":[[17.5,2.5],[10,11.11],[13.5,8],[9.4,0],[15.5,5]],"id":52385889},{"atl":[[560,2],[600,1],[610,0],[85,2.5],[110,5]],"id":52385889},{"atb":[[2.32,75.76],[10.5,2.5],[11.5,8],[9.4,5]],"id":52385914},{"atl":[[42,2.5],[50,5],[440,1.37]],"id":52385914},{"atb":[[25,8],[14,0]],"id":52385883},{"atl":[[760,2],[810,0],[800,0.75]],"id":52385883},{"atb":[[36,2.5],[25,8.04],[13,0],[3.25,44.44],[29,5]],"id":52385885},{"atl":[[160,2.5],[790,0.76],[800,0],[200,5],[850,2]],"id":52385885},{"atb":[[11,0]],"id":52385896},{"atl":[[720,0]],"id":52385896},{"atb":[[16,22.2],[10.5,5],[12.5,2.5],[7,12],[8.4,0]],"id":52385890},{"atl":[[36,16.2],[160,0],[44,2.5],[55,5],[110,2]],"id":52385890},{"atb":[[11.5,5],[13.5,10.5],[8.4,0],[9.4,11.9]],"id":52385892},{"atl":[[540,2],[560,0],[550,1.09],[75,5],[55,2.5]],"id":52385892},{"atb":[[9.6,5],[11,8.5],[6.6,0]],"id":52385904},{"atl":[[36,2.5],[44,5],[470,2],[510,0]],"id":52385904},{"atb":[[9.2,2.5],[8.4,5],[15,10.4],[8.6,0],[7,16.67]],"id":52385898},{"atl":[[36,2.5],[170,0],[42,10.4],[44,7.2],[110,2]],"id":52385898},{"atb":[[9,12.5],[10,2.5],[9.2,5],[7.8,0],[16,14]],"id":52385900},{"atl":[[140,0],[38,2.5],[40,14],[46,5],[110,2]],"id":52385900},{"atb":[[7.6,0],[12,5],[3.25,44.44],[14,2.5],[15.5,8]],"id":52385911},{"atl":[[540,0],[530,1.13],[560,2],[80,5],[60,2.5]],"id":52385911},{"atb":[[3,50],[13,11],[13.5,8],[6.6,0],[15,2.5]],"id":52385913},{"atl":[[65,5],[520,2],[48,2.5],[490,1.23],[500,0]],"id":52385913},{"atb":[[5.5,0],[13,18],[7.8,2.5],[7,18]],"id":52385907},{"atl":[[65,0],[36,5],[46,2.22],[27,10],[29,2.5]],"id":52385907},{"atb":[[34,2.5],[10.5,0],[1.88,105.79],[25,8],[28,5]],"id":52385886},{"atl":[[160,5],[690,0],[680,0.88],[750,2],[120,2.5]],"id":52385886},{"atb":[[5.7,0]],"id":52385919},{"atl":[[90,0]],"id":52385919},{"atb":[[9.6,5],[5,0],[2.06,94.34],[11,13.5],[11.5,26]],"id":52385921},{"atl":[[34,2.5],[42,5],[400,1.5]],"id":52385921},{"atb":[[10.5,0],[24,5],[28,2.5]],"id":52385882},{"atl":[[130,2.5],[170,5],[750,0]],"id":52385882},{"atb":[[21,8]],"id":52385884},{"atl":[[660,2],[750,0],[740,0.81]],"id":52385884},{"atb":[[17,2.5],[7.6,0],[13.5,18],[15,5]],"id":52385917},{"atl":[[65,2.5],[85,5],[500,1.2]],"id":52385917},{"atb":[[9.6,5],[9.2,0],[11,2.5],[15,12.4]],"id":52385897},{"atl":[[40,2.5],[46,12.4],[48,7.1],[200,0]],"id":52385897},{"atb":[[10.5,5],[7.4,0],[11.5,8],[12.5,2.5]],"id":52385891},{"atl":[[530,0],[520,1.16],[42,2.5],[50,5],[500,2]],"id":52385891},{"atb":[[11.5,2.5],[9.8,5],[13.5,8],[6.6,0]],"id":52385893},{"atl":[[42,2.5],[50,5],[510,0],[500,3.2]],"id":52385893},{"atb":[[16.5,2.5],[9.2,0],[7.8,14.71],[14.5,13]],"id":52385903},{"atl":[[570,0],[560,3.07],[80,5],[60,2.5]],"id":52385903},{"atb":[[8,5],[7.2,0],[8.8,2.5]],"id":52385905},{"atl":[[34,2.5],[42,8.2],[85,2],[120,0]],"id":52385905},{"atb":[[18.5,8],[11.5,9.52],[12,5],[14,2.5],[9.4,0]],"id":52385899},{"atl":[[600,0],[75,5],[590,1.02],[55,2.5]],"id":52385899}],"con":true,"img":false}]}
{"op":"mcm","clk":"11550847021","pt":1719504572245,"mc":[{"id":"1.230178175","rc":[{"atb":[[18.5,8],[6.8,17.24]],"id":52385912},{"atl":[[540,1.11]],"id":52385912},{"atb":[[8,14.29]],"id":52385906},{"atl":[[440,3.37]],"id":52385918},{"atb":[[14,27.6]],"id":52385920},{"atl":[[55,11.11]],"id":52385920},{"atb":[[5.3,0]],"id":52385914},{"atl":[[450,0],[500,2]],"id":52385914},{"atb":[[18.5,5.71],[26,5],[30,2.5]],"id":52385883},{"atl":[[160,5],[120,2.5]],"id":52385883},{"atb":[[18.5,5],[21,10.5],[14,7.69]],"id":52385896},{"atl":[[75,2.5],[620,2],[710,0.85],[95,5]],"id":52385896},{"atb":[[11.5,8],[7.8,12]],"id":52385904},{"atl":[[500,1.2]],"id":52385904},{"atb":[[7.2,13.87],[18,20.16],[10,2.5],[9.2,5]],"id":52385919},{"atl":[[65,2],[34,2.5],[42,5],[44,11.16]],"id":52385919},{"atb":[[12.5,8.7],[15.5,8]],"id":52385882},{"atl":[[710,2],[740,0.81]],"id":52385882},{"atb":[[26,5],[30,2.5]],"id":52385884},{"atl":[[150,5],[110,2.5]],"id":52385884},{"atb":[[7.4,15.62]],"id":52385897},{"atl":[[120,2]],"id":52385897},{"atb":[[8.8,12]],"id":52385891},{"atb":[[9.2,12]],"id":52385893},{"atb":[[14,21.4]],"id":52385905},{"atl":[[40,14.4]],"id":52385905},{"atl":[[550,2]],"id":52385899}],"con":true,"img":false}]}
{"op":"mcm","clk":"11550847026","pt":1719504572347,"mc":[{"id":"1.230178175","rc":[{"atl":[[65,2],[470,0]],"id":52385904},{"atb":[[8.8,12],[7,0]],"id":52385898},{"atl":[[85,2],[110,0]],"id":52385898},{"atl":[[65,2],[410,0]],"id":52385921},{"atl":[[140,2],[510,0]],"id":52385917},{"atb":[[7.6,9]],"id":52385905}],"con":true,"img":false}]}
{"op":"mcm","clk":"11550847042","pt":1719504572651,"mc":[{"id":"1.230178175","rc":[{"atb":[[15,0]],"id":52385882}],"con":true,"img":false}]}
{"op":"mcm","clk":"11550847057","pt":1719504572860,"mc":[{"id":"1.230178175","rc":[{"atb":[[24,0]],"id":52385883}],"con":true,"img":false}]}
{"op":"mcm","clk":"11550847070","pt":1719504573067,"mc":[{"id":"1.230178175","rc":[{"atb":[[24,0]],"id":52385885}],"con":true,"img":false}]}
{"op":"mcm","clk":"11550847084","pt":1719504573272,"mc":[{"id":"1.230178175","rc":[{"atb":[[24,0]],"id":52385886}],"con":true,"img":false}]}
{"op":"mcm","clk":"11550847102","pt":1719504573537,"mc":[{"id":"1.230178175","rc":[{"atb":[[13,0]],"id":52385889}],"con":true,"img":false}]}
{"op":"mcm","clk":"11550847119","pt":1719504573847,"mc":[{"id":"1.230178175","rc":[{"atb":[[16,0]],"id":52385910}],"con":true,"img":false}]}
{"op":"mcm","clk":"11550847132","pt":1719504574048,"mc":[{"id":"1.230178175","rc":[{"atb":[[13,0]],"id":52385917}],"con":true,"img":false}]}
{"op":"mcm","clk":"11550847141","pt":1719504574152,"mc":[{"id":"1.230178175","rc":[{"atb":[[11,10]],"id":52385884}],"con":true,"img":false}]}
{"op":"mcm","clk":"11550847145","pt":1719504574254,"mc":[{"id":"1.230178175","rc":[{"atb":[[6,2]],"id":52385884}],"con":true,"img":false}]}
{"op":"mcm","clk":"11550847151","pt":1719504574360,"mc":[{"id":"1.230178175","rc":[{"atb":[[18,0]],"id":52385912},{"atb":[[11,0]],"id":52385906},{"atb":[[12,0]],"id":52385918},{"atb":[[11,0]],"id":52385914},{"atb":[[13,0]],"id":52385892},{"atb":[[13,5]],"id":52385913},{"atb":[[11,2.5]],"id":52385921},{"atb":[[11,0]],"id":52385891},{"atb":[[13,0]],"id":52385893},{"atb":[[14,0]],"id":52385903}],"con":true,"img":false}]}
{"op":"mcm","clk":"11550847161","pt":1719504574464,"mc":[{"id":"1.230178175","rc":[{"atb":[[20,6]],"id":52385912},{"atb":[[13,7]],"id":52385906},{"atb":[[14,9]],"id":52385918},{"atb":[[13,10]],"id":52385914},{"atb":[[14,6]],"id":52385892},{"atb":[[15,8.5]],"id":52385913},{"atb":[[13,11]],"id":52385921},{"atb":[[12,6]],"id":52385891},{"atb":[[14,6]],"id":52385893},{"atb":[[16,6]],"id":52385903}],"con":true,"img":false}]}
{"op":"mcm","clk":"11550847167","pt":1719504574567,"mc":[{"id":"1.230178175","rc":[{"atb":[[12.5,0],[14.5,16.74]],"id":52385918}],"con":true,"img":false}]}
{"op":"mcm","clk":"11550847183","pt":1719504574785,"mc":[{"id":"1.230178175","rc":[{"atb":[[20,0]],"id":52385884}],"con":true,"img":false}]}
{"op":"mcm","clk":"11550847197","pt":1719504574941,"mc":[{"id":"1.230178175","rc":[{"atb":[[20,5]],"id":52385917}],"con":true,"img":false}]}
{"op":"mcm","clk":"11550847219","pt":1719504575244,"mc":[{"id":"1.230178175","rc":[{"atb":[[11,2.5]],"id":52385904}],"con":true,"img":false}]}
{"op":"mcm","clk":"11550847225","pt":1719504575345,"mc":[{"id":"1.230178175","rc":[{"atb":[[12,6]],"id":52385904}],"con":true,"img":false}]}
{"op":"mcm","clk":"11550847339","pt":1719504577247,"mc":[{"id":"1.230178175","rc":[{"atb":[[2.32,0]],"id":52385914},{"atb":[[2.24,80.65]],"id":52385917}],"con":true,"img":false}]}
{"op":"mcm","clk":"11550847342","pt":1719504577351,"mc":[{"id":"1.230178175","rc":[{"atb":[[1.55,148.1]],"id":52385914},{"atb":[[2.06,0],[1.61,100]],"id":52385921}],"con":true,"img":false}]}
{"op":"mcm","clk":"11550847413","pt":1719504578351,"mc":[{"id":"1.230178175","rc":[{"atl":[[600,3]],"id":52385910},{"atb":[[4.1,32.26]],"id":52385918},{"atb":[[12,9.09]],"id":52385889},{"atb":[[3.25,0]],"id":52385885},{"atl":[[700,2]],"id":52385885},{"atb":[[9.4,10]],"id":52385890},{"atb":[[9.8,11.36]],"id":52385892},{"atl":[[110,0]],"id":52385900},{"atb":[[3.7,37.04]],"id":52385911},{"atl":[[620,2],[750,0]],"id":52385886},{"atb":[[12,9.09],[7.8,0]],"id":52385903}],"con":true,"img":false}]}
{"op":"mcm","clk":"11550847416","pt":1719504578448,"mc":[{"id":"1.230178175","rc":[{"atl":[[730,0]],"id":52385910},{"atb":[[8,11],[6.8,0]],"id":52385912},{"atb":[[3.05,0.9]],"id":52385918},{"atb":[[4.5,28.57],[3.2,0]],"id":52385920},{"atb":[[10,0]],"id":52385889},{"atl":[[440,3.37],[500,0]],"id":52385914},{"atl":[[640,2],[760,0]],"id":52385883},{"atb":[[11,10]],"id":52385885},{"atl":[[850,0]],"id":52385885},{"atl":[[560,2],[620,0]],"id":52385896},{"atb":[[7,0]],"id":52385890},{"atl":[[85,2],[110,0]],"id":52385890},{"atb":[[9.4,0]],"id":52385892},{"atl":[[80,2]],"id":52385900},{"atb":[[3.25,0]],"id":52385911},{"atb":[[4.3,30.3],[3,0]],"id":52385913},{"atb":[[9.6,10],[1.88,0]],"id":52385886},{"atb":[[12.5,0],[15.5,14.9]],"id":52385882},{"atl":[[600,2],[710,0]],"id":52385882},{"atb":[[7.4,0],[9.4,10]],"id":52385897},{"atl":[[95,2],[120,0]],"id":52385897},{"atb":[[9.2,11],[8.8,0]],"id":52385891},{"atl":[[560,1.07],[510,2]],"id":52385903},{"atl":[[65,2],[85,0]],"id":52385905}],"con":true,"img":false}]}
{"op":"mcm","clk":"11550847531","pt":1719504580359,"mc":[{"id":"1.230178175","rc":[{"atb":[[16,6.67]],"id":52385884}],"con":true,"img":false}]}
{"op":"mcm","clk":"11550847538","pt":1719504580462,"mc":[{"id":"1.230178175","rc":[{"atb":[[11,0]],"id":52385884}],"con":true,"img":false}]}
{"op":"mcm","clk":"11550847617","pt":1719504582375,"mc":[{"id":"1.230178175","rc":[{"atb":[[4.8,26.32],[4.1,0]],"id":52385918},{"atb":[[4.5,0],[5,25]],"id":52385920},{"atb":[[1.55,0]],"id":52385914},{"atb":[[11,10],[9.8,0]],"id":52385892},{"atl":[[42,2.44],[46,0]],"id":52385907},{"atb":[[9.6,0]],"id":52385886},{"atb":[[16,0]],"id":52385884},{"atb":[[2.24,0]],"id":52385917},{"atl":[[450,2],[500,0]],"id":52385891},{"atl":[[450,2],[500,1.2]],"id":52385893}],"con":true,"img":false}]}
{"op":"mcm","clk":"11550847622","pt":1719504582478,"mc":[{"id":"1.230178175","rc":[{"atb":[[11,0]],"id":52385885},{"atb":[[1.61,0],[1.52,100]],"id":52385921},{"atb":[[11,10]],"id":52385884}],"con":true,"img":false}]}
{"op":"mcm","clk":"11550847737","pt":1719504584769,"mc":[{"id":"1.230178175","rc":[{"atb":[[16,0]],"id":52385903}],"con":true,"img":false}]}
{"op":"mcm","clk":"11550847742","pt":1719504584873,"mc":[{"id":"1.230178175","rc":[{"atb":[[19,6]],"id":52385903}],"con":true,"img":false}]}
{"op":"mcm","clk":"11550847775","pt":1719504585492,"mc":[{"id":"1.230178175","rc":[{"atb":[[40,15.38]],"id":52385910},{"atl":[[100,6.06]],"id":52385910},{"atb":[[13.5,16.5]],"id":52385906},{"atl":[[30,16.5]],"id":52385906},{"atl":[[29,16.74]],"id":52385918},{"atb":[[21,15]],"id":52385889},{"atl":[[80,7.59]],"id":52385889},{"atb":[[14.5,16.74]],"id":52385914},{"atl":[[38,16.22]],"id":52385914},{"atb":[[46,13.33]],"id":52385883},{"atl":[[110,5.5]],"id":52385883},{"atb":[[46,13.33]],"id":52385885},{"atl":[[150,4.03]],"id":52385885},{"atb":[[19.5,16.4]],"id":52385890},{"atb":[[20,20]],"id":52385892},{"atl":[[50,12.24]],"id":52385892},{"atl":[[34,18.18]],"id":52385898},{"atl":[[30,20.69]],"id":52385900},{"atb":[[21,15]],"id":52385911},{"atl":[[55,11.11]],"id":52385911},{"atb":[[20,20]],"id":52385913},{"atl":[[36,17.14]],"id":52385913},{"atl":[[23,16]],"id":52385907},{"atb":[[36,15]],"id":52385886},{"atl":[[110,5.5]],"id":52385886},{"atb":[[13.5,15]],"id":52385921},{"atl":[[29,15]],"id":52385921},{"atb":[[46,13.33]],"id":52385884},{"atl":[[100,6.06]],"id":52385884},{"atb":[[25,15]],"id":52385917},{"atl":[[60,10.17]],"id":52385917},{"atb":[[20,30.2]],"id":52385897},{"atl":[[38,16.22]],"id":52385897},{"atb":[[13,15]],"id":52385891},{"atl":[[40,15]],"id":52385891},{"atb":[[14.5,15]],"id":52385893},{"atl":[[34,15]],"id":52385893},{"atb":[[23,15]],"id":52385903},{"atl":[[55,11.11]],"id":52385903},{"atb":[[22,15]],"id":52385899},{"atl":[[50,12.24]],"id":52385899}],"con":true,"img":false}]}
{"op":"mcm","clk":"11550847781","pt":1719504585597,"mc":[{"id":"1.230178175","rc":[{"atl":[[270,2],[600,1]],"id":52385910},{"atb":[[22,15]],"id":52385912},{"atl":[[50,12.24]],"id":52385912},{"atl":[[70,2],[480,1.25]],"id":52385906},{"atl":[[70,2],[440,1.37]],"id":52385918},{"atl":[[23,18]],"id":52385920},{"atl":[[130,2],[560,0]],"id":52385889},{"atl":[[80,2],[440,1.37]],"id":52385914},{"atl":[[270,2],[640,0]],"id":52385883},{"atl":[[700,0],[350,2]],"id":52385885},{"atb":[[26,20]],"id":52385896},{"atl":[[70,8.7]],"id":52385896},{"atl":[[540,0],[110,2]],"id":52385892},{"atb":[[16,15]],"id":52385904},{"atl":[[30,15]],"id":52385904},{"atl":[[130,2],[560,0]],"id":52385911},{"atl":[[520,0],[90,2]],"id":52385913},{"atl":[[270,2],[620,0]],"id":52385886},{"atl":[[32,19.35]],"id":52385919},{"atb":[[40,15]],"id":52385882},{"atl":[[120,5.04]],"id":52385882},{"atl":[[260,2],[660,0]],"id":52385884},{"atl":[[120,2],[510,0]],"id":52385903},{"atb":[[15,24.4]],"id":52385905},{"atl":[[32,19.35]],"id":52385905},{"atl":[[550,0],[120,2]],"id":52385899}],"con":true,"img":false}]}
{"op":"mcm","clk":"11550847788","pt":1719504585700,"mc":[{"id":"1.230178175","rc":[{"atb":[[16.5,0]],"id":52385910},{"atl":[[600,0]],"id":52385910},{"atl":[[120,2],[510,0]],"id":52385912},{"atb":[[11.5,0]],"id":52385906},{"atl":[[480,0]],"id":52385906},{"atl":[[440,0]],"id":52385918},{"atl":[[65,0],[48,2.13],[55,0]],"id":52385920},{"atb":[[13.5,0]],"id":52385889},{"atl":[[600,0]],"id":52385889},{"atb":[[11.5,0]],"id":52385914},{"atl":[[440,0]],"id":52385914},{"atb":[[25,0]],"id":52385883},{"atl":[[800,0]],"id":52385883},{"atb":[[25,0]],"id":52385885},{"atl":[[790,0]],"id":52385885},{"atb":[[21,2.5]],"id":52385896},{"atl":[[560,0],[170,2],[710,0]],"id":52385896},{"atb":[[16,6]],"id":52385890},{"atb":[[13.5,2.5]],"id":52385892},{"atl":[[550,0]],"id":52385892},{"atb":[[11.5,0]],"id":52385904},{"atl":[[500,0]],"id":52385904},{"atl":[[42,0]],"id":52385898},{"atl":[[40,0]],"id":52385900},{"atb":[[15.5,0]],"id":52385911},{"atl":[[530,0]],"id":52385911},{"atb":[[13.5,0]],"id":52385913},{"atl":[[490,0]],"id":52385913},{"atl":[[27,0]],"id":52385907},{"atb":[[25,0]],"id":52385886},{"atl":[[680,0]],"id":52385886},{"atl":[[44,0]],"id":52385919},{"atb":[[11.5,0]],"id":52385921},{"atl":[[400,0]],"id":52385921},{"atb":[[15.5,6.9]],"id":52385882},{"atl":[[600,0],[740,0],[230,2]],"id":52385882},{"atb":[[21,0]],"id":52385884},{"atl":[[740,0]],"id":52385884},{"atb":[[13.5,0]],"id":52385917},{"atl":[[500,0]],"id":52385917},{"atb":[[15,0]],"id":52385897},{"atl":[[46,0]],"id":52385897},{"atb":[[11.5,0]],"id":52385891},{"atl":[[520,0]],"id":52385891},{"atb":[[13.5,0]],"id":52385893},{"atl":[[500,0]],"id":52385893},{"atb":[[14.5,5]],"id":52385903},{"atl":[[560,0]],"id":52385903},{"atb":[[14,7]],"id":52385905},{"atl":[[40,0]],"id":52385905},{"atb":[[18.5,0]],"id":52385899},{"atl":[[590,0]],"id":52385899}],"con":true,"img":false}]}
{"op":"mcm","clk":"11550847793","pt":1719504585753,"mc":[{"id":"1.230178175","rc":[{"atb":[[18.5,0]],"id":52385912},{"atl":[[540,0]],"id":52385912}],"con":true,"img":false}]}
{"op":"mcm","clk":"11550847812","pt":1719504586060,"mc":[{"id":"1.230178175","rc":[{"atl":[[30,0]],"id":52385906}],"con":true,"img":false}]}
{"op":"mcm","clk":"11550847817","pt":1719504586163,"mc":[{"id":"1.230178175","rc":[{"atl":[[30,20.69]],"id":52385906}],"con":true,"img":false}]}
{"op":"mcm","clk":"11550847859","pt":1719504586785,"mc":[{"id":"1.230178175","rc":[{"atb":[[13,0]],"id":52385906},{"atb":[[12,0]],"id":52385904},{"atb":[[14,0]],"id":52385905}],"con":true,"img":false}]}
{"op":"mcm","clk":"11550847867","pt":1719504586888,"mc":[{"id":"1.230178175","rc":[{"atb":[[14,7]],"id":52385906},{"atb":[[13,6]],"id":52385904},{"atb":[[16,7]],"id":52385905}],"con":true,"img":false}]}
{"op":"mcm","clk":"11550847876","pt":1719504586994,"mc":[{"id":"1.230178175","rc":[{"atb":[[13.5,0],[14.5,24]],"id":52385906}],"con":true,"img":false}]}
{"op":"mcm","clk":"11550847910","pt":1719504587462,"mc":[{"id":"1.230178175","rc":[{"atb":[[8,0],[5,25]],"id":52385912},{"atl":[[65,2.5],[75,0],[85,5],[55,0]],"id":52385912},{"atb":[[8,0],[8.8,12]],"id":52385906},{"atl":[[130,0],[120,2]],"id":52385889},{"atb":[[1.23,148.1]],"id":52385914},{"atb":[[4.9,25.64]],"id":52385885},{"atb":[[19.5,0]],"id":52385890},{"atb":[[3.7,0],[2.08,92.59]],"id":52385911},{"atb":[[4.3,0],[2.54,64.94]],"id":52385913},{"atl":[[36,0]],"id":52385913},{"atb":[[2.02,98.04]],"id":52385886},{"atb":[[7.2,0],[5.1,24.39]],"id":52385919},{"atb":[[1.52,0]],"id":52385921},{"atb":[[1.39,100]],"id":52385917},{"atl":[[80,2],[95,0]],"id":52385897},{"atb":[[9.2,0],[8.2,12]],"id":52385891},{"atb":[[11.5,0],[7.8,14]],"id":52385899}],"con":true,"img":false}]}
{"op":"mcm","clk":"11550847918","pt":1719504587563,"mc":[{"id":"1.230178175","rc":[{"atb":[[1.62,150]],"id":52385912},{"atb":[[16,24.4]],"id":52385890},{"atb":[[4.6,27.78]],"id":52385911},{"atb":[[4.5,28.57]],"id":52385913},{"atl":[[46,13.33]],"id":52385913},{"atb":[[6.6,10]],"id":52385886},{"atb":[[2.3,76.92]],"id":52385921}],"con":true,"img":false}]}
{"op":"mcm","clk":"11550847924","pt":1719504587667,"mc":[{"id":"1.230178175","rc":[{"atb":[[5,0]],"id":52385912},{"atl":[[50,0]],"id":52385912},{"atb":[[2.08,0]],"id":52385911},{"atb":[[2.54,0]],"id":52385913},{"atb":[[2.02,0]],"id":52385886}],"con":true,"img":false}]}
{"op":"mcm","clk":"11550847929","pt":1719504587769,"mc":[{"id":"1.230178175","rc":[{"atl":[[55,11.11]],"id":52385912}],"con":true,"img":false}]}
{"op":"mcm","clk":"11550847964","pt":1719504588494,"mc":[{"id":"1.230178175","rc":[{"atb":[[4.8,0],[6.8,14]],"id":52385918},{"atb":[[6.2,9]],"id":52385920},{"atl":[[23,0]],"id":52385907},{"atl":[[75,2],[450,0]],"id":52385891},{"atl":[[75,2],[450,0]],"id":52385893}],"con":true,"img":false}]}
{"op":"mcm","clk":"11550847968","pt":1719504588598,"mc":[{"id":"1.230178175","rc":[{"atb":[[5,0]],"id":52385920},{"atl":[[24,11]],"id":52385907},{"atb":[[17.5,6.06],[11,0]],"id":52385884}],"con":true,"img":false}]}
{"op":"mcm","clk":"11550847977","pt":1719504588756,"mc":[{"id":"1.230178175","rc":[{"atl":[[24,0]],"id":52385907}],"con":true,"img":false}]}
{"op":"mcm","clk":"11550847982","pt":1719504588859,"mc":[{"id":"1.230178175","rc":[{"atl":[[27,16]],"id":52385907}],"con":true,"img":false}]}
{"op":"mcm","clk":"11550848150","pt":1719504591760,"mc":[{"id":"1.230178175","rc":[{"atb":[[15,0]],"id":52385911},{"atb":[[12,0]],"id":52385891}],"con":true,"img":false}]}
{"op":"mcm","clk":"11550848158","pt":1719504591862,"mc":[{"id":"1.230178175","rc":[{"atb":[[17,6]],"id":52385911},{"atb":[[13,21]],"id":52385891}],"con":true,"img":false}]}
{"op":"mcm","clk":"11550848199","pt":1719504592482,"mc":[{"id":"1.230178175","rc":[{"atl":[[190,5],[110,0]],"id":52385910},{"atb":[[1.62,0]],"id":52385912},{"atl":[[30,0]],"id":52385906},{"atb":[[8,14],[6.8,0]],"id":52385918},{"atb":[[1.23,0]],"id":52385914},{"atb":[[18.5,0],[9.2,10.71]],"id":52385883},{"atb":[[4.9,0]],"id":52385885},{"atl":[[160,0],[200,0],[210,2.5],[250,5]],"id":52385885},{"atb":[[9.8,11.36],[14,0]],"id":52385896},{"atb":[[7.8,10],[9.4,0]],"id":52385890},{"atl":[[70,2],[85,0]],"id":52385890},{"atb":[[16,0]],"id":52385904},{"atb":[[4.5,0],[2.96,51.02]],"id":52385913},{"atb":[[4.4,29.41],[6.6,0]],"id":52385886},{"atb":[[18,9]],"id":52385919},{"atb":[[2.3,0],[2.14,87.72]],"id":52385921},{"atb":[[17.5,0],[10.5,10.53]],"id":52385884},{"atb":[[1.39,0]],"id":52385917},{"atb":[[20,0]],"id":52385897},{"atb":[[8,12],[9.2,0]],"id":52385893},{"atb":[[7.8,0],[6.6,14]],"id":52385899}],"con":true,"img":false}]}
{"op":"mcm","clk":"11550848208","pt":1719504592588,"mc":[{"id":"1.230178175","rc":[{"atl":[[34,18.18]],"id":52385906},{"atb":[[9.2,0],[14,7.69]],"id":52385883},{"atb":[[13,28]],"id":52385904},{"atb":[[2.96,0],[2.68,59.52]],"id":52385913},{"atb":[[1.94,100],[2.14,0]],"id":52385921},{"atb":[[16,6.67]],"id":52385884},{"atb":[[15,30.2]],"id":52385897}],"con":true,"img":false}]}
{"op":"mcm","clk":"11550848215","pt":1719504592689,"mc":[{"id":"1.230178175","rc":[{"atl":[[150,0]],"id":52385885},{"atb":[[10.5,0]],"id":52385884}],"con":true,"img":false}]}
{"op":"mcm","clk":"11550848221","pt":1719504592794,"mc":[{"id":"1.230178175","rc":[{"atl":[[100,0]],"id":52385910},{"atl":[[34,0]],"id":52385906},{"atl":[[160,3.77]],"id":52385885}],"con":true,"img":false}]}
{"op":"mcm","clk":"11550848229","pt":1719504592896,"mc":[{"id":"1.230178175","rc":[{"atl":[[110,5.5]],"id":52385910},{"atl":[[40,15]],"id":52385906}],"con":true,"img":false}]}
{"op":"mcm","clk":"11550848252","pt":1719504593162,"mc":[{"id":"1.230178175","rc":[{"atl":[[110,0]],"id":52385910},{"atl":[[160,0]],"id":52385885}],"con":true,"img":false}]}
{"op":"mcm","clk":"11550848260","pt":1719504593263,"mc":[{"id":"1.230178175","rc":[{"atl":[[150,9.03]],"id":52385910}],"con":true,"img":false}]}
{"op":"mcm","clk":"11550848265","pt":1719504593367,"mc":[{"id":"1.230178175","rc":[{"atl":[[25,25]],"id":52385918},{"atl":[[210,5.37]],"id":52385885}],"con":true,"img":false}]}
{"op":"mcm","clk":"11550848272","pt":1719504593471,"mc":[{"id":"1.230178175","rc":[{"atl":[[29,0]],"id":52385918},{"atb":[[11.5,0]],"id":52385920},{"atl":[[60,0]],"id":52385920},{"atb":[[8.6,0]],"id":52385890},{"atl":[[38,0]],"id":52385890},{"atb":[[14.5,0]],"id":52385898},{"atl":[[44,5]],"id":52385898},{"atb":[[15.5,0]],"id":52385900},{"atl":[[42,0]],"id":52385900},{"atb":[[11.5,0]],"id":52385907},{"atl":[[28,0]],"id":52385907},{"atb":[[16.5,0]],"id":52385919},{"atl":[[46,0]],"id":52385919},{"atb":[[14.5,0]],"id":52385897},{"atl":[[48,5]],"id":52385897},{"atl":[[42,5]],"id":52385905}],"con":true,"img":false}]}
{"op":"mcm","clk":"11550848286","pt":1719504593678,"mc":[{"id":"1.230178175","rc":[{"atb":[[12,3.66]],"id":52385918},{"atl":[[28,2.6]],"id":52385918},{"atb":[[9.8,5.6]],"id":52385920},{"atb":[[11,5.8]],"id":52385890},{"atl":[[34,2],[36,0]],"id":52385890},{"atb":[[9.8,5.21]],"id":52385904},{"atl":[[29,3]],"id":52385904},{"atb":[[15,4]],"id":52385898},{"atl":[[32,2.3]],"id":52385898},{"atb":[[16,0],[16.5,4]],"id":52385900},{"atl":[[29,4]],"id":52385900},{"atb":[[9.8,4]],"id":52385907},{"atl":[[26,3]],"id":52385907},{"atb":[[14.5,3.75]],"id":52385919},{"atl":[[30,4]],"id":52385919},{"atb":[[15,0],[15.5,4]],"id":52385897},{"atl":[[36,3.34]],"id":52385897},{"atb":[[13.5,5.07]],"id":52385891},{"atl":[[36,3.12]],"id":52385891},{"atb":[[12,4.1]],"id":52385893},{"atl":[[32,3.3]],"id":52385893},{"atl":[[30,2.7]],"id":52385905}],"con":true,"img":false}]}
{"op":"mcm","clk":"11550848293","pt":1719504593782,"mc":[{"id":"1.230178175","rc":[{"atl":[[38,16.22]],"id":52385890},{"atb":[[14.5,28]],"id":52385898},{"atb":[[15.5,28]],"id":52385900},{"atb":[[14.5,26],[9.4,0],[8.6,13.16]],"id":52385897}],"con":true,"img":false}]}
{"op":"mcm","clk":"11550848540","pt":1719504597772,"mc":[{"id":"1.230178175","rc":[{"atb":[[8.2,10]],"id":52385885}],"con":true,"img":false}]}
{"op":"mcm","clk":"11550848547","pt":1719504597875,"mc":[{"id":"1.230178175","rc":[{"atb":[[19.5,5.41],[14,0]],"id":52385883},{"atb":[[9.8,0],[26,0],[14,7.69]],"id":52385896},{"atb":[[4.6,0],[3.95,33.9]],"id":52385911},{"atb":[[3.8,35.71],[2.68,0]],"id":52385913},{"atb":[[9.6,10]],"id":52385886},{"atb":[[2.32,75.76],[1.94,0]],"id":52385921},{"atb":[[16,0],[18.5,5.71]],"id":52385884},{"atb":[[2.24,80.65]],"id":52385917}],"con":true,"img":false}]}
{"op":"mcm","clk":"11550848555","pt":1719504597975,"mc":[{"id":"1.230178175","rc":[{"atb":[[21,17.5]],"id":52385896},{"atb":[[4.4,0]],"id":52385886}],"con":true,"img":false}]}
{"op":"mcm","clk":"11550848579","pt":1719504598389,"mc":[{"id":"1.230178175","rc":[{"atl":[[25,0]],"id":52385918}],"con":true,"img":false}]}
{"op":"mcm","clk":"11550848583","pt":1719504598493,"mc":[{"id":"1.230178175","rc":[{"atb":[[42,14.63]],"id":52385910},{"atl":[[140,4.32]],"id":52385910},{"atl":[[34,18.18]],"id":52385906},{"atl":[[36,12.52]],"id":52385918},{"atb":[[30,20]],"id":52385889},{"atl":[[200,3.02]],"id":52385885},{"atl":[[30,20.69]],"id":52385898},{"atl":[[29,25.43]],"id":52385900},{"atl":[[42,14.63]],"id":52385913},{"atl":[[22,14]],"id":52385907},{"atb":[[20,24]],"id":52385897},{"atl":[[34,18.18]],"id":52385897},{"atb":[[16,16.38]],"id":52385891},{"atl":[[34,16.38]],"id":52385891},{"atl":[[30,20.2]],"id":52385893},{"atl":[[44,13.95]],"id":52385899}],"con":true,"img":false}]}
{"op":"mcm","clk":"11550848590","pt":1719504598598,"mc":[{"id":"1.230178175","rc":[{"atl":[[22,21.2]],"id":52385920},{"atl":[[28,16.42]],"id":52385904},{"atl":[[29,15.5]],"id":52385919},{"atl":[[29,21.43]],"id":52385905}],"con":true,"img":false}]}
{"op":"mcm","clk":"11550848597","pt":1719504598701,"mc":[{"id":"1.230178175","rc":[{"atb":[[40,0]],"id":52385910},{"atl":[[150,5]],"id":52385910},{"atb":[[21,0]],"id":52385889},{"atl":[[210,2.5]],"id":52385885},{"atl":[[34,0]],"id":52385898},{"atl":[[30,0]],"id":52385900},{"atl":[[46,0]],"id":52385913},{"atl":[[27,0]],"id":52385907},{"atb":[[14.5,0]],"id":52385897},{"atl":[[38,0]],"id":52385897},{"atb":[[13,6]],"id":52385891},{"atl":[[40,0]],"id":52385891},{"atl":[[34,0]],"id":52385893},{"atl":[[50,0]],"id":52385899}],"con":true,"img":false}]}
{"op":"mcm","clk":"11550848603","pt":1719504598805,"mc":[{"id":"1.230178175","rc":[{"atl":[[40,0]],"id":52385906},{"atl":[[23,0]],"id":52385920},{"atl":[[32,0]],"id":52385905}],"con":true,"img":false}]}
{"op":"mcm","clk":"11550848620","pt":1719504598908,"mc":[{"id":"1.230178175","rc":[{"atl":[[30,0]],"id":52385904},{"atl":[[32,0]],"id":52385919}],"con":true,"img":false}]}
{"op":"mcm","clk":"11550848804","pt":1719504601772,"mc":[{"id":"1.230178175","rc":[{"atb":[[13,0]],"id":52385891}],"con":true,"img":false}]}
{"op":"mcm","clk":"11550848808","pt":1719504601873,"mc":[{"id":"1.230178175","rc":[{"atb":[[14,6]],"id":52385891}],"con":true,"img":false}]}
{"op":"mcm","clk":"11550848877","pt":1719504603584,"mc":[{"id":"1.230178175","rc":[{"atb":[[1.11,238.56]],"id":52385912},{"atb":[[8,0],[6.8,14]],"id":52385918},{"atb":[[1.1,148.1]],"id":52385914},{"atb":[[15,16.42]],"id":52385904},{"atb":[[8,0],[8.8,10]],"id":52385893}],"con":true,"img":false}]}
{"op":"mcm","clk":"11550848889","pt":1719504603791,"mc":[{"id":"1.230178175","rc":[{"atb":[[14,0]],"id":52385892},{"atb":[[13,6]],"id":52385904},{"atb":[[14,0]],"id":52385893}],"con":true,"img":false}]}
{"op":"mcm","clk":"11550848895","pt":1719504603895,"mc":[{"id":"1.230178175","rc":[{"atb":[[16,6]],"id":52385892},{"atb":[[16,6]],"id":52385893}],"con":true,"img":false}]}
{"op":"mcm","clk":"11550848901","pt":1719504603998,"mc":[{"id":"1.230178175","rc":[{"atb":[[16,26.2],[14.5,0]],"id":52385893}],"con":true,"img":false}]}
{"op":"mcm","clk":"11550848949","pt":1719504604789,"mc":[{"id":"1.230178175","rc":[{"atb":[[13,0]],"id":52385904}],"con":true,"img":false}]}
{"op":"mcm","clk":"11550848954","pt":1719504604899,"mc":[{"id":"1.230178175","rc":[{"atb":[[14,6]],"id":52385904}],"con":true,"img":false}]}
{"op":"mcm","clk":"11550849026","pt":1719504606198,"mc":[{"id":"1.230178175","rc":[{"atl":[[28,24.82]],"id":52385918}],"con":true,"img":false}]}
{"op":"mcm","clk":"11550849035","pt":1719504606405,"mc":[{"id":"1.230178175","rc":[{"atl":[[36,0]],"id":52385918}],"con":true,"img":false}]}
{"op":"mcm","clk":"11550849048","pt":1719504606614,"mc":[{"id":"1.230178175","rc":[{"atl":[[32,16.6]],"id":52385890},{"atb":[[15.5,26]],"id":52385898}],"con":true,"img":false}]}
{"op":"mcm","clk":"11550849053","pt":1719504606718,"mc":[{"id":"1.230178175","rc":[{"atb":[[16.5,30]],"id":52385900}],"con":true,"img":false}]}
{"op":"mcm","clk":"11550849059","pt":1719504606775,"mc":[{"id":"1.230178175","rc":[{"atl":[[38,0]],"id":52385890},{"atb":[[14.5,0]],"id":52385898}],"con":true,"img":false}]}
{"op":"mcm","clk":"11550849064","pt":1719504606878,"mc":[{"id":"1.230178175","rc":[{"atb":[[15.5,0]],"id":52385900}],"con":true,"img":false}]}
{"op":"mcm","clk":"11550849209","pt":1719504609328,"mc":[{"id":"1.230178175","rc":[{"atb":[[1.11,0]],"id":52385912},{"atb":[[1.1,0]],"id":52385914},{"atb":[[8.2,0],[14.5,7.41]],"id":52385885},{"atl":[[70,2],[85,0]],"id":52385898},{"atb":[[3.45,40.82]],"id":52385911},{"atb":[[3.8,0],[3.4,41.67]],"id":52385913},{"atb":[[9.6,0],[14,7.69]],"id":52385886},{"atb":[[2.32,0],[2.1,90.91]],"id":52385921},{"atb":[[2.24,0],[3.4,41.67]],"id":52385917}],"con":true,"img":false}]}
{"op":"mcm","clk":"11550849215","pt":1719504609386,"mc":[{"id":"1.230178175","rc":[{"atb":[[3.95,0]],"id":52385911}],"con":true,"img":false}]}
{"op":"mcm","clk":"11550849323","pt":1719504611404,"mc":[{"id":"1.230178175","rc":[{"atl":[[25,15.5]],"id":52385919},{"atl":[[28,22]],"id":52385905}],"con":true,"img":false}]}
{"op":"mcm","clk":"11550849330","pt":1719504611511,"mc":[{"id":"1.230178175","rc":[{"atl":[[29,0]],"id":52385919}],"con":true,"img":false}]}
{"op":"mcm","clk":"11550849337","pt":1719504611613,"mc":[{"id":"1.230178175","rc":[{"atl":[[29,0]],"id":52385905}],"con":true,"img":false}]}
{"op":"mcm","clk":"11550849351","pt":1719504611924,"mc":[{"id":"1.230178175","rc":[{"atl":[[32,19]],"id":52385906}],"con":true,"img":false}]}
{"op":"mcm","clk":"11550849363","pt":1719504612088,"mc":[{"id":"1.230178175","rc":[{"atl":[[34,0]],"id":52385906}],"con":true,"img":false}]}
{"op":"mcm","clk":"11550849612","pt":1719504616633,"mc":[{"id":"1.230178175","rc":[{"atb":[[3.45,0],[3.8,35.71]],"id":52385911},{"atb":[[18,24.5]],"id":52385919},{"atl":[[25,0]],"id":52385919},{"atb":[[1.82,100],[2.1,0]],"id":52385921},{"atb":[[3.4,0],[3.05,49.68]],"id":52385917}],"con":true,"img":false}]}
{"op":"mcm","clk":"11550849620","pt":1719504616735,"mc":[{"id":"1.230178175","rc":[{"atl":[[29,12.5]],"id":52385919}],"con":true,"img":false}]}
{"op":"mcm","clk":"11550849651","pt":1719504617111,"mc":[{"id":"1.230178175","rc":[{"atb":[[44,13.95]],"id":52385910},{"atb":[[46,13.33]],"id":52385882},{"atb":[[28,20]],"id":52385917}],"con":true,"img":false}]}
{"op":"mcm","clk":"11550849666","pt":1719504617312,"mc":[{"id":"1.230178175","rc":[{"atb":[[42,0]],"id":52385910},{"atb":[[46,0]],"id":52385885},{"atb":[[40,0]],"id":52385882},{"atb":[[25,0]],"id":52385917}],"con":true,"img":false}]}
{"op":"mcm","clk":"11550849672","pt":1719504617414,"mc":[{"id":"1.230178175","rc":[{"atb":[[44,11.04]],"id":52385885}],"con":true,"img":false}]}
{"op":"mcm","clk":"11550849683","pt":1719504617621,"mc":[{"id":"1.230178175","rc":[{"atb":[[44,0]],"id":52385885}],"con":true,"img":false}]}
{"op":"mcm","clk":"11550849689","pt":1719504617724,"mc":[{"id":"1.230178175","rc":[{"atb":[[40,11.04]],"id":52385885}],"con":true,"img":false}]}
{"op":"mcm","clk":"11550849710","pt":1719504618137,"mc":[{"id":"1.230178175","rc":[{"atb":[[48,12.77]],"id":52385883},{"atb":[[48,12.77]],"id":52385884}],"con":true,"img":false}]}
{"op":"mcm","clk":"11550849718","pt":1719504618195,"mc":[{"id":"1.230178175","rc":[{"atb":[[46,0]],"id":52385883},{"atb":[[46,0]],"id":52385884}],"con":true,"img":false}]}
{"op":"mcm","clk":"11550849863","pt":1719504620727,"mc":[{"id":"1.230178175","rc":[{"atl":[[34,0]],"id":52385890},{"atb":[[9.8,0]],"id":52385904},{"atl":[[29,0]],"id":52385904},{"atl":[[32,0]],"id":52385898},{"atb":[[16.5,26]],"id":52385900},{"atl":[[26,0]],"id":52385907},{"atb":[[14.5,0]],"id":52385919},{"atl":[[30,0]],"id":52385919},{"atb":[[15.5,0]],"id":52385897},{"atl":[[36,0]],"id":52385897},{"atb":[[13.5,0]],"id":52385891},{"atl":[[36,0]],"id":52385891},{"atl":[[32,0]],"id":52385893},{"atl":[[30,0]],"id":52385905}],"con":true,"img":false}]}
{"op":"mcm","clk":"11550849870","pt":1719504620829,"mc":[{"id":"1.230178175","rc":[{"atl":[[21,4]],"id":52385920},{"atl":[[32,0],[30,2.2]],"id":52385890},{"atb":[[12.5,4]],"id":52385904},{"atl":[[27,3],[28,0]],"id":52385904},{"atl":[[29,2.83]],"id":52385898},{"atb":[[16.5,0],[13,4.79]],"id":52385900},{"atl":[[21,4]],"id":52385907},{"atb":[[12.5,3.7]],"id":52385919},{"atl":[[28,2],[29,0]],"id":52385919},{"atb":[[14.5,5]],"id":52385897},{"atl":[[32,2.26],[34,0]],"id":52385897},{"atl":[[32,3],[34,0]],"id":52385891},{"atl":[[29,2.6]],"id":52385893},{"atl":[[27,3.07]],"id":52385905}],"con":true,"img":false}]}
{"op":"mcm","clk":"11550849878","pt":1719504620933,"mc":[{"id":"1.230178175","rc":[{"atl":[[21,23.2]],"id":52385920},{"atl":[[34,18.18]],"id":52385890},{"atl":[[29,21.43]],"id":52385904},{"atl":[[29,24.26]],"id":52385898},{"atb":[[16,28]],"id":52385900},{"atl":[[21,20]],"id":52385907},{"atl":[[32,19.35]],"id":52385919},{"atl":[[36,17.14]],"id":52385897},{"atl":[[36,17.14]],"id":52385891},{"atl":[[29,16]],"id":52385893}],"con":true,"img":false}]}
{"op":"mcm","clk":"11550849891","pt":1719504621140,"mc":[{"id":"1.230178175","rc":[{"atl":[[22,0]],"id":52385920},{"atl":[[30,0]],"id":52385898},{"atl":[[22,0]],"id":52385907},{"atl":[[30,0]],"id":52385893}],"con":true,"img":false}]}
{"op":"mcm","clk":"11550849900","pt":1719504621296,"mc":[{"id":"1.230178175","rc":[{"atb":[[16,0]],"id":52385900}],"con":true,"img":false}]}
{"op":"mcm","clk":"11550849908","pt":1719504621400,"mc":[{"id":"1.230178175","rc":[{"atb":[[15.5,28]],"id":52385900}],"con":true,"img":false}]}
{"op":"mcm","clk":"11550849937","pt":1719504621917,"mc":[{"id":"1.230178175","rc":[{"atb":[[16,9.68]],"id":52385900}],"con":true,"img":false}]}
{"op":"mcm","clk":"11550849959","pt":1719504622331,"mc":[{"id":"1.230178175","rc":[{"atb":[[16,0]],"id":52385900}],"con":true,"img":false}]}
{"op":"mcm","clk":"11550850046","pt":1719504623942,"mc":[{"id":"1.230178175","rc":[{"atl":[[28,14.4]],"id":52385919},{"atl":[[26,22]],"id":52385905}],"con":true,"img":false}]}
{"op":"mcm","clk":"11550850058","pt":1719504624147,"mc":[{"id":"1.230178175","rc":[{"atl":[[32,0]],"id":52385919},{"atl":[[28,0]],"id":52385905}],"con":true,"img":false}]}
{"op":"mcm","clk":"11550850243","pt":1719504627561,"mc":[{"id":"1.230178175","rc":[{"atb":[[23,0],[26,5],[27,0],[30,2.5]],"id":52385910},{"atb":[[10.5,0],[14.5,2.5]],"id":52385912},{"atb":[[10.5,0],[11,5],[12.5,0],[13,2.5]],"id":52385906},{"atl":[[34,5],[36,0],[28,2.5],[29,0]],"id":52385920},{"atl":[[80,10.09],[85,0],[100,5],[110,0]],"id":52385889},{"atb":[[12.5,2.5],[9.4,0]],"id":52385914},{"atb":[[32,5],[36,0],[40,13.54],[29,0]],"id":52385885},{"atl":[[42,2.5],[44,0],[50,5],[55,0]],"id":52385890},{"atl":[[34,2.5],[36,0],[42,5],[44,0]],"id":52385904},{"atb":[[12,0],[13,5],[14,0],[15,2.5]],"id":52385911},{"atb":[[17,2.5],[13,0]],"id":52385913},{"atl":[[34,5],[36,0],[28,2.5],[29,0]],"id":52385907},{"atb":[[10,5],[11,0],[12,2.5],[9.6,0]],"id":52385921},{"atl":[[130,0],[160,5],[170,0],[120,7.54]],"id":52385882},{"atl":[[38,2.5],[40,0],[46,5],[48,0]],"id":52385897},{"atl":[[40,2.5],[42,0],[48,5],[50,0]],"id":52385891},{"atl":[[38,2.5],[42,0],[46,5],[50,0]],"id":52385893},{"atl":[[32,2.5],[34,0],[40,5],[42,0]],"id":52385905},{"atb":[[12,0],[13.5,5],[14,0],[15.5,2.5]],"id":52385899}],"con":true,"img":false}]}
{"op":"mcm","clk":"11550850255","pt":1719504627724,"mc":[{"id":"1.230178175","rc":[{"atl":[[130,7.15],[150,0],[170,5],[190,0]],"id":52385910},{"atl":[[180,5.85],[210,0],[220,5],[250,0]],"id":52385885}],"con":true,"img":false}]}
{"op":"mcm","clk":"11550850265","pt":1719504627827,"mc":[{"id":"1.230178175","rc":[{"atl":[[140,0]],"id":52385910},{"atl":[[200,0]],"id":52385885}],"con":true,"img":false}]}
{"op":"mcm","clk":"11550850358","pt":1719504629128,"mc":[{"id":"1.230178175","rc":[{"atb":[[4.1,32.26]],"id":52385912},{"atl":[[65,0],[80,5],[85,0],[46,13.33],[60,2.5]],"id":52385912},{"atl":[[36,2.5],[44,5]],"id":52385918},{"atb":[[17.5,0],[18,5],[20,2.5],[15.5,0]],"id":52385889},{"atl":[[150,2],[120,0]],"id":52385889},{"atb":[[2.88,53.19]],"id":52385914},{"atb":[[32,2.5],[26,0],[27,5],[30,0]],"id":52385883},{"atl":[[200,5],[120,0]],"id":52385883},{"atb":[[14.5,0]],"id":52385885},{"atl":[[270,5],[350,0],[180,3.35],[420,2],[220,0],[230,2.5]],"id":52385885},{"atb":[[40,15.38],[14,0],[18.5,0],[19,5],[21,15],[22,2.5],[7,13.69]],"id":52385896},{"atl":[[130,5],[75,0]],"id":52385896},{"atb":[[8.2,11]],"id":52385911},{"atb":[[3.4,0]],"id":52385913},{"atb":[[14,0]],"id":52385886},{"atl":[[270,0],[340,2],[200,5],[120,0]],"id":52385886},{"atl":[[25,17.4]],"id":52385919},{"atb":[[1.82,0],[3,50]],"id":52385921},{"atb":[[36,2.5],[15.5,0],[20,5.26],[29,5]],"id":52385882},{"atl":[[290,2],[230,0]],"id":52385882},{"atb":[[18.5,0],[9.8,10.71]],"id":52385884},{"atl":[[260,0],[330,2],[190,5],[110,0]],"id":52385884},{"atb":[[3.05,0.9]],"id":52385917},{"atl":[[65,0],[80,2.5],[85,0],[100,5]],"id":52385917},{"atb":[[20,0]],"id":52385897},{"atb":[[32,19.35],[9.2,12],[12,0],[14.5,0],[15,5],[16.5,0],[17,2.5]],"id":52385903},{"atl":[[70,2.5],[80,0],[160,2],[90,5],[60,0],[120,0]],"id":52385903},{"atb":[[9,12],[6.6,0]],"id":52385899}],"con":true,"img":false}]}
{"op":"mcm","clk":"11550850364","pt":1719504629225,"mc":[{"id":"1.230178175","rc":[{"atb":[[1.97,103.09],[4.1,0]],"id":52385912},{"atl":[[55,0]],"id":52385912},{"atb":[[8.2,10],[6.8,0]],"id":52385918},{"atl":[[38,0],[46,0]],"id":52385918},{"atb":[[6.2,0],[5.4,22.73]],"id":52385920},{"atb":[[30,0]],"id":52385889},{"atb":[[2.04,96.15],[2.88,0]],"id":52385914},{"atb":[[19.5,0],[8.4,10.41]],"id":52385883},{"atl":[[270,0],[340,2],[110,0]],"id":52385883},{"atb":[[2.74,57.47]],"id":52385885},{"atb":[[40,0],[3.8,35.71],[21,0],[7,0]],"id":52385896},{"atb":[[9,0],[6.2,14]],"id":52385900},{"atl":[[28,22.22]],"id":52385900},{"atb":[[8.2,0],[11,10],[3.8,0]],"id":52385911},{"atb":[[6,19]],"id":52385913},{"atb":[[3.6,38.46],[5.1,0]],"id":52385919},{"atl":[[28,2]],"id":52385919},{"atb":[[3,0],[2.26,79.37]],"id":52385921},{"atb":[[24,0],[28,0]],"id":52385882},{"atb":[[12,9.09]],"id":52385884},{"atl":[[100,0]],"id":52385884},{"atl":[[60,0]],"id":52385917},{"atb":[[15,26]],"id":52385897},{"atb":[[32,0],[23,0]],"id":52385903},{"atl":[[55,0]],"id":52385903},{"atb":[[9,0],[5.8,20.83]],"id":52385899}],"con":true,"img":false}]}
{"op":"mcm","clk":"11550850367","pt":1719504629331,"mc":[{"id":"1.230178175","rc":[{"atb":[[12,0],[13.5,8],[29,20]],"id":52385889},{"atl":[[150,4.03]],"id":52385883},{"atl":[[180,0]],"id":52385885},{"atb":[[26,24]],"id":52385896},{"atb":[[5,25]],"id":52385913},{"atl":[[110,0]],"id":52385886},{"atb":[[9.8,0]],"id":52385884},{"atl":[[140,4.32]],"id":52385884},{"atl":[[65,9.38],[140,0],[190,2]],"id":52385917},{"atb":[[24,26.09]],"id":52385903},{"atl":[[60,10.17]],"id":52385903}],"con":true,"img":false}]}
{"op":"mcm","clk":"11550850372","pt":1719504629431,"mc":[{"id":"1.230178175","rc":[{"atl":[[190,3.17]],"id":52385885},{"atl":[[29,4]],"id":52385900},{"atb":[[6,2]],"id":52385913},{"atl":[[150,4.03]],"id":52385886}],"con":true,"img":false}]}
{"op":"mcm","clk":"11550850377","pt":1719504629535,"mc":[{"id":"1.230178175","rc":[{"atb":[[29,0]],"id":52385889},{"atb":[[29,20]],"id":52385917},{"atl":[[60,0]],"id":52385903}],"con":true,"img":false}]}
{"op":"mcm","clk":"11550850385","pt":1719504629637,"mc":[{"id":"1.230178175","rc":[{"atb":[[27,20]],"id":52385889},{"atb":[[28,0]],"id":52385917},{"atl":[[65,9.38]],"id":52385903}],"con":true,"img":false}]}
{"op":"mcm","clk":"11550850398","pt":1719504629842,"mc":[{"id":"1.230178175","rc":[{"atb":[[48,12.77]],"id":52385885},{"atl":[[190,0]],"id":52385885},{"atb":[[34,0],[36,17.5],[28,0],[29,5]],"id":52385886}],"con":true,"img":false}]}
{"op":"mcm","clk":"11550850404","pt":1719504629946,"mc":[{"id":"1.230178175","rc":[{"atb":[[40,2.5]],"id":52385885},{"atl":[[220,2.74]],"id":52385885}],"con":true,"img":false}]}
{"op":"mcm","clk":"11550850447","pt":1719504630627,"mc":[{"id":"1.230178175","rc":[{"atb":[[20,0]],"id":52385912},{"atb":[[18,15.5]],"id":52385919}],"con":true,"img":false}]}
{"op":"mcm","clk":"11550850454","pt":1719504630731,"mc":[{"id":"1.230178175","rc":[{"atb":[[18,6]],"id":52385912},{"atb":[[16,9]],"id":52385919}],"con":true,"img":false}]}
{"op":"mcm","clk":"11550850459","pt":1719504630838,"mc":[{"id":"1.230178175","rc":[{"atb":[[18,0]],"id":52385919},{"atb":[[16,29]],"id":52385905}],"con":true,"img":false}]}
{"op":"mcm","clk":"11550850470","pt":1719504631045,"mc":[{"id":"1.230178175","rc":[{"atb":[[17.5,12.4]],"id":52385919},{"atb":[[15,0]],"id":52385905}],"con":true,"img":false}]}
{"op":"mcm","clk":"11550850492","pt":1719504631357,"mc":[{"id":"1.230178175","rc":[{"atb":[[32,2.5],[26,0],[27,5],[30,0]],"id":52385884},{"atb":[[17,0],[15,0]],"id":52385917}],"con":true,"img":false}]}
{"op":"mcm","clk":"11550850497","pt":1719504631415,"mc":[{"id":"1.230178175","rc":[{"atb":[[17.5,2.5],[15.5,5]],"id":52385917}],"con":true,"img":false}]}
{"op":"mcm","clk":"11550850509","pt":1719504631637,"mc":[{"id":"1.230178175","rc":[{"atb":[[17.5,0]],"id":52385919}],"con":true,"img":false}]}
{"op":"mcm","clk":"11550850516","pt":1719504631736,"mc":[{"id":"1.230178175","rc":[{"atb":[[16.5,25.4]],"id":52385919}],"con":true,"img":false}]}
{"op":"mcm","clk":"11550850596","pt":1719504633236,"mc":[{"id":"1.230178175","rc":[{"atl":[[29,16.6]],"id":52385890},{"atl":[[26,20]],"id":52385904},{"atl":[[30,20.69]],"id":52385897},{"atl":[[30,18]],"id":52385891}],"con":true,"img":false}]}
{"op":"mcm","clk":"11550850608","pt":1719504633444,"mc":[{"id":"1.230178175","rc":[{"atl":[[34,0]],"id":52385890},{"atl":[[29,0]],"id":52385904},{"atl":[[36,0]],"id":52385897},{"atl":[[36,0]],"id":52385891}],"con":true,"img":false}]}
{"op":"mcm","clk":"11550850659","pt":1719504634327,"mc":[{"id":"1.230178175","rc":[{"atb":[[1.97,0],[1.75,133.33]],"id":52385912},{"atb":[[6.4,15.41],[8.4,0]],"id":52385883},{"atb":[[2.74,0],[1.86,116.28]],"id":52385885},{"atb":[[3.8,0],[1.96,104.17]],"id":52385896},{"atl":[[130,0],[110,2]],"id":52385911},{"atb":[[3.6,0],[3.2,45.45]],"id":52385919},{"atl":[[25,0]],"id":52385919},{"atb":[[2.26,0],[2.1,90.91]],"id":52385921},{"atb":[[9.2,0],[7.4,12]],"id":52385903}],"con":true,"img":false}]}
{"op":"mcm","clk":"11550850668","pt":1719504634536,"mc":[{"id":"1.230178175","rc":[{"atl":[[32,12.4]],"id":52385919}],"con":true,"img":false}]}
{"op":"mcm","clk":"11550850682","pt":1719504634741,"mc":[{"id":"1.230178175","rc":[{"atb":[[27,0]],"id":52385889}],"con":true,"img":false}]}
{"op":"mcm","clk":"11550850688","pt":1719504634845,"mc":[{"id":"1.230178175","rc":[{"atb":[[21,20]],"id":52385889}],"con":true,"img":false}]}
{"op":"mcm","clk":"11550850780","pt":1719504636144,"mc":[{"id":"1.230178175","rc":[{"atl":[[28,24.22]],"id":52385919}],"con":true,"img":false}]}
{"op":"mcm","clk":"11550850790","pt":1719504636352,"mc":[{"id":"1.230178175","rc":[{"atl":[[32,0]],"id":52385919}],"con":true,"img":false}]}
{"op":"mcm","clk":"11550850811","pt":1719504636773,"mc":[{"id":"1.230178175","rc":[{"atb":[[13,0]],"id":52385914}],"con":true,"img":false}]}
{"op":"mcm","clk":"11550850830","pt":1719504637028,"mc":[{"id":"1.230178175","rc":[{"atb":[[20,28]],"id":52385898}],"con":true,"img":false}]}
{"op":"mcm","clk":"11550850841","pt":1719504637234,"mc":[{"id":"1.230178175","rc":[{"atb":[[15.5,0]],"id":52385898}],"con":true,"img":false}]}
{"op":"mcm","clk":"11550850865","pt":1719504637749,"mc":[{"id":"1.230178175","rc":[{"atl":[[40,15.38]],"id":52385913}],"con":true,"img":false}]}
{"op":"mcm","clk":"11550850877","pt":1719504637956,"mc":[{"id":"1.230178175","rc":[{"atl":[[42,0]],"id":52385913}],"con":true,"img":false}]}
{"op":"mcm","clk":"11550850883","pt":1719504638058,"mc":[{"id":"1.230178175","rc":[{"atl":[[75,5],[80,0],[55,13.61],[60,0]],"id":52385911}],"con":true,"img":false}]}
{"op":"mcm","clk":"11550850922","pt":1719504638732,"mc":[{"id":"1.230178175","rc":[{"atb":[[9.2,0],[8.4,0],[9.4,2.5]],"id":52385898}],"con":true,"img":false}]}
{"op":"mcm","clk":"11550850955","pt":1719504639356,"mc":[{"id":"1.230178175","rc":[{"atb":[[4.8,26.32],[5.4,0]],"id":52385920},{"atb":[[2.56,64.1],[2.04,0]],"id":52385914},{"atl":[[150,6.53],[160,0],[190,5],[200,0]],"id":52385883},{"atl":[[130,0],[90,2.5],[95,0],[120,5]],"id":52385896},{"atb":[[5.4,22.73]],"id":52385900},{"atb":[[2.4,71.43]],"id":52385886},{"atl":[[150,6.53],[160,0],[190,5],[200,0]],"id":52385886},{"atb":[[12,0],[15,7.14]],"id":52385884},{"atl":[[140,6.82],[150,0],[180,5],[190,0]],"id":52385884}],"con":true,"img":false}]}
{"op":"mcm","clk":"11550850961","pt":1719504639459,"mc":[{"id":"1.230178175","rc":[{"atb":[[6.2,0]],"id":52385900},{"atb":[[5,0],[6.2,17]],"id":52385913},{"atb":[[8,0],[9,2.5],[8.2,5],[8.8,0]],"id":52385905}],"con":true,"img":false}]}
{"op":"mcm","clk":"11550850966","pt":1719504639563,"mc":[{"id":"1.230178175","rc":[{"atb":[[2.4,0]],"id":52385886},{"atb":[[15,0]],"id":52385884}],"con":true,"img":false}]}
{"op":"mcm","clk":"11550850974","pt":1719504639667,"mc":[{"id":"1.230178175","rc":[{"atb":[[14,17.6]],"id":52385920},{"atb":[[13,0]],"id":52385921},{"atb":[[11.5,9.52]],"id":52385884},{"atb":[[14,0]],"id":52385891}],"con":true,"img":false}]}
{"op":"mcm","clk":"11550850981","pt":1719504639726,"mc":[{"id":"1.230178175","rc":[{"atb":[[13,10]],"id":52385920},{"atb":[[12,13.5]],"id":52385921},{"atb":[[16,22.38]],"id":52385891}],"con":true,"img":false}]}
{"op":"mcm","clk":"11550850986","pt":1719504639829,"mc":[{"id":"1.230178175","rc":[{"atb":[[14,0]],"id":52385920},{"atb":[[13.5,0]],"id":52385921},{"atb":[[24,0]],"id":52385903}],"con":true,"img":false}]}
{"op":"mcm","clk":"11550850989","pt":1719504639933,"mc":[{"id":"1.230178175","rc":[{"atb":[[3.45,40.82],[1.75,0]],"id":52385912},{"atb":[[13.5,31.2]],"id":52385920},{"atb":[[6.4,0],[7.8,10]],"id":52385883},{"atb":[[3.7,37.04],[1.86,0]],"id":52385885},{"atb":[[3.95,33.9],[1.96,0]],"id":52385896},{"atb":[[3.6,38.46],[3.2,0]],"id":52385919},{"atb":[[2.82,54.95],[13,37]],"id":52385921},{"atb":[[19.5,22],[9.2,11],[7.4,0]],"id":52385903}],"con":true,"img":false}]}
{"op":"mcm","clk":"11550850995","pt":1719504640037,"mc":[{"id":"1.230178175","rc":[{"atb":[[2.1,0]],"id":52385921}],"con":true,"img":false}]}
{"op":"mcm","clk":"11550851005","pt":1719504640354,"mc":[{"id":"1.230178175","rc":[{"atb":[[14,13]],"id":52385907}],"con":true,"img":false}]}
{"op":"mcm","clk":"11550851011","pt":1719504640451,"mc":[{"id":"1.230178175","rc":[{"atb":[[27,8.93]],"id":52385889}],"con":true,"img":false}]}
{"op":"mcm","clk":"11550851014","pt":1719504640556,"mc":[{"id":"1.230178175","rc":[{"atb":[[13,8]],"id":52385907}],"con":true,"img":false}]}
{"op":"mcm","clk":"11550851026","pt":1719504640867,"mc":[{"id":"1.230178175","rc":[{"atb":[[27,0]],"id":52385889}],"con":true,"img":false}]}
{"op":"mcm","clk":"11550851037","pt":1719504641075,"mc":[{"id":"1.230178175","rc":[{"atb":[[13.5,42.74]],"id":52385920}],"con":true,"img":false}]}
{"op":"mcm","clk":"11550851050","pt":1719504641334,"mc":[{"id":"1.230178175","rc":[{"atl":[[42,14.63]],"id":52385912},{"atb":[[44,13.95]],"id":52385896}],"con":true,"img":false}]}
{"op":"mcm","clk":"11550851055","pt":1719504641438,"mc":[{"id":"1.230178175","rc":[{"atl":[[46,0]],"id":52385912},{"atb":[[30,20]],"id":52385889},{"atb":[[26,0]],"id":52385896}],"con":true,"img":false}]}
{"op":"mcm","clk":"11550851064","pt":1719504641644,"mc":[{"id":"1.230178175","rc":[{"atb":[[21,0]],"id":52385889}],"con":true,"img":false}]}
{"op":"mcm","clk":"11550851069","pt":1719504641754,"mc":[{"id":"1.230178175","rc":[{"atb":[[20,0]],"id":52385896}],"con":true,"img":false}]}
{"op":"mcm","clk":"11550851078","pt":1719504641968,"mc":[{"id":"1.230178175","rc":[{"atb":[[13.5,31.2]],"id":52385920},{"atb":[[13,0]],"id":52385907}],"con":true,"img":false}]}
{"op":"mcm","clk":"11550851082","pt":1719504642064,"mc":[{"id":"1.230178175","rc":[{"atl":[[40,2.5],[42,0],[48,5],[50,0]],"id":52385914},{"atb":[[15,8]],"id":52385907}],"con":true,"img":false}]}
{"op":"mcm","clk":"11550851090","pt":1719504642167,"mc":[{"id":"1.230178175","rc":[{"atl":[[38,0]],"id":52385914}],"con":true,"img":false}]}
{"op":"mcm","clk":"11550851097","pt":1719504642271,"mc":[{"id":"1.230178175","rc":[{"atl":[[38,15]],"id":52385914}],"con":true,"img":false}]}
{"op":"mcm","clk":"11550851128","pt":1719504642846,"mc":[{"id":"1.230178175","rc":[{"atl":[[36,2.5],[38,0],[44,5],[46,0]],"id":52385906},{"atb":[[9.2,0],[8.4,0],[9.4,2.5]],"id":52385920},{"atl":[[65,5],[75,0],[48,2.5],[55,0]],"id":52385892},{"atb":[[10,0],[9.2,0],[10.5,2.5]],"id":52385900},{"atb":[[10,0],[9.2,0],[11,2.5]],"id":52385919},{"atl":[[28,22.22]],"id":52385921}],"con":true,"img":false}]}
{"op":"mcm","clk":"11550851136","pt":1719504642945,"mc":[{"id":"1.230178175","rc":[{"atl":[[48,15.27]],"id":52385892}],"con":true,"img":false}]}
{"op":"mcm","clk":"11550851140","pt":1719504643048,"mc":[{"id":"1.230178175","rc":[{"atl":[[29,0]],"id":52385921}],"con":true,"img":false}]}
{"op":"mcm","clk":"11550851147","pt":1719504643153,"mc":[{"id":"1.230178175","rc":[{"atl":[[50,0]],"id":52385892}],"con":true,"img":false}]}
{"op":"mcm","clk":"11550851153","pt":1719504643256,"mc":[{"id":"1.230178175","rc":[{"atl":[[28,0]],"id":52385921}],"con":true,"img":false}]}
{"op":"mcm","clk":"11550851160","pt":1719504643359,"mc":[{"id":"1.230178175","rc":[{"atl":[[30,20]],"id":52385921}],"con":true,"img":false}]}
{"op":"mcm","clk":"11550851166","pt":1719504643566,"mc":[{"id":"1.230178175","rc":[{"atl":[[30,0]],"id":52385921}],"con":true,"img":false}]}
{"op":"mcm","clk":"11550851170","pt":1719504643622,"mc":[{"id":"1.230178175","rc":[{"atl":[[36,17.14]],"id":52385921}],"con":true,"img":false}]}
{"op":"mcm","clk":"11550851178","pt":1719504643826,"mc":[{"id":"1.230178175","rc":[{"atl":[[27,23.08]],"id":52385918}],"con":true,"img":false}]}
{"op":"mcm","clk":"11550851185","pt":1719504644033,"mc":[{"id":"1.230178175","rc":[{"atl":[[28,2.6]],"id":52385918}],"con":true,"img":false}]}
{"op":"mcm","clk":"11550851208","pt":1719504644460,"mc":[{"id":"1.230178175","rc":[{"atb":[[3.45,0],[4.6,27.78]],"id":52385912},{"atb":[[17,24]],"id":52385906},{"atb":[[8,2.5],[7.8,0],[7,13]],"id":52385907},{"atb":[[3.6,0],[2.78,56.18]],"id":52385919},{"atb":[[2.82,0],[2.34,74.63]],"id":52385921},{"atb":[[7.2,12],[5.8,0]],"id":52385899},{"atl":[[40,15.38]],"id":52385899}],"con":true,"img":false}]}
{"op":"mcm","clk":"11550851215","pt":1719504644554,"mc":[{"id":"1.230178175","rc":[{"atl":[[65,0],[46,2.5],[48,0],[60,5]],"id":52385913}],"con":true,"img":false}]}
{"op":"mcm","clk":"11550851225","pt":1719504644660,"mc":[{"id":"1.230178175","rc":[{"atb":[[14.5,0]],"id":52385906},{"atl":[[44,0]],"id":52385899}],"con":true,"img":false}]}
{"op":"mcm","clk":"11550851247","pt":1719504644969,"mc":[{"id":"1.230178175","rc":[{"atb":[[2.56,0],[3.35,42.55]],"id":52385914},{"atb":[[5.9,20.41],[5.4,0]],"id":52385900}],"con":true,"img":false}]}
{"op":"mcm","clk":"11550851290","pt":1719504645648,"mc":[{"id":"1.230178175","rc":[{"atb":[[16,18.4]],"id":52385890}],"con":true,"img":false}]}
{"op":"mcm","clk":"11550851294","pt":1719504645744,"mc":[{"id":"1.230178175","rc":[{"atb":[[18,6]],"id":52385890}],"con":true,"img":false}]}
{"op":"mcm","clk":"11550851389","pt":1719504647727,"mc":[{"id":"1.230178175","rc":[{"atb":[[12,0]],"id":52385918},{"atl":[[28,0]],"id":52385918},{"atb":[[9.8,0]],"id":52385920},{"atl":[[21,19.2]],"id":52385920},{"atb":[[11,0]],"id":52385890},{"atl":[[30,0]],"id":52385890},{"atl":[[27,0]],"id":52385904},{"atb":[[15,0]],"id":52385898},{"atb":[[13,0]],"id":52385900},{"atl":[[29,0]],"id":52385900},{"atb":[[12.5,0]],"id":52385919},{"atb":[[14.5,0]],"id":52385897},{"atl":[[32,0]],"id":52385897},{"atl":[[32,0]],"id":52385891},{"atb":[[13.5,0]],"id":52385905},{"atl":[[27,0]],"id":52385905}],"con":true,"img":false}]}
{"op":"mcm","clk":"11550851398","pt":1719504647834,"mc":[{"id":"1.230178175","rc":[{"atl":[[21,0]],"id":52385920},{"atl":[[29,0]],"id":52385890},{"atl":[[28,22.22]],"id":52385898},{"atl":[[28,0]],"id":52385900},{"atb":[[15,0]],"id":52385897},{"atl":[[30,0]],"id":52385897},{"atl":[[30,0]],"id":52385891}],"con":true,"img":false}]}
{"op":"mcm","clk":"11550851408","pt":1719504647996,"mc":[{"id":"1.230178175","rc":[{"atb":[[23,3.86]],"id":52385912},{"atb":[[17.5,3.16]],"id":52385906},{"atb":[[15,3.2]],"id":52385918},{"atl":[[26,3]],"id":52385918},{"atb":[[14,5.5]],"id":52385920},{"atl":[[28,5.32]],"id":52385920},{"atb":[[15,4]],"id":52385914},{"atb":[[50,2]],"id":52385883},{"atl":[[180,2]],"id":52385883},{"atb":[[19.5,3]],"id":52385896},{"atl":[[28,3.62],[30,15]],"id":52385890},{"atb":[[21,3]],"id":52385892},{"atl":[[46,2.5]],"id":52385892},{"atl":[[25,2],[26,0]],"id":52385904},{"atb":[[14.5,4.78]],"id":52385898},{"atl":[[29,2.83]],"id":52385898},{"atb":[[16,3.39]],"id":52385900},{"atl":[[44,13.95],[27,3.2]],"id":52385900},{"atb":[[22,3.9]],"id":52385911},{"atb":[[21,3]],"id":52385913},{"atb":[[38,2.51]],"id":52385886},{"atl":[[180,2]],"id":52385886},{"atb":[[17,5.4]],"id":52385919},{"atb":[[13.5,4.23]],"id":52385921},{"atl":[[34,5.5]],"id":52385921},{"atb":[[50,3]],"id":52385884},{"atb":[[30,3.6]],"id":52385917},{"atb":[[11.5,10],[15.5,3.12]],"id":52385897},{"atl":[[32,10],[29,3.3]],"id":52385897},{"atb":[[11,5.9]],"id":52385891},{"atl":[[32,15],[29,3.6]],"id":52385891},{"atb":[[20,3]],"id":52385903},{"atb":[[11.5,4.7]],"id":52385905},{"atl":[[25,2.6]],"id":52385905},{"atb":[[23,3.3]],"id":52385899}],"con":true,"img":false}]}
{"op":"mcm","clk":"11550851414","pt":1719504648039,"mc":[{"id":"1.230178175","rc":[{"atl":[[22,15]],"id":52385920},{"atl":[[27,22]],"id":52385904}],"con":true,"img":false}]}
{"op":"mcm","clk":"11550851421","pt":1719504648142,"mc":[{"id":"1.230178175","rc":[{"atb":[[23,25.86]],"id":52385912},{"atb":[[15,27.6]],"id":52385918},{"atb":[[15.5,18]],"id":52385914},{"atb":[[55,11.11]],"id":52385883},{"atb":[[21,25]],"id":52385892},{"atb":[[16.5,24.78]],"id":52385900},{"atb":[[22,25.9]],"id":52385911},{"atb":[[21,19]],"id":52385913},{"atb":[[40,15.38]],"id":52385886},{"atb":[[17,34.2]],"id":52385919},{"atb":[[55,11.11]],"id":52385884},{"atb":[[32,19.35]],"id":52385917},{"atb":[[21,22]],"id":52385903},{"atl":[[25,17.2]],"id":52385905},{"atb":[[23,27.3]],"id":52385899}],"con":true,"img":false}]}
{"op":"mcm","clk":"11550851433","pt":1719504648349,"mc":[{"id":"1.230178175","rc":[{"atb":[[14.5,0]],"id":52385918},{"atb":[[36,2.5]],"id":52385886}],"con":true,"img":false}]}
{"op":"mcm","clk":"11550851443","pt":1719504648473,"mc":[{"id":"1.230178175","rc":[{"atb":[[22,0]],"id":52385912},{"atb":[[14.5,0]],"id":52385914},{"atb":[[48,0]],"id":52385883},{"atb":[[20,0]],"id":52385892},{"atb":[[15.5,0]],"id":52385900},{"atb":[[21,0]],"id":52385911},{"atb":[[20,0]],"id":52385913},{"atb":[[16.5,0]],"id":52385919},{"atb":[[48,0]],"id":52385884},{"atb":[[29,0]],"id":52385917},{"atb":[[19.5,0]],"id":52385903},{"atl":[[26,0]],"id":52385905},{"atb":[[22,0]],"id":52385899}],"con":true,"img":false}]}
{"op":"mcm","clk":"11550851451","pt":1719504648662,"mc":[{"id":"1.230178175","rc":[{"atb":[[15,0]],"id":52385900}],"con":true,"img":false}]}
{"op":"mcm","clk":"11550851462","pt":1719504648870,"mc":[{"id":"1.230178175","rc":[{"atb":[[19,0]],"id":52385903}],"con":true,"img":false}]}
{"op":"mcm","clk":"11550851479","pt":1719504649030,"mc":[{"id":"1.230178175","rc":[{"atb":[[15,2.5]],"id":52385913}],"con":true,"img":false}]}
{"op":"mcm","clk":"11550851487","pt":1719504649133,"mc":[{"id":"1.230178175","rc":[{"atl":[[85,2],[120,0]],"id":52385912},{"atl":[[70,0],[55,2]],"id":52385906},{"atl":[[70,0],[55,2]],"id":52385918},{"atl":[[42,2.44],[48,0]],"id":52385920},{"atl":[[80,0],[60,2]],"id":52385914},{"atl":[[260,2],[340,0]],"id":52385883},{"atl":[[320,2],[420,0]],"id":52385885},{"atl":[[85,2],[110,0]],"id":52385892},{"atl":[[80,0],[60,2]],"id":52385900},{"atl":[[70,2],[90,0]],"id":52385913},{"atl":[[270,2],[340,0]],"id":52385886},{"atl":[[160,2]],"id":52385917},{"atl":[[65,2],[80,0]],"id":52385897},{"atl":[[75,0],[60,2]],"id":52385893},{"atl":[[130,2],[160,0]],"id":52385903},{"atl":[[65,0]],"id":52385905},{"atl":[[85,2],[120,0]],"id":52385899}],"con":true,"img":false}]}
{"op":"mcm","clk":"11550851499","pt":1719504649236,"mc":[{"id":"1.230178175","rc":[{"atl":[[65,0],[55,2]],"id":52385921},{"atb":[[20,0]],"id":52385917},{"atl":[[190,0]],"id":52385917},{"atl":[[48,2.13]],"id":52385905}],"con":true,"img":false}]}
{"op":"mcm","clk":"11550851513","pt":1719504649555,"mc":[{"id":"1.230178175","rc":[{"atb":[[1.53,150]],"id":52385912},{"atl":[[42,0]],"id":52385912},{"atb":[[6,17.5]],"id":52385920},{"atb":[[3.35,0],[1.67,148.1]],"id":52385914},{"atb":[[8.8,7.5],[7.8,0]],"id":52385883},{"atb":[[3.7,0],[1.49,142.18]],"id":52385885},{"atb":[[3.95,0],[4.4,29.41]],"id":52385896},{"atb":[[14,0]],"id":52385904},{"atb":[[20,0]],"id":52385898},{"atb":[[6.8,6.78],[5.9,0]],"id":52385900},{"atb":[[11,0],[8.8,12]],"id":52385911},{"atb":[[6.2,0],[4.4,29.41]],"id":52385913},{"atb":[[14,0]],"id":52385907},{"atl":[[36,2.86],[42,0]],"id":52385907},{"atb":[[1.35,105.79]],"id":52385886},{"atb":[[4.3,30.3],[2.78,0]],"id":52385919},{"atl":[[65,0],[25,25],[50,2.04]],"id":52385919},{"atb":[[2.56,64.1],[2.34,0]],"id":52385921},{"atb":[[14,0]],"id":52385897},{"atl":[[75,0],[60,2]],"id":52385891},{"atb":[[9.2,0],[10.5,8]],"id":52385903},{"atb":[[7.2,0],[5.7,21.28]],"id":52385899},{"atl":[[40,0]],"id":52385899}],"con":true,"img":false}]}
{"op":"mcm","clk":"11550851522","pt":1719504649653,"mc":[{"id":"1.230178175","rc":[{"atb":[[4.6,0]],"id":52385912},{"atl":[[55,11.11]],"id":52385912},{"atb":[[4.8,0]],"id":52385920},{"atb":[[5.3,23.26],[4.4,0]],"id":52385896},{"atb":[[16,6]],"id":52385904},{"atb":[[15,27.56]],"id":52385898},{"atb":[[8.8,0]],"id":52385911},{"atl":[[28,2]],"id":52385919},{"atb":[[16,8]],"id":52385897},{"atl":[[50,12.24]],"id":52385899}],"con":true,"img":false}]}
{"op":"mcm","clk":"11550851528","pt":1719504649756,"mc":[{"id":"1.230178175","rc":[{"atb":[[7.2,12]],"id":52385911},{"atl":[[38,15]],"id":52385913}],"con":true,"img":false}]}
{"op":"mcm","clk":"11550851533","pt":1719504649861,"mc":[{"id":"1.230178175","rc":[{"atb":[[34,18.18]],"id":52385889},{"atl":[[40,0]],"id":52385913}],"con":true,"img":false}]}
{"op":"mcm","clk":"11550851543","pt":1719504650067,"mc":[{"id":"1.230178175","rc":[{"atb":[[30,0]],"id":52385889}],"con":true,"img":false}]}
{"op":"mcm","clk":"11550851645","pt":1719504651836,"mc":[{"id":"1.230178175","rc":[{"atb":[[14,36.5]],"id":52385920}],"con":true,"img":false}]}
{"op":"mcm","clk":"11550851653","pt":1719504651937,"mc":[{"id":"1.230178175","rc":[{"atb":[[14,38]],"id":52385921}],"con":true,"img":false}]}
{"op":"mcm","clk":"11550851657","pt":1719504652041,"mc":[{"id":"1.230178175","rc":[{"atb":[[13.5,0]],"id":52385920}],"con":true,"img":false}]}
{"op":"mcm","clk":"11550851663","pt":1719504652145,"mc":[{"id":"1.230178175","rc":[{"atb":[[13,0]],"id":52385921}],"con":true,"img":false}]}
{"op":"mcm","clk":"11550851702","pt":1719504652669,"mc":[{"id":"1.230178175","rc":[{"atb":[[15,0]],"id":52385907}],"con":true,"img":false}]}
{"op":"mcm","clk":"11550851708","pt":1719504652773,"mc":[{"id":"1.230178175","rc":[{"atb":[[10,18],[14,8]],"id":52385907}],"con":true,"img":false}]}
{"op":"mcm","clk":"11550851764","pt":1719504653867,"mc":[{"id":"1.230178175","rc":[{"atl":[[28,18.2]],"id":52385893}],"con":true,"img":false}]}
{"op":"mcm","clk":"11550851776","pt":1719504654072,"mc":[{"id":"1.230178175","rc":[{"atl":[[29,2.6]],"id":52385893}],"con":true,"img":false}]}
{"op":"mcm","clk":"11550851782","pt":1719504654175,"mc":[{"id":"1.230178175","rc":[{"atl":[[36,17.14]],"id":52385914}],"con":true,"img":false}]}
{"op":"mcm","clk":"11550851796","pt":1719504654339,"mc":[{"id":"1.230178175","rc":[{"atl":[[100,2]],"id":52385912},{"atl":[[38,0]],"id":52385914}],"con":true,"img":false}]}
{"op":"mcm","clk":"11550851807","pt":1719504654439,"mc":[{"id":"1.230178175","rc":[{"atl":[[85,0]],"id":52385912}],"con":true,"img":false}]}
{"op":"mcm","clk":"11550851814","pt":1719504654546,"mc":[{"id":"1.230178175","rc":[{"atl":[[130,4.65],[160,2.5],[170,0],[200,5]],"id":52385910},{"atb":[[2.84,54.35],[1.53,0]],"id":52385912},{"atb":[[8.8,0]],"id":52385883},{"atb":[[1.49,0]],"id":52385885},{"atb":[[3.1,47.62],[5.3,0]],"id":52385896},{"atl":[[65,0],[50,2.04]],"id":52385904},{"atb":[[1.35,0]],"id":52385886},{"atb":[[11.5,0],[8.8,10]],"id":52385884},{"atb":[[40,15.38],[10.5,0]],"id":52385903}],"con":true,"img":false}]}
{"op":"mcm","clk":"11550851826","pt":1719504654648,"mc":[{"id":"1.230178175","rc":[{"atb":[[3.6,38.46]],"id":52385883},{"atb":[[7.6,10]],"id":52385903}],"con":true,"img":false}]}
{"op":"mcm","clk":"11550851836","pt":1719504654755,"mc":[{"id":"1.230178175","rc":[{"atb":[[3.1,0],[2.38,72.46]],"id":52385896},{"atl":[[28,22.22]],"id":52385921},{"atb":[[7.6,10]],"id":52385884},{"atb":[[21,0]],"id":52385903}],"con":true,"img":false}]}
{"op":"mcm","clk":"11550851844","pt":1719504654857,"mc":[{"id":"1.230178175","rc":[{"atl":[[44,13.95]],"id":52385892},{"atb":[[8.8,0]],"id":52385884}],"con":true,"img":false}]}
{"op":"mcm","clk":"11550851850","pt":1719504654963,"mc":[{"id":"1.230178175","rc":[{"atb":[[3.25,44.44],[1.67,0]],"id":52385914},{"atl":[[48,2.5]],"id":52385892},{"atb":[[9.2,11]],"id":52385911},{"atb":[[6,7],[4.4,0]],"id":52385913},{"atb":[[4.8,26.32],[4.3,0]],"id":52385919},{"atb":[[2.56,0],[3.6,38.46]],"id":52385921},{"atl":[[36,0]],"id":52385921},{"atb":[[6.8,12],[5.7,0]],"id":52385899}],"con":true,"img":false}]}
{"op":"mcm","clk":"11550851857","pt":1719504655066,"mc":[{"id":"1.230178175","rc":[{"atb":[[7.2,0]],"id":52385911}],"con":true,"img":false}]}
{"op":"mcm","clk":"11550851888","pt":1719504655639,"mc":[{"id":"1.230178175","rc":[{"atl":[[25,24]],"id":52385918}],"con":true,"img":false}]}
{"op":"mcm","clk":"11550851897","pt":1719504655842,"mc":[{"id":"1.230178175","rc":[{"atl":[[27,0]],"id":52385918}],"con":true,"img":false}]}
{"op":"mcm","clk":"11550851922","pt":1719504656363,"mc":[{"id":"1.230178175","rc":[{"atb":[[20,24]],"id":52385906}],"con":true,"img":false}]}
{"op":"mcm","clk":"11550851932","pt":1719504656574,"mc":[{"id":"1.230178175","rc":[{"atb":[[17,0]],"id":52385906}],"con":true,"img":false}]}
{"op":"mcm","clk":"11550852113","pt":1719504659787,"mc":[{"id":"1.230178175","rc":[{"atb":[[2.84,0],[3.05,49.68]],"id":52385912},{"atb":[[3.6,0]],"id":52385883},{"atl":[[150,4.03],[180,4.5],[190,0],[220,5]],"id":52385883},{"atl":[[320,0],[400,2]],"id":52385885},{"atb":[[2.38,0]],"id":52385896},{"atl":[[70,0]],"id":52385896},{"atl":[[27,19.24]],"id":52385890},{"atl":[[27,16.38]],"id":52385900},{"atl":[[150,4.03],[180,4.5],[190,0],[220,5]],"id":52385886},{"atb":[[20,0],[14,7.69]],"id":52385882},{"atl":[[200,5],[120,5.04]],"id":52385882},{"atb":[[7.6,0]],"id":52385884},{"atl":[[140,4.32],[170,2.5],[180,0],[210,5]],"id":52385884},{"atl":[[65,0]],"id":52385917},{"atb":[[16,30.6]],"id":52385897},{"atl":[[29,24.73]],"id":52385897},{"atl":[[28,19]],"id":52385891},{"atb":[[5,25],[7.6,0]],"id":52385903},{"atl":[[70,0],[80,2.5],[90,0],[100,5]],"id":52385903}],"con":true,"img":false}]}
{"op":"mcm","clk":"11550852119","pt":1719504659845,"mc":[{"id":"1.230178175","rc":[{"atb":[[34,0]],"id":52385889},{"atl":[[150,0]],"id":52385883},{"atl":[[85,7.14]],"id":52385896},{"atl":[[30,0]],"id":52385890},{"atl":[[24,20]],"id":52385904},{"atl":[[44,0]],"id":52385900},{"atl":[[150,0]],"id":52385886},{"atl":[[290,0],[120,0],[250,2]],"id":52385882},{"atb":[[1.5,110.02]],"id":52385884},{"atl":[[140,0],[290,2],[330,0]],"id":52385884},{"atl":[[75,8.11]],"id":52385917},{"atb":[[11.5,0]],"id":52385897},{"atl":[[32,0]],"id":52385897},{"atl":[[32,0]],"id":52385891},{"atl":[[65,0]],"id":52385903}],"con":true,"img":false}]}
{"op":"mcm","clk":"11550852126","pt":1719504659947,"mc":[{"id":"1.230178175","rc":[{"atb":[[34,18.18]],"id":52385889},{"atl":[[160,3.77]],"id":52385883},{"atl":[[27,0]],"id":52385904},{"atl":[[160,3.77]],"id":52385886},{"atl":[[130,4.65]],"id":52385882},{"atl":[[150,4.03]],"id":52385884},{"atl":[[70,8.7]],"id":52385903}],"con":true,"img":false}]}
{"op":"mcm","clk":"11550852155","pt":1719504660572,"mc":[{"id":"1.230178175","rc":[{"atb":[[44,0],[46,13.33]],"id":52385910},{"atl":[[46,13.33]],"id":52385912},{"atb":[[20,0]],"id":52385906},{"atb":[[16,18]],"id":52385914},{"atb":[[22,15]],"id":52385913}],"con":true,"img":false}]}
{"op":"mcm","clk":"11550852162","pt":1719504660680,"mc":[{"id":"1.230178175","rc":[{"atl":[[55,0]],"id":52385912},{"atb":[[19.5,16.32]],"id":52385906},{"atb":[[15.5,0]],"id":52385914},{"atl":[[160,0]],"id":52385883},{"atl":[[130,0]],"id":52385882},{"atl":[[150,0]],"id":52385884},{"atl":[[70,0]],"id":52385903}],"con":true,"img":false}]}
{"op":"mcm","clk":"11550852169","pt":1719504660781,"mc":[{"id":"1.230178175","rc":[{"atb":[[17.5,0]],"id":52385906},{"atl":[[26,0]],"id":52385918},{"atb":[[15,0]],"id":52385914},{"atb":[[50,0]],"id":52385883},{"atl":[[170,3.55]],"id":52385883},{"atl":[[28,0]],"id":52385890},{"atl":[[46,0]],"id":52385892},{"atl":[[25,0]],"id":52385904},{"atb":[[14.5,0]],"id":52385898},{"atl":[[29,0]],"id":52385898},{"atb":[[16,0]],"id":52385900},{"atb":[[21,3]],"id":52385913},{"atb":[[9.8,0]],"id":52385907},{"atb":[[38,0]],"id":52385886},{"atl":[[28,0]],"id":52385919},{"atb":[[13.5,0]],"id":52385921},{"atl":[[150,4.03]],"id":52385882},{"atb":[[50,0]],"id":52385884},{"atl":[[180,3.35]],"id":52385884},{"atb":[[30,0]],"id":52385917},{"atb":[[15.5,0]],"id":52385897},{"atb":[[11,0]],"id":52385891},{"atl":[[29,0]],"id":52385891},{"atb":[[12,0]],"id":52385893},{"atl":[[29,0]],"id":52385893},{"atb":[[20,0]],"id":52385903},{"atl":[[80,10.09]],"id":52385903},{"atb":[[11.5,0]],"id":52385905}],"con":true,"img":false}]}
{"op":"mcm","clk":"11550852178","pt":1719504660988,"mc":[{"id":"1.230178175","rc":[{"atb":[[46,15.33]],"id":52385910},{"atl":[[120,2]],"id":52385910},{"atb":[[15.5,5]],"id":52385906},{"atl":[[30,3.66]],"id":52385906},{"atl":[[24,3.06]],"id":52385918},{"atb":[[18.5,4.51]],"id":52385889},{"atl":[[75,2]],"id":52385889},{"atb":[[16,21.4]],"id":52385914},{"atl":[[34,3]],"id":52385914},{"atb":[[55,0],[60,2.9]],"id":52385883},{"atb":[[50,2.21]],"id":52385885},{"atl":[[220,5.04]],"id":52385885},{"atb":[[16.5,3.46]],"id":52385890},{"atl":[[26,3],[27,0]],"id":52385890},{"atl":[[42,2.82],[44,0]],"id":52385892},{"atl":[[23,2.46],[24,0]],"id":52385904},{"atb":[[15,0],[15.5,4]],"id":52385898},{"atl":[[27,3]],"id":52385898},{"atb":[[16.5,0],[17,4.41]],"id":52385900},{"atl":[[50,2]],"id":52385911},{"atl":[[36,2.8]],"id":52385913},{"atb":[[10.5,5.16]],"id":52385907},{"atb":[[42,3]],"id":52385886},{"atl":[[34,5.5]],"id":52385919},{"atb":[[14.5,5.2]],"id":52385921},{"atb":[[48,2.68]],"id":52385882},{"atl":[[120,2]],"id":52385882},{"atb":[[55,0],[60,2]],"id":52385884},{"atl":[[170,4.5]],"id":52385884},{"atb":[[32,0],[34,4]],"id":52385917},{"atl":[[70,2.8]],"id":52385917},{"atb":[[16.5,3.03]],"id":52385897},{"atb":[[16.5,5]],"id":52385891},{"atl":[[27,3],[28,0]],"id":52385891},{"atb":[[16.5,4.51]],"id":52385893},{"atl":[[27,3.2]],"id":52385893},{"atb":[[18,3.8]],"id":52385903},{"atb":[[16.5,4.35]],"id":52385905},{"atl":[[48,2.8]],"id":52385899}],"con":true,"img":false}]}
{"op":"mcm","clk":"11550852185","pt":1719504661097,"mc":[{"id":"1.230178175","rc":[{"atl":[[120,7.04]],"id":52385910},{"atl":[[30,24.35]],"id":52385906},{"atl":[[70,8.7],[150,0],[120,2]],"id":52385889},{"atb":[[65,9.38]],"id":52385883},{"atb":[[55,11.11]],"id":52385885},{"atl":[[26,15.92]],"id":52385890},{"atl":[[40,10.64]],"id":52385892},{"atl":[[23,15.46]],"id":52385904},{"atb":[[15.5,18]],"id":52385898},{"atl":[[27,17]],"id":52385898},{"atb":[[17,18.23]],"id":52385900},{"atl":[[90,2],[50,14.24],[110,0]],"id":52385911},{"atb":[[44,13.95]],"id":52385886},{"atb":[[50,12.24]],"id":52385882},{"atb":[[65,9.38]],"id":52385884},{"atb":[[36,10.6]],"id":52385917},{"atb":[[16.5,16]],"id":52385891},{"atl":[[26,11]],"id":52385891},{"atb":[[16.5,19.93]],"id":52385893},{"atl":[[48,15.57]],"id":52385899}],"con":true,"img":false}]}
{"op":"mcm","clk":"11550852191","pt":1719504661188,"mc":[{"id":"1.230178175","rc":[{"atl":[[55,2.5]],"id":52385911},{"atl":[[50,0]],"id":52385899}],"con":true,"img":false}]}
{"op":"mcm","clk":"11550852196","pt":1719504661298,"mc":[{"id":"1.230178175","rc":[{"atl":[[130,0]],"id":52385910},{"atl":[[32,0]],"id":52385906},{"atb":[[48,0]],"id":52385885},{"atl":[[28,0]],"id":52385898},{"atb":[[40,0]],"id":52385886},{"atb":[[46,0]],"id":52385882},{"atb":[[16,6]],"id":52385891},{"atb":[[16,6]],"id":52385893}],"con":true,"img":false}]}
{"op":"mcm","clk":"11550852201","pt":1719504661349,"mc":[{"id":"1.230178175","rc":[{"atl":[[80,2.5]],"id":52385889}],"con":true,"img":false}]}
{"op":"mcm","clk":"11550852208","pt":1719504661459,"mc":[{"id":"1.230178175","rc":[{"atl":[[36,14.4]],"id":52385913}],"con":true,"img":false}]}
{"op":"mcm","clk":"11550852220","pt":1719504661661,"mc":[{"id":"1.230178175","rc":[{"atl":[[38,0]],"id":52385913}],"con":true,"img":false}]}
{"op":"mcm","clk":"11550852323","pt":1719504663678,"mc":[{"id":"1.230178175","rc":[{"atb":[[14.5,43.2]],"id":52385921}],"con":true,"img":false}]}
{"op":"mcm","clk":"11550852334","pt":1719504663889,"mc":[{"id":"1.230178175","rc":[{"atb":[[14,0]],"id":52385921}],"con":true,"img":false}]}
{"op":"mcm","clk":"11550852406","pt":1719504665493,"mc":[{"id":"1.230178175","rc":[{"atl":[[27,21.6]],"id":52385893}],"con":true,"img":false}]}
{"op":"mcm","clk":"11550852415","pt":1719504665599,"mc":[{"id":"1.230178175","rc":[{"atl":[[28,0]],"id":52385893}],"con":true,"img":false}]}
{"op":"mcm","clk":"11550852429","pt":1719504665799,"mc":[{"id":"1.230178175","rc":[{"atl":[[34,14]],"id":52385914}],"con":true,"img":false}]}
{"op":"mcm","clk":"11550852449","pt":1719504666065,"mc":[{"id":"1.230178175","rc":[{"atl":[[36,0]],"id":52385914}],"con":true,"img":false}]}
{"op":"mcm","clk":"11550852511","pt":1719504667303,"mc":[{"id":"1.230178175","rc":[{"atl":[[24,27.18]],"id":52385918}],"con":true,"img":false}]}
{"op":"mcm","clk":"11550852524","pt":1719504667505,"mc":[{"id":"1.230178175","rc":[{"atl":[[25,0]],"id":52385918}],"con":true,"img":false}]}
{"op":"mcm","clk":"11550852635","pt":1719504669410,"mc":[{"id":"1.230178175","rc":[{"atb":[[5.4,22.73]],"id":52385919},{"atb":[[16.5,6.45],[14,0]],"id":52385882},{"atb":[[3.95,33.9],[1.5,0]],"id":52385884},{"atb":[[5,0],[6,10.8]],"id":52385903},{"atl":[[75,2.5],[80,7.59],[95,5],[100,0]],"id":52385903}],"con":true,"img":false}]}
{"op":"mcm","clk":"11550852643","pt":1719504669491,"mc":[{"id":"1.230178175","rc":[{"atb":[[2.46,68.49],[3.05,0.9]],"id":52385912},{"atb":[[6,2],[7,16.67]],"id":52385920},{"atb":[[3.25,0],[3.5,40]],"id":52385914},{"atb":[[4.8,0]],"id":52385919},{"atb":[[3.6,0],[4.2,31.25]],"id":52385921},{"atb":[[2.68,59.52]],"id":52385884},{"atb":[[5.3,23.26],[6,1.99]],"id":52385903}],"con":true,"img":false}]}
{"op":"mcm","clk":"11550852650","pt":1719504669588,"mc":[{"id":"1.230178175","rc":[{"atb":[[3.95,0]],"id":52385884}],"con":true,"img":false}]}
{"op":"mcm","clk":"11550852730","pt":1719504671198,"mc":[{"id":"1.230178175","rc":[{"atb":[[40,0]],"id":52385903}],"con":true,"img":false}]}
{"op":"mcm","clk":"11550852733","pt":1719504671296,"mc":[{"id":"1.230178175","rc":[{"atb":[[16.5,19.08]],"id":52385897}],"con":true,"img":false}]}
{"op":"mcm","clk":"11550852738","pt":1719504671400,"mc":[{"id":"1.230178175","rc":[{"atl":[[70,11.5]],"id":52385917},{"atb":[[38,12.6]],"id":52385903}],"con":true,"img":false}]}
{"op":"mcm","clk":"11550852742","pt":1719504671500,"mc":[{"id":"1.230178175","rc":[{"atl":[[120,7.04]],"id":52385882},{"atl":[[160,3.77]],"id":52385884},{"atl":[[75,0]],"id":52385917},{"atb":[[16,8]],"id":52385897},{"atb":[[38,0]],"id":52385903},{"atl":[[70,8.7]],"id":52385903}],"con":true,"img":false}]}
{"op":"mcm","clk":"11550852745","pt":1719504671605,"mc":[{"id":"1.230178175","rc":[{"atl":[[150,0]],"id":52385882},{"atb":[[38,16.22]],"id":52385903}],"con":true,"img":false}]}
{"op":"mcm","clk":"11550852750","pt":1719504671703,"mc":[{"id":"1.230178175","rc":[{"atl":[[180,0]],"id":52385884},{"atl":[[80,0]],"id":52385903}],"con":true,"img":false}]}
{"op":"mcm","clk":"11550852756","pt":1719504671809,"mc":[{"id":"1.230178175","rc":[{"atb":[[22,17.64]],"id":52385892},{"atb":[[23,22]],"id":52385911},{"atl":[[120,2]],"id":52385882},{"atb":[[38,0],[40,15.38]],"id":52385903}],"con":true,"img":false}]}
{"op":"mcm","clk":"11550852770","pt":1719504671970,"mc":[{"id":"1.230178175","rc":[{"atb":[[21,3]],"id":52385892},{"atb":[[22,3.9]],"id":52385911},{"atb":[[40,0]],"id":52385903}],"con":true,"img":false}]}
{"op":"mcm","clk":"11550852778","pt":1719504672071,"mc":[{"id":"1.230178175","rc":[{"atb":[[36,17.14]],"id":52385903}],"con":true,"img":false}]}
{"op":"mcm","clk":"11550852870","pt":1719504673994,"mc":[{"id":"1.230178175","rc":[{"atl":[[120,5.04]],"id":52385910},{"atb":[[15.5,0]],"id":52385906},{"atl":[[75,0]],"id":52385889},{"atb":[[60,0]],"id":52385883},{"atb":[[50,0]],"id":52385885},{"atl":[[220,2.74]],"id":52385885},{"atb":[[19.5,0]],"id":52385896},{"atb":[[21,0]],"id":52385892},{"atl":[[42,0]],"id":52385892},{"atb":[[22,0]],"id":52385911},{"atb":[[21,0]],"id":52385913},{"atl":[[36,11.6]],"id":52385913},{"atb":[[42,0]],"id":52385886},{"atb":[[48,0]],"id":52385882},{"atl":[[120,0]],"id":52385882},{"atb":[[60,0]],"id":52385884},{"atb":[[34,0]],"id":52385917},{"atb":[[16.5,11]],"id":52385891},{"atl":[[27,0]],"id":52385891},{"atb":[[16.5,15.42]],"id":52385893},{"atb":[[18,0]],"id":52385903}],"con":true,"img":false}]}
{"op":"mcm","clk":"11550852875","pt":1719504674103,"mc":[{"id":"1.230178175","rc":[{"atl":[[130,4.65]],"id":52385882}],"con":true,"img":false}]}
{"op":"mcm","clk":"11550852881","pt":1719504674213,"mc":[{"id":"1.230178175","rc":[{"atl":[[150,2],[120,0]],"id":52385910},{"atb":[[14.5,4]],"id":52385906},{"atl":[[65,2.4],[70,0]],"id":52385889},{"atb":[[70,2]],"id":52385883},{"atb":[[55,0],[60,2.17]],"id":52385885},{"atb":[[46,2]],"id":52385896},{"atb":[[23,2.6]],"id":52385892},{"atl":[[38,2.1],[40,0]],"id":52385892},{"atb":[[24,4.1]],"id":52385911},{"atb":[[23,2.96]],"id":52385913},{"atl":[[36,0],[46,4.5]],"id":52385913},{"atb":[[46,3]],"id":52385886},{"atb":[[50,0],[55,2]],"id":52385882},{"atl":[[150,2]],"id":52385882},{"atb":[[70,2.5]],"id":52385884},{"atb":[[28,2.59]],"id":52385917},{"atb":[[14,3.33]],"id":52385891},{"atl":[[25,2.72],[26,0]],"id":52385891},{"atb":[[14,4.91]],"id":52385893},{"atb":[[38,3]],"id":52385903}],"con":true,"img":false}]}
{"op":"mcm","clk":"11550852885","pt":1719504674298,"mc":[{"id":"1.230178175","rc":[{"atb":[[75,8.11]],"id":52385883},{"atl":[[38,12.3]],"id":52385892},{"atb":[[23,17.88]],"id":52385913},{"atb":[[48,12.77]],"id":52385886},{"atb":[[60,9]],"id":52385882},{"atl":[[130,0]],"id":52385882}],"con":true,"img":false}]}
{"op":"mcm","clk":"11550852892","pt":1719504674412,"mc":[{"id":"1.230178175","rc":[{"atl":[[130,4.65]],"id":52385910},{"atb":[[65,0]],"id":52385883},{"atb":[[65,9.38]],"id":52385885},{"atb":[[46,15.33]],"id":52385896},{"atb":[[22,0]],"id":52385913},{"atl":[[38,14.92]],"id":52385913},{"atb":[[44,0]],"id":52385886},{"atl":[[140,4.32]],"id":52385882},{"atb":[[70,11.2]],"id":52385884},{"atl":[[25,14.82]],"id":52385891}],"con":true,"img":false}]}
{"op":"mcm","clk":"11550852903","pt":1719504674611,"mc":[{"id":"1.230178175","rc":[{"atl":[[260,0],[310,2]],"id":52385883},{"atl":[[270,0],[290,2.5],[330,5],[230,0]],"id":52385885},{"atb":[[44,0]],"id":52385896},{"atl":[[70,0],[55,2]],"id":52385890},{"atl":[[70,0],[55,2]],"id":52385898},{"atb":[[6.8,0],[7.8,14.71]],"id":52385900},{"atl":[[270,0],[310,2]],"id":52385886},{"atl":[[32,2.5],[34,3],[40,5],[42,0]],"id":52385919},{"atb":[[16.5,0],[8.2,10]],"id":52385882},{"atb":[[65,0],[2.68,0]],"id":52385884},{"atl":[[80,0],[90,2.5],[100,0],[120,5]],"id":52385917},{"atb":[[16.5,0]],"id":52385891},{"atb":[[7.6,11],[8.8,0]],"id":52385893},{"atb":[[5.3,0],[2.08,92.59]],"id":52385903}],"con":true,"img":false}]}
{"op":"mcm","clk":"11550852910","pt":1719504674713,"mc":[{"id":"1.230178175","rc":[{"atb":[[2.84,54.35]],"id":52385912},{"atb":[[38,10]],"id":52385889},{"atb":[[16,22.66]],"id":52385891}],"con":true,"img":false}]}
{"op":"mcm","clk":"11550852914","pt":1719504674812,"mc":[{"id":"1.230178175","rc":[{"atb":[[2.46,0]],"id":52385912}],"con":true,"img":false}]}
{"op":"mcm","clk":"11550852920","pt":1719504674882,"mc":[{"id":"1.230178175","rc":[{"atb":[[34,0]],"id":52385889}],"con":true,"img":false}]}
{"op":"mcm","clk":"11550852925","pt":1719504675019,"mc":[{"id":"1.230178175","rc":[{"atl":[[130,0]],"id":52385910}],"con":true,"img":false}]}
{"op":"mcm","clk":"11550852933","pt":1719504675083,"mc":[{"id":"1.230178175","rc":[{"atl":[[140,4.32]],"id":52385910}],"con":true,"img":false}]}
{"op":"mcm","clk":"11550853054","pt":1719504677103,"mc":[{"id":"1.230178175","rc":[{"atb":[[16.5,28]],"id":52385898}],"con":true,"img":false}]}
{"op":"mcm","clk":"11550853069","pt":1719504677310,"mc":[{"id":"1.230178175","rc":[{"atb":[[15.5,4]],"id":52385898}],"con":true,"img":false}]}
{"op":"mcm","clk":"11550853200","pt":1719504679908,"mc":[{"id":"1.230178175","rc":[{"atb":[[2.84,0],[2.94,51.55]],"id":52385912},{"atl":[[36,2.86],[42,0]],"id":52385920},{"atb":[[38,0]],"id":52385889},{"atb":[[3.5,0],[3.75,36.36]],"id":52385914},{"atl":[[400,0],[470,2]],"id":52385885},{"atl":[[150,5],[90,0],[110,2.5],[120,0]],"id":52385896},{"atl":[[34,2.5],[36,0],[42,5],[44,0]],"id":52385898},{"atb":[[8.2,0],[6.6,10]],"id":52385882},{"atb":[[1.16,258.87],[2.08,0]],"id":52385903},{"atl":[[75,0],[85,2.5],[95,0],[110,5]],"id":52385903}],"con":true,"img":false}]}
{"op":"mcm","clk":"11550853206","pt":1719504680012,"mc":[{"id":"1.230178175","rc":[{"atb":[[36,14.02]],"id":52385889},{"atb":[[4,33.33]],"id":52385914},{"atl":[[140,0]],"id":52385882}],"con":true,"img":false}]}
{"op":"mcm","clk":"11550853213","pt":1719504680116,"mc":[{"id":"1.230178175","rc":[{"atb":[[3.3,43.48],[2.94,0]],"id":52385912},{"atb":[[3.75,0]],"id":52385914},{"atl":[[85,0]],"id":52385896},{"atl":[[150,6.03]],"id":52385882},{"atb":[[1.16,0],[2.16,86.21]],"id":52385903},{"atl":[[70,0]],"id":52385903}],"con":true,"img":false}]}
{"op":"mcm","clk":"11550853217","pt":1719504680224,"mc":[{"id":"1.230178175","rc":[{"atb":[[38,2.5],[26,0]],"id":52385910},{"atl":[[32,5],[34,0],[27,2.5],[28,2.82]],"id":52385920},{"atb":[[65,11.88],[32,0],[40,0],[48,5]],"id":52385885},{"atl":[[90,6.74]],"id":52385896},{"atl":[[38,2.5],[42,0],[46,5],[50,0]],"id":52385890},{"atl":[[32,2.5],[34,0],[40,5],[42,0]],"id":52385904},{"atl":[[36,2.5],[38,0],[44,5],[46,0]],"id":52385897},{"atl":[[36,2.5],[40,0],[44,5],[48,0]],"id":52385891},{"atl":[[34,2.5],[38,0],[42,5],[46,0]],"id":52385893},{"atl":[[130,0],[75,8.11],[160,2]],"id":52385903}],"con":true,"img":false}]}
{"op":"mcm","clk":"11550853275","pt":1719504681214,"mc":[{"id":"1.230178175","rc":[{"atl":[[90,0]],"id":52385896},{"atl":[[75,0]],"id":52385903}],"con":true,"img":false}]}
{"op":"mcm","clk":"11550853282","pt":1719504681319,"mc":[{"id":"1.230178175","rc":[{"atl":[[100,6.06]],"id":52385896},{"atl":[[80,7.59]],"id":52385903}],"con":true,"img":false}]}
{"op":"mcm","clk":"11550853299","pt":1719504681726,"mc":[{"id":"1.230178175","rc":[{"atl":[[34,2.5],[36,0],[42,5],[44,0]],"id":52385918},{"atb":[[18,0],[19,5],[20,0],[22,2.5]],"id":52385889},{"atb":[[32,0],[42,5],[50,2.5],[27,0]],"id":52385883},{"atb":[[19,0],[22,0],[26,5],[30,2.5]],"id":52385896},{"atb":[[36,0],[38,5],[46,2.5],[29,0]],"id":52385882},{"atb":[[20,5],[24,2.5]],"id":52385903}],"con":true,"img":false}]}
{"op":"mcm","clk":"11550853305","pt":1719504681787,"mc":[{"id":"1.230178175","rc":[{"atb":[[15,0],[17,0]],"id":52385903}],"con":true,"img":false}]}
{"op":"mcm","clk":"11550853334","pt":1719504682416,"mc":[{"id":"1.230178175","rc":[{"atb":[[36,0],[46,8],[29,0],[60,2.5]],"id":52385886}],"con":true,"img":false}]}
{"op":"mcm","clk":"11550853356","pt":1719504682826,"mc":[{"id":"1.230178175","rc":[{"atb":[[38,19]],"id":52385903}],"con":true,"img":false}]}
{"op":"mcm","clk":"11550853367","pt":1719504683024,"mc":[{"id":"1.230178175","rc":[{"atb":[[36,0]],"id":52385903}],"con":true,"img":false}]}
{"op":"mcm","clk":"11550853377","pt":1719504683100,"mc":[{"id":"1.230178175","rc":[{"atb":[[23,24.6]],"id":52385892},{"atb":[[24,26.1]],"id":52385911}],"con":true,"img":false}]}
{"op":"mcm","clk":"11550853387","pt":1719504683305,"mc":[{"id":"1.230178175","rc":[{"atb":[[22,0]],"id":52385892},{"atb":[[23,0]],"id":52385911}],"con":true,"img":false}]}
{"op":"mcm","clk":"11550853419","pt":1719504683809,"mc":[{"id":"1.230178175","rc":[{"atb":[[32,0],[42,5],[50,2.5],[27,0]],"id":52385884},{"atb":[[17.5,0],[20,5],[24,2.5],[15.5,0]],"id":52385917}],"con":true,"img":false}]}
{"op":"mcm","clk":"11550853503","pt":1719504685113,"mc":[{"id":"1.230178175","rc":[{"atb":[[11,7.5],[6.6,0]],"id":52385882}],"con":true,"img":false}]}
{"op":"mcm","clk":"11550853525","pt":1719504685529,"mc":[{"id":"1.230178175","rc":[{"atb":[[65,9.38]],"id":52385886}],"con":true,"img":false}]}
{"op":"mcm","clk":"11550853532","pt":1719504685590,"mc":[{"id":"1.230178175","rc":[{"atb":[[70,8.7]],"id":52385885},{"atb":[[48,0]],"id":52385886}],"con":true,"img":false}]}
{"op":"mcm","clk":"11550853544","pt":1719504685796,"mc":[{"id":"1.230178175","rc":[{"atb":[[65,2.49]],"id":52385885}],"con":true,"img":false}]}
{"op":"mcm","clk":"11550853633","pt":1719504687095,"mc":[{"id":"1.230178175","rc":[{"atl":[[150,0]],"id":52385910},{"atb":[[18.5,0]],"id":52385889},{"atl":[[65,9.38]],"id":52385889},{"atb":[[70,0]],"id":52385883},{"atl":[[180,2.5]],"id":52385883},{"atb":[[60,0]],"id":52385885},{"atb":[[23,22]],"id":52385892},{"atb":[[15.5,0]],"id":52385898},{"atl":[[46,2.5]],"id":52385913},{"atb":[[46,5]],"id":52385886},{"atl":[[180,2.5]],"id":52385886},{"atl":[[34,2.5]],"id":52385921},{"atb":[[55,0]],"id":52385882},{"atl":[[170,2.5]],"id":52385884},{"atb":[[28,0]],"id":52385917},{"atb":[[14,0]],"id":52385891}],"con":true,"img":false}]}
{"op":"mcm","clk":"11550853641","pt":1719504687202,"mc":[{"id":"1.230178175","rc":[{"atb":[[1.89,112.36],[3.3,0]],"id":52385912},{"atl":[[46,0]],"id":52385912},{"atb":[[11,0],[13,0],[13.5,2.5],[21,24]],"id":52385906},{"atb":[[4,0],[3.35,42.55]],"id":52385914},{"atl":[[270,5],[180,0],[220,0],[230,2.5]],"id":52385883},{"atl":[[170,0],[210,2]],"id":52385896},{"atb":[[16,0],[10.5,0],[12.5,0]],"id":52385890},{"atb":[[23,0]],"id":52385892},{"atb":[[15,0]],"id":52385904},{"atb":[[9.2,0],[10.5,10.53]],"id":52385911},{"atb":[[6,2],[5.4,22.73]],"id":52385913},{"atl":[[180,0],[210,2.5],[220,0],[250,5]],"id":52385886},{"atb":[[4.6,27.78],[5.4,0]],"id":52385919},{"atl":[[25,0]],"id":52385919},{"atl":[[170,0],[250,5]],"id":52385884},{"atb":[[16,6],[10.5,0],[8.2,0],[12.5,0]],"id":52385891},{"atb":[[16.5,0]],"id":52385893},{"atb":[[2.16,0]],"id":52385903},{"atb":[[16.5,23.05]],"id":52385905},{"atb":[[5.5,22.22],[6.8,0]],"id":52385899}],"con":true,"img":false}]}
{"op":"mcm","clk":"11550853650","pt":1719504687295,"mc":[{"id":"1.230178175","rc":[{"atl":[[130,3],[140,0]],"id":52385910},{"atl":[[55,11.11],[60,4.5]],"id":52385912},{"atb":[[19.5,0]],"id":52385906},{"atb":[[36,0],[38,3.1]],"id":52385889},{"atl":[[65,0],[75,2]],"id":52385889},{"atb":[[80,2]],"id":52385883},{"atb":[[85,3]],"id":52385885},{"atl":[[280,2],[220,0]],"id":52385885},{"atl":[[95,2.6]],"id":52385896},{"atb":[[22,22],[15.5,4.29]],"id":52385892},{"atb":[[17,3.32]],"id":52385898},{"atl":[[36,3.1]],"id":52385913},{"atb":[[70,2]],"id":52385886},{"atl":[[30,20.69]],"id":52385919},{"atl":[[27,3.72]],"id":52385921},{"atb":[[65,2]],"id":52385882},{"atb":[[38,2.3]],"id":52385917},{"atb":[[9.2,2.5],[12.5,6],[7,10],[8.4,5]],"id":52385891},{"atb":[[16,7]],"id":52385905}],"con":true,"img":false}]}
{"op":"mcm","clk":"11550853660","pt":1719504687410,"mc":[{"id":"1.230178175","rc":[{"atl":[[130,6.87]],"id":52385910},{"atl":[[75,10.11]],"id":52385889},{"atb":[[85,7.14]],"id":52385883},{"atl":[[280,4.15]],"id":52385885},{"atb":[[9.6,2.5],[8.8,5]],"id":52385890},{"atl":[[36,14.3]],"id":52385913},{"atl":[[27,26.8]],"id":52385921},{"atb":[[70,8.7]],"id":52385882},{"atl":[[160,0]],"id":52385884},{"atb":[[40,15]],"id":52385917}],"con":true,"img":false}]}
{"op":"mcm","clk":"11550853666","pt":1719504687503,"mc":[{"id":"1.230178175","rc":[{"atb":[[75,0]],"id":52385883},{"atl":[[38,0]],"id":52385913},{"atl":[[28,0]],"id":52385921},{"atl":[[170,3.55]],"id":52385884}],"con":true,"img":false}]}
{"op":"mcm","clk":"11550853675","pt":1719504687613,"mc":[{"id":"1.230178175","rc":[{"atb":[[60,0]],"id":52385882},{"atb":[[36,0]],"id":52385917}],"con":true,"img":false}]}
{"op":"mcm","clk":"11550853706","pt":1719504688124,"mc":[{"id":"1.230178175","rc":[{"atl":[[170,0]],"id":52385884},{"atl":[[44,13.95]],"id":52385899}],"con":true,"img":false}]}
{"op":"mcm","clk":"11550853711","pt":1719504688230,"mc":[{"id":"1.230178175","rc":[{"atl":[[40,7.9]],"id":52385914},{"atl":[[200,3.02]],"id":52385884}],"con":true,"img":false}]}
{"op":"mcm","clk":"11550853722","pt":1719504688293,"mc":[{"id":"1.230178175","rc":[{"atb":[[19.5,28]],"id":52385898},{"atl":[[48,2.8]],"id":52385899}],"con":true,"img":false}]}
{"op":"mcm","clk":"11550853727","pt":1719504688391,"mc":[{"id":"1.230178175","rc":[{"atl":[[40,2.5]],"id":52385914}],"con":true,"img":false}]}
{"op":"mcm","clk":"11550853734","pt":1719504688503,"mc":[{"id":"1.230178175","rc":[{"atb":[[16.5,0]],"id":52385898}],"con":true,"img":false}]}
{"op":"mcm","clk":"11550853744","pt":1719504688700,"mc":[{"id":"1.230178175","rc":[{"atb":[[14,0]],"id":52385898}],"con":true,"img":false}]}
{"op":"mcm","clk":"11550853873","pt":1719504690697,"mc":[{"id":"1.230178175","rc":[{"atb":[[14,0]],"id":52385906},{"atb":[[13,0]],"id":52385920},{"atb":[[18,0]],"id":52385890}],"con":true,"img":false}]}
{"op":"mcm","clk":"11550853880","pt":1719504690800,"mc":[{"id":"1.230178175","rc":[{"atb":[[16,7]],"id":52385906},{"atb":[[14,46.5]],"id":52385920},{"atb":[[16,6]],"id":52385890}],"con":true,"img":false}]}
{"op":"mcm","clk":"11550853885","pt":1719504690904,"mc":[{"id":"1.230178175","rc":[{"atb":[[9.6,2.5],[8.8,17]],"id":52385898}],"con":true,"img":false}]}
{"op":"mcm","clk":"11550853891","pt":1719504691012,"mc":[{"id":"1.230178175","rc":[{"atb":[[9.4,0]],"id":52385898}],"con":true,"img":false}]}
{"op":"mcm","clk":"11550853908","pt":1719504691319,"mc":[{"id":"1.230178175","rc":[{"atl":[[95,8.98]],"id":52385896}],"con":true,"img":false}]}
{"op":"mcm","clk":"11550853922","pt":1719504691519,"mc":[{"id":"1.230178175","rc":[{"atl":[[100,0]],"id":52385896}],"con":true,"img":false}]}
{"op":"mcm","clk":"11550853955","pt":1719504692099,"mc":[{"id":"1.230178175","rc":[{"atb":[[42,14.63]],"id":52385903}],"con":true,"img":false}]}
{"op":"mcm","clk":"11550853968","pt":1719504692302,"mc":[{"id":"1.230178175","rc":[{"atb":[[38,3]],"id":52385903}],"con":true,"img":false}]}
{"op":"mcm","clk":"11550853974","pt":1719504692408,"mc":[{"id":"1.230178175","rc":[{"atb":[[48,12.77]],"id":52385910},{"atb":[[24,22]],"id":52385912},{"atl":[[25,19.82]],"id":52385893}],"con":true,"img":false}]}
{"op":"mcm","clk":"11550853977","pt":1719504692517,"mc":[{"id":"1.230178175","rc":[{"atb":[[46,2]],"id":52385910},{"atb":[[1.89,0],[2.76,56.82],[23,3.86]],"id":52385912},{"atb":[[7.4,14],[8.8,0]],"id":52385906},{"atl":[[42,2.5],[50,5]],"id":52385906},{"atl":[[46,2.22],[55,0]],"id":52385918},{"atb":[[7,0]],"id":52385920},{"atb":[[3.85,35.09],[3.35,0]],"id":52385914},{"atb":[[11,0]],"id":52385892},{"atb":[[4.8,26.32],[5.4,0]],"id":52385913},{"atb":[[14,34.32]],"id":52385907},{"atb":[[5.3,23.26]],"id":52385919},{"atb":[[11,0],[13.5,7.5]],"id":52385882},{"atl":[[290,0],[330,2]],"id":52385884},{"atb":[[11.5,0],[9.8,0]],"id":52385893},{"atl":[[48,2.13],[25,0],[27,3.2],[60,0]],"id":52385893},{"atl":[[130,5],[85,0],[95,2.5],[110,0]],"id":52385903},{"atb":[[9,0],[8.2,0],[9.4,2.5],[8.6,5]],"id":52385905},{"atb":[[6.4,12],[5.5,0]],"id":52385899}],"con":true,"img":false}]}
{"op":"mcm","clk":"11550853985","pt":1719504692621,"mc":[{"id":"1.230178175","rc":[{"atb":[[2.76,0],[3.95,33.9]],"id":52385912},{"atl":[[36,0],[44,0]],"id":52385906},{"atb":[[6.2,19.23]],"id":52385920},{"atl":[[110,2],[120,0]],"id":52385889},{"atb":[[3.85,0],[4.7,27.03]],"id":52385914},{"atb":[[9.4,11]],"id":52385892},{"atl":[[70,2],[85,0]],"id":52385892},{"atb":[[4.8,0],[18,6.25],[5.9,20.41]],"id":52385913},{"atb":[[10,0]],"id":52385907},{"atb":[[4.6,0]],"id":52385919},{"atb":[[4.8,26.32],[4.2,0]],"id":52385921},{"atl":[[48,2.13],[60,0]],"id":52385891},{"atb":[[8.2,2.5],[7.4,5]],"id":52385893},{"atl":[[26,21.82]],"id":52385893}],"con":true,"img":false}]}
{"op":"mcm","clk":"11550853991","pt":1719504692719,"mc":[{"id":"1.230178175","rc":[{"atl":[[80,0]],"id":52385903}],"con":true,"img":false}]}
{"op":"mcm","clk":"11550853998","pt":1719504692821,"mc":[{"id":"1.230178175","rc":[{"atb":[[18,0]],"id":52385913},{"atl":[[85,7.14]],"id":52385903}],"con":true,"img":false}]}
{"op":"mcm","clk":"11550854022","pt":1719504693241,"mc":[{"id":"1.230178175","rc":[{"atl":[[85,0]],"id":52385903}],"con":true,"img":false}]}
{"op":"mcm","clk":"11550854030","pt":1719504693300,"mc":[{"id":"1.230178175","rc":[{"atl":[[95,8.88]],"id":52385903}],"con":true,"img":false}]}
{"op":"mcm","clk":"11550854119","pt":1719504694799,"mc":[{"id":"1.230178175","rc":[{"atl":[[65,0],[42,2.5],[48,0],[50,5]],"id":52385892}],"con":true,"img":false}]}
{"op":"mcm","clk":"11550854195","pt":1719504696197,"mc":[{"id":"1.230178175","rc":[{"atb":[[8,0],[8.2,2.5],[7.4,5]],"id":52385907}],"con":true,"img":false}]}
{"op":"mcm","clk":"11550854207","pt":1719504696508,"mc":[{"id":"1.230178175","rc":[{"atb":[[75,8.11]],"id":52385886}],"con":true,"img":false}]}
{"op":"mcm","clk":"11550854211","pt":1719504696632,"mc":[{"id":"1.230178175","rc":[{"atb":[[90,6.74]],"id":52385885},{"atb":[[65,0]],"id":52385886},{"atb":[[16,0]],"id":52385897},{"atb":[[16,0]],"id":52385891},{"atb":[[16,0]],"id":52385893}],"con":true,"img":false}]}
{"op":"mcm","clk":"11550854217","pt":1719504696735,"mc":[{"id":"1.230178175","rc":[{"atb":[[70,0]],"id":52385885},{"atb":[[14,8]],"id":52385897},{"atb":[[14,6]],"id":52385891},{"atb":[[14,27.13]],"id":52385893}],"con":true,"img":false}]}
{"op":"mcm","clk":"11550854222","pt":1719504696789,"mc":[{"id":"1.230178175","rc":[{"atb":[[12.5,26]],"id":52385891}],"con":true,"img":false}]}
{"op":"mcm","clk":"11550854282","pt":1719504698229,"mc":[{"id":"1.230178175","rc":[{"atb":[[3.95,0],[4.7,27.03]],"id":52385912},{"atb":[[1.23,150]],"id":52385883},{"atl":[[46,7.22],[55,0]],"id":52385890},{"atb":[[9,12]],"id":52385899}],"con":true,"img":false}]}
{"op":"mcm","clk":"11550854286","pt":1719504698332,"mc":[{"id":"1.230178175","rc":[{"atl":[[25,24]],"id":52385919},{"atb":[[6.4,0]],"id":52385899}],"con":true,"img":false}]}
{"op":"mcm","clk":"11550854296","pt":1719504698539,"mc":[{"id":"1.230178175","rc":[{"atl":[[30,0]],"id":52385919}],"con":true,"img":false}]}
{"op":"mcm","clk":"11550854339","pt":1719504699732,"mc":[{"id":"1.230178175","rc":[{"atb":[[9.6,5],[11,2.5]],"id":52385900}],"con":true,"img":false}]}
{"op":"mcm","clk":"11550854345","pt":1719504699836,"mc":[{"id":"1.230178175","rc":[{"atl":[[170,0]],"id":52385883},{"atb":[[10.5,0]],"id":52385900}],"con":true,"img":false}]}
{"op":"mcm","clk":"11550854349","pt":1719504699939,"mc":[{"id":"1.230178175","rc":[{"atl":[[180,3.35]],"id":52385883}],"con":true,"img":false}]}
{"op":"mcm","clk":"11550854360","pt":1719504700096,"mc":[{"id":"1.230178175","rc":[{"atl":[[180,0]],"id":52385883}],"con":true,"img":false}]}
{"op":"mcm","clk":"11550854364","pt":1719504700201,"mc":[{"id":"1.230178175","rc":[{"atb":[[46,0]],"id":52385910},{"atb":[[23,0]],"id":52385912},{"atl":[[60,2.5]],"id":52385912},{"atb":[[38,0]],"id":52385889},{"atb":[[80,0]],"id":52385883},{"atl":[[200,3.02]],"id":52385883},{"atb":[[85,0]],"id":52385885},{"atb":[[15.5,0]],"id":52385892},{"atb":[[12.5,0]],"id":52385904},{"atb":[[17,0]],"id":52385898},{"atb":[[10.5,0]],"id":52385907},{"atb":[[70,0]],"id":52385886},{"atb":[[65,0]],"id":52385882},{"atb":[[38,0]],"id":52385917},{"atb":[[12.5,20]],"id":52385891},{"atl":[[27,0]],"id":52385893},{"atb":[[38,0]],"id":52385903},{"atl":[[48,0]],"id":52385899}],"con":true,"img":false}]}
{"op":"mcm","clk":"11550854369","pt":1719504700305,"mc":[{"id":"1.230178175","rc":[{"atb":[[23,20]],"id":52385889},{"atb":[[90,0]],"id":52385885}],"con":true,"img":false}]}
