{"op":"mcm","clk":"11536380648","pt":1719425245587,"mc":[{"id":"1.230178313","marketDefinition":{"bspMarket":true,"turnInPlayEnabled":false,"persistenceEnabled":false,"marketBaseRate":5.0,"eventId":"33376062","eventTypeId":"4339","numberOfWinners":2,"bettingType":"ODDS","marketType":"PLACE","marketTime":"2024-06-27T14:32:00.000Z","suspendTime":"2024-06-27T14:32:00.000Z","bspReconciled":false,"complete":true,"inPlay":false,"crossMatching":false,"runnersVoidable":false,"numberOfActiveRunners":6,"betDelay":0,"status":"OPEN","runners":[{"status":"ACTIVE","sortPriority":1,"id":39100893,"name":"1. Sheriffs Rose"},{"status":"ACTIVE","sortPriority":2,"id":52951653,"name":"2. Grumpy Wazock"},{"status":"ACTIVE","sortPriority":3,"id":51441055,"name":"3. Pounda Prisna"},{"status":"ACTIVE","sortPriority":4,"id":68462283,"name":"4. Tober Glory"},{"status":"ACTIVE","sortPriority":5,"id":70681331,"name":"5. Shelone Luna"},{"status":"ACTIVE","sortPriority":6,"id":56913144,"name":"6. Knotmor Best"}],"regulators":["MR_INT"],"venue":"Kinsley","countryCode":"GB","discountAllowed":false,"timezone":"Europe/London","openDate":"2024-06-27T13:36:00.000Z","version":5994643769,"name":"To Be Placed","eventName":"Kinsley 27th Jun"},"rc":[],"con":true,"img":false}]}
{"op":"mcm","clk":"11536381024","pt":1719425248531,"mc":[{"id":"1.230178313","marketDefinition":{"bspMarket":true,"turnInPlayEnabled":false,"persistenceEnabled":false,"marketBaseRate":5.0,"eventId":"33376062","eventTypeId":"4339","numberOfWinners":2,"bettingType":"ODDS","marketType":"PLACE","marketTime":"2024-06-27T14:32:00.000Z","suspendTime":"2024-06-27T14:32:00.000Z","bspReconciled":false,"complete":true,"inPlay":false,"crossMatching":false,"runnersVoidable":false,"numberOfActiveRunners":6,"betDelay":0,"status":"OPEN","runners":[{"status":"ACTIVE","sortPriority":1,"id":39100893,"name":"1. Sheriffs Rose"},{"status":"ACTIVE","sortPriority":2,"id":52951653,"name":"2. Grumpy Wazock"},{"status":"ACTIVE","sortPriority":3,"id":51441055,"name":"3. Pounda Prisna"},{"status":"ACTIVE","sortPriority":4,"id":68462283,"name":"4. Tober Glory"},{"status":"ACTIVE","sortPriority":5,"id":70681331,"name":"5. Shelone Luna"},{"status":"ACTIVE","sortPriority":6,"id":56913144,"name":"6. Knotmor Best"}],"regulators":["MR_INT"],"venue":"Kinsley","countryCode":"GB","discountAllowed":true,"timezone":"Europe/London","openDate":"2024-06-27T13:36:00.000Z","version":5994643769,"name":"To Be Placed","eventName":"Kinsley 27th Jun"},"rc":[],"con":true,"img":false}]}
{"op":"mcm","clk":"11536837185","pt":1719431855947,"mc":[{"id":"1.230178313","rc":[{"atb":[[1.02,11.22]],"id":56913144},{"atl":[[990,0.84]],"id":56913144},{"spn":495.51,"spf":"NaN","id":56913144},{"atb":[[1.01,22.45]],"id":68462283},{"atl":[[990,0.84]],"id":68462283},{"spn":495.5,"spf":"NaN","id":68462283},{"atb":[[1.01,22.45]],"id":70681331},{"atl":[[1000,0.84]],"id":70681331},{"spn":500.5,"spf":"NaN","id":70681331},{"atb":[[1.01,22.45]],"id":39100893},{"atl":[[1000,0.84]],"id":39100893},{"spn":500.5,"spf":"NaN","id":39100893},{"atb":[[1.02,11.22]],"id":52951653},{"atl":[[1000,0.84]],"id":52951653},{"spn":500.51,"spf":"NaN","id":52951653},{"atb":[[1.01,22.45]],"id":51441055},{"atl":[[990,0.84]],"id":51441055},{"spn":495.5,"spf":"NaN","id":51441055}],"con":true,"img":false}]}
{"op":"mcm","clk":"11537083977","pt":1719435435156,"mc":[{"id":"1.230178313","rc":[{"atl":[[990,0.32]],"id":56913144},{"atl":[[990,0.32]],"id":68462283},{"atl":[[1000,0.32]],"id":70681331},{"atl":[[1000,0.32]],"id":39100893},{"atl":[[1000,0.32]],"id":52951653},{"atl":[[990,0.32]],"id":51441055}],"con":true,"img":false}]}
{"op":"mcm","clk":"11537232245","pt":1719437882515,"mc":[{"id":"1.230178313","marketDefinition":{"bspMarket":true,"turnInPlayEnabled":false,"persistenceEnabled":false,"marketBaseRate":5.0,"eventId":"33376062","eventTypeId":"4339","numberOfWinners":2,"bettingType":"ODDS","marketType":"PLACE","marketTime":"2024-06-27T14:32:00.000Z","suspendTime":"2024-06-27T14:32:00.000Z","bspReconciled":false,"complete":true,"inPlay":false,"crossMatching":false,"runnersVoidable":false,"numberOfActiveRunners":6,"betDelay":0,"status":"OPEN","runners":[{"status":"ACTIVE","sortPriority":1,"id":39100893,"name":"1. Sheriffs Rose"},{"status":"ACTIVE","sortPriority":2,"id":52951653,"name":"2. Grumpy Wazock"},{"status":"ACTIVE","sortPriority":3,"id":51441055,"name":"3. Pounda Prisna"},{"status":"ACTIVE","sortPriority":4,"id":68462283,"name":"4. Tober Glory"},{"status":"ACTIVE","sortPriority":5,"id":70681331,"name":"5. Shelone Luna"},{"status":"ACTIVE","sortPriority":6,"id":56913144,"name":"6. Knotmor Best"}],"regulators":["MR_INT"],"venue":"Kinsley","countryCode":"GB","discountAllowed":true,"timezone":"Europe/London","openDate":"2024-06-27T13:36:00.000Z","version":5994643769,"name":"To Be Placed","eventName":"Kinsley 27th Jun"},"rc":[{"atb":[[1.02,11.22]],"id":56913144},{"atl":[[990,0.33]],"id":56913144},{"spn":495.51,"spf":"NaN","id":56913144},{"atb":[[1.01,22.45]],"id":68462283},{"atl":[[990,0.33]],"id":68462283},{"spn":495.5,"spf":"NaN","id":68462283},{"atb":[[1.01,22.45]],"id":70681331},{"atl":[[1000,0.33]],"id":70681331},{"spn":500.5,"spf":"NaN","id":70681331},{"atb":[[1.01,22.45]],"id":39100893},{"atl":[[1000,0.33]],"id":39100893},{"spn":500.5,"spf":"NaN","id":39100893},{"atb":[[1.02,11.22]],"id":52951653},{"atl":[[1000,0.33]],"id":52951653},{"spn":500.51,"spf":"NaN","id":52951653},{"atb":[[1.01,22.45]],"id":51441055},{"atl":[[990,0.33]],"id":51441055},{"spn":495.5,"spf":"NaN","id":51441055}],"con":true,"img":true}]}
{"op":"mcm","clk":"11537302273","pt":1719439033580,"mc":[{"id":"1.230178313","rc":[{"atb":[[1.02,11.22]],"id":56913144},{"atl":[[990,0.17]],"id":56913144},{"atb":[[1.01,22.45]],"id":68462283},{"atl":[[990,0.17]],"id":68462283},{"atb":[[1.01,22.45]],"id":70681331},{"atl":[[1000,0.17]],"id":70681331},{"atb":[[1.01,22.45]],"id":39100893},{"atl":[[1000,0.17]],"id":39100893},{"atb":[[1.02,11.22]],"id":52951653},{"atl":[[1000,0.17]],"id":52951653},{"atb":[[1.01,22.45]],"id":51441055},{"atl":[[990,0.17]],"id":51441055}],"con":true,"img":false}]}
{"op":"mcm","clk":"11537573372","pt":1719443282536,"mc":[{"id":"1.230178313","marketDefinition":{"bspMarket":true,"turnInPlayEnabled":false,"persistenceEnabled":false,"marketBaseRate":5.0,"eventId":"33376062","eventTypeId":"4339","numberOfWinners":2,"bettingType":"ODDS","marketType":"PLACE","marketTime":"2024-06-27T14:32:00.000Z","suspendTime":"2024-06-27T14:32:00.000Z","bspReconciled":false,"complete":true,"inPlay":false,"crossMatching":false,"runnersVoidable":false,"numberOfActiveRunners":6,"betDelay":0,"status":"OPEN","runners":[{"status":"ACTIVE","sortPriority":1,"id":39100893,"name":"1. Sheriffs Rose"},{"status":"ACTIVE","sortPriority":2,"id":52951653,"name":"2. Grumpy Wazock"},{"status":"ACTIVE","sortPriority":3,"id":51441055,"name":"3. Pounda Prisna"},{"status":"ACTIVE","sortPriority":4,"id":68462283,"name":"4. Tober Glory"},{"status":"ACTIVE","sortPriority":5,"id":70681331,"name":"5. Shelone Luna"},{"status":"ACTIVE","sortPriority":6,"id":56913144,"name":"6. Knotmor Best"}],"regulators":["MR_INT"],"venue":"Kinsley","countryCode":"GB","discountAllowed":true,"timezone":"Europe/London","openDate":"2024-06-27T13:36:00.000Z","version":5994643769,"name":"To Be Placed","eventName":"Kinsley 27th Jun"},"rc":[{"atb":[[1.02,11.22]],"id":56913144},{"atl":[[990,0.17]],"id":56913144},{"spn":495.51,"spf":"NaN","id":56913144},{"atb":[[1.01,22.45]],"id":68462283},{"atl":[[990,0.17]],"id":68462283},{"spn":495.5,"spf":"NaN","id":68462283},{"atb":[[1.01,22.45]],"id":70681331},{"atl":[[1000,0.17]],"id":70681331},{"spn":500.5,"spf":"NaN","id":70681331},{"atb":[[1.02,11.22]],"id":52951653},{"atl":[[1000,0.17]],"id":52951653},{"spn":500.51,"spf":"NaN","id":52951653},{"atb":[[1.01,22.45]],"id":39100893},{"atl":[[1000,0.17]],"id":39100893},{"spn":500.5,"spf":"NaN","id":39100893},{"atb":[[1.01,22.45]],"id":51441055},{"atl":[[990,0.17]],"id":51441055},{"spn":495.5,"spf":"NaN","id":51441055}],"con":true,"img":true}]}
{"op":"mcm","clk":"11537954932","pt":1719448682557,"mc":[{"id":"1.230178313","marketDefinition":{"bspMarket":true,"turnInPlayEnabled":false,"persistenceEnabled":false,"marketBaseRate":5.0,"eventId":"33376062","eventTypeId":"4339","numberOfWinners":2,"bettingType":"ODDS","marketType":"PLACE","marketTime":"2024-06-27T14:32:00.000Z","suspendTime":"2024-06-27T14:32:00.000Z","bspReconciled":false,"complete":true,"inPlay":false,"crossMatching":false,"runnersVoidable":false,"numberOfActiveRunners":6,"betDelay":0,"status":"OPEN","runners":[{"status":"ACTIVE","sortPriority":1,"id":39100893,"name":"1. Sheriffs Rose"},{"status":"ACTIVE","sortPriority":2,"id":52951653,"name":"2. Grumpy Wazock"},{"status":"ACTIVE","sortPriority":3,"id":51441055,"name":"3. Pounda Prisna"},{"status":"ACTIVE","sortPriority":4,"id":68462283,"name":"4. Tober Glory"},{"status":"ACTIVE","sortPriority":5,"id":70681331,"name":"5. Shelone Luna"},{"status":"ACTIVE","sortPriority":6,"id":56913144,"name":"6. Knotmor Best"}],"regulators":["MR_INT"],"venue":"Kinsley","countryCode":"GB","discountAllowed":true,"timezone":"Europe/London","openDate":"2024-06-27T13:36:00.000Z","version":5994643769,"name":"To Be Placed","eventName":"Kinsley 27th Jun"},"rc":[{"atb":[[1.02,11.22]],"id":56913144},{"atl":[[990,0.17]],"id":56913144},{"spn":495.51,"spf":"NaN","id":56913144},{"atb":[[1.01,22.45]],"id":68462283},{"atl":[[990,0.17]],"id":68462283},{"spn":495.5,"spf":"NaN","id":68462283},{"atb":[[1.01,22.45]],"id":70681331},{"atl":[[1000,0.17]],"id":70681331},{"spn":500.5,"spf":"NaN","id":70681331},{"atb":[[1.02,11.22]],"id":52951653},{"atl":[[1000,0.17]],"id":52951653},{"spn":500.51,"spf":"NaN","id":52951653},{"atb":[[1.01,22.45]],"id":39100893},{"atl":[[1000,0.17]],"id":39100893},{"spn":500.5,"spf":"NaN","id":39100893},{"atb":[[1.01,22.45]],"id":51441055},{"atl":[[990,0.17]],"id":51441055},{"spn":495.5,"spf":"NaN","id":51441055}],"con":true,"img":true}]}
{"op":"mcm","clk":"11538170595","pt":1719454082540,"mc":[{"id":"1.230178313","marketDefinition":{"bspMarket":true,"turnInPlayEnabled":false,"persistenceEnabled":false,"marketBaseRate":5.0,"eventId":"33376062","eventTypeId":"4339","numberOfWinners":2,"bettingType":"ODDS","marketType":"PLACE","marketTime":"2024-06-27T14:32:00.000Z","suspendTime":"2024-06-27T14:32:00.000Z","bspReconciled":false,"complete":true,"inPlay":false,"crossMatching":false,"runnersVoidable":false,"numberOfActiveRunners":6,"betDelay":0,"status":"OPEN","runners":[{"status":"ACTIVE","sortPriority":1,"id":39100893,"name":"1. Sheriffs Rose"},{"status":"ACTIVE","sortPriority":2,"id":52951653,"name":"2. Grumpy Wazock"},{"status":"ACTIVE","sortPriority":3,"id":51441055,"name":"3. Pounda Prisna"},{"status":"ACTIVE","sortPriority":4,"id":68462283,"name":"4. Tober Glory"},{"status":"ACTIVE","sortPriority":5,"id":70681331,"name":"5. Shelone Luna"},{"status":"ACTIVE","sortPriority":6,"id":56913144,"name":"6. Knotmor Best"}],"regulators":["MR_INT"],"venue":"Kinsley","countryCode":"GB","discountAllowed":true,"timezone":"Europe/London","openDate":"2024-06-27T13:36:00.000Z","version":5994643769,"name":"To Be Placed","eventName":"Kinsley 27th Jun"},"rc":[{"atb":[[1.02,11.23]],"id":56913144},{"atl":[[990,0.17]],"id":56913144},{"spn":495.51,"spf":"NaN","id":56913144},{"atb":[[1.01,22.46]],"id":68462283},{"atl":[[990,0.17]],"id":68462283},{"spn":495.5,"spf":"NaN","id":68462283},{"atb":[[1.01,22.46]],"id":70681331},{"atl":[[1000,0.17]],"id":70681331},{"spn":500.5,"spf":"NaN","id":70681331},{"atb":[[1.02,11.23]],"id":52951653},{"atl":[[1000,0.17]],"id":52951653},{"spn":500.51,"spf":"NaN","id":52951653},{"atb":[[1.01,22.46]],"id":39100893},{"atl":[[1000,0.17]],"id":39100893},{"spn":500.5,"spf":"NaN","id":39100893},{"atb":[[1.01,22.46]],"id":51441055},{"atl":[[990,0.17]],"id":51441055},{"spn":495.5,"spf":"NaN","id":51441055}],"con":true,"img":true}]}
{"op":"mcm","clk":"11538368253","pt":1719459482569,"mc":[{"id":"1.230178313","marketDefinition":{"bspMarket":true,"turnInPlayEnabled":false,"persistenceEnabled":false,"marketBaseRate":5.0,"eventId":"33376062","eventTypeId":"4339","numberOfWinners":2,"bettingType":"ODDS","marketType":"PLACE","marketTime":"2024-06-27T14:32:00.000Z","suspendTime":"2024-06-27T14:32:00.000Z","bspReconciled":false,"complete":true,"inPlay":false,"crossMatching":false,"runnersVoidable":false,"numberOfActiveRunners":6,"betDelay":0,"status":"OPEN","runners":[{"status":"ACTIVE","sortPriority":1,"id":39100893,"name":"1. Sheriffs Rose"},{"status":"ACTIVE","sortPriority":2,"id":52951653,"name":"2. Grumpy Wazock"},{"status":"ACTIVE","sortPriority":3,"id":51441055,"name":"3. Pounda Prisna"},{"status":"ACTIVE","sortPriority":4,"id":68462283,"name":"4. Tober Glory"},{"status":"ACTIVE","sortPriority":5,"id":70681331,"name":"5. Shelone Luna"},{"status":"ACTIVE","sortPriority":6,"id":56913144,"name":"6. Knotmor Best"}],"regulators":["MR_INT"],"venue":"Kinsley","countryCode":"GB","discountAllowed":true,"timezone":"Europe/London","openDate":"2024-06-27T13:36:00.000Z","version":5994643769,"name":"To Be Placed","eventName":"Kinsley 27th Jun"},"rc":[{"atb":[[1.02,11.23]],"id":56913144},{"atl":[[990,0.17]],"id":56913144},{"spn":495.51,"spf":"NaN","id":56913144},{"atb":[[1.01,22.46]],"id":68462283},{"atl":[[990,0.17]],"id":68462283},{"spn":495.5,"spf":"NaN","id":68462283},{"atb":[[1.01,22.46]],"id":70681331},{"atl":[[1000,0.17]],"id":70681331},{"spn":500.5,"spf":"NaN","id":70681331},{"atb":[[1.02,11.23]],"id":52951653},{"atl":[[1000,0.17]],"id":52951653},{"spn":500.51,"spf":"NaN","id":52951653},{"atb":[[1.01,22.46]],"id":39100893},{"atl":[[1000,0.17]],"id":39100893},{"spn":500.5,"spf":"NaN","id":39100893},{"atb":[[1.01,22.46]],"id":51441055},{"atl":[[990,0.17]],"id":51441055},{"spn":495.5,"spf":"NaN","id":51441055}],"con":true,"img":true}]}
{"op":"mcm","clk":"11538595379","pt":1719464882539,"mc":[{"id":"1.230178313","marketDefinition":{"bspMarket":true,"turnInPlayEnabled":false,"persistenceEnabled":false,"marketBaseRate":5.0,"eventId":"33376062","eventTypeId":"4339","numberOfWinners":2,"bettingType":"ODDS","marketType":"PLACE","marketTime":"2024-06-27T14:32:00.000Z","suspendTime":"2024-06-27T14:32:00.000Z","bspReconciled":false,"complete":true,"inPlay":false,"crossMatching":false,"runnersVoidable":false,"numberOfActiveRunners":6,"betDelay":0,"status":"OPEN","runners":[{"status":"ACTIVE","sortPriority":1,"id":39100893,"name":"1. Sheriffs Rose"},{"status":"ACTIVE","sortPriority":2,"id":52951653,"name":"2. Grumpy Wazock"},{"status":"ACTIVE","sortPriority":3,"id":51441055,"name":"3. Pounda Prisna"},{"status":"ACTIVE","sortPriority":4,"id":68462283,"name":"4. Tober Glory"},{"status":"ACTIVE","sortPriority":5,"id":70681331,"name":"5. Shelone Luna"},{"status":"ACTIVE","sortPriority":6,"id":56913144,"name":"6. Knotmor Best"}],"regulators":["MR_INT"],"venue":"Kinsley","countryCode":"GB","discountAllowed":true,"timezone":"Europe/London","openDate":"2024-06-27T13:36:00.000Z","version":5994643769,"name":"To Be Placed","eventName":"Kinsley 27th Jun"},"rc":[{"atb":[[1.02,11.23]],"id":56913144},{"atl":[[990,0.17]],"id":56913144},{"spn":495.51,"spf":"NaN","id":56913144},{"atb":[[1.01,22.46]],"id":68462283},{"atl":[[990,0.17]],"id":68462283},{"spn":495.5,"spf":"NaN","id":68462283},{"atb":[[1.01,22.46]],"id":70681331},{"atl":[[1000,0.17]],"id":70681331},{"spn":500.5,"spf":"NaN","id":70681331},{"atb":[[1.02,11.23]],"id":52951653},{"atl":[[1000,0.17]],"id":52951653},{"spn":500.51,"spf":"NaN","id":52951653},{"atb":[[1.01,22.46]],"id":39100893},{"atl":[[1000,0.17]],"id":39100893},{"spn":500.5,"spf":"NaN","id":39100893},{"atb":[[1.01,22.46]],"id":51441055},{"atl":[[990,0.17]],"id":51441055},{"spn":495.5,"spf":"NaN","id":51441055}],"con":true,"img":true}]}
{"op":"mcm","clk":"11538907355","pt":1719471509086,"mc":[{"id":"1.230178313","rc":[{"atb":[[1.02,11.23],[1.07,2.48]],"id":56913144},{"atl":[[1000,1]],"id":56913144},{"spn":495.53,"spf":"NaN","id":56913144},{"atb":[[1.01,22.46],[1.07,2.48]],"id":68462283},{"atl":[[1000,1]],"id":68462283},{"spn":495.53,"spf":"NaN","id":68462283},{"atb":[[1.01,22.46],[1.07,2.48]],"id":70681331},{"atl":[[1000,1.17]],"id":70681331},{"spn":500.53,"spf":"NaN","id":70681331},{"atb":[[1.02,11.23],[1.07,2.48]],"id":52951653},{"atl":[[1000,1.17]],"id":52951653},{"spn":500.53,"spf":"NaN","id":52951653},{"atb":[[1.01,22.46],[1.07,2.48]],"id":39100893},{"atl":[[1000,1.17]],"id":39100893},{"spn":500.53,"spf":"NaN","id":39100893},{"atb":[[1.01,22.46],[1.07,2.48]],"id":51441055},{"atl":[[1000,1]],"id":51441055},{"spn":495.53,"spf":"NaN","id":51441055}],"con":true,"img":false}]}
{"op":"mcm","clk":"11538907368","pt":1719471509292,"mc":[{"id":"1.230178313","rc":[{"atl":[[1000,0.48]],"id":56913144},{"atl":[[1000,0.48]],"id":68462283},{"atl":[[1000,0.65]],"id":70681331},{"atl":[[1000,0.65]],"id":52951653},{"atl":[[1000,0.65]],"id":39100893},{"atl":[[1000,0.48]],"id":51441055}],"con":true,"img":false}]}
{"op":"mcm","clk":"11538907374","pt":1719471509350,"mc":[{"id":"1.230178313","rc":[{"atl":[[1000,0]],"id":56913144},{"atl":[[1000,0]],"id":68462283},{"atl":[[1000,0.17]],"id":70681331},{"atl":[[1000,0.17]],"id":52951653},{"atl":[[1000,0.17]],"id":39100893},{"atl":[[1000,0]],"id":51441055}],"con":true,"img":false}]}
{"op":"mcm","clk":"11538907381","pt":1719471509499,"mc":[{"id":"1.230178313","rc":[{"atl":[[75,0.48]],"id":56913144},{"atl":[[75,0.48]],"id":68462283},{"atl":[[75,0.48]],"id":70681331},{"atl":[[75,0.48]],"id":39100893},{"atl":[[75,0.48]],"id":52951653},{"atl":[[75,0.48]],"id":51441055}],"con":true,"img":false}]}
{"op":"mcm","clk":"11539122526","pt":1719475682546,"mc":[{"id":"1.230178313","marketDefinition":{"bspMarket":true,"turnInPlayEnabled":false,"persistenceEnabled":false,"marketBaseRate":5.0,"eventId":"33376062","eventTypeId":"4339","numberOfWinners":2,"bettingType":"ODDS","marketType":"PLACE","marketTime":"2024-06-27T14:32:00.000Z","suspendTime":"2024-06-27T14:32:00.000Z","bspReconciled":false,"complete":true,"inPlay":false,"crossMatching":false,"runnersVoidable":false,"numberOfActiveRunners":6,"betDelay":0,"status":"OPEN","runners":[{"status":"ACTIVE","sortPriority":1,"id":39100893,"name":"1. Sheriffs Rose"},{"status":"ACTIVE","sortPriority":2,"id":52951653,"name":"2. Grumpy Wazock"},{"status":"ACTIVE","sortPriority":3,"id":51441055,"name":"3. Pounda Prisna"},{"status":"ACTIVE","sortPriority":4,"id":68462283,"name":"4. Tober Glory"},{"status":"ACTIVE","sortPriority":5,"id":70681331,"name":"5. Shelone Luna"},{"status":"ACTIVE","sortPriority":6,"id":56913144,"name":"6. Knotmor Best"}],"regulators":["MR_INT"],"venue":"Kinsley","countryCode":"GB","discountAllowed":true,"timezone":"Europe/London","openDate":"2024-06-27T13:36:00.000Z","version":5994643769,"name":"To Be Placed","eventName":"Kinsley 27th Jun"},"rc":[{"atb":[[1.02,11.22],[1.07,2.48]],"id":56913144},{"atl":[[75,0.48],[990,0.17]],"id":56913144},{"spn":38.03,"spf":"NaN","id":56913144},{"atb":[[1.01,22.45],[1.07,2.48]],"id":68462283},{"atl":[[75,0.48],[990,0.17]],"id":68462283},{"spn":38.03,"spf":"NaN","id":68462283},{"atb":[[1.01,22.45],[1.07,2.48]],"id":70681331},{"atl":[[75,0.48],[1000,0.17]],"id":70681331},{"spn":38.03,"spf":"NaN","id":70681331},{"atb":[[1.01,22.45],[1.07,2.48]],"id":39100893},{"atl":[[75,0.48],[1000,0.17]],"id":39100893},{"spn":38.03,"spf":"NaN","id":39100893},{"atb":[[1.02,11.22],[1.07,2.48]],"id":52951653},{"atl":[[75,0.48],[1000,0.17]],"id":52951653},{"spn":38.03,"spf":"NaN","id":52951653},{"atb":[[1.01,22.45],[1.07,2.48]],"id":51441055},{"atl":[[75,0.48],[990,0.17]],"id":51441055},{"spn":38.03,"spf":"NaN","id":51441055}],"con":true,"img":true}]}
{"op":"mcm","clk":"11539334046","pt":1719479172966,"mc":[{"id":"1.230178313","rc":[{"atb":[[1.02,11.22]],"id":56913144},{"spn":38.03,"spf":"NaN","id":56913144},{"spl":[[1.71,6]],"id":68462283},{"atb":[[1.01,22.45]],"id":68462283},{"spn":1.39,"spf":1.0,"id":68462283},{"atb":[[1.01,22.45]],"id":70681331},{"spn":38.03,"spf":"NaN","id":70681331},{"atb":[[1.01,22.45]],"id":39100893},{"spn":38.03,"spf":"NaN","id":39100893},{"atb":[[1.02,11.22]],"id":52951653},{"spn":38.03,"spf":"NaN","id":52951653},{"atb":[[1.01,22.45]],"id":51441055},{"spn":38.03,"spf":"NaN","id":51441055}],"con":true,"img":false}]}
{"op":"mcm","clk":"11539623059","pt":1719483961987,"mc":[{"id":"1.230178313","rc":[{"atb":[[1.02,11.22]],"id":56913144},{"atb":[[1.01,22.44]],"id":68462283},{"atb":[[1.01,22.44]],"id":70681331},{"atb":[[1.01,22.44]],"id":39100893},{"atb":[[1.02,11.22]],"id":52951653},{"spl":[[1.01,1.43]],"id":51441055},{"atb":[[1.01,22.44]],"id":51441055},{"spn":1.07,"spf":1.0,"id":51441055}],"con":true,"img":false}]}
{"op":"mcm","clk":"11539810799","pt":1719486482534,"mc":[{"id":"1.230178313","marketDefinition":{"bspMarket":true,"turnInPlayEnabled":false,"persistenceEnabled":false,"marketBaseRate":5.0,"eventId":"33376062","eventTypeId":"4339","numberOfWinners":2,"bettingType":"ODDS","marketType":"PLACE","marketTime":"2024-06-27T14:32:00.000Z","suspendTime":"2024-06-27T14:32:00.000Z","bspReconciled":false,"complete":true,"inPlay":false,"crossMatching":false,"runnersVoidable":false,"numberOfActiveRunners":6,"betDelay":0,"status":"OPEN","runners":[{"status":"ACTIVE","sortPriority":1,"id":39100893,"name":"1. Sheriffs Rose"},{"status":"ACTIVE","sortPriority":2,"id":52951653,"name":"2. Grumpy Wazock"},{"status":"ACTIVE","sortPriority":3,"id":51441055,"name":"3. Pounda Prisna"},{"status":"ACTIVE","sortPriority":4,"id":68462283,"name":"4. Tober Glory"},{"status":"ACTIVE","sortPriority":5,"id":70681331,"name":"5. Shelone Luna"},{"status":"ACTIVE","sortPriority":6,"id":56913144,"name":"6. Knotmor Best"}],"regulators":["MR_INT"],"venue":"Kinsley","countryCode":"GB","discountAllowed":true,"timezone":"Europe/London","openDate":"2024-06-27T13:36:00.000Z","version":5994643769,"name":"To Be Placed","eventName":"Kinsley 27th Jun"},"rc":[{"atb":[[1.02,11.22],[1.07,2.48]],"id":56913144},{"atl":[[75,0.48],[990,0.17]],"id":56913144},{"spn":38.03,"spf":"NaN","id":56913144},{"spl":[[1.71,6]],"id":68462283},{"atb":[[1.01,22.45],[1.07,2.48]],"id":68462283},{"atl":[[75,0.48],[990,0.17]],"id":68462283},{"spn":1.39,"spf":1.0,"id":68462283},{"atb":[[1.01,22.45],[1.07,2.48]],"id":70681331},{"atl":[[75,0.48],[1000,0.17]],"id":70681331},{"spn":38.03,"spf":"NaN","id":70681331},{"atb":[[1.01,22.45],[1.07,2.48]],"id":39100893},{"atl":[[75,0.48],[1000,0.17]],"id":39100893},{"spn":38.03,"spf":"NaN","id":39100893},{"atb":[[1.02,11.22],[1.07,2.48]],"id":52951653},{"atl":[[75,0.48],[1000,0.17]],"id":52951653},{"spn":38.03,"spf":"NaN","id":52951653},{"spl":[[1.01,1.43]],"id":51441055},{"atb":[[1.01,22.45],[1.07,2.48]],"id":51441055},{"atl":[[75,0.48],[990,0.17]],"id":51441055},{"spn":1.07,"spf":1.0,"id":51441055}],"con":true,"img":true}]}
{"op":"mcm","clk":"11540247716","pt":1719491882543,"mc":[{"id":"1.230178313","marketDefinition":{"bspMarket":true,"turnInPlayEnabled":false,"persistenceEnabled":false,"marketBaseRate":5.0,"eventId":"33376062","eventTypeId":"4339","numberOfWinners":2,"bettingType":"ODDS","marketType":"PLACE","marketTime":"2024-06-27T14:32:00.000Z","suspendTime":"2024-06-27T14:32:00.000Z","bspReconciled":false,"complete":true,"inPlay":false,"crossMatching":false,"runnersVoidable":false,"numberOfActiveRunners":6,"betDelay":0,"status":"OPEN","runners":[{"status":"ACTIVE","sortPriority":1,"id":39100893,"name":"1. Sheriffs Rose"},{"status":"ACTIVE","sortPriority":2,"id":52951653,"name":"2. Grumpy Wazock"},{"status":"ACTIVE","sortPriority":3,"id":51441055,"name":"3. Pounda Prisna"},{"status":"ACTIVE","sortPriority":4,"id":68462283,"name":"4. Tober Glory"},{"status":"ACTIVE","sortPriority":5,"id":70681331,"name":"5. Shelone Luna"},{"status":"ACTIVE","sortPriority":6,"id":56913144,"name":"6. Knotmor Best"}],"regulators":["MR_INT"],"venue":"Kinsley","countryCode":"GB","discountAllowed":true,"timezone":"Europe/London","openDate":"2024-06-27T13:36:00.000Z","version":5994643769,"name":"To Be Placed","eventName":"Kinsley 27th Jun"},"rc":[{"atb":[[1.02,11.22],[1.07,2.48]],"id":56913144},{"atl":[[75,0.48],[990,0.17]],"id":56913144},{"spn":38.03,"spf":"NaN","id":56913144},{"spl":[[1.71,6]],"id":68462283},{"atb":[[1.01,22.45],[1.07,2.48]],"id":68462283},{"atl":[[75,0.48],[990,0.17]],"id":68462283},{"spn":1.39,"spf":1.0,"id":68462283},{"atb":[[1.01,22.45],[1.07,2.48]],"id":70681331},{"atl":[[75,0.48],[1000,0.17]],"id":70681331},{"spn":38.03,"spf":"NaN","id":70681331},{"atb":[[1.01,22.45],[1.07,2.48]],"id":39100893},{"atl":[[75,0.48],[1000,0.17]],"id":39100893},{"spn":38.03,"spf":"NaN","id":39100893},{"atb":[[1.02,11.22],[1.07,2.48]],"id":52951653},{"atl":[[75,0.48],[1000,0.17]],"id":52951653},{"spn":38.03,"spf":"NaN","id":52951653},{"spl":[[1.01,1.43]],"id":51441055},{"atb":[[1.01,22.45],[1.07,2.48]],"id":51441055},{"atl":[[75,0.48],[990,0.17]],"id":51441055},{"spn":1.07,"spf":1.0,"id":51441055}],"con":true,"img":true}]}
{"op":"mcm","clk":"11540327073","pt":1719493057950,"mc":[{"id":"1.230178313","rc":[{"atb":[[1.02,11.22]],"id":56913144},{"atl":[[970,1.06]],"id":56913144},{"atb":[[1.01,22.45]],"id":68462283},{"atl":[[980,0.87]],"id":68462283},{"atb":[[1.01,22.45]],"id":70681331},{"atl":[[990,1.13]],"id":70681331},{"atb":[[1.01,22.45]],"id":39100893},{"atl":[[990,0.87]],"id":39100893},{"atb":[[1.02,11.22]],"id":52951653},{"atl":[[970,0.87]],"id":52951653},{"spl":[[1.01,1.43]],"id":51441055},{"atb":[[1.01,22.45]],"id":51441055},{"atl":[[990,1.23]],"id":51441055}],"con":true,"img":false}]}
{"op":"mcm","clk":"11540453975","pt":1719494692167,"mc":[{"id":"1.230178313","rc":[{"atb":[[1.02,11.23]],"id":56913144},{"atl":[[2.88,100],[970,1.06],[990,0.17]],"id":56913144},{"spn":1.97,"spf":"NaN","id":56913144},{"atb":[[1.01,22.47]],"id":68462283},{"atl":[[980,0.87],[990,0.17]],"id":68462283},{"atb":[[1.01,22.47]],"id":70681331},{"atl":[[990,1.13],[1000,0.17]],"id":70681331},{"atb":[[1.02,11.23]],"id":52951653},{"atl":[[970,0.87],[1000,0.17]],"id":52951653},{"atb":[[1.01,22.47]],"id":39100893},{"atl":[[990,0.87],[1000,0.17]],"id":39100893},{"spl":[[1.01,1.43]],"id":51441055},{"atb":[[1.01,22.47]],"id":51441055},{"atl":[[990,1.23]],"id":51441055}],"con":true,"img":false}]}
{"op":"mcm","clk":"11540455615","pt":1719494711985,"mc":[{"id":"1.230178313","marketDefinition":{"bspMarket":true,"turnInPlayEnabled":false,"persistenceEnabled":false,"marketBaseRate":5.0,"eventId":"33376062","eventTypeId":"4339","numberOfWinners":2,"bettingType":"ODDS","marketType":"PLACE","marketTime":"2024-06-27T14:32:00.000Z","suspendTime":"2024-06-27T14:32:00.000Z","bspReconciled":false,"complete":true,"inPlay":false,"crossMatching":true,"runnersVoidable":false,"numberOfActiveRunners":6,"betDelay":0,"status":"OPEN","runners":[{"status":"ACTIVE","sortPriority":1,"id":39100893,"name":"1. Sheriffs Rose"},{"status":"ACTIVE","sortPriority":2,"id":52951653,"name":"2. Grumpy Wazock"},{"status":"ACTIVE","sortPriority":3,"id":51441055,"name":"3. Pounda Prisna"},{"status":"ACTIVE","sortPriority":4,"id":68462283,"name":"4. Tober Glory"},{"status":"ACTIVE","sortPriority":5,"id":70681331,"name":"5. Shelone Luna"},{"status":"ACTIVE","sortPriority":6,"id":56913144,"name":"6. Knotmor Best"}],"regulators":["MR_INT"],"venue":"Kinsley","countryCode":"GB","discountAllowed":true,"timezone":"Europe/London","openDate":"2024-06-27T13:36:00.000Z","version":5994643769,"name":"To Be Placed","eventName":"Kinsley 27th Jun"},"rc":[],"con":true,"img":false}]}
{"op":"mcm","clk":"11540628010","pt":1719496623597,"mc":[{"id":"1.230178313","rc":[{"atb":[[1.04,1]],"id":56913144},{"atb":[[1.04,1]],"id":68462283},{"atb":[[1.04,1]],"id":70681331},{"atb":[[1.04,1]],"id":52951653},{"atb":[[1.04,1]],"id":39100893},{"atb":[[1.04,1]],"id":51441055}],"con":true,"img":false}]}
{"op":"mcm","clk":"11540628027","pt":1719496623799,"mc":[{"id":"1.230178313","rc":[{"atb":[[1.04,0.25]],"id":56913144},{"atb":[[1.04,0.25]],"id":68462283},{"atb":[[1.04,0.25]],"id":70681331},{"atb":[[1.04,0.25]],"id":52951653},{"atb":[[1.04,0.25]],"id":39100893},{"atb":[[1.04,0.25]],"id":51441055}],"con":true,"img":false}]}
{"op":"mcm","clk":"11540628048","pt":1719496624006,"mc":[{"id":"1.230178313","rc":[{"atb":[[1.04,0]],"id":56913144},{"atb":[[1.04,0]],"id":68462283},{"atb":[[1.04,0]],"id":70681331},{"atb":[[1.04,0]],"id":52951653},{"atb":[[1.04,0]],"id":39100893},{"atb":[[1.04,0]],"id":51441055}],"con":true,"img":false}]}
{"op":"mcm","clk":"11540628061","pt":1719496624109,"mc":[{"id":"1.230178313","rc":[{"atb":[[1.2,0.25]],"id":56913144},{"atb":[[1.2,0.25]],"id":68462283},{"atb":[[1.2,0.25]],"id":70681331},{"atb":[[1.2,0.25]],"id":52951653},{"atb":[[1.2,0.25]],"id":39100893},{"atb":[[1.2,0.25]],"id":51441055}],"con":true,"img":false}]}
{"op":"mcm","clk":"11540659842","pt":1719497020929,"mc":[{"id":"1.230178313","rc":[{"atb":[[1.02,11.23],[1.09,47.03]],"id":56913144},{"atl":[[970,1.06]],"id":56913144},{"spn":2.04,"spf":"NaN","id":56913144},{"atb":[[1.01,22.46]],"id":68462283},{"atl":[[980,0.87]],"id":68462283},{"spn":1.45,"spf":1.0,"id":68462283},{"atb":[[1.01,22.46]],"id":70681331},{"atl":[[990,1.13]],"id":70681331},{"spn":38.1,"spf":"NaN","id":70681331},{"atb":[[1.01,22.46]],"id":39100893},{"atl":[[990,0.87]],"id":39100893},{"spn":38.1,"spf":"NaN","id":39100893},{"atb":[[1.02,11.23]],"id":52951653},{"atl":[[970,0.87]],"id":52951653},{"spn":38.1,"spf":"NaN","id":52951653},{"spl":[[1.01,1.43]],"id":51441055},{"atb":[[1.01,22.46]],"id":51441055},{"atl":[[990,1.23]],"id":51441055},{"spn":1.09,"spf":1.0,"id":51441055}],"con":true,"img":false}]}
{"op":"mcm","clk":"11540664684","pt":1719497078677,"mc":[{"id":"1.230178313","rc":[{"atb":[[1.11,35.89]],"id":56913144}],"con":true,"img":false}]}
{"op":"mcm","clk":"11540666009","pt":1719497094607,"mc":[{"id":"1.230178313","rc":[{"atb":[[1.09,0]],"id":56913144}],"con":true,"img":false}]}
{"op":"mcm","clk":"11540666073","pt":1719497095490,"mc":[{"id":"1.230178313","rc":[{"atb":[[1.13,32.56]],"id":56913144}],"con":true,"img":false}]}
{"op":"mcm","clk":"11540666134","pt":1719497096315,"mc":[{"id":"1.230178313","rc":[{"atb":[[1.11,0]],"id":56913144}],"con":true,"img":false}]}
{"op":"mcm","clk":"11540666153","pt":1719497096472,"mc":[{"id":"1.230178313","rc":[{"atb":[[1.15,26.32]],"id":56913144}],"con":true,"img":false}]}
{"op":"mcm","clk":"11540669149","pt":1719497131427,"mc":[{"id":"1.230178313","rc":[{"atb":[[1.13,0]],"id":56913144}],"con":true,"img":false}]}
{"op":"mcm","clk":"11540669198","pt":1719497132049,"mc":[{"id":"1.230178313","rc":[{"atb":[[1.17,24.89]],"id":56913144}],"con":true,"img":false}]}
{"op":"mcm","clk":"11540669290","pt":1719497133442,"mc":[{"id":"1.230178313","rc":[{"atb":[[1.15,0]],"id":56913144}],"con":true,"img":false}]}
{"op":"mcm","clk":"11540669308","pt":1719497133748,"mc":[{"id":"1.230178313","rc":[{"atb":[[1.19,20.78]],"id":56913144}],"con":true,"img":false}]}
{"op":"mcm","clk":"11540672593","pt":1719497171390,"mc":[{"id":"1.230178313","rc":[{"atb":[[1.17,0]],"id":56913144}],"con":true,"img":false}]}
{"op":"mcm","clk":"11540672700","pt":1719497172583,"mc":[{"id":"1.230178313","rc":[{"atb":[[1.21,20.15]],"id":56913144}],"con":true,"img":false}]}
{"op":"mcm","clk":"11540674319","pt":1719497190360,"mc":[{"id":"1.230178313","rc":[{"atb":[[1.19,0]],"id":56913144}],"con":true,"img":false}]}
{"op":"mcm","clk":"11540674371","pt":1719497190982,"mc":[{"id":"1.230178313","rc":[{"atb":[[1.23,17.16]],"id":56913144}],"con":true,"img":false}]}
{"op":"mcm","clk":"11540675829","pt":1719497207620,"mc":[{"id":"1.230178313","rc":[{"atb":[[1.21,0]],"id":56913144}],"con":true,"img":false}]}
{"op":"mcm","clk":"11540675905","pt":1719497208510,"mc":[{"id":"1.230178313","rc":[{"atb":[[1.25,16.93]],"id":56913144}],"con":true,"img":false}]}
{"op":"mcm","clk":"11540675982","pt":1719497209392,"mc":[{"id":"1.230178313","rc":[{"atb":[[1.23,0]],"id":56913144}],"con":true,"img":false}]}
{"op":"mcm","clk":"11540676014","pt":1719497209805,"mc":[{"id":"1.230178313","rc":[{"atb":[[1.27,14.62]],"id":56913144}],"con":true,"img":false}]}
{"op":"mcm","clk":"11540678797","pt":1719497243015,"mc":[{"id":"1.230178313","rc":[{"atb":[[1.25,0]],"id":56913144},{"spn":2.07,"spf":"NaN","id":56913144}],"con":true,"img":false}]}
{"op":"mcm","clk":"11540678887","pt":1719497244046,"mc":[{"id":"1.230178313","rc":[{"atb":[[1.29,14.59]],"id":56913144}],"con":true,"img":false}]}
{"op":"mcm","clk":"11540679435","pt":1719497250438,"mc":[{"id":"1.230178313","rc":[{"atb":[[1.27,0]],"id":56913144}],"con":true,"img":false}]}
{"op":"mcm","clk":"11540679512","pt":1719497251415,"mc":[{"id":"1.230178313","rc":[{"atb":[[1.31,12.73]],"id":56913144}],"con":true,"img":false}]}
{"op":"mcm","clk":"11540681713","pt":1719497279947,"mc":[{"id":"1.230178313","rc":[{"atb":[[1.29,0]],"id":56913144}],"con":true,"img":false}]}
{"op":"mcm","clk":"11540681728","pt":1719497280258,"mc":[{"id":"1.230178313","rc":[{"atb":[[1.33,12.82]],"id":56913144}],"con":true,"img":false}]}
{"op":"mcm","clk":"11540687762","pt":1719497284354,"mc":[{"id":"1.230178313","rc":[{"atb":[[1.22,17.26]],"id":56913144}],"con":true,"img":false}]}
{"op":"mcm","clk":"11540688091","pt":1719497288281,"mc":[{"id":"1.230178313","rc":[{"atb":[[1.31,0]],"id":56913144}],"con":true,"img":false}]}
{"op":"mcm","clk":"11540688135","pt":1719497288645,"mc":[{"id":"1.230178313","rc":[{"atb":[[1.35,11.28]],"id":56913144}],"con":true,"img":false}]}
{"op":"mcm","clk":"11540689485","pt":1719497303193,"mc":[{"id":"1.230178313","rc":[{"atb":[[1.22,0]],"id":56913144},{"spn":2.11,"spf":"NaN","id":56913144}],"con":true,"img":false}]}
{"op":"mcm","clk":"11540690646","pt":1719497317404,"mc":[{"id":"1.230178313","rc":[{"atb":[[1.33,0]],"id":56913144}],"con":true,"img":false}]}
{"op":"mcm","clk":"11540690734","pt":1719497318282,"mc":[{"id":"1.230178313","rc":[{"atb":[[1.37,11.43]],"id":56913144}],"con":true,"img":false}]}
{"op":"mcm","clk":"11540691617","pt":1719497328533,"mc":[{"id":"1.230178313","rc":[{"atb":[[1.35,0]],"id":56913144}],"con":true,"img":false}]}
{"op":"mcm","clk":"11540691666","pt":1719497329000,"mc":[{"id":"1.230178313","rc":[{"atb":[[1.39,10.12]],"id":56913144}],"con":true,"img":false}]}
{"op":"mcm","clk":"11540694031","pt":1719497356116,"mc":[{"id":"1.230178313","rc":[{"atb":[[1.37,0]],"id":56913144}],"con":true,"img":false}]}
{"op":"mcm","clk":"11540694088","pt":1719497356731,"mc":[{"id":"1.230178313","rc":[{"atb":[[1.41,10.32]],"id":56913144}],"con":true,"img":false}]}
{"op":"mcm","clk":"11540695077","pt":1719497367342,"mc":[{"id":"1.230178313","rc":[{"atb":[[1.39,0]],"id":56913144},{"spn":2.14,"spf":"NaN","id":56913144}],"con":true,"img":false}]}
{"op":"mcm","clk":"11540695198","pt":1719497368441,"mc":[{"id":"1.230178313","rc":[{"atb":[[1.43,9.18]],"id":56913144}],"con":true,"img":false}]}
{"op":"mcm","clk":"11540697203","pt":1719497391968,"mc":[{"id":"1.230178313","rc":[{"atb":[[1.41,0]],"id":56913144}],"con":true,"img":false}]}
{"op":"mcm","clk":"11540697263","pt":1719497392692,"mc":[{"id":"1.230178313","rc":[{"atb":[[1.45,9.4]],"id":56913144}],"con":true,"img":false}]}
{"op":"mcm","clk":"11540698405","pt":1719497404192,"mc":[{"id":"1.230178313","rc":[{"atb":[[1.43,0]],"id":56913144}],"con":true,"img":false}]}
{"op":"mcm","clk":"11540698489","pt":1719497404765,"mc":[{"id":"1.230178313","rc":[{"atb":[[1.47,8.4]],"id":56913144}],"con":true,"img":false}]}
{"op":"mcm","clk":"11540701077","pt":1719497431021,"mc":[{"id":"1.230178313","rc":[{"atb":[[1.45,0]],"id":56913144},{"spn":2.17,"spf":"NaN","id":56913144}],"con":true,"img":false}]}
{"op":"mcm","clk":"11540701167","pt":1719497432009,"mc":[{"id":"1.230178313","rc":[{"atb":[[1.49,8.63]],"id":56913144}],"con":true,"img":false}]}
{"op":"mcm","clk":"11540702340","pt":1719497443822,"mc":[{"id":"1.230178313","rc":[{"atb":[[1.47,0]],"id":56913144}],"con":true,"img":false}]}
{"op":"mcm","clk":"11540702398","pt":1719497444547,"mc":[{"id":"1.230178313","rc":[{"atb":[[1.51,7.73]],"id":56913144}],"con":true,"img":false}]}
{"op":"mcm","clk":"11540709601","pt":1719497521921,"mc":[{"id":"1.230178313","rc":[{"atb":[[1.52,2.11]],"id":56913144},{"spn":2.2,"spf":"NaN","id":56913144}],"con":true,"img":false}]}
{"op":"mcm","clk":"11540711180","pt":1719497539839,"mc":[{"id":"1.230178313","rc":[{"atl":[[2.88,83.21]],"id":56913144},{"trd":[[2.88,33.58]],"ltp":2.88,"tv":33.58,"id":56913144}],"con":true,"img":false}]}
{"op":"mcm","clk":"11540711232","pt":1719497540415,"mc":[{"id":"1.230178313","rc":[{"atb":[[1.52,3.75]],"id":56913144}],"con":true,"img":false}]}
{"op":"mcm","clk":"11540717779","pt":1719497619480,"mc":[{"id":"1.230178313","rc":[{"atb":[[1.51,0]],"id":56913144}],"con":true,"img":false}]}
{"op":"mcm","clk":"11540717811","pt":1719497619894,"mc":[{"id":"1.230178313","rc":[{"atb":[[1.52,2.11]],"id":56913144}],"con":true,"img":false}]}
{"op":"mcm","clk":"11540717986","pt":1719497621802,"mc":[{"id":"1.230178313","rc":[{"atb":[[1.49,0]],"id":56913144}],"con":true,"img":false}]}
{"op":"mcm","clk":"11540724631","pt":1719497700670,"mc":[{"id":"1.230178313","rc":[{"spl":[[1.01,2.43]],"id":51441055},{"spn":1.08,"spf":1.0,"id":51441055}],"con":true,"img":false}]}
{"op":"mcm","clk":"11540735465","pt":1719497820814,"mc":[{"id":"1.230178313","rc":[{"atb":[[1.52,4.23]],"id":56913144},{"atl":[[4.2,31.25]],"id":56913144},{"atb":[[1.95,2.48]],"id":68462283},{"atl":[[46,2]],"id":68462283},{"spn":1.71,"spf":1.0,"id":68462283},{"atb":[[1.74,2.48]],"id":70681331},{"atl":[[22,2]],"id":70681331},{"spn":11.87,"spf":"NaN","id":70681331},{"atb":[[1.56,2.48]],"id":39100893},{"atl":[[12.5,2]],"id":39100893},{"spn":7.03,"spf":"NaN","id":39100893},{"atb":[[1.36,2.48]],"id":52951653},{"atl":[[9.4,2]],"id":52951653},{"spn":5.38,"spf":"NaN","id":52951653},{"atb":[[1.62,2.48]],"id":51441055},{"atl":[[14.5,2]],"id":51441055},{"spn":1.62,"spf":1.0,"id":51441055}],"con":true,"img":false}]}
{"op":"mcm","clk":"11540735481","pt":1719497820917,"mc":[{"id":"1.230178313","rc":[{"atb":[[1.59,1],[1.51,4.24],[1.52,2.11]],"id":56913144},{"atb":[[2.12,1]],"id":68462283},{"atl":[[6.4,1]],"id":68462283},{"atb":[[2.24,1]],"id":70681331},{"atl":[[6,1]],"id":70681331},{"atb":[[1.78,1]],"id":39100893},{"atl":[[4.7,1]],"id":39100893},{"atb":[[1.78,1]],"id":52951653},{"atl":[[4.7,1]],"id":52951653},{"atb":[[1.97,1]],"id":51441055},{"atl":[[5.4,1]],"id":51441055}],"con":true,"img":false}]}
{"op":"mcm","clk":"11540736023","pt":1719497826607,"mc":[{"id":"1.230178313","rc":[{"atb":[[1.01,24.17]],"id":39100893},{"atl":[[1000,1.88]],"id":39100893},{"atb":[[1.01,1.7]],"id":52951653},{"atl":[[1000,1.88]],"id":52951653},{"atb":[[1.01,24.17]],"id":51441055},{"atl":[[1000,1.7]],"id":51441055}],"con":true,"img":false}]}
{"op":"mcm","clk":"11540736045","pt":1719497826814,"mc":[{"id":"1.230178313","rc":[{"atb":[[1.01,0.85]],"id":52951653},{"atl":[[1000,0.21]],"id":52951653},{"atb":[[1.01,23.02]],"id":39100893},{"atl":[[1000,0.2]],"id":39100893},{"atb":[[1.01,22.97]],"id":51441055},{"atl":[[1000,0.02]],"id":51441055}],"con":true,"img":false}]}
{"op":"mcm","clk":"11540736053","pt":1719497826917,"mc":[{"id":"1.230178313","rc":[{"atb":[[1.03,1.56]],"id":52951653}],"con":true,"img":false}]}
{"op":"mcm","clk":"11540736067","pt":1719497827021,"mc":[{"id":"1.230178313","rc":[{"atb":[[1.01,0]],"id":52951653},{"atl":[[1000,0.17]],"id":52951653},{"atb":[[1.01,22.46]],"id":39100893},{"atl":[[1000,0.17]],"id":39100893},{"atb":[[1.01,22.46]],"id":51441055},{"atl":[[1000,0]],"id":51441055}],"con":true,"img":false}]}
{"op":"mcm","clk":"11540736076","pt":1719497827072,"mc":[{"id":"1.230178313","rc":[{"atb":[[1.57,0.55]],"id":39100893},{"atl":[[12,0.02]],"id":39100893},{"atb":[[1.37,0.85]],"id":52951653},{"atl":[[9.2,0.03]],"id":52951653},{"atb":[[1.63,0.5]],"id":51441055},{"atl":[[14,0.02]],"id":51441055}],"con":true,"img":false}]}
{"op":"mcm","clk":"11540736687","pt":1719497833335,"mc":[{"id":"1.230178313","rc":[{"atb":[[1.54,7.31]],"id":56913144}],"con":true,"img":false}]}
{"op":"mcm","clk":"11540736700","pt":1719497833388,"mc":[{"id":"1.230178313","rc":[{"atb":[[1.55,4.24],[1.51,0]],"id":56913144}],"con":true,"img":false}]}
{"op":"mcm","clk":"11540737493","pt":1719497842230,"mc":[{"id":"1.230178313","rc":[{"atb":[[2.12,0]],"id":68462283},{"atl":[[5.8,1]],"id":70681331},{"atl":[[4.6,1],[4.7,0]],"id":52951653},{"atl":[[4.7,0]],"id":39100893}],"con":true,"img":false}]}
{"op":"mcm","clk":"11540737502","pt":1719497842331,"mc":[{"id":"1.230178313","rc":[{"atb":[[1.55,0],[1.61,4.24]],"id":56913144},{"atb":[[2.32,1],[2.04,2.48],[1.95,0]],"id":68462283},{"atb":[[1.79,2.48],[1.74,0]],"id":70681331},{"atl":[[5.6,1],[5.8,0],[6,0]],"id":70681331},{"atl":[[4.6,0],[4.4,1],[8.8,2],[9.4,0]],"id":52951653},{"atb":[[1.56,0],[1.61,2]],"id":39100893},{"atl":[[4.6,1],[11.5,2],[12.5,0],[4.4,1]],"id":39100893},{"atl":[[4.8,1],[5.2,1],[5.4,0]],"id":51441055}],"con":true,"img":false}]}
{"op":"mcm","clk":"11540737517","pt":1719497842442,"mc":[{"id":"1.230178313","rc":[{"atl":[[22,0],[6,2]],"id":70681331},{"atl":[[13,2],[14.5,0]],"id":51441055}],"con":true,"img":false}]}
{"op":"mcm","clk":"11540737528","pt":1719497842545,"mc":[{"id":"1.230178313","rc":[{"atl":[[20,2],[6,0]],"id":70681331},{"atl":[[4.6,0]],"id":39100893},{"atl":[[5.2,0]],"id":51441055}],"con":true,"img":false}]}
{"op":"mcm","clk":"11540739800","pt":1719497869552,"mc":[{"id":"1.230178313","rc":[{"atb":[[1.57,0]],"id":39100893},{"atl":[[12,0]],"id":39100893},{"atb":[[1.37,0]],"id":52951653},{"atl":[[9.2,0]],"id":52951653},{"atb":[[1.63,0]],"id":51441055},{"atl":[[14,0]],"id":51441055}],"con":true,"img":false}]}
{"op":"mcm","clk":"11540740289","pt":1719497875681,"mc":[{"id":"1.230178313","rc":[{"atb":[[1.02,2]],"id":39100893}],"con":true,"img":false}]}
{"op":"mcm","clk":"11540740316","pt":1719497875941,"mc":[{"id":"1.230178313","rc":[{"atb":[[1.02,13.23]],"id":52951653}],"con":true,"img":false}]}
{"op":"mcm","clk":"11540740336","pt":1719497876139,"mc":[{"id":"1.230178313","rc":[{"atb":[[1.02,2]],"id":51441055}],"con":true,"img":false}]}
{"op":"mcm","clk":"11540740369","pt":1719497876347,"mc":[{"id":"1.230178313","rc":[{"atb":[[1.02,2]],"id":68462283}],"con":true,"img":false}]}
{"op":"mcm","clk":"11540740383","pt":1719497876551,"mc":[{"id":"1.230178313","rc":[{"atb":[[1.02,2]],"id":70681331}],"con":true,"img":false}]}
{"op":"mcm","clk":"11540740407","pt":1719497876861,"mc":[{"id":"1.230178313","rc":[{"atb":[[1.62,2]],"id":56913144}],"con":true,"img":false}]}
{"op":"mcm","clk":"11540744866","pt":1719497924295,"mc":[{"id":"1.230178313","rc":[{"atb":[[1.54,0]],"id":56913144},{"spn":2.25,"spf":"NaN","id":56913144},{"spn":3.92,"spf":"NaN","id":70681331},{"spn":3.09,"spf":"NaN","id":52951653},{"spn":3.09,"spf":"NaN","id":39100893},{"spn":1.76,"spf":1.0,"id":51441055}],"con":true,"img":false}]}
{"op":"mcm","clk":"11540747364","pt":1719497952812,"mc":[{"id":"1.230178313","rc":[{"atb":[[1.01,1.7]],"id":52951653},{"atl":[[1000,1.88]],"id":52951653},{"atb":[[1.01,24.17]],"id":39100893},{"atl":[[1000,1.88]],"id":39100893},{"atb":[[1.01,24.17]],"id":51441055},{"atl":[[1000,1.7]],"id":51441055}],"con":true,"img":false}]}
{"op":"mcm","clk":"11540747382","pt":1719497953011,"mc":[{"id":"1.230178313","rc":[{"atb":[[1.01,22.96]],"id":39100893},{"atl":[[1000,0.2]],"id":39100893},{"atb":[[1.01,0.82]],"id":52951653},{"atl":[[1000,0.21]],"id":52951653},{"atb":[[1.01,22.95]],"id":51441055},{"atl":[[1000,0.02]],"id":51441055}],"con":true,"img":false}]}
{"op":"mcm","clk":"11540747407","pt":1719497953216,"mc":[{"id":"1.230178313","rc":[{"atb":[[1.01,22.46]],"id":39100893},{"atb":[[1.01,0]],"id":52951653},{"atl":[[1000,0.17]],"id":52951653},{"atb":[[1.01,22.46]],"id":51441055},{"atl":[[1000,0]],"id":51441055}],"con":true,"img":false}]}
{"op":"mcm","clk":"11540747419","pt":1719497953323,"mc":[{"id":"1.230178313","rc":[{"atb":[[1.62,0.49]],"id":39100893},{"atl":[[1000,0.17]],"id":39100893},{"atb":[[1.37,0.82]],"id":52951653},{"atl":[[8.6,0.04]],"id":52951653},{"atb":[[1.63,0.48]],"id":51441055},{"atl":[[12.5,0.02]],"id":51441055}],"con":true,"img":false}]}
{"op":"mcm","clk":"11540747426","pt":1719497953422,"mc":[{"id":"1.230178313","rc":[{"atl":[[11,0.03]],"id":39100893}],"con":true,"img":false}]}
{"op":"mcm","clk":"11540750021","pt":1719497987136,"mc":[{"id":"1.230178313","rc":[{"atb":[[1.62,0]],"id":39100893},{"atl":[[11,0]],"id":39100893},{"atb":[[1.37,0]],"id":52951653},{"atl":[[8.6,0]],"id":52951653},{"atb":[[1.63,0]],"id":51441055},{"atl":[[12.5,0]],"id":51441055}],"con":true,"img":false}]}
{"op":"mcm","clk":"11540755243","pt":1719498045922,"mc":[{"id":"1.230178313","rc":[{"atl":[[2.5,10]],"id":56913144}],"con":true,"img":false}]}
{"op":"mcm","clk":"11540755922","pt":1719498054129,"mc":[{"id":"1.230178313","rc":[{"atl":[[2.5,0]],"id":56913144},{"trd":[[2.5,20]],"ltp":2.5,"tv":20.0,"id":56913144}],"con":true,"img":false}]}
{"op":"mcm","clk":"11540755976","pt":1719498054647,"mc":[{"id":"1.230178313","rc":[{"atl":[[2.86,0.84]],"id":56913144}],"con":true,"img":false}]}
{"op":"mcm","clk":"11540755994","pt":1719498054853,"mc":[{"id":"1.230178313","rc":[{"atl":[[2.86,2.18]],"id":56913144},{"atl":[[1000,1.33]],"id":68462283},{"atl":[[1000,1.44]],"id":70681331},{"atl":[[1000,1.44]],"id":39100893},{"atl":[[1000,1.44]],"id":52951653},{"atl":[[1000,1.27]],"id":51441055}],"con":true,"img":false}]}
{"op":"mcm","clk":"11540756662","pt":1719498062319,"mc":[{"id":"1.230178313","rc":[{"atb":[[1.01,24.17]],"id":39100893},{"atl":[[1000,3.14]],"id":39100893},{"atb":[[1.01,1.7]],"id":52951653},{"atl":[[1000,3.14]],"id":52951653},{"atb":[[1.01,24.17]],"id":51441055},{"atl":[[1000,2.98]],"id":51441055}],"con":true,"img":false}]}
{"op":"mcm","clk":"11540756684","pt":1719498062627,"mc":[{"id":"1.230178313","rc":[{"atb":[[1.01,22.94]],"id":39100893},{"atl":[[1000,1.47]],"id":39100893},{"atb":[[1.01,0.79]],"id":52951653},{"atl":[[1000,1.47]],"id":52951653},{"atb":[[1.01,22.93]],"id":51441055},{"atl":[[1000,1.3]],"id":51441055}],"con":true,"img":false}]}
{"op":"mcm","clk":"11540756702","pt":1719498062937,"mc":[{"id":"1.230178313","rc":[{"atb":[[1.01,22.46]],"id":39100893},{"atl":[[1000,1.44]],"id":39100893},{"atb":[[1.01,0]],"id":52951653},{"atl":[[1000,1.44]],"id":52951653},{"atb":[[1.01,22.46]],"id":51441055},{"atl":[[1000,1.27]],"id":51441055}],"con":true,"img":false}]}
{"op":"mcm","clk":"11540756716","pt":1719498063092,"mc":[{"id":"1.230178313","rc":[{"atb":[[1.37,0.79]],"id":52951653},{"atl":[[8.6,0.03]],"id":52951653},{"atb":[[1.62,0.47]],"id":39100893},{"atl":[[11,0.02]],"id":39100893},{"atb":[[1.63,0.46]],"id":51441055},{"atl":[[12.5,0.02]],"id":51441055}],"con":true,"img":false}]}
{"op":"mcm","clk":"11540761066","pt":1719498109380,"mc":[{"id":"1.230178313","rc":[{"atb":[[1.62,0]],"id":39100893},{"atl":[[11,0]],"id":39100893},{"atb":[[1.37,0]],"id":52951653},{"atl":[[8.6,0]],"id":52951653},{"atb":[[1.63,0]],"id":51441055},{"atl":[[12.5,0]],"id":51441055}],"con":true,"img":false}]}
{"op":"mcm","clk":"11540762082","pt":1719498121314,"mc":[{"id":"1.230178313","rc":[{"atb":[[1.01,1]],"id":56913144},{"spn":2.24,"spf":"NaN","id":56913144}],"con":true,"img":false}]}
{"op":"mcm","clk":"11540762120","pt":1719498121831,"mc":[{"id":"1.230178313","rc":[{"atb":[[1.03,1.64]],"id":56913144}],"con":true,"img":false}]}
{"op":"mcm","clk":"11540762578","pt":1719498126496,"mc":[{"id":"1.230178313","rc":[{"atb":[[2.32,0],[2.12,1]],"id":68462283}],"con":true,"img":false}]}
{"op":"mcm","clk":"11540762600","pt":1719498126702,"mc":[{"id":"1.230178313","rc":[{"atl":[[5.6,0],[5.8,1]],"id":70681331},{"atl":[[4.6,1],[4.4,0]],"id":39100893},{"atl":[[4.6,1]],"id":52951653},{"atl":[[4.8,0],[5.2,1]],"id":51441055}],"con":true,"img":false}]}
{"op":"mcm","clk":"11540762616","pt":1719498126805,"mc":[{"id":"1.230178313","rc":[{"atl":[[4.4,0]],"id":52951653}],"con":true,"img":false}]}
{"op":"mcm","clk":"11540762874","pt":1719498129536,"mc":[{"id":"1.230178313","rc":[{"atb":[[1.08,50]],"id":56913144},{"atb":[[1.08,50]],"id":68462283},{"atb":[[1.08,50]],"id":70681331},{"atb":[[1.08,50]],"id":52951653},{"atb":[[1.08,50]],"id":39100893},{"atb":[[1.08,50]],"id":51441055}],"con":true,"img":false}]}
{"op":"mcm","clk":"11540762896","pt":1719498129689,"mc":[{"id":"1.230178313","rc":[{"atb":[[1.98,3.48],[2.04,0]],"id":68462283}],"con":true,"img":false}]}
{"op":"mcm","clk":"11540762938","pt":1719498130203,"mc":[{"id":"1.230178313","rc":[{"atb":[[1.09,1.61]],"id":68462283},{"atb":[[1.09,1.61]],"id":70681331},{"atb":[[1.09,1.6]],"id":39100893},{"atb":[[1.09,1.49]],"id":51441055}],"con":true,"img":false}]}
{"op":"mcm","clk":"11540762945","pt":1719498130306,"mc":[{"id":"1.230178313","rc":[{"atb":[[1.03,0]],"id":56913144},{"atb":[[1.03,0]],"id":52951653}],"con":true,"img":false}]}
{"op":"mcm","clk":"11540762953","pt":1719498130410,"mc":[{"id":"1.230178313","rc":[{"atb":[[1.09,1.64]],"id":56913144},{"atb":[[1.09,1.56]],"id":52951653}],"con":true,"img":false}]}
{"op":"mcm","clk":"11540763651","pt":1719498138343,"mc":[{"id":"1.230178313","rc":[{"atl":[[2.84,0.52]],"id":56913144}],"con":true,"img":false}]}
{"op":"mcm","clk":"11540763659","pt":1719498138446,"mc":[{"id":"1.230178313","rc":[{"atb":[[1.63,0.83]],"id":56913144}],"con":true,"img":false}]}
{"op":"mcm","clk":"11540765044","pt":1719498153620,"mc":[{"id":"1.230178313","rc":[{"atl":[[2.84,0]],"id":56913144}],"con":true,"img":false}]}
{"op":"mcm","clk":"11540765076","pt":1719498154031,"mc":[{"id":"1.230178313","rc":[{"atb":[[1.63,0]],"id":56913144}],"con":true,"img":false}]}
{"op":"mcm","clk":"11540765386","pt":1719498157336,"mc":[{"id":"1.230178313","rc":[{"atb":[[2.32,1],[2.12,0]],"id":68462283}],"con":true,"img":false}]}
{"op":"mcm","clk":"11540765408","pt":1719498157543,"mc":[{"id":"1.230178313","rc":[{"atb":[[2.32,0],[2.12,1]],"id":68462283}],"con":true,"img":false}]}
{"op":"mcm","clk":"11540765445","pt":1719498157956,"mc":[{"id":"1.230178313","rc":[{"atb":[[2.32,1],[2.12,0]],"id":68462283}],"con":true,"img":false}]}
{"op":"mcm","clk":"11540765473","pt":1719498158166,"mc":[{"id":"1.230178313","rc":[{"atb":[[2.32,0],[2.12,1]],"id":68462283}],"con":true,"img":false}]}
{"op":"mcm","clk":"11540765505","pt":1719498158474,"mc":[{"id":"1.230178313","rc":[{"atb":[[1.63,0.83]],"id":56913144},{"atl":[[2.84,0.52]],"id":56913144}],"con":true,"img":false}]}
{"op":"mcm","clk":"11540766921","pt":1719498173752,"mc":[{"id":"1.230178313","rc":[{"atb":[[1.63,0]],"id":56913144}],"con":true,"img":false}]}
{"op":"mcm","clk":"11540766932","pt":1719498173856,"mc":[{"id":"1.230178313","rc":[{"atl":[[2.84,0]],"id":56913144}],"con":true,"img":false}]}
{"op":"mcm","clk":"11540767072","pt":1719498175353,"mc":[{"id":"1.230178313","rc":[{"atb":[[1.59,7.48]],"id":56913144}],"con":true,"img":false}]}
{"op":"mcm","clk":"11540767094","pt":1719498175558,"mc":[{"id":"1.230178313","rc":[{"atb":[[1.59,1]],"id":56913144}],"con":true,"img":false}]}
{"op":"mcm","clk":"11540767352","pt":1719498178475,"mc":[{"id":"1.230178313","rc":[{"atb":[[2.32,1],[2.12,0]],"id":68462283}],"con":true,"img":false}]}
{"op":"mcm","clk":"11540767492","pt":1719498180292,"mc":[{"id":"1.230178313","rc":[{"atb":[[2.32,0],[2.12,1]],"id":68462283}],"con":true,"img":false}]}
{"op":"mcm","clk":"11540767512","pt":1719498180491,"mc":[{"id":"1.230178313","rc":[{"atb":[[1.63,0.83]],"id":56913144},{"atl":[[2.84,0.52]],"id":56913144}],"con":true,"img":false}]}
{"op":"mcm","clk":"11540768099","pt":1719498185882,"mc":[{"id":"1.230178313","rc":[{"spn":2.23,"spf":"NaN","id":56913144},{"spn":1.78,"spf":1.0,"id":68462283},{"spn":4.02,"spf":"NaN","id":70681331},{"atb":[[1.01,1.7]],"id":52951653},{"atl":[[1000,3.14]],"id":52951653},{"spn":3.19,"spf":"NaN","id":52951653},{"atb":[[1.01,24.17]],"id":39100893},{"atl":[[1000,3.14]],"id":39100893},{"spn":3.19,"spf":"NaN","id":39100893},{"atb":[[1.01,24.17]],"id":51441055},{"atl":[[1000,2.98]],"id":51441055}],"con":true,"img":false}]}
{"op":"mcm","clk":"11540768140","pt":1719498186210,"mc":[{"id":"1.230178313","rc":[{"atb":[[1.01,22.92]],"id":39100893},{"atl":[[1000,1.46]],"id":39100893},{"atb":[[1.01,0.76]],"id":52951653},{"atl":[[1000,1.47]],"id":52951653},{"atb":[[1.01,22.91]],"id":51441055},{"atl":[[1000,1.3]],"id":51441055}],"con":true,"img":false}]}
{"op":"mcm","clk":"11540768162","pt":1719498186404,"mc":[{"id":"1.230178313","rc":[{"atb":[[1.01,22.46]],"id":39100893},{"atl":[[1000,1.44]],"id":39100893},{"atb":[[1.01,0]],"id":52951653},{"atl":[[1000,1.44]],"id":52951653},{"atb":[[1.01,22.46]],"id":51441055},{"atl":[[1000,1.27]],"id":51441055}],"con":true,"img":false}]}
{"op":"mcm","clk":"11540768173","pt":1719498186467,"mc":[{"id":"1.230178313","rc":[{"atb":[[1.37,0.76]],"id":52951653},{"atl":[[8.6,0.03]],"id":52951653},{"atb":[[1.62,0.45]],"id":39100893},{"atl":[[11,0.02]],"id":39100893},{"atb":[[1.63,0.45]],"id":51441055},{"atl":[[12.5,0.02]],"id":51441055}],"con":true,"img":false}]}
{"op":"mcm","clk":"11540768353","pt":1719498187973,"mc":[{"id":"1.230178313","rc":[{"atb":[[2.32,1],[2.12,0]],"id":68462283}],"con":true,"img":false}]}
{"op":"mcm","clk":"11540768363","pt":1719498188076,"mc":[{"id":"1.230178313","rc":[{"atl":[[5.6,1],[5.8,0]],"id":70681331},{"atl":[[4.6,0],[4.4,1]],"id":52951653},{"atl":[[4.6,0],[4.4,1]],"id":39100893},{"atl":[[4.8,1],[5.2,0]],"id":51441055}],"con":true,"img":false}]}
{"op":"mcm","clk":"11540768385","pt":1719498188288,"mc":[{"id":"1.230178313","rc":[{"atb":[[1.99,2.5]],"id":68462283},{"atb":[[1.86,2.09]],"id":70681331},{"atb":[[1.56,2.3]],"id":52951653},{"atb":[[1.62,2.55]],"id":39100893},{"atb":[[1.73,2]],"id":51441055}],"con":true,"img":false}]}
{"op":"mcm","clk":"11540768411","pt":1719498188496,"mc":[{"id":"1.230178313","rc":[{"atb":[[1.79,0],[1.86,4.18]],"id":70681331},{"atb":[[1.56,4.6],[1.36,0]],"id":52951653},{"atb":[[1.73,4],[1.62,0]],"id":51441055}],"con":true,"img":false}]}
{"op":"mcm","clk":"11540768640","pt":1719498190577,"mc":[{"id":"1.230178313","rc":[{"atb":[[1.02,11.23]],"id":52951653}],"con":true,"img":false}]}
{"op":"mcm","clk":"11540768652","pt":1719498190678,"mc":[{"id":"1.230178313","rc":[{"atb":[[1.57,2]],"id":52951653}],"con":true,"img":false}]}
{"op":"mcm","clk":"11540768680","pt":1719498190991,"mc":[{"id":"1.230178313","rc":[{"atb":[[1.02,0]],"id":51441055}],"con":true,"img":false}]}
{"op":"mcm","clk":"11540768694","pt":1719498191104,"mc":[{"id":"1.230178313","rc":[{"atb":[[2.32,0],[2.12,1]],"id":68462283},{"atb":[[1.74,2]],"id":51441055}],"con":true,"img":false}]}
{"op":"mcm","clk":"11540768708","pt":1719498191205,"mc":[{"id":"1.230178313","rc":[{"atb":[[2,2.5],[1.98,0]],"id":68462283}],"con":true,"img":false}]}
{"op":"mcm","clk":"11540768722","pt":1719498191308,"mc":[{"id":"1.230178313","rc":[{"atl":[[5.6,0],[5.8,1]],"id":70681331},{"atl":[[4.6,1],[4.4,0]],"id":52951653},{"atl":[[4.6,1],[4.4,0]],"id":39100893},{"atl":[[4.8,0],[5.2,1]],"id":51441055}],"con":true,"img":false}]}
{"op":"mcm","clk":"11540768733","pt":1719498191412,"mc":[{"id":"1.230178313","rc":[{"atb":[[1.02,0]],"id":70681331}],"con":true,"img":false}]}
{"op":"mcm","clk":"11540768743","pt":1719498191504,"mc":[{"id":"1.230178313","rc":[{"atb":[[1.87,2]],"id":70681331}],"con":true,"img":false}]}
{"op":"mcm","clk":"11540768897","pt":1719498192878,"mc":[{"id":"1.230178313","rc":[{"atb":[[2.22,3.75]],"id":70681331},{"atb":[[1.96,2.5]],"id":51441055}],"con":true,"img":false}]}
{"op":"mcm","clk":"11540768916","pt":1719498193090,"mc":[{"id":"1.230178313","rc":[{"atb":[[2.22,0]],"id":70681331},{"atb":[[1.96,0]],"id":51441055}],"con":true,"img":false}]}
{"op":"mcm","clk":"11540769036","pt":1719498194078,"mc":[{"id":"1.230178313","rc":[{"atb":[[1.57,0]],"id":52951653}],"con":true,"img":false}]}
{"op":"mcm","clk":"11540769051","pt":1719498194192,"mc":[{"id":"1.230178313","rc":[{"atb":[[1.02,13.23]],"id":52951653}],"con":true,"img":false}]}
{"op":"mcm","clk":"11540769085","pt":1719498194503,"mc":[{"id":"1.230178313","rc":[{"atb":[[1.74,0]],"id":51441055}],"con":true,"img":false}]}
{"op":"mcm","clk":"11540769097","pt":1719498194611,"mc":[{"id":"1.230178313","rc":[{"atb":[[1.02,2]],"id":51441055}],"con":true,"img":false}]}
{"op":"mcm","clk":"11540769127","pt":1719498194868,"mc":[{"id":"1.230178313","rc":[{"atb":[[1.87,0]],"id":70681331}],"con":true,"img":false}]}
{"op":"mcm","clk":"11540769140","pt":1719498194980,"mc":[{"id":"1.230178313","rc":[{"atb":[[1.02,2]],"id":70681331}],"con":true,"img":false}]}
{"op":"mcm","clk":"11540769241","pt":1719498196012,"mc":[{"id":"1.230178313","rc":[{"atl":[[2.84,0]],"id":56913144},{"atb":[[1.54,2.5]],"id":52951653}],"con":true,"img":false}]}
{"op":"mcm","clk":"11540769265","pt":1719498196209,"mc":[{"id":"1.230178313","rc":[{"atb":[[1.63,0]],"id":56913144},{"atb":[[1.54,0]],"id":52951653}],"con":true,"img":false}]}
{"op":"mcm","clk":"11540769305","pt":1719498196580,"mc":[{"id":"1.230178313","rc":[{"atb":[[1.02,11.23]],"id":52951653}],"con":true,"img":false}]}
{"op":"mcm","clk":"11540769315","pt":1719498196687,"mc":[{"id":"1.230178313","rc":[{"atb":[[1.57,2]],"id":52951653}],"con":true,"img":false}]}
{"op":"mcm","clk":"11540769362","pt":1719498197097,"mc":[{"id":"1.230178313","rc":[{"atb":[[1.02,0]],"id":51441055}],"con":true,"img":false}]}
{"op":"mcm","clk":"11540769375","pt":1719498197202,"mc":[{"id":"1.230178313","rc":[{"atb":[[1.74,2]],"id":51441055}],"con":true,"img":false}]}
{"op":"mcm","clk":"11540769407","pt":1719498197517,"mc":[{"id":"1.230178313","rc":[{"atb":[[1.02,0]],"id":70681331}],"con":true,"img":false}]}
{"op":"mcm","clk":"11540769420","pt":1719498197616,"mc":[{"id":"1.230178313","rc":[{"atb":[[1.87,2]],"id":70681331}],"con":true,"img":false}]}
{"op":"mcm","clk":"11540769605","pt":1719498199278,"mc":[{"id":"1.230178313","rc":[{"atb":[[1.57,0]],"id":52951653}],"con":true,"img":false}]}
{"op":"mcm","clk":"11540769615","pt":1719498199387,"mc":[{"id":"1.230178313","rc":[{"atb":[[1.02,13.23]],"id":52951653}],"con":true,"img":false}]}
{"op":"mcm","clk":"11540769659","pt":1719498199797,"mc":[{"id":"1.230178313","rc":[{"atb":[[1.74,0]],"id":51441055}],"con":true,"img":false}]}
{"op":"mcm","clk":"11540769669","pt":1719498199896,"mc":[{"id":"1.230178313","rc":[{"atb":[[1.02,2]],"id":51441055}],"con":true,"img":false}]}
{"op":"mcm","clk":"11540769712","pt":1719498200313,"mc":[{"id":"1.230178313","rc":[{"atb":[[1.87,0]],"id":70681331}],"con":true,"img":false}]}
{"op":"mcm","clk":"11540769722","pt":1719498200418,"mc":[{"id":"1.230178313","rc":[{"atb":[[1.02,2]],"id":70681331}],"con":true,"img":false}]}
{"op":"mcm","clk":"11540769809","pt":1719498201200,"mc":[{"id":"1.230178313","rc":[{"atb":[[2.32,1],[2.12,0]],"id":68462283}],"con":true,"img":false}]}
{"op":"mcm","clk":"11540769845","pt":1719498201518,"mc":[{"id":"1.230178313","rc":[{"atb":[[1.02,11.23]],"id":52951653}],"con":true,"img":false}]}
{"op":"mcm","clk":"11540769856","pt":1719498201621,"mc":[{"id":"1.230178313","rc":[{"atb":[[1.57,2]],"id":52951653}],"con":true,"img":false}]}
{"op":"mcm","clk":"11540769877","pt":1719498201821,"mc":[{"id":"1.230178313","rc":[{"atb":[[1.02,0]],"id":51441055}],"con":true,"img":false}]}
{"op":"mcm","clk":"11540769893","pt":1719498201886,"mc":[{"id":"1.230178313","rc":[{"atb":[[2.32,0],[2.12,1]],"id":68462283},{"atb":[[1.74,2]],"id":51441055}],"con":true,"img":false}]}
{"op":"mcm","clk":"11540769905","pt":1719498201985,"mc":[{"id":"1.230178313","rc":[{"atb":[[1.99,0]],"id":68462283},{"atb":[[1.86,2.09]],"id":70681331},{"atb":[[1.56,2.3]],"id":52951653},{"atb":[[1.73,2]],"id":51441055}],"con":true,"img":false}]}
{"op":"mcm","clk":"11540769914","pt":1719498202092,"mc":[{"id":"1.230178313","rc":[{"atb":[[1.02,0],[1.86,0],[1.76,3.09]],"id":70681331}],"con":true,"img":false}]}
{"op":"mcm","clk":"11540769924","pt":1719498202187,"mc":[{"id":"1.230178313","rc":[{"atb":[[1.62,5.1]],"id":56913144},{"atb":[[2.32,3]],"id":68462283},{"atb":[[2.24,3.9],[1.87,2]],"id":70681331},{"atb":[[1.58,2.9]],"id":52951653},{"atb":[[1.74,5]],"id":51441055}],"con":true,"img":false}]}
{"op":"mcm","clk":"11540769941","pt":1719498202301,"mc":[{"id":"1.230178313","rc":[{"atb":[[1.63,4.24],[1.61,0]],"id":56913144},{"atb":[[2,0],[2.34,2.5]],"id":68462283},{"atb":[[2.24,6.99]],"id":70681331}],"con":true,"img":false}]}
{"op":"mcm","clk":"11540769956","pt":1719498202404,"mc":[{"id":"1.230178313","rc":[{"atl":[[2.84,0.52]],"id":56913144},{"atb":[[1.76,0]],"id":70681331}],"con":true,"img":false}]}
{"op":"mcm","clk":"11540769969","pt":1719498202509,"mc":[{"id":"1.230178313","rc":[{"atb":[[1.63,5.07]],"id":56913144}],"con":true,"img":false}]}
{"op":"mcm","clk":"11540770032","pt":1719498203119,"mc":[{"id":"1.230178313","rc":[{"atb":[[1.57,0]],"id":52951653}],"con":true,"img":false}]}
{"op":"mcm","clk":"11540770043","pt":1719498203186,"mc":[{"id":"1.230178313","rc":[{"atb":[[1.59,2]],"id":52951653}],"con":true,"img":false}]}
{"op":"mcm","clk":"11540770087","pt":1719498203807,"mc":[{"id":"1.230178313","rc":[{"atb":[[1.74,3]],"id":51441055}],"con":true,"img":false}]}
{"op":"mcm","clk":"11540770098","pt":1719498203913,"mc":[{"id":"1.230178313","rc":[{"atb":[[1.02,2]],"id":51441055}],"con":true,"img":false}]}
{"op":"mcm","clk":"11540770124","pt":1719498204221,"mc":[{"id":"1.230178313","rc":[{"atb":[[1.87,0]],"id":70681331}],"con":true,"img":false}]}
{"op":"mcm","clk":"11540770136","pt":1719498204315,"mc":[{"id":"1.230178313","rc":[{"atb":[[1.02,2]],"id":70681331}],"con":true,"img":false}]}
{"op":"mcm","clk":"11540770162","pt":1719498204581,"mc":[{"id":"1.230178313","rc":[{"atb":[[1.62,3.1]],"id":56913144}],"con":true,"img":false}]}
{"op":"mcm","clk":"11540770173","pt":1719498204688,"mc":[{"id":"1.230178313","rc":[{"atb":[[1.64,2],[1.65,6.07]],"id":56913144}],"con":true,"img":false}]}
{"op":"mcm","clk":"11540770183","pt":1719498204792,"mc":[{"id":"1.230178313","rc":[{"atb":[[1.66,5.08]],"id":56913144}],"con":true,"img":false}]}
{"op":"mcm","clk":"11540770196","pt":1719498204898,"mc":[{"id":"1.230178313","rc":[{"atb":[[1.63,0.83]],"id":56913144}],"con":true,"img":false}]}
{"op":"mcm","clk":"11540770407","pt":1719498207015,"mc":[{"id":"1.230178313","rc":[{"atb":[[1.02,0]],"id":70681331}],"con":true,"img":false}]}
{"op":"mcm","clk":"11540770414","pt":1719498207077,"mc":[{"id":"1.230178313","rc":[{"atb":[[2.26,2]],"id":70681331}],"con":true,"img":false}]}
{"op":"mcm","clk":"11540770438","pt":1719498207381,"mc":[{"id":"1.230178313","rc":[{"atb":[[1.64,0]],"id":56913144},{"atb":[[2.32,8],[2.34,0]],"id":68462283}],"con":true,"img":false}]}
{"op":"mcm","clk":"11540770449","pt":1719498207480,"mc":[{"id":"1.230178313","rc":[{"atb":[[1.67,2]],"id":56913144},{"atb":[[2.12,6.5]],"id":68462283}],"con":true,"img":false}]}
{"op":"mcm","clk":"11540770463","pt":1719498207590,"mc":[{"id":"1.230178313","rc":[{"atb":[[2.32,3]],"id":68462283}],"con":true,"img":false}]}
{"op":"mcm","clk":"11540770563","pt":1719498208622,"mc":[{"id":"1.230178313","rc":[{"atb":[[2.12,1],[2.34,3]],"id":68462283}],"con":true,"img":false}]}
{"op":"mcm","clk":"11540770589","pt":1719498208890,"mc":[{"id":"1.230178313","rc":[{"atb":[[2.26,0]],"id":70681331}],"con":true,"img":false}]}
{"op":"mcm","clk":"11540770598","pt":1719498208996,"mc":[{"id":"1.230178313","rc":[{"atb":[[1.02,2]],"id":70681331}],"con":true,"img":false}]}
{"op":"mcm","clk":"11540770738","pt":1719498210703,"mc":[{"id":"1.230178313","rc":[{"atb":[[1.02,0]],"id":70681331}],"con":true,"img":false}]}
{"op":"mcm","clk":"11540770744","pt":1719498210796,"mc":[{"id":"1.230178313","rc":[{"atb":[[2.26,2]],"id":70681331}],"con":true,"img":false}]}
{"op":"mcm","clk":"11540770754","pt":1719498210899,"mc":[{"id":"1.230178313","rc":[{"atb":[[1.69,6.13]],"id":56913144}],"con":true,"img":false}]}
{"op":"mcm","clk":"11540770768","pt":1719498211003,"mc":[{"id":"1.230178313","rc":[{"atb":[[1.7,5.08]],"id":56913144}],"con":true,"img":false}]}
{"op":"mcm","clk":"11540770775","pt":1719498211108,"mc":[{"id":"1.230178313","rc":[{"atb":[[1.66,0]],"id":56913144}],"con":true,"img":false}]}
{"op":"mcm","clk":"11540770844","pt":1719498211698,"mc":[{"id":"1.230178313","rc":[{"atb":[[2.26,0]],"id":70681331}],"con":true,"img":false}]}
{"op":"mcm","clk":"11540770857","pt":1719498211794,"mc":[{"id":"1.230178313","rc":[{"atb":[[1.02,2]],"id":70681331}],"con":true,"img":false}]}
{"op":"mcm","clk":"11540770868","pt":1719498211899,"mc":[{"id":"1.230178313","rc":[{"atb":[[2.32,4],[2.12,0]],"id":68462283}],"con":true,"img":false}]}
{"op":"mcm","clk":"11540770880","pt":1719498212004,"mc":[{"id":"1.230178313","rc":[{"atb":[[1.67,0]],"id":56913144}],"con":true,"img":false}]}
{"op":"mcm","clk":"11540770893","pt":1719498212105,"mc":[{"id":"1.230178313","rc":[{"atb":[[1.71,2]],"id":56913144}],"con":true,"img":false}]}
{"op":"mcm","clk":"11540770956","pt":1719498212731,"mc":[{"id":"1.230178313","rc":[{"atb":[[2.32,3]],"id":68462283}],"con":true,"img":false}]}
{"op":"mcm","clk":"11540771018","pt":1719498213302,"mc":[{"id":"1.230178313","rc":[{"atb":[[1.02,0]],"id":70681331}],"con":true,"img":false}]}
{"op":"mcm","clk":"11540771029","pt":1719498213408,"mc":[{"id":"1.230178313","rc":[{"atb":[[2.26,2]],"id":70681331}],"con":true,"img":false}]}
{"op":"mcm","clk":"11540771053","pt":1719498213715,"mc":[{"id":"1.230178313","rc":[{"atb":[[2.32,9],[2.34,0]],"id":68462283}],"con":true,"img":false}]}
{"op":"mcm","clk":"11540771066","pt":1719498213821,"mc":[{"id":"1.230178313","rc":[{"atb":[[2.32,3],[1.98,6]],"id":68462283}],"con":true,"img":false}]}
{"op":"mcm","clk":"11540771174","pt":1719498214921,"mc":[{"id":"1.230178313","rc":[{"atb":[[1.98,0],[2.34,3]],"id":68462283}],"con":true,"img":false}]}
{"op":"mcm","clk":"11540771186","pt":1719498215004,"mc":[{"id":"1.230178313","rc":[{"atb":[[2.32,9],[2.34,0]],"id":68462283},{"atb":[[2.26,0]],"id":70681331}],"con":true,"img":false}]}
{"op":"mcm","clk":"11540771198","pt":1719498215100,"mc":[{"id":"1.230178313","rc":[{"atb":[[2.32,3],[1.98,6]],"id":68462283},{"atb":[[1.02,2]],"id":70681331}],"con":true,"img":false}]}
{"op":"mcm","clk":"11540771265","pt":1719498215725,"mc":[{"id":"1.230178313","rc":[{"atb":[[2.32,4]],"id":68462283}],"con":true,"img":false}]}
{"op":"mcm","clk":"11540771291","pt":1719498215927,"mc":[{"id":"1.230178313","rc":[{"atl":[[5.6,1],[5.8,0]],"id":70681331},{"atl":[[4.6,0],[4.4,1]],"id":52951653},{"atl":[[4.6,0],[4.4,1]],"id":39100893},{"atl":[[4.8,1],[5.2,0]],"id":51441055}],"con":true,"img":false}]}
{"op":"mcm","clk":"11540771308","pt":1719498215985,"mc":[{"id":"1.230178313","rc":[{"atl":[[20,0],[22,3]],"id":70681331}],"con":true,"img":false}]}
{"op":"mcm","clk":"11540771327","pt":1719498216187,"mc":[{"id":"1.230178313","rc":[{"atb":[[1.62,0]],"id":56913144},{"atb":[[1.58,0]],"id":52951653}],"con":true,"img":false}]}
{"op":"mcm","clk":"11540771349","pt":1719498216394,"mc":[{"id":"1.230178313","rc":[{"atb":[[1.71,5.6]],"id":56913144},{"atb":[[1.6,3.8]],"id":52951653}],"con":true,"img":false}]}
{"op":"mcm","clk":"11540771360","pt":1719498216499,"mc":[{"id":"1.230178313","rc":[{"atb":[[1.56,0],[1.61,2.3]],"id":52951653}],"con":true,"img":false}]}
{"op":"mcm","clk":"11540771387","pt":1719498216713,"mc":[{"id":"1.230178313","rc":[{"atb":[[1.09,0]],"id":56913144},{"atb":[[1.59,0]],"id":52951653}],"con":true,"img":false}]}
{"op":"mcm","clk":"11540771398","pt":1719498216817,"mc":[{"id":"1.230178313","rc":[{"atb":[[1.72,1.64]],"id":56913144},{"atb":[[1.57,2]],"id":52951653}],"con":true,"img":false}]}
{"op":"mcm","clk":"11540771430","pt":1719498217127,"mc":[{"id":"1.230178313","rc":[{"atb":[[1.02,0]],"id":70681331}],"con":true,"img":false}]}
{"op":"mcm","clk":"11540771440","pt":1719498217227,"mc":[{"id":"1.230178313","rc":[{"atb":[[1.7,0],[1.72,6.72]],"id":56913144},{"atb":[[2.26,2]],"id":70681331}],"con":true,"img":false}]}
{"op":"mcm","clk":"11540771481","pt":1719498217594,"mc":[{"id":"1.230178313","rc":[{"atb":[[2.32,3]],"id":68462283}],"con":true,"img":false}]}
{"op":"mcm","clk":"11540771489","pt":1719498217696,"mc":[{"id":"1.230178313","rc":[{"atl":[[2.84,0]],"id":56913144},{"atl":[[5.8,1]],"id":70681331},{"atl":[[4.6,1]],"id":52951653},{"atl":[[4.6,1]],"id":39100893},{"atl":[[4.8,0],[5.2,1]],"id":51441055}],"con":true,"img":false}]}
{"op":"mcm","clk":"11540771497","pt":1719498217801,"mc":[{"id":"1.230178313","rc":[{"atl":[[5.6,0]],"id":70681331},{"atl":[[4.4,0]],"id":52951653},{"atl":[[4.4,0]],"id":39100893}],"con":true,"img":false}]}
{"op":"mcm","clk":"11540771508","pt":1719498217902,"mc":[{"id":"1.230178313","rc":[{"atb":[[1.72,5.08],[1.63,0],[1.74,2.11],[1.52,0]],"id":56913144}],"con":true,"img":false}]}
{"op":"mcm","clk":"11540771646","pt":1719498219508,"mc":[{"id":"1.230178313","rc":[{"atb":[[1.57,0]],"id":52951653}],"con":true,"img":false}]}
{"op":"mcm","clk":"11540771653","pt":1719498219603,"mc":[{"id":"1.230178313","rc":[{"atb":[[1.62,2]],"id":52951653}],"con":true,"img":false}]}
{"op":"mcm","clk":"11540771683","pt":1719498219913,"mc":[{"id":"1.230178313","rc":[{"atb":[[2.26,0]],"id":70681331}],"con":true,"img":false}]}
{"op":"mcm","clk":"11540771693","pt":1719498220017,"mc":[{"id":"1.230178313","rc":[{"atb":[[1.02,2]],"id":70681331}],"con":true,"img":false}]}
{"op":"mcm","clk":"11540771787","pt":1719498220906,"mc":[{"id":"1.230178313","rc":[{"atb":[[1.71,3.6]],"id":56913144}],"con":true,"img":false}]}
{"op":"mcm","clk":"11540771796","pt":1719498221007,"mc":[{"id":"1.230178313","rc":[{"atb":[[1.75,2]],"id":56913144}],"con":true,"img":false}]}
{"op":"mcm","clk":"11540771823","pt":1719498221320,"mc":[{"id":"1.230178313","rc":[{"atb":[[1.98,0],[2.34,3]],"id":68462283}],"con":true,"img":false}]}
{"op":"mcm","clk":"11540771837","pt":1719498221419,"mc":[{"id":"1.230178313","rc":[{"atb":[[2.32,6],[2.34,0]],"id":68462283}],"con":true,"img":false}]}
{"op":"mcm","clk":"11540771860","pt":1719498221632,"mc":[{"id":"1.230178313","rc":[{"atb":[[2.32,3],[1.98,6]],"id":68462283}],"con":true,"img":false}]}
{"op":"mcm","clk":"11540771880","pt":1719498221829,"mc":[{"id":"1.230178313","rc":[{"atb":[[1.98,0],[2.34,2]],"id":68462283}],"con":true,"img":false}]}
{"op":"mcm","clk":"11540771887","pt":1719498221932,"mc":[{"id":"1.230178313","rc":[{"atb":[[2.32,6],[2.34,0]],"id":68462283}],"con":true,"img":false}]}
{"op":"mcm","clk":"11540771903","pt":1719498222094,"mc":[{"id":"1.230178313","rc":[{"atb":[[1.98,5]],"id":68462283}],"con":true,"img":false}]}
{"op":"mcm","clk":"11540771914","pt":1719498222201,"mc":[{"id":"1.230178313","rc":[{"atb":[[2.32,3]],"id":68462283}],"con":true,"img":false}]}
{"op":"mcm","clk":"11540771963","pt":1719498222818,"mc":[{"id":"1.230178313","rc":[{"atb":[[1.02,0]],"id":70681331}],"con":true,"img":false}]}
{"op":"mcm","clk":"11540771973","pt":1719498222922,"mc":[{"id":"1.230178313","rc":[{"atb":[[2.26,2]],"id":70681331}],"con":true,"img":false}]}
{"op":"mcm","clk":"11540771984","pt":1719498223024,"mc":[{"id":"1.230178313","rc":[{"atl":[[2.84,0.52]],"id":56913144}],"con":true,"img":false}]}
{"op":"mcm","clk":"11540771993","pt":1719498223128,"mc":[{"id":"1.230178313","rc":[{"atb":[[1.76,0.69]],"id":56913144}],"con":true,"img":false}]}
{"op":"mcm","clk":"11540772025","pt":1719498223429,"mc":[{"id":"1.230178313","rc":[{"atb":[[1.72,0],[1.75,4.12]],"id":56913144}],"con":true,"img":false}]}
{"op":"mcm","clk":"11540772106","pt":1719498224112,"mc":[{"id":"1.230178313","rc":[{"atb":[[2.26,0]],"id":70681331},{"atb":[[1.37,0]],"id":52951653},{"atl":[[8.6,0]],"id":52951653},{"atb":[[1.62,2.1]],"id":39100893},{"atl":[[11,0]],"id":39100893},{"atb":[[1.63,0]],"id":51441055},{"atl":[[12.5,0]],"id":51441055}],"con":true,"img":false}]}
{"op":"mcm","clk":"11540772122","pt":1719498224215,"mc":[{"id":"1.230178313","rc":[{"atb":[[1.02,2]],"id":70681331}],"con":true,"img":false}]}
{"op":"mcm","clk":"11540772211","pt":1719498225135,"mc":[{"id":"1.230178313","rc":[{"atb":[[2.12,1]],"id":68462283}],"con":true,"img":false}]}
{"op":"mcm","clk":"11540772289","pt":1719498225716,"mc":[{"id":"1.230178313","rc":[{"atb":[[1.02,0]],"id":70681331}],"con":true,"img":false}]}
{"op":"mcm","clk":"11540772299","pt":1719498225810,"mc":[{"id":"1.230178313","rc":[{"atb":[[2.26,2]],"id":70681331}],"con":true,"img":false}]}
{"op":"mcm","clk":"11540772510","pt":1719498227932,"mc":[{"id":"1.230178313","rc":[{"atb":[[2.26,0]],"id":70681331}],"con":true,"img":false}]}
{"op":"mcm","clk":"11540772521","pt":1719498228045,"mc":[{"id":"1.230178313","rc":[{"atb":[[1.02,2]],"id":70681331}],"con":true,"img":false}]}
{"op":"mcm","clk":"11540772531","pt":1719498228242,"mc":[{"id":"1.230178313","rc":[{"atb":[[1.98,0],[2.34,3]],"id":68462283}],"con":true,"img":false}]}
{"op":"mcm","clk":"11540772546","pt":1719498228303,"mc":[{"id":"1.230178313","rc":[{"atb":[[2.32,6],[2.34,0]],"id":68462283}],"con":true,"img":false}]}
{"op":"mcm","clk":"11540772561","pt":1719498228504,"mc":[{"id":"1.230178313","rc":[{"atb":[[2.32,3],[2.12,7]],"id":68462283}],"con":true,"img":false}]}
{"op":"mcm","clk":"11540772734","pt":1719498230317,"mc":[{"id":"1.230178313","rc":[{"atb":[[1.64,6.16]],"id":52951653}],"con":true,"img":false}]}
{"op":"mcm","clk":"11540772747","pt":1719498230514,"mc":[{"id":"1.230178313","rc":[{"atb":[[1.71,0]],"id":56913144},{"atb":[[1.02,0]],"id":70681331},{"atb":[[1.6,0],[1.65,2.3],[1.61,0]],"id":52951653}],"con":true,"img":false}]}
{"op":"mcm","clk":"11540772759","pt":1719498230624,"mc":[{"id":"1.230178313","rc":[{"atb":[[1.75,7.12]],"id":56913144},{"atb":[[2.26,2]],"id":70681331},{"atb":[[1.78,4.9]],"id":52951653}],"con":true,"img":false}]}
{"op":"mcm","clk":"11540772770","pt":1719498230720,"mc":[{"id":"1.230178313","rc":[{"atb":[[1.64,6.16]],"id":39100893}],"con":true,"img":false}]}
{"op":"mcm","clk":"11540772782","pt":1719498230823,"mc":[{"id":"1.230178313","rc":[{"atb":[[1.65,2.1],[1.61,0]],"id":39100893}],"con":true,"img":false}]}
{"op":"mcm","clk":"11540772792","pt":1719498230926,"mc":[{"id":"1.230178313","rc":[{"atb":[[1.65,0]],"id":56913144}],"con":true,"img":false}]}
{"op":"mcm","clk":"11540772816","pt":1719498231234,"mc":[{"id":"1.230178313","rc":[{"atb":[[1.77,5.12]],"id":56913144}],"con":true,"img":false}]}
{"op":"mcm","clk":"11540772824","pt":1719498231337,"mc":[{"id":"1.230178313","rc":[{"atb":[[1.78,5.13],[1.75,5]],"id":56913144}],"con":true,"img":false}]}
{"op":"mcm","clk":"11540772853","pt":1719498231701,"mc":[{"id":"1.230178313","rc":[{"atb":[[1.02,0]],"id":39100893}],"con":true,"img":false}]}
{"op":"mcm","clk":"11540772862","pt":1719498231803,"mc":[{"id":"1.230178313","rc":[{"atb":[[1.66,2]],"id":39100893}],"con":true,"img":false}]}
{"op":"mcm","clk":"11540772886","pt":1719498232112,"mc":[{"id":"1.230178313","rc":[{"atb":[[1.62,0]],"id":52951653}],"con":true,"img":false}]}
{"op":"mcm","clk":"11540772896","pt":1719498232215,"mc":[{"id":"1.230178313","rc":[{"atb":[[1.79,2]],"id":52951653}],"con":true,"img":false}]}
{"op":"mcm","clk":"11540772923","pt":1719498232524,"mc":[{"id":"1.230178313","rc":[{"atb":[[2.26,0]],"id":70681331}],"con":true,"img":false}]}
{"op":"mcm","clk":"11540772939","pt":1719498232636,"mc":[{"id":"1.230178313","rc":[{"atb":[[1.02,2]],"id":70681331}],"con":true,"img":false}]}
{"op":"mcm","clk":"11540772974","pt":1719498232939,"mc":[{"id":"1.230178313","rc":[{"atb":[[1.75,3]],"id":56913144}],"con":true,"img":false}]}
{"op":"mcm","clk":"11540772982","pt":1719498233043,"mc":[{"id":"1.230178313","rc":[{"atb":[[1.79,2]],"id":56913144}],"con":true,"img":false}]}
{"op":"mcm","clk":"11540773042","pt":1719498233610,"mc":[{"id":"1.230178313","rc":[{"atb":[[1.98,10],[2.12,1]],"id":68462283}],"con":true,"img":false}]}
{"op":"mcm","clk":"11540773106","pt":1719498234238,"mc":[{"id":"1.230178313","rc":[{"atb":[[2.02,2.11]],"id":68462283},{"atb":[[1.67,2.11]],"id":52951653},{"atb":[[1.67,2.11]],"id":39100893}],"con":true,"img":false}]}
{"op":"mcm","clk":"11540773125","pt":1719498234439,"mc":[{"id":"1.230178313","rc":[{"atb":[[1.02,0]],"id":70681331}],"con":true,"img":false}]}
{"op":"mcm","clk":"11540773139","pt":1719498234543,"mc":[{"id":"1.230178313","rc":[{"atb":[[1.98,0],[2.34,2.12]],"id":68462283},{"atb":[[2.26,2]],"id":70681331}],"con":true,"img":false}]}
{"op":"mcm","clk":"11540773150","pt":1719498234598,"mc":[{"id":"1.230178313","rc":[{"atb":[[2.32,5.12],[2.34,0]],"id":68462283}],"con":true,"img":false}]}
{"op":"mcm","clk":"11540773163","pt":1719498234703,"mc":[{"id":"1.230178313","rc":[{"atb":[[2.32,3],[2.12,6.12]],"id":68462283}],"con":true,"img":false}]}
{"op":"mcm","clk":"11540773245","pt":1719498235523,"mc":[{"id":"1.230178313","rc":[{"atb":[[1.66,0]],"id":39100893}],"con":true,"img":false}]}
{"op":"mcm","clk":"11540773255","pt":1719498235625,"mc":[{"id":"1.230178313","rc":[{"atb":[[1.68,2]],"id":39100893}],"con":true,"img":false}]}
{"op":"mcm","clk":"11540773282","pt":1719498235933,"mc":[{"id":"1.230178313","rc":[{"atb":[[2.26,0]],"id":70681331}],"con":true,"img":false}]}
{"op":"mcm","clk":"11540773296","pt":1719498236036,"mc":[{"id":"1.230178313","rc":[{"atb":[[1.02,2]],"id":70681331}],"con":true,"img":false}]}
{"op":"mcm","clk":"11540773346","pt":1719498236503,"mc":[{"id":"1.230178313","rc":[{"atb":[[1.77,6.9],[1.65,0]],"id":52951653}],"con":true,"img":false}]}
{"op":"mcm","clk":"11540773380","pt":1719498236811,"mc":[{"id":"1.230178313","rc":[{"atb":[[1.68,4.1],[1.65,0]],"id":39100893}],"con":true,"img":false}]}
{"op":"mcm","clk":"11540773407","pt":1719498237022,"mc":[{"id":"1.230178313","rc":[{"atb":[[1.02,0]],"id":70681331}],"con":true,"img":false}]}
{"op":"mcm","clk":"11540773420","pt":1719498237125,"mc":[{"id":"1.230178313","rc":[{"atb":[[2.26,2]],"id":70681331}],"con":true,"img":false}]}
{"op":"mcm","clk":"11540773529","pt":1719498238004,"mc":[{"id":"1.230178313","rc":[{"atb":[[2.26,0]],"id":70681331}],"con":true,"img":false}]}
{"op":"mcm","clk":"11540773539","pt":1719498238106,"mc":[{"id":"1.230178313","rc":[{"atb":[[1.02,2]],"id":70681331}],"con":true,"img":false}]}
{"op":"mcm","clk":"11540773568","pt":1719498238417,"mc":[{"id":"1.230178313","rc":[{"atl":[[2.84,0]],"id":56913144}],"con":true,"img":false}]}
{"op":"mcm","clk":"11540773605","pt":1719498238828,"mc":[{"id":"1.230178313","rc":[{"atb":[[1.76,0]],"id":56913144}],"con":true,"img":false}]}
{"op":"mcm","clk":"11540773728","pt":1719498240123,"mc":[{"id":"1.230178313","rc":[{"atb":[[1.02,0]],"id":70681331}],"con":true,"img":false}]}
{"op":"mcm","clk":"11540773738","pt":1719498240227,"mc":[{"id":"1.230178313","rc":[{"atb":[[1.8,1]],"id":56913144},{"atl":[[2.84,1]],"id":56913144},{"atb":[[2.26,2]],"id":70681331}],"con":true,"img":false}]}
{"op":"mcm","clk":"11540773792","pt":1719498240748,"mc":[{"id":"1.230178313","rc":[{"atb":[[2.12,1],[2.34,3]],"id":68462283}],"con":true,"img":false}]}
{"op":"mcm","clk":"11540773804","pt":1719498240805,"mc":[{"id":"1.230178313","rc":[{"atb":[[2.32,6],[2.34,0]],"id":68462283}],"con":true,"img":false}]}
{"op":"mcm","clk":"11540773844","pt":1719498241217,"mc":[{"id":"1.230178313","rc":[{"atb":[[2.26,0]],"id":70681331}],"con":true,"img":false}]}
{"op":"mcm","clk":"11540773854","pt":1719498241320,"mc":[{"id":"1.230178313","rc":[{"atb":[[1.02,2]],"id":70681331}],"con":true,"img":false}]}
{"op":"mcm","clk":"11540773956","pt":1719498242416,"mc":[{"id":"1.230178313","rc":[{"atb":[[1.71,5.22]],"id":56913144}],"con":true,"img":false}]}
{"op":"mcm","clk":"11540773968","pt":1719498242520,"mc":[{"id":"1.230178313","rc":[{"atb":[[1.02,0]],"id":70681331}],"con":true,"img":false}]}
{"op":"mcm","clk":"11540773981","pt":1719498242623,"mc":[{"id":"1.230178313","rc":[{"atb":[[2.26,2]],"id":70681331}],"con":true,"img":false}]}
{"op":"mcm","clk":"11540774077","pt":1719498243414,"mc":[{"id":"1.230178313","rc":[{"atl":[[2.82,0.52]],"id":56913144}],"con":true,"img":false}]}
{"op":"mcm","clk":"11540774092","pt":1719498243510,"mc":[{"id":"1.230178313","rc":[{"atl":[[2.84,0]],"id":56913144}],"con":true,"img":false}]}
{"op":"mcm","clk":"11540774105","pt":1719498243613,"mc":[{"id":"1.230178313","rc":[{"atb":[[1.81,0.64]],"id":56913144}],"con":true,"img":false}]}
{"op":"mcm","clk":"11540774115","pt":1719498243717,"mc":[{"id":"1.230178313","rc":[{"atb":[[1.78,0],[1.8,2]],"id":56913144}],"con":true,"img":false}]}
{"op":"mcm","clk":"11540774139","pt":1719498243922,"mc":[{"id":"1.230178313","rc":[{"atb":[[2.26,0]],"id":70681331}],"con":true,"img":false}]}
{"op":"mcm","clk":"11540774148","pt":1719498244025,"mc":[{"id":"1.230178313","rc":[{"atb":[[1.02,2]],"id":70681331}],"con":true,"img":false}]}
{"op":"mcm","clk":"11540774210","pt":1719498244645,"mc":[{"id":"1.230178313","rc":[{"atb":[[1.75,0]],"id":56913144},{"atb":[[1.62,0]],"id":39100893},{"atb":[[1.78,1]],"id":52951653}],"con":true,"img":false}]}
{"op":"mcm","clk":"11540774226","pt":1719498244851,"mc":[{"id":"1.230178313","rc":[{"atb":[[1.8,6]],"id":56913144},{"atb":[[1.78,3.2]],"id":39100893},{"atb":[[1.8,4.11]],"id":52951653}],"con":true,"img":false}]}
{"op":"mcm","clk":"11540774233","pt":1719498244917,"mc":[{"id":"1.230178313","rc":[{"atb":[[1.78,6.4],[1.68,2]],"id":39100893}],"con":true,"img":false}]}
{"op":"mcm","clk":"11540774290","pt":1719498245526,"mc":[{"id":"1.230178313","rc":[{"atb":[[1.71,0]],"id":56913144}],"con":true,"img":false}]}
{"op":"mcm","clk":"11540774298","pt":1719498245631,"mc":[{"id":"1.230178313","rc":[{"atb":[[1.68,0]],"id":39100893}],"con":true,"img":false}]}
{"op":"mcm","clk":"11540774306","pt":1719498245735,"mc":[{"id":"1.230178313","rc":[{"atl":[[2.8,1]],"id":56913144},{"atb":[[1.79,2]],"id":39100893}],"con":true,"img":false}]}
{"op":"mcm","clk":"11540774317","pt":1719498245839,"mc":[{"id":"1.230178313","rc":[{"atb":[[1.82,1]],"id":56913144}],"con":true,"img":false}]}
{"op":"mcm","clk":"11540774329","pt":1719498245943,"mc":[{"id":"1.230178313","rc":[{"spn":2.31,"spf":"NaN","id":56913144},{"spn":2.32,"spf":1.0,"id":68462283},{"spn":3.19,"spf":"NaN","id":39100893},{"atb":[[1.79,0]],"id":52951653},{"spn":3.2,"spf":"NaN","id":52951653},{"spn":1.83,"spf":1.0,"id":51441055}],"con":true,"img":false}]}
{"op":"mcm","clk":"11540774339","pt":1719498246046,"mc":[{"id":"1.230178313","rc":[{"atb":[[1.81,2]],"id":52951653}],"con":true,"img":false}]}
{"op":"mcm","clk":"11540774374","pt":1719498246411,"mc":[{"id":"1.230178313","rc":[{"atb":[[1.02,0]],"id":70681331}],"con":true,"img":false}]}
{"op":"mcm","clk":"11540774382","pt":1719498246514,"mc":[{"id":"1.230178313","rc":[{"atb":[[2.26,2]],"id":70681331}],"con":true,"img":false}]}
{"op":"mcm","clk":"11540774407","pt":1719498246839,"mc":[{"id":"1.230178313","rc":[{"atb":[[1.79,0]],"id":56913144}],"con":true,"img":false}]}
{"op":"mcm","clk":"11540774416","pt":1719498246930,"mc":[{"id":"1.230178313","rc":[{"atb":[[1.81,2.64]],"id":56913144}],"con":true,"img":false}]}
{"op":"mcm","clk":"11540774555","pt":1719498248332,"mc":[{"id":"1.230178313","rc":[{"atb":[[2.26,0]],"id":70681331}],"con":true,"img":false}]}
{"op":"mcm","clk":"11540774567","pt":1719498248434,"mc":[{"id":"1.230178313","rc":[{"atb":[[1.02,2]],"id":70681331}],"con":true,"img":false}]}
{"op":"mcm","clk":"11540774642","pt":1719498249213,"mc":[{"id":"1.230178313","rc":[{"atb":[[1.77,0]],"id":56913144}],"con":true,"img":false}]}
{"op":"mcm","clk":"11540774666","pt":1719498249416,"mc":[{"id":"1.230178313","rc":[{"atb":[[1.02,0]],"id":70681331}],"con":true,"img":false}]}
{"op":"mcm","clk":"11540774677","pt":1719498249520,"mc":[{"id":"1.230178313","rc":[{"atb":[[1.83,4.75]],"id":56913144},{"atb":[[2.26,2]],"id":70681331}],"con":true,"img":false}]}
{"op":"mcm","clk":"11540774692","pt":1719498249624,"mc":[{"id":"1.230178313","rc":[{"atb":[[1.84,2.65],[1.82,0],[1.8,4]],"id":56913144}],"con":true,"img":false}]}
{"op":"mcm","clk":"11540774847","pt":1719498251125,"mc":[{"id":"1.230178313","rc":[{"atb":[[2.26,0]],"id":70681331}],"con":true,"img":false}]}
{"op":"mcm","clk":"11540774862","pt":1719498251229,"mc":[{"id":"1.230178313","rc":[{"atb":[[1.02,2]],"id":70681331}],"con":true,"img":false}]}
{"op":"mcm","clk":"11540774906","pt":1719498251644,"mc":[{"id":"1.230178313","rc":[{"atb":[[1.81,0.64]],"id":56913144}],"con":true,"img":false}]}
{"op":"mcm","clk":"11540774915","pt":1719498251747,"mc":[{"id":"1.230178313","rc":[{"atb":[[1.85,3]],"id":56913144}],"con":true,"img":false}]}
{"op":"mcm","clk":"11540775095","pt":1719498253357,"mc":[{"id":"1.230178313","rc":[{"atb":[[1.02,0]],"id":70681331}],"con":true,"img":false}]}
{"op":"mcm","clk":"11540775105","pt":1719498253460,"mc":[{"id":"1.230178313","rc":[{"atb":[[2.26,2]],"id":70681331}],"con":true,"img":false}]}
{"op":"mcm","clk":"11540775158","pt":1719498253928,"mc":[{"id":"1.230178313","rc":[{"atb":[[1.69,0]],"id":56913144}],"con":true,"img":false}]}
{"op":"mcm","clk":"11540775221","pt":1719498254556,"mc":[{"id":"1.230178313","rc":[{"atb":[[1.09,1.64]],"id":56913144}],"con":true,"img":false}]}
{"op":"mcm","clk":"11540775240","pt":1719498254719,"mc":[{"id":"1.230178313","rc":[{"atb":[[2.26,0]],"id":70681331}],"con":true,"img":false}]}
{"op":"mcm","clk":"11540775249","pt":1719498254819,"mc":[{"id":"1.230178313","rc":[{"atb":[[1.02,2]],"id":70681331}],"con":true,"img":false}]}
{"op":"mcm","clk":"11540775284","pt":1719498255132,"mc":[{"id":"1.230178313","rc":[{"atb":[[1.87,4.86]],"id":56913144}],"con":true,"img":false}]}
{"op":"mcm","clk":"11540775304","pt":1719498255338,"mc":[{"id":"1.230178313","rc":[{"atb":[[1.85,2]],"id":56913144}],"con":true,"img":false}]}
{"op":"mcm","clk":"11540775312","pt":1719498255444,"mc":[{"id":"1.230178313","rc":[{"atb":[[1.84,0],[1.88,2.65]],"id":56913144}],"con":true,"img":false}]}
{"op":"mcm","clk":"11540775377","pt":1719498256023,"mc":[{"id":"1.230178313","rc":[{"atb":[[1.02,0]],"id":70681331}],"con":true,"img":false}]}
{"op":"mcm","clk":"11540775391","pt":1719498256123,"mc":[{"id":"1.230178313","rc":[{"atb":[[2.26,2]],"id":70681331}],"con":true,"img":false}]}
{"op":"mcm","clk":"11540775425","pt":1719498256433,"mc":[{"id":"1.230178313","rc":[{"atb":[[1.85,0]],"id":56913144}],"con":true,"img":false}]}
{"op":"mcm","clk":"11540775435","pt":1719498256537,"mc":[{"id":"1.230178313","rc":[{"atb":[[1.89,2]],"id":56913144}],"con":true,"img":false}]}
{"op":"mcm","clk":"11540775662","pt":1719498258764,"mc":[{"id":"1.230178313","rc":[{"atb":[[1.8,0]],"id":56913144},{"atl":[[2.82,0]],"id":56913144},{"atb":[[2.24,4.09]],"id":70681331},{"atb":[[1.8,0]],"id":52951653},{"atb":[[1.78,4.2]],"id":39100893}],"con":true,"img":false}]}
{"op":"mcm","clk":"11540775681","pt":1719498258919,"mc":[{"id":"1.230178313","rc":[{"atb":[[1.89,5.87]],"id":56913144},{"atl":[[2.8,0]],"id":56913144},{"atb":[[2.26,4.77]],"id":70681331},{"atb":[[1.82,4]],"id":52951653},{"atb":[[1.79,5.3]],"id":39100893}],"con":true,"img":false}]}
{"op":"mcm","clk":"11540775688","pt":1719498259023,"mc":[{"id":"1.230178313","rc":[{"atb":[[1.81,0],[1.88,0],[1.9,4.87]],"id":56913144},{"atb":[[2.24,1],[2.28,4.09],[2.26,2.77]],"id":70681331},{"atb":[[1.8,4.2]],"id":39100893}],"con":true,"img":false}]}
{"op":"mcm","clk":"11540775698","pt":1719498259125,"mc":[{"id":"1.230178313","rc":[{"atb":[[1.02,2],[2.28,0],[2.26,10.95]],"id":70681331},{"atb":[[1.78,1]],"id":39100893}],"con":true,"img":false}]}
{"op":"mcm","clk":"11540775707","pt":1719498259227,"mc":[{"id":"1.230178313","rc":[{"atb":[[2.24,7.86],[2.26,2.77]],"id":70681331}],"con":true,"img":false}]}
{"op":"mcm","clk":"11540775726","pt":1719498259431,"mc":[{"id":"1.230178313","rc":[{"atb":[[1.09,0]],"id":70681331}],"con":true,"img":false}]}
{"op":"mcm","clk":"11540775736","pt":1719498259534,"mc":[{"id":"1.230178313","rc":[{"atb":[[2.28,1.61]],"id":70681331}],"con":true,"img":false}]}
{"op":"mcm","clk":"11540775761","pt":1719498259842,"mc":[{"id":"1.230178313","rc":[{"atb":[[2.32,7],[2.12,0]],"id":68462283}],"con":true,"img":false}]}
{"op":"mcm","clk":"11540775783","pt":1719498260047,"mc":[{"id":"1.230178313","rc":[{"atb":[[2.28,0]],"id":70681331}],"con":true,"img":false}]}
{"op":"mcm","clk":"11540775828","pt":1719498260460,"mc":[{"id":"1.230178313","rc":[{"atb":[[1.79,3.3]],"id":39100893}],"con":true,"img":false}]}
{"op":"mcm","clk":"11540775840","pt":1719498260563,"mc":[{"id":"1.230178313","rc":[{"atb":[[1.81,2]],"id":39100893}],"con":true,"img":false}]}
{"op":"mcm","clk":"11540775881","pt":1719498260926,"mc":[{"id":"1.230178313","rc":[{"atb":[[1.81,0]],"id":52951653}],"con":true,"img":false}]}
{"op":"mcm","clk":"11540775894","pt":1719498261031,"mc":[{"id":"1.230178313","rc":[{"atl":[[2.84,1]],"id":56913144},{"atb":[[1.83,2]],"id":52951653}],"con":true,"img":false}]}
{"op":"mcm","clk":"11540775903","pt":1719498261137,"mc":[{"id":"1.230178313","rc":[{"atb":[[1.91,1]],"id":56913144}],"con":true,"img":false}]}
{"op":"mcm","clk":"11540775924","pt":1719498261344,"mc":[{"id":"1.230178313","rc":[{"atb":[[1.89,3.87]],"id":56913144}],"con":true,"img":false}]}
{"op":"mcm","clk":"11540775936","pt":1719498261448,"mc":[{"id":"1.230178313","rc":[{"atb":[[1.91,3]],"id":56913144},{"atb":[[2.32,6]],"id":68462283}],"con":true,"img":false}]}
{"op":"mcm","clk":"11540775949","pt":1719498261551,"mc":[{"id":"1.230178313","rc":[{"atb":[[1.92,3.87]],"id":56913144}],"con":true,"img":false}]}
{"op":"mcm","clk":"11540775957","pt":1719498261654,"mc":[{"id":"1.230178313","rc":[{"atb":[[1.92,0],[1.91,10.74],[1.9,0]],"id":56913144}],"con":true,"img":false}]}
{"op":"mcm","clk":"11540775975","pt":1719498261862,"mc":[{"id":"1.230178313","rc":[{"atb":[[1.09,0]],"id":56913144}],"con":true,"img":false}]}
{"op":"mcm","clk":"11540775991","pt":1719498262069,"mc":[{"id":"1.230178313","rc":[{"atb":[[1.91,9.74]],"id":56913144}],"con":true,"img":false}]}
{"op":"mcm","clk":"11540776006","pt":1719498262224,"mc":[{"id":"1.230178313","rc":[{"atb":[[2.32,7]],"id":68462283}],"con":true,"img":false}]}
{"op":"mcm","clk":"11540776042","pt":1719498262638,"mc":[{"id":"1.230178313","rc":[{"atb":[[2.3,2.11]],"id":70681331}],"con":true,"img":false}]}
{"op":"mcm","clk":"11540776223","pt":1719498264552,"mc":[{"id":"1.230178313","rc":[{"atl":[[2.82,0.52]],"id":56913144}],"con":true,"img":false}]}
{"op":"mcm","clk":"11540776231","pt":1719498264654,"mc":[{"id":"1.230178313","rc":[{"atb":[[1.92,0.57]],"id":56913144},{"atl":[[2.84,0]],"id":56913144},{"atb":[[1.02,0]],"id":70681331}],"con":true,"img":false}]}
{"op":"mcm","clk":"11540776239","pt":1719498264758,"mc":[{"id":"1.230178313","rc":[{"atb":[[2.32,2]],"id":70681331}],"con":true,"img":false}]}
{"op":"mcm","clk":"11540776253","pt":1719498264964,"mc":[{"id":"1.230178313","rc":[{"atb":[[2.24,1],[2.32,4.12]],"id":70681331}],"con":true,"img":false}]}
{"op":"mcm","clk":"11540776263","pt":1719498265067,"mc":[{"id":"1.230178313","rc":[{"atb":[[2.32,2],[2.3,6.11]],"id":70681331}],"con":true,"img":false}]}
{"op":"mcm","clk":"11540776293","pt":1719498265324,"mc":[{"id":"1.230178313","rc":[{"atb":[[2.3,3.75]],"id":68462283}],"con":true,"img":false}]}
{"op":"mcm","clk":"11540776304","pt":1719498265427,"mc":[{"id":"1.230178313","rc":[{"atb":[[1.91,5.23]],"id":70681331},{"atb":[[1.76,3.75]],"id":52951653},{"atb":[[1.64,11.16]],"id":39100893}],"con":true,"img":false}]}
{"op":"mcm","clk":"11540776354","pt":1719498266044,"mc":[{"id":"1.230178313","rc":[{"atb":[[1.09,0]],"id":68462283},{"atb":[[1.09,0]],"id":52951653}],"con":true,"img":false}]}
{"op":"mcm","clk":"11540776366","pt":1719498266147,"mc":[{"id":"1.230178313","rc":[{"atb":[[2.34,1.61]],"id":68462283},{"atb":[[1.78,2.56]],"id":52951653}],"con":true,"img":false}]}
{"op":"mcm","clk":"11540776409","pt":1719498266663,"mc":[{"id":"1.230178313","rc":[{"atb":[[2.3,0]],"id":68462283}],"con":true,"img":false}]}
{"op":"mcm","clk":"11540776419","pt":1719498266767,"mc":[{"id":"1.230178313","rc":[{"atb":[[1.93,1]],"id":56913144},{"atl":[[2.8,1]],"id":56913144}],"con":true,"img":false}]}
{"op":"mcm","clk":"11540776458","pt":1719498267130,"mc":[{"id":"1.230178313","rc":[{"atb":[[2.34,0]],"id":68462283}],"con":true,"img":false}]}
{"op":"mcm","clk":"11540776479","pt":1719498267336,"mc":[{"id":"1.230178313","rc":[{"atb":[[1.83,2.5],[1.96,5.75]],"id":56913144}],"con":true,"img":false}]}
{"op":"mcm","clk":"11540776496","pt":1719498267542,"mc":[{"id":"1.230178313","rc":[{"atb":[[1.89,0],[1.93,0],[1.97,2],[1.91,2]],"id":56913144},{"atb":[[2.32,4]],"id":68462283},{"atb":[[2.26,0]],"id":70681331},{"atb":[[1.82,0]],"id":52951653},{"atb":[[1.79,0]],"id":39100893}],"con":true,"img":false}]}
{"op":"mcm","clk":"11540776507","pt":1719498267646,"mc":[{"id":"1.230178313","rc":[{"atb":[[1.93,3]],"id":56913144},{"atb":[[2.34,2]],"id":68462283},{"atb":[[2.32,5.3]],"id":70681331},{"atb":[[1.81,5.45]],"id":39100893},{"atb":[[1.84,3.34]],"id":52951653}],"con":true,"img":false}]}
{"op":"mcm","clk":"11540776516","pt":1719498267753,"mc":[{"id":"1.230178313","rc":[{"atb":[[2.02,10.11],[2.32,1],[1.09,1.61]],"id":68462283},{"atb":[[2.32,10.6],[2.3,2.11],[2.34,1.61]],"id":70681331},{"atb":[[1.8,0],[1.82,4.2],[1.09,0]],"id":39100893}],"con":true,"img":false}]}
{"op":"mcm","clk":"11540776524","pt":1719498267856,"mc":[{"id":"1.230178313","rc":[{"atb":[[1.82,5.8]],"id":39100893}],"con":true,"img":false}]}
{"op":"mcm","clk":"11540776534","pt":1719498267959,"mc":[{"id":"1.230178313","rc":[{"atb":[[2.02,2.11],[2.34,4]],"id":68462283}],"con":true,"img":false}]}
{"op":"mcm","clk":"11540776576","pt":1719498268374,"mc":[{"id":"1.230178313","rc":[{"atb":[[1.82,4.2],[1.81,3.45]],"id":39100893}],"con":true,"img":false}]}
{"op":"mcm","clk":"11540776589","pt":1719498268428,"mc":[{"id":"1.230178313","rc":[{"atb":[[1.93,7.24]],"id":56913144},{"atb":[[1.83,2]],"id":39100893}],"con":true,"img":false}]}
{"op":"mcm","clk":"11540776604","pt":1719498268633,"mc":[{"id":"1.230178313","rc":[{"atb":[[1.83,0]],"id":56913144}],"con":true,"img":false}]}
{"op":"mcm","clk":"11540776639","pt":1719498268944,"mc":[{"id":"1.230178313","rc":[{"atb":[[1.83,0]],"id":52951653}],"con":true,"img":false}]}
{"op":"mcm","clk":"11540776653","pt":1719498269047,"mc":[{"id":"1.230178313","rc":[{"atb":[[1.85,2]],"id":52951653}],"con":true,"img":false}]}
{"op":"mcm","clk":"11540776715","pt":1719498269672,"mc":[{"id":"1.230178313","rc":[{"atb":[[2.32,8.6]],"id":70681331}],"con":true,"img":false}]}
{"op":"mcm","clk":"11540776725","pt":1719498269728,"mc":[{"id":"1.230178313","rc":[{"atb":[[1.98,1]],"id":56913144},{"atb":[[1.02,2]],"id":70681331}],"con":true,"img":false}]}
{"op":"mcm","clk":"11540776775","pt":1719498270139,"mc":[{"id":"1.230178313","rc":[{"atb":[[1.91,0]],"id":56913144}],"con":true,"img":false}]}
{"op":"mcm","clk":"11540776789","pt":1719498270243,"mc":[{"id":"1.230178313","rc":[{"atb":[[1.98,3]],"id":56913144}],"con":true,"img":false}]}
{"op":"mcm","clk":"11540776813","pt":1719498270450,"mc":[{"id":"1.230178313","rc":[{"atb":[[1.98,6],[1.97,0]],"id":56913144}],"con":true,"img":false}]}
{"op":"mcm","clk":"11540776835","pt":1719498270656,"mc":[{"id":"1.230178313","rc":[{"atb":[[1.98,5]],"id":56913144}],"con":true,"img":false}]}
{"op":"mcm","clk":"11540777046","pt":1719498272633,"mc":[{"id":"1.230178313","rc":[{"atb":[[1.64,6.16]],"id":39100893}],"con":true,"img":false}]}
{"op":"mcm","clk":"11540777057","pt":1719498272736,"mc":[{"id":"1.230178313","rc":[{"atb":[[1.99,1]],"id":56913144}],"con":true,"img":false}]}
{"op":"mcm","clk":"11540777101","pt":1719498273154,"mc":[{"id":"1.230178313","rc":[{"atb":[[1.91,0]],"id":70681331}],"con":true,"img":false}]}
{"op":"mcm","clk":"11540777427","pt":1719498276370,"mc":[{"id":"1.230178313","rc":[{"atb":[[1.93,4.24]],"id":56913144},{"atb":[[2.32,5.3]],"id":70681331},{"atb":[[1.81,0]],"id":39100893},{"atb":[[1.84,0]],"id":52951653}],"con":true,"img":false}]}
{"op":"mcm","clk":"11540777446","pt":1719498276578,"mc":[{"id":"1.230178313","rc":[{"atb":[[1.98,7.3]],"id":56913144},{"atb":[[2.34,4.21]],"id":70681331},{"atb":[[1.83,5.59]],"id":39100893},{"atb":[[1.85,5.2]],"id":52951653}],"con":true,"img":false}]}
{"op":"mcm","clk":"11540777456","pt":1719498276634,"mc":[{"id":"1.230178313","rc":[{"atb":[[1.82,0],[1.84,4.2]],"id":39100893}],"con":true,"img":false}]}
{"op":"mcm","clk":"11540777465","pt":1719498276739,"mc":[{"id":"1.230178313","rc":[{"atb":[[2.34,2.6]],"id":70681331},{"atb":[[1.84,5.8]],"id":39100893}],"con":true,"img":false}]}
{"op":"mcm","clk":"11540777542","pt":1719498277459,"mc":[{"id":"1.230178313","rc":[{"atb":[[1.84,4.2]],"id":39100893}],"con":true,"img":false}]}
{"op":"mcm","clk":"11540777629","pt":1719498278241,"mc":[{"id":"1.230178313","rc":[{"atb":[[1.83,3.59]],"id":39100893}],"con":true,"img":false}]}
{"op":"mcm","clk":"11540777642","pt":1719498278340,"mc":[{"id":"1.230178313","rc":[{"atb":[[1.85,2]],"id":39100893}],"con":true,"img":false}]}
{"op":"mcm","clk":"11540777675","pt":1719498278650,"mc":[{"id":"1.230178313","rc":[{"atb":[[1.02,0]],"id":70681331}],"con":true,"img":false}]}
{"op":"mcm","clk":"11540777686","pt":1719498278755,"mc":[{"id":"1.230178313","rc":[{"atb":[[2.36,2]],"id":70681331}],"con":true,"img":false}]}
{"op":"mcm","clk":"11540777789","pt":1719498279685,"mc":[{"id":"1.230178313","rc":[{"atb":[[1.76,0]],"id":52951653}],"con":true,"img":false}]}
{"op":"mcm","clk":"11540777844","pt":1719498279945,"mc":[{"id":"1.230178313","rc":[{"atb":[[1.92,0]],"id":56913144}],"con":true,"img":false}]}
{"op":"mcm","clk":"11540777853","pt":1719498280049,"mc":[{"id":"1.230178313","rc":[{"atl":[[2.82,0]],"id":56913144}],"con":true,"img":false}]}
{"op":"mcm","clk":"11540777874","pt":1719498280260,"mc":[{"id":"1.230178313","rc":[{"atl":[[2.8,0]],"id":56913144}],"con":true,"img":false}]}
{"op":"mcm","clk":"11540778340","pt":1719498284158,"mc":[{"id":"1.230178313","rc":[{"atb":[[2.32,0]],"id":68462283}],"con":true,"img":false}]}
{"op":"mcm","clk":"11540778356","pt":1719498284260,"mc":[{"id":"1.230178313","rc":[{"atl":[[2.84,1]],"id":56913144}],"con":true,"img":false}]}
{"op":"mcm","clk":"11540778422","pt":1719498284983,"mc":[{"id":"1.230178313","rc":[{"atb":[[1.98,5]],"id":56913144},{"atl":[[2.82,0.52]],"id":56913144},{"atb":[[2.34,0]],"id":70681331},{"atb":[[1.83,0]],"id":39100893}],"con":true,"img":false}]}
{"op":"mcm","clk":"11540778435","pt":1719498285038,"mc":[{"id":"1.230178313","rc":[{"atb":[[2,0.52]],"id":56913144},{"atl":[[2.84,0]],"id":56913144}],"con":true,"img":false}]}
{"op":"mcm","clk":"11540778441","pt":1719498285143,"mc":[{"id":"1.230178313","rc":[{"atb":[[1.99,5]],"id":56913144},{"atb":[[2.36,5.62]],"id":70681331},{"atb":[[1.85,4.8]],"id":39100893}],"con":true,"img":false}]}
{"op":"mcm","clk":"11540778451","pt":1719498285244,"mc":[{"id":"1.230178313","rc":[{"atb":[[1.99,4]],"id":56913144},{"atb":[[1.84,0],[1.86,4.2]],"id":39100893}],"con":true,"img":false}]}
{"op":"mcm","clk":"11540778693","pt":1719498287251,"mc":[{"id":"1.230178313","rc":[{"atb":[[2.32,1]],"id":68462283}],"con":true,"img":false}]}
{"op":"mcm","clk":"11540778708","pt":1719498287352,"mc":[{"id":"1.230178313","rc":[{"atl":[[2.8,1]],"id":56913144}],"con":true,"img":false}]}
{"op":"mcm","clk":"11540778721","pt":1719498287459,"mc":[{"id":"1.230178313","rc":[{"atb":[[2.02,1]],"id":56913144},{"atb":[[2.38,1.61]],"id":70681331}],"con":true,"img":false}]}
{"op":"mcm","clk":"11540778732","pt":1719498287572,"mc":[{"id":"1.230178313","rc":[{"atb":[[1.85,2.8]],"id":39100893}],"con":true,"img":false}]}
{"op":"mcm","clk":"11540778746","pt":1719498287666,"mc":[{"id":"1.230178313","rc":[{"atb":[[1.87,2]],"id":39100893}],"con":true,"img":false}]}
{"op":"mcm","clk":"11540778780","pt":1719498287984,"mc":[{"id":"1.230178313","rc":[{"atb":[[1.98,3]],"id":56913144}],"con":true,"img":false}]}
{"op":"mcm","clk":"11540778795","pt":1719498288088,"mc":[{"id":"1.230178313","rc":[{"atb":[[2,2.52]],"id":56913144}],"con":true,"img":false}]}
{"op":"mcm","clk":"11540778850","pt":1719498288667,"mc":[{"id":"1.230178313","rc":[{"atb":[[1.92,1],[1.97,0]],"id":51441055}],"con":true,"img":false}]}
{"op":"mcm","clk":"11540778857","pt":1719498288771,"mc":[{"id":"1.230178313","rc":[{"atb":[[1.59,0]],"id":56913144}],"con":true,"img":false}]}
{"op":"mcm","clk":"11540778868","pt":1719498288877,"mc":[{"id":"1.230178313","rc":[{"atb":[[2,5.52],[2.1,2.5],[2.02,8.39]],"id":56913144},{"atl":[[2.8,3.39]],"id":56913144},{"atb":[[2.58,10],[2.36,2.25],[2.74,2.5],[2.66,5]],"id":68462283},{"atl":[[8,2.5],[9.6,10],[6.2,2.25],[8.8,5]],"id":68462283},{"atb":[[2.32,0],[2.38,10.37],[2.52,5],[2.6,2.5],[2.44,10]],"id":70681331},{"atl":[[8.2,10],[7.4,5],[5.7,3.46],[6.6,2.5]],"id":70681331},{"atb":[[1.98,10],[2.04,5],[2.12,2.5],[1.87,5]],"id":39100893},{"atl":[[4.5,3],[5.3,5],[4.9,2.5],[5.7,10]],"id":39100893},{"atb":[[1.83,10.4],[1.89,10],[1.85,8.63],[1.93,5],[1.97,2.5],[1.77,0]],"id":52951653},{"atl":[[4.5,3.43],[5.3,5],[4.9,2.5],[5.7,10]],"id":52951653},{"atb":[[2.26,2.5],[2.1,10],[2.18,5],[1.75,1.5]],"id":51441055},{"atl":[[5.1,1.5],[6.4,10],[5.8,5],[5.4,2.5]],"id":51441055}],"con":true,"img":false}]}
{"op":"mcm","clk":"11540778878","pt":1719498288979,"mc":[{"id":"1.230178313","rc":[{"atb":[[1.98,0],[2.02,7.39]],"id":56913144},{"atb":[[2.34,2],[2.74,7.5]],"id":68462283},{"atl":[[9,4.75],[46,0]],"id":68462283},{"atl":[[22,0],[6,5]],"id":70681331},{"atl":[[8.8,0],[4.4,2.5]],"id":52951653},{"atl":[[11.5,0],[4.4,2.5]],"id":39100893},{"atb":[[1.73,0],[2.16,7.5]],"id":51441055},{"atl":[[5.1,3.5],[13,0]],"id":51441055}],"con":true,"img":false}]}
{"op":"mcm","clk":"11540778892","pt":1719498289085,"mc":[{"id":"1.230178313","rc":[{"atl":[[2.78,0.84]],"id":56913144},{"atl":[[6,0.84]],"id":68462283},{"atl":[[5.6,0.84]],"id":70681331},{"atl":[[4.4,3.34]],"id":52951653},{"atl":[[4.4,3.34]],"id":39100893}],"con":true,"img":false}]}
{"op":"mcm","clk":"11540778903","pt":1719498289188,"mc":[{"id":"1.230178313","rc":[{"atl":[[2.8,2.39],[2.86,0]],"id":56913144},{"atb":[[2.32,5.12]],"id":68462283},{"atb":[[2.24,6.18]],"id":70681331},{"atb":[[1.81,6.42]],"id":39100893},{"atl":[[4.6,6.5],[4.4,0.84]],"id":39100893},{"atb":[[1.77,5.09]],"id":52951653},{"atl":[[4.7,5.56]],"id":52951653}],"con":true,"img":false}]}
{"op":"mcm","clk":"11540778927","pt":1719498289349,"mc":[{"id":"1.230178313","rc":[{"atb":[[2.32,1]],"id":68462283},{"atb":[[2.24,1]],"id":70681331},{"atb":[[1.81,0]],"id":39100893},{"atb":[[1.77,0]],"id":52951653}],"con":true,"img":false}]}
{"op":"mcm","clk":"11540778939","pt":1719498289459,"mc":[{"id":"1.230178313","rc":[{"atb":[[1.09,0]],"id":51441055}],"con":true,"img":false}]}
{"op":"mcm","clk":"11540778953","pt":1719498289553,"mc":[{"id":"1.230178313","rc":[{"atb":[[2.2,1.49]],"id":51441055},{"atl":[[5,0.84]],"id":51441055}],"con":true,"img":false}]}
{"op":"mcm","clk":"11540778964","pt":1719498289665,"mc":[{"id":"1.230178313","rc":[{"atl":[[2.78,15.09]],"id":56913144}],"con":true,"img":false}]}
{"op":"mcm","clk":"11540778980","pt":1719498289766,"mc":[{"id":"1.230178313","rc":[{"atb":[[1.87,3]],"id":39100893}],"con":true,"img":false}]}
{"op":"mcm","clk":"11540778992","pt":1719498289872,"mc":[{"id":"1.230178313","rc":[{"atb":[[2.14,2]],"id":39100893}],"con":true,"img":false}]}
{"op":"mcm","clk":"11540779020","pt":1719498290067,"mc":[{"id":"1.230178313","rc":[{"atb":[[1.85,6.63]],"id":52951653},{"atl":[[4.7,0]],"id":52951653}],"con":true,"img":false}]}
{"op":"mcm","clk":"11540779029","pt":1719498290171,"mc":[{"id":"1.230178313","rc":[{"atb":[[1.98,2]],"id":52951653}],"con":true,"img":false}]}
{"op":"mcm","clk":"11540779048","pt":1719498290378,"mc":[{"id":"1.230178313","rc":[{"atl":[[4.5,8.24]],"id":52951653}],"con":true,"img":false}]}
{"op":"mcm","clk":"11540779078","pt":1719498290584,"mc":[{"id":"1.230178313","rc":[{"atb":[[2.36,3.62]],"id":70681331}],"con":true,"img":false}]}
{"op":"mcm","clk":"11540779091","pt":1719498290687,"mc":[{"id":"1.230178313","rc":[{"atb":[[2.62,2]],"id":70681331},{"atb":[[2.24,4.22]],"id":51441055}],"con":true,"img":false}]}
{"op":"mcm","clk":"11540779103","pt":1719498290792,"mc":[{"id":"1.230178313","rc":[{"atl":[[2.76,2.53]],"id":56913144},{"atb":[[2.08,5],[1.86,0]],"id":39100893}],"con":true,"img":false}]}
{"op":"mcm","clk":"11540779118","pt":1719498290847,"mc":[{"id":"1.230178313","rc":[{"atl":[[4.5,3.43]],"id":52951653}],"con":true,"img":false}]}
{"op":"mcm","clk":"11540779136","pt":1719498290962,"mc":[{"id":"1.230178313","rc":[{"atb":[[2,3.52],[2.08,5]],"id":56913144}],"con":true,"img":false}]}
{"op":"mcm","clk":"11540779147","pt":1719498291055,"mc":[{"id":"1.230178313","rc":[{"atb":[[2.12,2],[2.06,2.11],[1.74,0]],"id":56913144},{"atb":[[2.3,0],[2.5,2.11]],"id":70681331},{"atb":[[1.92,2.11],[1.67,0]],"id":52951653},{"atb":[[2.24,6.33]],"id":51441055}],"con":true,"img":false}]}
{"op":"mcm","clk":"11540779162","pt":1719498291161,"mc":[{"id":"1.230178313","rc":[{"atb":[[2.14,1]],"id":56913144},{"atl":[[2.74,1]],"id":56913144},{"atl":[[4.4,8.5]],"id":52951653}],"con":true,"img":false}]}
{"op":"mcm","clk":"11540779181","pt":1719498291381,"mc":[{"id":"1.230178313","rc":[{"atb":[[2.14,19.19]],"id":56913144}],"con":true,"img":false}]}
{"op":"mcm","clk":"11540779207","pt":1719498291684,"mc":[{"id":"1.230178313","rc":[{"atl":[[1000,0.17]],"id":52951653}],"con":true,"img":false}]}
{"op":"mcm","clk":"11540779217","pt":1719498291789,"mc":[{"id":"1.230178313","rc":[{"atb":[[2.08,0],[2.16,1.64]],"id":56913144},{"atl":[[4.3,1.26]],"id":52951653}],"con":true,"img":false}]}
{"op":"mcm","clk":"11540779241","pt":1719498291961,"mc":[{"id":"1.230178313","rc":[{"atb":[[2.14,18.19]],"id":56913144}],"con":true,"img":false}]}
{"op":"mcm","clk":"11540779259","pt":1719498292155,"mc":[{"id":"1.230178313","rc":[{"atb":[[2.14,0]],"id":56913144}],"con":true,"img":false}]}
{"op":"mcm","clk":"11540779292","pt":1719498292480,"mc":[{"id":"1.230178313","rc":[{"atb":[[2.16,0]],"id":56913144}],"con":true,"img":false}]}
{"op":"mcm","clk":"11540779400","pt":1719498293558,"mc":[{"id":"1.230178313","rc":[{"atb":[[2.12,23.78],[1.99,0]],"id":56913144},{"atb":[[2.34,0]],"id":68462283},{"atb":[[2.36,0]],"id":70681331},{"atb":[[1.85,3.43]],"id":52951653},{"atb":[[1.85,0]],"id":39100893},{"atb":[[1.74,0]],"id":51441055}],"con":true,"img":false}]}
{"op":"mcm","clk":"11540779416","pt":1719498293766,"mc":[{"id":"1.230178313","rc":[{"atb":[[2.1,5]],"id":56913144},{"atb":[[2.76,3.5]],"id":68462283},{"atb":[[2.62,4]],"id":70681331},{"atb":[[1.98,5.3]],"id":52951653},{"atb":[[2.14,4.28]],"id":39100893},{"atb":[[2.28,3]],"id":51441055}],"con":true,"img":false}]}
{"op":"mcm","clk":"11540779427","pt":1719498293870,"mc":[{"id":"1.230178313","rc":[{"atb":[[2.14,1]],"id":56913144}],"con":true,"img":false}]}
{"op":"mcm","clk":"11540779447","pt":1719498294079,"mc":[{"id":"1.230178313","rc":[{"atl":[[5.1,1.5],[5.2,5.35]],"id":51441055}],"con":true,"img":false}]}
{"op":"mcm","clk":"11540779459","pt":1719498294182,"mc":[{"id":"1.230178313","rc":[{"atb":[[2.14,2.64]],"id":56913144}],"con":true,"img":false}]}
{"op":"mcm","clk":"11540779476","pt":1719498294390,"mc":[{"id":"1.230178313","rc":[{"atb":[[2,0.52],[2.02,15.03]],"id":56913144},{"atb":[[2.78,5]],"id":68462283},{"atb":[[2.38,5.07],[2.44,20]],"id":70681331},{"atl":[[5,2.84]],"id":39100893}],"con":true,"img":false}]}
{"op":"mcm","clk":"11540779484","pt":1719498294492,"mc":[{"id":"1.230178313","rc":[{"atb":[[2.74,2.5]],"id":68462283}],"con":true,"img":false}]}
{"op":"mcm","clk":"11540779507","pt":1719498294752,"mc":[{"id":"1.230178313","rc":[{"atb":[[2.24,2.11]],"id":51441055}],"con":true,"img":false}]}
{"op":"mcm","clk":"11540779515","pt":1719498294858,"mc":[{"id":"1.230178313","rc":[{"atl":[[5,0]],"id":39100893}],"con":true,"img":false}]}
{"op":"mcm","clk":"11540779545","pt":1719498295167,"mc":[{"id":"1.230178313","rc":[{"atb":[[2.12,22.53]],"id":56913144},{"atl":[[4.9,6.12]],"id":39100893}],"con":true,"img":false}]}
{"op":"mcm","clk":"11540779565","pt":1719498295375,"mc":[{"id":"1.230178313","rc":[{"atb":[[2.12,2]],"id":56913144}],"con":true,"img":false}]}
{"op":"mcm","clk":"11540779572","pt":1719498295477,"mc":[{"id":"1.230178313","rc":[{"atb":[[2.12,0],[2.14,23.17]],"id":56913144}],"con":true,"img":false}]}
{"op":"mcm","clk":"11540779579","pt":1719498295582,"mc":[{"id":"1.230178313","rc":[{"atb":[[2.16,2]],"id":56913144}],"con":true,"img":false}]}
{"op":"mcm","clk":"11540779589","pt":1719498295685,"mc":[{"id":"1.230178313","rc":[{"atb":[[2.14,22.17]],"id":56913144}],"con":true,"img":false}]}
{"op":"mcm","clk":"11540779607","pt":1719498295891,"mc":[{"id":"1.230178313","rc":[{"atb":[[2.14,19.97]],"id":56913144}],"con":true,"img":false}]}
{"op":"mcm","clk":"11540779629","pt":1719498296099,"mc":[{"id":"1.230178313","rc":[{"atl":[[4.2,0],[3.65,4.93]],"id":56913144},{"atl":[[9,0],[7.8,4.75]],"id":68462283},{"atl":[[5.8,5.31],[6,0]],"id":70681331}],"con":true,"img":false}]}
{"op":"mcm","clk":"11540779638","pt":1719498296155,"mc":[{"id":"1.230178313","rc":[{"atb":[[2.14,1.64]],"id":56913144},{"atb":[[2.32,0]],"id":68462283}],"con":true,"img":false}]}
{"op":"mcm","clk":"11540779652","pt":1719498296257,"mc":[{"id":"1.230178313","rc":[{"atb":[[2.16,20.33]],"id":56913144}],"con":true,"img":false}]}
{"op":"mcm","clk":"11540779691","pt":1719498296667,"mc":[{"id":"1.230178313","rc":[{"atb":[[2.14,0]],"id":56913144}],"con":true,"img":false}]}
{"op":"mcm","clk":"11540779701","pt":1719498296771,"mc":[{"id":"1.230178313","rc":[{"atb":[[2.18,1.64]],"id":56913144}],"con":true,"img":false}]}
{"op":"mcm","clk":"11540779804","pt":1719498297863,"mc":[{"id":"1.230178313","rc":[{"atb":[[2.16,19.06]],"id":56913144}],"con":true,"img":false}]}
{"op":"mcm","clk":"11540779812","pt":1719498297963,"mc":[{"id":"1.230178313","rc":[{"atb":[[2.2,1]],"id":56913144}],"con":true,"img":false}]}
{"op":"mcm","clk":"11540779822","pt":1719498298066,"mc":[{"id":"1.230178313","rc":[{"atb":[[2.16,2]],"id":56913144}],"con":true,"img":false}]}
{"op":"mcm","clk":"11540779830","pt":1719498298168,"mc":[{"id":"1.230178313","rc":[{"atb":[[2.18,18.7]],"id":56913144}],"con":true,"img":false}]}
{"op":"mcm","clk":"11540779919","pt":1719498299203,"mc":[{"id":"1.230178313","rc":[{"atb":[[2.16,0]],"id":56913144}],"con":true,"img":false}]}
{"op":"mcm","clk":"11540779930","pt":1719498299260,"mc":[{"id":"1.230178313","rc":[{"atb":[[2.2,3]],"id":56913144}],"con":true,"img":false}]}
{"op":"mcm","clk":"11540779956","pt":1719498299565,"mc":[{"id":"1.230178313","rc":[{"atb":[[2.18,1.64]],"id":56913144}],"con":true,"img":false}]}
{"op":"mcm","clk":"11540780021","pt":1719498300295,"mc":[{"id":"1.230178313","rc":[{"atb":[[2.18,0]],"id":56913144},{"atl":[[2.82,0]],"id":56913144}],"con":true,"img":false}]}
{"op":"mcm","clk":"11540780041","pt":1719498300505,"mc":[{"id":"1.230178313","rc":[{"atb":[[2,0],[2.2,2]],"id":56913144}],"con":true,"img":false}]}
{"op":"mcm","clk":"11540780061","pt":1719498300663,"mc":[{"id":"1.230178313","rc":[{"atb":[[2.2,5.5]],"id":56913144},{"atl":[[2.74,4.5]],"id":56913144},{"atb":[[2.8,3.56]],"id":68462283},{"atb":[[2.64,5.6]],"id":70681331},{"atl":[[5.6,6.44]],"id":70681331},{"atb":[[2.14,9.74]],"id":39100893},{"atl":[[4.4,6.3]],"id":39100893},{"atb":[[1.98,11.62]],"id":52951653},{"atl":[[4.2,6.32]],"id":52951653},{"atb":[[2.28,6.46]],"id":51441055},{"atl":[[5,4.3]],"id":51441055}],"con":true,"img":false}]}
{"op":"mcm","clk":"11540780070","pt":1719498300768,"mc":[{"id":"1.230178313","rc":[{"atb":[[2.82,3.56],[2.78,0]],"id":68462283},{"atl":[[5.8,1],[5.5,5.31]],"id":70681331},{"atl":[[4.1,6.32],[4.4,6]],"id":52951653},{"atl":[[4.3,6.31]],"id":39100893},{"atl":[[5.2,1],[4.9,4.31]],"id":51441055}],"con":true,"img":false}]}
{"op":"mcm","clk":"11540780082","pt":1719498300875,"mc":[{"id":"1.230178313","rc":[{"atb":[[2.02,12.64]],"id":56913144},{"atl":[[2.8,0]],"id":56913144},{"atb":[[2.82,0],[2.36,0],[2.78,7.12]],"id":68462283},{"atb":[[2.38,1.61]],"id":70681331},{"atl":[[5.8,10.91],[5.5,0],[5.7,0]],"id":70681331},{"atb":[[1.85,0]],"id":52951653},{"atl":[[4.3,13.9],[4.5,0],[4.1,0]],"id":52951653},{"atb":[[1.87,0]],"id":39100893},{"atl":[[4.3,0],[4.5,12.62],[4.6,1]],"id":39100893},{"atb":[[1.75,0]],"id":51441055},{"atl":[[5.1,0],[4.9,0],[5.2,6.81]],"id":51441055}],"con":true,"img":false}]}
{"op":"mcm","clk":"11540780092","pt":1719498300978,"mc":[{"id":"1.230178313","rc":[{"atl":[[5.8,1],[6.6,19.86]],"id":70681331},{"atl":[[4.5,0],[4.6,19.93]],"id":39100893},{"atl":[[5.2,1],[5.4,13.62]],"id":51441055}],"con":true,"img":false}]}
{"op":"mcm","clk":"11540780105","pt":1719498301085,"mc":[{"id":"1.230178313","rc":[{"atl":[[2.72,0.85],[2.78,14.25]],"id":56913144},{"atl":[[5.4,0.84]],"id":70681331},{"atl":[[4.2,0.84]],"id":39100893},{"atl":[[4,0.84],[4.4,5.16]],"id":52951653},{"atl":[[4.8,0.84]],"id":51441055}],"con":true,"img":false}]}
{"op":"mcm","clk":"11540780118","pt":1719498301188,"mc":[{"id":"1.230178313","rc":[{"atl":[[1000,0.17]],"id":39100893},{"atl":[[4.3,12.64]],"id":52951653}],"con":true,"img":false}]}
{"op":"mcm","clk":"11540780132","pt":1719498301293,"mc":[{"id":"1.230178313","rc":[{"atl":[[2.74,3.5]],"id":56913144},{"atl":[[4.1,1.26]],"id":52951653},{"atl":[[4.3,1.26]],"id":39100893}],"con":true,"img":false}]}
{"op":"mcm","clk":"11540780141","pt":1719498301395,"mc":[{"id":"1.230178313","rc":[{"atb":[[2.16,1.6]],"id":39100893}],"con":true,"img":false}]}
{"op":"mcm","clk":"11540780152","pt":1719498301500,"mc":[{"id":"1.230178313","rc":[{"atl":[[2.78,12.25]],"id":56913144},{"atb":[[1.78,1]],"id":52951653},{"atl":[[4.3,0],[4.1,7.58]],"id":52951653}],"con":true,"img":false}]}
{"op":"mcm","clk":"11540780164","pt":1719498301605,"mc":[{"id":"1.230178313","rc":[{"atl":[[2.76,0]],"id":56913144},{"atb":[[1.99,1.56]],"id":52951653}],"con":true,"img":false}]}
{"op":"mcm","clk":"11540780177","pt":1719498301664,"mc":[{"id":"1.230178313","rc":[{"atl":[[2.78,0]],"id":56913144},{"atl":[[5.4,0]],"id":70681331},{"atl":[[4.8,0]],"id":51441055}],"con":true,"img":false}]}
{"op":"mcm","clk":"11540780190","pt":1719498301763,"mc":[{"id":"1.230178313","rc":[{"atl":[[2.74,15.75]],"id":56913144}],"con":true,"img":false}]}
{"op":"mcm","clk":"11540780201","pt":1719498301866,"mc":[{"id":"1.230178313","rc":[{"atb":[[2.62,2]],"id":70681331}],"con":true,"img":false}]}
{"op":"mcm","clk":"11540780213","pt":1719498301970,"mc":[{"id":"1.230178313","rc":[{"atb":[[2.66,2]],"id":70681331},{"atl":[[4.9,2.5]],"id":39100893}],"con":true,"img":false}]}
{"op":"mcm","clk":"11540780239","pt":1719498302178,"mc":[{"id":"1.230178313","rc":[{"atl":[[4.8,2.84]],"id":39100893}],"con":true,"img":false}]}
{"op":"mcm","clk":"11540780263","pt":1719498302384,"mc":[{"id":"1.230178313","rc":[{"atl":[[4.8,0]],"id":39100893}],"con":true,"img":false}]}
{"op":"mcm","clk":"11540780277","pt":1719498302592,"mc":[{"id":"1.230178313","rc":[{"atb":[[2.76,0]],"id":68462283},{"atb":[[2.62,0]],"id":70681331},{"atb":[[2.14,7.46]],"id":39100893},{"atb":[[1.98,8.32]],"id":52951653}],"con":true,"img":false}]}
{"op":"mcm","clk":"11540780286","pt":1719498302696,"mc":[{"id":"1.230178313","rc":[{"atb":[[2.82,2.5]],"id":68462283},{"atb":[[2.66,4.6]],"id":70681331},{"atb":[[2.16,3.6]],"id":39100893},{"atb":[[1.99,5.56]],"id":52951653}],"con":true,"img":false}]}
{"op":"mcm","clk":"11540780300","pt":1719498302799,"mc":[{"id":"1.230178313","rc":[{"atb":[[2.32,1],[2.74,13.18],[2.78,0]],"id":68462283},{"atl":[[4.7,3.84]],"id":39100893}],"con":true,"img":false}]}
{"op":"mcm","clk":"11540780307","pt":1719498302902,"mc":[{"id":"1.230178313","rc":[{"atb":[[2.82,6.06],[2.74,2.5]],"id":68462283}],"con":true,"img":false}]}
{"op":"mcm","clk":"11540780325","pt":1719498303066,"mc":[{"id":"1.230178313","rc":[{"atb":[[2.14,5.46]],"id":39100893}],"con":true,"img":false}]}
{"op":"mcm","clk":"11540780336","pt":1719498303164,"mc":[{"id":"1.230178313","rc":[{"atb":[[2.18,2]],"id":39100893}],"con":true,"img":false}]}
{"op":"mcm","clk":"11540780347","pt":1719498303272,"mc":[{"id":"1.230178313","rc":[{"atb":[[2.22,1],[2.06,0],[2.16,2.11]],"id":56913144},{"atl":[[2.84,3.02],[2.7,1]],"id":56913144},{"atb":[[1.67,0],[2.2,2.11],[2.16,2]],"id":39100893},{"atb":[[1.99,4]],"id":52951653}],"con":true,"img":false}]}
{"op":"mcm","clk":"11540780368","pt":1719498303474,"mc":[{"id":"1.230178313","rc":[{"atb":[[1.98,6.32]],"id":52951653}],"con":true,"img":false}]}
{"op":"mcm","clk":"11540780379","pt":1719498303577,"mc":[{"id":"1.230178313","rc":[{"atb":[[2.22,19.75]],"id":56913144},{"atb":[[2,2]],"id":52951653},{"atl":[[4.7,0]],"id":39100893}],"con":true,"img":false}]}
{"op":"mcm","clk":"11540780396","pt":1719498303783,"mc":[{"id":"1.230178313","rc":[{"atb":[[2.24,1.64]],"id":56913144}],"con":true,"img":false}]}
{"op":"mcm","clk":"11540780509","pt":1719498304983,"mc":[{"id":"1.230178313","rc":[{"atb":[[2.18,0]],"id":39100893}],"con":true,"img":false}]}
{"op":"mcm","clk":"11540780517","pt":1719498305087,"mc":[{"id":"1.230178313","rc":[{"atb":[[2.22,2]],"id":39100893}],"con":true,"img":false}]}
{"op":"mcm","clk":"11540780527","pt":1719498305190,"mc":[{"id":"1.230178313","rc":[{"atb":[[2.22,18.75]],"id":56913144}],"con":true,"img":false}]}
{"op":"mcm","clk":"11540780548","pt":1719498305399,"mc":[{"id":"1.230178313","rc":[{"atb":[[2.22,0]],"id":56913144}],"con":true,"img":false}]}
{"op":"mcm","clk":"11540780558","pt":1719498305502,"mc":[{"id":"1.230178313","rc":[{"atb":[[2.2,3.5]],"id":56913144}],"con":true,"img":false}]}
{"op":"mcm","clk":"11540780568","pt":1719498305606,"mc":[{"id":"1.230178313","rc":[{"atb":[[2.24,3.64]],"id":56913144}],"con":true,"img":false}]}
{"op":"mcm","clk":"11540780577","pt":1719498305709,"mc":[{"id":"1.230178313","rc":[{"atb":[[2.24,2]],"id":56913144}],"con":true,"img":false}]}
{"op":"mcm","clk":"11540780627","pt":1719498306276,"mc":[{"id":"1.230178313","rc":[{"spn":2.47,"spf":"NaN","id":56913144},{"spn":2.82,"spf":1.0,"id":68462283},{"spn":4.13,"spf":"NaN","id":70681331},{"atl":[[4.3,7.57],[4.6,1]],"id":39100893},{"spn":3.21,"spf":"NaN","id":39100893},{"spn":3.0,"spf":"NaN","id":52951653},{"spn":2.28,"spf":1.0,"id":51441055}],"con":true,"img":false}]}
{"op":"mcm","clk":"11540780640","pt":1719498306381,"mc":[{"id":"1.230178313","rc":[{"atb":[[2.24,20.41]],"id":56913144},{"atl":[[4.3,1.26],[4.4,12.61]],"id":39100893}],"con":true,"img":false}]}
{"op":"mcm","clk":"11540780685","pt":1719498306793,"mc":[{"id":"1.230178313","rc":[{"atb":[[2.26,1.64],[2.24,18.41]],"id":56913144}],"con":true,"img":false}]}
{"op":"mcm","clk":"11540780696","pt":1719498306897,"mc":[{"id":"1.230178313","rc":[{"atb":[[2.22,2]],"id":56913144}],"con":true,"img":false}]}
{"op":"mcm","clk":"11540780746","pt":1719498307366,"mc":[{"id":"1.230178313","rc":[{"atb":[[1.03,0.52]],"id":56913144}],"con":true,"img":false}]}
{"op":"mcm","clk":"11540780771","pt":1719498307570,"mc":[{"id":"1.230178313","rc":[{"atb":[[2.24,0],[2.28,1]],"id":56913144}],"con":true,"img":false}]}
{"op":"mcm","clk":"11540780784","pt":1719498307674,"mc":[{"id":"1.230178313","rc":[{"atb":[[1.03,0.41]],"id":56913144}],"con":true,"img":false}]}
{"op":"mcm","clk":"11540780817","pt":1719498307981,"mc":[{"id":"1.230178313","rc":[{"atb":[[1.03,0]],"id":56913144}],"con":true,"img":false}]}
{"op":"mcm","clk":"11540780833","pt":1719498308086,"mc":[{"id":"1.230178313","rc":[{"atb":[[2.22,0],[2.26,0],[2.28,1.41]],"id":56913144}],"con":true,"img":false}]}
{"op":"mcm","clk":"11540780847","pt":1719498308190,"mc":[{"id":"1.230178313","rc":[{"atb":[[2.26,2]],"id":56913144}],"con":true,"img":false}]}
{"op":"mcm","clk":"11540780857","pt":1719498308292,"mc":[{"id":"1.230178313","rc":[{"atb":[[2.28,19.73]],"id":56913144}],"con":true,"img":false}]}
{"op":"mcm","clk":"11540780883","pt":1719498308603,"mc":[{"id":"1.230178313","rc":[{"atb":[[2.3,1.64]],"id":56913144}],"con":true,"img":false}]}
{"op":"mcm","clk":"11540780909","pt":1719498308807,"mc":[{"id":"1.230178313","rc":[{"atb":[[2.28,18.73]],"id":56913144}],"con":true,"img":false}]}
{"op":"mcm","clk":"11540780990","pt":1719498309687,"mc":[{"id":"1.230178313","rc":[{"atb":[[2.28,17.27]],"id":56913144}],"con":true,"img":false}]}
{"op":"mcm","clk":"11540781009","pt":1719498309893,"mc":[{"id":"1.230178313","rc":[{"atb":[[2.28,0.41]],"id":56913144}],"con":true,"img":false}]}
{"op":"mcm","clk":"11540781019","pt":1719498309998,"mc":[{"id":"1.230178313","rc":[{"atb":[[2.3,18.5]],"id":56913144}],"con":true,"img":false}]}
{"op":"mcm","clk":"11540781059","pt":1719498310409,"mc":[{"id":"1.230178313","rc":[{"atb":[[2.3,16.86]],"id":56913144}],"con":true,"img":false}]}
{"op":"mcm","clk":"11540781082","pt":1719498310617,"mc":[{"id":"1.230178313","rc":[{"atb":[[2.26,0]],"id":56913144}],"con":true,"img":false}]}
{"op":"mcm","clk":"11540781097","pt":1719498310671,"mc":[{"id":"1.230178313","rc":[{"atb":[[2.3,18.86]],"id":56913144}],"con":true,"img":false}]}
{"op":"mcm","clk":"11540781142","pt":1719498311186,"mc":[{"id":"1.230178313","rc":[{"atb":[[2.1,2.5]],"id":56913144},{"atb":[[2.16,0]],"id":39100893},{"atb":[[1.99,0]],"id":52951653}],"con":true,"img":false}]}
{"op":"mcm","clk":"11540781152","pt":1719498311289,"mc":[{"id":"1.230178313","rc":[{"atb":[[2,4.32]],"id":52951653}],"con":true,"img":false}]}
{"op":"mcm","clk":"11540781194","pt":1719498311705,"mc":[{"id":"1.230178313","rc":[{"atb":[[2.76,3.1]],"id":68462283},{"atb":[[2.64,8.77]],"id":70681331},{"atb":[[1.96,5.09]],"id":52951653},{"atb":[[2.12,7.29]],"id":39100893}],"con":true,"img":false}]}
{"op":"mcm","clk":"11540781247","pt":1719498312176,"mc":[{"id":"1.230178313","rc":[{"atb":[[2.32,3.38]],"id":56913144},{"atb":[[2.84,4.01]],"id":68462283},{"atb":[[2.66,12.89]],"id":70681331},{"atb":[[2,12.3]],"id":52951653},{"atb":[[2.22,5.09]],"id":39100893},{"atl":[[4.2,3.93]],"id":39100893}],"con":true,"img":false}]}
{"op":"mcm","clk":"11540781259","pt":1719498312283,"mc":[{"id":"1.230178313","rc":[{"atb":[[2.86,4.01]],"id":68462283},{"atl":[[4.1,3.94],[4.4,6.3]],"id":39100893},{"atl":[[4,8.82]],"id":52951653}],"con":true,"img":false}]}
{"op":"mcm","clk":"11540781272","pt":1719498312387,"mc":[{"id":"1.230178313","rc":[{"atb":[[2.2,0]],"id":56913144},{"atb":[[2.82,2.5],[2.8,0]],"id":68462283},{"atb":[[2.64,3.17]],"id":70681331},{"atb":[[2.14,0]],"id":39100893},{"atl":[[4.4,0.84]],"id":39100893},{"atb":[[1.98,0]],"id":52951653},{"atl":[[3.95,7.58],[4.1,1.26]],"id":52951653}],"con":true,"img":false}]}
{"op":"mcm","clk":"11540781287","pt":1719498312491,"mc":[{"id":"1.230178313","rc":[{"atb":[[2.84,12.03]],"id":68462283},{"atl":[[4.2,11.81]],"id":39100893}],"con":true,"img":false}]}
{"op":"mcm","clk":"11540781298","pt":1719498312595,"mc":[{"id":"1.230178313","rc":[{"atb":[[2.86,0]],"id":68462283},{"atl":[[4,0.84],[4.1,0],[4.4,0]],"id":39100893},{"atl":[[3.95,0],[4.1,16.41],[4.2,0]],"id":52951653}],"con":true,"img":false}]}
{"op":"mcm","clk":"11540781312","pt":1719498312700,"mc":[{"id":"1.230178313","rc":[{"atl":[[4.3,25.24],[3.9,1.26]],"id":52951653}],"con":true,"img":false}]}
{"op":"mcm","clk":"11540781325","pt":1719498312802,"mc":[{"id":"1.230178313","rc":[{"atb":[[1.09,0]],"id":68462283},{"atb":[[2.38,0]],"id":70681331},{"atb":[[2.02,1.56]],"id":52951653},{"atl":[[4.3,0],[4.1,0],[3.9,10.09]],"id":52951653}],"con":true,"img":false}]}
{"op":"mcm","clk":"11540781339","pt":1719498312904,"mc":[{"id":"1.230178313","rc":[{"atl":[[2.84,0]],"id":56913144},{"atb":[[2.76,0],[2.86,1.61]],"id":68462283},{"atb":[[2.68,1.61]],"id":70681331},{"atb":[[1.96,0]],"id":52951653},{"atb":[[2.12,2.5]],"id":39100893}],"con":true,"img":false}]}
{"op":"mcm","clk":"11540781359","pt":1719498313112,"mc":[{"id":"1.230178313","rc":[{"atb":[[2.3,2]],"id":56913144}],"con":true,"img":false}]}
{"op":"mcm","clk":"11540781370","pt":1719498313215,"mc":[{"id":"1.230178313","rc":[{"atb":[[2.26,6.65]],"id":51441055}],"con":true,"img":false}]}
{"op":"mcm","clk":"11540781382","pt":1719498313272,"mc":[{"id":"1.230178313","rc":[{"atb":[[2.3,0]],"id":56913144},{"atl":[[4,7.98],[3.85,0.84]],"id":52951653},{"atl":[[4,0]],"id":39100893}],"con":true,"img":false}]}
{"op":"mcm","clk":"11540781391","pt":1719498313374,"mc":[{"id":"1.230178313","rc":[{"atb":[[2.34,2]],"id":56913144},{"atb":[[2.2,0]],"id":51441055}],"con":true,"img":false}]}
{"op":"mcm","clk":"11540781404","pt":1719498313477,"mc":[{"id":"1.230178313","rc":[{"atb":[[2.32,0],[2.34,4.25]],"id":56913144},{"atl":[[4.3,24.9],[4.2,3.93]],"id":39100893},{"atb":[[2.3,1.49]],"id":51441055}],"con":true,"img":false}]}
{"op":"mcm","clk":"11540781415","pt":1719498313580,"mc":[{"id":"1.230178313","rc":[{"atl":[[4.3,1.26],[4.6,14.08]],"id":39100893}],"con":true,"img":false}]}
{"op":"mcm","clk":"11540781427","pt":1719498313684,"mc":[{"id":"1.230178313","rc":[{"atb":[[2.34,20.69]],"id":56913144},{"atb":[[2.3,9.57]],"id":51441055}],"con":true,"img":false}]}
{"op":"mcm","clk":"11540781440","pt":1719498313890,"mc":[{"id":"1.230178313","rc":[{"atb":[[2.28,3]],"id":51441055}],"con":true,"img":false}]}
{"op":"mcm","clk":"11540781448","pt":1719498313993,"mc":[{"id":"1.230178313","rc":[{"atb":[[2.64,0]],"id":70681331}],"con":true,"img":false}]}
{"op":"mcm","clk":"11540781487","pt":1719498314510,"mc":[{"id":"1.230178313","rc":[{"atb":[[2.28,4.31]],"id":56913144},{"atb":[[2.26,2.49]],"id":51441055}],"con":true,"img":false}]}
{"op":"mcm","clk":"11540781567","pt":1719498315497,"mc":[{"id":"1.230178313","rc":[{"atb":[[2.34,2.11],[2.24,0]],"id":51441055}],"con":true,"img":false}]}
{"op":"mcm","clk":"11540781854","pt":1719498318507,"mc":[{"id":"1.230178313","rc":[{"atb":[[2.28,0.41]],"id":56913144}],"con":true,"img":false}]}
{"op":"mcm","clk":"11540782008","pt":1719498320011,"mc":[{"id":"1.230178313","rc":[{"atb":[[2.82,0]],"id":68462283},{"atb":[[2.66,10.29]],"id":70681331},{"atb":[[2,9.98]],"id":52951653},{"atb":[[2.28,0]],"id":51441055}],"con":true,"img":false}]}
{"op":"mcm","clk":"11540782019","pt":1719498320113,"mc":[{"id":"1.230178313","rc":[{"atb":[[2.86,4.61]],"id":68462283},{"atb":[[2.68,4.61]],"id":70681331},{"atl":[[5.6,7.44]],"id":70681331},{"atb":[[2.02,4.76]],"id":52951653},{"atl":[[4.6,0],[4.4,6.16]],"id":52951653},{"atb":[[2.24,2.2]],"id":39100893},{"atl":[[4.6,13.08],[4.4,1]],"id":39100893},{"atb":[[2.34,4.21]],"id":51441055},{"atl":[[5.2,0]],"id":51441055}],"con":true,"img":false}]}
{"op":"mcm","clk":"11540782027","pt":1719498320217,"mc":[{"id":"1.230178313","rc":[{"atb":[[2.84,4.01],[2.88,4.62]],"id":68462283},{"atl":[[5.6,14.89],[5.8,0]],"id":70681331},{"atl":[[4.3,9.14],[4.6,0]],"id":39100893},{"atl":[[4.8,1]],"id":51441055}],"con":true,"img":false}]}
{"op":"mcm","clk":"11540782037","pt":1719498320322,"mc":[{"id":"1.230178313","rc":[{"atl":[[7.4,20.62],[6.6,2.5]],"id":70681331},{"atl":[[4.3,1.26],[4.4,6.2]],"id":39100893},{"atl":[[4.9,5.04],[5.2,10],[5.4,2.5]],"id":51441055}],"con":true,"img":false}]}
{"op":"mcm","clk":"11540782050","pt":1719498320380,"mc":[{"id":"1.230178313","rc":[{"atl":[[5.6,7.44]],"id":70681331},{"atl":[[5,0.84],[5.4,12.5]],"id":51441055}],"con":true,"img":false}]}
{"op":"mcm","clk":"11540782058","pt":1719498320483,"mc":[{"id":"1.230178313","rc":[{"atb":[[2.22,3.09]],"id":39100893},{"atl":[[5,6.88],[5.2,0],[5.4,2.5]],"id":51441055}],"con":true,"img":false}]}
{"op":"mcm","clk":"11540782070","pt":1719498320586,"mc":[{"id":"1.230178313","rc":[{"atb":[[2.86,3]],"id":68462283},{"atb":[[2.68,3]],"id":70681331},{"atb":[[2.26,2]],"id":39100893},{"atb":[[2.02,3.2]],"id":52951653},{"atb":[[2.3,8.08]],"id":51441055}],"con":true,"img":false}]}
{"op":"mcm","clk":"11540782082","pt":1719498320688,"mc":[{"id":"1.230178313","rc":[{"atb":[[2.88,0],[2.86,12.24]],"id":68462283}],"con":true,"img":false}]}
{"op":"mcm","clk":"11540782093","pt":1719498320790,"mc":[{"id":"1.230178313","rc":[{"atb":[[2.86,3],[2.84,11.63]],"id":68462283}],"con":true,"img":false}]}
{"op":"mcm","clk":"11540782100","pt":1719498320894,"mc":[{"id":"1.230178313","rc":[{"atb":[[2.84,4.01]],"id":68462283},{"atb":[[2,7.98]],"id":52951653}],"con":true,"img":false}]}
{"op":"mcm","clk":"11540782110","pt":1719498320999,"mc":[{"id":"1.230178313","rc":[{"atb":[[2.74,17.13]],"id":68462283},{"atb":[[2.04,2]],"id":52951653}],"con":true,"img":false}]}
{"op":"mcm","clk":"11540782135","pt":1719498321206,"mc":[{"id":"1.230178313","rc":[{"atb":[[2.76,1.61]],"id":68462283},{"atb":[[2.66,8.29]],"id":70681331}],"con":true,"img":false}]}
{"op":"mcm","clk":"11540782146","pt":1719498321309,"mc":[{"id":"1.230178313","rc":[{"atb":[[2.7,2]],"id":70681331}],"con":true,"img":false}]}
{"op":"mcm","clk":"11540782349","pt":1719498323394,"mc":[{"id":"1.230178313","rc":[{"atb":[[2.28,0]],"id":56913144}],"con":true,"img":false}]}
{"op":"mcm","clk":"11540782364","pt":1719498323498,"mc":[{"id":"1.230178313","rc":[{"atb":[[2.88,2.9]],"id":68462283},{"atb":[[2.7,9.84]],"id":70681331},{"atb":[[2.04,10.38]],"id":52951653},{"atb":[[2.26,5.97]],"id":39100893}],"con":true,"img":false}]}
{"op":"mcm","clk":"11540782378","pt":1719498323603,"mc":[{"id":"1.230178313","rc":[{"atl":[[3.85,9.22]],"id":52951653}],"con":true,"img":false}]}
{"op":"mcm","clk":"11540782390","pt":1719498323708,"mc":[{"id":"1.230178313","rc":[{"atb":[[2.84,0]],"id":68462283},{"atb":[[2.66,0]],"id":70681331},{"atb":[[2,0]],"id":52951653},{"atl":[[4,0]],"id":52951653},{"atb":[[2.22,0]],"id":39100893}],"con":true,"img":false}]}
{"op":"mcm","clk":"11540782425","pt":1719498324020,"mc":[{"id":"1.230178313","rc":[{"atl":[[3.9,8.83]],"id":52951653}],"con":true,"img":false}]}
{"op":"mcm","clk":"11540782437","pt":1719498324121,"mc":[{"id":"1.230178313","rc":[{"atl":[[4.3,18.06],[3.8,1.26],[3.9,0]],"id":52951653}],"con":true,"img":false}]}
{"op":"mcm","clk":"11540782450","pt":1719498324177,"mc":[{"id":"1.230178313","rc":[{"atb":[[2.72,1.61]],"id":70681331},{"atb":[[2.06,1.56]],"id":52951653}],"con":true,"img":false}]}
{"op":"mcm","clk":"11540782481","pt":1719498324487,"mc":[{"id":"1.230178313","rc":[{"atb":[[2.34,4.24]],"id":56913144},{"atl":[[2.7,0]],"id":56913144},{"trd":[[2.7,1.99]],"ltp":2.7,"tv":1.99,"id":56913144}],"con":true,"img":false}]}
{"op":"mcm","clk":"11540782495","pt":1719498324591,"mc":[{"id":"1.230178313","rc":[{"atb":[[2.36,1]],"id":56913144},{"atl":[[3.8,0]],"id":52951653}],"con":true,"img":false}]}
{"op":"mcm","clk":"11540782505","pt":1719498324691,"mc":[{"id":"1.230178313","rc":[{"atb":[[2.36,5.78]],"id":56913144}],"con":true,"img":false}]}
{"op":"mcm","clk":"11540782517","pt":1719498324794,"mc":[{"id":"1.230178313","rc":[{"atb":[[2.34,1.99]],"id":56913144}],"con":true,"img":false}]}
{"op":"mcm","clk":"11540782536","pt":1719498325002,"mc":[{"id":"1.230178313","rc":[{"atb":[[2.34,11.15]],"id":51441055}],"con":true,"img":false}]}
{"op":"mcm","clk":"11540782548","pt":1719498325107,"mc":[{"id":"1.230178313","rc":[{"atb":[[2.3,0]],"id":51441055}],"con":true,"img":false}]}
{"op":"mcm","clk":"11540782559","pt":1719498325211,"mc":[{"id":"1.230178313","rc":[{"atb":[[2.36,24.71]],"id":56913144},{"atl":[[2.78,3.12]],"id":56913144}],"con":true,"img":false}]}
{"op":"mcm","clk":"11540782593","pt":1719498325522,"mc":[{"id":"1.230178313","rc":[{"atb":[[2.34,0]],"id":56913144}],"con":true,"img":false}]}
{"op":"mcm","clk":"11540782604","pt":1719498325625,"mc":[{"id":"1.230178313","rc":[{"atb":[[2.38,2]],"id":56913144}],"con":true,"img":false}]}
{"op":"mcm","clk":"11540782612","pt":1719498325678,"mc":[{"id":"1.230178313","rc":[{"atb":[[2.36,23.71]],"id":56913144}],"con":true,"img":false}]}
{"op":"mcm","clk":"11540782648","pt":1719498325992,"mc":[{"id":"1.230178313","rc":[{"atb":[[2.36,19.94]],"id":56913144}],"con":true,"img":false}]}
{"op":"mcm","clk":"11540782662","pt":1719498326092,"mc":[{"id":"1.230178313","rc":[{"atb":[[2.86,8.8],[2.74,2.5]],"id":68462283}],"con":true,"img":false}]}
{"op":"mcm","clk":"11540782677","pt":1719498326195,"mc":[{"id":"1.230178313","rc":[{"atb":[[2.36,4.78]],"id":56913144}],"con":true,"img":false}]}
{"op":"mcm","clk":"11540782687","pt":1719498326299,"mc":[{"id":"1.230178313","rc":[{"atb":[[2.38,17.16]],"id":56913144},{"atb":[[1.64,0]],"id":52951653},{"atb":[[1.64,0]],"id":39100893}],"con":true,"img":false}]}
{"op":"mcm","clk":"11540782783","pt":1719498327081,"mc":[{"id":"1.230178313","rc":[{"atb":[[2.04,10.31]],"id":39100893}],"con":true,"img":false}]}
{"op":"mcm","clk":"11540782930","pt":1719498328484,"mc":[{"id":"1.230178313","rc":[{"atb":[[2.86,5.8]],"id":68462283},{"atb":[[2.68,0]],"id":70681331},{"atb":[[2.24,0]],"id":39100893},{"atb":[[2.02,0]],"id":52951653},{"atb":[[2.34,9.05]],"id":51441055}],"con":true,"img":false}]}
{"op":"mcm","clk":"11540782940","pt":1719498328585,"mc":[{"id":"1.230178313","rc":[{"atb":[[2.4,1]],"id":56913144}],"con":true,"img":false}]}
{"op":"mcm","clk":"11540782953","pt":1719498328690,"mc":[{"id":"1.230178313","rc":[{"atb":[[2.9,2.47]],"id":68462283},{"atb":[[2.72,4.39]],"id":70681331},{"atb":[[2.06,3.86]],"id":52951653},{"atb":[[2.28,3]],"id":39100893},{"atb":[[2.36,3.8]],"id":51441055}],"con":true,"img":false}]}
{"op":"mcm","clk":"11540782986","pt":1719498328996,"mc":[{"id":"1.230178313","rc":[{"atb":[[2.72,2.78]],"id":70681331},{"atb":[[2.06,2.3]],"id":52951653}],"con":true,"img":false}]}
{"op":"mcm","clk":"11540783001","pt":1719498329102,"mc":[{"id":"1.230178313","rc":[{"atl":[[2.72,1.38]],"id":56913144}],"con":true,"img":false}]}
{"op":"mcm","clk":"11540783016","pt":1719498329204,"mc":[{"id":"1.230178313","rc":[{"atb":[[2.1,5.38]],"id":39100893}],"con":true,"img":false}]}
{"op":"mcm","clk":"11540783023","pt":1719498329310,"mc":[{"id":"1.230178313","rc":[{"atb":[[1.03,0.52]],"id":56913144}],"con":true,"img":false}]}
{"op":"mcm","clk":"11540783042","pt":1719498329516,"mc":[{"id":"1.230178313","rc":[{"atb":[[1.03,0.36]],"id":56913144}],"con":true,"img":false}]}
{"op":"mcm","clk":"11540783065","pt":1719498329722,"mc":[{"id":"1.230178313","rc":[{"atb":[[1.03,0]],"id":56913144}],"con":true,"img":false}]}
{"op":"mcm","clk":"11540783077","pt":1719498329825,"mc":[{"id":"1.230178313","rc":[{"atb":[[2.42,0.36]],"id":56913144},{"atb":[[2.26,3.97]],"id":39100893}],"con":true,"img":false}]}
{"op":"mcm","clk":"11540783086","pt":1719498329929,"mc":[{"id":"1.230178313","rc":[{"atb":[[2.3,2]],"id":39100893}],"con":true,"img":false}]}
{"op":"mcm","clk":"11540783097","pt":1719498329981,"mc":[{"id":"1.230178313","rc":[{"atb":[[2.4,0]],"id":56913144},{"atl":[[2.74,3.5]],"id":56913144}],"con":true,"img":false}]}
{"op":"mcm","clk":"11540783120","pt":1719498330190,"mc":[{"id":"1.230178313","rc":[{"atb":[[2.12,4.1]],"id":39100893}],"con":true,"img":false}]}
{"op":"mcm","clk":"11540783139","pt":1719498330393,"mc":[{"id":"1.230178313","rc":[{"atb":[[2.04,8.38]],"id":52951653}],"con":true,"img":false}]}
{"op":"mcm","clk":"11540783152","pt":1719498330499,"mc":[{"id":"1.230178313","rc":[{"atb":[[2.08,2]],"id":52951653}],"con":true,"img":false}]}
{"op":"mcm","clk":"11540783186","pt":1719498330910,"mc":[{"id":"1.230178313","rc":[{"atl":[[2.72,16.22]],"id":56913144}],"con":true,"img":false}]}
{"op":"mcm","clk":"11540783198","pt":1719498331032,"mc":[{"id":"1.230178313","rc":[{"atb":[[2.7,7.84]],"id":70681331}],"con":true,"img":false}]}
{"op":"mcm","clk":"11540783210","pt":1719498331087,"mc":[{"id":"1.230178313","rc":[{"atb":[[2.74,2]],"id":70681331}],"con":true,"img":false}]}
{"op":"mcm","clk":"11540783224","pt":1719498331190,"mc":[{"id":"1.230178313","rc":[{"atb":[[2.9,5.37],[2.86,0]],"id":68462283}],"con":true,"img":false}]}
{"op":"mcm","clk":"11540783244","pt":1719498331397,"mc":[{"id":"1.230178313","rc":[{"atl":[[4.7,6.63]],"id":51441055}],"con":true,"img":false}]}
{"op":"mcm","clk":"11540783260","pt":1719498331502,"mc":[{"id":"1.230178313","rc":[{"atl":[[5,0.84],[4.6,5.04]],"id":51441055}],"con":true,"img":false}]}
{"op":"mcm","clk":"11540783270","pt":1719498331606,"mc":[{"id":"1.230178313","rc":[{"atl":[[4.8,12.67],[4.6,0],[4.9,0]],"id":51441055}],"con":true,"img":false}]}
{"op":"mcm","clk":"11540783297","pt":1719498331814,"mc":[{"id":"1.230178313","rc":[{"atl":[[1000,0]],"id":51441055}],"con":true,"img":false}]}
{"op":"mcm","clk":"11540783311","pt":1719498331917,"mc":[{"id":"1.230178313","rc":[{"atl":[[4.8,1],[5,20.14],[4.6,1.27]],"id":51441055}],"con":true,"img":false}]}
{"op":"mcm","clk":"11540783319","pt":1719498332021,"mc":[{"id":"1.230178313","rc":[{"atl":[[4.6,3.27],[5,0.84]],"id":51441055}],"con":true,"img":false}]}
{"op":"mcm","clk":"11540783330","pt":1719498332125,"mc":[{"id":"1.230178313","rc":[{"atl":[[4.8,8.91],[4.6,2.12],[5,0]],"id":51441055}],"con":true,"img":false}]}
{"op":"mcm","clk":"11540783342","pt":1719498332228,"mc":[{"id":"1.230178313","rc":[{"atl":[[4.8,1],[4.6,5.4]],"id":51441055}],"con":true,"img":false}]}
{"op":"mcm","clk":"11540783364","pt":1719498332389,"mc":[{"id":"1.230178313","rc":[{"atl":[[4.6,4.12]],"id":51441055}],"con":true,"img":false}]}
{"op":"mcm","clk":"11540783410","pt":1719498333108,"mc":[{"id":"1.230178313","rc":[{"atb":[[2.68,3.1]],"id":70681331}],"con":true,"img":false}]}
{"op":"mcm","clk":"11540783420","pt":1719498333209,"mc":[{"id":"1.230178313","rc":[{"atb":[[2.02,4.94]],"id":52951653},{"atb":[[2.24,4.33]],"id":39100893}],"con":true,"img":false}]}
{"op":"mcm","clk":"11540783513","pt":1719498334505,"mc":[{"id":"1.230178313","rc":[{"atb":[[2.74,9.67]],"id":70681331}],"con":true,"img":false}]}
{"op":"mcm","clk":"11540783521","pt":1719498334607,"mc":[{"id":"1.230178313","rc":[{"atb":[[2.92,2.44]],"id":68462283},{"atb":[[2.08,12.9]],"id":52951653},{"atb":[[2.3,7.2]],"id":39100893},{"atb":[[2.34,12.98]],"id":51441055}],"con":true,"img":false}]}
{"op":"mcm","clk":"11540783529","pt":1719498334710,"mc":[{"id":"1.230178313","rc":[{"atb":[[2.88,0]],"id":68462283},{"atb":[[2.7,0]],"id":70681331},{"atb":[[2.26,0]],"id":39100893},{"atb":[[2.04,0]],"id":52951653}],"con":true,"img":false}]}
{"op":"mcm","clk":"11540783556","pt":1719498335021,"mc":[{"id":"1.230178313","rc":[{"atb":[[2.76,1.61]],"id":70681331},{"atb":[[2.1,1.56],[2.02,0]],"id":52951653},{"atb":[[2.24,0]],"id":39100893},{"atb":[[2.36,5.29]],"id":51441055}],"con":true,"img":false}]}
{"op":"mcm","clk":"11540783617","pt":1719498335696,"mc":[{"id":"1.230178313","rc":[{"atb":[[2.4,6.21]],"id":56913144}],"con":true,"img":false}]}
{"op":"mcm","clk":"11540783634","pt":1719498335901,"mc":[{"id":"1.230178313","rc":[{"atb":[[2.36,0]],"id":56913144}],"con":true,"img":false}]}
{"op":"mcm","clk":"11540783651","pt":1719498336007,"mc":[{"id":"1.230178313","rc":[{"atb":[[2.36,12.36]],"id":51441055}],"con":true,"img":false}]}
{"op":"mcm","clk":"11540783661","pt":1719498336108,"mc":[{"id":"1.230178313","rc":[{"atb":[[2.68,0]],"id":70681331}],"con":true,"img":false}]}
{"op":"mcm","clk":"11540783672","pt":1719498336213,"mc":[{"id":"1.230178313","rc":[{"atb":[[2.34,6.04]],"id":51441055}],"con":true,"img":false}]}
{"op":"mcm","clk":"11540783682","pt":1719498336315,"mc":[{"id":"1.230178313","rc":[{"atb":[[2.38,2]],"id":56913144}],"con":true,"img":false}]}
{"op":"mcm","clk":"11540783692","pt":1719498336419,"mc":[{"id":"1.230178313","rc":[{"atb":[[2.04,3.12]],"id":52951653}],"con":true,"img":false}]}
{"op":"mcm","clk":"11540783709","pt":1719498336629,"mc":[{"id":"1.230178313","rc":[{"atb":[[2.38,0]],"id":56913144}],"con":true,"img":false}]}
{"op":"mcm","clk":"11540783718","pt":1719498336730,"mc":[{"id":"1.230178313","rc":[{"atb":[[2.42,2.36]],"id":56913144}],"con":true,"img":false}]}
{"op":"mcm","clk":"11540783725","pt":1719498336788,"mc":[{"id":"1.230178313","rc":[{"atb":[[2.4,10.11]],"id":56913144}],"con":true,"img":false}]}
{"op":"mcm","clk":"11540783734","pt":1719498336889,"mc":[{"id":"1.230178313","rc":[{"atb":[[2.76,0]],"id":70681331}],"con":true,"img":false}]}
{"op":"mcm","clk":"11540783750","pt":1719498337104,"mc":[{"id":"1.230178313","rc":[{"atb":[[2.42,18.21]],"id":56913144}],"con":true,"img":false}]}
{"op":"mcm","clk":"11540783758","pt":1719498337199,"mc":[{"id":"1.230178313","rc":[{"atl":[[4.8,11.76],[4.6,0.84]],"id":51441055}],"con":true,"img":false}]}
{"op":"mcm","clk":"11540783775","pt":1719498337415,"mc":[{"id":"1.230178313","rc":[{"atb":[[2.9,2.9]],"id":68462283},{"atb":[[2.72,0]],"id":70681331},{"atb":[[2.06,0]],"id":52951653},{"atb":[[2.28,0]],"id":39100893}],"con":true,"img":false}]}
{"op":"mcm","clk":"11540783785","pt":1719498337506,"mc":[{"id":"1.230178313","rc":[{"atb":[[2.76,2]],"id":70681331},{"atb":[[2.1,5.56]],"id":52951653},{"atb":[[2.32,2.5]],"id":39100893}],"con":true,"img":false}]}
{"op":"mcm","clk":"11540783796","pt":1719498337610,"mc":[{"id":"1.230178313","rc":[{"atb":[[2.9,0],[2.78,5.34]],"id":68462283}],"con":true,"img":false}]}
{"op":"mcm","clk":"11540783873","pt":1719498338339,"mc":[{"id":"1.230178313","rc":[{"atb":[[2.3,5.2]],"id":39100893}],"con":true,"img":false}]}
{"op":"mcm","clk":"11540783885","pt":1719498338394,"mc":[{"id":"1.230178313","rc":[{"atb":[[2.34,2]],"id":39100893}],"con":true,"img":false}]}
{"op":"mcm","clk":"11540783898","pt":1719498338506,"mc":[{"id":"1.230178313","rc":[{"atb":[[2.04,0]],"id":52951653}],"con":true,"img":false}]}
{"op":"mcm","clk":"11540783911","pt":1719498338611,"mc":[{"id":"1.230178313","rc":[{"atb":[[2.08,10.9]],"id":52951653}],"con":true,"img":false}]}
{"op":"mcm","clk":"11540783927","pt":1719498338716,"mc":[{"id":"1.230178313","rc":[{"atb":[[2.12,2]],"id":52951653}],"con":true,"img":false}]}
{"op":"mcm","clk":"11540783977","pt":1719498339229,"mc":[{"id":"1.230178313","rc":[{"atb":[[2.74,7.67]],"id":70681331}],"con":true,"img":false}]}
{"op":"mcm","clk":"11540783988","pt":1719498339321,"mc":[{"id":"1.230178313","rc":[{"atb":[[2.78,2]],"id":70681331},{"atb":[[2.1,4]],"id":52951653}],"con":true,"img":false}]}
{"op":"mcm","clk":"11540784086","pt":1719498340407,"mc":[{"id":"1.230178313","rc":[{"atl":[[8,10],[7.2,5],[6.4,2.5],[8.2,0],[7.4,15.62],[6.6,0]],"id":70681331},{"atl":[[4.8,2.5],[5.3,0],[4.9,0],[5.7,0]],"id":52951653},{"atb":[[1.98,0],[2.2,4.61]],"id":39100893},{"atl":[[6.4,0],[5.8,0],[5.3,2.5],[5.4,0]],"id":51441055}],"con":true,"img":false}]}
{"op":"mcm","clk":"11540784098","pt":1719498340512,"mc":[{"id":"1.230178313","rc":[{"atl":[[6.4,17.4],[7.4,0]],"id":70681331}],"con":true,"img":false}]}
{"op":"mcm","clk":"11540784107","pt":1719498340615,"mc":[{"id":"1.230178313","rc":[{"atl":[[7.2,21.13],[6.4,2.5]],"id":70681331}],"con":true,"img":false}]}
{"op":"mcm","clk":"11540784257","pt":1719498342325,"mc":[{"id":"1.230178313","rc":[{"atl":[[4.6,10.35]],"id":51441055}],"con":true,"img":false}]}
{"op":"mcm","clk":"11540784267","pt":1719498342430,"mc":[{"id":"1.230178313","rc":[{"atl":[[4.8,1],[4.5,10.36]],"id":51441055}],"con":true,"img":false}]}
{"op":"mcm","clk":"11540784276","pt":1719498342532,"mc":[{"id":"1.230178313","rc":[{"atl":[[2.78,0]],"id":56913144},{"atl":[[4.4,1.27],[4.7,20.72]],"id":51441055}],"con":true,"img":false}]}
{"op":"mcm","clk":"11540784284","pt":1719498342635,"mc":[{"id":"1.230178313","rc":[{"atl":[[4.5,0],[4.4,11.63],[4.7,0]],"id":51441055}],"con":true,"img":false}]}
{"op":"mcm","clk":"11540784291","pt":1719498342739,"mc":[{"id":"1.230178313","rc":[{"atl":[[4.4,12.48]],"id":51441055}],"con":true,"img":false}]}
{"op":"mcm","clk":"11540784345","pt":1719498343210,"mc":[{"id":"1.230178313","rc":[{"atl":[[4.6,9.51]],"id":51441055}],"con":true,"img":false}]}
{"op":"mcm","clk":"11540784471","pt":1719498344416,"mc":[{"id":"1.230178313","rc":[{"atb":[[2.14,2.5]],"id":56913144},{"atl":[[7.4,2.5],[7.8,0],[7.2,4.75],[6.2,3.25],[6,3.28]],"id":68462283}],"con":true,"img":false}]}
{"op":"mcm","clk":"11540784484","pt":1719498344503,"mc":[{"id":"1.230178313","rc":[{"atb":[[2.1,0],[2.02,7.64]],"id":56913144},{"atl":[[2.72,15.69]],"id":56913144},{"atb":[[2.92,0]],"id":68462283},{"atl":[[8,0],[6.4,0],[6.8,4.75],[9.6,0],[7.2,0],[6.2,1],[8.8,0]],"id":68462283}],"con":true,"img":false}]}
{"op":"mcm","clk":"11540784497","pt":1719498344605,"mc":[{"id":"1.230178313","rc":[{"atb":[[2.76,12.29],[2.9,4.27],[2.78,0]],"id":68462283}],"con":true,"img":false}]}
{"op":"mcm","clk":"11540784541","pt":1719498345120,"mc":[{"id":"1.230178313","rc":[{"atb":[[2.42,17.85]],"id":56913144}],"con":true,"img":false}]}
{"op":"mcm","clk":"11540784561","pt":1719498345326,"mc":[{"id":"1.230178313","rc":[{"atb":[[2.78,9.46]],"id":70681331}],"con":true,"img":false}]}
{"op":"mcm","clk":"11540784572","pt":1719498345430,"mc":[{"id":"1.230178313","rc":[{"atb":[[2.12,13.54]],"id":52951653},{"atb":[[2.34,6.83]],"id":39100893}],"con":true,"img":false}]}
{"op":"mcm","clk":"11540784583","pt":1719498345532,"mc":[{"id":"1.230178313","rc":[{"atb":[[2.74,0]],"id":70681331}],"con":true,"img":false}]}
{"op":"mcm","clk":"11540784591","pt":1719498345636,"mc":[{"id":"1.230178313","rc":[{"atb":[[2.3,0]],"id":39100893},{"atb":[[2.08,0]],"id":52951653}],"con":true,"img":false}]}
{"op":"mcm","clk":"11540784613","pt":1719498345793,"mc":[{"id":"1.230178313","rc":[{"atb":[[2.14,1.56]],"id":52951653}],"con":true,"img":false}]}
{"op":"mcm","clk":"11540784633","pt":1719498346002,"mc":[{"id":"1.230178313","rc":[{"atl":[[2.76,3.16]],"id":56913144}],"con":true,"img":false}]}
{"op":"mcm","clk":"11540784661","pt":1719498346310,"mc":[{"id":"1.230178313","rc":[{"atb":[[2.76,0]],"id":70681331},{"atb":[[2.1,0]],"id":52951653},{"atb":[[2.32,0]],"id":39100893}],"con":true,"img":false}]}
{"op":"mcm","clk":"11540784667","pt":1719498346409,"mc":[{"id":"1.230178313","rc":[{"atb":[[2.92,3]],"id":68462283},{"atb":[[2.8,2]],"id":70681331},{"atb":[[2.14,5.84]],"id":52951653},{"atb":[[2.36,2.31]],"id":39100893}],"con":true,"img":false}]}
{"op":"mcm","clk":"11540784677","pt":1719498346512,"mc":[{"id":"1.230178313","rc":[{"atb":[[2.44,10.21]],"id":56913144},{"atb":[[2.92,8.67]],"id":68462283}],"con":true,"img":false}]}
{"op":"mcm","clk":"11540784689","pt":1719498346617,"mc":[{"id":"1.230178313","rc":[{"atb":[[2.8,7.27],[2.76,1.61]],"id":68462283}],"con":true,"img":false}]}
{"op":"mcm","clk":"11540784699","pt":1719498346720,"mc":[{"id":"1.230178313","rc":[{"atb":[[2.4,3.9]],"id":56913144},{"atb":[[2.9,0]],"id":68462283}],"con":true,"img":false}]}
{"op":"mcm","clk":"11540784732","pt":1719498347132,"mc":[{"id":"1.230178313","rc":[{"atb":[[2.42,16.7]],"id":56913144},{"atb":[[2.14,4.28]],"id":52951653}],"con":true,"img":false}]}
{"op":"mcm","clk":"11540784754","pt":1719498347444,"mc":[{"id":"1.230178313","rc":[{"atb":[[2.42,2]],"id":56913144}],"con":true,"img":false}]}
{"op":"mcm","clk":"11540784763","pt":1719498347499,"mc":[{"id":"1.230178313","rc":[{"atb":[[2.44,24.91]],"id":56913144}],"con":true,"img":false}]}
{"op":"mcm","clk":"11540784777","pt":1719498347709,"mc":[{"id":"1.230178313","rc":[{"atb":[[2.4,0]],"id":56913144}],"con":true,"img":false}]}
{"op":"mcm","clk":"11540784800","pt":1719498347912,"mc":[{"id":"1.230178313","rc":[{"atb":[[2.34,4.83]],"id":39100893}],"con":true,"img":false}]}
{"op":"mcm","clk":"11540784816","pt":1719498348015,"mc":[{"id":"1.230178313","rc":[{"atb":[[2.38,2]],"id":39100893}],"con":true,"img":false}]}
{"op":"mcm","clk":"11540784853","pt":1719498348429,"mc":[{"id":"1.230178313","rc":[{"atb":[[2.12,11.54]],"id":52951653}],"con":true,"img":false}]}
{"op":"mcm","clk":"11540784859","pt":1719498348534,"mc":[{"id":"1.230178313","rc":[{"atb":[[2.16,2]],"id":52951653}],"con":true,"img":false}]}
{"op":"mcm","clk":"11540784896","pt":1719498348899,"mc":[{"id":"1.230178313","rc":[{"atl":[[4.6,1],[4.4,5.16]],"id":52951653},{"atl":[[4.6,1],[4.4,5.2]],"id":39100893}],"con":true,"img":false}]}
{"op":"mcm","clk":"11540784903","pt":1719498349002,"mc":[{"id":"1.230178313","rc":[{"atb":[[2.78,7.46]],"id":70681331}],"con":true,"img":false}]}
{"op":"mcm","clk":"11540784908","pt":1719498349103,"mc":[{"id":"1.230178313","rc":[{"atb":[[2.82,2]],"id":70681331}],"con":true,"img":false}]}
{"op":"mcm","clk":"11540784919","pt":1719498349205,"mc":[{"id":"1.230178313","rc":[{"atl":[[4.6,0],[4.4,6.2]],"id":39100893},{"atl":[[4.6,0],[4.4,6.16]],"id":52951653}],"con":true,"img":false}]}
{"op":"mcm","clk":"11540784944","pt":1719498349516,"mc":[{"id":"1.230178313","rc":[{"atb":[[2.42,0]],"id":56913144}],"con":true,"img":false}]}
{"op":"mcm","clk":"11540784958","pt":1719498349620,"mc":[{"id":"1.230178313","rc":[{"atb":[[2.46,2]],"id":56913144}],"con":true,"img":false}]}
{"op":"mcm","clk":"11540785048","pt":1719498350603,"mc":[{"id":"1.230178313","rc":[{"atb":[[2.8,0],[2.92,15.94]],"id":68462283},{"atl":[[7.2,6.58],[6.4,1],[6.2,0],[6.8,0]],"id":68462283},{"atl":[[5.6,6.44],[5.8,1]],"id":70681331},{"atl":[[4.6,1],[4.4,5.16]],"id":52951653},{"atl":[[4.6,1],[4.4,5.2]],"id":39100893},{"atl":[[4.8,0],[5.1,1]],"id":51441055}],"con":true,"img":false}]}
{"op":"mcm","clk":"11540785060","pt":1719498350704,"mc":[{"id":"1.230178313","rc":[{"atb":[[2.92,8.67],[2.78,15.94]],"id":68462283},{"atl":[[7.2,5],[6.4,17.4]],"id":70681331}],"con":true,"img":false}]}
{"op":"mcm","clk":"11540785068","pt":1719498350807,"mc":[{"id":"1.230178313","rc":[{"atb":[[2.92,11.17],[2.78,0]],"id":68462283}],"con":true,"img":false}]}
{"op":"mcm","clk":"11540785074","pt":1719498350912,"mc":[{"id":"1.230178313","rc":[{"atb":[[2.92,8.67],[2.78,17.34]],"id":68462283}],"con":true,"img":false}]}
{"op":"mcm","clk":"11540785084","pt":1719498351012,"mc":[{"id":"1.230178313","rc":[{"atb":[[2.92,11.17],[2.78,0]],"id":68462283}],"con":true,"img":false}]}
{"op":"mcm","clk":"11540785092","pt":1719498351123,"mc":[{"id":"1.230178313","rc":[{"atb":[[2.78,17.34]],"id":68462283}],"con":true,"img":false}]}
{"op":"mcm","clk":"11540785101","pt":1719498351221,"mc":[{"id":"1.230178313","rc":[{"atb":[[2.92,8.67]],"id":68462283}],"con":true,"img":false}]}
{"op":"mcm","clk":"11540785121","pt":1719498351429,"mc":[{"id":"1.230178313","rc":[{"atb":[[2.92,19.84],[2.78,0]],"id":68462283}],"con":true,"img":false}]}
{"op":"mcm","clk":"11540785166","pt":1719498352010,"mc":[{"id":"1.230178313","rc":[{"atb":[[1.03,0.52]],"id":56913144}],"con":true,"img":false}]}
{"op":"mcm","clk":"11540785176","pt":1719498352115,"mc":[{"id":"1.230178313","rc":[{"atb":[[1.03,0.35]],"id":56913144}],"con":true,"img":false}]}
{"op":"mcm","clk":"11540785217","pt":1719498352528,"mc":[{"id":"1.230178313","rc":[{"atb":[[1.03,0]],"id":56913144}],"con":true,"img":false}]}
{"op":"mcm","clk":"11540785226","pt":1719498352633,"mc":[{"id":"1.230178313","rc":[{"atb":[[2.48,0.35]],"id":56913144}],"con":true,"img":false}]}
{"op":"mcm","clk":"11540785264","pt":1719498353015,"mc":[{"id":"1.230178313","rc":[{"atl":[[4.3,11.67]],"id":51441055}],"con":true,"img":false}]}
{"op":"mcm","clk":"11540785286","pt":1719498353215,"mc":[{"id":"1.230178313","rc":[{"atl":[[4.6,0]],"id":51441055}],"con":true,"img":false}]}
{"op":"mcm","clk":"11540785302","pt":1719498353423,"mc":[{"id":"1.230178313","rc":[{"atl":[[4.4,11.2]],"id":51441055}],"con":true,"img":false}]}
{"op":"mcm","clk":"11540785311","pt":1719498353526,"mc":[{"id":"1.230178313","rc":[{"atb":[[2.44,10.21]],"id":56913144},{"atb":[[2.32,4.07]],"id":39100893},{"atb":[[2.1,4.58]],"id":52951653},{"atl":[[5.1,23.88],[4.4,0.84],[4.2,1.27]],"id":51441055}],"con":true,"img":false}]}
{"op":"mcm","clk":"11540785321","pt":1719498353625,"mc":[{"id":"1.230178313","rc":[{"atl":[[4.2,2.12]],"id":51441055}],"con":true,"img":false}]}
{"op":"mcm","clk":"11540785352","pt":1719498354040,"mc":[{"id":"1.230178313","rc":[{"atl":[[4.2,0.84]],"id":51441055}],"con":true,"img":false}]}
{"op":"mcm","clk":"11540785363","pt":1719498354142,"mc":[{"id":"1.230178313","rc":[{"atl":[[4.4,0]],"id":51441055}],"con":true,"img":false}]}
{"op":"mcm","clk":"11540785398","pt":1719498354506,"mc":[{"id":"1.230178313","rc":[{"atb":[[2.46,16.38]],"id":56913144}],"con":true,"img":false}]}
{"op":"mcm","clk":"11540785429","pt":1719498354921,"mc":[{"id":"1.230178313","rc":[{"atb":[[2.8,0]],"id":70681331},{"atb":[[2.14,0]],"id":52951653},{"atb":[[2.36,0]],"id":39100893}],"con":true,"img":false}]}
{"op":"mcm","clk":"11540785445","pt":1719498355127,"mc":[{"id":"1.230178313","rc":[{"atb":[[2.82,5]],"id":70681331},{"atb":[[2.16,4.99]],"id":52951653},{"atb":[[2.38,4.63]],"id":39100893}],"con":true,"img":false}]}
{"op":"mcm","clk":"11540785500","pt":1719498355704,"mc":[{"id":"1.230178313","rc":[{"atb":[[2.38,2.63]],"id":39100893}],"con":true,"img":false}]}
{"op":"mcm","clk":"11540785509","pt":1719498355804,"mc":[{"id":"1.230178313","rc":[{"atb":[[2.36,2]],"id":39100893}],"con":true,"img":false}]}
{"op":"mcm","clk":"11540785518","pt":1719498355909,"mc":[{"id":"1.230178313","rc":[{"atb":[[2.82,13.59]],"id":70681331}],"con":true,"img":false}]}
{"op":"mcm","clk":"11540785527","pt":1719498356011,"mc":[{"id":"1.230178313","rc":[{"atb":[[2.78,0]],"id":70681331},{"atb":[[2.38,7.56]],"id":39100893},{"atb":[[2.16,15.78]],"id":52951653}],"con":true,"img":false}]}
{"op":"mcm","clk":"11540785546","pt":1719498356221,"mc":[{"id":"1.230178313","rc":[{"atb":[[2.52,2.11],[2.16,0]],"id":56913144},{"atb":[[2.12,0],[2.1,0],[2.16,13.78]],"id":52951653},{"atb":[[2.32,0],[2.34,0]],"id":39100893}],"con":true,"img":false}]}
{"op":"mcm","clk":"11540785555","pt":1719498356328,"mc":[{"id":"1.230178313","rc":[{"atb":[[2.14,2]],"id":52951653}],"con":true,"img":false}]}
{"op":"mcm","clk":"11540785565","pt":1719498356425,"mc":[{"id":"1.230178313","rc":[{"atl":[[2.74,0]],"id":56913144}],"con":true,"img":false}]}
{"op":"mcm","clk":"11540785580","pt":1719498356634,"mc":[{"id":"1.230178313","rc":[{"atb":[[2.18,1.56]],"id":52951653}],"con":true,"img":false}]}
{"op":"mcm","clk":"11540785592","pt":1719498356737,"mc":[{"id":"1.230178313","rc":[{"atb":[[2.82,11.59]],"id":70681331}],"con":true,"img":false}]}
{"op":"mcm","clk":"11540785607","pt":1719498356840,"mc":[{"id":"1.230178313","rc":[{"atb":[[2.8,2]],"id":70681331}],"con":true,"img":false}]}
{"op":"mcm","clk":"11540785618","pt":1719498356943,"mc":[{"id":"1.230178313","rc":[{"atb":[[2.42,3.84]],"id":56913144}],"con":true,"img":false}]}
{"op":"mcm","clk":"11540785649","pt":1719498357207,"mc":[{"id":"1.230178313","rc":[{"atb":[[2.84,1.61]],"id":70681331}],"con":true,"img":false}]}
{"op":"mcm","clk":"11540785687","pt":1719498357622,"mc":[{"id":"1.230178313","rc":[{"atb":[[2.36,0]],"id":39100893}],"con":true,"img":false}]}
{"op":"mcm","clk":"11540785698","pt":1719498357722,"mc":[{"id":"1.230178313","rc":[{"atb":[[2.4,2]],"id":39100893}],"con":true,"img":false}]}
{"op":"mcm","clk":"11540785725","pt":1719498358033,"mc":[{"id":"1.230178313","rc":[{"atb":[[2.14,0]],"id":52951653}],"con":true,"img":false}]}
{"op":"mcm","clk":"11540785735","pt":1719498358141,"mc":[{"id":"1.230178313","rc":[{"atb":[[2.42,0]],"id":56913144},{"atb":[[2.18,3.56]],"id":52951653}],"con":true,"img":false}]}
{"op":"mcm","clk":"11540785749","pt":1719498358243,"mc":[{"id":"1.230178313","rc":[{"atl":[[4.3,0]],"id":39100893}],"con":true,"img":false}]}
{"op":"mcm","clk":"11540785761","pt":1719498358347,"mc":[{"id":"1.230178313","rc":[{"atb":[[2.8,0]],"id":70681331},{"atl":[[4.6,10.14],[4.4,0]],"id":39100893}],"con":true,"img":false}]}
{"op":"mcm","clk":"11540785775","pt":1719498358453,"mc":[{"id":"1.230178313","rc":[{"atb":[[2.84,3.61]],"id":70681331},{"atb":[[2.18,2]],"id":52951653}],"con":true,"img":false}]}
{"op":"mcm","clk":"11540785789","pt":1719498358513,"mc":[{"id":"1.230178313","rc":[{"atl":[[4.6,1],[4.9,16.58]],"id":39100893}],"con":true,"img":false}]}
{"op":"mcm","clk":"11540785811","pt":1719498358720,"mc":[{"id":"1.230178313","rc":[{"atb":[[2.46,14.38]],"id":56913144}],"con":true,"img":false}]}
{"op":"mcm","clk":"11540785821","pt":1719498358820,"mc":[{"id":"1.230178313","rc":[{"atb":[[1.02,13.23]],"id":56913144}],"con":true,"img":false}]}
{"op":"mcm","clk":"11540785841","pt":1719498359021,"mc":[{"id":"1.230178313","rc":[{"atb":[[2.84,2]],"id":70681331}],"con":true,"img":false}]}
{"op":"mcm","clk":"11540786090","pt":1719498361937,"mc":[{"id":"1.230178313","rc":[{"atb":[[1.93,0]],"id":56913144}],"con":true,"img":false}]}
{"op":"mcm","clk":"11540786120","pt":1719498362246,"mc":[{"id":"1.230178313","rc":[{"atb":[[1.87,0]],"id":56913144}],"con":true,"img":false}]}
{"op":"mcm","clk":"11540786282","pt":1719498363544,"mc":[{"id":"1.230178313","rc":[{"atb":[[2.82,8.59]],"id":70681331},{"atb":[[2.38,4.93]],"id":39100893},{"atb":[[2.16,10.79]],"id":52951653},{"atl":[[4.2,14.13]],"id":51441055}],"con":true,"img":false}]}
{"op":"mcm","clk":"11540786293","pt":1719498363647,"mc":[{"id":"1.230178313","rc":[{"atb":[[2.84,4.8]],"id":70681331},{"atb":[[2.18,5.42]],"id":52951653},{"atb":[[2.4,4.6]],"id":39100893},{"atl":[[4.3,0]],"id":51441055}],"con":true,"img":false}]}
{"op":"mcm","clk":"11540786307","pt":1719498363854,"mc":[{"id":"1.230178313","rc":[{"atb":[[2.2,1.56]],"id":52951653}],"con":true,"img":false}]}
{"op":"mcm","clk":"11540786351","pt":1719498364327,"mc":[{"id":"1.230178313","rc":[{"atl":[[4.4,4.17]],"id":51441055}],"con":true,"img":false}]}
{"op":"mcm","clk":"11540786359","pt":1719498364429,"mc":[{"id":"1.230178313","rc":[{"atl":[[5.1,1],[4.3,28.28]],"id":51441055}],"con":true,"img":false}]}
{"op":"mcm","clk":"11540786366","pt":1719498364533,"mc":[{"id":"1.230178313","rc":[{"atl":[[4.3,0],[4.4,29.41]],"id":51441055}],"con":true,"img":false}]}
{"op":"mcm","clk":"11540786384","pt":1719498365121,"mc":[{"id":"1.230178313","rc":[{"atl":[[4.1,1.27]],"id":51441055}],"con":true,"img":false}]}
{"op":"mcm","clk":"11540786538","pt":1719498366330,"mc":[{"id":"1.230178313","rc":[{"spn":2.62,"spf":"NaN","id":56913144},{"spn":2.92,"spf":1.0,"id":68462283},{"atb":[[2.84,13.24]],"id":70681331},{"spn":4.22,"spf":"NaN","id":70681331},{"spn":3.02,"spf":"NaN","id":52951653},{"spn":3.3,"spf":"NaN","id":39100893},{"spn":2.36,"spf":1.0,"id":51441055}],"con":true,"img":false}]}
{"op":"mcm","clk":"11540786546","pt":1719498366432,"mc":[{"id":"1.230178313","rc":[{"atb":[[2.4,11.51]],"id":39100893}],"con":true,"img":false}]}
{"op":"mcm","clk":"11540786557","pt":1719498366538,"mc":[{"id":"1.230178313","rc":[{"atb":[[2.82,0]],"id":70681331}],"con":true,"img":false}]}
{"op":"mcm","clk":"11540786565","pt":1719498366640,"mc":[{"id":"1.230178313","rc":[{"atb":[[2.38,0]],"id":39100893}],"con":true,"img":false}]}
{"op":"mcm","clk":"11540786637","pt":1719498367315,"mc":[{"id":"1.230178313","rc":[{"atb":[[1.02,11.23]],"id":56913144}],"con":true,"img":false}]}
{"op":"mcm","clk":"11540786651","pt":1719498367423,"mc":[{"id":"1.230178313","rc":[{"atb":[[2.54,2]],"id":56913144}],"con":true,"img":false}]}
{"op":"mcm","clk":"11540786702","pt":1719498368043,"mc":[{"id":"1.230178313","rc":[{"atb":[[2.48,0]],"id":56913144}],"con":true,"img":false}]}
{"op":"mcm","clk":"11540786845","pt":1719498369761,"mc":[{"id":"1.230178313","rc":[{"atl":[[4.1,15.41],[4.4,0]],"id":51441055}],"con":true,"img":false}]}
{"op":"mcm","clk":"11540786886","pt":1719498370128,"mc":[{"id":"1.230178313","rc":[{"atl":[[4,0.84]],"id":51441055}],"con":true,"img":false}]}
{"op":"mcm","clk":"11540787041","pt":1719498372243,"mc":[{"id":"1.230178313","rc":[{"atb":[[2.84,10.44]],"id":70681331},{"atb":[[2.4,8.91]],"id":39100893},{"atb":[[2.18,2]],"id":52951653}],"con":true,"img":false}]}
{"op":"mcm","clk":"11540787052","pt":1719498372347,"mc":[{"id":"1.230178313","rc":[{"atb":[[2.86,3]],"id":70681331},{"atb":[[2.2,5.08]],"id":52951653},{"atb":[[2.42,2.96]],"id":39100893}],"con":true,"img":false}]}
{"op":"mcm","clk":"11540787097","pt":1719498372826,"mc":[{"id":"1.230178313","rc":[{"atb":[[2.38,3.9]],"id":39100893},{"atb":[[2.18,6.28],[2.2,3.52]],"id":52951653}],"con":true,"img":false}]}
{"op":"mcm","clk":"11540787123","pt":1719498373137,"mc":[{"id":"1.230178313","rc":[{"atb":[[1.04,0.52]],"id":56913144}],"con":true,"img":false}]}
{"op":"mcm","clk":"11540787149","pt":1719498373344,"mc":[{"id":"1.230178313","rc":[{"atb":[[2.4,6.91]],"id":39100893}],"con":true,"img":false}]}
{"op":"mcm","clk":"11540787163","pt":1719498373449,"mc":[{"id":"1.230178313","rc":[{"atb":[[1.04,0.33]],"id":56913144},{"atb":[[2.44,2]],"id":39100893}],"con":true,"img":false}]}
{"op":"mcm","clk":"11540787181","pt":1719498373642,"mc":[{"id":"1.230178313","rc":[{"atb":[[1.04,0]],"id":56913144}],"con":true,"img":false}]}
{"op":"mcm","clk":"11540787191","pt":1719498373745,"mc":[{"id":"1.230178313","rc":[{"atb":[[2.56,0.33]],"id":56913144},{"atl":[[4,14.65]],"id":51441055}],"con":true,"img":false}]}
{"op":"mcm","clk":"11540787205","pt":1719498373954,"mc":[{"id":"1.230178313","rc":[{"atb":[[2.18,4.28]],"id":52951653},{"atl":[[4.2,0.84]],"id":51441055}],"con":true,"img":false}]}
{"op":"mcm","clk":"11540787213","pt":1719498374057,"mc":[{"id":"1.230178313","rc":[{"atb":[[2.22,2]],"id":52951653}],"con":true,"img":false}]}
{"op":"mcm","clk":"11540787224","pt":1719498374161,"mc":[{"id":"1.230178313","rc":[{"atl":[[4.2,0]],"id":51441055}],"con":true,"img":false}]}
{"op":"mcm","clk":"11540787242","pt":1719498374422,"mc":[{"id":"1.230178313","rc":[{"atb":[[2.84,8.44]],"id":70681331},{"atl":[[4.1,14.14]],"id":51441055}],"con":true,"img":false}]}
{"op":"mcm","clk":"11540787251","pt":1719498374524,"mc":[{"id":"1.230178313","rc":[{"atb":[[2.88,2]],"id":70681331},{"atl":[[5.1,25.39],[3.95,1.27],[4.1,0]],"id":51441055}],"con":true,"img":false}]}
{"op":"mcm","clk":"11540787282","pt":1719498374832,"mc":[{"id":"1.230178313","rc":[{"atl":[[5.1,1],[4.1,15.94]],"id":51441055}],"con":true,"img":false}]}
{"op":"mcm","clk":"11540787300","pt":1719498375040,"mc":[{"id":"1.230178313","rc":[{"atl":[[3.95,0]],"id":51441055}],"con":true,"img":false}]}
{"op":"mcm","clk":"11540787312","pt":1719498375143,"mc":[{"id":"1.230178313","rc":[{"atl":[[5.1,25.39],[4.1,0]],"id":51441055}],"con":true,"img":false}]}
{"op":"mcm","clk":"11540787387","pt":1719498376127,"mc":[{"id":"1.230178313","rc":[{"atb":[[2.46,18.12]],"id":56913144}],"con":true,"img":false}]}
{"op":"mcm","clk":"11540787418","pt":1719498376539,"mc":[{"id":"1.230178313","rc":[{"atb":[[2.88,9.09]],"id":70681331}],"con":true,"img":false}]}
{"op":"mcm","clk":"11540787430","pt":1719498376643,"mc":[{"id":"1.230178313","rc":[{"atb":[[2.84,0]],"id":70681331},{"atb":[[2.44,7.18]],"id":39100893}],"con":true,"img":false}]}
{"op":"mcm","clk":"11540787442","pt":1719498376745,"mc":[{"id":"1.230178313","rc":[{"atb":[[2.4,0],[2.38,0]],"id":39100893}],"con":true,"img":false}]}
{"op":"mcm","clk":"11540787595","pt":1719498378041,"mc":[{"id":"1.230178313","rc":[{"atb":[[2.86,0]],"id":70681331},{"atb":[[2.42,0]],"id":39100893},{"atb":[[2.2,0]],"id":52951653}],"con":true,"img":false}]}
{"op":"mcm","clk":"11540787605","pt":1719498378146,"mc":[{"id":"1.230178313","rc":[{"atb":[[2.9,2]],"id":70681331},{"atb":[[2.22,4]],"id":52951653},{"atb":[[2.46,2]],"id":39100893}],"con":true,"img":false}]}
{"op":"mcm","clk":"11540787669","pt":1719498378966,"mc":[{"id":"1.230178313","rc":[{"atb":[[2.44,5.18]],"id":39100893}],"con":true,"img":false}]}
{"op":"mcm","clk":"11540787684","pt":1719498379068,"mc":[{"id":"1.230178313","rc":[{"atb":[[2.48,2]],"id":39100893}],"con":true,"img":false}]}
{"op":"mcm","clk":"11540787710","pt":1719498379434,"mc":[{"id":"1.230178313","rc":[{"atb":[[2.88,7.09]],"id":70681331}],"con":true,"img":false}]}
{"op":"mcm","clk":"11540787718","pt":1719498379549,"mc":[{"id":"1.230178313","rc":[{"atb":[[2.92,2]],"id":70681331}],"con":true,"img":false}]}
{"op":"mcm","clk":"11540787752","pt":1719498379959,"mc":[{"id":"1.230178313","rc":[{"atb":[[1.96,0]],"id":56913144}],"con":true,"img":false}]}
{"op":"mcm","clk":"11540787825","pt":1719498381074,"mc":[{"id":"1.230178313","rc":[{"atb":[[2.92,8.67],[2.9,39.68]],"id":68462283}],"con":true,"img":false}]}
{"op":"mcm","clk":"11540787850","pt":1719498381363,"mc":[{"id":"1.230178313","rc":[{"atb":[[2.76,0]],"id":68462283}],"con":true,"img":false}]}
{"op":"mcm","clk":"11540787856","pt":1719498381466,"mc":[{"id":"1.230178313","rc":[{"atb":[[2.94,1.61]],"id":68462283}],"con":true,"img":false}]}
{"op":"mcm","clk":"11540787863","pt":1719498381570,"mc":[{"id":"1.230178313","rc":[{"atb":[[2.96,7.4]],"id":68462283}],"con":true,"img":false}]}
{"op":"mcm","clk":"11540787887","pt":1719498381740,"mc":[{"id":"1.230178313","rc":[{"atb":[[2.92,3]],"id":68462283}],"con":true,"img":false}]}
{"op":"mcm","clk":"11540787902","pt":1719498381955,"mc":[{"id":"1.230178313","rc":[{"atb":[[2.94,0]],"id":68462283}],"con":true,"img":false}]}
{"op":"mcm","clk":"11540787911","pt":1719498382039,"mc":[{"id":"1.230178313","rc":[{"atb":[[2.98,1.61]],"id":68462283}],"con":true,"img":false}]}
{"op":"mcm","clk":"11540787927","pt":1719498382153,"mc":[{"id":"1.230178313","rc":[{"atb":[[3,4.72],[2.96,0]],"id":68462283}],"con":true,"img":false}]}
{"op":"mcm","clk":"11540787948","pt":1719498382453,"mc":[{"id":"1.230178313","rc":[{"atb":[[2.98,0]],"id":68462283}],"con":true,"img":false}]}
{"op":"mcm","clk":"11540787962","pt":1719498382661,"mc":[{"id":"1.230178313","rc":[{"atb":[[3,0]],"id":68462283}],"con":true,"img":false}]}
{"op":"mcm","clk":"11540787972","pt":1719498382764,"mc":[{"id":"1.230178313","rc":[{"atb":[[2.98,4.72]],"id":68462283}],"con":true,"img":false}]}
{"op":"mcm","clk":"11540787996","pt":1719498383074,"mc":[{"id":"1.230178313","rc":[{"atb":[[2.98,0]],"id":68462283}],"con":true,"img":false}]}
{"op":"mcm","clk":"11540788003","pt":1719498383139,"mc":[{"id":"1.230178313","rc":[{"atb":[[2.96,4.72]],"id":68462283}],"con":true,"img":false}]}
{"op":"mcm","clk":"11540788028","pt":1719498383545,"mc":[{"id":"1.230178313","rc":[{"atb":[[2.98,1.94]],"id":68462283},{"atb":[[2.9,3.94]],"id":70681331},{"atb":[[2.46,3.94]],"id":39100893},{"atb":[[2.24,1.94]],"id":52951653},{"atb":[[2.38,1.94]],"id":51441055}],"con":true,"img":false}]}
{"op":"mcm","clk":"11540788038","pt":1719498383649,"mc":[{"id":"1.230178313","rc":[{"atb":[[2.34,6.57],[2.38,15.75]],"id":51441055}],"con":true,"img":false}]}
{"op":"mcm","clk":"11540788051","pt":1719498383856,"mc":[{"id":"1.230178313","rc":[{"atb":[[2.34,6.04],[2.36,5.29]],"id":51441055},{"atl":[[3.95,20.27]],"id":51441055}],"con":true,"img":false}]}
{"op":"mcm","clk":"11540788063","pt":1719498384063,"mc":[{"id":"1.230178313","rc":[{"atl":[[4,0.84]],"id":51441055}],"con":true,"img":false}]}
{"op":"mcm","clk":"11540788075","pt":1719498384172,"mc":[{"id":"1.230178313","rc":[{"atb":[[2.92,0]],"id":68462283},{"atb":[[2.9,1.94]],"id":70681331},{"atb":[[2.46,1.94]],"id":39100893},{"atb":[[2.22,2]],"id":52951653},{"atb":[[2.36,1.49]],"id":51441055},{"atl":[[3.9,0.84]],"id":51441055}],"con":true,"img":false}]}
{"op":"mcm","clk":"11540788085","pt":1719498384277,"mc":[{"id":"1.230178313","rc":[{"atb":[[2.98,3.94]],"id":68462283},{"atb":[[2.92,4.8]],"id":70681331},{"atb":[[2.24,4.54]],"id":52951653},{"atb":[[2.48,4]],"id":39100893},{"atb":[[2.36,0],[2.4,2]],"id":51441055},{"atl":[[4,21.96],[5.1,1]],"id":51441055}],"con":true,"img":false}]}
{"op":"mcm","clk":"11540788097","pt":1719498384345,"mc":[{"id":"1.230178313","rc":[{"atb":[[2.34,2.11],[2.4,3.49]],"id":51441055}],"con":true,"img":false}]}
{"op":"mcm","clk":"11540788110","pt":1719498384541,"mc":[{"id":"1.230178313","rc":[{"atb":[[2.48,2]],"id":39100893},{"atl":[[3.9,2.12]],"id":51441055}],"con":true,"img":false}]}
{"op":"mcm","clk":"11540788117","pt":1719498384657,"mc":[{"id":"1.230178313","rc":[{"atb":[[2.46,3.94]],"id":39100893},{"atb":[[2.24,6.66],[1.92,0]],"id":52951653}],"con":true,"img":false}]}
{"op":"mcm","clk":"11540788141","pt":1719498384963,"mc":[{"id":"1.230178313","rc":[{"atb":[[2.22,0]],"id":52951653}],"con":true,"img":false}]}
{"op":"mcm","clk":"11540788151","pt":1719498385082,"mc":[{"id":"1.230178313","rc":[{"atb":[[2.2,2]],"id":52951653}],"con":true,"img":false}]}
{"op":"mcm","clk":"11540788159","pt":1719498385159,"mc":[{"id":"1.230178313","rc":[{"atl":[[4,21.12]],"id":51441055}],"con":true,"img":false}]}
{"op":"mcm","clk":"11540788187","pt":1719498385574,"mc":[{"id":"1.230178313","rc":[{"atb":[[2.92,2.8]],"id":70681331}],"con":true,"img":false}]}
{"op":"mcm","clk":"11540788194","pt":1719498385636,"mc":[{"id":"1.230178313","rc":[{"atb":[[2.9,3.94]],"id":70681331}],"con":true,"img":false}]}
{"op":"mcm","clk":"11540788223","pt":1719498386041,"mc":[{"id":"1.230178313","rc":[{"atl":[[4.4,0]],"id":52951653}],"con":true,"img":false}]}
{"op":"mcm","clk":"11540788231","pt":1719498386145,"mc":[{"id":"1.230178313","rc":[{"atb":[[2.94,8.67]],"id":68462283},{"atl":[[4.3,0],[4.6,28.29]],"id":52951653}],"con":true,"img":false}]}
{"op":"mcm","clk":"11540788237","pt":1719498386247,"mc":[{"id":"1.230178313","rc":[{"atb":[[2.9,0]],"id":68462283}],"con":true,"img":false}]}
{"op":"mcm","clk":"11540788258","pt":1719498386554,"mc":[{"id":"1.230178313","rc":[{"atb":[[2.92,10.6]],"id":70681331},{"atb":[[2.46,1.94]],"id":39100893}],"con":true,"img":false}]}
{"op":"mcm","clk":"11540788267","pt":1719498386657,"mc":[{"id":"1.230178313","rc":[{"atb":[[2.5,2],[2.48,7.92]],"id":39100893}],"con":true,"img":false}]}
{"op":"mcm","clk":"11540788273","pt":1719498386761,"mc":[{"id":"1.230178313","rc":[{"atb":[[2.88,0]],"id":70681331}],"con":true,"img":false}]}
{"op":"mcm","clk":"11540788282","pt":1719498386867,"mc":[{"id":"1.230178313","rc":[{"atb":[[2.9,2]],"id":70681331},{"atb":[[2.44,0]],"id":39100893},{"atb":[[2.38,13.81]],"id":51441055}],"con":true,"img":false}]}
{"op":"mcm","clk":"11540788287","pt":1719498386967,"mc":[{"id":"1.230178313","rc":[{"atb":[[2.94,1.94]],"id":70681331},{"atb":[[2.2,0]],"id":52951653},{"atb":[[2.42,1.94]],"id":51441055}],"con":true,"img":false}]}
{"op":"mcm","clk":"11540788292","pt":1719498387072,"mc":[{"id":"1.230178313","rc":[{"atb":[[2.26,2]],"id":52951653}],"con":true,"img":false}]}
{"op":"mcm","clk":"11540788300","pt":1719498387175,"mc":[{"id":"1.230178313","rc":[{"atb":[[2.64,9.44],[2.94,0]],"id":68462283},{"atb":[[1.89,0],[1.98,2.5],[1.93,0],[1.97,0]],"id":52951653}],"con":true,"img":false}]}
{"op":"mcm","clk":"11540788308","pt":1719498387238,"mc":[{"id":"1.230178313","rc":[{"atb":[[2.8,9.44],[2.64,0]],"id":68462283},{"atb":[[2.9,0]],"id":70681331},{"atb":[[2.14,3.37]],"id":52951653}],"con":true,"img":false}]}
{"op":"mcm","clk":"11540788315","pt":1719498387343,"mc":[{"id":"1.230178313","rc":[{"atb":[[2.52,0],[2.6,0],[2.44,10],[2.62,2.5],[2.94,3.94]],"id":70681331}],"con":true,"img":false}]}
{"op":"mcm","clk":"11540788328","pt":1719498387541,"mc":[{"id":"1.230178313","rc":[{"atl":[[4.2,6.37]],"id":52951653}],"con":true,"img":false}]}
{"op":"mcm","clk":"11540788337","pt":1719498387655,"mc":[{"id":"1.230178313","rc":[{"atl":[[4.6,1],[4.1,18.46]],"id":52951653}],"con":true,"img":false}]}
{"op":"mcm","clk":"11540788351","pt":1719498387847,"mc":[{"id":"1.230178313","rc":[{"atb":[[2.14,0]],"id":52951653}],"con":true,"img":false}]}
{"op":"mcm","clk":"11540788401","pt":1719498388571,"mc":[{"id":"1.230178313","rc":[{"atl":[[5.8,0],[5.5,1],[5.7,1]],"id":70681331},{"atl":[[4.3,1],[4.6,0]],"id":52951653},{"atl":[[4.4,1]],"id":39100893}],"con":true,"img":false}]}
{"op":"mcm","clk":"11540788409","pt":1719498388674,"mc":[{"id":"1.230178313","rc":[{"atb":[[2.54,5.96]],"id":56913144},{"atl":[[6.4,2.5],[5.5,5.84],[5.7,13.9]],"id":70681331},{"atl":[[4.6,7.88],[4.9,2.5]],"id":39100893},{"atl":[[4.2,1]],"id":52951653}],"con":true,"img":false}]}
{"op":"mcm","clk":"11540788415","pt":1719498388779,"mc":[{"id":"1.230178313","rc":[{"atb":[[1.89,5],[2.44,0],[2.02,0]],"id":56913144},{"atl":[[4.2,20.63],[3.65,0]],"id":56913144},{"atb":[[2.68,8.67]],"id":68462283},{"atl":[[5.6,0.84],[5.7,12.9]],"id":70681331},{"atb":[[1.83,0],[1.98,0],[2.16,0]],"id":52951653},{"atl":[[4.3,0]],"id":52951653},{"atb":[[2.08,0],[1.97,9.62]],"id":39100893},{"atb":[[2,8.5]],"id":51441055}],"con":true,"img":false}]}
{"op":"mcm","clk":"11540788425","pt":1719498388847,"mc":[{"id":"1.230178313","rc":[{"atb":[[2.18,11.92]],"id":56913144},{"atb":[[2.8,0],[2.88,8.67],[2.68,0]],"id":68462283},{"atb":[[2.18,6.62]],"id":39100893},{"atb":[[1.55,8.56]],"id":52951653},{"atl":[[4.1,0],[4.2,28.69]],"id":52951653},{"atb":[[2.16,0]],"id":51441055}],"con":true,"img":false}]}
{"op":"mcm","clk":"11540788434","pt":1719498388949,"mc":[{"id":"1.230178313","rc":[{"atb":[[2.56,0],[1.89,0]],"id":56913144},{"atl":[[6.8,2.53]],"id":68462283},{"atl":[[4.2,30.68]],"id":52951653},{"atb":[[1.97,0]],"id":39100893}],"con":true,"img":false}]}
{"op":"mcm","clk":"11540788444","pt":1719498389049,"mc":[{"id":"1.230178313","rc":[{"atl":[[7.2,0],[6.6,4.29]],"id":68462283}],"con":true,"img":false}]}
{"op":"mcm","clk":"11540788452","pt":1719498389154,"mc":[{"id":"1.230178313","rc":[{"atl":[[5.4,0.84]],"id":70681331},{"atl":[[4.2,28.69]],"id":52951653}],"con":true,"img":false}]}
{"op":"mcm","clk":"11540788460","pt":1719498389245,"mc":[{"id":"1.230178313","rc":[{"atl":[[4.6,27.78],[4.2,1]],"id":52951653}],"con":true,"img":false}]}
{"op":"mcm","clk":"11540788468","pt":1719498389349,"mc":[{"id":"1.230178313","rc":[{"atl":[[3.6,8.21]],"id":52951653}],"con":true,"img":false}]}
{"op":"mcm","clk":"11540788476","pt":1719498389452,"mc":[{"id":"1.230178313","rc":[{"atl":[[4.7,2.5]],"id":52951653},{"atb":[[2.26,5],[2.34,2.5]],"id":39100893},{"atl":[[4,0],[5.1,3.5],[5.3,0],[3.9,22.39]],"id":51441055}],"con":true,"img":false}]}
{"op":"mcm","clk":"11540788486","pt":1719498389554,"mc":[{"id":"1.230178313","rc":[{"atb":[[2.04,5.31],[2.12,1.6],[2.2,2.11]],"id":39100893},{"atl":[[4.8,0],[3.85,0.84],[3.55,0.84]],"id":52951653}],"con":true,"img":false}]}
{"op":"mcm","clk":"11540788493","pt":1719498389658,"mc":[{"id":"1.230178313","rc":[{"atb":[[2.92,7.8],[2.94,14.66]],"id":70681331},{"atl":[[5.4,5.98]],"id":70681331},{"atb":[[2.48,5.92]],"id":39100893},{"atb":[[2.24,4.06]],"id":52951653},{"atl":[[3.85,0]],"id":52951653},{"atb":[[2.4,1.49]],"id":51441055}],"con":true,"img":false}]}
{"op":"mcm","clk":"11540788504","pt":1719498389761,"mc":[{"id":"1.230178313","rc":[{"atb":[[2.96,3]],"id":70681331},{"atl":[[5.3,5.84],[5.7,0]],"id":70681331},{"atb":[[2.26,5]],"id":52951653},{"atb":[[2.5,4.4],[2.46,0]],"id":39100893},{"atb":[[2.42,3.1]],"id":51441055}],"con":true,"img":false}]}
{"op":"mcm","clk":"11540788521","pt":1719498389970,"mc":[{"id":"1.230178313","rc":[{"atb":[[2.5,6.34]],"id":39100893},{"atb":[[2.42,5.04]],"id":51441055}],"con":true,"img":false}]}
{"op":"mcm","clk":"11540788537","pt":1719498390177,"mc":[{"id":"1.230178313","rc":[{"atl":[[5.6,0]],"id":70681331}],"con":true,"img":false}]}
{"op":"mcm","clk":"11540788545","pt":1719498390237,"mc":[{"id":"1.230178313","rc":[{"atb":[[2.96,4.61],[2.94,3.94]],"id":70681331},{"atl":[[5.4,0.84]],"id":70681331}],"con":true,"img":false}]}
{"op":"mcm","clk":"11540788554","pt":1719498390345,"mc":[{"id":"1.230178313","rc":[{"atl":[[5.3,0],[5.5,12.53]],"id":70681331},{"atb":[[2.4,0]],"id":51441055}],"con":true,"img":false}]}
{"op":"mcm","clk":"11540788591","pt":1719498390762,"mc":[{"id":"1.230178313","rc":[{"atb":[[2.94,1.94]],"id":70681331}],"con":true,"img":false}]}
{"op":"mcm","clk":"11540788602","pt":1719498390852,"mc":[{"id":"1.230178313","rc":[{"atb":[[2.46,14.38]],"id":56913144},{"atb":[[2.98,2],[2.96,3]],"id":70681331},{"atl":[[6.4,15.88],[5.5,5.84]],"id":70681331}],"con":true,"img":false}]}
{"op":"mcm","clk":"11540788609","pt":1719498390964,"mc":[{"id":"1.230178313","rc":[{"atb":[[2.98,14.32]],"id":70681331},{"atl":[[5.4,6.2]],"id":70681331}],"con":true,"img":false}]}
{"op":"mcm","clk":"11540788623","pt":1719498391166,"mc":[{"id":"1.230178313","rc":[{"atl":[[6.4,2.5],[5.3,6.21]],"id":70681331}],"con":true,"img":false}]}
{"op":"mcm","clk":"11540788637","pt":1719498391266,"mc":[{"id":"1.230178313","rc":[{"atb":[[2.46,3.68]],"id":39100893}],"con":true,"img":false}]}
{"op":"mcm","clk":"11540788652","pt":1719498391473,"mc":[{"id":"1.230178313","rc":[{"atb":[[2.98,10.12]],"id":68462283},{"atb":[[3,1.61]],"id":70681331}],"con":true,"img":false}]}
{"op":"mcm","clk":"11540788664","pt":1719498391577,"mc":[{"id":"1.230178313","rc":[{"atb":[[2.96,0]],"id":68462283}],"con":true,"img":false}]}
{"op":"mcm","clk":"11540788697","pt":1719498391842,"mc":[{"id":"1.230178313","rc":[{"atb":[[2.98,2]],"id":70681331},{"atl":[[5.4,6.12]],"id":70681331}],"con":true,"img":false}]}
{"op":"mcm","clk":"11540788706","pt":1719498391951,"mc":[{"id":"1.230178313","rc":[{"atb":[[2.72,17.34],[2.88,0]],"id":68462283},{"atb":[[2.72,6],[2.44,0]],"id":70681331},{"atb":[[2.3,9.6]],"id":39100893},{"atb":[[1.63,8.56],[1.81,5],[1.55,0],[1.85,2.5]],"id":52951653},{"atb":[[2.1,20]],"id":51441055}],"con":true,"img":false}]}
{"op":"mcm","clk":"11540788717","pt":1719498392057,"mc":[{"id":"1.230178313","rc":[{"atb":[[2.72,0]],"id":68462283},{"atb":[[3,0]],"id":70681331},{"atb":[[2.18,0]],"id":39100893},{"atb":[[2,0]],"id":51441055}],"con":true,"img":false}]}
{"op":"mcm","clk":"11540788728","pt":1719498392162,"mc":[{"id":"1.230178313","rc":[{"atb":[[3,10.13]],"id":68462283}],"con":true,"img":false}]}
{"op":"mcm","clk":"11540788738","pt":1719498392267,"mc":[{"id":"1.230178313","rc":[{"atb":[[3,15.81]],"id":68462283}],"con":true,"img":false}]}
{"op":"mcm","clk":"11540788762","pt":1719498392471,"mc":[{"id":"1.230178313","rc":[{"atb":[[2.98,3.94]],"id":68462283}],"con":true,"img":false}]}
{"op":"mcm","clk":"11540788783","pt":1719498392678,"mc":[{"id":"1.230178313","rc":[{"atb":[[3.05,1.61]],"id":68462283}],"con":true,"img":false}]}
{"op":"mcm","clk":"11540788790","pt":1719498392782,"mc":[{"id":"1.230178313","rc":[{"atb":[[2.98,2],[3.05,7.04]],"id":68462283},{"atb":[[2.94,0]],"id":70681331},{"atl":[[5.4,0.84]],"id":70681331},{"atb":[[2.24,2.11]],"id":52951653}],"con":true,"img":false}]}
{"op":"mcm","clk":"11540788802","pt":1719498392844,"mc":[{"id":"1.230178313","rc":[{"atl":[[5.3,11.49]],"id":70681331}],"con":true,"img":false}]}
{"op":"mcm","clk":"11540788812","pt":1719498392947,"mc":[{"id":"1.230178313","rc":[{"atb":[[3,10.13]],"id":68462283},{"atb":[[2.98,3.94]],"id":70681331},{"atl":[[5.3,5.28],[5.5,12.9]],"id":70681331},{"atb":[[2.28,1.94]],"id":52951653}],"con":true,"img":false}]}
{"op":"mcm","clk":"11540788826","pt":1719498393152,"mc":[{"id":"1.230178313","rc":[{"atl":[[7.4,0]],"id":68462283}],"con":true,"img":false}]}
{"op":"mcm","clk":"11540788849","pt":1719498393465,"mc":[{"id":"1.230178313","rc":[{"atl":[[5.8,1],[5.5,11.9]],"id":70681331},{"atb":[[2.42,19.18]],"id":51441055}],"con":true,"img":false}]}
{"op":"mcm","clk":"11540788863","pt":1719498393578,"mc":[{"id":"1.230178313","rc":[{"atb":[[2.98,16.95]],"id":70681331},{"atl":[[5.2,5.28]],"id":70681331},{"atb":[[2.38,0]],"id":51441055}],"con":true,"img":false}]}
{"op":"mcm","clk":"11540788872","pt":1719498393688,"mc":[{"id":"1.230178313","rc":[{"atl":[[5.5,4.84]],"id":70681331},{"atl":[[3.85,24.75]],"id":51441055}],"con":true,"img":false}]}
{"op":"mcm","clk":"11540788886","pt":1719498393856,"mc":[{"id":"1.230178313","rc":[{"atb":[[2.44,1.49]],"id":51441055},{"atl":[[3.95,0]],"id":51441055}],"con":true,"img":false}]}
{"op":"mcm","clk":"11540788900","pt":1719498394054,"mc":[{"id":"1.230178313","rc":[{"atl":[[5.4,0]],"id":70681331},{"atl":[[3.8,0.84]],"id":51441055}],"con":true,"img":false}]}
{"op":"mcm","clk":"11540788914","pt":1719498394250,"mc":[{"id":"1.230178313","rc":[{"atl":[[3.9,21.11]],"id":51441055}],"con":true,"img":false}]}
{"op":"mcm","clk":"11540788919","pt":1719498394354,"mc":[{"id":"1.230178313","rc":[{"atb":[[2.48,3.69]],"id":56913144},{"atl":[[4.6,0],[4.2,10.06]],"id":52951653},{"atl":[[3.8,2.12]],"id":51441055}],"con":true,"img":false}]}
{"op":"mcm","clk":"11540788930","pt":1719498394459,"mc":[{"id":"1.230178313","rc":[{"atl":[[5.3,0]],"id":70681331}],"con":true,"img":false}]}
{"op":"mcm","clk":"11540788941","pt":1719498394564,"mc":[{"id":"1.230178313","rc":[{"atl":[[3.8,23.24],[3.9,0.84]],"id":51441055}],"con":true,"img":false}]}
{"op":"mcm","clk":"11540788948","pt":1719498394669,"mc":[{"id":"1.230178313","rc":[{"atl":[[3.9,0]],"id":51441055}],"con":true,"img":false}]}
{"op":"mcm","clk":"11540788975","pt":1719498394978,"mc":[{"id":"1.230178313","rc":[{"atb":[[1.04,0.52]],"id":56913144}],"con":true,"img":false}]}
{"op":"mcm","clk":"11540788991","pt":1719498395143,"mc":[{"id":"1.230178313","rc":[{"atb":[[1.04,0.33]],"id":56913144},{"atl":[[5.2,10.51]],"id":70681331}],"con":true,"img":false}]}
{"op":"mcm","clk":"11540789002","pt":1719498395345,"mc":[{"id":"1.230178313","rc":[{"atb":[[1.04,0]],"id":56913144}],"con":true,"img":false}]}
{"op":"mcm","clk":"11540789009","pt":1719498395445,"mc":[{"id":"1.230178313","rc":[{"atb":[[2.56,0.33]],"id":56913144},{"atb":[[2.98,0]],"id":68462283},{"atb":[[2.96,0]],"id":70681331},{"atb":[[2.26,2]],"id":52951653},{"atb":[[2.42,16.08]],"id":51441055}],"con":true,"img":false}]}
{"op":"mcm","clk":"11540789027","pt":1719498395652,"mc":[{"id":"1.230178313","rc":[{"atb":[[3,2.79]],"id":70681331},{"atb":[[2.28,4.96]],"id":52951653},{"atb":[[2.44,4.09]],"id":51441055}],"con":true,"img":false}]}
{"op":"mcm","clk":"11540789045","pt":1719498395858,"mc":[{"id":"1.230178313","rc":[{"atb":[[2.32,3]],"id":51441055}],"con":true,"img":false}]}
{"op":"mcm","clk":"11540789056","pt":1719498395959,"mc":[{"id":"1.230178313","rc":[{"atb":[[2.98,15.01]],"id":70681331},{"atb":[[2.42,14.14]],"id":51441055}],"con":true,"img":false}]}
{"op":"mcm","clk":"11540789062","pt":1719498396064,"mc":[{"id":"1.230178313","rc":[{"atb":[[2.98,14.88]],"id":70681331},{"atb":[[2.46,1.94]],"id":51441055}],"con":true,"img":false}]}
{"op":"mcm","clk":"11540789071","pt":1719498396168,"mc":[{"id":"1.230178313","rc":[{"atl":[[5.1,0.84]],"id":70681331}],"con":true,"img":false}]}
{"op":"mcm","clk":"11540789087","pt":1719498396375,"mc":[{"id":"1.230178313","rc":[{"atb":[[3,12.27]],"id":70681331},{"atb":[[2.46,0]],"id":39100893}],"con":true,"img":false}]}
{"op":"mcm","clk":"11540789096","pt":1719498396478,"mc":[{"id":"1.230178313","rc":[{"atb":[[2.98,2]],"id":70681331},{"atb":[[2.5,13.74]],"id":39100893},{"atb":[[2.32,0]],"id":51441055}],"con":true,"img":false}]}
{"op":"mcm","clk":"11540789105","pt":1719498396541,"mc":[{"id":"1.230178313","rc":[{"atb":[[2.92,0],[3,25.15]],"id":70681331},{"atb":[[2.48,0]],"id":39100893},{"atb":[[2.26,0]],"id":52951653}],"con":true,"img":false}]}
{"op":"mcm","clk":"11540789115","pt":1719498396652,"mc":[{"id":"1.230178313","rc":[{"atb":[[2.3,2]],"id":52951653}],"con":true,"img":false}]}
{"op":"mcm","clk":"11540789129","pt":1719498396891,"mc":[{"id":"1.230178313","rc":[{"atb":[[3.05,1.61]],"id":70681331}],"con":true,"img":false}]}
{"op":"mcm","clk":"11540789143","pt":1719498397050,"mc":[{"id":"1.230178313","rc":[{"atb":[[2.98,0]],"id":70681331}],"con":true,"img":false}]}
{"op":"mcm","clk":"11540789155","pt":1719498397154,"mc":[{"id":"1.230178313","rc":[{"atb":[[3.05,3.61]],"id":70681331}],"con":true,"img":false}]}
{"op":"mcm","clk":"11540789182","pt":1719498397464,"mc":[{"id":"1.230178313","rc":[{"atb":[[3,24.76]],"id":70681331},{"atl":[[4.3,1],[4.4,0]],"id":39100893}],"con":true,"img":false}]}
{"op":"mcm","clk":"11540789190","pt":1719498397567,"mc":[{"id":"1.230178313","rc":[{"atb":[[3.05,2]],"id":70681331},{"atb":[[1.78,0]],"id":52951653}],"con":true,"img":false}]}
{"op":"mcm","clk":"11540789197","pt":1719498397672,"mc":[{"id":"1.230178313","rc":[{"atb":[[3,12.27]],"id":70681331}],"con":true,"img":false}]}
{"op":"mcm","clk":"11540789207","pt":1719498397776,"mc":[{"id":"1.230178313","rc":[{"atb":[[3.05,14.49]],"id":70681331}],"con":true,"img":false}]}
{"op":"mcm","clk":"11540789235","pt":1719498398044,"mc":[{"id":"1.230178313","rc":[{"atb":[[3.1,1.61]],"id":70681331}],"con":true,"img":false}]}
{"op":"mcm","clk":"11540789258","pt":1719498398359,"mc":[{"id":"1.230178313","rc":[{"atb":[[2.14,0]],"id":56913144},{"atl":[[5.1,12.35]],"id":70681331}],"con":true,"img":false}]}
{"op":"mcm","clk":"11540789276","pt":1719498398561,"mc":[{"id":"1.230178313","rc":[{"atl":[[6.8,0]],"id":68462283},{"atl":[[5.5,0]],"id":70681331}],"con":true,"img":false}]}
{"op":"mcm","clk":"11540789285","pt":1719498398662,"mc":[{"id":"1.230178313","rc":[{"atl":[[8,5],[7.2,2.5],[8.8,10]],"id":68462283}],"con":true,"img":false}]}
{"op":"mcm","clk":"11540789307","pt":1719498398869,"mc":[{"id":"1.230178313","rc":[{"atl":[[5.6,4.62]],"id":68462283}],"con":true,"img":false}]}
{"op":"mcm","clk":"11540789318","pt":1719498398972,"mc":[{"id":"1.230178313","rc":[{"atl":[[6.2,7.91],[5.5,5.93],[6.6,0]],"id":68462283},{"atl":[[1000,0.17]],"id":70681331},{"atb":[[2.46,0]],"id":51441055}],"con":true,"img":false}]}
{"op":"mcm","clk":"11540789329","pt":1719498399076,"mc":[{"id":"1.230178313","rc":[{"atl":[[5,1.27],[5.2,5.28]],"id":70681331},{"atl":[[3.55,6.16]],"id":52951653}],"con":true,"img":false}]}
{"op":"mcm","clk":"11540789336","pt":1719498399180,"mc":[{"id":"1.230178313","rc":[{"atl":[[5.5,6.77],[6,0]],"id":68462283},{"atl":[[5.1,17.63]],"id":70681331},{"atl":[[3.6,0]],"id":52951653},{"atb":[[2.46,1.94]],"id":51441055}],"con":true,"img":false}]}
{"op":"mcm","clk":"11540789345","pt":1719498399285,"mc":[{"id":"1.230178313","rc":[{"atb":[[3.05,5.43]],"id":68462283},{"atl":[[5.2,0]],"id":70681331}],"con":true,"img":false}]}
{"op":"mcm","clk":"11540789356","pt":1719498399346,"mc":[{"id":"1.230178313","rc":[{"atb":[[3,0],[3.05,17.5]],"id":68462283}],"con":true,"img":false}]}
{"op":"mcm","clk":"11540789366","pt":1719498399451,"mc":[{"id":"1.230178313","rc":[{"atb":[[2.4,1],[2.74,18.06],[2.32,0]],"id":68462283}],"con":true,"img":false}]}
{"op":"mcm","clk":"11540789375","pt":1719498399567,"mc":[{"id":"1.230178313","rc":[{"atb":[[2.74,2.5],[3,35]],"id":68462283},{"atl":[[5,0]],"id":70681331}],"con":true,"img":false}]}
{"op":"mcm","clk":"11540789383","pt":1719498399661,"mc":[{"id":"1.230178313","rc":[{"atl":[[5.6,0]],"id":68462283},{"atl":[[5.1,12.35],[6.4,21.02]],"id":70681331}],"con":true,"img":false}]}
{"op":"mcm","clk":"11540789401","pt":1719498399883,"mc":[{"id":"1.230178313","rc":[{"atb":[[3.1,1.61],[2.4,0]],"id":68462283},{"atl":[[6.4,0],[6.2,8.91],[5.4,5.89]],"id":68462283},{"atl":[[4.5,1],[4.2,9.06]],"id":52951653},{"atl":[[4.3,0],[4.5,1]],"id":39100893}],"con":true,"img":false}]}
{"op":"mcm","clk":"11540789411","pt":1719498399967,"mc":[{"id":"1.230178313","rc":[{"atb":[[3.1,13.38]],"id":68462283}],"con":true,"img":false}]}
{"op":"mcm","clk":"11540789422","pt":1719498400069,"mc":[{"id":"1.230178313","rc":[{"atb":[[3.05,12.07]],"id":68462283}],"con":true,"img":false}]}
{"op":"mcm","clk":"11540789495","pt":1719498400755,"mc":[{"id":"1.230178313","rc":[{"atl":[[6.4,1]],"id":68462283},{"atb":[[2.1,0]],"id":39100893},{"atl":[[4.3,1]],"id":39100893}],"con":true,"img":false}]}
{"op":"mcm","clk":"11540789505","pt":1719498400864,"mc":[{"id":"1.230178313","rc":[{"atb":[[3.05,11.63]],"id":68462283},{"atl":[[6.2,7.91]],"id":68462283},{"atl":[[4.5,0]],"id":39100893}],"con":true,"img":false}]}
{"op":"mcm","clk":"11540789516","pt":1719498400964,"mc":[{"id":"1.230178313","rc":[{"atl":[[5.4,10.75]],"id":68462283},{"atl":[[4.5,0],[4.2,10.06]],"id":52951653}],"con":true,"img":false}]}
{"op":"mcm","clk":"11540789534","pt":1719498401171,"mc":[{"id":"1.230178313","rc":[{"atb":[[3.05,0]],"id":68462283}],"con":true,"img":false}]}
{"op":"mcm","clk":"11540789542","pt":1719498401270,"mc":[{"id":"1.230178313","rc":[{"atb":[[3.1,25.01]],"id":68462283},{"atb":[[3,9.48]],"id":70681331},{"atb":[[2.28,1.94]],"id":52951653},{"atb":[[2.5,11.34]],"id":39100893},{"atb":[[2.44,1.49]],"id":51441055}],"con":true,"img":false}]}
{"op":"mcm","clk":"11540789552","pt":1719498401372,"mc":[{"id":"1.230178313","rc":[{"atl":[[1000,0]],"id":68462283},{"atb":[[3.1,3.81]],"id":70681331},{"atb":[[2.3,5.86]],"id":52951653},{"atb":[[2.52,3.85]],"id":39100893},{"atb":[[2.46,4.94]],"id":51441055}],"con":true,"img":false}]}
{"op":"mcm","clk":"11540789562","pt":1719498401474,"mc":[{"id":"1.230178313","rc":[{"atl":[[5.3,1.33]],"id":68462283}],"con":true,"img":false}]}
{"op":"mcm","clk":"11540789575","pt":1719498401578,"mc":[{"id":"1.230178313","rc":[{"atl":[[5.6,3]],"id":68462283}],"con":true,"img":false}]}
{"op":"mcm","clk":"11540789600","pt":1719498401787,"mc":[{"id":"1.230178313","rc":[{"atb":[[2.44,0]],"id":51441055}],"con":true,"img":false}]}
{"op":"mcm","clk":"11540789619","pt":1719498401950,"mc":[{"id":"1.230178313","rc":[{"atl":[[5.6,0]],"id":68462283}],"con":true,"img":false}]}
{"op":"mcm","clk":"11540789629","pt":1719498402055,"mc":[{"id":"1.230178313","rc":[{"atb":[[2.5,9.4]],"id":39100893},{"atb":[[2.3,3.86],[2.28,0]],"id":52951653}],"con":true,"img":false}]}
{"op":"mcm","clk":"11540789639","pt":1719498402200,"mc":[{"id":"1.230178313","rc":[{"atb":[[2.26,2]],"id":52951653},{"atb":[[2.54,1.94]],"id":39100893}],"con":true,"img":false}]}
{"op":"mcm","clk":"11540789647","pt":1719498402268,"mc":[{"id":"1.230178313","rc":[{"atl":[[5.4,10.56]],"id":68462283},{"atb":[[3.05,12.07]],"id":70681331},{"atb":[[2.4,3.76]],"id":51441055}],"con":true,"img":false}]}
{"op":"mcm","clk":"11540789687","pt":1719498402675,"mc":[{"id":"1.230178313","rc":[{"atl":[[6.4,0],[6.2,8.91],[5.3,0],[5.4,5.89]],"id":68462283},{"atb":[[3.05,2]],"id":70681331},{"atl":[[4.3,0],[4.5,1]],"id":39100893},{"atl":[[4.5,1],[4.2,9.06]],"id":52951653}],"con":true,"img":false}]}
{"op":"mcm","clk":"11540789697","pt":1719498402775,"mc":[{"id":"1.230178313","rc":[{"atl":[[5.3,4.67]],"id":68462283},{"atb":[[3.1,13.88]],"id":70681331},{"atb":[[2.5,7.4]],"id":39100893}],"con":true,"img":false}]}
{"op":"mcm","clk":"11540789709","pt":1719498402879,"mc":[{"id":"1.230178313","rc":[{"atb":[[2.98,3.25]],"id":68462283},{"atb":[[3.1,12.27]],"id":70681331},{"atb":[[2.54,3.94]],"id":39100893}],"con":true,"img":false}]}
{"op":"mcm","clk":"11540789735","pt":1719498403191,"mc":[{"id":"1.230178313","rc":[{"atl":[[6.4,1],[5.5,5.93]],"id":68462283},{"atl":[[4.5,0]],"id":39100893},{"atb":[[2.26,0]],"id":52951653},{"atl":[[4.5,0]],"id":52951653},{"atb":[[2.46,19.26]],"id":51441055}],"con":true,"img":false}]}
{"op":"mcm","clk":"11540789744","pt":1719498403252,"mc":[{"id":"1.230178313","rc":[{"atl":[[6.2,7.91]],"id":68462283},{"atb":[[3.1,2.2]],"id":70681331},{"atl":[[4.3,1]],"id":39100893},{"atl":[[4.2,10.06]],"id":52951653}],"con":true,"img":false}]}
{"op":"mcm","clk":"11540789753","pt":1719498403359,"mc":[{"id":"1.230178313","rc":[{"atb":[[2.32,2]],"id":52951653},{"atl":[[4.6,0],[4.9,14.32]],"id":39100893},{"atb":[[2.42,0]],"id":51441055},{"atl":[[3.75,25.06]],"id":51441055}],"con":true,"img":false}]}
{"op":"mcm","clk":"11540789758","pt":1719498403462,"mc":[{"id":"1.230178313","rc":[{"atb":[[2.48,1.49]],"id":51441055}],"con":true,"img":false}]}
{"op":"mcm","clk":"11540789770","pt":1719498403567,"mc":[{"id":"1.230178313","rc":[{"atl":[[6.4,0],[6.2,8.91]],"id":68462283},{"atb":[[3.05,0]],"id":70681331},{"atl":[[4.3,0],[4.5,1]],"id":39100893},{"atl":[[4.5,1],[4.2,9.06]],"id":52951653},{"atl":[[3.85,0],[3.7,0.84]],"id":51441055}],"con":true,"img":false}]}
{"op":"mcm","clk":"11540789781","pt":1719498403674,"mc":[{"id":"1.230178313","rc":[{"atb":[[2.98,0]],"id":68462283},{"atb":[[3.15,2]],"id":70681331}],"con":true,"img":false}]}
{"op":"mcm","clk":"11540789792","pt":1719498403776,"mc":[{"id":"1.230178313","rc":[{"atb":[[3.1,14.06]],"id":70681331},{"atl":[[3.8,21.96]],"id":51441055}],"con":true,"img":false}]}
{"op":"mcm","clk":"11540789798","pt":1719498403867,"mc":[{"id":"1.230178313","rc":[{"atb":[[2.9,52.63],[3,0]],"id":68462283},{"atb":[[2.4,0]],"id":51441055},{"atl":[[3.7,2.12]],"id":51441055}],"con":true,"img":false}]}
{"op":"mcm","clk":"11540789806","pt":1719498403974,"mc":[{"id":"1.230178313","rc":[{"atl":[[3.8,0.84]],"id":51441055}],"con":true,"img":false}]}
{"op":"mcm","clk":"11540789817","pt":1719498404075,"mc":[{"id":"1.230178313","rc":[{"atb":[[3.1,23.4]],"id":68462283},{"atb":[[3.15,3.61]],"id":70681331},{"atl":[[3.7,24.09]],"id":51441055}],"con":true,"img":false}]}
{"op":"mcm","clk":"11540789825","pt":1719498404178,"mc":[{"id":"1.230178313","rc":[{"atl":[[3.7,2.12],[3.8,28.03]],"id":51441055}],"con":true,"img":false}]}
{"op":"mcm","clk":"11540789833","pt":1719498404281,"mc":[{"id":"1.230178313","rc":[{"atl":[[3.8,27.19]],"id":51441055}],"con":true,"img":false}]}
{"op":"mcm","clk":"11540789840","pt":1719498404386,"mc":[{"id":"1.230178313","rc":[{"atl":[[3.7,27.18],[3.8,0]],"id":51441055}],"con":true,"img":false}]}
{"op":"mcm","clk":"11540789868","pt":1719498404656,"mc":[{"id":"1.230178313","rc":[{"atb":[[3.1,11.77]],"id":68462283}],"con":true,"img":false}]}
{"op":"mcm","clk":"11540789885","pt":1719498404866,"mc":[{"id":"1.230178313","rc":[{"atb":[[3.1,0]],"id":68462283}],"con":true,"img":false}]}
{"op":"mcm","clk":"11540789894","pt":1719498404971,"mc":[{"id":"1.230178313","rc":[{"atb":[[3.05,8.86]],"id":68462283}],"con":true,"img":false}]}
{"op":"mcm","clk":"11540789982","pt":1719498405958,"mc":[{"id":"1.230178313","rc":[{"atb":[[3.15,19.99]],"id":70681331}],"con":true,"img":false}]}
{"op":"mcm","clk":"11540789991","pt":1719498406054,"mc":[{"id":"1.230178313","rc":[{"atl":[[5.2,0.84]],"id":68462283},{"atb":[[3,0]],"id":70681331},{"atb":[[2.54,9.86]],"id":39100893}],"con":true,"img":false}]}
{"op":"mcm","clk":"11540790000","pt":1719498406163,"mc":[{"id":"1.230178313","rc":[{"atb":[[2.32,1]],"id":68462283},{"atl":[[6.4,1],[6.2,7.91]],"id":68462283},{"atl":[[5.8,0],[5.7,1]],"id":70681331}],"con":true,"img":false}]}
{"op":"mcm","clk":"11540790005","pt":1719498406264,"mc":[{"id":"1.230178313","rc":[{"atl":[[6.4,2.5],[5.8,20.83]],"id":70681331},{"atb":[[2.5,0]],"id":39100893},{"atb":[[1.92,0]],"id":51441055}],"con":true,"img":false}]}
{"op":"mcm","clk":"11540790062","pt":1719498406981,"mc":[{"id":"1.230178313","rc":[{"atb":[[3.1,11.86]],"id":70681331},{"atb":[[2.52,0]],"id":39100893},{"atb":[[2.3,0]],"id":52951653},{"atb":[[2.46,16.26]],"id":51441055}],"con":true,"img":false}]}
{"op":"mcm","clk":"11540790069","pt":1719498407084,"mc":[{"id":"1.230178313","rc":[{"atb":[[3.2,3.8]],"id":70681331},{"atb":[[2.56,2.94]],"id":39100893},{"atb":[[2.32,4.6]],"id":52951653},{"atb":[[2.48,5.09]],"id":51441055}],"con":true,"img":false}]}
{"op":"mcm","clk":"11540790148","pt":1719498407973,"mc":[{"id":"1.230178313","rc":[{"atb":[[2.54,7.86]],"id":39100893}],"con":true,"img":false}]}
{"op":"mcm","clk":"11540790158","pt":1719498408075,"mc":[{"id":"1.230178313","rc":[{"atb":[[2.54,5.92],[1.02,2]],"id":39100893},{"atb":[[2.46,14.32]],"id":51441055}],"con":true,"img":false}]}
{"op":"mcm","clk":"11540790167","pt":1719498408180,"mc":[{"id":"1.230178313","rc":[{"atb":[[2.74,59.97]],"id":68462283}],"con":true,"img":false}]}
{"op":"mcm","clk":"11540790175","pt":1719498408281,"mc":[{"id":"1.230178313","rc":[{"atb":[[2.9,0]],"id":68462283},{"atb":[[2.58,1.94]],"id":39100893},{"atb":[[2.5,1.94],[2.48,3.6]],"id":51441055}],"con":true,"img":false}]}
{"op":"mcm","clk":"11540790190","pt":1719498408490,"mc":[{"id":"1.230178313","rc":[{"atb":[[3.15,17.99]],"id":70681331}],"con":true,"img":false}]}
{"op":"mcm","clk":"11540790198","pt":1719498408551,"mc":[{"id":"1.230178313","rc":[{"atl":[[5.2,9.01]],"id":68462283},{"atb":[[1.02,2]],"id":70681331}],"con":true,"img":false}]}
{"op":"mcm","clk":"11540790204","pt":1719498408661,"mc":[{"id":"1.230178313","rc":[{"atl":[[5.3,0],[5.5,0]],"id":68462283}],"con":true,"img":false}]}
{"op":"mcm","clk":"11540790216","pt":1719498408773,"mc":[{"id":"1.230178313","rc":[{"atb":[[2.52,3.54]],"id":39100893}],"con":true,"img":false}]}
{"op":"mcm","clk":"11540790223","pt":1719498408868,"mc":[{"id":"1.230178313","rc":[{"atb":[[3.1,15.49]],"id":70681331}],"con":true,"img":false}]}
{"op":"mcm","clk":"11540790242","pt":1719498409084,"mc":[{"id":"1.230178313","rc":[{"atb":[[2.04,0]],"id":39100893}],"con":true,"img":false}]}
{"op":"mcm","clk":"11540790251","pt":1719498409187,"mc":[{"id":"1.230178313","rc":[{"atb":[[1.02,3.7]],"id":51441055},{"atl":[[1000,6.81]],"id":51441055}],"con":true,"img":false}]}
{"op":"mcm","clk":"11540790261","pt":1719498409292,"mc":[{"id":"1.230178313","rc":[{"atb":[[1.03,1.7],[1.02,5.4]],"id":51441055}],"con":true,"img":false}]}
{"op":"mcm","clk":"11540790271","pt":1719498409358,"mc":[{"id":"1.230178313","rc":[{"atb":[[1.02,3.83]],"id":51441055},{"atl":[[1000,0.28]],"id":51441055}],"con":true,"img":false}]}
{"op":"mcm","clk":"11540790289","pt":1719498409561,"mc":[{"id":"1.230178313","rc":[{"atb":[[1.03,0.11],[1.02,2.12]],"id":51441055},{"atl":[[1000,0]],"id":51441055}],"con":true,"img":false}]}
{"op":"mcm","clk":"11540790298","pt":1719498409661,"mc":[{"id":"1.230178313","rc":[{"atl":[[5.2,14.65]],"id":68462283},{"atb":[[2.52,0.13]],"id":51441055},{"atl":[[3.65,0.28]],"id":51441055}],"con":true,"img":false}]}
{"op":"mcm","clk":"11540790306","pt":1719498409766,"mc":[{"id":"1.230178313","rc":[{"atb":[[1.03,0],[1.02,2]],"id":51441055}],"con":true,"img":false}]}
{"op":"mcm","clk":"11540790312","pt":1719498409867,"mc":[{"id":"1.230178313","rc":[{"atb":[[3.1,11.86]],"id":70681331},{"atb":[[2.52,0.37]],"id":51441055}],"con":true,"img":false}]}
{"op":"mcm","clk":"11540790349","pt":1719498410378,"mc":[{"id":"1.230178313","rc":[{"atl":[[5.1,1.33]],"id":68462283},{"atb":[[2.52,17.26]],"id":51441055},{"atl":[[3.65,9.07]],"id":51441055}],"con":true,"img":false}]}
{"op":"mcm","clk":"11540790362","pt":1719498410481,"mc":[{"id":"1.230178313","rc":[{"atl":[[3.6,25.06],[3.7,2.12]],"id":51441055}],"con":true,"img":false}]}
{"op":"mcm","clk":"11540790370","pt":1719498410687,"mc":[{"id":"1.230178313","rc":[{"atb":[[2.54,1.49]],"id":51441055}],"con":true,"img":false}]}
{"op":"mcm","clk":"11540790386","pt":1719498410862,"mc":[{"id":"1.230178313","rc":[{"atb":[[2.56,0]],"id":56913144},{"atl":[[3.8,3.88]],"id":51441055}],"con":true,"img":false}]}
{"op":"mcm","clk":"11540790400","pt":1719498411055,"mc":[{"id":"1.230178313","rc":[{"atb":[[2.58,0]],"id":39100893},{"atb":[[2.5,0]],"id":51441055},{"atl":[[3.7,0],[3.8,0],[3.55,0.84]],"id":51441055}],"con":true,"img":false}]}
{"op":"mcm","clk":"11540790408","pt":1719498411164,"mc":[{"id":"1.230178313","rc":[{"atl":[[3.55,2.12]],"id":51441055}],"con":true,"img":false}]}
{"op":"mcm","clk":"11540790415","pt":1719498411269,"mc":[{"id":"1.230178313","rc":[{"atl":[[5.2,9.01]],"id":68462283},{"atb":[[2.58,1.94]],"id":39100893},{"atb":[[2.52,14.1]],"id":51441055}],"con":true,"img":false}]}
{"op":"mcm","clk":"11540790433","pt":1719498411579,"mc":[{"id":"1.230178313","rc":[{"atb":[[2.52,0.37]],"id":51441055}],"con":true,"img":false}]}
{"op":"mcm","clk":"11540790438","pt":1719498411682,"mc":[{"id":"1.230178313","rc":[{"atl":[[5.1,0]],"id":68462283},{"atb":[[2.54,15.22]],"id":51441055}],"con":true,"img":false}]}
{"op":"mcm","clk":"11540790463","pt":1719498412084,"mc":[{"id":"1.230178313","rc":[{"atl":[[3.65,8.95]],"id":51441055}],"con":true,"img":false}]}
{"op":"mcm","clk":"11540790470","pt":1719498412187,"mc":[{"id":"1.230178313","rc":[{"atl":[[3.55,4.66]],"id":51441055}],"con":true,"img":false}]}
{"op":"mcm","clk":"11540790475","pt":1719498412292,"mc":[{"id":"1.230178313","rc":[{"atb":[[2.28,11.92]],"id":56913144},{"atl":[[5.7,0],[5.9,1]],"id":70681331},{"atl":[[4.5,0],[4.7,1]],"id":39100893},{"atl":[[3.65,0.28]],"id":51441055}],"con":true,"img":false}]}
{"op":"mcm","clk":"11540790484","pt":1719498412397,"mc":[{"id":"1.230178313","rc":[{"atb":[[2.18,0]],"id":56913144},{"atl":[[6.4,0],[5.9,1]],"id":68462283},{"atl":[[4.7,11]],"id":39100893},{"atl":[[3.55,13.33]],"id":51441055}],"con":true,"img":false}]}
{"op":"mcm","clk":"11540790494","pt":1719498412474,"mc":[{"id":"1.230178313","rc":[{"atl":[[5.2,14.11]],"id":68462283},{"atl":[[4.9,2.5]],"id":39100893}],"con":true,"img":false}]}
{"op":"mcm","clk":"11540790521","pt":1719498412781,"mc":[{"id":"1.230178313","rc":[{"atl":[[5.1,1.33]],"id":68462283}],"con":true,"img":false}]}
{"op":"mcm","clk":"11540790531","pt":1719498412874,"mc":[{"id":"1.230178313","rc":[{"atb":[[2.56,0]],"id":39100893},{"atb":[[2.48,0]],"id":51441055},{"atl":[[3.5,12.71]],"id":51441055}],"con":true,"img":false}]}
{"op":"mcm","clk":"11540790537","pt":1719498412976,"mc":[{"id":"1.230178313","rc":[{"atb":[[2.58,5.94]],"id":39100893},{"atb":[[2.56,3]],"id":51441055},{"atl":[[3.75,0]],"id":51441055}],"con":true,"img":false}]}
{"op":"mcm","clk":"11540790550","pt":1719498413182,"mc":[{"id":"1.230178313","rc":[{"atb":[[2.6,2.11],[2.34,0]],"id":51441055}],"con":true,"img":false}]}
{"op":"mcm","clk":"11540790569","pt":1719498413452,"mc":[{"id":"1.230178313","rc":[{"atl":[[3.55,12.05]],"id":51441055}],"con":true,"img":false}]}
{"op":"mcm","clk":"11540790578","pt":1719498413555,"mc":[{"id":"1.230178313","rc":[{"atl":[[5.2,9.01]],"id":68462283},{"atb":[[2.54,1.49]],"id":51441055},{"atl":[[3.55,11.69]],"id":51441055}],"con":true,"img":false}]}
{"op":"mcm","clk":"11540790597","pt":1719498413765,"mc":[{"id":"1.230178313","rc":[{"atl":[[3.55,3.38]],"id":51441055}],"con":true,"img":false}]}
{"op":"mcm","clk":"11540790604","pt":1719498413870,"mc":[{"id":"1.230178313","rc":[{"atl":[[3.5,21.02]],"id":51441055}],"con":true,"img":false}]}
{"op":"mcm","clk":"11540790619","pt":1719498414075,"mc":[{"id":"1.230178313","rc":[{"atl":[[5.1,0]],"id":68462283}],"con":true,"img":false}]}
{"op":"mcm","clk":"11540790649","pt":1719498414378,"mc":[{"id":"1.230178313","rc":[{"atb":[[2.54,0]],"id":51441055}],"con":true,"img":false}]}
{"op":"mcm","clk":"11540790654","pt":1719498414481,"mc":[{"id":"1.230178313","rc":[{"atl":[[5.2,13.78]],"id":68462283},{"atb":[[2.6,15.43]],"id":51441055}],"con":true,"img":false}]}
{"op":"mcm","clk":"11540790675","pt":1719498414690,"mc":[{"id":"1.230178313","rc":[{"atl":[[3.55,0.84]],"id":51441055}],"con":true,"img":false}]}
{"op":"mcm","clk":"11540790689","pt":1719498414795,"mc":[{"id":"1.230178313","rc":[{"atb":[[2.52,0]],"id":39100893}],"con":true,"img":false}]}
{"op":"mcm","clk":"11540790702","pt":1719498414900,"mc":[{"id":"1.230178313","rc":[{"atb":[[2.62,1.49]],"id":51441055}],"con":true,"img":false}]}
{"op":"mcm","clk":"11540790716","pt":1719498415065,"mc":[{"id":"1.230178313","rc":[{"atb":[[1.04,0.52]],"id":56913144}],"con":true,"img":false}]}
{"op":"mcm","clk":"11540790736","pt":1719498415277,"mc":[{"id":"1.230178313","rc":[{"atb":[[2.6,14.92]],"id":51441055}],"con":true,"img":false}]}
