{"op":"mcm","clk":"11536832968","pt":1719431775485,"mc":[{"id":"1.230180130","marketDefinition":{"bspMarket":true,"turnInPlayEnabled":false,"persistenceEnabled":false,"marketBaseRate":5.0,"eventId":"33376437","eventTypeId":"4339","numberOfWinners":1,"bettingType":"ODDS","marketType":"WIN","marketTime":"2024-06-27T16:21:00.000Z","suspendTime":"2024-06-27T16:21:00.000Z","bspReconciled":false,"complete":true,"inPlay":false,"crossMatching":false,"runnersVoidable":false,"numberOfActiveRunners":6,"betDelay":0,"status":"OPEN","runners":[{"status":"ACTIVE","sortPriority":1,"id":66499052,"name":"1. Salacres Wild"},{"status":"ACTIVE","sortPriority":2,"id":43210435,"name":"2. Bemyangelrosa"},{"status":"ACTIVE","sortPriority":3,"id":41138102,"name":"3. Traptoline Zorro"},{"status":"ACTIVE","sortPriority":4,"id":69979297,"name":"4. Jacktavern Pele"},{"status":"ACTIVE","sortPriority":5,"id":58149406,"name":"5. Salacres Herbert"},{"status":"ACTIVE","sortPriority":6,"id":51843546,"name":"6. Salacres Maybach"}],"regulators":["MR_INT"],"venue":"Towcester","countryCode":"GB","discountAllowed":false,"timezone":"Europe/London","openDate":"2024-06-27T13:33:00.000Z","version":5994767063,"name":"D2 270m","eventName":"Towcester 27th Jun"},"rc":[],"con":true,"img":false}]}
{"op":"mcm","clk":"11536833113","pt":1719431777487,"mc":[{"id":"1.230180130","marketDefinition":{"bspMarket":true,"turnInPlayEnabled":false,"persistenceEnabled":false,"marketBaseRate":5.0,"eventId":"33376437","eventTypeId":"4339","numberOfWinners":1,"bettingType":"ODDS","marketType":"WIN","marketTime":"2024-06-27T16:21:00.000Z","suspendTime":"2024-06-27T16:21:00.000Z","bspReconciled":false,"complete":true,"inPlay":false,"crossMatching":false,"runnersVoidable":false,"numberOfActiveRunners":6,"betDelay":0,"status":"OPEN","runners":[{"status":"ACTIVE","sortPriority":1,"id":66499052,"name":"1. Salacres Wild"},{"status":"ACTIVE","sortPriority":2,"id":43210435,"name":"2. Bemyangelrosa"},{"status":"ACTIVE","sortPriority":3,"id":41138102,"name":"3. Traptoline Zorro"},{"status":"ACTIVE","sortPriority":4,"id":69979297,"name":"4. Jacktavern Pele"},{"status":"ACTIVE","sortPriority":5,"id":58149406,"name":"5. Salacres Herbert"},{"status":"ACTIVE","sortPriority":6,"id":51843546,"name":"6. Salacres Maybach"}],"regulators":["MR_INT"],"venue":"Towcester","countryCode":"GB","discountAllowed":true,"timezone":"Europe/London","openDate":"2024-06-27T13:33:00.000Z","version":5994767063,"name":"D2 270m","eventName":"Towcester 27th Jun"},"rc":[],"con":true,"img":false}]}
{"op":"mcm","clk":"11537083760","pt":1719435430584,"mc":[{"id":"1.230180130","rc":[{"atb":[[1.01,32.96]],"id":58149406},{"atl":[[990,0.84]],"id":58149406},{"spn":495.5,"spf":"NaN","id":58149406},{"atb":[[1.01,32.96]],"id":41138102},{"atl":[[990,0.84]],"id":41138102},{"spn":495.5,"spf":"NaN","id":41138102},{"atb":[[1.03,10.99]],"id":43210435},{"atl":[[1000,0.84]],"id":43210435},{"spn":500.51,"spf":"NaN","id":43210435},{"atb":[[1.03,10.99]],"id":66499052},{"atl":[[1000,0.84]],"id":66499052},{"spn":500.51,"spf":"NaN","id":66499052},{"atb":[[1.01,32.96]],"id":51843546},{"atl":[[1000,0.84]],"id":51843546},{"spn":500.5,"spf":"NaN","id":51843546},{"atb":[[1.01,32.96]],"id":69979297},{"atl":[[990,0.84]],"id":69979297},{"spn":495.5,"spf":"NaN","id":69979297}],"con":true,"img":false}]}
{"op":"mcm","clk":"11537235634","pt":1719437882799,"mc":[{"id":"1.230180130","marketDefinition":{"bspMarket":true,"turnInPlayEnabled":false,"persistenceEnabled":false,"marketBaseRate":5.0,"eventId":"33376437","eventTypeId":"4339","numberOfWinners":1,"bettingType":"ODDS","marketType":"WIN","marketTime":"2024-06-27T16:21:00.000Z","suspendTime":"2024-06-27T16:21:00.000Z","bspReconciled":false,"complete":true,"inPlay":false,"crossMatching":false,"runnersVoidable":false,"numberOfActiveRunners":6,"betDelay":0,"status":"OPEN","runners":[{"status":"ACTIVE","sortPriority":1,"id":66499052,"name":"1. Salacres Wild"},{"status":"ACTIVE","sortPriority":2,"id":43210435,"name":"2. Bemyangelrosa"},{"status":"ACTIVE","sortPriority":3,"id":41138102,"name":"3. Traptoline Zorro"},{"status":"ACTIVE","sortPriority":4,"id":69979297,"name":"4. Jacktavern Pele"},{"status":"ACTIVE","sortPriority":5,"id":58149406,"name":"5. Salacres Herbert"},{"status":"ACTIVE","sortPriority":6,"id":51843546,"name":"6. Salacres Maybach"}],"regulators":["MR_INT"],"venue":"Towcester","countryCode":"GB","discountAllowed":true,"timezone":"Europe/London","openDate":"2024-06-27T13:33:00.000Z","version":5994767063,"name":"D2 270m","eventName":"Towcester 27th Jun"},"rc":[{"atb":[[1.01,32.96]],"id":58149406},{"atl":[[990,0.84]],"id":58149406},{"spn":495.5,"spf":"NaN","id":58149406},{"atb":[[1.01,32.96]],"id":41138102},{"atl":[[990,0.84]],"id":41138102},{"spn":495.5,"spf":"NaN","id":41138102},{"atb":[[1.03,10.99]],"id":43210435},{"atl":[[1000,0.84]],"id":43210435},{"spn":500.51,"spf":"NaN","id":43210435},{"atb":[[1.03,10.99]],"id":66499052},{"atl":[[1000,0.84]],"id":66499052},{"spn":500.51,"spf":"NaN","id":66499052},{"atb":[[1.01,32.96]],"id":51843546},{"atl":[[1000,0.84]],"id":51843546},{"spn":500.5,"spf":"NaN","id":51843546},{"atb":[[1.01,32.96]],"id":69979297},{"atl":[[990,0.84]],"id":69979297},{"spn":495.5,"spf":"NaN","id":69979297}],"con":true,"img":true}]}
{"op":"mcm","clk":"11537301978","pt":1719439027614,"mc":[{"id":"1.230180130","rc":[{"atb":[[1.01,32.96]],"id":58149406},{"atl":[[990,0.17]],"id":58149406},{"atb":[[1.01,32.96]],"id":41138102},{"atl":[[990,0.17]],"id":41138102},{"atb":[[1.03,10.99]],"id":43210435},{"atl":[[1000,0.17]],"id":43210435},{"atb":[[1.03,10.99]],"id":66499052},{"atl":[[1000,0.17]],"id":66499052},{"atb":[[1.01,32.96]],"id":51843546},{"atl":[[1000,0.17]],"id":51843546},{"atb":[[1.01,32.96]],"id":69979297},{"atl":[[990,0.17]],"id":69979297}],"con":true,"img":false}]}
{"op":"mcm","clk":"11537576922","pt":1719443282842,"mc":[{"id":"1.230180130","marketDefinition":{"bspMarket":true,"turnInPlayEnabled":false,"persistenceEnabled":false,"marketBaseRate":5.0,"eventId":"33376437","eventTypeId":"4339","numberOfWinners":1,"bettingType":"ODDS","marketType":"WIN","marketTime":"2024-06-27T16:21:00.000Z","suspendTime":"2024-06-27T16:21:00.000Z","bspReconciled":false,"complete":true,"inPlay":false,"crossMatching":false,"runnersVoidable":false,"numberOfActiveRunners":6,"betDelay":0,"status":"OPEN","runners":[{"status":"ACTIVE","sortPriority":1,"id":66499052,"name":"1. Salacres Wild"},{"status":"ACTIVE","sortPriority":2,"id":43210435,"name":"2. Bemyangelrosa"},{"status":"ACTIVE","sortPriority":3,"id":41138102,"name":"3. Traptoline Zorro"},{"status":"ACTIVE","sortPriority":4,"id":69979297,"name":"4. Jacktavern Pele"},{"status":"ACTIVE","sortPriority":5,"id":58149406,"name":"5. Salacres Herbert"},{"status":"ACTIVE","sortPriority":6,"id":51843546,"name":"6. Salacres Maybach"}],"regulators":["MR_INT"],"venue":"Towcester","countryCode":"GB","discountAllowed":true,"timezone":"Europe/London","openDate":"2024-06-27T13:33:00.000Z","version":5994767063,"name":"D2 270m","eventName":"Towcester 27th Jun"},"rc":[{"atb":[[1.01,32.96]],"id":58149406},{"atl":[[990,0.17]],"id":58149406},{"spn":495.5,"spf":"NaN","id":58149406},{"atb":[[1.01,32.96]],"id":41138102},{"atl":[[990,0.17]],"id":41138102},{"spn":495.5,"spf":"NaN","id":41138102},{"atb":[[1.03,10.99]],"id":43210435},{"atl":[[1000,0.17]],"id":43210435},{"spn":500.51,"spf":"NaN","id":43210435},{"atb":[[1.03,10.99]],"id":66499052},{"atl":[[1000,0.17]],"id":66499052},{"spn":500.51,"spf":"NaN","id":66499052},{"atb":[[1.01,32.96]],"id":51843546},{"atl":[[1000,0.17]],"id":51843546},{"spn":500.5,"spf":"NaN","id":51843546},{"atb":[[1.01,32.96]],"id":69979297},{"atl":[[990,0.17]],"id":69979297},{"spn":495.5,"spf":"NaN","id":69979297}],"con":true,"img":true}]}
{"op":"mcm","clk":"11537958609","pt":1719448682890,"mc":[{"id":"1.230180130","marketDefinition":{"bspMarket":true,"turnInPlayEnabled":false,"persistenceEnabled":false,"marketBaseRate":5.0,"eventId":"33376437","eventTypeId":"4339","numberOfWinners":1,"bettingType":"ODDS","marketType":"WIN","marketTime":"2024-06-27T16:21:00.000Z","suspendTime":"2024-06-27T16:21:00.000Z","bspReconciled":false,"complete":true,"inPlay":false,"crossMatching":false,"runnersVoidable":false,"numberOfActiveRunners":6,"betDelay":0,"status":"OPEN","runners":[{"status":"ACTIVE","sortPriority":1,"id":66499052,"name":"1. Salacres Wild"},{"status":"ACTIVE","sortPriority":2,"id":43210435,"name":"2. Bemyangelrosa"},{"status":"ACTIVE","sortPriority":3,"id":41138102,"name":"3. Traptoline Zorro"},{"status":"ACTIVE","sortPriority":4,"id":69979297,"name":"4. Jacktavern Pele"},{"status":"ACTIVE","sortPriority":5,"id":58149406,"name":"5. Salacres Herbert"},{"status":"ACTIVE","sortPriority":6,"id":51843546,"name":"6. Salacres Maybach"}],"regulators":["MR_INT"],"venue":"Towcester","countryCode":"GB","discountAllowed":true,"timezone":"Europe/London","openDate":"2024-06-27T13:33:00.000Z","version":5994767063,"name":"D2 270m","eventName":"Towcester 27th Jun"},"rc":[{"atb":[[1.01,32.96]],"id":58149406},{"atl":[[990,0.17]],"id":58149406},{"spn":495.5,"spf":"NaN","id":58149406},{"atb":[[1.01,32.96]],"id":41138102},{"atl":[[990,0.17]],"id":41138102},{"spn":495.5,"spf":"NaN","id":41138102},{"atb":[[1.03,10.99]],"id":43210435},{"atl":[[1000,0.17]],"id":43210435},{"spn":500.51,"spf":"NaN","id":43210435},{"atb":[[1.03,10.99]],"id":66499052},{"atl":[[1000,0.17]],"id":66499052},{"spn":500.51,"spf":"NaN","id":66499052},{"atb":[[1.01,32.96]],"id":51843546},{"atl":[[1000,0.17]],"id":51843546},{"spn":500.5,"spf":"NaN","id":51843546},{"atb":[[1.01,32.96]],"id":69979297},{"atl":[[990,0.17]],"id":69979297},{"spn":495.5,"spf":"NaN","id":69979297}],"con":true,"img":true}]}
{"op":"mcm","clk":"11538174185","pt":1719454082861,"mc":[{"id":"1.230180130","marketDefinition":{"bspMarket":true,"turnInPlayEnabled":false,"persistenceEnabled":false,"marketBaseRate":5.0,"eventId":"33376437","eventTypeId":"4339","numberOfWinners":1,"bettingType":"ODDS","marketType":"WIN","marketTime":"2024-06-27T16:21:00.000Z","suspendTime":"2024-06-27T16:21:00.000Z","bspReconciled":false,"complete":true,"inPlay":false,"crossMatching":false,"runnersVoidable":false,"numberOfActiveRunners":6,"betDelay":0,"status":"OPEN","runners":[{"status":"ACTIVE","sortPriority":1,"id":66499052,"name":"1. Salacres Wild"},{"status":"ACTIVE","sortPriority":2,"id":43210435,"name":"2. Bemyangelrosa"},{"status":"ACTIVE","sortPriority":3,"id":41138102,"name":"3. Traptoline Zorro"},{"status":"ACTIVE","sortPriority":4,"id":69979297,"name":"4. Jacktavern Pele"},{"status":"ACTIVE","sortPriority":5,"id":58149406,"name":"5. Salacres Herbert"},{"status":"ACTIVE","sortPriority":6,"id":51843546,"name":"6. Salacres Maybach"}],"regulators":["MR_INT"],"venue":"Towcester","countryCode":"GB","discountAllowed":true,"timezone":"Europe/London","openDate":"2024-06-27T13:33:00.000Z","version":5994767063,"name":"D2 270m","eventName":"Towcester 27th Jun"},"rc":[{"atb":[[1.01,32.97]],"id":58149406},{"atl":[[990,0.17]],"id":58149406},{"spn":495.5,"spf":"NaN","id":58149406},{"atb":[[1.01,32.97]],"id":41138102},{"atl":[[990,0.17]],"id":41138102},{"spn":495.5,"spf":"NaN","id":41138102},{"atb":[[1.03,10.99]],"id":43210435},{"atl":[[1000,0.17]],"id":43210435},{"spn":500.51,"spf":"NaN","id":43210435},{"atb":[[1.03,10.99]],"id":66499052},{"atl":[[1000,0.17]],"id":66499052},{"spn":500.51,"spf":"NaN","id":66499052},{"atb":[[1.01,32.97]],"id":51843546},{"atl":[[1000,0.17]],"id":51843546},{"spn":500.5,"spf":"NaN","id":51843546},{"atb":[[1.01,32.97]],"id":69979297},{"atl":[[990,0.17]],"id":69979297},{"spn":495.5,"spf":"NaN","id":69979297}],"con":true,"img":true}]}
{"op":"mcm","clk":"11538371898","pt":1719459482935,"mc":[{"id":"1.230180130","marketDefinition":{"bspMarket":true,"turnInPlayEnabled":false,"persistenceEnabled":false,"marketBaseRate":5.0,"eventId":"33376437","eventTypeId":"4339","numberOfWinners":1,"bettingType":"ODDS","marketType":"WIN","marketTime":"2024-06-27T16:21:00.000Z","suspendTime":"2024-06-27T16:21:00.000Z","bspReconciled":false,"complete":true,"inPlay":false,"crossMatching":false,"runnersVoidable":false,"numberOfActiveRunners":6,"betDelay":0,"status":"OPEN","runners":[{"status":"ACTIVE","sortPriority":1,"id":66499052,"name":"1. Salacres Wild"},{"status":"ACTIVE","sortPriority":2,"id":43210435,"name":"2. Bemyangelrosa"},{"status":"ACTIVE","sortPriority":3,"id":41138102,"name":"3. Traptoline Zorro"},{"status":"ACTIVE","sortPriority":4,"id":69979297,"name":"4. Jacktavern Pele"},{"status":"ACTIVE","sortPriority":5,"id":58149406,"name":"5. Salacres Herbert"},{"status":"ACTIVE","sortPriority":6,"id":51843546,"name":"6. Salacres Maybach"}],"regulators":["MR_INT"],"venue":"Towcester","countryCode":"GB","discountAllowed":true,"timezone":"Europe/London","openDate":"2024-06-27T13:33:00.000Z","version":5994767063,"name":"D2 270m","eventName":"Towcester 27th Jun"},"rc":[{"atb":[[1.01,32.97]],"id":58149406},{"atl":[[990,0.17]],"id":58149406},{"spn":495.5,"spf":"NaN","id":58149406},{"atb":[[1.01,32.97]],"id":41138102},{"atl":[[990,0.17]],"id":41138102},{"spn":495.5,"spf":"NaN","id":41138102},{"atb":[[1.03,10.99]],"id":43210435},{"atl":[[1000,0.17]],"id":43210435},{"spn":500.51,"spf":"NaN","id":43210435},{"atb":[[1.03,10.99]],"id":66499052},{"atl":[[1000,0.17]],"id":66499052},{"spn":500.51,"spf":"NaN","id":66499052},{"atb":[[1.01,32.97]],"id":51843546},{"atl":[[1000,0.17]],"id":51843546},{"spn":500.5,"spf":"NaN","id":51843546},{"atb":[[1.01,32.97]],"id":69979297},{"atl":[[990,0.17]],"id":69979297},{"spn":495.5,"spf":"NaN","id":69979297}],"con":true,"img":true}]}
{"op":"mcm","clk":"11538598975","pt":1719464882861,"mc":[{"id":"1.230180130","marketDefinition":{"bspMarket":true,"turnInPlayEnabled":false,"persistenceEnabled":false,"marketBaseRate":5.0,"eventId":"33376437","eventTypeId":"4339","numberOfWinners":1,"bettingType":"ODDS","marketType":"WIN","marketTime":"2024-06-27T16:21:00.000Z","suspendTime":"2024-06-27T16:21:00.000Z","bspReconciled":false,"complete":true,"inPlay":false,"crossMatching":false,"runnersVoidable":false,"numberOfActiveRunners":6,"betDelay":0,"status":"OPEN","runners":[{"status":"ACTIVE","sortPriority":1,"id":66499052,"name":"1. Salacres Wild"},{"status":"ACTIVE","sortPriority":2,"id":43210435,"name":"2. Bemyangelrosa"},{"status":"ACTIVE","sortPriority":3,"id":41138102,"name":"3. Traptoline Zorro"},{"status":"ACTIVE","sortPriority":4,"id":69979297,"name":"4. Jacktavern Pele"},{"status":"ACTIVE","sortPriority":5,"id":58149406,"name":"5. Salacres Herbert"},{"status":"ACTIVE","sortPriority":6,"id":51843546,"name":"6. Salacres Maybach"}],"regulators":["MR_INT"],"venue":"Towcester","countryCode":"GB","discountAllowed":true,"timezone":"Europe/London","openDate":"2024-06-27T13:33:00.000Z","version":5994767063,"name":"D2 270m","eventName":"Towcester 27th Jun"},"rc":[{"atb":[[1.01,32.97]],"id":58149406},{"atl":[[990,0.17]],"id":58149406},{"spn":495.5,"spf":"NaN","id":58149406},{"atb":[[1.01,32.97]],"id":41138102},{"atl":[[990,0.17]],"id":41138102},{"spn":495.5,"spf":"NaN","id":41138102},{"atb":[[1.03,10.99]],"id":43210435},{"atl":[[1000,0.17]],"id":43210435},{"spn":500.51,"spf":"NaN","id":43210435},{"atb":[[1.03,10.99]],"id":66499052},{"atl":[[1000,0.17]],"id":66499052},{"spn":500.51,"spf":"NaN","id":66499052},{"atb":[[1.01,32.97]],"id":51843546},{"atl":[[1000,0.17]],"id":51843546},{"spn":500.5,"spf":"NaN","id":51843546},{"atb":[[1.01,32.97]],"id":69979297},{"atl":[[990,0.17]],"id":69979297},{"spn":495.5,"spf":"NaN","id":69979297}],"con":true,"img":true}]}
{"op":"mcm","clk":"11538748671","pt":1719468205783,"mc":[{"id":"1.230180130","rc":[{"atb":[[1.01,32.97],[2.04,13.07]],"id":58149406},{"spn":496.02,"spf":"NaN","id":58149406},{"atb":[[1.01,32.97],[2.1,12.55]],"id":41138102},{"spn":496.05,"spf":"NaN","id":41138102},{"atb":[[2,10.25],[1.03,10.99]],"id":43210435},{"spn":501.0,"spf":"NaN","id":43210435},{"atb":[[2.02,9.49],[1.03,10.99]],"id":66499052},{"spn":501.01,"spf":"NaN","id":66499052},{"atb":[[2,9.4],[1.01,32.97]],"id":51843546},{"spn":501.0,"spf":"NaN","id":51843546},{"atb":[[1.01,32.97],[2.06,11.44]],"id":69979297},{"spn":496.03,"spf":"NaN","id":69979297}],"con":true,"img":false}]}
{"op":"mcm","clk":"11538750393","pt":1719468243055,"mc":[{"id":"1.230180130","rc":[{"atb":[[2.12,3.16]],"id":41138102}],"con":true,"img":false}]}
{"op":"mcm","clk":"11538750399","pt":1719468243158,"mc":[{"id":"1.230180130","rc":[{"atb":[[2.04,3.16]],"id":66499052}],"con":true,"img":false}]}
{"op":"mcm","clk":"11538750406","pt":1719468243259,"mc":[{"id":"1.230180130","rc":[{"atb":[[2.06,3.16]],"id":58149406}],"con":true,"img":false}]}
{"op":"mcm","clk":"11538750422","pt":1719468243566,"mc":[{"id":"1.230180130","rc":[{"atb":[[2.02,3.16]],"id":51843546}],"con":true,"img":false}]}
{"op":"mcm","clk":"11538750428","pt":1719468243670,"mc":[{"id":"1.230180130","rc":[{"atb":[[2.02,3.16]],"id":43210435}],"con":true,"img":false}]}
{"op":"mcm","clk":"11538752236","pt":1719468278915,"mc":[{"id":"1.230180130","rc":[{"spn":496.03,"spf":"NaN","id":58149406},{"spn":496.06,"spf":"NaN","id":41138102},{"spn":501.01,"spf":"NaN","id":43210435},{"atb":[[2.04,6.55]],"id":66499052},{"spn":501.02,"spf":"NaN","id":66499052},{"spn":501.01,"spf":"NaN","id":51843546}],"con":true,"img":false}]}
{"op":"mcm","clk":"11538752257","pt":1719468279483,"mc":[{"id":"1.230180130","rc":[{"atb":[[2.02,6.55]],"id":43210435}],"con":true,"img":false}]}
{"op":"mcm","clk":"11538752270","pt":1719468279788,"mc":[{"id":"1.230180130","rc":[{"atb":[[2.06,6.55]],"id":58149406},{"atb":[[2.12,6.55]],"id":41138102}],"con":true,"img":false}]}
{"op":"mcm","clk":"11538752284","pt":1719468280093,"mc":[{"id":"1.230180130","rc":[{"atb":[[2.02,6.55]],"id":51843546}],"con":true,"img":false}]}
{"op":"mcm","clk":"11538752384","pt":1719468281747,"mc":[{"id":"1.230180130","marketDefinition":{"bspMarket":true,"turnInPlayEnabled":false,"persistenceEnabled":false,"marketBaseRate":5.0,"eventId":"33376437","eventTypeId":"4339","numberOfWinners":1,"bettingType":"ODDS","marketType":"WIN","marketTime":"2024-06-27T16:21:00.000Z","suspendTime":"2024-06-27T16:21:00.000Z","bspReconciled":false,"complete":true,"inPlay":false,"crossMatching":true,"runnersVoidable":false,"numberOfActiveRunners":6,"betDelay":0,"status":"OPEN","runners":[{"status":"ACTIVE","sortPriority":1,"id":66499052,"name":"1. Salacres Wild"},{"status":"ACTIVE","sortPriority":2,"id":43210435,"name":"2. Bemyangelrosa"},{"status":"ACTIVE","sortPriority":3,"id":41138102,"name":"3. Traptoline Zorro"},{"status":"ACTIVE","sortPriority":4,"id":69979297,"name":"4. Jacktavern Pele"},{"status":"ACTIVE","sortPriority":5,"id":58149406,"name":"5. Salacres Herbert"},{"status":"ACTIVE","sortPriority":6,"id":51843546,"name":"6. Salacres Maybach"}],"regulators":["MR_INT"],"venue":"Towcester","countryCode":"GB","discountAllowed":true,"timezone":"Europe/London","openDate":"2024-06-27T13:33:00.000Z","version":5994767063,"name":"D2 270m","eventName":"Towcester 27th Jun"},"rc":[],"con":true,"img":false}]}
{"op":"mcm","clk":"11538938902","pt":1719472080058,"mc":[{"id":"1.230180130","rc":[{"atb":[[1.01,32.94],[2.06,6.54],[2.04,13.06]],"id":58149406},{"atl":[[990,0.17]],"id":58149406},{"atb":[[1.01,32.94],[2.12,6.54],[2.1,12.55]],"id":41138102},{"atl":[[990,0.17]],"id":41138102},{"atb":[[2,10.25],[2.02,6.54],[1.03,10.98]],"id":43210435},{"atl":[[1000,0.17]],"id":43210435},{"atb":[[2.02,9.48],[1.03,10.98],[2.04,6.54]],"id":66499052},{"atl":[[1000,0.17]],"id":66499052},{"atb":[[2,9.39],[2.02,6.54],[1.01,32.94]],"id":51843546},{"atl":[[1000,0.17]],"id":51843546},{"atb":[[1.01,32.94],[2.06,11.43]],"id":69979297},{"atl":[[21,4],[11.5,2],[990,0.17],[15.5,3]],"id":69979297},{"spn":6.78,"spf":"NaN","id":69979297}],"con":true,"img":false}]}
{"op":"mcm","clk":"11538940795","pt":1719472114100,"mc":[{"id":"1.230180130","rc":[{"atb":[[2.04,0]],"id":58149406},{"atb":[[2.1,0]],"id":41138102},{"atb":[[2,0]],"id":43210435},{"atb":[[2.02,0]],"id":66499052},{"atb":[[2,0]],"id":51843546}],"con":true,"img":false}]}
{"op":"mcm","clk":"11538940802","pt":1719472114195,"mc":[{"id":"1.230180130","rc":[{"atb":[[2.08,13.06]],"id":58149406},{"atb":[[2.14,12.55]],"id":41138102},{"atb":[[2.04,10.25]],"id":43210435},{"atb":[[2.06,9.48]],"id":66499052},{"atb":[[2.04,9.39]],"id":51843546}],"con":true,"img":false}]}
{"op":"mcm","clk":"11538942657","pt":1719472143873,"mc":[{"id":"1.230180130","rc":[{"spn":496.04,"spf":"NaN","id":58149406},{"spn":496.07,"spf":"NaN","id":41138102},{"spn":501.02,"spf":"NaN","id":43210435},{"atb":[[2.04,3.38]],"id":66499052},{"spn":501.03,"spf":"NaN","id":66499052},{"spn":501.02,"spf":"NaN","id":51843546}],"con":true,"img":false}]}
{"op":"mcm","clk":"11538942668","pt":1719472144072,"mc":[{"id":"1.230180130","rc":[{"atb":[[2.12,3.38]],"id":41138102}],"con":true,"img":false}]}
{"op":"mcm","clk":"11538942694","pt":1719472144436,"mc":[{"id":"1.230180130","rc":[{"atb":[[2.08,3.16]],"id":66499052}],"con":true,"img":false}]}
{"op":"mcm","clk":"11538942750","pt":1719472145154,"mc":[{"id":"1.230180130","rc":[{"atb":[[2.02,3.38]],"id":43210435}],"con":true,"img":false}]}
{"op":"mcm","clk":"11538942766","pt":1719472145364,"mc":[{"id":"1.230180130","rc":[{"atb":[[2.16,3.16]],"id":41138102}],"con":true,"img":false}]}
{"op":"mcm","clk":"11538943031","pt":1719472148866,"mc":[{"id":"1.230180130","rc":[{"atb":[[2.06,3.16]],"id":43210435}],"con":true,"img":false}]}
{"op":"mcm","clk":"11538943201","pt":1719472151685,"mc":[{"id":"1.230180130","rc":[{"atb":[[2.06,3.38]],"id":58149406}],"con":true,"img":false}]}
{"op":"mcm","clk":"11538943259","pt":1719472152764,"mc":[{"id":"1.230180130","rc":[{"atb":[[2.12,0]],"id":41138102}],"con":true,"img":false}]}
{"op":"mcm","clk":"11538943279","pt":1719472153176,"mc":[{"id":"1.230180130","rc":[{"atb":[[2.02,0]],"id":43210435},{"atb":[[2.04,0]],"id":66499052}],"con":true,"img":false}]}
{"op":"mcm","clk":"11538943338","pt":1719472154102,"mc":[{"id":"1.230180130","rc":[{"atb":[[2.06,0]],"id":58149406}],"con":true,"img":false}]}
{"op":"mcm","clk":"11538943354","pt":1719472154258,"mc":[{"id":"1.230180130","rc":[{"atb":[[2.1,3.16]],"id":58149406},{"atb":[[2.02,3.16]],"id":51843546}],"con":true,"img":false}]}
{"op":"mcm","clk":"11538943423","pt":1719472155288,"mc":[{"id":"1.230180130","rc":[{"atb":[[2.02,0]],"id":51843546}],"con":true,"img":false}]}
{"op":"mcm","clk":"11538943461","pt":1719472155998,"mc":[{"id":"1.230180130","rc":[{"atb":[[2.06,3.16]],"id":51843546}],"con":true,"img":false}]}
{"op":"mcm","clk":"11538943839","pt":1719472162716,"mc":[{"id":"1.230180130","rc":[{"atb":[[2.08,6.54]],"id":66499052}],"con":true,"img":false}]}
{"op":"mcm","clk":"11538943898","pt":1719472163589,"mc":[{"id":"1.230180130","rc":[{"atb":[[2.16,6.54]],"id":41138102}],"con":true,"img":false}]}
{"op":"mcm","clk":"11538943923","pt":1719472163891,"mc":[{"id":"1.230180130","rc":[{"atb":[[2.06,6.54]],"id":43210435}],"con":true,"img":false}]}
{"op":"mcm","clk":"11538944162","pt":1719472167887,"mc":[{"id":"1.230180130","rc":[{"atb":[[2.1,6.54]],"id":58149406}],"con":true,"img":false}]}
{"op":"mcm","clk":"11538944260","pt":1719472169677,"mc":[{"id":"1.230180130","rc":[{"atb":[[2.06,6.54]],"id":51843546}],"con":true,"img":false}]}
{"op":"mcm","clk":"11538981059","pt":1719472879252,"mc":[{"id":"1.230180130","rc":[{"atl":[[150,4]],"id":58149406},{"spn":76.05,"spf":"NaN","id":58149406},{"atl":[[150,4]],"id":41138102},{"spn":76.08,"spf":"NaN","id":41138102},{"atl":[[150,4]],"id":43210435},{"spn":76.03,"spf":"NaN","id":43210435},{"atl":[[150,4]],"id":66499052},{"spn":76.04,"spf":"NaN","id":66499052},{"atl":[[150,4]],"id":51843546},{"spn":76.03,"spf":"NaN","id":51843546},{"atl":[[150,4]],"id":69979297}],"con":true,"img":false}]}
{"op":"mcm","clk":"11539126207","pt":1719475682882,"mc":[{"id":"1.230180130","marketDefinition":{"bspMarket":true,"turnInPlayEnabled":false,"persistenceEnabled":false,"marketBaseRate":5.0,"eventId":"33376437","eventTypeId":"4339","numberOfWinners":1,"bettingType":"ODDS","marketType":"WIN","marketTime":"2024-06-27T16:21:00.000Z","suspendTime":"2024-06-27T16:21:00.000Z","bspReconciled":false,"complete":true,"inPlay":false,"crossMatching":true,"runnersVoidable":false,"numberOfActiveRunners":6,"betDelay":0,"status":"OPEN","runners":[{"status":"ACTIVE","sortPriority":1,"id":66499052,"name":"1. Salacres Wild"},{"status":"ACTIVE","sortPriority":2,"id":43210435,"name":"2. Bemyangelrosa"},{"status":"ACTIVE","sortPriority":3,"id":41138102,"name":"3. Traptoline Zorro"},{"status":"ACTIVE","sortPriority":4,"id":69979297,"name":"4. Jacktavern Pele"},{"status":"ACTIVE","sortPriority":5,"id":58149406,"name":"5. Salacres Herbert"},{"status":"ACTIVE","sortPriority":6,"id":51843546,"name":"6. Salacres Maybach"}],"regulators":["MR_INT"],"venue":"Towcester","countryCode":"GB","discountAllowed":true,"timezone":"Europe/London","openDate":"2024-06-27T13:33:00.000Z","version":5994767063,"name":"D2 270m","eventName":"Towcester 27th Jun"},"rc":[{"atb":[[1.01,32.96],[2.1,6.55],[2.08,13.07]],"id":58149406},{"atl":[[150,4],[990,0.17]],"id":58149406},{"spn":76.05,"spf":"NaN","id":58149406},{"atb":[[1.01,32.96],[2.16,6.55],[2.14,12.55]],"id":41138102},{"atl":[[150,4],[990,0.17]],"id":41138102},{"spn":76.08,"spf":"NaN","id":41138102},{"atb":[[2.06,6.55],[1.03,10.99],[2.04,10.25]],"id":43210435},{"atl":[[150,4],[1000,0.17]],"id":43210435},{"spn":76.03,"spf":"NaN","id":43210435},{"atb":[[2.06,9.49],[1.03,10.99],[2.08,6.55]],"id":66499052},{"atl":[[150,4],[1000,0.17]],"id":66499052},{"spn":76.04,"spf":"NaN","id":66499052},{"atb":[[1.01,32.96],[2.06,6.55],[2.04,9.4]],"id":51843546},{"atl":[[150,4],[1000,0.17]],"id":51843546},{"spn":76.03,"spf":"NaN","id":51843546},{"atb":[[1.01,32.96],[2.06,11.43]],"id":69979297},{"atl":[[150,4],[21,4],[11.5,2],[990,0.17],[15.5,3]],"id":69979297},{"spn":6.78,"spf":"NaN","id":69979297}],"con":true,"img":true}]}
{"op":"mcm","clk":"11539128148","pt":1719475714150,"mc":[{"id":"1.230180130","rc":[{"atb":[[1.01,32.96],[2.1,6.55],[2.08,0]],"id":58149406},{"atb":[[1.01,32.96],[2.16,6.55],[2.14,0]],"id":41138102},{"atb":[[2.06,6.55],[1.03,10.99],[2.04,0]],"id":43210435},{"atb":[[2.06,0],[1.03,10.99],[2.08,6.55]],"id":66499052},{"atb":[[1.01,32.96],[2.06,6.55],[2.04,0]],"id":51843546},{"atb":[[1.01,32.96],[2.06,11.43]],"id":69979297}],"con":true,"img":false}]}
{"op":"mcm","clk":"11539128154","pt":1719475714255,"mc":[{"id":"1.230180130","rc":[{"atb":[[2.12,13.07]],"id":58149406},{"atb":[[2.18,12.55]],"id":41138102},{"atb":[[2.08,10.25]],"id":43210435},{"atb":[[2.1,9.49]],"id":66499052},{"atb":[[2.08,9.4]],"id":51843546}],"con":true,"img":false}]}
{"op":"mcm","clk":"11539134356","pt":1719475811144,"mc":[{"id":"1.230180130","rc":[{"atb":[[2.1,3.38]],"id":58149406},{"spn":76.06,"spf":"NaN","id":58149406},{"atb":[[2.16,3.38]],"id":41138102},{"spn":76.09,"spf":"NaN","id":41138102},{"atb":[[2.06,3.38]],"id":43210435},{"spn":76.04,"spf":"NaN","id":43210435},{"atb":[[2.08,3.38]],"id":66499052},{"spn":76.05,"spf":"NaN","id":66499052},{"atb":[[2.06,3.38]],"id":51843546},{"spn":76.04,"spf":"NaN","id":51843546}],"con":true,"img":false}]}
{"op":"mcm","clk":"11539150669","pt":1719476079416,"mc":[{"id":"1.230180130","rc":[{"atb":[[2.1,0]],"id":58149406},{"atb":[[2.16,0]],"id":41138102},{"atb":[[2.06,0]],"id":43210435},{"atb":[[2.08,0]],"id":66499052},{"atb":[[2.06,0]],"id":51843546}],"con":true,"img":false}]}
{"op":"mcm","clk":"11539153189","pt":1719476115388,"mc":[{"id":"1.230180130","rc":[{"atb":[[2.12,3.16]],"id":66499052}],"con":true,"img":false}]}
{"op":"mcm","clk":"11539153197","pt":1719476115544,"mc":[{"id":"1.230180130","rc":[{"atb":[[2.2,3.16]],"id":41138102},{"atb":[[2.1,3.16]],"id":43210435}],"con":true,"img":false}]}
{"op":"mcm","clk":"11539153206","pt":1719476115749,"mc":[{"id":"1.230180130","rc":[{"atb":[[2.14,3.16]],"id":58149406},{"atb":[[2.1,3.16]],"id":51843546}],"con":true,"img":false}]}
{"op":"mcm","clk":"11539167877","pt":1719476379003,"mc":[{"id":"1.230180130","rc":[{"spn":76.07,"spf":"NaN","id":58149406},{"spn":76.1,"spf":"NaN","id":41138102},{"spn":76.05,"spf":"NaN","id":43210435},{"atb":[[2.12,6.55]],"id":66499052},{"spn":76.06,"spf":"NaN","id":66499052},{"atb":[[2.1,6.55]],"id":51843546},{"spn":76.05,"spf":"NaN","id":51843546}],"con":true,"img":false}]}
{"op":"mcm","clk":"11539167900","pt":1719476379307,"mc":[{"id":"1.230180130","rc":[{"atb":[[2.14,6.55]],"id":58149406},{"atb":[[2.2,6.55]],"id":41138102}],"con":true,"img":false}]}
{"op":"mcm","clk":"11539167917","pt":1719476379617,"mc":[{"id":"1.230180130","rc":[{"atb":[[2.1,6.55]],"id":43210435}],"con":true,"img":false}]}
{"op":"mcm","clk":"11539341556","pt":1719479312697,"mc":[{"id":"1.230180130","rc":[{"atb":[[1.01,32.95],[2.12,0],[2.14,6.54]],"id":58149406},{"atb":[[1.01,32.95],[2.18,0],[2.2,6.54]],"id":41138102},{"atb":[[1.03,10.98],[2.1,6.54],[2.08,0]],"id":43210435},{"atb":[[1.03,10.98],[2.12,6.54],[2.1,0]],"id":66499052},{"atb":[[1.01,32.95],[2.1,6.54],[2.08,0]],"id":51843546},{"atb":[[1.01,32.95],[2.06,11.43]],"id":69979297}],"con":true,"img":false}]}
{"op":"mcm","clk":"11539341565","pt":1719479312798,"mc":[{"id":"1.230180130","rc":[{"atb":[[2.16,13.06]],"id":58149406},{"atb":[[2.22,12.55]],"id":41138102},{"atb":[[2.12,10.25]],"id":43210435},{"atb":[[2.14,9.49]],"id":66499052},{"atb":[[2.12,9.39]],"id":51843546}],"con":true,"img":false}]}
{"op":"mcm","clk":"11539346554","pt":1719479392697,"mc":[{"id":"1.230180130","rc":[{"spn":76.08,"spf":"NaN","id":58149406},{"spn":76.11,"spf":"NaN","id":41138102},{"spn":76.06,"spf":"NaN","id":43210435},{"atb":[[2.12,3.38]],"id":66499052},{"spn":76.07,"spf":"NaN","id":66499052},{"atb":[[2.1,3.38]],"id":51843546},{"spn":76.06,"spf":"NaN","id":51843546}],"con":true,"img":false}]}
{"op":"mcm","clk":"11539346565","pt":1719479392996,"mc":[{"id":"1.230180130","rc":[{"atb":[[2.1,3.38]],"id":43210435}],"con":true,"img":false}]}
{"op":"mcm","clk":"11539346580","pt":1719479393299,"mc":[{"id":"1.230180130","rc":[{"atb":[[2.2,3.38]],"id":41138102}],"con":true,"img":false}]}
{"op":"mcm","clk":"11539346646","pt":1719479394382,"mc":[{"id":"1.230180130","rc":[{"atb":[[2.14,3.38]],"id":58149406}],"con":true,"img":false}]}
{"op":"mcm","clk":"11539367418","pt":1719479703750,"mc":[{"id":"1.230180130","rc":[{"atb":[[2.14,3.16]],"id":43210435},{"spn":76.07,"spf":"NaN","id":43210435}],"con":true,"img":false}]}
{"op":"mcm","clk":"11539367435","pt":1719479703955,"mc":[{"id":"1.230180130","rc":[{"atb":[[2.18,3.16]],"id":58149406}],"con":true,"img":false}]}
{"op":"mcm","clk":"11539367450","pt":1719479704161,"mc":[{"id":"1.230180130","rc":[{"atb":[[2.16,3.16]],"id":66499052}],"con":true,"img":false}]}
{"op":"mcm","clk":"11539367516","pt":1719479704931,"mc":[{"id":"1.230180130","rc":[{"atb":[[2.24,3.16]],"id":41138102}],"con":true,"img":false}]}
{"op":"mcm","clk":"11539367817","pt":1719479708758,"mc":[{"id":"1.230180130","rc":[{"atb":[[2.14,3.16]],"id":51843546}],"con":true,"img":false}]}
{"op":"mcm","clk":"11539376048","pt":1719479827809,"mc":[{"id":"1.230180130","rc":[{"spn":76.09,"spf":"NaN","id":58149406},{"spn":76.12,"spf":"NaN","id":41138102},{"atb":[[2.12,0]],"id":66499052},{"spn":76.08,"spf":"NaN","id":66499052},{"spn":76.07,"spf":"NaN","id":51843546}],"con":true,"img":false}]}
{"op":"mcm","clk":"11539376058","pt":1719479827912,"mc":[{"id":"1.230180130","rc":[{"atb":[[2.2,0]],"id":41138102}],"con":true,"img":false}]}
{"op":"mcm","clk":"11539376074","pt":1719479828220,"mc":[{"id":"1.230180130","rc":[{"atb":[[2.14,0]],"id":58149406},{"atb":[[2.1,0]],"id":51843546}],"con":true,"img":false}]}
{"op":"mcm","clk":"11539376104","pt":1719479828585,"mc":[{"id":"1.230180130","rc":[{"atb":[[2.1,0]],"id":43210435}],"con":true,"img":false}]}
{"op":"mcm","clk":"11539376112","pt":1719479828748,"mc":[{"id":"1.230180130","rc":[{"atb":[[2.16,6.54]],"id":66499052}],"con":true,"img":false}]}
{"op":"mcm","clk":"11539376123","pt":1719479828893,"mc":[{"id":"1.230180130","rc":[{"atb":[[2.24,6.54]],"id":41138102}],"con":true,"img":false}]}
{"op":"mcm","clk":"11539376139","pt":1719479829200,"mc":[{"id":"1.230180130","rc":[{"atb":[[2.14,6.54]],"id":43210435}],"con":true,"img":false}]}
{"op":"mcm","clk":"11539376145","pt":1719479829302,"mc":[{"id":"1.230180130","rc":[{"atb":[[2.18,6.54]],"id":58149406}],"con":true,"img":false}]}
{"op":"mcm","clk":"11539376160","pt":1719479829510,"mc":[{"id":"1.230180130","rc":[{"atb":[[2.14,6.54]],"id":51843546}],"con":true,"img":false}]}
{"op":"mcm","clk":"11539545609","pt":1719482912986,"mc":[{"id":"1.230180130","rc":[{"atb":[[1.01,32.95],[2.18,6.54],[2.16,0]],"id":58149406},{"atb":[[2.24,6.54],[1.01,32.95],[2.22,0]],"id":41138102},{"atb":[[1.03,10.98],[2.12,0],[2.14,6.54]],"id":43210435},{"atb":[[1.03,10.98],[2.16,6.54],[2.14,0]],"id":66499052},{"atb":[[1.01,32.95],[2.12,0],[2.14,6.54]],"id":51843546},{"atb":[[1.01,32.95],[2.06,11.43]],"id":69979297}],"con":true,"img":false}]}
{"op":"mcm","clk":"11539545615","pt":1719482913082,"mc":[{"id":"1.230180130","rc":[{"atb":[[2.2,13.06]],"id":58149406},{"atb":[[2.26,12.55]],"id":41138102},{"atb":[[2.16,10.25]],"id":43210435},{"atb":[[2.18,9.48]],"id":66499052},{"atb":[[2.16,9.39]],"id":51843546}],"con":true,"img":false}]}
{"op":"mcm","clk":"11539553034","pt":1719483024162,"mc":[{"id":"1.230180130","rc":[{"spn":76.1,"spf":"NaN","id":58149406},{"atb":[[2.24,3.38]],"id":41138102},{"spn":76.13,"spf":"NaN","id":41138102},{"spn":76.08,"spf":"NaN","id":43210435},{"spn":76.09,"spf":"NaN","id":66499052},{"spn":76.08,"spf":"NaN","id":51843546}],"con":true,"img":false}]}
{"op":"mcm","clk":"11539553049","pt":1719483024366,"mc":[{"id":"1.230180130","rc":[{"atb":[[2.14,3.38]],"id":43210435}],"con":true,"img":false}]}
{"op":"mcm","clk":"11539553112","pt":1719483025249,"mc":[{"id":"1.230180130","rc":[{"atb":[[2.18,3.38]],"id":58149406}],"con":true,"img":false}]}
{"op":"mcm","clk":"11539553146","pt":1719483025768,"mc":[{"id":"1.230180130","rc":[{"atb":[[2.18,3.16]],"id":43210435}],"con":true,"img":false}]}
{"op":"mcm","clk":"11539553160","pt":1719483025921,"mc":[{"id":"1.230180130","rc":[{"atb":[[2.28,3.16]],"id":41138102}],"con":true,"img":false}]}
{"op":"mcm","clk":"11539553200","pt":1719483026437,"mc":[{"id":"1.230180130","rc":[{"atb":[[2.16,3.38]],"id":66499052}],"con":true,"img":false}]}
{"op":"mcm","clk":"11539553211","pt":1719483026643,"mc":[{"id":"1.230180130","rc":[{"atb":[[2.14,3.38]],"id":51843546}],"con":true,"img":false}]}
{"op":"mcm","clk":"11539553225","pt":1719483026851,"mc":[{"id":"1.230180130","rc":[{"atb":[[2.22,3.16]],"id":58149406}],"con":true,"img":false}]}
{"op":"mcm","clk":"11539556733","pt":1719483082835,"mc":[{"id":"1.230180130","rc":[{"atb":[[2.18,0]],"id":58149406},{"atb":[[2.24,0]],"id":41138102},{"atb":[[2.14,0]],"id":43210435},{"atb":[[2.16,0]],"id":66499052},{"atb":[[2.14,0]],"id":51843546}],"con":true,"img":false}]}
{"op":"mcm","clk":"11539572851","pt":1719483321154,"mc":[{"id":"1.230180130","rc":[{"spn":76.11,"spf":"NaN","id":58149406},{"spn":76.14,"spf":"NaN","id":41138102},{"spn":76.09,"spf":"NaN","id":43210435},{"atb":[[2.2,3.16]],"id":66499052},{"spn":76.1,"spf":"NaN","id":66499052}],"con":true,"img":false}]}
{"op":"mcm","clk":"11539572864","pt":1719483321307,"mc":[{"id":"1.230180130","rc":[{"atb":[[2.18,3.16]],"id":51843546}],"con":true,"img":false}]}
{"op":"mcm","clk":"11539612010","pt":1719483820739,"mc":[{"id":"1.230180130","rc":[{"atb":[[2.2,6.54]],"id":66499052},{"spn":76.09,"spf":"NaN","id":51843546}],"con":true,"img":false}]}
{"op":"mcm","clk":"11539612035","pt":1719483821047,"mc":[{"id":"1.230180130","rc":[{"atb":[[2.18,6.54]],"id":43210435}],"con":true,"img":false}]}
{"op":"mcm","clk":"11539612048","pt":1719483821250,"mc":[{"id":"1.230180130","rc":[{"atb":[[2.28,6.54]],"id":41138102}],"con":true,"img":false}]}
{"op":"mcm","clk":"11539612053","pt":1719483821360,"mc":[{"id":"1.230180130","rc":[{"atb":[[2.22,6.54]],"id":58149406}],"con":true,"img":false}]}
{"op":"mcm","clk":"11539612073","pt":1719483821657,"mc":[{"id":"1.230180130","rc":[{"atb":[[2.18,6.54]],"id":51843546}],"con":true,"img":false}]}
{"op":"mcm","clk":"11539793887","pt":1719486294856,"mc":[{"id":"1.230180130","rc":[{"atb":[[1.01,32.95],[2.22,6.54],[2.2,13.06]],"id":58149406},{"atb":[[1.01,32.95],[2.28,6.54],[2.26,12.55],[3.9,6]],"id":41138102},{"spn":76.95,"spf":"NaN","id":41138102},{"atb":[[1.03,10.98],[2.18,6.54],[3.55,6],[2.16,10.25]],"id":43210435},{"spn":76.77,"spf":"NaN","id":43210435},{"atb":[[1.03,10.98],[2.18,9.49],[2.2,6.54]],"id":66499052},{"atb":[[1.01,32.95],[2.18,6.54],[2.16,9.39],[4.2,6]],"id":51843546},{"spn":77.1,"spf":"NaN","id":51843546},{"atb":[[1.01,32.95],[2.06,11.43]],"id":69979297}],"con":true,"img":false}]}
{"op":"mcm","clk":"11539793896","pt":1719486294949,"mc":[{"id":"1.230180130","rc":[{"atb":[[3,6]],"id":58149406},{"atb":[[3.55,6]],"id":66499052},{"atb":[[1.92,6]],"id":69979297}],"con":true,"img":false}]}
{"op":"mcm","clk":"11539795090","pt":1719486309066,"mc":[{"id":"1.230180130","rc":[{"atb":[[2.22,3.38]],"id":58149406}],"con":true,"img":false}]}
{"op":"mcm","clk":"11539795104","pt":1719486309265,"mc":[{"id":"1.230180130","rc":[{"atb":[[2.28,3.38]],"id":41138102},{"atb":[[2.18,3.38]],"id":43210435},{"atb":[[2.2,3.38]],"id":66499052},{"atb":[[2.18,3.38]],"id":51843546}],"con":true,"img":false}]}
{"op":"mcm","clk":"11539795117","pt":1719486309470,"mc":[{"id":"1.230180130","rc":[{"atb":[[3.05,3.16]],"id":58149406}],"con":true,"img":false}]}
{"op":"mcm","clk":"11539795607","pt":1719486315596,"mc":[{"id":"1.230180130","rc":[{"atb":[[2.22,0]],"id":58149406}],"con":true,"img":false}]}
{"op":"mcm","clk":"11539795640","pt":1719486316005,"mc":[{"id":"1.230180130","rc":[{"atb":[[2.28,0]],"id":41138102},{"atb":[[2.18,0]],"id":43210435},{"atb":[[2.2,0]],"id":66499052},{"atb":[[2.18,0]],"id":51843546}],"con":true,"img":false}]}
{"op":"mcm","clk":"11539795695","pt":1719486316584,"mc":[{"id":"1.230180130","rc":[{"atb":[[3.05,6.54]],"id":58149406}],"con":true,"img":false}]}
{"op":"mcm","clk":"11539814857","pt":1719486482813,"mc":[{"id":"1.230180130","marketDefinition":{"bspMarket":true,"turnInPlayEnabled":false,"persistenceEnabled":false,"marketBaseRate":5.0,"eventId":"33376437","eventTypeId":"4339","numberOfWinners":1,"bettingType":"ODDS","marketType":"WIN","marketTime":"2024-06-27T16:21:00.000Z","suspendTime":"2024-06-27T16:21:00.000Z","bspReconciled":false,"complete":true,"inPlay":false,"crossMatching":true,"runnersVoidable":false,"numberOfActiveRunners":6,"betDelay":0,"status":"OPEN","runners":[{"status":"ACTIVE","sortPriority":1,"id":66499052,"name":"1. Salacres Wild"},{"status":"ACTIVE","sortPriority":2,"id":43210435,"name":"2. Bemyangelrosa"},{"status":"ACTIVE","sortPriority":3,"id":41138102,"name":"3. Traptoline Zorro"},{"status":"ACTIVE","sortPriority":4,"id":69979297,"name":"4. Jacktavern Pele"},{"status":"ACTIVE","sortPriority":5,"id":58149406,"name":"5. Salacres Herbert"},{"status":"ACTIVE","sortPriority":6,"id":51843546,"name":"6. Salacres Maybach"}],"regulators":["MR_INT"],"venue":"Towcester","countryCode":"GB","discountAllowed":true,"timezone":"Europe/London","openDate":"2024-06-27T13:33:00.000Z","version":5994767063,"name":"D2 270m","eventName":"Towcester 27th Jun"},"rc":[{"atb":[[1.01,32.95],[3,6],[2.2,13.06],[3.05,6.54]],"id":58149406},{"atl":[[150,4],[990,0.17]],"id":58149406},{"spn":76.52,"spf":"NaN","id":58149406},{"atb":[[1.01,32.95],[2.26,12.55],[3.9,6]],"id":41138102},{"atl":[[150,4],[990,0.17]],"id":41138102},{"spn":76.95,"spf":"NaN","id":41138102},{"atb":[[1.03,10.98],[3.55,6],[2.16,10.25]],"id":43210435},{"atl":[[150,4],[1000,0.17]],"id":43210435},{"spn":76.77,"spf":"NaN","id":43210435},{"atb":[[1.03,10.98],[2.18,9.49],[3.55,6]],"id":66499052},{"atl":[[150,4],[1000,0.17]],"id":66499052},{"spn":76.77,"spf":"NaN","id":66499052},{"atb":[[1.01,32.95],[4.2,6],[2.16,9.39]],"id":51843546},{"atl":[[150,4],[1000,0.17]],"id":51843546},{"spn":77.1,"spf":"NaN","id":51843546},{"atb":[[1.92,6],[1.01,32.95],[2.06,11.43]],"id":69979297},{"atl":[[150,4],[21,4],[11.5,2],[990,0.17],[15.5,3]],"id":69979297},{"spn":6.78,"spf":"NaN","id":69979297}],"con":true,"img":true}]}
{"op":"mcm","clk":"11539875473","pt":1719487263937,"mc":[{"id":"1.230180130","rc":[{"atl":[[32,8]],"id":58149406},{"spn":17.52,"spf":"NaN","id":58149406},{"spn":76.77,"spf":"NaN","id":66499052},{"atl":[[17.5,8]],"id":69979297}],"con":true,"img":false}]}
{"op":"mcm","clk":"11539875484","pt":1719487264040,"mc":[{"id":"1.230180130","rc":[{"atl":[[55,12]],"id":58149406},{"atl":[[30,12]],"id":69979297}],"con":true,"img":false}]}
{"op":"mcm","clk":"11540014531","pt":1719489000769,"mc":[{"id":"1.230180130","rc":[{"atl":[[560,2]],"id":58149406},{"atb":[[1.16,150]],"id":41138102},{"atl":[[550,2]],"id":41138102},{"atb":[[1.16,150]],"id":43210435},{"atl":[[390,2]],"id":43210435},{"atb":[[1.16,150]],"id":66499052},{"atl":[[370,2]],"id":66499052},{"atl":[[270,2]],"id":69979297}],"con":true,"img":false}]}
{"op":"mcm","clk":"11540014539","pt":1719489000869,"mc":[{"id":"1.230180130","rc":[{"atb":[[1.16,150]],"id":58149406},{"atl":[[500,2]],"id":51843546},{"atb":[[1.16,150]],"id":69979297}],"con":true,"img":false}]}
{"op":"mcm","clk":"11540014550","pt":1719489000973,"mc":[{"id":"1.230180130","rc":[{"atb":[[1.16,150]],"id":51843546}],"con":true,"img":false}]}
{"op":"mcm","clk":"11540176912","pt":1719490864193,"mc":[{"id":"1.230180130","rc":[{"atb":[[3.05,6.54],[4.7,1]],"id":58149406},{"spn":18.35,"spf":"NaN","id":58149406},{"atb":[[5,1]],"id":41138102},{"spn":77.5,"spf":"NaN","id":41138102},{"atb":[[5,1]],"id":43210435},{"spn":77.5,"spf":"NaN","id":43210435},{"atb":[[5,1]],"id":66499052},{"spn":77.5,"spf":"NaN","id":66499052},{"atb":[[5,1]],"id":51843546},{"spn":77.5,"spf":"NaN","id":51843546},{"atb":[[2.74,1.29]],"id":69979297},{"spn":7.12,"spf":"NaN","id":69979297}],"con":true,"img":false}]}
{"op":"mcm","clk":"11540177268","pt":1719490869406,"mc":[{"id":"1.230180130","rc":[{"atb":[[1.51,196.08]],"id":58149406},{"atb":[[1.51,196.08]],"id":41138102},{"atb":[[1.51,196.08]],"id":43210435},{"atb":[[1.51,196.08]],"id":66499052},{"atb":[[1.51,196.08]],"id":51843546}],"con":true,"img":false}]}
{"op":"mcm","clk":"11540243281","pt":1719491824498,"mc":[{"id":"1.230180130","rc":[{"atb":[[2.12,89.29]],"id":41138102},{"atb":[[2.12,89.29]],"id":43210435},{"atb":[[2.12,89.29]],"id":66499052},{"atb":[[2.12,89.29]],"id":51843546}],"con":true,"img":false}]}
{"op":"mcm","clk":"11540435731","pt":1719494482008,"mc":[{"id":"1.230180130","rc":[{"atb":[[1.01,32.99],[2.2,13.08],[3.05,6.54]],"id":58149406},{"atl":[[990,0.17]],"id":58149406},{"atb":[[1.01,32.99],[2.26,12.56]],"id":41138102},{"atl":[[990,0.17]],"id":41138102},{"atb":[[1.03,11],[2.16,10.26]],"id":43210435},{"atl":[[1000,0.17]],"id":43210435},{"atb":[[1.03,11],[2.18,9.5]],"id":66499052},{"atl":[[1000,0.17]],"id":66499052},{"atb":[[1.01,32.99],[2.16,9.4]],"id":51843546},{"atl":[[1000,0.17]],"id":51843546},{"atb":[[1.01,32.99],[2.06,11.45]],"id":69979297},{"atl":[[34,18],[990,0.17]],"id":69979297}],"con":true,"img":false}]}
{"op":"mcm","clk":"11540687355","pt":1719497282744,"mc":[{"id":"1.230180130","marketDefinition":{"bspMarket":true,"turnInPlayEnabled":false,"persistenceEnabled":false,"marketBaseRate":5.0,"eventId":"33376437","eventTypeId":"4339","numberOfWinners":1,"bettingType":"ODDS","marketType":"WIN","marketTime":"2024-06-27T16:21:00.000Z","suspendTime":"2024-06-27T16:21:00.000Z","bspReconciled":false,"complete":true,"inPlay":false,"crossMatching":true,"runnersVoidable":false,"numberOfActiveRunners":6,"betDelay":0,"status":"OPEN","runners":[{"status":"ACTIVE","sortPriority":1,"id":66499052,"name":"1. Salacres Wild"},{"status":"ACTIVE","sortPriority":2,"id":43210435,"name":"2. Bemyangelrosa"},{"status":"ACTIVE","sortPriority":3,"id":41138102,"name":"3. Traptoline Zorro"},{"status":"ACTIVE","sortPriority":4,"id":69979297,"name":"4. Jacktavern Pele"},{"status":"ACTIVE","sortPriority":5,"id":58149406,"name":"5. Salacres Herbert"},{"status":"ACTIVE","sortPriority":6,"id":51843546,"name":"6. Salacres Maybach"}],"regulators":["MR_INT"],"venue":"Towcester","countryCode":"GB","discountAllowed":true,"timezone":"Europe/London","openDate":"2024-06-27T13:33:00.000Z","version":5994767063,"name":"D2 270m","eventName":"Towcester 27th Jun"},"rc":[{"atb":[[1.01,32.98],[1.16,150],[3,6],[2.2,13.07],[1.51,196.08],[3.05,6.54],[4.7,1]],"id":58149406},{"atl":[[32,8],[560,2],[150,4],[55,12],[990,0.17]],"id":58149406},{"spn":18.35,"spf":"NaN","id":58149406},{"atb":[[1.01,32.98],[5,1],[1.16,150],[2.12,89.29],[2.26,12.56],[1.51,196.08],[3.9,6]],"id":41138102},{"atl":[[550,2],[150,4],[990,0.17]],"id":41138102},{"spn":77.5,"spf":"NaN","id":41138102},{"atb":[[5,1],[1.16,150],[1.03,10.99],[2.12,89.29],[3.55,6],[1.51,196.08],[2.16,10.26]],"id":43210435},{"atl":[[150,4],[390,2],[1000,0.17]],"id":43210435},{"spn":77.5,"spf":"NaN","id":43210435},{"atb":[[5,1],[1.16,150],[1.03,10.99],[2.12,89.29],[2.18,9.49],[3.55,6],[1.51,196.08]],"id":66499052},{"atl":[[150,4],[370,2],[1000,0.17]],"id":66499052},{"spn":77.5,"spf":"NaN","id":66499052},{"atb":[[1.01,32.98],[5,1],[1.16,150],[2.12,89.29],[1.51,196.08],[4.2,6],[2.16,9.4]],"id":51843546},{"atl":[[150,4],[500,2],[1000,0.17]],"id":51843546},{"spn":77.5,"spf":"NaN","id":51843546},{"atb":[[1.92,6],[1.01,32.98],[2.74,1.29],[2.06,11.44],[1.16,150]],"id":69979297},{"atl":[[270,2],[17.5,8],[34,18],[150,4],[21,4],[11.5,2],[30,12],[990,0.17],[15.5,3]],"id":69979297},{"spn":7.12,"spf":"NaN","id":69979297}],"con":true,"img":true}]}
{"op":"mcm","clk":"11540724517","pt":1719497699369,"mc":[{"id":"1.230180130","rc":[{"atb":[[1.01,32.98],[2.2,13.07],[3.05,6.54]],"id":58149406},{"atb":[[1.01,32.98],[2.26,12.56]],"id":41138102},{"atb":[[1.03,10.99],[2.16,10.26]],"id":43210435},{"atb":[[1.03,10.99],[2.18,9.49]],"id":66499052},{"atb":[[1.01,32.98],[2.16,9.4]],"id":51843546},{"spl":[[1.01,1]],"id":69979297},{"atb":[[1.01,32.98],[2.06,11.44]],"id":69979297},{"spn":2.74,"spf":1.0,"id":69979297}],"con":true,"img":false}]}
{"op":"mcm","clk":"11540933164","pt":1719500140996,"mc":[{"id":"1.230180130","rc":[{"atb":[[1.04,139.68]],"id":58149406},{"atl":[[980,1.65]],"id":58149406},{"atb":[[1.02,117.67]],"id":41138102},{"atl":[[960,1.98]],"id":41138102},{"atb":[[1.03,193.86]],"id":43210435},{"atl":[[960,1.04]],"id":43210435},{"atb":[[1.04,107.51]],"id":66499052},{"atl":[[990,1.18]],"id":66499052},{"atb":[[1.03,155.77]],"id":51843546},{"atl":[[970,0.87]],"id":51843546},{"atb":[[1.04,70.26]],"id":69979297},{"atl":[[970,0.87]],"id":69979297}],"con":true,"img":false}]}
{"op":"mcm","clk":"11541142963","pt":1719502682762,"mc":[{"id":"1.230180130","marketDefinition":{"bspMarket":true,"turnInPlayEnabled":false,"persistenceEnabled":false,"marketBaseRate":5.0,"eventId":"33376437","eventTypeId":"4339","numberOfWinners":1,"bettingType":"ODDS","marketType":"WIN","marketTime":"2024-06-27T16:21:00.000Z","suspendTime":"2024-06-27T16:21:00.000Z","bspReconciled":false,"complete":true,"inPlay":false,"crossMatching":true,"runnersVoidable":false,"numberOfActiveRunners":6,"betDelay":0,"status":"OPEN","runners":[{"status":"ACTIVE","sortPriority":1,"id":66499052,"name":"1. Salacres Wild"},{"status":"ACTIVE","sortPriority":2,"id":43210435,"name":"2. Bemyangelrosa"},{"status":"ACTIVE","sortPriority":3,"id":41138102,"name":"3. Traptoline Zorro"},{"status":"ACTIVE","sortPriority":4,"id":69979297,"name":"4. Jacktavern Pele"},{"status":"ACTIVE","sortPriority":5,"id":58149406,"name":"5. Salacres Herbert"},{"status":"ACTIVE","sortPriority":6,"id":51843546,"name":"6. Salacres Maybach"}],"regulators":["MR_INT"],"venue":"Towcester","countryCode":"GB","discountAllowed":true,"timezone":"Europe/London","openDate":"2024-06-27T13:33:00.000Z","version":5994767063,"name":"D2 270m","eventName":"Towcester 27th Jun"},"rc":[{"atb":[[1.01,32.98],[1.16,150],[3,6],[2.2,13.08],[1.51,196.08],[3.05,6.54],[1.04,139.71],[4.7,1]],"id":58149406},{"atl":[[32,8],[560,2],[150,4],[55,12],[980,1.65],[990,0.17]],"id":58149406},{"spn":18.35,"spf":"NaN","id":58149406},{"atb":[[1.01,32.98],[5,1],[1.16,150],[1.02,117.69],[2.12,89.29],[2.26,12.56],[1.51,196.08],[3.9,6]],"id":41138102},{"atl":[[550,2],[150,4],[960,1.98],[990,0.17]],"id":41138102},{"spn":77.5,"spf":"NaN","id":41138102},{"atb":[[5,1],[1.16,150],[1.03,193.89],[2.12,89.29],[3.55,6],[1.51,196.08],[2.16,10.26]],"id":43210435},{"atl":[[150,4],[390,2],[960,1.04],[1000,0.17]],"id":43210435},{"spn":77.5,"spf":"NaN","id":43210435},{"atb":[[5,1],[1.16,150],[1.03,10.99],[2.12,89.29],[2.18,9.5],[3.55,6],[1.51,196.08],[1.04,107.53]],"id":66499052},{"atl":[[150,4],[370,2],[990,1.18],[1000,0.17]],"id":66499052},{"spn":77.5,"spf":"NaN","id":66499052},{"atb":[[1.01,32.98],[5,1],[1.16,150],[1.03,155.8],[2.12,89.29],[1.51,196.08],[4.2,6],[2.16,9.4]],"id":51843546},{"atl":[[150,4],[970,0.87],[500,2],[1000,0.17]],"id":51843546},{"spn":77.5,"spf":"NaN","id":51843546},{"spl":[[1.01,1]],"id":69979297},{"atb":[[1.92,6],[1.01,32.98],[2.74,1.29],[2.06,11.44],[1.16,150],[1.04,70.27]],"id":69979297},{"atl":[[270,2],[17.5,8],[34,18],[150,4],[21,4],[11.5,2],[30,12],[970,0.87],[990,0.17],[15.5,3]],"id":69979297},{"spn":2.74,"spf":1.0,"id":69979297}],"con":true,"img":true}]}
{"op":"mcm","clk":"11541167415","pt":1719502956355,"mc":[{"id":"1.230180130","rc":[{"atb":[[1.01,32.98],[2.2,13.08],[3.05,6.54],[1.04,139.71]],"id":58149406},{"atl":[[980,1.65],[30,1.54]],"id":58149406},{"spn":17.35,"spf":"NaN","id":58149406},{"atb":[[1.01,32.98],[1.02,117.69],[2.26,12.56]],"id":41138102},{"atl":[[960,1.98]],"id":41138102},{"atb":[[1.03,193.89],[2.16,10.26]],"id":43210435},{"atl":[[960,1.04]],"id":43210435},{"atb":[[1.03,10.99],[2.18,9.5],[1.04,107.53]],"id":66499052},{"atl":[[990,1.18]],"id":66499052},{"atb":[[1.01,32.98],[1.03,155.8],[2.16,9.4]],"id":51843546},{"atl":[[970,0.87]],"id":51843546},{"atb":[[1.01,32.98],[2.06,11.44],[1.04,70.27]],"id":69979297},{"atl":[[970,0.87]],"id":69979297}],"con":true,"img":false}]}
{"op":"mcm","clk":"11541167438","pt":1719502956620,"mc":[{"id":"1.230180130","rc":[{"atl":[[11,1.67]],"id":69979297}],"con":true,"img":false}]}
{"op":"mcm","clk":"11541246751","pt":1719503765407,"mc":[{"id":"1.230180130","rc":[{"atl":[[190,4]],"id":58149406},{"atl":[[190,4]],"id":41138102},{"atl":[[190,4]],"id":43210435},{"atl":[[190,4]],"id":66499052},{"atl":[[190,4]],"id":51843546},{"atl":[[190,4]],"id":69979297}],"con":true,"img":false}]}
{"op":"mcm","clk":"11541250738","pt":1719503805825,"mc":[{"id":"1.230180130","rc":[{"atb":[[1.02,2]],"id":66499052}],"con":true,"img":false}]}
{"op":"mcm","clk":"11541250777","pt":1719503806236,"mc":[{"id":"1.230180130","rc":[{"atb":[[1.02,2]],"id":43210435}],"con":true,"img":false}]}
{"op":"mcm","clk":"11541250790","pt":1719503806442,"mc":[{"id":"1.230180130","rc":[{"atb":[[1.02,119.69]],"id":41138102}],"con":true,"img":false}]}
{"op":"mcm","clk":"11541250809","pt":1719503806612,"mc":[{"id":"1.230180130","rc":[{"atb":[[1.02,2]],"id":69979297}],"con":true,"img":false}]}
{"op":"mcm","clk":"11541250837","pt":1719503806909,"mc":[{"id":"1.230180130","rc":[{"atb":[[1.02,2]],"id":58149406}],"con":true,"img":false}]}
{"op":"mcm","clk":"11541250853","pt":1719503807129,"mc":[{"id":"1.230180130","rc":[{"atb":[[1.02,2]],"id":51843546}],"con":true,"img":false}]}
{"op":"mcm","clk":"11541253244","pt":1719503830951,"mc":[{"id":"1.230180130","rc":[{"spl":[[1.01,4]],"id":66499052},{"spn":3.91,"spf":1.0,"id":66499052}],"con":true,"img":false}]}
{"op":"mcm","clk":"11541261080","pt":1719503902218,"mc":[{"id":"1.230180130","rc":[{"atl":[[44,6.36]],"id":69979297}],"con":true,"img":false}]}
{"op":"mcm","clk":"11541282787","pt":1719504108005,"mc":[{"id":"1.230180130","rc":[{"atb":[[1.01,32.97],[2.2,13.07],[3.05,6.54],[1.04,139.64]],"id":58149406},{"atl":[[29,0.84],[980,1.65]],"id":58149406},{"spn":16.85,"spf":"NaN","id":58149406},{"atb":[[1.01,32.97],[1.02,119.63],[2.26,12.55]],"id":41138102},{"atl":[[960,1.98]],"id":41138102},{"atb":[[1.03,193.79],[2.16,10.25]],"id":43210435},{"atl":[[960,1.04]],"id":43210435},{"atb":[[1.03,10.99],[2.18,9.49],[1.04,107.48]],"id":66499052},{"atl":[[990,1.18]],"id":66499052},{"atb":[[1.01,32.97],[1.03,155.72],[2.16,9.4]],"id":51843546},{"atl":[[970,0.87]],"id":51843546},{"atb":[[1.01,32.97],[2.06,11.44],[1.04,70.24]],"id":69979297},{"atl":[[10.5,0.84],[970,0.87]],"id":69979297}],"con":true,"img":false}]}
{"op":"mcm","clk":"11541285250","pt":1719504132832,"mc":[{"id":"1.230180130","rc":[{"atb":[[2.74,0]],"id":69979297},{"trd":[[2.74,2.58]],"ltp":2.74,"tv":2.58,"id":69979297}],"con":true,"img":false}]}
{"op":"mcm","clk":"11541285507","pt":1719504135226,"mc":[{"id":"1.230180130","rc":[{"atb":[[1.03,1]],"id":69979297},{"atl":[[1000,0.11]],"id":69979297}],"con":true,"img":false}]}
{"op":"mcm","clk":"11541285530","pt":1719504135437,"mc":[{"id":"1.230180130","rc":[{"atb":[[1.03,0.93]],"id":69979297},{"atl":[[1000,0]],"id":69979297}],"con":true,"img":false}]}
{"op":"mcm","clk":"11541285552","pt":1719504135544,"mc":[{"id":"1.230180130","rc":[{"atl":[[10.5,0.95]],"id":69979297}],"con":true,"img":false}]}
{"op":"mcm","clk":"11541285567","pt":1719504135653,"mc":[{"id":"1.230180130","rc":[{"atb":[[1.03,0]],"id":69979297}],"con":true,"img":false}]}
{"op":"mcm","clk":"11541285579","pt":1719504135751,"mc":[{"id":"1.230180130","rc":[{"atb":[[2.08,0.93]],"id":69979297}],"con":true,"img":false}]}
{"op":"mcm","clk":"11541285590","pt":1719504135808,"mc":[{"id":"1.230180130","rc":[{"atb":[[2.64,1.37]],"id":69979297}],"con":true,"img":false}]}
{"op":"mcm","clk":"11541287099","pt":1719504150727,"mc":[{"id":"1.230180130","rc":[{"atl":[[10.5,0.84]],"id":69979297}],"con":true,"img":false}]}
{"op":"mcm","clk":"11541287116","pt":1719504150936,"mc":[{"id":"1.230180130","rc":[{"atb":[[2.08,0]],"id":69979297}],"con":true,"img":false}]}
{"op":"mcm","clk":"11541287143","pt":1719504151249,"mc":[{"id":"1.230180130","rc":[{"atl":[[1000,0.11]],"id":69979297}],"con":true,"img":false}]}
{"op":"mcm","clk":"11541287165","pt":1719504151457,"mc":[{"id":"1.230180130","rc":[{"atl":[[1000,0]],"id":69979297}],"con":true,"img":false}]}
{"op":"mcm","clk":"11541287174","pt":1719504151561,"mc":[{"id":"1.230180130","rc":[{"atl":[[10.5,0.95]],"id":69979297}],"con":true,"img":false}]}
{"op":"mcm","clk":"11541288767","pt":1719504166794,"mc":[{"id":"1.230180130","rc":[{"atl":[[10.5,0.84]],"id":69979297}],"con":true,"img":false}]}
{"op":"mcm","clk":"11541288915","pt":1719504168088,"mc":[{"id":"1.230180130","rc":[{"atl":[[1000,0.11]],"id":69979297},{"spn":2.64,"spf":1.0,"id":69979297}],"con":true,"img":false}]}
{"op":"mcm","clk":"11541288937","pt":1719504168291,"mc":[{"id":"1.230180130","rc":[{"atl":[[1000,0]],"id":69979297}],"con":true,"img":false}]}
{"op":"mcm","clk":"11541288949","pt":1719504168399,"mc":[{"id":"1.230180130","rc":[{"atl":[[10.5,0.95]],"id":69979297}],"con":true,"img":false}]}
{"op":"mcm","clk":"11541290755","pt":1719504183595,"mc":[{"id":"1.230180130","rc":[{"atl":[[10.5,0.84]],"id":69979297}],"con":true,"img":false}]}
{"op":"mcm","clk":"11541290786","pt":1719504183906,"mc":[{"id":"1.230180130","rc":[{"atl":[[1000,0.11]],"id":69979297}],"con":true,"img":false}]}
{"op":"mcm","clk":"11541290814","pt":1719504184121,"mc":[{"id":"1.230180130","rc":[{"atl":[[1000,0]],"id":69979297}],"con":true,"img":false}]}
{"op":"mcm","clk":"11541290827","pt":1719504184223,"mc":[{"id":"1.230180130","rc":[{"atl":[[10.5,0.95]],"id":69979297}],"con":true,"img":false}]}
{"op":"mcm","clk":"11541292632","pt":1719504199343,"mc":[{"id":"1.230180130","rc":[{"atl":[[10.5,0.84]],"id":69979297}],"con":true,"img":false}]}
{"op":"mcm","clk":"11541292654","pt":1719504199515,"mc":[{"id":"1.230180130","rc":[{"atl":[[1000,0.11]],"id":69979297}],"con":true,"img":false}]}
{"op":"mcm","clk":"11541292663","pt":1719504199609,"mc":[{"id":"1.230180130","rc":[{"atl":[[1000,0]],"id":69979297}],"con":true,"img":false}]}
{"op":"mcm","clk":"11541292669","pt":1719504199721,"mc":[{"id":"1.230180130","rc":[{"atl":[[10.5,0.95]],"id":69979297}],"con":true,"img":false}]}
{"op":"mcm","clk":"11541294358","pt":1719504214937,"mc":[{"id":"1.230180130","rc":[{"atl":[[10.5,0.84]],"id":69979297}],"con":true,"img":false}]}
{"op":"mcm","clk":"11541294378","pt":1719504215146,"mc":[{"id":"1.230180130","rc":[{"atl":[[1000,0.11]],"id":69979297}],"con":true,"img":false}]}
{"op":"mcm","clk":"11541294401","pt":1719504215349,"mc":[{"id":"1.230180130","rc":[{"atl":[[1000,0]],"id":69979297}],"con":true,"img":false}]}
{"op":"mcm","clk":"11541294414","pt":1719504215458,"mc":[{"id":"1.230180130","rc":[{"atl":[[10.5,0.95]],"id":69979297}],"con":true,"img":false}]}
{"op":"mcm","clk":"11541296136","pt":1719504230555,"mc":[{"id":"1.230180130","rc":[{"atl":[[10.5,0.84]],"id":69979297}],"con":true,"img":false}]}
{"op":"mcm","clk":"11541296163","pt":1719504230768,"mc":[{"id":"1.230180130","rc":[{"atl":[[1000,0.11]],"id":69979297}],"con":true,"img":false}]}
{"op":"mcm","clk":"11541296192","pt":1719504230986,"mc":[{"id":"1.230180130","rc":[{"atl":[[1000,0]],"id":69979297}],"con":true,"img":false}]}
{"op":"mcm","clk":"11541296203","pt":1719504231077,"mc":[{"id":"1.230180130","rc":[{"atl":[[10.5,0.95]],"id":69979297}],"con":true,"img":false}]}
{"op":"mcm","clk":"11541297918","pt":1719504246307,"mc":[{"id":"1.230180130","rc":[{"atl":[[10.5,0.84]],"id":69979297}],"con":true,"img":false}]}
{"op":"mcm","clk":"11541298021","pt":1719504247205,"mc":[{"id":"1.230180130","rc":[{"atl":[[1000,0.11]],"id":69979297}],"con":true,"img":false}]}
{"op":"mcm","clk":"11541298046","pt":1719504247401,"mc":[{"id":"1.230180130","rc":[{"atl":[[1000,0]],"id":69979297}],"con":true,"img":false}]}
{"op":"mcm","clk":"11541298060","pt":1719504247510,"mc":[{"id":"1.230180130","rc":[{"atl":[[10.5,0.95]],"id":69979297}],"con":true,"img":false}]}
{"op":"mcm","clk":"11541299627","pt":1719504262725,"mc":[{"id":"1.230180130","rc":[{"atl":[[10.5,0.84]],"id":69979297}],"con":true,"img":false}]}
{"op":"mcm","clk":"11541299652","pt":1719504262885,"mc":[{"id":"1.230180130","rc":[{"atl":[[1000,0.11]],"id":69979297}],"con":true,"img":false}]}
{"op":"mcm","clk":"11541299672","pt":1719504263100,"mc":[{"id":"1.230180130","rc":[{"atl":[[1000,0]],"id":69979297}],"con":true,"img":false}]}
{"op":"mcm","clk":"11541299684","pt":1719504263199,"mc":[{"id":"1.230180130","rc":[{"atl":[[10.5,0.95]],"id":69979297}],"con":true,"img":false}]}
{"op":"mcm","clk":"11541301323","pt":1719504278415,"mc":[{"id":"1.230180130","rc":[{"atl":[[10.5,0.84]],"id":69979297}],"con":true,"img":false}]}
{"op":"mcm","clk":"11541301344","pt":1719504278627,"mc":[{"id":"1.230180130","rc":[{"atl":[[1000,0.11]],"id":69979297}],"con":true,"img":false}]}
{"op":"mcm","clk":"11541301373","pt":1719504278837,"mc":[{"id":"1.230180130","rc":[{"atl":[[1000,0]],"id":69979297}],"con":true,"img":false}]}
{"op":"mcm","clk":"11541301382","pt":1719504278941,"mc":[{"id":"1.230180130","rc":[{"atl":[[10.5,0.95]],"id":69979297}],"con":true,"img":false}]}
{"op":"mcm","clk":"11541303028","pt":1719504294134,"mc":[{"id":"1.230180130","rc":[{"atl":[[10.5,0.84]],"id":69979297}],"con":true,"img":false}]}
{"op":"mcm","clk":"11541303167","pt":1719504295272,"mc":[{"id":"1.230180130","rc":[{"atl":[[1000,0.11]],"id":69979297}],"con":true,"img":false}]}
{"op":"mcm","clk":"11541303191","pt":1719504295424,"mc":[{"id":"1.230180130","rc":[{"atl":[[1000,0]],"id":69979297}],"con":true,"img":false}]}
{"op":"mcm","clk":"11541303202","pt":1719504295531,"mc":[{"id":"1.230180130","rc":[{"atl":[[10.5,0.95]],"id":69979297}],"con":true,"img":false}]}
{"op":"mcm","clk":"11541304807","pt":1719504310734,"mc":[{"id":"1.230180130","rc":[{"atl":[[10.5,0.84]],"id":69979297}],"con":true,"img":false}]}
{"op":"mcm","clk":"11541304837","pt":1719504311046,"mc":[{"id":"1.230180130","rc":[{"atl":[[1000,0.11]],"id":69979297}],"con":true,"img":false}]}
{"op":"mcm","clk":"11541304861","pt":1719504311255,"mc":[{"id":"1.230180130","rc":[{"atl":[[1000,0]],"id":69979297}],"con":true,"img":false}]}
{"op":"mcm","clk":"11541304873","pt":1719504311363,"mc":[{"id":"1.230180130","rc":[{"atl":[[10.5,0.95]],"id":69979297}],"con":true,"img":false}]}
{"op":"mcm","clk":"11541306428","pt":1719504326553,"mc":[{"id":"1.230180130","rc":[{"atl":[[10.5,0.84]],"id":69979297}],"con":true,"img":false}]}
{"op":"mcm","clk":"11541306449","pt":1719504326762,"mc":[{"id":"1.230180130","rc":[{"atl":[[1000,0.11]],"id":69979297}],"con":true,"img":false}]}
{"op":"mcm","clk":"11541306470","pt":1719504326980,"mc":[{"id":"1.230180130","rc":[{"atl":[[1000,0]],"id":69979297}],"con":true,"img":false}]}
{"op":"mcm","clk":"11541306479","pt":1719504327073,"mc":[{"id":"1.230180130","rc":[{"atl":[[10.5,0.95]],"id":69979297}],"con":true,"img":false}]}
{"op":"mcm","clk":"11541308061","pt":1719504342293,"mc":[{"id":"1.230180130","rc":[{"atl":[[10.5,0.84]],"id":69979297}],"con":true,"img":false}]}
{"op":"mcm","clk":"11541308080","pt":1719504342506,"mc":[{"id":"1.230180130","rc":[{"atl":[[1000,0.11]],"id":69979297}],"con":true,"img":false}]}
{"op":"mcm","clk":"11541308104","pt":1719504342712,"mc":[{"id":"1.230180130","rc":[{"atl":[[1000,0]],"id":69979297}],"con":true,"img":false}]}
{"op":"mcm","clk":"11541308111","pt":1719504342812,"mc":[{"id":"1.230180130","rc":[{"atl":[[10.5,0.95]],"id":69979297}],"con":true,"img":false}]}
{"op":"mcm","clk":"11541309673","pt":1719504357737,"mc":[{"id":"1.230180130","rc":[{"atb":[[1.12,1.69]],"id":43210435},{"atb":[[1.12,1.69]],"id":66499052}],"con":true,"img":false}]}
{"op":"mcm","clk":"11541309697","pt":1719504357943,"mc":[{"id":"1.230180130","rc":[{"atb":[[1.1,1.69]],"id":58149406},{"atb":[[1.12,1.69]],"id":41138102}],"con":true,"img":false}]}
{"op":"mcm","clk":"11541309708","pt":1719504358048,"mc":[{"id":"1.230180130","rc":[{"atl":[[10.5,0.84]],"id":69979297}],"con":true,"img":false}]}
{"op":"mcm","clk":"11541309719","pt":1719504358103,"mc":[{"id":"1.230180130","rc":[{"atb":[[1.12,0.05]],"id":66499052},{"atb":[[1.12,1.69]],"id":51843546}],"con":true,"img":false}]}
{"op":"mcm","clk":"11541309740","pt":1719504358318,"mc":[{"id":"1.230180130","rc":[{"atb":[[1.06,1.69]],"id":69979297}],"con":true,"img":false}]}
{"op":"mcm","clk":"11541309752","pt":1719504358415,"mc":[{"id":"1.230180130","rc":[{"atb":[[1.12,0.05]],"id":41138102}],"con":true,"img":false}]}
{"op":"mcm","clk":"11541309778","pt":1719504358725,"mc":[{"id":"1.230180130","rc":[{"atb":[[1.12,0.05]],"id":51843546}],"con":true,"img":false}]}
{"op":"mcm","clk":"11541309793","pt":1719504358826,"mc":[{"id":"1.230180130","rc":[{"atb":[[1.1,0.06]],"id":58149406}],"con":true,"img":false}]}
{"op":"mcm","clk":"11541309820","pt":1719504359136,"mc":[{"id":"1.230180130","rc":[{"atb":[[1.12,0]],"id":66499052},{"atl":[[1000,0.11]],"id":69979297}],"con":true,"img":false}]}
{"op":"mcm","clk":"11541309831","pt":1719504359240,"mc":[{"id":"1.230180130","rc":[{"atb":[[5.1,0.05]],"id":66499052}],"con":true,"img":false}]}
{"op":"mcm","clk":"11541309843","pt":1719504359351,"mc":[{"id":"1.230180130","rc":[{"atl":[[1000,0]],"id":69979297}],"con":true,"img":false}]}
{"op":"mcm","clk":"11541309851","pt":1719504359444,"mc":[{"id":"1.230180130","rc":[{"atl":[[10.5,0.95]],"id":69979297}],"con":true,"img":false}]}
{"op":"mcm","clk":"11541309859","pt":1719504359554,"mc":[{"id":"1.230180130","rc":[{"atb":[[1.12,0.05]],"id":43210435},{"atb":[[1.06,0.11]],"id":69979297}],"con":true,"img":false}]}
{"op":"mcm","clk":"11541309891","pt":1719504359810,"mc":[{"id":"1.230180130","rc":[{"atb":[[1.12,0]],"id":41138102}],"con":true,"img":false}]}
{"op":"mcm","clk":"11541309902","pt":1719504359916,"mc":[{"id":"1.230180130","rc":[{"atb":[[5.1,0.05]],"id":41138102}],"con":true,"img":false}]}
{"op":"mcm","clk":"11541309935","pt":1719504360230,"mc":[{"id":"1.230180130","rc":[{"atb":[[3.95,12.56]],"id":41138102},{"atl":[[140,2]],"id":41138102},{"atb":[[3.4,41.67]],"id":66499052},{"atl":[[120,2]],"id":66499052},{"atb":[[1.12,0]],"id":51843546}],"con":true,"img":false}]}
{"op":"mcm","clk":"11541309943","pt":1719504360333,"mc":[{"id":"1.230180130","rc":[{"atb":[[3.1,6.55]],"id":58149406},{"atl":[[30,4.99]],"id":58149406},{"atb":[[3.6,10.26]],"id":43210435},{"atl":[[140,2]],"id":43210435},{"atb":[[5.1,0.05],[4.3,9.4]],"id":51843546},{"atl":[[140,2]],"id":51843546},{"atb":[[2,12.81]],"id":69979297},{"atl":[[11,3.67]],"id":69979297}],"con":true,"img":false}]}
{"op":"mcm","clk":"11541309974","pt":1719504360655,"mc":[{"id":"1.230180130","rc":[{"atb":[[1.1,0]],"id":58149406}],"con":true,"img":false}]}
{"op":"mcm","clk":"11541309984","pt":1719504360748,"mc":[{"id":"1.230180130","rc":[{"atb":[[4.8,0.06]],"id":58149406}],"con":true,"img":false}]}
{"op":"mcm","clk":"11541310014","pt":1719504361013,"mc":[{"id":"1.230180130","rc":[{"atb":[[1.06,0]],"id":69979297}],"con":true,"img":false}]}
{"op":"mcm","clk":"11541310025","pt":1719504361115,"mc":[{"id":"1.230180130","rc":[{"atb":[[2.66,0.11]],"id":69979297}],"con":true,"img":false}]}
{"op":"mcm","clk":"11541310061","pt":1719504361429,"mc":[{"id":"1.230180130","rc":[{"atb":[[1.12,0]],"id":43210435}],"con":true,"img":false}]}
{"op":"mcm","clk":"11541310071","pt":1719504361541,"mc":[{"id":"1.230180130","rc":[{"atb":[[5.1,0.05]],"id":43210435}],"con":true,"img":false}]}
{"op":"mcm","clk":"11541310152","pt":1719504362213,"mc":[{"id":"1.230180130","rc":[{"atl":[[12.5,1]],"id":66499052},{"atl":[[4.4,1]],"id":69979297}],"con":true,"img":false}]}
{"op":"mcm","clk":"11541310298","pt":1719504363725,"mc":[{"id":"1.230180130","rc":[{"atb":[[1.03,1.7]],"id":41138102},{"atl":[[1000,1.7]],"id":41138102},{"atb":[[1.02,3.7]],"id":43210435},{"atl":[[1000,1.87]],"id":43210435},{"atb":[[1.02,3.7]],"id":66499052},{"atl":[[1000,1.87]],"id":66499052}],"con":true,"img":false}]}
{"op":"mcm","clk":"11541310328","pt":1719504364033,"mc":[{"id":"1.230180130","rc":[{"atb":[[1.03,0.1]],"id":41138102},{"atl":[[1000,0]],"id":41138102},{"atb":[[1.02,2.12]],"id":43210435},{"atl":[[1000,0.17]],"id":43210435},{"atb":[[1.02,2.12]],"id":66499052},{"atl":[[1000,0.17]],"id":66499052}],"con":true,"img":false}]}
{"op":"mcm","clk":"11541310352","pt":1719504364241,"mc":[{"id":"1.230180130","rc":[{"atb":[[1.02,2]],"id":66499052}],"con":true,"img":false}]}
{"op":"mcm","clk":"11541310361","pt":1719504364340,"mc":[{"id":"1.230180130","rc":[{"atb":[[1.03,0]],"id":41138102},{"atb":[[1.02,2]],"id":43210435},{"atb":[[3.6,0.12]],"id":66499052}],"con":true,"img":false}]}
{"op":"mcm","clk":"11541310371","pt":1719504364442,"mc":[{"id":"1.230180130","rc":[{"atb":[[4,0.1]],"id":41138102},{"atb":[[3.65,0.12]],"id":43210435}],"con":true,"img":false}]}
{"op":"mcm","clk":"11541310964","pt":1719504370462,"mc":[{"id":"1.230180130","rc":[{"atb":[[2,0],[2.12,11.44]],"id":69979297}],"con":true,"img":false}]}
{"op":"mcm","clk":"11541311109","pt":1719504372232,"mc":[{"id":"1.230180130","rc":[{"atl":[[11,1],[12.5,0]],"id":66499052}],"con":true,"img":false}]}
{"op":"mcm","clk":"11541311154","pt":1719504372752,"mc":[{"id":"1.230180130","rc":[{"atb":[[3.05,3.38]],"id":58149406}],"con":true,"img":false}]}
{"op":"mcm","clk":"11541311324","pt":1719504374723,"mc":[{"id":"1.230180130","rc":[{"atl":[[10.5,0.84]],"id":69979297}],"con":true,"img":false}]}
{"op":"mcm","clk":"11541311344","pt":1719504374931,"mc":[{"id":"1.230180130","rc":[{"atl":[[1000,0.3]],"id":69979297}],"con":true,"img":false}]}
{"op":"mcm","clk":"11541311361","pt":1719504375137,"mc":[{"id":"1.230180130","rc":[{"atl":[[1000,0]],"id":69979297}],"con":true,"img":false}]}
{"op":"mcm","clk":"11541311372","pt":1719504375242,"mc":[{"id":"1.230180130","rc":[{"atl":[[4.3,0.3]],"id":69979297}],"con":true,"img":false}]}
{"op":"mcm","clk":"11541311811","pt":1719504380070,"mc":[{"id":"1.230180130","rc":[{"atb":[[3.05,0]],"id":58149406}],"con":true,"img":false}]}
{"op":"mcm","clk":"11541311833","pt":1719504380271,"mc":[{"id":"1.230180130","rc":[{"atb":[[1.9,2.31]],"id":69979297}],"con":true,"img":false}]}
{"op":"mcm","clk":"11541311853","pt":1719504380479,"mc":[{"id":"1.230180130","rc":[{"atb":[[1.9,0]],"id":69979297}],"con":true,"img":false}]}
{"op":"mcm","clk":"11541312004","pt":1719504382241,"mc":[{"id":"1.230180130","rc":[{"atl":[[11,0],[12.5,1]],"id":66499052}],"con":true,"img":false}]}
{"op":"mcm","clk":"11541312730","pt":1719504390481,"mc":[{"id":"1.230180130","rc":[{"atl":[[4.3,0]],"id":69979297}],"con":true,"img":false}]}
{"op":"mcm","clk":"11541312808","pt":1719504391466,"mc":[{"id":"1.230180130","rc":[{"atl":[[1000,0.3]],"id":69979297}],"con":true,"img":false}]}
{"op":"mcm","clk":"11541312827","pt":1719504391672,"mc":[{"id":"1.230180130","rc":[{"atl":[[1000,0]],"id":69979297}],"con":true,"img":false}]}
{"op":"mcm","clk":"11541312835","pt":1719504391782,"mc":[{"id":"1.230180130","rc":[{"atl":[[4.3,0.3]],"id":69979297}],"con":true,"img":false}]}
{"op":"mcm","clk":"11541313860","pt":1719504403803,"mc":[{"id":"1.230180130","rc":[{"atb":[[4,0]],"id":41138102},{"atb":[[3.65,0]],"id":43210435},{"atb":[[3.6,0]],"id":66499052}],"con":true,"img":false}]}
{"op":"mcm","clk":"11541314167","pt":1719504407068,"mc":[{"id":"1.230180130","rc":[{"atl":[[4.3,0]],"id":69979297}],"con":true,"img":false}]}
{"op":"mcm","clk":"11541314188","pt":1719504407276,"mc":[{"id":"1.230180130","rc":[{"atl":[[1000,0.3]],"id":69979297}],"con":true,"img":false}]}
{"op":"mcm","clk":"11541314212","pt":1719504407583,"mc":[{"id":"1.230180130","rc":[{"atl":[[1000,0]],"id":69979297}],"con":true,"img":false}]}
{"op":"mcm","clk":"11541314224","pt":1719504407686,"mc":[{"id":"1.230180130","rc":[{"atl":[[4.3,0.3]],"id":69979297}],"con":true,"img":false}]}
{"op":"mcm","clk":"11541314440","pt":1719504409917,"mc":[{"id":"1.230180130","rc":[{"atl":[[130,0.84]],"id":41138102},{"atl":[[130,0.84]],"id":43210435},{"atl":[[130,0.84]],"id":51843546},{"atl":[[10.5,0]],"id":69979297}],"con":true,"img":false}]}
{"op":"mcm","clk":"11541315745","pt":1719504422920,"mc":[{"id":"1.230180130","rc":[{"spn":16.9,"spf":"NaN","id":58149406},{"spn":67.55,"spf":"NaN","id":41138102},{"spn":67.55,"spf":"NaN","id":43210435},{"spn":3.93,"spf":1.0,"id":66499052},{"spn":67.55,"spf":"NaN","id":51843546},{"atl":[[4.3,0]],"id":69979297},{"spn":2.64,"spf":1.0,"id":69979297}],"con":true,"img":false}]}
{"op":"mcm","clk":"11541315831","pt":1719504423805,"mc":[{"id":"1.230180130","rc":[{"atl":[[1000,0.3]],"id":69979297}],"con":true,"img":false}]}
{"op":"mcm","clk":"11541315852","pt":1719504424006,"mc":[{"id":"1.230180130","rc":[{"atl":[[1000,0]],"id":69979297}],"con":true,"img":false}]}
{"op":"mcm","clk":"11541315866","pt":1719504424109,"mc":[{"id":"1.230180130","rc":[{"atl":[[4.3,0.3]],"id":69979297}],"con":true,"img":false}]}
{"op":"mcm","clk":"11541317242","pt":1719504439444,"mc":[{"id":"1.230180130","rc":[{"atl":[[4.3,0]],"id":69979297}],"con":true,"img":false}]}
{"op":"mcm","clk":"11541317263","pt":1719504439652,"mc":[{"id":"1.230180130","rc":[{"atl":[[1000,0.3]],"id":69979297}],"con":true,"img":false}]}
{"op":"mcm","clk":"11541317296","pt":1719504439969,"mc":[{"id":"1.230180130","rc":[{"atl":[[1000,0]],"id":69979297}],"con":true,"img":false}]}
{"op":"mcm","clk":"11541317309","pt":1719504440031,"mc":[{"id":"1.230180130","rc":[{"atl":[[4.3,0.3]],"id":69979297}],"con":true,"img":false}]}
{"op":"mcm","clk":"11541317496","pt":1719504442251,"mc":[{"id":"1.230180130","rc":[{"atb":[[5,2.02]],"id":51843546}],"con":true,"img":false}]}
{"op":"mcm","clk":"11541317505","pt":1719504442352,"mc":[{"id":"1.230180130","rc":[{"atb":[[4.3,0],[5,8.02]],"id":51843546}],"con":true,"img":false}]}
{"op":"mcm","clk":"11541318585","pt":1719504455352,"mc":[{"id":"1.230180130","rc":[{"atl":[[4.3,0]],"id":69979297}],"con":true,"img":false}]}
{"op":"mcm","clk":"11541318692","pt":1719504456546,"mc":[{"id":"1.230180130","rc":[{"atl":[[1000,0.3]],"id":69979297}],"con":true,"img":false}]}
{"op":"mcm","clk":"11541318712","pt":1719504456755,"mc":[{"id":"1.230180130","rc":[{"atl":[[1000,0]],"id":69979297}],"con":true,"img":false}]}
{"op":"mcm","clk":"11541318720","pt":1719504456860,"mc":[{"id":"1.230180130","rc":[{"atl":[[4.3,0.3]],"id":69979297}],"con":true,"img":false}]}
{"op":"mcm","clk":"11541319417","pt":1719504465775,"mc":[{"id":"1.230180130","rc":[{"atb":[[5.1,0.9]],"id":51843546}],"con":true,"img":false}]}
{"op":"mcm","clk":"11541319875","pt":1719504472164,"mc":[{"id":"1.230180130","rc":[{"atl":[[4.3,0]],"id":69979297}],"con":true,"img":false}]}
{"op":"mcm","clk":"11541319892","pt":1719504472484,"mc":[{"id":"1.230180130","rc":[{"atl":[[1000,0.3]],"id":69979297}],"con":true,"img":false}]}
{"op":"mcm","clk":"11541319909","pt":1719504472689,"mc":[{"id":"1.230180130","rc":[{"atl":[[1000,0]],"id":69979297}],"con":true,"img":false}]}
{"op":"mcm","clk":"11541319916","pt":1719504472785,"mc":[{"id":"1.230180130","rc":[{"atl":[[4.3,0.3]],"id":69979297}],"con":true,"img":false}]}
{"op":"mcm","clk":"11541320491","pt":1719504480491,"mc":[{"id":"1.230180130","rc":[{"atb":[[5.1,0]],"id":66499052}],"con":true,"img":false}]}
{"op":"mcm","clk":"11541320523","pt":1719504480809,"mc":[{"id":"1.230180130","rc":[{"atb":[[5.1,0]],"id":43210435}],"con":true,"img":false}]}
{"op":"mcm","clk":"11541320547","pt":1719504481069,"mc":[{"id":"1.230180130","rc":[{"atb":[[5.1,0]],"id":41138102}],"con":true,"img":false}]}
{"op":"mcm","clk":"11541320568","pt":1719504481376,"mc":[{"id":"1.230180130","rc":[{"atb":[[2.66,0]],"id":69979297}],"con":true,"img":false}]}
{"op":"mcm","clk":"11541320587","pt":1719504481687,"mc":[{"id":"1.230180130","rc":[{"atb":[[4.8,0]],"id":58149406}],"con":true,"img":false}]}
{"op":"mcm","clk":"11541320609","pt":1719504482001,"mc":[{"id":"1.230180130","rc":[{"atb":[[5.1,0.84]],"id":51843546}],"con":true,"img":false}]}
{"op":"mcm","clk":"11541320631","pt":1719504482273,"mc":[{"id":"1.230180130","rc":[{"atb":[[1.12,1.69]],"id":41138102},{"atb":[[1.12,1.69]],"id":66499052}],"con":true,"img":false}]}
{"op":"mcm","clk":"11541320649","pt":1719504482693,"mc":[{"id":"1.230180130","rc":[{"atb":[[1.06,1.69]],"id":69979297}],"con":true,"img":false}]}
{"op":"mcm","clk":"11541320660","pt":1719504482707,"mc":[{"id":"1.230180130","rc":[{"atb":[[1.1,1.69]],"id":58149406}],"con":true,"img":false}]}
{"op":"mcm","clk":"11541320677","pt":1719504482779,"mc":[{"id":"1.230180130","rc":[{"atb":[[1.12,1.69]],"id":43210435}],"con":true,"img":false}]}
{"op":"mcm","clk":"11541320688","pt":1719504482984,"mc":[{"id":"1.230180130","rc":[{"spn":16.85,"spf":"NaN","id":58149406},{"spn":67.5,"spf":"NaN","id":41138102},{"spn":67.5,"spf":"NaN","id":43210435},{"atb":[[1.12,0.05]],"id":66499052},{"spn":3.91,"spf":1.0,"id":66499052},{"spn":2.64,"spf":1.0,"id":69979297}],"con":true,"img":false}]}
{"op":"mcm","clk":"11541320693","pt":1719504483093,"mc":[{"id":"1.230180130","rc":[{"atb":[[1.12,1.69]],"id":51843546}],"con":true,"img":false}]}
{"op":"mcm","clk":"11541320708","pt":1719504483404,"mc":[{"id":"1.230180130","rc":[{"atb":[[1.12,0.05]],"id":41138102}],"con":true,"img":false}]}
{"op":"mcm","clk":"11541320717","pt":1719504483500,"mc":[{"id":"1.230180130","rc":[{"atb":[[1.06,0.11]],"id":69979297}],"con":true,"img":false}]}
{"op":"mcm","clk":"11541320730","pt":1719504483658,"mc":[{"id":"1.230180130","rc":[{"atb":[[1.1,0.06]],"id":58149406}],"con":true,"img":false}]}
{"op":"mcm","clk":"11541320751","pt":1719504483983,"mc":[{"id":"1.230180130","rc":[{"atb":[[1.12,0.05]],"id":43210435},{"atb":[[1.12,0]],"id":66499052}],"con":true,"img":false}]}
{"op":"mcm","clk":"11541320759","pt":1719504484074,"mc":[{"id":"1.230180130","rc":[{"atb":[[5.1,0.05]],"id":66499052}],"con":true,"img":false}]}
{"op":"mcm","clk":"11541320789","pt":1719504484489,"mc":[{"id":"1.230180130","rc":[{"atb":[[1.12,0]],"id":41138102}],"con":true,"img":false}]}
{"op":"mcm","clk":"11541320794","pt":1719504484592,"mc":[{"id":"1.230180130","rc":[{"atb":[[5.1,0.05]],"id":41138102},{"atb":[[1.12,0.05]],"id":51843546}],"con":true,"img":false}]}
{"op":"mcm","clk":"11541320830","pt":1719504485063,"mc":[{"id":"1.230180130","rc":[{"atb":[[1.06,0]],"id":69979297}],"con":true,"img":false}]}
{"op":"mcm","clk":"11541320836","pt":1719504485173,"mc":[{"id":"1.230180130","rc":[{"atb":[[2.66,0.11]],"id":69979297}],"con":true,"img":false}]}
{"op":"mcm","clk":"11541320862","pt":1719504485492,"mc":[{"id":"1.230180130","rc":[{"atb":[[1.1,0]],"id":58149406}],"con":true,"img":false}]}
{"op":"mcm","clk":"11541320873","pt":1719504485587,"mc":[{"id":"1.230180130","rc":[{"atb":[[4.8,0.06]],"id":58149406}],"con":true,"img":false}]}
{"op":"mcm","clk":"11541320908","pt":1719504486007,"mc":[{"id":"1.230180130","rc":[{"atb":[[1.12,0]],"id":43210435}],"con":true,"img":false}]}
{"op":"mcm","clk":"11541320917","pt":1719504486110,"mc":[{"id":"1.230180130","rc":[{"atb":[[5.1,0.05]],"id":43210435}],"con":true,"img":false}]}
{"op":"mcm","clk":"11541320942","pt":1719504486374,"mc":[{"id":"1.230180130","rc":[{"atb":[[1.12,0]],"id":51843546}],"con":true,"img":false}]}
{"op":"mcm","clk":"11541320951","pt":1719504486488,"mc":[{"id":"1.230180130","rc":[{"atb":[[5.1,0.9]],"id":51843546}],"con":true,"img":false}]}
{"op":"mcm","clk":"11541321111","pt":1719504488200,"mc":[{"id":"1.230180130","rc":[{"atl":[[4.3,0]],"id":69979297}],"con":true,"img":false}]}
{"op":"mcm","clk":"11541321147","pt":1719504488613,"mc":[{"id":"1.230180130","rc":[{"atl":[[1000,0.3]],"id":69979297}],"con":true,"img":false}]}
{"op":"mcm","clk":"11541321164","pt":1719504488787,"mc":[{"id":"1.230180130","rc":[{"atl":[[1000,0]],"id":69979297}],"con":true,"img":false}]}
{"op":"mcm","clk":"11541321177","pt":1719504488884,"mc":[{"id":"1.230180130","rc":[{"atl":[[4.3,0.3]],"id":69979297}],"con":true,"img":false}]}
{"op":"mcm","clk":"11541321211","pt":1719504489187,"mc":[{"id":"1.230180130","rc":[{"atb":[[2.06,0]],"id":69979297}],"con":true,"img":false}]}
{"op":"mcm","clk":"11541321217","pt":1719504489290,"mc":[{"id":"1.230180130","rc":[{"atb":[[2.14,11.44]],"id":69979297}],"con":true,"img":false}]}
{"op":"mcm","clk":"11541321282","pt":1719504490080,"mc":[{"id":"1.230180130","rc":[{"atb":[[1.03,1.7]],"id":41138102},{"atl":[[1000,1.7]],"id":41138102},{"atb":[[1.02,3.7]],"id":43210435},{"atl":[[1000,1.87]],"id":43210435},{"atb":[[1.02,3.7]],"id":66499052},{"atl":[[1000,1.87]],"id":66499052}],"con":true,"img":false}]}
{"op":"mcm","clk":"11541321295","pt":1719504490279,"mc":[{"id":"1.230180130","rc":[{"atl":[[1000,0.17]],"id":66499052}],"con":true,"img":false}]}
{"op":"mcm","clk":"11541321302","pt":1719504490381,"mc":[{"id":"1.230180130","rc":[{"atb":[[1.03,0.1]],"id":41138102},{"atl":[[1000,0]],"id":41138102},{"atb":[[1.02,2.11]],"id":43210435},{"atl":[[1000,0.17]],"id":43210435},{"atb":[[1.02,2.11]],"id":66499052}],"con":true,"img":false}]}
{"op":"mcm","clk":"11541321323","pt":1719504490592,"mc":[{"id":"1.230180130","rc":[{"atb":[[1.03,0]],"id":41138102},{"atb":[[1.02,2]],"id":43210435},{"atb":[[1.02,2]],"id":66499052}],"con":true,"img":false}]}
{"op":"mcm","clk":"11541321333","pt":1719504490696,"mc":[{"id":"1.230180130","rc":[{"atb":[[4,0.1]],"id":41138102},{"atb":[[3.65,0.11]],"id":43210435},{"atb":[[3.6,0.11]],"id":66499052}],"con":true,"img":false}]}
{"op":"mcm","clk":"11541321468","pt":1719504492776,"mc":[{"id":"1.230180130","rc":[{"atb":[[1.99,2.96]],"id":69979297}],"con":true,"img":false}]}
{"op":"mcm","clk":"11541321487","pt":1719504492987,"mc":[{"id":"1.230180130","rc":[{"atb":[[1.99,0]],"id":69979297}],"con":true,"img":false}]}
{"op":"mcm","clk":"11541322296","pt":1719504504142,"mc":[{"id":"1.230180130","rc":[{"atl":[[4.3,0]],"id":69979297}],"con":true,"img":false}]}
{"op":"mcm","clk":"11541322324","pt":1719504504415,"mc":[{"id":"1.230180130","rc":[{"atl":[[1000,0.3]],"id":69979297}],"con":true,"img":false}]}
{"op":"mcm","clk":"11541322342","pt":1719504504619,"mc":[{"id":"1.230180130","rc":[{"atl":[[1000,0]],"id":69979297}],"con":true,"img":false}]}
{"op":"mcm","clk":"11541322352","pt":1719504504724,"mc":[{"id":"1.230180130","rc":[{"atl":[[4.3,0.3]],"id":69979297}],"con":true,"img":false}]}
{"op":"mcm","clk":"11541323513","pt":1719504519954,"mc":[{"id":"1.230180130","rc":[{"atl":[[4.3,0]],"id":69979297}],"con":true,"img":false}]}
{"op":"mcm","clk":"11541323554","pt":1719504520454,"mc":[{"id":"1.230180130","rc":[{"atl":[[1000,0.3]],"id":69979297}],"con":true,"img":false}]}
{"op":"mcm","clk":"11541323576","pt":1719504520618,"mc":[{"id":"1.230180130","rc":[{"atl":[[1000,0]],"id":69979297}],"con":true,"img":false}]}
{"op":"mcm","clk":"11541323585","pt":1719504520721,"mc":[{"id":"1.230180130","rc":[{"atl":[[4.3,0.3]],"id":69979297}],"con":true,"img":false}]}
{"op":"mcm","clk":"11541323715","pt":1719504522324,"mc":[{"id":"1.230180130","rc":[{"atb":[[4,0]],"id":41138102},{"atb":[[3.65,0]],"id":43210435},{"atb":[[3.6,0]],"id":66499052}],"con":true,"img":false}]}
{"op":"mcm","clk":"11541324688","pt":1719504535951,"mc":[{"id":"1.230180130","rc":[{"atl":[[4.3,0]],"id":69979297}],"con":true,"img":false}]}
{"op":"mcm","clk":"11541324711","pt":1719504536260,"mc":[{"id":"1.230180130","rc":[{"atl":[[1000,0.3]],"id":69979297}],"con":true,"img":false}]}
{"op":"mcm","clk":"11541324729","pt":1719504536479,"mc":[{"id":"1.230180130","rc":[{"atl":[[1000,0]],"id":69979297}],"con":true,"img":false}]}
{"op":"mcm","clk":"11541324736","pt":1719504536582,"mc":[{"id":"1.230180130","rc":[{"atl":[[4.3,0.3]],"id":69979297}],"con":true,"img":false}]}
{"op":"mcm","clk":"11541325835","pt":1719504551868,"mc":[{"id":"1.230180130","rc":[{"spn":16.9,"spf":"NaN","id":58149406},{"spn":67.55,"spf":"NaN","id":41138102},{"spn":67.55,"spf":"NaN","id":43210435},{"spn":3.93,"spf":1.0,"id":66499052},{"atl":[[4.3,0]],"id":69979297},{"spn":2.64,"spf":1.0,"id":69979297}],"con":true,"img":false}]}
{"op":"mcm","clk":"11541325913","pt":1719504552898,"mc":[{"id":"1.230180130","rc":[{"atl":[[1000,0.3]],"id":69979297}],"con":true,"img":false}]}
{"op":"mcm","clk":"11541325930","pt":1719504553103,"mc":[{"id":"1.230180130","rc":[{"atl":[[1000,0]],"id":69979297}],"con":true,"img":false}]}
{"op":"mcm","clk":"11541325938","pt":1719504553214,"mc":[{"id":"1.230180130","rc":[{"atl":[[4.3,0.3]],"id":69979297}],"con":true,"img":false}]}
{"op":"mcm","clk":"11541326661","pt":1719504562707,"mc":[{"id":"1.230180130","rc":[{"atb":[[5.2,1.62]],"id":66499052}],"con":true,"img":false}]}
{"op":"mcm","clk":"11541326672","pt":1719504562810,"mc":[{"id":"1.230180130","rc":[{"atb":[[5.2,1.62]],"id":43210435},{"atb":[[3.8,9.5],[3.4,0]],"id":66499052}],"con":true,"img":false}]}
{"op":"mcm","clk":"11541326680","pt":1719504562917,"mc":[{"id":"1.230180130","rc":[{"atb":[[3.6,0],[4.2,10.26]],"id":43210435}],"con":true,"img":false}]}
{"op":"mcm","clk":"11541326691","pt":1719504563020,"mc":[{"id":"1.230180130","rc":[{"atb":[[5.2,1.62]],"id":41138102}],"con":true,"img":false}]}
{"op":"mcm","clk":"11541326699","pt":1719504563123,"mc":[{"id":"1.230180130","rc":[{"atb":[[4.6,12.56],[3.95,0]],"id":41138102}],"con":true,"img":false}]}
{"op":"mcm","clk":"11541326709","pt":1719504563223,"mc":[{"id":"1.230180130","rc":[{"atb":[[4.9,1.72]],"id":58149406}],"con":true,"img":false}]}
{"op":"mcm","clk":"11541326718","pt":1719504563324,"mc":[{"id":"1.230180130","rc":[{"atb":[[3.1,0],[3.5,6.55]],"id":58149406},{"atl":[[4.2,2.01]],"id":69979297}],"con":true,"img":false}]}
{"op":"mcm","clk":"11541326726","pt":1719504563429,"mc":[{"id":"1.230180130","rc":[{"atl":[[11,1.67],[4.5,3]],"id":69979297}],"con":true,"img":false}]}
{"op":"mcm","clk":"11541326742","pt":1719504563587,"mc":[{"id":"1.230180130","rc":[{"atl":[[1000,0.84]],"id":58149406}],"con":true,"img":false}]}
{"op":"mcm","clk":"11541326766","pt":1719504563898,"mc":[{"id":"1.230180130","rc":[{"atb":[[5,0.84]],"id":58149406},{"atb":[[5.2,0]],"id":43210435},{"atb":[[5.1,1.68]],"id":66499052},{"atl":[[4.1,0.84]],"id":69979297}],"con":true,"img":false}]}
{"op":"mcm","clk":"11541326789","pt":1719504564200,"mc":[{"id":"1.230180130","rc":[{"atb":[[5.1,1.68]],"id":43210435},{"atb":[[5.3,1.59]],"id":66499052}],"con":true,"img":false}]}
{"op":"mcm","clk":"11541326803","pt":1719504564407,"mc":[{"id":"1.230180130","rc":[{"atb":[[5.2,1.62]],"id":51843546}],"con":true,"img":false}]}
{"op":"mcm","clk":"11541326812","pt":1719504564509,"mc":[{"id":"1.230180130","rc":[{"atb":[[5,2.02],[5.2,3.62]],"id":51843546}],"con":true,"img":false}]}
{"op":"mcm","clk":"11541326826","pt":1719504564715,"mc":[{"id":"1.230180130","rc":[{"atb":[[5.3,1.59]],"id":43210435},{"atl":[[11,0]],"id":69979297}],"con":true,"img":false}]}
{"op":"mcm","clk":"11541326842","pt":1719504564922,"mc":[{"id":"1.230180130","rc":[{"atb":[[5.3,0.84]],"id":51843546}],"con":true,"img":false}]}
{"op":"mcm","clk":"11541326851","pt":1719504565126,"mc":[{"id":"1.230180130","rc":[{"atb":[[5.2,0]],"id":66499052}],"con":true,"img":false}]}
{"op":"mcm","clk":"11541326872","pt":1719504565388,"mc":[{"id":"1.230180130","rc":[{"atb":[[4.9,0]],"id":58149406},{"atl":[[4.2,0]],"id":69979297}],"con":true,"img":false}]}
{"op":"mcm","clk":"11541326891","pt":1719504565697,"mc":[{"id":"1.230180130","rc":[{"atb":[[5.2,0]],"id":41138102},{"atl":[[4.3,2.31]],"id":69979297}],"con":true,"img":false}]}
{"op":"mcm","clk":"11541326907","pt":1719504565901,"mc":[{"id":"1.230180130","rc":[{"atb":[[5,0]],"id":58149406},{"atb":[[5.1,1.68]],"id":41138102},{"atl":[[4.1,0]],"id":69979297}],"con":true,"img":false}]}
{"op":"mcm","clk":"11541326926","pt":1719504566111,"mc":[{"id":"1.230180130","rc":[{"atb":[[5.1,0.05]],"id":66499052}],"con":true,"img":false}]}
{"op":"mcm","clk":"11541326934","pt":1719504566209,"mc":[{"id":"1.230180130","rc":[{"atb":[[4.8,1.79]],"id":58149406}],"con":true,"img":false}]}
{"op":"mcm","clk":"11541326986","pt":1719504566832,"mc":[{"id":"1.230180130","rc":[{"atb":[[5.4,1.56]],"id":43210435}],"con":true,"img":false}]}
{"op":"mcm","clk":"11541327012","pt":1719504567103,"mc":[{"id":"1.230180130","rc":[{"atb":[[5.1,0.05]],"id":43210435},{"atb":[[5.3,3.19]],"id":66499052}],"con":true,"img":false}]}
{"op":"mcm","clk":"11541327052","pt":1719504567617,"mc":[{"id":"1.230180130","rc":[{"atl":[[1000,0.3]],"id":58149406}],"con":true,"img":false}]}
{"op":"mcm","clk":"11541327068","pt":1719504567921,"mc":[{"id":"1.230180130","rc":[{"atb":[[5.4,0.84]],"id":66499052}],"con":true,"img":false}]}
{"op":"mcm","clk":"11541327077","pt":1719504568032,"mc":[{"id":"1.230180130","rc":[{"atl":[[1000,0]],"id":58149406}],"con":true,"img":false}]}
{"op":"mcm","clk":"11541327085","pt":1719504568127,"mc":[{"id":"1.230180130","rc":[{"atl":[[28,0.3]],"id":58149406}],"con":true,"img":false}]}
{"op":"mcm","clk":"11541327092","pt":1719504568230,"mc":[{"id":"1.230180130","rc":[{"atb":[[5.5,1.54]],"id":43210435}],"con":true,"img":false}]}
{"op":"mcm","clk":"11541327107","pt":1719504568394,"mc":[{"id":"1.230180130","rc":[{"atb":[[5.3,0]],"id":43210435},{"atl":[[4.3,2.01]],"id":69979297}],"con":true,"img":false}]}
{"op":"mcm","clk":"11541327124","pt":1719504568601,"mc":[{"id":"1.230180130","rc":[{"atl":[[1000,0.31]],"id":69979297}],"con":true,"img":false}]}
{"op":"mcm","clk":"11541327140","pt":1719504568802,"mc":[{"id":"1.230180130","rc":[{"atl":[[1000,0]],"id":69979297}],"con":true,"img":false}]}
{"op":"mcm","clk":"11541327146","pt":1719504568904,"mc":[{"id":"1.230180130","rc":[{"atl":[[4.2,0.31]],"id":69979297}],"con":true,"img":false}]}
{"op":"mcm","clk":"11541327281","pt":1719504570709,"mc":[{"id":"1.230180130","rc":[{"atl":[[4.2,2.03]],"id":69979297}],"con":true,"img":false}]}
{"op":"mcm","clk":"11541327307","pt":1719504570920,"mc":[{"id":"1.230180130","rc":[{"atb":[[4.9,0.84]],"id":58149406},{"atl":[[4.2,2.87]],"id":69979297}],"con":true,"img":false}]}
{"op":"mcm","clk":"11541327315","pt":1719504571020,"mc":[{"id":"1.230180130","rc":[{"atl":[[4.3,0],[4.1,2.06]],"id":69979297}],"con":true,"img":false}]}
{"op":"mcm","clk":"11541327555","pt":1719504573738,"mc":[{"id":"1.230180130","rc":[{"atl":[[4.2,1.15]],"id":69979297}],"con":true,"img":false}]}
{"op":"mcm","clk":"11541327980","pt":1719504578445,"mc":[{"id":"1.230180130","rc":[{"atl":[[4,0.84]],"id":69979297}],"con":true,"img":false}]}
{"op":"mcm","clk":"11541328532","pt":1719504584152,"mc":[{"id":"1.230180130","rc":[{"atl":[[4.2,0.84]],"id":69979297}],"con":true,"img":false}]}
{"op":"mcm","clk":"11541328580","pt":1719504584731,"mc":[{"id":"1.230180130","rc":[{"atl":[[1000,0.33]],"id":69979297}],"con":true,"img":false}]}
{"op":"mcm","clk":"11541328594","pt":1719504584933,"mc":[{"id":"1.230180130","rc":[{"atl":[[1000,0]],"id":69979297}],"con":true,"img":false}]}
{"op":"mcm","clk":"11541328603","pt":1719504585033,"mc":[{"id":"1.230180130","rc":[{"atl":[[4,1.17]],"id":69979297}],"con":true,"img":false}]}
{"op":"mcm","clk":"11541329277","pt":1719504593066,"mc":[{"id":"1.230180130","rc":[{"atb":[[5.5,1.54]],"id":66499052}],"con":true,"img":false}]}
{"op":"mcm","clk":"11541329298","pt":1719504593263,"mc":[{"id":"1.230180130","rc":[{"atb":[[5.3,1.59]],"id":66499052}],"con":true,"img":false}]}
{"op":"mcm","clk":"11541329313","pt":1719504593367,"mc":[{"id":"1.230180130","rc":[{"atb":[[5,1.69]],"id":58149406}],"con":true,"img":false}]}
{"op":"mcm","clk":"11541329341","pt":1719504593638,"mc":[{"id":"1.230180130","rc":[{"atb":[[4.8,0.06]],"id":58149406}],"con":true,"img":false}]}
{"op":"mcm","clk":"11541329352","pt":1719504593743,"mc":[{"id":"1.230180130","rc":[{"atb":[[5.4,2.38]],"id":66499052}],"con":true,"img":false}]}
{"op":"mcm","clk":"11541329374","pt":1719504593944,"mc":[{"id":"1.230180130","rc":[{"atb":[[5.1,0.84]],"id":58149406},{"atb":[[5.2,2]],"id":51843546}],"con":true,"img":false}]}
{"op":"mcm","clk":"11541329383","pt":1719504594050,"mc":[{"id":"1.230180130","rc":[{"atb":[[5.4,0.84]],"id":66499052},{"atb":[[5.1,3.75],[5.2,0]],"id":51843546}],"con":true,"img":false}]}
{"op":"mcm","clk":"11541329405","pt":1719504594251,"mc":[{"id":"1.230180130","rc":[{"atb":[[5.5,0]],"id":66499052}],"con":true,"img":false}]}
{"op":"mcm","clk":"11541329412","pt":1719504594357,"mc":[{"id":"1.230180130","rc":[{"atb":[[5.4,1.56]],"id":51843546}],"con":true,"img":false}]}
{"op":"mcm","clk":"11541329422","pt":1719504594461,"mc":[{"id":"1.230180130","rc":[{"atb":[[5.3,0]],"id":51843546}],"con":true,"img":false}]}
{"op":"mcm","clk":"11541329430","pt":1719504594563,"mc":[{"id":"1.230180130","rc":[{"atb":[[5,0]],"id":58149406}],"con":true,"img":false}]}
{"op":"mcm","clk":"11541329457","pt":1719504594874,"mc":[{"id":"1.230180130","rc":[{"atb":[[4.9,2.53]],"id":58149406},{"atb":[[5.6,1.51]],"id":66499052}],"con":true,"img":false}]}
{"op":"mcm","clk":"11541329479","pt":1719504595144,"mc":[{"id":"1.230180130","rc":[{"atb":[[5.2,1.56]],"id":51843546}],"con":true,"img":false}]}
{"op":"mcm","clk":"11541329497","pt":1719504595445,"mc":[{"id":"1.230180130","rc":[{"atb":[[5.1,0]],"id":58149406},{"atb":[[5.4,0]],"id":51843546}],"con":true,"img":false}]}
{"op":"mcm","clk":"11541329922","pt":1719504600352,"mc":[{"id":"1.230180130","rc":[{"atl":[[4,0.84]],"id":69979297}],"con":true,"img":false}]}
{"op":"mcm","clk":"11541329940","pt":1719504600469,"mc":[{"id":"1.230180130","rc":[{"atl":[[1000,0.34]],"id":69979297}],"con":true,"img":false}]}
{"op":"mcm","clk":"11541329968","pt":1719504600780,"mc":[{"id":"1.230180130","rc":[{"atl":[[1000,0]],"id":69979297}],"con":true,"img":false}]}
{"op":"mcm","clk":"11541329976","pt":1719504600889,"mc":[{"id":"1.230180130","rc":[{"atl":[[3.95,0.34]],"id":69979297}],"con":true,"img":false}]}
{"op":"mcm","clk":"11541330315","pt":1719504604574,"mc":[{"id":"1.230180130","rc":[{"atb":[[5.1,0]],"id":66499052}],"con":true,"img":false}]}
{"op":"mcm","clk":"11541330352","pt":1719504604899,"mc":[{"id":"1.230180130","rc":[{"atb":[[5.1,0]],"id":43210435},{"atb":[[5.4,2.36],[5.6,0]],"id":66499052}],"con":true,"img":false}]}
{"op":"mcm","clk":"11541330389","pt":1719504605160,"mc":[{"id":"1.230180130","rc":[{"atb":[[5.1,1.62]],"id":41138102}],"con":true,"img":false}]}
{"op":"mcm","clk":"11541330433","pt":1719504605572,"mc":[{"id":"1.230180130","rc":[{"atb":[[2.66,0]],"id":69979297}],"con":true,"img":false}]}
{"op":"mcm","clk":"11541330469","pt":1719504605991,"mc":[{"id":"1.230180130","rc":[{"atb":[[4.8,0]],"id":58149406}],"con":true,"img":false}]}
{"op":"mcm","clk":"11541330506","pt":1719504606305,"mc":[{"id":"1.230180130","rc":[{"atb":[[5.1,3.69]],"id":51843546}],"con":true,"img":false}]}
{"op":"mcm","clk":"11541330538","pt":1719504606568,"mc":[{"id":"1.230180130","rc":[{"atb":[[1.12,1.69]],"id":41138102},{"atb":[[1.14,1.69]],"id":43210435}],"con":true,"img":false}]}
{"op":"mcm","clk":"11541330570","pt":1719504606877,"mc":[{"id":"1.230180130","rc":[{"atb":[[1.12,1.69]],"id":58149406},{"atb":[[1.12,1.69]],"id":51843546}],"con":true,"img":false}]}
{"op":"mcm","clk":"11541330602","pt":1719504607190,"mc":[{"id":"1.230180130","rc":[{"atb":[[1.12,1.69]],"id":66499052},{"atb":[[1.06,1.69]],"id":69979297}],"con":true,"img":false}]}
{"op":"mcm","clk":"11541330627","pt":1719504607501,"mc":[{"id":"1.230180130","rc":[{"atb":[[1.12,0.05]],"id":41138102},{"atb":[[1.12,0.05]],"id":51843546}],"con":true,"img":false}]}
{"op":"mcm","clk":"11541330662","pt":1719504607771,"mc":[{"id":"1.230180130","rc":[{"atb":[[1.14,0.05]],"id":43210435},{"atb":[[1.12,0.05]],"id":66499052}],"con":true,"img":false}]}
{"op":"mcm","clk":"11541330699","pt":1719504608233,"mc":[{"id":"1.230180130","rc":[{"atb":[[1.12,0],[1.04,1.7]],"id":41138102},{"atl":[[1000,1.7]],"id":41138102},{"atb":[[1.04,1.7]],"id":43210435},{"atl":[[1000,1.87]],"id":43210435},{"atb":[[1.04,109.18]],"id":66499052},{"atl":[[1000,1.87]],"id":66499052},{"atb":[[1.06,0.11]],"id":69979297}],"con":true,"img":false}]}
{"op":"mcm","clk":"11541330711","pt":1719504608293,"mc":[{"id":"1.230180130","rc":[{"atb":[[5.2,0.05]],"id":41138102}],"con":true,"img":false}]}
{"op":"mcm","clk":"11541330727","pt":1719504608493,"mc":[{"id":"1.230180130","rc":[{"atb":[[1.04,0.07]],"id":41138102},{"atl":[[1000,0]],"id":41138102},{"atb":[[1.04,0.06]],"id":43210435},{"atl":[[1000,0.17]],"id":43210435},{"atb":[[1.04,107.54]],"id":66499052},{"atl":[[1000,0.17]],"id":66499052}],"con":true,"img":false}]}
{"op":"mcm","clk":"11541330741","pt":1719504608666,"mc":[{"id":"1.230180130","rc":[{"atb":[[1.12,0.05]],"id":58149406}],"con":true,"img":false}]}
{"op":"mcm","clk":"11541330749","pt":1719504608808,"mc":[{"id":"1.230180130","rc":[{"atb":[[1.04,0]],"id":41138102},{"atb":[[1.04,0]],"id":43210435},{"atb":[[1.04,107.48]],"id":66499052}],"con":true,"img":false}]}
{"op":"mcm","clk":"11541330757","pt":1719504608878,"mc":[{"id":"1.230180130","rc":[{"atb":[[5.1,1.69]],"id":41138102},{"atb":[[5.5,1.6]],"id":43210435},{"atb":[[5.5,0.06]],"id":66499052}],"con":true,"img":false}]}
{"op":"mcm","clk":"11541330767","pt":1719504608970,"mc":[{"id":"1.230180130","rc":[{"atb":[[1.12,0]],"id":51843546}],"con":true,"img":false}]}
{"op":"mcm","clk":"11541330774","pt":1719504609081,"mc":[{"id":"1.230180130","rc":[{"atb":[[5.3,0.05]],"id":51843546}],"con":true,"img":false}]}
{"op":"mcm","clk":"11541330804","pt":1719504609385,"mc":[{"id":"1.230180130","rc":[{"atb":[[5.2,0.9]],"id":41138102},{"atb":[[1.14,0]],"id":43210435}],"con":true,"img":false}]}
{"op":"mcm","clk":"11541330815","pt":1719504609486,"mc":[{"id":"1.230180130","rc":[{"atb":[[5.6,0.05]],"id":43210435}],"con":true,"img":false}]}
{"op":"mcm","clk":"11541330839","pt":1719504609797,"mc":[{"id":"1.230180130","rc":[{"atb":[[1.12,0]],"id":66499052}],"con":true,"img":false}]}
{"op":"mcm","clk":"11541330851","pt":1719504609859,"mc":[{"id":"1.230180130","rc":[{"atb":[[5.5,0.12]],"id":66499052}],"con":true,"img":false}]}
{"op":"mcm","clk":"11541330878","pt":1719504610167,"mc":[{"id":"1.230180130","rc":[{"atb":[[1.06,0]],"id":69979297}],"con":true,"img":false}]}
{"op":"mcm","clk":"11541330886","pt":1719504610270,"mc":[{"id":"1.230180130","rc":[{"atb":[[2.66,0.11]],"id":69979297}],"con":true,"img":false}]}
{"op":"mcm","clk":"11541330911","pt":1719504610586,"mc":[{"id":"1.230180130","rc":[{"atb":[[1.12,0]],"id":58149406}],"con":true,"img":false}]}
{"op":"mcm","clk":"11541330918","pt":1719504610684,"mc":[{"id":"1.230180130","rc":[{"atb":[[5,0.05]],"id":58149406}],"con":true,"img":false}]}
{"op":"mcm","clk":"11541331407","pt":1719504616169,"mc":[{"id":"1.230180130","rc":[{"spn":16.5,"spf":"NaN","id":58149406},{"spn":67.6,"spf":"NaN","id":41138102},{"spn":67.8,"spf":"NaN","id":43210435},{"spn":5.36,"spf":1.0,"id":66499052},{"spn":67.65,"spf":"NaN","id":51843546},{"atl":[[3.95,0]],"id":69979297}],"con":true,"img":false}]}
{"op":"mcm","clk":"11541331457","pt":1719504617001,"mc":[{"id":"1.230180130","rc":[{"atl":[[1000,0.33]],"id":69979297}],"con":true,"img":false}]}
{"op":"mcm","clk":"11541331465","pt":1719504617109,"mc":[{"id":"1.230180130","rc":[{"atl":[[1000,0]],"id":69979297}],"con":true,"img":false}]}
{"op":"mcm","clk":"11541331470","pt":1719504617207,"mc":[{"id":"1.230180130","rc":[{"atl":[[4,1.17]],"id":69979297}],"con":true,"img":false}]}
{"op":"mcm","clk":"11541331897","pt":1719504623217,"mc":[{"id":"1.230180130","rc":[{"atb":[[5.3,1.59]],"id":41138102}],"con":true,"img":false}]}
{"op":"mcm","clk":"11541331916","pt":1719504623480,"mc":[{"id":"1.230180130","rc":[{"atb":[[4.9,0.84]],"id":58149406},{"atb":[[5.4,1.56]],"id":51843546}],"con":true,"img":false}]}
{"op":"mcm","clk":"11541331926","pt":1719504623583,"mc":[{"id":"1.230180130","rc":[{"atb":[[5.3,3.19],[5.1,0.84]],"id":51843546}],"con":true,"img":false}]}
{"op":"mcm","clk":"11541331942","pt":1719504623793,"mc":[{"id":"1.230180130","rc":[{"atb":[[5.1,1.65]],"id":58149406}],"con":true,"img":false}]}
{"op":"mcm","clk":"11541331956","pt":1719504623997,"mc":[{"id":"1.230180130","rc":[{"atb":[[4.9,0]],"id":58149406}],"con":true,"img":false}]}
{"op":"mcm","clk":"11541331963","pt":1719504624098,"mc":[{"id":"1.230180130","rc":[{"atb":[[5.1,0.07]],"id":41138102}],"con":true,"img":false}]}
{"op":"mcm","clk":"11541331978","pt":1719504624305,"mc":[{"id":"1.230180130","rc":[{"atb":[[5.1,0]],"id":51843546}],"con":true,"img":false}]}
{"op":"mcm","clk":"11541331984","pt":1719504624409,"mc":[{"id":"1.230180130","rc":[{"atb":[[5.3,0]],"id":41138102}],"con":true,"img":false}]}
{"op":"mcm","clk":"11541332018","pt":1719504624923,"mc":[{"id":"1.230180130","rc":[{"atb":[[5.2,0.05]],"id":41138102}],"con":true,"img":false}]}
{"op":"mcm","clk":"11541332028","pt":1719504624979,"mc":[{"id":"1.230180130","rc":[{"atb":[[3.4,2.31]],"id":58149406},{"atb":[[5.2,0]],"id":51843546}],"con":true,"img":false}]}
{"op":"mcm","clk":"11541332037","pt":1719504625080,"mc":[{"id":"1.230180130","rc":[{"atb":[[3.4,0]],"id":58149406}],"con":true,"img":false}]}
{"op":"mcm","clk":"11541332047","pt":1719504625285,"mc":[{"id":"1.230180130","rc":[{"atb":[[5.1,0]],"id":58149406}],"con":true,"img":false}]}
{"op":"mcm","clk":"11541332072","pt":1719504625596,"mc":[{"id":"1.230180130","rc":[{"atb":[[4.8,1.65]],"id":58149406}],"con":true,"img":false}]}
{"op":"mcm","clk":"11541332095","pt":1719504625904,"mc":[{"id":"1.230180130","rc":[{"atb":[[5.2,1.65]],"id":41138102}],"con":true,"img":false}]}
{"op":"mcm","clk":"11541332146","pt":1719504626479,"mc":[{"id":"1.230180130","rc":[{"atb":[[4.9,0.84]],"id":58149406}],"con":true,"img":false}]}
{"op":"mcm","clk":"11541332746","pt":1719504632413,"mc":[{"id":"1.230180130","rc":[{"atl":[[4,0.84]],"id":69979297}],"con":true,"img":false}]}
{"op":"mcm","clk":"11541332774","pt":1719504632719,"mc":[{"id":"1.230180130","rc":[{"atl":[[1000,0.34]],"id":69979297}],"con":true,"img":false}]}
{"op":"mcm","clk":"11541332793","pt":1719504632925,"mc":[{"id":"1.230180130","rc":[{"atl":[[1000,0]],"id":69979297}],"con":true,"img":false}]}
{"op":"mcm","clk":"11541332801","pt":1719504633030,"mc":[{"id":"1.230180130","rc":[{"atl":[[3.95,0.34]],"id":69979297}],"con":true,"img":false}]}
{"op":"mcm","clk":"11541333369","pt":1719504640353,"mc":[{"id":"1.230180130","rc":[{"atb":[[5.1,0]],"id":41138102},{"atb":[[5.5,1.54]],"id":43210435},{"atb":[[5.5,0.05]],"id":66499052}],"con":true,"img":false}]}
{"op":"mcm","clk":"11541333402","pt":1719504640721,"mc":[{"id":"1.230180130","rc":[{"atb":[[5.1,1.59],[5.2,0.05]],"id":41138102}],"con":true,"img":false}]}
{"op":"mcm","clk":"11541334051","pt":1719504648248,"mc":[{"id":"1.230180130","rc":[{"atl":[[3.95,0]],"id":69979297}],"con":true,"img":false}]}
{"op":"mcm","clk":"11541334144","pt":1719504649444,"mc":[{"id":"1.230180130","rc":[{"atl":[[1000,0.33]],"id":69979297}],"con":true,"img":false}]}
{"op":"mcm","clk":"11541334166","pt":1719504649652,"mc":[{"id":"1.230180130","rc":[{"atl":[[1000,0]],"id":69979297}],"con":true,"img":false}]}
{"op":"mcm","clk":"11541334173","pt":1719504649762,"mc":[{"id":"1.230180130","rc":[{"atl":[[4,1.17]],"id":69979297}],"con":true,"img":false}]}
{"op":"mcm","clk":"11541334237","pt":1719504650441,"mc":[{"id":"1.230180130","rc":[{"atb":[[5.6,1.51]],"id":66499052}],"con":true,"img":false}]}
{"op":"mcm","clk":"11541334246","pt":1719504650542,"mc":[{"id":"1.230180130","rc":[{"atb":[[5.4,0.84]],"id":66499052}],"con":true,"img":false}]}
{"op":"mcm","clk":"11541334257","pt":1719504650651,"mc":[{"id":"1.230180130","rc":[{"atb":[[5.3,1.59]],"id":41138102}],"con":true,"img":false}]}
{"op":"mcm","clk":"11541334285","pt":1719504650977,"mc":[{"id":"1.230180130","rc":[{"atb":[[5.1,1.65]],"id":58149406},{"atb":[[5.1,0]],"id":41138102}],"con":true,"img":false}]}
{"op":"mcm","clk":"11541334325","pt":1719504651368,"mc":[{"id":"1.230180130","rc":[{"atb":[[4.8,0]],"id":58149406},{"atb":[[5.6,0]],"id":66499052}],"con":true,"img":false}]}
{"op":"mcm","clk":"11541334366","pt":1719504651681,"mc":[{"id":"1.230180130","rc":[{"atb":[[5.3,0]],"id":41138102},{"atb":[[5.5,1.57]],"id":66499052}],"con":true,"img":false}]}
{"op":"mcm","clk":"11541334395","pt":1719504651941,"mc":[{"id":"1.230180130","rc":[{"atb":[[4.8,1.65],[5.1,0]],"id":58149406}],"con":true,"img":false}]}
{"op":"mcm","clk":"11541334428","pt":1719504652257,"mc":[{"id":"1.230180130","rc":[{"atb":[[5.1,1.59]],"id":41138102}],"con":true,"img":false}]}
{"op":"mcm","clk":"11541335247","pt":1719504661453,"mc":[{"id":"1.230180130","rc":[{"atb":[[1.01,1]],"id":66499052}],"con":true,"img":false}]}
{"op":"mcm","clk":"11541335298","pt":1719504661970,"mc":[{"id":"1.230180130","rc":[{"atl":[[4.5,0],[4.1,4.42]],"id":69979297}],"con":true,"img":false}]}
{"op":"mcm","clk":"11541335309","pt":1719504662074,"mc":[{"id":"1.230180130","rc":[{"atb":[[5.2,1]],"id":58149406},{"atb":[[5.4,1]],"id":41138102},{"atb":[[5.2,1]],"id":51843546}],"con":true,"img":false}]}
{"op":"mcm","clk":"11541335317","pt":1719504662177,"mc":[{"id":"1.230180130","rc":[{"atl":[[4,2.17]],"id":69979297}],"con":true,"img":false}]}
{"op":"mcm","clk":"11541335325","pt":1719504662282,"mc":[{"id":"1.230180130","rc":[{"atb":[[5.5,0.05]],"id":66499052}],"con":true,"img":false}]}
{"op":"mcm","clk":"11541335334","pt":1719504662385,"mc":[{"id":"1.230180130","rc":[{"atb":[[5.5,1.54]],"id":41138102}],"con":true,"img":false}]}
{"op":"mcm","clk":"11541335353","pt":1719504662593,"mc":[{"id":"1.230180130","rc":[{"atb":[[5.4,2.36]],"id":66499052}],"con":true,"img":false}]}
{"op":"mcm","clk":"11541335370","pt":1719504662751,"mc":[{"id":"1.230180130","rc":[{"atb":[[5.1,0]],"id":41138102}],"con":true,"img":false}]}
{"op":"mcm","clk":"11541335385","pt":1719504662955,"mc":[{"id":"1.230180130","rc":[{"atb":[[4.8,0]],"id":58149406},{"atl":[[4.2,0]],"id":69979297}],"con":true,"img":false}]}
{"op":"mcm","clk":"11541335410","pt":1719504663270,"mc":[{"id":"1.230180130","rc":[{"atb":[[5.3,1.59]],"id":58149406}],"con":true,"img":false}]}
{"op":"mcm","clk":"11541335467","pt":1719504663988,"mc":[{"id":"1.230180130","rc":[{"atb":[[4.9,0]],"id":58149406}],"con":true,"img":false}]}
{"op":"mcm","clk":"11541335541","pt":1719504665070,"mc":[{"id":"1.230180130","rc":[{"atl":[[4,1.84]],"id":69979297}],"con":true,"img":false}]}
{"op":"mcm","clk":"11541335561","pt":1719504665282,"mc":[{"id":"1.230180130","rc":[{"atl":[[1000,0.34]],"id":69979297}],"con":true,"img":false}]}
{"op":"mcm","clk":"11541335584","pt":1719504665597,"mc":[{"id":"1.230180130","rc":[{"atl":[[1000,0]],"id":69979297}],"con":true,"img":false}]}
{"op":"mcm","clk":"11541335593","pt":1719504665691,"mc":[{"id":"1.230180130","rc":[{"atl":[[3.95,0.34]],"id":69979297}],"con":true,"img":false}]}
{"op":"mcm","clk":"11541336049","pt":1719504670669,"mc":[{"id":"1.230180130","rc":[{"atb":[[1.25,20]],"id":58149406},{"atb":[[1.25,20]],"id":41138102},{"atb":[[1.25,20]],"id":43210435},{"atb":[[1.25,20]],"id":66499052},{"atb":[[1.25,20]],"id":51843546},{"atb":[[1.25,20]],"id":69979297}],"con":true,"img":false}]}
{"op":"mcm","clk":"11541336232","pt":1719504672908,"mc":[{"id":"1.230180130","rc":[{"atl":[[11,1],[12.5,0]],"id":66499052}],"con":true,"img":false}]}
{"op":"mcm","clk":"11541336816","pt":1719504680477,"mc":[{"id":"1.230180130","rc":[{"spn":16.65,"spf":"NaN","id":58149406},{"spn":67.75,"spf":"NaN","id":41138102},{"atb":[[5.7,1.48]],"id":43210435},{"spn":67.85,"spf":"NaN","id":43210435},{"spn":5.36,"spf":1.0,"id":66499052},{"spn":67.7,"spf":"NaN","id":51843546}],"con":true,"img":false}]}
{"op":"mcm","clk":"11541336822","pt":1719504680579,"mc":[{"id":"1.230180130","rc":[{"atb":[[5.5,0]],"id":43210435}],"con":true,"img":false}]}
{"op":"mcm","clk":"11541336839","pt":1719504680890,"mc":[{"id":"1.230180130","rc":[{"atb":[[5.7,0]],"id":43210435}],"con":true,"img":false}]}
{"op":"mcm","clk":"11541336847","pt":1719504680996,"mc":[{"id":"1.230180130","rc":[{"atl":[[3.95,0]],"id":69979297}],"con":true,"img":false}]}
{"op":"mcm","clk":"11541336858","pt":1719504681099,"mc":[{"id":"1.230180130","rc":[{"atb":[[5.6,1.53]],"id":43210435}],"con":true,"img":false}]}
{"op":"mcm","clk":"11541336866","pt":1719504681203,"mc":[{"id":"1.230180130","rc":[{"atb":[[5.3,3.03]],"id":58149406},{"atb":[[2.14,12.23]],"id":69979297},{"atl":[[1000,0.34]],"id":69979297}],"con":true,"img":false}]}
{"op":"mcm","clk":"11541336875","pt":1719504681309,"mc":[{"id":"1.230180130","rc":[{"atb":[[5.2,0]],"id":58149406}],"con":true,"img":false}]}
{"op":"mcm","clk":"11541336885","pt":1719504681417,"mc":[{"id":"1.230180130","rc":[{"atb":[[5.4,1]],"id":58149406},{"atl":[[1000,0]],"id":69979297}],"con":true,"img":false}]}
{"op":"mcm","clk":"11541336893","pt":1719504681516,"mc":[{"id":"1.230180130","rc":[{"atl":[[3.95,0.34]],"id":69979297}],"con":true,"img":false}]}
{"op":"mcm","clk":"11541337347","pt":1719504686522,"mc":[{"id":"1.230180130","rc":[{"atb":[[5.3,0],[5.4,0]],"id":58149406},{"atl":[[5.3,0.97]],"id":58149406},{"trd":[[5.3,6.07],[5.4,2]],"ltp":5.3,"tv":8.07,"id":58149406},{"atb":[[5.4,0],[5.5,0]],"id":66499052},{"atl":[[5.4,2.5]],"id":66499052},{"trd":[[5.4,4.72],[5.5,0.11]],"ltp":5.4,"tv":4.83,"id":66499052},{"atb":[[2.66,0],[2.64,0]],"id":69979297},{"atl":[[2.64,8.58]],"id":69979297},{"trd":[[2.64,2.74],[2.66,0.23]],"ltp":2.64,"tv":2.97,"id":69979297}],"con":true,"img":false}]}
{"op":"mcm","clk":"11541337356","pt":1719504686622,"mc":[{"id":"1.230180130","rc":[{"atl":[[5.3,0],[8.2,1]],"id":58149406},{"trd":[[5.3,8.02]],"ltp":5.3,"tv":8.02,"id":58149406},{"atb":[[4.6,13.56]],"id":41138102},{"atl":[[14,1]],"id":41138102},{"atl":[[14,1]],"id":43210435},{"atl":[[14,4],[120,0]],"id":66499052},{"atb":[[5.2,2]],"id":51843546},{"atl":[[17.5,1]],"id":51843546}],"con":true,"img":false}]}
{"op":"mcm","clk":"11541337362","pt":1719504686722,"mc":[{"id":"1.230180130","rc":[{"atb":[[5.8,1]],"id":43210435},{"atb":[[2.1,1]],"id":69979297},{"atl":[[4,0.84]],"id":69979297}],"con":true,"img":false}]}
{"op":"mcm","clk":"11541337382","pt":1719504686878,"mc":[{"id":"1.230180130","rc":[{"atb":[[5,0]],"id":58149406},{"atb":[[5.2,0]],"id":41138102},{"atb":[[5.6,1.48]],"id":43210435},{"atb":[[5.3,3.14]],"id":51843546},{"atb":[[2.16,0.84]],"id":69979297},{"atl":[[4,0]],"id":69979297}],"con":true,"img":false}]}
{"op":"mcm","clk":"11541337390","pt":1719504687010,"mc":[{"id":"1.230180130","rc":[{"atb":[[3.5,0],[3.05,13.08]],"id":58149406}],"con":true,"img":false}]}
{"op":"mcm","clk":"11541337420","pt":1719504687294,"mc":[{"id":"1.230180130","rc":[{"atb":[[5.1,1.51]],"id":66499052}],"con":true,"img":false}]}
{"op":"mcm","clk":"11541337429","pt":1719504687403,"mc":[{"id":"1.230180130","rc":[{"atb":[[5.9,1.43]],"id":43210435}],"con":true,"img":false}]}
{"op":"mcm","clk":"11541337453","pt":1719504687711,"mc":[{"id":"1.230180130","rc":[{"atb":[[5.6,0]],"id":43210435},{"atb":[[2.16,2.25]],"id":69979297}],"con":true,"img":false}]}
{"op":"mcm","clk":"11541337519","pt":1719504688496,"mc":[{"id":"1.230180130","rc":[{"atb":[[2.54,1.46]],"id":69979297}],"con":true,"img":false}]}
{"op":"mcm","clk":"11541337687","pt":1719504690279,"mc":[{"id":"1.230180130","rc":[{"atl":[[17.5,0]],"id":51843546},{"trd":[[17.5,1.99]],"ltp":17.5,"tv":1.99,"id":51843546}],"con":true,"img":false}]}
{"op":"mcm","clk":"11541337703","pt":1719504690443,"mc":[{"id":"1.230180130","rc":[{"atl":[[19,1]],"id":51843546}],"con":true,"img":false}]}
{"op":"mcm","clk":"11541337716","pt":1719504690536,"mc":[{"id":"1.230180130","rc":[{"atb":[[3.1,3.81]],"id":58149406}],"con":true,"img":false}]}
{"op":"mcm","clk":"11541337910","pt":1719504692717,"mc":[{"id":"1.230180130","rc":[{"atb":[[1.1,1]],"id":51843546}],"con":true,"img":false}]}
{"op":"mcm","clk":"11541337928","pt":1719504692925,"mc":[{"id":"1.230180130","rc":[{"atb":[[1.1,0.2]],"id":51843546}],"con":true,"img":false}]}
{"op":"mcm","clk":"11541337945","pt":1719504693138,"mc":[{"id":"1.230180130","rc":[{"atb":[[1.1,0]],"id":51843546}],"con":true,"img":false}]}
{"op":"mcm","clk":"11541337959","pt":1719504693247,"mc":[{"id":"1.230180130","rc":[{"atb":[[5.9,0.2]],"id":51843546}],"con":true,"img":false}]}
{"op":"mcm","clk":"11541338257","pt":1719504696514,"mc":[{"id":"1.230180130","rc":[{"atl":[[19,0]],"id":51843546},{"trd":[[19,1.99]],"ltp":19.0,"tv":1.99,"id":51843546}],"con":true,"img":false}]}
{"op":"mcm","clk":"11541338287","pt":1719504696790,"mc":[{"id":"1.230180130","rc":[{"atl":[[3.95,0]],"id":69979297}],"con":true,"img":false}]}
{"op":"mcm","clk":"11541338324","pt":1719504697204,"mc":[{"id":"1.230180130","rc":[{"atb":[[3.3,1]],"id":58149406}],"con":true,"img":false}]}
{"op":"mcm","clk":"11541338346","pt":1719504697514,"mc":[{"id":"1.230180130","rc":[{"atb":[[5.2,1.59]],"id":66499052}],"con":true,"img":false}]}
{"op":"mcm","clk":"11541338356","pt":1719504697611,"mc":[{"id":"1.230180130","rc":[{"atb":[[5.3,0]],"id":66499052}],"con":true,"img":false}]}
{"op":"mcm","clk":"11541339317","pt":1719504708363,"mc":[{"id":"1.230180130","rc":[{"atb":[[5.9,0]],"id":51843546}],"con":true,"img":false}]}
{"op":"mcm","clk":"11541339333","pt":1719504708520,"mc":[{"id":"1.230180130","rc":[{"atb":[[4.8,1]],"id":58149406},{"atb":[[2.6,1.41]],"id":69979297}],"con":true,"img":false}]}
{"op":"mcm","clk":"11541339344","pt":1719504708628,"mc":[{"id":"1.230180130","rc":[{"atb":[[4.7,0]],"id":58149406},{"atb":[[2.54,0]],"id":69979297}],"con":true,"img":false}]}
{"op":"mcm","clk":"11541339353","pt":1719504708729,"mc":[{"id":"1.230180130","rc":[{"atb":[[3.3,4.81],[3.05,0]],"id":58149406}],"con":true,"img":false}]}
{"op":"mcm","clk":"11541339373","pt":1719504708940,"mc":[{"id":"1.230180130","rc":[{"atb":[[2.16,1.41]],"id":69979297}],"con":true,"img":false}]}
{"op":"mcm","clk":"11541339429","pt":1719504709549,"mc":[{"id":"1.230180130","rc":[{"atb":[[1.1,1]],"id":51843546}],"con":true,"img":false}]}
{"op":"mcm","clk":"11541339450","pt":1719504709764,"mc":[{"id":"1.230180130","rc":[{"atb":[[1.1,0.2]],"id":51843546},{"atb":[[2.14,11.44]],"id":69979297}],"con":true,"img":false}]}
{"op":"mcm","clk":"11541339467","pt":1719504709917,"mc":[{"id":"1.230180130","rc":[{"atb":[[1.1,0]],"id":51843546}],"con":true,"img":false}]}
{"op":"mcm","clk":"11541339477","pt":1719504710017,"mc":[{"id":"1.230180130","rc":[{"atb":[[5.9,0.2]],"id":51843546}],"con":true,"img":false}]}
{"op":"mcm","clk":"11541339712","pt":1719504712763,"mc":[{"id":"1.230180130","rc":[{"atl":[[14,0],[14.5,1]],"id":41138102},{"atl":[[11,0]],"id":66499052}],"con":true,"img":false}]}
{"op":"mcm","clk":"11541339722","pt":1719504712820,"mc":[{"id":"1.230180130","rc":[{"atl":[[8.2,0],[8.4,1]],"id":58149406},{"atl":[[14,0],[14.5,1]],"id":43210435}],"con":true,"img":false}]}
{"op":"mcm","clk":"11541339735","pt":1719504712977,"mc":[{"id":"1.230180130","rc":[{"atb":[[5,7],[4.6,1]],"id":41138102},{"atb":[[4.5,10.26],[4.2,0]],"id":43210435},{"atb":[[3.8,0],[4,9.5]],"id":66499052},{"atl":[[3.8,17.16],[4.1,2.06]],"id":69979297}],"con":true,"img":false}]}
{"op":"mcm","clk":"11541339744","pt":1719504713028,"mc":[{"id":"1.230180130","rc":[{"atl":[[28,2.3],[30,1.54]],"id":58149406},{"atb":[[5.2,6]],"id":41138102}],"con":true,"img":false}]}
{"op":"mcm","clk":"11541339752","pt":1719504713136,"mc":[{"id":"1.230180130","rc":[{"atb":[[5,1]],"id":41138102},{"atb":[[4,0],[4.2,9.5]],"id":66499052}],"con":true,"img":false}]}
{"op":"mcm","clk":"11541339760","pt":1719504713235,"mc":[{"id":"1.230180130","rc":[{"atb":[[5.4,0]],"id":41138102}],"con":true,"img":false}]}
{"op":"mcm","clk":"11541339776","pt":1719504713445,"mc":[{"id":"1.230180130","rc":[{"atb":[[5.6,0.84]],"id":51843546}],"con":true,"img":false}]}
{"op":"mcm","clk":"11541339786","pt":1719504713548,"mc":[{"id":"1.230180130","rc":[{"atb":[[4.7,1]],"id":58149406},{"atb":[[5.3,1],[5.5,0]],"id":41138102},{"atb":[[5.3,0],[5.5,2],[5.2,1]],"id":51843546},{"atb":[[2.56,1.44]],"id":69979297}],"con":true,"img":false}]}
{"op":"mcm","clk":"11541339795","pt":1719504713651,"mc":[{"id":"1.230180130","rc":[{"atb":[[4.8,0]],"id":58149406},{"atb":[[2.6,0]],"id":69979297}],"con":true,"img":false}]}
{"op":"mcm","clk":"11541339800","pt":1719504713756,"mc":[{"id":"1.230180130","rc":[{"atb":[[3.35,3.4]],"id":58149406},{"atb":[[5.4,2.56]],"id":51843546}],"con":true,"img":false}]}
{"op":"mcm","clk":"11541339812","pt":1719504713860,"mc":[{"id":"1.230180130","rc":[{"atb":[[5.3,2.54]],"id":41138102}],"con":true,"img":false}]}
{"op":"mcm","clk":"11541339838","pt":1719504714126,"mc":[{"id":"1.230180130","rc":[{"atl":[[130,0]],"id":41138102},{"atl":[[130,0]],"id":43210435}],"con":true,"img":false}]}
{"op":"mcm","clk":"11541339848","pt":1719504714228,"mc":[{"id":"1.230180130","rc":[{"atb":[[5.4,4.7]],"id":41138102}],"con":true,"img":false}]}
{"op":"mcm","clk":"11541339858","pt":1719504714328,"mc":[{"id":"1.230180130","rc":[{"atl":[[29,0]],"id":58149406}],"con":true,"img":false}]}
{"op":"mcm","clk":"11541339868","pt":1719504714432,"mc":[{"id":"1.230180130","rc":[{"atb":[[5.3,1],[5.4,5.55],[5.5,1.54]],"id":41138102}],"con":true,"img":false}]}
{"op":"mcm","clk":"11541339946","pt":1719504715262,"mc":[{"id":"1.230180130","rc":[{"atb":[[5.4,0.84]],"id":41138102}],"con":true,"img":false}]}
{"op":"mcm","clk":"11541340063","pt":1719504716557,"mc":[{"id":"1.230180130","rc":[{"spl":[[1.01,5]],"id":66499052}],"con":true,"img":false}]}
{"op":"mcm","clk":"11541340298","pt":1719504719468,"mc":[{"id":"1.230180130","rc":[{"atb":[[3.6,4.56]],"id":43210435}],"con":true,"img":false}]}
{"op":"mcm","clk":"11541340313","pt":1719504719678,"mc":[{"id":"1.230180130","rc":[{"atb":[[2.28,9.26]],"id":41138102}],"con":true,"img":false}]}
{"op":"mcm","clk":"11541340331","pt":1719504719831,"mc":[{"id":"1.230180130","rc":[{"atb":[[1.93,12.74]],"id":69979297}],"con":true,"img":false}]}
{"op":"mcm","clk":"11541340347","pt":1719504720037,"mc":[{"id":"1.230180130","rc":[{"atb":[[2.22,9.72]],"id":58149406}],"con":true,"img":false}]}
{"op":"mcm","clk":"11541340352","pt":1719504720148,"mc":[{"id":"1.230180130","rc":[{"atl":[[27,0.96],[8.4,0]],"id":58149406},{"trd":[[8.4,2]],"ltp":8.4,"tv":2.0,"id":58149406},{"atb":[[5.5,6.47]],"id":41138102},{"atl":[[130,0.18]],"id":41138102},{"atb":[[5.9,6.81]],"id":43210435},{"atl":[[130,0.22]],"id":43210435}],"con":true,"img":false}]}
{"op":"mcm","clk":"11541340363","pt":1719504720258,"mc":[{"id":"1.230180130","rc":[{"atl":[[28,0.3],[29,3.57]],"id":58149406},{"atb":[[2.18,10.04]],"id":51843546}],"con":true,"img":false}]}
{"op":"mcm","clk":"11541340373","pt":1719504720358,"mc":[{"id":"1.230180130","rc":[{"atb":[[5.8,0]],"id":43210435}],"con":true,"img":false}]}
{"op":"mcm","clk":"11541340383","pt":1719504720454,"mc":[{"id":"1.230180130","rc":[{"atb":[[2.16,15.71]],"id":43210435},{"atb":[[2.16,5.45]],"id":66499052}],"con":true,"img":false}]}
{"op":"mcm","clk":"11541340394","pt":1719504720559,"mc":[{"id":"1.230180130","rc":[{"atb":[[6,1]],"id":43210435}],"con":true,"img":false}]}
{"op":"mcm","clk":"11541340404","pt":1719504720663,"mc":[{"id":"1.230180130","rc":[{"atb":[[2.16,21.66]],"id":51843546}],"con":true,"img":false}]}
{"op":"mcm","clk":"11541340418","pt":1719504720875,"mc":[{"id":"1.230180130","rc":[{"atl":[[1000,0.04]],"id":58149406},{"atb":[[5.9,5.38],[6.2,1.36]],"id":43210435}],"con":true,"img":false}]}
{"op":"mcm","clk":"11541340427","pt":1719504720982,"mc":[{"id":"1.230180130","rc":[{"atb":[[6.2,6.25],[6,1.84]],"id":43210435},{"atb":[[2.92,4.93]],"id":66499052}],"con":true,"img":false}]}
{"op":"mcm","clk":"11541340436","pt":1719504721031,"mc":[{"id":"1.230180130","rc":[{"atl":[[1000,0]],"id":58149406}],"con":true,"img":false}]}
{"op":"mcm","clk":"11541340445","pt":1719504721142,"mc":[{"id":"1.230180130","rc":[{"atl":[[27,1]],"id":58149406}],"con":true,"img":false}]}
{"op":"mcm","clk":"11541340455","pt":1719504721246,"mc":[{"id":"1.230180130","rc":[{"atb":[[6.4,3.96]],"id":43210435}],"con":true,"img":false}]}
{"op":"mcm","clk":"11541340465","pt":1719504721343,"mc":[{"id":"1.230180130","rc":[{"atb":[[2.9,4.99]],"id":58149406}],"con":true,"img":false}]}
{"op":"mcm","clk":"11541340510","pt":1719504721861,"mc":[{"id":"1.230180130","rc":[{"atb":[[2.04,5.4]],"id":69979297}],"con":true,"img":false}]}
{"op":"mcm","clk":"11541340517","pt":1719504721964,"mc":[{"id":"1.230180130","rc":[{"atb":[[5.6,0.84]],"id":41138102},{"atb":[[6.4,8.05],[6,1]],"id":43210435}],"con":true,"img":false}]}
{"op":"mcm","clk":"11541340544","pt":1719504722294,"mc":[{"id":"1.230180130","rc":[{"atb":[[5.3,0]],"id":41138102},{"atb":[[6,0]],"id":43210435}],"con":true,"img":false}]}
{"op":"mcm","clk":"11541340564","pt":1719504722451,"mc":[{"id":"1.230180130","rc":[{"atl":[[9.4,1]],"id":58149406},{"atb":[[5.6,1.84],[5.1,6.85],[5.2,0]],"id":41138102},{"atl":[[16.5,1],[14.5,0]],"id":41138102},{"atb":[[6.6,1]],"id":43210435},{"atb":[[4.6,10.05]],"id":51843546}],"con":true,"img":false}]}
{"op":"mcm","clk":"11541340574","pt":1719504722543,"mc":[{"id":"1.230180130","rc":[{"atb":[[5.5,0]],"id":51843546}],"con":true,"img":false}]}
{"op":"mcm","clk":"11541340582","pt":1719504722642,"mc":[{"id":"1.230180130","rc":[{"atb":[[5.5,2.02]],"id":51843546}],"con":true,"img":false}]}
{"op":"mcm","clk":"11541340590","pt":1719504722742,"mc":[{"id":"1.230180130","rc":[{"atb":[[3.4,9.32]],"id":58149406},{"atb":[[5.6,6.79]],"id":41138102}],"con":true,"img":false}]}
{"op":"mcm","clk":"11541340599","pt":1719504722848,"mc":[{"id":"1.230180130","rc":[{"atb":[[4.6,0]],"id":51843546}],"con":true,"img":false}]}
{"op":"mcm","clk":"11541340608","pt":1719504722951,"mc":[{"id":"1.230180130","rc":[{"atb":[[5.4,0]],"id":41138102},{"atb":[[6.4,4.09]],"id":43210435},{"atb":[[5.6,0]],"id":51843546}],"con":true,"img":false}]}
{"op":"mcm","clk":"11541340628","pt":1719504723167,"mc":[{"id":"1.230180130","rc":[{"atb":[[5.7,4.45]],"id":41138102}],"con":true,"img":false}]}
{"op":"mcm","clk":"11541340656","pt":1719504723478,"mc":[{"id":"1.230180130","rc":[{"atb":[[5.6,0.84]],"id":51843546}],"con":true,"img":false}]}
{"op":"mcm","clk":"11541340674","pt":1719504723649,"mc":[{"id":"1.230180130","rc":[{"atb":[[5,0]],"id":41138102}],"con":true,"img":false}]}
{"op":"mcm","clk":"11541340693","pt":1719504723843,"mc":[{"id":"1.230180130","rc":[{"atb":[[5.7,9.93]],"id":41138102}],"con":true,"img":false}]}
{"op":"mcm","clk":"11541340707","pt":1719504724055,"mc":[{"id":"1.230180130","rc":[{"atb":[[5.6,5.79]],"id":41138102}],"con":true,"img":false}]}
{"op":"mcm","clk":"11541340730","pt":1719504724364,"mc":[{"id":"1.230180130","rc":[{"atb":[[5.8,1]],"id":41138102}],"con":true,"img":false}]}
{"op":"mcm","clk":"11541340741","pt":1719504724569,"mc":[{"id":"1.230180130","rc":[{"atb":[[5.7,5.48]],"id":41138102}],"con":true,"img":false}]}
{"op":"mcm","clk":"11541340792","pt":1719504725146,"mc":[{"id":"1.230180130","rc":[{"atb":[[5.9,0]],"id":51843546}],"con":true,"img":false}]}
{"op":"mcm","clk":"11541340822","pt":1719504725456,"mc":[{"id":"1.230180130","rc":[{"atb":[[1.1,1]],"id":51843546}],"con":true,"img":false}]}
{"op":"mcm","clk":"11541340839","pt":1719504725662,"mc":[{"id":"1.230180130","rc":[{"atb":[[1.1,0.21]],"id":51843546}],"con":true,"img":false}]}
{"op":"mcm","clk":"11541340852","pt":1719504725870,"mc":[{"id":"1.230180130","rc":[{"atb":[[1.1,0]],"id":51843546}],"con":true,"img":false}]}
{"op":"mcm","clk":"11541340862","pt":1719504725974,"mc":[{"id":"1.230180130","rc":[{"atb":[[5.7,0.21]],"id":51843546}],"con":true,"img":false}]}
{"op":"mcm","clk":"11541340891","pt":1719504726238,"mc":[{"id":"1.230180130","rc":[{"atb":[[1.04,1.7]],"id":41138102},{"atl":[[1000,1.7]],"id":41138102},{"atb":[[1.05,1.7]],"id":43210435},{"atl":[[1000,1.87]],"id":43210435}],"con":true,"img":false}]}
{"op":"mcm","clk":"11541340906","pt":1719504726451,"mc":[{"id":"1.230180130","rc":[{"atb":[[1.04,0.05]],"id":41138102},{"atl":[[1000,0]],"id":41138102},{"atb":[[1.05,0.05]],"id":43210435},{"atl":[[1000,0.17]],"id":43210435}],"con":true,"img":false}]}
{"op":"mcm","clk":"11541340926","pt":1719504726655,"mc":[{"id":"1.230180130","rc":[{"atb":[[1.04,0]],"id":41138102},{"atb":[[1.05,0]],"id":43210435}],"con":true,"img":false}]}
{"op":"mcm","clk":"11541340935","pt":1719504726756,"mc":[{"id":"1.230180130","rc":[{"atb":[[5.8,1.05]],"id":41138102},{"atb":[[6.6,1.05]],"id":43210435}],"con":true,"img":false}]}
{"op":"mcm","clk":"11541341323","pt":1719504730942,"mc":[{"id":"1.230180130","rc":[{"atl":[[9.2,1],[9.4,0]],"id":58149406},{"atl":[[14,1]],"id":43210435},{"atb":[[5.8,1],[5.2,0]],"id":51843546}],"con":true,"img":false}]}
{"op":"mcm","clk":"11541341333","pt":1719504731048,"mc":[{"id":"1.230180130","rc":[{"atl":[[26,2],[29,0]],"id":58149406},{"atl":[[14.5,0]],"id":43210435}],"con":true,"img":false}]}
{"op":"mcm","clk":"11541341346","pt":1719504731157,"mc":[{"id":"1.230180130","rc":[{"atb":[[5.4,1.56]],"id":51843546}],"con":true,"img":false}]}
{"op":"mcm","clk":"11541341364","pt":1719504731360,"mc":[{"id":"1.230180130","rc":[{"atb":[[5.7,1.21]],"id":51843546}],"con":true,"img":false}]}
{"op":"mcm","clk":"11541341374","pt":1719504731463,"mc":[{"id":"1.230180130","rc":[{"atb":[[5.5,0],[5.7,3.21]],"id":51843546}],"con":true,"img":false}]}
{"op":"mcm","clk":"11541341394","pt":1719504731668,"mc":[{"id":"1.230180130","rc":[{"atb":[[5.7,2.21]],"id":51843546}],"con":true,"img":false}]}
{"op":"mcm","clk":"11541341403","pt":1719504731780,"mc":[{"id":"1.230180130","rc":[{"atb":[[5.6,1.84]],"id":51843546}],"con":true,"img":false}]}
{"op":"mcm","clk":"11541341417","pt":1719504731893,"mc":[{"id":"1.230180130","rc":[{"atl":[[25,1.1]],"id":58149406}],"con":true,"img":false}]}
{"op":"mcm","clk":"11541341528","pt":1719504733456,"mc":[{"id":"1.230180130","rc":[{"atl":[[25,2.1]],"id":58149406},{"atl":[[130,1.18]],"id":41138102},{"atl":[[130,1.22]],"id":43210435},{"atl":[[130,1.84]],"id":51843546},{"atl":[[2.62,1]],"id":69979297}],"con":true,"img":false}]}
{"op":"mcm","clk":"11541341649","pt":1719504734942,"mc":[{"id":"1.230180130","rc":[{"atl":[[2.62,14.75]],"id":69979297}],"con":true,"img":false}]}
{"op":"mcm","clk":"11541341750","pt":1719504736288,"mc":[{"id":"1.230180130","rc":[{"atl":[[27,0.96]],"id":58149406}],"con":true,"img":false}]}
{"op":"mcm","clk":"11541341927","pt":1719504738256,"mc":[{"id":"1.230180130","rc":[{"atb":[[2.16,5.45]],"id":41138102}],"con":true,"img":false}]}
{"op":"mcm","clk":"11541342176","pt":1719504741164,"mc":[{"id":"1.230180130","rc":[{"spn":6.95,"spf":"NaN","id":58149406},{"spn":11.15,"spf":"NaN","id":41138102},{"spn":10.3,"spf":"NaN","id":43210435},{"spn":4.95,"spf":1.0,"id":66499052},{"atb":[[5.7,2]],"id":51843546},{"spn":67.9,"spf":"NaN","id":51843546},{"spn":2.56,"spf":1.0,"id":69979297}],"con":true,"img":false}]}
{"op":"mcm","clk":"11541342205","pt":1719504741475,"mc":[{"id":"1.230180130","rc":[{"atb":[[1.1,1],[5.4,0]],"id":51843546}],"con":true,"img":false}]}
{"op":"mcm","clk":"11541342217","pt":1719504741578,"mc":[{"id":"1.230180130","rc":[{"atb":[[1.1,0.2],[5.9,1.43]],"id":51843546}],"con":true,"img":false}]}
{"op":"mcm","clk":"11541342235","pt":1719504741784,"mc":[{"id":"1.230180130","rc":[{"atb":[[1.1,0],[5.9,3.43],[5.7,0]],"id":51843546}],"con":true,"img":false}]}
{"op":"mcm","clk":"11541342246","pt":1719504741839,"mc":[{"id":"1.230180130","rc":[{"atb":[[5.9,3.63]],"id":51843546}],"con":true,"img":false}]}
{"op":"mcm","clk":"11541342267","pt":1719504742153,"mc":[{"id":"1.230180130","rc":[{"atb":[[2.1,0]],"id":69979297}],"con":true,"img":false}]}
{"op":"mcm","clk":"11541342291","pt":1719504742360,"mc":[{"id":"1.230180130","rc":[{"atb":[[6,0.84]],"id":51843546}],"con":true,"img":false}]}
{"op":"mcm","clk":"11541342305","pt":1719504742457,"mc":[{"id":"1.230180130","rc":[{"atb":[[5.6,1]],"id":51843546}],"con":true,"img":false}]}
{"op":"mcm","clk":"11541342315","pt":1719504742564,"mc":[{"id":"1.230180130","rc":[{"atb":[[5.6,0]],"id":51843546}],"con":true,"img":false}]}
{"op":"mcm","clk":"11541342352","pt":1719504742973,"mc":[{"id":"1.230180130","rc":[{"atb":[[5.8,0],[6,1.84]],"id":51843546}],"con":true,"img":false}]}
{"op":"mcm","clk":"11541342372","pt":1719504743181,"mc":[{"id":"1.230180130","rc":[{"atb":[[6.2,1]],"id":51843546}],"con":true,"img":false}]}
{"op":"mcm","clk":"11541342556","pt":1719504744944,"mc":[{"id":"1.230180130","rc":[{"atb":[[5.9,2.2],[6.2,2.36]],"id":51843546}],"con":true,"img":false}]}
{"op":"mcm","clk":"11541342833","pt":1719504748043,"mc":[{"id":"1.230180130","rc":[{"atb":[[5.9,0.2],[6.2,4.56]],"id":51843546}],"con":true,"img":false}]}
{"op":"mcm","clk":"11541342837","pt":1719504748152,"mc":[{"id":"1.230180130","rc":[{"atl":[[8.4,0.9]],"id":58149406}],"con":true,"img":false}]}
{"op":"mcm","clk":"11541342847","pt":1719504748257,"mc":[{"id":"1.230180130","rc":[{"atb":[[6.2,3.56]],"id":51843546}],"con":true,"img":false}]}
{"op":"mcm","clk":"11541342867","pt":1719504748460,"mc":[{"id":"1.230180130","rc":[{"atb":[[6.4,1]],"id":51843546}],"con":true,"img":false}]}
{"op":"mcm","clk":"11541342896","pt":1719504748771,"mc":[{"id":"1.230180130","rc":[{"atb":[[6.6,1.28]],"id":51843546}],"con":true,"img":false}]}
{"op":"mcm","clk":"11541342903","pt":1719504748874,"mc":[{"id":"1.230180130","rc":[{"atb":[[6.2,2.2]],"id":51843546}],"con":true,"img":false}]}
{"op":"mcm","clk":"11541342915","pt":1719504748981,"mc":[{"id":"1.230180130","rc":[{"atl":[[8.4,0]],"id":58149406},{"trd":[[8.4,3.81]],"ltp":8.4,"tv":3.81,"id":58149406}],"con":true,"img":false}]}
{"op":"mcm","clk":"11541342926","pt":1719504749081,"mc":[{"id":"1.230180130","rc":[{"atb":[[3.45,3.27]],"id":58149406}],"con":true,"img":false}]}
{"op":"mcm","clk":"11541342950","pt":1719504749492,"mc":[{"id":"1.230180130","rc":[{"atb":[[6,1]],"id":51843546}],"con":true,"img":false}]}
{"op":"mcm","clk":"11541342961","pt":1719504749546,"mc":[{"id":"1.230180130","rc":[{"atb":[[3.5,1.7]],"id":58149406},{"atb":[[5.8,2.86]],"id":41138102},{"atb":[[6.6,2.82]],"id":43210435}],"con":true,"img":false}]}
{"op":"mcm","clk":"11541342992","pt":1719504749955,"mc":[{"id":"1.230180130","rc":[{"atb":[[5.9,4.29]],"id":41138102},{"atb":[[6.8,3.73]],"id":43210435}],"con":true,"img":false}]}
{"op":"mcm","clk":"11541342997","pt":1719504750059,"mc":[{"id":"1.230180130","rc":[{"atb":[[3.55,9.66]],"id":58149406},{"atb":[[5.8,7.9]],"id":41138102},{"atb":[[6.6,7.07]],"id":43210435}],"con":true,"img":false}]}
{"op":"mcm","clk":"11541343003","pt":1719504750161,"mc":[{"id":"1.230180130","rc":[{"atb":[[5.8,6.09]],"id":41138102},{"atb":[[6.6,5.3]],"id":43210435}],"con":true,"img":false}]}
{"op":"mcm","clk":"11541343013","pt":1719504750263,"mc":[{"id":"1.230180130","rc":[{"atb":[[3.6,3.27],[3.3,1]],"id":58149406},{"atb":[[6,1.8]],"id":41138102},{"atb":[[7,1.77]],"id":43210435}],"con":true,"img":false}]}
{"op":"mcm","clk":"11541343020","pt":1719504750366,"mc":[{"id":"1.230180130","rc":[{"atb":[[5.6,4.95],[6,2.64]],"id":41138102},{"atb":[[7,2.62]],"id":43210435}],"con":true,"img":false}]}
{"op":"mcm","clk":"11541343044","pt":1719504750680,"mc":[{"id":"1.230180130","rc":[{"atb":[[5.9,0]],"id":41138102},{"atb":[[6.8,0]],"id":43210435}],"con":true,"img":false}]}
{"op":"mcm","clk":"11541343053","pt":1719504750779,"mc":[{"id":"1.230180130","rc":[{"atb":[[3.5,0]],"id":58149406}],"con":true,"img":false}]}
{"op":"mcm","clk":"11541343063","pt":1719504750882,"mc":[{"id":"1.230180130","rc":[{"atb":[[3.65,1.7]],"id":58149406}],"con":true,"img":false}]}
{"op":"mcm","clk":"11541343069","pt":1719504750987,"mc":[{"id":"1.230180130","rc":[{"atb":[[5.5,1.54]],"id":41138102},{"atb":[[5.9,0]],"id":43210435}],"con":true,"img":false}]}
{"op":"mcm","clk":"11541343079","pt":1719504751089,"mc":[{"id":"1.230180130","rc":[{"atb":[[3.65,11.38]],"id":58149406},{"atb":[[6,8.15]],"id":41138102},{"atb":[[7,6.53]],"id":43210435}],"con":true,"img":false}]}
{"op":"mcm","clk":"11541343093","pt":1719504751302,"mc":[{"id":"1.230180130","rc":[{"atb":[[5.8,5.09]],"id":41138102},{"atb":[[6.6,4.3]],"id":43210435}],"con":true,"img":false}]}
{"op":"mcm","clk":"11541343313","pt":1719504753897,"mc":[{"id":"1.230180130","rc":[{"atb":[[5,0]],"id":43210435}],"con":true,"img":false}]}
{"op":"mcm","clk":"11541343322","pt":1719504754002,"mc":[{"id":"1.230180130","rc":[{"atb":[[6.2,1]],"id":41138102},{"atb":[[7.2,1]],"id":43210435}],"con":true,"img":false}]}
{"op":"mcm","clk":"11541343354","pt":1719504754366,"mc":[{"id":"1.230180130","rc":[{"atb":[[3.6,0],[3.1,10.48]],"id":58149406},{"atl":[[9.2,0],[9.8,1]],"id":58149406},{"atb":[[5.1,0],[4.6,11.2]],"id":41138102},{"atb":[[3.6,6],[4.2,0]],"id":66499052},{"atl":[[10.5,5],[14,0]],"id":66499052},{"atb":[[6.2,0],[6.6,3.28]],"id":51843546},{"atb":[[2.04,0],[2.12,0]],"id":69979297},{"atl":[[3.8,0],[3.5,23.33]],"id":69979297}],"con":true,"img":false}]}
{"op":"mcm","clk":"11541343361","pt":1719504754469,"mc":[{"id":"1.230180130","rc":[{"atl":[[9,1.05]],"id":58149406}],"con":true,"img":false}]}
{"op":"mcm","clk":"11541343370","pt":1719504754575,"mc":[{"id":"1.230180130","rc":[{"atb":[[1.03,0.52]],"id":58149406},{"atl":[[24,2],[26,0]],"id":58149406},{"atb":[[6.4,0],[6,3.58],[6.6,1.28]],"id":51843546},{"atb":[[2.02,12.75],[2.04,5.4]],"id":69979297},{"atl":[[3.5,0],[3.2,23.33]],"id":69979297}],"con":true,"img":false}]}
{"op":"mcm","clk":"11541343380","pt":1719504754683,"mc":[{"id":"1.230180130","rc":[{"atl":[[12,2.05],[24,0]],"id":58149406}],"con":true,"img":false}]}
{"op":"mcm","clk":"11541343390","pt":1719504754782,"mc":[{"id":"1.230180130","rc":[{"atb":[[1.03,0.41]],"id":58149406},{"atb":[[6.2,1]],"id":51843546}],"con":true,"img":false}]}
{"op":"mcm","clk":"11541343408","pt":1719504754987,"mc":[{"id":"1.230180130","rc":[{"atb":[[1.03,0]],"id":58149406},{"atb":[[6.2,2.28],[6.6,0]],"id":51843546}],"con":true,"img":false}]}
{"op":"mcm","clk":"11541343414","pt":1719504755090,"mc":[{"id":"1.230180130","rc":[{"atb":[[4.8,0.41]],"id":58149406}],"con":true,"img":false}]}
{"op":"mcm","clk":"11541343433","pt":1719504755402,"mc":[{"id":"1.230180130","rc":[{"atb":[[6.4,0.84]],"id":51843546}],"con":true,"img":false}]}
{"op":"mcm","clk":"11541343440","pt":1719504755502,"mc":[{"id":"1.230180130","rc":[{"atb":[[3.25,3.86]],"id":66499052}],"con":true,"img":false}]}
{"op":"mcm","clk":"11541343449","pt":1719504755556,"mc":[{"id":"1.230180130","rc":[{"atb":[[6.2,3.91]],"id":51843546}],"con":true,"img":false}]}
{"op":"mcm","clk":"11541343460","pt":1719504755761,"mc":[{"id":"1.230180130","rc":[{"atb":[[3.2,3.95]],"id":58149406}],"con":true,"img":false}]}
{"op":"mcm","clk":"11541343469","pt":1719504755868,"mc":[{"id":"1.230180130","rc":[{"atb":[[3.4,10.49]],"id":66499052}],"con":true,"img":false}]}
{"op":"mcm","clk":"11541343498","pt":1719504756174,"mc":[{"id":"1.230180130","rc":[{"atb":[[3.65,1.61]],"id":66499052}],"con":true,"img":false}]}
{"op":"mcm","clk":"11541343587","pt":1719504757163,"mc":[{"id":"1.230180130","rc":[{"atb":[[5.9,0]],"id":51843546}],"con":true,"img":false}]}
{"op":"mcm","clk":"11541343659","pt":1719504757986,"mc":[{"id":"1.230180130","rc":[{"atb":[[1.11,1]],"id":51843546}],"con":true,"img":false}]}
{"op":"mcm","clk":"11541343692","pt":1719504758299,"mc":[{"id":"1.230180130","rc":[{"atb":[[1.11,0.19]],"id":51843546}],"con":true,"img":false}]}
{"op":"mcm","clk":"11541343709","pt":1719504758456,"mc":[{"id":"1.230180130","rc":[{"atb":[[1.11,0]],"id":51843546}],"con":true,"img":false}]}
{"op":"mcm","clk":"11541343716","pt":1719504758559,"mc":[{"id":"1.230180130","rc":[{"atl":[[25,1.1]],"id":58149406},{"atb":[[6.4,1.03]],"id":51843546}],"con":true,"img":false}]}
{"op":"mcm","clk":"11541343722","pt":1719504758662,"mc":[{"id":"1.230180130","rc":[{"atl":[[11.5,1]],"id":58149406}],"con":true,"img":false}]}
{"op":"mcm","clk":"11541343729","pt":1719504758766,"mc":[{"id":"1.230180130","rc":[{"atb":[[4.8,1.41],[4.7,0]],"id":58149406},{"atb":[[2.08,2.09],[2.56,0]],"id":69979297}],"con":true,"img":false}]}
{"op":"mcm","clk":"11541343738","pt":1719504758869,"mc":[{"id":"1.230180130","rc":[{"atb":[[3.7,2.96]],"id":58149406},{"atl":[[16.5,1]],"id":43210435}],"con":true,"img":false}]}
{"op":"mcm","clk":"11541343747","pt":1719504758972,"mc":[{"id":"1.230180130","rc":[{"atl":[[14,0]],"id":43210435}],"con":true,"img":false}]}
{"op":"mcm","clk":"11541343763","pt":1719504759184,"mc":[{"id":"1.230180130","rc":[{"atb":[[3.65,9.68]],"id":58149406},{"atb":[[6.2,2.28]],"id":51843546}],"con":true,"img":false}]}
{"op":"mcm","clk":"11541343772","pt":1719504759281,"mc":[{"id":"1.230180130","rc":[{"atb":[[3.7,4.66]],"id":58149406},{"atl":[[2.6,6.34]],"id":69979297}],"con":true,"img":false}]}
{"op":"mcm","clk":"11541343804","pt":1719504759693,"mc":[{"id":"1.230180130","rc":[{"atl":[[2.62,13.75]],"id":69979297}],"con":true,"img":false}]}
{"op":"mcm","clk":"11541343809","pt":1719504759797,"mc":[{"id":"1.230180130","rc":[{"atl":[[2.58,1]],"id":69979297}],"con":true,"img":false}]}
{"op":"mcm","clk":"11541343853","pt":1719504760266,"mc":[{"id":"1.230180130","rc":[{"atl":[[2.6,0],[2.58,17.33]],"id":69979297}],"con":true,"img":false}]}
{"op":"mcm","clk":"11541343864","pt":1719504760368,"mc":[{"id":"1.230180130","rc":[{"atb":[[3.7,6.69]],"id":58149406}],"con":true,"img":false}]}
{"op":"mcm","clk":"11541343882","pt":1719504760575,"mc":[{"id":"1.230180130","rc":[{"atl":[[2.58,16.33]],"id":69979297}],"con":true,"img":false}]}
{"op":"mcm","clk":"11541343892","pt":1719504760677,"mc":[{"id":"1.230180130","rc":[{"atl":[[2.6,1]],"id":69979297}],"con":true,"img":false}]}
{"op":"mcm","clk":"11541343920","pt":1719504760988,"mc":[{"id":"1.230180130","rc":[{"atl":[[2.56,6.34]],"id":69979297}],"con":true,"img":false}]}
{"op":"mcm","clk":"11541343992","pt":1719504761666,"mc":[{"id":"1.230180130","rc":[{"atl":[[2.6,0]],"id":69979297}],"con":true,"img":false}]}
{"op":"mcm","clk":"11541343999","pt":1719504761769,"mc":[{"id":"1.230180130","rc":[{"atl":[[2.54,1]],"id":69979297}],"con":true,"img":false}]}
{"op":"mcm","clk":"11541344034","pt":1719504762083,"mc":[{"id":"1.230180130","rc":[{"atl":[[1000,2],[2.56,0]],"id":69979297}],"con":true,"img":false}]}
{"op":"mcm","clk":"11541344051","pt":1719504762293,"mc":[{"id":"1.230180130","rc":[{"atl":[[1000,0.5]],"id":69979297}],"con":true,"img":false}]}
{"op":"mcm","clk":"11541344073","pt":1719504762500,"mc":[{"id":"1.230180130","rc":[{"atl":[[1000,0]],"id":69979297}],"con":true,"img":false}]}
{"op":"mcm","clk":"11541344083","pt":1719504762598,"mc":[{"id":"1.230180130","rc":[{"atl":[[2.56,0.5]],"id":69979297}],"con":true,"img":false}]}
{"op":"mcm","clk":"11541344094","pt":1719504762704,"mc":[{"id":"1.230180130","rc":[{"atl":[[2.54,0]],"id":69979297}],"con":true,"img":false}]}
{"op":"mcm","clk":"11541344106","pt":1719504762806,"mc":[{"id":"1.230180130","rc":[{"atl":[[2.56,1.5]],"id":69979297}],"con":true,"img":false}]}
{"op":"mcm","clk":"11541344116","pt":1719504762909,"mc":[{"id":"1.230180130","rc":[{"atb":[[2.18,0]],"id":51843546}],"con":true,"img":false}]}
{"op":"mcm","clk":"11541344306","pt":1719504765092,"mc":[{"id":"1.230180130","rc":[{"atb":[[5.8,5.04]],"id":41138102},{"atb":[[6.6,4.25]],"id":43210435}],"con":true,"img":false}]}
{"op":"mcm","clk":"11541344367","pt":1719504765917,"mc":[{"id":"1.230180130","rc":[{"atb":[[3.85,9.66],[3.1,3.81]],"id":58149406},{"atl":[[9,3.05],[9.2,1],[12,0],[9.8,0]],"id":58149406},{"atb":[[5.1,9.99]],"id":41138102},{"atl":[[16.5,0],[17.5,1]],"id":41138102},{"atb":[[4.5,0],[3.95,8.5]],"id":43210435},{"atl":[[140,0],[85,2]],"id":43210435},{"atb":[[3.6,0],[4.1,6]],"id":66499052},{"atb":[[6.4,3.32],[6,1]],"id":51843546},{"atb":[[2.12,12.85],[2.02,0]],"id":69979297},{"atl":[[3.55,27.5],[3.2,0]],"id":69979297}],"con":true,"img":false}]}
{"op":"mcm","clk":"11541344377","pt":1719504766016,"mc":[{"id":"1.230180130","rc":[{"atl":[[9,1.05]],"id":58149406},{"atb":[[4.6,1]],"id":41138102},{"atl":[[140,0],[120,2]],"id":41138102},{"atl":[[10.5,0]],"id":66499052}],"con":true,"img":false}]}
{"op":"mcm","clk":"11541344383","pt":1719504766151,"mc":[{"id":"1.230180130","rc":[{"atl":[[80,0.3]],"id":43210435},{"atl":[[13,7.5]],"id":66499052},{"atb":[[6.2,1.28]],"id":51843546}],"con":true,"img":false}]}
{"op":"mcm","clk":"11541344393","pt":1719504766196,"mc":[{"id":"1.230180130","rc":[{"atl":[[11,4.05]],"id":58149406}],"con":true,"img":false}]}
{"op":"mcm","clk":"11541344402","pt":1719504766304,"mc":[{"id":"1.230180130","rc":[{"atb":[[6.6,1]],"id":51843546}],"con":true,"img":false}]}
{"op":"mcm","clk":"11541344440","pt":1719504766772,"mc":[{"id":"1.230180130","rc":[{"atb":[[3.7,4.99]],"id":58149406},{"atl":[[110,0.25]],"id":41138102}],"con":true,"img":false}]}
{"op":"mcm","clk":"11541344452","pt":1719504766876,"mc":[{"id":"1.230180130","rc":[{"atb":[[3.9,1.7]],"id":58149406}],"con":true,"img":false}]}
{"op":"mcm","clk":"11541344584","pt":1719504768586,"mc":[{"id":"1.230180130","rc":[{"atl":[[11.5,0]],"id":58149406},{"atl":[[130,0.18]],"id":41138102},{"atl":[[130,0.22]],"id":43210435}],"con":true,"img":false}]}
{"op":"mcm","clk":"11541344594","pt":1719504768692,"mc":[{"id":"1.230180130","rc":[{"atl":[[10.5,1]],"id":58149406},{"atl":[[110,1.25]],"id":41138102},{"atl":[[80,1.3]],"id":43210435}],"con":true,"img":false}]}
{"op":"mcm","clk":"11541344603","pt":1719504768795,"mc":[{"id":"1.230180130","rc":[{"atl":[[16.5,0],[16,1]],"id":43210435}],"con":true,"img":false}]}
{"op":"mcm","clk":"11541344683","pt":1719504769678,"mc":[{"id":"1.230180130","rc":[{"atl":[[9,0]],"id":58149406}],"con":true,"img":false}]}
{"op":"mcm","clk":"11541344691","pt":1719504769778,"mc":[{"id":"1.230180130","rc":[{"atb":[[3.9,4.46]],"id":58149406}],"con":true,"img":false}]}
{"op":"mcm","clk":"11541344735","pt":1719504770399,"mc":[{"id":"1.230180130","rc":[{"atb":[[4.8,1]],"id":58149406}],"con":true,"img":false}]}
{"op":"mcm","clk":"11541344784","pt":1719504771017,"mc":[{"id":"1.230180130","rc":[{"atb":[[3.95,9.41]],"id":58149406},{"atb":[[2.12,0],[2.1,22.88]],"id":69979297}],"con":true,"img":false}]}
{"op":"mcm","clk":"11541344806","pt":1719504771280,"mc":[{"id":"1.230180130","rc":[{"atb":[[6.4,1.32]],"id":41138102}],"con":true,"img":false}]}
{"op":"mcm","clk":"11541344822","pt":1719504771491,"mc":[{"id":"1.230180130","rc":[{"atb":[[3.9,2.76]],"id":58149406},{"atb":[[5.5,0]],"id":41138102}],"con":true,"img":false}]}
{"op":"mcm","clk":"11541344832","pt":1719504771590,"mc":[{"id":"1.230180130","rc":[{"atb":[[4,1.7]],"id":58149406},{"atl":[[9,0.93]],"id":58149406}],"con":true,"img":false}]}
{"op":"mcm","clk":"11541344844","pt":1719504771797,"mc":[{"id":"1.230180130","rc":[{"atl":[[10.5,2],[28,0]],"id":58149406}],"con":true,"img":false}]}
{"op":"mcm","clk":"11541344859","pt":1719504772007,"mc":[{"id":"1.230180130","rc":[{"atb":[[5.4,9.99],[5.1,0]],"id":41138102},{"atb":[[4.6,8.34]],"id":43210435}],"con":true,"img":false}]}
{"op":"mcm","clk":"11541344870","pt":1719504772109,"mc":[{"id":"1.230180130","rc":[{"atb":[[3.95,0]],"id":43210435}],"con":true,"img":false}]}
{"op":"mcm","clk":"11541344919","pt":1719504772693,"mc":[{"id":"1.230180130","rc":[{"atl":[[30,0]],"id":58149406}],"con":true,"img":false}]}
{"op":"mcm","clk":"11541344941","pt":1719504772897,"mc":[{"id":"1.230180130","rc":[{"atb":[[3.4,0]],"id":58149406}],"con":true,"img":false}]}
{"op":"mcm","clk":"11541344952","pt":1719504773000,"mc":[{"id":"1.230180130","rc":[{"atb":[[4.1,7.48]],"id":58149406}],"con":true,"img":false}]}
{"op":"mcm","clk":"11541344984","pt":1719504773320,"mc":[{"id":"1.230180130","rc":[{"atb":[[4,0]],"id":58149406}],"con":true,"img":false}]}
{"op":"mcm","clk":"11541344993","pt":1719504773376,"mc":[{"id":"1.230180130","rc":[{"atb":[[4.2,1.7]],"id":58149406}],"con":true,"img":false}]}
{"op":"mcm","clk":"11541345043","pt":1719504773905,"mc":[{"id":"1.230180130","rc":[{"atb":[[6.4,3.13]],"id":51843546}],"con":true,"img":false}]}
{"op":"mcm","clk":"11541345064","pt":1719504774107,"mc":[{"id":"1.230180130","rc":[{"atb":[[3.55,0]],"id":58149406}],"con":true,"img":false}]}
{"op":"mcm","clk":"11541345071","pt":1719504774213,"mc":[{"id":"1.230180130","rc":[{"atb":[[4.3,8.1]],"id":58149406},{"atb":[[1.12,1]],"id":51843546}],"con":true,"img":false}]}
{"op":"mcm","clk":"11541345094","pt":1719504774418,"mc":[{"id":"1.230180130","rc":[{"atb":[[1.12,0.17]],"id":51843546}],"con":true,"img":false}]}
{"op":"mcm","clk":"11541345104","pt":1719504774521,"mc":[{"id":"1.230180130","rc":[{"atb":[[4.2,0]],"id":58149406}],"con":true,"img":false}]}
{"op":"mcm","clk":"11541345124","pt":1719504774676,"mc":[{"id":"1.230180130","rc":[{"atb":[[4.4,1.7]],"id":58149406},{"atb":[[1.12,0]],"id":51843546}],"con":true,"img":false}]}
{"op":"mcm","clk":"11541345134","pt":1719504774778,"mc":[{"id":"1.230180130","rc":[{"atb":[[6.8,0.17]],"id":51843546}],"con":true,"img":false}]}
{"op":"mcm","clk":"11541345143","pt":1719504774881,"mc":[{"id":"1.230180130","rc":[{"atb":[[3.65,0]],"id":58149406},{"atl":[[9.2,0],[9.4,1]],"id":58149406},{"atl":[[17.5,0],[18,1],[19.5,1]],"id":41138102},{"atl":[[16,0],[17,1]],"id":43210435}],"con":true,"img":false}]}
{"op":"mcm","clk":"11541345151","pt":1719504774985,"mc":[{"id":"1.230180130","rc":[{"atl":[[100,2],[120,0]],"id":41138102},{"atl":[[75,2]],"id":43210435}],"con":true,"img":false}]}
{"op":"mcm","clk":"11541345160","pt":1719504775089,"mc":[{"id":"1.230180130","rc":[{"atb":[[4.5,7.47]],"id":58149406},{"atl":[[18,0]],"id":41138102},{"atb":[[4.6,0]],"id":43210435},{"atl":[[85,0]],"id":43210435},{"atb":[[2,12.75],[2.1,0]],"id":69979297}],"con":true,"img":false}]}
{"op":"mcm","clk":"11541345168","pt":1719504775197,"mc":[{"id":"1.230180130","rc":[{"atb":[[4.9,8.34]],"id":43210435}],"con":true,"img":false}]}
{"op":"mcm","clk":"11541345211","pt":1719504775708,"mc":[{"id":"1.230180130","rc":[{"atb":[[4.4,0]],"id":58149406},{"atl":[[110,0.25]],"id":41138102},{"atl":[[80,0.3]],"id":43210435}],"con":true,"img":false}]}
{"op":"mcm","clk":"11541345220","pt":1719504775811,"mc":[{"id":"1.230180130","rc":[{"atb":[[4.6,1.7]],"id":58149406},{"atb":[[5.6,0]],"id":41138102},{"atl":[[95,1]],"id":41138102},{"atl":[[70,1]],"id":43210435}],"con":true,"img":false}]}
{"op":"mcm","clk":"11541345251","pt":1719504776192,"mc":[{"id":"1.230180130","rc":[{"atb":[[6.4,5.53]],"id":41138102},{"atl":[[95,1.26]],"id":41138102},{"atl":[[70,1.4]],"id":43210435}],"con":true,"img":false}]}
{"op":"mcm","clk":"11541345268","pt":1719504776392,"mc":[{"id":"1.230180130","rc":[{"atb":[[6.6,3.85]],"id":41138102}],"con":true,"img":false}]}
{"op":"mcm","clk":"11541345286","pt":1719504776598,"mc":[{"id":"1.230180130","rc":[{"atb":[[3.95,0]],"id":58149406}],"con":true,"img":false}]}
{"op":"mcm","clk":"11541345304","pt":1719504776808,"mc":[{"id":"1.230180130","rc":[{"atb":[[4.7,6.5]],"id":58149406},{"atb":[[6.8,0.84]],"id":41138102}],"con":true,"img":false}]}
{"op":"mcm","clk":"11541345313","pt":1719504776912,"mc":[{"id":"1.230180130","rc":[{"atb":[[6,5.51]],"id":41138102}],"con":true,"img":false}]}
{"op":"mcm","clk":"11541345321","pt":1719504777015,"mc":[{"id":"1.230180130","rc":[{"atb":[[6.8,2.64],[6.6,0]],"id":41138102}],"con":true,"img":false}]}
{"op":"mcm","clk":"11541345344","pt":1719504777253,"mc":[{"id":"1.230180130","rc":[{"atb":[[5.7,0]],"id":41138102}],"con":true,"img":false}]}
{"op":"mcm","clk":"11541345355","pt":1719504777281,"mc":[{"id":"1.230180130","rc":[{"atb":[[6.8,6.49]],"id":41138102}],"con":true,"img":false}]}
{"op":"mcm","clk":"11541345377","pt":1719504777488,"mc":[{"id":"1.230180130","rc":[{"atb":[[4.6,0]],"id":58149406}],"con":true,"img":false}]}
{"op":"mcm","clk":"11541345387","pt":1719504777591,"mc":[{"id":"1.230180130","rc":[{"atb":[[4.8,2.7]],"id":58149406}],"con":true,"img":false}]}
{"op":"mcm","clk":"11541345448","pt":1719504778319,"mc":[{"id":"1.230180130","rc":[{"atb":[[4.9,0.84]],"id":58149406}],"con":true,"img":false}]}
{"op":"mcm","clk":"11541345460","pt":1719504778420,"mc":[{"id":"1.230180130","rc":[{"atb":[[4.1,0]],"id":58149406}],"con":true,"img":false}]}
{"op":"mcm","clk":"11541345469","pt":1719504778525,"mc":[{"id":"1.230180130","rc":[{"atb":[[4.9,6.83]],"id":58149406}],"con":true,"img":false}]}
{"op":"mcm","clk":"11541345480","pt":1719504778629,"mc":[{"id":"1.230180130","rc":[{"atl":[[9.2,1.66]],"id":58149406}],"con":true,"img":false}]}
{"op":"mcm","clk":"11541345489","pt":1719504778685,"mc":[{"id":"1.230180130","rc":[{"atb":[[4.8,1]],"id":58149406}],"con":true,"img":false}]}
{"op":"mcm","clk":"11541345499","pt":1719504778847,"mc":[{"id":"1.230180130","rc":[{"atb":[[5,1.7]],"id":58149406}],"con":true,"img":false}]}
{"op":"mcm","clk":"11541345510","pt":1719504778897,"mc":[{"id":"1.230180130","rc":[{"atb":[[5,6.77]],"id":58149406}],"con":true,"img":false}]}
{"op":"mcm","clk":"11541345528","pt":1719504779098,"mc":[{"id":"1.230180130","rc":[{"atl":[[10.5,1]],"id":58149406}],"con":true,"img":false}]}
{"op":"mcm","clk":"11541345537","pt":1719504779207,"mc":[{"id":"1.230180130","rc":[{"atb":[[4.3,0]],"id":58149406},{"atl":[[9,1.93]],"id":58149406}],"con":true,"img":false}]}
{"op":"mcm","clk":"11541345558","pt":1719504779413,"mc":[{"id":"1.230180130","rc":[{"atb":[[5,13.12]],"id":58149406}],"con":true,"img":false}]}
{"op":"mcm","clk":"11541345601","pt":1719504779926,"mc":[{"id":"1.230180130","rc":[{"atl":[[8.8,0.84]],"id":58149406}],"con":true,"img":false}]}
{"op":"mcm","clk":"11541345641","pt":1719504780402,"mc":[{"id":"1.230180130","rc":[{"atb":[[5.1,1.41],[5,14.14]],"id":58149406},{"atb":[[1.03,194.79]],"id":43210435}],"con":true,"img":false}]}
{"op":"mcm","clk":"11541345653","pt":1719504780509,"mc":[{"id":"1.230180130","rc":[{"atl":[[9,2.2]],"id":58149406},{"atl":[[21,0.26]],"id":41138102},{"atl":[[23,0.26]],"id":43210435},{"atl":[[6.6,0.26]],"id":66499052},{"atl":[[120,0.26]],"id":51843546},{"atl":[[2.54,0.26]],"id":69979297}],"con":true,"img":false}]}
{"op":"mcm","clk":"11541345664","pt":1719504780615,"mc":[{"id":"1.230180130","rc":[{"atb":[[1.03,194.5]],"id":43210435}],"con":true,"img":false}]}
{"op":"mcm","clk":"11541345685","pt":1719504780820,"mc":[{"id":"1.230180130","rc":[{"atb":[[5,9.07]],"id":58149406}],"con":true,"img":false}]}
{"op":"mcm","clk":"11541345694","pt":1719504780926,"mc":[{"id":"1.230180130","rc":[{"atb":[[4.5,0]],"id":58149406},{"atb":[[1.03,193.79]],"id":43210435}],"con":true,"img":false}]}
{"op":"mcm","clk":"11541345703","pt":1719504781033,"mc":[{"id":"1.230180130","rc":[{"atb":[[7.2,1.71]],"id":43210435}],"con":true,"img":false}]}
{"op":"mcm","clk":"11541345711","pt":1719504781139,"mc":[{"id":"1.230180130","rc":[{"atb":[[5.1,8.06]],"id":58149406},{"atl":[[12.5,1.94]],"id":66499052},{"atl":[[2.54,16.56]],"id":69979297}],"con":true,"img":false}]}
{"op":"mcm","clk":"11541345739","pt":1719504781404,"mc":[{"id":"1.230180130","rc":[{"atb":[[5.2,4.88]],"id":58149406},{"atl":[[8.8,1.89]],"id":58149406},{"atb":[[2.28,0]],"id":41138102},{"atb":[[7.4,0.84]],"id":43210435},{"atl":[[2.52,6.34]],"id":69979297}],"con":true,"img":false}]}
{"op":"mcm","clk":"11541345748","pt":1719504781510,"mc":[{"id":"1.230180130","rc":[{"atb":[[1.03,0.52]],"id":58149406},{"atl":[[9,3.32]],"id":58149406}],"con":true,"img":false}]}
{"op":"mcm","clk":"11541345757","pt":1719504781615,"mc":[{"id":"1.230180130","rc":[{"atb":[[4.7,0],[5.3,0.26]],"id":58149406},{"atb":[[7,0.26]],"id":41138102},{"atb":[[6.2,1.36],[7.6,0.26]],"id":43210435},{"atb":[[5.1,1.77]],"id":66499052},{"atb":[[6,1.26]],"id":51843546},{"atb":[[2.16,1.67]],"id":69979297}],"con":true,"img":false}]}
{"op":"mcm","clk":"11541345764","pt":1719504781724,"mc":[{"id":"1.230180130","rc":[{"atb":[[1.03,0.37],[5,7.37],[5.2,11.51]],"id":58149406},{"atl":[[9,2.38],[8.6,0.98]],"id":58149406},{"atb":[[7.4,5.08],[7,4.75]],"id":43210435},{"atl":[[2.52,23.52]],"id":69979297}],"con":true,"img":false}]}
{"op":"mcm","clk":"11541345774","pt":1719504781826,"mc":[{"id":"1.230180130","rc":[{"atb":[[5.3,1.96]],"id":58149406},{"atb":[[6.2,0]],"id":41138102},{"atb":[[7.2,3.48]],"id":43210435}],"con":true,"img":false}]}
{"op":"mcm","clk":"11541345781","pt":1719504782045,"mc":[{"id":"1.230180130","rc":[{"atb":[[1.03,0],[4.9,5.99]],"id":58149406},{"atb":[[7,1.26]],"id":41138102}],"con":true,"img":false}]}
{"op":"mcm","clk":"11541345791","pt":1719504782078,"mc":[{"id":"1.230180130","rc":[{"atb":[[5.2,7]],"id":58149406},{"atl":[[9.2,0]],"id":58149406}],"con":true,"img":false}]}
{"op":"mcm","clk":"11541345798","pt":1719504782090,"mc":[{"id":"1.230180130","rc":[{"atl":[[2.64,12.11]],"id":69979297}],"con":true,"img":false}]}
{"op":"mcm","clk":"11541345807","pt":1719504782199,"mc":[{"id":"1.230180130","rc":[{"atb":[[5.4,4.7]],"id":58149406},{"atl":[[9,1.38]],"id":58149406},{"atb":[[7.6,3.6]],"id":43210435},{"atl":[[2.56,0.5]],"id":69979297}],"con":true,"img":false}]}
{"op":"mcm","clk":"11541345817","pt":1719504782299,"mc":[{"id":"1.230180130","rc":[{"atl":[[8.6,1.98]],"id":58149406},{"atb":[[7.2,1.71]],"id":43210435},{"atl":[[2.5,1],[2.56,0]],"id":69979297}],"con":true,"img":false}]}
{"op":"mcm","clk":"11541345826","pt":1719504782407,"mc":[{"id":"1.230180130","rc":[{"atb":[[7.6,5.38],[7,3.91]],"id":43210435}],"con":true,"img":false}]}
{"op":"mcm","clk":"11541345846","pt":1719504782615,"mc":[{"id":"1.230180130","rc":[{"atb":[[4.9,0]],"id":58149406},{"atb":[[5.8,0]],"id":41138102},{"atb":[[6.4,0],[7.2,0.71]],"id":43210435}],"con":true,"img":false}]}
{"op":"mcm","clk":"11541345855","pt":1719504782722,"mc":[{"id":"1.230180130","rc":[{"atb":[[7.8,1]],"id":43210435}],"con":true,"img":false}]}
{"op":"mcm","clk":"11541345863","pt":1719504782824,"mc":[{"id":"1.230180130","rc":[{"atb":[[5.4,10.85]],"id":58149406},{"atb":[[7,5.74]],"id":41138102},{"atb":[[7.6,8.98]],"id":43210435},{"atl":[[2.52,17.18]],"id":69979297}],"con":true,"img":false}]}
{"op":"mcm","clk":"11541345870","pt":1719504782930,"mc":[{"id":"1.230180130","rc":[{"atb":[[5.3,0.26]],"id":58149406}],"con":true,"img":false}]}
{"op":"mcm","clk":"11541345876","pt":1719504783032,"mc":[{"id":"1.230180130","rc":[{"atb":[[5.5,1.7]],"id":58149406},{"atb":[[7.2,3.52]],"id":41138102}],"con":true,"img":false}]}
{"op":"mcm","clk":"11541345905","pt":1719504783395,"mc":[{"id":"1.230180130","rc":[{"atb":[[6.8,5.65]],"id":41138102}],"con":true,"img":false}]}
{"op":"mcm","clk":"11541345914","pt":1719504783498,"mc":[{"id":"1.230180130","rc":[{"atb":[[5,1.02]],"id":58149406},{"atb":[[6.8,3.85],[6,0]],"id":41138102}],"con":true,"img":false}]}
{"op":"mcm","clk":"11541345922","pt":1719504783603,"mc":[{"id":"1.230180130","rc":[{"atb":[[5.4,6.15]],"id":58149406},{"atb":[[7.4,1.8]],"id":41138102},{"atb":[[7.6,5.63]],"id":43210435}],"con":true,"img":false}]}
{"op":"mcm","clk":"11541345930","pt":1719504783705,"mc":[{"id":"1.230180130","rc":[{"atb":[[5.4,7.97],[5.5,7.22]],"id":58149406},{"atl":[[8.6,3.15]],"id":58149406},{"atb":[[7.2,7.45]],"id":41138102}],"con":true,"img":false}]}
{"op":"mcm","clk":"11541345943","pt":1719504783914,"mc":[{"id":"1.230180130","rc":[{"atb":[[7.4,2.64],[7,4.74]],"id":41138102}],"con":true,"img":false}]}
{"op":"mcm","clk":"11541345951","pt":1719504784017,"mc":[{"id":"1.230180130","rc":[{"atb":[[4.8,0]],"id":58149406},{"atb":[[7.4,3.64]],"id":41138102}],"con":true,"img":false}]}
{"op":"mcm","clk":"11541345972","pt":1719504784329,"mc":[{"id":"1.230180130","rc":[{"atb":[[7.2,3.93]],"id":41138102}],"con":true,"img":false}]}
{"op":"mcm","clk":"11541345983","pt":1719504784433,"mc":[{"id":"1.230180130","rc":[{"atb":[[6.4,1.32]],"id":41138102}],"con":true,"img":false}]}
{"op":"mcm","clk":"11541345991","pt":1719504784548,"mc":[{"id":"1.230180130","rc":[{"atb":[[5.6,4.53]],"id":58149406},{"atb":[[7.6,3.34]],"id":41138102}],"con":true,"img":false}]}
{"op":"mcm","clk":"11541346002","pt":1719504784590,"mc":[{"id":"1.230180130","rc":[{"atb":[[7.4,7.09]],"id":41138102}],"con":true,"img":false}]}
{"op":"mcm","clk":"11541346006","pt":1719504784695,"mc":[{"id":"1.230180130","rc":[{"atb":[[7.4,6.09]],"id":41138102}],"con":true,"img":false}]}
{"op":"mcm","clk":"11541346021","pt":1719504784903,"mc":[{"id":"1.230180130","rc":[{"atb":[[7.8,1]],"id":41138102}],"con":true,"img":false}]}
{"op":"mcm","clk":"11541346037","pt":1719504785111,"mc":[{"id":"1.230180130","rc":[{"atb":[[5.1,1.41]],"id":58149406},{"atb":[[6.8,0]],"id":41138102}],"con":true,"img":false}]}
{"op":"mcm","clk":"11541346049","pt":1719504785222,"mc":[{"id":"1.230180130","rc":[{"atb":[[5.6,9.96]],"id":58149406},{"atb":[[7.8,4.9],[7.6,0]],"id":41138102}],"con":true,"img":false}]}
{"op":"mcm","clk":"11541346061","pt":1719504785320,"mc":[{"id":"1.230180130","rc":[{"atb":[[5.5,5.52]],"id":58149406},{"atb":[[7.4,4.29]],"id":41138102}],"con":true,"img":false}]}
{"op":"mcm","clk":"11541346072","pt":1719504785424,"mc":[{"id":"1.230180130","rc":[{"atb":[[5.7,2.54]],"id":58149406},{"atb":[[7.8,6.7]],"id":41138102}],"con":true,"img":false}]}
{"op":"mcm","clk":"11541346092","pt":1719504785629,"mc":[{"id":"1.230180130","rc":[{"atb":[[7.8,5.7]],"id":41138102},{"atb":[[3.6,0]],"id":43210435}],"con":true,"img":false}]}
{"op":"mcm","clk":"11541346100","pt":1719504785734,"mc":[{"id":"1.230180130","rc":[{"atb":[[8,1]],"id":41138102}],"con":true,"img":false}]}
{"op":"mcm","clk":"11541346116","pt":1719504785894,"mc":[{"id":"1.230180130","rc":[{"atb":[[5.2,0.37],[5.6,5.43]],"id":58149406},{"atb":[[7.4,3.45]],"id":41138102},{"atb":[[2.16,14.85]],"id":51843546}],"con":true,"img":false}]}
{"op":"mcm","clk":"11541346141","pt":1719504786103,"mc":[{"id":"1.230180130","rc":[{"atb":[[3.85,0],[2.74,13.08],[5.7,8.4],[5.8,4.37]],"id":58149406},{"atl":[[11,1],[15,3.28],[9.4,0]],"id":58149406},{"atb":[[3.8,12.56],[5.4,0]],"id":41138102},{"atb":[[4.9,0]],"id":43210435},{"atb":[[3.6,6],[4.1,0]],"id":66499052},{"atl":[[10.5,4],[13,0]],"id":66499052},{"atb":[[2,0],[1.78,70.24]],"id":69979297},{"atl":[[3.55,0],[3.3,30.08]],"id":69979297}],"con":true,"img":false}]}
{"op":"mcm","clk":"11541346151","pt":1719504786215,"mc":[{"id":"1.230180130","rc":[{"atb":[[4,15.71]],"id":43210435},{"atl":[[2.64,8.58]],"id":69979297}],"con":true,"img":false}]}
{"op":"mcm","clk":"11541346161","pt":1719504786313,"mc":[{"id":"1.230180130","rc":[{"atl":[[13,3.28],[15,0]],"id":58149406}],"con":true,"img":false}]}
{"op":"mcm","clk":"11541346183","pt":1719504786523,"mc":[{"id":"1.230180130","rc":[{"atb":[[5.7,6.7]],"id":58149406}],"con":true,"img":false}]}
{"op":"mcm","clk":"11541346192","pt":1719504786628,"mc":[{"id":"1.230180130","rc":[{"atb":[[5.9,1.7]],"id":58149406}],"con":true,"img":false}]}
{"op":"mcm","clk":"11541346200","pt":1719504786744,"mc":[{"id":"1.230180130","rc":[{"atb":[[5.4,1.82]],"id":58149406}],"con":true,"img":false}]}
{"op":"mcm","clk":"11541346220","pt":1719504786948,"mc":[{"id":"1.230180130","rc":[{"atb":[[5.8,9.23]],"id":58149406}],"con":true,"img":false}]}
{"op":"mcm","clk":"11541346257","pt":1719504787308,"mc":[{"id":"1.230180130","rc":[{"atb":[[5.8,4.86]],"id":58149406}],"con":true,"img":false}]}
{"op":"mcm","clk":"11541346266","pt":1719504787417,"mc":[{"id":"1.230180130","rc":[{"atb":[[5.5,0],[6,4.23],[5.7,5.86],[5.8,6.53]],"id":58149406},{"atb":[[7.8,0]],"id":43210435}],"con":true,"img":false}]}
{"op":"mcm","clk":"11541346277","pt":1719504787519,"mc":[{"id":"1.230180130","rc":[{"atb":[[5.9,6.77]],"id":58149406}],"con":true,"img":false}]}
{"op":"mcm","clk":"11541346293","pt":1719504787724,"mc":[{"id":"1.230180130","rc":[{"atb":[[5.9,5.07]],"id":58149406}],"con":true,"img":false}]}
{"op":"mcm","clk":"11541346303","pt":1719504787844,"mc":[{"id":"1.230180130","rc":[{"atb":[[6.2,1.7]],"id":58149406}],"con":true,"img":false}]}
{"op":"mcm","clk":"11541346326","pt":1719504788036,"mc":[{"id":"1.230180130","rc":[{"atb":[[6,0]],"id":58149406}],"con":true,"img":false}]}
{"op":"mcm","clk":"11541346342","pt":1719504788194,"mc":[{"id":"1.230180130","rc":[{"atb":[[7.8,3.25]],"id":43210435}],"con":true,"img":false}]}
{"op":"mcm","clk":"11541346352","pt":1719504788307,"mc":[{"id":"1.230180130","rc":[{"atb":[[6.2,0]],"id":58149406}],"con":true,"img":false}]}
{"op":"mcm","clk":"11541346362","pt":1719504788403,"mc":[{"id":"1.230180130","rc":[{"atb":[[6,1.7],[5.6,0]],"id":58149406},{"atb":[[6.6,0]],"id":43210435}],"con":true,"img":false}]}
{"op":"mcm","clk":"11541346380","pt":1719504788609,"mc":[{"id":"1.230180130","rc":[{"atb":[[6.2,4.85]],"id":58149406},{"atb":[[7.8,7.31]],"id":43210435}],"con":true,"img":false}]}
{"op":"mcm","clk":"11541346396","pt":1719504788819,"mc":[{"id":"1.230180130","rc":[{"atb":[[6.4,3.96]],"id":58149406}],"con":true,"img":false}]}
{"op":"mcm","clk":"11541346403","pt":1719504788928,"mc":[{"id":"1.230180130","rc":[{"atb":[[6,0]],"id":58149406},{"atb":[[8,0.84],[7.4,4.24],[7.6,3.86]],"id":43210435}],"con":true,"img":false}]}
{"op":"mcm","clk":"11541346413","pt":1719504789029,"mc":[{"id":"1.230180130","rc":[{"atb":[[6.4,5.67]],"id":58149406},{"atl":[[19.5,0],[20,1]],"id":41138102},{"atb":[[8,2.62]],"id":43210435},{"atb":[[6.2,2.28],[6,0.26]],"id":51843546}],"con":true,"img":false}]}
{"op":"mcm","clk":"11541346420","pt":1719504789138,"mc":[{"id":"1.230180130","rc":[{"atl":[[24,2],[100,0]],"id":41138102}],"con":true,"img":false}]}
{"op":"mcm","clk":"11541346430","pt":1719504789238,"mc":[{"id":"1.230180130","rc":[{"atb":[[2.26,0]],"id":41138102}],"con":true,"img":false}]}
{"op":"mcm","clk":"11541346439","pt":1719504789290,"mc":[{"id":"1.230180130","rc":[{"atb":[[2.3,12.55]],"id":41138102}],"con":true,"img":false}]}
{"op":"mcm","clk":"11541346453","pt":1719504789499,"mc":[{"id":"1.230180130","rc":[{"atb":[[7.8,4.06]],"id":43210435}],"con":true,"img":false}]}
{"op":"mcm","clk":"11541346473","pt":1719504789707,"mc":[{"id":"1.230180130","rc":[{"atb":[[8.2,3.09]],"id":43210435}],"con":true,"img":false}]}
{"op":"mcm","clk":"11541346499","pt":1719504790021,"mc":[{"id":"1.230180130","rc":[{"atb":[[6.8,0]],"id":51843546}],"con":true,"img":false}]}
{"op":"mcm","clk":"11541346508","pt":1719504790126,"mc":[{"id":"1.230180130","rc":[{"atb":[[8,0.84]],"id":43210435}],"con":true,"img":false}]}
{"op":"mcm","clk":"11541346516","pt":1719504790233,"mc":[{"id":"1.230180130","rc":[{"atb":[[8.2,4.87]],"id":43210435}],"con":true,"img":false}]}
{"op":"mcm","clk":"11541346527","pt":1719504790344,"mc":[{"id":"1.230180130","rc":[{"atb":[[1.12,1]],"id":51843546}],"con":true,"img":false}]}
{"op":"mcm","clk":"11541346546","pt":1719504790499,"mc":[{"id":"1.230180130","rc":[{"atb":[[1.12,0.17]],"id":51843546}],"con":true,"img":false}]}
{"op":"mcm","clk":"11541346571","pt":1719504790821,"mc":[{"id":"1.230180130","rc":[{"atl":[[95,0.26]],"id":41138102},{"atb":[[1.12,0]],"id":51843546}],"con":true,"img":false}]}
{"op":"mcm","clk":"11541346579","pt":1719504790921,"mc":[{"id":"1.230180130","rc":[{"atl":[[23,1]],"id":41138102},{"atb":[[6.8,0.17]],"id":51843546}],"con":true,"img":false}]}
{"op":"mcm","clk":"11541346585","pt":1719504791025,"mc":[{"id":"1.230180130","rc":[{"atb":[[6.4,7.15]],"id":58149406}],"con":true,"img":false}]}
{"op":"mcm","clk":"11541346595","pt":1719504791246,"mc":[{"id":"1.230180130","rc":[{"atb":[[2.74,0],[2.56,13.08]],"id":58149406},{"atl":[[11,0]],"id":58149406}],"con":true,"img":false}]}
{"op":"mcm","clk":"11541346671","pt":1719504792030,"mc":[{"id":"1.230180130","rc":[{"atb":[[5,7.38]],"id":41138102},{"atl":[[3.3,0],[2.92,30.08]],"id":69979297}],"con":true,"img":false}]}
{"op":"mcm","clk":"11541346680","pt":1719504792137,"mc":[{"id":"1.230180130","rc":[{"atb":[[3.8,0]],"id":41138102}],"con":true,"img":false}]}
{"op":"mcm","clk":"11541346705","pt":1719504792406,"mc":[{"id":"1.230180130","rc":[{"atb":[[6.6,0.84]],"id":58149406}],"con":true,"img":false}]}
{"op":"mcm","clk":"11541346717","pt":1719504792506,"mc":[{"id":"1.230180130","rc":[{"atb":[[5.7,0]],"id":58149406}],"con":true,"img":false}]}
{"op":"mcm","clk":"11541346736","pt":1719504792715,"mc":[{"id":"1.230180130","rc":[{"atb":[[6.6,4.94]],"id":58149406}],"con":true,"img":false}]}
{"op":"mcm","clk":"11541346741","pt":1719504792822,"mc":[{"id":"1.230180130","rc":[{"atb":[[6.4,3.18]],"id":58149406}],"con":true,"img":false}]}
{"op":"mcm","clk":"11541346766","pt":1719504793134,"mc":[{"id":"1.230180130","rc":[{"atb":[[6.4,1.48]],"id":58149406}],"con":true,"img":false}]}
{"op":"mcm","clk":"11541346827","pt":1719504794021,"mc":[{"id":"1.230180130","rc":[{"atb":[[2.2,40]],"id":69979297}],"con":true,"img":false}]}
{"op":"mcm","clk":"11541346849","pt":1719504794433,"mc":[{"id":"1.230180130","rc":[{"atb":[[2.22,0.84]],"id":69979297}],"con":true,"img":false}]}
{"op":"mcm","clk":"11541346871","pt":1719504794746,"mc":[{"id":"1.230180130","rc":[{"atb":[[5,0]],"id":58149406}],"con":true,"img":false}]}
{"op":"mcm","clk":"11541346909","pt":1719504795213,"mc":[{"id":"1.230180130","rc":[{"atb":[[7.2,0]],"id":43210435}],"con":true,"img":false}]}
{"op":"mcm","clk":"11541346973","pt":1719504795940,"mc":[{"id":"1.230180130","rc":[{"atb":[[8.4,0.84]],"id":43210435}],"con":true,"img":false}]}
{"op":"mcm","clk":"11541346997","pt":1719504796254,"mc":[{"id":"1.230180130","rc":[{"atl":[[23,3],[24,0]],"id":41138102}],"con":true,"img":false}]}
{"op":"mcm","clk":"11541347014","pt":1719504796414,"mc":[{"id":"1.230180130","rc":[{"atb":[[8.2,1.77]],"id":43210435}],"con":true,"img":false}]}
{"op":"mcm","clk":"11541347035","pt":1719504796632,"mc":[{"id":"1.230180130","rc":[{"atl":[[8.8,0.84]],"id":58149406},{"atl":[[23,2]],"id":41138102},{"atb":[[8.2,0]],"id":43210435}],"con":true,"img":false}]}
{"op":"mcm","clk":"11541347047","pt":1719504796727,"mc":[{"id":"1.230180130","rc":[{"atl":[[140,1]],"id":41138102},{"atb":[[8,2.62]],"id":43210435}],"con":true,"img":false}]}
{"op":"mcm","clk":"11541347096","pt":1719504797349,"mc":[{"id":"1.230180130","rc":[{"atb":[[5.2,0]],"id":58149406}],"con":true,"img":false}]}
{"op":"mcm","clk":"11541347107","pt":1719504797452,"mc":[{"id":"1.230180130","rc":[{"atb":[[8.4,0]],"id":43210435}],"con":true,"img":false}]}
{"op":"mcm","clk":"11541347150","pt":1719504798018,"mc":[{"id":"1.230180130","rc":[{"atb":[[8.2,3.09]],"id":43210435}],"con":true,"img":false}]}
{"op":"mcm","clk":"11541347411","pt":1719504801138,"mc":[{"id":"1.230180130","rc":[{"atb":[[7,1.21]],"id":51843546}],"con":true,"img":false}]}
{"op":"mcm","clk":"11541347421","pt":1719504801243,"mc":[{"id":"1.230180130","rc":[{"spn":7.6,"spf":"NaN","id":58149406},{"spn":14.0,"spf":"NaN","id":41138102},{"spn":12.6,"spf":"NaN","id":43210435},{"spn":4.93,"spf":1.0,"id":66499052},{"atb":[[6.4,0.84],[6.2,1],[6.6,3.29]],"id":51843546},{"spn":63.5,"spf":"NaN","id":51843546},{"spn":2.21,"spf":1.0,"id":69979297}],"con":true,"img":false}]}
{"op":"mcm","clk":"11541347447","pt":1719504801554,"mc":[{"id":"1.230180130","rc":[{"atb":[[7,0]],"id":51843546}],"con":true,"img":false}]}
{"op":"mcm","clk":"11541347456","pt":1719504801657,"mc":[{"id":"1.230180130","rc":[{"atl":[[8.6,2.15]],"id":58149406},{"atl":[[140,0]],"id":41138102},{"atb":[[6.4,4.3],[6.6,1]],"id":51843546}],"con":true,"img":false}]}
{"op":"mcm","clk":"11541347463","pt":1719504801717,"mc":[{"id":"1.230180130","rc":[{"atl":[[12.5,1]],"id":58149406},{"atl":[[22,1]],"id":41138102}],"con":true,"img":false}]}
{"op":"mcm","clk":"11541347475","pt":1719504801813,"mc":[{"id":"1.230180130","rc":[{"atb":[[6.8,1.38]],"id":51843546}],"con":true,"img":false}]}
{"op":"mcm","clk":"11541347478","pt":1719504801917,"mc":[{"id":"1.230180130","rc":[{"atb":[[6.8,2.22]],"id":51843546}],"con":true,"img":false}]}
{"op":"mcm","clk":"11541347485","pt":1719504802020,"mc":[{"id":"1.230180130","rc":[{"atl":[[12.5,0]],"id":58149406},{"atb":[[6.4,0.84],[6.6,3.76]],"id":51843546}],"con":true,"img":false}]}
{"op":"mcm","clk":"11541347494","pt":1719504802128,"mc":[{"id":"1.230180130","rc":[{"atl":[[8.4,1]],"id":58149406}],"con":true,"img":false}]}
{"op":"mcm","clk":"11541347527","pt":1719504802542,"mc":[{"id":"1.230180130","rc":[{"atb":[[6.4,0]],"id":51843546}],"con":true,"img":false}]}
{"op":"mcm","clk":"11541347605","pt":1719504803428,"mc":[{"id":"1.230180130","rc":[{"atb":[[8.4,0.84]],"id":43210435}],"con":true,"img":false}]}
{"op":"mcm","clk":"11541347632","pt":1719504803743,"mc":[{"id":"1.230180130","rc":[{"atb":[[8.2,0]],"id":43210435}],"con":true,"img":false}]}
{"op":"mcm","clk":"11541347692","pt":1719504804525,"mc":[{"id":"1.230180130","rc":[{"atb":[[8.4,0]],"id":43210435}],"con":true,"img":false}]}
{"op":"mcm","clk":"11541347722","pt":1719504804837,"mc":[{"id":"1.230180130","rc":[{"atb":[[8.2,3.09]],"id":43210435}],"con":true,"img":false}]}
{"op":"mcm","clk":"11541347737","pt":1719504805042,"mc":[{"id":"1.230180130","rc":[{"atb":[[2.22,0]],"id":58149406},{"atb":[[1.93,0]],"id":69979297}],"con":true,"img":false}]}
{"op":"mcm","clk":"11541347812","pt":1719504805929,"mc":[{"id":"1.230180130","rc":[{"atb":[[2.2,0]],"id":69979297}],"con":true,"img":false}]}
{"op":"mcm","clk":"11541347818","pt":1719504806034,"mc":[{"id":"1.230180130","rc":[{"atb":[[6.8,2.05]],"id":51843546}],"con":true,"img":false}]}
{"op":"mcm","clk":"11541347861","pt":1719504806565,"mc":[{"id":"1.230180130","rc":[{"atb":[[1.12,1]],"id":51843546},{"atb":[[2.22,0]],"id":69979297}],"con":true,"img":false}]}
{"op":"mcm","clk":"11541347881","pt":1719504806761,"mc":[{"id":"1.230180130","rc":[{"atb":[[1.12,0.17]],"id":51843546}],"con":true,"img":false}]}
{"op":"mcm","clk":"11541347891","pt":1719504806864,"mc":[{"id":"1.230180130","rc":[{"atl":[[23,0],[24,2]],"id":41138102}],"con":true,"img":false}]}
{"op":"mcm","clk":"11541347898","pt":1719504806916,"mc":[{"id":"1.230180130","rc":[{"atb":[[1.12,0]],"id":51843546}],"con":true,"img":false}]}
{"op":"mcm","clk":"11541347906","pt":1719504807019,"mc":[{"id":"1.230180130","rc":[{"atb":[[7,0.17]],"id":51843546},{"atl":[[2.56,3.72]],"id":69979297}],"con":true,"img":false}]}
{"op":"mcm","clk":"11541347992","pt":1719504808165,"mc":[{"id":"1.230180130","rc":[{"atl":[[22,0]],"id":41138102}],"con":true,"img":false}]}
{"op":"mcm","clk":"11541348000","pt":1719504808220,"mc":[{"id":"1.230180130","rc":[{"atl":[[23,1]],"id":41138102},{"atl":[[2.56,0]],"id":69979297}],"con":true,"img":false}]}
{"op":"mcm","clk":"11541348156","pt":1719504810245,"mc":[{"id":"1.230180130","rc":[{"atb":[[2.72,6.89]],"id":66499052}],"con":true,"img":false}]}
{"op":"mcm","clk":"11541348214","pt":1719504810969,"mc":[{"id":"1.230180130","rc":[{"atb":[[8.4,0.84]],"id":43210435}],"con":true,"img":false}]}
{"op":"mcm","clk":"11541348229","pt":1719504811127,"mc":[{"id":"1.230180130","rc":[{"atb":[[8,0.84]],"id":43210435}],"con":true,"img":false}]}
{"op":"mcm","clk":"11541348237","pt":1719504811233,"mc":[{"id":"1.230180130","rc":[{"atb":[[8.4,2.62]],"id":43210435}],"con":true,"img":false}]}
{"op":"mcm","clk":"11541348265","pt":1719504811544,"mc":[{"id":"1.230180130","rc":[{"atb":[[8.2,0]],"id":43210435}],"con":true,"img":false}]}
{"op":"mcm","clk":"11541348288","pt":1719504811746,"mc":[{"id":"1.230180130","rc":[{"atl":[[20,0],[21,1.26]],"id":41138102},{"atb":[[8.4,0.84]],"id":43210435},{"atl":[[17,0],[18,1]],"id":43210435}],"con":true,"img":false}]}
{"op":"mcm","clk":"11541348295","pt":1719504811851,"mc":[{"id":"1.230180130","rc":[{"atb":[[2.68,13.08],[2.56,0]],"id":58149406},{"atb":[[8,2.62]],"id":43210435},{"atl":[[75,0],[23,2.26]],"id":43210435}],"con":true,"img":false}]}
{"op":"mcm","clk":"11541348303","pt":1719504811952,"mc":[{"id":"1.230180130","rc":[{"atb":[[8,1.77]],"id":43210435},{"atl":[[65,2]],"id":43210435}],"con":true,"img":false}]}
{"op":"mcm","clk":"11541348309","pt":1719504812056,"mc":[{"id":"1.230180130","rc":[{"atl":[[23,0.26]],"id":43210435}],"con":true,"img":false}]}
{"op":"mcm","clk":"11541348315","pt":1719504812161,"mc":[{"id":"1.230180130","rc":[{"atl":[[60,0.47]],"id":43210435}],"con":true,"img":false}]}
{"op":"mcm","clk":"11541348338","pt":1719504812427,"mc":[{"id":"1.230180130","rc":[{"atb":[[8.4,0]],"id":43210435}],"con":true,"img":false}]}
{"op":"mcm","clk":"11541348356","pt":1719504812640,"mc":[{"id":"1.230180130","rc":[{"atb":[[4.8,15.71],[8.2,3.09],[4,0]],"id":43210435},{"atl":[[70,0.4]],"id":43210435}],"con":true,"img":false}]}
{"op":"mcm","clk":"11541348365","pt":1719504812732,"mc":[{"id":"1.230180130","rc":[{"atl":[[60,1.47]],"id":43210435}],"con":true,"img":false}]}
{"op":"mcm","clk":"11541348377","pt":1719504812940,"mc":[{"id":"1.230180130","rc":[{"atb":[[8,0]],"id":43210435}],"con":true,"img":false}]}
{"op":"mcm","clk":"11541348385","pt":1719504813049,"mc":[{"id":"1.230180130","rc":[{"atb":[[8.2,4.87]],"id":43210435}],"con":true,"img":false}]}
{"op":"mcm","clk":"11541348799","pt":1719504818335,"mc":[{"id":"1.230180130","rc":[{"atb":[[8.4,0.84]],"id":43210435}],"con":true,"img":false}]}
{"op":"mcm","clk":"11541348847","pt":1719504818853,"mc":[{"id":"1.230180130","rc":[{"atb":[[8.2,1.77]],"id":43210435}],"con":true,"img":false}]}
{"op":"mcm","clk":"11541348914","pt":1719504819576,"mc":[{"id":"1.230180130","rc":[{"atb":[[8.2,0]],"id":43210435}],"con":true,"img":false}]}
{"op":"mcm","clk":"11541348921","pt":1719504819679,"mc":[{"id":"1.230180130","rc":[{"atb":[[8,1.77]],"id":43210435}],"con":true,"img":false}]}
{"op":"mcm","clk":"11541348935","pt":1719504819834,"mc":[{"id":"1.230180130","rc":[{"atb":[[8.4,0]],"id":43210435}],"con":true,"img":false}]}
{"op":"mcm","clk":"11541348973","pt":1719504820354,"mc":[{"id":"1.230180130","rc":[{"atb":[[8.2,3.09]],"id":43210435}],"con":true,"img":false}]}
{"op":"mcm","clk":"11541348994","pt":1719504820663,"mc":[{"id":"1.230180130","rc":[{"atb":[[3.7,2.96]],"id":58149406}],"con":true,"img":false}]}
{"op":"mcm","clk":"11541349127","pt":1719504822271,"mc":[{"id":"1.230180130","rc":[{"atb":[[7,0]],"id":51843546}],"con":true,"img":false}]}
{"op":"mcm","clk":"11541349141","pt":1719504822478,"mc":[{"id":"1.230180130","rc":[{"atb":[[1.12,1]],"id":51843546}],"con":true,"img":false}]}
{"op":"mcm","clk":"11541349172","pt":1719504822782,"mc":[{"id":"1.230180130","rc":[{"atb":[[1.12,0.17]],"id":51843546}],"con":true,"img":false}]}
{"op":"mcm","clk":"11541349189","pt":1719504822940,"mc":[{"id":"1.230180130","rc":[{"atb":[[1.12,0]],"id":51843546}],"con":true,"img":false}]}
{"op":"mcm","clk":"11541349197","pt":1719504823053,"mc":[{"id":"1.230180130","rc":[{"atb":[[7,0.17]],"id":51843546}],"con":true,"img":false}]}
{"op":"mcm","clk":"11541349207","pt":1719504823154,"mc":[{"id":"1.230180130","rc":[{"atb":[[5.2,1.44]],"id":51843546}],"con":true,"img":false}]}
{"op":"mcm","clk":"11541349425","pt":1719504825688,"mc":[{"id":"1.230180130","rc":[{"atb":[[2.16,10.25]],"id":43210435}],"con":true,"img":false}]}
{"op":"mcm","clk":"11541349441","pt":1719504825845,"mc":[{"id":"1.230180130","rc":[{"atb":[[8.4,0.84]],"id":43210435}],"con":true,"img":false}]}
{"op":"mcm","clk":"11541349464","pt":1719504826167,"mc":[{"id":"1.230180130","rc":[{"atb":[[8,0]],"id":43210435}],"con":true,"img":false}]}
{"op":"mcm","clk":"11541349473","pt":1719504826261,"mc":[{"id":"1.230180130","rc":[{"atb":[[8.4,2.62]],"id":43210435}],"con":true,"img":false}]}
{"op":"mcm","clk":"11541349489","pt":1719504826474,"mc":[{"id":"1.230180130","rc":[{"atb":[[8.2,0]],"id":43210435}],"con":true,"img":false}]}
{"op":"mcm","clk":"11541349520","pt":1719504826879,"mc":[{"id":"1.230180130","rc":[{"atb":[[8.4,0.84]],"id":43210435}],"con":true,"img":false}]}
{"op":"mcm","clk":"11541349531","pt":1719504826982,"mc":[{"id":"1.230180130","rc":[{"atb":[[8,1.77]],"id":43210435}],"con":true,"img":false}]}
{"op":"mcm","clk":"11541349577","pt":1719504827448,"mc":[{"id":"1.230180130","rc":[{"atb":[[8.4,0]],"id":43210435}],"con":true,"img":false}]}
{"op":"mcm","clk":"11541349618","pt":1719504827967,"mc":[{"id":"1.230180130","rc":[{"atb":[[8.2,3.09]],"id":43210435}],"con":true,"img":false}]}
{"op":"mcm","clk":"11541349664","pt":1719504828595,"mc":[{"id":"1.230180130","rc":[{"atb":[[8,0]],"id":43210435}],"con":true,"img":false}]}
{"op":"mcm","clk":"11541349674","pt":1719504828642,"mc":[{"id":"1.230180130","rc":[{"atb":[[8.2,4.87]],"id":43210435}],"con":true,"img":false}]}
{"op":"mcm","clk":"11541349696","pt":1719504828852,"mc":[{"id":"1.230180130","rc":[{"atb":[[2.04,0]],"id":69979297}],"con":true,"img":false}]}
{"op":"mcm","clk":"11541349779","pt":1719504829891,"mc":[{"id":"1.230180130","rc":[{"atb":[[1.79,15]],"id":69979297}],"con":true,"img":false}]}
{"op":"mcm","clk":"11541349790","pt":1719504830000,"mc":[{"id":"1.230180130","rc":[{"atb":[[1.77,5.72]],"id":69979297}],"con":true,"img":false}]}
{"op":"mcm","clk":"11541349826","pt":1719504830359,"mc":[{"id":"1.230180130","rc":[{"atb":[[1.77,0]],"id":69979297}],"con":true,"img":false}]}
{"op":"mcm","clk":"11541349855","pt":1719504830872,"mc":[{"id":"1.230180130","rc":[{"atb":[[8.4,1]],"id":43210435}],"con":true,"img":false}]}
{"op":"mcm","clk":"11541349863","pt":1719504830976,"mc":[{"id":"1.230180130","rc":[{"atb":[[6.2,0]],"id":43210435}],"con":true,"img":false}]}
{"op":"mcm","clk":"11541349871","pt":1719504831090,"mc":[{"id":"1.230180130","rc":[{"atb":[[8.2,1.03]],"id":41138102}],"con":true,"img":false}]}
{"op":"mcm","clk":"11541349889","pt":1719504831287,"mc":[{"id":"1.230180130","rc":[{"atb":[[6.4,0]],"id":41138102}],"con":true,"img":false}]}
{"op":"mcm","clk":"11541349897","pt":1719504831391,"mc":[{"id":"1.230180130","rc":[{"atb":[[6.8,0.84]],"id":51843546}],"con":true,"img":false}]}
{"op":"mcm","clk":"11541349908","pt":1719504831498,"mc":[{"id":"1.230180130","rc":[{"atb":[[8.2,1.77]],"id":43210435}],"con":true,"img":false}]}
{"op":"mcm","clk":"11541349920","pt":1719504831551,"mc":[{"id":"1.230180130","rc":[{"atb":[[7.2,1.17]],"id":51843546}],"con":true,"img":false}]}
{"op":"mcm","clk":"11541349934","pt":1719504831770,"mc":[{"id":"1.230180130","rc":[{"atb":[[6.6,2.76]],"id":51843546}],"con":true,"img":false}]}
{"op":"mcm","clk":"11541349951","pt":1719504831984,"mc":[{"id":"1.230180130","rc":[{"atb":[[6.8,1.84]],"id":51843546}],"con":true,"img":false}]}
{"op":"mcm","clk":"11541349957","pt":1719504832075,"mc":[{"id":"1.230180130","rc":[{"atb":[[7.2,0],[7,1.34]],"id":51843546}],"con":true,"img":false}]}
{"op":"mcm","clk":"11541349964","pt":1719504832175,"mc":[{"id":"1.230180130","rc":[{"atb":[[8.2,0]],"id":43210435}],"con":true,"img":false}]}
{"op":"mcm","clk":"11541349974","pt":1719504832279,"mc":[{"id":"1.230180130","rc":[{"atb":[[8,1.77]],"id":43210435}],"con":true,"img":false}]}
{"op":"mcm","clk":"11541349991","pt":1719504832485,"mc":[{"id":"1.230180130","rc":[{"atb":[[8,2.78],[8.4,0]],"id":43210435}],"con":true,"img":false}]}
{"op":"mcm","clk":"11541350026","pt":1719504832849,"mc":[{"id":"1.230180130","rc":[{"atb":[[8.2,0.84]],"id":43210435}],"con":true,"img":false}]}
{"op":"mcm","clk":"11541350378","pt":1719504838190,"mc":[{"id":"1.230180130","rc":[{"atb":[[7,1.17]],"id":51843546}],"con":true,"img":false}]}
{"op":"mcm","clk":"11541350391","pt":1719504838404,"mc":[{"id":"1.230180130","rc":[{"atb":[[1.13,1]],"id":51843546}],"con":true,"img":false}]}
{"op":"mcm","clk":"11541350405","pt":1719504838603,"mc":[{"id":"1.230180130","rc":[{"atb":[[1.13,0.16]],"id":51843546}],"con":true,"img":false}]}
{"op":"mcm","clk":"11541350418","pt":1719504838810,"mc":[{"id":"1.230180130","rc":[{"atb":[[1.13,0]],"id":51843546}],"con":true,"img":false}]}
{"op":"mcm","clk":"11541350429","pt":1719504838862,"mc":[{"id":"1.230180130","rc":[{"atb":[[7.2,0.16]],"id":51843546}],"con":true,"img":false}]}
{"op":"mcm","clk":"11541350436","pt":1719504838967,"mc":[{"id":"1.230180130","rc":[{"atb":[[5.2,0]],"id":51843546}],"con":true,"img":false}]}
{"op":"mcm","clk":"11541350464","pt":1719504839277,"mc":[{"id":"1.230180130","rc":[{"atb":[[5.3,2.08]],"id":51843546}],"con":true,"img":false}]}
{"op":"mcm","clk":"11541350518","pt":1719504839897,"mc":[{"id":"1.230180130","rc":[{"atb":[[5.3,0]],"id":51843546}],"con":true,"img":false}]}
{"op":"mcm","clk":"11541350584","pt":1719504840679,"mc":[{"id":"1.230180130","rc":[{"atb":[[5.4,1.42]],"id":51843546}],"con":true,"img":false}]}
{"op":"mcm","clk":"11541351200","pt":1719504847298,"mc":[{"id":"1.230180130","rc":[{"atb":[[5.2,0]],"id":66499052},{"atl":[[5.2,0.6]],"id":66499052},{"trd":[[5.2,3.19]],"ltp":5.2,"tv":3.19,"id":66499052}],"con":true,"img":false}]}
{"op":"mcm","clk":"11541351245","pt":1719504847814,"mc":[{"id":"1.230180130","rc":[{"atb":[[6.8,3.84],[6.6,0]],"id":51843546}],"con":true,"img":false}]}
{"op":"mcm","clk":"11541351254","pt":1719504847915,"mc":[{"id":"1.230180130","rc":[{"atb":[[3.7,2.03]],"id":66499052},{"atb":[[5.4,0]],"id":51843546}],"con":true,"img":false}]}
{"op":"mcm","clk":"11541351262","pt":1719504848027,"mc":[{"id":"1.230180130","rc":[{"atb":[[8,1.84]],"id":41138102},{"atb":[[8.2,1.69]],"id":43210435}],"con":true,"img":false}]}
{"op":"mcm","clk":"11541351276","pt":1719504848127,"mc":[{"id":"1.230180130","rc":[{"atb":[[7,0.26]],"id":41138102},{"atb":[[5.5,2.12]],"id":51843546}],"con":true,"img":false}]}
{"op":"mcm","clk":"11541351297","pt":1719504848280,"mc":[{"id":"1.230180130","rc":[{"atb":[[8,1.77],[8.4,1]],"id":43210435}],"con":true,"img":false}]}
{"op":"mcm","clk":"11541351309","pt":1719504848386,"mc":[{"id":"1.230180130","rc":[{"atb":[[8.2,4.21]],"id":41138102},{"atb":[[8.4,4.02]],"id":43210435},{"atl":[[5.3,5.21]],"id":66499052},{"atb":[[2.98,5.99]],"id":51843546}],"con":true,"img":false}]}
{"op":"mcm","clk":"11541351319","pt":1719504848495,"mc":[{"id":"1.230180130","rc":[{"atb":[[2.72,0],[5.1,1.51]],"id":66499052}],"con":true,"img":false}]}
{"op":"mcm","clk":"11541351357","pt":1719504848905,"mc":[{"id":"1.230180130","rc":[{"atb":[[7.8,3.9],[8.4,0.84]],"id":41138102},{"atb":[[8.6,0.84]],"id":43210435}],"con":true,"img":false}]}
{"op":"mcm","clk":"11541351366","pt":1719504849006,"mc":[{"id":"1.230180130","rc":[{"atb":[[8.4,5.67]],"id":41138102}],"con":true,"img":false}]}
{"op":"mcm","clk":"11541351377","pt":1719504849110,"mc":[{"id":"1.230180130","rc":[{"atb":[[8,0.84]],"id":41138102},{"atb":[[4.8,4.42]],"id":66499052},{"atb":[[7.4,1.14],[7,0]],"id":51843546}],"con":true,"img":false}]}
{"op":"mcm","clk":"11541351400","pt":1719504849321,"mc":[{"id":"1.230180130","rc":[{"atb":[[4.8,0]],"id":66499052},{"atb":[[6.8,2.84]],"id":51843546}],"con":true,"img":false}]}
{"op":"mcm","clk":"11541351411","pt":1719504849422,"mc":[{"id":"1.230180130","rc":[{"atb":[[8,0.27],[8.6,1]],"id":41138102},{"atb":[[8.2,1.12]],"id":43210435}],"con":true,"img":false}]}
{"op":"mcm","clk":"11541351422","pt":1719504849528,"mc":[{"id":"1.230180130","rc":[{"atb":[[8,0]],"id":43210435},{"atb":[[7,2.14]],"id":51843546}],"con":true,"img":false}]}
{"op":"mcm","clk":"11541351431","pt":1719504849586,"mc":[{"id":"1.230180130","rc":[{"atb":[[8.4,2.64]],"id":41138102},{"atb":[[8.4,1],[8.6,2.62]],"id":43210435},{"atb":[[4.6,0.26]],"id":66499052},{"atb":[[7.4,0]],"id":51843546}],"con":true,"img":false}]}
{"op":"mcm","clk":"11541351451","pt":1719504849785,"mc":[{"id":"1.230180130","rc":[{"atb":[[7.2,0]],"id":41138102}],"con":true,"img":false}]}
{"op":"mcm","clk":"11541351460","pt":1719504849891,"mc":[{"id":"1.230180130","rc":[{"atb":[[8.4,0]],"id":43210435},{"atb":[[5.5,0]],"id":51843546}],"con":true,"img":false}]}
{"op":"mcm","clk":"11541351470","pt":1719504850003,"mc":[{"id":"1.230180130","rc":[{"atb":[[8.6,4.45]],"id":41138102}],"con":true,"img":false}]}
{"op":"mcm","clk":"11541351480","pt":1719504850096,"mc":[{"id":"1.230180130","rc":[{"atb":[[5.5,1.43]],"id":51843546}],"con":true,"img":false}]}
{"op":"mcm","clk":"11541351486","pt":1719504850200,"mc":[{"id":"1.230180130","rc":[{"atb":[[8.8,2.88]],"id":41138102},{"atb":[[8.6,0.84],[8.8,0.96]],"id":43210435},{"atb":[[3.65,0]],"id":66499052}],"con":true,"img":false}]}
{"op":"mcm","clk":"11541351495","pt":1719504850310,"mc":[{"id":"1.230180130","rc":[{"atb":[[8,1.77]],"id":43210435}],"con":true,"img":false}]}
{"op":"mcm","clk":"11541351505","pt":1719504850407,"mc":[{"id":"1.230180130","rc":[{"atb":[[8.2,0.27]],"id":43210435},{"atb":[[7.2,1]],"id":51843546}],"con":true,"img":false}]}
{"op":"mcm","clk":"11541351539","pt":1719504850724,"mc":[{"id":"1.230180130","rc":[{"atb":[[7.4,0]],"id":41138102}],"con":true,"img":false}]}
{"op":"mcm","clk":"11541351550","pt":1719504850823,"mc":[{"id":"1.230180130","rc":[{"atb":[[8.4,0.84]],"id":41138102}],"con":true,"img":false}]}
{"op":"mcm","clk":"11541351558","pt":1719504850928,"mc":[{"id":"1.230180130","rc":[{"atb":[[8,0],[8.4,0],[8.8,4.68]],"id":41138102}],"con":true,"img":false}]}
{"op":"mcm","clk":"11541351571","pt":1719504851033,"mc":[{"id":"1.230180130","rc":[{"atb":[[9,0.27],[8.6,3.45]],"id":41138102}],"con":true,"img":false}]}
{"op":"mcm","clk":"11541351579","pt":1719504851091,"mc":[{"id":"1.230180130","rc":[{"atb":[[8.8,8.22]],"id":41138102}],"con":true,"img":false}]}
{"op":"mcm","clk":"11541351590","pt":1719504851196,"mc":[{"id":"1.230180130","rc":[{"atb":[[9,1.27]],"id":41138102}],"con":true,"img":false}]}
{"op":"mcm","clk":"11541351611","pt":1719504851399,"mc":[{"id":"1.230180130","rc":[{"atb":[[7.8,0]],"id":41138102}],"con":true,"img":false}]}
{"op":"mcm","clk":"11541351620","pt":1719504851508,"mc":[{"id":"1.230180130","rc":[{"atb":[[9,4.23]],"id":41138102}],"con":true,"img":false}]}
{"op":"mcm","clk":"11541351646","pt":1719504851813,"mc":[{"id":"1.230180130","rc":[{"atb":[[8.8,5.34]],"id":41138102}],"con":true,"img":false}]}
{"op":"mcm","clk":"11541351652","pt":1719504851919,"mc":[{"id":"1.230180130","rc":[{"atb":[[8.8,3.54]],"id":41138102}],"con":true,"img":false}]}
{"op":"mcm","clk":"11541351659","pt":1719504852026,"mc":[{"id":"1.230180130","rc":[{"atb":[[9.2,4.56]],"id":41138102}],"con":true,"img":false}]}
{"op":"mcm","clk":"11541351676","pt":1719504852179,"mc":[{"id":"1.230180130","rc":[{"atb":[[9,3.23]],"id":41138102}],"con":true,"img":false}]}
{"op":"mcm","clk":"11541351687","pt":1719504852292,"mc":[{"id":"1.230180130","rc":[{"atb":[[9,2.96],[9.4,1]],"id":41138102}],"con":true,"img":false}]}
{"op":"mcm","clk":"11541351699","pt":1719504852389,"mc":[{"id":"1.230180130","rc":[{"atb":[[9.4,1.27]],"id":41138102}],"con":true,"img":false}]}
{"op":"mcm","clk":"11541351707","pt":1719504852499,"mc":[{"id":"1.230180130","rc":[{"atb":[[1.78,75.96]],"id":69979297}],"con":true,"img":false}]}
{"op":"mcm","clk":"11541351717","pt":1719504852596,"mc":[{"id":"1.230180130","rc":[{"atb":[[9.2,1.8]],"id":41138102}],"con":true,"img":false}]}
{"op":"mcm","clk":"11541351738","pt":1719504852809,"mc":[{"id":"1.230180130","rc":[{"atb":[[4.3,6]],"id":41138102},{"atl":[[27,2.52]],"id":41138102},{"atb":[[6.8,0.84],[6.6,4.28]],"id":51843546}],"con":true,"img":false}]}
{"op":"mcm","clk":"11541351748","pt":1719504852907,"mc":[{"id":"1.230180130","rc":[{"atb":[[5,0]],"id":41138102},{"atl":[[24,0]],"id":41138102}],"con":true,"img":false}]}
{"op":"mcm","clk":"11541351786","pt":1719504853329,"mc":[{"id":"1.230180130","rc":[{"atb":[[8.2,1.03]],"id":41138102}],"con":true,"img":false}]}
{"op":"mcm","clk":"11541351796","pt":1719504853427,"mc":[{"id":"1.230180130","rc":[{"atl":[[23,0]],"id":41138102}],"con":true,"img":false}]}
{"op":"mcm","clk":"11541351806","pt":1719504853488,"mc":[{"id":"1.230180130","rc":[{"atl":[[95,2.26],[26,1],[27,0]],"id":41138102}],"con":true,"img":false}]}
{"op":"mcm","clk":"11541351826","pt":1719504853695,"mc":[{"id":"1.230180130","rc":[{"atb":[[2.92,13.08]],"id":58149406},{"atb":[[4.8,6],[9.2,4.73]],"id":41138102},{"atl":[[21,0.26],[23,1]],"id":41138102},{"atl":[[18,0],[19,1]],"id":43210435},{"atl":[[9,4],[10.5,0]],"id":66499052},{"atb":[[6.2,0]],"id":51843546}],"con":true,"img":false}]}
{"op":"mcm","clk":"11541351835","pt":1719504853793,"mc":[{"id":"1.230180130","rc":[{"atb":[[2.68,0]],"id":58149406},{"atb":[[4.3,0],[9.4,1]],"id":41138102},{"atl":[[95,0.26],[27,2.26]],"id":41138102},{"atl":[[65,0],[23,2.26]],"id":43210435}],"con":true,"img":false}]}
{"op":"mcm","clk":"11541351842","pt":1719504853903,"mc":[{"id":"1.230180130","rc":[{"atb":[[1.13,0.27]],"id":41138102},{"atl":[[23,0.26],[55,2]],"id":43210435}],"con":true,"img":false}]}
{"op":"mcm","clk":"11541351853","pt":1719504854007,"mc":[{"id":"1.230180130","rc":[{"atb":[[7.2,0.84]],"id":51843546}],"con":true,"img":false}]}
{"op":"mcm","clk":"11541351867","pt":1719504854209,"mc":[{"id":"1.230180130","rc":[{"atb":[[2.26,1.79],[2.08,0]],"id":69979297}],"con":true,"img":false}]}
{"op":"mcm","clk":"11541351875","pt":1719504854318,"mc":[{"id":"1.230180130","rc":[{"atl":[[60,0.47]],"id":43210435},{"atb":[[1.13,1]],"id":51843546}],"con":true,"img":false}]}
{"op":"mcm","clk":"11541351884","pt":1719504854422,"mc":[{"id":"1.230180130","rc":[{"atl":[[50,1]],"id":43210435},{"atb":[[7,3.77]],"id":51843546}],"con":true,"img":false}]}
{"op":"mcm","clk":"11541351891","pt":1719504854520,"mc":[{"id":"1.230180130","rc":[{"atb":[[1.13,0.16]],"id":51843546}],"con":true,"img":false}]}
{"op":"mcm","clk":"11541351899","pt":1719504854623,"mc":[{"id":"1.230180130","rc":[{"atl":[[130,0]],"id":43210435}],"con":true,"img":false}]}
{"op":"mcm","clk":"11541351907","pt":1719504854729,"mc":[{"id":"1.230180130","rc":[{"atb":[[5.6,1.34],[1.13,0]],"id":51843546}],"con":true,"img":false}]}
{"op":"mcm","clk":"11541351916","pt":1719504854831,"mc":[{"id":"1.230180130","rc":[{"atb":[[7.4,0.16]],"id":51843546}],"con":true,"img":false}]}
{"op":"mcm","clk":"11541351925","pt":1719504854935,"mc":[{"id":"1.230180130","rc":[{"atl":[[50,1.46]],"id":43210435},{"atb":[[2.28,0.84]],"id":69979297}],"con":true,"img":false}]}
{"op":"mcm","clk":"11541351933","pt":1719504855040,"mc":[{"id":"1.230180130","rc":[{"atb":[[7,2.14]],"id":51843546},{"atb":[[1.78,70.24]],"id":69979297}],"con":true,"img":false}]}
{"op":"mcm","clk":"11541351956","pt":1719504855296,"mc":[{"id":"1.230180130","rc":[{"atb":[[1.13,0]],"id":41138102}],"con":true,"img":false}]}
{"op":"mcm","clk":"11541351964","pt":1719504855397,"mc":[{"id":"1.230180130","rc":[{"atb":[[9.4,1.27]],"id":41138102}],"con":true,"img":false}]}
{"op":"mcm","clk":"11541352055","pt":1719504856437,"mc":[{"id":"1.230180130","rc":[{"atb":[[8.6,0]],"id":41138102}],"con":true,"img":false}]}
{"op":"mcm","clk":"11541352076","pt":1719504856591,"mc":[{"id":"1.230180130","rc":[{"atb":[[9.4,4.32]],"id":41138102}],"con":true,"img":false}]}
{"op":"mcm","clk":"11541352098","pt":1719504856902,"mc":[{"id":"1.230180130","rc":[{"atb":[[9.2,2.93]],"id":41138102},{"atb":[[5.5,0]],"id":51843546}],"con":true,"img":false}]}
{"op":"mcm","clk":"11541352109","pt":1719504857004,"mc":[{"id":"1.230180130","rc":[{"atb":[[9.6,1.8]],"id":41138102}],"con":true,"img":false}]}
{"op":"mcm","clk":"11541352118","pt":1719504857110,"mc":[{"id":"1.230180130","rc":[{"atb":[[9.6,4.44]],"id":41138102},{"atb":[[5.7,1.79]],"id":51843546}],"con":true,"img":false}]}
{"op":"mcm","clk":"11541352125","pt":1719504857218,"mc":[{"id":"1.230180130","rc":[{"atb":[[8.8,0]],"id":41138102}],"con":true,"img":false}]}
{"op":"mcm","clk":"11541352134","pt":1719504857318,"mc":[{"id":"1.230180130","rc":[{"atb":[[9.4,3.32]],"id":41138102}],"con":true,"img":false}]}
{"op":"mcm","clk":"11541352141","pt":1719504857422,"mc":[{"id":"1.230180130","rc":[{"atb":[[9.8,0.84]],"id":41138102}],"con":true,"img":false}]}
{"op":"mcm","clk":"11541352150","pt":1719504857522,"mc":[{"id":"1.230180130","rc":[{"atb":[[9.6,7.44]],"id":41138102},{"atb":[[5.1,0]],"id":66499052},{"trd":[[5.1,3.02]],"ltp":5.1,"tv":3.02,"id":66499052}],"con":true,"img":false}]}
{"op":"mcm","clk":"11541352158","pt":1719504857628,"mc":[{"id":"1.230180130","rc":[{"atb":[[9.8,1.84]],"id":41138102},{"atb":[[5,0]],"id":66499052},{"trd":[[5,2]],"ltp":5.0,"tv":2.0,"id":66499052}],"con":true,"img":false}]}
{"op":"mcm","clk":"11541352175","pt":1719504857831,"mc":[{"id":"1.230180130","rc":[{"atb":[[9.6,4.8]],"id":41138102},{"atl":[[22,1],[23,0]],"id":41138102},{"atl":[[19,0],[19.5,1]],"id":43210435},{"atb":[[4.6,0],[3.65,1]],"id":66499052},{"atl":[[5.2,1.44]],"id":66499052}],"con":true,"img":false}]}
{"op":"mcm","clk":"11541352178","pt":1719504857932,"mc":[{"id":"1.230180130","rc":[{"atl":[[11,1]],"id":58149406},{"atb":[[4.8,0],[9,0]],"id":41138102},{"atl":[[21,1.26]],"id":41138102},{"atl":[[55,0],[18.5,1],[23,2.26]],"id":43210435},{"atb":[[6.4,2],[6.6,0]],"id":51843546}],"con":true,"img":false}]}
{"op":"mcm","clk":"11541352185","pt":1719504858043,"mc":[{"id":"1.230180130","rc":[{"atb":[[10,2.53],[4,6],[9.8,4.94]],"id":41138102},{"atb":[[3.6,0],[3.55,12],[3.65,2.61]],"id":66499052}],"con":true,"img":false}]}
{"op":"mcm","clk":"11541352196","pt":1719504858144,"mc":[{"id":"1.230180130","rc":[{"atb":[[6.4,0]],"id":51843546}],"con":true,"img":false}]}
{"op":"mcm","clk":"11541352213","pt":1719504858202,"mc":[{"id":"1.230180130","rc":[{"atb":[[5.5,5.99],[5.7,0]],"id":51843546}],"con":true,"img":false}]}
{"op":"mcm","clk":"11541352233","pt":1719504858410,"mc":[{"id":"1.230180130","rc":[{"atb":[[3.75,0.84],[3.7,3.41]],"id":66499052},{"atl":[[5.2,2.44]],"id":66499052}],"con":true,"img":false}]}
{"op":"mcm","clk":"11541352240","pt":1719504858515,"mc":[{"id":"1.230180130","rc":[{"atl":[[5.3,7.07]],"id":66499052},{"atb":[[5.9,1.4]],"id":51843546}],"con":true,"img":false}]}
{"op":"mcm","clk":"11541352251","pt":1719504858613,"mc":[{"id":"1.230180130","rc":[{"atl":[[5.1,4.97]],"id":66499052}],"con":true,"img":false}]}
{"op":"mcm","clk":"11541352255","pt":1719504858719,"mc":[{"id":"1.230180130","rc":[{"atb":[[9.6,3]],"id":41138102},{"atb":[[3.65,1]],"id":66499052},{"atl":[[5.2,9.1]],"id":66499052}],"con":true,"img":false}]}
{"op":"mcm","clk":"11541352262","pt":1719504858823,"mc":[{"id":"1.230180130","rc":[{"atb":[[10,4.34]],"id":41138102}],"con":true,"img":false}]}
{"op":"mcm","clk":"11541352277","pt":1719504859029,"mc":[{"id":"1.230180130","rc":[{"atb":[[9.8,3.94]],"id":41138102},{"atl":[[26,3.26],[27,0]],"id":41138102}],"con":true,"img":false}]}
{"op":"mcm","clk":"11541352286","pt":1719504859142,"mc":[{"id":"1.230180130","rc":[{"atb":[[3.65,1.26]],"id":66499052}],"con":true,"img":false}]}
{"op":"mcm","clk":"11541352295","pt":1719504859234,"mc":[{"id":"1.230180130","rc":[{"atb":[[10.5,1]],"id":41138102},{"atb":[[4.5,1]],"id":66499052}],"con":true,"img":false}]}
{"op":"mcm","clk":"11541352315","pt":1719504859392,"mc":[{"id":"1.230180130","rc":[{"atb":[[3.7,6.37]],"id":66499052}],"con":true,"img":false}]}
{"op":"mcm","clk":"11541352325","pt":1719504859503,"mc":[{"id":"1.230180130","rc":[{"atl":[[50,0.46]],"id":43210435}],"con":true,"img":false}]}
{"op":"mcm","clk":"11541352333","pt":1719504859611,"mc":[{"id":"1.230180130","rc":[{"atb":[[10,1.8],[9.2,0]],"id":41138102},{"atl":[[22,1]],"id":43210435}],"con":true,"img":false}]}
{"op":"mcm","clk":"11541352343","pt":1719504859704,"mc":[{"id":"1.230180130","rc":[{"atb":[[1.04,1]],"id":43210435},{"atb":[[3.75,3.38]],"id":66499052}],"con":true,"img":false}]}
{"op":"mcm","clk":"11541352354","pt":1719504859812,"mc":[{"id":"1.230180130","rc":[{"atb":[[10.5,3.59]],"id":41138102},{"atl":[[5.1,10.34]],"id":66499052}],"con":true,"img":false}]}
{"op":"mcm","clk":"11541352367","pt":1719504859911,"mc":[{"id":"1.230180130","rc":[{"atb":[[1.04,0.59]],"id":43210435}],"con":true,"img":false}]}
{"op":"mcm","clk":"11541352376","pt":1719504860015,"mc":[{"id":"1.230180130","rc":[{"atl":[[26,2.26]],"id":41138102},{"atl":[[5.2,8.1]],"id":66499052}],"con":true,"img":false}]}
{"op":"mcm","clk":"11541352383","pt":1719504860117,"mc":[{"id":"1.230180130","rc":[{"atl":[[140,1]],"id":41138102},{"atb":[[1.04,0]],"id":43210435},{"atl":[[5,1]],"id":66499052}],"con":true,"img":false}]}
{"op":"mcm","clk":"11541352392","pt":1719504860221,"mc":[{"id":"1.230180130","rc":[{"atb":[[11,2.31]],"id":41138102},{"atb":[[8.6,1.43]],"id":43210435},{"atb":[[5.9,0]],"id":51843546}],"con":true,"img":false}]}
{"op":"mcm","clk":"11541352409","pt":1719504860432,"mc":[{"id":"1.230180130","rc":[{"atb":[[10,0],[9.4,0.27],[9.8,3.1]],"id":41138102},{"atl":[[80,0]],"id":43210435},{"atb":[[3.8,1.61]],"id":66499052}],"con":true,"img":false}]}
{"op":"mcm","clk":"11541352418","pt":1719504860534,"mc":[{"id":"1.230180130","rc":[{"atb":[[11,4.11]],"id":41138102},{"atl":[[140,0]],"id":41138102},{"atb":[[5.7,7.68]],"id":51843546}],"con":true,"img":false}]}
{"op":"mcm","clk":"11541352428","pt":1719504860632,"mc":[{"id":"1.230180130","rc":[{"atl":[[25,1]],"id":41138102}],"con":true,"img":false}]}
{"op":"mcm","clk":"11541352447","pt":1719504860840,"mc":[{"id":"1.230180130","rc":[{"atb":[[10.5,2.59],[11,6.34]],"id":41138102},{"atl":[[22,2.19]],"id":43210435}],"con":true,"img":false}]}
{"op":"mcm","clk":"11541352453","pt":1719504860894,"mc":[{"id":"1.230180130","rc":[{"atl":[[5.1,5.37]],"id":66499052}],"con":true,"img":false}]}
{"op":"mcm","clk":"11541352460","pt":1719504861001,"mc":[{"id":"1.230180130","rc":[{"atb":[[11.5,1]],"id":41138102},{"atb":[[5.8,1.63]],"id":51843546}],"con":true,"img":false}]}
{"op":"mcm","clk":"11541352514","pt":1719504861628,"mc":[{"id":"1.230180130","rc":[{"spn":7.5,"spf":"NaN","id":58149406},{"atb":[[11,4.03]],"id":41138102},{"spn":16.25,"spf":"NaN","id":41138102},{"spn":13.65,"spf":"NaN","id":43210435},{"spn":3.91,"spf":1.0,"id":66499052},{"spn":63.7,"spf":"NaN","id":51843546},{"spn":2.27,"spf":1.0,"id":69979297}],"con":true,"img":false}]}
{"op":"mcm","clk":"11541352531","pt":1719504861829,"mc":[{"id":"1.230180130","rc":[{"atb":[[5.7,0]],"id":51843546}],"con":true,"img":false}]}
{"op":"mcm","clk":"11541352552","pt":1719504862142,"mc":[{"id":"1.230180130","rc":[{"atb":[[5.9,1.4]],"id":51843546}],"con":true,"img":false}]}
{"op":"mcm","clk":"11541352561","pt":1719504862243,"mc":[{"id":"1.230180130","rc":[{"atb":[[11,2.23]],"id":41138102},{"atb":[[5.8,0]],"id":51843546}],"con":true,"img":false}]}
{"op":"mcm","clk":"11541352605","pt":1719504862714,"mc":[{"id":"1.230180130","rc":[{"atb":[[5.9,0]],"id":51843546}],"con":true,"img":false}]}
{"op":"mcm","clk":"11541352615","pt":1719504862821,"mc":[{"id":"1.230180130","rc":[{"atb":[[3.75,0.84]],"id":66499052}],"con":true,"img":false}]}
{"op":"mcm","clk":"11541352639","pt":1719504863028,"mc":[{"id":"1.230180130","rc":[{"atl":[[21,2.19],[23,0.26]],"id":43210435}],"con":true,"img":false}]}
{"op":"mcm","clk":"11541352652","pt":1719504863133,"mc":[{"id":"1.230180130","rc":[{"atl":[[11,0]],"id":58149406},{"atb":[[2.54,12.56],[4,0]],"id":41138102},{"atl":[[32,2.26],[21,0.26],[26,0]],"id":41138102},{"atl":[[18.5,0],[19.5,0]],"id":43210435},{"atb":[[5.7,7.68]],"id":51843546}],"con":true,"img":false}]}
{"op":"mcm","clk":"11541352675","pt":1719504863341,"mc":[{"id":"1.230180130","rc":[{"atb":[[4.9,6],[5.5,0]],"id":51843546}],"con":true,"img":false}]}
{"op":"mcm","clk":"11541352689","pt":1719504863445,"mc":[{"id":"1.230180130","rc":[{"atb":[[10.5,4.39]],"id":41138102},{"atb":[[3.8,0]],"id":66499052}],"con":true,"img":false}]}
{"op":"mcm","clk":"11541352698","pt":1719504863508,"mc":[{"id":"1.230180130","rc":[{"atl":[[25,0]],"id":41138102},{"atl":[[70,0],[22,1.19]],"id":43210435}],"con":true,"img":false}]}
{"op":"mcm","clk":"11541352706","pt":1719504863605,"mc":[{"id":"1.230180130","rc":[{"atl":[[30,1]],"id":41138102},{"atl":[[20,1]],"id":43210435}],"con":true,"img":false}]}
{"op":"mcm","clk":"11541352718","pt":1719504863708,"mc":[{"id":"1.230180130","rc":[{"atl":[[21,0],[30,1.79]],"id":41138102},{"atl":[[21,1.29],[22,5.57]],"id":43210435}],"con":true,"img":false}]}
{"op":"mcm","clk":"11541352735","pt":1719504863917,"mc":[{"id":"1.230180130","rc":[{"atl":[[20,1.84]],"id":43210435}],"con":true,"img":false}]}
{"op":"mcm","clk":"11541352742","pt":1719504864018,"mc":[{"id":"1.230180130","rc":[{"atb":[[10.5,2.59]],"id":41138102},{"atl":[[19,1]],"id":43210435}],"con":true,"img":false}]}
{"op":"mcm","clk":"11541352752","pt":1719504864124,"mc":[{"id":"1.230180130","rc":[{"atb":[[3.3,7.23],[2.92,0]],"id":58149406},{"atb":[[5.7,0]],"id":51843546}],"con":true,"img":false}]}
{"op":"mcm","clk":"11541352765","pt":1719504864330,"mc":[{"id":"1.230180130","rc":[{"atb":[[5.9,1.4]],"id":51843546}],"con":true,"img":false}]}
{"op":"mcm","clk":"11541352781","pt":1719504864541,"mc":[{"id":"1.230180130","rc":[{"atl":[[60,0]],"id":43210435}],"con":true,"img":false}]}
{"op":"mcm","clk":"11541352812","pt":1719504865001,"mc":[{"id":"1.230180130","rc":[{"atl":[[19.5,1.47]],"id":43210435}],"con":true,"img":false}]}
{"op":"mcm","clk":"11541352818","pt":1719504865104,"mc":[{"id":"1.230180130","rc":[{"atl":[[21,0.26]],"id":41138102}],"con":true,"img":false}]}
{"op":"mcm","clk":"11541352841","pt":1719504865415,"mc":[{"id":"1.230180130","rc":[{"atb":[[5.9,0]],"id":51843546}],"con":true,"img":false}]}
{"op":"mcm","clk":"11541352869","pt":1719504865727,"mc":[{"id":"1.230180130","rc":[{"atl":[[20,0.84]],"id":43210435},{"atb":[[5.9,6.92]],"id":51843546}],"con":true,"img":false}]}
{"op":"mcm","clk":"11541352877","pt":1719504865827,"mc":[{"id":"1.230180130","rc":[{"atl":[[21,2.29]],"id":43210435}],"con":true,"img":false}]}
{"op":"mcm","clk":"11541352914","pt":1719504866340,"mc":[{"id":"1.230180130","rc":[{"atb":[[5.9,0]],"id":51843546}],"con":true,"img":false}]}
{"op":"mcm","clk":"11541352929","pt":1719504866556,"mc":[{"id":"1.230180130","rc":[{"atb":[[5.9,1.4]],"id":51843546}],"con":true,"img":false}]}
{"op":"mcm","clk":"11541352982","pt":1719504867119,"mc":[{"id":"1.230180130","rc":[{"atb":[[5.9,0]],"id":51843546}],"con":true,"img":false}]}
{"op":"mcm","clk":"11541352991","pt":1719504867223,"mc":[{"id":"1.230180130","rc":[{"atb":[[3.25,0]],"id":66499052}],"con":true,"img":false}]}
{"op":"mcm","clk":"11541353014","pt":1719504867537,"mc":[{"id":"1.230180130","rc":[{"atl":[[12.5,0]],"id":66499052}],"con":true,"img":false}]}
{"op":"mcm","clk":"11541353025","pt":1719504867635,"mc":[{"id":"1.230180130","rc":[{"atb":[[4.5,0]],"id":66499052},{"trd":[[4.5,2]],"ltp":4.5,"tv":2.0,"id":66499052}],"con":true,"img":false}]}
{"op":"mcm","clk":"11541353034","pt":1719504867740,"mc":[{"id":"1.230180130","rc":[{"atb":[[3.35,12.74],[3.55,6]],"id":66499052},{"atl":[[5.1,7.32]],"id":66499052},{"atb":[[6,1.67]],"id":51843546}],"con":true,"img":false}]}
{"op":"mcm","clk":"11541353088","pt":1719504868418,"mc":[{"id":"1.230180130","rc":[{"atl":[[5,1.79]],"id":66499052}],"con":true,"img":false}]}
{"op":"mcm","clk":"11541353115","pt":1719504868725,"mc":[{"id":"1.230180130","rc":[{"atb":[[2.54,0],[2.02,98.04]],"id":41138102},{"atb":[[4.8,0],[3.9,10.26]],"id":43210435},{"atb":[[3.6,1],[3.1,12.37],[3.35,0],[3.65,0.26]],"id":66499052},{"atb":[[4.9,0],[3.55,14.86]],"id":51843546},{"atb":[[1.83,20],[1.78,0]],"id":69979297}],"con":true,"img":false}]}
{"op":"mcm","clk":"11541353127","pt":1719504868834,"mc":[{"id":"1.230180130","rc":[{"atl":[[21,4.58]],"id":43210435}],"con":true,"img":false}]}
{"op":"mcm","clk":"11541353137","pt":1719504868931,"mc":[{"id":"1.230180130","rc":[{"atl":[[22,1.19]],"id":43210435},{"atl":[[4.9,6.02],[5.2,7.26]],"id":66499052}],"con":true,"img":false}]}
{"op":"mcm","clk":"11541353146","pt":1719504869031,"mc":[{"id":"1.230180130","rc":[{"atl":[[5,1.46]],"id":66499052}],"con":true,"img":false}]}
{"op":"mcm","clk":"11541353169","pt":1719504869239,"mc":[{"id":"1.230180130","rc":[{"atb":[[4,1]],"id":66499052},{"atl":[[4.9,12.5]],"id":66499052}],"con":true,"img":false}]}
{"op":"mcm","clk":"11541353206","pt":1719504869654,"mc":[{"id":"1.230180130","rc":[{"atl":[[21,3.58]],"id":43210435},{"atl":[[5,0]],"id":66499052}],"con":true,"img":false}]}
{"op":"mcm","clk":"11541353214","pt":1719504869759,"mc":[{"id":"1.230180130","rc":[{"atl":[[140,1]],"id":43210435},{"atb":[[3.75,3.38]],"id":66499052},{"atl":[[4.8,1],[1000,0.64]],"id":66499052}],"con":true,"img":false}]}
{"op":"mcm","clk":"11541353240","pt":1719504870024,"mc":[{"id":"1.230180130","rc":[{"atl":[[4.9,7.32]],"id":66499052},{"atb":[[7.4,0]],"id":51843546}],"con":true,"img":false}]}
{"op":"mcm","clk":"11541353256","pt":1719504870241,"mc":[{"id":"1.230180130","rc":[{"atb":[[1.13,1]],"id":51843546}],"con":true,"img":false}]}
{"op":"mcm","clk":"11541353276","pt":1719504870435,"mc":[{"id":"1.230180130","rc":[{"atb":[[1.13,0.16]],"id":51843546}],"con":true,"img":false}]}
{"op":"mcm","clk":"11541353297","pt":1719504870638,"mc":[{"id":"1.230180130","rc":[{"atb":[[1.13,0]],"id":51843546}],"con":true,"img":false}]}
