{"op":"mcm","clk":"11536380661","pt":1719425245603,"mc":[{"id":"1.230178328","marketDefinition":{"bspMarket":true,"turnInPlayEnabled":false,"persistenceEnabled":false,"marketBaseRate":5.0,"eventId":"33376062","eventTypeId":"4339","numberOfWinners":1,"bettingType":"ODDS","marketType":"WIN","marketTime":"2024-06-27T17:02:00.000Z","suspendTime":"2024-06-27T17:02:00.000Z","bspReconciled":false,"complete":true,"inPlay":false,"crossMatching":false,"runnersVoidable":false,"numberOfActiveRunners":6,"betDelay":0,"status":"OPEN","runners":[{"status":"ACTIVE","sortPriority":1,"id":53082422,"name":"1. Betsys Minnie"},{"status":"ACTIVE","sortPriority":2,"id":70053016,"name":"2. Tuxedo Twlight"},{"status":"ACTIVE","sortPriority":3,"id":66686625,"name":"3. Ballymac Addie"},{"status":"ACTIVE","sortPriority":4,"id":64812720,"name":"4. Hes A Rebel"},{"status":"ACTIVE","sortPriority":5,"id":70902603,"name":"5. Follow Suit"},{"status":"ACTIVE","sortPriority":6,"id":69942666,"name":"6. Pukka Poppy"}],"regulators":["MR_INT"],"venue":"Kinsley","countryCode":"GB","discountAllowed":false,"timezone":"Europe/London","openDate":"2024-06-27T13:36:00.000Z","version":5994643773,"name":"A4 462m","eventName":"Kinsley 27th Jun"},"rc":[],"con":true,"img":false}]}
{"op":"mcm","clk":"11536381027","pt":1719425248531,"mc":[{"id":"1.230178328","marketDefinition":{"bspMarket":true,"turnInPlayEnabled":false,"persistenceEnabled":false,"marketBaseRate":5.0,"eventId":"33376062","eventTypeId":"4339","numberOfWinners":1,"bettingType":"ODDS","marketType":"WIN","marketTime":"2024-06-27T17:02:00.000Z","suspendTime":"2024-06-27T17:02:00.000Z","bspReconciled":false,"complete":true,"inPlay":false,"crossMatching":false,"runnersVoidable":false,"numberOfActiveRunners":6,"betDelay":0,"status":"OPEN","runners":[{"status":"ACTIVE","sortPriority":1,"id":53082422,"name":"1. Betsys Minnie"},{"status":"ACTIVE","sortPriority":2,"id":70053016,"name":"2. Tuxedo Twlight"},{"status":"ACTIVE","sortPriority":3,"id":66686625,"name":"3. Ballymac Addie"},{"status":"ACTIVE","sortPriority":4,"id":64812720,"name":"4. Hes A Rebel"},{"status":"ACTIVE","sortPriority":5,"id":70902603,"name":"5. Follow Suit"},{"status":"ACTIVE","sortPriority":6,"id":69942666,"name":"6. Pukka Poppy"}],"regulators":["MR_INT"],"venue":"Kinsley","countryCode":"GB","discountAllowed":true,"timezone":"Europe/London","openDate":"2024-06-27T13:36:00.000Z","version":5994643773,"name":"A4 462m","eventName":"Kinsley 27th Jun"},"rc":[],"con":true,"img":false}]}
{"op":"mcm","clk":"11536615144","pt":1719428244120,"mc":[{"id":"1.230178328","rc":[{"atb":[[1.01,45.27]],"id":64812720},{"atl":[[1000,0.84]],"id":64812720},{"spn":500.5,"spf":"NaN","id":64812720},{"atb":[[1.03,15.09]],"id":70902603},{"atl":[[1000,0.84]],"id":70902603},{"spn":500.51,"spf":"NaN","id":70902603},{"atb":[[1.03,15.09]],"id":66686625},{"atl":[[1000,0.84]],"id":66686625},{"spn":500.51,"spf":"NaN","id":66686625},{"atb":[[1.01,45.27]],"id":70053016},{"atl":[[990,0.84]],"id":70053016},{"spn":495.5,"spf":"NaN","id":70053016},{"atb":[[1.01,45.27]],"id":69942666},{"atl":[[1000,0.84]],"id":69942666},{"spn":500.5,"spf":"NaN","id":69942666},{"atb":[[1.02,22.63]],"id":53082422},{"atl":[[990,0.84]],"id":53082422},{"spn":495.51,"spf":"NaN","id":53082422}],"con":true,"img":false}]}
{"op":"mcm","clk":"11536836904","pt":1719431850640,"mc":[{"id":"1.230178328","rc":[{"atb":[[1.01,45.28]],"id":64812720},{"atl":[[1000,0.26]],"id":64812720},{"atb":[[1.03,15.09]],"id":70902603},{"atl":[[1000,0.26]],"id":70902603},{"atb":[[1.03,15.09]],"id":66686625},{"atl":[[1000,0.26]],"id":66686625},{"atb":[[1.01,45.28]],"id":70053016},{"atl":[[990,0.26]],"id":70053016},{"atb":[[1.01,45.28]],"id":69942666},{"atl":[[1000,0.26]],"id":69942666},{"atb":[[1.02,22.64]],"id":53082422},{"atl":[[990,0.26]],"id":53082422}],"con":true,"img":false}]}
{"op":"mcm","clk":"11536864495","pt":1719432280288,"mc":[{"id":"1.230178328","rc":[{"spl":[[1.01,1]],"id":53082422},{"spn":1.02,"spf":1.0,"id":53082422}],"con":true,"img":false}]}
{"op":"mcm","clk":"11537232263","pt":1719437882520,"mc":[{"id":"1.230178328","marketDefinition":{"bspMarket":true,"turnInPlayEnabled":false,"persistenceEnabled":false,"marketBaseRate":5.0,"eventId":"33376062","eventTypeId":"4339","numberOfWinners":1,"bettingType":"ODDS","marketType":"WIN","marketTime":"2024-06-27T17:02:00.000Z","suspendTime":"2024-06-27T17:02:00.000Z","bspReconciled":false,"complete":true,"inPlay":false,"crossMatching":false,"runnersVoidable":false,"numberOfActiveRunners":6,"betDelay":0,"status":"OPEN","runners":[{"status":"ACTIVE","sortPriority":1,"id":53082422,"name":"1. Betsys Minnie"},{"status":"ACTIVE","sortPriority":2,"id":70053016,"name":"2. Tuxedo Twlight"},{"status":"ACTIVE","sortPriority":3,"id":66686625,"name":"3. Ballymac Addie"},{"status":"ACTIVE","sortPriority":4,"id":64812720,"name":"4. Hes A Rebel"},{"status":"ACTIVE","sortPriority":5,"id":70902603,"name":"5. Follow Suit"},{"status":"ACTIVE","sortPriority":6,"id":69942666,"name":"6. Pukka Poppy"}],"regulators":["MR_INT"],"venue":"Kinsley","countryCode":"GB","discountAllowed":true,"timezone":"Europe/London","openDate":"2024-06-27T13:36:00.000Z","version":5994643773,"name":"A4 462m","eventName":"Kinsley 27th Jun"},"rc":[{"atb":[[1.01,45.28]],"id":64812720},{"atl":[[1000,0.26]],"id":64812720},{"spn":500.5,"spf":"NaN","id":64812720},{"atb":[[1.03,15.09]],"id":70902603},{"atl":[[1000,0.26]],"id":70902603},{"spn":500.51,"spf":"NaN","id":70902603},{"atb":[[1.03,15.09]],"id":66686625},{"atl":[[1000,0.26]],"id":66686625},{"spn":500.51,"spf":"NaN","id":66686625},{"atb":[[1.01,45.28]],"id":70053016},{"atl":[[990,0.26]],"id":70053016},{"spn":495.5,"spf":"NaN","id":70053016},{"atb":[[1.01,45.28]],"id":69942666},{"atl":[[1000,0.26]],"id":69942666},{"spn":500.5,"spf":"NaN","id":69942666},{"spl":[[1.01,1]],"id":53082422},{"atb":[[1.02,22.64]],"id":53082422},{"atl":[[990,0.26]],"id":53082422},{"spn":1.02,"spf":1.0,"id":53082422}],"con":true,"img":true}]}
{"op":"mcm","clk":"11537573390","pt":1719443282538,"mc":[{"id":"1.230178328","marketDefinition":{"bspMarket":true,"turnInPlayEnabled":false,"persistenceEnabled":false,"marketBaseRate":5.0,"eventId":"33376062","eventTypeId":"4339","numberOfWinners":1,"bettingType":"ODDS","marketType":"WIN","marketTime":"2024-06-27T17:02:00.000Z","suspendTime":"2024-06-27T17:02:00.000Z","bspReconciled":false,"complete":true,"inPlay":false,"crossMatching":false,"runnersVoidable":false,"numberOfActiveRunners":6,"betDelay":0,"status":"OPEN","runners":[{"status":"ACTIVE","sortPriority":1,"id":53082422,"name":"1. Betsys Minnie"},{"status":"ACTIVE","sortPriority":2,"id":70053016,"name":"2. Tuxedo Twlight"},{"status":"ACTIVE","sortPriority":3,"id":66686625,"name":"3. Ballymac Addie"},{"status":"ACTIVE","sortPriority":4,"id":64812720,"name":"4. Hes A Rebel"},{"status":"ACTIVE","sortPriority":5,"id":70902603,"name":"5. Follow Suit"},{"status":"ACTIVE","sortPriority":6,"id":69942666,"name":"6. Pukka Poppy"}],"regulators":["MR_INT"],"venue":"Kinsley","countryCode":"GB","discountAllowed":true,"timezone":"Europe/London","openDate":"2024-06-27T13:36:00.000Z","version":5994643773,"name":"A4 462m","eventName":"Kinsley 27th Jun"},"rc":[{"atb":[[1.01,45.29]],"id":64812720},{"atl":[[1000,0.26]],"id":64812720},{"spn":500.5,"spf":"NaN","id":64812720},{"atb":[[1.03,15.09]],"id":70902603},{"atl":[[1000,0.26]],"id":70902603},{"spn":500.51,"spf":"NaN","id":70902603},{"atb":[[1.03,15.09]],"id":66686625},{"atl":[[1000,0.26]],"id":66686625},{"spn":500.51,"spf":"NaN","id":66686625},{"atb":[[1.01,45.29]],"id":70053016},{"atl":[[990,0.26]],"id":70053016},{"spn":495.5,"spf":"NaN","id":70053016},{"atb":[[1.01,45.29]],"id":69942666},{"atl":[[1000,0.26]],"id":69942666},{"spn":500.5,"spf":"NaN","id":69942666},{"spl":[[1.01,1]],"id":53082422},{"atb":[[1.02,22.64]],"id":53082422},{"atl":[[990,0.26]],"id":53082422},{"spn":1.02,"spf":1.0,"id":53082422}],"con":true,"img":true}]}
{"op":"mcm","clk":"11537954950","pt":1719448682563,"mc":[{"id":"1.230178328","marketDefinition":{"bspMarket":true,"turnInPlayEnabled":false,"persistenceEnabled":false,"marketBaseRate":5.0,"eventId":"33376062","eventTypeId":"4339","numberOfWinners":1,"bettingType":"ODDS","marketType":"WIN","marketTime":"2024-06-27T17:02:00.000Z","suspendTime":"2024-06-27T17:02:00.000Z","bspReconciled":false,"complete":true,"inPlay":false,"crossMatching":false,"runnersVoidable":false,"numberOfActiveRunners":6,"betDelay":0,"status":"OPEN","runners":[{"status":"ACTIVE","sortPriority":1,"id":53082422,"name":"1. Betsys Minnie"},{"status":"ACTIVE","sortPriority":2,"id":70053016,"name":"2. Tuxedo Twlight"},{"status":"ACTIVE","sortPriority":3,"id":66686625,"name":"3. Ballymac Addie"},{"status":"ACTIVE","sortPriority":4,"id":64812720,"name":"4. Hes A Rebel"},{"status":"ACTIVE","sortPriority":5,"id":70902603,"name":"5. Follow Suit"},{"status":"ACTIVE","sortPriority":6,"id":69942666,"name":"6. Pukka Poppy"}],"regulators":["MR_INT"],"venue":"Kinsley","countryCode":"GB","discountAllowed":true,"timezone":"Europe/London","openDate":"2024-06-27T13:36:00.000Z","version":5994643773,"name":"A4 462m","eventName":"Kinsley 27th Jun"},"rc":[{"atb":[[1.01,45.28]],"id":64812720},{"atl":[[1000,0.26]],"id":64812720},{"spn":500.5,"spf":"NaN","id":64812720},{"atb":[[1.03,15.09]],"id":70902603},{"atl":[[1000,0.26]],"id":70902603},{"spn":500.51,"spf":"NaN","id":70902603},{"atb":[[1.03,15.09]],"id":66686625},{"atl":[[1000,0.26]],"id":66686625},{"spn":500.51,"spf":"NaN","id":66686625},{"atb":[[1.01,45.28]],"id":70053016},{"atl":[[990,0.26]],"id":70053016},{"spn":495.5,"spf":"NaN","id":70053016},{"atb":[[1.01,45.28]],"id":69942666},{"atl":[[1000,0.26]],"id":69942666},{"spn":500.5,"spf":"NaN","id":69942666},{"spl":[[1.01,1]],"id":53082422},{"atb":[[1.02,22.64]],"id":53082422},{"atl":[[990,0.26]],"id":53082422},{"spn":1.02,"spf":1.0,"id":53082422}],"con":true,"img":true}]}
{"op":"mcm","clk":"11538170613","pt":1719454082546,"mc":[{"id":"1.230178328","marketDefinition":{"bspMarket":true,"turnInPlayEnabled":false,"persistenceEnabled":false,"marketBaseRate":5.0,"eventId":"33376062","eventTypeId":"4339","numberOfWinners":1,"bettingType":"ODDS","marketType":"WIN","marketTime":"2024-06-27T17:02:00.000Z","suspendTime":"2024-06-27T17:02:00.000Z","bspReconciled":false,"complete":true,"inPlay":false,"crossMatching":false,"runnersVoidable":false,"numberOfActiveRunners":6,"betDelay":0,"status":"OPEN","runners":[{"status":"ACTIVE","sortPriority":1,"id":53082422,"name":"1. Betsys Minnie"},{"status":"ACTIVE","sortPriority":2,"id":70053016,"name":"2. Tuxedo Twlight"},{"status":"ACTIVE","sortPriority":3,"id":66686625,"name":"3. Ballymac Addie"},{"status":"ACTIVE","sortPriority":4,"id":64812720,"name":"4. Hes A Rebel"},{"status":"ACTIVE","sortPriority":5,"id":70902603,"name":"5. Follow Suit"},{"status":"ACTIVE","sortPriority":6,"id":69942666,"name":"6. Pukka Poppy"}],"regulators":["MR_INT"],"venue":"Kinsley","countryCode":"GB","discountAllowed":true,"timezone":"Europe/London","openDate":"2024-06-27T13:36:00.000Z","version":5994643773,"name":"A4 462m","eventName":"Kinsley 27th Jun"},"rc":[{"atb":[[1.01,45.29]],"id":64812720},{"atl":[[1000,0.26]],"id":64812720},{"spn":500.5,"spf":"NaN","id":64812720},{"atb":[[1.03,15.09]],"id":70902603},{"atl":[[1000,0.26]],"id":70902603},{"spn":500.51,"spf":"NaN","id":70902603},{"atb":[[1.03,15.09]],"id":66686625},{"atl":[[1000,0.26]],"id":66686625},{"spn":500.51,"spf":"NaN","id":66686625},{"atb":[[1.01,45.29]],"id":70053016},{"atl":[[990,0.26]],"id":70053016},{"spn":495.5,"spf":"NaN","id":70053016},{"atb":[[1.01,45.29]],"id":69942666},{"atl":[[1000,0.26]],"id":69942666},{"spn":500.5,"spf":"NaN","id":69942666},{"spl":[[1.01,1]],"id":53082422},{"atb":[[1.02,22.64]],"id":53082422},{"atl":[[990,0.26]],"id":53082422},{"spn":1.02,"spf":1.0,"id":53082422}],"con":true,"img":true}]}
{"op":"mcm","clk":"11538368271","pt":1719459482595,"mc":[{"id":"1.230178328","marketDefinition":{"bspMarket":true,"turnInPlayEnabled":false,"persistenceEnabled":false,"marketBaseRate":5.0,"eventId":"33376062","eventTypeId":"4339","numberOfWinners":1,"bettingType":"ODDS","marketType":"WIN","marketTime":"2024-06-27T17:02:00.000Z","suspendTime":"2024-06-27T17:02:00.000Z","bspReconciled":false,"complete":true,"inPlay":false,"crossMatching":false,"runnersVoidable":false,"numberOfActiveRunners":6,"betDelay":0,"status":"OPEN","runners":[{"status":"ACTIVE","sortPriority":1,"id":53082422,"name":"1. Betsys Minnie"},{"status":"ACTIVE","sortPriority":2,"id":70053016,"name":"2. Tuxedo Twlight"},{"status":"ACTIVE","sortPriority":3,"id":66686625,"name":"3. Ballymac Addie"},{"status":"ACTIVE","sortPriority":4,"id":64812720,"name":"4. Hes A Rebel"},{"status":"ACTIVE","sortPriority":5,"id":70902603,"name":"5. Follow Suit"},{"status":"ACTIVE","sortPriority":6,"id":69942666,"name":"6. Pukka Poppy"}],"regulators":["MR_INT"],"venue":"Kinsley","countryCode":"GB","discountAllowed":true,"timezone":"Europe/London","openDate":"2024-06-27T13:36:00.000Z","version":5994643773,"name":"A4 462m","eventName":"Kinsley 27th Jun"},"rc":[{"atb":[[1.01,45.3]],"id":64812720},{"atl":[[1000,0.26]],"id":64812720},{"spn":500.5,"spf":"NaN","id":64812720},{"atb":[[1.03,15.1]],"id":70902603},{"atl":[[1000,0.26]],"id":70902603},{"spn":500.51,"spf":"NaN","id":70902603},{"atb":[[1.03,15.1]],"id":66686625},{"atl":[[1000,0.26]],"id":66686625},{"spn":500.51,"spf":"NaN","id":66686625},{"atb":[[1.01,45.3]],"id":70053016},{"atl":[[990,0.26]],"id":70053016},{"spn":495.5,"spf":"NaN","id":70053016},{"atb":[[1.01,45.3]],"id":69942666},{"atl":[[1000,0.26]],"id":69942666},{"spn":500.5,"spf":"NaN","id":69942666},{"spl":[[1.01,1]],"id":53082422},{"atb":[[1.02,22.65]],"id":53082422},{"atl":[[990,0.26]],"id":53082422},{"spn":1.02,"spf":1.0,"id":53082422}],"con":true,"img":true}]}
{"op":"mcm","clk":"11538595397","pt":1719464882544,"mc":[{"id":"1.230178328","marketDefinition":{"bspMarket":true,"turnInPlayEnabled":false,"persistenceEnabled":false,"marketBaseRate":5.0,"eventId":"33376062","eventTypeId":"4339","numberOfWinners":1,"bettingType":"ODDS","marketType":"WIN","marketTime":"2024-06-27T17:02:00.000Z","suspendTime":"2024-06-27T17:02:00.000Z","bspReconciled":false,"complete":true,"inPlay":false,"crossMatching":false,"runnersVoidable":false,"numberOfActiveRunners":6,"betDelay":0,"status":"OPEN","runners":[{"status":"ACTIVE","sortPriority":1,"id":53082422,"name":"1. Betsys Minnie"},{"status":"ACTIVE","sortPriority":2,"id":70053016,"name":"2. Tuxedo Twlight"},{"status":"ACTIVE","sortPriority":3,"id":66686625,"name":"3. Ballymac Addie"},{"status":"ACTIVE","sortPriority":4,"id":64812720,"name":"4. Hes A Rebel"},{"status":"ACTIVE","sortPriority":5,"id":70902603,"name":"5. Follow Suit"},{"status":"ACTIVE","sortPriority":6,"id":69942666,"name":"6. Pukka Poppy"}],"regulators":["MR_INT"],"venue":"Kinsley","countryCode":"GB","discountAllowed":true,"timezone":"Europe/London","openDate":"2024-06-27T13:36:00.000Z","version":5994643773,"name":"A4 462m","eventName":"Kinsley 27th Jun"},"rc":[{"atb":[[1.01,45.29]],"id":64812720},{"atl":[[1000,0.26]],"id":64812720},{"spn":500.5,"spf":"NaN","id":64812720},{"atb":[[1.03,15.09]],"id":70902603},{"atl":[[1000,0.26]],"id":70902603},{"spn":500.51,"spf":"NaN","id":70902603},{"atb":[[1.03,15.09]],"id":66686625},{"atl":[[1000,0.26]],"id":66686625},{"spn":500.51,"spf":"NaN","id":66686625},{"atb":[[1.01,45.29]],"id":70053016},{"atl":[[990,0.26]],"id":70053016},{"spn":495.5,"spf":"NaN","id":70053016},{"atb":[[1.01,45.29]],"id":69942666},{"atl":[[1000,0.26]],"id":69942666},{"spn":500.5,"spf":"NaN","id":69942666},{"spl":[[1.01,1]],"id":53082422},{"atb":[[1.02,22.64]],"id":53082422},{"atl":[[990,0.26]],"id":53082422},{"spn":1.02,"spf":1.0,"id":53082422}],"con":true,"img":true}]}
{"op":"mcm","clk":"11538748695","pt":1719468206195,"mc":[{"id":"1.230178328","rc":[{"atb":[[1.01,45.29],[2.08,13.32]],"id":64812720},{"spn":501.04,"spf":"NaN","id":64812720},{"atb":[[1.03,15.09],[2.08,13.32]],"id":70902603},{"spn":501.04,"spf":"NaN","id":70902603},{"atb":[[2.02,9.49],[1.03,15.09]],"id":66686625},{"spn":501.01,"spf":"NaN","id":66686625},{"atb":[[1.01,45.29],[2.04,13.07]],"id":70053016},{"spn":496.02,"spf":"NaN","id":70053016},{"atb":[[2,11.96],[1.01,45.29]],"id":69942666},{"spn":501.0,"spf":"NaN","id":69942666},{"atb":[[2.02,12.08],[1.02,22.64]],"id":53082422},{"spn":2.02,"spf":1.0,"id":53082422}],"con":true,"img":false}]}
{"op":"mcm","clk":"11538750177","pt":1719468238839,"mc":[{"id":"1.230178328","rc":[{"atb":[[2.04,3.16]],"id":53082422}],"con":true,"img":false}]}
{"op":"mcm","clk":"11538750214","pt":1719468239449,"mc":[{"id":"1.230178328","rc":[{"atb":[[2.04,3.16]],"id":66686625},{"atb":[[2.06,3.16]],"id":70053016}],"con":true,"img":false}]}
{"op":"mcm","clk":"11538750226","pt":1719468239653,"mc":[{"id":"1.230178328","rc":[{"atb":[[2.02,3.16]],"id":69942666}],"con":true,"img":false}]}
{"op":"mcm","clk":"11538750238","pt":1719468239960,"mc":[{"id":"1.230178328","rc":[{"atb":[[2.1,3.16]],"id":64812720}],"con":true,"img":false}]}
{"op":"mcm","clk":"11538750298","pt":1719468241251,"mc":[{"id":"1.230178328","rc":[{"atb":[[2.1,3.16]],"id":70902603}],"con":true,"img":false}]}
{"op":"mcm","clk":"11538751993","pt":1719468273519,"mc":[{"id":"1.230178328","rc":[{"spn":501.05,"spf":"NaN","id":64812720},{"spn":501.05,"spf":"NaN","id":70902603},{"spn":501.02,"spf":"NaN","id":66686625},{"spn":496.03,"spf":"NaN","id":70053016},{"spn":501.01,"spf":"NaN","id":69942666},{"atb":[[2.04,6.55]],"id":53082422},{"spn":2.04,"spf":1.0,"id":53082422}],"con":true,"img":false}]}
{"op":"mcm","clk":"11538751997","pt":1719468273622,"mc":[{"id":"1.230178328","rc":[{"atb":[[2.06,6.55]],"id":70053016}],"con":true,"img":false}]}
{"op":"mcm","clk":"11538752005","pt":1719468273775,"mc":[{"id":"1.230178328","rc":[{"atb":[[2.04,6.55]],"id":66686625}],"con":true,"img":false}]}
{"op":"mcm","clk":"11538752009","pt":1719468273878,"mc":[{"id":"1.230178328","rc":[{"atb":[[2.02,6.55]],"id":69942666}],"con":true,"img":false}]}
{"op":"mcm","clk":"11538752014","pt":1719468274085,"mc":[{"id":"1.230178328","rc":[{"atb":[[2.1,6.55]],"id":70902603}],"con":true,"img":false}]}
{"op":"mcm","clk":"11538752017","pt":1719468274187,"mc":[{"id":"1.230178328","rc":[{"atb":[[2.1,6.55]],"id":64812720}],"con":true,"img":false}]}
{"op":"mcm","clk":"11538752358","pt":1719468281716,"mc":[{"id":"1.230178328","marketDefinition":{"bspMarket":true,"turnInPlayEnabled":false,"persistenceEnabled":false,"marketBaseRate":5.0,"eventId":"33376062","eventTypeId":"4339","numberOfWinners":1,"bettingType":"ODDS","marketType":"WIN","marketTime":"2024-06-27T17:02:00.000Z","suspendTime":"2024-06-27T17:02:00.000Z","bspReconciled":false,"complete":true,"inPlay":false,"crossMatching":true,"runnersVoidable":false,"numberOfActiveRunners":6,"betDelay":0,"status":"OPEN","runners":[{"status":"ACTIVE","sortPriority":1,"id":53082422,"name":"1. Betsys Minnie"},{"status":"ACTIVE","sortPriority":2,"id":70053016,"name":"2. Tuxedo Twlight"},{"status":"ACTIVE","sortPriority":3,"id":66686625,"name":"3. Ballymac Addie"},{"status":"ACTIVE","sortPriority":4,"id":64812720,"name":"4. Hes A Rebel"},{"status":"ACTIVE","sortPriority":5,"id":70902603,"name":"5. Follow Suit"},{"status":"ACTIVE","sortPriority":6,"id":69942666,"name":"6. Pukka Poppy"}],"regulators":["MR_INT"],"venue":"Kinsley","countryCode":"GB","discountAllowed":true,"timezone":"Europe/London","openDate":"2024-06-27T13:36:00.000Z","version":5994643773,"name":"A4 462m","eventName":"Kinsley 27th Jun"},"rc":[],"con":true,"img":false}]}
{"op":"mcm","clk":"11538904947","pt":1719471463224,"mc":[{"id":"1.230178328","rc":[{"atl":[[1000,0.16]],"id":64812720},{"atl":[[1000,0.16]],"id":70902603},{"atl":[[1000,0.16]],"id":66686625},{"atl":[[990,0.16]],"id":70053016},{"atl":[[1000,0.16]],"id":69942666},{"atl":[[990,0.16]],"id":53082422}],"con":true,"img":false}]}
{"op":"mcm","clk":"11538939010","pt":1719472081853,"mc":[{"id":"1.230178328","rc":[{"atb":[[1.01,45.26],[2.1,6.54],[2.08,13.32]],"id":64812720},{"atl":[[1000,0.16]],"id":64812720},{"atb":[[1.03,15.08],[2.1,6.54],[2.08,13.32]],"id":70902603},{"atl":[[1000,0.16]],"id":70902603},{"atb":[[2.02,9.48],[1.03,15.08],[2.04,6.54]],"id":66686625},{"atl":[[1000,0.16]],"id":66686625},{"atb":[[1.01,45.26],[2.06,6.54],[2.04,13.06]],"id":70053016},{"atl":[[990,0.16]],"id":70053016},{"atb":[[2,11.95],[2.02,6.54],[1.01,45.26]],"id":69942666},{"atl":[[1000,0.16]],"id":69942666},{"atb":[[2.02,12.07],[2.04,6.54],[1.02,22.63]],"id":53082422},{"atl":[[990,0.16],[30,0.6]],"id":53082422}],"con":true,"img":false}]}
{"op":"mcm","clk":"11538940859","pt":1719472115370,"mc":[{"id":"1.230178328","rc":[{"atb":[[2.08,0]],"id":64812720},{"atb":[[2.08,0]],"id":70902603},{"atb":[[2.02,0]],"id":66686625},{"atb":[[2.04,0]],"id":70053016},{"atb":[[2,0]],"id":69942666},{"atb":[[2.02,0]],"id":53082422}],"con":true,"img":false}]}
{"op":"mcm","clk":"11538940865","pt":1719472115472,"mc":[{"id":"1.230178328","rc":[{"atb":[[2.12,13.32]],"id":64812720},{"atb":[[2.12,13.32]],"id":70902603},{"atb":[[2.06,9.48]],"id":66686625},{"atb":[[2.08,13.06]],"id":70053016},{"atb":[[2.04,11.95]],"id":69942666},{"atb":[[2.06,12.07]],"id":53082422}],"con":true,"img":false}]}
{"op":"mcm","clk":"11538942004","pt":1719472133604,"mc":[{"id":"1.230178328","rc":[{"atb":[[2.06,3.38]],"id":70053016}],"con":true,"img":false}]}
{"op":"mcm","clk":"11538942053","pt":1719472134377,"mc":[{"id":"1.230178328","rc":[{"atb":[[2.1,3.38]],"id":64812720},{"atb":[[2.1,3.38]],"id":70902603}],"con":true,"img":false}]}
{"op":"mcm","clk":"11538942067","pt":1719472134576,"mc":[{"id":"1.230178328","rc":[{"atb":[[2.14,3.16]],"id":64812720}],"con":true,"img":false}]}
{"op":"mcm","clk":"11538942124","pt":1719472135703,"mc":[{"id":"1.230178328","rc":[{"atb":[[2.02,3.38]],"id":69942666}],"con":true,"img":false}]}
{"op":"mcm","clk":"11538942211","pt":1719472136997,"mc":[{"id":"1.230178328","rc":[{"atb":[[2.1,3.16]],"id":70053016}],"con":true,"img":false}]}
{"op":"mcm","clk":"11538942216","pt":1719472137098,"mc":[{"id":"1.230178328","rc":[{"atb":[[2.04,3.38]],"id":53082422}],"con":true,"img":false}]}
{"op":"mcm","clk":"11538942257","pt":1719472137606,"mc":[{"id":"1.230178328","rc":[{"atb":[[2.04,3.38]],"id":66686625}],"con":true,"img":false}]}
{"op":"mcm","clk":"11538942332","pt":1719472138886,"mc":[{"id":"1.230178328","rc":[{"atb":[[2.14,3.16]],"id":70902603}],"con":true,"img":false}]}
{"op":"mcm","clk":"11538942406","pt":1719472140218,"mc":[{"id":"1.230178328","rc":[{"atb":[[2.08,3.16]],"id":53082422}],"con":true,"img":false}]}
{"op":"mcm","clk":"11538942585","pt":1719472142482,"mc":[{"id":"1.230178328","rc":[{"spn":501.07,"spf":"NaN","id":64812720},{"spn":501.07,"spf":"NaN","id":70902603},{"spn":501.03,"spf":"NaN","id":66686625},{"spn":496.05,"spf":"NaN","id":70053016},{"atb":[[2.06,3.16]],"id":69942666},{"spn":501.03,"spf":"NaN","id":69942666},{"spn":2.08,"spf":1.0,"id":53082422}],"con":true,"img":false}]}
{"op":"mcm","clk":"11538942590","pt":1719472142584,"mc":[{"id":"1.230178328","rc":[{"atb":[[2.08,3.16]],"id":66686625}],"con":true,"img":false}]}
{"op":"mcm","clk":"11538942762","pt":1719472145314,"mc":[{"id":"1.230178328","rc":[{"atb":[[2.06,0]],"id":70053016},{"atb":[[2.04,0]],"id":53082422}],"con":true,"img":false}]}
{"op":"mcm","clk":"11538942785","pt":1719472145623,"mc":[{"id":"1.230178328","rc":[{"atb":[[2.1,0]],"id":64812720},{"atb":[[2.04,0]],"id":66686625}],"con":true,"img":false}]}
{"op":"mcm","clk":"11538942848","pt":1719472146401,"mc":[{"id":"1.230178328","rc":[{"atb":[[2.02,0]],"id":69942666}],"con":true,"img":false}]}
{"op":"mcm","clk":"11538942897","pt":1719472147022,"mc":[{"id":"1.230178328","rc":[{"atb":[[2.1,0]],"id":70902603}],"con":true,"img":false}]}
{"op":"mcm","clk":"11538943372","pt":1719472154616,"mc":[{"id":"1.230178328","rc":[{"atb":[[2.08,6.54]],"id":66686625}],"con":true,"img":false}]}
{"op":"mcm","clk":"11538943396","pt":1719472154923,"mc":[{"id":"1.230178328","rc":[{"atb":[[2.06,6.54]],"id":69942666}],"con":true,"img":false}]}
{"op":"mcm","clk":"11538943404","pt":1719472155025,"mc":[{"id":"1.230178328","rc":[{"atb":[[2.08,6.54]],"id":53082422}],"con":true,"img":false}]}
{"op":"mcm","clk":"11538943419","pt":1719472155231,"mc":[{"id":"1.230178328","rc":[{"atb":[[2.14,6.54]],"id":64812720}],"con":true,"img":false}]}
{"op":"mcm","clk":"11538943473","pt":1719472156106,"mc":[{"id":"1.230178328","rc":[{"atb":[[2.14,6.54]],"id":70902603}],"con":true,"img":false}]}
{"op":"mcm","clk":"11538943513","pt":1719472156715,"mc":[{"id":"1.230178328","rc":[{"atb":[[2.1,6.54]],"id":70053016}],"con":true,"img":false}]}
{"op":"mcm","clk":"11539104728","pt":1719475339983,"mc":[{"id":"1.230178328","rc":[{"atb":[[1.01,45.28],[2.12,13.32],[2.14,6.55]],"id":64812720},{"atl":[[150,4]],"id":64812720},{"spn":76.07,"spf":"NaN","id":64812720},{"atb":[[1.03,15.09],[2.12,13.32],[2.14,6.55]],"id":70902603},{"atl":[[150,4]],"id":70902603},{"spn":76.07,"spf":"NaN","id":70902603},{"atb":[[2.06,9.49],[1.03,15.09],[2.08,6.55]],"id":66686625},{"atl":[[150,4]],"id":66686625},{"spn":76.04,"spf":"NaN","id":66686625},{"atb":[[1.01,45.28],[2.1,6.55],[2.08,13.07]],"id":70053016},{"atl":[[150,4]],"id":70053016},{"spn":76.05,"spf":"NaN","id":70053016},{"atb":[[1.01,45.28],[2.06,6.55],[2.04,11.96]],"id":69942666},{"atl":[[150,4]],"id":69942666},{"spn":76.03,"spf":"NaN","id":69942666},{"atb":[[2.06,12.08],[1.02,22.64],[2.08,6.55]],"id":53082422},{"atl":[[150,4]],"id":53082422}],"con":true,"img":false}]}
{"op":"mcm","clk":"11539128225","pt":1719475715285,"mc":[{"id":"1.230178328","rc":[{"atb":[[2.12,0]],"id":64812720},{"atb":[[2.12,0]],"id":70902603},{"atb":[[2.06,0]],"id":66686625},{"atb":[[2.08,0]],"id":70053016},{"atb":[[2.04,0]],"id":69942666},{"atb":[[2.06,0]],"id":53082422}],"con":true,"img":false}]}
{"op":"mcm","clk":"11539128234","pt":1719475715390,"mc":[{"id":"1.230178328","rc":[{"atb":[[2.16,13.32]],"id":64812720},{"atb":[[2.16,13.32]],"id":70902603},{"atb":[[2.1,9.49]],"id":66686625},{"atb":[[2.12,13.07]],"id":70053016},{"atb":[[2.08,11.96]],"id":69942666},{"atb":[[2.1,12.08]],"id":53082422}],"con":true,"img":false}]}
{"op":"mcm","clk":"11539132092","pt":1719475779357,"mc":[{"id":"1.230178328","rc":[{"spn":76.08,"spf":"NaN","id":64812720},{"spn":76.08,"spf":"NaN","id":70902603},{"spn":76.05,"spf":"NaN","id":66686625},{"spn":76.06,"spf":"NaN","id":70053016},{"atb":[[2.06,3.16]],"id":69942666},{"spn":76.04,"spf":"NaN","id":69942666},{"spn":2.1,"spf":1.0,"id":53082422}],"con":true,"img":false}]}
{"op":"mcm","clk":"11539132175","pt":1719475780690,"mc":[{"id":"1.230178328","rc":[{"atb":[[2.1,3.16]],"id":70053016}],"con":true,"img":false}]}
{"op":"mcm","clk":"11539132185","pt":1719475780794,"mc":[{"id":"1.230178328","rc":[{"atb":[[2.08,3.16]],"id":53082422}],"con":true,"img":false}]}
{"op":"mcm","clk":"11539132211","pt":1719475781099,"mc":[{"id":"1.230178328","rc":[{"atb":[[2.14,3.16]],"id":64812720}],"con":true,"img":false}]}
{"op":"mcm","clk":"11539132246","pt":1719475781568,"mc":[{"id":"1.230178328","rc":[{"atb":[[2.08,3.16]],"id":66686625}],"con":true,"img":false}]}
{"op":"mcm","clk":"11539132322","pt":1719475782897,"mc":[{"id":"1.230178328","rc":[{"atb":[[2.14,3.16]],"id":70902603}],"con":true,"img":false}]}
{"op":"mcm","clk":"11539132498","pt":1719475785781,"mc":[{"id":"1.230178328","rc":[{"atb":[[2.1,3.38]],"id":69942666}],"con":true,"img":false}]}
{"op":"mcm","clk":"11539132534","pt":1719475786399,"mc":[{"id":"1.230178328","rc":[{"atb":[[2.18,3.38]],"id":64812720},{"atb":[[2.14,3.38]],"id":70053016}],"con":true,"img":false}]}
{"op":"mcm","clk":"11539132562","pt":1719475786707,"mc":[{"id":"1.230178328","rc":[{"atb":[[2.12,3.38]],"id":66686625},{"atb":[[2.12,3.38]],"id":53082422}],"con":true,"img":false}]}
{"op":"mcm","clk":"11539132792","pt":1719475789702,"mc":[{"id":"1.230178328","rc":[{"atb":[[2.18,3.38]],"id":70902603}],"con":true,"img":false}]}
{"op":"mcm","clk":"11539134206","pt":1719475809296,"mc":[{"id":"1.230178328","rc":[{"atb":[[2.14,0]],"id":64812720},{"atb":[[2.14,0]],"id":70902603},{"atb":[[2.08,0]],"id":66686625},{"atb":[[2.1,0]],"id":70053016},{"atb":[[2.06,0]],"id":69942666},{"atb":[[2.08,0]],"id":53082422}],"con":true,"img":false}]}
{"op":"mcm","clk":"11539152890","pt":1719476111689,"mc":[{"id":"1.230178328","rc":[{"spn":76.09,"spf":"NaN","id":64812720},{"spn":76.09,"spf":"NaN","id":70902603},{"atb":[[2.12,6.55]],"id":66686625},{"spn":76.06,"spf":"NaN","id":66686625},{"spn":76.07,"spf":"NaN","id":70053016},{"spn":76.05,"spf":"NaN","id":69942666},{"spn":2.12,"spf":1.0,"id":53082422}],"con":true,"img":false}]}
{"op":"mcm","clk":"11539152899","pt":1719476111789,"mc":[{"id":"1.230178328","rc":[{"atb":[[2.18,6.55]],"id":64812720}],"con":true,"img":false}]}
{"op":"mcm","clk":"11539152908","pt":1719476111893,"mc":[{"id":"1.230178328","rc":[{"atb":[[2.14,6.55]],"id":70053016}],"con":true,"img":false}]}
{"op":"mcm","clk":"11539152917","pt":1719476111994,"mc":[{"id":"1.230178328","rc":[{"atb":[[2.1,6.55]],"id":69942666}],"con":true,"img":false}]}
{"op":"mcm","clk":"11539152952","pt":1719476112407,"mc":[{"id":"1.230178328","rc":[{"atb":[[2.18,6.55]],"id":70902603},{"atb":[[2.12,6.55]],"id":53082422}],"con":true,"img":false}]}
{"op":"mcm","clk":"11539341637","pt":1719479313834,"mc":[{"id":"1.230178328","rc":[{"atb":[[1.01,45.27],[2.18,6.54],[2.16,0]],"id":64812720},{"atb":[[1.03,15.09],[2.18,6.54],[2.16,0]],"id":70902603},{"atb":[[1.03,15.09],[2.12,6.54],[2.1,0]],"id":66686625},{"atb":[[1.01,45.27],[2.12,0],[2.14,6.54]],"id":70053016},{"atb":[[1.01,45.27],[2.1,6.54],[2.08,0]],"id":69942666},{"atb":[[1.02,22.63],[2.12,6.54],[2.1,0]],"id":53082422}],"con":true,"img":false}]}
{"op":"mcm","clk":"11539341646","pt":1719479313940,"mc":[{"id":"1.230178328","rc":[{"atb":[[2.2,13.32]],"id":64812720},{"atb":[[2.2,13.32]],"id":70902603},{"atb":[[2.14,9.49]],"id":66686625},{"atb":[[2.16,13.06]],"id":70053016},{"atb":[[2.12,11.96]],"id":69942666},{"atb":[[2.14,12.08]],"id":53082422}],"con":true,"img":false}]}
{"op":"mcm","clk":"11539345969","pt":1719479383437,"mc":[{"id":"1.230178328","rc":[{"spn":76.1,"spf":"NaN","id":64812720},{"atb":[[2.18,3.38]],"id":70902603},{"spn":76.1,"spf":"NaN","id":70902603},{"spn":76.07,"spf":"NaN","id":66686625},{"spn":76.08,"spf":"NaN","id":70053016},{"spn":76.06,"spf":"NaN","id":69942666},{"spn":2.14,"spf":1.0,"id":53082422}],"con":true,"img":false}]}
{"op":"mcm","clk":"11539345981","pt":1719479383749,"mc":[{"id":"1.230178328","rc":[{"atb":[[2.18,3.38]],"id":64812720}],"con":true,"img":false}]}
{"op":"mcm","clk":"11539345991","pt":1719479383958,"mc":[{"id":"1.230178328","rc":[{"atb":[[2.1,3.38]],"id":69942666}],"con":true,"img":false}]}
{"op":"mcm","clk":"11539345996","pt":1719479384012,"mc":[{"id":"1.230178328","rc":[{"atb":[[2.12,3.38]],"id":53082422}],"con":true,"img":false}]}
{"op":"mcm","clk":"11539346029","pt":1719479384637,"mc":[{"id":"1.230178328","rc":[{"atb":[[2.14,3.38]],"id":70053016}],"con":true,"img":false}]}
{"op":"mcm","clk":"11539346100","pt":1719479385611,"mc":[{"id":"1.230178328","rc":[{"atb":[[2.12,3.38]],"id":66686625}],"con":true,"img":false}]}
{"op":"mcm","clk":"11539347651","pt":1719479409687,"mc":[{"id":"1.230178328","rc":[{"atb":[[2.12,0]],"id":53082422}],"con":true,"img":false}]}
{"op":"mcm","clk":"11539347771","pt":1719479411382,"mc":[{"id":"1.230178328","rc":[{"atb":[[2.12,0]],"id":66686625}],"con":true,"img":false}]}
{"op":"mcm","clk":"11539347785","pt":1719479411591,"mc":[{"id":"1.230178328","rc":[{"atb":[[2.14,0]],"id":70053016}],"con":true,"img":false}]}
{"op":"mcm","clk":"11539347818","pt":1719479412205,"mc":[{"id":"1.230178328","rc":[{"atb":[[2.1,0]],"id":69942666}],"con":true,"img":false}]}
{"op":"mcm","clk":"11539347904","pt":1719479413501,"mc":[{"id":"1.230178328","rc":[{"atb":[[2.18,0]],"id":64812720}],"con":true,"img":false}]}
{"op":"mcm","clk":"11539348029","pt":1719479415573,"mc":[{"id":"1.230178328","rc":[{"atb":[[2.18,0]],"id":70902603}],"con":true,"img":false}]}
{"op":"mcm","clk":"11539348098","pt":1719479416823,"mc":[{"id":"1.230178328","rc":[{"atb":[[2.16,3.38]],"id":66686625}],"con":true,"img":false}]}
{"op":"mcm","clk":"11539348155","pt":1719479417818,"mc":[{"id":"1.230178328","rc":[{"atb":[[2.14,3.38]],"id":69942666}],"con":true,"img":false}]}
{"op":"mcm","clk":"11539348242","pt":1719479419317,"mc":[{"id":"1.230178328","rc":[{"atb":[[2.22,3.38]],"id":64812720}],"con":true,"img":false}]}
{"op":"mcm","clk":"11539348257","pt":1719479419626,"mc":[{"id":"1.230178328","rc":[{"atb":[[2.18,3.38]],"id":70053016}],"con":true,"img":false}]}
{"op":"mcm","clk":"11539348277","pt":1719479420088,"mc":[{"id":"1.230178328","rc":[{"atb":[[2.22,3.38]],"id":70902603}],"con":true,"img":false}]}
{"op":"mcm","clk":"11539348325","pt":1719479420914,"mc":[{"id":"1.230178328","rc":[{"atb":[[2.16,3.38]],"id":53082422}],"con":true,"img":false}]}
{"op":"mcm","clk":"11539367246","pt":1719479701900,"mc":[{"id":"1.230178328","rc":[{"spn":76.11,"spf":"NaN","id":64812720},{"spn":76.11,"spf":"NaN","id":70902603},{"spn":76.08,"spf":"NaN","id":66686625},{"spn":76.09,"spf":"NaN","id":70053016},{"spn":76.07,"spf":"NaN","id":69942666},{"atb":[[2.16,6.54]],"id":53082422},{"spn":2.16,"spf":1.0,"id":53082422}],"con":true,"img":false}]}
{"op":"mcm","clk":"11539367281","pt":1719479702312,"mc":[{"id":"1.230178328","rc":[{"atb":[[2.22,6.54]],"id":64812720}],"con":true,"img":false}]}
{"op":"mcm","clk":"11539367301","pt":1719479702468,"mc":[{"id":"1.230178328","rc":[{"atb":[[2.14,6.54]],"id":69942666}],"con":true,"img":false}]}
{"op":"mcm","clk":"11539367397","pt":1719479703497,"mc":[{"id":"1.230178328","rc":[{"atb":[[2.22,6.54]],"id":70902603}],"con":true,"img":false}]}
{"op":"mcm","clk":"11539367534","pt":1719479705190,"mc":[{"id":"1.230178328","rc":[{"atb":[[2.18,6.54]],"id":70053016}],"con":true,"img":false}]}
{"op":"mcm","clk":"11539367547","pt":1719479705395,"mc":[{"id":"1.230178328","rc":[{"atb":[[2.16,6.54]],"id":66686625}],"con":true,"img":false}]}
{"op":"mcm","clk":"11539545531","pt":1719482911985,"mc":[{"id":"1.230178328","rc":[{"atb":[[1.01,45.26],[2.22,6.54],[2.2,0]],"id":64812720},{"atb":[[1.03,15.08],[2.22,6.54],[2.2,0]],"id":70902603},{"atb":[[1.03,15.08],[2.16,6.54],[2.14,0]],"id":66686625},{"atb":[[1.01,45.26],[2.18,6.54],[2.16,0]],"id":70053016},{"atb":[[1.01,45.26],[2.12,0],[2.14,6.54]],"id":69942666},{"atb":[[1.02,22.63],[2.16,6.54],[2.14,0]],"id":53082422}],"con":true,"img":false}]}
{"op":"mcm","clk":"11539545535","pt":1719482912088,"mc":[{"id":"1.230178328","rc":[{"atb":[[2.24,13.32]],"id":64812720},{"atb":[[2.24,13.32]],"id":70902603},{"atb":[[2.18,9.48]],"id":66686625},{"atb":[[2.2,13.06]],"id":70053016},{"atb":[[2.16,11.95]],"id":69942666},{"atb":[[2.18,12.07]],"id":53082422}],"con":true,"img":false}]}
{"op":"mcm","clk":"11539547307","pt":1719482936428,"mc":[{"id":"1.230178328","rc":[{"atb":[[2.18,3.16]],"id":70053016}],"con":true,"img":false}]}
{"op":"mcm","clk":"11539547328","pt":1719482936900,"mc":[{"id":"1.230178328","rc":[{"atb":[[2.16,3.16]],"id":66686625},{"atb":[[2.16,3.16]],"id":53082422}],"con":true,"img":false}]}
{"op":"mcm","clk":"11539547342","pt":1719482937210,"mc":[{"id":"1.230178328","rc":[{"atb":[[2.2,3.38]],"id":66686625}],"con":true,"img":false}]}
{"op":"mcm","clk":"11539547346","pt":1719482937310,"mc":[{"id":"1.230178328","rc":[{"atb":[[2.22,3.16]],"id":70902603}],"con":true,"img":false}]}
{"op":"mcm","clk":"11539547358","pt":1719482937623,"mc":[{"id":"1.230178328","rc":[{"atb":[[2.22,3.16]],"id":64812720}],"con":true,"img":false}]}
{"op":"mcm","clk":"11539547378","pt":1719482938029,"mc":[{"id":"1.230178328","rc":[{"atb":[[2.14,3.16]],"id":69942666}],"con":true,"img":false}]}
{"op":"mcm","clk":"11539547393","pt":1719482938188,"mc":[{"id":"1.230178328","rc":[{"atb":[[2.2,3.38]],"id":53082422}],"con":true,"img":false}]}
{"op":"mcm","clk":"11539547420","pt":1719482938599,"mc":[{"id":"1.230178328","rc":[{"atb":[[2.26,3.38]],"id":64812720}],"con":true,"img":false}]}
{"op":"mcm","clk":"11539547438","pt":1719482938907,"mc":[{"id":"1.230178328","rc":[{"atb":[[2.26,3.38]],"id":70902603}],"con":true,"img":false}]}
{"op":"mcm","clk":"11539547452","pt":1719482939217,"mc":[{"id":"1.230178328","rc":[{"atb":[[2.22,3.38]],"id":70053016}],"con":true,"img":false}]}
{"op":"mcm","clk":"11539547469","pt":1719482939527,"mc":[{"id":"1.230178328","rc":[{"atb":[[2.18,3.38]],"id":69942666}],"con":true,"img":false}]}
{"op":"mcm","clk":"11539552539","pt":1719483018082,"mc":[{"id":"1.230178328","rc":[{"spn":76.13,"spf":"NaN","id":64812720},{"spn":76.13,"spf":"NaN","id":70902603},{"atb":[[2.16,0]],"id":66686625},{"spn":76.1,"spf":"NaN","id":66686625},{"spn":76.11,"spf":"NaN","id":70053016},{"spn":76.09,"spf":"NaN","id":69942666},{"spn":2.2,"spf":1.0,"id":53082422}],"con":true,"img":false}]}
{"op":"mcm","clk":"11539552557","pt":1719483018291,"mc":[{"id":"1.230178328","rc":[{"atb":[[2.22,0]],"id":70902603}],"con":true,"img":false}]}
{"op":"mcm","clk":"11539552586","pt":1719483018808,"mc":[{"id":"1.230178328","rc":[{"atb":[[2.22,0]],"id":64812720}],"con":true,"img":false}]}
{"op":"mcm","clk":"11539552596","pt":1719483018913,"mc":[{"id":"1.230178328","rc":[{"atb":[[2.26,6.54]],"id":70902603}],"con":true,"img":false}]}
{"op":"mcm","clk":"11539552624","pt":1719483019287,"mc":[{"id":"1.230178328","rc":[{"atb":[[2.16,0]],"id":53082422}],"con":true,"img":false}]}
{"op":"mcm","clk":"11539552632","pt":1719483019385,"mc":[{"id":"1.230178328","rc":[{"atb":[[2.14,0]],"id":69942666}],"con":true,"img":false}]}
{"op":"mcm","clk":"11539552662","pt":1719483019802,"mc":[{"id":"1.230178328","rc":[{"atb":[[2.18,0]],"id":70053016}],"con":true,"img":false}]}
{"op":"mcm","clk":"11539552709","pt":1719483020281,"mc":[{"id":"1.230178328","rc":[{"atb":[[2.2,6.54]],"id":66686625}],"con":true,"img":false}]}
{"op":"mcm","clk":"11539552894","pt":1719483022294,"mc":[{"id":"1.230178328","rc":[{"atb":[[2.18,6.54]],"id":69942666}],"con":true,"img":false}]}
{"op":"mcm","clk":"11539552912","pt":1719483022604,"mc":[{"id":"1.230178328","rc":[{"atb":[[2.26,6.54]],"id":64812720}],"con":true,"img":false}]}
{"op":"mcm","clk":"11539552940","pt":1719483023021,"mc":[{"id":"1.230178328","rc":[{"atb":[[2.2,6.54]],"id":53082422}],"con":true,"img":false}]}
{"op":"mcm","clk":"11539553142","pt":1719483025717,"mc":[{"id":"1.230178328","rc":[{"atb":[[2.22,6.54]],"id":70053016}],"con":true,"img":false}]}
{"op":"mcm","clk":"11539783777","pt":1719486147790,"mc":[{"id":"1.230178328","rc":[{"atb":[[2.24,13.32],[1.01,45.27],[2.26,6.54]],"id":64812720},{"atb":[[2.24,13.32],[1.03,15.09],[2.26,6.54]],"id":70902603},{"atb":[[1.03,15.09],[2.18,9.49],[2.2,6.54]],"id":66686625},{"atb":[[2.24,2],[1.01,45.27],[2.22,6.54],[2.2,13.06]],"id":70053016},{"spn":76.12,"spf":"NaN","id":70053016},{"atb":[[1.01,45.27],[2.18,6.54],[2.16,11.96]],"id":69942666},{"atb":[[1.02,22.63],[2.18,12.08],[2.2,6.54]],"id":53082422}],"con":true,"img":false}]}
{"op":"mcm","clk":"11539817539","pt":1719486508531,"mc":[{"id":"1.230178328","rc":[{"atb":[[2.24,0]],"id":64812720},{"atb":[[2.24,0]],"id":70902603},{"atb":[[2.18,0]],"id":66686625},{"atb":[[2.2,0]],"id":70053016},{"atb":[[2.16,0]],"id":69942666},{"atb":[[2.18,0]],"id":53082422}],"con":true,"img":false}]}
{"op":"mcm","clk":"11539817551","pt":1719486508634,"mc":[{"id":"1.230178328","rc":[{"atb":[[2.28,13.32]],"id":64812720},{"atb":[[2.28,13.32]],"id":70902603},{"atb":[[2.22,9.49]],"id":66686625},{"atb":[[2.24,15.06]],"id":70053016},{"atb":[[2.2,11.96]],"id":69942666},{"atb":[[2.22,12.08]],"id":53082422}],"con":true,"img":false}]}
{"op":"mcm","clk":"11539818025","pt":1719486514139,"mc":[{"id":"1.230178328","rc":[{"atb":[[2.2,3.38]],"id":53082422}],"con":true,"img":false}]}
{"op":"mcm","clk":"11539818037","pt":1719486514244,"mc":[{"id":"1.230178328","rc":[{"atb":[[2.26,3.38]],"id":64812720}],"con":true,"img":false}]}
{"op":"mcm","clk":"11539818047","pt":1719486514344,"mc":[{"id":"1.230178328","rc":[{"atb":[[2.26,3.38]],"id":70902603}],"con":true,"img":false}]}
{"op":"mcm","clk":"11539818134","pt":1719486515427,"mc":[{"id":"1.230178328","rc":[{"atb":[[2.18,3.38]],"id":69942666}],"con":true,"img":false}]}
{"op":"mcm","clk":"11539818195","pt":1719486516150,"mc":[{"id":"1.230178328","rc":[{"atb":[[2.3,3.16]],"id":64812720}],"con":true,"img":false}]}
{"op":"mcm","clk":"11539818239","pt":1719486516566,"mc":[{"id":"1.230178328","rc":[{"atb":[[2.3,3.16]],"id":70902603}],"con":true,"img":false}]}
{"op":"mcm","clk":"11539818264","pt":1719486516776,"mc":[{"id":"1.230178328","rc":[{"atb":[[2.2,3.38]],"id":66686625},{"atb":[[2.22,3.16]],"id":69942666}],"con":true,"img":false}]}
{"op":"mcm","clk":"11539818295","pt":1719486517045,"mc":[{"id":"1.230178328","rc":[{"atb":[[2.22,3.38]],"id":70053016}],"con":true,"img":false}]}
{"op":"mcm","clk":"11539818317","pt":1719486517261,"mc":[{"id":"1.230178328","rc":[{"atb":[[2.24,3.16]],"id":53082422}],"con":true,"img":false}]}
{"op":"mcm","clk":"11539818348","pt":1719486517576,"mc":[{"id":"1.230178328","rc":[{"atb":[[2.24,3.16]],"id":66686625}],"con":true,"img":false}]}
{"op":"mcm","clk":"11539818431","pt":1719486518251,"mc":[{"id":"1.230178328","rc":[{"atb":[[2.26,3.16]],"id":70053016}],"con":true,"img":false}]}
{"op":"mcm","clk":"11539824009","pt":1719486581423,"mc":[{"id":"1.230178328","rc":[{"spn":76.15,"spf":"NaN","id":64812720},{"spn":76.15,"spf":"NaN","id":70902603},{"spn":76.12,"spf":"NaN","id":66686625},{"atb":[[2.22,0]],"id":70053016},{"spn":76.13,"spf":"NaN","id":70053016},{"spn":76.11,"spf":"NaN","id":69942666},{"spn":2.24,"spf":1.0,"id":53082422}],"con":true,"img":false}]}
{"op":"mcm","clk":"11539824056","pt":1719486581991,"mc":[{"id":"1.230178328","rc":[{"atb":[[2.26,0]],"id":70902603},{"atb":[[2.2,0]],"id":66686625}],"con":true,"img":false}]}
{"op":"mcm","clk":"11539824075","pt":1719486582300,"mc":[{"id":"1.230178328","rc":[{"atb":[[2.26,0]],"id":64812720}],"con":true,"img":false}]}
{"op":"mcm","clk":"11539824138","pt":1719486583135,"mc":[{"id":"1.230178328","rc":[{"atb":[[2.2,0]],"id":53082422}],"con":true,"img":false}]}
{"op":"mcm","clk":"11539824144","pt":1719486583238,"mc":[{"id":"1.230178328","rc":[{"atb":[[2.18,0]],"id":69942666}],"con":true,"img":false}]}
{"op":"mcm","clk":"11539825259","pt":1719486598350,"mc":[{"id":"1.230178328","rc":[{"atb":[[2.3,6.54]],"id":70902603}],"con":true,"img":false}]}
{"op":"mcm","clk":"11539825305","pt":1719486598916,"mc":[{"id":"1.230178328","rc":[{"atb":[[2.26,6.54]],"id":70053016}],"con":true,"img":false}]}
{"op":"mcm","clk":"11539825325","pt":1719486599229,"mc":[{"id":"1.230178328","rc":[{"atb":[[2.3,6.54]],"id":64812720}],"con":true,"img":false}]}
{"op":"mcm","clk":"11539825419","pt":1719486600427,"mc":[{"id":"1.230178328","rc":[{"atb":[[2.24,6.54]],"id":53082422}],"con":true,"img":false}]}
{"op":"mcm","clk":"11539825523","pt":1719486601630,"mc":[{"id":"1.230178328","rc":[{"atb":[[2.22,6.54]],"id":69942666}],"con":true,"img":false}]}
{"op":"mcm","clk":"11539825538","pt":1719486601837,"mc":[{"id":"1.230178328","rc":[{"atb":[[2.24,6.54]],"id":66686625}],"con":true,"img":false}]}
{"op":"mcm","clk":"11539840742","pt":1719486808549,"mc":[{"id":"1.230178328","rc":[{"atb":[[2.28,0]],"id":64812720},{"atb":[[2.28,0]],"id":70902603},{"atb":[[2.22,0]],"id":66686625},{"atb":[[2.24,2]],"id":70053016},{"atb":[[2.2,0]],"id":69942666},{"atb":[[2.22,0]],"id":53082422}],"con":true,"img":false}]}
{"op":"mcm","clk":"11539840748","pt":1719486808652,"mc":[{"id":"1.230178328","rc":[{"atb":[[2.32,13.32]],"id":64812720},{"atb":[[2.32,13.32]],"id":70902603},{"atb":[[2.26,9.49]],"id":66686625},{"atb":[[2.28,13.06]],"id":70053016},{"atb":[[2.24,11.96]],"id":69942666},{"atb":[[2.26,12.08]],"id":53082422}],"con":true,"img":false}]}
{"op":"mcm","clk":"11539841361","pt":1719486818667,"mc":[{"id":"1.230178328","rc":[{"atb":[[2.3,3.38]],"id":64812720},{"atb":[[2.3,3.38]],"id":70902603},{"atb":[[2.24,3.38]],"id":66686625},{"atb":[[2.26,3.38]],"id":70053016},{"atb":[[2.22,3.38]],"id":69942666},{"atb":[[2.24,3.38]],"id":53082422}],"con":true,"img":false}]}
{"op":"mcm","clk":"11539842806","pt":1719486840556,"mc":[{"id":"1.230178328","rc":[{"atb":[[2.3,0]],"id":64812720},{"atb":[[2.3,0]],"id":70902603},{"atb":[[2.24,0]],"id":66686625},{"atb":[[2.26,0]],"id":70053016},{"atb":[[2.22,0]],"id":69942666},{"atb":[[2.24,0]],"id":53082422}],"con":true,"img":false}]}
{"op":"mcm","clk":"11539848185","pt":1719486917469,"mc":[{"id":"1.230178328","rc":[{"spn":76.16,"spf":"NaN","id":64812720},{"spn":76.16,"spf":"NaN","id":70902603},{"spn":76.13,"spf":"NaN","id":66686625},{"atb":[[2.3,3.38]],"id":70053016},{"spn":76.15,"spf":"NaN","id":70053016},{"spn":76.12,"spf":"NaN","id":69942666},{"spn":2.26,"spf":1.0,"id":53082422}],"con":true,"img":false}]}
{"op":"mcm","clk":"11539848231","pt":1719486917835,"mc":[{"id":"1.230178328","rc":[{"atb":[[2.34,3.38]],"id":70902603}],"con":true,"img":false}]}
{"op":"mcm","clk":"11539848264","pt":1719486918243,"mc":[{"id":"1.230178328","rc":[{"atb":[[2.28,3.38]],"id":66686625}],"con":true,"img":false}]}
{"op":"mcm","clk":"11539848282","pt":1719486918454,"mc":[{"id":"1.230178328","rc":[{"atb":[[2.34,3.38]],"id":64812720}],"con":true,"img":false}]}
{"op":"mcm","clk":"11539848312","pt":1719486918768,"mc":[{"id":"1.230178328","rc":[{"atb":[[2.28,3.38]],"id":53082422}],"con":true,"img":false}]}
{"op":"mcm","clk":"11539848320","pt":1719486918863,"mc":[{"id":"1.230178328","rc":[{"atb":[[2.26,3.38]],"id":69942666}],"con":true,"img":false}]}
{"op":"mcm","clk":"11539850000","pt":1719486940794,"mc":[{"id":"1.230178328","rc":[{"atb":[[2.28,6.54]],"id":53082422}],"con":true,"img":false}]}
{"op":"mcm","clk":"11539850020","pt":1719486941099,"mc":[{"id":"1.230178328","rc":[{"atb":[[2.3,6.54]],"id":70053016}],"con":true,"img":false}]}
{"op":"mcm","clk":"11539850033","pt":1719486941264,"mc":[{"id":"1.230178328","rc":[{"atb":[[2.34,6.54]],"id":64812720}],"con":true,"img":false}]}
{"op":"mcm","clk":"11539850047","pt":1719486941468,"mc":[{"id":"1.230178328","rc":[{"atb":[[2.34,6.54]],"id":70902603}],"con":true,"img":false}]}
{"op":"mcm","clk":"11539850059","pt":1719486941672,"mc":[{"id":"1.230178328","rc":[{"atb":[[2.26,6.54]],"id":69942666}],"con":true,"img":false}]}
{"op":"mcm","clk":"11539850073","pt":1719486941883,"mc":[{"id":"1.230178328","rc":[{"atb":[[2.28,6.54]],"id":66686625}],"con":true,"img":false}]}
{"op":"mcm","clk":"11540014640","pt":1719489001717,"mc":[{"id":"1.230178328","rc":[{"atl":[[270,2]],"id":64812720},{"spn":76.17,"spf":"NaN","id":64812720},{"atl":[[560,2]],"id":70902603},{"spn":76.17,"spf":"NaN","id":70902603},{"atb":[[1.16,150]],"id":66686625},{"atl":[[550,2]],"id":66686625},{"spn":76.14,"spf":"NaN","id":66686625},{"atb":[[1.16,150]],"id":70053016},{"atl":[[390,2]],"id":70053016},{"atl":[[500,2]],"id":69942666},{"spn":76.13,"spf":"NaN","id":69942666},{"atl":[[370,2]],"id":53082422},{"spn":2.28,"spf":1.0,"id":53082422}],"con":true,"img":false}]}
{"op":"mcm","clk":"11540014656","pt":1719489001812,"mc":[{"id":"1.230178328","rc":[{"atb":[[1.16,150]],"id":64812720},{"atb":[[1.16,150]],"id":70902603},{"atb":[[1.16,150]],"id":69942666},{"atb":[[1.16,150]],"id":53082422}],"con":true,"img":false}]}
{"op":"mcm","clk":"11540072828","pt":1719489720592,"mc":[{"id":"1.230178328","rc":[{"atb":[[2.34,6.54]],"id":64812720},{"atl":[[32,8],[55,12]],"id":64812720},{"spn":17.17,"spf":"NaN","id":64812720},{"atb":[[2.34,6.54]],"id":70902603},{"atb":[[2.28,6.54]],"id":66686625},{"atl":[[40,12],[23,8]],"id":66686625},{"spn":12.64,"spf":"NaN","id":66686625},{"atb":[[2.3,6.54]],"id":70053016},{"atb":[[2.26,6.54]],"id":69942666},{"atb":[[2.28,6.54]],"id":53082422},{"atl":[[46,12],[27,8]],"id":53082422}],"con":true,"img":false}]}
{"op":"mcm","clk":"11540136438","pt":1719490401519,"mc":[{"id":"1.230178328","rc":[{"atb":[[2.32,0]],"id":64812720},{"atb":[[2.32,0]],"id":70902603},{"atb":[[2.26,0]],"id":66686625},{"atb":[[2.28,0]],"id":70053016},{"atb":[[2.24,0]],"id":69942666},{"atb":[[2.26,0]],"id":53082422}],"con":true,"img":false}]}
{"op":"mcm","clk":"11540136445","pt":1719490401618,"mc":[{"id":"1.230178328","rc":[{"atb":[[2.36,13.32]],"id":64812720},{"atb":[[2.36,13.32]],"id":70902603},{"atb":[[2.3,9.49]],"id":66686625},{"atb":[[2.32,13.06]],"id":70053016},{"atb":[[2.28,11.96]],"id":69942666},{"atb":[[2.3,12.08]],"id":53082422}],"con":true,"img":false}]}
{"op":"mcm","clk":"11540139708","pt":1719490433765,"mc":[{"id":"1.230178328","rc":[{"atb":[[2.3,3.16]],"id":70053016}],"con":true,"img":false}]}
{"op":"mcm","clk":"11540139761","pt":1719490434280,"mc":[{"id":"1.230178328","rc":[{"atb":[[2.28,3.16]],"id":53082422}],"con":true,"img":false}]}
{"op":"mcm","clk":"11540139771","pt":1719490434486,"mc":[{"id":"1.230178328","rc":[{"atb":[[2.28,3.16]],"id":66686625}],"con":true,"img":false}]}
{"op":"mcm","clk":"11540139804","pt":1719490435006,"mc":[{"id":"1.230178328","rc":[{"atb":[[2.34,3.16]],"id":70902603}],"con":true,"img":false}]}
{"op":"mcm","clk":"11540139858","pt":1719490435473,"mc":[{"id":"1.230178328","rc":[{"atb":[[2.26,3.16]],"id":69942666}],"con":true,"img":false}]}
{"op":"mcm","clk":"11540139988","pt":1719490436663,"mc":[{"id":"1.230178328","rc":[{"atb":[[2.34,3.16]],"id":64812720}],"con":true,"img":false}]}
{"op":"mcm","clk":"11540141092","pt":1719490447707,"mc":[{"id":"1.230178328","rc":[{"atb":[[2.34,3.38]],"id":70053016}],"con":true,"img":false}]}
{"op":"mcm","clk":"11540141160","pt":1719490448278,"mc":[{"id":"1.230178328","rc":[{"atb":[[2.32,3.38]],"id":66686625}],"con":true,"img":false}]}
{"op":"mcm","clk":"11540141247","pt":1719490449002,"mc":[{"id":"1.230178328","rc":[{"atb":[[2.38,3.38]],"id":70902603}],"con":true,"img":false}]}
{"op":"mcm","clk":"11540141256","pt":1719490449105,"mc":[{"id":"1.230178328","rc":[{"atb":[[2.32,3.38]],"id":53082422}],"con":true,"img":false}]}
{"op":"mcm","clk":"11540141276","pt":1719490449265,"mc":[{"id":"1.230178328","rc":[{"atb":[[2.3,3.38]],"id":69942666}],"con":true,"img":false}]}
{"op":"mcm","clk":"11540141510","pt":1719490451392,"mc":[{"id":"1.230178328","rc":[{"atb":[[2.38,3.38]],"id":64812720}],"con":true,"img":false}]}
{"op":"mcm","clk":"11540142952","pt":1719490464491,"mc":[{"id":"1.230178328","rc":[{"spn":17.19,"spf":"NaN","id":64812720},{"spn":76.19,"spf":"NaN","id":70902603},{"spn":12.66,"spf":"NaN","id":66686625},{"spn":76.17,"spf":"NaN","id":70053016},{"spn":76.15,"spf":"NaN","id":69942666},{"atb":[[2.28,0]],"id":53082422},{"spn":2.32,"spf":1.0,"id":53082422}],"con":true,"img":false}]}
{"op":"mcm","clk":"11540143033","pt":1719490465212,"mc":[{"id":"1.230178328","rc":[{"atb":[[2.28,0]],"id":66686625}],"con":true,"img":false}]}
{"op":"mcm","clk":"11540143063","pt":1719490465521,"mc":[{"id":"1.230178328","rc":[{"atb":[[2.34,0]],"id":64812720}],"con":true,"img":false}]}
{"op":"mcm","clk":"11540143110","pt":1719490465982,"mc":[{"id":"1.230178328","rc":[{"atb":[[2.3,0]],"id":70053016}],"con":true,"img":false}]}
{"op":"mcm","clk":"11540143128","pt":1719490466189,"mc":[{"id":"1.230178328","rc":[{"atb":[[2.26,0]],"id":69942666}],"con":true,"img":false}]}
{"op":"mcm","clk":"11540143237","pt":1719490467429,"mc":[{"id":"1.230178328","rc":[{"atb":[[2.34,0]],"id":70902603}],"con":true,"img":false}]}
{"op":"mcm","clk":"11540145068","pt":1719490485107,"mc":[{"id":"1.230178328","rc":[{"atb":[[2.38,6.54]],"id":64812720}],"con":true,"img":false}]}
{"op":"mcm","clk":"11540145132","pt":1719490485833,"mc":[{"id":"1.230178328","rc":[{"atb":[[2.3,6.54]],"id":69942666}],"con":true,"img":false}]}
{"op":"mcm","clk":"11540145213","pt":1719490486606,"mc":[{"id":"1.230178328","rc":[{"atb":[[2.32,6.54]],"id":66686625}],"con":true,"img":false}]}
{"op":"mcm","clk":"11540145420","pt":1719490488621,"mc":[{"id":"1.230178328","rc":[{"atb":[[2.32,6.54]],"id":53082422}],"con":true,"img":false}]}
{"op":"mcm","clk":"11540145498","pt":1719490489351,"mc":[{"id":"1.230178328","rc":[{"atb":[[2.34,6.54]],"id":70053016}],"con":true,"img":false}]}
{"op":"mcm","clk":"11540145643","pt":1719490490857,"mc":[{"id":"1.230178328","rc":[{"atb":[[2.38,6.54]],"id":70902603}],"con":true,"img":false}]}
{"op":"mcm","clk":"11540164773","pt":1719490698921,"mc":[{"id":"1.230178328","rc":[{"atb":[[2.3,0]],"id":66686625},{"atb":[[2.32,0]],"id":70053016},{"atb":[[2.28,0]],"id":69942666},{"atb":[[2.3,0]],"id":53082422}],"con":true,"img":false}]}
{"op":"mcm","clk":"11540164783","pt":1719490699022,"mc":[{"id":"1.230178328","rc":[{"atb":[[2.34,9.49]],"id":66686625},{"atb":[[2.36,13.06]],"id":70053016},{"atb":[[2.32,11.96]],"id":69942666},{"atb":[[2.34,12.08]],"id":53082422}],"con":true,"img":false}]}
{"op":"mcm","clk":"11540168093","pt":1719490740859,"mc":[{"id":"1.230178328","rc":[{"atb":[[2.32,3.38]],"id":53082422}],"con":true,"img":false}]}
{"op":"mcm","clk":"11540168114","pt":1719490741065,"mc":[{"id":"1.230178328","rc":[{"atb":[[2.3,3.38]],"id":69942666}],"con":true,"img":false}]}
{"op":"mcm","clk":"11540168130","pt":1719490741273,"mc":[{"id":"1.230178328","rc":[{"atb":[[2.32,3.38]],"id":66686625}],"con":true,"img":false}]}
{"op":"mcm","clk":"11540168156","pt":1719490741538,"mc":[{"id":"1.230178328","rc":[{"atb":[[2.34,3.38]],"id":70053016}],"con":true,"img":false}]}
{"op":"mcm","clk":"11540168195","pt":1719490742053,"mc":[{"id":"1.230178328","rc":[{"atb":[[2.34,3.16]],"id":69942666}],"con":true,"img":false}]}
{"op":"mcm","clk":"11540168233","pt":1719490742571,"mc":[{"id":"1.230178328","rc":[{"atb":[[2.36,3.16]],"id":53082422}],"con":true,"img":false}]}
{"op":"mcm","clk":"11540168322","pt":1719490743866,"mc":[{"id":"1.230178328","rc":[{"atb":[[2.36,3.16]],"id":66686625}],"con":true,"img":false}]}
{"op":"mcm","clk":"11540168493","pt":1719490745980,"mc":[{"id":"1.230178328","rc":[{"atb":[[2.38,3.16]],"id":70053016}],"con":true,"img":false}]}
{"op":"mcm","clk":"11540170572","pt":1719490775882,"mc":[{"id":"1.230178328","rc":[{"spn":12.68,"spf":"NaN","id":66686625},{"spn":76.19,"spf":"NaN","id":70053016},{"atb":[[2.3,0]],"id":69942666},{"spn":76.17,"spf":"NaN","id":69942666},{"spn":2.36,"spf":1.0,"id":53082422}],"con":true,"img":false}]}
{"op":"mcm","clk":"11540170582","pt":1719490775985,"mc":[{"id":"1.230178328","rc":[{"atb":[[2.32,0]],"id":53082422}],"con":true,"img":false}]}
{"op":"mcm","clk":"11540170594","pt":1719490776289,"mc":[{"id":"1.230178328","rc":[{"atb":[[2.34,0]],"id":70053016}],"con":true,"img":false}]}
{"op":"mcm","clk":"11540170681","pt":1719490777887,"mc":[{"id":"1.230178328","rc":[{"atb":[[2.32,0]],"id":66686625}],"con":true,"img":false}]}
{"op":"mcm","clk":"11540172897","pt":1719490806996,"mc":[{"id":"1.230178328","rc":[{"atb":[[2.36,6.54]],"id":53082422}],"con":true,"img":false}]}
{"op":"mcm","clk":"11540173032","pt":1719490808617,"mc":[{"id":"1.230178328","rc":[{"atb":[[2.36,6.54]],"id":66686625}],"con":true,"img":false}]}
{"op":"mcm","clk":"11540173044","pt":1719490808798,"mc":[{"id":"1.230178328","rc":[{"atb":[[2.34,6.54]],"id":69942666}],"con":true,"img":false}]}
{"op":"mcm","clk":"11540173099","pt":1719490809722,"mc":[{"id":"1.230178328","rc":[{"atb":[[2.38,6.54]],"id":70053016}],"con":true,"img":false}]}
{"op":"mcm","clk":"11540345631","pt":1719493321992,"mc":[{"id":"1.230178328","rc":[{"atb":[[2.36,13.33],[1.01,45.32],[5,1],[2.38,6.54]],"id":64812720},{"atl":[[1000,0.16]],"id":64812720},{"spn":18.5,"spf":"NaN","id":64812720},{"atb":[[2.36,13.33],[1.03,15.1],[5,1],[2.38,6.54]],"id":70902603},{"atl":[[1000,0.16]],"id":70902603},{"spn":77.5,"spf":"NaN","id":70902603},{"atb":[[2.36,6.54],[1.03,15.1],[5,1],[2.34,9.5]],"id":66686625},{"atl":[[1000,0.16]],"id":66686625},{"spn":14.0,"spf":"NaN","id":66686625},{"atb":[[2.36,13.08],[1.01,45.32],[3.95,1],[2.38,6.54]],"id":70053016},{"atl":[[990,0.16]],"id":70053016},{"spn":76.97,"spf":"NaN","id":70053016},{"atb":[[1.01,45.32],[2.32,11.97],[5,1],[2.34,6.54]],"id":69942666},{"atl":[[1000,0.16]],"id":69942666},{"spn":77.5,"spf":"NaN","id":69942666},{"atb":[[2.36,6.54],[1.02,22.66],[3.7,1],[2.34,12.09]],"id":53082422},{"atl":[[990,0.16]],"id":53082422},{"spn":3.7,"spf":1.0,"id":53082422}],"con":true,"img":false}]}
{"op":"mcm","clk":"11540397935","pt":1719493997331,"mc":[{"id":"1.230178328","rc":[{"atb":[[2.32,0]],"id":69942666}],"con":true,"img":false}]}
{"op":"mcm","clk":"11540397940","pt":1719493997433,"mc":[{"id":"1.230178328","rc":[{"atb":[[2.36,11.97]],"id":69942666}],"con":true,"img":false}]}
{"op":"mcm","clk":"11540399296","pt":1719494013724,"mc":[{"id":"1.230178328","rc":[{"atb":[[2.34,3.16]],"id":69942666}],"con":true,"img":false}]}
{"op":"mcm","clk":"11540399519","pt":1719494016253,"mc":[{"id":"1.230178328","rc":[{"atb":[[2.38,3.38]],"id":69942666}],"con":true,"img":false}]}
{"op":"mcm","clk":"11540401416","pt":1719494038786,"mc":[{"id":"1.230178328","rc":[{"atb":[[2.34,0]],"id":69942666}],"con":true,"img":false}]}
{"op":"mcm","clk":"11540402326","pt":1719494048987,"mc":[{"id":"1.230178328","rc":[{"atb":[[2.38,6.54]],"id":69942666}],"con":true,"img":false}]}
{"op":"mcm","clk":"11540418502","pt":1719494286305,"mc":[{"id":"1.230178328","rc":[{"atb":[[1.51,196.08]],"id":64812720},{"atb":[[1.51,196.08]],"id":66686625},{"atb":[[1.51,196.08]],"id":70053016},{"atb":[[1.51,196.08]],"id":53082422}],"con":true,"img":false}]}
{"op":"mcm","clk":"11540418506","pt":1719494286406,"mc":[{"id":"1.230178328","rc":[{"atb":[[1.51,196.08]],"id":70902603},{"atb":[[1.51,196.08]],"id":69942666}],"con":true,"img":false}]}
{"op":"mcm","clk":"11540536913","pt":1719495649194,"mc":[{"id":"1.230178328","rc":[{"atb":[[3.3,6]],"id":64812720},{"atb":[[3.55,6]],"id":70902603},{"atb":[[3.1,6]],"id":66686625},{"atb":[[4.1,6]],"id":70053016},{"spn":77.05,"spf":"NaN","id":70053016},{"atb":[[4.2,6]],"id":69942666},{"atb":[[2.08,6]],"id":53082422}],"con":true,"img":false}]}
{"op":"mcm","clk":"11540537146","pt":1719495651175,"mc":[{"id":"1.230178328","rc":[{"atb":[[2.38,3.38]],"id":64812720},{"atb":[[2.38,3.38]],"id":70902603},{"atb":[[2.36,3.38]],"id":66686625},{"atb":[[2.38,3.38]],"id":70053016},{"atb":[[2.38,3.38]],"id":69942666}],"con":true,"img":false}]}
{"op":"mcm","clk":"11540537478","pt":1719495654469,"mc":[{"id":"1.230178328","rc":[{"atb":[[2.12,89.29]],"id":64812720},{"atb":[[2.12,89.29]],"id":70902603},{"atb":[[2.12,89.29]],"id":69942666}],"con":true,"img":false}]}
{"op":"mcm","clk":"11540539405","pt":1719495674501,"mc":[{"id":"1.230178328","rc":[{"atb":[[2.38,0]],"id":64812720},{"atb":[[2.38,0]],"id":70902603},{"atb":[[2.36,0]],"id":66686625},{"atb":[[2.38,0]],"id":70053016},{"atb":[[2.38,0]],"id":69942666}],"con":true,"img":false}]}
{"op":"mcm","clk":"11540611101","pt":1719496428701,"mc":[{"id":"1.230178328","rc":[{"atb":[[5,2]],"id":64812720},{"atb":[[5,2]],"id":70902603},{"atb":[[4,1]],"id":66686625},{"atb":[[4.6,1]],"id":70053016},{"spn":77.3,"spf":"NaN","id":70053016},{"atb":[[5.5,1]],"id":69942666},{"spn":77.75,"spf":"NaN","id":69942666},{"atb":[[3.2,1]],"id":53082422}],"con":true,"img":false}]}
{"op":"mcm","clk":"11540612671","pt":1719496444789,"mc":[{"id":"1.230178328","rc":[{"atb":[[2.12,89.29]],"id":66686625}],"con":true,"img":false}]}
{"op":"mcm","clk":"11540683354","pt":1719497282514,"mc":[{"id":"1.230178328","marketDefinition":{"bspMarket":true,"turnInPlayEnabled":false,"persistenceEnabled":false,"marketBaseRate":5.0,"eventId":"33376062","eventTypeId":"4339","numberOfWinners":1,"bettingType":"ODDS","marketType":"WIN","marketTime":"2024-06-27T17:02:00.000Z","suspendTime":"2024-06-27T17:02:00.000Z","bspReconciled":false,"complete":true,"inPlay":false,"crossMatching":true,"runnersVoidable":false,"numberOfActiveRunners":6,"betDelay":0,"status":"OPEN","runners":[{"status":"ACTIVE","sortPriority":1,"id":53082422,"name":"1. Betsys Minnie"},{"status":"ACTIVE","sortPriority":2,"id":70053016,"name":"2. Tuxedo Twlight"},{"status":"ACTIVE","sortPriority":3,"id":66686625,"name":"3. Ballymac Addie"},{"status":"ACTIVE","sortPriority":4,"id":64812720,"name":"4. Hes A Rebel"},{"status":"ACTIVE","sortPriority":5,"id":70902603,"name":"5. Follow Suit"},{"status":"ACTIVE","sortPriority":6,"id":69942666,"name":"6. Pukka Poppy"}],"regulators":["MR_INT"],"venue":"Kinsley","countryCode":"GB","discountAllowed":true,"timezone":"Europe/London","openDate":"2024-06-27T13:36:00.000Z","version":5994643773,"name":"A4 462m","eventName":"Kinsley 27th Jun"},"rc":[{"atb":[[2.36,13.33],[1.01,45.3],[5,2],[1.16,150],[2.12,89.29],[1.51,196.08],[3.3,6]],"id":64812720},{"atl":[[32,8],[270,2],[150,4],[55,12],[1000,0.16]],"id":64812720},{"spn":18.5,"spf":"NaN","id":64812720},{"atb":[[2.36,13.33],[5,2],[1.16,150],[1.03,15.1],[2.12,89.29],[3.55,6],[1.51,196.08]],"id":70902603},{"atl":[[560,2],[150,4],[1000,0.16]],"id":70902603},{"spn":77.5,"spf":"NaN","id":70902603},{"atb":[[4,1],[5,1],[1.16,150],[1.03,15.1],[3.1,6],[2.12,89.29],[1.51,196.08],[2.34,9.49]],"id":66686625},{"atl":[[550,2],[150,4],[40,12],[23,8],[1000,0.16]],"id":66686625},{"spn":14.0,"spf":"NaN","id":66686625},{"atb":[[2.36,13.07],[2.24,2],[1.01,45.3],[4.6,1],[1.16,150],[3.95,1],[4.1,6],[1.51,196.08]],"id":70053016},{"atl":[[150,4],[390,2],[990,0.16]],"id":70053016},{"spn":77.3,"spf":"NaN","id":70053016},{"atb":[[2.36,11.97],[1.01,45.3],[5,1],[1.16,150],[5.5,1],[2.12,89.29],[1.51,196.08],[4.2,6]],"id":69942666},{"atl":[[150,4],[500,2],[1000,0.16]],"id":69942666},{"spn":77.75,"spf":"NaN","id":69942666},{"spl":[[1.01,1]],"id":53082422},{"atb":[[2.36,6.54],[3.2,1],[1.16,150],[3.7,1],[1.02,22.65],[1.51,196.08],[2.34,12.08],[2.08,6]],"id":53082422},{"atl":[[150,4],[46,12],[370,2],[27,8],[30,0.6],[990,0.16]],"id":53082422},{"spn":3.7,"spf":1.0,"id":53082422}],"con":true,"img":true}]}
{"op":"mcm","clk":"11540697747","pt":1719497397361,"mc":[{"id":"1.230178328","rc":[{"atb":[[2.36,13.33],[1.01,45.3]],"id":64812720},{"atb":[[2.36,13.33],[1.03,15.1]],"id":70902603},{"atb":[[1.03,15.1],[2.34,9.49]],"id":66686625},{"atb":[[2.36,13.07],[1.01,45.3],[2.12,89.29]],"id":70053016},{"atb":[[2.36,11.97],[1.01,45.3]],"id":69942666},{"atb":[[2.36,6.54],[1.02,22.65],[2.34,12.08]],"id":53082422}],"con":true,"img":false}]}
{"op":"mcm","clk":"11540735705","pt":1719497823302,"mc":[{"id":"1.230178328","rc":[{"spl":[[1.01,2]],"id":53082422},{"spn":3.45,"spf":1.0,"id":53082422}],"con":true,"img":false}]}
{"op":"mcm","clk":"11540816961","pt":1719498694204,"mc":[{"id":"1.230178328","rc":[{"atb":[[5,1]],"id":64812720},{"atb":[[5,1]],"id":70902603},{"atb":[[4,0]],"id":66686625},{"atb":[[4.6,0]],"id":70053016},{"spn":77.05,"spf":"NaN","id":70053016},{"atb":[[5.5,0]],"id":69942666},{"spn":77.5,"spf":"NaN","id":69942666},{"atb":[[3.2,0]],"id":53082422},{"spn":3.03,"spf":1.0,"id":53082422}],"con":true,"img":false}]}
{"op":"mcm","clk":"11540845165","pt":1719499029583,"mc":[{"id":"1.230178328","rc":[{"atb":[[3.7,1]],"id":70902603}],"con":true,"img":false}]}
{"op":"mcm","clk":"11540845729","pt":1719499036664,"mc":[{"id":"1.230178328","rc":[{"atb":[[3.7,1]],"id":69942666}],"con":true,"img":false}]}
{"op":"mcm","clk":"11540942348","pt":1719500259570,"mc":[{"id":"1.230178328","rc":[{"atb":[[1.03,97.35]],"id":64812720},{"atl":[[980,1.72]],"id":64812720},{"atb":[[1.04,71.11]],"id":70902603},{"atl":[[990,1.82]],"id":70902603},{"atb":[[1.03,182.72]],"id":66686625},{"atl":[[970,1.06]],"id":66686625},{"atb":[[1.02,99.89]],"id":70053016},{"atl":[[980,0.84]],"id":70053016},{"atb":[[1.02,53.33]],"id":69942666},{"atl":[[970,0.99]],"id":69942666},{"atb":[[1.02,136.09]],"id":53082422},{"atl":[[990,1.29]],"id":53082422}],"con":true,"img":false}]}
{"op":"mcm","clk":"11540958064","pt":1719500452197,"mc":[{"id":"1.230178328","rc":[{"atb":[[2.36,13.33],[1.01,45.31],[1.03,97.37],[3.75,2.66]],"id":64812720},{"atl":[[980,1.72]],"id":64812720},{"atb":[[2.36,13.33],[4,2.5],[1.03,15.1],[1.04,71.12]],"id":70902603},{"atl":[[990,1.82]],"id":70902603},{"atb":[[3.6,2.77],[1.03,182.76],[2.34,9.5]],"id":66686625},{"atl":[[970,1.06]],"id":66686625},{"atb":[[2.36,13.08],[3.6,2.77],[1.01,45.31],[1.02,99.91]],"id":70053016},{"atl":[[980,0.84]],"id":70053016},{"atb":[[2.36,11.97],[1.01,45.31],[5.5,1.81],[1.02,53.34]],"id":69942666},{"atl":[[970,0.99]],"id":69942666},{"spn":77.75,"spf":"NaN","id":69942666},{"atb":[[2.36,6.54],[1.02,136.12],[2.6,3.84],[2.34,12.09]],"id":53082422},{"atl":[[990,1.29]],"id":53082422},{"spn":3.15,"spf":1.0,"id":53082422}],"con":true,"img":false}]}
{"op":"mcm","clk":"11541251881","pt":1719503817220,"mc":[{"id":"1.230178328","rc":[{"atb":[[3.75,0]],"id":64812720},{"atb":[[4,0]],"id":70902603},{"atb":[[3.6,0]],"id":66686625},{"atb":[[3.6,0]],"id":70053016},{"atb":[[5.5,0]],"id":69942666},{"spn":77.5,"spf":"NaN","id":69942666},{"atb":[[2.6,0]],"id":53082422},{"spn":3.03,"spf":1.0,"id":53082422}],"con":true,"img":false}]}
{"op":"mcm","clk":"11541277659","pt":1719504060396,"mc":[{"id":"1.230178328","rc":[{"atb":[[2.36,13.32],[1.01,45.29],[1.03,97.32]],"id":64812720},{"atl":[[980,1.72]],"id":64812720},{"atb":[[2.36,13.32],[1.03,15.09],[1.04,71.09]],"id":70902603},{"atl":[[990,1.82]],"id":70902603},{"atb":[[1.03,182.66],[2.34,9.49]],"id":66686625},{"atl":[[970,1.06]],"id":66686625},{"atb":[[2.36,13.07],[1.01,45.29],[3.95,0],[1.02,99.86],[3.9,1]],"id":70053016},{"atl":[[980,0.84]],"id":70053016},{"atb":[[2.36,11.96],[1.01,45.29],[1.02,53.31]],"id":69942666},{"atl":[[970,0.99]],"id":69942666},{"atb":[[2.36,6.54],[3.7,0],[1.02,136.05],[3.25,1],[2.34,12.08]],"id":53082422},{"atl":[[990,1.29]],"id":53082422},{"spn":2.8,"spf":1.0,"id":53082422}],"con":true,"img":false}]}
{"op":"mcm","clk":"11541400476","pt":1719505355991,"mc":[{"id":"1.230178328","rc":[{"atl":[[30,1.73]],"id":64812720},{"spn":17.5,"spf":"NaN","id":64812720}],"con":true,"img":false}]}
{"op":"mcm","clk":"11541400509","pt":1719505356302,"mc":[{"id":"1.230178328","rc":[{"atl":[[26,1.73]],"id":53082422}],"con":true,"img":false}]}
{"op":"mcm","clk":"11541468801","pt":1719506072323,"mc":[{"id":"1.230178328","rc":[{"atb":[[5.3,3.75]],"id":69942666},{"spn":77.65,"spf":"NaN","id":69942666}],"con":true,"img":false}]}
{"op":"mcm","clk":"11541468961","pt":1719506073822,"mc":[{"id":"1.230178328","rc":[{"atb":[[5.3,0]],"id":69942666}],"con":true,"img":false}]}
{"op":"mcm","clk":"11541474819","pt":1719506132381,"mc":[{"id":"1.230178328","rc":[{"atb":[[4.5,3.75]],"id":69942666},{"spn":77.5,"spf":"NaN","id":69942666}],"con":true,"img":false}]}
{"op":"mcm","clk":"11541475655","pt":1719506139999,"mc":[{"id":"1.230178328","rc":[{"atb":[[4.5,0]],"id":69942666}],"con":true,"img":false}]}
{"op":"mcm","clk":"11541479042","pt":1719506173320,"mc":[{"id":"1.230178328","rc":[{"spl":[[1.01,1.69]],"id":69942666}],"con":true,"img":false}]}
{"op":"mcm","clk":"11541481955","pt":1719506200360,"mc":[{"id":"1.230178328","rc":[{"atb":[[3.95,3.75]],"id":69942666},{"spn":4.67,"spf":1.0,"id":69942666}],"con":true,"img":false}]}
{"op":"mcm","clk":"11541481979","pt":1719506200524,"mc":[{"id":"1.230178328","rc":[{"atb":[[3.95,0]],"id":69942666}],"con":true,"img":false}]}
{"op":"mcm","clk":"11541485332","pt":1719506231292,"mc":[{"id":"1.230178328","rc":[{"atl":[[190,4]],"id":64812720},{"atl":[[190,4]],"id":70902603},{"atl":[[190,4]],"id":66686625},{"atl":[[190,4]],"id":70053016},{"atl":[[190,4]],"id":69942666},{"atl":[[190,4]],"id":53082422}],"con":true,"img":false}]}
{"op":"mcm","clk":"11541485535","pt":1719506233173,"mc":[{"id":"1.230178328","rc":[{"atb":[[1.02,138.05]],"id":53082422}],"con":true,"img":false}]}
{"op":"mcm","clk":"11541485576","pt":1719506233578,"mc":[{"id":"1.230178328","rc":[{"atb":[[1.02,101.86]],"id":70053016}],"con":true,"img":false}]}
{"op":"mcm","clk":"11541485609","pt":1719506233892,"mc":[{"id":"1.230178328","rc":[{"atb":[[1.02,2]],"id":66686625}],"con":true,"img":false}]}
{"op":"mcm","clk":"11541485649","pt":1719506234265,"mc":[{"id":"1.230178328","rc":[{"atb":[[1.02,2]],"id":64812720}],"con":true,"img":false}]}
{"op":"mcm","clk":"11541485708","pt":1719506234783,"mc":[{"id":"1.230178328","rc":[{"atb":[[1.02,2]],"id":70902603}],"con":true,"img":false}]}
{"op":"mcm","clk":"11541485751","pt":1719506235190,"mc":[{"id":"1.230178328","rc":[{"atb":[[5.1,2]],"id":69942666}],"con":true,"img":false}]}
{"op":"mcm","clk":"11541517508","pt":1719506540202,"mc":[{"id":"1.230178328","rc":[{"atl":[[29,0.84]],"id":64812720},{"spn":17.0,"spf":"NaN","id":64812720},{"spn":5.1,"spf":1.0,"id":69942666},{"atl":[[25,0.84]],"id":53082422}],"con":true,"img":false}]}
{"op":"mcm","clk":"11541532367","pt":1719506712733,"mc":[{"id":"1.230178328","rc":[{"atb":[[5.3,7.5]],"id":69942666},{"spn":5.3,"spf":1.0,"id":69942666}],"con":true,"img":false}]}
{"op":"mcm","clk":"11541532443","pt":1719506713659,"mc":[{"id":"1.230178328","rc":[{"atb":[[5.1,0]],"id":69942666}],"con":true,"img":false}]}
{"op":"mcm","clk":"11541532457","pt":1719506713762,"mc":[{"id":"1.230178328","rc":[{"atb":[[5.4,2]],"id":69942666}],"con":true,"img":false}]}
{"op":"mcm","clk":"11541532502","pt":1719506714249,"mc":[{"id":"1.230178328","rc":[{"atb":[[5.3,0]],"id":69942666}],"con":true,"img":false}]}
{"op":"mcm","clk":"11541532558","pt":1719506714854,"mc":[{"id":"1.230178328","rc":[{"atb":[[5.4,0]],"id":69942666}],"con":true,"img":false}]}
{"op":"mcm","clk":"11541532566","pt":1719506714959,"mc":[{"id":"1.230178328","rc":[{"atb":[[5.1,2]],"id":69942666}],"con":true,"img":false}]}
{"op":"mcm","clk":"11541532728","pt":1719506717146,"mc":[{"id":"1.230178328","rc":[{"atb":[[5,3.14]],"id":70053016}],"con":true,"img":false}]}
{"op":"mcm","clk":"11541535150","pt":1719506748096,"mc":[{"id":"1.230178328","rc":[{"atb":[[5,0]],"id":70053016}],"con":true,"img":false}]}
{"op":"mcm","clk":"11541541348","pt":1719506819469,"mc":[{"id":"1.230178328","rc":[{"spn":5.1,"spf":1.0,"id":69942666},{"atb":[[1.08,1.69]],"id":53082422}],"con":true,"img":false}]}
{"op":"mcm","clk":"11541541356","pt":1719506819565,"mc":[{"id":"1.230178328","rc":[{"atb":[[1.12,1.69]],"id":66686625}],"con":true,"img":false}]}
{"op":"mcm","clk":"11541541371","pt":1719506819769,"mc":[{"id":"1.230178328","rc":[{"atb":[[1.12,1.69]],"id":64812720}],"con":true,"img":false}]}
{"op":"mcm","clk":"11541541379","pt":1719506819827,"mc":[{"id":"1.230178328","rc":[{"atb":[[1.12,1.69]],"id":70902603}],"con":true,"img":false}]}
{"op":"mcm","clk":"11541541394","pt":1719506820034,"mc":[{"id":"1.230178328","rc":[{"atb":[[1.12,1.69]],"id":69942666}],"con":true,"img":false}]}
{"op":"mcm","clk":"11541541406","pt":1719506820138,"mc":[{"id":"1.230178328","rc":[{"atb":[[1.12,0.05],[3.15,9.5]],"id":66686625},{"atl":[[22,4.76]],"id":66686625},{"atb":[[5.1,4]],"id":69942666},{"atl":[[140,2]],"id":69942666}],"con":true,"img":false}]}
{"op":"mcm","clk":"11541541419","pt":1719506820243,"mc":[{"id":"1.230178328","rc":[{"atb":[[3.35,13.33]],"id":64812720},{"atl":[[30,5.18]],"id":64812720},{"atb":[[3.6,13.33]],"id":70902603},{"atl":[[110,2]],"id":70902603},{"atb":[[3,13.08]],"id":70053016},{"atl":[[26,4]],"id":70053016},{"atb":[[2.38,6.55]],"id":53082422},{"atl":[[17.5,2]],"id":53082422}],"con":true,"img":false}]}
{"op":"mcm","clk":"11541541430","pt":1719506820347,"mc":[{"id":"1.230178328","rc":[{"atb":[[1.12,0.05]],"id":64812720}],"con":true,"img":false}]}
{"op":"mcm","clk":"11541541435","pt":1719506820439,"mc":[{"id":"1.230178328","rc":[{"atb":[[1.08,0.09]],"id":53082422}],"con":true,"img":false}]}
{"op":"mcm","clk":"11541541459","pt":1719506820762,"mc":[{"id":"1.230178328","rc":[{"atb":[[1.12,0.05]],"id":70902603},{"atb":[[1.12,0.05]],"id":69942666}],"con":true,"img":false}]}
{"op":"mcm","clk":"11541541474","pt":1719506820972,"mc":[{"id":"1.230178328","rc":[{"atb":[[1.09,1.69]],"id":70053016}],"con":true,"img":false}]}
{"op":"mcm","clk":"11541541484","pt":1719506821062,"mc":[{"id":"1.230178328","rc":[{"atb":[[1.12,0]],"id":66686625}],"con":true,"img":false}]}
{"op":"mcm","clk":"11541541495","pt":1719506821169,"mc":[{"id":"1.230178328","rc":[{"atb":[[5.1,0.05]],"id":66686625}],"con":true,"img":false}]}
{"op":"mcm","clk":"11541541527","pt":1719506821544,"mc":[{"id":"1.230178328","rc":[{"atb":[[1.12,0]],"id":64812720},{"atl":[[26,0]],"id":53082422}],"con":true,"img":false}]}
{"op":"mcm","clk":"11541541536","pt":1719506821647,"mc":[{"id":"1.230178328","rc":[{"atb":[[5.1,0.05]],"id":64812720}],"con":true,"img":false}]}
{"op":"mcm","clk":"11541541561","pt":1719506821958,"mc":[{"id":"1.230178328","rc":[{"atb":[[1.08,0]],"id":53082422}],"con":true,"img":false}]}
{"op":"mcm","clk":"11541541571","pt":1719506822065,"mc":[{"id":"1.230178328","rc":[{"atb":[[3.3,0.09]],"id":53082422}],"con":true,"img":false}]}
{"op":"mcm","clk":"11541541597","pt":1719506822376,"mc":[{"id":"1.230178328","rc":[{"atb":[[1.12,0]],"id":69942666}],"con":true,"img":false}]}
{"op":"mcm","clk":"11541541613","pt":1719506822473,"mc":[{"id":"1.230178328","rc":[{"atb":[[5.2,0.05]],"id":69942666}],"con":true,"img":false}]}
{"op":"mcm","clk":"11541541653","pt":1719506822839,"mc":[{"id":"1.230178328","rc":[{"atb":[[1.12,0]],"id":70902603}],"con":true,"img":false}]}
{"op":"mcm","clk":"11541541666","pt":1719506822942,"mc":[{"id":"1.230178328","rc":[{"atb":[[5.1,0.05]],"id":70902603}],"con":true,"img":false}]}
{"op":"mcm","clk":"11541541691","pt":1719506823255,"mc":[{"id":"1.230178328","rc":[{"atb":[[1.09,0.07]],"id":70053016}],"con":true,"img":false}]}
{"op":"mcm","clk":"11541541722","pt":1719506823568,"mc":[{"id":"1.230178328","rc":[{"atb":[[1.09,0]],"id":70053016}],"con":true,"img":false}]}
{"op":"mcm","clk":"11541541730","pt":1719506823624,"mc":[{"id":"1.230178328","rc":[{"atb":[[4.2,0.07]],"id":70053016}],"con":true,"img":false}]}
{"op":"mcm","clk":"11541541737","pt":1719506823727,"mc":[{"id":"1.230178328","rc":[{"atl":[[140,2],[110,0]],"id":70902603},{"atl":[[34,3.03],[26,0]],"id":70053016},{"atl":[[17.5,0],[22,4]],"id":53082422}],"con":true,"img":false}]}
{"op":"mcm","clk":"11541541812","pt":1719506824659,"mc":[{"id":"1.230178328","rc":[{"atl":[[5.8,1]],"id":53082422}],"con":true,"img":false}]}
{"op":"mcm","clk":"11541542064","pt":1719506827467,"mc":[{"id":"1.230178328","rc":[{"atl":[[5.7,1.51]],"id":53082422}],"con":true,"img":false}]}
{"op":"mcm","clk":"11541542073","pt":1719506827571,"mc":[{"id":"1.230178328","rc":[{"atl":[[1000,1.87]],"id":66686625},{"atl":[[1000,1.7]],"id":70053016},{"atb":[[1.01,1.7]],"id":53082422},{"atl":[[1000,1.7]],"id":53082422}],"con":true,"img":false}]}
{"op":"mcm","clk":"11541542083","pt":1719506827674,"mc":[{"id":"1.230178328","rc":[{"atb":[[1.02,3.7]],"id":66686625},{"atb":[[1.03,1.7]],"id":70053016}],"con":true,"img":false}]}
{"op":"mcm","clk":"11541542093","pt":1719506827782,"mc":[{"id":"1.230178328","rc":[{"atl":[[1000,0.18]],"id":66686625},{"atl":[[1000,0.01]],"id":70053016},{"atb":[[1.01,0.22]],"id":53082422},{"atl":[[1000,0.01]],"id":53082422}],"con":true,"img":false}]}
{"op":"mcm","clk":"11541542105","pt":1719506827834,"mc":[{"id":"1.230178328","rc":[{"atb":[[1.02,2.14]],"id":66686625},{"atb":[[1.03,0.09]],"id":70053016}],"con":true,"img":false}]}
{"op":"mcm","clk":"11541542117","pt":1719506827940,"mc":[{"id":"1.230178328","rc":[{"atl":[[1000,0.16]],"id":66686625},{"atl":[[1000,0]],"id":70053016},{"atb":[[1.01,0]],"id":53082422},{"atl":[[1000,0]],"id":53082422}],"con":true,"img":false}]}
{"op":"mcm","clk":"11541542125","pt":1719506828042,"mc":[{"id":"1.230178328","rc":[{"atb":[[1.02,2]],"id":66686625},{"atl":[[21,0.01]],"id":66686625},{"atb":[[1.03,0]],"id":70053016},{"atl":[[32,0.01]],"id":70053016},{"atb":[[2.4,0.22]],"id":53082422},{"atl":[[21,0.01]],"id":53082422}],"con":true,"img":false}]}
{"op":"mcm","clk":"11541542136","pt":1719506828147,"mc":[{"id":"1.230178328","rc":[{"atb":[[3.2,0.14]],"id":66686625},{"atb":[[4.2,0.17]],"id":70053016}],"con":true,"img":false}]}
{"op":"mcm","clk":"11541542471","pt":1719506832143,"mc":[{"id":"1.230178328","rc":[{"atl":[[10.5,1]],"id":64812720},{"atb":[[4.3,1]],"id":70902603},{"atl":[[14,1]],"id":70902603},{"atl":[[10,1]],"id":66686625},{"atl":[[8.6,1]],"id":70053016},{"atb":[[4.9,1]],"id":69942666},{"atl":[[34,1]],"id":69942666},{"atl":[[5.7,2.51]],"id":53082422}],"con":true,"img":false}]}
{"op":"mcm","clk":"11541542484","pt":1719506832249,"mc":[{"id":"1.230178328","rc":[{"atb":[[3.6,0],[4.3,7]],"id":70902603},{"atl":[[5.8,0]],"id":53082422}],"con":true,"img":false}]}
{"op":"mcm","clk":"11541542599","pt":1719506833860,"mc":[{"id":"1.230178328","rc":[{"atl":[[5.8,5.02],[22,0]],"id":53082422}],"con":true,"img":false}]}
{"op":"mcm","clk":"11541543461","pt":1719506844763,"mc":[{"id":"1.230178328","rc":[{"atl":[[29,0]],"id":64812720},{"atl":[[25,0]],"id":53082422}],"con":true,"img":false}]}
{"op":"mcm","clk":"11541545408","pt":1719506868780,"mc":[{"id":"1.230178328","rc":[{"atb":[[3.2,0]],"id":66686625},{"atl":[[21,0]],"id":66686625},{"atb":[[4.2,0.07]],"id":70053016},{"atl":[[32,0]],"id":70053016},{"atb":[[2.4,0]],"id":53082422},{"atl":[[21,0]],"id":53082422}],"con":true,"img":false}]}
{"op":"mcm","clk":"11541546046","pt":1719506878021,"mc":[{"id":"1.230178328","rc":[{"atb":[[5.1,0],[5,0]],"id":70902603},{"atl":[[5,4.26]],"id":70902603},{"trd":[[5,2],[5.1,0.11]],"ltp":5.0,"tv":2.11,"id":70902603},{"atb":[[4.1,0],[4.2,0]],"id":70053016},{"atl":[[4.1,0.41]],"id":70053016},{"trd":[[4.1,12],[4.2,0.15]],"ltp":4.1,"tv":12.15,"id":70053016},{"atb":[[3.25,0],[3.3,0]],"id":53082422},{"atl":[[3.25,7.1]],"id":53082422},{"trd":[[3.25,2],[3.3,0.18]],"ltp":3.25,"tv":2.18,"id":53082422}],"con":true,"img":false}]}
{"op":"mcm","clk":"11541546053","pt":1719506878124,"mc":[{"id":"1.230178328","rc":[{"atl":[[5,4]],"id":70902603},{"trd":[[5,2.52]],"ltp":5.0,"tv":2.52,"id":70902603},{"atl":[[4.1,0]],"id":70053016},{"trd":[[4.1,12.82]],"ltp":4.1,"tv":12.82,"id":70053016},{"atl":[[3.25,6.84]],"id":53082422},{"trd":[[3.25,2.52]],"ltp":3.25,"tv":2.52,"id":53082422}],"con":true,"img":false}]}
{"op":"mcm","clk":"11541546061","pt":1719506878229,"mc":[{"id":"1.230178328","rc":[{"atb":[[3.6,13.33],[4.3,1]],"id":70902603},{"atl":[[16.5,5.26],[140,0]],"id":70902603},{"atb":[[2.38,14.08],[3,0]],"id":70053016}],"con":true,"img":false}]}
{"op":"mcm","clk":"11541546091","pt":1719506878595,"mc":[{"id":"1.230178328","rc":[{"atl":[[5.7,1]],"id":53082422}],"con":true,"img":false}]}
{"op":"mcm","clk":"11541546158","pt":1719506879530,"mc":[{"id":"1.230178328","rc":[{"spn":7.8,"spf":"NaN","id":64812720},{"atb":[[4.5,1]],"id":70902603},{"spn":4.75,"spf":"NaN","id":70902603},{"spn":7.55,"spf":"NaN","id":66686625},{"atb":[[3.95,1],[3.9,0]],"id":70053016},{"spn":6.27,"spf":"NaN","id":70053016},{"spn":5.1,"spf":1.0,"id":69942666},{"spn":2.38,"spf":1.0,"id":53082422}],"con":true,"img":false}]}
{"op":"mcm","clk":"11541546173","pt":1719506879738,"mc":[{"id":"1.230178328","rc":[{"atb":[[3.6,0],[3.75,6]],"id":70902603},{"atb":[[2.4,5]],"id":70053016}],"con":true,"img":false}]}
{"op":"mcm","clk":"11541546223","pt":1719506880315,"mc":[{"id":"1.230178328","rc":[{"atl":[[16.5,0],[19.5,5.41]],"id":70902603},{"atl":[[1000,0.14]],"id":70053016},{"atb":[[1.03,1]],"id":53082422}],"con":true,"img":false}]}
{"op":"mcm","clk":"11541546240","pt":1719506880523,"mc":[{"id":"1.230178328","rc":[{"atb":[[2.48,2.09]],"id":70053016},{"atl":[[1000,0]],"id":70053016},{"atb":[[1.03,0.71]],"id":53082422}],"con":true,"img":false}]}
{"op":"mcm","clk":"11541546246","pt":1719506880629,"mc":[{"id":"1.230178328","rc":[{"atb":[[2.38,0],[2.48,7.09]],"id":70053016},{"atl":[[8.4,0.14]],"id":70053016},{"atb":[[1.03,0]],"id":53082422}],"con":true,"img":false}]}
{"op":"mcm","clk":"11541546253","pt":1719506880683,"mc":[{"id":"1.230178328","rc":[{"atb":[[2.4,0.71]],"id":53082422}],"con":true,"img":false}]}
{"op":"mcm","clk":"11541546384","pt":1719506882210,"mc":[{"id":"1.230178328","rc":[{"atl":[[10.5,0],[11,1]],"id":64812720},{"atb":[[4.3,0],[3.85,1]],"id":70902603},{"atl":[[10,0],[10.5,1]],"id":66686625},{"atb":[[2.98,1]],"id":70053016},{"atl":[[8.6,0],[8.8,1]],"id":70053016},{"atb":[[2.52,1]],"id":53082422},{"atl":[[5.7,0]],"id":53082422}],"con":true,"img":false}]}
{"op":"mcm","clk":"11541546393","pt":1719506882313,"mc":[{"id":"1.230178328","rc":[{"atl":[[9.6,4],[34,0]],"id":70053016}],"con":true,"img":false}]}
{"op":"mcm","clk":"11541546422","pt":1719506882632,"mc":[{"id":"1.230178328","rc":[{"atb":[[1.02,139.75]],"id":53082422},{"atl":[[1000,1.7]],"id":53082422}],"con":true,"img":false}]}
{"op":"mcm","clk":"11541546428","pt":1719506882737,"mc":[{"id":"1.230178328","rc":[{"atb":[[1.02,138.19]],"id":53082422}],"con":true,"img":false}]}
{"op":"mcm","clk":"11541546443","pt":1719506882845,"mc":[{"id":"1.230178328","rc":[{"atb":[[1.02,138.05]],"id":53082422},{"atl":[[1000,0.09]],"id":53082422}],"con":true,"img":false}]}
{"op":"mcm","clk":"11541546455","pt":1719506882916,"mc":[{"id":"1.230178328","rc":[{"atb":[[2.42,0.14]],"id":53082422}],"con":true,"img":false}]}
{"op":"mcm","clk":"11541546468","pt":1719506883003,"mc":[{"id":"1.230178328","rc":[{"atl":[[1000,0]],"id":53082422}],"con":true,"img":false}]}
{"op":"mcm","clk":"11541546481","pt":1719506883108,"mc":[{"id":"1.230178328","rc":[{"atl":[[3.2,0.09]],"id":53082422}],"con":true,"img":false}]}
{"op":"mcm","clk":"11541546489","pt":1719506883213,"mc":[{"id":"1.230178328","rc":[{"atb":[[2.5,5]],"id":70053016}],"con":true,"img":false}]}
{"op":"mcm","clk":"11541546535","pt":1719506883634,"mc":[{"id":"1.230178328","rc":[{"atb":[[4.9,0],[5.5,1]],"id":69942666}],"con":true,"img":false}]}
{"op":"mcm","clk":"11541546621","pt":1719506884426,"mc":[{"id":"1.230178328","rc":[{"atb":[[4.9,1],[5.5,0]],"id":69942666}],"con":true,"img":false}]}
{"op":"mcm","clk":"11541546629","pt":1719506884531,"mc":[{"id":"1.230178328","rc":[{"atb":[[5.1,2]],"id":69942666}],"con":true,"img":false}]}
{"op":"mcm","clk":"11541546640","pt":1719506884636,"mc":[{"id":"1.230178328","rc":[{"atb":[[5.6,2]],"id":69942666}],"con":true,"img":false}]}
{"op":"mcm","clk":"11541546648","pt":1719506884740,"mc":[{"id":"1.230178328","rc":[{"atb":[[5.6,4],[5.1,0]],"id":69942666}],"con":true,"img":false}]}
{"op":"mcm","clk":"11541546656","pt":1719506884795,"mc":[{"id":"1.230178328","rc":[{"atb":[[5.6,2],[5.1,2.06]],"id":69942666}],"con":true,"img":false}]}
{"op":"mcm","clk":"11541546668","pt":1719506884919,"mc":[{"id":"1.230178328","rc":[{"atb":[[5.6,4],[5.1,0]],"id":69942666}],"con":true,"img":false}]}
{"op":"mcm","clk":"11541546679","pt":1719506885012,"mc":[{"id":"1.230178328","rc":[{"atb":[[5.6,2],[5.1,2.06]],"id":69942666}],"con":true,"img":false}]}
{"op":"mcm","clk":"11541546692","pt":1719506885108,"mc":[{"id":"1.230178328","rc":[{"atb":[[5.1,0]],"id":69942666}],"con":true,"img":false}]}
{"op":"mcm","clk":"11541546701","pt":1719506885211,"mc":[{"id":"1.230178328","rc":[{"atb":[[4.9,0],[5.6,4],[5.5,1]],"id":69942666}],"con":true,"img":false}]}
{"op":"mcm","clk":"11541546728","pt":1719506885524,"mc":[{"id":"1.230178328","rc":[{"atb":[[4.9,1],[5.5,0]],"id":69942666}],"con":true,"img":false}]}
{"op":"mcm","clk":"11541546743","pt":1719506885734,"mc":[{"id":"1.230178328","rc":[{"atb":[[5.3,3.75]],"id":69942666}],"con":true,"img":false}]}
{"op":"mcm","clk":"11541546779","pt":1719506886106,"mc":[{"id":"1.230178328","rc":[{"atb":[[5.3,0]],"id":69942666}],"con":true,"img":false}]}
{"op":"mcm","clk":"11541547028","pt":1719506889249,"mc":[{"id":"1.230178328","rc":[{"atb":[[3.75,0]],"id":70902603}],"con":true,"img":false}]}
{"op":"mcm","clk":"11541547038","pt":1719506889309,"mc":[{"id":"1.230178328","rc":[{"atb":[[3.85,3]],"id":70902603}],"con":true,"img":false}]}
{"op":"mcm","clk":"11541547121","pt":1719506890245,"mc":[{"id":"1.230178328","rc":[{"atl":[[5,0]],"id":70902603},{"trd":[[5,10.52]],"ltp":5.0,"tv":10.52,"id":70902603}],"con":true,"img":false}]}
{"op":"mcm","clk":"11541547131","pt":1719506890350,"mc":[{"id":"1.230178328","rc":[{"atl":[[140,2],[19.5,0]],"id":70902603}],"con":true,"img":false}]}
{"op":"mcm","clk":"11541547325","pt":1719506892820,"mc":[{"id":"1.230178328","rc":[{"atl":[[1000,0.24]],"id":70902603}],"con":true,"img":false}]}
{"op":"mcm","clk":"11541547343","pt":1719506893031,"mc":[{"id":"1.230178328","rc":[{"atl":[[1000,0.16]],"id":70902603}],"con":true,"img":false}]}
{"op":"mcm","clk":"11541547354","pt":1719506893135,"mc":[{"id":"1.230178328","rc":[{"atl":[[13.5,0.08]],"id":70902603}],"con":true,"img":false}]}
{"op":"mcm","clk":"11541547583","pt":1719506895709,"mc":[{"id":"1.230178328","rc":[{"atl":[[8.4,0]],"id":70053016}],"con":true,"img":false}]}
{"op":"mcm","clk":"11541547595","pt":1719506895917,"mc":[{"id":"1.230178328","rc":[{"atl":[[9.6,0],[46,2.22],[1000,0.13]],"id":70053016},{"atb":[[2.4,0]],"id":53082422}],"con":true,"img":false}]}
{"op":"mcm","clk":"11541547609","pt":1719506896128,"mc":[{"id":"1.230178328","rc":[{"atl":[[1000,0]],"id":70053016},{"atb":[[1.04,1]],"id":53082422}],"con":true,"img":false}]}
{"op":"mcm","clk":"11541547615","pt":1719506896231,"mc":[{"id":"1.230178328","rc":[{"atl":[[8.6,0.13]],"id":70053016}],"con":true,"img":false}]}
{"op":"mcm","clk":"11541547626","pt":1719506896336,"mc":[{"id":"1.230178328","rc":[{"atb":[[1.04,0.65]],"id":53082422}],"con":true,"img":false}]}
{"op":"mcm","clk":"11541547638","pt":1719506896546,"mc":[{"id":"1.230178328","rc":[{"atb":[[1.04,0]],"id":53082422}],"con":true,"img":false}]}
{"op":"mcm","clk":"11541547647","pt":1719506896651,"mc":[{"id":"1.230178328","rc":[{"atb":[[2.54,0.65]],"id":53082422}],"con":true,"img":false}]}
{"op":"mcm","clk":"11541547662","pt":1719506896810,"mc":[{"id":"1.230178328","rc":[{"atb":[[2.42,6.69],[2.38,0]],"id":53082422}],"con":true,"img":false}]}
{"op":"mcm","clk":"11541547687","pt":1719506897224,"mc":[{"id":"1.230178328","rc":[{"atb":[[2.32,7.52]],"id":53082422}],"con":true,"img":false}]}
{"op":"mcm","clk":"11541547701","pt":1719506897431,"mc":[{"id":"1.230178328","rc":[{"atb":[[2.32,0]],"id":53082422}],"con":true,"img":false}]}
{"op":"mcm","clk":"11541547922","pt":1719506900934,"mc":[{"id":"1.230178328","rc":[{"atb":[[2.5,8.16]],"id":70053016}],"con":true,"img":false}]}
{"op":"mcm","clk":"11541547931","pt":1719506901144,"mc":[{"id":"1.230178328","rc":[{"atb":[[2.16,5.45]],"id":70053016}],"con":true,"img":false}]}
{"op":"mcm","clk":"11541547937","pt":1719506901248,"mc":[{"id":"1.230178328","rc":[{"atb":[[2.36,3.38]],"id":53082422}],"con":true,"img":false}]}
{"op":"mcm","clk":"11541547945","pt":1719506901353,"mc":[{"id":"1.230178328","rc":[{"atb":[[2.16,5.45]],"id":64812720}],"con":true,"img":false}]}
{"op":"mcm","clk":"11541547959","pt":1719506901562,"mc":[{"id":"1.230178328","rc":[{"atb":[[4.9,0],[5.5,1]],"id":69942666}],"con":true,"img":false}]}
{"op":"mcm","clk":"11541547969","pt":1719506901616,"mc":[{"id":"1.230178328","rc":[{"atb":[[1.54,11.7]],"id":53082422}],"con":true,"img":false}]}
{"op":"mcm","clk":"11541547993","pt":1719506901928,"mc":[{"id":"1.230178328","rc":[{"atb":[[2.16,5.45]],"id":69942666}],"con":true,"img":false}]}
{"op":"mcm","clk":"11541548000","pt":1719506902031,"mc":[{"id":"1.230178328","rc":[{"atb":[[2.16,5.45]],"id":66686625}],"con":true,"img":false}]}
{"op":"mcm","clk":"11541548005","pt":1719506902134,"mc":[{"id":"1.230178328","rc":[{"atb":[[2.16,5.45]],"id":70902603}],"con":true,"img":false}]}
{"op":"mcm","clk":"11541548058","pt":1719506902867,"mc":[{"id":"1.230178328","rc":[{"atb":[[2.66,5.71]],"id":70053016}],"con":true,"img":false}]}
{"op":"mcm","clk":"11541548068","pt":1719506902922,"mc":[{"id":"1.230178328","rc":[{"atb":[[2.48,2.09],[2.68,7.1]],"id":70053016}],"con":true,"img":false}]}
{"op":"mcm","clk":"11541548083","pt":1719506903128,"mc":[{"id":"1.230178328","rc":[{"atb":[[4.9,1],[5.5,0]],"id":69942666}],"con":true,"img":false}]}
{"op":"mcm","clk":"11541548097","pt":1719506903336,"mc":[{"id":"1.230178328","rc":[{"atb":[[4.9,0],[5.5,1]],"id":69942666}],"con":true,"img":false}]}
{"op":"mcm","clk":"11541548460","pt":1719506908263,"mc":[{"id":"1.230178328","rc":[{"atl":[[13.5,0]],"id":70902603}],"con":true,"img":false}]}
{"op":"mcm","clk":"11541548472","pt":1719506908367,"mc":[{"id":"1.230178328","rc":[{"atb":[[3.75,2.91]],"id":70902603}],"con":true,"img":false}]}
{"op":"mcm","clk":"11541548480","pt":1719506908421,"mc":[{"id":"1.230178328","rc":[{"atl":[[1000,0.24]],"id":70902603}],"con":true,"img":false}]}
{"op":"mcm","clk":"11541548491","pt":1719506908526,"mc":[{"id":"1.230178328","rc":[{"atl":[[1000,0.16]],"id":70902603}],"con":true,"img":false}]}
{"op":"mcm","clk":"11541548502","pt":1719506908636,"mc":[{"id":"1.230178328","rc":[{"atl":[[13.5,0.08]],"id":70902603}],"con":true,"img":false}]}
{"op":"mcm","clk":"11541548544","pt":1719506909250,"mc":[{"id":"1.230178328","rc":[{"atl":[[13.5,1.08],[14,0]],"id":70902603},{"atl":[[9,1],[8.8,0]],"id":70053016},{"atl":[[34,0],[36,1]],"id":69942666}],"con":true,"img":false}]}
{"op":"mcm","clk":"11541548554","pt":1719506909355,"mc":[{"id":"1.230178328","rc":[{"atb":[[3.85,1],[3.55,12]],"id":70902603},{"atl":[[46,0],[9.8,4]],"id":70053016},{"atl":[[5.8,0],[6.8,10.04]],"id":53082422}],"con":true,"img":false}]}
{"op":"mcm","clk":"11541548566","pt":1719506909459,"mc":[{"id":"1.230178328","rc":[{"atb":[[3.8,2.91],[3.55,6]],"id":70902603}],"con":true,"img":false}]}
{"op":"mcm","clk":"11541548720","pt":1719506911435,"mc":[{"id":"1.230178328","rc":[{"atl":[[8.6,0]],"id":70053016}],"con":true,"img":false}]}
{"op":"mcm","clk":"11541548728","pt":1719506911539,"mc":[{"id":"1.230178328","rc":[{"atb":[[2.68,11.86]],"id":70053016},{"atl":[[48,2.13]],"id":70053016}],"con":true,"img":false}]}
{"op":"mcm","clk":"11541548734","pt":1719506911645,"mc":[{"id":"1.230178328","rc":[{"atl":[[9.8,0],[1000,0.13]],"id":70053016}],"con":true,"img":false}]}
{"op":"mcm","clk":"11541548750","pt":1719506911852,"mc":[{"id":"1.230178328","rc":[{"atl":[[1000,0]],"id":70053016},{"atb":[[2.54,0]],"id":53082422}],"con":true,"img":false}]}
{"op":"mcm","clk":"11541548761","pt":1719506911955,"mc":[{"id":"1.230178328","rc":[{"atl":[[8.8,0.13]],"id":70053016}],"con":true,"img":false}]}
{"op":"mcm","clk":"11541548776","pt":1719506912165,"mc":[{"id":"1.230178328","rc":[{"atb":[[1.04,1]],"id":53082422}],"con":true,"img":false}]}
{"op":"mcm","clk":"11541548784","pt":1719506912270,"mc":[{"id":"1.230178328","rc":[{"atb":[[1.04,0.65]],"id":53082422}],"con":true,"img":false}]}
{"op":"mcm","clk":"11541548797","pt":1719506912434,"mc":[{"id":"1.230178328","rc":[{"atb":[[1.04,0]],"id":53082422}],"con":true,"img":false}]}
{"op":"mcm","clk":"11541548806","pt":1719506912539,"mc":[{"id":"1.230178328","rc":[{"atb":[[2.54,0.65]],"id":53082422}],"con":true,"img":false}]}
{"op":"mcm","clk":"11541549004","pt":1719506914940,"mc":[{"id":"1.230178328","rc":[{"atb":[[1.54,24.23]],"id":53082422}],"con":true,"img":false}]}
{"op":"mcm","clk":"11541549011","pt":1719506915043,"mc":[{"id":"1.230178328","rc":[{"atb":[[2.16,11.29]],"id":64812720}],"con":true,"img":false}]}
{"op":"mcm","clk":"11541549027","pt":1719506915253,"mc":[{"id":"1.230178328","rc":[{"atb":[[2.16,11.29]],"id":66686625}],"con":true,"img":false}]}
{"op":"mcm","clk":"11541549035","pt":1719506915355,"mc":[{"id":"1.230178328","rc":[{"atb":[[2.16,11.29]],"id":70053016}],"con":true,"img":false}]}
{"op":"mcm","clk":"11541549050","pt":1719506915562,"mc":[{"id":"1.230178328","rc":[{"atb":[[2.16,11.29]],"id":70902603}],"con":true,"img":false}]}
{"op":"mcm","clk":"11541549075","pt":1719506915823,"mc":[{"id":"1.230178328","rc":[{"atb":[[2.66,11.83]],"id":70053016}],"con":true,"img":false}]}
{"op":"mcm","clk":"11541549090","pt":1719506916030,"mc":[{"id":"1.230178328","rc":[{"atb":[[2.16,11.29]],"id":69942666}],"con":true,"img":false}]}
{"op":"mcm","clk":"11541549228","pt":1719506917852,"mc":[{"id":"1.230178328","rc":[{"atb":[[2.62,7.31]],"id":64812720}],"con":true,"img":false}]}
{"op":"mcm","clk":"11541549244","pt":1719506918059,"mc":[{"id":"1.230178328","rc":[{"atb":[[2.38,5.15]],"id":53082422}],"con":true,"img":false}]}
{"op":"mcm","clk":"11541549258","pt":1719506918267,"mc":[{"id":"1.230178328","rc":[{"atb":[[1.53,14.91]],"id":53082422}],"con":true,"img":false}]}
{"op":"mcm","clk":"11541549268","pt":1719506918373,"mc":[{"id":"1.230178328","rc":[{"atb":[[2.16,18.1]],"id":69942666}],"con":true,"img":false}]}
{"op":"mcm","clk":"11541549275","pt":1719506918438,"mc":[{"id":"1.230178328","rc":[{"atb":[[2.84,5.15]],"id":70902603}],"con":true,"img":false}]}
{"op":"mcm","clk":"11541549306","pt":1719506918751,"mc":[{"id":"1.230178328","rc":[{"atb":[[2.5,5]],"id":70053016}],"con":true,"img":false}]}
{"op":"mcm","clk":"11541549326","pt":1719506918948,"mc":[{"id":"1.230178328","rc":[{"atb":[[3.15,5.51]],"id":69942666}],"con":true,"img":false}]}
{"op":"mcm","clk":"11541549351","pt":1719506919257,"mc":[{"id":"1.230178328","rc":[{"atl":[[12.5,1],[13.5,0.08]],"id":70902603}],"con":true,"img":false}]}
{"op":"mcm","clk":"11541549360","pt":1719506919363,"mc":[{"id":"1.230178328","rc":[{"atb":[[2.4,5.64]],"id":70902603}],"con":true,"img":false}]}
{"op":"mcm","clk":"11541549377","pt":1719506919577,"mc":[{"id":"1.230178328","rc":[{"atb":[[1.67,17.69]],"id":53082422}],"con":true,"img":false}]}
{"op":"mcm","clk":"11541549411","pt":1719506919852,"mc":[{"id":"1.230178328","rc":[{"atb":[[2.16,18.1]],"id":66686625},{"atb":[[2.7,3.16]],"id":70053016}],"con":true,"img":false}]}
{"op":"mcm","clk":"11541549736","pt":1719506923872,"mc":[{"id":"1.230178328","rc":[{"atl":[[13.5,0]],"id":70902603}],"con":true,"img":false}]}
{"op":"mcm","clk":"11541549750","pt":1719506924081,"mc":[{"id":"1.230178328","rc":[{"atl":[[1000,0.25]],"id":70902603}],"con":true,"img":false}]}
{"op":"mcm","clk":"11541549757","pt":1719506924185,"mc":[{"id":"1.230178328","rc":[{"atl":[[1000,0.16]],"id":70902603}],"con":true,"img":false}]}
{"op":"mcm","clk":"11541549765","pt":1719506924248,"mc":[{"id":"1.230178328","rc":[{"atl":[[12,0.09]],"id":70902603}],"con":true,"img":false}]}
{"op":"mcm","clk":"11541549885","pt":1719506925855,"mc":[{"id":"1.230178328","rc":[{"atb":[[5.7,0.84]],"id":69942666}],"con":true,"img":false}]}
{"op":"mcm","clk":"11541549966","pt":1719506927056,"mc":[{"id":"1.230178328","rc":[{"atl":[[8.8,0]],"id":70053016}],"con":true,"img":false}]}
{"op":"mcm","clk":"11541549982","pt":1719506927264,"mc":[{"id":"1.230178328","rc":[{"atb":[[2.72,4.65]],"id":70053016},{"atl":[[1000,0.13]],"id":70053016}],"con":true,"img":false}]}
{"op":"mcm","clk":"11541549989","pt":1719506927366,"mc":[{"id":"1.230178328","rc":[{"atl":[[1000,0]],"id":70053016}],"con":true,"img":false}]}
{"op":"mcm","clk":"11541550000","pt":1719506927469,"mc":[{"id":"1.230178328","rc":[{"atl":[[8.8,0.13]],"id":70053016}],"con":true,"img":false}]}
{"op":"mcm","clk":"11541550030","pt":1719506927783,"mc":[{"id":"1.230178328","rc":[{"atb":[[2.54,0]],"id":53082422}],"con":true,"img":false}]}
{"op":"mcm","clk":"11541550039","pt":1719506927887,"mc":[{"id":"1.230178328","rc":[{"atb":[[2.4,7.69],[2.42,0.14]],"id":53082422}],"con":true,"img":false}]}
{"op":"mcm","clk":"11541550048","pt":1719506927954,"mc":[{"id":"1.230178328","rc":[{"atb":[[1.04,1]],"id":53082422}],"con":true,"img":false}]}
{"op":"mcm","clk":"11541550069","pt":1719506928150,"mc":[{"id":"1.230178328","rc":[{"atb":[[1.04,0.65]],"id":53082422}],"con":true,"img":false}]}
{"op":"mcm","clk":"11541550089","pt":1719506928358,"mc":[{"id":"1.230178328","rc":[{"atb":[[1.04,0]],"id":53082422}],"con":true,"img":false}]}
{"op":"mcm","clk":"11541550095","pt":1719506928460,"mc":[{"id":"1.230178328","rc":[{"atb":[[2.54,0.65]],"id":53082422}],"con":true,"img":false}]}
{"op":"mcm","clk":"11541550772","pt":1719506936963,"mc":[{"id":"1.230178328","rc":[{"atb":[[2.74,6.81]],"id":70902603}],"con":true,"img":false}]}
{"op":"mcm","clk":"11541550779","pt":1719506937069,"mc":[{"id":"1.230178328","rc":[{"atb":[[2.72,8.78]],"id":70053016}],"con":true,"img":false}]}
{"op":"mcm","clk":"11541550785","pt":1719506937162,"mc":[{"id":"1.230178328","rc":[{"atb":[[2.38,0]],"id":53082422}],"con":true,"img":false}]}
{"op":"mcm","clk":"11541550799","pt":1719506937369,"mc":[{"id":"1.230178328","rc":[{"atb":[[2.72,13.37]],"id":70053016}],"con":true,"img":false}]}
{"op":"mcm","clk":"11541550948","pt":1719506939497,"mc":[{"id":"1.230178328","rc":[{"atl":[[12,0]],"id":70902603}],"con":true,"img":false}]}
{"op":"mcm","clk":"11541550961","pt":1719506939705,"mc":[{"id":"1.230178328","rc":[{"spn":8.05,"spf":"NaN","id":64812720},{"atl":[[1000,0.25]],"id":70902603},{"spn":8.5,"spf":"NaN","id":70902603},{"spn":7.8,"spf":"NaN","id":66686625},{"spn":6.37,"spf":"NaN","id":70053016},{"spn":5.65,"spf":1.0,"id":69942666},{"spn":2.5,"spf":1.0,"id":53082422}],"con":true,"img":false}]}
{"op":"mcm","clk":"11541550976","pt":1719506939861,"mc":[{"id":"1.230178328","rc":[{"atl":[[1000,0.16]],"id":70902603}],"con":true,"img":false}]}
{"op":"mcm","clk":"11541550984","pt":1719506939966,"mc":[{"id":"1.230178328","rc":[{"atl":[[12,0.09]],"id":70902603}],"con":true,"img":false}]}
{"op":"mcm","clk":"11541551040","pt":1719506940703,"mc":[{"id":"1.230178328","rc":[{"atl":[[1000,1.7]],"id":70053016}],"con":true,"img":false}]}
{"op":"mcm","clk":"11541551049","pt":1719506940768,"mc":[{"id":"1.230178328","rc":[{"atb":[[1.02,3.7]],"id":66686625},{"atl":[[1000,1.87]],"id":66686625},{"atb":[[1.02,103.56]],"id":70053016},{"atb":[[1.02,139.75]],"id":53082422},{"atl":[[1000,1.7]],"id":53082422}],"con":true,"img":false}]}
{"op":"mcm","clk":"11541551058","pt":1719506940889,"mc":[{"id":"1.230178328","rc":[{"atl":[[1000,0]],"id":70053016}],"con":true,"img":false}]}
{"op":"mcm","clk":"11541551072","pt":1719506941076,"mc":[{"id":"1.230178328","rc":[{"atb":[[1.02,2.13]],"id":66686625},{"atl":[[1000,0.18]],"id":66686625},{"atb":[[1.02,102.01]],"id":70053016},{"atl":[[1000,0]],"id":70053016},{"atb":[[1.02,138.18]],"id":53082422},{"atl":[[1000,0.08]],"id":53082422}],"con":true,"img":false}]}
{"op":"mcm","clk":"11541551081","pt":1719506941184,"mc":[{"id":"1.230178328","rc":[{"atl":[[46,0]],"id":70053016}],"con":true,"img":false}]}
{"op":"mcm","clk":"11541551089","pt":1719506941289,"mc":[{"id":"1.230178328","rc":[{"atb":[[1.02,2]],"id":66686625},{"atl":[[1000,0.16]],"id":66686625},{"atb":[[1.02,101.86]],"id":70053016},{"atb":[[1.02,138.05]],"id":53082422},{"atl":[[1000,0]],"id":53082422}],"con":true,"img":false}]}
{"op":"mcm","clk":"11541551100","pt":1719506941396,"mc":[{"id":"1.230178328","rc":[{"atb":[[3.2,0.13]],"id":66686625},{"atl":[[21,0.01]],"id":66686625},{"atb":[[3,0.15]],"id":70053016},{"atb":[[2.44,0.13]],"id":53082422},{"atl":[[3.2,0.18]],"id":53082422}],"con":true,"img":false}]}
{"op":"mcm","clk":"11541551111","pt":1719506941503,"mc":[{"id":"1.230178328","rc":[{"atb":[[2.98,4.16]],"id":70053016},{"atb":[[2.44,2.13],[2.4,0]],"id":53082422}],"con":true,"img":false}]}
{"op":"mcm","clk":"11541551122","pt":1719506941573,"mc":[{"id":"1.230178328","rc":[{"atb":[[2.68,4.76]],"id":70053016}],"con":true,"img":false}]}
{"op":"mcm","clk":"11541551214","pt":1719506942668,"mc":[{"id":"1.230178328","rc":[{"atl":[[8.8,0]],"id":70053016}],"con":true,"img":false}]}
{"op":"mcm","clk":"11541551240","pt":1719506942973,"mc":[{"id":"1.230178328","rc":[{"atl":[[1000,0.13]],"id":70053016}],"con":true,"img":false}]}
{"op":"mcm","clk":"11541551259","pt":1719506943180,"mc":[{"id":"1.230178328","rc":[{"atl":[[1000,0]],"id":70053016}],"con":true,"img":false}]}
{"op":"mcm","clk":"11541551267","pt":1719506943283,"mc":[{"id":"1.230178328","rc":[{"atl":[[8.8,0.13]],"id":70053016}],"con":true,"img":false}]}
{"op":"mcm","clk":"11541551296","pt":1719506943700,"mc":[{"id":"1.230178328","rc":[{"atb":[[2.54,0]],"id":53082422}],"con":true,"img":false}]}
{"op":"mcm","clk":"11541551332","pt":1719506944070,"mc":[{"id":"1.230178328","rc":[{"atb":[[2.36,0]],"id":53082422}],"con":true,"img":false}]}
{"op":"mcm","clk":"11541551348","pt":1719506944277,"mc":[{"id":"1.230178328","rc":[{"atb":[[1.53,30.88],[1.04,1]],"id":53082422}],"con":true,"img":false}]}
{"op":"mcm","clk":"11541551356","pt":1719506944381,"mc":[{"id":"1.230178328","rc":[{"atb":[[2.16,25.4]],"id":66686625},{"atb":[[1.04,0.65]],"id":53082422}],"con":true,"img":false}]}
{"op":"mcm","clk":"11541551373","pt":1719506944587,"mc":[{"id":"1.230178328","rc":[{"atb":[[2.16,18.58]],"id":70902603},{"atb":[[1.04,0]],"id":53082422}],"con":true,"img":false}]}
{"op":"mcm","clk":"11541551380","pt":1719506944692,"mc":[{"id":"1.230178328","rc":[{"atb":[[2.84,10.67]],"id":70902603},{"atb":[[2.54,0.65]],"id":53082422}],"con":true,"img":false}]}
{"op":"mcm","clk":"11541551407","pt":1719506945003,"mc":[{"id":"1.230178328","rc":[{"atb":[[2.16,25.4]],"id":69942666}],"con":true,"img":false}]}
{"op":"mcm","clk":"11541551418","pt":1719506945109,"mc":[{"id":"1.230178328","rc":[{"atb":[[2.38,5.51]],"id":53082422}],"con":true,"img":false}]}
{"op":"mcm","clk":"11541551651","pt":1719506948014,"mc":[{"id":"1.230178328","rc":[{"atl":[[95,2]],"id":70902603}],"con":true,"img":false}]}
{"op":"mcm","clk":"11541551661","pt":1719506948027,"mc":[{"id":"1.230178328","rc":[{"atl":[[140,0],[11.5,1],[12.5,0]],"id":70902603}],"con":true,"img":false}]}
{"op":"mcm","clk":"11541552193","pt":1719506955074,"mc":[{"id":"1.230178328","rc":[{"atl":[[12,0]],"id":70902603}],"con":true,"img":false}]}
{"op":"mcm","clk":"11541552210","pt":1719506955284,"mc":[{"id":"1.230178328","rc":[{"atl":[[1000,0.26]],"id":70902603}],"con":true,"img":false}]}
{"op":"mcm","clk":"11541552216","pt":1719506955388,"mc":[{"id":"1.230178328","rc":[{"atb":[[2.7,0]],"id":70053016}],"con":true,"img":false}]}
{"op":"mcm","clk":"11541552225","pt":1719506955484,"mc":[{"id":"1.230178328","rc":[{"atl":[[1000,0.16]],"id":70902603}],"con":true,"img":false}]}
{"op":"mcm","clk":"11541552236","pt":1719506955589,"mc":[{"id":"1.230178328","rc":[{"atl":[[11,0.1]],"id":70902603},{"atb":[[2.74,6.81]],"id":70053016}],"con":true,"img":false}]}
{"op":"mcm","clk":"11541552249","pt":1719506955792,"mc":[{"id":"1.230178328","rc":[{"atb":[[2.72,8.78]],"id":70053016}],"con":true,"img":false}]}
{"op":"mcm","clk":"11541552286","pt":1719506956315,"mc":[{"id":"1.230178328","rc":[{"atb":[[2.72,4.65]],"id":70053016}],"con":true,"img":false}]}
{"op":"mcm","clk":"11541552455","pt":1719506958503,"mc":[{"id":"1.230178328","rc":[{"atl":[[8.8,0]],"id":70053016}],"con":true,"img":false}]}
{"op":"mcm","clk":"11541552467","pt":1719506958606,"mc":[{"id":"1.230178328","rc":[{"atb":[[3,4.15]],"id":70053016}],"con":true,"img":false}]}
{"op":"mcm","clk":"11541552477","pt":1719506958710,"mc":[{"id":"1.230178328","rc":[{"atl":[[1000,0.13]],"id":70053016}],"con":true,"img":false}]}
{"op":"mcm","clk":"11541552485","pt":1719506958813,"mc":[{"id":"1.230178328","rc":[{"atl":[[1000,0]],"id":70053016}],"con":true,"img":false}]}
{"op":"mcm","clk":"11541552493","pt":1719506958918,"mc":[{"id":"1.230178328","rc":[{"atl":[[8.8,0.13]],"id":70053016}],"con":true,"img":false}]}
{"op":"mcm","clk":"11541552583","pt":1719506959917,"mc":[{"id":"1.230178328","rc":[{"atb":[[2.54,0]],"id":53082422}],"con":true,"img":false}]}
{"op":"mcm","clk":"11541552594","pt":1719506960023,"mc":[{"id":"1.230178328","rc":[{"atb":[[2.42,5.66],[2.44,0.13]],"id":53082422}],"con":true,"img":false}]}
{"op":"mcm","clk":"11541552608","pt":1719506960183,"mc":[{"id":"1.230178328","rc":[{"atb":[[1.04,1]],"id":53082422}],"con":true,"img":false}]}
{"op":"mcm","clk":"11541552624","pt":1719506960389,"mc":[{"id":"1.230178328","rc":[{"atb":[[1.04,0.65]],"id":53082422}],"con":true,"img":false}]}
{"op":"mcm","clk":"11541552639","pt":1719506960591,"mc":[{"id":"1.230178328","rc":[{"atb":[[1.04,0]],"id":53082422}],"con":true,"img":false}]}
{"op":"mcm","clk":"11541552647","pt":1719506960694,"mc":[{"id":"1.230178328","rc":[{"atb":[[2.54,0.65]],"id":53082422}],"con":true,"img":false}]}
{"op":"mcm","clk":"11541553156","pt":1719506967289,"mc":[{"id":"1.230178328","rc":[{"atb":[[3.85,0],[3.65,1]],"id":70902603},{"atb":[[2.62,1],[2.52,0]],"id":53082422}],"con":true,"img":false}]}
{"op":"mcm","clk":"11541553162","pt":1719506967392,"mc":[{"id":"1.230178328","rc":[{"atb":[[2.42,0.14],[2.52,2]],"id":53082422}],"con":true,"img":false}]}
{"op":"mcm","clk":"11541553282","pt":1719506969204,"mc":[{"id":"1.230178328","rc":[{"atb":[[2.62,0]],"id":64812720},{"atb":[[3.15,0]],"id":69942666},{"atb":[[1.67,0]],"id":53082422}],"con":true,"img":false}]}
{"op":"mcm","clk":"11541553425","pt":1719506970819,"mc":[{"id":"1.230178328","rc":[{"atl":[[11,0]],"id":70902603}],"con":true,"img":false}]}
{"op":"mcm","clk":"11541553445","pt":1719506971009,"mc":[{"id":"1.230178328","rc":[{"atl":[[1000,0.26]],"id":70902603}],"con":true,"img":false}]}
{"op":"mcm","clk":"11541553470","pt":1719506971339,"mc":[{"id":"1.230178328","rc":[{"atl":[[1000,0.16]],"id":70902603}],"con":true,"img":false}]}
{"op":"mcm","clk":"11541553481","pt":1719506971448,"mc":[{"id":"1.230178328","rc":[{"atl":[[11,0.1]],"id":70902603}],"con":true,"img":false}]}
{"op":"mcm","clk":"11541553685","pt":1719506973803,"mc":[{"id":"1.230178328","rc":[{"atb":[[3.25,5.27]],"id":69942666},{"atb":[[2.36,3.16]],"id":53082422}],"con":true,"img":false}]}
{"op":"mcm","clk":"11541553703","pt":1719506974016,"mc":[{"id":"1.230178328","rc":[{"atb":[[1.71,16.7],[2.38,10.67]],"id":53082422}],"con":true,"img":false}]}
{"op":"mcm","clk":"11541553715","pt":1719506974119,"mc":[{"id":"1.230178328","rc":[{"atl":[[8.8,0]],"id":70053016}],"con":true,"img":false}]}
{"op":"mcm","clk":"11541553726","pt":1719506974225,"mc":[{"id":"1.230178328","rc":[{"atb":[[2.4,10.64]],"id":70053016}],"con":true,"img":false}]}
{"op":"mcm","clk":"11541553734","pt":1719506974328,"mc":[{"id":"1.230178328","rc":[{"atb":[[2.68,7.92]],"id":70053016}],"con":true,"img":false}]}
{"op":"mcm","clk":"11541553757","pt":1719506974500,"mc":[{"id":"1.230178328","rc":[{"atb":[[2.4,15.72]],"id":70053016}],"con":true,"img":false}]}
{"op":"mcm","clk":"11541553766","pt":1719506974603,"mc":[{"id":"1.230178328","rc":[{"atl":[[1000,0.13]],"id":70053016}],"con":true,"img":false}]}
{"op":"mcm","clk":"11541553777","pt":1719506974709,"mc":[{"id":"1.230178328","rc":[{"atb":[[2.7,6.97]],"id":64812720}],"con":true,"img":false}]}
{"op":"mcm","clk":"11541553786","pt":1719506974814,"mc":[{"id":"1.230178328","rc":[{"atl":[[1000,0]],"id":70053016}],"con":true,"img":false}]}
{"op":"mcm","clk":"11541553796","pt":1719506974903,"mc":[{"id":"1.230178328","rc":[{"atl":[[8.8,0.13]],"id":70053016}],"con":true,"img":false}]}
{"op":"mcm","clk":"11541553877","pt":1719506975908,"mc":[{"id":"1.230178328","rc":[{"atb":[[2.54,0]],"id":53082422}],"con":true,"img":false}]}
{"op":"mcm","clk":"11541553887","pt":1719506976010,"mc":[{"id":"1.230178328","rc":[{"atb":[[2.44,3.13],[2.52,0]],"id":53082422}],"con":true,"img":false}]}
{"op":"mcm","clk":"11541553898","pt":1719506976105,"mc":[{"id":"1.230178328","rc":[{"atb":[[1.04,1]],"id":53082422}],"con":true,"img":false}]}
{"op":"mcm","clk":"11541553915","pt":1719506976312,"mc":[{"id":"1.230178328","rc":[{"atb":[[1.04,0.61]],"id":53082422}],"con":true,"img":false}]}
{"op":"mcm","clk":"11541553929","pt":1719506976520,"mc":[{"id":"1.230178328","rc":[{"atb":[[1.04,0]],"id":53082422}],"con":true,"img":false}]}
{"op":"mcm","clk":"11541553937","pt":1719506976628,"mc":[{"id":"1.230178328","rc":[{"atb":[[2.64,0.61]],"id":53082422}],"con":true,"img":false}]}
{"op":"mcm","clk":"11541553995","pt":1719506977315,"mc":[{"id":"1.230178328","rc":[{"atl":[[11,1.1],[11.5,0]],"id":70902603}],"con":true,"img":false}]}
{"op":"mcm","clk":"11541554197","pt":1719506980007,"mc":[{"id":"1.230178328","rc":[{"atb":[[1.53,14.91]],"id":53082422}],"con":true,"img":false}]}
{"op":"mcm","clk":"11541554217","pt":1719506980318,"mc":[{"id":"1.230178328","rc":[{"atb":[[2.36,6.54]],"id":53082422}],"con":true,"img":false}]}
{"op":"mcm","clk":"11541554433","pt":1719506983137,"mc":[{"id":"1.230178328","rc":[{"atb":[[3.2,0]],"id":66686625},{"atl":[[21,0]],"id":66686625},{"atb":[[3,4]],"id":70053016},{"atl":[[46,0]],"id":70053016},{"atb":[[2.44,3],[2.42,0]],"id":53082422},{"atl":[[3.2,0]],"id":53082422}],"con":true,"img":false}]}
{"op":"mcm","clk":"11541554683","pt":1719506986724,"mc":[{"id":"1.230178328","rc":[{"atl":[[11,1]],"id":70902603}],"con":true,"img":false}]}
{"op":"mcm","clk":"11541554721","pt":1719506987246,"mc":[{"id":"1.230178328","rc":[{"atl":[[1000,0.27]],"id":70902603}],"con":true,"img":false}]}
{"op":"mcm","clk":"11541554737","pt":1719506987453,"mc":[{"id":"1.230178328","rc":[{"atl":[[1000,0.16]],"id":70902603}],"con":true,"img":false}]}
{"op":"mcm","clk":"11541554745","pt":1719506987514,"mc":[{"id":"1.230178328","rc":[{"atl":[[10.5,0.11]],"id":70902603}],"con":true,"img":false}]}
{"op":"mcm","clk":"11541554930","pt":1719506990111,"mc":[{"id":"1.230178328","rc":[{"atl":[[8.8,0]],"id":70053016}],"con":true,"img":false}]}
{"op":"mcm","clk":"11541554942","pt":1719506990322,"mc":[{"id":"1.230178328","rc":[{"atl":[[1000,0.13]],"id":70053016}],"con":true,"img":false}]}
{"op":"mcm","clk":"11541554956","pt":1719506990529,"mc":[{"id":"1.230178328","rc":[{"atl":[[1000,0]],"id":70053016}],"con":true,"img":false}]}
{"op":"mcm","clk":"11541554961","pt":1719506990625,"mc":[{"id":"1.230178328","rc":[{"atl":[[8.8,0.13]],"id":70053016}],"con":true,"img":false}]}
{"op":"mcm","clk":"11541555041","pt":1719506991837,"mc":[{"id":"1.230178328","rc":[{"atb":[[2.64,0]],"id":53082422}],"con":true,"img":false}]}
{"op":"mcm","clk":"11541555091","pt":1719506992544,"mc":[{"id":"1.230178328","rc":[{"atb":[[1.04,1]],"id":53082422}],"con":true,"img":false}]}
{"op":"mcm","clk":"11541555115","pt":1719506992854,"mc":[{"id":"1.230178328","rc":[{"atb":[[1.04,0.61]],"id":53082422}],"con":true,"img":false}]}
{"op":"mcm","clk":"11541555132","pt":1719506993025,"mc":[{"id":"1.230178328","rc":[{"atb":[[1.04,0]],"id":53082422}],"con":true,"img":false}]}
{"op":"mcm","clk":"11541555142","pt":1719506993126,"mc":[{"id":"1.230178328","rc":[{"atb":[[2.64,0.61]],"id":53082422}],"con":true,"img":false}]}
{"op":"mcm","clk":"11541555277","pt":1719506995136,"mc":[{"id":"1.230178328","rc":[{"atb":[[2.74,7.29]],"id":64812720}],"con":true,"img":false}]}
{"op":"mcm","clk":"11541555294","pt":1719506995346,"mc":[{"id":"1.230178328","rc":[{"atb":[[2.76,3.38]],"id":70053016}],"con":true,"img":false}]}
{"op":"mcm","clk":"11541555300","pt":1719506995448,"mc":[{"id":"1.230178328","rc":[{"atb":[[2.1,11.54]],"id":53082422}],"con":true,"img":false}]}
{"op":"mcm","clk":"11541555314","pt":1719506995657,"mc":[{"id":"1.230178328","rc":[{"atb":[[2.76,10.59]],"id":70053016}],"con":true,"img":false}]}
{"op":"mcm","clk":"11541555335","pt":1719506995929,"mc":[{"id":"1.230178328","rc":[{"atb":[[3.3,5.51]],"id":69942666}],"con":true,"img":false}]}
{"op":"mcm","clk":"11541555351","pt":1719506996227,"mc":[{"id":"1.230178328","rc":[{"atb":[[2.76,7.21]],"id":70902603}],"con":true,"img":false}]}
{"op":"mcm","clk":"11541555363","pt":1719506996536,"mc":[{"id":"1.230178328","rc":[{"atb":[[2.78,4.28]],"id":70053016}],"con":true,"img":false}]}
{"op":"mcm","clk":"11541555381","pt":1719506996845,"mc":[{"id":"1.230178328","rc":[{"atb":[[1.73,11.59]],"id":53082422}],"con":true,"img":false}]}
{"op":"mcm","clk":"11541555399","pt":1719506997155,"mc":[{"id":"1.230178328","rc":[{"atb":[[2.44,5.87]],"id":70053016}],"con":true,"img":false}]}
{"op":"mcm","clk":"11541555464","pt":1719506998446,"mc":[{"id":"1.230178328","rc":[{"atb":[[2.34,24.38]],"id":53082422}],"con":true,"img":false}]}
{"op":"mcm","clk":"11541555573","pt":1719507000663,"mc":[{"id":"1.230178328","rc":[{"spn":7.5,"spf":"NaN","id":70902603},{"atl":[[1000,0.79]],"id":53082422},{"spn":2.59,"spf":1.0,"id":53082422}],"con":true,"img":false}]}
{"op":"mcm","clk":"11541555595","pt":1719507001067,"mc":[{"id":"1.230178328","rc":[{"atb":[[4.5,1.84]],"id":69942666}],"con":true,"img":false}]}
{"op":"mcm","clk":"11541555618","pt":1719507001434,"mc":[{"id":"1.230178328","rc":[{"atb":[[2.34,12.08]],"id":53082422}],"con":true,"img":false}]}
{"op":"mcm","clk":"11541555710","pt":1719507002754,"mc":[{"id":"1.230178328","rc":[{"atl":[[10.5,0]],"id":70902603}],"con":true,"img":false}]}
{"op":"mcm","clk":"11541555749","pt":1719507003370,"mc":[{"id":"1.230178328","rc":[{"atl":[[1000,0.27]],"id":70902603}],"con":true,"img":false}]}
{"op":"mcm","clk":"11541555776","pt":1719507003644,"mc":[{"id":"1.230178328","rc":[{"atl":[[1000,0.16]],"id":70902603}],"con":true,"img":false}]}
{"op":"mcm","clk":"11541555784","pt":1719507003737,"mc":[{"id":"1.230178328","rc":[{"atl":[[10.5,0.11]],"id":70902603}],"con":true,"img":false}]}
{"op":"mcm","clk":"11541555824","pt":1719507004151,"mc":[{"id":"1.230178328","rc":[{"atb":[[4.5,0]],"id":69942666}],"con":true,"img":false}]}
{"op":"mcm","clk":"11541555848","pt":1719507004462,"mc":[{"id":"1.230178328","rc":[{"atb":[[4.6,1.46]],"id":69942666}],"con":true,"img":false}]}
{"op":"mcm","clk":"11541555940","pt":1719507005837,"mc":[{"id":"1.230178328","rc":[{"atl":[[8.8,0]],"id":70053016}],"con":true,"img":false}]}
{"op":"mcm","clk":"11541555959","pt":1719507006049,"mc":[{"id":"1.230178328","rc":[{"atl":[[1000,0.13]],"id":70053016}],"con":true,"img":false}]}
{"op":"mcm","clk":"11541555984","pt":1719507006357,"mc":[{"id":"1.230178328","rc":[{"atl":[[1000,0]],"id":70053016}],"con":true,"img":false}]}
{"op":"mcm","clk":"11541555993","pt":1719507006465,"mc":[{"id":"1.230178328","rc":[{"atl":[[8.8,0.13]],"id":70053016}],"con":true,"img":false}]}
{"op":"mcm","clk":"11541556103","pt":1719507008282,"mc":[{"id":"1.230178328","rc":[{"atb":[[2.64,0]],"id":53082422}],"con":true,"img":false}]}
{"op":"mcm","clk":"11541556122","pt":1719507008480,"mc":[{"id":"1.230178328","rc":[{"atb":[[1.04,1]],"id":53082422}],"con":true,"img":false}]}
{"op":"mcm","clk":"11541556135","pt":1719507008650,"mc":[{"id":"1.230178328","rc":[{"atb":[[1.04,0.61]],"id":53082422}],"con":true,"img":false}]}
{"op":"mcm","clk":"11541556163","pt":1719507008963,"mc":[{"id":"1.230178328","rc":[{"atb":[[1.04,0]],"id":53082422}],"con":true,"img":false}]}
{"op":"mcm","clk":"11541556172","pt":1719507009066,"mc":[{"id":"1.230178328","rc":[{"atb":[[2.64,0.61]],"id":53082422}],"con":true,"img":false}]}
{"op":"mcm","clk":"11541556182","pt":1719507009170,"mc":[{"id":"1.230178328","rc":[{"atb":[[2.4,10.64]],"id":70053016}],"con":true,"img":false}]}
{"op":"mcm","clk":"11541556189","pt":1719507009273,"mc":[{"id":"1.230178328","rc":[{"atb":[[2.68,4.76]],"id":70053016}],"con":true,"img":false}]}
{"op":"mcm","clk":"11541556209","pt":1719507009575,"mc":[{"id":"1.230178328","rc":[{"atb":[[2.78,7.44]],"id":70053016}],"con":true,"img":false}]}
{"op":"mcm","clk":"11541556783","pt":1719507018343,"mc":[{"id":"1.230178328","rc":[{"atb":[[4.6,0]],"id":69942666}],"con":true,"img":false}]}
{"op":"mcm","clk":"11541556799","pt":1719507018552,"mc":[{"id":"1.230178328","rc":[{"atb":[[4.7,2.58]],"id":69942666}],"con":true,"img":false}]}
{"op":"mcm","clk":"11541556830","pt":1719507018969,"mc":[{"id":"1.230178328","rc":[{"atl":[[10.5,0]],"id":70902603}],"con":true,"img":false}]}
{"op":"mcm","clk":"11541556842","pt":1719507019174,"mc":[{"id":"1.230178328","rc":[{"atl":[[1000,0.27]],"id":70902603}],"con":true,"img":false}]}
{"op":"mcm","clk":"11541556861","pt":1719507019380,"mc":[{"id":"1.230178328","rc":[{"atl":[[1000,0.16]],"id":70902603}],"con":true,"img":false}]}
{"op":"mcm","clk":"11541556872","pt":1719507019481,"mc":[{"id":"1.230178328","rc":[{"atl":[[10.5,0.11]],"id":70902603}],"con":true,"img":false}]}
{"op":"mcm","clk":"11541556899","pt":1719507019849,"mc":[{"id":"1.230178328","rc":[{"atb":[[4.7,0]],"id":69942666}],"con":true,"img":false}]}
{"op":"mcm","clk":"11541556918","pt":1719507020162,"mc":[{"id":"1.230178328","rc":[{"atb":[[4.7,4.09]],"id":69942666}],"con":true,"img":false}]}
{"op":"mcm","clk":"11541557031","pt":1719507021665,"mc":[{"id":"1.230178328","rc":[{"atl":[[8.8,0]],"id":70053016}],"con":true,"img":false}]}
{"op":"mcm","clk":"11541557081","pt":1719507022073,"mc":[{"id":"1.230178328","rc":[{"atl":[[1000,0.13]],"id":70053016}],"con":true,"img":false}]}
{"op":"mcm","clk":"11541557090","pt":1719507022280,"mc":[{"id":"1.230178328","rc":[{"atl":[[1000,0]],"id":70053016}],"con":true,"img":false}]}
{"op":"mcm","clk":"11541557098","pt":1719507022384,"mc":[{"id":"1.230178328","rc":[{"atl":[[8.8,0.13]],"id":70053016}],"con":true,"img":false}]}
{"op":"mcm","clk":"11541557111","pt":1719507022591,"mc":[{"id":"1.230178328","rc":[{"atb":[[2.7,0]],"id":64812720},{"atb":[[3.25,0]],"id":69942666},{"atb":[[1.71,0]],"id":53082422}],"con":true,"img":false}]}
{"op":"mcm","clk":"11541557128","pt":1719507022789,"mc":[{"id":"1.230178328","rc":[{"atl":[[8.8,1.09]],"id":70053016}],"con":true,"img":false}]}
{"op":"mcm","clk":"11541557137","pt":1719507022859,"mc":[{"id":"1.230178328","rc":[{"atl":[[10,4],[48,0]],"id":70053016},{"atl":[[1000,1.01]],"id":69942666}],"con":true,"img":false}]}
{"op":"mcm","clk":"11541557143","pt":1719507022953,"mc":[{"id":"1.230178328","rc":[{"atb":[[5.8,1.45]],"id":69942666}],"con":true,"img":false}]}
{"op":"mcm","clk":"11541557158","pt":1719507023161,"mc":[{"id":"1.230178328","rc":[{"atl":[[10,0.84]],"id":70902603},{"atb":[[5.8,3.45],[5.6,2]],"id":69942666}],"con":true,"img":false}]}
{"op":"mcm","clk":"11541557159","pt":1719507023252,"mc":[{"id":"1.230178328","rc":[{"atl":[[95,0],[14,4]],"id":70902603},{"atl":[[1000,0.41]],"id":69942666}],"con":true,"img":false}]}
{"op":"mcm","clk":"11541557172","pt":1719507023470,"mc":[{"id":"1.230178328","rc":[{"atb":[[5.2,1.62]],"id":66686625}],"con":true,"img":false}]}
{"op":"mcm","clk":"11541557184","pt":1719507023572,"mc":[{"id":"1.230178328","rc":[{"atb":[[5.8,2]],"id":69942666}],"con":true,"img":false}]}
{"op":"mcm","clk":"11541557193","pt":1719507023676,"mc":[{"id":"1.230178328","rc":[{"atb":[[3.7,9.5],[3.15,0]],"id":66686625}],"con":true,"img":false}]}
{"op":"mcm","clk":"11541557205","pt":1719507023874,"mc":[{"id":"1.230178328","rc":[{"atb":[[5.9,0.84],[5.7,2.3]],"id":69942666}],"con":true,"img":false}]}
{"op":"mcm","clk":"11541557212","pt":1719507023978,"mc":[{"id":"1.230178328","rc":[{"atl":[[1000,0.16]],"id":69942666}],"con":true,"img":false}]}
{"op":"mcm","clk":"11541557218","pt":1719507024081,"mc":[{"id":"1.230178328","rc":[{"atl":[[34,0.24]],"id":69942666}],"con":true,"img":false}]}
{"op":"mcm","clk":"11541557227","pt":1719507024193,"mc":[{"id":"1.230178328","rc":[{"atb":[[5.2,1.62]],"id":64812720}],"con":true,"img":false}]}
{"op":"mcm","clk":"11541557236","pt":1719507024291,"mc":[{"id":"1.230178328","rc":[{"atb":[[3.95,7.3]],"id":64812720},{"atb":[[2.64,0]],"id":53082422}],"con":true,"img":false}]}
{"op":"mcm","clk":"11541557243","pt":1719507024392,"mc":[{"id":"1.230178328","rc":[{"atb":[[3.35,0]],"id":64812720},{"atb":[[5.1,1.68]],"id":66686625}],"con":true,"img":false}]}
{"op":"mcm","clk":"11541557253","pt":1719507024459,"mc":[{"id":"1.230178328","rc":[{"atb":[[1.04,1]],"id":53082422}],"con":true,"img":false}]}
{"op":"mcm","clk":"11541557266","pt":1719507024664,"mc":[{"id":"1.230178328","rc":[{"atb":[[5.2,0]],"id":66686625},{"atb":[[5.6,0]],"id":69942666},{"atb":[[1.04,0.61]],"id":53082422}],"con":true,"img":false}]}
{"op":"mcm","clk":"11541557274","pt":1719507024773,"mc":[{"id":"1.230178328","rc":[{"atb":[[5.9,2.84],[5.7,0.84]],"id":69942666}],"con":true,"img":false}]}
{"op":"mcm","clk":"11541557280","pt":1719507024877,"mc":[{"id":"1.230178328","rc":[{"atb":[[1.04,0]],"id":53082422}],"con":true,"img":false}]}
{"op":"mcm","clk":"11541557287","pt":1719507024977,"mc":[{"id":"1.230178328","rc":[{"atb":[[5.9,4.27]],"id":69942666},{"atb":[[2.64,0.61]],"id":53082422}],"con":true,"img":false}]}
{"op":"mcm","clk":"11541557304","pt":1719507025184,"mc":[{"id":"1.230178328","rc":[{"atb":[[5.2,0]],"id":64812720}],"con":true,"img":false}]}
{"op":"mcm","clk":"11541557323","pt":1719507025388,"mc":[{"id":"1.230178328","rc":[{"atb":[[5.7,0]],"id":69942666}],"con":true,"img":false}]}
{"op":"mcm","clk":"11541557329","pt":1719507025489,"mc":[{"id":"1.230178328","rc":[{"atb":[[5.1,1.68]],"id":64812720}],"con":true,"img":false}]}
{"op":"mcm","clk":"11541557354","pt":1719507025793,"mc":[{"id":"1.230178328","rc":[{"atb":[[5.1,0.05],[5.3,1.59]],"id":66686625}],"con":true,"img":false}]}
{"op":"mcm","clk":"11541557553","pt":1719507028277,"mc":[{"id":"1.230178328","rc":[{"atb":[[2.16,18.1]],"id":66686625},{"atb":[[2.44,0]],"id":70053016},{"atb":[[1.73,0]],"id":53082422}],"con":true,"img":false}]}
{"op":"mcm","clk":"11541557575","pt":1719507028680,"mc":[{"id":"1.230178328","rc":[{"atb":[[2.16,11.29]],"id":66686625}],"con":true,"img":false}]}
{"op":"mcm","clk":"11541557582","pt":1719507028793,"mc":[{"id":"1.230178328","rc":[{"atb":[[2.8,3.95]],"id":70053016}],"con":true,"img":false}]}
{"op":"mcm","clk":"11541557672","pt":1719507029888,"mc":[{"id":"1.230178328","rc":[{"atb":[[2.48,0],[2.88,2.09]],"id":70053016}],"con":true,"img":false}]}
{"op":"mcm","clk":"11541557756","pt":1719507031283,"mc":[{"id":"1.230178328","rc":[{"atb":[[5.8,0],[6,2]],"id":69942666}],"con":true,"img":false}]}
{"op":"mcm","clk":"11541557775","pt":1719507031592,"mc":[{"id":"1.230178328","rc":[{"atb":[[5.9,2.84],[6.2,1.36]],"id":69942666}],"con":true,"img":false}]}
{"op":"mcm","clk":"11541557832","pt":1719507032303,"mc":[{"id":"1.230178328","rc":[{"atb":[[5.9,0.84]],"id":69942666}],"con":true,"img":false}]}
{"op":"mcm","clk":"11541557839","pt":1719507032407,"mc":[{"id":"1.230178328","rc":[{"atb":[[2.78,13.8]],"id":70053016},{"atb":[[6.4,2]],"id":69942666}],"con":true,"img":false}]}
{"op":"mcm","clk":"11541557868","pt":1719507032819,"mc":[{"id":"1.230178328","rc":[{"atl":[[12,7.04]],"id":64812720}],"con":true,"img":false}]}
{"op":"mcm","clk":"11541557873","pt":1719507032881,"mc":[{"id":"1.230178328","rc":[{"atb":[[6.6,0.84]],"id":69942666}],"con":true,"img":false}]}
{"op":"mcm","clk":"11541557877","pt":1719507032983,"mc":[{"id":"1.230178328","rc":[{"atb":[[5.9,0]],"id":69942666}],"con":true,"img":false}]}
{"op":"mcm","clk":"11541557940","pt":1719507033915,"mc":[{"id":"1.230178328","rc":[{"atl":[[12,0]],"id":64812720},{"atb":[[2.78,7.44]],"id":70053016}],"con":true,"img":false}]}
{"op":"mcm","clk":"11541557991","pt":1719507034798,"mc":[{"id":"1.230178328","rc":[{"atl":[[10.5,0]],"id":70902603}],"con":true,"img":false}]}
{"op":"mcm","clk":"11541558015","pt":1719507035111,"mc":[{"id":"1.230178328","rc":[{"atl":[[1000,0.27]],"id":70902603},{"atb":[[5.1,1.65],[5.3,0]],"id":66686625}],"con":true,"img":false}]}
{"op":"mcm","clk":"11541558028","pt":1719507035314,"mc":[{"id":"1.230178328","rc":[{"atl":[[1000,0.16]],"id":70902603}],"con":true,"img":false}]}
{"op":"mcm","clk":"11541558037","pt":1719507035419,"mc":[{"id":"1.230178328","rc":[{"atl":[[10.5,0.11]],"id":70902603}],"con":true,"img":false}]}
{"op":"mcm","clk":"11541558044","pt":1719507035514,"mc":[{"id":"1.230178328","rc":[{"atb":[[2.34,24.38]],"id":53082422}],"con":true,"img":false}]}
{"op":"mcm","clk":"11541558052","pt":1719507035618,"mc":[{"id":"1.230178328","rc":[{"atb":[[4.7,0]],"id":69942666}],"con":true,"img":false}]}
{"op":"mcm","clk":"11541558069","pt":1719507035891,"mc":[{"id":"1.230178328","rc":[{"atb":[[2.74,0]],"id":70902603},{"atb":[[2.74,0]],"id":70053016}],"con":true,"img":false}]}
{"op":"mcm","clk":"11541558172","pt":1719507037595,"mc":[{"id":"1.230178328","rc":[{"atl":[[8.8,0.96]],"id":70053016}],"con":true,"img":false}]}
{"op":"mcm","clk":"11541558179","pt":1719507037702,"mc":[{"id":"1.230178328","rc":[{"atl":[[9.8,1.03]],"id":70053016}],"con":true,"img":false}]}
{"op":"mcm","clk":"11541558189","pt":1719507037804,"mc":[{"id":"1.230178328","rc":[{"atl":[[1000,0.13]],"id":70053016},{"atb":[[2.34,12.08]],"id":53082422}],"con":true,"img":false}]}
{"op":"mcm","clk":"11541558208","pt":1719507038009,"mc":[{"id":"1.230178328","rc":[{"atl":[[1000,0]],"id":70053016}],"con":true,"img":false}]}
{"op":"mcm","clk":"11541558214","pt":1719507038114,"mc":[{"id":"1.230178328","rc":[{"atl":[[8.6,0.13]],"id":70053016}],"con":true,"img":false}]}
{"op":"mcm","clk":"11541558282","pt":1719507039096,"mc":[{"id":"1.230178328","rc":[{"atb":[[5.5,3.95]],"id":69942666}],"con":true,"img":false}]}
{"op":"mcm","clk":"11541558298","pt":1719507039304,"mc":[{"id":"1.230178328","rc":[{"atb":[[6.2,4.21],[6,0]],"id":69942666}],"con":true,"img":false}]}
{"op":"mcm","clk":"11541558392","pt":1719507040227,"mc":[{"id":"1.230178328","rc":[{"atb":[[2.64,0]],"id":53082422}],"con":true,"img":false}]}
{"op":"mcm","clk":"11541558409","pt":1719507040396,"mc":[{"id":"1.230178328","rc":[{"atb":[[1.04,1]],"id":53082422}],"con":true,"img":false}]}
{"op":"mcm","clk":"11541558419","pt":1719507040602,"mc":[{"id":"1.230178328","rc":[{"atb":[[1.04,0.61]],"id":53082422}],"con":true,"img":false}]}
{"op":"mcm","clk":"11541558436","pt":1719507040809,"mc":[{"id":"1.230178328","rc":[{"atb":[[1.04,0]],"id":53082422}],"con":true,"img":false}]}
{"op":"mcm","clk":"11541558457","pt":1719507040911,"mc":[{"id":"1.230178328","rc":[{"atb":[[2.64,0.61]],"id":53082422}],"con":true,"img":false}]}
{"op":"mcm","clk":"11541558532","pt":1719507041902,"mc":[{"id":"1.230178328","rc":[{"atb":[[5.5,1]],"id":69942666}],"con":true,"img":false}]}
{"op":"mcm","clk":"11541558710","pt":1719507044390,"mc":[{"id":"1.230178328","rc":[{"atb":[[2.1,22.32]],"id":53082422}],"con":true,"img":false}]}
{"op":"mcm","clk":"11541558717","pt":1719507044492,"mc":[{"id":"1.230178328","rc":[{"atb":[[2.84,4.72]],"id":70053016}],"con":true,"img":false}]}
{"op":"mcm","clk":"11541558722","pt":1719507044593,"mc":[{"id":"1.230178328","rc":[{"atb":[[2.8,10.53]],"id":70053016}],"con":true,"img":false}]}
{"op":"mcm","clk":"11541558730","pt":1719507044700,"mc":[{"id":"1.230178328","rc":[{"atb":[[3.05,4.24]],"id":70902603}],"con":true,"img":false}]}
{"op":"mcm","clk":"11541558737","pt":1719507044806,"mc":[{"id":"1.230178328","rc":[{"atb":[[2.4,5.64]],"id":64812720}],"con":true,"img":false}]}
{"op":"mcm","clk":"11541558761","pt":1719507045012,"mc":[{"id":"1.230178328","rc":[{"atb":[[2.78,6.66]],"id":70902603}],"con":true,"img":false}]}
{"op":"mcm","clk":"11541558779","pt":1719507045216,"mc":[{"id":"1.230178328","rc":[{"atb":[[3.15,5.51]],"id":66686625},{"atb":[[3.45,4.83]],"id":69942666}],"con":true,"img":false}]}
{"op":"mcm","clk":"11541559157","pt":1719507050638,"mc":[{"id":"1.230178328","rc":[{"atl":[[10.5,0]],"id":70902603}],"con":true,"img":false}]}
{"op":"mcm","clk":"11541559169","pt":1719507050786,"mc":[{"id":"1.230178328","rc":[{"atl":[[1000,0.27]],"id":70902603}],"con":true,"img":false}]}
{"op":"mcm","clk":"11541559183","pt":1719507051003,"mc":[{"id":"1.230178328","rc":[{"atl":[[1000,0.16]],"id":70902603}],"con":true,"img":false}]}
{"op":"mcm","clk":"11541559189","pt":1719507051106,"mc":[{"id":"1.230178328","rc":[{"atl":[[10.5,0.11]],"id":70902603}],"con":true,"img":false}]}
{"op":"mcm","clk":"11541559282","pt":1719507052400,"mc":[{"id":"1.230178328","rc":[{"atb":[[5,6.18]],"id":69942666}],"con":true,"img":false}]}
{"op":"mcm","clk":"11541559318","pt":1719507052810,"mc":[{"id":"1.230178328","rc":[{"atl":[[8.4,1]],"id":70053016}],"con":true,"img":false}]}
{"op":"mcm","clk":"11541559341","pt":1719507053028,"mc":[{"id":"1.230178328","rc":[{"atl":[[8.8,0]],"id":70053016},{"atb":[[5,1]],"id":69942666}],"con":true,"img":false}]}
{"op":"mcm","clk":"11541559358","pt":1719507053231,"mc":[{"id":"1.230178328","rc":[{"atl":[[8.6,0]],"id":70053016},{"atb":[[5.1,1.43]],"id":69942666}],"con":true,"img":false}]}
{"op":"mcm","clk":"11541559364","pt":1719507053325,"mc":[{"id":"1.230178328","rc":[{"atl":[[8.4,0]],"id":70053016}],"con":true,"img":false}]}
{"op":"mcm","clk":"11541559383","pt":1719507053546,"mc":[{"id":"1.230178328","rc":[{"atl":[[1000,0.13]],"id":70053016}],"con":true,"img":false}]}
{"op":"mcm","clk":"11541559393","pt":1719507053638,"mc":[{"id":"1.230178328","rc":[{"atl":[[8.8,1],[1000,0]],"id":70053016}],"con":true,"img":false}]}
{"op":"mcm","clk":"11541559404","pt":1719507053743,"mc":[{"id":"1.230178328","rc":[{"atl":[[8.6,0.13]],"id":70053016}],"con":true,"img":false}]}
{"op":"mcm","clk":"11541559534","pt":1719507055612,"mc":[{"id":"1.230178328","rc":[{"atb":[[2.76,1.28]],"id":53082422}],"con":true,"img":false}]}
{"op":"mcm","clk":"11541559541","pt":1719507055715,"mc":[{"id":"1.230178328","rc":[{"atb":[[2.44,0],[2.74,2.56]],"id":53082422}],"con":true,"img":false}]}
{"op":"mcm","clk":"11541559562","pt":1719507056028,"mc":[{"id":"1.230178328","rc":[{"atb":[[2.64,0]],"id":53082422}],"con":true,"img":false}]}
{"op":"mcm","clk":"11541559580","pt":1719507056250,"mc":[{"id":"1.230178328","rc":[{"atb":[[1.04,1]],"id":53082422}],"con":true,"img":false}]}
{"op":"mcm","clk":"11541559594","pt":1719507056409,"mc":[{"id":"1.230178328","rc":[{"atb":[[1.04,0.61]],"id":53082422}],"con":true,"img":false}]}
{"op":"mcm","clk":"11541559600","pt":1719507056500,"mc":[{"id":"1.230178328","rc":[{"atb":[[2.62,0]],"id":53082422}],"con":true,"img":false}]}
{"op":"mcm","clk":"11541559612","pt":1719507056654,"mc":[{"id":"1.230178328","rc":[{"atb":[[1.04,0]],"id":53082422}],"con":true,"img":false}]}
{"op":"mcm","clk":"11541559620","pt":1719507056709,"mc":[{"id":"1.230178328","rc":[{"atb":[[2.64,0.61]],"id":53082422}],"con":true,"img":false}]}
{"op":"mcm","clk":"11541559674","pt":1719507057233,"mc":[{"id":"1.230178328","rc":[{"atl":[[3,22]],"id":53082422}],"con":true,"img":false}]}
{"op":"mcm","clk":"11541559989","pt":1719507062142,"mc":[{"id":"1.230178328","rc":[{"spn":7.25,"spf":"NaN","id":70902603},{"spn":6.27,"spf":"NaN","id":70053016},{"spn":6.5,"spf":1.0,"id":69942666},{"atb":[[2.84,51.05]],"id":53082422},{"spn":2.84,"spf":1.0,"id":53082422}],"con":true,"img":false}]}
{"op":"mcm","clk":"11541560055","pt":1719507062819,"mc":[{"id":"1.230178328","rc":[{"atb":[[2.86,0.84]],"id":53082422}],"con":true,"img":false}]}
{"op":"mcm","clk":"11541560114","pt":1719507063621,"mc":[{"id":"1.230178328","rc":[{"atb":[[2.36,3.38],[2.38,5.51]],"id":53082422}],"con":true,"img":false}]}
{"op":"mcm","clk":"11541560129","pt":1719507063827,"mc":[{"id":"1.230178328","rc":[{"atb":[[2.76,6.73]],"id":64812720}],"con":true,"img":false}]}
{"op":"mcm","clk":"11541560143","pt":1719507064038,"mc":[{"id":"1.230178328","rc":[{"atb":[[2.16,18.58]],"id":69942666},{"atb":[[1.53,0]],"id":53082422}],"con":true,"img":false}]}
{"op":"mcm","clk":"11541560308","pt":1719507066151,"mc":[{"id":"1.230178328","rc":[{"atb":[[1.04,1.7]],"id":66686625},{"atl":[[1000,1.87]],"id":66686625},{"atb":[[1.02,103.56]],"id":70053016},{"atl":[[1000,1.7]],"id":70053016}],"con":true,"img":false}]}
{"op":"mcm","clk":"11541560313","pt":1719507066243,"mc":[{"id":"1.230178328","rc":[{"atl":[[10.5,0]],"id":70902603}],"con":true,"img":false}]}
{"op":"mcm","clk":"11541560320","pt":1719507066346,"mc":[{"id":"1.230178328","rc":[{"atb":[[1.04,0.07]],"id":66686625},{"atl":[[1000,0.18]],"id":66686625},{"atb":[[1.02,102]],"id":70053016},{"atl":[[1000,0.03]],"id":70053016}],"con":true,"img":false}]}
{"op":"mcm","clk":"11541560327","pt":1719507066451,"mc":[{"id":"1.230178328","rc":[{"atl":[[1000,0.27]],"id":70902603}],"con":true,"img":false}]}
{"op":"mcm","clk":"11541560340","pt":1719507066553,"mc":[{"id":"1.230178328","rc":[{"atl":[[1000,0.16]],"id":70902603},{"atb":[[1.04,0]],"id":66686625},{"atl":[[1000,0.16]],"id":66686625},{"atb":[[1.02,101.86]],"id":70053016},{"atl":[[1000,0]],"id":70053016}],"con":true,"img":false}]}
{"op":"mcm","clk":"11541560345","pt":1719507066618,"mc":[{"id":"1.230178328","rc":[{"atl":[[10.5,0.11]],"id":70902603},{"atb":[[5.1,1.73]],"id":66686625},{"atl":[[21,0.01]],"id":66686625},{"atb":[[3.05,0.14]],"id":70053016},{"atl":[[8.8,1.04]],"id":70053016}],"con":true,"img":false}]}
{"op":"mcm","clk":"11541560380","pt":1719507067132,"mc":[{"id":"1.230178328","rc":[{"atb":[[4,10.72]],"id":70053016}],"con":true,"img":false}]}
{"op":"mcm","clk":"11541560399","pt":1719507067339,"mc":[{"id":"1.230178328","rc":[{"atb":[[5.2,0.84]],"id":66686625},{"atb":[[2.98,1],[3.3,11.72]],"id":70053016}],"con":true,"img":false}]}
{"op":"mcm","clk":"11541560533","pt":1719507068640,"mc":[{"id":"1.230178328","rc":[{"atb":[[2.84,0]],"id":53082422}],"con":true,"img":false}]}
{"op":"mcm","clk":"11541560537","pt":1719507068733,"mc":[{"id":"1.230178328","rc":[{"atb":[[2.86,51.89]],"id":53082422}],"con":true,"img":false}]}
{"op":"mcm","clk":"11541560555","pt":1719507068948,"mc":[{"id":"1.230178328","rc":[{"atl":[[8.6,0]],"id":70053016},{"atb":[[5.1,0]],"id":69942666}],"con":true,"img":false}]}
{"op":"mcm","clk":"11541560567","pt":1719507069154,"mc":[{"id":"1.230178328","rc":[{"atl":[[1000,0.13]],"id":70053016},{"atb":[[5.1,3.76]],"id":69942666}],"con":true,"img":false}]}
{"op":"mcm","clk":"11541560579","pt":1719507069363,"mc":[{"id":"1.230178328","rc":[{"atl":[[1000,0]],"id":70053016}],"con":true,"img":false}]}
{"op":"mcm","clk":"11541560588","pt":1719507069424,"mc":[{"id":"1.230178328","rc":[{"atl":[[8.6,0.13]],"id":70053016}],"con":true,"img":false}]}
{"op":"mcm","clk":"11541560596","pt":1719507069527,"mc":[{"id":"1.230178328","rc":[{"atb":[[5.1,0]],"id":69942666}],"con":true,"img":false}]}
{"op":"mcm","clk":"11541560613","pt":1719507069728,"mc":[{"id":"1.230178328","rc":[{"atb":[[5.2,1.49]],"id":69942666}],"con":true,"img":false}]}
{"op":"mcm","clk":"11541560619","pt":1719507069841,"mc":[{"id":"1.230178328","rc":[{"atb":[[2.74,0]],"id":64812720},{"atb":[[2.76,3.38]],"id":70053016},{"atb":[[3.3,0]],"id":69942666}],"con":true,"img":false}]}
{"op":"mcm","clk":"11541560634","pt":1719507070045,"mc":[{"id":"1.230178328","rc":[{"atb":[[2.86,0.84]],"id":53082422}],"con":true,"img":false}]}
{"op":"mcm","clk":"11541560650","pt":1719507070248,"mc":[{"id":"1.230178328","rc":[{"atb":[[5.2,0.05]],"id":69942666}],"con":true,"img":false}]}
{"op":"mcm","clk":"11541560666","pt":1719507070436,"mc":[{"id":"1.230178328","rc":[{"atb":[[2.86,0]],"id":53082422}],"con":true,"img":false}]}
{"op":"mcm","clk":"11541560675","pt":1719507070539,"mc":[{"id":"1.230178328","rc":[{"atb":[[5.2,3.79]],"id":69942666},{"atl":[[3,1.57]],"id":53082422},{"trd":[[3,40.86]],"ltp":3.0,"tv":40.86,"id":53082422}],"con":true,"img":false}]}
{"op":"mcm","clk":"11541560703","pt":1719507070953,"mc":[{"id":"1.230178328","rc":[{"atb":[[3.85,1.68]],"id":70902603},{"atb":[[4.1,1.7]],"id":70053016},{"atb":[[6.4,3.65]],"id":69942666}],"con":true,"img":false}]}
{"op":"mcm","clk":"11541560719","pt":1719507071159,"mc":[{"id":"1.230178328","rc":[{"atl":[[11,0]],"id":64812720},{"atl":[[13,1]],"id":66686625}],"con":true,"img":false}]}
{"op":"mcm","clk":"11541560728","pt":1719507071228,"mc":[{"id":"1.230178328","rc":[{"atl":[[12.5,1],[29,0.79]],"id":64812720},{"atl":[[10.5,1.11],[11,0]],"id":70902603},{"atl":[[10.5,0],[21,0.8]],"id":66686625},{"atl":[[34,1.24],[36,0]],"id":69942666}],"con":true,"img":false}]}
{"op":"mcm","clk":"11541560732","pt":1719507071326,"mc":[{"id":"1.230178328","rc":[{"atl":[[10,0],[9.8,5.03]],"id":70053016},{"atb":[[2.74,0],[2.7,3.84]],"id":53082422}],"con":true,"img":false}]}
{"op":"mcm","clk":"11541560741","pt":1719507071435,"mc":[{"id":"1.230178328","rc":[{"atb":[[5.2,0.05]],"id":69942666},{"atb":[[2.72,3.84],[2.7,0]],"id":53082422},{"atl":[[3.2,3.64]],"id":53082422}],"con":true,"img":false}]}
{"op":"mcm","clk":"11541560764","pt":1719507071733,"mc":[{"id":"1.230178328","rc":[{"atb":[[5.4,3.69]],"id":69942666}],"con":true,"img":false}]}
{"op":"mcm","clk":"11541560773","pt":1719507071849,"mc":[{"id":"1.230178328","rc":[{"atl":[[29,0.46]],"id":64812720},{"atl":[[21,0.48]],"id":66686625},{"atb":[[4.2,6.04]],"id":70053016}],"con":true,"img":false}]}
{"op":"mcm","clk":"11541560781","pt":1719507071938,"mc":[{"id":"1.230178328","rc":[{"atb":[[2.64,0]],"id":53082422}],"con":true,"img":false}]}
{"op":"mcm","clk":"11541560807","pt":1719507072250,"mc":[{"id":"1.230178328","rc":[{"atb":[[4.3,1.97],[4.1,0]],"id":70053016}],"con":true,"img":false}]}
{"op":"mcm","clk":"11541560815","pt":1719507072354,"mc":[{"id":"1.230178328","rc":[{"atb":[[4.3,3.67]],"id":70053016},{"atb":[[5.4,0]],"id":69942666}],"con":true,"img":false}]}
{"op":"mcm","clk":"11541560824","pt":1719507072413,"mc":[{"id":"1.230178328","rc":[{"atb":[[3.85,4.49]],"id":70902603},{"atb":[[4.1,2.58]],"id":70053016}],"con":true,"img":false}]}
{"op":"mcm","clk":"11541560835","pt":1719507072515,"mc":[{"id":"1.230178328","rc":[{"atb":[[4.2,0]],"id":70053016}],"con":true,"img":false}]}
{"op":"mcm","clk":"11541560845","pt":1719507072627,"mc":[{"id":"1.230178328","rc":[{"atb":[[3.9,0.84]],"id":70902603},{"atb":[[4.4,0.84]],"id":70053016},{"atb":[[6.6,1.69]],"id":69942666}],"con":true,"img":false}]}
{"op":"mcm","clk":"11541560863","pt":1719507072842,"mc":[{"id":"1.230178328","rc":[{"atb":[[4.3,1.97]],"id":70053016}],"con":true,"img":false}]}
{"op":"mcm","clk":"11541560871","pt":1719507072940,"mc":[{"id":"1.230178328","rc":[{"atb":[[4.1,4.28]],"id":70053016}],"con":true,"img":false}]}
{"op":"mcm","clk":"11541560888","pt":1719507073135,"mc":[{"id":"1.230178328","rc":[{"atb":[[6.8,3.73]],"id":69942666}],"con":true,"img":false}]}
{"op":"mcm","clk":"11541560913","pt":1719507073446,"mc":[{"id":"1.230178328","rc":[{"atb":[[6.4,2]],"id":69942666}],"con":true,"img":false}]}
{"op":"mcm","clk":"11541560921","pt":1719507073551,"mc":[{"id":"1.230178328","rc":[{"atb":[[6.4,0],[7,1.65]],"id":69942666}],"con":true,"img":false}]}
{"op":"mcm","clk":"11541560933","pt":1719507073655,"mc":[{"id":"1.230178328","rc":[{"atb":[[6.8,5.73]],"id":69942666}],"con":true,"img":false}]}
{"op":"mcm","clk":"11541560950","pt":1719507073812,"mc":[{"id":"1.230178328","rc":[{"atb":[[6.8,2]],"id":69942666}],"con":true,"img":false}]}
{"op":"mcm","clk":"11541560966","pt":1719507074020,"mc":[{"id":"1.230178328","rc":[{"atb":[[7,0]],"id":69942666}],"con":true,"img":false}]}
{"op":"mcm","clk":"11541560991","pt":1719507074330,"mc":[{"id":"1.230178328","rc":[{"atb":[[7,0.84]],"id":69942666}],"con":true,"img":false}]}
{"op":"mcm","clk":"11541561037","pt":1719507074948,"mc":[{"id":"1.230178328","rc":[{"atb":[[3.9,0.27]],"id":70902603},{"atb":[[4.4,0.25]],"id":70053016},{"atb":[[6.6,1.11]],"id":69942666}],"con":true,"img":false}]}
{"op":"mcm","clk":"11541561216","pt":1719507077233,"mc":[{"id":"1.230178328","rc":[{"atb":[[4.4,0]],"id":70053016},{"atb":[[6.6,0.84]],"id":69942666}],"con":true,"img":false}]}
{"op":"mcm","clk":"11541561226","pt":1719507077337,"mc":[{"id":"1.230178328","rc":[{"atb":[[4.2,0.25]],"id":70053016},{"atb":[[6.8,2.27]],"id":69942666}],"con":true,"img":false}]}
{"op":"mcm","clk":"11541561250","pt":1719507077644,"mc":[{"id":"1.230178328","rc":[{"atb":[[4.3,0]],"id":70053016}],"con":true,"img":false}]}
{"op":"mcm","clk":"11541561259","pt":1719507077763,"mc":[{"id":"1.230178328","rc":[{"atb":[[4.2,2.22]],"id":70053016}],"con":true,"img":false}]}
{"op":"mcm","clk":"11541561282","pt":1719507077956,"mc":[{"id":"1.230178328","rc":[{"atb":[[6.8,0.27]],"id":69942666}],"con":true,"img":false}]}
{"op":"mcm","clk":"11541561293","pt":1719507078069,"mc":[{"id":"1.230178328","rc":[{"atb":[[6.4,2]],"id":69942666}],"con":true,"img":false}]}
{"op":"mcm","clk":"11541561300","pt":1719507078165,"mc":[{"id":"1.230178328","rc":[{"atb":[[4.3,5.9]],"id":70053016}],"con":true,"img":false}]}
{"op":"mcm","clk":"11541561319","pt":1719507078424,"mc":[{"id":"1.230178328","rc":[{"atb":[[7,0]],"id":69942666}],"con":true,"img":false}]}
{"op":"mcm","clk":"11541561330","pt":1719507078529,"mc":[{"id":"1.230178328","rc":[{"atb":[[4.2,0.25]],"id":70053016}],"con":true,"img":false}]}
{"op":"mcm","clk":"11541561350","pt":1719507078735,"mc":[{"id":"1.230178328","rc":[{"atb":[[1.54,12.53]],"id":53082422}],"con":true,"img":false}]}
{"op":"mcm","clk":"11541561358","pt":1719507078837,"mc":[{"id":"1.230178328","rc":[{"atb":[[4.4,1.92],[4.1,2.58]],"id":70053016},{"atl":[[1000,0]],"id":53082422}],"con":true,"img":false}]}
{"op":"mcm","clk":"11541561370","pt":1719507078942,"mc":[{"id":"1.230178328","rc":[{"atb":[[4.4,3.62]],"id":70053016}],"con":true,"img":false}]}
{"op":"mcm","clk":"11541561391","pt":1719507079248,"mc":[{"id":"1.230178328","rc":[{"atb":[[4.3,0]],"id":70053016}],"con":true,"img":false}]}
{"op":"mcm","clk":"11541561403","pt":1719507079454,"mc":[{"id":"1.230178328","rc":[{"atb":[[2.16,18.58]],"id":64812720},{"atb":[[6.4,0]],"id":69942666}],"con":true,"img":false}]}
{"op":"mcm","clk":"11541561410","pt":1719507079556,"mc":[{"id":"1.230178328","rc":[{"atb":[[6.8,2]],"id":69942666}],"con":true,"img":false}]}
{"op":"mcm","clk":"11541561418","pt":1719507079660,"mc":[{"id":"1.230178328","rc":[{"atb":[[2.76,0]],"id":70053016},{"atb":[[1.13,0.27]],"id":69942666}],"con":true,"img":false}]}
{"op":"mcm","clk":"11541561426","pt":1719507079715,"mc":[{"id":"1.230178328","rc":[{"atb":[[3.05,8.78]],"id":70902603}],"con":true,"img":false}]}
{"op":"mcm","clk":"11541561442","pt":1719507079925,"mc":[{"id":"1.230178328","rc":[{"atb":[[1.53,15.96]],"id":53082422}],"con":true,"img":false}]}
{"op":"mcm","clk":"11541561448","pt":1719507080029,"mc":[{"id":"1.230178328","rc":[{"atb":[[4.4,1.92]],"id":70053016}],"con":true,"img":false}]}
{"op":"mcm","clk":"11541561451","pt":1719507080127,"mc":[{"id":"1.230178328","rc":[{"atb":[[2.78,3.16],[4.1,4.28]],"id":70053016}],"con":true,"img":false}]}
{"op":"mcm","clk":"11541561478","pt":1719507080541,"mc":[{"id":"1.230178328","rc":[{"atb":[[2.84,9.78]],"id":70053016}],"con":true,"img":false}]}
{"op":"mcm","clk":"11541561485","pt":1719507080648,"mc":[{"id":"1.230178328","rc":[{"atb":[[6.8,0]],"id":69942666}],"con":true,"img":false}]}
{"op":"mcm","clk":"11541561493","pt":1719507080744,"mc":[{"id":"1.230178328","rc":[{"atb":[[6.4,2]],"id":69942666}],"con":true,"img":false}]}
{"op":"mcm","clk":"11541561510","pt":1719507080961,"mc":[{"id":"1.230178328","rc":[{"atb":[[5,6.18]],"id":69942666}],"con":true,"img":false}]}
{"op":"mcm","clk":"11541561518","pt":1719507081154,"mc":[{"id":"1.230178328","rc":[{"atb":[[2.8,6.58]],"id":70053016},{"atb":[[6.4,3.65]],"id":69942666}],"con":true,"img":false}]}
{"op":"mcm","clk":"11541561539","pt":1719507081466,"mc":[{"id":"1.230178328","rc":[{"atb":[[2.78,0]],"id":70053016}],"con":true,"img":false}]}
{"op":"mcm","clk":"11541561556","pt":1719507081734,"mc":[{"id":"1.230178328","rc":[{"atb":[[2.4,5]],"id":70053016}],"con":true,"img":false}]}
{"op":"mcm","clk":"11541561560","pt":1719507081838,"mc":[{"id":"1.230178328","rc":[{"atl":[[10.5,1]],"id":70902603},{"atb":[[1.13,0]],"id":69942666}],"con":true,"img":false}]}
{"op":"mcm","clk":"11541561566","pt":1719507081935,"mc":[{"id":"1.230178328","rc":[{"atb":[[6.6,1.11]],"id":69942666}],"con":true,"img":false}]}
{"op":"mcm","clk":"11541561580","pt":1719507082148,"mc":[{"id":"1.230178328","rc":[{"atl":[[1000,0.27]],"id":70902603}],"con":true,"img":false}]}
{"op":"mcm","clk":"11541561596","pt":1719507082352,"mc":[{"id":"1.230178328","rc":[{"atl":[[1000,0.16]],"id":70902603}],"con":true,"img":false}]}
{"op":"mcm","clk":"11541561603","pt":1719507082456,"mc":[{"id":"1.230178328","rc":[{"atl":[[10,0.95]],"id":70902603},{"atb":[[6.4,2]],"id":69942666}],"con":true,"img":false}]}
{"op":"mcm","clk":"11541561620","pt":1719507082764,"mc":[{"id":"1.230178328","rc":[{"atb":[[6.4,0]],"id":69942666}],"con":true,"img":false}]}
{"op":"mcm","clk":"11541561630","pt":1719507082869,"mc":[{"id":"1.230178328","rc":[{"atb":[[6.8,2]],"id":69942666}],"con":true,"img":false}]}
{"op":"mcm","clk":"11541561654","pt":1719507083030,"mc":[{"id":"1.230178328","rc":[{"atb":[[5.1,0.13]],"id":66686625},{"atl":[[13.5,1]],"id":66686625},{"atl":[[9.8,1.03],[8.8,3.04]],"id":70053016}],"con":true,"img":false}]}
{"op":"mcm","clk":"11541561664","pt":1719507083137,"mc":[{"id":"1.230178328","rc":[{"atb":[[3.85,6],[5.3,1.59],[3.7,0]],"id":66686625},{"atl":[[13,0]],"id":66686625},{"atb":[[2.64,5.52]],"id":53082422},{"atl":[[5.8,8]],"id":53082422}],"con":true,"img":false}]}
{"op":"mcm","clk":"11541561675","pt":1719507083239,"mc":[{"id":"1.230178328","rc":[{"atb":[[2.72,0]],"id":53082422},{"atl":[[6.8,0]],"id":53082422}],"con":true,"img":false}]}
{"op":"mcm","clk":"11541561685","pt":1719507083340,"mc":[{"id":"1.230178328","rc":[{"atl":[[8.6,0.97]],"id":70053016},{"atb":[[7,0.84]],"id":69942666}],"con":true,"img":false}]}
{"op":"mcm","clk":"11541561695","pt":1719507083443,"mc":[{"id":"1.230178328","rc":[{"atb":[[5.1,1.73],[5.2,0]],"id":66686625}],"con":true,"img":false}]}
{"op":"mcm","clk":"11541561729","pt":1719507083757,"mc":[{"id":"1.230178328","rc":[{"atb":[[5.3,0]],"id":66686625}],"con":true,"img":false}]}
{"op":"mcm","clk":"11541561741","pt":1719507083862,"mc":[{"id":"1.230178328","rc":[{"atb":[[5.1,0.13]],"id":66686625}],"con":true,"img":false}]}
{"op":"mcm","clk":"11541561762","pt":1719507084062,"mc":[{"id":"1.230178328","rc":[{"atb":[[5.4,1.56]],"id":66686625}],"con":true,"img":false}]}
{"op":"mcm","clk":"11541561771","pt":1719507084166,"mc":[{"id":"1.230178328","rc":[{"atb":[[6.6,0.84]],"id":69942666}],"con":true,"img":false}]}
{"op":"mcm","clk":"11541561783","pt":1719507084269,"mc":[{"id":"1.230178328","rc":[{"atb":[[6.8,2.27]],"id":69942666}],"con":true,"img":false}]}
{"op":"mcm","clk":"11541561827","pt":1719507084735,"mc":[{"id":"1.230178328","rc":[{"atl":[[8.6,0.84]],"id":70053016}],"con":true,"img":false}]}
{"op":"mcm","clk":"11541561864","pt":1719507085152,"mc":[{"id":"1.230178328","rc":[{"atb":[[6.8,0.27],[5,1]],"id":69942666}],"con":true,"img":false}]}
{"op":"mcm","clk":"11541561874","pt":1719507085255,"mc":[{"id":"1.230178328","rc":[{"atb":[[6.4,2]],"id":69942666}],"con":true,"img":false}]}
{"op":"mcm","clk":"11541561903","pt":1719507085669,"mc":[{"id":"1.230178328","rc":[{"atl":[[1000,0.13]],"id":70053016}],"con":true,"img":false}]}
{"op":"mcm","clk":"11541561912","pt":1719507085873,"mc":[{"id":"1.230178328","rc":[{"atl":[[1000,0]],"id":70053016},{"atb":[[7,0]],"id":69942666}],"con":true,"img":false}]}
{"op":"mcm","clk":"11541561921","pt":1719507085939,"mc":[{"id":"1.230178328","rc":[{"atl":[[8.6,0.97]],"id":70053016}],"con":true,"img":false}]}
{"op":"mcm","clk":"11541561934","pt":1719507086134,"mc":[{"id":"1.230178328","rc":[{"atb":[[5.1,1.45]],"id":69942666}],"con":true,"img":false}]}
{"op":"mcm","clk":"11541561944","pt":1719507086359,"mc":[{"id":"1.230178328","rc":[{"atb":[[6.4,0]],"id":69942666}],"con":true,"img":false}]}
{"op":"mcm","clk":"11541561950","pt":1719507086444,"mc":[{"id":"1.230178328","rc":[{"atb":[[6.8,0],[5.1,0],[7,2]],"id":69942666}],"con":true,"img":false}]}
{"op":"mcm","clk":"11541561958","pt":1719507086546,"mc":[{"id":"1.230178328","rc":[{"atb":[[1.13,0.27]],"id":69942666}],"con":true,"img":false}]}
{"op":"mcm","clk":"11541561985","pt":1719507086856,"mc":[{"id":"1.230178328","rc":[{"atb":[[6.6,0]],"id":69942666}],"con":true,"img":false}]}
{"op":"mcm","clk":"11541561992","pt":1719507086960,"mc":[{"id":"1.230178328","rc":[{"atb":[[5.3,1.43]],"id":69942666}],"con":true,"img":false}]}
{"op":"mcm","clk":"11541562010","pt":1719507087272,"mc":[{"id":"1.230178328","rc":[{"atb":[[5.3,0]],"id":69942666}],"con":true,"img":false}]}
{"op":"mcm","clk":"11541562031","pt":1719507087534,"mc":[{"id":"1.230178328","rc":[{"atb":[[4.4,0],[4.3,1.92]],"id":70053016},{"atb":[[5.4,2.41],[7,0]],"id":69942666}],"con":true,"img":false}]}
{"op":"mcm","clk":"11541562041","pt":1719507087637,"mc":[{"id":"1.230178328","rc":[{"atb":[[6.4,2]],"id":69942666},{"atb":[[1.03,1.7]],"id":53082422},{"atl":[[1000,1.7]],"id":53082422}],"con":true,"img":false}]}
{"op":"mcm","clk":"11541562060","pt":1719507087845,"mc":[{"id":"1.230178328","rc":[{"atb":[[5.4,0]],"id":69942666}],"con":true,"img":false}]}
{"op":"mcm","clk":"11541562070","pt":1719507087946,"mc":[{"id":"1.230178328","rc":[{"atb":[[1.03,0.1]],"id":53082422},{"atl":[[1000,0.08]],"id":53082422}],"con":true,"img":false}]}
{"op":"mcm","clk":"11541562086","pt":1719507088153,"mc":[{"id":"1.230178328","rc":[{"atb":[[1.03,0]],"id":53082422},{"atl":[[1000,0]],"id":53082422}],"con":true,"img":false}]}
{"op":"mcm","clk":"11541562095","pt":1719507088257,"mc":[{"id":"1.230178328","rc":[{"atb":[[2.66,0.1]],"id":53082422},{"atl":[[3.15,0.08]],"id":53082422}],"con":true,"img":false}]}
{"op":"mcm","clk":"11541562124","pt":1719507088565,"mc":[{"id":"1.230178328","rc":[{"atb":[[5,2.44]],"id":69942666}],"con":true,"img":false}]}
{"op":"mcm","clk":"11541562145","pt":1719507088773,"mc":[{"id":"1.230178328","rc":[{"atb":[[5,1]],"id":69942666}],"con":true,"img":false}]}
{"op":"mcm","clk":"11541562180","pt":1719507089136,"mc":[{"id":"1.230178328","rc":[{"atb":[[5.1,1.45]],"id":69942666}],"con":true,"img":false}]}
{"op":"mcm","clk":"11541562193","pt":1719507089342,"mc":[{"id":"1.230178328","rc":[{"atl":[[9.8,5.03]],"id":70053016},{"atb":[[5.1,0]],"id":69942666}],"con":true,"img":false}]}
{"op":"mcm","clk":"11541562207","pt":1719507089448,"mc":[{"id":"1.230178328","rc":[{"atl":[[8.8,1.04]],"id":70053016}],"con":true,"img":false}]}
{"op":"mcm","clk":"11541562224","pt":1719507089751,"mc":[{"id":"1.230178328","rc":[{"atb":[[5.2,3.79]],"id":69942666}],"con":true,"img":false}]}
{"op":"mcm","clk":"11541562253","pt":1719507090062,"mc":[{"id":"1.230178328","rc":[{"atb":[[5.2,0.05]],"id":69942666}],"con":true,"img":false}]}
{"op":"mcm","clk":"11541562270","pt":1719507090369,"mc":[{"id":"1.230178328","rc":[{"atb":[[5.4,3.69]],"id":69942666}],"con":true,"img":false}]}
{"op":"mcm","clk":"11541562294","pt":1719507090679,"mc":[{"id":"1.230178328","rc":[{"atb":[[5.4,0]],"id":69942666}],"con":true,"img":false}]}
{"op":"mcm","clk":"11541562316","pt":1719507090842,"mc":[{"id":"1.230178328","rc":[{"atb":[[3.45,0],[6.6,0.84]],"id":69942666},{"atb":[[2.1,11.54]],"id":53082422}],"con":true,"img":false}]}
{"op":"mcm","clk":"11541562339","pt":1719507091143,"mc":[{"id":"1.230178328","rc":[{"atl":[[10.5,0],[11,1]],"id":70902603},{"atl":[[34,0.24],[36,1]],"id":69942666}],"con":true,"img":false}]}
{"op":"mcm","clk":"11541562349","pt":1719507091268,"mc":[{"id":"1.230178328","rc":[{"atl":[[12,4],[14,0]],"id":70902603}],"con":true,"img":false}]}
{"op":"mcm","clk":"11541562360","pt":1719507091371,"mc":[{"id":"1.230178328","rc":[{"atb":[[5,2.44]],"id":69942666}],"con":true,"img":false}]}
{"op":"mcm","clk":"11541562613","pt":1719507095264,"mc":[{"id":"1.230178328","rc":[{"atb":[[5.4,0],[5.1,1.69]],"id":66686625}],"con":true,"img":false}]}
{"op":"mcm","clk":"11541562637","pt":1719507095578,"mc":[{"id":"1.230178328","rc":[{"atb":[[5.2,1.62]],"id":66686625}],"con":true,"img":false}]}
{"op":"mcm","clk":"11541562732","pt":1719507096765,"mc":[{"id":"1.230178328","rc":[{"atl":[[9.8,1.03],[8.8,3.04]],"id":70053016}],"con":true,"img":false}]}
{"op":"mcm","clk":"11541562740","pt":1719507096971,"mc":[{"id":"1.230178328","rc":[{"atl":[[9,5],[8.8,1.04]],"id":70053016}],"con":true,"img":false}]}
{"op":"mcm","clk":"11541562743","pt":1719507097073,"mc":[{"id":"1.230178328","rc":[{"atl":[[8.8,2.18]],"id":70053016}],"con":true,"img":false}]}
{"op":"mcm","clk":"11541562787","pt":1719507097647,"mc":[{"id":"1.230178328","rc":[{"atl":[[10,0.84]],"id":70902603}],"con":true,"img":false}]}
{"op":"mcm","clk":"11541562800","pt":1719507097849,"mc":[{"id":"1.230178328","rc":[{"atl":[[1000,0.27]],"id":70902603}],"con":true,"img":false}]}
{"op":"mcm","clk":"11541562807","pt":1719507097953,"mc":[{"id":"1.230178328","rc":[{"atl":[[1000,0.16]],"id":70902603},{"atb":[[4.3,0]],"id":70053016}],"con":true,"img":false}]}
{"op":"mcm","clk":"11541562823","pt":1719507098057,"mc":[{"id":"1.230178328","rc":[{"atl":[[10.5,0.11]],"id":70902603}],"con":true,"img":false}]}
{"op":"mcm","clk":"11541562847","pt":1719507098159,"mc":[{"id":"1.230178328","rc":[{"atb":[[4.2,2.17]],"id":70053016}],"con":true,"img":false}]}
{"op":"mcm","clk":"11541562855","pt":1719507098264,"mc":[{"id":"1.230178328","rc":[{"atb":[[6.6,2.13]],"id":69942666}],"con":true,"img":false}]}
{"op":"mcm","clk":"11541562887","pt":1719507098677,"mc":[{"id":"1.230178328","rc":[{"atb":[[6.2,2.85]],"id":69942666}],"con":true,"img":false}]}
{"op":"mcm","clk":"11541562911","pt":1719507098987,"mc":[{"id":"1.230178328","rc":[{"atb":[[6.4,0]],"id":69942666}],"con":true,"img":false}]}
{"op":"mcm","clk":"11541562919","pt":1719507099087,"mc":[{"id":"1.230178328","rc":[{"atb":[[6.8,2]],"id":69942666}],"con":true,"img":false}]}
{"op":"mcm","clk":"11541562935","pt":1719507099350,"mc":[{"id":"1.230178328","rc":[{"atb":[[7,0.84]],"id":69942666}],"con":true,"img":false}]}
{"op":"mcm","clk":"11541562979","pt":1719507100066,"mc":[{"id":"1.230178328","rc":[{"atb":[[2.16,25.4]],"id":69942666}],"con":true,"img":false}]}
{"op":"mcm","clk":"11541562987","pt":1719507100170,"mc":[{"id":"1.230178328","rc":[{"atb":[[2.12,10.58]],"id":53082422}],"con":true,"img":false}]}
{"op":"mcm","clk":"11541562994","pt":1719507100274,"mc":[{"id":"1.230178328","rc":[{"atb":[[1.54,24.23]],"id":53082422}],"con":true,"img":false}]}
{"op":"mcm","clk":"11541563000","pt":1719507100374,"mc":[{"id":"1.230178328","rc":[{"atb":[[5.1,1.62]],"id":66686625},{"atl":[[21,0.47]],"id":66686625},{"atb":[[3.05,0]],"id":70053016},{"atl":[[8.8,2.14]],"id":70053016},{"atb":[[1.53,30.88],[2.66,0]],"id":53082422},{"atl":[[3.15,0]],"id":53082422}],"con":true,"img":false}]}
{"op":"mcm","clk":"11541563019","pt":1719507100583,"mc":[{"id":"1.230178328","rc":[{"atb":[[2.36,6.54]],"id":53082422}],"con":true,"img":false}]}
{"op":"mcm","clk":"11541563029","pt":1719507100688,"mc":[{"id":"1.230178328","rc":[{"atb":[[2.24,7.65]],"id":53082422}],"con":true,"img":false}]}
{"op":"mcm","clk":"11541563052","pt":1719507100947,"mc":[{"id":"1.230178328","rc":[{"atb":[[5,1]],"id":69942666}],"con":true,"img":false}]}
{"op":"mcm","clk":"11541563065","pt":1719507101152,"mc":[{"id":"1.230178328","rc":[{"atl":[[8.6,0.84]],"id":70053016}],"con":true,"img":false}]}
{"op":"mcm","clk":"11541563083","pt":1719507101357,"mc":[{"id":"1.230178328","rc":[{"atl":[[1000,0.13]],"id":70053016}],"con":true,"img":false}]}
{"op":"mcm","clk":"11541563103","pt":1719507101668,"mc":[{"id":"1.230178328","rc":[{"atl":[[1000,0]],"id":70053016}],"con":true,"img":false}]}
{"op":"mcm","clk":"11541563110","pt":1719507101772,"mc":[{"id":"1.230178328","rc":[{"atl":[[8.6,0.97]],"id":70053016}],"con":true,"img":false}]}
{"op":"mcm","clk":"11541563129","pt":1719507101977,"mc":[{"id":"1.230178328","rc":[{"atb":[[5.2,1.49]],"id":69942666}],"con":true,"img":false}]}
{"op":"mcm","clk":"11541563145","pt":1719507102184,"mc":[{"id":"1.230178328","rc":[{"atl":[[12,0]],"id":70902603},{"atb":[[5.2,0.05]],"id":69942666}],"con":true,"img":false}]}
{"op":"mcm","clk":"11541563156","pt":1719507102292,"mc":[{"id":"1.230178328","rc":[{"atl":[[14,4]],"id":70902603},{"atl":[[9,1],[9.8,5.33]],"id":70053016}],"con":true,"img":false}]}
{"op":"mcm","clk":"11541563166","pt":1719507102390,"mc":[{"id":"1.230178328","rc":[{"atb":[[3.95,0],[4.2,6.73]],"id":64812720},{"atb":[[2.64,0],[2.58,6.8]],"id":53082422}],"con":true,"img":false}]}
{"op":"mcm","clk":"11541563176","pt":1719507102494,"mc":[{"id":"1.230178328","rc":[{"atb":[[5.3,3.71]],"id":69942666}],"con":true,"img":false}]}
{"op":"mcm","clk":"11541563208","pt":1719507102855,"mc":[{"id":"1.230178328","rc":[{"atb":[[5.3,0]],"id":69942666}],"con":true,"img":false}]}
{"op":"mcm","clk":"11541563220","pt":1719507103065,"mc":[{"id":"1.230178328","rc":[{"atb":[[5.5,4.67]],"id":69942666}],"con":true,"img":false}]}
{"op":"mcm","clk":"11541563264","pt":1719507103681,"mc":[{"id":"1.230178328","rc":[{"atb":[[2.76,0]],"id":70902603},{"atb":[[2.1,0]],"id":53082422}],"con":true,"img":false}]}
{"op":"mcm","clk":"11541563304","pt":1719507104194,"mc":[{"id":"1.230178328","rc":[{"atb":[[5.5,1]],"id":69942666}],"con":true,"img":false}]}
{"op":"mcm","clk":"11541563366","pt":1719507105074,"mc":[{"id":"1.230178328","rc":[{"atb":[[5.2,3.43]],"id":69942666}],"con":true,"img":false}]}
{"op":"mcm","clk":"11541563469","pt":1719507106178,"mc":[{"id":"1.230178328","rc":[{"atb":[[4.3,5.9]],"id":70053016}],"con":true,"img":false}]}
{"op":"mcm","clk":"11541563531","pt":1719507107056,"mc":[{"id":"1.230178328","rc":[{"atb":[[4.2,1.92]],"id":70053016}],"con":true,"img":false}]}
{"op":"mcm","clk":"11541563538","pt":1719507107158,"mc":[{"id":"1.230178328","rc":[{"atb":[[4.4,0.25],[4.3,8.32]],"id":70053016}],"con":true,"img":false}]}
{"op":"mcm","clk":"11541563640","pt":1719507108701,"mc":[{"id":"1.230178328","rc":[{"atb":[[2.76,0]],"id":64812720},{"atb":[[2.8,0]],"id":70053016}],"con":true,"img":false}]}
{"op":"mcm","clk":"11541563701","pt":1719507109579,"mc":[{"id":"1.230178328","rc":[{"atl":[[12,4]],"id":70902603},{"atl":[[8.8,4.29]],"id":70053016}],"con":true,"img":false}]}
{"op":"mcm","clk":"11541563711","pt":1719507109685,"mc":[{"id":"1.230178328","rc":[{"atl":[[14,0]],"id":70902603},{"atl":[[9.8,1.03]],"id":70053016}],"con":true,"img":false}]}
{"op":"mcm","clk":"11541563939","pt":1719507112990,"mc":[{"id":"1.230178328","rc":[{"atb":[[4.5,1.87]],"id":70053016}],"con":true,"img":false}]}
{"op":"mcm","clk":"11541563957","pt":1719507113299,"mc":[{"id":"1.230178328","rc":[{"atl":[[10.5,0]],"id":70902603},{"atb":[[4.5,0]],"id":70053016},{"atb":[[2.36,3.16],[2.24,15.84]],"id":53082422}],"con":true,"img":false}]}
{"op":"mcm","clk":"11541563965","pt":1719507113401,"mc":[{"id":"1.230178328","rc":[{"atb":[[4.3,2.42]],"id":70053016}],"con":true,"img":false}]}
{"op":"mcm","clk":"11541563971","pt":1719507113504,"mc":[{"id":"1.230178328","rc":[{"atb":[[4.2,0]],"id":70053016},{"atb":[[2.6,5]],"id":53082422}],"con":true,"img":false}]}
{"op":"mcm","clk":"11541563979","pt":1719507113608,"mc":[{"id":"1.230178328","rc":[{"atb":[[2.8,7.04]],"id":70902603},{"atb":[[3.85,0],[4,6],[3.2,5.77]],"id":66686625},{"atb":[[4.4,2.13]],"id":70053016},{"atl":[[9,0],[8.8,5.29]],"id":70053016},{"atl":[[34,1.24],[36,0]],"id":69942666},{"atl":[[5.3,8]],"id":53082422}],"con":true,"img":false}]}
{"op":"mcm","clk":"11541563986","pt":1719507113711,"mc":[{"id":"1.230178328","rc":[{"atl":[[8.8,4.15]],"id":70053016},{"atl":[[140,0],[42,2.44]],"id":69942666},{"atl":[[5.8,0]],"id":53082422}],"con":true,"img":false}]}
{"op":"mcm","clk":"11541563993","pt":1719507113816,"mc":[{"id":"1.230178328","rc":[{"atb":[[4.1,2.58]],"id":70053016},{"atl":[[42,0]],"id":69942666}],"con":true,"img":false}]}
{"op":"mcm","clk":"11541564001","pt":1719507113875,"mc":[{"id":"1.230178328","rc":[{"atl":[[11,0],[11.5,1],[1000,0.27]],"id":70902603},{"atl":[[13.5,0],[14,1]],"id":66686625},{"atb":[[4.3,4.12]],"id":70053016},{"atl":[[9,1],[8.8,3.15]],"id":70053016},{"atl":[[34,0.24],[140,2],[36,1]],"id":69942666}],"con":true,"img":false}]}
{"op":"mcm","clk":"11541564013","pt":1719507113976,"mc":[{"id":"1.230178328","rc":[{"atb":[[6.2,0],[6,4.13]],"id":69942666}],"con":true,"img":false}]}
{"op":"mcm","clk":"11541564025","pt":1719507114080,"mc":[{"id":"1.230178328","rc":[{"atb":[[2.16,11.29]],"id":64812720},{"atl":[[1000,0.16]],"id":70902603},{"atb":[[6.2,4],[6,0]],"id":69942666}],"con":true,"img":false}]}
{"op":"mcm","clk":"11541564034","pt":1719507114182,"mc":[{"id":"1.230178328","rc":[{"atl":[[10.5,0.11]],"id":70902603}],"con":true,"img":false}]}
{"op":"mcm","clk":"11541564044","pt":1719507114287,"mc":[{"id":"1.230178328","rc":[{"atb":[[4.3,2.42]],"id":70053016}],"con":true,"img":false}]}
{"op":"mcm","clk":"11541564054","pt":1719507114390,"mc":[{"id":"1.230178328","rc":[{"atb":[[4.1,4.28]],"id":70053016}],"con":true,"img":false}]}
{"op":"mcm","clk":"11541564220","pt":1719507117429,"mc":[{"id":"1.230178328","rc":[{"atl":[[8.6,0.84]],"id":70053016}],"con":true,"img":false}]}
{"op":"mcm","clk":"11541564235","pt":1719507117760,"mc":[{"id":"1.230178328","rc":[{"atl":[[1000,0.13]],"id":70053016}],"con":true,"img":false}]}
{"op":"mcm","clk":"11541564245","pt":1719507117773,"mc":[{"id":"1.230178328","rc":[{"atl":[[1000,0]],"id":70053016}],"con":true,"img":false}]}
{"op":"mcm","clk":"11541564254","pt":1719507117784,"mc":[{"id":"1.230178328","rc":[{"atl":[[8.6,0.97]],"id":70053016}],"con":true,"img":false}]}
{"op":"mcm","clk":"11541564340","pt":1719507118701,"mc":[{"id":"1.230178328","rc":[{"atb":[[2.36,0]],"id":53082422}],"con":true,"img":false}]}
{"op":"mcm","clk":"11541564352","pt":1719507118907,"mc":[{"id":"1.230178328","rc":[{"atb":[[2.38,8.59]],"id":64812720}],"con":true,"img":false}]}
{"op":"mcm","clk":"11541564358","pt":1719507119008,"mc":[{"id":"1.230178328","rc":[{"atb":[[2.16,18.1]],"id":66686625}],"con":true,"img":false}]}
{"op":"mcm","clk":"11541564370","pt":1719507119216,"mc":[{"id":"1.230178328","rc":[{"atb":[[2.74,6.81]],"id":70053016}],"con":true,"img":false}]}
{"op":"mcm","clk":"11541564548","pt":1719507121404,"mc":[{"id":"1.230178328","rc":[{"atb":[[1.01,1]],"id":53082422}],"con":true,"img":false}]}
{"op":"mcm","clk":"11541564997","pt":1719507127912,"mc":[{"id":"1.230178328","rc":[{"spn":8.8,"spf":"NaN","id":64812720},{"spn":9.6,"spf":"NaN","id":66686625},{"atb":[[4.8,17.96]],"id":70053016},{"spn":6.7,"spf":"NaN","id":70053016},{"spn":6.9,"spf":1.0,"id":69942666},{"spn":2.7,"spf":1.0,"id":53082422}],"con":true,"img":false}]}
{"op":"mcm","clk":"11541565015","pt":1719507128123,"mc":[{"id":"1.230178328","rc":[{"atb":[[4.3,1]],"id":64812720},{"atl":[[4.9,1]],"id":70902603},{"atb":[[4.9,1],[4.1,2.58]],"id":70053016},{"atl":[[5.2,1]],"id":53082422}],"con":true,"img":false}]}
{"op":"mcm","clk":"11541565024","pt":1719507128222,"mc":[{"id":"1.230178328","rc":[{"atl":[[4.9,0]],"id":70902603},{"trd":[[4.9,2]],"ltp":4.9,"tv":2.0,"id":70902603},{"atb":[[4.9,2.7]],"id":70053016}],"con":true,"img":false}]}
{"op":"mcm","clk":"11541565039","pt":1719507128429,"mc":[{"id":"1.230178328","rc":[{"atl":[[10,0],[11,0.84]],"id":70902603},{"atb":[[5,5.07]],"id":70053016}],"con":true,"img":false}]}
{"op":"mcm","clk":"11541565057","pt":1719507128595,"mc":[{"id":"1.230178328","rc":[{"atb":[[4.3,0]],"id":64812720},{"atb":[[4.9,1.7]],"id":70053016}],"con":true,"img":false}]}
{"op":"mcm","clk":"11541565072","pt":1719507128805,"mc":[{"id":"1.230178328","rc":[{"atb":[[4.9,0]],"id":70053016}],"con":true,"img":false}]}
{"op":"mcm","clk":"11541565081","pt":1719507128910,"mc":[{"id":"1.230178328","rc":[{"atb":[[5.1,1.7]],"id":70053016}],"con":true,"img":false}]}
{"op":"mcm","clk":"11541565125","pt":1719507129426,"mc":[{"id":"1.230178328","rc":[{"atl":[[10.5,0]],"id":70902603}],"con":true,"img":false}]}
{"op":"mcm","clk":"11541565132","pt":1719507129527,"mc":[{"id":"1.230178328","rc":[{"atb":[[5,0]],"id":70053016}],"con":true,"img":false}]}
{"op":"mcm","clk":"11541565140","pt":1719507129627,"mc":[{"id":"1.230178328","rc":[{"atl":[[1000,0.26]],"id":70902603}],"con":true,"img":false}]}
{"op":"mcm","clk":"11541565149","pt":1719507129832,"mc":[{"id":"1.230178328","rc":[{"atl":[[10.5,1.58],[1000,0.16]],"id":70902603},{"atb":[[4.4,1.87]],"id":70053016},{"atb":[[1.13,0]],"id":69942666}],"con":true,"img":false}]}
{"op":"mcm","clk":"11541565152","pt":1719507129937,"mc":[{"id":"1.230178328","rc":[{"atl":[[11,0.94]],"id":70902603},{"atb":[[4.9,0.25],[5.1,0]],"id":70053016},{"atb":[[6.8,2.27]],"id":69942666}],"con":true,"img":false}]}
{"op":"mcm","clk":"11541565167","pt":1719507130011,"mc":[{"id":"1.230178328","rc":[{"atb":[[4.9,1.95]],"id":70053016}],"con":true,"img":false}]}
{"op":"mcm","clk":"11541565175","pt":1719507130102,"mc":[{"id":"1.230178328","rc":[{"atl":[[10,1.58]],"id":70902603}],"con":true,"img":false}]}
{"op":"mcm","clk":"11541565209","pt":1719507130523,"mc":[{"id":"1.230178328","rc":[{"atl":[[9.8,1.58]],"id":70902603}],"con":true,"img":false}]}
{"op":"mcm","clk":"11541565233","pt":1719507130829,"mc":[{"id":"1.230178328","rc":[{"atl":[[9.6,1.58]],"id":70902603}],"con":true,"img":false}]}
{"op":"mcm","clk":"11541565262","pt":1719507131131,"mc":[{"id":"1.230178328","rc":[{"atl":[[9.4,1.58]],"id":70902603}],"con":true,"img":false}]}
{"op":"mcm","clk":"11541565292","pt":1719507131406,"mc":[{"id":"1.230178328","rc":[{"atl":[[9.2,1.58]],"id":70902603}],"con":true,"img":false}]}
{"op":"mcm","clk":"11541565304","pt":1719507131507,"mc":[{"id":"1.230178328","rc":[{"atb":[[3.95,0]],"id":70053016}],"con":true,"img":false}]}
{"op":"mcm","clk":"11541565328","pt":1719507131816,"mc":[{"id":"1.230178328","rc":[{"atl":[[9,1.58]],"id":70902603}],"con":true,"img":false}]}
{"op":"mcm","clk":"11541565343","pt":1719507132023,"mc":[{"id":"1.230178328","rc":[{"atb":[[5,5.07]],"id":70053016}],"con":true,"img":false}]}
{"op":"mcm","clk":"11541565361","pt":1719507132427,"mc":[{"id":"1.230178328","rc":[{"atb":[[3.85,2.81]],"id":70902603}],"con":true,"img":false}]}
{"op":"mcm","clk":"11541565386","pt":1719507132801,"mc":[{"id":"1.230178328","rc":[{"atl":[[8.6,0.84]],"id":70053016}],"con":true,"img":false}]}
{"op":"mcm","clk":"11541565400","pt":1719507133012,"mc":[{"id":"1.230178328","rc":[{"atl":[[1000,0.13]],"id":70053016}],"con":true,"img":false}]}
{"op":"mcm","clk":"11541565415","pt":1719507133210,"mc":[{"id":"1.230178328","rc":[{"atl":[[1000,0]],"id":70053016}],"con":true,"img":false}]}
{"op":"mcm","clk":"11541565424","pt":1719507133310,"mc":[{"id":"1.230178328","rc":[{"atl":[[8.6,0.97]],"id":70053016}],"con":true,"img":false}]}
{"op":"mcm","clk":"11541565442","pt":1719507133620,"mc":[{"id":"1.230178328","rc":[{"atl":[[8.6,1.58]],"id":70902603}],"con":true,"img":false}]}
{"op":"mcm","clk":"11541565464","pt":1719507134027,"mc":[{"id":"1.230178328","rc":[{"atl":[[8.4,1.58]],"id":70902603}],"con":true,"img":false}]}
{"op":"mcm","clk":"11541565484","pt":1719507134336,"mc":[{"id":"1.230178328","rc":[{"atl":[[8.2,1.58],[1000,0.95]],"id":70902603}],"con":true,"img":false}]}
{"op":"mcm","clk":"11541565489","pt":1719507134392,"mc":[{"id":"1.230178328","rc":[{"atb":[[3.9,0]],"id":70902603},{"atb":[[4.9,1.7]],"id":70053016}],"con":true,"img":false}]}
{"op":"mcm","clk":"11541565498","pt":1719507134500,"mc":[{"id":"1.230178328","rc":[{"atb":[[1.13,0.27]],"id":70902603},{"atb":[[5.1,0.25]],"id":70053016}],"con":true,"img":false}]}
{"op":"mcm","clk":"11541565526","pt":1719507134904,"mc":[{"id":"1.230178328","rc":[{"atl":[[1000,0.66]],"id":70902603}],"con":true,"img":false}]}
{"op":"mcm","clk":"11541565606","pt":1719507136202,"mc":[{"id":"1.230178328","rc":[{"atl":[[8,1.58]],"id":70902603}],"con":true,"img":false}]}
{"op":"mcm","clk":"11541565619","pt":1719507136408,"mc":[{"id":"1.230178328","rc":[{"atl":[[7.8,1.58]],"id":70902603}],"con":true,"img":false}]}
{"op":"mcm","clk":"11541565675","pt":1719507137240,"mc":[{"id":"1.230178328","rc":[{"atl":[[7.4,1.58]],"id":70902603}],"con":true,"img":false}]}
{"op":"mcm","clk":"11541565783","pt":1719507138912,"mc":[{"id":"1.230178328","rc":[{"atl":[[7.2,1.58]],"id":70902603}],"con":true,"img":false}]}
{"op":"mcm","clk":"11541565803","pt":1719507139222,"mc":[{"id":"1.230178328","rc":[{"atl":[[7,1.58]],"id":70902603}],"con":true,"img":false}]}
{"op":"mcm","clk":"11541565821","pt":1719507139531,"mc":[{"id":"1.230178328","rc":[{"atl":[[6.8,1.58]],"id":70902603}],"con":true,"img":false}]}
{"op":"mcm","clk":"11541565844","pt":1719507139895,"mc":[{"id":"1.230178328","rc":[{"atl":[[6.6,1.58]],"id":70902603}],"con":true,"img":false}]}
{"op":"mcm","clk":"11541565904","pt":1719507140722,"mc":[{"id":"1.230178328","rc":[{"atb":[[4.4,6],[4.2,0]],"id":64812720},{"atb":[[4,0],[4.2,5.77]],"id":66686625},{"atb":[[6.8,4.54],[6.2,0]],"id":69942666}],"con":true,"img":false}]}
{"op":"mcm","clk":"11541565913","pt":1719507140824,"mc":[{"id":"1.230178328","rc":[{"atl":[[12.5,0],[13,1]],"id":64812720},{"atl":[[9,0],[9.2,1]],"id":70053016}],"con":true,"img":false}]}
{"op":"mcm","clk":"11541565945","pt":1719507141339,"mc":[{"id":"1.230178328","rc":[{"atb":[[7,2.5]],"id":69942666}],"con":true,"img":false}]}
{"op":"mcm","clk":"11541565955","pt":1719507141494,"mc":[{"id":"1.230178328","rc":[{"atb":[[7.2,3.52]],"id":69942666}],"con":true,"img":false}]}
{"op":"mcm","clk":"11541565968","pt":1719507141701,"mc":[{"id":"1.230178328","rc":[{"atl":[[6.4,1.58]],"id":70902603}],"con":true,"img":false}]}
{"op":"mcm","clk":"11541565978","pt":1719507141806,"mc":[{"id":"1.230178328","rc":[{"atb":[[7.4,0.84],[6.8,2.54],[6.6,1.28]],"id":69942666}],"con":true,"img":false}]}
{"op":"mcm","clk":"11541565988","pt":1719507141916,"mc":[{"id":"1.230178328","rc":[{"atb":[[7.2,5.52],[7,0.84]],"id":69942666}],"con":true,"img":false}]}
{"op":"mcm","clk":"11541565993","pt":1719507142010,"mc":[{"id":"1.230178328","rc":[{"atl":[[6.2,1.58]],"id":70902603},{"atb":[[7.4,2.5]],"id":69942666}],"con":true,"img":false}]}
{"op":"mcm","clk":"11541566013","pt":1719507142320,"mc":[{"id":"1.230178328","rc":[{"atb":[[7.2,2]],"id":69942666}],"con":true,"img":false}]}
{"op":"mcm","clk":"11541566019","pt":1719507142422,"mc":[{"id":"1.230178328","rc":[{"atl":[[6,1.58]],"id":70902603},{"atb":[[7,0]],"id":69942666}],"con":true,"img":false}]}
{"op":"mcm","clk":"11541566033","pt":1719507142629,"mc":[{"id":"1.230178328","rc":[{"atl":[[5.9,1.58]],"id":70902603},{"atb":[[7.4,0.84]],"id":69942666}],"con":true,"img":false}]}
{"op":"mcm","clk":"11541566057","pt":1719507142940,"mc":[{"id":"1.230178328","rc":[{"atl":[[5.8,1.58]],"id":70902603}],"con":true,"img":false}]}
{"op":"mcm","clk":"11541566074","pt":1719507143146,"mc":[{"id":"1.230178328","rc":[{"atb":[[7.2,0]],"id":69942666}],"con":true,"img":false}]}
{"op":"mcm","clk":"11541566086","pt":1719507143251,"mc":[{"id":"1.230178328","rc":[{"atb":[[7.6,2]],"id":69942666}],"con":true,"img":false}]}
{"op":"mcm","clk":"11541566116","pt":1719507143618,"mc":[{"id":"1.230178328","rc":[{"atb":[[6.8,2.27]],"id":69942666}],"con":true,"img":false}]}
{"op":"mcm","clk":"11541566121","pt":1719507143719,"mc":[{"id":"1.230178328","rc":[{"atb":[[1.13,0.27]],"id":69942666}],"con":true,"img":false}]}
{"op":"mcm","clk":"11541566175","pt":1719507144443,"mc":[{"id":"1.230178328","rc":[{"atb":[[7.6,0]],"id":69942666}],"con":true,"img":false}]}
{"op":"mcm","clk":"11541566184","pt":1719507144546,"mc":[{"id":"1.230178328","rc":[{"atb":[[7,2]],"id":69942666}],"con":true,"img":false}]}
{"op":"mcm","clk":"11541566194","pt":1719507144605,"mc":[{"id":"1.230178328","rc":[{"atl":[[5.7,1.58]],"id":70902603}],"con":true,"img":false}]}
{"op":"mcm","clk":"11541566203","pt":1719507144809,"mc":[{"id":"1.230178328","rc":[{"atb":[[2.78,0]],"id":70902603},{"atb":[[3.15,0]],"id":66686625},{"atb":[[7.4,0]],"id":69942666},{"atb":[[2.12,0]],"id":53082422}],"con":true,"img":false}]}
{"op":"mcm","clk":"11541566212","pt":1719507144918,"mc":[{"id":"1.230178328","rc":[{"atl":[[5.6,1.58]],"id":70902603}],"con":true,"img":false}]}
{"op":"mcm","clk":"11541566226","pt":1719507145124,"mc":[{"id":"1.230178328","rc":[{"atl":[[11,0.84]],"id":70902603}],"con":true,"img":false}]}
{"op":"mcm","clk":"11541566260","pt":1719507145738,"mc":[{"id":"1.230178328","rc":[{"atl":[[5.4,1.58]],"id":70902603}],"con":true,"img":false}]}
{"op":"mcm","clk":"11541566367","pt":1719507147238,"mc":[{"id":"1.230178328","rc":[{"atl":[[5.5,1.58]],"id":70902603}],"con":true,"img":false}]}
{"op":"mcm","clk":"11541566385","pt":1719507147550,"mc":[{"id":"1.230178328","rc":[{"atl":[[5.3,1.58]],"id":70902603}],"con":true,"img":false}]}
{"op":"mcm","clk":"11541566429","pt":1719507148222,"mc":[{"id":"1.230178328","rc":[{"atl":[[5.1,1.58]],"id":70902603}],"con":true,"img":false}]}
{"op":"mcm","clk":"11541566437","pt":1719507148325,"mc":[{"id":"1.230178328","rc":[{"atb":[[2.16,25.4]],"id":66686625}],"con":true,"img":false}]}
{"op":"mcm","clk":"11541566449","pt":1719507148532,"mc":[{"id":"1.230178328","rc":[{"atl":[[5,1.58]],"id":70902603},{"atl":[[8.6,0.84]],"id":70053016}],"con":true,"img":false}]}
{"op":"mcm","clk":"11541566463","pt":1719507148751,"mc":[{"id":"1.230178328","rc":[{"atl":[[1000,0.13]],"id":70053016}],"con":true,"img":false}]}
{"op":"mcm","clk":"11541566478","pt":1719507148943,"mc":[{"id":"1.230178328","rc":[{"atl":[[1000,0]],"id":70053016}],"con":true,"img":false}]}
{"op":"mcm","clk":"11541566484","pt":1719507149046,"mc":[{"id":"1.230178328","rc":[{"atl":[[8.6,0.97]],"id":70053016}],"con":true,"img":false}]}
{"op":"mcm","clk":"11541566513","pt":1719507149415,"mc":[{"id":"1.230178328","rc":[{"atb":[[7.2,0.84]],"id":69942666}],"con":true,"img":false}]}
{"op":"mcm","clk":"11541566545","pt":1719507150030,"mc":[{"id":"1.230178328","rc":[{"atl":[[13.5,0.84]],"id":66686625},{"atl":[[8.6,1.82]],"id":70053016}],"con":true,"img":false}]}
{"op":"mcm","clk":"11541566563","pt":1719507150337,"mc":[{"id":"1.230178328","rc":[{"atl":[[5.2,1.58]],"id":70902603}],"con":true,"img":false}]}
{"op":"mcm","clk":"11541566569","pt":1719507150449,"mc":[{"id":"1.230178328","rc":[{"atb":[[1.13,0]],"id":69942666}],"con":true,"img":false}]}
{"op":"mcm","clk":"11541566575","pt":1719507150544,"mc":[{"id":"1.230178328","rc":[{"atb":[[7,2.27]],"id":69942666}],"con":true,"img":false}]}
{"op":"mcm","clk":"11541566606","pt":1719507150811,"mc":[{"id":"1.230178328","rc":[{"atl":[[4.9,1.58]],"id":70902603}],"con":true,"img":false}]}
{"op":"mcm","clk":"11541566625","pt":1719507151117,"mc":[{"id":"1.230178328","rc":[{"atb":[[2.16,5.83]],"id":70053016}],"con":true,"img":false}]}
{"op":"mcm","clk":"11541566644","pt":1719507151426,"mc":[{"id":"1.230178328","rc":[{"atl":[[4.8,1.58]],"id":70902603}],"con":true,"img":false}]}
{"op":"mcm","clk":"11541566674","pt":1719507151941,"mc":[{"id":"1.230178328","rc":[{"atl":[[4.6,1.58]],"id":70902603}],"con":true,"img":false}]}
{"op":"mcm","clk":"11541566681","pt":1719507152045,"mc":[{"id":"1.230178328","rc":[{"atl":[[4.6,0]],"id":70902603},{"trd":[[4.6,3.16]],"ltp":4.6,"tv":3.16,"id":70902603}],"con":true,"img":false}]}
{"op":"mcm","clk":"11541566788","pt":1719507153350,"mc":[{"id":"1.230178328","rc":[{"atb":[[4.8,0]],"id":70053016}],"con":true,"img":false}]}
{"op":"mcm","clk":"11541566804","pt":1719507153551,"mc":[{"id":"1.230178328","rc":[{"atl":[[4.7,1.58]],"id":70902603}],"con":true,"img":false}]}
{"op":"mcm","clk":"11541566840","pt":1719507153961,"mc":[{"id":"1.230178328","rc":[{"atl":[[4.6,1.58]],"id":70902603}],"con":true,"img":false}]}
{"op":"mcm","clk":"11541566850","pt":1719507154017,"mc":[{"id":"1.230178328","rc":[{"atl":[[4.6,0]],"id":70902603},{"trd":[[4.6,6.32]],"ltp":4.6,"tv":6.32,"id":70902603}],"con":true,"img":false}]}
{"op":"mcm","clk":"11541566858","pt":1719507154123,"mc":[{"id":"1.230178328","rc":[{"atb":[[4.5,0]],"id":70902603},{"atl":[[4.5,0.57]],"id":70902603},{"trd":[[4.5,2]],"ltp":4.5,"tv":2.0,"id":70902603}],"con":true,"img":false}]}
{"op":"mcm","clk":"11541566867","pt":1719507154240,"mc":[{"id":"1.230178328","rc":[{"atl":[[4.5,0]],"id":70902603},{"trd":[[4.5,3.16]],"ltp":4.5,"tv":3.16,"id":70902603}],"con":true,"img":false}]}
{"op":"mcm","clk":"11541566876","pt":1719507154336,"mc":[{"id":"1.230178328","rc":[{"atb":[[3.9,6.34]],"id":70902603},{"atb":[[5,7.07]],"id":70053016},{"atb":[[2.1,10.78]],"id":53082422}],"con":true,"img":false}]}
{"op":"mcm","clk":"11541566889","pt":1719507154536,"mc":[{"id":"1.230178328","rc":[{"atb":[[3.8,0],[3.95,2.91]],"id":70902603}],"con":true,"img":false}]}
{"op":"mcm","clk":"11541566894","pt":1719507154638,"mc":[{"id":"1.230178328","rc":[{"atb":[[3.25,5.27]],"id":66686625},{"atb":[[7.2,2.5]],"id":69942666}],"con":true,"img":false}]}
{"op":"mcm","clk":"11541566906","pt":1719507154845,"mc":[{"id":"1.230178328","rc":[{"atb":[[3.05,4.54]],"id":70902603},{"atb":[[2.16,18.58]],"id":69942666}],"con":true,"img":false}]}
{"op":"mcm","clk":"11541566911","pt":1719507154948,"mc":[{"id":"1.230178328","rc":[{"atb":[[4,0.84],[3.9,0]],"id":70902603},{"atb":[[5.1,0]],"id":70053016},{"atb":[[7,2]],"id":69942666}],"con":true,"img":false}]}
{"op":"mcm","clk":"11541566917","pt":1719507155048,"mc":[{"id":"1.230178328","rc":[{"atb":[[2.82,6.51]],"id":70902603},{"atl":[[4.8,3.69]],"id":70902603},{"atb":[[1.14,0.25]],"id":70053016},{"atb":[[7.2,2.77]],"id":69942666}],"con":true,"img":false}]}
{"op":"mcm","clk":"11541566923","pt":1719507155153,"mc":[{"id":"1.230178328","rc":[{"atl":[[13.5,1.84],[14,0]],"id":66686625},{"atl":[[9,1],[9.2,0]],"id":70053016}],"con":true,"img":false}]}
{"op":"mcm","clk":"11541566930","pt":1719507155258,"mc":[{"id":"1.230178328","rc":[{"atb":[[4.4,0],[4.7,6]],"id":64812720},{"atl":[[22,0],[13.5,3.84]],"id":66686625},{"atb":[[6.8,0],[7.2,1.11],[6.6,5.82]],"id":69942666},{"atb":[[2.58,0]],"id":53082422}],"con":true,"img":false}]}
{"op":"mcm","clk":"11541566938","pt":1719507155360,"mc":[{"id":"1.230178328","rc":[{"atb":[[6.8,3.44],[7,0]],"id":69942666},{"atb":[[2.5,12.09]],"id":53082422}],"con":true,"img":false}]}
{"op":"mcm","clk":"11541566948","pt":1719507155466,"mc":[{"id":"1.230178328","rc":[{"atl":[[4.5,1.58]],"id":70902603},{"atb":[[7.4,2],[6.6,1.28]],"id":69942666}],"con":true,"img":false}]}
{"op":"mcm","clk":"11541566956","pt":1719507155522,"mc":[{"id":"1.230178328","rc":[{"atb":[[2.46,2.09]],"id":53082422}],"con":true,"img":false}]}
{"op":"mcm","clk":"11541566967","pt":1719507155636,"mc":[{"id":"1.230178328","rc":[{"atl":[[13.5,2.84],[14,1]],"id":66686625},{"atl":[[9,0],[9.2,1]],"id":70053016}],"con":true,"img":false}]}
{"op":"mcm","clk":"11541566974","pt":1719507155728,"mc":[{"id":"1.230178328","rc":[{"atb":[[4.7,0]],"id":64812720}],"con":true,"img":false}]}
{"op":"mcm","clk":"11541566982","pt":1719507155844,"mc":[{"id":"1.230178328","rc":[{"atb":[[4.4,6]],"id":64812720},{"atl":[[4.6,1.58]],"id":70902603}],"con":true,"img":false}]}
{"op":"mcm","clk":"11541566989","pt":1719507155933,"mc":[{"id":"1.230178328","rc":[{"atl":[[13,0.84]],"id":66686625}],"con":true,"img":false}]}
{"op":"mcm","clk":"11541566997","pt":1719507156040,"mc":[{"id":"1.230178328","rc":[{"atl":[[21,0]],"id":66686625}],"con":true,"img":false}]}
{"op":"mcm","clk":"11541567007","pt":1719507156145,"mc":[{"id":"1.230178328","rc":[{"atl":[[1000,0.64]],"id":66686625}],"con":true,"img":false}]}
{"op":"mcm","clk":"11541567031","pt":1719507156456,"mc":[{"id":"1.230178328","rc":[{"atb":[[7.6,0.84]],"id":69942666}],"con":true,"img":false}]}
{"op":"mcm","clk":"11541567056","pt":1719507156718,"mc":[{"id":"1.230178328","rc":[{"atb":[[4,11.72]],"id":70053016},{"atb":[[2.58,2.09],[2.46,0],[2.78,1.27]],"id":53082422}],"con":true,"img":false}]}
{"op":"mcm","clk":"11541567060","pt":1719507156821,"mc":[{"id":"1.230178328","rc":[{"atb":[[2.76,0]],"id":53082422}],"con":true,"img":false}]}
{"op":"mcm","clk":"11541567109","pt":1719507157342,"mc":[{"id":"1.230178328","rc":[{"atb":[[7.2,0.84]],"id":69942666}],"con":true,"img":false}]}
{"op":"mcm","clk":"11541567115","pt":1719507157443,"mc":[{"id":"1.230178328","rc":[{"atb":[[7.4,2.27]],"id":69942666}],"con":true,"img":false}]}
{"op":"mcm","clk":"11541567130","pt":1719507157651,"mc":[{"id":"1.230178328","rc":[{"atl":[[4.5,0],[4.7,0],[4.8,0],[4.6,0]],"id":70902603},{"trd":[[4.8,7.38],[4.5,6.32],[4.6,9.48],[4.7,3.16]],"ltp":4.8,"tv":26.34,"id":70902603}],"con":true,"img":false}]}
{"op":"mcm","clk":"11541567152","pt":1719507157860,"mc":[{"id":"1.230178328","rc":[{"atb":[[7.4,0.27]],"id":69942666}],"con":true,"img":false}]}
{"op":"mcm","clk":"11541567162","pt":1719507157965,"mc":[{"id":"1.230178328","rc":[{"atl":[[13.5,3.84]],"id":66686625},{"atl":[[9,1]],"id":70053016},{"atb":[[7,2]],"id":69942666}],"con":true,"img":false}]}
{"op":"mcm","clk":"11541567170","pt":1719507158070,"mc":[{"id":"1.230178328","rc":[{"atl":[[30,6.33]],"id":64812720},{"atl":[[980,1.15]],"id":70902603},{"atl":[[14,0]],"id":66686625},{"atb":[[5.1,2.53]],"id":70053016},{"atl":[[9.2,0]],"id":70053016},{"atl":[[150,5.25]],"id":69942666}],"con":true,"img":false}]}
{"op":"mcm","clk":"11541567186","pt":1719507158235,"mc":[{"id":"1.230178328","rc":[{"atl":[[13.5,2.84],[14,1]],"id":66686625},{"atl":[[9,0],[9.2,1]],"id":70053016},{"atb":[[7,3.65]],"id":69942666}],"con":true,"img":false}]}
{"op":"mcm","clk":"11541567205","pt":1719507158440,"mc":[{"id":"1.230178328","rc":[{"atb":[[5,2]],"id":70053016}],"con":true,"img":false}]}
{"op":"mcm","clk":"11541567212","pt":1719507158544,"mc":[{"id":"1.230178328","rc":[{"atl":[[4.4,1.58]],"id":70902603},{"atb":[[7.6,0]],"id":69942666}],"con":true,"img":false}]}
{"op":"mcm","clk":"11541567217","pt":1719507158647,"mc":[{"id":"1.230178328","rc":[{"atl":[[4.4,0]],"id":70902603},{"trd":[[4.4,3.16]],"ltp":4.4,"tv":3.16,"id":70902603},{"atb":[[7,1.65]],"id":69942666}],"con":true,"img":false}]}
{"op":"mcm","clk":"11541567224","pt":1719507158750,"mc":[{"id":"1.230178328","rc":[{"atl":[[4.8,2.11]],"id":70902603},{"atb":[[7.6,2]],"id":69942666}],"con":true,"img":false}]}
{"op":"mcm","clk":"11541567231","pt":1719507158855,"mc":[{"id":"1.230178328","rc":[{"atb":[[7,0]],"id":69942666}],"con":true,"img":false}]}
{"op":"mcm","clk":"11541567235","pt":1719507158959,"mc":[{"id":"1.230178328","rc":[{"atl":[[4.3,1.58]],"id":70902603}],"con":true,"img":false}]}
{"op":"mcm","clk":"11541567243","pt":1719507159066,"mc":[{"id":"1.230178328","rc":[{"atl":[[4.3,0]],"id":70902603},{"trd":[[4.3,3.16]],"ltp":4.3,"tv":3.16,"id":70902603}],"con":true,"img":false}]}
{"op":"mcm","clk":"11541567252","pt":1719507159169,"mc":[{"id":"1.230178328","rc":[{"atb":[[4,0.98],[3.95,9.91]],"id":70902603},{"atl":[[4.2,1.58],[4.8,2.24]],"id":70902603},{"atb":[[2.78,1.54]],"id":53082422},{"atl":[[3,1.82]],"id":53082422}],"con":true,"img":false}]}
{"op":"mcm","clk":"11541567262","pt":1719507159237,"mc":[{"id":"1.230178328","rc":[{"atl":[[4.2,0]],"id":70902603},{"trd":[[4.2,3.16]],"ltp":4.2,"tv":3.16,"id":70902603}],"con":true,"img":false}]}
{"op":"mcm","clk":"11541567283","pt":1719507159436,"mc":[{"id":"1.230178328","rc":[{"atl":[[4.7,0.84]],"id":70902603},{"atb":[[7.2,0]],"id":69942666}],"con":true,"img":false}]}
{"op":"mcm","clk":"11541567292","pt":1719507159541,"mc":[{"id":"1.230178328","rc":[{"atb":[[5.1,2.71],[5.2,1]],"id":64812720},{"atl":[[12.5,0.42],[13,1.4],[13.5,0.38]],"id":64812720},{"atb":[[3.8,1.38],[3.75,4.31],[1.13,0]],"id":70902603},{"atl":[[4.7,2.09],[4.6,1.14]],"id":70902603},{"atb":[[5.3,0.99],[5.2,2.63]],"id":66686625},{"atl":[[12.5,0.42],[13,1.25],[13.5,3.23]],"id":66686625},{"atb":[[5,3.05],[5.2,1],[5.1,3.56]],"id":70053016},{"atl":[[8.6,2.43],[9,0.58],[9.2,1.57]],"id":70053016},{"atb":[[7.4,0.7],[7.8,0.67],[7.6,2.69]],"id":69942666},{"atl":[[32,0.16],[34,0.39],[36,1.14]],"id":69942666},{"atb":[[2.76,1.74]],"id":53082422},{"atl":[[3.3,1.59],[3.15,1.66]],"id":53082422}],"con":true,"img":false}]}
{"op":"mcm","clk":"11541567302","pt":1719507159645,"mc":[{"id":"1.230178328","rc":[{"atl":[[14.5,6.34]],"id":64812720},{"atb":[[4,1.26]],"id":70902603},{"atl":[[4.6,1.27]],"id":70902603},{"atb":[[7,0.27]],"id":69942666},{"atl":[[140,0]],"id":69942666}],"con":true,"img":false}]}
{"op":"mcm","clk":"11541567309","pt":1719507159745,"mc":[{"id":"1.230178328","rc":[{"atl":[[30,2.88]],"id":64812720},{"atl":[[44,2.33]],"id":69942666},{"atl":[[5.2,0]],"id":53082422}],"con":true,"img":false}]}
{"op":"mcm","clk":"11541567316","pt":1719507159851,"mc":[{"id":"1.230178328","rc":[{"atb":[[5.3,1.59],[5.1,1.08]],"id":64812720},{"atl":[[30,1.73]],"id":64812720},{"atl":[[3.2,4.64]],"id":53082422}],"con":true,"img":false}]}
{"op":"mcm","clk":"11541567321","pt":1719507159955,"mc":[{"id":"1.230178328","rc":[{"atl":[[12.5,1.26],[14.5,7.49]],"id":64812720},{"atb":[[4,8.17],[3.95,2.91]],"id":70902603},{"atl":[[4.1,1.58]],"id":70902603},{"atb":[[7.6,0.69]],"id":69942666},{"atl":[[34,1.24]],"id":69942666}],"con":true,"img":false}]}
{"op":"mcm","clk":"11541567327","pt":1719507160057,"mc":[{"id":"1.230178328","rc":[{"atl":[[4.1,0]],"id":70902603},{"trd":[[4.1,3.16]],"ltp":4.1,"tv":3.16,"id":70902603},{"atb":[[7,2.27]],"id":69942666}],"con":true,"img":false}]}
{"op":"mcm","clk":"11541567355","pt":1719507160528,"mc":[{"id":"1.230178328","rc":[{"atb":[[2.74,0]],"id":70053016}],"con":true,"img":false}]}
{"op":"mcm","clk":"11541567363","pt":1719507160634,"mc":[{"id":"1.230178328","rc":[{"atb":[[7.2,1.65]],"id":69942666}],"con":true,"img":false}]}
{"op":"mcm","clk":"11541567367","pt":1719507160741,"mc":[{"id":"1.230178328","rc":[{"atl":[[12,0.43],[14,0.37],[15,0.35]],"id":64812720},{"atl":[[4.9,2.65]],"id":70902603},{"atl":[[12,0.43],[14,1.37],[14.5,0.36]],"id":66686625},{"atl":[[9.6,0.54],[9.4,0.55]],"id":70053016},{"atb":[[8,0.65]],"id":69942666},{"atl":[[38,0.15],[40,0.15],[30,0.17]],"id":69942666}],"con":true,"img":false}]}
{"op":"mcm","clk":"11541567383","pt":1719507161047,"mc":[{"id":"1.230178328","rc":[{"atl":[[12.5,0.84]],"id":64812720},{"atl":[[4.6,0.13]],"id":70902603},{"atb":[[5.3,0]],"id":66686625},{"atl":[[12.5,0]],"id":66686625},{"atb":[[5.2,0]],"id":70053016},{"atb":[[7.8,0],[7,0.27]],"id":69942666},{"atl":[[32,0]],"id":69942666}],"con":true,"img":false}]}
{"op":"mcm","clk":"11541567388","pt":1719507161153,"mc":[{"id":"1.230178328","rc":[{"atb":[[4.1,2.58]],"id":70902603},{"atl":[[4.6,0]],"id":70902603},{"trd":[[4.6,9.74]],"ltp":4.6,"tv":9.74,"id":70902603},{"atb":[[7.8,2]],"id":69942666}],"con":true,"img":false}]}
{"op":"mcm","clk":"11541567396","pt":1719507161258,"mc":[{"id":"1.230178328","rc":[{"atb":[[4.1,2.73]],"id":70902603},{"atl":[[4.7,1.96]],"id":70902603},{"atb":[[7.2,0]],"id":69942666}],"con":true,"img":false}]}
{"op":"mcm","clk":"11541567402","pt":1719507161362,"mc":[{"id":"1.230178328","rc":[{"atb":[[4,13.33],[3.95,0]],"id":70902603},{"atl":[[4.8,2.11]],"id":70902603},{"atl":[[8.6,3.6]],"id":70053016}],"con":true,"img":false}]}
{"op":"mcm","clk":"11541567409","pt":1719507161466,"mc":[{"id":"1.230178328","rc":[{"atb":[[4,6.42],[4.1,8.61]],"id":70902603},{"atb":[[5.3,0.84]],"id":66686625}],"con":true,"img":false}]}
{"op":"mcm","clk":"11541567419","pt":1719507161673,"mc":[{"id":"1.230178328","rc":[{"atl":[[8.6,4.8]],"id":70053016}],"con":true,"img":false}]}
{"op":"mcm","clk":"11541567434","pt":1719507161836,"mc":[{"id":"1.230178328","rc":[{"atb":[[4,6.14]],"id":70902603}],"con":true,"img":false}]}
{"op":"mcm","clk":"11541567442","pt":1719507161948,"mc":[{"id":"1.230178328","rc":[{"atb":[[1.13,0.27],[4.2,0.84]],"id":70902603}],"con":true,"img":false}]}
{"op":"mcm","clk":"11541567450","pt":1719507162044,"mc":[{"id":"1.230178328","rc":[{"atb":[[4.2,0.99]],"id":70902603}],"con":true,"img":false}]}
{"op":"mcm","clk":"11541567457","pt":1719507162147,"mc":[{"id":"1.230178328","rc":[{"atb":[[5.3,4.13]],"id":64812720},{"atb":[[4.2,6.31]],"id":70902603},{"atb":[[5.3,3.38]],"id":66686625},{"atb":[[7.8,0]],"id":69942666}],"con":true,"img":false}]}
{"op":"mcm","clk":"11541567473","pt":1719507162249,"mc":[{"id":"1.230178328","rc":[{"atl":[[11.5,0.45],[15.5,0.35],[16,0.35]],"id":64812720},{"atb":[[4.1,2.73]],"id":70902603},{"atl":[[5,2.63]],"id":70902603},{"atb":[[5.4,0.97]],"id":66686625},{"atl":[[11.5,0.45],[15,0.35]],"id":66686625},{"atb":[[4.9,2.77]],"id":70053016},{"atb":[[8.2,0.64],[7.6,2.69]],"id":69942666},{"atl":[[42,0.16],[44,2.49],[29,0.17]],"id":69942666}],"con":true,"img":false}]}
{"op":"mcm","clk":"11541567482","pt":1719507162355,"mc":[{"id":"1.230178328","rc":[{"atl":[[4.8,3.69]],"id":70902603},{"atl":[[9,1.58],[9.2,0.57]],"id":70053016}],"con":true,"img":false}]}
{"op":"mcm","clk":"11541567491","pt":1719507162464,"mc":[{"id":"1.230178328","rc":[{"atb":[[4.4,0],[3.95,6]],"id":64812720},{"atl":[[14.5,1.15],[17,2]],"id":64812720},{"atb":[[3.65,0]],"id":70902603},{"atb":[[5.4,4.06],[5.2,1]],"id":66686625},{"atl":[[13,3.25],[13.5,1.23]],"id":66686625},{"atl":[[8.6,7.96],[8.8,1]],"id":70053016}],"con":true,"img":false}]}
{"op":"mcm","clk":"11541567497","pt":1719507162565,"mc":[{"id":"1.230178328","rc":[{"atl":[[4.7,0.84]],"id":70902603}],"con":true,"img":false}]}
{"op":"mcm","clk":"11541567507","pt":1719507162669,"mc":[{"id":"1.230178328","rc":[{"atl":[[4.7,0]],"id":70902603},{"trd":[[4.7,4.85]],"ltp":4.7,"tv":4.85,"id":70902603},{"atl":[[13.5,2.23]],"id":66686625},{"atl":[[9,0.58],[9.2,1.57]],"id":70053016}],"con":true,"img":false}]}
{"op":"mcm","clk":"11541567516","pt":1719507162774,"mc":[{"id":"1.230178328","rc":[{"atb":[[5.4,5.63],[5.1,0.05]],"id":66686625},{"atl":[[14,0.37]],"id":66686625}],"con":true,"img":false}]}
{"op":"mcm","clk":"11541567522","pt":1719507162827,"mc":[{"id":"1.230178328","rc":[{"atl":[[14.5,0]],"id":64812720}],"con":true,"img":false}]}
{"op":"mcm","clk":"11541567529","pt":1719507162941,"mc":[{"id":"1.230178328","rc":[{"atb":[[5.4,0.84]],"id":64812720},{"atl":[[32,9.15]],"id":64812720},{"atl":[[13.5,1.23],[14,1.37]],"id":66686625},{"atl":[[9,1.58],[9.2,0.57]],"id":70053016}],"con":true,"img":false}]}
{"op":"mcm","clk":"11541567537","pt":1719507163038,"mc":[{"id":"1.230178328","rc":[{"atb":[[4,5.3]],"id":70902603},{"atl":[[4.7,1.58]],"id":70902603},{"atb":[[5.4,4.1]],"id":66686625}],"con":true,"img":false}]}
{"op":"mcm","clk":"11541567540","pt":1719507163136,"mc":[{"id":"1.230178328","rc":[{"atl":[[4.6,1.58]],"id":70902603},{"atl":[[9,0.58],[9.2,1.57]],"id":70053016}],"con":true,"img":false}]}
{"op":"mcm","clk":"11541567554","pt":1719507163261,"mc":[{"id":"1.230178328","rc":[{"atl":[[29,0]],"id":64812720},{"atb":[[5.5,4.61]],"id":66686625},{"atb":[[7.6,0.69]],"id":69942666}],"con":true,"img":false}]}
{"op":"mcm","clk":"11541567564","pt":1719507163359,"mc":[{"id":"1.230178328","rc":[{"atl":[[1000,0.63]],"id":64812720},{"atb":[[8.2,2.64]],"id":69942666}],"con":true,"img":false}]}
{"op":"mcm","clk":"11541567577","pt":1719507163582,"mc":[{"id":"1.230178328","rc":[{"atb":[[5.6,1.51]],"id":66686625}],"con":true,"img":false}]}
{"op":"mcm","clk":"11541567581","pt":1719507163667,"mc":[{"id":"1.230178328","rc":[{"atb":[[5.4,2.53],[5.6,3.04]],"id":66686625}],"con":true,"img":false}]}
{"op":"mcm","clk":"11541567591","pt":1719507163870,"mc":[{"id":"1.230178328","rc":[{"atb":[[5.5,0]],"id":66686625}],"con":true,"img":false}]}
{"op":"mcm","clk":"11541567596","pt":1719507163975,"mc":[{"id":"1.230178328","rc":[{"atb":[[5.5,0.95]],"id":64812720},{"atl":[[5.1,2.61]],"id":70902603},{"atb":[[5.3,2.53],[5.7,0.91]],"id":66686625},{"atb":[[8.4,0.84]],"id":69942666},{"atl":[[32,0.17],[28,0.18]],"id":69942666}],"con":true,"img":false}]}
{"op":"mcm","clk":"11541567605","pt":1719507164142,"mc":[{"id":"1.230178328","rc":[{"atl":[[4.5,1.58]],"id":70902603}],"con":true,"img":false}]}
{"op":"mcm","clk":"11541567610","pt":1719507164250,"mc":[{"id":"1.230178328","rc":[{"atb":[[5.3,2.53],[5.5,2.49]],"id":64812720},{"atl":[[11.5,0]],"id":64812720},{"atb":[[5.6,1.51]],"id":66686625},{"atl":[[11.5,0]],"id":66686625},{"atb":[[8.2,0.64]],"id":69942666},{"atl":[[29,0]],"id":69942666}],"con":true,"img":false}]}
{"op":"mcm","clk":"11541567616","pt":1719507164361,"mc":[{"id":"1.230178328","rc":[{"atl":[[8.6,7.83]],"id":70053016},{"atb":[[7.8,2]],"id":69942666}],"con":true,"img":false}]}
{"op":"mcm","clk":"11541567629","pt":1719507164557,"mc":[{"id":"1.230178328","rc":[{"atl":[[4.3,1.58]],"id":70902603}],"con":true,"img":false}]}
{"op":"mcm","clk":"11541567638","pt":1719507164662,"mc":[{"id":"1.230178328","rc":[{"atl":[[4.3,0]],"id":70902603},{"trd":[[4.3,6.32]],"ltp":4.3,"tv":6.32,"id":70902603}],"con":true,"img":false}]}
{"op":"mcm","clk":"11541567662","pt":1719507164872,"mc":[{"id":"1.230178328","rc":[{"atl":[[1000,0.14]],"id":70053016}],"con":true,"img":false}]}
{"op":"mcm","clk":"11541567669","pt":1719507164977,"mc":[{"id":"1.230178328","rc":[{"atb":[[5.3,0]],"id":66686625},{"atb":[[8.4,0]],"id":69942666}],"con":true,"img":false}]}
{"op":"mcm","clk":"11541567688","pt":1719507165237,"mc":[{"id":"1.230178328","rc":[{"atl":[[1000,0]],"id":70053016}],"con":true,"img":false}]}
{"op":"mcm","clk":"11541567697","pt":1719507165356,"mc":[{"id":"1.230178328","rc":[{"atl":[[8.4,0.14]],"id":70053016}],"con":true,"img":false}]}
{"op":"mcm","clk":"11541567704","pt":1719507165448,"mc":[{"id":"1.230178328","rc":[{"atb":[[7.8,0]],"id":69942666}],"con":true,"img":false}]}
{"op":"mcm","clk":"11541567713","pt":1719507165553,"mc":[{"id":"1.230178328","rc":[{"atl":[[9,1.58]],"id":70053016},{"atb":[[8.4,2]],"id":69942666}],"con":true,"img":false}]}
{"op":"mcm","clk":"11541567722","pt":1719507165656,"mc":[{"id":"1.230178328","rc":[{"atl":[[9.2,0.57]],"id":70053016}],"con":true,"img":false}]}
{"op":"mcm","clk":"11541567731","pt":1719507165765,"mc":[{"id":"1.230178328","rc":[{"atl":[[12.5,0.42]],"id":66686625},{"atl":[[27,0.19]],"id":69942666}],"con":true,"img":false}]}
{"op":"mcm","clk":"11541567772","pt":1719507166282,"mc":[{"id":"1.230178328","rc":[{"atl":[[4.4,1.58]],"id":70902603}],"con":true,"img":false}]}
{"op":"mcm","clk":"11541567789","pt":1719507166482,"mc":[{"id":"1.230178328","rc":[{"atb":[[5.5,3.34]],"id":64812720},{"atb":[[4,0.14],[3.95,10.6]],"id":70902603},{"atl":[[4.6,3.8]],"id":70902603},{"atl":[[9,0.58],[9.2,1.57]],"id":70053016},{"atb":[[8.4,0]],"id":69942666}],"con":true,"img":false}]}
{"op":"mcm","clk":"11541567797","pt":1719507166549,"mc":[{"id":"1.230178328","rc":[{"atb":[[8.2,2.64]],"id":69942666}],"con":true,"img":false}]}
{"op":"mcm","clk":"11541567807","pt":1719507166651,"mc":[{"id":"1.230178328","rc":[{"atb":[[5.3,0],[5.6,1.65]],"id":64812720},{"atl":[[4.3,1.58]],"id":70902603}],"con":true,"img":false}]}
{"op":"mcm","clk":"11541567815","pt":1719507166755,"mc":[{"id":"1.230178328","rc":[{"atl":[[13,0.4],[15,1.35]],"id":64812720},{"atb":[[4.2,6.16]],"id":70902603},{"atl":[[4.3,0]],"id":70902603},{"trd":[[4.3,9.48]],"ltp":4.3,"tv":9.48,"id":70902603},{"atb":[[3.95,1]],"id":70053016},{"atb":[[2.5,0],[2.56,12.09],[2.74,1.29]],"id":53082422}],"con":true,"img":false}]}
{"op":"mcm","clk":"11541567825","pt":1719507166855,"mc":[{"id":"1.230178328","rc":[{"atb":[[4.2,6.33]],"id":70902603},{"atb":[[4,10.72]],"id":70053016},{"atb":[[2.78,0.27]],"id":53082422}],"con":true,"img":false}]}
{"op":"mcm","clk":"11541567845","pt":1719507167064,"mc":[{"id":"1.230178328","rc":[{"atb":[[3.9,1.34]],"id":70902603},{"atl":[[26,0.19],[29,0.17]],"id":69942666}],"con":true,"img":false}]}
{"op":"mcm","clk":"11541567871","pt":1719507167376,"mc":[{"id":"1.230178328","rc":[{"atb":[[5.6,0]],"id":64812720},{"atl":[[12,0]],"id":66686625},{"atl":[[27,0]],"id":69942666}],"con":true,"img":false}]}
{"op":"mcm","clk":"11541567883","pt":1719507167468,"mc":[{"id":"1.230178328","rc":[{"atl":[[12.5,0]],"id":64812720},{"atb":[[2.78,1.11]],"id":53082422}],"con":true,"img":false}]}
{"op":"mcm","clk":"11541567891","pt":1719507167573,"mc":[{"id":"1.230178328","rc":[{"atl":[[13,1.25],[13.5,4.9]],"id":66686625},{"atl":[[8.8,8.97]],"id":70053016},{"atb":[[8.2,0.64]],"id":69942666}],"con":true,"img":false}]}
{"op":"mcm","clk":"11541567900","pt":1719507167675,"mc":[{"id":"1.230178328","rc":[{"atl":[[8.6,4.67]],"id":70053016},{"atb":[[7.8,2]],"id":69942666}],"con":true,"img":false}]}
{"op":"mcm","clk":"11541567933","pt":1719507167951,"mc":[{"id":"1.230178328","rc":[{"atb":[[5.7,3.45]],"id":66686625}],"con":true,"img":false}]}
{"op":"mcm","clk":"11541567947","pt":1719507168157,"mc":[{"id":"1.230178328","rc":[{"atl":[[4.3,1.58]],"id":70902603}],"con":true,"img":false}]}
{"op":"mcm","clk":"11541567957","pt":1719507168267,"mc":[{"id":"1.230178328","rc":[{"atl":[[4.4,0],[4.5,0.45],[4.3,0]],"id":70902603},{"trd":[[4.5,8.56],[4.3,12.64],[4.4,6.32]],"ltp":4.5,"tv":27.52,"id":70902603}],"con":true,"img":false}]}
{"op":"mcm","clk":"11541567966","pt":1719507168368,"mc":[{"id":"1.230178328","rc":[{"atb":[[4.2,6.16]],"id":70902603},{"atl":[[4.5,0]],"id":70902603},{"trd":[[4.5,9.48]],"ltp":4.5,"tv":9.48,"id":70902603}],"con":true,"img":false}]}
{"op":"mcm","clk":"11541567973","pt":1719507168467,"mc":[{"id":"1.230178328","rc":[{"atb":[[4.2,6.33]],"id":70902603},{"atb":[[5.8,0.84]],"id":66686625}],"con":true,"img":false}]}
{"op":"mcm","clk":"11541567983","pt":1719507168576,"mc":[{"id":"1.230178328","rc":[{"atl":[[12,0.43],[15.5,0.34]],"id":66686625},{"atl":[[8.4,0.76]],"id":70053016},{"atb":[[7.8,0]],"id":69942666},{"atl":[[25,0.21]],"id":69942666}],"con":true,"img":false}]}
{"op":"mcm","clk":"11541567989","pt":1719507168680,"mc":[{"id":"1.230178328","rc":[{"atb":[[8.2,2.64]],"id":69942666}],"con":true,"img":false}]}
{"op":"mcm","clk":"11541568000","pt":1719507168784,"mc":[{"id":"1.230178328","rc":[{"atb":[[5.5,2.49]],"id":64812720},{"atl":[[15.5,1.35]],"id":64812720}],"con":true,"img":false}]}
{"op":"mcm","clk":"11541568009","pt":1719507168883,"mc":[{"id":"1.230178328","rc":[{"atb":[[5.6,1]],"id":64812720},{"atl":[[15,0.35]],"id":64812720},{"atl":[[12.5,0]],"id":66686625},{"atb":[[8.2,2]],"id":69942666}],"con":true,"img":false}]}
{"op":"mcm","clk":"11541568027","pt":1719507169046,"mc":[{"id":"1.230178328","rc":[{"atb":[[7,1.92]],"id":69942666}],"con":true,"img":false}]}
{"op":"mcm","clk":"11541568036","pt":1719507169161,"mc":[{"id":"1.230178328","rc":[{"atb":[[4.4,6],[3.95,0]],"id":64812720},{"atl":[[15,2.35]],"id":64812720}],"con":true,"img":false}]}
{"op":"mcm","clk":"11541568047","pt":1719507169254,"mc":[{"id":"1.230178328","rc":[{"atl":[[17,0]],"id":64812720}],"con":true,"img":false}]}
{"op":"mcm","clk":"11541568069","pt":1719507169560,"mc":[{"id":"1.230178328","rc":[{"atb":[[8.2,0]],"id":69942666}],"con":true,"img":false}]}
{"op":"mcm","clk":"11541568081","pt":1719507169663,"mc":[{"id":"1.230178328","rc":[{"atb":[[7.8,2],[7,0.27]],"id":69942666}],"con":true,"img":false}]}
{"op":"mcm","clk":"11541568156","pt":1719507170361,"mc":[{"id":"1.230178328","rc":[{"atl":[[12.5,0.42]],"id":66686625},{"atb":[[8.2,0.64],[7.8,0]],"id":69942666},{"atl":[[24,0.22],[27,0.19]],"id":69942666}],"con":true,"img":false}]}
{"op":"mcm","clk":"11541568164","pt":1719507170465,"mc":[{"id":"1.230178328","rc":[{"atb":[[7.6,2.69]],"id":69942666},{"atb":[[2.76,6.29]],"id":53082422}],"con":true,"img":false}]}
{"op":"mcm","clk":"11541568171","pt":1719507170565,"mc":[{"id":"1.230178328","rc":[{"atl":[[4.5,1.58]],"id":70902603}],"con":true,"img":false}]}
{"op":"mcm","clk":"11541568189","pt":1719507170772,"mc":[{"id":"1.230178328","rc":[{"atb":[[5.6,3.53]],"id":64812720},{"atl":[[8.4,0.14]],"id":70053016}],"con":true,"img":false}]}
{"op":"mcm","clk":"11541568201","pt":1719507170883,"mc":[{"id":"1.230178328","rc":[{"atl":[[4.4,1.58]],"id":70902603}],"con":true,"img":false}]}
{"op":"mcm","clk":"11541568228","pt":1719507171145,"mc":[{"id":"1.230178328","rc":[{"atb":[[2.8,0]],"id":70902603},{"atb":[[3.2,0]],"id":66686625},{"atb":[[7.6,0.69]],"id":69942666}],"con":true,"img":false}]}
{"op":"mcm","clk":"11541568238","pt":1719507171252,"mc":[{"id":"1.230178328","rc":[{"atb":[[8.2,2.64]],"id":69942666}],"con":true,"img":false}]}
{"op":"mcm","clk":"11541568259","pt":1719507171463,"mc":[{"id":"1.230178328","rc":[{"atb":[[5.4,0],[5.7,0.84]],"id":64812720},{"atb":[[3.05,5.78]],"id":70053016},{"atb":[[2.68,2.09]],"id":53082422}],"con":true,"img":false}]}
{"op":"mcm","clk":"11541568266","pt":1719507171559,"mc":[{"id":"1.230178328","rc":[{"atb":[[2.38,0]],"id":64812720},{"atb":[[2.58,0]],"id":53082422}],"con":true,"img":false}]}
{"op":"mcm","clk":"11541568272","pt":1719507171657,"mc":[{"id":"1.230178328","rc":[{"atl":[[4.3,1.58]],"id":70902603},{"atb":[[2.16,11.29]],"id":70053016}],"con":true,"img":false}]}
{"op":"mcm","clk":"11541568280","pt":1719507171762,"mc":[{"id":"1.230178328","rc":[{"atl":[[4.3,0]],"id":70902603},{"trd":[[4.3,15.8]],"ltp":4.3,"tv":15.8,"id":70902603}],"con":true,"img":false}]}
{"op":"mcm","clk":"11541568290","pt":1719507171869,"mc":[{"id":"1.230178328","rc":[{"atb":[[4.2,6.16]],"id":70902603},{"atb":[[2.16,5.45]],"id":70053016},{"atb":[[2.76,1.74]],"id":53082422}],"con":true,"img":false}]}
{"op":"mcm","clk":"11541568297","pt":1719507171972,"mc":[{"id":"1.230178328","rc":[{"atb":[[8.4,0.84]],"id":69942666}],"con":true,"img":false}]}
{"op":"mcm","clk":"11541568310","pt":1719507172181,"mc":[{"id":"1.230178328","rc":[{"atb":[[2.4,0]],"id":70902603},{"atb":[[8.2,0.64]],"id":69942666},{"atb":[[1.53,15.96]],"id":53082422}],"con":true,"img":false}]}
{"op":"mcm","clk":"11541568315","pt":1719507172240,"mc":[{"id":"1.230178328","rc":[{"atb":[[7.8,2]],"id":69942666}],"con":true,"img":false}]}
{"op":"mcm","clk":"11541568335","pt":1719507172554,"mc":[{"id":"1.230178328","rc":[{"atl":[[9.8,1.59]],"id":70053016},{"atl":[[23,0.22]],"id":69942666}],"con":true,"img":false}]}
{"op":"mcm","clk":"11541568341","pt":1719507172665,"mc":[{"id":"1.230178328","rc":[{"atb":[[2.76,6.29]],"id":53082422}],"con":true,"img":false}]}
{"op":"mcm","clk":"11541568370","pt":1719507172974,"mc":[{"id":"1.230178328","rc":[{"atb":[[8.4,0]],"id":69942666}],"con":true,"img":false}]}
{"op":"mcm","clk":"11541568380","pt":1719507173076,"mc":[{"id":"1.230178328","rc":[{"atl":[[12,0]],"id":66686625},{"atl":[[23,0]],"id":69942666}],"con":true,"img":false}]}
{"op":"mcm","clk":"11541568390","pt":1719507173184,"mc":[{"id":"1.230178328","rc":[{"atb":[[4,9.04],[3.95,0]],"id":70902603}],"con":true,"img":false}]}
{"op":"mcm","clk":"11541568398","pt":1719507173244,"mc":[{"id":"1.230178328","rc":[{"atb":[[5.7,1.69]],"id":64812720},{"atb":[[2.76,1.74]],"id":53082422}],"con":true,"img":false}]}
{"op":"mcm","clk":"11541568410","pt":1719507173457,"mc":[{"id":"1.230178328","rc":[{"atb":[[7.8,0]],"id":69942666}],"con":true,"img":false}]}
{"op":"mcm","clk":"11541568419","pt":1719507173558,"mc":[{"id":"1.230178328","rc":[{"atb":[[8.4,2]],"id":69942666}],"con":true,"img":false}]}
{"op":"mcm","clk":"11541568470","pt":1719507174284,"mc":[{"id":"1.230178328","rc":[{"atl":[[8.4,3.16]],"id":70053016}],"con":true,"img":false}]}
{"op":"mcm","clk":"11541568487","pt":1719507174484,"mc":[{"id":"1.230178328","rc":[{"atl":[[12,0.43]],"id":66686625}],"con":true,"img":false}]}
{"op":"mcm","clk":"11541568510","pt":1719507174757,"mc":[{"id":"1.230178328","rc":[{"atb":[[8.4,0]],"id":69942666}],"con":true,"img":false}]}
{"op":"mcm","clk":"11541568522","pt":1719507174871,"mc":[{"id":"1.230178328","rc":[{"atl":[[12.5,0]],"id":66686625},{"atb":[[8.2,2.64]],"id":69942666},{"atl":[[24,0]],"id":69942666}],"con":true,"img":false}]}
