{"op":"mcm","clk":"11536832985","pt":1719431775521,"mc":[{"id":"1.230180133","marketDefinition":{"bspMarket":true,"turnInPlayEnabled":false,"persistenceEnabled":false,"marketBaseRate":5.0,"eventId":"33376437","eventTypeId":"4339","numberOfWinners":2,"bettingType":"ODDS","marketType":"PLACE","marketTime":"2024-06-27T16:39:00.000Z","suspendTime":"2024-06-27T16:39:00.000Z","bspReconciled":false,"complete":true,"inPlay":false,"crossMatching":false,"runnersVoidable":false,"numberOfActiveRunners":6,"betDelay":0,"status":"OPEN","runners":[{"status":"ACTIVE","sortPriority":1,"id":66314580,"name":"1. Shesbeenlit"},{"status":"ACTIVE","sortPriority":2,"id":67487134,"name":"2. Salacres Elbuena"},{"status":"ACTIVE","sortPriority":3,"id":67130716,"name":"3. Donishall Dolly"},{"status":"ACTIVE","sortPriority":4,"id":70086038,"name":"4. Greencroft Gerry"},{"status":"ACTIVE","sortPriority":5,"id":53826530,"name":"5. Meena"},{"status":"ACTIVE","sortPriority":6,"id":64618726,"name":"6. Ballyboss Rose"}],"regulators":["MR_INT"],"venue":"Towcester","countryCode":"GB","discountAllowed":false,"timezone":"Europe/London","openDate":"2024-06-27T13:33:00.000Z","version":5994767127,"name":"To Be Placed","eventName":"Towcester 27th Jun"},"rc":[],"con":true,"img":false}]}
{"op":"mcm","clk":"11536833147","pt":1719431777531,"mc":[{"id":"1.230180133","marketDefinition":{"bspMarket":true,"turnInPlayEnabled":false,"persistenceEnabled":false,"marketBaseRate":5.0,"eventId":"33376437","eventTypeId":"4339","numberOfWinners":2,"bettingType":"ODDS","marketType":"PLACE","marketTime":"2024-06-27T16:39:00.000Z","suspendTime":"2024-06-27T16:39:00.000Z","bspReconciled":false,"complete":true,"inPlay":false,"crossMatching":false,"runnersVoidable":false,"numberOfActiveRunners":6,"betDelay":0,"status":"OPEN","runners":[{"status":"ACTIVE","sortPriority":1,"id":66314580,"name":"1. Shesbeenlit"},{"status":"ACTIVE","sortPriority":2,"id":67487134,"name":"2. Salacres Elbuena"},{"status":"ACTIVE","sortPriority":3,"id":67130716,"name":"3. Donishall Dolly"},{"status":"ACTIVE","sortPriority":4,"id":70086038,"name":"4. Greencroft Gerry"},{"status":"ACTIVE","sortPriority":5,"id":53826530,"name":"5. Meena"},{"status":"ACTIVE","sortPriority":6,"id":64618726,"name":"6. Ballyboss Rose"}],"regulators":["MR_INT"],"venue":"Towcester","countryCode":"GB","discountAllowed":true,"timezone":"Europe/London","openDate":"2024-06-27T13:33:00.000Z","version":5994767127,"name":"To Be Placed","eventName":"Towcester 27th Jun"},"rc":[],"con":true,"img":false}]}
{"op":"mcm","clk":"11537083885","pt":1719435433215,"mc":[{"id":"1.230180133","rc":[{"atb":[[1.03,10.99]],"id":67487134},{"atl":[[990,0.84]],"id":67487134},{"spn":495.51,"spf":"NaN","id":67487134},{"atb":[[1.03,10.99]],"id":66314580},{"atl":[[1000,0.84]],"id":66314580},{"spn":500.51,"spf":"NaN","id":66314580},{"atb":[[1.03,10.99]],"id":53826530},{"atl":[[990,0.84]],"id":53826530},{"spn":495.51,"spf":"NaN","id":53826530},{"atb":[[1.01,32.96]],"id":70086038},{"atl":[[1000,0.84]],"id":70086038},{"spn":500.5,"spf":"NaN","id":70086038},{"atb":[[1.01,32.96]],"id":64618726},{"atl":[[1000,0.84]],"id":64618726},{"spn":500.5,"spf":"NaN","id":64618726},{"atb":[[1.02,16.48]],"id":67130716},{"atl":[[1000,0.84]],"id":67130716},{"spn":500.51,"spf":"NaN","id":67130716}],"con":true,"img":false}]}
{"op":"mcm","clk":"11537235637","pt":1719437882799,"mc":[{"id":"1.230180133","marketDefinition":{"bspMarket":true,"turnInPlayEnabled":false,"persistenceEnabled":false,"marketBaseRate":5.0,"eventId":"33376437","eventTypeId":"4339","numberOfWinners":2,"bettingType":"ODDS","marketType":"PLACE","marketTime":"2024-06-27T16:39:00.000Z","suspendTime":"2024-06-27T16:39:00.000Z","bspReconciled":false,"complete":true,"inPlay":false,"crossMatching":false,"runnersVoidable":false,"numberOfActiveRunners":6,"betDelay":0,"status":"OPEN","runners":[{"status":"ACTIVE","sortPriority":1,"id":66314580,"name":"1. Shesbeenlit"},{"status":"ACTIVE","sortPriority":2,"id":67487134,"name":"2. Salacres Elbuena"},{"status":"ACTIVE","sortPriority":3,"id":67130716,"name":"3. Donishall Dolly"},{"status":"ACTIVE","sortPriority":4,"id":70086038,"name":"4. Greencroft Gerry"},{"status":"ACTIVE","sortPriority":5,"id":53826530,"name":"5. Meena"},{"status":"ACTIVE","sortPriority":6,"id":64618726,"name":"6. Ballyboss Rose"}],"regulators":["MR_INT"],"venue":"Towcester","countryCode":"GB","discountAllowed":true,"timezone":"Europe/London","openDate":"2024-06-27T13:33:00.000Z","version":5994767127,"name":"To Be Placed","eventName":"Towcester 27th Jun"},"rc":[{"atb":[[1.03,10.99]],"id":67487134},{"atl":[[990,0.84]],"id":67487134},{"spn":495.51,"spf":"NaN","id":67487134},{"atb":[[1.03,10.99]],"id":66314580},{"atl":[[1000,0.84]],"id":66314580},{"spn":500.51,"spf":"NaN","id":66314580},{"atb":[[1.03,10.99]],"id":53826530},{"atl":[[990,0.84]],"id":53826530},{"spn":495.51,"spf":"NaN","id":53826530},{"atb":[[1.01,32.96]],"id":70086038},{"atl":[[1000,0.84]],"id":70086038},{"spn":500.5,"spf":"NaN","id":70086038},{"atb":[[1.01,32.96]],"id":64618726},{"atl":[[1000,0.84]],"id":64618726},{"spn":500.5,"spf":"NaN","id":64618726},{"atb":[[1.02,16.48]],"id":67130716},{"atl":[[1000,0.84]],"id":67130716},{"spn":500.51,"spf":"NaN","id":67130716}],"con":true,"img":true}]}
{"op":"mcm","clk":"11537302167","pt":1719439031147,"mc":[{"id":"1.230180133","rc":[{"atb":[[1.03,10.99]],"id":67487134},{"atl":[[990,0.17]],"id":67487134},{"atb":[[1.03,10.99]],"id":66314580},{"atl":[[1000,0.17]],"id":66314580},{"atb":[[1.03,10.99]],"id":53826530},{"atl":[[990,0.17]],"id":53826530},{"atb":[[1.01,32.96]],"id":70086038},{"atl":[[1000,0.17]],"id":70086038},{"atb":[[1.01,32.96]],"id":64618726},{"atl":[[1000,0.17]],"id":64618726},{"atb":[[1.02,16.48]],"id":67130716},{"atl":[[1000,0.17]],"id":67130716}],"con":true,"img":false}]}
{"op":"mcm","clk":"11537576925","pt":1719443282844,"mc":[{"id":"1.230180133","marketDefinition":{"bspMarket":true,"turnInPlayEnabled":false,"persistenceEnabled":false,"marketBaseRate":5.0,"eventId":"33376437","eventTypeId":"4339","numberOfWinners":2,"bettingType":"ODDS","marketType":"PLACE","marketTime":"2024-06-27T16:39:00.000Z","suspendTime":"2024-06-27T16:39:00.000Z","bspReconciled":false,"complete":true,"inPlay":false,"crossMatching":false,"runnersVoidable":false,"numberOfActiveRunners":6,"betDelay":0,"status":"OPEN","runners":[{"status":"ACTIVE","sortPriority":1,"id":66314580,"name":"1. Shesbeenlit"},{"status":"ACTIVE","sortPriority":2,"id":67487134,"name":"2. Salacres Elbuena"},{"status":"ACTIVE","sortPriority":3,"id":67130716,"name":"3. Donishall Dolly"},{"status":"ACTIVE","sortPriority":4,"id":70086038,"name":"4. Greencroft Gerry"},{"status":"ACTIVE","sortPriority":5,"id":53826530,"name":"5. Meena"},{"status":"ACTIVE","sortPriority":6,"id":64618726,"name":"6. Ballyboss Rose"}],"regulators":["MR_INT"],"venue":"Towcester","countryCode":"GB","discountAllowed":true,"timezone":"Europe/London","openDate":"2024-06-27T13:33:00.000Z","version":5994767127,"name":"To Be Placed","eventName":"Towcester 27th Jun"},"rc":[{"atb":[[1.03,10.99]],"id":67487134},{"atl":[[990,0.17]],"id":67487134},{"spn":495.51,"spf":"NaN","id":67487134},{"atb":[[1.03,10.99]],"id":66314580},{"atl":[[1000,0.17]],"id":66314580},{"spn":500.51,"spf":"NaN","id":66314580},{"atb":[[1.03,10.99]],"id":53826530},{"atl":[[990,0.17]],"id":53826530},{"spn":495.51,"spf":"NaN","id":53826530},{"atb":[[1.01,32.96]],"id":70086038},{"atl":[[1000,0.17]],"id":70086038},{"spn":500.5,"spf":"NaN","id":70086038},{"atb":[[1.01,32.96]],"id":64618726},{"atl":[[1000,0.17]],"id":64618726},{"spn":500.5,"spf":"NaN","id":64618726},{"atb":[[1.02,16.48]],"id":67130716},{"atl":[[1000,0.17]],"id":67130716},{"spn":500.51,"spf":"NaN","id":67130716}],"con":true,"img":true}]}
{"op":"mcm","clk":"11537958613","pt":1719448682890,"mc":[{"id":"1.230180133","marketDefinition":{"bspMarket":true,"turnInPlayEnabled":false,"persistenceEnabled":false,"marketBaseRate":5.0,"eventId":"33376437","eventTypeId":"4339","numberOfWinners":2,"bettingType":"ODDS","marketType":"PLACE","marketTime":"2024-06-27T16:39:00.000Z","suspendTime":"2024-06-27T16:39:00.000Z","bspReconciled":false,"complete":true,"inPlay":false,"crossMatching":false,"runnersVoidable":false,"numberOfActiveRunners":6,"betDelay":0,"status":"OPEN","runners":[{"status":"ACTIVE","sortPriority":1,"id":66314580,"name":"1. Shesbeenlit"},{"status":"ACTIVE","sortPriority":2,"id":67487134,"name":"2. Salacres Elbuena"},{"status":"ACTIVE","sortPriority":3,"id":67130716,"name":"3. Donishall Dolly"},{"status":"ACTIVE","sortPriority":4,"id":70086038,"name":"4. Greencroft Gerry"},{"status":"ACTIVE","sortPriority":5,"id":53826530,"name":"5. Meena"},{"status":"ACTIVE","sortPriority":6,"id":64618726,"name":"6. Ballyboss Rose"}],"regulators":["MR_INT"],"venue":"Towcester","countryCode":"GB","discountAllowed":true,"timezone":"Europe/London","openDate":"2024-06-27T13:33:00.000Z","version":5994767127,"name":"To Be Placed","eventName":"Towcester 27th Jun"},"rc":[{"atb":[[1.03,10.99]],"id":67487134},{"atl":[[990,0.17]],"id":67487134},{"spn":495.51,"spf":"NaN","id":67487134},{"atb":[[1.03,10.99]],"id":66314580},{"atl":[[1000,0.17]],"id":66314580},{"spn":500.51,"spf":"NaN","id":66314580},{"atb":[[1.03,10.99]],"id":53826530},{"atl":[[990,0.17]],"id":53826530},{"spn":495.51,"spf":"NaN","id":53826530},{"atb":[[1.01,32.96]],"id":70086038},{"atl":[[1000,0.17]],"id":70086038},{"spn":500.5,"spf":"NaN","id":70086038},{"atb":[[1.01,32.96]],"id":64618726},{"atl":[[1000,0.17]],"id":64618726},{"spn":500.5,"spf":"NaN","id":64618726},{"atb":[[1.02,16.48]],"id":67130716},{"atl":[[1000,0.17]],"id":67130716},{"spn":500.51,"spf":"NaN","id":67130716}],"con":true,"img":true}]}
{"op":"mcm","clk":"11538174189","pt":1719454082862,"mc":[{"id":"1.230180133","marketDefinition":{"bspMarket":true,"turnInPlayEnabled":false,"persistenceEnabled":false,"marketBaseRate":5.0,"eventId":"33376437","eventTypeId":"4339","numberOfWinners":2,"bettingType":"ODDS","marketType":"PLACE","marketTime":"2024-06-27T16:39:00.000Z","suspendTime":"2024-06-27T16:39:00.000Z","bspReconciled":false,"complete":true,"inPlay":false,"crossMatching":false,"runnersVoidable":false,"numberOfActiveRunners":6,"betDelay":0,"status":"OPEN","runners":[{"status":"ACTIVE","sortPriority":1,"id":66314580,"name":"1. Shesbeenlit"},{"status":"ACTIVE","sortPriority":2,"id":67487134,"name":"2. Salacres Elbuena"},{"status":"ACTIVE","sortPriority":3,"id":67130716,"name":"3. Donishall Dolly"},{"status":"ACTIVE","sortPriority":4,"id":70086038,"name":"4. Greencroft Gerry"},{"status":"ACTIVE","sortPriority":5,"id":53826530,"name":"5. Meena"},{"status":"ACTIVE","sortPriority":6,"id":64618726,"name":"6. Ballyboss Rose"}],"regulators":["MR_INT"],"venue":"Towcester","countryCode":"GB","discountAllowed":true,"timezone":"Europe/London","openDate":"2024-06-27T13:33:00.000Z","version":5994767127,"name":"To Be Placed","eventName":"Towcester 27th Jun"},"rc":[{"atb":[[1.03,10.99]],"id":67487134},{"atl":[[990,0.17]],"id":67487134},{"spn":495.51,"spf":"NaN","id":67487134},{"atb":[[1.03,10.99]],"id":66314580},{"atl":[[1000,0.17]],"id":66314580},{"spn":500.51,"spf":"NaN","id":66314580},{"atb":[[1.03,10.99]],"id":53826530},{"atl":[[990,0.17]],"id":53826530},{"spn":495.51,"spf":"NaN","id":53826530},{"atb":[[1.01,32.97]],"id":70086038},{"atl":[[1000,0.17]],"id":70086038},{"spn":500.5,"spf":"NaN","id":70086038},{"atb":[[1.01,32.97]],"id":64618726},{"atl":[[1000,0.17]],"id":64618726},{"spn":500.5,"spf":"NaN","id":64618726},{"atb":[[1.02,16.48]],"id":67130716},{"atl":[[1000,0.17]],"id":67130716},{"spn":500.51,"spf":"NaN","id":67130716}],"con":true,"img":true}]}
{"op":"mcm","clk":"11538371902","pt":1719459482936,"mc":[{"id":"1.230180133","marketDefinition":{"bspMarket":true,"turnInPlayEnabled":false,"persistenceEnabled":false,"marketBaseRate":5.0,"eventId":"33376437","eventTypeId":"4339","numberOfWinners":2,"bettingType":"ODDS","marketType":"PLACE","marketTime":"2024-06-27T16:39:00.000Z","suspendTime":"2024-06-27T16:39:00.000Z","bspReconciled":false,"complete":true,"inPlay":false,"crossMatching":false,"runnersVoidable":false,"numberOfActiveRunners":6,"betDelay":0,"status":"OPEN","runners":[{"status":"ACTIVE","sortPriority":1,"id":66314580,"name":"1. Shesbeenlit"},{"status":"ACTIVE","sortPriority":2,"id":67487134,"name":"2. Salacres Elbuena"},{"status":"ACTIVE","sortPriority":3,"id":67130716,"name":"3. Donishall Dolly"},{"status":"ACTIVE","sortPriority":4,"id":70086038,"name":"4. Greencroft Gerry"},{"status":"ACTIVE","sortPriority":5,"id":53826530,"name":"5. Meena"},{"status":"ACTIVE","sortPriority":6,"id":64618726,"name":"6. Ballyboss Rose"}],"regulators":["MR_INT"],"venue":"Towcester","countryCode":"GB","discountAllowed":true,"timezone":"Europe/London","openDate":"2024-06-27T13:33:00.000Z","version":5994767127,"name":"To Be Placed","eventName":"Towcester 27th Jun"},"rc":[{"atb":[[1.03,10.99]],"id":67487134},{"atl":[[990,0.17]],"id":67487134},{"spn":495.51,"spf":"NaN","id":67487134},{"atb":[[1.03,10.99]],"id":66314580},{"atl":[[1000,0.17]],"id":66314580},{"spn":500.51,"spf":"NaN","id":66314580},{"atb":[[1.03,10.99]],"id":53826530},{"atl":[[990,0.17]],"id":53826530},{"spn":495.51,"spf":"NaN","id":53826530},{"atb":[[1.01,32.97]],"id":70086038},{"atl":[[1000,0.17]],"id":70086038},{"spn":500.5,"spf":"NaN","id":70086038},{"atb":[[1.01,32.97]],"id":64618726},{"atl":[[1000,0.17]],"id":64618726},{"spn":500.5,"spf":"NaN","id":64618726},{"atb":[[1.02,16.48]],"id":67130716},{"atl":[[1000,0.17]],"id":67130716},{"spn":500.51,"spf":"NaN","id":67130716}],"con":true,"img":true}]}
{"op":"mcm","clk":"11538598979","pt":1719464882862,"mc":[{"id":"1.230180133","marketDefinition":{"bspMarket":true,"turnInPlayEnabled":false,"persistenceEnabled":false,"marketBaseRate":5.0,"eventId":"33376437","eventTypeId":"4339","numberOfWinners":2,"bettingType":"ODDS","marketType":"PLACE","marketTime":"2024-06-27T16:39:00.000Z","suspendTime":"2024-06-27T16:39:00.000Z","bspReconciled":false,"complete":true,"inPlay":false,"crossMatching":false,"runnersVoidable":false,"numberOfActiveRunners":6,"betDelay":0,"status":"OPEN","runners":[{"status":"ACTIVE","sortPriority":1,"id":66314580,"name":"1. Shesbeenlit"},{"status":"ACTIVE","sortPriority":2,"id":67487134,"name":"2. Salacres Elbuena"},{"status":"ACTIVE","sortPriority":3,"id":67130716,"name":"3. Donishall Dolly"},{"status":"ACTIVE","sortPriority":4,"id":70086038,"name":"4. Greencroft Gerry"},{"status":"ACTIVE","sortPriority":5,"id":53826530,"name":"5. Meena"},{"status":"ACTIVE","sortPriority":6,"id":64618726,"name":"6. Ballyboss Rose"}],"regulators":["MR_INT"],"venue":"Towcester","countryCode":"GB","discountAllowed":true,"timezone":"Europe/London","openDate":"2024-06-27T13:33:00.000Z","version":5994767127,"name":"To Be Placed","eventName":"Towcester 27th Jun"},"rc":[{"atb":[[1.03,10.99]],"id":67487134},{"atl":[[990,0.17]],"id":67487134},{"spn":495.51,"spf":"NaN","id":67487134},{"atb":[[1.03,10.99]],"id":66314580},{"atl":[[1000,0.17]],"id":66314580},{"spn":500.51,"spf":"NaN","id":66314580},{"atb":[[1.03,10.99]],"id":53826530},{"atl":[[990,0.17]],"id":53826530},{"spn":495.51,"spf":"NaN","id":53826530},{"atb":[[1.01,32.97]],"id":70086038},{"atl":[[1000,0.17]],"id":70086038},{"spn":500.5,"spf":"NaN","id":70086038},{"atb":[[1.01,32.97]],"id":64618726},{"atl":[[1000,0.17]],"id":64618726},{"spn":500.5,"spf":"NaN","id":64618726},{"atb":[[1.02,16.48]],"id":67130716},{"atl":[[1000,0.17]],"id":67130716},{"spn":500.51,"spf":"NaN","id":67130716}],"con":true,"img":true}]}
{"op":"mcm","clk":"11538906724","pt":1719471498379,"mc":[{"id":"1.230180133","rc":[{"atb":[[1.03,10.99],[1.07,2.48]],"id":67487134},{"atl":[[1000,1]],"id":67487134},{"spn":495.53,"spf":"NaN","id":67487134},{"atb":[[1.03,10.99],[1.07,2.48]],"id":66314580},{"atl":[[1000,1.17]],"id":66314580},{"spn":500.53,"spf":"NaN","id":66314580},{"atb":[[1.03,10.99],[1.07,2.48]],"id":53826530},{"atl":[[1000,1]],"id":53826530},{"spn":495.53,"spf":"NaN","id":53826530},{"atb":[[1.01,32.97],[1.07,2.48]],"id":70086038},{"atl":[[1000,1.17]],"id":70086038},{"spn":500.53,"spf":"NaN","id":70086038},{"atb":[[1.01,32.97],[1.07,2.48]],"id":64618726},{"atl":[[1000,1.17]],"id":64618726},{"spn":500.53,"spf":"NaN","id":64618726},{"atb":[[1.02,16.48],[1.07,2.48]],"id":67130716},{"atl":[[1000,1.17]],"id":67130716},{"spn":500.53,"spf":"NaN","id":67130716}],"con":true,"img":false}]}
{"op":"mcm","clk":"11538906737","pt":1719471498581,"mc":[{"id":"1.230180133","rc":[{"atl":[[1000,0.48]],"id":67487134},{"atl":[[1000,0.65]],"id":66314580},{"atl":[[1000,0.48]],"id":53826530},{"atl":[[1000,0.65]],"id":70086038},{"atl":[[1000,0.65]],"id":64618726},{"atl":[[1000,0.65]],"id":67130716}],"con":true,"img":false}]}
{"op":"mcm","clk":"11538906747","pt":1719471498785,"mc":[{"id":"1.230180133","rc":[{"atl":[[1000,0]],"id":67487134},{"atl":[[1000,0.17]],"id":66314580},{"atl":[[1000,0]],"id":53826530},{"atl":[[1000,0.17]],"id":70086038},{"atl":[[1000,0.17]],"id":64618726},{"atl":[[1000,0.17]],"id":67130716}],"con":true,"img":false}]}
{"op":"mcm","clk":"11538906751","pt":1719471498887,"mc":[{"id":"1.230180133","rc":[{"atl":[[75,0.48]],"id":67487134},{"atl":[[75,0.48]],"id":66314580},{"atl":[[75,0.48]],"id":53826530},{"atl":[[75,0.48]],"id":70086038},{"atl":[[75,0.48]],"id":64618726},{"atl":[[75,0.48]],"id":67130716}],"con":true,"img":false}]}
{"op":"mcm","clk":"11539126211","pt":1719475682883,"mc":[{"id":"1.230180133","marketDefinition":{"bspMarket":true,"turnInPlayEnabled":false,"persistenceEnabled":false,"marketBaseRate":5.0,"eventId":"33376437","eventTypeId":"4339","numberOfWinners":2,"bettingType":"ODDS","marketType":"PLACE","marketTime":"2024-06-27T16:39:00.000Z","suspendTime":"2024-06-27T16:39:00.000Z","bspReconciled":false,"complete":true,"inPlay":false,"crossMatching":false,"runnersVoidable":false,"numberOfActiveRunners":6,"betDelay":0,"status":"OPEN","runners":[{"status":"ACTIVE","sortPriority":1,"id":66314580,"name":"1. Shesbeenlit"},{"status":"ACTIVE","sortPriority":2,"id":67487134,"name":"2. Salacres Elbuena"},{"status":"ACTIVE","sortPriority":3,"id":67130716,"name":"3. Donishall Dolly"},{"status":"ACTIVE","sortPriority":4,"id":70086038,"name":"4. Greencroft Gerry"},{"status":"ACTIVE","sortPriority":5,"id":53826530,"name":"5. Meena"},{"status":"ACTIVE","sortPriority":6,"id":64618726,"name":"6. Ballyboss Rose"}],"regulators":["MR_INT"],"venue":"Towcester","countryCode":"GB","discountAllowed":true,"timezone":"Europe/London","openDate":"2024-06-27T13:33:00.000Z","version":5994767127,"name":"To Be Placed","eventName":"Towcester 27th Jun"},"rc":[{"atb":[[1.03,10.99],[1.07,2.48]],"id":67487134},{"atl":[[75,0.48],[990,0.17]],"id":67487134},{"spn":38.03,"spf":"NaN","id":67487134},{"atb":[[1.03,10.99],[1.07,2.48]],"id":66314580},{"atl":[[75,0.48],[1000,0.17]],"id":66314580},{"spn":38.03,"spf":"NaN","id":66314580},{"atb":[[1.03,10.99],[1.07,2.48]],"id":53826530},{"atl":[[75,0.48],[990,0.17]],"id":53826530},{"spn":38.03,"spf":"NaN","id":53826530},{"atb":[[1.01,32.96],[1.07,2.48]],"id":70086038},{"atl":[[75,0.48],[1000,0.17]],"id":70086038},{"spn":38.03,"spf":"NaN","id":70086038},{"atb":[[1.01,32.96],[1.07,2.48]],"id":64618726},{"atl":[[75,0.48],[1000,0.17]],"id":64618726},{"spn":38.03,"spf":"NaN","id":64618726},{"atb":[[1.02,16.48],[1.07,2.48]],"id":67130716},{"atl":[[75,0.48],[1000,0.17]],"id":67130716},{"spn":38.03,"spf":"NaN","id":67130716}],"con":true,"img":true}]}
{"op":"mcm","clk":"11539354638","pt":1719479517513,"mc":[{"id":"1.230180133","rc":[{"atb":[[1.03,10.98]],"id":67487134},{"spn":38.03,"spf":"NaN","id":67487134},{"spl":[[1.71,6]],"id":66314580},{"atb":[[1.03,10.98]],"id":66314580},{"spn":1.39,"spf":1.0,"id":66314580},{"atb":[[1.03,10.98]],"id":53826530},{"spn":38.03,"spf":"NaN","id":53826530},{"atb":[[1.01,32.95]],"id":70086038},{"spn":38.03,"spf":"NaN","id":70086038},{"atb":[[1.01,32.95]],"id":64618726},{"spn":38.03,"spf":"NaN","id":64618726},{"atb":[[1.02,16.47]],"id":67130716},{"spn":38.03,"spf":"NaN","id":67130716}],"con":true,"img":false}]}
{"op":"mcm","clk":"11540687360","pt":1719497282744,"mc":[{"id":"1.230180133","marketDefinition":{"bspMarket":true,"turnInPlayEnabled":false,"persistenceEnabled":false,"marketBaseRate":5.0,"eventId":"33376437","eventTypeId":"4339","numberOfWinners":2,"bettingType":"ODDS","marketType":"PLACE","marketTime":"2024-06-27T16:39:00.000Z","suspendTime":"2024-06-27T16:39:00.000Z","bspReconciled":false,"complete":true,"inPlay":false,"crossMatching":false,"runnersVoidable":false,"numberOfActiveRunners":6,"betDelay":0,"status":"OPEN","runners":[{"status":"ACTIVE","sortPriority":1,"id":66314580,"name":"1. Shesbeenlit"},{"status":"ACTIVE","sortPriority":2,"id":67487134,"name":"2. Salacres Elbuena"},{"status":"ACTIVE","sortPriority":3,"id":67130716,"name":"3. Donishall Dolly"},{"status":"ACTIVE","sortPriority":4,"id":70086038,"name":"4. Greencroft Gerry"},{"status":"ACTIVE","sortPriority":5,"id":53826530,"name":"5. Meena"},{"status":"ACTIVE","sortPriority":6,"id":64618726,"name":"6. Ballyboss Rose"}],"regulators":["MR_INT"],"venue":"Towcester","countryCode":"GB","discountAllowed":true,"timezone":"Europe/London","openDate":"2024-06-27T13:33:00.000Z","version":5994767127,"name":"To Be Placed","eventName":"Towcester 27th Jun"},"rc":[{"atb":[[1.03,10.99],[1.07,2.48]],"id":67487134},{"atl":[[75,0.48],[990,0.17]],"id":67487134},{"spn":38.03,"spf":"NaN","id":67487134},{"spl":[[1.71,6]],"id":66314580},{"atb":[[1.03,10.99],[1.07,2.48]],"id":66314580},{"atl":[[75,0.48],[1000,0.17]],"id":66314580},{"spn":1.39,"spf":1.0,"id":66314580},{"atb":[[1.03,10.99],[1.07,2.48]],"id":53826530},{"atl":[[75,0.48],[990,0.17]],"id":53826530},{"spn":38.03,"spf":"NaN","id":53826530},{"atb":[[1.01,32.98],[1.07,2.48]],"id":70086038},{"atl":[[75,0.48],[1000,0.17]],"id":70086038},{"spn":38.03,"spf":"NaN","id":70086038},{"atb":[[1.01,32.98],[1.07,2.48]],"id":64618726},{"atl":[[75,0.48],[1000,0.17]],"id":64618726},{"spn":38.03,"spf":"NaN","id":64618726},{"atb":[[1.02,16.49],[1.07,2.48]],"id":67130716},{"atl":[[75,0.48],[1000,0.17]],"id":67130716},{"spn":38.03,"spf":"NaN","id":67130716}],"con":true,"img":true}]}
{"op":"mcm","clk":"11540934060","pt":1719500152104,"mc":[{"id":"1.230180133","rc":[{"atb":[[1.03,10.99]],"id":67487134},{"atl":[[990,0.17],[960,0.9]],"id":67487134},{"atb":[[1.03,10.99]],"id":66314580},{"atl":[[980,2.04],[1000,0.17]],"id":66314580},{"atb":[[1.03,10.99]],"id":53826530},{"atl":[[990,0.17],[960,1.15]],"id":53826530},{"atb":[[1.01,32.98]],"id":70086038},{"atl":[[970,1.99],[1000,0.17]],"id":70086038},{"atb":[[1.01,32.98]],"id":64618726},{"atl":[[960,1.63],[1000,0.17]],"id":64618726},{"atb":[[1.02,16.49]],"id":67130716},{"atl":[[970,0.86],[1000,0.17]],"id":67130716}],"con":true,"img":false}]}
{"op":"mcm","clk":"11541142967","pt":1719502682763,"mc":[{"id":"1.230180133","marketDefinition":{"bspMarket":true,"turnInPlayEnabled":false,"persistenceEnabled":false,"marketBaseRate":5.0,"eventId":"33376437","eventTypeId":"4339","numberOfWinners":2,"bettingType":"ODDS","marketType":"PLACE","marketTime":"2024-06-27T16:39:00.000Z","suspendTime":"2024-06-27T16:39:00.000Z","bspReconciled":false,"complete":true,"inPlay":false,"crossMatching":false,"runnersVoidable":false,"numberOfActiveRunners":6,"betDelay":0,"status":"OPEN","runners":[{"status":"ACTIVE","sortPriority":1,"id":66314580,"name":"1. Shesbeenlit"},{"status":"ACTIVE","sortPriority":2,"id":67487134,"name":"2. Salacres Elbuena"},{"status":"ACTIVE","sortPriority":3,"id":67130716,"name":"3. Donishall Dolly"},{"status":"ACTIVE","sortPriority":4,"id":70086038,"name":"4. Greencroft Gerry"},{"status":"ACTIVE","sortPriority":5,"id":53826530,"name":"5. Meena"},{"status":"ACTIVE","sortPriority":6,"id":64618726,"name":"6. Ballyboss Rose"}],"regulators":["MR_INT"],"venue":"Towcester","countryCode":"GB","discountAllowed":true,"timezone":"Europe/London","openDate":"2024-06-27T13:33:00.000Z","version":5994767127,"name":"To Be Placed","eventName":"Towcester 27th Jun"},"rc":[{"atb":[[1.03,10.99],[1.07,2.48]],"id":67487134},{"atl":[[75,0.48],[960,0.9],[990,0.17]],"id":67487134},{"spn":38.03,"spf":"NaN","id":67487134},{"spl":[[1.71,6]],"id":66314580},{"atb":[[1.03,10.99],[1.07,2.48]],"id":66314580},{"atl":[[75,0.48],[980,2.04],[1000,0.17]],"id":66314580},{"spn":1.39,"spf":1.0,"id":66314580},{"atb":[[1.03,10.99],[1.07,2.48]],"id":53826530},{"atl":[[75,0.48],[960,1.16],[990,0.17]],"id":53826530},{"spn":38.03,"spf":"NaN","id":53826530},{"atb":[[1.01,32.98],[1.07,2.48]],"id":70086038},{"atl":[[75,0.48],[970,1.99],[1000,0.17]],"id":70086038},{"spn":38.03,"spf":"NaN","id":70086038},{"atb":[[1.01,32.98],[1.07,2.48]],"id":64618726},{"atl":[[75,0.48],[960,1.63],[1000,0.17]],"id":64618726},{"spn":38.03,"spf":"NaN","id":64618726},{"atb":[[1.02,16.49],[1.07,2.48]],"id":67130716},{"atl":[[75,0.48],[970,0.86],[1000,0.17]],"id":67130716},{"spn":38.03,"spf":"NaN","id":67130716}],"con":true,"img":true}]}
{"op":"mcm","clk":"11541330093","pt":1719504602183,"mc":[{"id":"1.230180133","rc":[{"atb":[[1.03,10.99],[1.04,1]],"id":67487134},{"atl":[[960,0.9]],"id":67487134},{"atb":[[1.03,10.99],[1.04,1]],"id":66314580},{"atl":[[980,2.03]],"id":66314580},{"atb":[[1.03,10.99],[1.04,1]],"id":53826530},{"atl":[[960,1.15]],"id":53826530},{"atb":[[1.01,32.97],[1.04,1]],"id":70086038},{"atl":[[970,1.99]],"id":70086038},{"atb":[[1.01,32.97],[1.04,1]],"id":64618726},{"atl":[[960,1.63]],"id":64618726},{"atb":[[1.02,16.48],[1.04,1]],"id":67130716},{"atl":[[970,0.86]],"id":67130716}],"con":true,"img":false}]}
{"op":"mcm","clk":"11541330115","pt":1719504602354,"mc":[{"id":"1.230180133","rc":[{"atb":[[1.04,0.25]],"id":67487134},{"atb":[[1.04,0.25]],"id":66314580},{"atb":[[1.04,0.25]],"id":53826530},{"atb":[[1.04,0.25]],"id":70086038},{"atb":[[1.04,0.25]],"id":64618726},{"atb":[[1.04,0.25]],"id":67130716}],"con":true,"img":false}]}
{"op":"mcm","clk":"11541330147","pt":1719504602657,"mc":[{"id":"1.230180133","rc":[{"atb":[[1.04,0]],"id":67487134},{"atb":[[1.04,0]],"id":66314580},{"atb":[[1.04,0]],"id":53826530},{"atb":[[1.04,0]],"id":70086038},{"atb":[[1.04,0]],"id":64618726},{"atb":[[1.04,0]],"id":67130716}],"con":true,"img":false}]}
{"op":"mcm","clk":"11541330156","pt":1719504602769,"mc":[{"id":"1.230180133","rc":[{"atb":[[1.2,0.25]],"id":67487134},{"atb":[[1.2,0.25]],"id":66314580},{"atb":[[1.2,0.25]],"id":53826530},{"atb":[[1.2,0.25]],"id":70086038},{"atb":[[1.2,0.25]],"id":64618726},{"atb":[[1.2,0.25]],"id":67130716}],"con":true,"img":false}]}
{"op":"mcm","clk":"11541330980","pt":1719504611363,"mc":[{"id":"1.230180133","rc":[{"atb":[[1.09,43.91]],"id":67487134}],"con":true,"img":false}]}
{"op":"mcm","clk":"11541330988","pt":1719504611470,"mc":[{"id":"1.230180133","rc":[{"atb":[[1.09,43.91]],"id":53826530}],"con":true,"img":false}]}
{"op":"mcm","clk":"11541330998","pt":1719504611577,"mc":[{"id":"1.230180133","rc":[{"atb":[[1.09,43.91]],"id":67130716}],"con":true,"img":false}]}
{"op":"mcm","clk":"11541333509","pt":1719504641940,"mc":[{"id":"1.230180133","marketDefinition":{"bspMarket":true,"turnInPlayEnabled":false,"persistenceEnabled":false,"marketBaseRate":5.0,"eventId":"33376437","eventTypeId":"4339","numberOfWinners":2,"bettingType":"ODDS","marketType":"PLACE","marketTime":"2024-06-27T16:39:00.000Z","suspendTime":"2024-06-27T16:39:00.000Z","bspReconciled":false,"complete":true,"inPlay":false,"crossMatching":true,"runnersVoidable":false,"numberOfActiveRunners":6,"betDelay":0,"status":"OPEN","runners":[{"status":"ACTIVE","sortPriority":1,"id":66314580,"name":"1. Shesbeenlit"},{"status":"ACTIVE","sortPriority":2,"id":67487134,"name":"2. Salacres Elbuena"},{"status":"ACTIVE","sortPriority":3,"id":67130716,"name":"3. Donishall Dolly"},{"status":"ACTIVE","sortPriority":4,"id":70086038,"name":"4. Greencroft Gerry"},{"status":"ACTIVE","sortPriority":5,"id":53826530,"name":"5. Meena"},{"status":"ACTIVE","sortPriority":6,"id":64618726,"name":"6. Ballyboss Rose"}],"regulators":["MR_INT"],"venue":"Towcester","countryCode":"GB","discountAllowed":true,"timezone":"Europe/London","openDate":"2024-06-27T13:33:00.000Z","version":5994767127,"name":"To Be Placed","eventName":"Towcester 27th Jun"},"rc":[],"con":true,"img":false}]}
{"op":"mcm","clk":"11541350854","pt":1719504843397,"mc":[{"id":"1.230180133","rc":[{"spn":38.1,"spf":"NaN","id":67487134},{"spn":1.45,"spf":1.0,"id":66314580},{"spn":38.1,"spf":"NaN","id":53826530},{"spn":38.1,"spf":"NaN","id":70086038},{"spn":38.1,"spf":"NaN","id":64618726},{"atb":[[1.11,38.46]],"id":67130716},{"spn":38.1,"spf":"NaN","id":67130716}],"con":true,"img":false}]}
{"op":"mcm","clk":"11541350867","pt":1719504843512,"mc":[{"id":"1.230180133","rc":[{"atb":[[1.11,38.46]],"id":67487134}],"con":true,"img":false}]}
{"op":"mcm","clk":"11541350905","pt":1719504843867,"mc":[{"id":"1.230180133","rc":[{"atb":[[1.11,38.46]],"id":53826530}],"con":true,"img":false}]}
{"op":"mcm","clk":"11541351377","pt":1719504849110,"mc":[{"id":"1.230180133","rc":[{"atb":[[1.09,0]],"id":67487134},{"atb":[[1.09,0]],"id":53826530}],"con":true,"img":false}]}
{"op":"mcm","clk":"11541351400","pt":1719504849321,"mc":[{"id":"1.230180133","rc":[{"atb":[[1.09,0]],"id":67130716}],"con":true,"img":false}]}
{"op":"mcm","clk":"11541351411","pt":1719504849422,"mc":[{"id":"1.230180133","rc":[{"atb":[[1.13,30.39]],"id":53826530}],"con":true,"img":false}]}
{"op":"mcm","clk":"11541351422","pt":1719504849528,"mc":[{"id":"1.230180133","rc":[{"atb":[[1.13,30.39]],"id":67487134}],"con":true,"img":false}]}
{"op":"mcm","clk":"11541351460","pt":1719504849891,"mc":[{"id":"1.230180133","rc":[{"atb":[[1.13,30.39]],"id":67130716}],"con":true,"img":false}]}
{"op":"mcm","clk":"11541353777","pt":1719504876166,"mc":[{"id":"1.230180133","rc":[{"atb":[[1.11,0]],"id":67487134},{"atb":[[1.11,0]],"id":67130716}],"con":true,"img":false}]}
{"op":"mcm","clk":"11541353799","pt":1719504876430,"mc":[{"id":"1.230180133","rc":[{"atb":[[1.11,0]],"id":53826530}],"con":true,"img":false}]}
{"op":"mcm","clk":"11541353888","pt":1719504877354,"mc":[{"id":"1.230180133","rc":[{"atb":[[1.15,28.2]],"id":67130716}],"con":true,"img":false}]}
{"op":"mcm","clk":"11541353895","pt":1719504877459,"mc":[{"id":"1.230180133","rc":[{"atb":[[1.15,28.2]],"id":67487134}],"con":true,"img":false}]}
{"op":"mcm","clk":"11541353920","pt":1719504877717,"mc":[{"id":"1.230180133","rc":[{"atb":[[1.15,28.2]],"id":53826530}],"con":true,"img":false}]}
{"op":"mcm","clk":"11541354626","pt":1719504885986,"mc":[{"id":"1.230180133","rc":[{"atb":[[1.13,0]],"id":67487134}],"con":true,"img":false}]}
{"op":"mcm","clk":"11541354633","pt":1719504886039,"mc":[{"id":"1.230180133","rc":[{"atb":[[1.13,0]],"id":67130716}],"con":true,"img":false}]}
{"op":"mcm","clk":"11541354644","pt":1719504886147,"mc":[{"id":"1.230180133","rc":[{"atb":[[1.13,0]],"id":53826530}],"con":true,"img":false}]}
{"op":"mcm","clk":"11541354668","pt":1719504886357,"mc":[{"id":"1.230180133","rc":[{"atb":[[1.17,23.24]],"id":67487134},{"atb":[[1.17,23.24]],"id":67130716}],"con":true,"img":false}]}
{"op":"mcm","clk":"11541354687","pt":1719504886564,"mc":[{"id":"1.230180133","rc":[{"atb":[[1.17,23.24]],"id":53826530}],"con":true,"img":false}]}
{"op":"mcm","clk":"11541356957","pt":1719504912091,"mc":[{"id":"1.230180133","rc":[{"atb":[[1.15,0]],"id":67487134},{"atb":[[1.15,0]],"id":67130716}],"con":true,"img":false}]}
{"op":"mcm","clk":"11541356986","pt":1719504912393,"mc":[{"id":"1.230180133","rc":[{"atb":[[1.15,0]],"id":53826530}],"con":true,"img":false}]}
{"op":"mcm","clk":"11541357069","pt":1719504913380,"mc":[{"id":"1.230180133","rc":[{"atb":[[1.19,22.27]],"id":67487134},{"atb":[[1.19,22.27]],"id":67130716}],"con":true,"img":false}]}
{"op":"mcm","clk":"11541357128","pt":1719504914205,"mc":[{"id":"1.230180133","rc":[{"atb":[[1.19,22.27]],"id":53826530}],"con":true,"img":false}]}
{"op":"mcm","clk":"11541357889","pt":1719504923831,"mc":[{"id":"1.230180133","rc":[{"atb":[[1.17,0]],"id":67487134}],"con":true,"img":false}]}
{"op":"mcm","clk":"11541357897","pt":1719504923884,"mc":[{"id":"1.230180133","rc":[{"atb":[[1.17,0]],"id":53826530}],"con":true,"img":false}]}
{"op":"mcm","clk":"11541357914","pt":1719504924096,"mc":[{"id":"1.230180133","rc":[{"atb":[[1.17,0]],"id":67130716}],"con":true,"img":false}]}
{"op":"mcm","clk":"11541357930","pt":1719504924298,"mc":[{"id":"1.230180133","rc":[{"atb":[[1.21,18.81]],"id":67487134},{"atb":[[1.21,18.81]],"id":53826530}],"con":true,"img":false}]}
{"op":"mcm","clk":"11541357945","pt":1719504924509,"mc":[{"id":"1.230180133","rc":[{"atb":[[1.21,18.81]],"id":67130716}],"con":true,"img":false}]}
{"op":"mcm","clk":"11541359787","pt":1719504946540,"mc":[{"id":"1.230180133","rc":[{"atb":[[1.19,0]],"id":67487134},{"atb":[[1.19,0]],"id":67130716}],"con":true,"img":false}]}
{"op":"mcm","clk":"11541359842","pt":1719504947158,"mc":[{"id":"1.230180133","rc":[{"atb":[[1.19,0]],"id":53826530}],"con":true,"img":false}]}
{"op":"mcm","clk":"11541359902","pt":1719504947831,"mc":[{"id":"1.230180133","rc":[{"atb":[[1.23,18.39]],"id":67487134}],"con":true,"img":false}]}
{"op":"mcm","clk":"11541359934","pt":1719504948141,"mc":[{"id":"1.230180133","rc":[{"atb":[[1.23,18.39]],"id":67130716}],"con":true,"img":false}]}
{"op":"mcm","clk":"11541359989","pt":1719504948772,"mc":[{"id":"1.230180133","rc":[{"atb":[[1.23,18.39]],"id":53826530}],"con":true,"img":false}]}
{"op":"mcm","clk":"11541360816","pt":1719504958133,"mc":[{"id":"1.230180133","rc":[{"atb":[[1.21,0]],"id":67487134},{"atb":[[1.21,0]],"id":67130716}],"con":true,"img":false}]}
{"op":"mcm","clk":"11541360858","pt":1719504958653,"mc":[{"id":"1.230180133","rc":[{"atb":[[1.21,0]],"id":53826530}],"con":true,"img":false}]}
{"op":"mcm","clk":"11541360901","pt":1719504959064,"mc":[{"id":"1.230180133","rc":[{"atb":[[1.25,15.8]],"id":67130716}],"con":true,"img":false}]}
{"op":"mcm","clk":"11541360919","pt":1719504959274,"mc":[{"id":"1.230180133","rc":[{"atb":[[1.25,15.8]],"id":67487134}],"con":true,"img":false}]}
{"op":"mcm","clk":"11541360971","pt":1719504959637,"mc":[{"id":"1.230180133","rc":[{"atb":[[1.25,15.8]],"id":53826530}],"con":true,"img":false}]}
{"op":"mcm","clk":"11541363229","pt":1719504982092,"mc":[{"id":"1.230180133","rc":[{"atb":[[1.23,0]],"id":67487134},{"spn":38.12,"spf":"NaN","id":67487134},{"spn":38.12,"spf":"NaN","id":53826530},{"atb":[[1.23,0]],"id":67130716},{"spn":38.12,"spf":"NaN","id":67130716}],"con":true,"img":false}]}
{"op":"mcm","clk":"11541363265","pt":1719504982352,"mc":[{"id":"1.230180133","rc":[{"atb":[[1.23,0]],"id":53826530}],"con":true,"img":false}]}
{"op":"mcm","clk":"11541363328","pt":1719504982979,"mc":[{"id":"1.230180133","rc":[{"atb":[[1.27,15.67]],"id":67130716}],"con":true,"img":false}]}
{"op":"mcm","clk":"11541363338","pt":1719504983080,"mc":[{"id":"1.230180133","rc":[{"atb":[[1.27,15.67]],"id":67487134}],"con":true,"img":false}]}
{"op":"mcm","clk":"11541363357","pt":1719504983288,"mc":[{"id":"1.230180133","rc":[{"atb":[[1.27,15.67]],"id":53826530}],"con":true,"img":false}]}
{"op":"mcm","clk":"11541364526","pt":1719504995253,"mc":[{"id":"1.230180133","rc":[{"atb":[[1.25,0]],"id":67487134}],"con":true,"img":false}]}
{"op":"mcm","clk":"11541364543","pt":1719504995269,"mc":[{"id":"1.230180133","rc":[{"atb":[[1.25,0]],"id":53826530}],"con":true,"img":false}]}
{"op":"mcm","clk":"11541364590","pt":1719504995373,"mc":[{"id":"1.230180133","rc":[{"atb":[[1.29,13.62]],"id":67487134},{"atb":[[1.29,13.62]],"id":53826530}],"con":true,"img":false}]}
{"op":"mcm","clk":"11541364640","pt":1719504995791,"mc":[{"id":"1.230180133","rc":[{"atb":[[1.25,0]],"id":67130716}],"con":true,"img":false}]}
{"op":"mcm","clk":"11541364665","pt":1719504995998,"mc":[{"id":"1.230180133","rc":[{"atb":[[1.29,13.62]],"id":67130716}],"con":true,"img":false}]}
{"op":"mcm","clk":"11541366567","pt":1719505016532,"mc":[{"id":"1.230180133","rc":[{"atb":[[1.27,0]],"id":67487134},{"atb":[[1.27,0]],"id":67130716}],"con":true,"img":false}]}
{"op":"mcm","clk":"11541366592","pt":1719505016829,"mc":[{"id":"1.230180133","rc":[{"atb":[[1.27,0]],"id":53826530}],"con":true,"img":false}]}
{"op":"mcm","clk":"11541366657","pt":1719505017437,"mc":[{"id":"1.230180133","rc":[{"atb":[[1.31,13.65]],"id":67130716}],"con":true,"img":false}]}
{"op":"mcm","clk":"11541366672","pt":1719505017629,"mc":[{"id":"1.230180133","rc":[{"atb":[[1.31,13.65]],"id":67487134}],"con":true,"img":false}]}
{"op":"mcm","clk":"11541366718","pt":1719505018108,"mc":[{"id":"1.230180133","rc":[{"atb":[[1.31,13.65]],"id":53826530}],"con":true,"img":false}]}
{"op":"mcm","clk":"11541368065","pt":1719505031415,"mc":[{"id":"1.230180133","rc":[{"atb":[[1.29,0]],"id":67487134},{"atb":[[1.29,0]],"id":53826530}],"con":true,"img":false}]}
{"op":"mcm","clk":"11541368108","pt":1719505031853,"mc":[{"id":"1.230180133","rc":[{"atb":[[1.33,11.97]],"id":67487134},{"atb":[[1.33,11.97]],"id":53826530}],"con":true,"img":false}]}
{"op":"mcm","clk":"11541368129","pt":1719505032053,"mc":[{"id":"1.230180133","rc":[{"atb":[[1.29,0]],"id":67130716}],"con":true,"img":false}]}
{"op":"mcm","clk":"11541368154","pt":1719505032213,"mc":[{"id":"1.230180133","rc":[{"atb":[[1.33,11.97]],"id":67130716}],"con":true,"img":false}]}
{"op":"mcm","clk":"11541370180","pt":1719505052187,"mc":[{"id":"1.230180133","rc":[{"atb":[[1.31,0]],"id":67487134},{"spn":38.16,"spf":"NaN","id":67487134},{"spn":38.16,"spf":"NaN","id":53826530},{"spn":38.16,"spf":"NaN","id":67130716}],"con":true,"img":false}]}
{"op":"mcm","clk":"11541370187","pt":1719505052293,"mc":[{"id":"1.230180133","rc":[{"atb":[[1.31,0]],"id":67130716}],"con":true,"img":false}]}
{"op":"mcm","clk":"11541370201","pt":1719505052505,"mc":[{"id":"1.230180133","rc":[{"atb":[[1.31,0]],"id":53826530}],"con":true,"img":false}]}
{"op":"mcm","clk":"11541370235","pt":1719505052935,"mc":[{"id":"1.230180133","rc":[{"atb":[[1.35,12.09]],"id":67487134}],"con":true,"img":false}]}
{"op":"mcm","clk":"11541370252","pt":1719505053090,"mc":[{"id":"1.230180133","rc":[{"atb":[[1.35,12.09]],"id":53826530}],"con":true,"img":false}]}
{"op":"mcm","clk":"11541370260","pt":1719505053194,"mc":[{"id":"1.230180133","rc":[{"atb":[[1.35,12.09]],"id":67130716}],"con":true,"img":false}]}
{"op":"mcm","clk":"11541371479","pt":1719505065681,"mc":[{"id":"1.230180133","rc":[{"atb":[[1.33,0]],"id":67487134}],"con":true,"img":false}]}
{"op":"mcm","clk":"11541371501","pt":1719505065890,"mc":[{"id":"1.230180133","rc":[{"atb":[[1.33,0]],"id":53826530},{"atb":[[1.33,0]],"id":67130716}],"con":true,"img":false}]}
{"op":"mcm","clk":"11541371549","pt":1719505066307,"mc":[{"id":"1.230180133","rc":[{"atb":[[1.37,10.67]],"id":67487134},{"atb":[[1.37,10.67]],"id":67130716}],"con":true,"img":false}]}
{"op":"mcm","clk":"11541371574","pt":1719505066507,"mc":[{"id":"1.230180133","rc":[{"atb":[[1.37,10.67]],"id":53826530}],"con":true,"img":false}]}
{"op":"mcm","clk":"11541373567","pt":1719505085598,"mc":[{"id":"1.230180133","rc":[{"atb":[[1.35,0]],"id":67487134}],"con":true,"img":false}]}
{"op":"mcm","clk":"11541373593","pt":1719505085911,"mc":[{"id":"1.230180133","rc":[{"atb":[[1.35,0]],"id":53826530}],"con":true,"img":false}]}
{"op":"mcm","clk":"11541373614","pt":1719505086117,"mc":[{"id":"1.230180133","rc":[{"atb":[[1.35,0]],"id":67130716}],"con":true,"img":false}]}
{"op":"mcm","clk":"11541373626","pt":1719505086223,"mc":[{"id":"1.230180133","rc":[{"atb":[[1.39,10.84]],"id":67487134}],"con":true,"img":false}]}
{"op":"mcm","clk":"11541373692","pt":1719505086897,"mc":[{"id":"1.230180133","rc":[{"atb":[[1.39,10.84]],"id":53826530}],"con":true,"img":false}]}
{"op":"mcm","clk":"11541373713","pt":1719505087205,"mc":[{"id":"1.230180133","rc":[{"atb":[[1.39,10.84]],"id":67130716}],"con":true,"img":false}]}
{"op":"mcm","clk":"11541375246","pt":1719505103013,"mc":[{"id":"1.230180133","rc":[{"atb":[[1.37,0]],"id":67487134}],"con":true,"img":false}]}
{"op":"mcm","clk":"11541375267","pt":1719505103232,"mc":[{"id":"1.230180133","rc":[{"atb":[[1.37,0]],"id":67130716}],"con":true,"img":false}]}
{"op":"mcm","clk":"11541375299","pt":1719505103542,"mc":[{"id":"1.230180133","rc":[{"atb":[[1.37,0]],"id":53826530}],"con":true,"img":false}]}
{"op":"mcm","clk":"11541375331","pt":1719505103855,"mc":[{"id":"1.230180133","rc":[{"atb":[[1.41,9.64]],"id":67487134}],"con":true,"img":false}]}
{"op":"mcm","clk":"11541375347","pt":1719505104049,"mc":[{"id":"1.230180133","rc":[{"atb":[[1.41,9.64]],"id":53826530},{"atb":[[1.41,9.64]],"id":67130716}],"con":true,"img":false}]}
{"op":"mcm","clk":"11541377166","pt":1719505124250,"mc":[{"id":"1.230180133","rc":[{"atb":[[1.39,0]],"id":67487134},{"spn":38.2,"spf":"NaN","id":67487134},{"spn":38.2,"spf":"NaN","id":53826530},{"spn":38.2,"spf":"NaN","id":67130716}],"con":true,"img":false}]}
{"op":"mcm","clk":"11541377196","pt":1719505124661,"mc":[{"id":"1.230180133","rc":[{"atb":[[1.39,0]],"id":67130716}],"con":true,"img":false}]}
{"op":"mcm","clk":"11541377204","pt":1719505124755,"mc":[{"id":"1.230180133","rc":[{"atb":[[1.39,0]],"id":53826530}],"con":true,"img":false}]}
{"op":"mcm","clk":"11541377232","pt":1719505125068,"mc":[{"id":"1.230180133","rc":[{"atb":[[1.43,9.84]],"id":67487134}],"con":true,"img":false}]}
{"op":"mcm","clk":"11541377275","pt":1719505125530,"mc":[{"id":"1.230180133","rc":[{"atb":[[1.43,9.84]],"id":67130716}],"con":true,"img":false}]}
{"op":"mcm","clk":"11541377293","pt":1719505125844,"mc":[{"id":"1.230180133","rc":[{"atb":[[1.43,9.84]],"id":53826530}],"con":true,"img":false}]}
{"op":"mcm","clk":"11541378585","pt":1719505140252,"mc":[{"id":"1.230180133","rc":[{"atb":[[1.41,0]],"id":53826530}],"con":true,"img":false}]}
{"op":"mcm","clk":"11541378610","pt":1719505140561,"mc":[{"id":"1.230180133","rc":[{"atb":[[1.41,0]],"id":67487134}],"con":true,"img":false}]}
{"op":"mcm","clk":"11541378627","pt":1719505140769,"mc":[{"id":"1.230180133","rc":[{"atb":[[1.41,0]],"id":67130716}],"con":true,"img":false}]}
{"op":"mcm","clk":"11541378643","pt":1719505140976,"mc":[{"id":"1.230180133","rc":[{"atb":[[1.45,8.78]],"id":53826530}],"con":true,"img":false}]}
{"op":"mcm","clk":"11541378663","pt":1719505141184,"mc":[{"id":"1.230180133","rc":[{"atb":[[1.45,8.78]],"id":67487134}],"con":true,"img":false}]}
{"op":"mcm","clk":"11541378707","pt":1719505141544,"mc":[{"id":"1.230180133","rc":[{"atb":[[1.45,8.78]],"id":67130716}],"con":true,"img":false}]}
{"op":"mcm","clk":"11541378741","pt":1719505141856,"mc":[{"id":"1.230180133","rc":[{"atb":[[1.46,2.11]],"id":67487134},{"atb":[[1.46,2.11]],"id":53826530}],"con":true,"img":false}]}
{"op":"mcm","clk":"11541378772","pt":1719505142180,"mc":[{"id":"1.230180133","rc":[{"atb":[[1.46,2.11]],"id":67130716}],"con":true,"img":false}]}
{"op":"mcm","clk":"11541380371","pt":1719505158172,"mc":[{"id":"1.230180133","rc":[{"atb":[[1.45,0]],"id":67487134},{"atb":[[1.45,0]],"id":67130716}],"con":true,"img":false}]}
{"op":"mcm","clk":"11541380399","pt":1719505158378,"mc":[{"id":"1.230180133","rc":[{"atb":[[1.48,8.23]],"id":67130716}],"con":true,"img":false}]}
{"op":"mcm","clk":"11541380411","pt":1719505158480,"mc":[{"id":"1.230180133","rc":[{"atb":[[1.45,0]],"id":53826530}],"con":true,"img":false}]}
{"op":"mcm","clk":"11541380423","pt":1719505158585,"mc":[{"id":"1.230180133","rc":[{"atb":[[1.48,8.23]],"id":67487134}],"con":true,"img":false}]}
{"op":"mcm","clk":"11541380431","pt":1719505158687,"mc":[{"id":"1.230180133","rc":[{"atb":[[1.48,8.23]],"id":53826530}],"con":true,"img":false}]}
{"op":"mcm","clk":"11541380443","pt":1719505158794,"mc":[{"id":"1.230180133","rc":[{"atb":[[1.43,0]],"id":53826530}],"con":true,"img":false}]}
{"op":"mcm","clk":"11541380462","pt":1719505159001,"mc":[{"id":"1.230180133","rc":[{"atb":[[1.43,0]],"id":67130716}],"con":true,"img":false}]}
{"op":"mcm","clk":"11541380484","pt":1719505159208,"mc":[{"id":"1.230180133","rc":[{"atb":[[1.43,0]],"id":67487134}],"con":true,"img":false}]}
{"op":"mcm","clk":"11541380547","pt":1719505159885,"mc":[{"id":"1.230180133","rc":[{"atb":[[1.48,17.05]],"id":53826530}],"con":true,"img":false}]}
{"op":"mcm","clk":"11541380559","pt":1719505159987,"mc":[{"id":"1.230180133","rc":[{"atb":[[1.48,17.05]],"id":67130716}],"con":true,"img":false}]}
{"op":"mcm","clk":"11541380595","pt":1719505160399,"mc":[{"id":"1.230180133","rc":[{"atb":[[1.48,17.05]],"id":67487134}],"con":true,"img":false}]}
{"op":"mcm","clk":"11541382179","pt":1719505175417,"mc":[{"id":"1.230180133","rc":[{"atb":[[1.48,8.81]],"id":53826530}],"con":true,"img":false}]}
{"op":"mcm","clk":"11541382194","pt":1719505175519,"mc":[{"id":"1.230180133","rc":[{"atb":[[1.48,8.81]],"id":67487134}],"con":true,"img":false}]}
{"op":"mcm","clk":"11541382219","pt":1719505175724,"mc":[{"id":"1.230180133","rc":[{"atb":[[1.48,8.81]],"id":67130716}],"con":true,"img":false}]}
{"op":"mcm","clk":"11541382232","pt":1719505175827,"mc":[{"id":"1.230180133","rc":[{"atb":[[1.5,7.9]],"id":53826530}],"con":true,"img":false}]}
{"op":"mcm","clk":"11541382242","pt":1719505175933,"mc":[{"id":"1.230180133","rc":[{"atb":[[1.5,7.9]],"id":67487134}],"con":true,"img":false}]}
{"op":"mcm","clk":"11541382267","pt":1719505176140,"mc":[{"id":"1.230180133","rc":[{"atb":[[1.5,7.9]],"id":67130716}],"con":true,"img":false}]}
{"op":"mcm","clk":"11541384127","pt":1719505192737,"mc":[{"id":"1.230180133","rc":[{"spn":38.25,"spf":"NaN","id":67487134},{"atb":[[1.48,0]],"id":53826530},{"spn":38.25,"spf":"NaN","id":53826530},{"atb":[[1.48,0]],"id":67130716},{"spn":38.25,"spf":"NaN","id":67130716}],"con":true,"img":false}]}
{"op":"mcm","clk":"11541384163","pt":1719505193047,"mc":[{"id":"1.230180133","rc":[{"atb":[[1.48,0]],"id":67487134}],"con":true,"img":false}]}
{"op":"mcm","clk":"11541384228","pt":1719505193719,"mc":[{"id":"1.230180133","rc":[{"atb":[[1.52,8.14]],"id":53826530},{"atb":[[1.52,8.14]],"id":67130716}],"con":true,"img":false}]}
{"op":"mcm","clk":"11541384283","pt":1719505194248,"mc":[{"id":"1.230180133","rc":[{"atb":[[1.52,8.14]],"id":67487134}],"con":true,"img":false}]}
{"op":"mcm","clk":"11541386295","pt":1719505212548,"mc":[{"id":"1.230180133","rc":[{"atb":[[1.5,0]],"id":67487134},{"atb":[[1.5,0]],"id":53826530}],"con":true,"img":false}]}
{"op":"mcm","clk":"11541386320","pt":1719505212751,"mc":[{"id":"1.230180133","rc":[{"atb":[[1.5,0]],"id":67130716}],"con":true,"img":false}]}
{"op":"mcm","clk":"11541386341","pt":1719505212959,"mc":[{"id":"1.230180133","rc":[{"atb":[[1.54,7.31]],"id":67487134},{"atb":[[1.54,7.31]],"id":53826530}],"con":true,"img":false}]}
{"op":"mcm","clk":"11541386362","pt":1719505213168,"mc":[{"id":"1.230180133","rc":[{"atb":[[1.54,7.31]],"id":67130716}],"con":true,"img":false}]}
{"op":"mcm","clk":"11541387584","pt":1719505225371,"mc":[{"id":"1.230180133","rc":[{"atb":[[1.52,0]],"id":67487134}],"con":true,"img":false}]}
{"op":"mcm","clk":"11541387617","pt":1719505225685,"mc":[{"id":"1.230180133","rc":[{"atb":[[1.52,0]],"id":53826530}],"con":true,"img":false}]}
{"op":"mcm","clk":"11541387642","pt":1719505225888,"mc":[{"id":"1.230180133","rc":[{"atb":[[1.52,0]],"id":67130716}],"con":true,"img":false}]}
{"op":"mcm","clk":"11541387725","pt":1719505226665,"mc":[{"id":"1.230180133","rc":[{"atb":[[1.56,7.55]],"id":67130716}],"con":true,"img":false}]}
{"op":"mcm","clk":"11541387734","pt":1719505226770,"mc":[{"id":"1.230180133","rc":[{"atb":[[1.56,7.55]],"id":53826530}],"con":true,"img":false}]}
{"op":"mcm","clk":"11541387753","pt":1719505226979,"mc":[{"id":"1.230180133","rc":[{"atb":[[1.56,7.55]],"id":67487134}],"con":true,"img":false}]}
{"op":"mcm","clk":"11541388081","pt":1719505230287,"mc":[{"id":"1.230180133","rc":[{"atb":[[1.54,0]],"id":67487134}],"con":true,"img":false}]}
{"op":"mcm","clk":"11541388113","pt":1719505230498,"mc":[{"id":"1.230180133","rc":[{"atb":[[1.54,0]],"id":67130716}],"con":true,"img":false}]}
{"op":"mcm","clk":"11541388136","pt":1719505230716,"mc":[{"id":"1.230180133","rc":[{"atb":[[1.58,6.81]],"id":67487134}],"con":true,"img":false}]}
{"op":"mcm","clk":"11541388156","pt":1719505230905,"mc":[{"id":"1.230180133","rc":[{"atb":[[1.54,0]],"id":53826530}],"con":true,"img":false}]}
{"op":"mcm","clk":"11541388179","pt":1719505231116,"mc":[{"id":"1.230180133","rc":[{"atb":[[1.58,6.81]],"id":67130716}],"con":true,"img":false}]}
{"op":"mcm","clk":"11541388196","pt":1719505231273,"mc":[{"id":"1.230180133","rc":[{"atb":[[1.58,6.81]],"id":53826530}],"con":true,"img":false}]}
{"op":"mcm","clk":"11541391439","pt":1719505261039,"mc":[{"id":"1.230180133","rc":[{"atb":[[1.56,0]],"id":67487134},{"spn":38.29,"spf":"NaN","id":67487134},{"spn":38.29,"spf":"NaN","id":53826530},{"atb":[[1.56,0]],"id":67130716},{"spn":38.29,"spf":"NaN","id":67130716}],"con":true,"img":false}]}
{"op":"mcm","clk":"11541391479","pt":1719505261347,"mc":[{"id":"1.230180133","rc":[{"atb":[[1.09,47.02]],"id":66314580}],"con":true,"img":false}]}
{"op":"mcm","clk":"11541391544","pt":1719505261916,"mc":[{"id":"1.230180133","rc":[{"atb":[[1.56,0]],"id":53826530}],"con":true,"img":false}]}
{"op":"mcm","clk":"11541391553","pt":1719505262027,"mc":[{"id":"1.230180133","rc":[{"atb":[[1.6,7.04]],"id":67130716}],"con":true,"img":false}]}
{"op":"mcm","clk":"11541391575","pt":1719505262238,"mc":[{"id":"1.230180133","rc":[{"atb":[[1.6,7.04]],"id":67487134}],"con":true,"img":false}]}
{"op":"mcm","clk":"11541391655","pt":1719505263015,"mc":[{"id":"1.230180133","rc":[{"atb":[[1.6,7.04]],"id":53826530}],"con":true,"img":false}]}
{"op":"mcm","clk":"11541391951","pt":1719505266035,"mc":[{"id":"1.230180133","rc":[{"atb":[[1.58,0]],"id":67487134},{"atb":[[1.1,55.32]],"id":66314580}],"con":true,"img":false}]}
{"op":"mcm","clk":"11541391974","pt":1719505266247,"mc":[{"id":"1.230180133","rc":[{"atb":[[1.58,0]],"id":53826530}],"con":true,"img":false}]}
{"op":"mcm","clk":"11541392003","pt":1719505266507,"mc":[{"id":"1.230180133","rc":[{"atb":[[1.58,0]],"id":67130716}],"con":true,"img":false}]}
{"op":"mcm","clk":"11541392027","pt":1719505266711,"mc":[{"id":"1.230180133","rc":[{"atb":[[1.62,6.37]],"id":67487134},{"atb":[[1.11,35.92]],"id":66314580}],"con":true,"img":false}]}
{"op":"mcm","clk":"11541392086","pt":1719505267256,"mc":[{"id":"1.230180133","rc":[{"atb":[[1.62,6.37]],"id":53826530}],"con":true,"img":false}]}
{"op":"mcm","clk":"11541392110","pt":1719505267463,"mc":[{"id":"1.230180133","rc":[{"atb":[[1.62,6.37]],"id":67130716}],"con":true,"img":false}]}
{"op":"mcm","clk":"11541394660","pt":1719505295944,"mc":[{"id":"1.230180133","rc":[{"atb":[[1.12,49.36],[1.09,0]],"id":66314580}],"con":true,"img":false}]}
{"op":"mcm","clk":"11541394688","pt":1719505296251,"mc":[{"id":"1.230180133","rc":[{"atb":[[1.6,0]],"id":53826530}],"con":true,"img":false}]}
{"op":"mcm","clk":"11541394709","pt":1719505296558,"mc":[{"id":"1.230180133","rc":[{"atb":[[1.13,32.54]],"id":66314580}],"con":true,"img":false}]}
{"op":"mcm","clk":"11541394734","pt":1719505296866,"mc":[{"id":"1.230180133","rc":[{"atb":[[1.6,0]],"id":67487134},{"atb":[[1.64,6.6]],"id":53826530}],"con":true,"img":false}]}
{"op":"mcm","clk":"11541394777","pt":1719505297385,"mc":[{"id":"1.230180133","rc":[{"atb":[[1.64,6.6]],"id":67487134}],"con":true,"img":false}]}
{"op":"mcm","clk":"11541395324","pt":1719505304346,"mc":[{"id":"1.230180133","rc":[{"atb":[[1.1,0]],"id":66314580}],"con":true,"img":false}]}
{"op":"mcm","clk":"11541395332","pt":1719505304458,"mc":[{"id":"1.230180133","rc":[{"atb":[[1.11,0]],"id":66314580}],"con":true,"img":false}]}
{"op":"mcm","clk":"11541395360","pt":1719505304769,"mc":[{"id":"1.230180133","rc":[{"atb":[[1.62,0]],"id":53826530}],"con":true,"img":false}]}
{"op":"mcm","clk":"11541395375","pt":1719505304976,"mc":[{"id":"1.230180133","rc":[{"atb":[[1.14,39.51]],"id":66314580}],"con":true,"img":false}]}
{"op":"mcm","clk":"11541395384","pt":1719505305074,"mc":[{"id":"1.230180133","rc":[{"atb":[[1.62,0]],"id":67487134}],"con":true,"img":false}]}
{"op":"mcm","clk":"11541395400","pt":1719505305279,"mc":[{"id":"1.230180133","rc":[{"atb":[[1.66,5.99]],"id":53826530}],"con":true,"img":false}]}
{"op":"mcm","clk":"11541395408","pt":1719505305387,"mc":[{"id":"1.230180133","rc":[{"atb":[[1.66,5.99]],"id":67487134}],"con":true,"img":false}]}
{"op":"mcm","clk":"11541395414","pt":1719505305485,"mc":[{"id":"1.230180133","rc":[{"atb":[[1.15,26.34]],"id":66314580}],"con":true,"img":false}]}
{"op":"mcm","clk":"11541397784","pt":1719505328736,"mc":[{"id":"1.230180133","rc":[{"spn":38.33,"spf":"NaN","id":67487134},{"atb":[[1.12,0],[1.13,0]],"id":66314580},{"spn":38.33,"spf":"NaN","id":53826530},{"spn":38.31,"spf":"NaN","id":67130716}],"con":true,"img":false}]}
{"op":"mcm","clk":"11541397822","pt":1719505329126,"mc":[{"id":"1.230180133","rc":[{"atb":[[1.64,0]],"id":53826530}],"con":true,"img":false}]}
{"op":"mcm","clk":"11541397855","pt":1719505329400,"mc":[{"id":"1.230180133","rc":[{"atb":[[1.64,0]],"id":67487134}],"con":true,"img":false}]}
{"op":"mcm","clk":"11541397875","pt":1719505329698,"mc":[{"id":"1.230180133","rc":[{"atb":[[1.16,37.02]],"id":66314580}],"con":true,"img":false}]}
{"op":"mcm","clk":"11541397881","pt":1719505329799,"mc":[{"id":"1.230180133","rc":[{"atb":[[1.17,24.88]],"id":66314580}],"con":true,"img":false}]}
{"op":"mcm","clk":"11541397900","pt":1719505330012,"mc":[{"id":"1.230180133","rc":[{"atb":[[1.68,6.22]],"id":53826530}],"con":true,"img":false}]}
{"op":"mcm","clk":"11541397946","pt":1719505330535,"mc":[{"id":"1.230180133","rc":[{"atb":[[1.68,6.22]],"id":67487134}],"con":true,"img":false}]}
{"op":"mcm","clk":"11541399049","pt":1719505342051,"mc":[{"id":"1.230180133","rc":[{"atb":[[1.66,0]],"id":67487134}],"con":true,"img":false}]}
{"op":"mcm","clk":"11541399057","pt":1719505342153,"mc":[{"id":"1.230180133","rc":[{"atb":[[1.15,0]],"id":66314580}],"con":true,"img":false}]}
{"op":"mcm","clk":"11541399083","pt":1719505342418,"mc":[{"id":"1.230180133","rc":[{"atb":[[1.19,20.8]],"id":66314580}],"con":true,"img":false}]}
{"op":"mcm","clk":"11541399102","pt":1719505342622,"mc":[{"id":"1.230180133","rc":[{"atb":[[1.7,5.64]],"id":67487134}],"con":true,"img":false}]}
{"op":"mcm","clk":"11541399113","pt":1719505342726,"mc":[{"id":"1.230180133","rc":[{"atb":[[1.66,0]],"id":53826530}],"con":true,"img":false}]}
{"op":"mcm","clk":"11541399155","pt":1719505343137,"mc":[{"id":"1.230180133","rc":[{"atb":[[1.7,5.64]],"id":53826530}],"con":true,"img":false}]}
{"op":"mcm","clk":"11541399179","pt":1719505343350,"mc":[{"id":"1.230180133","rc":[{"atb":[[1.14,0]],"id":66314580}],"con":true,"img":false}]}
{"op":"mcm","clk":"11541399197","pt":1719505343560,"mc":[{"id":"1.230180133","rc":[{"atb":[[1.18,30.73]],"id":66314580}],"con":true,"img":false}]}
{"op":"mcm","clk":"11541401366","pt":1719505364472,"mc":[{"id":"1.230180133","rc":[{"atb":[[1.68,0]],"id":67487134},{"atb":[[1.6,0]],"id":67130716}],"con":true,"img":false}]}
{"op":"mcm","clk":"11541401405","pt":1719505364883,"mc":[{"id":"1.230180133","rc":[{"atb":[[1.16,0],[1.17,0]],"id":66314580}],"con":true,"img":false}]}
{"op":"mcm","clk":"11541401446","pt":1719505365255,"mc":[{"id":"1.230180133","rc":[{"atb":[[1.68,0]],"id":53826530}],"con":true,"img":false}]}
{"op":"mcm","clk":"11541401477","pt":1719505365560,"mc":[{"id":"1.230180133","rc":[{"atb":[[1.72,5.87]],"id":67487134}],"con":true,"img":false}]}
{"op":"mcm","clk":"11541401511","pt":1719505365870,"mc":[{"id":"1.230180133","rc":[{"atb":[[1.64,6.6]],"id":67130716}],"con":true,"img":false}]}
{"op":"mcm","clk":"11541401523","pt":1719505365973,"mc":[{"id":"1.230180133","rc":[{"atb":[[1.2,29.87]],"id":66314580}],"con":true,"img":false}]}
{"op":"mcm","clk":"11541401542","pt":1719505366179,"mc":[{"id":"1.230180133","rc":[{"atb":[[1.21,20.15]],"id":66314580}],"con":true,"img":false}]}
{"op":"mcm","clk":"11541401566","pt":1719505366444,"mc":[{"id":"1.230180133","rc":[{"atb":[[1.72,5.87]],"id":53826530}],"con":true,"img":false}]}
{"op":"mcm","clk":"11541402736","pt":1719505377972,"mc":[{"id":"1.230180133","rc":[{"atb":[[1.19,0]],"id":66314580}],"con":true,"img":false}]}
{"op":"mcm","clk":"11541402746","pt":1719505378076,"mc":[{"id":"1.230180133","rc":[{"atb":[[1.7,0]],"id":53826530}],"con":true,"img":false}]}
{"op":"mcm","clk":"11541402767","pt":1719505378282,"mc":[{"id":"1.230180133","rc":[{"atb":[[1.18,0]],"id":66314580}],"con":true,"img":false}]}
{"op":"mcm","clk":"11541402780","pt":1719505378385,"mc":[{"id":"1.230180133","rc":[{"atb":[[1.62,0]],"id":67130716}],"con":true,"img":false}]}
{"op":"mcm","clk":"11541402795","pt":1719505378590,"mc":[{"id":"1.230180133","rc":[{"atb":[[1.23,17.18]],"id":66314580}],"con":true,"img":false}]}
{"op":"mcm","clk":"11541402828","pt":1719505378899,"mc":[{"id":"1.230180133","rc":[{"atb":[[1.74,5.34]],"id":53826530}],"con":true,"img":false}]}
{"op":"mcm","clk":"11541402846","pt":1719505379056,"mc":[{"id":"1.230180133","rc":[{"atb":[[1.7,0]],"id":67487134},{"atb":[[1.22,25.15]],"id":66314580}],"con":true,"img":false}]}
{"op":"mcm","clk":"11541402868","pt":1719505379262,"mc":[{"id":"1.230180133","rc":[{"atb":[[1.74,5.34]],"id":67487134},{"atb":[[1.66,5.99]],"id":67130716}],"con":true,"img":false}]}
{"op":"mcm","clk":"11541405193","pt":1719505400609,"mc":[{"id":"1.230180133","rc":[{"spn":38.37,"spf":"NaN","id":67487134},{"atb":[[1.2,0.25],[1.21,0]],"id":66314580},{"spn":1.47,"spf":1.0,"id":66314580},{"spn":38.37,"spf":"NaN","id":53826530},{"spn":38.33,"spf":"NaN","id":67130716}],"con":true,"img":false}]}
{"op":"mcm","clk":"11541405224","pt":1719505400919,"mc":[{"id":"1.230180133","rc":[{"atb":[[1.72,0]],"id":67487134},{"atb":[[1.64,0]],"id":67130716}],"con":true,"img":false}]}
{"op":"mcm","clk":"11541405259","pt":1719505401289,"mc":[{"id":"1.230180133","rc":[{"atb":[[1.72,0]],"id":53826530}],"con":true,"img":false}]}
{"op":"mcm","clk":"11541405320","pt":1719505401900,"mc":[{"id":"1.230180133","rc":[{"atb":[[1.24,24.68]],"id":66314580}],"con":true,"img":false}]}
{"op":"mcm","clk":"11541405330","pt":1719505402003,"mc":[{"id":"1.230180133","rc":[{"atb":[[1.25,16.92]],"id":66314580}],"con":true,"img":false}]}
{"op":"mcm","clk":"11541405351","pt":1719505402220,"mc":[{"id":"1.230180133","rc":[{"atb":[[1.68,6.22]],"id":67130716}],"con":true,"img":false}]}
{"op":"mcm","clk":"11541405362","pt":1719505402313,"mc":[{"id":"1.230180133","rc":[{"atb":[[1.76,5.56]],"id":67487134}],"con":true,"img":false}]}
{"op":"mcm","clk":"11541405387","pt":1719505402626,"mc":[{"id":"1.230180133","rc":[{"atb":[[1.76,5.56]],"id":53826530}],"con":true,"img":false}]}
{"op":"mcm","clk":"11541406685","pt":1719505414932,"mc":[{"id":"1.230180133","rc":[{"atb":[[1.22,0]],"id":66314580}],"con":true,"img":false}]}
{"op":"mcm","clk":"11541406718","pt":1719505415243,"mc":[{"id":"1.230180133","rc":[{"atb":[[1.74,0]],"id":67487134},{"atb":[[1.66,0]],"id":67130716}],"con":true,"img":false}]}
{"op":"mcm","clk":"11541406741","pt":1719505415410,"mc":[{"id":"1.230180133","rc":[{"atb":[[1.23,0]],"id":66314580}],"con":true,"img":false}]}
{"op":"mcm","clk":"11541406777","pt":1719505415732,"mc":[{"id":"1.230180133","rc":[{"atb":[[1.74,0]],"id":53826530}],"con":true,"img":false}]}
{"op":"mcm","clk":"11541406791","pt":1719505415823,"mc":[{"id":"1.230180133","rc":[{"atb":[[1.78,5.06]],"id":67487134}],"con":true,"img":false}]}
{"op":"mcm","clk":"11541406804","pt":1719505415934,"mc":[{"id":"1.230180133","rc":[{"atb":[[1.27,20.49]],"id":66314580}],"con":true,"img":false}]}
{"op":"mcm","clk":"11541406818","pt":1719505416029,"mc":[{"id":"1.230180133","rc":[{"atb":[[1.27,35.13]],"id":66314580}],"con":true,"img":false}]}
{"op":"mcm","clk":"11541406849","pt":1719505416335,"mc":[{"id":"1.230180133","rc":[{"atb":[[1.7,5.64]],"id":67130716}],"con":true,"img":false}]}
{"op":"mcm","clk":"11541406871","pt":1719505416544,"mc":[{"id":"1.230180133","rc":[{"atb":[[1.78,5.06]],"id":53826530}],"con":true,"img":false}]}
{"op":"mcm","clk":"11541409072","pt":1719505437850,"mc":[{"id":"1.230180133","rc":[{"atb":[[1.24,0]],"id":66314580},{"atb":[[1.68,0]],"id":67130716}],"con":true,"img":false}]}
{"op":"mcm","clk":"11541409118","pt":1719505438259,"mc":[{"id":"1.230180133","rc":[{"atb":[[1.25,0]],"id":66314580}],"con":true,"img":false}]}
{"op":"mcm","clk":"11541409151","pt":1719505438533,"mc":[{"id":"1.230180133","rc":[{"atb":[[1.29,20.42]],"id":66314580}],"con":true,"img":false}]}
{"op":"mcm","clk":"11541409190","pt":1719505438941,"mc":[{"id":"1.230180133","rc":[{"atb":[[1.76,0]],"id":67487134},{"atb":[[1.76,0]],"id":53826530}],"con":true,"img":false}]}
{"op":"mcm","clk":"11541409220","pt":1719505439248,"mc":[{"id":"1.230180133","rc":[{"atb":[[1.72,5.87]],"id":67130716}],"con":true,"img":false}]}
{"op":"mcm","clk":"11541409282","pt":1719505439828,"mc":[{"id":"1.230180133","rc":[{"atb":[[1.8,5.28]],"id":53826530}],"con":true,"img":false}]}
{"op":"mcm","clk":"11541409291","pt":1719505439931,"mc":[{"id":"1.230180133","rc":[{"atb":[[1.29,35.02]],"id":66314580}],"con":true,"img":false}]}
{"op":"mcm","clk":"11541409317","pt":1719505440245,"mc":[{"id":"1.230180133","rc":[{"atb":[[1.8,5.28]],"id":67487134}],"con":true,"img":false}]}
{"op":"mcm","clk":"11541409331","pt":1719505440343,"mc":[{"id":"1.230180133","rc":[{"atb":[[1.3,35.02]],"id":66314580},{"atl":[[6.4,2]],"id":66314580}],"con":true,"img":false}]}
{"op":"mcm","clk":"11541409340","pt":1719505440449,"mc":[{"id":"1.230180133","rc":[{"atb":[[1.89,2.12]],"id":67487134},{"atl":[[32,2]],"id":67487134},{"atb":[[1.83,5.07]],"id":53826530},{"atl":[[27,2]],"id":53826530},{"atb":[[1.33,2.48]],"id":70086038},{"atl":[[7,2]],"id":70086038},{"atb":[[1.24,2.48]],"id":64618726},{"atl":[[6.8,2]],"id":64618726},{"atb":[[1.73,5.64]],"id":67130716},{"atl":[[11,2]],"id":67130716}],"con":true,"img":false}]}
{"op":"mcm","clk":"11541409353","pt":1719505440552,"mc":[{"id":"1.230180133","rc":[{"atb":[[2.42,1]],"id":67487134},{"atl":[[8.4,1]],"id":67487134},{"atb":[[1.41,1]],"id":66314580},{"atl":[[3.45,1]],"id":66314580},{"atb":[[2.24,1]],"id":53826530},{"atl":[[7.4,1]],"id":53826530},{"atb":[[1.46,1]],"id":70086038},{"atl":[[3.7,1]],"id":70086038},{"atb":[[1.37,1]],"id":64618726},{"atl":[[3.25,1]],"id":64618726},{"atb":[[1.97,1]],"id":67130716},{"atl":[[7.2,1]],"id":67130716}],"con":true,"img":false}]}
{"op":"mcm","clk":"11541409362","pt":1719505440658,"mc":[{"id":"1.230180133","rc":[{"atl":[[7,1]],"id":67130716}],"con":true,"img":false}]}
{"op":"mcm","clk":"11541409514","pt":1719505442259,"mc":[{"id":"1.230180133","rc":[{"atl":[[7,0]],"id":67130716}],"con":true,"img":false}]}
{"op":"mcm","clk":"11541409601","pt":1719505443243,"mc":[{"id":"1.230180133","rc":[{"atb":[[1.33,2.11]],"id":66314580}],"con":true,"img":false}]}
{"op":"mcm","clk":"11541409619","pt":1719505443456,"mc":[{"id":"1.230180133","rc":[{"atb":[[1.33,37.13],[1.3,0]],"id":66314580}],"con":true,"img":false}]}
{"op":"mcm","clk":"11541409731","pt":1719505444533,"mc":[{"id":"1.230180133","rc":[{"atb":[[1.89,0],[2.06,5.07]],"id":67487134},{"atl":[[32,0],[60,2]],"id":67487134},{"atl":[[6.4,0],[9.2,3]],"id":66314580},{"atb":[[1.95,5.07]],"id":53826530},{"atl":[[46,2.22]],"id":53826530},{"atb":[[1.43,2.48],[1.33,0]],"id":70086038},{"atl":[[9.6,3],[7,0]],"id":70086038},{"atb":[[1.33,2.48],[1.24,0]],"id":64618726},{"atl":[[6.8,0],[9.4,3]],"id":64618726}],"con":true,"img":false}]}
{"op":"mcm","clk":"11541409736","pt":1719505444633,"mc":[{"id":"1.230180133","rc":[{"atb":[[1.83,0]],"id":53826530},{"atl":[[27,0]],"id":53826530}],"con":true,"img":false}]}
{"op":"mcm","clk":"11541410237","pt":1719505449054,"mc":[{"id":"1.230180133","rc":[{"atb":[[1.01,1.7]],"id":67487134},{"atl":[[1000,1.7]],"id":67487134},{"atb":[[1.01,1.7]],"id":66314580},{"atl":[[1000,1.87]],"id":66314580},{"atb":[[1.01,1.7]],"id":67130716},{"atl":[[1000,1.87]],"id":67130716}],"con":true,"img":false}]}
{"op":"mcm","clk":"11541410260","pt":1719505449258,"mc":[{"id":"1.230180133","rc":[{"atb":[[1.01,0.29]],"id":67487134},{"atl":[[1000,0]],"id":67487134},{"atb":[[1.01,0.93]],"id":66314580},{"atl":[[1000,0.21]],"id":66314580},{"atb":[[1.01,0.42]],"id":67130716},{"atl":[[11,0],[1000,0.21],[15.5,3]],"id":67130716}],"con":true,"img":false}]}
{"op":"mcm","clk":"11541410289","pt":1719505449460,"mc":[{"id":"1.230180133","rc":[{"atb":[[1.01,0]],"id":67487134},{"atl":[[1000,0]],"id":67487134},{"atb":[[1.01,0]],"id":66314580},{"atl":[[1000,0.17]],"id":66314580},{"atb":[[1.01,0]],"id":67130716},{"atl":[[1000,0.17]],"id":67130716}],"con":true,"img":false}]}
{"op":"mcm","clk":"11541410301","pt":1719505449567,"mc":[{"id":"1.230180133","rc":[{"atb":[[2.08,0.29]],"id":67487134},{"atl":[[55,0]],"id":67487134},{"atb":[[1.34,0.93]],"id":66314580},{"atl":[[9,0.03]],"id":66314580},{"atb":[[1.74,0.42]],"id":67130716},{"atl":[[10.5,0.03]],"id":67130716}],"con":true,"img":false}]}
{"op":"mcm","clk":"11541410327","pt":1719505449765,"mc":[{"id":"1.230180133","rc":[{"atb":[[1.27,14.63]],"id":66314580}],"con":true,"img":false}]}
{"op":"mcm","clk":"11541410389","pt":1719505450347,"mc":[{"id":"1.230180133","rc":[{"atb":[[1.27,0]],"id":66314580}],"con":true,"img":false}]}
{"op":"mcm","clk":"11541410407","pt":1719505450578,"mc":[{"id":"1.230180133","rc":[{"atb":[[1.35,11.29]],"id":66314580}],"con":true,"img":false}]}
{"op":"mcm","clk":"11541410467","pt":1719505451263,"mc":[{"id":"1.230180133","rc":[{"atl":[[7.4,0]],"id":53826530},{"trd":[[7.4,1.99]],"ltp":7.4,"tv":1.99,"id":53826530}],"con":true,"img":false}]}
{"op":"mcm","clk":"11541410486","pt":1719505451473,"mc":[{"id":"1.230180133","rc":[{"atl":[[9.6,1]],"id":53826530}],"con":true,"img":false}]}
{"op":"mcm","clk":"11541410649","pt":1719505453374,"mc":[{"id":"1.230180133","rc":[{"atb":[[2.08,2.24]],"id":67487134}],"con":true,"img":false}]}
{"op":"mcm","clk":"11541410660","pt":1719505453535,"mc":[{"id":"1.230180133","rc":[{"atb":[[1.36,11.29],[1.33,2.11]],"id":66314580}],"con":true,"img":false}]}
{"op":"mcm","clk":"11541411051","pt":1719505458685,"mc":[{"id":"1.230180133","rc":[{"atl":[[10.5,1],[8.4,0]],"id":67487134},{"atl":[[4.1,1]],"id":66314580},{"atl":[[4.2,1]],"id":70086038},{"atl":[[3.6,1],[3.25,0]],"id":64618726}],"con":true,"img":false}]}
{"op":"mcm","clk":"11541411063","pt":1719505458740,"mc":[{"id":"1.230180133","rc":[{"atl":[[3.45,0]],"id":66314580},{"atl":[[3.7,0]],"id":70086038}],"con":true,"img":false}]}
{"op":"mcm","clk":"11541411273","pt":1719505461270,"mc":[{"id":"1.230180133","rc":[{"spn":6.46,"spf":"NaN","id":67487134},{"atb":[[1.37,2]],"id":66314580},{"spn":1.56,"spf":1.0,"id":66314580},{"spn":5.92,"spf":"NaN","id":53826530},{"spn":2.83,"spf":"NaN","id":70086038},{"spn":2.48,"spf":"NaN","id":64618726},{"spn":4.58,"spf":"NaN","id":67130716}],"con":true,"img":false}]}
{"op":"mcm","clk":"11541411296","pt":1719505461579,"mc":[{"id":"1.230180133","rc":[{"atb":[[2.1,2]],"id":67487134}],"con":true,"img":false}]}
{"op":"mcm","clk":"11541411312","pt":1719505461788,"mc":[{"id":"1.230180133","rc":[{"atb":[[1.74,2.42]],"id":67130716}],"con":true,"img":false}]}
{"op":"mcm","clk":"11541411325","pt":1719505461946,"mc":[{"id":"1.230180133","rc":[{"atb":[[1.02,2]],"id":70086038}],"con":true,"img":false}]}
{"op":"mcm","clk":"11541411369","pt":1719505462464,"mc":[{"id":"1.230180133","rc":[{"atb":[[1.96,2]],"id":53826530}],"con":true,"img":false}]}
{"op":"mcm","clk":"11541411393","pt":1719505462769,"mc":[{"id":"1.230180133","rc":[{"atb":[[1.02,2]],"id":64618726}],"con":true,"img":false}]}
{"op":"mcm","clk":"11541411422","pt":1719505463184,"mc":[{"id":"1.230180133","rc":[{"atl":[[9.6,0]],"id":53826530},{"trd":[[9.6,1.99]],"ltp":9.6,"tv":1.99,"id":53826530}],"con":true,"img":false}]}
{"op":"mcm","clk":"11541411430","pt":1719505463296,"mc":[{"id":"1.230180133","rc":[{"atl":[[10.5,1]],"id":53826530}],"con":true,"img":false}]}
{"op":"mcm","clk":"11541412486","pt":1719505474898,"mc":[{"id":"1.230180133","rc":[{"atb":[[1.29,14.59]],"id":66314580}],"con":true,"img":false}]}
{"op":"mcm","clk":"11541413446","pt":1719505485413,"mc":[{"id":"1.230180133","rc":[{"atb":[[2.08,1.94]],"id":67487134},{"atl":[[55,0]],"id":67487134},{"atb":[[1.34,0]],"id":66314580},{"atl":[[9,0]],"id":66314580},{"atb":[[1.74,2]],"id":67130716},{"atl":[[10.5,0]],"id":67130716}],"con":true,"img":false}]}
{"op":"mcm","clk":"11541413537","pt":1719505486599,"mc":[{"id":"1.230180133","rc":[{"atb":[[2.1,0]],"id":67487134}],"con":true,"img":false}]}
{"op":"mcm","clk":"11541413544","pt":1719505486702,"mc":[{"id":"1.230180133","rc":[{"atb":[[2.08,3.94]],"id":67487134}],"con":true,"img":false}]}
{"op":"mcm","clk":"11541415912","pt":1719505514024,"mc":[{"id":"1.230180133","rc":[{"atb":[[1.78,0]],"id":67487134},{"atb":[[1.78,0]],"id":53826530},{"atb":[[1.7,0]],"id":67130716}],"con":true,"img":false}]}
{"op":"mcm","clk":"11541418096","pt":1719505539968,"mc":[{"id":"1.230180133","rc":[{"atb":[[1.35,0]],"id":66314580},{"spn":6.37,"spf":"NaN","id":53826530}],"con":true,"img":false}]}
{"op":"mcm","clk":"11541418202","pt":1719505541147,"mc":[{"id":"1.230180133","rc":[{"atb":[[1.8,0]],"id":67487134},{"atb":[[1.29,0]],"id":66314580},{"atb":[[1.8,0]],"id":53826530},{"atb":[[1.72,0]],"id":67130716}],"con":true,"img":false}]}
{"op":"mcm","clk":"11541418261","pt":1719505541764,"mc":[{"id":"1.230180133","rc":[{"atb":[[2.08,1.94]],"id":67487134}],"con":true,"img":false}]}
{"op":"mcm","clk":"11541418272","pt":1719505541871,"mc":[{"id":"1.230180133","rc":[{"atb":[[1.02,2]],"id":67487134}],"con":true,"img":false}]}
{"op":"mcm","clk":"11541418298","pt":1719505542169,"mc":[{"id":"1.230180133","rc":[{"atb":[[1.96,0]],"id":53826530}],"con":true,"img":false}]}
{"op":"mcm","clk":"11541418306","pt":1719505542273,"mc":[{"id":"1.230180133","rc":[{"atb":[[1.02,2]],"id":53826530}],"con":true,"img":false}]}
{"op":"mcm","clk":"11541418433","pt":1719505543978,"mc":[{"id":"1.230180133","rc":[{"atb":[[2.08,0]],"id":67487134}],"con":true,"img":false}]}
{"op":"mcm","clk":"11541418440","pt":1719505544079,"mc":[{"id":"1.230180133","rc":[{"atb":[[2.08,1.94]],"id":67487134}],"con":true,"img":false}]}
{"op":"mcm","clk":"11541418658","pt":1719505546465,"mc":[{"id":"1.230180133","rc":[{"atb":[[2.08,0]],"id":67487134}],"con":true,"img":false}]}
{"op":"mcm","clk":"11541418676","pt":1719505546672,"mc":[{"id":"1.230180133","rc":[{"atb":[[2.08,1.94]],"id":67487134}],"con":true,"img":false}]}
{"op":"mcm","clk":"11541418885","pt":1719505549087,"mc":[{"id":"1.230180133","rc":[{"atb":[[2.08,0]],"id":67487134}],"con":true,"img":false}]}
{"op":"mcm","clk":"11541418894","pt":1719505549192,"mc":[{"id":"1.230180133","rc":[{"atb":[[2.08,1.94]],"id":67487134}],"con":true,"img":false}]}
{"op":"mcm","clk":"11541419099","pt":1719505551570,"mc":[{"id":"1.230180133","rc":[{"atb":[[2.08,0]],"id":67487134}],"con":true,"img":false}]}
{"op":"mcm","clk":"11541419116","pt":1719505551787,"mc":[{"id":"1.230180133","rc":[{"atb":[[2.08,1.94]],"id":67487134}],"con":true,"img":false}]}
{"op":"mcm","clk":"11541419342","pt":1719505554196,"mc":[{"id":"1.230180133","rc":[{"atb":[[2.08,0]],"id":67487134}],"con":true,"img":false}]}
{"op":"mcm","clk":"11541419360","pt":1719505554360,"mc":[{"id":"1.230180133","rc":[{"atb":[[2.08,1.94]],"id":67487134}],"con":true,"img":false}]}
{"op":"mcm","clk":"11541419580","pt":1719505556783,"mc":[{"id":"1.230180133","rc":[{"atb":[[2.08,0]],"id":67487134}],"con":true,"img":false}]}
{"op":"mcm","clk":"11541419604","pt":1719505556989,"mc":[{"id":"1.230180133","rc":[{"atb":[[2.08,1.94]],"id":67487134}],"con":true,"img":false}]}
{"op":"mcm","clk":"11541419822","pt":1719505559398,"mc":[{"id":"1.230180133","rc":[{"atb":[[2.08,0]],"id":67487134}],"con":true,"img":false}]}
{"op":"mcm","clk":"11541419842","pt":1719505559560,"mc":[{"id":"1.230180133","rc":[{"atb":[[2.08,1.94]],"id":67487134}],"con":true,"img":false}]}
{"op":"mcm","clk":"11541419941","pt":1719505560703,"mc":[{"id":"1.230180133","rc":[{"atb":[[1.01,1.7]],"id":67487134},{"atl":[[1000,1.7]],"id":67487134},{"atb":[[1.01,1.7]],"id":66314580},{"atl":[[1000,1.87]],"id":66314580},{"atl":[[1000,1.87]],"id":67130716}],"con":true,"img":false}]}
{"op":"mcm","clk":"11541419951","pt":1719505560793,"mc":[{"id":"1.230180133","rc":[{"atb":[[1.01,1.7]],"id":67130716}],"con":true,"img":false}]}
{"op":"mcm","clk":"11541419968","pt":1719505560910,"mc":[{"id":"1.230180133","rc":[{"atb":[[1.01,0.27]],"id":67487134},{"atl":[[1000,0]],"id":67487134},{"atb":[[1.01,0.8]],"id":66314580},{"atl":[[1000,0.21]],"id":66314580},{"atb":[[1.01,0.4]],"id":67130716},{"atl":[[1000,0.19]],"id":67130716}],"con":true,"img":false}]}
{"op":"mcm","clk":"11541419988","pt":1719505561112,"mc":[{"id":"1.230180133","rc":[{"atb":[[1.01,0]],"id":67487134},{"atl":[[1000,0]],"id":67487134},{"atb":[[1.01,0]],"id":66314580},{"atl":[[1000,0.17]],"id":66314580},{"atb":[[1.01,0]],"id":67130716},{"atl":[[1000,0.17]],"id":67130716}],"con":true,"img":false}]}
{"op":"mcm","clk":"11541419995","pt":1719505561162,"mc":[{"id":"1.230180133","rc":[{"atb":[[2.1,0.27]],"id":67487134},{"atl":[[55,0]],"id":67487134},{"atb":[[1.38,0.8]],"id":66314580},{"atl":[[9,0.03]],"id":66314580},{"atb":[[1.75,0.4]],"id":67130716},{"atl":[[15,0.02]],"id":67130716}],"con":true,"img":false}]}
{"op":"mcm","clk":"11541420010","pt":1719505561276,"mc":[{"id":"1.230180133","rc":[{"atb":[[1.36,0],[1.38,2.8]],"id":66314580}],"con":true,"img":false}]}
{"op":"mcm","clk":"11541420073","pt":1719505561787,"mc":[{"id":"1.230180133","rc":[{"atb":[[1.37,0]],"id":66314580}],"con":true,"img":false}]}
{"op":"mcm","clk":"11541420083","pt":1719505561892,"mc":[{"id":"1.230180133","rc":[{"atb":[[1.39,2],[1.34,3.81],[1.38,0.8]],"id":66314580}],"con":true,"img":false}]}
{"op":"mcm","clk":"11541420132","pt":1719505562503,"mc":[{"id":"1.230180133","rc":[{"atb":[[1.39,0]],"id":66314580}],"con":true,"img":false}]}
{"op":"mcm","clk":"11541420141","pt":1719505562561,"mc":[{"id":"1.230180133","rc":[{"atb":[[1.35,2]],"id":66314580}],"con":true,"img":false}]}
{"op":"mcm","clk":"11541421002","pt":1719505569583,"mc":[{"id":"1.230180133","rc":[{"atl":[[10.5,0]],"id":53826530},{"trd":[[10.5,1.99]],"ltp":10.5,"tv":1.99,"id":53826530}],"con":true,"img":false}]}
{"op":"mcm","clk":"11541421039","pt":1719505569692,"mc":[{"id":"1.230180133","rc":[{"atb":[[1.47,2.3]],"id":53826530}],"con":true,"img":false}]}
{"op":"mcm","clk":"11541421053","pt":1719505569790,"mc":[{"id":"1.230180133","rc":[{"atl":[[12,1]],"id":53826530}],"con":true,"img":false}]}
{"op":"mcm","clk":"11541421095","pt":1719505570208,"mc":[{"id":"1.230180133","rc":[{"atb":[[1.02,0]],"id":53826530}],"con":true,"img":false}]}
{"op":"mcm","clk":"11541421103","pt":1719505570309,"mc":[{"id":"1.230180133","rc":[{"atb":[[1.96,2]],"id":53826530}],"con":true,"img":false}]}
{"op":"mcm","clk":"11541421153","pt":1719505570783,"mc":[{"id":"1.230180133","rc":[{"atb":[[1.36,2.12],[1.34,0]],"id":66314580}],"con":true,"img":false}]}
{"op":"mcm","clk":"11541421224","pt":1719505571397,"mc":[{"id":"1.230180133","rc":[{"atb":[[1.35,0]],"id":66314580}],"con":true,"img":false}]}
{"op":"mcm","clk":"11541421234","pt":1719505571510,"mc":[{"id":"1.230180133","rc":[{"atb":[[1.37,2]],"id":66314580}],"con":true,"img":false}]}
{"op":"mcm","clk":"11541421265","pt":1719505571815,"mc":[{"id":"1.230180133","rc":[{"atb":[[1.96,0]],"id":53826530}],"con":true,"img":false}]}
{"op":"mcm","clk":"11541421284","pt":1719505571917,"mc":[{"id":"1.230180133","rc":[{"atb":[[1.02,2]],"id":53826530}],"con":true,"img":false}]}
{"op":"mcm","clk":"11541421466","pt":1719505573631,"mc":[{"id":"1.230180133","rc":[{"atb":[[1.02,0]],"id":53826530}],"con":true,"img":false}]}
{"op":"mcm","clk":"11541421473","pt":1719505573724,"mc":[{"id":"1.230180133","rc":[{"atb":[[1.96,2]],"id":53826530}],"con":true,"img":false}]}
{"op":"mcm","clk":"11541421625","pt":1719505575176,"mc":[{"id":"1.230180133","rc":[{"atb":[[1.96,0]],"id":53826530}],"con":true,"img":false}]}
{"op":"mcm","clk":"11541421633","pt":1719505575278,"mc":[{"id":"1.230180133","rc":[{"atb":[[1.02,2]],"id":53826530}],"con":true,"img":false}]}
{"op":"mcm","clk":"11541421752","pt":1719505576717,"mc":[{"id":"1.230180133","rc":[{"atb":[[1.02,0]],"id":53826530}],"con":true,"img":false}]}
{"op":"mcm","clk":"11541421761","pt":1719505576778,"mc":[{"id":"1.230180133","rc":[{"atb":[[1.96,2]],"id":53826530}],"con":true,"img":false}]}
{"op":"mcm","clk":"11541421879","pt":1719505578075,"mc":[{"id":"1.230180133","rc":[{"atb":[[1.96,0]],"id":53826530}],"con":true,"img":false}]}
{"op":"mcm","clk":"11541421885","pt":1719505578180,"mc":[{"id":"1.230180133","rc":[{"atb":[[1.02,2]],"id":53826530}],"con":true,"img":false}]}
{"op":"mcm","clk":"11541422008","pt":1719505579686,"mc":[{"id":"1.230180133","rc":[{"atb":[[1.36,0],[1.38,2.8]],"id":66314580}],"con":true,"img":false}]}
{"op":"mcm","clk":"11541422070","pt":1719505580398,"mc":[{"id":"1.230180133","rc":[{"atb":[[1.02,0]],"id":53826530}],"con":true,"img":false}]}
{"op":"mcm","clk":"11541422078","pt":1719505580499,"mc":[{"id":"1.230180133","rc":[{"atb":[[1.96,2]],"id":53826530}],"con":true,"img":false}]}
{"op":"mcm","clk":"11541422183","pt":1719505581694,"mc":[{"id":"1.230180133","rc":[{"atb":[[1.37,0]],"id":66314580}],"con":true,"img":false}]}
{"op":"mcm","clk":"11541422190","pt":1719505581794,"mc":[{"id":"1.230180133","rc":[{"atb":[[1.39,2],[1.34,3.81],[1.38,0.8]],"id":66314580}],"con":true,"img":false}]}
{"op":"mcm","clk":"11541422201","pt":1719505581903,"mc":[{"id":"1.230180133","rc":[{"atb":[[1.39,4],[1.34,0]],"id":66314580}],"con":true,"img":false}]}
{"op":"mcm","clk":"11541422223","pt":1719505582211,"mc":[{"id":"1.230180133","rc":[{"atb":[[1.96,0]],"id":53826530}],"con":true,"img":false}]}
{"op":"mcm","clk":"11541422232","pt":1719505582315,"mc":[{"id":"1.230180133","rc":[{"atb":[[1.02,2]],"id":53826530}],"con":true,"img":false}]}
{"op":"mcm","clk":"11541422363","pt":1719505583608,"mc":[{"id":"1.230180133","rc":[{"atb":[[1.39,2]],"id":66314580}],"con":true,"img":false}]}
{"op":"mcm","clk":"11541422372","pt":1719505583712,"mc":[{"id":"1.230180133","rc":[{"atb":[[1.02,2],[1.38,3.8]],"id":66314580}],"con":true,"img":false}]}
{"op":"mcm","clk":"11541422383","pt":1719505583814,"mc":[{"id":"1.230180133","rc":[{"atb":[[1.39,0]],"id":66314580}],"con":true,"img":false}]}
{"op":"mcm","clk":"11541422399","pt":1719505584028,"mc":[{"id":"1.230180133","rc":[{"atb":[[1.02,0]],"id":53826530}],"con":true,"img":false}]}
{"op":"mcm","clk":"11541422410","pt":1719505584123,"mc":[{"id":"1.230180133","rc":[{"atb":[[1.96,2]],"id":53826530}],"con":true,"img":false}]}
{"op":"mcm","clk":"11541422539","pt":1719505585731,"mc":[{"id":"1.230180133","rc":[{"atb":[[1.96,0]],"id":53826530}],"con":true,"img":false}]}
{"op":"mcm","clk":"11541422552","pt":1719505585836,"mc":[{"id":"1.230180133","rc":[{"atb":[[1.02,2]],"id":53826530}],"con":true,"img":false}]}
{"op":"mcm","clk":"11541422686","pt":1719505587327,"mc":[{"id":"1.230180133","rc":[{"atb":[[1.02,0]],"id":53826530}],"con":true,"img":false}]}
{"op":"mcm","clk":"11541422695","pt":1719505587429,"mc":[{"id":"1.230180133","rc":[{"atb":[[1.96,2]],"id":53826530}],"con":true,"img":false}]}
{"op":"mcm","clk":"11541422759","pt":1719505588202,"mc":[{"id":"1.230180133","rc":[{"atb":[[1.97,2.06],[1.47,0]],"id":53826530}],"con":true,"img":false}]}
{"op":"mcm","clk":"11541422796","pt":1719505588723,"mc":[{"id":"1.230180133","rc":[{"atb":[[1.96,0]],"id":53826530}],"con":true,"img":false}]}
{"op":"mcm","clk":"11541422808","pt":1719505588826,"mc":[{"id":"1.230180133","rc":[{"atb":[[1.98,2]],"id":53826530}],"con":true,"img":false}]}
{"op":"mcm","clk":"11541422821","pt":1719505588923,"mc":[{"id":"1.230180133","rc":[{"atb":[[1.98,4.06],[1.95,0]],"id":53826530}],"con":true,"img":false}]}
{"op":"mcm","clk":"11541422917","pt":1719505590009,"mc":[{"id":"1.230180133","rc":[{"atb":[[1.98,2.06]],"id":53826530}],"con":true,"img":false}]}
{"op":"mcm","clk":"11541422925","pt":1719505590113,"mc":[{"id":"1.230180133","rc":[{"atb":[[1.02,2]],"id":53826530}],"con":true,"img":false}]}
{"op":"mcm","clk":"11541424279","pt":1719505606273,"mc":[{"id":"1.230180133","rc":[{"atb":[[1.97,0]],"id":53826530},{"spn":7.12,"spf":"NaN","id":53826530}],"con":true,"img":false}]}
{"op":"mcm","clk":"11541424288","pt":1719505606326,"mc":[{"id":"1.230180133","rc":[{"atb":[[1.47,2.3]],"id":53826530}],"con":true,"img":false}]}
{"op":"mcm","clk":"11541424409","pt":1719505607836,"mc":[{"id":"1.230180133","rc":[{"atb":[[2.1,0]],"id":67487134},{"atl":[[55,0]],"id":67487134},{"atb":[[1.38,3]],"id":66314580},{"atl":[[9,0]],"id":66314580},{"atb":[[1.75,0]],"id":67130716},{"atl":[[15,0]],"id":67130716}],"con":true,"img":false}]}
{"op":"mcm","clk":"11541424415","pt":1719505607944,"mc":[{"id":"1.230180133","rc":[{"atb":[[1.34,4],[1.38,0]],"id":66314580}],"con":true,"img":false}]}
{"op":"mcm","clk":"11541424550","pt":1719505609543,"mc":[{"id":"1.230180133","rc":[{"atb":[[2.08,0]],"id":67487134}],"con":true,"img":false}]}
{"op":"mcm","clk":"11541424562","pt":1719505609754,"mc":[{"id":"1.230180133","rc":[{"atb":[[2.08,1.94]],"id":67487134}],"con":true,"img":false}]}
{"op":"mcm","clk":"11541424766","pt":1719505612021,"mc":[{"id":"1.230180133","rc":[{"atb":[[2.08,0]],"id":67487134}],"con":true,"img":false}]}
{"op":"mcm","clk":"11541424786","pt":1719505612230,"mc":[{"id":"1.230180133","rc":[{"atb":[[2.08,1.94]],"id":67487134}],"con":true,"img":false}]}
{"op":"mcm","clk":"11541424821","pt":1719505612644,"mc":[{"id":"1.230180133","rc":[{"atb":[[1.36,11.75]],"id":66314580}],"con":true,"img":false}]}
{"op":"mcm","clk":"11541424892","pt":1719505613262,"mc":[{"id":"1.230180133","rc":[{"atb":[[1.02,0]],"id":66314580}],"con":true,"img":false}]}
{"op":"mcm","clk":"11541424904","pt":1719505613368,"mc":[{"id":"1.230180133","rc":[{"atb":[[1.37,2]],"id":66314580}],"con":true,"img":false}]}
{"op":"mcm","clk":"11541425026","pt":1719505614662,"mc":[{"id":"1.230180133","rc":[{"atb":[[2.08,0]],"id":67487134}],"con":true,"img":false}]}
{"op":"mcm","clk":"11541425045","pt":1719505614818,"mc":[{"id":"1.230180133","rc":[{"atb":[[2.08,1.94]],"id":67487134}],"con":true,"img":false}]}
{"op":"mcm","clk":"11541425178","pt":1719505616469,"mc":[{"id":"1.230180133","rc":[{"atb":[[1.37,6],[1.34,0]],"id":66314580}],"con":true,"img":false}]}
{"op":"mcm","clk":"11541425255","pt":1719505617246,"mc":[{"id":"1.230180133","rc":[{"atb":[[2.08,0]],"id":67487134}],"con":true,"img":false}]}
{"op":"mcm","clk":"11541425267","pt":1719505617350,"mc":[{"id":"1.230180133","rc":[{"atb":[[2.08,1.94]],"id":67487134}],"con":true,"img":false}]}
{"op":"mcm","clk":"11541425492","pt":1719505619641,"mc":[{"id":"1.230180133","rc":[{"atb":[[2.08,0]],"id":67487134}],"con":true,"img":false}]}
{"op":"mcm","clk":"11541425513","pt":1719505619846,"mc":[{"id":"1.230180133","rc":[{"atb":[[2.08,1.94]],"id":67487134}],"con":true,"img":false}]}
{"op":"mcm","clk":"11541425725","pt":1719505622228,"mc":[{"id":"1.230180133","rc":[{"atb":[[2.08,0]],"id":67487134}],"con":true,"img":false}]}
{"op":"mcm","clk":"11541425744","pt":1719505622491,"mc":[{"id":"1.230180133","rc":[{"atb":[[2.08,1.94]],"id":67487134}],"con":true,"img":false}]}
{"op":"mcm","clk":"11541425962","pt":1719505624768,"mc":[{"id":"1.230180133","rc":[{"atb":[[2.08,0]],"id":67487134}],"con":true,"img":false}]}
{"op":"mcm","clk":"11541425973","pt":1719505624870,"mc":[{"id":"1.230180133","rc":[{"atb":[[2.08,1.94]],"id":67487134}],"con":true,"img":false}]}
{"op":"mcm","clk":"11541426183","pt":1719505627252,"mc":[{"id":"1.230180133","rc":[{"atb":[[2.08,0]],"id":67487134}],"con":true,"img":false}]}
{"op":"mcm","clk":"11541426202","pt":1719505627460,"mc":[{"id":"1.230180133","rc":[{"atb":[[2.08,1.94]],"id":67487134}],"con":true,"img":false}]}
{"op":"mcm","clk":"11541426430","pt":1719505629743,"mc":[{"id":"1.230180133","rc":[{"atb":[[2.08,0]],"id":67487134}],"con":true,"img":false}]}
{"op":"mcm","clk":"11541426448","pt":1719505629946,"mc":[{"id":"1.230180133","rc":[{"atb":[[2.08,1.94]],"id":67487134}],"con":true,"img":false}]}
{"op":"mcm","clk":"11541426657","pt":1719505632241,"mc":[{"id":"1.230180133","rc":[{"atb":[[2.08,0]],"id":67487134}],"con":true,"img":false}]}
{"op":"mcm","clk":"11541426679","pt":1719505632444,"mc":[{"id":"1.230180133","rc":[{"atb":[[2.08,1.94]],"id":67487134}],"con":true,"img":false}]}
{"op":"mcm","clk":"11541426749","pt":1719505633169,"mc":[{"id":"1.230180133","rc":[{"atb":[[1.23,5]],"id":66314580}],"con":true,"img":false}]}
{"op":"mcm","clk":"11541426758","pt":1719505633269,"mc":[{"id":"1.230180133","rc":[{"atb":[[1.23,0]],"id":66314580}],"con":true,"img":false}]}
{"op":"mcm","clk":"11541426905","pt":1719505634770,"mc":[{"id":"1.230180133","rc":[{"atb":[[2.08,0]],"id":67487134}],"con":true,"img":false}]}
{"op":"mcm","clk":"11541426914","pt":1719505634873,"mc":[{"id":"1.230180133","rc":[{"atb":[[2.08,1.94]],"id":67487134}],"con":true,"img":false}]}
{"op":"mcm","clk":"11541427144","pt":1719505637258,"mc":[{"id":"1.230180133","rc":[{"atb":[[2.08,0]],"id":67487134}],"con":true,"img":false}]}
{"op":"mcm","clk":"11541427161","pt":1719505637463,"mc":[{"id":"1.230180133","rc":[{"atb":[[2.08,1.94]],"id":67487134}],"con":true,"img":false}]}
{"op":"mcm","clk":"11541427356","pt":1719505639888,"mc":[{"id":"1.230180133","rc":[{"atb":[[2.08,0]],"id":67487134}],"con":true,"img":false}]}
{"op":"mcm","clk":"11541427367","pt":1719505639996,"mc":[{"id":"1.230180133","rc":[{"atb":[[2.08,1.94]],"id":67487134}],"con":true,"img":false}]}
{"op":"mcm","clk":"11541427589","pt":1719505642375,"mc":[{"id":"1.230180133","rc":[{"atb":[[2.08,0]],"id":67487134}],"con":true,"img":false}]}
{"op":"mcm","clk":"11541427598","pt":1719505642479,"mc":[{"id":"1.230180133","rc":[{"atb":[[2.08,1.94]],"id":67487134}],"con":true,"img":false}]}
{"op":"mcm","clk":"11541427817","pt":1719505644762,"mc":[{"id":"1.230180133","rc":[{"atb":[[2.08,0]],"id":67487134}],"con":true,"img":false}]}
{"op":"mcm","clk":"11541427833","pt":1719505644968,"mc":[{"id":"1.230180133","rc":[{"atb":[[2.08,1.94]],"id":67487134}],"con":true,"img":false}]}
{"op":"mcm","clk":"11541427961","pt":1719505646571,"mc":[{"id":"1.230180133","rc":[{"atb":[[1.36,0]],"id":66314580}],"con":true,"img":false}]}
{"op":"mcm","clk":"11541428041","pt":1719505647394,"mc":[{"id":"1.230180133","rc":[{"atb":[[2.08,0]],"id":67487134}],"con":true,"img":false}]}
{"op":"mcm","clk":"11541428056","pt":1719505647605,"mc":[{"id":"1.230180133","rc":[{"atb":[[2.08,1.94]],"id":67487134},{"atb":[[1.37,4]],"id":66314580}],"con":true,"img":false}]}
{"op":"mcm","clk":"11541428066","pt":1719505647703,"mc":[{"id":"1.230180133","rc":[{"atb":[[1.37,0],[1.02,2],[1.34,5]],"id":66314580}],"con":true,"img":false}]}
{"op":"mcm","clk":"11541428261","pt":1719505649876,"mc":[{"id":"1.230180133","rc":[{"atb":[[2.08,0]],"id":67487134}],"con":true,"img":false}]}
{"op":"mcm","clk":"11541428272","pt":1719505649983,"mc":[{"id":"1.230180133","rc":[{"atb":[[2.08,1.94]],"id":67487134}],"con":true,"img":false}]}
{"op":"mcm","clk":"11541428517","pt":1719505652524,"mc":[{"id":"1.230180133","rc":[{"atb":[[2.08,0]],"id":67487134}],"con":true,"img":false}]}
{"op":"mcm","clk":"11541428534","pt":1719505652675,"mc":[{"id":"1.230180133","rc":[{"atb":[[2.08,1.94]],"id":67487134}],"con":true,"img":false}]}
{"op":"mcm","clk":"11541428731","pt":1719505655001,"mc":[{"id":"1.230180133","rc":[{"atb":[[2.08,0]],"id":67487134}],"con":true,"img":false}]}
{"op":"mcm","clk":"11541428775","pt":1719505655515,"mc":[{"id":"1.230180133","rc":[{"atb":[[2.08,1.94]],"id":67487134}],"con":true,"img":false}]}
{"op":"mcm","clk":"11541429003","pt":1719505657890,"mc":[{"id":"1.230180133","rc":[{"atb":[[2.08,0]],"id":67487134}],"con":true,"img":false}]}
{"op":"mcm","clk":"11541429026","pt":1719505658095,"mc":[{"id":"1.230180133","rc":[{"atb":[[2.08,1.94]],"id":67487134}],"con":true,"img":false}]}
{"op":"mcm","clk":"11541429216","pt":1719505660420,"mc":[{"id":"1.230180133","rc":[{"atb":[[2.08,0]],"id":67487134}],"con":true,"img":false}]}
{"op":"mcm","clk":"11541429238","pt":1719505660625,"mc":[{"id":"1.230180133","rc":[{"atb":[[2.08,1.94]],"id":67487134}],"con":true,"img":false}]}
{"op":"mcm","clk":"11541429476","pt":1719505662904,"mc":[{"id":"1.230180133","rc":[{"atb":[[2.08,0]],"id":67487134}],"con":true,"img":false}]}
{"op":"mcm","clk":"11541429491","pt":1719505663109,"mc":[{"id":"1.230180133","rc":[{"atb":[[2.08,1.94]],"id":67487134}],"con":true,"img":false}]}
{"op":"mcm","clk":"11541429732","pt":1719505665408,"mc":[{"id":"1.230180133","rc":[{"atb":[[2.08,0]],"id":67487134}],"con":true,"img":false}]}
{"op":"mcm","clk":"11541429753","pt":1719505665607,"mc":[{"id":"1.230180133","rc":[{"atb":[[2.08,1.94]],"id":67487134}],"con":true,"img":false}]}
{"op":"mcm","clk":"11541429957","pt":1719505668040,"mc":[{"id":"1.230180133","rc":[{"atb":[[2.08,0]],"id":67487134}],"con":true,"img":false}]}
{"op":"mcm","clk":"11541429964","pt":1719505668088,"mc":[{"id":"1.230180133","rc":[{"atb":[[2.08,1.94]],"id":67487134}],"con":true,"img":false}]}
{"op":"mcm","clk":"11541430169","pt":1719505670518,"mc":[{"id":"1.230180133","rc":[{"atb":[[2.08,0]],"id":67487134}],"con":true,"img":false}]}
{"op":"mcm","clk":"11541430188","pt":1719505670722,"mc":[{"id":"1.230180133","rc":[{"atb":[[2.08,1.94]],"id":67487134}],"con":true,"img":false}]}
{"op":"mcm","clk":"11541430413","pt":1719505673107,"mc":[{"id":"1.230180133","rc":[{"atb":[[2.08,0]],"id":67487134}],"con":true,"img":false}]}
{"op":"mcm","clk":"11541430432","pt":1719505673316,"mc":[{"id":"1.230180133","rc":[{"atb":[[2.08,1.94]],"id":67487134}],"con":true,"img":false}]}
{"op":"mcm","clk":"11541431481","pt":1719505684337,"mc":[{"id":"1.230180133","rc":[{"atl":[[1000,1.7]],"id":67487134},{"atl":[[1000,1.87]],"id":66314580},{"atl":[[1000,1.87]],"id":67130716}],"con":true,"img":false}]}
{"op":"mcm","clk":"11541431496","pt":1719505684436,"mc":[{"id":"1.230180133","rc":[{"atb":[[1.01,1.7]],"id":67487134},{"atb":[[1.01,1.7]],"id":66314580},{"atb":[[1.01,1.7]],"id":67130716}],"con":true,"img":false}]}
{"op":"mcm","clk":"11541431508","pt":1719505684540,"mc":[{"id":"1.230180133","rc":[{"atl":[[1000,0.21]],"id":66314580},{"atl":[[1000,0.19]],"id":67130716}],"con":true,"img":false}]}
{"op":"mcm","clk":"11541431519","pt":1719505684642,"mc":[{"id":"1.230180133","rc":[{"atb":[[1.01,0.26]],"id":67487134},{"atl":[[1000,0]],"id":67487134},{"atb":[[1.01,0.84]],"id":66314580},{"atb":[[1.01,0.39]],"id":67130716}],"con":true,"img":false}]}
{"op":"mcm","clk":"11541431526","pt":1719505684761,"mc":[{"id":"1.230180133","rc":[{"atl":[[1000,0.17]],"id":66314580},{"atl":[[1000,0.17]],"id":67130716}],"con":true,"img":false}]}
{"op":"mcm","clk":"11541431539","pt":1719505684861,"mc":[{"id":"1.230180133","rc":[{"atb":[[1.01,0]],"id":67487134},{"atl":[[1000,0]],"id":67487134},{"atb":[[1.01,0]],"id":66314580},{"atl":[[9,0.03]],"id":66314580},{"atb":[[1.01,0]],"id":67130716},{"atl":[[15,0.02]],"id":67130716}],"con":true,"img":false}]}
{"op":"mcm","clk":"11541431548","pt":1719505684955,"mc":[{"id":"1.230180133","rc":[{"atb":[[2.1,0.26]],"id":67487134},{"atl":[[55,0]],"id":67487134},{"atb":[[1.35,0.84]],"id":66314580},{"atb":[[1.75,0.39]],"id":67130716}],"con":true,"img":false}]}
{"op":"mcm","clk":"11541435446","pt":1719505726678,"mc":[{"id":"1.230180133","rc":[{"atb":[[2.1,0]],"id":67487134},{"atl":[[55,0]],"id":67487134},{"atb":[[1.35,0]],"id":66314580},{"atl":[[9,0]],"id":66314580},{"atb":[[1.75,0]],"id":67130716},{"atl":[[15,0]],"id":67130716}],"con":true,"img":false}]}
{"op":"mcm","clk":"11541436148","pt":1719505734626,"mc":[{"id":"1.230180133","rc":[{"atl":[[3.6,0],[4.2,1]],"id":64618726},{"spn":2.78,"spf":"NaN","id":64618726},{"atl":[[7.2,0],[9.2,1]],"id":67130716},{"spn":5.58,"spf":"NaN","id":67130716}],"con":true,"img":false}]}
{"op":"mcm","clk":"11541436159","pt":1719505734696,"mc":[{"id":"1.230180133","rc":[{"atl":[[7.6,1]],"id":67130716}],"con":true,"img":false}]}
{"op":"mcm","clk":"11541436168","pt":1719505734798,"mc":[{"id":"1.230180133","rc":[{"atl":[[3.6,1],[4.2,0]],"id":64618726},{"atl":[[7.4,1]],"id":67130716}],"con":true,"img":false}]}
{"op":"mcm","clk":"11541436176","pt":1719505734902,"mc":[{"id":"1.230180133","rc":[{"atl":[[9.2,2],[15.5,0]],"id":67130716}],"con":true,"img":false}]}
{"op":"mcm","clk":"11541436197","pt":1719505735106,"mc":[{"id":"1.230180133","rc":[{"atl":[[7.6,0]],"id":67130716}],"con":true,"img":false}]}
{"op":"mcm","clk":"11541436209","pt":1719505735207,"mc":[{"id":"1.230180133","rc":[{"atl":[[9.2,0],[15.5,3]],"id":67130716}],"con":true,"img":false}]}
{"op":"mcm","clk":"11541436459","pt":1719505738104,"mc":[{"id":"1.230180133","rc":[{"atb":[[2.44,2.21],[2.62,10],[2.14,2.12],[2.06,0],[2.78,2.5],[2.7,5]],"id":67487134},{"atl":[[9.2,5],[10,12.21],[8.4,2.5]],"id":67487134},{"atb":[[1.46,2.5],[1.42,7.34],[1.38,10]],"id":66314580},{"atl":[[4,2.34],[4.5,10],[3.85,2.5],[4.1,6]],"id":66314580},{"atb":[[2.8,10],[1.98,0],[2.04,2.12],[2.26,3.83],[2.88,5],[2.96,2.5]],"id":53826530},{"atl":[[10.5,2.5],[11.5,2.3],[12.5,5],[14.5,10]],"id":53826530},{"atb":[[1.99,5],[1.43,0],[2.06,2.5],[1.49,2],[1.95,10],[1.47,1.5]],"id":70086038},{"atl":[[4.5,2.5],[4.1,1.5],[5.3,10],[4.9,5]],"id":70086038},{"atb":[[1.92,2.5],[1.84,10],[1.88,5],[1.33,0],[1.39,2],[1.38,1.5]],"id":64618726},{"atl":[[5.1,5],[5.5,10],[3.55,1.5],[4.7,2.5]],"id":64618726},{"atb":[[2.36,2.5],[1.98,2.25],[2.28,5],[2.2,10]],"id":67130716},{"atl":[[7.2,3.25],[10.5,2.5],[7.4,0],[12.5,5],[14.5,10]],"id":67130716}],"con":true,"img":false}]}
{"op":"mcm","clk":"11541436470","pt":1719505738210,"mc":[{"id":"1.230180133","rc":[{"atl":[[9.6,7.5],[60,0]],"id":67487134},{"atb":[[1.46,5],[1.34,0]],"id":66314580},{"atl":[[3.85,5],[9.2,0]],"id":66314580},{"atb":[[2.86,7.5]],"id":53826530},{"atl":[[10.5,4.8],[46,0]],"id":53826530},{"atl":[[4.1,3.5]],"id":70086038},{"atb":[[1.81,10],[1.39,0]],"id":64618726},{"atb":[[2.18,10]],"id":67130716}],"con":true,"img":false}]}
{"op":"mcm","clk":"11541436480","pt":1719505738314,"mc":[{"id":"1.230180133","rc":[{"atb":[[2.78,7.5],[2.14,0]],"id":67487134},{"atb":[[2.04,0]],"id":53826530},{"atb":[[1.91,10]],"id":70086038},{"atl":[[3.7,5],[9.4,0]],"id":64618726},{"atb":[[1.73,0]],"id":67130716}],"con":true,"img":false}]}
{"op":"mcm","clk":"11541436488","pt":1719505738414,"mc":[{"id":"1.230180133","rc":[{"atb":[[1.41,13.34],[1.46,2.5]],"id":66314580},{"atl":[[3.85,2.5],[4.1,13.34]],"id":66314580},{"atl":[[10.5,2.5],[12,8.1]],"id":53826530},{"atb":[[1.49,0]],"id":70086038},{"atl":[[9.6,0],[4.5,7.5],[4.1,1.5]],"id":70086038}],"con":true,"img":false}]}
{"op":"mcm","clk":"11541436497","pt":1719505738524,"mc":[{"id":"1.230180133","rc":[{"atb":[[2.62,22.5]],"id":67487134}],"con":true,"img":false}]}
{"op":"mcm","clk":"11541436507","pt":1719505738579,"mc":[{"id":"1.230180133","rc":[{"atb":[[2.78,2.5]],"id":67487134}],"con":true,"img":false}]}
{"op":"mcm","clk":"11541436535","pt":1719505738894,"mc":[{"id":"1.230180133","rc":[{"atl":[[8.2,0.84]],"id":67487134},{"atb":[[1.02,0]],"id":66314580},{"atl":[[3.8,0.84]],"id":66314580},{"atl":[[7,0.84]],"id":67130716}],"con":true,"img":false}]}
{"op":"mcm","clk":"11541436544","pt":1719505738992,"mc":[{"id":"1.230180133","rc":[{"atb":[[1.47,2]],"id":66314580}],"con":true,"img":false}]}
{"op":"mcm","clk":"11541436584","pt":1719505739403,"mc":[{"id":"1.230180133","rc":[{"atb":[[1.02,0]],"id":67487134}],"con":true,"img":false}]}
{"op":"mcm","clk":"11541436595","pt":1719505739501,"mc":[{"id":"1.230180133","rc":[{"atb":[[2.8,2]],"id":67487134}],"con":true,"img":false}]}
{"op":"mcm","clk":"11541436605","pt":1719505739605,"mc":[{"id":"1.230180133","rc":[{"atb":[[2.62,10]],"id":67487134}],"con":true,"img":false}]}
{"op":"mcm","clk":"11541436614","pt":1719505739708,"mc":[{"id":"1.230180133","rc":[{"atb":[[2.8,4.5]],"id":67487134}],"con":true,"img":false}]}
{"op":"mcm","clk":"11541436626","pt":1719505739810,"mc":[{"id":"1.230180133","rc":[{"atb":[[2.8,2],[2.7,10]],"id":67487134},{"atb":[[1.74,0]],"id":67130716}],"con":true,"img":false}]}
{"op":"mcm","clk":"11541436639","pt":1719505739912,"mc":[{"id":"1.230180133","rc":[{"atb":[[2.8,6.5],[2.7,5]],"id":67487134},{"atb":[[2.38,2]],"id":67130716}],"con":true,"img":false}]}
{"op":"mcm","clk":"11541436656","pt":1719505740122,"mc":[{"id":"1.230180133","rc":[{"atl":[[3.55,4.03]],"id":64618726}],"con":true,"img":false}]}
{"op":"mcm","clk":"11541436667","pt":1719505740185,"mc":[{"id":"1.230180133","rc":[{"atb":[[1.45,2.11],[1.33,0]],"id":66314580},{"atb":[[1.98,2.11]],"id":70086038},{"atb":[[1.87,2.11]],"id":64618726}],"con":true,"img":false}]}
{"op":"mcm","clk":"11541436685","pt":1719505740407,"mc":[{"id":"1.230180133","rc":[{"atb":[[1.02,0]],"id":53826530}],"con":true,"img":false}]}
{"op":"mcm","clk":"11541436693","pt":1719505740496,"mc":[{"id":"1.230180133","rc":[{"atb":[[2.98,2]],"id":53826530}],"con":true,"img":false}]}
{"op":"mcm","clk":"11541436738","pt":1719505740906,"mc":[{"id":"1.230180133","rc":[{"atb":[[1.02,0]],"id":64618726},{"atl":[[3.5,0.84]],"id":64618726}],"con":true,"img":false}]}
{"op":"mcm","clk":"11541436745","pt":1719505741008,"mc":[{"id":"1.230180133","rc":[{"atb":[[1.93,2]],"id":64618726}],"con":true,"img":false}]}
{"op":"mcm","clk":"11541436826","pt":1719505741715,"mc":[{"id":"1.230180133","rc":[{"atb":[[3,2.06],[2.98,4.5],[2.86,0],[1.47,0]],"id":53826530},{"atb":[[1.91,0],[1.96,10]],"id":70086038}],"con":true,"img":false}]}
{"op":"mcm","clk":"11541436837","pt":1719505741823,"mc":[{"id":"1.230180133","rc":[{"atb":[[2.98,2],[2.96,7.5]],"id":53826530}],"con":true,"img":false}]}
{"op":"mcm","clk":"11541436848","pt":1719505741922,"mc":[{"id":"1.230180133","rc":[{"atb":[[3,0]],"id":53826530}],"con":true,"img":false}]}
{"op":"mcm","clk":"11541436895","pt":1719505742104,"mc":[{"id":"1.230180133","rc":[{"atl":[[4,3.34]],"id":66314580}],"con":true,"img":false}]}
{"op":"mcm","clk":"11541436905","pt":1719505742189,"mc":[{"id":"1.230180133","rc":[{"atl":[[4.1,12.34]],"id":66314580}],"con":true,"img":false}]}
{"op":"mcm","clk":"11541436929","pt":1719505742395,"mc":[{"id":"1.230180133","rc":[{"atl":[[10.5,7.5],[15.5,0]],"id":67130716}],"con":true,"img":false}]}
{"op":"mcm","clk":"11541436938","pt":1719505742504,"mc":[{"id":"1.230180133","rc":[{"atl":[[4.2,3.26]],"id":66314580}],"con":true,"img":false}]}
{"op":"mcm","clk":"11541436962","pt":1719505742709,"mc":[{"id":"1.230180133","rc":[{"atl":[[4,2.34],[3.9,1]],"id":66314580}],"con":true,"img":false}]}
{"op":"mcm","clk":"11541437242","pt":1719505745410,"mc":[{"id":"1.230180133","rc":[{"atl":[[9.6,0],[9.2,12.5]],"id":67487134}],"con":true,"img":false}]}
{"op":"mcm","clk":"11541437249","pt":1719505745499,"mc":[{"id":"1.230180133","rc":[{"atb":[[1.41,1],[1.47,4.12]],"id":66314580},{"atl":[[4.1,5],[3.9,4.35]],"id":66314580}],"con":true,"img":false}]}
{"op":"mcm","clk":"11541437265","pt":1719505745706,"mc":[{"id":"1.230180133","rc":[{"atl":[[4.2,0]],"id":66314580}],"con":true,"img":false}]}
{"op":"mcm","clk":"11541437284","pt":1719505745912,"mc":[{"id":"1.230180133","rc":[{"atl":[[4.2,2.07]],"id":66314580}],"con":true,"img":false}]}
{"op":"mcm","clk":"11541437420","pt":1719505747105,"mc":[{"id":"1.230180133","rc":[{"atl":[[9.6,1],[10.5,0]],"id":67487134},{"atl":[[4,3.34],[3.9,3.35]],"id":66314580},{"atb":[[1.97,10],[1.96,0]],"id":70086038},{"atl":[[3.6,0],[3.7,6]],"id":64618726},{"atl":[[7.2,2.25],[7.4,1]],"id":67130716}],"con":true,"img":false}]}
{"op":"mcm","clk":"11541437439","pt":1719505747308,"mc":[{"id":"1.230180133","rc":[{"atl":[[4.2,0]],"id":66314580}],"con":true,"img":false}]}
{"op":"mcm","clk":"11541437456","pt":1719505747512,"mc":[{"id":"1.230180133","rc":[{"atl":[[4.1,6.56]],"id":66314580}],"con":true,"img":false}]}
{"op":"mcm","clk":"11541437619","pt":1719505749534,"mc":[{"id":"1.230180133","rc":[{"atl":[[10.5,2.5],[7.4,6]],"id":67130716}],"con":true,"img":false}]}
{"op":"mcm","clk":"11541437728","pt":1719505750722,"mc":[{"id":"1.230180133","rc":[{"atl":[[10,0.52]],"id":53826530}],"con":true,"img":false}]}
{"op":"mcm","clk":"11541437735","pt":1719505750821,"mc":[{"id":"1.230180133","rc":[{"atb":[[1.04,0.52]],"id":53826530}],"con":true,"img":false}]}
{"op":"mcm","clk":"11541437745","pt":1719505750936,"mc":[{"id":"1.230180133","rc":[{"atb":[[1.04,0.26]],"id":53826530}],"con":true,"img":false}]}
{"op":"mcm","clk":"11541437760","pt":1719505751034,"mc":[{"id":"1.230180133","rc":[{"atb":[[1.04,0]],"id":53826530}],"con":true,"img":false}]}
{"op":"mcm","clk":"11541437771","pt":1719505751093,"mc":[{"id":"1.230180133","rc":[{"atb":[[3,0.26]],"id":53826530}],"con":true,"img":false}]}
{"op":"mcm","clk":"11541437897","pt":1719505752195,"mc":[{"id":"1.230180133","rc":[{"atb":[[1.08,50]],"id":67487134},{"atb":[[1.08,50]],"id":66314580},{"atb":[[1.08,50]],"id":53826530},{"atb":[[1.08,50]],"id":70086038},{"atb":[[1.08,50]],"id":64618726},{"atb":[[1.08,50]],"id":67130716}],"con":true,"img":false}]}
{"op":"mcm","clk":"11541437998","pt":1719505753323,"mc":[{"id":"1.230180133","rc":[{"atb":[[2.82,5.62]],"id":67487134},{"atl":[[8.2,6.46]],"id":67487134},{"atb":[[1.47,7.87]],"id":66314580},{"atl":[[3.8,4.59]],"id":66314580},{"atb":[[3,3.48],[3.05,2.15]],"id":53826530},{"atl":[[10,3.74]],"id":53826530},{"atb":[[2.06,5.96]],"id":70086038},{"atb":[[1.95,4.9]],"id":64618726},{"atl":[[3.5,5.74]],"id":64618726},{"atb":[[2.4,3.56]],"id":67130716},{"atl":[[7,4.4]],"id":67130716}],"con":true,"img":false}]}
{"op":"mcm","clk":"11541438005","pt":1719505753431,"mc":[{"id":"1.230180133","rc":[{"atb":[[2.44,0]],"id":67487134},{"atl":[[10,10]],"id":67487134},{"atb":[[1.46,10.74],[1.42,5],[1.47,5.75]],"id":66314580},{"atl":[[4,1]],"id":66314580},{"atb":[[3,5.48],[2.26,0],[2.96,2.5]],"id":53826530},{"atb":[[1.38,0]],"id":64618726},{"atl":[[3.55,2.53]],"id":64618726},{"atb":[[1.98,0]],"id":67130716},{"atl":[[7.2,0]],"id":67130716}],"con":true,"img":false}]}
{"op":"mcm","clk":"11541438018","pt":1719505753532,"mc":[{"id":"1.230180133","rc":[{"atl":[[11.5,0]],"id":53826530},{"atb":[[1.47,0]],"id":70086038}],"con":true,"img":false}]}
{"op":"mcm","clk":"11541438125","pt":1719505754523,"mc":[{"id":"1.230180133","rc":[{"atb":[[2.8,4.5]],"id":67487134}],"con":true,"img":false}]}
{"op":"mcm","clk":"11541438137","pt":1719505754627,"mc":[{"id":"1.230180133","rc":[{"atb":[[2.8,0],[2.84,2],[2.78,12.62]],"id":67487134},{"atl":[[10.5,12.91],[7.4,1]],"id":67130716}],"con":true,"img":false}]}
{"op":"mcm","clk":"11541438147","pt":1719505754723,"mc":[{"id":"1.230180133","rc":[{"atb":[[2.8,10],[2.78,2.5]],"id":67487134}],"con":true,"img":false}]}
{"op":"mcm","clk":"11541438182","pt":1719505755034,"mc":[{"id":"1.230180133","rc":[{"atb":[[2.38,0]],"id":67130716}],"con":true,"img":false}]}
{"op":"mcm","clk":"11541438191","pt":1719505755136,"mc":[{"id":"1.230180133","rc":[{"atb":[[2.42,2]],"id":67130716}],"con":true,"img":false}]}
{"op":"mcm","clk":"11541438221","pt":1719505755508,"mc":[{"id":"1.230180133","rc":[{"atb":[[2.98,0]],"id":53826530},{"atl":[[3.55,0]],"id":64618726}],"con":true,"img":false}]}
{"op":"mcm","clk":"11541438229","pt":1719505755607,"mc":[{"id":"1.230180133","rc":[{"atb":[[3.1,2]],"id":53826530},{"atl":[[3.7,1],[4.7,14.25]],"id":64618726}],"con":true,"img":false}]}
{"op":"mcm","clk":"11541438257","pt":1719505755926,"mc":[{"id":"1.230180133","rc":[{"atb":[[1.93,0]],"id":64618726}],"con":true,"img":false}]}
{"op":"mcm","clk":"11541438266","pt":1719505756026,"mc":[{"id":"1.230180133","rc":[{"atb":[[1.96,2]],"id":64618726}],"con":true,"img":false}]}
{"op":"mcm","clk":"11541438298","pt":1719505756424,"mc":[{"id":"1.230180133","rc":[{"atb":[[1.98,0],[2.04,2.11]],"id":70086038},{"atb":[[1.87,0],[1.91,2.11]],"id":64618726},{"atb":[[1.46,0],[2.34,2.11]],"id":67130716}],"con":true,"img":false}]}
{"op":"mcm","clk":"11541438322","pt":1719505756740,"mc":[{"id":"1.230180133","rc":[{"atb":[[3.15,2.06]],"id":53826530}],"con":true,"img":false}]}
{"op":"mcm","clk":"11541438491","pt":1719505758525,"mc":[{"id":"1.230180133","rc":[{"atb":[[3.1,0]],"id":53826530}],"con":true,"img":false}]}
{"op":"mcm","clk":"11541438501","pt":1719505758626,"mc":[{"id":"1.230180133","rc":[{"atb":[[3.2,2]],"id":53826530}],"con":true,"img":false}]}
{"op":"mcm","clk":"11541438677","pt":1719505760441,"mc":[{"id":"1.230180133","rc":[{"atb":[[3,3.48],[3.15,6.06]],"id":53826530}],"con":true,"img":false}]}
{"op":"mcm","clk":"11541438870","pt":1719505762233,"mc":[{"id":"1.230180133","rc":[{"atl":[[4.1,5]],"id":66314580}],"con":true,"img":false}]}
{"op":"mcm","clk":"11541438937","pt":1719505763017,"mc":[{"id":"1.230180133","rc":[{"atb":[[2.82,11.24]],"id":67487134},{"atl":[[9.6,0],[8.6,1]],"id":67487134},{"atl":[[4,0],[3.65,1]],"id":66314580},{"atb":[[3.15,4]],"id":53826530},{"atb":[[1.99,15],[1.97,0]],"id":70086038},{"atl":[[4.5,8.5],[4.2,0]],"id":70086038},{"atl":[[3.6,1],[3.7,0]],"id":64618726},{"atl":[[8,1],[7.4,0]],"id":67130716}],"con":true,"img":false}]}
{"op":"mcm","clk":"11541438945","pt":1719505763123,"mc":[{"id":"1.230180133","rc":[{"atb":[[2.82,5.62],[2.8,0],[2.62,20]],"id":67487134},{"atl":[[9.2,5],[8.4,15.44]],"id":67487134},{"atb":[[1.99,5],[2.02,10]],"id":70086038},{"atb":[[1.87,10],[1.81,0]],"id":64618726},{"atl":[[3.7,10],[4.7,2.5]],"id":64618726},{"atl":[[10.5,2.5],[7.8,8.82]],"id":67130716}],"con":true,"img":false}]}
{"op":"mcm","clk":"11541438954","pt":1719505763223,"mc":[{"id":"1.230180133","rc":[{"atb":[[1.99,16.92],[2.02,0]],"id":70086038},{"atl":[[4.5,3.5],[4.9,15]],"id":70086038},{"atb":[[2,7.12],[2.18,0]],"id":67130716},{"atl":[[8,14.23]],"id":67130716}],"con":true,"img":false}]}
{"op":"mcm","clk":"11541438964","pt":1719505763333,"mc":[{"id":"1.230180133","rc":[{"atb":[[2.34,7.11]],"id":67130716},{"atl":[[7.8,0]],"id":67130716}],"con":true,"img":false}]}
{"op":"mcm","clk":"11541438976","pt":1719505763436,"mc":[{"id":"1.230180133","rc":[{"atb":[[2,0]],"id":67130716}],"con":true,"img":false}]}
{"op":"mcm","clk":"11541438987","pt":1719505763543,"mc":[{"id":"1.230180133","rc":[{"atl":[[8,1],[10.5,13.03]],"id":67130716}],"con":true,"img":false}]}
{"op":"mcm","clk":"11541439199","pt":1719505766021,"mc":[{"id":"1.230180133","rc":[{"atl":[[10,3.22]],"id":53826530}],"con":true,"img":false}]}
{"op":"mcm","clk":"11541439228","pt":1719505766428,"mc":[{"id":"1.230180133","rc":[{"atb":[[3,3.22]],"id":53826530}],"con":true,"img":false}]}
{"op":"mcm","clk":"11541439367","pt":1719505768178,"mc":[{"id":"1.230180133","rc":[{"atb":[[2.84,7.72]],"id":67487134},{"atl":[[3.6,5.32]],"id":66314580},{"atb":[[3.25,7.15]],"id":53826530},{"atb":[[1.96,7.55]],"id":64618726}],"con":true,"img":false}]}
{"op":"mcm","clk":"11541439374","pt":1719505768232,"mc":[{"id":"1.230180133","rc":[{"atb":[[2.82,0]],"id":67487134},{"atl":[[8.6,14.16],[8.4,2.5]],"id":67487134},{"atl":[[3.8,4.19],[3.9,0]],"id":66314580},{"atb":[[3,0],[3.05,0]],"id":53826530},{"atb":[[1.95,0],[1.87,0],[1.81,9.8]],"id":64618726},{"atb":[[2.42,6.54]],"id":67130716}],"con":true,"img":false}]}
{"op":"mcm","clk":"11541439382","pt":1719505768333,"mc":[{"id":"1.230180133","rc":[{"atb":[[2.4,0]],"id":67130716}],"con":true,"img":false}]}
{"op":"mcm","clk":"11541439431","pt":1719505768954,"mc":[{"id":"1.230180133","rc":[{"atl":[[3.8,3.35],[3.55,0.84]],"id":66314580}],"con":true,"img":false}]}
{"op":"mcm","clk":"11541439440","pt":1719505769055,"mc":[{"id":"1.230180133","rc":[{"atl":[[3.8,0],[3.65,7.17]],"id":66314580}],"con":true,"img":false}]}
{"op":"mcm","clk":"11541439676","pt":1719505771439,"mc":[{"id":"1.230180133","rc":[{"atl":[[3.55,3.38]],"id":66314580}],"con":true,"img":false}]}
{"op":"mcm","clk":"11541439784","pt":1719505772727,"mc":[{"id":"1.230180133","rc":[{"atb":[[3.2,0]],"id":53826530}],"con":true,"img":false}]}
{"op":"mcm","clk":"11541439797","pt":1719505772835,"mc":[{"id":"1.230180133","rc":[{"atb":[[3.15,0],[2.96,13.65],[3.3,2]],"id":53826530}],"con":true,"img":false}]}
{"op":"mcm","clk":"11541440052","pt":1719505775872,"mc":[{"id":"1.230180133","rc":[{"atl":[[3.5,5.32],[3.65,1]],"id":66314580}],"con":true,"img":false}]}
{"op":"mcm","clk":"11541440098","pt":1719505776342,"mc":[{"id":"1.230180133","rc":[{"atl":[[3.45,0.84]],"id":66314580}],"con":true,"img":false}]}
{"op":"mcm","clk":"11541440248","pt":1719505777878,"mc":[{"id":"1.230180133","rc":[{"atl":[[10,0]],"id":53826530},{"trd":[[10,6.44]],"ltp":10.0,"tv":6.44,"id":53826530}],"con":true,"img":false}]}
{"op":"mcm","clk":"11541440257","pt":1719505778008,"mc":[{"id":"1.230180133","rc":[{"atb":[[3.35,2.06]],"id":53826530},{"atl":[[11.5,8.1],[12,1],[9.8,4.29]],"id":53826530}],"con":true,"img":false}]}
{"op":"mcm","clk":"11541440266","pt":1719505778055,"mc":[{"id":"1.230180133","rc":[{"atb":[[1.05,0.52]],"id":53826530},{"atl":[[11.5,0],[12,9.1],[9.8,4.81]],"id":53826530}],"con":true,"img":false}]}
{"op":"mcm","clk":"11541440273","pt":1719505778158,"mc":[{"id":"1.230180133","rc":[{"atl":[[9.8,0.52]],"id":53826530}],"con":true,"img":false}]}
{"op":"mcm","clk":"11541440277","pt":1719505778262,"mc":[{"id":"1.230180133","rc":[{"atl":[[3.55,0.84]],"id":66314580},{"atb":[[1.05,0.22]],"id":53826530},{"atl":[[10,3.42]],"id":53826530}],"con":true,"img":false}]}
{"op":"mcm","clk":"11541440286","pt":1719505778364,"mc":[{"id":"1.230180133","rc":[{"atl":[[11.5,9.1],[12,1]],"id":53826530}],"con":true,"img":false}]}
{"op":"mcm","clk":"11541440293","pt":1719505778467,"mc":[{"id":"1.230180133","rc":[{"atb":[[1.05,0]],"id":53826530}],"con":true,"img":false}]}
{"op":"mcm","clk":"11541440298","pt":1719505778571,"mc":[{"id":"1.230180133","rc":[{"atb":[[3.35,2.28]],"id":53826530}],"con":true,"img":false}]}
{"op":"mcm","clk":"11541440335","pt":1719505779144,"mc":[{"id":"1.230180133","rc":[{"atb":[[3.3,0]],"id":53826530}],"con":true,"img":false}]}
{"op":"mcm","clk":"11541440360","pt":1719505779298,"mc":[{"id":"1.230180133","rc":[{"atb":[[3.4,2]],"id":53826530}],"con":true,"img":false}]}
{"op":"mcm","clk":"11541440393","pt":1719505779654,"mc":[{"id":"1.230180133","rc":[{"atb":[[3.15,10],[2.96,2.5]],"id":53826530}],"con":true,"img":false}]}
{"op":"mcm","clk":"11541440488","pt":1719505780790,"mc":[{"id":"1.230180133","rc":[{"atl":[[12,0]],"id":53826530}],"con":true,"img":false}]}
{"op":"mcm","clk":"11541440496","pt":1719505780897,"mc":[{"id":"1.230180133","rc":[{"atl":[[3.45,3.38]],"id":66314580}],"con":true,"img":false}]}
{"op":"mcm","clk":"11541440507","pt":1719505780951,"mc":[{"id":"1.230180133","rc":[{"atl":[[3.55,7.01],[3.5,0]],"id":66314580}],"con":true,"img":false}]}
{"op":"mcm","clk":"11541440547","pt":1719505781459,"mc":[{"id":"1.230180133","rc":[{"atl":[[3.55,6.17]],"id":66314580}],"con":true,"img":false}]}
{"op":"mcm","clk":"11541440656","pt":1719505782655,"mc":[{"id":"1.230180133","rc":[{"atl":[[3.4,8.3]],"id":66314580},{"atb":[[3.45,5.99]],"id":53826530}],"con":true,"img":false}]}
{"op":"mcm","clk":"11541440675","pt":1719505782862,"mc":[{"id":"1.230180133","rc":[{"atl":[[3.6,0]],"id":66314580},{"atb":[[3.25,0]],"id":53826530}],"con":true,"img":false}]}
{"op":"mcm","clk":"11541440704","pt":1719505783176,"mc":[{"id":"1.230180133","rc":[{"atb":[[3.35,0.22]],"id":53826530}],"con":true,"img":false}]}
{"op":"mcm","clk":"11541440731","pt":1719505783484,"mc":[{"id":"1.230180133","rc":[{"atl":[[3.35,0.84]],"id":66314580}],"con":true,"img":false}]}
{"op":"mcm","clk":"11541440835","pt":1719505784572,"mc":[{"id":"1.230180133","rc":[{"atl":[[3.45,0.84]],"id":66314580}],"con":true,"img":false}]}
{"op":"mcm","clk":"11541440873","pt":1719505784987,"mc":[{"id":"1.230180133","rc":[{"atb":[[3.4,0]],"id":53826530}],"con":true,"img":false}]}
{"op":"mcm","clk":"11541440884","pt":1719505785045,"mc":[{"id":"1.230180133","rc":[{"atb":[[3.5,2]],"id":53826530}],"con":true,"img":false}]}
{"op":"mcm","clk":"11541440988","pt":1719505786286,"mc":[{"id":"1.230180133","rc":[{"atl":[[3.35,3.38]],"id":66314580}],"con":true,"img":false}]}
{"op":"mcm","clk":"11541441046","pt":1719505786962,"mc":[{"id":"1.230180133","rc":[{"atl":[[3.45,0]],"id":66314580}],"con":true,"img":false}]}
{"op":"mcm","clk":"11541441107","pt":1719505787676,"mc":[{"id":"1.230180133","rc":[{"atl":[[3.4,15.08],[3.55,0]],"id":66314580}],"con":true,"img":false}]}
{"op":"mcm","clk":"11541441285","pt":1719505790100,"mc":[{"id":"1.230180133","rc":[{"atl":[[9.8,0]],"id":53826530},{"trd":[[9.8,1.05]],"ltp":9.8,"tv":1.05,"id":53826530}],"con":true,"img":false}]}
{"op":"mcm","clk":"11541441490","pt":1719505792175,"mc":[{"id":"1.230180133","rc":[{"atb":[[3.55,2.06]],"id":53826530}],"con":true,"img":false}]}
{"op":"mcm","clk":"11541441621","pt":1719505793370,"mc":[{"id":"1.230180133","rc":[{"atb":[[3.5,0]],"id":53826530}],"con":true,"img":false}]}
{"op":"mcm","clk":"11541441631","pt":1719505793480,"mc":[{"id":"1.230180133","rc":[{"atb":[[3.6,2]],"id":53826530}],"con":true,"img":false}]}
{"op":"mcm","clk":"11541441666","pt":1719505793899,"mc":[{"id":"1.230180133","rc":[{"atb":[[3.35,0]],"id":53826530}],"con":true,"img":false}]}
{"op":"mcm","clk":"11541441938","pt":1719505796678,"mc":[{"id":"1.230180133","rc":[{"spn":5.52,"spf":"NaN","id":67487134},{"atl":[[3.35,6.77],[3.4,8.3]],"id":66314580},{"spn":1.59,"spf":1.0,"id":66314580},{"atb":[[3.55,0]],"id":53826530},{"atl":[[11.5,0],[12,6.84]],"id":53826530},{"spn":6.8,"spf":"NaN","id":53826530},{"atb":[[2,10],[1.99,5]],"id":70086038},{"spn":3.08,"spf":"NaN","id":70086038},{"spn":2.73,"spf":"NaN","id":64618726},{"atb":[[2.36,15.58],[2.34,2.11]],"id":67130716},{"spn":4.71,"spf":"NaN","id":67130716}],"con":true,"img":false}]}
{"op":"mcm","clk":"11541441968","pt":1719505796980,"mc":[{"id":"1.230180133","rc":[{"atl":[[3.3,9.4]],"id":66314580},{"atb":[[3.65,9.14]],"id":53826530}],"con":true,"img":false}]}
{"op":"mcm","clk":"11541441975","pt":1719505797087,"mc":[{"id":"1.230180133","rc":[{"atl":[[3.4,0]],"id":66314580},{"atb":[[2.84,10],[3.45,0],[3.15,0]],"id":53826530}],"con":true,"img":false}]}
{"op":"mcm","clk":"11541441982","pt":1719505797191,"mc":[{"id":"1.230180133","rc":[{"atb":[[3.35,11.98],[2.84,0]],"id":53826530}],"con":true,"img":false}]}
{"op":"mcm","clk":"11541442006","pt":1719505797394,"mc":[{"id":"1.230180133","rc":[{"atb":[[2.54,12.72],[2.42,0],[2.62,10]],"id":67487134},{"atl":[[8.6,13.16],[8.4,3.5]],"id":67487134},{"atl":[[3.25,0.84],[3.55,1],[3.65,0]],"id":66314580},{"atl":[[8,0],[8.2,1]],"id":67130716}],"con":true,"img":false}]}
{"op":"mcm","clk":"11541442017","pt":1719505797497,"mc":[{"id":"1.230180133","rc":[{"atl":[[8,8.82]],"id":67130716}],"con":true,"img":false}]}
{"op":"mcm","clk":"11541442024","pt":1719505797602,"mc":[{"id":"1.230180133","rc":[{"atl":[[8,0],[10.5,2.5],[8.2,14.23]],"id":67130716}],"con":true,"img":false}]}
{"op":"mcm","clk":"11541442081","pt":1719505798179,"mc":[{"id":"1.230180133","rc":[{"atl":[[9.2,0],[10,0],[6.8,2.5],[7.6,5]],"id":67487134},{"atb":[[1.46,8.24],[1.53,5],[1.57,2.5],[1.42,0],[1.49,10],[1.38,0]],"id":66314580},{"atb":[[2.8,0],[3.25,2.5],[3.05,5],[2.88,0],[2.96,0]],"id":53826530},{"atb":[[1.95,0],[2.14,2.5]],"id":70086038},{"atl":[[4.3,2.5],[5.5,0]],"id":64618726},{"atb":[[2.64,2.5],[2.48,10],[2.36,13.08],[2.56,5],[2.28,0],[2.2,0]],"id":67130716}],"con":true,"img":false}]}
{"op":"mcm","clk":"11541442093","pt":1719505798282,"mc":[{"id":"1.230180133","rc":[{"atl":[[8,5.62],[8.6,0],[8.2,12.93]],"id":67487134},{"atb":[[1.57,11.34]],"id":66314580},{"atl":[[4.5,0],[3.85,0],[4.1,0]],"id":66314580},{"atb":[[3.6,0]],"id":53826530},{"atb":[[2.14,7]],"id":70086038},{"atb":[[2.64,9.56]],"id":67130716},{"atl":[[9,5],[10.5,0],[8.2,16.73],[12.5,0],[9.8,10],[14.5,0]],"id":67130716}],"con":true,"img":false}]}
{"op":"mcm","clk":"11541442101","pt":1719505798385,"mc":[{"id":"1.230180133","rc":[{"atl":[[3.35,4.23]],"id":66314580},{"atb":[[3.7,2]],"id":53826530}],"con":true,"img":false}]}
{"op":"mcm","clk":"11541442109","pt":1719505798490,"mc":[{"id":"1.230180133","rc":[{"atl":[[8.2,7.31]],"id":67487134},{"atb":[[1.47,2]],"id":66314580},{"atb":[[2.06,2.5]],"id":70086038},{"atb":[[2.42,2]],"id":67130716}],"con":true,"img":false}]}
{"op":"mcm","clk":"11541442144","pt":1719505798898,"mc":[{"id":"1.230180133","rc":[{"atl":[[8.2,6.47],[6.6,0.84]],"id":67487134}],"con":true,"img":false}]}
{"op":"mcm","clk":"11541442152","pt":1719505799002,"mc":[{"id":"1.230180133","rc":[{"atl":[[8.2,0],[7.6,10.62]],"id":67487134}],"con":true,"img":false}]}
{"op":"mcm","clk":"11541442199","pt":1719505799473,"mc":[{"id":"1.230180133","rc":[{"atb":[[1.47,0]],"id":66314580}],"con":true,"img":false}]}
{"op":"mcm","clk":"11541442206","pt":1719505799579,"mc":[{"id":"1.230180133","rc":[{"atb":[[1.58,2]],"id":66314580}],"con":true,"img":false}]}
{"op":"mcm","clk":"11541442229","pt":1719505799883,"mc":[{"id":"1.230180133","rc":[{"atb":[[2.42,0]],"id":67130716}],"con":true,"img":false}]}
{"op":"mcm","clk":"11541442235","pt":1719505799983,"mc":[{"id":"1.230180133","rc":[{"atb":[[2.66,2]],"id":67130716}],"con":true,"img":false}]}
{"op":"mcm","clk":"11541442322","pt":1719505800784,"mc":[{"id":"1.230180133","rc":[{"atl":[[3.35,6.73],[3.55,6]],"id":66314580}],"con":true,"img":false}]}
{"op":"mcm","clk":"11541442344","pt":1719505801000,"mc":[{"id":"1.230180133","rc":[{"atl":[[3.25,3.38]],"id":66314580}],"con":true,"img":false}]}
{"op":"mcm","clk":"11541442401","pt":1719505801500,"mc":[{"id":"1.230180133","rc":[{"atl":[[3.35,5.89]],"id":66314580}],"con":true,"img":false}]}
{"op":"mcm","clk":"11541442430","pt":1719505801772,"mc":[{"id":"1.230180133","rc":[{"atl":[[13,8.33]],"id":53826530}],"con":true,"img":false}]}
{"op":"mcm","clk":"11541442442","pt":1719505801884,"mc":[{"id":"1.230180133","rc":[{"atl":[[12,0]],"id":53826530}],"con":true,"img":false}]}
{"op":"mcm","clk":"11541442492","pt":1719505802295,"mc":[{"id":"1.230180133","rc":[{"atb":[[1.02,1.7]],"id":67487134},{"atl":[[1000,1.7]],"id":67487134},{"atb":[[1.01,1.7]],"id":66314580},{"atl":[[1000,1.87]],"id":66314580},{"atb":[[1.02,18.18]],"id":67130716},{"atl":[[1000,1.87]],"id":67130716}],"con":true,"img":false}]}
{"op":"mcm","clk":"11541442514","pt":1719505802491,"mc":[{"id":"1.230180133","rc":[{"atb":[[1.02,0.15]],"id":67487134},{"atl":[[1000,0.05]],"id":67487134},{"atb":[[1.01,0.48]],"id":66314580},{"atl":[[1000,0.3]],"id":66314580},{"atl":[[10,0]],"id":53826530},{"trd":[[10,13.28]],"ltp":10.0,"tv":13.28,"id":53826530},{"atb":[[1.02,16.65]],"id":67130716},{"atl":[[1000,0.22]],"id":67130716}],"con":true,"img":false}]}
{"op":"mcm","clk":"11541442523","pt":1719505802594,"mc":[{"id":"1.230180133","rc":[{"atl":[[10,8.89]],"id":53826530}],"con":true,"img":false}]}
{"op":"mcm","clk":"11541442534","pt":1719505802701,"mc":[{"id":"1.230180133","rc":[{"atb":[[1.02,0]],"id":67487134},{"atl":[[1000,0]],"id":67487134},{"atb":[[1.01,0]],"id":66314580},{"atl":[[1000,0.17]],"id":66314580},{"atb":[[1.02,16.48]],"id":67130716},{"atl":[[9,17.5],[1000,0.17]],"id":67130716}],"con":true,"img":false}]}
{"op":"mcm","clk":"11541442547","pt":1719505802805,"mc":[{"id":"1.230180133","rc":[{"atb":[[2.86,0.15]],"id":67487134},{"atl":[[6.6,0.89]],"id":67487134},{"atb":[[1.59,0.48]],"id":66314580},{"atl":[[3.2,0.12]],"id":66314580},{"atb":[[2.68,0.16]],"id":67130716},{"atl":[[8.2,3.5],[6.8,0.04]],"id":67130716}],"con":true,"img":false}]}
{"op":"mcm","clk":"11541442560","pt":1719505802903,"mc":[{"id":"1.230180133","rc":[{"atl":[[6.8,4.16]],"id":67130716}],"con":true,"img":false}]}
{"op":"mcm","clk":"11541442577","pt":1719505803110,"mc":[{"id":"1.230180133","rc":[{"atl":[[7,0.84]],"id":67130716}],"con":true,"img":false}]}
{"op":"mcm","clk":"11541442587","pt":1719505803174,"mc":[{"id":"1.230180133","rc":[{"atb":[[2.08,0]],"id":67487134}],"con":true,"img":false}]}
{"op":"mcm","clk":"11541442598","pt":1719505803276,"mc":[{"id":"1.230180133","rc":[{"atl":[[3.35,2.5],[3.25,9.27]],"id":66314580},{"atb":[[2,0],[2.02,5]],"id":70086038}],"con":true,"img":false}]}
{"op":"mcm","clk":"11541442609","pt":1719505803384,"mc":[{"id":"1.230180133","rc":[{"atb":[[2.86,2.09]],"id":67487134},{"atl":[[3.3,15.4]],"id":66314580},{"atb":[[3.7,3.94]],"id":53826530},{"atb":[[2.16,1.94]],"id":70086038},{"atb":[[2.68,2.11]],"id":67130716}],"con":true,"img":false}]}
{"op":"mcm","clk":"11541442619","pt":1719505803483,"mc":[{"id":"1.230180133","rc":[{"atb":[[2.86,5.84]],"id":67487134},{"atl":[[3.25,3.38]],"id":66314580},{"atl":[[6.6,0.84]],"id":67130716}],"con":true,"img":false}]}
{"op":"mcm","clk":"11541442629","pt":1719505803587,"mc":[{"id":"1.230180133","rc":[{"atb":[[2.84,2]],"id":67487134}],"con":true,"img":false}]}
{"op":"mcm","clk":"11541442692","pt":1719505804201,"mc":[{"id":"1.230180133","rc":[{"atl":[[9,5],[7,5.86]],"id":67130716}],"con":true,"img":false}]}
{"op":"mcm","clk":"11541442716","pt":1719505804412,"mc":[{"id":"1.230180133","rc":[{"atl":[[3.5,5.39]],"id":66314580}],"con":true,"img":false}]}
{"op":"mcm","clk":"11541442736","pt":1719505804622,"mc":[{"id":"1.230180133","rc":[{"atb":[[2.84,0]],"id":67487134}],"con":true,"img":false}]}
{"op":"mcm","clk":"11541442747","pt":1719505804678,"mc":[{"id":"1.230180133","rc":[{"atb":[[2.88,2]],"id":67487134}],"con":true,"img":false}]}
{"op":"mcm","clk":"11541442783","pt":1719505805005,"mc":[{"id":"1.230180133","rc":[{"atb":[[2.66,0]],"id":67130716}],"con":true,"img":false}]}
{"op":"mcm","clk":"11541442793","pt":1719505805097,"mc":[{"id":"1.230180133","rc":[{"atb":[[2.7,2]],"id":67130716}],"con":true,"img":false}]}
{"op":"mcm","clk":"11541442805","pt":1719505805203,"mc":[{"id":"1.230180133","rc":[{"atb":[[2.12,2.11]],"id":70086038}],"con":true,"img":false}]}
{"op":"mcm","clk":"11541442819","pt":1719505805307,"mc":[{"id":"1.230180133","rc":[{"atb":[[2.04,0]],"id":70086038}],"con":true,"img":false}]}
{"op":"mcm","clk":"11541442905","pt":1719505806199,"mc":[{"id":"1.230180133","rc":[{"atb":[[3.75,3.04]],"id":53826530}],"con":true,"img":false}]}
{"op":"mcm","clk":"11541443034","pt":1719505807400,"mc":[{"id":"1.230180133","rc":[{"atb":[[3.7,1.94]],"id":53826530}],"con":true,"img":false}]}
{"op":"mcm","clk":"11541443045","pt":1719505807507,"mc":[{"id":"1.230180133","rc":[{"atb":[[3.8,2]],"id":53826530}],"con":true,"img":false}]}
{"op":"mcm","clk":"11541443230","pt":1719505809212,"mc":[{"id":"1.230180133","rc":[{"atb":[[3.7,0]],"id":53826530},{"atb":[[2.16,0]],"id":70086038}],"con":true,"img":false}]}
{"op":"mcm","clk":"11541443239","pt":1719505809317,"mc":[{"id":"1.230180133","rc":[{"atl":[[3.5,0]],"id":66314580}],"con":true,"img":false}]}
{"op":"mcm","clk":"11541443256","pt":1719505809418,"mc":[{"id":"1.230180133","rc":[{"atb":[[3.8,3.94]],"id":53826530},{"atb":[[2.16,1.94]],"id":70086038}],"con":true,"img":false}]}
{"op":"mcm","clk":"11541443290","pt":1719505809685,"mc":[{"id":"1.230180133","rc":[{"atl":[[3.45,1.57]],"id":66314580}],"con":true,"img":false}]}
{"op":"mcm","clk":"11541443312","pt":1719505809888,"mc":[{"id":"1.230180133","rc":[{"atl":[[3.25,6.77],[3.3,9.4]],"id":66314580}],"con":true,"img":false}]}
{"op":"mcm","clk":"11541443325","pt":1719505810005,"mc":[{"id":"1.230180133","rc":[{"atl":[[3.45,0],[3.25,3.38],[3.3,12.92]],"id":66314580}],"con":true,"img":false}]}
{"op":"mcm","clk":"11541443428","pt":1719505811017,"mc":[{"id":"1.230180133","rc":[{"atl":[[3.2,4.16]],"id":66314580},{"atb":[[3.85,11.18]],"id":53826530}],"con":true,"img":false}]}
{"op":"mcm","clk":"11541443449","pt":1719505811224,"mc":[{"id":"1.230180133","rc":[{"atl":[[3.3,3.52]],"id":66314580},{"atb":[[3.65,0]],"id":53826530}],"con":true,"img":false}]}
{"op":"mcm","clk":"11541443471","pt":1719505811392,"mc":[{"id":"1.230180133","rc":[{"atl":[[3.15,0.84]],"id":66314580}],"con":true,"img":false}]}
{"op":"mcm","clk":"11541443544","pt":1719505812118,"mc":[{"id":"1.230180133","rc":[{"atb":[[3.75,0]],"id":53826530}],"con":true,"img":false}]}
{"op":"mcm","clk":"11541443559","pt":1719505812209,"mc":[{"id":"1.230180133","rc":[{"atl":[[6.6,4.64]],"id":67487134},{"atb":[[1.58,6.04]],"id":66314580},{"atb":[[3.8,0]],"id":53826530},{"atb":[[2.16,4.22]],"id":70086038}],"con":true,"img":false}]}
{"op":"mcm","clk":"11541443571","pt":1719505812311,"mc":[{"id":"1.230180133","rc":[{"atb":[[3.9,2]],"id":53826530},{"atb":[[2.7,6.72]],"id":67130716}],"con":true,"img":false}]}
{"op":"mcm","clk":"11541443580","pt":1719505812416,"mc":[{"id":"1.230180133","rc":[{"atl":[[8,0],[7.6,5],[7,7.15]],"id":67487134},{"atb":[[1.57,2.5]],"id":66314580},{"atb":[[3.9,3.94]],"id":53826530},{"atb":[[2.16,6.16],[2.14,2.5]],"id":70086038}],"con":true,"img":false}]}
{"op":"mcm","clk":"11541443590","pt":1719505812520,"mc":[{"id":"1.230180133","rc":[{"atb":[[2.64,2.5]],"id":67130716}],"con":true,"img":false}]}
{"op":"mcm","clk":"11541443631","pt":1719505812891,"mc":[{"id":"1.230180133","rc":[{"atl":[[3.35,10.25]],"id":66314580}],"con":true,"img":false}]}
{"op":"mcm","clk":"11541443694","pt":1719505813528,"mc":[{"id":"1.230180133","rc":[{"atl":[[3.25,0.84]],"id":66314580}],"con":true,"img":false}]}
{"op":"mcm","clk":"11541443857","pt":1719505815210,"mc":[{"id":"1.230180133","rc":[{"atb":[[2.68,0.16]],"id":67130716}],"con":true,"img":false}]}
{"op":"mcm","clk":"11541443875","pt":1719505815413,"mc":[{"id":"1.230180133","rc":[{"atb":[[2.72,1.94]],"id":67130716}],"con":true,"img":false}]}
{"op":"mcm","clk":"11541443935","pt":1719505816037,"mc":[{"id":"1.230180133","rc":[{"atl":[[3.35,2.5]],"id":66314580}],"con":true,"img":false}]}
{"op":"mcm","clk":"11541443968","pt":1719505816317,"mc":[{"id":"1.230180133","rc":[{"atl":[[3.3,14.36]],"id":66314580}],"con":true,"img":false}]}
{"op":"mcm","clk":"11541443997","pt":1719505816618,"mc":[{"id":"1.230180133","rc":[{"atl":[[3.3,3.52]],"id":66314580}],"con":true,"img":false}]}
{"op":"mcm","clk":"11541444012","pt":1719505816813,"mc":[{"id":"1.230180133","rc":[{"atl":[[6.6,5.43]],"id":67130716}],"con":true,"img":false}]}
{"op":"mcm","clk":"11541444024","pt":1719505816919,"mc":[{"id":"1.230180133","rc":[{"atl":[[3.25,9.04]],"id":66314580},{"atl":[[6.8,0.04]],"id":67130716}],"con":true,"img":false}]}
{"op":"mcm","clk":"11541444033","pt":1719505817019,"mc":[{"id":"1.230180133","rc":[{"atl":[[3.25,14.06],[3.3,0]],"id":66314580}],"con":true,"img":false}]}
{"op":"mcm","clk":"11541444066","pt":1719505817336,"mc":[{"id":"1.230180133","rc":[{"atb":[[2.88,7.36]],"id":67487134}],"con":true,"img":false}]}
{"op":"mcm","clk":"11541444077","pt":1719505817437,"mc":[{"id":"1.230180133","rc":[{"atb":[[2.86,2.09]],"id":67487134},{"atb":[[1.45,0],[1.56,2.11]],"id":66314580},{"atl":[[3.15,3.38]],"id":66314580},{"atl":[[7,5.02]],"id":67130716}],"con":true,"img":false}]}
{"op":"mcm","clk":"11541444121","pt":1719505817906,"mc":[{"id":"1.230180133","rc":[{"atl":[[3.25,13.21]],"id":66314580}],"con":true,"img":false}]}
{"op":"mcm","clk":"11541444149","pt":1719505818320,"mc":[{"id":"1.230180133","rc":[{"atb":[[2.86,0.15]],"id":67487134},{"atb":[[2.72,0]],"id":67130716}],"con":true,"img":false}]}
{"op":"mcm","clk":"11541444170","pt":1719505818516,"mc":[{"id":"1.230180133","rc":[{"atb":[[2.9,1.94]],"id":67487134},{"atb":[[2.72,1.94]],"id":67130716}],"con":true,"img":false}]}
{"op":"mcm","clk":"11541444260","pt":1719505819507,"mc":[{"id":"1.230180133","rc":[{"atl":[[3.25,5.01]],"id":66314580}],"con":true,"img":false}]}
{"op":"mcm","clk":"11541444277","pt":1719505819712,"mc":[{"id":"1.230180133","rc":[{"atl":[[3.15,6.87]],"id":66314580}],"con":true,"img":false}]}
{"op":"mcm","clk":"11541444294","pt":1719505819920,"mc":[{"id":"1.230180133","rc":[{"atb":[[3.95,3.04]],"id":53826530}],"con":true,"img":false}]}
{"op":"mcm","clk":"11541444305","pt":1719505820030,"mc":[{"id":"1.230180133","rc":[{"atl":[[3.15,3.38]],"id":66314580}],"con":true,"img":false}]}
{"op":"mcm","clk":"11541444338","pt":1719505820328,"mc":[{"id":"1.230180133","rc":[{"atl":[[3.1,6.64]],"id":66314580}],"con":true,"img":false}]}
{"op":"mcm","clk":"11541444387","pt":1719505820705,"mc":[{"id":"1.230180133","rc":[{"atl":[[3.1,0]],"id":66314580}],"con":true,"img":false}]}
{"op":"mcm","clk":"11541444406","pt":1719505820909,"mc":[{"id":"1.230180133","rc":[{"atl":[[3.05,0.84]],"id":66314580}],"con":true,"img":false}]}
{"op":"mcm","clk":"11541444428","pt":1719505821115,"mc":[{"id":"1.230180133","rc":[{"atl":[[3.05,10.55]],"id":66314580},{"atb":[[3.9,1.94]],"id":53826530}],"con":true,"img":false}]}
{"op":"mcm","clk":"11541444440","pt":1719505821214,"mc":[{"id":"1.230180133","rc":[{"atb":[[4,2]],"id":53826530}],"con":true,"img":false}]}
{"op":"mcm","clk":"11541444450","pt":1719505821316,"mc":[{"id":"1.230180133","rc":[{"atb":[[2.9,0]],"id":67487134},{"atl":[[3.05,0.84]],"id":66314580},{"atb":[[3.9,0]],"id":53826530},{"atb":[[2.72,0]],"id":67130716}],"con":true,"img":false}]}
{"op":"mcm","clk":"11541444458","pt":1719505821419,"mc":[{"id":"1.230180133","rc":[{"atb":[[2.9,1.94]],"id":67487134},{"atl":[[3.05,0]],"id":66314580},{"atb":[[4,3.94]],"id":53826530},{"atb":[[2.72,1.94]],"id":67130716}],"con":true,"img":false}]}
{"op":"mcm","clk":"11541444485","pt":1719505821730,"mc":[{"id":"1.230180133","rc":[{"atb":[[2.9,3.94]],"id":67487134},{"atl":[[3,7.8]],"id":66314580},{"atb":[[4,6.94]],"id":53826530},{"atb":[[2.18,2]],"id":70086038},{"atb":[[1.97,2.5]],"id":64618726},{"atb":[[2.72,4.94]],"id":67130716}],"con":true,"img":false}]}
{"op":"mcm","clk":"11541444495","pt":1719505821834,"mc":[{"id":"1.230180133","rc":[{"atb":[[1.97,8.69]],"id":64618726}],"con":true,"img":false}]}
{"op":"mcm","clk":"11541444509","pt":1719505821996,"mc":[{"id":"1.230180133","rc":[{"atl":[[3,0]],"id":66314580},{"atb":[[1.96,2]],"id":64618726}],"con":true,"img":false}]}
{"op":"mcm","clk":"11541444543","pt":1719505822311,"mc":[{"id":"1.230180133","rc":[{"atl":[[2.98,1.45]],"id":66314580}],"con":true,"img":false}]}
{"op":"mcm","clk":"11541444570","pt":1719505822619,"mc":[{"id":"1.230180133","rc":[{"atl":[[2.98,0]],"id":66314580}],"con":true,"img":false}]}
{"op":"mcm","clk":"11541444597","pt":1719505822923,"mc":[{"id":"1.230180133","rc":[{"atb":[[2.88,5.36]],"id":67487134},{"atl":[[2.98,9.56]],"id":66314580}],"con":true,"img":false}]}
{"op":"mcm","clk":"11541444608","pt":1719505823023,"mc":[{"id":"1.230180133","rc":[{"atb":[[2.92,2]],"id":67487134}],"con":true,"img":false}]}
{"op":"mcm","clk":"11541444639","pt":1719505823337,"mc":[{"id":"1.230180133","rc":[{"atb":[[2.7,4.72]],"id":67130716}],"con":true,"img":false}]}
{"op":"mcm","clk":"11541444650","pt":1719505823441,"mc":[{"id":"1.230180133","rc":[{"atl":[[3.15,2.53]],"id":66314580},{"atb":[[2.74,2]],"id":67130716}],"con":true,"img":false}]}
{"op":"mcm","clk":"11541444670","pt":1719505823605,"mc":[{"id":"1.230180133","rc":[{"atl":[[2.98,0]],"id":66314580}],"con":true,"img":false}]}
{"op":"mcm","clk":"11541444677","pt":1719505823708,"mc":[{"id":"1.230180133","rc":[{"atb":[[1.96,0]],"id":64618726}],"con":true,"img":false}]}
{"op":"mcm","clk":"11541444687","pt":1719505823832,"mc":[{"id":"1.230180133","rc":[{"atb":[[1.98,2]],"id":64618726}],"con":true,"img":false}]}
{"op":"mcm","clk":"11541444694","pt":1719505823917,"mc":[{"id":"1.230180133","rc":[{"atl":[[2.98,3.21]],"id":66314580}],"con":true,"img":false}]}
{"op":"mcm","clk":"11541444723","pt":1719505824216,"mc":[{"id":"1.230180133","rc":[{"atl":[[2.98,0]],"id":66314580}],"con":true,"img":false}]}
{"op":"mcm","clk":"11541444770","pt":1719505824731,"mc":[{"id":"1.230180133","rc":[{"atl":[[3.1,5.03]],"id":66314580},{"atb":[[4.1,14.94]],"id":53826530}],"con":true,"img":false}]}
{"op":"mcm","clk":"11541444782","pt":1719505824936,"mc":[{"id":"1.230180133","rc":[{"atl":[[3.2,0.12]],"id":66314580},{"atb":[[3.85,0]],"id":53826530}],"con":true,"img":false}]}
{"op":"mcm","clk":"11541444795","pt":1719505825144,"mc":[{"id":"1.230180133","rc":[{"atb":[[3.95,0]],"id":53826530}],"con":true,"img":false}]}
{"op":"mcm","clk":"11541444832","pt":1719505825523,"mc":[{"id":"1.230180133","rc":[{"atl":[[3.15,0]],"id":66314580}],"con":true,"img":false}]}
{"op":"mcm","clk":"11541444861","pt":1719505825816,"mc":[{"id":"1.230180133","rc":[{"atl":[[3.1,0]],"id":66314580}],"con":true,"img":false}]}
{"op":"mcm","clk":"11541444869","pt":1719505825927,"mc":[{"id":"1.230180133","rc":[{"atl":[[3.2,5.76],[3.35,7.65],[3.25,0]],"id":66314580},{"atb":[[2.18,6.5]],"id":70086038}],"con":true,"img":false}]}
{"op":"mcm","clk":"11541444880","pt":1719505826021,"mc":[{"id":"1.230180133","rc":[{"atb":[[2.74,9.25]],"id":67130716}],"con":true,"img":false}]}
{"op":"mcm","clk":"11541444886","pt":1719505826125,"mc":[{"id":"1.230180133","rc":[{"atb":[[2.16,1.94]],"id":70086038}],"con":true,"img":false}]}
{"op":"mcm","clk":"11541444896","pt":1719505826229,"mc":[{"id":"1.230180133","rc":[{"atb":[[2.7,0]],"id":67130716}],"con":true,"img":false}]}
{"op":"mcm","clk":"11541444987","pt":1719505827114,"mc":[{"id":"1.230180133","rc":[{"atb":[[4,4.94]],"id":53826530}],"con":true,"img":false}]}
{"op":"mcm","clk":"11541444994","pt":1719505827224,"mc":[{"id":"1.230180133","rc":[{"atb":[[4.2,2]],"id":53826530}],"con":true,"img":false}]}
{"op":"mcm","clk":"11541445013","pt":1719505827418,"mc":[{"id":"1.230180133","rc":[{"atb":[[4,3]],"id":53826530},{"atb":[[2.16,0]],"id":70086038},{"atb":[[2.72,3]],"id":67130716}],"con":true,"img":false}]}
{"op":"mcm","clk":"11541445024","pt":1719505827524,"mc":[{"id":"1.230180133","rc":[{"atb":[[2.2,1.94]],"id":70086038},{"atb":[[2.76,1.94]],"id":67130716}],"con":true,"img":false}]}
{"op":"mcm","clk":"11541445098","pt":1719505828312,"mc":[{"id":"1.230180133","rc":[{"atl":[[3.15,2.53]],"id":66314580}],"con":true,"img":false}]}
{"op":"mcm","clk":"11541445110","pt":1719505828421,"mc":[{"id":"1.230180133","rc":[{"atl":[[3.15,3.38]],"id":66314580}],"con":true,"img":false}]}
{"op":"mcm","clk":"11541445293","pt":1719505830326,"mc":[{"id":"1.230180133","rc":[{"atb":[[2.2,0]],"id":70086038},{"atb":[[2.76,0]],"id":67130716}],"con":true,"img":false}]}
{"op":"mcm","clk":"11541445307","pt":1719505830429,"mc":[{"id":"1.230180133","rc":[{"atb":[[2.2,1.94]],"id":70086038},{"atb":[[2.76,1.94]],"id":67130716}],"con":true,"img":false}]}
{"op":"mcm","clk":"11541445363","pt":1719505830950,"mc":[{"id":"1.230180133","rc":[{"atb":[[2.92,8.45]],"id":67487134}],"con":true,"img":false}]}
{"op":"mcm","clk":"11541445376","pt":1719505831050,"mc":[{"id":"1.230180133","rc":[{"atb":[[2.88,0]],"id":67487134}],"con":true,"img":false}]}
{"op":"mcm","clk":"11541445493","pt":1719505832239,"mc":[{"id":"1.230180133","rc":[{"atl":[[3.35,2.5],[3.25,9.16]],"id":66314580}],"con":true,"img":false}]}
{"op":"mcm","clk":"11541445589","pt":1719505833329,"mc":[{"id":"1.230180133","rc":[{"atb":[[2.9,2]],"id":67487134},{"atb":[[4.3,2.06]],"id":53826530},{"atb":[[2.2,0]],"id":70086038},{"atb":[[2.76,0]],"id":67130716}],"con":true,"img":false}]}
{"op":"mcm","clk":"11541445601","pt":1719505833432,"mc":[{"id":"1.230180133","rc":[{"atb":[[2.94,1.94]],"id":67487134},{"atb":[[2.2,1.94]],"id":70086038},{"atb":[[2.76,1.94]],"id":67130716}],"con":true,"img":false}]}
{"op":"mcm","clk":"11541445634","pt":1719505833737,"mc":[{"id":"1.230180133","rc":[{"atb":[[4.2,0]],"id":53826530}],"con":true,"img":false}]}
{"op":"mcm","clk":"11541445644","pt":1719505833847,"mc":[{"id":"1.230180133","rc":[{"atb":[[4.4,2]],"id":53826530}],"con":true,"img":false}]}
{"op":"mcm","clk":"11541445768","pt":1719505835341,"mc":[{"id":"1.230180133","rc":[{"atb":[[1.98,8.19]],"id":64618726}],"con":true,"img":false}]}
{"op":"mcm","clk":"11541445783","pt":1719505835505,"mc":[{"id":"1.230180133","rc":[{"atb":[[1.97,2.5]],"id":64618726}],"con":true,"img":false}]}
{"op":"mcm","clk":"11541445800","pt":1719505835715,"mc":[{"id":"1.230180133","rc":[{"atb":[[2.9,0]],"id":67487134},{"atb":[[4,0]],"id":53826530},{"atb":[[2.18,4.5]],"id":70086038},{"atb":[[1.97,0]],"id":64618726},{"atb":[[2.72,0]],"id":67130716}],"con":true,"img":false}]}
{"op":"mcm","clk":"11541445810","pt":1719505835814,"mc":[{"id":"1.230180133","rc":[{"atb":[[4.4,4.23]],"id":53826530},{"atb":[[2.2,4.84]],"id":70086038},{"atb":[[1.99,2.9]],"id":64618726},{"atb":[[2.76,3.94]],"id":67130716}],"con":true,"img":false}]}
{"op":"mcm","clk":"11541445836","pt":1719505836126,"mc":[{"id":"1.230180133","rc":[{"atb":[[2.74,7.25]],"id":67130716}],"con":true,"img":false}]}
{"op":"mcm","clk":"11541445844","pt":1719505836231,"mc":[{"id":"1.230180133","rc":[{"atb":[[2.78,2]],"id":67130716}],"con":true,"img":false}]}
{"op":"mcm","clk":"11541445858","pt":1719505836329,"mc":[{"id":"1.230180133","rc":[{"atb":[[2.94,0]],"id":67487134}],"con":true,"img":false}]}
{"op":"mcm","clk":"11541445870","pt":1719505836426,"mc":[{"id":"1.230180133","rc":[{"atb":[[2.94,1.94]],"id":67487134},{"atb":[[1.98,6.19]],"id":64618726}],"con":true,"img":false}]}
{"op":"mcm","clk":"11541445879","pt":1719505836528,"mc":[{"id":"1.230180133","rc":[{"atb":[[2,2]],"id":64618726}],"con":true,"img":false}]}
{"op":"mcm","clk":"11541445970","pt":1719505837537,"mc":[{"id":"1.230180133","rc":[{"atb":[[4.5,0.52]],"id":53826530}],"con":true,"img":false}]}
{"op":"mcm","clk":"11541446030","pt":1719505838149,"mc":[{"id":"1.230180133","rc":[{"atl":[[3.1,6.87]],"id":66314580},{"atb":[[4.5,5.57],[4.6,3.36]],"id":53826530}],"con":true,"img":false}]}
{"op":"mcm","clk":"11541446046","pt":1719505838352,"mc":[{"id":"1.230180133","rc":[{"atl":[[3.2,0.12]],"id":66314580},{"atb":[[4.1,0]],"id":53826530}],"con":true,"img":false}]}
{"op":"mcm","clk":"11541446066","pt":1719505838512,"mc":[{"id":"1.230180133","rc":[{"atb":[[4.3,0],[4.4,2.23]],"id":53826530}],"con":true,"img":false}]}
{"op":"mcm","clk":"11541446077","pt":1719505838644,"mc":[{"id":"1.230180133","rc":[{"atb":[[4.7,2]],"id":53826530}],"con":true,"img":false}]}
{"op":"mcm","clk":"11541446109","pt":1719505838934,"mc":[{"id":"1.230180133","rc":[{"atl":[[3.05,0.84]],"id":66314580}],"con":true,"img":false}]}
{"op":"mcm","clk":"11541446149","pt":1719505839336,"mc":[{"id":"1.230180133","rc":[{"atb":[[2.94,0]],"id":67487134},{"atl":[[3.05,5.26]],"id":66314580},{"atb":[[2.2,10.84]],"id":70086038}],"con":true,"img":false}]}
{"op":"mcm","clk":"11541446159","pt":1719505839435,"mc":[{"id":"1.230180133","rc":[{"atb":[[2.94,1.94]],"id":67487134},{"atl":[[3.1,0]],"id":66314580},{"atb":[[2.18,0]],"id":70086038},{"atb":[[2.78,8.73]],"id":67130716}],"con":true,"img":false}]}
{"op":"mcm","clk":"11541446171","pt":1719505839543,"mc":[{"id":"1.230180133","rc":[{"atb":[[2.74,0]],"id":67130716}],"con":true,"img":false}]}
{"op":"mcm","clk":"11541446216","pt":1719505839908,"mc":[{"id":"1.230180133","rc":[{"atl":[[3.15,2.53]],"id":66314580}],"con":true,"img":false}]}
{"op":"mcm","clk":"11541446309","pt":1719505840736,"mc":[{"id":"1.230180133","rc":[{"atl":[[3.15,0]],"id":66314580}],"con":true,"img":false}]}
{"op":"mcm","clk":"11541446478","pt":1719505842343,"mc":[{"id":"1.230180133","rc":[{"atb":[[2.94,0]],"id":67487134},{"atb":[[2.76,2]],"id":67130716}],"con":true,"img":false}]}
{"op":"mcm","clk":"11541446492","pt":1719505842440,"mc":[{"id":"1.230180133","rc":[{"atb":[[2.94,1.94]],"id":67487134},{"atb":[[2.8,1.94]],"id":67130716}],"con":true,"img":false}]}
{"op":"mcm","clk":"11541446683","pt":1719505844212,"mc":[{"id":"1.230180133","rc":[{"atb":[[2.94,7.3]],"id":67487134}],"con":true,"img":false}]}
{"op":"mcm","clk":"11541446705","pt":1719505844423,"mc":[{"id":"1.230180133","rc":[{"atb":[[2.92,2]],"id":67487134}],"con":true,"img":false}]}
{"op":"mcm","clk":"11541446801","pt":1719505845352,"mc":[{"id":"1.230180133","rc":[{"atb":[[2.8,0]],"id":67130716}],"con":true,"img":false}]}
{"op":"mcm","clk":"11541446814","pt":1719505845447,"mc":[{"id":"1.230180133","rc":[{"atb":[[2.92,0]],"id":67487134},{"atb":[[2.8,1.94]],"id":67130716}],"con":true,"img":false}]}
{"op":"mcm","clk":"11541446823","pt":1719505845552,"mc":[{"id":"1.230180133","rc":[{"atb":[[2.96,2]],"id":67487134}],"con":true,"img":false}]}
{"op":"mcm","clk":"11541446838","pt":1719505845653,"mc":[{"id":"1.230180133","rc":[{"atb":[[2.86,0]],"id":67487134},{"atl":[[6.6,4.59]],"id":67487134},{"atb":[[1.59,0]],"id":66314580},{"atl":[[3.2,0]],"id":66314580},{"atb":[[2.68,0]],"id":67130716},{"atl":[[6.8,0]],"id":67130716}],"con":true,"img":false}]}
{"op":"mcm","clk":"11541446848","pt":1719505845757,"mc":[{"id":"1.230180133","rc":[{"atl":[[3.35,16.93],[3.25,0]],"id":66314580},{"atl":[[8.2,13.96],[7,0]],"id":67130716}],"con":true,"img":false}]}
{"op":"mcm","clk":"11541446922","pt":1719505846442,"mc":[{"id":"1.230180133","rc":[{"atb":[[4.8,2.06]],"id":53826530}],"con":true,"img":false}]}
{"op":"mcm","clk":"11541447015","pt":1719505847367,"mc":[{"id":"1.230180133","rc":[{"atb":[[4.7,0]],"id":53826530}],"con":true,"img":false}]}
{"op":"mcm","clk":"11541447030","pt":1719505847460,"mc":[{"id":"1.230180133","rc":[{"atb":[[4.9,2]],"id":53826530}],"con":true,"img":false}]}
{"op":"mcm","clk":"11541447078","pt":1719505847842,"mc":[{"id":"1.230180133","rc":[{"atb":[[2.8,0]],"id":67130716}],"con":true,"img":false}]}
{"op":"mcm","clk":"11541447097","pt":1719505848045,"mc":[{"id":"1.230180133","rc":[{"atb":[[2.8,1.94]],"id":67130716}],"con":true,"img":false}]}
{"op":"mcm","clk":"11541447140","pt":1719505848556,"mc":[{"id":"1.230180133","rc":[{"atb":[[2,8.49]],"id":64618726}],"con":true,"img":false}]}
{"op":"mcm","clk":"11541447149","pt":1719505848657,"mc":[{"id":"1.230180133","rc":[{"atb":[[1.98,0]],"id":64618726}],"con":true,"img":false}]}
{"op":"mcm","clk":"11541447256","pt":1719505849843,"mc":[{"id":"1.230180133","rc":[{"atb":[[4.4,0]],"id":53826530},{"atb":[[2.2,7.94]],"id":70086038},{"atb":[[1.99,0]],"id":64618726},{"atb":[[2.76,0]],"id":67130716}],"con":true,"img":false}]}
{"op":"mcm","clk":"11541447265","pt":1719505849952,"mc":[{"id":"1.230180133","rc":[{"atb":[[4.9,4]],"id":53826530},{"atb":[[2.22,2.5]],"id":70086038},{"atb":[[2.02,2]],"id":64618726},{"atb":[[2.8,4.95]],"id":67130716}],"con":true,"img":false}]}
{"op":"mcm","clk":"11541447308","pt":1719505850468,"mc":[{"id":"1.230180133","rc":[{"atb":[[2.2,6]],"id":70086038},{"atb":[[2.78,6.73]],"id":67130716}],"con":true,"img":false}]}
{"op":"mcm","clk":"11541447318","pt":1719505850564,"mc":[{"id":"1.230180133","rc":[{"atb":[[2.24,1.94]],"id":70086038},{"atb":[[2.02,3.94]],"id":64618726},{"atb":[[2.82,2]],"id":67130716}],"con":true,"img":false}]}
{"op":"mcm","clk":"11541447347","pt":1719505850835,"mc":[{"id":"1.230180133","rc":[{"atb":[[2,6.49]],"id":64618726},{"atl":[[9,17.5],[8.2,3.5]],"id":67130716}],"con":true,"img":false}]}
{"op":"mcm","clk":"11541447357","pt":1719505850935,"mc":[{"id":"1.230180133","rc":[{"atb":[[2.04,2]],"id":64618726}],"con":true,"img":false}]}
{"op":"mcm","clk":"11541447394","pt":1719505851353,"mc":[{"id":"1.230180133","rc":[{"atb":[[5,3.68]],"id":53826530}],"con":true,"img":false}]}
{"op":"mcm","clk":"11541447415","pt":1719505851548,"mc":[{"id":"1.230180133","rc":[{"atb":[[4.6,0]],"id":53826530}],"con":true,"img":false}]}
{"op":"mcm","clk":"11541447423","pt":1719505851653,"mc":[{"id":"1.230180133","rc":[{"atb":[[2.8,2.5],[2.72,5],[2.62,0],[2.78,0],[2.7,0]],"id":67487134},{"atb":[[4.8,0]],"id":53826530}],"con":true,"img":false}]}
{"op":"mcm","clk":"11541447451","pt":1719505851970,"mc":[{"id":"1.230180133","rc":[{"atb":[[4.9,2]],"id":53826530}],"con":true,"img":false}]}
{"op":"mcm","clk":"11541447463","pt":1719505852067,"mc":[{"id":"1.230180133","rc":[{"atb":[[5.1,2]],"id":53826530}],"con":true,"img":false}]}
{"op":"mcm","clk":"11541447503","pt":1719505852443,"mc":[{"id":"1.230180133","rc":[{"atb":[[2.24,6.44]],"id":70086038}],"con":true,"img":false}]}
{"op":"mcm","clk":"11541447514","pt":1719505852546,"mc":[{"id":"1.230180133","rc":[{"atb":[[2.82,9.8]],"id":67130716}],"con":true,"img":false}]}
{"op":"mcm","clk":"11541447525","pt":1719505852653,"mc":[{"id":"1.230180133","rc":[{"atb":[[2.2,0]],"id":70086038}],"con":true,"img":false}]}
{"op":"mcm","clk":"11541447534","pt":1719505852756,"mc":[{"id":"1.230180133","rc":[{"atb":[[2.78,0]],"id":67130716}],"con":true,"img":false}]}
{"op":"mcm","clk":"11541447549","pt":1719505852861,"mc":[{"id":"1.230180133","rc":[{"atb":[[4.5,5.05]],"id":53826530},{"atb":[[2.8,3.01]],"id":67130716}],"con":true,"img":false}]}
{"op":"mcm","clk":"11541447558","pt":1719505852960,"mc":[{"id":"1.230180133","rc":[{"atb":[[2.84,1.94]],"id":67130716}],"con":true,"img":false}]}
{"op":"mcm","clk":"11541447638","pt":1719505853640,"mc":[{"id":"1.230180133","rc":[{"atl":[[10,4.17]],"id":53826530},{"trd":[[10,22.72]],"ltp":10.0,"tv":22.72,"id":53826530}],"con":true,"img":false}]}
{"op":"mcm","clk":"11541447672","pt":1719505853947,"mc":[{"id":"1.230180133","rc":[{"atb":[[3.4,1.57]],"id":53826530},{"atb":[[2.84,3.55]],"id":67130716}],"con":true,"img":false}]}
{"op":"mcm","clk":"11541447795","pt":1719505855138,"mc":[{"id":"1.230180133","rc":[{"atb":[[2.82,7.8]],"id":67130716}],"con":true,"img":false}]}
{"op":"mcm","clk":"11541447808","pt":1719505855244,"mc":[{"id":"1.230180133","rc":[{"atb":[[3.25,0],[3.05,0]],"id":53826530},{"atb":[[2.12,7.11],[2.2,2.5]],"id":70086038},{"atb":[[2.86,2]],"id":67130716}],"con":true,"img":false}]}
{"op":"mcm","clk":"11541447819","pt":1719505855348,"mc":[{"id":"1.230180133","rc":[{"atb":[[2.14,0],[1.99,0],[2.06,0]],"id":70086038}],"con":true,"img":false}]}
{"op":"mcm","clk":"11541447872","pt":1719505855761,"mc":[{"id":"1.230180133","rc":[{"atb":[[3.4,0]],"id":53826530}],"con":true,"img":false}]}
{"op":"mcm","clk":"11541448047","pt":1719505857263,"mc":[{"id":"1.230180133","rc":[{"atb":[[2.96,7.32]],"id":67487134},{"spn":4.78,"spf":"NaN","id":67487134},{"spn":1.64,"spf":1.0,"id":66314580},{"atb":[[5.2,0.52]],"id":53826530},{"spn":7.6,"spf":"NaN","id":53826530},{"spn":3.17,"spf":"NaN","id":70086038},{"spn":2.77,"spf":"NaN","id":64618726},{"spn":4.73,"spf":"NaN","id":67130716}],"con":true,"img":false}]}
{"op":"mcm","clk":"11541448058","pt":1719505857371,"mc":[{"id":"1.230180133","rc":[{"atb":[[2.94,1.94]],"id":67487134}],"con":true,"img":false}]}
{"op":"mcm","clk":"11541448110","pt":1719505857945,"mc":[{"id":"1.230180133","rc":[{"atb":[[2.94,0]],"id":67487134}],"con":true,"img":false}]}
{"op":"mcm","clk":"11541448128","pt":1719505858157,"mc":[{"id":"1.230180133","rc":[{"atb":[[2.98,1.94]],"id":67487134}],"con":true,"img":false}]}
{"op":"mcm","clk":"11541448261","pt":1719505859367,"mc":[{"id":"1.230180133","rc":[{"atb":[[5.2,2.52]],"id":53826530}],"con":true,"img":false}]}
{"op":"mcm","clk":"11541448316","pt":1719505859983,"mc":[{"id":"1.230180133","rc":[{"atb":[[5.1,0]],"id":53826530}],"con":true,"img":false}]}
{"op":"mcm","clk":"11541448325","pt":1719505860039,"mc":[{"id":"1.230180133","rc":[{"atb":[[5.3,2]],"id":53826530}],"con":true,"img":false}]}
{"op":"mcm","clk":"11541448333","pt":1719505860142,"mc":[{"id":"1.230180133","rc":[{"atb":[[5.4,1],[5.2,8.43]],"id":53826530},{"atl":[[10,6.82]],"id":53826530}],"con":true,"img":false}]}
{"op":"mcm","clk":"11541448368","pt":1719505860566,"mc":[{"id":"1.230180133","rc":[{"atb":[[2.98,0]],"id":67487134},{"atb":[[5.3,3.57]],"id":53826530}],"con":true,"img":false}]}
{"op":"mcm","clk":"11541448388","pt":1719505860768,"mc":[{"id":"1.230180133","rc":[{"atb":[[2.98,1.94]],"id":67487134}],"con":true,"img":false}]}
{"op":"mcm","clk":"11541448419","pt":1719505861081,"mc":[{"id":"1.230180133","rc":[{"atb":[[5.2,8.24]],"id":53826530}],"con":true,"img":false}]}
{"op":"mcm","clk":"11541448439","pt":1719505861284,"mc":[{"id":"1.230180133","rc":[{"atb":[[5.2,2.52]],"id":53826530}],"con":true,"img":false}]}
{"op":"mcm","clk":"11541448450","pt":1719505861349,"mc":[{"id":"1.230180133","rc":[{"atb":[[5.4,6.72]],"id":53826530}],"con":true,"img":false}]}
{"op":"mcm","clk":"11541448461","pt":1719505861455,"mc":[{"id":"1.230180133","rc":[{"atb":[[2.04,9.28]],"id":64618726}],"con":true,"img":false}]}
{"op":"mcm","clk":"11541448481","pt":1719505861663,"mc":[{"id":"1.230180133","rc":[{"atb":[[2,0]],"id":64618726}],"con":true,"img":false}]}
{"op":"mcm","clk":"11541448490","pt":1719505861760,"mc":[{"id":"1.230180133","rc":[{"atb":[[5.3,1.57]],"id":53826530},{"atb":[[2.06,1.6]],"id":64618726}],"con":true,"img":false}]}
{"op":"mcm","clk":"11541448500","pt":1719505861869,"mc":[{"id":"1.230180133","rc":[{"atb":[[5.5,2]],"id":53826530},{"atb":[[2.22,6.87]],"id":70086038}],"con":true,"img":false}]}
{"op":"mcm","clk":"11541448522","pt":1719505862064,"mc":[{"id":"1.230180133","rc":[{"atb":[[5.4,5.72]],"id":53826530}],"con":true,"img":false}]}
{"op":"mcm","clk":"11541448552","pt":1719505862375,"mc":[{"id":"1.230180133","rc":[{"atb":[[2.26,1.62]],"id":70086038},{"atb":[[2.06,0]],"id":64618726}],"con":true,"img":false}]}
{"op":"mcm","clk":"11541448583","pt":1719505862792,"mc":[{"id":"1.230180133","rc":[{"atb":[[5.4,5.33]],"id":53826530}],"con":true,"img":false}]}
{"op":"mcm","clk":"11541448606","pt":1719505862962,"mc":[{"id":"1.230180133","rc":[{"atb":[[5.4,0]],"id":53826530}],"con":true,"img":false}]}
{"op":"mcm","clk":"11541448615","pt":1719505863064,"mc":[{"id":"1.230180133","rc":[{"atb":[[2.98,0]],"id":67487134},{"atb":[[5.5,7.33]],"id":53826530},{"atb":[[2.02,2]],"id":64618726}],"con":true,"img":false}]}
{"op":"mcm","clk":"11541448634","pt":1719505863268,"mc":[{"id":"1.230180133","rc":[{"atb":[[2.98,1.94]],"id":67487134},{"atb":[[2.06,1.94]],"id":64618726}],"con":true,"img":false}]}
{"op":"mcm","clk":"11541448653","pt":1719505863468,"mc":[{"id":"1.230180133","rc":[{"atb":[[5.5,5.33]],"id":53826530}],"con":true,"img":false}]}
{"op":"mcm","clk":"11541448668","pt":1719505863573,"mc":[{"id":"1.230180133","rc":[{"atb":[[5.3,3.57]],"id":53826530}],"con":true,"img":false}]}
{"op":"mcm","clk":"11541448688","pt":1719505863783,"mc":[{"id":"1.230180133","rc":[{"atb":[[4.9,0]],"id":53826530},{"atb":[[2.22,4.37]],"id":70086038},{"atb":[[2.02,0]],"id":64618726},{"atb":[[2.8,0]],"id":67130716}],"con":true,"img":false}]}
{"op":"mcm","clk":"11541448703","pt":1719505863885,"mc":[{"id":"1.230180133","rc":[{"atb":[[2.26,3.62]],"id":70086038},{"atb":[[2.06,4.04]],"id":64618726},{"atb":[[2.86,4.1]],"id":67130716}],"con":true,"img":false}]}
{"op":"mcm","clk":"11541448737","pt":1719505864051,"mc":[{"id":"1.230180133","rc":[{"atb":[[5.6,1]],"id":53826530}],"con":true,"img":false}]}
{"op":"mcm","clk":"11541448762","pt":1719505864263,"mc":[{"id":"1.230180133","rc":[{"atb":[[5.3,2],[5.7,4.28]],"id":53826530},{"atb":[[2.26,2]],"id":70086038},{"atb":[[2.84,1.94]],"id":67130716}],"con":true,"img":false}]}
{"op":"mcm","clk":"11541448783","pt":1719505864466,"mc":[{"id":"1.230180133","rc":[{"atb":[[5,0]],"id":53826530}],"con":true,"img":false}]}
{"op":"mcm","clk":"11541448793","pt":1719505864572,"mc":[{"id":"1.230180133","rc":[{"atb":[[5.2,0.52]],"id":53826530}],"con":true,"img":false}]}
{"op":"mcm","clk":"11541448849","pt":1719505865182,"mc":[{"id":"1.230180133","rc":[{"atb":[[5.5,5.16]],"id":53826530}],"con":true,"img":false}]}
{"op":"mcm","clk":"11541448871","pt":1719505865344,"mc":[{"id":"1.230180133","rc":[{"atb":[[5.6,0],[5.5,0]],"id":53826530},{"atb":[[2.26,7.9]],"id":70086038}],"con":true,"img":false}]}
{"op":"mcm","clk":"11541448881","pt":1719505865453,"mc":[{"id":"1.230180133","rc":[{"atb":[[5.7,9.44]],"id":53826530},{"atb":[[2.22,0]],"id":70086038},{"atb":[[2.86,11.25]],"id":67130716}],"con":true,"img":false}]}
{"op":"mcm","clk":"11541448892","pt":1719505865554,"mc":[{"id":"1.230180133","rc":[{"atb":[[5.7,5.16]],"id":53826530},{"atb":[[2.24,1.94]],"id":70086038}],"con":true,"img":false}]}
{"op":"mcm","clk":"11541448904","pt":1719505865668,"mc":[{"id":"1.230180133","rc":[{"atb":[[2.82,0]],"id":67130716}],"con":true,"img":false}]}
{"op":"mcm","clk":"11541448929","pt":1719505865870,"mc":[{"id":"1.230180133","rc":[{"atb":[[5.7,5]],"id":53826530}],"con":true,"img":false}]}
{"op":"mcm","clk":"11541448946","pt":1719505865977,"mc":[{"id":"1.230180133","rc":[{"atb":[[5.8,3.75]],"id":53826530},{"atb":[[2.88,1.6]],"id":67130716}],"con":true,"img":false}]}
{"op":"mcm","clk":"11541448960","pt":1719505866070,"mc":[{"id":"1.230180133","rc":[{"atb":[[2.98,0]],"id":67487134},{"atb":[[5.7,0]],"id":53826530},{"atb":[[2.24,0]],"id":70086038},{"atb":[[2.84,0]],"id":67130716}],"con":true,"img":false}]}
{"op":"mcm","clk":"11541448976","pt":1719505866184,"mc":[{"id":"1.230180133","rc":[{"atb":[[2.98,1.94]],"id":67487134},{"atb":[[5.4,5]],"id":53826530},{"atb":[[2.28,1.94]],"id":70086038},{"atb":[[2.88,3.55]],"id":67130716}],"con":true,"img":false}]}
{"op":"mcm","clk":"11541448988","pt":1719505866282,"mc":[{"id":"1.230180133","rc":[{"atb":[[5.8,0],[5.3,0]],"id":53826530}],"con":true,"img":false}]}
{"op":"mcm","clk":"11541449004","pt":1719505866382,"mc":[{"id":"1.230180133","rc":[{"atb":[[3.6,5],[3.8,2.5],[1.02,2],[3.4,10]],"id":53826530}],"con":true,"img":false}]}
{"op":"mcm","clk":"11541449019","pt":1719505866488,"mc":[{"id":"1.230180133","rc":[{"atb":[[5.5,5]],"id":53826530}],"con":true,"img":false}]}
{"op":"mcm","clk":"11541449042","pt":1719505866692,"mc":[{"id":"1.230180133","rc":[{"atb":[[2.04,7.28]],"id":64618726},{"atb":[[2.88,1.94]],"id":67130716}],"con":true,"img":false}]}
{"op":"mcm","clk":"11541449055","pt":1719505866761,"mc":[{"id":"1.230180133","rc":[{"atb":[[2.08,2]],"id":64618726}],"con":true,"img":false}]}
{"op":"mcm","clk":"11541449078","pt":1719505867058,"mc":[{"id":"1.230180133","rc":[{"atb":[[5.4,4.89]],"id":53826530}],"con":true,"img":false}]}
{"op":"mcm","clk":"11541449093","pt":1719505867263,"mc":[{"id":"1.230180133","rc":[{"atb":[[5.4,0]],"id":53826530}],"con":true,"img":false}]}
{"op":"mcm","clk":"11541449100","pt":1719505867362,"mc":[{"id":"1.230180133","rc":[{"atb":[[5.6,1],[5.5,4.89]],"id":53826530}],"con":true,"img":false}]}
{"op":"mcm","clk":"11541449109","pt":1719505867474,"mc":[{"id":"1.230180133","rc":[{"atb":[[5.7,3.7]],"id":53826530}],"con":true,"img":false}]}
{"op":"mcm","clk":"11541449120","pt":1719505867575,"mc":[{"id":"1.230180133","rc":[{"atb":[[4.8,7.5]],"id":53826530}],"con":true,"img":false}]}
{"op":"mcm","clk":"11541449138","pt":1719505867776,"mc":[{"id":"1.230180133","rc":[{"atb":[[4.5,0]],"id":53826530}],"con":true,"img":false}]}
{"op":"mcm","clk":"11541449215","pt":1719505868451,"mc":[{"id":"1.230180133","rc":[{"atb":[[5.5,0]],"id":53826530}],"con":true,"img":false}]}
{"op":"mcm","clk":"11541449222","pt":1719505868563,"mc":[{"id":"1.230180133","rc":[{"atb":[[5.6,0]],"id":53826530}],"con":true,"img":false}]}
{"op":"mcm","clk":"11541449240","pt":1719505868775,"mc":[{"id":"1.230180133","rc":[{"atb":[[5.7,0]],"id":53826530}],"con":true,"img":false}]}
{"op":"mcm","clk":"11541449250","pt":1719505868882,"mc":[{"id":"1.230180133","rc":[{"atb":[[5.3,3.75]],"id":53826530}],"con":true,"img":false}]}
{"op":"mcm","clk":"11541449275","pt":1719505869205,"mc":[{"id":"1.230180133","rc":[{"atb":[[2.98,0]],"id":67487134},{"atb":[[5.3,9.39]],"id":53826530},{"atb":[[2.28,0]],"id":70086038},{"atb":[[2.88,0]],"id":67130716}],"con":true,"img":false}]}
{"op":"mcm","clk":"11541449291","pt":1719505869388,"mc":[{"id":"1.230180133","rc":[{"atb":[[2.98,1.94]],"id":67487134},{"atb":[[2.28,1.94]],"id":70086038},{"atb":[[2.88,1.94]],"id":67130716}],"con":true,"img":false}]}
{"op":"mcm","clk":"11541449351","pt":1719505870062,"mc":[{"id":"1.230180133","rc":[{"atb":[[2.98,7.26]],"id":67487134}],"con":true,"img":false}]}
{"op":"mcm","clk":"11541449368","pt":1719505870257,"mc":[{"id":"1.230180133","rc":[{"atb":[[2.96,2]],"id":67487134}],"con":true,"img":false}]}
{"op":"mcm","clk":"11541449493","pt":1719505871693,"mc":[{"id":"1.230180133","rc":[{"atl":[[3.6,1]],"id":66314580},{"atl":[[10.5,13.03],[13,0]],"id":53826530},{"atl":[[4.5,2.5],[4.6,1]],"id":70086038},{"atl":[[8.6,1],[8.2,2.5]],"id":67130716}],"con":true,"img":false}]}
{"op":"mcm","clk":"11541449503","pt":1719505871756,"mc":[{"id":"1.230180133","rc":[{"atl":[[3.35,0],[3.7,10],[3.55,0],[3.3,2.5],[3.5,5]],"id":66314580},{"atb":[[5.4,1]],"id":53826530},{"atl":[[10.5,2.5],[11,9.32]],"id":53826530},{"atl":[[4.6,11],[4.9,5]],"id":70086038},{"atl":[[8.6,11],[9,5]],"id":67130716}],"con":true,"img":false}]}
{"op":"mcm","clk":"11541449511","pt":1719505871863,"mc":[{"id":"1.230180133","rc":[{"atb":[[2.96,0]],"id":67487134},{"atl":[[3.55,22.2]],"id":66314580}],"con":true,"img":false}]}
{"op":"mcm","clk":"11541449518","pt":1719505871979,"mc":[{"id":"1.230180133","rc":[{"atb":[[2.54,0],[2.32,10],[3,2]],"id":67487134},{"atb":[[5.4,3.12]],"id":53826530},{"atb":[[2.64,0],[2.58,5],[2.48,0],[2.56,0],[2.66,2.5]],"id":67130716}],"con":true,"img":false}]}
{"op":"mcm","clk":"11541449527","pt":1719505872077,"mc":[{"id":"1.230180133","rc":[{"atb":[[2.32,0]],"id":67487134}],"con":true,"img":false}]}
{"op":"mcm","clk":"11541449539","pt":1719505872176,"mc":[{"id":"1.230180133","rc":[{"atb":[[2.46,7.5]],"id":67487134}],"con":true,"img":false}]}
{"op":"mcm","clk":"11541449546","pt":1719505872273,"mc":[{"id":"1.230180133","rc":[{"atb":[[2.28,0]],"id":70086038},{"atb":[[2.88,0]],"id":67130716}],"con":true,"img":false}]}
{"op":"mcm","clk":"11541449570","pt":1719505872488,"mc":[{"id":"1.230180133","rc":[{"atb":[[2.28,1.94]],"id":70086038},{"atb":[[2.88,1.94]],"id":67130716}],"con":true,"img":false}]}
{"op":"mcm","clk":"11541449579","pt":1719505872581,"mc":[{"id":"1.230180133","rc":[{"atb":[[5.2,0]],"id":53826530}],"con":true,"img":false}]}
{"op":"mcm","clk":"11541449613","pt":1719505872994,"mc":[{"id":"1.230180133","rc":[{"atb":[[5.4,3.64],[1.02,0]],"id":53826530}],"con":true,"img":false}]}
{"op":"mcm","clk":"11541449624","pt":1719505873058,"mc":[{"id":"1.230180133","rc":[{"atb":[[5.5,2]],"id":53826530}],"con":true,"img":false}]}
{"op":"mcm","clk":"11541449630","pt":1719505873159,"mc":[{"id":"1.230180133","rc":[{"atb":[[5.3,8.66],[5.4,2.64]],"id":53826530}],"con":true,"img":false}]}
{"op":"mcm","clk":"11541449650","pt":1719505873367,"mc":[{"id":"1.230180133","rc":[{"atb":[[5.3,3.75]],"id":53826530}],"con":true,"img":false}]}
{"op":"mcm","clk":"11541449660","pt":1719505873466,"mc":[{"id":"1.230180133","rc":[{"atb":[[5.4,7.55]],"id":53826530}],"con":true,"img":false}]}
{"op":"mcm","clk":"11541449679","pt":1719505873676,"mc":[{"id":"1.230180133","rc":[{"atb":[[5.4,7.53]],"id":53826530}],"con":true,"img":false}]}
{"op":"mcm","clk":"11541449703","pt":1719505873991,"mc":[{"id":"1.230180133","rc":[{"atb":[[5.4,2.64]],"id":53826530}],"con":true,"img":false}]}
{"op":"mcm","clk":"11541449711","pt":1719505874098,"mc":[{"id":"1.230180133","rc":[{"atb":[[5.5,6.89]],"id":53826530}],"con":true,"img":false}]}
{"op":"mcm","clk":"11541449719","pt":1719505874183,"mc":[{"id":"1.230180133","rc":[{"atb":[[2.08,9.35]],"id":64618726}],"con":true,"img":false}]}
{"op":"mcm","clk":"11541449734","pt":1719505874383,"mc":[{"id":"1.230180133","rc":[{"atl":[[7.4,5],[6.8,0],[7.6,0],[6.6,7.09],[8.4,1]],"id":67487134},{"atb":[[2.04,0],[2.1,1.6]],"id":64618726}],"con":true,"img":false}]}
{"op":"mcm","clk":"11541449747","pt":1719505874589,"mc":[{"id":"1.230180133","rc":[{"atl":[[7.4,19.25],[7,0]],"id":67487134}],"con":true,"img":false}]}
{"op":"mcm","clk":"11541449778","pt":1719505874959,"mc":[{"id":"1.230180133","rc":[{"atb":[[2.1,0]],"id":64618726}],"con":true,"img":false}]}
{"op":"mcm","clk":"11541449785","pt":1719505875064,"mc":[{"id":"1.230180133","rc":[{"atb":[[2.02,3.48]],"id":64618726}],"con":true,"img":false}]}
{"op":"mcm","clk":"11541449810","pt":1719505875371,"mc":[{"id":"1.230180133","rc":[{"atb":[[2.02,0]],"id":64618726}],"con":true,"img":false}]}
{"op":"mcm","clk":"11541449821","pt":1719505875472,"mc":[{"id":"1.230180133","rc":[{"atb":[[5.6,1]],"id":53826530}],"con":true,"img":false}]}
{"op":"mcm","clk":"11541449962","pt":1719505876975,"mc":[{"id":"1.230180133","rc":[{"atb":[[5.7,4.74]],"id":53826530}],"con":true,"img":false}]}
{"op":"mcm","clk":"11541449980","pt":1719505877177,"mc":[{"id":"1.230180133","rc":[{"atb":[[5.3,0],[5.4,0.52],[5.6,0]],"id":53826530}],"con":true,"img":false}]}
{"op":"mcm","clk":"11541450002","pt":1719505877383,"mc":[{"id":"1.230180133","rc":[{"atb":[[5.7,0]],"id":53826530}],"con":true,"img":false}]}
{"op":"mcm","clk":"11541450024","pt":1719505877588,"mc":[{"id":"1.230180133","rc":[{"atb":[[5.6,6.86]],"id":53826530}],"con":true,"img":false}]}
{"op":"mcm","clk":"11541450057","pt":1719505878002,"mc":[{"id":"1.230180133","rc":[{"atb":[[5.7,1.57]],"id":53826530},{"atb":[[2.28,5.69],[2.26,5.9]],"id":70086038},{"atb":[[2.06,1.94]],"id":64618726},{"atb":[[2.86,9.15]],"id":67130716}],"con":true,"img":false}]}
{"op":"mcm","clk":"11541450068","pt":1719505878111,"mc":[{"id":"1.230180133","rc":[{"atb":[[2.28,8.29]],"id":70086038},{"atb":[[2.88,10.5]],"id":67130716}],"con":true,"img":false}]}
{"op":"mcm","clk":"11541450078","pt":1719505878170,"mc":[{"id":"1.230180133","rc":[{"atb":[[5.5,4.89]],"id":53826530},{"atb":[[2.26,0]],"id":70086038}],"con":true,"img":false}]}
{"op":"mcm","clk":"11541450085","pt":1719505878273,"mc":[{"id":"1.230180133","rc":[{"atb":[[1.02,2]],"id":53826530},{"atb":[[2.06,0]],"id":64618726},{"atb":[[2.88,8.56],[2.86,2]],"id":67130716}],"con":true,"img":false}]}
{"op":"mcm","clk":"11541450100","pt":1719505878477,"mc":[{"id":"1.230180133","rc":[{"atb":[[5.5,0]],"id":53826530},{"atb":[[2.1,1.94]],"id":64618726},{"atb":[[2.88,10.5]],"id":67130716}],"con":true,"img":false}]}
{"op":"mcm","clk":"11541450111","pt":1719505878585,"mc":[{"id":"1.230180133","rc":[{"atb":[[5.8,5.86],[5.7,0]],"id":53826530}],"con":true,"img":false}]}
{"op":"mcm","clk":"11541450121","pt":1719505878685,"mc":[{"id":"1.230180133","rc":[{"atl":[[8,2.5],[9,0],[8.2,0],[9.8,0],[8.8,5]],"id":67130716}],"con":true,"img":false}]}
{"op":"mcm","clk":"11541450128","pt":1719505878790,"mc":[{"id":"1.230180133","rc":[{"atb":[[5.8,0],[5.6,0]],"id":53826530},{"atl":[[8.6,1],[8.2,10.88]],"id":67130716}],"con":true,"img":false}]}
{"op":"mcm","clk":"11541450138","pt":1719505878894,"mc":[{"id":"1.230180133","rc":[{"atb":[[5.5,4.66]],"id":53826530}],"con":true,"img":false}]}
{"op":"mcm","clk":"11541450153","pt":1719505879088,"mc":[{"id":"1.230180133","rc":[{"atb":[[2.9,1.6]],"id":67130716}],"con":true,"img":false}]}
{"op":"mcm","clk":"11541450162","pt":1719505879192,"mc":[{"id":"1.230180133","rc":[{"atb":[[5.6,1]],"id":53826530}],"con":true,"img":false}]}
{"op":"mcm","clk":"11541450171","pt":1719505879296,"mc":[{"id":"1.230180133","rc":[{"atb":[[5.7,3.58]],"id":53826530}],"con":true,"img":false}]}
{"op":"mcm","clk":"11541450188","pt":1719505879501,"mc":[{"id":"1.230180133","rc":[{"atb":[[5.5,0]],"id":53826530}],"con":true,"img":false}]}
{"op":"mcm","clk":"11541450207","pt":1719505879708,"mc":[{"id":"1.230180133","rc":[{"atb":[[5.5,4.74]],"id":53826530},{"atb":[[2.86,0]],"id":67130716}],"con":true,"img":false}]}
{"op":"mcm","clk":"11541450217","pt":1719505879773,"mc":[{"id":"1.230180133","rc":[{"atb":[[2.9,3.6]],"id":67130716}],"con":true,"img":false}]}
{"op":"mcm","clk":"11541450234","pt":1719505879978,"mc":[{"id":"1.230180133","rc":[{"atb":[[5.6,0]],"id":53826530}],"con":true,"img":false}]}
{"op":"mcm","clk":"11541450252","pt":1719505880183,"mc":[{"id":"1.230180133","rc":[{"atb":[[5.7,0]],"id":53826530}],"con":true,"img":false}]}
{"op":"mcm","clk":"11541450262","pt":1719505880289,"mc":[{"id":"1.230180133","rc":[{"atb":[[5.6,5.78],[5.5,0]],"id":53826530}],"con":true,"img":false}]}
{"op":"mcm","clk":"11541450271","pt":1719505880389,"mc":[{"id":"1.230180133","rc":[{"atb":[[2.9,2]],"id":67130716}],"con":true,"img":false}]}
{"op":"mcm","clk":"11541450285","pt":1719505880493,"mc":[{"id":"1.230180133","rc":[{"atb":[[5.6,0]],"id":53826530}],"con":true,"img":false}]}
{"op":"mcm","clk":"11541450293","pt":1719505880590,"mc":[{"id":"1.230180133","rc":[{"atb":[[5.5,4.66]],"id":53826530}],"con":true,"img":false}]}
{"op":"mcm","clk":"11541450309","pt":1719505880801,"mc":[{"id":"1.230180133","rc":[{"atb":[[2.46,0],[2.26,10]],"id":67487134},{"atb":[[1.46,0],[1.58,2],[1.57,0],[1.49,0],[1.53,0],[1.31,10]],"id":66314580},{"atl":[[3.45,7.77]],"id":66314580},{"atb":[[4.8,0],[3.35,0],[3.75,10]],"id":53826530},{"atl":[[10.5,13.03],[11,0]],"id":53826530},{"atb":[[2.02,0],[1.84,12.12]],"id":70086038},{"atb":[[1.89,9.8],[1.81,0]],"id":64618726},{"atb":[[2.36,0],[2.24,7.5]],"id":67130716}],"con":true,"img":false}]}
{"op":"mcm","clk":"11541450320","pt":1719505880901,"mc":[{"id":"1.230180133","rc":[{"atl":[[3.55,0],[2.98,3.75]],"id":66314580},{"atb":[[2.24,0],[2.54,7.5]],"id":67130716}],"con":true,"img":false}]}
{"op":"mcm","clk":"11541450330","pt":1719505881005,"mc":[{"id":"1.230180133","rc":[{"atl":[[7.4,5],[8.4,14.51]],"id":67487134},{"atb":[[1.31,20],[1.39,2.5],[1.35,5]],"id":66314580},{"atl":[[3.45,0],[3.3,13.04],[3.05,0.84]],"id":66314580}],"con":true,"img":false}]}
{"op":"mcm","clk":"11541450342","pt":1719505881112,"mc":[{"id":"1.230180133","rc":[{"atb":[[5.5,9.37]],"id":53826530}],"con":true,"img":false}]}
{"op":"mcm","clk":"11541450378","pt":1719505881474,"mc":[{"id":"1.230180133","rc":[{"atl":[[2.96,0.84],[3.05,0]],"id":66314580}],"con":true,"img":false}]}
{"op":"mcm","clk":"11541450465","pt":1719505882501,"mc":[{"id":"1.230180133","rc":[{"atb":[[1.58,0]],"id":66314580}],"con":true,"img":false}]}
{"op":"mcm","clk":"11541450473","pt":1719505882602,"mc":[{"id":"1.230180133","rc":[{"atb":[[3,11.07]],"id":67487134},{"atb":[[1.57,2]],"id":66314580},{"atb":[[5.6,1]],"id":53826530}],"con":true,"img":false}]}
{"op":"mcm","clk":"11541450483","pt":1719505882710,"mc":[{"id":"1.230180133","rc":[{"atb":[[2.98,1.94]],"id":67487134}],"con":true,"img":false}]}
{"op":"mcm","clk":"11541450491","pt":1719505882809,"mc":[{"id":"1.230180133","rc":[{"atb":[[5.7,5.91]],"id":53826530}],"con":true,"img":false}]}
{"op":"mcm","clk":"11541450507","pt":1719505883015,"mc":[{"id":"1.230180133","rc":[{"atb":[[5.5,4.71]],"id":53826530}],"con":true,"img":false}]}
{"op":"mcm","clk":"11541450531","pt":1719505883283,"mc":[{"id":"1.230180133","rc":[{"atb":[[3.05,1.48]],"id":67487134}],"con":true,"img":false}]}
{"op":"mcm","clk":"11541450545","pt":1719505883491,"mc":[{"id":"1.230180133","rc":[{"atb":[[5.6,0],[5.5,0]],"id":53826530}],"con":true,"img":false}]}
{"op":"mcm","clk":"11541450554","pt":1719505883588,"mc":[{"id":"1.230180133","rc":[{"atb":[[5.7,0]],"id":53826530}],"con":true,"img":false}]}
{"op":"mcm","clk":"11541450563","pt":1719505883697,"mc":[{"id":"1.230180133","rc":[{"atb":[[3.8,8.12]],"id":53826530}],"con":true,"img":false}]}
{"op":"mcm","clk":"11541450572","pt":1719505883795,"mc":[{"id":"1.230180133","rc":[{"atb":[[5.5,7.47]],"id":53826530}],"con":true,"img":false}]}
{"op":"mcm","clk":"11541450598","pt":1719505884102,"mc":[{"id":"1.230180133","rc":[{"atb":[[1.02,0]],"id":53826530}],"con":true,"img":false}]}
{"op":"mcm","clk":"11541450605","pt":1719505884211,"mc":[{"id":"1.230180133","rc":[{"atb":[[3.85,2]],"id":53826530}],"con":true,"img":false}]}
{"op":"mcm","clk":"11541450616","pt":1719505884306,"mc":[{"id":"1.230180133","rc":[{"atb":[[5.5,12.02]],"id":53826530}],"con":true,"img":false}]}
{"op":"mcm","clk":"11541450624","pt":1719505884415,"mc":[{"id":"1.230180133","rc":[{"atb":[[3.9,2.12]],"id":53826530}],"con":true,"img":false}]}
{"op":"mcm","clk":"11541450633","pt":1719505884514,"mc":[{"id":"1.230180133","rc":[{"atb":[[3.9,0]],"id":53826530}],"con":true,"img":false}]}
{"op":"mcm","clk":"11541450677","pt":1719505884989,"mc":[{"id":"1.230180133","rc":[{"atb":[[3.85,0]],"id":53826530}],"con":true,"img":false}]}
{"op":"mcm","clk":"11541450686","pt":1719505885093,"mc":[{"id":"1.230180133","rc":[{"atb":[[1.02,2]],"id":53826530}],"con":true,"img":false}]}
{"op":"mcm","clk":"11541450752","pt":1719505885820,"mc":[{"id":"1.230180133","rc":[{"atb":[[1.54,5.15]],"id":66314580},{"atb":[[2.06,5.05]],"id":64618726}],"con":true,"img":false}]}
{"op":"mcm","clk":"11541450762","pt":1719505885915,"mc":[{"id":"1.230180133","rc":[{"atb":[[5.6,1]],"id":53826530}],"con":true,"img":false}]}
{"op":"mcm","clk":"11541450824","pt":1719505886496,"mc":[{"id":"1.230180133","rc":[{"atb":[[2.6,5]],"id":67487134},{"atb":[[1.39,7.5],[1.31,10]],"id":66314580},{"atb":[[1.84,0],[2.08,14.24]],"id":70086038}],"con":true,"img":false}]}
{"op":"mcm","clk":"11541450833","pt":1719505886598,"mc":[{"id":"1.230180133","rc":[{"atb":[[2.26,0]],"id":67487134},{"atb":[[2.28,5.69]],"id":70086038},{"atb":[[2.1,10.04]],"id":64618726},{"atb":[[2.88,7.9]],"id":67130716}],"con":true,"img":false}]}
{"op":"mcm","clk":"11541450843","pt":1719505886709,"mc":[{"id":"1.230180133","rc":[{"atb":[[2.3,3]],"id":70086038},{"atb":[[2.1,13.36],[2.08,2]],"id":64618726},{"atb":[[2.9,4]],"id":67130716}],"con":true,"img":false}]}
{"op":"mcm","clk":"11541450854","pt":1719505886807,"mc":[{"id":"1.230180133","rc":[{"atb":[[2.26,4.23]],"id":70086038}],"con":true,"img":false}]}
{"op":"mcm","clk":"11541450868","pt":1719505886909,"mc":[{"id":"1.230180133","rc":[{"atb":[[2.12,1.6]],"id":64618726}],"con":true,"img":false}]}
{"op":"mcm","clk":"11541450877","pt":1719505887015,"mc":[{"id":"1.230180133","rc":[{"atb":[[2.06,0]],"id":64618726}],"con":true,"img":false}]}
{"op":"mcm","clk":"11541450904","pt":1719505887317,"mc":[{"id":"1.230180133","rc":[{"atb":[[1.84,0],[1.93,2.5],[1.92,0],[1.88,0]],"id":64618726}],"con":true,"img":false}]}
{"op":"mcm","clk":"11541450996","pt":1719505888315,"mc":[{"id":"1.230180133","rc":[{"atb":[[5.4,0]],"id":53826530}],"con":true,"img":false}]}
{"op":"mcm","clk":"11541451033","pt":1719505888624,"mc":[{"id":"1.230180133","rc":[{"atb":[[2.08,0]],"id":64618726}],"con":true,"img":false}]}
{"op":"mcm","clk":"11541451042","pt":1719505888724,"mc":[{"id":"1.230180133","rc":[{"atb":[[2.12,3.6]],"id":64618726}],"con":true,"img":false}]}
{"op":"mcm","clk":"11541451113","pt":1719505889403,"mc":[{"id":"1.230180133","rc":[{"atb":[[2.12,2]],"id":64618726}],"con":true,"img":false}]}
{"op":"mcm","clk":"11541451142","pt":1719505889810,"mc":[{"id":"1.230180133","rc":[{"atb":[[3.75,13.88]],"id":53826530}],"con":true,"img":false}]}
{"op":"mcm","clk":"11541451200","pt":1719505890393,"mc":[{"id":"1.230180133","rc":[{"atb":[[2.3,8.42]],"id":70086038}],"con":true,"img":false}]}
{"op":"mcm","clk":"11541451209","pt":1719505890497,"mc":[{"id":"1.230180133","rc":[{"atb":[[2.26,0]],"id":70086038},{"atb":[[2.9,11.08]],"id":67130716}],"con":true,"img":false}]}
{"op":"mcm","clk":"11541451217","pt":1719505890608,"mc":[{"id":"1.230180133","rc":[{"atb":[[1.56,0],[1.44,2.11]],"id":66314580},{"atb":[[2.28,1.94]],"id":70086038},{"atb":[[2.88,1.94]],"id":67130716}],"con":true,"img":false}]}
{"op":"mcm","clk":"11541451248","pt":1719505890910,"mc":[{"id":"1.230180133","rc":[{"atb":[[5.5,4.55]],"id":53826530},{"atl":[[3.65,1]],"id":64618726},{"atb":[[2.54,0],[2.6,5]],"id":67130716}],"con":true,"img":false}]}
{"op":"mcm","clk":"11541451257","pt":1719505891008,"mc":[{"id":"1.230180133","rc":[{"atl":[[3.6,0]],"id":64618726}],"con":true,"img":false}]}
{"op":"mcm","clk":"11541451268","pt":1719505891113,"mc":[{"id":"1.230180133","rc":[{"atb":[[3.85,1.57]],"id":53826530},{"atb":[[2.92,1.6]],"id":67130716}],"con":true,"img":false}]}
{"op":"mcm","clk":"11541451279","pt":1719505891210,"mc":[{"id":"1.230180133","rc":[{"atb":[[1.57,0]],"id":66314580}],"con":true,"img":false}]}
{"op":"mcm","clk":"11541451288","pt":1719505891316,"mc":[{"id":"1.230180133","rc":[{"atb":[[1.55,2]],"id":66314580}],"con":true,"img":false}]}
{"op":"mcm","clk":"11541451349","pt":1719505891905,"mc":[{"id":"1.230180133","rc":[{"atb":[[5.5,6.55]],"id":53826530}],"con":true,"img":false}]}
{"op":"mcm","clk":"11541451390","pt":1719505892310,"mc":[{"id":"1.230180133","rc":[{"atb":[[3.75,10]],"id":53826530}],"con":true,"img":false}]}
{"op":"mcm","clk":"11541451457","pt":1719505893205,"mc":[{"id":"1.230180133","rc":[{"atl":[[2.8,4.4]],"id":66314580}],"con":true,"img":false}]}
{"op":"mcm","clk":"11541451466","pt":1719505893303,"mc":[{"id":"1.230180133","rc":[{"atl":[[2.98,5],[3.3,2.5]],"id":66314580}],"con":true,"img":false}]}
{"op":"mcm","clk":"11541451481","pt":1719505893511,"mc":[{"id":"1.230180133","rc":[{"atb":[[2.98,0]],"id":67487134},{"atb":[[2.28,0]],"id":70086038},{"atb":[[2.88,0]],"id":67130716}],"con":true,"img":false}]}
{"op":"mcm","clk":"11541451497","pt":1719505893718,"mc":[{"id":"1.230180133","rc":[{"atb":[[3.05,3.43]],"id":67487134},{"atb":[[2.32,1.94]],"id":70086038},{"atb":[[2.92,3.55]],"id":67130716}],"con":true,"img":false}]}
{"op":"mcm","clk":"11541451515","pt":1719505893914,"mc":[{"id":"1.230180133","rc":[{"atl":[[2.96,0],[2.78,0.84]],"id":66314580}],"con":true,"img":false}]}
{"op":"mcm","clk":"11541451528","pt":1719505894125,"mc":[{"id":"1.230180133","rc":[{"atb":[[3.05,1.94]],"id":67487134},{"atb":[[2.92,1.94]],"id":67130716}],"con":true,"img":false}]}
{"op":"mcm","clk":"11541451576","pt":1719505894819,"mc":[{"id":"1.230180133","rc":[{"atb":[[3,9.07]],"id":67487134}],"con":true,"img":false}]}
{"op":"mcm","clk":"11541451585","pt":1719505894909,"mc":[{"id":"1.230180133","rc":[{"atb":[[3.1,2],[3.05,11.01]],"id":67487134}],"con":true,"img":false}]}
{"op":"mcm","clk":"11541451594","pt":1719505895013,"mc":[{"id":"1.230180133","rc":[{"atb":[[3,0]],"id":67487134}],"con":true,"img":false}]}
{"op":"mcm","clk":"11541451612","pt":1719505895221,"mc":[{"id":"1.230180133","rc":[{"atb":[[2.9,9.08]],"id":67130716}],"con":true,"img":false}]}
{"op":"mcm","clk":"11541451620","pt":1719505895316,"mc":[{"id":"1.230180133","rc":[{"atb":[[2.3,5.42]],"id":70086038},{"atb":[[2.1,10.04]],"id":64618726},{"atb":[[2.9,7.08],[2.94,2]],"id":67130716}],"con":true,"img":false}]}
{"op":"mcm","clk":"11541451630","pt":1719505895414,"mc":[{"id":"1.230180133","rc":[{"atb":[[2.32,4.94]],"id":70086038},{"atb":[[2.12,5]],"id":64618726},{"atb":[[2.92,4.94]],"id":67130716}],"con":true,"img":false}]}
{"op":"mcm","clk":"11541451667","pt":1719505895889,"mc":[{"id":"1.230180133","rc":[{"atb":[[2.14,1.62]],"id":70086038}],"con":true,"img":false}]}
{"op":"mcm","clk":"11541451674","pt":1719505895995,"mc":[{"id":"1.230180133","rc":[{"atl":[[2.8,7.44]],"id":66314580},{"atl":[[3.7,11],[3.65,0]],"id":64618726}],"con":true,"img":false}]}
{"op":"mcm","clk":"11541451718","pt":1719505896509,"mc":[{"id":"1.230180133","rc":[{"atb":[[2.1,8.1]],"id":64618726}],"con":true,"img":false}]}
{"op":"mcm","clk":"11541451728","pt":1719505896608,"mc":[{"id":"1.230180133","rc":[{"atb":[[2.14,1.94]],"id":64618726},{"atl":[[4.3,19.25],[3.7,1]],"id":64618726}],"con":true,"img":false}]}
{"op":"mcm","clk":"11541451854","pt":1719505898108,"mc":[{"id":"1.230180133","rc":[{"atb":[[5.7,0.52]],"id":53826530}],"con":true,"img":false}]}
{"op":"mcm","clk":"11541451869","pt":1719505898312,"mc":[{"id":"1.230180133","rc":[{"atb":[[5.6,0]],"id":53826530}],"con":true,"img":false}]}
{"op":"mcm","clk":"11541451913","pt":1719505898824,"mc":[{"id":"1.230180133","rc":[{"atb":[[2.14,10]],"id":64618726}],"con":true,"img":false}]}
{"op":"mcm","clk":"11541451920","pt":1719505898927,"mc":[{"id":"1.230180133","rc":[{"atb":[[2.16,1.6]],"id":64618726}],"con":true,"img":false}]}
{"op":"mcm","clk":"11541451931","pt":1719505899030,"mc":[{"id":"1.230180133","rc":[{"atb":[[2.1,0]],"id":64618726}],"con":true,"img":false}]}
{"op":"mcm","clk":"11541451974","pt":1719505899505,"mc":[{"id":"1.230180133","rc":[{"atb":[[2.12,3]],"id":64618726}],"con":true,"img":false}]}
{"op":"mcm","clk":"11541451982","pt":1719505899609,"mc":[{"id":"1.230180133","rc":[{"atb":[[2.16,3.6]],"id":64618726}],"con":true,"img":false}]}
{"op":"mcm","clk":"11541452036","pt":1719505900220,"mc":[{"id":"1.230180133","rc":[{"atb":[[2.16,2]],"id":64618726}],"con":true,"img":false}]}
{"op":"mcm","clk":"11541452044","pt":1719505900323,"mc":[{"id":"1.230180133","rc":[{"atb":[[5.8,1]],"id":53826530}],"con":true,"img":false}]}
{"op":"mcm","clk":"11541452101","pt":1719505901002,"mc":[{"id":"1.230180133","rc":[{"atb":[[5.5,4.55],[5.7,2.52]],"id":53826530}],"con":true,"img":false}]}
{"op":"mcm","clk":"11541452214","pt":1719505902502,"mc":[{"id":"1.230180133","rc":[{"atl":[[2.8,4.4]],"id":66314580},{"atb":[[2.32,10.53]],"id":70086038}],"con":true,"img":false}]}
{"op":"mcm","clk":"11541452222","pt":1719505902613,"mc":[{"id":"1.230180133","rc":[{"atb":[[2.72,10],[2.6,0]],"id":67487134},{"atb":[[2.3,0],[2.12,14.56],[2.08,0]],"id":70086038},{"atb":[[2.94,9.79]],"id":67130716}],"con":true,"img":false}]}
{"op":"mcm","clk":"11541452238","pt":1719505902823,"mc":[{"id":"1.230180133","rc":[{"atb":[[2.9,0]],"id":67130716}],"con":true,"img":false}]}
{"op":"mcm","clk":"11541452269","pt":1719505903122,"mc":[{"id":"1.230180133","rc":[{"atb":[[2.96,1.6]],"id":67130716}],"con":true,"img":false}]}
{"op":"mcm","clk":"11541452346","pt":1719505904010,"mc":[{"id":"1.230180133","rc":[{"atb":[[2.32,7.53]],"id":70086038},{"atb":[[2.12,0]],"id":64618726},{"atb":[[2.92,1.94]],"id":67130716}],"con":true,"img":false}]}
{"op":"mcm","clk":"11541452357","pt":1719505904119,"mc":[{"id":"1.230180133","rc":[{"atb":[[2.34,3.26]],"id":70086038},{"atb":[[2.16,4]],"id":64618726},{"atb":[[2.96,4.9]],"id":67130716}],"con":true,"img":false}]}
{"op":"mcm","clk":"11541452421","pt":1719505904727,"mc":[{"id":"1.230180133","rc":[{"atb":[[2.94,7.79]],"id":67130716}],"con":true,"img":false}]}
{"op":"mcm","clk":"11541452432","pt":1719505904829,"mc":[{"id":"1.230180133","rc":[{"atb":[[2.98,2]],"id":67130716}],"con":true,"img":false}]}
{"op":"mcm","clk":"11541452440","pt":1719505904932,"mc":[{"id":"1.230180133","rc":[{"atb":[[2.96,3.3]],"id":67130716}],"con":true,"img":false}]}
{"op":"mcm","clk":"11541452476","pt":1719505905250,"mc":[{"id":"1.230180133","rc":[{"atl":[[2.76,4.89]],"id":66314580}],"con":true,"img":false}]}
{"op":"mcm","clk":"11541452505","pt":1719505905428,"mc":[{"id":"1.230180133","rc":[{"atl":[[2.98,0]],"id":66314580}],"con":true,"img":false}]}
{"op":"mcm","clk":"11541452564","pt":1719505905940,"mc":[{"id":"1.230180133","rc":[{"atl":[[2.74,0.85]],"id":66314580}],"con":true,"img":false}]}
{"op":"mcm","clk":"11541452574","pt":1719505906038,"mc":[{"id":"1.230180133","rc":[{"atb":[[3.75,0],[3.45,9.1]],"id":53826530}],"con":true,"img":false}]}
{"op":"mcm","clk":"11541452606","pt":1719505906318,"mc":[{"id":"1.230180133","rc":[{"atl":[[2.74,3.39]],"id":66314580}],"con":true,"img":false}]}
{"op":"mcm","clk":"11541452614","pt":1719505906419,"mc":[{"id":"1.230180133","rc":[{"atl":[[2.8,0],[2.72,3.39]],"id":66314580}],"con":true,"img":false}]}
{"op":"mcm","clk":"11541452664","pt":1719505906949,"mc":[{"id":"1.230180133","rc":[{"atb":[[3.1,11.07]],"id":67487134},{"atl":[[2.78,0]],"id":66314580}],"con":true,"img":false}]}
{"op":"mcm","clk":"11541452683","pt":1719505907154,"mc":[{"id":"1.230180133","rc":[{"atb":[[3.05,1.94]],"id":67487134},{"atb":[[1.54,0]],"id":66314580}],"con":true,"img":false}]}
{"op":"mcm","clk":"11541452709","pt":1719505907358,"mc":[{"id":"1.230180133","rc":[{"atb":[[3.15,1.48]],"id":67487134}],"con":true,"img":false}]}
{"op":"mcm","clk":"11541452799","pt":1719505908135,"mc":[{"id":"1.230180133","rc":[{"atb":[[1.55,0]],"id":66314580}],"con":true,"img":false}]}
{"op":"mcm","clk":"11541452806","pt":1719505908240,"mc":[{"id":"1.230180133","rc":[{"atb":[[1.44,7.19],[1.45,2],[1.39,2.5],[1.38,5]],"id":66314580}],"con":true,"img":false}]}
{"op":"mcm","clk":"11541452817","pt":1719505908348,"mc":[{"id":"1.230180133","rc":[{"atl":[[2.74,0.85]],"id":66314580}],"con":true,"img":false}]}
{"op":"mcm","clk":"11541452935","pt":1719505909534,"mc":[{"id":"1.230180133","rc":[{"atb":[[2.32,10.03],[2.12,9.56],[2.24,5],[2.2,0],[2.16,10]],"id":70086038},{"atb":[[2.12,4.78]],"id":64618726}],"con":true,"img":false}]}
{"op":"mcm","clk":"11541453008","pt":1719505910525,"mc":[{"id":"1.230180133","rc":[{"atb":[[1.43,5.42]],"id":66314580}],"con":true,"img":false}]}
{"op":"mcm","clk":"11541453015","pt":1719505910633,"mc":[{"id":"1.230180133","rc":[{"atb":[[2.12,0]],"id":64618726}],"con":true,"img":false}]}
{"op":"mcm","clk":"11541453023","pt":1719505910725,"mc":[{"id":"1.230180133","rc":[{"atb":[[2.16,11.31]],"id":64618726}],"con":true,"img":false}]}
{"op":"mcm","clk":"11541453038","pt":1719505910929,"mc":[{"id":"1.230180133","rc":[{"atb":[[2.18,1.6],[2.14,1.94]],"id":64618726}],"con":true,"img":false}]}
{"op":"mcm","clk":"11541453046","pt":1719505911030,"mc":[{"id":"1.230180133","rc":[{"atl":[[2.7,2.53]],"id":66314580}],"con":true,"img":false}]}
{"op":"mcm","clk":"11541453077","pt":1719505911351,"mc":[{"id":"1.230180133","rc":[{"atb":[[2.12,4.06]],"id":64618726}],"con":true,"img":false}]}
{"op":"mcm","clk":"11541453085","pt":1719505911445,"mc":[{"id":"1.230180133","rc":[{"atb":[[1.39,9.92],[1.38,0]],"id":66314580},{"atl":[[2.74,0]],"id":66314580},{"atb":[[3.6,0],[3.8,5.62],[3.4,0]],"id":53826530},{"atl":[[3.7,0],[3.75,1]],"id":64618726}],"con":true,"img":false}]}
{"op":"mcm","clk":"11541453093","pt":1719505911547,"mc":[{"id":"1.230180133","rc":[{"atb":[[2.32,14.04]],"id":70086038},{"atb":[[2.12,0]],"id":64618726},{"atl":[[4.3,2.5],[3.7,11.5]],"id":64618726}],"con":true,"img":false}]}
{"op":"mcm","clk":"11541453120","pt":1719505911923,"mc":[{"id":"1.230180133","rc":[{"atb":[[2.8,0],[2.82,2.5],[2.72,5]],"id":67487134}],"con":true,"img":false}]}
{"op":"mcm","clk":"11541453132","pt":1719505912136,"mc":[{"id":"1.230180133","rc":[{"atb":[[3.85,0]],"id":53826530},{"atb":[[2.14,0]],"id":70086038},{"atb":[[2.18,0]],"id":64618726}],"con":true,"img":false}]}
{"op":"mcm","clk":"11541453143","pt":1719505912250,"mc":[{"id":"1.230180133","rc":[{"atb":[[2.34,4.88]],"id":70086038}],"con":true,"img":false}]}
{"op":"mcm","clk":"11541453190","pt":1719505912651,"mc":[{"id":"1.230180133","rc":[{"atb":[[2.16,9.31]],"id":64618726},{"atb":[[2.96,0]],"id":67130716}],"con":true,"img":false}]}
{"op":"mcm","clk":"11541453209","pt":1719505912812,"mc":[{"id":"1.230180133","rc":[{"atb":[[1.45,7.46]],"id":66314580},{"atb":[[2.18,2.66]],"id":64618726},{"atb":[[2.98,4.1]],"id":67130716}],"con":true,"img":false}]}
{"op":"mcm","clk":"11541453219","pt":1719505912921,"mc":[{"id":"1.230180133","rc":[{"atl":[[2.68,0.85]],"id":66314580}],"con":true,"img":false}]}
{"op":"mcm","clk":"11541453262","pt":1719505913324,"mc":[{"id":"1.230180133","rc":[{"atb":[[1.46,1.69]],"id":66314580}],"con":true,"img":false}]}
{"op":"mcm","clk":"11541453282","pt":1719505913540,"mc":[{"id":"1.230180133","rc":[{"atb":[[5.7,2]],"id":53826530},{"atb":[[2.16,7.31]],"id":64618726}],"con":true,"img":false}]}
{"op":"mcm","clk":"11541453290","pt":1719505913634,"mc":[{"id":"1.230180133","rc":[{"atb":[[2.2,2]],"id":64618726}],"con":true,"img":false}]}
{"op":"mcm","clk":"11541453313","pt":1719505913941,"mc":[{"id":"1.230180133","rc":[{"atb":[[1.43,0]],"id":66314580}],"con":true,"img":false}]}
{"op":"mcm","clk":"11541453353","pt":1719505914414,"mc":[{"id":"1.230180133","rc":[{"atb":[[2.34,12.29]],"id":70086038}],"con":true,"img":false}]}
{"op":"mcm","clk":"11541453362","pt":1719505914557,"mc":[{"id":"1.230180133","rc":[{"atb":[[2.32,8.45]],"id":70086038},{"atb":[[2.98,11.25]],"id":67130716}],"con":true,"img":false}]}
{"op":"mcm","clk":"11541453376","pt":1719505914724,"mc":[{"id":"1.230180133","rc":[{"atb":[[2.94,0]],"id":67130716}],"con":true,"img":false}]}
{"op":"mcm","clk":"11541453397","pt":1719505915029,"mc":[{"id":"1.230180133","rc":[{"atb":[[2.4,2.11],[2.12,7.45]],"id":70086038}],"con":true,"img":false}]}
{"op":"mcm","clk":"11541453408","pt":1719505915163,"mc":[{"id":"1.230180133","rc":[{"atb":[[3,1.6]],"id":67130716}],"con":true,"img":false}]}
{"op":"mcm","clk":"11541453457","pt":1719505915636,"mc":[{"id":"1.230180133","rc":[{"atb":[[2.32,4.44]],"id":70086038}],"con":true,"img":false}]}
{"op":"mcm","clk":"11541453538","pt":1719505916657,"mc":[{"id":"1.230180133","rc":[{"atb":[[5.7,0]],"id":53826530},{"atl":[[3.7,0],[3.75,18.25]],"id":64618726}],"con":true,"img":false}]}
{"op":"mcm","clk":"11541453548","pt":1719505916755,"mc":[{"id":"1.230180133","rc":[{"atb":[[5.5,6.67]],"id":53826530}],"con":true,"img":false}]}
{"op":"mcm","clk":"11541453557","pt":1719505916858,"mc":[{"id":"1.230180133","rc":[{"atl":[[4.3,26.5],[3.75,1]],"id":64618726}],"con":true,"img":false}]}
{"op":"mcm","clk":"11541453562","pt":1719505916919,"mc":[{"id":"1.230180133","rc":[{"atb":[[5.8,0]],"id":53826530}],"con":true,"img":false}]}
{"op":"mcm","clk":"11541453570","pt":1719505917018,"mc":[{"id":"1.230180133","rc":[{"atl":[[2.68,5.3]],"id":66314580}],"con":true,"img":false}]}
{"op":"mcm","clk":"11541453580","pt":1719505917123,"mc":[{"id":"1.230180133","rc":[{"atl":[[2.72,0],[2.66,3.39]],"id":66314580},{"atb":[[3,5],[2.92,10],[3.2,2.5]],"id":53826530}],"con":true,"img":false}]}
{"op":"mcm","clk":"11541453589","pt":1719505917224,"mc":[{"id":"1.230180133","rc":[{"atl":[[2.66,0],[2.68,12.08],[2.76,0]],"id":66314580}],"con":true,"img":false}]}
{"op":"mcm","clk":"11541453608","pt":1719505917430,"mc":[{"id":"1.230180133","rc":[{"spn":4.87,"spf":"NaN","id":67487134},{"spn":1.58,"spf":1.0,"id":66314580},{"atb":[[5.5,2.12]],"id":53826530},{"spn":7.75,"spf":"NaN","id":53826530},{"spn":3.25,"spf":"NaN","id":70086038},{"spn":2.85,"spf":"NaN","id":64618726},{"spn":4.8,"spf":"NaN","id":67130716}],"con":true,"img":false}]}
{"op":"mcm","clk":"11541453643","pt":1719505917841,"mc":[{"id":"1.230180133","rc":[{"atb":[[5.5,0]],"id":53826530},{"atl":[[3.7,1],[3.75,0]],"id":64618726}],"con":true,"img":false}]}
{"op":"mcm","clk":"11541453652","pt":1719505917944,"mc":[{"id":"1.230180133","rc":[{"atb":[[3.85,6.22],[1.47,2.48]],"id":53826530},{"atl":[[4.3,2.5],[3.75,11.5]],"id":64618726}],"con":true,"img":false}]}
{"op":"mcm","clk":"11541453663","pt":1719505918046,"mc":[{"id":"1.230180133","rc":[{"atb":[[3.9,9.78]],"id":53826530}],"con":true,"img":false}]}
{"op":"mcm","clk":"11541453674","pt":1719505918153,"mc":[{"id":"1.230180133","rc":[{"atb":[[3.8,0],[3.9,11.35]],"id":53826530}],"con":true,"img":false}]}
{"op":"mcm","clk":"11541453721","pt":1719505918728,"mc":[{"id":"1.230180133","rc":[{"atb":[[3.15,10.55]],"id":67487134}],"con":true,"img":false}]}
{"op":"mcm","clk":"11541453738","pt":1719505918931,"mc":[{"id":"1.230180133","rc":[{"atb":[[3.1,2]],"id":67487134},{"atl":[[2.7,0]],"id":66314580},{"atb":[[3.95,1],[1.02,0]],"id":53826530}],"con":true,"img":false}]}
{"op":"mcm","clk":"11541453747","pt":1719505919032,"mc":[{"id":"1.230180133","rc":[{"atl":[[3.25,24.16],[2.68,5.3]],"id":66314580},{"atb":[[3.95,3]],"id":53826530}],"con":true,"img":false}]}
{"op":"mcm","clk":"11541453761","pt":1719505919237,"mc":[{"id":"1.230180133","rc":[{"atl":[[2.7,3.22]],"id":66314580}],"con":true,"img":false}]}
{"op":"mcm","clk":"11541453777","pt":1719505919439,"mc":[{"id":"1.230180133","rc":[{"atb":[[3.8,4.5]],"id":53826530}],"con":true,"img":false}]}
{"op":"mcm","clk":"11541453830","pt":1719505920059,"mc":[{"id":"1.230180133","rc":[{"atb":[[1.46,11.07]],"id":66314580}],"con":true,"img":false}]}
{"op":"mcm","clk":"11541453848","pt":1719505920224,"mc":[{"id":"1.230180133","rc":[{"atb":[[1.44,2.11]],"id":66314580},{"atb":[[3,0],[2.92,0],[3.2,0]],"id":53826530}],"con":true,"img":false}]}
{"op":"mcm","clk":"11541453872","pt":1719505920538,"mc":[{"id":"1.230180133","rc":[{"atb":[[3.1,0]],"id":67487134}],"con":true,"img":false}]}
{"op":"mcm","clk":"11541453881","pt":1719505920641,"mc":[{"id":"1.230180133","rc":[{"atb":[[3.2,2]],"id":67487134}],"con":true,"img":false}]}
{"op":"mcm","clk":"11541453917","pt":1719505921149,"mc":[{"id":"1.230180133","rc":[{"atb":[[3.15,9.07]],"id":67487134}],"con":true,"img":false}]}
{"op":"mcm","clk":"11541453940","pt":1719505921350,"mc":[{"id":"1.230180133","rc":[{"atb":[[1.45,2]],"id":66314580},{"atb":[[2.34,9.03]],"id":70086038},{"atb":[[2.18,0]],"id":64618726},{"atb":[[2.98,9.15]],"id":67130716}],"con":true,"img":false}]}
{"op":"mcm","clk":"11541453947","pt":1719505921455,"mc":[{"id":"1.230180133","rc":[{"atb":[[1.47,4]],"id":66314580},{"atb":[[3.95,6]],"id":53826530},{"atb":[[2.4,5.01]],"id":70086038},{"atb":[[2.2,4]],"id":64618726},{"atb":[[3,4.52]],"id":67130716}],"con":true,"img":false}]}
{"op":"mcm","clk":"11541453966","pt":1719505921661,"mc":[{"id":"1.230180133","rc":[{"atl":[[2.66,2.53]],"id":66314580}],"con":true,"img":false}]}
{"op":"mcm","clk":"11541453981","pt":1719505921841,"mc":[{"id":"1.230180133","rc":[{"atb":[[1.46,9.38],[1.45,0]],"id":66314580},{"atb":[[3.9,9.78]],"id":53826530},{"atb":[[2.34,7.41]],"id":70086038},{"atb":[[3,2.92]],"id":67130716}],"con":true,"img":false}]}
{"op":"mcm","clk":"11541453989","pt":1719505921973,"mc":[{"id":"1.230180133","rc":[{"atb":[[1.47,6]],"id":66314580},{"atb":[[4,1.57]],"id":53826530}],"con":true,"img":false}]}
{"op":"mcm","clk":"11541454004","pt":1719505922140,"mc":[{"id":"1.230180133","rc":[{"atb":[[3.95,5]],"id":53826530}],"con":true,"img":false}]}
{"op":"mcm","clk":"11541454012","pt":1719505922235,"mc":[{"id":"1.230180133","rc":[{"atb":[[2.2,2]],"id":64618726}],"con":true,"img":false}]}
{"op":"mcm","clk":"11541454021","pt":1719505922336,"mc":[{"id":"1.230180133","rc":[{"atb":[[1.48,1.69]],"id":66314580},{"atb":[[2.18,2]],"id":64618726}],"con":true,"img":false}]}
{"op":"mcm","clk":"11541454027","pt":1719505922438,"mc":[{"id":"1.230180133","rc":[{"atl":[[2.64,0.84]],"id":66314580},{"atb":[[4,0]],"id":53826530},{"atb":[[2.2,7.81]],"id":64618726}],"con":true,"img":false}]}
{"op":"mcm","clk":"11541454036","pt":1719505922541,"mc":[{"id":"1.230180133","rc":[{"atb":[[3.95,6.57]],"id":53826530}],"con":true,"img":false}]}
{"op":"mcm","clk":"11541454044","pt":1719505922655,"mc":[{"id":"1.230180133","rc":[{"atb":[[2.16,0]],"id":64618726}],"con":true,"img":false}]}
{"op":"mcm","clk":"11541454087","pt":1719505923166,"mc":[{"id":"1.230180133","rc":[{"atl":[[2.7,0]],"id":66314580},{"atb":[[1.47,0]],"id":53826530}],"con":true,"img":false}]}
{"op":"mcm","clk":"11541454199","pt":1719505924263,"mc":[{"id":"1.230180133","rc":[{"atb":[[2.98,7.15]],"id":67130716}],"con":true,"img":false}]}
{"op":"mcm","clk":"11541454211","pt":1719505924370,"mc":[{"id":"1.230180133","rc":[{"atl":[[2.66,7.83],[3.25,0]],"id":66314580},{"atb":[[4,1]],"id":53826530},{"atb":[[3.05,2]],"id":67130716}],"con":true,"img":false}]}
{"op":"mcm","clk":"11541454227","pt":1719505924575,"mc":[{"id":"1.230180133","rc":[{"atb":[[4,1.52]],"id":53826530}],"con":true,"img":false}]}
{"op":"mcm","clk":"11541454248","pt":1719505924744,"mc":[{"id":"1.230180133","rc":[{"atb":[[2.18,0]],"id":64618726}],"con":true,"img":false}]}
{"op":"mcm","clk":"11541454262","pt":1719505924847,"mc":[{"id":"1.230180133","rc":[{"atb":[[2.22,2]],"id":64618726}],"con":true,"img":false}]}
{"op":"mcm","clk":"11541454302","pt":1719505925140,"mc":[{"id":"1.230180133","rc":[{"atl":[[2.8,2.5],[3.3,0],[3.5,0],[2.88,5],[3.7,0],[2.96,10]],"id":66314580}],"con":true,"img":false}]}
{"op":"mcm","clk":"11541454341","pt":1719505925455,"mc":[{"id":"1.230180133","rc":[{"atb":[[2.58,0],[2.66,0]],"id":67130716}],"con":true,"img":false}]}
{"op":"mcm","clk":"11541454403","pt":1719505926039,"mc":[{"id":"1.230180133","rc":[{"atb":[[3.8,0]],"id":53826530},{"atb":[[2.4,12.11]],"id":70086038}],"con":true,"img":false}]}
{"op":"mcm","clk":"11541454413","pt":1719505926135,"mc":[{"id":"1.230180133","rc":[{"atb":[[2.34,0]],"id":70086038},{"atb":[[3.05,8.27]],"id":67130716}],"con":true,"img":false}]}
{"op":"mcm","clk":"11541454430","pt":1719505926340,"mc":[{"id":"1.230180133","rc":[{"atb":[[2.98,0]],"id":67130716}],"con":true,"img":false}]}
{"op":"mcm","clk":"11541454439","pt":1719505926438,"mc":[{"id":"1.230180133","rc":[{"atb":[[2.8,2.5],[2.72,5],[2.64,10]],"id":67130716}],"con":true,"img":false}]}
{"op":"mcm","clk":"11541454450","pt":1719505926540,"mc":[{"id":"1.230180133","rc":[{"atb":[[2.42,1.62]],"id":70086038},{"atb":[[3.1,1.6]],"id":67130716}],"con":true,"img":false}]}
{"op":"mcm","clk":"11541454507","pt":1719505927161,"mc":[{"id":"1.230180133","rc":[{"atb":[[1.44,0],[1.49,2.11]],"id":66314580}],"con":true,"img":false}]}
{"op":"mcm","clk":"11541454653","pt":1719505928649,"mc":[{"id":"1.230180133","rc":[{"atl":[[2.64,6.4]],"id":66314580}],"con":true,"img":false}]}
{"op":"mcm","clk":"11541454671","pt":1719505928853,"mc":[{"id":"1.230180133","rc":[{"atl":[[2.68,0.85]],"id":66314580}],"con":true,"img":false}]}
{"op":"mcm","clk":"11541454720","pt":1719505929472,"mc":[{"id":"1.230180133","rc":[{"atl":[[2.68,0]],"id":66314580},{"atb":[[4.1,2.12]],"id":53826530}],"con":true,"img":false}]}
{"op":"mcm","clk":"11541454730","pt":1719505929574,"mc":[{"id":"1.230180133","rc":[{"atb":[[4.1,8.82]],"id":53826530}],"con":true,"img":false}]}
{"op":"mcm","clk":"11541454739","pt":1719505929633,"mc":[{"id":"1.230180133","rc":[{"atb":[[4,0.52],[4.1,17.5]],"id":53826530}],"con":true,"img":false}]}
{"op":"mcm","clk":"11541454752","pt":1719505929742,"mc":[{"id":"1.230180133","rc":[{"atb":[[3.85,0]],"id":53826530}],"con":true,"img":false}]}
{"op":"mcm","clk":"11541454763","pt":1719505929841,"mc":[{"id":"1.230180133","rc":[{"atb":[[3.9,0]],"id":53826530}],"con":true,"img":false}]}
{"op":"mcm","clk":"11541454772","pt":1719505929965,"mc":[{"id":"1.230180133","rc":[{"atb":[[1.47,2]],"id":66314580},{"atb":[[3.95,3.57]],"id":53826530},{"atb":[[2.4,9.21]],"id":70086038},{"atb":[[2.2,5.81]],"id":64618726},{"atb":[[3,0]],"id":67130716}],"con":true,"img":false}]}
{"op":"mcm","clk":"11541454784","pt":1719505930044,"mc":[{"id":"1.230180133","rc":[{"atb":[[1.49,5.01]],"id":66314580},{"atl":[[2.66,5.3]],"id":66314580},{"atb":[[4.2,2.5]],"id":53826530},{"atb":[[2.42,4.52]],"id":70086038},{"atb":[[2.22,4.5]],"id":64618726},{"atb":[[3.1,3.7]],"id":67130716}],"con":true,"img":false}]}
{"op":"mcm","clk":"11541454803","pt":1719505930278,"mc":[{"id":"1.230180133","rc":[{"atb":[[1.48,0]],"id":66314580},{"atl":[[2.8,14.21],[2.66,0]],"id":66314580},{"atb":[[3.95,2]],"id":53826530},{"atb":[[2.42,2.9]],"id":70086038},{"atb":[[3.1,2.1]],"id":67130716}],"con":true,"img":false}]}
{"op":"mcm","clk":"11541454814","pt":1719505930355,"mc":[{"id":"1.230180133","rc":[{"atb":[[3.2,11.07]],"id":67487134},{"atb":[[4.2,4.07]],"id":53826530}],"con":true,"img":false}]}
{"op":"mcm","clk":"11541454823","pt":1719505930464,"mc":[{"id":"1.230180133","rc":[{"atb":[[3.15,0]],"id":67487134},{"atb":[[4.2,10.38]],"id":53826530}],"con":true,"img":false}]}
{"op":"mcm","clk":"11541454854","pt":1719505930761,"mc":[{"id":"1.230180133","rc":[{"atb":[[3.25,1.48]],"id":67487134}],"con":true,"img":false}]}
{"op":"mcm","clk":"11541454919","pt":1719505931543,"mc":[{"id":"1.230180133","rc":[{"atb":[[1.49,13.58]],"id":66314580}],"con":true,"img":false}]}
{"op":"mcm","clk":"11541454930","pt":1719505931649,"mc":[{"id":"1.230180133","rc":[{"atb":[[1.46,0]],"id":66314580},{"atb":[[4.3,1]],"id":53826530}],"con":true,"img":false}]}
{"op":"mcm","clk":"11541454939","pt":1719505931746,"mc":[{"id":"1.230180133","rc":[{"atl":[[8,0],[8.6,6],[8.8,0],[7.8,2.5]],"id":67130716}],"con":true,"img":false}]}
{"op":"mcm","clk":"11541454954","pt":1719505931961,"mc":[{"id":"1.230180133","rc":[{"atb":[[1.5,1.69]],"id":66314580}],"con":true,"img":false}]}
{"op":"mcm","clk":"11541454965","pt":1719505932064,"mc":[{"id":"1.230180133","rc":[{"atb":[[2.18,4.54]],"id":64618726}],"con":true,"img":false}]}
{"op":"mcm","clk":"11541455015","pt":1719505932475,"mc":[{"id":"1.230180133","rc":[{"atb":[[1.47,0]],"id":66314580}],"con":true,"img":false}]}
{"op":"mcm","clk":"11541455027","pt":1719505932575,"mc":[{"id":"1.230180133","rc":[{"atb":[[1.5,3.69]],"id":66314580},{"atl":[[4.6,10],[4.7,1]],"id":70086038}],"con":true,"img":false}]}
{"op":"mcm","clk":"11541455034","pt":1719505932682,"mc":[{"id":"1.230180133","rc":[{"atb":[[2.72,0],[2.6,5]],"id":67487134},{"atb":[[1.5,5.69],[1.39,2.5]],"id":66314580},{"atl":[[3.6,0],[3.5,1]],"id":66314580},{"atb":[[3.45,0],[3.95,13.38],[4.1,15.38]],"id":53826530},{"atl":[[3.6,1],[3.7,0]],"id":64618726},{"atb":[[2.72,10],[2.6,0]],"id":67130716}],"con":true,"img":false}]}
{"op":"mcm","clk":"11541455045","pt":1719505932748,"mc":[{"id":"1.230180133","rc":[{"atb":[[1.43,19.28],[1.5,3.69]],"id":66314580},{"atb":[[3.95,2],[3.5,20.76]],"id":53826530},{"atb":[[2.5,10.77]],"id":67130716}],"con":true,"img":false}]}
{"op":"mcm","clk":"11541455053","pt":1719505932843,"mc":[{"id":"1.230180133","rc":[{"atb":[[2.72,5]],"id":67130716}],"con":true,"img":false}]}
{"op":"mcm","clk":"11541455073","pt":1719505933050,"mc":[{"id":"1.230180133","rc":[{"atb":[[3.05,6.27]],"id":67130716}],"con":true,"img":false}]}
{"op":"mcm","clk":"11541455086","pt":1719505933153,"mc":[{"id":"1.230180133","rc":[{"atb":[[3.15,2]],"id":67130716}],"con":true,"img":false}]}
{"op":"mcm","clk":"11541455146","pt":1719505933665,"mc":[{"id":"1.230180133","rc":[{"atb":[[2.18,0]],"id":64618726}],"con":true,"img":false}]}
{"op":"mcm","clk":"11541455158","pt":1719505933769,"mc":[{"id":"1.230180133","rc":[{"atb":[[3.95,0]],"id":53826530}],"con":true,"img":false}]}
{"op":"mcm","clk":"11541455165","pt":1719505933872,"mc":[{"id":"1.230180133","rc":[{"atb":[[4.3,3]],"id":53826530}],"con":true,"img":false}]}
{"op":"mcm","clk":"11541455173","pt":1719505933976,"mc":[{"id":"1.230180133","rc":[{"atb":[[2.38,3.86]],"id":70086038},{"atb":[[2.22,12.19]],"id":64618726}],"con":true,"img":false}]}
{"op":"mcm","clk":"11541455193","pt":1719505934139,"mc":[{"id":"1.230180133","rc":[{"atb":[[2.2,0]],"id":64618726}],"con":true,"img":false}]}
{"op":"mcm","clk":"11541455239","pt":1719505934654,"mc":[{"id":"1.230180133","rc":[{"atb":[[4.2,4.07]],"id":53826530}],"con":true,"img":false}]}
{"op":"mcm","clk":"11541455273","pt":1719505935070,"mc":[{"id":"1.230180133","rc":[{"atb":[[1.48,5.42]],"id":66314580},{"atb":[[4.2,2.5]],"id":53826530}],"con":true,"img":false}]}
{"op":"mcm","clk":"11541455306","pt":1719505935381,"mc":[{"id":"1.230180133","rc":[{"atl":[[2.8,2.5],[2.88,25.62]],"id":66314580}],"con":true,"img":false}]}
{"op":"mcm","clk":"11541455318","pt":1719505935447,"mc":[{"id":"1.230180133","rc":[{"atb":[[4.3,10.5]],"id":53826530}],"con":true,"img":false}]}
{"op":"mcm","clk":"11541455390","pt":1719505936162,"mc":[{"id":"1.230180133","rc":[{"atb":[[4.4,1.57]],"id":53826530}],"con":true,"img":false}]}
{"op":"mcm","clk":"11541455400","pt":1719505936266,"mc":[{"id":"1.230180133","rc":[{"atb":[[2.6,0],[2.34,5]],"id":67487134},{"atb":[[1.43,0],[1.32,10]],"id":66314580},{"atb":[[3.1,21],[3.5,0]],"id":53826530},{"atb":[[1.89,0],[1.76,5]],"id":64618726},{"atl":[[3.6,0],[3.7,1]],"id":64618726},{"atb":[[2.5,0],[2.38,7.5]],"id":67130716}],"con":true,"img":false}]}
{"op":"mcm","clk":"11541455412","pt":1719505936366,"mc":[{"id":"1.230180133","rc":[{"atb":[[4.3,9.5]],"id":53826530}],"con":true,"img":false}]}
{"op":"mcm","clk":"11541455420","pt":1719505936468,"mc":[{"id":"1.230180133","rc":[{"atb":[[1.89,4.62],[1.76,0]],"id":64618726}],"con":true,"img":false}]}
{"op":"mcm","clk":"11541455496","pt":1719505937263,"mc":[{"id":"1.230180133","rc":[{"atb":[[4.3,8.99]],"id":53826530}],"con":true,"img":false}]}
{"op":"mcm","clk":"11541455517","pt":1719505937450,"mc":[{"id":"1.230180133","rc":[{"atb":[[4.3,2]],"id":53826530},{"atb":[[2.42,7.97]],"id":70086038}],"con":true,"img":false}]}
{"op":"mcm","clk":"11541455528","pt":1719505937550,"mc":[{"id":"1.230180133","rc":[{"atb":[[4.4,8.56]],"id":53826530},{"atb":[[2.4,2.11]],"id":70086038},{"atb":[[3.15,7.96]],"id":67130716}],"con":true,"img":false}]}
{"op":"mcm","clk":"11541455544","pt":1719505937759,"mc":[{"id":"1.230180133","rc":[{"atb":[[2.38,0]],"id":70086038},{"atb":[[3.05,0]],"id":67130716}],"con":true,"img":false}]}
{"op":"mcm","clk":"11541455637","pt":1719505938683,"mc":[{"id":"1.230180133","rc":[{"atb":[[1.49,10.68]],"id":66314580},{"atb":[[4.2,0]],"id":53826530},{"atb":[[2.42,5.07]],"id":70086038},{"atb":[[2.22,9.69]],"id":64618726},{"atb":[[3.1,0]],"id":67130716}],"con":true,"img":false}]}
{"op":"mcm","clk":"11541455647","pt":1719505938741,"mc":[{"id":"1.230180133","rc":[{"atb":[[4.5,1]],"id":53826530}],"con":true,"img":false}]}
{"op":"mcm","clk":"11541455662","pt":1719505938851,"mc":[{"id":"1.230180133","rc":[{"atb":[[1.5,7.19]],"id":66314580},{"atb":[[4.5,4]],"id":53826530},{"atb":[[2.44,2.5]],"id":70086038},{"atb":[[2.24,3.16]],"id":64618726},{"atb":[[3.2,2.6]],"id":67130716}],"con":true,"img":false}]}
{"op":"mcm","clk":"11541455699","pt":1719505939165,"mc":[{"id":"1.230180133","rc":[{"atb":[[2.18,1.62]],"id":70086038}],"con":true,"img":false}]}
{"op":"mcm","clk":"11541455775","pt":1719505939978,"mc":[{"id":"1.230180133","rc":[{"atb":[[4,0]],"id":53826530},{"atb":[[2,2.5],[1.96,5],[1.93,0]],"id":64618726}],"con":true,"img":false}]}
{"op":"mcm","clk":"11541455784","pt":1719505940083,"mc":[{"id":"1.230180133","rc":[{"atb":[[2.38,4.25]],"id":70086038}],"con":true,"img":false}]}
{"op":"mcm","clk":"11541455794","pt":1719505940187,"mc":[{"id":"1.230180133","rc":[{"atb":[[4.4,8.19]],"id":53826530}],"con":true,"img":false}]}
{"op":"mcm","clk":"11541455823","pt":1719505940462,"mc":[{"id":"1.230180133","rc":[{"atb":[[4.4,1.57]],"id":53826530}],"con":true,"img":false}]}
{"op":"mcm","clk":"11541455835","pt":1719505940554,"mc":[{"id":"1.230180133","rc":[{"atb":[[3.2,9.07]],"id":67487134},{"atb":[[4.5,10.62]],"id":53826530},{"atb":[[2.38,0]],"id":70086038}],"con":true,"img":false}]}
{"op":"mcm","clk":"11541455850","pt":1719505940665,"mc":[{"id":"1.230180133","rc":[{"atb":[[1.02,2]],"id":67487134},{"atb":[[4.6,2]],"id":53826530}],"con":true,"img":false}]}
{"op":"mcm","clk":"11541455869","pt":1719505940858,"mc":[{"id":"1.230180133","rc":[{"atb":[[4.5,9.62],[4.7,5.91]],"id":53826530},{"atb":[[3.15,5.96]],"id":67130716}],"con":true,"img":false}]}
{"op":"mcm","clk":"11541455888","pt":1719505941136,"mc":[{"id":"1.230180133","rc":[{"atb":[[3.25,0]],"id":67487134},{"atb":[[4.4,0],[4.1,8.68]],"id":53826530},{"atb":[[3.25,2]],"id":67130716}],"con":true,"img":false}]}
{"op":"mcm","clk":"11541455899","pt":1719505941268,"mc":[{"id":"1.230180133","rc":[{"atb":[[4.6,3.57]],"id":53826530}],"con":true,"img":false}]}
{"op":"mcm","clk":"11541455907","pt":1719505941367,"mc":[{"id":"1.230180133","rc":[{"atl":[[2.66,3.3]],"id":66314580}],"con":true,"img":false}]}
