{"op":"mcm","clk":"11536832980","pt":1719431775511,"mc":[{"id":"1.230180119","marketDefinition":{"bspMarket":true,"turnInPlayEnabled":false,"persistenceEnabled":false,"marketBaseRate":5.0,"eventId":"33376437","eventTypeId":"4339","numberOfWinners":2,"bettingType":"ODDS","marketType":"PLACE","marketTime":"2024-06-27T14:29:00.000Z","suspendTime":"2024-06-27T14:29:00.000Z","bspReconciled":false,"complete":true,"inPlay":false,"crossMatching":false,"runnersVoidable":false,"numberOfActiveRunners":6,"betDelay":0,"status":"OPEN","runners":[{"status":"ACTIVE","sortPriority":1,"id":69475360,"name":"1. Flitwick Lopes"},{"status":"ACTIVE","sortPriority":2,"id":50772801,"name":"2. Dunbally Girl"},{"status":"ACTIVE","sortPriority":3,"id":69624671,"name":"3. Salacres Eleanor"},{"status":"ACTIVE","sortPriority":4,"id":62145089,"name":"4. Lamorna Lill Moo"},{"status":"ACTIVE","sortPriority":5,"id":60276470,"name":"5. Salems Decision"},{"status":"ACTIVE","sortPriority":6,"id":48534288,"name":"6. Fabulous Glamour"}],"regulators":["MR_INT"],"venue":"Towcester","countryCode":"GB","discountAllowed":false,"timezone":"Europe/London","openDate":"2024-06-27T13:33:00.000Z","version":5994767113,"name":"To Be Placed","eventName":"Towcester 27th Jun"},"rc":[],"con":true,"img":false}]}
{"op":"mcm","clk":"11536833131","pt":1719431777511,"mc":[{"id":"1.230180119","marketDefinition":{"bspMarket":true,"turnInPlayEnabled":false,"persistenceEnabled":false,"marketBaseRate":5.0,"eventId":"33376437","eventTypeId":"4339","numberOfWinners":2,"bettingType":"ODDS","marketType":"PLACE","marketTime":"2024-06-27T14:29:00.000Z","suspendTime":"2024-06-27T14:29:00.000Z","bspReconciled":false,"complete":true,"inPlay":false,"crossMatching":false,"runnersVoidable":false,"numberOfActiveRunners":6,"betDelay":0,"status":"OPEN","runners":[{"status":"ACTIVE","sortPriority":1,"id":69475360,"name":"1. Flitwick Lopes"},{"status":"ACTIVE","sortPriority":2,"id":50772801,"name":"2. Dunbally Girl"},{"status":"ACTIVE","sortPriority":3,"id":69624671,"name":"3. Salacres Eleanor"},{"status":"ACTIVE","sortPriority":4,"id":62145089,"name":"4. Lamorna Lill Moo"},{"status":"ACTIVE","sortPriority":5,"id":60276470,"name":"5. Salems Decision"},{"status":"ACTIVE","sortPriority":6,"id":48534288,"name":"6. Fabulous Glamour"}],"regulators":["MR_INT"],"venue":"Towcester","countryCode":"GB","discountAllowed":true,"timezone":"Europe/London","openDate":"2024-06-27T13:33:00.000Z","version":5994767113,"name":"To Be Placed","eventName":"Towcester 27th Jun"},"rc":[],"con":true,"img":false}]}
{"op":"mcm","clk":"11537083991","pt":1719435435417,"mc":[{"id":"1.230180119","rc":[{"atb":[[1.02,16.48]],"id":50772801},{"atl":[[990,0.84]],"id":50772801},{"spn":495.51,"spf":"NaN","id":50772801},{"atb":[[1.03,10.99]],"id":62145089},{"atl":[[1000,0.84]],"id":62145089},{"spn":500.51,"spf":"NaN","id":62145089},{"atb":[[1.02,16.48]],"id":69624671},{"atl":[[1000,0.84]],"id":69624671},{"spn":500.51,"spf":"NaN","id":69624671},{"atb":[[1.01,32.96]],"id":60276470},{"atl":[[1000,0.84]],"id":60276470},{"spn":500.5,"spf":"NaN","id":60276470},{"atb":[[1.02,16.48]],"id":48534288},{"atl":[[990,0.84]],"id":48534288},{"spn":495.51,"spf":"NaN","id":48534288},{"atb":[[1.02,16.48]],"id":69475360},{"atl":[[990,0.84]],"id":69475360},{"spn":495.51,"spf":"NaN","id":69475360}],"con":true,"img":false}]}
{"op":"mcm","clk":"11537233725","pt":1719437882648,"mc":[{"id":"1.230180119","marketDefinition":{"bspMarket":true,"turnInPlayEnabled":false,"persistenceEnabled":false,"marketBaseRate":5.0,"eventId":"33376437","eventTypeId":"4339","numberOfWinners":2,"bettingType":"ODDS","marketType":"PLACE","marketTime":"2024-06-27T14:29:00.000Z","suspendTime":"2024-06-27T14:29:00.000Z","bspReconciled":false,"complete":true,"inPlay":false,"crossMatching":false,"runnersVoidable":false,"numberOfActiveRunners":6,"betDelay":0,"status":"OPEN","runners":[{"status":"ACTIVE","sortPriority":1,"id":69475360,"name":"1. Flitwick Lopes"},{"status":"ACTIVE","sortPriority":2,"id":50772801,"name":"2. Dunbally Girl"},{"status":"ACTIVE","sortPriority":3,"id":69624671,"name":"3. Salacres Eleanor"},{"status":"ACTIVE","sortPriority":4,"id":62145089,"name":"4. Lamorna Lill Moo"},{"status":"ACTIVE","sortPriority":5,"id":60276470,"name":"5. Salems Decision"},{"status":"ACTIVE","sortPriority":6,"id":48534288,"name":"6. Fabulous Glamour"}],"regulators":["MR_INT"],"venue":"Towcester","countryCode":"GB","discountAllowed":true,"timezone":"Europe/London","openDate":"2024-06-27T13:33:00.000Z","version":5994767113,"name":"To Be Placed","eventName":"Towcester 27th Jun"},"rc":[{"atb":[[1.02,16.48]],"id":50772801},{"atl":[[990,0.84]],"id":50772801},{"spn":495.51,"spf":"NaN","id":50772801},{"atb":[[1.03,10.99]],"id":62145089},{"atl":[[1000,0.84]],"id":62145089},{"spn":500.51,"spf":"NaN","id":62145089},{"atb":[[1.02,16.48]],"id":69624671},{"atl":[[1000,0.84]],"id":69624671},{"spn":500.51,"spf":"NaN","id":69624671},{"atb":[[1.01,32.96]],"id":60276470},{"atl":[[1000,0.84]],"id":60276470},{"spn":500.5,"spf":"NaN","id":60276470},{"atb":[[1.02,16.48]],"id":48534288},{"atl":[[990,0.84]],"id":48534288},{"spn":495.51,"spf":"NaN","id":48534288},{"atb":[[1.02,16.48]],"id":69475360},{"atl":[[990,0.84]],"id":69475360},{"spn":495.51,"spf":"NaN","id":69475360}],"con":true,"img":true}]}
{"op":"mcm","clk":"11537302280","pt":1719439033834,"mc":[{"id":"1.230180119","rc":[{"atb":[[1.02,16.48]],"id":50772801},{"atl":[[990,0.17]],"id":50772801},{"atb":[[1.03,10.99]],"id":62145089},{"atl":[[1000,0.17]],"id":62145089},{"atb":[[1.02,16.48]],"id":69624671},{"atl":[[1000,0.17]],"id":69624671},{"atb":[[1.01,32.96]],"id":60276470},{"atl":[[1000,0.17]],"id":60276470},{"atb":[[1.02,16.48]],"id":48534288},{"atl":[[990,0.17]],"id":48534288},{"atb":[[1.02,16.48]],"id":69475360},{"atl":[[990,0.17]],"id":69475360}],"con":true,"img":false}]}
{"op":"mcm","clk":"11537574873","pt":1719443282699,"mc":[{"id":"1.230180119","marketDefinition":{"bspMarket":true,"turnInPlayEnabled":false,"persistenceEnabled":false,"marketBaseRate":5.0,"eventId":"33376437","eventTypeId":"4339","numberOfWinners":2,"bettingType":"ODDS","marketType":"PLACE","marketTime":"2024-06-27T14:29:00.000Z","suspendTime":"2024-06-27T14:29:00.000Z","bspReconciled":false,"complete":true,"inPlay":false,"crossMatching":false,"runnersVoidable":false,"numberOfActiveRunners":6,"betDelay":0,"status":"OPEN","runners":[{"status":"ACTIVE","sortPriority":1,"id":69475360,"name":"1. Flitwick Lopes"},{"status":"ACTIVE","sortPriority":2,"id":50772801,"name":"2. Dunbally Girl"},{"status":"ACTIVE","sortPriority":3,"id":69624671,"name":"3. Salacres Eleanor"},{"status":"ACTIVE","sortPriority":4,"id":62145089,"name":"4. Lamorna Lill Moo"},{"status":"ACTIVE","sortPriority":5,"id":60276470,"name":"5. Salems Decision"},{"status":"ACTIVE","sortPriority":6,"id":48534288,"name":"6. Fabulous Glamour"}],"regulators":["MR_INT"],"venue":"Towcester","countryCode":"GB","discountAllowed":true,"timezone":"Europe/London","openDate":"2024-06-27T13:33:00.000Z","version":5994767113,"name":"To Be Placed","eventName":"Towcester 27th Jun"},"rc":[{"atb":[[1.02,16.48]],"id":50772801},{"atl":[[990,0.17]],"id":50772801},{"spn":495.51,"spf":"NaN","id":50772801},{"atb":[[1.03,10.99]],"id":62145089},{"atl":[[1000,0.17]],"id":62145089},{"spn":500.51,"spf":"NaN","id":62145089},{"atb":[[1.02,16.48]],"id":69624671},{"atl":[[1000,0.17]],"id":69624671},{"spn":500.51,"spf":"NaN","id":69624671},{"atb":[[1.01,32.96]],"id":60276470},{"atl":[[1000,0.17]],"id":60276470},{"spn":500.5,"spf":"NaN","id":60276470},{"atb":[[1.02,16.48]],"id":48534288},{"atl":[[990,0.17]],"id":48534288},{"spn":495.51,"spf":"NaN","id":48534288},{"atb":[[1.02,16.48]],"id":69475360},{"atl":[[990,0.17]],"id":69475360},{"spn":495.51,"spf":"NaN","id":69475360}],"con":true,"img":true}]}
{"op":"mcm","clk":"11537956493","pt":1719448682740,"mc":[{"id":"1.230180119","marketDefinition":{"bspMarket":true,"turnInPlayEnabled":false,"persistenceEnabled":false,"marketBaseRate":5.0,"eventId":"33376437","eventTypeId":"4339","numberOfWinners":2,"bettingType":"ODDS","marketType":"PLACE","marketTime":"2024-06-27T14:29:00.000Z","suspendTime":"2024-06-27T14:29:00.000Z","bspReconciled":false,"complete":true,"inPlay":false,"crossMatching":false,"runnersVoidable":false,"numberOfActiveRunners":6,"betDelay":0,"status":"OPEN","runners":[{"status":"ACTIVE","sortPriority":1,"id":69475360,"name":"1. Flitwick Lopes"},{"status":"ACTIVE","sortPriority":2,"id":50772801,"name":"2. Dunbally Girl"},{"status":"ACTIVE","sortPriority":3,"id":69624671,"name":"3. Salacres Eleanor"},{"status":"ACTIVE","sortPriority":4,"id":62145089,"name":"4. Lamorna Lill Moo"},{"status":"ACTIVE","sortPriority":5,"id":60276470,"name":"5. Salems Decision"},{"status":"ACTIVE","sortPriority":6,"id":48534288,"name":"6. Fabulous Glamour"}],"regulators":["MR_INT"],"venue":"Towcester","countryCode":"GB","discountAllowed":true,"timezone":"Europe/London","openDate":"2024-06-27T13:33:00.000Z","version":5994767113,"name":"To Be Placed","eventName":"Towcester 27th Jun"},"rc":[{"atb":[[1.02,16.48]],"id":50772801},{"atl":[[990,0.17]],"id":50772801},{"spn":495.51,"spf":"NaN","id":50772801},{"atb":[[1.03,10.99]],"id":62145089},{"atl":[[1000,0.17]],"id":62145089},{"spn":500.51,"spf":"NaN","id":62145089},{"atb":[[1.02,16.48]],"id":69624671},{"atl":[[1000,0.17]],"id":69624671},{"spn":500.51,"spf":"NaN","id":69624671},{"atb":[[1.01,32.96]],"id":60276470},{"atl":[[1000,0.17]],"id":60276470},{"spn":500.5,"spf":"NaN","id":60276470},{"atb":[[1.02,16.48]],"id":48534288},{"atl":[[990,0.17]],"id":48534288},{"spn":495.51,"spf":"NaN","id":48534288},{"atb":[[1.02,16.48]],"id":69475360},{"atl":[[990,0.17]],"id":69475360},{"spn":495.51,"spf":"NaN","id":69475360}],"con":true,"img":true}]}
{"op":"mcm","clk":"11538172110","pt":1719454082683,"mc":[{"id":"1.230180119","marketDefinition":{"bspMarket":true,"turnInPlayEnabled":false,"persistenceEnabled":false,"marketBaseRate":5.0,"eventId":"33376437","eventTypeId":"4339","numberOfWinners":2,"bettingType":"ODDS","marketType":"PLACE","marketTime":"2024-06-27T14:29:00.000Z","suspendTime":"2024-06-27T14:29:00.000Z","bspReconciled":false,"complete":true,"inPlay":false,"crossMatching":false,"runnersVoidable":false,"numberOfActiveRunners":6,"betDelay":0,"status":"OPEN","runners":[{"status":"ACTIVE","sortPriority":1,"id":69475360,"name":"1. Flitwick Lopes"},{"status":"ACTIVE","sortPriority":2,"id":50772801,"name":"2. Dunbally Girl"},{"status":"ACTIVE","sortPriority":3,"id":69624671,"name":"3. Salacres Eleanor"},{"status":"ACTIVE","sortPriority":4,"id":62145089,"name":"4. Lamorna Lill Moo"},{"status":"ACTIVE","sortPriority":5,"id":60276470,"name":"5. Salems Decision"},{"status":"ACTIVE","sortPriority":6,"id":48534288,"name":"6. Fabulous Glamour"}],"regulators":["MR_INT"],"venue":"Towcester","countryCode":"GB","discountAllowed":true,"timezone":"Europe/London","openDate":"2024-06-27T13:33:00.000Z","version":5994767113,"name":"To Be Placed","eventName":"Towcester 27th Jun"},"rc":[{"atb":[[1.02,16.48]],"id":50772801},{"atl":[[990,0.17]],"id":50772801},{"spn":495.51,"spf":"NaN","id":50772801},{"atb":[[1.03,10.99]],"id":62145089},{"atl":[[1000,0.17]],"id":62145089},{"spn":500.51,"spf":"NaN","id":62145089},{"atb":[[1.02,16.48]],"id":69624671},{"atl":[[1000,0.17]],"id":69624671},{"spn":500.51,"spf":"NaN","id":69624671},{"atb":[[1.01,32.97]],"id":60276470},{"atl":[[1000,0.17]],"id":60276470},{"spn":500.5,"spf":"NaN","id":60276470},{"atb":[[1.02,16.48]],"id":48534288},{"atl":[[990,0.17]],"id":48534288},{"spn":495.51,"spf":"NaN","id":48534288},{"atb":[[1.02,16.48]],"id":69475360},{"atl":[[990,0.17]],"id":69475360},{"spn":495.51,"spf":"NaN","id":69475360}],"con":true,"img":true}]}
{"op":"mcm","clk":"11538369777","pt":1719459482768,"mc":[{"id":"1.230180119","marketDefinition":{"bspMarket":true,"turnInPlayEnabled":false,"persistenceEnabled":false,"marketBaseRate":5.0,"eventId":"33376437","eventTypeId":"4339","numberOfWinners":2,"bettingType":"ODDS","marketType":"PLACE","marketTime":"2024-06-27T14:29:00.000Z","suspendTime":"2024-06-27T14:29:00.000Z","bspReconciled":false,"complete":true,"inPlay":false,"crossMatching":false,"runnersVoidable":false,"numberOfActiveRunners":6,"betDelay":0,"status":"OPEN","runners":[{"status":"ACTIVE","sortPriority":1,"id":69475360,"name":"1. Flitwick Lopes"},{"status":"ACTIVE","sortPriority":2,"id":50772801,"name":"2. Dunbally Girl"},{"status":"ACTIVE","sortPriority":3,"id":69624671,"name":"3. Salacres Eleanor"},{"status":"ACTIVE","sortPriority":4,"id":62145089,"name":"4. Lamorna Lill Moo"},{"status":"ACTIVE","sortPriority":5,"id":60276470,"name":"5. Salems Decision"},{"status":"ACTIVE","sortPriority":6,"id":48534288,"name":"6. Fabulous Glamour"}],"regulators":["MR_INT"],"venue":"Towcester","countryCode":"GB","discountAllowed":true,"timezone":"Europe/London","openDate":"2024-06-27T13:33:00.000Z","version":5994767113,"name":"To Be Placed","eventName":"Towcester 27th Jun"},"rc":[{"atb":[[1.02,16.48]],"id":50772801},{"atl":[[990,0.17]],"id":50772801},{"spn":495.51,"spf":"NaN","id":50772801},{"atb":[[1.03,10.99]],"id":62145089},{"atl":[[1000,0.17]],"id":62145089},{"spn":500.51,"spf":"NaN","id":62145089},{"atb":[[1.02,16.48]],"id":69624671},{"atl":[[1000,0.17]],"id":69624671},{"spn":500.51,"spf":"NaN","id":69624671},{"atb":[[1.01,32.97]],"id":60276470},{"atl":[[1000,0.17]],"id":60276470},{"spn":500.5,"spf":"NaN","id":60276470},{"atb":[[1.02,16.48]],"id":48534288},{"atl":[[990,0.17]],"id":48534288},{"spn":495.51,"spf":"NaN","id":48534288},{"atb":[[1.02,16.48]],"id":69475360},{"atl":[[990,0.17]],"id":69475360},{"spn":495.51,"spf":"NaN","id":69475360}],"con":true,"img":true}]}
{"op":"mcm","clk":"11538596907","pt":1719464882712,"mc":[{"id":"1.230180119","marketDefinition":{"bspMarket":true,"turnInPlayEnabled":false,"persistenceEnabled":false,"marketBaseRate":5.0,"eventId":"33376437","eventTypeId":"4339","numberOfWinners":2,"bettingType":"ODDS","marketType":"PLACE","marketTime":"2024-06-27T14:29:00.000Z","suspendTime":"2024-06-27T14:29:00.000Z","bspReconciled":false,"complete":true,"inPlay":false,"crossMatching":false,"runnersVoidable":false,"numberOfActiveRunners":6,"betDelay":0,"status":"OPEN","runners":[{"status":"ACTIVE","sortPriority":1,"id":69475360,"name":"1. Flitwick Lopes"},{"status":"ACTIVE","sortPriority":2,"id":50772801,"name":"2. Dunbally Girl"},{"status":"ACTIVE","sortPriority":3,"id":69624671,"name":"3. Salacres Eleanor"},{"status":"ACTIVE","sortPriority":4,"id":62145089,"name":"4. Lamorna Lill Moo"},{"status":"ACTIVE","sortPriority":5,"id":60276470,"name":"5. Salems Decision"},{"status":"ACTIVE","sortPriority":6,"id":48534288,"name":"6. Fabulous Glamour"}],"regulators":["MR_INT"],"venue":"Towcester","countryCode":"GB","discountAllowed":true,"timezone":"Europe/London","openDate":"2024-06-27T13:33:00.000Z","version":5994767113,"name":"To Be Placed","eventName":"Towcester 27th Jun"},"rc":[{"atb":[[1.02,16.48]],"id":50772801},{"atl":[[990,0.17]],"id":50772801},{"spn":495.51,"spf":"NaN","id":50772801},{"atb":[[1.03,10.99]],"id":62145089},{"atl":[[1000,0.17]],"id":62145089},{"spn":500.51,"spf":"NaN","id":62145089},{"atb":[[1.02,16.48]],"id":69624671},{"atl":[[1000,0.17]],"id":69624671},{"spn":500.51,"spf":"NaN","id":69624671},{"atb":[[1.01,32.97]],"id":60276470},{"atl":[[1000,0.17]],"id":60276470},{"spn":500.5,"spf":"NaN","id":60276470},{"atb":[[1.02,16.48]],"id":48534288},{"atl":[[990,0.17]],"id":48534288},{"spn":495.51,"spf":"NaN","id":48534288},{"atb":[[1.02,16.48]],"id":69475360},{"atl":[[990,0.17]],"id":69475360},{"spn":495.51,"spf":"NaN","id":69475360}],"con":true,"img":true}]}
{"op":"mcm","clk":"11538906770","pt":1719471499300,"mc":[{"id":"1.230180119","rc":[{"atb":[[1.02,16.48],[1.07,2.48]],"id":50772801},{"spn":495.53,"spf":"NaN","id":50772801},{"atb":[[1.03,10.99],[1.07,2.48]],"id":62145089},{"spn":500.53,"spf":"NaN","id":62145089},{"atb":[[1.02,16.48],[1.07,2.48]],"id":69624671},{"spn":500.53,"spf":"NaN","id":69624671},{"atb":[[1.01,32.97],[1.07,2.48]],"id":60276470},{"spn":500.53,"spf":"NaN","id":60276470},{"atb":[[1.02,16.48],[1.07,2.48]],"id":48534288},{"spn":495.53,"spf":"NaN","id":48534288},{"atb":[[1.02,16.48],[1.07,2.48]],"id":69475360},{"spn":495.53,"spf":"NaN","id":69475360}],"con":true,"img":false}]}
{"op":"mcm","clk":"11538906785","pt":1719471499517,"mc":[{"id":"1.230180119","rc":[{"atl":[[1000,1]],"id":50772801},{"atl":[[1000,1.17]],"id":62145089},{"atl":[[1000,1.17]],"id":69624671},{"atl":[[1000,1.17]],"id":60276470},{"atl":[[1000,1]],"id":48534288},{"atl":[[1000,1]],"id":69475360}],"con":true,"img":false}]}
{"op":"mcm","clk":"11538906798","pt":1719471499718,"mc":[{"id":"1.230180119","rc":[{"atl":[[1000,0.48]],"id":50772801},{"atl":[[1000,0.65]],"id":62145089},{"atl":[[1000,0.65]],"id":69624671},{"atl":[[1000,0.65]],"id":60276470},{"atl":[[1000,0.48]],"id":48534288},{"atl":[[1000,0.48]],"id":69475360}],"con":true,"img":false}]}
{"op":"mcm","clk":"11538906809","pt":1719471499924,"mc":[{"id":"1.230180119","rc":[{"atl":[[1000,0]],"id":50772801},{"atl":[[1000,0.17]],"id":62145089},{"atl":[[1000,0.17]],"id":69624671},{"atl":[[1000,0.17]],"id":60276470},{"atl":[[1000,0]],"id":48534288},{"atl":[[1000,0]],"id":69475360}],"con":true,"img":false}]}
{"op":"mcm","clk":"11538906815","pt":1719471499981,"mc":[{"id":"1.230180119","rc":[{"atl":[[75,0.48]],"id":50772801},{"atl":[[75,0.48]],"id":62145089},{"atl":[[75,0.48]],"id":69624671},{"atl":[[75,0.48]],"id":60276470},{"atl":[[75,0.48]],"id":48534288},{"atl":[[75,0.48]],"id":69475360}],"con":true,"img":false}]}
{"op":"mcm","clk":"11539124095","pt":1719475682699,"mc":[{"id":"1.230180119","marketDefinition":{"bspMarket":true,"turnInPlayEnabled":false,"persistenceEnabled":false,"marketBaseRate":5.0,"eventId":"33376437","eventTypeId":"4339","numberOfWinners":2,"bettingType":"ODDS","marketType":"PLACE","marketTime":"2024-06-27T14:29:00.000Z","suspendTime":"2024-06-27T14:29:00.000Z","bspReconciled":false,"complete":true,"inPlay":false,"crossMatching":false,"runnersVoidable":false,"numberOfActiveRunners":6,"betDelay":0,"status":"OPEN","runners":[{"status":"ACTIVE","sortPriority":1,"id":69475360,"name":"1. Flitwick Lopes"},{"status":"ACTIVE","sortPriority":2,"id":50772801,"name":"2. Dunbally Girl"},{"status":"ACTIVE","sortPriority":3,"id":69624671,"name":"3. Salacres Eleanor"},{"status":"ACTIVE","sortPriority":4,"id":62145089,"name":"4. Lamorna Lill Moo"},{"status":"ACTIVE","sortPriority":5,"id":60276470,"name":"5. Salems Decision"},{"status":"ACTIVE","sortPriority":6,"id":48534288,"name":"6. Fabulous Glamour"}],"regulators":["MR_INT"],"venue":"Towcester","countryCode":"GB","discountAllowed":true,"timezone":"Europe/London","openDate":"2024-06-27T13:33:00.000Z","version":5994767113,"name":"To Be Placed","eventName":"Towcester 27th Jun"},"rc":[{"atb":[[1.02,16.48],[1.07,2.48]],"id":50772801},{"atl":[[75,0.48],[990,0.17]],"id":50772801},{"spn":38.03,"spf":"NaN","id":50772801},{"atb":[[1.03,10.99],[1.07,2.48]],"id":62145089},{"atl":[[75,0.48],[1000,0.17]],"id":62145089},{"spn":38.03,"spf":"NaN","id":62145089},{"atb":[[1.02,16.48],[1.07,2.48]],"id":69624671},{"atl":[[75,0.48],[1000,0.17]],"id":69624671},{"spn":38.03,"spf":"NaN","id":69624671},{"atb":[[1.01,32.96],[1.07,2.48]],"id":60276470},{"atl":[[75,0.48],[1000,0.17]],"id":60276470},{"spn":38.03,"spf":"NaN","id":60276470},{"atb":[[1.02,16.48],[1.07,2.48]],"id":48534288},{"atl":[[75,0.48],[990,0.17]],"id":48534288},{"spn":38.03,"spf":"NaN","id":48534288},{"atb":[[1.02,16.48],[1.07,2.48]],"id":69475360},{"atl":[[75,0.48],[990,0.17]],"id":69475360},{"spn":38.03,"spf":"NaN","id":69475360}],"con":true,"img":true}]}
{"op":"mcm","clk":"11539440199","pt":1719481082673,"mc":[{"id":"1.230180119","marketDefinition":{"bspMarket":true,"turnInPlayEnabled":false,"persistenceEnabled":false,"marketBaseRate":5.0,"eventId":"33376437","eventTypeId":"4339","numberOfWinners":2,"bettingType":"ODDS","marketType":"PLACE","marketTime":"2024-06-27T14:29:00.000Z","suspendTime":"2024-06-27T14:29:00.000Z","bspReconciled":false,"complete":true,"inPlay":false,"crossMatching":false,"runnersVoidable":false,"numberOfActiveRunners":6,"betDelay":0,"status":"OPEN","runners":[{"status":"ACTIVE","sortPriority":1,"id":69475360,"name":"1. Flitwick Lopes"},{"status":"ACTIVE","sortPriority":2,"id":50772801,"name":"2. Dunbally Girl"},{"status":"ACTIVE","sortPriority":3,"id":69624671,"name":"3. Salacres Eleanor"},{"status":"ACTIVE","sortPriority":4,"id":62145089,"name":"4. Lamorna Lill Moo"},{"status":"ACTIVE","sortPriority":5,"id":60276470,"name":"5. Salems Decision"},{"status":"ACTIVE","sortPriority":6,"id":48534288,"name":"6. Fabulous Glamour"}],"regulators":["MR_INT"],"venue":"Towcester","countryCode":"GB","discountAllowed":true,"timezone":"Europe/London","openDate":"2024-06-27T13:33:00.000Z","version":5994767113,"name":"To Be Placed","eventName":"Towcester 27th Jun"},"rc":[{"atb":[[1.02,16.47],[1.07,2.48]],"id":50772801},{"atl":[[75,0.48],[990,0.17]],"id":50772801},{"spn":38.03,"spf":"NaN","id":50772801},{"atb":[[1.03,10.98],[1.07,2.48]],"id":62145089},{"atl":[[75,0.48],[1000,0.17]],"id":62145089},{"spn":38.03,"spf":"NaN","id":62145089},{"atb":[[1.02,16.47],[1.07,2.48]],"id":69624671},{"atl":[[75,0.48],[1000,0.17]],"id":69624671},{"spn":38.03,"spf":"NaN","id":69624671},{"atb":[[1.01,32.95],[1.07,2.48]],"id":60276470},{"atl":[[75,0.48],[1000,0.17]],"id":60276470},{"spn":38.03,"spf":"NaN","id":60276470},{"atb":[[1.02,16.47],[1.07,2.48]],"id":48534288},{"atl":[[75,0.48],[990,0.17]],"id":48534288},{"spn":38.03,"spf":"NaN","id":48534288},{"atb":[[1.02,16.47],[1.07,2.48]],"id":69475360},{"atl":[[75,0.48],[990,0.17]],"id":69475360},{"spn":38.03,"spf":"NaN","id":69475360}],"con":true,"img":true}]}
{"op":"mcm","clk":"11540642400","pt":1719496802313,"mc":[{"id":"1.230180119","rc":[{"atb":[[1.02,16.49],[1.04,1]],"id":50772801},{"atl":[[990,0.17]],"id":50772801},{"spn":38.03,"spf":"NaN","id":50772801},{"atb":[[1.03,11],[1.04,1]],"id":62145089},{"atl":[[1000,0.17]],"id":62145089},{"spn":38.03,"spf":"NaN","id":62145089},{"atb":[[1.02,16.49],[1.04,1]],"id":69624671},{"atl":[[1000,0.17]],"id":69624671},{"spn":38.03,"spf":"NaN","id":69624671},{"atb":[[1.01,32.99],[1.04,1]],"id":60276470},{"atl":[[1000,0.17]],"id":60276470},{"spn":38.03,"spf":"NaN","id":60276470},{"atb":[[1.02,16.49],[1.04,1]],"id":48534288},{"atl":[[990,0.17]],"id":48534288},{"spn":38.03,"spf":"NaN","id":48534288},{"atb":[[1.02,16.49],[1.04,1]],"id":69475360},{"atl":[[990,0.17]],"id":69475360},{"spn":38.03,"spf":"NaN","id":69475360}],"con":true,"img":false}]}
{"op":"mcm","clk":"11540642422","pt":1719496802589,"mc":[{"id":"1.230180119","rc":[{"atb":[[1.04,0.25]],"id":50772801},{"atb":[[1.04,0.25]],"id":62145089},{"atb":[[1.04,0.25]],"id":69624671},{"atb":[[1.04,0.25]],"id":60276470},{"atb":[[1.04,0.25]],"id":48534288},{"atb":[[1.04,0.25]],"id":69475360}],"con":true,"img":false}]}
{"op":"mcm","clk":"11540642447","pt":1719496802849,"mc":[{"id":"1.230180119","rc":[{"atb":[[1.04,0]],"id":50772801},{"atb":[[1.04,0]],"id":62145089},{"atb":[[1.04,0]],"id":69624671},{"atb":[[1.04,0]],"id":60276470},{"atb":[[1.04,0]],"id":48534288},{"atb":[[1.04,0]],"id":69475360}],"con":true,"img":false}]}
{"op":"mcm","clk":"11540642458","pt":1719496802993,"mc":[{"id":"1.230180119","rc":[{"atb":[[1.2,0.25]],"id":50772801},{"atb":[[1.2,0.25]],"id":62145089},{"atb":[[1.2,0.25]],"id":69624671},{"atb":[[1.2,0.25]],"id":60276470},{"atb":[[1.2,0.25]],"id":48534288},{"atb":[[1.2,0.25]],"id":69475360}],"con":true,"img":false}]}
{"op":"mcm","clk":"11540643648","pt":1719496816777,"mc":[{"id":"1.230180119","rc":[{"atb":[[1.02,16.49],[1.09,43.87]],"id":50772801},{"atb":[[1.03,10.99]],"id":62145089},{"atb":[[1.02,16.49]],"id":69624671},{"atb":[[1.01,32.98]],"id":60276470},{"atb":[[1.02,16.49]],"id":48534288},{"atb":[[1.02,16.49]],"id":69475360}],"con":true,"img":false}]}
{"op":"mcm","clk":"11540643669","pt":1719496816987,"mc":[{"id":"1.230180119","rc":[{"atb":[[1.09,43.87]],"id":62145089},{"atb":[[1.09,43.87]],"id":48534288}],"con":true,"img":false}]}
{"op":"mcm","clk":"11540659845","pt":1719497020982,"mc":[{"id":"1.230180119","rc":[{"atb":[[1.11,38.47]],"id":50772801},{"spn":38.1,"spf":"NaN","id":50772801},{"spn":38.1,"spf":"NaN","id":62145089},{"spn":38.1,"spf":"NaN","id":69624671},{"spn":38.1,"spf":"NaN","id":60276470},{"spn":38.1,"spf":"NaN","id":48534288},{"spn":38.1,"spf":"NaN","id":69475360}],"con":true,"img":false}]}
{"op":"mcm","clk":"11540659866","pt":1719497021192,"mc":[{"id":"1.230180119","rc":[{"atb":[[1.11,38.47]],"id":62145089}],"con":true,"img":false}]}
{"op":"mcm","clk":"11540659878","pt":1719497021296,"mc":[{"id":"1.230180119","rc":[{"atb":[[1.11,38.47]],"id":48534288}],"con":true,"img":false}]}
{"op":"mcm","clk":"11540661397","pt":1719497040432,"mc":[{"id":"1.230180119","rc":[{"atb":[[1.09,0]],"id":50772801}],"con":true,"img":false}]}
{"op":"mcm","clk":"11540661413","pt":1719497040641,"mc":[{"id":"1.230180119","rc":[{"atb":[[1.09,0]],"id":62145089}],"con":true,"img":false}]}
{"op":"mcm","clk":"11540661449","pt":1719497041012,"mc":[{"id":"1.230180119","rc":[{"atb":[[1.09,0]],"id":48534288}],"con":true,"img":false}]}
{"op":"mcm","clk":"11540661460","pt":1719497041112,"mc":[{"id":"1.230180119","rc":[{"atb":[[1.13,30.37]],"id":62145089}],"con":true,"img":false}]}
{"op":"mcm","clk":"11540661465","pt":1719497041215,"mc":[{"id":"1.230180119","rc":[{"atb":[[1.13,30.37]],"id":50772801}],"con":true,"img":false}]}
{"op":"mcm","clk":"11540661496","pt":1719497041633,"mc":[{"id":"1.230180119","rc":[{"atb":[[1.13,30.37]],"id":48534288}],"con":true,"img":false}]}
{"op":"mcm","clk":"11540662311","pt":1719497051713,"mc":[{"id":"1.230180119","marketDefinition":{"bspMarket":true,"turnInPlayEnabled":false,"persistenceEnabled":false,"marketBaseRate":5.0,"eventId":"33376437","eventTypeId":"4339","numberOfWinners":2,"bettingType":"ODDS","marketType":"PLACE","marketTime":"2024-06-27T14:29:00.000Z","suspendTime":"2024-06-27T14:29:00.000Z","bspReconciled":false,"complete":true,"inPlay":false,"crossMatching":true,"runnersVoidable":false,"numberOfActiveRunners":6,"betDelay":0,"status":"OPEN","runners":[{"status":"ACTIVE","sortPriority":1,"id":69475360,"name":"1. Flitwick Lopes"},{"status":"ACTIVE","sortPriority":2,"id":50772801,"name":"2. Dunbally Girl"},{"status":"ACTIVE","sortPriority":3,"id":69624671,"name":"3. Salacres Eleanor"},{"status":"ACTIVE","sortPriority":4,"id":62145089,"name":"4. Lamorna Lill Moo"},{"status":"ACTIVE","sortPriority":5,"id":60276470,"name":"5. Salems Decision"},{"status":"ACTIVE","sortPriority":6,"id":48534288,"name":"6. Fabulous Glamour"}],"regulators":["MR_INT"],"venue":"Towcester","countryCode":"GB","discountAllowed":true,"timezone":"Europe/London","openDate":"2024-06-27T13:33:00.000Z","version":5994767113,"name":"To Be Placed","eventName":"Towcester 27th Jun"},"rc":[],"con":true,"img":false}]}
{"op":"mcm","clk":"11540662872","pt":1719497058018,"mc":[{"id":"1.230180119","rc":[{"atb":[[1.11,0]],"id":50772801},{"atb":[[1.11,0]],"id":62145089}],"con":true,"img":false}]}
{"op":"mcm","clk":"11540662908","pt":1719497058432,"mc":[{"id":"1.230180119","rc":[{"atb":[[1.11,0]],"id":48534288}],"con":true,"img":false}]}
{"op":"mcm","clk":"11540662929","pt":1719497058639,"mc":[{"id":"1.230180119","rc":[{"atb":[[1.15,28.21]],"id":50772801}],"con":true,"img":false}]}
{"op":"mcm","clk":"11540662958","pt":1719497059003,"mc":[{"id":"1.230180119","rc":[{"atb":[[1.15,28.21]],"id":48534288}],"con":true,"img":false}]}
{"op":"mcm","clk":"11540662976","pt":1719497059208,"mc":[{"id":"1.230180119","rc":[{"atb":[[1.15,28.21]],"id":62145089}],"con":true,"img":false}]}
{"op":"mcm","clk":"11540663072","pt":1719497060251,"mc":[{"id":"1.230180119","rc":[{"atb":[[1.13,0]],"id":50772801},{"atb":[[1.13,0]],"id":62145089}],"con":true,"img":false}]}
{"op":"mcm","clk":"11540663084","pt":1719497060451,"mc":[{"id":"1.230180119","rc":[{"atb":[[1.13,0]],"id":48534288}],"con":true,"img":false}]}
{"op":"mcm","clk":"11540663119","pt":1719497060819,"mc":[{"id":"1.230180119","rc":[{"atb":[[1.17,23.22]],"id":48534288}],"con":true,"img":false}]}
{"op":"mcm","clk":"11540663136","pt":1719497061023,"mc":[{"id":"1.230180119","rc":[{"atb":[[1.17,23.22]],"id":62145089}],"con":true,"img":false}]}
{"op":"mcm","clk":"11540663143","pt":1719497061132,"mc":[{"id":"1.230180119","rc":[{"atb":[[1.17,23.22]],"id":50772801}],"con":true,"img":false}]}
{"op":"mcm","clk":"11540666003","pt":1719497094562,"mc":[{"id":"1.230180119","rc":[{"atb":[[1.15,0]],"id":50772801}],"con":true,"img":false}]}
{"op":"mcm","clk":"11540666030","pt":1719497094970,"mc":[{"id":"1.230180119","rc":[{"atb":[[1.15,0]],"id":62145089},{"atb":[[1.15,0]],"id":48534288}],"con":true,"img":false}]}
{"op":"mcm","clk":"11540666106","pt":1719497095849,"mc":[{"id":"1.230180119","rc":[{"atb":[[1.19,22.28]],"id":50772801}],"con":true,"img":false}]}
{"op":"mcm","clk":"11540666124","pt":1719497096163,"mc":[{"id":"1.230180119","rc":[{"atb":[[1.19,22.28]],"id":48534288}],"con":true,"img":false}]}
{"op":"mcm","clk":"11540666148","pt":1719497096471,"mc":[{"id":"1.230180119","rc":[{"atb":[[1.19,22.28]],"id":62145089}],"con":true,"img":false}]}
{"op":"mcm","clk":"11540667741","pt":1719497114401,"mc":[{"id":"1.230180119","rc":[{"atb":[[1.17,0]],"id":50772801},{"atb":[[1.17,0]],"id":62145089}],"con":true,"img":false}]}
{"op":"mcm","clk":"11540667756","pt":1719497114610,"mc":[{"id":"1.230180119","rc":[{"atb":[[1.17,0]],"id":48534288}],"con":true,"img":false}]}
{"op":"mcm","clk":"11540667791","pt":1719497115023,"mc":[{"id":"1.230180119","rc":[{"atb":[[1.21,18.8]],"id":50772801},{"atb":[[1.21,18.8]],"id":62145089}],"con":true,"img":false}]}
{"op":"mcm","clk":"11540667811","pt":1719497115180,"mc":[{"id":"1.230180119","rc":[{"atb":[[1.21,18.8]],"id":48534288}],"con":true,"img":false}]}
{"op":"mcm","clk":"11540669144","pt":1719497131427,"mc":[{"id":"1.230180119","rc":[{"atb":[[1.19,0]],"id":50772801}],"con":true,"img":false}]}
{"op":"mcm","clk":"11540669168","pt":1719497131738,"mc":[{"id":"1.230180119","rc":[{"atb":[[1.19,0]],"id":62145089}],"con":true,"img":false}]}
{"op":"mcm","clk":"11540669194","pt":1719497132047,"mc":[{"id":"1.230180119","rc":[{"atb":[[1.23,18.4]],"id":62145089}],"con":true,"img":false}]}
{"op":"mcm","clk":"11540669218","pt":1719497132310,"mc":[{"id":"1.230180119","rc":[{"atb":[[1.23,18.4]],"id":50772801}],"con":true,"img":false}]}
{"op":"mcm","clk":"11540669239","pt":1719497132619,"mc":[{"id":"1.230180119","rc":[{"atb":[[1.19,0]],"id":48534288}],"con":true,"img":false}]}
{"op":"mcm","clk":"11540669255","pt":1719497132925,"mc":[{"id":"1.230180119","rc":[{"atb":[[1.23,18.4]],"id":48534288}],"con":true,"img":false}]}
{"op":"mcm","clk":"11540669280","pt":1719497133337,"mc":[{"id":"1.230180119","rc":[{"atb":[[1.21,0]],"id":50772801}],"con":true,"img":false}]}
{"op":"mcm","clk":"11540669319","pt":1719497133802,"mc":[{"id":"1.230180119","rc":[{"atb":[[1.25,15.79]],"id":50772801}],"con":true,"img":false}]}
{"op":"mcm","clk":"11540669331","pt":1719497133959,"mc":[{"id":"1.230180119","rc":[{"atb":[[1.21,0]],"id":62145089}],"con":true,"img":false}]}
{"op":"mcm","clk":"11540669355","pt":1719497134222,"mc":[{"id":"1.230180119","rc":[{"atb":[[1.25,15.79]],"id":62145089}],"con":true,"img":false}]}
{"op":"mcm","clk":"11540670828","pt":1719497151535,"mc":[{"id":"1.230180119","rc":[{"atb":[[1.21,0]],"id":48534288}],"con":true,"img":false}]}
{"op":"mcm","clk":"11540670843","pt":1719497151751,"mc":[{"id":"1.230180119","rc":[{"atb":[[1.25,15.79]],"id":48534288}],"con":true,"img":false}]}
{"op":"mcm","clk":"11540672579","pt":1719497171288,"mc":[{"id":"1.230180119","rc":[{"atb":[[1.23,0]],"id":50772801},{"spn":38.12,"spf":"NaN","id":50772801},{"spn":38.12,"spf":"NaN","id":62145089},{"spn":38.12,"spf":"NaN","id":48534288}],"con":true,"img":false}]}
{"op":"mcm","clk":"11540672619","pt":1719497171654,"mc":[{"id":"1.230180119","rc":[{"atb":[[1.23,0]],"id":62145089},{"atb":[[1.23,0]],"id":48534288}],"con":true,"img":false}]}
{"op":"mcm","clk":"11540672680","pt":1719497172278,"mc":[{"id":"1.230180119","rc":[{"atb":[[1.27,15.67]],"id":50772801},{"atb":[[1.27,15.67]],"id":62145089}],"con":true,"img":false}]}
{"op":"mcm","clk":"11540672730","pt":1719497172845,"mc":[{"id":"1.230180119","rc":[{"atb":[[1.27,15.67]],"id":48534288}],"con":true,"img":false}]}
{"op":"mcm","clk":"11540674314","pt":1719497190265,"mc":[{"id":"1.230180119","rc":[{"atb":[[1.25,0]],"id":50772801}],"con":true,"img":false}]}
{"op":"mcm","clk":"11540674351","pt":1719497190674,"mc":[{"id":"1.230180119","rc":[{"atb":[[1.25,0]],"id":48534288}],"con":true,"img":false}]}
{"op":"mcm","clk":"11540674363","pt":1719497190777,"mc":[{"id":"1.230180119","rc":[{"atb":[[1.25,0]],"id":62145089}],"con":true,"img":false}]}
{"op":"mcm","clk":"11540674382","pt":1719497191090,"mc":[{"id":"1.230180119","rc":[{"atb":[[1.29,13.61]],"id":48534288}],"con":true,"img":false}]}
{"op":"mcm","clk":"11540674407","pt":1719497191294,"mc":[{"id":"1.230180119","rc":[{"atb":[[1.29,13.61]],"id":50772801}],"con":true,"img":false}]}
{"op":"mcm","clk":"11540674427","pt":1719497191505,"mc":[{"id":"1.230180119","rc":[{"atb":[[1.29,13.61]],"id":62145089}],"con":true,"img":false}]}
{"op":"mcm","clk":"11540675822","pt":1719497207528,"mc":[{"id":"1.230180119","rc":[{"atb":[[1.27,0]],"id":50772801}],"con":true,"img":false}]}
{"op":"mcm","clk":"11540675845","pt":1719497207783,"mc":[{"id":"1.230180119","rc":[{"atb":[[1.27,0]],"id":48534288}],"con":true,"img":false}]}
{"op":"mcm","clk":"11540675850","pt":1719497207892,"mc":[{"id":"1.230180119","rc":[{"atb":[[1.27,0]],"id":62145089}],"con":true,"img":false}]}
{"op":"mcm","clk":"11540675875","pt":1719497208097,"mc":[{"id":"1.230180119","rc":[{"atb":[[1.31,13.65]],"id":50772801}],"con":true,"img":false}]}
{"op":"mcm","clk":"11540675923","pt":1719497208716,"mc":[{"id":"1.230180119","rc":[{"atb":[[1.31,13.65]],"id":48534288}],"con":true,"img":false}]}
{"op":"mcm","clk":"11540675957","pt":1719497209089,"mc":[{"id":"1.230180119","rc":[{"atb":[[1.31,13.65]],"id":62145089}],"con":true,"img":false}]}
{"op":"mcm","clk":"11540675986","pt":1719497209394,"mc":[{"id":"1.230180119","rc":[{"atb":[[1.29,0]],"id":50772801}],"con":true,"img":false}]}
{"op":"mcm","clk":"11540676008","pt":1719497209703,"mc":[{"id":"1.230180119","rc":[{"atb":[[1.33,11.96]],"id":50772801}],"con":true,"img":false}]}
{"op":"mcm","clk":"11540676067","pt":1719497210220,"mc":[{"id":"1.230180119","rc":[{"atb":[[1.29,0]],"id":48534288}],"con":true,"img":false}]}
{"op":"mcm","clk":"11540676086","pt":1719497210485,"mc":[{"id":"1.230180119","rc":[{"atb":[[1.33,11.96]],"id":48534288}],"con":true,"img":false}]}
{"op":"mcm","clk":"11540677725","pt":1719497229947,"mc":[{"id":"1.230180119","rc":[{"atb":[[1.29,0]],"id":62145089}],"con":true,"img":false}]}
{"op":"mcm","clk":"11540677767","pt":1719497230314,"mc":[{"id":"1.230180119","rc":[{"atb":[[1.33,11.96]],"id":62145089}],"con":true,"img":false}]}
{"op":"mcm","clk":"11540678800","pt":1719497243066,"mc":[{"id":"1.230180119","rc":[{"atb":[[1.31,0]],"id":50772801},{"spn":38.16,"spf":"NaN","id":50772801},{"spn":38.16,"spf":"NaN","id":62145089},{"spn":38.16,"spf":"NaN","id":48534288}],"con":true,"img":false}]}
{"op":"mcm","clk":"11540678831","pt":1719497243433,"mc":[{"id":"1.230180119","rc":[{"atb":[[1.31,0]],"id":48534288}],"con":true,"img":false}]}
{"op":"mcm","clk":"11540678862","pt":1719497243740,"mc":[{"id":"1.230180119","rc":[{"atb":[[1.31,0]],"id":62145089}],"con":true,"img":false}]}
{"op":"mcm","clk":"11540678893","pt":1719497244053,"mc":[{"id":"1.230180119","rc":[{"atb":[[1.35,12.09]],"id":50772801}],"con":true,"img":false}]}
{"op":"mcm","clk":"11540678956","pt":1719497244669,"mc":[{"id":"1.230180119","rc":[{"atb":[[1.35,12.09]],"id":62145089},{"atb":[[1.35,12.09]],"id":48534288}],"con":true,"img":false}]}
{"op":"mcm","clk":"11540679474","pt":1719497250953,"mc":[{"id":"1.230180119","rc":[{"atb":[[1.33,0]],"id":50772801},{"atb":[[1.33,0]],"id":62145089}],"con":true,"img":false}]}
{"op":"mcm","clk":"11540679497","pt":1719497251270,"mc":[{"id":"1.230180119","rc":[{"atb":[[1.33,0]],"id":48534288}],"con":true,"img":false}]}
{"op":"mcm","clk":"11540679526","pt":1719497251677,"mc":[{"id":"1.230180119","rc":[{"atb":[[1.37,10.66]],"id":50772801},{"atb":[[1.37,10.66]],"id":62145089}],"con":true,"img":false}]}
{"op":"mcm","clk":"11540679543","pt":1719497251933,"mc":[{"id":"1.230180119","rc":[{"atb":[[1.37,10.66]],"id":48534288}],"con":true,"img":false}]}
{"op":"mcm","clk":"11540681742","pt":1719497280362,"mc":[{"id":"1.230180119","rc":[{"atb":[[1.35,0]],"id":50772801}],"con":true,"img":false}]}
{"op":"mcm","clk":"11540681768","pt":1719497280673,"mc":[{"id":"1.230180119","rc":[{"atb":[[1.35,0]],"id":62145089}],"con":true,"img":false}]}
{"op":"mcm","clk":"11540681800","pt":1719497281089,"mc":[{"id":"1.230180119","rc":[{"atb":[[1.35,0]],"id":48534288}],"con":true,"img":false}]}
{"op":"mcm","clk":"11540681811","pt":1719497281296,"mc":[{"id":"1.230180119","rc":[{"atb":[[1.39,10.85]],"id":50772801}],"con":true,"img":false}]}
{"op":"mcm","clk":"11540681819","pt":1719497281404,"mc":[{"id":"1.230180119","rc":[{"atb":[[1.39,10.85]],"id":62145089}],"con":true,"img":false}]}
{"op":"mcm","clk":"11540681859","pt":1719497281870,"mc":[{"id":"1.230180119","rc":[{"atb":[[1.39,10.85]],"id":48534288}],"con":true,"img":false}]}
{"op":"mcm","clk":"11540688119","pt":1719497288492,"mc":[{"id":"1.230180119","rc":[{"atb":[[1.37,0]],"id":62145089}],"con":true,"img":false}]}
{"op":"mcm","clk":"11540688157","pt":1719497288904,"mc":[{"id":"1.230180119","rc":[{"atb":[[1.41,9.63]],"id":62145089}],"con":true,"img":false}]}
{"op":"mcm","clk":"11540688182","pt":1719497289214,"mc":[{"id":"1.230180119","rc":[{"atb":[[1.37,0]],"id":50772801},{"atb":[[1.37,0]],"id":48534288}],"con":true,"img":false}]}
{"op":"mcm","clk":"11540688231","pt":1719497289686,"mc":[{"id":"1.230180119","rc":[{"atb":[[1.41,9.63]],"id":48534288}],"con":true,"img":false}]}
{"op":"mcm","clk":"11540688237","pt":1719497289783,"mc":[{"id":"1.230180119","rc":[{"atb":[[1.41,9.63]],"id":50772801}],"con":true,"img":false}]}
{"op":"mcm","clk":"11540690675","pt":1719497317662,"mc":[{"id":"1.230180119","rc":[{"atb":[[1.39,0]],"id":50772801},{"spn":38.2,"spf":"NaN","id":50772801},{"spn":38.2,"spf":"NaN","id":62145089},{"spn":38.2,"spf":"NaN","id":48534288}],"con":true,"img":false}]}
{"op":"mcm","clk":"11540690683","pt":1719497317722,"mc":[{"id":"1.230180119","rc":[{"atb":[[1.39,0]],"id":62145089}],"con":true,"img":false}]}
{"op":"mcm","clk":"11540690729","pt":1719497318238,"mc":[{"id":"1.230180119","rc":[{"atb":[[1.39,0]],"id":48534288}],"con":true,"img":false}]}
{"op":"mcm","clk":"11540690762","pt":1719497318659,"mc":[{"id":"1.230180119","rc":[{"atb":[[1.43,9.84]],"id":50772801}],"con":true,"img":false}]}
{"op":"mcm","clk":"11540690785","pt":1719497318922,"mc":[{"id":"1.230180119","rc":[{"atb":[[1.43,9.84]],"id":62145089}],"con":true,"img":false}]}
{"op":"mcm","clk":"11540690805","pt":1719497319135,"mc":[{"id":"1.230180119","rc":[{"atb":[[1.43,9.84]],"id":48534288}],"con":true,"img":false}]}
{"op":"mcm","clk":"11540691511","pt":1719497327560,"mc":[{"id":"1.230180119","rc":[{"atb":[[1.41,0]],"id":50772801}],"con":true,"img":false}]}
{"op":"mcm","clk":"11540691521","pt":1719497327661,"mc":[{"id":"1.230180119","rc":[{"atb":[[1.41,0]],"id":62145089}],"con":true,"img":false}]}
{"op":"mcm","clk":"11540691534","pt":1719497327762,"mc":[{"id":"1.230180119","rc":[{"atb":[[1.41,0]],"id":48534288}],"con":true,"img":false}]}
{"op":"mcm","clk":"11540691591","pt":1719497328275,"mc":[{"id":"1.230180119","rc":[{"atb":[[1.45,8.77]],"id":50772801},{"atb":[[1.45,8.77]],"id":62145089}],"con":true,"img":false}]}
{"op":"mcm","clk":"11540691646","pt":1719497328757,"mc":[{"id":"1.230180119","rc":[{"atb":[[1.45,8.77]],"id":48534288}],"con":true,"img":false}]}
{"op":"mcm","clk":"11540694038","pt":1719497356213,"mc":[{"id":"1.230180119","rc":[{"atb":[[1.43,0]],"id":50772801}],"con":true,"img":false}]}
{"op":"mcm","clk":"11540694071","pt":1719497356480,"mc":[{"id":"1.230180119","rc":[{"atb":[[1.43,0]],"id":48534288}],"con":true,"img":false}]}
{"op":"mcm","clk":"11540694096","pt":1719497356795,"mc":[{"id":"1.230180119","rc":[{"atb":[[1.47,9]],"id":50772801}],"con":true,"img":false}]}
{"op":"mcm","clk":"11540694122","pt":1719497357104,"mc":[{"id":"1.230180119","rc":[{"atb":[[1.43,0]],"id":62145089}],"con":true,"img":false}]}
{"op":"mcm","clk":"11540694152","pt":1719497357413,"mc":[{"id":"1.230180119","rc":[{"atb":[[1.47,9]],"id":48534288}],"con":true,"img":false}]}
{"op":"mcm","clk":"11540694188","pt":1719497357816,"mc":[{"id":"1.230180119","rc":[{"atb":[[1.47,9]],"id":62145089}],"con":true,"img":false}]}
{"op":"mcm","clk":"11540695021","pt":1719497366620,"mc":[{"id":"1.230180119","rc":[{"atb":[[1.45,0]],"id":50772801},{"atb":[[1.45,0]],"id":62145089}],"con":true,"img":false}]}
{"op":"mcm","clk":"11540695042","pt":1719497366894,"mc":[{"id":"1.230180119","rc":[{"atb":[[1.45,0]],"id":48534288}],"con":true,"img":false}]}
{"op":"mcm","clk":"11540695116","pt":1719497367714,"mc":[{"id":"1.230180119","rc":[{"atb":[[1.49,8.05]],"id":50772801}],"con":true,"img":false}]}
{"op":"mcm","clk":"11540695138","pt":1719497367914,"mc":[{"id":"1.230180119","rc":[{"atb":[[1.49,8.05]],"id":62145089}],"con":true,"img":false}]}
{"op":"mcm","clk":"11540695172","pt":1719497368232,"mc":[{"id":"1.230180119","rc":[{"atb":[[1.49,8.05]],"id":48534288}],"con":true,"img":false}]}
{"op":"mcm","clk":"11540697207","pt":1719497392036,"mc":[{"id":"1.230180119","rc":[{"atb":[[1.47,0]],"id":50772801},{"spn":38.24,"spf":"NaN","id":50772801},{"spn":38.24,"spf":"NaN","id":62145089},{"spn":38.24,"spf":"NaN","id":48534288}],"con":true,"img":false}]}
{"op":"mcm","clk":"11540697269","pt":1719497392750,"mc":[{"id":"1.230180119","rc":[{"atb":[[1.47,0]],"id":48534288}],"con":true,"img":false}]}
{"op":"mcm","clk":"11540697314","pt":1719497393218,"mc":[{"id":"1.230180119","rc":[{"atb":[[1.47,0]],"id":62145089}],"con":true,"img":false}]}
{"op":"mcm","clk":"11540697319","pt":1719497393316,"mc":[{"id":"1.230180119","rc":[{"atb":[[1.51,8.29]],"id":48534288}],"con":true,"img":false}]}
{"op":"mcm","clk":"11540697346","pt":1719497393638,"mc":[{"id":"1.230180119","rc":[{"atb":[[1.51,8.29]],"id":50772801}],"con":true,"img":false}]}
{"op":"mcm","clk":"11540697362","pt":1719497393836,"mc":[{"id":"1.230180119","rc":[{"atb":[[1.51,8.29]],"id":62145089}],"con":true,"img":false}]}
{"op":"mcm","clk":"11540698400","pt":1719497404153,"mc":[{"id":"1.230180119","rc":[{"atb":[[1.49,0]],"id":50772801}],"con":true,"img":false}]}
{"op":"mcm","clk":"11540698426","pt":1719497404362,"mc":[{"id":"1.230180119","rc":[{"atb":[[1.49,0]],"id":48534288}],"con":true,"img":false}]}
{"op":"mcm","clk":"11540698467","pt":1719497404661,"mc":[{"id":"1.230180119","rc":[{"atb":[[1.53,7.44]],"id":50772801}],"con":true,"img":false}]}
{"op":"mcm","clk":"11540698493","pt":1719497404825,"mc":[{"id":"1.230180119","rc":[{"atb":[[1.49,0]],"id":62145089}],"con":true,"img":false}]}
{"op":"mcm","clk":"11540698509","pt":1719497405038,"mc":[{"id":"1.230180119","rc":[{"atb":[[1.53,7.44]],"id":48534288}],"con":true,"img":false}]}
{"op":"mcm","clk":"11540698538","pt":1719497405356,"mc":[{"id":"1.230180119","rc":[{"atb":[[1.53,7.44]],"id":62145089}],"con":true,"img":false}]}
{"op":"mcm","clk":"11540700505","pt":1719497425029,"mc":[{"id":"1.230180119","rc":[{"atb":[[1.09,43.87]],"id":69624671}],"con":true,"img":false}]}
{"op":"mcm","clk":"11540701071","pt":1719497430981,"mc":[{"id":"1.230180119","rc":[{"atb":[[1.51,0]],"id":50772801}],"con":true,"img":false}]}
{"op":"mcm","clk":"11540701101","pt":1719497431286,"mc":[{"id":"1.230180119","rc":[{"atb":[[1.51,0]],"id":48534288}],"con":true,"img":false}]}
{"op":"mcm","clk":"11540701111","pt":1719497431388,"mc":[{"id":"1.230180119","rc":[{"atb":[[1.51,0]],"id":62145089}],"con":true,"img":false}]}
{"op":"mcm","clk":"11540701136","pt":1719497431649,"mc":[{"id":"1.230180119","rc":[{"atb":[[1.11,38.47]],"id":69624671}],"con":true,"img":false}]}
{"op":"mcm","clk":"11540701184","pt":1719497432274,"mc":[{"id":"1.230180119","rc":[{"atb":[[1.55,7.69]],"id":50772801}],"con":true,"img":false}]}
{"op":"mcm","clk":"11540701193","pt":1719497432375,"mc":[{"id":"1.230180119","rc":[{"atb":[[1.55,7.69]],"id":62145089}],"con":true,"img":false}]}
{"op":"mcm","clk":"11540701209","pt":1719497432581,"mc":[{"id":"1.230180119","rc":[{"atb":[[1.55,7.69]],"id":48534288}],"con":true,"img":false}]}
{"op":"mcm","clk":"11540702360","pt":1719497444087,"mc":[{"id":"1.230180119","rc":[{"atb":[[1.53,0]],"id":48534288}],"con":true,"img":false}]}
{"op":"mcm","clk":"11540702383","pt":1719497444407,"mc":[{"id":"1.230180119","rc":[{"atb":[[1.53,0]],"id":50772801}],"con":true,"img":false}]}
{"op":"mcm","clk":"11540702408","pt":1719497444655,"mc":[{"id":"1.230180119","rc":[{"atb":[[1.57,6.92]],"id":48534288}],"con":true,"img":false}]}
{"op":"mcm","clk":"11540702416","pt":1719497444804,"mc":[{"id":"1.230180119","rc":[{"atb":[[1.09,0]],"id":69624671}],"con":true,"img":false}]}
{"op":"mcm","clk":"11540702437","pt":1719497444969,"mc":[{"id":"1.230180119","rc":[{"atb":[[1.53,0]],"id":62145089}],"con":true,"img":false}]}
{"op":"mcm","clk":"11540702479","pt":1719497445375,"mc":[{"id":"1.230180119","rc":[{"atb":[[1.57,6.92]],"id":50772801}],"con":true,"img":false}]}
{"op":"mcm","clk":"11540702493","pt":1719497445582,"mc":[{"id":"1.230180119","rc":[{"atb":[[1.57,6.92]],"id":62145089},{"atb":[[1.13,30.37]],"id":69624671}],"con":true,"img":false}]}
{"op":"mcm","clk":"11540705105","pt":1719497471315,"mc":[{"id":"1.230180119","rc":[{"spn":38.28,"spf":"NaN","id":50772801},{"spn":38.28,"spf":"NaN","id":62145089},{"atb":[[1.11,0]],"id":69624671},{"spn":38.28,"spf":"NaN","id":48534288}],"con":true,"img":false}]}
{"op":"mcm","clk":"11540705113","pt":1719497471421,"mc":[{"id":"1.230180119","rc":[{"atb":[[1.55,0]],"id":50772801}],"con":true,"img":false}]}
{"op":"mcm","clk":"11540705132","pt":1719497471624,"mc":[{"id":"1.230180119","rc":[{"atb":[[1.55,0]],"id":48534288}],"con":true,"img":false}]}
{"op":"mcm","clk":"11540705143","pt":1719497471731,"mc":[{"id":"1.230180119","rc":[{"atb":[[1.55,0]],"id":62145089}],"con":true,"img":false}]}
{"op":"mcm","clk":"11540705165","pt":1719497471884,"mc":[{"id":"1.230180119","rc":[{"atb":[[1.15,28.21]],"id":69624671}],"con":true,"img":false}]}
{"op":"mcm","clk":"11540705170","pt":1719497471986,"mc":[{"id":"1.230180119","rc":[{"atb":[[1.59,7.17]],"id":50772801}],"con":true,"img":false}]}
{"op":"mcm","clk":"11540705199","pt":1719497472295,"mc":[{"id":"1.230180119","rc":[{"atb":[[1.59,7.17]],"id":62145089}],"con":true,"img":false}]}
{"op":"mcm","clk":"11540705209","pt":1719497472404,"mc":[{"id":"1.230180119","rc":[{"atb":[[1.59,7.17]],"id":48534288}],"con":true,"img":false}]}
{"op":"mcm","clk":"11540706164","pt":1719497482813,"mc":[{"id":"1.230180119","rc":[{"atb":[[1.57,0]],"id":50772801}],"con":true,"img":false}]}
{"op":"mcm","clk":"11540706184","pt":1719497483020,"mc":[{"id":"1.230180119","rc":[{"atb":[[1.13,0]],"id":69624671}],"con":true,"img":false}]}
{"op":"mcm","clk":"11540706196","pt":1719497483122,"mc":[{"id":"1.230180119","rc":[{"atb":[[1.57,0]],"id":62145089}],"con":true,"img":false}]}
{"op":"mcm","clk":"11540706212","pt":1719497483331,"mc":[{"id":"1.230180119","rc":[{"atb":[[1.61,6.47]],"id":50772801},{"atb":[[1.57,0]],"id":48534288}],"con":true,"img":false}]}
{"op":"mcm","clk":"11540706229","pt":1719497483533,"mc":[{"id":"1.230180119","rc":[{"atb":[[1.61,6.47]],"id":62145089},{"atb":[[1.17,23.22]],"id":69624671}],"con":true,"img":false}]}
{"op":"mcm","clk":"11540706248","pt":1719497483744,"mc":[{"id":"1.230180119","rc":[{"atb":[[1.61,6.47]],"id":48534288}],"con":true,"img":false}]}
{"op":"mcm","clk":"11540708293","pt":1719497508454,"mc":[{"id":"1.230180119","rc":[{"atb":[[1.59,0]],"id":50772801}],"con":true,"img":false}]}
{"op":"mcm","clk":"11540708330","pt":1719497508870,"mc":[{"id":"1.230180119","rc":[{"atb":[[1.59,0]],"id":62145089},{"atb":[[1.15,0]],"id":69624671}],"con":true,"img":false}]}
{"op":"mcm","clk":"11540708360","pt":1719497509131,"mc":[{"id":"1.230180119","rc":[{"atb":[[1.63,6.72]],"id":50772801}],"con":true,"img":false}]}
{"op":"mcm","clk":"11540708371","pt":1719497509240,"mc":[{"id":"1.230180119","rc":[{"atb":[[1.59,0]],"id":48534288}],"con":true,"img":false}]}
{"op":"mcm","clk":"11540708393","pt":1719497509446,"mc":[{"id":"1.230180119","rc":[{"atb":[[1.19,22.28]],"id":69624671}],"con":true,"img":false}]}
{"op":"mcm","clk":"11540708405","pt":1719497509544,"mc":[{"id":"1.230180119","rc":[{"atb":[[1.63,6.72]],"id":62145089}],"con":true,"img":false}]}
{"op":"mcm","clk":"11540708430","pt":1719497509848,"mc":[{"id":"1.230180119","rc":[{"atb":[[1.63,6.72]],"id":48534288}],"con":true,"img":false}]}
{"op":"mcm","clk":"11540709619","pt":1719497522118,"mc":[{"id":"1.230180119","rc":[{"atb":[[1.61,0]],"id":50772801}],"con":true,"img":false}]}
{"op":"mcm","clk":"11540709657","pt":1719497522376,"mc":[{"id":"1.230180119","rc":[{"atb":[[1.17,0]],"id":69624671}],"con":true,"img":false}]}
{"op":"mcm","clk":"11540709695","pt":1719497522690,"mc":[{"id":"1.230180119","rc":[{"atb":[[1.61,0]],"id":48534288}],"con":true,"img":false}]}
{"op":"mcm","clk":"11540709722","pt":1719497522870,"mc":[{"id":"1.230180119","rc":[{"atb":[[1.65,6.07]],"id":50772801},{"atb":[[1.21,18.8]],"id":69624671}],"con":true,"img":false}]}
{"op":"mcm","clk":"11540709745","pt":1719497523048,"mc":[{"id":"1.230180119","rc":[{"atb":[[1.65,6.07]],"id":48534288}],"con":true,"img":false}]}
{"op":"mcm","clk":"11540711795","pt":1719497546989,"mc":[{"id":"1.230180119","rc":[{"atb":[[1.63,0]],"id":50772801},{"spn":38.32,"spf":"NaN","id":50772801},{"spn":38.31,"spf":"NaN","id":62145089},{"spn":38.1,"spf":"NaN","id":69624671},{"spn":38.32,"spf":"NaN","id":48534288}],"con":true,"img":false}]}
{"op":"mcm","clk":"11540711822","pt":1719497547298,"mc":[{"id":"1.230180119","rc":[{"atb":[[1.19,0]],"id":69624671},{"atb":[[1.63,0]],"id":48534288}],"con":true,"img":false}]}
{"op":"mcm","clk":"11540711849","pt":1719497547606,"mc":[{"id":"1.230180119","rc":[{"atb":[[1.67,6.31]],"id":50772801}],"con":true,"img":false}]}
{"op":"mcm","clk":"11540711865","pt":1719497547817,"mc":[{"id":"1.230180119","rc":[{"atb":[[1.23,18.4]],"id":69624671}],"con":true,"img":false}]}
{"op":"mcm","clk":"11540711898","pt":1719497548074,"mc":[{"id":"1.230180119","rc":[{"atb":[[1.67,6.31]],"id":48534288}],"con":true,"img":false}]}
{"op":"mcm","clk":"11540713241","pt":1719497563438,"mc":[{"id":"1.230180119","rc":[{"atb":[[1.65,0]],"id":50772801},{"atb":[[1.21,0]],"id":69624671}],"con":true,"img":false}]}
{"op":"mcm","clk":"11540713261","pt":1719497563595,"mc":[{"id":"1.230180119","rc":[{"atb":[[1.69,5.72]],"id":50772801},{"atb":[[1.25,15.79]],"id":69624671}],"con":true,"img":false}]}
{"op":"mcm","clk":"11540714805","pt":1719497582634,"mc":[{"id":"1.230180119","rc":[{"atb":[[1.61,0]],"id":62145089}],"con":true,"img":false}]}
{"op":"mcm","clk":"11540715070","pt":1719497585436,"mc":[{"id":"1.230180119","rc":[{"atb":[[1.67,0]],"id":50772801},{"atb":[[1.23,0]],"id":69624671}],"con":true,"img":false}]}
{"op":"mcm","clk":"11540715099","pt":1719497585747,"mc":[{"id":"1.230180119","rc":[{"atb":[[1.71,5.96]],"id":50772801},{"atb":[[1.27,15.67]],"id":69624671}],"con":true,"img":false}]}
{"op":"mcm","clk":"11540716255","pt":1719497600240,"mc":[{"id":"1.230180119","rc":[{"atb":[[1.69,0]],"id":50772801},{"atb":[[1.25,0]],"id":69624671}],"con":true,"img":false}]}
{"op":"mcm","clk":"11540716267","pt":1719497600442,"mc":[{"id":"1.230180119","rc":[{"atb":[[1.73,5.4]],"id":50772801},{"atb":[[1.29,13.61]],"id":69624671}],"con":true,"img":false}]}
{"op":"mcm","clk":"11540718054","pt":1719497622472,"mc":[{"id":"1.230180119","rc":[{"atb":[[1.71,0]],"id":50772801},{"spn":38.36,"spf":"NaN","id":50772801},{"atb":[[1.27,0]],"id":69624671},{"spn":38.14,"spf":"NaN","id":69624671},{"spn":38.33,"spf":"NaN","id":48534288}],"con":true,"img":false}]}
{"op":"mcm","clk":"11540718079","pt":1719497622788,"mc":[{"id":"1.230180119","rc":[{"atb":[[1.31,13.65]],"id":69624671}],"con":true,"img":false}]}
{"op":"mcm","clk":"11540718097","pt":1719497622988,"mc":[{"id":"1.230180119","rc":[{"atb":[[1.75,5.64]],"id":50772801}],"con":true,"img":false}]}
{"op":"mcm","clk":"11540718568","pt":1719497628704,"mc":[{"id":"1.230180119","rc":[{"atb":[[1.73,0]],"id":50772801}],"con":true,"img":false}]}
{"op":"mcm","clk":"11540718602","pt":1719497628965,"mc":[{"id":"1.230180119","rc":[{"atb":[[1.29,0]],"id":69624671}],"con":true,"img":false}]}
{"op":"mcm","clk":"11540718628","pt":1719497629170,"mc":[{"id":"1.230180119","rc":[{"atb":[[1.77,5.12]],"id":50772801}],"con":true,"img":false}]}
{"op":"mcm","clk":"11540718645","pt":1719497629376,"mc":[{"id":"1.230180119","rc":[{"atb":[[1.33,11.96]],"id":69624671}],"con":true,"img":false}]}
{"op":"mcm","clk":"11540719556","pt":1719497640390,"mc":[{"id":"1.230180119","rc":[{"atb":[[1.78,5.13],[2.1,1]],"id":50772801},{"atl":[[19.5,2],[7,1]],"id":50772801},{"atb":[[1.64,2.48],[1.74,1]],"id":62145089},{"atl":[[5.3,1],[13.5,2]],"id":62145089},{"atb":[[1.51,1],[1.39,11.96]],"id":69624671},{"atl":[[4.1,1],[7.8,2]],"id":69624671},{"atb":[[1.46,1],[1.22,2.48]],"id":60276470},{"atl":[[3.8,1],[6.6,2]],"id":60276470},{"atb":[[1.41,1],[1.37,2.48]],"id":69475360},{"atl":[[7.4,2],[3.55,1]],"id":69475360}],"con":true,"img":false}]}
{"op":"mcm","clk":"11540719570","pt":1719497640492,"mc":[{"id":"1.230180119","rc":[{"atb":[[1.73,6.07]],"id":48534288},{"atl":[[19.5,2]],"id":48534288}],"con":true,"img":false}]}
{"op":"mcm","clk":"11540719582","pt":1719497640597,"mc":[{"id":"1.230180119","rc":[{"atb":[[1.97,1]],"id":48534288},{"atl":[[6.4,1]],"id":48534288}],"con":true,"img":false}]}
{"op":"mcm","clk":"11540719592","pt":1719497640701,"mc":[{"id":"1.230180119","rc":[{"atb":[[1.01,1.7]],"id":50772801},{"atl":[[1000,1.7]],"id":50772801},{"atb":[[1.01,1.7]],"id":69624671},{"atl":[[7.8,7.94],[1000,1.88]],"id":69624671},{"atb":[[1.01,1.7]],"id":69475360},{"atl":[[1000,1.7]],"id":69475360}],"con":true,"img":false}]}
{"op":"mcm","clk":"11540719619","pt":1719497641014,"mc":[{"id":"1.230180119","rc":[{"atb":[[1.01,0.4]],"id":50772801},{"atl":[[1000,0.01]],"id":50772801},{"atb":[[1.01,0.79]],"id":69624671},{"atl":[[1000,0.22]],"id":69624671},{"atb":[[1.01,0.83]],"id":69475360},{"atl":[[1000,0.05]],"id":69475360}],"con":true,"img":false}]}
{"op":"mcm","clk":"11540719650","pt":1719497641317,"mc":[{"id":"1.230180119","rc":[{"atb":[[1.01,0]],"id":50772801},{"atl":[[1000,0]],"id":50772801},{"atb":[[1.01,0]],"id":69624671},{"atl":[[1000,0.17]],"id":69624671},{"atb":[[1.01,0]],"id":69475360},{"atl":[[1000,0]],"id":69475360}],"con":true,"img":false}]}
{"op":"mcm","clk":"11540719660","pt":1719497641424,"mc":[{"id":"1.230180119","rc":[{"atb":[[1.79,0.4]],"id":50772801},{"atl":[[19,0.01]],"id":50772801},{"atb":[[1.4,0.79]],"id":69624671},{"atl":[[7.6,0.04]],"id":69624671},{"atb":[[1.38,0.83]],"id":69475360},{"atl":[[7.2,0.05]],"id":69475360}],"con":true,"img":false}]}
{"op":"mcm","clk":"11540719868","pt":1719497643391,"mc":[{"id":"1.230180119","rc":[{"atb":[[1.8,2.11]],"id":50772801},{"atb":[[1.66,2.11]],"id":62145089},{"atb":[[1.42,2.11]],"id":69624671},{"atb":[[1.7,2.11]],"id":48534288}],"con":true,"img":false}]}
{"op":"mcm","clk":"11540720057","pt":1719497645501,"mc":[{"id":"1.230180119","rc":[{"atl":[[19.5,3],[13.5,0]],"id":62145089},{"atl":[[6.6,0],[9.4,3]],"id":60276470}],"con":true,"img":false}]}
{"op":"mcm","clk":"11540720066","pt":1719497645603,"mc":[{"id":"1.230180119","rc":[{"atl":[[19.5,0],[28,3]],"id":48534288}],"con":true,"img":false}]}
{"op":"mcm","clk":"11540720073","pt":1719497645718,"mc":[{"id":"1.230180119","rc":[{"atb":[[1.33,0]],"id":69624671}],"con":true,"img":false}]}
{"op":"mcm","clk":"11540720089","pt":1719497645913,"mc":[{"id":"1.230180119","rc":[{"atb":[[1.44,8.97]],"id":69624671}],"con":true,"img":false}]}
{"op":"mcm","clk":"11540720444","pt":1719497650297,"mc":[{"id":"1.230180119","rc":[{"atb":[[1.63,0]],"id":62145089}],"con":true,"img":false}]}
{"op":"mcm","clk":"11540720462","pt":1719497650501,"mc":[{"id":"1.230180119","rc":[{"atb":[[1.64,0],[1.71,2.12]],"id":62145089},{"atb":[[1.5,2.12],[1.39,0]],"id":69624671},{"atb":[[1.22,0],[1.31,2.48]],"id":60276470},{"atb":[[1.37,0],[1.48,2]],"id":69475360}],"con":true,"img":false}]}
{"op":"mcm","clk":"11540720471","pt":1719497650606,"mc":[{"id":"1.230180119","rc":[{"atb":[[1.73,0],[1.83,6.07]],"id":48534288}],"con":true,"img":false}]}
{"op":"mcm","clk":"11540720800","pt":1719497654117,"mc":[{"id":"1.230180119","rc":[{"atl":[[8.2,1]],"id":50772801},{"atl":[[4.3,1]],"id":60276470}],"con":true,"img":false}]}
{"op":"mcm","clk":"11540720806","pt":1719497654217,"mc":[{"id":"1.230180119","rc":[{"atl":[[7,0]],"id":50772801},{"atl":[[6.2,1],[5.3,0]],"id":62145089},{"atl":[[4.1,0],[4.9,1],[7.8,2]],"id":69624671},{"atl":[[3.8,0]],"id":60276470},{"atl":[[8,1],[6.4,0]],"id":48534288},{"atl":[[3.55,0],[4.2,1]],"id":69475360}],"con":true,"img":false}]}
{"op":"mcm","clk":"11540720817","pt":1719497654423,"mc":[{"id":"1.230180119","rc":[{"atl":[[8.2,0]],"id":50772801}],"con":true,"img":false}]}
{"op":"mcm","clk":"11540720822","pt":1719497654535,"mc":[{"id":"1.230180119","rc":[{"atl":[[19.5,0],[28,2.02]],"id":50772801},{"atl":[[7.8,7.97]],"id":69624671}],"con":true,"img":false}]}
{"op":"mcm","clk":"11540720831","pt":1719497654632,"mc":[{"id":"1.230180119","rc":[{"atl":[[8.2,1]],"id":50772801}],"con":true,"img":false}]}
{"op":"mcm","clk":"11540720925","pt":1719497656023,"mc":[{"id":"1.230180119","rc":[{"atl":[[7.8,2]],"id":69624671}],"con":true,"img":false}]}
{"op":"mcm","clk":"11540720946","pt":1719497656334,"mc":[{"id":"1.230180119","rc":[{"atl":[[7.6,2.06]],"id":69624671}],"con":true,"img":false}]}
{"op":"mcm","clk":"11540721019","pt":1719497657517,"mc":[{"id":"1.230180119","rc":[{"atb":[[1.78,0],[1.87,2.12]],"id":50772801},{"atb":[[1.75,2.12],[1.71,0]],"id":62145089},{"atb":[[1.5,0],[1.51,3.12]],"id":69624671},{"atb":[[1.37,2.48],[1.31,0]],"id":60276470},{"atb":[[1.88,6.07]],"id":48534288},{"atb":[[1.48,0],[1.53,2]],"id":69475360}],"con":true,"img":false}]}
{"op":"mcm","clk":"11540721026","pt":1719497657615,"mc":[{"id":"1.230180119","rc":[{"atb":[[1.83,0]],"id":48534288}],"con":true,"img":false}]}
{"op":"mcm","clk":"11540721158","pt":1719497659313,"mc":[{"id":"1.230180119","rc":[{"atl":[[7.6,0.04]],"id":69624671}],"con":true,"img":false}]}
{"op":"mcm","clk":"11540721641","pt":1719497665238,"mc":[{"id":"1.230180119","rc":[{"atb":[[1.44,0]],"id":69624671}],"con":true,"img":false}]}
{"op":"mcm","clk":"11540721658","pt":1719497665438,"mc":[{"id":"1.230180119","rc":[{"atl":[[4.8,1],[4.9,0]],"id":69624671}],"con":true,"img":false}]}
{"op":"mcm","clk":"11540721669","pt":1719497665642,"mc":[{"id":"1.230180119","rc":[{"atb":[[1.53,7.44]],"id":69624671}],"con":true,"img":false}]}
{"op":"mcm","clk":"11540721803","pt":1719497667439,"mc":[{"id":"1.230180119","rc":[{"atb":[[1.76,2.12]],"id":62145089},{"atb":[[1.39,2.48]],"id":60276470},{"atb":[[1.9,6.07]],"id":48534288},{"atb":[[1.55,2]],"id":69475360}],"con":true,"img":false}]}
{"op":"mcm","clk":"11540721815","pt":1719497667542,"mc":[{"id":"1.230180119","rc":[{"atb":[[1.75,0]],"id":62145089},{"atb":[[1.54,3.12],[1.51,1]],"id":69624671},{"atb":[[1.37,0]],"id":60276470},{"atb":[[1.88,0]],"id":48534288},{"atb":[[1.53,0]],"id":69475360}],"con":true,"img":false}]}
{"op":"mcm","clk":"11540722155","pt":1719497671560,"mc":[{"id":"1.230180119","rc":[{"atb":[[1.31,0]],"id":69624671}],"con":true,"img":false}]}
{"op":"mcm","clk":"11540722172","pt":1719497671874,"mc":[{"id":"1.230180119","rc":[{"atb":[[1.56,7.56]],"id":69624671}],"con":true,"img":false}]}
{"op":"mcm","clk":"11540722407","pt":1719497674652,"mc":[{"id":"1.230180119","rc":[{"atl":[[7.8,8.86]],"id":69624671}],"con":true,"img":false}]}
{"op":"mcm","clk":"11540722443","pt":1719497675169,"mc":[{"id":"1.230180119","rc":[{"atl":[[7.8,2]],"id":69624671}],"con":true,"img":false}]}
{"op":"mcm","clk":"11540722516","pt":1719497676245,"mc":[{"id":"1.230180119","rc":[{"atl":[[8.6,1],[8.2,0]],"id":50772801},{"atl":[[4.8,0],[4.7,1]],"id":69624671},{"atl":[[8,0],[8.2,1]],"id":48534288}],"con":true,"img":false}]}
{"op":"mcm","clk":"11540722521","pt":1719497676348,"mc":[{"id":"1.230180119","rc":[{"atl":[[19,2.01]],"id":50772801},{"atl":[[27,2],[28,0]],"id":48534288}],"con":true,"img":false}]}
{"op":"mcm","clk":"11540722527","pt":1719497676450,"mc":[{"id":"1.230180119","rc":[{"atl":[[19,0.01],[28,0]],"id":50772801}],"con":true,"img":false}]}
{"op":"mcm","clk":"11540722532","pt":1719497676554,"mc":[{"id":"1.230180119","rc":[{"atl":[[26,3.02]],"id":50772801}],"con":true,"img":false}]}
{"op":"mcm","clk":"11540722608","pt":1719497677428,"mc":[{"id":"1.230180119","rc":[{"atb":[[1.57,7.45],[1.54,0]],"id":69624671}],"con":true,"img":false}]}
{"op":"mcm","clk":"11540722736","pt":1719497679076,"mc":[{"id":"1.230180119","rc":[{"atl":[[6.4,8.98]],"id":69475360}],"con":true,"img":false}]}
{"op":"mcm","clk":"11540722746","pt":1719497679186,"mc":[{"id":"1.230180119","rc":[{"atl":[[6.2,2],[7.4,0]],"id":69475360}],"con":true,"img":false}]}
{"op":"mcm","clk":"11540722751","pt":1719497679234,"mc":[{"id":"1.230180119","rc":[{"atl":[[6.4,0]],"id":69475360}],"con":true,"img":false}]}
{"op":"mcm","clk":"11540723116","pt":1719497683254,"mc":[{"id":"1.230180119","rc":[{"spn":5.35,"spf":"NaN","id":50772801},{"spn":3.98,"spf":"NaN","id":62145089},{"atb":[[1.53,0]],"id":69624671},{"spn":3.13,"spf":"NaN","id":69624671},{"atb":[[1.41,9.63]],"id":60276470},{"spn":2.88,"spf":"NaN","id":60276470},{"spn":5.08,"spf":"NaN","id":48534288},{"spn":2.87,"spf":"NaN","id":69475360}],"con":true,"img":false}]}
{"op":"mcm","clk":"11540723123","pt":1719497683358,"mc":[{"id":"1.230180119","rc":[{"atb":[[1.42,2.48]],"id":60276470}],"con":true,"img":false}]}
{"op":"mcm","clk":"11540723127","pt":1719497683458,"mc":[{"id":"1.230180119","rc":[{"atb":[[1.39,0]],"id":60276470}],"con":true,"img":false}]}
{"op":"mcm","clk":"11540723137","pt":1719497683565,"mc":[{"id":"1.230180119","rc":[{"atb":[[1.59,6.68]],"id":69624671}],"con":true,"img":false}]}
{"op":"mcm","clk":"11540723165","pt":1719497683975,"mc":[{"id":"1.230180119","rc":[{"atb":[[1.02,18.49]],"id":69475360}],"con":true,"img":false}]}
{"op":"mcm","clk":"11540723173","pt":1719497684083,"mc":[{"id":"1.230180119","rc":[{"atb":[[1.44,2.11]],"id":60276470}],"con":true,"img":false}]}
{"op":"mcm","clk":"11540723189","pt":1719497684288,"mc":[{"id":"1.230180119","rc":[{"atb":[[1.88,2]],"id":50772801},{"atb":[[1.44,4.59],[1.42,0]],"id":60276470}],"con":true,"img":false}]}
{"op":"mcm","clk":"11540723206","pt":1719497684445,"mc":[{"id":"1.230180119","rc":[{"atb":[[1.79,0]],"id":50772801},{"atl":[[19,0]],"id":50772801},{"atb":[[1.4,0],[1.58,2]],"id":69624671},{"atl":[[7.6,0]],"id":69624671},{"atb":[[1.38,0]],"id":69475360},{"atl":[[7.2,0]],"id":69475360}],"con":true,"img":false}]}
{"op":"mcm","clk":"11540723213","pt":1719497684548,"mc":[{"id":"1.230180119","rc":[{"atl":[[9,3],[7.8,0]],"id":69624671},{"atl":[[9.6,3],[6.2,0]],"id":69475360}],"con":true,"img":false}]}
{"op":"mcm","clk":"11540723229","pt":1719497684754,"mc":[{"id":"1.230180119","rc":[{"atb":[[1.02,2]],"id":62145089}],"con":true,"img":false}]}
{"op":"mcm","clk":"11540723259","pt":1719497685066,"mc":[{"id":"1.230180119","rc":[{"atb":[[1.02,2]],"id":60276470}],"con":true,"img":false}]}
{"op":"mcm","clk":"11540723305","pt":1719497685581,"mc":[{"id":"1.230180119","rc":[{"atb":[[1.91,2]],"id":48534288}],"con":true,"img":false}]}
{"op":"mcm","clk":"11540723448","pt":1719497687178,"mc":[{"id":"1.230180119","rc":[{"atb":[[1.6,6.69],[1.57,0]],"id":69624671}],"con":true,"img":false}]}
{"op":"mcm","clk":"11540723665","pt":1719497688682,"mc":[{"id":"1.230180119","rc":[{"atb":[[1.58,0]],"id":69624671}],"con":true,"img":false}]}
{"op":"mcm","clk":"11540723672","pt":1719497688784,"mc":[{"id":"1.230180119","rc":[{"atb":[[1.61,2]],"id":69624671}],"con":true,"img":false}]}
{"op":"mcm","clk":"11540724074","pt":1719497693592,"mc":[{"id":"1.230180119","rc":[{"atl":[[34,3.03],[8.6,0],[9.2,1],[26,0]],"id":50772801},{"atb":[[1.75,4.24]],"id":62145089},{"atl":[[8,1],[8.2,0]],"id":48534288},{"atb":[[1.55,0]],"id":69475360}],"con":true,"img":false}]}
{"op":"mcm","clk":"11540724082","pt":1719497693650,"mc":[{"id":"1.230180119","rc":[{"atb":[[1.99,2.12],[1.87,0]],"id":50772801},{"atb":[[1.76,0]],"id":62145089},{"atl":[[26,2],[27,0]],"id":48534288},{"atb":[[1.54,4]],"id":69475360}],"con":true,"img":false}]}
{"op":"mcm","clk":"11540724097","pt":1719497693857,"mc":[{"id":"1.230180119","rc":[{"atb":[[1.02,16.49]],"id":69475360}],"con":true,"img":false}]}
{"op":"mcm","clk":"11540724105","pt":1719497693964,"mc":[{"id":"1.230180119","rc":[{"atb":[[1.08,2]],"id":69475360}],"con":true,"img":false}]}
{"op":"mcm","clk":"11540724140","pt":1719497694371,"mc":[{"id":"1.230180119","rc":[{"atb":[[1.02,0]],"id":62145089}],"con":true,"img":false}]}
{"op":"mcm","clk":"11540724146","pt":1719497694474,"mc":[{"id":"1.230180119","rc":[{"atb":[[1.77,2]],"id":62145089}],"con":true,"img":false}]}
{"op":"mcm","clk":"11540724252","pt":1719497695868,"mc":[{"id":"1.230180119","rc":[{"atb":[[1.08,0]],"id":69475360}],"con":true,"img":false}]}
{"op":"mcm","clk":"11540724260","pt":1719497695970,"mc":[{"id":"1.230180119","rc":[{"atb":[[1.02,18.49]],"id":69475360}],"con":true,"img":false}]}
{"op":"mcm","clk":"11540724282","pt":1719497696281,"mc":[{"id":"1.230180119","rc":[{"atb":[[1.88,0]],"id":50772801}],"con":true,"img":false}]}
{"op":"mcm","clk":"11540724291","pt":1719497696379,"mc":[{"id":"1.230180119","rc":[{"atb":[[2,2]],"id":50772801}],"con":true,"img":false}]}
{"op":"mcm","clk":"11540724306","pt":1719497696585,"mc":[{"id":"1.230180119","rc":[{"atb":[[1.77,0]],"id":62145089}],"con":true,"img":false}]}
{"op":"mcm","clk":"11540724312","pt":1719497696691,"mc":[{"id":"1.230180119","rc":[{"atb":[[1.76,2]],"id":62145089}],"con":true,"img":false}]}
{"op":"mcm","clk":"11540724636","pt":1719497700674,"mc":[{"id":"1.230180119","rc":[{"atb":[[1.54,0],[1.53,8]],"id":69475360}],"con":true,"img":false}]}
{"op":"mcm","clk":"11540724742","pt":1719497701606,"mc":[{"id":"1.230180119","rc":[{"atb":[[1.02,16.49]],"id":69475360}],"con":true,"img":false}]}
{"op":"mcm","clk":"11540724754","pt":1719497701654,"mc":[{"id":"1.230180119","rc":[{"atb":[[1.54,2]],"id":69475360}],"con":true,"img":false}]}
{"op":"mcm","clk":"11540724866","pt":1719497702700,"mc":[{"id":"1.230180119","rc":[{"atb":[[1.54,0]],"id":69475360}],"con":true,"img":false}]}
{"op":"mcm","clk":"11540724878","pt":1719497702799,"mc":[{"id":"1.230180119","rc":[{"atb":[[1.02,18.49]],"id":69475360}],"con":true,"img":false}]}
{"op":"mcm","clk":"11540724932","pt":1719497703265,"mc":[{"id":"1.230180119","rc":[{"atb":[[1.99,0],[2.08,2.12]],"id":50772801},{"atb":[[1.54,2]],"id":69475360}],"con":true,"img":false}]}
{"op":"mcm","clk":"11540724962","pt":1719497703369,"mc":[{"id":"1.230180119","rc":[{"atb":[[1.53,0]],"id":69475360}],"con":true,"img":false}]}
{"op":"mcm","clk":"11540724991","pt":1719497703581,"mc":[{"id":"1.230180119","rc":[{"atb":[[1.02,16.49]],"id":69475360}],"con":true,"img":false}]}
{"op":"mcm","clk":"11540725002","pt":1719497703685,"mc":[{"id":"1.230180119","rc":[{"atb":[[1.54,4]],"id":69475360}],"con":true,"img":false}]}
{"op":"mcm","clk":"11540725012","pt":1719497703787,"mc":[{"id":"1.230180119","rc":[{"atb":[[1.59,0]],"id":69624671}],"con":true,"img":false}]}
{"op":"mcm","clk":"11540725045","pt":1719497704105,"mc":[{"id":"1.230180119","rc":[{"atb":[[1.63,6.27]],"id":69624671},{"atb":[[1.41,0]],"id":60276470}],"con":true,"img":false}]}
{"op":"mcm","clk":"11540725065","pt":1719497704260,"mc":[{"id":"1.230180119","rc":[{"atb":[[1.64,6.27],[1.6,0]],"id":69624671},{"atb":[[1.46,9.58]],"id":60276470}],"con":true,"img":false}]}
{"op":"mcm","clk":"11540725086","pt":1719497704467,"mc":[{"id":"1.230180119","rc":[{"atb":[[1.44,2.11],[1.47,4.6]],"id":60276470}],"con":true,"img":false}]}
{"op":"mcm","clk":"11540725127","pt":1719497704874,"mc":[{"id":"1.230180119","rc":[{"atb":[[1.54,2]],"id":69475360}],"con":true,"img":false}]}
{"op":"mcm","clk":"11540725136","pt":1719497704982,"mc":[{"id":"1.230180119","rc":[{"atb":[[1.02,18.49]],"id":69475360}],"con":true,"img":false}]}
{"op":"mcm","clk":"11540725180","pt":1719497705393,"mc":[{"id":"1.230180119","rc":[{"atb":[[2,0]],"id":50772801}],"con":true,"img":false}]}
{"op":"mcm","clk":"11540725192","pt":1719497705491,"mc":[{"id":"1.230180119","rc":[{"atb":[[2.1,3]],"id":50772801}],"con":true,"img":false}]}
{"op":"mcm","clk":"11540725235","pt":1719497705907,"mc":[{"id":"1.230180119","rc":[{"atb":[[1.61,0]],"id":69624671}],"con":true,"img":false}]}
{"op":"mcm","clk":"11540725242","pt":1719497706019,"mc":[{"id":"1.230180119","rc":[{"atb":[[1.65,2]],"id":69624671}],"con":true,"img":false}]}
{"op":"mcm","clk":"11540725281","pt":1719497706275,"mc":[{"id":"1.230180119","rc":[{"atb":[[1.02,0]],"id":60276470}],"con":true,"img":false}]}
{"op":"mcm","clk":"11540725294","pt":1719497706379,"mc":[{"id":"1.230180119","rc":[{"atb":[[1.49,8.63],[1.48,2]],"id":60276470}],"con":true,"img":false}]}
{"op":"mcm","clk":"11540725392","pt":1719497707356,"mc":[{"id":"1.230180119","rc":[{"atb":[[1.48,0]],"id":60276470}],"con":true,"img":false}]}
{"op":"mcm","clk":"11540725401","pt":1719497707460,"mc":[{"id":"1.230180119","rc":[{"atb":[[1.5,2]],"id":60276470}],"con":true,"img":false}]}
{"op":"mcm","clk":"11540725507","pt":1719497708394,"mc":[{"id":"1.230180119","rc":[{"atb":[[1.44,0],[1.52,2.11]],"id":60276470}],"con":true,"img":false}]}
{"op":"mcm","clk":"11540725576","pt":1719497709068,"mc":[{"id":"1.230180119","rc":[{"atb":[[1.5,0]],"id":60276470}],"con":true,"img":false}]}
{"op":"mcm","clk":"11540725586","pt":1719497709175,"mc":[{"id":"1.230180119","rc":[{"atb":[[1.53,2]],"id":60276470}],"con":true,"img":false}]}
{"op":"mcm","clk":"11540726065","pt":1719497713968,"mc":[{"id":"1.230180119","rc":[{"atb":[[1.53,4.12]],"id":60276470}],"con":true,"img":false}]}
{"op":"mcm","clk":"11540726073","pt":1719497714076,"mc":[{"id":"1.230180119","rc":[{"atb":[[1.53,2],[1.47,0],[1.52,6.71]],"id":60276470}],"con":true,"img":false}]}
{"op":"mcm","clk":"11540726194","pt":1719497715266,"mc":[{"id":"1.230180119","rc":[{"atl":[[9.2,0],[9.4,1]],"id":50772801}],"con":true,"img":false}]}
{"op":"mcm","clk":"11540726204","pt":1719497715374,"mc":[{"id":"1.230180119","rc":[{"atl":[[34,0],[42,2.44]],"id":50772801}],"con":true,"img":false}]}
{"op":"mcm","clk":"11540726690","pt":1719497720589,"mc":[{"id":"1.230180119","rc":[{"atb":[[1.77,0]],"id":50772801},{"atb":[[1.65,0]],"id":48534288}],"con":true,"img":false}]}
{"op":"mcm","clk":"11540726864","pt":1719497722768,"mc":[{"id":"1.230180119","rc":[{"atb":[[1.63,0]],"id":69624671}],"con":true,"img":false}]}
{"op":"mcm","clk":"11540726882","pt":1719497722974,"mc":[{"id":"1.230180119","rc":[{"atb":[[1.67,5.89]],"id":69624671}],"con":true,"img":false}]}
{"op":"mcm","clk":"11540726887","pt":1719497723078,"mc":[{"id":"1.230180119","rc":[{"atb":[[1.64,0],[1.68,5.89]],"id":69624671}],"con":true,"img":false}]}
{"op":"mcm","clk":"11540726932","pt":1719497723493,"mc":[{"id":"1.230180119","rc":[{"atb":[[1.65,0]],"id":69624671}],"con":true,"img":false}]}
{"op":"mcm","clk":"11540726945","pt":1719497723598,"mc":[{"id":"1.230180119","rc":[{"atb":[[1.68,7.89]],"id":69624671}],"con":true,"img":false}]}
{"op":"mcm","clk":"11540728438","pt":1719497741805,"mc":[{"id":"1.230180119","rc":[{"atb":[[1.93,4.24]],"id":48534288}],"con":true,"img":false}]}
{"op":"mcm","clk":"11540728449","pt":1719497741894,"mc":[{"id":"1.230180119","rc":[{"atb":[[1.9,0],[1.94,4.25]],"id":48534288}],"con":true,"img":false}]}
{"op":"mcm","clk":"11540728489","pt":1719497742406,"mc":[{"id":"1.230180119","rc":[{"atb":[[1.91,0]],"id":48534288}],"con":true,"img":false}]}
{"op":"mcm","clk":"11540728532","pt":1719497742514,"mc":[{"id":"1.230180119","rc":[{"atb":[[1.95,2]],"id":48534288}],"con":true,"img":false}]}
{"op":"mcm","clk":"11540728944","pt":1719497747118,"mc":[{"id":"1.230180119","rc":[{"atb":[[1.75,0]],"id":50772801},{"spn":5.75,"spf":"NaN","id":50772801},{"spn":3.19,"spf":"NaN","id":69624671},{"spn":2.91,"spf":"NaN","id":60276470},{"atb":[[1.67,0]],"id":48534288},{"spn":4.98,"spf":"NaN","id":48534288},{"spn":2.87,"spf":"NaN","id":69475360}],"con":true,"img":false}]}
{"op":"mcm","clk":"11540730639","pt":1719497765848,"mc":[{"id":"1.230180119","rc":[{"atb":[[1.82,3.75]],"id":48534288}],"con":true,"img":false}]}
{"op":"mcm","clk":"11540730770","pt":1719497767359,"mc":[{"id":"1.230180119","rc":[{"atb":[[1.82,0]],"id":48534288}],"con":true,"img":false}]}
{"op":"mcm","clk":"11540731092","pt":1719497770869,"mc":[{"id":"1.230180119","rc":[{"atb":[[1.01,1.7]],"id":50772801},{"atl":[[1000,1.7]],"id":50772801},{"atb":[[1.01,1.7]],"id":69624671},{"atl":[[1000,1.88]],"id":69624671},{"atb":[[1.01,1.7]],"id":69475360},{"atl":[[1000,1.7]],"id":69475360}],"con":true,"img":false}]}
{"op":"mcm","clk":"11540731110","pt":1719497771081,"mc":[{"id":"1.230180119","rc":[{"atl":[[1000,0]],"id":50772801},{"atl":[[1000,0.21]],"id":69624671}],"con":true,"img":false}]}
{"op":"mcm","clk":"11540731120","pt":1719497771123,"mc":[{"id":"1.230180119","rc":[{"atb":[[1.01,0.27]],"id":50772801},{"atb":[[1.01,0.44]],"id":69624671},{"atb":[[1.01,0.55]],"id":69475360},{"atl":[[1000,0.03]],"id":69475360}],"con":true,"img":false}]}
{"op":"mcm","clk":"11540731133","pt":1719497771236,"mc":[{"id":"1.230180119","rc":[{"atl":[[1000,0]],"id":50772801},{"atl":[[1000,0.17]],"id":69624671}],"con":true,"img":false}]}
{"op":"mcm","clk":"11540731145","pt":1719497771331,"mc":[{"id":"1.230180119","rc":[{"atb":[[1.01,0]],"id":50772801},{"atl":[[40,0]],"id":50772801},{"atb":[[1.01,0]],"id":69624671},{"atl":[[8.8,0.03]],"id":69624671},{"atb":[[1.01,0]],"id":69475360},{"atl":[[1000,0]],"id":69475360}],"con":true,"img":false}]}
{"op":"mcm","clk":"11540731156","pt":1719497771441,"mc":[{"id":"1.230180119","rc":[{"atb":[[2.12,0.27]],"id":50772801},{"atb":[[1.69,0.44]],"id":69624671},{"atb":[[1.55,0.55]],"id":69475360},{"atl":[[9.4,0.03]],"id":69475360}],"con":true,"img":false}]}
{"op":"mcm","clk":"11540732168","pt":1719497783733,"mc":[{"id":"1.230180119","rc":[{"atb":[[1.56,0]],"id":69624671}],"con":true,"img":false}]}
{"op":"mcm","clk":"11540732641","pt":1719497788872,"mc":[{"id":"1.230180119","rc":[{"atb":[[1.46,1]],"id":60276470}],"con":true,"img":false}]}
{"op":"mcm","clk":"11540733920","pt":1719497803163,"mc":[{"id":"1.230180119","rc":[{"atb":[[2.12,0]],"id":50772801},{"atl":[[40,0]],"id":50772801},{"atb":[[1.69,0]],"id":69624671},{"atl":[[8.8,0]],"id":69624671},{"atb":[[1.55,0]],"id":69475360},{"atl":[[9.4,0]],"id":69475360}],"con":true,"img":false}]}
{"op":"mcm","clk":"11540733932","pt":1719497803267,"mc":[{"id":"1.230180119","rc":[{"atl":[[9.8,1]],"id":50772801}],"con":true,"img":false}]}
{"op":"mcm","clk":"11540733948","pt":1719497803373,"mc":[{"id":"1.230180119","rc":[{"atl":[[9.4,0]],"id":50772801}],"con":true,"img":false}]}
{"op":"mcm","clk":"11540734252","pt":1719497806978,"mc":[{"id":"1.230180119","rc":[{"atb":[[1.67,0]],"id":69624671}],"con":true,"img":false}]}
{"op":"mcm","clk":"11540734280","pt":1719497807391,"mc":[{"id":"1.230180119","rc":[{"spn":5.95,"spf":"NaN","id":50772801},{"atb":[[1.68,5.89]],"id":69624671}],"con":true,"img":false}]}
{"op":"mcm","clk":"11540734288","pt":1719497807499,"mc":[{"id":"1.230180119","rc":[{"atb":[[1.02,18.49],[1.48,6.89]],"id":69624671}],"con":true,"img":false}]}
{"op":"mcm","clk":"11540734299","pt":1719497807603,"mc":[{"id":"1.230180119","rc":[{"atb":[[1.68,0]],"id":69624671}],"con":true,"img":false}]}
{"op":"mcm","clk":"11540734384","pt":1719497808579,"mc":[{"id":"1.230180119","rc":[{"atl":[[8,0],[7.8,1]],"id":48534288}],"con":true,"img":false}]}
{"op":"mcm","clk":"11540734400","pt":1719497808687,"mc":[{"id":"1.230180119","rc":[{"atl":[[23,2],[26,0]],"id":48534288}],"con":true,"img":false}]}
{"op":"mcm","clk":"11540734592","pt":1719497811208,"mc":[{"id":"1.230180119","rc":[{"atl":[[6.4,1],[6.2,0]],"id":62145089},{"atl":[[7.2,1],[7.8,0]],"id":48534288}],"con":true,"img":false}]}
{"op":"mcm","clk":"11540734608","pt":1719497811309,"mc":[{"id":"1.230180119","rc":[{"atl":[[18,2],[19.5,0]],"id":62145089}],"con":true,"img":false}]}
{"op":"mcm","clk":"11540734963","pt":1719497815290,"mc":[{"id":"1.230180119","rc":[{"atb":[[1.5,7.89]],"id":69624671}],"con":true,"img":false}]}
{"op":"mcm","clk":"11540735015","pt":1719497815907,"mc":[{"id":"1.230180119","rc":[{"atb":[[1.51,7.89],[1.48,0]],"id":69624671}],"con":true,"img":false}]}
{"op":"mcm","clk":"11540735050","pt":1719497816279,"mc":[{"id":"1.230180119","rc":[{"atb":[[2.1,5.12],[2.08,0]],"id":50772801},{"atb":[[1.75,0],[1.76,4]],"id":62145089},{"atb":[[1.56,2],[1.54,0]],"id":69475360}],"con":true,"img":false}]}
{"op":"mcm","clk":"11540735060","pt":1719497816374,"mc":[{"id":"1.230180119","rc":[{"atb":[[1.02,16.49]],"id":69624671}],"con":true,"img":false}]}
{"op":"mcm","clk":"11540735065","pt":1719497816480,"mc":[{"id":"1.230180119","rc":[{"atb":[[1.51,9.89]],"id":69624671}],"con":true,"img":false}]}
{"op":"mcm","clk":"11540735164","pt":1719497817408,"mc":[{"id":"1.230180119","rc":[{"atb":[[2.1,3.12]],"id":50772801}],"con":true,"img":false}]}
{"op":"mcm","clk":"11540735173","pt":1719497817512,"mc":[{"id":"1.230180119","rc":[{"atb":[[1.02,18.49]],"id":50772801}],"con":true,"img":false}]}
{"op":"mcm","clk":"11540735188","pt":1719497817663,"mc":[{"id":"1.230180119","rc":[{"atb":[[1.76,2]],"id":62145089}],"con":true,"img":false}]}
{"op":"mcm","clk":"11540735193","pt":1719497817766,"mc":[{"id":"1.230180119","rc":[{"atb":[[1.02,2]],"id":62145089}],"con":true,"img":false}]}
{"op":"mcm","clk":"11540735413","pt":1719497820295,"mc":[{"id":"1.230180119","rc":[{"atb":[[2.88,10],[3.1,2.5],[2.96,5],[2.48,2.34]],"id":50772801},{"atl":[[8,2.5],[9.6,12.34],[8.8,5]],"id":50772801},{"atb":[[1.92,2.25],[2.5,2.5],[2.42,5],[2.34,10]],"id":62145089},{"atl":[[6.2,2.25],[6.8,2.5],[7.6,5],[8.4,10]],"id":62145089},{"atb":[[2,5],[1.96,10],[2.08,2.5],[1.52,3.84]],"id":69624671},{"atl":[[5.1,5],[4.6,3.84],[5.5,10],[4.7,3.5]],"id":69624671},{"atb":[[1.92,2.5],[1.84,10],[1.54,3.75],[1.88,5]],"id":60276470},{"atl":[[6.2,10],[5.3,2.5],[5.7,5],[4.2,3.75]],"id":60276470},{"atb":[[2.3,2.5],[2.22,5],[2.04,2.25],[2.14,10]],"id":48534288},{"atl":[[7.4,10],[6.6,5],[7,2.25],[5.9,2.5]],"id":48534288},{"atb":[[1.57,1.5],[1.67,10],[1.75,2.5],[1.71,5]],"id":69475360},{"atl":[[4.5,2.5],[4.1,1.5],[5.3,10],[4.9,5]],"id":69475360}],"con":true,"img":false}]}
{"op":"mcm","clk":"11540735420","pt":1719497820400,"mc":[{"id":"1.230180119","rc":[{"atl":[[9.6,14.34],[42,0]],"id":50772801},{"atl":[[6.8,4.5]],"id":62145089},{"atl":[[9,0]],"id":69624671},{"atb":[[1.77,6.72],[1.52,2.11]],"id":60276470},{"atl":[[5.3,4.5],[9.4,0]],"id":60276470},{"atl":[[4.5,4.5]],"id":69475360}],"con":true,"img":false}]}
{"op":"mcm","clk":"11540735434","pt":1719497820510,"mc":[{"id":"1.230180119","rc":[{"atl":[[18,0]],"id":62145089},{"atl":[[5.1,7]],"id":69624671},{"atb":[[1.94,0],[2.14,12]],"id":48534288},{"atl":[[23,0],[7,4.25]],"id":48534288},{"atl":[[9.6,0]],"id":69475360}],"con":true,"img":false}]}
{"op":"mcm","clk":"11540735445","pt":1719497820606,"mc":[{"id":"1.230180119","rc":[{"atl":[[7.8,0.84]],"id":50772801},{"atl":[[6,0.84]],"id":62145089},{"atl":[[4.5,0.84]],"id":69624671},{"atl":[[4.1,0.84]],"id":60276470},{"atl":[[5.8,0.84]],"id":48534288}],"con":true,"img":false}]}
{"op":"mcm","clk":"11540735470","pt":1719497820820,"mc":[{"id":"1.230180119","rc":[{"atb":[[1.02,16.49]],"id":69475360}],"con":true,"img":false}]}
{"op":"mcm","clk":"11540735477","pt":1719497820915,"mc":[{"id":"1.230180119","rc":[{"atb":[[1.76,2]],"id":69475360}],"con":true,"img":false}]}
{"op":"mcm","clk":"11540735509","pt":1719497821173,"mc":[{"id":"1.230180119","rc":[{"atb":[[1.02,16.49]],"id":50772801}],"con":true,"img":false}]}
{"op":"mcm","clk":"11540735522","pt":1719497821277,"mc":[{"id":"1.230180119","rc":[{"atb":[[3.15,2]],"id":50772801}],"con":true,"img":false}]}
{"op":"mcm","clk":"11540735594","pt":1719497822106,"mc":[{"id":"1.230180119","rc":[{"atb":[[1.7,2.11]],"id":69475360}],"con":true,"img":false}]}
{"op":"mcm","clk":"11540735646","pt":1719497822577,"mc":[{"id":"1.230180119","rc":[{"atb":[[1.51,7.89]],"id":69624671}],"con":true,"img":false}]}
{"op":"mcm","clk":"11540735656","pt":1719497822676,"mc":[{"id":"1.230180119","rc":[{"atb":[[2.1,2]],"id":69624671}],"con":true,"img":false}]}
{"op":"mcm","clk":"11540735678","pt":1719497822986,"mc":[{"id":"1.230180119","rc":[{"atb":[[1.02,0]],"id":62145089}],"con":true,"img":false}]}
{"op":"mcm","clk":"11540735690","pt":1719497823089,"mc":[{"id":"1.230180119","rc":[{"atb":[[2.52,2]],"id":62145089}],"con":true,"img":false}]}
{"op":"mcm","clk":"11540735730","pt":1719497823608,"mc":[{"id":"1.230180119","rc":[{"atb":[[1.49,0]],"id":60276470}],"con":true,"img":false}]}
{"op":"mcm","clk":"11540735741","pt":1719497823707,"mc":[{"id":"1.230180119","rc":[{"atb":[[1.53,0]],"id":60276470}],"con":true,"img":false}]}
{"op":"mcm","clk":"11540735750","pt":1719497823816,"mc":[{"id":"1.230180119","rc":[{"atb":[[1.93,2]],"id":60276470}],"con":true,"img":false}]}
{"op":"mcm","clk":"11540735781","pt":1719497824080,"mc":[{"id":"1.230180119","rc":[{"atb":[[1.95,0]],"id":48534288}],"con":true,"img":false}]}
{"op":"mcm","clk":"11540735792","pt":1719497824183,"mc":[{"id":"1.230180119","rc":[{"atb":[[1.02,18.49]],"id":48534288}],"con":true,"img":false}]}
{"op":"mcm","clk":"11540735798","pt":1719497824278,"mc":[{"id":"1.230180119","rc":[{"atb":[[1.91,7.89],[1.51,1]],"id":69624671}],"con":true,"img":false}]}
{"op":"mcm","clk":"11540735807","pt":1719497824381,"mc":[{"id":"1.230180119","rc":[{"atb":[[1.93,0]],"id":48534288}],"con":true,"img":false}]}
{"op":"mcm","clk":"11540735840","pt":1719497824692,"mc":[{"id":"1.230180119","rc":[{"atb":[[2.9,5],[2.1,1]],"id":50772801},{"atb":[[2.32,7.5],[1.76,0]],"id":62145089},{"atb":[[1.56,0],[1.76,4.5]],"id":69475360}],"con":true,"img":false}]}
{"op":"mcm","clk":"11540735987","pt":1719497826100,"mc":[{"id":"1.230180119","rc":[{"atb":[[1.74,2.11],[1.7,0]],"id":69475360}],"con":true,"img":false}]}
{"op":"mcm","clk":"11540736225","pt":1719497828733,"mc":[{"id":"1.230180119","rc":[{"atl":[[6.4,5.5],[6.8,2.5]],"id":62145089},{"atl":[[4.3,5.6],[5.3,2.5]],"id":60276470}],"con":true,"img":false}]}
{"op":"mcm","clk":"11540736239","pt":1719497828832,"mc":[{"id":"1.230180119","rc":[{"atl":[[5.1,5],[4.7,10.5]],"id":69624671},{"atl":[[6.6,9.25],[7,2.25]],"id":48534288}],"con":true,"img":false}]}
{"op":"mcm","clk":"11540737119","pt":1719497837837,"mc":[{"id":"1.230180119","rc":[{"atl":[[7.8,4.59]],"id":50772801},{"atb":[[2.52,5.56]],"id":62145089},{"atl":[[6,4.4]],"id":62145089},{"atb":[[2.1,6.76]],"id":69624671},{"atl":[[4.5,5.6]],"id":69624671},{"atb":[[1.93,6.69]],"id":60276470},{"atb":[[2.34,5.62]],"id":48534288},{"atl":[[5.8,6.46]],"id":48534288},{"atb":[[1.76,7.96]],"id":69475360}],"con":true,"img":false}]}
{"op":"mcm","clk":"11540737131","pt":1719497837934,"mc":[{"id":"1.230180119","rc":[{"atb":[[3.15,5.75]],"id":50772801},{"atl":[[9.6,12]],"id":50772801},{"atb":[[1.92,0]],"id":62145089},{"atl":[[6.2,0]],"id":62145089},{"atb":[[1.52,0]],"id":69624671},{"atl":[[4.6,0]],"id":69624671},{"atb":[[1.54,0]],"id":60276470},{"atl":[[4.1,5.53]],"id":60276470},{"atb":[[2.22,10],[2.04,0],[2.14,10]],"id":48534288},{"atl":[[5.9,15.44]],"id":48534288},{"atb":[[1.57,0],[1.75,11.5],[1.76,5.46]],"id":69475360}],"con":true,"img":false}]}
{"op":"mcm","clk":"11540737136","pt":1719497838032,"mc":[{"id":"1.230180119","rc":[{"atl":[[6.6,5],[7,0]],"id":48534288}],"con":true,"img":false}]}
{"op":"mcm","clk":"11540737150","pt":1719497838140,"mc":[{"id":"1.230180119","rc":[{"atb":[[2.48,0]],"id":50772801},{"atl":[[6.4,1],[6.8,12.41]],"id":62145089},{"atl":[[5.1,21.11],[4.7,3.5]],"id":69624671},{"atl":[[4.2,0]],"id":60276470},{"atl":[[6.6,22.86],[5.9,2.5]],"id":48534288}],"con":true,"img":false}]}
{"op":"mcm","clk":"11540737165","pt":1719497838294,"mc":[{"id":"1.230180119","rc":[{"atb":[[1.66,0],[2.48,2.11]],"id":62145089},{"atl":[[4.3,1],[5.3,13.64]],"id":60276470}],"con":true,"img":false}]}
{"op":"mcm","clk":"11540741286","pt":1719497886294,"mc":[{"id":"1.230180119","rc":[{"spn":5.47,"spf":"NaN","id":50772801},{"atl":[[7.4,5],[6.8,9.91],[7.6,0],[6.6,2.5],[8.4,0]],"id":62145089},{"spn":4.26,"spf":"NaN","id":62145089},{"spn":3.3,"spf":"NaN","id":69624671},{"atl":[[5.6,5],[6.2,0],[5.3,11.14],[5.2,2.5],[5.7,0]],"id":60276470},{"spn":3.01,"spf":"NaN","id":60276470},{"atb":[[2.3,0],[2.22,5],[2.18,10],[2.26,5],[2.14,0],[2.34,8.12]],"id":48534288},{"spn":4.07,"spf":"NaN","id":48534288},{"atb":[[1.8,2.5],[1.72,10],[1.67,0],[1.75,9],[1.71,0],[1.76,10.46]],"id":69475360},{"spn":2.95,"spf":"NaN","id":69475360}],"con":true,"img":false}]}
{"op":"mcm","clk":"11540741294","pt":1719497886349,"mc":[{"id":"1.230180119","rc":[{"atl":[[6.4,9.82],[6.8,0]],"id":62145089},{"atl":[[5.1,6.54]],"id":60276470},{"atb":[[2.38,9.07],[2.34,13.12]],"id":48534288},{"atb":[[1.8,11.5],[1.77,4.96]],"id":69475360}],"con":true,"img":false}]}
{"op":"mcm","clk":"11540741308","pt":1719497886451,"mc":[{"id":"1.230180119","rc":[{"atl":[[5.3,0]],"id":60276470},{"atb":[[2.22,0]],"id":48534288},{"atb":[[1.75,0]],"id":69475360}],"con":true,"img":false}]}
{"op":"mcm","clk":"11540741318","pt":1719497886554,"mc":[{"id":"1.230180119","rc":[{"atb":[[2.34,7.5]],"id":48534288},{"atb":[[1.76,7]],"id":69475360}],"con":true,"img":false}]}
{"op":"mcm","clk":"11540741391","pt":1719497887279,"mc":[{"id":"1.230180119","rc":[{"atb":[[1.74,0]],"id":69475360}],"con":true,"img":false}]}
{"op":"mcm","clk":"11540741401","pt":1719497887384,"mc":[{"id":"1.230180119","rc":[{"atb":[[1.83,2.11]],"id":69475360}],"con":true,"img":false}]}
{"op":"mcm","clk":"11540741475","pt":1719497888271,"mc":[{"id":"1.230180119","rc":[{"atb":[[1.76,5]],"id":69475360}],"con":true,"img":false}]}
{"op":"mcm","clk":"11540741482","pt":1719497888369,"mc":[{"id":"1.230180119","rc":[{"atb":[[1.84,2]],"id":69475360}],"con":true,"img":false}]}
{"op":"mcm","clk":"11540741543","pt":1719497889092,"mc":[{"id":"1.230180119","rc":[{"atb":[[1.02,18.19]],"id":50772801},{"atl":[[1000,1.7]],"id":50772801},{"atb":[[1.01,1.7]],"id":69624671},{"atl":[[1000,1.88]],"id":69624671},{"atb":[[1.01,1.7]],"id":69475360},{"atl":[[1000,1.7]],"id":69475360}],"con":true,"img":false}]}
{"op":"mcm","clk":"11540741567","pt":1719497889350,"mc":[{"id":"1.230180119","rc":[{"atb":[[1.02,16.62]],"id":50772801},{"atl":[[1000,0.04]],"id":50772801},{"atb":[[1.01,0.26]],"id":69624671},{"atl":[[1000,0.26]],"id":69624671},{"atb":[[1.01,0.34]],"id":69475360},{"atl":[[1000,0.09]],"id":69475360}],"con":true,"img":false}]}
{"op":"mcm","clk":"11540741585","pt":1719497889556,"mc":[{"id":"1.230180119","rc":[{"atb":[[1.02,16.49]],"id":50772801},{"atl":[[1000,0]],"id":50772801},{"atb":[[1.01,0]],"id":69624671},{"atl":[[1000,0.17]],"id":69624671},{"atb":[[1.01,0]],"id":69475360},{"atl":[[1000,0]],"id":69475360}],"con":true,"img":false}]}
{"op":"mcm","clk":"11540741599","pt":1719497889661,"mc":[{"id":"1.230180119","rc":[{"atb":[[3.2,0.13]],"id":50772801},{"atl":[[7.6,0.04]],"id":50772801},{"atb":[[2.12,0.26]],"id":69624671},{"atl":[[4.4,0.08]],"id":69624671},{"atb":[[1.85,0.34]],"id":69475360},{"atl":[[4.1,1.59]],"id":69475360}],"con":true,"img":false}]}
{"op":"mcm","clk":"11540741609","pt":1719497889762,"mc":[{"id":"1.230180119","rc":[{"atl":[[7.6,3.79]],"id":50772801},{"atl":[[4.7,13.5]],"id":69624671}],"con":true,"img":false}]}
{"op":"mcm","clk":"11540741619","pt":1719497889868,"mc":[{"id":"1.230180119","rc":[{"atl":[[5.1,5],[4.4,4.58]],"id":69624671}],"con":true,"img":false}]}
{"op":"mcm","clk":"11540741628","pt":1719497889968,"mc":[{"id":"1.230180119","rc":[{"atl":[[7.8,0.84]],"id":50772801}],"con":true,"img":false}]}
{"op":"mcm","clk":"11540741636","pt":1719497890071,"mc":[{"id":"1.230180119","rc":[{"atl":[[7.4,0.84]],"id":50772801},{"atl":[[4.5,0.84]],"id":69624671}],"con":true,"img":false}]}
{"op":"mcm","clk":"11540741695","pt":1719497890591,"mc":[{"id":"1.230180119","rc":[{"atl":[[4.3,0.84]],"id":69624671}],"con":true,"img":false}]}
{"op":"mcm","clk":"11540741707","pt":1719497890695,"mc":[{"id":"1.230180119","rc":[{"atl":[[4.5,6.28],[4.7,3.5]],"id":69624671}],"con":true,"img":false}]}
{"op":"mcm","clk":"11540741811","pt":1719497891487,"mc":[{"id":"1.230180119","rc":[{"atl":[[6.6,16.73]],"id":62145089},{"atb":[[2.26,21.57],[2.34,2.5]],"id":48534288}],"con":true,"img":false}]}
{"op":"mcm","clk":"11540741830","pt":1719497891594,"mc":[{"id":"1.230180119","rc":[{"atl":[[6.4,1]],"id":62145089}],"con":true,"img":false}]}
{"op":"mcm","clk":"11540742054","pt":1719497894086,"mc":[{"id":"1.230180119","rc":[{"atb":[[1.8,2.5],[1.84,4.12]],"id":69475360}],"con":true,"img":false}]}
{"op":"mcm","clk":"11540742518","pt":1719497898580,"mc":[{"id":"1.230180119","rc":[{"atb":[[1.5,0]],"id":69624671}],"con":true,"img":false}]}
{"op":"mcm","clk":"11540742599","pt":1719497899297,"mc":[{"id":"1.230180119","rc":[{"atb":[[2.4,2.11],[1.7,0]],"id":48534288}],"con":true,"img":false}]}
{"op":"mcm","clk":"11540742607","pt":1719497899399,"mc":[{"id":"1.230180119","rc":[{"atb":[[2.36,11.19],[2.26,5]],"id":48534288}],"con":true,"img":false}]}
{"op":"mcm","clk":"11540742916","pt":1719497902616,"mc":[{"id":"1.230180119","rc":[{"atb":[[2.4,13.77]],"id":48534288},{"atb":[[1.84,6.91]],"id":69475360}],"con":true,"img":false}]}
{"op":"mcm","clk":"11540742939","pt":1719497902777,"mc":[{"id":"1.230180119","rc":[{"atb":[[2.38,0]],"id":48534288},{"atb":[[1.77,0]],"id":69475360}],"con":true,"img":false}]}
{"op":"mcm","clk":"11540743242","pt":1719497905882,"mc":[{"id":"1.230180119","rc":[{"atl":[[7.4,3.35]],"id":50772801}],"con":true,"img":false}]}
{"op":"mcm","clk":"11540743254","pt":1719497905982,"mc":[{"id":"1.230180119","rc":[{"atl":[[4.3,6.16]],"id":69624671}],"con":true,"img":false}]}
{"op":"mcm","clk":"11540743265","pt":1719497906081,"mc":[{"id":"1.230180119","rc":[{"atl":[[7.6,0.04]],"id":50772801}],"con":true,"img":false}]}
{"op":"mcm","clk":"11540743275","pt":1719497906186,"mc":[{"id":"1.230180119","rc":[{"atl":[[4.4,0.08]],"id":69624671}],"con":true,"img":false}]}
{"op":"mcm","clk":"11540743319","pt":1719497906599,"mc":[{"id":"1.230180119","rc":[{"atl":[[7.8,0]],"id":50772801},{"atl":[[4.5,5.44]],"id":69624671}],"con":true,"img":false}]}
{"op":"mcm","clk":"11540744227","pt":1719497916923,"mc":[{"id":"1.230180119","rc":[{"atb":[[2.4,0]],"id":48534288},{"trd":[[2.4,27.54]],"ltp":2.4,"tv":27.54,"id":48534288}],"con":true,"img":false}]}
{"op":"mcm","clk":"11540744237","pt":1719497917021,"mc":[{"id":"1.230180119","rc":[{"atl":[[5.7,8.83]],"id":48534288}],"con":true,"img":false}]}
{"op":"mcm","clk":"11540744244","pt":1719497917125,"mc":[{"id":"1.230180119","rc":[{"atb":[[2.36,0],[2.26,18.69]],"id":48534288},{"atl":[[5.6,8.6],[6.6,5],[5.9,17.8]],"id":48534288}],"con":true,"img":false}]}
{"op":"mcm","clk":"11540744261","pt":1719497917280,"mc":[{"id":"1.230180119","rc":[{"atl":[[5.8,0.84]],"id":48534288}],"con":true,"img":false}]}
{"op":"mcm","clk":"11540744285","pt":1719497917596,"mc":[{"id":"1.230180119","rc":[{"atl":[[5.8,0],[5.5,0.84]],"id":48534288}],"con":true,"img":false}]}
{"op":"mcm","clk":"11540744363","pt":1719497918526,"mc":[{"id":"1.230180119","rc":[{"atb":[[2.38,13.07]],"id":48534288}],"con":true,"img":false}]}
{"op":"mcm","clk":"11540744413","pt":1719497918986,"mc":[{"id":"1.230180119","rc":[{"atb":[[3.2,2.08]],"id":50772801},{"atb":[[2.54,1.94]],"id":62145089},{"atb":[[2.12,2.21]],"id":69624671},{"atb":[[2.4,1.94]],"id":48534288}],"con":true,"img":false}]}
{"op":"mcm","clk":"11540744420","pt":1719497919089,"mc":[{"id":"1.230180119","rc":[{"atb":[[3.2,5.83]],"id":50772801},{"atb":[[2.54,7.12]],"id":62145089},{"atb":[[2.12,8.17]],"id":69624671}],"con":true,"img":false}]}
{"op":"mcm","clk":"11540744433","pt":1719497919297,"mc":[{"id":"1.230180119","rc":[{"atb":[[3.15,2]],"id":50772801},{"atb":[[2.52,2]],"id":62145089},{"atb":[[2.1,2]],"id":69624671}],"con":true,"img":false}]}
{"op":"mcm","clk":"11540744468","pt":1719497919707,"mc":[{"id":"1.230180119","rc":[{"atl":[[5.4,0.92]],"id":48534288}],"con":true,"img":false}]}
{"op":"mcm","clk":"11540744519","pt":1719497920321,"mc":[{"id":"1.230180119","rc":[{"atb":[[3.15,0]],"id":50772801}],"con":true,"img":false}]}
{"op":"mcm","clk":"11540744530","pt":1719497920427,"mc":[{"id":"1.230180119","rc":[{"atb":[[3.25,2]],"id":50772801}],"con":true,"img":false}]}
{"op":"mcm","clk":"11540744558","pt":1719497920686,"mc":[{"id":"1.230180119","rc":[{"atb":[[2.1,0]],"id":69624671}],"con":true,"img":false}]}
{"op":"mcm","clk":"11540744569","pt":1719497920789,"mc":[{"id":"1.230180119","rc":[{"atb":[[2.14,2]],"id":69624671}],"con":true,"img":false}]}
{"op":"mcm","clk":"11540744624","pt":1719497921407,"mc":[{"id":"1.230180119","rc":[{"atb":[[2.52,0]],"id":62145089}],"con":true,"img":false}]}
{"op":"mcm","clk":"11540744636","pt":1719497921508,"mc":[{"id":"1.230180119","rc":[{"atb":[[2.56,2]],"id":62145089}],"con":true,"img":false}]}
{"op":"mcm","clk":"11540744669","pt":1719497921926,"mc":[{"id":"1.230180119","rc":[{"atb":[[2.4,0]],"id":48534288}],"con":true,"img":false}]}
{"op":"mcm","clk":"11540744680","pt":1719497922029,"mc":[{"id":"1.230180119","rc":[{"atl":[[5.4,6.1]],"id":48534288}],"con":true,"img":false}]}
{"op":"mcm","clk":"11540744689","pt":1719497922125,"mc":[{"id":"1.230180119","rc":[{"atb":[[2.4,1.94]],"id":48534288}],"con":true,"img":false}]}
{"op":"mcm","clk":"11540744889","pt":1719497924501,"mc":[{"id":"1.230180119","rc":[{"atb":[[2.4,0],[2.36,15.02],[2.26,5]],"id":48534288}],"con":true,"img":false}]}
{"op":"mcm","clk":"11540744898","pt":1719497924605,"mc":[{"id":"1.230180119","rc":[{"atl":[[5.3,0.84]],"id":48534288}],"con":true,"img":false}]}
{"op":"mcm","clk":"11540744905","pt":1719497924709,"mc":[{"id":"1.230180119","rc":[{"atb":[[2.36,0],[2.4,1.94],[2.34,30.59]],"id":48534288}],"con":true,"img":false}]}
{"op":"mcm","clk":"11540744925","pt":1719497924923,"mc":[{"id":"1.230180119","rc":[{"atb":[[2.88,0],[3.1,0],[2.96,0]],"id":50772801},{"atl":[[8,0],[9.6,2],[8.2,5],[8.8,0]],"id":50772801},{"atb":[[2.54,1.94],[2.5,0],[2.42,0],[2.34,0]],"id":62145089},{"atl":[[7.4,0],[6,0.84],[6.6,14.23]],"id":62145089},{"atb":[[2,0],[2.12,2.21],[1.96,0],[2.08,0]],"id":69624671},{"atl":[[4.3,0.84],[5.1,0],[5.5,0],[4.7,1]],"id":69624671},{"atb":[[1.92,0],[1.84,0],[1.88,0],[1.93,1.99]],"id":60276470},{"atl":[[5.6,0],[4.1,0.84],[5.2,0]],"id":60276470},{"atb":[[2.36,15.02],[2.18,0],[2.26,0],[2.34,0]],"id":48534288},{"atl":[[5.5,9.44],[7.4,0],[6.6,0],[5.9,0]],"id":48534288},{"atb":[[1.84,4.12]],"id":69475360},{"atl":[[4.1,0.09]],"id":69475360}],"con":true,"img":false}]}
{"op":"mcm","clk":"11540744934","pt":1719497925023,"mc":[{"id":"1.230180119","rc":[{"atb":[[3.2,2.08]],"id":50772801},{"atl":[[9.6,0],[7.4,0.84]],"id":50772801},{"atb":[[2.38,0]],"id":48534288},{"atl":[[5.6,0],[5.7,0]],"id":48534288},{"atb":[[1.8,0],[1.72,0],[1.76,0]],"id":69475360},{"atl":[[4.5,2],[5.3,0],[4.9,0]],"id":69475360}],"con":true,"img":false}]}
{"op":"mcm","clk":"11540744966","pt":1719497925430,"mc":[{"id":"1.230180119","rc":[{"atb":[[3.2,1.94]],"id":50772801},{"atl":[[7.6,0]],"id":50772801},{"atb":[[2.12,1.94]],"id":69624671},{"atl":[[4.4,0]],"id":69624671},{"atb":[[1.85,0]],"id":69475360},{"atl":[[4.1,0]],"id":69475360}],"con":true,"img":false}]}
{"op":"mcm","clk":"11540744973","pt":1719497925533,"mc":[{"id":"1.230180119","rc":[{"atb":[[1.84,2.12]],"id":69475360}],"con":true,"img":false}]}
{"op":"mcm","clk":"11540744979","pt":1719497925636,"mc":[{"id":"1.230180119","rc":[{"atl":[[8.2,0],[7.4,0],[9.8,6.85]],"id":50772801},{"atl":[[6.2,0.84],[6,0]],"id":62145089},{"atl":[[4.3,0],[4.5,0],[4.7,7.29]],"id":69624671},{"atl":[[4.1,0],[4.2,0.84]],"id":60276470},{"atb":[[1.02,18.49]],"id":69475360},{"atl":[[4.5,0],[8.4,3]],"id":69475360}],"con":true,"img":false}]}
{"op":"mcm","clk":"11540744991","pt":1719497925689,"mc":[{"id":"1.230180119","rc":[{"atb":[[1.83,6.35]],"id":69475360}],"con":true,"img":false}]}
{"op":"mcm","clk":"11540745000","pt":1719497925797,"mc":[{"id":"1.230180119","rc":[{"atl":[[7.6,14.58],[4.7,1]],"id":69624671},{"atb":[[1.84,0]],"id":69475360}],"con":true,"img":false}]}
{"op":"mcm","clk":"11540745010","pt":1719497925901,"mc":[{"id":"1.230180119","rc":[{"atb":[[2.56,0]],"id":62145089}],"con":true,"img":false}]}
{"op":"mcm","clk":"11540745020","pt":1719497925997,"mc":[{"id":"1.230180119","rc":[{"atb":[[2.5,2]],"id":62145089}],"con":true,"img":false}]}
{"op":"mcm","clk":"11540745026","pt":1719497926101,"mc":[{"id":"1.230180119","rc":[{"atl":[[9.6,0.84]],"id":50772801}],"con":true,"img":false}]}
{"op":"mcm","clk":"11540745084","pt":1719497926822,"mc":[{"id":"1.230180119","rc":[{"atb":[[3.2,0]],"id":50772801},{"atb":[[2.54,0]],"id":62145089},{"atb":[[2.12,0]],"id":69624671},{"atb":[[2.4,0]],"id":48534288}],"con":true,"img":false}]}
{"op":"mcm","clk":"11540745093","pt":1719497926937,"mc":[{"id":"1.230180119","rc":[{"atb":[[2.92,1.94]],"id":50772801},{"atb":[[2.5,3.94]],"id":62145089},{"atb":[[1.93,0]],"id":60276470},{"atb":[[2.36,0],[2.38,1.94],[1.78,16.02]],"id":48534288}],"con":true,"img":false}]}
{"op":"mcm","clk":"11540745104","pt":1719497927028,"mc":[{"id":"1.230180119","rc":[{"atb":[[1.78,2]],"id":60276470}],"con":true,"img":false}]}
{"op":"mcm","clk":"11540745113","pt":1719497927133,"mc":[{"id":"1.230180119","rc":[{"atb":[[1.77,0],[1.52,15.55]],"id":60276470},{"atb":[[2.36,3.9],[1.78,0]],"id":48534288}],"con":true,"img":false}]}
{"op":"mcm","clk":"11540745123","pt":1719497927231,"mc":[{"id":"1.230180119","rc":[{"atb":[[1.77,4],[1.52,2.11]],"id":60276470}],"con":true,"img":false}]}
{"op":"mcm","clk":"11540745198","pt":1719497928111,"mc":[{"id":"1.230180119","rc":[{"atb":[[1.02,16.49]],"id":69475360}],"con":true,"img":false}]}
{"op":"mcm","clk":"11540745207","pt":1719497928219,"mc":[{"id":"1.230180119","rc":[{"atb":[[1.84,2]],"id":69475360}],"con":true,"img":false}]}
{"op":"mcm","clk":"11540745244","pt":1719497928626,"mc":[{"id":"1.230180119","rc":[{"atb":[[3.25,0]],"id":50772801}],"con":true,"img":false}]}
{"op":"mcm","clk":"11540745256","pt":1719497928735,"mc":[{"id":"1.230180119","rc":[{"atb":[[2.92,3.94]],"id":50772801}],"con":true,"img":false}]}
{"op":"mcm","clk":"11540745284","pt":1719497929040,"mc":[{"id":"1.230180119","rc":[{"atb":[[2.92,2]],"id":50772801},{"atb":[[2.14,0]],"id":69624671},{"atb":[[2.38,0]],"id":48534288}],"con":true,"img":false}]}
{"op":"mcm","clk":"11540745295","pt":1719497929145,"mc":[{"id":"1.230180119","rc":[{"atb":[[2.92,3.94]],"id":50772801},{"atb":[[1.92,2]],"id":69624671},{"atb":[[2.38,1.94]],"id":48534288}],"con":true,"img":false}]}
{"op":"mcm","clk":"11540745306","pt":1719497929247,"mc":[{"id":"1.230180119","rc":[{"atb":[[1.91,0],[1.51,16.78]],"id":69624671},{"atb":[[1.78,4.9]],"id":48534288}],"con":true,"img":false}]}
{"op":"mcm","clk":"11540745314","pt":1719497929302,"mc":[{"id":"1.230180119","rc":[{"atb":[[1.91,4],[1.51,1]],"id":69624671},{"atb":[[2.36,0]],"id":48534288}],"con":true,"img":false}]}
{"op":"mcm","clk":"11540745319","pt":1719497929398,"mc":[{"id":"1.230180119","rc":[{"atb":[[2.36,3.9],[1.78,0]],"id":48534288}],"con":true,"img":false}]}
{"op":"mcm","clk":"11540745420","pt":1719497930540,"mc":[{"id":"1.230180119","rc":[{"atb":[[1.84,0]],"id":69475360}],"con":true,"img":false}]}
{"op":"mcm","clk":"11540745436","pt":1719497930744,"mc":[{"id":"1.230180119","rc":[{"atl":[[32,3.23],[9.8,1]],"id":50772801},{"atb":[[1.02,18.49]],"id":69475360}],"con":true,"img":false}]}
{"op":"mcm","clk":"11540745467","pt":1719497931110,"mc":[{"id":"1.230180119","rc":[{"atb":[[2.92,1.94]],"id":50772801}],"con":true,"img":false}]}
{"op":"mcm","clk":"11540745477","pt":1719497931212,"mc":[{"id":"1.230180119","rc":[{"atb":[[1.02,18.49]],"id":50772801}],"con":true,"img":false}]}
{"op":"mcm","clk":"11540745486","pt":1719497931315,"mc":[{"id":"1.230180119","rc":[{"atb":[[2.38,0]],"id":48534288}],"con":true,"img":false}]}
{"op":"mcm","clk":"11540745499","pt":1719497931418,"mc":[{"id":"1.230180119","rc":[{"atb":[[2.36,0],[1.78,4.9]],"id":48534288}],"con":true,"img":false}]}
{"op":"mcm","clk":"11540745508","pt":1719497931523,"mc":[{"id":"1.230180119","rc":[{"atb":[[1.92,0]],"id":69624671},{"atb":[[2.38,1.94]],"id":48534288}],"con":true,"img":false}]}
{"op":"mcm","clk":"11540745518","pt":1719497931625,"mc":[{"id":"1.230180119","rc":[{"atb":[[1.02,18.49],[1.91,0],[1.51,9]],"id":69624671}],"con":true,"img":false}]}
{"op":"mcm","clk":"11540745636","pt":1719497932819,"mc":[{"id":"1.230180119","rc":[{"atb":[[1.02,16.49]],"id":69475360}],"con":true,"img":false}]}
{"op":"mcm","clk":"11540745647","pt":1719497932921,"mc":[{"id":"1.230180119","rc":[{"atb":[[1.84,2]],"id":69475360}],"con":true,"img":false}]}
{"op":"mcm","clk":"11540745659","pt":1719497933021,"mc":[{"id":"1.230180119","rc":[{"atb":[[1.53,7.44]],"id":69624671}],"con":true,"img":false}]}
{"op":"mcm","clk":"11540745669","pt":1719497933122,"mc":[{"id":"1.230180119","rc":[{"atb":[[1.54,7.45],[1.51,1]],"id":69624671}],"con":true,"img":false}]}
{"op":"mcm","clk":"11540745721","pt":1719497933738,"mc":[{"id":"1.230180119","rc":[{"atb":[[2.92,0]],"id":50772801},{"atb":[[2.38,0]],"id":48534288}],"con":true,"img":false}]}
{"op":"mcm","clk":"11540745731","pt":1719497933841,"mc":[{"id":"1.230180119","rc":[{"atb":[[2.9,0],[2.1,11]],"id":50772801}],"con":true,"img":false}]}
{"op":"mcm","clk":"11540745740","pt":1719497933948,"mc":[{"id":"1.230180119","rc":[{"atb":[[2.92,1.94]],"id":50772801}],"con":true,"img":false}]}
{"op":"mcm","clk":"11540745791","pt":1719497934411,"mc":[{"id":"1.230180119","rc":[{"atb":[[1.84,0]],"id":69475360}],"con":true,"img":false}]}
{"op":"mcm","clk":"11540745805","pt":1719497934512,"mc":[{"id":"1.230180119","rc":[{"atb":[[1.02,18.49]],"id":69475360}],"con":true,"img":false}]}
{"op":"mcm","clk":"11540745839","pt":1719497934926,"mc":[{"id":"1.230180119","rc":[{"atb":[[1.02,16.49]],"id":69624671}],"con":true,"img":false}]}
{"op":"mcm","clk":"11540745851","pt":1719497935029,"mc":[{"id":"1.230180119","rc":[{"atb":[[1.55,2]],"id":69624671}],"con":true,"img":false}]}
{"op":"mcm","clk":"11540745880","pt":1719497935338,"mc":[{"id":"1.230180119","rc":[{"atb":[[1.02,16.49]],"id":48534288}],"con":true,"img":false}]}
{"op":"mcm","clk":"11540745894","pt":1719497935437,"mc":[{"id":"1.230180119","rc":[{"atb":[[1.79,2]],"id":48534288}],"con":true,"img":false}]}
{"op":"mcm","clk":"11540745944","pt":1719497935909,"mc":[{"id":"1.230180119","rc":[{"atb":[[2.92,0]],"id":50772801}],"con":true,"img":false}]}
{"op":"mcm","clk":"11540745955","pt":1719497936010,"mc":[{"id":"1.230180119","rc":[{"atb":[[2.12,1.94]],"id":50772801}],"con":true,"img":false}]}
{"op":"mcm","clk":"11540745977","pt":1719497936317,"mc":[{"id":"1.230180119","rc":[{"atb":[[2.32,0],[2.22,7.9]],"id":62145089},{"atl":[[9.6,11.63],[7.6,0]],"id":69624671},{"atb":[[1.72,6],[1.77,0]],"id":60276470},{"atl":[[6.4,12.2],[5.5,0.84]],"id":48534288},{"atl":[[10.5,4],[8.4,0]],"id":69475360}],"con":true,"img":false}]}
{"op":"mcm","clk":"11540746017","pt":1719497936830,"mc":[{"id":"1.230180119","rc":[{"atb":[[1.02,16.49]],"id":69475360}],"con":true,"img":false}]}
{"op":"mcm","clk":"11540746026","pt":1719497936932,"mc":[{"id":"1.230180119","rc":[{"atb":[[1.84,2]],"id":69475360}],"con":true,"img":false}]}
{"op":"mcm","clk":"11540746048","pt":1719497937247,"mc":[{"id":"1.230180119","rc":[{"atb":[[1.79,0]],"id":48534288}],"con":true,"img":false}]}
{"op":"mcm","clk":"11540746055","pt":1719497937348,"mc":[{"id":"1.230180119","rc":[{"atb":[[1.02,18.49]],"id":48534288}],"con":true,"img":false}]}
{"op":"mcm","clk":"11540746105","pt":1719497938123,"mc":[{"id":"1.230180119","rc":[{"atb":[[2.12,0]],"id":50772801}],"con":true,"img":false}]}
{"op":"mcm","clk":"11540746112","pt":1719497938225,"mc":[{"id":"1.230180119","rc":[{"atb":[[1.84,0]],"id":69475360}],"con":true,"img":false}]}
{"op":"mcm","clk":"11540746124","pt":1719497938326,"mc":[{"id":"1.230180119","rc":[{"atb":[[2.12,1.94]],"id":50772801},{"atb":[[1.02,18.49]],"id":69475360}],"con":true,"img":false}]}
{"op":"mcm","clk":"11540746184","pt":1719497939045,"mc":[{"id":"1.230180119","rc":[{"atb":[[1.78,0]],"id":60276470}],"con":true,"img":false}]}
{"op":"mcm","clk":"11540746196","pt":1719497939146,"mc":[{"id":"1.230180119","rc":[{"atb":[[1.73,2],[1.52,14.11]],"id":60276470}],"con":true,"img":false}]}
{"op":"mcm","clk":"11540746207","pt":1719497939254,"mc":[{"id":"1.230180119","rc":[{"atb":[[1.72,0],[1.46,9.12],[1.52,2.11]],"id":60276470}],"con":true,"img":false}]}
{"op":"mcm","clk":"11540746217","pt":1719497939355,"mc":[{"id":"1.230180119","rc":[{"atb":[[1.46,1],[1.72,6]],"id":60276470},{"atb":[[1.02,16.49]],"id":48534288}],"con":true,"img":false}]}
{"op":"mcm","clk":"11540746226","pt":1719497939408,"mc":[{"id":"1.230180119","rc":[{"atb":[[1.79,2]],"id":48534288}],"con":true,"img":false}]}
{"op":"mcm","clk":"11540746299","pt":1719497940337,"mc":[{"id":"1.230180119","rc":[{"atb":[[2.12,0]],"id":50772801}],"con":true,"img":false}]}
{"op":"mcm","clk":"11540746308","pt":1719497940447,"mc":[{"id":"1.230180119","rc":[{"atb":[[1.97,22]],"id":50772801}],"con":true,"img":false}]}
{"op":"mcm","clk":"11540746315","pt":1719497940544,"mc":[{"id":"1.230180119","rc":[{"atb":[[2.12,1.94],[2.1,1]],"id":50772801}],"con":true,"img":false}]}
{"op":"mcm","clk":"11540746324","pt":1719497940647,"mc":[{"id":"1.230180119","rc":[{"atb":[[1.02,16.49]],"id":69475360}],"con":true,"img":false}]}
{"op":"mcm","clk":"11540746331","pt":1719497940750,"mc":[{"id":"1.230180119","rc":[{"atb":[[1.84,2]],"id":69475360}],"con":true,"img":false}]}
{"op":"mcm","clk":"11540746356","pt":1719497941010,"mc":[{"id":"1.230180119","rc":[{"atb":[[1.79,0]],"id":48534288}],"con":true,"img":false}]}
{"op":"mcm","clk":"11540746368","pt":1719497941112,"mc":[{"id":"1.230180119","rc":[{"atb":[[1.02,18.49]],"id":48534288}],"con":true,"img":false}]}
{"op":"mcm","clk":"11540746437","pt":1719497942040,"mc":[{"id":"1.230180119","rc":[{"atl":[[10,1],[9.8,0]],"id":50772801},{"atl":[[4.3,0],[4.5,1]],"id":60276470},{"atb":[[1.97,0],[1.74,1]],"id":48534288},{"atb":[[1.84,0]],"id":69475360},{"atl":[[4.3,1],[4.2,0]],"id":69475360}],"con":true,"img":false}]}
{"op":"mcm","clk":"11540746446","pt":1719497942144,"mc":[{"id":"1.230180119","rc":[{"atl":[[32,0],[10,3]],"id":50772801},{"atl":[[4.5,3],[5.1,0]],"id":60276470},{"atb":[[1.74,6.9],[1.78,0]],"id":48534288}],"con":true,"img":false}]}
{"op":"mcm","clk":"11540746454","pt":1719497942246,"mc":[{"id":"1.230180119","rc":[{"atb":[[1.02,18.49]],"id":69475360}],"con":true,"img":false}]}
{"op":"mcm","clk":"11540746469","pt":1719497942452,"mc":[{"id":"1.230180119","rc":[{"atb":[[2.12,0]],"id":50772801}],"con":true,"img":false}]}
{"op":"mcm","clk":"11540746479","pt":1719497942556,"mc":[{"id":"1.230180119","rc":[{"atb":[[1.02,16.49]],"id":50772801}],"con":true,"img":false}]}
{"op":"mcm","clk":"11540746489","pt":1719497942665,"mc":[{"id":"1.230180119","rc":[{"atb":[[2.12,2]],"id":50772801},{"atl":[[9.6,0],[9.8,0.84]],"id":50772801},{"atl":[[4.4,0.84],[4.2,0]],"id":60276470}],"con":true,"img":false}]}
{"op":"mcm","clk":"11540746523","pt":1719497943073,"mc":[{"id":"1.230180119","rc":[{"atb":[[1.02,16.49]],"id":48534288}],"con":true,"img":false}]}
{"op":"mcm","clk":"11540746535","pt":1719497943184,"mc":[{"id":"1.230180119","rc":[{"atb":[[1.79,2]],"id":48534288}],"con":true,"img":false}]}
{"op":"mcm","clk":"11540746676","pt":1719497944732,"mc":[{"id":"1.230180119","rc":[{"atb":[[1.02,16.49]],"id":69475360}],"con":true,"img":false}]}
{"op":"mcm","clk":"11540746685","pt":1719497944830,"mc":[{"id":"1.230180119","rc":[{"atb":[[1.84,2]],"id":69475360}],"con":true,"img":false}]}
{"op":"mcm","clk":"11540746739","pt":1719497945449,"mc":[{"id":"1.230180119","rc":[{"atb":[[2.12,0]],"id":50772801}],"con":true,"img":false}]}
{"op":"mcm","clk":"11540746749","pt":1719497945562,"mc":[{"id":"1.230180119","rc":[{"atb":[[1.98,2]],"id":50772801}],"con":true,"img":false}]}
{"op":"mcm","clk":"11540746781","pt":1719497945861,"mc":[{"id":"1.230180119","rc":[{"atb":[[1.79,0]],"id":48534288}],"con":true,"img":false}]}
{"op":"mcm","clk":"11540746788","pt":1719497945973,"mc":[{"id":"1.230180119","rc":[{"atb":[[1.75,2]],"id":48534288}],"con":true,"img":false}]}
{"op":"mcm","clk":"11540746864","pt":1719497947057,"mc":[{"id":"1.230180119","rc":[{"spn":5.95,"spf":"NaN","id":50772801},{"spn":4.35,"spf":"NaN","id":62145089},{"spn":3.12,"spf":"NaN","id":69624671},{"spn":3.06,"spf":"NaN","id":60276470},{"spn":3.52,"spf":"NaN","id":48534288},{"atb":[[1.84,0]],"id":69475360},{"spn":3.06,"spf":"NaN","id":69475360}],"con":true,"img":false}]}
{"op":"mcm","clk":"11540746873","pt":1719497947156,"mc":[{"id":"1.230180119","rc":[{"atb":[[1.02,18.49]],"id":69475360}],"con":true,"img":false}]}
{"op":"mcm","clk":"11540746883","pt":1719497947258,"mc":[{"id":"1.230180119","rc":[{"atl":[[10,1],[50,2.04]],"id":50772801},{"atl":[[9.4,3.85]],"id":60276470}],"con":true,"img":false}]}
{"op":"mcm","clk":"11540746894","pt":1719497947367,"mc":[{"id":"1.230180119","rc":[{"atl":[[4.5,1]],"id":60276470}],"con":true,"img":false}]}
{"op":"mcm","clk":"11540746941","pt":1719497947940,"mc":[{"id":"1.230180119","rc":[{"atb":[[1.75,0]],"id":48534288}],"con":true,"img":false}]}
{"op":"mcm","clk":"11540746947","pt":1719497948051,"mc":[{"id":"1.230180119","rc":[{"atb":[[1.57,7.42]],"id":69624671},{"atb":[[1.73,13.8],[1.74,1],[1.02,18.49]],"id":48534288}],"con":true,"img":false}]}
{"op":"mcm","clk":"11540746964","pt":1719497948250,"mc":[{"id":"1.230180119","rc":[{"atb":[[1.58,7.42],[1.54,0]],"id":69624671}],"con":true,"img":false}]}
{"op":"mcm","clk":"11540746973","pt":1719497948352,"mc":[{"id":"1.230180119","rc":[{"atb":[[1.77,5.49]],"id":48534288}],"con":true,"img":false}]}
{"op":"mcm","clk":"11540747055","pt":1719497949236,"mc":[{"id":"1.230180119","rc":[{"atb":[[1.73,0],[1.78,5.49]],"id":48534288}],"con":true,"img":false}]}
{"op":"mcm","clk":"11540747077","pt":1719497949546,"mc":[{"id":"1.230180119","rc":[{"atb":[[1.02,16.49]],"id":69475360}],"con":true,"img":false}]}
{"op":"mcm","clk":"11540747085","pt":1719497949649,"mc":[{"id":"1.230180119","rc":[{"atb":[[1.84,2]],"id":69475360}],"con":true,"img":false}]}
{"op":"mcm","clk":"11540747109","pt":1719497949954,"mc":[{"id":"1.230180119","rc":[{"atb":[[1.55,0]],"id":69624671}],"con":true,"img":false}]}
{"op":"mcm","clk":"11540747117","pt":1719497950064,"mc":[{"id":"1.230180119","rc":[{"atb":[[1.59,2]],"id":69624671}],"con":true,"img":false}]}
{"op":"mcm","clk":"11540747130","pt":1719497950264,"mc":[{"id":"1.230180119","rc":[{"atb":[[1.53,0]],"id":69624671},{"atb":[[1.8,4.93],[1.79,0.66]],"id":48534288},{"atl":[[5.3,1.37]],"id":48534288}],"con":true,"img":false}]}
{"op":"mcm","clk":"11540747139","pt":1719497950319,"mc":[{"id":"1.230180119","rc":[{"atb":[[1.81,4.94],[1.78,0]],"id":48534288}],"con":true,"img":false}]}
{"op":"mcm","clk":"11540747148","pt":1719497950421,"mc":[{"id":"1.230180119","rc":[{"atb":[[1.6,6.57]],"id":69624671}],"con":true,"img":false}]}
{"op":"mcm","clk":"11540747158","pt":1719497950524,"mc":[{"id":"1.230180119","rc":[{"atl":[[4.8,6.95]],"id":48534288}],"con":true,"img":false}]}
{"op":"mcm","clk":"11540747163","pt":1719497950625,"mc":[{"id":"1.230180119","rc":[{"atb":[[1.08,50]],"id":50772801},{"atb":[[1.08,50]],"id":62145089},{"atb":[[1.08,50]],"id":69624671},{"atb":[[1.08,50]],"id":60276470},{"atb":[[1.08,50]],"id":48534288},{"atb":[[1.08,50]],"id":69475360}],"con":true,"img":false}]}
{"op":"mcm","clk":"11540747198","pt":1719497951039,"mc":[{"id":"1.230180119","rc":[{"atl":[[4.7,0.84]],"id":48534288}],"con":true,"img":false}]}
{"op":"mcm","clk":"11540747209","pt":1719497951148,"mc":[{"id":"1.230180119","rc":[{"atl":[[5.3,0.52],[5.5,0]],"id":48534288}],"con":true,"img":false}]}
{"op":"mcm","clk":"11540747265","pt":1719497951773,"mc":[{"id":"1.230180119","rc":[{"atb":[[1.84,0]],"id":69475360}],"con":true,"img":false}]}
{"op":"mcm","clk":"11540747278","pt":1719497951821,"mc":[{"id":"1.230180119","rc":[{"atb":[[1.02,18.49]],"id":69475360}],"con":true,"img":false}]}
{"op":"mcm","clk":"11540747306","pt":1719497952137,"mc":[{"id":"1.230180119","rc":[{"atb":[[1.59,0]],"id":69624671}],"con":true,"img":false}]}
{"op":"mcm","clk":"11540747321","pt":1719497952236,"mc":[{"id":"1.230180119","rc":[{"atb":[[1.61,2]],"id":69624671}],"con":true,"img":false}]}
{"op":"mcm","clk":"11540747349","pt":1719497952648,"mc":[{"id":"1.230180119","rc":[{"atb":[[1.02,16.49]],"id":48534288}],"con":true,"img":false}]}
{"op":"mcm","clk":"11540747358","pt":1719497952752,"mc":[{"id":"1.230180119","rc":[{"atb":[[1.82,2]],"id":48534288}],"con":true,"img":false}]}
{"op":"mcm","clk":"11540747427","pt":1719497953423,"mc":[{"id":"1.230180119","rc":[{"atl":[[4.7,6.06],[5.4,0.92]],"id":48534288}],"con":true,"img":false}]}
{"op":"mcm","clk":"11540747448","pt":1719497953803,"mc":[{"id":"1.230180119","rc":[{"atb":[[1.02,16.49]],"id":69475360}],"con":true,"img":false}]}
{"op":"mcm","clk":"11540747461","pt":1719497953942,"mc":[{"id":"1.230180119","rc":[{"atb":[[1.84,2]],"id":69475360}],"con":true,"img":false}]}
{"op":"mcm","clk":"11540747575","pt":1719497955331,"mc":[{"id":"1.230180119","rc":[{"atb":[[1.58,0]],"id":69624671}],"con":true,"img":false}]}
{"op":"mcm","clk":"11540747585","pt":1719497955434,"mc":[{"id":"1.230180119","rc":[{"atb":[[1.61,8.58]],"id":69624671},{"atl":[[4.8,0]],"id":48534288}],"con":true,"img":false}]}
{"op":"mcm","clk":"11540747590","pt":1719497955537,"mc":[{"id":"1.230180119","rc":[{"atb":[[1.84,0]],"id":69475360}],"con":true,"img":false}]}
{"op":"mcm","clk":"11540747598","pt":1719497955639,"mc":[{"id":"1.230180119","rc":[{"atb":[[1.02,18.49]],"id":69475360}],"con":true,"img":false}]}
{"op":"mcm","clk":"11540747694","pt":1719497956628,"mc":[{"id":"1.230180119","rc":[{"atb":[[1.02,16.49]],"id":69475360}],"con":true,"img":false}]}
{"op":"mcm","clk":"11540747705","pt":1719497956741,"mc":[{"id":"1.230180119","rc":[{"atb":[[1.84,2]],"id":69475360}],"con":true,"img":false}]}
{"op":"mcm","clk":"11540747834","pt":1719497958247,"mc":[{"id":"1.230180119","rc":[{"atb":[[1.84,0]],"id":69475360}],"con":true,"img":false}]}
{"op":"mcm","clk":"11540747839","pt":1719497958342,"mc":[{"id":"1.230180119","rc":[{"atb":[[1.02,18.49]],"id":69475360}],"con":true,"img":false}]}
{"op":"mcm","clk":"11540747862","pt":1719497958650,"mc":[{"id":"1.230180119","rc":[{"atl":[[4.7,8.06]],"id":48534288}],"con":true,"img":false}]}
{"op":"mcm","clk":"11540747876","pt":1719497958849,"mc":[{"id":"1.230180119","rc":[{"atl":[[4.7,2.84]],"id":48534288}],"con":true,"img":false}]}
{"op":"mcm","clk":"11540747936","pt":1719497959571,"mc":[{"id":"1.230180119","rc":[{"atb":[[2.8,10],[2.22,2],[2.12,2.25],[2.88,5],[1.97,0],[2.96,2.5]],"id":50772801},{"atl":[[36,2],[9.2,10],[7.6,2.5],[9.8,3.09],[50,0],[8.4,5]],"id":50772801},{"atb":[[2.02,7.9],[2.5,13.94],[2.22,0],[2.52,4.55],[2.66,2.5],[2.58,5]],"id":62145089},{"atl":[[8.6,10],[6.2,5.39],[6.6,0],[7,4.5],[7.8,5]],"id":62145089},{"atb":[[1.98,10],[2.04,5],[2.12,2.5],[1.62,10.5]],"id":69624671},{"atl":[[4.6,10.5],[5.3,5],[4.9,2.5],[5.7,10]],"id":69624671},{"atb":[[2.32,2.5],[2.24,5],[1.72,0],[1.57,8],[1.74,3.09],[2.16,10]],"id":60276470},{"atl":[[6.4,10],[5.8,5],[4.4,3.93],[5.4,2.5]],"id":60276470},{"atb":[[1.83,3.64],[2.22,2.5],[2.14,5],[2.06,10]],"id":48534288},{"atl":[[5.1,8.2],[6.4,0],[4.6,6.06],[5.5,5],[5.9,10]],"id":48534288},{"atb":[[1.83,3.61],[1.72,5],[1.02,16.49],[1.68,10],[1.76,2.5],[1.69,12.72]],"id":69475360},{"atl":[[8,2],[4.3,6],[10.5,0],[3.95,2.5],[4.2,1.5],[4.7,10]],"id":69475360}],"con":true,"img":false}]}
{"op":"mcm","clk":"11540747946","pt":1719497959676,"mc":[{"id":"1.230180119","rc":[{"atl":[[4.8,11.5]],"id":69624671},{"atl":[[5.4,4.5],[9.4,0]],"id":60276470},{"atb":[[2.06,14.94],[1.81,0]],"id":48534288},{"atb":[[1.84,2]],"id":69475360}],"con":true,"img":false}]}
{"op":"mcm","clk":"11540747956","pt":1719497959758,"mc":[{"id":"1.230180119","rc":[{"atl":[[9.6,0]],"id":69624671}],"con":true,"img":false}]}
{"op":"mcm","clk":"11540747965","pt":1719497959847,"mc":[{"id":"1.230180119","rc":[{"atl":[[4.2,1.84]],"id":69624671}],"con":true,"img":false}]}
{"op":"mcm","clk":"11540747986","pt":1719497960045,"mc":[{"id":"1.230180119","rc":[{"atl":[[7.4,0.84],[9.8,2.25]],"id":50772801},{"atl":[[4.1,0.84]],"id":69624671},{"atl":[[4.5,0.84]],"id":48534288},{"atl":[[3.9,0.84]],"id":69475360}],"con":true,"img":false}]}
{"op":"mcm","clk":"11540748006","pt":1719497960347,"mc":[{"id":"1.230180119","rc":[{"atb":[[2.58,7.11],[2.48,0]],"id":62145089},{"atl":[[4.8,1.05],[5.4,0]],"id":48534288},{"atb":[[1.83,1.5],[1.75,2.11]],"id":69475360}],"con":true,"img":false}]}
{"op":"mcm","clk":"11540748025","pt":1719497960758,"mc":[{"id":"1.230180119","rc":[{"atb":[[1.84,0]],"id":69475360}],"con":true,"img":false}]}
{"op":"mcm","clk":"11540748033","pt":1719497960861,"mc":[{"id":"1.230180119","rc":[{"atb":[[1.77,2]],"id":69475360}],"con":true,"img":false}]}
{"op":"mcm","clk":"11540748039","pt":1719497960963,"mc":[{"id":"1.230180119","rc":[{"atb":[[1.83,0]],"id":69475360}],"con":true,"img":false}]}
{"op":"mcm","clk":"11540748048","pt":1719497961071,"mc":[{"id":"1.230180119","rc":[{"atb":[[1.82,2.62]],"id":69475360}],"con":true,"img":false}]}
{"op":"mcm","clk":"11540748054","pt":1719497961174,"mc":[{"id":"1.230180119","rc":[{"atb":[[1.98,0]],"id":50772801}],"con":true,"img":false}]}
{"op":"mcm","clk":"11540748063","pt":1719497961272,"mc":[{"id":"1.230180119","rc":[{"atb":[[2.98,2]],"id":50772801}],"con":true,"img":false}]}
{"op":"mcm","clk":"11540748072","pt":1719497961530,"mc":[{"id":"1.230180119","rc":[{"atb":[[1.61,6.58]],"id":69624671}],"con":true,"img":false}]}
{"op":"mcm","clk":"11540748083","pt":1719497961738,"mc":[{"id":"1.230180119","rc":[{"atb":[[2.14,2]],"id":69624671}],"con":true,"img":false}]}
{"op":"mcm","clk":"11540748102","pt":1719497962050,"mc":[{"id":"1.230180119","rc":[{"atb":[[2.5,11.94]],"id":62145089}],"con":true,"img":false}]}
{"op":"mcm","clk":"11540748109","pt":1719497962150,"mc":[{"id":"1.230180119","rc":[{"atb":[[1.02,2]],"id":62145089}],"con":true,"img":false}]}
{"op":"mcm","clk":"11540748127","pt":1719497962356,"mc":[{"id":"1.230180119","rc":[{"atb":[[1.73,0]],"id":60276470}],"con":true,"img":false}]}
{"op":"mcm","clk":"11540748134","pt":1719497962460,"mc":[{"id":"1.230180119","rc":[{"atb":[[1.99,10]],"id":69624671},{"atb":[[1.02,2]],"id":60276470}],"con":true,"img":false}]}
{"op":"mcm","clk":"11540748143","pt":1719497962568,"mc":[{"id":"1.230180119","rc":[{"atb":[[1.61,0]],"id":69624671}],"con":true,"img":false}]}
{"op":"mcm","clk":"11540748149","pt":1719497962671,"mc":[{"id":"1.230180119","rc":[{"atb":[[1.82,0]],"id":48534288}],"con":true,"img":false}]}
{"op":"mcm","clk":"11540748158","pt":1719497962769,"mc":[{"id":"1.230180119","rc":[{"atb":[[1.02,18.49]],"id":48534288}],"con":true,"img":false}]}
{"op":"mcm","clk":"11540748215","pt":1719497963549,"mc":[{"id":"1.230180119","rc":[{"atb":[[1.77,0]],"id":69475360}],"con":true,"img":false}]}
{"op":"mcm","clk":"11540748221","pt":1719497963649,"mc":[{"id":"1.230180119","rc":[{"atb":[[1.83,2]],"id":69475360}],"con":true,"img":false}]}
{"op":"mcm","clk":"11540748373","pt":1719497965566,"mc":[{"id":"1.230180119","rc":[{"atl":[[5.3,0]],"id":48534288}],"con":true,"img":false}]}
{"op":"mcm","clk":"11540748383","pt":1719497965665,"mc":[{"id":"1.230180119","rc":[{"atb":[[1.79,0]],"id":48534288}],"con":true,"img":false}]}
{"op":"mcm","clk":"11540748447","pt":1719497966495,"mc":[{"id":"1.230180119","rc":[{"atb":[[2.98,4.5]],"id":50772801},{"atl":[[36,0],[8.4,10]],"id":50772801},{"atb":[[1.83,4.5],[1.69,0]],"id":69475360},{"atl":[[8,0]],"id":69475360}],"con":true,"img":false}]}
{"op":"mcm","clk":"11540748459","pt":1719497966542,"mc":[{"id":"1.230180119","rc":[{"atb":[[2.22,0]],"id":50772801},{"atb":[[2.02,0],[2.32,11.67]],"id":62145089},{"atl":[[4.8,0],[4.2,3.84]],"id":69624671},{"atb":[[1.57,0],[1.77,10]],"id":60276470},{"atl":[[5.1,2.5],[4.6,8.91]],"id":48534288},{"atl":[[4.2,7.5]],"id":69475360}],"con":true,"img":false}]}
{"op":"mcm","clk":"11540748533","pt":1719497967370,"mc":[{"id":"1.230180119","rc":[{"atl":[[4.5,1.37]],"id":48534288}],"con":true,"img":false}]}
{"op":"mcm","clk":"11540748542","pt":1719497967477,"mc":[{"id":"1.230180119","rc":[{"atb":[[1.03,0.52]],"id":48534288}],"con":true,"img":false}]}
{"op":"mcm","clk":"11540748564","pt":1719497967677,"mc":[{"id":"1.230180119","rc":[{"atb":[[1.03,0.42]],"id":48534288}],"con":true,"img":false}]}
{"op":"mcm","clk":"11540748587","pt":1719497967838,"mc":[{"id":"1.230180119","rc":[{"atb":[[1.03,0]],"id":48534288}],"con":true,"img":false}]}
{"op":"mcm","clk":"11540748595","pt":1719497967945,"mc":[{"id":"1.230180119","rc":[{"atb":[[2.24,0.42]],"id":48534288}],"con":true,"img":false}]}
{"op":"mcm","clk":"11540748618","pt":1719497968143,"mc":[{"id":"1.230180119","rc":[{"atb":[[2.06,10],[2.14,10]],"id":48534288}],"con":true,"img":false}]}
{"op":"mcm","clk":"11540748627","pt":1719497968241,"mc":[{"id":"1.230180119","rc":[{"atl":[[4.4,3.9]],"id":48534288}],"con":true,"img":false}]}
{"op":"mcm","clk":"11540748655","pt":1719497968651,"mc":[{"id":"1.230180119","rc":[{"atl":[[4.3,0.84],[4.7,2]],"id":48534288}],"con":true,"img":false}]}
{"op":"mcm","clk":"11540748922","pt":1719497972465,"mc":[{"id":"1.230180119","rc":[{"atl":[[4.8,0],[4.3,2.03]],"id":48534288}],"con":true,"img":false}]}
{"op":"mcm","clk":"11540748963","pt":1719497973181,"mc":[{"id":"1.230180119","rc":[{"atl":[[4.5,0.52]],"id":48534288}],"con":true,"img":false}]}
{"op":"mcm","clk":"11540748978","pt":1719497973485,"mc":[{"id":"1.230180119","rc":[{"atl":[[4.3,4.06],[4.6,6.06]],"id":48534288}],"con":true,"img":false}]}
{"op":"mcm","clk":"11540748985","pt":1719497973543,"mc":[{"id":"1.230180119","rc":[{"atl":[[4.3,2.03],[4.5,6.45]],"id":48534288}],"con":true,"img":false}]}
{"op":"mcm","clk":"11540748992","pt":1719497973654,"mc":[{"id":"1.230180119","rc":[{"atl":[[4.3,5.93],[4.5,0.52]],"id":48534288}],"con":true,"img":false}]}
{"op":"mcm","clk":"11540749000","pt":1719497973748,"mc":[{"id":"1.230180119","rc":[{"atl":[[4.3,2.03],[4.5,6.58]],"id":48534288}],"con":true,"img":false}]}
{"op":"mcm","clk":"11540749004","pt":1719497973851,"mc":[{"id":"1.230180119","rc":[{"atl":[[4.3,5.93],[4.5,0.52]],"id":48534288}],"con":true,"img":false}]}
{"op":"mcm","clk":"11540749010","pt":1719497973964,"mc":[{"id":"1.230180119","rc":[{"atl":[[4.3,2.03],[4.5,6.58]],"id":48534288}],"con":true,"img":false}]}
{"op":"mcm","clk":"11540749027","pt":1719497974265,"mc":[{"id":"1.230180119","rc":[{"atb":[[2.98,9.75]],"id":50772801},{"atl":[[7.4,6.09]],"id":50772801},{"atb":[[2.14,6.76]],"id":69624671},{"atl":[[4.1,5.6]],"id":69624671},{"atb":[[2.32,8.83]],"id":60276470},{"atb":[[2.24,5.22]],"id":48534288},{"atl":[[4.3,6.83],[4.2,3.2]],"id":48534288},{"atl":[[3.9,4.68]],"id":69475360}],"con":true,"img":false}]}
{"op":"mcm","clk":"11540749030","pt":1719497974367,"mc":[{"id":"1.230180119","rc":[{"atb":[[2.88,12],[2.12,0],[2.98,7.25]],"id":50772801},{"atl":[[9.8,0]],"id":50772801},{"atb":[[2.68,6.79]],"id":62145089},{"atb":[[1.62,0]],"id":69624671},{"atl":[[4.6,0]],"id":69624671},{"atb":[[1.74,0]],"id":60276470},{"atb":[[1.83,0]],"id":48534288},{"atl":[[4.3,13.42],[4.5,0.52],[4.6,0]],"id":48534288},{"atb":[[1.83,8.34]],"id":69475360},{"atl":[[4.2,6]],"id":69475360}],"con":true,"img":false}]}
{"op":"mcm","clk":"11540749039","pt":1719497974471,"mc":[{"id":"1.230180119","rc":[{"atb":[[2.88,5],[2.98,12.25]],"id":50772801},{"atb":[[2.52,0]],"id":62145089},{"atl":[[4.3,6.83],[4.4,13.93]],"id":48534288},{"atb":[[1.83,5.84],[1.82,0],[1.76,9.62]],"id":69475360}],"con":true,"img":false}]}
{"op":"mcm","clk":"11540749049","pt":1719497974670,"mc":[{"id":"1.230180119","rc":[{"atb":[[1.46,0],[1.51,1]],"id":60276470}],"con":true,"img":false}]}
{"op":"mcm","clk":"11540749111","pt":1719497975392,"mc":[{"id":"1.230180119","rc":[{"atl":[[4.4,10.03]],"id":48534288}],"con":true,"img":false}]}
{"op":"mcm","clk":"11540749129","pt":1719497975656,"mc":[{"id":"1.230180119","rc":[{"atl":[[4.1,0.84]],"id":48534288}],"con":true,"img":false}]}
{"op":"mcm","clk":"11540749204","pt":1719497976575,"mc":[{"id":"1.230180119","rc":[{"atb":[[2.1,2.11],[1.42,0]],"id":69624671}],"con":true,"img":false}]}
{"op":"mcm","clk":"11540749531","pt":1719497981260,"mc":[{"id":"1.230180119","rc":[{"atl":[[4.4,0],[4.2,10.03]],"id":48534288},{"atb":[[1.83,11.68],[1.76,2.5]],"id":69475360}],"con":true,"img":false}]}
{"op":"mcm","clk":"11540749633","pt":1719497982758,"mc":[{"id":"1.230180119","rc":[{"atl":[[4.5,0]],"id":48534288}],"con":true,"img":false}]}
{"op":"mcm","clk":"11540749663","pt":1719497983275,"mc":[{"id":"1.230180119","rc":[{"atb":[[2.24,4.8]],"id":48534288}],"con":true,"img":false}]}
{"op":"mcm","clk":"11540749775","pt":1719497984681,"mc":[{"id":"1.230180119","rc":[{"atl":[[4.3,5.64],[3.95,1.28]],"id":48534288}],"con":true,"img":false}]}
{"op":"mcm","clk":"11540749822","pt":1719497985279,"mc":[{"id":"1.230180119","rc":[{"atb":[[1.03,0.52]],"id":48534288},{"atl":[[3.9,0.52]],"id":48534288}],"con":true,"img":false}]}
{"op":"mcm","clk":"11540749838","pt":1719497985484,"mc":[{"id":"1.230180119","rc":[{"atb":[[1.03,0.41]],"id":48534288}],"con":true,"img":false}]}
{"op":"mcm","clk":"11540749845","pt":1719497985588,"mc":[{"id":"1.230180119","rc":[{"atb":[[1.03,0]],"id":48534288},{"atl":[[4.3,4.8],[4.1,0],[3.9,1.37]],"id":48534288}],"con":true,"img":false}]}
{"op":"mcm","clk":"11540749853","pt":1719497985690,"mc":[{"id":"1.230180119","rc":[{"atb":[[2.26,0.41]],"id":48534288}],"con":true,"img":false}]}
{"op":"mcm","clk":"11540749868","pt":1719497985899,"mc":[{"id":"1.230180119","rc":[{"atb":[[2.22,12.5],[2.14,5]],"id":48534288}],"con":true,"img":false}]}
{"op":"mcm","clk":"11540749887","pt":1719497986103,"mc":[{"id":"1.230180119","rc":[{"atl":[[3.85,3.47]],"id":48534288}],"con":true,"img":false}]}
{"op":"mcm","clk":"11540750161","pt":1719497988691,"mc":[{"id":"1.230180119","rc":[{"atl":[[3.8,6.05]],"id":48534288}],"con":true,"img":false}]}
{"op":"mcm","clk":"11540750180","pt":1719497988900,"mc":[{"id":"1.230180119","rc":[{"atl":[[4.3,0],[4.2,6.83]],"id":48534288}],"con":true,"img":false}]}
{"op":"mcm","clk":"11540750196","pt":1719497989107,"mc":[{"id":"1.230180119","rc":[{"atl":[[3.9,0.52]],"id":48534288}],"con":true,"img":false}]}
{"op":"mcm","clk":"11540750420","pt":1719497991779,"mc":[{"id":"1.230180119","rc":[{"atl":[[3.85,0]],"id":48534288}],"con":true,"img":false}]}
{"op":"mcm","clk":"11540750538","pt":1719497993067,"mc":[{"id":"1.230180119","rc":[{"atl":[[3.75,0.84]],"id":48534288}],"con":true,"img":false}]}
{"op":"mcm","clk":"11540751127","pt":1719498000212,"mc":[{"id":"1.230180119","rc":[{"atl":[[3.85,4.94]],"id":48534288}],"con":true,"img":false}]}
{"op":"mcm","clk":"11540751157","pt":1719498000621,"mc":[{"id":"1.230180119","rc":[{"atl":[[3.9,0]],"id":48534288}],"con":true,"img":false}]}
{"op":"mcm","clk":"11540751190","pt":1719498000881,"mc":[{"id":"1.230180119","rc":[{"atb":[[2.26,0]],"id":48534288},{"atl":[[3.95,0],[3.7,1.37]],"id":48534288}],"con":true,"img":false}]}
{"op":"mcm","clk":"11540751213","pt":1719498001107,"mc":[{"id":"1.230180119","rc":[{"atl":[[4.2,2]],"id":69624671},{"atb":[[2.22,2.5],[2.14,22.3]],"id":48534288}],"con":true,"img":false}]}
{"op":"mcm","clk":"11540751219","pt":1719498001188,"mc":[{"id":"1.230180119","rc":[{"atl":[[4.7,8.61]],"id":69624671}],"con":true,"img":false}]}
{"op":"mcm","clk":"11540751229","pt":1719498001293,"mc":[{"id":"1.230180119","rc":[{"atl":[[4.2,0]],"id":69624671}],"con":true,"img":false}]}
{"op":"mcm","clk":"11540751244","pt":1719498001499,"mc":[{"id":"1.230180119","rc":[{"atl":[[4.2,11.06]],"id":69624671}],"con":true,"img":false}]}
{"op":"mcm","clk":"11540751253","pt":1719498001606,"mc":[{"id":"1.230180119","rc":[{"atl":[[4.1,14.21],[4.7,1]],"id":69624671}],"con":true,"img":false}]}
{"op":"mcm","clk":"11540751279","pt":1719498001919,"mc":[{"id":"1.230180119","rc":[{"atl":[[4.2,0]],"id":69624671}],"con":true,"img":false}]}
{"op":"mcm","clk":"11540751332","pt":1719498002499,"mc":[{"id":"1.230180119","rc":[{"atl":[[4.1,15.84]],"id":69624671}],"con":true,"img":false}]}
{"op":"mcm","clk":"11540751360","pt":1719498002807,"mc":[{"id":"1.230180119","rc":[{"atl":[[3.7,6.85],[3.65,3.65]],"id":48534288}],"con":true,"img":false}]}
{"op":"mcm","clk":"11540751364","pt":1719498002905,"mc":[{"id":"1.230180119","rc":[{"atl":[[3.8,0]],"id":48534288}],"con":true,"img":false}]}
{"op":"mcm","clk":"11540751379","pt":1719498003040,"mc":[{"id":"1.230180119","rc":[{"atl":[[4.1,14.21]],"id":69624671},{"atl":[[3.85,0],[3.65,4.17]],"id":48534288}],"con":true,"img":false}]}
{"op":"mcm","clk":"11540751384","pt":1719498003117,"mc":[{"id":"1.230180119","rc":[{"atl":[[3.6,0.84],[3.75,0]],"id":48534288}],"con":true,"img":false}]}
{"op":"mcm","clk":"11540751397","pt":1719498003233,"mc":[{"id":"1.230180119","rc":[{"atb":[[1.03,0.52]],"id":48534288}],"con":true,"img":false}]}
{"op":"mcm","clk":"11540751409","pt":1719498003333,"mc":[{"id":"1.230180119","rc":[{"atl":[[4,4.53]],"id":69624671},{"atb":[[1.03,0.41]],"id":48534288}],"con":true,"img":false}]}
{"op":"mcm","clk":"11540751422","pt":1719498003479,"mc":[{"id":"1.230180119","rc":[{"atl":[[3.95,5.27]],"id":69624671},{"atb":[[1.03,0]],"id":48534288}],"con":true,"img":false}]}
{"op":"mcm","clk":"11540751435","pt":1719498003584,"mc":[{"id":"1.230180119","rc":[{"atb":[[2.26,0.41]],"id":48534288}],"con":true,"img":false}]}
{"op":"mcm","clk":"11540751449","pt":1719498003697,"mc":[{"id":"1.230180119","rc":[{"atl":[[3.95,6.11],[4.1,9.45]],"id":69624671}],"con":true,"img":false}]}
{"op":"mcm","clk":"11540751482","pt":1719498004100,"mc":[{"id":"1.230180119","rc":[{"atl":[[4.1,8.61]],"id":69624671}],"con":true,"img":false}]}
{"op":"mcm","clk":"11540751532","pt":1719498004618,"mc":[{"id":"1.230180119","rc":[{"atb":[[2.5,10]],"id":62145089}],"con":true,"img":false}]}
{"op":"mcm","clk":"11540751543","pt":1719498004722,"mc":[{"id":"1.230180119","rc":[{"atb":[[3,1.94]],"id":50772801},{"atb":[[2.7,1.94]],"id":62145089},{"atb":[[2.16,1.94]],"id":69624671},{"atb":[[2.34,1.94]],"id":60276470},{"atb":[[2.26,2.36]],"id":48534288}],"con":true,"img":false}]}
{"op":"mcm","clk":"11540751554","pt":1719498004840,"mc":[{"id":"1.230180119","rc":[{"atb":[[3,8.39]],"id":50772801},{"atb":[[2.7,7.19]],"id":62145089},{"atb":[[2.16,9.93]],"id":69624671},{"atb":[[2.34,8.27]],"id":60276470},{"atb":[[2.26,7.37]],"id":48534288}],"con":true,"img":false}]}
{"op":"mcm","clk":"11540751569","pt":1719498004982,"mc":[{"id":"1.230180119","rc":[{"atb":[[2.98,7]],"id":50772801},{"atb":[[2.68,0]],"id":62145089},{"atb":[[2.14,2]],"id":69624671},{"atb":[[2.32,2.5]],"id":60276470},{"atb":[[2.24,0]],"id":48534288}],"con":true,"img":false}]}
{"op":"mcm","clk":"11540751617","pt":1719498005501,"mc":[{"id":"1.230180119","rc":[{"atb":[[2.98,5]],"id":50772801}],"con":true,"img":false}]}
{"op":"mcm","clk":"11540751638","pt":1719498005715,"mc":[{"id":"1.230180119","rc":[{"atb":[[3.05,2]],"id":50772801}],"con":true,"img":false}]}
{"op":"mcm","clk":"11540751650","pt":1719498005828,"mc":[{"id":"1.230180119","rc":[{"atb":[[2.98,0]],"id":50772801}],"con":true,"img":false}]}
{"op":"mcm","clk":"11540751655","pt":1719498005913,"mc":[{"id":"1.230180119","rc":[{"atb":[[3.05,7]],"id":50772801}],"con":true,"img":false}]}
{"op":"mcm","clk":"11540751687","pt":1719498006237,"mc":[{"id":"1.230180119","rc":[{"atb":[[2.14,0]],"id":69624671}],"con":true,"img":false}]}
{"op":"mcm","clk":"11540751694","pt":1719498006333,"mc":[{"id":"1.230180119","rc":[{"atb":[[2.18,2]],"id":69624671}],"con":true,"img":false}]}
{"op":"mcm","clk":"11540751727","pt":1719498006600,"mc":[{"id":"1.230180119","rc":[{"atb":[[1.02,18.19]],"id":50772801},{"atl":[[1000,1.7]],"id":50772801},{"atb":[[1.01,1.7]],"id":69624671},{"atl":[[1000,1.88]],"id":69624671},{"atl":[[1000,1.7]],"id":69475360}],"con":true,"img":false}]}
{"op":"mcm","clk":"11540751732","pt":1719498006693,"mc":[{"id":"1.230180119","rc":[{"atb":[[1.01,1.7]],"id":69475360}],"con":true,"img":false}]}
{"op":"mcm","clk":"11540751743","pt":1719498006804,"mc":[{"id":"1.230180119","rc":[{"atb":[[1.02,16.62]],"id":50772801},{"atl":[[1000,0.04]],"id":50772801},{"atb":[[1.01,0.23]],"id":69624671},{"atl":[[1000,0.27]],"id":69624671},{"atl":[[1000,0.09]],"id":69475360}],"con":true,"img":false}]}
{"op":"mcm","clk":"11540751752","pt":1719498006914,"mc":[{"id":"1.230180119","rc":[{"atb":[[1.01,0.33]],"id":69475360}],"con":true,"img":false}]}
{"op":"mcm","clk":"11540751761","pt":1719498007002,"mc":[{"id":"1.230180119","rc":[{"atb":[[1.02,16.49]],"id":50772801},{"atl":[[1000,0]],"id":50772801},{"atl":[[1000,0.17]],"id":69624671}],"con":true,"img":false}]}
{"op":"mcm","clk":"11540751774","pt":1719498007117,"mc":[{"id":"1.230180119","rc":[{"atb":[[3.1,0.13]],"id":50772801},{"atl":[[7.2,0.04]],"id":50772801},{"spn":5.15,"spf":"NaN","id":50772801},{"spn":4.45,"spf":"NaN","id":62145089},{"atb":[[1.01,0]],"id":69624671},{"atl":[[3.9,0.09]],"id":69624671},{"spn":3.04,"spf":"NaN","id":69624671},{"spn":3.37,"spf":"NaN","id":60276470},{"spn":2.93,"spf":"NaN","id":48534288},{"atb":[[1.01,0]],"id":69475360},{"atl":[[1000,0]],"id":69475360},{"spn":2.86,"spf":"NaN","id":69475360}],"con":true,"img":false}]}
{"op":"mcm","clk":"11540751781","pt":1719498007213,"mc":[{"id":"1.230180119","rc":[{"atl":[[7.2,6.49],[7.6,12.5]],"id":50772801},{"atb":[[2.2,0.23]],"id":69624671},{"atb":[[1.84,0.33]],"id":69475360},{"atl":[[3.85,0.09]],"id":69475360}],"con":true,"img":false}]}
{"op":"mcm","clk":"11540751798","pt":1719498007324,"mc":[{"id":"1.230180119","rc":[{"atl":[[7.4,0.84],[8.4,5]],"id":50772801},{"atl":[[3.85,3.84],[3.95,8.5],[4.2,0]],"id":69475360}],"con":true,"img":false}]}
{"op":"mcm","clk":"11540751806","pt":1719498007422,"mc":[{"id":"1.230180119","rc":[{"atb":[[3,6.45]],"id":50772801},{"atl":[[3.9,0.84]],"id":69475360}],"con":true,"img":false}]}
{"op":"mcm","clk":"11540751818","pt":1719498007522,"mc":[{"id":"1.230180119","rc":[{"atb":[[3.1,2.08]],"id":50772801}],"con":true,"img":false}]}
{"op":"mcm","clk":"11540751827","pt":1719498007631,"mc":[{"id":"1.230180119","rc":[{"atl":[[7,0.84]],"id":50772801},{"atb":[[2.24,14.74]],"id":48534288},{"atl":[[3.8,0.84]],"id":69475360}],"con":true,"img":false}]}
{"op":"mcm","clk":"11540751837","pt":1719498007729,"mc":[{"id":"1.230180119","rc":[{"atb":[[2.14,5]],"id":48534288}],"con":true,"img":false}]}
{"op":"mcm","clk":"11540751875","pt":1719498008101,"mc":[{"id":"1.230180119","rc":[{"atl":[[3.95,12.23],[4.1,0]],"id":69624671}],"con":true,"img":false}]}
{"op":"mcm","clk":"11540751918","pt":1719498008516,"mc":[{"id":"1.230180119","rc":[{"atb":[[3.05,5]],"id":50772801}],"con":true,"img":false}]}
{"op":"mcm","clk":"11540751931","pt":1719498008623,"mc":[{"id":"1.230180119","rc":[{"atb":[[3.15,2]],"id":50772801},{"atb":[[1.99,0],[2.02,10]],"id":69624671},{"atb":[[1.83,5.84],[1.82,12.02]],"id":69475360}],"con":true,"img":false}]}
{"op":"mcm","clk":"11540751960","pt":1719498009044,"mc":[{"id":"1.230180119","rc":[{"atb":[[2.22,2.11],[2.1,0]],"id":69624671}],"con":true,"img":false}]}
{"op":"mcm","clk":"11540751986","pt":1719498009289,"mc":[{"id":"1.230180119","rc":[{"atl":[[4,0]],"id":69624671}],"con":true,"img":false}]}
{"op":"mcm","clk":"11540752002","pt":1719498009493,"mc":[{"id":"1.230180119","rc":[{"atl":[[3.95,13.86]],"id":69624671}],"con":true,"img":false}]}
{"op":"mcm","clk":"11540752050","pt":1719498010011,"mc":[{"id":"1.230180119","rc":[{"atl":[[3.95,12.23]],"id":69624671}],"con":true,"img":false}]}
{"op":"mcm","clk":"11540752060","pt":1719498010118,"mc":[{"id":"1.230180119","rc":[{"atb":[[2.16,7.99]],"id":69624671}],"con":true,"img":false}]}
{"op":"mcm","clk":"11540752081","pt":1719498010226,"mc":[{"id":"1.230180119","rc":[{"atb":[[2.24,1.94],[2.18,0]],"id":69624671},{"atl":[[3.9,5.79]],"id":69624671}],"con":true,"img":false}]}
{"op":"mcm","clk":"11540752088","pt":1719498010324,"mc":[{"id":"1.230180119","rc":[{"atb":[[2.24,3.94]],"id":69624671}],"con":true,"img":false}]}
{"op":"mcm","clk":"11540752173","pt":1719498011107,"mc":[{"id":"1.230180119","rc":[{"atl":[[3.85,0.84]],"id":69624671}],"con":true,"img":false}]}
{"op":"mcm","clk":"11540752239","pt":1719498011816,"mc":[{"id":"1.230180119","rc":[{"atl":[[3.9,0.09]],"id":69624671}],"con":true,"img":false}]}
{"op":"mcm","clk":"11540752260","pt":1719498012031,"mc":[{"id":"1.230180119","rc":[{"atl":[[3.85,3.48]],"id":69624671}],"con":true,"img":false}]}
{"op":"mcm","clk":"11540752282","pt":1719498012235,"mc":[{"id":"1.230180119","rc":[{"atl":[[3.85,2.64]],"id":69624671}],"con":true,"img":false}]}
{"op":"mcm","clk":"11540752301","pt":1719498012392,"mc":[{"id":"1.230180119","rc":[{"atb":[[3.05,0],[3.15,4.08]],"id":50772801}],"con":true,"img":false}]}
{"op":"mcm","clk":"11540752308","pt":1719498012504,"mc":[{"id":"1.230180119","rc":[{"atb":[[3.1,7.08]],"id":50772801},{"atl":[[3.85,0]],"id":69624671}],"con":true,"img":false}]}
{"op":"mcm","clk":"11540752316","pt":1719498012598,"mc":[{"id":"1.230180119","rc":[{"atb":[[3.15,2]],"id":50772801},{"atl":[[3.95,11.39]],"id":69624671}],"con":true,"img":false}]}
{"op":"mcm","clk":"11540752337","pt":1719498012812,"mc":[{"id":"1.230180119","rc":[{"atb":[[3.1,5.13]],"id":50772801},{"atl":[[3.8,4.87]],"id":69624671}],"con":true,"img":false}]}
{"op":"mcm","clk":"11540752357","pt":1719498013010,"mc":[{"id":"1.230180119","rc":[{"atb":[[3.2,1.94]],"id":50772801}],"con":true,"img":false}]}
{"op":"mcm","clk":"11540752368","pt":1719498013127,"mc":[{"id":"1.230180119","rc":[{"atb":[[3.1,0.13]],"id":50772801},{"atl":[[3.8,0]],"id":69624671}],"con":true,"img":false}]}
{"op":"mcm","clk":"11540752376","pt":1719498013218,"mc":[{"id":"1.230180119","rc":[{"atb":[[3.2,3.94]],"id":50772801}],"con":true,"img":false}]}
{"op":"mcm","clk":"11540752391","pt":1719498013340,"mc":[{"id":"1.230180119","rc":[{"atl":[[3.95,5.27],[4.7,12.49]],"id":69624671}],"con":true,"img":false}]}
{"op":"mcm","clk":"11540752400","pt":1719498013427,"mc":[{"id":"1.230180119","rc":[{"atl":[[3.7,6.71]],"id":69624671}],"con":true,"img":false}]}
{"op":"mcm","clk":"11540752419","pt":1719498013634,"mc":[{"id":"1.230180119","rc":[{"atl":[[3.7,0]],"id":69624671},{"atb":[[2.24,0],[2.22,24.61]],"id":48534288}],"con":true,"img":false}]}
{"op":"mcm","clk":"11540752459","pt":1719498013996,"mc":[{"id":"1.230180119","rc":[{"atl":[[3.6,3.2]],"id":48534288}],"con":true,"img":false}]}
{"op":"mcm","clk":"11540752485","pt":1719498014305,"mc":[{"id":"1.230180119","rc":[{"atb":[[3.15,0]],"id":50772801}],"con":true,"img":false}]}
{"op":"mcm","clk":"11540752491","pt":1719498014408,"mc":[{"id":"1.230180119","rc":[{"atb":[[3.25,2]],"id":50772801}],"con":true,"img":false}]}
{"op":"mcm","clk":"11540752586","pt":1719498015591,"mc":[{"id":"1.230180119","rc":[{"atl":[[3.55,2.53]],"id":48534288}],"con":true,"img":false}]}
{"op":"mcm","clk":"11540752631","pt":1719498016106,"mc":[{"id":"1.230180119","rc":[{"atl":[[3.5,0.84]],"id":48534288}],"con":true,"img":false}]}
{"op":"mcm","clk":"11540752676","pt":1719498016621,"mc":[{"id":"1.230180119","rc":[{"atl":[[3.45,4.11]],"id":48534288}],"con":true,"img":false}]}
{"op":"mcm","clk":"11540752683","pt":1719498016724,"mc":[{"id":"1.230180119","rc":[{"atl":[[3.55,8.69],[3.65,0.52]],"id":48534288}],"con":true,"img":false}]}
{"op":"mcm","clk":"11540752699","pt":1719498016930,"mc":[{"id":"1.230180119","rc":[{"atl":[[3.7,1.37]],"id":48534288}],"con":true,"img":false}]}
{"op":"mcm","clk":"11540752712","pt":1719498017135,"mc":[{"id":"1.230180119","rc":[{"atl":[[3.6,2.36]],"id":48534288}],"con":true,"img":false}]}
{"op":"mcm","clk":"11540752718","pt":1719498017193,"mc":[{"id":"1.230180119","rc":[{"atl":[[3.7,0],[3.4,1.49]],"id":48534288}],"con":true,"img":false}]}
{"op":"mcm","clk":"11540752735","pt":1719498017394,"mc":[{"id":"1.230180119","rc":[{"atl":[[3.9,4.64]],"id":69624671}],"con":true,"img":false}]}
{"op":"mcm","clk":"11540752754","pt":1719498017609,"mc":[{"id":"1.230180119","rc":[{"atl":[[3.95,0]],"id":69624671}],"con":true,"img":false}]}
{"op":"mcm","clk":"11540752788","pt":1719498018115,"mc":[{"id":"1.230180119","rc":[{"atl":[[3.85,0.84]],"id":69624671}],"con":true,"img":false}]}
{"op":"mcm","clk":"11540752799","pt":1719498018223,"mc":[{"id":"1.230180119","rc":[{"atl":[[3.55,6.16]],"id":48534288}],"con":true,"img":false}]}
{"op":"mcm","clk":"11540752824","pt":1719498018425,"mc":[{"id":"1.230180119","rc":[{"atl":[[3.65,0]],"id":48534288}],"con":true,"img":false}]}
{"op":"mcm","clk":"11540752832","pt":1719498018533,"mc":[{"id":"1.230180119","rc":[{"atb":[[2.8,10],[2.32,0],[2.88,5],[2.06,14.4],[2.96,2.5]],"id":62145089},{"atl":[[4.8,5],[4.4,2.5]],"id":69624671},{"atl":[[5.6,5],[6.4,0],[5.8,0],[5.2,2.5],[5.4,2]],"id":60276470},{"atl":[[3.6,0]],"id":48534288},{"atb":[[1.82,0],[1.79,11.68]],"id":69475360},{"atl":[[4.3,1],[3.95,6],[3.9,3.34],[4.7,0]],"id":69475360}],"con":true,"img":false}]}
{"op":"mcm","clk":"11540752847","pt":1719498018640,"mc":[{"id":"1.230180119","rc":[{"atb":[[2.8,0],[3.25,4.14],[2.88,0],[3.15,2.5],[2.96,0]],"id":50772801},{"atb":[[2.5,0],[2.58,2.11],[2.98,7.12],[2.66,0]],"id":62145089},{"atl":[[5.3,0],[4.9,0],[5.7,0]],"id":69624671},{"atl":[[5.2,7.5],[5.4,0]],"id":60276470}],"con":true,"img":false}]}
{"op":"mcm","clk":"11540752856","pt":1719498018839,"mc":[{"id":"1.230180119","rc":[{"atb":[[3,0]],"id":50772801},{"atb":[[2.7,1.94]],"id":62145089}],"con":true,"img":false}]}
{"op":"mcm","clk":"11540752869","pt":1719498018892,"mc":[{"id":"1.230180119","rc":[{"atb":[[2.26,6.95]],"id":48534288}],"con":true,"img":false}]}
{"op":"mcm","clk":"11540752928","pt":1719498019726,"mc":[{"id":"1.230180119","rc":[{"atl":[[4.4,8],[4.7,1]],"id":69624671}],"con":true,"img":false}]}
{"op":"mcm","clk":"11540753008","pt":1719498020808,"mc":[{"id":"1.230180119","rc":[{"atb":[[3.2,2]],"id":50772801},{"atb":[[2.7,0]],"id":62145089}],"con":true,"img":false}]}
{"op":"mcm","clk":"11540753020","pt":1719498021011,"mc":[{"id":"1.230180119","rc":[{"atb":[[3.3,1.94]],"id":50772801},{"atl":[[7,4.22]],"id":50772801},{"atb":[[3,1.94]],"id":62145089}],"con":true,"img":false}]}
{"op":"mcm","clk":"11540753032","pt":1719498021123,"mc":[{"id":"1.230180119","rc":[{"atl":[[3.8,6.24]],"id":69475360}],"con":true,"img":false}]}
{"op":"mcm","clk":"11540753043","pt":1719498021229,"mc":[{"id":"1.230180119","rc":[{"atb":[[3.2,0],[3.3,3.94]],"id":50772801},{"atl":[[7.2,0.04]],"id":50772801},{"atl":[[3.85,0.09]],"id":69475360}],"con":true,"img":false}]}
{"op":"mcm","clk":"11540753073","pt":1719498021533,"mc":[{"id":"1.230180119","rc":[{"atl":[[3.35,0.52]],"id":48534288}],"con":true,"img":false}]}
{"op":"mcm","clk":"11540753087","pt":1719498021640,"mc":[{"id":"1.230180119","rc":[{"atl":[[7.4,0]],"id":50772801},{"atl":[[3.9,2.5]],"id":69475360}],"con":true,"img":false}]}
{"op":"mcm","clk":"11540753098","pt":1719498021733,"mc":[{"id":"1.230180119","rc":[{"atb":[[1.03,0.52]],"id":48534288},{"atl":[[3.4,4.02]],"id":48534288}],"con":true,"img":false}]}
{"op":"mcm","clk":"11540753115","pt":1719498021939,"mc":[{"id":"1.230180119","rc":[{"atb":[[1.03,0.41]],"id":48534288}],"con":true,"img":false}]}
{"op":"mcm","clk":"11540753133","pt":1719498022102,"mc":[{"id":"1.230180119","rc":[{"atb":[[3.25,2.14]],"id":50772801},{"atb":[[1.03,0]],"id":48534288}],"con":true,"img":false}]}
{"op":"mcm","clk":"11540753137","pt":1719498022202,"mc":[{"id":"1.230180119","rc":[{"atb":[[3.35,2]],"id":50772801},{"atb":[[2.28,0.41]],"id":48534288},{"atl":[[3.5,0]],"id":48534288}],"con":true,"img":false}]}
{"op":"mcm","clk":"11540753218","pt":1719498023141,"mc":[{"id":"1.230180119","rc":[{"atl":[[3.35,1.37]],"id":48534288}],"con":true,"img":false}]}
{"op":"mcm","clk":"11540753261","pt":1719498023605,"mc":[{"id":"1.230180119","rc":[{"atb":[[3,0]],"id":62145089}],"con":true,"img":false}]}
{"op":"mcm","clk":"11540753281","pt":1719498023814,"mc":[{"id":"1.230180119","rc":[{"atb":[[3,1.94]],"id":62145089}],"con":true,"img":false}]}
{"op":"mcm","clk":"11540753337","pt":1719498024524,"mc":[{"id":"1.230180119","rc":[{"atb":[[1.95,8.95],[2.02,0]],"id":69624671}],"con":true,"img":false}]}
{"op":"mcm","clk":"11540753485","pt":1719498026334,"mc":[{"id":"1.230180119","rc":[{"atb":[[3,0]],"id":62145089}],"con":true,"img":false}]}
{"op":"mcm","clk":"11540753497","pt":1719498026447,"mc":[{"id":"1.230180119","rc":[{"atb":[[3,1.94]],"id":62145089}],"con":true,"img":false}]}
{"op":"mcm","clk":"11540753601","pt":1719498027529,"mc":[{"id":"1.230180119","rc":[{"atl":[[3.3,3.02]],"id":48534288}],"con":true,"img":false}]}
{"op":"mcm","clk":"11540753704","pt":1719498028853,"mc":[{"id":"1.230180119","rc":[{"atl":[[3.4,1.49]],"id":48534288}],"con":true,"img":false}]}
{"op":"mcm","clk":"11540753714","pt":1719498028917,"mc":[{"id":"1.230180119","rc":[{"atb":[[3,0]],"id":62145089}],"con":true,"img":false}]}
{"op":"mcm","clk":"11540753732","pt":1719498029119,"mc":[{"id":"1.230180119","rc":[{"atb":[[3,1.94]],"id":62145089}],"con":true,"img":false}]}
{"op":"mcm","clk":"11540753796","pt":1719498029735,"mc":[{"id":"1.230180119","rc":[{"atb":[[2.16,0]],"id":69624671}],"con":true,"img":false}]}
{"op":"mcm","clk":"11540753847","pt":1719498030250,"mc":[{"id":"1.230180119","rc":[{"atl":[[3.25,2.26]],"id":48534288}],"con":true,"img":false}]}
{"op":"mcm","clk":"11540753854","pt":1719498030347,"mc":[{"id":"1.230180119","rc":[{"atl":[[3.3,6.4]],"id":48534288}],"con":true,"img":false}]}
{"op":"mcm","clk":"11540753862","pt":1719498030462,"mc":[{"id":"1.230180119","rc":[{"atl":[[3.45,0]],"id":48534288}],"con":true,"img":false}]}
{"op":"mcm","clk":"11540753867","pt":1719498030502,"mc":[{"id":"1.230180119","rc":[{"atl":[[3.55,0]],"id":48534288}],"con":true,"img":false}]}
{"op":"mcm","clk":"11540753876","pt":1719498030606,"mc":[{"id":"1.230180119","rc":[{"atl":[[3.35,0.52],[3.2,0.84]],"id":48534288}],"con":true,"img":false}]}
{"op":"mcm","clk":"11540753885","pt":1719498030712,"mc":[{"id":"1.230180119","rc":[{"atl":[[3.25,4.79]],"id":48534288}],"con":true,"img":false}]}
{"op":"mcm","clk":"11540753913","pt":1719498031021,"mc":[{"id":"1.230180119","rc":[{"atl":[[3.85,5.39]],"id":69624671}],"con":true,"img":false}]}
{"op":"mcm","clk":"11540753936","pt":1719498031234,"mc":[{"id":"1.230180119","rc":[{"atl":[[3.9,0.09]],"id":69624671}],"con":true,"img":false}]}
{"op":"mcm","clk":"11540753967","pt":1719498031655,"mc":[{"id":"1.230180119","rc":[{"atb":[[3,0]],"id":62145089}],"con":true,"img":false}]}
{"op":"mcm","clk":"11540753982","pt":1719498031869,"mc":[{"id":"1.230180119","rc":[{"atb":[[3,1.94]],"id":62145089}],"con":true,"img":false}]}
{"op":"mcm","clk":"11540754011","pt":1719498032117,"mc":[{"id":"1.230180119","rc":[{"atb":[[3.35,6.57]],"id":50772801}],"con":true,"img":false}]}
{"op":"mcm","clk":"11540754022","pt":1719498032223,"mc":[{"id":"1.230180119","rc":[{"atb":[[3.25,0]],"id":50772801},{"atb":[[3.05,5.25]],"id":62145089}],"con":true,"img":false}]}
{"op":"mcm","clk":"11540754034","pt":1719498032333,"mc":[{"id":"1.230180119","rc":[{"atb":[[2.98,0]],"id":62145089}],"con":true,"img":false}]}
{"op":"mcm","clk":"11540754129","pt":1719498033459,"mc":[{"id":"1.230180119","rc":[{"atb":[[2.22,0],[2.1,2.11]],"id":69624671}],"con":true,"img":false}]}
{"op":"mcm","clk":"11540754183","pt":1719498034238,"mc":[{"id":"1.230180119","rc":[{"atb":[[2.24,1.94]],"id":69624671}],"con":true,"img":false}]}
{"op":"mcm","clk":"11540754191","pt":1719498034339,"mc":[{"id":"1.230180119","rc":[{"atb":[[3.3,2]],"id":50772801},{"atb":[[3,0]],"id":62145089},{"atb":[[2.14,2]],"id":69624671}],"con":true,"img":false}]}
{"op":"mcm","clk":"11540754206","pt":1719498034544,"mc":[{"id":"1.230180119","rc":[{"atb":[[3.4,1.94]],"id":50772801},{"atb":[[3.1,1.94],[3.05,0]],"id":62145089}],"con":true,"img":false}]}
{"op":"mcm","clk":"11540754211","pt":1719498034647,"mc":[{"id":"1.230180119","rc":[{"atb":[[3,7.12]],"id":62145089}],"con":true,"img":false}]}
{"op":"mcm","clk":"11540754219","pt":1719498034748,"mc":[{"id":"1.230180119","rc":[{"atb":[[3.25,4],[3.3,0]],"id":50772801},{"atl":[[3.3,3.38]],"id":48534288}],"con":true,"img":false}]}
{"op":"mcm","clk":"11540754298","pt":1719498035826,"mc":[{"id":"1.230180119","rc":[{"atb":[[2.14,0]],"id":69624671}],"con":true,"img":false}]}
{"op":"mcm","clk":"11540754306","pt":1719498035928,"mc":[{"id":"1.230180119","rc":[{"atb":[[2.22,2]],"id":69624671}],"con":true,"img":false}]}
{"op":"mcm","clk":"11540754376","pt":1719498036755,"mc":[{"id":"1.230180119","rc":[{"atb":[[3.4,4.94]],"id":50772801},{"atb":[[3.1,4.34]],"id":62145089},{"atb":[[2.36,4]],"id":60276470},{"atb":[[2.28,4.11]],"id":48534288},{"atb":[[1.84,3.43]],"id":69475360}],"con":true,"img":false}]}
{"op":"mcm","clk":"11540754382","pt":1719498036854,"mc":[{"id":"1.230180119","rc":[{"atb":[[2.36,9.96]],"id":60276470},{"atb":[[2.28,10.79]],"id":48534288},{"atb":[[1.84,10.39]],"id":69475360}],"con":true,"img":false}]}
{"op":"mcm","clk":"11540754391","pt":1719498036962,"mc":[{"id":"1.230180119","rc":[{"atb":[[2.34,1.94]],"id":60276470},{"atb":[[2.26,1.94]],"id":48534288},{"atb":[[1.83,2]],"id":69475360}],"con":true,"img":false}]}
{"op":"mcm","clk":"11540754404","pt":1719498037056,"mc":[{"id":"1.230180119","rc":[{"atl":[[3.35,0]],"id":48534288}],"con":true,"img":false}]}
{"op":"mcm","clk":"11540754439","pt":1719498037323,"mc":[{"id":"1.230180119","rc":[{"atb":[[2.24,0]],"id":69624671},{"atb":[[2.34,0]],"id":60276470},{"atb":[[2.26,0]],"id":48534288},{"atb":[[1.83,0]],"id":69475360}],"con":true,"img":false}]}
{"op":"mcm","clk":"11540754446","pt":1719498037423,"mc":[{"id":"1.230180119","rc":[{"atb":[[1.85,2]],"id":69475360}],"con":true,"img":false}]}
{"op":"mcm","clk":"11540754457","pt":1719498037530,"mc":[{"id":"1.230180119","rc":[{"atb":[[2.14,1.94]],"id":69624671},{"atb":[[2.38,1.94]],"id":60276470},{"atb":[[2.3,1.94],[2.28,10.38]],"id":48534288}],"con":true,"img":false}]}
{"op":"mcm","clk":"11540754476","pt":1719498037743,"mc":[{"id":"1.230180119","rc":[{"atb":[[3.35,4.57]],"id":50772801}],"con":true,"img":false}]}
{"op":"mcm","clk":"11540754482","pt":1719498037840,"mc":[{"id":"1.230180119","rc":[{"atb":[[3.45,2]],"id":50772801}],"con":true,"img":false}]}
{"op":"mcm","clk":"11540754519","pt":1719498038254,"mc":[{"id":"1.230180119","rc":[{"atb":[[2.22,0]],"id":69624671}],"con":true,"img":false}]}
{"op":"mcm","clk":"11540754529","pt":1719498038355,"mc":[{"id":"1.230180119","rc":[{"atb":[[2.14,3.94]],"id":69624671}],"con":true,"img":false}]}
{"op":"mcm","clk":"11540754539","pt":1719498038461,"mc":[{"id":"1.230180119","rc":[{"atb":[[2.14,7.28]],"id":69624671}],"con":true,"img":false}]}
{"op":"mcm","clk":"11540754635","pt":1719498039564,"mc":[{"id":"1.230180119","rc":[{"atb":[[1.6,0]],"id":69624671},{"atb":[[1.8,0]],"id":48534288}],"con":true,"img":false}]}
{"op":"mcm","clk":"11540754699","pt":1719498040262,"mc":[{"id":"1.230180119","rc":[{"atl":[[3.2,1.37]],"id":48534288}],"con":true,"img":false}]}
{"op":"mcm","clk":"11540754717","pt":1719498040475,"mc":[{"id":"1.230180119","rc":[{"atb":[[1.03,0.52]],"id":48534288}],"con":true,"img":false}]}
{"op":"mcm","clk":"11540754734","pt":1719498040631,"mc":[{"id":"1.230180119","rc":[{"atb":[[1.03,0.39]],"id":48534288}],"con":true,"img":false}]}
{"op":"mcm","clk":"11540754752","pt":1719498040826,"mc":[{"id":"1.230180119","rc":[{"atl":[[3.15,2.24]],"id":48534288}],"con":true,"img":false}]}
{"op":"mcm","clk":"11540754763","pt":1719498040937,"mc":[{"id":"1.230180119","rc":[{"atb":[[1.03,0]],"id":48534288}],"con":true,"img":false}]}
{"op":"mcm","clk":"11540754776","pt":1719498041036,"mc":[{"id":"1.230180119","rc":[{"atb":[[2.32,0.39]],"id":48534288},{"atl":[[3.1,0.84]],"id":48534288}],"con":true,"img":false}]}
{"op":"mcm","clk":"11540754958","pt":1719498042943,"mc":[{"id":"1.230180119","rc":[{"atl":[[3.25,2.26]],"id":48534288}],"con":true,"img":false}]}
{"op":"mcm","clk":"11540755029","pt":1719498043565,"mc":[{"id":"1.230180119","rc":[{"atl":[[3.05,1.66]],"id":48534288}],"con":true,"img":false}]}
{"op":"mcm","clk":"11540755038","pt":1719498043672,"mc":[{"id":"1.230180119","rc":[{"atl":[[3.1,3.33]],"id":48534288}],"con":true,"img":false}]}
{"op":"mcm","clk":"11540755050","pt":1719498043774,"mc":[{"id":"1.230180119","rc":[{"atl":[[3.25,0]],"id":48534288}],"con":true,"img":false}]}
{"op":"mcm","clk":"11540755059","pt":1719498043871,"mc":[{"id":"1.230180119","rc":[{"atl":[[3.3,0]],"id":48534288}],"con":true,"img":false}]}
{"op":"mcm","clk":"11540755083","pt":1719498044124,"mc":[{"id":"1.230180119","rc":[{"atl":[[3.2,0.52]],"id":48534288}],"con":true,"img":false}]}
{"op":"mcm","clk":"11540755169","pt":1719498045156,"mc":[{"id":"1.230180119","rc":[{"atl":[[3.05,4.19]],"id":48534288}],"con":true,"img":false}]}
{"op":"mcm","clk":"11540755201","pt":1719498045470,"mc":[{"id":"1.230180119","rc":[{"atb":[[3.45,8.6]],"id":50772801}],"con":true,"img":false}]}
{"op":"mcm","clk":"11540755211","pt":1719498045564,"mc":[{"id":"1.230180119","rc":[{"atb":[[3.35,0]],"id":50772801},{"atb":[[3.1,10.98]],"id":62145089}],"con":true,"img":false}]}
{"op":"mcm","clk":"11540755218","pt":1719498045663,"mc":[{"id":"1.230180119","rc":[{"atb":[[1.87,2.11],[1.75,0]],"id":69475360}],"con":true,"img":false}]}
{"op":"mcm","clk":"11540755231","pt":1719498045773,"mc":[{"id":"1.230180119","rc":[{"atb":[[3,0]],"id":62145089}],"con":true,"img":false}]}
{"op":"mcm","clk":"11540755276","pt":1719498046347,"mc":[{"id":"1.230180119","rc":[{"atb":[[1.85,0]],"id":69475360}],"con":true,"img":false}]}
{"op":"mcm","clk":"11540755283","pt":1719498046440,"mc":[{"id":"1.230180119","rc":[{"atb":[[1.88,2]],"id":69475360}],"con":true,"img":false}]}
{"op":"mcm","clk":"11540755358","pt":1719498047362,"mc":[{"id":"1.230180119","rc":[{"atl":[[3.15,0]],"id":48534288}],"con":true,"img":false}]}
{"op":"mcm","clk":"11540755447","pt":1719498048548,"mc":[{"id":"1.230180119","rc":[{"atl":[[3,0.84]],"id":48534288}],"con":true,"img":false}]}
{"op":"mcm","clk":"11540755548","pt":1719498049745,"mc":[{"id":"1.230180119","rc":[{"atb":[[3.1,0]],"id":50772801},{"atl":[[7.2,0]],"id":50772801},{"atb":[[2.2,0]],"id":69624671},{"atl":[[3.9,0]],"id":69624671},{"atb":[[1.84,10.06]],"id":69475360},{"atl":[[3.85,0]],"id":69475360}],"con":true,"img":false}]}
{"op":"mcm","clk":"11540755562","pt":1719498049946,"mc":[{"id":"1.230180119","rc":[{"atl":[[7.6,2.5],[8.4,18.51]],"id":50772801},{"atl":[[4.4,2.5],[4.7,14.4]],"id":69624671}],"con":true,"img":false}]}
{"op":"mcm","clk":"11540755570","pt":1719498050045,"mc":[{"id":"1.230180119","rc":[{"atb":[[2.38,6.77]],"id":60276470},{"atb":[[2.3,5.91]],"id":48534288},{"atb":[[1.88,8.38]],"id":69475360}],"con":true,"img":false}]}
{"op":"mcm","clk":"11540755589","pt":1719498050256,"mc":[{"id":"1.230180119","rc":[{"atb":[[2.36,4]],"id":60276470},{"atb":[[2.28,3.7]],"id":48534288},{"atb":[[1.84,3.1]],"id":69475360}],"con":true,"img":false}]}
{"op":"mcm","clk":"11540755618","pt":1719498050568,"mc":[{"id":"1.230180119","rc":[{"atb":[[1.98,0],[2.04,0],[2.12,0]],"id":69624671}],"con":true,"img":false}]}
{"op":"mcm","clk":"11540755626","pt":1719498050675,"mc":[{"id":"1.230180119","rc":[{"atb":[[1.8,5],[1.84,2.5],[1.76,10]],"id":69624671}],"con":true,"img":false}]}
{"op":"mcm","clk":"11540755633","pt":1719498050776,"mc":[{"id":"1.230180119","rc":[{"atb":[[3.4,1.94]],"id":50772801},{"atb":[[3.1,8.58]],"id":62145089},{"atb":[[2.36,0]],"id":60276470},{"atb":[[2.28,0]],"id":48534288},{"atb":[[1.84,0]],"id":69475360}],"con":true,"img":false}]}
{"op":"mcm","clk":"11540755649","pt":1719498050926,"mc":[{"id":"1.230180119","rc":[{"atb":[[3.5,3]],"id":50772801},{"atb":[[3.15,3.4]],"id":62145089},{"atb":[[2.4,2.89]],"id":60276470},{"atb":[[2.32,3.96]],"id":48534288}],"con":true,"img":false}]}
{"op":"mcm","clk":"11540755656","pt":1719498051032,"mc":[{"id":"1.230180119","rc":[{"atb":[[3.15,9.33]],"id":62145089}],"con":true,"img":false}]}
{"op":"mcm","clk":"11540755670","pt":1719498051236,"mc":[{"id":"1.230180119","rc":[{"atb":[[3.1,1.94]],"id":62145089}],"con":true,"img":false}]}
{"op":"mcm","clk":"11540755739","pt":1719498052062,"mc":[{"id":"1.230180119","rc":[{"atb":[[3.45,6.6]],"id":50772801}],"con":true,"img":false}]}
{"op":"mcm","clk":"11540755748","pt":1719498052165,"mc":[{"id":"1.230180119","rc":[{"atb":[[3.55,2]],"id":50772801}],"con":true,"img":false}]}
{"op":"mcm","clk":"11540755892","pt":1719498053763,"mc":[{"id":"1.230180119","rc":[{"atl":[[3,3.11]],"id":48534288}],"con":true,"img":false}]}
{"op":"mcm","clk":"11540755925","pt":1719498054185,"mc":[{"id":"1.230180119","rc":[{"atl":[[3.1,2.49]],"id":48534288}],"con":true,"img":false}]}
{"op":"mcm","clk":"11540756055","pt":1719498055581,"mc":[{"id":"1.230180119","rc":[{"atl":[[3.05,1.66],[3.2,0]],"id":48534288}],"con":true,"img":false}]}
{"op":"mcm","clk":"11540756116","pt":1719498056357,"mc":[{"id":"1.230180119","rc":[{"atb":[[2.32,3.57]],"id":48534288}],"con":true,"img":false}]}
{"op":"mcm","clk":"11540756142","pt":1719498056658,"mc":[{"id":"1.230180119","rc":[{"atl":[[3,8.13],[2.98,3.34]],"id":48534288}],"con":true,"img":false}]}
{"op":"mcm","clk":"11540756155","pt":1719498056866,"mc":[{"id":"1.230180119","rc":[{"atb":[[1.57,0]],"id":69624671},{"atb":[[1.77,0]],"id":48534288},{"atl":[[3.1,0],[3.05,0]],"id":48534288}],"con":true,"img":false}]}
{"op":"mcm","clk":"11540756176","pt":1719498057067,"mc":[{"id":"1.230180119","rc":[{"atl":[[2.96,0.84]],"id":48534288}],"con":true,"img":false}]}
{"op":"mcm","clk":"11540756260","pt":1719498057943,"mc":[{"id":"1.230180119","rc":[{"atl":[[2.96,3.38]],"id":48534288}],"con":true,"img":false}]}
{"op":"mcm","clk":"11540756290","pt":1719498058252,"mc":[{"id":"1.230180119","rc":[{"atl":[[2.94,0.52]],"id":48534288}],"con":true,"img":false}]}
{"op":"mcm","clk":"11540756306","pt":1719498058355,"mc":[{"id":"1.230180119","rc":[{"atb":[[1.03,0.52]],"id":48534288}],"con":true,"img":false}]}
{"op":"mcm","clk":"11540756320","pt":1719498058457,"mc":[{"id":"1.230180119","rc":[{"atb":[[3.55,7.42]],"id":50772801}],"con":true,"img":false}]}
{"op":"mcm","clk":"11540756330","pt":1719498058565,"mc":[{"id":"1.230180119","rc":[{"atb":[[1.03,0.39]],"id":48534288},{"atl":[[3,7.29]],"id":48534288}],"con":true,"img":false}]}
{"op":"mcm","clk":"11540756340","pt":1719498058664,"mc":[{"id":"1.230180119","rc":[{"atb":[[3.45,0]],"id":50772801}],"con":true,"img":false}]}
{"op":"mcm","clk":"11540756350","pt":1719498058771,"mc":[{"id":"1.230180119","rc":[{"atb":[[1.03,0]],"id":48534288}],"con":true,"img":false}]}
{"op":"mcm","clk":"11540756363","pt":1719498058871,"mc":[{"id":"1.230180119","rc":[{"atb":[[2.34,0.39]],"id":48534288}],"con":true,"img":false}]}
{"op":"mcm","clk":"11540756369","pt":1719498058976,"mc":[{"id":"1.230180119","rc":[{"atl":[[3,5.02]],"id":48534288}],"con":true,"img":false}]}
{"op":"mcm","clk":"11540756486","pt":1719498060563,"mc":[{"id":"1.230180119","rc":[{"atb":[[3.55,15.66]],"id":50772801},{"atb":[[2.34,15.84]],"id":48534288},{"atl":[[2.94,11.09]],"id":48534288}],"con":true,"img":false}]}
{"op":"mcm","clk":"11540756495","pt":1719498060665,"mc":[{"id":"1.230180119","rc":[{"atl":[[2.92,1]],"id":48534288}],"con":true,"img":false}]}
{"op":"mcm","clk":"11540756580","pt":1719498061447,"mc":[{"id":"1.230180119","rc":[{"atb":[[3.4,0]],"id":50772801},{"atb":[[3.1,0]],"id":62145089},{"atb":[[2.38,4.83]],"id":60276470},{"atb":[[2.3,3.97]],"id":48534288}],"con":true,"img":false}]}
{"op":"mcm","clk":"11540756592","pt":1719498061647,"mc":[{"id":"1.230180119","rc":[{"atb":[[3.6,1.94]],"id":50772801},{"atb":[[3.2,1.94]],"id":62145089},{"atb":[[2.42,1.94]],"id":60276470},{"atb":[[2.36,1.94]],"id":48534288}],"con":true,"img":false}]}
{"op":"mcm","clk":"11540756600","pt":1719498061757,"mc":[{"id":"1.230180119","rc":[{"atb":[[3.2,7.19]],"id":62145089}],"con":true,"img":false}]}
{"op":"mcm","clk":"11540756614","pt":1719498061854,"mc":[{"id":"1.230180119","rc":[{"atb":[[3.15,3.4]],"id":62145089},{"atb":[[2.36,4]],"id":60276470},{"atb":[[2.3,8.04]],"id":48534288},{"atl":[[2.88,1.76],[3.4,0]],"id":48534288},{"atb":[[1.86,5.39]],"id":69475360}],"con":true,"img":false}]}
{"op":"mcm","clk":"11540756622","pt":1719498061962,"mc":[{"id":"1.230180119","rc":[{"atl":[[2.92,0]],"id":48534288}],"con":true,"img":false}]}
{"op":"mcm","clk":"11540756634","pt":1719498062060,"mc":[{"id":"1.230180119","rc":[{"atl":[[2.96,2.53]],"id":48534288}],"con":true,"img":false}]}
{"op":"mcm","clk":"11540756685","pt":1719498062684,"mc":[{"id":"1.230180119","rc":[{"atl":[[2.96,0]],"id":48534288}],"con":true,"img":false}]}
{"op":"mcm","clk":"11540756696","pt":1719498062834,"mc":[{"id":"1.230180119","rc":[{"atb":[[3.55,7.42]],"id":50772801},{"atb":[[2.34,0.39]],"id":48534288},{"atl":[[2.94,0.52]],"id":48534288}],"con":true,"img":false}]}
{"op":"mcm","clk":"11540756707","pt":1719498062942,"mc":[{"id":"1.230180119","rc":[{"atb":[[2.42,7.06]],"id":60276470},{"atb":[[2.36,4.72]],"id":48534288}],"con":true,"img":false}]}
{"op":"mcm","clk":"11540756714","pt":1719498063039,"mc":[{"id":"1.230180119","rc":[{"atb":[[2.3,4.07]],"id":48534288}],"con":true,"img":false}]}
{"op":"mcm","clk":"11540756727","pt":1719498063149,"mc":[{"id":"1.230180119","rc":[{"atb":[[2.38,0]],"id":60276470}],"con":true,"img":false}]}
{"op":"mcm","clk":"11540756750","pt":1719498063349,"mc":[{"id":"1.230180119","rc":[{"atb":[[2.36,0]],"id":60276470}],"con":true,"img":false}]}
{"op":"mcm","clk":"11540756789","pt":1719498063877,"mc":[{"id":"1.230180119","rc":[{"atb":[[2.3,0]],"id":48534288}],"con":true,"img":false}]}
{"op":"mcm","clk":"11540756805","pt":1719498064083,"mc":[{"id":"1.230180119","rc":[{"atb":[[3.6,11.4]],"id":50772801},{"atb":[[2.36,22.71]],"id":48534288},{"atl":[[2.88,13.96],[2.86,1]],"id":48534288}],"con":true,"img":false}]}
{"op":"mcm","clk":"11540756822","pt":1719498064277,"mc":[{"id":"1.230180119","rc":[{"atb":[[3.6,9.46]],"id":50772801}],"con":true,"img":false}]}
{"op":"mcm","clk":"11540756833","pt":1719498064388,"mc":[{"id":"1.230180119","rc":[{"atb":[[3.6,11.4]],"id":50772801}],"con":true,"img":false}]}
{"op":"mcm","clk":"11540756871","pt":1719498064640,"mc":[{"id":"1.230180119","rc":[{"atb":[[3.55,5.42]],"id":50772801}],"con":true,"img":false}]}
{"op":"mcm","clk":"11540756877","pt":1719498064743,"mc":[{"id":"1.230180119","rc":[{"atb":[[3.65,2]],"id":50772801}],"con":true,"img":false}]}
{"op":"mcm","clk":"11540756885","pt":1719498064847,"mc":[{"id":"1.230180119","rc":[{"atb":[[3.5,0]],"id":50772801},{"atb":[[3.15,0]],"id":62145089},{"atb":[[2.4,0]],"id":60276470},{"atb":[[2.32,0]],"id":48534288}],"con":true,"img":false}]}
{"op":"mcm","clk":"11540756898","pt":1719498064956,"mc":[{"id":"1.230180119","rc":[{"atb":[[3.65,4.78]],"id":50772801},{"atb":[[3.25,2]],"id":62145089},{"atb":[[2.44,2.6]],"id":60276470},{"atb":[[2.38,2.9]],"id":48534288}],"con":true,"img":false}]}
{"op":"mcm","clk":"11540756906","pt":1719498065063,"mc":[{"id":"1.230180119","rc":[{"atb":[[3.25,7.25]],"id":62145089}],"con":true,"img":false}]}
{"op":"mcm","clk":"11540756918","pt":1719498065159,"mc":[{"id":"1.230180119","rc":[{"atb":[[3.2,1.94]],"id":62145089}],"con":true,"img":false}]}
{"op":"mcm","clk":"11540756940","pt":1719498065367,"mc":[{"id":"1.230180119","rc":[{"atb":[[3.6,11.19]],"id":50772801},{"atb":[[2.36,4.72]],"id":48534288}],"con":true,"img":false}]}
{"op":"mcm","clk":"11540756987","pt":1719498065877,"mc":[{"id":"1.230180119","rc":[{"atb":[[3.6,1.94]],"id":50772801}],"con":true,"img":false}]}
{"op":"mcm","clk":"11540756995","pt":1719498065981,"mc":[{"id":"1.230180119","rc":[{"atb":[[3.65,14.03]],"id":50772801}],"con":true,"img":false}]}
{"op":"mcm","clk":"11540757039","pt":1719498066453,"mc":[{"id":"1.230180119","rc":[{"atb":[[2.38,21.06]],"id":48534288}],"con":true,"img":false}]}
{"op":"mcm","clk":"11540757051","pt":1719498066552,"mc":[{"id":"1.230180119","rc":[{"atl":[[2.86,3.45]],"id":48534288}],"con":true,"img":false}]}
{"op":"mcm","clk":"11540757087","pt":1719498066965,"mc":[{"id":"1.230180119","rc":[{"atl":[[2.88,12.58]],"id":48534288}],"con":true,"img":false}]}
{"op":"mcm","clk":"11540757099","pt":1719498067069,"mc":[{"id":"1.230180119","rc":[{"atb":[[3.6,0]],"id":50772801},{"atb":[[3.2,0]],"id":62145089},{"atb":[[2.42,5.12]],"id":60276470},{"atb":[[2.36,2.78]],"id":48534288},{"atl":[[2.84,0.84]],"id":48534288}],"con":true,"img":false}]}
{"op":"mcm","clk":"11540757116","pt":1719498067182,"mc":[{"id":"1.230180119","rc":[{"spn":5.32,"spf":"NaN","id":50772801},{"spn":4.72,"spf":"NaN","id":62145089},{"spn":2.99,"spf":"NaN","id":69624671},{"spn":3.42,"spf":"NaN","id":60276470},{"atl":[[2.88,1.76],[2.86,2.45]],"id":48534288},{"spn":2.61,"spf":"NaN","id":48534288},{"spn":2.84,"spf":"NaN","id":69475360}],"con":true,"img":false}]}
{"op":"mcm","clk":"11540757128","pt":1719498067273,"mc":[{"id":"1.230180119","rc":[{"atb":[[3.7,1.94]],"id":50772801},{"atb":[[3.3,1.94]],"id":62145089},{"atb":[[2.4,1.94]],"id":48534288},{"atl":[[2.86,13.27]],"id":48534288}],"con":true,"img":false}]}
{"op":"mcm","clk":"11540757188","pt":1719498067846,"mc":[{"id":"1.230180119","rc":[{"atb":[[3.65,12.49]],"id":50772801},{"atb":[[2.38,18.31]],"id":48534288}],"con":true,"img":false}]}
{"op":"mcm","clk":"11540757206","pt":1719498068056,"mc":[{"id":"1.230180119","rc":[{"atb":[[3.65,4.78]],"id":50772801},{"atb":[[2.38,2.9]],"id":48534288}],"con":true,"img":false}]}
{"op":"mcm","clk":"11540757217","pt":1719498068160,"mc":[{"id":"1.230180119","rc":[{"atb":[[3.7,9.65]],"id":50772801},{"atb":[[2.4,17.35]],"id":48534288}],"con":true,"img":false}]}
{"op":"mcm","clk":"11540757319","pt":1719498069347,"mc":[{"id":"1.230180119","rc":[{"atb":[[3.65,2.78]],"id":50772801}],"con":true,"img":false}]}
{"op":"mcm","clk":"11540757331","pt":1719498069455,"mc":[{"id":"1.230180119","rc":[{"atb":[[3.75,2]],"id":50772801},{"atl":[[2.82,3.84]],"id":48534288}],"con":true,"img":false}]}
{"op":"mcm","clk":"11540757347","pt":1719498069657,"mc":[{"id":"1.230180119","rc":[{"atl":[[2.98,0]],"id":48534288}],"con":true,"img":false}]}
{"op":"mcm","clk":"11540757359","pt":1719498069761,"mc":[{"id":"1.230180119","rc":[{"atb":[[3.3,0]],"id":62145089},{"atb":[[2.4,15.41]],"id":48534288}],"con":true,"img":false}]}
{"op":"mcm","clk":"11540757373","pt":1719498069971,"mc":[{"id":"1.230180119","rc":[{"atb":[[3.3,1.94]],"id":62145089}],"con":true,"img":false}]}
{"op":"mcm","clk":"11540757450","pt":1719498070743,"mc":[{"id":"1.230180119","rc":[{"atb":[[3.7,1.94]],"id":50772801},{"atl":[[2.86,2.45]],"id":48534288}],"con":true,"img":false}]}
{"op":"mcm","clk":"11540757493","pt":1719498071266,"mc":[{"id":"1.230180119","rc":[{"atb":[[3.75,5.96]],"id":50772801}],"con":true,"img":false}]}
{"op":"mcm","clk":"11540757514","pt":1719498071468,"mc":[{"id":"1.230180119","rc":[{"atb":[[3.55,0]],"id":50772801}],"con":true,"img":false}]}
{"op":"mcm","clk":"11540757525","pt":1719498071572,"mc":[{"id":"1.230180119","rc":[{"atb":[[3.75,12.33]],"id":50772801},{"atl":[[2.82,16.29]],"id":48534288}],"con":true,"img":false}]}
{"op":"mcm","clk":"11540757535","pt":1719498071669,"mc":[{"id":"1.230180119","rc":[{"atb":[[3.7,3.94]],"id":50772801}],"con":true,"img":false}]}
{"op":"mcm","clk":"11540757572","pt":1719498072082,"mc":[{"id":"1.230180119","rc":[{"atl":[[2.86,0]],"id":48534288}],"con":true,"img":false}]}
{"op":"mcm","clk":"11540757625","pt":1719498072554,"mc":[{"id":"1.230180119","rc":[{"atb":[[3.7,2]],"id":50772801},{"atb":[[3.3,0]],"id":62145089}],"con":true,"img":false}]}
{"op":"mcm","clk":"11540757634","pt":1719498072651,"mc":[{"id":"1.230180119","rc":[{"atb":[[3.8,1.94]],"id":50772801},{"atb":[[3.3,1.94]],"id":62145089}],"con":true,"img":false}]}
{"op":"mcm","clk":"11540757749","pt":1719498073949,"mc":[{"id":"1.230180119","rc":[{"atb":[[3.7,0]],"id":50772801}],"con":true,"img":false}]}
{"op":"mcm","clk":"11540757758","pt":1719498074050,"mc":[{"id":"1.230180119","rc":[{"atb":[[3.8,3.94]],"id":50772801}],"con":true,"img":false}]}
{"op":"mcm","clk":"11540757770","pt":1719498074153,"mc":[{"id":"1.230180119","rc":[{"atl":[[2.94,0]],"id":48534288}],"con":true,"img":false}]}
{"op":"mcm","clk":"11540757778","pt":1719498074258,"mc":[{"id":"1.230180119","rc":[{"atb":[[3.75,11.21]],"id":50772801}],"con":true,"img":false}]}
{"op":"mcm","clk":"11540757787","pt":1719498074360,"mc":[{"id":"1.230180119","rc":[{"atb":[[2.34,0]],"id":48534288}],"con":true,"img":false}]}
{"op":"mcm","clk":"11540757797","pt":1719498074468,"mc":[{"id":"1.230180119","rc":[{"atb":[[3.75,3.96]],"id":50772801},{"atb":[[3.3,7.19]],"id":62145089}],"con":true,"img":false}]}
{"op":"mcm","clk":"11540757805","pt":1719498074567,"mc":[{"id":"1.230180119","rc":[{"atb":[[3.8,11.19]],"id":50772801},{"atb":[[3.25,2]],"id":62145089},{"atl":[[2.8,0.84]],"id":48534288}],"con":true,"img":false}]}
{"op":"mcm","clk":"11540757815","pt":1719498074678,"mc":[{"id":"1.230180119","rc":[{"atb":[[3.15,0],[3.3,2.5]],"id":50772801},{"atb":[[2.8,0],[3,2.5],[2.92,5],[2.88,0],[2.96,0]],"id":62145089},{"atl":[[4.8,0],[4.3,2.5],[4.4,0],[4.7,19.4]],"id":69624671},{"atb":[[1.75,10.78]],"id":69475360},{"atl":[[4,5],[3.8,8.74],[3.9,0]],"id":69475360}],"con":true,"img":false}]}
{"op":"mcm","clk":"11540757828","pt":1719498074778,"mc":[{"id":"1.230180119","rc":[{"atl":[[4.3,13.3],[4.7,6]],"id":69624671},{"atl":[[2.82,15.29]],"id":48534288},{"atb":[[1.79,0]],"id":69475360},{"atl":[[3.95,0],[3.75,6]],"id":69475360}],"con":true,"img":false}]}
{"op":"mcm","clk":"11540757839","pt":1719498074885,"mc":[{"id":"1.230180119","rc":[{"atl":[[4.3,2.5],[4.7,24.7]],"id":69624671},{"atl":[[3.95,17.5],[3.75,11.63]],"id":69475360}],"con":true,"img":false}]}
{"op":"mcm","clk":"11540757851","pt":1719498074985,"mc":[{"id":"1.230180119","rc":[{"atl":[[4,19.75],[3.95,0],[3.8,3.34],[3.75,5.63]],"id":69475360}],"con":true,"img":false}]}
{"op":"mcm","clk":"11540757871","pt":1719498075088,"mc":[{"id":"1.230180119","rc":[{"atl":[[3.7,0.84]],"id":69475360}],"con":true,"img":false}]}
{"op":"mcm","clk":"11540757889","pt":1719498075244,"mc":[{"id":"1.230180119","rc":[{"atl":[[4,5],[3.8,9.82]],"id":69475360}],"con":true,"img":false}]}
{"op":"mcm","clk":"11540757931","pt":1719498075666,"mc":[{"id":"1.230180119","rc":[{"atb":[[2.44,7.5]],"id":60276470},{"atb":[[2.42,4.26]],"id":48534288}],"con":true,"img":false}]}
{"op":"mcm","clk":"11540757955","pt":1719498075868,"mc":[{"id":"1.230180119","rc":[{"atb":[[2.42,0]],"id":60276470},{"atb":[[2.36,0]],"id":48534288}],"con":true,"img":false}]}
{"op":"mcm","clk":"11540758102","pt":1719498077257,"mc":[{"id":"1.230180119","rc":[{"atb":[[2.12,4.56]],"id":69624671},{"atb":[[2.4,0]],"id":48534288}],"con":true,"img":false}]}
{"op":"mcm","clk":"11540758111","pt":1719498077364,"mc":[{"id":"1.230180119","rc":[{"atb":[[2.42,0]],"id":48534288},{"atl":[[2.78,1]],"id":48534288},{"trd":[[2.42,8.52]],"ltp":2.42,"tv":8.52,"id":48534288}],"con":true,"img":false}]}
{"op":"mcm","clk":"11540758121","pt":1719498077471,"mc":[{"id":"1.230180119","rc":[{"atb":[[2.4,2.92]],"id":48534288}],"con":true,"img":false}]}
{"op":"mcm","clk":"11540758154","pt":1719498077771,"mc":[{"id":"1.230180119","rc":[{"atl":[[2.8,1.37]],"id":48534288}],"con":true,"img":false}]}
{"op":"mcm","clk":"11540758162","pt":1719498077875,"mc":[{"id":"1.230180119","rc":[{"atb":[[3.85,1.56]],"id":50772801},{"atb":[[2.24,1.59]],"id":48534288}],"con":true,"img":false}]}
{"op":"mcm","clk":"11540758180","pt":1719498078081,"mc":[{"id":"1.230180119","rc":[{"atl":[[2.84,0]],"id":48534288}],"con":true,"img":false}]}
{"op":"mcm","clk":"11540758222","pt":1719498078501,"mc":[{"id":"1.230180119","rc":[{"atb":[[3.8,3.94]],"id":50772801},{"atl":[[2.82,14.9]],"id":48534288}],"con":true,"img":false}]}
{"op":"mcm","clk":"11540758237","pt":1719498078548,"mc":[{"id":"1.230180119","rc":[{"atb":[[2.4,21.13]],"id":48534288}],"con":true,"img":false}]}
{"op":"mcm","clk":"11540758252","pt":1719498078761,"mc":[{"id":"1.230180119","rc":[{"atl":[[2.82,2.84]],"id":48534288}],"con":true,"img":false}]}
{"op":"mcm","clk":"11540758265","pt":1719498078857,"mc":[{"id":"1.230180119","rc":[{"atb":[[1.74,0]],"id":48534288},{"atl":[[2.78,13.06]],"id":48534288}],"con":true,"img":false}]}
{"op":"mcm","clk":"11540758277","pt":1719498078961,"mc":[{"id":"1.230180119","rc":[{"atb":[[3.85,9.33],[3.65,0]],"id":50772801},{"atb":[[3.25,0]],"id":62145089},{"atb":[[2.38,0]],"id":48534288}],"con":true,"img":false}]}
{"op":"mcm","clk":"11540758290","pt":1719498079065,"mc":[{"id":"1.230180119","rc":[{"atb":[[3.85,9.83]],"id":50772801},{"atb":[[3.35,2.57]],"id":62145089},{"atb":[[2.24,0],[2.42,2.93]],"id":48534288},{"atl":[[2.78,15.39]],"id":48534288},{"atb":[[1.89,3.39]],"id":69475360}],"con":true,"img":false}]}
{"op":"mcm","clk":"11540758299","pt":1719498079166,"mc":[{"id":"1.230180119","rc":[{"atb":[[3.35,7.87]],"id":62145089},{"atb":[[1.89,10.15]],"id":69475360}],"con":true,"img":false}]}
{"op":"mcm","clk":"11540758312","pt":1719498079270,"mc":[{"id":"1.230180119","rc":[{"atb":[[3.3,1.94]],"id":62145089},{"atl":[[5.9,0],[5.1,0],[5.5,0]],"id":48534288},{"atb":[[1.88,2]],"id":69475360}],"con":true,"img":false}]}
{"op":"mcm","clk":"11540758321","pt":1719498079377,"mc":[{"id":"1.230180119","rc":[{"atl":[[4.7,0]],"id":48534288}],"con":true,"img":false}]}
{"op":"mcm","clk":"11540758356","pt":1719498079681,"mc":[{"id":"1.230180119","rc":[{"atb":[[3.9,1.56]],"id":50772801},{"atb":[[1.9,1.5]],"id":69475360}],"con":true,"img":false}]}
{"op":"mcm","clk":"11540758367","pt":1719498079783,"mc":[{"id":"1.230180119","rc":[{"atb":[[2.06,0],[1.97,7.5]],"id":62145089}],"con":true,"img":false}]}
{"op":"mcm","clk":"11540758389","pt":1719498079989,"mc":[{"id":"1.230180119","rc":[{"atb":[[2.4,19.8]],"id":48534288},{"atb":[[1.88,0],[1.86,0]],"id":69475360}],"con":true,"img":false}]}
{"op":"mcm","clk":"11540758396","pt":1719498080094,"mc":[{"id":"1.230180119","rc":[{"atb":[[1.9,3.5]],"id":69475360}],"con":true,"img":false}]}
{"op":"mcm","clk":"11540758403","pt":1719498080147,"mc":[{"id":"1.230180119","rc":[{"atb":[[2.4,2.92]],"id":48534288}],"con":true,"img":false}]}
{"op":"mcm","clk":"11540758412","pt":1719498080251,"mc":[{"id":"1.230180119","rc":[{"atb":[[2.42,19.81]],"id":48534288}],"con":true,"img":false}]}
{"op":"mcm","clk":"11540758420","pt":1719498080353,"mc":[{"id":"1.230180119","rc":[{"atb":[[3.8,1.94]],"id":50772801},{"atb":[[1.9,2]],"id":69475360}],"con":true,"img":false}]}
{"op":"mcm","clk":"11540758435","pt":1719498080460,"mc":[{"id":"1.230180119","rc":[{"atb":[[3.9,3.56]],"id":50772801}],"con":true,"img":false}]}
{"op":"mcm","clk":"11540758443","pt":1719498080561,"mc":[{"id":"1.230180119","rc":[{"atb":[[3.85,9.33],[3.8,0]],"id":50772801},{"atb":[[3.3,0]],"id":62145089}],"con":true,"img":false}]}
{"op":"mcm","clk":"11540758459","pt":1719498080766,"mc":[{"id":"1.230180119","rc":[{"atb":[[3.85,2.06],[3.9,5.51]],"id":50772801},{"atb":[[3.4,1.94]],"id":62145089}],"con":true,"img":false}]}
{"op":"mcm","clk":"11540758468","pt":1719498080869,"mc":[{"id":"1.230180119","rc":[{"atb":[[3.9,11.21]],"id":50772801}],"con":true,"img":false}]}
{"op":"mcm","clk":"11540758479","pt":1719498080974,"mc":[{"id":"1.230180119","rc":[{"atb":[[1.09,1.56]],"id":50772801}],"con":true,"img":false}]}
{"op":"mcm","clk":"11540758534","pt":1719498081555,"mc":[{"id":"1.230180119","rc":[{"atb":[[1.09,0]],"id":50772801}],"con":true,"img":false}]}
{"op":"mcm","clk":"11540758545","pt":1719498081658,"mc":[{"id":"1.230180119","rc":[{"atb":[[3.95,1.56]],"id":50772801}],"con":true,"img":false}]}
{"op":"mcm","clk":"11540758573","pt":1719498081967,"mc":[{"id":"1.230180119","rc":[{"atl":[[2.76,9.16]],"id":48534288}],"con":true,"img":false}]}
{"op":"mcm","clk":"11540758582","pt":1719498082069,"mc":[{"id":"1.230180119","rc":[{"atl":[[2.82,0],[2.78,14.39],[2.76,10]],"id":48534288}],"con":true,"img":false}]}
{"op":"mcm","clk":"11540758593","pt":1719498082172,"mc":[{"id":"1.230180119","rc":[{"atb":[[3.9,3.94]],"id":50772801},{"atl":[[2.78,2.33]],"id":48534288}],"con":true,"img":false}]}
{"op":"mcm","clk":"11540758604","pt":1719498082277,"mc":[{"id":"1.230180119","rc":[{"atl":[[2.72,1.87],[2.88,0]],"id":48534288}],"con":true,"img":false}]}
{"op":"mcm","clk":"11540758634","pt":1719498082590,"mc":[{"id":"1.230180119","rc":[{"atl":[[2.8,0.52],[2.76,9.16]],"id":48534288}],"con":true,"img":false}]}
{"op":"mcm","clk":"11540758650","pt":1719498082747,"mc":[{"id":"1.230180119","rc":[{"atb":[[3.95,0]],"id":50772801}],"con":true,"img":false}]}
{"op":"mcm","clk":"11540758657","pt":1719498082851,"mc":[{"id":"1.230180119","rc":[{"atb":[[1.09,1.56]],"id":50772801}],"con":true,"img":false}]}
{"op":"mcm","clk":"11540758668","pt":1719498082955,"mc":[{"id":"1.230180119","rc":[{"atb":[[3.9,12.61]],"id":50772801},{"atl":[[2.72,15.07]],"id":48534288}],"con":true,"img":false}]}
{"op":"mcm","clk":"11540758693","pt":1719498083268,"mc":[{"id":"1.230180119","rc":[{"atb":[[3.4,0]],"id":62145089}],"con":true,"img":false}]}
{"op":"mcm","clk":"11540758714","pt":1719498083481,"mc":[{"id":"1.230180119","rc":[{"atb":[[3.4,1.94]],"id":62145089}],"con":true,"img":false}]}
{"op":"mcm","clk":"11540758746","pt":1719498083790,"mc":[{"id":"1.230180119","rc":[{"atb":[[3.95,6.14]],"id":50772801}],"con":true,"img":false}]}
{"op":"mcm","clk":"11540758758","pt":1719498083888,"mc":[{"id":"1.230180119","rc":[{"atb":[[3.75,0]],"id":50772801}],"con":true,"img":false}]}
{"op":"mcm","clk":"11540758778","pt":1719498084095,"mc":[{"id":"1.230180119","rc":[{"atb":[[3.9,3.94]],"id":50772801}],"con":true,"img":false}]}
{"op":"mcm","clk":"11540758821","pt":1719498084559,"mc":[{"id":"1.230180119","rc":[{"atb":[[3.9,1.94]],"id":50772801}],"con":true,"img":false}]}
{"op":"mcm","clk":"11540758831","pt":1719498084664,"mc":[{"id":"1.230180119","rc":[{"atb":[[4,2]],"id":50772801}],"con":true,"img":false}]}
{"op":"mcm","clk":"11540758850","pt":1719498084868,"mc":[{"id":"1.230180119","rc":[{"atb":[[3.95,13.7]],"id":50772801}],"con":true,"img":false}]}
{"op":"mcm","clk":"11540758880","pt":1719498085178,"mc":[{"id":"1.230180119","rc":[{"atb":[[1.09,0]],"id":50772801}],"con":true,"img":false}]}
{"op":"mcm","clk":"11540758891","pt":1719498085280,"mc":[{"id":"1.230180119","rc":[{"atb":[[4,3.56]],"id":50772801}],"con":true,"img":false}]}
{"op":"mcm","clk":"11540758907","pt":1719498085491,"mc":[{"id":"1.230180119","rc":[{"atl":[[2.72,18.59],[2.78,0]],"id":48534288}],"con":true,"img":false}]}
{"op":"mcm","clk":"11540758918","pt":1719498085588,"mc":[{"id":"1.230180119","rc":[{"atb":[[3.95,6.14]],"id":50772801}],"con":true,"img":false}]}
{"op":"mcm","clk":"11540758933","pt":1719498085796,"mc":[{"id":"1.230180119","rc":[{"atb":[[4,2]],"id":50772801}],"con":true,"img":false}]}
{"op":"mcm","clk":"11540758955","pt":1719498086057,"mc":[{"id":"1.230180119","rc":[{"atb":[[3.9,0]],"id":50772801},{"atb":[[3.4,0]],"id":62145089}],"con":true,"img":false}]}
{"op":"mcm","clk":"11540758964","pt":1719498086163,"mc":[{"id":"1.230180119","rc":[{"atb":[[4.1,1.94]],"id":50772801},{"atb":[[3.4,1.94]],"id":62145089}],"con":true,"img":false}]}
{"op":"mcm","clk":"11540758970","pt":1719498086262,"mc":[{"id":"1.230180119","rc":[{"atb":[[4.1,8.62]],"id":50772801}],"con":true,"img":false}]}
{"op":"mcm","clk":"11540759009","pt":1719498086785,"mc":[{"id":"1.230180119","rc":[{"atb":[[2.42,3.83]],"id":60276470},{"atb":[[2.4,6.7]],"id":48534288},{"atb":[[1.87,7.5]],"id":69475360}],"con":true,"img":false}]}
{"op":"mcm","clk":"11540759018","pt":1719498086882,"mc":[{"id":"1.230180119","rc":[{"atb":[[4.2,1.56]],"id":50772801},{"atb":[[3.4,7.19]],"id":62145089}],"con":true,"img":false}]}
{"op":"mcm","clk":"11540759032","pt":1719498087088,"mc":[{"id":"1.230180119","rc":[{"atb":[[3.35,2.57]],"id":62145089},{"atb":[[2.42,11.11]],"id":48534288},{"trd":[[2.42,25.92]],"ltp":2.42,"tv":25.92,"id":48534288}],"con":true,"img":false}]}
{"op":"mcm","clk":"11540759044","pt":1719498087299,"mc":[{"id":"1.230180119","rc":[{"atb":[[4.1,1.94]],"id":50772801},{"atl":[[3.7,10.7]],"id":69475360}],"con":true,"img":false}]}
{"op":"mcm","clk":"11540759059","pt":1719498087505,"mc":[{"id":"1.230180119","rc":[{"atb":[[4,0],[4.2,0]],"id":50772801},{"atb":[[1.9,3.5]],"id":69475360},{"atl":[[3.75,0]],"id":69475360}],"con":true,"img":false}]}
{"op":"mcm","clk":"11540759068","pt":1719498087610,"mc":[{"id":"1.230180119","rc":[{"atb":[[4.2,2]],"id":50772801},{"atl":[[4,25.54],[3.8,2.5],[3.65,1.35]],"id":69475360}],"con":true,"img":false}]}
{"op":"mcm","clk":"11540759080","pt":1719498087660,"mc":[{"id":"1.230180119","rc":[{"atb":[[3.85,0]],"id":50772801},{"atb":[[3.35,0]],"id":62145089},{"atb":[[2.44,1.35]],"id":48534288},{"atb":[[1.89,8.11]],"id":69475360}],"con":true,"img":false}]}
{"op":"mcm","clk":"11540759088","pt":1719498087759,"mc":[{"id":"1.230180119","rc":[{"atb":[[3.45,2]],"id":62145089},{"atb":[[1.9,6.5]],"id":69475360}],"con":true,"img":false}]}
{"op":"mcm","clk":"11540759115","pt":1719498088062,"mc":[{"id":"1.230180119","rc":[{"atb":[[2.44,13.25]],"id":48534288}],"con":true,"img":false}]}
{"op":"mcm","clk":"11540759129","pt":1719498088269,"mc":[{"id":"1.230180119","rc":[{"atb":[[2.4,3.78],[2.42,0]],"id":48534288},{"atl":[[3.65,0]],"id":69475360}],"con":true,"img":false}]}
{"op":"mcm","clk":"11540759138","pt":1719498088392,"mc":[{"id":"1.230180119","rc":[{"atb":[[4.2,9.52]],"id":50772801},{"atb":[[1.89,6.76]],"id":69475360}],"con":true,"img":false}]}
{"op":"mcm","clk":"11540759148","pt":1719498088480,"mc":[{"id":"1.230180119","rc":[{"atb":[[1.9,7.86]],"id":69475360}],"con":true,"img":false}]}
{"op":"mcm","clk":"11540759168","pt":1719498088683,"mc":[{"id":"1.230180119","rc":[{"atb":[[4.1,0]],"id":50772801}],"con":true,"img":false}]}
{"op":"mcm","clk":"11540759246","pt":1719498089568,"mc":[{"id":"1.230180119","rc":[{"atl":[[2.7,0.85]],"id":48534288}],"con":true,"img":false}]}
{"op":"mcm","clk":"11540759271","pt":1719498089882,"mc":[{"id":"1.230180119","rc":[{"atb":[[2.44,27.99]],"id":48534288}],"con":true,"img":false}]}
{"op":"mcm","clk":"11540759281","pt":1719498090094,"mc":[{"id":"1.230180119","rc":[{"atl":[[6.4,0],[6.6,1]],"id":62145089},{"atb":[[2.4,0]],"id":48534288}],"con":true,"img":false}]}
{"op":"mcm","clk":"11540759375","pt":1719498091379,"mc":[{"id":"1.230180119","rc":[{"atb":[[2.44,13.25]],"id":48534288}],"con":true,"img":false}]}
{"op":"mcm","clk":"11540759386","pt":1719498091480,"mc":[{"id":"1.230180119","rc":[{"atb":[[3.45,7.25]],"id":62145089}],"con":true,"img":false}]}
{"op":"mcm","clk":"11540759396","pt":1719498091583,"mc":[{"id":"1.230180119","rc":[{"atb":[[3.45,17.33]],"id":62145089},{"atl":[[6.8,3.96]],"id":62145089},{"atb":[[1.9,19.39]],"id":69475360}],"con":true,"img":false}]}
{"op":"mcm","clk":"11540759411","pt":1719498091785,"mc":[{"id":"1.230180119","rc":[{"atb":[[3.4,1.94]],"id":62145089},{"atb":[[1.89,0]],"id":69475360}],"con":true,"img":false}]}
{"op":"mcm","clk":"11540759423","pt":1719498091890,"mc":[{"id":"1.230180119","rc":[{"atb":[[3.45,18.68]],"id":62145089}],"con":true,"img":false}]}
{"op":"mcm","clk":"11540759433","pt":1719498091991,"mc":[{"id":"1.230180119","rc":[{"atb":[[1.87,2.11]],"id":69475360}],"con":true,"img":false}]}
{"op":"mcm","clk":"11540759460","pt":1719498092301,"mc":[{"id":"1.230180119","rc":[{"atb":[[3.5,1.61]],"id":62145089}],"con":true,"img":false}]}
{"op":"mcm","clk":"11540759481","pt":1719498092515,"mc":[{"id":"1.230180119","rc":[{"atl":[[2.74,3.08]],"id":48534288}],"con":true,"img":false}]}
{"op":"mcm","clk":"11540759528","pt":1719498093076,"mc":[{"id":"1.230180119","rc":[{"atb":[[2.44,11.9]],"id":48534288}],"con":true,"img":false}]}
{"op":"mcm","clk":"11540759538","pt":1719498093180,"mc":[{"id":"1.230180119","rc":[{"atb":[[3.45,16.95]],"id":62145089},{"atb":[[2.22,2.5],[2.44,0],[2.14,41.51]],"id":48534288}],"con":true,"img":false}]}
{"op":"mcm","clk":"11540759545","pt":1719498093283,"mc":[{"id":"1.230180119","rc":[{"atb":[[2.42,12.68],[2.2,3.62]],"id":48534288},{"atl":[[2.8,0],[2.68,1]],"id":48534288}],"con":true,"img":false}]}
{"op":"mcm","clk":"11540759553","pt":1719498093385,"mc":[{"id":"1.230180119","rc":[{"atb":[[3.45,8.6]],"id":62145089}],"con":true,"img":false}]}
{"op":"mcm","clk":"11540759565","pt":1719498093493,"mc":[{"id":"1.230180119","rc":[{"atb":[[3.5,9.96]],"id":62145089},{"atb":[[2.42,0],[2.2,0]],"id":48534288}],"con":true,"img":false}]}
{"op":"mcm","clk":"11540759578","pt":1719498093598,"mc":[{"id":"1.230180119","rc":[{"atb":[[2.24,4.59]],"id":48534288}],"con":true,"img":false}]}
{"op":"mcm","clk":"11540759589","pt":1719498093694,"mc":[{"id":"1.230180119","rc":[{"atb":[[2.16,1.35]],"id":48534288},{"atb":[[1.75,14.28]],"id":69475360}],"con":true,"img":false}]}
{"op":"mcm","clk":"11540759632","pt":1719498094160,"mc":[{"id":"1.230180119","rc":[{"atb":[[3.4,0]],"id":62145089},{"atb":[[2.24,21.94]],"id":48534288}],"con":true,"img":false}]}
{"op":"mcm","clk":"11540759639","pt":1719498094263,"mc":[{"id":"1.230180119","rc":[{"atb":[[3.55,1.94]],"id":62145089},{"atb":[[2.26,1.94],[2.16,0]],"id":48534288}],"con":true,"img":false}]}
{"op":"mcm","clk":"11540759651","pt":1719498094417,"mc":[{"id":"1.230180119","rc":[{"atb":[[2.24,23.29]],"id":48534288}],"con":true,"img":false}]}
{"op":"mcm","clk":"11540759679","pt":1719498094676,"mc":[{"id":"1.230180119","rc":[{"atb":[[2.26,3.53]],"id":48534288}],"con":true,"img":false}]}
{"op":"mcm","clk":"11540759747","pt":1719498095401,"mc":[{"id":"1.230180119","rc":[{"atl":[[2.72,15.07],[2.7,4.4]],"id":48534288}],"con":true,"img":false}]}
{"op":"mcm","clk":"11540759764","pt":1719498095608,"mc":[{"id":"1.230180119","rc":[{"atb":[[3.5,1.61]],"id":62145089},{"atb":[[2.24,5.94]],"id":48534288}],"con":true,"img":false}]}
{"op":"mcm","clk":"11540759794","pt":1719498095975,"mc":[{"id":"1.230180119","rc":[{"atb":[[3.5,0]],"id":62145089},{"atb":[[2.26,1.94]],"id":48534288}],"con":true,"img":false}]}
{"op":"mcm","clk":"11540759803","pt":1719498096079,"mc":[{"id":"1.230180119","rc":[{"atb":[[4.2,17.3]],"id":50772801},{"atb":[[3.45,7.25]],"id":62145089}],"con":true,"img":false}]}
{"op":"mcm","clk":"11540759808","pt":1719498096192,"mc":[{"id":"1.230180119","rc":[{"atb":[[3.95,0]],"id":50772801}],"con":true,"img":false}]}
{"op":"mcm","clk":"11540759829","pt":1719498096387,"mc":[{"id":"1.230180119","rc":[{"atb":[[3.55,9.92]],"id":62145089},{"atb":[[2.26,20.86]],"id":48534288}],"con":true,"img":false}]}
{"op":"mcm","clk":"11540759834","pt":1719498096491,"mc":[{"id":"1.230180119","rc":[{"atb":[[3.45,5.25]],"id":62145089},{"atb":[[1.9,16.39]],"id":69475360}],"con":true,"img":false}]}
{"op":"mcm","clk":"11540759852","pt":1719498096704,"mc":[{"id":"1.230180119","rc":[{"atb":[[3.55,12.82]],"id":62145089},{"atb":[[2.24,4.58]],"id":48534288},{"atb":[[1.91,3.4]],"id":69475360}],"con":true,"img":false}]}
{"op":"mcm","clk":"11540759864","pt":1719498096803,"mc":[{"id":"1.230180119","rc":[{"atb":[[2.28,1.35]],"id":48534288}],"con":true,"img":false}]}
{"op":"mcm","clk":"11540759894","pt":1719498097114,"mc":[{"id":"1.230180119","rc":[{"atb":[[4.2,9.78]],"id":50772801},{"atb":[[3.6,1.61]],"id":62145089},{"atb":[[2.26,1.94]],"id":48534288},{"atb":[[1.9,14.39]],"id":69475360}],"con":true,"img":false}]}
{"op":"mcm","clk":"11540759908","pt":1719498097211,"mc":[{"id":"1.230180119","rc":[{"atb":[[1.92,2]],"id":69475360}],"con":true,"img":false}]}
{"op":"mcm","clk":"11540759925","pt":1719498097367,"mc":[{"id":"1.230180119","rc":[{"atb":[[2.28,0]],"id":48534288},{"atb":[[1.75,10.78]],"id":69475360}],"con":true,"img":false}]}
{"op":"mcm","clk":"11540759937","pt":1719498097476,"mc":[{"id":"1.230180119","rc":[{"atb":[[2.24,5.94]],"id":48534288}],"con":true,"img":false}]}
{"op":"mcm","clk":"11540759979","pt":1719498097886,"mc":[{"id":"1.230180119","rc":[{"atb":[[3.55,4.84]],"id":62145089}],"con":true,"img":false}]}
{"op":"mcm","clk":"11540760005","pt":1719498098301,"mc":[{"id":"1.230180119","rc":[{"atb":[[2.26,21.96]],"id":48534288}],"con":true,"img":false}]}
{"op":"mcm","clk":"11540760016","pt":1719498098399,"mc":[{"id":"1.230180119","rc":[{"atb":[[3.6,0]],"id":62145089}],"con":true,"img":false}]}
{"op":"mcm","clk":"11540760024","pt":1719498098511,"mc":[{"id":"1.230180119","rc":[{"atb":[[2.24,4.58]],"id":48534288},{"atl":[[2.66,0.52]],"id":48534288}],"con":true,"img":false}]}
{"op":"mcm","clk":"11540760032","pt":1719498098608,"mc":[{"id":"1.230180119","rc":[{"atb":[[1.03,0.52],[2.28,1.35]],"id":48534288},{"atl":[[2.68,0]],"id":48534288}],"con":true,"img":false}]}
{"op":"mcm","clk":"11540760048","pt":1719498098812,"mc":[{"id":"1.230180119","rc":[{"atb":[[3.55,13.33]],"id":62145089},{"atb":[[1.03,0.41],[2.2,10],[2.14,5]],"id":48534288}],"con":true,"img":false}]}
{"op":"mcm","clk":"11540760069","pt":1719498098968,"mc":[{"id":"1.230180119","rc":[{"atb":[[1.03,0]],"id":48534288}],"con":true,"img":false}]}
{"op":"mcm","clk":"11540760080","pt":1719498099074,"mc":[{"id":"1.230180119","rc":[{"atb":[[3.6,6.91]],"id":62145089},{"atb":[[2.28,1.76]],"id":48534288}],"con":true,"img":false}]}
{"op":"mcm","clk":"11540760094","pt":1719498099177,"mc":[{"id":"1.230180119","rc":[{"atb":[[3.45,0]],"id":62145089}],"con":true,"img":false}]}
{"op":"mcm","clk":"11540760113","pt":1719498099386,"mc":[{"id":"1.230180119","rc":[{"atb":[[3.55,11.39]],"id":62145089}],"con":true,"img":false}]}
{"op":"mcm","clk":"11540760127","pt":1719498099491,"mc":[{"id":"1.230180119","rc":[{"atb":[[3.65,1.61]],"id":62145089}],"con":true,"img":false}]}
{"op":"mcm","clk":"11540760139","pt":1719498099594,"mc":[{"id":"1.230180119","rc":[{"atb":[[3.55,2.9],[3.65,3.56]],"id":62145089},{"atb":[[2.26,20.06]],"id":48534288}],"con":true,"img":false}]}
{"op":"mcm","clk":"11540760172","pt":1719498099898,"mc":[{"id":"1.230180119","rc":[{"atb":[[2.26,1.94]],"id":48534288}],"con":true,"img":false}]}
{"op":"mcm","clk":"11540760185","pt":1719498100007,"mc":[{"id":"1.230180119","rc":[{"atb":[[2.28,19.88]],"id":48534288}],"con":true,"img":false}]}
{"op":"mcm","clk":"11540760198","pt":1719498100106,"mc":[{"id":"1.230180119","rc":[{"atb":[[3.65,1.94]],"id":62145089}],"con":true,"img":false}]}
{"op":"mcm","clk":"11540760219","pt":1719498100317,"mc":[{"id":"1.230180119","rc":[{"atb":[[2.3,6.75]],"id":48534288}],"con":true,"img":false}]}
{"op":"mcm","clk":"11540760228","pt":1719498100420,"mc":[{"id":"1.230180119","rc":[{"atb":[[3.65,10.68]],"id":62145089}],"con":true,"img":false}]}
{"op":"mcm","clk":"11540760239","pt":1719498100473,"mc":[{"id":"1.230180119","rc":[{"atb":[[2.24,0]],"id":48534288}],"con":true,"img":false}]}
{"op":"mcm","clk":"11540760251","pt":1719498100580,"mc":[{"id":"1.230180119","rc":[{"atl":[[2.64,1]],"id":48534288}],"con":true,"img":false}]}
{"op":"mcm","clk":"11540760279","pt":1719498100882,"mc":[{"id":"1.230180119","rc":[{"atb":[[2.28,18.53]],"id":48534288}],"con":true,"img":false}]}
{"op":"mcm","clk":"11540760289","pt":1719498100987,"mc":[{"id":"1.230180119","rc":[{"atb":[[2.3,8.1],[2.28,16.34]],"id":48534288}],"con":true,"img":false}]}
{"op":"mcm","clk":"11540760309","pt":1719498101193,"mc":[{"id":"1.230180119","rc":[{"atb":[[2.28,0.41]],"id":48534288}],"con":true,"img":false}]}
{"op":"mcm","clk":"11540760315","pt":1719498101295,"mc":[{"id":"1.230180119","rc":[{"atb":[[3.7,1.61]],"id":62145089}],"con":true,"img":false}]}
{"op":"mcm","clk":"11540760328","pt":1719498101400,"mc":[{"id":"1.230180119","rc":[{"atb":[[2.3,24.03]],"id":48534288}],"con":true,"img":false}]}
{"op":"mcm","clk":"11540760408","pt":1719498102175,"mc":[{"id":"1.230180119","rc":[{"atb":[[2.26,0]],"id":48534288}],"con":true,"img":false}]}
{"op":"mcm","clk":"11540760415","pt":1719498102284,"mc":[{"id":"1.230180119","rc":[{"atb":[[3.65,1.94]],"id":62145089}],"con":true,"img":false}]}
{"op":"mcm","clk":"11540760440","pt":1719498102592,"mc":[{"id":"1.230180119","rc":[{"atb":[[3.7,0]],"id":62145089}],"con":true,"img":false}]}
{"op":"mcm","clk":"11540760537","pt":1719498103587,"mc":[{"id":"1.230180119","rc":[{"atb":[[3.65,7.08]],"id":62145089}],"con":true,"img":false}]}
{"op":"mcm","clk":"11540760543","pt":1719498103690,"mc":[{"id":"1.230180119","rc":[{"atb":[[3.6,0],[3.65,16.77]],"id":62145089},{"atb":[[1.92,12.58]],"id":69475360}],"con":true,"img":false}]}
{"op":"mcm","clk":"11540760554","pt":1719498103794,"mc":[{"id":"1.230180119","rc":[{"atb":[[1.9,2.86]],"id":69475360}],"con":true,"img":false}]}
{"op":"mcm","clk":"11540760562","pt":1719498103902,"mc":[{"id":"1.230180119","rc":[{"atb":[[2.3,22.68]],"id":48534288},{"atb":[[1.9,1.5]],"id":69475360}],"con":true,"img":false}]}
{"op":"mcm","clk":"11540760571","pt":1719498104001,"mc":[{"id":"1.230180119","rc":[{"atb":[[1.92,13.93]],"id":69475360}],"con":true,"img":false}]}
{"op":"mcm","clk":"11540760606","pt":1719498104413,"mc":[{"id":"1.230180119","rc":[{"atb":[[1.9,0]],"id":69475360}],"con":true,"img":false}]}
{"op":"mcm","clk":"11540760617","pt":1719498104520,"mc":[{"id":"1.230180119","rc":[{"atb":[[1.93,1.5]],"id":69475360}],"con":true,"img":false}]}
{"op":"mcm","clk":"11540760807","pt":1719498106691,"mc":[{"id":"1.230180119","rc":[{"atl":[[2.66,4.12],[2.7,0.85]],"id":48534288}],"con":true,"img":false}]}
{"op":"mcm","clk":"11540760848","pt":1719498107104,"mc":[{"id":"1.230180119","rc":[{"atb":[[3.55,0]],"id":62145089},{"atb":[[1.91,0]],"id":69475360}],"con":true,"img":false}]}
{"op":"mcm","clk":"11540760858","pt":1719498107208,"mc":[{"id":"1.230180119","rc":[{"atb":[[3.7,2.4]],"id":62145089},{"atb":[[2.32,3.73]],"id":48534288},{"atl":[[2.7,0]],"id":48534288},{"atb":[[1.93,5.5]],"id":69475360}],"con":true,"img":false}]}
{"op":"mcm","clk":"11540760867","pt":1719498107311,"mc":[{"id":"1.230180119","rc":[{"atb":[[2.32,9.63]],"id":48534288}],"con":true,"img":false}]}
{"op":"mcm","clk":"11540760871","pt":1719498107419,"mc":[{"id":"1.230180119","rc":[{"atb":[[2.3,15.93]],"id":48534288}],"con":true,"img":false}]}
{"op":"mcm","clk":"11540760880","pt":1719498107523,"mc":[{"id":"1.230180119","rc":[{"atb":[[2.34,1.35]],"id":48534288}],"con":true,"img":false}]}
{"op":"mcm","clk":"11540760886","pt":1719498107629,"mc":[{"id":"1.230180119","rc":[{"atb":[[3.65,14.83]],"id":62145089},{"atb":[[1.92,12.58]],"id":69475360}],"con":true,"img":false}]}
{"op":"mcm","clk":"11540760896","pt":1719498107677,"mc":[{"id":"1.230180119","rc":[{"atb":[[1.93,6.86]],"id":69475360}],"con":true,"img":false}]}
{"op":"mcm","clk":"11540760902","pt":1719498107781,"mc":[{"id":"1.230180119","rc":[{"atb":[[3.75,1.94],[3.65,13.39]],"id":62145089},{"atb":[[2.3,15.43]],"id":48534288}],"con":true,"img":false}]}
{"op":"mcm","clk":"11540760913","pt":1719498107883,"mc":[{"id":"1.230180119","rc":[{"atb":[[1.92,10.58]],"id":69475360}],"con":true,"img":false}]}
{"op":"mcm","clk":"11540760919","pt":1719498107989,"mc":[{"id":"1.230180119","rc":[{"atb":[[3.65,5.14]],"id":62145089},{"atb":[[2.3,0]],"id":48534288},{"atb":[[1.94,2]],"id":69475360}],"con":true,"img":false}]}
{"op":"mcm","clk":"11540760931","pt":1719498108089,"mc":[{"id":"1.230180119","rc":[{"atb":[[3.7,10.65]],"id":62145089},{"atb":[[2.32,25.06]],"id":48534288}],"con":true,"img":false}]}
{"op":"mcm","clk":"11540760970","pt":1719498108507,"mc":[{"id":"1.230180119","rc":[{"atb":[[3.7,2.4]],"id":62145089},{"atb":[[2.32,9.63]],"id":48534288}],"con":true,"img":false}]}
{"op":"mcm","clk":"11540760984","pt":1719498108604,"mc":[{"id":"1.230180119","rc":[{"atb":[[3.75,3.56]],"id":62145089},{"atb":[[1.93,5.35]],"id":69475360}],"con":true,"img":false}]}
{"op":"mcm","clk":"11540761046","pt":1719498109225,"mc":[{"id":"1.230180119","rc":[{"atb":[[3.75,1.94]],"id":62145089}],"con":true,"img":false}]}
{"op":"mcm","clk":"11540761057","pt":1719498109278,"mc":[{"id":"1.230180119","rc":[{"atb":[[3.75,10.7]],"id":62145089},{"atb":[[2.34,19.25]],"id":48534288}],"con":true,"img":false}]}
{"op":"mcm","clk":"11540761100","pt":1719498109812,"mc":[{"id":"1.230180119","rc":[{"atb":[[3.8,1.61]],"id":62145089}],"con":true,"img":false}]}
{"op":"mcm","clk":"11540761151","pt":1719498110482,"mc":[{"id":"1.230180119","rc":[{"atb":[[2.3,4.07]],"id":48534288},{"atb":[[1.93,4],[1.9,5.38]],"id":69475360}],"con":true,"img":false}]}
{"op":"mcm","clk":"11540761168","pt":1719498110688,"mc":[{"id":"1.230180119","rc":[{"atb":[[3.75,10.19]],"id":62145089}],"con":true,"img":false}]}
{"op":"mcm","clk":"11540761190","pt":1719498110897,"mc":[{"id":"1.230180119","rc":[{"atb":[[3.75,1.94]],"id":62145089}],"con":true,"img":false}]}
{"op":"mcm","clk":"11540761202","pt":1719498110999,"mc":[{"id":"1.230180119","rc":[{"atb":[[3.8,13.12]],"id":62145089},{"atb":[[1.93,5.5]],"id":69475360}],"con":true,"img":false}]}
{"op":"mcm","clk":"11540761209","pt":1719498111101,"mc":[{"id":"1.230180119","rc":[{"atb":[[1.92,11.93]],"id":69475360}],"con":true,"img":false}]}
{"op":"mcm","clk":"11540761217","pt":1719498111205,"mc":[{"id":"1.230180119","rc":[{"atb":[[3.65,0]],"id":62145089}],"con":true,"img":false}]}
{"op":"mcm","clk":"11540761280","pt":1719498111830,"mc":[{"id":"1.230180119","rc":[{"atb":[[1.92,10.58]],"id":69475360}],"con":true,"img":false}]}
{"op":"mcm","clk":"11540761292","pt":1719498111886,"mc":[{"id":"1.230180119","rc":[{"atb":[[1.93,6.86]],"id":69475360}],"con":true,"img":false}]}
{"op":"mcm","clk":"11540761326","pt":1719498112192,"mc":[{"id":"1.230180119","rc":[{"atb":[[2.36,10.32]],"id":48534288}],"con":true,"img":false}]}
{"op":"mcm","clk":"11540761334","pt":1719498112298,"mc":[{"id":"1.230180119","rc":[{"atb":[[2.32,3.73]],"id":48534288},{"atl":[[2.64,0]],"id":48534288}],"con":true,"img":false}]}
{"op":"mcm","clk":"11540761348","pt":1719498112400,"mc":[{"id":"1.230180119","rc":[{"atb":[[2.34,17.45]],"id":48534288}],"con":true,"img":false}]}
{"op":"mcm","clk":"11540761362","pt":1719498112606,"mc":[{"id":"1.230180119","rc":[{"atb":[[2.3,0],[2.34,1.35]],"id":48534288},{"atl":[[2.64,0.84]],"id":48534288}],"con":true,"img":false}]}
{"op":"mcm","clk":"11540761376","pt":1719498112710,"mc":[{"id":"1.230180119","rc":[{"atb":[[2.36,26.42]],"id":48534288}],"con":true,"img":false}]}
{"op":"mcm","clk":"11540761393","pt":1719498112915,"mc":[{"id":"1.230180119","rc":[{"atb":[[3.75,0]],"id":62145089},{"atb":[[2.34,0]],"id":48534288}],"con":true,"img":false}]}
{"op":"mcm","clk":"11540761403","pt":1719498113018,"mc":[{"id":"1.230180119","rc":[{"atb":[[2.38,1.35]],"id":48534288}],"con":true,"img":false}]}
{"op":"mcm","clk":"11540761413","pt":1719498113120,"mc":[{"id":"1.230180119","rc":[{"atb":[[3.85,1.94]],"id":62145089}],"con":true,"img":false}]}
{"op":"mcm","clk":"11540761425","pt":1719498113224,"mc":[{"id":"1.230180119","rc":[{"atb":[[2.36,10.31]],"id":48534288}],"con":true,"img":false}]}
{"op":"mcm","clk":"11540761445","pt":1719498113431,"mc":[{"id":"1.230180119","rc":[{"atb":[[3.8,11.51]],"id":62145089}],"con":true,"img":false}]}
{"op":"mcm","clk":"11540761483","pt":1719498113896,"mc":[{"id":"1.230180119","rc":[{"atl":[[6.4,1],[6.8,10.36],[6.6,0],[7,2.5]],"id":62145089},{"atb":[[1.82,10],[1.77,0]],"id":60276470}],"con":true,"img":false}]}
{"op":"mcm","clk":"11540761490","pt":1719498113999,"mc":[{"id":"1.230180119","rc":[{"atl":[[2.66,3.6]],"id":48534288}],"con":true,"img":false}]}
{"op":"mcm","clk":"11540761501","pt":1719498114102,"mc":[{"id":"1.230180119","rc":[{"atb":[[3.8,10.29]],"id":62145089}],"con":true,"img":false}]}
{"op":"mcm","clk":"11540761534","pt":1719498114413,"mc":[{"id":"1.230180119","rc":[{"atb":[[2.38,16.5],[2.28,0]],"id":48534288}],"con":true,"img":false}]}
{"op":"mcm","clk":"11540761542","pt":1719498114518,"mc":[{"id":"1.230180119","rc":[{"atb":[[3.8,3.26]],"id":62145089}],"con":true,"img":false}]}
{"op":"mcm","clk":"11540761552","pt":1719498114617,"mc":[{"id":"1.230180119","rc":[{"atb":[[3.85,8.97]],"id":62145089}],"con":true,"img":false}]}
{"op":"mcm","clk":"11540761577","pt":1719498114928,"mc":[{"id":"1.230180119","rc":[{"atl":[[6.8,10.33]],"id":62145089}],"con":true,"img":false}]}
{"op":"mcm","clk":"11540761595","pt":1719498115080,"mc":[{"id":"1.230180119","rc":[{"atl":[[6.8,6.4]],"id":62145089}],"con":true,"img":false}]}
{"op":"mcm","clk":"11540761605","pt":1719498115184,"mc":[{"id":"1.230180119","rc":[{"atl":[[6.2,9.32]],"id":62145089}],"con":true,"img":false}]}
{"op":"mcm","clk":"11540761619","pt":1719498115390,"mc":[{"id":"1.230180119","rc":[{"atb":[[3.9,7.24]],"id":62145089}],"con":true,"img":false}]}
{"op":"mcm","clk":"11540761626","pt":1719498115493,"mc":[{"id":"1.230180119","rc":[{"atb":[[3.8,0]],"id":62145089},{"atb":[[1.94,15.08]],"id":69475360}],"con":true,"img":false}]}
{"op":"mcm","clk":"11540761641","pt":1719498115699,"mc":[{"id":"1.230180119","rc":[{"atb":[[3.85,1.94]],"id":62145089},{"atb":[[1.92,0],[1.9,0]],"id":69475360}],"con":true,"img":false}]}
{"op":"mcm","clk":"11540761650","pt":1719498115801,"mc":[{"id":"1.230180119","rc":[{"atb":[[3.95,1.61]],"id":62145089},{"atb":[[1.93,5.35]],"id":69475360}],"con":true,"img":false}]}
