{"op":"mcm","clk":"11536380649","pt":1719425245588,"mc":[{"id":"1.230178317","marketDefinition":{"bspMarket":true,"turnInPlayEnabled":false,"persistenceEnabled":false,"marketBaseRate":5.0,"eventId":"33376062","eventTypeId":"4339","numberOfWinners":2,"bettingType":"ODDS","marketType":"PLACE","marketTime":"2024-06-27T15:09:00.000Z","suspendTime":"2024-06-27T15:09:00.000Z","bspReconciled":false,"complete":true,"inPlay":false,"crossMatching":false,"runnersVoidable":false,"numberOfActiveRunners":6,"betDelay":0,"status":"OPEN","runners":[{"status":"ACTIVE","sortPriority":1,"id":69685608,"name":"1. Spin It Danny"},{"status":"ACTIVE","sortPriority":2,"id":49159417,"name":"2. Derrymore Ella"},{"status":"ACTIVE","sortPriority":3,"id":57196226,"name":"3. Shrewd Cass"},{"status":"ACTIVE","sortPriority":4,"id":70902601,"name":"4. Fairy Hill John"},{"status":"ACTIVE","sortPriority":5,"id":52655636,"name":"5. Lady Quickstep"},{"status":"ACTIVE","sortPriority":6,"id":46611436,"name":"6. Curryhills Tiana"}],"regulators":["MR_INT"],"venue":"Kinsley","countryCode":"GB","discountAllowed":false,"timezone":"Europe/London","openDate":"2024-06-27T13:36:00.000Z","version":5994643765,"name":"To Be Placed","eventName":"Kinsley 27th Jun"},"rc":[],"con":true,"img":false}]}
{"op":"mcm","clk":"11536381009","pt":1719425248523,"mc":[{"id":"1.230178317","marketDefinition":{"bspMarket":true,"turnInPlayEnabled":false,"persistenceEnabled":false,"marketBaseRate":5.0,"eventId":"33376062","eventTypeId":"4339","numberOfWinners":2,"bettingType":"ODDS","marketType":"PLACE","marketTime":"2024-06-27T15:09:00.000Z","suspendTime":"2024-06-27T15:09:00.000Z","bspReconciled":false,"complete":true,"inPlay":false,"crossMatching":false,"runnersVoidable":false,"numberOfActiveRunners":6,"betDelay":0,"status":"OPEN","runners":[{"status":"ACTIVE","sortPriority":1,"id":69685608,"name":"1. Spin It Danny"},{"status":"ACTIVE","sortPriority":2,"id":49159417,"name":"2. Derrymore Ella"},{"status":"ACTIVE","sortPriority":3,"id":57196226,"name":"3. Shrewd Cass"},{"status":"ACTIVE","sortPriority":4,"id":70902601,"name":"4. Fairy Hill John"},{"status":"ACTIVE","sortPriority":5,"id":52655636,"name":"5. Lady Quickstep"},{"status":"ACTIVE","sortPriority":6,"id":46611436,"name":"6. Curryhills Tiana"}],"regulators":["MR_INT"],"venue":"Kinsley","countryCode":"GB","discountAllowed":true,"timezone":"Europe/London","openDate":"2024-06-27T13:36:00.000Z","version":5994643765,"name":"To Be Placed","eventName":"Kinsley 27th Jun"},"rc":[],"con":true,"img":false}]}
{"op":"mcm","clk":"11536615571","pt":1719428251205,"mc":[{"id":"1.230178317","rc":[{"atb":[[1.02,22.63]],"id":57196226},{"atl":[[990,0.84]],"id":57196226},{"spn":495.51,"spf":"NaN","id":57196226},{"atb":[[1.03,15.09]],"id":46611436},{"atl":[[1000,0.84]],"id":46611436},{"spn":500.51,"spf":"NaN","id":46611436},{"atb":[[1.03,15.09]],"id":52655636},{"atl":[[1000,0.84]],"id":52655636},{"spn":500.51,"spf":"NaN","id":52655636},{"atb":[[1.02,22.63]],"id":70902601},{"atl":[[990,0.84]],"id":70902601},{"spn":495.51,"spf":"NaN","id":70902601},{"atb":[[1.02,22.63]],"id":69685608},{"atl":[[1000,0.84]],"id":69685608},{"spn":500.51,"spf":"NaN","id":69685608},{"atb":[[1.01,45.27]],"id":49159417},{"atl":[[990,0.84]],"id":49159417},{"spn":495.5,"spf":"NaN","id":49159417}],"con":true,"img":false}]}
{"op":"mcm","clk":"11536837597","pt":1719431863745,"mc":[{"id":"1.230178317","rc":[{"atb":[[1.02,22.64]],"id":57196226},{"atl":[[990,0.26]],"id":57196226},{"atb":[[1.03,15.09]],"id":46611436},{"atl":[[1000,0.26]],"id":46611436},{"atb":[[1.03,15.09]],"id":52655636},{"atl":[[1000,0.26]],"id":52655636},{"atb":[[1.02,22.64]],"id":70902601},{"atl":[[990,0.26]],"id":70902601},{"atb":[[1.02,22.64]],"id":69685608},{"atl":[[1000,0.26]],"id":69685608},{"atb":[[1.01,45.28]],"id":49159417},{"atl":[[990,0.26]],"id":49159417}],"con":true,"img":false}]}
{"op":"mcm","clk":"11537232238","pt":1719437882515,"mc":[{"id":"1.230178317","marketDefinition":{"bspMarket":true,"turnInPlayEnabled":false,"persistenceEnabled":false,"marketBaseRate":5.0,"eventId":"33376062","eventTypeId":"4339","numberOfWinners":2,"bettingType":"ODDS","marketType":"PLACE","marketTime":"2024-06-27T15:09:00.000Z","suspendTime":"2024-06-27T15:09:00.000Z","bspReconciled":false,"complete":true,"inPlay":false,"crossMatching":false,"runnersVoidable":false,"numberOfActiveRunners":6,"betDelay":0,"status":"OPEN","runners":[{"status":"ACTIVE","sortPriority":1,"id":69685608,"name":"1. Spin It Danny"},{"status":"ACTIVE","sortPriority":2,"id":49159417,"name":"2. Derrymore Ella"},{"status":"ACTIVE","sortPriority":3,"id":57196226,"name":"3. Shrewd Cass"},{"status":"ACTIVE","sortPriority":4,"id":70902601,"name":"4. Fairy Hill John"},{"status":"ACTIVE","sortPriority":5,"id":52655636,"name":"5. Lady Quickstep"},{"status":"ACTIVE","sortPriority":6,"id":46611436,"name":"6. Curryhills Tiana"}],"regulators":["MR_INT"],"venue":"Kinsley","countryCode":"GB","discountAllowed":true,"timezone":"Europe/London","openDate":"2024-06-27T13:36:00.000Z","version":5994643765,"name":"To Be Placed","eventName":"Kinsley 27th Jun"},"rc":[{"atb":[[1.02,22.64]],"id":57196226},{"atl":[[990,0.26]],"id":57196226},{"spn":495.51,"spf":"NaN","id":57196226},{"atb":[[1.03,15.09]],"id":46611436},{"atl":[[1000,0.26]],"id":46611436},{"spn":500.51,"spf":"NaN","id":46611436},{"atb":[[1.03,15.09]],"id":52655636},{"atl":[[1000,0.26]],"id":52655636},{"spn":500.51,"spf":"NaN","id":52655636},{"atb":[[1.02,22.64]],"id":70902601},{"atl":[[990,0.26]],"id":70902601},{"spn":495.51,"spf":"NaN","id":70902601},{"atb":[[1.02,22.64]],"id":69685608},{"atl":[[1000,0.26]],"id":69685608},{"spn":500.51,"spf":"NaN","id":69685608},{"atb":[[1.01,45.28]],"id":49159417},{"atl":[[990,0.26]],"id":49159417},{"spn":495.5,"spf":"NaN","id":49159417}],"con":true,"img":true}]}
{"op":"mcm","clk":"11537573365","pt":1719443282536,"mc":[{"id":"1.230178317","marketDefinition":{"bspMarket":true,"turnInPlayEnabled":false,"persistenceEnabled":false,"marketBaseRate":5.0,"eventId":"33376062","eventTypeId":"4339","numberOfWinners":2,"bettingType":"ODDS","marketType":"PLACE","marketTime":"2024-06-27T15:09:00.000Z","suspendTime":"2024-06-27T15:09:00.000Z","bspReconciled":false,"complete":true,"inPlay":false,"crossMatching":false,"runnersVoidable":false,"numberOfActiveRunners":6,"betDelay":0,"status":"OPEN","runners":[{"status":"ACTIVE","sortPriority":1,"id":69685608,"name":"1. Spin It Danny"},{"status":"ACTIVE","sortPriority":2,"id":49159417,"name":"2. Derrymore Ella"},{"status":"ACTIVE","sortPriority":3,"id":57196226,"name":"3. Shrewd Cass"},{"status":"ACTIVE","sortPriority":4,"id":70902601,"name":"4. Fairy Hill John"},{"status":"ACTIVE","sortPriority":5,"id":52655636,"name":"5. Lady Quickstep"},{"status":"ACTIVE","sortPriority":6,"id":46611436,"name":"6. Curryhills Tiana"}],"regulators":["MR_INT"],"venue":"Kinsley","countryCode":"GB","discountAllowed":true,"timezone":"Europe/London","openDate":"2024-06-27T13:36:00.000Z","version":5994643765,"name":"To Be Placed","eventName":"Kinsley 27th Jun"},"rc":[{"atb":[[1.02,22.64]],"id":57196226},{"atl":[[990,0.26]],"id":57196226},{"spn":495.51,"spf":"NaN","id":57196226},{"atb":[[1.03,15.09]],"id":46611436},{"atl":[[1000,0.26]],"id":46611436},{"spn":500.51,"spf":"NaN","id":46611436},{"atb":[[1.03,15.09]],"id":52655636},{"atl":[[1000,0.26]],"id":52655636},{"spn":500.51,"spf":"NaN","id":52655636},{"atb":[[1.02,22.64]],"id":70902601},{"atl":[[990,0.26]],"id":70902601},{"spn":495.51,"spf":"NaN","id":70902601},{"atb":[[1.02,22.64]],"id":69685608},{"atl":[[1000,0.26]],"id":69685608},{"spn":500.51,"spf":"NaN","id":69685608},{"atb":[[1.01,45.29]],"id":49159417},{"atl":[[990,0.26]],"id":49159417},{"spn":495.5,"spf":"NaN","id":49159417}],"con":true,"img":true}]}
{"op":"mcm","clk":"11537954925","pt":1719448682555,"mc":[{"id":"1.230178317","marketDefinition":{"bspMarket":true,"turnInPlayEnabled":false,"persistenceEnabled":false,"marketBaseRate":5.0,"eventId":"33376062","eventTypeId":"4339","numberOfWinners":2,"bettingType":"ODDS","marketType":"PLACE","marketTime":"2024-06-27T15:09:00.000Z","suspendTime":"2024-06-27T15:09:00.000Z","bspReconciled":false,"complete":true,"inPlay":false,"crossMatching":false,"runnersVoidable":false,"numberOfActiveRunners":6,"betDelay":0,"status":"OPEN","runners":[{"status":"ACTIVE","sortPriority":1,"id":69685608,"name":"1. Spin It Danny"},{"status":"ACTIVE","sortPriority":2,"id":49159417,"name":"2. Derrymore Ella"},{"status":"ACTIVE","sortPriority":3,"id":57196226,"name":"3. Shrewd Cass"},{"status":"ACTIVE","sortPriority":4,"id":70902601,"name":"4. Fairy Hill John"},{"status":"ACTIVE","sortPriority":5,"id":52655636,"name":"5. Lady Quickstep"},{"status":"ACTIVE","sortPriority":6,"id":46611436,"name":"6. Curryhills Tiana"}],"regulators":["MR_INT"],"venue":"Kinsley","countryCode":"GB","discountAllowed":true,"timezone":"Europe/London","openDate":"2024-06-27T13:36:00.000Z","version":5994643765,"name":"To Be Placed","eventName":"Kinsley 27th Jun"},"rc":[{"atb":[[1.02,22.64]],"id":57196226},{"atl":[[990,0.26]],"id":57196226},{"spn":495.51,"spf":"NaN","id":57196226},{"atb":[[1.03,15.09]],"id":46611436},{"atl":[[1000,0.26]],"id":46611436},{"spn":500.51,"spf":"NaN","id":46611436},{"atb":[[1.03,15.09]],"id":52655636},{"atl":[[1000,0.26]],"id":52655636},{"spn":500.51,"spf":"NaN","id":52655636},{"atb":[[1.02,22.64]],"id":70902601},{"atl":[[990,0.26]],"id":70902601},{"spn":495.51,"spf":"NaN","id":70902601},{"atb":[[1.02,22.64]],"id":69685608},{"atl":[[1000,0.26]],"id":69685608},{"spn":500.51,"spf":"NaN","id":69685608},{"atb":[[1.01,45.28]],"id":49159417},{"atl":[[990,0.26]],"id":49159417},{"spn":495.5,"spf":"NaN","id":49159417}],"con":true,"img":true}]}
{"op":"mcm","clk":"11538170588","pt":1719454082537,"mc":[{"id":"1.230178317","marketDefinition":{"bspMarket":true,"turnInPlayEnabled":false,"persistenceEnabled":false,"marketBaseRate":5.0,"eventId":"33376062","eventTypeId":"4339","numberOfWinners":2,"bettingType":"ODDS","marketType":"PLACE","marketTime":"2024-06-27T15:09:00.000Z","suspendTime":"2024-06-27T15:09:00.000Z","bspReconciled":false,"complete":true,"inPlay":false,"crossMatching":false,"runnersVoidable":false,"numberOfActiveRunners":6,"betDelay":0,"status":"OPEN","runners":[{"status":"ACTIVE","sortPriority":1,"id":69685608,"name":"1. Spin It Danny"},{"status":"ACTIVE","sortPriority":2,"id":49159417,"name":"2. Derrymore Ella"},{"status":"ACTIVE","sortPriority":3,"id":57196226,"name":"3. Shrewd Cass"},{"status":"ACTIVE","sortPriority":4,"id":70902601,"name":"4. Fairy Hill John"},{"status":"ACTIVE","sortPriority":5,"id":52655636,"name":"5. Lady Quickstep"},{"status":"ACTIVE","sortPriority":6,"id":46611436,"name":"6. Curryhills Tiana"}],"regulators":["MR_INT"],"venue":"Kinsley","countryCode":"GB","discountAllowed":true,"timezone":"Europe/London","openDate":"2024-06-27T13:36:00.000Z","version":5994643765,"name":"To Be Placed","eventName":"Kinsley 27th Jun"},"rc":[{"atb":[[1.02,22.64]],"id":57196226},{"atl":[[990,0.26]],"id":57196226},{"spn":495.51,"spf":"NaN","id":57196226},{"atb":[[1.03,15.09]],"id":46611436},{"atl":[[1000,0.26]],"id":46611436},{"spn":500.51,"spf":"NaN","id":46611436},{"atb":[[1.03,15.09]],"id":52655636},{"atl":[[1000,0.26]],"id":52655636},{"spn":500.51,"spf":"NaN","id":52655636},{"atb":[[1.02,22.64]],"id":70902601},{"atl":[[990,0.26]],"id":70902601},{"spn":495.51,"spf":"NaN","id":70902601},{"atb":[[1.02,22.64]],"id":69685608},{"atl":[[1000,0.26]],"id":69685608},{"spn":500.51,"spf":"NaN","id":69685608},{"atb":[[1.01,45.29]],"id":49159417},{"atl":[[990,0.26]],"id":49159417},{"spn":495.5,"spf":"NaN","id":49159417}],"con":true,"img":true}]}
{"op":"mcm","clk":"11538368246","pt":1719459482565,"mc":[{"id":"1.230178317","marketDefinition":{"bspMarket":true,"turnInPlayEnabled":false,"persistenceEnabled":false,"marketBaseRate":5.0,"eventId":"33376062","eventTypeId":"4339","numberOfWinners":2,"bettingType":"ODDS","marketType":"PLACE","marketTime":"2024-06-27T15:09:00.000Z","suspendTime":"2024-06-27T15:09:00.000Z","bspReconciled":false,"complete":true,"inPlay":false,"crossMatching":false,"runnersVoidable":false,"numberOfActiveRunners":6,"betDelay":0,"status":"OPEN","runners":[{"status":"ACTIVE","sortPriority":1,"id":69685608,"name":"1. Spin It Danny"},{"status":"ACTIVE","sortPriority":2,"id":49159417,"name":"2. Derrymore Ella"},{"status":"ACTIVE","sortPriority":3,"id":57196226,"name":"3. Shrewd Cass"},{"status":"ACTIVE","sortPriority":4,"id":70902601,"name":"4. Fairy Hill John"},{"status":"ACTIVE","sortPriority":5,"id":52655636,"name":"5. Lady Quickstep"},{"status":"ACTIVE","sortPriority":6,"id":46611436,"name":"6. Curryhills Tiana"}],"regulators":["MR_INT"],"venue":"Kinsley","countryCode":"GB","discountAllowed":true,"timezone":"Europe/London","openDate":"2024-06-27T13:36:00.000Z","version":5994643765,"name":"To Be Placed","eventName":"Kinsley 27th Jun"},"rc":[{"atb":[[1.02,22.65]],"id":57196226},{"atl":[[990,0.26]],"id":57196226},{"spn":495.51,"spf":"NaN","id":57196226},{"atb":[[1.03,15.1]],"id":46611436},{"atl":[[1000,0.26]],"id":46611436},{"spn":500.51,"spf":"NaN","id":46611436},{"atb":[[1.03,15.1]],"id":52655636},{"atl":[[1000,0.26]],"id":52655636},{"spn":500.51,"spf":"NaN","id":52655636},{"atb":[[1.02,22.65]],"id":70902601},{"atl":[[990,0.26]],"id":70902601},{"spn":495.51,"spf":"NaN","id":70902601},{"atb":[[1.02,22.65]],"id":69685608},{"atl":[[1000,0.26]],"id":69685608},{"spn":500.51,"spf":"NaN","id":69685608},{"atb":[[1.01,45.3]],"id":49159417},{"atl":[[990,0.26]],"id":49159417},{"spn":495.5,"spf":"NaN","id":49159417}],"con":true,"img":true}]}
{"op":"mcm","clk":"11538595372","pt":1719464882536,"mc":[{"id":"1.230178317","marketDefinition":{"bspMarket":true,"turnInPlayEnabled":false,"persistenceEnabled":false,"marketBaseRate":5.0,"eventId":"33376062","eventTypeId":"4339","numberOfWinners":2,"bettingType":"ODDS","marketType":"PLACE","marketTime":"2024-06-27T15:09:00.000Z","suspendTime":"2024-06-27T15:09:00.000Z","bspReconciled":false,"complete":true,"inPlay":false,"crossMatching":false,"runnersVoidable":false,"numberOfActiveRunners":6,"betDelay":0,"status":"OPEN","runners":[{"status":"ACTIVE","sortPriority":1,"id":69685608,"name":"1. Spin It Danny"},{"status":"ACTIVE","sortPriority":2,"id":49159417,"name":"2. Derrymore Ella"},{"status":"ACTIVE","sortPriority":3,"id":57196226,"name":"3. Shrewd Cass"},{"status":"ACTIVE","sortPriority":4,"id":70902601,"name":"4. Fairy Hill John"},{"status":"ACTIVE","sortPriority":5,"id":52655636,"name":"5. Lady Quickstep"},{"status":"ACTIVE","sortPriority":6,"id":46611436,"name":"6. Curryhills Tiana"}],"regulators":["MR_INT"],"venue":"Kinsley","countryCode":"GB","discountAllowed":true,"timezone":"Europe/London","openDate":"2024-06-27T13:36:00.000Z","version":5994643765,"name":"To Be Placed","eventName":"Kinsley 27th Jun"},"rc":[{"atb":[[1.02,22.64]],"id":57196226},{"atl":[[990,0.26]],"id":57196226},{"spn":495.51,"spf":"NaN","id":57196226},{"atb":[[1.03,15.09]],"id":46611436},{"atl":[[1000,0.26]],"id":46611436},{"spn":500.51,"spf":"NaN","id":46611436},{"atb":[[1.03,15.09]],"id":52655636},{"atl":[[1000,0.26]],"id":52655636},{"spn":500.51,"spf":"NaN","id":52655636},{"atb":[[1.02,22.64]],"id":70902601},{"atl":[[990,0.26]],"id":70902601},{"spn":495.51,"spf":"NaN","id":70902601},{"atb":[[1.02,22.64]],"id":69685608},{"atl":[[1000,0.26]],"id":69685608},{"spn":500.51,"spf":"NaN","id":69685608},{"atb":[[1.01,45.29]],"id":49159417},{"atl":[[990,0.26]],"id":49159417},{"spn":495.5,"spf":"NaN","id":49159417}],"con":true,"img":true}]}
{"op":"mcm","clk":"11538905651","pt":1719471476903,"mc":[{"id":"1.230178317","rc":[{"atb":[[1.02,22.64]],"id":57196226},{"atl":[[990,0.16]],"id":57196226},{"atb":[[1.03,15.09]],"id":46611436},{"atl":[[1000,0.16]],"id":46611436},{"atb":[[1.03,15.09]],"id":52655636},{"atl":[[1000,0.16]],"id":52655636},{"atb":[[1.02,22.64]],"id":70902601},{"atl":[[990,0.16]],"id":70902601},{"atb":[[1.02,22.64]],"id":69685608},{"atl":[[1000,0.16]],"id":69685608},{"atb":[[1.01,45.29]],"id":49159417},{"atl":[[990,0.16]],"id":49159417}],"con":true,"img":false}]}
{"op":"mcm","clk":"11538907336","pt":1719471508775,"mc":[{"id":"1.230178317","rc":[{"atb":[[1.07,2.48]],"id":57196226},{"atb":[[1.07,2.48]],"id":46611436},{"atb":[[1.07,2.48]],"id":52655636},{"atb":[[1.07,2.48]],"id":70902601},{"atb":[[1.07,2.48]],"id":69685608},{"atb":[[1.07,2.48]],"id":49159417}],"con":true,"img":false}]}
{"op":"mcm","clk":"11538907355","pt":1719471509086,"mc":[{"id":"1.230178317","rc":[{"atl":[[1000,1]],"id":57196226},{"atl":[[1000,1.16]],"id":46611436},{"atl":[[1000,1.16]],"id":52655636},{"atl":[[1000,1]],"id":70902601},{"atl":[[1000,1.16]],"id":69685608},{"atl":[[1000,1]],"id":49159417}],"con":true,"img":false}]}
{"op":"mcm","clk":"11538907368","pt":1719471509292,"mc":[{"id":"1.230178317","rc":[{"atl":[[1000,0.48]],"id":57196226},{"atl":[[1000,0.64]],"id":46611436},{"atl":[[1000,0.64]],"id":52655636},{"atl":[[1000,0.48]],"id":70902601},{"atl":[[1000,0.64]],"id":69685608},{"atl":[[1000,0.48]],"id":49159417}],"con":true,"img":false}]}
{"op":"mcm","clk":"11538907381","pt":1719471509499,"mc":[{"id":"1.230178317","rc":[{"atl":[[1000,0]],"id":57196226},{"atl":[[1000,0.16]],"id":46611436},{"atl":[[1000,0.16]],"id":52655636},{"atl":[[1000,0]],"id":70902601},{"atl":[[1000,0.16]],"id":69685608},{"atl":[[1000,0]],"id":49159417}],"con":true,"img":false}]}
{"op":"mcm","clk":"11538907388","pt":1719471509554,"mc":[{"id":"1.230178317","rc":[{"atl":[[75,0.48]],"id":57196226},{"atl":[[75,0.48]],"id":46611436},{"atl":[[75,0.48]],"id":52655636},{"atl":[[75,0.48]],"id":70902601},{"atl":[[75,0.48]],"id":69685608},{"atl":[[75,0.48]],"id":49159417}],"con":true,"img":false}]}
{"op":"mcm","clk":"11539122519","pt":1719475682544,"mc":[{"id":"1.230178317","marketDefinition":{"bspMarket":true,"turnInPlayEnabled":false,"persistenceEnabled":false,"marketBaseRate":5.0,"eventId":"33376062","eventTypeId":"4339","numberOfWinners":2,"bettingType":"ODDS","marketType":"PLACE","marketTime":"2024-06-27T15:09:00.000Z","suspendTime":"2024-06-27T15:09:00.000Z","bspReconciled":false,"complete":true,"inPlay":false,"crossMatching":false,"runnersVoidable":false,"numberOfActiveRunners":6,"betDelay":0,"status":"OPEN","runners":[{"status":"ACTIVE","sortPriority":1,"id":69685608,"name":"1. Spin It Danny"},{"status":"ACTIVE","sortPriority":2,"id":49159417,"name":"2. Derrymore Ella"},{"status":"ACTIVE","sortPriority":3,"id":57196226,"name":"3. Shrewd Cass"},{"status":"ACTIVE","sortPriority":4,"id":70902601,"name":"4. Fairy Hill John"},{"status":"ACTIVE","sortPriority":5,"id":52655636,"name":"5. Lady Quickstep"},{"status":"ACTIVE","sortPriority":6,"id":46611436,"name":"6. Curryhills Tiana"}],"regulators":["MR_INT"],"venue":"Kinsley","countryCode":"GB","discountAllowed":true,"timezone":"Europe/London","openDate":"2024-06-27T13:36:00.000Z","version":5994643765,"name":"To Be Placed","eventName":"Kinsley 27th Jun"},"rc":[{"atb":[[1.02,22.64],[1.07,2.48]],"id":57196226},{"atl":[[75,0.48],[990,0.16]],"id":57196226},{"spn":38.03,"spf":"NaN","id":57196226},{"atb":[[1.03,15.09],[1.07,2.48]],"id":46611436},{"atl":[[75,0.48],[1000,0.16]],"id":46611436},{"spn":38.03,"spf":"NaN","id":46611436},{"atb":[[1.03,15.09],[1.07,2.48]],"id":52655636},{"atl":[[75,0.48],[1000,0.16]],"id":52655636},{"spn":38.03,"spf":"NaN","id":52655636},{"atb":[[1.02,22.64],[1.07,2.48]],"id":70902601},{"atl":[[75,0.48],[990,0.16]],"id":70902601},{"spn":38.03,"spf":"NaN","id":70902601},{"atb":[[1.02,22.64],[1.07,2.48]],"id":69685608},{"atl":[[75,0.48],[1000,0.16]],"id":69685608},{"spn":38.03,"spf":"NaN","id":69685608},{"atb":[[1.01,45.28],[1.07,2.48]],"id":49159417},{"atl":[[75,0.48],[990,0.16]],"id":49159417},{"spn":38.03,"spf":"NaN","id":49159417}],"con":true,"img":true}]}
{"op":"mcm","clk":"11539438495","pt":1719481082545,"mc":[{"id":"1.230178317","marketDefinition":{"bspMarket":true,"turnInPlayEnabled":false,"persistenceEnabled":false,"marketBaseRate":5.0,"eventId":"33376062","eventTypeId":"4339","numberOfWinners":2,"bettingType":"ODDS","marketType":"PLACE","marketTime":"2024-06-27T15:09:00.000Z","suspendTime":"2024-06-27T15:09:00.000Z","bspReconciled":false,"complete":true,"inPlay":false,"crossMatching":false,"runnersVoidable":false,"numberOfActiveRunners":6,"betDelay":0,"status":"OPEN","runners":[{"status":"ACTIVE","sortPriority":1,"id":69685608,"name":"1. Spin It Danny"},{"status":"ACTIVE","sortPriority":2,"id":49159417,"name":"2. Derrymore Ella"},{"status":"ACTIVE","sortPriority":3,"id":57196226,"name":"3. Shrewd Cass"},{"status":"ACTIVE","sortPriority":4,"id":70902601,"name":"4. Fairy Hill John"},{"status":"ACTIVE","sortPriority":5,"id":52655636,"name":"5. Lady Quickstep"},{"status":"ACTIVE","sortPriority":6,"id":46611436,"name":"6. Curryhills Tiana"}],"regulators":["MR_INT"],"venue":"Kinsley","countryCode":"GB","discountAllowed":true,"timezone":"Europe/London","openDate":"2024-06-27T13:36:00.000Z","version":5994643765,"name":"To Be Placed","eventName":"Kinsley 27th Jun"},"rc":[{"atb":[[1.02,22.63],[1.07,2.48]],"id":57196226},{"atl":[[75,0.48],[990,0.16]],"id":57196226},{"spn":38.03,"spf":"NaN","id":57196226},{"atb":[[1.03,15.09],[1.07,2.48]],"id":46611436},{"atl":[[75,0.48],[1000,0.16]],"id":46611436},{"spn":38.03,"spf":"NaN","id":46611436},{"atb":[[1.03,15.09],[1.07,2.48]],"id":52655636},{"atl":[[75,0.48],[1000,0.16]],"id":52655636},{"spn":38.03,"spf":"NaN","id":52655636},{"atb":[[1.02,22.63],[1.07,2.48]],"id":70902601},{"atl":[[75,0.48],[990,0.16]],"id":70902601},{"spn":38.03,"spf":"NaN","id":70902601},{"atb":[[1.02,22.63],[1.07,2.48]],"id":69685608},{"atl":[[75,0.48],[1000,0.16]],"id":69685608},{"spn":38.03,"spf":"NaN","id":69685608},{"atb":[[1.01,45.27],[1.07,2.48]],"id":49159417},{"atl":[[75,0.48],[990,0.16]],"id":49159417},{"spn":38.03,"spf":"NaN","id":49159417}],"con":true,"img":true}]}
{"op":"mcm","clk":"11540334893","pt":1719493169188,"mc":[{"id":"1.230178317","rc":[{"atb":[[1.02,22.63]],"id":57196226},{"atl":[[960,1.61]],"id":57196226},{"spn":38.03,"spf":"NaN","id":57196226},{"atb":[[1.03,15.09]],"id":46611436},{"atl":[[970,1.24]],"id":46611436},{"spn":38.03,"spf":"NaN","id":46611436},{"atb":[[1.03,15.09]],"id":52655636},{"atl":[[990,0.84]],"id":52655636},{"spn":38.03,"spf":"NaN","id":52655636},{"atb":[[1.02,22.63]],"id":70902601},{"atl":[[990,2.01]],"id":70902601},{"spn":38.03,"spf":"NaN","id":70902601},{"atb":[[1.02,22.63]],"id":69685608},{"atl":[[970,1.16]],"id":69685608},{"spn":38.03,"spf":"NaN","id":69685608},{"atb":[[1.01,45.27]],"id":49159417},{"atl":[[980,2.1]],"id":49159417},{"spn":38.03,"spf":"NaN","id":49159417}],"con":true,"img":false}]}
{"op":"mcm","clk":"11540683330","pt":1719497282513,"mc":[{"id":"1.230178317","marketDefinition":{"bspMarket":true,"turnInPlayEnabled":false,"persistenceEnabled":false,"marketBaseRate":5.0,"eventId":"33376062","eventTypeId":"4339","numberOfWinners":2,"bettingType":"ODDS","marketType":"PLACE","marketTime":"2024-06-27T15:09:00.000Z","suspendTime":"2024-06-27T15:09:00.000Z","bspReconciled":false,"complete":true,"inPlay":false,"crossMatching":false,"runnersVoidable":false,"numberOfActiveRunners":6,"betDelay":0,"status":"OPEN","runners":[{"status":"ACTIVE","sortPriority":1,"id":69685608,"name":"1. Spin It Danny"},{"status":"ACTIVE","sortPriority":2,"id":49159417,"name":"2. Derrymore Ella"},{"status":"ACTIVE","sortPriority":3,"id":57196226,"name":"3. Shrewd Cass"},{"status":"ACTIVE","sortPriority":4,"id":70902601,"name":"4. Fairy Hill John"},{"status":"ACTIVE","sortPriority":5,"id":52655636,"name":"5. Lady Quickstep"},{"status":"ACTIVE","sortPriority":6,"id":46611436,"name":"6. Curryhills Tiana"}],"regulators":["MR_INT"],"venue":"Kinsley","countryCode":"GB","discountAllowed":true,"timezone":"Europe/London","openDate":"2024-06-27T13:36:00.000Z","version":5994643765,"name":"To Be Placed","eventName":"Kinsley 27th Jun"},"rc":[{"atb":[[1.02,22.65],[1.07,2.48]],"id":57196226},{"atl":[[75,0.48],[960,1.61],[990,0.16]],"id":57196226},{"spn":38.03,"spf":"NaN","id":57196226},{"atb":[[1.03,15.1],[1.07,2.48]],"id":46611436},{"atl":[[75,0.48],[970,1.24],[1000,0.16]],"id":46611436},{"spn":38.03,"spf":"NaN","id":46611436},{"atb":[[1.03,15.1],[1.07,2.48]],"id":52655636},{"atl":[[75,0.48],[990,0.84],[1000,0.16]],"id":52655636},{"spn":38.03,"spf":"NaN","id":52655636},{"atb":[[1.02,22.65],[1.07,2.48]],"id":70902601},{"atl":[[75,0.48],[990,2.01]],"id":70902601},{"spn":38.03,"spf":"NaN","id":70902601},{"atb":[[1.02,22.65],[1.07,2.48]],"id":69685608},{"atl":[[75,0.48],[970,1.16],[1000,0.16]],"id":69685608},{"spn":38.03,"spf":"NaN","id":69685608},{"atb":[[1.01,45.3],[1.07,2.48]],"id":49159417},{"atl":[[75,0.48],[980,2.1],[990,0.16]],"id":49159417},{"spn":38.03,"spf":"NaN","id":49159417}],"con":true,"img":true}]}
{"op":"mcm","clk":"11540828590","pt":1719498843091,"mc":[{"id":"1.230178317","rc":[{"atb":[[1.02,22.65],[1.04,1]],"id":57196226},{"atl":[[960,1.61],[990,0.16]],"id":57196226},{"atb":[[1.03,15.1],[1.04,1]],"id":46611436},{"atl":[[970,1.24],[1000,0.16]],"id":46611436},{"atb":[[1.03,15.1],[1.04,1]],"id":52655636},{"atl":[[990,0.84],[1000,0.16]],"id":52655636},{"atb":[[1.02,22.65],[1.04,1]],"id":70902601},{"atl":[[990,2.01]],"id":70902601},{"atb":[[1.02,22.65],[1.04,1]],"id":69685608},{"atl":[[970,1.16],[1000,0.16]],"id":69685608},{"atb":[[1.01,45.3],[1.04,1]],"id":49159417},{"atl":[[980,2.1],[990,0.16]],"id":49159417}],"con":true,"img":false}]}
{"op":"mcm","clk":"11540828613","pt":1719498843264,"mc":[{"id":"1.230178317","rc":[{"atb":[[1.04,0.25]],"id":57196226},{"atb":[[1.04,0.25]],"id":46611436},{"atb":[[1.04,0.25]],"id":52655636},{"atb":[[1.04,0.25]],"id":70902601},{"atb":[[1.04,0.25]],"id":69685608},{"atb":[[1.04,0.25]],"id":49159417}],"con":true,"img":false}]}
{"op":"mcm","clk":"11540828624","pt":1719498843466,"mc":[{"id":"1.230178317","rc":[{"atb":[[1.04,0]],"id":57196226},{"atb":[[1.04,0]],"id":46611436},{"atb":[[1.04,0]],"id":52655636},{"atb":[[1.04,0]],"id":70902601},{"atb":[[1.04,0]],"id":69685608},{"atb":[[1.04,0]],"id":49159417}],"con":true,"img":false}]}
{"op":"mcm","clk":"11540828634","pt":1719498843571,"mc":[{"id":"1.230178317","rc":[{"atb":[[1.2,0.25]],"id":57196226},{"atb":[[1.2,0.25]],"id":46611436},{"atb":[[1.2,0.25]],"id":52655636},{"atb":[[1.2,0.25]],"id":70902601},{"atb":[[1.2,0.25]],"id":69685608},{"atb":[[1.2,0.25]],"id":49159417}],"con":true,"img":false}]}
{"op":"mcm","clk":"11540856192","pt":1719499176418,"mc":[{"id":"1.230178317","rc":[{"atb":[[1.09,43.87]],"id":57196226},{"spn":38.1,"spf":"NaN","id":57196226},{"spn":38.1,"spf":"NaN","id":46611436},{"atb":[[1.09,43.87]],"id":52655636},{"spn":38.1,"spf":"NaN","id":52655636},{"spn":38.1,"spf":"NaN","id":70902601},{"spn":38.1,"spf":"NaN","id":69685608},{"spn":38.1,"spf":"NaN","id":49159417}],"con":true,"img":false}]}
{"op":"mcm","clk":"11540856612","pt":1719499182165,"mc":[{"id":"1.230178317","marketDefinition":{"bspMarket":true,"turnInPlayEnabled":false,"persistenceEnabled":false,"marketBaseRate":5.0,"eventId":"33376062","eventTypeId":"4339","numberOfWinners":2,"bettingType":"ODDS","marketType":"PLACE","marketTime":"2024-06-27T15:09:00.000Z","suspendTime":"2024-06-27T15:09:00.000Z","bspReconciled":false,"complete":true,"inPlay":false,"crossMatching":true,"runnersVoidable":false,"numberOfActiveRunners":6,"betDelay":0,"status":"OPEN","runners":[{"status":"ACTIVE","sortPriority":1,"id":69685608,"name":"1. Spin It Danny"},{"status":"ACTIVE","sortPriority":2,"id":49159417,"name":"2. Derrymore Ella"},{"status":"ACTIVE","sortPriority":3,"id":57196226,"name":"3. Shrewd Cass"},{"status":"ACTIVE","sortPriority":4,"id":70902601,"name":"4. Fairy Hill John"},{"status":"ACTIVE","sortPriority":5,"id":52655636,"name":"5. Lady Quickstep"},{"status":"ACTIVE","sortPriority":6,"id":46611436,"name":"6. Curryhills Tiana"}],"regulators":["MR_INT"],"venue":"Kinsley","countryCode":"GB","discountAllowed":true,"timezone":"Europe/London","openDate":"2024-06-27T13:36:00.000Z","version":5994643765,"name":"To Be Placed","eventName":"Kinsley 27th Jun"},"rc":[],"con":true,"img":false}]}
{"op":"mcm","clk":"11540875962","pt":1719499431168,"mc":[{"id":"1.230178317","rc":[{"atb":[[1.11,38.47]],"id":57196226}],"con":true,"img":false}]}
{"op":"mcm","clk":"11540875973","pt":1719499431376,"mc":[{"id":"1.230178317","rc":[{"atb":[[1.11,38.47]],"id":52655636}],"con":true,"img":false}]}
{"op":"mcm","clk":"11540876286","pt":1719499435700,"mc":[{"id":"1.230178317","rc":[{"atb":[[1.09,0]],"id":57196226},{"atb":[[1.09,0]],"id":52655636}],"con":true,"img":false}]}
{"op":"mcm","clk":"11540876328","pt":1719499436168,"mc":[{"id":"1.230178317","rc":[{"atb":[[1.13,30.37]],"id":52655636}],"con":true,"img":false}]}
{"op":"mcm","clk":"11540876351","pt":1719499436479,"mc":[{"id":"1.230178317","rc":[{"atb":[[1.13,30.37]],"id":57196226}],"con":true,"img":false}]}
{"op":"mcm","clk":"11540878640","pt":1719499466395,"mc":[{"id":"1.230178317","rc":[{"atb":[[1.11,0]],"id":52655636}],"con":true,"img":false}]}
{"op":"mcm","clk":"11540878717","pt":1719499467382,"mc":[{"id":"1.230178317","rc":[{"atb":[[1.11,0]],"id":57196226},{"atb":[[1.15,28.21]],"id":52655636}],"con":true,"img":false}]}
{"op":"mcm","clk":"11540878805","pt":1719499468523,"mc":[{"id":"1.230178317","rc":[{"atb":[[1.15,28.21]],"id":57196226}],"con":true,"img":false}]}
{"op":"mcm","clk":"11540879118","pt":1719499472415,"mc":[{"id":"1.230178317","rc":[{"atb":[[1.13,0]],"id":57196226}],"con":true,"img":false}]}
{"op":"mcm","clk":"11540879192","pt":1719499473397,"mc":[{"id":"1.230178317","rc":[{"atb":[[1.17,23.22]],"id":57196226}],"con":true,"img":false}]}
{"op":"mcm","clk":"11540879213","pt":1719499473707,"mc":[{"id":"1.230178317","rc":[{"atb":[[1.13,0]],"id":52655636}],"con":true,"img":false}]}
{"op":"mcm","clk":"11540879249","pt":1719499474125,"mc":[{"id":"1.230178317","rc":[{"atb":[[1.17,23.22]],"id":52655636}],"con":true,"img":false}]}
{"op":"mcm","clk":"11540882090","pt":1719499506929,"mc":[{"id":"1.230178317","rc":[{"atb":[[1.15,0]],"id":57196226}],"con":true,"img":false}]}
{"op":"mcm","clk":"11540882139","pt":1719499507553,"mc":[{"id":"1.230178317","rc":[{"atb":[[1.19,22.28]],"id":57196226}],"con":true,"img":false}]}
{"op":"mcm","clk":"11540882169","pt":1719499507918,"mc":[{"id":"1.230178317","rc":[{"atb":[[1.15,0]],"id":52655636}],"con":true,"img":false}]}
{"op":"mcm","clk":"11540882247","pt":1719499508849,"mc":[{"id":"1.230178317","rc":[{"atb":[[1.19,22.28]],"id":52655636}],"con":true,"img":false}]}
{"op":"mcm","clk":"11540883811","pt":1719499529050,"mc":[{"id":"1.230178317","rc":[{"atb":[[1.17,0]],"id":57196226},{"atb":[[1.17,0]],"id":52655636}],"con":true,"img":false}]}
{"op":"mcm","clk":"11540883856","pt":1719499529658,"mc":[{"id":"1.230178317","rc":[{"atb":[[1.21,18.8]],"id":52655636}],"con":true,"img":false}]}
{"op":"mcm","clk":"11540883864","pt":1719499529762,"mc":[{"id":"1.230178317","rc":[{"atb":[[1.21,18.8]],"id":57196226}],"con":true,"img":false}]}
{"op":"mcm","clk":"11540884946","pt":1719499545696,"mc":[{"id":"1.230178317","rc":[{"atb":[[1.19,0]],"id":52655636}],"con":true,"img":false}]}
{"op":"mcm","clk":"11540884988","pt":1719499546471,"mc":[{"id":"1.230178317","rc":[{"atb":[[1.23,18.4]],"id":52655636}],"con":true,"img":false}]}
{"op":"mcm","clk":"11540885042","pt":1719499547402,"mc":[{"id":"1.230178317","rc":[{"atb":[[1.19,0]],"id":57196226}],"con":true,"img":false}]}
{"op":"mcm","clk":"11540885073","pt":1719499547868,"mc":[{"id":"1.230178317","rc":[{"atb":[[1.23,18.4]],"id":57196226}],"con":true,"img":false}]}
{"op":"mcm","clk":"11540885119","pt":1719499548693,"mc":[{"id":"1.230178317","rc":[{"atb":[[1.21,0]],"id":57196226}],"con":true,"img":false}]}
{"op":"mcm","clk":"11540885132","pt":1719499548900,"mc":[{"id":"1.230178317","rc":[{"atb":[[1.25,15.79]],"id":57196226}],"con":true,"img":false}]}
{"op":"mcm","clk":"11540885153","pt":1719499549211,"mc":[{"id":"1.230178317","rc":[{"atb":[[1.21,0]],"id":52655636}],"con":true,"img":false}]}
{"op":"mcm","clk":"11540885170","pt":1719499549380,"mc":[{"id":"1.230178317","rc":[{"atb":[[1.25,15.79]],"id":52655636}],"con":true,"img":false}]}
{"op":"mcm","clk":"11540887802","pt":1719499585834,"mc":[{"id":"1.230178317","rc":[{"atb":[[1.23,0]],"id":57196226},{"spn":38.12,"spf":"NaN","id":57196226},{"spn":38.12,"spf":"NaN","id":52655636}],"con":true,"img":false}]}
{"op":"mcm","clk":"11540887848","pt":1719499586511,"mc":[{"id":"1.230178317","rc":[{"atb":[[1.23,0]],"id":52655636}],"con":true,"img":false}]}
{"op":"mcm","clk":"11540887898","pt":1719499587335,"mc":[{"id":"1.230178317","rc":[{"atb":[[1.27,15.67]],"id":57196226}],"con":true,"img":false}]}
{"op":"mcm","clk":"11540887934","pt":1719499587802,"mc":[{"id":"1.230178317","rc":[{"atb":[[1.27,15.67]],"id":52655636}],"con":true,"img":false}]}
{"op":"mcm","clk":"11540889027","pt":1719499603334,"mc":[{"id":"1.230178317","rc":[{"atb":[[1.25,0]],"id":57196226}],"con":true,"img":false}]}
{"op":"mcm","clk":"11540889056","pt":1719499603635,"mc":[{"id":"1.230178317","rc":[{"atb":[[1.25,0]],"id":52655636}],"con":true,"img":false}]}
{"op":"mcm","clk":"11540889073","pt":1719499603842,"mc":[{"id":"1.230178317","rc":[{"atb":[[1.29,13.61]],"id":57196226}],"con":true,"img":false}]}
{"op":"mcm","clk":"11540889102","pt":1719499604254,"mc":[{"id":"1.230178317","rc":[{"atb":[[1.29,13.61]],"id":52655636}],"con":true,"img":false}]}
{"op":"mcm","clk":"11540890727","pt":1719499625086,"mc":[{"id":"1.230178317","rc":[{"atb":[[1.27,0]],"id":52655636}],"con":true,"img":false}]}
{"op":"mcm","clk":"11540890735","pt":1719499625189,"mc":[{"id":"1.230178317","rc":[{"atb":[[1.27,0]],"id":57196226}],"con":true,"img":false}]}
{"op":"mcm","clk":"11540890807","pt":1719499626273,"mc":[{"id":"1.230178317","rc":[{"atb":[[1.31,13.65]],"id":52655636}],"con":true,"img":false}]}
{"op":"mcm","clk":"11540890862","pt":1719499627160,"mc":[{"id":"1.230178317","rc":[{"atb":[[1.31,13.65]],"id":57196226}],"con":true,"img":false}]}
{"op":"mcm","clk":"11540891850","pt":1719499639299,"mc":[{"id":"1.230178317","rc":[{"atb":[[1.29,0]],"id":57196226}],"con":true,"img":false}]}
{"op":"mcm","clk":"11540891871","pt":1719499639571,"mc":[{"id":"1.230178317","rc":[{"atb":[[1.29,0]],"id":52655636}],"con":true,"img":false}]}
{"op":"mcm","clk":"11540891886","pt":1719499639774,"mc":[{"id":"1.230178317","rc":[{"atb":[[1.33,11.96]],"id":57196226}],"con":true,"img":false}]}
{"op":"mcm","clk":"11540891920","pt":1719499640193,"mc":[{"id":"1.230178317","rc":[{"atb":[[1.33,11.96]],"id":52655636}],"con":true,"img":false}]}
{"op":"mcm","clk":"11540893876","pt":1719499664792,"mc":[{"id":"1.230178317","rc":[{"atb":[[1.31,0]],"id":57196226},{"spn":38.16,"spf":"NaN","id":57196226},{"spn":38.16,"spf":"NaN","id":52655636}],"con":true,"img":false}]}
{"op":"mcm","clk":"11540893936","pt":1719499665613,"mc":[{"id":"1.230178317","rc":[{"atb":[[1.31,0]],"id":52655636}],"con":true,"img":false}]}
{"op":"mcm","clk":"11540893959","pt":1719499665917,"mc":[{"id":"1.230178317","rc":[{"atb":[[1.35,12.09]],"id":57196226}],"con":true,"img":false}]}
{"op":"mcm","clk":"11540893977","pt":1719499666078,"mc":[{"id":"1.230178317","rc":[{"atb":[[1.35,12.09]],"id":52655636}],"con":true,"img":false}]}
{"op":"mcm","clk":"11540894809","pt":1719499676827,"mc":[{"id":"1.230178317","rc":[{"atb":[[1.33,0]],"id":57196226}],"con":true,"img":false}]}
{"op":"mcm","clk":"11540894830","pt":1719499677132,"mc":[{"id":"1.230178317","rc":[{"atb":[[1.33,0]],"id":52655636}],"con":true,"img":false}]}
{"op":"mcm","clk":"11540894863","pt":1719499677599,"mc":[{"id":"1.230178317","rc":[{"atb":[[1.37,10.66]],"id":57196226}],"con":true,"img":false}]}
{"op":"mcm","clk":"11540894876","pt":1719499677805,"mc":[{"id":"1.230178317","rc":[{"atb":[[1.37,10.66]],"id":52655636}],"con":true,"img":false}]}
{"op":"mcm","clk":"11540894994","pt":1719499679192,"mc":[{"id":"1.230178317","rc":[{"atb":[[1.28,2]],"id":52655636}],"con":true,"img":false}]}
{"op":"mcm","clk":"11540895088","pt":1719499680230,"mc":[{"id":"1.230178317","rc":[{"atb":[[1.28,0]],"id":52655636}],"con":true,"img":false}]}
{"op":"mcm","clk":"11540897015","pt":1719499701549,"mc":[{"id":"1.230178317","rc":[{"atb":[[1.35,0]],"id":52655636}],"con":true,"img":false}]}
{"op":"mcm","clk":"11540897044","pt":1719499701929,"mc":[{"id":"1.230178317","rc":[{"atb":[[1.35,0]],"id":57196226}],"con":true,"img":false}]}
{"op":"mcm","clk":"11540897053","pt":1719499702037,"mc":[{"id":"1.230178317","rc":[{"atb":[[1.39,10.85]],"id":52655636}],"con":true,"img":false}]}
{"op":"mcm","clk":"11540897098","pt":1719499702549,"mc":[{"id":"1.230178317","rc":[{"atb":[[1.39,10.85]],"id":57196226}],"con":true,"img":false}]}
{"op":"mcm","clk":"11540898227","pt":1719499715283,"mc":[{"id":"1.230178317","rc":[{"atb":[[1.37,0]],"id":57196226},{"atb":[[1.37,0]],"id":52655636}],"con":true,"img":false}]}
{"op":"mcm","clk":"11540898264","pt":1719499715650,"mc":[{"id":"1.230178317","rc":[{"atb":[[1.41,9.63]],"id":57196226}],"con":true,"img":false}]}
{"op":"mcm","clk":"11540898271","pt":1719499715749,"mc":[{"id":"1.230178317","rc":[{"atb":[[1.41,9.63]],"id":52655636}],"con":true,"img":false}]}
{"op":"mcm","clk":"11540900310","pt":1719499739382,"mc":[{"id":"1.230178317","rc":[{"atb":[[1.39,0]],"id":57196226},{"spn":38.2,"spf":"NaN","id":57196226},{"spn":38.2,"spf":"NaN","id":52655636}],"con":true,"img":false}]}
{"op":"mcm","clk":"11540900324","pt":1719499739588,"mc":[{"id":"1.230178317","rc":[{"atb":[[1.39,0]],"id":52655636}],"con":true,"img":false}]}
{"op":"mcm","clk":"11540900331","pt":1719499739692,"mc":[{"id":"1.230178317","rc":[{"atb":[[1.43,9.84]],"id":57196226}],"con":true,"img":false}]}
{"op":"mcm","clk":"11540900366","pt":1719499740208,"mc":[{"id":"1.230178317","rc":[{"atb":[[1.43,9.84]],"id":52655636}],"con":true,"img":false}]}
{"op":"mcm","clk":"11540900512","pt":1719499741813,"mc":[{"id":"1.230178317","rc":[{"atb":[[1.44,2.11]],"id":57196226},{"atb":[[1.44,2.11]],"id":52655636}],"con":true,"img":false}]}
{"op":"mcm","clk":"11540901236","pt":1719499749580,"mc":[{"id":"1.230178317","rc":[{"atb":[[1.41,0]],"id":57196226}],"con":true,"img":false}]}
{"op":"mcm","clk":"11540901253","pt":1719499749785,"mc":[{"id":"1.230178317","rc":[{"atb":[[1.46,8.58]],"id":57196226},{"atb":[[1.41,0]],"id":52655636}],"con":true,"img":false}]}
{"op":"mcm","clk":"11540901272","pt":1719499749991,"mc":[{"id":"1.230178317","rc":[{"atb":[[1.46,8.58]],"id":52655636}],"con":true,"img":false}]}
{"op":"mcm","clk":"11540903688","pt":1719499778700,"mc":[{"id":"1.230178317","rc":[{"atb":[[1.43,0]],"id":57196226}],"con":true,"img":false}]}
{"op":"mcm","clk":"11540903741","pt":1719499779421,"mc":[{"id":"1.230178317","rc":[{"atb":[[1.43,0]],"id":52655636}],"con":true,"img":false}]}
{"op":"mcm","clk":"11540903767","pt":1719499779731,"mc":[{"id":"1.230178317","rc":[{"atb":[[1.48,8.82]],"id":57196226}],"con":true,"img":false}]}
{"op":"mcm","clk":"11540903812","pt":1719499780351,"mc":[{"id":"1.230178317","rc":[{"atb":[[1.48,8.82]],"id":52655636}],"con":true,"img":false}]}
{"op":"mcm","clk":"11540904459","pt":1719499787415,"mc":[{"id":"1.230178317","rc":[{"atb":[[1.46,0]],"id":52655636}],"con":true,"img":false}]}
{"op":"mcm","clk":"11540904471","pt":1719499787519,"mc":[{"id":"1.230178317","rc":[{"atb":[[1.46,0]],"id":57196226}],"con":true,"img":false}]}
{"op":"mcm","clk":"11540904511","pt":1719499787933,"mc":[{"id":"1.230178317","rc":[{"atb":[[1.5,7.89]],"id":52655636}],"con":true,"img":false}]}
{"op":"mcm","clk":"11540904551","pt":1719499788347,"mc":[{"id":"1.230178317","rc":[{"atb":[[1.5,7.89]],"id":57196226}],"con":true,"img":false}]}
{"op":"mcm","clk":"11540907058","pt":1719499816957,"mc":[{"id":"1.230178317","rc":[{"spn":38.25,"spf":"NaN","id":57196226},{"atb":[[1.48,0]],"id":52655636},{"spn":38.25,"spf":"NaN","id":52655636}],"con":true,"img":false}]}
{"op":"mcm","clk":"11540907144","pt":1719499817883,"mc":[{"id":"1.230178317","rc":[{"atb":[[1.52,8.14]],"id":52655636}],"con":true,"img":false}]}
{"op":"mcm","clk":"11540907181","pt":1719499818255,"mc":[{"id":"1.230178317","rc":[{"atb":[[1.48,0]],"id":57196226}],"con":true,"img":false}]}
{"op":"mcm","clk":"11540907225","pt":1719499818759,"mc":[{"id":"1.230178317","rc":[{"atb":[[1.52,8.14]],"id":57196226}],"con":true,"img":false}]}
{"op":"mcm","clk":"11540907975","pt":1719499826758,"mc":[{"id":"1.230178317","rc":[{"atb":[[1.5,0]],"id":52655636}],"con":true,"img":false}]}
{"op":"mcm","clk":"11540907987","pt":1719499826863,"mc":[{"id":"1.230178317","rc":[{"atb":[[1.5,0]],"id":57196226}],"con":true,"img":false}]}
{"op":"mcm","clk":"11540908057","pt":1719499827676,"mc":[{"id":"1.230178317","rc":[{"atb":[[1.54,7.31]],"id":57196226},{"atb":[[1.54,7.31]],"id":52655636}],"con":true,"img":false}]}
{"op":"mcm","clk":"11540910415","pt":1719499855139,"mc":[{"id":"1.230178317","rc":[{"atb":[[1.52,0]],"id":57196226}],"con":true,"img":false}]}
{"op":"mcm","clk":"11540910468","pt":1719499855709,"mc":[{"id":"1.230178317","rc":[{"atb":[[1.52,0]],"id":52655636}],"con":true,"img":false}]}
{"op":"mcm","clk":"11540910519","pt":1719499856430,"mc":[{"id":"1.230178317","rc":[{"atb":[[1.56,7.56]],"id":57196226}],"con":true,"img":false}]}
{"op":"mcm","clk":"11540910530","pt":1719499856635,"mc":[{"id":"1.230178317","rc":[{"atb":[[1.56,7.56]],"id":52655636}],"con":true,"img":false}]}
{"op":"mcm","clk":"11540910979","pt":1719499862536,"mc":[{"id":"1.230178317","rc":[{"atb":[[1.54,0]],"id":52655636}],"con":true,"img":false}]}
{"op":"mcm","clk":"11540910991","pt":1719499862641,"mc":[{"id":"1.230178317","rc":[{"atb":[[1.54,0]],"id":57196226}],"con":true,"img":false}]}
{"op":"mcm","clk":"11540911056","pt":1719499863208,"mc":[{"id":"1.230178317","rc":[{"atb":[[1.58,6.8]],"id":52655636}],"con":true,"img":false}]}
{"op":"mcm","clk":"11540911066","pt":1719499863311,"mc":[{"id":"1.230178317","rc":[{"atb":[[1.58,6.8]],"id":57196226}],"con":true,"img":false}]}
{"op":"mcm","clk":"11540913533","pt":1719499893267,"mc":[{"id":"1.230178317","rc":[{"atb":[[1.56,0]],"id":57196226},{"spn":38.29,"spf":"NaN","id":57196226},{"spn":38.29,"spf":"NaN","id":52655636}],"con":true,"img":false}]}
{"op":"mcm","clk":"11540913618","pt":1719499894145,"mc":[{"id":"1.230178317","rc":[{"atb":[[1.6,7.05]],"id":57196226}],"con":true,"img":false}]}
{"op":"mcm","clk":"11540913630","pt":1719499894350,"mc":[{"id":"1.230178317","rc":[{"atb":[[1.56,0]],"id":52655636}],"con":true,"img":false}]}
{"op":"mcm","clk":"11540913677","pt":1719499894865,"mc":[{"id":"1.230178317","rc":[{"atb":[[1.6,7.05]],"id":52655636}],"con":true,"img":false}]}
{"op":"mcm","clk":"11540914067","pt":1719499899770,"mc":[{"id":"1.230178317","rc":[{"atb":[[1.58,0]],"id":57196226},{"atb":[[1.58,0]],"id":52655636}],"con":true,"img":false}]}
{"op":"mcm","clk":"11540914103","pt":1719499900182,"mc":[{"id":"1.230178317","rc":[{"atb":[[1.62,6.36]],"id":57196226}],"con":true,"img":false}]}
{"op":"mcm","clk":"11540914123","pt":1719499900389,"mc":[{"id":"1.230178317","rc":[{"atb":[[1.62,6.36]],"id":52655636}],"con":true,"img":false}]}
{"op":"mcm","clk":"11540924894","pt":1719500040200,"mc":[{"id":"1.230178317","rc":[{"spn":38.31,"spf":"NaN","id":57196226},{"spn":38.31,"spf":"NaN","id":52655636},{"atb":[[1.26,2.48]],"id":70902601},{"atl":[[6.8,2]],"id":70902601},{"spn":4.03,"spf":"NaN","id":70902601}],"con":true,"img":false}]}
{"op":"mcm","clk":"11540924904","pt":1719500040321,"mc":[{"id":"1.230178317","rc":[{"atb":[[1.44,15.53]],"id":57196226},{"atl":[[5.7,2]],"id":57196226},{"atb":[[1.6,2.48]],"id":46611436},{"atl":[[12.5,2]],"id":46611436},{"atb":[[1.63,6.37]],"id":52655636},{"atl":[[12,2]],"id":52655636},{"atb":[[1.82,2.48]],"id":69685608},{"atl":[[26,2]],"id":69685608},{"atb":[[1.69,2.48]],"id":49159417},{"atl":[[17.5,2]],"id":49159417}],"con":true,"img":false}]}
{"op":"mcm","clk":"11540924915","pt":1719500040425,"mc":[{"id":"1.230178317","rc":[{"atl":[[3.75,1]],"id":57196226},{"atb":[[1.97,1]],"id":46611436},{"atl":[[5.5,1]],"id":46611436},{"atb":[[2.24,1]],"id":52655636},{"atl":[[6.8,1]],"id":52655636},{"atb":[[1.74,1]],"id":70902601},{"atl":[[5,1]],"id":70902601},{"atb":[[1.92,1]],"id":69685608},{"atl":[[6.2,1]],"id":69685608},{"atb":[[1.97,1]],"id":49159417},{"atl":[[5.3,1]],"id":49159417}],"con":true,"img":false}]}
{"op":"mcm","clk":"11540925364","pt":1719500046101,"mc":[{"id":"1.230178317","rc":[{"atb":[[1.01,1.7]],"id":57196226},{"atl":[[1000,1.7]],"id":57196226},{"atb":[[1.01,1.7]],"id":69685608},{"atl":[[1000,1.87]],"id":69685608},{"atb":[[1.01,47.01]],"id":49159417},{"atl":[[1000,1.7]],"id":49159417}],"con":true,"img":false}]}
{"op":"mcm","clk":"11540925382","pt":1719500046306,"mc":[{"id":"1.230178317","rc":[{"atb":[[1.01,0.5]],"id":57196226},{"atl":[[1000,0.06]],"id":57196226},{"atb":[[1.01,0.38]],"id":69685608},{"atl":[[1000,0.18]],"id":69685608},{"atb":[[1.01,45.76]],"id":49159417},{"atl":[[1000,0.02]],"id":49159417}],"con":true,"img":false}]}
{"op":"mcm","clk":"11540925404","pt":1719500046616,"mc":[{"id":"1.230178317","rc":[{"atb":[[1.01,0]],"id":57196226},{"atl":[[1000,0]],"id":57196226},{"atb":[[1.01,0]],"id":69685608},{"atl":[[1000,0.16]],"id":69685608},{"atb":[[1.01,45.3]],"id":49159417},{"atl":[[1000,0]],"id":49159417}],"con":true,"img":false}]}
{"op":"mcm","clk":"11540925412","pt":1719500046719,"mc":[{"id":"1.230178317","rc":[{"atb":[[1.63,0.5]],"id":57196226},{"atl":[[5.6,0.06]],"id":57196226},{"atb":[[1.83,0.38]],"id":69685608},{"atl":[[25,0.01]],"id":69685608},{"atb":[[1.7,0.45]],"id":49159417},{"atl":[[17,0.02]],"id":49159417}],"con":true,"img":false}]}
{"op":"mcm","clk":"11540926291","pt":1719500057453,"mc":[{"id":"1.230178317","rc":[{"atl":[[3.75,0],[3.65,1]],"id":57196226},{"atb":[[1.6,0],[2.02,1]],"id":46611436},{"atl":[[5.5,0],[12.5,0]],"id":46611436},{"atl":[[17.5,3]],"id":52655636},{"atl":[[4.8,1]],"id":70902601},{"atb":[[1.79,2],[1.97,0]],"id":49159417},{"atl":[[5.3,0]],"id":49159417}],"con":true,"img":false}]}
{"op":"mcm","clk":"11540926300","pt":1719500057556,"mc":[{"id":"1.230178317","rc":[{"atb":[[1.44,2.11],[1.52,12.74]],"id":57196226},{"atl":[[3.35,1]],"id":57196226},{"atb":[[1.97,0],[1.67,2.48]],"id":46611436},{"atl":[[17.5,3],[5.1,1],[5.3,1]],"id":46611436},{"atb":[[1.63,0],[1.7,6.37]],"id":52655636},{"atl":[[6.4,1],[6.8,0],[12,0],[5.7,1]],"id":52655636},{"atb":[[1.26,0],[1.35,2.48]],"id":70902601},{"atl":[[5,0],[6.8,0],[4.2,1],[9.4,3]],"id":70902601},{"atb":[[1.82,0],[1.92,0],[2.32,1],[1.94,2]],"id":69685608},{"atl":[[6.2,0],[6.8,1]],"id":69685608},{"atb":[[2.02,1],[1.69,0]],"id":49159417},{"atl":[[5.1,1]],"id":49159417}],"con":true,"img":false}]}
{"op":"mcm","clk":"11540926309","pt":1719500057659,"mc":[{"id":"1.230178317","rc":[{"atl":[[3.65,0]],"id":57196226},{"atl":[[4.8,0]],"id":70902601}],"con":true,"img":false}]}
{"op":"mcm","clk":"11540926320","pt":1719500057762,"mc":[{"id":"1.230178317","rc":[{"atl":[[5.3,0]],"id":46611436},{"atl":[[6.4,0]],"id":52655636},{"atb":[[2.12,2],[1.94,0]],"id":69685608}],"con":true,"img":false}]}
{"op":"mcm","clk":"11540926824","pt":1719500064140,"mc":[{"id":"1.230178317","rc":[{"atb":[[1.92,1],[2.32,0]],"id":69685608}],"con":true,"img":false}]}
{"op":"mcm","clk":"11540926881","pt":1719500064962,"mc":[{"id":"1.230178317","rc":[{"atb":[[1.92,0],[2.32,1]],"id":69685608}],"con":true,"img":false}]}
{"op":"mcm","clk":"11540927084","pt":1719500067554,"mc":[{"id":"1.230178317","rc":[{"atb":[[1.58,12.74],[1.52,0]],"id":57196226},{"atb":[[1.43,2.48],[1.35,0]],"id":70902601}],"con":true,"img":false}]}
{"op":"mcm","clk":"11540927144","pt":1719500068376,"mc":[{"id":"1.230178317","rc":[{"atb":[[1.11,3.75]],"id":57196226}],"con":true,"img":false}]}
{"op":"mcm","clk":"11540927351","pt":1719500070847,"mc":[{"id":"1.230178317","rc":[{"atb":[[1.11,0]],"id":57196226}],"con":true,"img":false}]}
{"op":"mcm","clk":"11540927407","pt":1719500071569,"mc":[{"id":"1.230178317","rc":[{"atb":[[1.92,1],[2.32,0]],"id":69685608}],"con":true,"img":false}]}
{"op":"mcm","clk":"11540927415","pt":1719500071671,"mc":[{"id":"1.230178317","rc":[{"atb":[[1.63,2.62],[1.44,0]],"id":57196226}],"con":true,"img":false}]}
{"op":"mcm","clk":"11540927470","pt":1719500072240,"mc":[{"id":"1.230178317","rc":[{"atb":[[1.92,0],[2.32,1]],"id":69685608}],"con":true,"img":false}]}
{"op":"mcm","clk":"11540927609","pt":1719500074258,"mc":[{"id":"1.230178317","rc":[{"atb":[[2.02,0],[1.97,1]],"id":46611436},{"atb":[[2.02,0],[1.97,1]],"id":49159417}],"con":true,"img":false}]}
{"op":"mcm","clk":"11540927618","pt":1719500074362,"mc":[{"id":"1.230178317","rc":[{"atb":[[1.67,0],[1.7,2.48]],"id":46611436},{"atb":[[1.83,2],[1.79,0]],"id":49159417}],"con":true,"img":false}]}
{"op":"mcm","clk":"11540928387","pt":1719500084369,"mc":[{"id":"1.230178317","rc":[{"atb":[[1.63,2.11]],"id":57196226},{"atl":[[5.6,0]],"id":57196226},{"atb":[[1.83,0]],"id":69685608},{"atl":[[25,0]],"id":69685608},{"atb":[[1.7,0]],"id":49159417},{"atl":[[17,0]],"id":49159417}],"con":true,"img":false}]}
{"op":"mcm","clk":"11540928396","pt":1719500084472,"mc":[{"id":"1.230178317","rc":[{"atl":[[8,3],[5.7,0]],"id":57196226},{"atl":[[44,2.33],[26,0]],"id":69685608},{"atl":[[17.5,0],[22,3]],"id":49159417}],"con":true,"img":false}]}
{"op":"mcm","clk":"11540930850","pt":1719500113184,"mc":[{"id":"1.230178317","rc":[{"spn":2.49,"spf":"NaN","id":57196226},{"spn":3.53,"spf":"NaN","id":46611436},{"atb":[[1.62,0]],"id":52655636},{"spn":3.97,"spf":"NaN","id":52655636},{"spn":2.97,"spf":"NaN","id":70902601},{"spn":4.56,"spf":"NaN","id":69685608},{"spn":3.53,"spf":"NaN","id":49159417}],"con":true,"img":false}]}
{"op":"mcm","clk":"11540931189","pt":1719500117622,"mc":[{"id":"1.230178317","rc":[{"atb":[[1.02,24.65]],"id":69685608}],"con":true,"img":false}]}
{"op":"mcm","clk":"11540931204","pt":1719500117777,"mc":[{"id":"1.230178317","rc":[{"atb":[[1.02,2]],"id":49159417}],"con":true,"img":false}]}
{"op":"mcm","clk":"11540931229","pt":1719500117983,"mc":[{"id":"1.230178317","rc":[{"atb":[[1.64,2]],"id":57196226}],"con":true,"img":false}]}
{"op":"mcm","clk":"11540931260","pt":1719500118293,"mc":[{"id":"1.230178317","rc":[{"atb":[[1.02,24.65]],"id":70902601}],"con":true,"img":false}]}
{"op":"mcm","clk":"11540931291","pt":1719500118602,"mc":[{"id":"1.230178317","rc":[{"atb":[[1.71,2]],"id":52655636}],"con":true,"img":false}]}
{"op":"mcm","clk":"11540931314","pt":1719500118808,"mc":[{"id":"1.230178317","rc":[{"atb":[[1.02,2]],"id":46611436}],"con":true,"img":false}]}
{"op":"mcm","clk":"11540931760","pt":1719500124198,"mc":[{"id":"1.230178317","rc":[{"atl":[[6.8,0],[6.6,1]],"id":69685608}],"con":true,"img":false}]}
{"op":"mcm","clk":"11540931897","pt":1719500126208,"mc":[{"id":"1.230178317","rc":[{"atl":[[6.8,1],[6.6,0]],"id":69685608}],"con":true,"img":false}]}
{"op":"mcm","clk":"11540932560","pt":1719500133401,"mc":[{"id":"1.230178317","rc":[{"atl":[[6.8,0],[6.6,1]],"id":69685608}],"con":true,"img":false}]}
{"op":"mcm","clk":"11540932955","pt":1719500138630,"mc":[{"id":"1.230178317","rc":[{"atl":[[3.35,0],[3.65,1]],"id":57196226},{"atl":[[5.1,0],[5.3,1]],"id":46611436},{"atl":[[6.4,1],[5.7,0]],"id":52655636},{"atl":[[4.8,1],[4.2,0]],"id":70902601},{"atb":[[1.92,1],[2.32,0]],"id":69685608}],"con":true,"img":false}]}
{"op":"mcm","clk":"11540932993","pt":1719500139007,"mc":[{"id":"1.230178317","rc":[{"atb":[[1.92,0],[2.32,1]],"id":69685608}],"con":true,"img":false}]}
{"op":"mcm","clk":"11540933111","pt":1719500140421,"mc":[{"id":"1.230178317","rc":[{"atb":[[1.92,1],[2.32,0]],"id":69685608}],"con":true,"img":false}]}
{"op":"mcm","clk":"11540933627","pt":1719500146730,"mc":[{"id":"1.230178317","rc":[{"atb":[[1.92,0],[2.32,1]],"id":69685608}],"con":true,"img":false}]}
{"op":"mcm","clk":"11540933648","pt":1719500146937,"mc":[{"id":"1.230178317","rc":[{"atb":[[1.6,0]],"id":57196226},{"atb":[[1.6,0]],"id":52655636}],"con":true,"img":false}]}
{"op":"mcm","clk":"11540933780","pt":1719500148642,"mc":[{"id":"1.230178317","rc":[{"atl":[[3.35,1],[3.65,0]],"id":57196226},{"atl":[[5.1,1],[5.3,0]],"id":46611436},{"atl":[[6.4,0],[5.7,1]],"id":52655636},{"atl":[[4.8,0],[4.2,1]],"id":70902601}],"con":true,"img":false}]}
{"op":"mcm","clk":"11540933788","pt":1719500148745,"mc":[{"id":"1.230178317","rc":[{"atl":[[15.5,2]],"id":46611436},{"atl":[[17.5,0],[15.5,2]],"id":52655636},{"atl":[[8.8,2.01]],"id":70902601}],"con":true,"img":false}]}
{"op":"mcm","clk":"11540933798","pt":1719500148846,"mc":[{"id":"1.230178317","rc":[{"atl":[[17.5,0]],"id":46611436},{"atl":[[9.4,0]],"id":70902601}],"con":true,"img":false}]}
{"op":"mcm","clk":"11540933895","pt":1719500150036,"mc":[{"id":"1.230178317","rc":[{"atb":[[1.62,0]],"id":57196226}],"con":true,"img":false}]}
{"op":"mcm","clk":"11540934237","pt":1719500154313,"mc":[{"id":"1.230178317","rc":[{"atb":[[1.92,1],[2.32,0]],"id":69685608}],"con":true,"img":false}]}
{"op":"mcm","clk":"11540934254","pt":1719500154623,"mc":[{"id":"1.230178317","rc":[{"atb":[[1.92,0],[2.32,1]],"id":69685608}],"con":true,"img":false}]}
{"op":"mcm","clk":"11540934737","pt":1719500160864,"mc":[{"id":"1.230178317","rc":[{"atb":[[1.01,1.7]],"id":57196226},{"atl":[[1000,1.7]],"id":57196226},{"atb":[[1.01,1.7]],"id":69685608},{"atl":[[1000,1.87]],"id":69685608},{"atb":[[1.01,47.01]],"id":49159417},{"atl":[[1000,1.7]],"id":49159417}],"con":true,"img":false}]}
{"op":"mcm","clk":"11540934761","pt":1719500161072,"mc":[{"id":"1.230178317","rc":[{"atb":[[1.01,0.47]],"id":57196226},{"atl":[[1000,0.04]],"id":57196226},{"atb":[[1.92,1],[1.01,0.26],[2.32,0]],"id":69685608},{"atl":[[1000,0.17]],"id":69685608},{"atb":[[1.01,45.67]],"id":49159417},{"atl":[[1000,0.01]],"id":49159417}],"con":true,"img":false}]}
{"op":"mcm","clk":"11540934781","pt":1719500161229,"mc":[{"id":"1.230178317","rc":[{"atb":[[1.01,0]],"id":57196226},{"atl":[[1000,0]],"id":57196226},{"atb":[[1.92,0],[1.01,0],[2.32,1]],"id":69685608},{"atl":[[1000,0.16]],"id":69685608},{"atb":[[1.01,45.3]],"id":49159417},{"atl":[[1000,0]],"id":49159417}],"con":true,"img":false}]}
{"op":"mcm","clk":"11540934787","pt":1719500161332,"mc":[{"id":"1.230178317","rc":[{"atb":[[1.65,0.47]],"id":57196226},{"atl":[[7.8,0.04]],"id":57196226},{"atb":[[2.14,0.26]],"id":69685608},{"atl":[[42,0]],"id":69685608},{"atb":[[1.84,0.36]],"id":49159417},{"atl":[[21,0.01]],"id":49159417}],"con":true,"img":false}]}
{"op":"mcm","clk":"11540935365","pt":1719500168146,"mc":[{"id":"1.230178317","rc":[{"atb":[[1.92,1],[2.32,0]],"id":69685608}],"con":true,"img":false}]}
{"op":"mcm","clk":"11540935439","pt":1719500168866,"mc":[{"id":"1.230178317","rc":[{"atb":[[1.92,0],[2.32,1]],"id":69685608}],"con":true,"img":false}]}
{"op":"mcm","clk":"11540936070","pt":1719500175658,"mc":[{"id":"1.230178317","rc":[{"spn":2.5,"spf":"NaN","id":57196226},{"atb":[[1.92,1],[2.32,0]],"id":69685608},{"spn":4.37,"spf":"NaN","id":69685608}],"con":true,"img":false}]}
{"op":"mcm","clk":"11540936151","pt":1719500176643,"mc":[{"id":"1.230178317","rc":[{"atb":[[1.92,0],[2.32,1]],"id":69685608}],"con":true,"img":false}]}
{"op":"mcm","clk":"11540936217","pt":1719500177573,"mc":[{"id":"1.230178317","rc":[{"atb":[[1.58,0],[1.53,4.12]],"id":57196226},{"atb":[[1.43,0],[1.37,3.48]],"id":70902601}],"con":true,"img":false}]}
{"op":"mcm","clk":"11540936677","pt":1719500183393,"mc":[{"id":"1.230178317","rc":[{"atb":[[1.92,1],[2.32,0]],"id":69685608}],"con":true,"img":false}]}
{"op":"mcm","clk":"11540936684","pt":1719500183496,"mc":[{"id":"1.230178317","rc":[{"atb":[[1.92,0]],"id":69685608}],"con":true,"img":false}]}
{"op":"mcm","clk":"11540936695","pt":1719500183599,"mc":[{"id":"1.230178317","rc":[{"atb":[[2.32,1],[1.98,2.48]],"id":69685608}],"con":true,"img":false}]}
{"op":"mcm","clk":"11540936701","pt":1719500183703,"mc":[{"id":"1.230178317","rc":[{"atb":[[2.12,0]],"id":69685608}],"con":true,"img":false}]}
{"op":"mcm","clk":"11540936707","pt":1719500183756,"mc":[{"id":"1.230178317","rc":[{"atb":[[1.98,0],[2.12,2]],"id":69685608}],"con":true,"img":false}]}
{"op":"mcm","clk":"11540937286","pt":1719500190499,"mc":[{"id":"1.230178317","rc":[{"atb":[[1.92,1],[2.32,0]],"id":69685608}],"con":true,"img":false}]}
{"op":"mcm","clk":"11540937306","pt":1719500190707,"mc":[{"id":"1.230178317","rc":[{"atb":[[1.98,2.27],[2.12,0]],"id":69685608}],"con":true,"img":false}]}
{"op":"mcm","clk":"11540937322","pt":1719500190915,"mc":[{"id":"1.230178317","rc":[{"atb":[[2.32,1]],"id":69685608}],"con":true,"img":false}]}
{"op":"mcm","clk":"11540937331","pt":1719500190970,"mc":[{"id":"1.230178317","rc":[{"atb":[[1.92,0]],"id":69685608}],"con":true,"img":false}]}
{"op":"mcm","clk":"11540937902","pt":1719500197875,"mc":[{"id":"1.230178317","rc":[{"atb":[[1.92,1],[2.32,0]],"id":69685608}],"con":true,"img":false}]}
{"op":"mcm","clk":"11540937959","pt":1719500198399,"mc":[{"id":"1.230178317","rc":[{"atb":[[1.92,0],[2.32,1]],"id":69685608}],"con":true,"img":false}]}
{"op":"mcm","clk":"11540938185","pt":1719500200880,"mc":[{"id":"1.230178317","rc":[{"atb":[[1.92,1],[2.32,0]],"id":69685608}],"con":true,"img":false}]}
{"op":"mcm","clk":"11540938263","pt":1719500201911,"mc":[{"id":"1.230178317","rc":[{"atl":[[5.1,0],[5.3,1]],"id":46611436},{"atl":[[6.4,1],[5.7,0]],"id":52655636},{"atl":[[4.8,1],[4.2,0]],"id":70902601}],"con":true,"img":false}]}
{"op":"mcm","clk":"11540938269","pt":1719500202014,"mc":[{"id":"1.230178317","rc":[{"atl":[[16.5,3]],"id":52655636}],"con":true,"img":false}]}
{"op":"mcm","clk":"11540938275","pt":1719500202116,"mc":[{"id":"1.230178317","rc":[{"atl":[[15.5,0]],"id":52655636}],"con":true,"img":false}]}
{"op":"mcm","clk":"11540938339","pt":1719500202891,"mc":[{"id":"1.230178317","rc":[{"atb":[[1.92,0],[2.32,1]],"id":69685608}],"con":true,"img":false}]}
{"op":"mcm","clk":"11540938353","pt":1719500203097,"mc":[{"id":"1.230178317","rc":[{"atb":[[1.92,1],[2.32,0]],"id":69685608}],"con":true,"img":false}]}
{"op":"mcm","clk":"11540938361","pt":1719500203200,"mc":[{"id":"1.230178317","rc":[{"atl":[[3.35,0],[3.65,1]],"id":57196226}],"con":true,"img":false}]}
{"op":"mcm","clk":"11540938506","pt":1719500205010,"mc":[{"id":"1.230178317","rc":[{"atb":[[1.92,0],[2.32,1]],"id":69685608}],"con":true,"img":false}]}
{"op":"mcm","clk":"11540938521","pt":1719500205218,"mc":[{"id":"1.230178317","rc":[{"atb":[[1.92,1],[2.32,0]],"id":69685608}],"con":true,"img":false}]}
{"op":"mcm","clk":"11540938533","pt":1719500205424,"mc":[{"id":"1.230178317","rc":[{"atb":[[1.92,0],[2.32,1]],"id":69685608}],"con":true,"img":false}]}
{"op":"mcm","clk":"11540938562","pt":1719500205990,"mc":[{"id":"1.230178317","rc":[{"atb":[[1.92,1],[2.32,0]],"id":69685608},{"atl":[[6.8,1],[6.6,0]],"id":69685608}],"con":true,"img":false}]}
{"op":"mcm","clk":"11540938603","pt":1719500206508,"mc":[{"id":"1.230178317","rc":[{"atb":[[2.24,0.21]],"id":52655636},{"trd":[[2.24,1.57]],"ltp":2.24,"tv":1.57,"id":52655636}],"con":true,"img":false}]}
{"op":"mcm","clk":"11540938613","pt":1719500206611,"mc":[{"id":"1.230178317","rc":[{"atb":[[2.24,0],[2.18,1]],"id":52655636},{"atl":[[6.4,0],[5.7,1]],"id":52655636}],"con":true,"img":false}]}
{"op":"mcm","clk":"11540938913","pt":1719500210914,"mc":[{"id":"1.230178317","rc":[{"atl":[[6.4,1],[5.7,0]],"id":52655636},{"atl":[[6.6,1]],"id":69685608}],"con":true,"img":false}]}
{"op":"mcm","clk":"11540938921","pt":1719500211017,"mc":[{"id":"1.230178317","rc":[{"atb":[[1.92,0],[2.32,1]],"id":69685608},{"atl":[[6.8,0]],"id":69685608}],"con":true,"img":false}]}
{"op":"mcm","clk":"11540938990","pt":1719500211846,"mc":[{"id":"1.230178317","rc":[{"atb":[[1.65,0]],"id":57196226},{"atl":[[7.8,0]],"id":57196226},{"atb":[[2.14,0]],"id":69685608},{"atl":[[42,0]],"id":69685608},{"atb":[[1.84,0]],"id":49159417},{"atl":[[21,0]],"id":49159417}],"con":true,"img":false}]}
{"op":"mcm","clk":"11540939000","pt":1719500211899,"mc":[{"id":"1.230178317","rc":[{"atl":[[5.1,1],[5.3,0]],"id":46611436},{"atl":[[4.8,0],[4.2,1]],"id":70902601}],"con":true,"img":false}]}
{"op":"mcm","clk":"11540939006","pt":1719500212002,"mc":[{"id":"1.230178317","rc":[{"atl":[[17,3],[15.5,0]],"id":46611436},{"atb":[[1.83,0],[1.77,3]],"id":49159417}],"con":true,"img":false}]}
{"op":"mcm","clk":"11540939088","pt":1719500213044,"mc":[{"id":"1.230178317","rc":[{"atb":[[1.92,1],[2.32,0]],"id":69685608},{"atl":[[6.8,1],[6.6,0]],"id":69685608}],"con":true,"img":false}]}
{"op":"mcm","clk":"11540939379","pt":1719500216823,"mc":[{"id":"1.230178317","rc":[{"atb":[[1.92,0],[2.32,1]],"id":69685608},{"atl":[[6.8,0],[6.6,1]],"id":69685608}],"con":true,"img":false}]}
{"op":"mcm","clk":"11540939502","pt":1719500218429,"mc":[{"id":"1.230178317","rc":[{"atl":[[3.35,1],[3.65,0]],"id":57196226},{"atl":[[6.4,0],[5.7,1]],"id":52655636},{"atl":[[6.8,1],[6.6,0]],"id":69685608}],"con":true,"img":false}]}
{"op":"mcm","clk":"11540939574","pt":1719500219362,"mc":[{"id":"1.230178317","rc":[{"atl":[[3.35,0],[3.65,1]],"id":57196226},{"atl":[[5.1,0],[5.3,1]],"id":46611436},{"atl":[[6.4,1],[5.7,0]],"id":52655636},{"atl":[[4.8,1],[4.2,0]],"id":70902601},{"atb":[[1.92,1],[2.32,0]],"id":69685608},{"atl":[[6.8,0],[6.6,1]],"id":69685608}],"con":true,"img":false}]}
{"op":"mcm","clk":"11540939581","pt":1719500219415,"mc":[{"id":"1.230178317","rc":[{"atl":[[17,0],[15.5,2]],"id":46611436}],"con":true,"img":false}]}
{"op":"mcm","clk":"11540944087","pt":1719500282282,"mc":[{"id":"1.230178317","rc":[{"atl":[[1000,1.7]],"id":57196226},{"spn":2.64,"spf":"NaN","id":57196226},{"spn":3.63,"spf":"NaN","id":46611436},{"spn":4.29,"spf":"NaN","id":52655636},{"spn":3.27,"spf":"NaN","id":70902601},{"atl":[[1000,1.87]],"id":69685608},{"spn":4.29,"spf":"NaN","id":69685608},{"atl":[[1000,1.7]],"id":49159417}],"con":true,"img":false}]}
{"op":"mcm","clk":"11540944097","pt":1719500282390,"mc":[{"id":"1.230178317","rc":[{"atb":[[1.01,1.7]],"id":57196226},{"atb":[[1.01,1.7]],"id":69685608},{"atb":[[1.01,47.01]],"id":49159417}],"con":true,"img":false}]}
{"op":"mcm","clk":"11540944107","pt":1719500282496,"mc":[{"id":"1.230178317","rc":[{"atl":[[1000,0.04]],"id":57196226},{"atl":[[1000,0.17]],"id":69685608}],"con":true,"img":false}]}
{"op":"mcm","clk":"11540944117","pt":1719500282585,"mc":[{"id":"1.230178317","rc":[{"atb":[[1.01,0.45]],"id":57196226},{"atb":[[1.01,0.29]],"id":69685608},{"atb":[[1.01,45.68]],"id":49159417},{"atl":[[1000,0.01]],"id":49159417}],"con":true,"img":false}]}
{"op":"mcm","clk":"11540944122","pt":1719500282688,"mc":[{"id":"1.230178317","rc":[{"atl":[[1000,0]],"id":57196226},{"atl":[[1000,0.16]],"id":69685608}],"con":true,"img":false}]}
{"op":"mcm","clk":"11540944131","pt":1719500282806,"mc":[{"id":"1.230178317","rc":[{"atb":[[1.01,0]],"id":57196226},{"atl":[[7.8,0.04]],"id":57196226},{"atb":[[1.01,0]],"id":69685608},{"atl":[[42,0]],"id":69685608},{"atb":[[1.01,45.3]],"id":49159417},{"atl":[[1000,0]],"id":49159417}],"con":true,"img":false}]}
{"op":"mcm","clk":"11540944140","pt":1719500282897,"mc":[{"id":"1.230178317","rc":[{"atb":[[1.65,0.45]],"id":57196226},{"atb":[[1.99,0.29]],"id":69685608},{"atb":[[1.78,0.37]],"id":49159417},{"atl":[[21,0.01]],"id":49159417}],"con":true,"img":false}]}
{"op":"mcm","clk":"11540944388","pt":1719500286111,"mc":[{"id":"1.230178317","rc":[{"atb":[[1.66,5.98]],"id":57196226}],"con":true,"img":false}]}
{"op":"mcm","clk":"11540944454","pt":1719500286891,"mc":[{"id":"1.230178317","rc":[{"atb":[[1.64,0]],"id":57196226}],"con":true,"img":false}]}
{"op":"mcm","clk":"11540944463","pt":1719500286995,"mc":[{"id":"1.230178317","rc":[{"atb":[[1.67,2]],"id":57196226}],"con":true,"img":false}]}
{"op":"mcm","clk":"11540944843","pt":1719500291818,"mc":[{"id":"1.230178317","rc":[{"atb":[[1.92,0],[2.02,1]],"id":69685608}],"con":true,"img":false}]}
{"op":"mcm","clk":"11540945016","pt":1719500293697,"mc":[{"id":"1.230178317","rc":[{"atl":[[4.8,0],[4.6,1]],"id":70902601},{"atl":[[5.3,1]],"id":49159417}],"con":true,"img":false}]}
{"op":"mcm","clk":"11540945025","pt":1719500293799,"mc":[{"id":"1.230178317","rc":[{"atl":[[5.1,0]],"id":49159417}],"con":true,"img":false}]}
{"op":"mcm","clk":"11540945070","pt":1719500294305,"mc":[{"id":"1.230178317","rc":[{"atb":[[1.92,1],[2.02,0]],"id":69685608}],"con":true,"img":false}]}
{"op":"mcm","clk":"11540945090","pt":1719500294512,"mc":[{"id":"1.230178317","rc":[{"atl":[[4.8,1],[4.6,0]],"id":70902601},{"atl":[[5.1,1],[5.3,0]],"id":49159417}],"con":true,"img":false}]}
{"op":"mcm","clk":"11540945210","pt":1719500296116,"mc":[{"id":"1.230178317","rc":[{"atb":[[1.92,0],[2.02,1]],"id":69685608}],"con":true,"img":false}]}
{"op":"mcm","clk":"11540945238","pt":1719500296387,"mc":[{"id":"1.230178317","rc":[{"atl":[[4.8,0],[4.6,1]],"id":70902601},{"atl":[[5.1,0],[5.3,1]],"id":49159417}],"con":true,"img":false}]}
{"op":"mcm","clk":"11540945932","pt":1719500305024,"mc":[{"id":"1.230178317","rc":[{"atb":[[1.92,1],[2.02,0]],"id":69685608}],"con":true,"img":false}]}
{"op":"mcm","clk":"11540946317","pt":1719500309732,"mc":[{"id":"1.230178317","rc":[{"atb":[[2.02,1]],"id":69685608}],"con":true,"img":false}]}
{"op":"mcm","clk":"11540946328","pt":1719500309834,"mc":[{"id":"1.230178317","rc":[{"atb":[[1.92,0]],"id":69685608}],"con":true,"img":false}]}
{"op":"mcm","clk":"11540947270","pt":1719500321429,"mc":[{"id":"1.230178317","rc":[{"atb":[[1.66,0]],"id":57196226}],"con":true,"img":false}]}
{"op":"mcm","clk":"11540947329","pt":1719500322259,"mc":[{"id":"1.230178317","rc":[{"atl":[[3.6,1],[3.65,0]],"id":57196226},{"atl":[[5.3,0],[5.2,1]],"id":46611436},{"atl":[[6.2,1]],"id":52655636},{"atl":[[4.5,1]],"id":70902601},{"atl":[[5.3,0],[5.2,1]],"id":49159417}],"con":true,"img":false}]}
{"op":"mcm","clk":"11540947335","pt":1719500322362,"mc":[{"id":"1.230178317","rc":[{"atl":[[17,3],[15.5,0]],"id":46611436},{"atl":[[6.4,0]],"id":52655636},{"atl":[[4.6,0]],"id":70902601}],"con":true,"img":false}]}
{"op":"mcm","clk":"11540947356","pt":1719500322628,"mc":[{"id":"1.230178317","rc":[{"atb":[[1.67,0]],"id":57196226}],"con":true,"img":false}]}
{"op":"mcm","clk":"11540947364","pt":1719500322734,"mc":[{"id":"1.230178317","rc":[{"atb":[[1.64,2]],"id":57196226}],"con":true,"img":false}]}
{"op":"mcm","clk":"11540947572","pt":1719500325465,"mc":[{"id":"1.230178317","rc":[{"atb":[[1.65,0]],"id":57196226},{"atl":[[7.8,0]],"id":57196226},{"atb":[[1.99,0]],"id":69685608},{"atl":[[42,0]],"id":69685608},{"atb":[[1.78,0]],"id":49159417},{"atl":[[21,0]],"id":49159417}],"con":true,"img":false}]}
{"op":"mcm","clk":"11540947590","pt":1719500325626,"mc":[{"id":"1.230178317","rc":[{"atb":[[2.02,0],[2.46,1]],"id":69685608},{"atl":[[6.8,1],[6.6,0]],"id":69685608}],"con":true,"img":false}]}
{"op":"mcm","clk":"11540947728","pt":1719500327166,"mc":[{"id":"1.230178317","rc":[{"atl":[[4.1,1]],"id":70902601}],"con":true,"img":false}]}
{"op":"mcm","clk":"11540947736","pt":1719500327269,"mc":[{"id":"1.230178317","rc":[{"atl":[[5,1],[5.2,0]],"id":46611436},{"atl":[[5.6,1],[6.2,0]],"id":52655636},{"atl":[[4.5,0],[4.6,2.01],[8.8,0]],"id":70902601},{"atl":[[5,1],[5.2,0]],"id":49159417}],"con":true,"img":false}]}
{"op":"mcm","clk":"11540947746","pt":1719500327341,"mc":[{"id":"1.230178317","rc":[{"atl":[[17,0],[15.5,2]],"id":46611436},{"atl":[[16.5,0],[6.4,2]],"id":52655636},{"atl":[[8.8,2.01]],"id":70902601}],"con":true,"img":false}]}
{"op":"mcm","clk":"11540947755","pt":1719500327435,"mc":[{"id":"1.230178317","rc":[{"atl":[[16.5,2],[6.4,0]],"id":52655636},{"atl":[[4.6,0]],"id":70902601}],"con":true,"img":false}]}
{"op":"mcm","clk":"11540947808","pt":1719500328047,"mc":[{"id":"1.230178317","rc":[{"atl":[[3.6,0],[3.3,1]],"id":57196226}],"con":true,"img":false}]}
{"op":"mcm","clk":"11540949603","pt":1719500350192,"mc":[{"id":"1.230178317","rc":[{"spn":2.47,"spf":"NaN","id":57196226},{"spn":3.48,"spf":"NaN","id":46611436},{"atl":[[5.5,0.52]],"id":52655636},{"spn":3.84,"spf":"NaN","id":52655636},{"spn":2.92,"spf":"NaN","id":70902601},{"spn":4.63,"spf":"NaN","id":69685608},{"spn":3.48,"spf":"NaN","id":49159417}],"con":true,"img":false}]}
{"op":"mcm","clk":"11540949617","pt":1719500350398,"mc":[{"id":"1.230178317","rc":[{"atb":[[1.03,15.62]],"id":52655636}],"con":true,"img":false}]}
{"op":"mcm","clk":"11540949634","pt":1719500350562,"mc":[{"id":"1.230178317","rc":[{"atb":[[1.03,15.53]],"id":52655636}],"con":true,"img":false}]}
{"op":"mcm","clk":"11540949652","pt":1719500350770,"mc":[{"id":"1.230178317","rc":[{"atb":[[1.03,15.1]],"id":52655636}],"con":true,"img":false}]}
{"op":"mcm","clk":"11540949661","pt":1719500350872,"mc":[{"id":"1.230178317","rc":[{"atb":[[2.2,0.43]],"id":52655636}],"con":true,"img":false}]}
{"op":"mcm","clk":"11540949952","pt":1719500353977,"mc":[{"id":"1.230178317","rc":[{"atb":[[1.08,50]],"id":57196226},{"atb":[[1.08,50]],"id":46611436},{"atb":[[1.08,50]],"id":52655636},{"atb":[[1.08,50]],"id":70902601},{"atb":[[1.08,50]],"id":69685608},{"atb":[[1.08,50]],"id":49159417}],"con":true,"img":false}]}
{"op":"mcm","clk":"11540950344","pt":1719500359981,"mc":[{"id":"1.230178317","rc":[{"atb":[[1.66,5.98]],"id":57196226}],"con":true,"img":false}]}
{"op":"mcm","clk":"11540950436","pt":1719500361375,"mc":[{"id":"1.230178317","rc":[{"atb":[[1.64,0]],"id":57196226}],"con":true,"img":false}]}
{"op":"mcm","clk":"11540950443","pt":1719500361480,"mc":[{"id":"1.230178317","rc":[{"atb":[[1.67,2]],"id":57196226}],"con":true,"img":false}]}
{"op":"mcm","clk":"11540950783","pt":1719500365696,"mc":[{"id":"1.230178317","rc":[{"atl":[[5.5,0]],"id":52655636}],"con":true,"img":false}]}
{"op":"mcm","clk":"11540950823","pt":1719500366205,"mc":[{"id":"1.230178317","rc":[{"atb":[[2.2,0]],"id":52655636}],"con":true,"img":false}]}
{"op":"mcm","clk":"11540950962","pt":1719500367607,"mc":[{"id":"1.230178317","rc":[{"atb":[[1.69,6.13]],"id":57196226}],"con":true,"img":false}]}
{"op":"mcm","clk":"11540950979","pt":1719500367819,"mc":[{"id":"1.230178317","rc":[{"atl":[[5.5,0.52]],"id":52655636}],"con":true,"img":false}]}
{"op":"mcm","clk":"11540950987","pt":1719500367904,"mc":[{"id":"1.230178317","rc":[{"atb":[[1.03,15.62]],"id":52655636}],"con":true,"img":false}]}
{"op":"mcm","clk":"11540951005","pt":1719500368114,"mc":[{"id":"1.230178317","rc":[{"atb":[[1.03,15.53]],"id":52655636}],"con":true,"img":false}]}
{"op":"mcm","clk":"11540951026","pt":1719500368291,"mc":[{"id":"1.230178317","rc":[{"atb":[[1.03,15.1]],"id":52655636}],"con":true,"img":false}]}
{"op":"mcm","clk":"11540951036","pt":1719500368389,"mc":[{"id":"1.230178317","rc":[{"atb":[[2.2,0.43]],"id":52655636}],"con":true,"img":false}]}
{"op":"mcm","clk":"11540951070","pt":1719500368997,"mc":[{"id":"1.230178317","rc":[{"atb":[[1.67,0]],"id":57196226}],"con":true,"img":false}]}
{"op":"mcm","clk":"11540951083","pt":1719500369097,"mc":[{"id":"1.230178317","rc":[{"atb":[[1.7,2]],"id":57196226}],"con":true,"img":false}]}
{"op":"mcm","clk":"11540951536","pt":1719500374414,"mc":[{"id":"1.230178317","rc":[{"atl":[[50,0.71]],"id":49159417}],"con":true,"img":false}]}
{"op":"mcm","clk":"11540951820","pt":1719500377994,"mc":[{"id":"1.230178317","rc":[{"atl":[[50,0.77]],"id":49159417}],"con":true,"img":false}]}
{"op":"mcm","clk":"11540952196","pt":1719500382315,"mc":[{"id":"1.230178317","rc":[{"atl":[[50,0.06]],"id":49159417}],"con":true,"img":false}]}
{"op":"mcm","clk":"11540952251","pt":1719500383021,"mc":[{"id":"1.230178317","rc":[{"atb":[[2.02,1],[2.46,0]],"id":69685608}],"con":true,"img":false}]}
{"op":"mcm","clk":"11540952259","pt":1719500383125,"mc":[{"id":"1.230178317","rc":[{"atl":[[5.5,0]],"id":52655636}],"con":true,"img":false}]}
{"op":"mcm","clk":"11540952287","pt":1719500383435,"mc":[{"id":"1.230178317","rc":[{"atb":[[2.02,0],[2.46,1]],"id":69685608}],"con":true,"img":false}]}
{"op":"mcm","clk":"11540952312","pt":1719500383700,"mc":[{"id":"1.230178317","rc":[{"atb":[[2.2,0]],"id":52655636}],"con":true,"img":false}]}
{"op":"mcm","clk":"11540952354","pt":1719500384417,"mc":[{"id":"1.230178317","rc":[{"atb":[[1.7,1]],"id":70902601}],"con":true,"img":false}]}
{"op":"mcm","clk":"11540952359","pt":1719500384521,"mc":[{"id":"1.230178317","rc":[{"atb":[[1.74,0]],"id":70902601}],"con":true,"img":false}]}
{"op":"mcm","clk":"11540952365","pt":1719500384624,"mc":[{"id":"1.230178317","rc":[{"atb":[[2.02,1],[2.46,0]],"id":69685608}],"con":true,"img":false}]}
{"op":"mcm","clk":"11540952482","pt":1719500385927,"mc":[{"id":"1.230178317","rc":[{"atl":[[5.5,0.52]],"id":52655636}],"con":true,"img":false}]}
{"op":"mcm","clk":"11540952505","pt":1719500386136,"mc":[{"id":"1.230178317","rc":[{"atb":[[1.03,15.62]],"id":52655636}],"con":true,"img":false}]}
{"op":"mcm","clk":"11540952529","pt":1719500386406,"mc":[{"id":"1.230178317","rc":[{"atb":[[1.03,15.53]],"id":52655636}],"con":true,"img":false}]}
{"op":"mcm","clk":"11540952547","pt":1719500386615,"mc":[{"id":"1.230178317","rc":[{"atb":[[1.03,15.1]],"id":52655636}],"con":true,"img":false}]}
{"op":"mcm","clk":"11540952556","pt":1719500386717,"mc":[{"id":"1.230178317","rc":[{"atb":[[2.2,0.43]],"id":52655636}],"con":true,"img":false}]}
{"op":"mcm","clk":"11540952730","pt":1719500388934,"mc":[{"id":"1.230178317","rc":[{"atl":[[3.6,1],[3.3,0]],"id":57196226},{"atl":[[5,0],[5.2,1]],"id":46611436},{"atl":[[5.6,0],[6.2,1]],"id":52655636},{"atl":[[4.5,1],[4.1,0]],"id":70902601},{"atl":[[5.2,1]],"id":49159417}],"con":true,"img":false}]}
{"op":"mcm","clk":"11540952736","pt":1719500389037,"mc":[{"id":"1.230178317","rc":[{"atl":[[5,0]],"id":49159417}],"con":true,"img":false}]}
{"op":"mcm","clk":"11540952745","pt":1719500389142,"mc":[{"id":"1.230178317","rc":[{"atl":[[17,3]],"id":46611436},{"atl":[[16.5,0],[6.2,3]],"id":52655636}],"con":true,"img":false}]}
{"op":"mcm","clk":"11540952755","pt":1719500389213,"mc":[{"id":"1.230178317","rc":[{"atl":[[15.5,0]],"id":46611436}],"con":true,"img":false}]}
{"op":"mcm","clk":"11540952766","pt":1719500389310,"mc":[{"id":"1.230178317","rc":[{"atl":[[16.5,3.53],[6.2,1]],"id":52655636}],"con":true,"img":false}]}
{"op":"mcm","clk":"11540953794","pt":1719500401123,"mc":[{"id":"1.230178317","rc":[{"atl":[[5.5,0]],"id":52655636}],"con":true,"img":false}]}
{"op":"mcm","clk":"11540953901","pt":1719500402016,"mc":[{"id":"1.230178317","rc":[{"atb":[[2.2,0]],"id":52655636}],"con":true,"img":false}]}
{"op":"mcm","clk":"11540954168","pt":1719500404352,"mc":[{"id":"1.230178317","rc":[{"atb":[[1.63,2.11],[1.02,22.65],[1.66,5.99],[1.69,6.13]],"id":57196226},{"atl":[[960,1.61]],"id":57196226},{"atb":[[1.03,15.1]],"id":46611436},{"atl":[[970,1.24]],"id":46611436},{"atb":[[1.44,2.11],[1.03,15.1]],"id":52655636},{"atl":[[6,0.52],[990,0.84]],"id":52655636},{"trd":[[2.24,1.58]],"ltp":2.24,"tv":1.58,"id":52655636},{"atb":[[1.02,24.65]],"id":70902601},{"atl":[[990,2.01]],"id":70902601},{"atb":[[1.02,24.65]],"id":69685608},{"atl":[[970,1.16]],"id":69685608},{"atb":[[1.01,45.31]],"id":49159417},{"atl":[[50,0.06],[980,2.1]],"id":49159417}],"con":true,"img":false}]}
{"op":"mcm","clk":"11540954189","pt":1719500404563,"mc":[{"id":"1.230178317","rc":[{"atb":[[1.03,15.63]],"id":52655636}],"con":true,"img":false}]}
{"op":"mcm","clk":"11540954206","pt":1719500404634,"mc":[{"id":"1.230178317","rc":[{"atb":[[2.02,0],[2.46,1]],"id":69685608}],"con":true,"img":false}]}
{"op":"mcm","clk":"11540954219","pt":1719500404746,"mc":[{"id":"1.230178317","rc":[{"atb":[[1.03,15.54]],"id":52655636}],"con":true,"img":false}]}
{"op":"mcm","clk":"11540954238","pt":1719500404957,"mc":[{"id":"1.230178317","rc":[{"atb":[[1.03,15.1]],"id":52655636}],"con":true,"img":false}]}
{"op":"mcm","clk":"11540954248","pt":1719500405059,"mc":[{"id":"1.230178317","rc":[{"atb":[[2.2,0.43]],"id":52655636}],"con":true,"img":false}]}
{"op":"mcm","clk":"11540954306","pt":1719500405549,"mc":[{"id":"1.230178317","rc":[{"atb":[[2.02,1],[2.46,0]],"id":69685608}],"con":true,"img":false}]}
{"op":"mcm","clk":"11540954409","pt":1719500406529,"mc":[{"id":"1.230178317","rc":[{"atl":[[1000,1.7]],"id":57196226},{"atb":[[1.01,1.7]],"id":69685608},{"atl":[[1000,1.87]],"id":69685608},{"atb":[[1.01,47.02]],"id":49159417},{"atl":[[1000,1.7]],"id":49159417}],"con":true,"img":false}]}
{"op":"mcm","clk":"11540954423","pt":1719500406639,"mc":[{"id":"1.230178317","rc":[{"atb":[[1.01,1.7]],"id":57196226}],"con":true,"img":false}]}
{"op":"mcm","clk":"11540954440","pt":1719500406837,"mc":[{"id":"1.230178317","rc":[{"atl":[[1000,0.04]],"id":57196226},{"atb":[[1.01,0.28]],"id":69685608},{"atl":[[1000,0.17]],"id":69685608},{"atb":[[1.01,45.68]],"id":49159417},{"atl":[[1000,0.01]],"id":49159417}],"con":true,"img":false}]}
{"op":"mcm","clk":"11540954450","pt":1719500406946,"mc":[{"id":"1.230178317","rc":[{"atb":[[1.01,0.39]],"id":57196226}],"con":true,"img":false}]}
{"op":"mcm","clk":"11540954472","pt":1719500407150,"mc":[{"id":"1.230178317","rc":[{"atl":[[1000,0]],"id":57196226},{"atb":[[1.01,0]],"id":69685608},{"atl":[[1000,0.16]],"id":69685608},{"atb":[[1.01,45.31]],"id":49159417},{"atl":[[1000,0]],"id":49159417}],"con":true,"img":false}]}
{"op":"mcm","clk":"11540954483","pt":1719500407253,"mc":[{"id":"1.230178317","rc":[{"atb":[[1.01,0]],"id":57196226},{"atl":[[7.8,0.04]],"id":57196226},{"atb":[[1.99,0.28]],"id":69685608},{"atl":[[42,0]],"id":69685608},{"atb":[[1.78,0.36]],"id":49159417},{"atl":[[21,0.01]],"id":49159417}],"con":true,"img":false}]}
{"op":"mcm","clk":"11540954497","pt":1719500407365,"mc":[{"id":"1.230178317","rc":[{"atb":[[1.71,0.39]],"id":57196226}],"con":true,"img":false}]}
{"op":"mcm","clk":"11540955475","pt":1719500417646,"mc":[{"id":"1.230178317","rc":[{"atl":[[13.5,3.25]],"id":57196226},{"spn":2.65,"spf":"NaN","id":57196226},{"spn":3.58,"spf":"NaN","id":46611436},{"spn":4.1,"spf":"NaN","id":52655636},{"spn":3.1,"spf":"NaN","id":70902601},{"spn":4.41,"spf":"NaN","id":69685608},{"spn":3.58,"spf":"NaN","id":49159417}],"con":true,"img":false}]}
{"op":"mcm","clk":"11540955644","pt":1719500419663,"mc":[{"id":"1.230178317","rc":[{"atl":[[6,0]],"id":52655636}],"con":true,"img":false}]}
{"op":"mcm","clk":"11540955710","pt":1719500420358,"mc":[{"id":"1.230178317","rc":[{"atb":[[2.2,0]],"id":52655636}],"con":true,"img":false}]}
{"op":"mcm","clk":"11540955949","pt":1719500423083,"mc":[{"id":"1.230178317","rc":[{"atl":[[13.5,0]],"id":57196226},{"atl":[[6,0.52]],"id":52655636}],"con":true,"img":false}]}
{"op":"mcm","clk":"11540955960","pt":1719500423172,"mc":[{"id":"1.230178317","rc":[{"atb":[[1.03,15.63]],"id":52655636}],"con":true,"img":false}]}
{"op":"mcm","clk":"11540955992","pt":1719500423451,"mc":[{"id":"1.230178317","rc":[{"atb":[[1.03,15.54]],"id":52655636}],"con":true,"img":false}]}
{"op":"mcm","clk":"11540956011","pt":1719500423654,"mc":[{"id":"1.230178317","rc":[{"atb":[[1.03,15.1]],"id":52655636}],"con":true,"img":false}]}
{"op":"mcm","clk":"11540956020","pt":1719500423761,"mc":[{"id":"1.230178317","rc":[{"atb":[[2.2,0.43]],"id":52655636}],"con":true,"img":false}]}
{"op":"mcm","clk":"11540956405","pt":1719500429262,"mc":[{"id":"1.230178317","rc":[{"atb":[[2.02,0],[2.46,1]],"id":69685608}],"con":true,"img":false}]}
{"op":"mcm","clk":"11540956700","pt":1719500433082,"mc":[{"id":"1.230178317","rc":[{"atb":[[2.02,1],[2.46,0]],"id":69685608}],"con":true,"img":false}]}
{"op":"mcm","clk":"11540956977","pt":1719500437278,"mc":[{"id":"1.230178317","rc":[{"atb":[[2.46,1]],"id":69685608}],"con":true,"img":false}]}
{"op":"mcm","clk":"11540956984","pt":1719500437379,"mc":[{"id":"1.230178317","rc":[{"atb":[[2.02,0]],"id":69685608}],"con":true,"img":false}]}
{"op":"mcm","clk":"11540957055","pt":1719500438365,"mc":[{"id":"1.230178317","rc":[{"atl":[[6,0]],"id":52655636}],"con":true,"img":false}]}
{"op":"mcm","clk":"11540957072","pt":1719500438566,"mc":[{"id":"1.230178317","rc":[{"atb":[[2.02,1]],"id":69685608}],"con":true,"img":false}]}
{"op":"mcm","clk":"11540957081","pt":1719500438672,"mc":[{"id":"1.230178317","rc":[{"atb":[[2.46,0]],"id":69685608}],"con":true,"img":false}]}
{"op":"mcm","clk":"11540957106","pt":1719500438988,"mc":[{"id":"1.230178317","rc":[{"atb":[[2.2,0]],"id":52655636}],"con":true,"img":false}]}
{"op":"mcm","clk":"11540957269","pt":1719500441367,"mc":[{"id":"1.230178317","rc":[{"atl":[[6,0.52]],"id":52655636}],"con":true,"img":false}]}
{"op":"mcm","clk":"11540957280","pt":1719500441471,"mc":[{"id":"1.230178317","rc":[{"atb":[[1.03,15.63]],"id":52655636}],"con":true,"img":false}]}
{"op":"mcm","clk":"11540957296","pt":1719500441687,"mc":[{"id":"1.230178317","rc":[{"atb":[[1.03,15.54]],"id":52655636}],"con":true,"img":false}]}
{"op":"mcm","clk":"11540957315","pt":1719500441897,"mc":[{"id":"1.230178317","rc":[{"atb":[[1.03,15.1]],"id":52655636}],"con":true,"img":false}]}
{"op":"mcm","clk":"11540957319","pt":1719500441999,"mc":[{"id":"1.230178317","rc":[{"atb":[[2.2,0.43]],"id":52655636}],"con":true,"img":false}]}
{"op":"mcm","clk":"11540957380","pt":1719500442787,"mc":[{"id":"1.230178317","rc":[{"atb":[[1.71,0]],"id":57196226},{"atl":[[7.8,0]],"id":57196226},{"atb":[[1.99,0]],"id":69685608},{"atl":[[42,0]],"id":69685608},{"atb":[[1.78,0]],"id":49159417},{"atl":[[21,0]],"id":49159417}],"con":true,"img":false}]}
{"op":"mcm","clk":"11540957402","pt":1719500443104,"mc":[{"id":"1.230178317","rc":[{"atb":[[2.46,1]],"id":69685608}],"con":true,"img":false}]}
{"op":"mcm","clk":"11540957408","pt":1719500443207,"mc":[{"id":"1.230178317","rc":[{"atb":[[2.02,0]],"id":69685608}],"con":true,"img":false}]}
{"op":"mcm","clk":"11540957460","pt":1719500443881,"mc":[{"id":"1.230178317","rc":[{"atb":[[2.02,1],[2.46,0]],"id":69685608}],"con":true,"img":false}]}
{"op":"mcm","clk":"11540957470","pt":1719500443985,"mc":[{"id":"1.230178317","rc":[{"atb":[[1.66,0]],"id":57196226}],"con":true,"img":false}]}
{"op":"mcm","clk":"11540958441","pt":1719500456900,"mc":[{"id":"1.230178317","rc":[{"atl":[[6,0]],"id":52655636}],"con":true,"img":false}]}
{"op":"mcm","clk":"11540958471","pt":1719500457313,"mc":[{"id":"1.230178317","rc":[{"atb":[[2.2,0]],"id":52655636}],"con":true,"img":false}]}
{"op":"mcm","clk":"11540958592","pt":1719500458913,"mc":[{"id":"1.230178317","rc":[{"atl":[[6,0.52]],"id":52655636}],"con":true,"img":false}]}
{"op":"mcm","clk":"11540958610","pt":1719500459110,"mc":[{"id":"1.230178317","rc":[{"atb":[[1.03,15.63]],"id":52655636}],"con":true,"img":false}]}
{"op":"mcm","clk":"11540958635","pt":1719500459419,"mc":[{"id":"1.230178317","rc":[{"atb":[[1.03,15.54]],"id":52655636}],"con":true,"img":false}]}
{"op":"mcm","clk":"11540958642","pt":1719500459522,"mc":[{"id":"1.230178317","rc":[{"atb":[[1.03,15.1]],"id":52655636}],"con":true,"img":false}]}
{"op":"mcm","clk":"11540958649","pt":1719500459584,"mc":[{"id":"1.230178317","rc":[{"atb":[[2.2,0.43]],"id":52655636}],"con":true,"img":false}]}
{"op":"mcm","clk":"11540959576","pt":1719500471631,"mc":[{"id":"1.230178317","rc":[{"atb":[[1.69,0]],"id":57196226}],"con":true,"img":false}]}
{"op":"mcm","clk":"11540959610","pt":1719500472100,"mc":[{"id":"1.230178317","rc":[{"atb":[[1.7,0]],"id":57196226}],"con":true,"img":false}]}
{"op":"mcm","clk":"11540959615","pt":1719500472205,"mc":[{"id":"1.230178317","rc":[{"atb":[[1.64,2]],"id":57196226}],"con":true,"img":false}]}
{"op":"mcm","clk":"11540959784","pt":1719500474137,"mc":[{"id":"1.230178317","rc":[{"atl":[[6,0]],"id":52655636}],"con":true,"img":false}]}
{"op":"mcm","clk":"11540959858","pt":1719500475018,"mc":[{"id":"1.230178317","rc":[{"atb":[[2.2,0]],"id":52655636}],"con":true,"img":false}]}
{"op":"mcm","clk":"11540960045","pt":1719500478126,"mc":[{"id":"1.230178317","rc":[{"spn":2.62,"spf":"NaN","id":57196226},{"atl":[[6,0.52]],"id":52655636},{"spn":4.09,"spf":"NaN","id":52655636}],"con":true,"img":false}]}
{"op":"mcm","clk":"11540960058","pt":1719500478332,"mc":[{"id":"1.230178317","rc":[{"atb":[[1.03,15.63]],"id":52655636}],"con":true,"img":false}]}
{"op":"mcm","clk":"11540960072","pt":1719500478494,"mc":[{"id":"1.230178317","rc":[{"atb":[[1.03,15.54]],"id":52655636}],"con":true,"img":false}]}
{"op":"mcm","clk":"11540960089","pt":1719500478704,"mc":[{"id":"1.230178317","rc":[{"atb":[[1.03,15.1]],"id":52655636}],"con":true,"img":false}]}
{"op":"mcm","clk":"11540960097","pt":1719500478809,"mc":[{"id":"1.230178317","rc":[{"atb":[[2.2,0.43]],"id":52655636}],"con":true,"img":false}]}
{"op":"mcm","clk":"11540960122","pt":1719500479119,"mc":[{"id":"1.230178317","rc":[{"atb":[[1.64,5.09],[1.57,4.12],[1.53,0],[1.65,5],[1.61,10],[1.69,2.5]],"id":57196226},{"atl":[[4.5,5],[4.1,2.5],[4.9,10],[3.55,3.09]],"id":57196226},{"atb":[[2.36,2.5],[1.98,1.5],[2.28,5],[2.2,10]],"id":46611436},{"atl":[[5.1,1.5],[5.5,2.5],[6.6,10],[5.9,5]],"id":46611436},{"atb":[[2.24,2.5],[2.18,2.5],[2.16,5],[2.08,10]],"id":52655636},{"atl":[[6.2,6],[6,2.02],[5.7,2.5],[7,10]],"id":52655636},{"atb":[[1.37,0],[1.7,2.5],[1.9,5],[1.86,10],[1.42,3.48],[1.94,2.5]],"id":70902601},{"atl":[[5.3,5],[4.9,2.5],[4.4,1.5],[5.7,10]],"id":70902601},{"atb":[[1.98,0],[1.97,3.27],[2.52,5],[2.04,1.5],[2.6,2.5],[2.44,10]],"id":69685608},{"atl":[[8,2.5],[9.6,10],[8.8,5],[6.6,1.5]],"id":69685608},{"atb":[[2.3,10],[1.98,1.5],[2.38,5],[1.85,3],[2.46,2.5],[1.77,0]],"id":49159417},{"atl":[[8,10],[7.2,5],[5.1,1.5],[6.4,2.5]],"id":49159417}],"con":true,"img":false}]}
{"op":"mcm","clk":"11540960130","pt":1719500479219,"mc":[{"id":"1.230178317","rc":[{"atl":[[8,0],[3.5,2.5]],"id":57196226},{"atb":[[1.7,0],[2.2,17.5]],"id":46611436},{"atl":[[17,0],[5.1,3.5]],"id":46611436},{"atb":[[1.7,0],[2.2,5.43]],"id":52655636},{"atl":[[16.5,0],[5.7,5]],"id":52655636},{"atl":[[4.4,3.5]],"id":70902601},{"atb":[[2.02,0],[2.12,1]],"id":69685608},{"atl":[[44,0],[9.4,4]],"id":69685608},{"atl":[[22,0],[6.8,5]],"id":49159417}],"con":true,"img":false}]}
{"op":"mcm","clk":"11540960138","pt":1719500479323,"mc":[{"id":"1.230178317","rc":[{"atl":[[3.6,0],[3.5,3.5]],"id":57196226},{"atl":[[5.8,1],[6.2,5]],"id":52655636},{"atl":[[8.8,0]],"id":70902601}],"con":true,"img":false}]}
{"op":"mcm","clk":"11540960164","pt":1719500479736,"mc":[{"id":"1.230178317","rc":[{"atl":[[3.45,0.84]],"id":57196226},{"atl":[[5,0.84]],"id":46611436},{"atl":[[5.6,0.84]],"id":52655636},{"atl":[[4.3,0.84]],"id":70902601}],"con":true,"img":false}]}
{"op":"mcm","clk":"11540960211","pt":1719500480312,"mc":[{"id":"1.230178317","rc":[{"atb":[[1.02,22.65]],"id":69685608}],"con":true,"img":false}]}
{"op":"mcm","clk":"11540960217","pt":1719500480416,"mc":[{"id":"1.230178317","rc":[{"atb":[[2.62,2]],"id":69685608}],"con":true,"img":false}]}
{"op":"mcm","clk":"11540960231","pt":1719500480623,"mc":[{"id":"1.230178317","rc":[{"atl":[[3.7,1.84]],"id":57196226}],"con":true,"img":false}]}
{"op":"mcm","clk":"11540960235","pt":1719500480727,"mc":[{"id":"1.230178317","rc":[{"atb":[[1.02,0]],"id":49159417}],"con":true,"img":false}]}
{"op":"mcm","clk":"11540960245","pt":1719500480832,"mc":[{"id":"1.230178317","rc":[{"atb":[[2.48,2]],"id":49159417}],"con":true,"img":false}]}
{"op":"mcm","clk":"11540960274","pt":1719500481303,"mc":[{"id":"1.230178317","rc":[{"atb":[[1.64,3.09]],"id":57196226}],"con":true,"img":false}]}
{"op":"mcm","clk":"11540960283","pt":1719500481415,"mc":[{"id":"1.230178317","rc":[{"atb":[[1.7,2]],"id":57196226}],"con":true,"img":false}]}
{"op":"mcm","clk":"11540960303","pt":1719500481624,"mc":[{"id":"1.230178317","rc":[{"atl":[[3.45,3.38]],"id":57196226}],"con":true,"img":false}]}
{"op":"mcm","clk":"11540960323","pt":1719500481832,"mc":[{"id":"1.230178317","rc":[{"atb":[[1.02,22.65]],"id":70902601}],"con":true,"img":false}]}
{"op":"mcm","clk":"11540960331","pt":1719500481925,"mc":[{"id":"1.230178317","rc":[{"atb":[[1.95,2]],"id":70902601}],"con":true,"img":false}]}
{"op":"mcm","clk":"11540960343","pt":1719500482033,"mc":[{"id":"1.230178317","rc":[{"atb":[[2.12,0]],"id":69685608}],"con":true,"img":false}]}
{"op":"mcm","clk":"11540960346","pt":1719500482131,"mc":[{"id":"1.230178317","rc":[{"atl":[[3.6,1],[3.5,2.5]],"id":57196226},{"atl":[[5.8,0],[6.2,6]],"id":52655636}],"con":true,"img":false}]}
{"op":"mcm","clk":"11540960358","pt":1719500482340,"mc":[{"id":"1.230178317","rc":[{"atb":[[1.71,0]],"id":52655636}],"con":true,"img":false}]}
{"op":"mcm","clk":"11540960371","pt":1719500482451,"mc":[{"id":"1.230178317","rc":[{"atb":[[1.02,2]],"id":52655636}],"con":true,"img":false}]}
{"op":"mcm","clk":"11540960387","pt":1719500482615,"mc":[{"id":"1.230178317","rc":[{"atb":[[1.63,0],[1.67,2.11]],"id":57196226},{"atb":[[1.02,0],[2.26,2.11]],"id":46611436},{"atb":[[2.24,4.61],[1.44,0]],"id":52655636},{"atb":[[1.89,2.11]],"id":70902601},{"atb":[[2.5,2.11]],"id":69685608},{"atb":[[2.36,2.11]],"id":49159417}],"con":true,"img":false}]}
{"op":"mcm","clk":"11540960393","pt":1719500482706,"mc":[{"id":"1.230178317","rc":[{"atb":[[2.38,2]],"id":46611436}],"con":true,"img":false}]}
{"op":"mcm","clk":"11540960528","pt":1719500484425,"mc":[{"id":"1.230178317","rc":[{"atl":[[5.1,1.5],[5.2,5.35]],"id":46611436},{"atl":[[6,8.02],[5.7,2.5]],"id":52655636},{"atl":[[4.5,5.35],[4.4,1.5]],"id":70902601}],"con":true,"img":false}]}
{"op":"mcm","clk":"11540960568","pt":1719500484934,"mc":[{"id":"1.230178317","rc":[{"atb":[[1.83,5],[1.42,0]],"id":70902601},{"atb":[[1.97,0],[2.62,4.5]],"id":69685608},{"atb":[[1.85,0],[2.46,6.5]],"id":49159417}],"con":true,"img":false}]}
{"op":"mcm","clk":"11540960634","pt":1719500485608,"mc":[{"id":"1.230178317","rc":[{"atb":[[1.02,1.7]],"id":49159417}],"con":true,"img":false}]}
{"op":"mcm","clk":"11540960650","pt":1719500485814,"mc":[{"id":"1.230178317","rc":[{"atb":[[1.69,8.16]],"id":57196226},{"atb":[[2.22,4.4]],"id":52655636},{"atb":[[1.02,0.12],[2.46,10.35]],"id":49159417}],"con":true,"img":false}]}
{"op":"mcm","clk":"11540960664","pt":1719500486020,"mc":[{"id":"1.230178317","rc":[{"atb":[[1.02,0]],"id":49159417}],"con":true,"img":false}]}
{"op":"mcm","clk":"11540960670","pt":1719500486124,"mc":[{"id":"1.230178317","rc":[{"atb":[[2.5,0.12]],"id":49159417}],"con":true,"img":false}]}
{"op":"mcm","clk":"11540960717","pt":1719500486908,"mc":[{"id":"1.230178317","rc":[{"atb":[[2.6,5.74]],"id":69685608}],"con":true,"img":false}]}
{"op":"mcm","clk":"11540960740","pt":1719500487218,"mc":[{"id":"1.230178317","rc":[{"atb":[[1.65,13.51]],"id":57196226}],"con":true,"img":false}]}
{"op":"mcm","clk":"11540960757","pt":1719500487424,"mc":[{"id":"1.230178317","rc":[{"atb":[[1.91,6.07]],"id":70902601}],"con":true,"img":false}]}
{"op":"mcm","clk":"11540960767","pt":1719500487528,"mc":[{"id":"1.230178317","rc":[{"atb":[[2.46,6.5]],"id":49159417}],"con":true,"img":false}]}
{"op":"mcm","clk":"11540960781","pt":1719500487735,"mc":[{"id":"1.230178317","rc":[{"atb":[[2.14,4.85]],"id":52655636}],"con":true,"img":false}]}
{"op":"mcm","clk":"11540961040","pt":1719500491559,"mc":[{"id":"1.230178317","rc":[{"atb":[[1.71,4.19]],"id":57196226},{"atl":[[3.4,4.19]],"id":57196226},{"atb":[[2.4,3.38]],"id":46611436},{"atl":[[5,4.22]],"id":46611436},{"atb":[[2.24,11.37]],"id":52655636},{"atl":[[5.5,6.76]],"id":52655636},{"atb":[[1.98,3.38]],"id":70902601},{"atl":[[4.3,4.22]],"id":70902601},{"atb":[[2.64,5.25]],"id":69685608},{"atb":[[2.48,4.62]],"id":49159417}],"con":true,"img":false}]}
{"op":"mcm","clk":"11540961057","pt":1719500491723,"mc":[{"id":"1.230178317","rc":[{"atb":[[1.64,0]],"id":57196226},{"atl":[[3.55,0]],"id":57196226},{"atb":[[1.98,0]],"id":46611436},{"atl":[[5.1,8.46],[5.2,1]],"id":46611436},{"atb":[[2.18,1]],"id":52655636},{"atl":[[6,0.52],[5.4,2.5]],"id":52655636},{"atb":[[1.7,1]],"id":70902601},{"atl":[[4.5,1],[4.4,0],[4.2,4.23]],"id":70902601},{"atb":[[2.66,5.25],[2.62,2]],"id":69685608},{"atb":[[1.98,0]],"id":49159417}],"con":true,"img":false}]}
{"op":"mcm","clk":"11540961065","pt":1719500491826,"mc":[{"id":"1.230178317","rc":[{"atb":[[2.04,0]],"id":69685608}],"con":true,"img":false}]}
{"op":"mcm","clk":"11540961079","pt":1719500492132,"mc":[{"id":"1.230178317","rc":[{"atl":[[3.35,0.84]],"id":57196226},{"atl":[[5.6,0],[5.3,0.84]],"id":52655636},{"atl":[[4.1,0.84]],"id":70902601}],"con":true,"img":false}]}
{"op":"mcm","clk":"11540961102","pt":1719500492443,"mc":[{"id":"1.230178317","rc":[{"atb":[[2.62,0]],"id":69685608}],"con":true,"img":false}]}
{"op":"mcm","clk":"11540961114","pt":1719500492545,"mc":[{"id":"1.230178317","rc":[{"atb":[[1.69,2.5]],"id":57196226},{"atb":[[2.6,2.5],[2.68,2]],"id":69685608}],"con":true,"img":false}]}
{"op":"mcm","clk":"11540961154","pt":1719500493004,"mc":[{"id":"1.230178317","rc":[{"atb":[[1.7,0]],"id":57196226}],"con":true,"img":false}]}
{"op":"mcm","clk":"11540961162","pt":1719500493118,"mc":[{"id":"1.230178317","rc":[{"atb":[[1.72,2]],"id":57196226}],"con":true,"img":false}]}
{"op":"mcm","clk":"11540961185","pt":1719500493421,"mc":[{"id":"1.230178317","rc":[{"atb":[[1.95,0]],"id":70902601}],"con":true,"img":false}]}
{"op":"mcm","clk":"11540961194","pt":1719500493543,"mc":[{"id":"1.230178317","rc":[{"atl":[[6,0]],"id":52655636},{"atb":[[1.99,2]],"id":70902601}],"con":true,"img":false}]}
{"op":"mcm","clk":"11540961202","pt":1719500493620,"mc":[{"id":"1.230178317","rc":[{"atl":[[3.45,0.84]],"id":57196226}],"con":true,"img":false}]}
{"op":"mcm","clk":"11540961217","pt":1719500493827,"mc":[{"id":"1.230178317","rc":[{"atb":[[2.38,0]],"id":46611436}],"con":true,"img":false}]}
{"op":"mcm","clk":"11540961228","pt":1719500493934,"mc":[{"id":"1.230178317","rc":[{"atb":[[2.42,2]],"id":46611436}],"con":true,"img":false}]}
{"op":"mcm","clk":"11540961250","pt":1719500494246,"mc":[{"id":"1.230178317","rc":[{"atl":[[3.6,0],[3.5,3.5]],"id":57196226},{"atb":[[2.18,11.88],[2.2,5]],"id":52655636},{"atl":[[5.8,1],[6.2,5]],"id":52655636}],"con":true,"img":false}]}
{"op":"mcm","clk":"11540961255","pt":1719500494343,"mc":[{"id":"1.230178317","rc":[{"atb":[[2.22,0],[2.2,0]],"id":52655636}],"con":true,"img":false}]}
{"op":"mcm","clk":"11540961264","pt":1719500494456,"mc":[{"id":"1.230178317","rc":[{"atb":[[2.18,1],[2.2,22.76]],"id":52655636}],"con":true,"img":false}]}
{"op":"mcm","clk":"11540961294","pt":1719500494817,"mc":[{"id":"1.230178317","rc":[{"atb":[[2.34,2.11]],"id":46611436},{"atb":[[1.94,4.61]],"id":70902601}],"con":true,"img":false}]}
{"op":"mcm","clk":"11540961306","pt":1719500494919,"mc":[{"id":"1.230178317","rc":[{"atb":[[2.26,0]],"id":46611436},{"atb":[[1.89,0]],"id":70902601}],"con":true,"img":false}]}
{"op":"mcm","clk":"11540961429","pt":1719500496431,"mc":[{"id":"1.230178317","rc":[{"atl":[[5.3,1.37]],"id":52655636}],"con":true,"img":false}]}
{"op":"mcm","clk":"11540961451","pt":1719500496847,"mc":[{"id":"1.230178317","rc":[{"atl":[[3.35,3.38]],"id":57196226}],"con":true,"img":false}]}
{"op":"mcm","clk":"11540961460","pt":1719500496949,"mc":[{"id":"1.230178317","rc":[{"atl":[[5.1,0],[5.2,13.69]],"id":46611436},{"atl":[[4.3,9.3],[4.2,0]],"id":70902601}],"con":true,"img":false}]}
{"op":"mcm","clk":"11540961469","pt":1719500497054,"mc":[{"id":"1.230178317","rc":[{"atl":[[5.5,20.42],[5.2,1]],"id":46611436},{"atl":[[4.3,4.22],[4.5,11.16]],"id":70902601}],"con":true,"img":false}]}
{"op":"mcm","clk":"11540961490","pt":1719500497217,"mc":[{"id":"1.230178317","rc":[{"atl":[[3.45,0]],"id":57196226},{"atl":[[4.1,0]],"id":70902601}],"con":true,"img":false}]}
{"op":"mcm","clk":"11540961497","pt":1719500497317,"mc":[{"id":"1.230178317","rc":[{"atl":[[4.5,1],[4.9,17.89]],"id":70902601}],"con":true,"img":false}]}
{"op":"mcm","clk":"11540961536","pt":1719500497842,"mc":[{"id":"1.230178317","rc":[{"atl":[[3.6,1],[3.5,2.5]],"id":57196226},{"atl":[[5.8,0],[6.2,6]],"id":52655636},{"atb":[[2.38,14.24],[2.46,2.5]],"id":49159417}],"con":true,"img":false}]}
{"op":"mcm","clk":"11540961877","pt":1719500501818,"mc":[{"id":"1.230178317","rc":[{"atl":[[6.8,0],[6.6,2.5]],"id":69685608}],"con":true,"img":false}]}
{"op":"mcm","clk":"11540961885","pt":1719500501925,"mc":[{"id":"1.230178317","rc":[{"atb":[[2.18,35.14],[2.2,0]],"id":52655636}],"con":true,"img":false}]}
{"op":"mcm","clk":"11540961899","pt":1719500502126,"mc":[{"id":"1.230178317","rc":[{"atb":[[2.18,1],[2.2,22.76]],"id":52655636},{"atl":[[6.4,0.84]],"id":69685608}],"con":true,"img":false}]}
{"op":"mcm","clk":"11540961906","pt":1719500502233,"mc":[{"id":"1.230178317","rc":[{"atl":[[6.4,4.59]],"id":69685608}],"con":true,"img":false}]}
{"op":"mcm","clk":"11540961916","pt":1719500502337,"mc":[{"id":"1.230178317","rc":[{"atl":[[6.6,1]],"id":69685608}],"con":true,"img":false}]}
{"op":"mcm","clk":"11540961993","pt":1719500503457,"mc":[{"id":"1.230178317","rc":[{"atb":[[2.38,5],[2.48,9.24]],"id":49159417}],"con":true,"img":false}]}
{"op":"mcm","clk":"11540962014","pt":1719500503625,"mc":[{"id":"1.230178317","rc":[{"atb":[[1.72,6.42]],"id":57196226},{"atl":[[3.6,0],[3.5,3.5],[3.3,4.42]],"id":57196226},{"atb":[[2.42,6.41]],"id":46611436},{"atl":[[5.2,6.94]],"id":52655636},{"atb":[[1.99,7.71]],"id":70902601},{"atb":[[2.7,5.32]],"id":69685608}],"con":true,"img":false}]}
{"op":"mcm","clk":"11540962029","pt":1719500503829,"mc":[{"id":"1.230178317","rc":[{"atb":[[1.71,0]],"id":57196226},{"atl":[[3.4,0]],"id":57196226},{"atb":[[2.4,0]],"id":46611436},{"atl":[[5.5,0]],"id":52655636},{"atb":[[1.98,0]],"id":70902601},{"atb":[[2.64,0]],"id":69685608}],"con":true,"img":false}]}
{"op":"mcm","clk":"11540962037","pt":1719500503926,"mc":[{"id":"1.230178317","rc":[{"atb":[[2.4,3.86]],"id":46611436},{"atb":[[1.97,5.62]],"id":70902601}],"con":true,"img":false}]}
{"op":"mcm","clk":"11540962046","pt":1719500504034,"mc":[{"id":"1.230178317","rc":[{"atl":[[3.6,1]],"id":57196226}],"con":true,"img":false}]}
{"op":"mcm","clk":"11540962054","pt":1719500504138,"mc":[{"id":"1.230178317","rc":[{"atl":[[3.5,2.5]],"id":57196226}],"con":true,"img":false}]}
{"op":"mcm","clk":"11540962064","pt":1719500504245,"mc":[{"id":"1.230178317","rc":[{"atl":[[3.25,0.84]],"id":57196226},{"atl":[[5.1,0.84]],"id":52655636}],"con":true,"img":false}]}
{"op":"mcm","clk":"11540962077","pt":1719500504443,"mc":[{"id":"1.230178317","rc":[{"atl":[[5.2,9.44],[5.4,0]],"id":52655636}],"con":true,"img":false}]}
{"op":"mcm","clk":"11540962083","pt":1719500504545,"mc":[{"id":"1.230178317","rc":[{"atb":[[2.68,0]],"id":69685608}],"con":true,"img":false}]}
{"op":"mcm","clk":"11540962088","pt":1719500504650,"mc":[{"id":"1.230178317","rc":[{"atb":[[2.72,2],[2.6,13.07],[2.7,0]],"id":69685608}],"con":true,"img":false}]}
{"op":"mcm","clk":"11540962096","pt":1719500504752,"mc":[{"id":"1.230178317","rc":[{"atb":[[2.74,3.38],[2.66,0]],"id":69685608}],"con":true,"img":false}]}
{"op":"mcm","clk":"11540962101","pt":1719500504858,"mc":[{"id":"1.230178317","rc":[{"atb":[[2.72,7.25],[2.6,2.5]],"id":69685608}],"con":true,"img":false}]}
{"op":"mcm","clk":"11540962109","pt":1719500504962,"mc":[{"id":"1.230178317","rc":[{"atb":[[2.62,4]],"id":69685608}],"con":true,"img":false}]}
{"op":"mcm","clk":"11540962126","pt":1719500505123,"mc":[{"id":"1.230178317","rc":[{"atb":[[2.62,0]],"id":69685608}],"con":true,"img":false}]}
{"op":"mcm","clk":"11540962150","pt":1719500505428,"mc":[{"id":"1.230178317","rc":[{"atl":[[3.35,0.84]],"id":57196226}],"con":true,"img":false}]}
{"op":"mcm","clk":"11540962217","pt":1719500506251,"mc":[{"id":"1.230178317","rc":[{"atl":[[5.8,1],[6.2,5]],"id":52655636}],"con":true,"img":false}]}
{"op":"mcm","clk":"11540962275","pt":1719500506927,"mc":[{"id":"1.230178317","rc":[{"atb":[[2,2.11],[1.94,2.5]],"id":70902601}],"con":true,"img":false}]}
{"op":"mcm","clk":"11540962305","pt":1719500507331,"mc":[{"id":"1.230178317","rc":[{"atl":[[3.6,0],[3.45,1]],"id":57196226},{"atl":[[5.8,0],[5.7,3.5]],"id":52655636},{"atb":[[2.72,5.25]],"id":69685608},{"atl":[[6.8,1],[6.6,0]],"id":69685608}],"con":true,"img":false}]}
{"op":"mcm","clk":"11540962316","pt":1719500507444,"mc":[{"id":"1.230178317","rc":[{"atb":[[2.18,35.14],[2.2,0]],"id":52655636},{"atb":[[2.76,2]],"id":69685608}],"con":true,"img":false}]}
{"op":"mcm","clk":"11540962325","pt":1719500507553,"mc":[{"id":"1.230178317","rc":[{"atb":[[2.72,0],[2.6,11.13]],"id":69685608}],"con":true,"img":false}]}
{"op":"mcm","clk":"11540962331","pt":1719500507643,"mc":[{"id":"1.230178317","rc":[{"atb":[[2.18,1],[2.2,22.76]],"id":52655636}],"con":true,"img":false}]}
{"op":"mcm","clk":"11540962337","pt":1719500507751,"mc":[{"id":"1.230178317","rc":[{"atl":[[3.45,3],[3.5,0]],"id":57196226},{"atl":[[5.8,1],[5.7,2.5]],"id":52655636},{"atb":[[2.5,3.12]],"id":49159417},{"atl":[[5.3,1],[5.2,0]],"id":49159417}],"con":true,"img":false}]}
{"op":"mcm","clk":"11540962349","pt":1719500507950,"mc":[{"id":"1.230178317","rc":[{"atb":[[2.48,6.62]],"id":49159417}],"con":true,"img":false}]}
{"op":"mcm","clk":"11540962359","pt":1719500508056,"mc":[{"id":"1.230178317","rc":[{"atl":[[5.1,0]],"id":49159417}],"con":true,"img":false}]}
{"op":"mcm","clk":"11540962366","pt":1719500508160,"mc":[{"id":"1.230178317","rc":[{"atl":[[5.2,3.75]],"id":49159417}],"con":true,"img":false}]}
{"op":"mcm","clk":"11540962374","pt":1719500508262,"mc":[{"id":"1.230178317","rc":[{"atb":[[1.97,0]],"id":46611436},{"atb":[[1.7,0]],"id":70902601}],"con":true,"img":false}]}
{"op":"mcm","clk":"11540962383","pt":1719500508362,"mc":[{"id":"1.230178317","rc":[{"atl":[[3.45,2],[3.15,1]],"id":57196226},{"atl":[[5,5.22],[5.2,0]],"id":46611436},{"atl":[[5.6,1],[5.8,0]],"id":52655636},{"atb":[[1.83,0],[1.77,10.62]],"id":70902601},{"atl":[[4.5,0],[4.1,1]],"id":70902601},{"atl":[[6.8,0],[7,1]],"id":69685608}],"con":true,"img":false}]}
{"op":"mcm","clk":"11540962394","pt":1719500508467,"mc":[{"id":"1.230178317","rc":[{"atl":[[5.5,2.5],[5.9,25.41]],"id":46611436},{"atl":[[4.5,8.46],[4.9,2.5],[4.2,4.76]],"id":70902601}],"con":true,"img":false}]}
{"op":"mcm","clk":"11540962402","pt":1719500508530,"mc":[{"id":"1.230178317","rc":[{"atb":[[2.22,4.4]],"id":52655636},{"atb":[[1.97,0]],"id":70902601},{"atl":[[4.9,12.5]],"id":70902601}],"con":true,"img":false}]}
{"op":"mcm","clk":"11540962410","pt":1719500508638,"mc":[{"id":"1.230178317","rc":[{"atl":[[3.35,0]],"id":57196226},{"atl":[[4.3,0.84],[4.5,0]],"id":70902601},{"atl":[[5.1,0.84]],"id":49159417}],"con":true,"img":false}]}
{"op":"mcm","clk":"11540962420","pt":1719500508836,"mc":[{"id":"1.230178317","rc":[{"atb":[[1.69,11.08]],"id":57196226}],"con":true,"img":false}]}
{"op":"mcm","clk":"11540962436","pt":1719500509038,"mc":[{"id":"1.230178317","rc":[{"atb":[[2.48,4.62]],"id":49159417}],"con":true,"img":false}]}
{"op":"mcm","clk":"11540962447","pt":1719500509142,"mc":[{"id":"1.230178317","rc":[{"atl":[[3.25,3.38]],"id":57196226},{"atb":[[2.52,2]],"id":49159417}],"con":true,"img":false}]}
{"op":"mcm","clk":"11540962453","pt":1719500509246,"mc":[{"id":"1.230178317","rc":[{"atb":[[2.46,10.24],[2.48,0]],"id":49159417}],"con":true,"img":false}]}
{"op":"mcm","clk":"11540962475","pt":1719500509555,"mc":[{"id":"1.230178317","rc":[{"atb":[[1.71,5.66]],"id":57196226},{"atb":[[1.99,5.71]],"id":70902601},{"atb":[[2.48,3.8]],"id":49159417}],"con":true,"img":false}]}
{"op":"mcm","clk":"11540962483","pt":1719500509660,"mc":[{"id":"1.230178317","rc":[{"atb":[[2.02,2]],"id":70902601}],"con":true,"img":false}]}
{"op":"mcm","clk":"11540962490","pt":1719500509713,"mc":[{"id":"1.230178317","rc":[{"atb":[[2.48,0]],"id":49159417}],"con":true,"img":false}]}
{"op":"mcm","clk":"11540962549","pt":1719500510643,"mc":[{"id":"1.230178317","rc":[{"atb":[[2.66,3.13]],"id":69685608}],"con":true,"img":false}]}
{"op":"mcm","clk":"11540962644","pt":1719500511942,"mc":[{"id":"1.230178317","rc":[{"atl":[[5.3,0.84]],"id":52655636}],"con":true,"img":false}]}
{"op":"mcm","clk":"11540962661","pt":1719500512152,"mc":[{"id":"1.230178317","rc":[{"atl":[[5.3,11.13],[5.2,6.94]],"id":52655636}],"con":true,"img":false}]}
{"op":"mcm","clk":"11540962717","pt":1719500512826,"mc":[{"id":"1.230178317","rc":[{"atb":[[2.22,0]],"id":52655636}],"con":true,"img":false}]}
{"op":"mcm","clk":"11540962734","pt":1719500513034,"mc":[{"id":"1.230178317","rc":[{"atb":[[2.6,2.49],[2.76,5.13]],"id":69685608}],"con":true,"img":false}]}
{"op":"mcm","clk":"11540962803","pt":1719500514057,"mc":[{"id":"1.230178317","rc":[{"atl":[[4.3,6.6],[4.9,2.5]],"id":70902601}],"con":true,"img":false}]}
{"op":"mcm","clk":"11540962814","pt":1719500514196,"mc":[{"id":"1.230178317","rc":[{"atl":[[5.1,1.37]],"id":52655636}],"con":true,"img":false}]}
{"op":"mcm","clk":"11540962817","pt":1719500514267,"mc":[{"id":"1.230178317","rc":[{"atl":[[5.1,8.31]],"id":52655636}],"con":true,"img":false}]}
{"op":"mcm","clk":"11540962828","pt":1719500514334,"mc":[{"id":"1.230178317","rc":[{"atl":[[5.3,0.84]],"id":52655636}],"con":true,"img":false}]}
{"op":"mcm","clk":"11540962864","pt":1719500514756,"mc":[{"id":"1.230178317","rc":[{"atl":[[5.3,0]],"id":52655636},{"atb":[[2.52,5.12],[2.46,2.5]],"id":49159417}],"con":true,"img":false}]}
{"op":"mcm","clk":"11540962917","pt":1719500515460,"mc":[{"id":"1.230178317","rc":[{"atl":[[3.1,7.56]],"id":57196226},{"atl":[[5,11.44]],"id":52655636},{"atb":[[2.78,4.88]],"id":69685608}],"con":true,"img":false}]}
{"op":"mcm","clk":"11540962925","pt":1719500515563,"mc":[{"id":"1.230178317","rc":[{"atb":[[2.02,7.16]],"id":70902601}],"con":true,"img":false}]}
{"op":"mcm","clk":"11540962932","pt":1719500515666,"mc":[{"id":"1.230178317","rc":[{"atl":[[3.3,0]],"id":57196226},{"atl":[[5.2,0]],"id":52655636},{"atb":[[2.74,0],[2.66,0]],"id":69685608}],"con":true,"img":false}]}
{"op":"mcm","clk":"11540962938","pt":1719500515768,"mc":[{"id":"1.230178317","rc":[{"atb":[[1.99,0]],"id":70902601}],"con":true,"img":false}]}
{"op":"mcm","clk":"11540962967","pt":1719500516133,"mc":[{"id":"1.230178317","rc":[{"atl":[[3.05,0.84]],"id":57196226},{"atl":[[4.9,0.84]],"id":52655636}],"con":true,"img":false}]}
{"op":"mcm","clk":"11540962976","pt":1719500516236,"mc":[{"id":"1.230178317","rc":[{"atl":[[3.25,2.54]],"id":57196226},{"atb":[[2.76,3.13]],"id":69685608}],"con":true,"img":false}]}
{"op":"mcm","clk":"11540962988","pt":1719500516342,"mc":[{"id":"1.230178317","rc":[{"atb":[[2.16,10.62]],"id":52655636},{"atb":[[2.8,2],[2.6,10.51]],"id":69685608}],"con":true,"img":false}]}
{"op":"mcm","clk":"11540962994","pt":1719500516434,"mc":[{"id":"1.230178317","rc":[{"atb":[[2.76,0]],"id":69685608}],"con":true,"img":false}]}
{"op":"mcm","clk":"11540963007","pt":1719500516549,"mc":[{"id":"1.230178317","rc":[{"atb":[[2.16,5]],"id":52655636},{"atb":[[2.8,5.13],[2.82,3.38],[2.6,2.5]],"id":69685608}],"con":true,"img":false}]}
{"op":"mcm","clk":"11540963011","pt":1719500516644,"mc":[{"id":"1.230178317","rc":[{"atb":[[2.78,5]],"id":69685608}],"con":true,"img":false}]}
{"op":"mcm","clk":"11540963016","pt":1719500516741,"mc":[{"id":"1.230178317","rc":[{"atb":[[2.8,2]],"id":69685608}],"con":true,"img":false}]}
{"op":"mcm","clk":"11540963068","pt":1719500517465,"mc":[{"id":"1.230178317","rc":[{"atl":[[3.25,0]],"id":57196226}],"con":true,"img":false}]}
{"op":"mcm","clk":"11540963130","pt":1719500518649,"mc":[{"id":"1.230178317","rc":[{"atb":[[2.8,0]],"id":69685608}],"con":true,"img":false}]}
{"op":"mcm","clk":"11540963135","pt":1719500518741,"mc":[{"id":"1.230178317","rc":[{"atb":[[2.82,0],[2.6,10.88],[2.84,2]],"id":69685608}],"con":true,"img":false}]}
{"op":"mcm","clk":"11540963142","pt":1719500518853,"mc":[{"id":"1.230178317","rc":[{"atb":[[2.8,4.41],[2.78,0]],"id":69685608}],"con":true,"img":false}]}
{"op":"mcm","clk":"11540963161","pt":1719500519261,"mc":[{"id":"1.230178317","rc":[{"atb":[[1.67,0],[1.74,2.11]],"id":57196226}],"con":true,"img":false}]}
{"op":"mcm","clk":"11540963165","pt":1719500519367,"mc":[{"id":"1.230178317","rc":[{"atb":[[1.74,7.95]],"id":57196226}],"con":true,"img":false}]}
{"op":"mcm","clk":"11540963178","pt":1719500519575,"mc":[{"id":"1.230178317","rc":[{"atb":[[1.72,2]],"id":57196226},{"atb":[[2.52,9.34]],"id":49159417}],"con":true,"img":false}]}
{"op":"mcm","clk":"11540963186","pt":1719500519676,"mc":[{"id":"1.230178317","rc":[{"atb":[[2.5,0.12]],"id":49159417}],"con":true,"img":false}]}
{"op":"mcm","clk":"11540963201","pt":1719500519876,"mc":[{"id":"1.230178317","rc":[{"atb":[[2.84,0]],"id":69685608},{"atl":[[5.1,3.46]],"id":49159417}],"con":true,"img":false}]}
{"op":"mcm","clk":"11540963212","pt":1719500519939,"mc":[{"id":"1.230178317","rc":[{"atb":[[2.82,2]],"id":69685608},{"atl":[[5.2,0]],"id":49159417}],"con":true,"img":false}]}
{"op":"mcm","clk":"11540963232","pt":1719500520250,"mc":[{"id":"1.230178317","rc":[{"atl":[[4,5.16]],"id":70902601}],"con":true,"img":false}]}
{"op":"mcm","clk":"11540963246","pt":1719500520458,"mc":[{"id":"1.230178317","rc":[{"atb":[[1.72,0]],"id":57196226},{"atl":[[4.2,0]],"id":70902601}],"con":true,"img":false}]}
{"op":"mcm","clk":"11540963255","pt":1719500520556,"mc":[{"id":"1.230178317","rc":[{"atb":[[1.75,2]],"id":57196226}],"con":true,"img":false}]}
{"op":"mcm","clk":"11540963263","pt":1719500520666,"mc":[{"id":"1.230178317","rc":[{"atb":[[1.71,0]],"id":57196226},{"atl":[[3.95,0.84]],"id":70902601}],"con":true,"img":false}]}
{"op":"mcm","clk":"11540963271","pt":1719500520780,"mc":[{"id":"1.230178317","rc":[{"atl":[[4.3,5.76]],"id":70902601}],"con":true,"img":false}]}
{"op":"mcm","clk":"11540963279","pt":1719500520870,"mc":[{"id":"1.230178317","rc":[{"atl":[[4.3,0],[4.1,7.01]],"id":70902601}],"con":true,"img":false}]}
{"op":"mcm","clk":"11540963388","pt":1719500522163,"mc":[{"id":"1.230178317","rc":[{"atb":[[1.76,2.54]],"id":57196226},{"atb":[[2.44,2.54]],"id":46611436},{"atb":[[2.26,2.54]],"id":52655636},{"atb":[[2.04,2.54]],"id":70902601},{"atb":[[2.84,2.54]],"id":69685608},{"atb":[[2.54,2.54]],"id":49159417}],"con":true,"img":false}]}
{"op":"mcm","clk":"11540963395","pt":1719500522262,"mc":[{"id":"1.230178317","rc":[{"atb":[[2.26,17.31]],"id":52655636}],"con":true,"img":false}]}
{"op":"mcm","clk":"11540963403","pt":1719500522367,"mc":[{"id":"1.230178317","rc":[{"atb":[[2.44,9.36]],"id":46611436}],"con":true,"img":false}]}
{"op":"mcm","clk":"11540963410","pt":1719500522470,"mc":[{"id":"1.230178317","rc":[{"atb":[[2.24,4.61]],"id":52655636}],"con":true,"img":false}]}
{"op":"mcm","clk":"11540963417","pt":1719500522574,"mc":[{"id":"1.230178317","rc":[{"atb":[[2.42,2]],"id":46611436}],"con":true,"img":false}]}
{"op":"mcm","clk":"11540963432","pt":1719500522785,"mc":[{"id":"1.230178317","rc":[{"atb":[[2.4,0]],"id":46611436}],"con":true,"img":false}]}
{"op":"mcm","clk":"11540963538","pt":1719500523871,"mc":[{"id":"1.230178317","rc":[{"atb":[[2.82,0]],"id":69685608}],"con":true,"img":false}]}
{"op":"mcm","clk":"11540963548","pt":1719500523971,"mc":[{"id":"1.230178317","rc":[{"atb":[[2.86,2]],"id":69685608}],"con":true,"img":false}]}
{"op":"mcm","clk":"11540963556","pt":1719500524074,"mc":[{"id":"1.230178317","rc":[{"atb":[[2.6,2.49],[2.84,6.95]],"id":69685608}],"con":true,"img":false}]}
{"op":"mcm","clk":"11540963591","pt":1719500524477,"mc":[{"id":"1.230178317","rc":[{"atb":[[2.52,7.34]],"id":49159417}],"con":true,"img":false}]}
{"op":"mcm","clk":"11540963598","pt":1719500524580,"mc":[{"id":"1.230178317","rc":[{"atb":[[2.56,2]],"id":49159417}],"con":true,"img":false}]}
{"op":"mcm","clk":"11540963625","pt":1719500524949,"mc":[{"id":"1.230178317","rc":[{"atb":[[1.75,0]],"id":57196226}],"con":true,"img":false}]}
{"op":"mcm","clk":"11540963636","pt":1719500525056,"mc":[{"id":"1.230178317","rc":[{"atb":[[1.77,2]],"id":57196226}],"con":true,"img":false}]}
{"op":"mcm","clk":"11540963653","pt":1719500525262,"mc":[{"id":"1.230178317","rc":[{"atl":[[3.45,0],[3.15,9.41]],"id":57196226},{"atb":[[2.2,10],[2.26,17.5]],"id":46611436},{"atl":[[5,4.22],[5.2,1]],"id":46611436},{"atb":[[2.24,39.23],[2.2,0]],"id":52655636},{"atl":[[4.5,1],[4.1,6.01]],"id":70902601},{"atb":[[2.56,4.54],[2.52,4.22]],"id":49159417}],"con":true,"img":false}]}
{"op":"mcm","clk":"11540963664","pt":1719500525363,"mc":[{"id":"1.230178317","rc":[{"atl":[[5.5,12.96],[5.9,5]],"id":46611436}],"con":true,"img":false}]}
{"op":"mcm","clk":"11540963690","pt":1719500525678,"mc":[{"id":"1.230178317","rc":[{"atl":[[5,5.22],[5.2,0]],"id":46611436},{"atb":[[2.02,5.16]],"id":70902601},{"atl":[[4.5,0],[4.1,7.01]],"id":70902601}],"con":true,"img":false}]}
{"op":"mcm","clk":"11540963697","pt":1719500525778,"mc":[{"id":"1.230178317","rc":[{"atb":[[1.65,5]],"id":57196226},{"atb":[[2.4,3.92]],"id":46611436},{"atb":[[2.06,2]],"id":70902601}],"con":true,"img":false}]}
{"op":"mcm","clk":"11540963706","pt":1719500525881,"mc":[{"id":"1.230178317","rc":[{"atl":[[5.5,2.5],[5.9,23.19]],"id":46611436},{"atb":[[2.84,4.41]],"id":69685608},{"atb":[[2.54,0]],"id":49159417}],"con":true,"img":false}]}
{"op":"mcm","clk":"11540963727","pt":1719500526080,"mc":[{"id":"1.230178317","rc":[{"atb":[[1.73,7.58]],"id":57196226}],"con":true,"img":false}]}
{"op":"mcm","clk":"11540963751","pt":1719500526348,"mc":[{"id":"1.230178317","rc":[{"atb":[[2.42,0]],"id":46611436}],"con":true,"img":false}]}
{"op":"mcm","clk":"11540963761","pt":1719500526455,"mc":[{"id":"1.230178317","rc":[{"atb":[[2.46,2]],"id":46611436}],"con":true,"img":false}]}
{"op":"mcm","clk":"11540963786","pt":1719500526760,"mc":[{"id":"1.230178317","rc":[{"atb":[[2,7.67]],"id":70902601}],"con":true,"img":false}]}
{"op":"mcm","clk":"11540963809","pt":1719500527082,"mc":[{"id":"1.230178317","rc":[{"atl":[[3.05,10.95]],"id":57196226},{"atl":[[4.9,15.65]],"id":52655636},{"atb":[[2.88,5.18]],"id":69685608}],"con":true,"img":false}]}
{"op":"mcm","clk":"11540963820","pt":1719500527176,"mc":[{"id":"1.230178317","rc":[{"atb":[[1.76,0]],"id":57196226},{"atb":[[2.4,0]],"id":46611436},{"atb":[[2.04,0],[2.06,7.78]],"id":70902601}],"con":true,"img":false}]}
{"op":"mcm","clk":"11540963830","pt":1719500527284,"mc":[{"id":"1.230178317","rc":[{"atl":[[3.1,0]],"id":57196226},{"atl":[[5,0]],"id":52655636},{"atb":[[2.8,0]],"id":69685608}],"con":true,"img":false}]}
{"op":"mcm","clk":"11540963835","pt":1719500527377,"mc":[{"id":"1.230178317","rc":[{"atb":[[2.02,0]],"id":70902601}],"con":true,"img":false}]}
{"op":"mcm","clk":"11540963861","pt":1719500527691,"mc":[{"id":"1.230178317","rc":[{"atl":[[5.1,7.46]],"id":52655636}],"con":true,"img":false}]}
{"op":"mcm","clk":"11540963866","pt":1719500527752,"mc":[{"id":"1.230178317","rc":[{"atl":[[5.6,22.74],[5.1,0.52]],"id":52655636}],"con":true,"img":false}]}
{"op":"mcm","clk":"11540963891","pt":1719500528063,"mc":[{"id":"1.230178317","rc":[{"atl":[[5,4.22],[5.2,1]],"id":46611436},{"atl":[[5.6,21.74],[5.8,1]],"id":52655636},{"atl":[[4.5,1],[4.1,6.01]],"id":70902601}],"con":true,"img":false}]}
{"op":"mcm","clk":"11540963902","pt":1719500528177,"mc":[{"id":"1.230178317","rc":[{"atl":[[5.5,12.96],[5.9,4.99]],"id":46611436}],"con":true,"img":false}]}
{"op":"mcm","clk":"11540963949","pt":1719500528687,"mc":[{"id":"1.230178317","rc":[{"atb":[[2.86,0]],"id":69685608}],"con":true,"img":false}]}
{"op":"mcm","clk":"11540963958","pt":1719500528792,"mc":[{"id":"1.230178317","rc":[{"atb":[[2.9,2]],"id":69685608}],"con":true,"img":false}]}
{"op":"mcm","clk":"11540963966","pt":1719500528885,"mc":[{"id":"1.230178317","rc":[{"atb":[[2.92,5.18],[2.88,0],[2.6,12.09],[2.84,0]],"id":69685608}],"con":true,"img":false}]}
{"op":"mcm","clk":"11540963980","pt":1719500529052,"mc":[{"id":"1.230178317","rc":[{"atb":[[1.77,0]],"id":57196226}],"con":true,"img":false}]}
{"op":"mcm","clk":"11540963987","pt":1719500529155,"mc":[{"id":"1.230178317","rc":[{"atb":[[1.75,2]],"id":57196226}],"con":true,"img":false}]}
{"op":"mcm","clk":"11540964016","pt":1719500529563,"mc":[{"id":"1.230178317","rc":[{"atb":[[2.44,6.82]],"id":46611436}],"con":true,"img":false}]}
{"op":"mcm","clk":"11540964026","pt":1719500529675,"mc":[{"id":"1.230178317","rc":[{"atl":[[5.1,0]],"id":52655636}],"con":true,"img":false}]}
{"op":"mcm","clk":"11540964057","pt":1719500530082,"mc":[{"id":"1.230178317","rc":[{"atb":[[2.22,4.4]],"id":52655636}],"con":true,"img":false}]}
{"op":"mcm","clk":"11540964102","pt":1719500530561,"mc":[{"id":"1.230178317","rc":[{"atl":[[3.1,21.92],[3.15,1]],"id":57196226}],"con":true,"img":false}]}
{"op":"mcm","clk":"11540964131","pt":1719500530868,"mc":[{"id":"1.230178317","rc":[{"atb":[[1.75,17.81]],"id":57196226},{"atb":[[2.46,5]],"id":46611436},{"atb":[[2.28,3.4]],"id":52655636},{"atl":[[4.8,0.52]],"id":52655636},{"atb":[[2.08,3]],"id":70902601},{"atb":[[2.58,3]],"id":49159417}],"con":true,"img":false}]}
{"op":"mcm","clk":"11540964140","pt":1719500530970,"mc":[{"id":"1.230178317","rc":[{"atb":[[1.74,2.11]],"id":57196226},{"atb":[[2.58,7.22],[2.56,2]],"id":49159417}],"con":true,"img":false}]}
{"op":"mcm","clk":"11540964146","pt":1719500531076,"mc":[{"id":"1.230178317","rc":[{"atb":[[2.6,4.48]],"id":49159417}],"con":true,"img":false}]}
{"op":"mcm","clk":"11540964167","pt":1719500531300,"mc":[{"id":"1.230178317","rc":[{"atb":[[2,2.11]],"id":70902601},{"atb":[[2.52,0]],"id":49159417}],"con":true,"img":false}]}
{"op":"mcm","clk":"11540964189","pt":1719500531481,"mc":[{"id":"1.230178317","rc":[{"atb":[[1.74,0],[1.78,2.11]],"id":57196226},{"atb":[[2.32,2.11],[2.24,37.12]],"id":52655636}],"con":true,"img":false}]}
{"op":"mcm","clk":"11540964212","pt":1719500531784,"mc":[{"id":"1.230178317","rc":[{"atb":[[2.22,0]],"id":52655636},{"atl":[[3.95,6.96]],"id":70902601}],"con":true,"img":false}]}
{"op":"mcm","clk":"11540964229","pt":1719500531990,"mc":[{"id":"1.230178317","rc":[{"atl":[[4,0]],"id":70902601}],"con":true,"img":false}]}
{"op":"mcm","clk":"11540964242","pt":1719500532056,"mc":[{"id":"1.230178317","rc":[{"atb":[[2.52,3.7]],"id":49159417}],"con":true,"img":false}]}
{"op":"mcm","clk":"11540964251","pt":1719500532155,"mc":[{"id":"1.230178317","rc":[{"atl":[[5.8,5],[5.4,2.5]],"id":46611436},{"atl":[[4.5,13.98],[4.1,0]],"id":70902601},{"atb":[[2.54,5],[2.52,0],[2.6,9.59],[2.44,0],[2.62,2.5]],"id":69685608}],"con":true,"img":false}]}
{"op":"mcm","clk":"11540964262","pt":1719500532262,"mc":[{"id":"1.230178317","rc":[{"atl":[[5.5,0],[5.3,5.23],[6.6,0],[5.9,0]],"id":46611436}],"con":true,"img":false}]}
{"op":"mcm","clk":"11540964278","pt":1719500532466,"mc":[{"id":"1.230178317","rc":[{"atb":[[2.9,0]],"id":69685608}],"con":true,"img":false}]}
{"op":"mcm","clk":"11540964289","pt":1719500532573,"mc":[{"id":"1.230178317","rc":[{"atb":[[2.94,2]],"id":69685608}],"con":true,"img":false}]}
{"op":"mcm","clk":"11540964300","pt":1719500532675,"mc":[{"id":"1.230178317","rc":[{"atb":[[2.92,0],[2.96,3.75]],"id":69685608}],"con":true,"img":false}]}
{"op":"mcm","clk":"11540964335","pt":1719500533087,"mc":[{"id":"1.230178317","rc":[{"atb":[[1.73,13.24]],"id":57196226}],"con":true,"img":false}]}
{"op":"mcm","clk":"11540964351","pt":1719500533288,"mc":[{"id":"1.230178317","rc":[{"atb":[[2.26,14.77]],"id":52655636}],"con":true,"img":false}]}
{"op":"mcm","clk":"11540964363","pt":1719500533351,"mc":[{"id":"1.230178317","rc":[{"atb":[[2.56,0]],"id":49159417}],"con":true,"img":false}]}
{"op":"mcm","clk":"11540964375","pt":1719500533462,"mc":[{"id":"1.230178317","rc":[{"atb":[[2.62,2]],"id":49159417}],"con":true,"img":false}]}
{"op":"mcm","clk":"11540964403","pt":1719500533763,"mc":[{"id":"1.230178317","rc":[{"atb":[[2.32,15.74]],"id":52655636}],"con":true,"img":false}]}
{"op":"mcm","clk":"11540964411","pt":1719500533876,"mc":[{"id":"1.230178317","rc":[{"atb":[[2.46,11.92]],"id":46611436}],"con":true,"img":false}]}
{"op":"mcm","clk":"11540964420","pt":1719500533975,"mc":[{"id":"1.230178317","rc":[{"atb":[[2.26,0]],"id":52655636}],"con":true,"img":false}]}
{"op":"mcm","clk":"11540964426","pt":1719500534072,"mc":[{"id":"1.230178317","rc":[{"atb":[[1.75,15.81]],"id":57196226},{"atb":[[2.44,0]],"id":46611436},{"atb":[[2.94,9.5]],"id":69685608}],"con":true,"img":false}]}
{"op":"mcm","clk":"11540964436","pt":1719500534174,"mc":[{"id":"1.230178317","rc":[{"atb":[[1.79,2]],"id":57196226},{"atb":[[2.92,5.75],[2.6,0]],"id":69685608},{"atb":[[2.52,0]],"id":49159417}],"con":true,"img":false}]}
{"op":"mcm","clk":"11540964442","pt":1719500534275,"mc":[{"id":"1.230178317","rc":[{"atb":[[2.94,2]],"id":69685608}],"con":true,"img":false}]}
{"op":"mcm","clk":"11540964475","pt":1719500534782,"mc":[{"id":"1.230178317","rc":[{"atb":[[2.06,5.78]],"id":70902601}],"con":true,"img":false}]}
{"op":"mcm","clk":"11540964482","pt":1719500534892,"mc":[{"id":"1.230178317","rc":[{"atb":[[2.1,2]],"id":70902601}],"con":true,"img":false}]}
{"op":"mcm","clk":"11540964655","pt":1719500537292,"mc":[{"id":"1.230178317","rc":[{"atl":[[4.5,1],[4.9,23.45]],"id":70902601}],"con":true,"img":false}]}
{"op":"mcm","clk":"11540964698","pt":1719500537763,"mc":[{"id":"1.230178317","rc":[{"atb":[[2.94,0]],"id":69685608}],"con":true,"img":false}]}
{"op":"mcm","clk":"11540964702","pt":1719500537861,"mc":[{"id":"1.230178317","rc":[{"atb":[[2.98,2]],"id":69685608}],"con":true,"img":false}]}
{"op":"mcm","clk":"11540964710","pt":1719500537974,"mc":[{"id":"1.230178317","rc":[{"atb":[[3,4.69],[2.96,0]],"id":69685608}],"con":true,"img":false}]}
{"op":"mcm","clk":"11540964751","pt":1719500538489,"mc":[{"id":"1.230178317","rc":[{"spn":2.42,"spf":"NaN","id":57196226},{"spn":3.73,"spf":"NaN","id":46611436},{"atl":[[4.7,21.62]],"id":52655636},{"spn":3.51,"spf":"NaN","id":52655636},{"spn":3.02,"spf":"NaN","id":70902601},{"spn":4.7,"spf":"NaN","id":69685608},{"spn":3.86,"spf":"NaN","id":49159417}],"con":true,"img":false}]}
{"op":"mcm","clk":"11540964760","pt":1719500538586,"mc":[{"id":"1.230178317","rc":[{"atb":[[2.22,5.88]],"id":52655636},{"atl":[[4.9,16.5]],"id":52655636},{"atb":[[2.1,8.59]],"id":70902601}],"con":true,"img":false}]}
{"op":"mcm","clk":"11540964770","pt":1719500538691,"mc":[{"id":"1.230178317","rc":[{"atl":[[5.6,0]],"id":52655636},{"atb":[[2.06,0]],"id":70902601}],"con":true,"img":false}]}
{"op":"mcm","clk":"11540964799","pt":1719500538995,"mc":[{"id":"1.230178317","rc":[{"atb":[[2.22,0]],"id":52655636}],"con":true,"img":false}]}
{"op":"mcm","clk":"11540964814","pt":1719500539158,"mc":[{"id":"1.230178317","rc":[{"atl":[[4.6,0.84],[4.9,15.66]],"id":52655636}],"con":true,"img":false}]}
{"op":"mcm","clk":"11540964826","pt":1719500539362,"mc":[{"id":"1.230178317","rc":[{"atb":[[2.92,0],[2.98,11.38]],"id":69685608}],"con":true,"img":false}]}
{"op":"mcm","clk":"11540964834","pt":1719500539475,"mc":[{"id":"1.230178317","rc":[{"atb":[[2.92,6.69],[2.98,1.99]],"id":69685608}],"con":true,"img":false}]}
{"op":"mcm","clk":"11540964838","pt":1719500539565,"mc":[{"id":"1.230178317","rc":[{"atb":[[2.98,9.38]],"id":69685608}],"con":true,"img":false}]}
{"op":"mcm","clk":"11540964849","pt":1719500539676,"mc":[{"id":"1.230178317","rc":[{"atb":[[2.92,0],[3.05,2]],"id":69685608}],"con":true,"img":false}]}
{"op":"mcm","clk":"11540964867","pt":1719500539880,"mc":[{"id":"1.230178317","rc":[{"atb":[[3.1,5.32]],"id":69685608}],"con":true,"img":false}]}
{"op":"mcm","clk":"11540964885","pt":1719500540088,"mc":[{"id":"1.230178317","rc":[{"atb":[[3,0]],"id":69685608}],"con":true,"img":false}]}
{"op":"mcm","clk":"11540964916","pt":1719500540494,"mc":[{"id":"1.230178317","rc":[{"atb":[[3.05,0]],"id":69685608}],"con":true,"img":false}]}
{"op":"mcm","clk":"11540964926","pt":1719500540560,"mc":[{"id":"1.230178317","rc":[{"atb":[[1.69,2.5]],"id":57196226},{"atb":[[3.15,2]],"id":69685608}],"con":true,"img":false}]}
{"op":"mcm","clk":"11540964937","pt":1719500540666,"mc":[{"id":"1.230178317","rc":[{"atb":[[3.2,5.32],[3.1,0]],"id":69685608}],"con":true,"img":false}]}
{"op":"mcm","clk":"11540964976","pt":1719500541085,"mc":[{"id":"1.230178317","rc":[{"atb":[[1.8,7.4]],"id":57196226}],"con":true,"img":false}]}
{"op":"mcm","clk":"11540965022","pt":1719500541699,"mc":[{"id":"1.230178317","rc":[{"atb":[[3.15,0]],"id":69685608}],"con":true,"img":false}]}
{"op":"mcm","clk":"11540965030","pt":1719500541759,"mc":[{"id":"1.230178317","rc":[{"atb":[[3.2,0],[3.25,2]],"id":69685608}],"con":true,"img":false}]}
{"op":"mcm","clk":"11540965036","pt":1719500541861,"mc":[{"id":"1.230178317","rc":[{"atb":[[3.15,5.32]],"id":69685608}],"con":true,"img":false}]}
{"op":"mcm","clk":"11540965057","pt":1719500542171,"mc":[{"id":"1.230178317","rc":[{"atb":[[1.8,14.55],[1.79,0]],"id":57196226}],"con":true,"img":false}]}
{"op":"mcm","clk":"11540965066","pt":1719500542278,"mc":[{"id":"1.230178317","rc":[{"atb":[[1.73,12.1],[1.81,2],[1.74,4.53]],"id":57196226}],"con":true,"img":false}]}
{"op":"mcm","clk":"11540965073","pt":1719500542377,"mc":[{"id":"1.230178317","rc":[{"atb":[[1.75,4.15]],"id":57196226},{"atb":[[2.62,6.48]],"id":49159417}],"con":true,"img":false}]}
{"op":"mcm","clk":"11540965082","pt":1719500542482,"mc":[{"id":"1.230178317","rc":[{"atb":[[1.74,0]],"id":57196226},{"atb":[[2.6,0]],"id":49159417}],"con":true,"img":false}]}
{"op":"mcm","clk":"11540965100","pt":1719500542688,"mc":[{"id":"1.230178317","rc":[{"atb":[[1.73,4.52]],"id":57196226}],"con":true,"img":false}]}
{"op":"mcm","clk":"11540965109","pt":1719500542794,"mc":[{"id":"1.230178317","rc":[{"atb":[[1.73,0]],"id":57196226}],"con":true,"img":false}]}
{"op":"mcm","clk":"11540965116","pt":1719500542898,"mc":[{"id":"1.230178317","rc":[{"atb":[[1.8,21.47]],"id":57196226}],"con":true,"img":false}]}
{"op":"mcm","clk":"11540965125","pt":1719500543103,"mc":[{"id":"1.230178317","rc":[{"atl":[[3.9,7.48]],"id":70902601}],"con":true,"img":false}]}
{"op":"mcm","clk":"11540965132","pt":1719500543199,"mc":[{"id":"1.230178317","rc":[{"atl":[[4.5,14.94],[3.95,0.84]],"id":70902601}],"con":true,"img":false}]}
{"op":"mcm","clk":"11540965139","pt":1719500543302,"mc":[{"id":"1.230178317","rc":[{"atl":[[4.9,2.5]],"id":70902601},{"atb":[[3.25,0]],"id":69685608}],"con":true,"img":false}]}
{"op":"mcm","clk":"11540965145","pt":1719500543364,"mc":[{"id":"1.230178317","rc":[{"atb":[[3.2,2]],"id":69685608}],"con":true,"img":false}]}
{"op":"mcm","clk":"11540965175","pt":1719500543782,"mc":[{"id":"1.230178317","rc":[{"atl":[[3.85,0.84]],"id":70902601}],"con":true,"img":false}]}
{"op":"mcm","clk":"11540965186","pt":1719500543985,"mc":[{"id":"1.230178317","rc":[{"atb":[[3.25,5.32]],"id":69685608}],"con":true,"img":false}]}
{"op":"mcm","clk":"11540965197","pt":1719500544188,"mc":[{"id":"1.230178317","rc":[{"atb":[[3.15,0]],"id":69685608}],"con":true,"img":false}]}
{"op":"mcm","clk":"11540965235","pt":1719500544697,"mc":[{"id":"1.230178317","rc":[{"atb":[[2.98,0],[3.15,7.32]],"id":69685608}],"con":true,"img":false}]}
{"op":"mcm","clk":"11540965260","pt":1719500544967,"mc":[{"id":"1.230178317","rc":[{"atb":[[1.75,0]],"id":57196226},{"atb":[[2.46,8.92]],"id":46611436},{"atb":[[2.28,0]],"id":52655636},{"atb":[[2.08,0]],"id":70902601},{"atb":[[2.58,4.22]],"id":49159417}],"con":true,"img":false}]}
{"op":"mcm","clk":"11540965268","pt":1719500545065,"mc":[{"id":"1.230178317","rc":[{"atb":[[1.81,4.6]],"id":57196226},{"atb":[[2.48,2]],"id":46611436},{"atb":[[2.34,2.5]],"id":52655636},{"atb":[[2.12,2.06]],"id":70902601},{"atb":[[2.64,2]],"id":49159417}],"con":true,"img":false}]}
{"op":"mcm","clk":"11540965278","pt":1719500545171,"mc":[{"id":"1.230178317","rc":[{"atb":[[2.48,7.05]],"id":46611436},{"atb":[[2.34,16.19]],"id":52655636}],"con":true,"img":false}]}
{"op":"mcm","clk":"11540965297","pt":1719500545392,"mc":[{"id":"1.230178317","rc":[{"atb":[[2.46,2]],"id":46611436},{"atb":[[2.32,2.11]],"id":52655636}],"con":true,"img":false}]}
{"op":"mcm","clk":"11540965305","pt":1719500545488,"mc":[{"id":"1.230178317","rc":[{"atb":[[3.2,0]],"id":69685608}],"con":true,"img":false}]}
{"op":"mcm","clk":"11540965314","pt":1719500545588,"mc":[{"id":"1.230178317","rc":[{"atb":[[3.3,2]],"id":69685608}],"con":true,"img":false}]}
{"op":"mcm","clk":"11540965321","pt":1719500545686,"mc":[{"id":"1.230178317","rc":[{"atb":[[3.35,5.32],[3.25,0]],"id":69685608}],"con":true,"img":false}]}
{"op":"mcm","clk":"11540965351","pt":1719500546098,"mc":[{"id":"1.230178317","rc":[{"atl":[[4.8,0]],"id":52655636}],"con":true,"img":false}]}
{"op":"mcm","clk":"11540965397","pt":1719500546570,"mc":[{"id":"1.230178317","rc":[{"atb":[[3.35,14.49],[3.3,0]],"id":69685608},{"atl":[[7.8,3.35]],"id":69685608}],"con":true,"img":false}]}
{"op":"mcm","clk":"11540965401","pt":1719500546667,"mc":[{"id":"1.230178317","rc":[{"atb":[[3.4,2]],"id":69685608}],"con":true,"img":false}]}
{"op":"mcm","clk":"11540965426","pt":1719500547085,"mc":[{"id":"1.230178317","rc":[{"atb":[[2.62,4.48]],"id":49159417}],"con":true,"img":false}]}
{"op":"mcm","clk":"11540965434","pt":1719500547187,"mc":[{"id":"1.230178317","rc":[{"atb":[[2.66,2]],"id":49159417}],"con":true,"img":false}]}
{"op":"mcm","clk":"11540965440","pt":1719500547283,"mc":[{"id":"1.230178317","rc":[{"atb":[[3.35,5.32]],"id":69685608}],"con":true,"img":false}]}
{"op":"mcm","clk":"11540965461","pt":1719500547501,"mc":[{"id":"1.230178317","rc":[{"atb":[[2.46,5.79]],"id":46611436},{"atb":[[2.1,6.59]],"id":70902601}],"con":true,"img":false}]}
{"op":"mcm","clk":"11540965469","pt":1719500547596,"mc":[{"id":"1.230178317","rc":[{"atb":[[2.14,2]],"id":70902601}],"con":true,"img":false}]}
{"op":"mcm","clk":"11540965478","pt":1719500547697,"mc":[{"id":"1.230178317","rc":[{"atb":[[2.42,2.11],[2.34,0]],"id":46611436},{"atb":[[2.32,0],[2.4,2.11]],"id":52655636}],"con":true,"img":false}]}
{"op":"mcm","clk":"11540965496","pt":1719500547902,"mc":[{"id":"1.230178317","rc":[{"atb":[[2.46,3.79]],"id":46611436}],"con":true,"img":false}]}
{"op":"mcm","clk":"11540965503","pt":1719500548007,"mc":[{"id":"1.230178317","rc":[{"atb":[[2.5,2]],"id":46611436}],"con":true,"img":false}]}
{"op":"mcm","clk":"11540965512","pt":1719500548101,"mc":[{"id":"1.230178317","rc":[{"atb":[[3.4,11.78]],"id":69685608}],"con":true,"img":false}]}
{"op":"mcm","clk":"11540965527","pt":1719500548306,"mc":[{"id":"1.230178317","rc":[{"atl":[[4.5,1],[3.95,9.17]],"id":70902601}],"con":true,"img":false}]}
{"op":"mcm","clk":"11540965546","pt":1719500548476,"mc":[{"id":"1.230178317","rc":[{"atb":[[2.08,5.16]],"id":70902601}],"con":true,"img":false}]}
{"op":"mcm","clk":"11540965599","pt":1719500549191,"mc":[{"id":"1.230178317","rc":[{"atb":[[3.45,7.44]],"id":69685608}],"con":true,"img":false}]}
{"op":"mcm","clk":"11540965608","pt":1719500549294,"mc":[{"id":"1.230178317","rc":[{"atl":[[4.6,1.37]],"id":52655636}],"con":true,"img":false}]}
{"op":"mcm","clk":"11540965616","pt":1719500549403,"mc":[{"id":"1.230178317","rc":[{"atl":[[4.6,17.03]],"id":52655636},{"atb":[[3.35,0],[3.4,11.37]],"id":69685608}],"con":true,"img":false}]}
{"op":"mcm","clk":"11540965625","pt":1719500549497,"mc":[{"id":"1.230178317","rc":[{"atl":[[4.9,0]],"id":52655636}],"con":true,"img":false}]}
{"op":"mcm","clk":"11540965633","pt":1719500549598,"mc":[{"id":"1.230178317","rc":[{"atl":[[4.5,22.86]],"id":52655636}],"con":true,"img":false}]}
{"op":"mcm","clk":"11540965642","pt":1719500549704,"mc":[{"id":"1.230178317","rc":[{"atl":[[4.7,0]],"id":52655636},{"atb":[[2.14,8.49]],"id":70902601},{"atb":[[3.4,2]],"id":69685608}],"con":true,"img":false}]}
{"op":"mcm","clk":"11540965650","pt":1719500549799,"mc":[{"id":"1.230178317","rc":[{"atb":[[3.45,16.81]],"id":69685608}],"con":true,"img":false}]}
{"op":"mcm","clk":"11540965658","pt":1719500549901,"mc":[{"id":"1.230178317","rc":[{"atb":[[2.1,0]],"id":70902601}],"con":true,"img":false}]}
{"op":"mcm","clk":"11540965664","pt":1719500550005,"mc":[{"id":"1.230178317","rc":[{"atb":[[1.03,3.4],[1.04,3.4]],"id":69685608},{"atl":[[1000,6.98]],"id":69685608}],"con":true,"img":false}]}
{"op":"mcm","clk":"11540965674","pt":1719500550109,"mc":[{"id":"1.230178317","rc":[{"atb":[[3.4,0]],"id":69685608}],"con":true,"img":false}]}
{"op":"mcm","clk":"11540965683","pt":1719500550211,"mc":[{"id":"1.230178317","rc":[{"atb":[[1.03,0.15],[3.5,2],[1.04,0.14]],"id":69685608},{"atl":[[1000,0.31]],"id":69685608}],"con":true,"img":false}]}
{"op":"mcm","clk":"11540965692","pt":1719500550270,"mc":[{"id":"1.230178317","rc":[{"atl":[[4.4,0.84]],"id":52655636}],"con":true,"img":false}]}
{"op":"mcm","clk":"11540965709","pt":1719500550484,"mc":[{"id":"1.230178317","rc":[{"atb":[[1.03,0],[1.04,0]],"id":69685608},{"atl":[[1000,0.16]],"id":69685608}],"con":true,"img":false}]}
{"op":"mcm","clk":"11540965715","pt":1719500550579,"mc":[{"id":"1.230178317","rc":[{"atb":[[3.5,2.29]],"id":69685608},{"atl":[[6.2,0.14]],"id":69685608}],"con":true,"img":false}]}
{"op":"mcm","clk":"11540965743","pt":1719500550996,"mc":[{"id":"1.230178317","rc":[{"atb":[[3.45,15.93],[3.5,7.47]],"id":69685608}],"con":true,"img":false}]}
{"op":"mcm","clk":"11540965753","pt":1719500551198,"mc":[{"id":"1.230178317","rc":[{"atb":[[3.45,8.49]],"id":69685608}],"con":true,"img":false}]}
{"op":"mcm","clk":"11540965761","pt":1719500551399,"mc":[{"id":"1.230178317","rc":[{"atl":[[4.7,10.07]],"id":52655636},{"atb":[[3.45,0]],"id":69685608}],"con":true,"img":false}]}
{"op":"mcm","clk":"11540965770","pt":1719500551503,"mc":[{"id":"1.230178317","rc":[{"atb":[[3.5,15.96]],"id":69685608}],"con":true,"img":false}]}
{"op":"mcm","clk":"11540965774","pt":1719500551602,"mc":[{"id":"1.230178317","rc":[{"atb":[[2.3,4.17]],"id":52655636},{"atl":[[4.7,0]],"id":52655636}],"con":true,"img":false}]}
{"op":"mcm","clk":"11540965800","pt":1719500551979,"mc":[{"id":"1.230178317","rc":[{"atb":[[3.5,7.47]],"id":69685608}],"con":true,"img":false}]}
{"op":"mcm","clk":"11540965821","pt":1719500552299,"mc":[{"id":"1.230178317","rc":[{"atb":[[3.5,5.47]],"id":69685608}],"con":true,"img":false}]}
{"op":"mcm","clk":"11540965831","pt":1719500552394,"mc":[{"id":"1.230178317","rc":[{"atb":[[1.02,24.65],[3.15,0],[2.62,15.3]],"id":69685608}],"con":true,"img":false}]}
{"op":"mcm","clk":"11540965896","pt":1719500553312,"mc":[{"id":"1.230178317","rc":[{"atb":[[1.81,16.27]],"id":57196226}],"con":true,"img":false}]}
{"op":"mcm","clk":"11540965901","pt":1719500553415,"mc":[{"id":"1.230178317","rc":[{"atb":[[2.08,0]],"id":70902601}],"con":true,"img":false}]}
{"op":"mcm","clk":"11540965910","pt":1719500553518,"mc":[{"id":"1.230178317","rc":[{"atb":[[1.8,14.32]],"id":57196226},{"atb":[[2.62,7.98],[2.66,5.38]],"id":49159417}],"con":true,"img":false}]}
{"op":"mcm","clk":"11540965922","pt":1719500553588,"mc":[{"id":"1.230178317","rc":[{"atb":[[1.02,22.65]],"id":69685608}],"con":true,"img":false}]}
{"op":"mcm","clk":"11540965935","pt":1719500553682,"mc":[{"id":"1.230178317","rc":[{"atb":[[3.55,2]],"id":69685608},{"atb":[[2.62,3.49]],"id":49159417}],"con":true,"img":false}]}
{"op":"mcm","clk":"11540965942","pt":1719500553813,"mc":[{"id":"1.230178317","rc":[{"atb":[[2.3,0]],"id":52655636},{"atb":[[3.55,6.95]],"id":69685608}],"con":true,"img":false}]}
{"op":"mcm","clk":"11540965956","pt":1719500553989,"mc":[{"id":"1.230178317","rc":[{"atb":[[3.5,0.29]],"id":69685608}],"con":true,"img":false}]}
{"op":"mcm","clk":"11540965970","pt":1719500554194,"mc":[{"id":"1.230178317","rc":[{"atl":[[3.85,8.04]],"id":70902601}],"con":true,"img":false}]}
{"op":"mcm","clk":"11540965978","pt":1719500554403,"mc":[{"id":"1.230178317","rc":[{"atl":[[3.9,0]],"id":70902601}],"con":true,"img":false}]}
{"op":"mcm","clk":"11540965984","pt":1719500554509,"mc":[{"id":"1.230178317","rc":[{"atl":[[4.5,18.23],[3.95,0.84]],"id":70902601}],"con":true,"img":false}]}
{"op":"mcm","clk":"11540965999","pt":1719500554708,"mc":[{"id":"1.230178317","rc":[{"atl":[[3.95,0]],"id":70902601}],"con":true,"img":false}]}
{"op":"mcm","clk":"11540966006","pt":1719500554805,"mc":[{"id":"1.230178317","rc":[{"atl":[[4.5,1],[4.9,28.14]],"id":70902601}],"con":true,"img":false}]}
{"op":"mcm","clk":"11540966060","pt":1719500555487,"mc":[{"id":"1.230178317","rc":[{"atb":[[1.79,5.65]],"id":57196226}],"con":true,"img":false}]}
{"op":"mcm","clk":"11540966105","pt":1719500556206,"mc":[{"id":"1.230178317","rc":[{"atb":[[1.79,4.65]],"id":57196226},{"atb":[[2.5,8.02]],"id":46611436},{"atb":[[2.4,27.03]],"id":52655636}],"con":true,"img":false}]}
{"op":"mcm","clk":"11540966114","pt":1719500556308,"mc":[{"id":"1.230178317","rc":[{"atb":[[2.48,2]],"id":46611436},{"atb":[[2.34,2.5]],"id":52655636}],"con":true,"img":false}]}
{"op":"mcm","clk":"11540966208","pt":1719500557397,"mc":[{"id":"1.230178317","rc":[{"atl":[[3.1,0],[3,10.96]],"id":57196226},{"atl":[[8.8,10],[9.4,0]],"id":69685608}],"con":true,"img":false}]}
{"op":"mcm","clk":"11540966217","pt":1719500557505,"mc":[{"id":"1.230178317","rc":[{"atl":[[3,29.93]],"id":57196226},{"atb":[[3.15,7.25]],"id":69685608}],"con":true,"img":false}]}
{"op":"mcm","clk":"11540966224","pt":1719500557606,"mc":[{"id":"1.230178317","rc":[{"atb":[[2.62,2.5]],"id":69685608}],"con":true,"img":false}]}
{"op":"mcm","clk":"11540966231","pt":1719500557712,"mc":[{"id":"1.230178317","rc":[{"atl":[[2.98,0.84],[3.05,3.38]],"id":57196226}],"con":true,"img":false}]}
{"op":"mcm","clk":"11540966249","pt":1719500557908,"mc":[{"id":"1.230178317","rc":[{"atb":[[2.46,0]],"id":46611436},{"atb":[[2.62,0]],"id":49159417}],"con":true,"img":false}]}
{"op":"mcm","clk":"11540966257","pt":1719500558025,"mc":[{"id":"1.230178317","rc":[{"atb":[[3.55,4.95]],"id":69685608}],"con":true,"img":false}]}
{"op":"mcm","clk":"11540966268","pt":1719500558117,"mc":[{"id":"1.230178317","rc":[{"atb":[[1.02,24.65]],"id":69685608}],"con":true,"img":false}]}
{"op":"mcm","clk":"11540966323","pt":1719500558794,"mc":[{"id":"1.230178317","rc":[{"atl":[[3.05,0.84]],"id":57196226}],"con":true,"img":false}]}
{"op":"mcm","clk":"11540966358","pt":1719500559210,"mc":[{"id":"1.230178317","rc":[{"atb":[[1.81,13.67]],"id":57196226},{"atb":[[2.48,0]],"id":46611436},{"atb":[[2.34,0]],"id":52655636},{"atb":[[2.12,0]],"id":70902601},{"atb":[[2.64,0]],"id":49159417}],"con":true,"img":false}]}
{"op":"mcm","clk":"11540966363","pt":1719500559309,"mc":[{"id":"1.230178317","rc":[{"atb":[[1.82,4.4]],"id":57196226},{"atb":[[2.52,2.93]],"id":46611436},{"atb":[[2.42,2.9]],"id":52655636},{"atb":[[2.16,2.55]],"id":70902601},{"atb":[[2.68,2]],"id":49159417}],"con":true,"img":false}]}
{"op":"mcm","clk":"11540966411","pt":1719500559925,"mc":[{"id":"1.230178317","rc":[{"atb":[[1.84,2.11],[1.78,0]],"id":57196226}],"con":true,"img":false}]}
{"op":"mcm","clk":"11540966419","pt":1719500560029,"mc":[{"id":"1.230178317","rc":[{"atl":[[2.98,3.38]],"id":57196226}],"con":true,"img":false}]}
{"op":"mcm","clk":"11540966452","pt":1719500560410,"mc":[{"id":"1.230178317","rc":[{"atb":[[2.66,3.38]],"id":49159417}],"con":true,"img":false}]}
{"op":"mcm","clk":"11540966461","pt":1719500560512,"mc":[{"id":"1.230178317","rc":[{"atl":[[4.4,24.37]],"id":52655636},{"atb":[[2.7,2]],"id":49159417}],"con":true,"img":false}]}
{"op":"mcm","clk":"11540966468","pt":1719500560617,"mc":[{"id":"1.230178317","rc":[{"atl":[[4.5,0]],"id":52655636},{"atb":[[2.16,10.5]],"id":70902601}],"con":true,"img":false}]}
{"op":"mcm","clk":"11540966482","pt":1719500560818,"mc":[{"id":"1.230178317","rc":[{"atb":[[1.81,11.67]],"id":57196226},{"atl":[[3.05,0]],"id":57196226},{"atb":[[2.14,2]],"id":70902601}],"con":true,"img":false}]}
{"op":"mcm","clk":"11540966492","pt":1719500560923,"mc":[{"id":"1.230178317","rc":[{"atb":[[1.83,2]],"id":57196226}],"con":true,"img":false}]}
{"op":"mcm","clk":"11540966515","pt":1719500561225,"mc":[{"id":"1.230178317","rc":[{"atb":[[2.14,0]],"id":70902601}],"con":true,"img":false}]}
{"op":"mcm","clk":"11540966520","pt":1719500561329,"mc":[{"id":"1.230178317","rc":[{"atl":[[4.6,16.18]],"id":52655636},{"atb":[[2.18,2]],"id":70902601}],"con":true,"img":false}]}
{"op":"mcm","clk":"11540966527","pt":1719500561395,"mc":[{"id":"1.230178317","rc":[{"atl":[[4.6,0.52],[5.7,23.78]],"id":52655636}],"con":true,"img":false}]}
{"op":"mcm","clk":"11540966533","pt":1719500561494,"mc":[{"id":"1.230178317","rc":[{"atb":[[2.38,7]],"id":52655636}],"con":true,"img":false}]}
{"op":"mcm","clk":"11540966539","pt":1719500561598,"mc":[{"id":"1.230178317","rc":[{"atb":[[2.5,6.02]],"id":46611436}],"con":true,"img":false}]}
{"op":"mcm","clk":"11540966545","pt":1719500561701,"mc":[{"id":"1.230178317","rc":[{"atb":[[2.54,2]],"id":46611436}],"con":true,"img":false}]}
{"op":"mcm","clk":"11540966604","pt":1719500562516,"mc":[{"id":"1.230178317","rc":[{"atl":[[2.98,6.77]],"id":57196226}],"con":true,"img":false}]}
{"op":"mcm","clk":"11540966613","pt":1719500562619,"mc":[{"id":"1.230178317","rc":[{"atl":[[3,18.97]],"id":57196226}],"con":true,"img":false}]}
{"op":"mcm","clk":"11540966637","pt":1719500563034,"mc":[{"id":"1.230178317","rc":[{"atb":[[1.83,0]],"id":57196226}],"con":true,"img":false}]}
{"op":"mcm","clk":"11540966644","pt":1719500563096,"mc":[{"id":"1.230178317","rc":[{"atb":[[1.85,2]],"id":57196226}],"con":true,"img":false}]}
{"op":"mcm","clk":"11540966715","pt":1719500564199,"mc":[{"id":"1.230178317","rc":[{"atb":[[1.85,6.89]],"id":57196226}],"con":true,"img":false}]}
{"op":"mcm","clk":"11540966732","pt":1719500564411,"mc":[{"id":"1.230178317","rc":[{"atb":[[1.81,0]],"id":57196226},{"atb":[[2.7,5.38]],"id":49159417}],"con":true,"img":false}]}
{"op":"mcm","clk":"11540966753","pt":1719500564609,"mc":[{"id":"1.230178317","rc":[{"atl":[[4.6,0]],"id":52655636},{"atb":[[2.66,0]],"id":49159417}],"con":true,"img":false}]}
{"op":"mcm","clk":"11540966773","pt":1719500564914,"mc":[{"id":"1.230178317","rc":[{"atb":[[1.79,0]],"id":57196226}],"con":true,"img":false}]}
{"op":"mcm","clk":"11540966903","pt":1719500566627,"mc":[{"id":"1.230178317","rc":[{"atb":[[2.38,0]],"id":52655636}],"con":true,"img":false}]}
{"op":"mcm","clk":"11540966932","pt":1719500567031,"mc":[{"id":"1.230178317","rc":[{"atb":[[2.54,7.37]],"id":46611436},{"atb":[[2.42,39.01]],"id":52655636}],"con":true,"img":false}]}
{"op":"mcm","clk":"11540966941","pt":1719500567134,"mc":[{"id":"1.230178317","rc":[{"atb":[[2.5,0]],"id":46611436},{"atb":[[2.4,2.11]],"id":52655636}],"con":true,"img":false}]}
{"op":"mcm","clk":"11540966963","pt":1719500567410,"mc":[{"id":"1.230178317","rc":[{"atl":[[4.3,0.52]],"id":52655636}],"con":true,"img":false}]}
{"op":"mcm","clk":"11540967028","pt":1719500568327,"mc":[{"id":"1.230178317","rc":[{"atl":[[2.96,8.38]],"id":57196226}],"con":true,"img":false}]}
{"op":"mcm","clk":"11540967045","pt":1719500568536,"mc":[{"id":"1.230178317","rc":[{"atl":[[3,0]],"id":57196226}],"con":true,"img":false}]}
{"op":"mcm","clk":"11540967053","pt":1719500568601,"mc":[{"id":"1.230178317","rc":[{"atl":[[2.94,0.84]],"id":57196226}],"con":true,"img":false}]}
{"op":"mcm","clk":"11540967095","pt":1719500569133,"mc":[{"id":"1.230178317","rc":[{"atb":[[2.52,6.57]],"id":46611436},{"atb":[[2.14,4.89]],"id":70902601}],"con":true,"img":false}]}
{"op":"mcm","clk":"11540967134","pt":1719500569504,"mc":[{"id":"1.230178317","rc":[{"atl":[[3.15,0]],"id":57196226}],"con":true,"img":false}]}
{"op":"mcm","clk":"11540967142","pt":1719500569602,"mc":[{"id":"1.230178317","rc":[{"atl":[[2.98,4.23]],"id":57196226}],"con":true,"img":false}]}
{"op":"mcm","clk":"11540967160","pt":1719500569806,"mc":[{"id":"1.230178317","rc":[{"atb":[[1.91,0]],"id":70902601}],"con":true,"img":false}]}
{"op":"mcm","clk":"11540967267","pt":1719500571238,"mc":[{"id":"1.230178317","rc":[{"atl":[[4.2,25]],"id":52655636}],"con":true,"img":false}]}
{"op":"mcm","clk":"11540967275","pt":1719500571342,"mc":[{"id":"1.230178317","rc":[{"atl":[[4.4,24.62]],"id":52655636}],"con":true,"img":false}]}
{"op":"mcm","clk":"11540967285","pt":1719500571409,"mc":[{"id":"1.230178317","rc":[{"atl":[[5.7,2.5]],"id":52655636}],"con":true,"img":false}]}
{"op":"mcm","clk":"11540967308","pt":1719500571723,"mc":[{"id":"1.230178317","rc":[{"atl":[[4.1,0.84],[4.4,23.78]],"id":52655636}],"con":true,"img":false}]}
{"op":"mcm","clk":"11540967316","pt":1719500571818,"mc":[{"id":"1.230178317","rc":[{"atb":[[3.55,14.13]],"id":69685608}],"con":true,"img":false}]}
{"op":"mcm","clk":"11540967328","pt":1719500572023,"mc":[{"id":"1.230178317","rc":[{"atl":[[2.94,3.38]],"id":57196226}],"con":true,"img":false}]}
{"op":"mcm","clk":"11540967336","pt":1719500572127,"mc":[{"id":"1.230178317","rc":[{"atb":[[2.4,5.98]],"id":52655636}],"con":true,"img":false}]}
{"op":"mcm","clk":"11540967392","pt":1719500572808,"mc":[{"id":"1.230178317","rc":[{"atl":[[2.98,3.39]],"id":57196226}],"con":true,"img":false}]}
{"op":"mcm","clk":"11540967413","pt":1719500573117,"mc":[{"id":"1.230178317","rc":[{"atb":[[1.85,2],[1.65,0],[1.61,0],[1.69,0]],"id":57196226},{"atl":[[4.5,0],[4.1,0],[4.9,0],[2.96,0]],"id":57196226},{"atb":[[2.36,0],[2.54,2],[2.28,0],[2.2,0]],"id":46611436},{"atl":[[5,0.84],[5.8,0],[5.4,0]],"id":46611436},{"atb":[[2.24,34.62],[2.42,2.9],[2.16,0],[2.08,0]],"id":52655636},{"atl":[[6.2,0],[5.7,0],[7,0],[4.2,0]],"id":52655636},{"atb":[[1.9,0],[1.86,0],[1.94,0],[2.16,2.55]],"id":70902601},{"atl":[[3.85,0.84],[5.3,0],[4.9,25.64],[5.7,0]],"id":70902601},{"atb":[[2.54,0],[3.55,9.18],[2.62,0]],"id":69685608},{"atl":[[8,0],[9.6,0],[6.4,0.84],[8.8,5]],"id":69685608},{"atb":[[2.3,0],[2.38,0],[2.46,0],[2.7,2]],"id":49159417},{"atl":[[8,0],[7.2,0],[5.1,0.84],[6.4,0]],"id":49159417}],"con":true,"img":false}]}
{"op":"mcm","clk":"11540967419","pt":1719500573223,"mc":[{"id":"1.230178317","rc":[{"atb":[[1.82,0]],"id":57196226},{"atb":[[2.52,3.64]],"id":46611436},{"atb":[[2.16,0]],"id":70902601},{"atb":[[2.68,0]],"id":49159417}],"con":true,"img":false}]}
{"op":"mcm","clk":"11540967427","pt":1719500573327,"mc":[{"id":"1.230178317","rc":[{"atb":[[1.86,2.65]],"id":57196226},{"atb":[[2.56,2]],"id":46611436},{"atb":[[2.18,5.5]],"id":70902601},{"atb":[[2.72,2]],"id":49159417}],"con":true,"img":false}]}
{"op":"mcm","clk":"11540967437","pt":1719500573429,"mc":[{"id":"1.230178317","rc":[{"atl":[[5.7,6.52]],"id":46611436}],"con":true,"img":false}]}
{"op":"mcm","clk":"11540967478","pt":1719500573835,"mc":[{"id":"1.230178317","rc":[{"atl":[[5,0]],"id":46611436},{"atl":[[4.1,0]],"id":52655636},{"atl":[[3.85,0]],"id":70902601},{"atl":[[6.4,0]],"id":69685608},{"atb":[[2.68,3.38]],"id":49159417},{"atl":[[5.1,0]],"id":49159417}],"con":true,"img":false}]}
{"op":"mcm","clk":"11540967487","pt":1719500573938,"mc":[{"id":"1.230178317","rc":[{"atb":[[2.7,0]],"id":49159417}],"con":true,"img":false}]}
{"op":"mcm","clk":"11540967493","pt":1719500574040,"mc":[{"id":"1.230178317","rc":[{"atl":[[5.6,6.23],[5.3,0]],"id":46611436},{"atl":[[4.9,0],[7,16.67]],"id":70902601},{"atb":[[2.74,2]],"id":49159417},{"atl":[[19,5.56],[6.8,0]],"id":49159417}],"con":true,"img":false}]}
{"op":"mcm","clk":"11540967517","pt":1719500574311,"mc":[{"id":"1.230178317","rc":[{"atb":[[1.85,0]],"id":57196226}],"con":true,"img":false}]}
{"op":"mcm","clk":"11540967524","pt":1719500574422,"mc":[{"id":"1.230178317","rc":[{"atb":[[1.87,2]],"id":57196226}],"con":true,"img":false}]}
{"op":"mcm","clk":"11540967558","pt":1719500574832,"mc":[{"id":"1.230178317","rc":[{"atb":[[2.54,0]],"id":46611436}],"con":true,"img":false}]}
{"op":"mcm","clk":"11540967568","pt":1719500574957,"mc":[{"id":"1.230178317","rc":[{"atb":[[2.58,2]],"id":46611436}],"con":true,"img":false}]}
{"op":"mcm","clk":"11540967621","pt":1719500575713,"mc":[{"id":"1.230178317","rc":[{"atb":[[1.83,5.66]],"id":57196226}],"con":true,"img":false}]}
{"op":"mcm","clk":"11540967650","pt":1719500576122,"mc":[{"id":"1.230178317","rc":[{"atl":[[5.8,21.83],[4.4,0]],"id":52655636}],"con":true,"img":false}]}
{"op":"mcm","clk":"11540967819","pt":1719500578648,"mc":[{"id":"1.230178317","rc":[{"atl":[[5.7,0.84]],"id":52655636}],"con":true,"img":false}]}
{"op":"mcm","clk":"11540968015","pt":1719500581426,"mc":[{"id":"1.230178317","rc":[{"atb":[[2.22,7.5]],"id":52655636}],"con":true,"img":false}]}
{"op":"mcm","clk":"11540968106","pt":1719500582746,"mc":[{"id":"1.230178317","rc":[{"atl":[[4.3,0]],"id":52655636}],"con":true,"img":false}]}
{"op":"mcm","clk":"11540968121","pt":1719500582953,"mc":[{"id":"1.230178317","rc":[{"atl":[[5.8,1],[12,9.09]],"id":52655636}],"con":true,"img":false}]}
{"op":"mcm","clk":"11540968241","pt":1719500584357,"mc":[{"id":"1.230178317","rc":[{"atb":[[2.4,3.87],[2.3,2.11]],"id":52655636}],"con":true,"img":false}]}
{"op":"mcm","clk":"11540968282","pt":1719500584725,"mc":[{"id":"1.230178317","rc":[{"atb":[[2.22,0]],"id":52655636}],"con":true,"img":false}]}
{"op":"mcm","clk":"11540968299","pt":1719500584932,"mc":[{"id":"1.230178317","rc":[{"atl":[[5.7,1.37]],"id":52655636}],"con":true,"img":false}]}
{"op":"mcm","clk":"11540968309","pt":1719500585035,"mc":[{"id":"1.230178317","rc":[{"atl":[[12,0],[5.7,3.37]],"id":52655636}],"con":true,"img":false}]}
{"op":"mcm","clk":"11540968364","pt":1719500585757,"mc":[{"id":"1.230178317","rc":[{"atl":[[17.5,3.25]],"id":57196226}],"con":true,"img":false}]}
{"op":"mcm","clk":"11540968496","pt":1719500587256,"mc":[{"id":"1.230178317","rc":[{"atb":[[1.86,0]],"id":57196226},{"atb":[[2.72,0]],"id":49159417}],"con":true,"img":false}]}
{"op":"mcm","clk":"11540968511","pt":1719500587358,"mc":[{"id":"1.230178317","rc":[{"atb":[[1.87,5.3]],"id":57196226}],"con":true,"img":false}]}
{"op":"mcm","clk":"11540968592","pt":1719500588235,"mc":[{"id":"1.230178317","rc":[{"atb":[[2.74,0]],"id":49159417}],"con":true,"img":false}]}
{"op":"mcm","clk":"11540968601","pt":1719500588342,"mc":[{"id":"1.230178317","rc":[{"atb":[[2.5,7.72],[2.58,0],[2.7,2]],"id":49159417}],"con":true,"img":false}]}
{"op":"mcm","clk":"11540969003","pt":1719500593455,"mc":[{"id":"1.230178317","rc":[{"atb":[[2.5,0.12],[2.58,5.38]],"id":49159417}],"con":true,"img":false}]}
{"op":"mcm","clk":"11540969214","pt":1719500596140,"mc":[{"id":"1.230178317","rc":[{"atb":[[2.4,0]],"id":52655636},{"atb":[[2.68,0]],"id":49159417}],"con":true,"img":false}]}
{"op":"mcm","clk":"11540969292","pt":1719500597061,"mc":[{"id":"1.230178317","rc":[{"atb":[[2.7,0]],"id":49159417}],"con":true,"img":false}]}
{"op":"mcm","clk":"11540969304","pt":1719500597166,"mc":[{"id":"1.230178317","rc":[{"atb":[[2.38,5.5],[2.6,2],[2.58,0]],"id":49159417}],"con":true,"img":false}]}
{"op":"mcm","clk":"11540969320","pt":1719500597365,"mc":[{"id":"1.230178317","rc":[{"atb":[[2.28,4.2]],"id":52655636},{"atb":[[2.56,2]],"id":49159417}],"con":true,"img":false}]}
{"op":"mcm","clk":"11540969382","pt":1719500598251,"mc":[{"id":"1.230178317","rc":[{"atb":[[2.6,0]],"id":49159417}],"con":true,"img":false}]}
{"op":"mcm","clk":"11540969389","pt":1719500598354,"mc":[{"id":"1.230178317","rc":[{"atb":[[2.58,2]],"id":49159417}],"con":true,"img":false}]}
{"op":"mcm","clk":"11540969408","pt":1719500598661,"mc":[{"id":"1.230178317","rc":[{"spn":2.4,"spf":"NaN","id":57196226},{"spn":3.89,"spf":"NaN","id":46611436},{"spn":4.06,"spf":"NaN","id":52655636},{"spn":3.34,"spf":"NaN","id":70902601},{"spn":4.87,"spf":"NaN","id":69685608},{"atb":[[2.56,0]],"id":49159417},{"spn":3.94,"spf":"NaN","id":49159417}],"con":true,"img":false}]}
{"op":"mcm","clk":"11540969537","pt":1719500600369,"mc":[{"id":"1.230178317","rc":[{"atl":[[5.7,2.84]],"id":52655636}],"con":true,"img":false}]}
{"op":"mcm","clk":"11540969544","pt":1719500600473,"mc":[{"id":"1.230178317","rc":[{"atb":[[2.58,0]],"id":49159417}],"con":true,"img":false}]}
{"op":"mcm","clk":"11540969553","pt":1719500600555,"mc":[{"id":"1.230178317","rc":[{"atl":[[12,3.85],[5.7,0.84]],"id":52655636},{"atb":[[2.4,2]],"id":49159417}],"con":true,"img":false}]}
{"op":"mcm","clk":"11540969841","pt":1719500603732,"mc":[{"id":"1.230178317","rc":[{"atl":[[5.7,1.37]],"id":52655636}],"con":true,"img":false}]}
{"op":"mcm","clk":"11540969851","pt":1719500603833,"mc":[{"id":"1.230178317","rc":[{"atl":[[12,0],[5.7,3.37]],"id":52655636}],"con":true,"img":false}]}
{"op":"mcm","clk":"11540969862","pt":1719500603936,"mc":[{"id":"1.230178317","rc":[{"atl":[[12,2.37]],"id":52655636}],"con":true,"img":false}]}
{"op":"mcm","clk":"11540969870","pt":1719500604041,"mc":[{"id":"1.230178317","rc":[{"atl":[[5.7,1.37]],"id":52655636}],"con":true,"img":false}]}
{"op":"mcm","clk":"11540970192","pt":1719500607551,"mc":[{"id":"1.230178317","rc":[{"atb":[[2.14,0]],"id":52655636}],"con":true,"img":false}]}
{"op":"mcm","clk":"11540970204","pt":1719500607665,"mc":[{"id":"1.230178317","rc":[{"atl":[[5.7,3.37]],"id":52655636}],"con":true,"img":false}]}
{"op":"mcm","clk":"11540970215","pt":1719500607765,"mc":[{"id":"1.230178317","rc":[{"atl":[[12,0]],"id":52655636}],"con":true,"img":false}]}
{"op":"mcm","clk":"11540970435","pt":1719500609961,"mc":[{"id":"1.230178317","rc":[{"atb":[[2.28,0]],"id":52655636}],"con":true,"img":false}]}
{"op":"mcm","clk":"11540970757","pt":1719500613577,"mc":[{"id":"1.230178317","rc":[{"atb":[[2.56,0]],"id":46611436}],"con":true,"img":false}]}
{"op":"mcm","clk":"11540970776","pt":1719500613788,"mc":[{"id":"1.230178317","rc":[{"atb":[[2.58,5]],"id":46611436},{"atb":[[2.4,5]],"id":49159417}],"con":true,"img":false}]}
{"op":"mcm","clk":"11540970788","pt":1719500613886,"mc":[{"id":"1.230178317","rc":[{"atb":[[2.42,5],[2.38,0]],"id":49159417}],"con":true,"img":false}]}
{"op":"mcm","clk":"11540970851","pt":1719500614465,"mc":[{"id":"1.230178317","rc":[{"atb":[[2.28,4.2]],"id":52655636}],"con":true,"img":false}]}
{"op":"mcm","clk":"11540970873","pt":1719500614673,"mc":[{"id":"1.230178317","rc":[{"atb":[[2.4,3]],"id":49159417}],"con":true,"img":false}]}
{"op":"mcm","clk":"11540970882","pt":1719500614771,"mc":[{"id":"1.230178317","rc":[{"atb":[[2.44,2]],"id":49159417}],"con":true,"img":false}]}
{"op":"mcm","clk":"11540970951","pt":1719500615482,"mc":[{"id":"1.230178317","rc":[{"atl":[[5,1],[5.2,0]],"id":46611436},{"atl":[[5.6,1],[5.8,0]],"id":52655636},{"atl":[[4.5,0],[4.1,1]],"id":70902601},{"atb":[[2.48,3.75]],"id":49159417}],"con":true,"img":false}]}
{"op":"mcm","clk":"11540970962","pt":1719500615584,"mc":[{"id":"1.230178317","rc":[{"atl":[[4.9,2.02]],"id":70902601},{"atb":[[2.42,0],[2.46,3]],"id":49159417}],"con":true,"img":false}]}
{"op":"mcm","clk":"11540970970","pt":1719500615687,"mc":[{"id":"1.230178317","rc":[{"atl":[[7,0]],"id":70902601}],"con":true,"img":false}]}
{"op":"mcm","clk":"11540970983","pt":1719500615759,"mc":[{"id":"1.230178317","rc":[{"atl":[[7,3.02]],"id":70902601}],"con":true,"img":false}]}
{"op":"mcm","clk":"11540970992","pt":1719500615858,"mc":[{"id":"1.230178317","rc":[{"atl":[[4.9,0]],"id":70902601}],"con":true,"img":false}]}
{"op":"mcm","clk":"11540971056","pt":1719500616688,"mc":[{"id":"1.230178317","rc":[{"atb":[[2.44,0]],"id":49159417}],"con":true,"img":false}]}
{"op":"mcm","clk":"11540971064","pt":1719500616782,"mc":[{"id":"1.230178317","rc":[{"atb":[[2.5,2.12]],"id":49159417}],"con":true,"img":false}]}
{"op":"mcm","clk":"11540971085","pt":1719500616984,"mc":[{"id":"1.230178317","rc":[{"atb":[[2.5,5.12],[2.46,0]],"id":49159417}],"con":true,"img":false}]}
{"op":"mcm","clk":"11540971093","pt":1719500617089,"mc":[{"id":"1.230178317","rc":[{"atb":[[2.5,2.12],[2.46,5.87]],"id":49159417}],"con":true,"img":false}]}
{"op":"mcm","clk":"11540971101","pt":1719500617185,"mc":[{"id":"1.230178317","rc":[{"atb":[[2.5,5.87],[2.46,0]],"id":49159417}],"con":true,"img":false}]}
{"op":"mcm","clk":"11540971268","pt":1719500619088,"mc":[{"id":"1.230178317","rc":[{"atl":[[5.7,2.84]],"id":52655636}],"con":true,"img":false}]}
{"op":"mcm","clk":"11540971279","pt":1719500619153,"mc":[{"id":"1.230178317","rc":[{"atl":[[12,3.85],[5.7,0.84]],"id":52655636}],"con":true,"img":false}]}
{"op":"mcm","clk":"11540971530","pt":1719500621793,"mc":[{"id":"1.230178317","rc":[{"atl":[[5.5,0.52]],"id":52655636}],"con":true,"img":false}]}
{"op":"mcm","clk":"11540971543","pt":1719500621992,"mc":[{"id":"1.230178317","rc":[{"atl":[[12,0],[5.7,2.84]],"id":52655636}],"con":true,"img":false}]}
{"op":"mcm","clk":"11540971553","pt":1719500622099,"mc":[{"id":"1.230178317","rc":[{"atl":[[5,0],[5.2,1]],"id":46611436},{"atb":[[2.28,0]],"id":52655636},{"atl":[[4.5,1],[4.1,0]],"id":70902601}],"con":true,"img":false}]}
{"op":"mcm","clk":"11540971562","pt":1719500622192,"mc":[{"id":"1.230178317","rc":[{"atl":[[7,0]],"id":70902601},{"atb":[[2.4,0]],"id":49159417}],"con":true,"img":false}]}
{"op":"mcm","clk":"11540971576","pt":1719500622262,"mc":[{"id":"1.230178317","rc":[{"atl":[[4.9,2.02]],"id":70902601}],"con":true,"img":false}]}
{"op":"mcm","clk":"11540971583","pt":1719500622350,"mc":[{"id":"1.230178317","rc":[{"atl":[[7,2]],"id":70902601},{"atb":[[2.52,2.4]],"id":49159417}],"con":true,"img":false}]}
{"op":"mcm","clk":"11540971599","pt":1719500622474,"mc":[{"id":"1.230178317","rc":[{"atl":[[4.9,0]],"id":70902601}],"con":true,"img":false}]}
{"op":"mcm","clk":"11540971654","pt":1719500623183,"mc":[{"id":"1.230178317","rc":[{"atb":[[2.5,3.87]],"id":49159417}],"con":true,"img":false}]}
{"op":"mcm","clk":"11540971664","pt":1719500623289,"mc":[{"id":"1.230178317","rc":[{"atb":[[2.54,2]],"id":49159417}],"con":true,"img":false}]}
{"op":"mcm","clk":"11540971681","pt":1719500623494,"mc":[{"id":"1.230178317","rc":[{"atb":[[2.54,4.4],[2.5,0.12]],"id":49159417}],"con":true,"img":false}]}
{"op":"mcm","clk":"11540971693","pt":1719500623596,"mc":[{"id":"1.230178317","rc":[{"atb":[[2.54,2],[2.52,6.4]],"id":49159417}],"con":true,"img":false}]}
{"op":"mcm","clk":"11540971723","pt":1719500623898,"mc":[{"id":"1.230178317","rc":[{"atl":[[5,1],[5.2,0]],"id":46611436},{"atl":[[4.5,0],[4.1,1]],"id":70902601},{"atb":[[2.48,0]],"id":49159417}],"con":true,"img":false}]}
{"op":"mcm","clk":"11540971778","pt":1719500624575,"mc":[{"id":"1.230178317","rc":[{"atb":[[1.8,7.4]],"id":57196226}],"con":true,"img":false}]}
{"op":"mcm","clk":"11540971795","pt":1719500624779,"mc":[{"id":"1.230178317","rc":[{"atl":[[17.5,0]],"id":57196226}],"con":true,"img":false}]}
{"op":"mcm","clk":"11540971917","pt":1719500626194,"mc":[{"id":"1.230178317","rc":[{"atl":[[5,0],[5.2,1],[5.7,0]],"id":46611436},{"atl":[[5.6,0],[5.8,1]],"id":52655636},{"atl":[[4.5,1],[4.1,0]],"id":70902601}],"con":true,"img":false}]}
{"op":"mcm","clk":"11540971924","pt":1719500626292,"mc":[{"id":"1.230178317","rc":[{"atl":[[5.6,0],[12.5,7.23]],"id":46611436},{"atl":[[5.8,4.38],[5.7,0.84]],"id":52655636}],"con":true,"img":false}]}
{"op":"mcm","clk":"11540971929","pt":1719500626354,"mc":[{"id":"1.230178317","rc":[{"atl":[[5.6,3.17]],"id":46611436}],"con":true,"img":false}]}
{"op":"mcm","clk":"11540972028","pt":1719500627801,"mc":[{"id":"1.230178317","rc":[{"atl":[[19.5,3.38]],"id":57196226}],"con":true,"img":false}]}
{"op":"mcm","clk":"11540972073","pt":1719500628264,"mc":[{"id":"1.230178317","rc":[{"atb":[[1.49,10.6]],"id":57196226},{"atl":[[3.2,6.78]],"id":57196226}],"con":true,"img":false}]}
{"op":"mcm","clk":"11540972078","pt":1719500628369,"mc":[{"id":"1.230178317","rc":[{"atb":[[1.57,0]],"id":57196226},{"atl":[[2.98,0]],"id":57196226},{"atb":[[2.12,8.64],[2.26,0]],"id":46611436},{"atb":[[2.24,0],[2.12,5.02]],"id":52655636},{"atb":[[1.77,0],[1.71,10.39]],"id":70902601},{"atb":[[2.88,14.5],[3.15,0]],"id":69685608},{"atb":[[2.4,4],[2.52,2.4]],"id":49159417}],"con":true,"img":false}]}
{"op":"mcm","clk":"11540972092","pt":1719500628569,"mc":[{"id":"1.230178317","rc":[{"atl":[[19.5,0]],"id":57196226}],"con":true,"img":false}]}
{"op":"mcm","clk":"11540972109","pt":1719500628773,"mc":[{"id":"1.230178317","rc":[{"atb":[[1.02,22.65]],"id":69685608}],"con":true,"img":false}]}
{"op":"mcm","clk":"11540972116","pt":1719500628881,"mc":[{"id":"1.230178317","rc":[{"atb":[[3.6,2]],"id":69685608}],"con":true,"img":false}]}
{"op":"mcm","clk":"11540972205","pt":1719500629861,"mc":[{"id":"1.230178317","rc":[{"atb":[[3.6,0]],"id":69685608}],"con":true,"img":false}]}
{"op":"mcm","clk":"11540972212","pt":1719500629963,"mc":[{"id":"1.230178317","rc":[{"atb":[[1.02,24.65]],"id":69685608}],"con":true,"img":false}]}
{"op":"mcm","clk":"11540972286","pt":1719500630893,"mc":[{"id":"1.230178317","rc":[{"atb":[[2.52,0]],"id":49159417}],"con":true,"img":false}]}
{"op":"mcm","clk":"11540972299","pt":1719500630995,"mc":[{"id":"1.230178317","rc":[{"atb":[[2.54,5]],"id":49159417}],"con":true,"img":false}]}
{"op":"mcm","clk":"11540972329","pt":1719500631301,"mc":[{"id":"1.230178317","rc":[{"atb":[[1.02,22.65]],"id":69685608}],"con":true,"img":false}]}
{"op":"mcm","clk":"11540972340","pt":1719500631397,"mc":[{"id":"1.230178317","rc":[{"atl":[[5.5,3.17],[12.5,0]],"id":46611436},{"atb":[[3.6,2]],"id":69685608}],"con":true,"img":false}]}
{"op":"mcm","clk":"11540972418","pt":1719500632386,"mc":[{"id":"1.230178317","rc":[{"atb":[[3.6,0]],"id":69685608}],"con":true,"img":false}]}
{"op":"mcm","clk":"11540972426","pt":1719500632491,"mc":[{"id":"1.230178317","rc":[{"atb":[[1.02,24.65]],"id":69685608}],"con":true,"img":false}]}
{"op":"mcm","clk":"11540972453","pt":1719500632697,"mc":[{"id":"1.230178317","rc":[{"atb":[[2.5,3.9]],"id":49159417}],"con":true,"img":false}]}
{"op":"mcm","clk":"11540972465","pt":1719500632798,"mc":[{"id":"1.230178317","rc":[{"atb":[[2.28,3.9]],"id":52655636}],"con":true,"img":false}]}
{"op":"mcm","clk":"11540972525","pt":1719500633277,"mc":[{"id":"1.230178317","rc":[{"atb":[[1.02,22.65]],"id":69685608}],"con":true,"img":false}]}
{"op":"mcm","clk":"11540972535","pt":1719500633382,"mc":[{"id":"1.230178317","rc":[{"atb":[[3.6,2]],"id":69685608}],"con":true,"img":false}]}
{"op":"mcm","clk":"11540972623","pt":1719500634403,"mc":[{"id":"1.230178317","rc":[{"atb":[[3.6,0]],"id":69685608}],"con":true,"img":false}]}
{"op":"mcm","clk":"11540972634","pt":1719500634505,"mc":[{"id":"1.230178317","rc":[{"atb":[[1.02,24.65]],"id":69685608}],"con":true,"img":false}]}
{"op":"mcm","clk":"11540972774","pt":1719500636010,"mc":[{"id":"1.230178317","rc":[{"atb":[[1.02,22.65]],"id":69685608}],"con":true,"img":false}]}
{"op":"mcm","clk":"11540972785","pt":1719500636107,"mc":[{"id":"1.230178317","rc":[{"atb":[[3.6,2]],"id":69685608}],"con":true,"img":false}]}
{"op":"mcm","clk":"11540972875","pt":1719500637297,"mc":[{"id":"1.230178317","rc":[{"atl":[[5.5,0]],"id":52655636},{"atb":[[3.6,0]],"id":69685608}],"con":true,"img":false}]}
{"op":"mcm","clk":"11540972882","pt":1719500637401,"mc":[{"id":"1.230178317","rc":[{"atl":[[5.8,1],[13.5,5.23]],"id":52655636},{"atb":[[1.02,24.65]],"id":69685608}],"con":true,"img":false}]}
{"op":"mcm","clk":"11540972991","pt":1719500638788,"mc":[{"id":"1.230178317","rc":[{"atb":[[1.02,22.65]],"id":69685608}],"con":true,"img":false}]}
{"op":"mcm","clk":"11540973002","pt":1719500638890,"mc":[{"id":"1.230178317","rc":[{"atb":[[3.6,2]],"id":69685608}],"con":true,"img":false}]}
{"op":"mcm","clk":"11540973009","pt":1719500638994,"mc":[{"id":"1.230178317","rc":[{"atl":[[5.7,1.37]],"id":52655636}],"con":true,"img":false}]}
{"op":"mcm","clk":"11540973067","pt":1719500639707,"mc":[{"id":"1.230178317","rc":[{"atb":[[3.6,0]],"id":69685608}],"con":true,"img":false}]}
{"op":"mcm","clk":"11540973074","pt":1719500639811,"mc":[{"id":"1.230178317","rc":[{"atb":[[1.02,24.65]],"id":69685608}],"con":true,"img":false}]}
{"op":"mcm","clk":"11540973139","pt":1719500640496,"mc":[{"id":"1.230178317","rc":[{"atb":[[1.83,0]],"id":57196226},{"atb":[[2.52,0]],"id":46611436},{"atb":[[2.14,0]],"id":70902601},{"atb":[[2.5,0.12]],"id":49159417}],"con":true,"img":false}]}
{"op":"mcm","clk":"11540973146","pt":1719500640595,"mc":[{"id":"1.230178317","rc":[{"atb":[[2.58,12.94]],"id":46611436},{"atl":[[5.5,7.15]],"id":46611436},{"atl":[[7.8,10.34]],"id":69685608}],"con":true,"img":false}]}
{"op":"mcm","clk":"11540973167","pt":1719500640809,"mc":[{"id":"1.230178317","rc":[{"atb":[[1.02,22.65]],"id":69685608}],"con":true,"img":false}]}
{"op":"mcm","clk":"11540973176","pt":1719500640909,"mc":[{"id":"1.230178317","rc":[{"atb":[[3.6,2]],"id":69685608}],"con":true,"img":false}]}
{"op":"mcm","clk":"11540973227","pt":1719500641528,"mc":[{"id":"1.230178317","rc":[{"atl":[[7.8,10.11]],"id":69685608}],"con":true,"img":false}]}
{"op":"mcm","clk":"11540973243","pt":1719500641692,"mc":[{"id":"1.230178317","rc":[{"atl":[[7.8,6.99]],"id":69685608}],"con":true,"img":false}]}
{"op":"mcm","clk":"11540973253","pt":1719500641788,"mc":[{"id":"1.230178317","rc":[{"atl":[[8.6,3.12]],"id":69685608}],"con":true,"img":false}]}
{"op":"mcm","clk":"11540973277","pt":1719500642098,"mc":[{"id":"1.230178317","rc":[{"atb":[[3.6,0]],"id":69685608}],"con":true,"img":false}]}
{"op":"mcm","clk":"11540973284","pt":1719500642218,"mc":[{"id":"1.230178317","rc":[{"atb":[[1.02,24.65]],"id":69685608}],"con":true,"img":false}]}
{"op":"mcm","clk":"11540973299","pt":1719500642516,"mc":[{"id":"1.230178317","rc":[{"atl":[[5.7,3.37],[13.5,0]],"id":52655636}],"con":true,"img":false}]}
{"op":"mcm","clk":"11540973307","pt":1719500642618,"mc":[{"id":"1.230178317","rc":[{"atb":[[2.14,4.89]],"id":70902601}],"con":true,"img":false}]}
{"op":"mcm","clk":"11540973359","pt":1719500643291,"mc":[{"id":"1.230178317","rc":[{"atb":[[1.02,22.65]],"id":69685608}],"con":true,"img":false}]}
{"op":"mcm","clk":"11540973365","pt":1719500643393,"mc":[{"id":"1.230178317","rc":[{"atb":[[3.6,2]],"id":69685608}],"con":true,"img":false}]}
{"op":"mcm","clk":"11540973408","pt":1719500644013,"mc":[{"id":"1.230178317","rc":[{"atb":[[2.6,1.94]],"id":46611436},{"atb":[[2.44,1.94]],"id":52655636},{"atb":[[2.2,1.94]],"id":70902601},{"atb":[[2.56,1.94]],"id":49159417}],"con":true,"img":false}]}
{"op":"mcm","clk":"11540973424","pt":1719500644216,"mc":[{"id":"1.230178317","rc":[{"atl":[[3.7,0]],"id":57196226},{"atl":[[5.6,0]],"id":46611436},{"atl":[[6.4,2.83]],"id":52655636}],"con":true,"img":false}]}
{"op":"mcm","clk":"11540973443","pt":1719500644417,"mc":[{"id":"1.230178317","rc":[{"atl":[[17.5,3.25]],"id":57196226}],"con":true,"img":false}]}
{"op":"mcm","clk":"11540973459","pt":1719500644623,"mc":[{"id":"1.230178317","rc":[{"atl":[[5.4,7.55]],"id":46611436},{"atb":[[3.6,0]],"id":69685608}],"con":true,"img":false}]}
{"op":"mcm","clk":"11540973465","pt":1719500644726,"mc":[{"id":"1.230178317","rc":[{"atl":[[5.5,3.98],[5.3,7.15]],"id":46611436},{"atb":[[1.02,24.65]],"id":69685608}],"con":true,"img":false}]}
{"op":"mcm","clk":"11540973484","pt":1719500644892,"mc":[{"id":"1.230178317","rc":[{"atl":[[17.5,0]],"id":57196226},{"atb":[[2.28,0]],"id":52655636},{"atb":[[2.14,0]],"id":70902601}],"con":true,"img":false}]}
{"op":"mcm","clk":"11540973492","pt":1719500644993,"mc":[{"id":"1.230178317","rc":[{"atl":[[6.4,0]],"id":52655636}],"con":true,"img":false}]}
{"op":"mcm","clk":"11540973500","pt":1719500645094,"mc":[{"id":"1.230178317","rc":[{"atl":[[4.8,1],[5.2,0]],"id":46611436},{"atl":[[5.8,0],[5.4,1]],"id":52655636},{"atl":[[4,1],[4.5,0],[4.1,1]],"id":70902601},{"atl":[[5.3,0],[5.2,1]],"id":49159417}],"con":true,"img":false}]}
{"op":"mcm","clk":"11540973510","pt":1719500645201,"mc":[{"id":"1.230178317","rc":[{"atl":[[5.5,0]],"id":46611436},{"atl":[[4.5,2],[7,0]],"id":70902601}],"con":true,"img":false}]}
{"op":"mcm","clk":"11540973531","pt":1719500645410,"mc":[{"id":"1.230178317","rc":[{"atl":[[4.8,0],[4.9,1],[5.4,11.38]],"id":46611436},{"atl":[[6.4,3.68],[5.5,1],[5.4,0]],"id":52655636},{"atl":[[4,0],[4.1,0],[4.2,1]],"id":70902601},{"atb":[[2.88,0],[2.96,9.48]],"id":69685608},{"atb":[[2.4,0],[2.46,3.9]],"id":49159417}],"con":true,"img":false}]}
{"op":"mcm","clk":"11540973540","pt":1719500645514,"mc":[{"id":"1.230178317","rc":[{"atl":[[4.5,0],[4.1,2]],"id":70902601}],"con":true,"img":false}]}
{"op":"mcm","clk":"11540973545","pt":1719500645615,"mc":[{"id":"1.230178317","rc":[{"atl":[[4.5,3],[4.1,0]],"id":70902601}],"con":true,"img":false}]}
{"op":"mcm","clk":"11540973553","pt":1719500645717,"mc":[{"id":"1.230178317","rc":[{"atl":[[4.5,0],[7.6,4]],"id":70902601},{"atb":[[1.02,22.65]],"id":69685608}],"con":true,"img":false}]}
{"op":"mcm","clk":"11540973563","pt":1719500645822,"mc":[{"id":"1.230178317","rc":[{"atl":[[4.8,4.72]],"id":70902601},{"atb":[[3.6,2]],"id":69685608}],"con":true,"img":false}]}
{"op":"mcm","clk":"11540973583","pt":1719500646021,"mc":[{"id":"1.230178317","rc":[{"atl":[[7.6,0],[4.7,4]],"id":70902601}],"con":true,"img":false}]}
{"op":"mcm","clk":"11540973603","pt":1719500646228,"mc":[{"id":"1.230178317","rc":[{"atb":[[2.56,3.52]],"id":46611436}],"con":true,"img":false}]}
{"op":"mcm","clk":"11540973624","pt":1719500646394,"mc":[{"id":"1.230178317","rc":[{"atb":[[1.01,1.7]],"id":57196226},{"atl":[[1000,1.7]],"id":57196226},{"atb":[[3.55,9.08],[1.05,1.7]],"id":69685608},{"atl":[[1000,1.87]],"id":69685608},{"atb":[[1.02,1.7]],"id":49159417},{"atl":[[1000,1.7]],"id":49159417}],"con":true,"img":false}]}
{"op":"mcm","clk":"11540973636","pt":1719500646504,"mc":[{"id":"1.230178317","rc":[{"atb":[[3.55,0]],"id":69685608}],"con":true,"img":false}]}
{"op":"mcm","clk":"11540973643","pt":1719500646601,"mc":[{"id":"1.230178317","rc":[{"atb":[[1.01,0.29]],"id":57196226},{"atl":[[1000,0.13]],"id":57196226},{"atb":[[3.6,11.08],[1.05,0.05]],"id":69685608},{"atl":[[1000,0.19]],"id":69685608},{"atb":[[1.02,0.16]],"id":49159417},{"atl":[[1000,0.01]],"id":49159417}],"con":true,"img":false}]}
{"op":"mcm","clk":"11540973662","pt":1719500646811,"mc":[{"id":"1.230178317","rc":[{"atb":[[1.01,0]],"id":57196226},{"atl":[[1000,0]],"id":57196226},{"atb":[[1.05,0]],"id":69685608},{"atl":[[1000,0.16]],"id":69685608},{"atb":[[1.02,0]],"id":49159417},{"atl":[[1000,0]],"id":49159417}],"con":true,"img":false}]}
{"op":"mcm","clk":"11540973672","pt":1719500646914,"mc":[{"id":"1.230178317","rc":[{"atb":[[1.92,2.5],[1.84,12.11],[1.54,10.6],[1.88,5.29],[1.49,0],[1.87,11.82]],"id":57196226},{"atl":[[2.92,0.13],[3.2,0],[4.6,5],[5,10],[2.94,13.29],[4.2,2.5]],"id":57196226},{"atb":[[2.36,8.64],[2.12,0],[2.6,9.94]],"id":46611436},{"atl":[[4.8,8],[6.4,10],[5.8,5],[5.4,13.88]],"id":46611436},{"atb":[[2.24,6.74],[2.12,0],[2.44,4.99]],"id":52655636},{"atl":[[5.6,3.05],[6.2,5],[5.7,5.87],[7,10]],"id":52655636},{"atb":[[1.8,10.39],[2.2,6.53],[1.71,0]],"id":70902601},{"atl":[[4.1,4.59]],"id":70902601},{"atb":[[2.5,12.11],[2.66,2.5],[2.58,5],[2.96,0],[2.62,18.96],[3.65,0.05]],"id":69685608},{"atl":[[8.2,10],[7.4,5],[6.8,5.99],[5.5,1],[7.6,5.02],[8.8,0],[7,0],[6.6,2.5]],"id":69685608},{"atb":[[2.56,6.15],[2.5,2.62],[2.46,0],[2.58,0.16]],"id":49159417},{"atl":[[8,10],[7.2,5],[5.1,3.21],[18.5,0.01],[19,0],[6.4,2.5],[5.2,0],[15,2]],"id":49159417}],"con":true,"img":false}]}
{"op":"mcm","clk":"11540973684","pt":1719500647020,"mc":[{"id":"1.230178317","rc":[{"atb":[[2.44,7.11]],"id":52655636},{"atl":[[15,0]],"id":49159417}],"con":true,"img":false}]}
{"op":"mcm","clk":"11540973692","pt":1719500647115,"mc":[{"id":"1.230178317","rc":[{"atb":[[1.54,0],[1.7,10.6]],"id":57196226},{"atl":[[2.94,9.9],[4.2,12.67]],"id":57196226},{"atb":[[2.24,2.5],[2.42,12.9]],"id":52655636},{"atb":[[1.8,0],[1.97,10.39]],"id":70902601},{"atb":[[2.98,11.38],[2.62,0]],"id":69685608},{"atl":[[7.6,0.02],[6.6,5.62]],"id":69685608},{"atl":[[6.4,4.5]],"id":49159417}],"con":true,"img":false}]}
{"op":"mcm","clk":"11540973700","pt":1719500647222,"mc":[{"id":"1.230178317","rc":[{"atb":[[2.44,4.99]],"id":52655636},{"atb":[[2.02,2.5],[1.97,15.39],[1.93,10]],"id":70902601},{"atl":[[4.8,7.22],[5.6,10],[5.2,5]],"id":70902601}],"con":true,"img":false}]}
{"op":"mcm","clk":"11540973712","pt":1719500647342,"mc":[{"id":"1.230178317","rc":[{"atl":[[3.55,1]],"id":57196226},{"atl":[[7.2,12.71],[6.4,2.5]],"id":49159417}],"con":true,"img":false}]}
{"op":"mcm","clk":"11540973723","pt":1719500647409,"mc":[{"id":"1.230178317","rc":[{"atl":[[3.55,11.05],[4.2,2.5]],"id":57196226},{"atb":[[2.56,0]],"id":46611436},{"atl":[[4.8,2.5]],"id":70902601}],"con":true,"img":false}]}
{"op":"mcm","clk":"11540973742","pt":1719500647615,"mc":[{"id":"1.230178317","rc":[{"atb":[[2.54,3]],"id":49159417}],"con":true,"img":false}]}
{"op":"mcm","clk":"11540973753","pt":1719500647718,"mc":[{"id":"1.230178317","rc":[{"atl":[[4.7,0.84]],"id":46611436},{"atl":[[4,0.84]],"id":70902601},{"atb":[[2.58,2.16]],"id":49159417},{"atl":[[5,0.84]],"id":49159417}],"con":true,"img":false}]}
{"op":"mcm","clk":"11540973764","pt":1719500647822,"mc":[{"id":"1.230178317","rc":[{"atl":[[7.2,5]],"id":49159417}],"con":true,"img":false}]}
{"op":"mcm","clk":"11540973772","pt":1719500647918,"mc":[{"id":"1.230178317","rc":[{"atl":[[6.4,12.5]],"id":49159417}],"con":true,"img":false}]}
{"op":"mcm","clk":"11540973791","pt":1719500648121,"mc":[{"id":"1.230178317","rc":[{"atb":[[1.87,9.82]],"id":57196226}],"con":true,"img":false}]}
{"op":"mcm","clk":"11540973804","pt":1719500648226,"mc":[{"id":"1.230178317","rc":[{"atb":[[1.93,2]],"id":57196226}],"con":true,"img":false}]}
{"op":"mcm","clk":"11540973830","pt":1719500648530,"mc":[{"id":"1.230178317","rc":[{"atb":[[1.7,0],[1.93,4.5]],"id":57196226},{"atb":[[2.36,17.9],[2.42,2.9]],"id":52655636},{"atb":[[1.97,5],[2.18,3.5],[2.1,12.04]],"id":70902601},{"atb":[[2.48,10]],"id":69685608}],"con":true,"img":false}]}
{"op":"mcm","clk":"11540973840","pt":1719500648599,"mc":[{"id":"1.230178317","rc":[{"atb":[[1.87,6.52]],"id":57196226},{"atb":[[2.58,9.94]],"id":46611436},{"atb":[[2.42,0]],"id":52655636},{"atb":[[2.22,2],[2.18,0]],"id":70902601},{"atb":[[2.98,0]],"id":69685608},{"atb":[[2.54,0]],"id":49159417}],"con":true,"img":false}]}
{"op":"mcm","clk":"11540973860","pt":1719500648802,"mc":[{"id":"1.230178317","rc":[{"atb":[[1.93,7.1]],"id":57196226},{"atb":[[2.62,3.42]],"id":46611436},{"atb":[[2.46,3]],"id":52655636},{"atb":[[2.22,4]],"id":70902601},{"atl":[[4.5,3.96]],"id":70902601}],"con":true,"img":false}]}
{"op":"mcm","clk":"11540973876","pt":1719500649007,"mc":[{"id":"1.230178317","rc":[{"atb":[[2.58,7.94]],"id":46611436}],"con":true,"img":false}]}
{"op":"mcm","clk":"11540973884","pt":1719500649107,"mc":[{"id":"1.230178317","rc":[{"atb":[[2.62,5.42]],"id":46611436},{"atb":[[2.52,3.85]],"id":49159417}],"con":true,"img":false}]}
{"op":"mcm","clk":"11540973898","pt":1719500649218,"mc":[{"id":"1.230178317","rc":[{"atl":[[5,1],[4.9,0]],"id":46611436},{"atb":[[2.42,3.82]],"id":52655636},{"atl":[[5.6,4.05],[5.5,0]],"id":52655636},{"atl":[[4.1,5.59]],"id":70902601},{"atl":[[5.6,1],[5.5,0]],"id":69685608}],"con":true,"img":false}]}
{"op":"mcm","clk":"11540973910","pt":1719500649323,"mc":[{"id":"1.230178317","rc":[{"atb":[[1.84,10],[1.91,2.11]],"id":57196226},{"atb":[[2,0],[2.26,2.11]],"id":70902601},{"atl":[[4.2,0]],"id":70902601},{"atl":[[6.2,5.76],[6.6,2.5]],"id":69685608}],"con":true,"img":false}]}
{"op":"mcm","clk":"11540973930","pt":1719500649519,"mc":[{"id":"1.230178317","rc":[{"atb":[[2.42,0]],"id":52655636}],"con":true,"img":false}]}
{"op":"mcm","clk":"11540973939","pt":1719500649631,"mc":[{"id":"1.230178317","rc":[{"atl":[[5,0],[4.9,1]],"id":46611436},{"atl":[[5.5,1]],"id":52655636},{"atl":[[5.6,0],[6.2,6.76]],"id":69685608}],"con":true,"img":false}]}
{"op":"mcm","clk":"11540973949","pt":1719500649740,"mc":[{"id":"1.230178317","rc":[{"atl":[[5.6,3.05],[5.5,1.84]],"id":52655636}],"con":true,"img":false}]}
{"op":"mcm","clk":"11540973958","pt":1719500649833,"mc":[{"id":"1.230178317","rc":[{"atl":[[4.9,9.85]],"id":46611436}],"con":true,"img":false}]}
{"op":"mcm","clk":"11540973968","pt":1719500649927,"mc":[{"id":"1.230178317","rc":[{"atl":[[5.3,0]],"id":46611436}],"con":true,"img":false}]}
{"op":"mcm","clk":"11540973978","pt":1719500650031,"mc":[{"id":"1.230178317","rc":[{"atb":[[1.92,8.16]],"id":57196226},{"atb":[[2.6,8]],"id":46611436},{"atb":[[2.44,3.05]],"id":52655636},{"atb":[[2.2,4.59]],"id":70902601},{"atb":[[2.56,4.21]],"id":49159417}],"con":true,"img":false}]}
{"op":"mcm","clk":"11540973987","pt":1719500650134,"mc":[{"id":"1.230178317","rc":[{"atb":[[2.58,0]],"id":46611436},{"atl":[[5.4,10.05]],"id":46611436},{"atl":[[7.8,0]],"id":69685608}],"con":true,"img":false}]}
{"op":"mcm","clk":"11540973995","pt":1719500650202,"mc":[{"id":"1.230178317","rc":[{"atb":[[2.64,1.94]],"id":46611436},{"atb":[[2.48,1.94]],"id":52655636},{"atl":[[5.7,5.02]],"id":52655636},{"atb":[[2.28,1.94]],"id":70902601},{"atl":[[6,0.84]],"id":69685608},{"atb":[[2.6,1.94]],"id":49159417}],"con":true,"img":false}]}
{"op":"mcm","clk":"11540974003","pt":1719500650303,"mc":[{"id":"1.230178317","rc":[{"atb":[[1.84,27.32]],"id":57196226},{"atb":[[2.62,12.91]],"id":46611436},{"atl":[[4.8,10.79]],"id":46611436},{"atb":[[2.36,23.28]],"id":52655636},{"atl":[[5.6,11.05]],"id":52655636},{"atb":[[2.22,2]],"id":70902601},{"atl":[[4.1,17.35]],"id":70902601},{"atl":[[6.2,12.47]],"id":69685608},{"atb":[[2.56,8.35],[2.6,4.11]],"id":49159417},{"atl":[[5.1,8.1]],"id":49159417}],"con":true,"img":false}]}
{"op":"mcm","clk":"11540974011","pt":1719500650403,"mc":[{"id":"1.230178317","rc":[{"atl":[[5.5,6.87],[5.7,3.02]],"id":52655636},{"atb":[[2.28,3.94]],"id":70902601},{"atl":[[6.2,11.47]],"id":69685608}],"con":true,"img":false}]}
{"op":"mcm","clk":"11540974018","pt":1719500650506,"mc":[{"id":"1.230178317","rc":[{"atl":[[6.8,6.99]],"id":69685608}],"con":true,"img":false}]}
{"op":"mcm","clk":"11540974036","pt":1719500650815,"mc":[{"id":"1.230178317","rc":[{"atl":[[4.5,0]],"id":70902601}],"con":true,"img":false}]}
{"op":"mcm","clk":"11540974045","pt":1719500651019,"mc":[{"id":"1.230178317","rc":[{"atl":[[4.4,1.78]],"id":70902601}],"con":true,"img":false}]}
{"op":"mcm","clk":"11540974069","pt":1719500651332,"mc":[{"id":"1.230178317","rc":[{"atl":[[4,4.84],[4.4,0],[4.7,0]],"id":70902601}],"con":true,"img":false}]}
{"op":"mcm","clk":"11540974077","pt":1719500651431,"mc":[{"id":"1.230178317","rc":[{"atl":[[6.2,12.47],[6.8,5.99]],"id":69685608},{"atb":[[2.58,0.16]],"id":49159417}],"con":true,"img":false}]}
{"op":"mcm","clk":"11540974083","pt":1719500651533,"mc":[{"id":"1.230178317","rc":[{"atb":[[2.62,2]],"id":49159417}],"con":true,"img":false}]}
{"op":"mcm","clk":"11540974090","pt":1719500651637,"mc":[{"id":"1.230178317","rc":[{"atl":[[4.3,4.22]],"id":70902601}],"con":true,"img":false}]}
{"op":"mcm","clk":"11540974118","pt":1719500651903,"mc":[{"id":"1.230178317","rc":[{"atb":[[2.02,10.4],[2.1,0]],"id":70902601},{"atb":[[2.52,0]],"id":49159417},{"atl":[[5.3,1]],"id":49159417}],"con":true,"img":false}]}
{"op":"mcm","clk":"11540974131","pt":1719500652026,"mc":[{"id":"1.230178317","rc":[{"atl":[[5.1,7.1]],"id":49159417}],"con":true,"img":false}]}
{"op":"mcm","clk":"11540974152","pt":1719500652313,"mc":[{"id":"1.230178317","rc":[{"atl":[[4.3,0]],"id":70902601}],"con":true,"img":false}]}
{"op":"mcm","clk":"11540974171","pt":1719500652516,"mc":[{"id":"1.230178317","rc":[{"atl":[[3.1,10.05],[3.55,0.99]],"id":57196226}],"con":true,"img":false}]}
{"op":"mcm","clk":"11540974184","pt":1719500652621,"mc":[{"id":"1.230178317","rc":[{"atl":[[4.2,3.62]],"id":70902601}],"con":true,"img":false}]}
{"op":"mcm","clk":"11540974217","pt":1719500653032,"mc":[{"id":"1.230178317","rc":[{"atb":[[2.64,0]],"id":46611436},{"atb":[[2.48,0]],"id":52655636},{"atl":[[4.2,0]],"id":70902601},{"atl":[[6.4,2.5]],"id":49159417}],"con":true,"img":false}]}
{"op":"mcm","clk":"11540974225","pt":1719500653134,"mc":[{"id":"1.230178317","rc":[{"atb":[[2.36,5.38],[2.34,6.1]],"id":52655636},{"atl":[[5.2,7.95]],"id":49159417}],"con":true,"img":false}]}
{"op":"mcm","clk":"11540974229","pt":1719500653231,"mc":[{"id":"1.230178317","rc":[{"atb":[[2.64,1.94]],"id":46611436},{"atb":[[2.48,1.94]],"id":52655636}],"con":true,"img":false}]}
{"op":"mcm","clk":"11540974238","pt":1719500653392,"mc":[{"id":"1.230178317","rc":[{"atl":[[4.3,8.47]],"id":70902601}],"con":true,"img":false}]}
{"op":"mcm","clk":"11540974244","pt":1719500653494,"mc":[{"id":"1.230178317","rc":[{"atl":[[5.4,2.5]],"id":46611436}],"con":true,"img":false}]}
{"op":"mcm","clk":"11540974292","pt":1719500654215,"mc":[{"id":"1.230178317","rc":[{"atb":[[1.8,0]],"id":57196226}],"con":true,"img":false}]}
{"op":"mcm","clk":"11540974303","pt":1719500654328,"mc":[{"id":"1.230178317","rc":[{"atl":[[5,1],[4.9,8.85]],"id":46611436},{"atl":[[5.6,12.05],[5.5,5.87]],"id":52655636},{"atl":[[5.6,1],[6.2,11.47],[6,1.84]],"id":69685608}],"con":true,"img":false}]}
{"op":"mcm","clk":"11540974310","pt":1719500654425,"mc":[{"id":"1.230178317","rc":[{"atl":[[5.7,2.5]],"id":52655636}],"con":true,"img":false}]}
{"op":"mcm","clk":"11540974319","pt":1719500654528,"mc":[{"id":"1.230178317","rc":[{"atl":[[5.1,1],[5,0]],"id":46611436},{"atl":[[5.6,11.05],[5.5,6.87]],"id":52655636},{"atl":[[5.6,0],[5.5,1],[6,0.84]],"id":69685608}],"con":true,"img":false}]}
{"op":"mcm","clk":"11540974337","pt":1719500654732,"mc":[{"id":"1.230178317","rc":[{"atl":[[5.1,0],[5.2,1]],"id":46611436}],"con":true,"img":false}]}
{"op":"mcm","clk":"11540974363","pt":1719500654939,"mc":[{"id":"1.230178317","rc":[{"atl":[[5.6,3.05]],"id":52655636},{"atl":[[4.1,5.59]],"id":70902601},{"atl":[[6.2,5.76]],"id":69685608}],"con":true,"img":false}]}
{"op":"mcm","clk":"11540974374","pt":1719500655040,"mc":[{"id":"1.230178317","rc":[{"atl":[[5.5,1.84],[5.7,12.43]],"id":52655636},{"atl":[[4,0.84],[4.2,10.44]],"id":70902601}],"con":true,"img":false}]}
{"op":"mcm","clk":"11540974384","pt":1719500655137,"mc":[{"id":"1.230178317","rc":[{"atl":[[5.5,9.72]],"id":52655636},{"atl":[[4,12.38]],"id":70902601},{"atl":[[6,6.33]],"id":69685608}],"con":true,"img":false}]}
{"op":"mcm","clk":"11540974395","pt":1719500655201,"mc":[{"id":"1.230178317","rc":[{"atl":[[5.7,2.5],[5.4,9.73]],"id":52655636},{"atl":[[3.95,10.44],[4.2,0]],"id":70902601},{"atl":[[5.9,5.77],[6.2,0.14]],"id":69685608}],"con":true,"img":false}]}
{"op":"mcm","clk":"11540974440","pt":1719500655712,"mc":[{"id":"1.230178317","rc":[{"atl":[[3.9,0.84]],"id":70902601}],"con":true,"img":false}]}
{"op":"mcm","clk":"11540974456","pt":1719500655925,"mc":[{"id":"1.230178317","rc":[{"atb":[[1.94,11.44]],"id":57196226},{"atb":[[2.64,14.58]],"id":46611436},{"atl":[[4.7,13.48]],"id":46611436},{"atb":[[2.48,6.51]],"id":52655636},{"atl":[[5.3,4.57]],"id":52655636},{"atl":[[3.9,5.39]],"id":70902601},{"atl":[[5.4,5.08]],"id":69685608},{"atb":[[2.62,6.59]],"id":49159417},{"atl":[[5,5.43]],"id":49159417}],"con":true,"img":false}]}
{"op":"mcm","clk":"11540974463","pt":1719500656025,"mc":[{"id":"1.230178317","rc":[{"atb":[[1.87,0]],"id":57196226},{"atb":[[2.64,12.64],[2.6,0]],"id":46611436},{"atl":[[4.8,2.79]],"id":46611436},{"atb":[[2.44,0],[2.48,4.57]],"id":52655636},{"atl":[[5.6,0]],"id":52655636},{"atl":[[6.8,0]],"id":69685608},{"atb":[[2.56,6.14]],"id":49159417},{"atl":[[5.1,4.89]],"id":49159417}],"con":true,"img":false}]}
{"op":"mcm","clk":"11540974471","pt":1719500656128,"mc":[{"id":"1.230178317","rc":[{"atb":[[1.92,7.27]],"id":57196226},{"atl":[[4.1,1]],"id":70902601}],"con":true,"img":false}]}
{"op":"mcm","clk":"11540974480","pt":1719500656420,"mc":[{"id":"1.230178317","rc":[{"atb":[[2.64,14.58]],"id":46611436},{"atb":[[2.48,6.51]],"id":52655636},{"atl":[[8.6,0]],"id":69685608}],"con":true,"img":false}]}
{"op":"mcm","clk":"11540974490","pt":1719500656437,"mc":[{"id":"1.230178317","rc":[{"atl":[[5.5,8.88]],"id":52655636},{"atl":[[4,11.53]],"id":70902601},{"atl":[[6,5.49]],"id":69685608}],"con":true,"img":false}]}
{"op":"mcm","clk":"11540974498","pt":1719500656448,"mc":[{"id":"1.230178317","rc":[{"atl":[[5.2,0.52]],"id":52655636}],"con":true,"img":false}]}
{"op":"mcm","clk":"11540974509","pt":1719500656634,"mc":[{"id":"1.230178317","rc":[{"atb":[[1.92,2.5]],"id":57196226}],"con":true,"img":false}]}
{"op":"mcm","clk":"11540974533","pt":1719500656806,"mc":[{"id":"1.230178317","rc":[{"atb":[[1.93,5.1]],"id":57196226},{"atl":[[5.2,1.37]],"id":52655636}],"con":true,"img":false}]}
{"op":"mcm","clk":"11540974542","pt":1719500656901,"mc":[{"id":"1.230178317","rc":[{"atb":[[1.95,2]],"id":57196226},{"atl":[[5.2,5.94],[5.4,0]],"id":52655636},{"atl":[[5.4,10.4]],"id":69685608}],"con":true,"img":false}]}
{"op":"mcm","clk":"11540974550","pt":1719500656999,"mc":[{"id":"1.230178317","rc":[{"atb":[[1.95,7.1],[1.93,2.6]],"id":57196226},{"atl":[[5.3,5.77]],"id":69685608}],"con":true,"img":false}]}
{"op":"mcm","clk":"11540974565","pt":1719500657112,"mc":[{"id":"1.230178317","rc":[{"atb":[[1.94,16.54],[1.95,2]],"id":57196226},{"atb":[[2.36,0],[2.42,29.61]],"id":46611436},{"atl":[[5.9,0]],"id":69685608}],"con":true,"img":false}]}
{"op":"mcm","clk":"11540974574","pt":1719500657213,"mc":[{"id":"1.230178317","rc":[{"atb":[[2.3,2.5],[2.22,5],[2.14,10]],"id":46611436}],"con":true,"img":false}]}
{"op":"mcm","clk":"11540974588","pt":1719500657316,"mc":[{"id":"1.230178317","rc":[{"atb":[[1.93,0]],"id":57196226},{"atb":[[2.62,7.49]],"id":46611436},{"atb":[[2.46,0]],"id":52655636},{"atb":[[2.22,0]],"id":70902601}],"con":true,"img":false}]}
{"op":"mcm","clk":"11540974593","pt":1719500657415,"mc":[{"id":"1.230178317","rc":[{"atb":[[1.95,6]],"id":57196226},{"atb":[[2.66,2]],"id":46611436},{"atb":[[2.5,3]],"id":52655636}],"con":true,"img":false}]}
{"op":"mcm","clk":"11540974613","pt":1719500657627,"mc":[{"id":"1.230178317","rc":[{"atb":[[1.96,6]],"id":57196226}],"con":true,"img":false}]}
{"op":"mcm","clk":"11540974623","pt":1719500657721,"mc":[{"id":"1.230178317","rc":[{"atb":[[1.94,11.44]],"id":57196226},{"atl":[[5.2,0.84]],"id":69685608}],"con":true,"img":false}]}
{"op":"mcm","clk":"11540974630","pt":1719500657828,"mc":[{"id":"1.230178317","rc":[{"atl":[[5.4,5.08]],"id":69685608}],"con":true,"img":false}]}
{"op":"mcm","clk":"11540974650","pt":1719500658029,"mc":[{"id":"1.230178317","rc":[{"atl":[[5.3,0],[5.4,11.7]],"id":69685608}],"con":true,"img":false}]}
{"op":"mcm","clk":"11540974665","pt":1719500658237,"mc":[{"id":"1.230178317","rc":[{"atb":[[1.95,4]],"id":57196226}],"con":true,"img":false}]}
{"op":"mcm","clk":"11540974676","pt":1719500658291,"mc":[{"id":"1.230178317","rc":[{"atb":[[1.97,2]],"id":57196226}],"con":true,"img":false}]}
{"op":"mcm","clk":"11540974706","pt":1719500658704,"mc":[{"id":"1.230178317","rc":[{"spn":2.44,"spf":"NaN","id":57196226},{"spn":3.68,"spf":"NaN","id":46611436},{"spn":3.85,"spf":"NaN","id":52655636},{"spn":3.09,"spf":"NaN","id":70902601},{"atl":[[5.2,0]],"id":69685608},{"spn":4.52,"spf":"NaN","id":69685608},{"spn":3.81,"spf":"NaN","id":49159417}],"con":true,"img":false}]}
{"op":"mcm","clk":"11540974712","pt":1719500658805,"mc":[{"id":"1.230178317","rc":[{"atl":[[5.3,5.87]],"id":69685608}],"con":true,"img":false}]}
{"op":"mcm","clk":"11540974741","pt":1719500659116,"mc":[{"id":"1.230178317","rc":[{"atb":[[2.48,4.57]],"id":52655636},{"atb":[[2.6,2.17]],"id":49159417}],"con":true,"img":false}]}
{"op":"mcm","clk":"11540974761","pt":1719500659330,"mc":[{"id":"1.230178317","rc":[{"atb":[[2.52,1.94]],"id":52655636},{"atb":[[2.64,1.94]],"id":49159417}],"con":true,"img":false}]}
{"op":"mcm","clk":"11540974829","pt":1719500660122,"mc":[{"id":"1.230178317","rc":[{"atb":[[1.84,10]],"id":57196226},{"atb":[[2.62,0]],"id":46611436},{"atl":[[4.8,0]],"id":46611436},{"atl":[[5.5,1]],"id":52655636},{"atl":[[4,0]],"id":70902601},{"atl":[[6,0]],"id":69685608},{"atb":[[2.56,0]],"id":49159417},{"atl":[[5.1,0]],"id":49159417}],"con":true,"img":false}]}
{"op":"mcm","clk":"11540974838","pt":1719500660205,"mc":[{"id":"1.230178317","rc":[{"atl":[[5.2,23.34]],"id":46611436},{"atl":[[4.1,16.84]],"id":70902601},{"atl":[[5.2,0]],"id":49159417}],"con":true,"img":false}]}
{"op":"mcm","clk":"11540974845","pt":1719500660308,"mc":[{"id":"1.230178317","rc":[{"atb":[[1.94,25.48]],"id":57196226},{"atb":[[2.64,21.86]],"id":46611436},{"atl":[[4.9,0],[4.7,16.07]],"id":46611436},{"atl":[[5.2,13.41]],"id":52655636},{"atl":[[3.95,0],[3.9,16.69]],"id":70902601},{"atl":[[5.3,10.43]],"id":69685608},{"atb":[[2.62,12.08]],"id":49159417},{"atl":[[5,10.15],[5.3,14.39]],"id":49159417}],"con":true,"img":false}]}
{"op":"mcm","clk":"11540974939","pt":1719500661342,"mc":[{"id":"1.230178317","rc":[{"atl":[[5.5,0]],"id":69685608}],"con":true,"img":false}]}
{"op":"mcm","clk":"11540974966","pt":1719500661505,"mc":[{"id":"1.230178317","rc":[{"atb":[[1.98,2.11],[1.91,0]],"id":57196226},{"atb":[[2.3,0],[2.42,2.11]],"id":52655636}],"con":true,"img":false}]}
{"op":"mcm","clk":"11540974980","pt":1719500661607,"mc":[{"id":"1.230178317","rc":[{"atb":[[1.98,4.23],[1.96,0]],"id":57196226}],"con":true,"img":false}]}
{"op":"mcm","clk":"11540975021","pt":1719500662015,"mc":[{"id":"1.230178317","rc":[{"atb":[[2.62,3.4]],"id":46611436}],"con":true,"img":false}]}
{"op":"mcm","clk":"11540975029","pt":1719500662118,"mc":[{"id":"1.230178317","rc":[{"atb":[[2.6,0],[2.62,15.98]],"id":49159417}],"con":true,"img":false}]}
{"op":"mcm","clk":"11540975035","pt":1719500662221,"mc":[{"id":"1.230178317","rc":[{"atb":[[2.52,0]],"id":52655636},{"atl":[[5.5,1]],"id":69685608},{"atb":[[2.64,0]],"id":49159417},{"atl":[[5.5,1]],"id":49159417}],"con":true,"img":false}]}
{"op":"mcm","clk":"11540975040","pt":1719500662322,"mc":[{"id":"1.230178317","rc":[{"atb":[[1.97,0]],"id":57196226},{"atb":[[2.4,4.12]],"id":46611436},{"atb":[[2.52,1.94]],"id":52655636},{"atb":[[2.64,1.94]],"id":49159417},{"atl":[[5.3,13.39]],"id":49159417}],"con":true,"img":false}]}
{"op":"mcm","clk":"11540975050","pt":1719500662425,"mc":[{"id":"1.230178317","rc":[{"atb":[[1.99,2]],"id":57196226}],"con":true,"img":false}]}
{"op":"mcm","clk":"11540975059","pt":1719500662535,"mc":[{"id":"1.230178317","rc":[{"atb":[[2.4,0]],"id":46611436}],"con":true,"img":false}]}
{"op":"mcm","clk":"11540975118","pt":1719500663098,"mc":[{"id":"1.230178317","rc":[{"atl":[[5.4,5.08]],"id":69685608}],"con":true,"img":false}]}
{"op":"mcm","clk":"11540975128","pt":1719500663203,"mc":[{"id":"1.230178317","rc":[{"atl":[[5.2,10.44]],"id":69685608}],"con":true,"img":false}]}
{"op":"mcm","clk":"11540975161","pt":1719500663514,"mc":[{"id":"1.230178317","rc":[{"atl":[[5.8,1],[5.5,0]],"id":69685608}],"con":true,"img":false}]}
{"op":"mcm","clk":"11540975190","pt":1719500663930,"mc":[{"id":"1.230178317","rc":[{"atl":[[5.3,9.34]],"id":69685608}],"con":true,"img":false}]}
{"op":"mcm","clk":"11540975202","pt":1719500664032,"mc":[{"id":"1.230178317","rc":[{"atl":[[6.4,0]],"id":52655636}],"con":true,"img":false}]}
{"op":"mcm","clk":"11540975210","pt":1719500664132,"mc":[{"id":"1.230178317","rc":[{"atl":[[5.3,4.56]],"id":69685608}],"con":true,"img":false}]}
{"op":"mcm","clk":"11540975219","pt":1719500664235,"mc":[{"id":"1.230178317","rc":[{"atl":[[5.2,15.22]],"id":69685608},{"atl":[[5.3,0],[5.4,22.73]],"id":49159417}],"con":true,"img":false}]}
{"op":"mcm","clk":"11540975257","pt":1719500664698,"mc":[{"id":"1.230178317","rc":[{"atb":[[1.99,8.18]],"id":57196226},{"atb":[[2.66,16.6]],"id":46611436},{"atb":[[2.48,8.21],[2.52,7.62]],"id":52655636},{"atl":[[5.1,5.68]],"id":52655636},{"atl":[[5.1,8.08]],"id":69685608},{"atb":[[2.64,11.02],[2.6,3.52]],"id":49159417}],"con":true,"img":false}]}
{"op":"mcm","clk":"11540975264","pt":1719500664798,"mc":[{"id":"1.230178317","rc":[{"atb":[[1.94,14.04]],"id":57196226},{"atb":[[2.64,9.22]],"id":46611436},{"atb":[[2.48,3.64]],"id":52655636},{"atl":[[5.3,0]],"id":52655636},{"atl":[[5.4,0]],"id":69685608},{"atb":[[2.62,11.39]],"id":49159417}],"con":true,"img":false}]}
{"op":"mcm","clk":"11540975274","pt":1719500664907,"mc":[{"id":"1.230178317","rc":[{"atl":[[5.3,0]],"id":69685608}],"con":true,"img":false}]}
{"op":"mcm","clk":"11540975297","pt":1719500665107,"mc":[{"id":"1.230178317","rc":[{"atb":[[2.64,7.27]],"id":46611436},{"atl":[[5.2,19.63]],"id":69685608}],"con":true,"img":false}]}
{"op":"mcm","clk":"11540975309","pt":1719500665211,"mc":[{"id":"1.230178317","rc":[{"atb":[[2.68,1.94]],"id":46611436},{"atl":[[5,0.84]],"id":52655636}],"con":true,"img":false}]}
{"op":"mcm","clk":"11540975319","pt":1719500665316,"mc":[{"id":"1.230178317","rc":[{"atl":[[4.6,16.07],[5.2,1]],"id":46611436},{"atl":[[3.85,16.69],[4.1,1]],"id":70902601}],"con":true,"img":false}]}
{"op":"mcm","clk":"11540975326","pt":1719500665417,"mc":[{"id":"1.230178317","rc":[{"atl":[[4.6,33.57]],"id":46611436},{"atl":[[3.85,23.09]],"id":70902601},{"atl":[[5.2,14.85]],"id":69685608}],"con":true,"img":false}]}
{"op":"mcm","clk":"11540975337","pt":1719500665520,"mc":[{"id":"1.230178317","rc":[{"atb":[[1.97,5.66]],"id":57196226},{"atb":[[2.62,0]],"id":46611436},{"atl":[[4.7,3.43]],"id":46611436},{"atb":[[2.48,0]],"id":52655636},{"atb":[[2.6,0],[2.62,9.39]],"id":49159417}],"con":true,"img":false}]}
{"op":"mcm","clk":"11540975346","pt":1719500665628,"mc":[{"id":"1.230178317","rc":[{"atl":[[3.9,12.14]],"id":70902601},{"atb":[[2.66,2]],"id":49159417}],"con":true,"img":false}]}
{"op":"mcm","clk":"11540975354","pt":1719500665733,"mc":[{"id":"1.230178317","rc":[{"atb":[[1.97,0]],"id":57196226}],"con":true,"img":false}]}
{"op":"mcm","clk":"11540975360","pt":1719500665830,"mc":[{"id":"1.230178317","rc":[{"atl":[[4.5,0.84]],"id":46611436},{"atl":[[3.8,0.84]],"id":70902601}],"con":true,"img":false}]}
{"op":"mcm","clk":"11540975369","pt":1719500665938,"mc":[{"id":"1.230178317","rc":[{"atb":[[2.24,4.46]],"id":70902601}],"con":true,"img":false}]}
{"op":"mcm","clk":"11540975380","pt":1719500666037,"mc":[{"id":"1.230178317","rc":[{"atb":[[2.56,11.39],[2.62,5.49]],"id":49159417}],"con":true,"img":false}]}
{"op":"mcm","clk":"11540975387","pt":1719500666149,"mc":[{"id":"1.230178317","rc":[{"atb":[[1.95,0]],"id":57196226},{"atb":[[2.5,0]],"id":52655636}],"con":true,"img":false}]}
{"op":"mcm","clk":"11540975401","pt":1719500666298,"mc":[{"id":"1.230178317","rc":[{"atb":[[2,2.5]],"id":57196226},{"atb":[[2.68,4.92]],"id":46611436},{"atb":[[2.54,2.16]],"id":52655636},{"atb":[[2.3,2]],"id":70902601},{"atl":[[5.1,13.56]],"id":69685608}],"con":true,"img":false}]}
{"op":"mcm","clk":"11540975408","pt":1719500666401,"mc":[{"id":"1.230178317","rc":[{"atb":[[2,6.74]],"id":57196226},{"atl":[[5,13.57],[5.2,4.41]],"id":69685608}],"con":true,"img":false}]}
{"op":"mcm","clk":"11540975417","pt":1719500666503,"mc":[{"id":"1.230178317","rc":[{"atb":[[1.98,2.11]],"id":57196226}],"con":true,"img":false}]}
{"op":"mcm","clk":"11540975428","pt":1719500666606,"mc":[{"id":"1.230178317","rc":[{"atb":[[2.24,0]],"id":70902601}],"con":true,"img":false}]}
{"op":"mcm","clk":"11540975462","pt":1719500667017,"mc":[{"id":"1.230178317","rc":[{"atb":[[1.99,6.18]],"id":57196226}],"con":true,"img":false}]}
{"op":"mcm","clk":"11540975470","pt":1719500667120,"mc":[{"id":"1.230178317","rc":[{"atb":[[2.02,2]],"id":57196226},{"atl":[[5.1,8.08]],"id":69685608}],"con":true,"img":false}]}
{"op":"mcm","clk":"11540975481","pt":1719500667235,"mc":[{"id":"1.230178317","rc":[{"atb":[[2.58,15],[2.48,0]],"id":69685608},{"atl":[[5.6,1],[5.5,0]],"id":49159417}],"con":true,"img":false}]}
{"op":"mcm","clk":"11540975504","pt":1719500667534,"mc":[{"id":"1.230178317","rc":[{"atb":[[2.28,1.94]],"id":70902601}],"con":true,"img":false}]}
{"op":"mcm","clk":"11540975509","pt":1719500667636,"mc":[{"id":"1.230178317","rc":[{"atb":[[1.02,24.65]],"id":70902601},{"atl":[[5,18.63]],"id":69685608}],"con":true,"img":false}]}
{"op":"mcm","clk":"11540975536","pt":1719500667906,"mc":[{"id":"1.230178317","rc":[{"atb":[[2.66,14.6]],"id":46611436}],"con":true,"img":false}]}
{"op":"mcm","clk":"11540975542","pt":1719500668000,"mc":[{"id":"1.230178317","rc":[{"atb":[[2.7,2]],"id":46611436},{"atl":[[4.2,1]],"id":70902601},{"atl":[[5.8,0],[5.7,1]],"id":69685608}],"con":true,"img":false}]}
{"op":"mcm","clk":"11540975551","pt":1719500668112,"mc":[{"id":"1.230178317","rc":[{"atb":[[2.18,0]],"id":52655636},{"atl":[[4.1,0]],"id":70902601},{"atl":[[5.5,22.22],[5.4,0]],"id":49159417}],"con":true,"img":false}]}
{"op":"mcm","clk":"11540975558","pt":1719500668209,"mc":[{"id":"1.230178317","rc":[{"atb":[[2.52,5.68]],"id":52655636},{"atb":[[2.28,0]],"id":70902601}],"con":true,"img":false}]}
{"op":"mcm","clk":"11540975575","pt":1719500668412,"mc":[{"id":"1.230178317","rc":[{"atb":[[2.02,3.94]],"id":57196226},{"atb":[[2.56,1.94]],"id":52655636},{"atb":[[2.28,1.94]],"id":70902601}],"con":true,"img":false}]}
{"op":"mcm","clk":"11540975634","pt":1719500669340,"mc":[{"id":"1.230178317","rc":[{"atl":[[3.55,0]],"id":57196226},{"atl":[[5.8,1]],"id":69685608}],"con":true,"img":false}]}
{"op":"mcm","clk":"11540975640","pt":1719500669445,"mc":[{"id":"1.230178317","rc":[{"atl":[[5.7,0]],"id":69685608}],"con":true,"img":false}]}
{"op":"mcm","clk":"11540975649","pt":1719500669555,"mc":[{"id":"1.230178317","rc":[{"atl":[[4.1,1],[4.2,0]],"id":70902601}],"con":true,"img":false}]}
{"op":"mcm","clk":"11540975655","pt":1719500669651,"mc":[{"id":"1.230178317","rc":[{"atl":[[5.8,0]],"id":69685608}],"con":true,"img":false}]}
{"op":"mcm","clk":"11540975664","pt":1719500669717,"mc":[{"id":"1.230178317","rc":[{"atl":[[5.7,1]],"id":69685608}],"con":true,"img":false}]}
{"op":"mcm","clk":"11540975667","pt":1719500669807,"mc":[{"id":"1.230178317","rc":[{"atb":[[2.64,0]],"id":46611436},{"atl":[[4.7,0.84]],"id":46611436},{"atb":[[2.36,0]],"id":52655636},{"atl":[[5.2,5.94]],"id":52655636},{"atl":[[3.9,0.84]],"id":70902601},{"atl":[[5.2,0]],"id":69685608},{"atb":[[2.62,0]],"id":49159417}],"con":true,"img":false}]}
{"op":"mcm","clk":"11540975677","pt":1719500669915,"mc":[{"id":"1.230178317","rc":[{"atl":[[4.6,17.5],[4.7,27.87]],"id":46611436},{"atl":[[3.85,6.39],[3.9,24.78]],"id":70902601}],"con":true,"img":false}]}
{"op":"mcm","clk":"11540975686","pt":1719500670022,"mc":[{"id":"1.230178317","rc":[{"atb":[[2.68,11.77]],"id":46611436},{"atl":[[4.6,19.86]],"id":46611436},{"atb":[[2.52,9.06]],"id":52655636},{"atl":[[5.1,12.99]],"id":52655636},{"atl":[[3.85,17.57]],"id":70902601},{"atl":[[5,22.7]],"id":69685608},{"atb":[[2.64,16.3]],"id":49159417}],"con":true,"img":false}]}
{"op":"mcm","clk":"11540975689","pt":1719500670116,"mc":[{"id":"1.230178317","rc":[{"atl":[[5,6.78],[5.2,1.37]],"id":52655636}],"con":true,"img":false}]}
{"op":"mcm","clk":"11540975718","pt":1719500670428,"mc":[{"id":"1.230178317","rc":[{"atl":[[3.8,18.41]],"id":70902601}],"con":true,"img":false}]}
{"op":"mcm","clk":"11540975726","pt":1719500670535,"mc":[{"id":"1.230178317","rc":[{"atl":[[3.9,0.84]],"id":70902601}],"con":true,"img":false}]}
{"op":"mcm","clk":"11540975743","pt":1719500670747,"mc":[{"id":"1.230178317","rc":[{"atl":[[5.2,0.52]],"id":52655636}],"con":true,"img":false}]}
{"op":"mcm","clk":"11540975773","pt":1719500671151,"mc":[{"id":"1.230178317","rc":[{"atl":[[3.9,0]],"id":70902601}],"con":true,"img":false}]}
{"op":"mcm","clk":"11540975784","pt":1719500671209,"mc":[{"id":"1.230178317","rc":[{"atb":[[2.56,0]],"id":52655636},{"atb":[[2.28,0]],"id":70902601}],"con":true,"img":false}]}
{"op":"mcm","clk":"11540975803","pt":1719500671413,"mc":[{"id":"1.230178317","rc":[{"atb":[[2.56,1.94]],"id":52655636},{"atb":[[2.28,1.94]],"id":70902601}],"con":true,"img":false}]}
{"op":"mcm","clk":"11540975832","pt":1719500671725,"mc":[{"id":"1.230178317","rc":[{"atl":[[5.2,0]],"id":52655636},{"atl":[[4.9,0.84]],"id":69685608}],"con":true,"img":false}]}
{"op":"mcm","clk":"11540976007","pt":1719500673651,"mc":[{"id":"1.230178317","rc":[{"atl":[[4.9,0.52]],"id":52655636}],"con":true,"img":false}]}
{"op":"mcm","clk":"11540976017","pt":1719500673747,"mc":[{"id":"1.230178317","rc":[{"atb":[[1.98,0],[2.06,2.11]],"id":57196226}],"con":true,"img":false}]}
{"op":"mcm","clk":"11540976060","pt":1719500674220,"mc":[{"id":"1.230178317","rc":[{"atb":[[2.02,2]],"id":57196226},{"atb":[[2.56,0]],"id":52655636},{"atb":[[2.28,0]],"id":70902601}],"con":true,"img":false}]}
{"op":"mcm","clk":"11540976071","pt":1719500674316,"mc":[{"id":"1.230178317","rc":[{"atb":[[2.02,0]],"id":57196226}],"con":true,"img":false}]}
{"op":"mcm","clk":"11540976080","pt":1719500674419,"mc":[{"id":"1.230178317","rc":[{"atb":[[2.08,3.94]],"id":57196226},{"atb":[[2.56,1.94]],"id":52655636},{"atb":[[2.28,1.94]],"id":70902601}],"con":true,"img":false}]}
{"op":"mcm","clk":"11540976105","pt":1719500674735,"mc":[{"id":"1.230178317","rc":[{"atl":[[5.1,5.68]],"id":52655636},{"atl":[[3.85,6.39]],"id":70902601}],"con":true,"img":false}]}
{"op":"mcm","clk":"11540976113","pt":1719500674833,"mc":[{"id":"1.230178317","rc":[{"atb":[[2,4.24]],"id":57196226},{"atb":[[2.68,8.79]],"id":46611436},{"atb":[[2.54,0]],"id":52655636}],"con":true,"img":false}]}
{"op":"mcm","clk":"11540976118","pt":1719500674935,"mc":[{"id":"1.230178317","rc":[{"atb":[[2.1,2.84]],"id":57196226},{"atb":[[2.7,5.4]],"id":46611436},{"atb":[[2.56,4.43]],"id":52655636},{"atl":[[5,13.94]],"id":52655636},{"atl":[[3.8,29.45]],"id":70902601},{"atb":[[2.66,5]],"id":49159417}],"con":true,"img":false}]}
{"op":"mcm","clk":"11540976166","pt":1719500675560,"mc":[{"id":"1.230178317","rc":[{"atb":[[2.08,1.94]],"id":57196226}],"con":true,"img":false}]}
{"op":"mcm","clk":"11540976174","pt":1719500675654,"mc":[{"id":"1.230178317","rc":[{"atb":[[2.12,2]],"id":57196226}],"con":true,"img":false}]}
{"op":"mcm","clk":"11540976307","pt":1719500677358,"mc":[{"id":"1.230178317","rc":[{"atb":[[2.08,0]],"id":57196226},{"atb":[[2.68,6.84]],"id":46611436},{"atb":[[2.28,0]],"id":70902601},{"atb":[[2.64,14.35]],"id":49159417}],"con":true,"img":false}]}
{"op":"mcm","clk":"11540976328","pt":1719500677519,"mc":[{"id":"1.230178317","rc":[{"atb":[[2.12,3.94]],"id":57196226},{"atb":[[2.72,1.94]],"id":46611436},{"atb":[[2.28,1.94]],"id":70902601},{"atb":[[2.68,1.94]],"id":49159417}],"con":true,"img":false}]}
{"op":"mcm","clk":"11540976483","pt":1719500679751,"mc":[{"id":"1.230178317","rc":[{"atb":[[2.68,0]],"id":46611436},{"atb":[[2.64,9.08]],"id":49159417}],"con":true,"img":false}]}
{"op":"mcm","clk":"11540976492","pt":1719500679855,"mc":[{"id":"1.230178317","rc":[{"atb":[[2,0],[2.12,9.03],[2.02,6.18]],"id":57196226},{"atb":[[2.72,11.13],[2.54,12.25],[2.42,2.11]],"id":46611436},{"atl":[[4.5,10.03]],"id":46611436},{"atb":[[2.38,8.88],[2.34,0]],"id":52655636},{"atb":[[2.56,0],[2.58,10.16],[2.68,13.31]],"id":49159417}],"con":true,"img":false}]}
{"op":"mcm","clk":"11540976501","pt":1719500679961,"mc":[{"id":"1.230178317","rc":[{"atb":[[2.7,12.04]],"id":46611436},{"atb":[[2.56,12.02]],"id":52655636},{"atl":[[4.9,8.11]],"id":52655636},{"atb":[[2.66,10.07]],"id":49159417}],"con":true,"img":false}]}
{"op":"mcm","clk":"11540976512","pt":1719500680062,"mc":[{"id":"1.230178317","rc":[{"atb":[[1.99,0]],"id":57196226},{"atb":[[2.66,0]],"id":46611436},{"atl":[[4.6,2.36]],"id":46611436},{"atl":[[4.9,7.54]],"id":69685608},{"atb":[[2.64,0]],"id":49159417}],"con":true,"img":false}]}
{"op":"mcm","clk":"11540976527","pt":1719500680267,"mc":[{"id":"1.230178317","rc":[{"atl":[[4.7,27.03]],"id":46611436},{"atl":[[3.75,3.09]],"id":70902601}],"con":true,"img":false}]}
