{"op":"mcm","clk":"11536380662","pt":1719425245604,"mc":[{"id":"1.230178329","marketDefinition":{"bspMarket":true,"turnInPlayEnabled":false,"persistenceEnabled":false,"marketBaseRate":5.0,"eventId":"33376062","eventTypeId":"4339","numberOfWinners":2,"bettingType":"ODDS","marketType":"PLACE","marketTime":"2024-06-27T17:02:00.000Z","suspendTime":"2024-06-27T17:02:00.000Z","bspReconciled":false,"complete":true,"inPlay":false,"crossMatching":false,"runnersVoidable":false,"numberOfActiveRunners":6,"betDelay":0,"status":"OPEN","runners":[{"status":"ACTIVE","sortPriority":1,"id":53082422,"name":"1. Betsys Minnie"},{"status":"ACTIVE","sortPriority":2,"id":70053016,"name":"2. Tuxedo Twlight"},{"status":"ACTIVE","sortPriority":3,"id":66686625,"name":"3. Ballymac Addie"},{"status":"ACTIVE","sortPriority":4,"id":64812720,"name":"4. Hes A Rebel"},{"status":"ACTIVE","sortPriority":5,"id":70902603,"name":"5. Follow Suit"},{"status":"ACTIVE","sortPriority":6,"id":69942666,"name":"6. Pukka Poppy"}],"regulators":["MR_INT"],"venue":"Kinsley","countryCode":"GB","discountAllowed":false,"timezone":"Europe/London","openDate":"2024-06-27T13:36:00.000Z","version":5994643783,"name":"To Be Placed","eventName":"Kinsley 27th Jun"},"rc":[],"con":true,"img":false}]}
{"op":"mcm","clk":"11536381023","pt":1719425248531,"mc":[{"id":"1.230178329","marketDefinition":{"bspMarket":true,"turnInPlayEnabled":false,"persistenceEnabled":false,"marketBaseRate":5.0,"eventId":"33376062","eventTypeId":"4339","numberOfWinners":2,"bettingType":"ODDS","marketType":"PLACE","marketTime":"2024-06-27T17:02:00.000Z","suspendTime":"2024-06-27T17:02:00.000Z","bspReconciled":false,"complete":true,"inPlay":false,"crossMatching":false,"runnersVoidable":false,"numberOfActiveRunners":6,"betDelay":0,"status":"OPEN","runners":[{"status":"ACTIVE","sortPriority":1,"id":53082422,"name":"1. Betsys Minnie"},{"status":"ACTIVE","sortPriority":2,"id":70053016,"name":"2. Tuxedo Twlight"},{"status":"ACTIVE","sortPriority":3,"id":66686625,"name":"3. Ballymac Addie"},{"status":"ACTIVE","sortPriority":4,"id":64812720,"name":"4. Hes A Rebel"},{"status":"ACTIVE","sortPriority":5,"id":70902603,"name":"5. Follow Suit"},{"status":"ACTIVE","sortPriority":6,"id":69942666,"name":"6. Pukka Poppy"}],"regulators":["MR_INT"],"venue":"Kinsley","countryCode":"GB","discountAllowed":true,"timezone":"Europe/London","openDate":"2024-06-27T13:36:00.000Z","version":5994643783,"name":"To Be Placed","eventName":"Kinsley 27th Jun"},"rc":[],"con":true,"img":false}]}
{"op":"mcm","clk":"11536615521","pt":1719428250428,"mc":[{"id":"1.230178329","rc":[{"atb":[[1.01,45.27]],"id":64812720},{"atl":[[990,0.84]],"id":64812720},{"spn":495.5,"spf":"NaN","id":64812720},{"atb":[[1.02,22.63]],"id":70902603},{"atl":[[1000,0.84]],"id":70902603},{"spn":500.51,"spf":"NaN","id":70902603},{"atb":[[1.03,15.09]],"id":66686625},{"atl":[[990,0.84]],"id":66686625},{"spn":495.51,"spf":"NaN","id":66686625},{"atb":[[1.03,15.09]],"id":70053016},{"atl":[[1000,0.84]],"id":70053016},{"spn":500.51,"spf":"NaN","id":70053016},{"atb":[[1.03,15.09]],"id":69942666},{"atl":[[1000,0.84]],"id":69942666},{"spn":500.51,"spf":"NaN","id":69942666},{"atb":[[1.03,15.09]],"id":53082422},{"atl":[[990,0.84]],"id":53082422},{"spn":495.51,"spf":"NaN","id":53082422}],"con":true,"img":false}]}
{"op":"mcm","clk":"11536837512","pt":1719431862143,"mc":[{"id":"1.230178329","rc":[{"atb":[[1.01,45.28]],"id":64812720},{"atl":[[990,0.26]],"id":64812720},{"atb":[[1.02,22.64]],"id":70902603},{"atl":[[1000,0.26]],"id":70902603},{"atb":[[1.03,15.09]],"id":66686625},{"atl":[[990,0.26]],"id":66686625},{"atb":[[1.03,15.09]],"id":70053016},{"atl":[[1000,0.26]],"id":70053016},{"atb":[[1.03,15.09]],"id":69942666},{"atl":[[1000,0.26]],"id":69942666},{"atb":[[1.03,15.09]],"id":53082422},{"atl":[[990,0.26]],"id":53082422}],"con":true,"img":false}]}
{"op":"mcm","clk":"11537232265","pt":1719437882521,"mc":[{"id":"1.230178329","marketDefinition":{"bspMarket":true,"turnInPlayEnabled":false,"persistenceEnabled":false,"marketBaseRate":5.0,"eventId":"33376062","eventTypeId":"4339","numberOfWinners":2,"bettingType":"ODDS","marketType":"PLACE","marketTime":"2024-06-27T17:02:00.000Z","suspendTime":"2024-06-27T17:02:00.000Z","bspReconciled":false,"complete":true,"inPlay":false,"crossMatching":false,"runnersVoidable":false,"numberOfActiveRunners":6,"betDelay":0,"status":"OPEN","runners":[{"status":"ACTIVE","sortPriority":1,"id":53082422,"name":"1. Betsys Minnie"},{"status":"ACTIVE","sortPriority":2,"id":70053016,"name":"2. Tuxedo Twlight"},{"status":"ACTIVE","sortPriority":3,"id":66686625,"name":"3. Ballymac Addie"},{"status":"ACTIVE","sortPriority":4,"id":64812720,"name":"4. Hes A Rebel"},{"status":"ACTIVE","sortPriority":5,"id":70902603,"name":"5. Follow Suit"},{"status":"ACTIVE","sortPriority":6,"id":69942666,"name":"6. Pukka Poppy"}],"regulators":["MR_INT"],"venue":"Kinsley","countryCode":"GB","discountAllowed":true,"timezone":"Europe/London","openDate":"2024-06-27T13:36:00.000Z","version":5994643783,"name":"To Be Placed","eventName":"Kinsley 27th Jun"},"rc":[{"atb":[[1.01,45.28]],"id":64812720},{"atl":[[990,0.26]],"id":64812720},{"spn":495.5,"spf":"NaN","id":64812720},{"atb":[[1.02,22.64]],"id":70902603},{"atl":[[1000,0.26]],"id":70902603},{"spn":500.51,"spf":"NaN","id":70902603},{"atb":[[1.03,15.09]],"id":66686625},{"atl":[[990,0.26]],"id":66686625},{"spn":495.51,"spf":"NaN","id":66686625},{"atb":[[1.03,15.09]],"id":70053016},{"atl":[[1000,0.26]],"id":70053016},{"spn":500.51,"spf":"NaN","id":70053016},{"atb":[[1.03,15.09]],"id":69942666},{"atl":[[1000,0.26]],"id":69942666},{"spn":500.51,"spf":"NaN","id":69942666},{"atb":[[1.03,15.09]],"id":53082422},{"atl":[[990,0.26]],"id":53082422},{"spn":495.51,"spf":"NaN","id":53082422}],"con":true,"img":true}]}
{"op":"mcm","clk":"11537573392","pt":1719443282539,"mc":[{"id":"1.230178329","marketDefinition":{"bspMarket":true,"turnInPlayEnabled":false,"persistenceEnabled":false,"marketBaseRate":5.0,"eventId":"33376062","eventTypeId":"4339","numberOfWinners":2,"bettingType":"ODDS","marketType":"PLACE","marketTime":"2024-06-27T17:02:00.000Z","suspendTime":"2024-06-27T17:02:00.000Z","bspReconciled":false,"complete":true,"inPlay":false,"crossMatching":false,"runnersVoidable":false,"numberOfActiveRunners":6,"betDelay":0,"status":"OPEN","runners":[{"status":"ACTIVE","sortPriority":1,"id":53082422,"name":"1. Betsys Minnie"},{"status":"ACTIVE","sortPriority":2,"id":70053016,"name":"2. Tuxedo Twlight"},{"status":"ACTIVE","sortPriority":3,"id":66686625,"name":"3. Ballymac Addie"},{"status":"ACTIVE","sortPriority":4,"id":64812720,"name":"4. Hes A Rebel"},{"status":"ACTIVE","sortPriority":5,"id":70902603,"name":"5. Follow Suit"},{"status":"ACTIVE","sortPriority":6,"id":69942666,"name":"6. Pukka Poppy"}],"regulators":["MR_INT"],"venue":"Kinsley","countryCode":"GB","discountAllowed":true,"timezone":"Europe/London","openDate":"2024-06-27T13:36:00.000Z","version":5994643783,"name":"To Be Placed","eventName":"Kinsley 27th Jun"},"rc":[{"atb":[[1.01,45.29]],"id":64812720},{"atl":[[990,0.26]],"id":64812720},{"spn":495.5,"spf":"NaN","id":64812720},{"atb":[[1.02,22.64]],"id":70902603},{"atl":[[1000,0.26]],"id":70902603},{"spn":500.51,"spf":"NaN","id":70902603},{"atb":[[1.03,15.09]],"id":66686625},{"atl":[[990,0.26]],"id":66686625},{"spn":495.51,"spf":"NaN","id":66686625},{"atb":[[1.03,15.09]],"id":70053016},{"atl":[[1000,0.26]],"id":70053016},{"spn":500.51,"spf":"NaN","id":70053016},{"atb":[[1.03,15.09]],"id":69942666},{"atl":[[1000,0.26]],"id":69942666},{"spn":500.51,"spf":"NaN","id":69942666},{"atb":[[1.03,15.09]],"id":53082422},{"atl":[[990,0.26]],"id":53082422},{"spn":495.51,"spf":"NaN","id":53082422}],"con":true,"img":true}]}
{"op":"mcm","clk":"11537954952","pt":1719448682564,"mc":[{"id":"1.230178329","marketDefinition":{"bspMarket":true,"turnInPlayEnabled":false,"persistenceEnabled":false,"marketBaseRate":5.0,"eventId":"33376062","eventTypeId":"4339","numberOfWinners":2,"bettingType":"ODDS","marketType":"PLACE","marketTime":"2024-06-27T17:02:00.000Z","suspendTime":"2024-06-27T17:02:00.000Z","bspReconciled":false,"complete":true,"inPlay":false,"crossMatching":false,"runnersVoidable":false,"numberOfActiveRunners":6,"betDelay":0,"status":"OPEN","runners":[{"status":"ACTIVE","sortPriority":1,"id":53082422,"name":"1. Betsys Minnie"},{"status":"ACTIVE","sortPriority":2,"id":70053016,"name":"2. Tuxedo Twlight"},{"status":"ACTIVE","sortPriority":3,"id":66686625,"name":"3. Ballymac Addie"},{"status":"ACTIVE","sortPriority":4,"id":64812720,"name":"4. Hes A Rebel"},{"status":"ACTIVE","sortPriority":5,"id":70902603,"name":"5. Follow Suit"},{"status":"ACTIVE","sortPriority":6,"id":69942666,"name":"6. Pukka Poppy"}],"regulators":["MR_INT"],"venue":"Kinsley","countryCode":"GB","discountAllowed":true,"timezone":"Europe/London","openDate":"2024-06-27T13:36:00.000Z","version":5994643783,"name":"To Be Placed","eventName":"Kinsley 27th Jun"},"rc":[{"atb":[[1.01,45.28]],"id":64812720},{"atl":[[990,0.26]],"id":64812720},{"spn":495.5,"spf":"NaN","id":64812720},{"atb":[[1.02,22.64]],"id":70902603},{"atl":[[1000,0.26]],"id":70902603},{"spn":500.51,"spf":"NaN","id":70902603},{"atb":[[1.03,15.09]],"id":66686625},{"atl":[[990,0.26]],"id":66686625},{"spn":495.51,"spf":"NaN","id":66686625},{"atb":[[1.03,15.09]],"id":70053016},{"atl":[[1000,0.26]],"id":70053016},{"spn":500.51,"spf":"NaN","id":70053016},{"atb":[[1.03,15.09]],"id":69942666},{"atl":[[1000,0.26]],"id":69942666},{"spn":500.51,"spf":"NaN","id":69942666},{"atb":[[1.03,15.09]],"id":53082422},{"atl":[[990,0.26]],"id":53082422},{"spn":495.51,"spf":"NaN","id":53082422}],"con":true,"img":true}]}
{"op":"mcm","clk":"11538056550","pt":1719450842068,"mc":[{"id":"1.230178329","rc":[{"spl":[[1.01,39]],"id":64812720},{"atb":[[1.01,45.3]],"id":64812720},{"atl":[[990,0.26]],"id":64812720},{"spn":1.01,"spf":1.0,"id":64812720},{"atb":[[1.02,22.65]],"id":70902603},{"atl":[[1000,0.26]],"id":70902603},{"atb":[[1.03,15.1]],"id":66686625},{"atl":[[990,0.26]],"id":66686625},{"atb":[[1.03,15.1]],"id":70053016},{"atl":[[1000,0.26]],"id":70053016},{"atb":[[1.03,15.1]],"id":69942666},{"atl":[[1000,0.26]],"id":69942666},{"atb":[[1.03,15.1]],"id":53082422},{"atl":[[990,0.26]],"id":53082422}],"con":true,"img":false}]}
{"op":"mcm","clk":"11538170615","pt":1719454082547,"mc":[{"id":"1.230178329","marketDefinition":{"bspMarket":true,"turnInPlayEnabled":false,"persistenceEnabled":false,"marketBaseRate":5.0,"eventId":"33376062","eventTypeId":"4339","numberOfWinners":2,"bettingType":"ODDS","marketType":"PLACE","marketTime":"2024-06-27T17:02:00.000Z","suspendTime":"2024-06-27T17:02:00.000Z","bspReconciled":false,"complete":true,"inPlay":false,"crossMatching":false,"runnersVoidable":false,"numberOfActiveRunners":6,"betDelay":0,"status":"OPEN","runners":[{"status":"ACTIVE","sortPriority":1,"id":53082422,"name":"1. Betsys Minnie"},{"status":"ACTIVE","sortPriority":2,"id":70053016,"name":"2. Tuxedo Twlight"},{"status":"ACTIVE","sortPriority":3,"id":66686625,"name":"3. Ballymac Addie"},{"status":"ACTIVE","sortPriority":4,"id":64812720,"name":"4. Hes A Rebel"},{"status":"ACTIVE","sortPriority":5,"id":70902603,"name":"5. Follow Suit"},{"status":"ACTIVE","sortPriority":6,"id":69942666,"name":"6. Pukka Poppy"}],"regulators":["MR_INT"],"venue":"Kinsley","countryCode":"GB","discountAllowed":true,"timezone":"Europe/London","openDate":"2024-06-27T13:36:00.000Z","version":5994643783,"name":"To Be Placed","eventName":"Kinsley 27th Jun"},"rc":[{"spl":[[1.01,39]],"id":64812720},{"atb":[[1.01,45.29]],"id":64812720},{"atl":[[990,0.26]],"id":64812720},{"spn":1.01,"spf":1.0,"id":64812720},{"atb":[[1.02,22.64]],"id":70902603},{"atl":[[1000,0.26]],"id":70902603},{"spn":500.51,"spf":"NaN","id":70902603},{"atb":[[1.03,15.09]],"id":66686625},{"atl":[[990,0.26]],"id":66686625},{"spn":495.51,"spf":"NaN","id":66686625},{"atb":[[1.03,15.09]],"id":70053016},{"atl":[[1000,0.26]],"id":70053016},{"spn":500.51,"spf":"NaN","id":70053016},{"atb":[[1.03,15.09]],"id":69942666},{"atl":[[1000,0.26]],"id":69942666},{"spn":500.51,"spf":"NaN","id":69942666},{"atb":[[1.03,15.09]],"id":53082422},{"atl":[[990,0.26]],"id":53082422},{"spn":495.51,"spf":"NaN","id":53082422}],"con":true,"img":true}]}
{"op":"mcm","clk":"11538368273","pt":1719459482596,"mc":[{"id":"1.230178329","marketDefinition":{"bspMarket":true,"turnInPlayEnabled":false,"persistenceEnabled":false,"marketBaseRate":5.0,"eventId":"33376062","eventTypeId":"4339","numberOfWinners":2,"bettingType":"ODDS","marketType":"PLACE","marketTime":"2024-06-27T17:02:00.000Z","suspendTime":"2024-06-27T17:02:00.000Z","bspReconciled":false,"complete":true,"inPlay":false,"crossMatching":false,"runnersVoidable":false,"numberOfActiveRunners":6,"betDelay":0,"status":"OPEN","runners":[{"status":"ACTIVE","sortPriority":1,"id":53082422,"name":"1. Betsys Minnie"},{"status":"ACTIVE","sortPriority":2,"id":70053016,"name":"2. Tuxedo Twlight"},{"status":"ACTIVE","sortPriority":3,"id":66686625,"name":"3. Ballymac Addie"},{"status":"ACTIVE","sortPriority":4,"id":64812720,"name":"4. Hes A Rebel"},{"status":"ACTIVE","sortPriority":5,"id":70902603,"name":"5. Follow Suit"},{"status":"ACTIVE","sortPriority":6,"id":69942666,"name":"6. Pukka Poppy"}],"regulators":["MR_INT"],"venue":"Kinsley","countryCode":"GB","discountAllowed":true,"timezone":"Europe/London","openDate":"2024-06-27T13:36:00.000Z","version":5994643783,"name":"To Be Placed","eventName":"Kinsley 27th Jun"},"rc":[{"spl":[[1.01,39]],"id":64812720},{"atb":[[1.01,45.3]],"id":64812720},{"atl":[[990,0.26]],"id":64812720},{"spn":1.01,"spf":1.0,"id":64812720},{"atb":[[1.02,22.65]],"id":70902603},{"atl":[[1000,0.26]],"id":70902603},{"spn":500.51,"spf":"NaN","id":70902603},{"atb":[[1.03,15.1]],"id":66686625},{"atl":[[990,0.26]],"id":66686625},{"spn":495.51,"spf":"NaN","id":66686625},{"atb":[[1.03,15.1]],"id":70053016},{"atl":[[1000,0.26]],"id":70053016},{"spn":500.51,"spf":"NaN","id":70053016},{"atb":[[1.03,15.1]],"id":69942666},{"atl":[[1000,0.26]],"id":69942666},{"spn":500.51,"spf":"NaN","id":69942666},{"atb":[[1.03,15.1]],"id":53082422},{"atl":[[990,0.26]],"id":53082422},{"spn":495.51,"spf":"NaN","id":53082422}],"con":true,"img":true}]}
{"op":"mcm","clk":"11538595399","pt":1719464882545,"mc":[{"id":"1.230178329","marketDefinition":{"bspMarket":true,"turnInPlayEnabled":false,"persistenceEnabled":false,"marketBaseRate":5.0,"eventId":"33376062","eventTypeId":"4339","numberOfWinners":2,"bettingType":"ODDS","marketType":"PLACE","marketTime":"2024-06-27T17:02:00.000Z","suspendTime":"2024-06-27T17:02:00.000Z","bspReconciled":false,"complete":true,"inPlay":false,"crossMatching":false,"runnersVoidable":false,"numberOfActiveRunners":6,"betDelay":0,"status":"OPEN","runners":[{"status":"ACTIVE","sortPriority":1,"id":53082422,"name":"1. Betsys Minnie"},{"status":"ACTIVE","sortPriority":2,"id":70053016,"name":"2. Tuxedo Twlight"},{"status":"ACTIVE","sortPriority":3,"id":66686625,"name":"3. Ballymac Addie"},{"status":"ACTIVE","sortPriority":4,"id":64812720,"name":"4. Hes A Rebel"},{"status":"ACTIVE","sortPriority":5,"id":70902603,"name":"5. Follow Suit"},{"status":"ACTIVE","sortPriority":6,"id":69942666,"name":"6. Pukka Poppy"}],"regulators":["MR_INT"],"venue":"Kinsley","countryCode":"GB","discountAllowed":true,"timezone":"Europe/London","openDate":"2024-06-27T13:36:00.000Z","version":5994643783,"name":"To Be Placed","eventName":"Kinsley 27th Jun"},"rc":[{"spl":[[1.01,39]],"id":64812720},{"atb":[[1.01,45.29]],"id":64812720},{"atl":[[990,0.26]],"id":64812720},{"spn":1.01,"spf":1.0,"id":64812720},{"atb":[[1.02,22.64]],"id":70902603},{"atl":[[1000,0.26]],"id":70902603},{"spn":500.51,"spf":"NaN","id":70902603},{"atb":[[1.03,15.09]],"id":66686625},{"atl":[[990,0.26]],"id":66686625},{"spn":495.51,"spf":"NaN","id":66686625},{"atb":[[1.03,15.09]],"id":70053016},{"atl":[[1000,0.26]],"id":70053016},{"spn":500.51,"spf":"NaN","id":70053016},{"atb":[[1.03,15.09]],"id":69942666},{"atl":[[1000,0.26]],"id":69942666},{"spn":500.51,"spf":"NaN","id":69942666},{"atb":[[1.03,15.09]],"id":53082422},{"atl":[[990,0.26]],"id":53082422},{"spn":495.51,"spf":"NaN","id":53082422}],"con":true,"img":true}]}
{"op":"mcm","clk":"11538905542","pt":1719471474801,"mc":[{"id":"1.230178329","rc":[{"atb":[[1.01,45.29]],"id":64812720},{"atl":[[990,0.16]],"id":64812720},{"atb":[[1.02,22.64]],"id":70902603},{"atl":[[1000,0.16]],"id":70902603},{"atb":[[1.03,15.09]],"id":66686625},{"atl":[[990,0.16]],"id":66686625},{"atb":[[1.03,15.09]],"id":70053016},{"atl":[[1000,0.16]],"id":70053016},{"atb":[[1.03,15.09]],"id":69942666},{"atl":[[1000,0.16]],"id":69942666},{"atb":[[1.03,15.09]],"id":53082422},{"atl":[[990,0.16]],"id":53082422}],"con":true,"img":false}]}
{"op":"mcm","clk":"11538907296","pt":1719471508059,"mc":[{"id":"1.230178329","rc":[{"atl":[[1000,1]],"id":64812720},{"atl":[[1000,1.16]],"id":70902603},{"atl":[[1000,1]],"id":66686625},{"atl":[[1000,1.16]],"id":70053016},{"atl":[[1000,1.16]],"id":69942666},{"atl":[[1000,1]],"id":53082422}],"con":true,"img":false}]}
{"op":"mcm","clk":"11538907306","pt":1719471508163,"mc":[{"id":"1.230178329","rc":[{"atb":[[1.07,2.48]],"id":64812720},{"atb":[[1.07,2.48]],"id":70902603},{"atb":[[1.07,2.48]],"id":66686625},{"atb":[[1.07,2.48]],"id":70053016},{"atb":[[1.07,2.48]],"id":69942666},{"atb":[[1.07,2.48]],"id":53082422}],"con":true,"img":false}]}
{"op":"mcm","clk":"11538907311","pt":1719471508267,"mc":[{"id":"1.230178329","rc":[{"atl":[[1000,0.48]],"id":64812720},{"atl":[[1000,0.64]],"id":70902603},{"atl":[[1000,0.48]],"id":66686625},{"atl":[[1000,0.64]],"id":70053016},{"atl":[[1000,0.64]],"id":69942666},{"atl":[[1000,0.48]],"id":53082422}],"con":true,"img":false}]}
{"op":"mcm","clk":"11538907323","pt":1719471508471,"mc":[{"id":"1.230178329","rc":[{"atl":[[1000,0]],"id":64812720},{"atl":[[1000,0.16]],"id":70902603},{"atl":[[1000,0]],"id":66686625},{"atl":[[1000,0.16]],"id":70053016},{"atl":[[1000,0.16]],"id":69942666},{"atl":[[1000,0]],"id":53082422}],"con":true,"img":false}]}
{"op":"mcm","clk":"11538907326","pt":1719471508570,"mc":[{"id":"1.230178329","rc":[{"atl":[[75,0.48]],"id":64812720},{"atl":[[75,0.48]],"id":70902603},{"atl":[[75,0.48]],"id":66686625},{"atl":[[75,0.48]],"id":70053016},{"atl":[[75,0.48]],"id":69942666},{"atl":[[75,0.48]],"id":53082422}],"con":true,"img":false}]}
{"op":"mcm","clk":"11539122546","pt":1719475682551,"mc":[{"id":"1.230178329","marketDefinition":{"bspMarket":true,"turnInPlayEnabled":false,"persistenceEnabled":false,"marketBaseRate":5.0,"eventId":"33376062","eventTypeId":"4339","numberOfWinners":2,"bettingType":"ODDS","marketType":"PLACE","marketTime":"2024-06-27T17:02:00.000Z","suspendTime":"2024-06-27T17:02:00.000Z","bspReconciled":false,"complete":true,"inPlay":false,"crossMatching":false,"runnersVoidable":false,"numberOfActiveRunners":6,"betDelay":0,"status":"OPEN","runners":[{"status":"ACTIVE","sortPriority":1,"id":53082422,"name":"1. Betsys Minnie"},{"status":"ACTIVE","sortPriority":2,"id":70053016,"name":"2. Tuxedo Twlight"},{"status":"ACTIVE","sortPriority":3,"id":66686625,"name":"3. Ballymac Addie"},{"status":"ACTIVE","sortPriority":4,"id":64812720,"name":"4. Hes A Rebel"},{"status":"ACTIVE","sortPriority":5,"id":70902603,"name":"5. Follow Suit"},{"status":"ACTIVE","sortPriority":6,"id":69942666,"name":"6. Pukka Poppy"}],"regulators":["MR_INT"],"venue":"Kinsley","countryCode":"GB","discountAllowed":true,"timezone":"Europe/London","openDate":"2024-06-27T13:36:00.000Z","version":5994643783,"name":"To Be Placed","eventName":"Kinsley 27th Jun"},"rc":[{"spl":[[1.01,39]],"id":64812720},{"atb":[[1.01,45.28],[1.07,2.48]],"id":64812720},{"atl":[[75,0.48],[990,0.16]],"id":64812720},{"spn":1.01,"spf":1.0,"id":64812720},{"atb":[[1.02,22.64],[1.07,2.48]],"id":70902603},{"atl":[[75,0.48],[1000,0.16]],"id":70902603},{"spn":38.03,"spf":"NaN","id":70902603},{"atb":[[1.03,15.09],[1.07,2.48]],"id":66686625},{"atl":[[75,0.48],[990,0.16]],"id":66686625},{"spn":38.03,"spf":"NaN","id":66686625},{"atb":[[1.03,15.09],[1.07,2.48]],"id":70053016},{"atl":[[75,0.48],[1000,0.16]],"id":70053016},{"spn":38.03,"spf":"NaN","id":70053016},{"atb":[[1.03,15.09],[1.07,2.48]],"id":69942666},{"atl":[[75,0.48],[1000,0.16]],"id":69942666},{"spn":38.03,"spf":"NaN","id":69942666},{"atb":[[1.03,15.09],[1.07,2.48]],"id":53082422},{"atl":[[75,0.48],[990,0.16]],"id":53082422},{"spn":38.03,"spf":"NaN","id":53082422}],"con":true,"img":true}]}
{"op":"mcm","clk":"11539361014","pt":1719479613039,"mc":[{"id":"1.230178329","rc":[{"atb":[[1.01,45.27]],"id":64812720},{"spn":1.01,"spf":1.0,"id":64812720},{"atb":[[1.02,22.63]],"id":70902603},{"spn":38.03,"spf":"NaN","id":70902603},{"atb":[[1.03,15.09]],"id":66686625},{"spn":38.03,"spf":"NaN","id":66686625},{"atb":[[1.03,15.09]],"id":70053016},{"spn":38.03,"spf":"NaN","id":70053016},{"atb":[[1.03,15.09]],"id":69942666},{"spn":38.03,"spf":"NaN","id":69942666},{"spl":[[1.71,6]],"id":53082422},{"atb":[[1.03,15.09]],"id":53082422},{"spn":1.39,"spf":1.0,"id":53082422}],"con":true,"img":false}]}
{"op":"mcm","clk":"11540683356","pt":1719497282514,"mc":[{"id":"1.230178329","marketDefinition":{"bspMarket":true,"turnInPlayEnabled":false,"persistenceEnabled":false,"marketBaseRate":5.0,"eventId":"33376062","eventTypeId":"4339","numberOfWinners":2,"bettingType":"ODDS","marketType":"PLACE","marketTime":"2024-06-27T17:02:00.000Z","suspendTime":"2024-06-27T17:02:00.000Z","bspReconciled":false,"complete":true,"inPlay":false,"crossMatching":false,"runnersVoidable":false,"numberOfActiveRunners":6,"betDelay":0,"status":"OPEN","runners":[{"status":"ACTIVE","sortPriority":1,"id":53082422,"name":"1. Betsys Minnie"},{"status":"ACTIVE","sortPriority":2,"id":70053016,"name":"2. Tuxedo Twlight"},{"status":"ACTIVE","sortPriority":3,"id":66686625,"name":"3. Ballymac Addie"},{"status":"ACTIVE","sortPriority":4,"id":64812720,"name":"4. Hes A Rebel"},{"status":"ACTIVE","sortPriority":5,"id":70902603,"name":"5. Follow Suit"},{"status":"ACTIVE","sortPriority":6,"id":69942666,"name":"6. Pukka Poppy"}],"regulators":["MR_INT"],"venue":"Kinsley","countryCode":"GB","discountAllowed":true,"timezone":"Europe/London","openDate":"2024-06-27T13:36:00.000Z","version":5994643783,"name":"To Be Placed","eventName":"Kinsley 27th Jun"},"rc":[{"spl":[[1.01,39]],"id":64812720},{"atb":[[1.01,45.3],[1.07,2.48]],"id":64812720},{"atl":[[75,0.48],[990,0.16]],"id":64812720},{"spn":1.01,"spf":1.0,"id":64812720},{"atb":[[1.02,22.65],[1.07,2.48]],"id":70902603},{"atl":[[75,0.48],[1000,0.16]],"id":70902603},{"spn":38.03,"spf":"NaN","id":70902603},{"atb":[[1.03,15.1],[1.07,2.48]],"id":66686625},{"atl":[[75,0.48],[990,0.16]],"id":66686625},{"spn":38.03,"spf":"NaN","id":66686625},{"atb":[[1.03,15.1],[1.07,2.48]],"id":70053016},{"atl":[[75,0.48],[1000,0.16]],"id":70053016},{"spn":38.03,"spf":"NaN","id":70053016},{"atb":[[1.03,15.1],[1.07,2.48]],"id":69942666},{"atl":[[75,0.48],[1000,0.16]],"id":69942666},{"spn":38.03,"spf":"NaN","id":69942666},{"spl":[[1.71,6]],"id":53082422},{"atb":[[1.03,15.1],[1.07,2.48]],"id":53082422},{"atl":[[75,0.48],[990,0.16]],"id":53082422},{"spn":1.39,"spf":1.0,"id":53082422}],"con":true,"img":true}]}
{"op":"mcm","clk":"11541139067","pt":1719502682530,"mc":[{"id":"1.230178329","marketDefinition":{"bspMarket":true,"turnInPlayEnabled":false,"persistenceEnabled":false,"marketBaseRate":5.0,"eventId":"33376062","eventTypeId":"4339","numberOfWinners":2,"bettingType":"ODDS","marketType":"PLACE","marketTime":"2024-06-27T17:02:00.000Z","suspendTime":"2024-06-27T17:02:00.000Z","bspReconciled":false,"complete":true,"inPlay":false,"crossMatching":false,"runnersVoidable":false,"numberOfActiveRunners":6,"betDelay":0,"status":"OPEN","runners":[{"status":"ACTIVE","sortPriority":1,"id":53082422,"name":"1. Betsys Minnie"},{"status":"ACTIVE","sortPriority":2,"id":70053016,"name":"2. Tuxedo Twlight"},{"status":"ACTIVE","sortPriority":3,"id":66686625,"name":"3. Ballymac Addie"},{"status":"ACTIVE","sortPriority":4,"id":64812720,"name":"4. Hes A Rebel"},{"status":"ACTIVE","sortPriority":5,"id":70902603,"name":"5. Follow Suit"},{"status":"ACTIVE","sortPriority":6,"id":69942666,"name":"6. Pukka Poppy"}],"regulators":["MR_INT"],"venue":"Kinsley","countryCode":"GB","discountAllowed":true,"timezone":"Europe/London","openDate":"2024-06-27T13:36:00.000Z","version":5994643783,"name":"To Be Placed","eventName":"Kinsley 27th Jun"},"rc":[{"spl":[[1.01,39]],"id":64812720},{"atb":[[1.01,45.31],[1.07,2.48]],"id":64812720},{"atl":[[75,0.48],[990,0.16]],"id":64812720},{"spn":1.01,"spf":1.0,"id":64812720},{"atb":[[1.02,22.65],[1.07,2.48]],"id":70902603},{"atl":[[75,0.48],[1000,0.16]],"id":70902603},{"spn":38.03,"spf":"NaN","id":70902603},{"atb":[[1.03,15.1],[1.07,2.48]],"id":66686625},{"atl":[[75,0.48],[990,0.16]],"id":66686625},{"spn":38.03,"spf":"NaN","id":66686625},{"atb":[[1.03,15.1],[1.07,2.48]],"id":70053016},{"atl":[[75,0.48],[1000,0.16]],"id":70053016},{"spn":38.03,"spf":"NaN","id":70053016},{"atb":[[1.03,15.1],[1.07,2.48]],"id":69942666},{"atl":[[75,0.48],[1000,0.16]],"id":69942666},{"spn":38.03,"spf":"NaN","id":69942666},{"spl":[[1.71,6]],"id":53082422},{"atb":[[1.03,15.1],[1.07,2.48]],"id":53082422},{"atl":[[75,0.48],[990,0.16]],"id":53082422},{"spn":1.39,"spf":1.0,"id":53082422}],"con":true,"img":true}]}
{"op":"mcm","clk":"11541425795","pt":1719505622913,"mc":[{"id":"1.230178329","rc":[{"atb":[[1.01,45.29],[1.04,1]],"id":64812720},{"spn":1.01,"spf":1.0,"id":64812720},{"atb":[[1.02,22.64],[1.04,1]],"id":70902603},{"atb":[[1.03,15.09],[1.04,1]],"id":66686625},{"atb":[[1.03,15.09],[1.04,1]],"id":70053016},{"atb":[[1.03,15.09],[1.04,1]],"id":69942666},{"atb":[[1.03,15.09],[1.04,1]],"id":53082422}],"con":true,"img":false}]}
{"op":"mcm","clk":"11541425812","pt":1719505623109,"mc":[{"id":"1.230178329","rc":[{"atb":[[1.04,0.25]],"id":64812720},{"atb":[[1.04,0.25]],"id":70902603},{"atb":[[1.04,0.25]],"id":66686625},{"atb":[[1.04,0.25]],"id":70053016},{"atb":[[1.04,0.25]],"id":69942666},{"atb":[[1.04,0.25]],"id":53082422}],"con":true,"img":false}]}
{"op":"mcm","clk":"11541425832","pt":1719505623319,"mc":[{"id":"1.230178329","rc":[{"atb":[[1.04,0]],"id":64812720},{"atb":[[1.04,0]],"id":70902603},{"atb":[[1.04,0]],"id":66686625},{"atb":[[1.04,0]],"id":70053016},{"atb":[[1.04,0]],"id":69942666},{"atb":[[1.04,0]],"id":53082422}],"con":true,"img":false}]}
{"op":"mcm","clk":"11541425842","pt":1719505623424,"mc":[{"id":"1.230178329","rc":[{"atb":[[1.2,0.25]],"id":64812720},{"atb":[[1.2,0.25]],"id":70902603},{"atb":[[1.2,0.25]],"id":66686625},{"atb":[[1.2,0.25]],"id":70053016},{"atb":[[1.2,0.25]],"id":69942666},{"atb":[[1.2,0.25]],"id":53082422}],"con":true,"img":false}]}
{"op":"mcm","clk":"11541464189","pt":1719506026152,"mc":[{"id":"1.230178329","rc":[{"spn":1.01,"spf":1.0,"id":64812720},{"spn":38.1,"spf":"NaN","id":70902603},{"spn":38.1,"spf":"NaN","id":66686625},{"atb":[[1.09,47.02]],"id":70053016},{"spn":38.1,"spf":"NaN","id":70053016},{"spn":38.1,"spf":"NaN","id":69942666},{"spn":1.45,"spf":1.0,"id":53082422}],"con":true,"img":false}]}
{"op":"mcm","clk":"11541464212","pt":1719506026354,"mc":[{"id":"1.230178329","rc":[{"atb":[[1.09,47.02]],"id":70902603}],"con":true,"img":false}]}
{"op":"mcm","clk":"11541464226","pt":1719506026455,"mc":[{"id":"1.230178329","rc":[{"atb":[[1.09,47.02]],"id":69942666}],"con":true,"img":false}]}
{"op":"mcm","clk":"11541473774","pt":1719506122090,"mc":[{"id":"1.230178329","rc":[{"atb":[[1.11,35.92]],"id":70902603}],"con":true,"img":false}]}
{"op":"mcm","clk":"11541473785","pt":1719506122195,"mc":[{"id":"1.230178329","rc":[{"atb":[[1.11,35.92]],"id":69942666}],"con":true,"img":false}]}
{"op":"mcm","clk":"11541473817","pt":1719506122458,"mc":[{"id":"1.230178329","rc":[{"atb":[[1.11,35.92]],"id":70053016}],"con":true,"img":false}]}
{"op":"mcm","clk":"11541474402","pt":1719506127954,"mc":[{"id":"1.230178329","rc":[{"atb":[[1.09,0]],"id":70902603},{"atb":[[1.09,0]],"id":70053016}],"con":true,"img":false}]}
{"op":"mcm","clk":"11541474423","pt":1719506128265,"mc":[{"id":"1.230178329","rc":[{"atb":[[1.13,32.54]],"id":70902603},{"atb":[[1.09,0]],"id":69942666}],"con":true,"img":false}]}
{"op":"mcm","clk":"11541474453","pt":1719506128573,"mc":[{"id":"1.230178329","rc":[{"atb":[[1.13,32.54]],"id":70053016}],"con":true,"img":false}]}
{"op":"mcm","clk":"11541474461","pt":1719506128676,"mc":[{"id":"1.230178329","rc":[{"atb":[[1.13,32.54]],"id":69942666}],"con":true,"img":false}]}
{"op":"mcm","clk":"11541475624","pt":1719506139702,"mc":[{"id":"1.230178329","rc":[{"atb":[[1.11,0]],"id":70053016},{"atb":[[1.11,0]],"id":69942666}],"con":true,"img":false}]}
{"op":"mcm","clk":"11541475655","pt":1719506139999,"mc":[{"id":"1.230178329","rc":[{"atb":[[1.11,0]],"id":70902603},{"atb":[[1.15,26.34]],"id":69942666}],"con":true,"img":false}]}
{"op":"mcm","clk":"11541475678","pt":1719506140173,"mc":[{"id":"1.230178329","rc":[{"atb":[[1.15,26.34]],"id":70902603},{"atb":[[1.15,26.34]],"id":70053016}],"con":true,"img":false}]}
{"op":"mcm","clk":"11541475875","pt":1719506142211,"mc":[{"id":"1.230178329","marketDefinition":{"bspMarket":true,"turnInPlayEnabled":false,"persistenceEnabled":false,"marketBaseRate":5.0,"eventId":"33376062","eventTypeId":"4339","numberOfWinners":2,"bettingType":"ODDS","marketType":"PLACE","marketTime":"2024-06-27T17:02:00.000Z","suspendTime":"2024-06-27T17:02:00.000Z","bspReconciled":false,"complete":true,"inPlay":false,"crossMatching":true,"runnersVoidable":false,"numberOfActiveRunners":6,"betDelay":0,"status":"OPEN","runners":[{"status":"ACTIVE","sortPriority":1,"id":53082422,"name":"1. Betsys Minnie"},{"status":"ACTIVE","sortPriority":2,"id":70053016,"name":"2. Tuxedo Twlight"},{"status":"ACTIVE","sortPriority":3,"id":66686625,"name":"3. Ballymac Addie"},{"status":"ACTIVE","sortPriority":4,"id":64812720,"name":"4. Hes A Rebel"},{"status":"ACTIVE","sortPriority":5,"id":70902603,"name":"5. Follow Suit"},{"status":"ACTIVE","sortPriority":6,"id":69942666,"name":"6. Pukka Poppy"}],"regulators":["MR_INT"],"venue":"Kinsley","countryCode":"GB","discountAllowed":true,"timezone":"Europe/London","openDate":"2024-06-27T13:36:00.000Z","version":5994643783,"name":"To Be Placed","eventName":"Kinsley 27th Jun"},"rc":[],"con":true,"img":false}]}
{"op":"mcm","clk":"11541477830","pt":1719506161821,"mc":[{"id":"1.230178329","rc":[{"atb":[[1.13,0]],"id":70053016}],"con":true,"img":false}]}
{"op":"mcm","clk":"11541477843","pt":1719506161921,"mc":[{"id":"1.230178329","rc":[{"atb":[[1.13,0]],"id":70902603}],"con":true,"img":false}]}
{"op":"mcm","clk":"11541477872","pt":1719506162202,"mc":[{"id":"1.230178329","rc":[{"atb":[[1.17,24.88]],"id":70902603},{"atb":[[1.13,0]],"id":69942666}],"con":true,"img":false}]}
{"op":"mcm","clk":"11541477918","pt":1719506162504,"mc":[{"id":"1.230178329","rc":[{"atb":[[1.17,24.88]],"id":70053016},{"atb":[[1.17,24.88]],"id":69942666}],"con":true,"img":false}]}
{"op":"mcm","clk":"11541479312","pt":1719506175717,"mc":[{"id":"1.230178329","rc":[{"atb":[[1.15,0]],"id":70053016},{"atb":[[1.15,0]],"id":69942666}],"con":true,"img":false}]}
{"op":"mcm","clk":"11541479341","pt":1719506176028,"mc":[{"id":"1.230178329","rc":[{"atb":[[1.15,0]],"id":70902603},{"atb":[[1.19,20.8]],"id":69942666}],"con":true,"img":false}]}
{"op":"mcm","clk":"11541479365","pt":1719506176228,"mc":[{"id":"1.230178329","rc":[{"atb":[[1.19,20.8]],"id":70053016}],"con":true,"img":false}]}
{"op":"mcm","clk":"11541479384","pt":1719506176435,"mc":[{"id":"1.230178329","rc":[{"atb":[[1.19,20.8]],"id":70902603}],"con":true,"img":false}]}
{"op":"mcm","clk":"11541481620","pt":1719506197545,"mc":[{"id":"1.230178329","rc":[{"atb":[[1.17,0]],"id":70902603},{"atb":[[1.17,0]],"id":70053016}],"con":true,"img":false}]}
{"op":"mcm","clk":"11541481704","pt":1719506198226,"mc":[{"id":"1.230178329","rc":[{"atb":[[1.21,20.15]],"id":70902603},{"atb":[[1.17,0]],"id":69942666}],"con":true,"img":false}]}
{"op":"mcm","clk":"11541481765","pt":1719506198745,"mc":[{"id":"1.230178329","rc":[{"atb":[[1.21,20.15]],"id":70053016}],"con":true,"img":false}]}
{"op":"mcm","clk":"11541481788","pt":1719506198951,"mc":[{"id":"1.230178329","rc":[{"atb":[[1.21,20.15]],"id":69942666}],"con":true,"img":false}]}
{"op":"mcm","clk":"11541541406","pt":1719506820138,"mc":[{"id":"1.230178329","rc":[{"spn":38.1,"spf":"NaN","id":70902603},{"atb":[[1.22,20.15]],"id":70053016},{"atl":[[8,2]],"id":70053016},{"spn":4.61,"spf":"NaN","id":70053016},{"spn":38.1,"spf":"NaN","id":69942666}],"con":true,"img":false}]}
{"op":"mcm","clk":"11541541419","pt":1719506820243,"mc":[{"id":"1.230178329","rc":[{"atb":[[1.92,1],[1.65,2.48]],"id":64812720},{"atl":[[18,2],[5.3,1]],"id":64812720},{"atb":[[2.32,1],[1.71,20.15]],"id":70902603},{"atl":[[6.2,1],[23,2]],"id":70902603},{"atb":[[1.83,1],[1.48,2.48]],"id":66686625},{"atl":[[4.6,1],[11,2]],"id":66686625},{"atb":[[1.66,1]],"id":70053016},{"atl":[[4.6,1]],"id":70053016},{"atb":[[2.2,20.15]],"id":69942666},{"atl":[[95,2]],"id":69942666},{"atb":[[1.48,1],[1.07,11.27]],"id":53082422},{"atl":[[5.8,2],[3.55,1]],"id":53082422}],"con":true,"img":false}]}
{"op":"mcm","clk":"11541541435","pt":1719506820439,"mc":[{"id":"1.230178329","rc":[{"atb":[[2.54,1]],"id":69942666},{"atl":[[9.4,1]],"id":69942666}],"con":true,"img":false}]}
{"op":"mcm","clk":"11541541702","pt":1719506823360,"mc":[{"id":"1.230178329","rc":[{"atb":[[1.74,2.11]],"id":70902603},{"atb":[[2.26,2.11]],"id":69942666}],"con":true,"img":false}]}
{"op":"mcm","clk":"11541541713","pt":1719506823464,"mc":[{"id":"1.230178329","rc":[{"atb":[[2.26,22.26],[2.2,0]],"id":69942666}],"con":true,"img":false}]}
{"op":"mcm","clk":"11541542177","pt":1719506828562,"mc":[{"id":"1.230178329","rc":[{"atb":[[1.01,1.7]],"id":66686625},{"atl":[[1000,1.7]],"id":66686625},{"atb":[[1.01,1.7]],"id":70053016},{"atl":[[1000,1.87]],"id":70053016},{"atb":[[1.08,3.97]],"id":53082422},{"atl":[[1000,1.7]],"id":53082422}],"con":true,"img":false}]}
{"op":"mcm","clk":"11541542197","pt":1719506828769,"mc":[{"id":"1.230178329","rc":[{"atb":[[1.01,0.64]],"id":66686625},{"atl":[[1000,0.03]],"id":66686625},{"atb":[[1.01,1.38]],"id":70053016},{"atl":[[1000,0.21]],"id":70053016},{"atl":[[1000,0.06]],"id":53082422}],"con":true,"img":false}]}
{"op":"mcm","clk":"11541542211","pt":1719506828978,"mc":[{"id":"1.230178329","rc":[{"atb":[[1.01,0]],"id":66686625},{"atl":[[1000,0]],"id":66686625},{"atb":[[1.01,0]],"id":70053016},{"atl":[[1000,0.16]],"id":70053016},{"atl":[[1000,0]],"id":53082422}],"con":true,"img":false}]}
{"op":"mcm","clk":"11541542218","pt":1719506829084,"mc":[{"id":"1.230178329","rc":[{"atb":[[1.49,0.64]],"id":66686625},{"atl":[[10.5,0.03]],"id":66686625},{"atb":[[1.23,1.38]],"id":70053016},{"atl":[[7.8,0.04]],"id":70053016},{"atl":[[5.7,0.06]],"id":53082422}],"con":true,"img":false}]}
{"op":"mcm","clk":"11541542471","pt":1719506832143,"mc":[{"id":"1.230178329","rc":[{"atb":[[1.73,2.48]],"id":64812720},{"atl":[[5.2,1]],"id":64812720},{"atb":[[2.24,1],[2.32,0],[1.81,20.15],[1.71,0]],"id":70902603},{"atl":[[6.2,0],[5.9,1]],"id":70902603},{"atb":[[1.6,2],[1.48,0]],"id":66686625},{"atl":[[4.6,0],[4.4,1]],"id":66686625},{"atb":[[1.27,20.15],[1.22,0]],"id":70053016},{"atl":[[4.5,1],[4.6,0]],"id":70053016},{"atb":[[2.26,2.11],[2.34,20.15]],"id":69942666},{"atl":[[10,1],[9.4,0]],"id":69942666},{"atl":[[3.55,0],[3.5,1]],"id":53082422}],"con":true,"img":false}]}
{"op":"mcm","clk":"11541542484","pt":1719506832249,"mc":[{"id":"1.230178329","rc":[{"atb":[[1.65,0]],"id":64812720},{"atl":[[5.3,0]],"id":64812720},{"atl":[[23,0],[24,3]],"id":70902603},{"atl":[[4.5,1],[4.4,0]],"id":66686625},{"atl":[[75,2.48],[10.5,1],[95,0]],"id":69942666}],"con":true,"img":false}]}
{"op":"mcm","clk":"11541542494","pt":1719506832354,"mc":[{"id":"1.230178329","rc":[{"atl":[[10,0]],"id":69942666}],"con":true,"img":false}]}
{"op":"mcm","clk":"11541542875","pt":1719506837340,"mc":[{"id":"1.230178329","rc":[{"atl":[[130,2],[75,0.48]],"id":69942666}],"con":true,"img":false}]}
{"op":"mcm","clk":"11541543240","pt":1719506842170,"mc":[{"id":"1.230178329","rc":[{"atb":[[1.77,2.48]],"id":64812720},{"atb":[[1.39,20.15]],"id":70053016},{"atb":[[2.46,20.15],[2.34,0]],"id":69942666}],"con":true,"img":false}]}
{"op":"mcm","clk":"11541543249","pt":1719506842264,"mc":[{"id":"1.230178329","rc":[{"atb":[[1.73,0]],"id":64812720},{"atb":[[1.27,0]],"id":70053016}],"con":true,"img":false}]}
{"op":"mcm","clk":"11541543376","pt":1719506843670,"mc":[{"id":"1.230178329","rc":[{"atb":[[1.42,2.11]],"id":70053016}],"con":true,"img":false}]}
{"op":"mcm","clk":"11541544327","pt":1719506854494,"mc":[{"id":"1.230178329","rc":[{"atb":[[2.24,0],[2.32,1]],"id":70902603},{"atb":[[3.2,1]],"id":69942666}],"con":true,"img":false}]}
{"op":"mcm","clk":"11541544334","pt":1719506854599,"mc":[{"id":"1.230178329","rc":[{"atb":[[2.54,0]],"id":69942666}],"con":true,"img":false}]}
{"op":"mcm","clk":"11541544628","pt":1719506858508,"mc":[{"id":"1.230178329","rc":[{"atb":[[1.09,2]],"id":53082422}],"con":true,"img":false}]}
{"op":"mcm","clk":"11541544654","pt":1719506858767,"mc":[{"id":"1.230178329","rc":[{"atb":[[1.43,2]],"id":70053016}],"con":true,"img":false}]}
{"op":"mcm","clk":"11541544670","pt":1719506858974,"mc":[{"id":"1.230178329","rc":[{"atb":[[1.02,2]],"id":66686625}],"con":true,"img":false}]}
{"op":"mcm","clk":"11541544682","pt":1719506859181,"mc":[{"id":"1.230178329","rc":[{"atb":[[1.02,2]],"id":64812720}],"con":true,"img":false}]}
{"op":"mcm","clk":"11541544703","pt":1719506859388,"mc":[{"id":"1.230178329","rc":[{"atb":[[1.02,24.64]],"id":70902603}],"con":true,"img":false}]}
{"op":"mcm","clk":"11541544725","pt":1719506859698,"mc":[{"id":"1.230178329","rc":[{"atb":[[1.02,2]],"id":69942666}],"con":true,"img":false}]}
{"op":"mcm","clk":"11541545483","pt":1719506869822,"mc":[{"id":"1.230178329","rc":[{"atb":[[1.49,0]],"id":66686625},{"atl":[[10.5,0]],"id":66686625},{"atb":[[1.23,0]],"id":70053016},{"atl":[[7.8,0]],"id":70053016},{"atb":[[1.08,0]],"id":53082422},{"atl":[[5.7,0]],"id":53082422}],"con":true,"img":false}]}
{"op":"mcm","clk":"11541545532","pt":1719506870395,"mc":[{"id":"1.230178329","rc":[{"atb":[[1.09,0]],"id":53082422}],"con":true,"img":false}]}
{"op":"mcm","clk":"11541545541","pt":1719506870499,"mc":[{"id":"1.230178329","rc":[{"atb":[[1.08,2]],"id":53082422}],"con":true,"img":false}]}
{"op":"mcm","clk":"11541546061","pt":1719506878229,"mc":[{"id":"1.230178329","rc":[{"atl":[[5,1],[5.2,0]],"id":64812720},{"atb":[[2.32,0],[2.3,1]],"id":70902603},{"atl":[[4.8,1],[4.5,0]],"id":66686625},{"atl":[[4.5,0],[3.85,1]],"id":70053016},{"atl":[[10.5,0],[11.5,1]],"id":69942666},{"atl":[[3.2,1],[3.5,0]],"id":53082422}],"con":true,"img":false}]}
{"op":"mcm","clk":"11541546071","pt":1719506878334,"mc":[{"id":"1.230178329","rc":[{"atl":[[4.7,1]],"id":64812720},{"atb":[[1.81,0]],"id":70902603},{"atl":[[4.4,1]],"id":66686625},{"atl":[[130,0]],"id":69942666}],"con":true,"img":false}]}
{"op":"mcm","clk":"11541546077","pt":1719506878405,"mc":[{"id":"1.230178329","rc":[{"atb":[[1.85,20.15]],"id":70902603},{"atl":[[75,2.48]],"id":69942666}],"con":true,"img":false}]}
{"op":"mcm","clk":"11541546173","pt":1719506879738,"mc":[{"id":"1.230178329","rc":[{"atl":[[5,0]],"id":64812720},{"atb":[[2.3,0],[2.32,1]],"id":70902603},{"atl":[[4.8,0]],"id":66686625},{"atl":[[10.5,1],[11.5,0]],"id":69942666}],"con":true,"img":false}]}
{"op":"mcm","clk":"11541546316","pt":1719506881417,"mc":[{"id":"1.230178329","rc":[{"spn":1.08,"spf":1.0,"id":64812720},{"spn":4.11,"spf":"NaN","id":70902603},{"spn":3.11,"spf":"NaN","id":66686625},{"atb":[[1.21,0]],"id":70053016},{"spn":2.75,"spf":"NaN","id":70053016},{"spn":6.85,"spf":"NaN","id":69942666},{"spn":1.59,"spf":1.0,"id":53082422}],"con":true,"img":false}]}
{"op":"mcm","clk":"11541546373","pt":1719506882102,"mc":[{"id":"1.230178329","rc":[{"atb":[[1.21,0]],"id":70902603},{"atb":[[1.21,0]],"id":69942666}],"con":true,"img":false}]}
{"op":"mcm","clk":"11541546535","pt":1719506883634,"mc":[{"id":"1.230178329","rc":[{"atl":[[4.8,1],[5.2,1],[4.7,0]],"id":64812720},{"atb":[[2.32,0],[2.12,1]],"id":70902603},{"atl":[[5.8,1],[5.9,0]],"id":70902603},{"atl":[[4.5,1],[4.6,1],[4.4,0]],"id":66686625},{"atl":[[4.5,1],[3.85,0],[3.9,1]],"id":70053016},{"atb":[[3.2,0],[2.54,1],[2.76,1]],"id":69942666},{"atl":[[130,2],[75,0.48]],"id":69942666},{"atl":[[3.2,0],[3.5,1]],"id":53082422}],"con":true,"img":false}]}
{"op":"mcm","clk":"11541546547","pt":1719506883738,"mc":[{"id":"1.230178329","rc":[{"atl":[[18,0],[5.9,2]],"id":64812720},{"atl":[[21,2],[24,0]],"id":70902603},{"atl":[[4.6,3],[11,0]],"id":66686625},{"atl":[[8,0],[4.5,3]],"id":70053016},{"atb":[[2.54,3.12],[2.46,0]],"id":69942666}],"con":true,"img":false}]}
{"op":"mcm","clk":"11541546553","pt":1719506883844,"mc":[{"id":"1.230178329","rc":[{"atl":[[18,2],[5.9,0]],"id":64812720},{"atl":[[4.6,1],[11,2]],"id":66686625},{"atl":[[8,2],[4.5,1]],"id":70053016},{"atb":[[2.54,0],[2.46,2.12]],"id":69942666}],"con":true,"img":false}]}
{"op":"mcm","clk":"11541546565","pt":1719506883912,"mc":[{"id":"1.230178329","rc":[{"atl":[[18,0],[5.9,2]],"id":64812720}],"con":true,"img":false}]}
{"op":"mcm","clk":"11541546609","pt":1719506884322,"mc":[{"id":"1.230178329","rc":[{"atl":[[4.8,0],[5.2,0]],"id":64812720},{"atl":[[5.8,0],[5.9,1]],"id":70902603},{"atl":[[4.5,0],[4.6,0],[4.7,1]],"id":66686625},{"atl":[[3.9,0]],"id":70053016},{"atb":[[2.54,1],[2.76,0]],"id":69942666}],"con":true,"img":false}]}
{"op":"mcm","clk":"11541546621","pt":1719506884426,"mc":[{"id":"1.230178329","rc":[{"atl":[[11,0],[4.7,3]],"id":66686625}],"con":true,"img":false}]}
{"op":"mcm","clk":"11541546640","pt":1719506884636,"mc":[{"id":"1.230178329","rc":[{"atb":[[2.54,0],[2.76,1]],"id":69942666}],"con":true,"img":false}]}
{"op":"mcm","clk":"11541546656","pt":1719506884795,"mc":[{"id":"1.230178329","rc":[{"atl":[[5.2,1]],"id":64812720}],"con":true,"img":false}]}
{"op":"mcm","clk":"11541546668","pt":1719506884919,"mc":[{"id":"1.230178329","rc":[{"atl":[[19.5,3],[5.9,0]],"id":64812720}],"con":true,"img":false}]}
{"op":"mcm","clk":"11541546701","pt":1719506885211,"mc":[{"id":"1.230178329","rc":[{"atb":[[2.54,1],[2.76,0]],"id":69942666}],"con":true,"img":false}]}
{"op":"mcm","clk":"11541546709","pt":1719506885317,"mc":[{"id":"1.230178329","rc":[{"atl":[[5.8,1],[5.9,0]],"id":70902603},{"atl":[[4.6,1],[4.7,2]],"id":66686625}],"con":true,"img":false}]}
{"op":"mcm","clk":"11541546728","pt":1719506885524,"mc":[{"id":"1.230178329","rc":[{"atb":[[2.32,1],[2.12,0]],"id":70902603},{"atl":[[5.8,0]],"id":70902603},{"atl":[[4.6,0],[4.7,3]],"id":66686625},{"atb":[[2.54,0],[3.2,1],[2.76,1]],"id":69942666}],"con":true,"img":false}]}
{"op":"mcm","clk":"11541546736","pt":1719506885629,"mc":[{"id":"1.230178329","rc":[{"atl":[[5.9,1]],"id":70902603}],"con":true,"img":false}]}
{"op":"mcm","clk":"11541546791","pt":1719506886208,"mc":[{"id":"1.230178329","rc":[{"atb":[[1.02,0]],"id":69942666}],"con":true,"img":false}]}
{"op":"mcm","clk":"11541546803","pt":1719506886314,"mc":[{"id":"1.230178329","rc":[{"atb":[[2.78,2]],"id":69942666}],"con":true,"img":false}]}
{"op":"mcm","clk":"11541546809","pt":1719506886419,"mc":[{"id":"1.230178329","rc":[{"atb":[[2.46,0],[2.78,4]],"id":69942666}],"con":true,"img":false}]}
{"op":"mcm","clk":"11541546846","pt":1719506886938,"mc":[{"id":"1.230178329","rc":[{"atb":[[2.78,2]],"id":69942666}],"con":true,"img":false}]}
{"op":"mcm","clk":"11541546856","pt":1719506886995,"mc":[{"id":"1.230178329","rc":[{"atb":[[1.02,2]],"id":69942666}],"con":true,"img":false}]}
{"op":"mcm","clk":"11541546862","pt":1719506887106,"mc":[{"id":"1.230178329","rc":[{"atb":[[3.2,0],[2.76,0]],"id":69942666}],"con":true,"img":false}]}
{"op":"mcm","clk":"11541546975","pt":1719506888612,"mc":[{"id":"1.230178329","rc":[{"atb":[[3.2,1]],"id":69942666}],"con":true,"img":false}]}
{"op":"mcm","clk":"11541547060","pt":1719506889511,"mc":[{"id":"1.230178329","rc":[{"atl":[[12,6],[4.7,1]],"id":66686625}],"con":true,"img":false}]}
{"op":"mcm","clk":"11541547121","pt":1719506890245,"mc":[{"id":"1.230178329","rc":[{"atb":[[1.19,0]],"id":70053016}],"con":true,"img":false}]}
{"op":"mcm","clk":"11541547131","pt":1719506890350,"mc":[{"id":"1.230178329","rc":[{"atl":[[5.2,0],[4.7,1]],"id":64812720},{"atl":[[4.4,1],[4.7,0]],"id":66686625},{"atl":[[4.5,0],[3.85,1]],"id":70053016},{"atl":[[3.2,1],[3.5,0]],"id":53082422}],"con":true,"img":false}]}
{"op":"mcm","clk":"11541547220","pt":1719506891516,"mc":[{"id":"1.230178329","rc":[{"atb":[[2.46,3],[2.78,0]],"id":69942666}],"con":true,"img":false}]}
{"op":"mcm","clk":"11541547295","pt":1719506892457,"mc":[{"id":"1.230178329","rc":[{"atb":[[3.2,0],[2.54,1]],"id":69942666}],"con":true,"img":false}]}
{"op":"mcm","clk":"11541547370","pt":1719506893346,"mc":[{"id":"1.230178329","rc":[{"atl":[[5.2,1],[4.7,0]],"id":64812720},{"atl":[[4.5,1],[3.85,0]],"id":70053016}],"con":true,"img":false}]}
{"op":"mcm","clk":"11541547662","pt":1719506896810,"mc":[{"id":"1.230178329","rc":[{"atl":[[3.2,0],[3.5,1]],"id":53082422}],"con":true,"img":false}]}
{"op":"mcm","clk":"11541547959","pt":1719506901562,"mc":[{"id":"1.230178329","rc":[{"atb":[[2.32,0],[2.12,1]],"id":70902603},{"atl":[[5.8,1],[5.9,0]],"id":70902603},{"atl":[[4.6,1],[4.4,0]],"id":66686625},{"atb":[[2.54,0],[2.76,1]],"id":69942666}],"con":true,"img":false}]}
{"op":"mcm","clk":"11541547969","pt":1719506901616,"mc":[{"id":"1.230178329","rc":[{"atb":[[1.8,21.15],[1.85,0]],"id":70902603},{"atl":[[12,0],[4.7,2]],"id":66686625}],"con":true,"img":false}]}
{"op":"mcm","clk":"11541547978","pt":1719506901720,"mc":[{"id":"1.230178329","rc":[{"atl":[[12,2]],"id":66686625}],"con":true,"img":false}]}
{"op":"mcm","clk":"11541547987","pt":1719506901824,"mc":[{"id":"1.230178329","rc":[{"atl":[[4.7,0]],"id":66686625}],"con":true,"img":false}]}
{"op":"mcm","clk":"11541548078","pt":1719506903026,"mc":[{"id":"1.230178329","rc":[{"atb":[[2.32,1],[2.12,0]],"id":70902603},{"atl":[[5.8,0],[5.9,1]],"id":70902603},{"atl":[[4.6,0],[4.7,1]],"id":66686625},{"atb":[[2.54,1],[2.76,0]],"id":69942666}],"con":true,"img":false}]}
{"op":"mcm","clk":"11541548097","pt":1719506903336,"mc":[{"id":"1.230178329","rc":[{"atb":[[2.32,0],[2.12,1]],"id":70902603},{"atl":[[5.8,1],[5.9,0]],"id":70902603},{"atl":[[4.6,1],[4.7,0]],"id":66686625},{"atb":[[2.54,0],[2.76,1]],"id":69942666}],"con":true,"img":false}]}
{"op":"mcm","clk":"11541548480","pt":1719506908421,"mc":[{"id":"1.230178329","rc":[{"atb":[[2.32,1],[2.12,0]],"id":70902603},{"atl":[[5.8,0],[5.9,1]],"id":70902603},{"atl":[[4.6,0],[4.4,1]],"id":66686625},{"atb":[[2.54,1],[2.76,0]],"id":69942666}],"con":true,"img":false}]}
{"op":"mcm","clk":"11541548491","pt":1719506908526,"mc":[{"id":"1.230178329","rc":[{"atb":[[2.32,0]],"id":70902603},{"atl":[[5.8,1]],"id":70902603},{"atb":[[2.76,1]],"id":69942666}],"con":true,"img":false}]}
{"op":"mcm","clk":"11541548502","pt":1719506908636,"mc":[{"id":"1.230178329","rc":[{"atb":[[2.12,1]],"id":70902603},{"atl":[[5.9,0]],"id":70902603},{"atl":[[4.6,1],[4.4,0]],"id":66686625},{"atb":[[2.54,0]],"id":69942666}],"con":true,"img":false}]}
{"op":"mcm","clk":"11541548517","pt":1719506908835,"mc":[{"id":"1.230178329","rc":[{"atl":[[4.6,0],[4.7,1]],"id":66686625}],"con":true,"img":false}]}
{"op":"mcm","clk":"11541548537","pt":1719506909148,"mc":[{"id":"1.230178329","rc":[{"atb":[[1.02,0]],"id":69942666}],"con":true,"img":false}]}
{"op":"mcm","clk":"11541548544","pt":1719506909250,"mc":[{"id":"1.230178329","rc":[{"atb":[[2.56,2]],"id":69942666}],"con":true,"img":false}]}
{"op":"mcm","clk":"11541548554","pt":1719506909355,"mc":[{"id":"1.230178329","rc":[{"atl":[[18,2],[21,0]],"id":70902603},{"atb":[[1.45,2.12],[1.39,0]],"id":70053016},{"atl":[[5.8,0],[6.8,3]],"id":53082422}],"con":true,"img":false}]}
{"op":"mcm","clk":"11541548566","pt":1719506909459,"mc":[{"id":"1.230178329","rc":[{"atb":[[2.56,4.12],[2.46,0]],"id":69942666}],"con":true,"img":false}]}
{"op":"mcm","clk":"11541548598","pt":1719506909829,"mc":[{"id":"1.230178329","rc":[{"atb":[[1.43,0]],"id":70053016}],"con":true,"img":false}]}
{"op":"mcm","clk":"11541548605","pt":1719506909928,"mc":[{"id":"1.230178329","rc":[{"atb":[[1.46,2]],"id":70053016}],"con":true,"img":false}]}
{"op":"mcm","clk":"11541548633","pt":1719506910239,"mc":[{"id":"1.230178329","rc":[{"atb":[[2.56,2.12]],"id":69942666}],"con":true,"img":false}]}
{"op":"mcm","clk":"11541548641","pt":1719506910343,"mc":[{"id":"1.230178329","rc":[{"atb":[[1.02,2]],"id":69942666}],"con":true,"img":false}]}
{"op":"mcm","clk":"11541548966","pt":1719506914571,"mc":[{"id":"1.230178329","rc":[{"atb":[[2.56,0],[2.48,3.12]],"id":69942666}],"con":true,"img":false}]}
{"op":"mcm","clk":"11541549111","pt":1719506916342,"mc":[{"id":"1.230178329","rc":[{"atl":[[5.1,1],[5.2,0]],"id":64812720}],"con":true,"img":false}]}
{"op":"mcm","clk":"11541549288","pt":1719506918582,"mc":[{"id":"1.230178329","rc":[{"atl":[[5.8,0]],"id":70902603}],"con":true,"img":false}]}
{"op":"mcm","clk":"11541549296","pt":1719506918657,"mc":[{"id":"1.230178329","rc":[{"atl":[[5.6,1]],"id":70902603}],"con":true,"img":false}]}
{"op":"mcm","clk":"11541549966","pt":1719506927056,"mc":[{"id":"1.230178329","rc":[{"atb":[[2.24,1],[2.12,0]],"id":70902603},{"atb":[[1.83,0],[1.88,1]],"id":66686625},{"atb":[[3.25,1]],"id":69942666},{"atl":[[3.45,1],[3.5,0]],"id":53082422}],"con":true,"img":false}]}
{"op":"mcm","clk":"11541549974","pt":1719506927158,"mc":[{"id":"1.230178329","rc":[{"atl":[[4.8,1],[5.1,0]],"id":64812720},{"atl":[[5.6,0],[5.5,1]],"id":70902603},{"atb":[[1.64,2],[1.92,1]],"id":66686625},{"atl":[[4,1],[4.5,0],[3.95,1]],"id":70053016},{"atb":[[2.56,2.12],[2.48,0],[2.76,0]],"id":69942666},{"atl":[[3.2,1],[5.8,2],[6.8,0],[3.15,1]],"id":53082422}],"con":true,"img":false}]}
{"op":"mcm","clk":"11541549982","pt":1719506927264,"mc":[{"id":"1.230178329","rc":[{"atb":[[2.24,0],[2.12,1]],"id":70902603},{"atl":[[5.3,1]],"id":70902603},{"atb":[[1.6,0],[1.88,0]],"id":66686625},{"atl":[[8,0],[4.5,2]],"id":70053016},{"atl":[[5.8,0],[6.8,2]],"id":53082422}],"con":true,"img":false}]}
{"op":"mcm","clk":"11541549989","pt":1719506927366,"mc":[{"id":"1.230178329","rc":[{"atl":[[8,2],[4.5,0]],"id":70053016},{"atl":[[3.45,3],[6.8,0]],"id":53082422}],"con":true,"img":false}]}
{"op":"mcm","clk":"11541550000","pt":1719506927469,"mc":[{"id":"1.230178329","rc":[{"atl":[[8,0],[4.5,2]],"id":70053016},{"atb":[[1.02,0]],"id":69942666}],"con":true,"img":false}]}
{"op":"mcm","clk":"11541550009","pt":1719506927573,"mc":[{"id":"1.230178329","rc":[{"atb":[[2.78,2]],"id":69942666}],"con":true,"img":false}]}
{"op":"mcm","clk":"11541550018","pt":1719506927678,"mc":[{"id":"1.230178329","rc":[{"atl":[[5.5,0]],"id":70902603},{"atl":[[3.95,0]],"id":70053016},{"atb":[[2.56,0],[2.78,4.12]],"id":69942666}],"con":true,"img":false}]}
{"op":"mcm","clk":"11541550048","pt":1719506927954,"mc":[{"id":"1.230178329","rc":[{"atl":[[3.45,2],[3.15,0]],"id":53082422}],"con":true,"img":false}]}
{"op":"mcm","clk":"11541550069","pt":1719506928150,"mc":[{"id":"1.230178329","rc":[{"atl":[[3.45,0],[6.8,3]],"id":53082422}],"con":true,"img":false}]}
{"op":"mcm","clk":"11541550095","pt":1719506928460,"mc":[{"id":"1.230178329","rc":[{"atb":[[2.78,2.12]],"id":69942666}],"con":true,"img":false}]}
{"op":"mcm","clk":"11541550107","pt":1719506928567,"mc":[{"id":"1.230178329","rc":[{"atb":[[1.02,2],[2.78,0],[2.48,3.12]],"id":69942666}],"con":true,"img":false}]}
{"op":"mcm","clk":"11541550224","pt":1719506929867,"mc":[{"id":"1.230178329","rc":[{"atb":[[1.83,1],[1.92,0]],"id":66686625}],"con":true,"img":false}]}
{"op":"mcm","clk":"11541550274","pt":1719506930565,"mc":[{"id":"1.230178329","rc":[{"atb":[[1.83,0],[1.92,1]],"id":66686625},{"atb":[[3.25,0],[2.76,1]],"id":69942666}],"con":true,"img":false}]}
{"op":"mcm","clk":"11541550282","pt":1719506930663,"mc":[{"id":"1.230178329","rc":[{"atb":[[2.48,0],[2.76,3.12]],"id":69942666}],"con":true,"img":false}]}
{"op":"mcm","clk":"11541550292","pt":1719506930758,"mc":[{"id":"1.230178329","rc":[{"atb":[[2.76,1]],"id":69942666}],"con":true,"img":false}]}
{"op":"mcm","clk":"11541550300","pt":1719506930860,"mc":[{"id":"1.230178329","rc":[{"atb":[[2.48,2.12]],"id":69942666}],"con":true,"img":false}]}
{"op":"mcm","clk":"11541550785","pt":1719506937162,"mc":[{"id":"1.230178329","rc":[{"atl":[[4.8,0],[5.1,1]],"id":64812720},{"atl":[[4,0],[4.5,3]],"id":70053016},{"atl":[[3.45,1],[3.2,0]],"id":53082422}],"con":true,"img":false}]}
{"op":"mcm","clk":"11541550799","pt":1719506937369,"mc":[{"id":"1.230178329","rc":[{"atl":[[4.5,1],[8.8,6]],"id":70053016}],"con":true,"img":false}]}
{"op":"mcm","clk":"11541551141","pt":1719506941769,"mc":[{"id":"1.230178329","rc":[{"spn":3.71,"spf":"NaN","id":70902603},{"atb":[[1.01,1.7]],"id":66686625},{"atl":[[1000,1.7]],"id":66686625},{"spn":3.31,"spf":"NaN","id":66686625},{"atb":[[1.01,1.7]],"id":70053016},{"atl":[[1000,1.87]],"id":70053016},{"spn":3.08,"spf":"NaN","id":70053016},{"spn":6.63,"spf":"NaN","id":69942666},{"atb":[[1.09,3.4]],"id":53082422},{"atl":[[1000,1.7]],"id":53082422}],"con":true,"img":false}]}
{"op":"mcm","clk":"11541551155","pt":1719506941976,"mc":[{"id":"1.230178329","rc":[{"atb":[[1.01,0.47]],"id":66686625},{"atl":[[1000,0.02]],"id":66686625},{"atb":[[1.01,0.65]],"id":70053016},{"atl":[[1000,0.21]],"id":70053016},{"atl":[[1000,0.05]],"id":53082422}],"con":true,"img":false}]}
{"op":"mcm","clk":"11541551169","pt":1719506942186,"mc":[{"id":"1.230178329","rc":[{"atb":[[1.01,0]],"id":66686625},{"atl":[[1000,0]],"id":66686625},{"atb":[[1.01,0]],"id":70053016},{"atl":[[1000,0.16]],"id":70053016},{"atl":[[1000,0]],"id":53082422}],"con":true,"img":false}]}
{"op":"mcm","clk":"11541551178","pt":1719506942292,"mc":[{"id":"1.230178329","rc":[{"atb":[[1.65,0.47]],"id":66686625},{"atl":[[11.5,0.02]],"id":66686625},{"atb":[[1.47,0.65]],"id":70053016},{"atl":[[8.6,0.04]],"id":70053016},{"atb":[[1.08,0]],"id":53082422},{"atl":[[6.6,0.05]],"id":53082422}],"con":true,"img":false}]}
{"op":"mcm","clk":"11541551186","pt":1719506942396,"mc":[{"id":"1.230178329","rc":[{"atb":[[1.1,2]],"id":53082422}],"con":true,"img":false}]}
{"op":"mcm","clk":"11541551636","pt":1719506947998,"mc":[{"id":"1.230178329","rc":[{"atb":[[1.97,1]],"id":70902603},{"atb":[[1.83,1],[1.92,0]],"id":66686625},{"atb":[[3.25,1],[2.76,0]],"id":69942666}],"con":true,"img":false}]}
{"op":"mcm","clk":"11541551651","pt":1719506948014,"mc":[{"id":"1.230178329","rc":[{"atb":[[2.12,0]],"id":70902603}],"con":true,"img":false}]}
{"op":"mcm","clk":"11541551661","pt":1719506948027,"mc":[{"id":"1.230178329","rc":[{"atb":[[1.64,0],[1.65,2.47]],"id":66686625},{"atb":[[3.25,0],[2.76,1]],"id":69942666}],"con":true,"img":false}]}
{"op":"mcm","clk":"11541551982","pt":1719506952176,"mc":[{"id":"1.230178329","rc":[{"atb":[[3.25,1],[2.76,0]],"id":69942666}],"con":true,"img":false}]}
{"op":"mcm","clk":"11541552210","pt":1719506955284,"mc":[{"id":"1.230178329","rc":[{"atb":[[3.25,0],[2.76,1]],"id":69942666}],"con":true,"img":false}]}
{"op":"mcm","clk":"11541552382","pt":1719506957615,"mc":[{"id":"1.230178329","rc":[{"atl":[[4.8,1],[5.1,0]],"id":64812720},{"atl":[[5.1,1],[5.3,0]],"id":70902603},{"atl":[[4,1],[4.5,0]],"id":70053016},{"atb":[[3.25,1],[3.3,1],[2.76,0]],"id":69942666},{"atl":[[3.45,0],[3.2,1],[3.5,1]],"id":53082422}],"con":true,"img":false}]}
{"op":"mcm","clk":"11541552389","pt":1719506957720,"mc":[{"id":"1.230178329","rc":[{"atb":[[2.76,2.12]],"id":69942666},{"atl":[[6.8,0]],"id":53082422}],"con":true,"img":false}]}
{"op":"mcm","clk":"11541552397","pt":1719506957784,"mc":[{"id":"1.230178329","rc":[{"atb":[[2.48,0]],"id":69942666},{"atl":[[3.45,2]],"id":53082422}],"con":true,"img":false}]}
{"op":"mcm","clk":"11541552415","pt":1719506957995,"mc":[{"id":"1.230178329","rc":[{"atl":[[3.45,0],[6.6,2.05]],"id":53082422}],"con":true,"img":false}]}
{"op":"mcm","clk":"11541552455","pt":1719506958503,"mc":[{"id":"1.230178329","rc":[{"atl":[[4.8,0],[4.9,1]],"id":64812720},{"atl":[[5.1,0],[5,1]],"id":70902603},{"atl":[[4,0],[3.95,1]],"id":70053016},{"atb":[[3.25,0],[3.3,0]],"id":69942666},{"atl":[[10.5,0],[11,1]],"id":69942666},{"atl":[[3.2,0],[3.5,0],[3.3,1]],"id":53082422}],"con":true,"img":false}]}
{"op":"mcm","clk":"11541552467","pt":1719506958606,"mc":[{"id":"1.230178329","rc":[{"atl":[[19.5,0],[6,2]],"id":64812720},{"atl":[[18,0],[5.4,2]],"id":70902603},{"atl":[[4.5,2]],"id":70053016},{"atl":[[130,0],[75,2.48]],"id":69942666}],"con":true,"img":false}]}
{"op":"mcm","clk":"11541552477","pt":1719506958710,"mc":[{"id":"1.230178329","rc":[{"atb":[[1.8,2.48],[1.77,0]],"id":64812720},{"atl":[[4.9,0]],"id":64812720},{"atl":[[8.8,0]],"id":70053016},{"atb":[[3.25,1],[2.48,4.24],[2.76,0]],"id":69942666},{"atl":[[10.5,1],[11,0]],"id":69942666}],"con":true,"img":false}]}
{"op":"mcm","clk":"11541552508","pt":1719506959083,"mc":[{"id":"1.230178329","rc":[{"atl":[[4.9,1]],"id":64812720}],"con":true,"img":false}]}
{"op":"mcm","clk":"11541552602","pt":1719506960082,"mc":[{"id":"1.230178329","rc":[{"atl":[[4.8,1]],"id":64812720}],"con":true,"img":false}]}
{"op":"mcm","clk":"11541552668","pt":1719506960903,"mc":[{"id":"1.230178329","rc":[{"atl":[[4.8,0]],"id":64812720}],"con":true,"img":false}]}
{"op":"mcm","clk":"11541552897","pt":1719506963706,"mc":[{"id":"1.230178329","rc":[{"atl":[[21,3],[6,0]],"id":64812720},{"atl":[[5.4,0]],"id":70902603},{"atl":[[8.6,3.04]],"id":70053016}],"con":true,"img":false}]}
{"op":"mcm","clk":"11541552907","pt":1719506963809,"mc":[{"id":"1.230178329","rc":[{"atl":[[17,3]],"id":70902603},{"atl":[[4.5,0]],"id":70053016}],"con":true,"img":false}]}
{"op":"mcm","clk":"11541554496","pt":1719506984016,"mc":[{"id":"1.230178329","rc":[{"atb":[[1.65,2]],"id":66686625},{"atl":[[11.5,0]],"id":66686625},{"atb":[[1.47,0]],"id":70053016},{"atl":[[8.6,3]],"id":70053016},{"atb":[[1.09,0]],"id":53082422},{"atl":[[6.6,2]],"id":53082422}],"con":true,"img":false}]}
{"op":"mcm","clk":"11541554572","pt":1719506985062,"mc":[{"id":"1.230178329","rc":[{"atb":[[1.1,0]],"id":53082422}],"con":true,"img":false}]}
{"op":"mcm","clk":"11541554579","pt":1719506985115,"mc":[{"id":"1.230178329","rc":[{"atb":[[1.08,2]],"id":53082422}],"con":true,"img":false}]}
{"op":"mcm","clk":"11541554877","pt":1719506989225,"mc":[{"id":"1.230178329","rc":[{"atb":[[2.76,1]],"id":69942666}],"con":true,"img":false}]}
{"op":"mcm","clk":"11541554888","pt":1719506989329,"mc":[{"id":"1.230178329","rc":[{"atb":[[3.25,0]],"id":69942666},{"atl":[[140,2]],"id":69942666}],"con":true,"img":false}]}
{"op":"mcm","clk":"11541554895","pt":1719506989431,"mc":[{"id":"1.230178329","rc":[{"atl":[[75,0.48]],"id":69942666}],"con":true,"img":false}]}
{"op":"mcm","clk":"11541554937","pt":1719506990260,"mc":[{"id":"1.230178329","rc":[{"atl":[[5.1,1],[4.9,0]],"id":64812720},{"atl":[[5,0]],"id":70902603},{"atl":[[4.5,1],[3.95,0]],"id":70053016}],"con":true,"img":false}]}
{"op":"mcm","clk":"11541554942","pt":1719506990322,"mc":[{"id":"1.230178329","rc":[{"atl":[[5.2,1]],"id":70902603}],"con":true,"img":false}]}
{"op":"mcm","clk":"11541555057","pt":1719506992029,"mc":[{"id":"1.230178329","rc":[{"atl":[[3.3,0],[3.5,1]],"id":53082422}],"con":true,"img":false}]}
{"op":"mcm","clk":"11541555560","pt":1719507000457,"mc":[{"id":"1.230178329","rc":[{"atb":[[1.48,2.5]],"id":53082422},{"atl":[[3.45,1.5]],"id":53082422}],"con":true,"img":false}]}
{"op":"mcm","clk":"11541555567","pt":1719507000555,"mc":[{"id":"1.230178329","rc":[{"atb":[[2.4,5],[2.32,10],[2.48,2.5]],"id":70902603},{"atl":[[5.6,2.5],[6,5],[6.8,10]],"id":70902603}],"con":true,"img":false}]}
{"op":"mcm","clk":"11541555573","pt":1719507000663,"mc":[{"id":"1.230178329","rc":[{"atb":[[1.99,1.5],[2.5,10],[2.66,2.5],[2.58,5]],"id":64812720},{"atl":[[8,10],[7.2,5],[6.4,2.5],[9.8,1.5]],"id":64812720},{"atb":[[2.26,2.12],[2.08,2.34]],"id":70902603},{"atl":[[5.1,2.34],[6,7]],"id":70902603},{"atb":[[1.84,1.5],[2.28,2.5],[2.12,10],[2.2,5]],"id":66686625},{"atl":[[4.6,1.5],[6.2,5],[5.7,2.5],[7,10]],"id":66686625},{"atb":[[1.92,5],[1.88,10],[1.96,2.5],[1.66,3.25]],"id":70053016},{"atl":[[7.2,2.25],[5,2.5],[5.8,10],[5.4,5]],"id":70053016},{"atb":[[3.35,2.5],[3.15,5],[2.98,10],[2.78,2.25]],"id":69942666},{"atl":[[16.5,10],[10,2.25],[12.5,2.5],[14.5,5]],"id":69942666},{"atb":[[1.41,10],[1.45,5],[1.49,2.5]],"id":53082422},{"atl":[[3.45,4],[3.85,10],[3.65,5]],"id":53082422}],"con":true,"img":false}]}
{"op":"mcm","clk":"11541555578","pt":1719507000763,"mc":[{"id":"1.230178329","rc":[{"atb":[[2.4,2],[1.8,0]],"id":64812720},{"atl":[[6.4,4.5],[21,0]],"id":64812720},{"atb":[[1.8,0]],"id":70902603},{"atl":[[5.6,7.5],[17,0],[6,5]],"id":70902603},{"atb":[[1.65,0],[2.08,2]],"id":66686625},{"atl":[[12,0],[5.7,4.5]],"id":66686625},{"atb":[[1.85,2]],"id":70053016},{"atl":[[5,4.5]],"id":70053016},{"atb":[[1.44,5],[1.07,2.48]],"id":53082422},{"atl":[[6.6,0],[3.65,7.5]],"id":53082422}],"con":true,"img":false}]}
{"op":"mcm","clk":"11541555585","pt":1719507000871,"mc":[{"id":"1.230178329","rc":[{"atl":[[7.2,10],[6.4,2.5]],"id":64812720},{"atb":[[1.45,0]],"id":70053016},{"atl":[[8.6,0],[5,2.5],[5.4,10]],"id":70053016},{"atb":[[2.98,12.12],[2.48,0]],"id":69942666},{"atl":[[140,0],[17,2]],"id":69942666}],"con":true,"img":false}]}
{"op":"mcm","clk":"11541555605","pt":1719507001130,"mc":[{"id":"1.230178329","rc":[{"atb":[[1.08,0]],"id":53082422}],"con":true,"img":false}]}
{"op":"mcm","clk":"11541555607","pt":1719507001225,"mc":[{"id":"1.230178329","rc":[{"atb":[[1.02,2]],"id":53082422}],"con":true,"img":false}]}
{"op":"mcm","clk":"11541555615","pt":1719507001329,"mc":[{"id":"1.230178329","rc":[{"atl":[[5,0.84]],"id":70902603},{"atl":[[9.8,0.84]],"id":69942666},{"atl":[[3.4,0.84]],"id":53082422}],"con":true,"img":false}]}
{"op":"mcm","clk":"11541555618","pt":1719507001434,"mc":[{"id":"1.230178329","rc":[{"atl":[[5.6,2.5],[5.4,7.5]],"id":70902603},{"atb":[[1.03,21.34]],"id":53082422},{"atl":[[3.5,8.5],[3.65,5]],"id":53082422}],"con":true,"img":false}]}
{"op":"mcm","clk":"11541555634","pt":1719507001653,"mc":[{"id":"1.230178329","rc":[{"atb":[[1.02,22.64]],"id":70902603},{"atb":[[1.03,15.09]],"id":53082422}],"con":true,"img":false}]}
{"op":"mcm","clk":"11541555645","pt":1719507001756,"mc":[{"id":"1.230178329","rc":[{"atb":[[2.5,2]],"id":70902603}],"con":true,"img":false}]}
{"op":"mcm","clk":"11541555688","pt":1719507002447,"mc":[{"id":"1.230178329","rc":[{"spn":1.83,"spf":1.0,"id":64812720},{"spn":3.75,"spf":"NaN","id":70902603},{"spn":3.44,"spf":"NaN","id":66686625},{"spn":3.23,"spf":"NaN","id":70053016},{"spn":6.57,"spf":"NaN","id":69942666},{"atb":[[1.02,0]],"id":53082422},{"spn":1.6,"spf":1.0,"id":53082422}],"con":true,"img":false}]}
{"op":"mcm","clk":"11541555699","pt":1719507002544,"mc":[{"id":"1.230178329","rc":[{"atb":[[2.56,2.11]],"id":64812720},{"atb":[[2.18,2.11]],"id":66686625},{"atb":[[1.5,2],[1.47,2.11]],"id":53082422}],"con":true,"img":false}]}
{"op":"mcm","clk":"11541555719","pt":1719507002959,"mc":[{"id":"1.230178329","rc":[{"atb":[[1.46,0]],"id":70053016}],"con":true,"img":false}]}
{"op":"mcm","clk":"11541555726","pt":1719507003065,"mc":[{"id":"1.230178329","rc":[{"atb":[[1.97,2]],"id":70053016}],"con":true,"img":false}]}
{"op":"mcm","clk":"11541555749","pt":1719507003370,"mc":[{"id":"1.230178329","rc":[{"atb":[[1.02,0]],"id":66686625}],"con":true,"img":false}]}
{"op":"mcm","clk":"11541555759","pt":1719507003424,"mc":[{"id":"1.230178329","rc":[{"atb":[[2.3,2]],"id":66686625}],"con":true,"img":false}]}
{"op":"mcm","clk":"11541555799","pt":1719507003853,"mc":[{"id":"1.230178329","rc":[{"atb":[[1.02,0]],"id":69942666}],"con":true,"img":false}]}
{"op":"mcm","clk":"11541555807","pt":1719507003942,"mc":[{"id":"1.230178329","rc":[{"atb":[[3.4,2]],"id":69942666}],"con":true,"img":false}]}
{"op":"mcm","clk":"11541556182","pt":1719507009170,"mc":[{"id":"1.230178329","rc":[{"atb":[[3.4,4.5],[2.98,10]],"id":69942666}],"con":true,"img":false}]}
{"op":"mcm","clk":"11541556189","pt":1719507009273,"mc":[{"id":"1.230178329","rc":[{"atb":[[1.97,0]],"id":70902603},{"atl":[[5.2,4.19],[5.4,0]],"id":70902603},{"atb":[[3.4,2],[3.15,10]],"id":69942666},{"atl":[[17,0],[14.5,10]],"id":69942666}],"con":true,"img":false}]}
{"op":"mcm","clk":"11541556197","pt":1719507009377,"mc":[{"id":"1.230178329","rc":[{"atb":[[3.4,6.5],[3.15,5]],"id":69942666}],"con":true,"img":false}]}
{"op":"mcm","clk":"11541556202","pt":1719507009479,"mc":[{"id":"1.230178329","rc":[{"atb":[[3.4,2],[3.15,15]],"id":69942666}],"con":true,"img":false}]}
{"op":"mcm","clk":"11541556209","pt":1719507009575,"mc":[{"id":"1.230178329","rc":[{"atb":[[3.4,7],[3.15,5]],"id":69942666}],"con":true,"img":false}]}
{"op":"mcm","clk":"11541556746","pt":1719507017983,"mc":[{"id":"1.230178329","rc":[{"atb":[[1.5,5.75]],"id":53082422},{"atl":[[3.3,3.75]],"id":53082422}],"con":true,"img":false}]}
{"op":"mcm","clk":"11541556755","pt":1719507018084,"mc":[{"id":"1.230178329","rc":[{"atl":[[3.25,3.75],[3.5,1]],"id":53082422}],"con":true,"img":false}]}
{"op":"mcm","clk":"11541556765","pt":1719507018180,"mc":[{"id":"1.230178329","rc":[{"atb":[[2.66,6.25]],"id":64812720},{"atl":[[5,3.75]],"id":64812720},{"atb":[[2.5,5.63]],"id":70902603},{"atl":[[5,4.47]],"id":70902603},{"atb":[[2.3,5.38]],"id":66686625},{"atb":[[1.99,3.75]],"id":70053016},{"atl":[[4.4,3.75]],"id":70053016},{"atb":[[3.45,3.56]],"id":69942666},{"atl":[[9.8,4.4]],"id":69942666},{"atb":[[1.48,1]],"id":53082422},{"atl":[[3.45,7.5]],"id":53082422}],"con":true,"img":false}]}
{"op":"mcm","clk":"11541556777","pt":1719507018284,"mc":[{"id":"1.230178329","rc":[{"atb":[[1.99,0]],"id":64812720},{"atl":[[7.2,5],[6.4,12.5],[9.8,0]],"id":64812720},{"atb":[[2.08,0]],"id":70902603},{"atl":[[5.1,0]],"id":70902603},{"atb":[[1.84,0]],"id":66686625},{"atl":[[5,12.5],[5.4,5]],"id":70053016},{"atl":[[3.25,0]],"id":53082422}],"con":true,"img":false}]}
{"op":"mcm","clk":"11541556783","pt":1719507018343,"mc":[{"id":"1.230178329","rc":[{"atb":[[1.66,1]],"id":70053016},{"atl":[[7.2,0]],"id":70053016},{"atb":[[2.78,0]],"id":69942666},{"atl":[[10,0]],"id":69942666},{"atl":[[3.2,0.84]],"id":53082422}],"con":true,"img":false}]}
{"op":"mcm","clk":"11541556793","pt":1719507018448,"mc":[{"id":"1.230178329","rc":[{"atl":[[3.4,0]],"id":53082422}],"con":true,"img":false}]}
{"op":"mcm","clk":"11541556812","pt":1719507018761,"mc":[{"id":"1.230178329","rc":[{"atb":[[2.56,0],[2.64,2.11]],"id":64812720},{"atb":[[1.74,0],[2.46,2.11]],"id":70902603},{"atb":[[2.18,0],[2.26,2.11]],"id":66686625},{"atb":[[1.42,0],[1.95,2.11]],"id":70053016}],"con":true,"img":false}]}
{"op":"mcm","clk":"11541556822","pt":1719507018867,"mc":[{"id":"1.230178329","rc":[{"atl":[[4.9,0.84]],"id":64812720},{"atl":[[4.3,0.84]],"id":70053016}],"con":true,"img":false}]}
{"op":"mcm","clk":"11541556830","pt":1719507018969,"mc":[{"id":"1.230178329","rc":[{"atl":[[5.6,11.17],[5.2,1]],"id":70902603},{"atb":[[1.97,0]],"id":70053016},{"atl":[[3.2,0]],"id":53082422}],"con":true,"img":false}]}
{"op":"mcm","clk":"11541556838","pt":1719507019070,"mc":[{"id":"1.230178329","rc":[{"atl":[[6.4,2.5],[5.5,10]],"id":64812720},{"atb":[[2,2]],"id":70053016},{"atl":[[4.5,6],[5,2.5]],"id":70053016}],"con":true,"img":false}]}
{"op":"mcm","clk":"11541556852","pt":1719507019275,"mc":[{"id":"1.230178329","rc":[{"atl":[[3.45,2.5],[3.5,12.25]],"id":53082422}],"con":true,"img":false}]}
{"op":"mcm","clk":"11541556872","pt":1719507019481,"mc":[{"id":"1.230178329","rc":[{"atb":[[3.4,5]],"id":69942666}],"con":true,"img":false}]}
{"op":"mcm","clk":"11541556880","pt":1719507019586,"mc":[{"id":"1.230178329","rc":[{"atb":[[3.35,11.06],[3.4,0],[3.5,2]],"id":69942666}],"con":true,"img":false}]}
{"op":"mcm","clk":"11541556884","pt":1719507019681,"mc":[{"id":"1.230178329","rc":[{"atb":[[3.35,2.5],[3.5,5.56]],"id":69942666}],"con":true,"img":false}]}
{"op":"mcm","clk":"11541557364","pt":1719507025852,"mc":[{"id":"1.230178329","rc":[{"atl":[[3.25,0.84]],"id":53082422}],"con":true,"img":false}]}
{"op":"mcm","clk":"11541557470","pt":1719507027194,"mc":[{"id":"1.230178329","rc":[{"atb":[[2.98,17.5]],"id":69942666}],"con":true,"img":false}]}
{"op":"mcm","clk":"11541557488","pt":1719507027400,"mc":[{"id":"1.230178329","rc":[{"atb":[[2.98,10]],"id":69942666}],"con":true,"img":false}]}
{"op":"mcm","clk":"11541558021","pt":1719507035208,"mc":[{"id":"1.230178329","rc":[{"atl":[[3.25,4.59]],"id":53082422}],"con":true,"img":false}]}
{"op":"mcm","clk":"11541558028","pt":1719507035314,"mc":[{"id":"1.230178329","rc":[{"atl":[[4.9,5.24]],"id":64812720},{"atb":[[2,6.69]],"id":70053016},{"atl":[[4.3,5.53]],"id":70053016},{"atb":[[3.55,4.54]],"id":69942666},{"atl":[[3.3,0]],"id":53082422}],"con":true,"img":false}]}
{"op":"mcm","clk":"11541558044","pt":1719507035514,"mc":[{"id":"1.230178329","rc":[{"atl":[[5,0]],"id":64812720},{"atb":[[1.99,0]],"id":70053016},{"atl":[[4.4,0]],"id":70053016},{"atb":[[3.45,0]],"id":69942666}],"con":true,"img":false}]}
{"op":"mcm","clk":"11541558052","pt":1719507035618,"mc":[{"id":"1.230178329","rc":[{"atl":[[5,14.04]],"id":70053016}],"con":true,"img":false}]}
{"op":"mcm","clk":"11541558057","pt":1719507035720,"mc":[{"id":"1.230178329","rc":[{"atl":[[4.5,1]],"id":70053016}],"con":true,"img":false}]}
{"op":"mcm","clk":"11541558075","pt":1719507035994,"mc":[{"id":"1.230178329","rc":[{"atb":[[3.5,3.56]],"id":69942666}],"con":true,"img":false}]}
{"op":"mcm","clk":"11541558082","pt":1719507036097,"mc":[{"id":"1.230178329","rc":[{"atb":[[3.6,2],[3.35,10.6],[3.5,0]],"id":69942666}],"con":true,"img":false}]}
{"op":"mcm","clk":"11541558090","pt":1719507036199,"mc":[{"id":"1.230178329","rc":[{"atb":[[3.6,6.54],[3.35,2.5]],"id":69942666}],"con":true,"img":false}]}
{"op":"mcm","clk":"11541558099","pt":1719507036299,"mc":[{"id":"1.230178329","rc":[{"atb":[[3.6,2],[3.35,12.5]],"id":69942666}],"con":true,"img":false}]}
{"op":"mcm","clk":"11541558261","pt":1719507038810,"mc":[{"id":"1.230178329","rc":[{"atb":[[1.48,4.75]],"id":53082422}],"con":true,"img":false}]}
{"op":"mcm","clk":"11541558532","pt":1719507041902,"mc":[{"id":"1.230178329","rc":[{"atb":[[1.48,1]],"id":53082422}],"con":true,"img":false}]}
{"op":"mcm","clk":"11541558604","pt":1719507042922,"mc":[{"id":"1.230178329","rc":[{"atb":[[2.46,5.86]],"id":70902603}],"con":true,"img":false}]}
{"op":"mcm","clk":"11541558799","pt":1719507045425,"mc":[{"id":"1.230178329","rc":[{"atl":[[5.3,5]],"id":70902603}],"con":true,"img":false}]}
{"op":"mcm","clk":"11541558805","pt":1719507045526,"mc":[{"id":"1.230178329","rc":[{"atl":[[5.6,2.5],[5.3,15]],"id":70902603}],"con":true,"img":false}]}
{"op":"mcm","clk":"11541558833","pt":1719507045931,"mc":[{"id":"1.230178329","rc":[{"atb":[[2.46,2.11]],"id":70902603},{"atl":[[5.3,10]],"id":70902603}],"con":true,"img":false}]}
{"op":"mcm","clk":"11541559266","pt":1719507052125,"mc":[{"id":"1.230178329","rc":[{"atb":[[3.6,7.18]],"id":69942666}],"con":true,"img":false}]}
{"op":"mcm","clk":"11541559272","pt":1719507052241,"mc":[{"id":"1.230178329","rc":[{"atb":[[3.35,2.5],[3.65,7.18]],"id":69942666}],"con":true,"img":false}]}
{"op":"mcm","clk":"11541559277","pt":1719507052332,"mc":[{"id":"1.230178329","rc":[{"atb":[[3.55,0]],"id":69942666}],"con":true,"img":false}]}
{"op":"mcm","clk":"11541559303","pt":1719507052699,"mc":[{"id":"1.230178329","rc":[{"atb":[[3.6,5.18]],"id":69942666}],"con":true,"img":false}]}
{"op":"mcm","clk":"11541559318","pt":1719507052810,"mc":[{"id":"1.230178329","rc":[{"atb":[[3.7,2]],"id":69942666}],"con":true,"img":false}]}
{"op":"mcm","clk":"11541559856","pt":1719507060119,"mc":[{"id":"1.230178329","rc":[{"atl":[[5.1,0],[5.2,1]],"id":64812720},{"atb":[[3.25,1]],"id":69942666}],"con":true,"img":false}]}
{"op":"mcm","clk":"11541559862","pt":1719507060229,"mc":[{"id":"1.230178329","rc":[{"atb":[[2.76,0]],"id":69942666}],"con":true,"img":false}]}
{"op":"mcm","clk":"11541559981","pt":1719507062029,"mc":[{"id":"1.230178329","rc":[{"atb":[[3.25,0]],"id":69942666},{"atb":[[1.51,1],[1.48,0]],"id":53082422},{"atl":[[3.5,11.25],[3.3,1]],"id":53082422}],"con":true,"img":false}]}
{"op":"mcm","clk":"11541559989","pt":1719507062142,"mc":[{"id":"1.230178329","rc":[{"atb":[[1.51,4.75]],"id":53082422}],"con":true,"img":false}]}
{"op":"mcm","clk":"11541560008","pt":1719507062353,"mc":[{"id":"1.230178329","rc":[{"atb":[[1.5,2]],"id":53082422},{"atl":[[3.3,0],[3.5,12.25]],"id":53082422}],"con":true,"img":false}]}
{"op":"mcm","clk":"11541560033","pt":1719507062653,"mc":[{"id":"1.230178329","rc":[{"spn":2.04,"spf":1.0,"id":64812720},{"spn":3.45,"spf":"NaN","id":66686625},{"spn":3.15,"spf":"NaN","id":70053016},{"spn":6.75,"spf":"NaN","id":69942666},{"atb":[[1.5,0]],"id":53082422},{"spn":1.61,"spf":1.0,"id":53082422}],"con":true,"img":false}]}
{"op":"mcm","clk":"11541560046","pt":1719507062718,"mc":[{"id":"1.230178329","rc":[{"atb":[[1.52,2]],"id":53082422}],"con":true,"img":false}]}
{"op":"mcm","clk":"11541560073","pt":1719507063041,"mc":[{"id":"1.230178329","rc":[{"atl":[[3.4,1],[3.5,11.25]],"id":53082422}],"con":true,"img":false}]}
{"op":"mcm","clk":"11541560120","pt":1719507063713,"mc":[{"id":"1.230178329","rc":[{"atb":[[3.25,1]],"id":69942666},{"atb":[[1.51,3.75],[1.48,1]],"id":53082422}],"con":true,"img":false}]}
{"op":"mcm","clk":"11541560340","pt":1719507066553,"mc":[{"id":"1.230178329","rc":[{"atb":[[3.55,2.5]],"id":69942666}],"con":true,"img":false}]}
{"op":"mcm","clk":"11541560345","pt":1719507066618,"mc":[{"id":"1.230178329","rc":[{"atb":[[1.92,0],[1.97,2.5],[1.88,0],[1.96,0],[1.93,5]],"id":70053016},{"atb":[[2.98,0]],"id":69942666}],"con":true,"img":false}]}
{"op":"mcm","clk":"11541560380","pt":1719507067132,"mc":[{"id":"1.230178329","rc":[{"atb":[[1.02,1.7]],"id":66686625},{"atb":[[1.01,1.7]],"id":70053016},{"atl":[[1000,1.87]],"id":70053016},{"atb":[[1.01,1.7]],"id":53082422},{"atl":[[1000,1.7]],"id":53082422}],"con":true,"img":false}]}
{"op":"mcm","clk":"11541560388","pt":1719507067228,"mc":[{"id":"1.230178329","rc":[{"atl":[[1000,1.7]],"id":66686625}],"con":true,"img":false}]}
{"op":"mcm","clk":"11541560399","pt":1719507067339,"mc":[{"id":"1.230178329","rc":[{"atl":[[4.9,6.24],[5.2,0]],"id":64812720},{"atl":[[4.8,1],[5.2,0]],"id":70902603},{"atb":[[1.02,0.22]],"id":66686625},{"atb":[[1.01,0.28]],"id":70053016},{"atl":[[4.5,0],[3.95,1],[1000,0.26]],"id":70053016},{"atb":[[1.01,0.55]],"id":53082422},{"atl":[[1000,0.13]],"id":53082422}],"con":true,"img":false}]}
{"op":"mcm","clk":"11541560408","pt":1719507067460,"mc":[{"id":"1.230178329","rc":[{"atl":[[4.9,3.46]],"id":70902603},{"atl":[[1000,0.08]],"id":66686625},{"atl":[[4.5,11.08],[5,2.5],[4.2,3.46]],"id":70053016}],"con":true,"img":false}]}
{"op":"mcm","clk":"11541560417","pt":1719507067551,"mc":[{"id":"1.230178329","rc":[{"atl":[[6.4,18.75],[5.5,0]],"id":64812720},{"atl":[[5,8.95],[5.3,0]],"id":70902603},{"atb":[[1.02,0]],"id":66686625},{"atb":[[1.01,0]],"id":70053016},{"atl":[[4.3,0.84],[5,12.5],[1000,0.16]],"id":70053016},{"atb":[[1.01,0]],"id":53082422},{"atl":[[1000,0]],"id":53082422}],"con":true,"img":false}]}
{"op":"mcm","clk":"11541560423","pt":1719507067652,"mc":[{"id":"1.230178329","rc":[{"atl":[[5,5.32]],"id":70902603},{"atb":[[2.32,0.22]],"id":66686625},{"atl":[[1000,0]],"id":66686625},{"atb":[[2.02,0.28]],"id":70053016},{"atl":[[4.3,6.38],[4.5,0],[4.2,3.55]],"id":70053016},{"atb":[[1.53,0.55]],"id":53082422},{"atl":[[3.2,0.13]],"id":53082422}],"con":true,"img":false}]}
{"op":"mcm","clk":"11541560435","pt":1719507067757,"mc":[{"id":"1.230178329","rc":[{"atl":[[4.6,1.58]],"id":66686625},{"atl":[[5,2.5]],"id":70053016},{"atl":[[3.2,2.38],[3.4,5.73],[3.5,0]],"id":53082422}],"con":true,"img":false}]}
{"op":"mcm","clk":"11541560446","pt":1719507067866,"mc":[{"id":"1.230178329","rc":[{"atl":[[3.25,0.84]],"id":53082422}],"con":true,"img":false}]}
{"op":"mcm","clk":"11541560504","pt":1719507068322,"mc":[{"id":"1.230178329","rc":[{"atl":[[3.15,0.84]],"id":53082422}],"con":true,"img":false}]}
{"op":"mcm","clk":"11541560517","pt":1719507068448,"mc":[{"id":"1.230178329","rc":[{"atl":[[3.4,0.99],[3.25,4.07]],"id":53082422}],"con":true,"img":false}]}
{"op":"mcm","clk":"11541560533","pt":1719507068640,"mc":[{"id":"1.230178329","rc":[{"atb":[[3.75,5.18]],"id":69942666}],"con":true,"img":false}]}
{"op":"mcm","clk":"11541560548","pt":1719507068847,"mc":[{"id":"1.230178329","rc":[{"atb":[[3.6,0]],"id":69942666}],"con":true,"img":false}]}
{"op":"mcm","clk":"11541560567","pt":1719507069154,"mc":[{"id":"1.230178329","rc":[{"atl":[[4.8,1],[4.7,0]],"id":66686625}],"con":true,"img":false}]}
{"op":"mcm","clk":"11541560572","pt":1719507069249,"mc":[{"id":"1.230178329","rc":[{"atl":[[4.8,6],[4.6,0.08],[5.7,2.5]],"id":66686625},{"atb":[[3.7,0]],"id":69942666}],"con":true,"img":false}]}
{"op":"mcm","clk":"11541560579","pt":1719507069363,"mc":[{"id":"1.230178329","rc":[{"atl":[[4.5,3.06]],"id":66686625},{"atb":[[3.8,2],[3.55,14.86],[3.75,0]],"id":69942666}],"con":true,"img":false}]}
{"op":"mcm","clk":"11541560588","pt":1719507069424,"mc":[{"id":"1.230178329","rc":[{"atb":[[3.7,5.18],[3.65,0]],"id":69942666}],"con":true,"img":false}]}
{"op":"mcm","clk":"11541560596","pt":1719507069527,"mc":[{"id":"1.230178329","rc":[{"atb":[[2.4,0],[2.48,11.25]],"id":64812720},{"atb":[[2.3,10]],"id":70902603},{"atb":[[2.14,5],[2.08,0]],"id":66686625},{"atl":[[3.95,0]],"id":70053016},{"atb":[[1.44,0]],"id":53082422},{"atl":[[3.4,0]],"id":53082422}],"con":true,"img":false}]}
{"op":"mcm","clk":"11541560601","pt":1719507069623,"mc":[{"id":"1.230178329","rc":[{"atb":[[2.26,0]],"id":70902603},{"atl":[[4.8,0],[4.9,4.46]],"id":70902603},{"atb":[[1.89,5],[1.85,0]],"id":70053016},{"atl":[[4,1],[4.3,0.84]],"id":70053016},{"atb":[[1.47,7.11]],"id":53082422},{"atl":[[3.3,1]],"id":53082422}],"con":true,"img":false}]}
{"op":"mcm","clk":"11541560613","pt":1719507069728,"mc":[{"id":"1.230178329","rc":[{"atl":[[5,12.44]],"id":70053016}],"con":true,"img":false}]}
{"op":"mcm","clk":"11541560619","pt":1719507069841,"mc":[{"id":"1.230178329","rc":[{"atl":[[4.8,0.84]],"id":70902603},{"atl":[[4.4,0.84]],"id":66686625},{"atl":[[4.3,5.39],[5,2.5]],"id":70053016}],"con":true,"img":false}]}
{"op":"mcm","clk":"11541560634","pt":1719507070045,"mc":[{"id":"1.230178329","rc":[{"atb":[[3.8,0]],"id":69942666}],"con":true,"img":false}]}
{"op":"mcm","clk":"11541560641","pt":1719507070132,"mc":[{"id":"1.230178329","rc":[{"atb":[[3.75,2]],"id":69942666}],"con":true,"img":false}]}
{"op":"mcm","clk":"11541560650","pt":1719507070248,"mc":[{"id":"1.230178329","rc":[{"atb":[[3.7,0],[3.8,5.18]],"id":69942666}],"con":true,"img":false}]}
{"op":"mcm","clk":"11541560684","pt":1719507070641,"mc":[{"id":"1.230178329","rc":[{"atl":[[3.2,3.38],[3.3,0]],"id":53082422}],"con":true,"img":false}]}
{"op":"mcm","clk":"11541560719","pt":1719507071159,"mc":[{"id":"1.230178329","rc":[{"atb":[[3.75,0]],"id":69942666}],"con":true,"img":false}]}
{"op":"mcm","clk":"11541560728","pt":1719507071228,"mc":[{"id":"1.230178329","rc":[{"atl":[[5,1],[4.9,5.24]],"id":64812720},{"atb":[[3.85,2]],"id":69942666}],"con":true,"img":false}]}
{"op":"mcm","clk":"11541560732","pt":1719507071326,"mc":[{"id":"1.230178329","rc":[{"atb":[[2.56,10],[2.72,2.5],[2.5,0],[2.66,3.75],[2.64,7.11],[2.58,0]],"id":64812720},{"atl":[[5.6,0],[5.5,2.5],[6,0],[6.8,0]],"id":70902603},{"atl":[[4.8,5],[6.2,0],[4.9,1],[5.7,0],[7,0]],"id":66686625},{"atl":[[5,0],[5.8,0],[4.9,2.5],[5.4,0]],"id":70053016},{"atb":[[3.8,0],[3.9,5.18]],"id":69942666}],"con":true,"img":false}]}
{"op":"mcm","clk":"11541560741","pt":1719507071435,"mc":[{"id":"1.230178329","rc":[{"atb":[[2.72,9.25]],"id":64812720}],"con":true,"img":false}]}
{"op":"mcm","clk":"11541560756","pt":1719507071640,"mc":[{"id":"1.230178329","rc":[{"atb":[[2.66,0]],"id":64812720}],"con":true,"img":false}]}
{"op":"mcm","clk":"11541560773","pt":1719507071849,"mc":[{"id":"1.230178329","rc":[{"atb":[[3.85,0]],"id":69942666}],"con":true,"img":false}]}
{"op":"mcm","clk":"11541560781","pt":1719507071938,"mc":[{"id":"1.230178329","rc":[{"atb":[[1.02,2]],"id":69942666}],"con":true,"img":false}]}
{"op":"mcm","clk":"11541560792","pt":1719507072048,"mc":[{"id":"1.230178329","rc":[{"atb":[[3.9,0]],"id":69942666}],"con":true,"img":false}]}
{"op":"mcm","clk":"11541560807","pt":1719507072250,"mc":[{"id":"1.230178329","rc":[{"atb":[[3.6,5.18]],"id":69942666}],"con":true,"img":false}]}
{"op":"mcm","clk":"11541560845","pt":1719507072627,"mc":[{"id":"1.230178329","rc":[{"atb":[[1.02,0]],"id":69942666}],"con":true,"img":false}]}
{"op":"mcm","clk":"11541560854","pt":1719507072729,"mc":[{"id":"1.230178329","rc":[{"atb":[[3.65,2]],"id":69942666}],"con":true,"img":false}]}
{"op":"mcm","clk":"11541561129","pt":1719507076133,"mc":[{"id":"1.230178329","rc":[{"atb":[[3.25,0]],"id":69942666}],"con":true,"img":false}]}
{"op":"mcm","clk":"11541561184","pt":1719507076868,"mc":[{"id":"1.230178329","rc":[{"atl":[[4.8,0],[4.6,3.99]],"id":66686625}],"con":true,"img":false}]}
{"op":"mcm","clk":"11541561194","pt":1719507076975,"mc":[{"id":"1.230178329","rc":[{"atb":[[3.55,2.5],[3.65,7.18]],"id":69942666}],"con":true,"img":false}]}
{"op":"mcm","clk":"11541561210","pt":1719507077132,"mc":[{"id":"1.230178329","rc":[{"atb":[[2.52,18.5],[2.48,0]],"id":64812720}],"con":true,"img":false}]}
{"op":"mcm","clk":"11541561226","pt":1719507077337,"mc":[{"id":"1.230178329","rc":[{"atl":[[5,0],[5.2,1]],"id":64812720},{"atl":[[4.9,3.46],[5.2,1]],"id":70902603},{"atl":[[4.9,0],[4.7,1]],"id":66686625},{"atl":[[4,0],[4.5,1]],"id":70053016}],"con":true,"img":false}]}
{"op":"mcm","clk":"11541561240","pt":1719507077438,"mc":[{"id":"1.230178329","rc":[{"atl":[[6.4,2.5],[5.7,10]],"id":64812720}],"con":true,"img":false}]}
{"op":"mcm","clk":"11541561272","pt":1719507077851,"mc":[{"id":"1.230178329","rc":[{"atl":[[4.1,0.84]],"id":70053016}],"con":true,"img":false}]}
{"op":"mcm","clk":"11541561319","pt":1719507078424,"mc":[{"id":"1.230178329","rc":[{"atb":[[1.52,6.04]],"id":53082422}],"con":true,"img":false}]}
{"op":"mcm","clk":"11541561340","pt":1719507078632,"mc":[{"id":"1.230178329","rc":[{"atb":[[1.51,0]],"id":53082422}],"con":true,"img":false}]}
{"op":"mcm","clk":"11541561485","pt":1719507080648,"mc":[{"id":"1.230178329","rc":[{"atl":[[3.2,2.38],[3.5,1]],"id":53082422}],"con":true,"img":false}]}
{"op":"mcm","clk":"11541561664","pt":1719507083137,"mc":[{"id":"1.230178329","rc":[{"atb":[[2.12,0],[2.26,7.11],[2.14,0],[2.34,2.5],[2.28,0],[2.18,5],[2.2,0]],"id":66686625},{"atb":[[1.42,7.5],[1.47,2.11]],"id":53082422},{"atl":[[3.45,0],[3.85,0],[3.35,2.5],[3.65,0]],"id":53082422}],"con":true,"img":false}]}
{"op":"mcm","clk":"11541561675","pt":1719507083239,"mc":[{"id":"1.230178329","rc":[{"atb":[[2.34,6.67]],"id":66686625},{"atb":[[1.44,7.5],[1.42,0]],"id":53082422}],"con":true,"img":false}]}
{"op":"mcm","clk":"11541561695","pt":1719507083443,"mc":[{"id":"1.230178329","rc":[{"atb":[[2.3,2]],"id":66686625}],"con":true,"img":false}]}
{"op":"mcm","clk":"11541561718","pt":1719507083660,"mc":[{"id":"1.230178329","rc":[{"atl":[[4.8,5.31]],"id":70902603},{"atb":[[2.36,2.11],[2.26,5]],"id":66686625},{"atl":[[4.1,5.38]],"id":70053016}],"con":true,"img":false}]}
{"op":"mcm","clk":"11541561729","pt":1719507083757,"mc":[{"id":"1.230178329","rc":[{"atl":[[5,0.84],[4.7,5.32]],"id":70902603},{"atb":[[2.3,0]],"id":66686625},{"atl":[[4,5.39],[4.3,0.84]],"id":70053016}],"con":true,"img":false}]}
{"op":"mcm","clk":"11541561741","pt":1719507083862,"mc":[{"id":"1.230178329","rc":[{"atl":[[4.9,0]],"id":70902603},{"atb":[[2.36,4.11]],"id":66686625},{"atl":[[4.2,0.09]],"id":70053016}],"con":true,"img":false}]}
{"op":"mcm","clk":"11541561751","pt":1719507083958,"mc":[{"id":"1.230178329","rc":[{"atl":[[3.15,4.5]],"id":53082422}],"con":true,"img":false}]}
{"op":"mcm","clk":"11541561771","pt":1719507084166,"mc":[{"id":"1.230178329","rc":[{"atl":[[3.2,0.13]],"id":53082422}],"con":true,"img":false}]}
{"op":"mcm","clk":"11541561794","pt":1719507084324,"mc":[{"id":"1.230178329","rc":[{"atl":[[4.6,0.84]],"id":70902603}],"con":true,"img":false}]}
{"op":"mcm","clk":"11541561802","pt":1719507084427,"mc":[{"id":"1.230178329","rc":[{"atl":[[5,0]],"id":70902603},{"atl":[[4.3,0]],"id":70053016},{"atl":[[3.25,3.23]],"id":53082422}],"con":true,"img":false}]}
{"op":"mcm","clk":"11541561837","pt":1719507084840,"mc":[{"id":"1.230178329","rc":[{"atl":[[3.95,0.84]],"id":70053016},{"atb":[[3.7,5.18]],"id":69942666}],"con":true,"img":false}]}
{"op":"mcm","clk":"11541561852","pt":1719507085045,"mc":[{"id":"1.230178329","rc":[{"atb":[[3.6,0]],"id":69942666}],"con":true,"img":false}]}
{"op":"mcm","clk":"11541561891","pt":1719507085461,"mc":[{"id":"1.230178329","rc":[{"atl":[[4.4,6.13]],"id":66686625}],"con":true,"img":false}]}
{"op":"mcm","clk":"11541561903","pt":1719507085669,"mc":[{"id":"1.230178329","rc":[{"atl":[[4.5,0]],"id":66686625}],"con":true,"img":false}]}
{"op":"mcm","clk":"11541561907","pt":1719507085771,"mc":[{"id":"1.230178329","rc":[{"atl":[[6,2.5],[6.8,5],[7.6,10]],"id":66686625}],"con":true,"img":false}]}
{"op":"mcm","clk":"11541561912","pt":1719507085873,"mc":[{"id":"1.230178329","rc":[{"atl":[[4.6,0.08],[4.7,11.13]],"id":66686625},{"atb":[[3.65,5.18]],"id":69942666}],"con":true,"img":false}]}
{"op":"mcm","clk":"11541561921","pt":1719507085939,"mc":[{"id":"1.230178329","rc":[{"atb":[[3.55,12.86],[3.65,0],[3.75,2]],"id":69942666}],"con":true,"img":false}]}
{"op":"mcm","clk":"11541561926","pt":1719507086029,"mc":[{"id":"1.230178329","rc":[{"atb":[[3.8,5.18],[2.84,1],[2.76,1]],"id":69942666}],"con":true,"img":false}]}
{"op":"mcm","clk":"11541561934","pt":1719507086134,"mc":[{"id":"1.230178329","rc":[{"atb":[[3.7,0]],"id":69942666}],"con":true,"img":false}]}
{"op":"mcm","clk":"11541561966","pt":1719507086650,"mc":[{"id":"1.230178329","rc":[{"atb":[[3.75,0]],"id":69942666}],"con":true,"img":false}]}
{"op":"mcm","clk":"11541561977","pt":1719507086754,"mc":[{"id":"1.230178329","rc":[{"atb":[[3.85,2],[3.8,0],[2.84,0],[2.76,0]],"id":69942666}],"con":true,"img":false}]}
{"op":"mcm","clk":"11541561985","pt":1719507086856,"mc":[{"id":"1.230178329","rc":[{"atb":[[3.9,3.38]],"id":69942666}],"con":true,"img":false}]}
{"op":"mcm","clk":"11541561998","pt":1719507087065,"mc":[{"id":"1.230178329","rc":[{"atb":[[1.48,8.16]],"id":53082422}],"con":true,"img":false}]}
{"op":"mcm","clk":"11541562010","pt":1719507087272,"mc":[{"id":"1.230178329","rc":[{"atb":[[1.48,1]],"id":53082422}],"con":true,"img":false}]}
{"op":"mcm","clk":"11541562031","pt":1719507087534,"mc":[{"id":"1.230178329","rc":[{"atb":[[3.85,0]],"id":69942666}],"con":true,"img":false}]}
{"op":"mcm","clk":"11541562041","pt":1719507087637,"mc":[{"id":"1.230178329","rc":[{"atb":[[1.02,2],[3.9,0],[2.76,1]],"id":69942666}],"con":true,"img":false}]}
{"op":"mcm","clk":"11541562048","pt":1719507087740,"mc":[{"id":"1.230178329","rc":[{"atb":[[3.6,4.41]],"id":69942666}],"con":true,"img":false}]}
{"op":"mcm","clk":"11541562095","pt":1719507088257,"mc":[{"id":"1.230178329","rc":[{"atb":[[1.02,0]],"id":69942666}],"con":true,"img":false}]}
{"op":"mcm","clk":"11541562104","pt":1719507088359,"mc":[{"id":"1.230178329","rc":[{"atb":[[3.65,2]],"id":69942666}],"con":true,"img":false}]}
{"op":"mcm","clk":"11541562116","pt":1719507088462,"mc":[{"id":"1.230178329","rc":[{"atb":[[3.7,5.18]],"id":69942666}],"con":true,"img":false}]}
{"op":"mcm","clk":"11541562136","pt":1719507088669,"mc":[{"id":"1.230178329","rc":[{"atb":[[3.6,0]],"id":69942666}],"con":true,"img":false}]}
{"op":"mcm","clk":"11541562153","pt":1719507088875,"mc":[{"id":"1.230178329","rc":[{"atl":[[4.8,11.48]],"id":70902603},{"atl":[[4,0]],"id":70053016},{"atb":[[3.65,0]],"id":69942666}],"con":true,"img":false}]}
{"op":"mcm","clk":"11541562164","pt":1719507088977,"mc":[{"id":"1.230178329","rc":[{"atl":[[4.7,0]],"id":70902603},{"atl":[[4.1,11.62]],"id":70053016},{"atb":[[3.75,2]],"id":69942666}],"con":true,"img":false}]}
{"op":"mcm","clk":"11541562170","pt":1719507089031,"mc":[{"id":"1.230178329","rc":[{"atl":[[4.2,12.57]],"id":70053016},{"atb":[[3.7,0],[3.8,5.18]],"id":69942666}],"con":true,"img":false}]}
{"op":"mcm","clk":"11541562180","pt":1719507089136,"mc":[{"id":"1.230178329","rc":[{"atl":[[4.1,5.38]],"id":70053016}],"con":true,"img":false}]}
{"op":"mcm","clk":"11541562207","pt":1719507089448,"mc":[{"id":"1.230178329","rc":[{"atl":[[4.6,0]],"id":70902603},{"atl":[[3.95,0]],"id":70053016},{"atb":[[3.75,0]],"id":69942666}],"con":true,"img":false}]}
{"op":"mcm","clk":"11541562212","pt":1719507089546,"mc":[{"id":"1.230178329","rc":[{"atb":[[3.85,2]],"id":69942666}],"con":true,"img":false}]}
{"op":"mcm","clk":"11541562220","pt":1719507089648,"mc":[{"id":"1.230178329","rc":[{"atl":[[4.8,5.31],[5.5,14.99]],"id":70902603},{"atl":[[4.5,18.96],[4.2,0.09]],"id":70053016},{"atb":[[3.8,0],[3.9,5.18]],"id":69942666}],"con":true,"img":false}]}
{"op":"mcm","clk":"11541562255","pt":1719507090163,"mc":[{"id":"1.230178329","rc":[{"atb":[[3.85,0]],"id":69942666}],"con":true,"img":false}]}
{"op":"mcm","clk":"11541562264","pt":1719507090266,"mc":[{"id":"1.230178329","rc":[{"atb":[[1.02,2],[3.9,0]],"id":69942666}],"con":true,"img":false}]}
{"op":"mcm","clk":"11541562270","pt":1719507090369,"mc":[{"id":"1.230178329","rc":[{"atb":[[3.6,3.75]],"id":69942666}],"con":true,"img":false}]}
{"op":"mcm","clk":"11541562294","pt":1719507090679,"mc":[{"id":"1.230178329","rc":[{"atl":[[3.4,1],[3.5,0]],"id":53082422}],"con":true,"img":false}]}
{"op":"mcm","clk":"11541562332","pt":1719507091042,"mc":[{"id":"1.230178329","rc":[{"atb":[[3.35,19.11],[1.02,0],[2.84,1],[2.76,0]],"id":69942666}],"con":true,"img":false}]}
{"op":"mcm","clk":"11541562339","pt":1719507091143,"mc":[{"id":"1.230178329","rc":[{"atb":[[3.55,2.5],[3.65,2]],"id":69942666}],"con":true,"img":false}]}
{"op":"mcm","clk":"11541562488","pt":1719507093456,"mc":[{"id":"1.230178329","rc":[{"atb":[[3.65,4.5]],"id":69942666}],"con":true,"img":false}]}
{"op":"mcm","clk":"11541562501","pt":1719507093564,"mc":[{"id":"1.230178329","rc":[{"atb":[[3.35,2.5]],"id":69942666}],"con":true,"img":false}]}
{"op":"mcm","clk":"11541562693","pt":1719507096253,"mc":[{"id":"1.230178329","rc":[{"atb":[[2.52,28.5],[2.6,5],[2.68,2.5]],"id":64812720}],"con":true,"img":false}]}
{"op":"mcm","clk":"11541562703","pt":1719507096354,"mc":[{"id":"1.230178329","rc":[{"atb":[[2.56,0],[2.72,6.75],[2.64,2.11]],"id":64812720}],"con":true,"img":false}]}
{"op":"mcm","clk":"11541562711","pt":1719507096456,"mc":[{"id":"1.230178329","rc":[{"atb":[[2.72,0]],"id":64812720}],"con":true,"img":false}]}
{"op":"mcm","clk":"11541562714","pt":1719507096557,"mc":[{"id":"1.230178329","rc":[{"atb":[[2.7,5.81]],"id":64812720}],"con":true,"img":false}]}
{"op":"mcm","clk":"11541562919","pt":1719507099087,"mc":[{"id":"1.230178329","rc":[{"atb":[[2.36,11.81]],"id":66686625}],"con":true,"img":false}]}
{"op":"mcm","clk":"11541562928","pt":1719507099245,"mc":[{"id":"1.230178329","rc":[{"atb":[[2.34,2.5]],"id":66686625}],"con":true,"img":false}]}
{"op":"mcm","clk":"11541563029","pt":1719507100688,"mc":[{"id":"1.230178329","rc":[{"atb":[[3.7,4.69]],"id":69942666}],"con":true,"img":false}]}
{"op":"mcm","clk":"11541563035","pt":1719507100788,"mc":[{"id":"1.230178329","rc":[{"atb":[[3.75,4.5],[3.65,2]],"id":69942666}],"con":true,"img":false}]}
{"op":"mcm","clk":"11541563043","pt":1719507100891,"mc":[{"id":"1.230178329","rc":[{"atb":[[3.6,0]],"id":69942666}],"con":true,"img":false}]}
{"op":"mcm","clk":"11541563096","pt":1719507101564,"mc":[{"id":"1.230178329","rc":[{"atb":[[2.32,0]],"id":66686625},{"atl":[[4.6,0]],"id":66686625},{"atb":[[2.02,0]],"id":70053016},{"atl":[[4.2,0]],"id":70053016},{"atb":[[3.65,0]],"id":69942666},{"atb":[[1.53,0]],"id":53082422},{"atl":[[3.2,0]],"id":53082422}],"con":true,"img":false}]}
{"op":"mcm","clk":"11541563103","pt":1719507101668,"mc":[{"id":"1.230178329","rc":[{"atb":[[3.8,2]],"id":69942666}],"con":true,"img":false}]}
{"op":"mcm","clk":"11541563110","pt":1719507101772,"mc":[{"id":"1.230178329","rc":[{"atl":[[6,19.77],[4.7,0.99]],"id":66686625},{"atl":[[4.5,1],[4.9,26.85]],"id":70053016},{"atl":[[3.35,10.24],[3.25,0]],"id":53082422}],"con":true,"img":false}]}
{"op":"mcm","clk":"11541563120","pt":1719507101879,"mc":[{"id":"1.230178329","rc":[{"atb":[[3.85,5.18]],"id":69942666}],"con":true,"img":false}]}
{"op":"mcm","clk":"11541563129","pt":1719507101977,"mc":[{"id":"1.230178329","rc":[{"atb":[[3.7,0]],"id":69942666}],"con":true,"img":false}]}
{"op":"mcm","clk":"11541563145","pt":1719507102184,"mc":[{"id":"1.230178329","rc":[{"atl":[[4.7,0]],"id":66686625},{"atl":[[3.35,11.24],[3.4,0]],"id":53082422}],"con":true,"img":false}]}
{"op":"mcm","clk":"11541563156","pt":1719507102292,"mc":[{"id":"1.230178329","rc":[{"atl":[[4.8,1]],"id":66686625},{"atb":[[1.44,8.5],[1.48,0]],"id":53082422},{"atl":[[3.35,3.5],[3.4,15.75]],"id":53082422}],"con":true,"img":false}]}
{"op":"mcm","clk":"11541563166","pt":1719507102390,"mc":[{"id":"1.230178329","rc":[{"atb":[[2.52,10],[2.58,7.5]],"id":64812720},{"atl":[[4.8,13.28],[6,2.5]],"id":66686625}],"con":true,"img":false}]}
{"op":"mcm","clk":"11541563176","pt":1719507102494,"mc":[{"id":"1.230178329","rc":[{"atb":[[3.8,0]],"id":69942666}],"con":true,"img":false}]}
{"op":"mcm","clk":"11541563185","pt":1719507102595,"mc":[{"id":"1.230178329","rc":[{"atb":[[3.9,2]],"id":69942666}],"con":true,"img":false}]}
{"op":"mcm","clk":"11541563193","pt":1719507102698,"mc":[{"id":"1.230178329","rc":[{"atb":[[3.85,0],[3.95,5.18]],"id":69942666}],"con":true,"img":false}]}
{"op":"mcm","clk":"11541563272","pt":1719507103789,"mc":[{"id":"1.230178329","rc":[{"atb":[[3.9,0]],"id":69942666}],"con":true,"img":false}]}
{"op":"mcm","clk":"11541563283","pt":1719507103892,"mc":[{"id":"1.230178329","rc":[{"atb":[[3.95,0],[1.02,2]],"id":69942666}],"con":true,"img":false}]}
{"op":"mcm","clk":"11541563291","pt":1719507103992,"mc":[{"id":"1.230178329","rc":[{"atb":[[3.85,5.18]],"id":69942666}],"con":true,"img":false}]}
{"op":"mcm","clk":"11541563304","pt":1719507104194,"mc":[{"id":"1.230178329","rc":[{"atb":[[3.85,0]],"id":69942666}],"con":true,"img":false}]}
{"op":"mcm","clk":"11541563311","pt":1719507104297,"mc":[{"id":"1.230178329","rc":[{"atb":[[3.6,3.75]],"id":69942666}],"con":true,"img":false}]}
{"op":"mcm","clk":"11541563341","pt":1719507104763,"mc":[{"id":"1.230178329","rc":[{"atb":[[3.8,4.69]],"id":69942666}],"con":true,"img":false}]}
{"op":"mcm","clk":"11541563358","pt":1719507104976,"mc":[{"id":"1.230178329","rc":[{"atb":[[3.6,0]],"id":69942666}],"con":true,"img":false}]}
{"op":"mcm","clk":"11541563366","pt":1719507105074,"mc":[{"id":"1.230178329","rc":[{"atb":[[1.02,0]],"id":69942666}],"con":true,"img":false}]}
{"op":"mcm","clk":"11541563371","pt":1719507105178,"mc":[{"id":"1.230178329","rc":[{"atb":[[3.8,6.69]],"id":69942666}],"con":true,"img":false}]}
{"op":"mcm","clk":"11541563552","pt":1719507107472,"mc":[{"id":"1.230178329","rc":[{"atl":[[4.8,1],[6,21.92]],"id":66686625}],"con":true,"img":false}]}
{"op":"mcm","clk":"11541563622","pt":1719507108495,"mc":[{"id":"1.230178329","rc":[{"atb":[[1.19,0]],"id":69942666}],"con":true,"img":false}]}
{"op":"mcm","clk":"11541563979","pt":1719507113608,"mc":[{"id":"1.230178329","rc":[{"atl":[[4.8,6.31],[5.2,0]],"id":70902603},{"atb":[[2.24,10],[2.18,0]],"id":66686625},{"atl":[[4.8,0]],"id":66686625},{"atb":[[1.89,0],[1.85,10]],"id":70053016},{"atl":[[3.95,1]],"id":70053016},{"atl":[[3.2,1],[3.35,2.5]],"id":53082422}],"con":true,"img":false}]}
{"op":"mcm","clk":"11541563986","pt":1719507113711,"mc":[{"id":"1.230178329","rc":[{"atl":[[4.8,12.63],[5.5,2.5]],"id":70902603},{"atl":[[5.1,1]],"id":66686625},{"atl":[[4.5,6.39],[4.9,2.5],[3.9,3.46]],"id":70053016}],"con":true,"img":false}]}
{"op":"mcm","clk":"11541563993","pt":1719507113816,"mc":[{"id":"1.230178329","rc":[{"atl":[[13.5,8]],"id":70902603},{"atl":[[3.2,0],[3.15,5.5]],"id":53082422}],"con":true,"img":false}]}
{"op":"mcm","clk":"11541564001","pt":1719507113875,"mc":[{"id":"1.230178329","rc":[{"atl":[[4.8,5.31],[4.9,1]],"id":70902603},{"atl":[[5,1]],"id":66686625},{"atl":[[4,1],[3.95,0],[4.1,0.84]],"id":70053016},{"atl":[[3.4,0],[3.15,11.01]],"id":53082422}],"con":true,"img":false}]}
{"op":"mcm","clk":"11541564013","pt":1719507113976,"mc":[{"id":"1.230178329","rc":[{"atl":[[5.1,8.14],[6,2.49]],"id":66686625},{"atb":[[1.44,1],[1.39,11.04]],"id":53082422},{"atl":[[3.15,10.01],[3.05,1]],"id":53082422}],"con":true,"img":false}]}
{"op":"mcm","clk":"11541564025","pt":1719507114080,"mc":[{"id":"1.230178329","rc":[{"atl":[[3.1,3.75]],"id":53082422}],"con":true,"img":false}]}
{"op":"mcm","clk":"11541564044","pt":1719507114287,"mc":[{"id":"1.230178329","rc":[{"atl":[[3.15,6.35]],"id":53082422}],"con":true,"img":false}]}
{"op":"mcm","clk":"11541564054","pt":1719507114390,"mc":[{"id":"1.230178329","rc":[{"atl":[[3.85,0.84],[4.1,0]],"id":70053016}],"con":true,"img":false}]}
{"op":"mcm","clk":"11541564157","pt":1719507116101,"mc":[{"id":"1.230178329","rc":[{"atb":[[1.9,6.58]],"id":70053016}],"con":true,"img":false}]}
{"op":"mcm","clk":"11541564192","pt":1719507117319,"mc":[{"id":"1.230178329","rc":[{"atb":[[1.41,24.44]],"id":53082422}],"con":true,"img":false}]}
{"op":"mcm","clk":"11541564509","pt":1719507120899,"mc":[{"id":"1.230178329","rc":[{"atl":[[4,5.31],[4.5,0]],"id":70053016}],"con":true,"img":false}]}
{"op":"mcm","clk":"11541564519","pt":1719507120998,"mc":[{"id":"1.230178329","rc":[{"atl":[[5.5,8.82],[13.5,0]],"id":70902603}],"con":true,"img":false}]}
{"op":"mcm","clk":"11541564743","pt":1719507123911,"mc":[{"id":"1.230178329","rc":[{"spn":2.37,"spf":1.0,"id":64812720},{"spn":3.65,"spf":"NaN","id":70902603},{"atl":[[5,0]],"id":66686625},{"spn":3.38,"spf":"NaN","id":66686625},{"spn":2.92,"spf":"NaN","id":70053016},{"spn":6.8,"spf":"NaN","id":69942666},{"spn":1.61,"spf":1.0,"id":53082422}],"con":true,"img":false}]}
{"op":"mcm","clk":"11541565090","pt":1719507129010,"mc":[{"id":"1.230178329","rc":[{"atl":[[3.85,5.31]],"id":70053016}],"con":true,"img":false}]}
{"op":"mcm","clk":"11541565106","pt":1719507129220,"mc":[{"id":"1.230178329","rc":[{"atl":[[3.9,0]],"id":70053016}],"con":true,"img":false}]}
{"op":"mcm","clk":"11541565116","pt":1719507129323,"mc":[{"id":"1.230178329","rc":[{"atl":[[3,4.69]],"id":53082422}],"con":true,"img":false}]}
{"op":"mcm","clk":"11541565125","pt":1719507129426,"mc":[{"id":"1.230178329","rc":[{"atl":[[3.15,0.84],[2.98,3.75]],"id":53082422}],"con":true,"img":false}]}
{"op":"mcm","clk":"11541565132","pt":1719507129527,"mc":[{"id":"1.230178329","rc":[{"atl":[[3.1,0]],"id":53082422}],"con":true,"img":false}]}
{"op":"mcm","clk":"11541565140","pt":1719507129627,"mc":[{"id":"1.230178329","rc":[{"atl":[[2.98,0],[3.05,9.44]],"id":53082422}],"con":true,"img":false}]}
{"op":"mcm","clk":"11541565149","pt":1719507129832,"mc":[{"id":"1.230178329","rc":[{"atl":[[2.98,0.84]],"id":53082422}],"con":true,"img":false}]}
{"op":"mcm","clk":"11541565152","pt":1719507129937,"mc":[{"id":"1.230178329","rc":[{"atl":[[3.15,0]],"id":53082422}],"con":true,"img":false}]}
{"op":"mcm","clk":"11541565424","pt":1719507133310,"mc":[{"id":"1.230178329","rc":[{"atl":[[4.8,6.31],[4.9,0]],"id":70902603},{"atb":[[1.44,0]],"id":53082422}],"con":true,"img":false}]}
{"op":"mcm","clk":"11541565434","pt":1719507133514,"mc":[{"id":"1.230178329","rc":[{"atl":[[5.5,2.5],[13.5,8]],"id":70902603}],"con":true,"img":false}]}
{"op":"mcm","clk":"11541565694","pt":1719507137507,"mc":[{"id":"1.230178329","rc":[{"atl":[[5.2,1.57]],"id":70902603}],"con":true,"img":false}]}
{"op":"mcm","clk":"11541565701","pt":1719507137606,"mc":[{"id":"1.230178329","rc":[{"atl":[[5.2,14.21]],"id":70902603}],"con":true,"img":false}]}
{"op":"mcm","clk":"11541565711","pt":1719507137717,"mc":[{"id":"1.230178329","rc":[{"atl":[[5.5,10.39],[13.5,0]],"id":70902603}],"con":true,"img":false}]}
{"op":"mcm","clk":"11541565716","pt":1719507137812,"mc":[{"id":"1.230178329","rc":[{"atl":[[5.2,1.57]],"id":70902603}],"con":true,"img":false}]}
{"op":"mcm","clk":"11541565725","pt":1719507137938,"mc":[{"id":"1.230178329","rc":[{"atl":[[5.5,2.5],[5.2,14.21]],"id":70902603}],"con":true,"img":false}]}
{"op":"mcm","clk":"11541565733","pt":1719507138041,"mc":[{"id":"1.230178329","rc":[{"atl":[[5.5,10.39],[5.2,1.57]],"id":70902603}],"con":true,"img":false}]}
{"op":"mcm","clk":"11541565741","pt":1719507138145,"mc":[{"id":"1.230178329","rc":[{"atl":[[5.2,14.21]],"id":70902603}],"con":true,"img":false}]}
{"op":"mcm","clk":"11541565749","pt":1719507138198,"mc":[{"id":"1.230178329","rc":[{"atl":[[5.5,2.5]],"id":70902603}],"con":true,"img":false}]}
{"op":"mcm","clk":"11541565803","pt":1719507139222,"mc":[{"id":"1.230178329","rc":[{"atl":[[5.2,12.64]],"id":70902603}],"con":true,"img":false}]}
{"op":"mcm","clk":"11541565821","pt":1719507139531,"mc":[{"id":"1.230178329","rc":[{"atl":[[4.9,1.57]],"id":70902603}],"con":true,"img":false}]}
{"op":"mcm","clk":"11541565837","pt":1719507139795,"mc":[{"id":"1.230178329","rc":[{"atl":[[4.9,0]],"id":70902603}],"con":true,"img":false}]}
{"op":"mcm","clk":"11541565850","pt":1719507140005,"mc":[{"id":"1.230178329","rc":[{"atl":[[4.8,7.88]],"id":70902603}],"con":true,"img":false}]}
{"op":"mcm","clk":"11541565869","pt":1719507140314,"mc":[{"id":"1.230178329","rc":[{"atl":[[4.8,6.31]],"id":70902603}],"con":true,"img":false}]}
{"op":"mcm","clk":"11541565891","pt":1719507140619,"mc":[{"id":"1.230178329","rc":[{"atl":[[4.7,1.57]],"id":70902603}],"con":true,"img":false}]}
{"op":"mcm","clk":"11541565904","pt":1719507140722,"mc":[{"id":"1.230178329","rc":[{"atl":[[5.3,1],[5.2,0]],"id":64812720},{"atl":[[4.8,5.31],[4.6,6.1],[4.9,1]],"id":70902603},{"atl":[[5.1,7.14],[5.2,1]],"id":66686625},{"atl":[[4,4.31],[3.95,1]],"id":70053016}],"con":true,"img":false}]}
{"op":"mcm","clk":"11541565913","pt":1719507140824,"mc":[{"id":"1.230178329","rc":[{"atl":[[6.2,10.5],[5.7,0]],"id":64812720},{"atb":[[2.26,19.32]],"id":66686625},{"atl":[[2.92,1]],"id":53082422}],"con":true,"img":false}]}
{"op":"mcm","clk":"11541565920","pt":1719507140928,"mc":[{"id":"1.230178329","rc":[{"atl":[[4.8,0.84]],"id":70902603},{"atb":[[2.24,0]],"id":66686625},{"atl":[[3.05,8.44]],"id":53082422}],"con":true,"img":false}]}
{"op":"mcm","clk":"11541565929","pt":1719507141031,"mc":[{"id":"1.230178329","rc":[{"atb":[[2.52,0],[2.6,0],[2.62,5],[2.68,0],[2.7,8.31]],"id":64812720},{"atl":[[4,5.31],[3.95,0]],"id":70053016}],"con":true,"img":false}]}
{"op":"mcm","clk":"11541565934","pt":1719507141134,"mc":[{"id":"1.230178329","rc":[{"atb":[[2.6,7.5],[2.58,0]],"id":64812720},{"atl":[[4,1],[4.9,13.13]],"id":70053016}],"con":true,"img":false}]}
{"op":"mcm","clk":"11541565945","pt":1719507141339,"mc":[{"id":"1.230178329","rc":[{"atl":[[4.5,0.84]],"id":70902603}],"con":true,"img":false}]}
{"op":"mcm","clk":"11541565951","pt":1719507141392,"mc":[{"id":"1.230178329","rc":[{"atl":[[4.8,0]],"id":70902603}],"con":true,"img":false}]}
{"op":"mcm","clk":"11541565968","pt":1719507141701,"mc":[{"id":"1.230178329","rc":[{"atl":[[5.3,0],[5.2,1]],"id":64812720},{"atl":[[4.8,1],[4.9,0]],"id":70902603},{"atl":[[5.1,8.14],[5.2,0]],"id":66686625},{"atl":[[10.5,0],[11,1]],"id":69942666},{"atl":[[2.92,0],[2.94,1],[3.05,9.44]],"id":53082422}],"con":true,"img":false}]}
{"op":"mcm","clk":"11541565978","pt":1719507141806,"mc":[{"id":"1.230178329","rc":[{"atl":[[4.7,0]],"id":70902603},{"atb":[[3.6,2.5],[3.35,0],[3.4,5],[3.55,0],[3.15,0]],"id":69942666},{"atl":[[2.98,5.53],[3.05,1]],"id":53082422}],"con":true,"img":false}]}
{"op":"mcm","clk":"11541565988","pt":1719507141916,"mc":[{"id":"1.230178329","rc":[{"atl":[[10.5,1]],"id":69942666}],"con":true,"img":false}]}
{"op":"mcm","clk":"11541565993","pt":1719507142010,"mc":[{"id":"1.230178329","rc":[{"atl":[[4.5,2.41]],"id":70902603},{"atl":[[11,0]],"id":69942666}],"con":true,"img":false}]}
{"op":"mcm","clk":"11541566013","pt":1719507142320,"mc":[{"id":"1.230178329","rc":[{"atl":[[4.5,0.84]],"id":70902603}],"con":true,"img":false}]}
{"op":"mcm","clk":"11541566033","pt":1719507142629,"mc":[{"id":"1.230178329","rc":[{"atl":[[4.3,1.57]],"id":70902603}],"con":true,"img":false}]}
{"op":"mcm","clk":"11541566057","pt":1719507142940,"mc":[{"id":"1.230178329","rc":[{"atl":[[4.3,0]],"id":70902603}],"con":true,"img":false}]}
{"op":"mcm","clk":"11541566086","pt":1719507143251,"mc":[{"id":"1.230178329","rc":[{"atl":[[4.2,1.57]],"id":70902603}],"con":true,"img":false}]}
{"op":"mcm","clk":"11541566159","pt":1719507144237,"mc":[{"id":"1.230178329","rc":[{"atl":[[2.92,5.39]],"id":53082422}],"con":true,"img":false}]}
{"op":"mcm","clk":"11541566175","pt":1719507144443,"mc":[{"id":"1.230178329","rc":[{"atl":[[3,0]],"id":53082422}],"con":true,"img":false}]}
{"op":"mcm","clk":"11541566203","pt":1719507144809,"mc":[{"id":"1.230178329","rc":[{"atl":[[2.9,0.84],[2.98,4.69]],"id":53082422}],"con":true,"img":false}]}
{"op":"mcm","clk":"11541566212","pt":1719507144918,"mc":[{"id":"1.230178329","rc":[{"atl":[[4.2,0]],"id":70902603}],"con":true,"img":false}]}
{"op":"mcm","clk":"11541566218","pt":1719507145012,"mc":[{"id":"1.230178329","rc":[{"atl":[[4.8,7.95],[5.2,0]],"id":70902603},{"atb":[[2.42,2.5]],"id":66686625},{"atl":[[3.35,0],[2.94,0],[3.05,0]],"id":53082422}],"con":true,"img":false}]}
{"op":"mcm","clk":"11541566226","pt":1719507145124,"mc":[{"id":"1.230178329","rc":[{"atb":[[2.42,8.98]],"id":66686625},{"atl":[[6,16.77]],"id":66686625},{"atl":[[3.45,5],[3.25,2.5],[3.65,10]],"id":53082422}],"con":true,"img":false}]}
{"op":"mcm","clk":"11541566232","pt":1719507145220,"mc":[{"id":"1.230178329","rc":[{"atl":[[5.1,1]],"id":66686625}],"con":true,"img":false}]}
{"op":"mcm","clk":"11541566242","pt":1719507145328,"mc":[{"id":"1.230178329","rc":[{"atb":[[2.36,4.11]],"id":66686625}],"con":true,"img":false}]}
{"op":"mcm","clk":"11541566273","pt":1719507145946,"mc":[{"id":"1.230178329","rc":[{"atb":[[2.36,2.11],[1.83,0],[2.02,1]],"id":66686625}],"con":true,"img":false}]}
{"op":"mcm","clk":"11541566283","pt":1719507146049,"mc":[{"id":"1.230178329","rc":[{"atb":[[2.44,2]],"id":66686625}],"con":true,"img":false}]}
{"op":"mcm","clk":"11541566299","pt":1719507146208,"mc":[{"id":"1.230178329","rc":[{"atb":[[2.6,0],[2.58,12.5]],"id":64812720}],"con":true,"img":false}]}
{"op":"mcm","clk":"11541566688","pt":1719507152147,"mc":[{"id":"1.230178329","rc":[{"atb":[[2.5,2]],"id":70902603}],"con":true,"img":false}]}
{"op":"mcm","clk":"11541566698","pt":1719507152249,"mc":[{"id":"1.230178329","rc":[{"atb":[[2.48,5.96]],"id":70902603}],"con":true,"img":false}]}
{"op":"mcm","clk":"11541566711","pt":1719507152362,"mc":[{"id":"1.230178329","rc":[{"atl":[[3.05,1]],"id":53082422}],"con":true,"img":false}]}
{"op":"mcm","clk":"11541566876","pt":1719507154336,"mc":[{"id":"1.230178329","rc":[{"atb":[[2.4,0],[2.32,0],[2.48,0]],"id":70902603}],"con":true,"img":false}]}
{"op":"mcm","clk":"11541566884","pt":1719507154433,"mc":[{"id":"1.230178329","rc":[{"atb":[[1.81,5],[1.85,2.5],[1.77,10]],"id":70902603}],"con":true,"img":false}]}
{"op":"mcm","clk":"11541566889","pt":1719507154536,"mc":[{"id":"1.230178329","rc":[{"atb":[[1.86,2.5]],"id":70902603}],"con":true,"img":false}]}
{"op":"mcm","clk":"11541566894","pt":1719507154638,"mc":[{"id":"1.230178329","rc":[{"atb":[[1.81,0],[1.85,0],[1.77,0]],"id":70902603}],"con":true,"img":false}]}
{"op":"mcm","clk":"11541566906","pt":1719507154845,"mc":[{"id":"1.230178329","rc":[{"atb":[[2.5,0]],"id":70902603}],"con":true,"img":false}]}
{"op":"mcm","clk":"11541566911","pt":1719507154948,"mc":[{"id":"1.230178329","rc":[{"atb":[[2.48,2]],"id":70902603}],"con":true,"img":false}]}
{"op":"mcm","clk":"11541566923","pt":1719507155153,"mc":[{"id":"1.230178329","rc":[{"atl":[[5.2,0],[5.7,1]],"id":64812720},{"atb":[[2.48,9.37]],"id":70902603},{"atl":[[5,1]],"id":70902603},{"atb":[[2.02,0]],"id":66686625},{"atl":[[4.5,1]],"id":70053016},{"atb":[[2.84,0]],"id":69942666},{"atb":[[1.44,1]],"id":53082422},{"atl":[[3.35,1],[3.25,3.5],[3.05,0]],"id":53082422}],"con":true,"img":false}]}
{"op":"mcm","clk":"11541566930","pt":1719507155258,"mc":[{"id":"1.230178329","rc":[{"atb":[[2.42,13.31],[2.58,0]],"id":64812720},{"atb":[[2.48,2]],"id":70902603},{"atl":[[4.8,6.95]],"id":70902603},{"atl":[[4,0],[4.9,2.5],[4.4,6.32]],"id":70053016},{"atl":[[3.35,0]],"id":53082422}],"con":true,"img":false}]}
{"op":"mcm","clk":"11541566938","pt":1719507155360,"mc":[{"id":"1.230178329","rc":[{"atl":[[5,0]],"id":70902603}],"con":true,"img":false}]}
{"op":"mcm","clk":"11541566948","pt":1719507155466,"mc":[{"id":"1.230178329","rc":[{"atl":[[4.5,7]],"id":70902603}],"con":true,"img":false}]}
{"op":"mcm","clk":"11541566956","pt":1719507155522,"mc":[{"id":"1.230178329","rc":[{"atl":[[4.7,13.11]],"id":70902603}],"con":true,"img":false}]}
{"op":"mcm","clk":"11541566967","pt":1719507155636,"mc":[{"id":"1.230178329","rc":[{"atl":[[5.6,1]],"id":64812720},{"atl":[[4.8,1],[4.6,0],[5,1]],"id":70902603},{"atl":[[4,1]],"id":70053016},{"atb":[[1.44,0]],"id":53082422},{"atl":[[3.25,2.5],[3.05,1]],"id":53082422}],"con":true,"img":false}]}
{"op":"mcm","clk":"11541566974","pt":1719507155728,"mc":[{"id":"1.230178329","rc":[{"atl":[[5.2,1],[5.7,0]],"id":64812720},{"atl":[[4.7,0]],"id":70902603},{"atl":[[4.5,0]],"id":70053016}],"con":true,"img":false}]}
{"op":"mcm","clk":"11541566982","pt":1719507155844,"mc":[{"id":"1.230178329","rc":[{"atl":[[4.8,21.12]],"id":70902603}],"con":true,"img":false}]}
{"op":"mcm","clk":"11541566989","pt":1719507155933,"mc":[{"id":"1.230178329","rc":[{"atl":[[5,9.01]],"id":70902603}],"con":true,"img":false}]}
{"op":"mcm","clk":"11541566997","pt":1719507156040,"mc":[{"id":"1.230178329","rc":[{"atl":[[4.8,1]],"id":70902603}],"con":true,"img":false}]}
{"op":"mcm","clk":"11541567007","pt":1719507156145,"mc":[{"id":"1.230178329","rc":[{"atl":[[5.6,0]],"id":64812720}],"con":true,"img":false}]}
{"op":"mcm","clk":"11541567140","pt":1719507157755,"mc":[{"id":"1.230178329","rc":[{"atb":[[2.48,8.85]],"id":70902603},{"atl":[[5,8.01]],"id":70902603}],"con":true,"img":false}]}
{"op":"mcm","clk":"11541567162","pt":1719507157965,"mc":[{"id":"1.230178329","rc":[{"atb":[[1.44,1]],"id":53082422},{"atl":[[3.35,1],[3.05,0]],"id":53082422}],"con":true,"img":false}]}
{"op":"mcm","clk":"11541567170","pt":1719507158070,"mc":[{"id":"1.230178329","rc":[{"atl":[[5.2,0],[5.7,1]],"id":64812720},{"atl":[[4.8,0],[5,9.01]],"id":70902603},{"atl":[[4,0],[4.5,1]],"id":70053016},{"atl":[[3.25,3.5]],"id":53082422}],"con":true,"img":false}]}
{"op":"mcm","clk":"11541567186","pt":1719507158235,"mc":[{"id":"1.230178329","rc":[{"atl":[[4.8,1],[6.4,10],[5.8,5],[5.5,0],[5.4,2.5]],"id":70902603},{"atl":[[4,1],[4.5,0]],"id":70053016},{"atb":[[1.44,0]],"id":53082422},{"atl":[[3.35,0],[3.05,1]],"id":53082422}],"con":true,"img":false}]}
{"op":"mcm","clk":"11541567196","pt":1719507158336,"mc":[{"id":"1.230178329","rc":[{"atl":[[5,8.01]],"id":70902603},{"atl":[[3.25,2.5]],"id":53082422}],"con":true,"img":false}]}
{"op":"mcm","clk":"11541567205","pt":1719507158440,"mc":[{"id":"1.230178329","rc":[{"atl":[[5.2,1]],"id":64812720}],"con":true,"img":false}]}
{"op":"mcm","clk":"11541567212","pt":1719507158544,"mc":[{"id":"1.230178329","rc":[{"atl":[[5.7,0]],"id":64812720}],"con":true,"img":false}]}
{"op":"mcm","clk":"11541567224","pt":1719507158750,"mc":[{"id":"1.230178329","rc":[{"atb":[[2.48,2]],"id":70902603}],"con":true,"img":false}]}
{"op":"mcm","clk":"11541567231","pt":1719507158855,"mc":[{"id":"1.230178329","rc":[{"atb":[[2.48,13.26]],"id":70902603},{"atl":[[5.2,1]],"id":70902603},{"atl":[[4,0],[4.5,1]],"id":70053016}],"con":true,"img":false}]}
{"op":"mcm","clk":"11541567235","pt":1719507158959,"mc":[{"id":"1.230178329","rc":[{"atl":[[4.8,0]],"id":70902603},{"atl":[[2.9,6.23]],"id":53082422}],"con":true,"img":false}]}
{"op":"mcm","clk":"11541567243","pt":1719507159066,"mc":[{"id":"1.230178329","rc":[{"atb":[[2.48,2]],"id":70902603},{"atl":[[4.8,1],[5.2,0]],"id":70902603},{"atl":[[4,1],[4.5,0]],"id":70053016},{"atl":[[2.92,0],[2.88,5.39],[2.98,0]],"id":53082422}],"con":true,"img":false}]}
{"op":"mcm","clk":"11541567252","pt":1719507159169,"mc":[{"id":"1.230178329","rc":[{"atl":[[2.92,11.63],[2.88,0]],"id":53082422}],"con":true,"img":false}]}
{"op":"mcm","clk":"11541567262","pt":1719507159237,"mc":[{"id":"1.230178329","rc":[{"atb":[[2.46,8.96]],"id":70902603}],"con":true,"img":false}]}
{"op":"mcm","clk":"11541567283","pt":1719507159436,"mc":[{"id":"1.230178329","rc":[{"atb":[[2.46,2.11]],"id":70902603},{"atl":[[2.86,0.84]],"id":53082422}],"con":true,"img":false}]}
{"op":"mcm","clk":"11541567302","pt":1719507159645,"mc":[{"id":"1.230178329","rc":[{"atl":[[4.8,0],[5.2,1]],"id":70902603},{"atl":[[4,0],[4.5,1]],"id":70053016}],"con":true,"img":false}]}
{"op":"mcm","clk":"11541567309","pt":1719507159745,"mc":[{"id":"1.230178329","rc":[{"atb":[[2.44,8.2]],"id":66686625}],"con":true,"img":false}]}
{"op":"mcm","clk":"11541567316","pt":1719507159851,"mc":[{"id":"1.230178329","rc":[{"atb":[[2.42,2.5]],"id":66686625}],"con":true,"img":false}]}
{"op":"mcm","clk":"11541567327","pt":1719507160057,"mc":[{"id":"1.230178329","rc":[{"atl":[[2.86,0]],"id":53082422}],"con":true,"img":false}]}
{"op":"mcm","clk":"11541567329","pt":1719507160159,"mc":[{"id":"1.230178329","rc":[{"atl":[[3.05,0]],"id":53082422}],"con":true,"img":false}]}
{"op":"mcm","clk":"11541567337","pt":1719507160265,"mc":[{"id":"1.230178329","rc":[{"atl":[[3.35,1]],"id":53082422}],"con":true,"img":false}]}
{"op":"mcm","clk":"11541567450","pt":1719507162044,"mc":[{"id":"1.230178329","rc":[{"atb":[[2.42,0],[2.58,10]],"id":64812720}],"con":true,"img":false}]}
{"op":"mcm","clk":"11541567482","pt":1719507162355,"mc":[{"id":"1.230178329","rc":[{"atl":[[5.2,0],[5.7,1]],"id":64812720}],"con":true,"img":false}]}
{"op":"mcm","clk":"11541567491","pt":1719507162464,"mc":[{"id":"1.230178329","rc":[{"atb":[[2.42,13.31],[2.58,0]],"id":64812720},{"atl":[[5,9.01],[5.2,0]],"id":70902603}],"con":true,"img":false}]}
{"op":"mcm","clk":"11541567507","pt":1719507162669,"mc":[{"id":"1.230178329","rc":[{"atl":[[4.8,1],[5,0],[5.2,1],[5.4,18.52]],"id":70902603}],"con":true,"img":false}]}
{"op":"mcm","clk":"11541567516","pt":1719507162774,"mc":[{"id":"1.230178329","rc":[{"atb":[[2.48,5.09]],"id":70902603},{"atl":[[5,8.01],[5.2,0],[5.4,2.5]],"id":70902603}],"con":true,"img":false}]}
{"op":"mcm","clk":"11541567537","pt":1719507163038,"mc":[{"id":"1.230178329","rc":[{"atl":[[4.8,0],[5.2,1]],"id":70902603}],"con":true,"img":false}]}
{"op":"mcm","clk":"11541567540","pt":1719507163136,"mc":[{"id":"1.230178329","rc":[{"atl":[[5.2,1],[5.7,0]],"id":64812720}],"con":true,"img":false}]}
{"op":"mcm","clk":"11541567554","pt":1719507163261,"mc":[{"id":"1.230178329","rc":[{"atb":[[2.48,2]],"id":70902603}],"con":true,"img":false}]}
{"op":"mcm","clk":"11541567610","pt":1719507164250,"mc":[{"id":"1.230178329","rc":[{"atl":[[2.92,0],[3.25,20.37]],"id":53082422}],"con":true,"img":false}]}
{"op":"mcm","clk":"11541567616","pt":1719507164361,"mc":[{"id":"1.230178329","rc":[{"atl":[[5.1,0],[5,1]],"id":66686625}],"con":true,"img":false}]}
{"op":"mcm","clk":"11541567624","pt":1719507164457,"mc":[{"id":"1.230178329","rc":[{"atl":[[5.1,12.28],[6,2.49]],"id":66686625}],"con":true,"img":false}]}
{"op":"mcm","clk":"11541567722","pt":1719507165656,"mc":[{"id":"1.230178329","rc":[{"atl":[[5.2,0],[5.7,1]],"id":64812720},{"atl":[[5,9.01],[5.2,0]],"id":70902603}],"con":true,"img":false}]}
{"op":"mcm","clk":"11541567731","pt":1719507165765,"mc":[{"id":"1.230178329","rc":[{"atb":[[2.3,0],[2.18,4.24]],"id":70902603}],"con":true,"img":false}]}
{"op":"mcm","clk":"11541567742","pt":1719507165865,"mc":[{"id":"1.230178329","rc":[{"atb":[[2.24,4.12]],"id":70902603},{"atl":[[5,1],[5.4,18.52]],"id":70902603}],"con":true,"img":false}]}
{"op":"mcm","clk":"11541567750","pt":1719507165970,"mc":[{"id":"1.230178329","rc":[{"atb":[[2.18,0]],"id":70902603}],"con":true,"img":false}]}
{"op":"mcm","clk":"11541567789","pt":1719507166482,"mc":[{"id":"1.230178329","rc":[{"atl":[[4.8,1],[5,0]],"id":70902603}],"con":true,"img":false}]}
{"op":"mcm","clk":"11541567797","pt":1719507166549,"mc":[{"id":"1.230178329","rc":[{"atl":[[5.2,1]],"id":70902603}],"con":true,"img":false}]}
{"op":"mcm","clk":"11541567807","pt":1719507166651,"mc":[{"id":"1.230178329","rc":[{"atl":[[5.2,1],[5.7,0]],"id":64812720},{"atl":[[4.8,0]],"id":70902603}],"con":true,"img":false}]}
{"op":"mcm","clk":"11541567815","pt":1719507166755,"mc":[{"id":"1.230178329","rc":[{"atl":[[5.3,1]],"id":64812720},{"atl":[[5.2,0]],"id":70902603},{"atb":[[1.85,0],[1.88,10]],"id":70053016}],"con":true,"img":false}]}
{"op":"mcm","clk":"11541567836","pt":1719507166968,"mc":[{"id":"1.230178329","rc":[{"atl":[[5.2,0]],"id":64812720}],"con":true,"img":false}]}
{"op":"mcm","clk":"11541567966","pt":1719507168368,"mc":[{"id":"1.230178329","rc":[{"atl":[[5.2,1]],"id":70902603}],"con":true,"img":false}]}
{"op":"mcm","clk":"11541568000","pt":1719507168784,"mc":[{"id":"1.230178329","rc":[{"atl":[[4.8,1],[5.2,0],[4.9,1]],"id":70902603},{"atl":[[5,0],[5.2,1]],"id":66686625},{"atl":[[4,1],[4.5,0],[3.95,1]],"id":70053016},{"atl":[[3.35,0],[3.05,1]],"id":53082422}],"con":true,"img":false}]}
{"op":"mcm","clk":"11541568009","pt":1719507168883,"mc":[{"id":"1.230178329","rc":[{"atl":[[4,11.64]],"id":70053016},{"atl":[[2.92,1]],"id":53082422}],"con":true,"img":false}]}
{"op":"mcm","clk":"11541568019","pt":1719507168942,"mc":[{"id":"1.230178329","rc":[{"atl":[[4.4,0]],"id":70053016},{"atl":[[3.25,2.5],[3.05,13.48]],"id":53082422}],"con":true,"img":false}]}
{"op":"mcm","clk":"11541568036","pt":1719507169161,"mc":[{"id":"1.230178329","rc":[{"atb":[[2.42,0],[2.6,10]],"id":64812720},{"atl":[[3.95,0]],"id":70053016}],"con":true,"img":false}]}
{"op":"mcm","clk":"11541568201","pt":1719507170883,"mc":[{"id":"1.230178329","rc":[{"atl":[[4.8,0]],"id":70902603}],"con":true,"img":false}]}
{"op":"mcm","clk":"11541568335","pt":1719507172554,"mc":[{"id":"1.230178329","rc":[{"atl":[[4.9,15.02],[5.4,2.5]],"id":70902603}],"con":true,"img":false}]}
{"op":"mcm","clk":"11541568341","pt":1719507172665,"mc":[{"id":"1.230178329","rc":[{"atl":[[5.4,24.53]],"id":70902603}],"con":true,"img":false}]}
{"op":"mcm","clk":"11541568353","pt":1719507172766,"mc":[{"id":"1.230178329","rc":[{"atl":[[4.9,1]],"id":70902603}],"con":true,"img":false}]}
{"op":"mcm","clk":"11541568398","pt":1719507173244,"mc":[{"id":"1.230178329","rc":[{"atl":[[3.05,12.48]],"id":53082422}],"con":true,"img":false}]}
{"op":"mcm","clk":"11541568434","pt":1719507173758,"mc":[{"id":"1.230178329","rc":[{"atl":[[4,10.64],[4.5,1]],"id":70053016}],"con":true,"img":false}]}
{"op":"mcm","clk":"11541568444","pt":1719507173870,"mc":[{"id":"1.230178329","rc":[{"atl":[[4,0],[4.4,15.96]],"id":70053016}],"con":true,"img":false}]}
{"op":"mcm","clk":"11541568550","pt":1719507175172,"mc":[{"id":"1.230178329","rc":[{"atl":[[5.6,1],[5.3,0],[5.4,1]],"id":64812720},{"atl":[[4.9,0],[5.2,1]],"id":70902603},{"atl":[[5.3,1],[5.2,0]],"id":66686625},{"atl":[[10.5,0],[11,1]],"id":69942666},{"atl":[[2.92,0],[3.35,1]],"id":53082422}],"con":true,"img":false}]}
{"op":"mcm","clk":"11541568557","pt":1719507175275,"mc":[{"id":"1.230178329","rc":[{"atb":[[2.6,0],[2.44,13.31]],"id":64812720},{"atl":[[5.7,1]],"id":64812720},{"atl":[[5.1,14.02],[5.4,2.5]],"id":70902603},{"atl":[[4.5,0],[3.9,1]],"id":70053016},{"atl":[[2.94,1]],"id":53082422}],"con":true,"img":false}]}
{"op":"mcm","clk":"11541568565","pt":1719507175380,"mc":[{"id":"1.230178329","rc":[{"atb":[[2.64,18.73]],"id":64812720}],"con":true,"img":false}]}
{"op":"mcm","clk":"11541568573","pt":1719507175477,"mc":[{"id":"1.230178329","rc":[{"atb":[[2.44,0]],"id":64812720}],"con":true,"img":false}]}
{"op":"mcm","clk":"11541568635","pt":1719507176265,"mc":[{"id":"1.230178329","rc":[{"atl":[[5.6,0],[5.4,0]],"id":64812720},{"atl":[[5.3,0],[5.2,1]],"id":66686625}],"con":true,"img":false}]}
{"op":"mcm","clk":"11541568689","pt":1719507177046,"mc":[{"id":"1.230178329","rc":[{"atl":[[4.5,1],[3.9,0]],"id":70053016}],"con":true,"img":false}]}
{"op":"mcm","clk":"11541568828","pt":1719507179284,"mc":[{"id":"1.230178329","rc":[{"atl":[[3.35,0],[2.94,0]],"id":53082422}],"con":true,"img":false}]}
{"op":"mcm","clk":"11541568843","pt":1719507179488,"mc":[{"id":"1.230178329","rc":[{"atl":[[3.25,21.22],[3.05,0]],"id":53082422}],"con":true,"img":false}]}
{"op":"mcm","clk":"11541568893","pt":1719507180072,"mc":[{"id":"1.230178329","rc":[{"atb":[[1.08,50]],"id":64812720},{"atb":[[1.08,50]],"id":70902603},{"atb":[[1.08,50]],"id":66686625},{"atb":[[1.08,50]],"id":70053016},{"atb":[[1.08,50]],"id":69942666},{"atb":[[1.08,50]],"id":53082422}],"con":true,"img":false}]}
{"op":"mcm","clk":"11541568947","pt":1719507180695,"mc":[{"id":"1.230178329","rc":[{"atl":[[4.5,0],[3.9,1]],"id":70053016}],"con":true,"img":false}]}
{"op":"mcm","clk":"11541568970","pt":1719507181062,"mc":[{"id":"1.230178329","rc":[{"atl":[[4.9,1]],"id":70902603},{"atl":[[2.94,1]],"id":53082422}],"con":true,"img":false}]}
{"op":"mcm","clk":"11541568979","pt":1719507181168,"mc":[{"id":"1.230178329","rc":[{"atl":[[5.2,0]],"id":70902603}],"con":true,"img":false}]}
{"op":"mcm","clk":"11541569006","pt":1719507181483,"mc":[{"id":"1.230178329","rc":[{"atb":[[2.48,6.68]],"id":70902603}],"con":true,"img":false}]}
{"op":"mcm","clk":"11541569099","pt":1719507182665,"mc":[{"id":"1.230178329","rc":[{"atl":[[5.7,0],[5.9,1]],"id":64812720},{"atl":[[4.8,1],[4.9,0]],"id":70902603},{"atl":[[4.5,1]],"id":70053016}],"con":true,"img":false}]}
{"op":"mcm","clk":"11541569111","pt":1719507182772,"mc":[{"id":"1.230178329","rc":[{"atl":[[5.8,1]],"id":64812720},{"atl":[[5.1,0],[4.9,14.02],[5.2,1]],"id":70902603},{"atl":[[3.9,0]],"id":70053016},{"atl":[[3.35,1],[2.94,0]],"id":53082422}],"con":true,"img":false}]}
{"op":"mcm","clk":"11541569116","pt":1719507182868,"mc":[{"id":"1.230178329","rc":[{"atl":[[5.7,1],[5.9,0]],"id":64812720},{"atl":[[4.8,0]],"id":70902603}],"con":true,"img":false}]}
{"op":"mcm","clk":"11541569146","pt":1719507183185,"mc":[{"id":"1.230178329","rc":[{"atl":[[5.8,0]],"id":64812720}],"con":true,"img":false}]}
{"op":"mcm","clk":"11541569242","pt":1719507184495,"mc":[{"id":"1.230178329","rc":[{"atl":[[5.9,1]],"id":64812720},{"spn":2.39,"spf":1.0,"id":64812720},{"atl":[[4.8,1],[5.2,0]],"id":70902603},{"spn":3.49,"spf":"NaN","id":70902603},{"spn":3.42,"spf":"NaN","id":66686625}],"con":true,"img":false}]}
{"op":"mcm","clk":"11541569250","pt":1719507184594,"mc":[{"id":"1.230178329","rc":[{"atl":[[5.7,0]],"id":64812720}],"con":true,"img":false}]}
{"op":"mcm","clk":"11541569256","pt":1719507184692,"mc":[{"id":"1.230178329","rc":[{"atl":[[5.9,0]],"id":64812720}],"con":true,"img":false}]}
{"op":"mcm","clk":"11541569285","pt":1719507184964,"mc":[{"id":"1.230178329","rc":[{"atl":[[5.9,1]],"id":64812720}],"con":true,"img":false}]}
{"op":"mcm","clk":"11541569367","pt":1719507186100,"mc":[{"id":"1.230178329","rc":[{"atb":[[2.42,16.62],[2.64,2.11]],"id":64812720},{"atl":[[7.2,0],[6.4,0],[6.2,0],[6.6,1],[5.9,0]],"id":64812720},{"atb":[[2.24,0],[1.94,8.24],[2.48,2]],"id":70902603},{"atb":[[1.89,5],[2.26,5]],"id":66686625},{"atl":[[5.1,0],[6,14.77]],"id":66686625},{"atb":[[2.32,2.5],[1.93,0],[2.24,5],[1.97,0],[1.88,0],[2.16,10],[1.61,10]],"id":70053016},{"atb":[[3.25,9.5],[3.75,0]],"id":69942666},{"atl":[[16.5,0],[10.5,5],[12.5,11.2],[14.5,0],[9.4,2.5]],"id":69942666},{"atb":[[1.41,14.44],[1.45,0],[1.49,0],[1.39,0],[1.52,2]],"id":53082422},{"atl":[[3.25,2.5],[2.96,12.48]],"id":53082422}],"con":true,"img":false}]}
{"op":"mcm","clk":"11541569378","pt":1719507186156,"mc":[{"id":"1.230178329","rc":[{"atb":[[2.32,10.24]],"id":70053016},{"atl":[[9.2,5.18]],"id":69942666},{"atb":[[1.37,2.5],[1.33,5],[1.29,10],[1.31,11.04]],"id":53082422}],"con":true,"img":false}]}
{"op":"mcm","clk":"11541569387","pt":1719507186265,"mc":[{"id":"1.230178329","rc":[{"atb":[[2.42,0],[2.62,15.43]],"id":64812720},{"atl":[[8,0],[9.2,5],[10,10],[6.8,6.25],[8.4,2.5]],"id":64812720},{"atb":[[2.06,4.12],[1.94,0]],"id":70902603},{"atb":[[1.89,0],[2.12,5]],"id":66686625},{"atl":[[6,2.49],[5.2,13.28]],"id":66686625},{"atb":[[1.78,11.58],[1.61,0]],"id":70053016},{"atb":[[3.25,0],[3.65,13.38]],"id":69942666},{"atl":[[10,6.91],[12.5,2.5]],"id":69942666},{"atb":[[1.08,53.46]],"id":53082422}],"con":true,"img":false}]}
{"op":"mcm","clk":"11541569394","pt":1719507186363,"mc":[{"id":"1.230178329","rc":[{"atb":[[2,1.99]],"id":70053016},{"atl":[[9.8,0.84]],"id":69942666},{"atb":[[1.37,6.74]],"id":53082422}],"con":true,"img":false}]}
{"op":"mcm","clk":"11541569401","pt":1719507186474,"mc":[{"id":"1.230178329","rc":[{"atl":[[6,21.92],[5.2,1]],"id":66686625},{"atl":[[9.2,6.02],[9.8,0]],"id":69942666},{"atb":[[1.31,0]],"id":53082422}],"con":true,"img":false}]}
{"op":"mcm","clk":"11541569407","pt":1719507186571,"mc":[{"id":"1.230178329","rc":[{"atb":[[1.52,0]],"id":53082422}],"con":true,"img":false}]}
{"op":"mcm","clk":"11541569413","pt":1719507186675,"mc":[{"id":"1.230178329","rc":[{"atb":[[1.48,2]],"id":53082422}],"con":true,"img":false}]}
{"op":"mcm","clk":"11541569425","pt":1719507186879,"mc":[{"id":"1.230178329","rc":[{"atb":[[2,0]],"id":70053016}],"con":true,"img":false}]}
{"op":"mcm","clk":"11541569436","pt":1719507186994,"mc":[{"id":"1.230178329","rc":[{"atb":[[2.34,2]],"id":70053016}],"con":true,"img":false}]}
{"op":"mcm","clk":"11541569449","pt":1719507187192,"mc":[{"id":"1.230178329","rc":[{"atb":[[1.41,15.44]],"id":53082422}],"con":true,"img":false}]}
{"op":"mcm","clk":"11541569463","pt":1719507187355,"mc":[{"id":"1.230178329","rc":[{"atb":[[2.48,0]],"id":70902603}],"con":true,"img":false}]}
{"op":"mcm","clk":"11541569469","pt":1719507187456,"mc":[{"id":"1.230178329","rc":[{"atb":[[1.02,24.64]],"id":70902603}],"con":true,"img":false}]}
{"op":"mcm","clk":"11541569518","pt":1719507188080,"mc":[{"id":"1.230178329","rc":[{"atb":[[1.02,22.64]],"id":70902603}],"con":true,"img":false}]}
{"op":"mcm","clk":"11541569530","pt":1719507188202,"mc":[{"id":"1.230178329","rc":[{"atb":[[2.48,2]],"id":70902603}],"con":true,"img":false}]}
{"op":"mcm","clk":"11541569542","pt":1719507188296,"mc":[{"id":"1.230178329","rc":[{"atl":[[2.58,6.56]],"id":53082422}],"con":true,"img":false}]}
{"op":"mcm","clk":"11541569549","pt":1719507188395,"mc":[{"id":"1.230178329","rc":[{"atb":[[3.6,5.62]],"id":69942666},{"atl":[[2.56,6.56],[2.96,0]],"id":53082422}],"con":true,"img":false}]}
{"op":"mcm","clk":"11541569555","pt":1719507188454,"mc":[{"id":"1.230178329","rc":[{"atl":[[2.9,0.84]],"id":53082422}],"con":true,"img":false}]}
{"op":"mcm","clk":"11541569566","pt":1719507188564,"mc":[{"id":"1.230178329","rc":[{"atl":[[2.9,13.96]],"id":53082422}],"con":true,"img":false}]}
{"op":"mcm","clk":"11541569576","pt":1719507188671,"mc":[{"id":"1.230178329","rc":[{"atl":[[2.56,0]],"id":53082422}],"con":true,"img":false}]}
{"op":"mcm","clk":"11541569595","pt":1719507188975,"mc":[{"id":"1.230178329","rc":[{"atl":[[2.54,0.84],[2.9,13.12]],"id":53082422}],"con":true,"img":false}]}
{"op":"mcm","clk":"11541569605","pt":1719507189083,"mc":[{"id":"1.230178329","rc":[{"atb":[[1.47,6.11]],"id":53082422}],"con":true,"img":false}]}
{"op":"mcm","clk":"11541569642","pt":1719507189510,"mc":[{"id":"1.230178329","rc":[{"atl":[[2.54,0]],"id":53082422}],"con":true,"img":false}]}
{"op":"mcm","clk":"11541569747","pt":1719507190687,"mc":[{"id":"1.230178329","rc":[{"atl":[[1000,1.7]],"id":53082422}],"con":true,"img":false}]}
{"op":"mcm","clk":"11541569754","pt":1719507190791,"mc":[{"id":"1.230178329","rc":[{"atl":[[1000,1.7]],"id":66686625},{"atl":[[1000,1.87]],"id":70053016},{"atb":[[1.01,1.7]],"id":53082422}],"con":true,"img":false}]}
{"op":"mcm","clk":"11541569763","pt":1719507190906,"mc":[{"id":"1.230178329","rc":[{"atb":[[1.02,1.7]],"id":66686625},{"atb":[[1.02,1.7]],"id":70053016},{"atl":[[1000,0.18]],"id":53082422}],"con":true,"img":false}]}
{"op":"mcm","clk":"11541569773","pt":1719507191004,"mc":[{"id":"1.230178329","rc":[{"atl":[[1000,0.08]],"id":66686625},{"atl":[[1000,0.27]],"id":70053016},{"atb":[[1.01,0.57]],"id":53082422}],"con":true,"img":false}]}
{"op":"mcm","clk":"11541569778","pt":1719507191101,"mc":[{"id":"1.230178329","rc":[{"atb":[[1.02,0.19]],"id":66686625},{"atb":[[1.02,0.2]],"id":70053016},{"atl":[[1000,0]],"id":53082422}],"con":true,"img":false}]}
{"op":"mcm","clk":"11541569786","pt":1719507191162,"mc":[{"id":"1.230178329","rc":[{"atl":[[6.4,1],[9.2,0],[10,0],[8.2,2.5],[8.4,0]],"id":64812720},{"atl":[[1000,0]],"id":66686625},{"atl":[[1000,0.16]],"id":70053016},{"atb":[[1.01,0]],"id":53082422},{"atl":[[2.56,0.18]],"id":53082422}],"con":true,"img":false}]}
{"op":"mcm","clk":"11541569800","pt":1719507191268,"mc":[{"id":"1.230178329","rc":[{"atl":[[6.6,0]],"id":64812720},{"atb":[[1.02,0]],"id":66686625},{"atl":[[4.3,0.08]],"id":66686625},{"atb":[[1.02,0]],"id":70053016},{"atl":[[3.8,0.1]],"id":70053016},{"atb":[[1.49,0.57]],"id":53082422}],"con":true,"img":false}]}
{"op":"mcm","clk":"11541569809","pt":1719507191378,"mc":[{"id":"1.230178329","rc":[{"atb":[[2.46,0.19]],"id":66686625},{"atb":[[2.36,0.2]],"id":70053016}],"con":true,"img":false}]}
{"op":"mcm","clk":"11541569818","pt":1719507191477,"mc":[{"id":"1.230178329","rc":[{"atl":[[10,0],[10.5,15.53]],"id":69942666}],"con":true,"img":false}]}
{"op":"mcm","clk":"11541569825","pt":1719507191581,"mc":[{"id":"1.230178329","rc":[{"atb":[[2.46,2.81]],"id":66686625}],"con":true,"img":false}]}
{"op":"mcm","clk":"11541569842","pt":1719507191791,"mc":[{"id":"1.230178329","rc":[{"atb":[[2.44,2]],"id":66686625}],"con":true,"img":false}]}
{"op":"mcm","clk":"11541569902","pt":1719507192568,"mc":[{"id":"1.230178329","rc":[{"atb":[[2.44,0]],"id":66686625}],"con":true,"img":false}]}
{"op":"mcm","clk":"11541569908","pt":1719507192665,"mc":[{"id":"1.230178329","rc":[{"atb":[[2.48,2]],"id":66686625}],"con":true,"img":false}]}
{"op":"mcm","clk":"11541569920","pt":1719507192777,"mc":[{"id":"1.230178329","rc":[{"atb":[[3.8,13.38]],"id":69942666}],"con":true,"img":false}]}
{"op":"mcm","clk":"11541569927","pt":1719507192875,"mc":[{"id":"1.230178329","rc":[{"atb":[[3.65,0]],"id":69942666}],"con":true,"img":false}]}
{"op":"mcm","clk":"11541569928","pt":1719507192974,"mc":[{"id":"1.230178329","rc":[{"atl":[[6,2.49],[5.2,7.23]],"id":66686625}],"con":true,"img":false}]}
{"op":"mcm","clk":"11541569969","pt":1719507193490,"mc":[{"id":"1.230178329","rc":[{"atb":[[3.6,2.5]],"id":69942666}],"con":true,"img":false}]}
{"op":"mcm","clk":"11541570196","pt":1719507196394,"mc":[{"id":"1.230178329","rc":[{"atb":[[1.84,10],[1.78,0]],"id":70053016}],"con":true,"img":false}]}
{"op":"mcm","clk":"11541570201","pt":1719507196488,"mc":[{"id":"1.230178329","rc":[{"atl":[[2.56,1.02]],"id":53082422}],"con":true,"img":false}]}
{"op":"mcm","clk":"11541570207","pt":1719507196598,"mc":[{"id":"1.230178329","rc":[{"atl":[[2.56,7.58]],"id":53082422}],"con":true,"img":false}]}
{"op":"mcm","clk":"11541570218","pt":1719507196703,"mc":[{"id":"1.230178329","rc":[{"atl":[[2.9,0]],"id":53082422}],"con":true,"img":false}]}
{"op":"mcm","clk":"11541570223","pt":1719507196796,"mc":[{"id":"1.230178329","rc":[{"atl":[[3.9,1]],"id":70053016},{"atl":[[10.5,16.53],[11,0]],"id":69942666}],"con":true,"img":false}]}
{"op":"mcm","clk":"11541570232","pt":1719507196915,"mc":[{"id":"1.230178329","rc":[{"atl":[[4.5,0],[3.85,10.63],[4.4,0]],"id":70053016}],"con":true,"img":false}]}
{"op":"mcm","clk":"11541570235","pt":1719507197009,"mc":[{"id":"1.230178329","rc":[{"atl":[[3.8,2.35]],"id":70053016}],"con":true,"img":false}]}
{"op":"mcm","clk":"11541570247","pt":1719507197111,"mc":[{"id":"1.230178329","rc":[{"atl":[[3.85,5.31],[3.9,11.74]],"id":70053016}],"con":true,"img":false}]}
{"op":"mcm","clk":"11541570253","pt":1719507197213,"mc":[{"id":"1.230178329","rc":[{"atl":[[5.5,1],[5.2,6.23]],"id":66686625},{"atl":[[3.85,0.84]],"id":70053016}],"con":true,"img":false}]}
{"op":"mcm","clk":"11541570265","pt":1719507197272,"mc":[{"id":"1.230178329","rc":[{"atb":[[2.32,5],[2.12,0]],"id":66686625}],"con":true,"img":false}]}
{"op":"mcm","clk":"11541570272","pt":1719507197473,"mc":[{"id":"1.230178329","rc":[{"atl":[[3.75,0.84]],"id":70053016}],"con":true,"img":false}]}
{"op":"mcm","clk":"11541570462","pt":1719507200005,"mc":[{"id":"1.230178329","rc":[{"atb":[[2.36,2.34]],"id":70053016}],"con":true,"img":false}]}
{"op":"mcm","clk":"11541570477","pt":1719507200206,"mc":[{"id":"1.230178329","rc":[{"atb":[[2.32,2.5]],"id":70053016}],"con":true,"img":false}]}
{"op":"mcm","clk":"11541570511","pt":1719507200624,"mc":[{"id":"1.230178329","rc":[{"atb":[[2.34,0]],"id":70053016}],"con":true,"img":false}]}
{"op":"mcm","clk":"11541570518","pt":1719507200714,"mc":[{"id":"1.230178329","rc":[{"atb":[[2.38,2]],"id":70053016}],"con":true,"img":false}]}
{"op":"mcm","clk":"11541570526","pt":1719507200816,"mc":[{"id":"1.230178329","rc":[{"atb":[[3.8,15.88]],"id":69942666}],"con":true,"img":false}]}
{"op":"mcm","clk":"11541570534","pt":1719507200877,"mc":[{"id":"1.230178329","rc":[{"atb":[[3.8,9.19],[3.4,20.88]],"id":69942666}],"con":true,"img":false}]}
{"op":"mcm","clk":"11541570606","pt":1719507201805,"mc":[{"id":"1.230178329","rc":[{"atl":[[3.95,1],[3.9,10.74]],"id":70053016}],"con":true,"img":false}]}
{"op":"mcm","clk":"11541570630","pt":1719507202120,"mc":[{"id":"1.230178329","rc":[{"atl":[[2.54,6.09]],"id":53082422}],"con":true,"img":false}]}
{"op":"mcm","clk":"11541570646","pt":1719507202308,"mc":[{"id":"1.230178329","rc":[{"atl":[[2.56,1.02],[2.52,6.56],[2.58,0]],"id":53082422}],"con":true,"img":false}]}
{"op":"mcm","clk":"11541570695","pt":1719507203088,"mc":[{"id":"1.230178329","rc":[{"atl":[[2.56,0.18]],"id":53082422}],"con":true,"img":false}]}
{"op":"mcm","clk":"11541570699","pt":1719507203197,"mc":[{"id":"1.230178329","rc":[{"atb":[[1.47,2.11]],"id":53082422}],"con":true,"img":false}]}
{"op":"mcm","clk":"11541570713","pt":1719507203299,"mc":[{"id":"1.230178329","rc":[{"atb":[[2.72,3]],"id":64812720},{"atb":[[2.48,4.3]],"id":70902603},{"atb":[[2.48,4.6]],"id":66686625},{"atb":[[3.85,3]],"id":69942666},{"atb":[[1.48,6.1]],"id":53082422}],"con":true,"img":false}]}
{"op":"mcm","clk":"11541570719","pt":1719507203403,"mc":[{"id":"1.230178329","rc":[{"atb":[[2.74,6.19]],"id":64812720}],"con":true,"img":false}]}
{"op":"mcm","clk":"11541570726","pt":1719507203506,"mc":[{"id":"1.230178329","rc":[{"atb":[[2.74,9.19],[2.62,5]],"id":64812720},{"atb":[[3.9,6.77]],"id":69942666},{"atl":[[2.5,0.84]],"id":53082422}],"con":true,"img":false}]}
{"op":"mcm","clk":"11541570729","pt":1719507203604,"mc":[{"id":"1.230178329","rc":[{"atb":[[2.72,15.38],[2.7,2.5]],"id":64812720}],"con":true,"img":false}]}
{"op":"mcm","clk":"11541570734","pt":1719507203707,"mc":[{"id":"1.230178329","rc":[{"atb":[[2.74,6.19],[2.7,14.69]],"id":64812720},{"atb":[[3.8,4.49]],"id":69942666}],"con":true,"img":false}]}
{"op":"mcm","clk":"11541570738","pt":1719507203807,"mc":[{"id":"1.230178329","rc":[{"atb":[[2.72,3]],"id":64812720},{"atb":[[2.72,2.5],[2.64,5],[2.26,0],[2.34,0],[2.56,10],[2.42,0]],"id":66686625}],"con":true,"img":false}]}
{"op":"mcm","clk":"11541570755","pt":1719507204015,"mc":[{"id":"1.230178329","rc":[{"atb":[[3.8,2.49]],"id":69942666}],"con":true,"img":false}]}
{"op":"mcm","clk":"11541570763","pt":1719507204117,"mc":[{"id":"1.230178329","rc":[{"atb":[[3.9,8.77]],"id":69942666}],"con":true,"img":false}]}
{"op":"mcm","clk":"11541570804","pt":1719507204687,"mc":[{"id":"1.230178329","rc":[{"atb":[[2.48,2.6]],"id":66686625}],"con":true,"img":false}]}
{"op":"mcm","clk":"11541570813","pt":1719507204783,"mc":[{"id":"1.230178329","rc":[{"atb":[[2.74,2]],"id":66686625}],"con":true,"img":false}]}
{"op":"mcm","clk":"11541570848","pt":1719507205300,"mc":[{"id":"1.230178329","rc":[{"atb":[[2.74,7.62]],"id":66686625}],"con":true,"img":false}]}
{"op":"mcm","clk":"11541570860","pt":1719507205507,"mc":[{"id":"1.230178329","rc":[{"atb":[[2.46,0.19]],"id":66686625}],"con":true,"img":false}]}
{"op":"mcm","clk":"11541570970","pt":1719507207102,"mc":[{"id":"1.230178329","rc":[{"atl":[[6.4,0],[6.2,1]],"id":64812720}],"con":true,"img":false}]}
{"op":"mcm","clk":"11541570978","pt":1719507207206,"mc":[{"id":"1.230178329","rc":[{"atb":[[3.85,20.54],[3.4,5]],"id":69942666}],"con":true,"img":false}]}
{"op":"mcm","clk":"11541570991","pt":1719507207410,"mc":[{"id":"1.230178329","rc":[{"atl":[[2.54,13.5],[2.52,0]],"id":53082422}],"con":true,"img":false}]}
{"op":"mcm","clk":"11541571049","pt":1719507208022,"mc":[{"id":"1.230178329","rc":[{"atl":[[2.5,0]],"id":53082422}],"con":true,"img":false}]}
{"op":"mcm","clk":"11541571058","pt":1719507208083,"mc":[{"id":"1.230178329","rc":[{"atl":[[2.54,6.09],[2.96,13.68]],"id":53082422}],"con":true,"img":false}]}
{"op":"mcm","clk":"11541571290","pt":1719507211011,"mc":[{"id":"1.230178329","rc":[{"atl":[[2.52,0.84]],"id":53082422}],"con":true,"img":false}]}
{"op":"mcm","clk":"11541571325","pt":1719507211521,"mc":[{"id":"1.230178329","rc":[{"atb":[[1.48,8.33]],"id":53082422}],"con":true,"img":false}]}
{"op":"mcm","clk":"11541571338","pt":1719507211682,"mc":[{"id":"1.230178329","rc":[{"atb":[[1.08,50]],"id":53082422}],"con":true,"img":false}]}
{"op":"mcm","clk":"11541571353","pt":1719507211988,"mc":[{"id":"1.230178329","rc":[{"atb":[[1.9,0]],"id":70053016}],"con":true,"img":false}]}
{"op":"mcm","clk":"11541571410","pt":1719507212918,"mc":[{"id":"1.230178329","rc":[{"atb":[[2.02,5],[1.97,10],[1.86,0],[2.1,2.5]],"id":70902603}],"con":true,"img":false}]}
{"op":"mcm","clk":"11541571456","pt":1719507213528,"mc":[{"id":"1.230178329","rc":[{"atb":[[2.46,0],[2.12,2.11]],"id":70902603},{"atb":[[2.38,5.26]],"id":70053016}],"con":true,"img":false}]}
{"op":"mcm","clk":"11541571467","pt":1719507213687,"mc":[{"id":"1.230178329","rc":[{"atb":[[2.36,0.2]],"id":70053016}],"con":true,"img":false}]}
{"op":"mcm","clk":"11541571510","pt":1719507214405,"mc":[{"id":"1.230178329","rc":[{"atl":[[2.56,7.12],[2.96,0]],"id":53082422}],"con":true,"img":false}]}
{"op":"mcm","clk":"11541571591","pt":1719507215637,"mc":[{"id":"1.230178329","rc":[{"atl":[[2.52,7]],"id":53082422}],"con":true,"img":false}]}
{"op":"mcm","clk":"11541571601","pt":1719507215797,"mc":[{"id":"1.230178329","rc":[{"atl":[[2.54,0]],"id":53082422}],"con":true,"img":false}]}
{"op":"mcm","clk":"11541571612","pt":1719507215906,"mc":[{"id":"1.230178329","rc":[{"atl":[[2.96,14.13]],"id":53082422}],"con":true,"img":false}]}
{"op":"mcm","clk":"11541571620","pt":1719507216016,"mc":[{"id":"1.230178329","rc":[{"atl":[[2.56,0.18]],"id":53082422}],"con":true,"img":false}]}
{"op":"mcm","clk":"11541571644","pt":1719507216417,"mc":[{"id":"1.230178329","rc":[{"atl":[[6.4,0],[5.8,0],[4.6,2.5],[5,5]],"id":70902603}],"con":true,"img":false}]}
{"op":"mcm","clk":"11541571660","pt":1719507216526,"mc":[{"id":"1.230178329","rc":[{"atl":[[4.6,16.52],[4.9,0]],"id":70902603}],"con":true,"img":false}]}
{"op":"mcm","clk":"11541571715","pt":1719507217196,"mc":[{"id":"1.230178329","rc":[{"atb":[[2.72,0]],"id":64812720},{"atb":[[2.48,2]],"id":70902603},{"atb":[[2.48,0]],"id":66686625},{"atb":[[3.85,17.54]],"id":69942666}],"con":true,"img":false}]}
{"op":"mcm","clk":"11541571725","pt":1719507217294,"mc":[{"id":"1.230178329","rc":[{"atb":[[2.66,20.88],[2.7,2.5],[2.76,2.8]],"id":64812720},{"atb":[[2.14,2.96]],"id":70902603},{"atb":[[2.76,3]],"id":66686625},{"atb":[[3.95,2.43]],"id":69942666}],"con":true,"img":false}]}
{"op":"mcm","clk":"11541571728","pt":1719507217394,"mc":[{"id":"1.230178329","rc":[{"atb":[[2.78,6.04]],"id":64812720},{"atb":[[3.95,13.53]],"id":69942666}],"con":true,"img":false}]}
{"op":"mcm","clk":"11541571752","pt":1719507217602,"mc":[{"id":"1.230178329","rc":[{"atb":[[2.74,0]],"id":64812720},{"atb":[[3.9,2]],"id":69942666}],"con":true,"img":false}]}
{"op":"mcm","clk":"11541571767","pt":1719507217809,"mc":[{"id":"1.230178329","rc":[{"atb":[[2.48,0]],"id":70902603}],"con":true,"img":false}]}
{"op":"mcm","clk":"11541571774","pt":1719507217908,"mc":[{"id":"1.230178329","rc":[{"atb":[[2.06,0],[2.12,8.03],[2.14,9.06]],"id":70902603}],"con":true,"img":false}]}
{"op":"mcm","clk":"11541571844","pt":1719507218731,"mc":[{"id":"1.230178329","rc":[{"atl":[[4,1.57]],"id":70902603},{"atb":[[2.76,9.86]],"id":66686625}],"con":true,"img":false}]}
{"op":"mcm","clk":"11541571855","pt":1719507218831,"mc":[{"id":"1.230178329","rc":[{"atl":[[3.95,11.29]],"id":70902603},{"atb":[[2.74,0]],"id":66686625}],"con":true,"img":false}]}
{"op":"mcm","clk":"11541571867","pt":1719507218885,"mc":[{"id":"1.230178329","rc":[{"atb":[[2.78,2]],"id":66686625}],"con":true,"img":false}]}
{"op":"mcm","clk":"11541571879","pt":1719507218991,"mc":[{"id":"1.230178329","rc":[{"atl":[[4.5,0.84]],"id":70902603}],"con":true,"img":false}]}
{"op":"mcm","clk":"11541571896","pt":1719507219197,"mc":[{"id":"1.230178329","rc":[{"atb":[[3.9,0]],"id":69942666}],"con":true,"img":false}]}
{"op":"mcm","clk":"11541571906","pt":1719507219305,"mc":[{"id":"1.230178329","rc":[{"atb":[[1.02,2]],"id":69942666}],"con":true,"img":false}]}
{"op":"mcm","clk":"11541571922","pt":1719507219508,"mc":[{"id":"1.230178329","rc":[{"atl":[[4.5,0],[3.9,0.84]],"id":70902603}],"con":true,"img":false}]}
{"op":"mcm","clk":"11541571974","pt":1719507220231,"mc":[{"id":"1.230178329","rc":[{"atl":[[4,0]],"id":70902603}],"con":true,"img":false}]}
{"op":"mcm","clk":"11541571997","pt":1719507220553,"mc":[{"id":"1.230178329","rc":[{"atl":[[4,1.57]],"id":70902603},{"atb":[[3.8,5.62]],"id":69942666}],"con":true,"img":false}]}
{"op":"mcm","clk":"11541572014","pt":1719507220812,"mc":[{"id":"1.230178329","rc":[{"atl":[[4,0]],"id":70902603}],"con":true,"img":false}]}
{"op":"mcm","clk":"11541572036","pt":1719507221124,"mc":[{"id":"1.230178329","rc":[{"atl":[[4,1.57]],"id":70902603}],"con":true,"img":false}]}
{"op":"mcm","clk":"11541572071","pt":1719507221432,"mc":[{"id":"1.230178329","rc":[{"atl":[[4,0]],"id":70902603}],"con":true,"img":false}]}
{"op":"mcm","clk":"11541572087","pt":1719507221638,"mc":[{"id":"1.230178329","rc":[{"atl":[[6.4,1],[6.2,0]],"id":64812720},{"atl":[[3.95,0],[3.9,11.74]],"id":70053016},{"atb":[[3.85,0],[3.75,27.06]],"id":69942666}],"con":true,"img":false}]}
{"op":"mcm","clk":"11541572095","pt":1719507221736,"mc":[{"id":"1.230178329","rc":[{"atl":[[4.1,1.57]],"id":70902603}],"con":true,"img":false}]}
{"op":"mcm","clk":"11541572123","pt":1719507222006,"mc":[{"id":"1.230178329","rc":[{"atl":[[4.1,0]],"id":70902603}],"con":true,"img":false}]}
{"op":"mcm","clk":"11541572149","pt":1719507222316,"mc":[{"id":"1.230178329","rc":[{"atl":[[3.95,12.86]],"id":70902603},{"atb":[[3.8,2.5]],"id":69942666}],"con":true,"img":false}]}
{"op":"mcm","clk":"11541572157","pt":1719507222413,"mc":[{"id":"1.230178329","rc":[{"atl":[[4.8,0],[4.7,1]],"id":70902603},{"atl":[[4,1],[3.9,10.74]],"id":70053016}],"con":true,"img":false}]}
{"op":"mcm","clk":"11541572164","pt":1719507222516,"mc":[{"id":"1.230178329","rc":[{"atb":[[1.84,0],[1.91,7.5]],"id":70053016}],"con":true,"img":false}]}
{"op":"mcm","clk":"11541572177","pt":1719507222729,"mc":[{"id":"1.230178329","rc":[{"atl":[[4.6,2.5],[3.95,25.72]],"id":70902603}],"con":true,"img":false}]}
{"op":"mcm","clk":"11541572263","pt":1719507223540,"mc":[{"id":"1.230178329","rc":[{"atb":[[2.66,0],[2.7,11.34]],"id":64812720}],"con":true,"img":false}]}
{"op":"mcm","clk":"11541572295","pt":1719507224006,"mc":[{"id":"1.230178329","rc":[{"atl":[[5.5,0],[5.4,1]],"id":66686625},{"atb":[[1.41,14.44]],"id":53082422}],"con":true,"img":false}]}
{"op":"mcm","clk":"11541572301","pt":1719507224112,"mc":[{"id":"1.230178329","rc":[{"atb":[[2.12,2.11],[2.16,8.04]],"id":70902603}],"con":true,"img":false}]}
{"op":"mcm","clk":"11541572325","pt":1719507224424,"mc":[{"id":"1.230178329","rc":[{"atb":[[2.14,7.06]],"id":70902603}],"con":true,"img":false}]}
{"op":"mcm","clk":"11541572333","pt":1719507224529,"mc":[{"id":"1.230178329","rc":[{"atb":[[2.18,2]],"id":70902603}],"con":true,"img":false}]}
{"op":"mcm","clk":"11541572490","pt":1719507226224,"mc":[{"id":"1.230178329","rc":[{"atl":[[5.6,1],[5.4,0]],"id":66686625},{"atl":[[4,0],[4.1,1]],"id":70053016},{"atl":[[10.5,15.53],[11,1]],"id":69942666}],"con":true,"img":false}]}
{"op":"mcm","clk":"11541572571","pt":1719507226944,"mc":[{"id":"1.230178329","rc":[{"atl":[[6.4,0],[6.8,7.25]],"id":64812720},{"atl":[[4.5,1],[4.7,0]],"id":70902603},{"atb":[[2.32,0],[2.42,7.5]],"id":66686625},{"atb":[[3.7,27.06],[3.75,0]],"id":69942666},{"atb":[[1.48,6.1]],"id":53082422}],"con":true,"img":false}]}
{"op":"mcm","clk":"11541572595","pt":1719507227146,"mc":[{"id":"1.230178329","rc":[{"atl":[[8.2,15],[6.8,1]],"id":64812720}],"con":true,"img":false}]}
{"op":"mcm","clk":"11541572755","pt":1719507229101,"mc":[{"id":"1.230178329","rc":[{"atb":[[2.46,0]],"id":66686625},{"atl":[[4.3,0]],"id":66686625},{"atb":[[2.36,0]],"id":70053016},{"atl":[[3.8,2.25]],"id":70053016},{"atb":[[1.49,0]],"id":53082422},{"atl":[[2.56,0]],"id":53082422}],"con":true,"img":false}]}
{"op":"mcm","clk":"11541572761","pt":1719507229204,"mc":[{"id":"1.230178329","rc":[{"atb":[[2.16,0],[2.14,17.1]],"id":70902603}],"con":true,"img":false}]}
{"op":"mcm","clk":"11541572767","pt":1719507229304,"mc":[{"id":"1.230178329","rc":[{"atl":[[5.6,13.37],[5.2,0]],"id":66686625}],"con":true,"img":false}]}
{"op":"mcm","clk":"11541572796","pt":1719507229661,"mc":[{"id":"1.230178329","rc":[{"atb":[[2.76,14.88]],"id":64812720},{"atb":[[2.18,0]],"id":70902603}],"con":true,"img":false}]}
{"op":"mcm","clk":"11541572803","pt":1719507229727,"mc":[{"id":"1.230178329","rc":[{"atb":[[2.7,2.5]],"id":64812720},{"atb":[[2.16,2]],"id":70902603}],"con":true,"img":false}]}
{"op":"mcm","clk":"11541572911","pt":1719507231111,"mc":[{"id":"1.230178329","rc":[{"atb":[[2.16,5.09]],"id":70902603}],"con":true,"img":false}]}
{"op":"mcm","clk":"11541572920","pt":1719507231213,"mc":[{"id":"1.230178329","rc":[{"atb":[[2.76,12.08]],"id":64812720},{"atb":[[2.14,10.04]],"id":70902603},{"atb":[[2.76,6.86]],"id":66686625}],"con":true,"img":false}]}
{"op":"mcm","clk":"11541572931","pt":1719507231320,"mc":[{"id":"1.230178329","rc":[{"atb":[[2.8,3]],"id":64812720},{"atb":[[2.16,7.89]],"id":70902603},{"atb":[[2.78,4]],"id":66686625}],"con":true,"img":false}]}
{"op":"mcm","clk":"11541572946","pt":1719507231426,"mc":[{"id":"1.230178329","rc":[{"atb":[[2.76,0],[2.7,20.62]],"id":64812720}],"con":true,"img":false}]}
{"op":"mcm","clk":"11541572959","pt":1719507231530,"mc":[{"id":"1.230178329","rc":[{"atb":[[2.82,8.47]],"id":64812720}],"con":true,"img":false}]}
{"op":"mcm","clk":"11541572979","pt":1719507231730,"mc":[{"id":"1.230178329","rc":[{"atb":[[2.78,0]],"id":64812720}],"con":true,"img":false}]}
{"op":"mcm","clk":"11541572985","pt":1719507231828,"mc":[{"id":"1.230178329","rc":[{"atb":[[2.78,11.6]],"id":66686625}],"con":true,"img":false}]}
{"op":"mcm","clk":"11541572999","pt":1719507231937,"mc":[{"id":"1.230178329","rc":[{"atl":[[3.9,8.35]],"id":70902603},{"atb":[[2.76,0]],"id":66686625}],"con":true,"img":false}]}
{"op":"mcm","clk":"11541573021","pt":1719507232142,"mc":[{"id":"1.230178329","rc":[{"atl":[[3.95,14.43]],"id":70902603}],"con":true,"img":false}]}
{"op":"mcm","clk":"11541573037","pt":1719507232250,"mc":[{"id":"1.230178329","rc":[{"atl":[[4.5,23.79]],"id":70902603}],"con":true,"img":false}]}
{"op":"mcm","clk":"11541573043","pt":1719507232355,"mc":[{"id":"1.230178329","rc":[{"atl":[[3.95,1.57]],"id":70902603}],"con":true,"img":false}]}
{"op":"mcm","clk":"11541573053","pt":1719507232403,"mc":[{"id":"1.230178329","rc":[{"atl":[[4.5,1],[3.95,18.29]],"id":70902603}],"con":true,"img":false}]}
{"op":"mcm","clk":"11541573064","pt":1719507232611,"mc":[{"id":"1.230178329","rc":[{"atl":[[4.5,10.93],[3.95,1.57]],"id":70902603}],"con":true,"img":false}]}
{"op":"mcm","clk":"11541573248","pt":1719507235340,"mc":[{"id":"1.230178329","rc":[{"atb":[[1.48,15.93]],"id":53082422}],"con":true,"img":false}]}
{"op":"mcm","clk":"11541573309","pt":1719507236221,"mc":[{"id":"1.230178329","rc":[{"atl":[[7,1]],"id":64812720},{"atl":[[2.82,1],[3.35,0]],"id":53082422}],"con":true,"img":false}]}
{"op":"mcm","clk":"11541573318","pt":1719507236319,"mc":[{"id":"1.230178329","rc":[{"atl":[[6.8,0]],"id":64812720},{"atb":[[1.48,6.1]],"id":53082422}],"con":true,"img":false}]}
{"op":"mcm","clk":"11541573395","pt":1719507237348,"mc":[{"id":"1.230178329","rc":[{"atb":[[1.48,15.93]],"id":53082422}],"con":true,"img":false}]}
{"op":"mcm","clk":"11541573405","pt":1719507237448,"mc":[{"id":"1.230178329","rc":[{"atb":[[2.8,19.94],[2.7,2.5]],"id":64812720}],"con":true,"img":false}]}
{"op":"mcm","clk":"11541573432","pt":1719507237816,"mc":[{"id":"1.230178329","rc":[{"atb":[[1.51,2.11],[1.47,0]],"id":53082422}],"con":true,"img":false}]}
{"op":"mcm","clk":"11541573476","pt":1719507238428,"mc":[{"id":"1.230178329","rc":[{"atb":[[1.48,13.93]],"id":53082422}],"con":true,"img":false}]}
{"op":"mcm","clk":"11541573485","pt":1719507238534,"mc":[{"id":"1.230178329","rc":[{"atb":[[1.52,2]],"id":53082422}],"con":true,"img":false}]}
{"op":"mcm","clk":"11541573495","pt":1719507238635,"mc":[{"id":"1.230178329","rc":[{"atl":[[4.5,1],[3.95,18.29]],"id":70902603}],"con":true,"img":false}]}
{"op":"mcm","clk":"11541573569","pt":1719507239556,"mc":[{"id":"1.230178329","rc":[{"atl":[[3.95,16.72]],"id":70902603}],"con":true,"img":false}]}
{"op":"mcm","clk":"11541573590","pt":1719507239814,"mc":[{"id":"1.230178329","rc":[{"atl":[[4.1,1.57]],"id":70902603}],"con":true,"img":false}]}
{"op":"mcm","clk":"11541573628","pt":1719507240342,"mc":[{"id":"1.230178329","rc":[{"atb":[[2.82,20.15]],"id":64812720},{"atb":[[2.78,24.12]],"id":66686625},{"atb":[[3.95,20.88]],"id":69942666},{"atl":[[9.2,9.14]],"id":69942666}],"con":true,"img":false}]}
{"op":"mcm","clk":"11541573644","pt":1719507240540,"mc":[{"id":"1.230178329","rc":[{"atl":[[10,11.11],[10.5,5]],"id":69942666}],"con":true,"img":false}]}
{"op":"mcm","clk":"11541573767","pt":1719507241943,"mc":[{"id":"1.230178329","rc":[{"atb":[[2.14,14.5]],"id":70902603},{"atl":[[3.75,4.4]],"id":70053016},{"atl":[[2.54,3.54]],"id":53082422}],"con":true,"img":false}]}
{"op":"mcm","clk":"11541573779","pt":1719507242051,"mc":[{"id":"1.230178329","rc":[{"atl":[[3.7,2.25],[3.9,0]],"id":70053016},{"atl":[[2.82,15.02],[2.96,0]],"id":53082422}],"con":true,"img":false}]}
{"op":"mcm","clk":"11541573796","pt":1719507242252,"mc":[{"id":"1.230178329","rc":[{"atl":[[3.8,0]],"id":70053016}],"con":true,"img":false}]}
{"op":"mcm","clk":"11541573805","pt":1719507242354,"mc":[{"id":"1.230178329","rc":[{"atb":[[2.22,4.85]],"id":70902603}],"con":true,"img":false}]}
{"op":"mcm","clk":"11541573813","pt":1719507242465,"mc":[{"id":"1.230178329","rc":[{"atl":[[3.85,0],[3.65,0.84]],"id":70053016}],"con":true,"img":false}]}
{"op":"mcm","clk":"11541573864","pt":1719507242976,"mc":[{"id":"1.230178329","rc":[{"atb":[[2.76,3.2]],"id":64812720}],"con":true,"img":false}]}
{"op":"mcm","clk":"11541573889","pt":1719507243183,"mc":[{"id":"1.230178329","rc":[{"atb":[[2.16,5.89]],"id":70902603}],"con":true,"img":false}]}
{"op":"mcm","clk":"11541573900","pt":1719507243288,"mc":[{"id":"1.230178329","rc":[{"atb":[[2.24,2]],"id":70902603}],"con":true,"img":false}]}
{"op":"mcm","clk":"11541573922","pt":1719507243454,"mc":[{"id":"1.230178329","rc":[{"atb":[[2.76,0]],"id":64812720},{"atb":[[2.14,10.04]],"id":70902603}],"con":true,"img":false}]}
{"op":"mcm","clk":"11541573943","pt":1719507243761,"mc":[{"id":"1.230178329","rc":[{"atl":[[4,25.08],[3.95,0]],"id":70902603}],"con":true,"img":false}]}
{"op":"mcm","clk":"11541573954","pt":1719507243960,"mc":[{"id":"1.230178329","rc":[{"atl":[[2.54,0]],"id":53082422}],"con":true,"img":false}]}
{"op":"mcm","clk":"11541573966","pt":1719507244062,"mc":[{"id":"1.230178329","rc":[{"atb":[[2.24,10.06]],"id":70902603}],"con":true,"img":false}]}
{"op":"mcm","clk":"11541573978","pt":1719507244267,"mc":[{"id":"1.230178329","rc":[{"atb":[[2.16,2.8]],"id":70902603}],"con":true,"img":false}]}
{"op":"mcm","clk":"11541574070","pt":1719507245356,"mc":[{"id":"1.230178329","rc":[{"atb":[[2.8,16.94]],"id":64812720},{"spn":2.8,"spf":1.0,"id":64812720},{"atb":[[2.16,0]],"id":70902603},{"spn":3.07,"spf":"NaN","id":70902603},{"atb":[[2.78,22.12]],"id":66686625},{"spn":3.59,"spf":"NaN","id":66686625},{"spn":3.01,"spf":"NaN","id":70053016},{"spn":6.57,"spf":"NaN","id":69942666},{"atb":[[1.48,9.83]],"id":53082422}],"con":true,"img":false}]}
{"op":"mcm","clk":"11541574077","pt":1719507245459,"mc":[{"id":"1.230178329","rc":[{"atb":[[2.84,4.1]],"id":64812720},{"atb":[[2.26,3.3]],"id":70902603},{"atb":[[2.4,2.32]],"id":70053016},{"atb":[[1.52,6.4]],"id":53082422}],"con":true,"img":false}]}
{"op":"mcm","clk":"11541574085","pt":1719507245562,"mc":[{"id":"1.230178329","rc":[{"atb":[[2.86,15.19]],"id":64812720},{"atb":[[2.4,5.94]],"id":70053016}],"con":true,"img":false}]}
{"op":"mcm","clk":"11541574101","pt":1719507245763,"mc":[{"id":"1.230178329","rc":[{"atb":[[2.82,11.68]],"id":64812720},{"atb":[[2.38,2]],"id":70053016}],"con":true,"img":false}]}
{"op":"mcm","clk":"11541574128","pt":1719507246067,"mc":[{"id":"1.230178329","rc":[{"atb":[[2.38,0]],"id":70053016}],"con":true,"img":false}]}
{"op":"mcm","clk":"11541574138","pt":1719507246171,"mc":[{"id":"1.230178329","rc":[{"atb":[[2.42,2]],"id":70053016}],"con":true,"img":false}]}
{"op":"mcm","clk":"11541574155","pt":1719507246376,"mc":[{"id":"1.230178329","rc":[{"atb":[[2.8,0],[2.76,26.87]],"id":64812720},{"atl":[[7.2,1],[7,0]],"id":64812720},{"atl":[[6,0],[6.8,0],[7.6,0],[6.6,5],[5.9,2.5]],"id":66686625},{"atb":[[3.7,0],[3.65,37.74]],"id":69942666}],"con":true,"img":false}]}
{"op":"mcm","clk":"11541574167","pt":1719507246479,"mc":[{"id":"1.230178329","rc":[{"atb":[[2.24,8.06]],"id":70902603}],"con":true,"img":false}]}
{"op":"mcm","clk":"11541574174","pt":1719507246582,"mc":[{"id":"1.230178329","rc":[{"atb":[[2.28,2]],"id":70902603},{"atb":[[3.65,52.3]],"id":69942666}],"con":true,"img":false}]}
{"op":"mcm","clk":"11541574191","pt":1719507246787,"mc":[{"id":"1.230178329","rc":[{"atb":[[3.65,37.74]],"id":69942666}],"con":true,"img":false}]}
{"op":"mcm","clk":"11541574214","pt":1719507246954,"mc":[{"id":"1.230178329","rc":[{"atb":[[2.82,10.97]],"id":64812720}],"con":true,"img":false}]}
{"op":"mcm","clk":"11541574236","pt":1719507247167,"mc":[{"id":"1.230178329","rc":[{"atb":[[2.82,0]],"id":64812720},{"atl":[[3.7,0]],"id":70053016}],"con":true,"img":false}]}
{"op":"mcm","clk":"11541574246","pt":1719507247257,"mc":[{"id":"1.230178329","rc":[{"atb":[[2.86,26.16]],"id":64812720},{"atl":[[3.75,7.5]],"id":70053016}],"con":true,"img":false}]}
{"op":"mcm","clk":"11541574255","pt":1719507247380,"mc":[{"id":"1.230178329","rc":[{"atl":[[4.1,9.36],[3.75,4.4]],"id":70053016}],"con":true,"img":false}]}
{"op":"mcm","clk":"11541574309","pt":1719507247974,"mc":[{"id":"1.230178329","rc":[{"atl":[[3.65,0]],"id":70053016}],"con":true,"img":false}]}
{"op":"mcm","clk":"11541574321","pt":1719507248077,"mc":[{"id":"1.230178329","rc":[{"atl":[[4.9,16.27]],"id":70053016}],"con":true,"img":false}]}
{"op":"mcm","clk":"11541574332","pt":1719507248179,"mc":[{"id":"1.230178329","rc":[{"atl":[[4.1,1]],"id":70053016}],"con":true,"img":false}]}
{"op":"mcm","clk":"11541574472","pt":1719507249980,"mc":[{"id":"1.230178329","rc":[{"atb":[[2.3,2.11],[2.12,0]],"id":70902603}],"con":true,"img":false}]}
{"op":"mcm","clk":"11541574513","pt":1719507250458,"mc":[{"id":"1.230178329","rc":[{"atb":[[2.28,0]],"id":70902603}],"con":true,"img":false}]}
{"op":"mcm","clk":"11541574522","pt":1719507250562,"mc":[{"id":"1.230178329","rc":[{"atb":[[2.32,2]],"id":70902603}],"con":true,"img":false}]}
{"op":"mcm","clk":"11541574607","pt":1719507251577,"mc":[{"id":"1.230178329","rc":[{"atb":[[2.76,0],[2.78,30.26]],"id":64812720},{"atb":[[2.42,0],[2.48,15]],"id":66686625},{"atb":[[3.85,35.09],[3.65,0]],"id":69942666},{"atl":[[10,0],[10.5,15.53]],"id":69942666}],"con":true,"img":false}]}
{"op":"mcm","clk":"11541574845","pt":1719507254469,"mc":[{"id":"1.230178329","rc":[{"atl":[[4.5,0],[4.4,1],[4.7,1]],"id":70902603},{"atl":[[5.6,12.37],[5.1,1],[5.3,1]],"id":66686625},{"atl":[[4.3,1],[4.1,0],[4.4,1]],"id":70053016},{"atl":[[10,1],[10.5,16.53],[11,0]],"id":69942666},{"atl":[[2.82,14.02],[3.1,1],[3.3,1]],"id":53082422}],"con":true,"img":false}]}
{"op":"mcm","clk":"11541574857","pt":1719507254673,"mc":[{"id":"1.230178329","rc":[{"atl":[[5.6,0],[5.2,7.14]],"id":66686625},{"atl":[[4.9,2.5],[4.2,8.82]],"id":70053016}],"con":true,"img":false}]}
{"op":"mcm","clk":"11541574884","pt":1719507255080,"mc":[{"id":"1.230178329","rc":[{"atl":[[4.5,1],[4.4,0]],"id":70902603},{"atl":[[4.3,0]],"id":70053016},{"atl":[[3.3,0]],"id":53082422}],"con":true,"img":false}]}
{"op":"mcm","clk":"11541574892","pt":1719507255182,"mc":[{"id":"1.230178329","rc":[{"atl":[[5.1,0],[5.3,0]],"id":66686625},{"atl":[[4.5,1]],"id":70053016},{"atl":[[10.5,15.53]],"id":69942666}],"con":true,"img":false}]}
{"op":"mcm","clk":"11541574901","pt":1719507255285,"mc":[{"id":"1.230178329","rc":[{"atl":[[4.7,0]],"id":70902603},{"atl":[[4.4,0]],"id":70053016}],"con":true,"img":false}]}
{"op":"mcm","clk":"11541574953","pt":1719507256067,"mc":[{"id":"1.230178329","rc":[{"atl":[[4.5,0],[4.7,1]],"id":70902603},{"atl":[[5.1,1],[5.3,1]],"id":66686625},{"atl":[[4.5,0],[4.4,1]],"id":70053016},{"atl":[[10,0],[10.5,16.53]],"id":69942666},{"atl":[[3.1,0],[3.15,1],[3.3,1]],"id":53082422}],"con":true,"img":false}]}
{"op":"mcm","clk":"11541574962","pt":1719507256176,"mc":[{"id":"1.230178329","rc":[{"atl":[[4.4,1]],"id":70902603},{"atl":[[4.3,1]],"id":70053016}],"con":true,"img":false}]}
{"op":"mcm","clk":"11541574980","pt":1719507256386,"mc":[{"id":"1.230178329","rc":[{"atl":[[4.5,1],[4.4,0]],"id":70902603}],"con":true,"img":false}]}
{"op":"mcm","clk":"11541574995","pt":1719507256480,"mc":[{"id":"1.230178329","rc":[{"atl":[[5.1,0],[5.3,0]],"id":66686625},{"atl":[[4.3,0]],"id":70053016},{"atl":[[3.3,0]],"id":53082422}],"con":true,"img":false}]}
{"op":"mcm","clk":"11541575011","pt":1719507256678,"mc":[{"id":"1.230178329","rc":[{"atb":[[2.32,6.06]],"id":70902603}],"con":true,"img":false}]}
{"op":"mcm","clk":"11541575025","pt":1719507256886,"mc":[{"id":"1.230178329","rc":[{"atb":[[2.24,0]],"id":70902603}],"con":true,"img":false}]}
{"op":"mcm","clk":"11541575062","pt":1719507257298,"mc":[{"id":"1.230178329","rc":[{"atl":[[4.4,1]],"id":70902603},{"atl":[[4,1],[4.4,0]],"id":70053016},{"atl":[[2.8,1]],"id":53082422}],"con":true,"img":false}]}
{"op":"mcm","clk":"11541575073","pt":1719507257401,"mc":[{"id":"1.230178329","rc":[{"atb":[[2.74,52.32],[2.78,0]],"id":64812720},{"atl":[[7.2,0],[8.6,5],[6.2,1],[8.2,12.5],[7.8,2.5],[9.4,10]],"id":64812720},{"atb":[[2.3,14.23],[2.14,0]],"id":70902603},{"atl":[[4,0],[4.5,0],[4.3,1],[4.1,33.83],[4.7,0]],"id":70902603},{"atb":[[2.48,0],[2.34,15]],"id":66686625},{"atl":[[5.6,1],[5.9,3.5]],"id":66686625},{"atb":[[2.32,0],[1.85,10],[2.4,2.32],[2.24,0],[1.91,0],[1.66,0],[2.16,0]],"id":70053016},{"atb":[[4,20.88],[3.85,0]],"id":69942666},{"atl":[[10.5,0],[11,10],[12,1],[12.5,0],[9.4,0]],"id":69942666},{"atb":[[1.37,0],[1.43,2.5],[1.33,0],[1.29,0],[1.42,12.8],[1.52,16.46]],"id":53082422},{"atl":[[2.82,0],[3.15,0],[2.96,21.03]],"id":53082422}],"con":true,"img":false}]}
{"op":"mcm","clk":"11541575081","pt":1719507257503,"mc":[{"id":"1.230178329","rc":[{"atl":[[7.2,10.5]],"id":64812720},{"atb":[[4,40.14]],"id":69942666},{"atb":[[1.42,0]],"id":53082422}],"con":true,"img":false}]}
{"op":"mcm","clk":"11541575091","pt":1719507257572,"mc":[{"id":"1.230178329","rc":[{"atl":[[8.2,0]],"id":64812720},{"atb":[[2.3,2.11]],"id":70902603},{"atl":[[4.3,0],[4.4,0]],"id":70902603},{"atb":[[1.89,5],[1.85,20],[1.93,2.5]],"id":70053016},{"atb":[[3.95,9.78]],"id":69942666},{"atl":[[17.5,10],[11,0],[13.5,2.5],[15.5,5]],"id":69942666},{"atb":[[1.36,22.63],[1.48,0]],"id":53082422}],"con":true,"img":false}]}
{"op":"mcm","clk":"11541575100","pt":1719507257674,"mc":[{"id":"1.230178329","rc":[{"atb":[[2.16,10.92]],"id":70902603},{"atl":[[4.6,3.5]],"id":70902603},{"atl":[[5.6,0]],"id":66686625},{"atl":[[4,0],[4.6,1]],"id":70053016},{"atl":[[13.5,10.5]],"id":69942666},{"atl":[[2.8,0],[3.3,1]],"id":53082422}],"con":true,"img":false}]}
{"op":"mcm","clk":"11541575120","pt":1719507257874,"mc":[{"id":"1.230178329","rc":[{"atl":[[9.2,8.06]],"id":69942666}],"con":true,"img":false}]}
{"op":"mcm","clk":"11541575140","pt":1719507258083,"mc":[{"id":"1.230178329","rc":[{"atl":[[9.2,6.02]],"id":69942666}],"con":true,"img":false}]}
{"op":"mcm","clk":"11541575148","pt":1719507258182,"mc":[{"id":"1.230178329","rc":[{"atl":[[11.5,2.04]],"id":69942666}],"con":true,"img":false}]}
{"op":"mcm","clk":"11541575156","pt":1719507258282,"mc":[{"id":"1.230178329","rc":[{"atb":[[2.42,0]],"id":70053016}],"con":true,"img":false}]}
{"op":"mcm","clk":"11541575165","pt":1719507258379,"mc":[{"id":"1.230178329","rc":[{"atb":[[1.02,2]],"id":70053016}],"con":true,"img":false}]}
{"op":"mcm","clk":"11541575198","pt":1719507258788,"mc":[{"id":"1.230178329","rc":[{"atl":[[4.3,1]],"id":70902603},{"atl":[[4,1],[4.6,0]],"id":70053016},{"atl":[[2.8,1]],"id":53082422}],"con":true,"img":false}]}
{"op":"mcm","clk":"11541575207","pt":1719507258891,"mc":[{"id":"1.230178329","rc":[{"atl":[[4.6,2.5]],"id":70902603},{"atl":[[3.3,0]],"id":53082422}],"con":true,"img":false}]}
{"op":"mcm","clk":"11541575253","pt":1719507259404,"mc":[{"id":"1.230178329","rc":[{"atb":[[2.84,0]],"id":64812720},{"atb":[[2.26,0]],"id":70902603},{"atb":[[2.4,0]],"id":70053016},{"atb":[[3.95,7.35]],"id":69942666},{"atb":[[1.52,12.06]],"id":53082422}],"con":true,"img":false}]}
{"op":"mcm","clk":"11541575262","pt":1719507259508,"mc":[{"id":"1.230178329","rc":[{"atb":[[2.88,3.59]],"id":64812720},{"atb":[[2.34,3.44]],"id":70902603},{"atb":[[2.8,3]],"id":66686625},{"atb":[[1.96,3],[1.95,7.29]],"id":70053016},{"atb":[[4.1,3]],"id":69942666},{"atb":[[1.53,5.1]],"id":53082422}],"con":true,"img":false}]}
{"op":"mcm","clk":"11541575274","pt":1719507259613,"mc":[{"id":"1.230178329","rc":[{"atb":[[2.9,11.81]],"id":64812720},{"atb":[[2.8,10.23]],"id":66686625}],"con":true,"img":false}]}
{"op":"mcm","clk":"11541575292","pt":1719507259774,"mc":[{"id":"1.230178329","rc":[{"atb":[[2.86,10.97]],"id":64812720},{"atb":[[2.78,14.52]],"id":66686625}],"con":true,"img":false}]}
{"op":"mcm","clk":"11541575299","pt":1719507259876,"mc":[{"id":"1.230178329","rc":[{"atl":[[5.2,0],[5.9,16.78]],"id":66686625}],"con":true,"img":false}]}
{"op":"mcm","clk":"11541575340","pt":1719507260288,"mc":[{"id":"1.230178329","rc":[{"atb":[[2.86,0]],"id":64812720},{"atb":[[2.78,2]],"id":66686625},{"atb":[[3.95,7.33]],"id":69942666},{"atb":[[1.52,10.06]],"id":53082422}],"con":true,"img":false}]}
{"op":"mcm","clk":"11541575351","pt":1719507260390,"mc":[{"id":"1.230178329","rc":[{"atb":[[1.54,2]],"id":53082422}],"con":true,"img":false}]}
{"op":"mcm","clk":"11541575371","pt":1719507260595,"mc":[{"id":"1.230178329","rc":[{"atb":[[3.95,0]],"id":69942666}],"con":true,"img":false}]}
{"op":"mcm","clk":"11541575383","pt":1719507260697,"mc":[{"id":"1.230178329","rc":[{"atb":[[4.1,10.33]],"id":69942666}],"con":true,"img":false}]}
{"op":"mcm","clk":"11541575389","pt":1719507260800,"mc":[{"id":"1.230178329","rc":[{"atb":[[1.02,0]],"id":70053016}],"con":true,"img":false}]}
{"op":"mcm","clk":"11541575396","pt":1719507260903,"mc":[{"id":"1.230178329","rc":[{"atb":[[1.97,2]],"id":70053016}],"con":true,"img":false}]}
{"op":"mcm","clk":"11541575413","pt":1719507261110,"mc":[{"id":"1.230178329","rc":[{"atb":[[2.9,23.46]],"id":64812720},{"atb":[[2.8,22.01]],"id":66686625}],"con":true,"img":false}]}
{"op":"mcm","clk":"11541575436","pt":1719507261381,"mc":[{"id":"1.230178329","rc":[{"atl":[[4.1,32.26]],"id":70902603},{"atb":[[2.78,0]],"id":66686625}],"con":true,"img":false}]}
{"op":"mcm","clk":"11541575444","pt":1719507261480,"mc":[{"id":"1.230178329","rc":[{"atb":[[2.82,2]],"id":66686625}],"con":true,"img":false}]}
{"op":"mcm","clk":"11541575461","pt":1719507261680,"mc":[{"id":"1.230178329","rc":[{"atl":[[4,1.57]],"id":70902603}],"con":true,"img":false}]}
{"op":"mcm","clk":"11541575470","pt":1719507261784,"mc":[{"id":"1.230178329","rc":[{"atb":[[2.32,4.06]],"id":70902603}],"con":true,"img":false}]}
{"op":"mcm","clk":"11541575478","pt":1719507261882,"mc":[{"id":"1.230178329","rc":[{"atb":[[2.36,2]],"id":70902603},{"atb":[[2.8,10.23]],"id":66686625}],"con":true,"img":false}]}
{"op":"mcm","clk":"11541575485","pt":1719507261986,"mc":[{"id":"1.230178329","rc":[{"atl":[[4,0],[4.3,0],[4.6,3.5]],"id":70902603},{"atl":[[4,0],[4.6,1]],"id":70053016}],"con":true,"img":false}]}
{"op":"mcm","clk":"11541575507","pt":1719507262195,"mc":[{"id":"1.230178329","rc":[{"atb":[[2.74,0]],"id":64812720},{"atl":[[7.2,1],[6.2,0]],"id":64812720},{"atb":[[2.16,0]],"id":70902603},{"atb":[[2.46,10],[2.34,0]],"id":66686625},{"atb":[[4,19.26]],"id":69942666},{"atb":[[1.52,0]],"id":53082422},{"atl":[[2.8,0],[3.3,1]],"id":53082422}],"con":true,"img":false}]}
{"op":"mcm","clk":"11541575515","pt":1719507262301,"mc":[{"id":"1.230178329","rc":[{"atb":[[2.76,27.05]],"id":64812720},{"atl":[[7.8,8.75]],"id":64812720},{"atb":[[2.12,6.88]],"id":70902603},{"atl":[[3.95,1.57]],"id":70902603},{"atb":[[3.8,32.09]],"id":69942666}],"con":true,"img":false}]}
{"op":"mcm","clk":"11541575530","pt":1719507262506,"mc":[{"id":"1.230178329","rc":[{"atl":[[3.95,0]],"id":70902603}],"con":true,"img":false}]}
{"op":"mcm","clk":"11541575539","pt":1719507262609,"mc":[{"id":"1.230178329","rc":[{"atl":[[4.6,31.28]],"id":70902603}],"con":true,"img":false}]}
{"op":"mcm","clk":"11541575544","pt":1719507262671,"mc":[{"id":"1.230178329","rc":[{"atl":[[4.1,0]],"id":70902603},{"atb":[[2.82,14.51]],"id":66686625}],"con":true,"img":false}]}
{"op":"mcm","clk":"11541575550","pt":1719507262776,"mc":[{"id":"1.230178329","rc":[{"atl":[[3.85,3.15]],"id":70902603}],"con":true,"img":false}]}
{"op":"mcm","clk":"11541575559","pt":1719507262876,"mc":[{"id":"1.230178329","rc":[{"atl":[[3.8,5.62]],"id":70902603}],"con":true,"img":false}]}
{"op":"mcm","clk":"11541575567","pt":1719507262979,"mc":[{"id":"1.230178329","rc":[{"atl":[[3.85,0]],"id":70902603}],"con":true,"img":false}]}
{"op":"mcm","clk":"11541575580","pt":1719507263094,"mc":[{"id":"1.230178329","rc":[{"atl":[[3.9,0.84]],"id":70902603},{"atl":[[13.5,2.5]],"id":69942666}],"con":true,"img":false}]}
{"op":"mcm","clk":"11541575592","pt":1719507263193,"mc":[{"id":"1.230178329","rc":[{"atl":[[3.8,0]],"id":70902603},{"atl":[[11.5,11.56]],"id":69942666}],"con":true,"img":false}]}
{"op":"mcm","clk":"11541575605","pt":1719507263286,"mc":[{"id":"1.230178329","rc":[{"atl":[[3.95,5.62]],"id":70902603}],"con":true,"img":false}]}
{"op":"mcm","clk":"11541575613","pt":1719507263388,"mc":[{"id":"1.230178329","rc":[{"atl":[[3.85,1.57]],"id":70902603}],"con":true,"img":false}]}
{"op":"mcm","clk":"11541575621","pt":1719507263491,"mc":[{"id":"1.230178329","rc":[{"atl":[[3.9,0],[3.75,0.84]],"id":70902603}],"con":true,"img":false}]}
{"op":"mcm","clk":"11541575668","pt":1719507264108,"mc":[{"id":"1.230178329","rc":[{"atl":[[3.85,0],[3.75,0]],"id":70902603}],"con":true,"img":false}]}
{"op":"mcm","clk":"11541575697","pt":1719507264374,"mc":[{"id":"1.230178329","rc":[{"atl":[[3.85,3.34]],"id":70902603}],"con":true,"img":false}]}
{"op":"mcm","clk":"11541575802","pt":1719507265908,"mc":[{"id":"1.230178329","rc":[{"atb":[[1.96,8.58]],"id":70053016},{"atb":[[1.47,5.38]],"id":53082422}],"con":true,"img":false}]}
{"op":"mcm","clk":"11541575810","pt":1719507266010,"mc":[{"id":"1.230178329","rc":[{"atl":[[4.6,14.23]],"id":70053016}],"con":true,"img":false}]}
{"op":"mcm","clk":"11541575822","pt":1719507266116,"mc":[{"id":"1.230178329","rc":[{"atl":[[4.2,0]],"id":70053016}],"con":true,"img":false}]}
{"op":"mcm","clk":"11541575840","pt":1719507266323,"mc":[{"id":"1.230178329","rc":[{"atb":[[1.99,2.11],[1.95,5.18]],"id":70053016}],"con":true,"img":false}]}
{"op":"mcm","clk":"11541575872","pt":1719507266791,"mc":[{"id":"1.230178329","rc":[{"atb":[[1.97,0]],"id":70053016}],"con":true,"img":false}]}
{"op":"mcm","clk":"11541575881","pt":1719507266926,"mc":[{"id":"1.230178329","rc":[{"atb":[[2.32,7.92]],"id":70902603},{"atb":[[2,2]],"id":70053016},{"atl":[[2.54,3.54]],"id":53082422}],"con":true,"img":false}]}
{"op":"mcm","clk":"11541575902","pt":1719507267201,"mc":[{"id":"1.230178329","rc":[{"atb":[[1.96,3]],"id":70053016}],"con":true,"img":false}]}
{"op":"mcm","clk":"11541575945","pt":1719507267817,"mc":[{"id":"1.230178329","rc":[{"atb":[[2.84,5.44]],"id":64812720}],"con":true,"img":false}]}
{"op":"mcm","clk":"11541575962","pt":1719507268024,"mc":[{"id":"1.230178329","rc":[{"atb":[[2.88,0]],"id":64812720},{"atb":[[2.34,0]],"id":70902603},{"atb":[[2.8,7.23]],"id":66686625},{"atb":[[1.96,0]],"id":70053016},{"atb":[[1.53,0]],"id":53082422}],"con":true,"img":false}]}
{"op":"mcm","clk":"11541575973","pt":1719507268129,"mc":[{"id":"1.230178329","rc":[{"atb":[[2.84,3.08],[2.92,3]],"id":64812720},{"atb":[[2.36,5]],"id":70902603},{"atb":[[2.84,3.1]],"id":66686625},{"atb":[[2,5.4]],"id":70053016},{"atb":[[1.54,4.3]],"id":53082422}],"con":true,"img":false}]}
{"op":"mcm","clk":"11541575990","pt":1719507268292,"mc":[{"id":"1.230178329","rc":[{"atl":[[4.6,3.5],[3.8,5.62]],"id":70902603}],"con":true,"img":false}]}
{"op":"mcm","clk":"11541576003","pt":1719507268491,"mc":[{"id":"1.230178329","rc":[{"atb":[[1.54,2.3]],"id":53082422}],"con":true,"img":false}]}
{"op":"mcm","clk":"11541576010","pt":1719507268591,"mc":[{"id":"1.230178329","rc":[{"atb":[[2.84,0]],"id":64812720},{"atb":[[2.32,4.06]],"id":70902603},{"atb":[[1.52,2]],"id":53082422}],"con":true,"img":false}]}
{"op":"mcm","clk":"11541576039","pt":1719507268901,"mc":[{"id":"1.230178329","rc":[{"atb":[[2.9,11.81]],"id":64812720},{"atb":[[2.36,3]],"id":70902603},{"atb":[[2.82,2]],"id":66686625}],"con":true,"img":false}]}
{"op":"mcm","clk":"11541576046","pt":1719507269005,"mc":[{"id":"1.230178329","rc":[{"atb":[[2.34,2]],"id":70902603}],"con":true,"img":false}]}
{"op":"mcm","clk":"11541576053","pt":1719507269108,"mc":[{"id":"1.230178329","rc":[{"atb":[[2.36,8.55]],"id":70902603}],"con":true,"img":false}]}
{"op":"mcm","clk":"11541576066","pt":1719507269314,"mc":[{"id":"1.230178329","rc":[{"atb":[[2.32,0]],"id":70902603}],"con":true,"img":false}]}
{"op":"mcm","clk":"11541576087","pt":1719507270015,"mc":[{"id":"1.230178329","rc":[{"atb":[[1.52,0]],"id":53082422}],"con":true,"img":false}]}
{"op":"mcm","clk":"11541576095","pt":1719507270027,"mc":[{"id":"1.230178329","rc":[{"atb":[[1.55,2]],"id":53082422}],"con":true,"img":false}]}
{"op":"mcm","clk":"11541576109","pt":1719507270047,"mc":[{"id":"1.230178329","rc":[{"atb":[[4.2,16.42]],"id":69942666}],"con":true,"img":false}]}
{"op":"mcm","clk":"11541576116","pt":1719507270057,"mc":[{"id":"1.230178329","rc":[{"atb":[[2.82,0]],"id":66686625}],"con":true,"img":false}]}
{"op":"mcm","clk":"11541576124","pt":1719507270096,"mc":[{"id":"1.230178329","rc":[{"atb":[[2.86,2]],"id":66686625},{"atb":[[4,0]],"id":69942666}],"con":true,"img":false}]}
{"op":"mcm","clk":"11541576137","pt":1719507270207,"mc":[{"id":"1.230178329","rc":[{"atb":[[2.92,16.16]],"id":64812720},{"atb":[[2.84,15.71]],"id":66686625}],"con":true,"img":false}]}
{"op":"mcm","clk":"11541576159","pt":1719507270498,"mc":[{"id":"1.230178329","rc":[{"atb":[[2.34,0]],"id":70902603},{"atl":[[3.75,0.84]],"id":70902603}],"con":true,"img":false}]}
{"op":"mcm","clk":"11541576166","pt":1719507270599,"mc":[{"id":"1.230178329","rc":[{"atb":[[2.38,2]],"id":70902603}],"con":true,"img":false}]}
{"op":"mcm","clk":"11541576216","pt":1719507271215,"mc":[{"id":"1.230178329","rc":[{"atb":[[2.84,3.1]],"id":66686625},{"atb":[[4.1,3]],"id":69942666}],"con":true,"img":false}]}
{"op":"mcm","clk":"11541576260","pt":1719507271790,"mc":[{"id":"1.230178329","rc":[{"atb":[[2,12.59]],"id":70053016}],"con":true,"img":false}]}
{"op":"mcm","clk":"11541576271","pt":1719507271899,"mc":[{"id":"1.230178329","rc":[{"atb":[[2.94,15.42]],"id":64812720},{"atb":[[2.86,21.33]],"id":66686625},{"atb":[[4.2,23.46]],"id":69942666}],"con":true,"img":false}]}
{"op":"mcm","clk":"11541576280","pt":1719507272001,"mc":[{"id":"1.230178329","rc":[{"atb":[[1.95,0]],"id":70053016}],"con":true,"img":false}]}
{"op":"mcm","clk":"11541576290","pt":1719507272095,"mc":[{"id":"1.230178329","rc":[{"atb":[[2.9,0]],"id":64812720},{"atb":[[2.8,0]],"id":66686625}],"con":true,"img":false}]}
{"op":"mcm","clk":"11541576344","pt":1719507272814,"mc":[{"id":"1.230178329","rc":[{"atb":[[2.92,13.98]],"id":64812720}],"con":true,"img":false}]}
{"op":"mcm","clk":"11541576352","pt":1719507272917,"mc":[{"id":"1.230178329","rc":[{"atb":[[2.92,3]],"id":64812720},{"atb":[[2.36,3]],"id":70902603},{"atl":[[4.6,1],[5,0],[5.4,0]],"id":70902603},{"atb":[[3.85,26.46],[3.8,2.5]],"id":69942666}],"con":true,"img":false}]}
{"op":"mcm","clk":"11541576360","pt":1719507273021,"mc":[{"id":"1.230178329","rc":[{"atb":[[2.94,26.4]],"id":64812720}],"con":true,"img":false}]}
{"op":"mcm","clk":"11541576390","pt":1719507273284,"mc":[{"id":"1.230178329","rc":[{"atb":[[4,3.63]],"id":69942666}],"con":true,"img":false}]}
{"op":"mcm","clk":"11541576505","pt":1719507275024,"mc":[{"id":"1.230178329","rc":[{"atb":[[1.41,0]],"id":53082422}],"con":true,"img":false}]}
{"op":"mcm","clk":"11541576522","pt":1719507275194,"mc":[{"id":"1.230178329","rc":[{"atl":[[3.75,4.68]],"id":70902603}],"con":true,"img":false}]}
{"op":"mcm","clk":"11541576536","pt":1719507275397,"mc":[{"id":"1.230178329","rc":[{"atl":[[3.95,0]],"id":70902603}],"con":true,"img":false}]}
{"op":"mcm","clk":"11541576557","pt":1719507275601,"mc":[{"id":"1.230178329","rc":[{"atl":[[4.5,2.5]],"id":70902603}],"con":true,"img":false}]}
{"op":"mcm","clk":"11541576613","pt":1719507276312,"mc":[{"id":"1.230178329","rc":[{"atl":[[5.8,1]],"id":66686625}],"con":true,"img":false}]}
{"op":"mcm","clk":"11541576622","pt":1719507276414,"mc":[{"id":"1.230178329","rc":[{"atl":[[5.9,15.78]],"id":66686625},{"atl":[[4.5,1],[4.6,13.23]],"id":70053016}],"con":true,"img":false}]}
{"op":"mcm","clk":"11541576659","pt":1719507276824,"mc":[{"id":"1.230178329","rc":[{"atb":[[2.92,0]],"id":64812720},{"atb":[[2.36,0]],"id":70902603},{"atb":[[2.84,0]],"id":66686625},{"atb":[[2,9.19]],"id":70053016},{"atb":[[4.1,0]],"id":69942666}],"con":true,"img":false}]}
{"op":"mcm","clk":"11541576667","pt":1719507276928,"mc":[{"id":"1.230178329","rc":[{"atb":[[2.96,2.53]],"id":64812720},{"atb":[[2.38,5]],"id":70902603},{"atb":[[2.88,3.55]],"id":66686625},{"atb":[[2.02,3.5]],"id":70053016},{"atb":[[4.3,2]],"id":69942666}],"con":true,"img":false}]}
{"op":"mcm","clk":"11541576685","pt":1719507277096,"mc":[{"id":"1.230178329","rc":[{"atb":[[4,0]],"id":69942666}],"con":true,"img":false}]}
{"op":"mcm","clk":"11541576694","pt":1719507277194,"mc":[{"id":"1.230178329","rc":[{"atb":[[2.22,0]],"id":70902603}],"con":true,"img":false}]}
{"op":"mcm","clk":"11541576708","pt":1719507277403,"mc":[{"id":"1.230178329","rc":[{"atb":[[2.94,15.42]],"id":64812720},{"atb":[[2.86,10.36]],"id":66686625},{"atb":[[4.2,16.42]],"id":69942666}],"con":true,"img":false}]}
{"op":"mcm","clk":"11541576722","pt":1719507277500,"mc":[{"id":"1.230178329","rc":[{"atb":[[1.38,15.58]],"id":53082422}],"con":true,"img":false}]}
{"op":"mcm","clk":"11541576742","pt":1719507277809,"mc":[{"id":"1.230178329","rc":[{"atb":[[2.06,5.58]],"id":70053016}],"con":true,"img":false}]}
{"op":"mcm","clk":"11541576757","pt":1719507278012,"mc":[{"id":"1.230178329","rc":[{"atb":[[2,7.19]],"id":70053016}],"con":true,"img":false}]}
{"op":"mcm","clk":"11541576766","pt":1719507278116,"mc":[{"id":"1.230178329","rc":[{"atl":[[4.6,0],[4.4,1]],"id":70902603},{"atl":[[5.8,0],[5.9,16.78]],"id":66686625},{"atb":[[2.04,2]],"id":70053016},{"atl":[[4.5,0],[4.4,1]],"id":70053016},{"atl":[[3.1,1],[3.3,0]],"id":53082422}],"con":true,"img":false}]}
{"op":"mcm","clk":"11541576774","pt":1719507278219,"mc":[{"id":"1.230178329","rc":[{"atb":[[2.96,13.64]],"id":64812720},{"atb":[[2.88,16.27]],"id":66686625},{"atb":[[4.3,8.95]],"id":69942666}],"con":true,"img":false}]}
{"op":"mcm","clk":"11541576822","pt":1719507278734,"mc":[{"id":"1.230178329","rc":[{"atb":[[2.86,8.36]],"id":66686625}],"con":true,"img":false}]}
{"op":"mcm","clk":"11541576832","pt":1719507278792,"mc":[{"id":"1.230178329","rc":[{"atb":[[2.9,2]],"id":66686625}],"con":true,"img":false}]}
{"op":"mcm","clk":"11541576848","pt":1719507278999,"mc":[{"id":"1.230178329","rc":[{"atb":[[2.88,3.55]],"id":66686625}],"con":true,"img":false}]}
{"op":"mcm","clk":"11541576859","pt":1719507279101,"mc":[{"id":"1.230178329","rc":[{"atl":[[4.6,1],[4.4,0]],"id":70902603},{"atl":[[5.8,1],[5.9,15.78]],"id":66686625},{"atl":[[4.5,1]],"id":70053016},{"atl":[[3.1,0],[3.3,1]],"id":53082422}],"con":true,"img":false}]}
{"op":"mcm","clk":"11541576867","pt":1719507279200,"mc":[{"id":"1.230178329","rc":[{"atl":[[4.4,0]],"id":70053016}],"con":true,"img":false}]}
{"op":"mcm","clk":"11541576899","pt":1719507279610,"mc":[{"id":"1.230178329","rc":[{"atb":[[2.04,0]],"id":70053016}],"con":true,"img":false}]}
{"op":"mcm","clk":"11541576908","pt":1719507279714,"mc":[{"id":"1.230178329","rc":[{"atb":[[2.08,2]],"id":70053016}],"con":true,"img":false}]}
{"op":"mcm","clk":"11541576914","pt":1719507279815,"mc":[{"id":"1.230178329","rc":[{"atb":[[2.9,15.33]],"id":66686625}],"con":true,"img":false}]}
{"op":"mcm","clk":"11541576927","pt":1719507280021,"mc":[{"id":"1.230178329","rc":[{"atb":[[2.92,3.88]],"id":64812720}],"con":true,"img":false}]}
{"op":"mcm","clk":"11541576944","pt":1719507280227,"mc":[{"id":"1.230178329","rc":[{"atl":[[4.6,0],[4.4,1]],"id":70902603},{"atl":[[5.8,0],[5.9,16.78]],"id":66686625},{"atl":[[4.5,0],[4.4,1]],"id":70053016},{"atl":[[3.1,1],[3.3,0]],"id":53082422}],"con":true,"img":false}]}
{"op":"mcm","clk":"11541576952","pt":1719507280330,"mc":[{"id":"1.230178329","rc":[{"atl":[[4.6,14.23]],"id":70053016}],"con":true,"img":false}]}
{"op":"mcm","clk":"11541576960","pt":1719507280433,"mc":[{"id":"1.230178329","rc":[{"atl":[[4.6,1],[4.4,0]],"id":70902603},{"atl":[[5.8,1]],"id":66686625},{"atl":[[4.5,1],[4.4,0]],"id":70053016},{"atl":[[3.1,0],[3.3,1]],"id":53082422}],"con":true,"img":false}]}
{"op":"mcm","clk":"11541576971","pt":1719507280492,"mc":[{"id":"1.230178329","rc":[{"atl":[[5.9,15.78]],"id":66686625},{"atl":[[4.3,1],[4.6,0],[4.4,8.82]],"id":70053016}],"con":true,"img":false}]}
{"op":"mcm","clk":"11541577017","pt":1719507281104,"mc":[{"id":"1.230178329","rc":[{"atb":[[2.92,0]],"id":64812720}],"con":true,"img":false}]}
{"op":"mcm","clk":"11541577070","pt":1719507281817,"mc":[{"id":"1.230178329","rc":[{"atl":[[4.6,0],[4.4,1]],"id":70902603},{"atl":[[5.8,0],[5.9,16.78]],"id":66686625},{"atl":[[4.3,0],[4.5,0],[4.4,9.82]],"id":70053016},{"atl":[[3.1,1],[3.3,0]],"id":53082422}],"con":true,"img":false}]}
{"op":"mcm","clk":"11541577082","pt":1719507282022,"mc":[{"id":"1.230178329","rc":[{"atl":[[4.9,16.73],[4.4,1]],"id":70053016},{"atb":[[4.4,15.38]],"id":69942666}],"con":true,"img":false}]}
{"op":"mcm","clk":"11541577097","pt":1719507282229,"mc":[{"id":"1.230178329","rc":[{"atb":[[4.2,0]],"id":69942666}],"con":true,"img":false}]}
{"op":"mcm","clk":"11541577179","pt":1719507283414,"mc":[{"id":"1.230178329","rc":[{"atb":[[4.3,8.43]],"id":69942666}],"con":true,"img":false}]}
{"op":"mcm","clk":"11541577185","pt":1719507283518,"mc":[{"id":"1.230178329","rc":[{"atl":[[4.6,1],[4.4,0]],"id":70902603},{"atl":[[5.8,1],[5.9,15.78]],"id":66686625},{"atl":[[4.5,1],[4.4,0]],"id":70053016},{"atb":[[4.3,2]],"id":69942666},{"atl":[[3.1,0],[3.3,1]],"id":53082422}],"con":true,"img":false}]}
{"op":"mcm","clk":"11541577193","pt":1719507283619,"mc":[{"id":"1.230178329","rc":[{"atb":[[4.4,21.81]],"id":69942666}],"con":true,"img":false}]}
{"op":"mcm","clk":"11541577215","pt":1719507283926,"mc":[{"id":"1.230178329","rc":[{"atb":[[2.08,7.93]],"id":70053016}],"con":true,"img":false}]}
{"op":"mcm","clk":"11541577222","pt":1719507284030,"mc":[{"id":"1.230178329","rc":[{"atb":[[2.98,10.5]],"id":64812720},{"atb":[[2.92,10.88]],"id":66686625}],"con":true,"img":false}]}
{"op":"mcm","clk":"11541577232","pt":1719507284131,"mc":[{"id":"1.230178329","rc":[{"atb":[[2,0]],"id":70053016}],"con":true,"img":false}]}
{"op":"mcm","clk":"11541577237","pt":1719507284236,"mc":[{"id":"1.230178329","rc":[{"atb":[[2.94,0],[2.96,2.53]],"id":64812720},{"atb":[[2.9,13.73],[2.86,0]],"id":66686625}],"con":true,"img":false}]}
{"op":"mcm","clk":"11541577249","pt":1719507284397,"mc":[{"id":"1.230178329","rc":[{"atb":[[2.9,2]],"id":66686625}],"con":true,"img":false}]}
{"op":"mcm","clk":"11541577256","pt":1719507284501,"mc":[{"id":"1.230178329","rc":[{"atl":[[4.6,0],[4.4,1]],"id":70902603},{"atb":[[2.92,22.61]],"id":66686625},{"atl":[[5.8,0],[5.9,16.78]],"id":66686625},{"atl":[[4.5,0],[4.4,1]],"id":70053016},{"atl":[[3.1,1],[3.3,0]],"id":53082422}],"con":true,"img":false}]}
{"op":"mcm","clk":"11541577266","pt":1719507284704,"mc":[{"id":"1.230178329","rc":[{"atb":[[2.9,0]],"id":66686625}],"con":true,"img":false}]}
{"op":"mcm","clk":"11541577272","pt":1719507284808,"mc":[{"id":"1.230178329","rc":[{"atb":[[2.94,2]],"id":66686625}],"con":true,"img":false}]}
{"op":"mcm","clk":"11541577279","pt":1719507284910,"mc":[{"id":"1.230178329","rc":[{"atb":[[2.98,21.67]],"id":64812720}],"con":true,"img":false}]}
{"op":"mcm","clk":"11541577308","pt":1719507285417,"mc":[{"id":"1.230178329","rc":[{"atb":[[2.96,0]],"id":64812720},{"atl":[[4.6,1]],"id":70902603},{"atb":[[2.88,0]],"id":66686625},{"atl":[[5.8,1]],"id":66686625},{"atb":[[2.02,0]],"id":70053016},{"atl":[[4.5,1],[4.4,0]],"id":70053016},{"atb":[[4.3,0]],"id":69942666},{"atl":[[3.1,0],[3.3,1]],"id":53082422}],"con":true,"img":false}]}
{"op":"mcm","clk":"11541577312","pt":1719507285520,"mc":[{"id":"1.230178329","rc":[{"atb":[[3,2]],"id":64812720},{"atl":[[4.4,0]],"id":70902603},{"atb":[[2.94,5.6]],"id":66686625},{"atl":[[5.8,0],[5.9,15.78]],"id":66686625},{"atb":[[2.1,2.7]],"id":70053016},{"atl":[[4.4,1]],"id":70053016},{"atb":[[4.5,3]],"id":69942666},{"atl":[[3.1,1]],"id":53082422}],"con":true,"img":false}]}
{"op":"mcm","clk":"11541577320","pt":1719507285623,"mc":[{"id":"1.230178329","rc":[{"atl":[[4.6,0]],"id":70902603},{"atl":[[4.5,0]],"id":70053016},{"atl":[[3.3,0]],"id":53082422}],"con":true,"img":false}]}
{"op":"mcm","clk":"11541577329","pt":1719507285726,"mc":[{"id":"1.230178329","rc":[{"atb":[[2.98,10.5]],"id":64812720},{"atl":[[5.9,16.78]],"id":66686625},{"atl":[[4.6,1],[4.4,0]],"id":70053016},{"atb":[[4.4,21.55]],"id":69942666},{"atl":[[3.1,0],[3.3,1]],"id":53082422}],"con":true,"img":false}]}
{"op":"mcm","clk":"11541577336","pt":1719507285830,"mc":[{"id":"1.230178329","rc":[{"atl":[[4.6,1]],"id":70902603}],"con":true,"img":false}]}
{"op":"mcm","clk":"11541577344","pt":1719507285932,"mc":[{"id":"1.230178329","rc":[{"atb":[[4.4,15.38]],"id":69942666}],"con":true,"img":false}]}
{"op":"mcm","clk":"11541577352","pt":1719507286034,"mc":[{"id":"1.230178329","rc":[{"atb":[[2.08,5.93]],"id":70053016},{"atb":[[4.5,9.17]],"id":69942666}],"con":true,"img":false}]}
{"op":"mcm","clk":"11541577359","pt":1719507286095,"mc":[{"id":"1.230178329","rc":[{"atb":[[2.12,2]],"id":70053016}],"con":true,"img":false}]}
{"op":"mcm","clk":"11541577389","pt":1719507286505,"mc":[{"id":"1.230178329","rc":[{"atb":[[3,12.16]],"id":64812720}],"con":true,"img":false}]}
{"op":"mcm","clk":"11541577407","pt":1719507286808,"mc":[{"id":"1.230178329","rc":[{"atl":[[5.8,1],[5.9,15.78]],"id":66686625},{"atl":[[4.5,1]],"id":70053016}],"con":true,"img":false}]}
{"op":"mcm","clk":"11541577415","pt":1719507286912,"mc":[{"id":"1.230178329","rc":[{"atl":[[4.6,0]],"id":70053016}],"con":true,"img":false}]}
{"op":"mcm","clk":"11541577462","pt":1719507287533,"mc":[{"id":"1.230178329","rc":[{"atl":[[4.6,5.41],[4.9,2.5]],"id":70053016}],"con":true,"img":false}]}
{"op":"mcm","clk":"11541577535","pt":1719507288323,"mc":[{"id":"1.230178329","rc":[{"atl":[[3.1,1],[3.3,0]],"id":53082422}],"con":true,"img":false}]}
{"op":"mcm","clk":"11541577647","pt":1719507289617,"mc":[{"id":"1.230178329","rc":[{"atb":[[2,5.53]],"id":70053016}],"con":true,"img":false}]}
{"op":"mcm","clk":"11541577710","pt":1719507290228,"mc":[{"id":"1.230178329","rc":[{"atb":[[2,0]],"id":70053016}],"con":true,"img":false}]}
{"op":"mcm","clk":"11541577737","pt":1719507290535,"mc":[{"id":"1.230178329","rc":[{"atb":[[2.36,3.75]],"id":70902603}],"con":true,"img":false}]}
{"op":"mcm","clk":"11541577816","pt":1719507291626,"mc":[{"id":"1.230178329","rc":[{"atl":[[4.5,0],[4.3,1]],"id":70053016}],"con":true,"img":false}]}
{"op":"mcm","clk":"11541577848","pt":1719507292135,"mc":[{"id":"1.230178329","rc":[{"atl":[[3.85,0],[4.6,0],[4.4,1]],"id":70902603}],"con":true,"img":false}]}
{"op":"mcm","clk":"11541577863","pt":1719507292342,"mc":[{"id":"1.230178329","rc":[{"atl":[[3.8,0],[4.4,11.31]],"id":70902603}],"con":true,"img":false}]}
{"op":"mcm","clk":"11541577880","pt":1719507292507,"mc":[{"id":"1.230178329","rc":[{"atl":[[3.9,3.15]],"id":70902603}],"con":true,"img":false}]}
{"op":"mcm","clk":"11541577914","pt":1719507293016,"mc":[{"id":"1.230178329","rc":[{"atb":[[3.05,12.16],[2.76,0]],"id":64812720},{"atl":[[7.2,0],[6.2,1]],"id":64812720},{"atb":[[2.02,0],[2.3,10.86],[1.97,0],[2.38,11.33],[2.12,2.5],[2.1,0]],"id":70902603},{"atl":[[4.6,1],[4.4,10.31]],"id":70902603},{"atb":[[1.98,5.4],[1.85,10]],"id":70053016},{"atb":[[4.3,24.55],[3.85,0]],"id":69942666},{"atl":[[11.5,2.04],[13.5,10.5]],"id":69942666},{"atb":[[1.36,0],[1.55,6.38],[1.42,15.59],[1.47,6.8]],"id":53082422}],"con":true,"img":false}]}
{"op":"mcm","clk":"11541577924","pt":1719507293124,"mc":[{"id":"1.230178329","rc":[{"atb":[[3.05,0],[2.86,22.66]],"id":64812720},{"atb":[[2.3,2.11],[2.16,7.5]],"id":70902603},{"atb":[[1.98,0],[1.87,20]],"id":70053016},{"atb":[[3.8,33.26]],"id":69942666},{"atb":[[1.36,22.63],[1.42,0],[1.47,5.38]],"id":53082422}],"con":true,"img":false}]}
{"op":"mcm","clk":"11541577934","pt":1719507293222,"mc":[{"id":"1.230178329","rc":[{"atb":[[4.3,0]],"id":69942666}],"con":true,"img":false}]}
{"op":"mcm","clk":"11541577976","pt":1719507293635,"mc":[{"id":"1.230178329","rc":[{"atb":[[1.47,0]],"id":53082422}],"con":true,"img":false}]}
{"op":"mcm","clk":"11541578003","pt":1719507293943,"mc":[{"id":"1.230178329","rc":[{"atb":[[4.6,6.05]],"id":69942666}],"con":true,"img":false}]}
{"op":"mcm","clk":"11541578020","pt":1719507294149,"mc":[{"id":"1.230178329","rc":[{"atb":[[4.4,0]],"id":69942666}],"con":true,"img":false}]}
{"op":"mcm","clk":"11541578049","pt":1719507294380,"mc":[{"id":"1.230178329","rc":[{"atb":[[2.38,8.33]],"id":70902603},{"atb":[[2.1,0]],"id":70053016},{"atb":[[1.54,0]],"id":53082422}],"con":true,"img":false}]}
{"op":"mcm","clk":"11541578057","pt":1719507294433,"mc":[{"id":"1.230178329","rc":[{"atl":[[4.6,0],[4.4,11.31]],"id":70902603}],"con":true,"img":false}]}
{"op":"mcm","clk":"11541578069","pt":1719507294534,"mc":[{"id":"1.230178329","rc":[{"atb":[[2.4,3.75]],"id":70902603},{"atb":[[2.12,5.18]],"id":70053016},{"atb":[[1.56,3.05]],"id":53082422}],"con":true,"img":false}]}
{"op":"mcm","clk":"11541578089","pt":1719507294742,"mc":[{"id":"1.230178329","rc":[{"atb":[[2.12,3.18]],"id":70053016},{"atb":[[1.46,2.11],[1.51,0]],"id":53082422}],"con":true,"img":false}]}
{"op":"mcm","clk":"11541578096","pt":1719507294845,"mc":[{"id":"1.230178329","rc":[{"atb":[[2.1,2]],"id":70053016}],"con":true,"img":false}]}
{"op":"mcm","clk":"11541578104","pt":1719507294948,"mc":[{"id":"1.230178329","rc":[{"atb":[[4.5,9.14]],"id":69942666}],"con":true,"img":false}]}
{"op":"mcm","clk":"11541578122","pt":1719507295154,"mc":[{"id":"1.230178329","rc":[{"atb":[[4.5,3]],"id":69942666}],"con":true,"img":false}]}
{"op":"mcm","clk":"11541578132","pt":1719507295210,"mc":[{"id":"1.230178329","rc":[{"atb":[[4.6,12.19]],"id":69942666}],"con":true,"img":false}]}
{"op":"mcm","clk":"11541578158","pt":1719507295519,"mc":[{"id":"1.230178329","rc":[{"atb":[[1.55,4.38]],"id":53082422}],"con":true,"img":false}]}
{"op":"mcm","clk":"11541578166","pt":1719507295620,"mc":[{"id":"1.230178329","rc":[{"atb":[[1.57,2]],"id":53082422}],"con":true,"img":false}]}
{"op":"mcm","clk":"11541578171","pt":1719507295724,"mc":[{"id":"1.230178329","rc":[{"atb":[[2.12,8.87]],"id":70053016}],"con":true,"img":false}]}
{"op":"mcm","clk":"11541578183","pt":1719507295930,"mc":[{"id":"1.230178329","rc":[{"atb":[[3.05,14.44]],"id":64812720},{"atb":[[2.96,8.8]],"id":66686625},{"atb":[[2.08,0]],"id":70053016}],"con":true,"img":false}]}
{"op":"mcm","clk":"11541578201","pt":1719507296144,"mc":[{"id":"1.230178329","rc":[{"atb":[[2.98,0]],"id":64812720},{"atl":[[4.6,1],[4.4,10.31]],"id":70902603},{"atb":[[2.92,11.73]],"id":66686625},{"atb":[[2.1,0]],"id":70053016}],"con":true,"img":false}]}
{"op":"mcm","clk":"11541578203","pt":1719507296249,"mc":[{"id":"1.230178329","rc":[{"atb":[[2.14,2]],"id":70053016}],"con":true,"img":false}]}
{"op":"mcm","clk":"11541578210","pt":1719507296353,"mc":[{"id":"1.230178329","rc":[{"atl":[[4.6,0],[4.4,11.31]],"id":70902603}],"con":true,"img":false}]}
{"op":"mcm","clk":"11541578223","pt":1719507296510,"mc":[{"id":"1.230178329","rc":[{"atb":[[3,12.06],[2.86,0],[2.38,17.16]],"id":64812720},{"atl":[[7.2,1],[6.2,0]],"id":64812720},{"atb":[[1.99,20.8],[2.38,2],[2.16,0]],"id":70902603},{"atb":[[2.24,14.4],[2.46,0]],"id":66686625},{"atb":[[1.87,0],[1.71,10.59]],"id":70053016},{"atb":[[3.4,20.19]],"id":69942666},{"atl":[[11.5,11.56]],"id":69942666},{"atb":[[1.55,0]],"id":53082422}],"con":true,"img":false}]}
{"op":"mcm","clk":"11541578231","pt":1719507296616,"mc":[{"id":"1.230178329","rc":[{"atb":[[2.76,26.5],[2.38,0]],"id":64812720},{"atb":[[2.36,0]],"id":70902603},{"atb":[[1.71,0],[1.86,10]],"id":70053016},{"atb":[[3.8,2.5]],"id":69942666},{"atl":[[13.5,2.5]],"id":69942666}],"con":true,"img":false}]}
{"op":"mcm","clk":"11541578238","pt":1719507296717,"mc":[{"id":"1.230178329","rc":[{"atb":[[3,2]],"id":64812720}],"con":true,"img":false}]}
{"op":"mcm","clk":"11541578249","pt":1719507296823,"mc":[{"id":"1.230178329","rc":[{"atb":[[3.05,24.5]],"id":64812720}],"con":true,"img":false}]}
{"op":"mcm","clk":"11541578258","pt":1719507296926,"mc":[{"id":"1.230178329","rc":[{"atb":[[2.38,0]],"id":70902603}],"con":true,"img":false}]}
{"op":"mcm","clk":"11541578268","pt":1719507297028,"mc":[{"id":"1.230178329","rc":[{"atb":[[2.42,2]],"id":70902603}],"con":true,"img":false}]}
{"op":"mcm","clk":"11541578347","pt":1719507297730,"mc":[{"id":"1.230178329","rc":[{"atl":[[3.85,9.38],[4.4,1]],"id":70902603}],"con":true,"img":false}]}
{"op":"mcm","clk":"11541578360","pt":1719507297834,"mc":[{"id":"1.230178329","rc":[{"atb":[[2.94,3.6]],"id":66686625}],"con":true,"img":false}]}
{"op":"mcm","clk":"11541578374","pt":1719507297996,"mc":[{"id":"1.230178329","rc":[{"atb":[[2.98,2]],"id":66686625}],"con":true,"img":false}]}
{"op":"mcm","clk":"11541578779","pt":1719507301159,"mc":[{"id":"1.230178329","rc":[{"atl":[[3.9,0]],"id":70902603}],"con":true,"img":false}]}
{"op":"mcm","clk":"11541578799","pt":1719507301318,"mc":[{"id":"1.230178329","rc":[{"atl":[[4.4,15.07]],"id":70902603}],"con":true,"img":false}]}
{"op":"mcm","clk":"11541578808","pt":1719507301424,"mc":[{"id":"1.230178329","rc":[{"atl":[[3.85,0],[3.95,1.57]],"id":70902603}],"con":true,"img":false}]}
{"op":"mcm","clk":"11541578841","pt":1719507301837,"mc":[{"id":"1.230178329","rc":[{"atl":[[2.54,0]],"id":53082422}],"con":true,"img":false}]}
{"op":"mcm","clk":"11541578850","pt":1719507301940,"mc":[{"id":"1.230178329","rc":[{"atb":[[1.99,0],[2.14,4.24]],"id":70902603},{"atb":[[2.24,0],[2.46,10]],"id":66686625},{"atb":[[3.85,15.19],[3.4,5]],"id":69942666}],"con":true,"img":false}]}
{"op":"mcm","clk":"11541578917","pt":1719507302665,"mc":[{"id":"1.230178329","rc":[{"atl":[[3.95,0]],"id":70902603}],"con":true,"img":false}]}
{"op":"mcm","clk":"11541578942","pt":1719507302828,"mc":[{"id":"1.230178329","rc":[{"atl":[[4,1.57]],"id":70902603}],"con":true,"img":false}]}
{"op":"mcm","clk":"11541578954","pt":1719507302932,"mc":[{"id":"1.230178329","rc":[{"atb":[[3,0]],"id":64812720},{"atb":[[2.4,0]],"id":70902603},{"atb":[[2.94,0]],"id":66686625},{"atb":[[2.12,5.69]],"id":70053016},{"atb":[[4.5,0]],"id":69942666},{"atb":[[1.56,0]],"id":53082422}],"con":true,"img":false}]}
{"op":"mcm","clk":"11541578965","pt":1719507303036,"mc":[{"id":"1.230178329","rc":[{"atb":[[3.1,3.18],[3.05,14.44]],"id":64812720},{"atb":[[2.42,5]],"id":70902603},{"atb":[[2.14,4.8]],"id":70053016},{"atb":[[4.6,6.05],[4.7,2.38]],"id":69942666},{"atb":[[1.53,3]],"id":53082422}],"con":true,"img":false}]}
{"op":"mcm","clk":"11541578997","pt":1719507303345,"mc":[{"id":"1.230178329","rc":[{"atb":[[1.57,0]],"id":53082422}],"con":true,"img":false}]}
{"op":"mcm","clk":"11541579009","pt":1719507303450,"mc":[{"id":"1.230178329","rc":[{"atb":[[1.47,2]],"id":53082422}],"con":true,"img":false}]}
{"op":"mcm","clk":"11541579047","pt":1719507303761,"mc":[{"id":"1.230178329","rc":[{"atb":[[2.42,3]],"id":70902603}],"con":true,"img":false}]}
{"op":"mcm","clk":"11541579060","pt":1719507303864,"mc":[{"id":"1.230178329","rc":[{"atb":[[2.32,2]],"id":70902603}],"con":true,"img":false}]}
{"op":"mcm","clk":"11541579083","pt":1719507304025,"mc":[{"id":"1.230178329","rc":[{"atb":[[3.1,14.57]],"id":64812720},{"atb":[[4.7,8.37]],"id":69942666},{"atl":[[2.54,3.54]],"id":53082422}],"con":true,"img":false}]}
{"op":"mcm","clk":"11541579091","pt":1719507304127,"mc":[{"id":"1.230178329","rc":[{"atl":[[2.52,14.01],[2.96,0]],"id":53082422}],"con":true,"img":false}]}
{"op":"mcm","clk":"11541579114","pt":1719507304336,"mc":[{"id":"1.230178329","rc":[{"atb":[[1.47,0]],"id":53082422}],"con":true,"img":false}]}
{"op":"mcm","clk":"11541579124","pt":1719507304439,"mc":[{"id":"1.230178329","rc":[{"atb":[[1.54,2]],"id":53082422}],"con":true,"img":false}]}
{"op":"mcm","clk":"11541579151","pt":1719507304744,"mc":[{"id":"1.230178329","rc":[{"atb":[[2.32,0]],"id":70902603}],"con":true,"img":false}]}
{"op":"mcm","clk":"11541579160","pt":1719507304846,"mc":[{"id":"1.230178329","rc":[{"atb":[[2.44,2]],"id":70902603}],"con":true,"img":false}]}
{"op":"mcm","clk":"11541579244","pt":1719507305623,"mc":[{"id":"1.230178329","rc":[{"spn":2.99,"spf":1.0,"id":64812720},{"spn":3.09,"spf":"NaN","id":70902603},{"spn":3.69,"spf":"NaN","id":66686625},{"spn":2.94,"spf":"NaN","id":70053016},{"atb":[[4.8,10.81]],"id":69942666},{"spn":7.0,"spf":"NaN","id":69942666},{"spn":1.62,"spf":1.0,"id":53082422}],"con":true,"img":false}]}
{"op":"mcm","clk":"11541579261","pt":1719507305828,"mc":[{"id":"1.230178329","rc":[{"atb":[[4.6,0]],"id":69942666}],"con":true,"img":false}]}
{"op":"mcm","clk":"11541579317","pt":1719507306448,"mc":[{"id":"1.230178329","rc":[{"atb":[[4.7,2.38]],"id":69942666}],"con":true,"img":false}]}
{"op":"mcm","clk":"11541579333","pt":1719507306654,"mc":[{"id":"1.230178329","rc":[{"atl":[[4,10.95],[4.4,1]],"id":70902603}],"con":true,"img":false}]}
{"op":"mcm","clk":"11541579343","pt":1719507306757,"mc":[{"id":"1.230178329","rc":[{"atl":[[4,1.56],[4.4,7.26]],"id":70902603}],"con":true,"img":false}]}
{"op":"mcm","clk":"11541579367","pt":1719507306963,"mc":[{"id":"1.230178329","rc":[{"atb":[[1.41,2.11],[1.46,0]],"id":53082422}],"con":true,"img":false}]}
{"op":"mcm","clk":"11541579382","pt":1719507307169,"mc":[{"id":"1.230178329","rc":[{"atl":[[2.54,0]],"id":53082422}],"con":true,"img":false}]}
{"op":"mcm","clk":"11541579403","pt":1719507307328,"mc":[{"id":"1.230178329","rc":[{"atb":[[2.14,12.46]],"id":70053016},{"atb":[[4.8,17.23]],"id":69942666}],"con":true,"img":false}]}
{"op":"mcm","clk":"11541579422","pt":1719507307531,"mc":[{"id":"1.230178329","rc":[{"atb":[[3.15,17.39]],"id":64812720},{"atb":[[2.98,13.21]],"id":66686625},{"atb":[[2.12,0]],"id":70053016}],"con":true,"img":false}]}
{"op":"mcm","clk":"11541579429","pt":1719507307635,"mc":[{"id":"1.230178329","rc":[{"atb":[[3.05,0]],"id":64812720},{"atl":[[4.6,1]],"id":70902603},{"atb":[[2.96,0]],"id":66686625}],"con":true,"img":false}]}
{"op":"mcm","clk":"11541579439","pt":1719507307736,"mc":[{"id":"1.230178329","rc":[{"atb":[[3.85,17.69]],"id":69942666}],"con":true,"img":false}]}
{"op":"mcm","clk":"11541579447","pt":1719507307841,"mc":[{"id":"1.230178329","rc":[{"atl":[[4.4,6.26]],"id":70902603},{"atb":[[3.6,0],[3.8,0],[3.4,0]],"id":69942666}],"con":true,"img":false}]}
{"op":"mcm","clk":"11541579493","pt":1719507308255,"mc":[{"id":"1.230178329","rc":[{"atb":[[3.1,13.45]],"id":64812720}],"con":true,"img":false}]}
{"op":"mcm","clk":"11541579516","pt":1719507308461,"mc":[{"id":"1.230178329","rc":[{"atb":[[3.1,3.18]],"id":64812720},{"atb":[[3.8,3]],"id":69942666}],"con":true,"img":false}]}
{"op":"mcm","clk":"11541579528","pt":1719507308565,"mc":[{"id":"1.230178329","rc":[{"atb":[[3.15,27.66]],"id":64812720}],"con":true,"img":false}]}
{"op":"mcm","clk":"11541579589","pt":1719507309235,"mc":[{"id":"1.230178329","rc":[{"atl":[[2.9,28.04],[2.52,7]],"id":53082422}],"con":true,"img":false}]}
{"op":"mcm","clk":"11541579622","pt":1719507309546,"mc":[{"id":"1.230178329","rc":[{"atb":[[2.06,0]],"id":70053016}],"con":true,"img":false}]}
{"op":"mcm","clk":"11541579680","pt":1719507310163,"mc":[{"id":"1.230178329","rc":[{"atb":[[2.2,4.93]],"id":70053016}],"con":true,"img":false}]}
{"op":"mcm","clk":"11541579723","pt":1719507310632,"mc":[{"id":"1.230178329","rc":[{"atb":[[1.89,0],[1.85,0],[1.93,0],[2.08,10],[2.24,2.5],[2.16,5]],"id":70053016},{"atl":[[17.5,0],[10,2.5],[12,6],[13.5,0],[15.5,0]],"id":69942666}],"con":true,"img":false}]}
{"op":"mcm","clk":"11541579732","pt":1719507310735,"mc":[{"id":"1.230178329","rc":[{"atl":[[10.5,8.53],[11.5,2.04]],"id":69942666}],"con":true,"img":false}]}
{"op":"mcm","clk":"11541579772","pt":1719507311250,"mc":[{"id":"1.230178329","rc":[{"atl":[[4.4,7.26]],"id":70902603},{"atb":[[2.14,10.46]],"id":70053016},{"atb":[[3.8,0]],"id":69942666}],"con":true,"img":false}]}
{"op":"mcm","clk":"11541579783","pt":1719507311352,"mc":[{"id":"1.230178329","rc":[{"atl":[[4.6,0]],"id":70902603},{"atb":[[2.22,2]],"id":70053016}],"con":true,"img":false}]}
{"op":"mcm","clk":"11541579816","pt":1719507311666,"mc":[{"id":"1.230178329","rc":[{"atb":[[3.1,0]],"id":64812720},{"atb":[[2.42,0]],"id":70902603},{"atb":[[2.14,7.66]],"id":70053016},{"atb":[[4.7,0]],"id":69942666},{"atb":[[1.53,0]],"id":53082422}],"con":true,"img":false}]}
{"op":"mcm","clk":"11541579846","pt":1719507311869,"mc":[{"id":"1.230178329","rc":[{"atb":[[3.2,4.03]],"id":64812720},{"atb":[[2.44,5.38]],"id":70902603},{"atb":[[2.24,4.64],[2.22,0]],"id":70053016},{"atb":[[4.9,3]],"id":69942666},{"atb":[[1.54,6]],"id":53082422}],"con":true,"img":false}]}
{"op":"mcm","clk":"11541579859","pt":1719507311972,"mc":[{"id":"1.230178329","rc":[{"atb":[[2.26,2]],"id":70053016}],"con":true,"img":false}]}
{"op":"mcm","clk":"11541579869","pt":1719507312076,"mc":[{"id":"1.230178329","rc":[{"atl":[[4,10.95],[4.4,1]],"id":70902603}],"con":true,"img":false}]}
{"op":"mcm","clk":"11541579881","pt":1719507312181,"mc":[{"id":"1.230178329","rc":[{"atl":[[4,1.56],[4.6,1],[4.4,6.26]],"id":70902603}],"con":true,"img":false}]}
{"op":"mcm","clk":"11541579894","pt":1719507312235,"mc":[{"id":"1.230178329","rc":[{"atb":[[3.15,17.39]],"id":64812720},{"atl":[[4,10.95],[4.4,0]],"id":70902603},{"atb":[[4.8,10.81]],"id":69942666},{"atb":[[1.43,0]],"id":53082422}],"con":true,"img":false}]}
{"op":"mcm","clk":"11541579948","pt":1719507312751,"mc":[{"id":"1.230178329","rc":[{"atl":[[2.5,6.09]],"id":53082422}],"con":true,"img":false}]}
{"op":"mcm","clk":"11541579967","pt":1719507312959,"mc":[{"id":"1.230178329","rc":[{"atl":[[2.52,0.84]],"id":53082422}],"con":true,"img":false}]}
{"op":"mcm","clk":"11541579978","pt":1719507313063,"mc":[{"id":"1.230178329","rc":[{"atb":[[3.2,15.43]],"id":64812720},{"atb":[[2.4,3.64]],"id":70902603},{"atb":[[4.9,9.26]],"id":69942666}],"con":true,"img":false}]}
{"op":"mcm","clk":"11541580015","pt":1719507313477,"mc":[{"id":"1.230178329","rc":[{"atl":[[2.48,0.84]],"id":53082422}],"con":true,"img":false}]}
{"op":"mcm","clk":"11541580034","pt":1719507313635,"mc":[{"id":"1.230178329","rc":[{"atl":[[2.9,0],[2.52,7.78]],"id":53082422}],"con":true,"img":false}]}
{"op":"mcm","clk":"11541580089","pt":1719507314251,"mc":[{"id":"1.230178329","rc":[{"atb":[[2.24,9.07]],"id":70053016}],"con":true,"img":false}]}
{"op":"mcm","clk":"11541580186","pt":1719507315180,"mc":[{"id":"1.230178329","rc":[{"atb":[[3.1,3.12]],"id":64812720}],"con":true,"img":false}]}
{"op":"mcm","clk":"11541580260","pt":1719507316055,"mc":[{"id":"1.230178329","rc":[{"atb":[[1.52,5.38]],"id":53082422}],"con":true,"img":false}]}
{"op":"mcm","clk":"11541580275","pt":1719507316262,"mc":[{"id":"1.230178329","rc":[{"atb":[[3.1,0]],"id":64812720}],"con":true,"img":false}]}
{"op":"mcm","clk":"11541580340","pt":1719507317038,"mc":[{"id":"1.230178329","rc":[{"atb":[[4.9,22.6]],"id":69942666}],"con":true,"img":false}]}
{"op":"mcm","clk":"11541580361","pt":1719507317242,"mc":[{"id":"1.230178329","rc":[{"atl":[[6.4,5],[5.8,3.5],[6.6,0],[5.9,13.28]],"id":66686625},{"atb":[[4.8,0]],"id":69942666}],"con":true,"img":false}]}
{"op":"mcm","clk":"11541580481","pt":1719507318484,"mc":[{"id":"1.230178329","rc":[{"atb":[[4.9,16.34]],"id":69942666}],"con":true,"img":false}]}
{"op":"mcm","clk":"11541580504","pt":1719507318742,"mc":[{"id":"1.230178329","rc":[{"atb":[[2.28,7]],"id":70053016}],"con":true,"img":false}]}
