{"op":"mcm","clk":"11536380671","pt":1719425245615,"mc":[{"id":"1.230178321","marketDefinition":{"bspMarket":true,"turnInPlayEnabled":false,"persistenceEnabled":false,"marketBaseRate":5.0,"eventId":"33376062","eventTypeId":"4339","numberOfWinners":2,"bettingType":"ODDS","marketType":"PLACE","marketTime":"2024-06-27T15:47:00.000Z","suspendTime":"2024-06-27T15:47:00.000Z","bspReconciled":false,"complete":true,"inPlay":false,"crossMatching":false,"runnersVoidable":false,"numberOfActiveRunners":6,"betDelay":0,"status":"OPEN","runners":[{"status":"ACTIVE","sortPriority":1,"id":51643934,"name":"1. Ballymac Frisby"},{"status":"ACTIVE","sortPriority":2,"id":62531723,"name":"2. Lynnway Touch"},{"status":"ACTIVE","sortPriority":3,"id":61941199,"name":"3. Kilara Thyestes"},{"status":"ACTIVE","sortPriority":4,"id":69176305,"name":"4. Moss Row Jemma"},{"status":"ACTIVE","sortPriority":5,"id":61419789,"name":"5. Buzzers Delight"},{"status":"ACTIVE","sortPriority":6,"id":43498435,"name":"6. Easy Cookie"}],"regulators":["MR_INT"],"venue":"Kinsley","countryCode":"GB","discountAllowed":false,"timezone":"Europe/London","openDate":"2024-06-27T13:36:00.000Z","version":5994643797,"name":"To Be Placed","eventName":"Kinsley 27th Jun"},"rc":[],"con":true,"img":false}]}
{"op":"mcm","clk":"11536381042","pt":1719425248539,"mc":[{"id":"1.230178321","marketDefinition":{"bspMarket":true,"turnInPlayEnabled":false,"persistenceEnabled":false,"marketBaseRate":5.0,"eventId":"33376062","eventTypeId":"4339","numberOfWinners":2,"bettingType":"ODDS","marketType":"PLACE","marketTime":"2024-06-27T15:47:00.000Z","suspendTime":"2024-06-27T15:47:00.000Z","bspReconciled":false,"complete":true,"inPlay":false,"crossMatching":false,"runnersVoidable":false,"numberOfActiveRunners":6,"betDelay":0,"status":"OPEN","runners":[{"status":"ACTIVE","sortPriority":1,"id":51643934,"name":"1. Ballymac Frisby"},{"status":"ACTIVE","sortPriority":2,"id":62531723,"name":"2. Lynnway Touch"},{"status":"ACTIVE","sortPriority":3,"id":61941199,"name":"3. Kilara Thyestes"},{"status":"ACTIVE","sortPriority":4,"id":69176305,"name":"4. Moss Row Jemma"},{"status":"ACTIVE","sortPriority":5,"id":61419789,"name":"5. Buzzers Delight"},{"status":"ACTIVE","sortPriority":6,"id":43498435,"name":"6. Easy Cookie"}],"regulators":["MR_INT"],"venue":"Kinsley","countryCode":"GB","discountAllowed":true,"timezone":"Europe/London","openDate":"2024-06-27T13:36:00.000Z","version":5994643797,"name":"To Be Placed","eventName":"Kinsley 27th Jun"},"rc":[],"con":true,"img":false}]}
{"op":"mcm","clk":"11536837129","pt":1719431855123,"mc":[{"id":"1.230178321","rc":[{"atb":[[1.01,22.45]],"id":69176305},{"atl":[[1000,0.84]],"id":69176305},{"spn":500.5,"spf":"NaN","id":69176305},{"atb":[[1.03,7.48]],"id":43498435},{"atl":[[1000,0.84]],"id":43498435},{"spn":500.51,"spf":"NaN","id":43498435},{"atb":[[1.01,22.45]],"id":61941199},{"atl":[[1000,0.84]],"id":61941199},{"spn":500.5,"spf":"NaN","id":61941199},{"atb":[[1.02,11.22]],"id":61419789},{"atl":[[990,0.84]],"id":61419789},{"spn":495.51,"spf":"NaN","id":61419789},{"atb":[[1.02,11.22]],"id":62531723},{"atl":[[990,0.84]],"id":62531723},{"spn":495.51,"spf":"NaN","id":62531723},{"atb":[[1.03,7.48]],"id":51643934},{"atl":[[990,0.84]],"id":51643934},{"spn":495.51,"spf":"NaN","id":51643934}],"con":true,"img":false}]}
{"op":"mcm","clk":"11537083934","pt":1719435434185,"mc":[{"id":"1.230178321","rc":[{"atl":[[1000,0.32]],"id":69176305},{"atl":[[1000,0.32]],"id":43498435},{"atl":[[1000,0.32]],"id":61941199},{"atl":[[990,0.32]],"id":61419789},{"atl":[[990,0.32]],"id":62531723},{"atl":[[990,0.32]],"id":51643934}],"con":true,"img":false}]}
{"op":"mcm","clk":"11537232278","pt":1719437882526,"mc":[{"id":"1.230178321","marketDefinition":{"bspMarket":true,"turnInPlayEnabled":false,"persistenceEnabled":false,"marketBaseRate":5.0,"eventId":"33376062","eventTypeId":"4339","numberOfWinners":2,"bettingType":"ODDS","marketType":"PLACE","marketTime":"2024-06-27T15:47:00.000Z","suspendTime":"2024-06-27T15:47:00.000Z","bspReconciled":false,"complete":true,"inPlay":false,"crossMatching":false,"runnersVoidable":false,"numberOfActiveRunners":6,"betDelay":0,"status":"OPEN","runners":[{"status":"ACTIVE","sortPriority":1,"id":51643934,"name":"1. Ballymac Frisby"},{"status":"ACTIVE","sortPriority":2,"id":62531723,"name":"2. Lynnway Touch"},{"status":"ACTIVE","sortPriority":3,"id":61941199,"name":"3. Kilara Thyestes"},{"status":"ACTIVE","sortPriority":4,"id":69176305,"name":"4. Moss Row Jemma"},{"status":"ACTIVE","sortPriority":5,"id":61419789,"name":"5. Buzzers Delight"},{"status":"ACTIVE","sortPriority":6,"id":43498435,"name":"6. Easy Cookie"}],"regulators":["MR_INT"],"venue":"Kinsley","countryCode":"GB","discountAllowed":true,"timezone":"Europe/London","openDate":"2024-06-27T13:36:00.000Z","version":5994643797,"name":"To Be Placed","eventName":"Kinsley 27th Jun"},"rc":[{"atb":[[1.01,22.45]],"id":61941199},{"atl":[[1000,0.33]],"id":61941199},{"spn":500.5,"spf":"NaN","id":61941199},{"atb":[[1.01,22.45]],"id":69176305},{"atl":[[1000,0.33]],"id":69176305},{"spn":500.5,"spf":"NaN","id":69176305},{"atb":[[1.03,7.48]],"id":43498435},{"atl":[[1000,0.33]],"id":43498435},{"spn":500.51,"spf":"NaN","id":43498435},{"atb":[[1.02,11.22]],"id":61419789},{"atl":[[990,0.33]],"id":61419789},{"spn":495.51,"spf":"NaN","id":61419789},{"atb":[[1.02,11.22]],"id":62531723},{"atl":[[990,0.33]],"id":62531723},{"spn":495.51,"spf":"NaN","id":62531723},{"atb":[[1.03,7.48]],"id":51643934},{"atl":[[990,0.33]],"id":51643934},{"spn":495.51,"spf":"NaN","id":51643934}],"con":true,"img":true}]}
{"op":"mcm","clk":"11537302217","pt":1719439032279,"mc":[{"id":"1.230178321","rc":[{"atb":[[1.01,22.45]],"id":61941199},{"atl":[[1000,0.17]],"id":61941199},{"atb":[[1.01,22.45]],"id":69176305},{"atl":[[1000,0.17]],"id":69176305},{"atb":[[1.03,7.48]],"id":43498435},{"atl":[[1000,0.17]],"id":43498435},{"atb":[[1.02,11.22]],"id":61419789},{"atl":[[990,0.17]],"id":61419789},{"atb":[[1.02,11.22]],"id":62531723},{"atl":[[990,0.17]],"id":62531723},{"atb":[[1.03,7.48]],"id":51643934},{"atl":[[990,0.17]],"id":51643934}],"con":true,"img":false}]}
{"op":"mcm","clk":"11537573405","pt":1719443282545,"mc":[{"id":"1.230178321","marketDefinition":{"bspMarket":true,"turnInPlayEnabled":false,"persistenceEnabled":false,"marketBaseRate":5.0,"eventId":"33376062","eventTypeId":"4339","numberOfWinners":2,"bettingType":"ODDS","marketType":"PLACE","marketTime":"2024-06-27T15:47:00.000Z","suspendTime":"2024-06-27T15:47:00.000Z","bspReconciled":false,"complete":true,"inPlay":false,"crossMatching":false,"runnersVoidable":false,"numberOfActiveRunners":6,"betDelay":0,"status":"OPEN","runners":[{"status":"ACTIVE","sortPriority":1,"id":51643934,"name":"1. Ballymac Frisby"},{"status":"ACTIVE","sortPriority":2,"id":62531723,"name":"2. Lynnway Touch"},{"status":"ACTIVE","sortPriority":3,"id":61941199,"name":"3. Kilara Thyestes"},{"status":"ACTIVE","sortPriority":4,"id":69176305,"name":"4. Moss Row Jemma"},{"status":"ACTIVE","sortPriority":5,"id":61419789,"name":"5. Buzzers Delight"},{"status":"ACTIVE","sortPriority":6,"id":43498435,"name":"6. Easy Cookie"}],"regulators":["MR_INT"],"venue":"Kinsley","countryCode":"GB","discountAllowed":true,"timezone":"Europe/London","openDate":"2024-06-27T13:36:00.000Z","version":5994643797,"name":"To Be Placed","eventName":"Kinsley 27th Jun"},"rc":[{"atb":[[1.01,22.45]],"id":61941199},{"atl":[[1000,0.17]],"id":61941199},{"spn":500.5,"spf":"NaN","id":61941199},{"atb":[[1.01,22.45]],"id":69176305},{"atl":[[1000,0.17]],"id":69176305},{"spn":500.5,"spf":"NaN","id":69176305},{"atb":[[1.03,7.48]],"id":43498435},{"atl":[[1000,0.17]],"id":43498435},{"spn":500.51,"spf":"NaN","id":43498435},{"atb":[[1.02,11.22]],"id":61419789},{"atl":[[990,0.17]],"id":61419789},{"spn":495.51,"spf":"NaN","id":61419789},{"atb":[[1.02,11.22]],"id":62531723},{"atl":[[990,0.17]],"id":62531723},{"spn":495.51,"spf":"NaN","id":62531723},{"atb":[[1.03,7.48]],"id":51643934},{"atl":[[990,0.17]],"id":51643934},{"spn":495.51,"spf":"NaN","id":51643934}],"con":true,"img":true}]}
{"op":"mcm","clk":"11537954965","pt":1719448682569,"mc":[{"id":"1.230178321","marketDefinition":{"bspMarket":true,"turnInPlayEnabled":false,"persistenceEnabled":false,"marketBaseRate":5.0,"eventId":"33376062","eventTypeId":"4339","numberOfWinners":2,"bettingType":"ODDS","marketType":"PLACE","marketTime":"2024-06-27T15:47:00.000Z","suspendTime":"2024-06-27T15:47:00.000Z","bspReconciled":false,"complete":true,"inPlay":false,"crossMatching":false,"runnersVoidable":false,"numberOfActiveRunners":6,"betDelay":0,"status":"OPEN","runners":[{"status":"ACTIVE","sortPriority":1,"id":51643934,"name":"1. Ballymac Frisby"},{"status":"ACTIVE","sortPriority":2,"id":62531723,"name":"2. Lynnway Touch"},{"status":"ACTIVE","sortPriority":3,"id":61941199,"name":"3. Kilara Thyestes"},{"status":"ACTIVE","sortPriority":4,"id":69176305,"name":"4. Moss Row Jemma"},{"status":"ACTIVE","sortPriority":5,"id":61419789,"name":"5. Buzzers Delight"},{"status":"ACTIVE","sortPriority":6,"id":43498435,"name":"6. Easy Cookie"}],"regulators":["MR_INT"],"venue":"Kinsley","countryCode":"GB","discountAllowed":true,"timezone":"Europe/London","openDate":"2024-06-27T13:36:00.000Z","version":5994643797,"name":"To Be Placed","eventName":"Kinsley 27th Jun"},"rc":[{"atb":[[1.01,22.45]],"id":61941199},{"atl":[[1000,0.17]],"id":61941199},{"spn":500.5,"spf":"NaN","id":61941199},{"atb":[[1.01,22.45]],"id":69176305},{"atl":[[1000,0.17]],"id":69176305},{"spn":500.5,"spf":"NaN","id":69176305},{"atb":[[1.03,7.48]],"id":43498435},{"atl":[[1000,0.17]],"id":43498435},{"spn":500.51,"spf":"NaN","id":43498435},{"atb":[[1.02,11.22]],"id":61419789},{"atl":[[990,0.17]],"id":61419789},{"spn":495.51,"spf":"NaN","id":61419789},{"atb":[[1.02,11.22]],"id":62531723},{"atl":[[990,0.17]],"id":62531723},{"spn":495.51,"spf":"NaN","id":62531723},{"atb":[[1.03,7.48]],"id":51643934},{"atl":[[990,0.17]],"id":51643934},{"spn":495.51,"spf":"NaN","id":51643934}],"con":true,"img":true}]}
{"op":"mcm","clk":"11538170628","pt":1719454082552,"mc":[{"id":"1.230178321","marketDefinition":{"bspMarket":true,"turnInPlayEnabled":false,"persistenceEnabled":false,"marketBaseRate":5.0,"eventId":"33376062","eventTypeId":"4339","numberOfWinners":2,"bettingType":"ODDS","marketType":"PLACE","marketTime":"2024-06-27T15:47:00.000Z","suspendTime":"2024-06-27T15:47:00.000Z","bspReconciled":false,"complete":true,"inPlay":false,"crossMatching":false,"runnersVoidable":false,"numberOfActiveRunners":6,"betDelay":0,"status":"OPEN","runners":[{"status":"ACTIVE","sortPriority":1,"id":51643934,"name":"1. Ballymac Frisby"},{"status":"ACTIVE","sortPriority":2,"id":62531723,"name":"2. Lynnway Touch"},{"status":"ACTIVE","sortPriority":3,"id":61941199,"name":"3. Kilara Thyestes"},{"status":"ACTIVE","sortPriority":4,"id":69176305,"name":"4. Moss Row Jemma"},{"status":"ACTIVE","sortPriority":5,"id":61419789,"name":"5. Buzzers Delight"},{"status":"ACTIVE","sortPriority":6,"id":43498435,"name":"6. Easy Cookie"}],"regulators":["MR_INT"],"venue":"Kinsley","countryCode":"GB","discountAllowed":true,"timezone":"Europe/London","openDate":"2024-06-27T13:36:00.000Z","version":5994643797,"name":"To Be Placed","eventName":"Kinsley 27th Jun"},"rc":[{"atb":[[1.01,22.46]],"id":61941199},{"atl":[[1000,0.17]],"id":61941199},{"spn":500.5,"spf":"NaN","id":61941199},{"atb":[[1.01,22.46]],"id":69176305},{"atl":[[1000,0.17]],"id":69176305},{"spn":500.5,"spf":"NaN","id":69176305},{"atb":[[1.03,7.49]],"id":43498435},{"atl":[[1000,0.17]],"id":43498435},{"spn":500.51,"spf":"NaN","id":43498435},{"atb":[[1.02,11.23]],"id":61419789},{"atl":[[990,0.17]],"id":61419789},{"spn":495.51,"spf":"NaN","id":61419789},{"atb":[[1.02,11.23]],"id":62531723},{"atl":[[990,0.17]],"id":62531723},{"spn":495.51,"spf":"NaN","id":62531723},{"atb":[[1.03,7.49]],"id":51643934},{"atl":[[990,0.17]],"id":51643934},{"spn":495.51,"spf":"NaN","id":51643934}],"con":true,"img":true}]}
{"op":"mcm","clk":"11538368286","pt":1719459482602,"mc":[{"id":"1.230178321","marketDefinition":{"bspMarket":true,"turnInPlayEnabled":false,"persistenceEnabled":false,"marketBaseRate":5.0,"eventId":"33376062","eventTypeId":"4339","numberOfWinners":2,"bettingType":"ODDS","marketType":"PLACE","marketTime":"2024-06-27T15:47:00.000Z","suspendTime":"2024-06-27T15:47:00.000Z","bspReconciled":false,"complete":true,"inPlay":false,"crossMatching":false,"runnersVoidable":false,"numberOfActiveRunners":6,"betDelay":0,"status":"OPEN","runners":[{"status":"ACTIVE","sortPriority":1,"id":51643934,"name":"1. Ballymac Frisby"},{"status":"ACTIVE","sortPriority":2,"id":62531723,"name":"2. Lynnway Touch"},{"status":"ACTIVE","sortPriority":3,"id":61941199,"name":"3. Kilara Thyestes"},{"status":"ACTIVE","sortPriority":4,"id":69176305,"name":"4. Moss Row Jemma"},{"status":"ACTIVE","sortPriority":5,"id":61419789,"name":"5. Buzzers Delight"},{"status":"ACTIVE","sortPriority":6,"id":43498435,"name":"6. Easy Cookie"}],"regulators":["MR_INT"],"venue":"Kinsley","countryCode":"GB","discountAllowed":true,"timezone":"Europe/London","openDate":"2024-06-27T13:36:00.000Z","version":5994643797,"name":"To Be Placed","eventName":"Kinsley 27th Jun"},"rc":[{"atb":[[1.01,22.46]],"id":61941199},{"atl":[[1000,0.17]],"id":61941199},{"spn":500.5,"spf":"NaN","id":61941199},{"atb":[[1.01,22.46]],"id":69176305},{"atl":[[1000,0.17]],"id":69176305},{"spn":500.5,"spf":"NaN","id":69176305},{"atb":[[1.03,7.49]],"id":43498435},{"atl":[[1000,0.17]],"id":43498435},{"spn":500.51,"spf":"NaN","id":43498435},{"atb":[[1.02,11.23]],"id":61419789},{"atl":[[990,0.17]],"id":61419789},{"spn":495.51,"spf":"NaN","id":61419789},{"atb":[[1.02,11.23]],"id":62531723},{"atl":[[990,0.17]],"id":62531723},{"spn":495.51,"spf":"NaN","id":62531723},{"atb":[[1.03,7.49]],"id":51643934},{"atl":[[990,0.17]],"id":51643934},{"spn":495.51,"spf":"NaN","id":51643934}],"con":true,"img":true}]}
{"op":"mcm","clk":"11538595412","pt":1719464882550,"mc":[{"id":"1.230178321","marketDefinition":{"bspMarket":true,"turnInPlayEnabled":false,"persistenceEnabled":false,"marketBaseRate":5.0,"eventId":"33376062","eventTypeId":"4339","numberOfWinners":2,"bettingType":"ODDS","marketType":"PLACE","marketTime":"2024-06-27T15:47:00.000Z","suspendTime":"2024-06-27T15:47:00.000Z","bspReconciled":false,"complete":true,"inPlay":false,"crossMatching":false,"runnersVoidable":false,"numberOfActiveRunners":6,"betDelay":0,"status":"OPEN","runners":[{"status":"ACTIVE","sortPriority":1,"id":51643934,"name":"1. Ballymac Frisby"},{"status":"ACTIVE","sortPriority":2,"id":62531723,"name":"2. Lynnway Touch"},{"status":"ACTIVE","sortPriority":3,"id":61941199,"name":"3. Kilara Thyestes"},{"status":"ACTIVE","sortPriority":4,"id":69176305,"name":"4. Moss Row Jemma"},{"status":"ACTIVE","sortPriority":5,"id":61419789,"name":"5. Buzzers Delight"},{"status":"ACTIVE","sortPriority":6,"id":43498435,"name":"6. Easy Cookie"}],"regulators":["MR_INT"],"venue":"Kinsley","countryCode":"GB","discountAllowed":true,"timezone":"Europe/London","openDate":"2024-06-27T13:36:00.000Z","version":5994643797,"name":"To Be Placed","eventName":"Kinsley 27th Jun"},"rc":[{"atb":[[1.01,22.46]],"id":61941199},{"atl":[[1000,0.17]],"id":61941199},{"spn":500.5,"spf":"NaN","id":61941199},{"atb":[[1.01,22.46]],"id":69176305},{"atl":[[1000,0.17]],"id":69176305},{"spn":500.5,"spf":"NaN","id":69176305},{"atb":[[1.03,7.48]],"id":43498435},{"atl":[[1000,0.17]],"id":43498435},{"spn":500.51,"spf":"NaN","id":43498435},{"atb":[[1.02,11.23]],"id":61419789},{"atl":[[990,0.17]],"id":61419789},{"spn":495.51,"spf":"NaN","id":61419789},{"atb":[[1.02,11.23]],"id":62531723},{"atl":[[990,0.17]],"id":62531723},{"spn":495.51,"spf":"NaN","id":62531723},{"atb":[[1.03,7.48]],"id":51643934},{"atl":[[990,0.17]],"id":51643934},{"spn":495.51,"spf":"NaN","id":51643934}],"con":true,"img":true}]}
{"op":"mcm","clk":"11538907330","pt":1719471508675,"mc":[{"id":"1.230178321","rc":[{"atb":[[1.01,22.46],[1.07,2.48]],"id":61941199},{"atl":[[1000,1.17]],"id":61941199},{"spn":500.53,"spf":"NaN","id":61941199},{"atb":[[1.01,22.46],[1.07,2.48]],"id":69176305},{"atl":[[1000,1.17]],"id":69176305},{"spn":500.53,"spf":"NaN","id":69176305},{"atb":[[1.03,7.48],[1.07,2.48]],"id":43498435},{"atl":[[1000,1.17]],"id":43498435},{"spn":500.53,"spf":"NaN","id":43498435},{"atb":[[1.02,11.23],[1.07,2.48]],"id":61419789},{"atl":[[1000,1]],"id":61419789},{"spn":495.53,"spf":"NaN","id":61419789},{"atb":[[1.02,11.23],[1.07,2.48]],"id":62531723},{"atl":[[1000,1]],"id":62531723},{"spn":495.53,"spf":"NaN","id":62531723},{"atb":[[1.03,7.48],[1.07,2.48]],"id":51643934},{"atl":[[1000,1]],"id":51643934},{"spn":495.53,"spf":"NaN","id":51643934}],"con":true,"img":false}]}
{"op":"mcm","clk":"11538907343","pt":1719471508878,"mc":[{"id":"1.230178321","rc":[{"atl":[[1000,0.65]],"id":43498435},{"atl":[[1000,0.65]],"id":61941199},{"atl":[[1000,0.65]],"id":69176305},{"atl":[[1000,0.48]],"id":61419789},{"atl":[[1000,0.48]],"id":62531723},{"atl":[[1000,0.48]],"id":51643934}],"con":true,"img":false}]}
{"op":"mcm","clk":"11538907355","pt":1719471509086,"mc":[{"id":"1.230178321","rc":[{"atl":[[1000,0.17]],"id":43498435},{"atl":[[1000,0.17]],"id":61941199},{"atl":[[1000,0.17]],"id":69176305},{"atl":[[1000,0]],"id":61419789},{"atl":[[1000,0]],"id":62531723},{"atl":[[1000,0]],"id":51643934}],"con":true,"img":false}]}
{"op":"mcm","clk":"11538907362","pt":1719471509188,"mc":[{"id":"1.230178321","rc":[{"atl":[[75,0.48]],"id":43498435},{"atl":[[75,0.48]],"id":61941199},{"atl":[[75,0.48]],"id":69176305},{"atl":[[75,0.48]],"id":61419789},{"atl":[[75,0.48]],"id":62531723},{"atl":[[75,0.48]],"id":51643934}],"con":true,"img":false}]}
{"op":"mcm","clk":"11539122559","pt":1719475682558,"mc":[{"id":"1.230178321","marketDefinition":{"bspMarket":true,"turnInPlayEnabled":false,"persistenceEnabled":false,"marketBaseRate":5.0,"eventId":"33376062","eventTypeId":"4339","numberOfWinners":2,"bettingType":"ODDS","marketType":"PLACE","marketTime":"2024-06-27T15:47:00.000Z","suspendTime":"2024-06-27T15:47:00.000Z","bspReconciled":false,"complete":true,"inPlay":false,"crossMatching":false,"runnersVoidable":false,"numberOfActiveRunners":6,"betDelay":0,"status":"OPEN","runners":[{"status":"ACTIVE","sortPriority":1,"id":51643934,"name":"1. Ballymac Frisby"},{"status":"ACTIVE","sortPriority":2,"id":62531723,"name":"2. Lynnway Touch"},{"status":"ACTIVE","sortPriority":3,"id":61941199,"name":"3. Kilara Thyestes"},{"status":"ACTIVE","sortPriority":4,"id":69176305,"name":"4. Moss Row Jemma"},{"status":"ACTIVE","sortPriority":5,"id":61419789,"name":"5. Buzzers Delight"},{"status":"ACTIVE","sortPriority":6,"id":43498435,"name":"6. Easy Cookie"}],"regulators":["MR_INT"],"venue":"Kinsley","countryCode":"GB","discountAllowed":true,"timezone":"Europe/London","openDate":"2024-06-27T13:36:00.000Z","version":5994643797,"name":"To Be Placed","eventName":"Kinsley 27th Jun"},"rc":[{"atb":[[1.01,22.45],[1.07,2.48]],"id":69176305},{"atl":[[75,0.48],[1000,0.17]],"id":69176305},{"spn":38.03,"spf":"NaN","id":69176305},{"atb":[[1.01,22.45],[1.07,2.48]],"id":61941199},{"atl":[[75,0.48],[1000,0.17]],"id":61941199},{"spn":38.03,"spf":"NaN","id":61941199},{"atb":[[1.03,7.48],[1.07,2.48]],"id":43498435},{"atl":[[75,0.48],[1000,0.17]],"id":43498435},{"spn":38.03,"spf":"NaN","id":43498435},{"atb":[[1.02,11.22],[1.07,2.48]],"id":61419789},{"atl":[[75,0.48],[990,0.17]],"id":61419789},{"spn":38.03,"spf":"NaN","id":61419789},{"atb":[[1.02,11.22],[1.07,2.48]],"id":62531723},{"atl":[[75,0.48],[990,0.17]],"id":62531723},{"spn":38.03,"spf":"NaN","id":62531723},{"atb":[[1.03,7.48],[1.07,2.48]],"id":51643934},{"atl":[[75,0.48],[990,0.17]],"id":51643934},{"spn":38.03,"spf":"NaN","id":51643934}],"con":true,"img":true}]}
{"op":"mcm","clk":"11539438535","pt":1719481082553,"mc":[{"id":"1.230178321","marketDefinition":{"bspMarket":true,"turnInPlayEnabled":false,"persistenceEnabled":false,"marketBaseRate":5.0,"eventId":"33376062","eventTypeId":"4339","numberOfWinners":2,"bettingType":"ODDS","marketType":"PLACE","marketTime":"2024-06-27T15:47:00.000Z","suspendTime":"2024-06-27T15:47:00.000Z","bspReconciled":false,"complete":true,"inPlay":false,"crossMatching":false,"runnersVoidable":false,"numberOfActiveRunners":6,"betDelay":0,"status":"OPEN","runners":[{"status":"ACTIVE","sortPriority":1,"id":51643934,"name":"1. Ballymac Frisby"},{"status":"ACTIVE","sortPriority":2,"id":62531723,"name":"2. Lynnway Touch"},{"status":"ACTIVE","sortPriority":3,"id":61941199,"name":"3. Kilara Thyestes"},{"status":"ACTIVE","sortPriority":4,"id":69176305,"name":"4. Moss Row Jemma"},{"status":"ACTIVE","sortPriority":5,"id":61419789,"name":"5. Buzzers Delight"},{"status":"ACTIVE","sortPriority":6,"id":43498435,"name":"6. Easy Cookie"}],"regulators":["MR_INT"],"venue":"Kinsley","countryCode":"GB","discountAllowed":true,"timezone":"Europe/London","openDate":"2024-06-27T13:36:00.000Z","version":5994643797,"name":"To Be Placed","eventName":"Kinsley 27th Jun"},"rc":[{"atb":[[1.01,22.45],[1.07,2.48]],"id":69176305},{"atl":[[75,0.48],[1000,0.17]],"id":69176305},{"spn":38.03,"spf":"NaN","id":69176305},{"atb":[[1.01,22.45],[1.07,2.48]],"id":61941199},{"atl":[[75,0.48],[1000,0.17]],"id":61941199},{"spn":38.03,"spf":"NaN","id":61941199},{"atb":[[1.03,7.48],[1.07,2.48]],"id":43498435},{"atl":[[75,0.48],[1000,0.17]],"id":43498435},{"spn":38.03,"spf":"NaN","id":43498435},{"atb":[[1.02,11.22],[1.07,2.48]],"id":61419789},{"atl":[[75,0.48],[990,0.17]],"id":61419789},{"spn":38.03,"spf":"NaN","id":61419789},{"atb":[[1.02,11.22],[1.07,2.48]],"id":62531723},{"atl":[[75,0.48],[990,0.17]],"id":62531723},{"spn":38.03,"spf":"NaN","id":62531723},{"atb":[[1.03,7.48],[1.07,2.48]],"id":51643934},{"atl":[[75,0.48],[990,0.17]],"id":51643934},{"spn":38.03,"spf":"NaN","id":51643934}],"con":true,"img":true}]}
{"op":"mcm","clk":"11540621565","pt":1719496547727,"mc":[{"id":"1.230178321","rc":[{"atb":[[1.01,22.47]],"id":69176305},{"atl":[[970,1.13],[1000,0.17]],"id":69176305},{"spn":38.03,"spf":"NaN","id":69176305},{"atb":[[1.01,22.47]],"id":61941199},{"atl":[[960,1.84],[1000,0.17]],"id":61941199},{"spn":38.03,"spf":"NaN","id":61941199},{"atb":[[1.03,7.49]],"id":43498435},{"atl":[[980,1.26],[1000,0.17]],"id":43498435},{"spn":38.03,"spf":"NaN","id":43498435},{"atb":[[1.02,11.23]],"id":61419789},{"atl":[[990,0.17],[980,2.07]],"id":61419789},{"spn":38.03,"spf":"NaN","id":61419789},{"atb":[[1.02,11.23]],"id":62531723},{"atl":[[990,0.17],[980,1.74]],"id":62531723},{"spn":38.03,"spf":"NaN","id":62531723},{"atb":[[1.03,7.49]],"id":51643934},{"atl":[[990,0.17],[970,1.82]],"id":51643934},{"spn":38.03,"spf":"NaN","id":51643934}],"con":true,"img":false}]}
{"op":"mcm","clk":"11540683369","pt":1719497282517,"mc":[{"id":"1.230178321","marketDefinition":{"bspMarket":true,"turnInPlayEnabled":false,"persistenceEnabled":false,"marketBaseRate":5.0,"eventId":"33376062","eventTypeId":"4339","numberOfWinners":2,"bettingType":"ODDS","marketType":"PLACE","marketTime":"2024-06-27T15:47:00.000Z","suspendTime":"2024-06-27T15:47:00.000Z","bspReconciled":false,"complete":true,"inPlay":false,"crossMatching":false,"runnersVoidable":false,"numberOfActiveRunners":6,"betDelay":0,"status":"OPEN","runners":[{"status":"ACTIVE","sortPriority":1,"id":51643934,"name":"1. Ballymac Frisby"},{"status":"ACTIVE","sortPriority":2,"id":62531723,"name":"2. Lynnway Touch"},{"status":"ACTIVE","sortPriority":3,"id":61941199,"name":"3. Kilara Thyestes"},{"status":"ACTIVE","sortPriority":4,"id":69176305,"name":"4. Moss Row Jemma"},{"status":"ACTIVE","sortPriority":5,"id":61419789,"name":"5. Buzzers Delight"},{"status":"ACTIVE","sortPriority":6,"id":43498435,"name":"6. Easy Cookie"}],"regulators":["MR_INT"],"venue":"Kinsley","countryCode":"GB","discountAllowed":true,"timezone":"Europe/London","openDate":"2024-06-27T13:36:00.000Z","version":5994643797,"name":"To Be Placed","eventName":"Kinsley 27th Jun"},"rc":[{"atb":[[1.01,22.46],[1.07,2.48]],"id":69176305},{"atl":[[75,0.48],[970,1.13],[1000,0.17]],"id":69176305},{"spn":38.03,"spf":"NaN","id":69176305},{"atb":[[1.01,22.46],[1.07,2.48]],"id":61941199},{"atl":[[75,0.48],[960,1.84],[1000,0.17]],"id":61941199},{"spn":38.03,"spf":"NaN","id":61941199},{"atb":[[1.03,7.49],[1.07,2.48]],"id":43498435},{"atl":[[75,0.48],[980,1.26],[1000,0.17]],"id":43498435},{"spn":38.03,"spf":"NaN","id":43498435},{"atb":[[1.02,11.23],[1.07,2.48]],"id":61419789},{"atl":[[75,0.48],[980,2.07],[990,0.17]],"id":61419789},{"spn":38.03,"spf":"NaN","id":61419789},{"atb":[[1.02,11.23],[1.07,2.48]],"id":62531723},{"atl":[[75,0.48],[980,1.74],[990,0.17]],"id":62531723},{"spn":38.03,"spf":"NaN","id":62531723},{"atb":[[1.03,7.49],[1.07,2.48]],"id":51643934},{"atl":[[75,0.48],[970,1.82],[990,0.17]],"id":51643934},{"spn":38.03,"spf":"NaN","id":51643934}],"con":true,"img":true}]}
{"op":"mcm","clk":"11541011378","pt":1719501122445,"mc":[{"id":"1.230178321","rc":[{"atb":[[1.01,22.47],[1.04,1]],"id":69176305},{"atl":[[970,1.13]],"id":69176305},{"atb":[[1.01,22.47],[1.04,1]],"id":61941199},{"atl":[[960,1.84]],"id":61941199},{"atb":[[1.03,7.49],[1.04,1]],"id":43498435},{"atl":[[980,1.26]],"id":43498435},{"atb":[[1.02,11.23],[1.04,1]],"id":61419789},{"atl":[[980,2.07]],"id":61419789},{"atb":[[1.02,11.23],[1.04,1]],"id":62531723},{"atl":[[980,1.74]],"id":62531723},{"atb":[[1.03,7.49],[1.04,1]],"id":51643934},{"atl":[[970,1.82]],"id":51643934}],"con":true,"img":false}]}
{"op":"mcm","clk":"11541011388","pt":1719501122538,"mc":[{"id":"1.230178321","rc":[{"atb":[[1.04,0.25]],"id":43498435},{"atb":[[1.04,0.25]],"id":61941199},{"atb":[[1.04,0.25]],"id":69176305},{"atb":[[1.04,0.25]],"id":61419789},{"atb":[[1.04,0.25]],"id":62531723},{"atb":[[1.04,0.25]],"id":51643934}],"con":true,"img":false}]}
{"op":"mcm","clk":"11541011395","pt":1719501122655,"mc":[{"id":"1.230178321","rc":[{"atb":[[1.04,0]],"id":43498435},{"atb":[[1.04,0]],"id":61941199},{"atb":[[1.04,0]],"id":69176305},{"atb":[[1.04,0]],"id":61419789},{"atb":[[1.04,0]],"id":62531723},{"atb":[[1.04,0]],"id":51643934}],"con":true,"img":false}]}
{"op":"mcm","clk":"11541011402","pt":1719501122710,"mc":[{"id":"1.230178321","rc":[{"atb":[[1.2,0.25]],"id":61941199},{"atb":[[1.2,0.25]],"id":69176305},{"atb":[[1.2,0.25]],"id":43498435},{"atb":[[1.2,0.25]],"id":61419789},{"atb":[[1.2,0.25]],"id":62531723},{"atb":[[1.2,0.25]],"id":51643934}],"con":true,"img":false}]}
{"op":"mcm","clk":"11541044817","pt":1719501513138,"mc":[{"id":"1.230178321","rc":[{"atb":[[1.09,47.04]],"id":69176305},{"spn":38.1,"spf":"NaN","id":69176305},{"spn":38.1,"spf":"NaN","id":61941199},{"spn":38.1,"spf":"NaN","id":43498435},{"spn":38.1,"spf":"NaN","id":61419789},{"spn":38.1,"spf":"NaN","id":62531723},{"spn":38.1,"spf":"NaN","id":51643934}],"con":true,"img":false}]}
{"op":"mcm","clk":"11541044866","pt":1719501513862,"mc":[{"id":"1.230178321","rc":[{"atb":[[1.09,47.04]],"id":51643934}],"con":true,"img":false}]}
{"op":"mcm","clk":"11541045534","pt":1719501521972,"mc":[{"id":"1.230178321","marketDefinition":{"bspMarket":true,"turnInPlayEnabled":false,"persistenceEnabled":false,"marketBaseRate":5.0,"eventId":"33376062","eventTypeId":"4339","numberOfWinners":2,"bettingType":"ODDS","marketType":"PLACE","marketTime":"2024-06-27T15:47:00.000Z","suspendTime":"2024-06-27T15:47:00.000Z","bspReconciled":false,"complete":true,"inPlay":false,"crossMatching":true,"runnersVoidable":false,"numberOfActiveRunners":6,"betDelay":0,"status":"OPEN","runners":[{"status":"ACTIVE","sortPriority":1,"id":51643934,"name":"1. Ballymac Frisby"},{"status":"ACTIVE","sortPriority":2,"id":62531723,"name":"2. Lynnway Touch"},{"status":"ACTIVE","sortPriority":3,"id":61941199,"name":"3. Kilara Thyestes"},{"status":"ACTIVE","sortPriority":4,"id":69176305,"name":"4. Moss Row Jemma"},{"status":"ACTIVE","sortPriority":5,"id":61419789,"name":"5. Buzzers Delight"},{"status":"ACTIVE","sortPriority":6,"id":43498435,"name":"6. Easy Cookie"}],"regulators":["MR_INT"],"venue":"Kinsley","countryCode":"GB","discountAllowed":true,"timezone":"Europe/London","openDate":"2024-06-27T13:36:00.000Z","version":5994643797,"name":"To Be Placed","eventName":"Kinsley 27th Jun"},"rc":[],"con":true,"img":false}]}
{"op":"mcm","clk":"11541049872","pt":1719501573791,"mc":[{"id":"1.230178321","rc":[{"atb":[[1.11,35.93]],"id":69176305},{"atb":[[1.11,35.93]],"id":51643934}],"con":true,"img":false}]}
{"op":"mcm","clk":"11541050805","pt":1719501585018,"mc":[{"id":"1.230178321","rc":[{"atb":[[1.09,0]],"id":69176305},{"atb":[[1.09,0]],"id":51643934}],"con":true,"img":false}]}
{"op":"mcm","clk":"11541050848","pt":1719501585636,"mc":[{"id":"1.230178321","rc":[{"atb":[[1.13,32.56]],"id":69176305}],"con":true,"img":false}]}
{"op":"mcm","clk":"11541050943","pt":1719501586613,"mc":[{"id":"1.230178321","rc":[{"atb":[[1.13,32.56]],"id":51643934}],"con":true,"img":false}]}
{"op":"mcm","clk":"11541051201","pt":1719501590131,"mc":[{"id":"1.230178321","rc":[{"atb":[[1.11,0]],"id":51643934}],"con":true,"img":false}]}
{"op":"mcm","clk":"11541051214","pt":1719501590339,"mc":[{"id":"1.230178321","rc":[{"atb":[[1.11,0]],"id":69176305}],"con":true,"img":false}]}
{"op":"mcm","clk":"11541051254","pt":1719501590808,"mc":[{"id":"1.230178321","rc":[{"atb":[[1.15,26.34]],"id":51643934}],"con":true,"img":false}]}
{"op":"mcm","clk":"11541051272","pt":1719501591015,"mc":[{"id":"1.230178321","rc":[{"atb":[[1.15,26.34]],"id":69176305}],"con":true,"img":false}]}
{"op":"mcm","clk":"11541053671","pt":1719501618671,"mc":[{"id":"1.230178321","rc":[{"atb":[[1.13,0]],"id":69176305}],"con":true,"img":false}]}
{"op":"mcm","clk":"11541053700","pt":1719501619041,"mc":[{"id":"1.230178321","rc":[{"atb":[[1.13,0]],"id":51643934}],"con":true,"img":false}]}
{"op":"mcm","clk":"11541053787","pt":1719501620066,"mc":[{"id":"1.230178321","rc":[{"atb":[[1.17,24.9]],"id":69176305}],"con":true,"img":false}]}
{"op":"mcm","clk":"11541053823","pt":1719501620479,"mc":[{"id":"1.230178321","rc":[{"atb":[[1.17,24.9]],"id":51643934}],"con":true,"img":false}]}
{"op":"mcm","clk":"11541054651","pt":1719501628891,"mc":[{"id":"1.230178321","rc":[{"atb":[[1.15,0]],"id":69176305},{"atb":[[1.15,0]],"id":51643934}],"con":true,"img":false}]}
{"op":"mcm","clk":"11541054687","pt":1719501629263,"mc":[{"id":"1.230178321","rc":[{"atb":[[1.19,20.8]],"id":69176305}],"con":true,"img":false}]}
{"op":"mcm","clk":"11541054705","pt":1719501629470,"mc":[{"id":"1.230178321","rc":[{"atb":[[1.19,20.8]],"id":51643934}],"con":true,"img":false}]}
{"op":"mcm","clk":"11541056926","pt":1719501656197,"mc":[{"id":"1.230178321","rc":[{"atb":[[1.17,0]],"id":69176305}],"con":true,"img":false}]}
{"op":"mcm","clk":"11541056933","pt":1719501656297,"mc":[{"id":"1.230178321","rc":[{"atb":[[1.17,0]],"id":51643934}],"con":true,"img":false}]}
{"op":"mcm","clk":"11541057001","pt":1719501657223,"mc":[{"id":"1.230178321","rc":[{"atb":[[1.21,20.16]],"id":51643934}],"con":true,"img":false}]}
{"op":"mcm","clk":"11541057041","pt":1719501657594,"mc":[{"id":"1.230178321","rc":[{"atb":[[1.21,20.16]],"id":69176305}],"con":true,"img":false}]}
{"op":"mcm","clk":"11541057657","pt":1719501664615,"mc":[{"id":"1.230178321","rc":[{"atb":[[1.19,0]],"id":51643934}],"con":true,"img":false}]}
{"op":"mcm","clk":"11541057692","pt":1719501665029,"mc":[{"id":"1.230178321","rc":[{"atb":[[1.19,0]],"id":69176305}],"con":true,"img":false}]}
{"op":"mcm","clk":"11541057716","pt":1719501665338,"mc":[{"id":"1.230178321","rc":[{"atb":[[1.23,17.18]],"id":51643934}],"con":true,"img":false}]}
{"op":"mcm","clk":"11541057800","pt":1719501666218,"mc":[{"id":"1.230178321","rc":[{"atb":[[1.23,17.18]],"id":69176305}],"con":true,"img":false}]}
{"op":"mcm","clk":"11541060057","pt":1719501692946,"mc":[{"id":"1.230178321","rc":[{"atb":[[1.21,0]],"id":69176305},{"atb":[[1.21,0]],"id":51643934}],"con":true,"img":false}]}
{"op":"mcm","clk":"11541060094","pt":1719501693524,"mc":[{"id":"1.230178321","rc":[{"atb":[[1.25,16.93]],"id":51643934}],"con":true,"img":false}]}
{"op":"mcm","clk":"11541060147","pt":1719501694460,"mc":[{"id":"1.230178321","rc":[{"atb":[[1.25,16.93]],"id":69176305}],"con":true,"img":false}]}
{"op":"mcm","clk":"11541060681","pt":1719501701146,"mc":[{"id":"1.230178321","rc":[{"atb":[[1.23,0]],"id":51643934}],"con":true,"img":false}]}
{"op":"mcm","clk":"11541060685","pt":1719501701249,"mc":[{"id":"1.230178321","rc":[{"atb":[[1.23,0]],"id":69176305}],"con":true,"img":false}]}
{"op":"mcm","clk":"11541060707","pt":1719501701552,"mc":[{"id":"1.230178321","rc":[{"atb":[[1.27,14.64]],"id":51643934}],"con":true,"img":false}]}
{"op":"mcm","clk":"11541060713","pt":1719501701657,"mc":[{"id":"1.230178321","rc":[{"atb":[[1.27,14.64]],"id":69176305}],"con":true,"img":false}]}
{"op":"mcm","clk":"11541062987","pt":1719501729394,"mc":[{"id":"1.230178321","rc":[{"atb":[[1.25,0]],"id":69176305},{"spn":38.13,"spf":"NaN","id":69176305},{"atb":[[1.25,0]],"id":51643934},{"spn":38.13,"spf":"NaN","id":51643934}],"con":true,"img":false}]}
{"op":"mcm","clk":"11541063019","pt":1719501729860,"mc":[{"id":"1.230178321","rc":[{"atb":[[1.29,14.59]],"id":69176305}],"con":true,"img":false}]}
{"op":"mcm","clk":"11541063055","pt":1719501730373,"mc":[{"id":"1.230178321","rc":[{"atb":[[1.29,14.59]],"id":51643934}],"con":true,"img":false}]}
{"op":"mcm","clk":"11541063628","pt":1719501736985,"mc":[{"id":"1.230178321","rc":[{"atb":[[1.27,0]],"id":51643934}],"con":true,"img":false}]}
{"op":"mcm","clk":"11541063654","pt":1719501737291,"mc":[{"id":"1.230178321","rc":[{"atb":[[1.27,0]],"id":69176305}],"con":true,"img":false}]}
{"op":"mcm","clk":"11541063673","pt":1719501737498,"mc":[{"id":"1.230178321","rc":[{"atb":[[1.31,12.75]],"id":51643934}],"con":true,"img":false}]}
{"op":"mcm","clk":"11541063688","pt":1719501737705,"mc":[{"id":"1.230178321","rc":[{"atb":[[1.31,12.75]],"id":69176305}],"con":true,"img":false}]}
{"op":"mcm","clk":"11541065619","pt":1719501761115,"mc":[{"id":"1.230178321","rc":[{"atb":[[1.29,0]],"id":51643934}],"con":true,"img":false}]}
{"op":"mcm","clk":"11541065651","pt":1719501761528,"mc":[{"id":"1.230178321","rc":[{"atb":[[1.29,0]],"id":69176305}],"con":true,"img":false}]}
{"op":"mcm","clk":"11541065667","pt":1719501761734,"mc":[{"id":"1.230178321","rc":[{"atb":[[1.33,12.82]],"id":51643934}],"con":true,"img":false}]}
{"op":"mcm","clk":"11541065705","pt":1719501762202,"mc":[{"id":"1.230178321","rc":[{"atb":[[1.33,12.82]],"id":69176305}],"con":true,"img":false}]}
{"op":"mcm","clk":"11541066688","pt":1719501774942,"mc":[{"id":"1.230178321","rc":[{"atb":[[1.31,0]],"id":51643934}],"con":true,"img":false}]}
{"op":"mcm","clk":"11541066706","pt":1719501775215,"mc":[{"id":"1.230178321","rc":[{"atb":[[1.31,0]],"id":69176305}],"con":true,"img":false}]}
{"op":"mcm","clk":"11541066743","pt":1719501775825,"mc":[{"id":"1.230178321","rc":[{"atb":[[1.35,11.29]],"id":51643934}],"con":true,"img":false}]}
{"op":"mcm","clk":"11541066766","pt":1719501776230,"mc":[{"id":"1.230178321","rc":[{"atb":[[1.35,11.29]],"id":69176305}],"con":true,"img":false}]}
{"op":"mcm","clk":"11541068465","pt":1719501796763,"mc":[{"id":"1.230178321","rc":[{"spn":38.17,"spf":"NaN","id":69176305},{"atb":[[1.33,0]],"id":51643934},{"spn":38.17,"spf":"NaN","id":51643934}],"con":true,"img":false}]}
{"op":"mcm","clk":"11541068478","pt":1719501796931,"mc":[{"id":"1.230178321","rc":[{"atb":[[1.33,0]],"id":69176305}],"con":true,"img":false}]}
{"op":"mcm","clk":"11541068539","pt":1719501797654,"mc":[{"id":"1.230178321","rc":[{"atb":[[1.37,11.43]],"id":69176305}],"con":true,"img":false}]}
{"op":"mcm","clk":"11541068575","pt":1719501798061,"mc":[{"id":"1.230178321","rc":[{"atb":[[1.37,11.43]],"id":51643934}],"con":true,"img":false}]}
{"op":"mcm","clk":"11541069602","pt":1719501809853,"mc":[{"id":"1.230178321","rc":[{"atb":[[1.35,0]],"id":69176305},{"atb":[[1.35,0]],"id":51643934}],"con":true,"img":false}]}
{"op":"mcm","clk":"11541069622","pt":1719501810060,"mc":[{"id":"1.230178321","rc":[{"atb":[[1.39,10.13]],"id":51643934}],"con":true,"img":false}]}
{"op":"mcm","clk":"11541069643","pt":1719501810265,"mc":[{"id":"1.230178321","rc":[{"atb":[[1.39,10.13]],"id":69176305}],"con":true,"img":false}]}
{"op":"mcm","clk":"11541071514","pt":1719501833505,"mc":[{"id":"1.230178321","rc":[{"atb":[[1.37,0]],"id":51643934}],"con":true,"img":false}]}
{"op":"mcm","clk":"11541071534","pt":1719501833668,"mc":[{"id":"1.230178321","rc":[{"atb":[[1.37,0]],"id":69176305}],"con":true,"img":false}]}
{"op":"mcm","clk":"11541071568","pt":1719501834069,"mc":[{"id":"1.230178321","rc":[{"atb":[[1.41,10.33]],"id":51643934}],"con":true,"img":false}]}
{"op":"mcm","clk":"11541071632","pt":1719501834894,"mc":[{"id":"1.230178321","rc":[{"atb":[[1.41,10.33]],"id":69176305}],"con":true,"img":false}]}
{"op":"mcm","clk":"11541072557","pt":1719501845483,"mc":[{"id":"1.230178321","rc":[{"atb":[[1.39,0]],"id":69176305},{"atb":[[1.39,0]],"id":51643934}],"con":true,"img":false}]}
{"op":"mcm","clk":"11541072599","pt":1719501845902,"mc":[{"id":"1.230178321","rc":[{"atb":[[1.43,9.19]],"id":69176305}],"con":true,"img":false}]}
{"op":"mcm","clk":"11541072624","pt":1719501846096,"mc":[{"id":"1.230178321","rc":[{"atb":[[1.43,9.19]],"id":51643934}],"con":true,"img":false}]}
{"op":"mcm","clk":"11541074393","pt":1719501866604,"mc":[{"id":"1.230178321","rc":[{"atb":[[1.41,0]],"id":69176305},{"spn":38.21,"spf":"NaN","id":69176305},{"atb":[[1.41,0]],"id":51643934},{"spn":38.21,"spf":"NaN","id":51643934}],"con":true,"img":false}]}
{"op":"mcm","clk":"11541074440","pt":1719501867119,"mc":[{"id":"1.230178321","rc":[{"atb":[[1.45,9.4]],"id":69176305}],"con":true,"img":false}]}
{"op":"mcm","clk":"11541074453","pt":1719501867326,"mc":[{"id":"1.230178321","rc":[{"atb":[[1.45,9.4]],"id":51643934}],"con":true,"img":false}]}
{"op":"mcm","clk":"11541075663","pt":1719501881527,"mc":[{"id":"1.230178321","rc":[{"atb":[[1.43,0]],"id":69176305},{"atb":[[1.43,0]],"id":51643934}],"con":true,"img":false}]}
{"op":"mcm","clk":"11541075680","pt":1719501881734,"mc":[{"id":"1.230178321","rc":[{"atb":[[1.47,8.41]],"id":51643934}],"con":true,"img":false}]}
{"op":"mcm","clk":"11541075699","pt":1719501881994,"mc":[{"id":"1.230178321","rc":[{"atb":[[1.47,8.41]],"id":69176305}],"con":true,"img":false}]}
{"op":"mcm","clk":"11541077001","pt":1719501898646,"mc":[{"id":"1.230178321","rc":[{"atb":[[1.45,0]],"id":51643934}],"con":true,"img":false}]}
{"op":"mcm","clk":"11541077010","pt":1719501898751,"mc":[{"id":"1.230178321","rc":[{"atb":[[1.45,0]],"id":69176305}],"con":true,"img":false}]}
{"op":"mcm","clk":"11541077047","pt":1719501899219,"mc":[{"id":"1.230178321","rc":[{"atb":[[1.49,8.63]],"id":69176305}],"con":true,"img":false}]}
{"op":"mcm","clk":"11541077054","pt":1719501899321,"mc":[{"id":"1.230178321","rc":[{"atb":[[1.49,8.63]],"id":51643934}],"con":true,"img":false}]}
{"op":"mcm","clk":"11541078691","pt":1719501917781,"mc":[{"id":"1.230178321","rc":[{"atb":[[1.47,0]],"id":51643934}],"con":true,"img":false}]}
{"op":"mcm","clk":"11541078713","pt":1719501917943,"mc":[{"id":"1.230178321","rc":[{"atb":[[1.51,7.74]],"id":51643934}],"con":true,"img":false}]}
{"op":"mcm","clk":"11541078741","pt":1719501918251,"mc":[{"id":"1.230178321","rc":[{"atb":[[1.47,0]],"id":69176305}],"con":true,"img":false}]}
{"op":"mcm","clk":"11541078755","pt":1719501918461,"mc":[{"id":"1.230178321","rc":[{"atb":[[1.51,7.74]],"id":69176305}],"con":true,"img":false}]}
{"op":"mcm","clk":"11541079994","pt":1719501931991,"mc":[{"id":"1.230178321","rc":[{"atb":[[1.49,0]],"id":69176305},{"spn":38.25,"spf":"NaN","id":69176305},{"spn":38.25,"spf":"NaN","id":51643934}],"con":true,"img":false}]}
{"op":"mcm","clk":"11541080069","pt":1719501932671,"mc":[{"id":"1.230178321","rc":[{"atb":[[1.53,7.98]],"id":69176305}],"con":true,"img":false}]}
{"op":"mcm","clk":"11541080382","pt":1719501935890,"mc":[{"id":"1.230178321","rc":[{"atb":[[1.51,0]],"id":69176305}],"con":true,"img":false}]}
{"op":"mcm","clk":"11541080400","pt":1719501936096,"mc":[{"id":"1.230178321","rc":[{"atb":[[1.55,7.18]],"id":69176305}],"con":true,"img":false}]}
{"op":"mcm","clk":"11541083186","pt":1719501965893,"mc":[{"id":"1.230178321","rc":[{"atb":[[1.53,0]],"id":69176305}],"con":true,"img":false}]}
{"op":"mcm","clk":"11541083220","pt":1719501966203,"mc":[{"id":"1.230178321","rc":[{"atb":[[1.57,7.42]],"id":69176305}],"con":true,"img":false}]}
{"op":"mcm","clk":"11541083858","pt":1719501973434,"mc":[{"id":"1.230178321","rc":[{"atb":[[1.55,0]],"id":69176305}],"con":true,"img":false}]}
{"op":"mcm","clk":"11541083876","pt":1719501973596,"mc":[{"id":"1.230178321","rc":[{"atb":[[1.59,6.69]],"id":69176305}],"con":true,"img":false}]}
{"op":"mcm","clk":"11541085718","pt":1719501996958,"mc":[{"id":"1.230178321","rc":[{"atb":[[1.57,0]],"id":69176305},{"spn":38.29,"spf":"NaN","id":69176305}],"con":true,"img":false}]}
{"op":"mcm","clk":"11541085752","pt":1719501997426,"mc":[{"id":"1.230178321","rc":[{"atb":[[1.61,6.94]],"id":69176305}],"con":true,"img":false}]}
{"op":"mcm","clk":"11541086538","pt":1719502008168,"mc":[{"id":"1.230178321","rc":[{"atb":[[1.59,0]],"id":69176305}],"con":true,"img":false}]}
{"op":"mcm","clk":"11541086554","pt":1719502008328,"mc":[{"id":"1.230178321","rc":[{"atb":[[1.63,6.27]],"id":69176305}],"con":true,"img":false}]}
{"op":"mcm","clk":"11541087552","pt":1719502021850,"mc":[{"id":"1.230178321","rc":[{"atb":[[1.64,2.11]],"id":69176305},{"atb":[[1.52,2.11]],"id":51643934}],"con":true,"img":false}]}
{"op":"mcm","clk":"11541087872","pt":1719502026285,"mc":[{"id":"1.230178321","rc":[{"atb":[[1.63,0]],"id":69176305}],"con":true,"img":false}]}
{"op":"mcm","clk":"11541087886","pt":1719502026449,"mc":[{"id":"1.230178321","rc":[{"atb":[[1.66,5.99]],"id":69176305}],"con":true,"img":false}]}
{"op":"mcm","clk":"11541088079","pt":1719502028658,"mc":[{"id":"1.230178321","rc":[{"atb":[[1.61,0]],"id":69176305}],"con":true,"img":false}]}
{"op":"mcm","clk":"11541088104","pt":1719502028971,"mc":[{"id":"1.230178321","rc":[{"atb":[[1.68,6.22]],"id":69176305}],"con":true,"img":false}]}
{"op":"mcm","clk":"11541089217","pt":1719502044366,"mc":[{"id":"1.230178321","rc":[{"atb":[[1.66,0]],"id":69176305}],"con":true,"img":false}]}
{"op":"mcm","clk":"11541089253","pt":1719502044767,"mc":[{"id":"1.230178321","rc":[{"atb":[[1.7,5.64]],"id":69176305}],"con":true,"img":false}]}
{"op":"mcm","clk":"11541090374","pt":1719502059606,"mc":[{"id":"1.230178321","rc":[{"atb":[[1.68,0]],"id":69176305},{"spn":38.35,"spf":"NaN","id":69176305},{"spn":38.26,"spf":"NaN","id":51643934}],"con":true,"img":false}]}
{"op":"mcm","clk":"11541090399","pt":1719502059873,"mc":[{"id":"1.230178321","rc":[{"atb":[[1.72,5.87]],"id":69176305}],"con":true,"img":false}]}
{"op":"mcm","clk":"11541090677","pt":1719502062888,"mc":[{"id":"1.230178321","rc":[{"atb":[[1.7,0]],"id":69176305}],"con":true,"img":false}]}
{"op":"mcm","clk":"11541090700","pt":1719502063195,"mc":[{"id":"1.230178321","rc":[{"atb":[[1.74,5.34]],"id":69176305}],"con":true,"img":false}]}
{"op":"mcm","clk":"11541092969","pt":1719502092050,"mc":[{"id":"1.230178321","rc":[{"atb":[[1.49,0]],"id":51643934}],"con":true,"img":false}]}
{"op":"mcm","clk":"11541093158","pt":1719502094249,"mc":[{"id":"1.230178321","rc":[{"atb":[[1.72,0]],"id":69176305}],"con":true,"img":false}]}
{"op":"mcm","clk":"11541093210","pt":1719502094934,"mc":[{"id":"1.230178321","rc":[{"atb":[[1.76,5.57]],"id":69176305}],"con":true,"img":false}]}
{"op":"mcm","clk":"11541093413","pt":1719502098141,"mc":[{"id":"1.230178321","rc":[{"atb":[[1.51,0]],"id":51643934}],"con":true,"img":false}]}
{"op":"mcm","clk":"11541110258","pt":1719502320366,"mc":[{"id":"1.230178321","rc":[{"atb":[[1.74,6.34],[1.53,10.68]],"id":69176305},{"atl":[[9.2,2],[4.9,1]],"id":69176305},{"spn":3.33,"spf":"NaN","id":69176305},{"atb":[[2.24,1],[1.64,2.48]],"id":61941199},{"atl":[[21,2],[6,1]],"id":61941199},{"spn":4.12,"spf":"NaN","id":61941199},{"atb":[[2.54,1],[1.93,2.48]],"id":43498435},{"atl":[[70,2],[7.4,1]],"id":43498435},{"spn":4.97,"spf":"NaN","id":43498435},{"atb":[[2.12,1],[1.69,2.48]],"id":62531723},{"atl":[[25,2],[5.7,1]],"id":62531723},{"spn":3.91,"spf":"NaN","id":62531723}],"con":true,"img":false}]}
{"op":"mcm","clk":"11541110279","pt":1719502320574,"mc":[{"id":"1.230178321","rc":[{"atb":[[1.63,2.48]],"id":61419789},{"atl":[[20,2]],"id":61419789},{"atb":[[1.44,1],[1.34,4.24]],"id":51643934},{"atl":[[7.4,2],[3.5,1]],"id":51643934}],"con":true,"img":false}]}
{"op":"mcm","clk":"11541110288","pt":1719502320677,"mc":[{"id":"1.230178321","rc":[{"atb":[[1.78,1]],"id":61419789},{"atl":[[4.6,1]],"id":61419789}],"con":true,"img":false}]}
{"op":"mcm","clk":"11541111035","pt":1719502329676,"mc":[{"id":"1.230178321","rc":[{"atb":[[1.63,0],[1.71,2.48]],"id":61419789},{"atb":[[1.4,3.12]],"id":51643934}],"con":true,"img":false}]}
{"op":"mcm","clk":"11541111042","pt":1719502329780,"mc":[{"id":"1.230178321","rc":[{"atb":[[1.34,0]],"id":51643934}],"con":true,"img":false}]}
{"op":"mcm","clk":"11541111110","pt":1719502330454,"mc":[{"id":"1.230178321","rc":[{"atb":[[2.16,2.48]],"id":43498435},{"atb":[[1.62,11.14]],"id":69176305},{"atb":[[1.64,0],[1.72,2.48]],"id":61941199},{"atb":[[1.78,2.48],[1.69,0]],"id":62531723}],"con":true,"img":false}]}
{"op":"mcm","clk":"11541111117","pt":1719502330558,"mc":[{"id":"1.230178321","rc":[{"atb":[[1.53,0]],"id":69176305},{"atb":[[1.93,0]],"id":43498435}],"con":true,"img":false}]}
{"op":"mcm","clk":"11541111730","pt":1719502339269,"mc":[{"id":"1.230178321","rc":[{"atb":[[2.54,0],[2.62,1]],"id":43498435},{"atl":[[4.8,1],[4.9,0]],"id":69176305},{"atl":[[5.8,1],[6,0]],"id":61941199},{"atb":[[2.24,1],[2.12,0]],"id":62531723},{"atl":[[5.6,1],[5.7,0]],"id":62531723},{"atl":[[3.45,1],[3.5,0]],"id":51643934}],"con":true,"img":false}]}
{"op":"mcm","clk":"11541111750","pt":1719502339479,"mc":[{"id":"1.230178321","rc":[{"atl":[[5.6,1],[5.8,0]],"id":61941199},{"atl":[[4.8,0],[4.3,1]],"id":69176305},{"atb":[[1.75,2.48],[1.71,0]],"id":61419789},{"atl":[[4.5,1],[4.6,0]],"id":61419789},{"atb":[[1.4,0],[1.44,5.24]],"id":51643934},{"atl":[[3.45,0],[3.15,1]],"id":51643934}],"con":true,"img":false}]}
{"op":"mcm","clk":"11541111762","pt":1719502339583,"mc":[{"id":"1.230178321","rc":[{"atl":[[18.5,2],[21,0]],"id":61941199},{"atl":[[8.6,2],[9.2,0]],"id":69176305},{"atl":[[18,2],[20,0]],"id":61419789},{"atl":[[6.8,2]],"id":51643934}],"con":true,"img":false}]}
{"op":"mcm","clk":"11541111770","pt":1719502339685,"mc":[{"id":"1.230178321","rc":[{"atl":[[7.4,0]],"id":51643934}],"con":true,"img":false}]}
{"op":"mcm","clk":"11541111781","pt":1719502339893,"mc":[{"id":"1.230178321","rc":[{"atb":[[2.54,1],[2.62,0]],"id":43498435},{"atb":[[1.83,1],[1.78,0]],"id":61419789},{"atb":[[2.24,0],[2.12,1]],"id":62531723}],"con":true,"img":false}]}
{"op":"mcm","clk":"11541111798","pt":1719502340161,"mc":[{"id":"1.230178321","rc":[{"atl":[[4.8,1],[4.3,0]],"id":69176305},{"atl":[[5.6,0],[5.8,1]],"id":61941199},{"atl":[[3.45,1],[3.15,0]],"id":51643934}],"con":true,"img":false}]}
{"op":"mcm","clk":"11541111827","pt":1719502340467,"mc":[{"id":"1.230178321","rc":[{"atb":[[1.74,17.48]],"id":69176305},{"atb":[[2.24,2.48],[2.16,0]],"id":43498435},{"atb":[[1.83,2.48]],"id":62531723}],"con":true,"img":false}]}
{"op":"mcm","clk":"11541111836","pt":1719502340574,"mc":[{"id":"1.230178321","rc":[{"atb":[[1.62,0]],"id":69176305},{"atb":[[1.78,0]],"id":62531723}],"con":true,"img":false}]}
{"op":"mcm","clk":"11541112910","pt":1719502354315,"mc":[{"id":"1.230178321","rc":[{"atb":[[2.54,0],[2.62,1]],"id":43498435},{"atl":[[5.6,1]],"id":61941199},{"atb":[[1.83,0],[1.78,1]],"id":61419789},{"atb":[[2.24,1],[2.12,0]],"id":62531723}],"con":true,"img":false}]}
{"op":"mcm","clk":"11541112919","pt":1719502354382,"mc":[{"id":"1.230178321","rc":[{"atl":[[5.8,0]],"id":61941199},{"atl":[[4.8,0],[4.3,1]],"id":69176305},{"atl":[[3.45,0],[3.15,1]],"id":51643934}],"con":true,"img":false}]}
{"op":"mcm","clk":"11541113678","pt":1719502364702,"mc":[{"id":"1.230178321","rc":[{"atb":[[1.02,2]],"id":51643934}],"con":true,"img":false}]}
{"op":"mcm","clk":"11541113699","pt":1719502365117,"mc":[{"id":"1.230178321","rc":[{"atb":[[1.02,13.23]],"id":62531723}],"con":true,"img":false}]}
{"op":"mcm","clk":"11541113720","pt":1719502365388,"mc":[{"id":"1.230178321","rc":[{"atb":[[1.02,2]],"id":61941199}],"con":true,"img":false}]}
{"op":"mcm","clk":"11541113741","pt":1719502365695,"mc":[{"id":"1.230178321","rc":[{"atb":[[1.77,2]],"id":69176305}],"con":true,"img":false}]}
{"op":"mcm","clk":"11541113775","pt":1719502366109,"mc":[{"id":"1.230178321","rc":[{"atb":[[1.02,13.23]],"id":61419789}],"con":true,"img":false}]}
{"op":"mcm","clk":"11541113806","pt":1719502366487,"mc":[{"id":"1.230178321","rc":[{"atb":[[1.02,2]],"id":43498435}],"con":true,"img":false}]}
{"op":"mcm","clk":"11541117697","pt":1719502417840,"mc":[{"id":"1.230178321","rc":[{"atb":[[2.54,1],[2.62,0]],"id":43498435},{"spn":3.03,"spf":"NaN","id":69176305},{"spn":3.92,"spf":"NaN","id":61941199},{"spn":3.14,"spf":"NaN","id":61419789},{"atb":[[2.24,0],[2.12,1]],"id":62531723},{"spn":3.86,"spf":"NaN","id":62531723},{"spn":2.33,"spf":"NaN","id":51643934}],"con":true,"img":false}]}
{"op":"mcm","clk":"11541117730","pt":1719502418255,"mc":[{"id":"1.230178321","rc":[{"atl":[[5.6,0],[5.8,1]],"id":61941199}],"con":true,"img":false}]}
{"op":"mcm","clk":"11541117736","pt":1719502418357,"mc":[{"id":"1.230178321","rc":[{"atb":[[2.54,0],[2.62,1]],"id":43498435},{"atl":[[4.8,1],[4.3,0]],"id":69176305},{"atb":[[2.24,1],[2.12,0]],"id":62531723},{"atl":[[3.45,1],[3.15,0]],"id":51643934}],"con":true,"img":false}]}
{"op":"mcm","clk":"11541118069","pt":1719502423571,"mc":[{"id":"1.230178321","rc":[{"atl":[[4.8,0],[4.3,1]],"id":69176305},{"atl":[[5.6,1],[5.8,0]],"id":61941199},{"atl":[[3.45,0],[3.15,1]],"id":51643934}],"con":true,"img":false}]}
{"op":"mcm","clk":"11541119631","pt":1719502442383,"mc":[{"id":"1.230178321","rc":[{"atb":[[1.74,12.14]],"id":69176305}],"con":true,"img":false}]}
{"op":"mcm","clk":"11541120722","pt":1719502456212,"mc":[{"id":"1.230178321","rc":[{"atb":[[1.76,0]],"id":69176305}],"con":true,"img":false}]}
{"op":"mcm","clk":"11541120782","pt":1719502457022,"mc":[{"id":"1.230178321","rc":[{"atb":[[1.77,0]],"id":69176305}],"con":true,"img":false}]}
{"op":"mcm","clk":"11541120792","pt":1719502457129,"mc":[{"id":"1.230178321","rc":[{"atb":[[1.64,26.39],[1.74,1],[1.75,2]],"id":69176305}],"con":true,"img":false}]}
{"op":"mcm","clk":"11541120802","pt":1719502457231,"mc":[{"id":"1.230178321","rc":[{"atb":[[1.64,2.11],[1.34,14.26]],"id":69176305}],"con":true,"img":false}]}
{"op":"mcm","clk":"11541120807","pt":1719502457340,"mc":[{"id":"1.230178321","rc":[{"atb":[[1.74,5],[1.34,0]],"id":69176305}],"con":true,"img":false}]}
{"op":"mcm","clk":"11541120902","pt":1719502458738,"mc":[{"id":"1.230178321","rc":[{"atb":[[1.26,5]],"id":69176305}],"con":true,"img":false}]}
{"op":"mcm","clk":"11541120916","pt":1719502458903,"mc":[{"id":"1.230178321","rc":[{"atb":[[1.26,0]],"id":69176305}],"con":true,"img":false}]}
{"op":"mcm","clk":"11541120953","pt":1719502459416,"mc":[{"id":"1.230178321","rc":[{"atb":[[1.7,3.48],[1.75,0]],"id":61419789},{"atb":[[1.4,7.36],[1.44,1]],"id":51643934}],"con":true,"img":false}]}
{"op":"mcm","clk":"11541120958","pt":1719502459520,"mc":[{"id":"1.230178321","rc":[{"atb":[[1.74,1],[1.68,7]],"id":69176305},{"atb":[[1.83,0],[1.77,3.48]],"id":62531723}],"con":true,"img":false}]}
{"op":"mcm","clk":"11541121094","pt":1719502461529,"mc":[{"id":"1.230178321","rc":[{"atb":[[1.75,0]],"id":69176305}],"con":true,"img":false}]}
{"op":"mcm","clk":"11541121099","pt":1719502461633,"mc":[{"id":"1.230178321","rc":[{"atb":[[1.68,0],[1.65,8],[1.69,2]],"id":69176305}],"con":true,"img":false}]}
{"op":"mcm","clk":"11541121108","pt":1719502461737,"mc":[{"id":"1.230178321","rc":[{"atb":[[1.68,3],[1.65,0]],"id":69176305}],"con":true,"img":false}]}
{"op":"mcm","clk":"11541121213","pt":1719502463239,"mc":[{"id":"1.230178321","rc":[{"atb":[[1.77,5.13]],"id":69176305}],"con":true,"img":false}]}
{"op":"mcm","clk":"11541121338","pt":1719502464839,"mc":[{"id":"1.230178321","rc":[{"atb":[[1.69,0]],"id":69176305}],"con":true,"img":false}]}
{"op":"mcm","clk":"11541121349","pt":1719502464943,"mc":[{"id":"1.230178321","rc":[{"atb":[[1.78,2]],"id":69176305}],"con":true,"img":false}]}
{"op":"mcm","clk":"11541122431","pt":1719502479927,"mc":[{"id":"1.230178321","rc":[{"spn":3.04,"spf":"NaN","id":69176305},{"spn":5.01,"spf":"NaN","id":43498435},{"spn":3.92,"spf":"NaN","id":62531723},{"atb":[[1.54,7.32]],"id":51643934},{"spn":2.34,"spf":"NaN","id":51643934}],"con":true,"img":false}]}
{"op":"mcm","clk":"11541122567","pt":1719502481637,"mc":[{"id":"1.230178321","rc":[{"atb":[[1.02,0]],"id":51643934}],"con":true,"img":false}]}
{"op":"mcm","clk":"11541122576","pt":1719502481739,"mc":[{"id":"1.230178321","rc":[{"atb":[[1.55,2]],"id":51643934}],"con":true,"img":false}]}
{"op":"mcm","clk":"11541123271","pt":1719502491073,"mc":[{"id":"1.230178321","rc":[{"atb":[[2.54,1],[2.62,0]],"id":43498435},{"atb":[[1.83,1],[1.78,0]],"id":61419789},{"atb":[[2.24,0],[2.12,1]],"id":62531723}],"con":true,"img":false}]}
{"op":"mcm","clk":"11541123280","pt":1719502491179,"mc":[{"id":"1.230178321","rc":[{"atb":[[1.83,2.48],[1.77,0]],"id":62531723}],"con":true,"img":false}]}
{"op":"mcm","clk":"11541123289","pt":1719502491279,"mc":[{"id":"1.230178321","rc":[{"atb":[[1.83,0],[1.77,2.48]],"id":62531723}],"con":true,"img":false}]}
{"op":"mcm","clk":"11541123383","pt":1719502492573,"mc":[{"id":"1.230178321","rc":[{"atl":[[4.8,1],[4.3,0]],"id":69176305},{"atl":[[5.6,0],[5.8,1]],"id":61941199},{"atl":[[3.45,1],[3.15,0]],"id":51643934}],"con":true,"img":false}]}
{"op":"mcm","clk":"11541123432","pt":1719502493280,"mc":[{"id":"1.230178321","rc":[{"atb":[[2.54,0],[2.62,1]],"id":43498435},{"atb":[[1.83,0],[1.78,1]],"id":61419789},{"atb":[[2.24,1],[2.12,0]],"id":62531723}],"con":true,"img":false}]}
{"op":"mcm","clk":"11541123443","pt":1719502493291,"mc":[{"id":"1.230178321","rc":[{"atb":[[2.14,3.48]],"id":43498435}],"con":true,"img":false}]}
{"op":"mcm","clk":"11541123450","pt":1719502493396,"mc":[{"id":"1.230178321","rc":[{"atb":[[2.24,0]],"id":43498435}],"con":true,"img":false}]}
{"op":"mcm","clk":"11541123554","pt":1719502494483,"mc":[{"id":"1.230178321","rc":[{"atb":[[2.54,1],[2.62,0]],"id":43498435},{"atb":[[1.83,1]],"id":61419789},{"atb":[[2.24,0],[2.12,1]],"id":62531723}],"con":true,"img":false}]}
{"op":"mcm","clk":"11541123562","pt":1719502494586,"mc":[{"id":"1.230178321","rc":[{"atb":[[2.24,2.48],[2.14,0]],"id":43498435},{"atb":[[1.78,0]],"id":61419789}],"con":true,"img":false}]}
{"op":"mcm","clk":"11541127702","pt":1719502552062,"mc":[{"id":"1.230178321","rc":[{"spn":4.97,"spf":"NaN","id":43498435},{"atb":[[1.77,0]],"id":69176305},{"spn":3.29,"spf":"NaN","id":69176305},{"spn":4.02,"spf":"NaN","id":61941199},{"spn":3.16,"spf":"NaN","id":61419789},{"spn":3.86,"spf":"NaN","id":62531723},{"spn":2.5,"spf":"NaN","id":51643934}],"con":true,"img":false}]}
{"op":"mcm","clk":"11541127811","pt":1719502553458,"mc":[{"id":"1.230178321","rc":[{"atb":[[1.78,0]],"id":69176305}],"con":true,"img":false}]}
{"op":"mcm","clk":"11541127817","pt":1719502553561,"mc":[{"id":"1.230178321","rc":[{"atb":[[1.65,4],[1.69,2]],"id":69176305}],"con":true,"img":false}]}
{"op":"mcm","clk":"11541127825","pt":1719502553664,"mc":[{"id":"1.230178321","rc":[{"atb":[[1.68,0]],"id":69176305}],"con":true,"img":false}]}
{"op":"mcm","clk":"11541127977","pt":1719502555636,"mc":[{"id":"1.230178321","rc":[{"atb":[[1.69,0]],"id":69176305}],"con":true,"img":false}]}
{"op":"mcm","clk":"11541127985","pt":1719502555734,"mc":[{"id":"1.230178321","rc":[{"atb":[[1.66,2]],"id":69176305}],"con":true,"img":false}]}
{"op":"mcm","clk":"11541129215","pt":1719502570974,"mc":[{"id":"1.230178321","rc":[{"atb":[[1.54,0]],"id":51643934}],"con":true,"img":false}]}
{"op":"mcm","clk":"11541129277","pt":1719502571749,"mc":[{"id":"1.230178321","rc":[{"atb":[[1.55,0]],"id":51643934}],"con":true,"img":false}]}
{"op":"mcm","clk":"11541129285","pt":1719502571850,"mc":[{"id":"1.230178321","rc":[{"atb":[[1.53,2]],"id":51643934}],"con":true,"img":false}]}
{"op":"mcm","clk":"11541129318","pt":1719502572264,"mc":[{"id":"1.230178321","rc":[{"atb":[[1.68,5.81]],"id":69176305}],"con":true,"img":false}]}
{"op":"mcm","clk":"11541129327","pt":1719502572366,"mc":[{"id":"1.230178321","rc":[{"atb":[[1.68,9.81],[1.65,0]],"id":69176305}],"con":true,"img":false}]}
{"op":"mcm","clk":"11541129433","pt":1719502573449,"mc":[{"id":"1.230178321","rc":[{"atb":[[1.66,0]],"id":69176305}],"con":true,"img":false}]}
{"op":"mcm","clk":"11541129441","pt":1719502573552,"mc":[{"id":"1.230178321","rc":[{"atb":[[1.69,2]],"id":69176305}],"con":true,"img":false}]}
{"op":"mcm","clk":"11541129827","pt":1719502577993,"mc":[{"id":"1.230178321","rc":[{"atb":[[1.83,0],[1.78,1]],"id":61419789}],"con":true,"img":false}]}
{"op":"mcm","clk":"11541130273","pt":1719502583675,"mc":[{"id":"1.230178321","rc":[{"atb":[[1.71,5.96]],"id":69176305}],"con":true,"img":false}]}
{"op":"mcm","clk":"11541130309","pt":1719502584294,"mc":[{"id":"1.230178321","rc":[{"atb":[[1.55,7.69]],"id":51643934}],"con":true,"img":false}]}
{"op":"mcm","clk":"11541130334","pt":1719502584654,"mc":[{"id":"1.230178321","rc":[{"atb":[[1.53,0]],"id":51643934}],"con":true,"img":false}]}
{"op":"mcm","clk":"11541130340","pt":1719502584760,"mc":[{"id":"1.230178321","rc":[{"atb":[[1.56,2]],"id":51643934}],"con":true,"img":false}]}
{"op":"mcm","clk":"11541130368","pt":1719502585066,"mc":[{"id":"1.230178321","rc":[{"atb":[[1.69,0]],"id":69176305}],"con":true,"img":false}]}
{"op":"mcm","clk":"11541130377","pt":1719502585175,"mc":[{"id":"1.230178321","rc":[{"atb":[[1.72,2]],"id":69176305}],"con":true,"img":false}]}
{"op":"mcm","clk":"11541130703","pt":1719502589407,"mc":[{"id":"1.230178321","rc":[{"atb":[[1.68,4]],"id":69176305}],"con":true,"img":false}]}
{"op":"mcm","clk":"11541130787","pt":1719502590391,"mc":[{"id":"1.230178321","rc":[{"atb":[[1.74,6.34]],"id":69176305}],"con":true,"img":false}]}
{"op":"mcm","clk":"11541130815","pt":1719502590802,"mc":[{"id":"1.230178321","rc":[{"atb":[[1.72,0]],"id":69176305}],"con":true,"img":false}]}
{"op":"mcm","clk":"11541130821","pt":1719502590907,"mc":[{"id":"1.230178321","rc":[{"atb":[[1.75,2]],"id":69176305}],"con":true,"img":false}]}
{"op":"mcm","clk":"11541132125","pt":1719502608199,"mc":[{"id":"1.230178321","rc":[{"atb":[[1.74,1]],"id":69176305}],"con":true,"img":false}]}
{"op":"mcm","clk":"11541132137","pt":1719502608403,"mc":[{"id":"1.230178321","rc":[{"atb":[[1.77,5.13]],"id":69176305}],"con":true,"img":false}]}
{"op":"mcm","clk":"11541132241","pt":1719502609788,"mc":[{"id":"1.230178321","rc":[{"atb":[[1.75,0]],"id":69176305}],"con":true,"img":false}]}
{"op":"mcm","clk":"11541132251","pt":1719502609894,"mc":[{"id":"1.230178321","rc":[{"atb":[[1.78,2]],"id":69176305}],"con":true,"img":false}]}
{"op":"mcm","clk":"11541133740","pt":1719502630135,"mc":[{"id":"1.230178321","rc":[{"atb":[[1.08,50]],"id":69176305},{"atb":[[1.08,50]],"id":43498435},{"atb":[[1.08,50]],"id":61941199},{"atb":[[1.08,50]],"id":61419789},{"spn":3.14,"spf":"NaN","id":61419789},{"atb":[[1.08,50]],"id":62531723},{"atb":[[1.08,50]],"id":51643934},{"spn":2.5,"spf":"NaN","id":51643934}],"con":true,"img":false}]}
{"op":"mcm","clk":"11541134855","pt":1719502645327,"mc":[{"id":"1.230178321","rc":[{"atb":[[2.62,1]],"id":43498435},{"atb":[[2.24,1],[2.12,0]],"id":62531723}],"con":true,"img":false}]}
{"op":"mcm","clk":"11541134864","pt":1719502645427,"mc":[{"id":"1.230178321","rc":[{"atb":[[2.54,0]],"id":43498435}],"con":true,"img":false}]}
{"op":"mcm","clk":"11541134917","pt":1719502646045,"mc":[{"id":"1.230178321","rc":[{"atl":[[4.8,0],[4.3,1]],"id":69176305},{"atl":[[5.6,1],[5.8,0]],"id":61941199},{"atl":[[3.45,0],[3.15,1]],"id":51643934}],"con":true,"img":false}]}
{"op":"mcm","clk":"11541135045","pt":1719502647742,"mc":[{"id":"1.230178321","rc":[{"atb":[[2.54,1]],"id":43498435},{"atb":[[2.12,1]],"id":62531723}],"con":true,"img":false}]}
{"op":"mcm","clk":"11541135052","pt":1719502647846,"mc":[{"id":"1.230178321","rc":[{"atb":[[2.62,0]],"id":43498435},{"atb":[[2.24,0]],"id":62531723}],"con":true,"img":false}]}
{"op":"mcm","clk":"11541135148","pt":1719502649033,"mc":[{"id":"1.230178321","rc":[{"atb":[[2.62,1]],"id":43498435},{"atb":[[2.24,1],[2.12,0]],"id":62531723}],"con":true,"img":false}]}
{"op":"mcm","clk":"11541135154","pt":1719502649132,"mc":[{"id":"1.230178321","rc":[{"atb":[[2.54,0]],"id":43498435}],"con":true,"img":false}]}
{"op":"mcm","clk":"11541135420","pt":1719502653050,"mc":[{"id":"1.230178321","rc":[{"atb":[[2.54,1],[2.62,0]],"id":43498435},{"atb":[[2.24,0],[2.12,1]],"id":62531723}],"con":true,"img":false}]}
{"op":"mcm","clk":"11541135523","pt":1719502654342,"mc":[{"id":"1.230178321","rc":[{"atb":[[2.54,0],[2.62,1]],"id":43498435},{"atb":[[2.24,1],[2.12,0]],"id":62531723}],"con":true,"img":false}]}
{"op":"mcm","clk":"11541135534","pt":1719502654445,"mc":[{"id":"1.230178321","rc":[{"atb":[[2.24,0],[2.14,3.48]],"id":43498435}],"con":true,"img":false}]}
{"op":"mcm","clk":"11541135806","pt":1719502658433,"mc":[{"id":"1.230178321","rc":[{"atb":[[2.54,1],[2.62,0]],"id":43498435},{"atb":[[2.24,0],[2.12,1]],"id":62531723}],"con":true,"img":false}]}
{"op":"mcm","clk":"11541135821","pt":1719502658639,"mc":[{"id":"1.230178321","rc":[{"atb":[[2.54,0],[2.62,1]],"id":43498435},{"atb":[[2.24,1],[2.12,0]],"id":62531723}],"con":true,"img":false}]}
{"op":"mcm","clk":"11541135902","pt":1719502659669,"mc":[{"id":"1.230178321","rc":[{"atb":[[2.54,1],[2.62,0]],"id":43498435},{"atb":[[2.24,0],[2.12,1]],"id":62531723}],"con":true,"img":false}]}
{"op":"mcm","clk":"11541135922","pt":1719502659825,"mc":[{"id":"1.230178321","rc":[{"atb":[[2.54,0],[2.62,1]],"id":43498435},{"atb":[[2.24,1],[2.12,0]],"id":62531723}],"con":true,"img":false}]}
{"op":"mcm","clk":"11541135971","pt":1719502660653,"mc":[{"id":"1.230178321","rc":[{"atb":[[2.54,1],[2.62,0]],"id":43498435},{"atb":[[2.24,0],[2.12,1]],"id":62531723}],"con":true,"img":false}]}
{"op":"mcm","clk":"11541136011","pt":1719502661370,"mc":[{"id":"1.230178321","rc":[{"atb":[[2.54,0],[2.62,1]],"id":43498435},{"atb":[[2.24,1],[2.12,0]],"id":62531723}],"con":true,"img":false}]}
{"op":"mcm","clk":"11541136183","pt":1719502664157,"mc":[{"id":"1.230178321","rc":[{"atb":[[2.54,1],[2.62,0]],"id":43498435},{"atb":[[2.24,0],[2.12,1]],"id":62531723}],"con":true,"img":false}]}
{"op":"mcm","clk":"11541136197","pt":1719502664465,"mc":[{"id":"1.230178321","rc":[{"atl":[[5.6,0],[5.8,1]],"id":61941199},{"atl":[[4.8,1],[4.3,0]],"id":69176305},{"atl":[[3.45,1]],"id":51643934}],"con":true,"img":false}]}
{"op":"mcm","clk":"11541136200","pt":1719502664568,"mc":[{"id":"1.230178321","rc":[{"atl":[[3.15,0]],"id":51643934}],"con":true,"img":false}]}
{"op":"mcm","clk":"11541136251","pt":1719502665342,"mc":[{"id":"1.230178321","rc":[{"atb":[[2.62,1]],"id":43498435},{"atb":[[2.24,1],[2.12,0]],"id":62531723}],"con":true,"img":false}]}
{"op":"mcm","clk":"11541136258","pt":1719502665444,"mc":[{"id":"1.230178321","rc":[{"atb":[[2.54,0]],"id":43498435}],"con":true,"img":false}]}
{"op":"mcm","clk":"11541136371","pt":1719502667250,"mc":[{"id":"1.230178321","rc":[{"atb":[[2.54,1]],"id":43498435},{"atb":[[2.24,0],[2.12,1]],"id":62531723}],"con":true,"img":false}]}
{"op":"mcm","clk":"11541136380","pt":1719502667350,"mc":[{"id":"1.230178321","rc":[{"atb":[[2.62,0]],"id":43498435}],"con":true,"img":false}]}
{"op":"mcm","clk":"11541137324","pt":1719502679096,"mc":[{"id":"1.230178321","rc":[{"atb":[[1.71,0]],"id":69176305},{"atb":[[1.55,0]],"id":51643934}],"con":true,"img":false}]}
{"op":"mcm","clk":"11541137378","pt":1719502679775,"mc":[{"id":"1.230178321","rc":[{"atb":[[1.58,6.81]],"id":51643934}],"con":true,"img":false}]}
{"op":"mcm","clk":"11541137385","pt":1719502679877,"mc":[{"id":"1.230178321","rc":[{"atb":[[1.77,0]],"id":69176305}],"con":true,"img":false}]}
{"op":"mcm","clk":"11541137398","pt":1719502680087,"mc":[{"id":"1.230178321","rc":[{"atb":[[1.8,4.94]],"id":69176305}],"con":true,"img":false}]}
{"op":"mcm","clk":"11541137517","pt":1719502681252,"mc":[{"id":"1.230178321","rc":[{"atb":[[1.56,0]],"id":51643934}],"con":true,"img":false}]}
{"op":"mcm","clk":"11541137527","pt":1719502681355,"mc":[{"id":"1.230178321","rc":[{"atb":[[1.59,2]],"id":51643934}],"con":true,"img":false}]}
{"op":"mcm","clk":"11541137553","pt":1719502681667,"mc":[{"id":"1.230178321","rc":[{"atb":[[1.78,0]],"id":69176305}],"con":true,"img":false}]}
{"op":"mcm","clk":"11541137562","pt":1719502681777,"mc":[{"id":"1.230178321","rc":[{"atb":[[1.81,2]],"id":69176305}],"con":true,"img":false}]}
{"op":"mcm","clk":"11541143311","pt":1719502683256,"mc":[{"id":"1.230178321","rc":[{"atb":[[1.6,7.05]],"id":51643934}],"con":true,"img":false}]}
{"op":"mcm","clk":"11541143416","pt":1719502684394,"mc":[{"id":"1.230178321","rc":[{"atb":[[1.59,0]],"id":51643934}],"con":true,"img":false}]}
{"op":"mcm","clk":"11541143423","pt":1719502684499,"mc":[{"id":"1.230178321","rc":[{"atb":[[1.61,2]],"id":51643934}],"con":true,"img":false}]}
{"op":"mcm","clk":"11541144580","pt":1719502699065,"mc":[{"id":"1.230178321","rc":[{"spn":3.3,"spf":"NaN","id":69176305},{"atb":[[1.58,0]],"id":51643934},{"spn":2.53,"spf":"NaN","id":51643934}],"con":true,"img":false}]}
{"op":"mcm","clk":"11541144605","pt":1719502699378,"mc":[{"id":"1.230178321","rc":[{"atb":[[1.81,4.81]],"id":69176305},{"atb":[[2.16,3.76]],"id":43498435},{"atb":[[1.87,3]],"id":61941199},{"atb":[[1.78,4.8]],"id":61419789},{"atb":[[1.81,4]],"id":62531723},{"atb":[[1.61,5.76]],"id":51643934}],"con":true,"img":false}]}
{"op":"mcm","clk":"11541144611","pt":1719502699480,"mc":[{"id":"1.230178321","rc":[{"atb":[[1.87,5.48]],"id":61941199},{"atb":[[1.7,0]],"id":61419789}],"con":true,"img":false}]}
{"op":"mcm","clk":"11541144619","pt":1719502699584,"mc":[{"id":"1.230178321","rc":[{"atb":[[1.72,0]],"id":61941199},{"atb":[[1.79,3.48]],"id":61419789},{"atb":[[1.82,2.48]],"id":62531723}],"con":true,"img":false}]}
{"op":"mcm","clk":"11541144626","pt":1719502699687,"mc":[{"id":"1.230178321","rc":[{"atb":[[1.77,0]],"id":62531723}],"con":true,"img":false}]}
{"op":"mcm","clk":"11541144660","pt":1719502700099,"mc":[{"id":"1.230178321","rc":[{"atb":[[1.8,0]],"id":69176305}],"con":true,"img":false}]}
{"op":"mcm","clk":"11541144687","pt":1719502700409,"mc":[{"id":"1.230178321","rc":[{"atb":[[1.83,4.75]],"id":69176305}],"con":true,"img":false}]}
{"op":"mcm","clk":"11541144705","pt":1719502700719,"mc":[{"id":"1.230178321","rc":[{"atb":[[1.02,0]],"id":61941199}],"con":true,"img":false}]}
{"op":"mcm","clk":"11541144719","pt":1719502700773,"mc":[{"id":"1.230178321","rc":[{"atb":[[1.88,2]],"id":61941199}],"con":true,"img":false}]}
{"op":"mcm","clk":"11541144755","pt":1719502701186,"mc":[{"id":"1.230178321","rc":[{"atb":[[1.81,2.81]],"id":69176305}],"con":true,"img":false}]}
{"op":"mcm","clk":"11541144768","pt":1719502701290,"mc":[{"id":"1.230178321","rc":[{"atb":[[1.84,2]],"id":69176305}],"con":true,"img":false}]}
{"op":"mcm","clk":"11541144846","pt":1719502702177,"mc":[{"id":"1.230178321","rc":[{"atb":[[1.88,0]],"id":61941199}],"con":true,"img":false}]}
{"op":"mcm","clk":"11541144855","pt":1719502702279,"mc":[{"id":"1.230178321","rc":[{"atb":[[1.02,2]],"id":61941199}],"con":true,"img":false}]}
{"op":"mcm","clk":"11541144927","pt":1719502703214,"mc":[{"id":"1.230178321","rc":[{"atb":[[1.02,0]],"id":61941199}],"con":true,"img":false}]}
{"op":"mcm","clk":"11541144933","pt":1719502703317,"mc":[{"id":"1.230178321","rc":[{"atb":[[1.88,2]],"id":61941199}],"con":true,"img":false}]}
{"op":"mcm","clk":"11541145025","pt":1719502704508,"mc":[{"id":"1.230178321","rc":[{"atb":[[1.88,0]],"id":61941199}],"con":true,"img":false}]}
{"op":"mcm","clk":"11541145034","pt":1719502704613,"mc":[{"id":"1.230178321","rc":[{"atb":[[1.02,2]],"id":61941199}],"con":true,"img":false}]}
{"op":"mcm","clk":"11541145128","pt":1719502705799,"mc":[{"id":"1.230178321","rc":[{"atb":[[1.02,0]],"id":61941199}],"con":true,"img":false}]}
{"op":"mcm","clk":"11541145139","pt":1719502705901,"mc":[{"id":"1.230178321","rc":[{"atb":[[1.88,2]],"id":61941199}],"con":true,"img":false}]}
{"op":"mcm","clk":"11541145197","pt":1719502706678,"mc":[{"id":"1.230178321","rc":[{"atb":[[1.88,0]],"id":61941199}],"con":true,"img":false}]}
{"op":"mcm","clk":"11541145210","pt":1719502706783,"mc":[{"id":"1.230178321","rc":[{"atb":[[1.02,2]],"id":61941199}],"con":true,"img":false}]}
{"op":"mcm","clk":"11541145345","pt":1719502708489,"mc":[{"id":"1.230178321","rc":[{"atb":[[1.02,0]],"id":61941199}],"con":true,"img":false}]}
{"op":"mcm","clk":"11541145354","pt":1719502708590,"mc":[{"id":"1.230178321","rc":[{"atb":[[1.88,2]],"id":61941199}],"con":true,"img":false}]}
{"op":"mcm","clk":"11541145443","pt":1719502709681,"mc":[{"id":"1.230178321","rc":[{"atb":[[1.88,0]],"id":61941199}],"con":true,"img":false}]}
{"op":"mcm","clk":"11541145449","pt":1719502709784,"mc":[{"id":"1.230178321","rc":[{"atb":[[1.02,2]],"id":61941199}],"con":true,"img":false}]}
{"op":"mcm","clk":"11541145556","pt":1719502711082,"mc":[{"id":"1.230178321","rc":[{"atb":[[1.02,0]],"id":61941199}],"con":true,"img":false}]}
{"op":"mcm","clk":"11541145561","pt":1719502711187,"mc":[{"id":"1.230178321","rc":[{"atb":[[1.88,2]],"id":61941199}],"con":true,"img":false}]}
{"op":"mcm","clk":"11541145651","pt":1719502712279,"mc":[{"id":"1.230178321","rc":[{"atb":[[1.88,0]],"id":61941199}],"con":true,"img":false}]}
{"op":"mcm","clk":"11541145666","pt":1719502712434,"mc":[{"id":"1.230178321","rc":[{"atb":[[1.02,2]],"id":61941199}],"con":true,"img":false}]}
{"op":"mcm","clk":"11541145700","pt":1719502712701,"mc":[{"id":"1.230178321","rc":[{"atb":[[2.54,0],[2.62,1]],"id":43498435},{"atb":[[2.24,1],[2.12,0]],"id":62531723}],"con":true,"img":false}]}
{"op":"mcm","clk":"11541145737","pt":1719502713112,"mc":[{"id":"1.230178321","rc":[{"atb":[[2.54,1],[2.62,0]],"id":43498435},{"atb":[[2.24,0],[2.12,1]],"id":62531723}],"con":true,"img":false}]}
{"op":"mcm","clk":"11541145748","pt":1719502713217,"mc":[{"id":"1.230178321","rc":[{"atb":[[2.18,3.48],[2.14,0]],"id":43498435}],"con":true,"img":false}]}
{"op":"mcm","clk":"11541145767","pt":1719502713423,"mc":[{"id":"1.230178321","rc":[{"atb":[[1.87,2.48]],"id":61941199},{"atb":[[1.81,0]],"id":69176305},{"atb":[[1.78,1]],"id":61419789},{"atb":[[1.81,0]],"id":62531723}],"con":true,"img":false}]}
{"op":"mcm","clk":"11541145774","pt":1719502713527,"mc":[{"id":"1.230178321","rc":[{"atb":[[1.84,4.8]],"id":69176305},{"atb":[[1.02,0],[1.88,3.69],[1.87,0],[1.71,3.48]],"id":61941199},{"atb":[[1.79,3],[1.7,4.48]],"id":61419789},{"atb":[[1.86,3.3]],"id":62531723}],"con":true,"img":false}]}
{"op":"mcm","clk":"11541145781","pt":1719502713581,"mc":[{"id":"1.230178321","rc":[{"atb":[[1.88,5.69]],"id":61941199},{"atb":[[1.82,0],[1.87,2.48]],"id":62531723}],"con":true,"img":false}]}
{"op":"mcm","clk":"11541145791","pt":1719502713684,"mc":[{"id":"1.230178321","rc":[{"atb":[[1.89,3.48],[1.71,0]],"id":61941199}],"con":true,"img":false}]}
{"op":"mcm","clk":"11541145913","pt":1719502714985,"mc":[{"id":"1.230178321","rc":[{"atb":[[1.88,3.69]],"id":61941199}],"con":true,"img":false}]}
{"op":"mcm","clk":"11541145927","pt":1719502715089,"mc":[{"id":"1.230178321","rc":[{"atb":[[1.02,2]],"id":61941199},{"atb":[[1.6,0]],"id":51643934}],"con":true,"img":false}]}
{"op":"mcm","clk":"11541146032","pt":1719502716233,"mc":[{"id":"1.230178321","rc":[{"atb":[[1.89,4.44]],"id":62531723}],"con":true,"img":false}]}
{"op":"mcm","clk":"11541146061","pt":1719502716535,"mc":[{"id":"1.230178321","rc":[{"atb":[[1.63,6.27]],"id":51643934}],"con":true,"img":false}]}
{"op":"mcm","clk":"11541146078","pt":1719502716692,"mc":[{"id":"1.230178321","rc":[{"atb":[[1.83,0]],"id":69176305},{"atb":[[1.89,9.2]],"id":62531723}],"con":true,"img":false}]}
{"op":"mcm","clk":"11541146099","pt":1719502716900,"mc":[{"id":"1.230178321","rc":[{"atb":[[1.86,4.59]],"id":69176305}],"con":true,"img":false}]}
{"op":"mcm","clk":"11541146106","pt":1719502717003,"mc":[{"id":"1.230178321","rc":[{"atb":[[1.86,9.51]],"id":69176305}],"con":true,"img":false}]}
{"op":"mcm","clk":"11541146113","pt":1719502717107,"mc":[{"id":"1.230178321","rc":[{"atb":[[1.61,3.76]],"id":51643934}],"con":true,"img":false}]}
{"op":"mcm","clk":"11541146121","pt":1719502717212,"mc":[{"id":"1.230178321","rc":[{"atb":[[1.92,2.11]],"id":62531723},{"atb":[[1.64,2]],"id":51643934}],"con":true,"img":false}]}
{"op":"mcm","clk":"11541146128","pt":1719502717314,"mc":[{"id":"1.230178321","rc":[{"atb":[[2.54,0],[2.62,1]],"id":43498435},{"atb":[[2.24,1],[2.12,0]],"id":62531723}],"con":true,"img":false}]}
{"op":"mcm","clk":"11541146136","pt":1719502717417,"mc":[{"id":"1.230178321","rc":[{"atb":[[1.92,4.59],[1.87,0]],"id":62531723}],"con":true,"img":false}]}
{"op":"mcm","clk":"11541146143","pt":1719502717518,"mc":[{"id":"1.230178321","rc":[{"atb":[[1.02,11.23]],"id":62531723}],"con":true,"img":false}]}
{"op":"mcm","clk":"11541146153","pt":1719502717621,"mc":[{"id":"1.230178321","rc":[{"atb":[[1.9,2]],"id":62531723}],"con":true,"img":false}]}
{"op":"mcm","clk":"11541146236","pt":1719502718818,"mc":[{"id":"1.230178321","rc":[{"atb":[[2.54,1],[2.62,0]],"id":43498435},{"atb":[[2.24,0],[1.9,0],[2.12,1]],"id":62531723}],"con":true,"img":false}]}
{"op":"mcm","clk":"11541146244","pt":1719502718920,"mc":[{"id":"1.230178321","rc":[{"atb":[[1.93,2]],"id":62531723}],"con":true,"img":false}]}
{"op":"mcm","clk":"11541146268","pt":1719502719230,"mc":[{"id":"1.230178321","rc":[{"atb":[[1.84,2.8]],"id":69176305}],"con":true,"img":false}]}
{"op":"mcm","clk":"11541146277","pt":1719502719336,"mc":[{"id":"1.230178321","rc":[{"atb":[[1.87,2]],"id":69176305}],"con":true,"img":false}]}
{"op":"mcm","clk":"11541146931","pt":1719502727415,"mc":[{"id":"1.230178321","rc":[{"atb":[[1.84,0]],"id":69176305},{"atb":[[2.16,0]],"id":43498435},{"atb":[[1.88,0]],"id":61941199},{"atb":[[1.86,0]],"id":62531723},{"atb":[[1.61,0]],"id":51643934}],"con":true,"img":false}]}
{"op":"mcm","clk":"11541146941","pt":1719502727521,"mc":[{"id":"1.230178321","rc":[{"atb":[[1.89,0],[1.71,4.48]],"id":61941199}],"con":true,"img":false}]}
{"op":"mcm","clk":"11541146948","pt":1719502727625,"mc":[{"id":"1.230178321","rc":[{"atb":[[1.9,3.94]],"id":61941199},{"atb":[[1.87,4.8]],"id":69176305},{"atb":[[2.2,2.2]],"id":43498435},{"atb":[[2.12,3.6]],"id":62531723},{"atb":[[1.64,5]],"id":51643934}],"con":true,"img":false}]}
{"op":"mcm","clk":"11541146963","pt":1719502727746,"mc":[{"id":"1.230178321","rc":[{"atb":[[1.91,3.94],[1.71,0]],"id":61941199},{"atb":[[1.92,2.11],[2.12,7.2]],"id":62531723}],"con":true,"img":false}]}
{"op":"mcm","clk":"11541147053","pt":1719502728917,"mc":[{"id":"1.230178321","rc":[{"atb":[[1.93,0]],"id":62531723}],"con":true,"img":false}]}
{"op":"mcm","clk":"11541147060","pt":1719502729021,"mc":[{"id":"1.230178321","rc":[{"atb":[[2.14,2]],"id":62531723}],"con":true,"img":false}]}
{"op":"mcm","clk":"11541147618","pt":1719502735640,"mc":[{"id":"1.230178321","rc":[{"atb":[[1.63,0]],"id":51643934}],"con":true,"img":false}]}
{"op":"mcm","clk":"11541147662","pt":1719502736108,"mc":[{"id":"1.230178321","rc":[{"atb":[[1.86,4.91]],"id":69176305}],"con":true,"img":false}]}
{"op":"mcm","clk":"11541147685","pt":1719502736308,"mc":[{"id":"1.230178321","rc":[{"atb":[[1.66,5.99]],"id":51643934}],"con":true,"img":false}]}
{"op":"mcm","clk":"11541147723","pt":1719502736724,"mc":[{"id":"1.230178321","rc":[{"atb":[[1.89,4.44]],"id":69176305}],"con":true,"img":false}]}
{"op":"mcm","clk":"11541147802","pt":1719502737729,"mc":[{"id":"1.230178321","rc":[{"atb":[[1.64,3]],"id":51643934}],"con":true,"img":false}]}
{"op":"mcm","clk":"11541147809","pt":1719502737837,"mc":[{"id":"1.230178321","rc":[{"atb":[[1.67,2]],"id":51643934}],"con":true,"img":false}]}
{"op":"mcm","clk":"11541147828","pt":1719502738143,"mc":[{"id":"1.230178321","rc":[{"atb":[[1.87,2.8]],"id":69176305}],"con":true,"img":false}]}
{"op":"mcm","clk":"11541147837","pt":1719502738245,"mc":[{"id":"1.230178321","rc":[{"atb":[[1.9,2]],"id":69176305}],"con":true,"img":false}]}
{"op":"mcm","clk":"11541148106","pt":1719502741513,"mc":[{"id":"1.230178321","rc":[{"atb":[[1.87,0]],"id":69176305},{"atb":[[1.9,0]],"id":61941199},{"atb":[[2.12,4.6]],"id":62531723},{"atb":[[1.64,0]],"id":51643934}],"con":true,"img":false}]}
{"op":"mcm","clk":"11541148122","pt":1719502741723,"mc":[{"id":"1.230178321","rc":[{"atb":[[1.92,4]],"id":61941199},{"atb":[[1.9,4.9]],"id":69176305},{"atb":[[2.14,4]],"id":62531723},{"atb":[[1.67,6]],"id":51643934}],"con":true,"img":false}]}
{"op":"mcm","clk":"11541148131","pt":1719502741828,"mc":[{"id":"1.230178321","rc":[{"atb":[[1.91,0],[1.71,4.94]],"id":61941199}],"con":true,"img":false}]}
{"op":"mcm","clk":"11541148142","pt":1719502741936,"mc":[{"id":"1.230178321","rc":[{"atb":[[2.12,1],[2.16,4]],"id":62531723}],"con":true,"img":false}]}
{"op":"mcm","clk":"11541148204","pt":1719502742554,"mc":[{"id":"1.230178321","rc":[{"atb":[[2.14,2]],"id":62531723}],"con":true,"img":false}]}
{"op":"mcm","clk":"11541148219","pt":1719502742610,"mc":[{"id":"1.230178321","rc":[{"atb":[[2.18,2],[2.14,10]],"id":62531723}],"con":true,"img":false}]}
{"op":"mcm","clk":"11541148229","pt":1719502742716,"mc":[{"id":"1.230178321","rc":[{"atb":[[2.16,0]],"id":62531723}],"con":true,"img":false}]}
{"op":"mcm","clk":"11541148459","pt":1719502745055,"mc":[{"id":"1.230178321","rc":[{"atb":[[2.18,0]],"id":62531723}],"con":true,"img":false}]}
{"op":"mcm","clk":"11541148471","pt":1719502745108,"mc":[{"id":"1.230178321","rc":[{"atb":[[2.16,2]],"id":62531723}],"con":true,"img":false}]}
{"op":"mcm","clk":"11541148659","pt":1719502747361,"mc":[{"id":"1.230178321","rc":[{"atb":[[2.54,0],[2.62,1]],"id":43498435},{"atb":[[2.24,1],[2.12,0]],"id":62531723}],"con":true,"img":false}]}
{"op":"mcm","clk":"11541148671","pt":1719502747415,"mc":[{"id":"1.230178321","rc":[{"atl":[[4.8,0],[4.6,1]],"id":69176305},{"atl":[[5.8,1]],"id":62531723},{"atl":[[3.45,0],[3.25,1]],"id":51643934}],"con":true,"img":false}]}
{"op":"mcm","clk":"11541148682","pt":1719502747521,"mc":[{"id":"1.230178321","rc":[{"atl":[[5.6,0]],"id":62531723}],"con":true,"img":false}]}
{"op":"mcm","clk":"11541148706","pt":1719502747729,"mc":[{"id":"1.230178321","rc":[{"atl":[[4.8,1],[4.6,0]],"id":69176305},{"atb":[[1.93,4],[1.71,0]],"id":61941199},{"atb":[[2.24,0],[2.12,1]],"id":62531723},{"atl":[[5.6,1],[5.8,0]],"id":62531723},{"atl":[[3.45,1],[3.25,0]],"id":51643934}],"con":true,"img":false}]}
{"op":"mcm","clk":"11541148716","pt":1719502747833,"mc":[{"id":"1.230178321","rc":[{"atl":[[24,2],[25,0]],"id":62531723}],"con":true,"img":false}]}
{"op":"mcm","clk":"11541148722","pt":1719502747937,"mc":[{"id":"1.230178321","rc":[{"atb":[[2.24,1],[2.12,0]],"id":62531723}],"con":true,"img":false}]}
{"op":"mcm","clk":"11541148740","pt":1719502748144,"mc":[{"id":"1.230178321","rc":[{"atb":[[2.54,1],[2.62,0]],"id":43498435},{"atb":[[2.12,1]],"id":62531723},{"atl":[[5.8,1]],"id":62531723}],"con":true,"img":false}]}
{"op":"mcm","clk":"11541148750","pt":1719502748248,"mc":[{"id":"1.230178321","rc":[{"atb":[[2.22,2.2],[2.18,0]],"id":43498435},{"atb":[[2.24,0]],"id":62531723},{"atl":[[5.6,0]],"id":62531723}],"con":true,"img":false}]}
{"op":"mcm","clk":"11541148967","pt":1719502750338,"mc":[{"id":"1.230178321","rc":[{"atb":[[1.95,4.45]],"id":61941199}],"con":true,"img":false}]}
{"op":"mcm","clk":"11541148994","pt":1719502750545,"mc":[{"id":"1.230178321","rc":[{"atl":[[5.6,1],[5.8,0]],"id":62531723}],"con":true,"img":false}]}
{"op":"mcm","clk":"11541149042","pt":1719502750958,"mc":[{"id":"1.230178321","rc":[{"atb":[[1.69,6.13]],"id":51643934}],"con":true,"img":false}]}
{"op":"mcm","clk":"11541149084","pt":1719502751323,"mc":[{"id":"1.230178321","rc":[{"atb":[[1.02,0]],"id":61941199}],"con":true,"img":false}]}
{"op":"mcm","clk":"11541149095","pt":1719502751428,"mc":[{"id":"1.230178321","rc":[{"atb":[[1.96,2]],"id":61941199}],"con":true,"img":false}]}
{"op":"mcm","clk":"11541149120","pt":1719502751635,"mc":[{"id":"1.230178321","rc":[{"atb":[[1.86,0]],"id":69176305}],"con":true,"img":false}]}
{"op":"mcm","clk":"11541149144","pt":1719502751842,"mc":[{"id":"1.230178321","rc":[{"atb":[[1.82,5],[1.9,7.15],[1.78,10],[1.86,2.5]],"id":69176305},{"atl":[[6.2,5],[5.7,2.5],[7,10],[4.7,2.25]],"id":69176305},{"atb":[[2.24,3.25],[2.54,2.5],[2.38,10],[2.46,5]],"id":61941199},{"atl":[[6,2.5],[6.8,5],[7.6,10],[5.7,2.25]],"id":61941199},{"atb":[[2.56,2.25],[2.36,10],[2.52,2.5],[2.44,5]],"id":43498435},{"atl":[[7.2,3.25],[9,2.5],[7.4,0],[11.5,10],[9.8,5]],"id":43498435},{"atb":[[1.79,5.25],[2.3,2.5],[2.22,5],[1.74,4.48],[1.7,0],[2.14,10]],"id":61419789},{"atl":[[5.6,2.5],[4.5,2.25],[4.6,1],[6,5],[6.8,10]],"id":61419789},{"atb":[[2.5,5],[2.58,2.5],[2.42,10],[2.18,2.25]],"id":62531723},{"atl":[[8.6,10],[5.5,2.25],[7,2.5],[7.8,5]],"id":62531723},{"atb":[[1.69,12.12]],"id":51643934},{"atl":[[4,2.5],[4.8,10],[3.4,5.99],[4.4,5]],"id":51643934}],"con":true,"img":false}]}
{"op":"mcm","clk":"11541149155","pt":1719502751945,"mc":[{"id":"1.230178321","rc":[{"atl":[[8.6,0],[4.7,4.5]],"id":69176305},{"atb":[[2.3,10],[1.93,0]],"id":61941199},{"atl":[[18.5,0],[5.7,4.5]],"id":61941199},{"atb":[[2.56,4.5],[2.22,0]],"id":43498435},{"atl":[[70,0],[11,6.5]],"id":43498435},{"atl":[[5.6,7.5]],"id":61419789},{"atb":[[2.14,2],[2.56,5]],"id":62531723},{"atl":[[7.2,5],[24,0]],"id":62531723},{"atl":[[3.35,2.5],[6.8,0]],"id":51643934}],"con":true,"img":false}]}
{"op":"mcm","clk":"11541149163","pt":1719502752051,"mc":[{"id":"1.230178321","rc":[{"atl":[[18,0]],"id":61419789}],"con":true,"img":false}]}
{"op":"mcm","clk":"11541149172","pt":1719502752154,"mc":[{"id":"1.230178321","rc":[{"atl":[[3.45,15.87]],"id":51643934}],"con":true,"img":false}]}
{"op":"mcm","clk":"11541149187","pt":1719502752360,"mc":[{"id":"1.230178321","rc":[{"atl":[[7,0.84]],"id":43498435},{"atl":[[5.6,0.84]],"id":61941199},{"atl":[[4.6,0.84]],"id":69176305},{"atl":[[4.4,0.84]],"id":61419789},{"atl":[[5.4,0.84]],"id":62531723},{"atl":[[3.3,0.84]],"id":51643934}],"con":true,"img":false}]}
{"op":"mcm","clk":"11541149220","pt":1719502752727,"mc":[{"id":"1.230178321","rc":[{"atb":[[1.92,4.59]],"id":69176305}],"con":true,"img":false}]}
{"op":"mcm","clk":"11541149241","pt":1719502753040,"mc":[{"id":"1.230178321","rc":[{"atb":[[1.67,4]],"id":51643934}],"con":true,"img":false}]}
{"op":"mcm","clk":"11541149253","pt":1719502753146,"mc":[{"id":"1.230178321","rc":[{"atb":[[1.7,2]],"id":51643934}],"con":true,"img":false}]}
{"op":"mcm","clk":"11541149292","pt":1719502753561,"mc":[{"id":"1.230178321","rc":[{"atb":[[2.16,0]],"id":62531723}],"con":true,"img":false}]}
{"op":"mcm","clk":"11541149301","pt":1719502753615,"mc":[{"id":"1.230178321","rc":[{"atb":[[1.02,13.23]],"id":62531723}],"con":true,"img":false}]}
{"op":"mcm","clk":"11541149328","pt":1719502753943,"mc":[{"id":"1.230178321","rc":[{"atb":[[2.5,2.11]],"id":43498435},{"atb":[[2.44,2.11]],"id":61941199},{"atb":[[2.2,2.11]],"id":61419789}],"con":true,"img":false}]}
{"op":"mcm","clk":"11541149358","pt":1719502754239,"mc":[{"id":"1.230178321","rc":[{"atb":[[1.96,0]],"id":61941199}],"con":true,"img":false}]}
{"op":"mcm","clk":"11541149376","pt":1719502754343,"mc":[{"id":"1.230178321","rc":[{"atb":[[2.56,2]],"id":61941199}],"con":true,"img":false}]}
{"op":"mcm","clk":"11541149398","pt":1719502754652,"mc":[{"id":"1.230178321","rc":[{"atb":[[1.02,11.23]],"id":61419789}],"con":true,"img":false}]}
{"op":"mcm","clk":"11541149408","pt":1719502754754,"mc":[{"id":"1.230178321","rc":[{"atb":[[2.54,0],[2.62,1]],"id":43498435},{"atb":[[2.32,2]],"id":61419789},{"atb":[[2.12,0],[2.24,1]],"id":62531723}],"con":true,"img":false}]}
{"op":"mcm","clk":"11541149438","pt":1719502755018,"mc":[{"id":"1.230178321","rc":[{"atb":[[1.02,0]],"id":43498435},{"atb":[[1.83,6.66],[1.89,0]],"id":69176305}],"con":true,"img":false}]}
{"op":"mcm","clk":"11541149447","pt":1719502755122,"mc":[{"id":"1.230178321","rc":[{"atb":[[2.58,2]],"id":43498435}],"con":true,"img":false}]}
{"op":"mcm","clk":"11541149501","pt":1719502755740,"mc":[{"id":"1.230178321","rc":[{"atb":[[2.2,0]],"id":43498435},{"atb":[[1.9,4.25]],"id":69176305},{"atb":[[1.92,0]],"id":61941199},{"atb":[[1.79,2.25]],"id":61419789},{"atb":[[2.14,0]],"id":62531723},{"atb":[[1.67,0]],"id":51643934}],"con":true,"img":false}]}
{"op":"mcm","clk":"11541149521","pt":1719502755949,"mc":[{"id":"1.230178321","rc":[{"atb":[[1.93,3]],"id":69176305},{"atb":[[2.56,4]],"id":61941199},{"atb":[[2.32,4.97]],"id":61419789},{"atb":[[2.6,2.91]],"id":62531723},{"atb":[[1.7,5.4]],"id":51643934}],"con":true,"img":false}]}
{"op":"mcm","clk":"11541149546","pt":1719502756254,"mc":[{"id":"1.230178321","rc":[{"atb":[[1.9,2.25]],"id":69176305}],"con":true,"img":false}]}
{"op":"mcm","clk":"11541149557","pt":1719502756358,"mc":[{"id":"1.230178321","rc":[{"atb":[[1.94,4.2],[1.93,5]],"id":69176305}],"con":true,"img":false}]}
{"op":"mcm","clk":"11541149580","pt":1719502756618,"mc":[{"id":"1.230178321","rc":[{"atl":[[4.6,1.84]],"id":69176305},{"atl":[[3.45,14.87],[3.25,1]],"id":51643934}],"con":true,"img":false}]}
{"op":"mcm","clk":"11541149588","pt":1719502756721,"mc":[{"id":"1.230178321","rc":[{"atl":[[4.8,0]],"id":69176305}],"con":true,"img":false}]}
{"op":"mcm","clk":"11541149622","pt":1719502757040,"mc":[{"id":"1.230178321","rc":[{"atl":[[5.7,8.85],[4.7,2.25]],"id":69176305},{"atl":[[5.8,6.35]],"id":61941199}],"con":true,"img":false}]}
{"op":"mcm","clk":"11541149634","pt":1719502757137,"mc":[{"id":"1.230178321","rc":[{"atl":[[5.7,2.25]],"id":61941199}],"con":true,"img":false}]}
{"op":"mcm","clk":"11541149646","pt":1719502757244,"mc":[{"id":"1.230178321","rc":[{"atb":[[2.54,1]],"id":43498435},{"atl":[[7.4,1]],"id":43498435},{"atb":[[2.24,0]],"id":62531723},{"atl":[[5.6,0],[5.8,1]],"id":62531723}],"con":true,"img":false}]}
{"op":"mcm","clk":"11541149659","pt":1719502757350,"mc":[{"id":"1.230178321","rc":[{"atb":[[2.62,0]],"id":43498435},{"atl":[[7.2,2.25]],"id":43498435}],"con":true,"img":false}]}
{"op":"mcm","clk":"11541149694","pt":1719502757657,"mc":[{"id":"1.230178321","rc":[{"atb":[[1.93,3]],"id":69176305},{"atb":[[2.32,9.94],[1.74,0]],"id":61419789}],"con":true,"img":false}]}
{"op":"mcm","clk":"11541149708","pt":1719502757763,"mc":[{"id":"1.230178321","rc":[{"atb":[[1.95,2]],"id":69176305},{"atl":[[9.2,6.5],[11,0]],"id":43498435},{"atl":[[5.6,2.5],[5,7.5]],"id":61419789},{"atl":[[7.2,0],[6.2,5]],"id":62531723}],"con":true,"img":false}]}
{"op":"mcm","clk":"11541149734","pt":1719502757925,"mc":[{"id":"1.230178321","rc":[{"atb":[[2.52,2.11]],"id":61941199},{"atb":[[2.28,2.11]],"id":61419789},{"atb":[[2.62,2.11]],"id":62531723}],"con":true,"img":false}]}
{"op":"mcm","clk":"11541149745","pt":1719502758027,"mc":[{"id":"1.230178321","rc":[{"atb":[[2.44,0]],"id":61941199},{"atb":[[2.2,0]],"id":61419789},{"atb":[[1.92,0]],"id":62531723}],"con":true,"img":false}]}
{"op":"mcm","clk":"11541149782","pt":1719502758356,"mc":[{"id":"1.230178321","rc":[{"atl":[[7.2,3.25],[7.4,0]],"id":43498435},{"atl":[[4.8,1],[4.6,0.84]],"id":69176305},{"atl":[[5.6,1],[5.8,0]],"id":62531723},{"atl":[[3.45,15.87],[3.25,0]],"id":51643934}],"con":true,"img":false}]}
{"op":"mcm","clk":"11541149789","pt":1719502758461,"mc":[{"id":"1.230178321","rc":[{"atl":[[5.7,2.5],[4.7,4.5]],"id":69176305}],"con":true,"img":false}]}
{"op":"mcm","clk":"11541149804","pt":1719502758668,"mc":[{"id":"1.230178321","rc":[{"atl":[[4.8,6.35],[4.7,2.25]],"id":69176305}],"con":true,"img":false}]}
{"op":"mcm","clk":"11541149813","pt":1719502758725,"mc":[{"id":"1.230178321","rc":[{"atl":[[7.2,2.25],[7.4,1]],"id":43498435},{"atl":[[5.8,5.35],[5.9,1]],"id":61941199},{"atl":[[5.6,0],[5.7,1]],"id":62531723}],"con":true,"img":false}]}
{"op":"mcm","clk":"11541149823","pt":1719502758828,"mc":[{"id":"1.230178321","rc":[{"atb":[[2.54,0],[2.7,1]],"id":43498435},{"atl":[[7.6,1]],"id":43498435},{"atl":[[4.8,5.35],[4.6,1.84]],"id":69176305},{"atb":[[2.32,4.97],[2.3,22.38]],"id":61419789},{"atb":[[2.54,5.41],[2.56,0]],"id":62531723},{"atl":[[6.2,6]],"id":62531723},{"atb":[[1.52,4.61]],"id":51643934},{"atl":[[3.45,14.87],[3.25,1]],"id":51643934}],"con":true,"img":false}]}
{"op":"mcm","clk":"11541149833","pt":1719502758931,"mc":[{"id":"1.230178321","rc":[{"atl":[[10,4.75],[7.4,0]],"id":43498435},{"atl":[[5.8,6.35]],"id":61941199},{"atb":[[2.32,7.47],[2.3,2.5]],"id":61419789},{"atb":[[2.54,0],[2.56,5]],"id":62531723}],"con":true,"img":false}]}
{"op":"mcm","clk":"11541149843","pt":1719502759039,"mc":[{"id":"1.230178321","rc":[{"atl":[[9.2,0]],"id":43498435},{"atl":[[5.9,0]],"id":61941199},{"atb":[[2.32,4.97],[2.3,12.44]],"id":61419789},{"atl":[[6.2,5],[5.7,0]],"id":62531723}],"con":true,"img":false}]}
{"op":"mcm","clk":"11541149873","pt":1719502759347,"mc":[{"id":"1.230178321","rc":[{"spn":4.85,"spf":"NaN","id":43498435},{"spn":4.08,"spf":"NaN","id":61941199},{"spn":3.27,"spf":"NaN","id":69176305},{"spn":3.36,"spf":"NaN","id":61419789},{"atl":[[6.2,6]],"id":62531723},{"spn":4.01,"spf":"NaN","id":62531723},{"spn":2.47,"spf":"NaN","id":51643934}],"con":true,"img":false}]}
{"op":"mcm","clk":"11541150347","pt":1719502764069,"mc":[{"id":"1.230178321","rc":[{"atb":[[2.54,5.41],[2.56,0]],"id":62531723}],"con":true,"img":false}]}
{"op":"mcm","clk":"11541150378","pt":1719502764328,"mc":[{"id":"1.230178321","rc":[{"atb":[[2.72,2.25]],"id":43498435},{"atb":[[2.56,7.56]],"id":61941199},{"atl":[[5.6,4.4]],"id":61941199},{"atb":[[1.95,5.94]],"id":69176305},{"atl":[[4.5,3.94]],"id":69176305},{"atb":[[2.32,8.25]],"id":61419789},{"atb":[[2.66,3.56]],"id":62531723},{"atl":[[5.4,4.4]],"id":62531723},{"atb":[[1.7,11.33]],"id":51643934},{"atl":[[3.2,5.93]],"id":51643934}],"con":true,"img":false}]}
{"op":"mcm","clk":"11541150390","pt":1719502764434,"mc":[{"id":"1.230178321","rc":[{"atb":[[2.6,2.5]],"id":43498435},{"atl":[[3.4,0]],"id":51643934}],"con":true,"img":false}]}
{"op":"mcm","clk":"11541150400","pt":1719502764537,"mc":[{"id":"1.230178321","rc":[{"atb":[[2.56,0]],"id":43498435},{"atb":[[1.9,0]],"id":69176305},{"atl":[[4.7,0]],"id":69176305},{"atb":[[2.24,1]],"id":61941199},{"atl":[[5.7,0]],"id":61941199},{"atb":[[1.79,0]],"id":61419789},{"atb":[[2.18,0]],"id":62531723},{"atl":[[5.5,0]],"id":62531723},{"atb":[[1.69,6.13]],"id":51643934}],"con":true,"img":false}]}
{"op":"mcm","clk":"11541150412","pt":1719502764646,"mc":[{"id":"1.230178321","rc":[{"atl":[[5.8,1],[6,13.26]],"id":61941199}],"con":true,"img":false}]}
{"op":"mcm","clk":"11541150420","pt":1719502764746,"mc":[{"id":"1.230178321","rc":[{"atl":[[6.2,1],[7,12.91]],"id":62531723}],"con":true,"img":false}]}
{"op":"mcm","clk":"11541150430","pt":1719502764848,"mc":[{"id":"1.230178321","rc":[{"atl":[[7,3.28]],"id":43498435},{"atl":[[4.4,0.84]],"id":69176305},{"atl":[[3.15,0.84],[3.3,0]],"id":51643934}],"con":true,"img":false}]}
{"op":"mcm","clk":"11541150438","pt":1719502764952,"mc":[{"id":"1.230178321","rc":[{"atl":[[7.2,0]],"id":43498435},{"atl":[[4.6,6.63]],"id":69176305},{"atl":[[3.35,0],[3.25,7.78]],"id":51643934}],"con":true,"img":false}]}
{"op":"mcm","clk":"11541150445","pt":1719502765053,"mc":[{"id":"1.230178321","rc":[{"atl":[[4.8,0]],"id":69176305}],"con":true,"img":false}]}
{"op":"mcm","clk":"11541150549","pt":1719502766149,"mc":[{"id":"1.230178321","rc":[{"atb":[[1.93,8.13]],"id":69176305},{"atb":[[2.68,3.23]],"id":43498435},{"atb":[[2.54,5.98]],"id":61941199},{"atb":[[2.64,3.26]],"id":62531723},{"atb":[[1.68,5.08]],"id":51643934}],"con":true,"img":false}]}
{"op":"mcm","clk":"11541150561","pt":1719502766253,"mc":[{"id":"1.230178321","rc":[{"atb":[[2.68,6.48]],"id":43498435}],"con":true,"img":false}]}
{"op":"mcm","clk":"11541150572","pt":1719502766356,"mc":[{"id":"1.230178321","rc":[{"atb":[[2.6,0],[2.58,0]],"id":43498435},{"atb":[[2.3,16.77]],"id":61419789}],"con":true,"img":false}]}
{"op":"mcm","clk":"11541150582","pt":1719502766457,"mc":[{"id":"1.230178321","rc":[{"atb":[[2.74,2]],"id":43498435}],"con":true,"img":false}]}
{"op":"mcm","clk":"11541150816","pt":1719502768849,"mc":[{"id":"1.230178321","rc":[{"atb":[[1.68,4.2]],"id":51643934}],"con":true,"img":false}]}
{"op":"mcm","clk":"11541150840","pt":1719502769159,"mc":[{"id":"1.230178321","rc":[{"atb":[[2.62,1],[2.7,0]],"id":43498435},{"atb":[[1.74,0]],"id":69176305},{"atb":[[1.44,0]],"id":51643934}],"con":true,"img":false}]}
{"op":"mcm","clk":"11541150863","pt":1719502769365,"mc":[{"id":"1.230178321","rc":[{"atl":[[7.6,0],[7.8,1]],"id":43498435},{"atl":[[4.6,5.63],[4.1,1]],"id":69176305},{"atl":[[5.6,5.4],[5.8,0]],"id":61941199},{"atb":[[2.32,16.5],[2.3,6.83]],"id":61419789},{"atb":[[2.54,0],[2.56,5.82]],"id":62531723},{"atl":[[6.2,0],[5.9,1]],"id":62531723},{"atl":[[3.25,6.78],[3.05,1]],"id":51643934}],"con":true,"img":false}]}
{"op":"mcm","clk":"11541150873","pt":1719502769467,"mc":[{"id":"1.230178321","rc":[{"atl":[[6.8,22.24]],"id":61941199},{"atb":[[2.32,8.25],[2.3,23.33]],"id":61419789},{"atl":[[6.4,10],[7,2.5]],"id":62531723}],"con":true,"img":false}]}
{"op":"mcm","clk":"11541150881","pt":1719502769570,"mc":[{"id":"1.230178321","rc":[{"atl":[[6,2.5]],"id":61941199},{"atb":[[2.32,15.08],[2.3,6.83]],"id":61419789}],"con":true,"img":false}]}
{"op":"mcm","clk":"11541150911","pt":1719502769880,"mc":[{"id":"1.230178321","rc":[{"atb":[[1.93,5.13]],"id":69176305},{"atl":[[4.6,4.79]],"id":69176305},{"atb":[[2.6,0]],"id":62531723}],"con":true,"img":false}]}
{"op":"mcm","clk":"11541150932","pt":1719502770038,"mc":[{"id":"1.230178321","rc":[{"atb":[[1.96,3.05]],"id":69176305}],"con":true,"img":false}]}
{"op":"mcm","clk":"11541150943","pt":1719502770141,"mc":[{"id":"1.230178321","rc":[{"atb":[[2.28,0]],"id":61419789},{"atb":[[1.52,2.5]],"id":51643934}],"con":true,"img":false}]}
{"op":"mcm","clk":"11541150954","pt":1719502770246,"mc":[{"id":"1.230178321","rc":[{"atb":[[2.38,2.11]],"id":61419789},{"atb":[[1.73,2.11]],"id":51643934}],"con":true,"img":false}]}
{"op":"mcm","clk":"11541151010","pt":1719502770770,"mc":[{"id":"1.230178321","rc":[{"atb":[[1.7,9.33]],"id":51643934}],"con":true,"img":false}]}
{"op":"mcm","clk":"11541151021","pt":1719502770871,"mc":[{"id":"1.230178321","rc":[{"atb":[[1.74,2]],"id":51643934}],"con":true,"img":false}]}
{"op":"mcm","clk":"11541151028","pt":1719502770976,"mc":[{"id":"1.230178321","rc":[{"atb":[[2.3,0],[2.36,11.96]],"id":61941199},{"atb":[[2.32,8.25],[2.38,8.94]],"id":61419789},{"atb":[[2.56,0],[2.64,10.38]],"id":62531723},{"atb":[[1.45,10.19],[1.4,0]],"id":51643934}],"con":true,"img":false}]}
{"op":"mcm","clk":"11541151037","pt":1719502771079,"mc":[{"id":"1.230178321","rc":[{"atl":[[6.2,1],[5.9,0]],"id":62531723}],"con":true,"img":false}]}
{"op":"mcm","clk":"11541151048","pt":1719502771183,"mc":[{"id":"1.230178321","rc":[{"atb":[[1.95,3.94]],"id":69176305}],"con":true,"img":false}]}
{"op":"mcm","clk":"11541151057","pt":1719502771238,"mc":[{"id":"1.230178321","rc":[{"atb":[[1.97,2]],"id":69176305}],"con":true,"img":false}]}
{"op":"mcm","clk":"11541151118","pt":1719502771964,"mc":[{"id":"1.230178321","rc":[{"atb":[[2.74,4.25],[2.68,3.23]],"id":43498435},{"atb":[[2.32,6.25]],"id":61419789}],"con":true,"img":false}]}
{"op":"mcm","clk":"11541151129","pt":1719502772068,"mc":[{"id":"1.230178321","rc":[{"atb":[[2.4,2]],"id":61419789}],"con":true,"img":false}]}
{"op":"mcm","clk":"11541151491","pt":1719502776576,"mc":[{"id":"1.230178321","rc":[{"atb":[[2.76,4.3]],"id":43498435},{"atb":[[1.97,5.79]],"id":69176305},{"atl":[[4,3.79]],"id":69176305},{"atb":[[2.4,5.19]],"id":61419789},{"atl":[[3,3.09]],"id":51643934}],"con":true,"img":false}]}
{"op":"mcm","clk":"11541151499","pt":1719502776679,"mc":[{"id":"1.230178321","rc":[{"atl":[[4.4,4.78]],"id":69176305},{"atb":[[2.32,2.97]],"id":61419789},{"atl":[[3.15,6.77]],"id":51643934}],"con":true,"img":false}]}
{"op":"mcm","clk":"11541151508","pt":1719502776782,"mc":[{"id":"1.230178321","rc":[{"atb":[[1.95,0]],"id":69176305},{"atl":[[4.5,0],[4.6,0]],"id":69176305},{"atb":[[2.72,0]],"id":43498435},{"atl":[[3.2,0],[3.25,0]],"id":51643934}],"con":true,"img":false}]}
{"op":"mcm","clk":"11541151557","pt":1719502777354,"mc":[{"id":"1.230178321","rc":[{"atl":[[3.95,0.84]],"id":69176305},{"atl":[[2.98,0.84]],"id":51643934}],"con":true,"img":false}]}
{"op":"mcm","clk":"11541151566","pt":1719502777457,"mc":[{"id":"1.230178321","rc":[{"atb":[[1.93,0]],"id":69176305},{"atl":[[4.1,5.64],[4.4,0]],"id":69176305},{"atb":[[2.68,0]],"id":43498435},{"atb":[[2.3,2.5]],"id":61419789},{"atl":[[3.15,0],[3.05,7.78]],"id":51643934}],"con":true,"img":false}]}
{"op":"mcm","clk":"11541151665","pt":1719502778493,"mc":[{"id":"1.230178321","rc":[{"atb":[[1.96,0]],"id":69176305},{"atb":[[2.32,0]],"id":61419789},{"atb":[[1.7,5.93]],"id":51643934}],"con":true,"img":false}]}
{"op":"mcm","clk":"11541151675","pt":1719502778546,"mc":[{"id":"1.230178321","rc":[{"atb":[[1.98,3.4]],"id":69176305},{"atb":[[2.74,2.25]],"id":43498435},{"atb":[[2.68,3]],"id":62531723},{"atb":[[1.74,4.43]],"id":51643934}],"con":true,"img":false}]}
{"op":"mcm","clk":"11541151688","pt":1719502778650,"mc":[{"id":"1.230178321","rc":[{"atb":[[2.74,0],[2.62,7.55],[2.78,2]],"id":43498435},{"atb":[[2.68,8.98]],"id":62531723}],"con":true,"img":false}]}
{"op":"mcm","clk":"11541151705","pt":1719502778855,"mc":[{"id":"1.230178321","rc":[{"atb":[[2.66,0]],"id":62531723}],"con":true,"img":false}]}
{"op":"mcm","clk":"11541151758","pt":1719502779474,"mc":[{"id":"1.230178321","rc":[{"atb":[[2.62,6.55]],"id":43498435},{"atl":[[4.1,4.64],[4.2,1]],"id":69176305},{"atl":[[5.6,4.4],[5.7,1]],"id":61941199},{"atl":[[3.1,1],[3.05,6.78]],"id":51643934}],"con":true,"img":false}]}
{"op":"mcm","clk":"11541151771","pt":1719502779576,"mc":[{"id":"1.230178321","rc":[{"atl":[[6,12.5],[6.8,5]],"id":61941199},{"atl":[[6.2,0],[5.7,1]],"id":62531723}],"con":true,"img":false}]}
{"op":"mcm","clk":"11541151814","pt":1719502779987,"mc":[{"id":"1.230178321","rc":[{"atb":[[2.64,7.12]],"id":62531723}],"con":true,"img":false}]}
{"op":"mcm","clk":"11541151821","pt":1719502780091,"mc":[{"id":"1.230178321","rc":[{"atb":[[1.97,3.79]],"id":69176305}],"con":true,"img":false}]}
{"op":"mcm","clk":"11541151835","pt":1719502780148,"mc":[{"id":"1.230178321","rc":[{"atb":[[1.99,2]],"id":69176305},{"atl":[[4.8,1],[4.2,0]],"id":69176305},{"atl":[[5.8,1],[5.7,0]],"id":61941199},{"atb":[[2.62,7.55]],"id":43498435},{"atl":[[5.7,0],[5.9,1]],"id":62531723},{"atl":[[3.45,15.87],[3.1,0]],"id":51643934}],"con":true,"img":false}]}
{"op":"mcm","clk":"11541151844","pt":1719502780250,"mc":[{"id":"1.230178321","rc":[{"atl":[[6.2,1]],"id":62531723}],"con":true,"img":false}]}
{"op":"mcm","clk":"11541151894","pt":1719502780881,"mc":[{"id":"1.230178321","rc":[{"atb":[[2.62,6.55],[2.7,1]],"id":43498435},{"atl":[[6.2,0]],"id":62531723}],"con":true,"img":false}]}
{"op":"mcm","clk":"11541151983","pt":1719502781978,"mc":[{"id":"1.230178321","rc":[{"atb":[[2.62,7.55],[2.7,0]],"id":43498435},{"atl":[[4.8,0],[4.6,1]],"id":69176305},{"atl":[[3.45,14.87],[3.25,1]],"id":51643934}],"con":true,"img":false}]}
{"op":"mcm","clk":"11541152141","pt":1719502783864,"mc":[{"id":"1.230178321","rc":[{"atl":[[4.1,5.64]],"id":69176305},{"atl":[[5.6,5.4]],"id":61941199},{"atl":[[6.2,1]],"id":62531723}],"con":true,"img":false}]}
{"op":"mcm","clk":"11541152148","pt":1719502783984,"mc":[{"id":"1.230178321","rc":[{"atl":[[4.6,0]],"id":69176305},{"atl":[[5.8,0]],"id":61941199},{"atl":[[5.9,0]],"id":62531723}],"con":true,"img":false}]}
{"op":"mcm","clk":"11541152163","pt":1719502784172,"mc":[{"id":"1.230178321","rc":[{"atb":[[2.78,6.3],[2.62,1]],"id":43498435}],"con":true,"img":false}]}
{"op":"mcm","clk":"11541152214","pt":1719502784794,"mc":[{"id":"1.230178321","rc":[{"atb":[[2.62,0],[2.7,1]],"id":43498435},{"atl":[[4.6,1]],"id":69176305},{"atl":[[5.6,4.4],[5.8,1]],"id":61941199},{"atl":[[5.9,1]],"id":62531723},{"atl":[[3.25,0],[3.05,7.78]],"id":51643934}],"con":true,"img":false}]}
{"op":"mcm","clk":"11541152222","pt":1719502784849,"mc":[{"id":"1.230178321","rc":[{"atl":[[4.1,4.64]],"id":69176305},{"atl":[[6.2,0]],"id":62531723}],"con":true,"img":false}]}
{"op":"mcm","clk":"11541152243","pt":1719502785055,"mc":[{"id":"1.230178321","rc":[{"atb":[[1.68,0]],"id":51643934}],"con":true,"img":false}]}
{"op":"mcm","clk":"11541152429","pt":1719502787088,"mc":[{"id":"1.230178321","rc":[{"atb":[[2.56,5.56]],"id":61941199}],"con":true,"img":false}]}
{"op":"mcm","clk":"11541152442","pt":1719502787191,"mc":[{"id":"1.230178321","rc":[{"atb":[[2.58,2]],"id":61941199},{"atb":[[2.8,2.3]],"id":43498435}],"con":true,"img":false}]}
{"op":"mcm","clk":"11541152455","pt":1719502787294,"mc":[{"id":"1.230178321","rc":[{"atb":[[2.58,9.48]],"id":61941199}],"con":true,"img":false}]}
{"op":"mcm","clk":"11541152477","pt":1719502787454,"mc":[{"id":"1.230178321","rc":[{"atb":[[2.56,2]],"id":61941199}],"con":true,"img":false}]}
{"op":"mcm","clk":"11541152536","pt":1719502787971,"mc":[{"id":"1.230178321","rc":[{"atl":[[4.5,1.57]],"id":69176305}],"con":true,"img":false}]}
{"op":"mcm","clk":"11541152573","pt":1719502788389,"mc":[{"id":"1.230178321","rc":[{"atb":[[2.56,0]],"id":61941199}],"con":true,"img":false}]}
{"op":"mcm","clk":"11541152577","pt":1719502788489,"mc":[{"id":"1.230178321","rc":[{"atb":[[1.02,2]],"id":61941199}],"con":true,"img":false}]}
{"op":"mcm","clk":"11541152586","pt":1719502788593,"mc":[{"id":"1.230178321","rc":[{"atb":[[1.99,7.39]],"id":69176305},{"atl":[[3.95,6.23]],"id":69176305},{"atb":[[2.82,4.34]],"id":43498435},{"atl":[[2.98,6.48]],"id":51643934}],"con":true,"img":false}]}
{"op":"mcm","clk":"11541152606","pt":1719502788799,"mc":[{"id":"1.230178321","rc":[{"atb":[[1.97,0]],"id":69176305},{"atl":[[4,0]],"id":69176305},{"atb":[[2.76,0]],"id":43498435},{"atl":[[3,0]],"id":51643934}],"con":true,"img":false}]}
{"op":"mcm","clk":"11541152616","pt":1719502788855,"mc":[{"id":"1.230178321","rc":[{"atb":[[2.78,4.3]],"id":43498435}],"con":true,"img":false}]}
{"op":"mcm","clk":"11541152626","pt":1719502788960,"mc":[{"id":"1.230178321","rc":[{"atb":[[2.82,6.34]],"id":43498435},{"atl":[[4.1,0],[4.4,10.88]],"id":69176305},{"atb":[[2.54,2.5]],"id":61941199},{"atl":[[3.4,14.27],[3.05,1]],"id":51643934}],"con":true,"img":false}]}
{"op":"mcm","clk":"11541152637","pt":1719502789063,"mc":[{"id":"1.230178321","rc":[{"atl":[[4.5,0]],"id":69176305},{"atb":[[2.82,10.64],[2.78,0]],"id":43498435}],"con":true,"img":false}]}
{"op":"mcm","clk":"11541152662","pt":1719502789375,"mc":[{"id":"1.230178321","rc":[{"atl":[[4.4,14.03]],"id":69176305}],"con":true,"img":false}]}
{"op":"mcm","clk":"11541152694","pt":1719502789687,"mc":[{"id":"1.230178321","rc":[{"atl":[[4.4,10.88]],"id":69176305}],"con":true,"img":false}]}
{"op":"mcm","clk":"11541152714","pt":1719502789896,"mc":[{"id":"1.230178321","rc":[{"atb":[[2.66,3.24]],"id":62531723},{"atb":[[1.69,11.2]],"id":51643934}],"con":true,"img":false}]}
{"op":"mcm","clk":"11541152722","pt":1719502790000,"mc":[{"id":"1.230178321","rc":[{"atl":[[4.3,3.15]],"id":69176305}],"con":true,"img":false}]}
{"op":"mcm","clk":"11541152730","pt":1719502790061,"mc":[{"id":"1.230178321","rc":[{"atb":[[2.56,3.44]],"id":61941199},{"atb":[[2.38,13.02]],"id":61419789}],"con":true,"img":false}]}
{"op":"mcm","clk":"11541152750","pt":1719502790274,"mc":[{"id":"1.230178321","rc":[{"atl":[[4.3,0]],"id":69176305}],"con":true,"img":false}]}
{"op":"mcm","clk":"11541152776","pt":1719502790588,"mc":[{"id":"1.230178321","rc":[{"atl":[[4.2,1.57]],"id":69176305}],"con":true,"img":false}]}
{"op":"mcm","clk":"11541152808","pt":1719502790889,"mc":[{"id":"1.230178321","rc":[{"atb":[[1.97,5.13]],"id":69176305},{"atb":[[2.78,3.04]],"id":43498435}],"con":true,"img":false}]}
{"op":"mcm","clk":"11541152818","pt":1719502790991,"mc":[{"id":"1.230178321","rc":[{"atl":[[3.25,1],[3.05,0]],"id":51643934}],"con":true,"img":false}]}
{"op":"mcm","clk":"11541152878","pt":1719502791574,"mc":[{"id":"1.230178321","rc":[{"atl":[[4.2,0]],"id":69176305}],"con":true,"img":false}]}
{"op":"mcm","clk":"11541152897","pt":1719502791774,"mc":[{"id":"1.230178321","rc":[{"atl":[[4.2,7.53]],"id":69176305}],"con":true,"img":false}]}
{"op":"mcm","clk":"11541152939","pt":1719502792293,"mc":[{"id":"1.230178321","rc":[{"atb":[[1.83,0]],"id":69176305}],"con":true,"img":false}]}
{"op":"mcm","clk":"11541152999","pt":1719502792873,"mc":[{"id":"1.230178321","rc":[{"atb":[[2.04,5.32]],"id":69176305},{"atl":[[4.2,0]],"id":69176305}],"con":true,"img":false}]}
{"op":"mcm","clk":"11541153024","pt":1719502793186,"mc":[{"id":"1.230178321","rc":[{"atl":[[4.1,3.15]],"id":69176305}],"con":true,"img":false}]}
{"op":"mcm","clk":"11541153058","pt":1719502793601,"mc":[{"id":"1.230178321","rc":[{"atl":[[4.1,0]],"id":69176305}],"con":true,"img":false}]}
{"op":"mcm","clk":"11541153067","pt":1719502793657,"mc":[{"id":"1.230178321","rc":[{"atb":[[1.99,5.39]],"id":69176305}],"con":true,"img":false}]}
{"op":"mcm","clk":"11541153075","pt":1719502793760,"mc":[{"id":"1.230178321","rc":[{"atb":[[2.06,2]],"id":69176305},{"atl":[[4,4.52]],"id":69176305}],"con":true,"img":false}]}
{"op":"mcm","clk":"11541153139","pt":1719502794389,"mc":[{"id":"1.230178321","rc":[{"atl":[[3.95,12.47],[4.4,0]],"id":69176305}],"con":true,"img":false}]}
{"op":"mcm","clk":"11541153148","pt":1719502794488,"mc":[{"id":"1.230178321","rc":[{"atl":[[4,0]],"id":69176305}],"con":true,"img":false}]}
{"op":"mcm","clk":"11541153158","pt":1719502794591,"mc":[{"id":"1.230178321","rc":[{"atb":[[1.64,0],[2.04,7.43]],"id":69176305},{"atl":[[3.95,6.23],[5.7,15.98]],"id":69176305}],"con":true,"img":false}]}
{"op":"mcm","clk":"11541153176","pt":1719502794798,"mc":[{"id":"1.230178321","rc":[{"atl":[[3.95,9.38]],"id":69176305}],"con":true,"img":false}]}
{"op":"mcm","clk":"11541153203","pt":1719502795063,"mc":[{"id":"1.230178321","rc":[{"atl":[[3.95,6.23]],"id":69176305}],"con":true,"img":false}]}
{"op":"mcm","clk":"11541153235","pt":1719502795375,"mc":[{"id":"1.230178321","rc":[{"atl":[[3.85,4.78]],"id":69176305}],"con":true,"img":false}]}
{"op":"mcm","clk":"11541153291","pt":1719502795894,"mc":[{"id":"1.230178321","rc":[{"atl":[[3.95,5.39],[3.8,0.84]],"id":69176305}],"con":true,"img":false}]}
{"op":"mcm","clk":"11541153301","pt":1719502795997,"mc":[{"id":"1.230178321","rc":[{"atb":[[1.98,0]],"id":69176305},{"atb":[[2.8,0]],"id":43498435}],"con":true,"img":false}]}
{"op":"mcm","clk":"11541153316","pt":1719502796103,"mc":[{"id":"1.230178321","rc":[{"atb":[[1.68,0],[2.14,4.2],[1.76,9.6]],"id":69176305},{"atb":[[2.82,6.34],[2.84,2],[2.74,6.08]],"id":43498435},{"atl":[[9,7.25],[10,0],[7.6,1],[7.8,0]],"id":43498435},{"atb":[[2.54,15.42],[2.36,0]],"id":61941199},{"atb":[[2.32,18.22],[2.42,2.2],[2.38,2.11]],"id":61419789},{"atl":[[4.8,1],[4.6,0],[5,0],[5.4,5]],"id":61419789},{"atb":[[2.66,0],[2.64,0],[2.62,16.35]],"id":62531723},{"atb":[[1.45,0],[1.74,12.2],[1.38,11.86]],"id":51643934}],"con":true,"img":false}]}
{"op":"mcm","clk":"11541153327","pt":1719502796204,"mc":[{"id":"1.230178321","rc":[{"atb":[[2.82,9.38],[2.74,0]],"id":43498435},{"atl":[[9,2.5],[7.8,6.58]],"id":43498435},{"atb":[[2.4,10.38],[2.32,0],[2.42,5.44]],"id":61419789},{"atl":[[5.4,0],[4.7,5]],"id":61419789},{"atb":[[2.62,2.11],[2.7,7.12]],"id":62531723},{"atb":[[1.7,0],[1.47,10.36],[1.38,0]],"id":51643934}],"con":true,"img":false}]}
{"op":"mcm","clk":"11541153336","pt":1719502796310,"mc":[{"id":"1.230178321","rc":[{"atl":[[9,9.75],[7.8,0]],"id":43498435},{"atb":[[2.4,7.19]],"id":61419789},{"atl":[[4.8,4.1],[4.7,0]],"id":61419789},{"atb":[[2.68,17.96],[2.7,8.65]],"id":62531723},{"atl":[[3.45,0]],"id":51643934}],"con":true,"img":false}]}
{"op":"mcm","clk":"11541153352","pt":1719502796364,"mc":[{"id":"1.230178321","rc":[{"atl":[[9,2.5],[7.8,5]],"id":43498435},{"atb":[[2.64,16.1]],"id":62531723}],"con":true,"img":false}]}
{"op":"mcm","clk":"11541153364","pt":1719502796467,"mc":[{"id":"1.230178321","rc":[{"atl":[[9,12.25]],"id":43498435},{"atb":[[2.68,3]],"id":62531723}],"con":true,"img":false}]}
{"op":"mcm","clk":"11541153379","pt":1719502796568,"mc":[{"id":"1.230178321","rc":[{"atl":[[7.8,0]],"id":43498435},{"atb":[[2.68,20.3]],"id":62531723}],"con":true,"img":false}]}
{"op":"mcm","clk":"11541153393","pt":1719502796672,"mc":[{"id":"1.230178321","rc":[{"atl":[[7.8,5]],"id":43498435},{"atb":[[2.64,0]],"id":62531723}],"con":true,"img":false}]}
{"op":"mcm","clk":"11541153407","pt":1719502796778,"mc":[{"id":"1.230178321","rc":[{"atl":[[9,2.5]],"id":43498435}],"con":true,"img":false}]}
{"op":"mcm","clk":"11541153417","pt":1719502796879,"mc":[{"id":"1.230178321","rc":[{"atl":[[3.85,0]],"id":69176305}],"con":true,"img":false}]}
{"op":"mcm","clk":"11541153426","pt":1719502796982,"mc":[{"id":"1.230178321","rc":[{"atb":[[2.06,0]],"id":69176305}],"con":true,"img":false}]}
{"op":"mcm","clk":"11541153438","pt":1719502797087,"mc":[{"id":"1.230178321","rc":[{"atb":[[2.16,2]],"id":69176305}],"con":true,"img":false}]}
{"op":"mcm","clk":"11541153447","pt":1719502797190,"mc":[{"id":"1.230178321","rc":[{"atl":[[3.7,1.57]],"id":69176305}],"con":true,"img":false}]}
{"op":"mcm","clk":"11541153466","pt":1719502797397,"mc":[{"id":"1.230178321","rc":[{"atl":[[3.8,0]],"id":69176305},{"atb":[[2.4,5.19]],"id":61419789}],"con":true,"img":false}]}
{"op":"mcm","clk":"11541153479","pt":1719502797501,"mc":[{"id":"1.230178321","rc":[{"atl":[[3.7,0]],"id":69176305},{"atb":[[1.02,13.23]],"id":61419789},{"atb":[[1.69,6.13]],"id":51643934}],"con":true,"img":false}]}
{"op":"mcm","clk":"11541153505","pt":1719502797811,"mc":[{"id":"1.230178321","rc":[{"atb":[[2.82,7.38]],"id":43498435}],"con":true,"img":false}]}
{"op":"mcm","clk":"11541153516","pt":1719502797916,"mc":[{"id":"1.230178321","rc":[{"atb":[[2.86,2]],"id":43498435}],"con":true,"img":false}]}
{"op":"mcm","clk":"11541153529","pt":1719502797972,"mc":[{"id":"1.230178321","rc":[{"atb":[[2.82,4.34]],"id":43498435},{"atl":[[3.8,5.3]],"id":69176305}],"con":true,"img":false}]}
{"op":"mcm","clk":"11541153541","pt":1719502798075,"mc":[{"id":"1.230178321","rc":[{"atb":[[2.86,4]],"id":43498435}],"con":true,"img":false}]}
{"op":"mcm","clk":"11541153710","pt":1719502799993,"mc":[{"id":"1.230178321","rc":[{"atl":[[5.7,2.5],[3.75,5.3]],"id":69176305}],"con":true,"img":false}]}
{"op":"mcm","clk":"11541153752","pt":1719502800410,"mc":[{"id":"1.230178321","rc":[{"atl":[[3.7,7.95]],"id":69176305},{"atb":[[2.86,9.47],[2.7,0]],"id":43498435}],"con":true,"img":false}]}
{"op":"mcm","clk":"11541153764","pt":1719502800519,"mc":[{"id":"1.230178321","rc":[{"atb":[[2.82,0]],"id":43498435},{"atl":[[3.95,0]],"id":69176305}],"con":true,"img":false}]}
{"op":"mcm","clk":"11541153813","pt":1719502800894,"mc":[{"id":"1.230178321","rc":[{"atl":[[3.8,0]],"id":69176305}],"con":true,"img":false}]}
{"op":"mcm","clk":"11541153839","pt":1719502801108,"mc":[{"id":"1.230178321","rc":[{"atb":[[1.97,0]],"id":69176305},{"atb":[[2.78,0]],"id":43498435}],"con":true,"img":false}]}
{"op":"mcm","clk":"11541153851","pt":1719502801212,"mc":[{"id":"1.230178321","rc":[{"atl":[[3.7,11.67]],"id":69176305},{"atb":[[2.54,2.5],[2.56,0],[2.52,21.07]],"id":61941199},{"atl":[[4.8,3.1],[4.9,1]],"id":61419789}],"con":true,"img":false}]}
{"op":"mcm","clk":"11541153922","pt":1719502801795,"mc":[{"id":"1.230178321","rc":[{"atl":[[3.7,7.95]],"id":69176305}],"con":true,"img":false}]}
{"op":"mcm","clk":"11541153947","pt":1719502802003,"mc":[{"id":"1.230178321","rc":[{"atl":[[3.65,1.57]],"id":69176305}],"con":true,"img":false}]}
{"op":"mcm","clk":"11541154012","pt":1719502802582,"mc":[{"id":"1.230178321","rc":[{"atl":[[3.65,0]],"id":69176305}],"con":true,"img":false}]}
{"op":"mcm","clk":"11541154060","pt":1719502802995,"mc":[{"id":"1.230178321","rc":[{"atl":[[3.6,1.57]],"id":69176305}],"con":true,"img":false}]}
{"op":"mcm","clk":"11541154095","pt":1719502803308,"mc":[{"id":"1.230178321","rc":[{"atl":[[3.6,0]],"id":69176305}],"con":true,"img":false}]}
{"op":"mcm","clk":"11541154132","pt":1719502803573,"mc":[{"id":"1.230178321","rc":[{"atl":[[3.6,1.57]],"id":69176305}],"con":true,"img":false}]}
{"op":"mcm","clk":"11541154154","pt":1719502803779,"mc":[{"id":"1.230178321","rc":[{"atl":[[3.6,0]],"id":69176305}],"con":true,"img":false}]}
{"op":"mcm","clk":"11541154166","pt":1719502803883,"mc":[{"id":"1.230178321","rc":[{"atl":[[3.65,0.84]],"id":69176305}],"con":true,"img":false}]}
{"op":"mcm","clk":"11541154200","pt":1719502804195,"mc":[{"id":"1.230178321","rc":[{"atl":[[3.55,4.73]],"id":69176305}],"con":true,"img":false}]}
{"op":"mcm","clk":"11541154229","pt":1719502804404,"mc":[{"id":"1.230178321","rc":[{"atl":[[3.55,0]],"id":69176305}],"con":true,"img":false}]}
{"op":"mcm","clk":"11541154248","pt":1719502804607,"mc":[{"id":"1.230178321","rc":[{"atb":[[2.84,0]],"id":43498435},{"atb":[[2.68,17.3]],"id":62531723},{"atb":[[1.74,9.77]],"id":51643934}],"con":true,"img":false}]}
{"op":"mcm","clk":"11541154259","pt":1719502804713,"mc":[{"id":"1.230178321","rc":[{"atb":[[2.88,2]],"id":43498435},{"atb":[[2.72,2.5],[2.64,25.95],[2.68,0]],"id":62531723},{"atb":[[1.75,3.5]],"id":51643934}],"con":true,"img":false}]}
{"op":"mcm","clk":"11541154266","pt":1719502804769,"mc":[{"id":"1.230178321","rc":[{"atl":[[3.5,1.57]],"id":69176305},{"atb":[[2.72,11.15],[2.64,0]],"id":62531723}],"con":true,"img":false}]}
{"op":"mcm","clk":"11541154295","pt":1719502805079,"mc":[{"id":"1.230178321","rc":[{"atl":[[3.5,0]],"id":69176305}],"con":true,"img":false}]}
{"op":"mcm","clk":"11541154315","pt":1719502805289,"mc":[{"id":"1.230178321","rc":[{"atl":[[6.2,0],[5.7,0],[4.4,2.5],[7,0]],"id":69176305},{"atb":[[2.44,0],[2.58,10],[2.36,0],[2.74,2.5],[2.52,0],[2.66,5]],"id":43498435},{"atb":[[2.3,0],[2.32,10],[2.22,0],[2.14,0],[2.48,2.5],[2.4,10.19]],"id":61419789},{"atb":[[2.5,0],[2.6,10],[2.58,0],[2.76,2.5],[2.42,0],[2.68,5]],"id":62531723}],"con":true,"img":false}]}
{"op":"mcm","clk":"11541154322","pt":1719502805395,"mc":[{"id":"1.230178321","rc":[{"atl":[[3.5,3.15]],"id":69176305},{"atl":[[8,5],[7.2,2.5],[9,0],[11.5,0],[9.8,0],[8.8,10]],"id":43498435}],"con":true,"img":false}]}
{"op":"mcm","clk":"11541154335","pt":1719502805497,"mc":[{"id":"1.230178321","rc":[{"atl":[[7.4,5.79],[7.8,0]],"id":43498435},{"atl":[[3.45,3.15],[3.75,0]],"id":69176305},{"atb":[[2.4,5],[2.48,7.94]],"id":61419789}],"con":true,"img":false}]}
{"op":"mcm","clk":"11541154347","pt":1719502805601,"mc":[{"id":"1.230178321","rc":[{"atb":[[2.42,21.32],[2.48,2.5]],"id":61419789}],"con":true,"img":false}]}
{"op":"mcm","clk":"11541154366","pt":1719502805807,"mc":[{"id":"1.230178321","rc":[{"atl":[[3.65,0]],"id":69176305}],"con":true,"img":false}]}
{"op":"mcm","clk":"11541154377","pt":1719502805910,"mc":[{"id":"1.230178321","rc":[{"atb":[[2.6,21.13]],"id":62531723}],"con":true,"img":false}]}
{"op":"mcm","clk":"11541154397","pt":1719502806118,"mc":[{"id":"1.230178321","rc":[{"atb":[[2.6,10]],"id":62531723}],"con":true,"img":false}]}
{"op":"mcm","clk":"11541154420","pt":1719502806277,"mc":[{"id":"1.230178321","rc":[{"atl":[[4.8,0],[5,5],[4.9,0]],"id":61419789},{"atb":[[1.74,7.77]],"id":51643934}],"con":true,"img":false}]}
{"op":"mcm","clk":"11541154432","pt":1719502806381,"mc":[{"id":"1.230178321","rc":[{"atb":[[2.5,18.96],[2.52,2.11]],"id":61941199},{"atl":[[5,6]],"id":61419789},{"atb":[[1.76,2]],"id":51643934}],"con":true,"img":false}]}
{"op":"mcm","clk":"11541154472","pt":1719502806795,"mc":[{"id":"1.230178321","rc":[{"atb":[[2.6,2.11],[2.52,0]],"id":61941199},{"atb":[[2.38,0],[2.48,4.61]],"id":61419789}],"con":true,"img":false}]}
{"op":"mcm","clk":"11541154480","pt":1719502806899,"mc":[{"id":"1.230178321","rc":[{"atb":[[2.6,7.29]],"id":61941199},{"atb":[[2.86,7.47]],"id":43498435},{"atb":[[2.42,5.44],[2.46,10]],"id":61419789}],"con":true,"img":false}]}
{"op":"mcm","clk":"11541154492","pt":1719502807001,"mc":[{"id":"1.230178321","rc":[{"atb":[[2.9,2]],"id":43498435}],"con":true,"img":false}]}
{"op":"mcm","clk":"11541154501","pt":1719502807108,"mc":[{"id":"1.230178321","rc":[{"atb":[[2.9,4],[2.86,5.47]],"id":43498435},{"atb":[[2.58,2]],"id":61941199}],"con":true,"img":false}]}
{"op":"mcm","clk":"11541154557","pt":1719502807679,"mc":[{"id":"1.230178321","rc":[{"atb":[[1.76,9.49]],"id":51643934}],"con":true,"img":false}]}
{"op":"mcm","clk":"11541154569","pt":1719502807782,"mc":[{"id":"1.230178321","rc":[{"atb":[[2.48,12.15]],"id":61419789}],"con":true,"img":false}]}
{"op":"mcm","clk":"11541154582","pt":1719502807886,"mc":[{"id":"1.230178321","rc":[{"atb":[[2.42,2.2]],"id":61419789},{"atb":[[2.84,9.8]],"id":62531723},{"atb":[[1.74,0]],"id":51643934}],"con":true,"img":false}]}
{"op":"mcm","clk":"11541154595","pt":1719502807989,"mc":[{"id":"1.230178321","rc":[{"atb":[[2.7,0]],"id":62531723}],"con":true,"img":false}]}
{"op":"mcm","clk":"11541154679","pt":1719502808818,"mc":[{"id":"1.230178321","rc":[{"atb":[[1.89,4.75]],"id":62531723}],"con":true,"img":false}]}
{"op":"mcm","clk":"11541154808","pt":1719502810212,"mc":[{"id":"1.230178321","rc":[{"atb":[[2.04,2.11]],"id":69176305}],"con":true,"img":false}]}
{"op":"mcm","clk":"11541154834","pt":1719502810472,"mc":[{"id":"1.230178321","rc":[{"atb":[[1.94,0]],"id":69176305}],"con":true,"img":false}]}
{"op":"mcm","clk":"11541154895","pt":1719502811305,"mc":[{"id":"1.230178321","rc":[{"atl":[[3.4,0.84]],"id":69176305}],"con":true,"img":false}]}
{"op":"mcm","clk":"11541154913","pt":1719502811510,"mc":[{"id":"1.230178321","rc":[{"atl":[[5.1,1],[5,5]],"id":61419789}],"con":true,"img":false}]}
{"op":"mcm","clk":"11541154954","pt":1719502811875,"mc":[{"id":"1.230178321","rc":[{"atl":[[3.4,4.79]],"id":69176305},{"atb":[[2.9,9.47]],"id":43498435}],"con":true,"img":false}]}
{"op":"mcm","clk":"11541154966","pt":1719502811979,"mc":[{"id":"1.230178321","rc":[{"atl":[[3.45,0],[3.35,3.15]],"id":69176305},{"atb":[[2.42,24.36]],"id":61419789}],"con":true,"img":false}]}
{"op":"mcm","clk":"11541154973","pt":1719502812084,"mc":[{"id":"1.230178321","rc":[{"atl":[[3.7,0]],"id":69176305},{"atb":[[2.86,0]],"id":43498435},{"atb":[[2.46,0]],"id":61419789}],"con":true,"img":false}]}
{"op":"mcm","clk":"11541154986","pt":1719502812187,"mc":[{"id":"1.230178321","rc":[{"atl":[[3.45,7.95],[3.35,0]],"id":69176305}],"con":true,"img":false}]}
{"op":"mcm","clk":"11541155009","pt":1719502812396,"mc":[{"id":"1.230178321","rc":[{"atb":[[1.74,5.08]],"id":51643934}],"con":true,"img":false}]}
{"op":"mcm","clk":"11541155019","pt":1719502812498,"mc":[{"id":"1.230178321","rc":[{"atb":[[2.46,3.86]],"id":61419789}],"con":true,"img":false}]}
{"op":"mcm","clk":"11541155030","pt":1719502812600,"mc":[{"id":"1.230178321","rc":[{"atb":[[2.58,5.39]],"id":61941199}],"con":true,"img":false}]}
{"op":"mcm","clk":"11541155100","pt":1719502813173,"mc":[{"id":"1.230178321","rc":[{"atb":[[2.58,3.39]],"id":61941199},{"atb":[[2.88,0]],"id":43498435},{"atb":[[2.42,22.16]],"id":61419789},{"atb":[[2.72,8.65]],"id":62531723},{"atb":[[1.75,0]],"id":51643934}],"con":true,"img":false}]}
{"op":"mcm","clk":"11541155116","pt":1719502813381,"mc":[{"id":"1.230178321","rc":[{"atb":[[2.92,2.2]],"id":43498435},{"atb":[[2.62,3.08]],"id":61941199},{"atb":[[2.04,7]],"id":69176305},{"atb":[[2.5,3.07]],"id":61419789},{"atb":[[2.86,3]],"id":62531723},{"atb":[[1.77,3]],"id":51643934}],"con":true,"img":false}]}
{"op":"mcm","clk":"11541155125","pt":1719502813483,"mc":[{"id":"1.230178321","rc":[{"atb":[[2.72,0],[2.84,18.45]],"id":62531723}],"con":true,"img":false}]}
{"op":"mcm","clk":"11541155204","pt":1719502814518,"mc":[{"id":"1.230178321","rc":[{"atb":[[1.76,7.49]],"id":51643934}],"con":true,"img":false}]}
{"op":"mcm","clk":"11541155214","pt":1719502814572,"mc":[{"id":"1.230178321","rc":[{"atb":[[1.78,2]],"id":51643934}],"con":true,"img":false}]}
{"op":"mcm","clk":"11541155262","pt":1719502815090,"mc":[{"id":"1.230178321","rc":[{"atb":[[2.9,7.47]],"id":43498435}],"con":true,"img":false}]}
{"op":"mcm","clk":"11541155272","pt":1719502815194,"mc":[{"id":"1.230178321","rc":[{"atb":[[2.94,2]],"id":43498435}],"con":true,"img":false}]}
{"op":"mcm","clk":"11541155280","pt":1719502815297,"mc":[{"id":"1.230178321","rc":[{"atb":[[2.9,5.47],[2.94,4.2]],"id":43498435}],"con":true,"img":false}]}
{"op":"mcm","clk":"11541155397","pt":1719502816590,"mc":[{"id":"1.230178321","rc":[{"atl":[[3.5,0]],"id":69176305},{"atb":[[2.42,0],[2.44,10]],"id":61419789},{"atl":[[5.1,0],[5,6]],"id":61419789}],"con":true,"img":false}]}
{"op":"mcm","clk":"11541155413","pt":1719502816795,"mc":[{"id":"1.230178321","rc":[{"atb":[[2.46,0]],"id":61419789}],"con":true,"img":false}]}
{"op":"mcm","clk":"11541155419","pt":1719502816898,"mc":[{"id":"1.230178321","rc":[{"atl":[[3.65,3.87]],"id":69176305}],"con":true,"img":false}]}
{"op":"mcm","clk":"11541155463","pt":1719502817311,"mc":[{"id":"1.230178321","rc":[{"atl":[[3.45,0]],"id":69176305}],"con":true,"img":false}]}
{"op":"mcm","clk":"11541155472","pt":1719502817415,"mc":[{"id":"1.230178321","rc":[{"atl":[[3.6,12.75]],"id":69176305},{"atl":[[4,0],[4.8,0],[3.95,2.5],[4.4,0]],"id":51643934}],"con":true,"img":false}]}
{"op":"mcm","clk":"11541155507","pt":1719502817781,"mc":[{"id":"1.230178321","rc":[{"atl":[[3.65,0]],"id":69176305}],"con":true,"img":false}]}
{"op":"mcm","clk":"11541155520","pt":1719502817883,"mc":[{"id":"1.230178321","rc":[{"atl":[[6,10],[6.8,0],[7.6,0]],"id":61941199}],"con":true,"img":false}]}
{"op":"mcm","clk":"11541155530","pt":1719502817985,"mc":[{"id":"1.230178321","rc":[{"atl":[[6.6,5],[5.9,2.5]],"id":61941199}],"con":true,"img":false}]}
{"op":"mcm","clk":"11541155542","pt":1719502818092,"mc":[{"id":"1.230178321","rc":[{"atl":[[5.8,9.82],[6,0]],"id":61941199},{"atl":[[3.65,2.79]],"id":69176305}],"con":true,"img":false}]}
{"op":"mcm","clk":"11541155567","pt":1719502818298,"mc":[{"id":"1.230178321","rc":[{"atb":[[2.62,8.93]],"id":61941199},{"atb":[[1.89,0]],"id":62531723}],"con":true,"img":false}]}
{"op":"mcm","clk":"11541155577","pt":1719502818403,"mc":[{"id":"1.230178321","rc":[{"atb":[[2.6,2.11]],"id":61941199}],"con":true,"img":false}]}
{"op":"mcm","clk":"11541155598","pt":1719502818609,"mc":[{"id":"1.230178321","rc":[{"atb":[[2.82,21.45],[2.84,9.8]],"id":62531723}],"con":true,"img":false}]}
{"op":"mcm","clk":"11541155616","pt":1719502818816,"mc":[{"id":"1.230178321","rc":[{"atb":[[2.58,0]],"id":61941199}],"con":true,"img":false}]}
{"op":"mcm","clk":"11541155637","pt":1719502819020,"mc":[{"id":"1.230178321","rc":[{"atb":[[1.92,0]],"id":69176305},{"atb":[[1.73,0]],"id":51643934}],"con":true,"img":false}]}
{"op":"mcm","clk":"11541155648","pt":1719502819123,"mc":[{"id":"1.230178321","rc":[{"atb":[[1.78,9.12],[1.79,2.11]],"id":51643934}],"con":true,"img":false}]}
{"op":"mcm","clk":"11541155659","pt":1719502819227,"mc":[{"id":"1.230178321","rc":[{"atb":[[2.5,9.87]],"id":61419789},{"atb":[[1.76,0]],"id":51643934}],"con":true,"img":false}]}
{"op":"mcm","clk":"11541155670","pt":1719502819331,"mc":[{"id":"1.230178321","rc":[{"atb":[[2.86,13.66]],"id":62531723}],"con":true,"img":false}]}
{"op":"mcm","clk":"11541155685","pt":1719502819385,"mc":[{"id":"1.230178321","rc":[{"spn":2.78,"spf":"NaN","id":69176305},{"spn":4.11,"spf":"NaN","id":61941199},{"spn":4.97,"spf":"NaN","id":43498435},{"atb":[[2.48,4.61]],"id":61419789},{"spn":3.45,"spf":"NaN","id":61419789},{"spn":4.13,"spf":"NaN","id":62531723},{"spn":2.38,"spf":"NaN","id":51643934}],"con":true,"img":false}]}
{"op":"mcm","clk":"11541155690","pt":1719502819488,"mc":[{"id":"1.230178321","rc":[{"atb":[[2.84,0]],"id":62531723}],"con":true,"img":false}]}
{"op":"mcm","clk":"11541155732","pt":1719502819903,"mc":[{"id":"1.230178321","rc":[{"atb":[[1.74,0],[1.78,7.12]],"id":51643934}],"con":true,"img":false}]}
{"op":"mcm","clk":"11541155742","pt":1719502820007,"mc":[{"id":"1.230178321","rc":[{"atb":[[1.8,2]],"id":51643934}],"con":true,"img":false}]}
{"op":"mcm","clk":"11541155910","pt":1719502821507,"mc":[{"id":"1.230178321","rc":[{"atl":[[6.2,4.29]],"id":61941199}],"con":true,"img":false}]}
{"op":"mcm","clk":"11541155924","pt":1719502821612,"mc":[{"id":"1.230178321","rc":[{"atb":[[2.04,6.45]],"id":69176305},{"atb":[[2.46,14.49],[2.44,0]],"id":61419789}],"con":true,"img":false}]}
{"op":"mcm","clk":"11541155962","pt":1719502821919,"mc":[{"id":"1.230178321","rc":[{"atb":[[2.92,0]],"id":43498435},{"atb":[[1.77,0]],"id":51643934}],"con":true,"img":false}]}
{"op":"mcm","clk":"11541155972","pt":1719502822024,"mc":[{"id":"1.230178321","rc":[{"atb":[[2.96,3]],"id":43498435},{"atb":[[1.8,4.6]],"id":51643934}],"con":true,"img":false}]}
{"op":"mcm","clk":"11541155989","pt":1719502822183,"mc":[{"id":"1.230178321","rc":[{"atb":[[2.96,7.2],[2.94,1.99]],"id":43498435}],"con":true,"img":false}]}
{"op":"mcm","clk":"11541156046","pt":1719502822809,"mc":[{"id":"1.230178321","rc":[{"atb":[[2.94,0]],"id":43498435}],"con":true,"img":false}]}
{"op":"mcm","clk":"11541156053","pt":1719502822911,"mc":[{"id":"1.230178321","rc":[{"atb":[[2.98,2]],"id":43498435}],"con":true,"img":false}]}
{"op":"mcm","clk":"11541156073","pt":1719502823222,"mc":[{"id":"1.230178321","rc":[{"atb":[[2.98,8.57]],"id":43498435},{"atl":[[5.8,1],[5.9,16.73]],"id":61941199}],"con":true,"img":false}]}
{"op":"mcm","clk":"11541156093","pt":1719502823430,"mc":[{"id":"1.230178321","rc":[{"atb":[[2.9,0]],"id":43498435}],"con":true,"img":false}]}
{"op":"mcm","clk":"11541156123","pt":1719502823797,"mc":[{"id":"1.230178321","rc":[{"atb":[[2.82,0],[2.78,35.11]],"id":62531723}],"con":true,"img":false}]}
{"op":"mcm","clk":"11541156339","pt":1719502826495,"mc":[{"id":"1.230178321","rc":[{"atl":[[6.2,0]],"id":61941199}],"con":true,"img":false}]}
{"op":"mcm","clk":"11541156348","pt":1719502826599,"mc":[{"id":"1.230178321","rc":[{"atb":[[2.46,0],[2.44,19.74]],"id":61419789},{"atb":[[2.78,0],[2.76,51.27]],"id":62531723}],"con":true,"img":false}]}
{"op":"mcm","clk":"11541156354","pt":1719502826701,"mc":[{"id":"1.230178321","rc":[{"atl":[[6,2.05]],"id":61941199}],"con":true,"img":false}]}
{"op":"mcm","clk":"11541156375","pt":1719502827031,"mc":[{"id":"1.230178321","rc":[{"atl":[[6,0]],"id":61941199}],"con":true,"img":false}]}
{"op":"mcm","clk":"11541156397","pt":1719502827321,"mc":[{"id":"1.230178321","rc":[{"atl":[[6,2.07]],"id":61941199}],"con":true,"img":false}]}
{"op":"mcm","clk":"11541156429","pt":1719502827731,"mc":[{"id":"1.230178321","rc":[{"atl":[[6,0]],"id":61941199},{"atb":[[1.66,0]],"id":51643934}],"con":true,"img":false}]}
{"op":"mcm","clk":"11541156456","pt":1719502828093,"mc":[{"id":"1.230178321","rc":[{"atl":[[5.9,21.19]],"id":61941199}],"con":true,"img":false}]}
{"op":"mcm","clk":"11541156622","pt":1719502830221,"mc":[{"id":"1.230178321","rc":[{"atb":[[1.8,12.92]],"id":51643934}],"con":true,"img":false}]}
{"op":"mcm","clk":"11541156637","pt":1719502830430,"mc":[{"id":"1.230178321","rc":[{"atb":[[1.78,0]],"id":51643934}],"con":true,"img":false}]}
{"op":"mcm","clk":"11541156649","pt":1719502830541,"mc":[{"id":"1.230178321","rc":[{"atb":[[1.56,5],[1.6,2.5]],"id":51643934}],"con":true,"img":false}]}
{"op":"mcm","clk":"11541156706","pt":1719502831212,"mc":[{"id":"1.230178321","rc":[{"atb":[[2.96,4.2]],"id":43498435},{"atb":[[2.14,0]],"id":69176305},{"atb":[[1.8,10.32]],"id":51643934}],"con":true,"img":false}]}
{"op":"mcm","clk":"11541156721","pt":1719502831422,"mc":[{"id":"1.230178321","rc":[{"atb":[[2.16,5]],"id":69176305},{"atb":[[3,3.42]],"id":43498435},{"atb":[[1.81,3.8]],"id":51643934}],"con":true,"img":false}]}
{"op":"mcm","clk":"11541156766","pt":1719502831937,"mc":[{"id":"1.230178321","rc":[{"atb":[[2.16,3]],"id":69176305}],"con":true,"img":false}]}
{"op":"mcm","clk":"11541156776","pt":1719502832042,"mc":[{"id":"1.230178321","rc":[{"atb":[[2.06,2]],"id":69176305}],"con":true,"img":false}]}
{"op":"mcm","clk":"11541156785","pt":1719502832097,"mc":[{"id":"1.230178321","rc":[{"atb":[[2.46,14.49]],"id":61419789},{"atb":[[2.78,27.32],[2.76,2.5]],"id":62531723}],"con":true,"img":false}]}
{"op":"mcm","clk":"11541156791","pt":1719502832200,"mc":[{"id":"1.230178321","rc":[{"atb":[[2.44,0]],"id":61419789}],"con":true,"img":false}]}
{"op":"mcm","clk":"11541156801","pt":1719502832312,"mc":[{"id":"1.230178321","rc":[{"atb":[[2.44,10]],"id":61941199}],"con":true,"img":false}]}
{"op":"mcm","clk":"11541156808","pt":1719502832405,"mc":[{"id":"1.230178321","rc":[{"atb":[[2.5,0]],"id":61941199}],"con":true,"img":false}]}
{"op":"mcm","clk":"11541156835","pt":1719502832829,"mc":[{"id":"1.230178321","rc":[{"atb":[[1.8,8.32]],"id":51643934}],"con":true,"img":false}]}
{"op":"mcm","clk":"11541156844","pt":1719502832933,"mc":[{"id":"1.230178321","rc":[{"atb":[[1.82,2]],"id":51643934}],"con":true,"img":false}]}
{"op":"mcm","clk":"11541156852","pt":1719502833029,"mc":[{"id":"1.230178321","rc":[{"atl":[[5.9,16.73]],"id":61941199}],"con":true,"img":false}]}
{"op":"mcm","clk":"11541156862","pt":1719502833236,"mc":[{"id":"1.230178321","rc":[{"atl":[[5.8,2.62]],"id":61941199},{"atb":[[2.06,0]],"id":69176305}],"con":true,"img":false}]}
{"op":"mcm","clk":"11541156870","pt":1719502833337,"mc":[{"id":"1.230178321","rc":[{"atb":[[2.18,2]],"id":69176305}],"con":true,"img":false}]}
{"op":"mcm","clk":"11541156907","pt":1719502833702,"mc":[{"id":"1.230178321","rc":[{"atb":[[2.04,7]],"id":69176305}],"con":true,"img":false}]}
{"op":"mcm","clk":"11541156913","pt":1719502833815,"mc":[{"id":"1.230178321","rc":[{"atb":[[2.98,6.57]],"id":43498435},{"atb":[[1.78,5.07]],"id":51643934}],"con":true,"img":false}]}
{"op":"mcm","clk":"11541156922","pt":1719502833910,"mc":[{"id":"1.230178321","rc":[{"atb":[[3.05,2]],"id":43498435},{"atl":[[3.35,5.85]],"id":69176305},{"atb":[[2.48,8.41]],"id":61419789}],"con":true,"img":false}]}
{"op":"mcm","clk":"11541156930","pt":1719502834023,"mc":[{"id":"1.230178321","rc":[{"atb":[[2.6,5.46]],"id":61941199}],"con":true,"img":false}]}
{"op":"mcm","clk":"11541156941","pt":1719502834116,"mc":[{"id":"1.230178321","rc":[{"atl":[[3.4,0.84]],"id":69176305}],"con":true,"img":false}]}
{"op":"mcm","clk":"11541156954","pt":1719502834332,"mc":[{"id":"1.230178321","rc":[{"atl":[[3.3,0.84]],"id":69176305},{"atb":[[3.05,7.03]],"id":43498435}],"con":true,"img":false}]}
{"op":"mcm","clk":"11541156965","pt":1719502834437,"mc":[{"id":"1.230178321","rc":[{"atl":[[3.6,0],[3.4,7.54]],"id":69176305},{"atb":[[2.98,0]],"id":43498435}],"con":true,"img":false}]}
{"op":"mcm","clk":"11541156997","pt":1719502834740,"mc":[{"id":"1.230178321","rc":[{"atl":[[5.8,1]],"id":61941199}],"con":true,"img":false}]}
{"op":"mcm","clk":"11541157026","pt":1719502835000,"mc":[{"id":"1.230178321","rc":[{"atl":[[5.7,2.51]],"id":61941199}],"con":true,"img":false}]}
{"op":"mcm","clk":"11541157039","pt":1719502835112,"mc":[{"id":"1.230178321","rc":[{"atl":[[5.7,11.33],[5.9,2.5]],"id":61941199}],"con":true,"img":false}]}
{"op":"mcm","clk":"11541157048","pt":1719502835216,"mc":[{"id":"1.230178321","rc":[{"atl":[[5.8,7.92],[5.7,2.51]],"id":61941199}],"con":true,"img":false}]}
{"op":"mcm","clk":"11541157111","pt":1719502835927,"mc":[{"id":"1.230178321","rc":[{"atl":[[5.7,0]],"id":61941199}],"con":true,"img":false}]}
{"op":"mcm","clk":"11541157121","pt":1719502836043,"mc":[{"id":"1.230178321","rc":[{"atl":[[5.8,1],[5.9,14.83]],"id":61941199}],"con":true,"img":false}]}
{"op":"mcm","clk":"11541157136","pt":1719502836238,"mc":[{"id":"1.230178321","rc":[{"atl":[[5.6,8.28]],"id":61941199}],"con":true,"img":false}]}
{"op":"mcm","clk":"11541157147","pt":1719502836343,"mc":[{"id":"1.230178321","rc":[{"atl":[[5.5,8.29],[5.9,2.5]],"id":61941199}],"con":true,"img":false}]}
{"op":"mcm","clk":"11541157158","pt":1719502836446,"mc":[{"id":"1.230178321","rc":[{"atl":[[5.5,14.27]],"id":61941199}],"con":true,"img":false}]}
{"op":"mcm","clk":"11541157177","pt":1719502836602,"mc":[{"id":"1.230178321","rc":[{"atl":[[5.6,4.72]],"id":61941199}],"con":true,"img":false}]}
{"op":"mcm","clk":"11541157192","pt":1719502836859,"mc":[{"id":"1.230178321","rc":[{"atl":[[5.6,0.84],[5.4,0.84]],"id":61941199}],"con":true,"img":false}]}
{"op":"mcm","clk":"11541157223","pt":1719502837221,"mc":[{"id":"1.230178321","rc":[{"atl":[[5.4,5.09]],"id":61941199}],"con":true,"img":false}]}
{"op":"mcm","clk":"11541157241","pt":1719502837429,"mc":[{"id":"1.230178321","rc":[{"atb":[[2.98,10.45]],"id":43498435},{"atl":[[6.2,1],[5.9,0]],"id":62531723},{"atl":[[3.05,1]],"id":51643934}],"con":true,"img":false}]}
{"op":"mcm","clk":"11541157253","pt":1719502837536,"mc":[{"id":"1.230178321","rc":[{"atb":[[2.96,0]],"id":43498435},{"atl":[[5.6,1.84],[5.8,0]],"id":61941199},{"atb":[[2.46,0],[2.44,19.74],[2.48,4.61]],"id":61419789},{"atb":[[2.78,0],[2.76,43.48]],"id":62531723},{"atl":[[6.4,0],[6,8.82]],"id":62531723},{"atl":[[3.25,7.49]],"id":51643934}],"con":true,"img":false}]}
{"op":"mcm","clk":"11541157263","pt":1719502837639,"mc":[{"id":"1.230178321","rc":[{"atl":[[3.4,0]],"id":51643934}],"con":true,"img":false}]}
{"op":"mcm","clk":"11541157283","pt":1719502837843,"mc":[{"id":"1.230178321","rc":[{"atl":[[5.6,1]],"id":61941199}],"con":true,"img":false}]}
{"op":"mcm","clk":"11541157346","pt":1719502838435,"mc":[{"id":"1.230178321","rc":[{"atl":[[5.6,0],[5.8,1]],"id":61941199},{"atl":[[6.2,0],[5.9,1]],"id":62531723}],"con":true,"img":false}]}
{"op":"mcm","clk":"11541157392","pt":1719502838940,"mc":[{"id":"1.230178321","rc":[{"atl":[[5.4,0.84]],"id":61941199}],"con":true,"img":false}]}
{"op":"mcm","clk":"11541157420","pt":1719502839244,"mc":[{"id":"1.230178321","rc":[{"atl":[[5.3,1.68]],"id":61941199}],"con":true,"img":false}]}
{"op":"mcm","clk":"11541157455","pt":1719502839617,"mc":[{"id":"1.230178321","rc":[{"atl":[[5.6,1],[5.8,0]],"id":61941199},{"atl":[[6.2,1],[5.9,0]],"id":62531723}],"con":true,"img":false}]}
{"op":"mcm","clk":"11541157532","pt":1719502840650,"mc":[{"id":"1.230178321","rc":[{"atb":[[3,0]],"id":43498435},{"atb":[[2.16,0]],"id":69176305},{"atb":[[1.81,0]],"id":51643934}],"con":true,"img":false}]}
{"op":"mcm","clk":"11541157547","pt":1719502840857,"mc":[{"id":"1.230178321","rc":[{"atb":[[2.18,5]],"id":69176305},{"atb":[[3.1,3.39]],"id":43498435},{"atb":[[1.82,5.1]],"id":51643934}],"con":true,"img":false}]}
{"op":"mcm","clk":"11541157568","pt":1719502841108,"mc":[{"id":"1.230178321","rc":[{"atb":[[1.82,13.79]],"id":51643934}],"con":true,"img":false}]}
{"op":"mcm","clk":"11541157585","pt":1719502841313,"mc":[{"id":"1.230178321","rc":[{"atb":[[1.8,0]],"id":51643934}],"con":true,"img":false}]}
{"op":"mcm","clk":"11541157600","pt":1719502841518,"mc":[{"id":"1.230178321","rc":[{"atb":[[3.05,5.03]],"id":43498435},{"atl":[[5.3,3.68],[5.5,5.98]],"id":61941199}],"con":true,"img":false}]}
{"op":"mcm","clk":"11541157608","pt":1719502841622,"mc":[{"id":"1.230178321","rc":[{"atb":[[3.15,2]],"id":43498435},{"atl":[[5.3,2]],"id":61941199}],"con":true,"img":false}]}
{"op":"mcm","clk":"11541157635","pt":1719502842033,"mc":[{"id":"1.230178321","rc":[{"atb":[[1.78,0]],"id":51643934}],"con":true,"img":false}]}
{"op":"mcm","clk":"11541157672","pt":1719502842567,"mc":[{"id":"1.230178321","rc":[{"atb":[[3,6.78],[2.98,0]],"id":43498435},{"atb":[[2.6,2.11]],"id":61941199},{"atl":[[5.6,0],[5.8,1]],"id":61941199},{"atl":[[6.2,0],[5.9,1]],"id":62531723},{"atl":[[3.25,8.49],[3.05,0]],"id":51643934}],"con":true,"img":false}]}
{"op":"mcm","clk":"11541157683","pt":1719502842618,"mc":[{"id":"1.230178321","rc":[{"atl":[[5.2,5.61]],"id":61941199}],"con":true,"img":false}]}
{"op":"mcm","clk":"11541157752","pt":1719502843451,"mc":[{"id":"1.230178321","rc":[{"atl":[[5.4,0]],"id":61941199}],"con":true,"img":false}]}
{"op":"mcm","clk":"11541157784","pt":1719502843817,"mc":[{"id":"1.230178321","rc":[{"atl":[[5.1,0.84]],"id":61941199}],"con":true,"img":false}]}
{"op":"mcm","clk":"11541157808","pt":1719502844127,"mc":[{"id":"1.230178321","rc":[{"atl":[[7.6,0]],"id":43498435}],"con":true,"img":false}]}
{"op":"mcm","clk":"11541157816","pt":1719502844232,"mc":[{"id":"1.230178321","rc":[{"atl":[[7.2,3.5],[7.4,6.79]],"id":43498435},{"atl":[[5.6,1],[5.8,0]],"id":61941199},{"atl":[[6.2,1]],"id":62531723}],"con":true,"img":false}]}
{"op":"mcm","clk":"11541157834","pt":1719502844449,"mc":[{"id":"1.230178321","rc":[{"atl":[[5.9,0]],"id":62531723}],"con":true,"img":false}]}
{"op":"mcm","clk":"11541157850","pt":1719502844761,"mc":[{"id":"1.230178321","rc":[{"atl":[[3.25,8.43]],"id":69176305}],"con":true,"img":false}]}
{"op":"mcm","clk":"11541157871","pt":1719502844955,"mc":[{"id":"1.230178321","rc":[{"atl":[[3.35,0]],"id":69176305}],"con":true,"img":false}]}
{"op":"mcm","clk":"11541157890","pt":1719502845114,"mc":[{"id":"1.230178321","rc":[{"atb":[[3.15,7.17]],"id":43498435}],"con":true,"img":false}]}
{"op":"mcm","clk":"11541157905","pt":1719502845318,"mc":[{"id":"1.230178321","rc":[{"atb":[[3.05,0]],"id":43498435},{"atl":[[3.2,0.84],[3.4,6.7]],"id":69176305}],"con":true,"img":false}]}
{"op":"mcm","clk":"11541157913","pt":1719502845423,"mc":[{"id":"1.230178321","rc":[{"atl":[[3.4,0],[3.3,10.12]],"id":69176305}],"con":true,"img":false}]}
{"op":"mcm","clk":"11541157923","pt":1719502845526,"mc":[{"id":"1.230178321","rc":[{"atl":[[3.25,7.49],[3.05,1]],"id":51643934}],"con":true,"img":false}]}
{"op":"mcm","clk":"11541157935","pt":1719502845629,"mc":[{"id":"1.230178321","rc":[{"atl":[[7.4,5.79]],"id":43498435}],"con":true,"img":false}]}
{"op":"mcm","clk":"11541157944","pt":1719502845733,"mc":[{"id":"1.230178321","rc":[{"atl":[[5.2,0]],"id":61941199}],"con":true,"img":false}]}
{"op":"mcm","clk":"11541158021","pt":1719502846455,"mc":[{"id":"1.230178321","rc":[{"atl":[[5.1,0],[5.3,0],[5.5,8.83]],"id":61941199}],"con":true,"img":false}]}
{"op":"mcm","clk":"11541158086","pt":1719502847233,"mc":[{"id":"1.230178321","rc":[{"atl":[[5.2,3.46]],"id":61941199}],"con":true,"img":false}]}
{"op":"mcm","clk":"11541158103","pt":1719502847438,"mc":[{"id":"1.230178321","rc":[{"atl":[[5.5,2.85],[5.2,0]],"id":61941199}],"con":true,"img":false}]}
{"op":"mcm","clk":"11541158112","pt":1719502847540,"mc":[{"id":"1.230178321","rc":[{"atl":[[5.5,6.31]],"id":61941199}],"con":true,"img":false}]}
{"op":"mcm","clk":"11541158196","pt":1719502848628,"mc":[{"id":"1.230178321","rc":[{"atl":[[3.25,8.49],[3.05,0]],"id":51643934}],"con":true,"img":false}]}
{"op":"mcm","clk":"11541158206","pt":1719502848731,"mc":[{"id":"1.230178321","rc":[{"atb":[[2.36,13.93]],"id":61941199},{"atl":[[5.1,1],[5,5]],"id":61419789}],"con":true,"img":false}]}
{"op":"mcm","clk":"11541158212","pt":1719502848834,"mc":[{"id":"1.230178321","rc":[{"atb":[[2.44,0]],"id":61941199},{"atl":[[3.25,7.49],[3.05,1]],"id":51643934}],"con":true,"img":false}]}
{"op":"mcm","clk":"11541158242","pt":1719502849248,"mc":[{"id":"1.230178321","rc":[{"atl":[[5.6,0],[5.8,1]],"id":61941199},{"atb":[[3.1,0]],"id":43498435},{"atl":[[7.4,6.79]],"id":43498435},{"atb":[[1.82,10.69]],"id":51643934}],"con":true,"img":false}]}
{"op":"mcm","clk":"11541158251","pt":1719502849352,"mc":[{"id":"1.230178321","rc":[{"atb":[[3.2,2]],"id":43498435},{"atl":[[7.2,2.5]],"id":43498435},{"atl":[[3.65,0]],"id":69176305},{"atb":[[1.83,3.9]],"id":51643934}],"con":true,"img":false}]}
{"op":"mcm","clk":"11541158295","pt":1719502849916,"mc":[{"id":"1.230178321","rc":[{"atb":[[1.82,8.69]],"id":51643934}],"con":true,"img":false}]}
{"op":"mcm","clk":"11541158303","pt":1719502850019,"mc":[{"id":"1.230178321","rc":[{"atb":[[1.84,2]],"id":51643934}],"con":true,"img":false}]}
{"op":"mcm","clk":"11541158335","pt":1719502850433,"mc":[{"id":"1.230178321","rc":[{"atb":[[3.15,5.17]],"id":43498435}],"con":true,"img":false}]}
{"op":"mcm","clk":"11541158346","pt":1719502850537,"mc":[{"id":"1.230178321","rc":[{"atb":[[3.25,2]],"id":43498435}],"con":true,"img":false}]}
{"op":"mcm","clk":"11541158420","pt":1719502851322,"mc":[{"id":"1.230178321","rc":[{"atl":[[5.5,3.46],[5.9,9.81],[5.4,0.84]],"id":61941199}],"con":true,"img":false}]}
{"op":"mcm","clk":"11541158469","pt":1719502851838,"mc":[{"id":"1.230178321","rc":[{"atb":[[1.84,9.79]],"id":51643934},{"atl":[[3.25,8.49],[3.05,0]],"id":51643934}],"con":true,"img":false}]}
{"op":"mcm","clk":"11541158488","pt":1719502852044,"mc":[{"id":"1.230178321","rc":[{"atb":[[1.82,0]],"id":51643934}],"con":true,"img":false}]}
{"op":"mcm","clk":"11541158499","pt":1719502852150,"mc":[{"id":"1.230178321","rc":[{"atl":[[3.25,1]],"id":51643934}],"con":true,"img":false}]}
{"op":"mcm","clk":"11541158504","pt":1719502852251,"mc":[{"id":"1.230178321","rc":[{"atl":[[3.95,17.48]],"id":51643934}],"con":true,"img":false}]}
{"op":"mcm","clk":"11541158544","pt":1719502852764,"mc":[{"id":"1.230178321","rc":[{"atb":[[1.95,0]],"id":61941199},{"atb":[[1.69,0]],"id":51643934}],"con":true,"img":false}]}
{"op":"mcm","clk":"11541158584","pt":1719502853234,"mc":[{"id":"1.230178321","rc":[{"atb":[[2.48,8.41]],"id":61419789}],"con":true,"img":false}]}
{"op":"mcm","clk":"11541158593","pt":1719502853338,"mc":[{"id":"1.230178321","rc":[{"atb":[[2.6,5.46]],"id":61941199}],"con":true,"img":false}]}
{"op":"mcm","clk":"11541158648","pt":1719502853857,"mc":[{"id":"1.230178321","rc":[{"atb":[[3.1,5],[3,0]],"id":43498435},{"atb":[[2.48,4.61]],"id":61419789},{"atl":[[5.1,0],[5,6]],"id":61419789}],"con":true,"img":false}]}
{"op":"mcm","clk":"11541158687","pt":1719502854163,"mc":[{"id":"1.230178321","rc":[{"atb":[[1.82,5.07]],"id":51643934}],"con":true,"img":false}]}
{"op":"mcm","clk":"11541158808","pt":1719502855356,"mc":[{"id":"1.230178321","rc":[{"atl":[[3.15,9.3]],"id":69176305}],"con":true,"img":false}]}
{"op":"mcm","clk":"11541158817","pt":1719502855458,"mc":[{"id":"1.230178321","rc":[{"atl":[[3.1,8.43],[3.3,0.84]],"id":69176305}],"con":true,"img":false}]}
{"op":"mcm","clk":"11541158828","pt":1719502855562,"mc":[{"id":"1.230178321","rc":[{"atl":[[3.25,0]],"id":69176305}],"con":true,"img":false}]}
{"op":"mcm","clk":"11541158849","pt":1719502855718,"mc":[{"id":"1.230178321","rc":[{"atl":[[3.05,0.84]],"id":69176305},{"atb":[[3.25,6.34]],"id":43498435}],"con":true,"img":false}]}
{"op":"mcm","clk":"11541158860","pt":1719502855840,"mc":[{"id":"1.230178321","rc":[{"atb":[[3.15,0]],"id":43498435},{"atl":[[3.2,0],[3.3,0]],"id":69176305}],"con":true,"img":false}]}
{"op":"mcm","clk":"11541158882","pt":1719502856045,"mc":[{"id":"1.230178321","rc":[{"atb":[[2.8,5],[2.58,0],[2.88,2.5],[2.74,0],[2.66,0]],"id":43498435},{"atb":[[2.6,0],[2.84,2.5]],"id":62531723}],"con":true,"img":false}]}
{"op":"mcm","clk":"11541158917","pt":1719502856360,"mc":[{"id":"1.230178321","rc":[{"atb":[[2.94,9.92]],"id":62531723}],"con":true,"img":false}]}
{"op":"mcm","clk":"11541158934","pt":1719502856567,"mc":[{"id":"1.230178321","rc":[{"atb":[[2.86,3]],"id":62531723}],"con":true,"img":false}]}
{"op":"mcm","clk":"11541159061","pt":1719502857863,"mc":[{"id":"1.230178321","rc":[{"atl":[[5.3,4.47]],"id":61941199}],"con":true,"img":false}]}
{"op":"mcm","clk":"11541159077","pt":1719502858069,"mc":[{"id":"1.230178321","rc":[{"atl":[[5.9,2.5]],"id":61941199}],"con":true,"img":false}]}
{"op":"mcm","clk":"11541159109","pt":1719502858330,"mc":[{"id":"1.230178321","rc":[{"atb":[[3.2,0]],"id":43498435},{"atb":[[2.86,0]],"id":62531723},{"atb":[[1.83,0]],"id":51643934}],"con":true,"img":false}]}
{"op":"mcm","clk":"11541159120","pt":1719502858432,"mc":[{"id":"1.230178321","rc":[{"atb":[[3.3,2.14]],"id":43498435},{"atb":[[2.96,2]],"id":62531723},{"atb":[[1.85,2.43]],"id":51643934}],"con":true,"img":false}]}
{"op":"mcm","clk":"11541159150","pt":1719502858741,"mc":[{"id":"1.230178321","rc":[{"atl":[[5.2,0.84]],"id":61941199}],"con":true,"img":false}]}
{"op":"mcm","clk":"11541159159","pt":1719502858846,"mc":[{"id":"1.230178321","rc":[{"atl":[[5.2,6.07]],"id":61941199},{"atb":[[2.96,12.39]],"id":62531723}],"con":true,"img":false}]}
{"op":"mcm","clk":"11541159179","pt":1719502859053,"mc":[{"id":"1.230178321","rc":[{"atl":[[5.3,0]],"id":61941199}],"con":true,"img":false}]}
{"op":"mcm","clk":"11541159215","pt":1719502859368,"mc":[{"id":"1.230178321","rc":[{"atl":[[5.4,0]],"id":61941199},{"atb":[[3.1,0],[3.25,11.34]],"id":43498435},{"atb":[[2.46,14.49],[2.44,0]],"id":61419789},{"atb":[[2.82,19.84],[2.76,2.5]],"id":62531723},{"atb":[[1.84,7.79]],"id":51643934}],"con":true,"img":false}]}
{"op":"mcm","clk":"11541159223","pt":1719502859468,"mc":[{"id":"1.230178321","rc":[{"atb":[[1.86,2]],"id":51643934}],"con":true,"img":false}]}
{"op":"mcm","clk":"11541159252","pt":1719502859728,"mc":[{"id":"1.230178321","rc":[{"atb":[[3.25,9.34]],"id":43498435}],"con":true,"img":false}]}
{"op":"mcm","clk":"11541159265","pt":1719502859834,"mc":[{"id":"1.230178321","rc":[{"atb":[[3.35,2]],"id":43498435}],"con":true,"img":false}]}
{"op":"mcm","clk":"11541159296","pt":1719502860246,"mc":[{"id":"1.230178321","rc":[{"atl":[[3.1,0],[3.15,18.58]],"id":69176305}],"con":true,"img":false}]}
{"op":"mcm","clk":"11541159314","pt":1719502860455,"mc":[{"id":"1.230178321","rc":[{"atl":[[3.15,9.3],[4.4,21.93]],"id":69176305}],"con":true,"img":false}]}
{"op":"mcm","clk":"11541159328","pt":1719502860562,"mc":[{"id":"1.230178321","rc":[{"atb":[[3.35,11.82]],"id":43498435},{"atl":[[7,6.63]],"id":43498435}],"con":true,"img":false}]}
{"op":"mcm","clk":"11541159369","pt":1719502860874,"mc":[{"id":"1.230178321","rc":[{"atl":[[3.05,0]],"id":69176305}],"con":true,"img":false}]}
{"op":"mcm","clk":"11541159554","pt":1719502862571,"mc":[{"id":"1.230178321","rc":[{"atb":[[1.82,0]],"id":51643934}],"con":true,"img":false}]}
{"op":"mcm","clk":"11541159575","pt":1719502862731,"mc":[{"id":"1.230178321","rc":[{"atl":[[5.8,10.54],[5.5,0]],"id":61941199}],"con":true,"img":false}]}
{"op":"mcm","clk":"11541159585","pt":1719502862837,"mc":[{"id":"1.230178321","rc":[{"atl":[[3.1,0.84]],"id":69176305}],"con":true,"img":false}]}
{"op":"mcm","clk":"11541159881","pt":1719502865760,"mc":[{"id":"1.230178321","rc":[{"atl":[[3.1,10.14]],"id":69176305}],"con":true,"img":false}]}
{"op":"mcm","clk":"11541159900","pt":1719502865968,"mc":[{"id":"1.230178321","rc":[{"atl":[[3.15,0]],"id":69176305}],"con":true,"img":false}]}
{"op":"mcm","clk":"11541159919","pt":1719502866173,"mc":[{"id":"1.230178321","rc":[{"atb":[[3.4,10.07]],"id":43498435}],"con":true,"img":false}]}
{"op":"mcm","clk":"11541159920","pt":1719502866275,"mc":[{"id":"1.230178321","rc":[{"atl":[[6.2,0],[5.9,1]],"id":62531723}],"con":true,"img":false}]}
{"op":"mcm","clk":"11541159938","pt":1719502866382,"mc":[{"id":"1.230178321","rc":[{"atb":[[3.25,5]],"id":43498435}],"con":true,"img":false}]}
{"op":"mcm","clk":"11541159952","pt":1719502866546,"mc":[{"id":"1.230178321","rc":[{"atb":[[3.35,10.6]],"id":43498435}],"con":true,"img":false}]}
{"op":"mcm","clk":"11541159972","pt":1719502866745,"mc":[{"id":"1.230178321","rc":[{"atb":[[3.35,0]],"id":43498435},{"atb":[[2.98,9.92]],"id":62531723}],"con":true,"img":false}]}
{"op":"mcm","clk":"11541159981","pt":1719502866847,"mc":[{"id":"1.230178321","rc":[{"atb":[[3.45,2],[3.4,18.67]],"id":43498435}],"con":true,"img":false}]}
{"op":"mcm","clk":"11541159989","pt":1719502866950,"mc":[{"id":"1.230178321","rc":[{"atb":[[3.45,8.86],[3.4,8.6],[3.3,0]],"id":43498435},{"atb":[[2.94,0]],"id":62531723},{"atb":[[1.85,0]],"id":51643934}],"con":true,"img":false}]}
{"op":"mcm","clk":"11541159996","pt":1719502867054,"mc":[{"id":"1.230178321","rc":[{"atb":[[3.25,0],[3.3,20.67]],"id":43498435},{"atb":[[2.46,0],[2.48,24.35]],"id":61419789},{"atl":[[5,5],[4.9,1]],"id":61419789}],"con":true,"img":false}]}
{"op":"mcm","clk":"11541160009","pt":1719502867157,"mc":[{"id":"1.230178321","rc":[{"atb":[[3.45,12.46]],"id":43498435},{"atb":[[1.86,4.1]],"id":51643934}],"con":true,"img":false}]}
{"op":"mcm","clk":"11541160028","pt":1719502867366,"mc":[{"id":"1.230178321","rc":[{"atb":[[3.4,0]],"id":43498435}],"con":true,"img":false}]}
{"op":"mcm","clk":"11541160101","pt":1719502868051,"mc":[{"id":"1.230178321","rc":[{"atl":[[5.5,2.5]],"id":61941199}],"con":true,"img":false}]}
{"op":"mcm","clk":"11541160119","pt":1719502868255,"mc":[{"id":"1.230178321","rc":[{"atb":[[3.45,22.52]],"id":43498435}],"con":true,"img":false}]}
{"op":"mcm","clk":"11541160253","pt":1719502869755,"mc":[{"id":"1.230178321","rc":[{"atb":[[3.25,3.38]],"id":43498435}],"con":true,"img":false}]}
{"op":"mcm","clk":"11541160304","pt":1719502870372,"mc":[{"id":"1.230178321","rc":[{"atb":[[3.25,0]],"id":43498435}],"con":true,"img":false}]}
{"op":"mcm","clk":"11541160392","pt":1719502871574,"mc":[{"id":"1.230178321","rc":[{"atb":[[2.48,28.15]],"id":61419789}],"con":true,"img":false}]}
{"op":"mcm","clk":"11541160520","pt":1719502873473,"mc":[{"id":"1.230178321","rc":[{"atb":[[1.83,5.08]],"id":51643934}],"con":true,"img":false}]}
{"op":"mcm","clk":"11541160555","pt":1719502873890,"mc":[{"id":"1.230178321","rc":[{"atb":[[2.18,10],[3.3,0]],"id":43498435},{"atl":[[7.4,1],[7,13.27]],"id":43498435},{"atb":[[2.52,9.87],[2.48,4.61]],"id":61419789},{"atb":[[2.82,0],[2.94,22.31]],"id":62531723},{"atb":[[1.62,9.18],[1.47,0]],"id":51643934}],"con":true,"img":false}]}
{"op":"mcm","clk":"11541160563","pt":1719502873961,"mc":[{"id":"1.230178321","rc":[{"atb":[[2.54,5.15]],"id":61419789}],"con":true,"img":false}]}
{"op":"mcm","clk":"11541160571","pt":1719502874058,"mc":[{"id":"1.230178321","rc":[{"atb":[[2.54,15.02],[2.52,0]],"id":61419789}],"con":true,"img":false}]}
{"op":"mcm","clk":"11541160580","pt":1719502874163,"mc":[{"id":"1.230178321","rc":[{"atb":[[2.5,3.07]],"id":61419789}],"con":true,"img":false}]}
{"op":"mcm","clk":"11541160589","pt":1719502874271,"mc":[{"id":"1.230178321","rc":[{"atb":[[2.54,5.15],[2.52,30.04]],"id":61419789}],"con":true,"img":false}]}
{"op":"mcm","clk":"11541160609","pt":1719502874479,"mc":[{"id":"1.230178321","rc":[{"atb":[[3.45,12.46]],"id":43498435}],"con":true,"img":false}]}
{"op":"mcm","clk":"11541160693","pt":1719502875602,"mc":[{"id":"1.230178321","rc":[{"atb":[[2.5,0]],"id":61419789},{"atb":[[2.96,10.39]],"id":62531723}],"con":true,"img":false}]}
{"op":"mcm","clk":"11541160703","pt":1719502875680,"mc":[{"id":"1.230178321","rc":[{"atb":[[2.54,10.15]],"id":61419789},{"atb":[[3,2.32]],"id":62531723}],"con":true,"img":false}]}
{"op":"mcm","clk":"11541160728","pt":1719502875991,"mc":[{"id":"1.230178321","rc":[{"atb":[[2.58,2.11]],"id":61419789}],"con":true,"img":false}]}
{"op":"mcm","clk":"11541160740","pt":1719502876081,"mc":[{"id":"1.230178321","rc":[{"atb":[[2.48,2.5]],"id":61419789}],"con":true,"img":false}]}
{"op":"mcm","clk":"11541160828","pt":1719502876964,"mc":[{"id":"1.230178321","rc":[{"atb":[[3,12.24]],"id":62531723}],"con":true,"img":false}]}
{"op":"mcm","clk":"11541160853","pt":1719502877191,"mc":[{"id":"1.230178321","rc":[{"atb":[[2.98,0]],"id":62531723}],"con":true,"img":false}]}
{"op":"mcm","clk":"11541160913","pt":1719502877665,"mc":[{"id":"1.230178321","rc":[{"atl":[[5.1,8.66]],"id":61941199}],"con":true,"img":false}]}
{"op":"mcm","clk":"11541160923","pt":1719502877765,"mc":[{"id":"1.230178321","rc":[{"atl":[[5.8,1],[5.5,14.66],[5.2,0.84]],"id":61941199}],"con":true,"img":false}]}
{"op":"mcm","clk":"11541160971","pt":1719502878374,"mc":[{"id":"1.230178321","rc":[{"atl":[[5,0.84]],"id":61941199}],"con":true,"img":false}]}
{"op":"mcm","clk":"11541160982","pt":1719502878481,"mc":[{"id":"1.230178321","rc":[{"atl":[[5.2,10.35]],"id":61941199}],"con":true,"img":false}]}
{"op":"mcm","clk":"11541160998","pt":1719502878688,"mc":[{"id":"1.230178321","rc":[{"atl":[[5.5,2.5]],"id":61941199}],"con":true,"img":false}]}
{"op":"mcm","clk":"11541161042","pt":1719502879479,"mc":[{"id":"1.230178321","rc":[{"spn":3.81,"spf":"NaN","id":61941199},{"spn":5.22,"spf":"NaN","id":43498435},{"spn":2.64,"spf":"NaN","id":69176305},{"atb":[[2.54,20.3],[2.52,0]],"id":61419789},{"spn":3.49,"spf":"NaN","id":61419789},{"spn":4.2,"spf":"NaN","id":62531723},{"spn":2.42,"spf":"NaN","id":51643934}],"con":true,"img":false}]}
{"op":"mcm","clk":"11541161242","pt":1719502882397,"mc":[{"id":"1.230178321","rc":[{"atb":[[2.24,0]],"id":61941199},{"atl":[[5.8,0],[5.5,3.5]],"id":61941199},{"atl":[[7.4,0],[7,14.27]],"id":43498435},{"atl":[[4.6,0],[4.2,1]],"id":69176305},{"atb":[[2.54,10.15],[2.52,22.42]],"id":61419789},{"atl":[[6,9.82],[5.9,0]],"id":62531723}],"con":true,"img":false}]}
{"op":"mcm","clk":"11541161250","pt":1719502882458,"mc":[{"id":"1.230178321","rc":[{"atb":[[2.52,0],[2.48,22.8]],"id":61419789}],"con":true,"img":false}]}
{"op":"mcm","clk":"11541161319","pt":1719502883282,"mc":[{"id":"1.230178321","rc":[{"atl":[[7.2,3.5],[7,13.27]],"id":43498435}],"con":true,"img":false}]}
{"op":"mcm","clk":"11541161380","pt":1719502883490,"mc":[{"id":"1.230178321","rc":[{"atl":[[5,3.27]],"id":61941199}],"con":true,"img":false}]}
{"op":"mcm","clk":"11541161400","pt":1719502883688,"mc":[{"id":"1.230178321","rc":[{"atl":[[5.2,0.84],[4.9,8.66]],"id":61941199}],"con":true,"img":false}]}
{"op":"mcm","clk":"11541161422","pt":1719502883896,"mc":[{"id":"1.230178321","rc":[{"atl":[[5,0.84],[5.2,0]],"id":61941199}],"con":true,"img":false}]}
{"op":"mcm","clk":"11541161434","pt":1719502884000,"mc":[{"id":"1.230178321","rc":[{"atl":[[5.1,18.17],[4.9,0]],"id":61941199}],"con":true,"img":false}]}
{"op":"mcm","clk":"11541161443","pt":1719502884064,"mc":[{"id":"1.230178321","rc":[{"atl":[[4.9,4.55]],"id":61941199},{"atb":[[2.58,4.45]],"id":61419789}],"con":true,"img":false}]}
{"op":"mcm","clk":"11541161454","pt":1719502884170,"mc":[{"id":"1.230178321","rc":[{"atl":[[4.8,4.55],[5.1,8.66]],"id":61941199}],"con":true,"img":false}]}
{"op":"mcm","clk":"11541161460","pt":1719502884272,"mc":[{"id":"1.230178321","rc":[{"atb":[[2.54,5]],"id":61419789}],"con":true,"img":false}]}
{"op":"mcm","clk":"11541161498","pt":1719502884682,"mc":[{"id":"1.230178321","rc":[{"atb":[[2.54,0]],"id":61419789}],"con":true,"img":false}]}
{"op":"mcm","clk":"11541161504","pt":1719502884784,"mc":[{"id":"1.230178321","rc":[{"atb":[[2.58,8.45]],"id":61419789}],"con":true,"img":false}]}
{"op":"mcm","clk":"11541161516","pt":1719502884891,"mc":[{"id":"1.230178321","rc":[{"atl":[[5,0]],"id":61941199}],"con":true,"img":false}]}
{"op":"mcm","clk":"11541161575","pt":1719502885574,"mc":[{"id":"1.230178321","rc":[{"atl":[[4.9,0]],"id":61941199},{"atl":[[5,6],[4.9,0]],"id":61419789}],"con":true,"img":false}]}
{"op":"mcm","clk":"11541161582","pt":1719502885673,"mc":[{"id":"1.230178321","rc":[{"atl":[[7.2,19.63],[7,6.63]],"id":43498435},{"atb":[[1.84,0]],"id":51643934}],"con":true,"img":false}]}
{"op":"mcm","clk":"11541161603","pt":1719502885880,"mc":[{"id":"1.230178321","rc":[{"atl":[[8,19.29],[7.2,3.5]],"id":43498435},{"atl":[[4.8,6.01],[4.7,0.84]],"id":61941199}],"con":true,"img":false}]}
{"op":"mcm","clk":"11541161738","pt":1719502887678,"mc":[{"id":"1.230178321","rc":[{"atl":[[4.7,9.45]],"id":61941199}],"con":true,"img":false}]}
{"op":"mcm","clk":"11541161754","pt":1719502887891,"mc":[{"id":"1.230178321","rc":[{"atl":[[5.1,0]],"id":61941199}],"con":true,"img":false}]}
{"op":"mcm","clk":"11541161917","pt":1719502890097,"mc":[{"id":"1.230178321","rc":[{"atb":[[2.56,3.61]],"id":61419789}],"con":true,"img":false}]}
{"op":"mcm","clk":"11541161980","pt":1719502890979,"mc":[{"id":"1.230178321","rc":[{"atl":[[8,5],[7.2,16.78]],"id":43498435}],"con":true,"img":false}]}
{"op":"mcm","clk":"11541161993","pt":1719502891087,"mc":[{"id":"1.230178321","rc":[{"atl":[[5,5],[4.9,1]],"id":61419789},{"atb":[[2.96,34.87]],"id":62531723}],"con":true,"img":false}]}
{"op":"mcm","clk":"11541162003","pt":1719502891188,"mc":[{"id":"1.230178321","rc":[{"atb":[[2.94,0]],"id":62531723}],"con":true,"img":false}]}
{"op":"mcm","clk":"11541162015","pt":1719502891293,"mc":[{"id":"1.230178321","rc":[{"atl":[[6,1],[7,16.73]],"id":62531723}],"con":true,"img":false}]}
{"op":"mcm","clk":"11541162102","pt":1719502892319,"mc":[{"id":"1.230178321","rc":[{"atb":[[1.83,0]],"id":51643934}],"con":true,"img":false}]}
{"op":"mcm","clk":"11541162206","pt":1719502893401,"mc":[{"id":"1.230178321","rc":[{"atl":[[4.3,1],[4.2,0]],"id":69176305},{"atl":[[6.2,1],[6,0]],"id":62531723},{"atl":[[3.25,0],[3.3,1]],"id":51643934}],"con":true,"img":false}]}
{"op":"mcm","clk":"11541162215","pt":1719502893504,"mc":[{"id":"1.230178321","rc":[{"atb":[[1.84,5.08]],"id":51643934},{"atl":[[3.95,2.5],[3.25,12.98]],"id":51643934}],"con":true,"img":false}]}
{"op":"mcm","clk":"11541162238","pt":1719502893667,"mc":[{"id":"1.230178321","rc":[{"atl":[[4.3,0],[4.5,1]],"id":69176305},{"atl":[[7.2,15.78],[6.8,1]],"id":43498435},{"atl":[[5.3,1],[5.4,1]],"id":61941199},{"atl":[[3.2,1],[3.3,0]],"id":51643934}],"con":true,"img":false}]}
{"op":"mcm","clk":"11541162247","pt":1719502893771,"mc":[{"id":"1.230178321","rc":[{"atl":[[6.6,8.73]],"id":43498435},{"atl":[[5.5,2.5]],"id":61941199}],"con":true,"img":false}]}
{"op":"mcm","clk":"11541162261","pt":1719502893973,"mc":[{"id":"1.230178321","rc":[{"atl":[[7,4.19]],"id":43498435}],"con":true,"img":false}]}
{"op":"mcm","clk":"11541162294","pt":1719502894387,"mc":[{"id":"1.230178321","rc":[{"atl":[[6.4,0.84],[7,3.35]],"id":43498435},{"atl":[[5.4,0]],"id":61941199},{"atl":[[4.6,1]],"id":69176305},{"atb":[[2.54,12.07],[2.48,2.5]],"id":61419789}],"con":true,"img":false}]}
{"op":"mcm","clk":"11541162305","pt":1719502894499,"mc":[{"id":"1.230178321","rc":[{"atl":[[4.5,0]],"id":69176305},{"atb":[[2.56,0]],"id":61419789}],"con":true,"img":false}]}
{"op":"mcm","clk":"11541162320","pt":1719502894703,"mc":[{"id":"1.230178321","rc":[{"atl":[[4.6,0],[4.7,1]],"id":69176305},{"atl":[[5.2,1]],"id":61941199},{"atl":[[3.3,1]],"id":51643934}],"con":true,"img":false}]}
{"op":"mcm","clk":"11541162329","pt":1719502894798,"mc":[{"id":"1.230178321","rc":[{"atl":[[5.3,0]],"id":61941199},{"atl":[[3.2,0]],"id":51643934}],"con":true,"img":false}]}
{"op":"mcm","clk":"11541162419","pt":1719502896195,"mc":[{"id":"1.230178321","rc":[{"atb":[[2.06,10],[2.18,0]],"id":43498435},{"atl":[[7.2,2.5],[7.4,6.7]],"id":43498435}],"con":true,"img":false}]}
{"op":"mcm","clk":"11541162429","pt":1719502896395,"mc":[{"id":"1.230178321","rc":[{"atl":[[6.2,9.82],[7,2.5]],"id":62531723}],"con":true,"img":false}]}
{"op":"mcm","clk":"11541162439","pt":1719502896498,"mc":[{"id":"1.230178321","rc":[{"atl":[[7,16.73]],"id":62531723}],"con":true,"img":false}]}
{"op":"mcm","clk":"11541162448","pt":1719502896613,"mc":[{"id":"1.230178321","rc":[{"atl":[[6.2,1]],"id":62531723}],"con":true,"img":false}]}
{"op":"mcm","clk":"11541162796","pt":1719502901091,"mc":[{"id":"1.230178321","rc":[{"atl":[[5.7,1]],"id":61941199}],"con":true,"img":false}]}
{"op":"mcm","clk":"11541162803","pt":1719502901191,"mc":[{"id":"1.230178321","rc":[{"atl":[[5.2,0]],"id":61941199},{"atl":[[6.8,0],[7,4.35]],"id":43498435}],"con":true,"img":false}]}
{"op":"mcm","clk":"11541162978","pt":1719502903607,"mc":[{"id":"1.230178321","rc":[{"atl":[[6.4,7.85]],"id":43498435}],"con":true,"img":false}]}
{"op":"mcm","clk":"11541162996","pt":1719502903813,"mc":[{"id":"1.230178321","rc":[{"atl":[[6.6,0]],"id":43498435}],"con":true,"img":false}]}
{"op":"mcm","clk":"11541163017","pt":1719502904184,"mc":[{"id":"1.230178321","rc":[{"atb":[[2.8,0],[3.1,2.5],[2.96,5]],"id":43498435}],"con":true,"img":false}]}
{"op":"mcm","clk":"11541163025","pt":1719502904395,"mc":[{"id":"1.230178321","rc":[{"atl":[[7,1]],"id":43498435}],"con":true,"img":false}]}
{"op":"mcm","clk":"11541163078","pt":1719502905110,"mc":[{"id":"1.230178321","rc":[{"atl":[[6.4,12.62]],"id":43498435}],"con":true,"img":false}]}
{"op":"mcm","clk":"11541163245","pt":1719502906607,"mc":[{"id":"1.230178321","rc":[{"atb":[[2.56,3.61]],"id":61419789}],"con":true,"img":false}]}
{"op":"mcm","clk":"11541163297","pt":1719502907319,"mc":[{"id":"1.230178321","rc":[{"atl":[[6.2,0],[5.9,1]],"id":62531723}],"con":true,"img":false}]}
{"op":"mcm","clk":"11541163307","pt":1719502907411,"mc":[{"id":"1.230178321","rc":[{"atl":[[6.2,8.82],[7,2.5]],"id":62531723}],"con":true,"img":false}]}
{"op":"mcm","clk":"11541163321","pt":1719502907594,"mc":[{"id":"1.230178321","rc":[{"atl":[[6.2,0],[7,12.5]],"id":62531723}],"con":true,"img":false}]}
{"op":"mcm","clk":"11541163350","pt":1719502907997,"mc":[{"id":"1.230178321","rc":[{"atl":[[6.8,1],[7,0]],"id":43498435},{"atl":[[3.4,1],[3.3,0]],"id":51643934}],"con":true,"img":false}]}
{"op":"mcm","clk":"11541163428","pt":1719502909122,"mc":[{"id":"1.230178321","rc":[{"atl":[[6.8,0],[7,1]],"id":43498435}],"con":true,"img":false}]}
{"op":"mcm","clk":"11541163458","pt":1719502909506,"mc":[{"id":"1.230178321","rc":[{"atl":[[6.2,1],[5.9,0]],"id":62531723},{"atl":[[3.4,0],[3.3,1]],"id":51643934}],"con":true,"img":false}]}
{"op":"mcm","clk":"11541163551","pt":1719502911304,"mc":[{"id":"1.230178321","rc":[{"atl":[[7.4,0],[7.6,9.2]],"id":43498435},{"atb":[[2.54,0],[2.52,16.92]],"id":61419789},{"atl":[[5,6],[4.9,0]],"id":61419789},{"atb":[[2.86,47.11]],"id":62531723},{"atl":[[6.2,0],[5.9,1]],"id":62531723},{"atb":[[1.56,0],[1.6,0],[1.52,0]],"id":51643934},{"atl":[[3.4,1],[3.3,0]],"id":51643934}],"con":true,"img":false}]}
{"op":"mcm","clk":"11541163560","pt":1719502911401,"mc":[{"id":"1.230178321","rc":[{"atb":[[2.56,0]],"id":61419789},{"atb":[[2.96,10.39]],"id":62531723},{"atl":[[3.4,20.47],[3.25,0]],"id":51643934}],"con":true,"img":false}]}
{"op":"mcm","clk":"11541163654","pt":1719502912729,"mc":[{"id":"1.230178321","rc":[{"atl":[[3.4,19.47],[3.3,1]],"id":51643934}],"con":true,"img":false}]}
{"op":"mcm","clk":"11541163739","pt":1719502913621,"mc":[{"id":"1.230178321","rc":[{"atl":[[3.4,20.47],[3.3,0]],"id":51643934}],"con":true,"img":false}]}
{"op":"mcm","clk":"11541163753","pt":1719502913821,"mc":[{"id":"1.230178321","rc":[{"atl":[[6.2,1],[5.9,0]],"id":62531723},{"atl":[[3.4,19.47],[3.3,1]],"id":51643934}],"con":true,"img":false}]}
{"op":"mcm","clk":"11541163765","pt":1719502913927,"mc":[{"id":"1.230178321","rc":[{"atl":[[6.2,11],[7,2.5]],"id":62531723}],"con":true,"img":false}]}
{"op":"mcm","clk":"11541163774","pt":1719502914035,"mc":[{"id":"1.230178321","rc":[{"atl":[[6.2,1],[7,12.5]],"id":62531723}],"con":true,"img":false}]}
{"op":"mcm","clk":"11541163888","pt":1719502915419,"mc":[{"id":"1.230178321","rc":[{"atl":[[6.4,1],[6.2,0]],"id":62531723}],"con":true,"img":false}]}
{"op":"mcm","clk":"11541163894","pt":1719502915524,"mc":[{"id":"1.230178321","rc":[{"atl":[[6.2,8.82],[7,2.5]],"id":62531723}],"con":true,"img":false}]}
{"op":"mcm","clk":"11541163904","pt":1719502915721,"mc":[{"id":"1.230178321","rc":[{"atl":[[5.5,0],[6.6,0],[5.9,0],[5.4,2.5]],"id":61941199}],"con":true,"img":false}]}
{"op":"mcm","clk":"11541164150","pt":1719502919331,"mc":[{"id":"1.230178321","rc":[{"atl":[[7.4,9.2],[7.6,0]],"id":43498435},{"atb":[[2.88,22.63],[2.86,0]],"id":62531723},{"atl":[[3.4,20.47],[3.3,0]],"id":51643934}],"con":true,"img":false}]}
{"op":"mcm","clk":"11541164165","pt":1719502919529,"mc":[{"id":"1.230178321","rc":[{"atl":[[3.95,29.46],[3.4,1]],"id":51643934}],"con":true,"img":false}]}
{"op":"mcm","clk":"11541164276","pt":1719502920946,"mc":[{"id":"1.230178321","rc":[{"atb":[[3.45,20.44]],"id":43498435},{"atb":[[2.62,11.09]],"id":61941199},{"atl":[[4.7,16.22]],"id":61941199},{"atl":[[5,15.97]],"id":61419789},{"atl":[[5.4,10.6]],"id":62531723}],"con":true,"img":false}]}
{"op":"mcm","clk":"11541164294","pt":1719502921136,"mc":[{"id":"1.230178321","rc":[{"atl":[[4.8,1.46],[4.6,6.01]],"id":61941199},{"atl":[[5.6,21.2],[6.2,0]],"id":62531723}],"con":true,"img":false}]}
{"op":"mcm","clk":"11541164302","pt":1719502921204,"mc":[{"id":"1.230178321","rc":[{"atl":[[4.6,14.62]],"id":61941199}],"con":true,"img":false}]}
{"op":"mcm","clk":"11541164311","pt":1719502921307,"mc":[{"id":"1.230178321","rc":[{"atl":[[4.7,7.61]],"id":61941199}],"con":true,"img":false}]}
{"op":"mcm","clk":"11541164342","pt":1719502921723,"mc":[{"id":"1.230178321","rc":[{"atl":[[5.4,15.84]],"id":62531723}],"con":true,"img":false}]}
{"op":"mcm","clk":"11541164352","pt":1719502921819,"mc":[{"id":"1.230178321","rc":[{"atl":[[4.5,0.84]],"id":61941199}],"con":true,"img":false}]}
{"op":"mcm","clk":"11541164381","pt":1719502922229,"mc":[{"id":"1.230178321","rc":[{"atb":[[2.56,3.61]],"id":61419789}],"con":true,"img":false}]}
{"op":"mcm","clk":"11541164423","pt":1719502922741,"mc":[{"id":"1.230178321","rc":[{"atb":[[2.18,10]],"id":43498435},{"atl":[[7.2,16.13]],"id":43498435},{"atb":[[1.83,10.39]],"id":69176305},{"atb":[[2.98,24.48]],"id":62531723}],"con":true,"img":false}]}
{"op":"mcm","clk":"11541164431","pt":1719502922805,"mc":[{"id":"1.230178321","rc":[{"atb":[[2.06,0]],"id":43498435},{"atl":[[7.4,0]],"id":43498435},{"atb":[[1.76,0]],"id":69176305},{"atb":[[2.56,0],[2.54,12.07],[2.52,0]],"id":61419789},{"atb":[[2.88,0]],"id":62531723},{"atb":[[1.84,0],[1.67,9.18],[1.62,0]],"id":51643934}],"con":true,"img":false}]}
{"op":"mcm","clk":"11541164442","pt":1719502922912,"mc":[{"id":"1.230178321","rc":[{"atb":[[1.84,5.08]],"id":51643934}],"con":true,"img":false}]}
{"op":"mcm","clk":"11541164449","pt":1719502923012,"mc":[{"id":"1.230178321","rc":[{"atb":[[1.57,5],[1.53,10],[1.61,2.5]],"id":51643934}],"con":true,"img":false}]}
{"op":"mcm","clk":"11541164571","pt":1719502924206,"mc":[{"id":"1.230178321","rc":[{"atb":[[2.18,0],[2.34,10]],"id":43498435},{"atl":[[4.8,1],[4.7,0]],"id":69176305},{"atl":[[5.7,0]],"id":61941199},{"atb":[[2.66,15.39],[2.98,0]],"id":62531723},{"atl":[[6.4,0],[6.6,1]],"id":62531723},{"atl":[[3.45,1],[3.4,0]],"id":51643934}],"con":true,"img":false}]}
{"op":"mcm","clk":"11541164577","pt":1719502924310,"mc":[{"id":"1.230178321","rc":[{"atl":[[7.2,3.5],[7.4,15.62],[7,0]],"id":43498435},{"atl":[[5.1,1]],"id":61941199},{"atl":[[5,14.97],[4.9,1]],"id":61419789},{"atl":[[8.6,0],[6.8,2.5],[7,0],[7.8,0]],"id":62531723},{"atb":[[1.86,10.98]],"id":51643934},{"atl":[[3.95,2.5],[3.4,12.98]],"id":51643934}],"con":true,"img":false}]}
{"op":"mcm","clk":"11541164586","pt":1719502924410,"mc":[{"id":"1.230178321","rc":[{"atl":[[4.8,3.1]],"id":61419789}],"con":true,"img":false}]}
{"op":"mcm","clk":"11541164598","pt":1719502924518,"mc":[{"id":"1.230178321","rc":[{"atl":[[5,9.97]],"id":61419789}],"con":true,"img":false}]}
{"op":"mcm","clk":"11541164617","pt":1719502924725,"mc":[{"id":"1.230178321","rc":[{"atl":[[6.4,11.74]],"id":43498435}],"con":true,"img":false}]}
{"op":"mcm","clk":"11541164636","pt":1719502924928,"mc":[{"id":"1.230178321","rc":[{"atl":[[6.4,7.85]],"id":43498435}],"con":true,"img":false}]}
{"op":"mcm","clk":"11541164643","pt":1719502925033,"mc":[{"id":"1.230178321","rc":[{"atl":[[7,3.89]],"id":43498435}],"con":true,"img":false}]}
{"op":"mcm","clk":"11541164649","pt":1719502925128,"mc":[{"id":"1.230178321","rc":[{"atb":[[1.86,8.88]],"id":51643934}],"con":true,"img":false}]}
{"op":"mcm","clk":"11541164652","pt":1719502925234,"mc":[{"id":"1.230178321","rc":[{"atl":[[5.1,0],[5.2,1]],"id":61941199},{"atb":[[1.87,5.07]],"id":51643934},{"atl":[[3.45,0],[3.5,1]],"id":51643934}],"con":true,"img":false}]}
{"op":"mcm","clk":"11541164660","pt":1719502925338,"mc":[{"id":"1.230178321","rc":[{"atl":[[4.8,0],[4.6,1]],"id":69176305},{"atl":[[6.6,0]],"id":62531723}],"con":true,"img":false}]}
{"op":"mcm","clk":"11541164666","pt":1719502925444,"mc":[{"id":"1.230178321","rc":[{"atl":[[4.5,1]],"id":69176305},{"atl":[[4.8,2.46],[5.2,0]],"id":61941199},{"atl":[[6.2,1]],"id":62531723},{"atl":[[3.45,1],[3.5,0]],"id":51643934}],"con":true,"img":false}]}
{"op":"mcm","clk":"11541164708","pt":1719502926000,"mc":[{"id":"1.230178321","rc":[{"atl":[[4.7,0.84]],"id":61941199},{"atl":[[5,0]],"id":61419789}],"con":true,"img":false}]}
{"op":"mcm","clk":"11541164720","pt":1719502926109,"mc":[{"id":"1.230178321","rc":[{"atl":[[4.6,8.61],[4.7,16.31]],"id":61941199}],"con":true,"img":false}]}
{"op":"mcm","clk":"11541164733","pt":1719502926219,"mc":[{"id":"1.230178321","rc":[{"atl":[[4.6,15.18]],"id":61941199},{"atb":[[1.83,26.12]],"id":69176305},{"atl":[[4.6,0],[3.1,12.65]],"id":69176305},{"atl":[[4.8,12.76]],"id":61419789},{"atl":[[5.6,0],[5.3,15.84]],"id":62531723},{"atb":[[1.86,18.49]],"id":51643934},{"atl":[[2.98,11.8]],"id":51643934}],"con":true,"img":false}]}
{"op":"mcm","clk":"11541164742","pt":1719502926318,"mc":[{"id":"1.230178321","rc":[{"atl":[[3.25,25.32],[4.4,2.5]],"id":69176305},{"atl":[[4.5,16.03],[4.7,0.84]],"id":61941199},{"atl":[[5.2,16.97]],"id":62531723},{"atl":[[3.4,0]],"id":51643934}],"con":true,"img":false}]}
{"op":"mcm","clk":"11541164748","pt":1719502926411,"mc":[{"id":"1.230178321","rc":[{"atl":[[2.96,11.8]],"id":51643934}],"con":true,"img":false}]}
{"op":"mcm","clk":"11541164757","pt":1719502926516,"mc":[{"id":"1.230178321","rc":[{"atl":[[5.4,12.28]],"id":62531723},{"atb":[[1.84,0]],"id":51643934},{"atl":[[2.94,12.66]],"id":51643934}],"con":true,"img":false}]}
{"op":"mcm","clk":"11541164770","pt":1719502926626,"mc":[{"id":"1.230178321","rc":[{"atl":[[2.92,11.8],[2.96,0]],"id":51643934}],"con":true,"img":false}]}
{"op":"mcm","clk":"11541164783","pt":1719502926735,"mc":[{"id":"1.230178321","rc":[{"atl":[[4.7,0]],"id":61941199},{"atl":[[5.1,0.84],[5.4,11.43]],"id":62531723},{"atl":[[2.92,0],[2.98,6.16],[2.96,25.32],[2.94,13.5]],"id":51643934}],"con":true,"img":false}]}
{"op":"mcm","clk":"11541164813","pt":1719502927032,"mc":[{"id":"1.230178321","rc":[{"atb":[[1.86,16.49]],"id":51643934}],"con":true,"img":false}]}
{"op":"mcm","clk":"11541164824","pt":1719502927134,"mc":[{"id":"1.230178321","rc":[{"atl":[[5.4,6.19]],"id":62531723},{"atb":[[1.88,2]],"id":51643934}],"con":true,"img":false}]}
{"op":"mcm","clk":"11541164860","pt":1719502927403,"mc":[{"id":"1.230178321","rc":[{"atl":[[2.98,5.31]],"id":51643934}],"con":true,"img":false}]}
{"op":"mcm","clk":"11541164911","pt":1719502927927,"mc":[{"id":"1.230178321","rc":[{"atb":[[2.56,16.92],[2.54,0]],"id":61419789},{"atl":[[5.1,6.8]],"id":62531723}],"con":true,"img":false}]}
{"op":"mcm","clk":"11541164960","pt":1719502928533,"mc":[{"id":"1.230178321","rc":[{"atl":[[4.8,9.66],[4.9,5.5]],"id":61419789}],"con":true,"img":false}]}
{"op":"mcm","clk":"11541165022","pt":1719502929298,"mc":[{"id":"1.230178321","rc":[{"atb":[[2.82,20.78]],"id":62531723}],"con":true,"img":false}]}
{"op":"mcm","clk":"11541165039","pt":1719502929407,"mc":[{"id":"1.230178321","rc":[{"atl":[[7.4,0],[7.6,11.75]],"id":43498435},{"atb":[[2.66,0]],"id":62531723}],"con":true,"img":false}]}
{"op":"mcm","clk":"11541165130","pt":1719502930342,"mc":[{"id":"1.230178321","rc":[{"atl":[[4.4,12.42]],"id":61941199}],"con":true,"img":false}]}
{"op":"mcm","clk":"11541165145","pt":1719502930440,"mc":[{"id":"1.230178321","rc":[{"atb":[[2.36,0],[2.24,15.47]],"id":61941199},{"atb":[[2.72,7.5],[2.34,0]],"id":43498435},{"atl":[[4.8,15.16],[4.9,1]],"id":61419789}],"con":true,"img":false}]}
{"op":"mcm","clk":"11541165154","pt":1719502930547,"mc":[{"id":"1.230178321","rc":[{"atl":[[4.5,0.84],[4.3,15.19],[4.6,6.57]],"id":61941199}],"con":true,"img":false}]}
{"op":"mcm","clk":"11541165163","pt":1719502930637,"mc":[{"id":"1.230178321","rc":[{"atl":[[4.3,0],[4.5,25.68]],"id":61941199},{"atb":[[2.72,0],[3.35,40.88]],"id":43498435},{"atb":[[2.82,0],[2.72,20.78]],"id":62531723}],"con":true,"img":false}]}
{"op":"mcm","clk":"11541165182","pt":1719502930842,"mc":[{"id":"1.230178321","rc":[{"atl":[[4.3,0.84]],"id":61941199}],"con":true,"img":false}]}
{"op":"mcm","clk":"11541165200","pt":1719502931000,"mc":[{"id":"1.230178321","rc":[{"atb":[[2.6,2.11]],"id":61941199},{"atl":[[4.6,0]],"id":61941199},{"atl":[[5.4,0]],"id":62531723},{"atl":[[2.98,0]],"id":51643934}],"con":true,"img":false}]}
{"op":"mcm","clk":"11541165213","pt":1719502931208,"mc":[{"id":"1.230178321","rc":[{"atl":[[4.5,32.06]],"id":61941199},{"atl":[[5.1,12.54]],"id":62531723},{"atl":[[3.45,39.83],[2.96,0],[2.94,18.58]],"id":51643934}],"con":true,"img":false}]}
{"op":"mcm","clk":"11541165223","pt":1719502931414,"mc":[{"id":"1.230178321","rc":[{"atl":[[5,15.84],[5.3,0]],"id":62531723}],"con":true,"img":false}]}
{"op":"mcm","clk":"11541165229","pt":1719502931515,"mc":[{"id":"1.230178321","rc":[{"atl":[[3.25,0],[3.05,12.66]],"id":69176305}],"con":true,"img":false}]}
{"op":"mcm","clk":"11541165238","pt":1719502931617,"mc":[{"id":"1.230178321","rc":[{"atl":[[3,9.3]],"id":69176305}],"con":true,"img":false}]}
{"op":"mcm","clk":"11541165254","pt":1719502931833,"mc":[{"id":"1.230178321","rc":[{"atl":[[3.1,3.35],[3,10.14]],"id":69176305}],"con":true,"img":false}]}
{"op":"mcm","clk":"11541165270","pt":1719502932038,"mc":[{"id":"1.230178321","rc":[{"atb":[[2.04,2.11]],"id":69176305},{"atl":[[5.1,6.58]],"id":62531723}],"con":true,"img":false}]}
{"op":"mcm","clk":"11541165300","pt":1719502932412,"mc":[{"id":"1.230178321","rc":[{"atl":[[3.1,2.51]],"id":69176305},{"atb":[[2.6,5.46]],"id":61941199}],"con":true,"img":false}]}
{"op":"mcm","clk":"11541165321","pt":1719502932720,"mc":[{"id":"1.230178321","rc":[{"atl":[[5,21.24]],"id":62531723}],"con":true,"img":false}]}
{"op":"mcm","clk":"11541165363","pt":1719502933248,"mc":[{"id":"1.230178321","rc":[{"atl":[[4.8,1.46],[4.7,1]],"id":61941199}],"con":true,"img":false}]}
{"op":"mcm","clk":"11541165373","pt":1719502933340,"mc":[{"id":"1.230178321","rc":[{"atb":[[2.56,0],[2.6,8.46]],"id":61419789}],"con":true,"img":false}]}
{"op":"mcm","clk":"11541165383","pt":1719502933443,"mc":[{"id":"1.230178321","rc":[{"atb":[[2.6,16.68]],"id":61419789}],"con":true,"img":false}]}
{"op":"mcm","clk":"11541165401","pt":1719502933620,"mc":[{"id":"1.230178321","rc":[{"atb":[[2.58,6.11]],"id":61419789}],"con":true,"img":false}]}
{"op":"mcm","clk":"11541165414","pt":1719502933804,"mc":[{"id":"1.230178321","rc":[{"atl":[[4.9,0.84]],"id":62531723}],"con":true,"img":false}]}
{"op":"mcm","clk":"11541165459","pt":1719502934426,"mc":[{"id":"1.230178321","rc":[{"atl":[[4.7,0]],"id":61941199},{"atl":[[4.5,0]],"id":69176305},{"atl":[[7.2,2.5],[7.4,1]],"id":43498435},{"atl":[[6.2,0],[5.9,1]],"id":62531723}],"con":true,"img":false}]}
{"op":"mcm","clk":"11541165473","pt":1719502934533,"mc":[{"id":"1.230178321","rc":[{"atb":[[3.35,0],[3.25,44.44]],"id":43498435},{"atl":[[8,0],[7.2,0],[8.8,0]],"id":43498435}],"con":true,"img":false}]}
{"op":"mcm","clk":"11541165544","pt":1719502935305,"mc":[{"id":"1.230178321","rc":[{"atl":[[4.9,13.58],[5.9,0]],"id":62531723}],"con":true,"img":false}]}
{"op":"mcm","clk":"11541165559","pt":1719502935511,"mc":[{"id":"1.230178321","rc":[{"atl":[[5.2,0]],"id":62531723}],"con":true,"img":false}]}
{"op":"mcm","clk":"11541165583","pt":1719502935822,"mc":[{"id":"1.230178321","rc":[{"atl":[[5.1,5.74]],"id":62531723}],"con":true,"img":false}]}
{"op":"mcm","clk":"11541165591","pt":1719502935924,"mc":[{"id":"1.230178321","rc":[{"atl":[[3.1,0]],"id":69176305},{"atl":[[4.5,25.68]],"id":61941199},{"atl":[[5.1,0]],"id":62531723}],"con":true,"img":false}]}
{"op":"mcm","clk":"11541165603","pt":1719502936032,"mc":[{"id":"1.230178321","rc":[{"atl":[[5,21.15]],"id":62531723}],"con":true,"img":false}]}
{"op":"mcm","clk":"11541165611","pt":1719502936129,"mc":[{"id":"1.230178321","rc":[{"atl":[[4.4,18.57],[4.7,1]],"id":61941199},{"atl":[[3,12.05],[4.4,25.31],[3.05,0]],"id":69176305},{"atl":[[5,26.72]],"id":62531723}],"con":true,"img":false}]}
{"op":"mcm","clk":"11541165624","pt":1719502936232,"mc":[{"id":"1.230178321","rc":[{"atl":[[5,21.41]],"id":62531723}],"con":true,"img":false}]}
{"op":"mcm","clk":"11541165630","pt":1719502936333,"mc":[{"id":"1.230178321","rc":[{"atl":[[4.3,19.42],[4.5,0.84]],"id":61941199},{"atl":[[4.9,18.89]],"id":62531723}],"con":true,"img":false}]}
{"op":"mcm","clk":"11541165635","pt":1719502936435,"mc":[{"id":"1.230178321","rc":[{"atl":[[3.45,1],[2.92,18.59]],"id":51643934}],"con":true,"img":false}]}
{"op":"mcm","clk":"11541165644","pt":1719502936538,"mc":[{"id":"1.230178321","rc":[{"atl":[[2.9,16.18]],"id":51643934}],"con":true,"img":false}]}
{"op":"mcm","clk":"11541165649","pt":1719502936641,"mc":[{"id":"1.230178321","rc":[{"atb":[[2.24,0],[2.38,20.47]],"id":61941199},{"atl":[[4.7,0]],"id":61941199},{"atb":[[3.2,45.45],[3.25,0]],"id":43498435},{"atb":[[2.58,2.11]],"id":61419789},{"atl":[[2.92,0],[2.88,18.59],[2.94,5.92]],"id":51643934}],"con":true,"img":false}]}
{"op":"mcm","clk":"11541165655","pt":1719502936744,"mc":[{"id":"1.230178321","rc":[{"atl":[[3,24.11],[4.4,2.5]],"id":69176305},{"atl":[[2.92,34.77],[2.88,0]],"id":51643934}],"con":true,"img":false}]}
{"op":"mcm","clk":"11541165660","pt":1719502936848,"mc":[{"id":"1.230178321","rc":[{"atl":[[4.5,0]],"id":61941199},{"atb":[[2.6,8.03]],"id":61419789},{"trd":[[2.6,17.29],[2.62,6.87]],"ltp":2.6,"tv":24.16,"id":61419789},{"atl":[[2.88,0.84],[2.94,5.07]],"id":51643934}],"con":true,"img":false}]}
{"op":"mcm","clk":"11541165666","pt":1719502936904,"mc":[{"id":"1.230178321","rc":[{"atl":[[4.3,3.38]],"id":61419789}],"con":true,"img":false}]}
{"op":"mcm","clk":"11541165674","pt":1719502937008,"mc":[{"id":"1.230178321","rc":[{"atl":[[4.8,9.66],[4.3,6.94],[4.7,5.58]],"id":61419789}],"con":true,"img":false}]}
{"op":"mcm","clk":"11541165685","pt":1719502937209,"mc":[{"id":"1.230178321","rc":[{"atl":[[4.5,0],[4.7,3.1]],"id":61419789}],"con":true,"img":false}]}
{"op":"mcm","clk":"11541165693","pt":1719502937309,"mc":[{"id":"1.230178321","rc":[{"atl":[[4.2,0.84]],"id":61419789}],"con":true,"img":false}]}
{"op":"mcm","clk":"11541165753","pt":1719502938140,"mc":[{"id":"1.230178321","rc":[{"atb":[[2.64,1.94]],"id":61941199},{"atb":[[2.2,1.94]],"id":69176305},{"atb":[[3.5,1.94]],"id":43498435},{"atb":[[2.58,5.65],[2.62,1.94]],"id":61419789},{"atb":[[3.05,1.94]],"id":62531723}],"con":true,"img":false}]}
{"op":"mcm","clk":"11541165758","pt":1719502938236,"mc":[{"id":"1.230178321","rc":[{"atl":[[2.88,3.38]],"id":51643934}],"con":true,"img":false}]}
{"op":"mcm","clk":"11541165766","pt":1719502938340,"mc":[{"id":"1.230178321","rc":[{"atb":[[2.64,14.36]],"id":61941199},{"atb":[[3.5,21.1]],"id":43498435},{"atb":[[2.58,2.11]],"id":61419789},{"atl":[[4.3,5.94]],"id":61419789},{"atb":[[3.05,18.91]],"id":62531723}],"con":true,"img":false}]}
{"op":"mcm","clk":"11541165776","pt":1719502938546,"mc":[{"id":"1.230178321","rc":[{"atb":[[3.45,13.58]],"id":43498435},{"atb":[[2.62,5.24]],"id":61941199},{"atb":[[3,2.32]],"id":62531723}],"con":true,"img":false}]}
{"op":"mcm","clk":"11541165791","pt":1719502938749,"mc":[{"id":"1.230178321","rc":[{"atb":[[3.2,0],[3.25,34.69]],"id":43498435}],"con":true,"img":false}]}
{"op":"mcm","clk":"11541165814","pt":1719502939010,"mc":[{"id":"1.230178321","rc":[{"atb":[[3.45,11.58]],"id":43498435},{"atb":[[2.6,2.11]],"id":61941199}],"con":true,"img":false}]}
{"op":"mcm","clk":"11541165826","pt":1719502939116,"mc":[{"id":"1.230178321","rc":[{"atb":[[3.55,2]],"id":43498435}],"con":true,"img":false}]}
{"op":"mcm","clk":"11541165847","pt":1719502939317,"mc":[{"id":"1.230178321","rc":[{"atl":[[4.2,14.71]],"id":61941199}],"con":true,"img":false}]}
{"op":"mcm","clk":"11541165856","pt":1719502939420,"mc":[{"id":"1.230178321","rc":[{"atl":[[7.2,1],[7.4,0]],"id":43498435},{"atl":[[5,5.57],[4.9,37.79]],"id":62531723}],"con":true,"img":false}]}
{"op":"mcm","clk":"11541165867","pt":1719502939523,"mc":[{"id":"1.230178321","rc":[{"spn":4.97,"spf":"NaN","id":43498435},{"atl":[[4.4,6.15]],"id":61941199},{"spn":3.42,"spf":"NaN","id":61941199},{"spn":2.6,"spf":"NaN","id":69176305},{"spn":3.41,"spf":"NaN","id":61419789},{"spn":3.97,"spf":"NaN","id":62531723},{"spn":2.38,"spf":"NaN","id":51643934}],"con":true,"img":false}]}
{"op":"mcm","clk":"11541165897","pt":1719502939837,"mc":[{"id":"1.230178321","rc":[{"atl":[[4.1,0.84]],"id":61941199}],"con":true,"img":false}]}
{"op":"mcm","clk":"11541165914","pt":1719502940037,"mc":[{"id":"1.230178321","rc":[{"atb":[[3.5,20.31]],"id":43498435},{"atl":[[4.2,1.37]],"id":61419789}],"con":true,"img":false}]}
{"op":"mcm","clk":"11541165949","pt":1719502940449,"mc":[{"id":"1.230178321","rc":[{"atb":[[3.5,10.75]],"id":43498435}],"con":true,"img":false}]}
{"op":"mcm","clk":"11541165959","pt":1719502940551,"mc":[{"id":"1.230178321","rc":[{"atb":[[3.55,11.56]],"id":43498435},{"atl":[[4.1,1]],"id":61419789}],"con":true,"img":false}]}
{"op":"mcm","clk":"11541165982","pt":1719502940822,"mc":[{"id":"1.230178321","rc":[{"atb":[[3.45,3.6]],"id":43498435},{"atb":[[2.62,3.08]],"id":61941199},{"atl":[[4.4,0]],"id":61941199},{"atl":[[4.8,0],[4.6,3.1],[4.7,0]],"id":61419789},{"atb":[[2.72,0],[2.88,20.78]],"id":62531723},{"atl":[[5,25],[4.9,18.89]],"id":62531723},{"atl":[[2.94,0]],"id":51643934}],"con":true,"img":false}]}
{"op":"mcm","clk":"11541165995","pt":1719502941017,"mc":[{"id":"1.230178321","rc":[{"atb":[[2.64,16.33]],"id":61941199},{"atl":[[4.2,20.39]],"id":61941199},{"atb":[[3.5,18.46]],"id":43498435},{"atl":[[4.3,14.66]],"id":61419789},{"atl":[[4.9,24.3]],"id":62531723},{"atl":[[2.9,21.01]],"id":51643934}],"con":true,"img":false}]}
{"op":"mcm","clk":"11541166000","pt":1719502941125,"mc":[{"id":"1.230178321","rc":[{"atl":[[4.1,20.27]],"id":61941199}],"con":true,"img":false}]}
{"op":"mcm","clk":"11541166003","pt":1719502941223,"mc":[{"id":"1.230178321","rc":[{"atl":[[4.3,0.84]],"id":61941199}],"con":true,"img":false}]}
{"op":"mcm","clk":"11541166014","pt":1719502941327,"mc":[{"id":"1.230178321","rc":[{"atb":[[3.5,16.51]],"id":43498435},{"atb":[[2.2,0]],"id":69176305},{"atb":[[2.62,0]],"id":61419789},{"atl":[[4.4,0]],"id":61419789}],"con":true,"img":false}]}
{"op":"mcm","clk":"11541166029","pt":1719502941531,"mc":[{"id":"1.230178321","rc":[{"atb":[[2.2,1.94]],"id":69176305},{"atb":[[3.6,1.94]],"id":43498435},{"atb":[[2.62,1.94]],"id":61419789}],"con":true,"img":false}]}
{"op":"mcm","clk":"11541166044","pt":1719502941741,"mc":[{"id":"1.230178321","rc":[{"atl":[[4.3,0]],"id":61941199}],"con":true,"img":false}]}
{"op":"mcm","clk":"11541166050","pt":1719502941840,"mc":[{"id":"1.230178321","rc":[{"atl":[[2.92,0],[2.86,21.01]],"id":51643934}],"con":true,"img":false}]}
{"op":"mcm","clk":"11541166081","pt":1719502942250,"mc":[{"id":"1.230178321","rc":[{"atb":[[2.62,4.99]],"id":61419789}],"con":true,"img":false}]}
{"op":"mcm","clk":"11541166089","pt":1719502942354,"mc":[{"id":"1.230178321","rc":[{"atb":[[2.6,0]],"id":61419789}],"con":true,"img":false}]}
{"op":"mcm","clk":"11541166097","pt":1719502942409,"mc":[{"id":"1.230178321","rc":[{"atb":[[3.55,9.75]],"id":43498435}],"con":true,"img":false}]}
{"op":"mcm","clk":"11541166107","pt":1719502942518,"mc":[{"id":"1.230178321","rc":[{"atb":[[3.45,0]],"id":43498435},{"atb":[[2.62,0]],"id":61941199},{"atb":[[2.18,2]],"id":69176305},{"atb":[[3,0]],"id":62531723},{"atb":[[1.87,0]],"id":51643934}],"con":true,"img":false}]}
{"op":"mcm","clk":"11541166116","pt":1719502942622,"mc":[{"id":"1.230178321","rc":[{"atb":[[2.2,5.94]],"id":69176305},{"atb":[[3.6,5.03],[3.55,2]],"id":43498435},{"atb":[[2.66,2.8]],"id":61941199},{"atb":[[2.62,7.47]],"id":61419789},{"atb":[[3.1,3]],"id":62531723},{"atb":[[1.88,6.2]],"id":51643934}],"con":true,"img":false}]}
{"op":"mcm","clk":"11541166122","pt":1719502942721,"mc":[{"id":"1.230178321","rc":[{"atb":[[3.6,12.78]],"id":43498435}],"con":true,"img":false}]}
{"op":"mcm","clk":"11541166145","pt":1719502942926,"mc":[{"id":"1.230178321","rc":[{"atb":[[1.88,4.2]],"id":51643934}],"con":true,"img":false}]}
{"op":"mcm","clk":"11541166155","pt":1719502943036,"mc":[{"id":"1.230178321","rc":[{"atl":[[4.8,0]],"id":61941199},{"atb":[[1.87,2]],"id":51643934},{"atl":[[2.88,0.84]],"id":51643934}],"con":true,"img":false}]}
{"op":"mcm","clk":"11541166187","pt":1719502943338,"mc":[{"id":"1.230178321","rc":[{"atb":[[2.18,0]],"id":69176305}],"con":true,"img":false}]}
{"op":"mcm","clk":"11541166199","pt":1719502943441,"mc":[{"id":"1.230178321","rc":[{"atb":[[2.06,2]],"id":69176305},{"atb":[[2.66,17.94]],"id":61941199}],"con":true,"img":false}]}
{"op":"mcm","clk":"11541166208","pt":1719502943544,"mc":[{"id":"1.230178321","rc":[{"atl":[[4.5,1.84]],"id":61941199}],"con":true,"img":false}]}
{"op":"mcm","clk":"11541166263","pt":1719502944116,"mc":[{"id":"1.230178321","rc":[{"atb":[[1.87,0]],"id":51643934}],"con":true,"img":false}]}
{"op":"mcm","clk":"11541166273","pt":1719502944220,"mc":[{"id":"1.230178321","rc":[{"atb":[[1.89,2]],"id":51643934}],"con":true,"img":false}]}
{"op":"mcm","clk":"11541166281","pt":1719502944323,"mc":[{"id":"1.230178321","rc":[{"atl":[[2.84,0.84]],"id":51643934}],"con":true,"img":false}]}
{"op":"mcm","clk":"11541166290","pt":1719502944429,"mc":[{"id":"1.230178321","rc":[{"atb":[[2.54,0],[2.38,10.47],[2.46,0],[2.64,1.96]],"id":61941199},{"atb":[[2.06,0]],"id":69176305},{"atl":[[7.2,0],[7.4,1]],"id":43498435},{"atb":[[3.05,16.97]],"id":62531723}],"con":true,"img":false}]}
{"op":"mcm","clk":"11541166298","pt":1719502944531,"mc":[{"id":"1.230178321","rc":[{"atb":[[2.22,2]],"id":69176305}],"con":true,"img":false}]}
{"op":"mcm","clk":"11541166322","pt":1719502944737,"mc":[{"id":"1.230178321","rc":[{"atl":[[4.5,0]],"id":61941199},{"atl":[[4.6,0],[4.7,4.47]],"id":61419789}],"con":true,"img":false}]}
{"op":"mcm","clk":"11541166344","pt":1719502944943,"mc":[{"id":"1.230178321","rc":[{"atl":[[4.4,1.51]],"id":61941199},{"atb":[[3.55,0]],"id":43498435},{"atb":[[3,3.5]],"id":62531723}],"con":true,"img":false}]}
{"op":"mcm","clk":"11541166353","pt":1719502945044,"mc":[{"id":"1.230178321","rc":[{"atb":[[3.65,2]],"id":43498435}],"con":true,"img":false}]}
{"op":"mcm","clk":"11541166373","pt":1719502945353,"mc":[{"id":"1.230178321","rc":[{"atl":[[2.84,5.49]],"id":51643934}],"con":true,"img":false}]}
{"op":"mcm","clk":"11541166398","pt":1719502945616,"mc":[{"id":"1.230178321","rc":[{"atl":[[4.1,4.28]],"id":61419789},{"atl":[[2.9,4.83],[2.84,8.03]],"id":51643934}],"con":true,"img":false}]}
{"op":"mcm","clk":"11541166409","pt":1719502945722,"mc":[{"id":"1.230178321","rc":[{"atb":[[3.5,8.81]],"id":43498435},{"atb":[[2.64,0]],"id":61941199},{"atl":[[4.2,14.71]],"id":61941199},{"atl":[[4,2.31]],"id":61419789},{"atl":[[2.9,0]],"id":51643934}],"con":true,"img":false}]}
{"op":"mcm","clk":"11541166416","pt":1719502945818,"mc":[{"id":"1.230178321","rc":[{"atb":[[3.6,5.03]],"id":43498435},{"atb":[[2.3,2.5],[2.22,5],[2.14,10]],"id":61941199},{"atl":[[4.3,30.3]],"id":61941199},{"atl":[[4.3,12.28],[4.1,8.36]],"id":61419789},{"atl":[[2.88,0]],"id":51643934}],"con":true,"img":false}]}
{"op":"mcm","clk":"11541166427","pt":1719502945923,"mc":[{"id":"1.230178321","rc":[{"atl":[[4.1,6.26]],"id":61941199},{"atb":[[3.6,12.22]],"id":43498435},{"atl":[[4.3,8.72]],"id":61419789},{"atl":[[2.86,25.58]],"id":51643934}],"con":true,"img":false}]}
{"op":"mcm","clk":"11541166477","pt":1719502946335,"mc":[{"id":"1.230178321","rc":[{"atl":[[3.95,0.84]],"id":61419789},{"atl":[[5.8,1]],"id":62531723}],"con":true,"img":false}]}
{"op":"mcm","clk":"11541166484","pt":1719502946439,"mc":[{"id":"1.230178321","rc":[{"atl":[[4.2,0.52]],"id":61419789},{"atb":[[3,0]],"id":62531723}],"con":true,"img":false}]}
{"op":"mcm","clk":"11541166498","pt":1719502946549,"mc":[{"id":"1.230178321","rc":[{"atl":[[5.8,0]],"id":62531723}],"con":true,"img":false}]}
{"op":"mcm","clk":"11541166506","pt":1719502946645,"mc":[{"id":"1.230178321","rc":[{"atb":[[3.65,10.07]],"id":43498435},{"atl":[[4.1,13.02]],"id":61941199},{"atb":[[2.62,20.01]],"id":61419789},{"atl":[[3.95,8.69]],"id":61419789}],"con":true,"img":false}]}
{"op":"mcm","clk":"11541166540","pt":1719502947055,"mc":[{"id":"1.230178321","rc":[{"atl":[[2.82,8.04],[2.86,4.57]],"id":51643934}],"con":true,"img":false}]}
{"op":"mcm","clk":"11541166552","pt":1719502947111,"mc":[{"id":"1.230178321","rc":[{"atb":[[2.58,3.12]],"id":61941199},{"atb":[[3.6,9.13],[3.7,12.5]],"id":43498435},{"atb":[[2.2,1.94]],"id":69176305},{"atb":[[2.62,17.53]],"id":61419789},{"atb":[[3.1,23.52]],"id":62531723},{"atb":[[1.88,0]],"id":51643934}],"con":true,"img":false}]}
{"op":"mcm","clk":"11541166561","pt":1719502947222,"mc":[{"id":"1.230178321","rc":[{"atb":[[3.5,0],[3.7,15.31]],"id":43498435},{"atb":[[2.22,5.6]],"id":69176305},{"atb":[[2.64,3.5]],"id":61419789},{"atb":[[3.05,0]],"id":62531723},{"atb":[[1.89,5.7]],"id":51643934}],"con":true,"img":false}]}
{"op":"mcm","clk":"11541166568","pt":1719502947313,"mc":[{"id":"1.230178321","rc":[{"atb":[[3.6,7.18],[3.65,2]],"id":43498435},{"atb":[[2.2,0]],"id":69176305},{"atb":[[2.4,0],[2.32,0],[2.5,2.5],[2.48,0]],"id":61419789},{"atl":[[5.8,1]],"id":62531723},{"atl":[[3.45,0]],"id":51643934}],"con":true,"img":false}]}
{"op":"mcm","clk":"11541166588","pt":1719502947526,"mc":[{"id":"1.230178321","rc":[{"atb":[[2.06,1.94]],"id":69176305},{"atb":[[3.75,1.94]],"id":43498435}],"con":true,"img":false}]}
{"op":"mcm","clk":"11541166610","pt":1719502947735,"mc":[{"id":"1.230178321","rc":[{"atb":[[3.65,0]],"id":43498435}],"con":true,"img":false}]}
{"op":"mcm","clk":"11541166618","pt":1719502947833,"mc":[{"id":"1.230178321","rc":[{"atb":[[3.75,3.94]],"id":43498435},{"atb":[[2.62,3.29]],"id":61941199},{"atl":[[3.9,1]],"id":61419789}],"con":true,"img":false}]}
{"op":"mcm","clk":"11541166635","pt":1719502948044,"mc":[{"id":"1.230178321","rc":[{"atl":[[4,20.8]],"id":61941199}],"con":true,"img":false}]}
{"op":"mcm","clk":"11541166657","pt":1719502948252,"mc":[{"id":"1.230178321","rc":[{"atl":[[4.2,0]],"id":61941199},{"atb":[[1.87,5.07]],"id":51643934}],"con":true,"img":false}]}
{"op":"mcm","clk":"11541166675","pt":1719502948454,"mc":[{"id":"1.230178321","rc":[{"atb":[[2.58,0]],"id":61941199},{"atb":[[2.62,4.99]],"id":61419789}],"con":true,"img":false}]}
{"op":"mcm","clk":"11541166702","pt":1719502948659,"mc":[{"id":"1.230178321","rc":[{"atb":[[3.75,12.04]],"id":43498435}],"con":true,"img":false}]}
{"op":"mcm","clk":"11541166724","pt":1719502948818,"mc":[{"id":"1.230178321","rc":[{"atl":[[3.95,0.84]],"id":61941199}],"con":true,"img":false}]}
{"op":"mcm","clk":"11541166744","pt":1719502949026,"mc":[{"id":"1.230178321","rc":[{"atb":[[1.79,0],[1.9,2.11]],"id":51643934}],"con":true,"img":false}]}
{"op":"mcm","clk":"11541166750","pt":1719502949125,"mc":[{"id":"1.230178321","rc":[{"atl":[[4.1,6.26]],"id":61941199}],"con":true,"img":false}]}
{"op":"mcm","clk":"11541166761","pt":1719502949228,"mc":[{"id":"1.230178321","rc":[{"atl":[[2.84,5.49]],"id":51643934}],"con":true,"img":false}]}
{"op":"mcm","clk":"11541166768","pt":1719502949329,"mc":[{"id":"1.230178321","rc":[{"atb":[[2.64,17.27]],"id":61419789},{"atl":[[2.82,0],[2.84,21.57]],"id":51643934}],"con":true,"img":false}]}
{"op":"mcm","clk":"11541166777","pt":1719502949434,"mc":[{"id":"1.230178321","rc":[{"atl":[[7.4,0],[7.6,12.75]],"id":43498435},{"atl":[[4.1,5.08]],"id":61419789},{"atl":[[5,0],[4.9,48.6]],"id":62531723}],"con":true,"img":false}]}
{"op":"mcm","clk":"11541166783","pt":1719502949534,"mc":[{"id":"1.230178321","rc":[{"atl":[[10.5,5],[12.5,10],[9.4,2.5]],"id":43498435},{"atl":[[4.9,0]],"id":61419789}],"con":true,"img":false}]}
{"op":"mcm","clk":"11541166810","pt":1719502949849,"mc":[{"id":"1.230178321","rc":[{"atb":[[1.89,3.7]],"id":51643934}],"con":true,"img":false}]}
{"op":"mcm","clk":"11541166817","pt":1719502949947,"mc":[{"id":"1.230178321","rc":[{"atl":[[4.9,47.64]],"id":62531723},{"atb":[[1.91,2]],"id":51643934}],"con":true,"img":false}]}
{"op":"mcm","clk":"11541166828","pt":1719502950056,"mc":[{"id":"1.230178321","rc":[{"atb":[[3.3,2.5],[2.88,0]],"id":43498435},{"atl":[[4.4,0]],"id":61941199},{"atb":[[1.87,0]],"id":51643934}],"con":true,"img":false}]}
{"op":"mcm","clk":"11541166832","pt":1719502950156,"mc":[{"id":"1.230178321","rc":[{"atl":[[3.95,9.23]],"id":61941199}],"con":true,"img":false}]}
{"op":"mcm","clk":"11541166851","pt":1719502950214,"mc":[{"id":"1.230178321","rc":[{"atl":[[4.9,43.29]],"id":62531723}],"con":true,"img":false}]}
{"op":"mcm","clk":"11541166856","pt":1719502950314,"mc":[{"id":"1.230178321","rc":[{"atl":[[5.7,4.35]],"id":62531723}],"con":true,"img":false}]}
{"op":"mcm","clk":"11541166878","pt":1719502950421,"mc":[{"id":"1.230178321","rc":[{"atb":[[2.06,0]],"id":69176305},{"atb":[[2.62,3.05]],"id":61419789}],"con":true,"img":false}]}
{"op":"mcm","clk":"11541166888","pt":1719502950525,"mc":[{"id":"1.230178321","rc":[{"atb":[[2.24,1.94]],"id":69176305},{"atb":[[2.62,0]],"id":61941199},{"atb":[[2.66,1.94]],"id":61419789}],"con":true,"img":false}]}
{"op":"mcm","clk":"11541166935","pt":1719502950939,"mc":[{"id":"1.230178321","rc":[{"atl":[[4.1,0]],"id":61941199},{"atb":[[3.6,0]],"id":43498435},{"atb":[[2.66,5.96]],"id":61419789},{"atl":[[4.3,0]],"id":61419789},{"atl":[[2.86,0]],"id":51643934}],"con":true,"img":false}]}
{"op":"mcm","clk":"11541166946","pt":1719502951042,"mc":[{"id":"1.230178321","rc":[{"atl":[[4.3,0],[3.9,9.24]],"id":61941199},{"atl":[[5.8,0]],"id":62531723}],"con":true,"img":false}]}
{"op":"mcm","clk":"11541166956","pt":1719502951146,"mc":[{"id":"1.230178321","rc":[{"atl":[[4,25.94]],"id":61941199},{"atb":[[3.75,18.52]],"id":43498435},{"atb":[[2.62,0]],"id":61419789},{"atl":[[3.95,16.57]],"id":61419789},{"atl":[[2.84,26.01]],"id":51643934}],"con":true,"img":false}]}
{"op":"mcm","clk":"11541166988","pt":1719502951559,"mc":[{"id":"1.230178321","rc":[{"atl":[[3.95,8.41]],"id":61941199},{"atb":[[2.18,4.28]],"id":69176305},{"atb":[[2.64,3.5]],"id":61419789}],"con":true,"img":false}]}
{"op":"mcm","clk":"11541167001","pt":1719502951619,"mc":[{"id":"1.230178321","rc":[{"atl":[[2.82,2.54]],"id":51643934}],"con":true,"img":false}]}
{"op":"mcm","clk":"11541167024","pt":1719502951826,"mc":[{"id":"1.230178321","rc":[{"atl":[[3.95,0.84]],"id":61941199}],"con":true,"img":false}]}
{"op":"mcm","clk":"11541167033","pt":1719502951923,"mc":[{"id":"1.230178321","rc":[{"atl":[[3.9,16.81]],"id":61941199},{"atb":[[2.22,2],[2.24,20.78]],"id":69176305},{"atb":[[3.7,12.5]],"id":43498435},{"atb":[[2.64,0]],"id":61419789},{"atb":[[1.89,0]],"id":51643934}],"con":true,"img":false}]}
{"op":"mcm","clk":"11541167041","pt":1719502952028,"mc":[{"id":"1.230178321","rc":[{"atb":[[3.8,4.28]],"id":43498435},{"atb":[[2.24,24.78]],"id":69176305},{"atb":[[2.68,2.85]],"id":61419789},{"atb":[[1.91,5]],"id":51643934}],"con":true,"img":false}]}
{"op":"mcm","clk":"11541167068","pt":1719502952339,"mc":[{"id":"1.230178321","rc":[{"atb":[[3.75,10.42]],"id":43498435},{"atb":[[2.66,8.46]],"id":61419789},{"atl":[[2.8,0.84]],"id":51643934}],"con":true,"img":false}]}
{"op":"mcm","clk":"11541167083","pt":1719502952544,"mc":[{"id":"1.230178321","rc":[{"atl":[[4,29.69]],"id":61941199},{"atb":[[2.68,18.09]],"id":61419789}],"con":true,"img":false}]}
{"op":"mcm","clk":"11541167093","pt":1719502952650,"mc":[{"id":"1.230178321","rc":[{"atl":[[4,25.94]],"id":61941199},{"atb":[[2.18,0]],"id":69176305}],"con":true,"img":false}]}
{"op":"mcm","clk":"11541167118","pt":1719502952954,"mc":[{"id":"1.230178321","rc":[{"atb":[[2.22,0]],"id":69176305}],"con":true,"img":false}]}
{"op":"mcm","clk":"11541167122","pt":1719502953056,"mc":[{"id":"1.230178321","rc":[{"atb":[[2.26,2]],"id":69176305}],"con":true,"img":false}]}
{"op":"mcm","clk":"11541167139","pt":1719502953264,"mc":[{"id":"1.230178321","rc":[{"atb":[[2.24,24.54]],"id":69176305}],"con":true,"img":false}]}
{"op":"mcm","clk":"11541167159","pt":1719502953433,"mc":[{"id":"1.230178321","rc":[{"atb":[[3.75,8.47]],"id":43498435},{"atb":[[2.66,6.52]],"id":61419789}],"con":true,"img":false}]}
{"op":"mcm","clk":"11541167167","pt":1719502953523,"mc":[{"id":"1.230178321","rc":[{"atb":[[3.75,6.47]],"id":43498435}],"con":true,"img":false}]}
{"op":"mcm","clk":"11541167175","pt":1719502953633,"mc":[{"id":"1.230178321","rc":[{"atb":[[3.85,3.94]],"id":43498435},{"atb":[[2.24,5.94]],"id":69176305},{"atb":[[2.7,1.94]],"id":61419789}],"con":true,"img":false}]}
{"op":"mcm","clk":"11541167183","pt":1719502953730,"mc":[{"id":"1.230178321","rc":[{"atb":[[3.8,12.2]],"id":43498435},{"atb":[[2.26,20.6]],"id":69176305}],"con":true,"img":false}]}
{"op":"mcm","clk":"11541167199","pt":1719502953934,"mc":[{"id":"1.230178321","rc":[{"atl":[[2.82,8.2]],"id":51643934}],"con":true,"img":false}]}
{"op":"mcm","clk":"11541167207","pt":1719502954037,"mc":[{"id":"1.230178321","rc":[{"atb":[[3.8,4.28]],"id":43498435},{"atb":[[2.68,17.51]],"id":61419789},{"atl":[[2.84,21.36]],"id":51643934}],"con":true,"img":false}]}
{"op":"mcm","clk":"11541167218","pt":1719502954141,"mc":[{"id":"1.230178321","rc":[{"atl":[[3.9,3.09]],"id":61419789}],"con":true,"img":false}]}
{"op":"mcm","clk":"11541167234","pt":1719502954252,"mc":[{"id":"1.230178321","rc":[{"atb":[[2.68,2.85]],"id":61419789}],"con":true,"img":false}]}
{"op":"mcm","clk":"11541167240","pt":1719502954345,"mc":[{"id":"1.230178321","rc":[{"atb":[[2.7,16.6]],"id":61419789},{"atl":[[3.85,4.8]],"id":61419789}],"con":true,"img":false}]}
{"op":"mcm","clk":"11541167246","pt":1719502954452,"mc":[{"id":"1.230178321","rc":[{"atl":[[3.9,7.55]],"id":61419789}],"con":true,"img":false}]}
{"op":"mcm","clk":"11541167259","pt":1719502954568,"mc":[{"id":"1.230178321","rc":[{"atl":[[4,0],[3.9,6.55]],"id":61419789}],"con":true,"img":false}]}
{"op":"mcm","clk":"11541167266","pt":1719502954659,"mc":[{"id":"1.230178321","rc":[{"atl":[[4.1,0]],"id":61419789}],"con":true,"img":false}]}
{"op":"mcm","clk":"11541167277","pt":1719502954762,"mc":[{"id":"1.230178321","rc":[{"atl":[[4.7,1]],"id":61941199},{"atl":[[3.95,15.5],[3.8,0.84]],"id":61419789},{"atb":[[2.8,31.17]],"id":62531723}],"con":true,"img":false}]}
{"op":"mcm","clk":"11541167293","pt":1719502954867,"mc":[{"id":"1.230178321","rc":[{"atl":[[3.9,4.46]],"id":61419789},{"atb":[[2.88,0]],"id":62531723}],"con":true,"img":false}]}
{"op":"mcm","clk":"11541167298","pt":1719502954966,"mc":[{"id":"1.230178321","rc":[{"atl":[[3.95,7.87]],"id":61419789}],"con":true,"img":false}]}
{"op":"mcm","clk":"11541167306","pt":1719502955064,"mc":[{"id":"1.230178321","rc":[{"atb":[[3.85,11.53]],"id":43498435},{"atl":[[3.85,12.43]],"id":61419789}],"con":true,"img":false}]}
{"op":"mcm","clk":"11541167337","pt":1719502955438,"mc":[{"id":"1.230178321","rc":[{"atl":[[4.2,0]],"id":61419789}],"con":true,"img":false}]}
{"op":"mcm","clk":"11541167362","pt":1719502955736,"mc":[{"id":"1.230178321","rc":[{"atb":[[3.75,0],[3.9,10.76]],"id":43498435},{"atl":[[4,20.8]],"id":61941199},{"atb":[[1.83,10.39]],"id":69176305},{"atl":[[3.95,0]],"id":61419789},{"atl":[[2.84,16.92]],"id":51643934}],"con":true,"img":false}]}
{"op":"mcm","clk":"11541167380","pt":1719502955947,"mc":[{"id":"1.230178321","rc":[{"atb":[[3.85,17.58],[3.7,0]],"id":43498435},{"atl":[[3.9,21.66]],"id":61941199},{"atb":[[2.26,26.04]],"id":69176305},{"atl":[[3.85,20.02]],"id":61419789},{"atl":[[2.82,12.5]],"id":51643934}],"con":true,"img":false}]}
{"op":"mcm","clk":"11541167387","pt":1719502956045,"mc":[{"id":"1.230178321","rc":[{"atb":[[2.66,9.89]],"id":61419789},{"atl":[[2.8,13.35]],"id":51643934}],"con":true,"img":false}]}
{"op":"mcm","clk":"11541167398","pt":1719502956154,"mc":[{"id":"1.230178321","rc":[{"atl":[[2.84,0.84]],"id":51643934}],"con":true,"img":false}]}
{"op":"mcm","clk":"11541167410","pt":1719502956259,"mc":[{"id":"1.230178321","rc":[{"atl":[[3.85,0.84]],"id":61941199}],"con":true,"img":false}]}
{"op":"mcm","clk":"11541167425","pt":1719502956459,"mc":[{"id":"1.230178321","rc":[{"atb":[[2.24,3.99]],"id":69176305},{"atb":[[3.85,6.04]],"id":43498435},{"atl":[[3.8,1.37]],"id":61419789}],"con":true,"img":false}]}
{"op":"mcm","clk":"11541167433","pt":1719502956561,"mc":[{"id":"1.230178321","rc":[{"atb":[[3.95,1.94],[1.02,2]],"id":43498435},{"atl":[[3.75,1]],"id":61419789}],"con":true,"img":false}]}
{"op":"mcm","clk":"11541167445","pt":1719502956662,"mc":[{"id":"1.230178321","rc":[{"atl":[[3.85,10.28]],"id":61941199}],"con":true,"img":false}]}
{"op":"mcm","clk":"11541167459","pt":1719502956773,"mc":[{"id":"1.230178321","rc":[{"atl":[[4,0]],"id":61941199},{"atb":[[3.8,0]],"id":43498435},{"atb":[[2.24,0]],"id":69176305},{"atb":[[2.68,0]],"id":61419789}],"con":true,"img":false}]}
{"op":"mcm","clk":"11541167471","pt":1719502956829,"mc":[{"id":"1.230178321","rc":[{"atb":[[3.95,5.48]],"id":43498435},{"atb":[[2.28,3.29]],"id":69176305},{"atb":[[2.72,4.1]],"id":61419789},{"atl":[[2.84,0]],"id":51643934}],"con":true,"img":false}]}
{"op":"mcm","clk":"11541167502","pt":1719502957146,"mc":[{"id":"1.230178321","rc":[{"atb":[[2.26,7.44]],"id":69176305},{"atl":[[3.9,14.09]],"id":61941199},{"atb":[[2.66,6.52],[2.7,15.91]],"id":61419789},{"atl":[[3.85,12.39]],"id":61419789}],"con":true,"img":false}]}
{"op":"mcm","clk":"11541167525","pt":1719502957340,"mc":[{"id":"1.230178321","rc":[{"atb":[[2.7,1.94]],"id":61419789}],"con":true,"img":false}]}
{"op":"mcm","clk":"11541167533","pt":1719502957438,"mc":[{"id":"1.230178321","rc":[{"atl":[[3.95,0]],"id":61941199},{"atb":[[2.72,18.07],[2.68,6.05]],"id":61419789}],"con":true,"img":false}]}
{"op":"mcm","clk":"11541167545","pt":1719502957548,"mc":[{"id":"1.230178321","rc":[{"atb":[[2.26,5.44]],"id":69176305},{"atb":[[3.95,12.74]],"id":43498435},{"atb":[[2.66,4.02]],"id":61419789}],"con":true,"img":false}]}
{"op":"mcm","clk":"11541167555","pt":1719502957648,"mc":[{"id":"1.230178321","rc":[{"atb":[[2.3,2]],"id":69176305}],"con":true,"img":false}]}
{"op":"mcm","clk":"11541167565","pt":1719502957752,"mc":[{"id":"1.230178321","rc":[{"spl":[[1.01,1]],"id":62531723}],"con":true,"img":false}]}
{"op":"mcm","clk":"11541167583","pt":1719502957952,"mc":[{"id":"1.230178321","rc":[{"atb":[[2.3,20.38]],"id":69176305},{"atl":[[3.85,18.48]],"id":61941199},{"atl":[[3.75,10.16]],"id":61419789}],"con":true,"img":false}]}
{"op":"mcm","clk":"11541167593","pt":1719502958057,"mc":[{"id":"1.230178321","rc":[{"atl":[[3.8,14.09]],"id":61941199}],"con":true,"img":false}]}
{"op":"mcm","clk":"11541167604","pt":1719502958160,"mc":[{"id":"1.230178321","rc":[{"atl":[[3.9,4.85]],"id":61941199}],"con":true,"img":false}]}
