{"op":"mcm","clk":"11536832976","pt":1719431775507,"mc":[{"id":"1.230180115","marketDefinition":{"bspMarket":true,"turnInPlayEnabled":false,"persistenceEnabled":false,"marketBaseRate":5.0,"eventId":"33376437","eventTypeId":"4339","numberOfWinners":2,"bettingType":"ODDS","marketType":"PLACE","marketTime":"2024-06-27T13:52:00.000Z","suspendTime":"2024-06-27T13:52:00.000Z","bspReconciled":false,"complete":true,"inPlay":false,"crossMatching":false,"runnersVoidable":false,"numberOfActiveRunners":6,"betDelay":0,"status":"OPEN","runners":[{"status":"ACTIVE","sortPriority":1,"id":39682601,"name":"1. Lilys Pearl"},{"status":"ACTIVE","sortPriority":2,"id":61150133,"name":"2. Mind The Mud"},{"status":"ACTIVE","sortPriority":3,"id":43289758,"name":"3. Salacres Harry"},{"status":"ACTIVE","sortPriority":4,"id":44213406,"name":"4. Go Bye Baby"},{"status":"ACTIVE","sortPriority":5,"id":41804643,"name":"5. Salacres Harold"},{"status":"ACTIVE","sortPriority":6,"id":63387150,"name":"6. Salacres Dolce"}],"regulators":["MR_INT"],"venue":"Towcester","countryCode":"GB","discountAllowed":false,"timezone":"Europe/London","openDate":"2024-06-27T13:33:00.000Z","version":5994767107,"name":"To Be Placed","eventName":"Towcester 27th Jun"},"rc":[],"con":true,"img":false}]}
{"op":"mcm","clk":"11536833144","pt":1719431777527,"mc":[{"id":"1.230180115","marketDefinition":{"bspMarket":true,"turnInPlayEnabled":false,"persistenceEnabled":false,"marketBaseRate":5.0,"eventId":"33376437","eventTypeId":"4339","numberOfWinners":2,"bettingType":"ODDS","marketType":"PLACE","marketTime":"2024-06-27T13:52:00.000Z","suspendTime":"2024-06-27T13:52:00.000Z","bspReconciled":false,"complete":true,"inPlay":false,"crossMatching":false,"runnersVoidable":false,"numberOfActiveRunners":6,"betDelay":0,"status":"OPEN","runners":[{"status":"ACTIVE","sortPriority":1,"id":39682601,"name":"1. Lilys Pearl"},{"status":"ACTIVE","sortPriority":2,"id":61150133,"name":"2. Mind The Mud"},{"status":"ACTIVE","sortPriority":3,"id":43289758,"name":"3. Salacres Harry"},{"status":"ACTIVE","sortPriority":4,"id":44213406,"name":"4. Go Bye Baby"},{"status":"ACTIVE","sortPriority":5,"id":41804643,"name":"5. Salacres Harold"},{"status":"ACTIVE","sortPriority":6,"id":63387150,"name":"6. Salacres Dolce"}],"regulators":["MR_INT"],"venue":"Towcester","countryCode":"GB","discountAllowed":true,"timezone":"Europe/London","openDate":"2024-06-27T13:33:00.000Z","version":5994767107,"name":"To Be Placed","eventName":"Towcester 27th Jun"},"rc":[],"con":true,"img":false}]}
{"op":"mcm","clk":"11537084050","pt":1719435436293,"mc":[{"id":"1.230180115","rc":[{"atb":[[1.02,25.92]],"id":41804643},{"atl":[[1000,0.84]],"id":41804643},{"spn":500.51,"spf":"NaN","id":41804643},{"atb":[[1.03,17.28]],"id":61150133},{"atl":[[1000,0.84]],"id":61150133},{"spn":500.51,"spf":"NaN","id":61150133},{"atb":[[1.03,17.28]],"id":44213406},{"atl":[[990,0.84]],"id":44213406},{"spn":495.51,"spf":"NaN","id":44213406},{"atb":[[1.03,17.28]],"id":39682601},{"atl":[[990,0.84]],"id":39682601},{"spn":495.51,"spf":"NaN","id":39682601},{"atb":[[1.02,25.92]],"id":63387150},{"atl":[[990,0.84]],"id":63387150},{"spn":495.51,"spf":"NaN","id":63387150},{"atb":[[1.03,17.28]],"id":43289758},{"atl":[[1000,0.84]],"id":43289758},{"spn":500.51,"spf":"NaN","id":43289758}],"con":true,"img":false}]}
{"op":"mcm","clk":"11537233749","pt":1719437882658,"mc":[{"id":"1.230180115","marketDefinition":{"bspMarket":true,"turnInPlayEnabled":false,"persistenceEnabled":false,"marketBaseRate":5.0,"eventId":"33376437","eventTypeId":"4339","numberOfWinners":2,"bettingType":"ODDS","marketType":"PLACE","marketTime":"2024-06-27T13:52:00.000Z","suspendTime":"2024-06-27T13:52:00.000Z","bspReconciled":false,"complete":true,"inPlay":false,"crossMatching":false,"runnersVoidable":false,"numberOfActiveRunners":6,"betDelay":0,"status":"OPEN","runners":[{"status":"ACTIVE","sortPriority":1,"id":39682601,"name":"1. Lilys Pearl"},{"status":"ACTIVE","sortPriority":2,"id":61150133,"name":"2. Mind The Mud"},{"status":"ACTIVE","sortPriority":3,"id":43289758,"name":"3. Salacres Harry"},{"status":"ACTIVE","sortPriority":4,"id":44213406,"name":"4. Go Bye Baby"},{"status":"ACTIVE","sortPriority":5,"id":41804643,"name":"5. Salacres Harold"},{"status":"ACTIVE","sortPriority":6,"id":63387150,"name":"6. Salacres Dolce"}],"regulators":["MR_INT"],"venue":"Towcester","countryCode":"GB","discountAllowed":true,"timezone":"Europe/London","openDate":"2024-06-27T13:33:00.000Z","version":5994767107,"name":"To Be Placed","eventName":"Towcester 27th Jun"},"rc":[{"atb":[[1.02,25.92]],"id":41804643},{"atl":[[1000,0.84]],"id":41804643},{"spn":500.51,"spf":"NaN","id":41804643},{"atb":[[1.03,17.28]],"id":61150133},{"atl":[[1000,0.84]],"id":61150133},{"spn":500.51,"spf":"NaN","id":61150133},{"atb":[[1.03,17.28]],"id":44213406},{"atl":[[990,0.84]],"id":44213406},{"spn":495.51,"spf":"NaN","id":44213406},{"atb":[[1.03,17.28]],"id":39682601},{"atl":[[990,0.84]],"id":39682601},{"spn":495.51,"spf":"NaN","id":39682601},{"atb":[[1.02,25.92]],"id":63387150},{"atl":[[990,0.84]],"id":63387150},{"spn":495.51,"spf":"NaN","id":63387150},{"atb":[[1.03,17.28]],"id":43289758},{"atl":[[1000,0.84]],"id":43289758},{"spn":500.51,"spf":"NaN","id":43289758}],"con":true,"img":true}]}
{"op":"mcm","clk":"11537302630","pt":1719439040960,"mc":[{"id":"1.230180115","rc":[{"atb":[[1.02,25.92]],"id":41804643},{"atl":[[1000,0.23]],"id":41804643},{"atb":[[1.03,17.28]],"id":61150133},{"atl":[[1000,0.23]],"id":61150133},{"atb":[[1.03,17.28]],"id":44213406},{"atl":[[990,0.23]],"id":44213406},{"atb":[[1.03,17.28]],"id":39682601},{"atl":[[990,0.23]],"id":39682601},{"atb":[[1.02,25.92]],"id":63387150},{"atl":[[990,0.23]],"id":63387150},{"atb":[[1.03,17.28]],"id":43289758},{"atl":[[1000,0.23]],"id":43289758}],"con":true,"img":false}]}
{"op":"mcm","clk":"11537574901","pt":1719443282709,"mc":[{"id":"1.230180115","marketDefinition":{"bspMarket":true,"turnInPlayEnabled":false,"persistenceEnabled":false,"marketBaseRate":5.0,"eventId":"33376437","eventTypeId":"4339","numberOfWinners":2,"bettingType":"ODDS","marketType":"PLACE","marketTime":"2024-06-27T13:52:00.000Z","suspendTime":"2024-06-27T13:52:00.000Z","bspReconciled":false,"complete":true,"inPlay":false,"crossMatching":false,"runnersVoidable":false,"numberOfActiveRunners":6,"betDelay":0,"status":"OPEN","runners":[{"status":"ACTIVE","sortPriority":1,"id":39682601,"name":"1. Lilys Pearl"},{"status":"ACTIVE","sortPriority":2,"id":61150133,"name":"2. Mind The Mud"},{"status":"ACTIVE","sortPriority":3,"id":43289758,"name":"3. Salacres Harry"},{"status":"ACTIVE","sortPriority":4,"id":44213406,"name":"4. Go Bye Baby"},{"status":"ACTIVE","sortPriority":5,"id":41804643,"name":"5. Salacres Harold"},{"status":"ACTIVE","sortPriority":6,"id":63387150,"name":"6. Salacres Dolce"}],"regulators":["MR_INT"],"venue":"Towcester","countryCode":"GB","discountAllowed":true,"timezone":"Europe/London","openDate":"2024-06-27T13:33:00.000Z","version":5994767107,"name":"To Be Placed","eventName":"Towcester 27th Jun"},"rc":[{"atb":[[1.02,25.92]],"id":41804643},{"atl":[[1000,0.23]],"id":41804643},{"spn":500.51,"spf":"NaN","id":41804643},{"atb":[[1.03,17.28]],"id":61150133},{"atl":[[1000,0.23]],"id":61150133},{"spn":500.51,"spf":"NaN","id":61150133},{"atb":[[1.03,17.28]],"id":44213406},{"atl":[[990,0.23]],"id":44213406},{"spn":495.51,"spf":"NaN","id":44213406},{"atb":[[1.03,17.28]],"id":39682601},{"atl":[[990,0.23]],"id":39682601},{"spn":495.51,"spf":"NaN","id":39682601},{"atb":[[1.02,25.92]],"id":63387150},{"atl":[[990,0.23]],"id":63387150},{"spn":495.51,"spf":"NaN","id":63387150},{"atb":[[1.03,17.28]],"id":43289758},{"atl":[[1000,0.23]],"id":43289758},{"spn":500.51,"spf":"NaN","id":43289758}],"con":true,"img":true}]}
{"op":"mcm","clk":"11537956521","pt":1719448682750,"mc":[{"id":"1.230180115","marketDefinition":{"bspMarket":true,"turnInPlayEnabled":false,"persistenceEnabled":false,"marketBaseRate":5.0,"eventId":"33376437","eventTypeId":"4339","numberOfWinners":2,"bettingType":"ODDS","marketType":"PLACE","marketTime":"2024-06-27T13:52:00.000Z","suspendTime":"2024-06-27T13:52:00.000Z","bspReconciled":false,"complete":true,"inPlay":false,"crossMatching":false,"runnersVoidable":false,"numberOfActiveRunners":6,"betDelay":0,"status":"OPEN","runners":[{"status":"ACTIVE","sortPriority":1,"id":39682601,"name":"1. Lilys Pearl"},{"status":"ACTIVE","sortPriority":2,"id":61150133,"name":"2. Mind The Mud"},{"status":"ACTIVE","sortPriority":3,"id":43289758,"name":"3. Salacres Harry"},{"status":"ACTIVE","sortPriority":4,"id":44213406,"name":"4. Go Bye Baby"},{"status":"ACTIVE","sortPriority":5,"id":41804643,"name":"5. Salacres Harold"},{"status":"ACTIVE","sortPriority":6,"id":63387150,"name":"6. Salacres Dolce"}],"regulators":["MR_INT"],"venue":"Towcester","countryCode":"GB","discountAllowed":true,"timezone":"Europe/London","openDate":"2024-06-27T13:33:00.000Z","version":5994767107,"name":"To Be Placed","eventName":"Towcester 27th Jun"},"rc":[{"atb":[[1.02,25.92]],"id":41804643},{"atl":[[1000,0.23]],"id":41804643},{"spn":500.51,"spf":"NaN","id":41804643},{"atb":[[1.03,17.28]],"id":61150133},{"atl":[[1000,0.23]],"id":61150133},{"spn":500.51,"spf":"NaN","id":61150133},{"atb":[[1.03,17.28]],"id":44213406},{"atl":[[990,0.23]],"id":44213406},{"spn":495.51,"spf":"NaN","id":44213406},{"atb":[[1.03,17.28]],"id":39682601},{"atl":[[990,0.23]],"id":39682601},{"spn":495.51,"spf":"NaN","id":39682601},{"atb":[[1.02,25.92]],"id":63387150},{"atl":[[990,0.23]],"id":63387150},{"spn":495.51,"spf":"NaN","id":63387150},{"atb":[[1.03,17.28]],"id":43289758},{"atl":[[1000,0.23]],"id":43289758},{"spn":500.51,"spf":"NaN","id":43289758}],"con":true,"img":true}]}
{"op":"mcm","clk":"11538172138","pt":1719454082693,"mc":[{"id":"1.230180115","marketDefinition":{"bspMarket":true,"turnInPlayEnabled":false,"persistenceEnabled":false,"marketBaseRate":5.0,"eventId":"33376437","eventTypeId":"4339","numberOfWinners":2,"bettingType":"ODDS","marketType":"PLACE","marketTime":"2024-06-27T13:52:00.000Z","suspendTime":"2024-06-27T13:52:00.000Z","bspReconciled":false,"complete":true,"inPlay":false,"crossMatching":false,"runnersVoidable":false,"numberOfActiveRunners":6,"betDelay":0,"status":"OPEN","runners":[{"status":"ACTIVE","sortPriority":1,"id":39682601,"name":"1. Lilys Pearl"},{"status":"ACTIVE","sortPriority":2,"id":61150133,"name":"2. Mind The Mud"},{"status":"ACTIVE","sortPriority":3,"id":43289758,"name":"3. Salacres Harry"},{"status":"ACTIVE","sortPriority":4,"id":44213406,"name":"4. Go Bye Baby"},{"status":"ACTIVE","sortPriority":5,"id":41804643,"name":"5. Salacres Harold"},{"status":"ACTIVE","sortPriority":6,"id":63387150,"name":"6. Salacres Dolce"}],"regulators":["MR_INT"],"venue":"Towcester","countryCode":"GB","discountAllowed":true,"timezone":"Europe/London","openDate":"2024-06-27T13:33:00.000Z","version":5994767107,"name":"To Be Placed","eventName":"Towcester 27th Jun"},"rc":[{"atb":[[1.02,25.93]],"id":41804643},{"atl":[[1000,0.23]],"id":41804643},{"spn":500.51,"spf":"NaN","id":41804643},{"atb":[[1.03,17.29]],"id":61150133},{"atl":[[1000,0.23]],"id":61150133},{"spn":500.51,"spf":"NaN","id":61150133},{"atb":[[1.03,17.29]],"id":44213406},{"atl":[[990,0.23]],"id":44213406},{"spn":495.51,"spf":"NaN","id":44213406},{"atb":[[1.03,17.29]],"id":39682601},{"atl":[[990,0.23]],"id":39682601},{"spn":495.51,"spf":"NaN","id":39682601},{"atb":[[1.02,25.93]],"id":63387150},{"atl":[[990,0.23]],"id":63387150},{"spn":495.51,"spf":"NaN","id":63387150},{"atb":[[1.03,17.29]],"id":43289758},{"atl":[[1000,0.23]],"id":43289758},{"spn":500.51,"spf":"NaN","id":43289758}],"con":true,"img":true}]}
{"op":"mcm","clk":"11538369805","pt":1719459482779,"mc":[{"id":"1.230180115","marketDefinition":{"bspMarket":true,"turnInPlayEnabled":false,"persistenceEnabled":false,"marketBaseRate":5.0,"eventId":"33376437","eventTypeId":"4339","numberOfWinners":2,"bettingType":"ODDS","marketType":"PLACE","marketTime":"2024-06-27T13:52:00.000Z","suspendTime":"2024-06-27T13:52:00.000Z","bspReconciled":false,"complete":true,"inPlay":false,"crossMatching":false,"runnersVoidable":false,"numberOfActiveRunners":6,"betDelay":0,"status":"OPEN","runners":[{"status":"ACTIVE","sortPriority":1,"id":39682601,"name":"1. Lilys Pearl"},{"status":"ACTIVE","sortPriority":2,"id":61150133,"name":"2. Mind The Mud"},{"status":"ACTIVE","sortPriority":3,"id":43289758,"name":"3. Salacres Harry"},{"status":"ACTIVE","sortPriority":4,"id":44213406,"name":"4. Go Bye Baby"},{"status":"ACTIVE","sortPriority":5,"id":41804643,"name":"5. Salacres Harold"},{"status":"ACTIVE","sortPriority":6,"id":63387150,"name":"6. Salacres Dolce"}],"regulators":["MR_INT"],"venue":"Towcester","countryCode":"GB","discountAllowed":true,"timezone":"Europe/London","openDate":"2024-06-27T13:33:00.000Z","version":5994767107,"name":"To Be Placed","eventName":"Towcester 27th Jun"},"rc":[{"atb":[[1.02,25.93]],"id":41804643},{"atl":[[1000,0.23]],"id":41804643},{"spn":500.51,"spf":"NaN","id":41804643},{"atb":[[1.03,17.29]],"id":61150133},{"atl":[[1000,0.23]],"id":61150133},{"spn":500.51,"spf":"NaN","id":61150133},{"atb":[[1.03,17.29]],"id":44213406},{"atl":[[990,0.23]],"id":44213406},{"spn":495.51,"spf":"NaN","id":44213406},{"atb":[[1.03,17.29]],"id":39682601},{"atl":[[990,0.23]],"id":39682601},{"spn":495.51,"spf":"NaN","id":39682601},{"atb":[[1.02,25.93]],"id":63387150},{"atl":[[990,0.23]],"id":63387150},{"spn":495.51,"spf":"NaN","id":63387150},{"atb":[[1.03,17.29]],"id":43289758},{"atl":[[1000,0.23]],"id":43289758},{"spn":500.51,"spf":"NaN","id":43289758}],"con":true,"img":true}]}
{"op":"mcm","clk":"11538596935","pt":1719464882722,"mc":[{"id":"1.230180115","marketDefinition":{"bspMarket":true,"turnInPlayEnabled":false,"persistenceEnabled":false,"marketBaseRate":5.0,"eventId":"33376437","eventTypeId":"4339","numberOfWinners":2,"bettingType":"ODDS","marketType":"PLACE","marketTime":"2024-06-27T13:52:00.000Z","suspendTime":"2024-06-27T13:52:00.000Z","bspReconciled":false,"complete":true,"inPlay":false,"crossMatching":false,"runnersVoidable":false,"numberOfActiveRunners":6,"betDelay":0,"status":"OPEN","runners":[{"status":"ACTIVE","sortPriority":1,"id":39682601,"name":"1. Lilys Pearl"},{"status":"ACTIVE","sortPriority":2,"id":61150133,"name":"2. Mind The Mud"},{"status":"ACTIVE","sortPriority":3,"id":43289758,"name":"3. Salacres Harry"},{"status":"ACTIVE","sortPriority":4,"id":44213406,"name":"4. Go Bye Baby"},{"status":"ACTIVE","sortPriority":5,"id":41804643,"name":"5. Salacres Harold"},{"status":"ACTIVE","sortPriority":6,"id":63387150,"name":"6. Salacres Dolce"}],"regulators":["MR_INT"],"venue":"Towcester","countryCode":"GB","discountAllowed":true,"timezone":"Europe/London","openDate":"2024-06-27T13:33:00.000Z","version":5994767107,"name":"To Be Placed","eventName":"Towcester 27th Jun"},"rc":[{"atb":[[1.02,25.93]],"id":41804643},{"atl":[[1000,0.23]],"id":41804643},{"spn":500.51,"spf":"NaN","id":41804643},{"atb":[[1.03,17.29]],"id":61150133},{"atl":[[1000,0.23]],"id":61150133},{"spn":500.51,"spf":"NaN","id":61150133},{"atb":[[1.03,17.29]],"id":44213406},{"atl":[[990,0.23]],"id":44213406},{"spn":495.51,"spf":"NaN","id":44213406},{"atb":[[1.03,17.29]],"id":39682601},{"atl":[[990,0.23]],"id":39682601},{"spn":495.51,"spf":"NaN","id":39682601},{"atb":[[1.02,25.93]],"id":63387150},{"atl":[[990,0.23]],"id":63387150},{"spn":495.51,"spf":"NaN","id":63387150},{"atb":[[1.03,17.29]],"id":43289758},{"atl":[[1000,0.23]],"id":43289758},{"spn":500.51,"spf":"NaN","id":43289758}],"con":true,"img":true}]}
{"op":"mcm","clk":"11538906785","pt":1719471499517,"mc":[{"id":"1.230180115","rc":[{"atb":[[1.02,25.93],[1.07,2.48]],"id":41804643},{"atl":[[1000,1.23]],"id":41804643},{"spn":500.53,"spf":"NaN","id":41804643},{"atb":[[1.03,17.29],[1.07,2.48]],"id":61150133},{"atl":[[1000,1.23]],"id":61150133},{"spn":500.53,"spf":"NaN","id":61150133},{"atb":[[1.03,17.29],[1.07,2.48]],"id":44213406},{"atl":[[1000,1]],"id":44213406},{"spn":495.53,"spf":"NaN","id":44213406},{"atb":[[1.03,17.29],[1.07,2.48]],"id":39682601},{"atl":[[1000,1]],"id":39682601},{"spn":495.53,"spf":"NaN","id":39682601},{"atb":[[1.02,25.93],[1.07,2.48]],"id":63387150},{"atl":[[1000,1]],"id":63387150},{"spn":495.53,"spf":"NaN","id":63387150},{"atb":[[1.03,17.29],[1.07,2.48]],"id":43289758},{"atl":[[1000,1.23]],"id":43289758},{"spn":500.53,"spf":"NaN","id":43289758}],"con":true,"img":false}]}
{"op":"mcm","clk":"11538906798","pt":1719471499718,"mc":[{"id":"1.230180115","rc":[{"atl":[[1000,0.71]],"id":41804643},{"atl":[[1000,0.71]],"id":61150133},{"atl":[[1000,0.48]],"id":44213406},{"atl":[[1000,0.48]],"id":39682601},{"atl":[[1000,0.48]],"id":63387150},{"atl":[[1000,0.71]],"id":43289758}],"con":true,"img":false}]}
{"op":"mcm","clk":"11538906809","pt":1719471499924,"mc":[{"id":"1.230180115","rc":[{"atl":[[1000,0.23]],"id":41804643},{"atl":[[1000,0.23]],"id":61150133},{"atl":[[1000,0]],"id":44213406},{"atl":[[1000,0]],"id":39682601},{"atl":[[1000,0]],"id":63387150},{"atl":[[1000,0.23]],"id":43289758}],"con":true,"img":false}]}
{"op":"mcm","clk":"11538906815","pt":1719471499981,"mc":[{"id":"1.230180115","rc":[{"atl":[[75,0.48]],"id":41804643},{"atl":[[75,0.48]],"id":61150133},{"atl":[[75,0.48]],"id":44213406},{"atl":[[75,0.48]],"id":39682601},{"atl":[[75,0.48]],"id":63387150},{"atl":[[75,0.48]],"id":43289758}],"con":true,"img":false}]}
{"op":"mcm","clk":"11539124123","pt":1719475682709,"mc":[{"id":"1.230180115","marketDefinition":{"bspMarket":true,"turnInPlayEnabled":false,"persistenceEnabled":false,"marketBaseRate":5.0,"eventId":"33376437","eventTypeId":"4339","numberOfWinners":2,"bettingType":"ODDS","marketType":"PLACE","marketTime":"2024-06-27T13:52:00.000Z","suspendTime":"2024-06-27T13:52:00.000Z","bspReconciled":false,"complete":true,"inPlay":false,"crossMatching":false,"runnersVoidable":false,"numberOfActiveRunners":6,"betDelay":0,"status":"OPEN","runners":[{"status":"ACTIVE","sortPriority":1,"id":39682601,"name":"1. Lilys Pearl"},{"status":"ACTIVE","sortPriority":2,"id":61150133,"name":"2. Mind The Mud"},{"status":"ACTIVE","sortPriority":3,"id":43289758,"name":"3. Salacres Harry"},{"status":"ACTIVE","sortPriority":4,"id":44213406,"name":"4. Go Bye Baby"},{"status":"ACTIVE","sortPriority":5,"id":41804643,"name":"5. Salacres Harold"},{"status":"ACTIVE","sortPriority":6,"id":63387150,"name":"6. Salacres Dolce"}],"regulators":["MR_INT"],"venue":"Towcester","countryCode":"GB","discountAllowed":true,"timezone":"Europe/London","openDate":"2024-06-27T13:33:00.000Z","version":5994767107,"name":"To Be Placed","eventName":"Towcester 27th Jun"},"rc":[{"atb":[[1.02,25.92],[1.07,2.48]],"id":41804643},{"atl":[[75,0.48],[1000,0.23]],"id":41804643},{"spn":38.03,"spf":"NaN","id":41804643},{"atb":[[1.03,17.28],[1.07,2.48]],"id":61150133},{"atl":[[75,0.48],[1000,0.23]],"id":61150133},{"spn":38.03,"spf":"NaN","id":61150133},{"atb":[[1.03,17.28],[1.07,2.48]],"id":44213406},{"atl":[[75,0.48],[990,0.23]],"id":44213406},{"spn":38.03,"spf":"NaN","id":44213406},{"atb":[[1.03,17.28],[1.07,2.48]],"id":39682601},{"atl":[[75,0.48],[990,0.23]],"id":39682601},{"spn":38.03,"spf":"NaN","id":39682601},{"atb":[[1.02,25.92],[1.07,2.48]],"id":63387150},{"atl":[[75,0.48],[990,0.23]],"id":63387150},{"spn":38.03,"spf":"NaN","id":63387150},{"atb":[[1.03,17.28],[1.07,2.48]],"id":43289758},{"atl":[[75,0.48],[1000,0.23]],"id":43289758},{"spn":38.03,"spf":"NaN","id":43289758}],"con":true,"img":true}]}
{"op":"mcm","clk":"11539440236","pt":1719481082682,"mc":[{"id":"1.230180115","marketDefinition":{"bspMarket":true,"turnInPlayEnabled":false,"persistenceEnabled":false,"marketBaseRate":5.0,"eventId":"33376437","eventTypeId":"4339","numberOfWinners":2,"bettingType":"ODDS","marketType":"PLACE","marketTime":"2024-06-27T13:52:00.000Z","suspendTime":"2024-06-27T13:52:00.000Z","bspReconciled":false,"complete":true,"inPlay":false,"crossMatching":false,"runnersVoidable":false,"numberOfActiveRunners":6,"betDelay":0,"status":"OPEN","runners":[{"status":"ACTIVE","sortPriority":1,"id":39682601,"name":"1. Lilys Pearl"},{"status":"ACTIVE","sortPriority":2,"id":61150133,"name":"2. Mind The Mud"},{"status":"ACTIVE","sortPriority":3,"id":43289758,"name":"3. Salacres Harry"},{"status":"ACTIVE","sortPriority":4,"id":44213406,"name":"4. Go Bye Baby"},{"status":"ACTIVE","sortPriority":5,"id":41804643,"name":"5. Salacres Harold"},{"status":"ACTIVE","sortPriority":6,"id":63387150,"name":"6. Salacres Dolce"}],"regulators":["MR_INT"],"venue":"Towcester","countryCode":"GB","discountAllowed":true,"timezone":"Europe/London","openDate":"2024-06-27T13:33:00.000Z","version":5994767107,"name":"To Be Placed","eventName":"Towcester 27th Jun"},"rc":[{"atb":[[1.02,25.91],[1.07,2.48]],"id":41804643},{"atl":[[75,0.48],[1000,0.23]],"id":41804643},{"spn":38.03,"spf":"NaN","id":41804643},{"atb":[[1.03,17.28],[1.07,2.48]],"id":61150133},{"atl":[[75,0.48],[1000,0.23]],"id":61150133},{"spn":38.03,"spf":"NaN","id":61150133},{"atb":[[1.03,17.28],[1.07,2.48]],"id":44213406},{"atl":[[75,0.48],[990,0.23]],"id":44213406},{"spn":38.03,"spf":"NaN","id":44213406},{"atb":[[1.03,17.28],[1.07,2.48]],"id":39682601},{"atl":[[75,0.48],[990,0.23]],"id":39682601},{"spn":38.03,"spf":"NaN","id":39682601},{"atb":[[1.02,25.91],[1.07,2.48]],"id":63387150},{"atl":[[75,0.48],[990,0.23]],"id":63387150},{"spn":38.03,"spf":"NaN","id":63387150},{"atb":[[1.03,17.28],[1.07,2.48]],"id":43289758},{"atl":[[75,0.48],[1000,0.23]],"id":43289758},{"spn":38.03,"spf":"NaN","id":43289758}],"con":true,"img":true}]}
{"op":"mcm","clk":"11540158716","pt":1719490624207,"mc":[{"id":"1.230180115","marketDefinition":{"bspMarket":true,"turnInPlayEnabled":false,"persistenceEnabled":false,"marketBaseRate":5.0,"eventId":"33376437","eventTypeId":"4339","numberOfWinners":2,"bettingType":"ODDS","marketType":"PLACE","marketTime":"2024-06-27T13:52:00.000Z","suspendTime":"2024-06-27T13:52:00.000Z","bspReconciled":false,"complete":true,"inPlay":false,"crossMatching":false,"runnersVoidable":false,"numberOfActiveRunners":6,"betDelay":0,"status":"SUSPENDED","runners":[{"status":"ACTIVE","sortPriority":1,"id":39682601,"name":"1. Lilys Pearl"},{"status":"ACTIVE","sortPriority":2,"id":61150133,"name":"2. Mind The Mud"},{"status":"ACTIVE","sortPriority":3,"id":43289758,"name":"3. Salacres Harry"},{"status":"ACTIVE","sortPriority":4,"id":44213406,"name":"4. Go Bye Baby"},{"status":"ACTIVE","sortPriority":5,"id":41804643,"name":"5. Salacres Harold"},{"status":"ACTIVE","sortPriority":6,"id":63387150,"name":"6. Salacres Dolce"}],"regulators":["MR_INT"],"venue":"Towcester","countryCode":"GB","discountAllowed":true,"timezone":"Europe/London","openDate":"2024-06-27T13:33:00.000Z","version":5995359784,"name":"To Be Placed","eventName":"Towcester 27th Jun"},"rc":[],"con":true,"img":false}]}
{"op":"mcm","clk":"11540158716","pt":1719490624207,"mc":[{"id":"1.230180115","rc":[{"atb":[[1.02,0],[1.07,0]],"id":41804643},{"atl":[[75,0],[1000,0]],"id":41804643},{"atb":[[1.03,0],[1.07,0]],"id":61150133},{"atl":[[75,0],[1000,0]],"id":61150133},{"atb":[[1.03,0],[1.07,0]],"id":44213406},{"atl":[[75,0],[990,0]],"id":44213406},{"atb":[[1.03,0],[1.07,0]],"id":39682601},{"atl":[[75,0],[990,0]],"id":39682601},{"atb":[[1.02,0],[1.07,0]],"id":63387150},{"atl":[[75,0],[990,0]],"id":63387150},{"atb":[[1.03,0],[1.07,0]],"id":43289758},{"atl":[[75,0],[1000,0]],"id":43289758}],"con":true,"img":false}]}
{"op":"mcm","clk":"11540158771","pt":1719490624818,"mc":[{"id":"1.230180115","marketDefinition":{"bspMarket":true,"turnInPlayEnabled":false,"persistenceEnabled":false,"marketBaseRate":5.0,"eventId":"33376437","eventTypeId":"4339","numberOfWinners":2,"bettingType":"ODDS","marketType":"PLACE","marketTime":"2024-06-27T13:52:00.000Z","suspendTime":"2024-06-27T13:52:00.000Z","bspReconciled":false,"complete":true,"inPlay":false,"crossMatching":false,"runnersVoidable":false,"numberOfActiveRunners":5,"betDelay":0,"status":"OPEN","runners":[{"status":"ACTIVE","sortPriority":1,"id":39682601,"name":"1. Lilys Pearl"},{"status":"ACTIVE","sortPriority":2,"id":61150133,"name":"2. Mind The Mud"},{"status":"ACTIVE","sortPriority":3,"id":44213406,"name":"4. Go Bye Baby"},{"status":"ACTIVE","sortPriority":4,"id":41804643,"name":"5. Salacres Harold"},{"status":"ACTIVE","sortPriority":5,"id":63387150,"name":"6. Salacres Dolce"},{"status":"REMOVED","sortPriority":6,"removalDate":"2024-06-27T12:17:04.000Z","id":43289758,"name":"3. Salacres Harry"}],"regulators":["MR_INT"],"venue":"Towcester","countryCode":"GB","discountAllowed":true,"timezone":"Europe/London","openDate":"2024-06-27T13:33:00.000Z","version":5995359800,"name":"To Be Placed","eventName":"Towcester 27th Jun"},"rc":[],"con":true,"img":false}]}
{"op":"mcm","clk":"11540162485","pt":1719490670052,"mc":[{"id":"1.230180115","rc":[{"atb":[[1.01,102.04]],"id":41804643},{"atb":[[1.01,102.04]],"id":61150133},{"atb":[[1.01,102.04]],"id":44213406},{"atb":[[1.01,102.04]],"id":39682601}],"con":true,"img":false}]}
{"op":"mcm","clk":"11540162493","pt":1719490670153,"mc":[{"id":"1.230180115","rc":[{"atb":[[1.01,102.04]],"id":63387150}],"con":true,"img":false}]}
{"op":"mcm","clk":"11540249585","pt":1719491882662,"mc":[{"id":"1.230180115","marketDefinition":{"bspMarket":true,"turnInPlayEnabled":false,"persistenceEnabled":false,"marketBaseRate":5.0,"eventId":"33376437","eventTypeId":"4339","numberOfWinners":2,"bettingType":"ODDS","marketType":"PLACE","marketTime":"2024-06-27T13:52:00.000Z","suspendTime":"2024-06-27T13:52:00.000Z","bspReconciled":false,"complete":true,"inPlay":false,"crossMatching":false,"runnersVoidable":false,"numberOfActiveRunners":5,"betDelay":0,"status":"OPEN","runners":[{"status":"ACTIVE","sortPriority":1,"id":39682601,"name":"1. Lilys Pearl"},{"status":"ACTIVE","sortPriority":2,"id":61150133,"name":"2. Mind The Mud"},{"status":"ACTIVE","sortPriority":3,"id":44213406,"name":"4. Go Bye Baby"},{"status":"ACTIVE","sortPriority":4,"id":41804643,"name":"5. Salacres Harold"},{"status":"ACTIVE","sortPriority":5,"id":63387150,"name":"6. Salacres Dolce"},{"status":"REMOVED","sortPriority":6,"removalDate":"2024-06-27T12:17:04.000Z","id":43289758,"name":"3. Salacres Harry"}],"regulators":["MR_INT"],"venue":"Towcester","countryCode":"GB","discountAllowed":true,"timezone":"Europe/London","openDate":"2024-06-27T13:33:00.000Z","version":5995359800,"name":"To Be Placed","eventName":"Towcester 27th Jun"},"rc":[{"atb":[[1.01,102.04]],"id":41804643},{"spn":"Infinity","spf":"NaN","id":41804643},{"atb":[[1.01,102.04]],"id":61150133},{"spn":"Infinity","spf":"NaN","id":61150133},{"atb":[[1.01,102.04]],"id":44213406},{"spn":"Infinity","spf":"NaN","id":44213406},{"atb":[[1.01,102.04]],"id":39682601},{"spn":"Infinity","spf":"NaN","id":39682601},{"atb":[[1.01,102.04]],"id":63387150},{"spn":"Infinity","spf":"NaN","id":63387150}],"con":true,"img":true}]}
{"op":"mcm","clk":"11540325288","pt":1719493032924,"mc":[{"id":"1.230180115","rc":[{"atb":[[1.01,118.97]],"id":41804643},{"atl":[[990,0.84]],"id":41804643},{"spn":495.5,"spf":"NaN","id":41804643},{"atb":[[1.01,118.97]],"id":61150133},{"atl":[[1000,0.84]],"id":61150133},{"spn":500.5,"spf":"NaN","id":61150133},{"atb":[[1.02,8.46]],"id":44213406},{"atl":[[1000,0.84]],"id":44213406},{"spn":500.51,"spf":"NaN","id":44213406},{"atb":[[1.02,8.46]],"id":39682601},{"atl":[[990,0.84]],"id":39682601},{"spn":495.51,"spf":"NaN","id":39682601},{"atb":[[1.03,5.64]],"id":63387150},{"atl":[[1000,0.84]],"id":63387150},{"spn":500.51,"spf":"NaN","id":63387150}],"con":true,"img":false}]}
{"op":"mcm","clk":"11540446211","pt":1719494602765,"mc":[{"id":"1.230180115","rc":[{"atb":[[1.01,118.99]],"id":41804643},{"atl":[[990,0.84]],"id":41804643},{"atb":[[1.01,118.99]],"id":61150133},{"atl":[[1000,0.84]],"id":61150133},{"atb":[[1.02,8.47],[1.04,105.86]],"id":44213406},{"atl":[[1000,0.84]],"id":44213406},{"spn":500.52,"spf":"NaN","id":44213406},{"atb":[[1.02,8.47]],"id":39682601},{"atl":[[990,0.84]],"id":39682601},{"atb":[[1.03,5.64]],"id":63387150},{"atl":[[1000,0.84]],"id":63387150}],"con":true,"img":false}]}
{"op":"mcm","clk":"11540446230","pt":1719494602970,"mc":[{"id":"1.230180115","rc":[{"atb":[[1.03,141.16]],"id":61150133}],"con":true,"img":false}]}
{"op":"mcm","clk":"11540446238","pt":1719494603073,"mc":[{"id":"1.230180115","rc":[{"atb":[[1.04,105.86]],"id":39682601}],"con":true,"img":false}]}
{"op":"mcm","clk":"11540446290","pt":1719494603654,"mc":[{"id":"1.230180115","rc":[{"atb":[[1.03,141.16]],"id":41804643},{"atb":[[1.05,84.69]],"id":63387150}],"con":true,"img":false}]}
{"op":"mcm","clk":"11540446971","pt":1719494611398,"mc":[{"id":"1.230180115","rc":[{"atb":[[1.05,110.61]],"id":39682601},{"atb":[[1.06,92.17]],"id":63387150}],"con":true,"img":false}]}
{"op":"mcm","clk":"11540446994","pt":1719494611596,"mc":[{"id":"1.230180115","rc":[{"atb":[[1.05,110.61]],"id":44213406}],"con":true,"img":false}]}
{"op":"mcm","clk":"11540447986","pt":1719494622779,"mc":[{"id":"1.230180115","marketDefinition":{"bspMarket":true,"turnInPlayEnabled":false,"persistenceEnabled":false,"marketBaseRate":5.0,"eventId":"33376437","eventTypeId":"4339","numberOfWinners":2,"bettingType":"ODDS","marketType":"PLACE","marketTime":"2024-06-27T13:52:00.000Z","suspendTime":"2024-06-27T13:52:00.000Z","bspReconciled":false,"complete":true,"inPlay":false,"crossMatching":true,"runnersVoidable":false,"numberOfActiveRunners":5,"betDelay":0,"status":"OPEN","runners":[{"status":"ACTIVE","sortPriority":1,"id":39682601,"name":"1. Lilys Pearl"},{"status":"ACTIVE","sortPriority":2,"id":61150133,"name":"2. Mind The Mud"},{"status":"ACTIVE","sortPriority":3,"id":44213406,"name":"4. Go Bye Baby"},{"status":"ACTIVE","sortPriority":4,"id":41804643,"name":"5. Salacres Harold"},{"status":"ACTIVE","sortPriority":5,"id":63387150,"name":"6. Salacres Dolce"},{"status":"REMOVED","sortPriority":6,"removalDate":"2024-06-27T12:17:04.000Z","id":43289758,"name":"3. Salacres Harry"}],"regulators":["MR_INT"],"venue":"Towcester","countryCode":"GB","discountAllowed":true,"timezone":"Europe/London","openDate":"2024-06-27T13:33:00.000Z","version":5995359800,"name":"To Be Placed","eventName":"Towcester 27th Jun"},"rc":[],"con":true,"img":false}]}
{"op":"mcm","clk":"11540451722","pt":1719494666957,"mc":[{"id":"1.230180115","rc":[{"spn":495.51,"spf":"NaN","id":41804643},{"atb":[[1.05,79]],"id":61150133},{"spn":500.52,"spf":"NaN","id":61150133},{"spn":500.52,"spf":"NaN","id":44213406},{"spn":495.52,"spf":"NaN","id":39682601},{"spn":500.53,"spf":"NaN","id":63387150}],"con":true,"img":false}]}
{"op":"mcm","clk":"11540451729","pt":1719494667060,"mc":[{"id":"1.230180115","rc":[{"atb":[[1.06,65.83]],"id":39682601}],"con":true,"img":false}]}
{"op":"mcm","clk":"11540451738","pt":1719494667161,"mc":[{"id":"1.230180115","rc":[{"atb":[[1.05,79]],"id":41804643}],"con":true,"img":false}]}
{"op":"mcm","clk":"11540451746","pt":1719494667265,"mc":[{"id":"1.230180115","rc":[{"atb":[[1.06,65.83]],"id":44213406}],"con":true,"img":false}]}
{"op":"mcm","clk":"11540451763","pt":1719494667478,"mc":[{"id":"1.230180115","rc":[{"atb":[[1.07,56.43]],"id":63387150}],"con":true,"img":false}]}
{"op":"mcm","clk":"11540452177","pt":1719494671839,"mc":[{"id":"1.230180115","rc":[{"atb":[[1.07,84.69]],"id":39682601}],"con":true,"img":false}]}
{"op":"mcm","clk":"11540452200","pt":1719494672041,"mc":[{"id":"1.230180115","rc":[{"atb":[[1.06,98.81]],"id":61150133}],"con":true,"img":false}]}
{"op":"mcm","clk":"11540452212","pt":1719494672151,"mc":[{"id":"1.230180115","rc":[{"atb":[[1.08,74.1]],"id":63387150}],"con":true,"img":false}]}
{"op":"mcm","clk":"11540452232","pt":1719494672355,"mc":[{"id":"1.230180115","rc":[{"atb":[[1.06,98.81]],"id":41804643}],"con":true,"img":false}]}
{"op":"mcm","clk":"11540452242","pt":1719494672461,"mc":[{"id":"1.230180115","rc":[{"atb":[[1.04,0]],"id":39682601}],"con":true,"img":false}]}
{"op":"mcm","clk":"11540452266","pt":1719494672773,"mc":[{"id":"1.230180115","rc":[{"atb":[[1.04,0]],"id":44213406}],"con":true,"img":false}]}
{"op":"mcm","clk":"11540452278","pt":1719494672881,"mc":[{"id":"1.230180115","rc":[{"atb":[[1.03,0]],"id":61150133}],"con":true,"img":false}]}
{"op":"mcm","clk":"11540452297","pt":1719494673033,"mc":[{"id":"1.230180115","rc":[{"atb":[[1.05,0]],"id":63387150}],"con":true,"img":false}]}
{"op":"mcm","clk":"11540452306","pt":1719494673142,"mc":[{"id":"1.230180115","rc":[{"atb":[[1.07,84.69]],"id":44213406}],"con":true,"img":false}]}
{"op":"mcm","clk":"11540452416","pt":1719494674436,"mc":[{"id":"1.230180115","rc":[{"atb":[[1.03,0]],"id":41804643}],"con":true,"img":false}]}
{"op":"mcm","clk":"11540452435","pt":1719494674748,"mc":[{"id":"1.230180115","rc":[{"atb":[[1.08,52.93]],"id":39682601}],"con":true,"img":false}]}
{"op":"mcm","clk":"11540452484","pt":1719494675269,"mc":[{"id":"1.230180115","rc":[{"atb":[[1.08,52.93]],"id":44213406},{"atb":[[1.09,47.05]],"id":63387150}],"con":true,"img":false}]}
{"op":"mcm","clk":"11540452515","pt":1719494675683,"mc":[{"id":"1.230180115","rc":[{"atb":[[1.07,60.49]],"id":61150133}],"con":true,"img":false}]}
{"op":"mcm","clk":"11540452535","pt":1719494675961,"mc":[{"id":"1.230180115","rc":[{"atb":[[1.07,60.49]],"id":41804643}],"con":true,"img":false}]}
{"op":"mcm","clk":"11540453565","pt":1719494687797,"mc":[{"id":"1.230180115","rc":[{"atb":[[1.05,0]],"id":39682601}],"con":true,"img":false}]}
{"op":"mcm","clk":"11540453579","pt":1719494687896,"mc":[{"id":"1.230180115","rc":[{"atb":[[1.08,69.13]],"id":41804643}],"con":true,"img":false}]}
{"op":"mcm","clk":"11540453601","pt":1719494688103,"mc":[{"id":"1.230180115","rc":[{"atb":[[1.05,0]],"id":44213406}],"con":true,"img":false}]}
{"op":"mcm","clk":"11540453650","pt":1719494688591,"mc":[{"id":"1.230180115","rc":[{"atb":[[1.06,0]],"id":63387150}],"con":true,"img":false}]}
{"op":"mcm","clk":"11540453669","pt":1719494688800,"mc":[{"id":"1.230180115","rc":[{"atb":[[1.09,61.45]],"id":44213406},{"atb":[[1.06,0]],"id":39682601}],"con":true,"img":false}]}
{"op":"mcm","clk":"11540453684","pt":1719494689006,"mc":[{"id":"1.230180115","rc":[{"atb":[[1.05,0],[1.08,69.13]],"id":61150133}],"con":true,"img":false}]}
{"op":"mcm","clk":"11540453704","pt":1719494689159,"mc":[{"id":"1.230180115","rc":[{"atb":[[1.09,61.45]],"id":39682601}],"con":true,"img":false}]}
{"op":"mcm","clk":"11540453721","pt":1719494689366,"mc":[{"id":"1.230180115","rc":[{"atb":[[1.1,39.5]],"id":39682601}],"con":true,"img":false}]}
{"op":"mcm","clk":"11540453739","pt":1719494689577,"mc":[{"id":"1.230180115","rc":[{"atb":[[1.1,55.3]],"id":63387150}],"con":true,"img":false}]}
{"op":"mcm","clk":"11540453758","pt":1719494689777,"mc":[{"id":"1.230180115","rc":[{"atb":[[1.07,0]],"id":63387150}],"con":true,"img":false}]}
{"op":"mcm","clk":"11540453774","pt":1719494689991,"mc":[{"id":"1.230180115","rc":[{"atb":[[1.09,43.89]],"id":61150133}],"con":true,"img":false}]}
{"op":"mcm","clk":"11540453804","pt":1719494690304,"mc":[{"id":"1.230180115","rc":[{"atb":[[1.05,0]],"id":41804643}],"con":true,"img":false}]}
{"op":"mcm","clk":"11540453825","pt":1719494690506,"mc":[{"id":"1.230180115","rc":[{"atb":[[1.06,0]],"id":44213406}],"con":true,"img":false}]}
{"op":"mcm","clk":"11540453872","pt":1719494690973,"mc":[{"id":"1.230180115","rc":[{"atb":[[1.09,43.89]],"id":41804643},{"atb":[[1.1,39.5]],"id":44213406}],"con":true,"img":false}]}
{"op":"mcm","clk":"11540453885","pt":1719494691180,"mc":[{"id":"1.230180115","rc":[{"atb":[[1.11,35.9]],"id":63387150}],"con":true,"img":false}]}
{"op":"mcm","clk":"11540456258","pt":1719494719017,"mc":[{"id":"1.230180115","rc":[{"atb":[[1.06,0]],"id":61150133},{"atb":[[1.07,0]],"id":39682601}],"con":true,"img":false}]}
{"op":"mcm","clk":"11540456279","pt":1719494719326,"mc":[{"id":"1.230180115","rc":[{"atb":[[1.06,0]],"id":41804643},{"atb":[[1.08,0]],"id":63387150}],"con":true,"img":false}]}
{"op":"mcm","clk":"11540456305","pt":1719494719631,"mc":[{"id":"1.230180115","rc":[{"atb":[[1.08,0],[1.07,0]],"id":44213406}],"con":true,"img":false}]}
{"op":"mcm","clk":"11540456331","pt":1719494719938,"mc":[{"id":"1.230180115","rc":[{"atb":[[1.07,0]],"id":61150133}],"con":true,"img":false}]}
{"op":"mcm","clk":"11540456340","pt":1719494720046,"mc":[{"id":"1.230180115","rc":[{"atb":[[1.08,0]],"id":39682601}],"con":true,"img":false}]}
{"op":"mcm","clk":"11540456367","pt":1719494720308,"mc":[{"id":"1.230180115","rc":[{"atb":[[1.07,0]],"id":41804643}],"con":true,"img":false}]}
{"op":"mcm","clk":"11540456440","pt":1719494721238,"mc":[{"id":"1.230180115","rc":[{"atb":[[1.09,0]],"id":63387150}],"con":true,"img":false}]}
{"op":"mcm","clk":"11540456539","pt":1719494722526,"mc":[{"id":"1.230180115","rc":[{"atb":[[1.11,53.9]],"id":39682601},{"atb":[[1.12,49.4]],"id":63387150}],"con":true,"img":false}]}
{"op":"mcm","clk":"11540456558","pt":1719494722833,"mc":[{"id":"1.230180115","rc":[{"atb":[[1.1,59.28]],"id":61150133},{"atb":[[1.12,35.29]],"id":44213406}],"con":true,"img":false}]}
{"op":"mcm","clk":"11540456583","pt":1719494723143,"mc":[{"id":"1.230180115","rc":[{"atb":[[1.11,38.49],[1.1,59.28]],"id":41804643}],"con":true,"img":false}]}
{"op":"mcm","clk":"11540456627","pt":1719494723629,"mc":[{"id":"1.230180115","rc":[{"atb":[[1.11,53.9]],"id":44213406}],"con":true,"img":false}]}
{"op":"mcm","clk":"11540456634","pt":1719494723716,"mc":[{"id":"1.230180115","rc":[{"atb":[[1.12,35.29]],"id":39682601}],"con":true,"img":false}]}
{"op":"mcm","clk":"11540456652","pt":1719494723923,"mc":[{"id":"1.230180115","rc":[{"atb":[[1.11,38.49]],"id":61150133}],"con":true,"img":false}]}
{"op":"mcm","clk":"11540456743","pt":1719494725019,"mc":[{"id":"1.230180115","rc":[{"atb":[[1.13,32.57]],"id":63387150}],"con":true,"img":false}]}
{"op":"mcm","clk":"11540457559","pt":1719494735628,"mc":[{"id":"1.230180115","rc":[{"spn":495.55,"spf":"NaN","id":41804643},{"atb":[[1.08,0]],"id":61150133},{"spn":500.55,"spf":"NaN","id":61150133},{"spn":500.56,"spf":"NaN","id":44213406},{"atb":[[1.09,0]],"id":39682601},{"spn":495.56,"spf":"NaN","id":39682601},{"spn":500.56,"spf":"NaN","id":63387150}],"con":true,"img":false}]}
{"op":"mcm","clk":"11540457575","pt":1719494735837,"mc":[{"id":"1.230180115","rc":[{"atb":[[1.08,0]],"id":41804643},{"atb":[[1.1,0]],"id":63387150}],"con":true,"img":false}]}
{"op":"mcm","clk":"11540457596","pt":1719494736046,"mc":[{"id":"1.230180115","rc":[{"atb":[[1.09,0]],"id":44213406},{"atb":[[1.1,0]],"id":39682601}],"con":true,"img":false}]}
{"op":"mcm","clk":"11540457623","pt":1719494736361,"mc":[{"id":"1.230180115","rc":[{"atb":[[1.1,0]],"id":44213406}],"con":true,"img":false}]}
{"op":"mcm","clk":"11540457653","pt":1719494736620,"mc":[{"id":"1.230180115","rc":[{"atb":[[1.09,0]],"id":41804643},{"atb":[[1.11,0]],"id":63387150}],"con":true,"img":false}]}
{"op":"mcm","clk":"11540457680","pt":1719494736935,"mc":[{"id":"1.230180115","rc":[{"atb":[[1.09,0]],"id":61150133}],"con":true,"img":false}]}
{"op":"mcm","clk":"11540457750","pt":1719494737758,"mc":[{"id":"1.230180115","rc":[{"atb":[[1.12,46.08]],"id":61150133}],"con":true,"img":false}]}
{"op":"mcm","clk":"11540457768","pt":1719494737967,"mc":[{"id":"1.230180115","rc":[{"atb":[[1.14,39.5]],"id":63387150}],"con":true,"img":false}]}
{"op":"mcm","clk":"11540457774","pt":1719494738021,"mc":[{"id":"1.230180115","rc":[{"atb":[[1.13,42.54]],"id":39682601}],"con":true,"img":false}]}
{"op":"mcm","clk":"11540457782","pt":1719494738122,"mc":[{"id":"1.230180115","rc":[{"atb":[[1.14,28.21]],"id":39682601}],"con":true,"img":false}]}
{"op":"mcm","clk":"11540457791","pt":1719494738228,"mc":[{"id":"1.230180115","rc":[{"atb":[[1.12,46.08]],"id":41804643}],"con":true,"img":false}]}
{"op":"mcm","clk":"11540457800","pt":1719494738331,"mc":[{"id":"1.230180115","rc":[{"atb":[[1.13,30.38]],"id":41804643}],"con":true,"img":false}]}
{"op":"mcm","clk":"11540457808","pt":1719494738436,"mc":[{"id":"1.230180115","rc":[{"atb":[[1.13,42.54]],"id":44213406}],"con":true,"img":false}]}
{"op":"mcm","clk":"11540457887","pt":1719494739266,"mc":[{"id":"1.230180115","rc":[{"atb":[[1.15,26.33]],"id":63387150}],"con":true,"img":false}]}
{"op":"mcm","clk":"11540457910","pt":1719494739528,"mc":[{"id":"1.230180115","rc":[{"atb":[[1.14,28.21]],"id":44213406}],"con":true,"img":false}]}
{"op":"mcm","clk":"11540457936","pt":1719494739849,"mc":[{"id":"1.230180115","rc":[{"atb":[[1.13,30.38]],"id":61150133}],"con":true,"img":false}]}
{"op":"mcm","clk":"11540460111","pt":1719494764579,"mc":[{"id":"1.230180115","rc":[{"atb":[[1.1,0]],"id":61150133}],"con":true,"img":false}]}
{"op":"mcm","clk":"11540460122","pt":1719494764686,"mc":[{"id":"1.230180115","rc":[{"atb":[[1.11,0]],"id":39682601}],"con":true,"img":false}]}
{"op":"mcm","clk":"11540460153","pt":1719494764995,"mc":[{"id":"1.230180115","rc":[{"atb":[[1.1,0]],"id":41804643}],"con":true,"img":false}]}
{"op":"mcm","clk":"11540460165","pt":1719494765098,"mc":[{"id":"1.230180115","rc":[{"atb":[[1.11,0]],"id":44213406}],"con":true,"img":false}]}
{"op":"mcm","clk":"11540460188","pt":1719494765319,"mc":[{"id":"1.230180115","rc":[{"atb":[[1.12,0]],"id":39682601}],"con":true,"img":false}]}
{"op":"mcm","clk":"11540460200","pt":1719494765414,"mc":[{"id":"1.230180115","rc":[{"atb":[[1.11,0]],"id":61150133}],"con":true,"img":false}]}
{"op":"mcm","clk":"11540460221","pt":1719494765674,"mc":[{"id":"1.230180115","rc":[{"atb":[[1.12,0]],"id":44213406}],"con":true,"img":false}]}
{"op":"mcm","clk":"11540460227","pt":1719494765780,"mc":[{"id":"1.230180115","rc":[{"atb":[[1.11,0]],"id":41804643}],"con":true,"img":false}]}
{"op":"mcm","clk":"11540460243","pt":1719494765984,"mc":[{"id":"1.230180115","rc":[{"atb":[[1.13,0]],"id":63387150}],"con":true,"img":false}]}
{"op":"mcm","clk":"11540460261","pt":1719494766200,"mc":[{"id":"1.230180115","rc":[{"atb":[[1.12,0]],"id":63387150}],"con":true,"img":false}]}
{"op":"mcm","clk":"11540460355","pt":1719494767288,"mc":[{"id":"1.230180115","rc":[{"atb":[[1.15,39.52]],"id":39682601}],"con":true,"img":false}]}
{"op":"mcm","clk":"11540460379","pt":1719494767594,"mc":[{"id":"1.230180115","rc":[{"atb":[[1.15,28.22]],"id":61150133}],"con":true,"img":false}]}
{"op":"mcm","clk":"11540460391","pt":1719494767705,"mc":[{"id":"1.230180115","rc":[{"atb":[[1.15,39.52]],"id":44213406}],"con":true,"img":false}]}
{"op":"mcm","clk":"11540460410","pt":1719494767904,"mc":[{"id":"1.230180115","rc":[{"atb":[[1.14,42.34]],"id":61150133}],"con":true,"img":false}]}
{"op":"mcm","clk":"11540460420","pt":1719494768009,"mc":[{"id":"1.230180115","rc":[{"atb":[[1.16,26.46]],"id":44213406}],"con":true,"img":false}]}
{"op":"mcm","clk":"11540460438","pt":1719494768215,"mc":[{"id":"1.230180115","rc":[{"atb":[[1.17,24.9]],"id":63387150}],"con":true,"img":false}]}
{"op":"mcm","clk":"11540460447","pt":1719494768270,"mc":[{"id":"1.230180115","rc":[{"atb":[[1.15,28.22]],"id":41804643}],"con":true,"img":false}]}
{"op":"mcm","clk":"11540460463","pt":1719494768486,"mc":[{"id":"1.230180115","rc":[{"atb":[[1.16,37.05]],"id":63387150}],"con":true,"img":false}]}
{"op":"mcm","clk":"11540460471","pt":1719494768583,"mc":[{"id":"1.230180115","rc":[{"atb":[[1.14,42.34]],"id":41804643}],"con":true,"img":false}]}
{"op":"mcm","clk":"11540460485","pt":1719494768793,"mc":[{"id":"1.230180115","rc":[{"atb":[[1.16,26.46]],"id":39682601}],"con":true,"img":false}]}
{"op":"mcm","clk":"11540461268","pt":1719494778008,"mc":[{"id":"1.230180115","rc":[{"atb":[[1.12,0]],"id":61150133},{"atb":[[1.13,0]],"id":39682601}],"con":true,"img":false}]}
{"op":"mcm","clk":"11540461284","pt":1719494778213,"mc":[{"id":"1.230180115","rc":[{"atb":[[1.12,0]],"id":41804643},{"atb":[[1.14,0]],"id":44213406}],"con":true,"img":false}]}
{"op":"mcm","clk":"11540461298","pt":1719494778418,"mc":[{"id":"1.230180115","rc":[{"atb":[[1.13,0]],"id":44213406}],"con":true,"img":false}]}
{"op":"mcm","clk":"11540461311","pt":1719494778624,"mc":[{"id":"1.230180115","rc":[{"atb":[[1.13,0]],"id":41804643}],"con":true,"img":false}]}
{"op":"mcm","clk":"11540461338","pt":1719494778889,"mc":[{"id":"1.230180115","rc":[{"atb":[[1.13,0]],"id":61150133}],"con":true,"img":false}]}
{"op":"mcm","clk":"11540461357","pt":1719494779092,"mc":[{"id":"1.230180115","rc":[{"atb":[[1.14,0]],"id":63387150}],"con":true,"img":false}]}
{"op":"mcm","clk":"11540461379","pt":1719494779302,"mc":[{"id":"1.230180115","rc":[{"atb":[[1.16,34.56]],"id":61150133}],"con":true,"img":false}]}
{"op":"mcm","clk":"11540461396","pt":1719494779504,"mc":[{"id":"1.230180115","rc":[{"atb":[[1.16,34.56]],"id":41804643},{"atb":[[1.18,21.94]],"id":44213406}],"con":true,"img":false}]}
{"op":"mcm","clk":"11540461422","pt":1719494779821,"mc":[{"id":"1.230180115","rc":[{"atb":[[1.17,32.53]],"id":44213406}],"con":true,"img":false}]}
{"op":"mcm","clk":"11540461429","pt":1719494779935,"mc":[{"id":"1.230180115","rc":[{"atb":[[1.17,23.23]],"id":41804643}],"con":true,"img":false}]}
{"op":"mcm","clk":"11540461436","pt":1719494780025,"mc":[{"id":"1.230180115","rc":[{"atb":[[1.17,32.53]],"id":39682601}],"con":true,"img":false}]}
{"op":"mcm","clk":"11540461454","pt":1719494780226,"mc":[{"id":"1.230180115","rc":[{"atb":[[1.17,23.23]],"id":61150133}],"con":true,"img":false}]}
{"op":"mcm","clk":"11540461470","pt":1719494780392,"mc":[{"id":"1.230180115","rc":[{"atb":[[1.18,30.72]],"id":63387150}],"con":true,"img":false}]}
{"op":"mcm","clk":"11540463599","pt":1719494807419,"mc":[{"id":"1.230180115","rc":[{"spn":495.58,"spf":"NaN","id":41804643},{"spn":500.58,"spf":"NaN","id":61150133},{"spn":500.59,"spf":"NaN","id":44213406},{"atb":[[1.15,0]],"id":39682601},{"spn":495.58,"spf":"NaN","id":39682601},{"spn":500.59,"spf":"NaN","id":63387150}],"con":true,"img":false}]}
{"op":"mcm","clk":"11540463627","pt":1719494807728,"mc":[{"id":"1.230180115","rc":[{"atb":[[1.14,0]],"id":61150133},{"atb":[[1.15,0]],"id":44213406}],"con":true,"img":false}]}
{"op":"mcm","clk":"11540463658","pt":1719494808043,"mc":[{"id":"1.230180115","rc":[{"atb":[[1.14,0]],"id":41804643}],"con":true,"img":false}]}
{"op":"mcm","clk":"11540463690","pt":1719494808350,"mc":[{"id":"1.230180115","rc":[{"atb":[[1.16,0]],"id":63387150}],"con":true,"img":false}]}
{"op":"mcm","clk":"11540463739","pt":1719494809025,"mc":[{"id":"1.230180115","rc":[{"atb":[[1.18,32.93]],"id":61150133},{"atb":[[1.18,32.93]],"id":39682601}],"con":true,"img":false}]}
{"op":"mcm","clk":"11540463759","pt":1719494809334,"mc":[{"id":"1.230180115","rc":[{"atb":[[1.19,31.2]],"id":44213406}],"con":true,"img":false}]}
{"op":"mcm","clk":"11540463778","pt":1719494809643,"mc":[{"id":"1.230180115","rc":[{"atb":[[1.18,32.93]],"id":41804643}],"con":true,"img":false}]}
{"op":"mcm","clk":"11540463838","pt":1719494810270,"mc":[{"id":"1.230180115","rc":[{"atb":[[1.19,31.2]],"id":63387150}],"con":true,"img":false}]}
{"op":"mcm","clk":"11540464904","pt":1719494823268,"mc":[{"id":"1.230180115","rc":[{"atb":[[1.16,0]],"id":61150133},{"atb":[[1.17,0]],"id":39682601}],"con":true,"img":false}]}
{"op":"mcm","clk":"11540464919","pt":1719494823475,"mc":[{"id":"1.230180115","rc":[{"atb":[[1.16,0]],"id":41804643}],"con":true,"img":false}]}
{"op":"mcm","clk":"11540464932","pt":1719494823632,"mc":[{"id":"1.230180115","rc":[{"atb":[[1.17,0]],"id":44213406}],"con":true,"img":false}]}
{"op":"mcm","clk":"11540465000","pt":1719494824360,"mc":[{"id":"1.230180115","rc":[{"atb":[[1.19,29.1]],"id":61150133}],"con":true,"img":false}]}
{"op":"mcm","clk":"11540465019","pt":1719494824564,"mc":[{"id":"1.230180115","rc":[{"atb":[[1.19,29.1]],"id":41804643}],"con":true,"img":false}]}
{"op":"mcm","clk":"11540465055","pt":1719494824983,"mc":[{"id":"1.230180115","rc":[{"atb":[[1.2,27.65]],"id":44213406},{"atb":[[1.19,29.1]],"id":39682601}],"con":true,"img":false}]}
{"op":"mcm","clk":"11540466946","pt":1719494844275,"mc":[{"id":"1.230180115","rc":[{"atb":[[1.15,0]],"id":63387150}],"con":true,"img":false}]}
{"op":"mcm","clk":"11540467497","pt":1719494850480,"mc":[{"id":"1.230180115","rc":[{"atb":[[1.18,0]],"id":39682601}],"con":true,"img":false}]}
{"op":"mcm","clk":"11540467520","pt":1719494850688,"mc":[{"id":"1.230180115","rc":[{"atb":[[1.18,0]],"id":61150133}],"con":true,"img":false}]}
{"op":"mcm","clk":"11540467532","pt":1719494850791,"mc":[{"id":"1.230180115","rc":[{"atb":[[1.19,0]],"id":44213406}],"con":true,"img":false}]}
{"op":"mcm","clk":"11540467631","pt":1719494851720,"mc":[{"id":"1.230180115","rc":[{"atb":[[1.21,28.22]],"id":44213406}],"con":true,"img":false}]}
{"op":"mcm","clk":"11540467638","pt":1719494851823,"mc":[{"id":"1.230180115","rc":[{"atb":[[1.2,29.64]],"id":61150133}],"con":true,"img":false}]}
{"op":"mcm","clk":"11540467657","pt":1719494851977,"mc":[{"id":"1.230180115","rc":[{"atb":[[1.2,29.64]],"id":39682601}],"con":true,"img":false}]}
{"op":"mcm","clk":"11540470418","pt":1719494884165,"mc":[{"id":"1.230180115","rc":[{"atb":[[1.17,0]],"id":41804643},{"spn":495.59,"spf":"NaN","id":41804643},{"atb":[[1.17,0]],"id":61150133},{"spn":500.6,"spf":"NaN","id":61150133},{"atb":[[1.18,0]],"id":44213406},{"spn":500.6,"spf":"NaN","id":44213406},{"atb":[[1.14,0]],"id":39682601},{"spn":495.6,"spf":"NaN","id":39682601},{"spn":500.59,"spf":"NaN","id":63387150}],"con":true,"img":false}]}
{"op":"mcm","clk":"11540470739","pt":1719494887451,"mc":[{"id":"1.230180115","rc":[{"atb":[[1.15,0]],"id":41804643},{"atb":[[1.15,0]],"id":61150133},{"atb":[[1.16,0]],"id":44213406},{"atb":[[1.16,0]],"id":39682601},{"atb":[[1.17,0]],"id":63387150}],"con":true,"img":false}]}
{"op":"mcm","clk":"11540497863","pt":1719495192461,"mc":[{"id":"1.230180115","rc":[{"atb":[[1.21,0]],"id":44213406},{"spn":500.6,"spf":"NaN","id":44213406}],"con":true,"img":false}]}
{"op":"mcm","clk":"11540498289","pt":1719495196970,"mc":[{"id":"1.230180115","rc":[{"atb":[[1.22,19.25]],"id":44213406}],"con":true,"img":false}]}
{"op":"mcm","clk":"11540498719","pt":1719495201882,"mc":[{"id":"1.230180115","rc":[{"atb":[[1.2,0]],"id":44213406}],"con":true,"img":false}]}
{"op":"mcm","clk":"11540500217","pt":1719495219192,"mc":[{"id":"1.230180115","rc":[{"atb":[[1.22,0]],"id":44213406}],"con":true,"img":false}]}
{"op":"mcm","clk":"11540500463","pt":1719495222912,"mc":[{"id":"1.230180115","rc":[{"atb":[[1.04,98.75]],"id":44213406}],"con":true,"img":false}]}
{"op":"mcm","clk":"11540501638","pt":1719495236732,"mc":[{"id":"1.230180115","rc":[{"atb":[[1.05,118.57]],"id":44213406}],"con":true,"img":false}]}
{"op":"mcm","clk":"11540501663","pt":1719495237020,"mc":[{"id":"1.230180115","rc":[{"atb":[[1.06,70.57]],"id":44213406}],"con":true,"img":false}]}
{"op":"mcm","clk":"11540502201","pt":1719495244323,"mc":[{"id":"1.230180115","rc":[{"atb":[[1.04,0]],"id":44213406}],"con":true,"img":false}]}
{"op":"mcm","clk":"11540502215","pt":1719495244528,"mc":[{"id":"1.230180115","rc":[{"atb":[[1.07,79]],"id":44213406}],"con":true,"img":false}]}
{"op":"mcm","clk":"11540502279","pt":1719495245350,"mc":[{"id":"1.230180115","rc":[{"atb":[[1.08,49.37]],"id":44213406}],"con":true,"img":false}]}
{"op":"mcm","clk":"11540505183","pt":1719495277283,"mc":[{"id":"1.230180115","rc":[{"atb":[[1.05,0]],"id":44213406},{"spn":500.54,"spf":"NaN","id":44213406}],"con":true,"img":false}]}
{"op":"mcm","clk":"11540505444","pt":1719495279776,"mc":[{"id":"1.230180115","rc":[{"atb":[[1.06,0]],"id":44213406}],"con":true,"img":false}]}
{"op":"mcm","clk":"11540505517","pt":1719495280666,"mc":[{"id":"1.230180115","rc":[{"atb":[[1.1,42.34]],"id":44213406}],"con":true,"img":false}]}
{"op":"mcm","clk":"11540505912","pt":1719495283957,"mc":[{"id":"1.230180115","rc":[{"atb":[[1.07,0]],"id":44213406}],"con":true,"img":false}]}
{"op":"mcm","clk":"11540506046","pt":1719495285565,"mc":[{"id":"1.230180115","rc":[{"atb":[[1.08,0]],"id":44213406}],"con":true,"img":false}]}
{"op":"mcm","clk":"11540506087","pt":1719495285980,"mc":[{"id":"1.230180115","rc":[{"atb":[[1.12,32.92]],"id":44213406}],"con":true,"img":false}]}
{"op":"mcm","clk":"11540509298","pt":1719495320498,"mc":[{"id":"1.230180115","rc":[{"atb":[[1.1,0]],"id":44213406}],"con":true,"img":false}]}
{"op":"mcm","clk":"11540509464","pt":1719495321908,"mc":[{"id":"1.230180115","rc":[{"atb":[[1.14,30.24]],"id":44213406}],"con":true,"img":false}]}
{"op":"mcm","clk":"11540511240","pt":1719495341916,"mc":[{"id":"1.230180115","rc":[{"atb":[[1.15,36.87]],"id":44213406},{"spn":500.57,"spf":"NaN","id":44213406}],"con":true,"img":false}]}
{"op":"mcm","clk":"11540511267","pt":1719495342229,"mc":[{"id":"1.230180115","rc":[{"atb":[[1.12,0]],"id":44213406}],"con":true,"img":false}]}
{"op":"mcm","clk":"11540511287","pt":1719495342433,"mc":[{"id":"1.230180115","rc":[{"atb":[[1.16,24.68]],"id":44213406}],"con":true,"img":false}]}
{"op":"mcm","clk":"11540513345","pt":1719495364539,"mc":[{"id":"1.230180115","rc":[{"atb":[[1.17,34.87]],"id":44213406}],"con":true,"img":false}]}
{"op":"mcm","clk":"11540513431","pt":1719495365267,"mc":[{"id":"1.230180115","rc":[{"atb":[[1.14,0]],"id":44213406}],"con":true,"img":false}]}
{"op":"mcm","clk":"11540513587","pt":1719495366782,"mc":[{"id":"1.230180115","rc":[{"atb":[[1.18,23.52]],"id":44213406}],"con":true,"img":false}]}
{"op":"mcm","clk":"11540514580","pt":1719495378181,"mc":[{"id":"1.230180115","rc":[{"atb":[[1.15,0]],"id":44213406}],"con":true,"img":false}]}
{"op":"mcm","clk":"11540514597","pt":1719495378490,"mc":[{"id":"1.230180115","rc":[{"atb":[[1.16,0]],"id":44213406}],"con":true,"img":false}]}
{"op":"mcm","clk":"11540516007","pt":1719495398012,"mc":[{"id":"1.230180115","rc":[{"atb":[[1.19,0]],"id":41804643},{"atb":[[1.19,0]],"id":61150133},{"atb":[[1.19,0]],"id":39682601},{"atb":[[1.18,0]],"id":63387150}],"con":true,"img":false}]}
{"op":"mcm","clk":"11540516340","pt":1719495402089,"mc":[{"id":"1.230180115","rc":[{"spn":495.59,"spf":"NaN","id":41804643},{"atb":[[1.17,0]],"id":44213406},{"spn":500.59,"spf":"NaN","id":44213406}],"con":true,"img":false}]}
{"op":"mcm","clk":"11540516370","pt":1719495402402,"mc":[{"id":"1.230180115","rc":[{"atb":[[1.18,0]],"id":44213406}],"con":true,"img":false}]}
{"op":"mcm","clk":"11540516485","pt":1719495404402,"mc":[{"id":"1.230180115","rc":[{"atb":[[1.03,141.16]],"id":41804643}],"con":true,"img":false}]}
{"op":"mcm","clk":"11540516513","pt":1719495404920,"mc":[{"id":"1.230180115","rc":[{"atb":[[1.03,141.16]],"id":61150133}],"con":true,"img":false}]}
{"op":"mcm","clk":"11540516558","pt":1719495405487,"mc":[{"id":"1.230180115","rc":[{"atb":[[1.05,84.69]],"id":63387150}],"con":true,"img":false}]}
{"op":"mcm","clk":"11540516582","pt":1719495406027,"mc":[{"id":"1.230180115","rc":[{"atb":[[1.04,105.86]],"id":39682601}],"con":true,"img":false}]}
{"op":"mcm","clk":"11540517404","pt":1719495417653,"mc":[{"id":"1.230180115","rc":[{"atb":[[1.21,26.33]],"id":39682601}],"con":true,"img":false}]}
{"op":"mcm","clk":"11540517411","pt":1719495417700,"mc":[{"id":"1.230180115","rc":[{"atb":[[1.21,26.33]],"id":61150133}],"con":true,"img":false}]}
{"op":"mcm","clk":"11540517418","pt":1719495417803,"mc":[{"id":"1.230180115","rc":[{"atb":[[1.19,29.1]],"id":41804643}],"con":true,"img":false}]}
{"op":"mcm","clk":"11540517429","pt":1719495417906,"mc":[{"id":"1.230180115","rc":[{"atb":[[1.2,27.65]],"id":63387150}],"con":true,"img":false}]}
{"op":"mcm","clk":"11540517609","pt":1719495420223,"mc":[{"id":"1.230180115","rc":[{"atb":[[1.83,32.94],[1.74,1]],"id":41804643},{"atl":[[6.4,1],[46,2]],"id":41804643},{"atb":[[1.63,29.64],[1.86,1]],"id":61150133},{"atl":[[5,1],[20,2]],"id":61150133},{"atb":[[1.71,55.26]],"id":44213406},{"atl":[[26,2]],"id":44213406},{"atb":[[1.18,102.04],[1.13,1]],"id":39682601},{"atl":[[2.96,1],[3.65,2]],"id":39682601},{"atb":[[1.97,1],[1.96,31.2]],"id":63387150},{"atl":[[75,2],[7.6,1]],"id":63387150}],"con":true,"img":false}]}
{"op":"mcm","clk":"11540517614","pt":1719495420326,"mc":[{"id":"1.230180115","rc":[{"atb":[[1.74,1]],"id":44213406},{"atl":[[5.2,1]],"id":44213406},{"atl":[[2.8,1]],"id":39682601}],"con":true,"img":false}]}
{"op":"mcm","clk":"11540517620","pt":1719495420434,"mc":[{"id":"1.230180115","rc":[{"atl":[[2.28,1],[2.96,0]],"id":39682601}],"con":true,"img":false}]}
{"op":"mcm","clk":"11540517629","pt":1719495420540,"mc":[{"id":"1.230180115","rc":[{"atl":[[2.96,2],[3.65,0]],"id":39682601}],"con":true,"img":false}]}
{"op":"mcm","clk":"11540517749","pt":1719495422139,"mc":[{"id":"1.230180115","rc":[{"atl":[[2.8,0]],"id":39682601}],"con":true,"img":false}]}
{"op":"mcm","clk":"11540518687","pt":1719495433355,"mc":[{"id":"1.230180115","rc":[{"atl":[[2.3,1],[2.28,0]],"id":39682601}],"con":true,"img":false}]}
{"op":"mcm","clk":"11540518696","pt":1719495433462,"mc":[{"id":"1.230180115","rc":[{"atl":[[2.8,2],[2.96,0]],"id":39682601}],"con":true,"img":false}]}
{"op":"mcm","clk":"11540518701","pt":1719495433560,"mc":[{"id":"1.230180115","rc":[{"atl":[[2.8,0],[3.65,3]],"id":39682601}],"con":true,"img":false}]}
{"op":"mcm","clk":"11540518870","pt":1719495435572,"mc":[{"id":"1.230180115","rc":[{"atb":[[1.83,0],[1.91,29.11]],"id":41804643},{"atb":[[1.63,0],[1.71,29.64]],"id":61150133},{"atb":[[1.8,8.48],[1.74,0],[1.7,1],[1.71,0]],"id":44213406},{"atb":[[1.22,29.64]],"id":39682601},{"atb":[[1.96,0],[2.2,27.65]],"id":63387150}],"con":true,"img":false}]}
{"op":"mcm","clk":"11540518875","pt":1719495435622,"mc":[{"id":"1.230180115","rc":[{"atb":[[1.92,29.11],[1.91,0]],"id":41804643},{"atl":[[5,0],[5.3,1]],"id":61150133},{"atb":[[1.18,0]],"id":39682601},{"atl":[[2.3,0],[2.28,1]],"id":39682601}],"con":true,"img":false}]}
{"op":"mcm","clk":"11540518960","pt":1719495436757,"mc":[{"id":"1.230180115","rc":[{"atb":[[1.19,0]],"id":41804643},{"atb":[[1.21,0]],"id":61150133}],"con":true,"img":false}]}
{"op":"mcm","clk":"11540518973","pt":1719495436961,"mc":[{"id":"1.230180115","rc":[{"atb":[[1.85,6.51]],"id":44213406}],"con":true,"img":false}]}
{"op":"mcm","clk":"11540518982","pt":1719495437065,"mc":[{"id":"1.230180115","rc":[{"atb":[[1.8,0],[1.86,6.51]],"id":44213406}],"con":true,"img":false}]}
{"op":"mcm","clk":"11540519388","pt":1719495441675,"mc":[{"id":"1.230180115","rc":[{"atb":[[1.18,0],[1.03,0]],"id":41804643},{"atb":[[1.2,0],[1.03,0]],"id":61150133},{"atb":[[1.19,0],[1.05,0]],"id":63387150}],"con":true,"img":false}]}
{"op":"mcm","clk":"11540520536","pt":1719495456366,"mc":[{"id":"1.230180115","rc":[{"atb":[[1.2,0]],"id":63387150}],"con":true,"img":false}]}
{"op":"mcm","clk":"11540521880","pt":1719495473003,"mc":[{"id":"1.230180115","rc":[{"spn":4.16,"spf":"NaN","id":41804643},{"atl":[[5.3,0],[5.4,1]],"id":61150133},{"spn":3.63,"spf":"NaN","id":61150133},{"spn":3.53,"spf":"NaN","id":44213406},{"spn":1.75,"spf":"NaN","id":39682601},{"spn":4.9,"spf":"NaN","id":63387150}],"con":true,"img":false}]}
{"op":"mcm","clk":"11540521889","pt":1719495473107,"mc":[{"id":"1.230180115","rc":[{"atb":[[1.92,0],[1.94,29.11]],"id":41804643},{"atl":[[5.5,1]],"id":61150133},{"atb":[[1.7,0]],"id":44213406},{"atl":[[2.3,1],[2.28,0]],"id":39682601}],"con":true,"img":false}]}
{"op":"mcm","clk":"11540521904","pt":1719495473208,"mc":[{"id":"1.230180115","rc":[{"atl":[[5.4,0]],"id":61150133}],"con":true,"img":false}]}
{"op":"mcm","clk":"11540521911","pt":1719495473311,"mc":[{"id":"1.230180115","rc":[{"atl":[[2.3,0],[2.26,1]],"id":39682601}],"con":true,"img":false}]}
{"op":"mcm","clk":"11540522055","pt":1719495475084,"mc":[{"id":"1.230180115","rc":[{"atl":[[5.6,1],[5.5,0]],"id":61150133}],"con":true,"img":false}]}
{"op":"mcm","clk":"11540522101","pt":1719495475802,"mc":[{"id":"1.230180115","rc":[{"atb":[[1.75,7.37]],"id":61150133},{"atb":[[1.85,0]],"id":44213406}],"con":true,"img":false}]}
{"op":"mcm","clk":"11540522107","pt":1719495475899,"mc":[{"id":"1.230180115","rc":[{"atb":[[1.71,0],[1.76,29.64]],"id":61150133},{"atb":[[1.8,55.26],[1.86,0]],"id":44213406}],"con":true,"img":false}]}
{"op":"mcm","clk":"11540522158","pt":1719495476470,"mc":[{"id":"1.230180115","rc":[{"atl":[[5.6,0],[5.9,1]],"id":61150133},{"atl":[[2.3,1],[2.26,0]],"id":39682601}],"con":true,"img":false}]}
{"op":"mcm","clk":"11540522188","pt":1719495476883,"mc":[{"id":"1.230180115","rc":[{"atb":[[1.62,1]],"id":44213406}],"con":true,"img":false}]}
{"op":"mcm","clk":"11540522268","pt":1719495477911,"mc":[{"id":"1.230180115","rc":[{"atb":[[1.74,0],[1.62,1]],"id":41804643},{"atl":[[6.2,1],[5.9,0]],"id":61150133},{"atl":[[2.3,0],[2.28,1]],"id":39682601}],"con":true,"img":false}]}
{"op":"mcm","clk":"11540522289","pt":1719495478173,"mc":[{"id":"1.230180115","rc":[{"atb":[[1.83,60],[1.94,0]],"id":41804643}],"con":true,"img":false}]}
{"op":"mcm","clk":"11540522426","pt":1719495479487,"mc":[{"id":"1.230180115","rc":[{"atb":[[1.2,0]],"id":39682601}],"con":true,"img":false}]}
{"op":"mcm","clk":"11540522491","pt":1719495480212,"mc":[{"id":"1.230180115","rc":[{"atb":[[1.62,0],[1.66,1]],"id":41804643}],"con":true,"img":false}]}
{"op":"mcm","clk":"11540522541","pt":1719495480890,"mc":[{"id":"1.230180115","rc":[{"atl":[[5.8,1],[6.2,0]],"id":61150133}],"con":true,"img":false}]}
{"op":"mcm","clk":"11540522601","pt":1719495481624,"mc":[{"id":"1.230180115","rc":[{"atl":[[5.8,0],[5.9,1]],"id":61150133},{"atb":[[1.8,0],[1.59,1],[1.62,0],[1.78,110.52]],"id":44213406}],"con":true,"img":false}]}
{"op":"mcm","clk":"11540522618","pt":1719495481782,"mc":[{"id":"1.230180115","rc":[{"atl":[[20,0],[6.2,2]],"id":61150133}],"con":true,"img":false}]}
{"op":"mcm","clk":"11540522631","pt":1719495481891,"mc":[{"id":"1.230180115","rc":[{"atb":[[1.7,1],[1.66,0]],"id":41804643},{"atl":[[5.8,1],[20,2],[6.2,0],[5.9,0]],"id":61150133}],"con":true,"img":false}]}
{"op":"mcm","clk":"11540522637","pt":1719495481988,"mc":[{"id":"1.230180115","rc":[{"atl":[[20,0],[6.2,2]],"id":61150133}],"con":true,"img":false}]}
{"op":"mcm","clk":"11540522654","pt":1719495482094,"mc":[{"id":"1.230180115","rc":[{"atl":[[20,3],[6.2,0]],"id":61150133}],"con":true,"img":false}]}
{"op":"mcm","clk":"11540522746","pt":1719495483183,"mc":[{"id":"1.230180115","rc":[{"atb":[[1.74,1],[1.7,0]],"id":41804643},{"atb":[[1.78,5.42]],"id":61150133},{"atl":[[5.8,0],[6,1],[5.9,1]],"id":61150133},{"atl":[[2.26,1]],"id":39682601}],"con":true,"img":false}]}
{"op":"mcm","clk":"11540522757","pt":1719495483301,"mc":[{"id":"1.230180115","rc":[{"atl":[[20,0],[6,3]],"id":61150133},{"atl":[[2.28,0]],"id":39682601}],"con":true,"img":false}]}
{"op":"mcm","clk":"11540522766","pt":1719495483390,"mc":[{"id":"1.230180115","rc":[{"atb":[[1.79,7.37],[1.76,0]],"id":61150133},{"atl":[[20,4],[6,1]],"id":61150133}],"con":true,"img":false}]}
{"op":"mcm","clk":"11540522841","pt":1719495484284,"mc":[{"id":"1.230180115","rc":[{"atl":[[6,0]],"id":61150133}],"con":true,"img":false}]}
{"op":"mcm","clk":"11540523031","pt":1719495486695,"mc":[{"id":"1.230180115","rc":[{"atb":[[1.78,0],[1.76,131.58]],"id":44213406}],"con":true,"img":false}]}
{"op":"mcm","clk":"11540523118","pt":1719495487803,"mc":[{"id":"1.230180115","rc":[{"atb":[[1.83,0],[1.91,60]],"id":41804643}],"con":true,"img":false}]}
{"op":"mcm","clk":"11540523844","pt":1719495496736,"mc":[{"id":"1.230180115","rc":[{"atb":[[1.75,0]],"id":61150133},{"atb":[[1.21,0]],"id":39682601}],"con":true,"img":false}]}
{"op":"mcm","clk":"11540523854","pt":1719495496796,"mc":[{"id":"1.230180115","rc":[{"atb":[[1.22,0],[1.05,102.04]],"id":39682601}],"con":true,"img":false}]}
{"op":"mcm","clk":"11540523884","pt":1719495497213,"mc":[{"id":"1.230180115","rc":[{"atb":[[1.81,4.87]],"id":61150133}],"con":true,"img":false}]}
{"op":"mcm","clk":"11540523892","pt":1719495497317,"mc":[{"id":"1.230180115","rc":[{"atb":[[1.82,5.43],[1.79,0]],"id":61150133}],"con":true,"img":false}]}
{"op":"mcm","clk":"11540524141","pt":1719495500304,"mc":[{"id":"1.230180115","rc":[{"atb":[[1.23,2]],"id":39682601}],"con":true,"img":false}]}
{"op":"mcm","clk":"11540524160","pt":1719495500605,"mc":[{"id":"1.230180115","rc":[{"atb":[[1.77,2]],"id":61150133}],"con":true,"img":false}]}
{"op":"mcm","clk":"11540524193","pt":1719495501024,"mc":[{"id":"1.230180115","rc":[{"atb":[[1.81,2]],"id":44213406}],"con":true,"img":false}]}
{"op":"mcm","clk":"11540524202","pt":1719495501127,"mc":[{"id":"1.230180115","rc":[{"atb":[[1.81,4],[1.76,0]],"id":44213406}],"con":true,"img":false}]}
{"op":"mcm","clk":"11540524212","pt":1719495501227,"mc":[{"id":"1.230180115","rc":[{"atb":[[1.84,2]],"id":41804643}],"con":true,"img":false}]}
{"op":"mcm","clk":"11540524245","pt":1719495501600,"mc":[{"id":"1.230180115","rc":[{"atb":[[2.22,2]],"id":63387150}],"con":true,"img":false}]}
{"op":"mcm","clk":"11540524379","pt":1719495503305,"mc":[{"id":"1.230180115","rc":[{"spl":[[1.01,1]],"id":61150133}],"con":true,"img":false}]}
{"op":"mcm","clk":"11540524573","pt":1719495505633,"mc":[{"id":"1.230180115","rc":[{"atb":[[1.23,0]],"id":39682601}],"con":true,"img":false}]}
{"op":"mcm","clk":"11540524584","pt":1719495505740,"mc":[{"id":"1.230180115","rc":[{"atb":[[1.06,2]],"id":39682601}],"con":true,"img":false}]}
{"op":"mcm","clk":"11540524607","pt":1719495506120,"mc":[{"id":"1.230180115","rc":[{"atb":[[1.77,0]],"id":61150133}],"con":true,"img":false}]}
{"op":"mcm","clk":"11540524618","pt":1719495506224,"mc":[{"id":"1.230180115","rc":[{"atb":[[1.83,2]],"id":61150133}],"con":true,"img":false}]}
{"op":"mcm","clk":"11540524642","pt":1719495506517,"mc":[{"id":"1.230180115","rc":[{"atb":[[1.81,2]],"id":44213406}],"con":true,"img":false}]}
{"op":"mcm","clk":"11540524651","pt":1719495506620,"mc":[{"id":"1.230180115","rc":[{"atb":[[1.02,10.47]],"id":44213406}],"con":true,"img":false}]}
{"op":"mcm","clk":"11540524656","pt":1719495506726,"mc":[{"id":"1.230180115","rc":[{"atb":[[1.81,0],[1.76,8.48]],"id":44213406}],"con":true,"img":false}]}
{"op":"mcm","clk":"11540524689","pt":1719495507035,"mc":[{"id":"1.230180115","rc":[{"atb":[[1.84,0]],"id":41804643}],"con":true,"img":false}]}
{"op":"mcm","clk":"11540524700","pt":1719495507138,"mc":[{"id":"1.230180115","rc":[{"atb":[[1.92,2]],"id":41804643}],"con":true,"img":false}]}
{"op":"mcm","clk":"11540524726","pt":1719495507520,"mc":[{"id":"1.230180115","rc":[{"atb":[[2.22,0]],"id":63387150}],"con":true,"img":false}]}
{"op":"mcm","clk":"11540524736","pt":1719495507622,"mc":[{"id":"1.230180115","rc":[{"atb":[[1.02,2]],"id":63387150}],"con":true,"img":false}]}
{"op":"mcm","clk":"11540525018","pt":1719495511616,"mc":[{"id":"1.230180115","rc":[{"atb":[[1.02,8.47]],"id":44213406}],"con":true,"img":false}]}
{"op":"mcm","clk":"11540525028","pt":1719495511768,"mc":[{"id":"1.230180115","rc":[{"atb":[[1.77,2]],"id":44213406}],"con":true,"img":false}]}
{"op":"mcm","clk":"11540525073","pt":1719495512234,"mc":[{"id":"1.230180115","rc":[{"atb":[[1.02,0]],"id":63387150}],"con":true,"img":false}]}
{"op":"mcm","clk":"11540525081","pt":1719495512345,"mc":[{"id":"1.230180115","rc":[{"atb":[[2.22,2]],"id":63387150}],"con":true,"img":false}]}
{"op":"mcm","clk":"11540525320","pt":1719495515316,"mc":[{"id":"1.230180115","rc":[{"atb":[[1.77,0]],"id":44213406}],"con":true,"img":false}]}
{"op":"mcm","clk":"11540525335","pt":1719495515417,"mc":[{"id":"1.230180115","rc":[{"atb":[[1.02,10.47]],"id":44213406}],"con":true,"img":false}]}
{"op":"mcm","clk":"11540525369","pt":1719495515825,"mc":[{"id":"1.230180115","rc":[{"atb":[[2.22,0]],"id":63387150}],"con":true,"img":false}]}
{"op":"mcm","clk":"11540525372","pt":1719495515929,"mc":[{"id":"1.230180115","rc":[{"atb":[[1.02,2]],"id":63387150}],"con":true,"img":false}]}
{"op":"mcm","clk":"11540525447","pt":1719495516822,"mc":[{"id":"1.230180115","rc":[{"atb":[[1.04,0]],"id":39682601}],"con":true,"img":false}]}
{"op":"mcm","clk":"11540525540","pt":1719495518017,"mc":[{"id":"1.230180115","rc":[{"atb":[[1.06,94.17]],"id":39682601}],"con":true,"img":false}]}
{"op":"mcm","clk":"11540525563","pt":1719495518220,"mc":[{"id":"1.230180115","rc":[{"atb":[[1.07,94.18]],"id":39682601}],"con":true,"img":false}]}
{"op":"mcm","clk":"11540525577","pt":1719495518330,"mc":[{"id":"1.230180115","rc":[{"atb":[[1.05,0],[1.08,49.37]],"id":39682601}],"con":true,"img":false}]}
{"op":"mcm","clk":"11540525684","pt":1719495519313,"mc":[{"id":"1.230180115","rc":[{"atb":[[1.06,92.17]],"id":39682601}],"con":true,"img":false}]}
{"op":"mcm","clk":"11540525692","pt":1719495519420,"mc":[{"id":"1.230180115","rc":[{"atb":[[1.09,2]],"id":39682601}],"con":true,"img":false}]}
{"op":"mcm","clk":"11540525712","pt":1719495519732,"mc":[{"id":"1.230180115","rc":[{"atb":[[1.02,8.47]],"id":44213406}],"con":true,"img":false}]}
{"op":"mcm","clk":"11540525718","pt":1719495519830,"mc":[{"id":"1.230180115","rc":[{"atb":[[1.77,2]],"id":44213406}],"con":true,"img":false}]}
{"op":"mcm","clk":"11540525753","pt":1719495520245,"mc":[{"id":"1.230180115","rc":[{"atb":[[1.02,0]],"id":63387150}],"con":true,"img":false}]}
{"op":"mcm","clk":"11540525758","pt":1719495520347,"mc":[{"id":"1.230180115","rc":[{"atb":[[2.22,2]],"id":63387150}],"con":true,"img":false}]}
{"op":"mcm","clk":"11540525810","pt":1719495521036,"mc":[{"id":"1.230180115","rc":[{"atb":[[1.06,190.99]],"id":39682601}],"con":true,"img":false}]}
{"op":"mcm","clk":"11540525874","pt":1719495521853,"mc":[{"id":"1.230180115","rc":[{"atb":[[1.08,102.31]],"id":39682601}],"con":true,"img":false}]}
{"op":"mcm","clk":"11540526056","pt":1719495524041,"mc":[{"id":"1.230180115","rc":[{"atb":[[1.77,0]],"id":44213406}],"con":true,"img":false}]}
{"op":"mcm","clk":"11540526061","pt":1719495524143,"mc":[{"id":"1.230180115","rc":[{"atb":[[1.02,10.47]],"id":44213406}],"con":true,"img":false}]}
{"op":"mcm","clk":"11540526080","pt":1719495524351,"mc":[{"id":"1.230180115","rc":[{"atb":[[2.22,0]],"id":63387150}],"con":true,"img":false}]}
{"op":"mcm","clk":"11540526086","pt":1719495524454,"mc":[{"id":"1.230180115","rc":[{"atb":[[1.02,2]],"id":63387150}],"con":true,"img":false}]}
{"op":"mcm","clk":"11540526350","pt":1719495527442,"mc":[{"id":"1.230180115","rc":[{"atb":[[1.09,96.18],[1.07,0]],"id":39682601}],"con":true,"img":false}]}
{"op":"mcm","clk":"11540526440","pt":1719495528550,"mc":[{"id":"1.230180115","rc":[{"atb":[[1.02,8.47]],"id":44213406}],"con":true,"img":false}]}
{"op":"mcm","clk":"11540526453","pt":1719495528638,"mc":[{"id":"1.230180115","rc":[{"atb":[[1.77,2]],"id":44213406}],"con":true,"img":false}]}
{"op":"mcm","clk":"11540526479","pt":1719495528949,"mc":[{"id":"1.230180115","rc":[{"atb":[[1.02,0]],"id":63387150}],"con":true,"img":false}]}
{"op":"mcm","clk":"11540526489","pt":1719495529061,"mc":[{"id":"1.230180115","rc":[{"atb":[[2.22,2]],"id":63387150}],"con":true,"img":false}]}
{"op":"mcm","clk":"11540526738","pt":1719495532188,"mc":[{"id":"1.230180115","rc":[{"atb":[[1.77,0]],"id":44213406}],"con":true,"img":false}]}
{"op":"mcm","clk":"11540526751","pt":1719495532354,"mc":[{"id":"1.230180115","rc":[{"atb":[[1.02,10.47]],"id":44213406}],"con":true,"img":false}]}
{"op":"mcm","clk":"11540526795","pt":1719495532871,"mc":[{"id":"1.230180115","rc":[{"atb":[[2.22,0]],"id":63387150}],"con":true,"img":false}]}
{"op":"mcm","clk":"11540526804","pt":1719495532937,"mc":[{"id":"1.230180115","rc":[{"atb":[[1.02,2]],"id":63387150}],"con":true,"img":false}]}
{"op":"mcm","clk":"11540527023","pt":1719495535457,"mc":[{"id":"1.230180115","rc":[{"spn":1.86,"spf":1.0,"id":61150133},{"atb":[[1.02,8.47]],"id":44213406},{"spn":3.48,"spf":"NaN","id":44213406},{"spn":1.69,"spf":"NaN","id":39682601}],"con":true,"img":false}]}
{"op":"mcm","clk":"11540527029","pt":1719495535558,"mc":[{"id":"1.230180115","rc":[{"atb":[[1.77,2]],"id":44213406}],"con":true,"img":false}]}
{"op":"mcm","clk":"11540527056","pt":1719495535966,"mc":[{"id":"1.230180115","rc":[{"atb":[[1.02,0]],"id":63387150}],"con":true,"img":false}]}
{"op":"mcm","clk":"11540527062","pt":1719495536071,"mc":[{"id":"1.230180115","rc":[{"atb":[[2.22,2]],"id":63387150}],"con":true,"img":false}]}
{"op":"mcm","clk":"11540527348","pt":1719495539155,"mc":[{"id":"1.230180115","rc":[{"atb":[[1.77,0]],"id":44213406},{"atb":[[1.06,98.81]],"id":39682601}],"con":true,"img":false}]}
{"op":"mcm","clk":"11540527363","pt":1719495539297,"mc":[{"id":"1.230180115","rc":[{"atb":[[1.02,10.47]],"id":44213406}],"con":true,"img":false}]}
{"op":"mcm","clk":"11540527379","pt":1719495539467,"mc":[{"id":"1.230180115","rc":[{"atb":[[1.08,52.93]],"id":39682601}],"con":true,"img":false}]}
{"op":"mcm","clk":"11540527409","pt":1719495539875,"mc":[{"id":"1.230180115","rc":[{"atb":[[1.11,35.9]],"id":39682601},{"atb":[[2.22,0]],"id":63387150}],"con":true,"img":false}]}
{"op":"mcm","clk":"11540527419","pt":1719495539973,"mc":[{"id":"1.230180115","rc":[{"atb":[[1.12,52.93],[1.09,2]],"id":39682601},{"atb":[[1.02,2]],"id":63387150}],"con":true,"img":false}]}
{"op":"mcm","clk":"11540527428","pt":1719495540078,"mc":[{"id":"1.230180115","rc":[{"atb":[[1.1,55.3]],"id":39682601}],"con":true,"img":false}]}
{"op":"mcm","clk":"11540527727","pt":1719495543261,"mc":[{"id":"1.230180115","rc":[{"atb":[[1.09,0]],"id":39682601}],"con":true,"img":false}]}
{"op":"mcm","clk":"11540527738","pt":1719495543366,"mc":[{"id":"1.230180115","rc":[{"atb":[[1.13,3]],"id":39682601}],"con":true,"img":false}]}
{"op":"mcm","clk":"11540527753","pt":1719495543573,"mc":[{"id":"1.230180115","rc":[{"atb":[[1.02,8.47]],"id":44213406}],"con":true,"img":false}]}
{"op":"mcm","clk":"11540527762","pt":1719495543677,"mc":[{"id":"1.230180115","rc":[{"atb":[[1.77,2]],"id":44213406}],"con":true,"img":false}]}
{"op":"mcm","clk":"11540527782","pt":1719495543884,"mc":[{"id":"1.230180115","rc":[{"atb":[[1.02,0]],"id":63387150}],"con":true,"img":false}]}
{"op":"mcm","clk":"11540527792","pt":1719495543936,"mc":[{"id":"1.230180115","rc":[{"atb":[[2.22,2]],"id":63387150}],"con":true,"img":false}]}
{"op":"mcm","clk":"11540527992","pt":1719495546345,"mc":[{"id":"1.230180115","rc":[{"atb":[[1.77,0]],"id":44213406}],"con":true,"img":false}]}
{"op":"mcm","clk":"11540527998","pt":1719495546443,"mc":[{"id":"1.230180115","rc":[{"atb":[[1.02,10.47]],"id":44213406}],"con":true,"img":false}]}
{"op":"mcm","clk":"11540528036","pt":1719495546862,"mc":[{"id":"1.230180115","rc":[{"atb":[[2.22,0]],"id":63387150}],"con":true,"img":false}]}
{"op":"mcm","clk":"11540528046","pt":1719495546969,"mc":[{"id":"1.230180115","rc":[{"atb":[[1.02,2]],"id":63387150}],"con":true,"img":false}]}
{"op":"mcm","clk":"11540528297","pt":1719495549755,"mc":[{"id":"1.230180115","rc":[{"atb":[[1.02,8.47]],"id":44213406}],"con":true,"img":false}]}
{"op":"mcm","clk":"11540528307","pt":1719495549855,"mc":[{"id":"1.230180115","rc":[{"atb":[[1.77,2]],"id":44213406}],"con":true,"img":false}]}
{"op":"mcm","clk":"11540528328","pt":1719495550217,"mc":[{"id":"1.230180115","rc":[{"atb":[[1.02,0]],"id":63387150}],"con":true,"img":false}]}
{"op":"mcm","clk":"11540528341","pt":1719495550279,"mc":[{"id":"1.230180115","rc":[{"atb":[[2.22,2]],"id":63387150}],"con":true,"img":false}]}
{"op":"mcm","clk":"11540528631","pt":1719495553580,"mc":[{"id":"1.230180115","rc":[{"atb":[[1.77,0]],"id":44213406}],"con":true,"img":false}]}
{"op":"mcm","clk":"11540528643","pt":1719495553672,"mc":[{"id":"1.230180115","rc":[{"atb":[[1.02,10.47]],"id":44213406}],"con":true,"img":false}]}
{"op":"mcm","clk":"11540528714","pt":1719495554257,"mc":[{"id":"1.230180115","rc":[{"atb":[[2.22,0]],"id":63387150}],"con":true,"img":false}]}
{"op":"mcm","clk":"11540528726","pt":1719495554362,"mc":[{"id":"1.230180115","rc":[{"atb":[[1.02,2]],"id":63387150}],"con":true,"img":false}]}
{"op":"mcm","clk":"11540528943","pt":1719495557204,"mc":[{"id":"1.230180115","rc":[{"atb":[[1.02,8.47]],"id":44213406}],"con":true,"img":false}]}
{"op":"mcm","clk":"11540528952","pt":1719495557358,"mc":[{"id":"1.230180115","rc":[{"atb":[[1.77,2]],"id":44213406}],"con":true,"img":false}]}
{"op":"mcm","clk":"11540529001","pt":1719495557783,"mc":[{"id":"1.230180115","rc":[{"atb":[[1.02,0]],"id":63387150}],"con":true,"img":false}]}
{"op":"mcm","clk":"11540529012","pt":1719495557892,"mc":[{"id":"1.230180115","rc":[{"atb":[[2.22,2]],"id":63387150}],"con":true,"img":false}]}
{"op":"mcm","clk":"11540529129","pt":1719495559300,"mc":[{"id":"1.230180115","rc":[{"atb":[[1.06,0]],"id":39682601}],"con":true,"img":false}]}
{"op":"mcm","clk":"11540529143","pt":1719495559539,"mc":[{"id":"1.230180115","rc":[{"atb":[[1.79,5]],"id":44213406},{"atb":[[1.1,0]],"id":39682601}],"con":true,"img":false}]}
{"op":"mcm","clk":"11540529152","pt":1719495559641,"mc":[{"id":"1.230180115","rc":[{"atb":[[1.79,10.36]],"id":44213406}],"con":true,"img":false}]}
{"op":"mcm","clk":"11540529163","pt":1719495559700,"mc":[{"id":"1.230180115","rc":[{"atb":[[1.8,5],[1.76,0]],"id":44213406},{"atb":[[1.08,0]],"id":39682601}],"con":true,"img":false}]}
{"op":"mcm","clk":"11540529191","pt":1719495560005,"mc":[{"id":"1.230180115","rc":[{"atb":[[1.11,0],[1.13,45.54]],"id":39682601}],"con":true,"img":false}]}
{"op":"mcm","clk":"11540529201","pt":1719495560056,"mc":[{"id":"1.230180115","rc":[{"atb":[[1.12,0],[1.14,45.55]],"id":39682601}],"con":true,"img":false}]}
{"op":"mcm","clk":"11540529210","pt":1719495560162,"mc":[{"id":"1.230180115","rc":[{"atb":[[1.15,26.33]],"id":39682601}],"con":true,"img":false}]}
{"op":"mcm","clk":"11540529248","pt":1719495560787,"mc":[{"id":"1.230180115","rc":[{"atb":[[1.13,91.15]],"id":39682601}],"con":true,"img":false}]}
{"op":"mcm","clk":"11540529263","pt":1719495560995,"mc":[{"id":"1.230180115","rc":[{"atb":[[1.15,54.56],[1.13,89.15]],"id":39682601}],"con":true,"img":false}]}
{"op":"mcm","clk":"11540529272","pt":1719495561141,"mc":[{"id":"1.230180115","rc":[{"atb":[[1.16,2]],"id":39682601}],"con":true,"img":false}]}
{"op":"mcm","clk":"11540529299","pt":1719495561505,"mc":[{"id":"1.230180115","rc":[{"atb":[[1.77,0]],"id":44213406}],"con":true,"img":false}]}
{"op":"mcm","clk":"11540529311","pt":1719495561624,"mc":[{"id":"1.230180115","rc":[{"atb":[[1.81,2]],"id":44213406}],"con":true,"img":false}]}
{"op":"mcm","clk":"11540529337","pt":1719495561882,"mc":[{"id":"1.230180115","rc":[{"atb":[[2.22,0]],"id":63387150}],"con":true,"img":false}]}
{"op":"mcm","clk":"11540529347","pt":1719495561979,"mc":[{"id":"1.230180115","rc":[{"atb":[[1.02,2]],"id":63387150}],"con":true,"img":false}]}
{"op":"mcm","clk":"11540529480","pt":1719495563689,"mc":[{"id":"1.230180115","rc":[{"atb":[[1.02,0]],"id":63387150}],"con":true,"img":false}]}
{"op":"mcm","clk":"11540529487","pt":1719495563780,"mc":[{"id":"1.230180115","rc":[{"atb":[[2.22,2]],"id":63387150}],"con":true,"img":false}]}
{"op":"mcm","clk":"11540529726","pt":1719495566687,"mc":[{"id":"1.230180115","rc":[{"atb":[[2.22,0]],"id":63387150}],"con":true,"img":false}]}
{"op":"mcm","clk":"11540529736","pt":1719495566793,"mc":[{"id":"1.230180115","rc":[{"atb":[[1.02,2]],"id":63387150}],"con":true,"img":false}]}
{"op":"mcm","clk":"11540529880","pt":1719495568814,"mc":[{"id":"1.230180115","rc":[{"atb":[[1.16,47.55],[1.14,0]],"id":39682601}],"con":true,"img":false}]}
{"op":"mcm","clk":"11540529932","pt":1719495569492,"mc":[{"id":"1.230180115","rc":[{"atb":[[1.02,0]],"id":63387150}],"con":true,"img":false}]}
{"op":"mcm","clk":"11540529944","pt":1719495569593,"mc":[{"id":"1.230180115","rc":[{"atb":[[2.22,2]],"id":63387150}],"con":true,"img":false}]}
{"op":"mcm","clk":"11540530120","pt":1719495571793,"mc":[{"id":"1.230180115","rc":[{"atb":[[2.22,0]],"id":63387150}],"con":true,"img":false}]}
{"op":"mcm","clk":"11540530130","pt":1719495571903,"mc":[{"id":"1.230180115","rc":[{"atb":[[1.02,2]],"id":63387150}],"con":true,"img":false}]}
{"op":"mcm","clk":"11540530282","pt":1719495573725,"mc":[{"id":"1.230180115","rc":[{"atb":[[1.02,0]],"id":63387150}],"con":true,"img":false}]}
{"op":"mcm","clk":"11540530287","pt":1719495573777,"mc":[{"id":"1.230180115","rc":[{"atb":[[2.22,2]],"id":63387150}],"con":true,"img":false}]}
{"op":"mcm","clk":"11540530406","pt":1719495575489,"mc":[{"id":"1.230180115","rc":[{"atb":[[2.22,0]],"id":63387150}],"con":true,"img":false}]}
{"op":"mcm","clk":"11540530409","pt":1719495575591,"mc":[{"id":"1.230180115","rc":[{"atb":[[1.02,2]],"id":63387150}],"con":true,"img":false}]}
{"op":"mcm","clk":"11540530540","pt":1719495577412,"mc":[{"id":"1.230180115","rc":[{"atb":[[1.02,0]],"id":63387150}],"con":true,"img":false}]}
{"op":"mcm","clk":"11540530551","pt":1719495577516,"mc":[{"id":"1.230180115","rc":[{"atb":[[2.22,2]],"id":63387150}],"con":true,"img":false}]}
{"op":"mcm","clk":"11540530769","pt":1719495579920,"mc":[{"id":"1.230180115","rc":[{"atb":[[1.81,0]],"id":61150133},{"atb":[[2.22,0]],"id":63387150}],"con":true,"img":false}]}
{"op":"mcm","clk":"11540530782","pt":1719495580018,"mc":[{"id":"1.230180115","rc":[{"atb":[[1.02,2]],"id":63387150}],"con":true,"img":false}]}
{"op":"mcm","clk":"11540530810","pt":1719495580431,"mc":[{"id":"1.230180115","rc":[{"atb":[[1.79,5.36]],"id":44213406},{"atb":[[1.15,28.22]],"id":39682601}],"con":true,"img":false}]}
{"op":"mcm","clk":"11540530854","pt":1719495581009,"mc":[{"id":"1.230180115","rc":[{"atb":[[1.83,4.75]],"id":44213406}],"con":true,"img":false}]}
{"op":"mcm","clk":"11540530857","pt":1719495581114,"mc":[{"id":"1.230180115","rc":[{"atb":[[1.8,0],[1.84,4.76]],"id":44213406}],"con":true,"img":false}]}
{"op":"mcm","clk":"11540530906","pt":1719495581430,"mc":[{"id":"1.230180115","rc":[{"atb":[[1.18,21.94]],"id":39682601}],"con":true,"img":false}]}
{"op":"mcm","clk":"11540530912","pt":1719495581532,"mc":[{"id":"1.230180115","rc":[{"atb":[[1.16,2],[1.19,28.23]],"id":39682601}],"con":true,"img":false}]}
{"op":"mcm","clk":"11540530928","pt":1719495581735,"mc":[{"id":"1.230180115","rc":[{"atb":[[1.13,46.6]],"id":39682601}],"con":true,"img":false}]}
{"op":"mcm","clk":"11540530943","pt":1719495581918,"mc":[{"id":"1.230180115","rc":[{"atb":[[1.17,32.53]],"id":39682601}],"con":true,"img":false}]}
{"op":"mcm","clk":"11540531006","pt":1719495582700,"mc":[{"id":"1.230180115","rc":[{"atb":[[1.16,0]],"id":39682601}],"con":true,"img":false}]}
{"op":"mcm","clk":"11540531014","pt":1719495582812,"mc":[{"id":"1.230180115","rc":[{"atb":[[1.2,2]],"id":39682601}],"con":true,"img":false}]}
{"op":"mcm","clk":"11540531061","pt":1719495583329,"mc":[{"id":"1.230180115","rc":[{"atb":[[1.81,0]],"id":44213406}],"con":true,"img":false}]}
{"op":"mcm","clk":"11540531071","pt":1719495583432,"mc":[{"id":"1.230180115","rc":[{"atb":[[1.85,2]],"id":44213406}],"con":true,"img":false}]}
{"op":"mcm","clk":"11540531115","pt":1719495583907,"mc":[{"id":"1.230180115","rc":[{"atb":[[1.02,0]],"id":63387150}],"con":true,"img":false}]}
{"op":"mcm","clk":"11540531127","pt":1719495584009,"mc":[{"id":"1.230180115","rc":[{"atb":[[2.22,2]],"id":63387150}],"con":true,"img":false}]}
{"op":"mcm","clk":"11540531265","pt":1719495585500,"mc":[{"id":"1.230180115","rc":[{"atb":[[2.22,0]],"id":63387150}],"con":true,"img":false}]}
{"op":"mcm","clk":"11540531269","pt":1719495585609,"mc":[{"id":"1.230180115","rc":[{"atb":[[1.02,2]],"id":63387150}],"con":true,"img":false}]}
{"op":"mcm","clk":"11540531403","pt":1719495587313,"mc":[{"id":"1.230180115","rc":[{"atb":[[1.02,0]],"id":63387150}],"con":true,"img":false}]}
{"op":"mcm","clk":"11540531412","pt":1719495587416,"mc":[{"id":"1.230180115","rc":[{"atb":[[2.22,2]],"id":63387150}],"con":true,"img":false}]}
{"op":"mcm","clk":"11540531595","pt":1719495589640,"mc":[{"id":"1.230180115","rc":[{"atb":[[2.22,0]],"id":63387150}],"con":true,"img":false}]}
{"op":"mcm","clk":"11540531606","pt":1719495589704,"mc":[{"id":"1.230180115","rc":[{"atb":[[1.02,2]],"id":63387150}],"con":true,"img":false}]}
{"op":"mcm","clk":"11540531737","pt":1719495591414,"mc":[{"id":"1.230180115","rc":[{"atb":[[1.02,0]],"id":63387150}],"con":true,"img":false}]}
{"op":"mcm","clk":"11540531746","pt":1719495591517,"mc":[{"id":"1.230180115","rc":[{"atb":[[2.22,2]],"id":63387150}],"con":true,"img":false}]}
{"op":"mcm","clk":"11540531901","pt":1719495593449,"mc":[{"id":"1.230180115","rc":[{"atb":[[2.22,0]],"id":63387150}],"con":true,"img":false}]}
{"op":"mcm","clk":"11540531912","pt":1719495593547,"mc":[{"id":"1.230180115","rc":[{"atb":[[1.02,2]],"id":63387150}],"con":true,"img":false}]}
{"op":"mcm","clk":"11540531923","pt":1719495593649,"mc":[{"id":"1.230180115","rc":[{"atb":[[1.78,0]],"id":61150133}],"con":true,"img":false}]}
{"op":"mcm","clk":"11540532127","pt":1719495596524,"mc":[{"id":"1.230180115","rc":[{"atb":[[1.79,0]],"id":44213406},{"spn":3.52,"spf":"NaN","id":44213406},{"spn":1.73,"spf":"NaN","id":39682601},{"atb":[[1.02,0]],"id":63387150}],"con":true,"img":false}]}
{"op":"mcm","clk":"11540532134","pt":1719495596628,"mc":[{"id":"1.230180115","rc":[{"atb":[[2.22,2]],"id":63387150}],"con":true,"img":false}]}
{"op":"mcm","clk":"11540532274","pt":1719495598126,"mc":[{"id":"1.230180115","rc":[{"atb":[[2.22,0]],"id":63387150}],"con":true,"img":false}]}
{"op":"mcm","clk":"11540532279","pt":1719495598229,"mc":[{"id":"1.230180115","rc":[{"atb":[[1.02,2]],"id":63387150}],"con":true,"img":false}]}
{"op":"mcm","clk":"11540532343","pt":1719495599114,"mc":[{"id":"1.230180115","rc":[{"atb":[[1.13,1]],"id":39682601}],"con":true,"img":false}]}
{"op":"mcm","clk":"11540532373","pt":1719495599533,"mc":[{"id":"1.230180115","rc":[{"atb":[[1.02,0]],"id":63387150}],"con":true,"img":false}]}
{"op":"mcm","clk":"11540532381","pt":1719495599632,"mc":[{"id":"1.230180115","rc":[{"atb":[[2.22,2]],"id":63387150}],"con":true,"img":false}]}
{"op":"mcm","clk":"11540532464","pt":1719495600526,"mc":[{"id":"1.230180115","rc":[{"atb":[[1.2,31.64]],"id":39682601}],"con":true,"img":false}]}
{"op":"mcm","clk":"11540532476","pt":1719495600626,"mc":[{"id":"1.230180115","rc":[{"atb":[[1.21,28.23],[1.19,0]],"id":39682601}],"con":true,"img":false}]}
{"op":"mcm","clk":"11540532501","pt":1719495600957,"mc":[{"id":"1.230180115","rc":[{"atb":[[1.83,0]],"id":44213406}],"con":true,"img":false}]}
{"op":"mcm","clk":"11540532541","pt":1719495601429,"mc":[{"id":"1.230180115","rc":[{"atb":[[1.2,29.64]],"id":39682601}],"con":true,"img":false}]}
{"op":"mcm","clk":"11540532551","pt":1719495601537,"mc":[{"id":"1.230180115","rc":[{"atb":[[1.22,2]],"id":39682601}],"con":true,"img":false}]}
{"op":"mcm","clk":"11540532576","pt":1719495601850,"mc":[{"id":"1.230180115","rc":[{"atb":[[1.85,0]],"id":44213406}],"con":true,"img":false}]}
{"op":"mcm","clk":"11540532585","pt":1719495601955,"mc":[{"id":"1.230180115","rc":[{"atb":[[1.02,10.47]],"id":44213406}],"con":true,"img":false}]}
{"op":"mcm","clk":"11540532593","pt":1719495602053,"mc":[{"id":"1.230180115","rc":[{"atb":[[1.84,0],[1.76,9.52]],"id":44213406}],"con":true,"img":false}]}
{"op":"mcm","clk":"11540532619","pt":1719495602424,"mc":[{"id":"1.230180115","rc":[{"atb":[[2.22,0]],"id":63387150}],"con":true,"img":false}]}
{"op":"mcm","clk":"11540532628","pt":1719495602525,"mc":[{"id":"1.230180115","rc":[{"atb":[[1.02,2]],"id":63387150}],"con":true,"img":false}]}
{"op":"mcm","clk":"11540532831","pt":1719495604825,"mc":[{"id":"1.230180115","rc":[{"atb":[[1.02,8.47]],"id":44213406}],"con":true,"img":false}]}
{"op":"mcm","clk":"11540532840","pt":1719495604927,"mc":[{"id":"1.230180115","rc":[{"atb":[[1.77,2]],"id":44213406}],"con":true,"img":false}]}
{"op":"mcm","clk":"11540532881","pt":1719495605446,"mc":[{"id":"1.230180115","rc":[{"atb":[[1.02,0]],"id":63387150}],"con":true,"img":false}]}
{"op":"mcm","clk":"11540532889","pt":1719495605548,"mc":[{"id":"1.230180115","rc":[{"atb":[[2.22,2]],"id":63387150}],"con":true,"img":false}]}
{"op":"mcm","clk":"11540533808","pt":1719495616151,"mc":[{"id":"1.230180115","rc":[{"atb":[[1.77,0]],"id":44213406}],"con":true,"img":false}]}
{"op":"mcm","clk":"11540533819","pt":1719495616261,"mc":[{"id":"1.230180115","rc":[{"atb":[[1.02,10.47]],"id":44213406}],"con":true,"img":false}]}
{"op":"mcm","clk":"11540533855","pt":1719495616665,"mc":[{"id":"1.230180115","rc":[{"atb":[[2.22,0]],"id":63387150}],"con":true,"img":false}]}
{"op":"mcm","clk":"11540533864","pt":1719495616767,"mc":[{"id":"1.230180115","rc":[{"atb":[[1.02,2]],"id":63387150}],"con":true,"img":false}]}
{"op":"mcm","clk":"11540534161","pt":1719495620045,"mc":[{"id":"1.230180115","rc":[{"atb":[[1.02,8.47]],"id":44213406}],"con":true,"img":false}]}
{"op":"mcm","clk":"11540534168","pt":1719495620150,"mc":[{"id":"1.230180115","rc":[{"atb":[[1.77,2]],"id":44213406}],"con":true,"img":false}]}
{"op":"mcm","clk":"11540534210","pt":1719495620664,"mc":[{"id":"1.230180115","rc":[{"atb":[[1.17,0]],"id":39682601},{"atb":[[1.02,0]],"id":63387150}],"con":true,"img":false}]}
{"op":"mcm","clk":"11540534218","pt":1719495620772,"mc":[{"id":"1.230180115","rc":[{"atb":[[2.22,2]],"id":63387150}],"con":true,"img":false}]}
{"op":"mcm","clk":"11540534379","pt":1719495622282,"mc":[{"id":"1.230180115","rc":[{"atb":[[1.77,0]],"id":44213406}],"con":true,"img":false}]}
{"op":"mcm","clk":"11540534391","pt":1719495622332,"mc":[{"id":"1.230180115","rc":[{"atb":[[1.02,10.47]],"id":44213406}],"con":true,"img":false}]}
{"op":"mcm","clk":"11540534429","pt":1719495622761,"mc":[{"id":"1.230180115","rc":[{"atb":[[2.22,0]],"id":63387150}],"con":true,"img":false}]}
{"op":"mcm","clk":"11540534442","pt":1719495622865,"mc":[{"id":"1.230180115","rc":[{"atb":[[1.02,2]],"id":63387150}],"con":true,"img":false}]}
{"op":"mcm","clk":"11540534656","pt":1719495625167,"mc":[{"id":"1.230180115","rc":[{"atb":[[1.02,8.47]],"id":44213406}],"con":true,"img":false}]}
{"op":"mcm","clk":"11540534668","pt":1719495625271,"mc":[{"id":"1.230180115","rc":[{"atb":[[1.77,2]],"id":44213406}],"con":true,"img":false}]}
{"op":"mcm","clk":"11540534718","pt":1719495625691,"mc":[{"id":"1.230180115","rc":[{"atb":[[1.02,0]],"id":63387150}],"con":true,"img":false}]}
{"op":"mcm","clk":"11540534726","pt":1719495625786,"mc":[{"id":"1.230180115","rc":[{"atb":[[2.22,2]],"id":63387150}],"con":true,"img":false}]}
{"op":"mcm","clk":"11540534998","pt":1719495628508,"mc":[{"id":"1.230180115","rc":[{"atb":[[1.77,0]],"id":44213406}],"con":true,"img":false}]}
{"op":"mcm","clk":"11540535008","pt":1719495628598,"mc":[{"id":"1.230180115","rc":[{"atb":[[1.02,10.47]],"id":44213406}],"con":true,"img":false}]}
{"op":"mcm","clk":"11540535039","pt":1719495628966,"mc":[{"id":"1.230180115","rc":[{"atb":[[2.22,0]],"id":63387150}],"con":true,"img":false}]}
{"op":"mcm","clk":"11540535044","pt":1719495629066,"mc":[{"id":"1.230180115","rc":[{"atb":[[1.02,2]],"id":63387150}],"con":true,"img":false}]}
{"op":"mcm","clk":"11540535286","pt":1719495631520,"mc":[{"id":"1.230180115","rc":[{"atb":[[1.02,8.47]],"id":44213406}],"con":true,"img":false}]}
{"op":"mcm","clk":"11540535298","pt":1719495631567,"mc":[{"id":"1.230180115","rc":[{"atb":[[1.77,2]],"id":44213406}],"con":true,"img":false}]}
{"op":"mcm","clk":"11540535333","pt":1719495631996,"mc":[{"id":"1.230180115","rc":[{"atb":[[1.02,0]],"id":63387150}],"con":true,"img":false}]}
{"op":"mcm","clk":"11540535344","pt":1719495632080,"mc":[{"id":"1.230180115","rc":[{"atb":[[2.22,2]],"id":63387150}],"con":true,"img":false}]}
{"op":"mcm","clk":"11540535459","pt":1719495633389,"mc":[{"id":"1.230180115","rc":[{"atb":[[1.77,0]],"id":44213406}],"con":true,"img":false}]}
{"op":"mcm","clk":"11540535471","pt":1719495633507,"mc":[{"id":"1.230180115","rc":[{"atb":[[1.02,10.47]],"id":44213406}],"con":true,"img":false}]}
{"op":"mcm","clk":"11540535511","pt":1719495634006,"mc":[{"id":"1.230180115","rc":[{"atb":[[2.22,0]],"id":63387150}],"con":true,"img":false}]}
{"op":"mcm","clk":"11540535519","pt":1719495634059,"mc":[{"id":"1.230180115","rc":[{"atb":[[1.02,2]],"id":63387150}],"con":true,"img":false}]}
{"op":"mcm","clk":"11540535738","pt":1719495636637,"mc":[{"id":"1.230180115","rc":[{"atb":[[1.02,8.47]],"id":44213406}],"con":true,"img":false}]}
{"op":"mcm","clk":"11540535750","pt":1719495636724,"mc":[{"id":"1.230180115","rc":[{"atb":[[1.77,2]],"id":44213406}],"con":true,"img":false}]}
{"op":"mcm","clk":"11540535779","pt":1719495636988,"mc":[{"id":"1.230180115","rc":[{"atb":[[1.02,0]],"id":63387150}],"con":true,"img":false}]}
{"op":"mcm","clk":"11540535793","pt":1719495637087,"mc":[{"id":"1.230180115","rc":[{"atb":[[2.22,2]],"id":63387150}],"con":true,"img":false}]}
{"op":"mcm","clk":"11540536057","pt":1719495639776,"mc":[{"id":"1.230180115","rc":[{"atb":[[1.77,0]],"id":44213406}],"con":true,"img":false}]}
{"op":"mcm","clk":"11540536069","pt":1719495639882,"mc":[{"id":"1.230180115","rc":[{"atb":[[1.02,10.47]],"id":44213406}],"con":true,"img":false}]}
{"op":"mcm","clk":"11540536090","pt":1719495640195,"mc":[{"id":"1.230180115","rc":[{"atb":[[1.2,0]],"id":39682601}],"con":true,"img":false}]}
{"op":"mcm","clk":"11540536101","pt":1719495640301,"mc":[{"id":"1.230180115","rc":[{"atb":[[2.22,0]],"id":63387150}],"con":true,"img":false}]}
{"op":"mcm","clk":"11540536110","pt":1719495640401,"mc":[{"id":"1.230180115","rc":[{"atb":[[1.02,2]],"id":63387150}],"con":true,"img":false}]}
{"op":"mcm","clk":"11540536325","pt":1719495642585,"mc":[{"id":"1.230180115","rc":[{"atb":[[1.02,8.47]],"id":44213406}],"con":true,"img":false}]}
{"op":"mcm","clk":"11540536336","pt":1719495642690,"mc":[{"id":"1.230180115","rc":[{"atb":[[1.77,2]],"id":44213406}],"con":true,"img":false}]}
{"op":"mcm","clk":"11540536362","pt":1719495643002,"mc":[{"id":"1.230180115","rc":[{"atb":[[1.02,0]],"id":63387150}],"con":true,"img":false}]}
{"op":"mcm","clk":"11540536372","pt":1719495643109,"mc":[{"id":"1.230180115","rc":[{"atb":[[2.22,2]],"id":63387150}],"con":true,"img":false}]}
{"op":"mcm","clk":"11540536543","pt":1719495645017,"mc":[{"id":"1.230180115","rc":[{"atb":[[1.77,0]],"id":44213406}],"con":true,"img":false}]}
{"op":"mcm","clk":"11540536557","pt":1719495645122,"mc":[{"id":"1.230180115","rc":[{"atb":[[1.02,10.47]],"id":44213406}],"con":true,"img":false}]}
{"op":"mcm","clk":"11540536586","pt":1719495645389,"mc":[{"id":"1.230180115","rc":[{"atb":[[2.22,0]],"id":63387150}],"con":true,"img":false}]}
{"op":"mcm","clk":"11540536597","pt":1719495645488,"mc":[{"id":"1.230180115","rc":[{"atb":[[1.02,2]],"id":63387150}],"con":true,"img":false}]}
{"op":"mcm","clk":"11540536788","pt":1719495647521,"mc":[{"id":"1.230180115","rc":[{"atb":[[1.02,8.47]],"id":44213406}],"con":true,"img":false}]}
{"op":"mcm","clk":"11540536795","pt":1719495647615,"mc":[{"id":"1.230180115","rc":[{"atb":[[1.77,2]],"id":44213406}],"con":true,"img":false}]}
{"op":"mcm","clk":"11540536821","pt":1719495647993,"mc":[{"id":"1.230180115","rc":[{"atb":[[1.02,0]],"id":63387150}],"con":true,"img":false}]}
{"op":"mcm","clk":"11540536828","pt":1719495648099,"mc":[{"id":"1.230180115","rc":[{"atb":[[2.22,2]],"id":63387150}],"con":true,"img":false}]}
{"op":"mcm","clk":"11540537004","pt":1719495649933,"mc":[{"id":"1.230180115","rc":[{"atb":[[1.77,0]],"id":44213406}],"con":true,"img":false}]}
{"op":"mcm","clk":"11540537016","pt":1719495650025,"mc":[{"id":"1.230180115","rc":[{"atb":[[1.02,10.47]],"id":44213406}],"con":true,"img":false}]}
{"op":"mcm","clk":"11540537055","pt":1719495650388,"mc":[{"id":"1.230180115","rc":[{"atb":[[2.22,0]],"id":63387150}],"con":true,"img":false}]}
{"op":"mcm","clk":"11540537067","pt":1719495650498,"mc":[{"id":"1.230180115","rc":[{"atb":[[1.02,2]],"id":63387150}],"con":true,"img":false}]}
{"op":"mcm","clk":"11540537156","pt":1719495651337,"mc":[{"id":"1.230180115","rc":[{"atb":[[1.02,8.47]],"id":44213406}],"con":true,"img":false}]}
{"op":"mcm","clk":"11540537168","pt":1719495651390,"mc":[{"id":"1.230180115","rc":[{"atb":[[1.77,2]],"id":44213406}],"con":true,"img":false}]}
{"op":"mcm","clk":"11540537201","pt":1719495651712,"mc":[{"id":"1.230180115","rc":[{"atb":[[1.02,0]],"id":63387150}],"con":true,"img":false}]}
{"op":"mcm","clk":"11540537213","pt":1719495651819,"mc":[{"id":"1.230180115","rc":[{"atb":[[2.22,2]],"id":63387150}],"con":true,"img":false}]}
{"op":"mcm","clk":"11540537392","pt":1719495653588,"mc":[{"id":"1.230180115","rc":[{"atb":[[1.77,0]],"id":44213406}],"con":true,"img":false}]}
{"op":"mcm","clk":"11540537402","pt":1719495653707,"mc":[{"id":"1.230180115","rc":[{"atb":[[1.02,10.47]],"id":44213406}],"con":true,"img":false}]}
{"op":"mcm","clk":"11540537457","pt":1719495654310,"mc":[{"id":"1.230180115","rc":[{"atb":[[2.22,0]],"id":63387150}],"con":true,"img":false}]}
{"op":"mcm","clk":"11540537472","pt":1719495654426,"mc":[{"id":"1.230180115","rc":[{"atb":[[1.02,2]],"id":63387150}],"con":true,"img":false}]}
{"op":"mcm","clk":"11540537590","pt":1719495655825,"mc":[{"id":"1.230180115","rc":[{"atb":[[1.02,8.47]],"id":44213406}],"con":true,"img":false}]}
{"op":"mcm","clk":"11540537599","pt":1719495655924,"mc":[{"id":"1.230180115","rc":[{"atb":[[1.77,2]],"id":44213406}],"con":true,"img":false}]}
{"op":"mcm","clk":"11540537622","pt":1719495656193,"mc":[{"id":"1.230180115","rc":[{"atb":[[1.02,0]],"id":63387150}],"con":true,"img":false}]}
{"op":"mcm","clk":"11540537637","pt":1719495656303,"mc":[{"id":"1.230180115","rc":[{"atb":[[2.22,2]],"id":63387150}],"con":true,"img":false}]}
{"op":"mcm","clk":"11540537772","pt":1719495657705,"mc":[{"id":"1.230180115","rc":[{"atb":[[1.77,0]],"id":44213406},{"spn":3.48,"spf":"NaN","id":44213406},{"spn":1.74,"spf":"NaN","id":39682601},{"spn":4.91,"spf":"NaN","id":63387150}],"con":true,"img":false}]}
{"op":"mcm","clk":"11540537786","pt":1719495657810,"mc":[{"id":"1.230180115","rc":[{"atb":[[1.02,10.47]],"id":44213406}],"con":true,"img":false}]}
{"op":"mcm","clk":"11540537816","pt":1719495658123,"mc":[{"id":"1.230180115","rc":[{"atb":[[2.22,0]],"id":63387150}],"con":true,"img":false}]}
{"op":"mcm","clk":"11540537830","pt":1719495658239,"mc":[{"id":"1.230180115","rc":[{"atb":[[1.02,2]],"id":63387150}],"con":true,"img":false}]}
{"op":"mcm","clk":"11540537946","pt":1719495659632,"mc":[{"id":"1.230180115","rc":[{"atb":[[1.02,8.47]],"id":44213406}],"con":true,"img":false}]}
{"op":"mcm","clk":"11540537960","pt":1719495659741,"mc":[{"id":"1.230180115","rc":[{"atb":[[1.77,2]],"id":44213406}],"con":true,"img":false}]}
{"op":"mcm","clk":"11540538001","pt":1719495660105,"mc":[{"id":"1.230180115","rc":[{"atb":[[1.02,0]],"id":63387150}],"con":true,"img":false}]}
{"op":"mcm","clk":"11540538012","pt":1719495660210,"mc":[{"id":"1.230180115","rc":[{"atb":[[2.22,2]],"id":63387150}],"con":true,"img":false}]}
{"op":"mcm","clk":"11540538214","pt":1719495662333,"mc":[{"id":"1.230180115","rc":[{"atb":[[1.77,0]],"id":44213406}],"con":true,"img":false}]}
{"op":"mcm","clk":"11540538224","pt":1719495662393,"mc":[{"id":"1.230180115","rc":[{"atb":[[1.02,10.47]],"id":44213406}],"con":true,"img":false}]}
{"op":"mcm","clk":"11540538249","pt":1719495662703,"mc":[{"id":"1.230180115","rc":[{"atb":[[2.22,0]],"id":63387150}],"con":true,"img":false}]}
{"op":"mcm","clk":"11540538262","pt":1719495662808,"mc":[{"id":"1.230180115","rc":[{"atb":[[1.02,2]],"id":63387150}],"con":true,"img":false}]}
{"op":"mcm","clk":"11540538523","pt":1719495665616,"mc":[{"id":"1.230180115","rc":[{"atb":[[1.02,8.47]],"id":44213406}],"con":true,"img":false}]}
{"op":"mcm","clk":"11540538535","pt":1719495665720,"mc":[{"id":"1.230180115","rc":[{"atb":[[1.77,2]],"id":44213406}],"con":true,"img":false}]}
{"op":"mcm","clk":"11540538570","pt":1719495666033,"mc":[{"id":"1.230180115","rc":[{"atb":[[1.02,0]],"id":63387150}],"con":true,"img":false}]}
{"op":"mcm","clk":"11540538580","pt":1719495666138,"mc":[{"id":"1.230180115","rc":[{"atb":[[2.22,2]],"id":63387150}],"con":true,"img":false}]}
{"op":"mcm","clk":"11540538654","pt":1719495666928,"mc":[{"id":"1.230180115","rc":[{"atb":[[1.77,0]],"id":44213406}],"con":true,"img":false}]}
{"op":"mcm","clk":"11540538667","pt":1719495667023,"mc":[{"id":"1.230180115","rc":[{"atb":[[1.02,10.47]],"id":44213406}],"con":true,"img":false}]}
{"op":"mcm","clk":"11540538694","pt":1719495667348,"mc":[{"id":"1.230180115","rc":[{"atb":[[2.22,0]],"id":63387150}],"con":true,"img":false}]}
{"op":"mcm","clk":"11540538705","pt":1719495667437,"mc":[{"id":"1.230180115","rc":[{"atb":[[1.02,2]],"id":63387150}],"con":true,"img":false}]}
{"op":"mcm","clk":"11540538819","pt":1719495668647,"mc":[{"id":"1.230180115","rc":[{"atb":[[1.02,8.47]],"id":44213406}],"con":true,"img":false}]}
{"op":"mcm","clk":"11540538830","pt":1719495668750,"mc":[{"id":"1.230180115","rc":[{"atb":[[1.77,2]],"id":44213406}],"con":true,"img":false}]}
{"op":"mcm","clk":"11540538879","pt":1719495669215,"mc":[{"id":"1.230180115","rc":[{"atb":[[1.02,0]],"id":63387150}],"con":true,"img":false}]}
{"op":"mcm","clk":"11540538892","pt":1719495669317,"mc":[{"id":"1.230180115","rc":[{"atb":[[2.22,2]],"id":63387150}],"con":true,"img":false}]}
{"op":"mcm","clk":"11540539072","pt":1719495671240,"mc":[{"id":"1.230180115","rc":[{"atb":[[1.77,0]],"id":44213406}],"con":true,"img":false}]}
{"op":"mcm","clk":"11540539083","pt":1719495671344,"mc":[{"id":"1.230180115","rc":[{"atb":[[1.02,10.47]],"id":44213406}],"con":true,"img":false}]}
{"op":"mcm","clk":"11540539104","pt":1719495671550,"mc":[{"id":"1.230180115","rc":[{"atb":[[2.22,0]],"id":63387150}],"con":true,"img":false}]}
{"op":"mcm","clk":"11540539113","pt":1719495671652,"mc":[{"id":"1.230180115","rc":[{"atb":[[1.02,2]],"id":63387150}],"con":true,"img":false}]}
{"op":"mcm","clk":"11540539349","pt":1719495673935,"mc":[{"id":"1.230180115","rc":[{"atb":[[1.02,8.47]],"id":44213406}],"con":true,"img":false}]}
{"op":"mcm","clk":"11540539362","pt":1719495674046,"mc":[{"id":"1.230180115","rc":[{"atb":[[1.77,2]],"id":44213406}],"con":true,"img":false}]}
{"op":"mcm","clk":"11540539376","pt":1719495674264,"mc":[{"id":"1.230180115","rc":[{"atb":[[1.02,0]],"id":63387150}],"con":true,"img":false}]}
{"op":"mcm","clk":"11540539385","pt":1719495674343,"mc":[{"id":"1.230180115","rc":[{"atb":[[2.22,2]],"id":63387150}],"con":true,"img":false}]}
{"op":"mcm","clk":"11540539532","pt":1719495675852,"mc":[{"id":"1.230180115","rc":[{"atb":[[1.77,0]],"id":44213406}],"con":true,"img":false}]}
{"op":"mcm","clk":"11540539542","pt":1719495675955,"mc":[{"id":"1.230180115","rc":[{"atb":[[1.02,10.47]],"id":44213406}],"con":true,"img":false}]}
{"op":"mcm","clk":"11540539577","pt":1719495676217,"mc":[{"id":"1.230180115","rc":[{"atb":[[2.22,0]],"id":63387150}],"con":true,"img":false}]}
{"op":"mcm","clk":"11540539590","pt":1719495676331,"mc":[{"id":"1.230180115","rc":[{"atb":[[1.02,2]],"id":63387150}],"con":true,"img":false}]}
{"op":"mcm","clk":"11540539786","pt":1719495678249,"mc":[{"id":"1.230180115","rc":[{"atb":[[1.02,8.47]],"id":44213406}],"con":true,"img":false}]}
{"op":"mcm","clk":"11540539799","pt":1719495678352,"mc":[{"id":"1.230180115","rc":[{"atb":[[1.77,2]],"id":44213406}],"con":true,"img":false}]}
{"op":"mcm","clk":"11540539807","pt":1719495678442,"mc":[{"id":"1.230180115","rc":[{"atb":[[1.18,0]],"id":39682601}],"con":true,"img":false}]}
{"op":"mcm","clk":"11540539829","pt":1719495678658,"mc":[{"id":"1.230180115","rc":[{"atb":[[1.02,0]],"id":63387150}],"con":true,"img":false}]}
{"op":"mcm","clk":"11540539838","pt":1719495678760,"mc":[{"id":"1.230180115","rc":[{"atb":[[2.22,2]],"id":63387150}],"con":true,"img":false}]}
{"op":"mcm","clk":"11540539886","pt":1719495679235,"mc":[{"id":"1.230180115","rc":[{"atb":[[1.15,0]],"id":39682601}],"con":true,"img":false}]}
{"op":"mcm","clk":"11540540093","pt":1719495681450,"mc":[{"id":"1.230180115","rc":[{"atb":[[1.77,0]],"id":44213406}],"con":true,"img":false}]}
{"op":"mcm","clk":"11540540101","pt":1719495681553,"mc":[{"id":"1.230180115","rc":[{"atb":[[1.02,10.47]],"id":44213406}],"con":true,"img":false}]}
{"op":"mcm","clk":"11540540119","pt":1719495681817,"mc":[{"id":"1.230180115","rc":[{"atb":[[2.22,0]],"id":63387150}],"con":true,"img":false}]}
{"op":"mcm","clk":"11540540127","pt":1719495681921,"mc":[{"id":"1.230180115","rc":[{"atb":[[1.02,2]],"id":63387150}],"con":true,"img":false}]}
{"op":"mcm","clk":"11540540230","pt":1719495683422,"mc":[{"id":"1.230180115","rc":[{"atb":[[1.22,28.95]],"id":39682601}],"con":true,"img":false}]}
{"op":"mcm","clk":"11540540247","pt":1719495683627,"mc":[{"id":"1.230180115","rc":[{"atb":[[1.21,0],[1.23,28.23]],"id":39682601}],"con":true,"img":false}]}
{"op":"mcm","clk":"11540540289","pt":1719495684348,"mc":[{"id":"1.230180115","rc":[{"atb":[[1.22,26.95]],"id":39682601}],"con":true,"img":false}]}
{"op":"mcm","clk":"11540540296","pt":1719495684458,"mc":[{"id":"1.230180115","rc":[{"atb":[[1.24,2]],"id":39682601}],"con":true,"img":false}]}
{"op":"mcm","clk":"11540540333","pt":1719495684968,"mc":[{"id":"1.230180115","rc":[{"atb":[[1.02,8.47]],"id":44213406}],"con":true,"img":false}]}
{"op":"mcm","clk":"11540540344","pt":1719495685031,"mc":[{"id":"1.230180115","rc":[{"atb":[[1.77,2]],"id":44213406}],"con":true,"img":false}]}
{"op":"mcm","clk":"11540540377","pt":1719495685543,"mc":[{"id":"1.230180115","rc":[{"atb":[[1.02,0]],"id":63387150}],"con":true,"img":false}]}
{"op":"mcm","clk":"11540540386","pt":1719495685644,"mc":[{"id":"1.230180115","rc":[{"atb":[[2.22,2]],"id":63387150}],"con":true,"img":false}]}
{"op":"mcm","clk":"11540540549","pt":1719495687653,"mc":[{"id":"1.230180115","rc":[{"atb":[[1.77,0]],"id":44213406}],"con":true,"img":false}]}
{"op":"mcm","clk":"11540540559","pt":1719495687762,"mc":[{"id":"1.230180115","rc":[{"atb":[[1.02,10.47]],"id":44213406}],"con":true,"img":false}]}
{"op":"mcm","clk":"11540540587","pt":1719495688015,"mc":[{"id":"1.230180115","rc":[{"atb":[[2.22,0]],"id":63387150}],"con":true,"img":false}]}
{"op":"mcm","clk":"11540540595","pt":1719495688126,"mc":[{"id":"1.230180115","rc":[{"atb":[[1.02,2]],"id":63387150}],"con":true,"img":false}]}
{"op":"mcm","clk":"11540540786","pt":1719495690652,"mc":[{"id":"1.230180115","rc":[{"atb":[[1.02,8.47]],"id":44213406}],"con":true,"img":false}]}
{"op":"mcm","clk":"11540540793","pt":1719495690757,"mc":[{"id":"1.230180115","rc":[{"atb":[[1.77,2]],"id":44213406}],"con":true,"img":false}]}
{"op":"mcm","clk":"11540540824","pt":1719495691061,"mc":[{"id":"1.230180115","rc":[{"atb":[[1.02,0]],"id":63387150}],"con":true,"img":false}]}
{"op":"mcm","clk":"11540540829","pt":1719495691167,"mc":[{"id":"1.230180115","rc":[{"atb":[[2.22,2]],"id":63387150}],"con":true,"img":false}]}
{"op":"mcm","clk":"11540540915","pt":1719495692353,"mc":[{"id":"1.230180115","rc":[{"atb":[[1.77,0]],"id":44213406}],"con":true,"img":false}]}
{"op":"mcm","clk":"11540540922","pt":1719495692454,"mc":[{"id":"1.230180115","rc":[{"atb":[[1.02,10.47]],"id":44213406}],"con":true,"img":false}]}
{"op":"mcm","clk":"11540540959","pt":1719495692816,"mc":[{"id":"1.230180115","rc":[{"atb":[[2.22,0]],"id":63387150}],"con":true,"img":false}]}
{"op":"mcm","clk":"11540540968","pt":1719495692921,"mc":[{"id":"1.230180115","rc":[{"atb":[[1.02,2]],"id":63387150}],"con":true,"img":false}]}
{"op":"mcm","clk":"11540541105","pt":1719495694419,"mc":[{"id":"1.230180115","rc":[{"atb":[[1.02,8.47]],"id":44213406}],"con":true,"img":false}]}
{"op":"mcm","clk":"11540541114","pt":1719495694523,"mc":[{"id":"1.230180115","rc":[{"atb":[[1.77,2]],"id":44213406}],"con":true,"img":false}]}
{"op":"mcm","clk":"11540541139","pt":1719495694835,"mc":[{"id":"1.230180115","rc":[{"atb":[[1.02,0]],"id":63387150}],"con":true,"img":false}]}
{"op":"mcm","clk":"11540541150","pt":1719495694941,"mc":[{"id":"1.230180115","rc":[{"atb":[[2.22,2]],"id":63387150}],"con":true,"img":false}]}
{"op":"mcm","clk":"11540541318","pt":1719495697065,"mc":[{"id":"1.230180115","rc":[{"atb":[[1.77,0]],"id":44213406}],"con":true,"img":false}]}
{"op":"mcm","clk":"11540541326","pt":1719495697160,"mc":[{"id":"1.230180115","rc":[{"atb":[[1.02,10.47]],"id":44213406}],"con":true,"img":false}]}
{"op":"mcm","clk":"11540541353","pt":1719495697470,"mc":[{"id":"1.230180115","rc":[{"atb":[[2.22,0]],"id":63387150}],"con":true,"img":false}]}
{"op":"mcm","clk":"11540541367","pt":1719495697595,"mc":[{"id":"1.230180115","rc":[{"atb":[[1.02,2]],"id":63387150}],"con":true,"img":false}]}
{"op":"mcm","clk":"11540541465","pt":1719495698660,"mc":[{"id":"1.230180115","rc":[{"atb":[[1.24,25.04]],"id":39682601}],"con":true,"img":false}]}
{"op":"mcm","clk":"11540541474","pt":1719495698762,"mc":[{"id":"1.230180115","rc":[{"atb":[[1.02,8.47]],"id":44213406}],"con":true,"img":false}]}
{"op":"mcm","clk":"11540541481","pt":1719495698865,"mc":[{"id":"1.230180115","rc":[{"atb":[[1.77,2]],"id":44213406},{"atb":[[1.25,26.95],[1.23,0]],"id":39682601}],"con":true,"img":false}]}
{"op":"mcm","clk":"11540541507","pt":1719495699186,"mc":[{"id":"1.230180115","rc":[{"atb":[[1.02,0]],"id":63387150}],"con":true,"img":false}]}
{"op":"mcm","clk":"11540541517","pt":1719495699278,"mc":[{"id":"1.230180115","rc":[{"atb":[[2.22,2]],"id":63387150}],"con":true,"img":false}]}
{"op":"mcm","clk":"11540541613","pt":1719495700463,"mc":[{"id":"1.230180115","rc":[{"atb":[[1.24,23.04]],"id":39682601}],"con":true,"img":false}]}
{"op":"mcm","clk":"11540541623","pt":1719495700567,"mc":[{"id":"1.230180115","rc":[{"atb":[[1.26,2]],"id":39682601}],"con":true,"img":false}]}
{"op":"mcm","clk":"11540541646","pt":1719495700984,"mc":[{"id":"1.230180115","rc":[{"atb":[[1.77,0]],"id":44213406}],"con":true,"img":false}]}
{"op":"mcm","clk":"11540541654","pt":1719495701041,"mc":[{"id":"1.230180115","rc":[{"atb":[[1.02,10.47]],"id":44213406}],"con":true,"img":false}]}
{"op":"mcm","clk":"11540541687","pt":1719495701554,"mc":[{"id":"1.230180115","rc":[{"atb":[[2.22,0]],"id":63387150}],"con":true,"img":false}]}
{"op":"mcm","clk":"11540541695","pt":1719495701690,"mc":[{"id":"1.230180115","rc":[{"atb":[[1.02,2]],"id":63387150}],"con":true,"img":false}]}
{"op":"mcm","clk":"11540541761","pt":1719495702793,"mc":[{"id":"1.230180115","rc":[{"atb":[[1.02,8.47]],"id":44213406}],"con":true,"img":false}]}
{"op":"mcm","clk":"11540541769","pt":1719495702845,"mc":[{"id":"1.230180115","rc":[{"atb":[[1.77,2]],"id":44213406}],"con":true,"img":false}]}
{"op":"mcm","clk":"11540541793","pt":1719495703152,"mc":[{"id":"1.230180115","rc":[{"atb":[[1.02,0]],"id":63387150}],"con":true,"img":false}]}
{"op":"mcm","clk":"11540541802","pt":1719495703256,"mc":[{"id":"1.230180115","rc":[{"atb":[[2.22,2]],"id":63387150}],"con":true,"img":false}]}
{"op":"mcm","clk":"11540541919","pt":1719495704763,"mc":[{"id":"1.230180115","rc":[{"atb":[[1.77,0]],"id":44213406}],"con":true,"img":false}]}
{"op":"mcm","clk":"11540541927","pt":1719495704867,"mc":[{"id":"1.230180115","rc":[{"atb":[[1.02,10.47]],"id":44213406}],"con":true,"img":false}]}
{"op":"mcm","clk":"11540541952","pt":1719495705177,"mc":[{"id":"1.230180115","rc":[{"atb":[[2.22,0]],"id":63387150}],"con":true,"img":false}]}
{"op":"mcm","clk":"11540541958","pt":1719495705282,"mc":[{"id":"1.230180115","rc":[{"atb":[[1.02,2]],"id":63387150}],"con":true,"img":false}]}
{"op":"mcm","clk":"11540542137","pt":1719495707774,"mc":[{"id":"1.230180115","rc":[{"atb":[[1.02,8.47]],"id":44213406}],"con":true,"img":false}]}
{"op":"mcm","clk":"11540542152","pt":1719495707874,"mc":[{"id":"1.230180115","rc":[{"atb":[[1.77,2]],"id":44213406}],"con":true,"img":false}]}
{"op":"mcm","clk":"11540542174","pt":1719495708135,"mc":[{"id":"1.230180115","rc":[{"atb":[[1.02,0]],"id":63387150}],"con":true,"img":false}]}
{"op":"mcm","clk":"11540542185","pt":1719495708239,"mc":[{"id":"1.230180115","rc":[{"atb":[[2.22,2]],"id":63387150}],"con":true,"img":false}]}
{"op":"mcm","clk":"11540542320","pt":1719495710055,"mc":[{"id":"1.230180115","rc":[{"atb":[[1.77,0]],"id":44213406}],"con":true,"img":false}]}
{"op":"mcm","clk":"11540542331","pt":1719495710151,"mc":[{"id":"1.230180115","rc":[{"atb":[[1.02,10.47]],"id":44213406}],"con":true,"img":false}]}
{"op":"mcm","clk":"11540542362","pt":1719495710561,"mc":[{"id":"1.230180115","rc":[{"atb":[[2.22,0]],"id":63387150}],"con":true,"img":false}]}
{"op":"mcm","clk":"11540542371","pt":1719495710665,"mc":[{"id":"1.230180115","rc":[{"atb":[[1.02,2]],"id":63387150}],"con":true,"img":false}]}
{"op":"mcm","clk":"11540542534","pt":1719495713159,"mc":[{"id":"1.230180115","rc":[{"atb":[[1.02,8.47]],"id":44213406}],"con":true,"img":false}]}
{"op":"mcm","clk":"11540542541","pt":1719495713264,"mc":[{"id":"1.230180115","rc":[{"atb":[[1.77,2]],"id":44213406}],"con":true,"img":false}]}
{"op":"mcm","clk":"11540542575","pt":1719495713679,"mc":[{"id":"1.230180115","rc":[{"atb":[[1.02,0]],"id":63387150}],"con":true,"img":false}]}
{"op":"mcm","clk":"11540542585","pt":1719495713787,"mc":[{"id":"1.230180115","rc":[{"atb":[[2.22,2]],"id":63387150}],"con":true,"img":false}]}
{"op":"mcm","clk":"11540542803","pt":1719495716278,"mc":[{"id":"1.230180115","rc":[{"atb":[[1.77,0]],"id":44213406}],"con":true,"img":false}]}
{"op":"mcm","clk":"11540542813","pt":1719495716385,"mc":[{"id":"1.230180115","rc":[{"atb":[[1.02,10.47]],"id":44213406}],"con":true,"img":false}]}
{"op":"mcm","clk":"11540542843","pt":1719495716747,"mc":[{"id":"1.230180115","rc":[{"atb":[[2.22,0]],"id":63387150}],"con":true,"img":false}]}
{"op":"mcm","clk":"11540542851","pt":1719495716852,"mc":[{"id":"1.230180115","rc":[{"atb":[[1.02,2]],"id":63387150}],"con":true,"img":false}]}
{"op":"mcm","clk":"11540542864","pt":1719495717062,"mc":[{"id":"1.230180115","rc":[{"atb":[[1.24,0]],"id":39682601}],"con":true,"img":false}]}
{"op":"mcm","clk":"11540543055","pt":1719495719562,"mc":[{"id":"1.230180115","rc":[{"atb":[[1.02,8.47]],"id":44213406},{"spn":1.76,"spf":"NaN","id":39682601},{"spn":4.9,"spf":"NaN","id":63387150}],"con":true,"img":false}]}
{"op":"mcm","clk":"11540543065","pt":1719495719660,"mc":[{"id":"1.230180115","rc":[{"atb":[[1.77,2]],"id":44213406}],"con":true,"img":false}]}
{"op":"mcm","clk":"11540543076","pt":1719495719865,"mc":[{"id":"1.230180115","rc":[{"atb":[[1.02,0]],"id":63387150}],"con":true,"img":false}]}
{"op":"mcm","clk":"11540543082","pt":1719495719968,"mc":[{"id":"1.230180115","rc":[{"atb":[[1.22,0]],"id":39682601},{"atb":[[2.22,2]],"id":63387150}],"con":true,"img":false}]}
{"op":"mcm","clk":"11540543182","pt":1719495721175,"mc":[{"id":"1.230180115","rc":[{"atb":[[1.26,0]],"id":39682601}],"con":true,"img":false}]}
{"op":"mcm","clk":"11540543192","pt":1719495721272,"mc":[{"id":"1.230180115","rc":[{"atb":[[1.25,0],[1.03,55.26],[1.02,10.47]],"id":39682601}],"con":true,"img":false}]}
{"op":"mcm","clk":"11540543217","pt":1719495721591,"mc":[{"id":"1.230180115","rc":[{"atb":[[1.77,0]],"id":44213406}],"con":true,"img":false}]}
{"op":"mcm","clk":"11540543225","pt":1719495721688,"mc":[{"id":"1.230180115","rc":[{"atb":[[1.02,10.47]],"id":44213406}],"con":true,"img":false}]}
{"op":"mcm","clk":"11540543234","pt":1719495721797,"mc":[{"id":"1.230180115","rc":[{"atb":[[1.92,4],[1.91,0]],"id":41804643},{"atb":[[1.97,1],[1.86,0]],"id":61150133},{"atb":[[1.59,0],[1.55,1],[1.76,0],[1.69,19.04]],"id":44213406},{"atb":[[1.14,1],[1.13,0]],"id":39682601},{"atb":[[2.1,1]],"id":63387150}],"con":true,"img":false}]}
{"op":"mcm","clk":"11540543241","pt":1719495721897,"mc":[{"id":"1.230180115","rc":[{"atb":[[1.97,0],[2.18,3.75]],"id":63387150}],"con":true,"img":false}]}
{"op":"mcm","clk":"11540543260","pt":1719495722059,"mc":[{"id":"1.230180115","rc":[{"atb":[[2.22,0]],"id":63387150}],"con":true,"img":false}]}
{"op":"mcm","clk":"11540543268","pt":1719495722164,"mc":[{"id":"1.230180115","rc":[{"atb":[[1.02,2]],"id":63387150}],"con":true,"img":false}]}
{"op":"mcm","clk":"11540543326","pt":1719495722998,"mc":[{"id":"1.230180115","rc":[{"atb":[[2.18,0]],"id":63387150}],"con":true,"img":false}]}
{"op":"mcm","clk":"11540543451","pt":1719495724305,"mc":[{"id":"1.230180115","rc":[{"atb":[[1.02,8.47]],"id":39682601}],"con":true,"img":false}]}
{"op":"mcm","clk":"11540543462","pt":1719495724360,"mc":[{"id":"1.230180115","rc":[{"atb":[[1.04,2]],"id":39682601}],"con":true,"img":false}]}
{"op":"mcm","clk":"11540543495","pt":1719495724889,"mc":[{"id":"1.230180115","rc":[{"atb":[[1.02,8.47]],"id":44213406}],"con":true,"img":false}]}
{"op":"mcm","clk":"11540543503","pt":1719495725014,"mc":[{"id":"1.230180115","rc":[{"atb":[[1.7,2]],"id":44213406}],"con":true,"img":false}]}
{"op":"mcm","clk":"11540543532","pt":1719495725430,"mc":[{"id":"1.230180115","rc":[{"atb":[[1.02,0]],"id":63387150}],"con":true,"img":false}]}
{"op":"mcm","clk":"11540543539","pt":1719495725570,"mc":[{"id":"1.230180115","rc":[{"atb":[[2.22,2]],"id":63387150}],"con":true,"img":false}]}
{"op":"mcm","clk":"11540543651","pt":1719495726933,"mc":[{"id":"1.230180115","rc":[{"atb":[[1.7,0]],"id":44213406}],"con":true,"img":false}]}
{"op":"mcm","clk":"11540543668","pt":1719495727091,"mc":[{"id":"1.230180115","rc":[{"atb":[[1.02,10.47]],"id":44213406}],"con":true,"img":false}]}
{"op":"mcm","clk":"11540543704","pt":1719495727556,"mc":[{"id":"1.230180115","rc":[{"atb":[[2.22,0]],"id":63387150}],"con":true,"img":false}]}
{"op":"mcm","clk":"11540543714","pt":1719495727666,"mc":[{"id":"1.230180115","rc":[{"atb":[[1.02,2]],"id":63387150}],"con":true,"img":false}]}
{"op":"mcm","clk":"11540543748","pt":1719495728087,"mc":[{"id":"1.230180115","rc":[{"atb":[[1.54,3.12]],"id":44213406}],"con":true,"img":false}]}
{"op":"mcm","clk":"11540543832","pt":1719495728969,"mc":[{"id":"1.230180115","rc":[{"atb":[[1.02,0]],"id":63387150}],"con":true,"img":false}]}
{"op":"mcm","clk":"11540543845","pt":1719495729075,"mc":[{"id":"1.230180115","rc":[{"atb":[[2.22,2]],"id":63387150}],"con":true,"img":false}]}
{"op":"mcm","clk":"11540544026","pt":1719495731117,"mc":[{"id":"1.230180115","rc":[{"atb":[[1.54,0]],"id":44213406}],"con":true,"img":false}]}
{"op":"mcm","clk":"11540544070","pt":1719495731586,"mc":[{"id":"1.230180115","rc":[{"atb":[[2.22,0]],"id":63387150}],"con":true,"img":false}]}
{"op":"mcm","clk":"11540544080","pt":1719495731692,"mc":[{"id":"1.230180115","rc":[{"atb":[[1.02,2]],"id":63387150}],"con":true,"img":false}]}
{"op":"mcm","clk":"11540544165","pt":1719495732678,"mc":[{"id":"1.230180115","rc":[{"atb":[[1.08,50]],"id":41804643},{"atb":[[1.08,50]],"id":61150133},{"atb":[[1.08,50]],"id":44213406},{"atb":[[1.08,50]],"id":39682601},{"atb":[[1.08,50]],"id":63387150}],"con":true,"img":false}]}
{"op":"mcm","clk":"11540544173","pt":1719495732784,"mc":[{"id":"1.230180115","rc":[{"atb":[[1.03,0],[1.09,50]],"id":39682601}],"con":true,"img":false}]}
{"op":"mcm","clk":"11540544255","pt":1719495733875,"mc":[{"id":"1.230180115","rc":[{"atb":[[1.04,0]],"id":39682601}],"con":true,"img":false}]}
{"op":"mcm","clk":"11540544261","pt":1719495733983,"mc":[{"id":"1.230180115","rc":[{"atb":[[1.1,2]],"id":39682601}],"con":true,"img":false}]}
{"op":"mcm","clk":"11540544309","pt":1719495734607,"mc":[{"id":"1.230180115","rc":[{"atb":[[1.83,0]],"id":61150133}],"con":true,"img":false}]}
{"op":"mcm","clk":"11540544318","pt":1719495734710,"mc":[{"id":"1.230180115","rc":[{"atb":[[1.82,0],[1.02,2],[1.71,84.5]],"id":61150133}],"con":true,"img":false}]}
{"op":"mcm","clk":"11540544353","pt":1719495735189,"mc":[{"id":"1.230180115","rc":[{"atb":[[1.02,8.47]],"id":44213406}],"con":true,"img":false}]}
{"op":"mcm","clk":"11540544362","pt":1719495735290,"mc":[{"id":"1.230180115","rc":[{"atb":[[1.7,2]],"id":44213406}],"con":true,"img":false}]}
{"op":"mcm","clk":"11540544416","pt":1719495735912,"mc":[{"id":"1.230180115","rc":[{"atb":[[1.92,2]],"id":41804643}],"con":true,"img":false}]}
{"op":"mcm","clk":"11540544425","pt":1719495735968,"mc":[{"id":"1.230180115","rc":[{"atb":[[1.02,2]],"id":41804643},{"atb":[[1.07,3.75]],"id":39682601}],"con":true,"img":false}]}
{"op":"mcm","clk":"11540544498","pt":1719495736694,"mc":[{"id":"1.230180115","rc":[{"atb":[[1.02,0]],"id":63387150}],"con":true,"img":false}]}
{"op":"mcm","clk":"11540544505","pt":1719495736800,"mc":[{"id":"1.230180115","rc":[{"atb":[[2.22,2]],"id":63387150}],"con":true,"img":false}]}
{"op":"mcm","clk":"11540544667","pt":1719495738425,"mc":[{"id":"1.230180115","rc":[{"atb":[[1.7,2.5]],"id":61150133}],"con":true,"img":false}]}
{"op":"mcm","clk":"11540544731","pt":1719495738999,"mc":[{"id":"1.230180115","rc":[{"atb":[[1.73,3.75]],"id":41804643}],"con":true,"img":false}]}
{"op":"mcm","clk":"11540544753","pt":1719495739311,"mc":[{"id":"1.230180115","rc":[{"atb":[[1.72,5.48]],"id":44213406}],"con":true,"img":false}]}
{"op":"mcm","clk":"11540544765","pt":1719495739475,"mc":[{"id":"1.230180115","rc":[{"atb":[[1.73,5.48],[1.7,0],[1.69,0]],"id":44213406}],"con":true,"img":false}]}
{"op":"mcm","clk":"11540544776","pt":1719495739576,"mc":[{"id":"1.230180115","rc":[{"atb":[[1.02,10.47]],"id":44213406}],"con":true,"img":false}]}
{"op":"mcm","clk":"11540544784","pt":1719495739680,"mc":[{"id":"1.230180115","rc":[{"atb":[[1.12,32.92]],"id":39682601}],"con":true,"img":false}]}
{"op":"mcm","clk":"11540544792","pt":1719495739782,"mc":[{"id":"1.230180115","rc":[{"atb":[[1.13,32.92]],"id":39682601}],"con":true,"img":false}]}
{"op":"mcm","clk":"11540544801","pt":1719495739887,"mc":[{"id":"1.230180115","rc":[{"atb":[[1.09,0]],"id":39682601}],"con":true,"img":false}]}
{"op":"mcm","clk":"11540544809","pt":1719495739997,"mc":[{"id":"1.230180115","rc":[{"atb":[[2.22,0]],"id":63387150}],"con":true,"img":false}]}
{"op":"mcm","clk":"11540544820","pt":1719495740102,"mc":[{"id":"1.230180115","rc":[{"atb":[[1.07,0]],"id":39682601},{"atb":[[1.02,2]],"id":63387150}],"con":true,"img":false}]}
{"op":"mcm","clk":"11540544913","pt":1719495740984,"mc":[{"id":"1.230180115","rc":[{"atb":[[1.1,0]],"id":39682601}],"con":true,"img":false}]}
{"op":"mcm","clk":"11540544926","pt":1719495741097,"mc":[{"id":"1.230180115","rc":[{"atb":[[1.14,3]],"id":39682601}],"con":true,"img":false}]}
{"op":"mcm","clk":"11540544971","pt":1719495741507,"mc":[{"id":"1.230180115","rc":[{"atb":[[1.02,0]],"id":63387150}],"con":true,"img":false}]}
{"op":"mcm","clk":"11540544980","pt":1719495741607,"mc":[{"id":"1.230180115","rc":[{"atb":[[2.22,2]],"id":63387150}],"con":true,"img":false}]}
{"op":"mcm","clk":"11540545137","pt":1719495743695,"mc":[{"id":"1.230180115","rc":[{"atb":[[2.22,0]],"id":63387150}],"con":true,"img":false}]}
{"op":"mcm","clk":"11540545149","pt":1719495743802,"mc":[{"id":"1.230180115","rc":[{"atb":[[1.02,2]],"id":63387150}],"con":true,"img":false}]}
{"op":"mcm","clk":"11540545267","pt":1719495745414,"mc":[{"id":"1.230180115","rc":[{"atb":[[1.02,0]],"id":63387150}],"con":true,"img":false}]}
{"op":"mcm","clk":"11540545279","pt":1719495745542,"mc":[{"id":"1.230180115","rc":[{"atb":[[2.22,2]],"id":63387150}],"con":true,"img":false}]}
{"op":"mcm","clk":"11540545391","pt":1719495746619,"mc":[{"id":"1.230180115","rc":[{"atb":[[2.22,0]],"id":63387150}],"con":true,"img":false}]}
{"op":"mcm","clk":"11540545398","pt":1719495746712,"mc":[{"id":"1.230180115","rc":[{"atb":[[1.02,2]],"id":63387150}],"con":true,"img":false}]}
{"op":"mcm","clk":"11540545533","pt":1719495748216,"mc":[{"id":"1.230180115","rc":[{"atb":[[1.02,0]],"id":63387150}],"con":true,"img":false}]}
{"op":"mcm","clk":"11540545540","pt":1719495748320,"mc":[{"id":"1.230180115","rc":[{"atb":[[2.22,2]],"id":63387150}],"con":true,"img":false}]}
{"op":"mcm","clk":"11540545641","pt":1719495749416,"mc":[{"id":"1.230180115","rc":[{"atb":[[2.22,0]],"id":63387150}],"con":true,"img":false}]}
{"op":"mcm","clk":"11540545650","pt":1719495749516,"mc":[{"id":"1.230180115","rc":[{"atb":[[1.02,2]],"id":63387150}],"con":true,"img":false}]}
{"op":"mcm","clk":"11540545681","pt":1719495749832,"mc":[{"id":"1.230180115","rc":[{"atb":[[1.73,0]],"id":41804643}],"con":true,"img":false}]}
{"op":"mcm","clk":"11540545855","pt":1719495751609,"mc":[{"id":"1.230180115","rc":[{"atb":[[1.02,0]],"id":63387150}],"con":true,"img":false}]}
{"op":"mcm","clk":"11540545863","pt":1719495751705,"mc":[{"id":"1.230180115","rc":[{"atb":[[2.22,2]],"id":63387150}],"con":true,"img":false}]}
{"op":"mcm","clk":"11540545978","pt":1719495752902,"mc":[{"id":"1.230180115","rc":[{"atb":[[2.22,0]],"id":63387150}],"con":true,"img":false}]}
{"op":"mcm","clk":"11540545991","pt":1719495753006,"mc":[{"id":"1.230180115","rc":[{"atb":[[1.02,2]],"id":63387150}],"con":true,"img":false}]}
{"op":"mcm","clk":"11540546071","pt":1719495753800,"mc":[{"id":"1.230180115","rc":[{"atb":[[2.08,3.75]],"id":63387150}],"con":true,"img":false}]}
{"op":"mcm","clk":"11540546086","pt":1719495753998,"mc":[{"id":"1.230180115","rc":[{"atb":[[2.08,0]],"id":63387150}],"con":true,"img":false}]}
{"op":"mcm","clk":"11540546121","pt":1719495754516,"mc":[{"id":"1.230180115","rc":[{"atb":[[1.02,0]],"id":63387150}],"con":true,"img":false}]}
{"op":"mcm","clk":"11540546126","pt":1719495754622,"mc":[{"id":"1.230180115","rc":[{"atb":[[2.22,2]],"id":63387150}],"con":true,"img":false}]}
{"op":"mcm","clk":"11540546205","pt":1719495755720,"mc":[{"id":"1.230180115","rc":[{"atb":[[2.22,0]],"id":63387150}],"con":true,"img":false}]}
{"op":"mcm","clk":"11540546214","pt":1719495755828,"mc":[{"id":"1.230180115","rc":[{"atb":[[1.02,2]],"id":63387150}],"con":true,"img":false}]}
{"op":"mcm","clk":"11540546301","pt":1719495757017,"mc":[{"id":"1.230180115","rc":[{"atb":[[1.02,0]],"id":63387150}],"con":true,"img":false}]}
{"op":"mcm","clk":"11540546313","pt":1719495757124,"mc":[{"id":"1.230180115","rc":[{"atb":[[2.22,2]],"id":63387150}],"con":true,"img":false}]}
{"op":"mcm","clk":"11540546447","pt":1719495758421,"mc":[{"id":"1.230180115","rc":[{"atb":[[2.22,0]],"id":63387150}],"con":true,"img":false}]}
{"op":"mcm","clk":"11540546455","pt":1719495758525,"mc":[{"id":"1.230180115","rc":[{"atb":[[1.02,2]],"id":63387150}],"con":true,"img":false}]}
{"op":"mcm","clk":"11540546464","pt":1719495758628,"mc":[{"id":"1.230180115","rc":[{"atb":[[1.12,0]],"id":39682601}],"con":true,"img":false}]}
{"op":"mcm","clk":"11540546480","pt":1719495758835,"mc":[{"id":"1.230180115","rc":[{"atb":[[1.16,24.68]],"id":39682601}],"con":true,"img":false}]}
{"op":"mcm","clk":"11540546499","pt":1719495759043,"mc":[{"id":"1.230180115","rc":[{"atb":[[1.13,0],[1.17,24.69]],"id":39682601}],"con":true,"img":false}]}
{"op":"mcm","clk":"11540546610","pt":1719495760361,"mc":[{"id":"1.230180115","rc":[{"atb":[[1.14,1]],"id":39682601}],"con":true,"img":false}]}
{"op":"mcm","clk":"11540546621","pt":1719495760460,"mc":[{"id":"1.230180115","rc":[{"atb":[[1.18,2]],"id":39682601}],"con":true,"img":false}]}
{"op":"mcm","clk":"11540546654","pt":1719495760734,"mc":[{"id":"1.230180115","rc":[{"atb":[[1.02,0]],"id":63387150}],"con":true,"img":false}]}
{"op":"mcm","clk":"11540546660","pt":1719495760817,"mc":[{"id":"1.230180115","rc":[{"atb":[[2.22,2]],"id":63387150}],"con":true,"img":false}]}
{"op":"mcm","clk":"11540546792","pt":1719495762332,"mc":[{"id":"1.230180115","rc":[{"atb":[[2.22,0]],"id":63387150}],"con":true,"img":false}]}
{"op":"mcm","clk":"11540546803","pt":1719495762427,"mc":[{"id":"1.230180115","rc":[{"atb":[[1.02,2]],"id":63387150}],"con":true,"img":false}]}
{"op":"mcm","clk":"11540546929","pt":1719495763929,"mc":[{"id":"1.230180115","rc":[{"atb":[[1.02,0]],"id":63387150}],"con":true,"img":false}]}
{"op":"mcm","clk":"11540546942","pt":1719495764032,"mc":[{"id":"1.230180115","rc":[{"atb":[[2.22,2]],"id":63387150}],"con":true,"img":false}]}
{"op":"mcm","clk":"11540546972","pt":1719495764440,"mc":[{"id":"1.230180115","rc":[{"atb":[[1.19,22.29]],"id":39682601}],"con":true,"img":false}]}
{"op":"mcm","clk":"11540547040","pt":1719495765218,"mc":[{"id":"1.230180115","rc":[{"atb":[[1.18,0]],"id":39682601}],"con":true,"img":false}]}
{"op":"mcm","clk":"11540547046","pt":1719495765326,"mc":[{"id":"1.230180115","rc":[{"atb":[[1.2,2]],"id":39682601}],"con":true,"img":false}]}
{"op":"mcm","clk":"11540547085","pt":1719495765740,"mc":[{"id":"1.230180115","rc":[{"atb":[[1.2,24.29],[1.17,0]],"id":39682601},{"atb":[[2.22,0]],"id":63387150}],"con":true,"img":false}]}
{"op":"mcm","clk":"11540547097","pt":1719495765838,"mc":[{"id":"1.230180115","rc":[{"atb":[[1.02,2]],"id":63387150}],"con":true,"img":false}]}
{"op":"mcm","clk":"11540547133","pt":1719495766261,"mc":[{"id":"1.230180115","rc":[{"atb":[[1.15,7.87]],"id":39682601}],"con":true,"img":false}]}
{"op":"mcm","clk":"11540547201","pt":1719495766927,"mc":[{"id":"1.230180115","rc":[{"atb":[[1.15,0]],"id":39682601}],"con":true,"img":false}]}
{"op":"mcm","clk":"11540547261","pt":1719495767511,"mc":[{"id":"1.230180115","rc":[{"atb":[[1.7,4.38]],"id":61150133}],"con":true,"img":false}]}
{"op":"mcm","clk":"11540547279","pt":1719495767719,"mc":[{"id":"1.230180115","rc":[{"atb":[[1.02,0]],"id":63387150}],"con":true,"img":false}]}
{"op":"mcm","clk":"11540547289","pt":1719495767822,"mc":[{"id":"1.230180115","rc":[{"atb":[[2.22,2]],"id":63387150}],"con":true,"img":false}]}
{"op":"mcm","clk":"11540547314","pt":1719495768137,"mc":[{"id":"1.230180115","rc":[{"atb":[[1.73,2.5]],"id":41804643}],"con":true,"img":false}]}
{"op":"mcm","clk":"11540547424","pt":1719495769321,"mc":[{"id":"1.230180115","rc":[{"atb":[[2.22,0]],"id":63387150}],"con":true,"img":false}]}
{"op":"mcm","clk":"11540547432","pt":1719495769428,"mc":[{"id":"1.230180115","rc":[{"atb":[[1.02,2]],"id":63387150}],"con":true,"img":false}]}
{"op":"mcm","clk":"11540547686","pt":1719495772429,"mc":[{"id":"1.230180115","rc":[{"atb":[[1.73,0]],"id":41804643}],"con":true,"img":false}]}
{"op":"mcm","clk":"11540547696","pt":1719495772535,"mc":[{"id":"1.230180115","rc":[{"atb":[[1.02,0]],"id":63387150}],"con":true,"img":false}]}
{"op":"mcm","clk":"11540547706","pt":1719495772634,"mc":[{"id":"1.230180115","rc":[{"atb":[[2.22,2]],"id":63387150}],"con":true,"img":false}]}
{"op":"mcm","clk":"11540547787","pt":1719495773515,"mc":[{"id":"1.230180115","rc":[{"atb":[[2.22,0]],"id":63387150}],"con":true,"img":false}]}
{"op":"mcm","clk":"11540547797","pt":1719495773621,"mc":[{"id":"1.230180115","rc":[{"atb":[[1.02,2]],"id":63387150}],"con":true,"img":false}]}
{"op":"mcm","clk":"11540548053","pt":1719495776248,"mc":[{"id":"1.230180115","rc":[{"atb":[[1.02,0]],"id":63387150}],"con":true,"img":false}]}
{"op":"mcm","clk":"11540548062","pt":1719495776357,"mc":[{"id":"1.230180115","rc":[{"atb":[[2.22,2]],"id":63387150}],"con":true,"img":false}]}
{"op":"mcm","clk":"11540548150","pt":1719495777535,"mc":[{"id":"1.230180115","rc":[{"atb":[[1.16,0]],"id":39682601}],"con":true,"img":false}]}
{"op":"mcm","clk":"11540548161","pt":1719495777643,"mc":[{"id":"1.230180115","rc":[{"atb":[[2.22,0]],"id":63387150}],"con":true,"img":false}]}
{"op":"mcm","clk":"11540548175","pt":1719495777742,"mc":[{"id":"1.230180115","rc":[{"atb":[[1.02,2]],"id":63387150}],"con":true,"img":false}]}
{"op":"mcm","clk":"11540548225","pt":1719495778356,"mc":[{"id":"1.230180115","rc":[{"atb":[[1.22,17.95]],"id":39682601}],"con":true,"img":false}]}
{"op":"mcm","clk":"11540548243","pt":1719495778567,"mc":[{"id":"1.230180115","rc":[{"atb":[[1.2,2],[1.23,22.29]],"id":39682601}],"con":true,"img":false}]}
{"op":"mcm","clk":"11540548288","pt":1719495778933,"mc":[{"id":"1.230180115","rc":[{"atb":[[1.2,0]],"id":39682601}],"con":true,"img":false}]}
{"op":"mcm","clk":"11540548298","pt":1719495779027,"mc":[{"id":"1.230180115","rc":[{"atb":[[1.23,24.29]],"id":39682601}],"con":true,"img":false}]}
{"op":"mcm","clk":"11540548347","pt":1719495779540,"mc":[{"id":"1.230180115","rc":[{"atb":[[1.02,0]],"id":63387150}],"con":true,"img":false}]}
{"op":"mcm","clk":"11540548361","pt":1719495779644,"mc":[{"id":"1.230180115","rc":[{"spn":1.97,"spf":1.0,"id":61150133},{"spn":3.46,"spf":"NaN","id":44213406},{"spn":1.74,"spf":"NaN","id":39682601},{"atb":[[2.22,2]],"id":63387150},{"spn":4.91,"spf":"NaN","id":63387150}],"con":true,"img":false}]}
{"op":"mcm","clk":"11540548467","pt":1719495780639,"mc":[{"id":"1.230180115","rc":[{"atb":[[2.22,0]],"id":63387150}],"con":true,"img":false}]}
{"op":"mcm","clk":"11540548482","pt":1719495780736,"mc":[{"id":"1.230180115","rc":[{"atb":[[1.02,2]],"id":63387150}],"con":true,"img":false}]}
{"op":"mcm","clk":"11540548653","pt":1719495782242,"mc":[{"id":"1.230180115","rc":[{"atb":[[1.02,0]],"id":63387150}],"con":true,"img":false}]}
{"op":"mcm","clk":"11540548663","pt":1719495782349,"mc":[{"id":"1.230180115","rc":[{"atb":[[2.22,2]],"id":63387150}],"con":true,"img":false}]}
{"op":"mcm","clk":"11540548810","pt":1719495783738,"mc":[{"id":"1.230180115","rc":[{"atb":[[2.22,0]],"id":63387150}],"con":true,"img":false}]}
{"op":"mcm","clk":"11540548822","pt":1719495783843,"mc":[{"id":"1.230180115","rc":[{"atb":[[1.02,2]],"id":63387150}],"con":true,"img":false}]}
{"op":"mcm","clk":"11540548927","pt":1719495784928,"mc":[{"id":"1.230180115","rc":[{"atb":[[1.02,0]],"id":63387150}],"con":true,"img":false}]}
{"op":"mcm","clk":"11540548936","pt":1719495785030,"mc":[{"id":"1.230180115","rc":[{"atb":[[2.22,2]],"id":63387150}],"con":true,"img":false}]}
{"op":"mcm","clk":"11540549035","pt":1719495786159,"mc":[{"id":"1.230180115","rc":[{"atb":[[2.22,0]],"id":63387150}],"con":true,"img":false}]}
{"op":"mcm","clk":"11540549046","pt":1719495786263,"mc":[{"id":"1.230180115","rc":[{"atb":[[1.02,2]],"id":63387150}],"con":true,"img":false}]}
{"op":"mcm","clk":"11540549215","pt":1719495787964,"mc":[{"id":"1.230180115","rc":[{"atb":[[1.02,0]],"id":63387150}],"con":true,"img":false}]}
{"op":"mcm","clk":"11540549227","pt":1719495788062,"mc":[{"id":"1.230180115","rc":[{"atb":[[2.22,2]],"id":63387150}],"con":true,"img":false}]}
{"op":"mcm","clk":"11540549481","pt":1719495790547,"mc":[{"id":"1.230180115","rc":[{"atb":[[2.22,0]],"id":63387150}],"con":true,"img":false}]}
{"op":"mcm","clk":"11540549490","pt":1719495790650,"mc":[{"id":"1.230180115","rc":[{"atb":[[1.02,2]],"id":63387150}],"con":true,"img":false}]}
{"op":"mcm","clk":"11540549653","pt":1719495792573,"mc":[{"id":"1.230180115","rc":[{"atb":[[1.02,0]],"id":63387150}],"con":true,"img":false}]}
{"op":"mcm","clk":"11540549664","pt":1719495792675,"mc":[{"id":"1.230180115","rc":[{"atb":[[2.22,2]],"id":63387150}],"con":true,"img":false}]}
{"op":"mcm","clk":"11540549763","pt":1719495793866,"mc":[{"id":"1.230180115","rc":[{"atb":[[2.22,0]],"id":63387150}],"con":true,"img":false}]}
{"op":"mcm","clk":"11540549771","pt":1719495793964,"mc":[{"id":"1.230180115","rc":[{"atb":[[1.02,2]],"id":63387150}],"con":true,"img":false}]}
{"op":"mcm","clk":"11540549857","pt":1719495794945,"mc":[{"id":"1.230180115","rc":[{"atb":[[1.18,4.75]],"id":39682601}],"con":true,"img":false}]}
{"op":"mcm","clk":"11540549881","pt":1719495795257,"mc":[{"id":"1.230180115","rc":[{"atb":[[1.7,6.25]],"id":61150133}],"con":true,"img":false}]}
{"op":"mcm","clk":"11540549923","pt":1719495795670,"mc":[{"id":"1.230180115","rc":[{"atb":[[1.73,3.75]],"id":41804643},{"atb":[[1.02,0]],"id":63387150}],"con":true,"img":false}]}
{"op":"mcm","clk":"11540549930","pt":1719495795775,"mc":[{"id":"1.230180115","rc":[{"atb":[[2.22,2]],"id":63387150}],"con":true,"img":false}]}
{"op":"mcm","clk":"11540550051","pt":1719495796862,"mc":[{"id":"1.230180115","rc":[{"atb":[[1.18,0]],"id":39682601}],"con":true,"img":false}]}
{"op":"mcm","clk":"11540550082","pt":1719495797168,"mc":[{"id":"1.230180115","rc":[{"atb":[[2.22,0]],"id":63387150}],"con":true,"img":false}]}
{"op":"mcm","clk":"11540550092","pt":1719495797272,"mc":[{"id":"1.230180115","rc":[{"atb":[[1.02,2]],"id":63387150}],"con":true,"img":false}]}
{"op":"mcm","clk":"11540550136","pt":1719495797742,"mc":[{"id":"1.230180115","rc":[{"atb":[[1.24,23.04]],"id":39682601}],"con":true,"img":false}]}
{"op":"mcm","clk":"11540550147","pt":1719495797848,"mc":[{"id":"1.230180115","rc":[{"atb":[[1.25,23.05]],"id":39682601}],"con":true,"img":false}]}
{"op":"mcm","clk":"11540550161","pt":1719495797955,"mc":[{"id":"1.230180115","rc":[{"atb":[[1.72,0]],"id":44213406},{"atb":[[1.23,2]],"id":39682601}],"con":true,"img":false}]}
{"op":"mcm","clk":"11540550172","pt":1719495798050,"mc":[{"id":"1.230180115","rc":[{"atb":[[1.73,0],[1.69,10.96]],"id":44213406}],"con":true,"img":false}]}
{"op":"mcm","clk":"11540550181","pt":1719495798154,"mc":[{"id":"1.230180115","rc":[{"atb":[[1.94,4.2]],"id":41804643}],"con":true,"img":false}]}
{"op":"mcm","clk":"11540550189","pt":1719495798258,"mc":[{"id":"1.230180115","rc":[{"atb":[[1.92,0],[1.95,2]],"id":41804643}],"con":true,"img":false}]}
{"op":"mcm","clk":"11540550198","pt":1719495798366,"mc":[{"id":"1.230180115","rc":[{"atb":[[1.75,5.26]],"id":44213406}],"con":true,"img":false}]}
{"op":"mcm","clk":"11540550204","pt":1719495798464,"mc":[{"id":"1.230180115","rc":[{"atb":[[1.23,0]],"id":39682601}],"con":true,"img":false}]}
{"op":"mcm","clk":"11540550217","pt":1719495798575,"mc":[{"id":"1.230180115","rc":[{"atb":[[1.26,2]],"id":39682601}],"con":true,"img":false}]}
{"op":"mcm","clk":"11540550254","pt":1719495798876,"mc":[{"id":"1.230180115","rc":[{"atb":[[1.02,8.47]],"id":44213406}],"con":true,"img":false}]}
{"op":"mcm","clk":"11540550269","pt":1719495798979,"mc":[{"id":"1.230180115","rc":[{"atb":[[1.74,2]],"id":44213406}],"con":true,"img":false}]}
{"op":"mcm","clk":"11540550291","pt":1719495799185,"mc":[{"id":"1.230180115","rc":[{"atb":[[1.73,0]],"id":41804643},{"atb":[[1.02,0]],"id":63387150}],"con":true,"img":false}]}
{"op":"mcm","clk":"11540550306","pt":1719495799294,"mc":[{"id":"1.230180115","rc":[{"atb":[[2.22,2]],"id":63387150}],"con":true,"img":false}]}
{"op":"mcm","clk":"11540550373","pt":1719495800070,"mc":[{"id":"1.230180115","rc":[{"atb":[[1.74,0]],"id":44213406}],"con":true,"img":false}]}
{"op":"mcm","clk":"11540550383","pt":1719495800178,"mc":[{"id":"1.230180115","rc":[{"atb":[[1.76,2]],"id":44213406}],"con":true,"img":false}]}
{"op":"mcm","clk":"11540550434","pt":1719495800644,"mc":[{"id":"1.230180115","rc":[{"atb":[[2.22,0]],"id":63387150}],"con":true,"img":false}]}
{"op":"mcm","clk":"11540550443","pt":1719495800748,"mc":[{"id":"1.230180115","rc":[{"atb":[[1.02,2]],"id":63387150}],"con":true,"img":false}]}
{"op":"mcm","clk":"11540550534","pt":1719495802083,"mc":[{"id":"1.230180115","rc":[{"atb":[[1.02,0]],"id":63387150}],"con":true,"img":false}]}
{"op":"mcm","clk":"11540550548","pt":1719495802188,"mc":[{"id":"1.230180115","rc":[{"atb":[[2.22,2]],"id":63387150}],"con":true,"img":false}]}
{"op":"mcm","clk":"11540550650","pt":1719495803375,"mc":[{"id":"1.230180115","rc":[{"atb":[[1.27,21.96]],"id":39682601}],"con":true,"img":false}]}
{"op":"mcm","clk":"11540550670","pt":1719495803582,"mc":[{"id":"1.230180115","rc":[{"atb":[[1.73,8.12]],"id":44213406},{"atb":[[2.22,0]],"id":63387150}],"con":true,"img":false}]}
{"op":"mcm","clk":"11540550675","pt":1719495803684,"mc":[{"id":"1.230180115","rc":[{"atb":[[1.02,2],[2.28,4.63]],"id":63387150}],"con":true,"img":false}]}
{"op":"mcm","clk":"11540550690","pt":1719495803841,"mc":[{"id":"1.230180115","rc":[{"atb":[[1.78,5.42]],"id":44213406},{"atb":[[2.3,4.63],[2.2,0]],"id":63387150}],"con":true,"img":false}]}
{"op":"mcm","clk":"11540550733","pt":1719495804458,"mc":[{"id":"1.230180115","rc":[{"atb":[[1.79,5.27],[1.69,0]],"id":44213406}],"con":true,"img":false}]}
{"op":"mcm","clk":"11540550767","pt":1719495804870,"mc":[{"id":"1.230180115","rc":[{"atb":[[1.26,0]],"id":39682601}],"con":true,"img":false}]}
{"op":"mcm","clk":"11540550779","pt":1719495804973,"mc":[{"id":"1.230180115","rc":[{"atb":[[1.28,2]],"id":39682601}],"con":true,"img":false}]}
{"op":"mcm","clk":"11540550814","pt":1719495805390,"mc":[{"id":"1.230180115","rc":[{"atb":[[1.76,0]],"id":44213406}],"con":true,"img":false}]}
{"op":"mcm","clk":"11540550822","pt":1719495805490,"mc":[{"id":"1.230180115","rc":[{"atb":[[1.8,2]],"id":44213406}],"con":true,"img":false}]}
{"op":"mcm","clk":"11540550955","pt":1719495806782,"mc":[{"id":"1.230180115","rc":[{"atb":[[1.72,5]],"id":44213406}],"con":true,"img":false}]}
{"op":"mcm","clk":"11540551033","pt":1719495807762,"mc":[{"id":"1.230180115","rc":[{"atb":[[1.72,0]],"id":44213406}],"con":true,"img":false}]}
{"op":"mcm","clk":"11540551819","pt":1719495816076,"mc":[{"id":"1.230180115","rc":[{"atb":[[1.24,0]],"id":39682601}],"con":true,"img":false}]}
{"op":"mcm","clk":"11540551871","pt":1719495816593,"mc":[{"id":"1.230180115","rc":[{"atb":[[1.29,19.07]],"id":39682601}],"con":true,"img":false}]}
{"op":"mcm","clk":"11540551925","pt":1719495817168,"mc":[{"id":"1.230180115","rc":[{"atb":[[1.75,0]],"id":44213406}],"con":true,"img":false}]}
{"op":"mcm","clk":"11540551931","pt":1719495817277,"mc":[{"id":"1.230180115","rc":[{"atb":[[1.28,0]],"id":39682601}],"con":true,"img":false}]}
{"op":"mcm","clk":"11540551944","pt":1719495817375,"mc":[{"id":"1.230180115","rc":[{"atb":[[1.3,2]],"id":39682601}],"con":true,"img":false}]}
{"op":"mcm","clk":"11540552005","pt":1719495818095,"mc":[{"id":"1.230180115","rc":[{"atb":[[1.82,4.81]],"id":44213406}],"con":true,"img":false}]}
{"op":"mcm","clk":"11540552015","pt":1719495818194,"mc":[{"id":"1.230180115","rc":[{"atb":[[1.83,4.82],[1.79,0]],"id":44213406}],"con":true,"img":false}]}
{"op":"mcm","clk":"11540552072","pt":1719495818766,"mc":[{"id":"1.230180115","rc":[{"atb":[[1.8,0]],"id":44213406}],"con":true,"img":false}]}
{"op":"mcm","clk":"11540552082","pt":1719495818870,"mc":[{"id":"1.230180115","rc":[{"atb":[[1.84,2]],"id":44213406}],"con":true,"img":false}]}
{"op":"mcm","clk":"11540552437","pt":1719495822176,"mc":[{"id":"1.230180115","rc":[{"atb":[[1.28,3.88]],"id":39682601}],"con":true,"img":false}]}
{"op":"mcm","clk":"11540552499","pt":1719495822904,"mc":[{"id":"1.230180115","rc":[{"atb":[[1.28,0]],"id":39682601}],"con":true,"img":false}]}
{"op":"mcm","clk":"11540553644","pt":1719495834720,"mc":[{"id":"1.230180115","rc":[{"atb":[[1.82,0]],"id":44213406}],"con":true,"img":false}]}
{"op":"mcm","clk":"11540553669","pt":1719495834927,"mc":[{"id":"1.230180115","rc":[{"atb":[[1.86,4.59]],"id":44213406}],"con":true,"img":false}]}
{"op":"mcm","clk":"11540553682","pt":1719495835029,"mc":[{"id":"1.230180115","rc":[{"atb":[[1.83,0],[1.87,4.59]],"id":44213406}],"con":true,"img":false}]}
{"op":"mcm","clk":"11540553712","pt":1719495835289,"mc":[{"id":"1.230180115","rc":[{"atb":[[1.84,0]],"id":44213406}],"con":true,"img":false}]}
{"op":"mcm","clk":"11540553723","pt":1719495835396,"mc":[{"id":"1.230180115","rc":[{"atb":[[1.88,2]],"id":44213406}],"con":true,"img":false}]}
{"op":"mcm","clk":"11540553953","pt":1719495837816,"mc":[{"id":"1.230180115","rc":[{"atb":[[2.28,0]],"id":63387150}],"con":true,"img":false}]}
{"op":"mcm","clk":"11540553966","pt":1719495837921,"mc":[{"id":"1.230180115","rc":[{"atb":[[2.3,0],[2.2,9.26]],"id":63387150}],"con":true,"img":false}]}
{"op":"mcm","clk":"11540554103","pt":1719495839420,"mc":[{"id":"1.230180115","rc":[{"atb":[[1.02,0]],"id":63387150}],"con":true,"img":false}]}
{"op":"mcm","clk":"11540554114","pt":1719495839519,"mc":[{"id":"1.230180115","rc":[{"atb":[[2.22,2]],"id":63387150}],"con":true,"img":false}]}
{"op":"mcm","clk":"11540554133","pt":1719495839727,"mc":[{"id":"1.230180115","rc":[{"spn":4.17,"spf":"NaN","id":41804643},{"atb":[[1.78,0]],"id":44213406},{"spn":3.54,"spf":"NaN","id":44213406},{"spn":1.78,"spf":"NaN","id":39682601}],"con":true,"img":false}]}
{"op":"mcm","clk":"11540554242","pt":1719495840919,"mc":[{"id":"1.230180115","rc":[{"atb":[[1.9,4.7]],"id":44213406}],"con":true,"img":false}]}
{"op":"mcm","clk":"11540554254","pt":1719495841028,"mc":[{"id":"1.230180115","rc":[{"atb":[[1.91,4.59],[1.87,0]],"id":44213406}],"con":true,"img":false}]}
{"op":"mcm","clk":"11540554316","pt":1719495841696,"mc":[{"id":"1.230180115","rc":[{"atb":[[1.88,0]],"id":44213406}],"con":true,"img":false}]}
{"op":"mcm","clk":"11540554329","pt":1719495841799,"mc":[{"id":"1.230180115","rc":[{"atb":[[1.92,2]],"id":44213406}],"con":true,"img":false}]}
{"op":"mcm","clk":"11540554348","pt":1719495842013,"mc":[{"id":"1.230180115","rc":[{"atb":[[2.22,0]],"id":63387150}],"con":true,"img":false}]}
{"op":"mcm","clk":"11540554357","pt":1719495842109,"mc":[{"id":"1.230180115","rc":[{"atb":[[1.02,2]],"id":63387150}],"con":true,"img":false}]}
{"op":"mcm","clk":"11540554455","pt":1719495843243,"mc":[{"id":"1.230180115","rc":[{"atb":[[1.02,0]],"id":63387150}],"con":true,"img":false}]}
{"op":"mcm","clk":"11540554466","pt":1719495843298,"mc":[{"id":"1.230180115","rc":[{"atb":[[1.82,5]],"id":44213406},{"atb":[[2.22,2]],"id":63387150}],"con":true,"img":false}]}
{"op":"mcm","clk":"11540554584","pt":1719495844530,"mc":[{"id":"1.230180115","rc":[{"atb":[[2.22,0]],"id":63387150}],"con":true,"img":false}]}
{"op":"mcm","clk":"11540554594","pt":1719495844632,"mc":[{"id":"1.230180115","rc":[{"atb":[[1.02,2]],"id":63387150}],"con":true,"img":false}]}
{"op":"mcm","clk":"11540554716","pt":1719495845923,"mc":[{"id":"1.230180115","rc":[{"atb":[[1.02,0],[1.07,3.75]],"id":63387150}],"con":true,"img":false}]}
{"op":"mcm","clk":"11540554727","pt":1719495846024,"mc":[{"id":"1.230180115","rc":[{"atb":[[2.22,2]],"id":63387150}],"con":true,"img":false}]}
{"op":"mcm","clk":"11540554766","pt":1719495846544,"mc":[{"id":"1.230180115","rc":[{"atb":[[1.07,0]],"id":63387150}],"con":true,"img":false}]}
{"op":"mcm","clk":"11540554816","pt":1719495847004,"mc":[{"id":"1.230180115","rc":[{"atb":[[2.22,0]],"id":63387150}],"con":true,"img":false}]}
{"op":"mcm","clk":"11540554826","pt":1719495847107,"mc":[{"id":"1.230180115","rc":[{"atb":[[1.02,2]],"id":63387150}],"con":true,"img":false}]}
{"op":"mcm","clk":"11540554927","pt":1719495848118,"mc":[{"id":"1.230180115","rc":[{"atb":[[1.28,3.38]],"id":39682601}],"con":true,"img":false}]}
{"op":"mcm","clk":"11540554958","pt":1719495848434,"mc":[{"id":"1.230180115","rc":[{"atb":[[1.28,0]],"id":39682601},{"atb":[[1.02,0]],"id":63387150}],"con":true,"img":false}]}
{"op":"mcm","clk":"11540554969","pt":1719495848533,"mc":[{"id":"1.230180115","rc":[{"atb":[[2.22,2]],"id":63387150}],"con":true,"img":false}]}
{"op":"mcm","clk":"11540555067","pt":1719495849716,"mc":[{"id":"1.230180115","rc":[{"atb":[[2.22,0]],"id":63387150}],"con":true,"img":false}]}
{"op":"mcm","clk":"11540555072","pt":1719495849821,"mc":[{"id":"1.230180115","rc":[{"atb":[[1.02,2]],"id":63387150}],"con":true,"img":false}]}
{"op":"mcm","clk":"11540555134","pt":1719495850452,"mc":[{"id":"1.230180115","rc":[{"atb":[[1.82,0]],"id":44213406}],"con":true,"img":false}]}
{"op":"mcm","clk":"11540555193","pt":1719495851021,"mc":[{"id":"1.230180115","rc":[{"atb":[[1.02,0]],"id":63387150}],"con":true,"img":false}]}
{"op":"mcm","clk":"11540555199","pt":1719495851125,"mc":[{"id":"1.230180115","rc":[{"atb":[[2.22,2]],"id":63387150}],"con":true,"img":false}]}
{"op":"mcm","clk":"11540555307","pt":1719495852316,"mc":[{"id":"1.230180115","rc":[{"atb":[[2.22,0]],"id":63387150}],"con":true,"img":false}]}
{"op":"mcm","clk":"11540555316","pt":1719495852410,"mc":[{"id":"1.230180115","rc":[{"atb":[[1.02,2]],"id":63387150}],"con":true,"img":false}]}
{"op":"mcm","clk":"11540555424","pt":1719495853909,"mc":[{"id":"1.230180115","rc":[{"atb":[[1.02,0]],"id":63387150}],"con":true,"img":false}]}
{"op":"mcm","clk":"11540555431","pt":1719495854014,"mc":[{"id":"1.230180115","rc":[{"atb":[[2.22,2]],"id":63387150}],"con":true,"img":false}]}
{"op":"mcm","clk":"11540555561","pt":1719495855616,"mc":[{"id":"1.230180115","rc":[{"atb":[[2.22,0]],"id":63387150}],"con":true,"img":false}]}
{"op":"mcm","clk":"11540555570","pt":1719495855718,"mc":[{"id":"1.230180115","rc":[{"atb":[[1.02,2]],"id":63387150}],"con":true,"img":false}]}
{"op":"mcm","clk":"11540555685","pt":1719495856904,"mc":[{"id":"1.230180115","rc":[{"atb":[[1.02,0]],"id":63387150}],"con":true,"img":false}]}
{"op":"mcm","clk":"11540555694","pt":1719495857013,"mc":[{"id":"1.230180115","rc":[{"atb":[[2.22,2]],"id":63387150}],"con":true,"img":false}]}
{"op":"mcm","clk":"11540555786","pt":1719495858349,"mc":[{"id":"1.230180115","rc":[{"atb":[[2.22,0]],"id":63387150}],"con":true,"img":false}]}
{"op":"mcm","clk":"11540555797","pt":1719495858456,"mc":[{"id":"1.230180115","rc":[{"atb":[[1.02,2]],"id":63387150}],"con":true,"img":false}]}
{"op":"mcm","clk":"11540555913","pt":1719495859738,"mc":[{"id":"1.230180115","rc":[{"atb":[[1.02,0]],"id":63387150}],"con":true,"img":false}]}
{"op":"mcm","clk":"11540555921","pt":1719495859841,"mc":[{"id":"1.230180115","rc":[{"atb":[[2.22,2]],"id":63387150}],"con":true,"img":false}]}
{"op":"mcm","clk":"11540556056","pt":1719495861132,"mc":[{"id":"1.230180115","rc":[{"atb":[[2.22,0]],"id":63387150}],"con":true,"img":false}]}
{"op":"mcm","clk":"11540556067","pt":1719495861236,"mc":[{"id":"1.230180115","rc":[{"atb":[[1.02,2]],"id":63387150}],"con":true,"img":false}]}
{"op":"mcm","clk":"11540556214","pt":1719495862432,"mc":[{"id":"1.230180115","rc":[{"atb":[[1.02,0]],"id":63387150}],"con":true,"img":false}]}
{"op":"mcm","clk":"11540556225","pt":1719495862531,"mc":[{"id":"1.230180115","rc":[{"atb":[[2.22,2]],"id":63387150}],"con":true,"img":false}]}
{"op":"mcm","clk":"11540556327","pt":1719495863624,"mc":[{"id":"1.230180115","rc":[{"atb":[[2.22,0]],"id":63387150}],"con":true,"img":false}]}
{"op":"mcm","clk":"11540556337","pt":1719495863720,"mc":[{"id":"1.230180115","rc":[{"atb":[[1.02,2]],"id":63387150}],"con":true,"img":false}]}
{"op":"mcm","clk":"11540556454","pt":1719495864853,"mc":[{"id":"1.230180115","rc":[{"atb":[[1.02,0]],"id":63387150}],"con":true,"img":false}]}
{"op":"mcm","clk":"11540556461","pt":1719495864957,"mc":[{"id":"1.230180115","rc":[{"atb":[[2.22,2]],"id":63387150}],"con":true,"img":false}]}
{"op":"mcm","clk":"11540556574","pt":1719495866247,"mc":[{"id":"1.230180115","rc":[{"atb":[[1.94,7.95]],"id":41804643},{"atb":[[1.69,5.08]],"id":61150133},{"atl":[[2.86,3.08]],"id":39682601}],"con":true,"img":false}]}
{"op":"mcm","clk":"11540556581","pt":1719495866352,"mc":[{"id":"1.230180115","rc":[{"atl":[[2.84,3],[3.65,0]],"id":39682601}],"con":true,"img":false}]}
{"op":"mcm","clk":"11540556592","pt":1719495866459,"mc":[{"id":"1.230180115","rc":[{"atb":[[2.22,0],[2.2,13.01]],"id":63387150}],"con":true,"img":false}]}
{"op":"mcm","clk":"11540556600","pt":1719495866557,"mc":[{"id":"1.230180115","rc":[{"atb":[[1.02,2]],"id":63387150}],"con":true,"img":false}]}
{"op":"mcm","clk":"11540556629","pt":1719495866921,"mc":[{"id":"1.230180115","rc":[{"atb":[[2.2,9.26]],"id":63387150}],"con":true,"img":false}]}
{"op":"mcm","clk":"11540556747","pt":1719495868130,"mc":[{"id":"1.230180115","rc":[{"atb":[[1.02,0]],"id":61150133},{"atb":[[1.9,9.7]],"id":44213406}],"con":true,"img":false}]}
{"op":"mcm","clk":"11540556758","pt":1719495868214,"mc":[{"id":"1.230180115","rc":[{"atb":[[1.72,2]],"id":61150133}],"con":true,"img":false}]}
{"op":"mcm","clk":"11540556778","pt":1719495868526,"mc":[{"id":"1.230180115","rc":[{"atb":[[1.02,0]],"id":63387150}],"con":true,"img":false}]}
{"op":"mcm","clk":"11540556787","pt":1719495868626,"mc":[{"id":"1.230180115","rc":[{"atb":[[2.22,2]],"id":63387150}],"con":true,"img":false}]}
{"op":"mcm","clk":"11540556815","pt":1719495868936,"mc":[{"id":"1.230180115","rc":[{"atb":[[1.69,0]],"id":61150133}],"con":true,"img":false}]}
{"op":"mcm","clk":"11540556824","pt":1719495869039,"mc":[{"id":"1.230180115","rc":[{"atb":[[1.7,0]],"id":61150133}],"con":true,"img":false}]}
{"op":"mcm","clk":"11540556879","pt":1719495869659,"mc":[{"id":"1.230180115","rc":[{"atb":[[1.22,0]],"id":39682601}],"con":true,"img":false}]}
{"op":"mcm","clk":"11540556956","pt":1719495870439,"mc":[{"id":"1.230180115","rc":[{"atb":[[1.72,0]],"id":61150133}],"con":true,"img":false}]}
{"op":"mcm","clk":"11540556972","pt":1719495870539,"mc":[{"id":"1.230180115","rc":[{"atb":[[1.02,2]],"id":61150133}],"con":true,"img":false}]}
{"op":"mcm","clk":"11540557000","pt":1719495870846,"mc":[{"id":"1.230180115","rc":[{"atb":[[2.22,0]],"id":63387150}],"con":true,"img":false}]}
{"op":"mcm","clk":"11540557009","pt":1719495870949,"mc":[{"id":"1.230180115","rc":[{"atb":[[1.02,2]],"id":63387150}],"con":true,"img":false}]}
{"op":"mcm","clk":"11540557117","pt":1719495872340,"mc":[{"id":"1.230180115","rc":[{"atb":[[1.02,0]],"id":61150133}],"con":true,"img":false}]}
{"op":"mcm","clk":"11540557127","pt":1719495872449,"mc":[{"id":"1.230180115","rc":[{"atb":[[1.72,2]],"id":61150133}],"con":true,"img":false}]}
{"op":"mcm","clk":"11540557146","pt":1719495872753,"mc":[{"id":"1.230180115","rc":[{"atb":[[1.28,3.38]],"id":39682601},{"atb":[[1.02,0]],"id":63387150}],"con":true,"img":false}]}
{"op":"mcm","clk":"11540557154","pt":1719495872856,"mc":[{"id":"1.230180115","rc":[{"atb":[[2.22,2]],"id":63387150}],"con":true,"img":false}]}
{"op":"mcm","clk":"11540557162","pt":1719495872961,"mc":[{"id":"1.230180115","rc":[{"atb":[[1.28,0]],"id":39682601}],"con":true,"img":false}]}
{"op":"mcm","clk":"11540557248","pt":1719495873740,"mc":[{"id":"1.230180115","rc":[{"atb":[[1.72,0]],"id":61150133}],"con":true,"img":false}]}
{"op":"mcm","clk":"11540557259","pt":1719495873842,"mc":[{"id":"1.230180115","rc":[{"atb":[[1.02,2]],"id":61150133}],"con":true,"img":false}]}
{"op":"mcm","clk":"11540557292","pt":1719495874154,"mc":[{"id":"1.230180115","rc":[{"atb":[[2.22,0]],"id":63387150}],"con":true,"img":false}]}
{"op":"mcm","clk":"11540557307","pt":1719495874258,"mc":[{"id":"1.230180115","rc":[{"atb":[[1.02,2]],"id":63387150}],"con":true,"img":false}]}
{"op":"mcm","clk":"11540557411","pt":1719495875448,"mc":[{"id":"1.230180115","rc":[{"atb":[[1.02,0]],"id":61150133}],"con":true,"img":false}]}
{"op":"mcm","clk":"11540557422","pt":1719495875552,"mc":[{"id":"1.230180115","rc":[{"atb":[[1.72,2]],"id":61150133}],"con":true,"img":false}]}
{"op":"mcm","clk":"11540557454","pt":1719495875866,"mc":[{"id":"1.230180115","rc":[{"atb":[[1.02,0]],"id":63387150}],"con":true,"img":false}]}
{"op":"mcm","clk":"11540557463","pt":1719495875920,"mc":[{"id":"1.230180115","rc":[{"atb":[[1.95,5.82]],"id":44213406},{"atb":[[2.22,2]],"id":63387150}],"con":true,"img":false}]}
{"op":"mcm","clk":"11540557478","pt":1719495876128,"mc":[{"id":"1.230180115","rc":[{"atb":[[1.91,0],[1.96,4.59]],"id":44213406}],"con":true,"img":false}]}
{"op":"mcm","clk":"11540557497","pt":1719495876332,"mc":[{"id":"1.230180115","rc":[{"atb":[[1.19,0]],"id":39682601}],"con":true,"img":false}]}
{"op":"mcm","clk":"11540557584","pt":1719495877258,"mc":[{"id":"1.230180115","rc":[{"atb":[[1.72,0]],"id":61150133}],"con":true,"img":false}]}
{"op":"mcm","clk":"11540557593","pt":1719495877360,"mc":[{"id":"1.230180115","rc":[{"atb":[[1.02,2]],"id":61150133}],"con":true,"img":false}]}
{"op":"mcm","clk":"11540557638","pt":1719495877725,"mc":[{"id":"1.230180115","rc":[{"atb":[[1.92,0]],"id":44213406}],"con":true,"img":false}]}
{"op":"mcm","clk":"11540557650","pt":1719495877879,"mc":[{"id":"1.230180115","rc":[{"atb":[[1.97,2]],"id":44213406}],"con":true,"img":false}]}
{"op":"mcm","clk":"11540557692","pt":1719495878355,"mc":[{"id":"1.230180115","rc":[{"atb":[[2.22,0]],"id":63387150}],"con":true,"img":false}]}
{"op":"mcm","clk":"11540557701","pt":1719495878452,"mc":[{"id":"1.230180115","rc":[{"atb":[[1.14,6.69]],"id":39682601},{"atb":[[1.02,2]],"id":63387150}],"con":true,"img":false}]}
{"op":"mcm","clk":"11540557796","pt":1719495879640,"mc":[{"id":"1.230180115","rc":[{"atb":[[1.02,0]],"id":61150133}],"con":true,"img":false}]}
{"op":"mcm","clk":"11540557804","pt":1719495879740,"mc":[{"id":"1.230180115","rc":[{"atb":[[1.72,2]],"id":61150133}],"con":true,"img":false}]}
{"op":"mcm","clk":"11540557843","pt":1719495880363,"mc":[{"id":"1.230180115","rc":[{"atb":[[1.02,0]],"id":63387150}],"con":true,"img":false}]}
{"op":"mcm","clk":"11540557854","pt":1719495880459,"mc":[{"id":"1.230180115","rc":[{"atb":[[2.22,2]],"id":63387150}],"con":true,"img":false}]}
{"op":"mcm","clk":"11540557947","pt":1719495881747,"mc":[{"id":"1.230180115","rc":[{"atb":[[1.72,0]],"id":61150133}],"con":true,"img":false}]}
{"op":"mcm","clk":"11540557956","pt":1719495881857,"mc":[{"id":"1.230180115","rc":[{"atb":[[1.02,2]],"id":61150133}],"con":true,"img":false}]}
{"op":"mcm","clk":"11540557977","pt":1719495882054,"mc":[{"id":"1.230180115","rc":[{"atb":[[2.22,0]],"id":63387150}],"con":true,"img":false}]}
{"op":"mcm","clk":"11540557989","pt":1719495882158,"mc":[{"id":"1.230180115","rc":[{"atb":[[1.02,2]],"id":63387150}],"con":true,"img":false}]}
{"op":"mcm","clk":"11540558169","pt":1719495884326,"mc":[{"id":"1.230180115","rc":[{"spl":[[1.01,12]],"id":39682601}],"con":true,"img":false}]}
{"op":"mcm","clk":"11540558183","pt":1719495884534,"mc":[{"id":"1.230180115","rc":[{"atb":[[1.02,0]],"id":61150133}],"con":true,"img":false}]}
{"op":"mcm","clk":"11540558191","pt":1719495884634,"mc":[{"id":"1.230180115","rc":[{"atb":[[1.72,2]],"id":61150133}],"con":true,"img":false}]}
{"op":"mcm","clk":"11540558219","pt":1719495884941,"mc":[{"id":"1.230180115","rc":[{"atb":[[1.02,0]],"id":63387150}],"con":true,"img":false}]}
{"op":"mcm","clk":"11540558226","pt":1719495885044,"mc":[{"id":"1.230180115","rc":[{"atb":[[2.22,2]],"id":63387150}],"con":true,"img":false}]}
{"op":"mcm","clk":"11540558360","pt":1719495886440,"mc":[{"id":"1.230180115","rc":[{"atb":[[1.72,0]],"id":61150133}],"con":true,"img":false}]}
{"op":"mcm","clk":"11540558371","pt":1719495886546,"mc":[{"id":"1.230180115","rc":[{"atb":[[1.02,2]],"id":61150133}],"con":true,"img":false}]}
{"op":"mcm","clk":"11540558396","pt":1719495886850,"mc":[{"id":"1.230180115","rc":[{"atb":[[2.22,0]],"id":63387150}],"con":true,"img":false}]}
{"op":"mcm","clk":"11540558408","pt":1719495886955,"mc":[{"id":"1.230180115","rc":[{"atb":[[1.02,2]],"id":63387150}],"con":true,"img":false}]}
{"op":"mcm","clk":"11540558468","pt":1719495887581,"mc":[{"id":"1.230180115","rc":[{"atb":[[1.9,4.7]],"id":44213406}],"con":true,"img":false}]}
{"op":"mcm","clk":"11540558510","pt":1719495888044,"mc":[{"id":"1.230180115","rc":[{"atb":[[1.02,0]],"id":61150133}],"con":true,"img":false}]}
{"op":"mcm","clk":"11540558522","pt":1719495888146,"mc":[{"id":"1.230180115","rc":[{"atb":[[1.72,2]],"id":61150133}],"con":true,"img":false}]}
{"op":"mcm","clk":"11540558539","pt":1719495888351,"mc":[{"id":"1.230180115","rc":[{"atb":[[1.02,0]],"id":63387150}],"con":true,"img":false}]}
{"op":"mcm","clk":"11540558545","pt":1719495888462,"mc":[{"id":"1.230180115","rc":[{"atb":[[2.22,2]],"id":63387150}],"con":true,"img":false}]}
{"op":"mcm","clk":"11540558583","pt":1719495889075,"mc":[{"id":"1.230180115","rc":[{"atb":[[1.94,4.2]],"id":41804643},{"atb":[[1.14,1]],"id":39682601}],"con":true,"img":false}]}
{"op":"mcm","clk":"11540558632","pt":1719495889646,"mc":[{"id":"1.230180115","rc":[{"atb":[[1.72,0]],"id":61150133}],"con":true,"img":false}]}
{"op":"mcm","clk":"11540558642","pt":1719495889750,"mc":[{"id":"1.230180115","rc":[{"atb":[[1.02,2]],"id":61150133}],"con":true,"img":false}]}
{"op":"mcm","clk":"11540558679","pt":1719495890076,"mc":[{"id":"1.230180115","rc":[{"atb":[[2.22,0]],"id":63387150}],"con":true,"img":false}]}
{"op":"mcm","clk":"11540558685","pt":1719495890184,"mc":[{"id":"1.230180115","rc":[{"atb":[[1.02,2],[2.2,13.01]],"id":63387150}],"con":true,"img":false}]}
{"op":"mcm","clk":"11540558744","pt":1719495890655,"mc":[{"id":"1.230180115","rc":[{"atl":[[2.88,3.38]],"id":39682601}],"con":true,"img":false}]}
{"op":"mcm","clk":"11540558795","pt":1719495891168,"mc":[{"id":"1.230180115","rc":[{"atb":[[2.2,9.26]],"id":63387150}],"con":true,"img":false}]}
{"op":"mcm","clk":"11540558842","pt":1719495891578,"mc":[{"id":"1.230180115","rc":[{"atb":[[1.02,0]],"id":61150133}],"con":true,"img":false}]}
{"op":"mcm","clk":"11540558854","pt":1719495891686,"mc":[{"id":"1.230180115","rc":[{"atb":[[1.72,2],[1.7,6.25]],"id":61150133}],"con":true,"img":false}]}
{"op":"mcm","clk":"11540558883","pt":1719495892000,"mc":[{"id":"1.230180115","rc":[{"atb":[[1.02,0]],"id":63387150}],"con":true,"img":false}]}
{"op":"mcm","clk":"11540558895","pt":1719495892045,"mc":[{"id":"1.230180115","rc":[{"atb":[[1.81,3.75],[1.7,0]],"id":61150133},{"atb":[[2.22,2]],"id":63387150}],"con":true,"img":false}]}
{"op":"mcm","clk":"11540558907","pt":1719495892147,"mc":[{"id":"1.230180115","rc":[{"atb":[[1.82,3.75],[1.71,0]],"id":61150133}],"con":true,"img":false}]}
{"op":"mcm","clk":"11540558941","pt":1719495892561,"mc":[{"id":"1.230180115","rc":[{"atb":[[1.93,3.75]],"id":41804643}],"con":true,"img":false}]}
{"op":"mcm","clk":"11540558995","pt":1719495893074,"mc":[{"id":"1.230180115","rc":[{"atb":[[1.72,0]],"id":61150133}],"con":true,"img":false}]}
{"op":"mcm","clk":"11540559010","pt":1719495893183,"mc":[{"id":"1.230180115","rc":[{"atb":[[1.83,2]],"id":61150133}],"con":true,"img":false}]}
{"op":"mcm","clk":"11540559027","pt":1719495893386,"mc":[{"id":"1.230180115","rc":[{"atb":[[1.02,0]],"id":41804643}],"con":true,"img":false}]}
{"op":"mcm","clk":"11540559039","pt":1719495893446,"mc":[{"id":"1.230180115","rc":[{"atb":[[1.96,2]],"id":41804643}],"con":true,"img":false}]}
{"op":"mcm","clk":"11540559071","pt":1719495893749,"mc":[{"id":"1.230180115","rc":[{"atb":[[1.84,4.7]],"id":61150133},{"atb":[[2.22,0]],"id":63387150}],"con":true,"img":false}]}
{"op":"mcm","clk":"11540559081","pt":1719495893851,"mc":[{"id":"1.230180115","rc":[{"atb":[[1.82,0],[1.85,3.75]],"id":61150133},{"atb":[[1.02,2]],"id":63387150}],"con":true,"img":false}]}
{"op":"mcm","clk":"11540559100","pt":1719495894063,"mc":[{"id":"1.230180115","rc":[{"atb":[[1.89,5]],"id":44213406}],"con":true,"img":false}]}
{"op":"mcm","clk":"11540559181","pt":1719495895144,"mc":[{"id":"1.230180115","rc":[{"atb":[[1.93,0]],"id":41804643}],"con":true,"img":false}]}
{"op":"mcm","clk":"11540559208","pt":1719495895456,"mc":[{"id":"1.230180115","rc":[{"atb":[[1.83,0]],"id":61150133}],"con":true,"img":false}]}
{"op":"mcm","clk":"11540559216","pt":1719495895558,"mc":[{"id":"1.230180115","rc":[{"atb":[[1.86,2]],"id":61150133}],"con":true,"img":false}]}
{"op":"mcm","clk":"11540559240","pt":1719495895866,"mc":[{"id":"1.230180115","rc":[{"atb":[[1.02,0]],"id":63387150}],"con":true,"img":false}]}
{"op":"mcm","clk":"11540559250","pt":1719495895975,"mc":[{"id":"1.230180115","rc":[{"atb":[[2.22,2]],"id":63387150}],"con":true,"img":false}]}
{"op":"mcm","clk":"11540559270","pt":1719495896177,"mc":[{"id":"1.230180115","rc":[{"atb":[[1.28,3.38]],"id":39682601}],"con":true,"img":false}]}
{"op":"mcm","clk":"11540559292","pt":1719495896386,"mc":[{"id":"1.230180115","rc":[{"atb":[[1.28,0]],"id":39682601}],"con":true,"img":false}]}
{"op":"mcm","clk":"11540559382","pt":1719495897167,"mc":[{"id":"1.230180115","rc":[{"atb":[[2.22,0]],"id":63387150}],"con":true,"img":false}]}
{"op":"mcm","clk":"11540559387","pt":1719495897266,"mc":[{"id":"1.230180115","rc":[{"atb":[[1.02,2]],"id":63387150}],"con":true,"img":false}]}
{"op":"mcm","clk":"11540559515","pt":1719495898666,"mc":[{"id":"1.230180115","rc":[{"atb":[[1.02,0]],"id":63387150}],"con":true,"img":false}]}
{"op":"mcm","clk":"11540559524","pt":1719495898769,"mc":[{"id":"1.230180115","rc":[{"atb":[[2.22,2]],"id":63387150}],"con":true,"img":false}]}
{"op":"mcm","clk":"11540559613","pt":1719495899653,"mc":[{"id":"1.230180115","rc":[{"atb":[[2.22,0]],"id":63387150}],"con":true,"img":false}]}
{"op":"mcm","clk":"11540559624","pt":1719495899753,"mc":[{"id":"1.230180115","rc":[{"spn":4.18,"spf":"NaN","id":41804643},{"spn":3.58,"spf":"NaN","id":44213406},{"spn":1.29,"spf":1.0,"id":39682601},{"atb":[[1.02,2]],"id":63387150},{"spn":4.9,"spf":"NaN","id":63387150}],"con":true,"img":false}]}
{"op":"mcm","clk":"11540559712","pt":1719495900690,"mc":[{"id":"1.230180115","rc":[{"atb":[[1.3,0]],"id":39682601}],"con":true,"img":false}]}
{"op":"mcm","clk":"11540559723","pt":1719495900748,"mc":[{"id":"1.230180115","rc":[{"atb":[[1.02,10.47]],"id":39682601}],"con":true,"img":false}]}
{"op":"mcm","clk":"11540559753","pt":1719495901057,"mc":[{"id":"1.230180115","rc":[{"atb":[[1.02,0]],"id":63387150}],"con":true,"img":false}]}
{"op":"mcm","clk":"11540559765","pt":1719495901163,"mc":[{"id":"1.230180115","rc":[{"atb":[[2.22,2]],"id":63387150}],"con":true,"img":false}]}
{"op":"mcm","clk":"11540559806","pt":1719495901576,"mc":[{"id":"1.230180115","rc":[{"atb":[[1.14,6.69]],"id":39682601}],"con":true,"img":false}]}
{"op":"mcm","clk":"11540559919","pt":1719495902569,"mc":[{"id":"1.230180115","rc":[{"atb":[[2.22,0]],"id":63387150}],"con":true,"img":false}]}
{"op":"mcm","clk":"11540559931","pt":1719495902672,"mc":[{"id":"1.230180115","rc":[{"atb":[[1.02,2]],"id":63387150}],"con":true,"img":false}]}
{"op":"mcm","clk":"11540560016","pt":1719495903454,"mc":[{"id":"1.230180115","rc":[{"atb":[[1.02,0]],"id":63387150}],"con":true,"img":false}]}
{"op":"mcm","clk":"11540560025","pt":1719495903552,"mc":[{"id":"1.230180115","rc":[{"atb":[[2.22,2]],"id":63387150}],"con":true,"img":false}]}
{"op":"mcm","clk":"11540560123","pt":1719495904546,"mc":[{"id":"1.230180115","rc":[{"atb":[[2.22,0]],"id":63387150}],"con":true,"img":false}]}
{"op":"mcm","clk":"11540560131","pt":1719495904648,"mc":[{"id":"1.230180115","rc":[{"atb":[[1.89,0]],"id":44213406},{"atb":[[1.14,1]],"id":39682601},{"atl":[[2.86,0]],"id":39682601},{"atb":[[1.02,2]],"id":63387150}],"con":true,"img":false}]}
{"op":"mcm","clk":"11540560161","pt":1719495904958,"mc":[{"id":"1.230180115","rc":[{"atl":[[2.88,0]],"id":39682601}],"con":true,"img":false}]}
{"op":"mcm","clk":"11540560172","pt":1719495905061,"mc":[{"id":"1.230180115","rc":[{"atl":[[2.84,0],[3.65,4]],"id":39682601}],"con":true,"img":false}]}
{"op":"mcm","clk":"11540560251","pt":1719495905888,"mc":[{"id":"1.230180115","rc":[{"atb":[[1.02,0]],"id":63387150}],"con":true,"img":false}]}
{"op":"mcm","clk":"11540560260","pt":1719495905943,"mc":[{"id":"1.230180115","rc":[{"atb":[[2.22,2]],"id":63387150}],"con":true,"img":false}]}
{"op":"mcm","clk":"11540560340","pt":1719495906571,"mc":[{"id":"1.230180115","rc":[{"atb":[[1.29,0]],"id":39682601}],"con":true,"img":false}]}
{"op":"mcm","clk":"11540560405","pt":1719495907186,"mc":[{"id":"1.230180115","rc":[{"atl":[[2.86,3.08]],"id":39682601}],"con":true,"img":false}]}
{"op":"mcm","clk":"11540560439","pt":1719495907454,"mc":[{"id":"1.230180115","rc":[{"atb":[[1.02,8.47]],"id":39682601}],"con":true,"img":false}]}
{"op":"mcm","clk":"11540560451","pt":1719495907556,"mc":[{"id":"1.230180115","rc":[{"atb":[[1.28,2]],"id":39682601}],"con":true,"img":false}]}
{"op":"mcm","clk":"11540560475","pt":1719495907760,"mc":[{"id":"1.230180115","rc":[{"atb":[[1.81,0]],"id":61150133},{"atb":[[2.22,0]],"id":63387150}],"con":true,"img":false}]}
{"op":"mcm","clk":"11540560486","pt":1719495907868,"mc":[{"id":"1.230180115","rc":[{"atb":[[1.02,2]],"id":63387150}],"con":true,"img":false}]}
{"op":"mcm","clk":"11540560615","pt":1719495908957,"mc":[{"id":"1.230180115","rc":[{"atb":[[1.02,0]],"id":63387150}],"con":true,"img":false}]}
{"op":"mcm","clk":"11540560629","pt":1719495909054,"mc":[{"id":"1.230180115","rc":[{"atb":[[2.22,2]],"id":63387150}],"con":true,"img":false}]}
{"op":"mcm","clk":"11540560769","pt":1719495910378,"mc":[{"id":"1.230180115","rc":[{"atb":[[2.22,0]],"id":63387150}],"con":true,"img":false}]}
{"op":"mcm","clk":"11540560781","pt":1719495910486,"mc":[{"id":"1.230180115","rc":[{"atb":[[1.02,2]],"id":63387150}],"con":true,"img":false}]}
{"op":"mcm","clk":"11540560896","pt":1719495911573,"mc":[{"id":"1.230180115","rc":[{"atb":[[1.02,0]],"id":63387150}],"con":true,"img":false}]}
{"op":"mcm","clk":"11540560904","pt":1719495911672,"mc":[{"id":"1.230180115","rc":[{"atb":[[2.22,2]],"id":63387150}],"con":true,"img":false}]}
{"op":"mcm","clk":"11540560960","pt":1719495912191,"mc":[{"id":"1.230180115","rc":[{"atb":[[1.29,19.07]],"id":39682601}],"con":true,"img":false}]}
{"op":"mcm","clk":"11540560990","pt":1719495912503,"mc":[{"id":"1.230180115","rc":[{"atb":[[1.84,0]],"id":61150133}],"con":true,"img":false}]}
{"op":"mcm","clk":"11540561014","pt":1719495912660,"mc":[{"id":"1.230180115","rc":[{"atb":[[1.88,4.48]],"id":61150133},{"atb":[[1.28,0]],"id":39682601}],"con":true,"img":false}]}
{"op":"mcm","clk":"11540561029","pt":1719495912761,"mc":[{"id":"1.230180115","rc":[{"atb":[[1.89,3.75],[1.85,0]],"id":61150133},{"atb":[[1.02,10.47]],"id":39682601}],"con":true,"img":false}]}
{"op":"mcm","clk":"11540561051","pt":1719495912967,"mc":[{"id":"1.230180115","rc":[{"atb":[[2.22,0]],"id":63387150}],"con":true,"img":false}]}
{"op":"mcm","clk":"11540561064","pt":1719495913070,"mc":[{"id":"1.230180115","rc":[{"atb":[[1.73,0]],"id":44213406},{"atb":[[1.27,0]],"id":39682601},{"atb":[[1.02,2]],"id":63387150}],"con":true,"img":false}]}
{"op":"mcm","clk":"11540561196","pt":1719495914470,"mc":[{"id":"1.230180115","rc":[{"atb":[[1.84,5.08],[1.86,0]],"id":61150133}],"con":true,"img":false}]}
{"op":"mcm","clk":"11540561204","pt":1719495914578,"mc":[{"id":"1.230180115","rc":[{"atb":[[1.9,2]],"id":61150133}],"con":true,"img":false}]}
{"op":"mcm","clk":"11540561225","pt":1719495914780,"mc":[{"id":"1.230180115","rc":[{"atb":[[1.02,0]],"id":63387150}],"con":true,"img":false}]}
{"op":"mcm","clk":"11540561235","pt":1719495914882,"mc":[{"id":"1.230180115","rc":[{"atb":[[2.22,2]],"id":63387150}],"con":true,"img":false}]}
{"op":"mcm","clk":"11540561246","pt":1719495914986,"mc":[{"id":"1.230180115","rc":[{"atb":[[1.95,7]],"id":41804643}],"con":true,"img":false}]}
{"op":"mcm","clk":"11540561353","pt":1719495916078,"mc":[{"id":"1.230180115","rc":[{"atb":[[2.22,0]],"id":63387150}],"con":true,"img":false}]}
{"op":"mcm","clk":"11540561369","pt":1719495916175,"mc":[{"id":"1.230180115","rc":[{"atb":[[1.02,2]],"id":63387150}],"con":true,"img":false}]}
{"op":"mcm","clk":"11540561391","pt":1719495916386,"mc":[{"id":"1.230180115","rc":[{"atb":[[1.95,10.82]],"id":44213406}],"con":true,"img":false}]}
{"op":"mcm","clk":"11540561489","pt":1719495917367,"mc":[{"id":"1.230180115","rc":[{"atb":[[1.02,0]],"id":63387150}],"con":true,"img":false}]}
{"op":"mcm","clk":"11540561496","pt":1719495917468,"mc":[{"id":"1.230180115","rc":[{"atb":[[1.92,4.59]],"id":61150133},{"atb":[[2.22,2]],"id":63387150}],"con":true,"img":false}]}
{"op":"mcm","clk":"11540561506","pt":1719495917575,"mc":[{"id":"1.230180115","rc":[{"atb":[[1.89,0],[1.93,3.75]],"id":61150133}],"con":true,"img":false}]}
{"op":"mcm","clk":"11540561529","pt":1719495917885,"mc":[{"id":"1.230180115","rc":[{"atb":[[1.31,19.12]],"id":39682601}],"con":true,"img":false}]}
{"op":"mcm","clk":"11540561621","pt":1719495918706,"mc":[{"id":"1.230180115","rc":[{"atb":[[1.9,0]],"id":61150133}],"con":true,"img":false}]}
{"op":"mcm","clk":"11540561629","pt":1719495918767,"mc":[{"id":"1.230180115","rc":[{"atb":[[1.02,2]],"id":61150133}],"con":true,"img":false}]}
{"op":"mcm","clk":"11540561652","pt":1719495919069,"mc":[{"id":"1.230180115","rc":[{"atb":[[2.22,0]],"id":63387150}],"con":true,"img":false}]}
{"op":"mcm","clk":"11540561667","pt":1719495919178,"mc":[{"id":"1.230180115","rc":[{"atb":[[1.02,2],[2.2,13.01]],"id":63387150}],"con":true,"img":false}]}
{"op":"mcm","clk":"11540561771","pt":1719495920203,"mc":[{"id":"1.230180115","rc":[{"atb":[[2.2,9.26]],"id":63387150}],"con":true,"img":false}]}
{"op":"mcm","clk":"11540561866","pt":1719495920985,"mc":[{"id":"1.230180115","rc":[{"atb":[[1.02,0]],"id":63387150}],"con":true,"img":false}]}
{"op":"mcm","clk":"11540561880","pt":1719495921086,"mc":[{"id":"1.230180115","rc":[{"atb":[[2.22,2]],"id":63387150}],"con":true,"img":false}]}
{"op":"mcm","clk":"11540561999","pt":1719495921970,"mc":[{"id":"1.230180115","rc":[{"atb":[[2.22,0]],"id":63387150}],"con":true,"img":false}]}
{"op":"mcm","clk":"11540562028","pt":1719495922177,"mc":[{"id":"1.230180115","rc":[{"atb":[[1.02,2]],"id":63387150}],"con":true,"img":false}]}
{"op":"mcm","clk":"11540562160","pt":1719495923474,"mc":[{"id":"1.230180115","rc":[{"atb":[[1.14,6.69]],"id":39682601}],"con":true,"img":false}]}
{"op":"mcm","clk":"11540562173","pt":1719495923578,"mc":[{"id":"1.230180115","rc":[{"atb":[[1.02,0]],"id":63387150}],"con":true,"img":false}]}
{"op":"mcm","clk":"11540562184","pt":1719495923681,"mc":[{"id":"1.230180115","rc":[{"atb":[[2.22,2]],"id":63387150}],"con":true,"img":false}]}
{"op":"mcm","clk":"11540562269","pt":1719495924506,"mc":[{"id":"1.230180115","rc":[{"atb":[[1.86,0]],"id":44213406}],"con":true,"img":false}]}
{"op":"mcm","clk":"11540562375","pt":1719495925390,"mc":[{"id":"1.230180115","rc":[{"atb":[[1.84,0]],"id":61150133}],"con":true,"img":false}]}
{"op":"mcm","clk":"11540562388","pt":1719495925512,"mc":[{"id":"1.230180115","rc":[{"atb":[[2.22,0]],"id":63387150}],"con":true,"img":false}]}
{"op":"mcm","clk":"11540562395","pt":1719495925589,"mc":[{"id":"1.230180115","rc":[{"atb":[[1.02,2]],"id":63387150}],"con":true,"img":false}]}
{"op":"mcm","clk":"11540562495","pt":1719495926673,"mc":[{"id":"1.230180115","rc":[{"atb":[[1.02,0]],"id":63387150}],"con":true,"img":false}]}
{"op":"mcm","clk":"11540562503","pt":1719495926775,"mc":[{"id":"1.230180115","rc":[{"atb":[[1.95,2]],"id":41804643},{"atb":[[1.95,5.82]],"id":44213406},{"atb":[[1.14,1]],"id":39682601},{"atl":[[2.86,0]],"id":39682601},{"atb":[[2.22,2]],"id":63387150}],"con":true,"img":false}]}
{"op":"mcm","clk":"11540562578","pt":1719495927602,"mc":[{"id":"1.230180115","rc":[{"atb":[[2.22,0]],"id":63387150}],"con":true,"img":false}]}
{"op":"mcm","clk":"11540562585","pt":1719495927709,"mc":[{"id":"1.230180115","rc":[{"atb":[[1.02,2]],"id":63387150}],"con":true,"img":false}]}
{"op":"mcm","clk":"11540562643","pt":1719495928273,"mc":[{"id":"1.230180115","rc":[{"atb":[[1.24,3.38]],"id":39682601}],"con":true,"img":false}]}
{"op":"mcm","clk":"11540562702","pt":1719495928893,"mc":[{"id":"1.230180115","rc":[{"atb":[[1.02,0]],"id":63387150}],"con":true,"img":false}]}
{"op":"mcm","clk":"11540562714","pt":1719495928997,"mc":[{"id":"1.230180115","rc":[{"atb":[[2.22,2]],"id":63387150}],"con":true,"img":false}]}
{"op":"mcm","clk":"11540562782","pt":1719495929784,"mc":[{"id":"1.230180115","rc":[{"atl":[[2.86,3.08]],"id":39682601}],"con":true,"img":false}]}
{"op":"mcm","clk":"11540562803","pt":1719495929979,"mc":[{"id":"1.230180115","rc":[{"atb":[[1.24,0]],"id":39682601}],"con":true,"img":false}]}
{"op":"mcm","clk":"11540562813","pt":1719495930085,"mc":[{"id":"1.230180115","rc":[{"atb":[[1.88,0]],"id":61150133}],"con":true,"img":false}]}
{"op":"mcm","clk":"11540562836","pt":1719495930290,"mc":[{"id":"1.230180115","rc":[{"atb":[[2.22,0]],"id":63387150}],"con":true,"img":false}]}
{"op":"mcm","clk":"11540562849","pt":1719495930396,"mc":[{"id":"1.230180115","rc":[{"atb":[[1.02,2]],"id":63387150}],"con":true,"img":false}]}
{"op":"mcm","clk":"11540562861","pt":1719495930497,"mc":[{"id":"1.230180115","rc":[{"atb":[[1.95,4.15]],"id":61150133}],"con":true,"img":false}]}
{"op":"mcm","clk":"11540562870","pt":1719495930596,"mc":[{"id":"1.230180115","rc":[{"atb":[[1.96,4.16],[1.93,0]],"id":61150133}],"con":true,"img":false}]}
{"op":"mcm","clk":"11540563048","pt":1719495932317,"mc":[{"id":"1.230180115","rc":[{"atb":[[1.02,0]],"id":63387150}],"con":true,"img":false}]}
{"op":"mcm","clk":"11540563058","pt":1719495932420,"mc":[{"id":"1.230180115","rc":[{"atb":[[2.22,2]],"id":63387150}],"con":true,"img":false}]}
{"op":"mcm","clk":"11540563183","pt":1719495933613,"mc":[{"id":"1.230180115","rc":[{"atb":[[2.22,0]],"id":63387150}],"con":true,"img":false}]}
{"op":"mcm","clk":"11540563194","pt":1719495933718,"mc":[{"id":"1.230180115","rc":[{"atb":[[1.02,2]],"id":63387150}],"con":true,"img":false}]}
{"op":"mcm","clk":"11540563415","pt":1719495935795,"mc":[{"id":"1.230180115","rc":[{"atb":[[1.91,5.08]],"id":61150133}],"con":true,"img":false}]}
{"op":"mcm","clk":"11540563440","pt":1719495936002,"mc":[{"id":"1.230180115","rc":[{"atl":[[34,2],[46,0]],"id":41804643},{"atb":[[1.91,0]],"id":61150133},{"atl":[[17,2.42],[20,0]],"id":61150133},{"atl":[[3.15,4.08],[3.65,0]],"id":39682601}],"con":true,"img":false}]}
{"op":"mcm","clk":"11540563458","pt":1719495936208,"mc":[{"id":"1.230180115","rc":[{"atb":[[1.94,9.2]],"id":41804643}],"con":true,"img":false}]}
{"op":"mcm","clk":"11540563480","pt":1719495936409,"mc":[{"id":"1.230180115","rc":[{"atl":[[2.86,0]],"id":39682601}],"con":true,"img":false}]}
{"op":"mcm","clk":"11540563586","pt":1719495937602,"mc":[{"id":"1.230180115","rc":[{"atb":[[1.94,5]],"id":44213406},{"atb":[[1.02,0]],"id":63387150}],"con":true,"img":false}]}
{"op":"mcm","clk":"11540563598","pt":1719495937708,"mc":[{"id":"1.230180115","rc":[{"atb":[[2.22,2]],"id":63387150}],"con":true,"img":false}]}
{"op":"mcm","clk":"11540563672","pt":1719495938423,"mc":[{"id":"1.230180115","rc":[{"atl":[[5.6,1],[5.9,0]],"id":61150133}],"con":true,"img":false}]}
{"op":"mcm","clk":"11540563741","pt":1719495938997,"mc":[{"id":"1.230180115","rc":[{"atb":[[2.22,0]],"id":63387150}],"con":true,"img":false}]}
{"op":"mcm","clk":"11540563753","pt":1719495939108,"mc":[{"id":"1.230180115","rc":[{"atb":[[1.02,2]],"id":63387150}],"con":true,"img":false}]}
{"op":"mcm","clk":"11540563897","pt":1719495940431,"mc":[{"id":"1.230180115","rc":[{"atb":[[1.02,0]],"id":63387150}],"con":true,"img":false}]}
{"op":"mcm","clk":"11540563905","pt":1719495940482,"mc":[{"id":"1.230180115","rc":[{"atb":[[2.22,2]],"id":63387150}],"con":true,"img":false}]}
{"op":"mcm","clk":"11540564060","pt":1719495942031,"mc":[{"id":"1.230180115","rc":[{"atb":[[2.22,0]],"id":63387150}],"con":true,"img":false}]}
{"op":"mcm","clk":"11540564073","pt":1719495942083,"mc":[{"id":"1.230180115","rc":[{"atb":[[1.02,2]],"id":63387150}],"con":true,"img":false}]}
{"op":"mcm","clk":"11540564103","pt":1719495942393,"mc":[{"id":"1.230180115","rc":[{"atl":[[5.6,0],[5.7,1]],"id":61150133},{"atb":[[2.2,13.01]],"id":63387150}],"con":true,"img":false}]}
{"op":"mcm","clk":"11540564111","pt":1719495942495,"mc":[{"id":"1.230180115","rc":[{"atb":[[1.55,0]],"id":44213406}],"con":true,"img":false}]}
{"op":"mcm","clk":"11540564176","pt":1719495943217,"mc":[{"id":"1.230180115","rc":[{"atl":[[5.6,1],[5.7,0]],"id":61150133}],"con":true,"img":false}]}
{"op":"mcm","clk":"11540564222","pt":1719495943687,"mc":[{"id":"1.230180115","rc":[{"atb":[[1.02,0]],"id":63387150}],"con":true,"img":false}]}
{"op":"mcm","clk":"11540564233","pt":1719495943789,"mc":[{"id":"1.230180115","rc":[{"atb":[[1.94,4.2]],"id":41804643},{"atb":[[1.94,0]],"id":44213406},{"atb":[[2.22,2],[2.2,9.26]],"id":63387150}],"con":true,"img":false}]}
{"op":"mcm","clk":"11540564278","pt":1719495944311,"mc":[{"id":"1.230180115","rc":[{"atb":[[1.92,5.59],[1.97,0]],"id":61150133},{"atl":[[5.6,0],[5.5,1]],"id":61150133},{"atl":[[2.3,1],[2.26,0]],"id":39682601}],"con":true,"img":false}]}
{"op":"mcm","clk":"11540564345","pt":1719495944925,"mc":[{"id":"1.230180115","rc":[{"atb":[[2.22,0]],"id":63387150}],"con":true,"img":false}]}
{"op":"mcm","clk":"11540564357","pt":1719495945030,"mc":[{"id":"1.230180115","rc":[{"atb":[[1.02,2]],"id":63387150}],"con":true,"img":false}]}
{"op":"mcm","clk":"11540564531","pt":1719495946866,"mc":[{"id":"1.230180115","rc":[{"atb":[[1.13,5.69]],"id":39682601}],"con":true,"img":false}]}
{"op":"mcm","clk":"11540564566","pt":1719495947122,"mc":[{"id":"1.230180115","rc":[{"atb":[[1.02,0]],"id":63387150}],"con":true,"img":false}]}
{"op":"mcm","clk":"11540564576","pt":1719495947221,"mc":[{"id":"1.230180115","rc":[{"atb":[[2.22,2]],"id":63387150}],"con":true,"img":false}]}
{"op":"mcm","clk":"11540564757","pt":1719495948932,"mc":[{"id":"1.230180115","rc":[{"atb":[[1.24,3.38]],"id":39682601}],"con":true,"img":false}]}
{"op":"mcm","clk":"11540564809","pt":1719495949406,"mc":[{"id":"1.230180115","rc":[{"atb":[[1.13,0]],"id":39682601}],"con":true,"img":false}]}
{"op":"mcm","clk":"11540564882","pt":1719495950345,"mc":[{"id":"1.230180115","rc":[{"atl":[[2.66,3.45]],"id":39682601}],"con":true,"img":false}]}
{"op":"mcm","clk":"11540564890","pt":1719495950444,"mc":[{"id":"1.230180115","rc":[{"atl":[[2.64,3.45],[3.15,0]],"id":39682601}],"con":true,"img":false}]}
{"op":"mcm","clk":"11540564905","pt":1719495950650,"mc":[{"id":"1.230180115","rc":[{"atb":[[2.22,0]],"id":63387150}],"con":true,"img":false}]}
{"op":"mcm","clk":"11540564915","pt":1719495950704,"mc":[{"id":"1.230180115","rc":[{"atb":[[1.02,2]],"id":63387150}],"con":true,"img":false}]}
{"op":"mcm","clk":"11540564989","pt":1719495951526,"mc":[{"id":"1.230180115","rc":[{"atl":[[5.5,0],[5.4,1]],"id":61150133}],"con":true,"img":false}]}
{"op":"mcm","clk":"11540564996","pt":1719495951632,"mc":[{"id":"1.230180115","rc":[{"atl":[[5.6,2],[17,0]],"id":61150133}],"con":true,"img":false}]}
{"op":"mcm","clk":"11540565084","pt":1719495952924,"mc":[{"id":"1.230180115","rc":[{"atb":[[1.02,0]],"id":63387150}],"con":true,"img":false}]}
{"op":"mcm","clk":"11540565095","pt":1719495953028,"mc":[{"id":"1.230180115","rc":[{"atb":[[2.22,2]],"id":63387150}],"con":true,"img":false}]}
{"op":"mcm","clk":"11540565157","pt":1719495953805,"mc":[{"id":"1.230180115","rc":[{"atb":[[1.9,0]],"id":44213406}],"con":true,"img":false}]}
{"op":"mcm","clk":"11540565183","pt":1719495954123,"mc":[{"id":"1.230180115","rc":[{"atb":[[2.22,0]],"id":63387150}],"con":true,"img":false}]}
{"op":"mcm","clk":"11540565197","pt":1719495954222,"mc":[{"id":"1.230180115","rc":[{"atb":[[1.02,2]],"id":63387150}],"con":true,"img":false}]}
{"op":"mcm","clk":"11540565341","pt":1719495956033,"mc":[{"id":"1.230180115","rc":[{"atb":[[1.95,9.24]],"id":61150133},{"atb":[[1.02,0]],"id":63387150}],"con":true,"img":false}]}
{"op":"mcm","clk":"11540565350","pt":1719495956137,"mc":[{"id":"1.230180115","rc":[{"atb":[[1.96,0],[1.93,8.32]],"id":61150133},{"atb":[[2.22,2]],"id":63387150}],"con":true,"img":false}]}
{"op":"mcm","clk":"11540565375","pt":1719495956448,"mc":[{"id":"1.230180115","rc":[{"atb":[[1.93,5]],"id":41804643},{"atl":[[5.6,0],[17,3]],"id":61150133}],"con":true,"img":false}]}
{"op":"mcm","clk":"11540565426","pt":1719495956915,"mc":[{"id":"1.230180115","rc":[{"atb":[[1.95,4.15]],"id":61150133}],"con":true,"img":false}]}
{"op":"mcm","clk":"11540565474","pt":1719495957431,"mc":[{"id":"1.230180115","rc":[{"atb":[[2.22,0]],"id":63387150}],"con":true,"img":false}]}
{"op":"mcm","clk":"11540565481","pt":1719495957536,"mc":[{"id":"1.230180115","rc":[{"atb":[[1.02,2]],"id":63387150}],"con":true,"img":false}]}
{"op":"mcm","clk":"11540565500","pt":1719495957741,"mc":[{"id":"1.230180115","rc":[{"atb":[[1.95,10.82]],"id":44213406}],"con":true,"img":false}]}
{"op":"mcm","clk":"11540565676","pt":1719495959443,"mc":[{"id":"1.230180115","rc":[{"atb":[[1.02,0]],"id":63387150}],"con":true,"img":false}]}
{"op":"mcm","clk":"11540565686","pt":1719495959552,"mc":[{"id":"1.230180115","rc":[{"atb":[[2.22,2]],"id":63387150}],"con":true,"img":false}]}
{"op":"mcm","clk":"11540565864","pt":1719495961416,"mc":[{"id":"1.230180115","rc":[{"spn":1.95,"spf":1.0,"id":61150133},{"spn":1.31,"spf":1.0,"id":39682601},{"atb":[[2.22,0]],"id":63387150}],"con":true,"img":false}]}
{"op":"mcm","clk":"11540565871","pt":1719495961524,"mc":[{"id":"1.230180115","rc":[{"atb":[[1.02,2]],"id":63387150}],"con":true,"img":false}]}
{"op":"mcm","clk":"11540565988","pt":1719495963134,"mc":[{"id":"1.230180115","rc":[{"atb":[[1.02,0]],"id":63387150}],"con":true,"img":false}]}
{"op":"mcm","clk":"11540565996","pt":1719495963240,"mc":[{"id":"1.230180115","rc":[{"atb":[[2.22,2]],"id":63387150}],"con":true,"img":false}]}
{"op":"mcm","clk":"11540566030","pt":1719495963645,"mc":[{"id":"1.230180115","rc":[{"atb":[[1.95,5]],"id":44213406}],"con":true,"img":false}]}
{"op":"mcm","clk":"11540566050","pt":1719495963956,"mc":[{"id":"1.230180115","rc":[{"atb":[[2.18,3.75]],"id":63387150}],"con":true,"img":false}]}
{"op":"mcm","clk":"11540566070","pt":1719495964163,"mc":[{"id":"1.230180115","rc":[{"atb":[[2.18,0]],"id":63387150}],"con":true,"img":false}]}
{"op":"mcm","clk":"11540566186","pt":1719495965463,"mc":[{"id":"1.230180115","rc":[{"atb":[[2.22,0]],"id":63387150}],"con":true,"img":false}]}
{"op":"mcm","clk":"11540566203","pt":1719495965559,"mc":[{"id":"1.230180115","rc":[{"atb":[[1.02,2]],"id":63387150}],"con":true,"img":false}]}
{"op":"mcm","clk":"11540566341","pt":1719495966955,"mc":[{"id":"1.230180115","rc":[{"atb":[[1.07,3.75]],"id":63387150}],"con":true,"img":false}]}
{"op":"mcm","clk":"11540566362","pt":1719495967162,"mc":[{"id":"1.230180115","rc":[{"atb":[[1.02,0]],"id":63387150}],"con":true,"img":false}]}
{"op":"mcm","clk":"11540566372","pt":1719495967265,"mc":[{"id":"1.230180115","rc":[{"atb":[[2.22,2]],"id":63387150}],"con":true,"img":false}]}
{"op":"mcm","clk":"11540566382","pt":1719495967320,"mc":[{"id":"1.230180115","rc":[{"atb":[[1.07,3.31]],"id":63387150}],"con":true,"img":false}]}
{"op":"mcm","clk":"11540566391","pt":1719495967422,"mc":[{"id":"1.230180115","rc":[{"atb":[[1.07,0]],"id":63387150}],"con":true,"img":false}]}
{"op":"mcm","clk":"11540566477","pt":1719495968354,"mc":[{"id":"1.230180115","rc":[{"atb":[[2.22,0]],"id":63387150}],"con":true,"img":false}]}
{"op":"mcm","clk":"11540566484","pt":1719495968457,"mc":[{"id":"1.230180115","rc":[{"atb":[[1.02,2]],"id":63387150}],"con":true,"img":false}]}
{"op":"mcm","clk":"11540566583","pt":1719495969552,"mc":[{"id":"1.230180115","rc":[{"atb":[[1.99,5.58]],"id":61150133}],"con":true,"img":false}]}
{"op":"mcm","clk":"11540566593","pt":1719495969659,"mc":[{"id":"1.230180115","rc":[{"atb":[[2,5.59],[1.93,0]],"id":61150133}],"con":true,"img":false}]}
{"op":"mcm","clk":"11540566659","pt":1719495970326,"mc":[{"id":"1.230180115","rc":[{"atb":[[1.02,0]],"id":63387150}],"con":true,"img":false}]}
{"op":"mcm","clk":"11540566667","pt":1719495970434,"mc":[{"id":"1.230180115","rc":[{"atb":[[2.22,2]],"id":63387150}],"con":true,"img":false}]}
{"op":"mcm","clk":"11540566813","pt":1719495971871,"mc":[{"id":"1.230180115","rc":[{"atb":[[2.22,0]],"id":63387150}],"con":true,"img":false}]}
{"op":"mcm","clk":"11540566824","pt":1719495971976,"mc":[{"id":"1.230180115","rc":[{"atb":[[1.02,2]],"id":63387150}],"con":true,"img":false}]}
{"op":"mcm","clk":"11540566927","pt":1719495973061,"mc":[{"id":"1.230180115","rc":[{"atb":[[1.02,0]],"id":63387150}],"con":true,"img":false}]}
{"op":"mcm","clk":"11540566937","pt":1719495973163,"mc":[{"id":"1.230180115","rc":[{"atb":[[2.22,2]],"id":63387150}],"con":true,"img":false}]}
{"op":"mcm","clk":"11540567026","pt":1719495974248,"mc":[{"id":"1.230180115","rc":[{"atb":[[2.22,0]],"id":63387150}],"con":true,"img":false}]}
{"op":"mcm","clk":"11540567036","pt":1719495974349,"mc":[{"id":"1.230180115","rc":[{"atb":[[1.02,2]],"id":63387150}],"con":true,"img":false}]}
{"op":"mcm","clk":"11540567108","pt":1719495975230,"mc":[{"id":"1.230180115","rc":[{"atb":[[1.93,5.08]],"id":61150133}],"con":true,"img":false}]}
{"op":"mcm","clk":"11540567208","pt":1719495976539,"mc":[{"id":"1.230180115","rc":[{"atb":[[1.02,0]],"id":63387150}],"con":true,"img":false}]}
{"op":"mcm","clk":"11540567214","pt":1719495976635,"mc":[{"id":"1.230180115","rc":[{"atb":[[2.22,2]],"id":63387150}],"con":true,"img":false}]}
{"op":"mcm","clk":"11540567355","pt":1719495978133,"mc":[{"id":"1.230180115","rc":[{"atb":[[2.22,0]],"id":63387150}],"con":true,"img":false}]}
{"op":"mcm","clk":"11540567376","pt":1719495978240,"mc":[{"id":"1.230180115","rc":[{"atb":[[1.02,2]],"id":63387150}],"con":true,"img":false}]}
{"op":"mcm","clk":"11540567484","pt":1719495979267,"mc":[{"id":"1.230180115","rc":[{"atb":[[1.02,0]],"id":63387150}],"con":true,"img":false}]}
{"op":"mcm","clk":"11540567498","pt":1719495979369,"mc":[{"id":"1.230180115","rc":[{"atb":[[2.22,2]],"id":63387150}],"con":true,"img":false}]}
{"op":"mcm","clk":"11540567666","pt":1719495980895,"mc":[{"id":"1.230180115","rc":[{"atb":[[1.94,0]],"id":41804643}],"con":true,"img":false}]}
{"op":"mcm","clk":"11540567694","pt":1719495981138,"mc":[{"id":"1.230180115","rc":[{"atl":[[6.2,2.16]],"id":41804643},{"atl":[[5.3,2.25]],"id":61150133},{"atl":[[5.1,2.44]],"id":44213406},{"atl":[[2.28,3.46]],"id":39682601},{"atl":[[7.4,2.19]],"id":63387150}],"con":true,"img":false}]}
{"op":"mcm","clk":"11540567702","pt":1719495981289,"mc":[{"id":"1.230180115","rc":[{"atl":[[34,0],[8.4,3.16]],"id":41804643},{"atl":[[17,0],[5.4,5.5]],"id":61150133},{"atl":[[26,0],[6.6,3.44]],"id":44213406},{"atl":[[2.64,0],[2.26,3.45]],"id":39682601},{"atl":[[75,0],[11,3.19]],"id":63387150}],"con":true,"img":false}]}
{"op":"mcm","clk":"11540567712","pt":1719495981345,"mc":[{"id":"1.230180115","rc":[{"atl":[[2.24,3.64]],"id":39682601}],"con":true,"img":false}]}
{"op":"mcm","clk":"11540567728","pt":1719495981448,"mc":[{"id":"1.230180115","rc":[{"atl":[[8.2,5.44]],"id":63387150}],"con":true,"img":false}]}
{"op":"mcm","clk":"11540567738","pt":1719495981555,"mc":[{"id":"1.230180115","rc":[{"atb":[[1.93,0]],"id":41804643},{"atb":[[1.93,0]],"id":61150133}],"con":true,"img":false}]}
{"op":"mcm","clk":"11540567748","pt":1719495981653,"mc":[{"id":"1.230180115","rc":[{"atl":[[6,0.84]],"id":41804643},{"atl":[[5.2,0.84]],"id":61150133},{"atl":[[5,0.84]],"id":44213406},{"atl":[[2.24,4.49]],"id":39682601},{"atl":[[7.2,0.84]],"id":63387150}],"con":true,"img":false}]}
{"op":"mcm","clk":"11540567810","pt":1719495982274,"mc":[{"id":"1.230180115","rc":[{"atb":[[1.92,3.75]],"id":41804643}],"con":true,"img":false}]}
{"op":"mcm","clk":"11540567822","pt":1719495982382,"mc":[{"id":"1.230180115","rc":[{"atb":[[1.92,0]],"id":41804643}],"con":true,"img":false}]}
{"op":"mcm","clk":"11540567854","pt":1719495982741,"mc":[{"id":"1.230180115","rc":[{"atb":[[1.95,5.75]],"id":41804643},{"atb":[[2.22,0],[2.2,13.01]],"id":63387150}],"con":true,"img":false}]}
{"op":"mcm","clk":"11540567865","pt":1719495982848,"mc":[{"id":"1.230180115","rc":[{"atb":[[1.02,2]],"id":63387150}],"con":true,"img":false}]}
{"op":"mcm","clk":"11540567941","pt":1719495983569,"mc":[{"id":"1.230180115","rc":[{"atb":[[2.2,9.26]],"id":63387150}],"con":true,"img":false}]}
{"op":"mcm","clk":"11540568005","pt":1719495984248,"mc":[{"id":"1.230180115","rc":[{"atb":[[1.96,0]],"id":41804643}],"con":true,"img":false}]}
{"op":"mcm","clk":"11540568015","pt":1719495984359,"mc":[{"id":"1.230180115","rc":[{"atb":[[1.92,50],[1.02,2],[1.95,3.75]],"id":41804643}],"con":true,"img":false}]}
{"op":"mcm","clk":"11540568046","pt":1719495984760,"mc":[{"id":"1.230180115","rc":[{"atb":[[1.02,0]],"id":63387150}],"con":true,"img":false}]}
{"op":"mcm","clk":"11540568057","pt":1719495984864,"mc":[{"id":"1.230180115","rc":[{"atb":[[2.22,2]],"id":63387150}],"con":true,"img":false}]}
{"op":"mcm","clk":"11540568159","pt":1719495985849,"mc":[{"id":"1.230180115","rc":[{"atb":[[2.22,0]],"id":63387150}],"con":true,"img":false}]}
{"op":"mcm","clk":"11540568168","pt":1719495985950,"mc":[{"id":"1.230180115","rc":[{"atb":[[1.02,2]],"id":63387150}],"con":true,"img":false}]}
{"op":"mcm","clk":"11540568267","pt":1719495987082,"mc":[{"id":"1.230180115","rc":[{"atb":[[1.95,0]],"id":41804643}],"con":true,"img":false}]}
{"op":"mcm","clk":"11540568303","pt":1719495987448,"mc":[{"id":"1.230180115","rc":[{"atb":[[1.02,0]],"id":63387150}],"con":true,"img":false}]}
{"op":"mcm","clk":"11540568311","pt":1719495987553,"mc":[{"id":"1.230180115","rc":[{"atb":[[2.22,2]],"id":63387150}],"con":true,"img":false}]}
{"op":"mcm","clk":"11540568404","pt":1719495988595,"mc":[{"id":"1.230180115","rc":[{"atb":[[1.94,4.2]],"id":41804643}],"con":true,"img":false}]}
{"op":"mcm","clk":"11540568443","pt":1719495988857,"mc":[{"id":"1.230180115","rc":[{"atb":[[1.02,0]],"id":41804643}],"con":true,"img":false}]}
{"op":"mcm","clk":"11540568454","pt":1719495988960,"mc":[{"id":"1.230180115","rc":[{"atb":[[1.93,2]],"id":41804643}],"con":true,"img":false}]}
{"op":"mcm","clk":"11540568490","pt":1719495989368,"mc":[{"id":"1.230180115","rc":[{"atb":[[2.22,0]],"id":63387150}],"con":true,"img":false}]}
{"op":"mcm","clk":"11540568498","pt":1719495989480,"mc":[{"id":"1.230180115","rc":[{"atb":[[1.92,0],[1.95,4.2]],"id":41804643},{"atb":[[1.02,2]],"id":63387150}],"con":true,"img":false}]}
{"op":"mcm","clk":"11540568585","pt":1719495990557,"mc":[{"id":"1.230180115","rc":[{"atb":[[1.93,0]],"id":41804643}],"con":true,"img":false}]}
{"op":"mcm","clk":"11540568595","pt":1719495990659,"mc":[{"id":"1.230180115","rc":[{"atb":[[1.96,2]],"id":41804643}],"con":true,"img":false}]}
{"op":"mcm","clk":"11540568632","pt":1719495991072,"mc":[{"id":"1.230180115","rc":[{"atb":[[1.02,0]],"id":63387150}],"con":true,"img":false}]}
{"op":"mcm","clk":"11540568644","pt":1719495991171,"mc":[{"id":"1.230180115","rc":[{"atb":[[2.22,2]],"id":63387150}],"con":true,"img":false}]}
{"op":"mcm","clk":"11540568746","pt":1719495992671,"mc":[{"id":"1.230180115","rc":[{"atl":[[2.66,0]],"id":39682601}],"con":true,"img":false}]}
{"op":"mcm","clk":"11540568797","pt":1719495993290,"mc":[{"id":"1.230180115","rc":[{"atb":[[2.22,0]],"id":63387150}],"con":true,"img":false}]}
{"op":"mcm","clk":"11540568806","pt":1719495993390,"mc":[{"id":"1.230180115","rc":[{"atb":[[1.02,2]],"id":63387150}],"con":true,"img":false}]}
{"op":"mcm","clk":"11540568815","pt":1719495993498,"mc":[{"id":"1.230180115","rc":[{"atb":[[1.99,10.66]],"id":61150133}],"con":true,"img":false}]}
{"op":"mcm","clk":"11540568822","pt":1719495993596,"mc":[{"id":"1.230180115","rc":[{"atb":[[2,0],[1.96,11.18]],"id":61150133}],"con":true,"img":false}]}
{"op":"mcm","clk":"11540568842","pt":1719495993809,"mc":[{"id":"1.230180115","rc":[{"atb":[[2,10.67],[1.96,0]],"id":61150133},{"atl":[[2.28,7.98]],"id":39682601}],"con":true,"img":false}]}
{"op":"mcm","clk":"11540568880","pt":1719495994171,"mc":[{"id":"1.230180115","rc":[{"atb":[[1.99,5.58]],"id":61150133}],"con":true,"img":false}]}
{"op":"mcm","clk":"11540568889","pt":1719495994273,"mc":[{"id":"1.230180115","rc":[{"atb":[[2,0],[1.96,16.26]],"id":61150133}],"con":true,"img":false}]}
{"op":"mcm","clk":"11540568901","pt":1719495994373,"mc":[{"id":"1.230180115","rc":[{"atb":[[2,5.59],[1.96,0]],"id":61150133}],"con":true,"img":false}]}
{"op":"mcm","clk":"11540568931","pt":1719495994688,"mc":[{"id":"1.230180115","rc":[{"atl":[[2.28,3.46]],"id":39682601}],"con":true,"img":false}]}
{"op":"mcm","clk":"11540568998","pt":1719495995462,"mc":[{"id":"1.230180115","rc":[{"atb":[[1.02,0]],"id":63387150}],"con":true,"img":false}]}
{"op":"mcm","clk":"11540569008","pt":1719495995570,"mc":[{"id":"1.230180115","rc":[{"atb":[[2.22,2]],"id":63387150}],"con":true,"img":false}]}
{"op":"mcm","clk":"11540569093","pt":1719495996597,"mc":[{"id":"1.230180115","rc":[{"atb":[[2.22,0]],"id":63387150}],"con":true,"img":false}]}
{"op":"mcm","clk":"11540569101","pt":1719495996702,"mc":[{"id":"1.230180115","rc":[{"atb":[[1.02,2]],"id":63387150}],"con":true,"img":false}]}
{"op":"mcm","clk":"11540569316","pt":1719495999287,"mc":[{"id":"1.230180115","rc":[{"atb":[[1.02,0]],"id":63387150}],"con":true,"img":false}]}
{"op":"mcm","clk":"11540569323","pt":1719495999385,"mc":[{"id":"1.230180115","rc":[{"atb":[[2.22,2]],"id":63387150}],"con":true,"img":false}]}
{"op":"mcm","clk":"11540569420","pt":1719496000575,"mc":[{"id":"1.230180115","rc":[{"atb":[[1.95,9.26]],"id":41804643}],"con":true,"img":false}]}
{"op":"mcm","clk":"11540569455","pt":1719496001089,"mc":[{"id":"1.230180115","rc":[{"atb":[[2.22,0]],"id":63387150}],"con":true,"img":false}]}
{"op":"mcm","clk":"11540569462","pt":1719496001192,"mc":[{"id":"1.230180115","rc":[{"atb":[[1.02,2]],"id":63387150}],"con":true,"img":false}]}
{"op":"mcm","clk":"11540569502","pt":1719496001708,"mc":[{"id":"1.230180115","rc":[{"atb":[[2.2,13.25]],"id":63387150}],"con":true,"img":false}]}
{"op":"mcm","clk":"11540569588","pt":1719496002584,"mc":[{"id":"1.230180115","rc":[{"atb":[[1.02,0]],"id":63387150}],"con":true,"img":false}]}
{"op":"mcm","clk":"11540569595","pt":1719496002687,"mc":[{"id":"1.230180115","rc":[{"atb":[[2.22,2],[2.2,9.26]],"id":63387150}],"con":true,"img":false}]}
{"op":"mcm","clk":"11540569691","pt":1719496004083,"mc":[{"id":"1.230180115","rc":[{"atb":[[2.22,0]],"id":63387150}],"con":true,"img":false}]}
{"op":"mcm","clk":"11540569702","pt":1719496004190,"mc":[{"id":"1.230180115","rc":[{"atb":[[1.02,2]],"id":63387150}],"con":true,"img":false}]}
{"op":"mcm","clk":"11540569839","pt":1719496005786,"mc":[{"id":"1.230180115","rc":[{"atb":[[1.02,0]],"id":63387150}],"con":true,"img":false}]}
{"op":"mcm","clk":"11540569851","pt":1719496005887,"mc":[{"id":"1.230180115","rc":[{"atb":[[2.22,2]],"id":63387150}],"con":true,"img":false}]}
{"op":"mcm","clk":"11540569963","pt":1719496007278,"mc":[{"id":"1.230180115","rc":[{"atb":[[1.29,0]],"id":39682601}],"con":true,"img":false}]}
{"op":"mcm","clk":"11540569980","pt":1719496007483,"mc":[{"id":"1.230180115","rc":[{"atb":[[1.24,0]],"id":39682601},{"atb":[[2.22,0]],"id":63387150}],"con":true,"img":false}]}
{"op":"mcm","clk":"11540569993","pt":1719496007587,"mc":[{"id":"1.230180115","rc":[{"atb":[[1.02,2]],"id":63387150}],"con":true,"img":false}]}
{"op":"mcm","clk":"11540570099","pt":1719496008673,"mc":[{"id":"1.230180115","rc":[{"atb":[[1.18,5.69]],"id":39682601},{"atb":[[1.02,0]],"id":63387150}],"con":true,"img":false}]}
{"op":"mcm","clk":"11540570107","pt":1719496008774,"mc":[{"id":"1.230180115","rc":[{"atb":[[2.22,2]],"id":63387150}],"con":true,"img":false}]}
{"op":"mcm","clk":"11540570261","pt":1719496010323,"mc":[{"id":"1.230180115","rc":[{"atb":[[2.22,0]],"id":63387150}],"con":true,"img":false}]}
{"op":"mcm","clk":"11540570271","pt":1719496010378,"mc":[{"id":"1.230180115","rc":[{"atb":[[1.02,2]],"id":63387150}],"con":true,"img":false}]}
{"op":"mcm","clk":"11540570304","pt":1719496010793,"mc":[{"id":"1.230180115","rc":[{"atb":[[1.99,10.66]],"id":61150133}],"con":true,"img":false}]}
{"op":"mcm","clk":"11540570325","pt":1719496010995,"mc":[{"id":"1.230180115","rc":[{"atb":[[2,0],[1.96,11.18]],"id":61150133}],"con":true,"img":false}]}
{"op":"mcm","clk":"11540570334","pt":1719496011095,"mc":[{"id":"1.230180115","rc":[{"atb":[[2,5.59],[1.96,0]],"id":61150133}],"con":true,"img":false}]}
{"op":"mcm","clk":"11540570345","pt":1719496011199,"mc":[{"id":"1.230180115","rc":[{"atl":[[2.26,8.01]],"id":39682601}],"con":true,"img":false}]}
{"op":"mcm","clk":"11540570381","pt":1719496011710,"mc":[{"id":"1.230180115","rc":[{"atb":[[1.99,5.58]],"id":61150133}],"con":true,"img":false}]}
{"op":"mcm","clk":"11540570391","pt":1719496011814,"mc":[{"id":"1.230180115","rc":[{"atb":[[2,0],[1.96,11.18]],"id":61150133}],"con":true,"img":false}]}
{"op":"mcm","clk":"11540570397","pt":1719496011921,"mc":[{"id":"1.230180115","rc":[{"atb":[[2,5.59],[1.96,0]],"id":61150133}],"con":true,"img":false}]}
{"op":"mcm","clk":"11540570403","pt":1719496012024,"mc":[{"id":"1.230180115","rc":[{"atb":[[1.02,0]],"id":63387150}],"con":true,"img":false}]}
{"op":"mcm","clk":"11540570414","pt":1719496012074,"mc":[{"id":"1.230180115","rc":[{"atb":[[2.22,2]],"id":63387150}],"con":true,"img":false}]}
{"op":"mcm","clk":"11540570517","pt":1719496013414,"mc":[{"id":"1.230180115","rc":[{"atb":[[2.22,0]],"id":63387150}],"con":true,"img":false}]}
{"op":"mcm","clk":"11540570525","pt":1719496013518,"mc":[{"id":"1.230180115","rc":[{"atb":[[1.02,2]],"id":63387150}],"con":true,"img":false}]}
{"op":"mcm","clk":"11540570609","pt":1719496014703,"mc":[{"id":"1.230180115","rc":[{"atb":[[1.02,0]],"id":63387150}],"con":true,"img":false}]}
{"op":"mcm","clk":"11540570615","pt":1719496014806,"mc":[{"id":"1.230180115","rc":[{"atb":[[2.22,2]],"id":63387150}],"con":true,"img":false}]}
{"op":"mcm","clk":"11540570697","pt":1719496015788,"mc":[{"id":"1.230180115","rc":[{"atb":[[2.22,0]],"id":63387150}],"con":true,"img":false}]}
{"op":"mcm","clk":"11540570708","pt":1719496015900,"mc":[{"id":"1.230180115","rc":[{"atb":[[1.02,2]],"id":63387150}],"con":true,"img":false}]}
{"op":"mcm","clk":"11540570801","pt":1719496017127,"mc":[{"id":"1.230180115","rc":[{"atb":[[1.02,0]],"id":63387150}],"con":true,"img":false}]}
{"op":"mcm","clk":"11540570808","pt":1719496017231,"mc":[{"id":"1.230180115","rc":[{"atb":[[2.22,2]],"id":63387150}],"con":true,"img":false}]}
{"op":"mcm","clk":"11540570909","pt":1719496018520,"mc":[{"id":"1.230180115","rc":[{"atb":[[2.22,0]],"id":63387150}],"con":true,"img":false}]}
{"op":"mcm","clk":"11540570917","pt":1719496018623,"mc":[{"id":"1.230180115","rc":[{"atb":[[1.02,2]],"id":63387150}],"con":true,"img":false}]}
{"op":"mcm","clk":"11540570936","pt":1719496018831,"mc":[{"id":"1.230180115","rc":[{"atb":[[2.2,13.25]],"id":63387150}],"con":true,"img":false}]}
{"op":"mcm","clk":"11540570987","pt":1719496019309,"mc":[{"id":"1.230180115","rc":[{"atb":[[2.2,9.26]],"id":63387150}],"con":true,"img":false}]}
{"op":"mcm","clk":"11540571025","pt":1719496019726,"mc":[{"id":"1.230180115","rc":[{"atb":[[1.02,0]],"id":63387150}],"con":true,"img":false}]}
{"op":"mcm","clk":"11540571031","pt":1719496019832,"mc":[{"id":"1.230180115","rc":[{"atb":[[2.22,2]],"id":63387150}],"con":true,"img":false}]}
{"op":"mcm","clk":"11540571099","pt":1719496020725,"mc":[{"id":"1.230180115","rc":[{"atl":[[8.2,0]],"id":63387150}],"con":true,"img":false}]}
{"op":"mcm","clk":"11540571111","pt":1719496020935,"mc":[{"id":"1.230180115","rc":[{"atb":[[1.95,0]],"id":61150133}],"con":true,"img":false}]}
{"op":"mcm","clk":"11540571130","pt":1719496021139,"mc":[{"id":"1.230180115","rc":[{"atb":[[2.22,0]],"id":63387150}],"con":true,"img":false}]}
{"op":"mcm","clk":"11540571138","pt":1719496021242,"mc":[{"id":"1.230180115","rc":[{"atb":[[1.02,2]],"id":63387150}],"con":true,"img":false}]}
{"op":"mcm","clk":"11540571153","pt":1719496021399,"mc":[{"id":"1.230180115","rc":[{"atl":[[8.2,3.27]],"id":63387150}],"con":true,"img":false}]}
{"op":"mcm","clk":"11540571210","pt":1719496022026,"mc":[{"id":"1.230180115","rc":[{"spn":3.98,"spf":"NaN","id":41804643},{"atb":[[1.92,4.59]],"id":61150133},{"atl":[[5.3,3.25],[5.4,4.5]],"id":61150133},{"spn":2.0,"spf":1.0,"id":61150133},{"spn":3.48,"spf":"NaN","id":44213406},{"atl":[[2.3,0],[2.28,4.46]],"id":39682601},{"spn":4.7,"spf":"NaN","id":63387150}],"con":true,"img":false}]}
{"op":"mcm","clk":"11540571243","pt":1719496022331,"mc":[{"id":"1.230180115","rc":[{"atl":[[5.3,2.25],[5.2,1.84]],"id":61150133}],"con":true,"img":false}]}
{"op":"mcm","clk":"11540571252","pt":1719496022435,"mc":[{"id":"1.230180115","rc":[{"atl":[[5.1,2.44]],"id":61150133}],"con":true,"img":false}]}
{"op":"mcm","clk":"11540571268","pt":1719496022594,"mc":[{"id":"1.230180115","rc":[{"atb":[[1.97,1]],"id":41804643},{"atb":[[2.02,1.35]],"id":61150133},{"atb":[[1.98,1]],"id":44213406},{"atb":[[2.22,1.2]],"id":63387150}],"con":true,"img":false}]}
