{"op":"mcm","clk":"11547086390","pt":1719432856314,"mc":[{"id":"1.230178177","marketDefinition":{"bspMarket":false,"turnInPlayEnabled":false,"persistenceEnabled":false,"marketBaseRate":5.0,"eventId":"33376048","eventTypeId":"4339","numberOfWinners":1,"bettingType":"ODDS","marketType":"FORECAST","marketTime":"2024-06-27T16:56:00.000Z","suspendTime":"2024-06-27T16:56:00.000Z","bspReconciled":false,"complete":true,"inPlay":false,"crossMatching":false,"runnersVoidable":false,"numberOfActiveRunners":20,"betDelay":0,"status":"OPEN","runners":[{"status":"ACTIVE","sortPriority":1,"id":52385882,"name":"1 - 2"},{"status":"ACTIVE","sortPriority":2,"id":52385883,"name":"1 - 3"},{"status":"ACTIVE","sortPriority":3,"id":52385884,"name":"1 - 4"},{"status":"ACTIVE","sortPriority":4,"id":52385885,"name":"1 - 5"},{"status":"ACTIVE","sortPriority":5,"id":52385889,"name":"2 - 1"},{"status":"ACTIVE","sortPriority":6,"id":52385890,"name":"2 - 3"},{"status":"ACTIVE","sortPriority":7,"id":52385891,"name":"2 - 4"},{"status":"ACTIVE","sortPriority":8,"id":52385892,"name":"2 - 5"},{"status":"ACTIVE","sortPriority":9,"id":52385896,"name":"3 - 1"},{"status":"ACTIVE","sortPriority":10,"id":52385897,"name":"3 - 2"},{"status":"ACTIVE","sortPriority":11,"id":52385898,"name":"3 - 4"},{"status":"ACTIVE","sortPriority":12,"id":52385899,"name":"3 - 5"},{"status":"ACTIVE","sortPriority":13,"id":52385903,"name":"4 - 1"},{"status":"ACTIVE","sortPriority":14,"id":52385904,"name":"4 - 2"},{"status":"ACTIVE","sortPriority":15,"id":52385905,"name":"4 - 3"},{"status":"ACTIVE","sortPriority":16,"id":52385906,"name":"4 - 5"},{"status":"ACTIVE","sortPriority":17,"id":52385910,"name":"5 - 1"},{"status":"ACTIVE","sortPriority":18,"id":52385911,"name":"5 - 2"},{"status":"ACTIVE","sortPriority":19,"id":52385912,"name":"5 - 3"},{"status":"ACTIVE","sortPriority":20,"id":52385913,"name":"5 - 4"}],"regulators":["MR_INT"],"venue":"Perry Barr","countryCode":"GB","discountAllowed":false,"timezone":"Europe/London","openDate":"2024-06-27T13:29:00.000Z","version":5994794130,"name":"Forecast","eventName":"Perry Barr (F/C) 27th Jun"},"rc":[],"con":true,"img":false}]}
{"op":"mcm","clk":"11547086551","pt":1719432858319,"mc":[{"id":"1.230178177","marketDefinition":{"bspMarket":false,"turnInPlayEnabled":false,"persistenceEnabled":false,"marketBaseRate":5.0,"eventId":"33376048","eventTypeId":"4339","numberOfWinners":1,"bettingType":"ODDS","marketType":"FORECAST","marketTime":"2024-06-27T16:56:00.000Z","suspendTime":"2024-06-27T16:56:00.000Z","bspReconciled":false,"complete":true,"inPlay":false,"crossMatching":false,"runnersVoidable":false,"numberOfActiveRunners":20,"betDelay":0,"status":"OPEN","runners":[{"status":"ACTIVE","sortPriority":1,"id":52385882,"name":"1 - 2"},{"status":"ACTIVE","sortPriority":2,"id":52385883,"name":"1 - 3"},{"status":"ACTIVE","sortPriority":3,"id":52385884,"name":"1 - 4"},{"status":"ACTIVE","sortPriority":4,"id":52385885,"name":"1 - 5"},{"status":"ACTIVE","sortPriority":5,"id":52385889,"name":"2 - 1"},{"status":"ACTIVE","sortPriority":6,"id":52385890,"name":"2 - 3"},{"status":"ACTIVE","sortPriority":7,"id":52385891,"name":"2 - 4"},{"status":"ACTIVE","sortPriority":8,"id":52385892,"name":"2 - 5"},{"status":"ACTIVE","sortPriority":9,"id":52385896,"name":"3 - 1"},{"status":"ACTIVE","sortPriority":10,"id":52385897,"name":"3 - 2"},{"status":"ACTIVE","sortPriority":11,"id":52385898,"name":"3 - 4"},{"status":"ACTIVE","sortPriority":12,"id":52385899,"name":"3 - 5"},{"status":"ACTIVE","sortPriority":13,"id":52385903,"name":"4 - 1"},{"status":"ACTIVE","sortPriority":14,"id":52385904,"name":"4 - 2"},{"status":"ACTIVE","sortPriority":15,"id":52385905,"name":"4 - 3"},{"status":"ACTIVE","sortPriority":16,"id":52385906,"name":"4 - 5"},{"status":"ACTIVE","sortPriority":17,"id":52385910,"name":"5 - 1"},{"status":"ACTIVE","sortPriority":18,"id":52385911,"name":"5 - 2"},{"status":"ACTIVE","sortPriority":19,"id":52385912,"name":"5 - 3"},{"status":"ACTIVE","sortPriority":20,"id":52385913,"name":"5 - 4"}],"regulators":["MR_INT"],"venue":"Perry Barr","countryCode":"GB","discountAllowed":true,"timezone":"Europe/London","openDate":"2024-06-27T13:29:00.000Z","version":5994794130,"name":"Forecast","eventName":"Perry Barr (F/C) 27th Jun"},"rc":[],"con":true,"img":false}]}
{"op":"mcm","clk":"11547146204","pt":1719434092565,"mc":[{"id":"1.230178177","rc":[{"atb":[[1.1,200]],"id":52385910},{"atb":[[1.1,200]],"id":52385911},{"atb":[[1.1,200]],"id":52385912},{"atb":[[1.1,200]],"id":52385913},{"atb":[[1.1,200]],"id":52385906},{"atb":[[1.1,200]],"id":52385889},{"atb":[[1.1,200]],"id":52385882},{"atb":[[1.1,200]],"id":52385883},{"atb":[[1.1,200]],"id":52385884},{"atb":[[1.1,200]],"id":52385885},{"atb":[[1.1,200]],"id":52385896},{"atb":[[1.1,200]],"id":52385897},{"atb":[[1.1,200]],"id":52385890},{"atb":[[1.1,200]],"id":52385891},{"atb":[[1.1,200]],"id":52385892},{"atb":[[1.1,200]],"id":52385903},{"atb":[[1.1,200]],"id":52385904},{"atb":[[1.1,200]],"id":52385905},{"atb":[[1.1,200]],"id":52385898},{"atb":[[1.1,200]],"id":52385899}],"con":true,"img":false}]}
{"op":"mcm","clk":"11547210673","pt":1719435445704,"mc":[{"id":"1.230178177","rc":[{"atb":[[1.01,32.96]],"id":52385910},{"atl":[[990,0.84]],"id":52385910},{"atb":[[1.01,32.96]],"id":52385911},{"atl":[[990,0.84]],"id":52385911},{"atb":[[1.03,10.99]],"id":52385912},{"atl":[[1000,0.84]],"id":52385912},{"atb":[[1.03,10.99]],"id":52385913},{"atl":[[1000,0.84]],"id":52385913},{"atb":[[1.02,16.48]],"id":52385906},{"atl":[[990,0.84]],"id":52385906},{"atb":[[1.02,16.48]],"id":52385889},{"atl":[[1000,0.84]],"id":52385889},{"atb":[[1.02,16.48]],"id":52385882},{"atl":[[1000,0.84]],"id":52385882},{"atb":[[1.02,16.48]],"id":52385883},{"atl":[[1000,0.84]],"id":52385883},{"atb":[[1.03,10.99]],"id":52385884},{"atl":[[990,0.84]],"id":52385884},{"atb":[[1.03,10.99]],"id":52385885},{"atl":[[1000,0.84]],"id":52385885},{"atb":[[1.01,32.96]],"id":52385896},{"atl":[[990,0.84]],"id":52385896},{"atb":[[1.03,10.99]],"id":52385897},{"atl":[[1000,0.84]],"id":52385897},{"atb":[[1.01,32.96]],"id":52385890},{"atl":[[990,0.84]],"id":52385890},{"atb":[[1.01,32.96]],"id":52385891},{"atl":[[990,0.84]],"id":52385891},{"atb":[[1.01,32.96]],"id":52385892},{"atl":[[990,0.84]],"id":52385892},{"atb":[[1.02,16.48]],"id":52385903},{"atl":[[1000,0.84]],"id":52385903},{"atb":[[1.02,16.48]],"id":52385904},{"atl":[[990,0.84]],"id":52385904},{"atb":[[1.01,32.96]],"id":52385905},{"atl":[[1000,0.84]],"id":52385905},{"atb":[[1.01,32.96]],"id":52385898},{"atl":[[990,0.84]],"id":52385898},{"atb":[[1.01,32.96]],"id":52385899},{"atl":[[990,0.84]],"id":52385899}],"con":true,"img":false}]}
{"op":"mcm","clk":"11547344036","pt":1719439051276,"mc":[{"id":"1.230178177","rc":[{"atb":[[1.01,32.96]],"id":52385910},{"atl":[[990,0.17]],"id":52385910},{"atb":[[1.01,32.96]],"id":52385911},{"atl":[[990,0.17]],"id":52385911},{"atb":[[1.03,10.99]],"id":52385912},{"atl":[[1000,0.17]],"id":52385912},{"atb":[[1.03,10.99]],"id":52385913},{"atl":[[1000,0.17]],"id":52385913},{"atb":[[1.02,16.48]],"id":52385906},{"atl":[[990,0.17]],"id":52385906},{"atb":[[1.02,16.48]],"id":52385889},{"atl":[[1000,0.17]],"id":52385889},{"atb":[[1.02,16.48]],"id":52385882},{"atl":[[1000,0.17]],"id":52385882},{"atb":[[1.02,16.48]],"id":52385883},{"atl":[[1000,0.17]],"id":52385883},{"atb":[[1.03,10.99]],"id":52385884},{"atl":[[990,0.17]],"id":52385884},{"atb":[[1.03,10.99]],"id":52385885},{"atl":[[1000,0.17]],"id":52385885},{"atb":[[1.01,32.96]],"id":52385896},{"atl":[[990,0.17]],"id":52385896},{"atb":[[1.03,10.99]],"id":52385897},{"atl":[[1000,0.17]],"id":52385897},{"atb":[[1.01,32.96]],"id":52385890},{"atl":[[990,0.17]],"id":52385890},{"atb":[[1.01,32.96]],"id":52385891},{"atl":[[990,0.17]],"id":52385891},{"atb":[[1.01,32.96]],"id":52385892},{"atl":[[990,0.17]],"id":52385892},{"atb":[[1.02,16.48]],"id":52385903},{"atl":[[1000,0.17]],"id":52385903},{"atb":[[1.02,16.48]],"id":52385904},{"atl":[[990,0.17]],"id":52385904},{"atb":[[1.01,32.96]],"id":52385905},{"atl":[[1000,0.17]],"id":52385905},{"atb":[[1.01,32.96]],"id":52385898},{"atl":[[990,0.17]],"id":52385898},{"atb":[[1.01,32.96]],"id":52385899},{"atl":[[990,0.17]],"id":52385899}],"con":true,"img":false}]}
{"op":"mcm","clk":"11547371009","pt":1719439682592,"mc":[{"id":"1.230178177","marketDefinition":{"bspMarket":false,"turnInPlayEnabled":false,"persistenceEnabled":false,"marketBaseRate":5.0,"eventId":"33376048","eventTypeId":"4339","numberOfWinners":1,"bettingType":"ODDS","marketType":"FORECAST","marketTime":"2024-06-27T16:56:00.000Z","suspendTime":"2024-06-27T16:56:00.000Z","bspReconciled":false,"complete":true,"inPlay":false,"crossMatching":false,"runnersVoidable":false,"numberOfActiveRunners":20,"betDelay":0,"status":"OPEN","runners":[{"status":"ACTIVE","sortPriority":1,"id":52385882,"name":"1 - 2"},{"status":"ACTIVE","sortPriority":2,"id":52385883,"name":"1 - 3"},{"status":"ACTIVE","sortPriority":3,"id":52385884,"name":"1 - 4"},{"status":"ACTIVE","sortPriority":4,"id":52385885,"name":"1 - 5"},{"status":"ACTIVE","sortPriority":5,"id":52385889,"name":"2 - 1"},{"status":"ACTIVE","sortPriority":6,"id":52385890,"name":"2 - 3"},{"status":"ACTIVE","sortPriority":7,"id":52385891,"name":"2 - 4"},{"status":"ACTIVE","sortPriority":8,"id":52385892,"name":"2 - 5"},{"status":"ACTIVE","sortPriority":9,"id":52385896,"name":"3 - 1"},{"status":"ACTIVE","sortPriority":10,"id":52385897,"name":"3 - 2"},{"status":"ACTIVE","sortPriority":11,"id":52385898,"name":"3 - 4"},{"status":"ACTIVE","sortPriority":12,"id":52385899,"name":"3 - 5"},{"status":"ACTIVE","sortPriority":13,"id":52385903,"name":"4 - 1"},{"status":"ACTIVE","sortPriority":14,"id":52385904,"name":"4 - 2"},{"status":"ACTIVE","sortPriority":15,"id":52385905,"name":"4 - 3"},{"status":"ACTIVE","sortPriority":16,"id":52385906,"name":"4 - 5"},{"status":"ACTIVE","sortPriority":17,"id":52385910,"name":"5 - 1"},{"status":"ACTIVE","sortPriority":18,"id":52385911,"name":"5 - 2"},{"status":"ACTIVE","sortPriority":19,"id":52385912,"name":"5 - 3"},{"status":"ACTIVE","sortPriority":20,"id":52385913,"name":"5 - 4"}],"regulators":["MR_INT"],"venue":"Perry Barr","countryCode":"GB","discountAllowed":true,"timezone":"Europe/London","openDate":"2024-06-27T13:29:00.000Z","version":5994794130,"name":"Forecast","eventName":"Perry Barr (F/C) 27th Jun"},"rc":[{"atb":[[1.01,32.96],[1.1,200]],"id":52385910},{"atl":[[990,0.17]],"id":52385910},{"atb":[[1.01,32.96],[1.1,200]],"id":52385911},{"atl":[[990,0.17]],"id":52385911},{"atb":[[1.03,10.98],[1.1,200]],"id":52385912},{"atl":[[1000,0.17]],"id":52385912},{"atb":[[1.03,10.98],[1.1,200]],"id":52385913},{"atl":[[1000,0.17]],"id":52385913},{"atb":[[1.02,16.48],[1.1,200]],"id":52385906},{"atl":[[990,0.17]],"id":52385906},{"atb":[[1.02,16.48],[1.1,200]],"id":52385889},{"atl":[[1000,0.17]],"id":52385889},{"atb":[[1.02,16.48],[1.1,200]],"id":52385882},{"atl":[[1000,0.17]],"id":52385882},{"atb":[[1.02,16.48],[1.1,200]],"id":52385883},{"atl":[[1000,0.17]],"id":52385883},{"atb":[[1.03,10.98],[1.1,200]],"id":52385884},{"atl":[[990,0.17]],"id":52385884},{"atb":[[1.03,10.98],[1.1,200]],"id":52385885},{"atl":[[1000,0.17]],"id":52385885},{"atb":[[1.01,32.96],[1.1,200]],"id":52385896},{"atl":[[990,0.17]],"id":52385896},{"atb":[[1.03,10.98],[1.1,200]],"id":52385897},{"atl":[[1000,0.17]],"id":52385897},{"atb":[[1.01,32.96],[1.1,200]],"id":52385890},{"atl":[[990,0.17]],"id":52385890},{"atb":[[1.01,32.96],[1.1,200]],"id":52385891},{"atl":[[990,0.17]],"id":52385891},{"atb":[[1.01,32.96],[1.1,200]],"id":52385892},{"atl":[[990,0.17]],"id":52385892},{"atb":[[1.02,16.48],[1.1,200]],"id":52385903},{"atl":[[1000,0.17]],"id":52385903},{"atb":[[1.02,16.48],[1.1,200]],"id":52385904},{"atl":[[990,0.17]],"id":52385904},{"atb":[[1.01,32.96],[1.1,200]],"id":52385905},{"atl":[[1000,0.17]],"id":52385905},{"atb":[[1.01,32.96],[1.1,200]],"id":52385898},{"atl":[[990,0.17]],"id":52385898},{"atb":[[1.01,32.96],[1.1,200]],"id":52385899},{"atl":[[990,0.17]],"id":52385899}],"con":true,"img":true}]}
{"op":"mcm","clk":"11547659677","pt":1719445082618,"mc":[{"id":"1.230178177","marketDefinition":{"bspMarket":false,"turnInPlayEnabled":false,"persistenceEnabled":false,"marketBaseRate":5.0,"eventId":"33376048","eventTypeId":"4339","numberOfWinners":1,"bettingType":"ODDS","marketType":"FORECAST","marketTime":"2024-06-27T16:56:00.000Z","suspendTime":"2024-06-27T16:56:00.000Z","bspReconciled":false,"complete":true,"inPlay":false,"crossMatching":false,"runnersVoidable":false,"numberOfActiveRunners":20,"betDelay":0,"status":"OPEN","runners":[{"status":"ACTIVE","sortPriority":1,"id":52385882,"name":"1 - 2"},{"status":"ACTIVE","sortPriority":2,"id":52385883,"name":"1 - 3"},{"status":"ACTIVE","sortPriority":3,"id":52385884,"name":"1 - 4"},{"status":"ACTIVE","sortPriority":4,"id":52385885,"name":"1 - 5"},{"status":"ACTIVE","sortPriority":5,"id":52385889,"name":"2 - 1"},{"status":"ACTIVE","sortPriority":6,"id":52385890,"name":"2 - 3"},{"status":"ACTIVE","sortPriority":7,"id":52385891,"name":"2 - 4"},{"status":"ACTIVE","sortPriority":8,"id":52385892,"name":"2 - 5"},{"status":"ACTIVE","sortPriority":9,"id":52385896,"name":"3 - 1"},{"status":"ACTIVE","sortPriority":10,"id":52385897,"name":"3 - 2"},{"status":"ACTIVE","sortPriority":11,"id":52385898,"name":"3 - 4"},{"status":"ACTIVE","sortPriority":12,"id":52385899,"name":"3 - 5"},{"status":"ACTIVE","sortPriority":13,"id":52385903,"name":"4 - 1"},{"status":"ACTIVE","sortPriority":14,"id":52385904,"name":"4 - 2"},{"status":"ACTIVE","sortPriority":15,"id":52385905,"name":"4 - 3"},{"status":"ACTIVE","sortPriority":16,"id":52385906,"name":"4 - 5"},{"status":"ACTIVE","sortPriority":17,"id":52385910,"name":"5 - 1"},{"status":"ACTIVE","sortPriority":18,"id":52385911,"name":"5 - 2"},{"status":"ACTIVE","sortPriority":19,"id":52385912,"name":"5 - 3"},{"status":"ACTIVE","sortPriority":20,"id":52385913,"name":"5 - 4"}],"regulators":["MR_INT"],"venue":"Perry Barr","countryCode":"GB","discountAllowed":true,"timezone":"Europe/London","openDate":"2024-06-27T13:29:00.000Z","version":5994794130,"name":"Forecast","eventName":"Perry Barr (F/C) 27th Jun"},"rc":[{"atb":[[1.01,32.96],[1.1,200]],"id":52385910},{"atl":[[990,0.17]],"id":52385910},{"atb":[[1.01,32.96],[1.1,200]],"id":52385911},{"atl":[[990,0.17]],"id":52385911},{"atb":[[1.03,10.99],[1.1,200]],"id":52385912},{"atl":[[1000,0.17]],"id":52385912},{"atb":[[1.03,10.99],[1.1,200]],"id":52385913},{"atl":[[1000,0.17]],"id":52385913},{"atb":[[1.02,16.48],[1.1,200]],"id":52385906},{"atl":[[990,0.17]],"id":52385906},{"atb":[[1.02,16.48],[1.1,200]],"id":52385889},{"atl":[[1000,0.17]],"id":52385889},{"atb":[[1.02,16.48],[1.1,200]],"id":52385882},{"atl":[[1000,0.17]],"id":52385882},{"atb":[[1.02,16.48],[1.1,200]],"id":52385883},{"atl":[[1000,0.17]],"id":52385883},{"atb":[[1.03,10.99],[1.1,200]],"id":52385884},{"atl":[[990,0.17]],"id":52385884},{"atb":[[1.03,10.99],[1.1,200]],"id":52385885},{"atl":[[1000,0.17]],"id":52385885},{"atb":[[1.01,32.96],[1.1,200]],"id":52385896},{"atl":[[990,0.17]],"id":52385896},{"atb":[[1.03,10.99],[1.1,200]],"id":52385897},{"atl":[[1000,0.17]],"id":52385897},{"atb":[[1.01,32.96],[1.1,200]],"id":52385890},{"atl":[[990,0.17]],"id":52385890},{"atb":[[1.01,32.96],[1.1,200]],"id":52385891},{"atl":[[990,0.17]],"id":52385891},{"atb":[[1.01,32.96],[1.1,200]],"id":52385892},{"atl":[[990,0.17]],"id":52385892},{"atb":[[1.02,16.48],[1.1,200]],"id":52385903},{"atl":[[1000,0.17]],"id":52385903},{"atb":[[1.02,16.48],[1.1,200]],"id":52385904},{"atl":[[990,0.17]],"id":52385904},{"atb":[[1.01,32.96],[1.1,200]],"id":52385905},{"atl":[[1000,0.17]],"id":52385905},{"atb":[[1.01,32.96],[1.1,200]],"id":52385898},{"atl":[[990,0.17]],"id":52385898},{"atb":[[1.01,32.96],[1.1,200]],"id":52385899},{"atl":[[990,0.17]],"id":52385899}],"con":true,"img":true}]}
{"op":"mcm","clk":"11548031721","pt":1719450482634,"mc":[{"id":"1.230178177","marketDefinition":{"bspMarket":false,"turnInPlayEnabled":false,"persistenceEnabled":false,"marketBaseRate":5.0,"eventId":"33376048","eventTypeId":"4339","numberOfWinners":1,"bettingType":"ODDS","marketType":"FORECAST","marketTime":"2024-06-27T16:56:00.000Z","suspendTime":"2024-06-27T16:56:00.000Z","bspReconciled":false,"complete":true,"inPlay":false,"crossMatching":false,"runnersVoidable":false,"numberOfActiveRunners":20,"betDelay":0,"status":"OPEN","runners":[{"status":"ACTIVE","sortPriority":1,"id":52385882,"name":"1 - 2"},{"status":"ACTIVE","sortPriority":2,"id":52385883,"name":"1 - 3"},{"status":"ACTIVE","sortPriority":3,"id":52385884,"name":"1 - 4"},{"status":"ACTIVE","sortPriority":4,"id":52385885,"name":"1 - 5"},{"status":"ACTIVE","sortPriority":5,"id":52385889,"name":"2 - 1"},{"status":"ACTIVE","sortPriority":6,"id":52385890,"name":"2 - 3"},{"status":"ACTIVE","sortPriority":7,"id":52385891,"name":"2 - 4"},{"status":"ACTIVE","sortPriority":8,"id":52385892,"name":"2 - 5"},{"status":"ACTIVE","sortPriority":9,"id":52385896,"name":"3 - 1"},{"status":"ACTIVE","sortPriority":10,"id":52385897,"name":"3 - 2"},{"status":"ACTIVE","sortPriority":11,"id":52385898,"name":"3 - 4"},{"status":"ACTIVE","sortPriority":12,"id":52385899,"name":"3 - 5"},{"status":"ACTIVE","sortPriority":13,"id":52385903,"name":"4 - 1"},{"status":"ACTIVE","sortPriority":14,"id":52385904,"name":"4 - 2"},{"status":"ACTIVE","sortPriority":15,"id":52385905,"name":"4 - 3"},{"status":"ACTIVE","sortPriority":16,"id":52385906,"name":"4 - 5"},{"status":"ACTIVE","sortPriority":17,"id":52385910,"name":"5 - 1"},{"status":"ACTIVE","sortPriority":18,"id":52385911,"name":"5 - 2"},{"status":"ACTIVE","sortPriority":19,"id":52385912,"name":"5 - 3"},{"status":"ACTIVE","sortPriority":20,"id":52385913,"name":"5 - 4"}],"regulators":["MR_INT"],"venue":"Perry Barr","countryCode":"GB","discountAllowed":true,"timezone":"Europe/London","openDate":"2024-06-27T13:29:00.000Z","version":5994794130,"name":"Forecast","eventName":"Perry Barr (F/C) 27th Jun"},"rc":[{"atb":[[1.01,32.97],[1.1,200]],"id":52385910},{"atl":[[990,0.17]],"id":52385910},{"atb":[[1.01,32.97],[1.1,200]],"id":52385911},{"atl":[[990,0.17]],"id":52385911},{"atb":[[1.03,10.99],[1.1,200]],"id":52385912},{"atl":[[1000,0.17]],"id":52385912},{"atb":[[1.03,10.99],[1.1,200]],"id":52385913},{"atl":[[1000,0.17]],"id":52385913},{"atb":[[1.02,16.48],[1.1,200]],"id":52385906},{"atl":[[990,0.17]],"id":52385906},{"atb":[[1.02,16.48],[1.1,200]],"id":52385889},{"atl":[[1000,0.17]],"id":52385889},{"atb":[[1.02,16.48],[1.1,200]],"id":52385882},{"atl":[[1000,0.17]],"id":52385882},{"atb":[[1.02,16.48],[1.1,200]],"id":52385883},{"atl":[[1000,0.17]],"id":52385883},{"atb":[[1.03,10.99],[1.1,200]],"id":52385884},{"atl":[[990,0.17]],"id":52385884},{"atb":[[1.03,10.99],[1.1,200]],"id":52385885},{"atl":[[1000,0.17]],"id":52385885},{"atb":[[1.01,32.97],[1.1,200]],"id":52385896},{"atl":[[990,0.17]],"id":52385896},{"atb":[[1.03,10.99],[1.1,200]],"id":52385897},{"atl":[[1000,0.17]],"id":52385897},{"atb":[[1.01,32.97],[1.1,200]],"id":52385890},{"atl":[[990,0.17]],"id":52385890},{"atb":[[1.01,32.97],[1.1,200]],"id":52385891},{"atl":[[990,0.17]],"id":52385891},{"atb":[[1.01,32.97],[1.1,200]],"id":52385892},{"atl":[[990,0.17]],"id":52385892},{"atb":[[1.02,16.48],[1.1,200]],"id":52385903},{"atl":[[1000,0.17]],"id":52385903},{"atb":[[1.02,16.48],[1.1,200]],"id":52385904},{"atl":[[990,0.17]],"id":52385904},{"atb":[[1.01,32.97],[1.1,200]],"id":52385905},{"atl":[[1000,0.17]],"id":52385905},{"atb":[[1.01,32.97],[1.1,200]],"id":52385898},{"atl":[[990,0.17]],"id":52385898},{"atb":[[1.01,32.97],[1.1,200]],"id":52385899},{"atl":[[990,0.17]],"id":52385899}],"con":true,"img":true}]}
{"op":"mcm","clk":"11548270786","pt":1719455882653,"mc":[{"id":"1.230178177","marketDefinition":{"bspMarket":false,"turnInPlayEnabled":false,"persistenceEnabled":false,"marketBaseRate":5.0,"eventId":"33376048","eventTypeId":"4339","numberOfWinners":1,"bettingType":"ODDS","marketType":"FORECAST","marketTime":"2024-06-27T16:56:00.000Z","suspendTime":"2024-06-27T16:56:00.000Z","bspReconciled":false,"complete":true,"inPlay":false,"crossMatching":false,"runnersVoidable":false,"numberOfActiveRunners":20,"betDelay":0,"status":"OPEN","runners":[{"status":"ACTIVE","sortPriority":1,"id":52385882,"name":"1 - 2"},{"status":"ACTIVE","sortPriority":2,"id":52385883,"name":"1 - 3"},{"status":"ACTIVE","sortPriority":3,"id":52385884,"name":"1 - 4"},{"status":"ACTIVE","sortPriority":4,"id":52385885,"name":"1 - 5"},{"status":"ACTIVE","sortPriority":5,"id":52385889,"name":"2 - 1"},{"status":"ACTIVE","sortPriority":6,"id":52385890,"name":"2 - 3"},{"status":"ACTIVE","sortPriority":7,"id":52385891,"name":"2 - 4"},{"status":"ACTIVE","sortPriority":8,"id":52385892,"name":"2 - 5"},{"status":"ACTIVE","sortPriority":9,"id":52385896,"name":"3 - 1"},{"status":"ACTIVE","sortPriority":10,"id":52385897,"name":"3 - 2"},{"status":"ACTIVE","sortPriority":11,"id":52385898,"name":"3 - 4"},{"status":"ACTIVE","sortPriority":12,"id":52385899,"name":"3 - 5"},{"status":"ACTIVE","sortPriority":13,"id":52385903,"name":"4 - 1"},{"status":"ACTIVE","sortPriority":14,"id":52385904,"name":"4 - 2"},{"status":"ACTIVE","sortPriority":15,"id":52385905,"name":"4 - 3"},{"status":"ACTIVE","sortPriority":16,"id":52385906,"name":"4 - 5"},{"status":"ACTIVE","sortPriority":17,"id":52385910,"name":"5 - 1"},{"status":"ACTIVE","sortPriority":18,"id":52385911,"name":"5 - 2"},{"status":"ACTIVE","sortPriority":19,"id":52385912,"name":"5 - 3"},{"status":"ACTIVE","sortPriority":20,"id":52385913,"name":"5 - 4"}],"regulators":["MR_INT"],"venue":"Perry Barr","countryCode":"GB","discountAllowed":true,"timezone":"Europe/London","openDate":"2024-06-27T13:29:00.000Z","version":5994794130,"name":"Forecast","eventName":"Perry Barr (F/C) 27th Jun"},"rc":[{"atb":[[1.01,32.97],[1.1,200]],"id":52385910},{"atl":[[990,0.17]],"id":52385910},{"atb":[[1.01,32.97],[1.1,200]],"id":52385911},{"atl":[[990,0.17]],"id":52385911},{"atb":[[1.03,10.99],[1.1,200]],"id":52385912},{"atl":[[1000,0.17]],"id":52385912},{"atb":[[1.03,10.99],[1.1,200]],"id":52385913},{"atl":[[1000,0.17]],"id":52385913},{"atb":[[1.02,16.48],[1.1,200]],"id":52385906},{"atl":[[990,0.17]],"id":52385906},{"atb":[[1.02,16.48],[1.1,200]],"id":52385889},{"atl":[[1000,0.17]],"id":52385889},{"atb":[[1.02,16.48],[1.1,200]],"id":52385882},{"atl":[[1000,0.17]],"id":52385882},{"atb":[[1.02,16.48],[1.1,200]],"id":52385883},{"atl":[[1000,0.17]],"id":52385883},{"atb":[[1.03,10.99],[1.1,200]],"id":52385884},{"atl":[[990,0.17]],"id":52385884},{"atb":[[1.03,10.99],[1.1,200]],"id":52385885},{"atl":[[1000,0.17]],"id":52385885},{"atb":[[1.01,32.97],[1.1,200]],"id":52385896},{"atl":[[990,0.17]],"id":52385896},{"atb":[[1.03,10.99],[1.1,200]],"id":52385897},{"atl":[[1000,0.17]],"id":52385897},{"atb":[[1.01,32.97],[1.1,200]],"id":52385890},{"atl":[[990,0.17]],"id":52385890},{"atb":[[1.01,32.97],[1.1,200]],"id":52385891},{"atl":[[990,0.17]],"id":52385891},{"atb":[[1.01,32.97],[1.1,200]],"id":52385892},{"atl":[[990,0.17]],"id":52385892},{"atb":[[1.02,16.48],[1.1,200]],"id":52385903},{"atl":[[1000,0.17]],"id":52385903},{"atb":[[1.02,16.48],[1.1,200]],"id":52385904},{"atl":[[990,0.17]],"id":52385904},{"atb":[[1.01,32.97],[1.1,200]],"id":52385905},{"atl":[[1000,0.17]],"id":52385905},{"atb":[[1.01,32.97],[1.1,200]],"id":52385898},{"atl":[[990,0.17]],"id":52385898},{"atb":[[1.01,32.97],[1.1,200]],"id":52385899},{"atl":[[990,0.17]],"id":52385899}],"con":true,"img":true}]}
{"op":"mcm","clk":"11548426208","pt":1719461282620,"mc":[{"id":"1.230178177","marketDefinition":{"bspMarket":false,"turnInPlayEnabled":false,"persistenceEnabled":false,"marketBaseRate":5.0,"eventId":"33376048","eventTypeId":"4339","numberOfWinners":1,"bettingType":"ODDS","marketType":"FORECAST","marketTime":"2024-06-27T16:56:00.000Z","suspendTime":"2024-06-27T16:56:00.000Z","bspReconciled":false,"complete":true,"inPlay":false,"crossMatching":false,"runnersVoidable":false,"numberOfActiveRunners":20,"betDelay":0,"status":"OPEN","runners":[{"status":"ACTIVE","sortPriority":1,"id":52385882,"name":"1 - 2"},{"status":"ACTIVE","sortPriority":2,"id":52385883,"name":"1 - 3"},{"status":"ACTIVE","sortPriority":3,"id":52385884,"name":"1 - 4"},{"status":"ACTIVE","sortPriority":4,"id":52385885,"name":"1 - 5"},{"status":"ACTIVE","sortPriority":5,"id":52385889,"name":"2 - 1"},{"status":"ACTIVE","sortPriority":6,"id":52385890,"name":"2 - 3"},{"status":"ACTIVE","sortPriority":7,"id":52385891,"name":"2 - 4"},{"status":"ACTIVE","sortPriority":8,"id":52385892,"name":"2 - 5"},{"status":"ACTIVE","sortPriority":9,"id":52385896,"name":"3 - 1"},{"status":"ACTIVE","sortPriority":10,"id":52385897,"name":"3 - 2"},{"status":"ACTIVE","sortPriority":11,"id":52385898,"name":"3 - 4"},{"status":"ACTIVE","sortPriority":12,"id":52385899,"name":"3 - 5"},{"status":"ACTIVE","sortPriority":13,"id":52385903,"name":"4 - 1"},{"status":"ACTIVE","sortPriority":14,"id":52385904,"name":"4 - 2"},{"status":"ACTIVE","sortPriority":15,"id":52385905,"name":"4 - 3"},{"status":"ACTIVE","sortPriority":16,"id":52385906,"name":"4 - 5"},{"status":"ACTIVE","sortPriority":17,"id":52385910,"name":"5 - 1"},{"status":"ACTIVE","sortPriority":18,"id":52385911,"name":"5 - 2"},{"status":"ACTIVE","sortPriority":19,"id":52385912,"name":"5 - 3"},{"status":"ACTIVE","sortPriority":20,"id":52385913,"name":"5 - 4"}],"regulators":["MR_INT"],"venue":"Perry Barr","countryCode":"GB","discountAllowed":true,"timezone":"Europe/London","openDate":"2024-06-27T13:29:00.000Z","version":5994794130,"name":"Forecast","eventName":"Perry Barr (F/C) 27th Jun"},"rc":[{"atb":[[1.01,32.97],[1.1,200]],"id":52385910},{"atl":[[990,0.17]],"id":52385910},{"atb":[[1.01,32.97],[1.1,200]],"id":52385911},{"atl":[[990,0.17]],"id":52385911},{"atb":[[1.03,10.99],[1.1,200]],"id":52385912},{"atl":[[1000,0.17]],"id":52385912},{"atb":[[1.03,10.99],[1.1,200]],"id":52385913},{"atl":[[1000,0.17]],"id":52385913},{"atb":[[1.02,16.48],[1.1,200]],"id":52385906},{"atl":[[990,0.17]],"id":52385906},{"atb":[[1.02,16.48],[1.1,200]],"id":52385889},{"atl":[[1000,0.17]],"id":52385889},{"atb":[[1.02,16.48],[1.1,200]],"id":52385882},{"atl":[[1000,0.17]],"id":52385882},{"atb":[[1.02,16.48],[1.1,200]],"id":52385883},{"atl":[[1000,0.17]],"id":52385883},{"atb":[[1.03,10.99],[1.1,200]],"id":52385884},{"atl":[[990,0.17]],"id":52385884},{"atb":[[1.03,10.99],[1.1,200]],"id":52385885},{"atl":[[1000,0.17]],"id":52385885},{"atb":[[1.01,32.97],[1.1,200]],"id":52385896},{"atl":[[990,0.17]],"id":52385896},{"atb":[[1.03,10.99],[1.1,200]],"id":52385897},{"atl":[[1000,0.17]],"id":52385897},{"atb":[[1.01,32.97],[1.1,200]],"id":52385890},{"atl":[[990,0.17]],"id":52385890},{"atb":[[1.01,32.97],[1.1,200]],"id":52385891},{"atl":[[990,0.17]],"id":52385891},{"atb":[[1.01,32.97],[1.1,200]],"id":52385892},{"atl":[[990,0.17]],"id":52385892},{"atb":[[1.02,16.48],[1.1,200]],"id":52385903},{"atl":[[1000,0.17]],"id":52385903},{"atb":[[1.02,16.48],[1.1,200]],"id":52385904},{"atl":[[990,0.17]],"id":52385904},{"atb":[[1.01,32.97],[1.1,200]],"id":52385905},{"atl":[[1000,0.17]],"id":52385905},{"atb":[[1.01,32.97],[1.1,200]],"id":52385898},{"atl":[[990,0.17]],"id":52385898},{"atb":[[1.01,32.97],[1.1,200]],"id":52385899},{"atl":[[990,0.17]],"id":52385899}],"con":true,"img":true}]}
{"op":"mcm","clk":"11548535722","pt":1719466682820,"mc":[{"id":"1.230178177","marketDefinition":{"bspMarket":false,"turnInPlayEnabled":false,"persistenceEnabled":false,"marketBaseRate":5.0,"eventId":"33376048","eventTypeId":"4339","numberOfWinners":1,"bettingType":"ODDS","marketType":"FORECAST","marketTime":"2024-06-27T16:56:00.000Z","suspendTime":"2024-06-27T16:56:00.000Z","bspReconciled":false,"complete":true,"inPlay":false,"crossMatching":false,"runnersVoidable":false,"numberOfActiveRunners":20,"betDelay":0,"status":"OPEN","runners":[{"status":"ACTIVE","sortPriority":1,"id":52385882,"name":"1 - 2"},{"status":"ACTIVE","sortPriority":2,"id":52385883,"name":"1 - 3"},{"status":"ACTIVE","sortPriority":3,"id":52385884,"name":"1 - 4"},{"status":"ACTIVE","sortPriority":4,"id":52385885,"name":"1 - 5"},{"status":"ACTIVE","sortPriority":5,"id":52385889,"name":"2 - 1"},{"status":"ACTIVE","sortPriority":6,"id":52385890,"name":"2 - 3"},{"status":"ACTIVE","sortPriority":7,"id":52385891,"name":"2 - 4"},{"status":"ACTIVE","sortPriority":8,"id":52385892,"name":"2 - 5"},{"status":"ACTIVE","sortPriority":9,"id":52385896,"name":"3 - 1"},{"status":"ACTIVE","sortPriority":10,"id":52385897,"name":"3 - 2"},{"status":"ACTIVE","sortPriority":11,"id":52385898,"name":"3 - 4"},{"status":"ACTIVE","sortPriority":12,"id":52385899,"name":"3 - 5"},{"status":"ACTIVE","sortPriority":13,"id":52385903,"name":"4 - 1"},{"status":"ACTIVE","sortPriority":14,"id":52385904,"name":"4 - 2"},{"status":"ACTIVE","sortPriority":15,"id":52385905,"name":"4 - 3"},{"status":"ACTIVE","sortPriority":16,"id":52385906,"name":"4 - 5"},{"status":"ACTIVE","sortPriority":17,"id":52385910,"name":"5 - 1"},{"status":"ACTIVE","sortPriority":18,"id":52385911,"name":"5 - 2"},{"status":"ACTIVE","sortPriority":19,"id":52385912,"name":"5 - 3"},{"status":"ACTIVE","sortPriority":20,"id":52385913,"name":"5 - 4"}],"regulators":["MR_INT"],"venue":"Perry Barr","countryCode":"GB","discountAllowed":true,"timezone":"Europe/London","openDate":"2024-06-27T13:29:00.000Z","version":5994794130,"name":"Forecast","eventName":"Perry Barr (F/C) 27th Jun"},"rc":[{"atb":[[1.01,32.97],[1.1,200]],"id":52385910},{"atl":[[990,0.17]],"id":52385910},{"atb":[[1.01,32.97],[1.1,200]],"id":52385911},{"atl":[[990,0.17]],"id":52385911},{"atb":[[1.03,10.99],[1.1,200]],"id":52385912},{"atl":[[1000,0.17]],"id":52385912},{"atb":[[1.03,10.99],[1.1,200]],"id":52385913},{"atl":[[1000,0.17]],"id":52385913},{"atb":[[1.02,16.48],[1.1,200]],"id":52385906},{"atl":[[990,0.17]],"id":52385906},{"atb":[[1.02,16.48],[1.1,200]],"id":52385889},{"atl":[[1000,0.17]],"id":52385889},{"atb":[[1.02,16.48],[1.1,200]],"id":52385882},{"atl":[[1000,0.17]],"id":52385882},{"atb":[[1.02,16.48],[1.1,200]],"id":52385883},{"atl":[[1000,0.17]],"id":52385883},{"atb":[[1.03,10.99],[1.1,200]],"id":52385884},{"atl":[[990,0.17]],"id":52385884},{"atb":[[1.03,10.99],[1.1,200]],"id":52385885},{"atl":[[1000,0.17]],"id":52385885},{"atb":[[1.01,32.97],[1.1,200]],"id":52385896},{"atl":[[990,0.17]],"id":52385896},{"atb":[[1.03,10.99],[1.1,200]],"id":52385897},{"atl":[[1000,0.17]],"id":52385897},{"atb":[[1.01,32.97],[1.1,200]],"id":52385890},{"atl":[[990,0.17]],"id":52385890},{"atb":[[1.01,32.97],[1.1,200]],"id":52385891},{"atl":[[990,0.17]],"id":52385891},{"atb":[[1.01,32.97],[1.1,200]],"id":52385892},{"atl":[[990,0.17]],"id":52385892},{"atb":[[1.02,16.48],[1.1,200]],"id":52385903},{"atl":[[1000,0.17]],"id":52385903},{"atb":[[1.02,16.48],[1.1,200]],"id":52385904},{"atl":[[990,0.17]],"id":52385904},{"atb":[[1.01,32.97],[1.1,200]],"id":52385905},{"atl":[[1000,0.17]],"id":52385905},{"atb":[[1.01,32.97],[1.1,200]],"id":52385898},{"atl":[[990,0.17]],"id":52385898},{"atb":[[1.01,32.97],[1.1,200]],"id":52385899},{"atl":[[990,0.17]],"id":52385899}],"con":true,"img":true}]}
{"op":"mcm","clk":"11548656203","pt":1719472082590,"mc":[{"id":"1.230178177","marketDefinition":{"bspMarket":false,"turnInPlayEnabled":false,"persistenceEnabled":false,"marketBaseRate":5.0,"eventId":"33376048","eventTypeId":"4339","numberOfWinners":1,"bettingType":"ODDS","marketType":"FORECAST","marketTime":"2024-06-27T16:56:00.000Z","suspendTime":"2024-06-27T16:56:00.000Z","bspReconciled":false,"complete":true,"inPlay":false,"crossMatching":false,"runnersVoidable":false,"numberOfActiveRunners":20,"betDelay":0,"status":"OPEN","runners":[{"status":"ACTIVE","sortPriority":1,"id":52385882,"name":"1 - 2"},{"status":"ACTIVE","sortPriority":2,"id":52385883,"name":"1 - 3"},{"status":"ACTIVE","sortPriority":3,"id":52385884,"name":"1 - 4"},{"status":"ACTIVE","sortPriority":4,"id":52385885,"name":"1 - 5"},{"status":"ACTIVE","sortPriority":5,"id":52385889,"name":"2 - 1"},{"status":"ACTIVE","sortPriority":6,"id":52385890,"name":"2 - 3"},{"status":"ACTIVE","sortPriority":7,"id":52385891,"name":"2 - 4"},{"status":"ACTIVE","sortPriority":8,"id":52385892,"name":"2 - 5"},{"status":"ACTIVE","sortPriority":9,"id":52385896,"name":"3 - 1"},{"status":"ACTIVE","sortPriority":10,"id":52385897,"name":"3 - 2"},{"status":"ACTIVE","sortPriority":11,"id":52385898,"name":"3 - 4"},{"status":"ACTIVE","sortPriority":12,"id":52385899,"name":"3 - 5"},{"status":"ACTIVE","sortPriority":13,"id":52385903,"name":"4 - 1"},{"status":"ACTIVE","sortPriority":14,"id":52385904,"name":"4 - 2"},{"status":"ACTIVE","sortPriority":15,"id":52385905,"name":"4 - 3"},{"status":"ACTIVE","sortPriority":16,"id":52385906,"name":"4 - 5"},{"status":"ACTIVE","sortPriority":17,"id":52385910,"name":"5 - 1"},{"status":"ACTIVE","sortPriority":18,"id":52385911,"name":"5 - 2"},{"status":"ACTIVE","sortPriority":19,"id":52385912,"name":"5 - 3"},{"status":"ACTIVE","sortPriority":20,"id":52385913,"name":"5 - 4"}],"regulators":["MR_INT"],"venue":"Perry Barr","countryCode":"GB","discountAllowed":true,"timezone":"Europe/London","openDate":"2024-06-27T13:29:00.000Z","version":5994794130,"name":"Forecast","eventName":"Perry Barr (F/C) 27th Jun"},"rc":[{"atb":[[1.01,32.94],[1.1,200]],"id":52385910},{"atl":[[990,0.17]],"id":52385910},{"atb":[[1.01,32.94],[1.1,200]],"id":52385911},{"atl":[[990,0.17]],"id":52385911},{"atb":[[1.03,10.98],[1.1,200]],"id":52385912},{"atl":[[1000,0.17]],"id":52385912},{"atb":[[1.03,10.98],[1.1,200]],"id":52385913},{"atl":[[1000,0.17]],"id":52385913},{"atb":[[1.02,16.47],[1.1,200]],"id":52385906},{"atl":[[990,0.17]],"id":52385906},{"atb":[[1.02,16.47],[1.1,200]],"id":52385889},{"atl":[[1000,0.17]],"id":52385889},{"atb":[[1.02,16.47],[1.1,200]],"id":52385882},{"atl":[[1000,0.17]],"id":52385882},{"atb":[[1.02,16.47],[1.1,200]],"id":52385883},{"atl":[[1000,0.17]],"id":52385883},{"atb":[[1.03,10.98],[1.1,200]],"id":52385884},{"atl":[[990,0.17]],"id":52385884},{"atb":[[1.03,10.98],[1.1,200]],"id":52385885},{"atl":[[1000,0.17]],"id":52385885},{"atb":[[1.01,32.94],[1.1,200]],"id":52385896},{"atl":[[990,0.17]],"id":52385896},{"atb":[[1.03,10.98],[1.1,200]],"id":52385897},{"atl":[[1000,0.17]],"id":52385897},{"atb":[[1.01,32.94],[1.1,200]],"id":52385890},{"atl":[[990,0.17]],"id":52385890},{"atb":[[1.01,32.94],[1.1,200]],"id":52385891},{"atl":[[990,0.17]],"id":52385891},{"atb":[[1.01,32.94],[1.1,200]],"id":52385892},{"atl":[[990,0.17]],"id":52385892},{"atb":[[1.02,16.47],[1.1,200]],"id":52385903},{"atl":[[1000,0.17]],"id":52385903},{"atb":[[1.02,16.47],[1.1,200]],"id":52385904},{"atl":[[990,0.17]],"id":52385904},{"atb":[[1.01,32.94],[1.1,200]],"id":52385905},{"atl":[[1000,0.17]],"id":52385905},{"atb":[[1.01,32.94],[1.1,200]],"id":52385898},{"atl":[[990,0.17]],"id":52385898},{"atb":[[1.01,32.94],[1.1,200]],"id":52385899},{"atl":[[990,0.17]],"id":52385899}],"con":true,"img":true}]}
{"op":"mcm","clk":"11548861949","pt":1719477482591,"mc":[{"id":"1.230178177","marketDefinition":{"bspMarket":false,"turnInPlayEnabled":false,"persistenceEnabled":false,"marketBaseRate":5.0,"eventId":"33376048","eventTypeId":"4339","numberOfWinners":1,"bettingType":"ODDS","marketType":"FORECAST","marketTime":"2024-06-27T16:56:00.000Z","suspendTime":"2024-06-27T16:56:00.000Z","bspReconciled":false,"complete":true,"inPlay":false,"crossMatching":false,"runnersVoidable":false,"numberOfActiveRunners":20,"betDelay":0,"status":"OPEN","runners":[{"status":"ACTIVE","sortPriority":1,"id":52385882,"name":"1 - 2"},{"status":"ACTIVE","sortPriority":2,"id":52385883,"name":"1 - 3"},{"status":"ACTIVE","sortPriority":3,"id":52385884,"name":"1 - 4"},{"status":"ACTIVE","sortPriority":4,"id":52385885,"name":"1 - 5"},{"status":"ACTIVE","sortPriority":5,"id":52385889,"name":"2 - 1"},{"status":"ACTIVE","sortPriority":6,"id":52385890,"name":"2 - 3"},{"status":"ACTIVE","sortPriority":7,"id":52385891,"name":"2 - 4"},{"status":"ACTIVE","sortPriority":8,"id":52385892,"name":"2 - 5"},{"status":"ACTIVE","sortPriority":9,"id":52385896,"name":"3 - 1"},{"status":"ACTIVE","sortPriority":10,"id":52385897,"name":"3 - 2"},{"status":"ACTIVE","sortPriority":11,"id":52385898,"name":"3 - 4"},{"status":"ACTIVE","sortPriority":12,"id":52385899,"name":"3 - 5"},{"status":"ACTIVE","sortPriority":13,"id":52385903,"name":"4 - 1"},{"status":"ACTIVE","sortPriority":14,"id":52385904,"name":"4 - 2"},{"status":"ACTIVE","sortPriority":15,"id":52385905,"name":"4 - 3"},{"status":"ACTIVE","sortPriority":16,"id":52385906,"name":"4 - 5"},{"status":"ACTIVE","sortPriority":17,"id":52385910,"name":"5 - 1"},{"status":"ACTIVE","sortPriority":18,"id":52385911,"name":"5 - 2"},{"status":"ACTIVE","sortPriority":19,"id":52385912,"name":"5 - 3"},{"status":"ACTIVE","sortPriority":20,"id":52385913,"name":"5 - 4"}],"regulators":["MR_INT"],"venue":"Perry Barr","countryCode":"GB","discountAllowed":true,"timezone":"Europe/London","openDate":"2024-06-27T13:29:00.000Z","version":5994794130,"name":"Forecast","eventName":"Perry Barr (F/C) 27th Jun"},"rc":[{"atb":[[1.01,32.96],[1.1,200]],"id":52385910},{"atl":[[990,0.17]],"id":52385910},{"atb":[[1.01,32.96],[1.1,200]],"id":52385911},{"atl":[[990,0.17]],"id":52385911},{"atb":[[1.03,10.99],[1.1,200]],"id":52385912},{"atl":[[1000,0.17]],"id":52385912},{"atb":[[1.03,10.99],[1.1,200]],"id":52385913},{"atl":[[1000,0.17]],"id":52385913},{"atb":[[1.02,16.48],[1.1,200]],"id":52385906},{"atl":[[990,0.17]],"id":52385906},{"atb":[[1.02,16.48],[1.1,200]],"id":52385889},{"atl":[[1000,0.17]],"id":52385889},{"atb":[[1.02,16.48],[1.1,200]],"id":52385882},{"atl":[[1000,0.17]],"id":52385882},{"atb":[[1.02,16.48],[1.1,200]],"id":52385883},{"atl":[[1000,0.17]],"id":52385883},{"atb":[[1.03,10.99],[1.1,200]],"id":52385884},{"atl":[[990,0.17]],"id":52385884},{"atb":[[1.03,10.99],[1.1,200]],"id":52385885},{"atl":[[1000,0.17]],"id":52385885},{"atb":[[1.01,32.96],[1.1,200]],"id":52385896},{"atl":[[990,0.17]],"id":52385896},{"atb":[[1.03,10.99],[1.1,200]],"id":52385897},{"atl":[[1000,0.17]],"id":52385897},{"atb":[[1.01,32.96],[1.1,200]],"id":52385890},{"atl":[[990,0.17]],"id":52385890},{"atb":[[1.01,32.96],[1.1,200]],"id":52385891},{"atl":[[990,0.17]],"id":52385891},{"atb":[[1.01,32.96],[1.1,200]],"id":52385892},{"atl":[[990,0.17]],"id":52385892},{"atb":[[1.02,16.48],[1.1,200]],"id":52385903},{"atl":[[1000,0.17]],"id":52385903},{"atb":[[1.02,16.48],[1.1,200]],"id":52385904},{"atl":[[990,0.17]],"id":52385904},{"atb":[[1.01,32.96],[1.1,200]],"id":52385905},{"atl":[[1000,0.17]],"id":52385905},{"atb":[[1.01,32.96],[1.1,200]],"id":52385898},{"atl":[[990,0.17]],"id":52385898},{"atb":[[1.01,32.96],[1.1,200]],"id":52385899},{"atl":[[990,0.17]],"id":52385899}],"con":true,"img":true}]}
{"op":"mcm","clk":"11549140213","pt":1719482882591,"mc":[{"id":"1.230178177","marketDefinition":{"bspMarket":false,"turnInPlayEnabled":false,"persistenceEnabled":false,"marketBaseRate":5.0,"eventId":"33376048","eventTypeId":"4339","numberOfWinners":1,"bettingType":"ODDS","marketType":"FORECAST","marketTime":"2024-06-27T16:56:00.000Z","suspendTime":"2024-06-27T16:56:00.000Z","bspReconciled":false,"complete":true,"inPlay":false,"crossMatching":false,"runnersVoidable":false,"numberOfActiveRunners":20,"betDelay":0,"status":"OPEN","runners":[{"status":"ACTIVE","sortPriority":1,"id":52385882,"name":"1 - 2"},{"status":"ACTIVE","sortPriority":2,"id":52385883,"name":"1 - 3"},{"status":"ACTIVE","sortPriority":3,"id":52385884,"name":"1 - 4"},{"status":"ACTIVE","sortPriority":4,"id":52385885,"name":"1 - 5"},{"status":"ACTIVE","sortPriority":5,"id":52385889,"name":"2 - 1"},{"status":"ACTIVE","sortPriority":6,"id":52385890,"name":"2 - 3"},{"status":"ACTIVE","sortPriority":7,"id":52385891,"name":"2 - 4"},{"status":"ACTIVE","sortPriority":8,"id":52385892,"name":"2 - 5"},{"status":"ACTIVE","sortPriority":9,"id":52385896,"name":"3 - 1"},{"status":"ACTIVE","sortPriority":10,"id":52385897,"name":"3 - 2"},{"status":"ACTIVE","sortPriority":11,"id":52385898,"name":"3 - 4"},{"status":"ACTIVE","sortPriority":12,"id":52385899,"name":"3 - 5"},{"status":"ACTIVE","sortPriority":13,"id":52385903,"name":"4 - 1"},{"status":"ACTIVE","sortPriority":14,"id":52385904,"name":"4 - 2"},{"status":"ACTIVE","sortPriority":15,"id":52385905,"name":"4 - 3"},{"status":"ACTIVE","sortPriority":16,"id":52385906,"name":"4 - 5"},{"status":"ACTIVE","sortPriority":17,"id":52385910,"name":"5 - 1"},{"status":"ACTIVE","sortPriority":18,"id":52385911,"name":"5 - 2"},{"status":"ACTIVE","sortPriority":19,"id":52385912,"name":"5 - 3"},{"status":"ACTIVE","sortPriority":20,"id":52385913,"name":"5 - 4"}],"regulators":["MR_INT"],"venue":"Perry Barr","countryCode":"GB","discountAllowed":true,"timezone":"Europe/London","openDate":"2024-06-27T13:29:00.000Z","version":5994794130,"name":"Forecast","eventName":"Perry Barr (F/C) 27th Jun"},"rc":[{"atb":[[1.01,32.95],[1.1,200]],"id":52385910},{"atl":[[990,0.17]],"id":52385910},{"atb":[[1.01,32.95],[1.1,200]],"id":52385911},{"atl":[[990,0.17]],"id":52385911},{"atb":[[1.03,10.98],[1.1,200]],"id":52385912},{"atl":[[1000,0.17]],"id":52385912},{"atb":[[1.03,10.98],[1.1,200]],"id":52385913},{"atl":[[1000,0.17]],"id":52385913},{"atb":[[1.02,16.47],[1.1,200]],"id":52385906},{"atl":[[990,0.17]],"id":52385906},{"atb":[[1.02,16.47],[1.1,200]],"id":52385889},{"atl":[[1000,0.17]],"id":52385889},{"atb":[[1.02,16.47],[1.1,200]],"id":52385882},{"atl":[[1000,0.17]],"id":52385882},{"atb":[[1.02,16.47],[1.1,200]],"id":52385883},{"atl":[[1000,0.17]],"id":52385883},{"atb":[[1.03,10.98],[1.1,200]],"id":52385884},{"atl":[[990,0.17]],"id":52385884},{"atb":[[1.03,10.98],[1.1,200]],"id":52385885},{"atl":[[1000,0.17]],"id":52385885},{"atb":[[1.01,32.95],[1.1,200]],"id":52385896},{"atl":[[990,0.17]],"id":52385896},{"atb":[[1.03,10.98],[1.1,200]],"id":52385897},{"atl":[[1000,0.17]],"id":52385897},{"atb":[[1.01,32.95],[1.1,200]],"id":52385890},{"atl":[[990,0.17]],"id":52385890},{"atb":[[1.01,32.95],[1.1,200]],"id":52385891},{"atl":[[990,0.17]],"id":52385891},{"atb":[[1.01,32.95],[1.1,200]],"id":52385892},{"atl":[[990,0.17]],"id":52385892},{"atb":[[1.02,16.47],[1.1,200]],"id":52385903},{"atl":[[1000,0.17]],"id":52385903},{"atb":[[1.02,16.47],[1.1,200]],"id":52385904},{"atl":[[990,0.17]],"id":52385904},{"atb":[[1.01,32.95],[1.1,200]],"id":52385905},{"atl":[[1000,0.17]],"id":52385905},{"atb":[[1.01,32.95],[1.1,200]],"id":52385898},{"atl":[[990,0.17]],"id":52385898},{"atb":[[1.01,32.95],[1.1,200]],"id":52385899},{"atl":[[990,0.17]],"id":52385899}],"con":true,"img":true}]}
{"op":"mcm","clk":"11549606644","pt":1719488282608,"mc":[{"id":"1.230178177","marketDefinition":{"bspMarket":false,"turnInPlayEnabled":false,"persistenceEnabled":false,"marketBaseRate":5.0,"eventId":"33376048","eventTypeId":"4339","numberOfWinners":1,"bettingType":"ODDS","marketType":"FORECAST","marketTime":"2024-06-27T16:56:00.000Z","suspendTime":"2024-06-27T16:56:00.000Z","bspReconciled":false,"complete":true,"inPlay":false,"crossMatching":false,"runnersVoidable":false,"numberOfActiveRunners":20,"betDelay":0,"status":"OPEN","runners":[{"status":"ACTIVE","sortPriority":1,"id":52385882,"name":"1 - 2"},{"status":"ACTIVE","sortPriority":2,"id":52385883,"name":"1 - 3"},{"status":"ACTIVE","sortPriority":3,"id":52385884,"name":"1 - 4"},{"status":"ACTIVE","sortPriority":4,"id":52385885,"name":"1 - 5"},{"status":"ACTIVE","sortPriority":5,"id":52385889,"name":"2 - 1"},{"status":"ACTIVE","sortPriority":6,"id":52385890,"name":"2 - 3"},{"status":"ACTIVE","sortPriority":7,"id":52385891,"name":"2 - 4"},{"status":"ACTIVE","sortPriority":8,"id":52385892,"name":"2 - 5"},{"status":"ACTIVE","sortPriority":9,"id":52385896,"name":"3 - 1"},{"status":"ACTIVE","sortPriority":10,"id":52385897,"name":"3 - 2"},{"status":"ACTIVE","sortPriority":11,"id":52385898,"name":"3 - 4"},{"status":"ACTIVE","sortPriority":12,"id":52385899,"name":"3 - 5"},{"status":"ACTIVE","sortPriority":13,"id":52385903,"name":"4 - 1"},{"status":"ACTIVE","sortPriority":14,"id":52385904,"name":"4 - 2"},{"status":"ACTIVE","sortPriority":15,"id":52385905,"name":"4 - 3"},{"status":"ACTIVE","sortPriority":16,"id":52385906,"name":"4 - 5"},{"status":"ACTIVE","sortPriority":17,"id":52385910,"name":"5 - 1"},{"status":"ACTIVE","sortPriority":18,"id":52385911,"name":"5 - 2"},{"status":"ACTIVE","sortPriority":19,"id":52385912,"name":"5 - 3"},{"status":"ACTIVE","sortPriority":20,"id":52385913,"name":"5 - 4"}],"regulators":["MR_INT"],"venue":"Perry Barr","countryCode":"GB","discountAllowed":true,"timezone":"Europe/London","openDate":"2024-06-27T13:29:00.000Z","version":5994794130,"name":"Forecast","eventName":"Perry Barr (F/C) 27th Jun"},"rc":[{"atb":[[1.01,32.95],[1.1,200]],"id":52385910},{"atl":[[990,0.17]],"id":52385910},{"atb":[[1.01,32.95],[1.1,200]],"id":52385911},{"atl":[[990,0.17]],"id":52385911},{"atb":[[1.03,10.98],[1.1,200]],"id":52385912},{"atl":[[1000,0.17]],"id":52385912},{"atb":[[1.03,10.98],[1.1,200]],"id":52385913},{"atl":[[1000,0.17]],"id":52385913},{"atb":[[1.02,16.47],[1.1,200]],"id":52385906},{"atl":[[990,0.17]],"id":52385906},{"atb":[[1.02,16.47],[1.1,200]],"id":52385889},{"atl":[[1000,0.17]],"id":52385889},{"atb":[[1.02,16.47],[1.1,200]],"id":52385882},{"atl":[[1000,0.17]],"id":52385882},{"atb":[[1.02,16.47],[1.1,200]],"id":52385883},{"atl":[[1000,0.17]],"id":52385883},{"atb":[[1.03,10.98],[1.1,200]],"id":52385884},{"atl":[[990,0.17]],"id":52385884},{"atb":[[1.03,10.98],[1.1,200]],"id":52385885},{"atl":[[1000,0.17]],"id":52385885},{"atb":[[1.01,32.95],[1.1,200]],"id":52385896},{"atl":[[990,0.17]],"id":52385896},{"atb":[[1.03,10.98],[1.1,200]],"id":52385897},{"atl":[[1000,0.17]],"id":52385897},{"atb":[[1.01,32.95],[1.1,200]],"id":52385890},{"atl":[[990,0.17]],"id":52385890},{"atb":[[1.01,32.95],[1.1,200]],"id":52385891},{"atl":[[990,0.17]],"id":52385891},{"atb":[[1.01,32.95],[1.1,200]],"id":52385892},{"atl":[[990,0.17]],"id":52385892},{"atb":[[1.02,16.47],[1.1,200]],"id":52385903},{"atl":[[1000,0.17]],"id":52385903},{"atb":[[1.02,16.47],[1.1,200]],"id":52385904},{"atl":[[990,0.17]],"id":52385904},{"atb":[[1.01,32.95],[1.1,200]],"id":52385905},{"atl":[[1000,0.17]],"id":52385905},{"atb":[[1.01,32.95],[1.1,200]],"id":52385898},{"atl":[[990,0.17]],"id":52385898},{"atb":[[1.01,32.95],[1.1,200]],"id":52385899},{"atl":[[990,0.17]],"id":52385899}],"con":true,"img":true}]}
{"op":"mcm","clk":"11550017460","pt":1719493682608,"mc":[{"id":"1.230178177","marketDefinition":{"bspMarket":false,"turnInPlayEnabled":false,"persistenceEnabled":false,"marketBaseRate":5.0,"eventId":"33376048","eventTypeId":"4339","numberOfWinners":1,"bettingType":"ODDS","marketType":"FORECAST","marketTime":"2024-06-27T16:56:00.000Z","suspendTime":"2024-06-27T16:56:00.000Z","bspReconciled":false,"complete":true,"inPlay":false,"crossMatching":false,"runnersVoidable":false,"numberOfActiveRunners":20,"betDelay":0,"status":"OPEN","runners":[{"status":"ACTIVE","sortPriority":1,"id":52385882,"name":"1 - 2"},{"status":"ACTIVE","sortPriority":2,"id":52385883,"name":"1 - 3"},{"status":"ACTIVE","sortPriority":3,"id":52385884,"name":"1 - 4"},{"status":"ACTIVE","sortPriority":4,"id":52385885,"name":"1 - 5"},{"status":"ACTIVE","sortPriority":5,"id":52385889,"name":"2 - 1"},{"status":"ACTIVE","sortPriority":6,"id":52385890,"name":"2 - 3"},{"status":"ACTIVE","sortPriority":7,"id":52385891,"name":"2 - 4"},{"status":"ACTIVE","sortPriority":8,"id":52385892,"name":"2 - 5"},{"status":"ACTIVE","sortPriority":9,"id":52385896,"name":"3 - 1"},{"status":"ACTIVE","sortPriority":10,"id":52385897,"name":"3 - 2"},{"status":"ACTIVE","sortPriority":11,"id":52385898,"name":"3 - 4"},{"status":"ACTIVE","sortPriority":12,"id":52385899,"name":"3 - 5"},{"status":"ACTIVE","sortPriority":13,"id":52385903,"name":"4 - 1"},{"status":"ACTIVE","sortPriority":14,"id":52385904,"name":"4 - 2"},{"status":"ACTIVE","sortPriority":15,"id":52385905,"name":"4 - 3"},{"status":"ACTIVE","sortPriority":16,"id":52385906,"name":"4 - 5"},{"status":"ACTIVE","sortPriority":17,"id":52385910,"name":"5 - 1"},{"status":"ACTIVE","sortPriority":18,"id":52385911,"name":"5 - 2"},{"status":"ACTIVE","sortPriority":19,"id":52385912,"name":"5 - 3"},{"status":"ACTIVE","sortPriority":20,"id":52385913,"name":"5 - 4"}],"regulators":["MR_INT"],"venue":"Perry Barr","countryCode":"GB","discountAllowed":true,"timezone":"Europe/London","openDate":"2024-06-27T13:29:00.000Z","version":5994794130,"name":"Forecast","eventName":"Perry Barr (F/C) 27th Jun"},"rc":[{"atb":[[1.01,32.99],[1.1,200]],"id":52385910},{"atl":[[990,0.17]],"id":52385910},{"atb":[[1.01,32.99],[1.1,200]],"id":52385911},{"atl":[[990,0.17]],"id":52385911},{"atb":[[1.03,11],[1.1,200]],"id":52385912},{"atl":[[1000,0.17]],"id":52385912},{"atb":[[1.03,11],[1.1,200]],"id":52385913},{"atl":[[1000,0.17]],"id":52385913},{"atb":[[1.02,16.49],[1.1,200]],"id":52385906},{"atl":[[990,0.17]],"id":52385906},{"atb":[[1.02,16.49],[1.1,200]],"id":52385889},{"atl":[[1000,0.17]],"id":52385889},{"atb":[[1.02,16.49],[1.1,200]],"id":52385882},{"atl":[[1000,0.17]],"id":52385882},{"atb":[[1.02,16.49],[1.1,200]],"id":52385883},{"atl":[[1000,0.17]],"id":52385883},{"atb":[[1.03,11],[1.1,200]],"id":52385884},{"atl":[[990,0.17]],"id":52385884},{"atb":[[1.03,11],[1.1,200]],"id":52385885},{"atl":[[1000,0.17]],"id":52385885},{"atb":[[1.01,32.99],[1.1,200]],"id":52385896},{"atl":[[990,0.17]],"id":52385896},{"atb":[[1.03,11],[1.1,200]],"id":52385897},{"atl":[[1000,0.17]],"id":52385897},{"atb":[[1.01,32.99],[1.1,200]],"id":52385890},{"atl":[[990,0.17]],"id":52385890},{"atb":[[1.01,32.99],[1.1,200]],"id":52385891},{"atl":[[990,0.17]],"id":52385891},{"atb":[[1.01,32.99],[1.1,200]],"id":52385892},{"atl":[[990,0.17]],"id":52385892},{"atb":[[1.02,16.49],[1.1,200]],"id":52385903},{"atl":[[1000,0.17]],"id":52385903},{"atb":[[1.02,16.49],[1.1,200]],"id":52385904},{"atl":[[990,0.17]],"id":52385904},{"atb":[[1.01,32.99],[1.1,200]],"id":52385905},{"atl":[[1000,0.17]],"id":52385905},{"atb":[[1.01,32.99],[1.1,200]],"id":52385898},{"atl":[[990,0.17]],"id":52385898},{"atb":[[1.01,32.99],[1.1,200]],"id":52385899},{"atl":[[990,0.17]],"id":52385899}],"con":true,"img":true}]}
{"op":"mcm","clk":"11550284086","pt":1719496612260,"mc":[{"id":"1.230178177","rc":[{"atb":[[1.01,32.99]],"id":52385910},{"atl":[[990,0.17]],"id":52385910},{"atb":[[1.01,32.99]],"id":52385911},{"atl":[[990,0.17]],"id":52385911},{"atb":[[1.03,11]],"id":52385912},{"atl":[[1000,0.17]],"id":52385912},{"atb":[[1.03,11]],"id":52385913},{"atl":[[1000,0.17]],"id":52385913},{"atb":[[1.02,16.49]],"id":52385906},{"atl":[[990,0.17]],"id":52385906},{"atb":[[1.02,16.49]],"id":52385889},{"atl":[[1000,0.17]],"id":52385889},{"atb":[[1.01,204.08],[1.02,16.49]],"id":52385882},{"atl":[[1000,0.17]],"id":52385882},{"atb":[[1.01,204.08],[1.02,16.49]],"id":52385883},{"atl":[[1000,0.17]],"id":52385883},{"atb":[[1.03,11]],"id":52385884},{"atl":[[990,0.17]],"id":52385884},{"atb":[[1.03,11]],"id":52385885},{"atl":[[1000,0.17]],"id":52385885},{"atb":[[1.01,32.99]],"id":52385896},{"atl":[[990,0.17]],"id":52385896},{"atb":[[1.03,11]],"id":52385897},{"atl":[[1000,0.17]],"id":52385897},{"atb":[[1.01,32.99]],"id":52385890},{"atl":[[990,0.17]],"id":52385890},{"atb":[[1.01,32.99]],"id":52385891},{"atl":[[990,0.17]],"id":52385891},{"atb":[[1.01,32.99]],"id":52385892},{"atl":[[990,0.17]],"id":52385892},{"atb":[[1.02,16.49]],"id":52385903},{"atl":[[1000,0.17]],"id":52385903},{"atb":[[1.02,16.49]],"id":52385904},{"atl":[[990,0.17]],"id":52385904},{"atb":[[1.01,32.99]],"id":52385905},{"atl":[[1000,0.17]],"id":52385905},{"atb":[[1.01,32.99]],"id":52385898},{"atl":[[990,0.17]],"id":52385898},{"atb":[[1.01,32.99]],"id":52385899},{"atl":[[990,0.17]],"id":52385899}],"con":true,"img":false}]}
{"op":"mcm","clk":"11550284106","pt":1719496612461,"mc":[{"id":"1.230178177","rc":[{"atb":[[1.01,204.08]],"id":52385884}],"con":true,"img":false}]}
{"op":"mcm","clk":"11550284119","pt":1719496612570,"mc":[{"id":"1.230178177","rc":[{"atb":[[1.01,204.08]],"id":52385885}],"con":true,"img":false}]}
{"op":"mcm","clk":"11550284132","pt":1719496612674,"mc":[{"id":"1.230178177","rc":[{"atb":[[1.01,204.08]],"id":52385889}],"con":true,"img":false}]}
{"op":"mcm","clk":"11550284156","pt":1719496612883,"mc":[{"id":"1.230178177","rc":[{"atb":[[1.01,237.07]],"id":52385890}],"con":true,"img":false}]}
{"op":"mcm","clk":"11550284168","pt":1719496612989,"mc":[{"id":"1.230178177","rc":[{"atb":[[1.01,237.07]],"id":52385891}],"con":true,"img":false}]}
{"op":"mcm","clk":"11550284183","pt":1719496613048,"mc":[{"id":"1.230178177","rc":[{"atb":[[1.01,237.07]],"id":52385892}],"con":true,"img":false}]}
{"op":"mcm","clk":"11550284195","pt":1719496613155,"mc":[{"id":"1.230178177","rc":[{"atb":[[1.01,237.07]],"id":52385896}],"con":true,"img":false}]}
{"op":"mcm","clk":"11550284223","pt":1719496613358,"mc":[{"id":"1.230178177","rc":[{"atb":[[1.01,204.08]],"id":52385897},{"atb":[[1.01,237.07]],"id":52385898}],"con":true,"img":false}]}
{"op":"mcm","clk":"11550284229","pt":1719496613461,"mc":[{"id":"1.230178177","rc":[{"atb":[[1.01,237.07]],"id":52385899}],"con":true,"img":false}]}
{"op":"mcm","clk":"11550284241","pt":1719496613567,"mc":[{"id":"1.230178177","rc":[{"atb":[[1.01,204.08]],"id":52385903}],"con":true,"img":false}]}
{"op":"mcm","clk":"11550284254","pt":1719496613774,"mc":[{"id":"1.230178177","rc":[{"atb":[[1.01,204.08]],"id":52385906},{"atb":[[1.01,204.08]],"id":52385904},{"atb":[[1.01,237.07]],"id":52385905}],"con":true,"img":false}]}
{"op":"mcm","clk":"11550284268","pt":1719496613981,"mc":[{"id":"1.230178177","rc":[{"atb":[[1.01,237.07]],"id":52385910},{"atb":[[1.01,237.07]],"id":52385911}],"con":true,"img":false}]}
{"op":"mcm","clk":"11550284275","pt":1719496614085,"mc":[{"id":"1.230178177","rc":[{"atb":[[1.01,204.08]],"id":52385912}],"con":true,"img":false}]}
{"op":"mcm","clk":"11550284286","pt":1719496614188,"mc":[{"id":"1.230178177","rc":[{"atb":[[1.01,204.08]],"id":52385913}],"con":true,"img":false}]}
{"op":"mcm","clk":"11550491745","pt":1719499082587,"mc":[{"id":"1.230178177","marketDefinition":{"bspMarket":false,"turnInPlayEnabled":false,"persistenceEnabled":false,"marketBaseRate":5.0,"eventId":"33376048","eventTypeId":"4339","numberOfWinners":1,"bettingType":"ODDS","marketType":"FORECAST","marketTime":"2024-06-27T16:56:00.000Z","suspendTime":"2024-06-27T16:56:00.000Z","bspReconciled":false,"complete":true,"inPlay":false,"crossMatching":false,"runnersVoidable":false,"numberOfActiveRunners":20,"betDelay":0,"status":"OPEN","runners":[{"status":"ACTIVE","sortPriority":1,"id":52385882,"name":"1 - 2"},{"status":"ACTIVE","sortPriority":2,"id":52385883,"name":"1 - 3"},{"status":"ACTIVE","sortPriority":3,"id":52385884,"name":"1 - 4"},{"status":"ACTIVE","sortPriority":4,"id":52385885,"name":"1 - 5"},{"status":"ACTIVE","sortPriority":5,"id":52385889,"name":"2 - 1"},{"status":"ACTIVE","sortPriority":6,"id":52385890,"name":"2 - 3"},{"status":"ACTIVE","sortPriority":7,"id":52385891,"name":"2 - 4"},{"status":"ACTIVE","sortPriority":8,"id":52385892,"name":"2 - 5"},{"status":"ACTIVE","sortPriority":9,"id":52385896,"name":"3 - 1"},{"status":"ACTIVE","sortPriority":10,"id":52385897,"name":"3 - 2"},{"status":"ACTIVE","sortPriority":11,"id":52385898,"name":"3 - 4"},{"status":"ACTIVE","sortPriority":12,"id":52385899,"name":"3 - 5"},{"status":"ACTIVE","sortPriority":13,"id":52385903,"name":"4 - 1"},{"status":"ACTIVE","sortPriority":14,"id":52385904,"name":"4 - 2"},{"status":"ACTIVE","sortPriority":15,"id":52385905,"name":"4 - 3"},{"status":"ACTIVE","sortPriority":16,"id":52385906,"name":"4 - 5"},{"status":"ACTIVE","sortPriority":17,"id":52385910,"name":"5 - 1"},{"status":"ACTIVE","sortPriority":18,"id":52385911,"name":"5 - 2"},{"status":"ACTIVE","sortPriority":19,"id":52385912,"name":"5 - 3"},{"status":"ACTIVE","sortPriority":20,"id":52385913,"name":"5 - 4"}],"regulators":["MR_INT"],"venue":"Perry Barr","countryCode":"GB","discountAllowed":true,"timezone":"Europe/London","openDate":"2024-06-27T13:29:00.000Z","version":5994794130,"name":"Forecast","eventName":"Perry Barr (F/C) 27th Jun"},"rc":[{"atb":[[1.01,237.06],[1.1,200]],"id":52385910},{"atl":[[990,0.17]],"id":52385910},{"atb":[[1.01,237.06],[1.1,200]],"id":52385911},{"atl":[[990,0.17]],"id":52385911},{"atb":[[1.01,204.08],[1.03,10.99],[1.1,200]],"id":52385912},{"atl":[[1000,0.17]],"id":52385912},{"atb":[[1.01,204.08],[1.03,10.99],[1.1,200]],"id":52385913},{"atl":[[1000,0.17]],"id":52385913},{"atb":[[1.01,204.08],[1.02,16.49],[1.1,200]],"id":52385906},{"atl":[[990,0.17]],"id":52385906},{"atb":[[1.01,204.08],[1.02,16.49],[1.1,200]],"id":52385889},{"atl":[[1000,0.17]],"id":52385889},{"atb":[[1.01,204.08],[1.02,16.49],[1.1,200]],"id":52385882},{"atl":[[1000,0.17]],"id":52385882},{"atb":[[1.01,204.08],[1.02,16.49],[1.1,200]],"id":52385883},{"atl":[[1000,0.17]],"id":52385883},{"atb":[[1.01,204.08],[1.03,10.99],[1.1,200]],"id":52385884},{"atl":[[990,0.17]],"id":52385884},{"atb":[[1.01,204.08],[1.03,10.99],[1.1,200]],"id":52385885},{"atl":[[1000,0.17]],"id":52385885},{"atb":[[1.01,237.06],[1.1,200]],"id":52385896},{"atl":[[990,0.17]],"id":52385896},{"atb":[[1.01,204.08],[1.03,10.99],[1.1,200]],"id":52385897},{"atl":[[1000,0.17]],"id":52385897},{"atb":[[1.01,237.06],[1.1,200]],"id":52385890},{"atl":[[990,0.17]],"id":52385890},{"atb":[[1.01,237.06],[1.1,200]],"id":52385891},{"atl":[[990,0.17]],"id":52385891},{"atb":[[1.01,237.06],[1.1,200]],"id":52385892},{"atl":[[990,0.17]],"id":52385892},{"atb":[[1.01,204.08],[1.02,16.49],[1.1,200]],"id":52385903},{"atl":[[1000,0.17]],"id":52385903},{"atb":[[1.01,204.08],[1.02,16.49],[1.1,200]],"id":52385904},{"atl":[[990,0.17]],"id":52385904},{"atb":[[1.01,237.06],[1.1,200]],"id":52385905},{"atl":[[1000,0.17]],"id":52385905},{"atb":[[1.01,237.06],[1.1,200]],"id":52385898},{"atl":[[990,0.17]],"id":52385898},{"atb":[[1.01,237.06],[1.1,200]],"id":52385899},{"atl":[[990,0.17]],"id":52385899}],"con":true,"img":true}]}
{"op":"mcm","clk":"11550571142","pt":1719500161287,"mc":[{"id":"1.230178177","rc":[{"atb":[[1.01,237.06]],"id":52385910},{"atl":[[970,1.73]],"id":52385910},{"atb":[[1.01,237.06]],"id":52385911},{"atl":[[970,0.85]],"id":52385911},{"atb":[[1.03,10.99]],"id":52385912},{"atl":[[980,1.96]],"id":52385912},{"atb":[[1.03,10.99]],"id":52385913},{"atl":[[970,1.02]],"id":52385913},{"atb":[[1.02,16.49]],"id":52385906},{"atl":[[990,1.43]],"id":52385906},{"atb":[[1.02,16.49]],"id":52385889},{"atl":[[960,0.91]],"id":52385889},{"atb":[[1.02,16.49]],"id":52385882},{"atl":[[980,1.08]],"id":52385882},{"atb":[[1.02,16.49]],"id":52385883},{"atl":[[990,1.64]],"id":52385883},{"atb":[[1.03,10.99]],"id":52385884},{"atl":[[990,1.03]],"id":52385884},{"atb":[[1.03,10.99]],"id":52385885},{"atl":[[990,1.44]],"id":52385885},{"atb":[[1.01,237.06]],"id":52385896},{"atl":[[970,2.01]],"id":52385896},{"atb":[[1.03,10.99]],"id":52385897},{"atl":[[970,0.85]],"id":52385897},{"atb":[[1.01,237.06]],"id":52385890},{"atl":[[970,0.85]],"id":52385890},{"atb":[[1.01,237.06]],"id":52385891},{"atl":[[960,1.28]],"id":52385891},{"atb":[[1.01,237.06]],"id":52385892},{"atl":[[990,1.28]],"id":52385892},{"atb":[[1.02,16.49]],"id":52385903},{"atl":[[960,0.85]],"id":52385903},{"atb":[[1.02,16.49]],"id":52385904},{"atl":[[960,1.06]],"id":52385904},{"atb":[[1.01,237.06]],"id":52385905},{"atl":[[970,0.94]],"id":52385905},{"atb":[[1.01,237.06]],"id":52385898},{"atl":[[970,0.85]],"id":52385898},{"atb":[[1.01,237.06]],"id":52385899},{"atl":[[990,1.28]],"id":52385899}],"con":true,"img":false}]}
{"op":"mcm","clk":"11550572147","pt":1719500173628,"mc":[{"id":"1.230178177","marketDefinition":{"bspMarket":false,"turnInPlayEnabled":false,"persistenceEnabled":false,"marketBaseRate":5.0,"eventId":"33376048","eventTypeId":"4339","numberOfWinners":1,"bettingType":"ODDS","marketType":"FORECAST","marketTime":"2024-06-27T16:56:00.000Z","suspendTime":"2024-06-27T16:56:00.000Z","bspReconciled":false,"complete":true,"inPlay":false,"crossMatching":true,"runnersVoidable":false,"numberOfActiveRunners":20,"betDelay":0,"status":"OPEN","runners":[{"status":"ACTIVE","sortPriority":1,"id":52385882,"name":"1 - 2"},{"status":"ACTIVE","sortPriority":2,"id":52385883,"name":"1 - 3"},{"status":"ACTIVE","sortPriority":3,"id":52385884,"name":"1 - 4"},{"status":"ACTIVE","sortPriority":4,"id":52385885,"name":"1 - 5"},{"status":"ACTIVE","sortPriority":5,"id":52385889,"name":"2 - 1"},{"status":"ACTIVE","sortPriority":6,"id":52385890,"name":"2 - 3"},{"status":"ACTIVE","sortPriority":7,"id":52385891,"name":"2 - 4"},{"status":"ACTIVE","sortPriority":8,"id":52385892,"name":"2 - 5"},{"status":"ACTIVE","sortPriority":9,"id":52385896,"name":"3 - 1"},{"status":"ACTIVE","sortPriority":10,"id":52385897,"name":"3 - 2"},{"status":"ACTIVE","sortPriority":11,"id":52385898,"name":"3 - 4"},{"status":"ACTIVE","sortPriority":12,"id":52385899,"name":"3 - 5"},{"status":"ACTIVE","sortPriority":13,"id":52385903,"name":"4 - 1"},{"status":"ACTIVE","sortPriority":14,"id":52385904,"name":"4 - 2"},{"status":"ACTIVE","sortPriority":15,"id":52385905,"name":"4 - 3"},{"status":"ACTIVE","sortPriority":16,"id":52385906,"name":"4 - 5"},{"status":"ACTIVE","sortPriority":17,"id":52385910,"name":"5 - 1"},{"status":"ACTIVE","sortPriority":18,"id":52385911,"name":"5 - 2"},{"status":"ACTIVE","sortPriority":19,"id":52385912,"name":"5 - 3"},{"status":"ACTIVE","sortPriority":20,"id":52385913,"name":"5 - 4"}],"regulators":["MR_INT"],"venue":"Perry Barr","countryCode":"GB","discountAllowed":true,"timezone":"Europe/London","openDate":"2024-06-27T13:29:00.000Z","version":5994794130,"name":"Forecast","eventName":"Perry Barr (F/C) 27th Jun"},"rc":[],"con":true,"img":false}]}
{"op":"mcm","clk":"11550621713","pt":1719500908803,"mc":[{"id":"1.230178177","rc":[{"atb":[[1.01,237.06],[1.03,1]],"id":52385910},{"atl":[[970,1.73]],"id":52385910},{"atb":[[1.01,237.06],[1.03,1]],"id":52385911},{"atl":[[970,0.85]],"id":52385911},{"atb":[[1.03,11.99]],"id":52385912},{"atl":[[980,1.96]],"id":52385912},{"atb":[[1.03,11.99]],"id":52385913},{"atl":[[970,1.02]],"id":52385913},{"atb":[[1.03,1],[1.02,16.49]],"id":52385906},{"atl":[[990,1.43]],"id":52385906},{"atb":[[1.03,1],[1.02,16.49]],"id":52385889},{"atl":[[960,0.91]],"id":52385889},{"atb":[[1.03,1],[1.02,16.49]],"id":52385882},{"atl":[[980,1.08]],"id":52385882},{"atb":[[1.03,1],[1.02,16.49]],"id":52385883},{"atl":[[990,1.64]],"id":52385883},{"atb":[[1.03,11.99]],"id":52385884},{"atl":[[990,1.03]],"id":52385884},{"atb":[[1.03,11.99]],"id":52385885},{"atl":[[990,1.44]],"id":52385885},{"atb":[[1.01,237.06],[1.03,1]],"id":52385896},{"atl":[[970,2.01]],"id":52385896},{"atb":[[1.03,11.99]],"id":52385897},{"atl":[[970,0.85]],"id":52385897},{"atb":[[1.01,237.06],[1.03,1]],"id":52385890},{"atl":[[970,0.85]],"id":52385890},{"atb":[[1.01,237.06],[1.03,1]],"id":52385891},{"atl":[[960,1.28]],"id":52385891},{"atb":[[1.01,237.06],[1.03,1]],"id":52385892},{"atl":[[990,1.28]],"id":52385892},{"atb":[[1.03,1],[1.02,16.49]],"id":52385903},{"atl":[[960,0.85]],"id":52385903},{"atb":[[1.03,1],[1.02,16.49]],"id":52385904},{"atl":[[960,1.06]],"id":52385904},{"atb":[[1.01,237.06],[1.03,1]],"id":52385905},{"atl":[[970,0.94]],"id":52385905},{"atb":[[1.01,237.06],[1.03,1]],"id":52385898},{"atl":[[970,0.85]],"id":52385898},{"atb":[[1.01,237.06],[1.03,1]],"id":52385899},{"atl":[[990,1.28]],"id":52385899}],"con":true,"img":false}]}
{"op":"mcm","clk":"11550621723","pt":1719500909009,"mc":[{"id":"1.230178177","rc":[{"atb":[[1.03,0.9]],"id":52385910},{"atb":[[1.03,0.9]],"id":52385911},{"atb":[[1.03,11.89]],"id":52385912},{"atb":[[1.03,11.89]],"id":52385913},{"atb":[[1.03,0.9]],"id":52385906},{"atb":[[1.03,0.9]],"id":52385889},{"atb":[[1.03,0.9]],"id":52385882},{"atb":[[1.03,0.9]],"id":52385883},{"atb":[[1.03,11.89]],"id":52385884},{"atb":[[1.03,11.89]],"id":52385885},{"atb":[[1.03,0.9]],"id":52385896},{"atb":[[1.03,11.89]],"id":52385897},{"atb":[[1.03,0.9]],"id":52385890},{"atb":[[1.03,0.9]],"id":52385891},{"atb":[[1.03,0.9]],"id":52385892},{"atb":[[1.03,0.9]],"id":52385903},{"atb":[[1.03,0.9]],"id":52385904},{"atb":[[1.03,0.9]],"id":52385905},{"atb":[[1.03,0.9]],"id":52385898},{"atb":[[1.03,0.9]],"id":52385899}],"con":true,"img":false}]}
{"op":"mcm","clk":"11550621729","pt":1719500909217,"mc":[{"id":"1.230178177","rc":[{"atb":[[1.03,0]],"id":52385910},{"atb":[[1.03,0]],"id":52385911},{"atb":[[1.03,10.99]],"id":52385912},{"atb":[[1.03,10.99]],"id":52385913},{"atb":[[1.03,0]],"id":52385906},{"atb":[[1.03,0]],"id":52385889},{"atb":[[1.03,0]],"id":52385882},{"atb":[[1.03,0]],"id":52385883},{"atb":[[1.03,10.99]],"id":52385884},{"atb":[[1.03,10.99]],"id":52385885},{"atb":[[1.03,0]],"id":52385896},{"atb":[[1.03,10.99]],"id":52385897},{"atb":[[1.03,0]],"id":52385890},{"atb":[[1.03,0]],"id":52385891},{"atb":[[1.03,0]],"id":52385892},{"atb":[[1.03,0]],"id":52385903},{"atb":[[1.03,0]],"id":52385904},{"atb":[[1.03,0]],"id":52385905},{"atb":[[1.03,0]],"id":52385898},{"atb":[[1.03,0]],"id":52385899}],"con":true,"img":false}]}
{"op":"mcm","clk":"11550621735","pt":1719500909323,"mc":[{"id":"1.230178177","rc":[{"atb":[[3.05,0.9]],"id":52385910},{"atb":[[3.05,0.9]],"id":52385911},{"atb":[[3.05,0.9]],"id":52385912},{"atb":[[3.05,0.9]],"id":52385913},{"atb":[[3.05,0.9]],"id":52385906},{"atb":[[3.05,0.9]],"id":52385889},{"atb":[[3.05,0.9]],"id":52385882},{"atb":[[3.05,0.9]],"id":52385883},{"atb":[[3.05,0.9]],"id":52385884},{"atb":[[3.05,0.9]],"id":52385885},{"atb":[[3.05,0.9]],"id":52385896},{"atb":[[3.05,0.9]],"id":52385897},{"atb":[[3.05,0.9]],"id":52385890},{"atb":[[3.05,0.9]],"id":52385891},{"atb":[[3.05,0.9]],"id":52385892},{"atb":[[3.05,0.9]],"id":52385903},{"atb":[[3.05,0.9]],"id":52385904},{"atb":[[3.05,0.9]],"id":52385905},{"atb":[[3.05,0.9]],"id":52385898},{"atb":[[3.05,0.9]],"id":52385899}],"con":true,"img":false}]}
{"op":"mcm","clk":"11550840617","pt":1719504482594,"mc":[{"id":"1.230178177","marketDefinition":{"bspMarket":false,"turnInPlayEnabled":false,"persistenceEnabled":false,"marketBaseRate":5.0,"eventId":"33376048","eventTypeId":"4339","numberOfWinners":1,"bettingType":"ODDS","marketType":"FORECAST","marketTime":"2024-06-27T16:56:00.000Z","suspendTime":"2024-06-27T16:56:00.000Z","bspReconciled":false,"complete":true,"inPlay":false,"crossMatching":true,"runnersVoidable":false,"numberOfActiveRunners":20,"betDelay":0,"status":"OPEN","runners":[{"status":"ACTIVE","sortPriority":1,"id":52385882,"name":"1 - 2"},{"status":"ACTIVE","sortPriority":2,"id":52385883,"name":"1 - 3"},{"status":"ACTIVE","sortPriority":3,"id":52385884,"name":"1 - 4"},{"status":"ACTIVE","sortPriority":4,"id":52385885,"name":"1 - 5"},{"status":"ACTIVE","sortPriority":5,"id":52385889,"name":"2 - 1"},{"status":"ACTIVE","sortPriority":6,"id":52385890,"name":"2 - 3"},{"status":"ACTIVE","sortPriority":7,"id":52385891,"name":"2 - 4"},{"status":"ACTIVE","sortPriority":8,"id":52385892,"name":"2 - 5"},{"status":"ACTIVE","sortPriority":9,"id":52385896,"name":"3 - 1"},{"status":"ACTIVE","sortPriority":10,"id":52385897,"name":"3 - 2"},{"status":"ACTIVE","sortPriority":11,"id":52385898,"name":"3 - 4"},{"status":"ACTIVE","sortPriority":12,"id":52385899,"name":"3 - 5"},{"status":"ACTIVE","sortPriority":13,"id":52385903,"name":"4 - 1"},{"status":"ACTIVE","sortPriority":14,"id":52385904,"name":"4 - 2"},{"status":"ACTIVE","sortPriority":15,"id":52385905,"name":"4 - 3"},{"status":"ACTIVE","sortPriority":16,"id":52385906,"name":"4 - 5"},{"status":"ACTIVE","sortPriority":17,"id":52385910,"name":"5 - 1"},{"status":"ACTIVE","sortPriority":18,"id":52385911,"name":"5 - 2"},{"status":"ACTIVE","sortPriority":19,"id":52385912,"name":"5 - 3"},{"status":"ACTIVE","sortPriority":20,"id":52385913,"name":"5 - 4"}],"regulators":["MR_INT"],"venue":"Perry Barr","countryCode":"GB","discountAllowed":true,"timezone":"Europe/London","openDate":"2024-06-27T13:29:00.000Z","version":5994794130,"name":"Forecast","eventName":"Perry Barr (F/C) 27th Jun"},"rc":[{"atb":[[1.01,237.05],[1.1,200],[3.05,0.9]],"id":52385910},{"atl":[[970,1.73],[990,0.17]],"id":52385910},{"atb":[[1.01,237.05],[1.1,200],[3.05,0.9]],"id":52385911},{"atl":[[970,0.85],[990,0.17]],"id":52385911},{"atb":[[1.01,204.08],[1.03,10.99],[1.1,200],[3.05,0.9]],"id":52385912},{"atl":[[980,1.96],[1000,0.17]],"id":52385912},{"atb":[[1.01,204.08],[1.03,10.99],[1.1,200],[3.05,0.9]],"id":52385913},{"atl":[[970,1.02],[1000,0.17]],"id":52385913},{"atb":[[1.01,204.08],[1.02,16.48],[1.1,200],[3.05,0.9]],"id":52385906},{"atl":[[990,1.43]],"id":52385906},{"atb":[[1.01,204.08],[1.02,16.48],[1.1,200],[3.05,0.9]],"id":52385889},{"atl":[[960,0.91],[1000,0.17]],"id":52385889},{"atb":[[1.01,204.08],[1.02,16.48],[1.1,200],[3.05,0.9]],"id":52385882},{"atl":[[980,1.08],[1000,0.17]],"id":52385882},{"atb":[[1.01,204.08],[1.02,16.48],[1.1,200],[3.05,0.9]],"id":52385883},{"atl":[[990,1.64],[1000,0.17]],"id":52385883},{"atb":[[1.01,204.08],[1.03,10.99],[1.1,200],[3.05,0.9]],"id":52385884},{"atl":[[990,1.03]],"id":52385884},{"atb":[[1.01,204.08],[1.03,10.99],[1.1,200],[3.05,0.9]],"id":52385885},{"atl":[[990,1.44],[1000,0.17]],"id":52385885},{"atb":[[1.01,237.05],[1.1,200],[3.05,0.9]],"id":52385896},{"atl":[[970,2.01],[990,0.17]],"id":52385896},{"atb":[[1.01,204.08],[1.03,10.99],[1.1,200],[3.05,0.9]],"id":52385897},{"atl":[[970,0.85],[1000,0.17]],"id":52385897},{"atb":[[1.01,237.05],[1.1,200],[3.05,0.9]],"id":52385890},{"atl":[[970,0.85],[990,0.17]],"id":52385890},{"atb":[[1.01,237.05],[1.1,200],[3.05,0.9]],"id":52385891},{"atl":[[960,1.28],[990,0.17]],"id":52385891},{"atb":[[1.01,237.05],[1.1,200],[3.05,0.9]],"id":52385892},{"atl":[[990,1.28]],"id":52385892},{"atb":[[1.01,204.08],[1.02,16.48],[1.1,200],[3.05,0.9]],"id":52385903},{"atl":[[960,0.85],[1000,0.17]],"id":52385903},{"atb":[[1.01,204.08],[1.02,16.48],[1.1,200],[3.05,0.9]],"id":52385904},{"atl":[[960,1.06],[990,0.17]],"id":52385904},{"atb":[[1.01,237.05],[1.1,200],[3.05,0.9]],"id":52385905},{"atl":[[970,0.94],[1000,0.17]],"id":52385905},{"atb":[[1.01,237.05],[1.1,200],[3.05,0.9]],"id":52385898},{"atl":[[970,0.85],[990,0.17]],"id":52385898},{"atb":[[1.01,237.05],[1.1,200],[3.05,0.9]],"id":52385899},{"atl":[[990,1.28]],"id":52385899}],"con":true,"img":true}]}
{"op":"mcm","clk":"11550938038","pt":1719506188696,"mc":[{"id":"1.230178177","rc":[{"atb":[[1.01,237.05]],"id":52385910},{"atl":[[970,1.73]],"id":52385910},{"atb":[[1.01,237.05]],"id":52385911},{"atl":[[970,0.85]],"id":52385911},{"atb":[[1.03,10.99]],"id":52385912},{"atl":[[980,1.96]],"id":52385912},{"atb":[[1.03,10.99]],"id":52385913},{"atl":[[970,1.02]],"id":52385913},{"atb":[[8.6,22.4],[1.02,16.48]],"id":52385906},{"atl":[[990,1.43]],"id":52385906},{"atb":[[1.02,16.48]],"id":52385889},{"atl":[[960,0.91]],"id":52385889},{"atb":[[1.02,16.48]],"id":52385882},{"atl":[[980,1.08]],"id":52385882},{"atb":[[1.02,16.48]],"id":52385883},{"atl":[[990,1.64]],"id":52385883},{"atb":[[1.03,10.99]],"id":52385884},{"atl":[[990,1.03]],"id":52385884},{"atb":[[1.03,10.99]],"id":52385885},{"atl":[[990,1.44]],"id":52385885},{"atb":[[1.01,237.05]],"id":52385896},{"atl":[[970,2.01]],"id":52385896},{"atb":[[1.03,10.99]],"id":52385897},{"atl":[[970,0.85]],"id":52385897},{"atb":[[1.01,237.05]],"id":52385890},{"atl":[[970,0.85]],"id":52385890},{"atb":[[1.01,237.05]],"id":52385891},{"atl":[[960,1.28]],"id":52385891},{"atb":[[1.01,237.05]],"id":52385892},{"atl":[[990,1.28]],"id":52385892},{"atb":[[1.02,16.48]],"id":52385903},{"atl":[[960,0.85]],"id":52385903},{"atb":[[1.02,16.48]],"id":52385904},{"atl":[[960,1.06]],"id":52385904},{"atb":[[1.01,237.05],[8.8,2.38]],"id":52385905},{"atl":[[970,0.94]],"id":52385905},{"atb":[[1.01,237.05]],"id":52385898},{"atl":[[970,0.85]],"id":52385898},{"atb":[[1.01,237.05]],"id":52385899},{"atl":[[990,1.28]],"id":52385899}],"con":true,"img":false}]}
{"op":"mcm","clk":"11550938045","pt":1719506188753,"mc":[{"id":"1.230178177","rc":[{"atb":[[8.6,0]],"id":52385906},{"atb":[[8.8,0]],"id":52385905}],"con":true,"img":false}]}
{"op":"mcm","clk":"11550938913","pt":1719506202183,"mc":[{"id":"1.230178177","rc":[{"atb":[[14,2.7]],"id":52385882},{"atb":[[15.5,4.1]],"id":52385883},{"atb":[[6.6,15.02]],"id":52385884},{"atb":[[15.5,3.62]],"id":52385885}],"con":true,"img":false}]}
{"op":"mcm","clk":"11550938958","pt":1719506202907,"mc":[{"id":"1.230178177","rc":[{"atb":[[2,50]],"id":52385882},{"atb":[[2,50]],"id":52385883},{"atb":[[2,50]],"id":52385884},{"atb":[[2,50]],"id":52385885}],"con":true,"img":false}]}
{"op":"mcm","clk":"11550939104","pt":1719506204883,"mc":[{"id":"1.230178177","rc":[{"atb":[[14,0]],"id":52385882}],"con":true,"img":false}]}
{"op":"mcm","clk":"11550939112","pt":1719506204992,"mc":[{"id":"1.230178177","rc":[{"atb":[[15.5,0]],"id":52385883},{"atb":[[6.6,0]],"id":52385884},{"atb":[[15.5,0]],"id":52385885}],"con":true,"img":false}]}
{"op":"mcm","clk":"11550939308","pt":1719506208108,"mc":[{"id":"1.230178177","rc":[{"atb":[[2,0]],"id":52385882}],"con":true,"img":false}]}
{"op":"mcm","clk":"11550939324","pt":1719506208310,"mc":[{"id":"1.230178177","rc":[{"atb":[[2,0]],"id":52385883}],"con":true,"img":false}]}
{"op":"mcm","clk":"11550939361","pt":1719506208784,"mc":[{"id":"1.230178177","rc":[{"atb":[[2,0]],"id":52385884}],"con":true,"img":false}]}
{"op":"mcm","clk":"11550939378","pt":1719506209096,"mc":[{"id":"1.230178177","rc":[{"atb":[[2,0]],"id":52385885}],"con":true,"img":false}]}
{"op":"mcm","clk":"11550940402","pt":1719506223395,"mc":[{"id":"1.230178177","rc":[{"atb":[[12,8]],"id":52385910},{"atb":[[16,6]],"id":52385911},{"atb":[[15,6]],"id":52385912},{"atb":[[9,11]],"id":52385913},{"atb":[[6,12]],"id":52385906},{"atb":[[9,11]],"id":52385889},{"atb":[[9,11]],"id":52385882},{"atb":[[11,9]],"id":52385883},{"atb":[[9,11]],"id":52385884},{"atb":[[13,8]],"id":52385885},{"atb":[[11,9]],"id":52385896},{"atb":[[12,8]],"id":52385897},{"atb":[[14,7]],"id":52385890},{"atb":[[9,11]],"id":52385891},{"atb":[[14,7]],"id":52385892},{"atb":[[5,12]],"id":52385903},{"atb":[[6,12]],"id":52385904},{"atb":[[6,12]],"id":52385905},{"atb":[[8,12]],"id":52385898},{"atb":[[14,7]],"id":52385899}],"con":true,"img":false}]}
{"op":"mcm","clk":"11550940731","pt":1719506229734,"mc":[{"id":"1.230178177","rc":[{"atb":[[2,50]],"id":52385889}],"con":true,"img":false}]}
{"op":"mcm","clk":"11550940736","pt":1719506229791,"mc":[{"id":"1.230178177","rc":[{"atb":[[2,50]],"id":52385910},{"atb":[[2,50]],"id":52385911},{"atb":[[2,50]],"id":52385912},{"atb":[[2,50]],"id":52385913},{"atb":[[2,50]],"id":52385906},{"atb":[[2,50]],"id":52385896},{"atb":[[2,50]],"id":52385897},{"atb":[[2,50]],"id":52385890},{"atb":[[2,50]],"id":52385891},{"atb":[[2,50]],"id":52385903},{"atb":[[2,50]],"id":52385905},{"atb":[[2,50]],"id":52385898},{"atb":[[2,50]],"id":52385899}],"con":true,"img":false}]}
{"op":"mcm","clk":"11550940741","pt":1719506229896,"mc":[{"id":"1.230178177","rc":[{"atb":[[2,50]],"id":52385892}],"con":true,"img":false}]}
{"op":"mcm","clk":"11550940755","pt":1719506230110,"mc":[{"id":"1.230178177","rc":[{"atb":[[2,50]],"id":52385904}],"con":true,"img":false}]}
{"op":"mcm","clk":"11550940994","pt":1719506235035,"mc":[{"id":"1.230178177","rc":[{"atb":[[2,0]],"id":52385889}],"con":true,"img":false}]}
{"op":"mcm","clk":"11550941007","pt":1719506235343,"mc":[{"id":"1.230178177","rc":[{"atb":[[2,0]],"id":52385892}],"con":true,"img":false}]}
{"op":"mcm","clk":"11550941019","pt":1719506235506,"mc":[{"id":"1.230178177","rc":[{"atb":[[2,0]],"id":52385913}],"con":true,"img":false}]}
{"op":"mcm","clk":"11550941033","pt":1719506235716,"mc":[{"id":"1.230178177","rc":[{"atb":[[2,0]],"id":52385890}],"con":true,"img":false}]}
{"op":"mcm","clk":"11550941046","pt":1719506235913,"mc":[{"id":"1.230178177","rc":[{"atb":[[2,0]],"id":52385910}],"con":true,"img":false}]}
{"op":"mcm","clk":"11550941056","pt":1719506236119,"mc":[{"id":"1.230178177","rc":[{"atb":[[2,0]],"id":52385897}],"con":true,"img":false}]}
{"op":"mcm","clk":"11550941072","pt":1719506236429,"mc":[{"id":"1.230178177","rc":[{"atb":[[2,0]],"id":52385899}],"con":true,"img":false}]}
{"op":"mcm","clk":"11550941100","pt":1719506236905,"mc":[{"id":"1.230178177","rc":[{"atb":[[2,0]],"id":52385891}],"con":true,"img":false}]}
{"op":"mcm","clk":"11550941115","pt":1719506237109,"mc":[{"id":"1.230178177","rc":[{"atb":[[2,0]],"id":52385898}],"con":true,"img":false}]}
{"op":"mcm","clk":"11550941130","pt":1719506237428,"mc":[{"id":"1.230178177","rc":[{"atb":[[2,0]],"id":52385911}],"con":true,"img":false}]}
{"op":"mcm","clk":"11550941142","pt":1719506237735,"mc":[{"id":"1.230178177","rc":[{"atb":[[2,0]],"id":52385906}],"con":true,"img":false}]}
{"op":"mcm","clk":"11550941158","pt":1719506237938,"mc":[{"id":"1.230178177","rc":[{"atb":[[2,0]],"id":52385896}],"con":true,"img":false}]}
{"op":"mcm","clk":"11550941170","pt":1719506238101,"mc":[{"id":"1.230178177","rc":[{"atb":[[2,0]],"id":52385903}],"con":true,"img":false}]}
{"op":"mcm","clk":"11550941180","pt":1719506238307,"mc":[{"id":"1.230178177","rc":[{"atb":[[2,0]],"id":52385905}],"con":true,"img":false}]}
{"op":"mcm","clk":"11550941191","pt":1719506238512,"mc":[{"id":"1.230178177","rc":[{"atb":[[2,0]],"id":52385912}],"con":true,"img":false}]}
{"op":"mcm","clk":"11550941204","pt":1719506238717,"mc":[{"id":"1.230178177","rc":[{"atb":[[2,0]],"id":52385904}],"con":true,"img":false}]}
{"op":"mcm","clk":"11550952284","pt":1719506460323,"mc":[{"id":"1.230178177","rc":[{"atb":[[5.8,20.83]],"id":52385910},{"atl":[[450,2]],"id":52385910},{"atb":[[9.6,11.63]],"id":52385911},{"atl":[[580,2]],"id":52385911},{"atb":[[11,10]],"id":52385912},{"atl":[[670,2]],"id":52385912},{"atb":[[5.4,22]],"id":52385913},{"atl":[[430,2]],"id":52385913},{"atb":[[4.4,24]],"id":52385906},{"atl":[[280,2]],"id":52385906},{"atb":[[5.3,22]],"id":52385889},{"atl":[[420,2]],"id":52385889},{"atb":[[5.9,20.41]],"id":52385882},{"atl":[[450,2]],"id":52385882},{"atb":[[8.2,13.89]],"id":52385883},{"atl":[[520,2]],"id":52385883},{"atb":[[4.4,22]],"id":52385884},{"atl":[[300,2]],"id":52385884},{"atb":[[6.4,16]],"id":52385885},{"atl":[[480,2]],"id":52385885},{"atb":[[7,16.67]],"id":52385896},{"atl":[[500,2]],"id":52385896},{"atb":[[10.5,10.53]],"id":52385897},{"atl":[[640,2]],"id":52385897},{"atb":[[10.5,10.53]],"id":52385890},{"atl":[[650,2]],"id":52385890},{"atb":[[5.5,22.22]],"id":52385891},{"atl":[[440,2]],"id":52385891},{"atb":[[9.4,11.9]],"id":52385892},{"atl":[[570,2]],"id":52385892},{"atb":[[3.15,24]],"id":52385903},{"atl":[[65,2]],"id":52385903},{"atb":[[4.6,24]],"id":52385904},{"atl":[[320,2]],"id":52385904},{"atb":[[5.1,24.39]],"id":52385905},{"atl":[[410,2]],"id":52385905},{"atb":[[7,16.67]],"id":52385898},{"atl":[[490,2]],"id":52385898},{"atb":[[10.5,10.53]],"id":52385899},{"atl":[[650,2]],"id":52385899}],"con":true,"img":false}]}
{"op":"mcm","clk":"11550954670","pt":1719506509881,"mc":[{"id":"1.230178177","rc":[{"atb":[[4.7,24]],"id":52385906},{"atl":[[260,2]],"id":52385906},{"atb":[[10.5,0]],"id":52385897},{"atl":[[640,0]],"id":52385897}],"con":true,"img":false}]}
{"op":"mcm","clk":"11550954677","pt":1719506509995,"mc":[{"id":"1.230178177","rc":[{"atb":[[5.8,0],[6.6,17.86]],"id":52385910},{"atl":[[440,2],[450,0]],"id":52385910},{"atb":[[9.6,0],[11,10]],"id":52385911},{"atl":[[560,2],[580,0]],"id":52385911},{"atb":[[11,0],[12.5,8.7]],"id":52385912},{"atl":[[670,0],[650,2]],"id":52385912},{"atb":[[6,20],[5.4,0]],"id":52385913},{"atl":[[430,0],[420,2]],"id":52385913},{"atb":[[4.4,0]],"id":52385906},{"atl":[[280,0]],"id":52385906},{"atb":[[5.3,0],[5.9,20.41]],"id":52385889},{"atl":[[410,2],[420,0]],"id":52385889},{"atb":[[6.6,17.86],[5.9,0]],"id":52385882},{"atl":[[440,2],[450,0]],"id":52385882},{"atb":[[8.2,0],[8.8,12.82]],"id":52385883},{"atl":[[520,0],[510,2]],"id":52385883},{"atb":[[4.9,22],[4.4,0]],"id":52385884},{"atl":[[270,2],[300,0]],"id":52385884},{"atb":[[6.4,0],[7.4,15.62]],"id":52385885},{"atl":[[460,2],[480,0]],"id":52385885},{"atb":[[7.6,15.15],[7,0]],"id":52385896},{"atl":[[480,2],[500,0]],"id":52385896},{"atb":[[11,10]],"id":52385897},{"atl":[[620,2]],"id":52385897},{"atb":[[10.5,0],[11.5,9.52]],"id":52385890},{"atl":[[620,2],[650,0]],"id":52385890},{"atb":[[5.5,0],[6,20]],"id":52385891},{"atl":[[420,2],[440,0]],"id":52385891},{"atb":[[10,11.11],[9.4,0]],"id":52385892},{"atl":[[570,0],[550,2]],"id":52385892},{"atl":[[65,0],[55,2]],"id":52385903},{"atb":[[4.6,0],[5,24]],"id":52385904},{"atl":[[290,2],[320,0]],"id":52385904},{"atb":[[5.1,0],[5.7,21.28]],"id":52385905},{"atl":[[380,2],[410,0]],"id":52385905},{"atb":[[7,0],[7.8,14.71]],"id":52385898},{"atl":[[470,2],[490,0]],"id":52385898},{"atb":[[10.5,0],[11.5,9.52]],"id":52385899},{"atl":[[630,2],[650,0]],"id":52385899}],"con":true,"img":false}]}
{"op":"mcm","clk":"11550955121","pt":1719506519480,"mc":[{"id":"1.230178177","rc":[{"atl":[[260,0],[250,2]],"id":52385906}],"con":true,"img":false}]}
{"op":"mcm","clk":"11550955132","pt":1719506519583,"mc":[{"id":"1.230178177","rc":[{"atb":[[8.8,0],[9.4,11.9]],"id":52385883},{"atb":[[11,0],[12,16]],"id":52385897},{"atb":[[11.5,0],[12,9.09]],"id":52385890},{"atb":[[11.5,0],[12.5,8.7]],"id":52385899}],"con":true,"img":false}]}
{"op":"mcm","clk":"11550955342","pt":1719506523595,"mc":[{"id":"1.230178177","rc":[{"atb":[[9,0]],"id":52385884}],"con":true,"img":false}]}
{"op":"mcm","clk":"11550955347","pt":1719506523697,"mc":[{"id":"1.230178177","rc":[{"atb":[[8,11]],"id":52385884}],"con":true,"img":false}]}
{"op":"mcm","clk":"11550955352","pt":1719506523800,"mc":[{"id":"1.230178177","rc":[{"atb":[[4.9,0],[2.78,56.18]],"id":52385884}],"con":true,"img":false}]}
{"op":"mcm","clk":"11550955521","pt":1719506527377,"mc":[{"id":"1.230178177","rc":[{"atl":[[440,0],[470,2]],"id":52385910},{"atl":[[560,0],[610,2]],"id":52385911},{"atl":[[650,0],[710,2]],"id":52385912},{"atl":[[420,0],[440,2]],"id":52385913},{"atl":[[300,2],[250,0]],"id":52385906},{"atl":[[430,2]],"id":52385889},{"atl":[[440,0],[470,2]],"id":52385882},{"atl":[[540,2],[510,0]],"id":52385883},{"atl":[[270,0],[320,2]],"id":52385884},{"atl":[[460,0],[500,2]],"id":52385885},{"atl":[[480,0],[510,2]],"id":52385896},{"atl":[[620,0],[680,2]],"id":52385897},{"atl":[[620,0],[680,2]],"id":52385890},{"atl":[[420,0],[450,2]],"id":52385891},{"atl":[[550,0],[590,2]],"id":52385892},{"atl":[[70,2],[55,0]],"id":52385903},{"atl":[[290,0],[330,2]],"id":52385904},{"atl":[[380,0],[420,2]],"id":52385905},{"atl":[[470,0],[510,2]],"id":52385898},{"atl":[[630,0],[690,2]],"id":52385899}],"con":true,"img":false}]}
{"op":"mcm","clk":"11550955524","pt":1719506527481,"mc":[{"id":"1.230178177","rc":[{"atl":[[410,0]],"id":52385889}],"con":true,"img":false}]}
{"op":"mcm","clk":"11550955818","pt":1719506533281,"mc":[{"id":"1.230178177","rc":[{"atb":[[4.9,25.64],[2.78,0]],"id":52385884}],"con":true,"img":false}]}
{"op":"mcm","clk":"11550955979","pt":1719506536779,"mc":[{"id":"1.230178177","rc":[{"atl":[[420,2]],"id":52385913},{"atl":[[500,0]],"id":52385885}],"con":true,"img":false}]}
{"op":"mcm","clk":"11550955985","pt":1719506536878,"mc":[{"id":"1.230178177","rc":[{"atl":[[440,2],[470,0]],"id":52385910},{"atl":[[560,2],[610,0]],"id":52385911},{"atl":[[650,2],[710,0]],"id":52385912},{"atl":[[440,0]],"id":52385913},{"atl":[[300,0],[250,2]],"id":52385906},{"atl":[[410,2],[430,0]],"id":52385889},{"atl":[[440,2],[470,0]],"id":52385882},{"atl":[[540,0],[510,2]],"id":52385883},{"atl":[[270,2],[320,0]],"id":52385884},{"atl":[[460,2]],"id":52385885},{"atl":[[480,2],[510,0]],"id":52385896},{"atl":[[620,2],[680,0]],"id":52385897},{"atl":[[620,2],[680,0]],"id":52385890},{"atl":[[420,2],[450,0]],"id":52385891},{"atl":[[550,2]],"id":52385892},{"atl":[[70,0],[55,2]],"id":52385903},{"atl":[[290,2],[330,0]],"id":52385904},{"atl":[[380,2],[420,0]],"id":52385905},{"atl":[[470,2],[510,0]],"id":52385898},{"atl":[[630,2],[690,0]],"id":52385899}],"con":true,"img":false}]}
{"op":"mcm","clk":"11550955991","pt":1719506536989,"mc":[{"id":"1.230178177","rc":[{"atl":[[590,0]],"id":52385892}],"con":true,"img":false}]}
{"op":"mcm","clk":"11550956666","pt":1719506551515,"mc":[{"id":"1.230178177","rc":[{"atb":[[7.6,5]],"id":52385884}],"con":true,"img":false}]}
{"op":"mcm","clk":"11550956689","pt":1719506552035,"mc":[{"id":"1.230178177","rc":[{"atb":[[7.6,0]],"id":52385884}],"con":true,"img":false}]}
{"op":"mcm","clk":"11550956751","pt":1719506553228,"mc":[{"id":"1.230178177","rc":[{"atl":[[440,0],[470,2]],"id":52385910},{"atl":[[560,0],[610,2]],"id":52385911},{"atl":[[650,0],[710,2]],"id":52385912},{"atl":[[420,0],[440,2]],"id":52385913},{"atl":[[300,2],[250,0]],"id":52385906},{"atl":[[410,0],[430,2]],"id":52385889},{"atl":[[440,0],[470,2]],"id":52385882},{"atl":[[540,2],[510,0]],"id":52385883},{"atl":[[270,0],[320,2]],"id":52385884},{"atl":[[460,0],[500,2]],"id":52385885},{"atl":[[480,0],[510,2]],"id":52385896},{"atl":[[620,0],[680,2]],"id":52385897},{"atl":[[620,0],[680,2]],"id":52385890},{"atl":[[420,0],[450,2]],"id":52385891},{"atl":[[550,0],[590,2]],"id":52385892},{"atl":[[70,2],[55,0]],"id":52385903},{"atl":[[290,0],[330,2]],"id":52385904},{"atl":[[380,0],[420,2]],"id":52385905},{"atl":[[470,0],[510,2]],"id":52385898},{"atl":[[630,0],[690,2]],"id":52385899}],"con":true,"img":false}]}
{"op":"mcm","clk":"11550956828","pt":1719506554937,"mc":[{"id":"1.230178177","rc":[{"atl":[[620,2],[680,0]],"id":52385897},{"atl":[[380,2]],"id":52385905}],"con":true,"img":false}]}
{"op":"mcm","clk":"11550956831","pt":1719506555037,"mc":[{"id":"1.230178177","rc":[{"atl":[[440,2],[470,0]],"id":52385882},{"atl":[[420,0]],"id":52385905}],"con":true,"img":false}]}
{"op":"mcm","clk":"11550957119","pt":1719506562451,"mc":[{"id":"1.230178177","rc":[{"atl":[[440,2],[470,0]],"id":52385910},{"atl":[[560,2],[610,0]],"id":52385911},{"atl":[[650,2],[710,0]],"id":52385912},{"atl":[[420,2],[440,0]],"id":52385913},{"atl":[[300,0],[250,2]],"id":52385906},{"atl":[[410,2],[430,0]],"id":52385889},{"atl":[[540,0],[510,2]],"id":52385883},{"atl":[[270,2],[320,0]],"id":52385884},{"atl":[[460,2],[500,0]],"id":52385885},{"atl":[[480,2],[510,0]],"id":52385896},{"atl":[[620,2],[680,0]],"id":52385890},{"atl":[[420,2],[450,0]],"id":52385891},{"atl":[[550,2],[590,0]],"id":52385892},{"atl":[[70,0],[55,2]],"id":52385903},{"atl":[[290,2],[330,0]],"id":52385904},{"atl":[[470,2],[510,0]],"id":52385898},{"atl":[[630,2],[690,0]],"id":52385899}],"con":true,"img":false}]}
{"op":"mcm","clk":"11550957275","pt":1719506566027,"mc":[{"id":"1.230178177","rc":[{"atb":[[26,4.95]],"id":52385912},{"atb":[[16.5,3.85]],"id":52385882},{"atb":[[18,4.55]],"id":52385883},{"atb":[[18,4.31]],"id":52385885},{"atb":[[19,5.01]],"id":52385896},{"atb":[[24,3.62]],"id":52385890},{"atb":[[24,4.11]],"id":52385892},{"atb":[[26,4.11]],"id":52385899}],"con":true,"img":false}]}
{"op":"mcm","clk":"11550957282","pt":1719506566232,"mc":[{"id":"1.230178177","rc":[{"atb":[[26,0]],"id":52385912},{"atb":[[16.5,0]],"id":52385882},{"atb":[[18,0]],"id":52385883},{"atb":[[18,0]],"id":52385885},{"atb":[[19,0]],"id":52385896},{"atb":[[24,0]],"id":52385890},{"atb":[[24,0]],"id":52385892},{"atb":[[26,0]],"id":52385899}],"con":true,"img":false}]}
{"op":"mcm","clk":"11550957293","pt":1719506566542,"mc":[{"id":"1.230178177","rc":[{"atl":[[470,2]],"id":52385910},{"atl":[[320,2]],"id":52385884},{"atl":[[510,2]],"id":52385896},{"atl":[[330,2]],"id":52385904}],"con":true,"img":false}]}
{"op":"mcm","clk":"11550957302","pt":1719506566647,"mc":[{"id":"1.230178177","rc":[{"atl":[[440,0]],"id":52385910},{"atl":[[560,0],[610,2]],"id":52385911},{"atl":[[650,0],[710,2]],"id":52385912},{"atl":[[420,0],[440,2]],"id":52385913},{"atl":[[300,2],[250,0]],"id":52385906},{"atl":[[410,0],[430,2]],"id":52385889},{"atl":[[440,0],[470,2]],"id":52385882},{"atl":[[540,2]],"id":52385883},{"atl":[[270,0]],"id":52385884},{"atl":[[460,0],[500,2]],"id":52385885},{"atl":[[480,0]],"id":52385896},{"atl":[[620,0],[680,2]],"id":52385897},{"atl":[[620,0],[680,2]],"id":52385890},{"atl":[[420,0],[450,2]],"id":52385891},{"atl":[[550,0],[590,2]],"id":52385892},{"atl":[[70,2],[55,0]],"id":52385903},{"atl":[[290,0]],"id":52385904},{"atl":[[380,0],[420,2]],"id":52385905},{"atl":[[470,0],[510,2]],"id":52385898},{"atl":[[630,0],[690,2]],"id":52385899}],"con":true,"img":false}]}
{"op":"mcm","clk":"11550957305","pt":1719506566753,"mc":[{"id":"1.230178177","rc":[{"atl":[[510,0]],"id":52385883}],"con":true,"img":false}]}
{"op":"mcm","clk":"11550958053","pt":1719506582248,"mc":[{"id":"1.230178177","rc":[{"atl":[[440,2],[470,0]],"id":52385910},{"atl":[[560,2],[610,0]],"id":52385911},{"atl":[[650,2],[710,0]],"id":52385912},{"atl":[[420,2],[440,0]],"id":52385913},{"atl":[[300,0],[250,2]],"id":52385906},{"atl":[[410,2],[430,0]],"id":52385889},{"atl":[[440,2],[470,0]],"id":52385882},{"atl":[[540,0],[510,2]],"id":52385883},{"atl":[[270,2],[320,0]],"id":52385884},{"atl":[[460,2],[500,0]],"id":52385885},{"atl":[[480,2],[510,0]],"id":52385896},{"atl":[[620,2],[680,0]],"id":52385897},{"atl":[[620,2],[680,0]],"id":52385890},{"atl":[[420,2],[450,0]],"id":52385891},{"atl":[[550,2],[590,0]],"id":52385892},{"atl":[[70,0],[55,2]],"id":52385903},{"atl":[[290,2]],"id":52385904},{"atl":[[380,2],[420,0]],"id":52385905},{"atl":[[470,2],[510,0]],"id":52385898},{"atl":[[630,2],[690,0]],"id":52385899}],"con":true,"img":false}]}
{"op":"mcm","clk":"11550958060","pt":1719506582356,"mc":[{"id":"1.230178177","rc":[{"atl":[[330,0]],"id":52385904}],"con":true,"img":false}]}
{"op":"mcm","clk":"11550960264","pt":1719506624778,"mc":[{"id":"1.230178177","rc":[{"atb":[[7.6,5]],"id":52385884}],"con":true,"img":false}]}
{"op":"mcm","clk":"11550960275","pt":1719506625043,"mc":[{"id":"1.230178177","rc":[{"atb":[[7.6,0]],"id":52385884}],"con":true,"img":false}]}
{"op":"mcm","clk":"11550960285","pt":1719506625249,"mc":[{"id":"1.230178177","rc":[{"atl":[[440,0],[470,2]],"id":52385910},{"atl":[[650,0],[710,2]],"id":52385912},{"atl":[[420,0],[440,2]],"id":52385913},{"atl":[[300,2]],"id":52385906},{"atl":[[410,0],[430,2]],"id":52385889},{"atl":[[440,0],[470,2]],"id":52385882},{"atl":[[540,2],[510,0]],"id":52385883},{"atl":[[270,0],[320,2]],"id":52385884},{"atl":[[460,0],[500,2]],"id":52385885},{"atl":[[480,0],[510,2]],"id":52385896},{"atl":[[620,0],[680,2]],"id":52385897},{"atl":[[620,0],[680,2]],"id":52385890},{"atl":[[420,0],[450,2]],"id":52385891},{"atl":[[550,0],[590,2]],"id":52385892},{"atl":[[70,2],[55,0]],"id":52385903},{"atl":[[290,0],[330,2]],"id":52385904},{"atl":[[380,0],[420,2]],"id":52385905},{"atl":[[470,0],[510,2]],"id":52385898},{"atl":[[630,0],[690,2]],"id":52385899}],"con":true,"img":false}]}
{"op":"mcm","clk":"11550960289","pt":1719506625352,"mc":[{"id":"1.230178177","rc":[{"atl":[[560,0],[610,2]],"id":52385911},{"atl":[[250,0]],"id":52385906}],"con":true,"img":false}]}
{"op":"mcm","clk":"11550960296","pt":1719506625459,"mc":[{"id":"1.230178177","rc":[{"atl":[[440,2],[470,0]],"id":52385910},{"atl":[[650,2],[710,0]],"id":52385912},{"atl":[[420,2],[440,0]],"id":52385913},{"atl":[[410,2],[430,0]],"id":52385889},{"atl":[[440,2],[470,0]],"id":52385882},{"atl":[[540,0],[510,2]],"id":52385883},{"atl":[[270,2],[320,0]],"id":52385884},{"atl":[[480,2],[510,0]],"id":52385896},{"atl":[[620,2],[680,0]],"id":52385897},{"atl":[[620,2],[680,0]],"id":52385890},{"atl":[[420,2],[450,0]],"id":52385891},{"atl":[[550,2],[590,0]],"id":52385892},{"atl":[[70,0],[55,2]],"id":52385903},{"atl":[[290,2],[330,0]],"id":52385904},{"atl":[[380,2],[420,0]],"id":52385905},{"atl":[[630,2],[690,0]],"id":52385899}],"con":true,"img":false}]}
{"op":"mcm","clk":"11550960299","pt":1719506625564,"mc":[{"id":"1.230178177","rc":[{"atl":[[300,0],[250,2]],"id":52385906}],"con":true,"img":false}]}
{"op":"mcm","clk":"11550960344","pt":1719506626656,"mc":[{"id":"1.230178177","rc":[{"atl":[[650,0],[710,2]],"id":52385912},{"atl":[[550,0],[590,2]],"id":52385892}],"con":true,"img":false}]}
{"op":"mcm","clk":"11550960477","pt":1719506629969,"mc":[{"id":"1.230178177","rc":[{"atb":[[11,10],[12.5,0]],"id":52385912},{"atb":[[6,0],[5.4,22.73]],"id":52385913},{"atb":[[5.3,23.26],[5.9,0]],"id":52385889},{"atb":[[8.2,13.89],[9.4,0]],"id":52385883},{"atb":[[10.5,10.53],[12,8]],"id":52385897},{"atb":[[10.5,10.53],[12,0]],"id":52385890},{"atb":[[4.5,28.57],[5,0]],"id":52385904},{"atb":[[5.1,24.39],[5.7,0]],"id":52385905},{"atb":[[7.8,0],[7,16.67]],"id":52385898},{"atb":[[10.5,10.53],[12.5,0]],"id":52385899}],"con":true,"img":false}]}
{"op":"mcm","clk":"11550960485","pt":1719506630177,"mc":[{"id":"1.230178177","rc":[{"atb":[[10.5,0],[4.1,18.53]],"id":52385897}],"con":true,"img":false}]}
{"op":"mcm","clk":"11550960490","pt":1719506630281,"mc":[{"id":"1.230178177","rc":[{"atb":[[10.5,10.53],[4.1,0]],"id":52385897}],"con":true,"img":false}]}
{"op":"mcm","clk":"11550960494","pt":1719506630383,"mc":[{"id":"1.230178177","rc":[{"atl":[[510,2]],"id":52385885},{"atl":[[520,2],[510,0]],"id":52385898}],"con":true,"img":false}]}
{"op":"mcm","clk":"11550960498","pt":1719506630488,"mc":[{"id":"1.230178177","rc":[{"atl":[[610,0],[630,2]],"id":52385911},{"atl":[[500,0]],"id":52385885}],"con":true,"img":false}]}
{"op":"mcm","clk":"11550960501","pt":1719506630592,"mc":[{"id":"1.230178177","rc":[{"atl":[[440,0],[490,2]],"id":52385910},{"atl":[[420,0],[460,2]],"id":52385913},{"atl":[[410,0],[450,2]],"id":52385889},{"atl":[[440,0],[490,2]],"id":52385882},{"atl":[[550,2],[510,0]],"id":52385883},{"atl":[[270,0],[330,2]],"id":52385884},{"atl":[[520,2]],"id":52385896},{"atl":[[620,0],[710,2]],"id":52385897},{"atl":[[620,0],[710,2]],"id":52385890},{"atl":[[420,0],[470,2]],"id":52385891},{"atl":[[80,2],[55,0]],"id":52385903},{"atl":[[290,0],[340,2]],"id":52385904},{"atl":[[380,0],[430,2]],"id":52385905},{"atl":[[630,0],[720,2]],"id":52385899}],"con":true,"img":false}]}
{"op":"mcm","clk":"11550960503","pt":1719506630646,"mc":[{"id":"1.230178177","rc":[{"atl":[[320,2]],"id":52385906},{"atl":[[480,0]],"id":52385896}],"con":true,"img":false}]}
{"op":"mcm","clk":"11550960508","pt":1719506630747,"mc":[{"id":"1.230178177","rc":[{"atl":[[250,0]],"id":52385906}],"con":true,"img":false}]}
{"op":"mcm","clk":"11550960546","pt":1719506631786,"mc":[{"id":"1.230178177","rc":[{"atl":[[740,2]],"id":52385912},{"atl":[[590,0],[610,2]],"id":52385892}],"con":true,"img":false}]}
{"op":"mcm","clk":"11550960550","pt":1719506631890,"mc":[{"id":"1.230178177","rc":[{"atl":[[710,0]],"id":52385912}],"con":true,"img":false}]}
{"op":"mcm","clk":"11550962304","pt":1719506672034,"mc":[{"id":"1.230178177","rc":[{"atl":[[450,2],[490,0]],"id":52385910},{"atl":[[680,2],[740,0]],"id":52385912},{"atl":[[430,2],[460,0]],"id":52385913},{"atl":[[420,2]],"id":52385889},{"atl":[[460,2],[490,0]],"id":52385882},{"atl":[[330,0]],"id":52385884},{"atl":[[520,0]],"id":52385896},{"atl":[[650,2]],"id":52385897},{"atl":[[650,2],[710,0]],"id":52385890},{"atl":[[440,2],[470,0]],"id":52385891},{"atl":[[60,2]],"id":52385903},{"atl":[[310,2],[340,0]],"id":52385904},{"atl":[[400,2]],"id":52385905},{"atl":[[520,0],[490,2]],"id":52385898},{"atl":[[660,2]],"id":52385899}],"con":true,"img":false}]}
{"op":"mcm","clk":"11550962307","pt":1719506672137,"mc":[{"id":"1.230178177","rc":[{"atl":[[590,2],[630,0]],"id":52385911},{"atl":[[280,2],[320,0]],"id":52385906},{"atl":[[450,0]],"id":52385889},{"atl":[[530,2]],"id":52385883},{"atl":[[300,2]],"id":52385884},{"atl":[[480,2],[510,0]],"id":52385885},{"atl":[[500,2]],"id":52385896},{"atl":[[710,0]],"id":52385897},{"atl":[[570,2],[610,0]],"id":52385892},{"atl":[[80,0]],"id":52385903},{"atl":[[430,0]],"id":52385905},{"atl":[[720,0]],"id":52385899}],"con":true,"img":false}]}
{"op":"mcm","clk":"11550962312","pt":1719506672244,"mc":[{"id":"1.230178177","rc":[{"atl":[[550,0]],"id":52385883}],"con":true,"img":false}]}
{"op":"mcm","clk":"11550965043","pt":1719506732101,"mc":[{"id":"1.230178177","rc":[{"atl":[[490,2]],"id":52385910},{"atl":[[520,2],[500,0]],"id":52385896},{"atl":[[650,0],[710,2]],"id":52385897},{"atl":[[440,0],[470,2]],"id":52385891}],"con":true,"img":false}]}
{"op":"mcm","clk":"11550965049","pt":1719506732204,"mc":[{"id":"1.230178177","rc":[{"atl":[[450,0]],"id":52385910},{"atl":[[590,0],[630,2]],"id":52385911},{"atl":[[680,0],[740,2]],"id":52385912},{"atl":[[430,0],[460,2]],"id":52385913},{"atl":[[280,0],[320,2]],"id":52385906},{"atl":[[420,0],[450,2]],"id":52385889},{"atl":[[460,0],[490,2]],"id":52385882},{"atl":[[530,0],[550,2]],"id":52385883},{"atl":[[300,0],[330,2]],"id":52385884},{"atl":[[480,0],[510,2]],"id":52385885},{"atl":[[650,0],[710,2]],"id":52385890},{"atl":[[570,0],[610,2]],"id":52385892},{"atl":[[80,2],[60,0]],"id":52385903},{"atl":[[310,0],[340,2]],"id":52385904},{"atl":[[400,0],[430,2]],"id":52385905},{"atl":[[520,2],[490,0]],"id":52385898},{"atl":[[660,0],[720,2]],"id":52385899}],"con":true,"img":false}]}
{"op":"mcm","clk":"11550965891","pt":1719506751624,"mc":[{"id":"1.230178177","rc":[{"atb":[[12,0]],"id":52385910},{"atb":[[16,0]],"id":52385911},{"atb":[[15,0]],"id":52385912},{"atb":[[6,0]],"id":52385906},{"atb":[[9,0]],"id":52385889},{"atb":[[11,0]],"id":52385883},{"atb":[[11,0]],"id":52385896},{"atb":[[12,0]],"id":52385897},{"atb":[[14,0]],"id":52385890},{"atb":[[9,0]],"id":52385891},{"atb":[[14,0]],"id":52385892},{"atb":[[6,0]],"id":52385904},{"atb":[[6,0]],"id":52385905},{"atb":[[8,0]],"id":52385898},{"atb":[[14,0]],"id":52385899}],"con":true,"img":false}]}
{"op":"mcm","clk":"11550965899","pt":1719506751728,"mc":[{"id":"1.230178177","rc":[{"atb":[[2.98,50.51],[14,8]],"id":52385910},{"atb":[[20,6],[3.95,33.9],[11,0]],"id":52385911},{"atb":[[20,6],[4.2,20]],"id":52385912},{"atb":[[2.66,60.24],[7,12]],"id":52385906},{"atb":[[10,11],[2.86,53.76]],"id":52385889},{"atb":[[13,9]],"id":52385883},{"atb":[[16,9]],"id":52385896},{"atb":[[18,8],[4.1,21.06]],"id":52385897},{"atb":[[20,7],[10.5,0]],"id":52385890},{"atb":[[10,11]],"id":52385891},{"atb":[[18,7]],"id":52385892},{"atb":[[7,12]],"id":52385904},{"atb":[[8,12],[5.1,0]],"id":52385905},{"atb":[[11,12]],"id":52385898},{"atb":[[20,7]],"id":52385899}],"con":true,"img":false}]}
{"op":"mcm","clk":"11550965907","pt":1719506751832,"mc":[{"id":"1.230178177","rc":[{"atb":[[6.6,0]],"id":52385910},{"atb":[[11,0]],"id":52385912},{"atb":[[4.7,0]],"id":52385906},{"atb":[[5.3,0]],"id":52385889},{"atb":[[3.55,27.78]],"id":52385883},{"atb":[[3.25,44.44]],"id":52385896},{"atb":[[10.5,0]],"id":52385897},{"atb":[[4.1,32.26]],"id":52385890},{"atb":[[2.9,52.63],[6,0]],"id":52385891},{"atb":[[3.85,35.09],[10,0]],"id":52385892},{"atb":[[4.5,0],[2.7,58.82]],"id":52385904},{"atb":[[2.82,54.95]],"id":52385905},{"atb":[[3.25,44.44],[7,0]],"id":52385898},{"atb":[[10.5,0],[4.1,32.26]],"id":52385899}],"con":true,"img":false}]}
{"op":"mcm","clk":"11550965910","pt":1719506751936,"mc":[{"id":"1.230178177","rc":[{"atb":[[9,0]],"id":52385913},{"atb":[[8.2,0]],"id":52385883},{"atb":[[7.6,0]],"id":52385896}],"con":true,"img":false}]}
{"op":"mcm","clk":"11550965914","pt":1719506752042,"mc":[{"id":"1.230178177","rc":[{"atb":[[2.88,53.19],[10,11],[5.4,0]],"id":52385913},{"atb":[[2.9,0],[5.5,22.22]],"id":52385891}],"con":true,"img":false}]}
{"op":"mcm","clk":"11550966273","pt":1719506758945,"mc":[{"id":"1.230178177","rc":[{"atb":[[2.98,0],[5.9,20.41]],"id":52385910},{"atb":[[3.95,0],[9.8,11.36]],"id":52385911},{"atb":[[11,10],[4.2,0]],"id":52385912},{"atb":[[4.3,30.3],[2.66,0]],"id":52385906},{"atb":[[2.86,0],[5.3,23.26]],"id":52385889},{"atb":[[10.5,10.53]],"id":52385897}],"con":true,"img":false}]}
{"op":"mcm","clk":"11550966278","pt":1719506759048,"mc":[{"id":"1.230178177","rc":[{"atb":[[8.2,13.89],[3.55,0]],"id":52385883},{"atb":[[3.25,0],[7,16.67]],"id":52385896},{"atb":[[4.1,0]],"id":52385897},{"atb":[[10.5,10.53],[4.1,0]],"id":52385890},{"atb":[[3.85,0],[9.4,11.9]],"id":52385892},{"atb":[[4.5,28.57],[2.7,0]],"id":52385904},{"atb":[[2.82,0],[5.1,24.39]],"id":52385905},{"atb":[[3.25,0],[7,16.67]],"id":52385898},{"atb":[[10.5,10.53],[4.1,0]],"id":52385899}],"con":true,"img":false}]}
{"op":"mcm","clk":"11550966290","pt":1719506759255,"mc":[{"id":"1.230178177","rc":[{"atb":[[2.88,0],[5.4,22.73]],"id":52385913}],"con":true,"img":false}]}
{"op":"mcm","clk":"11550966296","pt":1719506759317,"mc":[{"id":"1.230178177","rc":[{"atb":[[6.8,5]],"id":52385906}],"con":true,"img":false}]}
{"op":"mcm","clk":"11550966316","pt":1719506759620,"mc":[{"id":"1.230178177","rc":[{"atb":[[6.8,0]],"id":52385906}],"con":true,"img":false}]}
{"op":"mcm","clk":"11550966364","pt":1719506760657,"mc":[{"id":"1.230178177","rc":[{"atb":[[3.05,0]],"id":52385910},{"atb":[[3.05,0]],"id":52385911},{"atb":[[3.05,0]],"id":52385912},{"atb":[[3.05,0]],"id":52385913},{"atb":[[3.05,0]],"id":52385906},{"atb":[[1.31,100],[3.05,0]],"id":52385889},{"atb":[[9,0],[1.31,100],[3.05,0]],"id":52385882},{"atb":[[1.31,100],[3.05,0]],"id":52385883},{"atb":[[8,0],[1.31,100],[3.05,0]],"id":52385884},{"atb":[[13,0],[1.31,100],[3.05,0]],"id":52385885},{"atb":[[3.05,0]],"id":52385896},{"atb":[[3.05,0]],"id":52385897},{"atb":[[1.31,100],[3.05,0]],"id":52385890},{"atb":[[3.05,0]],"id":52385891},{"atb":[[3.05,0]],"id":52385892},{"atb":[[5,0],[3.05,0]],"id":52385903},{"atb":[[3.05,0]],"id":52385904},{"atb":[[3.05,0]],"id":52385905},{"atb":[[3.05,0]],"id":52385898},{"atb":[[3.05,0]],"id":52385899}],"con":true,"img":false}]}
{"op":"mcm","clk":"11550966372","pt":1719506760763,"mc":[{"id":"1.230178177","rc":[{"atb":[[1.31,100]],"id":52385910},{"atb":[[1.31,100]],"id":52385911},{"atb":[[1.31,100]],"id":52385912},{"atb":[[1.31,100]],"id":52385906},{"atb":[[2.98,50.51],[6.6,0],[7,11]],"id":52385882},{"atb":[[6,11],[4.9,0],[2.68,59.52]],"id":52385884},{"atb":[[9,8],[7.4,0],[3.15,46.51]],"id":52385885},{"atb":[[1.31,100]],"id":52385896},{"atb":[[1.31,100]],"id":52385897},{"atb":[[1.31,100]],"id":52385891},{"atb":[[4,12],[2.24,80.65],[3.15,0],[1.31,100]],"id":52385903},{"atb":[[1.31,100]],"id":52385904},{"atb":[[1.31,100]],"id":52385905},{"atb":[[1.31,100]],"id":52385898},{"atb":[[1.31,100]],"id":52385899}],"con":true,"img":false}]}
{"op":"mcm","clk":"11550966385","pt":1719506760922,"mc":[{"id":"1.230178177","rc":[{"atb":[[1.31,100]],"id":52385892}],"con":true,"img":false}]}
{"op":"mcm","clk":"11550966397","pt":1719506761136,"mc":[{"id":"1.230178177","rc":[{"atb":[[1.31,100]],"id":52385913}],"con":true,"img":false}]}
{"op":"mcm","clk":"11550966419","pt":1719506761747,"mc":[{"id":"1.230178177","rc":[{"atb":[[14,0]],"id":52385910},{"atb":[[10,0]],"id":52385889},{"atb":[[13,0]],"id":52385883},{"atb":[[16,0]],"id":52385896}],"con":true,"img":false}]}
{"op":"mcm","clk":"11550966425","pt":1719506761851,"mc":[{"id":"1.230178177","rc":[{"atb":[[12,8],[2.98,50.51]],"id":52385910},{"atb":[[9,11]],"id":52385889},{"atb":[[9,9]],"id":52385883},{"atb":[[3.25,44.44],[14,9]],"id":52385896}],"con":true,"img":false}]}
{"op":"mcm","clk":"11550966431","pt":1719506761960,"mc":[{"id":"1.230178177","rc":[{"atb":[[5.9,0]],"id":52385910},{"atb":[[2.86,53.76],[5.3,0]],"id":52385889},{"atb":[[8.2,0],[3.55,39.22]],"id":52385883},{"atb":[[7,0]],"id":52385896}],"con":true,"img":false}]}
{"op":"mcm","clk":"11550966439","pt":1719506762020,"mc":[{"id":"1.230178177","rc":[{"atb":[[5.9,20.41]],"id":52385910},{"atb":[[3.25,0],[7,16.67]],"id":52385896}],"con":true,"img":false}]}
{"op":"mcm","clk":"11550966446","pt":1719506762126,"mc":[{"id":"1.230178177","rc":[{"atb":[[2.98,0]],"id":52385910}],"con":true,"img":false}]}
{"op":"mcm","clk":"11550966458","pt":1719506762432,"mc":[{"id":"1.230178177","rc":[{"atl":[[440,2]],"id":52385891}],"con":true,"img":false}]}
{"op":"mcm","clk":"11550966474","pt":1719506762749,"mc":[{"id":"1.230178177","rc":[{"atl":[[450,2],[490,0]],"id":52385910},{"atl":[[590,2],[630,0]],"id":52385911},{"atl":[[680,2],[740,0]],"id":52385912},{"atl":[[430,2],[460,0]],"id":52385913},{"atl":[[280,2],[320,0]],"id":52385906},{"atl":[[420,2],[450,0]],"id":52385889},{"atl":[[460,2],[490,0]],"id":52385882},{"atl":[[530,2],[550,0]],"id":52385883},{"atl":[[300,2],[330,0]],"id":52385884},{"atl":[[480,2],[510,0]],"id":52385885},{"atl":[[520,0],[500,2]],"id":52385896},{"atl":[[650,2],[710,0]],"id":52385897},{"atl":[[650,2],[710,0]],"id":52385890},{"atl":[[470,0]],"id":52385891},{"atl":[[570,2],[610,0]],"id":52385892},{"atl":[[80,0],[60,2]],"id":52385903},{"atl":[[310,2],[340,0]],"id":52385904},{"atl":[[400,2],[430,0]],"id":52385905},{"atl":[[520,0],[490,2]],"id":52385898},{"atl":[[660,2],[720,0]],"id":52385899}],"con":true,"img":false}]}
{"op":"mcm","clk":"11550966546","pt":1719506764248,"mc":[{"id":"1.230178177","rc":[{"atb":[[1.3,3.72]],"id":52385883}],"con":true,"img":false}]}
{"op":"mcm","clk":"11550966556","pt":1719506764453,"mc":[{"id":"1.230178177","rc":[{"atb":[[1.3,0]],"id":52385883}],"con":true,"img":false}]}
{"op":"mcm","clk":"11550966751","pt":1719506767872,"mc":[{"id":"1.230178177","rc":[{"atb":[[2.98,0],[5.9,20.41]],"id":52385882},{"atb":[[4.4,29.41]],"id":52385884},{"atb":[[3.15,0],[6.6,17.86]],"id":52385885},{"atb":[[3.1,47.62]],"id":52385903}],"con":true,"img":false}]}
{"op":"mcm","clk":"11550966757","pt":1719506767974,"mc":[{"id":"1.230178177","rc":[{"atb":[[2.68,0]],"id":52385884},{"atb":[[2.24,0]],"id":52385903}],"con":true,"img":false}]}
{"op":"mcm","clk":"11550966812","pt":1719506769062,"mc":[{"id":"1.230178177","rc":[{"atb":[[2.86,0],[5.3,23.26]],"id":52385889},{"atb":[[8.2,13.89],[3.55,0]],"id":52385883}],"con":true,"img":false}]}
{"op":"mcm","clk":"11550967264","pt":1719506777573,"mc":[{"id":"1.230178177","rc":[{"atb":[[4,2]],"id":52385910},{"atb":[[4,2]],"id":52385911},{"atb":[[4,2]],"id":52385912},{"atb":[[4,2]],"id":52385913},{"atb":[[4,2]],"id":52385906},{"atb":[[4,2]],"id":52385889},{"atb":[[4,2]],"id":52385882},{"atb":[[4,2]],"id":52385883},{"atb":[[4,2]],"id":52385884},{"atb":[[4,2]],"id":52385885},{"atb":[[4,2]],"id":52385896},{"atb":[[4,2]],"id":52385897},{"atb":[[4,2]],"id":52385890},{"atb":[[4,2]],"id":52385891},{"atb":[[4,2]],"id":52385892},{"atb":[[4,14]],"id":52385903},{"atb":[[4,2]],"id":52385904},{"atb":[[4,2]],"id":52385905},{"atb":[[4,2]],"id":52385898},{"atb":[[4,2]],"id":52385899}],"con":true,"img":false}]}
{"op":"mcm","clk":"11550968443","pt":1719506799038,"mc":[{"id":"1.230178177","rc":[{"atl":[[450,0],[490,2]],"id":52385910},{"atl":[[590,0],[630,2]],"id":52385911},{"atl":[[680,0],[740,2]],"id":52385912},{"atl":[[430,0],[460,2]],"id":52385913},{"atl":[[280,0],[320,2]],"id":52385906},{"atl":[[420,0],[450,2]],"id":52385889},{"atl":[[460,0],[490,2]],"id":52385882},{"atl":[[530,0],[550,2]],"id":52385883},{"atl":[[300,0],[330,2]],"id":52385884},{"atl":[[480,0],[510,2]],"id":52385885},{"atl":[[520,2],[500,0]],"id":52385896},{"atl":[[650,0],[710,2]],"id":52385897},{"atl":[[650,0],[710,2]],"id":52385890},{"atl":[[440,0],[470,2]],"id":52385891},{"atl":[[570,0],[610,2]],"id":52385892},{"atl":[[80,2],[60,0]],"id":52385903},{"atl":[[310,0],[340,2]],"id":52385904},{"atl":[[400,0],[430,2]],"id":52385905},{"atl":[[520,2],[490,0]],"id":52385898},{"atl":[[660,0],[720,2]],"id":52385899}],"con":true,"img":false}]}
{"op":"mcm","clk":"11550968456","pt":1719506799243,"mc":[{"id":"1.230178177","rc":[{"atb":[[9,5],[6.8,17.24],[12.5,8],[9.8,2.5]],"id":52385910},{"atl":[[42,2.5],[50,5],[490,0],[480,2],[960,0.63]],"id":52385910},{"atb":[[21,8],[12,5],[14,2.5]],"id":52385911},{"atl":[[75,2.5],[95,5],[960,0.63]],"id":52385911},{"atb":[[32,2.5],[21,8],[11,0],[13,8.33],[27,5]],"id":52385912},{"atl":[[150,5],[720,2],[740,0],[110,2.5],[970,0.62]],"id":52385912},{"atb":[[10.5,8],[7.6,5],[6,20],[8.4,2.5],[5.4,0]],"id":52385913},{"atl":[[34,5],[28,2.5],[960,0.63]],"id":52385913},{"atb":[[4.5,2.5],[4.1,5],[7,20]],"id":52385906},{"atl":[[17.5,5],[290,2],[320,0],[980,0.61],[15.5,2.5]],"id":52385906},{"atb":[[10,2.5],[9.2,13],[6,20]],"id":52385889},{"atl":[[42,2.5],[50,5],[950,0.63]],"id":52385889},{"atb":[[7.2,8],[9.2,2.5],[6,20],[5.9,0],[8.4,5]],"id":52385882},{"atl":[[36,2.5],[44,5],[490,0],[480,2],[970,0.62]],"id":52385882},{"atb":[[16,5],[18,2.5],[9.2,8],[8.2,0],[8.4,13.51]],"id":52385883},{"atl":[[540,2],[550,0],[70,2.5],[90,5],[980,0.61]],"id":52385883},{"atb":[[4.8,26.32],[4.5,2.5],[6.2,8],[4.1,5],[4.4,0]],"id":52385884},{"atl":[[18,2.5],[20,5],[980,0.61]],"id":52385884},{"atb":[[9.6,5],[9.2,8],[11,2.5],[7.6,15.15]],"id":52385885},{"atl":[[44,2.5],[55,5],[980,0.61]],"id":52385885},{"atb":[[10.5,5],[8.2,13.89],[12.5,2.5],[7,0],[14.5,8.02]],"id":52385896},{"atl":[[130,2.5],[170,5],[960,0.63]],"id":52385896},{"atb":[[18.5,8],[12.5,8.7],[26,5],[30,2.5]],"id":52385897},{"atl":[[160,2.5],[200,5],[960,0.63]],"id":52385897},{"atb":[[10.5,0],[21,8],[24,5],[12.5,8.7],[28,2.5]],"id":52385890},{"atl":[[140,5],[100,2.5],[960,0.63]],"id":52385890},{"atb":[[10.5,8],[5.5,0],[6,20],[7.8,2.5],[7,5]],"id":52385891},{"atl":[[32,2.5],[40,5],[950,0.63]],"id":52385891},{"atb":[[16.5,2.5],[18.5,8],[11,10],[14.5,5],[9.4,0]],"id":52385892},{"atl":[[75,2.5],[95,5],[980,0.61]],"id":52385892},{"atb":[[4,46],[2.82,5],[2.9,2.5],[3.1,0],[3.25,44.44]],"id":52385903},{"atl":[[9.6,2.5],[11,5],[950,0.63]],"id":52385903},{"atb":[[7.2,8],[3.9,5],[4.2,2.5]],"id":52385904},{"atl":[[17.5,2.5],[19.5,5],[320,2],[340,0],[950,0.63]],"id":52385904},{"atb":[[5.6,21.74],[5.1,0],[8.2,8],[7.4,2.5],[6.6,5]],"id":52385905},{"atl":[[26,2.5],[30,5],[960,0.63]],"id":52385905},{"atb":[[11,17],[11.5,8],[13,2.5],[7,0],[7.8,14.71]],"id":52385898},{"atl":[[520,0],[75,2.5],[95,5],[960,0.63],[510,2]],"id":52385898},{"atb":[[34,2.5],[21,8],[12.5,8.7],[28,5]],"id":52385899},{"atl":[[170,2.5],[700,2],[720,0],[210,5],[980,0.61]],"id":52385899}],"con":true,"img":false}]}
{"op":"mcm","clk":"11550968463","pt":1719506799300,"mc":[{"id":"1.230178177","rc":[{"atb":[[5.9,0]],"id":52385910},{"atb":[[5.3,0]],"id":52385889},{"atb":[[6.6,0]],"id":52385885},{"atb":[[10.5,0]],"id":52385897},{"atb":[[10.5,0]],"id":52385899}],"con":true,"img":false}]}
{"op":"mcm","clk":"11550968469","pt":1719506799402,"mc":[{"id":"1.230178177","rc":[{"atl":[[450,2],[480,0]],"id":52385910},{"atl":[[680,2],[720,0]],"id":52385912},{"atb":[[6,0],[6.8,17.24]],"id":52385882},{"atl":[[460,2],[480,0]],"id":52385882},{"atb":[[9.2,17],[8.4,0]],"id":52385883},{"atl":[[520,0],[500,2]],"id":52385896},{"atl":[[490,2],[510,0]],"id":52385898},{"atl":[[660,2],[700,0]],"id":52385899}],"con":true,"img":false}]}
{"op":"mcm","clk":"11550968485","pt":1719506799715,"mc":[{"id":"1.230178177","rc":[{"atb":[[7,0]],"id":52385882}],"con":true,"img":false}]}
{"op":"mcm","clk":"11550968497","pt":1719506800028,"mc":[{"id":"1.230178177","rc":[{"atb":[[9,0]],"id":52385883}],"con":true,"img":false}]}
{"op":"mcm","clk":"11550968503","pt":1719506800190,"mc":[{"id":"1.230178177","rc":[{"atl":[[240,2]],"id":52385906},{"atb":[[9,0]],"id":52385885}],"con":true,"img":false}]}
{"op":"mcm","clk":"11550968508","pt":1719506800293,"mc":[{"id":"1.230178177","rc":[{"atl":[[290,0]],"id":52385906}],"con":true,"img":false}]}
{"op":"mcm","clk":"11550968513","pt":1719506800397,"mc":[{"id":"1.230178177","rc":[{"atb":[[20,0]],"id":52385890}],"con":true,"img":false}]}
{"op":"mcm","clk":"11550968524","pt":1719506800602,"mc":[{"id":"1.230178177","rc":[{"atb":[[18,0]],"id":52385897}],"con":true,"img":false}]}
{"op":"mcm","clk":"11550968536","pt":1719506800911,"mc":[{"id":"1.230178177","rc":[{"atb":[[20,0]],"id":52385899}],"con":true,"img":false}]}
{"op":"mcm","clk":"11550968550","pt":1719506801219,"mc":[{"id":"1.230178177","rc":[{"atb":[[20,0]],"id":52385912}],"con":true,"img":false}]}
{"op":"mcm","clk":"11550968566","pt":1719506801484,"mc":[{"id":"1.230178177","rc":[{"atb":[[12,0]],"id":52385910},{"atb":[[10,0]],"id":52385913},{"atb":[[9,0]],"id":52385889},{"atb":[[6,0]],"id":52385884},{"atb":[[10,0]],"id":52385891},{"atb":[[18,0]],"id":52385892}],"con":true,"img":false}]}
{"op":"mcm","clk":"11550968573","pt":1719506801589,"mc":[{"id":"1.230178177","rc":[{"atb":[[15,8]],"id":52385910},{"atb":[[12,11]],"id":52385913},{"atb":[[11,11]],"id":52385889},{"atb":[[7,11]],"id":52385884},{"atb":[[12,11]],"id":52385891},{"atb":[[20,7]],"id":52385892}],"con":true,"img":false}]}
{"op":"mcm","clk":"11550968585","pt":1719506801798,"mc":[{"id":"1.230178177","rc":[{"atb":[[13,8]],"id":52385885}],"con":true,"img":false}]}
{"op":"mcm","clk":"11550968632","pt":1719506802728,"mc":[{"id":"1.230178177","rc":[{"atb":[[8,0]],"id":52385905}],"con":true,"img":false}]}
{"op":"mcm","clk":"11550968643","pt":1719506802889,"mc":[{"id":"1.230178177","rc":[{"atb":[[14,0]],"id":52385896}],"con":true,"img":false}]}
{"op":"mcm","clk":"11550968647","pt":1719506802992,"mc":[{"id":"1.230178177","rc":[{"atb":[[16,9]],"id":52385896}],"con":true,"img":false}]}
{"op":"mcm","clk":"11550968652","pt":1719506803097,"mc":[{"id":"1.230178177","rc":[{"atb":[[16.5,15],[14.5,0]],"id":52385896}],"con":true,"img":false}]}
{"op":"mcm","clk":"11550968694","pt":1719506804131,"mc":[{"id":"1.230178177","rc":[{"atl":[[380,2],[450,0]],"id":52385910},{"atb":[[12.5,8.7]],"id":52385911},{"atb":[[1.3,200],[13,0]],"id":52385912},{"atb":[[7,12]],"id":52385906},{"atb":[[7.2,16.13],[6,0]],"id":52385889},{"atb":[[6.8,0]],"id":52385882},{"atl":[[460,0]],"id":52385882},{"atb":[[9.2,8]],"id":52385883},{"atl":[[70,0],[120,5]],"id":52385883},{"atb":[[4.8,0],[3.75,36.36]],"id":52385884},{"atb":[[9,12.5],[7.6,0]],"id":52385885},{"atb":[[8.2,0]],"id":52385896},{"atb":[[12.5,0]],"id":52385897},{"atb":[[12.5,0]],"id":52385890},{"atl":[[180,5],[100,0]],"id":52385890},{"atb":[[6,0],[7,21]],"id":52385891},{"atb":[[11,0],[13.5,8]],"id":52385892},{"atb":[[3.25,0],[3.5,40]],"id":52385903},{"atb":[[4.5,0]],"id":52385904},{"atl":[[320,0],[230,2]],"id":52385904},{"atb":[[5.6,0]],"id":52385905},{"atl":[[38,2.5],[46,5],[26,0],[30,0]],"id":52385905},{"atb":[[7.8,0]],"id":52385898},{"atl":[[140,5],[75,0],[95,0],[100,2.5]],"id":52385898},{"atb":[[12.5,0]],"id":52385899}],"con":true,"img":false}]}
{"op":"mcm","clk":"11550968698","pt":1719506804194,"mc":[{"id":"1.230178177","rc":[{"atb":[[9.8,0]],"id":52385911},{"atb":[[7.2,16]],"id":52385882},{"atl":[[400,2]],"id":52385882},{"atl":[[540,0],[150,2]],"id":52385883},{"atb":[[5.2,20]],"id":52385904}],"con":true,"img":false}]}
{"op":"mcm","clk":"11550968749","pt":1719506805833,"mc":[{"id":"1.230178177","rc":[{"atl":[[530,2],[630,0]],"id":52385911},{"atl":[[360,2],[460,0]],"id":52385913},{"atl":[[400,2],[450,0]],"id":52385889},{"atl":[[450,2],[510,0]],"id":52385885},{"atl":[[420,2],[470,0]],"id":52385891},{"atl":[[540,2],[610,0]],"id":52385892},{"atl":[[80,0],[40,2.56]],"id":52385903}],"con":true,"img":false}]}
{"op":"mcm","clk":"11550968796","pt":1719506806935,"mc":[{"id":"1.230178177","rc":[{"atl":[[160,2],[240,0]],"id":52385906}],"con":true,"img":false}]}
{"op":"mcm","clk":"11550968923","pt":1719506809338,"mc":[{"id":"1.230178177","rc":[{"atl":[[150,0],[190,2]],"id":52385883}],"con":true,"img":false}]}
{"op":"mcm","clk":"11550968993","pt":1719506810799,"mc":[{"id":"1.230178177","rc":[{"atb":[[6.2,19.23]],"id":52385912},{"atb":[[4.7,19]],"id":52385884}],"con":true,"img":false}]}
{"op":"mcm","clk":"11550968996","pt":1719506810905,"mc":[{"id":"1.230178177","rc":[{"atb":[[1.3,0]],"id":52385912},{"atb":[[3.75,0]],"id":52385884}],"con":true,"img":false}]}
{"op":"mcm","clk":"11550969100","pt":1719506813652,"mc":[{"id":"1.230178177","rc":[{"atb":[[15,23]],"id":52385910},{"atl":[[40,15]],"id":52385910},{"atb":[[30,15]],"id":52385911},{"atl":[[70,8.7]],"id":52385911},{"atb":[[36,15]],"id":52385912},{"atl":[[100,6.06]],"id":52385912},{"atb":[[12,26]],"id":52385913},{"atl":[[23,15]],"id":52385913},{"atl":[[11.5,15]],"id":52385906},{"atb":[[12.5,15]],"id":52385889},{"atl":[[32,15]],"id":52385889},{"atb":[[14,15]],"id":52385882},{"atl":[[29,15]],"id":52385882},{"atb":[[18.5,20]],"id":52385883},{"atl":[[65,9.38]],"id":52385883},{"atb":[[7.8,26]],"id":52385884},{"atl":[[17.5,26]],"id":52385884},{"atb":[[19,15]],"id":52385885},{"atl":[[42,14.63]],"id":52385885},{"atb":[[29,15]],"id":52385896},{"atl":[[120,5.04]],"id":52385896},{"atb":[[32,15]],"id":52385897},{"atl":[[150,4.03]],"id":52385897},{"atb":[[30,20]],"id":52385890},{"atl":[[130,4.65]],"id":52385890},{"atb":[[13,15]],"id":52385891},{"atl":[[30,15]],"id":52385891},{"atb":[[29,15]],"id":52385892},{"atl":[[70,8.7]],"id":52385892},{"atl":[[8,15.12]],"id":52385903},{"atl":[[14,26]],"id":52385904},{"atb":[[10,15]],"id":52385905},{"atl":[[36,15]],"id":52385905},{"atb":[[14.5,15]],"id":52385898},{"atl":[[95,6.38]],"id":52385898},{"atb":[[36,15]],"id":52385899},{"atl":[[160,3.77]],"id":52385899}],"con":true,"img":false}]}
{"op":"mcm","clk":"11550969105","pt":1719506813757,"mc":[{"id":"1.230178177","rc":[{"atb":[[12.5,0]],"id":52385910},{"atl":[[380,0],[960,0],[60,2]],"id":52385910},{"atb":[[21,0],[30,0]],"id":52385911},{"atl":[[530,0],[130,2],[960,0]],"id":52385911},{"atl":[[290,2],[680,0],[970,0]],"id":52385912},{"atb":[[10.5,0]],"id":52385913},{"atl":[[42,2.44],[360,0],[960,0]],"id":52385913},{"atl":[[18,5.88],[160,0],[980,0]],"id":52385906},{"atb":[[9.2,5]],"id":52385889},{"atl":[[50,7.04],[400,0],[950,0]],"id":52385889},{"atb":[[7.2,0],[7.6,15.15]],"id":52385882},{"atl":[[65,2],[400,0],[29,0],[970,0]],"id":52385882},{"atb":[[9.2,0]],"id":52385883},{"atl":[[980,0]],"id":52385883},{"atb":[[6.2,0]],"id":52385884},{"atl":[[32,3.23],[330,0],[980,0]],"id":52385884},{"atb":[[9.2,0]],"id":52385885},{"atl":[[75,2],[450,0],[980,0]],"id":52385885},{"atb":[[16.5,0]],"id":52385896},{"atl":[[220,2],[960,0],[500,0]],"id":52385896},{"atb":[[18.5,0]],"id":52385897},{"atl":[[710,0],[370,2],[960,0]],"id":52385897},{"atl":[[320,2],[710,0],[960,0]],"id":52385890},{"atb":[[10.5,0]],"id":52385891},{"atl":[[420,0],[950,0],[60,2]],"id":52385891},{"atb":[[18.5,0],[29,0]],"id":52385892},{"atl":[[140,2],[980,0]],"id":52385892},{"atl":[[9,12.5],[40,0]],"id":52385903},{"atb":[[7.4,40]],"id":52385904},{"atl":[[22,4.76],[230,0],[950,0]],"id":52385904},{"atb":[[8.2,0]],"id":52385905},{"atl":[[70,2],[430,0],[960,0]],"id":52385905},{"atb":[[11.5,0]],"id":52385898},{"atl":[[230,2],[490,0],[960,0]],"id":52385898},{"atb":[[21,0]],"id":52385899},{"atl":[[660,0],[370,2],[980,0]],"id":52385899}],"con":true,"img":false}]}
{"op":"mcm","clk":"11550969107","pt":1719506813822,"mc":[{"id":"1.230178177","rc":[{"atb":[[21,0]],"id":52385912},{"atb":[[21,0]],"id":52385890},{"atl":[[540,0]],"id":52385892},{"atl":[[950,0]],"id":52385903}],"con":true,"img":false}]}
{"op":"mcm","clk":"11550969111","pt":1719506813921,"mc":[{"id":"1.230178177","rc":[{"atb":[[23,27.27]],"id":52385911},{"atl":[[34,18.18]],"id":52385882},{"atb":[[22,28.57]],"id":52385892},{"atl":[[9,0],[11,15]],"id":52385903}],"con":true,"img":false}]}
{"op":"mcm","clk":"11550969117","pt":1719506814024,"mc":[{"id":"1.230178177","rc":[{"atb":[[7.2,0]],"id":52385904}],"con":true,"img":false}]}
{"op":"mcm","clk":"11550969150","pt":1719506814855,"mc":[{"id":"1.230178177","rc":[{"atb":[[13,0]],"id":52385885}],"con":true,"img":false}]}
{"op":"mcm","clk":"11550969161","pt":1719506815014,"mc":[{"id":"1.230178177","rc":[{"atb":[[15,15]],"id":52385910},{"atb":[[11,0]],"id":52385889},{"atb":[[7,0]],"id":52385884},{"atb":[[16,0]],"id":52385896}],"con":true,"img":false}]}
{"op":"mcm","clk":"11550969165","pt":1719506815113,"mc":[{"id":"1.230178177","rc":[{"atb":[[14,8]],"id":52385910},{"atb":[[10,13.5]],"id":52385889},{"atb":[[6,11]],"id":52385884},{"atb":[[14,9]],"id":52385896}],"con":true,"img":false}]}
{"op":"mcm","clk":"11550969286","pt":1719506817342,"mc":[{"id":"1.230178177","rc":[{"atb":[[30,20.08]],"id":52385896}],"con":true,"img":false}]}
{"op":"mcm","clk":"11550969298","pt":1719506817541,"mc":[{"id":"1.230178177","rc":[{"atb":[[29,0]],"id":52385896}],"con":true,"img":false}]}
{"op":"mcm","clk":"11550969645","pt":1719506825025,"mc":[{"id":"1.230178177","rc":[{"atb":[[6.2,0]],"id":52385912},{"atl":[[140,2.5],[150,0],[180,5],[110,0]],"id":52385912},{"atb":[[5.7,21.28],[4.7,0]],"id":52385884},{"atl":[[32,0],[26,4]],"id":52385884},{"atb":[[19,0]],"id":52385885},{"atl":[[160,0],[240,5]],"id":52385897},{"atb":[[4,14]],"id":52385903},{"atl":[[170,0],[200,2.5],[210,0],[240,5]],"id":52385899}],"con":true,"img":false}]}
{"op":"mcm","clk":"11550969651","pt":1719506825127,"mc":[{"id":"1.230178177","rc":[{"atb":[[18.5,20]],"id":52385885}],"con":true,"img":false}]}
{"op":"mcm","clk":"11550969656","pt":1719506825232,"mc":[{"id":"1.230178177","rc":[{"atl":[[150,0]],"id":52385897}],"con":true,"img":false}]}
{"op":"mcm","clk":"11550969662","pt":1719506825337,"mc":[{"id":"1.230178177","rc":[{"atl":[[100,0]],"id":52385912},{"atl":[[160,3.77]],"id":52385897},{"atl":[[160,0]],"id":52385899}],"con":true,"img":false}]}
{"op":"mcm","clk":"11550969668","pt":1719506825437,"mc":[{"id":"1.230178177","rc":[{"atl":[[110,5.5]],"id":52385912},{"atl":[[170,3.55]],"id":52385899}],"con":true,"img":false}]}
{"op":"mcm","clk":"11550969691","pt":1719506825750,"mc":[{"id":"1.230178177","rc":[{"atb":[[14,0]],"id":52385910},{"atl":[[110,0]],"id":52385912},{"atb":[[10,2.5]],"id":52385889},{"atb":[[6,0]],"id":52385884},{"atb":[[14,0]],"id":52385896},{"atl":[[160,0]],"id":52385897},{"atl":[[170,0]],"id":52385899}],"con":true,"img":false}]}
{"op":"mcm","clk":"11550969699","pt":1719506825854,"mc":[{"id":"1.230178177","rc":[{"atb":[[16,8]],"id":52385910},{"atb":[[11,11]],"id":52385889},{"atb":[[8,11]],"id":52385884},{"atb":[[16,9]],"id":52385896},{"atl":[[180,3.35]],"id":52385897},{"atl":[[210,2.87]],"id":52385899}],"con":true,"img":false}]}
{"op":"mcm","clk":"11550969704","pt":1719506825957,"mc":[{"id":"1.230178177","rc":[{"atl":[[150,4.03]],"id":52385912}],"con":true,"img":false}]}
{"op":"mcm","clk":"11550969711","pt":1719506826061,"mc":[{"id":"1.230178177","rc":[{"atl":[[180,0]],"id":52385897}],"con":true,"img":false}]}
{"op":"mcm","clk":"11550969716","pt":1719506826165,"mc":[{"id":"1.230178177","rc":[{"atl":[[190,3.17]],"id":52385897}],"con":true,"img":false}]}
{"op":"mcm","clk":"11550969778","pt":1719506827626,"mc":[{"id":"1.230178177","rc":[{"atl":[[11,34]],"id":52385906},{"atl":[[26,20]],"id":52385882},{"atb":[[19,20]],"id":52385883},{"atb":[[8,75.56]],"id":52385884},{"atl":[[14.5,44.44]],"id":52385884},{"atl":[[29,20]],"id":52385885},{"atb":[[15,22.76]],"id":52385898},{"atl":[[190,3.17]],"id":52385899}],"con":true,"img":false}]}
{"op":"mcm","clk":"11550969785","pt":1719506827728,"mc":[{"id":"1.230178177","rc":[{"atb":[[30,20.69]],"id":52385911},{"atl":[[130,4.65]],"id":52385912},{"atb":[[32,19.35]],"id":52385890},{"atb":[[30,20.69]],"id":52385892},{"atb":[[4,72]],"id":52385903},{"atb":[[10.5,20]],"id":52385905},{"atl":[[85,7.14]],"id":52385898}],"con":true,"img":false}]}
{"op":"mcm","clk":"11550969792","pt":1719506827830,"mc":[{"id":"1.230178177","rc":[{"atl":[[11.5,0]],"id":52385906},{"atl":[[34,0]],"id":52385882},{"atb":[[18.5,0]],"id":52385883},{"atb":[[7.8,0]],"id":52385884},{"atl":[[17.5,0]],"id":52385884},{"atl":[[42,0]],"id":52385885},{"atb":[[22,0]],"id":52385892},{"atb":[[2.9,55.13]],"id":52385903},{"atb":[[14.5,0]],"id":52385898},{"atl":[[95,0]],"id":52385898},{"atl":[[210,0]],"id":52385899}],"con":true,"img":false}]}
{"op":"mcm","clk":"11550969799","pt":1719506827936,"mc":[{"id":"1.230178177","rc":[{"atb":[[23,0]],"id":52385911},{"atl":[[150,0]],"id":52385912},{"atb":[[30,0]],"id":52385890},{"atb":[[3.5,0]],"id":52385903},{"atb":[[10,0]],"id":52385905}],"con":true,"img":false}]}
{"op":"mcm","clk":"11550969874","pt":1719506829446,"mc":[{"id":"1.230178177","rc":[{"atb":[[19,0]],"id":52385883},{"atb":[[18.5,0]],"id":52385885}],"con":true,"img":false}]}
{"op":"mcm","clk":"11550969877","pt":1719506829549,"mc":[{"id":"1.230178177","rc":[{"atb":[[10.5,15]],"id":52385885}],"con":true,"img":false}]}
{"op":"mcm","clk":"11550969880","pt":1719506829651,"mc":[{"id":"1.230178177","rc":[{"atb":[[18,22.5]],"id":52385883}],"con":true,"img":false}]}
{"op":"mcm","clk":"11550969886","pt":1719506829756,"mc":[{"id":"1.230178177","rc":[{"atb":[[14,7]],"id":52385885}],"con":true,"img":false}]}
{"op":"mcm","clk":"11550969925","pt":1719506830743,"mc":[{"id":"1.230178177","rc":[{"atl":[[140,0],[160,2.5],[180,0],[200,5]],"id":52385890},{"atb":[[4,14]],"id":52385903}],"con":true,"img":false}]}
{"op":"mcm","clk":"11550969930","pt":1719506830845,"mc":[{"id":"1.230178177","rc":[{"atl":[[130,0]],"id":52385890}],"con":true,"img":false}]}
{"op":"mcm","clk":"11550969936","pt":1719506830949,"mc":[{"id":"1.230178177","rc":[{"atl":[[140,4.32]],"id":52385890}],"con":true,"img":false}]}
{"op":"mcm","clk":"11550969968","pt":1719506831880,"mc":[{"id":"1.230178177","rc":[{"atl":[[140,0]],"id":52385890}],"con":true,"img":false}]}
{"op":"mcm","clk":"11550969974","pt":1719506831935,"mc":[{"id":"1.230178177","rc":[{"atl":[[160,6.27]],"id":52385890}],"con":true,"img":false}]}
{"op":"mcm","clk":"11550970117","pt":1719506834378,"mc":[{"id":"1.230178177","rc":[{"atb":[[2.9,2.5],[3.35,42.55]],"id":52385903}],"con":true,"img":false}]}
{"op":"mcm","clk":"11550970188","pt":1719506835675,"mc":[{"id":"1.230178177","rc":[{"atb":[[7,16.67]],"id":52385913},{"atb":[[5.9,20.41]],"id":52385891},{"atl":[[160,5],[120,2.5]],"id":52385898}],"con":true,"img":false}]}
{"op":"mcm","clk":"11550970191","pt":1719506835781,"mc":[{"id":"1.230178177","rc":[{"atb":[[6,0]],"id":52385913},{"atb":[[8,64.56]],"id":52385884},{"atb":[[7,5]],"id":52385891},{"atl":[[140,0],[85,0],[100,0]],"id":52385898}],"con":true,"img":false}]}
{"op":"mcm","clk":"11550970195","pt":1719506835884,"mc":[{"id":"1.230178177","rc":[{"atb":[[4.5,31.07],[5.7,0],[7,11]],"id":52385884},{"atl":[[270,2],[150,4.03],[230,0]],"id":52385898}],"con":true,"img":false}]}
{"op":"mcm","clk":"11550970342","pt":1719506838945,"mc":[{"id":"1.230178177","rc":[{"atb":[[17.5,24]],"id":52385885}],"con":true,"img":false}]}
{"op":"mcm","clk":"11550970349","pt":1719506839151,"mc":[{"id":"1.230178177","rc":[{"atb":[[10.5,0]],"id":52385885}],"con":true,"img":false}]}
{"op":"mcm","clk":"11550970370","pt":1719506839769,"mc":[{"id":"1.230178177","rc":[{"atb":[[14,0]],"id":52385885}],"con":true,"img":false}]}
{"op":"mcm","clk":"11550970376","pt":1719506839878,"mc":[{"id":"1.230178177","rc":[{"atb":[[13,7]],"id":52385885}],"con":true,"img":false}]}
{"op":"mcm","clk":"11550970451","pt":1719506841380,"mc":[{"id":"1.230178177","rc":[{"atb":[[19.5,20]],"id":52385883}],"con":true,"img":false}]}
{"op":"mcm","clk":"11550970458","pt":1719506841485,"mc":[{"id":"1.230178177","rc":[{"atb":[[18,2.5]],"id":52385883},{"atb":[[8.2,32]],"id":52385884},{"atl":[[13,32]],"id":52385884},{"atl":[[110,5.5]],"id":52385898}],"con":true,"img":false}]}
{"op":"mcm","clk":"11550970466","pt":1719506841692,"mc":[{"id":"1.230178177","rc":[{"atb":[[8,0]],"id":52385884},{"atl":[[14.5,0]],"id":52385884},{"atl":[[150,0]],"id":52385898}],"con":true,"img":false}]}
{"op":"mcm","clk":"11550970488","pt":1719506842264,"mc":[{"id":"1.230178177","rc":[{"atb":[[5.6,21.74],[4.5,2.5]],"id":52385884}],"con":true,"img":false}]}
{"op":"mcm","clk":"11550970544","pt":1719506843363,"mc":[{"id":"1.230178177","rc":[{"atb":[[20,20]],"id":52385883}],"con":true,"img":false}]}
{"op":"mcm","clk":"11550970550","pt":1719506843454,"mc":[{"id":"1.230178177","rc":[{"atb":[[19.5,0]],"id":52385883}],"con":true,"img":false}]}
{"op":"mcm","clk":"11550971287","pt":1719506857306,"mc":[{"id":"1.230178177","rc":[{"atb":[[13,5],[15,2.5]],"id":52385911},{"atb":[[32,0],[36,17.5],[27,0],[29,5]],"id":52385912},{"atb":[[8.6,2.5],[7.6,0],[7.8,5],[8.4,0]],"id":52385913},{"atl":[[17.5,0],[13,2.5],[15,5],[15.5,0]],"id":52385906},{"atl":[[32,2.5],[36,0],[40,5],[44,0]],"id":52385882},{"atb":[[16,0],[18,0],[18.5,5],[21,2.5]],"id":52385883},{"atl":[[17,2.5],[18,0],[19,5],[20,0]],"id":52385884},{"atl":[[36,2.5],[55,0]],"id":52385885},{"atb":[[10.5,0],[12.5,0],[25,5],[29,2.5]],"id":52385896},{"atb":[[44,5],[26,0],[55,2.5],[30,0]],"id":52385897},{"atb":[[34,2.5],[24,0]],"id":52385890},{"atb":[[8,2.5],[7.2,5],[7.8,0],[7,0]],"id":52385891},{"atb":[[17.5,2.5],[15.5,5]],"id":52385892},{"atl":[[9.6,0],[9.2,2.5],[10,5],[11,10]],"id":52385903},{"atl":[[17.5,0],[17,5],[19.5,0],[15,2.5]],"id":52385904},{"atb":[[8.2,2.5],[6.6,0]],"id":52385905},{"atb":[[21,5],[11,12],[25,2.5],[13,0]],"id":52385898},{"atb":[[34,0],[46,5],[28,0],[60,2.5]],"id":52385899}],"con":true,"img":false}]}
{"op":"mcm","clk":"11550971293","pt":1719506857412,"mc":[{"id":"1.230178177","rc":[{"atb":[[12,0],[14,0]],"id":52385911},{"atl":[[65,2.5],[75,0],[85,5],[95,0]],"id":52385911},{"atl":[[34,0],[26,2.5],[28,0],[30,5]],"id":52385913},{"atb":[[22,20]],"id":52385883},{"atl":[[85,2.5],[90,0],[110,5],[120,0]],"id":52385883},{"atb":[[60,10.17]],"id":52385897},{"atb":[[32,0],[36,15]],"id":52385890},{"atb":[[16.5,0],[14.5,0]],"id":52385892},{"atl":[[9.2,14.7],[11,0]],"id":52385903},{"atb":[[26,20],[15,0]],"id":52385898},{"atb":[[65,9.38]],"id":52385899}],"con":true,"img":false}]}
{"op":"mcm","clk":"11550971300","pt":1719506857516,"mc":[{"id":"1.230178177","rc":[{"atl":[[60,10.17]],"id":52385911},{"atb":[[32,0]],"id":52385897},{"atl":[[10,16.11]],"id":52385903}],"con":true,"img":false}]}
{"op":"mcm","clk":"11550971305","pt":1719506857574,"mc":[{"id":"1.230178177","rc":[{"atb":[[20,0]],"id":52385883},{"atl":[[9.2,2.5]],"id":52385903},{"atb":[[36,0]],"id":52385899}],"con":true,"img":false}]}
{"op":"mcm","clk":"11550971311","pt":1719506857677,"mc":[{"id":"1.230178177","rc":[{"atl":[[70,0]],"id":52385911}],"con":true,"img":false}]}
{"op":"mcm","clk":"11550971316","pt":1719506857782,"mc":[{"id":"1.230178177","rc":[{"atl":[[50,7.04],[60,0]],"id":52385910},{"atl":[[130,0],[110,2]],"id":52385911},{"atl":[[260,2],[290,0]],"id":52385912},{"atl":[[16,6.67],[18,0]],"id":52385906},{"atl":[[65,0],[46,2.22]],"id":52385882},{"atl":[[140,2],[190,0]],"id":52385883},{"atl":[[21,5]],"id":52385884},{"atl":[[75,0],[60,2]],"id":52385885},{"atb":[[16,0]],"id":52385896},{"atl":[[190,2],[220,0]],"id":52385896},{"atl":[[330,2]],"id":52385897},{"atl":[[120,2]],"id":52385892},{"atl":[[270,0],[210,2]],"id":52385898},{"atl":[[330,2],[370,0]],"id":52385899}],"con":true,"img":false}]}
{"op":"mcm","clk":"11550971321","pt":1719506857884,"mc":[{"id":"1.230178177","rc":[{"atl":[[26,0]],"id":52385884},{"atl":[[370,0]],"id":52385897},{"atl":[[140,0]],"id":52385892}],"con":true,"img":false}]}
{"op":"mcm","clk":"11550971333","pt":1719506858093,"mc":[{"id":"1.230178177","rc":[{"atb":[[11,0]],"id":52385898}],"con":true,"img":false}]}
{"op":"mcm","clk":"11550971513","pt":1719506862080,"mc":[{"id":"1.230178177","rc":[{"atb":[[32,19.35]],"id":52385896}],"con":true,"img":false}]}
{"op":"mcm","clk":"11550971527","pt":1719506862290,"mc":[{"id":"1.230178177","rc":[{"atb":[[30,0]],"id":52385896}],"con":true,"img":false}]}
{"op":"mcm","clk":"11550971949","pt":1719506870911,"mc":[{"id":"1.230178177","rc":[{"atb":[[38,15]],"id":52385890}],"con":true,"img":false}]}
{"op":"mcm","clk":"11550971960","pt":1719506871118,"mc":[{"id":"1.230178177","rc":[{"atb":[[36,0]],"id":52385890}],"con":true,"img":false}]}
{"op":"mcm","clk":"11550972089","pt":1719506874103,"mc":[{"id":"1.230178177","rc":[{"atb":[[18.5,19]],"id":52385885}],"con":true,"img":false}]}
{"op":"mcm","clk":"11550972103","pt":1719506874331,"mc":[{"id":"1.230178177","rc":[{"atb":[[17.5,0]],"id":52385885}],"con":true,"img":false}]}
{"op":"mcm","clk":"11550972298","pt":1719506879113,"mc":[{"id":"1.230178177","rc":[{"atl":[[19.5,5.41]],"id":52385904}],"con":true,"img":false}]}
{"op":"mcm","clk":"11550972300","pt":1719506879216,"mc":[{"id":"1.230178177","rc":[{"atl":[[22,0]],"id":52385904}],"con":true,"img":false}]}
{"op":"mcm","clk":"11550972389","pt":1719506881104,"mc":[{"id":"1.230178177","rc":[{"atb":[[8,64]],"id":52385904}],"con":true,"img":false}]}
{"op":"mcm","clk":"11550972400","pt":1719506881313,"mc":[{"id":"1.230178177","rc":[{"atb":[[7.4,0]],"id":52385904}],"con":true,"img":false}]}
{"op":"mcm","clk":"11550972414","pt":1719506881522,"mc":[{"id":"1.230178177","rc":[{"atb":[[16,38.08]],"id":52385910},{"atb":[[7.2,3.66]],"id":52385904}],"con":true,"img":false}]}
{"op":"mcm","clk":"11550972429","pt":1719506881733,"mc":[{"id":"1.230178177","rc":[{"atb":[[15,0]],"id":52385910}],"con":true,"img":false}]}
{"op":"mcm","clk":"11550972443","pt":1719506882102,"mc":[{"id":"1.230178177","rc":[{"atb":[[7.2,0]],"id":52385904}],"con":true,"img":false}]}
{"op":"mcm","clk":"11550972495","pt":1719506883844,"mc":[{"id":"1.230178177","rc":[{"atb":[[7,0]],"id":52385906},{"atb":[[12,0]],"id":52385891},{"atb":[[7,0]],"id":52385904}],"con":true,"img":false}]}
{"op":"mcm","clk":"11550972500","pt":1719506883950,"mc":[{"id":"1.230178177","rc":[{"atb":[[4.3,0],[4.6,20],[4.1,37.26],[6,12]],"id":52385906},{"atb":[[11,11]],"id":52385891},{"atb":[[6,12],[5.2,0],[4.2,33.75]],"id":52385904}],"con":true,"img":false}]}
{"op":"mcm","clk":"11550972509","pt":1719506884113,"mc":[{"id":"1.230178177","rc":[{"atb":[[4.3,5],[4.1,5]],"id":52385906},{"atb":[[5.3,23.26],[4.2,2.5]],"id":52385904}],"con":true,"img":false}]}
{"op":"mcm","clk":"11550972513","pt":1719506884215,"mc":[{"id":"1.230178177","rc":[{"atb":[[8,14.29]],"id":52385910},{"atl":[[55,2]],"id":52385910},{"atb":[[4.3,0],[4.7,24]],"id":52385906},{"atb":[[11.5,2.5],[9.8,5]],"id":52385885},{"atb":[[10.5,10.53]],"id":52385892}],"con":true,"img":false}]}
{"op":"mcm","clk":"11550972519","pt":1719506884322,"mc":[{"id":"1.230178177","rc":[{"atb":[[6.8,0]],"id":52385910},{"atl":[[50,5]],"id":52385910},{"atl":[[140,0],[160,2.5],[180,0],[200,5]],"id":52385912},{"atb":[[14,15]],"id":52385913},{"atb":[[9.6,0],[11,0]],"id":52385885},{"atb":[[13.5,0]],"id":52385892},{"atb":[[8,0]],"id":52385904},{"atl":[[11.5,57.14]],"id":52385904}],"con":true,"img":false}]}
{"op":"mcm","clk":"11550972524","pt":1719506884426,"mc":[{"id":"1.230178177","rc":[{"atb":[[6.2,70.52]],"id":52385904}],"con":true,"img":false}]}
{"op":"mcm","clk":"11550972528","pt":1719506884531,"mc":[{"id":"1.230178177","rc":[{"atl":[[130,0]],"id":52385912},{"atb":[[12,11]],"id":52385913},{"atl":[[11.5,0],[14,0]],"id":52385904}],"con":true,"img":false}]}
{"op":"mcm","clk":"11550972534","pt":1719506884636,"mc":[{"id":"1.230178177","rc":[{"atl":[[140,4.32]],"id":52385912},{"atl":[[13.5,48]],"id":52385904}],"con":true,"img":false}]}
{"op":"mcm","clk":"11550972558","pt":1719506885211,"mc":[{"id":"1.230178177","rc":[{"atl":[[140,0]],"id":52385912}],"con":true,"img":false}]}
{"op":"mcm","clk":"11550972563","pt":1719506885317,"mc":[{"id":"1.230178177","rc":[{"atl":[[150,4.03]],"id":52385912}],"con":true,"img":false}]}
{"op":"mcm","clk":"11550972755","pt":1719506889665,"mc":[{"id":"1.230178177","rc":[{"atl":[[70,0],[60,2]],"id":52385905}],"con":true,"img":false}]}
{"op":"mcm","clk":"11550972912","pt":1719506892927,"mc":[{"id":"1.230178177","rc":[{"atb":[[13,0]],"id":52385885}],"con":true,"img":false}]}
{"op":"mcm","clk":"11550972918","pt":1719506893031,"mc":[{"id":"1.230178177","rc":[{"atb":[[14,7]],"id":52385885}],"con":true,"img":false}]}
{"op":"mcm","clk":"11550973138","pt":1719506896651,"mc":[{"id":"1.230178177","rc":[{"atb":[[6,76]],"id":52385906}],"con":true,"img":false}]}
{"op":"mcm","clk":"11550973148","pt":1719506896858,"mc":[{"id":"1.230178177","rc":[{"atb":[[4.6,0]],"id":52385906}],"con":true,"img":false}]}
{"op":"mcm","clk":"11550973153","pt":1719506896962,"mc":[{"id":"1.230178177","rc":[{"atl":[[11,60]],"id":52385904}],"con":true,"img":false}]}
{"op":"mcm","clk":"11550973169","pt":1719506897170,"mc":[{"id":"1.230178177","rc":[{"atl":[[13.5,0]],"id":52385904}],"con":true,"img":false}]}
{"op":"mcm","clk":"11550973477","pt":1719506903751,"mc":[{"id":"1.230178177","rc":[{"atb":[[14,0]],"id":52385885}],"con":true,"img":false}]}
{"op":"mcm","clk":"11550973484","pt":1719506903856,"mc":[{"id":"1.230178177","rc":[{"atb":[[13,7]],"id":52385885}],"con":true,"img":false}]}
{"op":"mcm","clk":"11550973540","pt":1719506905154,"mc":[{"id":"1.230178177","rc":[{"atl":[[270,5],[200,0],[230,2.5],[240,0]],"id":52385897},{"atl":[[280,5]],"id":52385899}],"con":true,"img":false}]}
{"op":"mcm","clk":"11550973545","pt":1719506905258,"mc":[{"id":"1.230178177","rc":[{"atb":[[2.82,0],[2.9,0],[3.35,0]],"id":52385903},{"atl":[[200,0]],"id":52385899}],"con":true,"img":false}]}
{"op":"mcm","clk":"11550973552","pt":1719506905362,"mc":[{"id":"1.230178177","rc":[{"atl":[[190,0]],"id":52385897},{"atb":[[2.3,2.5],[3.1,47.62],[2.22,5]],"id":52385903},{"atl":[[95,6.38]],"id":52385898},{"atl":[[190,0]],"id":52385899}],"con":true,"img":false}]}
{"op":"mcm","clk":"11550973557","pt":1719506905464,"mc":[{"id":"1.230178177","rc":[{"atl":[[12.5,52.17]],"id":52385884},{"atl":[[200,3.02]],"id":52385897},{"atl":[[110,0]],"id":52385898},{"atl":[[200,3.02]],"id":52385899}],"con":true,"img":false}]}
{"op":"mcm","clk":"11550973563","pt":1719506905671,"mc":[{"id":"1.230178177","rc":[{"atl":[[13,0]],"id":52385884}],"con":true,"img":false}]}
{"op":"mcm","clk":"11550973586","pt":1719506906242,"mc":[{"id":"1.230178177","rc":[{"atb":[[8,70.52]],"id":52385904},{"atl":[[11,0]],"id":52385904}],"con":true,"img":false}]}
{"op":"mcm","clk":"11550973593","pt":1719506906348,"mc":[{"id":"1.230178177","rc":[{"atl":[[200,0]],"id":52385897},{"atb":[[6.2,0]],"id":52385904},{"atl":[[16.5,34]],"id":52385904},{"atl":[[200,0]],"id":52385899}],"con":true,"img":false}]}
{"op":"mcm","clk":"11550973599","pt":1719506906450,"mc":[{"id":"1.230178177","rc":[{"atl":[[220,2.74]],"id":52385897},{"atl":[[220,2.74]],"id":52385899}],"con":true,"img":false}]}
{"op":"mcm","clk":"11550973608","pt":1719506906659,"mc":[{"id":"1.230178177","rc":[{"atl":[[220,0]],"id":52385899}],"con":true,"img":false}]}
{"op":"mcm","clk":"11550973615","pt":1719506906763,"mc":[{"id":"1.230178177","rc":[{"atl":[[230,2.62]],"id":52385899}],"con":true,"img":false}]}
{"op":"mcm","clk":"11550973751","pt":1719506909355,"mc":[{"id":"1.230178177","rc":[{"atl":[[14.5,34]],"id":52385904}],"con":true,"img":false}]}
{"op":"mcm","clk":"11550973762","pt":1719506909561,"mc":[{"id":"1.230178177","rc":[{"atl":[[16.5,0]],"id":52385904}],"con":true,"img":false}]}
{"op":"mcm","clk":"11550973865","pt":1719506911797,"mc":[{"id":"1.230178177","rc":[{"atl":[[270,0],[260,5],[220,5.24],[230,0]],"id":52385897},{"atb":[[2.24,5],[2.32,2.5]],"id":52385903}],"con":true,"img":false}]}
{"op":"mcm","clk":"11550973871","pt":1719506911852,"mc":[{"id":"1.230178177","rc":[{"atb":[[2.3,0],[2.22,0]],"id":52385903}],"con":true,"img":false}]}
{"op":"mcm","clk":"11550973892","pt":1719506912378,"mc":[{"id":"1.230178177","rc":[{"atb":[[17.5,2.5],[13,0],[15,0],[15.5,5]],"id":52385911},{"atb":[[44,2.5],[29,0]],"id":52385912},{"atb":[[9.6,2.5],[8.6,0],[8.8,5],[7.8,0]],"id":52385913},{"atl":[[16,2.5],[17,0],[18,5],[19,0]],"id":52385884},{"atb":[[25,0],[26,5],[29,0],[30,2.5]],"id":52385896},{"atb":[[44,0],[46,5],[55,0],[60,12.67]],"id":52385897},{"atb":[[34,0],[36,2.5],[28,0],[29,5]],"id":52385890},{"atb":[[19.5,2.5],[15.5,0]],"id":52385892},{"atl":[[10,11.11],[8.4,2.5]],"id":52385903},{"atl":[[16.5,5],[17,0],[14.5,36.5],[15,0]],"id":52385904},{"atb":[[21,0],[22,5],[25,0],[26,22.5]],"id":52385898},{"atb":[[70,2.5],[46,0],[50,5],[60,0]],"id":52385899}],"con":true,"img":false}]}
{"op":"mcm","clk":"11550973896","pt":1719506912479,"mc":[{"id":"1.230178177","rc":[{"atb":[[46,13.06]],"id":52385912},{"atl":[[10,0],[8.4,16.01]],"id":52385903},{"atb":[[75,8.11]],"id":52385899}],"con":true,"img":false}]}
{"op":"mcm","clk":"11550973901","pt":1719506912584,"mc":[{"id":"1.230178177","rc":[{"atl":[[9.2,14.7],[8.4,2.5]],"id":52385903},{"atb":[[65,0]],"id":52385899}],"con":true,"img":false}]}
{"op":"mcm","clk":"11550973904","pt":1719506912688,"mc":[{"id":"1.230178177","rc":[{"atb":[[36,2.5]],"id":52385912}],"con":true,"img":false}]}
{"op":"mcm","clk":"11550974095","pt":1719506917278,"mc":[{"id":"1.230178177","rc":[{"atb":[[34,15]],"id":52385896}],"con":true,"img":false}]}
{"op":"mcm","clk":"11550974101","pt":1719506917484,"mc":[{"id":"1.230178177","rc":[{"atb":[[32,0]],"id":52385896}],"con":true,"img":false}]}
{"op":"mcm","clk":"11550974832","pt":1719506931903,"mc":[{"id":"1.230178177","rc":[{"atl":[[11,60]],"id":52385904}],"con":true,"img":false}]}
{"op":"mcm","clk":"11550974843","pt":1719506932113,"mc":[{"id":"1.230178177","rc":[{"atl":[[14.5,2.5]],"id":52385904}],"con":true,"img":false}]}
{"op":"mcm","clk":"11550976281","pt":1719506964844,"mc":[{"id":"1.230178177","rc":[{"atb":[[16,5],[17.5,0],[18,2.5],[15.5,0]],"id":52385911},{"atl":[[16.5,0],[16,5],[14,2.5],[14.5,0]],"id":52385904},{"atb":[[22,0],[23,5],[26,20],[27,2.5]],"id":52385898},{"atb":[[70,0],[75,10.61],[50,0],[55,5]],"id":52385899}],"con":true,"img":false}]}
{"op":"mcm","clk":"11550976288","pt":1719506964948,"mc":[{"id":"1.230178177","rc":[{"atb":[[27,17.5]],"id":52385898}],"con":true,"img":false}]}
{"op":"mcm","clk":"11550976300","pt":1719506965158,"mc":[{"id":"1.230178177","rc":[{"atb":[[26,0]],"id":52385898}],"con":true,"img":false}]}
{"op":"mcm","clk":"11550976481","pt":1719506969659,"mc":[{"id":"1.230178177","rc":[{"atb":[[9.6,0],[9,5],[9.8,2.5],[8.8,0]],"id":52385913},{"atl":[[330,0],[370,2]],"id":52385899}],"con":true,"img":false}]}
{"op":"mcm","clk":"11550976492","pt":1719506969965,"mc":[{"id":"1.230178177","rc":[{"atb":[[8,0],[7.2,0],[8.2,2.5],[7.4,5]],"id":52385891},{"atb":[[17.5,0],[18,5],[19.5,0],[20,9.5]],"id":52385892}],"con":true,"img":false}]}
{"op":"mcm","clk":"11550976503","pt":1719506970229,"mc":[{"id":"1.230178177","rc":[{"atb":[[40,15]],"id":52385890}],"con":true,"img":false}]}
{"op":"mcm","clk":"11550976511","pt":1719506970436,"mc":[{"id":"1.230178177","rc":[{"atb":[[38,0]],"id":52385890}],"con":true,"img":false}]}
{"op":"mcm","clk":"11550976515","pt":1719506970542,"mc":[{"id":"1.230178177","rc":[{"atb":[[65,2.5],[46,0],[48,5],[60,10.17]],"id":52385897}],"con":true,"img":false}]}
{"op":"mcm","clk":"11550976522","pt":1719506970646,"mc":[{"id":"1.230178177","rc":[{"atb":[[65,11.88]],"id":52385897}],"con":true,"img":false}]}
{"op":"mcm","clk":"11550976527","pt":1719506970750,"mc":[{"id":"1.230178177","rc":[{"atb":[[60,0]],"id":52385897}],"con":true,"img":false}]}
{"op":"mcm","clk":"11550976549","pt":1719506971064,"mc":[{"id":"1.230178177","rc":[{"atb":[[36,0],[38,2.5],[29,0],[30,5]],"id":52385890}],"con":true,"img":false}]}
{"op":"mcm","clk":"11550976567","pt":1719506971390,"mc":[{"id":"1.230178177","rc":[{"atl":[[9,5],[9.2,12.2],[8.2,2.5],[8.4,0]],"id":52385903}],"con":true,"img":false}]}
{"op":"mcm","clk":"11550976579","pt":1719506971552,"mc":[{"id":"1.230178177","rc":[{"atl":[[9.2,0],[8.4,13.51]],"id":52385903}],"con":true,"img":false}]}
{"op":"mcm","clk":"11550976719","pt":1719506973858,"mc":[{"id":"1.230178177","rc":[{"atb":[[4.3,2.5],[3.9,0],[4.2,0]],"id":52385904}],"con":true,"img":false}]}
{"op":"mcm","clk":"11550976724","pt":1719506973961,"mc":[{"id":"1.230178177","rc":[{"atb":[[8,0]],"id":52385904}],"con":true,"img":false}]}
{"op":"mcm","clk":"11550976731","pt":1719506974071,"mc":[{"id":"1.230178177","rc":[{"atb":[[7.8,34]],"id":52385904}],"con":true,"img":false}]}
{"op":"mcm","clk":"11550976739","pt":1719506974275,"mc":[{"id":"1.230178177","rc":[{"atb":[[7.8,0]],"id":52385904}],"con":true,"img":false}]}
{"op":"mcm","clk":"11550976745","pt":1719506974378,"mc":[{"id":"1.230178177","rc":[{"atb":[[7.4,70.52]],"id":52385904}],"con":true,"img":false}]}
{"op":"mcm","clk":"11550976757","pt":1719506974643,"mc":[{"id":"1.230178177","rc":[{"atl":[[80,2.5],[100,5]],"id":52385911},{"atb":[[5.8,20.83],[11.5,2.5],[16.5,36.08],[7.2,0],[9.8,5]],"id":52385889},{"atl":[[85,0],[110,0]],"id":52385883},{"atl":[[17.5,5],[15.5,2.5]],"id":52385884},{"atl":[[190,2.5],[230,5]],"id":52385890},{"atl":[[32,0]],"id":52385891},{"atb":[[4.8,26.32]],"id":52385892},{"atl":[[160,2],[90,2.5],[120,7]],"id":52385892},{"atl":[[11,0]],"id":52385904},{"atl":[[270,5],[230,5.12]],"id":52385899}],"con":true,"img":false}]}
{"op":"mcm","clk":"11550976762","pt":1719506974747,"mc":[{"id":"1.230178177","rc":[{"atl":[[65,0],[85,0]],"id":52385911},{"atb":[[10,0],[9.2,0],[12.5,0],[16.5,0]],"id":52385889},{"atl":[[540,2],[140,0],[80,2.5],[100,5]],"id":52385883},{"atl":[[16,0],[18,0]],"id":52385884},{"atl":[[160,3.77],[200,0]],"id":52385890},{"atb":[[3.6,38.46],[5.9,0]],"id":52385891},{"atl":[[48,5],[30,0]],"id":52385891},{"atb":[[10.5,0]],"id":52385892},{"atl":[[75,0],[95,0],[120,5]],"id":52385892},{"atl":[[13.5,48]],"id":52385904},{"atl":[[280,0],[340,2],[370,0],[240,0]],"id":52385899}],"con":true,"img":false}]}
{"op":"mcm","clk":"11550976773","pt":1719506974855,"mc":[{"id":"1.230178177","rc":[{"atb":[[13,44.08]],"id":52385889},{"atl":[[540,0],[140,2]],"id":52385883},{"atl":[[38,16.22]],"id":52385891}],"con":true,"img":false}]}
{"op":"mcm","clk":"11550976777","pt":1719506974957,"mc":[{"id":"1.230178177","rc":[{"atl":[[70,0]],"id":52385892}],"con":true,"img":false}]}
{"op":"mcm","clk":"11550976783","pt":1719506975062,"mc":[{"id":"1.230178177","rc":[{"atl":[[75,8.11]],"id":52385892}],"con":true,"img":false}]}
{"op":"mcm","clk":"11550976793","pt":1719506975271,"mc":[{"id":"1.230178177","rc":[{"atl":[[32,0]],"id":52385889}],"con":true,"img":false}]}
{"op":"mcm","clk":"11550976798","pt":1719506975373,"mc":[{"id":"1.230178177","rc":[{"atl":[[34,18.18]],"id":52385889}],"con":true,"img":false}]}
{"op":"mcm","clk":"11550976802","pt":1719506975477,"mc":[{"id":"1.230178177","rc":[{"atl":[[60,10.17]],"id":52385883}],"con":true,"img":false}]}
{"op":"mcm","clk":"11550976806","pt":1719506975581,"mc":[{"id":"1.230178177","rc":[{"atl":[[34,0]],"id":52385889},{"atl":[[75,0]],"id":52385892}],"con":true,"img":false}]}
{"op":"mcm","clk":"11550976812","pt":1719506975649,"mc":[{"id":"1.230178177","rc":[{"atl":[[36,17.14],[390,2],[50,5]],"id":52385889},{"atl":[[65,0]],"id":52385883},{"atl":[[85,7.14]],"id":52385892}],"con":true,"img":false}]}
{"op":"mcm","clk":"11550976820","pt":1719506975753,"mc":[{"id":"1.230178177","rc":[{"atl":[[390,0],[50,7.04]],"id":52385889}],"con":true,"img":false}]}
{"op":"mcm","clk":"11550976896","pt":1719506978082,"mc":[{"id":"1.230178177","rc":[{"atl":[[130,0],[160,5],[170,0],[120,7.54]],"id":52385896}],"con":true,"img":false}]}
{"op":"mcm","clk":"11550976915","pt":1719506978651,"mc":[{"id":"1.230178177","rc":[{"atl":[[36,0]],"id":52385889}],"con":true,"img":false}]}
{"op":"mcm","clk":"11550976921","pt":1719506978752,"mc":[{"id":"1.230178177","rc":[{"atl":[[38,16.22],[390,2],[50,5]],"id":52385889}],"con":true,"img":false}]}
{"op":"mcm","clk":"11550976972","pt":1719506979786,"mc":[{"id":"1.230178177","rc":[{"atb":[[5.8,0],[4.9,25.64]],"id":52385889},{"atb":[[1.78,100]],"id":52385883},{"atb":[[8.2,0]],"id":52385884},{"atl":[[19,5.56],[21,0]],"id":52385884},{"atl":[[180,2],[190,0]],"id":52385896},{"atb":[[2.24,80.65],[3.6,0]],"id":52385891},{"atb":[[4.8,0],[2.22,81.97]],"id":52385892},{"atl":[[18,5],[14,0]],"id":52385904},{"atl":[[29,15]],"id":52385905},{"atl":[[150,5],[160,0],[110,2.5],[120,0]],"id":52385898}],"con":true,"img":false}]}
{"op":"mcm","clk":"11550976982","pt":1719506979948,"mc":[{"id":"1.230178177","rc":[{"atb":[[8,32]],"id":52385884},{"atl":[[36,0]],"id":52385905}],"con":true,"img":false}]}
{"op":"mcm","clk":"11550976990","pt":1719506980155,"mc":[{"id":"1.230178177","rc":[{"atb":[[8,0]],"id":52385884}],"con":true,"img":false}]}
{"op":"mcm","clk":"11550976996","pt":1719506980258,"mc":[{"id":"1.230178177","rc":[{"atb":[[7.8,65.48]],"id":52385884},{"atl":[[220,2.74]],"id":52385899}],"con":true,"img":false}]}
{"op":"mcm","clk":"11550977003","pt":1719506980468,"mc":[{"id":"1.230178177","rc":[{"atl":[[230,2.5]],"id":52385899}],"con":true,"img":false}]}
{"op":"mcm","clk":"11550977014","pt":1719506980678,"mc":[{"id":"1.230178177","rc":[{"atl":[[85,7.14]],"id":52385898}],"con":true,"img":false}]}
{"op":"mcm","clk":"11550977018","pt":1719506980781,"mc":[{"id":"1.230178177","rc":[{"atl":[[95,0]],"id":52385898}],"con":true,"img":false}]}
{"op":"mcm","clk":"11550977179","pt":1719506983860,"mc":[{"id":"1.230178177","rc":[{"atl":[[390,0],[55,2]],"id":52385889}],"con":true,"img":false}]}
{"op":"mcm","clk":"11550977219","pt":1719506984847,"mc":[{"id":"1.230178177","rc":[{"atb":[[8.4,70.52]],"id":52385904}],"con":true,"img":false}]}
{"op":"mcm","clk":"11550977226","pt":1719506985066,"mc":[{"id":"1.230178177","rc":[{"atb":[[7.4,0]],"id":52385904},{"atl":[[13.5,0]],"id":52385904}],"con":true,"img":false}]}
{"op":"mcm","clk":"11550977233","pt":1719506985157,"mc":[{"id":"1.230178177","rc":[{"atl":[[15.5,41.38]],"id":52385904}],"con":true,"img":false}]}
{"op":"mcm","clk":"11550977250","pt":1719506985471,"mc":[{"id":"1.230178177","rc":[{"atb":[[16.5,32]],"id":52385889}],"con":true,"img":false}]}
{"op":"mcm","clk":"11550977260","pt":1719506985683,"mc":[{"id":"1.230178177","rc":[{"atl":[[75,2.5],[80,0],[95,5],[100,0]],"id":52385911},{"atb":[[4.9,0],[13,0],[6.6,17.86]],"id":52385889},{"atb":[[1.78,0]],"id":52385883},{"atl":[[60,0]],"id":52385883},{"atl":[[180,2.5],[190,0],[220,5],[230,0]],"id":52385890},{"atb":[[2.24,0],[4.8,26.32]],"id":52385891},{"atl":[[34,18.18],[38,18.72],[40,0],[46,5],[48,0]],"id":52385891},{"atb":[[7.2,16.13],[2.22,0]],"id":52385892},{"atb":[[8.4,0]],"id":52385904},{"atl":[[12,54.55]],"id":52385904},{"atl":[[29,0]],"id":52385905},{"atl":[[85,0]],"id":52385898}],"con":true,"img":false}]}
{"op":"mcm","clk":"11550977267","pt":1719506985785,"mc":[{"id":"1.230178177","rc":[{"atb":[[16.5,0],[11,0]],"id":52385889},{"atl":[[95,6.38]],"id":52385883},{"atl":[[38,2.5]],"id":52385891},{"atb":[[5.4,70.52]],"id":52385904},{"atl":[[44,10]],"id":52385905},{"atl":[[140,4.32]],"id":52385898}],"con":true,"img":false}]}
{"op":"mcm","clk":"11550977275","pt":1719506985888,"mc":[{"id":"1.230178177","rc":[{"atl":[[15.5,0]],"id":52385904}],"con":true,"img":false}]}
{"op":"mcm","clk":"11550977281","pt":1719506985956,"mc":[{"id":"1.230178177","rc":[{"atb":[[16,15]],"id":52385889}],"con":true,"img":false}]}
{"op":"mcm","clk":"11550977293","pt":1719506986154,"mc":[{"id":"1.230178177","rc":[{"atl":[[36,17.14]],"id":52385889}],"con":true,"img":false}]}
{"op":"mcm","clk":"11550977300","pt":1719506986260,"mc":[{"id":"1.230178177","rc":[{"atl":[[38,0],[46,2.22],[55,0]],"id":52385889},{"atl":[[75,8.11]],"id":52385883}],"con":true,"img":false}]}
{"op":"mcm","clk":"11550977309","pt":1719506986466,"mc":[{"id":"1.230178177","rc":[{"atl":[[95,0]],"id":52385883}],"con":true,"img":false}]}
{"op":"mcm","clk":"11550977315","pt":1719506986673,"mc":[{"id":"1.230178177","rc":[{"atl":[[34,15]],"id":52385889}],"con":true,"img":false}]}
{"op":"mcm","clk":"11550977324","pt":1719506986879,"mc":[{"id":"1.230178177","rc":[{"atl":[[36,0]],"id":52385889}],"con":true,"img":false}]}
{"op":"mcm","clk":"11550977332","pt":1719506987088,"mc":[{"id":"1.230178177","rc":[{"atl":[[38,3.75]],"id":52385889}],"con":true,"img":false}]}
{"op":"mcm","clk":"11550977357","pt":1719506987765,"mc":[{"id":"1.230178177","rc":[{"atl":[[38,0]],"id":52385889}],"con":true,"img":false}]}
{"op":"mcm","clk":"11550977464","pt":1719506990470,"mc":[{"id":"1.230178177","rc":[{"atl":[[36,15]],"id":52385905}],"con":true,"img":false}]}
{"op":"mcm","clk":"11550977472","pt":1719506990679,"mc":[{"id":"1.230178177","rc":[{"atb":[[8,65.48]],"id":52385884},{"atl":[[44,0]],"id":52385905}],"con":true,"img":false}]}
{"op":"mcm","clk":"11550977482","pt":1719506990885,"mc":[{"id":"1.230178177","rc":[{"atb":[[7.8,0]],"id":52385884}],"con":true,"img":false}]}
{"op":"mcm","clk":"11550977506","pt":1719506991357,"mc":[{"id":"1.230178177","rc":[{"atl":[[100,6.06]],"id":52385898}],"con":true,"img":false}]}
{"op":"mcm","clk":"11550977511","pt":1719506991563,"mc":[{"id":"1.230178177","rc":[{"atl":[[140,0]],"id":52385898}],"con":true,"img":false}]}
{"op":"mcm","clk":"11550977645","pt":1719506995500,"mc":[{"id":"1.230178177","rc":[{"atb":[[6.2,70.52]],"id":52385904}],"con":true,"img":false}]}
{"op":"mcm","clk":"11550977654","pt":1719506995661,"mc":[{"id":"1.230178177","rc":[{"atb":[[5.4,0]],"id":52385904}],"con":true,"img":false}]}
{"op":"mcm","clk":"11550977931","pt":1719507003211,"mc":[{"id":"1.230178177","rc":[{"atb":[[14.5,7.41]],"id":52385912},{"atl":[[260,0],[140,2.5],[180,5],[200,7]],"id":52385912},{"atb":[[5.4,22.73]],"id":52385906},{"atl":[[19,5.56]],"id":52385906},{"atb":[[16,0]],"id":52385889},{"atl":[[60,10.17]],"id":52385883},{"atb":[[11.5,5],[13.5,2.5]],"id":52385896},{"atb":[[65,0],[34,2.5],[48,0],[28,5],[4.2,31.25]],"id":52385897},{"atl":[[260,0],[200,2.5],[220,2.74],[240,5]],"id":52385897},{"atb":[[13.5,8]],"id":52385890},{"atl":[[190,2]],"id":52385890},{"atb":[[5.8,20.83]],"id":52385904},{"atl":[[38,0],[46,0],[30,15]],"id":52385905},{"atb":[[4.1,32.26],[12.5,5],[14.5,2.5]],"id":52385898},{"atl":[[150,7],[85,7.14]],"id":52385898},{"atb":[[75,2.5],[36,2.5],[4.3,30.3],[29,5]],"id":52385899},{"atl":[[270,7]],"id":52385899}],"con":true,"img":false}]}
{"op":"mcm","clk":"11550977940","pt":1719507003320,"mc":[{"id":"1.230178177","rc":[{"atb":[[8,0],[19,20],[6.6,17.86]],"id":52385910},{"atl":[[70,2],[55,0]],"id":52385910},{"atl":[[170,2]],"id":52385911},{"atl":[[160,0],[200,2]],"id":52385912},{"atb":[[7,0]],"id":52385913},{"atb":[[5.4,0],[7.2,58],[4.5,0],[4.6,2.5],[4.1,0],[4.2,5],[4.7,0]],"id":52385906},{"atl":[[16,0],[11,0],[13,0],[15,0],[15.5,2.5]],"id":52385906},{"atl":[[46,0],[55,2]],"id":52385889},{"atb":[[16,20]],"id":52385882},{"atb":[[10.5,10.53]],"id":52385883},{"atl":[[140,0],[75,0],[100,7]],"id":52385883},{"atb":[[5.6,0],[4.8,26.32]],"id":52385884},{"atl":[[19,0],[12.5,0],[27,3.85]],"id":52385884},{"atb":[[9,0],[7.6,15.15]],"id":52385885},{"atl":[[29,0]],"id":52385885},{"atb":[[34,0],[8.2,13.89],[26,0],[30,0]],"id":52385896},{"atb":[[4.1,10]],"id":52385897},{"atl":[[260,2],[330,0],[210,2.87]],"id":52385897},{"atl":[[320,0]],"id":52385890},{"atb":[[4.8,0],[7.4,20.62]],"id":52385891},{"atl":[[46,7.22],[27,23.08],[60,0]],"id":52385891},{"atb":[[7.2,0],[13.5,8]],"id":52385892},{"atl":[[75,2.5],[160,0],[90,0],[95,5],[120,2]],"id":52385892},{"atb":[[4,69.02],[2.24,0],[3.6,28],[2.32,0],[3.1,0],[2.84,2.5],[2.76,5]],"id":52385903},{"atl":[[8.4,0]],"id":52385903},{"atb":[[5.3,0],[8.4,70.52]],"id":52385904},{"atl":[[12,0],[27,3.85]],"id":52385904},{"atb":[[6.2,19.23]],"id":52385905},{"atl":[[46,2.22],[26,2.5],[30,20],[60,0]],"id":52385905},{"atb":[[23,0],[27,0]],"id":52385898},{"atl":[[210,0]],"id":52385898},{"atb":[[75,0],[55,0]],"id":52385899},{"atl":[[340,0]],"id":52385899}],"con":true,"img":false}]}
{"op":"mcm","clk":"11550977945","pt":1719507003376,"mc":[{"id":"1.230178177","rc":[{"atl":[[110,0]],"id":52385911},{"atl":[[140,6.82]],"id":52385912},{"atb":[[15.5,15]],"id":52385889},{"atl":[[70,2],[46,0]],"id":52385882},{"atb":[[19.5,19]],"id":52385885},{"atl":[[150,4.03]],"id":52385890},{"atl":[[9.6,11.63]],"id":52385903},{"atb":[[5.8,0]],"id":52385904},{"atl":[[19.5,0]],"id":52385904},{"atl":[[36,0]],"id":52385905},{"atl":[[100,0]],"id":52385898}],"con":true,"img":false}]}
{"op":"mcm","clk":"11550977949","pt":1719507003490,"mc":[{"id":"1.230178177","rc":[{"atb":[[16,8],[19,0]],"id":52385910},{"atb":[[6,20]],"id":52385913},{"atb":[[4.6,30.28],[6,12]],"id":52385906},{"atl":[[17.5,5],[18.5,0.58]],"id":52385906},{"atb":[[16,0],[14,0]],"id":52385882},{"atl":[[60,0]],"id":52385883},{"atl":[[17,15]],"id":52385884},{"atl":[[80,2],[42,10],[60,0]],"id":52385885},{"atb":[[12,4]],"id":52385896},{"atl":[[220,0]],"id":52385897},{"atb":[[7.4,5]],"id":52385891},{"atl":[[34,0]],"id":52385891},{"atb":[[13.5,0]],"id":52385892},{"atl":[[70,8.7]],"id":52385892},{"atb":[[3.6,0]],"id":52385903},{"atb":[[6.2,0]],"id":52385904},{"atl":[[17.5,34]],"id":52385904},{"atb":[[13,10]],"id":52385898},{"atb":[[38,10]],"id":52385899}],"con":true,"img":false}]}
{"op":"mcm","clk":"11550977953","pt":1719507003583,"mc":[{"id":"1.230178177","rc":[{"atb":[[16.5,38.71]],"id":52385910},{"atb":[[12.5,0]],"id":52385911},{"atb":[[14.5,0]],"id":52385912},{"atl":[[140,4.32],[150,0],[170,2.5],[180,0],[200,0]],"id":52385912},{"atl":[[42,0],[60,2]],"id":52385913},{"atb":[[7.2,0]],"id":52385906},{"atl":[[17.5,0],[13,2.5],[15,5],[15.5,0]],"id":52385906},{"atb":[[4.9,25.64],[6.6,0],[15.5,0]],"id":52385889},{"atb":[[7.6,0],[13.5,40],[5.9,20.41]],"id":52385882},{"atb":[[10.5,0]],"id":52385883},{"atl":[[80,10.09],[100,5]],"id":52385883},{"atb":[[18.5,0]],"id":52385885},{"atb":[[8.2,0],[11.5,0],[26,5],[13.5,0],[30,2.5]],"id":52385896},{"atl":[[270,2],[180,0]],"id":52385896},{"atb":[[4.2,0]],"id":52385897},{"atl":[[260,0],[200,0],[230,2.5],[240,0]],"id":52385897},{"atb":[[13.5,0]],"id":52385890},{"atl":[[160,0],[190,0]],"id":52385890},{"atb":[[2.76,56.82]],"id":52385891},{"atl":[[46,5],[27,0]],"id":52385891},{"atb":[[2.92,52.08]],"id":52385892},{"atl":[[85,0],[120,0]],"id":52385892},{"atb":[[2.18,5],[2.84,0],[2.26,2.5],[2.78,56.18],[2.76,0]],"id":52385903},{"atl":[[9.6,0],[9,17.5]],"id":52385903},{"atb":[[4.9,25.64],[8.4,0]],"id":52385904},{"atb":[[6.2,0]],"id":52385905},{"atl":[[40,2.5],[46,0],[48,5],[26,0],[30,15]],"id":52385905},{"atb":[[4.1,0]],"id":52385898},{"atl":[[150,5],[85,0]],"id":52385898},{"atb":[[4.3,0]],"id":52385899},{"atl":[[270,5]],"id":52385899}],"con":true,"img":false}]}
{"op":"mcm","clk":"11550977960","pt":1719507003689,"mc":[{"id":"1.230178177","rc":[{"atl":[[130,2],[170,0]],"id":52385911},{"atb":[[13,0]],"id":52385885},{"atb":[[4,14]],"id":52385903}],"con":true,"img":false}]}
{"op":"mcm","clk":"11550977964","pt":1719507003790,"mc":[{"id":"1.230178177","rc":[{"atb":[[13,8.33]],"id":52385911},{"atl":[[290,2]],"id":52385912},{"atb":[[6.8,15]],"id":52385906},{"atb":[[11.5,17.5]],"id":52385889},{"atl":[[540,2]],"id":52385883},{"atl":[[270,5],[340,2]],"id":52385897},{"atl":[[300,2]],"id":52385890},{"atl":[[36,15],[60,2]],"id":52385891},{"atl":[[150,2]],"id":52385892},{"atb":[[2.8,58.24]],"id":52385903},{"atb":[[8,34]],"id":52385904},{"atl":[[65,2]],"id":52385905},{"atl":[[90,6.74],[220,2]],"id":52385898},{"atl":[[350,2]],"id":52385899}],"con":true,"img":false}]}
{"op":"mcm","clk":"11550977966","pt":1719507003895,"mc":[{"id":"1.230178177","rc":[{"atb":[[20,5]],"id":52385896},{"atl":[[150,0]],"id":52385890},{"atb":[[19,5]],"id":52385898},{"atb":[[42,2]],"id":52385899}],"con":true,"img":false}]}
{"op":"mcm","clk":"11550977972","pt":1719507003997,"mc":[{"id":"1.230178177","rc":[{"atl":[[140,0]],"id":52385912},{"atl":[[23,0]],"id":52385913},{"atl":[[210,0]],"id":52385897},{"atl":[[160,3.77]],"id":52385890},{"atl":[[90,0]],"id":52385898}],"con":true,"img":false}]}
{"op":"mcm","clk":"11550977977","pt":1719507004102,"mc":[{"id":"1.230178177","rc":[{"atb":[[12,0]],"id":52385913},{"atb":[[7,0]],"id":52385884},{"atl":[[160,0]],"id":52385890},{"atl":[[120,5.04]],"id":52385898}],"con":true,"img":false}]}
{"op":"mcm","clk":"11550977982","pt":1719507004204,"mc":[{"id":"1.230178177","rc":[{"atl":[[150,4.03]],"id":52385912},{"atb":[[11,11]],"id":52385913},{"atl":[[24,15]],"id":52385913},{"atb":[[6,11]],"id":52385884},{"atl":[[230,5.12]],"id":52385897},{"atl":[[170,3.55]],"id":52385890}],"con":true,"img":false}]}
{"op":"mcm","clk":"11550977986","pt":1719507004311,"mc":[{"id":"1.230178177","rc":[{"atb":[[42,14.63]],"id":52385890},{"atl":[[7.8,65.24]],"id":52385903},{"atb":[[26,6.75]],"id":52385898}],"con":true,"img":false}]}
{"op":"mcm","clk":"11550977988","pt":1719507004411,"mc":[{"id":"1.230178177","rc":[{"atl":[[150,0]],"id":52385912}],"con":true,"img":false}]}
{"op":"mcm","clk":"11550977992","pt":1719507004479,"mc":[{"id":"1.230178177","rc":[{"atl":[[160,3.77]],"id":52385912},{"atb":[[40,0]],"id":52385890},{"atl":[[8,0]],"id":52385903},{"atb":[[26,0]],"id":52385898}],"con":true,"img":false}]}
{"op":"mcm","clk":"11550978084","pt":1719507006092,"mc":[{"id":"1.230178177","rc":[{"atl":[[30,0]],"id":52385905}],"con":true,"img":false}]}
{"op":"mcm","clk":"11550978092","pt":1719507006195,"mc":[{"id":"1.230178177","rc":[{"atl":[[32,10]],"id":52385905}],"con":true,"img":false}]}
{"op":"mcm","clk":"11550978103","pt":1719507006406,"mc":[{"id":"1.230178177","rc":[{"atl":[[32,0]],"id":52385905}],"con":true,"img":false}]}
{"op":"mcm","clk":"11550978112","pt":1719507006612,"mc":[{"id":"1.230178177","rc":[{"atl":[[38,15]],"id":52385905}],"con":true,"img":false}]}
{"op":"mcm","clk":"11550978189","pt":1719507008534,"mc":[{"id":"1.230178177","rc":[{"atb":[[8,14.29],[6.6,0]],"id":52385910},{"atl":[[70,0],[55,2]],"id":52385910},{"atb":[[4.8,0],[5.4,22.73]],"id":52385884},{"atl":[[19.5,5.41],[27,0]],"id":52385884},{"atl":[[19,5.56],[27,0]],"id":52385904}],"con":true,"img":false}]}
{"op":"mcm","clk":"11550978195","pt":1719507008589,"mc":[{"id":"1.230178177","rc":[{"atb":[[6,0],[7,16.67]],"id":52385913},{"atl":[[70,0],[46,2.22]],"id":52385882},{"atl":[[80,0]],"id":52385885}],"con":true,"img":false}]}
{"op":"mcm","clk":"11550978202","pt":1719507008695,"mc":[{"id":"1.230178177","rc":[{"atl":[[60,2]],"id":52385885}],"con":true,"img":false}]}
{"op":"mcm","clk":"11550978208","pt":1719507008795,"mc":[{"id":"1.230178177","rc":[{"atl":[[44,2.33],[60,0]],"id":52385913},{"atb":[[7.2,16.13],[5.9,0]],"id":52385882},{"atb":[[4.5,28.57],[2.76,0]],"id":52385891},{"atb":[[2.92,0],[6.2,19.23]],"id":52385892},{"atb":[[2.78,0],[3.05,48.78]],"id":52385903}],"con":true,"img":false}]}
{"op":"mcm","clk":"11550978249","pt":1719507009994,"mc":[{"id":"1.230178177","rc":[{"atb":[[36,0],[38,5],[44,0],[46,15.56]],"id":52385912}],"con":true,"img":false}]}
{"op":"mcm","clk":"11550978401","pt":1719507013518,"mc":[{"id":"1.230178177","rc":[{"atl":[[65,9.38]],"id":52385883},{"atl":[[30,15]],"id":52385905},{"atl":[[90,6.74]],"id":52385898}],"con":true,"img":false}]}
{"op":"mcm","clk":"11550978405","pt":1719507013621,"mc":[{"id":"1.230178177","rc":[{"atl":[[540,0],[140,2],[80,2.5]],"id":52385883},{"atb":[[36,17.14]],"id":52385897},{"atl":[[120,0]],"id":52385898}],"con":true,"img":false}]}
{"op":"mcm","clk":"11550978412","pt":1719507013725,"mc":[{"id":"1.230178177","rc":[{"atb":[[4.1,0]],"id":52385897},{"atl":[[38,0]],"id":52385905}],"con":true,"img":false}]}
{"op":"mcm","clk":"11550978420","pt":1719507013836,"mc":[{"id":"1.230178177","rc":[{"atl":[[11,34]],"id":52385906},{"atl":[[12.5,52]],"id":52385884},{"atl":[[29,15]],"id":52385885},{"atb":[[36,17.14]],"id":52385896},{"atl":[[11.5,57.14]],"id":52385904},{"atb":[[25,15]],"id":52385898},{"atb":[[44,10.48]],"id":52385899}],"con":true,"img":false}]}
{"op":"mcm","clk":"11550978427","pt":1719507014037,"mc":[{"id":"1.230178177","rc":[{"atl":[[16,6.67],[18.5,0],[19,0]],"id":52385906},{"atl":[[17,0]],"id":52385884},{"atl":[[42,0]],"id":52385885},{"atb":[[12,0]],"id":52385896},{"atl":[[17.5,0]],"id":52385904},{"atb":[[13,0]],"id":52385898},{"atb":[[38,0]],"id":52385899}],"con":true,"img":false}]}
{"op":"mcm","clk":"11550978455","pt":1719507014407,"mc":[{"id":"1.230178177","rc":[{"atl":[[23,27.27]],"id":52385913}],"con":true,"img":false}]}
{"op":"mcm","clk":"11550978462","pt":1719507014509,"mc":[{"id":"1.230178177","rc":[{"atl":[[24,0]],"id":52385913}],"con":true,"img":false}]}
{"op":"mcm","clk":"11550978468","pt":1719507014613,"mc":[{"id":"1.230178177","rc":[{"atb":[[16,0],[16.5,5],[18,0],[18.5,2.5]],"id":52385911},{"atl":[[16,0],[16.5,5],[18,0],[14.5,2.5]],"id":52385904},{"atb":[[22,5],[12.5,0],[26,2.5],[14.5,0]],"id":52385898},{"atb":[[70,2.5],[36,0],[50,5],[29,0]],"id":52385899}],"con":true,"img":false}]}
{"op":"mcm","clk":"11550978473","pt":1719507014718,"mc":[{"id":"1.230178177","rc":[{"atb":[[20,0]],"id":52385896}],"con":true,"img":false}]}
{"op":"mcm","clk":"11550978524","pt":1719507015798,"mc":[{"id":"1.230178177","rc":[{"atb":[[19,0]],"id":52385898}],"con":true,"img":false}]}
{"op":"mcm","clk":"11550978532","pt":1719507016110,"mc":[{"id":"1.230178177","rc":[{"atb":[[42,0]],"id":52385899}],"con":true,"img":false}]}
{"op":"mcm","clk":"11550978636","pt":1719507018597,"mc":[{"id":"1.230178177","rc":[{"atb":[[9,0],[19.5,26],[10,2.5],[9.2,5],[9.8,0]],"id":52385910},{"atl":[[75,2],[55,0]],"id":52385910},{"atb":[[9.8,11.36],[13,0]],"id":52385911},{"atl":[[190,2],[60,0]],"id":52385911},{"atb":[[12.5,8.7]],"id":52385912},{"atl":[[36,5],[26,0],[29,2.5],[30,0]],"id":52385913},{"atb":[[4.6,2.5],[7.4,54],[5.4,22.73]],"id":52385906},{"atl":[[16,0],[18.5,5.71],[11,0],[13,0]],"id":52385906},{"atb":[[16,20],[7.2,0],[8.2,13.89]],"id":52385882},{"atl":[[70,2],[46,0],[26,0]],"id":52385882},{"atb":[[12,9.09]],"id":52385883},{"atl":[[140,0],[100,7]],"id":52385883},{"atb":[[5.4,0],[4.7,27.03]],"id":52385884},{"atl":[[19.5,0],[25,4.17]],"id":52385884},{"atb":[[9.2,12.2],[7.6,0]],"id":52385885},{"atl":[[29,0]],"id":52385885},{"atb":[[36,0],[12.5,5],[9.8,11.36],[26,0],[14.5,2.5],[30,0]],"id":52385896},{"atb":[[12,9.09]],"id":52385897},{"atb":[[11,10]],"id":52385890},{"atl":[[300,0],[220,7]],"id":52385890},{"atb":[[4.5,0],[7,16.67]],"id":52385891},{"atl":[[48,2.13],[27,23.08],[60,0]],"id":52385891},{"atb":[[6.2,0],[9.8,11.36]],"id":52385892},{"atl":[[130,2],[150,0]],"id":52385892},{"atb":[[4,146.56],[3.45,40.82],[3.05,0]],"id":52385903},{"atb":[[4.9,0],[5.7,21.28]],"id":52385904},{"atl":[[16.5,0],[17,2.5],[19,5],[11.5,0],[27,3.85],[14.5,0]],"id":52385904},{"atb":[[6.8,17.24]],"id":52385905},{"atl":[[65,0],[40,5.06]],"id":52385905},{"atb":[[22,0],[9.8,11.36],[26,0],[13,5],[15,2.5]],"id":52385898},{"atl":[[150,7],[220,0]],"id":52385898},{"atb":[[32,5],[70,0],[40,2.5],[50,0],[12.5,8.7]],"id":52385899},{"atl":[[270,7],[350,0]],"id":52385899}],"con":true,"img":false}]}
{"op":"mcm","clk":"11550978641","pt":1719507018702,"mc":[{"id":"1.230178177","rc":[{"atb":[[16.5,0],[6.6,17.86]],"id":52385910},{"atl":[[130,0],[70,8.7]],"id":52385911},{"atb":[[12.5,0]],"id":52385912},{"atl":[[290,0],[380,2]],"id":52385912},{"atb":[[6.8,0],[5.4,0]],"id":52385906},{"atl":[[13,50]],"id":52385906},{"atb":[[16,0],[8.2,0],[13.5,0]],"id":52385882},{"atl":[[30,20]],"id":52385882},{"atb":[[12,0]],"id":52385883},{"atl":[[55,11.11]],"id":52385883},{"atl":[[12.5,0]],"id":52385884},{"atb":[[9.2,0]],"id":52385885},{"atl":[[34,15],[85,2],[60,0]],"id":52385885},{"atb":[[4.1,20]],"id":52385896},{"atb":[[11,0]],"id":52385890},{"atl":[[160,3.77],[220,5]],"id":52385890},{"atl":[[36,0]],"id":52385891},{"atb":[[2.8,0]],"id":52385903},{"atl":[[7.6,90.91],[7.8,0]],"id":52385903},{"atb":[[5.7,0]],"id":52385904},{"atl":[[950,0.63]],"id":52385904},{"atb":[[6.8,0]],"id":52385905},{"atl":[[21,10]],"id":52385905},{"atl":[[70,8.7]],"id":52385898}],"con":true,"img":false}]}
{"op":"mcm","clk":"11550978645","pt":1719507018805,"mc":[{"id":"1.230178177","rc":[{"atb":[[8,0],[19.5,0]],"id":52385910},{"atb":[[4.8,26.32],[7.4,0]],"id":52385906},{"atb":[[7.2,16.13],[13,15]],"id":52385882},{"atl":[[65,0],[100,5],[55,0]],"id":52385883},{"atl":[[12.5,52.17]],"id":52385884},{"atb":[[8.4,13.51]],"id":52385885},{"atb":[[9.8,0]],"id":52385896},{"atb":[[12,0]],"id":52385897},{"atl":[[340,0],[450,2]],"id":52385897},{"atl":[[300,2],[170,0]],"id":52385890},{"atb":[[7,0]],"id":52385891},{"atl":[[48,0],[27,0]],"id":52385891},{"atb":[[9.8,0]],"id":52385892},{"atb":[[4,14],[3.45,0]],"id":52385903},{"atl":[[9,5],[8.2,16.39]],"id":52385903},{"atb":[[5.3,23.26]],"id":52385904},{"atl":[[40,2.5],[21,0],[30,0]],"id":52385905},{"atb":[[9.8,0]],"id":52385898},{"atl":[[70,0],[150,5],[90,0]],"id":52385898},{"atb":[[12.5,0]],"id":52385899},{"atl":[[270,5]],"id":52385899}],"con":true,"img":false}]}
{"op":"mcm","clk":"11550978652","pt":1719507018907,"mc":[{"id":"1.230178177","rc":[{"atb":[[16,34]],"id":52385910},{"atl":[[13,0]],"id":52385906},{"atl":[[70,8.7],[140,2]],"id":52385883},{"atb":[[5.2,23.81]],"id":52385891},{"atl":[[36,17.14],[60,2]],"id":52385891},{"atb":[[11,10]],"id":52385892},{"atb":[[3.05,48.78]],"id":52385903},{"atl":[[32,19.35],[65,2]],"id":52385905},{"atl":[[95,6.38],[220,2]],"id":52385898},{"atl":[[350,2]],"id":52385899}],"con":true,"img":false}]}
{"op":"mcm","clk":"11550978656","pt":1719507019011,"mc":[{"id":"1.230178177","rc":[{"atl":[[23,0]],"id":52385913},{"atb":[[6.6,35.42]],"id":52385906},{"atl":[[14.5,35.42]],"id":52385906},{"atb":[[13,0]],"id":52385882},{"atl":[[160,0]],"id":52385890}],"con":true,"img":false}]}
{"op":"mcm","clk":"11550978661","pt":1719507019133,"mc":[{"id":"1.230178177","rc":[{"atl":[[23,27.27]],"id":52385913},{"atb":[[12.5,20]],"id":52385882},{"atl":[[70,0],[60,10.17]],"id":52385883},{"atl":[[170,3.55]],"id":52385890},{"atl":[[32,0]],"id":52385905},{"atl":[[95,0]],"id":52385898}],"con":true,"img":false}]}
{"op":"mcm","clk":"11550978665","pt":1719507019218,"mc":[{"id":"1.230178177","rc":[{"atl":[[34,15]],"id":52385905},{"atl":[[100,6.06]],"id":52385898}],"con":true,"img":false}]}
{"op":"mcm","clk":"11550978667","pt":1719507019320,"mc":[{"id":"1.230178177","rc":[{"atl":[[60,0]],"id":52385883}],"con":true,"img":false}]}
{"op":"mcm","clk":"11550978671","pt":1719507019423,"mc":[{"id":"1.230178177","rc":[{"atl":[[80,10.09]],"id":52385883}],"con":true,"img":false}]}
{"op":"mcm","clk":"11550978675","pt":1719507019527,"mc":[{"id":"1.230178177","rc":[{"atb":[[8.6,2.5],[8.2,0],[7.4,0],[7.8,5]],"id":52385891},{"atb":[[18.5,5],[21,2.5]],"id":52385892}],"con":true,"img":false}]}
{"op":"mcm","clk":"11550978680","pt":1719507019629,"mc":[{"id":"1.230178177","rc":[{"atb":[[18,0],[20,7]],"id":52385892}],"con":true,"img":false}]}
{"op":"mcm","clk":"11550978684","pt":1719507019732,"mc":[{"id":"1.230178177","rc":[{"atb":[[20,5]],"id":52385896}],"con":true,"img":false}]}
{"op":"mcm","clk":"11550978698","pt":1719507019995,"mc":[{"id":"1.230178177","rc":[{"atb":[[65,2.5],[34,0],[48,5],[28,0]],"id":52385897}],"con":true,"img":false}]}
{"op":"mcm","clk":"11550978726","pt":1719507020614,"mc":[{"id":"1.230178177","rc":[{"atl":[[34,5],[36,0],[28,2.5],[29,0]],"id":52385913}],"con":true,"img":false}]}
{"op":"mcm","clk":"11550978768","pt":1719507021700,"mc":[{"id":"1.230178177","rc":[{"atb":[[12,8]],"id":52385889}],"con":true,"img":false}]}
{"op":"mcm","clk":"11550978774","pt":1719507021809,"mc":[{"id":"1.230178177","rc":[{"atb":[[12.5,26]],"id":52385889}],"con":true,"img":false}]}
{"op":"mcm","clk":"11550978777","pt":1719507021914,"mc":[{"id":"1.230178177","rc":[{"atb":[[7.4,15.62],[4.9,0]],"id":52385889},{"atb":[[6,0]],"id":52385884}],"con":true,"img":false}]}
{"op":"mcm","clk":"11550978784","pt":1719507022013,"mc":[{"id":"1.230178177","rc":[{"atb":[[11.5,2.5]],"id":52385889},{"atb":[[7,11]],"id":52385884}],"con":true,"img":false}]}
{"op":"mcm","clk":"11550978844","pt":1719507023409,"mc":[{"id":"1.230178177","rc":[{"atl":[[9,17.5],[8.2,2.5]],"id":52385903}],"con":true,"img":false}]}
{"op":"mcm","clk":"11550978855","pt":1719507023615,"mc":[{"id":"1.230178177","rc":[{"atl":[[75,8.11]],"id":52385883}],"con":true,"img":false}]}
{"op":"mcm","clk":"11550978861","pt":1719507023721,"mc":[{"id":"1.230178177","rc":[{"atl":[[75,0],[55,2]],"id":52385910},{"atb":[[9.8,0],[14.5,7.41]],"id":52385911},{"atl":[[130,2],[190,0]],"id":52385911},{"atl":[[70,0],[46,2.22]],"id":52385882},{"atb":[[4.7,0],[5.4,22.73]],"id":52385884},{"atl":[[18.5,5.71],[25,0]],"id":52385884},{"atb":[[70,8.7]],"id":52385897}],"con":true,"img":false}]}
{"op":"mcm","clk":"11550978867","pt":1719507023823,"mc":[{"id":"1.230178177","rc":[{"atb":[[8,14.29],[6.6,0]],"id":52385910},{"atl":[[80,2.5]],"id":52385883},{"atl":[[85,0],[60,2]],"id":52385885}],"con":true,"img":false}]}
{"op":"mcm","clk":"11550978870","pt":1719507023929,"mc":[{"id":"1.230178177","rc":[{"atl":[[11.5,57.14]],"id":52385906},{"atl":[[12,54.55]],"id":52385884},{"atl":[[30,15]],"id":52385885},{"atb":[[36,17.14]],"id":52385896},{"atb":[[36,0]],"id":52385897},{"atl":[[11.5,34]],"id":52385904},{"atb":[[55,11.11]],"id":52385899}],"con":true,"img":false}]}
{"op":"mcm","clk":"11550978872","pt":1719507024030,"mc":[{"id":"1.230178177","rc":[{"atb":[[4.1,32.26]],"id":52385912},{"atl":[[18.5,0],[15.5,6.9]],"id":52385906},{"atl":[[34,0]],"id":52385885},{"atb":[[6,20],[5.2,0]],"id":52385891},{"atl":[[18.5,5.71],[27,0]],"id":52385904},{"atb":[[1.35,200]],"id":52385905},{"atl":[[65,0],[55,2],[29,15]],"id":52385905},{"atl":[[85,7.14],[200,2]],"id":52385898},{"atb":[[44,0]],"id":52385899},{"atl":[[270,0],[210,2.5],[230,0],[250,5]],"id":52385899}],"con":true,"img":false}]}
{"op":"mcm","clk":"11550978876","pt":1719507024134,"mc":[{"id":"1.230178177","rc":[{"atl":[[14.5,0]],"id":52385906},{"atb":[[1.96,100]],"id":52385883},{"atb":[[5.4,0]],"id":52385884},{"atl":[[12.5,0]],"id":52385884},{"atb":[[4.1,0]],"id":52385896},{"atb":[[2.92,52.08]],"id":52385897},{"atb":[[8.2,13.89]],"id":52385890},{"atb":[[7.4,15.62],[6,0]],"id":52385891},{"atb":[[11,0],[15,7.14]],"id":52385892},{"atl":[[950,0]],"id":52385904},{"atb":[[2.24,80.65],[1.35,0]],"id":52385905},{"atl":[[34,0]],"id":52385905},{"atl":[[100,0],[220,0]],"id":52385898},{"atl":[[200,3.02]],"id":52385899}],"con":true,"img":false}]}
{"op":"mcm","clk":"11550978878","pt":1719507024237,"mc":[{"id":"1.230178177","rc":[{"atb":[[4.7,27.03]],"id":52385884}],"con":true,"img":false}]}
{"op":"mcm","clk":"11550978883","pt":1719507024294,"mc":[{"id":"1.230178177","rc":[{"atl":[[220,0]],"id":52385899}],"con":true,"img":false}]}
{"op":"mcm","clk":"11550978887","pt":1719507024407,"mc":[{"id":"1.230178177","rc":[{"atl":[[12,0]],"id":52385884}],"con":true,"img":false}]}
{"op":"mcm","clk":"11550978891","pt":1719507024505,"mc":[{"id":"1.230178177","rc":[{"atl":[[17,32]],"id":52385884}],"con":true,"img":false}]}
{"op":"mcm","clk":"11550978907","pt":1719507025019,"mc":[{"id":"1.230178177","rc":[{"atb":[[18.5,0],[19,5],[21,0],[22,22.5]],"id":52385883},{"atb":[[10,5],[12,2.5]],"id":52385885}],"con":true,"img":false}]}
{"op":"mcm","clk":"11550978911","pt":1719507025123,"mc":[{"id":"1.230178177","rc":[{"atb":[[11.5,0],[9.8,0]],"id":52385885}],"con":true,"img":false}]}
{"op":"mcm","clk":"11550979018","pt":1719507027805,"mc":[{"id":"1.230178177","rc":[{"atb":[[11,0]],"id":52385891}],"con":true,"img":false}]}
{"op":"mcm","clk":"11550979021","pt":1719507027909,"mc":[{"id":"1.230178177","rc":[{"atb":[[13,26]],"id":52385891}],"con":true,"img":false}]}
{"op":"mcm","clk":"11550979030","pt":1719507028216,"mc":[{"id":"1.230178177","rc":[{"atl":[[18.5,0],[21,5]],"id":52385884}],"con":true,"img":false}]}
{"op":"mcm","clk":"11550979046","pt":1719507028527,"mc":[{"id":"1.230178177","rc":[{"atl":[[27,20]],"id":52385891}],"con":true,"img":false}]}
{"op":"mcm","clk":"11550979049","pt":1719507028628,"mc":[{"id":"1.230178177","rc":[{"atb":[[16,20]],"id":52385882}],"con":true,"img":false}]}
{"op":"mcm","clk":"11550979054","pt":1719507028736,"mc":[{"id":"1.230178177","rc":[{"atl":[[11,60]],"id":52385906},{"atl":[[27,20]],"id":52385882},{"atl":[[36,0]],"id":52385891},{"atl":[[7.4,63]],"id":52385903},{"atl":[[80,7.59]],"id":52385898}],"con":true,"img":false}]}
{"op":"mcm","clk":"11550979061","pt":1719507028836,"mc":[{"id":"1.230178177","rc":[{"atb":[[12.5,0]],"id":52385882},{"atl":[[15,42.86]],"id":52385884},{"atl":[[8.2,16.39]],"id":52385903},{"atl":[[85,0]],"id":52385898}],"con":true,"img":false}]}
{"op":"mcm","clk":"11550979067","pt":1719507028939,"mc":[{"id":"1.230178177","rc":[{"atl":[[11.5,0]],"id":52385906},{"atl":[[30,0]],"id":52385882},{"atl":[[9,5],[7.6,0]],"id":52385903}],"con":true,"img":false}]}
{"op":"mcm","clk":"11550979072","pt":1719507029042,"mc":[{"id":"1.230178177","rc":[{"atl":[[17,0]],"id":52385884}],"con":true,"img":false}]}
{"op":"mcm","clk":"11550979077","pt":1719507029147,"mc":[{"id":"1.230178177","rc":[{"atb":[[1.96,0],[2.76,56.82]],"id":52385883},{"atb":[[2.92,0]],"id":52385897},{"atb":[[8.2,0],[4.2,31.25]],"id":52385890},{"atb":[[1.97,103.09]],"id":52385905}],"con":true,"img":false}]}
{"op":"mcm","clk":"11550979082","pt":1719507029216,"mc":[{"id":"1.230178177","rc":[{"atb":[[2.24,0]],"id":52385905}],"con":true,"img":false}]}
{"op":"mcm","clk":"11550979091","pt":1719507029515,"mc":[{"id":"1.230178177","rc":[{"atl":[[27,0]],"id":52385891}],"con":true,"img":false}]}
{"op":"mcm","clk":"11550979094","pt":1719507029628,"mc":[{"id":"1.230178177","rc":[{"atl":[[44,13.95]],"id":52385891}],"con":true,"img":false}]}
{"op":"mcm","clk":"11550979112","pt":1719507030030,"mc":[{"id":"1.230178177","rc":[{"atl":[[28,15]],"id":52385885}],"con":true,"img":false}]}
{"op":"mcm","clk":"11550979124","pt":1719507030237,"mc":[{"id":"1.230178177","rc":[{"atl":[[30,0]],"id":52385885}],"con":true,"img":false}]}
{"op":"mcm","clk":"11550979152","pt":1719507030810,"mc":[{"id":"1.230178177","rc":[{"atb":[[20,0]],"id":52385911},{"atb":[[11,0]],"id":52385913},{"atb":[[20,0]],"id":52385896},{"atb":[[20,0]],"id":52385892}],"con":true,"img":false}]}
{"op":"mcm","clk":"11550979156","pt":1719507030912,"mc":[{"id":"1.230178177","rc":[{"atb":[[24,6]],"id":52385911},{"atb":[[12,11]],"id":52385913},{"atb":[[24,5]],"id":52385896},{"atb":[[32,5],[38,0],[40,2.5],[30,0]],"id":52385890},{"atb":[[24,7]],"id":52385892}],"con":true,"img":false}]}
{"op":"mcm","clk":"11550979188","pt":1719507031738,"mc":[{"id":"1.230178177","rc":[{"atb":[[17.5,26]],"id":52385889}],"con":true,"img":false}]}
{"op":"mcm","clk":"11550979191","pt":1719507031840,"mc":[{"id":"1.230178177","rc":[{"atb":[[12,0]],"id":52385889}],"con":true,"img":false}]}
{"op":"mcm","clk":"11550979195","pt":1719507031943,"mc":[{"id":"1.230178177","rc":[{"atb":[[12.5,0],[15,8]],"id":52385889},{"atl":[[34,0]],"id":52385889}],"con":true,"img":false}]}
{"op":"mcm","clk":"11550979199","pt":1719507032044,"mc":[{"id":"1.230178177","rc":[{"atl":[[36,17.14]],"id":52385889}],"con":true,"img":false}]}
{"op":"mcm","clk":"11550979209","pt":1719507032202,"mc":[{"id":"1.230178177","rc":[{"atl":[[36,0]],"id":52385889}],"con":true,"img":false}]}
{"op":"mcm","clk":"11550979212","pt":1719507032306,"mc":[{"id":"1.230178177","rc":[{"atl":[[40,15]],"id":52385889}],"con":true,"img":false}]}
{"op":"mcm","clk":"11550979217","pt":1719507032409,"mc":[{"id":"1.230178177","rc":[{"atl":[[48,2.13],[55,0]],"id":52385889}],"con":true,"img":false}]}
{"op":"mcm","clk":"11550979219","pt":1719507032513,"mc":[{"id":"1.230178177","rc":[{"atl":[[48,0],[50,7.04]],"id":52385889}],"con":true,"img":false}]}
{"op":"mcm","clk":"11550979230","pt":1719507032925,"mc":[{"id":"1.230178177","rc":[{"atb":[[7,0]],"id":52385884}],"con":true,"img":false}]}
{"op":"mcm","clk":"11550979234","pt":1719507033029,"mc":[{"id":"1.230178177","rc":[{"atb":[[8,76.48]],"id":52385884}],"con":true,"img":false}]}
{"op":"mcm","clk":"11550979238","pt":1719507033130,"mc":[{"id":"1.230178177","rc":[{"atb":[[44,12.1]],"id":52385890}],"con":true,"img":false}]}
{"op":"mcm","clk":"11550979242","pt":1719507033232,"mc":[{"id":"1.230178177","rc":[{"atl":[[9,17.5],[8.2,2.5]],"id":52385903}],"con":true,"img":false}]}
{"op":"mcm","clk":"11550979246","pt":1719507033341,"mc":[{"id":"1.230178177","rc":[{"atb":[[42,0]],"id":52385890}],"con":true,"img":false}]}
{"op":"mcm","clk":"11550979252","pt":1719507033440,"mc":[{"id":"1.230178177","rc":[{"atl":[[19.5,5.41],[21,0]],"id":52385884}],"con":true,"img":false}]}
{"op":"mcm","clk":"11550979281","pt":1719507034651,"mc":[{"id":"1.230178177","rc":[{"atb":[[17.5,0]],"id":52385889},{"atb":[[16,0]],"id":52385882},{"atb":[[2.1,90.91],[2.76,0]],"id":52385883},{"atb":[[5.2,23.81],[4.7,0]],"id":52385884},{"atl":[[12,54.55]],"id":52385884},{"atb":[[2.18,84.75],[4.2,0]],"id":52385890},{"atb":[[1.97,0],[1.06,237.05]],"id":52385905},{"atl":[[80,0]],"id":52385898}],"con":true,"img":false}]}
{"op":"mcm","clk":"11550979288","pt":1719507034662,"mc":[{"id":"1.230178177","rc":[{"atl":[[29,0]],"id":52385905}],"con":true,"img":false}]}
{"op":"mcm","clk":"11550979294","pt":1719507034673,"mc":[{"id":"1.230178177","rc":[{"atb":[[15,29]],"id":52385889},{"atb":[[9.4,20]],"id":52385882},{"atl":[[15,0]],"id":52385884},{"atl":[[38,15]],"id":52385905},{"atl":[[100,6.06]],"id":52385898}],"con":true,"img":false}]}
{"op":"mcm","clk":"11550979338","pt":1719507035726,"mc":[{"id":"1.230178177","rc":[{"atb":[[10,10]],"id":52385882}],"con":true,"img":false}]}
{"op":"mcm","clk":"11550979355","pt":1719507036242,"mc":[{"id":"1.230178177","rc":[{"atb":[[36,6.58]],"id":52385899}],"con":true,"img":false}]}
{"op":"mcm","clk":"11550979369","pt":1719507036449,"mc":[{"id":"1.230178177","rc":[{"atb":[[36,0]],"id":52385899}],"con":true,"img":false}]}
{"op":"mcm","clk":"11550979422","pt":1719507037846,"mc":[{"id":"1.230178177","rc":[{"atb":[[13,15]],"id":52385891}],"con":true,"img":false}]}
{"op":"mcm","clk":"11550979428","pt":1719507037948,"mc":[{"id":"1.230178177","rc":[{"atb":[[11,11]],"id":52385891}],"con":true,"img":false}]}
{"op":"mcm","clk":"11550979443","pt":1719507038316,"mc":[{"id":"1.230178177","rc":[{"atl":[[27,15]],"id":52385885},{"atl":[[36,17.14]],"id":52385891}],"con":true,"img":false}]}
{"op":"mcm","clk":"11550979448","pt":1719507038420,"mc":[{"id":"1.230178177","rc":[{"atb":[[10.5,30]],"id":52385882},{"atl":[[6.8,63]],"id":52385903},{"atl":[[90,6.74]],"id":52385898}],"con":true,"img":false}]}
{"op":"mcm","clk":"11550979453","pt":1719507038524,"mc":[{"id":"1.230178177","rc":[{"atl":[[28,0]],"id":52385885},{"atl":[[44,0]],"id":52385891},{"atl":[[9,5],[6.6,17.86]],"id":52385903}],"con":true,"img":false}]}
{"op":"mcm","clk":"11550979458","pt":1719507038625,"mc":[{"id":"1.230178177","rc":[{"atb":[[9.4,0]],"id":52385882},{"atl":[[7.4,0]],"id":52385903},{"atl":[[100,0]],"id":52385898}],"con":true,"img":false}]}
{"op":"mcm","clk":"11550979479","pt":1719507039141,"mc":[{"id":"1.230178177","rc":[{"atl":[[310,5]],"id":52385897},{"atb":[[5.7,21.28]],"id":52385891},{"atl":[[9,0],[8.6,5],[8.2,0],[7.8,2.5]],"id":52385903},{"atl":[[270,2.5],[310,5]],"id":52385899}],"con":true,"img":false}]}
{"op":"mcm","clk":"11550979484","pt":1719507039243,"mc":[{"id":"1.230178177","rc":[{"atb":[[4.1,0]],"id":52385912},{"atb":[[2.1,0]],"id":52385883},{"atl":[[18,5.88],[19.5,0]],"id":52385884},{"atb":[[19.5,0]],"id":52385885},{"atl":[[230,2.62]],"id":52385897},{"atb":[[2.18,0]],"id":52385890},{"atl":[[180,0],[210,2.5],[220,0],[250,5]],"id":52385890},{"atb":[[7.4,0]],"id":52385891},{"atl":[[75,0],[90,2.5],[95,0],[120,5]],"id":52385892},{"atb":[[1.06,0]],"id":52385905},{"atl":[[70,2],[55,0]],"id":52385905},{"atl":[[140,2.5],[150,0],[90,0],[180,5],[110,0]],"id":52385898},{"atl":[[210,0],[420,2],[250,0]],"id":52385899}],"con":true,"img":false}]}
{"op":"mcm","clk":"11550979489","pt":1719507039350,"mc":[{"id":"1.230178177","rc":[{"atb":[[6.6,0]],"id":52385906},{"atl":[[11.5,57.14]],"id":52385884},{"atb":[[12.5,15]],"id":52385885},{"atl":[[70,0]],"id":52385892},{"atl":[[110,5.5],[250,2]],"id":52385898},{"atl":[[350,0],[200,0]],"id":52385899}],"con":true,"img":false}]}
{"op":"mcm","clk":"11550979492","pt":1719507039451,"mc":[{"id":"1.230178177","rc":[{"atb":[[6.4,76.64]],"id":52385906},{"atl":[[12,0]],"id":52385884},{"atl":[[170,0]],"id":52385890},{"atl":[[130,0],[75,8.11],[160,2]],"id":52385892},{"atl":[[200,0]],"id":52385898},{"atl":[[260,2.32]],"id":52385899}],"con":true,"img":false}]}
{"op":"mcm","clk":"11550979497","pt":1719507039552,"mc":[{"id":"1.230178177","rc":[{"atl":[[180,3.35]],"id":52385890}],"con":true,"img":false}]}
{"op":"mcm","clk":"11550979508","pt":1719507039718,"mc":[{"id":"1.230178177","rc":[{"atb":[[16,6]],"id":52385885}],"con":true,"img":false}]}
{"op":"mcm","clk":"11550979537","pt":1719507040231,"mc":[{"id":"1.230178177","rc":[{"atb":[[6.2,39.06]],"id":52385906}],"con":true,"img":false}]}
{"op":"mcm","clk":"11550979547","pt":1719507040440,"mc":[{"id":"1.230178177","rc":[{"atb":[[6.2,0]],"id":52385906},{"atl":[[75,0]],"id":52385892}],"con":true,"img":false}]}
{"op":"mcm","clk":"11550979552","pt":1719507040542,"mc":[{"id":"1.230178177","rc":[{"atl":[[180,0]],"id":52385890},{"atl":[[85,7.14]],"id":52385892}],"con":true,"img":false}]}
{"op":"mcm","clk":"11550979555","pt":1719507040648,"mc":[{"id":"1.230178177","rc":[{"atl":[[200,3.02]],"id":52385890}],"con":true,"img":false}]}
{"op":"mcm","clk":"11550979568","pt":1719507040851,"mc":[{"id":"1.230178177","rc":[{"atb":[[24,0]],"id":52385892}],"con":true,"img":false}]}
{"op":"mcm","clk":"11550979621","pt":1719507041731,"mc":[{"id":"1.230178177","rc":[{"atl":[[38,16.22]],"id":52385889}],"con":true,"img":false}]}
{"op":"mcm","clk":"11550979629","pt":1719507041838,"mc":[{"id":"1.230178177","rc":[{"atb":[[15,21]],"id":52385889}],"con":true,"img":false}]}
{"op":"mcm","clk":"11550979636","pt":1719507041943,"mc":[{"id":"1.230178177","rc":[{"atb":[[13,8]],"id":52385889},{"atl":[[40,0]],"id":52385889}],"con":true,"img":false}]}
{"op":"mcm","clk":"11550979644","pt":1719507042047,"mc":[{"id":"1.230178177","rc":[{"atb":[[15,0]],"id":52385889}],"con":true,"img":false}]}
{"op":"mcm","clk":"11550979648","pt":1719507042147,"mc":[{"id":"1.230178177","rc":[{"atb":[[14.5,21]],"id":52385889}],"con":true,"img":false}]}
{"op":"mcm","clk":"11550979674","pt":1719507042560,"mc":[{"id":"1.230178177","rc":[{"atb":[[8.2,0],[7.4,0],[7.6,5],[8.4,2.5]],"id":52385905}],"con":true,"img":false}]}
{"op":"mcm","clk":"11550979690","pt":1719507042820,"mc":[{"id":"1.230178177","rc":[{"atb":[[12,0]],"id":52385913}],"con":true,"img":false}]}
{"op":"mcm","clk":"11550979701","pt":1719507042924,"mc":[{"id":"1.230178177","rc":[{"atb":[[13,11]],"id":52385913},{"atl":[[6.6,0],[7.8,17.21]],"id":52385903}],"con":true,"img":false}]}
{"op":"mcm","clk":"11550979712","pt":1719507043029,"mc":[{"id":"1.230178177","rc":[{"atb":[[4.3,0],[4.4,2.5]],"id":52385904}],"con":true,"img":false}]}
{"op":"mcm","clk":"11550979719","pt":1719507043131,"mc":[{"id":"1.230178177","rc":[{"atl":[[8.6,18.16],[7.8,2.5]],"id":52385903}],"con":true,"img":false}]}
{"op":"mcm","clk":"11550979766","pt":1719507043858,"mc":[{"id":"1.230178177","rc":[{"atb":[[8,65.48]],"id":52385884}],"con":true,"img":false}]}
{"op":"mcm","clk":"11550979774","pt":1719507043963,"mc":[{"id":"1.230178177","rc":[{"atb":[[4.5,31.07],[5.2,0],[7,11]],"id":52385884}],"con":true,"img":false}]}
{"op":"mcm","clk":"11550979794","pt":1719507044171,"mc":[{"id":"1.230178177","rc":[{"atl":[[34,18.18]],"id":52385905}],"con":true,"img":false}]}
{"op":"mcm","clk":"11550979800","pt":1719507044225,"mc":[{"id":"1.230178177","rc":[{"atb":[[10,5],[11.5,0],[12,2.5],[18.5,30.08],[9.8,0]],"id":52385889},{"atb":[[1.2,200]],"id":52385883},{"atb":[[8,0]],"id":52385884},{"atl":[[16.5,5],[17.5,0],[14.5,2.5],[15.5,0]],"id":52385884},{"atl":[[34,2.5],[36,0],[42,5],[44,0]],"id":52385885},{"atl":[[300,0],[350,2]],"id":52385890},{"atb":[[3.35,42.55],[5.7,0]],"id":52385891},{"atl":[[38,0],[60,7]],"id":52385891},{"atb":[[9.2,12.2],[15,0]],"id":52385892},{"atb":[[5.6,21.74],[5.3,0],[8.4,70.52]],"id":52385904},{"atl":[[38,0]],"id":52385905}],"con":true,"img":false}]}
{"op":"mcm","clk":"11550979803","pt":1719507044328,"mc":[{"id":"1.230178177","rc":[{"atb":[[14.5,30]],"id":52385882},{"atb":[[7.8,84.14]],"id":52385884},{"atl":[[11.5,0]],"id":52385904}],"con":true,"img":false}]}
{"op":"mcm","clk":"11550979808","pt":1719507044431,"mc":[{"id":"1.230178177","rc":[{"atb":[[18.5,0],[14.5,0]],"id":52385889},{"atb":[[8,0]],"id":52385904},{"atl":[[18.5,0],[18,35.29],[21,5]],"id":52385904}],"con":true,"img":false}]}
{"op":"mcm","clk":"11550979816","pt":1719507044537,"mc":[{"id":"1.230178177","rc":[{"atb":[[18,19.08]],"id":52385889},{"atb":[[10.5,0]],"id":52385882},{"atb":[[7.8,0]],"id":52385884},{"atl":[[34,18.18]],"id":52385891}],"con":true,"img":false}]}
{"op":"mcm","clk":"11550979823","pt":1719507044639,"mc":[{"id":"1.230178177","rc":[{"atb":[[7.4,32]],"id":52385884}],"con":true,"img":false}]}
{"op":"mcm","clk":"11550979829","pt":1719507044846,"mc":[{"id":"1.230178177","rc":[{"atl":[[36,0]],"id":52385891}],"con":true,"img":false}]}
{"op":"mcm","clk":"11550979938","pt":1719507046859,"mc":[{"id":"1.230178177","rc":[{"atl":[[40,17.5],[42,0],[48,5],[50,0]],"id":52385910}],"con":true,"img":false}]}
{"op":"mcm","clk":"11550979944","pt":1719507046963,"mc":[{"id":"1.230178177","rc":[{"atl":[[50,2.04],[55,0]],"id":52385910}],"con":true,"img":false}]}
{"op":"mcm","clk":"11550980005","pt":1719507047851,"mc":[{"id":"1.230178177","rc":[{"atb":[[11,0]],"id":52385891}],"con":true,"img":false}]}
{"op":"mcm","clk":"11550980012","pt":1719507047952,"mc":[{"id":"1.230178177","rc":[{"atb":[[14,11]],"id":52385891}],"con":true,"img":false}]}
{"op":"mcm","clk":"11550980019","pt":1719507048054,"mc":[{"id":"1.230178177","rc":[{"atb":[[14.5,36]],"id":52385891},{"atl":[[6.4,64.32]],"id":52385903}],"con":true,"img":false}]}
{"op":"mcm","clk":"11550980025","pt":1719507048155,"mc":[{"id":"1.230178177","rc":[{"atl":[[8.6,5],[6.4,82.84]],"id":52385903}],"con":true,"img":false}]}
{"op":"mcm","clk":"11550980032","pt":1719507048258,"mc":[{"id":"1.230178177","rc":[{"atb":[[13,0]],"id":52385891},{"atl":[[6.8,0]],"id":52385903}],"con":true,"img":false}]}
{"op":"mcm","clk":"11550980061","pt":1719507048835,"mc":[{"id":"1.230178177","rc":[{"atb":[[17.5,17]],"id":52385885}],"con":true,"img":false}]}
{"op":"mcm","clk":"11550980080","pt":1719507049035,"mc":[{"id":"1.230178177","rc":[{"atb":[[4.5,2.5],[5.1,24.39]],"id":52385884},{"atb":[[12.5,0]],"id":52385885}],"con":true,"img":false}]}
{"op":"mcm","clk":"11550980096","pt":1719507049444,"mc":[{"id":"1.230178177","rc":[{"atb":[[16,8]],"id":52385910},{"atl":[[38,2.7],[21,30]],"id":52385913},{"atb":[[17.5,0]],"id":52385885},{"atl":[[530,2],[350,5],[230,0],[450,0]],"id":52385897},{"atl":[[290,5]],"id":52385890},{"atb":[[2.86,53.76],[3.35,0]],"id":52385891},{"atl":[[34,0]],"id":52385891},{"atl":[[34,0],[70,7],[40,0],[48,0],[50,2.5]],"id":52385905},{"atl":[[110,0]],"id":52385898}],"con":true,"img":false}]}
{"op":"mcm","clk":"11550980102","pt":1719507049548,"mc":[{"id":"1.230178177","rc":[{"atl":[[44,0],[23,0]],"id":52385913},{"atb":[[1.2,0]],"id":52385883},{"atb":[[16,28]],"id":52385885},{"atl":[[160,0],[180,2.5],[220,5],[120,0]],"id":52385896},{"atl":[[270,2.23]],"id":52385897},{"atl":[[210,0]],"id":52385890},{"atl":[[70,2],[44,13.95]],"id":52385891},{"atl":[[70,5],[80,2],[46,13.33]],"id":52385905},{"atl":[[130,4.65]],"id":52385898}],"con":true,"img":false}]}
{"op":"mcm","clk":"11550980108","pt":1719507049651,"mc":[{"id":"1.230178177","rc":[{"atl":[[270,0],[130,4.65],[240,2]],"id":52385896},{"atl":[[270,0]],"id":52385897},{"atl":[[200,0]],"id":52385890},{"atl":[[60,5]],"id":52385891},{"atl":[[38,16.22],[46,0]],"id":52385905}],"con":true,"img":false}]}
{"op":"mcm","clk":"11550980113","pt":1719507049754,"mc":[{"id":"1.230178177","rc":[{"atb":[[16,22]],"id":52385885},{"atl":[[350,0],[400,2],[210,2.87]],"id":52385890}],"con":true,"img":false}]}
{"op":"mcm","clk":"11550980116","pt":1719507049855,"mc":[{"id":"1.230178177","rc":[{"atb":[[14,6]],"id":52385885},{"atl":[[130,0]],"id":52385896},{"atl":[[280,2.15]],"id":52385897}],"con":true,"img":false}]}
{"op":"mcm","clk":"11550980121","pt":1719507049958,"mc":[{"id":"1.230178177","rc":[{"atb":[[16,0]],"id":52385885},{"atl":[[170,3.55]],"id":52385896}],"con":true,"img":false}]}
{"op":"mcm","clk":"11550980126","pt":1719507050062,"mc":[{"id":"1.230178177","rc":[{"atb":[[15.5,22]],"id":52385885}],"con":true,"img":false}]}
{"op":"mcm","clk":"11550980159","pt":1719507050542,"mc":[{"id":"1.230178177","rc":[{"atb":[[15.5,26]],"id":52385885},{"atl":[[170,6.05],[180,0],[210,5],[220,0]],"id":52385896}],"con":true,"img":false}]}
{"op":"mcm","clk":"11550980175","pt":1719507050838,"mc":[{"id":"1.230178177","rc":[{"atb":[[15.5,22]],"id":52385885},{"atl":[[280,0]],"id":52385897},{"atl":[[210,0]],"id":52385890}],"con":true,"img":false}]}
{"op":"mcm","clk":"11550980179","pt":1719507050942,"mc":[{"id":"1.230178177","rc":[{"atl":[[300,2.01]],"id":52385897},{"atl":[[240,2.51]],"id":52385890}],"con":true,"img":false}]}
{"op":"mcm","clk":"11550980193","pt":1719507051353,"mc":[{"id":"1.230178177","rc":[{"atb":[[55,0]],"id":52385899}],"con":true,"img":false}]}
{"op":"mcm","clk":"11550980201","pt":1719507051458,"mc":[{"id":"1.230178177","rc":[{"atl":[[12,2.5],[14,5],[15,0]],"id":52385906},{"atb":[[38,2.5],[12.5,0],[14.5,0],[30,5]],"id":52385896},{"atb":[[50,12.24]],"id":52385899}],"con":true,"img":false}]}
{"op":"mcm","clk":"11550980205","pt":1719507051560,"mc":[{"id":"1.230178177","rc":[{"atl":[[14.5,7.41],[15.5,0]],"id":52385906},{"atb":[[38,16.5]],"id":52385896},{"atb":[[85,7.14]],"id":52385897},{"atb":[[32,19.3]],"id":52385898}],"con":true,"img":false}]}
{"op":"mcm","clk":"11550980213","pt":1719507051764,"mc":[{"id":"1.230178177","rc":[{"atb":[[36,0]],"id":52385896},{"atb":[[70,0]],"id":52385897},{"atb":[[55,11.11]],"id":52385890},{"atb":[[25,0]],"id":52385898}],"con":true,"img":false}]}
{"op":"mcm","clk":"11550980218","pt":1719507051869,"mc":[{"id":"1.230178177","rc":[{"atb":[[24,0]],"id":52385896}],"con":true,"img":false}]}
{"op":"mcm","clk":"11550980228","pt":1719507051971,"mc":[{"id":"1.230178177","rc":[{"atb":[[44,0]],"id":52385890}],"con":true,"img":false}]}
{"op":"mcm","clk":"11550980238","pt":1719507052177,"mc":[{"id":"1.230178177","rc":[{"atb":[[13,0]],"id":52385889},{"atb":[[6,0]],"id":52385904}],"con":true,"img":false}]}
{"op":"mcm","clk":"11550980241","pt":1719507052247,"mc":[{"id":"1.230178177","rc":[{"atb":[[15,8]],"id":52385889},{"atb":[[5.6,0],[4.4,31.91],[7,12]],"id":52385904}],"con":true,"img":false}]}
{"op":"mcm","clk":"11550980247","pt":1719507052451,"mc":[{"id":"1.230178177","rc":[{"atl":[[7.8,17.21]],"id":52385903},{"atb":[[5.6,21.74],[4.4,2.5]],"id":52385904}],"con":true,"img":false}]}
{"op":"mcm","clk":"11550980250","pt":1719507052543,"mc":[{"id":"1.230178177","rc":[{"atl":[[8.6,18.16],[6.4,64.32],[7.8,2.5]],"id":52385903}],"con":true,"img":false}]}
{"op":"mcm","clk":"11550980272","pt":1719507052855,"mc":[{"id":"1.230178177","rc":[{"atb":[[13,0]],"id":52385913}],"con":true,"img":false}]}
{"op":"mcm","clk":"11550980281","pt":1719507052958,"mc":[{"id":"1.230178177","rc":[{"atb":[[12,11]],"id":52385913}],"con":true,"img":false}]}
{"op":"mcm","clk":"11550980311","pt":1719507053640,"mc":[{"id":"1.230178177","rc":[{"atb":[[8.8,67.48]],"id":52385904}],"con":true,"img":false}]}
{"op":"mcm","clk":"11550980318","pt":1719507053849,"mc":[{"id":"1.230178177","rc":[{"atb":[[8.4,0]],"id":52385904},{"atl":[[16.5,38.71]],"id":52385904}],"con":true,"img":false}]}
{"op":"mcm","clk":"11550980325","pt":1719507054057,"mc":[{"id":"1.230178177","rc":[{"atl":[[18,0]],"id":52385904}],"con":true,"img":false}]}
{"op":"mcm","clk":"11550980351","pt":1719507054679,"mc":[{"id":"1.230178177","rc":[{"atb":[[5.4,22.73]],"id":52385912},{"atl":[[140,2.5],[170,0],[180,5]],"id":52385912},{"atb":[[5.6,21.74],[19.5,30.08],[7.4,0]],"id":52385889},{"atb":[[4.1,32.26]],"id":52385883},{"atl":[[140,0],[70,2.5],[80,0],[90,5],[100,0],[110,2]],"id":52385883},{"atb":[[38,14],[20,5],[24,2.5],[30,0]],"id":52385896},{"atl":[[530,0],[270,2.5],[350,2]],"id":52385897},{"atl":[[290,0],[200,2.5],[240,7.51],[250,0]],"id":52385890},{"atb":[[2.86,0]],"id":52385891},{"atb":[[6.4,18.52],[9.2,0]],"id":52385892},{"atb":[[2.28,2.5],[2.18,0],[2.26,0],[2.2,5]],"id":52385903},{"atb":[[5.6,0],[5,25]],"id":52385904},{"atb":[[2.26,79.37]],"id":52385905},{"atl":[[70,0],[38,18.72],[80,0],[46,5],[50,0],[55,2]],"id":52385905},{"atl":[[180,0],[190,2],[100,2.5],[250,0]],"id":52385898},{"atb":[[5.5,22.22]],"id":52385899},{"atl":[[310,7],[420,0]],"id":52385899}],"con":true,"img":false}]}
{"op":"mcm","clk":"11550980356","pt":1719507054781,"mc":[{"id":"1.230178177","rc":[{"atl":[[150,4.03],[380,0],[240,2]],"id":52385912},{"atb":[[18,0]],"id":52385889},{"atb":[[10,0]],"id":52385882},{"atl":[[70,11.2]],"id":52385883},{"atl":[[330,2],[350,0]],"id":52385897}],"con":true,"img":false}]}
{"op":"mcm","clk":"11550980364","pt":1719507054852,"mc":[{"id":"1.230178177","rc":[{"atb":[[16,20]],"id":52385882},{"atl":[[75,0]],"id":52385883},{"atl":[[38,16.22]],"id":52385891}],"con":true,"img":false}]}
{"op":"mcm","clk":"11550980372","pt":1719507054943,"mc":[{"id":"1.230178177","rc":[{"atl":[[160,0]],"id":52385912},{"atb":[[14.5,0]],"id":52385882},{"atb":[[50,14.24]],"id":52385899}],"con":true,"img":false}]}
{"op":"mcm","clk":"11550980379","pt":1719507055044,"mc":[{"id":"1.230178177","rc":[{"atl":[[44,0]],"id":52385891}],"con":true,"img":false}]}
{"op":"mcm","clk":"11550980386","pt":1719507055148,"mc":[{"id":"1.230178177","rc":[{"atb":[[50,2]],"id":52385899}],"con":true,"img":false}]}
{"op":"mcm","clk":"11550980397","pt":1719507055251,"mc":[{"id":"1.230178177","rc":[{"atb":[[48,10]],"id":52385899}],"con":true,"img":false}]}
{"op":"mcm","clk":"11550980412","pt":1719507055460,"mc":[{"id":"1.230178177","rc":[{"atb":[[6.8,76.64]],"id":52385906}],"con":true,"img":false}]}
{"op":"mcm","clk":"11550980425","pt":1719507055667,"mc":[{"id":"1.230178177","rc":[{"atb":[[6.4,0]],"id":52385906}],"con":true,"img":false}]}
{"op":"mcm","clk":"11550980525","pt":1719507057850,"mc":[{"id":"1.230178177","rc":[{"atb":[[7,0]],"id":52385884}],"con":true,"img":false}]}
{"op":"mcm","clk":"11550980529","pt":1719507057946,"mc":[{"id":"1.230178177","rc":[{"atb":[[6,11]],"id":52385884}],"con":true,"img":false}]}
{"op":"mcm","clk":"11550980532","pt":1719507058049,"mc":[{"id":"1.230178177","rc":[{"atb":[[5.1,0],[4.5,31.07]],"id":52385884}],"con":true,"img":false}]}
{"op":"mcm","clk":"11550980536","pt":1719507058152,"mc":[{"id":"1.230178177","rc":[{"atb":[[4.5,2.5],[5.1,24.39]],"id":52385884}],"con":true,"img":false}]}
{"op":"mcm","clk":"11550980577","pt":1719507058871,"mc":[{"id":"1.230178177","rc":[{"atl":[[260,2.32]],"id":52385897},{"atl":[[90,6.74]],"id":52385898}],"con":true,"img":false}]}
{"op":"mcm","clk":"11550980588","pt":1719507059079,"mc":[{"id":"1.230178177","rc":[{"atl":[[160,3.77]],"id":52385896},{"atl":[[300,0]],"id":52385897},{"atl":[[190,3.17]],"id":52385890},{"atl":[[130,0]],"id":52385898}],"con":true,"img":false}]}
{"op":"mcm","clk":"11550980595","pt":1719507059182,"mc":[{"id":"1.230178177","rc":[{"atl":[[170,2.5],[210,7],[240,0]],"id":52385896},{"atl":[[320,2],[400,0],[240,5]],"id":52385890}],"con":true,"img":false}]}
{"op":"mcm","clk":"11550980616","pt":1719507059853,"mc":[{"id":"1.230178177","rc":[{"atb":[[14,0]],"id":52385885}],"con":true,"img":false}]}
{"op":"mcm","clk":"11550980619","pt":1719507059957,"mc":[{"id":"1.230178177","rc":[{"atb":[[13,6]],"id":52385885}],"con":true,"img":false}]}
{"op":"mcm","clk":"11550980659","pt":1719507060781,"mc":[{"id":"1.230178177","rc":[{"atb":[[55,10]],"id":52385899}],"con":true,"img":false}]}
{"op":"mcm","clk":"11550980665","pt":1719507060884,"mc":[{"id":"1.230178177","rc":[{"atb":[[34,15]],"id":52385898},{"atb":[[48,0]],"id":52385899}],"con":true,"img":false}]}
{"op":"mcm","clk":"11550980678","pt":1719507061090,"mc":[{"id":"1.230178177","rc":[{"atb":[[60,10.17]],"id":52385890},{"atb":[[32,0]],"id":52385898}],"con":true,"img":false}]}
{"op":"mcm","clk":"11550980690","pt":1719507061265,"mc":[{"id":"1.230178177","rc":[{"atb":[[55,0]],"id":52385890}],"con":true,"img":false}]}
{"op":"mcm","clk":"11550980718","pt":1719507061771,"mc":[{"id":"1.230178177","rc":[{"atl":[[38,0]],"id":52385889}],"con":true,"img":false}]}
{"op":"mcm","clk":"11550980723","pt":1719507061874,"mc":[{"id":"1.230178177","rc":[{"atb":[[16.5,0],[18.5,0],[18,5],[20,2.5]],"id":52385911},{"atl":[[40,15.38],[50,5],[60,2]],"id":52385889},{"atb":[[13,0],[26,5],[15,0],[30,2.5]],"id":52385898},{"atb":[[32,0],[65,2.5],[40,0],[48,5]],"id":52385899}],"con":true,"img":false}]}
{"op":"mcm","clk":"11550980766","pt":1719507062862,"mc":[{"id":"1.230178177","rc":[{"atb":[[15,0]],"id":52385889}],"con":true,"img":false}]}
{"op":"mcm","clk":"11550980772","pt":1719507062983,"mc":[{"id":"1.230178177","rc":[{"atb":[[14,8]],"id":52385889}],"con":true,"img":false}]}
{"op":"mcm","clk":"11550980803","pt":1719507063653,"mc":[{"id":"1.230178177","rc":[{"atb":[[6,20],[5.4,0]],"id":52385912},{"atl":[[220,2],[240,0]],"id":52385912},{"atb":[[5.6,0],[6.4,18.52]],"id":52385889},{"atl":[[55,2],[60,0]],"id":52385889},{"atb":[[5.1,0],[5.4,22.73]],"id":52385884},{"atl":[[16.5,11.45],[18,0]],"id":52385884},{"atl":[[46,2.22],[60,0]],"id":52385885},{"atb":[[5.4,22.73]],"id":52385897},{"atl":[[310,7],[330,0]],"id":52385897},{"atb":[[1.44,200]],"id":52385890},{"atb":[[1.87,114.94]],"id":52385891},{"atb":[[6.4,0],[8.2,13.89]],"id":52385892},{"atb":[[3.15,46.51],[2.26,0]],"id":52385905},{"atl":[[170,2],[190,0]],"id":52385898},{"atb":[[10,11.11],[5.5,0]],"id":52385899}],"con":true,"img":false}]}
{"op":"mcm","clk":"11550980808","pt":1719507063757,"mc":[{"id":"1.230178177","rc":[{"atb":[[14,0]],"id":52385891},{"atb":[[32,19.35],[30,0]],"id":52385892},{"atb":[[4,2]],"id":52385903}],"con":true,"img":false}]}
{"op":"mcm","clk":"11550980813","pt":1719507063857,"mc":[{"id":"1.230178177","rc":[{"atb":[[16,11]],"id":52385891},{"atb":[[3,12]],"id":52385903}],"con":true,"img":false}]}
{"op":"mcm","clk":"11550980819","pt":1719507063963,"mc":[{"id":"1.230178177","rc":[{"atl":[[130,4.65]],"id":52385912},{"atb":[[16.5,32]],"id":52385891}],"con":true,"img":false}]}
{"op":"mcm","clk":"11550980828","pt":1719507064170,"mc":[{"id":"1.230178177","rc":[{"atl":[[150,0]],"id":52385912},{"atb":[[14.5,0]],"id":52385891}],"con":true,"img":false}]}
{"op":"mcm","clk":"11550980844","pt":1719507064486,"mc":[{"id":"1.230178177","rc":[{"atb":[[70,8.7]],"id":52385899}],"con":true,"img":false}]}
{"op":"mcm","clk":"11550980853","pt":1719507064687,"mc":[{"id":"1.230178177","rc":[{"atb":[[55,0]],"id":52385899}],"con":true,"img":false}]}
{"op":"mcm","clk":"11550980859","pt":1719507064853,"mc":[{"id":"1.230178177","rc":[{"atb":[[50,0]],"id":52385899}],"con":true,"img":false}]}
