{"op":"mcm","clk":"11536832981","pt":1719431775512,"mc":[{"id":"1.230180128","marketDefinition":{"bspMarket":true,"turnInPlayEnabled":false,"persistenceEnabled":false,"marketBaseRate":5.0,"eventId":"33376437","eventTypeId":"4339","numberOfWinners":1,"bettingType":"ODDS","marketType":"WIN","marketTime":"2024-06-27T16:03:00.000Z","suspendTime":"2024-06-27T16:03:00.000Z","bspReconciled":false,"complete":true,"inPlay":false,"crossMatching":false,"runnersVoidable":false,"numberOfActiveRunners":6,"betDelay":0,"status":"OPEN","runners":[{"status":"ACTIVE","sortPriority":1,"id":66050026,"name":"1. Salacres Elunico"},{"status":"ACTIVE","sortPriority":2,"id":58821523,"name":"2. Makeit Missy"},{"status":"ACTIVE","sortPriority":3,"id":50639934,"name":"3. Greencroft Annie"},{"status":"ACTIVE","sortPriority":4,"id":69213654,"name":"4. Salacres Crafty"},{"status":"ACTIVE","sortPriority":5,"id":51218587,"name":"5. Golden Bullet"},{"status":"ACTIVE","sortPriority":6,"id":60237218,"name":"6. Arwens Link"}],"regulators":["MR_INT"],"venue":"Towcester","countryCode":"GB","discountAllowed":false,"timezone":"Europe/London","openDate":"2024-06-27T13:33:00.000Z","version":5994767097,"name":"A3 500m","eventName":"Towcester 27th Jun"},"rc":[],"con":true,"img":false}]}
{"op":"mcm","clk":"11536833133","pt":1719431777518,"mc":[{"id":"1.230180128","marketDefinition":{"bspMarket":true,"turnInPlayEnabled":false,"persistenceEnabled":false,"marketBaseRate":5.0,"eventId":"33376437","eventTypeId":"4339","numberOfWinners":1,"bettingType":"ODDS","marketType":"WIN","marketTime":"2024-06-27T16:03:00.000Z","suspendTime":"2024-06-27T16:03:00.000Z","bspReconciled":false,"complete":true,"inPlay":false,"crossMatching":false,"runnersVoidable":false,"numberOfActiveRunners":6,"betDelay":0,"status":"OPEN","runners":[{"status":"ACTIVE","sortPriority":1,"id":66050026,"name":"1. Salacres Elunico"},{"status":"ACTIVE","sortPriority":2,"id":58821523,"name":"2. Makeit Missy"},{"status":"ACTIVE","sortPriority":3,"id":50639934,"name":"3. Greencroft Annie"},{"status":"ACTIVE","sortPriority":4,"id":69213654,"name":"4. Salacres Crafty"},{"status":"ACTIVE","sortPriority":5,"id":51218587,"name":"5. Golden Bullet"},{"status":"ACTIVE","sortPriority":6,"id":60237218,"name":"6. Arwens Link"}],"regulators":["MR_INT"],"venue":"Towcester","countryCode":"GB","discountAllowed":true,"timezone":"Europe/London","openDate":"2024-06-27T13:33:00.000Z","version":5994767097,"name":"A3 500m","eventName":"Towcester 27th Jun"},"rc":[],"con":true,"img":false}]}
{"op":"mcm","clk":"11537083767","pt":1719435430788,"mc":[{"id":"1.230180128","rc":[{"atb":[[1.03,10.99]],"id":58821523},{"atl":[[990,0.84]],"id":58821523},{"spn":495.51,"spf":"NaN","id":58821523},{"atb":[[1.02,16.48]],"id":50639934},{"atl":[[1000,0.84]],"id":50639934},{"spn":500.51,"spf":"NaN","id":50639934},{"atb":[[1.02,16.48]],"id":60237218},{"atl":[[990,0.84]],"id":60237218},{"spn":495.51,"spf":"NaN","id":60237218},{"atb":[[1.02,16.48]],"id":51218587},{"atl":[[990,0.84]],"id":51218587},{"spn":495.51,"spf":"NaN","id":51218587},{"atb":[[1.03,10.99]],"id":69213654},{"atl":[[1000,0.84]],"id":69213654},{"spn":500.51,"spf":"NaN","id":69213654},{"atb":[[1.03,10.99]],"id":66050026},{"atl":[[1000,0.84]],"id":66050026},{"spn":500.51,"spf":"NaN","id":66050026}],"con":true,"img":false}]}
{"op":"mcm","clk":"11537235629","pt":1719437882798,"mc":[{"id":"1.230180128","marketDefinition":{"bspMarket":true,"turnInPlayEnabled":false,"persistenceEnabled":false,"marketBaseRate":5.0,"eventId":"33376437","eventTypeId":"4339","numberOfWinners":1,"bettingType":"ODDS","marketType":"WIN","marketTime":"2024-06-27T16:03:00.000Z","suspendTime":"2024-06-27T16:03:00.000Z","bspReconciled":false,"complete":true,"inPlay":false,"crossMatching":false,"runnersVoidable":false,"numberOfActiveRunners":6,"betDelay":0,"status":"OPEN","runners":[{"status":"ACTIVE","sortPriority":1,"id":66050026,"name":"1. Salacres Elunico"},{"status":"ACTIVE","sortPriority":2,"id":58821523,"name":"2. Makeit Missy"},{"status":"ACTIVE","sortPriority":3,"id":50639934,"name":"3. Greencroft Annie"},{"status":"ACTIVE","sortPriority":4,"id":69213654,"name":"4. Salacres Crafty"},{"status":"ACTIVE","sortPriority":5,"id":51218587,"name":"5. Golden Bullet"},{"status":"ACTIVE","sortPriority":6,"id":60237218,"name":"6. Arwens Link"}],"regulators":["MR_INT"],"venue":"Towcester","countryCode":"GB","discountAllowed":true,"timezone":"Europe/London","openDate":"2024-06-27T13:33:00.000Z","version":5994767097,"name":"A3 500m","eventName":"Towcester 27th Jun"},"rc":[{"atb":[[1.03,10.99]],"id":58821523},{"atl":[[990,0.84]],"id":58821523},{"spn":495.51,"spf":"NaN","id":58821523},{"atb":[[1.02,16.48]],"id":50639934},{"atl":[[1000,0.84]],"id":50639934},{"spn":500.51,"spf":"NaN","id":50639934},{"atb":[[1.02,16.48]],"id":60237218},{"atl":[[990,0.84]],"id":60237218},{"spn":495.51,"spf":"NaN","id":60237218},{"atb":[[1.02,16.48]],"id":51218587},{"atl":[[990,0.84]],"id":51218587},{"spn":495.51,"spf":"NaN","id":51218587},{"atb":[[1.03,10.99]],"id":69213654},{"atl":[[1000,0.84]],"id":69213654},{"spn":500.51,"spf":"NaN","id":69213654},{"atb":[[1.03,10.99]],"id":66050026},{"atl":[[1000,0.84]],"id":66050026},{"spn":500.51,"spf":"NaN","id":66050026}],"con":true,"img":true}]}
{"op":"mcm","clk":"11537301988","pt":1719439027820,"mc":[{"id":"1.230180128","rc":[{"atb":[[1.03,10.99]],"id":58821523},{"atl":[[990,0.17]],"id":58821523},{"atb":[[1.02,16.48]],"id":50639934},{"atl":[[1000,0.17]],"id":50639934},{"atb":[[1.02,16.48]],"id":60237218},{"atl":[[990,0.17]],"id":60237218},{"atb":[[1.02,16.48]],"id":51218587},{"atl":[[990,0.17]],"id":51218587},{"atb":[[1.03,10.99]],"id":69213654},{"atl":[[1000,0.17]],"id":69213654},{"atb":[[1.03,10.99]],"id":66050026},{"atl":[[1000,0.17]],"id":66050026}],"con":true,"img":false}]}
{"op":"mcm","clk":"11537576917","pt":1719443282842,"mc":[{"id":"1.230180128","marketDefinition":{"bspMarket":true,"turnInPlayEnabled":false,"persistenceEnabled":false,"marketBaseRate":5.0,"eventId":"33376437","eventTypeId":"4339","numberOfWinners":1,"bettingType":"ODDS","marketType":"WIN","marketTime":"2024-06-27T16:03:00.000Z","suspendTime":"2024-06-27T16:03:00.000Z","bspReconciled":false,"complete":true,"inPlay":false,"crossMatching":false,"runnersVoidable":false,"numberOfActiveRunners":6,"betDelay":0,"status":"OPEN","runners":[{"status":"ACTIVE","sortPriority":1,"id":66050026,"name":"1. Salacres Elunico"},{"status":"ACTIVE","sortPriority":2,"id":58821523,"name":"2. Makeit Missy"},{"status":"ACTIVE","sortPriority":3,"id":50639934,"name":"3. Greencroft Annie"},{"status":"ACTIVE","sortPriority":4,"id":69213654,"name":"4. Salacres Crafty"},{"status":"ACTIVE","sortPriority":5,"id":51218587,"name":"5. Golden Bullet"},{"status":"ACTIVE","sortPriority":6,"id":60237218,"name":"6. Arwens Link"}],"regulators":["MR_INT"],"venue":"Towcester","countryCode":"GB","discountAllowed":true,"timezone":"Europe/London","openDate":"2024-06-27T13:33:00.000Z","version":5994767097,"name":"A3 500m","eventName":"Towcester 27th Jun"},"rc":[{"atb":[[1.03,10.99]],"id":58821523},{"atl":[[990,0.17]],"id":58821523},{"spn":495.51,"spf":"NaN","id":58821523},{"atb":[[1.02,16.48]],"id":50639934},{"atl":[[1000,0.17]],"id":50639934},{"spn":500.51,"spf":"NaN","id":50639934},{"atb":[[1.02,16.48]],"id":60237218},{"atl":[[990,0.17]],"id":60237218},{"spn":495.51,"spf":"NaN","id":60237218},{"atb":[[1.02,16.48]],"id":51218587},{"atl":[[990,0.17]],"id":51218587},{"spn":495.51,"spf":"NaN","id":51218587},{"atb":[[1.03,10.99]],"id":69213654},{"atl":[[1000,0.17]],"id":69213654},{"spn":500.51,"spf":"NaN","id":69213654},{"atb":[[1.03,10.99]],"id":66050026},{"atl":[[1000,0.17]],"id":66050026},{"spn":500.51,"spf":"NaN","id":66050026}],"con":true,"img":true}]}
{"op":"mcm","clk":"11537958604","pt":1719448682890,"mc":[{"id":"1.230180128","marketDefinition":{"bspMarket":true,"turnInPlayEnabled":false,"persistenceEnabled":false,"marketBaseRate":5.0,"eventId":"33376437","eventTypeId":"4339","numberOfWinners":1,"bettingType":"ODDS","marketType":"WIN","marketTime":"2024-06-27T16:03:00.000Z","suspendTime":"2024-06-27T16:03:00.000Z","bspReconciled":false,"complete":true,"inPlay":false,"crossMatching":false,"runnersVoidable":false,"numberOfActiveRunners":6,"betDelay":0,"status":"OPEN","runners":[{"status":"ACTIVE","sortPriority":1,"id":66050026,"name":"1. Salacres Elunico"},{"status":"ACTIVE","sortPriority":2,"id":58821523,"name":"2. Makeit Missy"},{"status":"ACTIVE","sortPriority":3,"id":50639934,"name":"3. Greencroft Annie"},{"status":"ACTIVE","sortPriority":4,"id":69213654,"name":"4. Salacres Crafty"},{"status":"ACTIVE","sortPriority":5,"id":51218587,"name":"5. Golden Bullet"},{"status":"ACTIVE","sortPriority":6,"id":60237218,"name":"6. Arwens Link"}],"regulators":["MR_INT"],"venue":"Towcester","countryCode":"GB","discountAllowed":true,"timezone":"Europe/London","openDate":"2024-06-27T13:33:00.000Z","version":5994767097,"name":"A3 500m","eventName":"Towcester 27th Jun"},"rc":[{"atb":[[1.03,10.99]],"id":58821523},{"atl":[[990,0.17]],"id":58821523},{"spn":495.51,"spf":"NaN","id":58821523},{"atb":[[1.02,16.48]],"id":50639934},{"atl":[[1000,0.17]],"id":50639934},{"spn":500.51,"spf":"NaN","id":50639934},{"atb":[[1.02,16.48]],"id":60237218},{"atl":[[990,0.17]],"id":60237218},{"spn":495.51,"spf":"NaN","id":60237218},{"atb":[[1.02,16.48]],"id":51218587},{"atl":[[990,0.17]],"id":51218587},{"spn":495.51,"spf":"NaN","id":51218587},{"atb":[[1.03,10.99]],"id":69213654},{"atl":[[1000,0.17]],"id":69213654},{"spn":500.51,"spf":"NaN","id":69213654},{"atb":[[1.03,10.99]],"id":66050026},{"atl":[[1000,0.17]],"id":66050026},{"spn":500.51,"spf":"NaN","id":66050026}],"con":true,"img":true}]}
{"op":"mcm","clk":"11538174180","pt":1719454082861,"mc":[{"id":"1.230180128","marketDefinition":{"bspMarket":true,"turnInPlayEnabled":false,"persistenceEnabled":false,"marketBaseRate":5.0,"eventId":"33376437","eventTypeId":"4339","numberOfWinners":1,"bettingType":"ODDS","marketType":"WIN","marketTime":"2024-06-27T16:03:00.000Z","suspendTime":"2024-06-27T16:03:00.000Z","bspReconciled":false,"complete":true,"inPlay":false,"crossMatching":false,"runnersVoidable":false,"numberOfActiveRunners":6,"betDelay":0,"status":"OPEN","runners":[{"status":"ACTIVE","sortPriority":1,"id":66050026,"name":"1. Salacres Elunico"},{"status":"ACTIVE","sortPriority":2,"id":58821523,"name":"2. Makeit Missy"},{"status":"ACTIVE","sortPriority":3,"id":50639934,"name":"3. Greencroft Annie"},{"status":"ACTIVE","sortPriority":4,"id":69213654,"name":"4. Salacres Crafty"},{"status":"ACTIVE","sortPriority":5,"id":51218587,"name":"5. Golden Bullet"},{"status":"ACTIVE","sortPriority":6,"id":60237218,"name":"6. Arwens Link"}],"regulators":["MR_INT"],"venue":"Towcester","countryCode":"GB","discountAllowed":true,"timezone":"Europe/London","openDate":"2024-06-27T13:33:00.000Z","version":5994767097,"name":"A3 500m","eventName":"Towcester 27th Jun"},"rc":[{"atb":[[1.03,10.99]],"id":58821523},{"atl":[[990,0.17]],"id":58821523},{"spn":495.51,"spf":"NaN","id":58821523},{"atb":[[1.02,16.48]],"id":50639934},{"atl":[[1000,0.17]],"id":50639934},{"spn":500.51,"spf":"NaN","id":50639934},{"atb":[[1.02,16.48]],"id":60237218},{"atl":[[990,0.17]],"id":60237218},{"spn":495.51,"spf":"NaN","id":60237218},{"atb":[[1.02,16.48]],"id":51218587},{"atl":[[990,0.17]],"id":51218587},{"spn":495.51,"spf":"NaN","id":51218587},{"atb":[[1.03,10.99]],"id":69213654},{"atl":[[1000,0.17]],"id":69213654},{"spn":500.51,"spf":"NaN","id":69213654},{"atb":[[1.03,10.99]],"id":66050026},{"atl":[[1000,0.17]],"id":66050026},{"spn":500.51,"spf":"NaN","id":66050026}],"con":true,"img":true}]}
{"op":"mcm","clk":"11538371893","pt":1719459482934,"mc":[{"id":"1.230180128","marketDefinition":{"bspMarket":true,"turnInPlayEnabled":false,"persistenceEnabled":false,"marketBaseRate":5.0,"eventId":"33376437","eventTypeId":"4339","numberOfWinners":1,"bettingType":"ODDS","marketType":"WIN","marketTime":"2024-06-27T16:03:00.000Z","suspendTime":"2024-06-27T16:03:00.000Z","bspReconciled":false,"complete":true,"inPlay":false,"crossMatching":false,"runnersVoidable":false,"numberOfActiveRunners":6,"betDelay":0,"status":"OPEN","runners":[{"status":"ACTIVE","sortPriority":1,"id":66050026,"name":"1. Salacres Elunico"},{"status":"ACTIVE","sortPriority":2,"id":58821523,"name":"2. Makeit Missy"},{"status":"ACTIVE","sortPriority":3,"id":50639934,"name":"3. Greencroft Annie"},{"status":"ACTIVE","sortPriority":4,"id":69213654,"name":"4. Salacres Crafty"},{"status":"ACTIVE","sortPriority":5,"id":51218587,"name":"5. Golden Bullet"},{"status":"ACTIVE","sortPriority":6,"id":60237218,"name":"6. Arwens Link"}],"regulators":["MR_INT"],"venue":"Towcester","countryCode":"GB","discountAllowed":true,"timezone":"Europe/London","openDate":"2024-06-27T13:33:00.000Z","version":5994767097,"name":"A3 500m","eventName":"Towcester 27th Jun"},"rc":[{"atb":[[1.03,10.99]],"id":58821523},{"atl":[[990,0.17]],"id":58821523},{"spn":495.51,"spf":"NaN","id":58821523},{"atb":[[1.02,16.48]],"id":50639934},{"atl":[[1000,0.17]],"id":50639934},{"spn":500.51,"spf":"NaN","id":50639934},{"atb":[[1.02,16.48]],"id":60237218},{"atl":[[990,0.17]],"id":60237218},{"spn":495.51,"spf":"NaN","id":60237218},{"atb":[[1.02,16.48]],"id":51218587},{"atl":[[990,0.17]],"id":51218587},{"spn":495.51,"spf":"NaN","id":51218587},{"atb":[[1.03,10.99]],"id":69213654},{"atl":[[1000,0.17]],"id":69213654},{"spn":500.51,"spf":"NaN","id":69213654},{"atb":[[1.03,10.99]],"id":66050026},{"atl":[[1000,0.17]],"id":66050026},{"spn":500.51,"spf":"NaN","id":66050026}],"con":true,"img":true}]}
{"op":"mcm","clk":"11538598970","pt":1719464882861,"mc":[{"id":"1.230180128","marketDefinition":{"bspMarket":true,"turnInPlayEnabled":false,"persistenceEnabled":false,"marketBaseRate":5.0,"eventId":"33376437","eventTypeId":"4339","numberOfWinners":1,"bettingType":"ODDS","marketType":"WIN","marketTime":"2024-06-27T16:03:00.000Z","suspendTime":"2024-06-27T16:03:00.000Z","bspReconciled":false,"complete":true,"inPlay":false,"crossMatching":false,"runnersVoidable":false,"numberOfActiveRunners":6,"betDelay":0,"status":"OPEN","runners":[{"status":"ACTIVE","sortPriority":1,"id":66050026,"name":"1. Salacres Elunico"},{"status":"ACTIVE","sortPriority":2,"id":58821523,"name":"2. Makeit Missy"},{"status":"ACTIVE","sortPriority":3,"id":50639934,"name":"3. Greencroft Annie"},{"status":"ACTIVE","sortPriority":4,"id":69213654,"name":"4. Salacres Crafty"},{"status":"ACTIVE","sortPriority":5,"id":51218587,"name":"5. Golden Bullet"},{"status":"ACTIVE","sortPriority":6,"id":60237218,"name":"6. Arwens Link"}],"regulators":["MR_INT"],"venue":"Towcester","countryCode":"GB","discountAllowed":true,"timezone":"Europe/London","openDate":"2024-06-27T13:33:00.000Z","version":5994767097,"name":"A3 500m","eventName":"Towcester 27th Jun"},"rc":[{"atb":[[1.03,10.99]],"id":58821523},{"atl":[[990,0.17]],"id":58821523},{"spn":495.51,"spf":"NaN","id":58821523},{"atb":[[1.02,16.48]],"id":50639934},{"atl":[[1000,0.17]],"id":50639934},{"spn":500.51,"spf":"NaN","id":50639934},{"atb":[[1.02,16.48]],"id":60237218},{"atl":[[990,0.17]],"id":60237218},{"spn":495.51,"spf":"NaN","id":60237218},{"atb":[[1.02,16.48]],"id":51218587},{"atl":[[990,0.17]],"id":51218587},{"spn":495.51,"spf":"NaN","id":51218587},{"atb":[[1.03,10.99]],"id":69213654},{"atl":[[1000,0.17]],"id":69213654},{"spn":500.51,"spf":"NaN","id":69213654},{"atb":[[1.03,10.99]],"id":66050026},{"atl":[[1000,0.17]],"id":66050026},{"spn":500.51,"spf":"NaN","id":66050026}],"con":true,"img":true}]}
{"op":"mcm","clk":"11538748667","pt":1719468205680,"mc":[{"id":"1.230180128","rc":[{"atb":[[1.03,10.99],[2.06,11.44]],"id":58821523},{"spn":496.03,"spf":"NaN","id":58821523},{"atb":[[1.02,16.48],[2.1,8.97]],"id":50639934},{"spn":501.05,"spf":"NaN","id":50639934},{"atb":[[1.02,16.48],[2.08,12.44]],"id":60237218},{"spn":496.04,"spf":"NaN","id":60237218},{"atb":[[1.02,16.48],[2.08,11.55]],"id":51218587},{"spn":496.04,"spf":"NaN","id":51218587},{"atb":[[2,11.11],[1.03,10.99]],"id":69213654},{"spn":501.0,"spf":"NaN","id":69213654},{"atb":[[2.02,12.08],[1.03,10.99]],"id":66050026},{"spn":501.01,"spf":"NaN","id":66050026}],"con":true,"img":false}]}
{"op":"mcm","clk":"11538750488","pt":1719468244542,"mc":[{"id":"1.230180128","rc":[{"atb":[[2.12,3.16]],"id":50639934}],"con":true,"img":false}]}
{"op":"mcm","clk":"11538750542","pt":1719468245258,"mc":[{"id":"1.230180128","rc":[{"atb":[[2.1,3.16]],"id":60237218}],"con":true,"img":false}]}
{"op":"mcm","clk":"11538750555","pt":1719468245463,"mc":[{"id":"1.230180128","rc":[{"atb":[[2.08,3.16]],"id":58821523}],"con":true,"img":false}]}
{"op":"mcm","clk":"11538750575","pt":1719468245874,"mc":[{"id":"1.230180128","rc":[{"atb":[[2.1,3.16]],"id":51218587}],"con":true,"img":false}]}
{"op":"mcm","clk":"11538750586","pt":1719468246032,"mc":[{"id":"1.230180128","rc":[{"atb":[[2.04,3.16]],"id":66050026}],"con":true,"img":false}]}
{"op":"mcm","clk":"11538750596","pt":1719468246238,"mc":[{"id":"1.230180128","rc":[{"atb":[[2.02,3.16]],"id":69213654}],"con":true,"img":false}]}
{"op":"mcm","clk":"11538752434","pt":1719468282613,"mc":[{"id":"1.230180128","rc":[{"spn":496.04,"spf":"NaN","id":58821523},{"atb":[[2.12,6.55]],"id":50639934},{"spn":501.06,"spf":"NaN","id":50639934},{"spn":496.05,"spf":"NaN","id":60237218},{"spn":496.05,"spf":"NaN","id":51218587},{"spn":501.01,"spf":"NaN","id":69213654},{"spn":501.02,"spf":"NaN","id":66050026}],"con":true,"img":false}]}
{"op":"mcm","clk":"11538752453","pt":1719468282919,"mc":[{"id":"1.230180128","rc":[{"atb":[[2.02,6.55]],"id":69213654}],"con":true,"img":false}]}
{"op":"mcm","clk":"11538752481","pt":1719468283284,"mc":[{"id":"1.230180128","rc":[{"atb":[[2.08,6.55]],"id":58821523}],"con":true,"img":false}]}
{"op":"mcm","clk":"11538752487","pt":1719468283387,"mc":[{"id":"1.230180128","rc":[{"atb":[[2.1,6.55]],"id":51218587}],"con":true,"img":false}]}
{"op":"mcm","clk":"11538752500","pt":1719468283589,"mc":[{"id":"1.230180128","rc":[{"atb":[[2.1,6.55]],"id":60237218}],"con":true,"img":false}]}
{"op":"mcm","clk":"11538752520","pt":1719468283999,"mc":[{"id":"1.230180128","rc":[{"atb":[[2.04,6.55]],"id":66050026}],"con":true,"img":false}]}
{"op":"mcm","clk":"11538754060","pt":1719468311795,"mc":[{"id":"1.230180128","marketDefinition":{"bspMarket":true,"turnInPlayEnabled":false,"persistenceEnabled":false,"marketBaseRate":5.0,"eventId":"33376437","eventTypeId":"4339","numberOfWinners":1,"bettingType":"ODDS","marketType":"WIN","marketTime":"2024-06-27T16:03:00.000Z","suspendTime":"2024-06-27T16:03:00.000Z","bspReconciled":false,"complete":true,"inPlay":false,"crossMatching":true,"runnersVoidable":false,"numberOfActiveRunners":6,"betDelay":0,"status":"OPEN","runners":[{"status":"ACTIVE","sortPriority":1,"id":66050026,"name":"1. Salacres Elunico"},{"status":"ACTIVE","sortPriority":2,"id":58821523,"name":"2. Makeit Missy"},{"status":"ACTIVE","sortPriority":3,"id":50639934,"name":"3. Greencroft Annie"},{"status":"ACTIVE","sortPriority":4,"id":69213654,"name":"4. Salacres Crafty"},{"status":"ACTIVE","sortPriority":5,"id":51218587,"name":"5. Golden Bullet"},{"status":"ACTIVE","sortPriority":6,"id":60237218,"name":"6. Arwens Link"}],"regulators":["MR_INT"],"venue":"Towcester","countryCode":"GB","discountAllowed":true,"timezone":"Europe/London","openDate":"2024-06-27T13:33:00.000Z","version":5994767097,"name":"A3 500m","eventName":"Towcester 27th Jun"},"rc":[],"con":true,"img":false}]}
{"op":"mcm","clk":"11538921979","pt":1719471788208,"mc":[{"id":"1.230180128","rc":[{"atb":[[2.06,11.43],[1.03,10.98],[2.08,6.54]],"id":58821523},{"atl":[[150,4],[990,0.17]],"id":58821523},{"spn":76.04,"spf":"NaN","id":58821523},{"atb":[[1.02,16.47],[2.12,6.54],[2.1,8.96]],"id":50639934},{"atl":[[150,4],[1000,0.17]],"id":50639934},{"spn":76.06,"spf":"NaN","id":50639934},{"atb":[[1.02,16.47],[2.1,6.54],[2.08,12.43]],"id":60237218},{"atl":[[150,4],[990,0.17]],"id":60237218},{"spn":76.05,"spf":"NaN","id":60237218},{"atb":[[1.02,16.47],[2.1,6.54],[2.08,11.54]],"id":51218587},{"atl":[[150,4],[990,0.17]],"id":51218587},{"spn":76.05,"spf":"NaN","id":51218587},{"atb":[[2,11.1],[2.02,6.54],[1.03,10.98]],"id":69213654},{"atl":[[150,4],[1000,0.17]],"id":69213654},{"spn":76.01,"spf":"NaN","id":69213654},{"atb":[[2.02,12.07],[1.03,10.98],[2.04,6.54]],"id":66050026},{"atl":[[150,4],[1000,0.17]],"id":66050026},{"spn":76.02,"spf":"NaN","id":66050026}],"con":true,"img":false}]}
{"op":"mcm","clk":"11538938873","pt":1719472079184,"mc":[{"id":"1.230180128","rc":[{"atl":[[30,0.6]],"id":50639934},{"spn":16.06,"spf":"NaN","id":50639934}],"con":true,"img":false}]}
{"op":"mcm","clk":"11538940779","pt":1719472113837,"mc":[{"id":"1.230180128","rc":[{"atb":[[2.06,0]],"id":58821523},{"atb":[[2.1,0]],"id":50639934},{"atb":[[2.08,0]],"id":60237218},{"atb":[[2.08,0]],"id":51218587},{"atb":[[2,0]],"id":69213654},{"atb":[[2.02,0]],"id":66050026}],"con":true,"img":false}]}
{"op":"mcm","clk":"11538940786","pt":1719472113889,"mc":[{"id":"1.230180128","rc":[{"atb":[[2.1,11.43]],"id":58821523},{"atb":[[2.14,8.96]],"id":50639934},{"atb":[[2.12,12.43]],"id":60237218},{"atb":[[2.12,11.54]],"id":51218587},{"atb":[[2.04,11.1]],"id":69213654},{"atb":[[2.06,12.07]],"id":66050026}],"con":true,"img":false}]}
{"op":"mcm","clk":"11538942812","pt":1719472145981,"mc":[{"id":"1.230180128","rc":[{"spn":76.05,"spf":"NaN","id":58821523},{"atb":[[2.12,3.38]],"id":50639934},{"spn":16.07,"spf":"NaN","id":50639934},{"spn":76.06,"spf":"NaN","id":60237218},{"spn":76.06,"spf":"NaN","id":51218587},{"spn":76.02,"spf":"NaN","id":69213654},{"spn":76.03,"spf":"NaN","id":66050026}],"con":true,"img":false}]}
{"op":"mcm","clk":"11538942836","pt":1719472146242,"mc":[{"id":"1.230180128","rc":[{"atb":[[2.04,3.38]],"id":66050026}],"con":true,"img":false}]}
{"op":"mcm","clk":"11538942850","pt":1719472146449,"mc":[{"id":"1.230180128","rc":[{"atb":[[2.02,3.38]],"id":69213654}],"con":true,"img":false}]}
{"op":"mcm","clk":"11538942874","pt":1719472146759,"mc":[{"id":"1.230180128","rc":[{"atb":[[2.1,3.38]],"id":51218587}],"con":true,"img":false}]}
{"op":"mcm","clk":"11538942911","pt":1719472147279,"mc":[{"id":"1.230180128","rc":[{"atb":[[2.1,3.38]],"id":60237218}],"con":true,"img":false}]}
{"op":"mcm","clk":"11538942967","pt":1719472147945,"mc":[{"id":"1.230180128","rc":[{"atb":[[2.08,3.16]],"id":66050026}],"con":true,"img":false}]}
{"op":"mcm","clk":"11538942984","pt":1719472148151,"mc":[{"id":"1.230180128","rc":[{"atb":[[2.14,3.16]],"id":60237218}],"con":true,"img":false}]}
{"op":"mcm","clk":"11538943003","pt":1719472148457,"mc":[{"id":"1.230180128","rc":[{"atb":[[2.08,3.38]],"id":58821523}],"con":true,"img":false}]}
{"op":"mcm","clk":"11538943031","pt":1719472148866,"mc":[{"id":"1.230180128","rc":[{"atb":[[2.06,3.16]],"id":69213654}],"con":true,"img":false}]}
{"op":"mcm","clk":"11538943069","pt":1719472149583,"mc":[{"id":"1.230180128","rc":[{"atb":[[2.14,3.16]],"id":51218587}],"con":true,"img":false}]}
{"op":"mcm","clk":"11538943124","pt":1719472150457,"mc":[{"id":"1.230180128","rc":[{"atb":[[2.16,3.16]],"id":50639934}],"con":true,"img":false}]}
{"op":"mcm","clk":"11538943218","pt":1719472151993,"mc":[{"id":"1.230180128","rc":[{"atb":[[2.12,3.16]],"id":58821523}],"con":true,"img":false}]}
{"op":"mcm","clk":"11538943653","pt":1719472159684,"mc":[{"id":"1.230180128","rc":[{"atb":[[2.1,0]],"id":51218587}],"con":true,"img":false}]}
{"op":"mcm","clk":"11538943688","pt":1719472160295,"mc":[{"id":"1.230180128","rc":[{"atb":[[2.1,0]],"id":60237218}],"con":true,"img":false}]}
{"op":"mcm","clk":"11538943694","pt":1719472160397,"mc":[{"id":"1.230180128","rc":[{"atb":[[2.04,0]],"id":66050026}],"con":true,"img":false}]}
{"op":"mcm","clk":"11538943709","pt":1719472160703,"mc":[{"id":"1.230180128","rc":[{"atb":[[2.12,0]],"id":50639934}],"con":true,"img":false}]}
{"op":"mcm","clk":"11538943778","pt":1719472161680,"mc":[{"id":"1.230180128","rc":[{"atb":[[2.08,0]],"id":58821523}],"con":true,"img":false}]}
{"op":"mcm","clk":"11538943859","pt":1719472163016,"mc":[{"id":"1.230180128","rc":[{"atb":[[2.02,0]],"id":69213654}],"con":true,"img":false}]}
{"op":"mcm","clk":"11538944564","pt":1719472174631,"mc":[{"id":"1.230180128","rc":[{"atb":[[2.14,6.54]],"id":51218587}],"con":true,"img":false}]}
{"op":"mcm","clk":"11538944617","pt":1719472175501,"mc":[{"id":"1.230180128","rc":[{"atb":[[2.16,6.54]],"id":50639934}],"con":true,"img":false}]}
{"op":"mcm","clk":"11538944636","pt":1719472175809,"mc":[{"id":"1.230180128","rc":[{"atb":[[2.08,6.54]],"id":66050026}],"con":true,"img":false}]}
{"op":"mcm","clk":"11538944678","pt":1719472176523,"mc":[{"id":"1.230180128","rc":[{"atb":[[2.14,6.54]],"id":60237218}],"con":true,"img":false}]}
{"op":"mcm","clk":"11538944929","pt":1719472180523,"mc":[{"id":"1.230180128","rc":[{"atb":[[2.06,6.54]],"id":69213654}],"con":true,"img":false}]}
{"op":"mcm","clk":"11538945010","pt":1719472181909,"mc":[{"id":"1.230180128","rc":[{"atb":[[2.12,6.54]],"id":58821523}],"con":true,"img":false}]}
{"op":"mcm","clk":"11539126202","pt":1719475682882,"mc":[{"id":"1.230180128","marketDefinition":{"bspMarket":true,"turnInPlayEnabled":false,"persistenceEnabled":false,"marketBaseRate":5.0,"eventId":"33376437","eventTypeId":"4339","numberOfWinners":1,"bettingType":"ODDS","marketType":"WIN","marketTime":"2024-06-27T16:03:00.000Z","suspendTime":"2024-06-27T16:03:00.000Z","bspReconciled":false,"complete":true,"inPlay":false,"crossMatching":true,"runnersVoidable":false,"numberOfActiveRunners":6,"betDelay":0,"status":"OPEN","runners":[{"status":"ACTIVE","sortPriority":1,"id":66050026,"name":"1. Salacres Elunico"},{"status":"ACTIVE","sortPriority":2,"id":58821523,"name":"2. Makeit Missy"},{"status":"ACTIVE","sortPriority":3,"id":50639934,"name":"3. Greencroft Annie"},{"status":"ACTIVE","sortPriority":4,"id":69213654,"name":"4. Salacres Crafty"},{"status":"ACTIVE","sortPriority":5,"id":51218587,"name":"5. Golden Bullet"},{"status":"ACTIVE","sortPriority":6,"id":60237218,"name":"6. Arwens Link"}],"regulators":["MR_INT"],"venue":"Towcester","countryCode":"GB","discountAllowed":true,"timezone":"Europe/London","openDate":"2024-06-27T13:33:00.000Z","version":5994767097,"name":"A3 500m","eventName":"Towcester 27th Jun"},"rc":[{"atb":[[1.03,10.99],[2.12,6.55],[2.1,11.43]],"id":58821523},{"atl":[[150,4],[990,0.17]],"id":58821523},{"spn":76.06,"spf":"NaN","id":58821523},{"atb":[[1.02,16.48],[2.16,6.55],[2.14,8.96]],"id":50639934},{"atl":[[150,4],[30,0.6],[1000,0.17]],"id":50639934},{"spn":16.08,"spf":"NaN","id":50639934},{"atb":[[1.02,16.48],[2.12,12.43],[2.14,6.55]],"id":60237218},{"atl":[[150,4],[990,0.17]],"id":60237218},{"spn":76.07,"spf":"NaN","id":60237218},{"atb":[[1.02,16.48],[2.12,11.54],[2.14,6.55]],"id":51218587},{"atl":[[150,4],[990,0.17]],"id":51218587},{"spn":76.07,"spf":"NaN","id":51218587},{"atb":[[2.06,6.55],[1.03,10.99],[2.04,11.1]],"id":69213654},{"atl":[[150,4],[1000,0.17]],"id":69213654},{"spn":76.03,"spf":"NaN","id":69213654},{"atb":[[2.06,12.08],[1.03,10.99],[2.08,6.55]],"id":66050026},{"atl":[[150,4],[1000,0.17]],"id":66050026},{"spn":76.04,"spf":"NaN","id":66050026}],"con":true,"img":true}]}
{"op":"mcm","clk":"11539128128","pt":1719475713841,"mc":[{"id":"1.230180128","rc":[{"atb":[[1.03,10.99],[2.12,6.55],[2.1,0]],"id":58821523},{"spn":76.06,"spf":"NaN","id":58821523},{"atb":[[1.02,16.48],[2.16,6.55],[2.14,0]],"id":50639934},{"spn":16.08,"spf":"NaN","id":50639934},{"atb":[[1.02,16.48],[2.12,0],[2.14,6.55]],"id":60237218},{"spn":76.07,"spf":"NaN","id":60237218},{"atb":[[1.02,16.48],[2.12,0],[2.14,6.55]],"id":51218587},{"spn":76.07,"spf":"NaN","id":51218587},{"atb":[[2.06,6.55],[1.03,10.99],[2.04,0]],"id":69213654},{"spn":76.03,"spf":"NaN","id":69213654},{"atb":[[2.06,0],[1.03,10.99],[2.08,6.55]],"id":66050026},{"spn":76.04,"spf":"NaN","id":66050026}],"con":true,"img":false}]}
{"op":"mcm","clk":"11539128131","pt":1719475713944,"mc":[{"id":"1.230180128","rc":[{"atb":[[2.14,11.43]],"id":58821523},{"atb":[[2.18,8.96]],"id":50639934},{"atb":[[2.16,12.43]],"id":60237218},{"atb":[[2.16,11.54]],"id":51218587},{"atb":[[2.08,11.1]],"id":69213654},{"atb":[[2.1,12.08]],"id":66050026}],"con":true,"img":false}]}
{"op":"mcm","clk":"11539132939","pt":1719475792162,"mc":[{"id":"1.230180128","rc":[{"spn":76.07,"spf":"NaN","id":58821523},{"spn":16.09,"spf":"NaN","id":50639934},{"spn":76.08,"spf":"NaN","id":60237218},{"spn":76.08,"spf":"NaN","id":51218587},{"spn":76.04,"spf":"NaN","id":69213654},{"atb":[[2.08,3.16]],"id":66050026},{"spn":76.05,"spf":"NaN","id":66050026}],"con":true,"img":false}]}
{"op":"mcm","clk":"11539132947","pt":1719475792221,"mc":[{"id":"1.230180128","rc":[{"atb":[[2.12,3.16]],"id":58821523}],"con":true,"img":false}]}
{"op":"mcm","clk":"11539133034","pt":1719475793560,"mc":[{"id":"1.230180128","rc":[{"atb":[[2.14,3.16]],"id":51218587}],"con":true,"img":false}]}
{"op":"mcm","clk":"11539133039","pt":1719475793662,"mc":[{"id":"1.230180128","rc":[{"atb":[[2.16,3.16]],"id":50639934}],"con":true,"img":false}]}
{"op":"mcm","clk":"11539133064","pt":1719475793920,"mc":[{"id":"1.230180128","rc":[{"atb":[[2.14,3.16]],"id":60237218}],"con":true,"img":false}]}
{"op":"mcm","clk":"11539133092","pt":1719475794228,"mc":[{"id":"1.230180128","rc":[{"atb":[[2.06,3.16]],"id":69213654}],"con":true,"img":false}]}
{"op":"mcm","clk":"11539133147","pt":1719475794944,"mc":[{"id":"1.230180128","rc":[{"atb":[[2.16,3.38]],"id":58821523}],"con":true,"img":false}]}
{"op":"mcm","clk":"11539133186","pt":1719475795562,"mc":[{"id":"1.230180128","rc":[{"atb":[[2.2,3.38]],"id":50639934}],"con":true,"img":false}]}
{"op":"mcm","clk":"11539133199","pt":1719475795719,"mc":[{"id":"1.230180128","rc":[{"atb":[[2.18,3.38]],"id":60237218}],"con":true,"img":false}]}
{"op":"mcm","clk":"11539133222","pt":1719475796024,"mc":[{"id":"1.230180128","rc":[{"atb":[[2.1,3.38]],"id":69213654}],"con":true,"img":false}]}
{"op":"mcm","clk":"11539133279","pt":1719475796850,"mc":[{"id":"1.230180128","rc":[{"atb":[[2.18,3.38]],"id":51218587}],"con":true,"img":false}]}
{"op":"mcm","clk":"11539133331","pt":1719475797528,"mc":[{"id":"1.230180128","rc":[{"atb":[[2.12,3.38]],"id":66050026}],"con":true,"img":false}]}
{"op":"mcm","clk":"11539134330","pt":1719475810841,"mc":[{"id":"1.230180128","rc":[{"atb":[[2.12,0]],"id":58821523},{"atb":[[2.16,0]],"id":50639934},{"atb":[[2.14,0]],"id":60237218},{"atb":[[2.14,0]],"id":51218587},{"atb":[[2.06,0]],"id":69213654},{"atb":[[2.08,0]],"id":66050026}],"con":true,"img":false}]}
{"op":"mcm","clk":"11539153301","pt":1719476117189,"mc":[{"id":"1.230180128","rc":[{"spn":76.08,"spf":"NaN","id":58821523},{"atb":[[2.2,6.55]],"id":50639934},{"spn":16.1,"spf":"NaN","id":50639934},{"spn":76.09,"spf":"NaN","id":60237218},{"spn":76.09,"spf":"NaN","id":51218587},{"spn":76.05,"spf":"NaN","id":69213654},{"spn":76.06,"spf":"NaN","id":66050026}],"con":true,"img":false}]}
{"op":"mcm","clk":"11539153313","pt":1719476117283,"mc":[{"id":"1.230180128","rc":[{"atb":[[2.16,6.55]],"id":58821523}],"con":true,"img":false}]}
{"op":"mcm","clk":"11539153331","pt":1719476117488,"mc":[{"id":"1.230180128","rc":[{"atb":[[2.18,6.55]],"id":60237218},{"atb":[[2.12,6.55]],"id":66050026}],"con":true,"img":false}]}
{"op":"mcm","clk":"11539153354","pt":1719476117849,"mc":[{"id":"1.230180128","rc":[{"atb":[[2.18,6.55]],"id":51218587}],"con":true,"img":false}]}
{"op":"mcm","clk":"11539153393","pt":1719476118468,"mc":[{"id":"1.230180128","rc":[{"atb":[[2.1,6.55]],"id":69213654}],"con":true,"img":false}]}
{"op":"mcm","clk":"11539341536","pt":1719479312386,"mc":[{"id":"1.230180128","rc":[{"atb":[[1.03,10.98],[2.16,6.54],[2.14,0]],"id":58821523},{"atb":[[1.02,16.47],[2.18,0],[2.2,6.54]],"id":50639934},{"atb":[[1.02,16.47],[2.18,6.54],[2.16,0]],"id":60237218},{"atb":[[1.02,16.47],[2.18,6.54],[2.16,0]],"id":51218587},{"atb":[[1.03,10.98],[2.1,6.54],[2.08,0]],"id":69213654},{"atb":[[1.03,10.98],[2.12,6.54],[2.1,0]],"id":66050026}],"con":true,"img":false}]}
{"op":"mcm","clk":"11539341543","pt":1719479312486,"mc":[{"id":"1.230180128","rc":[{"atb":[[2.18,11.43]],"id":58821523},{"atb":[[2.22,8.96]],"id":50639934},{"atb":[[2.2,12.43]],"id":60237218},{"atb":[[2.2,11.54]],"id":51218587},{"atb":[[2.12,11.1]],"id":69213654},{"atb":[[2.14,12.08]],"id":66050026}],"con":true,"img":false}]}
{"op":"mcm","clk":"11539346651","pt":1719479394485,"mc":[{"id":"1.230180128","rc":[{"atb":[[2.16,3.38]],"id":58821523},{"spn":76.09,"spf":"NaN","id":58821523},{"spn":16.11,"spf":"NaN","id":50639934},{"spn":76.1,"spf":"NaN","id":60237218},{"spn":76.1,"spf":"NaN","id":51218587},{"spn":76.06,"spf":"NaN","id":69213654},{"spn":76.07,"spf":"NaN","id":66050026}],"con":true,"img":false}]}
{"op":"mcm","clk":"11539346665","pt":1719479394893,"mc":[{"id":"1.230180128","rc":[{"atb":[[2.1,3.38]],"id":69213654}],"con":true,"img":false}]}
{"op":"mcm","clk":"11539346671","pt":1719479395097,"mc":[{"id":"1.230180128","rc":[{"atb":[[2.18,3.38]],"id":60237218},{"atb":[[2.12,3.38]],"id":66050026}],"con":true,"img":false}]}
{"op":"mcm","clk":"11539346833","pt":1719479397833,"mc":[{"id":"1.230180128","rc":[{"atb":[[2.18,3.38]],"id":51218587}],"con":true,"img":false}]}
{"op":"mcm","clk":"11539346902","pt":1719479398905,"mc":[{"id":"1.230180128","rc":[{"atb":[[2.2,3.38]],"id":50639934}],"con":true,"img":false}]}
{"op":"mcm","clk":"11539348851","pt":1719479428544,"mc":[{"id":"1.230180128","rc":[{"atb":[[2.16,0]],"id":58821523},{"atb":[[2.12,0]],"id":66050026}],"con":true,"img":false}]}
{"op":"mcm","clk":"11539348872","pt":1719479428810,"mc":[{"id":"1.230180128","rc":[{"atb":[[2.1,0]],"id":69213654}],"con":true,"img":false}]}
{"op":"mcm","clk":"11539348899","pt":1719479429217,"mc":[{"id":"1.230180128","rc":[{"atb":[[2.2,0]],"id":50639934}],"con":true,"img":false}]}
{"op":"mcm","clk":"11539348938","pt":1719479429946,"mc":[{"id":"1.230180128","rc":[{"atb":[[2.18,0]],"id":51218587}],"con":true,"img":false}]}
{"op":"mcm","clk":"11539348980","pt":1719479430622,"mc":[{"id":"1.230180128","rc":[{"atb":[[2.18,0]],"id":60237218}],"con":true,"img":false}]}
{"op":"mcm","clk":"11539349034","pt":1719479431643,"mc":[{"id":"1.230180128","rc":[{"atb":[[2.14,3.38]],"id":69213654}],"con":true,"img":false}]}
{"op":"mcm","clk":"11539349050","pt":1719479431848,"mc":[{"id":"1.230180128","rc":[{"atb":[[2.16,3.38]],"id":66050026}],"con":true,"img":false}]}
{"op":"mcm","clk":"11539349088","pt":1719479432525,"mc":[{"id":"1.230180128","rc":[{"atb":[[2.2,3.38]],"id":58821523}],"con":true,"img":false}]}
{"op":"mcm","clk":"11539349102","pt":1719479432833,"mc":[{"id":"1.230180128","rc":[{"atb":[[2.22,3.38]],"id":51218587}],"con":true,"img":false}]}
{"op":"mcm","clk":"11539349116","pt":1719479433141,"mc":[{"id":"1.230180128","rc":[{"atb":[[2.24,3.38]],"id":50639934}],"con":true,"img":false}]}
{"op":"mcm","clk":"11539349176","pt":1719479434025,"mc":[{"id":"1.230180128","rc":[{"atb":[[2.22,3.38]],"id":60237218}],"con":true,"img":false}]}
{"op":"mcm","clk":"11539367483","pt":1719479704521,"mc":[{"id":"1.230180128","rc":[{"spn":76.1,"spf":"NaN","id":58821523},{"atb":[[2.24,6.54]],"id":50639934},{"spn":16.12,"spf":"NaN","id":50639934},{"spn":76.11,"spf":"NaN","id":60237218},{"spn":76.11,"spf":"NaN","id":51218587},{"spn":76.07,"spf":"NaN","id":69213654},{"spn":76.08,"spf":"NaN","id":66050026}],"con":true,"img":false}]}
{"op":"mcm","clk":"11539367500","pt":1719479704728,"mc":[{"id":"1.230180128","rc":[{"atb":[[2.16,6.54]],"id":66050026}],"con":true,"img":false}]}
{"op":"mcm","clk":"11539367523","pt":1719479705034,"mc":[{"id":"1.230180128","rc":[{"atb":[[2.22,6.54]],"id":60237218}],"con":true,"img":false}]}
{"op":"mcm","clk":"11539367561","pt":1719479705553,"mc":[{"id":"1.230180128","rc":[{"atb":[[2.2,6.54]],"id":58821523}],"con":true,"img":false}]}
{"op":"mcm","clk":"11539367685","pt":1719479706953,"mc":[{"id":"1.230180128","rc":[{"atb":[[2.14,6.54]],"id":69213654}],"con":true,"img":false}]}
{"op":"mcm","clk":"11539367831","pt":1719479708959,"mc":[{"id":"1.230180128","rc":[{"atb":[[2.22,6.54]],"id":51218587}],"con":true,"img":false}]}
{"op":"mcm","clk":"11539526289","pt":1719482590225,"mc":[{"id":"1.230180128","rc":[{"atb":[[1.03,10.98],[2.18,11.43],[2.2,6.54]],"id":58821523},{"atb":[[2.24,6.54],[2.22,8.96],[1.02,16.47]],"id":50639934},{"atb":[[2.24,2],[2.22,6.54],[1.02,16.47],[2.2,12.43]],"id":60237218},{"spn":76.12,"spf":"NaN","id":60237218},{"atb":[[2.22,6.54],[1.02,16.47],[2.2,11.54]],"id":51218587},{"atb":[[1.03,10.98],[2.12,11.1],[2.14,6.54]],"id":69213654},{"atb":[[1.03,10.98],[2.16,6.54],[2.14,12.07]],"id":66050026}],"con":true,"img":false}]}
{"op":"mcm","clk":"11539545578","pt":1719482912607,"mc":[{"id":"1.230180128","rc":[{"atb":[[2.18,0]],"id":58821523},{"atb":[[2.22,0]],"id":50639934},{"atb":[[2.2,0]],"id":60237218},{"atb":[[2.2,0]],"id":51218587},{"atb":[[2.12,0]],"id":69213654},{"atb":[[2.14,0]],"id":66050026}],"con":true,"img":false}]}
{"op":"mcm","clk":"11539545590","pt":1719482912665,"mc":[{"id":"1.230180128","rc":[{"atb":[[2.22,11.43]],"id":58821523},{"atb":[[2.26,8.96]],"id":50639934},{"atb":[[2.24,14.43]],"id":60237218},{"atb":[[2.24,11.54]],"id":51218587},{"atb":[[2.16,11.1]],"id":69213654},{"atb":[[2.18,12.07]],"id":66050026}],"con":true,"img":false}]}
{"op":"mcm","clk":"11539548090","pt":1719482950155,"mc":[{"id":"1.230180128","rc":[{"atb":[[2.2,3.16]],"id":58821523}],"con":true,"img":false}]}
{"op":"mcm","clk":"11539548101","pt":1719482950416,"mc":[{"id":"1.230180128","rc":[{"atb":[[2.16,3.16]],"id":66050026}],"con":true,"img":false}]}
{"op":"mcm","clk":"11539548118","pt":1719482950937,"mc":[{"id":"1.230180128","rc":[{"atb":[[2.24,3.16]],"id":50639934}],"con":true,"img":false}]}
{"op":"mcm","clk":"11539548121","pt":1719482951037,"mc":[{"id":"1.230180128","rc":[{"atb":[[2.22,3.16]],"id":60237218}],"con":true,"img":false}]}
{"op":"mcm","clk":"11539548134","pt":1719482951359,"mc":[{"id":"1.230180128","rc":[{"atb":[[2.22,3.16]],"id":51218587}],"con":true,"img":false}]}
{"op":"mcm","clk":"11539548168","pt":1719482951931,"mc":[{"id":"1.230180128","rc":[{"atb":[[2.14,3.16]],"id":69213654}],"con":true,"img":false}]}
{"op":"mcm","clk":"11539548177","pt":1719482952032,"mc":[{"id":"1.230180128","rc":[{"atb":[[2.24,3.38]],"id":58821523}],"con":true,"img":false}]}
{"op":"mcm","clk":"11539548239","pt":1719482952964,"mc":[{"id":"1.230180128","rc":[{"atb":[[2.26,3.38]],"id":60237218},{"atb":[[2.2,3.38]],"id":66050026}],"con":true,"img":false}]}
{"op":"mcm","clk":"11539548270","pt":1719482953434,"mc":[{"id":"1.230180128","rc":[{"atb":[[2.18,3.38]],"id":69213654}],"con":true,"img":false}]}
{"op":"mcm","clk":"11539548277","pt":1719482953544,"mc":[{"id":"1.230180128","rc":[{"atb":[[2.28,3.38]],"id":50639934}],"con":true,"img":false}]}
{"op":"mcm","clk":"11539548305","pt":1719482953874,"mc":[{"id":"1.230180128","rc":[{"atb":[[2.26,3.38]],"id":51218587}],"con":true,"img":false}]}
{"op":"mcm","clk":"11539553297","pt":1719483027847,"mc":[{"id":"1.230180128","rc":[{"atb":[[2.2,0]],"id":58821523},{"spn":76.12,"spf":"NaN","id":58821523},{"atb":[[2.24,0]],"id":50639934},{"spn":16.14,"spf":"NaN","id":50639934},{"atb":[[2.22,0]],"id":60237218},{"spn":76.13,"spf":"NaN","id":60237218},{"atb":[[2.22,0]],"id":51218587},{"spn":76.13,"spf":"NaN","id":51218587},{"atb":[[2.14,0]],"id":69213654},{"spn":76.09,"spf":"NaN","id":69213654},{"atb":[[2.16,0]],"id":66050026},{"spn":76.1,"spf":"NaN","id":66050026}],"con":true,"img":false}]}
{"op":"mcm","clk":"11539572891","pt":1719483321830,"mc":[{"id":"1.230180128","rc":[{"atb":[[2.2,6.54]],"id":66050026}],"con":true,"img":false}]}
{"op":"mcm","clk":"11539572900","pt":1719483321927,"mc":[{"id":"1.230180128","rc":[{"atb":[[2.24,6.54]],"id":58821523}],"con":true,"img":false}]}
{"op":"mcm","clk":"11539572904","pt":1719483322031,"mc":[{"id":"1.230180128","rc":[{"atb":[[2.26,6.54]],"id":51218587}],"con":true,"img":false}]}
{"op":"mcm","clk":"11539572910","pt":1719483322136,"mc":[{"id":"1.230180128","rc":[{"atb":[[2.18,6.54]],"id":69213654}],"con":true,"img":false}]}
{"op":"mcm","clk":"11539572930","pt":1719483322446,"mc":[{"id":"1.230180128","rc":[{"atb":[[2.28,6.54]],"id":50639934}],"con":true,"img":false}]}
{"op":"mcm","clk":"11539572950","pt":1719483322668,"mc":[{"id":"1.230180128","rc":[{"atb":[[2.26,6.54]],"id":60237218}],"con":true,"img":false}]}
{"op":"mcm","clk":"11539777400","pt":1719486049622,"mc":[{"id":"1.230180128","rc":[{"atb":[[2.24,6.54],[1.03,10.98],[2.22,11.43],[3,6]],"id":58821523},{"spn":76.5,"spf":"NaN","id":58821523},{"atb":[[1.02,16.47],[2.28,6.54],[3.55,6],[2.26,8.96]],"id":50639934},{"spn":16.77,"spf":"NaN","id":50639934},{"atb":[[2.24,14.43],[5,6],[1.02,16.47],[2.26,6.54]],"id":60237218},{"spn":77.5,"spf":"NaN","id":60237218},{"atb":[[2.24,11.54],[1.02,16.47],[2.26,6.54]],"id":51218587},{"atb":[[1.03,10.98],[2.18,6.54],[3.55,6],[2.16,11.1]],"id":69213654},{"spn":76.77,"spf":"NaN","id":69213654},{"atb":[[1.03,10.98],[5,6],[2.18,12.08],[2.2,6.54]],"id":66050026},{"spn":77.5,"spf":"NaN","id":66050026}],"con":true,"img":false}]}
{"op":"mcm","clk":"11539777408","pt":1719486049721,"mc":[{"id":"1.230180128","rc":[{"atb":[[1.84,6]],"id":51218587}],"con":true,"img":false}]}
{"op":"mcm","clk":"11539778669","pt":1719486069877,"mc":[{"id":"1.230180128","rc":[{"atb":[[2.24,3.16]],"id":58821523},{"atb":[[2.28,3.16]],"id":50639934},{"atb":[[2.26,3.16]],"id":60237218},{"atb":[[2.18,3.16]],"id":69213654},{"atb":[[2.2,3.16]],"id":66050026}],"con":true,"img":false}]}
{"op":"mcm","clk":"11539779069","pt":1719486076547,"mc":[{"id":"1.230180128","rc":[{"atb":[[2.24,0]],"id":58821523},{"atb":[[2.28,0]],"id":50639934},{"atb":[[2.26,0]],"id":60237218},{"atb":[[2.18,0]],"id":69213654},{"atb":[[2.2,0]],"id":66050026}],"con":true,"img":false}]}
{"op":"mcm","clk":"11539787016","pt":1719486199105,"mc":[{"id":"1.230180128","rc":[{"atl":[[36,12],[21,8]],"id":58821523},{"spn":12.0,"spf":"NaN","id":58821523},{"atl":[[46,12],[27,8]],"id":50639934},{"spn":15.27,"spf":"NaN","id":50639934},{"atl":[[32,8],[55,12]],"id":51218587},{"spn":17.13,"spf":"NaN","id":51218587},{"atl":[[32,8],[55,12]],"id":69213654},{"spn":17.77,"spf":"NaN","id":69213654}],"con":true,"img":false}]}
{"op":"mcm","clk":"11539817436","pt":1719486507339,"mc":[{"id":"1.230180128","rc":[{"atb":[[2.24,0]],"id":51218587}],"con":true,"img":false}]}
{"op":"mcm","clk":"11539817439","pt":1719486507447,"mc":[{"id":"1.230180128","rc":[{"atb":[[2.28,11.54]],"id":51218587}],"con":true,"img":false}]}
{"op":"mcm","clk":"11539818735","pt":1719486521577,"mc":[{"id":"1.230180128","rc":[{"atb":[[2.26,3.38]],"id":51218587}],"con":true,"img":false}]}
{"op":"mcm","clk":"11539818805","pt":1719486522364,"mc":[{"id":"1.230180128","rc":[{"atb":[[2.3,3.16]],"id":51218587}],"con":true,"img":false}]}
{"op":"mcm","clk":"11539824755","pt":1719486591464,"mc":[{"id":"1.230180128","rc":[{"atb":[[2.26,0]],"id":51218587},{"spn":17.15,"spf":"NaN","id":51218587}],"con":true,"img":false}]}
{"op":"mcm","clk":"11539825647","pt":1719486603338,"mc":[{"id":"1.230180128","rc":[{"atb":[[2.3,6.54]],"id":51218587}],"con":true,"img":false}]}
{"op":"mcm","clk":"11539840669","pt":1719486807422,"mc":[{"id":"1.230180128","rc":[{"atb":[[2.28,0]],"id":51218587}],"con":true,"img":false}]}
{"op":"mcm","clk":"11539840677","pt":1719486807528,"mc":[{"id":"1.230180128","rc":[{"atb":[[2.32,11.54]],"id":51218587}],"con":true,"img":false}]}
{"op":"mcm","clk":"11539841485","pt":1719486820634,"mc":[{"id":"1.230180128","rc":[{"atb":[[2.3,3.38]],"id":51218587}],"con":true,"img":false}]}
{"op":"mcm","clk":"11539843009","pt":1719486843748,"mc":[{"id":"1.230180128","rc":[{"atb":[[2.3,0]],"id":51218587}],"con":true,"img":false}]}
{"op":"mcm","clk":"11539848721","pt":1719486924194,"mc":[{"id":"1.230180128","rc":[{"atb":[[2.34,3.38]],"id":51218587},{"spn":17.17,"spf":"NaN","id":51218587}],"con":true,"img":false}]}
{"op":"mcm","clk":"11539850333","pt":1719486945135,"mc":[{"id":"1.230180128","rc":[{"atb":[[2.34,6.54]],"id":51218587}],"con":true,"img":false}]}
{"op":"mcm","clk":"11540014485","pt":1719489000334,"mc":[{"id":"1.230180128","rc":[{"atb":[[1.16,150]],"id":58821523},{"atl":[[390,2]],"id":58821523},{"atb":[[1.16,150]],"id":50639934},{"atl":[[550,2]],"id":50639934},{"atb":[[1.16,150]],"id":60237218},{"atl":[[500,2]],"id":60237218},{"atb":[[1.16,150]],"id":51218587},{"atl":[[560,2]],"id":51218587},{"atb":[[1.16,150]],"id":69213654},{"atl":[[270,2]],"id":69213654},{"atb":[[1.16,150]],"id":66050026},{"atl":[[370,2]],"id":66050026}],"con":true,"img":false}]}
{"op":"mcm","clk":"11540078225","pt":1719489783681,"mc":[{"id":"1.230180128","rc":[{"atb":[[4.8,1]],"id":58821523},{"spn":12.9,"spf":"NaN","id":58821523},{"atb":[[5,1]],"id":50639934},{"spn":16.0,"spf":"NaN","id":50639934},{"atb":[[5,7]],"id":60237218},{"atb":[[2.4,1.61],[2.34,6.54]],"id":51218587},{"spn":17.2,"spf":"NaN","id":51218587},{"atb":[[5,1]],"id":69213654},{"spn":18.5,"spf":"NaN","id":69213654},{"atb":[[5,7]],"id":66050026}],"con":true,"img":false}]}
{"op":"mcm","clk":"11540078985","pt":1719489792402,"mc":[{"id":"1.230180128","rc":[{"atb":[[1.51,196.08]],"id":50639934},{"atb":[[1.51,196.08]],"id":60237218},{"atb":[[1.51,196.08]],"id":69213654},{"atb":[[1.51,196.08]],"id":66050026}],"con":true,"img":false}]}
{"op":"mcm","clk":"11540136518","pt":1719490402399,"mc":[{"id":"1.230180128","rc":[{"atb":[[2.32,0]],"id":51218587}],"con":true,"img":false}]}
{"op":"mcm","clk":"11540136526","pt":1719490402451,"mc":[{"id":"1.230180128","rc":[{"atb":[[2.36,11.54]],"id":51218587}],"con":true,"img":false}]}
{"op":"mcm","clk":"11540140411","pt":1719490440811,"mc":[{"id":"1.230180128","rc":[{"atb":[[2.34,3.16]],"id":51218587}],"con":true,"img":false}]}
{"op":"mcm","clk":"11540141482","pt":1719490451128,"mc":[{"id":"1.230180128","rc":[{"atb":[[2.38,3.38]],"id":51218587}],"con":true,"img":false}]}
{"op":"mcm","clk":"11540143817","pt":1719490474049,"mc":[{"id":"1.230180128","rc":[{"atb":[[2.34,0]],"id":51218587}],"con":true,"img":false}]}
{"op":"mcm","clk":"11540145787","pt":1719490492155,"mc":[{"id":"1.230180128","rc":[{"atb":[[2.38,6.54]],"id":51218587}],"con":true,"img":false}]}
{"op":"mcm","clk":"11540168654","pt":1719490747948,"mc":[{"id":"1.230180128","rc":[{"atb":[[2.12,89.29]],"id":50639934}],"con":true,"img":false}]}
{"op":"mcm","clk":"11540168664","pt":1719490748052,"mc":[{"id":"1.230180128","rc":[{"atb":[[1.51,196.08]],"id":58821523},{"atb":[[2.12,89.29]],"id":69213654}],"con":true,"img":false}]}
{"op":"mcm","clk":"11540639871","pt":1719496771436,"mc":[{"id":"1.230180128","rc":[{"atb":[[1.03,120.25],[2.22,11.45]],"id":58821523},{"atl":[[990,0.17],[960,1.79]],"id":58821523},{"atb":[[1.03,174.47],[1.02,16.49],[2.26,8.97]],"id":50639934},{"atl":[[970,2.11],[1000,0.17]],"id":50639934},{"atb":[[2.24,14.45],[1.02,97.8]],"id":60237218},{"atl":[[990,0.17],[970,0.84]],"id":60237218},{"atb":[[2.36,11.56],[2.38,6.54],[1.02,118.98]],"id":51218587},{"atl":[[990,0.17],[970,2.11]],"id":51218587},{"atb":[[1.03,11],[1.02,106.71],[2.16,11.12]],"id":69213654},{"atl":[[990,1.05],[1000,0.17]],"id":69213654},{"atb":[[1.03,11],[2.18,12.09],[1.04,94.01]],"id":66050026},{"atl":[[960,1.71],[1000,0.17]],"id":66050026}],"con":true,"img":false}]}
{"op":"mcm","clk":"11540687344","pt":1719497282743,"mc":[{"id":"1.230180128","marketDefinition":{"bspMarket":true,"turnInPlayEnabled":false,"persistenceEnabled":false,"marketBaseRate":5.0,"eventId":"33376437","eventTypeId":"4339","numberOfWinners":1,"bettingType":"ODDS","marketType":"WIN","marketTime":"2024-06-27T16:03:00.000Z","suspendTime":"2024-06-27T16:03:00.000Z","bspReconciled":false,"complete":true,"inPlay":false,"crossMatching":true,"runnersVoidable":false,"numberOfActiveRunners":6,"betDelay":0,"status":"OPEN","runners":[{"status":"ACTIVE","sortPriority":1,"id":66050026,"name":"1. Salacres Elunico"},{"status":"ACTIVE","sortPriority":2,"id":58821523,"name":"2. Makeit Missy"},{"status":"ACTIVE","sortPriority":3,"id":50639934,"name":"3. Greencroft Annie"},{"status":"ACTIVE","sortPriority":4,"id":69213654,"name":"4. Salacres Crafty"},{"status":"ACTIVE","sortPriority":5,"id":51218587,"name":"5. Golden Bullet"},{"status":"ACTIVE","sortPriority":6,"id":60237218,"name":"6. Arwens Link"}],"regulators":["MR_INT"],"venue":"Towcester","countryCode":"GB","discountAllowed":true,"timezone":"Europe/London","openDate":"2024-06-27T13:33:00.000Z","version":5994767097,"name":"A3 500m","eventName":"Towcester 27th Jun"},"rc":[{"atb":[[4.8,1],[1.16,150],[1.03,120.2],[2.22,11.44],[3,6],[1.51,196.08]],"id":58821523},{"atl":[[36,12],[150,4],[21,8],[390,2],[960,1.79],[990,0.17]],"id":58821523},{"spn":12.9,"spf":"NaN","id":58821523},{"atb":[[5,1],[1.16,150],[1.03,174.39],[1.02,16.49],[2.12,89.29],[3.55,6],[2.26,8.97],[1.51,196.08]],"id":50639934},{"atl":[[550,2],[150,4],[46,12],[27,8],[30,0.6],[970,2.11],[1000,0.17]],"id":50639934},{"spn":16.0,"spf":"NaN","id":50639934},{"atb":[[2.24,14.44],[5,7],[1.16,150],[1.02,97.76],[1.51,196.08]],"id":60237218},{"atl":[[150,4],[970,0.84],[990,0.17],[500,2]],"id":60237218},{"spn":77.5,"spf":"NaN","id":60237218},{"atb":[[2.4,1.61],[2.36,11.55],[1.16,150],[1.84,6],[2.38,6.54],[1.02,118.92]],"id":51218587},{"atl":[[32,8],[560,2],[150,4],[55,12],[970,2.11],[990,0.17]],"id":51218587},{"spn":17.2,"spf":"NaN","id":51218587},{"atb":[[5,1],[1.16,150],[1.03,10.99],[1.02,106.67],[2.12,89.29],[3.55,6],[1.51,196.08],[2.16,11.11]],"id":69213654},{"atl":[[32,8],[270,2],[150,4],[55,12],[990,1.04],[1000,0.17]],"id":69213654},{"spn":18.5,"spf":"NaN","id":69213654},{"atb":[[5,7],[1.16,150],[1.03,10.99],[2.18,12.08],[1.51,196.08],[1.04,93.97]],"id":66050026},{"atl":[[150,4],[370,2],[960,1.71],[1000,0.17]],"id":66050026},{"spn":77.5,"spf":"NaN","id":66050026}],"con":true,"img":true}]}
{"op":"mcm","clk":"11540723545","pt":1719497688264,"mc":[{"id":"1.230180128","rc":[{"spl":[[1.01,1]],"id":58821523},{"atb":[[1.03,120.2],[2.22,11.44]],"id":58821523},{"atl":[[960,1.79]],"id":58821523},{"spn":4.8,"spf":1.0,"id":58821523},{"atb":[[1.03,174.39],[1.02,16.49],[2.26,8.97]],"id":50639934},{"atl":[[970,2.11]],"id":50639934},{"atb":[[2.24,14.44],[1.02,97.76]],"id":60237218},{"atl":[[970,0.84]],"id":60237218},{"atb":[[2.36,11.55],[2.38,6.54],[1.02,118.92]],"id":51218587},{"atl":[[970,2.11]],"id":51218587},{"atb":[[1.03,10.99],[1.02,106.67],[2.16,11.11]],"id":69213654},{"atl":[[990,1.04]],"id":69213654},{"atb":[[1.03,10.99],[2.18,12.08],[1.04,93.97]],"id":66050026},{"atl":[[960,1.71]],"id":66050026}],"con":true,"img":false}]}
{"op":"mcm","clk":"11541090077","pt":1719502055731,"mc":[{"id":"1.230180128","rc":[{"atb":[[1.03,120.22],[2.22,11.44]],"id":58821523},{"atl":[[960,1.79]],"id":58821523},{"atb":[[1.03,174.42],[1.02,16.49],[2.26,8.97]],"id":50639934},{"atl":[[26,1.69],[970,2.11]],"id":50639934},{"spn":15.5,"spf":"NaN","id":50639934},{"atb":[[2.24,14.44],[1.02,97.78]],"id":60237218},{"atl":[[970,0.84]],"id":60237218},{"atb":[[2.36,11.55],[2.38,6.54],[1.02,118.95]],"id":51218587},{"atl":[[970,2.11]],"id":51218587},{"atb":[[1.03,10.99],[1.02,106.68],[2.16,11.11]],"id":69213654},{"atl":[[990,1.04]],"id":69213654},{"atb":[[1.03,10.99],[2.18,12.09],[1.04,93.98]],"id":66050026},{"atl":[[960,1.71]],"id":66050026}],"con":true,"img":false}]}
{"op":"mcm","clk":"11541090105","pt":1719502056040,"mc":[{"id":"1.230180128","rc":[{"atl":[[20,1.52]],"id":58821523}],"con":true,"img":false}]}
{"op":"mcm","clk":"11541144296","pt":1719502695688,"mc":[{"id":"1.230180128","rc":[{"atl":[[190,4]],"id":58821523},{"atl":[[190,4]],"id":50639934},{"atl":[[190,4]],"id":60237218},{"atl":[[190,4]],"id":51218587},{"atl":[[190,4]],"id":69213654},{"atl":[[190,4]],"id":66050026}],"con":true,"img":false}]}
{"op":"mcm","clk":"11541145917","pt":1719502715040,"mc":[{"id":"1.230180128","rc":[{"atb":[[1.02,2]],"id":66050026}],"con":true,"img":false}]}
{"op":"mcm","clk":"11541145950","pt":1719502715295,"mc":[{"id":"1.230180128","rc":[{"atb":[[1.02,2]],"id":58821523}],"con":true,"img":false}]}
{"op":"mcm","clk":"11541145965","pt":1719502715508,"mc":[{"id":"1.230180128","rc":[{"atb":[[1.02,18.49]],"id":50639934}],"con":true,"img":false}]}
{"op":"mcm","clk":"11541145985","pt":1719502715712,"mc":[{"id":"1.230180128","rc":[{"atb":[[1.02,108.68]],"id":69213654}],"con":true,"img":false}]}
{"op":"mcm","clk":"11541146017","pt":1719502716035,"mc":[{"id":"1.230180128","rc":[{"atb":[[2.42,2]],"id":51218587}],"con":true,"img":false}]}
{"op":"mcm","clk":"11541146034","pt":1719502716242,"mc":[{"id":"1.230180128","rc":[{"atb":[[1.02,99.78]],"id":60237218}],"con":true,"img":false}]}
{"op":"mcm","clk":"11541147879","pt":1719502738822,"mc":[{"id":"1.230180128","rc":[{"atl":[[1000,1]],"id":51218587}],"con":true,"img":false}]}
{"op":"mcm","clk":"11541147899","pt":1719502739024,"mc":[{"id":"1.230180128","rc":[{"atl":[[1000,0.03]],"id":51218587}],"con":true,"img":false}]}
{"op":"mcm","clk":"11541147915","pt":1719502739228,"mc":[{"id":"1.230180128","rc":[{"atl":[[1000,0]],"id":51218587}],"con":true,"img":false}]}
{"op":"mcm","clk":"11541147924","pt":1719502739332,"mc":[{"id":"1.230180128","rc":[{"atl":[[30,0.03]],"id":51218587}],"con":true,"img":false}]}
{"op":"mcm","clk":"11541154608","pt":1719502808095,"mc":[{"id":"1.230180128","rc":[{"spn":16.21,"spf":"NaN","id":51218587},{"atb":[[5.5,5]],"id":66050026},{"spn":77.75,"spf":"NaN","id":66050026}],"con":true,"img":false}]}
{"op":"mcm","clk":"11541156094","pt":1719502823432,"mc":[{"id":"1.230180128","rc":[{"atb":[[2.12,89.29]],"id":66050026}],"con":true,"img":false}]}
{"op":"mcm","clk":"11541156140","pt":1719502824108,"mc":[{"id":"1.230180128","rc":[{"atb":[[5.5,5]],"id":60237218}],"con":true,"img":false}]}
{"op":"mcm","clk":"11541157421","pt":1719502839246,"mc":[{"id":"1.230180128","rc":[{"atb":[[2.12,89.29]],"id":60237218}],"con":true,"img":false}]}
{"op":"mcm","clk":"11541157645","pt":1719502842151,"mc":[{"id":"1.230180128","rc":[{"atb":[[5.5,0]],"id":60237218}],"con":true,"img":false}]}
{"op":"mcm","clk":"11541157755","pt":1719502843465,"mc":[{"id":"1.230180128","rc":[{"atb":[[5.5,0]],"id":66050026}],"con":true,"img":false}]}
{"op":"mcm","clk":"11541176582","pt":1719503052457,"mc":[{"id":"1.230180128","rc":[{"atb":[[4.8,0]],"id":58821523},{"trd":[[4.8,2]],"ltp":4.8,"tv":2.0,"id":58821523},{"spn":3.0,"spf":1.0,"id":58821523},{"spn":77.5,"spf":"NaN","id":66050026}],"con":true,"img":false}]}
{"op":"mcm","clk":"11541176748","pt":1719503054175,"mc":[{"id":"1.230180128","rc":[{"atb":[[1.05,1]],"id":58821523},{"atl":[[1000,0.05]],"id":58821523}],"con":true,"img":false}]}
{"op":"mcm","clk":"11541176759","pt":1719503054276,"mc":[{"id":"1.230180128","rc":[{"atb":[[1.05,0.49]],"id":58821523},{"atl":[[1000,0]],"id":58821523}],"con":true,"img":false}]}
{"op":"mcm","clk":"11541176770","pt":1719503054382,"mc":[{"id":"1.230180128","rc":[{"atb":[[1.05,0]],"id":58821523},{"atl":[[19.5,0.05]],"id":58821523}],"con":true,"img":false}]}
{"op":"mcm","clk":"11541176778","pt":1719503054484,"mc":[{"id":"1.230180128","rc":[{"atb":[[3.05,0.49]],"id":58821523}],"con":true,"img":false}]}
{"op":"mcm","clk":"11541176817","pt":1719503054847,"mc":[{"id":"1.230180128","rc":[{"atb":[[4.3,1]],"id":58821523}],"con":true,"img":false}]}
{"op":"mcm","clk":"11541178190","pt":1719503069595,"mc":[{"id":"1.230180128","rc":[{"atl":[[19.5,0]],"id":58821523}],"con":true,"img":false}]}
{"op":"mcm","clk":"11541178205","pt":1719503069700,"mc":[{"id":"1.230180128","rc":[{"atb":[[3.05,0]],"id":58821523}],"con":true,"img":false}]}
{"op":"mcm","clk":"11541178249","pt":1719503070077,"mc":[{"id":"1.230180128","rc":[{"atl":[[1000,0.05]],"id":58821523}],"con":true,"img":false}]}
{"op":"mcm","clk":"11541178273","pt":1719503070276,"mc":[{"id":"1.230180128","rc":[{"atl":[[1000,0]],"id":58821523}],"con":true,"img":false}]}
{"op":"mcm","clk":"11541178281","pt":1719503070382,"mc":[{"id":"1.230180128","rc":[{"atl":[[19.5,0.05]],"id":58821523}],"con":true,"img":false}]}
{"op":"mcm","clk":"11541179836","pt":1719503085610,"mc":[{"id":"1.230180128","rc":[{"atl":[[19.5,0]],"id":58821523}],"con":true,"img":false}]}
{"op":"mcm","clk":"11541179860","pt":1719503085923,"mc":[{"id":"1.230180128","rc":[{"atl":[[1000,0.05]],"id":58821523}],"con":true,"img":false}]}
{"op":"mcm","clk":"11541179875","pt":1719503086126,"mc":[{"id":"1.230180128","rc":[{"atl":[[1000,0]],"id":58821523}],"con":true,"img":false}]}
{"op":"mcm","clk":"11541179886","pt":1719503086180,"mc":[{"id":"1.230180128","rc":[{"atl":[[19.5,0.05]],"id":58821523}],"con":true,"img":false}]}
{"op":"mcm","clk":"11541180499","pt":1719503092519,"mc":[{"id":"1.230180128","rc":[{"atb":[[2.5,85.81]],"id":60237218}],"con":true,"img":false}]}
{"op":"mcm","clk":"11541181114","pt":1719503099833,"mc":[{"id":"1.230180128","rc":[{"atl":[[19.5,0.89]],"id":58821523},{"atl":[[25,0.84]],"id":50639934}],"con":true,"img":false}]}
{"op":"mcm","clk":"11541181278","pt":1719503101412,"mc":[{"id":"1.230180128","rc":[{"atl":[[19.5,0.84]],"id":58821523}],"con":true,"img":false}]}
{"op":"mcm","clk":"11541181308","pt":1719503101730,"mc":[{"id":"1.230180128","rc":[{"atl":[[1000,0.05]],"id":58821523}],"con":true,"img":false}]}
{"op":"mcm","clk":"11541181331","pt":1719503101930,"mc":[{"id":"1.230180128","rc":[{"atl":[[1000,0]],"id":58821523}],"con":true,"img":false}]}
{"op":"mcm","clk":"11541181342","pt":1719503102040,"mc":[{"id":"1.230180128","rc":[{"atl":[[19.5,0.89]],"id":58821523}],"con":true,"img":false}]}
{"op":"mcm","clk":"11541182824","pt":1719503117258,"mc":[{"id":"1.230180128","rc":[{"atl":[[19.5,0.84]],"id":58821523},{"spn":4.3,"spf":1.0,"id":58821523},{"spn":15.0,"spf":"NaN","id":50639934}],"con":true,"img":false}]}
{"op":"mcm","clk":"11541182845","pt":1719503117563,"mc":[{"id":"1.230180128","rc":[{"atl":[[1000,0.05]],"id":58821523}],"con":true,"img":false}]}
{"op":"mcm","clk":"11541182864","pt":1719503117769,"mc":[{"id":"1.230180128","rc":[{"atl":[[1000,0]],"id":58821523}],"con":true,"img":false}]}
{"op":"mcm","clk":"11541182878","pt":1719503117892,"mc":[{"id":"1.230180128","rc":[{"atl":[[19.5,0.89]],"id":58821523}],"con":true,"img":false}]}
{"op":"mcm","clk":"11541183851","pt":1719503128056,"mc":[{"id":"1.230180128","rc":[{"atb":[[2.22,18.52]],"id":58821523},{"atb":[[2.26,16.54]],"id":50639934},{"atb":[[2.42,3.8]],"id":51218587}],"con":true,"img":false}]}
{"op":"mcm","clk":"11541184388","pt":1719503133153,"mc":[{"id":"1.230180128","rc":[{"atl":[[19.5,0.84]],"id":58821523}],"con":true,"img":false}]}
{"op":"mcm","clk":"11541184403","pt":1719503133351,"mc":[{"id":"1.230180128","rc":[{"atl":[[1000,0.05]],"id":58821523}],"con":true,"img":false}]}
{"op":"mcm","clk":"11541184429","pt":1719503133567,"mc":[{"id":"1.230180128","rc":[{"atl":[[1000,0]],"id":58821523}],"con":true,"img":false}]}
{"op":"mcm","clk":"11541184435","pt":1719503133661,"mc":[{"id":"1.230180128","rc":[{"atl":[[19.5,0.89]],"id":58821523}],"con":true,"img":false}]}
{"op":"mcm","clk":"11541185929","pt":1719503148878,"mc":[{"id":"1.230180128","rc":[{"atl":[[19.5,0.84]],"id":58821523}],"con":true,"img":false}]}
{"op":"mcm","clk":"11541185955","pt":1719503149185,"mc":[{"id":"1.230180128","rc":[{"atl":[[1000,0.05]],"id":58821523}],"con":true,"img":false}]}
{"op":"mcm","clk":"11541185974","pt":1719503149400,"mc":[{"id":"1.230180128","rc":[{"atl":[[1000,0]],"id":58821523}],"con":true,"img":false}]}
{"op":"mcm","clk":"11541185984","pt":1719503149500,"mc":[{"id":"1.230180128","rc":[{"atl":[[19.5,0.89]],"id":58821523}],"con":true,"img":false}]}
{"op":"mcm","clk":"11541187486","pt":1719503164750,"mc":[{"id":"1.230180128","rc":[{"atl":[[19.5,0.84]],"id":58821523}],"con":true,"img":false}]}
{"op":"mcm","clk":"11541187512","pt":1719503165011,"mc":[{"id":"1.230180128","rc":[{"atl":[[1000,0.05]],"id":58821523}],"con":true,"img":false}]}
{"op":"mcm","clk":"11541187532","pt":1719503165219,"mc":[{"id":"1.230180128","rc":[{"atl":[[1000,0]],"id":58821523}],"con":true,"img":false}]}
{"op":"mcm","clk":"11541187545","pt":1719503165319,"mc":[{"id":"1.230180128","rc":[{"atl":[[19.5,0.89]],"id":58821523}],"con":true,"img":false}]}
{"op":"mcm","clk":"11541189247","pt":1719503180529,"mc":[{"id":"1.230180128","rc":[{"atl":[[19.5,0.84]],"id":58821523}],"con":true,"img":false}]}
{"op":"mcm","clk":"11541189274","pt":1719503180737,"mc":[{"id":"1.230180128","rc":[{"atl":[[1000,0.05]],"id":58821523}],"con":true,"img":false}]}
{"op":"mcm","clk":"11541189292","pt":1719503180893,"mc":[{"id":"1.230180128","rc":[{"atl":[[1000,0]],"id":58821523}],"con":true,"img":false}]}
{"op":"mcm","clk":"11541189307","pt":1719503181005,"mc":[{"id":"1.230180128","rc":[{"atl":[[19.5,0.89]],"id":58821523}],"con":true,"img":false}]}
{"op":"mcm","clk":"11541191123","pt":1719503196263,"mc":[{"id":"1.230180128","rc":[{"atl":[[19.5,0.84]],"id":58821523}],"con":true,"img":false}]}
{"op":"mcm","clk":"11541191339","pt":1719503197758,"mc":[{"id":"1.230180128","rc":[{"atl":[[1000,0.05]],"id":58821523}],"con":true,"img":false}]}
{"op":"mcm","clk":"11541191366","pt":1719503197927,"mc":[{"id":"1.230180128","rc":[{"atl":[[1000,0]],"id":58821523}],"con":true,"img":false}]}
{"op":"mcm","clk":"11541191379","pt":1719503198029,"mc":[{"id":"1.230180128","rc":[{"atl":[[19.5,0.89]],"id":58821523}],"con":true,"img":false}]}
{"op":"mcm","clk":"11541193094","pt":1719503213268,"mc":[{"id":"1.230180128","rc":[{"atl":[[19.5,0.84]],"id":58821523}],"con":true,"img":false}]}
{"op":"mcm","clk":"11541193117","pt":1719503213474,"mc":[{"id":"1.230180128","rc":[{"atl":[[1000,0.05]],"id":58821523}],"con":true,"img":false}]}
{"op":"mcm","clk":"11541193140","pt":1719503213691,"mc":[{"id":"1.230180128","rc":[{"atl":[[1000,0]],"id":58821523}],"con":true,"img":false}]}
{"op":"mcm","clk":"11541193151","pt":1719503213787,"mc":[{"id":"1.230180128","rc":[{"atl":[[19.5,0.89]],"id":58821523}],"con":true,"img":false}]}
{"op":"mcm","clk":"11541194759","pt":1719503229013,"mc":[{"id":"1.230180128","rc":[{"atl":[[19.5,0.84]],"id":58821523}],"con":true,"img":false}]}
{"op":"mcm","clk":"11541194778","pt":1719503229220,"mc":[{"id":"1.230180128","rc":[{"atl":[[1000,0.05]],"id":58821523}],"con":true,"img":false}]}
{"op":"mcm","clk":"11541194788","pt":1719503229365,"mc":[{"id":"1.230180128","rc":[{"atl":[[1000,0]],"id":58821523}],"con":true,"img":false}]}
{"op":"mcm","clk":"11541194797","pt":1719503229474,"mc":[{"id":"1.230180128","rc":[{"atl":[[19.5,0.89]],"id":58821523}],"con":true,"img":false}]}
{"op":"mcm","clk":"11541196110","pt":1719503242892,"mc":[{"id":"1.230180128","rc":[{"atb":[[3,9.14]],"id":58821523}],"con":true,"img":false}]}
{"op":"mcm","clk":"11541196284","pt":1719503244812,"mc":[{"id":"1.230180128","rc":[{"atl":[[19.5,0.84]],"id":58821523}],"con":true,"img":false}]}
{"op":"mcm","clk":"11541196302","pt":1719503245018,"mc":[{"id":"1.230180128","rc":[{"atl":[[1000,0.05]],"id":58821523}],"con":true,"img":false}]}
{"op":"mcm","clk":"11541196315","pt":1719503245222,"mc":[{"id":"1.230180128","rc":[{"atl":[[1000,0]],"id":58821523}],"con":true,"img":false}]}
{"op":"mcm","clk":"11541196324","pt":1719503245333,"mc":[{"id":"1.230180128","rc":[{"atl":[[19.5,0.89]],"id":58821523}],"con":true,"img":false}]}
{"op":"mcm","clk":"11541197781","pt":1719503260547,"mc":[{"id":"1.230180128","rc":[{"atl":[[19.5,0.84]],"id":58821523}],"con":true,"img":false}]}
{"op":"mcm","clk":"11541197884","pt":1719503261533,"mc":[{"id":"1.230180128","rc":[{"atl":[[1000,0.05]],"id":58821523}],"con":true,"img":false}]}
{"op":"mcm","clk":"11541197911","pt":1719503261738,"mc":[{"id":"1.230180128","rc":[{"atl":[[1000,0]],"id":58821523}],"con":true,"img":false}]}
{"op":"mcm","clk":"11541197931","pt":1719503261848,"mc":[{"id":"1.230180128","rc":[{"atl":[[19.5,0.89]],"id":58821523}],"con":true,"img":false}]}
{"op":"mcm","clk":"11541199349","pt":1719503277057,"mc":[{"id":"1.230180128","rc":[{"atl":[[19.5,0.84]],"id":58821523}],"con":true,"img":false}]}
{"op":"mcm","clk":"11541199364","pt":1719503277264,"mc":[{"id":"1.230180128","rc":[{"atl":[[1000,0.05]],"id":58821523}],"con":true,"img":false}]}
{"op":"mcm","clk":"11541199379","pt":1719503277477,"mc":[{"id":"1.230180128","rc":[{"atl":[[1000,0]],"id":58821523}],"con":true,"img":false}]}
{"op":"mcm","clk":"11541199392","pt":1719503277577,"mc":[{"id":"1.230180128","rc":[{"atl":[[19.5,0.89]],"id":58821523}],"con":true,"img":false}]}
{"op":"mcm","clk":"11541199639","pt":1719503280271,"mc":[{"id":"1.230180128","rc":[{"atl":[[30,2.03]],"id":51218587}],"con":true,"img":false}]}
{"op":"mcm","clk":"11541199646","pt":1719503280389,"mc":[{"id":"1.230180128","rc":[{"atb":[[1.98,102.04]],"id":51218587},{"atl":[[12,8]],"id":51218587}],"con":true,"img":false}]}
{"op":"mcm","clk":"11541199655","pt":1719503280443,"mc":[{"id":"1.230180128","rc":[{"atb":[[3,27.66]],"id":58821523},{"atl":[[20,6.78]],"id":58821523},{"atb":[[4.7,27.03]],"id":60237218},{"atl":[[140,2]],"id":60237218},{"atb":[[3.35,42.55]],"id":69213654},{"atl":[[30,3.45]],"id":69213654},{"atb":[[4.9,25.64]],"id":66050026},{"atl":[[140,2]],"id":66050026}],"con":true,"img":false}]}
{"op":"mcm","clk":"11541199663","pt":1719503280549,"mc":[{"id":"1.230180128","rc":[{"atb":[[3.45,40.82]],"id":50639934},{"atl":[[26,3.69]],"id":50639934}],"con":true,"img":false}]}
{"op":"mcm","clk":"11541199681","pt":1719503280756,"mc":[{"id":"1.230180128","rc":[{"atl":[[30,0.03]],"id":51218587}],"con":true,"img":false}]}
{"op":"mcm","clk":"11541199728","pt":1719503281334,"mc":[{"id":"1.230180128","rc":[{"atl":[[1000,1.7]],"id":58821523},{"atl":[[1000,1.88]],"id":50639934},{"atb":[[1.03,12.7]],"id":66050026},{"atl":[[1000,1.88]],"id":66050026}],"con":true,"img":false}]}
{"op":"mcm","clk":"11541199741","pt":1719503281492,"mc":[{"id":"1.230180128","rc":[{"atb":[[1.02,3.7]],"id":58821523},{"atb":[[1.02,20.19]],"id":50639934},{"atl":[[30,0]],"id":51218587}],"con":true,"img":false}]}
{"op":"mcm","clk":"11541199749","pt":1719503281547,"mc":[{"id":"1.230180128","rc":[{"atb":[[1.1,1.69]],"id":58821523},{"atl":[[1000,0.01]],"id":58821523},{"atl":[[1000,0.19]],"id":50639934},{"atl":[[11.5,0.03]],"id":51218587},{"atb":[[1.03,11.07]],"id":66050026},{"atl":[[1000,0.17]],"id":66050026}],"con":true,"img":false}]}
{"op":"mcm","clk":"11541199759","pt":1719503281652,"mc":[{"id":"1.230180128","rc":[{"atb":[[1.02,2.15]],"id":58821523},{"atb":[[1.02,18.61]],"id":50639934},{"atb":[[1.12,1.69]],"id":66050026}],"con":true,"img":false}]}
{"op":"mcm","clk":"11541199768","pt":1719503281753,"mc":[{"id":"1.230180128","rc":[{"atl":[[1000,0]],"id":58821523},{"atl":[[1000,0.17]],"id":50639934},{"atb":[[1.03,10.99]],"id":66050026}],"con":true,"img":false}]}
{"op":"mcm","clk":"11541199778","pt":1719503281858,"mc":[{"id":"1.230180128","rc":[{"atb":[[1.02,2],[3.15,1]],"id":58821523},{"atl":[[9,1],[19.5,0.91]],"id":58821523},{"atb":[[1.02,18.49]],"id":50639934},{"atl":[[25,0.86]],"id":50639934},{"atb":[[1.12,1.69]],"id":69213654},{"atb":[[5.1,0.07]],"id":66050026}],"con":true,"img":false}]}
{"op":"mcm","clk":"11541199786","pt":1719503281962,"mc":[{"id":"1.230180128","rc":[{"atb":[[3.05,0.15]],"id":58821523},{"atb":[[1.12,1.69],[3.6,0.12]],"id":50639934}],"con":true,"img":false}]}
{"op":"mcm","clk":"11541199803","pt":1719503282169,"mc":[{"id":"1.230180128","rc":[{"atb":[[1.12,1.69]],"id":60237218}],"con":true,"img":false}]}
{"op":"mcm","clk":"11541199812","pt":1719503282273,"mc":[{"id":"1.230180128","rc":[{"atb":[[1.06,1.69]],"id":51218587}],"con":true,"img":false}]}
{"op":"mcm","clk":"11541199837","pt":1719503282533,"mc":[{"id":"1.230180128","rc":[{"atb":[[1.12,0.05]],"id":66050026}],"con":true,"img":false}]}
{"op":"mcm","clk":"11541199847","pt":1719503282641,"mc":[{"id":"1.230180128","rc":[{"atb":[[1.12,0.05]],"id":50639934}],"con":true,"img":false}]}
{"op":"mcm","clk":"11541199864","pt":1719503282845,"mc":[{"id":"1.230180128","rc":[{"atb":[[1.1,0.06]],"id":58821523}],"con":true,"img":false}]}
{"op":"mcm","clk":"11541199876","pt":1719503282948,"mc":[{"id":"1.230180128","rc":[{"atb":[[1.06,0.12]],"id":51218587}],"con":true,"img":false}]}
{"op":"mcm","clk":"11541199897","pt":1719503283155,"mc":[{"id":"1.230180128","rc":[{"atb":[[1.12,0.05]],"id":69213654}],"con":true,"img":false}]}
{"op":"mcm","clk":"11541199923","pt":1719503283465,"mc":[{"id":"1.230180128","rc":[{"atb":[[1.12,0.05]],"id":60237218}],"con":true,"img":false}]}
{"op":"mcm","clk":"11541199963","pt":1719503283878,"mc":[{"id":"1.230180128","rc":[{"atb":[[1.12,0]],"id":66050026}],"con":true,"img":false}]}
{"op":"mcm","clk":"11541199971","pt":1719503283983,"mc":[{"id":"1.230180128","rc":[{"atb":[[5.1,0.13]],"id":66050026}],"con":true,"img":false}]}
{"op":"mcm","clk":"11541200002","pt":1719503284245,"mc":[{"id":"1.230180128","rc":[{"atb":[[1.12,0]],"id":50639934}],"con":true,"img":false}]}
{"op":"mcm","clk":"11541200011","pt":1719503284349,"mc":[{"id":"1.230180128","rc":[{"atb":[[5.1,0.05]],"id":50639934}],"con":true,"img":false}]}
{"op":"mcm","clk":"11541200063","pt":1719503284766,"mc":[{"id":"1.230180128","rc":[{"atb":[[1.1,0]],"id":58821523}],"con":true,"img":false}]}
{"op":"mcm","clk":"11541200072","pt":1719503284871,"mc":[{"id":"1.230180128","rc":[{"atb":[[4.4,0.06]],"id":58821523}],"con":true,"img":false}]}
{"op":"mcm","clk":"11541200108","pt":1719503285242,"mc":[{"id":"1.230180128","rc":[{"atb":[[1.06,0]],"id":51218587}],"con":true,"img":false}]}
{"op":"mcm","clk":"11541200119","pt":1719503285351,"mc":[{"id":"1.230180128","rc":[{"atb":[[2.44,0.12]],"id":51218587}],"con":true,"img":false}]}
{"op":"mcm","clk":"11541200149","pt":1719503285656,"mc":[{"id":"1.230180128","rc":[{"atb":[[1.12,0]],"id":69213654}],"con":true,"img":false}]}
{"op":"mcm","clk":"11541200157","pt":1719503285761,"mc":[{"id":"1.230180128","rc":[{"atb":[[5.1,0.05]],"id":69213654}],"con":true,"img":false}]}
{"op":"mcm","clk":"11541200202","pt":1719503286075,"mc":[{"id":"1.230180128","rc":[{"atb":[[1.12,0]],"id":60237218}],"con":true,"img":false}]}
{"op":"mcm","clk":"11541200214","pt":1719503286185,"mc":[{"id":"1.230180128","rc":[{"atb":[[5.1,0.05]],"id":60237218}],"con":true,"img":false}]}
{"op":"mcm","clk":"11541200845","pt":1719503291889,"mc":[{"id":"1.230180128","rc":[{"atl":[[9,0],[8.4,1]],"id":58821523}],"con":true,"img":false}]}
{"op":"mcm","clk":"11541200878","pt":1719503292295,"mc":[{"id":"1.230180128","rc":[{"atl":[[11.5,2.03]],"id":51218587}],"con":true,"img":false}]}
{"op":"mcm","clk":"11541200935","pt":1719503292872,"mc":[{"id":"1.230180128","rc":[{"atl":[[19.5,0.86]],"id":58821523}],"con":true,"img":false}]}
{"op":"mcm","clk":"11541200956","pt":1719503293084,"mc":[{"id":"1.230180128","rc":[{"atl":[[1000,0.14]],"id":58821523}],"con":true,"img":false}]}
{"op":"mcm","clk":"11541200967","pt":1719503293184,"mc":[{"id":"1.230180128","rc":[{"atl":[[1000,0]],"id":58821523}],"con":true,"img":false}]}
{"op":"mcm","clk":"11541200980","pt":1719503293289,"mc":[{"id":"1.230180128","rc":[{"atl":[[8.2,0.14]],"id":58821523}],"con":true,"img":false}]}
{"op":"mcm","clk":"11541201095","pt":1719503294386,"mc":[{"id":"1.230180128","rc":[{"atb":[[2.22,11.44]],"id":58821523},{"atb":[[2.26,8.97]],"id":50639934}],"con":true,"img":false}]}
{"op":"mcm","clk":"11541201405","pt":1719503297457,"mc":[{"id":"1.230180128","rc":[{"atl":[[11.5,0.03]],"id":51218587}],"con":true,"img":false}]}
{"op":"mcm","clk":"11541201547","pt":1719503299270,"mc":[{"id":"1.230180128","rc":[{"atl":[[11.5,2.03]],"id":51218587}],"con":true,"img":false}]}
{"op":"mcm","clk":"11541201998","pt":1719503304475,"mc":[{"id":"1.230180128","rc":[{"spn":4.3,"spf":1.0,"id":58821523},{"spn":15.05,"spf":"NaN","id":50639934},{"spn":72.55,"spf":"NaN","id":60237218},{"atl":[[11.5,0.03]],"id":51218587},{"spn":6.97,"spf":"NaN","id":51218587},{"spn":17.55,"spf":"NaN","id":69213654},{"spn":72.55,"spf":"NaN","id":66050026}],"con":true,"img":false}]}
{"op":"mcm","clk":"11541202177","pt":1719503306380,"mc":[{"id":"1.230180128","rc":[{"atl":[[11.5,2.03]],"id":51218587}],"con":true,"img":false}]}
{"op":"mcm","clk":"11541202214","pt":1719503306795,"mc":[{"id":"1.230180128","rc":[{"atb":[[2.42,2]],"id":51218587}],"con":true,"img":false}]}
{"op":"mcm","clk":"11541202312","pt":1719503307881,"mc":[{"id":"1.230180128","rc":[{"atl":[[11.5,1]],"id":50639934},{"atb":[[6,1]],"id":60237218},{"atl":[[25,1]],"id":60237218},{"atl":[[3.9,1]],"id":51218587},{"atl":[[11.5,1]],"id":69213654},{"atb":[[5.8,1]],"id":66050026},{"atl":[[23,1]],"id":66050026}],"con":true,"img":false}]}
{"op":"mcm","clk":"11541202320","pt":1719503307987,"mc":[{"id":"1.230180128","rc":[{"atb":[[5.1,7.05],[4.7,0]],"id":60237218},{"atb":[[2.06,94.34]],"id":51218587},{"atl":[[11,8],[12,0]],"id":51218587},{"atb":[[3.6,11.12],[3.35,0]],"id":69213654},{"atb":[[5.1,7.13],[4.9,0]],"id":66050026}],"con":true,"img":false}]}
{"op":"mcm","clk":"11541202331","pt":1719503308090,"mc":[{"id":"1.230180128","rc":[{"atb":[[1.98,0]],"id":51218587}],"con":true,"img":false}]}
{"op":"mcm","clk":"11541202362","pt":1719503308507,"mc":[{"id":"1.230180128","rc":[{"atl":[[11.5,0.03]],"id":51218587}],"con":true,"img":false}]}
{"op":"mcm","clk":"11541202376","pt":1719503308614,"mc":[{"id":"1.230180128","rc":[{"atl":[[8.2,0]],"id":58821523}],"con":true,"img":false}]}
{"op":"mcm","clk":"11541202398","pt":1719503308764,"mc":[{"id":"1.230180128","rc":[{"atl":[[1000,0.14]],"id":58821523}],"con":true,"img":false}]}
{"op":"mcm","clk":"11541202407","pt":1719503308869,"mc":[{"id":"1.230180128","rc":[{"atl":[[1000,0]],"id":58821523}],"con":true,"img":false}]}
{"op":"mcm","clk":"11541202420","pt":1719503308973,"mc":[{"id":"1.230180128","rc":[{"atl":[[8.2,0.14]],"id":58821523}],"con":true,"img":false}]}
{"op":"mcm","clk":"11541202840","pt":1719503313396,"mc":[{"id":"1.230180128","rc":[{"atl":[[3.85,2]],"id":51218587}],"con":true,"img":false}]}
{"op":"mcm","clk":"11541203273","pt":1719503317895,"mc":[{"id":"1.230180128","rc":[{"atl":[[11,0],[4.2,8]],"id":51218587}],"con":true,"img":false}]}
{"op":"mcm","clk":"11541203347","pt":1719503318620,"mc":[{"id":"1.230180128","rc":[{"atl":[[3.85,0]],"id":51218587}],"con":true,"img":false}]}
{"op":"mcm","clk":"11541203536","pt":1719503320485,"mc":[{"id":"1.230180128","rc":[{"atb":[[3.05,0]],"id":58821523},{"atl":[[19.5,0.84]],"id":58821523},{"atb":[[3.6,0]],"id":50639934},{"atl":[[25,0.84]],"id":50639934},{"atl":[[3.85,2]],"id":51218587},{"atb":[[5.1,7.05]],"id":66050026}],"con":true,"img":false}]}
{"op":"mcm","clk":"11541203874","pt":1719503324307,"mc":[{"id":"1.230180128","rc":[{"atl":[[8.2,0]],"id":58821523}],"con":true,"img":false}]}
{"op":"mcm","clk":"11541203933","pt":1719503325029,"mc":[{"id":"1.230180128","rc":[{"atl":[[1000,0.14]],"id":58821523}],"con":true,"img":false}]}
{"op":"mcm","clk":"11541203970","pt":1719503325392,"mc":[{"id":"1.230180128","rc":[{"atl":[[1000,0]],"id":58821523}],"con":true,"img":false}]}
{"op":"mcm","clk":"11541203979","pt":1719503325493,"mc":[{"id":"1.230180128","rc":[{"atl":[[8.2,0.14]],"id":58821523}],"con":true,"img":false}]}
{"op":"mcm","clk":"11541203997","pt":1719503325705,"mc":[{"id":"1.230180128","rc":[{"atl":[[3.85,0]],"id":51218587}],"con":true,"img":false}]}
{"op":"mcm","clk":"11541204011","pt":1719503325805,"mc":[{"id":"1.230180128","rc":[{"atl":[[11,9],[4.2,0]],"id":51218587}],"con":true,"img":false}]}
{"op":"mcm","clk":"11541204165","pt":1719503327818,"mc":[{"id":"1.230180128","rc":[{"atl":[[3.85,2]],"id":51218587}],"con":true,"img":false}]}
{"op":"mcm","clk":"11541204621","pt":1719503333024,"mc":[{"id":"1.230180128","rc":[{"atl":[[3.85,0]],"id":51218587}],"con":true,"img":false}]}
{"op":"mcm","clk":"11541204831","pt":1719503334910,"mc":[{"id":"1.230180128","rc":[{"atl":[[3.85,2]],"id":51218587}],"con":true,"img":false}]}
{"op":"mcm","clk":"11541204879","pt":1719503335526,"mc":[{"id":"1.230180128","rc":[{"atl":[[11,0],[4.2,8]],"id":51218587}],"con":true,"img":false}]}
{"op":"mcm","clk":"11541205303","pt":1719503340097,"mc":[{"id":"1.230180128","rc":[{"atl":[[3.85,0]],"id":51218587}],"con":true,"img":false}]}
{"op":"mcm","clk":"11541205315","pt":1719503340215,"mc":[{"id":"1.230180128","rc":[{"atl":[[11,9]],"id":51218587}],"con":true,"img":false}]}
{"op":"mcm","clk":"11541205328","pt":1719503340361,"mc":[{"id":"1.230180128","rc":[{"atl":[[4.2,0]],"id":51218587}],"con":true,"img":false}]}
{"op":"mcm","clk":"11541205400","pt":1719503340615,"mc":[{"id":"1.230180128","rc":[{"atl":[[8.2,0]],"id":58821523}],"con":true,"img":false}]}
{"op":"mcm","clk":"11541205426","pt":1719503340824,"mc":[{"id":"1.230180128","rc":[{"atl":[[1000,0.14]],"id":58821523}],"con":true,"img":false}]}
{"op":"mcm","clk":"11541205450","pt":1719503341131,"mc":[{"id":"1.230180128","rc":[{"atl":[[1000,0]],"id":58821523}],"con":true,"img":false}]}
{"op":"mcm","clk":"11541205461","pt":1719503341237,"mc":[{"id":"1.230180128","rc":[{"atl":[[8.2,0.14]],"id":58821523}],"con":true,"img":false}]}
{"op":"mcm","clk":"11541205550","pt":1719503342022,"mc":[{"id":"1.230180128","rc":[{"atl":[[3.85,2]],"id":51218587}],"con":true,"img":false}]}
{"op":"mcm","clk":"11541206069","pt":1719503347223,"mc":[{"id":"1.230180128","rc":[{"atl":[[3.85,0]],"id":51218587}],"con":true,"img":false}]}
{"op":"mcm","clk":"11541206300","pt":1719503349442,"mc":[{"id":"1.230180128","rc":[{"atl":[[3.85,2]],"id":51218587}],"con":true,"img":false}]}
{"op":"mcm","clk":"11541206338","pt":1719503349855,"mc":[{"id":"1.230180128","rc":[{"atl":[[11,0],[4.2,8]],"id":51218587}],"con":true,"img":false}]}
{"op":"mcm","clk":"11541206751","pt":1719503354712,"mc":[{"id":"1.230180128","rc":[{"atl":[[3.85,0]],"id":51218587}],"con":true,"img":false}]}
{"op":"mcm","clk":"11541206770","pt":1719503354918,"mc":[{"id":"1.230180128","rc":[{"atl":[[11,9],[4.2,0]],"id":51218587}],"con":true,"img":false}]}
{"op":"mcm","clk":"11541206904","pt":1719503356541,"mc":[{"id":"1.230180128","rc":[{"atl":[[8.2,0]],"id":58821523},{"atl":[[3.85,2]],"id":51218587}],"con":true,"img":false}]}
{"op":"mcm","clk":"11541206918","pt":1719503356746,"mc":[{"id":"1.230180128","rc":[{"atl":[[11,0],[4.2,8]],"id":51218587}],"con":true,"img":false}]}
{"op":"mcm","clk":"11541206924","pt":1719503356856,"mc":[{"id":"1.230180128","rc":[{"atl":[[1000,0.14]],"id":58821523}],"con":true,"img":false}]}
{"op":"mcm","clk":"11541206937","pt":1719503357054,"mc":[{"id":"1.230180128","rc":[{"atl":[[1000,0]],"id":58821523}],"con":true,"img":false}]}
{"op":"mcm","clk":"11541206941","pt":1719503357157,"mc":[{"id":"1.230180128","rc":[{"atl":[[8.2,0.14]],"id":58821523}],"con":true,"img":false}]}
{"op":"mcm","clk":"11541207331","pt":1719503361863,"mc":[{"id":"1.230180128","rc":[{"atl":[[3.85,0]],"id":51218587}],"con":true,"img":false}]}
{"op":"mcm","clk":"11541207347","pt":1719503362063,"mc":[{"id":"1.230180128","rc":[{"atl":[[11,9],[4.2,0]],"id":51218587}],"con":true,"img":false}]}
{"op":"mcm","clk":"11541207355","pt":1719503362167,"mc":[{"id":"1.230180128","rc":[{"atb":[[3,24.52]],"id":58821523}],"con":true,"img":false}]}
{"op":"mcm","clk":"11541207486","pt":1719503363544,"mc":[{"id":"1.230180128","rc":[{"atl":[[3.85,2]],"id":51218587}],"con":true,"img":false}]}
{"op":"mcm","clk":"11541208413","pt":1719503368784,"mc":[{"id":"1.230180128","rc":[{"spn":8.3,"spf":"NaN","id":50639934},{"spn":15.5,"spf":"NaN","id":60237218},{"atl":[[3.85,0]],"id":51218587},{"spn":3.17,"spf":"NaN","id":51218587},{"spn":8.3,"spf":"NaN","id":69213654},{"spn":14.4,"spf":"NaN","id":66050026}],"con":true,"img":false}]}
{"op":"mcm","clk":"11541208666","pt":1719503371187,"mc":[{"id":"1.230180128","rc":[{"atl":[[3.85,2]],"id":51218587}],"con":true,"img":false}]}
{"op":"mcm","clk":"11541208690","pt":1719503371385,"mc":[{"id":"1.230180128","rc":[{"atl":[[4.2,8]],"id":51218587}],"con":true,"img":false}]}
{"op":"mcm","clk":"11541208701","pt":1719503371446,"mc":[{"id":"1.230180128","rc":[{"atl":[[11,0]],"id":51218587}],"con":true,"img":false}]}
{"op":"mcm","clk":"11541208827","pt":1719503372385,"mc":[{"id":"1.230180128","rc":[{"atl":[[8.2,0]],"id":58821523}],"con":true,"img":false}]}
{"op":"mcm","clk":"11541208856","pt":1719503372551,"mc":[{"id":"1.230180128","rc":[{"atl":[[1000,0.14]],"id":58821523}],"con":true,"img":false}]}
{"op":"mcm","clk":"11541208885","pt":1719503372763,"mc":[{"id":"1.230180128","rc":[{"atl":[[1000,0]],"id":58821523}],"con":true,"img":false}]}
{"op":"mcm","clk":"11541208904","pt":1719503372870,"mc":[{"id":"1.230180128","rc":[{"atl":[[8.2,0.14]],"id":58821523}],"con":true,"img":false}]}
{"op":"mcm","clk":"11541208973","pt":1719503373485,"mc":[{"id":"1.230180128","rc":[{"atb":[[3.15,1.79]],"id":58821523},{"atb":[[3.55,6.79]],"id":50639934},{"atb":[[2.44,0.91]],"id":51218587},{"atb":[[3.6,11.91]],"id":69213654}],"con":true,"img":false}]}
{"op":"mcm","clk":"11541209209","pt":1719503375582,"mc":[{"id":"1.230180128","rc":[{"atb":[[2.5,0]],"id":60237218}],"con":true,"img":false}]}
{"op":"mcm","clk":"11541209344","pt":1719503376481,"mc":[{"id":"1.230180128","rc":[{"atl":[[3.85,0]],"id":51218587}],"con":true,"img":false}]}
{"op":"mcm","clk":"11541209360","pt":1719503376579,"mc":[{"id":"1.230180128","rc":[{"atl":[[11,9],[4.2,0]],"id":51218587}],"con":true,"img":false}]}
{"op":"mcm","clk":"11541209524","pt":1719503378187,"mc":[{"id":"1.230180128","rc":[{"atl":[[3.85,2]],"id":51218587}],"con":true,"img":false}]}
{"op":"mcm","clk":"11541209532","pt":1719503378289,"mc":[{"id":"1.230180128","rc":[{"atl":[[11,0],[4.2,8]],"id":51218587}],"con":true,"img":false}]}
{"op":"mcm","clk":"11541209547","pt":1719503378344,"mc":[{"id":"1.230180128","rc":[{"atb":[[7,0.71]],"id":66050026}],"con":true,"img":false}]}
{"op":"mcm","clk":"11541210081","pt":1719503383491,"mc":[{"id":"1.230180128","rc":[{"atl":[[3.85,0]],"id":51218587}],"con":true,"img":false}]}
{"op":"mcm","clk":"11541210088","pt":1719503383592,"mc":[{"id":"1.230180128","rc":[{"atl":[[4.2,0]],"id":51218587}],"con":true,"img":false}]}
{"op":"mcm","clk":"11541210101","pt":1719503383694,"mc":[{"id":"1.230180128","rc":[{"atl":[[11,9]],"id":51218587}],"con":true,"img":false}]}
{"op":"mcm","clk":"11541210244","pt":1719503385257,"mc":[{"id":"1.230180128","rc":[{"atl":[[3.85,2]],"id":51218587}],"con":true,"img":false}]}
{"op":"mcm","clk":"11541210284","pt":1719503385778,"mc":[{"id":"1.230180128","rc":[{"atl":[[3.8,0.84]],"id":51218587},{"atb":[[5.9,0.84]],"id":66050026}],"con":true,"img":false}]}
{"op":"mcm","clk":"11541210291","pt":1719503385881,"mc":[{"id":"1.230180128","rc":[{"atb":[[5.4,7.06]],"id":66050026}],"con":true,"img":false}]}
{"op":"mcm","clk":"11541210300","pt":1719503385984,"mc":[{"id":"1.230180128","rc":[{"atb":[[5.1,0.05]],"id":66050026}],"con":true,"img":false}]}
{"op":"mcm","clk":"11541210400","pt":1719503386971,"mc":[{"id":"1.230180128","rc":[{"atb":[[7,0]],"id":66050026}],"con":true,"img":false}]}
{"op":"mcm","clk":"11541210439","pt":1719503387397,"mc":[{"id":"1.230180128","rc":[{"atb":[[6,4.14]],"id":60237218}],"con":true,"img":false}]}
{"op":"mcm","clk":"11541210487","pt":1719503387805,"mc":[{"id":"1.230180128","rc":[{"atb":[[6.2,0.84]],"id":60237218}],"con":true,"img":false}]}
{"op":"mcm","clk":"11541210525","pt":1719503388066,"mc":[{"id":"1.230180128","rc":[{"atl":[[8.2,0]],"id":58821523}],"con":true,"img":false}]}
{"op":"mcm","clk":"11541210545","pt":1719503388275,"mc":[{"id":"1.230180128","rc":[{"atl":[[1000,0.14]],"id":58821523}],"con":true,"img":false}]}
{"op":"mcm","clk":"11541210564","pt":1719503388481,"mc":[{"id":"1.230180128","rc":[{"atl":[[1000,0]],"id":58821523}],"con":true,"img":false}]}
{"op":"mcm","clk":"11541210572","pt":1719503388585,"mc":[{"id":"1.230180128","rc":[{"atl":[[8.2,0.14]],"id":58821523}],"con":true,"img":false}]}
{"op":"mcm","clk":"11541210752","pt":1719503390498,"mc":[{"id":"1.230180128","rc":[{"atl":[[3.85,0]],"id":51218587}],"con":true,"img":false}]}
{"op":"mcm","clk":"11541210779","pt":1719503390764,"mc":[{"id":"1.230180128","rc":[{"atl":[[3.8,0]],"id":51218587}],"con":true,"img":false}]}
{"op":"mcm","clk":"11541210952","pt":1719503392680,"mc":[{"id":"1.230180128","rc":[{"atl":[[3.85,2]],"id":51218587}],"con":true,"img":false}]}
{"op":"mcm","clk":"11541210976","pt":1719503392886,"mc":[{"id":"1.230180128","rc":[{"atl":[[11,0],[4.2,8]],"id":51218587}],"con":true,"img":false}]}
{"op":"mcm","clk":"11541211028","pt":1719503393402,"mc":[{"id":"1.230180128","rc":[{"atl":[[3.8,0.84]],"id":51218587}],"con":true,"img":false}]}
{"op":"mcm","clk":"11541211468","pt":1719503397887,"mc":[{"id":"1.230180128","rc":[{"atl":[[3.85,0]],"id":51218587}],"con":true,"img":false}]}
{"op":"mcm","clk":"11541211510","pt":1719503398300,"mc":[{"id":"1.230180128","rc":[{"atl":[[3.8,0]],"id":51218587}],"con":true,"img":false}]}
{"op":"mcm","clk":"11541211525","pt":1719503398504,"mc":[{"id":"1.230180128","rc":[{"atl":[[11,9],[4.2,0]],"id":51218587}],"con":true,"img":false}]}
{"op":"mcm","clk":"11541211643","pt":1719503399698,"mc":[{"id":"1.230180128","rc":[{"atl":[[3.85,2]],"id":51218587}],"con":true,"img":false}]}
{"op":"mcm","clk":"11541211745","pt":1719503400699,"mc":[{"id":"1.230180128","rc":[{"atl":[[3.8,0.84]],"id":51218587}],"con":true,"img":false}]}
{"op":"mcm","clk":"11541211788","pt":1719503401009,"mc":[{"id":"1.230180128","rc":[{"atl":[[19.5,0]],"id":58821523},{"atl":[[25,0]],"id":50639934}],"con":true,"img":false}]}
{"op":"mcm","clk":"11541211820","pt":1719503401321,"mc":[{"id":"1.230180128","rc":[{"atl":[[1000,1.88]],"id":50639934},{"atb":[[1.04,95.69]],"id":66050026},{"atl":[[1000,1.88]],"id":66050026}],"con":true,"img":false}]}
{"op":"mcm","clk":"11541211831","pt":1719503401424,"mc":[{"id":"1.230180128","rc":[{"atb":[[1.02,3.7]],"id":58821523},{"atl":[[1000,1.7]],"id":58821523},{"atb":[[1.02,20.19]],"id":50639934}],"con":true,"img":false}]}
{"op":"mcm","clk":"11541211842","pt":1719503401529,"mc":[{"id":"1.230180128","rc":[{"atl":[[1000,0.19]],"id":50639934},{"atb":[[1.04,94.05]],"id":66050026},{"atl":[[1000,0.17]],"id":66050026}],"con":true,"img":false}]}
{"op":"mcm","clk":"11541211852","pt":1719503401584,"mc":[{"id":"1.230180128","rc":[{"atb":[[1.02,2.13]],"id":58821523},{"atl":[[1000,0.01]],"id":58821523},{"atb":[[1.02,18.61]],"id":50639934}],"con":true,"img":false}]}
{"op":"mcm","clk":"11541211863","pt":1719503401690,"mc":[{"id":"1.230180128","rc":[{"atl":[[1000,0.17]],"id":50639934},{"atb":[[1.04,93.98]],"id":66050026}],"con":true,"img":false}]}
{"op":"mcm","clk":"11541211874","pt":1719503401794,"mc":[{"id":"1.230180128","rc":[{"atb":[[1.02,2],[4.4,0]],"id":58821523},{"atl":[[1000,0]],"id":58821523},{"atb":[[1.02,18.49]],"id":50639934},{"atl":[[25,0.01]],"id":50639934},{"atb":[[5.9,0.9]],"id":66050026}],"con":true,"img":false}]}
{"op":"mcm","clk":"11541211881","pt":1719503401902,"mc":[{"id":"1.230180128","rc":[{"atb":[[3.2,0.13]],"id":58821523},{"atl":[[19.5,0.01]],"id":58821523},{"atb":[[3.6,0.11]],"id":50639934}],"con":true,"img":false}]}
{"op":"mcm","clk":"11541211890","pt":1719503402005,"mc":[{"id":"1.230180128","rc":[{"atb":[[5.1,0]],"id":66050026}],"con":true,"img":false}]}
{"op":"mcm","clk":"11541211900","pt":1719503402110,"mc":[{"id":"1.230180128","rc":[{"atb":[[1.1,1.69]],"id":58821523}],"con":true,"img":false}]}
{"op":"mcm","clk":"11541211907","pt":1719503402216,"mc":[{"id":"1.230180128","rc":[{"atb":[[7,0.71]],"id":60237218}],"con":true,"img":false}]}
{"op":"mcm","clk":"11541211915","pt":1719503402321,"mc":[{"id":"1.230180128","rc":[{"atb":[[5.1,0]],"id":50639934},{"atb":[[5.1,0]],"id":69213654}],"con":true,"img":false}]}
{"op":"mcm","clk":"11541211949","pt":1719503402584,"mc":[{"id":"1.230180128","rc":[{"atb":[[1.1,0.06]],"id":58821523},{"atb":[[1.14,1.69]],"id":66050026}],"con":true,"img":false}]}
{"op":"mcm","clk":"11541211985","pt":1719503402903,"mc":[{"id":"1.230180128","rc":[{"atb":[[2.44,0.79]],"id":51218587}],"con":true,"img":false}]}
{"op":"mcm","clk":"11541212009","pt":1719503403113,"mc":[{"id":"1.230180128","rc":[{"atb":[[5.1,7]],"id":60237218}],"con":true,"img":false}]}
{"op":"mcm","clk":"11541212021","pt":1719503403212,"mc":[{"id":"1.230180128","rc":[{"atb":[[1.1,0]],"id":58821523},{"atb":[[2.44,1.63]],"id":51218587}],"con":true,"img":false}]}
{"op":"mcm","clk":"11541212032","pt":1719503403317,"mc":[{"id":"1.230180128","rc":[{"atb":[[4.4,0.06]],"id":58821523}],"con":true,"img":false}]}
{"op":"mcm","clk":"11541212050","pt":1719503403526,"mc":[{"id":"1.230180128","rc":[{"atb":[[1.12,1.69]],"id":50639934}],"con":true,"img":false}]}
{"op":"mcm","clk":"11541212059","pt":1719503403629,"mc":[{"id":"1.230180128","rc":[{"atb":[[1.14,0.05]],"id":66050026}],"con":true,"img":false}]}
{"op":"mcm","clk":"11541212073","pt":1719503403787,"mc":[{"id":"1.230180128","rc":[{"atl":[[8.2,0]],"id":58821523},{"atb":[[1.06,1.69]],"id":51218587}],"con":true,"img":false}]}
{"op":"mcm","clk":"11541212080","pt":1719503403890,"mc":[{"id":"1.230180128","rc":[{"atb":[[1.14,1.69]],"id":60237218}],"con":true,"img":false}]}
{"op":"mcm","clk":"11541212095","pt":1719503403992,"mc":[{"id":"1.230180128","rc":[{"atl":[[1000,0.14]],"id":58821523}],"con":true,"img":false}]}
{"op":"mcm","clk":"11541212107","pt":1719503404101,"mc":[{"id":"1.230180128","rc":[{"atb":[[1.12,1.69]],"id":69213654}],"con":true,"img":false}]}
{"op":"mcm","clk":"11541212118","pt":1719503404202,"mc":[{"id":"1.230180128","rc":[{"atl":[[1000,0]],"id":58821523},{"atb":[[1.14,0]],"id":66050026}],"con":true,"img":false}]}
{"op":"mcm","clk":"11541212131","pt":1719503404303,"mc":[{"id":"1.230180128","rc":[{"atl":[[8.2,0.14]],"id":58821523},{"atb":[[2.42,0]],"id":51218587},{"atb":[[5.9,0.95]],"id":66050026}],"con":true,"img":false}]}
{"op":"mcm","clk":"11541212141","pt":1719503404407,"mc":[{"id":"1.230180128","rc":[{"atb":[[1.12,0.05]],"id":50639934},{"atb":[[2.46,2]],"id":51218587}],"con":true,"img":false}]}
{"op":"mcm","clk":"11541212180","pt":1719503404717,"mc":[{"id":"1.230180128","rc":[{"atb":[[1.14,0.05]],"id":60237218}],"con":true,"img":false}]}
{"op":"mcm","clk":"11541212189","pt":1719503404822,"mc":[{"id":"1.230180128","rc":[{"atb":[[1.06,0.12]],"id":51218587}],"con":true,"img":false}]}
{"op":"mcm","clk":"11541212203","pt":1719503404984,"mc":[{"id":"1.230180128","rc":[{"atb":[[1.12,0]],"id":50639934},{"atl":[[3.85,0]],"id":51218587}],"con":true,"img":false}]}
{"op":"mcm","clk":"11541212213","pt":1719503405094,"mc":[{"id":"1.230180128","rc":[{"atb":[[5.1,0.05]],"id":50639934},{"atb":[[1.12,0.05]],"id":69213654}],"con":true,"img":false}]}
{"op":"mcm","clk":"11541212227","pt":1719503405200,"mc":[{"id":"1.230180128","rc":[{"atl":[[3.8,0]],"id":51218587}],"con":true,"img":false}]}
{"op":"mcm","clk":"11541212248","pt":1719503405397,"mc":[{"id":"1.230180128","rc":[{"atb":[[1.14,0]],"id":60237218}],"con":true,"img":false}]}
{"op":"mcm","clk":"11541212257","pt":1719503405502,"mc":[{"id":"1.230180128","rc":[{"atb":[[6.4,0.05]],"id":60237218}],"con":true,"img":false}]}
{"op":"mcm","clk":"11541212288","pt":1719503405809,"mc":[{"id":"1.230180128","rc":[{"atb":[[1.06,0]],"id":51218587}],"con":true,"img":false}]}
{"op":"mcm","clk":"11541212299","pt":1719503405912,"mc":[{"id":"1.230180128","rc":[{"atb":[[2.44,1.76]],"id":51218587}],"con":true,"img":false}]}
{"op":"mcm","clk":"11541212319","pt":1719503406121,"mc":[{"id":"1.230180128","rc":[{"atb":[[1.12,0]],"id":69213654}],"con":true,"img":false}]}
{"op":"mcm","clk":"11541212334","pt":1719503406223,"mc":[{"id":"1.230180128","rc":[{"atb":[[5.1,0.05]],"id":69213654}],"con":true,"img":false}]}
{"op":"mcm","clk":"11541212386","pt":1719503406692,"mc":[{"id":"1.230180128","rc":[{"atl":[[3.85,2]],"id":51218587}],"con":true,"img":false}]}
{"op":"mcm","clk":"11541212464","pt":1719503407417,"mc":[{"id":"1.230180128","rc":[{"atl":[[11,0],[4.2,8]],"id":51218587}],"con":true,"img":false}]}
{"op":"mcm","clk":"11541212498","pt":1719503407727,"mc":[{"id":"1.230180128","rc":[{"atl":[[3.8,0.84]],"id":51218587}],"con":true,"img":false}]}
{"op":"mcm","clk":"11541212590","pt":1719503408613,"mc":[{"id":"1.230180128","rc":[{"atb":[[7,0]],"id":60237218}],"con":true,"img":false}]}
{"op":"mcm","clk":"11541212773","pt":1719503410434,"mc":[{"id":"1.230180128","rc":[{"atb":[[2.48,0.84]],"id":51218587}],"con":true,"img":false}]}
{"op":"mcm","clk":"11541212928","pt":1719503411895,"mc":[{"id":"1.230180128","rc":[{"atl":[[3.85,0]],"id":51218587}],"con":true,"img":false}]}
{"op":"mcm","clk":"11541212964","pt":1719503412313,"mc":[{"id":"1.230180128","rc":[{"atl":[[3.8,0]],"id":51218587}],"con":true,"img":false}]}
{"op":"mcm","clk":"11541212979","pt":1719503412510,"mc":[{"id":"1.230180128","rc":[{"atl":[[11,9],[4.2,0]],"id":51218587}],"con":true,"img":false}]}
{"op":"mcm","clk":"11541213117","pt":1719503414217,"mc":[{"id":"1.230180128","rc":[{"atl":[[3.85,2]],"id":51218587}],"con":true,"img":false}]}
{"op":"mcm","clk":"11541213179","pt":1719503414833,"mc":[{"id":"1.230180128","rc":[{"atl":[[3.8,0.84]],"id":51218587}],"con":true,"img":false}]}
{"op":"mcm","clk":"11541213301","pt":1719503416234,"mc":[{"id":"1.230180128","rc":[{"atl":[[11,0],[4.2,8]],"id":51218587}],"con":true,"img":false}]}
{"op":"mcm","clk":"11541213349","pt":1719503416802,"mc":[{"id":"1.230180128","rc":[{"atb":[[8,0.71]],"id":66050026}],"con":true,"img":false}]}
{"op":"mcm","clk":"11541213479","pt":1719503418301,"mc":[{"id":"1.230180128","rc":[{"atb":[[3.15,1]],"id":58821523},{"atb":[[3.55,6]],"id":50639934},{"atb":[[2.44,0.97]],"id":51218587}],"con":true,"img":false}]}
{"op":"mcm","clk":"11541213510","pt":1719503418710,"mc":[{"id":"1.230180128","rc":[{"atb":[[2.46,0]],"id":51218587}],"con":true,"img":false}]}
{"op":"mcm","clk":"11541213518","pt":1719503418816,"mc":[{"id":"1.230180128","rc":[{"atb":[[2.42,2]],"id":51218587}],"con":true,"img":false}]}
{"op":"mcm","clk":"11541213571","pt":1719503419439,"mc":[{"id":"1.230180128","rc":[{"atb":[[2.48,0]],"id":51218587},{"atl":[[3.85,0]],"id":51218587}],"con":true,"img":false}]}
{"op":"mcm","clk":"11541213587","pt":1719503419639,"mc":[{"id":"1.230180128","rc":[{"atl":[[8.2,0]],"id":58821523}],"con":true,"img":false}]}
{"op":"mcm","clk":"11541213593","pt":1719503419743,"mc":[{"id":"1.230180128","rc":[{"atb":[[2.42,0]],"id":51218587}],"con":true,"img":false}]}
{"op":"mcm","clk":"11541213603","pt":1719503419897,"mc":[{"id":"1.230180128","rc":[{"atb":[[2.46,2]],"id":51218587},{"atl":[[3.8,0]],"id":51218587}],"con":true,"img":false}]}
{"op":"mcm","clk":"11541213612","pt":1719503419954,"mc":[{"id":"1.230180128","rc":[{"atl":[[1000,0.14]],"id":58821523}],"con":true,"img":false}]}
{"op":"mcm","clk":"11541213618","pt":1719503420056,"mc":[{"id":"1.230180128","rc":[{"atl":[[11,9],[4.2,0]],"id":51218587}],"con":true,"img":false}]}
{"op":"mcm","clk":"11541213626","pt":1719503420107,"mc":[{"id":"1.230180128","rc":[{"atl":[[1000,0]],"id":58821523}],"con":true,"img":false}]}
{"op":"mcm","clk":"11541213634","pt":1719503420210,"mc":[{"id":"1.230180128","rc":[{"atl":[[8.2,0.14]],"id":58821523},{"atb":[[2.48,0.84]],"id":51218587}],"con":true,"img":false}]}
{"op":"mcm","clk":"11541213687","pt":1719503420929,"mc":[{"id":"1.230180128","rc":[{"atb":[[2.46,0]],"id":51218587}],"con":true,"img":false}]}
{"op":"mcm","clk":"11541213695","pt":1719503421034,"mc":[{"id":"1.230180128","rc":[{"atb":[[2.42,2]],"id":51218587}],"con":true,"img":false}]}
{"op":"mcm","clk":"11541213715","pt":1719503421247,"mc":[{"id":"1.230180128","rc":[{"atb":[[2.48,0]],"id":51218587}],"con":true,"img":false}]}
{"op":"mcm","clk":"11541213727","pt":1719503421297,"mc":[{"id":"1.230180128","rc":[{"atl":[[3.85,2]],"id":51218587}],"con":true,"img":false}]}
{"op":"mcm","clk":"11541213772","pt":1719503421820,"mc":[{"id":"1.230180128","rc":[{"atl":[[3.8,0.84]],"id":51218587}],"con":true,"img":false}]}
{"op":"mcm","clk":"11541213951","pt":1719503423936,"mc":[{"id":"1.230180128","rc":[{"atb":[[8,0]],"id":66050026}],"con":true,"img":false}]}
{"op":"mcm","clk":"11541214199","pt":1719503426516,"mc":[{"id":"1.230180128","rc":[{"atl":[[3.85,0]],"id":51218587}],"con":true,"img":false}]}
{"op":"mcm","clk":"11541214234","pt":1719503426834,"mc":[{"id":"1.230180128","rc":[{"atl":[[3.8,0]],"id":51218587}],"con":true,"img":false}]}
{"op":"mcm","clk":"11541214331","pt":1719503428025,"mc":[{"id":"1.230180128","rc":[{"atb":[[5.4,7]],"id":60237218}],"con":true,"img":false}]}
{"op":"mcm","clk":"11541214341","pt":1719503428124,"mc":[{"id":"1.230180128","rc":[{"atb":[[5.1,0]],"id":60237218}],"con":true,"img":false}]}
{"op":"mcm","clk":"11541214358","pt":1719503428329,"mc":[{"id":"1.230180128","rc":[{"atl":[[3.85,2]],"id":51218587}],"con":true,"img":false}]}
{"op":"mcm","clk":"11541214404","pt":1719503428845,"mc":[{"id":"1.230180128","rc":[{"spn":15.7,"spf":"NaN","id":60237218},{"atl":[[11,0],[4.4,8]],"id":51218587},{"spn":3.14,"spf":"NaN","id":51218587},{"spn":14.45,"spf":"NaN","id":66050026}],"con":true,"img":false}]}
{"op":"mcm","clk":"11541214434","pt":1719503429206,"mc":[{"id":"1.230180128","rc":[{"atl":[[3.8,0.84]],"id":51218587}],"con":true,"img":false}]}
{"op":"mcm","clk":"11541214834","pt":1719503433525,"mc":[{"id":"1.230180128","rc":[{"atl":[[3.85,0]],"id":51218587}],"con":true,"img":false}]}
{"op":"mcm","clk":"11541214903","pt":1719503434355,"mc":[{"id":"1.230180128","rc":[{"atl":[[3.8,0]],"id":51218587}],"con":true,"img":false}]}
{"op":"mcm","clk":"11541214913","pt":1719503434455,"mc":[{"id":"1.230180128","rc":[{"atl":[[11.5,9.03],[4.4,0]],"id":51218587}],"con":true,"img":false}]}
{"op":"mcm","clk":"11541215019","pt":1719503435449,"mc":[{"id":"1.230180128","rc":[{"atl":[[8.2,0]],"id":58821523}],"con":true,"img":false}]}
{"op":"mcm","clk":"11541215027","pt":1719503435555,"mc":[{"id":"1.230180128","rc":[{"atl":[[3.85,2]],"id":51218587}],"con":true,"img":false}]}
{"op":"mcm","clk":"11541215080","pt":1719503436250,"mc":[{"id":"1.230180128","rc":[{"atl":[[3.8,0.84]],"id":51218587}],"con":true,"img":false}]}
{"op":"mcm","clk":"11541215091","pt":1719503436434,"mc":[{"id":"1.230180128","rc":[{"atl":[[1000,0.14]],"id":58821523}],"con":true,"img":false}]}
{"op":"mcm","clk":"11541215109","pt":1719503436641,"mc":[{"id":"1.230180128","rc":[{"atl":[[1000,0]],"id":58821523}],"con":true,"img":false}]}
{"op":"mcm","clk":"11541215114","pt":1719503436746,"mc":[{"id":"1.230180128","rc":[{"atl":[[8.2,0.14]],"id":58821523}],"con":true,"img":false}]}
{"op":"mcm","clk":"11541215421","pt":1719503440752,"mc":[{"id":"1.230180128","rc":[{"atl":[[3.85,0]],"id":51218587}],"con":true,"img":false}]}
{"op":"mcm","clk":"11541215462","pt":1719503441368,"mc":[{"id":"1.230180128","rc":[{"atl":[[3.8,0]],"id":51218587}],"con":true,"img":false}]}
{"op":"mcm","clk":"11541215577","pt":1719503442617,"mc":[{"id":"1.230180128","rc":[{"atl":[[3.85,2]],"id":51218587}],"con":true,"img":false}]}
{"op":"mcm","clk":"11541215626","pt":1719503443042,"mc":[{"id":"1.230180128","rc":[{"atl":[[11.5,0.03],[4.4,9.03]],"id":51218587}],"con":true,"img":false}]}
{"op":"mcm","clk":"11541215661","pt":1719503443351,"mc":[{"id":"1.230180128","rc":[{"atl":[[3.8,0.84]],"id":51218587}],"con":true,"img":false}]}
{"op":"mcm","clk":"11541216042","pt":1719503447864,"mc":[{"id":"1.230180128","rc":[{"atl":[[3.85,0]],"id":51218587}],"con":true,"img":false}]}
{"op":"mcm","clk":"11541216079","pt":1719503448285,"mc":[{"id":"1.230180128","rc":[{"atb":[[3.2,0]],"id":58821523},{"atl":[[19.5,0]],"id":58821523},{"atb":[[3.6,0]],"id":50639934},{"atl":[[25,0]],"id":50639934},{"atl":[[3.8,0]],"id":51218587},{"atb":[[5.9,0.89]],"id":66050026}],"con":true,"img":false}]}
{"op":"mcm","clk":"11541216093","pt":1719503448433,"mc":[{"id":"1.230180128","rc":[{"atl":[[11.5,9.55],[4.4,0]],"id":51218587}],"con":true,"img":false}]}
{"op":"mcm","clk":"11541216212","pt":1719503449784,"mc":[{"id":"1.230180128","rc":[{"atl":[[3.85,2]],"id":51218587}],"con":true,"img":false}]}
{"op":"mcm","clk":"11541216232","pt":1719503449937,"mc":[{"id":"1.230180128","rc":[{"atl":[[11.5,0.03],[4.4,9.55]],"id":51218587}],"con":true,"img":false}]}
{"op":"mcm","clk":"11541216289","pt":1719503450770,"mc":[{"id":"1.230180128","rc":[{"atl":[[3.8,0.84]],"id":51218587}],"con":true,"img":false}]}
{"op":"mcm","clk":"11541216376","pt":1719503451963,"mc":[{"id":"1.230180128","rc":[{"atl":[[8.2,0]],"id":58821523}],"con":true,"img":false}]}
{"op":"mcm","clk":"11541216396","pt":1719503452176,"mc":[{"id":"1.230180128","rc":[{"atl":[[1000,0.14]],"id":58821523}],"con":true,"img":false}]}
{"op":"mcm","clk":"11541216414","pt":1719503452381,"mc":[{"id":"1.230180128","rc":[{"atl":[[1000,0]],"id":58821523}],"con":true,"img":false}]}
{"op":"mcm","clk":"11541216428","pt":1719503452482,"mc":[{"id":"1.230180128","rc":[{"atl":[[8.2,0.14]],"id":58821523}],"con":true,"img":false}]}
{"op":"mcm","clk":"11541216610","pt":1719503454963,"mc":[{"id":"1.230180128","rc":[{"atl":[[3.85,0]],"id":51218587}],"con":true,"img":false}]}
{"op":"mcm","clk":"11541216645","pt":1719503455381,"mc":[{"id":"1.230180128","rc":[{"atl":[[3.8,0]],"id":51218587}],"con":true,"img":false}]}
{"op":"mcm","clk":"11541216655","pt":1719503455483,"mc":[{"id":"1.230180128","rc":[{"atl":[[11.5,9.55],[4.4,0]],"id":51218587}],"con":true,"img":false}]}
{"op":"mcm","clk":"11541216781","pt":1719503457196,"mc":[{"id":"1.230180128","rc":[{"atl":[[3.85,2]],"id":51218587}],"con":true,"img":false}]}
{"op":"mcm","clk":"11541216868","pt":1719503458288,"mc":[{"id":"1.230180128","rc":[{"atl":[[3.8,0.84]],"id":51218587}],"con":true,"img":false}]}
{"op":"mcm","clk":"11541216880","pt":1719503458495,"mc":[{"id":"1.230180128","rc":[{"atl":[[11.5,0.03],[4.4,9.55]],"id":51218587}],"con":true,"img":false}]}
{"op":"mcm","clk":"11541217056","pt":1719503460557,"mc":[{"id":"1.230180128","rc":[{"atl":[[1000,0.79]],"id":51218587}],"con":true,"img":false}]}
{"op":"mcm","clk":"11541217190","pt":1719503462375,"mc":[{"id":"1.230180128","rc":[{"atl":[[3.85,0]],"id":51218587}],"con":true,"img":false}]}
{"op":"mcm","clk":"11541217235","pt":1719503462794,"mc":[{"id":"1.230180128","rc":[{"atl":[[3.8,0]],"id":51218587}],"con":true,"img":false}]}
{"op":"mcm","clk":"11541217248","pt":1719503462895,"mc":[{"id":"1.230180128","rc":[{"atl":[[11.5,9.55],[4.4,0]],"id":51218587}],"con":true,"img":false}]}
{"op":"mcm","clk":"11541217384","pt":1719503464204,"mc":[{"id":"1.230180128","rc":[{"atl":[[3.85,2]],"id":51218587}],"con":true,"img":false}]}
{"op":"mcm","clk":"11541217483","pt":1719503465294,"mc":[{"id":"1.230180128","rc":[{"atl":[[3.8,0.84]],"id":51218587}],"con":true,"img":false}]}
{"op":"mcm","clk":"11541217682","pt":1719503467686,"mc":[{"id":"1.230180128","rc":[{"atl":[[8.2,0]],"id":58821523}],"con":true,"img":false}]}
{"op":"mcm","clk":"11541217700","pt":1719503467897,"mc":[{"id":"1.230180128","rc":[{"atl":[[1000,0.14]],"id":58821523}],"con":true,"img":false}]}
{"op":"mcm","clk":"11541217710","pt":1719503468008,"mc":[{"id":"1.230180128","rc":[{"atl":[[1000,0]],"id":58821523}],"con":true,"img":false}]}
{"op":"mcm","clk":"11541217722","pt":1719503468106,"mc":[{"id":"1.230180128","rc":[{"atl":[[8.2,0.14]],"id":58821523}],"con":true,"img":false}]}
{"op":"mcm","clk":"11541217765","pt":1719503468473,"mc":[{"id":"1.230180128","rc":[{"atb":[[6,1]],"id":60237218}],"con":true,"img":false}]}
{"op":"mcm","clk":"11541217872","pt":1719503469412,"mc":[{"id":"1.230180128","rc":[{"atl":[[3.85,0]],"id":51218587}],"con":true,"img":false}]}
{"op":"mcm","clk":"11541217922","pt":1719503469872,"mc":[{"id":"1.230180128","rc":[{"atl":[[3.8,0]],"id":51218587}],"con":true,"img":false}]}
{"op":"mcm","clk":"11541218041","pt":1719503471396,"mc":[{"id":"1.230180128","rc":[{"atl":[[3.85,2]],"id":51218587}],"con":true,"img":false}]}
{"op":"mcm","clk":"11541218051","pt":1719503471507,"mc":[{"id":"1.230180128","rc":[{"atl":[[11.5,0.03],[4.4,9.55]],"id":51218587}],"con":true,"img":false}]}
{"op":"mcm","clk":"11541218121","pt":1719503472389,"mc":[{"id":"1.230180128","rc":[{"atl":[[3.8,0.84]],"id":51218587}],"con":true,"img":false}]}
{"op":"mcm","clk":"11541218422","pt":1719503475779,"mc":[{"id":"1.230180128","rc":[{"atb":[[5.8,0],[6,1]],"id":66050026}],"con":true,"img":false}]}
{"op":"mcm","clk":"11541218427","pt":1719503475881,"mc":[{"id":"1.230180128","rc":[{"atb":[[5.7,7.06],[5.4,0]],"id":66050026}],"con":true,"img":false}]}
{"op":"mcm","clk":"11541218442","pt":1719503475990,"mc":[{"id":"1.230180128","rc":[{"atb":[[5.7,0],[5.4,7.06]],"id":66050026}],"con":true,"img":false}]}
{"op":"mcm","clk":"11541218491","pt":1719503476638,"mc":[{"id":"1.230180128","rc":[{"atl":[[3.85,0]],"id":51218587}],"con":true,"img":false}]}
{"op":"mcm","clk":"11541218550","pt":1719503477393,"mc":[{"id":"1.230180128","rc":[{"atl":[[3.8,0]],"id":51218587}],"con":true,"img":false}]}
{"op":"mcm","clk":"11541218560","pt":1719503477501,"mc":[{"id":"1.230180128","rc":[{"atl":[[11.5,9.55],[4.4,0]],"id":51218587}],"con":true,"img":false}]}
{"op":"mcm","clk":"11541218660","pt":1719503478688,"mc":[{"id":"1.230180128","rc":[{"atl":[[3.85,2]],"id":51218587}],"con":true,"img":false}]}
{"op":"mcm","clk":"11541218739","pt":1719503479720,"mc":[{"id":"1.230180128","rc":[{"atl":[[3.8,0.84]],"id":51218587}],"con":true,"img":false}]}
{"op":"mcm","clk":"11541218765","pt":1719503479980,"mc":[{"id":"1.230180128","rc":[{"atl":[[8,1.05]],"id":58821523},{"atl":[[1000,1.02]],"id":66050026}],"con":true,"img":false}]}
{"op":"mcm","clk":"11541218774","pt":1719503480085,"mc":[{"id":"1.230180128","rc":[{"atl":[[20,1.52],[11.5,8]],"id":58821523}],"con":true,"img":false}]}
{"op":"mcm","clk":"11541218796","pt":1719503480297,"mc":[{"id":"1.230180128","rc":[{"atl":[[1000,0.84]],"id":60237218},{"atb":[[5.2,1.62]],"id":69213654}],"con":true,"img":false}]}
{"op":"mcm","clk":"11541218823","pt":1719503480602,"mc":[{"id":"1.230180128","rc":[{"atl":[[8,0]],"id":58821523},{"atb":[[5.2,1.62]],"id":50639934}],"con":true,"img":false}]}
{"op":"mcm","clk":"11541218829","pt":1719503480711,"mc":[{"id":"1.230180128","rc":[{"atb":[[3.9,8.98]],"id":50639934}],"con":true,"img":false}]}
{"op":"mcm","clk":"11541218838","pt":1719503480810,"mc":[{"id":"1.230180128","rc":[{"atb":[[3.45,0]],"id":50639934},{"atl":[[1000,0.55]],"id":66050026}],"con":true,"img":false}]}
{"op":"mcm","clk":"11541218846","pt":1719503480911,"mc":[{"id":"1.230180128","rc":[{"atl":[[8.2,1.19]],"id":58821523}],"con":true,"img":false}]}
{"op":"mcm","clk":"11541218853","pt":1719503481117,"mc":[{"id":"1.230180128","rc":[{"atl":[[1000,0.35]],"id":60237218}],"con":true,"img":false}]}
{"op":"mcm","clk":"11541218867","pt":1719503481331,"mc":[{"id":"1.230180128","rc":[{"atb":[[5.2,0]],"id":50639934}],"con":true,"img":false}]}
{"op":"mcm","clk":"11541218876","pt":1719503481381,"mc":[{"id":"1.230180128","rc":[{"atb":[[5.1,1.68]],"id":69213654}],"con":true,"img":false}]}
{"op":"mcm","clk":"11541218888","pt":1719503481587,"mc":[{"id":"1.230180128","rc":[{"atb":[[5.2,0]],"id":69213654}],"con":true,"img":false}]}
{"op":"mcm","clk":"11541218898","pt":1719503481690,"mc":[{"id":"1.230180128","rc":[{"atb":[[5.1,1.68]],"id":50639934}],"con":true,"img":false}]}
{"op":"mcm","clk":"11541218940","pt":1719503482106,"mc":[{"id":"1.230180128","rc":[{"atl":[[1000,0.17]],"id":66050026}],"con":true,"img":false}]}
{"op":"mcm","clk":"11541218949","pt":1719503482216,"mc":[{"id":"1.230180128","rc":[{"atl":[[22,0.38]],"id":66050026}],"con":true,"img":false}]}
{"op":"mcm","clk":"11541218971","pt":1719503482521,"mc":[{"id":"1.230180128","rc":[{"atl":[[1000,0]],"id":60237218}],"con":true,"img":false}]}
{"op":"mcm","clk":"11541218977","pt":1719503482627,"mc":[{"id":"1.230180128","rc":[{"atl":[[24,0.35]],"id":60237218}],"con":true,"img":false}]}
{"op":"mcm","clk":"11541219044","pt":1719503483307,"mc":[{"id":"1.230180128","rc":[{"atl":[[8.2,1.05]],"id":58821523}],"con":true,"img":false}]}
{"op":"mcm","clk":"11541219067","pt":1719503483507,"mc":[{"id":"1.230180128","rc":[{"atl":[[1000,0.14]],"id":58821523}],"con":true,"img":false}]}
{"op":"mcm","clk":"11541219077","pt":1719503483613,"mc":[{"id":"1.230180128","rc":[{"atl":[[1000,0]],"id":58821523}],"con":true,"img":false}]}
{"op":"mcm","clk":"11541219091","pt":1719503483717,"mc":[{"id":"1.230180128","rc":[{"atl":[[8,0.14]],"id":58821523}],"con":true,"img":false}]}
{"op":"mcm","clk":"11541219110","pt":1719503483926,"mc":[{"id":"1.230180128","rc":[{"atl":[[3.85,0]],"id":51218587}],"con":true,"img":false}]}
{"op":"mcm","clk":"11541219147","pt":1719503484293,"mc":[{"id":"1.230180128","rc":[{"atl":[[3.8,0]],"id":51218587}],"con":true,"img":false}]}
{"op":"mcm","clk":"11541219259","pt":1719503485712,"mc":[{"id":"1.230180128","rc":[{"atl":[[3.85,2]],"id":51218587}],"con":true,"img":false}]}
{"op":"mcm","clk":"11541219272","pt":1719503485811,"mc":[{"id":"1.230180128","rc":[{"atl":[[11.5,0.03],[4.4,9.55]],"id":51218587}],"con":true,"img":false}]}
{"op":"mcm","clk":"11541219356","pt":1719503486799,"mc":[{"id":"1.230180128","rc":[{"atl":[[3.8,0.84]],"id":51218587}],"con":true,"img":false}]}
{"op":"mcm","clk":"11541219682","pt":1719503491243,"mc":[{"id":"1.230180128","rc":[{"spn":15.2,"spf":"NaN","id":60237218},{"atl":[[3.85,0]],"id":51218587},{"spn":3.12,"spf":"NaN","id":51218587},{"spn":14.0,"spf":"NaN","id":66050026}],"con":true,"img":false}]}
{"op":"mcm","clk":"11541219746","pt":1719503491799,"mc":[{"id":"1.230180128","rc":[{"atl":[[3.8,0]],"id":51218587}],"con":true,"img":false}]}
{"op":"mcm","clk":"11541219760","pt":1719503492009,"mc":[{"id":"1.230180128","rc":[{"atl":[[11.5,9.55],[4.4,0]],"id":51218587}],"con":true,"img":false}]}
{"op":"mcm","clk":"11541219844","pt":1719503492828,"mc":[{"id":"1.230180128","rc":[{"atl":[[3.85,2]],"id":51218587}],"con":true,"img":false}]}
{"op":"mcm","clk":"11541219966","pt":1719503494216,"mc":[{"id":"1.230180128","rc":[{"atl":[[3.8,0.84]],"id":51218587}],"con":true,"img":false}]}
{"op":"mcm","clk":"11541220319","pt":1719503498018,"mc":[{"id":"1.230180128","rc":[{"atl":[[3.85,0]],"id":51218587}],"con":true,"img":false}]}
{"op":"mcm","clk":"11541220346","pt":1719503498329,"mc":[{"id":"1.230180128","rc":[{"atl":[[3.8,0]],"id":51218587}],"con":true,"img":false}]}
{"op":"mcm","clk":"11541220408","pt":1719503498945,"mc":[{"id":"1.230180128","rc":[{"atl":[[8,0]],"id":58821523}],"con":true,"img":false}]}
{"op":"mcm","clk":"11541220528","pt":1719503500237,"mc":[{"id":"1.230180128","rc":[{"atl":[[1000,0.14]],"id":58821523},{"atl":[[3.85,2]],"id":51218587}],"con":true,"img":false}]}
{"op":"mcm","clk":"11541220538","pt":1719503500338,"mc":[{"id":"1.230180128","rc":[{"atl":[[11.5,0.03],[4.4,9.55]],"id":51218587}],"con":true,"img":false}]}
{"op":"mcm","clk":"11541220544","pt":1719503500441,"mc":[{"id":"1.230180128","rc":[{"atl":[[1000,0]],"id":58821523}],"con":true,"img":false}]}
{"op":"mcm","clk":"11541220553","pt":1719503500550,"mc":[{"id":"1.230180128","rc":[{"atl":[[8,0.14]],"id":58821523}],"con":true,"img":false}]}
{"op":"mcm","clk":"11541220619","pt":1719503501324,"mc":[{"id":"1.230180128","rc":[{"atl":[[3.8,0.84]],"id":51218587}],"con":true,"img":false}]}
{"op":"mcm","clk":"11541221034","pt":1719503505441,"mc":[{"id":"1.230180128","rc":[{"atl":[[3.85,0]],"id":51218587}],"con":true,"img":false}]}
{"op":"mcm","clk":"11541221074","pt":1719503505807,"mc":[{"id":"1.230180128","rc":[{"atl":[[3.8,0]],"id":51218587}],"con":true,"img":false}]}
{"op":"mcm","clk":"11541221082","pt":1719503505910,"mc":[{"id":"1.230180128","rc":[{"atl":[[11.5,9.55],[4.4,0]],"id":51218587}],"con":true,"img":false}]}
{"op":"mcm","clk":"11541221219","pt":1719503507209,"mc":[{"id":"1.230180128","rc":[{"atl":[[3.85,2]],"id":51218587}],"con":true,"img":false}]}
{"op":"mcm","clk":"11541221321","pt":1719503508241,"mc":[{"id":"1.230180128","rc":[{"atl":[[11.5,0.03],[4.4,9.55]],"id":51218587}],"con":true,"img":false}]}
{"op":"mcm","clk":"11541221369","pt":1719503508748,"mc":[{"id":"1.230180128","rc":[{"atl":[[3.8,0.84]],"id":51218587}],"con":true,"img":false}]}
{"op":"mcm","clk":"11541221477","pt":1719503510139,"mc":[{"id":"1.230180128","rc":[{"atl":[[7.8,1.08]],"id":58821523}],"con":true,"img":false}]}
{"op":"mcm","clk":"11541221493","pt":1719503510346,"mc":[{"id":"1.230180128","rc":[{"atl":[[8.2,0]],"id":58821523}],"con":true,"img":false}]}
{"op":"mcm","clk":"11541221510","pt":1719503510552,"mc":[{"id":"1.230180128","rc":[{"atl":[[8.2,1.08]],"id":58821523}],"con":true,"img":false}]}
{"op":"mcm","clk":"11541221520","pt":1719503510604,"mc":[{"id":"1.230180128","rc":[{"atl":[[7.8,0]],"id":58821523}],"con":true,"img":false}]}
{"op":"mcm","clk":"11541221540","pt":1719503510812,"mc":[{"id":"1.230180128","rc":[{"atl":[[7.6,1.11]],"id":58821523}],"con":true,"img":false}]}
{"op":"mcm","clk":"11541221565","pt":1719503511122,"mc":[{"id":"1.230180128","rc":[{"atl":[[8.2,0]],"id":58821523}],"con":true,"img":false}]}
{"op":"mcm","clk":"11541221682","pt":1719503512413,"mc":[{"id":"1.230180128","rc":[{"atl":[[3.85,0]],"id":51218587}],"con":true,"img":false}]}
{"op":"mcm","clk":"11541221717","pt":1719503512827,"mc":[{"id":"1.230180128","rc":[{"atl":[[3.8,0]],"id":51218587}],"con":true,"img":false}]}
{"op":"mcm","clk":"11541221772","pt":1719503513348,"mc":[{"id":"1.230180128","rc":[{"atl":[[11.5,9.55],[4.4,0]],"id":51218587}],"con":true,"img":false}]}
{"op":"mcm","clk":"11541221893","pt":1719503514326,"mc":[{"id":"1.230180128","rc":[{"atl":[[3.85,2]],"id":51218587}],"con":true,"img":false}]}
{"op":"mcm","clk":"11541222040","pt":1719503515723,"mc":[{"id":"1.230180128","rc":[{"atl":[[8,0]],"id":58821523},{"atl":[[3.8,0.84]],"id":51218587}],"con":true,"img":false}]}
{"op":"mcm","clk":"11541222071","pt":1719503516033,"mc":[{"id":"1.230180128","rc":[{"atl":[[11.5,0.03],[4.4,9.55]],"id":51218587}],"con":true,"img":false}]}
{"op":"mcm","clk":"11541222397","pt":1719503519558,"mc":[{"id":"1.230180128","rc":[{"atl":[[3.85,0]],"id":51218587}],"con":true,"img":false}]}
{"op":"mcm","clk":"11541222456","pt":1719503520272,"mc":[{"id":"1.230180128","rc":[{"atl":[[3.8,0]],"id":51218587}],"con":true,"img":false}]}
{"op":"mcm","clk":"11541222493","pt":1719503520560,"mc":[{"id":"1.230180128","rc":[{"atl":[[11.5,9.55],[4.4,0]],"id":51218587}],"con":true,"img":false}]}
{"op":"mcm","clk":"11541222512","pt":1719503520739,"mc":[{"id":"1.230180128","rc":[{"atl":[[8.2,1.11],[7.6,0]],"id":58821523}],"con":true,"img":false}]}
{"op":"mcm","clk":"11541222569","pt":1719503521360,"mc":[{"id":"1.230180128","rc":[{"atl":[[1000,0.14]],"id":58821523}],"con":true,"img":false}]}
{"op":"mcm","clk":"11541222590","pt":1719503521574,"mc":[{"id":"1.230180128","rc":[{"atl":[[1000,0]],"id":58821523}],"con":true,"img":false}]}
{"op":"mcm","clk":"11541222605","pt":1719503521670,"mc":[{"id":"1.230180128","rc":[{"atl":[[8,0.14]],"id":58821523}],"con":true,"img":false}]}
{"op":"mcm","clk":"11541222627","pt":1719503521878,"mc":[{"id":"1.230180128","rc":[{"atl":[[3.85,2]],"id":51218587}],"con":true,"img":false}]}
{"op":"mcm","clk":"11541222650","pt":1719503522035,"mc":[{"id":"1.230180128","rc":[{"atl":[[11.5,0.03],[4.4,9.55]],"id":51218587}],"con":true,"img":false}]}
{"op":"mcm","clk":"11541222736","pt":1719503522862,"mc":[{"id":"1.230180128","rc":[{"atl":[[3.8,0.84]],"id":51218587}],"con":true,"img":false}]}
{"op":"mcm","clk":"11541222771","pt":1719503523170,"mc":[{"id":"1.230180128","rc":[{"atb":[[4.4,0]],"id":58821523}],"con":true,"img":false}]}
{"op":"mcm","clk":"11541222805","pt":1719503523717,"mc":[{"id":"1.230180128","rc":[{"atb":[[1.02,3.7],[1.1,1.69]],"id":58821523},{"atl":[[1000,1.7]],"id":58821523},{"atb":[[1.04,1.7]],"id":50639934},{"atl":[[1000,1.88]],"id":50639934},{"atb":[[1.04,95.69]],"id":66050026},{"atl":[[1000,1.88]],"id":66050026}],"con":true,"img":false}]}
{"op":"mcm","clk":"11541222831","pt":1719503523741,"mc":[{"id":"1.230180128","rc":[{"atb":[[1.02,2.13]],"id":58821523},{"atl":[[1000,0.04]],"id":58821523},{"atb":[[1.04,0.07]],"id":50639934},{"atl":[[1000,0.19]],"id":50639934},{"atb":[[1.04,94.04]],"id":66050026},{"atl":[[1000,0.17]],"id":66050026}],"con":true,"img":false}]}
{"op":"mcm","clk":"11541222839","pt":1719503523751,"mc":[{"id":"1.230180128","rc":[{"atb":[[1.1,0.06]],"id":58821523}],"con":true,"img":false}]}
{"op":"mcm","clk":"11541222851","pt":1719503523842,"mc":[{"id":"1.230180128","rc":[{"atb":[[1.02,2]],"id":58821523},{"atl":[[1000,0]],"id":58821523},{"atb":[[1.04,0]],"id":50639934},{"atl":[[1000,0.17]],"id":50639934},{"atb":[[1.04,93.98]],"id":66050026}],"con":true,"img":false}]}
{"op":"mcm","clk":"11541222862","pt":1719503523949,"mc":[{"id":"1.230180128","rc":[{"atb":[[3.2,0.13]],"id":58821523},{"atl":[[8.2,1.15]],"id":58821523},{"atb":[[5.1,1.75]],"id":50639934},{"atl":[[25,0.01]],"id":50639934},{"atb":[[6,1.05],[5.9,0.84]],"id":66050026}],"con":true,"img":false}]}
{"op":"mcm","clk":"11541222886","pt":1719503524163,"mc":[{"id":"1.230180128","rc":[{"atb":[[1.1,0]],"id":58821523}],"con":true,"img":false}]}
{"op":"mcm","clk":"11541222897","pt":1719503524260,"mc":[{"id":"1.230180128","rc":[{"atb":[[4.4,0.06]],"id":58821523},{"atb":[[5.1,1.69],[5.2,0.84]],"id":50639934}],"con":true,"img":false}]}
{"op":"mcm","clk":"11541222940","pt":1719503524569,"mc":[{"id":"1.230180128","rc":[{"atb":[[1.14,1.69]],"id":66050026}],"con":true,"img":false}]}
{"op":"mcm","clk":"11541222967","pt":1719503524880,"mc":[{"id":"1.230180128","rc":[{"atb":[[1.14,0.05]],"id":66050026}],"con":true,"img":false}]}
{"op":"mcm","clk":"11541222977","pt":1719503524982,"mc":[{"id":"1.230180128","rc":[{"atb":[[5.1,1.62]],"id":69213654}],"con":true,"img":false}]}
{"op":"mcm","clk":"11541223000","pt":1719503525145,"mc":[{"id":"1.230180128","rc":[{"atb":[[2.44,0.84]],"id":51218587}],"con":true,"img":false}]}
{"op":"mcm","clk":"11541223034","pt":1719503525448,"mc":[{"id":"1.230180128","rc":[{"atb":[[1.14,0]],"id":66050026}],"con":true,"img":false}]}
{"op":"mcm","clk":"11541223042","pt":1719503525558,"mc":[{"id":"1.230180128","rc":[{"atb":[[6.2,0.05]],"id":66050026}],"con":true,"img":false}]}
{"op":"mcm","clk":"11541223058","pt":1719503525759,"mc":[{"id":"1.230180128","rc":[{"atb":[[5.4,0],[5.7,7.06]],"id":66050026}],"con":true,"img":false}]}
{"op":"mcm","clk":"11541223074","pt":1719503525865,"mc":[{"id":"1.230180128","rc":[{"atb":[[1.12,1.69]],"id":50639934},{"atb":[[6.4,0]],"id":60237218}],"con":true,"img":false}]}
{"op":"mcm","clk":"11541223099","pt":1719503526070,"mc":[{"id":"1.230180128","rc":[{"atb":[[1.12,1.69]],"id":69213654}],"con":true,"img":false}]}
{"op":"mcm","clk":"11541223119","pt":1719503526283,"mc":[{"id":"1.230180128","rc":[{"atb":[[1.12,0.05]],"id":50639934},{"atb":[[1.14,1.69]],"id":60237218}],"con":true,"img":false}]}
{"op":"mcm","clk":"11541223150","pt":1719503526583,"mc":[{"id":"1.230180128","rc":[{"atb":[[1.06,1.69]],"id":51218587}],"con":true,"img":false}]}
{"op":"mcm","clk":"11541223179","pt":1719503526741,"mc":[{"id":"1.230180128","rc":[{"atb":[[1.12,0]],"id":50639934}],"con":true,"img":false}]}
{"op":"mcm","clk":"11541223190","pt":1719503526898,"mc":[{"id":"1.230180128","rc":[{"atb":[[5.2,0.9]],"id":50639934},{"atb":[[1.12,0.05]],"id":69213654}],"con":true,"img":false}]}
{"op":"mcm","clk":"11541223214","pt":1719503527050,"mc":[{"id":"1.230180128","rc":[{"atl":[[3.85,0]],"id":51218587}],"con":true,"img":false}]}
{"op":"mcm","clk":"11541223226","pt":1719503527154,"mc":[{"id":"1.230180128","rc":[{"atb":[[1.14,0.05]],"id":60237218},{"atb":[[1.06,0.12]],"id":51218587}],"con":true,"img":false}]}
{"op":"mcm","clk":"11541223256","pt":1719503527465,"mc":[{"id":"1.230180128","rc":[{"atb":[[1.12,0]],"id":69213654}],"con":true,"img":false}]}
{"op":"mcm","clk":"11541223269","pt":1719503527572,"mc":[{"id":"1.230180128","rc":[{"atb":[[5.2,0.05]],"id":69213654}],"con":true,"img":false}]}
{"op":"mcm","clk":"11541223296","pt":1719503527878,"mc":[{"id":"1.230180128","rc":[{"atl":[[3.8,0]],"id":51218587}],"con":true,"img":false}]}
{"op":"mcm","clk":"11541223314","pt":1719503528084,"mc":[{"id":"1.230180128","rc":[{"atb":[[1.06,0]],"id":51218587},{"atl":[[11.5,9.55],[4.4,0]],"id":51218587}],"con":true,"img":false}]}
{"op":"mcm","clk":"11541223323","pt":1719503528185,"mc":[{"id":"1.230180128","rc":[{"atb":[[2.44,0.97]],"id":51218587}],"con":true,"img":false}]}
{"op":"mcm","clk":"11541223365","pt":1719503528446,"mc":[{"id":"1.230180128","rc":[{"atb":[[1.14,0]],"id":60237218}],"con":true,"img":false}]}
{"op":"mcm","clk":"11541223376","pt":1719503528546,"mc":[{"id":"1.230180128","rc":[{"atb":[[6.2,0.89]],"id":60237218}],"con":true,"img":false}]}
{"op":"mcm","clk":"11541223439","pt":1719503529166,"mc":[{"id":"1.230180128","rc":[{"atl":[[3.85,2]],"id":51218587}],"con":true,"img":false}]}
{"op":"mcm","clk":"11541223451","pt":1719503529272,"mc":[{"id":"1.230180128","rc":[{"atl":[[4.4,9.55]],"id":51218587}],"con":true,"img":false}]}
{"op":"mcm","clk":"11541223463","pt":1719503529371,"mc":[{"id":"1.230180128","rc":[{"atl":[[11.5,0.03]],"id":51218587}],"con":true,"img":false}]}
{"op":"mcm","clk":"11541223559","pt":1719503530248,"mc":[{"id":"1.230180128","rc":[{"atl":[[3.8,0.84]],"id":51218587}],"con":true,"img":false}]}
{"op":"mcm","clk":"11541224012","pt":1719503534385,"mc":[{"id":"1.230180128","rc":[{"atl":[[3.85,0]],"id":51218587}],"con":true,"img":false}]}
{"op":"mcm","clk":"11541224084","pt":1719503535054,"mc":[{"id":"1.230180128","rc":[{"atl":[[3.8,0]],"id":51218587}],"con":true,"img":false}]}
{"op":"mcm","clk":"11541224093","pt":1719503535159,"mc":[{"id":"1.230180128","rc":[{"atl":[[11.5,9.55],[4.4,0]],"id":51218587}],"con":true,"img":false}]}
{"op":"mcm","clk":"11541224178","pt":1719503536086,"mc":[{"id":"1.230180128","rc":[{"atl":[[3.85,2]],"id":51218587}],"con":true,"img":false}]}
{"op":"mcm","clk":"11541224199","pt":1719503536291,"mc":[{"id":"1.230180128","rc":[{"atl":[[11.5,0.03],[4.4,9.55]],"id":51218587}],"con":true,"img":false}]}
{"op":"mcm","clk":"11541224265","pt":1719503536964,"mc":[{"id":"1.230180128","rc":[{"atl":[[8,0]],"id":58821523}],"con":true,"img":false}]}
{"op":"mcm","clk":"11541224283","pt":1719503537169,"mc":[{"id":"1.230180128","rc":[{"atl":[[1000,0.14]],"id":58821523}],"con":true,"img":false}]}
{"op":"mcm","clk":"11541224297","pt":1719503537276,"mc":[{"id":"1.230180128","rc":[{"atl":[[3.8,0.84]],"id":51218587}],"con":true,"img":false}]}
{"op":"mcm","clk":"11541224308","pt":1719503537374,"mc":[{"id":"1.230180128","rc":[{"atl":[[1000,0]],"id":58821523}],"con":true,"img":false}]}
{"op":"mcm","clk":"11541224316","pt":1719503537480,"mc":[{"id":"1.230180128","rc":[{"atl":[[8,0.14]],"id":58821523}],"con":true,"img":false}]}
{"op":"mcm","clk":"11541224591","pt":1719503540169,"mc":[{"id":"1.230180128","rc":[{"atb":[[5.1,0.07],[5.3,1.6]],"id":50639934}],"con":true,"img":false}]}
{"op":"mcm","clk":"11541224609","pt":1719503540477,"mc":[{"id":"1.230180128","rc":[{"atb":[[5.1,1.67]],"id":50639934},{"atb":[[5.3,1.6]],"id":69213654}],"con":true,"img":false}]}
{"op":"mcm","clk":"11541224633","pt":1719503540783,"mc":[{"id":"1.230180128","rc":[{"atb":[[5.3,0]],"id":50639934},{"atb":[[5.1,0]],"id":69213654}],"con":true,"img":false}]}
{"op":"mcm","clk":"11541224654","pt":1719503541092,"mc":[{"id":"1.230180128","rc":[{"atb":[[5.3,0],[5.2,1.65]],"id":69213654}],"con":true,"img":false}]}
{"op":"mcm","clk":"11541224674","pt":1719503541408,"mc":[{"id":"1.230180128","rc":[{"atl":[[3.85,0]],"id":51218587}],"con":true,"img":false}]}
{"op":"mcm","clk":"11541224712","pt":1719503541767,"mc":[{"id":"1.230180128","rc":[{"atl":[[3.8,0]],"id":51218587}],"con":true,"img":false}]}
{"op":"mcm","clk":"11541224726","pt":1719503541864,"mc":[{"id":"1.230180128","rc":[{"atl":[[4.4,0]],"id":51218587}],"con":true,"img":false}]}
{"op":"mcm","clk":"11541224737","pt":1719503541972,"mc":[{"id":"1.230180128","rc":[{"atl":[[11.5,9.55]],"id":51218587}],"con":true,"img":false}]}
{"op":"mcm","clk":"11541224879","pt":1719503543411,"mc":[{"id":"1.230180128","rc":[{"atl":[[3.85,2]],"id":51218587}],"con":true,"img":false}]}
{"op":"mcm","clk":"11541224904","pt":1719503543570,"mc":[{"id":"1.230180128","rc":[{"atl":[[11.5,0.03],[4.4,9.55]],"id":51218587}],"con":true,"img":false}]}
{"op":"mcm","clk":"11541224977","pt":1719503544287,"mc":[{"id":"1.230180128","rc":[{"atb":[[3.6,11.12]],"id":69213654}],"con":true,"img":false}]}
{"op":"mcm","clk":"11541224987","pt":1719503544394,"mc":[{"id":"1.230180128","rc":[{"atl":[[3.8,0.84]],"id":51218587}],"con":true,"img":false}]}
{"op":"mcm","clk":"11541225410","pt":1719503548612,"mc":[{"id":"1.230180128","rc":[{"atl":[[3.85,0]],"id":51218587}],"con":true,"img":false}]}
{"op":"mcm","clk":"11541225471","pt":1719503549283,"mc":[{"id":"1.230180128","rc":[{"atl":[[3.8,0]],"id":51218587}],"con":true,"img":false}]}
{"op":"mcm","clk":"11541225482","pt":1719503549383,"mc":[{"id":"1.230180128","rc":[{"atl":[[11.5,9.55],[4.4,0]],"id":51218587}],"con":true,"img":false}]}
{"op":"mcm","clk":"11541225582","pt":1719503550418,"mc":[{"id":"1.230180128","rc":[{"atl":[[3.85,2]],"id":51218587}],"con":true,"img":false}]}
{"op":"mcm","clk":"11541225609","pt":1719503550572,"mc":[{"id":"1.230180128","rc":[{"atl":[[11.5,0.03],[4.4,9.55]],"id":51218587}],"con":true,"img":false}]}
{"op":"mcm","clk":"11541225640","pt":1719503550882,"mc":[{"id":"1.230180128","rc":[{"atb":[[5.1,1.6],[5.2,0.05]],"id":69213654}],"con":true,"img":false}]}
{"op":"mcm","clk":"11541225694","pt":1719503551399,"mc":[{"id":"1.230180128","rc":[{"spn":8.35,"spf":"NaN","id":50639934},{"spn":15.1,"spf":"NaN","id":60237218},{"atl":[[3.8,0.84]],"id":51218587},{"spn":8.35,"spf":"NaN","id":69213654},{"spn":14.1,"spf":"NaN","id":66050026}],"con":true,"img":false}]}
{"op":"mcm","clk":"11541225802","pt":1719503552689,"mc":[{"id":"1.230180128","rc":[{"atl":[[8,0]],"id":58821523}],"con":true,"img":false}]}
{"op":"mcm","clk":"11541225821","pt":1719503552893,"mc":[{"id":"1.230180128","rc":[{"atl":[[1000,0.14]],"id":58821523}],"con":true,"img":false}]}
{"op":"mcm","clk":"11541225838","pt":1719503553098,"mc":[{"id":"1.230180128","rc":[{"atl":[[1000,0]],"id":58821523}],"con":true,"img":false}]}
{"op":"mcm","clk":"11541225847","pt":1719503553202,"mc":[{"id":"1.230180128","rc":[{"atl":[[8,0.14]],"id":58821523}],"con":true,"img":false}]}
{"op":"mcm","clk":"11541226056","pt":1719503555722,"mc":[{"id":"1.230180128","rc":[{"atl":[[3.85,0]],"id":51218587}],"con":true,"img":false}]}
{"op":"mcm","clk":"11541226119","pt":1719503556391,"mc":[{"id":"1.230180128","rc":[{"atl":[[3.8,0]],"id":51218587}],"con":true,"img":false}]}
{"op":"mcm","clk":"11541226125","pt":1719503556494,"mc":[{"id":"1.230180128","rc":[{"atl":[[11.5,9.55],[4.4,0]],"id":51218587}],"con":true,"img":false}]}
{"op":"mcm","clk":"11541226208","pt":1719503557527,"mc":[{"id":"1.230180128","rc":[{"atl":[[3.85,2]],"id":51218587}],"con":true,"img":false}]}
{"op":"mcm","clk":"11541226319","pt":1719503558713,"mc":[{"id":"1.230180128","rc":[{"atl":[[3.8,0.84]],"id":51218587}],"con":true,"img":false}]}
{"op":"mcm","clk":"11541226574","pt":1719503561201,"mc":[{"id":"1.230180128","rc":[{"atl":[[1000,0]],"id":51218587}],"con":true,"img":false}]}
{"op":"mcm","clk":"11541226724","pt":1719503562711,"mc":[{"id":"1.230180128","rc":[{"atl":[[3.85,0]],"id":51218587}],"con":true,"img":false}]}
{"op":"mcm","clk":"11541226790","pt":1719503563331,"mc":[{"id":"1.230180128","rc":[{"atl":[[3.8,0]],"id":51218587}],"con":true,"img":false}]}
{"op":"mcm","clk":"11541226961","pt":1719503564824,"mc":[{"id":"1.230180128","rc":[{"atl":[[3.85,2]],"id":51218587}],"con":true,"img":false}]}
{"op":"mcm","clk":"11541226972","pt":1719503564927,"mc":[{"id":"1.230180128","rc":[{"atl":[[11.5,0.03],[4.4,9.55]],"id":51218587}],"con":true,"img":false}]}
{"op":"mcm","clk":"11541227058","pt":1719503565806,"mc":[{"id":"1.230180128","rc":[{"atl":[[3.8,0.84]],"id":51218587}],"con":true,"img":false}]}
{"op":"mcm","clk":"11541227127","pt":1719503566422,"mc":[{"id":"1.230180128","rc":[{"atb":[[3.2,0]],"id":58821523},{"atl":[[8.2,1.11]],"id":58821523},{"atb":[[5.1,1.6]],"id":50639934},{"atl":[[25,0]],"id":50639934},{"atb":[[6,1]],"id":66050026}],"con":true,"img":false}]}
{"op":"mcm","clk":"11541227329","pt":1719503568440,"mc":[{"id":"1.230180128","rc":[{"atl":[[8,0]],"id":58821523}],"con":true,"img":false}]}
{"op":"mcm","clk":"11541227346","pt":1719503568651,"mc":[{"id":"1.230180128","rc":[{"atl":[[1000,0.14]],"id":58821523}],"con":true,"img":false}]}
{"op":"mcm","clk":"11541227368","pt":1719503568811,"mc":[{"id":"1.230180128","rc":[{"atl":[[1000,0]],"id":58821523}],"con":true,"img":false}]}
{"op":"mcm","clk":"11541227377","pt":1719503568914,"mc":[{"id":"1.230180128","rc":[{"atl":[[8,0.14]],"id":58821523}],"con":true,"img":false}]}
{"op":"mcm","clk":"11541227499","pt":1719503570007,"mc":[{"id":"1.230180128","rc":[{"atl":[[3.85,0]],"id":51218587}],"con":true,"img":false}]}
{"op":"mcm","clk":"11541227521","pt":1719503570217,"mc":[{"id":"1.230180128","rc":[{"atl":[[8.2,0],[7.8,1.08]],"id":58821523}],"con":true,"img":false}]}
{"op":"mcm","clk":"11541227533","pt":1719503570319,"mc":[{"id":"1.230180128","rc":[{"atl":[[3.8,0]],"id":51218587}],"con":true,"img":false}]}
{"op":"mcm","clk":"11541227541","pt":1719503570419,"mc":[{"id":"1.230180128","rc":[{"atb":[[5.1,0]],"id":50639934},{"atl":[[11.5,9.55],[4.4,0]],"id":51218587}],"con":true,"img":false}]}
{"op":"mcm","clk":"11541227548","pt":1719503570522,"mc":[{"id":"1.230180128","rc":[{"atb":[[5.3,1.6]],"id":50639934}],"con":true,"img":false}]}
{"op":"mcm","clk":"11541227570","pt":1719503570727,"mc":[{"id":"1.230180128","rc":[{"atb":[[5.1,0],[5.3,1.6]],"id":69213654}],"con":true,"img":false}]}
{"op":"mcm","clk":"11541227580","pt":1719503570830,"mc":[{"id":"1.230180128","rc":[{"atb":[[5.2,0.05]],"id":50639934}],"con":true,"img":false}]}
{"op":"mcm","clk":"11541227598","pt":1719503571039,"mc":[{"id":"1.230180128","rc":[{"atl":[[8.2,1.08],[7.8,0]],"id":58821523}],"con":true,"img":false}]}
{"op":"mcm","clk":"11541227636","pt":1719503571351,"mc":[{"id":"1.230180128","rc":[{"atb":[[5.1,1.6],[5.3,0]],"id":50639934}],"con":true,"img":false}]}
{"op":"mcm","clk":"11541227683","pt":1719503571671,"mc":[{"id":"1.230180128","rc":[{"atb":[[5.1,1.6],[5.3,0]],"id":69213654}],"con":true,"img":false}]}
{"op":"mcm","clk":"11541227719","pt":1719503571923,"mc":[{"id":"1.230180128","rc":[{"atl":[[3.85,2]],"id":51218587}],"con":true,"img":false}]}
{"op":"mcm","clk":"11541227814","pt":1719503572851,"mc":[{"id":"1.230180128","rc":[{"atl":[[3.8,0.84]],"id":51218587}],"con":true,"img":false}]}
{"op":"mcm","clk":"11541228252","pt":1719503577166,"mc":[{"id":"1.230180128","rc":[{"atl":[[3.85,0]],"id":51218587}],"con":true,"img":false}]}
{"op":"mcm","clk":"11541228307","pt":1719503577743,"mc":[{"id":"1.230180128","rc":[{"atl":[[3.8,0]],"id":51218587}],"con":true,"img":false}]}
{"op":"mcm","clk":"11541228420","pt":1719503579074,"mc":[{"id":"1.230180128","rc":[{"atl":[[3.85,2]],"id":51218587}],"con":true,"img":false}]}
{"op":"mcm","clk":"11541228431","pt":1719503579175,"mc":[{"id":"1.230180128","rc":[{"atl":[[4.4,9.55]],"id":51218587}],"con":true,"img":false}]}
{"op":"mcm","clk":"11541228440","pt":1719503579283,"mc":[{"id":"1.230180128","rc":[{"atl":[[11.5,0.03]],"id":51218587}],"con":true,"img":false}]}
{"op":"mcm","clk":"11541228521","pt":1719503580277,"mc":[{"id":"1.230180128","rc":[{"atl":[[3.8,0.84]],"id":51218587}],"con":true,"img":false}]}
{"op":"mcm","clk":"11541228626","pt":1719503581258,"mc":[{"id":"1.230180128","rc":[{"atl":[[7.4,1]],"id":58821523},{"atl":[[44,1]],"id":50639934},{"atb":[[5.5,1]],"id":60237218},{"atb":[[2.48,1]],"id":51218587},{"atb":[[5.4,1]],"id":69213654},{"atb":[[5.8,1]],"id":66050026}],"con":true,"img":false}]}
{"op":"mcm","clk":"11541228639","pt":1719503581363,"mc":[{"id":"1.230180128","rc":[{"atb":[[1.01,1]],"id":66050026}],"con":true,"img":false}]}
{"op":"mcm","clk":"11541228692","pt":1719503581890,"mc":[{"id":"1.230180128","rc":[{"atl":[[4.4,0],[4.1,8]],"id":51218587},{"atb":[[5.8,2],[6,0]],"id":66050026}],"con":true,"img":false}]}
{"op":"mcm","clk":"11541228741","pt":1719503582285,"mc":[{"id":"1.230180128","rc":[{"atb":[[4.3,0],[4.4,0]],"id":58821523},{"atl":[[4.3,2.84]],"id":58821523},{"trd":[[4.3,2],[4.4,0.13]],"ltp":4.3,"tv":2.13,"id":58821523},{"atb":[[5.1,0],[5.2,0]],"id":50639934},{"atl":[[5.1,1.63]],"id":50639934},{"trd":[[5.1,3.2],[5.2,0.11]],"ltp":5.1,"tv":3.31,"id":50639934},{"atb":[[6.2,0],[6,0]],"id":60237218},{"atl":[[6,0.9]],"id":60237218},{"trd":[[6,2],[6.2,1.79]],"ltp":6.0,"tv":3.79,"id":60237218}],"con":true,"img":false}]}
{"op":"mcm","clk":"11541228754","pt":1719503582395,"mc":[{"id":"1.230180128","rc":[{"atb":[[4.3,0.26]],"id":58821523},{"atl":[[4.3,0]],"id":58821523},{"trd":[[4.3,7.68]],"ltp":4.3,"tv":7.68,"id":58821523},{"atb":[[3.6,9.98],[3.9,0]],"id":50639934},{"atl":[[14.5,3.69],[5.1,0],[26,1.69]],"id":50639934},{"trd":[[5.1,6.46]],"ltp":5.1,"tv":6.46,"id":50639934},{"atl":[[36,2.86],[6,0.64]],"id":60237218},{"trd":[[6,2.52]],"ltp":6.0,"tv":2.52,"id":60237218},{"atb":[[2.42,0]],"id":51218587}],"con":true,"img":false}]}
{"op":"mcm","clk":"11541228768","pt":1719503582454,"mc":[{"id":"1.230180128","rc":[{"atl":[[7.4,0]],"id":58821523},{"atb":[[5.6,1],[5.1,14.45],[5.4,0]],"id":60237218},{"atl":[[140,0],[6,0]],"id":60237218},{"trd":[[6,3.8]],"ltp":6.0,"tv":3.8,"id":60237218},{"atb":[[2.5,2]],"id":51218587}],"con":true,"img":false}]}
{"op":"mcm","clk":"11541228780","pt":1719503582554,"mc":[{"id":"1.230180128","rc":[{"atl":[[44,0]],"id":50639934}],"con":true,"img":false}]}
{"op":"mcm","clk":"11541228792","pt":1719503582659,"mc":[{"id":"1.230180128","rc":[{"atb":[[4.3,0],[3.9,1]],"id":58821523},{"atl":[[4.2,0.74]],"id":58821523},{"trd":[[4.3,8.2]],"ltp":4.3,"tv":8.2,"id":58821523},{"atb":[[2.44,0.84]],"id":51218587},{"atb":[[5.2,0]],"id":69213654},{"atb":[[6.2,0]],"id":66050026}],"con":true,"img":false}]}
{"op":"mcm","clk":"11541228804","pt":1719503582765,"mc":[{"id":"1.230180128","rc":[{"atl":[[4.2,0.48]],"id":58821523},{"trd":[[4.2,0.52]],"ltp":4.2,"tv":0.52,"id":58821523},{"atl":[[26,2.69]],"id":50639934},{"atb":[[2.52,0.84],[2.44,0]],"id":51218587}],"con":true,"img":false}]}
{"op":"mcm","clk":"11541228820","pt":1719503582865,"mc":[{"id":"1.230180128","rc":[{"atl":[[4.2,0]],"id":58821523},{"trd":[[4.2,1.48]],"ltp":4.2,"tv":1.48,"id":58821523},{"atl":[[1000,0.27]],"id":50639934},{"atb":[[5.5,0]],"id":60237218},{"atb":[[2.48,0]],"id":51218587}],"con":true,"img":false}]}
{"op":"mcm","clk":"11541228842","pt":1719503583072,"mc":[{"id":"1.230180128","rc":[{"atl":[[1000,0.17]],"id":50639934},{"atb":[[5.4,0]],"id":69213654},{"atb":[[5.8,1]],"id":66050026}],"con":true,"img":false}]}
{"op":"mcm","clk":"11541228854","pt":1719503583174,"mc":[{"id":"1.230180128","rc":[{"atl":[[11,0.1]],"id":50639934}],"con":true,"img":false}]}
{"op":"mcm","clk":"11541228901","pt":1719503583587,"mc":[{"id":"1.230180128","rc":[{"atb":[[2.5,0]],"id":51218587}],"con":true,"img":false}]}
{"op":"mcm","clk":"11541228911","pt":1719503583647,"mc":[{"id":"1.230180128","rc":[{"atb":[[2.42,2]],"id":51218587},{"atb":[[5.5,1.54]],"id":69213654}],"con":true,"img":false}]}
{"op":"mcm","clk":"11541228918","pt":1719503583754,"mc":[{"id":"1.230180128","rc":[{"atb":[[3.05,3.9]],"id":58821523},{"atb":[[5.1,0]],"id":69213654}],"con":true,"img":false}]}
{"op":"mcm","clk":"11541228933","pt":1719503583964,"mc":[{"id":"1.230180128","rc":[{"atb":[[2.52,0]],"id":51218587}],"con":true,"img":false}]}
{"op":"mcm","clk":"11541228945","pt":1719503584059,"mc":[{"id":"1.230180128","rc":[{"atb":[[5.5,0]],"id":69213654},{"atb":[[5.9,2.27]],"id":66050026}],"con":true,"img":false}]}
{"op":"mcm","clk":"11541228955","pt":1719503584166,"mc":[{"id":"1.230180128","rc":[{"atl":[[8,0]],"id":58821523}],"con":true,"img":false}]}
{"op":"mcm","clk":"11541228966","pt":1719503584271,"mc":[{"id":"1.230180128","rc":[{"atl":[[3.85,0]],"id":51218587},{"atb":[[6,4.23]],"id":66050026}],"con":true,"img":false}]}
{"op":"mcm","clk":"11541228980","pt":1719503584375,"mc":[{"id":"1.230180128","rc":[{"atl":[[10.5,8],[11.5,0],[1000,0.14]],"id":58821523},{"atb":[[5.2,1.54]],"id":69213654}],"con":true,"img":false}]}
{"op":"mcm","clk":"11541229000","pt":1719503584572,"mc":[{"id":"1.230180128","rc":[{"atl":[[1000,0]],"id":58821523}],"con":true,"img":false}]}
{"op":"mcm","clk":"11541229009","pt":1719503584678,"mc":[{"id":"1.230180128","rc":[{"atl":[[8,0.14]],"id":58821523}],"con":true,"img":false}]}
{"op":"mcm","clk":"11541229019","pt":1719503584780,"mc":[{"id":"1.230180128","rc":[{"atl":[[3.8,0]],"id":51218587},{"atb":[[6.2,0.84]],"id":66050026}],"con":true,"img":false}]}
{"op":"mcm","clk":"11541229033","pt":1719503584882,"mc":[{"id":"1.230180128","rc":[{"atl":[[10.5,9],[4.1,0]],"id":51218587}],"con":true,"img":false}]}
{"op":"mcm","clk":"11541229043","pt":1719503584983,"mc":[{"id":"1.230180128","rc":[{"atb":[[6,0]],"id":66050026}],"con":true,"img":false}]}
{"op":"mcm","clk":"11541229074","pt":1719503585287,"mc":[{"id":"1.230180128","rc":[{"atb":[[5.9,0.84],[6.2,2.2]],"id":66050026}],"con":true,"img":false}]}
{"op":"mcm","clk":"11541229085","pt":1719503585392,"mc":[{"id":"1.230180128","rc":[{"atb":[[6.2,1.36]],"id":66050026}],"con":true,"img":false}]}
{"op":"mcm","clk":"11541229153","pt":1719503586067,"mc":[{"id":"1.230180128","rc":[{"atb":[[5.9,2.2],[6.2,0]],"id":66050026}],"con":true,"img":false}]}
{"op":"mcm","clk":"11541229161","pt":1719503586178,"mc":[{"id":"1.230180128","rc":[{"atl":[[3.85,2]],"id":51218587}],"con":true,"img":false}]}
{"op":"mcm","clk":"11541229173","pt":1719503586282,"mc":[{"id":"1.230180128","rc":[{"atb":[[6,4.23]],"id":66050026}],"con":true,"img":false}]}
{"op":"mcm","clk":"11541229184","pt":1719503586377,"mc":[{"id":"1.230180128","rc":[{"atl":[[10.5,0],[4.4,8]],"id":51218587}],"con":true,"img":false}]}
{"op":"mcm","clk":"11541229205","pt":1719503586579,"mc":[{"id":"1.230180128","rc":[{"atb":[[5.9,0.84],[6.2,1.36]],"id":66050026}],"con":true,"img":false}]}
{"op":"mcm","clk":"11541229257","pt":1719503587053,"mc":[{"id":"1.230180128","rc":[{"atb":[[6,0]],"id":66050026}],"con":true,"img":false}]}
{"op":"mcm","clk":"11541229290","pt":1719503587367,"mc":[{"id":"1.230180128","rc":[{"atl":[[3.8,0.84]],"id":51218587}],"con":true,"img":false}]}
{"op":"mcm","clk":"11541229301","pt":1719503587466,"mc":[{"id":"1.230180128","rc":[{"atl":[[14.5,0],[17,2.69]],"id":50639934}],"con":true,"img":false}]}
{"op":"mcm","clk":"11541229315","pt":1719503587670,"mc":[{"id":"1.230180128","rc":[{"atl":[[26,1.69]],"id":50639934}],"con":true,"img":false}]}
{"op":"mcm","clk":"11541229334","pt":1719503587881,"mc":[{"id":"1.230180128","rc":[{"atl":[[14,1]],"id":50639934}],"con":true,"img":false}]}
{"op":"mcm","clk":"11541229522","pt":1719503589784,"mc":[{"id":"1.230180128","rc":[{"atb":[[2.44,0.84]],"id":51218587}],"con":true,"img":false}]}
{"op":"mcm","clk":"11541229683","pt":1719503591392,"mc":[{"id":"1.230180128","rc":[{"atl":[[3.85,0]],"id":51218587}],"con":true,"img":false}]}
{"op":"mcm","clk":"11541229691","pt":1719503591479,"mc":[{"id":"1.230180128","rc":[{"atb":[[1.25,20]],"id":58821523},{"atb":[[1.25,20]],"id":50639934},{"atb":[[1.25,20]],"id":60237218},{"atb":[[1.25,20]],"id":51218587},{"atb":[[1.25,20]],"id":69213654},{"atb":[[1.25,20]],"id":66050026}],"con":true,"img":false}]}
{"op":"mcm","clk":"11541229727","pt":1719503591891,"mc":[{"id":"1.230180128","rc":[{"atl":[[3.8,0]],"id":51218587}],"con":true,"img":false}]}
{"op":"mcm","clk":"11541229744","pt":1719503592102,"mc":[{"id":"1.230180128","rc":[{"atl":[[11.5,9.03],[4.4,0]],"id":51218587}],"con":true,"img":false}]}
{"op":"mcm","clk":"11541229864","pt":1719503593286,"mc":[{"id":"1.230180128","rc":[{"atl":[[3.85,2]],"id":51218587}],"con":true,"img":false}]}
{"op":"mcm","clk":"11541229873","pt":1719503593385,"mc":[{"id":"1.230180128","rc":[{"atb":[[5.6,0],[5.7,1]],"id":60237218},{"atl":[[11.5,0.03],[4.4,9.03]],"id":51218587}],"con":true,"img":false}]}
{"op":"mcm","clk":"11541229996","pt":1719503594781,"mc":[{"id":"1.230180128","rc":[{"atl":[[3.8,0.84]],"id":51218587}],"con":true,"img":false}]}
{"op":"mcm","clk":"11541230017","pt":1719503595088,"mc":[{"id":"1.230180128","rc":[{"atb":[[5.1,1.54]],"id":69213654}],"con":true,"img":false}]}
{"op":"mcm","clk":"11541230025","pt":1719503595190,"mc":[{"id":"1.230180128","rc":[{"atb":[[5.2,0]],"id":69213654}],"con":true,"img":false}]}
{"op":"mcm","clk":"11541230315","pt":1719503598405,"mc":[{"id":"1.230180128","rc":[{"atl":[[11,0]],"id":50639934}],"con":true,"img":false}]}
{"op":"mcm","clk":"11541230329","pt":1719503598504,"mc":[{"id":"1.230180128","rc":[{"atl":[[3.85,0]],"id":51218587}],"con":true,"img":false}]}
{"op":"mcm","clk":"11541230354","pt":1719503598667,"mc":[{"id":"1.230180128","rc":[{"atl":[[1000,0.27]],"id":50639934},{"atb":[[6.2,0],[6,1.36]],"id":66050026}],"con":true,"img":false}]}
{"op":"mcm","clk":"11541230376","pt":1719503598911,"mc":[{"id":"1.230180128","rc":[{"atl":[[1000,0.17]],"id":50639934},{"atl":[[3.8,0]],"id":51218587}],"con":true,"img":false}]}
{"op":"mcm","clk":"11541230388","pt":1719503599031,"mc":[{"id":"1.230180128","rc":[{"atl":[[11,0.1]],"id":50639934}],"con":true,"img":false}]}
{"op":"mcm","clk":"11541230397","pt":1719503599106,"mc":[{"id":"1.230180128","rc":[{"atl":[[11.5,9.55],[4.4,0]],"id":51218587}],"con":true,"img":false}]}
{"op":"mcm","clk":"11541230479","pt":1719503599896,"mc":[{"id":"1.230180128","rc":[{"atl":[[8,0]],"id":58821523}],"con":true,"img":false}]}
{"op":"mcm","clk":"11541230517","pt":1719503600265,"mc":[{"id":"1.230180128","rc":[{"atl":[[3.85,2]],"id":51218587}],"con":true,"img":false}]}
{"op":"mcm","clk":"11541230527","pt":1719503600381,"mc":[{"id":"1.230180128","rc":[{"atl":[[4.4,9.55]],"id":51218587}],"con":true,"img":false}]}
{"op":"mcm","clk":"11541230536","pt":1719503600475,"mc":[{"id":"1.230180128","rc":[{"atl":[[11.5,0.03]],"id":51218587}],"con":true,"img":false}]}
{"op":"mcm","clk":"11541230589","pt":1719503601193,"mc":[{"id":"1.230180128","rc":[{"atl":[[1000,0.14]],"id":58821523}],"con":true,"img":false}]}
{"op":"mcm","clk":"11541230614","pt":1719503601499,"mc":[{"id":"1.230180128","rc":[{"atl":[[1000,0]],"id":58821523}],"con":true,"img":false}]}
{"op":"mcm","clk":"11541230626","pt":1719503601597,"mc":[{"id":"1.230180128","rc":[{"atl":[[8,0.14]],"id":58821523}],"con":true,"img":false}]}
{"op":"mcm","clk":"11541230651","pt":1719503601805,"mc":[{"id":"1.230180128","rc":[{"atl":[[3.8,0.84]],"id":51218587}],"con":true,"img":false}]}
{"op":"mcm","clk":"11541231081","pt":1719503605595,"mc":[{"id":"1.230180128","rc":[{"atl":[[3.85,0]],"id":51218587}],"con":true,"img":false}]}
{"op":"mcm","clk":"11541231162","pt":1719503606276,"mc":[{"id":"1.230180128","rc":[{"atl":[[3.8,0]],"id":51218587}],"con":true,"img":false}]}
{"op":"mcm","clk":"11541231174","pt":1719503606374,"mc":[{"id":"1.230180128","rc":[{"atl":[[11.5,9.55],[4.4,0]],"id":51218587}],"con":true,"img":false}]}
{"op":"mcm","clk":"11541231293","pt":1719503607604,"mc":[{"id":"1.230180128","rc":[{"atl":[[3.85,2]],"id":51218587}],"con":true,"img":false}]}
{"op":"mcm","clk":"11541231410","pt":1719503608898,"mc":[{"id":"1.230180128","rc":[{"atl":[[3.8,0.84]],"id":51218587}],"con":true,"img":false}]}
{"op":"mcm","clk":"11541231436","pt":1719503609201,"mc":[{"id":"1.230180128","rc":[{"atb":[[6,0]],"id":66050026}],"con":true,"img":false}]}
{"op":"mcm","clk":"11541231464","pt":1719503609507,"mc":[{"id":"1.230180128","rc":[{"atb":[[5.9,2.2]],"id":66050026}],"con":true,"img":false}]}
{"op":"mcm","clk":"11541231518","pt":1719503609983,"mc":[{"id":"1.230180128","rc":[{"atb":[[6,4.23]],"id":66050026}],"con":true,"img":false}]}
{"op":"mcm","clk":"11541231550","pt":1719503610284,"mc":[{"id":"1.230180128","rc":[{"atb":[[6.2,2.2]],"id":66050026}],"con":true,"img":false}]}
{"op":"mcm","clk":"11541231561","pt":1719503610391,"mc":[{"id":"1.230180128","rc":[{"atb":[[5.9,0.84]],"id":66050026}],"con":true,"img":false}]}
{"op":"mcm","clk":"11541231597","pt":1719503610701,"mc":[{"id":"1.230180128","rc":[{"atb":[[6,0]],"id":66050026}],"con":true,"img":false}]}
{"op":"mcm","clk":"11541231617","pt":1719503610913,"mc":[{"id":"1.230180128","rc":[{"atb":[[5.9,0]],"id":66050026}],"con":true,"img":false}]}
{"op":"mcm","clk":"11541231782","pt":1719503612812,"mc":[{"id":"1.230180128","rc":[{"spn":3.9,"spf":1.0,"id":58821523},{"spn":8.0,"spf":"NaN","id":50639934},{"spn":14.85,"spf":"NaN","id":60237218},{"atl":[[3.85,0]],"id":51218587},{"spn":8.3,"spf":"NaN","id":69213654}],"con":true,"img":false}]}
{"op":"mcm","clk":"11541231805","pt":1719503613020,"mc":[{"id":"1.230180128","rc":[{"atb":[[2.18,10.04]],"id":69213654}],"con":true,"img":false}]}
{"op":"mcm","clk":"11541231824","pt":1719503613174,"mc":[{"id":"1.230180128","rc":[{"atb":[[2.24,9.56]],"id":58821523},{"atb":[[2.28,9.26]],"id":50639934}],"con":true,"img":false}]}
{"op":"mcm","clk":"11541231842","pt":1719503613380,"mc":[{"id":"1.230180128","rc":[{"atb":[[2.16,5.45]],"id":50639934},{"atl":[[3.8,0]],"id":51218587},{"atb":[[2.16,16.57]],"id":69213654}],"con":true,"img":false}]}
{"op":"mcm","clk":"11541231858","pt":1719503613596,"mc":[{"id":"1.230180128","rc":[{"atb":[[1.85,13.95]],"id":51218587},{"atb":[[2.16,5.45]],"id":66050026}],"con":true,"img":false}]}
{"op":"mcm","clk":"11541231880","pt":1719503613837,"mc":[{"id":"1.230180128","rc":[{"atb":[[3.1,3.76]],"id":58821523}],"con":true,"img":false}]}
{"op":"mcm","clk":"11541231891","pt":1719503613936,"mc":[{"id":"1.230180128","rc":[{"atb":[[2.26,9.4]],"id":60237218}],"con":true,"img":false}]}
{"op":"mcm","clk":"11541231901","pt":1719503614055,"mc":[{"id":"1.230180128","rc":[{"atb":[[3,6],[3.15,4.76]],"id":58821523},{"atb":[[2.4,6.69]],"id":51218587}],"con":true,"img":false}]}
{"op":"mcm","clk":"11541231915","pt":1719503614133,"mc":[{"id":"1.230180128","rc":[{"atb":[[2.1,7.18]],"id":51218587}],"con":true,"img":false}]}
{"op":"mcm","clk":"11541231922","pt":1719503614199,"mc":[{"id":"1.230180128","rc":[{"atb":[[2.86,5.09]],"id":50639934},{"atl":[[11,0]],"id":50639934}],"con":true,"img":false}]}
{"op":"mcm","clk":"11541231937","pt":1719503614405,"mc":[{"id":"1.230180128","rc":[{"atl":[[1000,0.27]],"id":50639934},{"atb":[[2.1,12.93]],"id":51218587},{"atb":[[2.2,9.88]],"id":66050026}],"con":true,"img":false}]}
{"op":"mcm","clk":"11541231956","pt":1719503614610,"mc":[{"id":"1.230180128","rc":[{"atb":[[3.05,6.98]],"id":58821523},{"atl":[[1000,0.17]],"id":50639934}],"con":true,"img":false}]}
{"op":"mcm","clk":"11541231967","pt":1719503614716,"mc":[{"id":"1.230180128","rc":[{"atl":[[11,0.1]],"id":50639934},{"atb":[[3.1,4.51]],"id":60237218},{"atl":[[3.85,2]],"id":51218587}],"con":true,"img":false}]}
{"op":"mcm","clk":"11541231984","pt":1719503614918,"mc":[{"id":"1.230180128","rc":[{"atl":[[11.5,0.03],[4.4,9.55]],"id":51218587}],"con":true,"img":false}]}
{"op":"mcm","clk":"11541232071","pt":1719503615890,"mc":[{"id":"1.230180128","rc":[{"atl":[[3.8,0.84]],"id":51218587}],"con":true,"img":false}]}
{"op":"mcm","clk":"11541232134","pt":1719503616715,"mc":[{"id":"1.230180128","rc":[{"atl":[[8,0]],"id":58821523}],"con":true,"img":false}]}
{"op":"mcm","clk":"11541232154","pt":1719503616968,"mc":[{"id":"1.230180128","rc":[{"atl":[[1000,0.14]],"id":58821523}],"con":true,"img":false}]}
{"op":"mcm","clk":"11541232168","pt":1719503617174,"mc":[{"id":"1.230180128","rc":[{"atl":[[1000,0]],"id":58821523}],"con":true,"img":false}]}
{"op":"mcm","clk":"11541232178","pt":1719503617276,"mc":[{"id":"1.230180128","rc":[{"atl":[[8,0.14]],"id":58821523}],"con":true,"img":false}]}
{"op":"mcm","clk":"11541232255","pt":1719503618201,"mc":[{"id":"1.230180128","rc":[{"atl":[[10,1]],"id":58821523},{"atl":[[16.5,1]],"id":50639934},{"atl":[[34,1]],"id":60237218},{"atl":[[3.8,1.84]],"id":51218587},{"atl":[[29,1]],"id":69213654},{"atl":[[130,1]],"id":66050026}],"con":true,"img":false}]}
{"op":"mcm","clk":"11541232427","pt":1719503620014,"mc":[{"id":"1.230180128","rc":[{"atl":[[3.85,0]],"id":51218587}],"con":true,"img":false}]}
{"op":"mcm","clk":"11541232576","pt":1719503621384,"mc":[{"id":"1.230180128","rc":[{"atb":[[3.15,7.14]],"id":58821523},{"atb":[[3.6,12.66]],"id":50639934},{"atb":[[2.44,1.63]],"id":51218587},{"atb":[[3.6,15.43]],"id":69213654},{"atb":[[6,1.22]],"id":66050026}],"con":true,"img":false}]}
{"op":"mcm","clk":"11541232612","pt":1719503621794,"mc":[{"id":"1.230180128","rc":[{"atl":[[3.75,2]],"id":51218587}],"con":true,"img":false}]}
{"op":"mcm","clk":"11541232698","pt":1719503622925,"mc":[{"id":"1.230180128","rc":[{"atl":[[3.7,0.84]],"id":51218587}],"con":true,"img":false}]}
{"op":"mcm","clk":"11541232751","pt":1719503623591,"mc":[{"id":"1.230180128","rc":[{"atl":[[3.8,0.84]],"id":51218587}],"con":true,"img":false}]}
{"op":"mcm","clk":"11541232756","pt":1719503623695,"mc":[{"id":"1.230180128","rc":[{"atl":[[3.7,1.84]],"id":51218587}],"con":true,"img":false}]}
{"op":"mcm","clk":"11541232815","pt":1719503624415,"mc":[{"id":"1.230180128","rc":[{"atl":[[3.8,0]],"id":51218587}],"con":true,"img":false}]}
{"op":"mcm","clk":"11541232823","pt":1719503624517,"mc":[{"id":"1.230180128","rc":[{"atb":[[2.42,0]],"id":51218587}],"con":true,"img":false}]}
{"op":"mcm","clk":"11541232830","pt":1719503624621,"mc":[{"id":"1.230180128","rc":[{"atb":[[2.46,2]],"id":51218587}],"con":true,"img":false}]}
{"op":"mcm","clk":"11541232848","pt":1719503624829,"mc":[{"id":"1.230180128","rc":[{"atb":[[2.44,0.79]],"id":51218587}],"con":true,"img":false}]}
{"op":"mcm","clk":"11541232883","pt":1719503625193,"mc":[{"id":"1.230180128","rc":[{"atb":[[2.48,0.84]],"id":51218587}],"con":true,"img":false}]}
{"op":"mcm","clk":"11541232984","pt":1719503626282,"mc":[{"id":"1.230180128","rc":[{"atb":[[2.46,0]],"id":51218587}],"con":true,"img":false}]}
{"op":"mcm","clk":"11541232992","pt":1719503626396,"mc":[{"id":"1.230180128","rc":[{"atb":[[2.42,2]],"id":51218587}],"con":true,"img":false}]}
{"op":"mcm","clk":"11541233023","pt":1719503626796,"mc":[{"id":"1.230180128","rc":[{"atb":[[2.48,0]],"id":51218587}],"con":true,"img":false}]}
{"op":"mcm","clk":"11541233048","pt":1719503627110,"mc":[{"id":"1.230180128","rc":[{"atl":[[3.75,0]],"id":51218587}],"con":true,"img":false}]}
{"op":"mcm","clk":"11541233091","pt":1719503627649,"mc":[{"id":"1.230180128","rc":[{"atl":[[3.7,0.84]],"id":51218587}],"con":true,"img":false}]}
{"op":"mcm","clk":"11541233103","pt":1719503627727,"mc":[{"id":"1.230180128","rc":[{"atl":[[4.3,1]],"id":51218587}],"con":true,"img":false}]}
{"op":"mcm","clk":"11541233153","pt":1719503628292,"mc":[{"id":"1.230180128","rc":[{"atl":[[3.7,0]],"id":51218587}],"con":true,"img":false}]}
{"op":"mcm","clk":"11541233231","pt":1719503629318,"mc":[{"id":"1.230180128","rc":[{"atl":[[3.85,2]],"id":51218587}],"con":true,"img":false}]}
{"op":"mcm","clk":"11541233283","pt":1719503629882,"mc":[{"id":"1.230180128","rc":[{"atl":[[11,0]],"id":50639934}],"con":true,"img":false}]}
{"op":"mcm","clk":"11541233302","pt":1719503630091,"mc":[{"id":"1.230180128","rc":[{"atl":[[1000,0.27]],"id":50639934}],"con":true,"img":false}]}
{"op":"mcm","clk":"11541233309","pt":1719503630193,"mc":[{"id":"1.230180128","rc":[{"atl":[[1000,0.17]],"id":50639934},{"atl":[[3.8,0.84]],"id":51218587}],"con":true,"img":false}]}
{"op":"mcm","clk":"11541233321","pt":1719503630300,"mc":[{"id":"1.230180128","rc":[{"atl":[[8.2,0],[7.8,1.08]],"id":58821523},{"atl":[[11,0.1]],"id":50639934}],"con":true,"img":false}]}
{"op":"mcm","clk":"11541233347","pt":1719503630604,"mc":[{"id":"1.230180128","rc":[{"atl":[[7.8,0]],"id":58821523},{"atl":[[1000,1.02]],"id":50639934}],"con":true,"img":false}]}
{"op":"mcm","clk":"11541233388","pt":1719503630918,"mc":[{"id":"1.230180128","rc":[{"atl":[[8.2,1.08]],"id":58821523}],"con":true,"img":false}]}
{"op":"mcm","clk":"11541233419","pt":1719503631223,"mc":[{"id":"1.230180128","rc":[{"atl":[[1000,0.98]],"id":50639934}],"con":true,"img":false}]}
{"op":"mcm","clk":"11541233457","pt":1719503631530,"mc":[{"id":"1.230180128","rc":[{"atl":[[1000,0.17]],"id":50639934}],"con":true,"img":false}]}
{"op":"mcm","clk":"11541233469","pt":1719503631583,"mc":[{"id":"1.230180128","rc":[{"atl":[[10.5,0.8]],"id":50639934}],"con":true,"img":false}]}
{"op":"mcm","clk":"11541233522","pt":1719503632205,"mc":[{"id":"1.230180128","rc":[{"atb":[[2.44,1.63]],"id":51218587}],"con":true,"img":false}]}
{"op":"mcm","clk":"11541233551","pt":1719503632516,"mc":[{"id":"1.230180128","rc":[{"atl":[[8,0]],"id":58821523}],"con":true,"img":false}]}
{"op":"mcm","clk":"11541233574","pt":1719503632724,"mc":[{"id":"1.230180128","rc":[{"atl":[[1000,0.14]],"id":58821523},{"atb":[[2.42,0]],"id":51218587}],"con":true,"img":false}]}
{"op":"mcm","clk":"11541233582","pt":1719503632826,"mc":[{"id":"1.230180128","rc":[{"atb":[[2.46,2]],"id":51218587}],"con":true,"img":false}]}
{"op":"mcm","clk":"11541233595","pt":1719503633039,"mc":[{"id":"1.230180128","rc":[{"atl":[[1000,0]],"id":58821523}],"con":true,"img":false}]}
{"op":"mcm","clk":"11541233603","pt":1719503633087,"mc":[{"id":"1.230180128","rc":[{"atl":[[8,0.14]],"id":58821523}],"con":true,"img":false}]}
{"op":"mcm","clk":"11541233660","pt":1719503633707,"mc":[{"id":"1.230180128","rc":[{"atl":[[4.3,0]],"id":51218587}],"con":true,"img":false}]}
{"op":"mcm","clk":"11541233673","pt":1719503633806,"mc":[{"id":"1.230180128","rc":[{"atl":[[3.8,1.84]],"id":51218587}],"con":true,"img":false}]}
{"op":"mcm","clk":"11541233753","pt":1719503634526,"mc":[{"id":"1.230180128","rc":[{"atb":[[3.1,0]],"id":58821523},{"atl":[[3.85,0]],"id":51218587}],"con":true,"img":false}]}
{"op":"mcm","clk":"11541233790","pt":1719503634897,"mc":[{"id":"1.230180128","rc":[{"atb":[[6,0]],"id":66050026}],"con":true,"img":false}]}
{"op":"mcm","clk":"11541233814","pt":1719503635102,"mc":[{"id":"1.230180128","rc":[{"atl":[[26,0]],"id":50639934},{"atl":[[3.8,0.84]],"id":51218587}],"con":true,"img":false}]}
{"op":"mcm","clk":"11541233825","pt":1719503635203,"mc":[{"id":"1.230180128","rc":[{"atl":[[4.3,1]],"id":51218587}],"con":true,"img":false}]}
{"op":"mcm","clk":"11541233883","pt":1719503635827,"mc":[{"id":"1.230180128","rc":[{"atl":[[3.8,0]],"id":51218587}],"con":true,"img":false}]}
{"op":"mcm","clk":"11541233938","pt":1719503636390,"mc":[{"id":"1.230180128","rc":[{"atl":[[3.85,2]],"id":51218587}],"con":true,"img":false}]}
{"op":"mcm","clk":"11541234008","pt":1719503637118,"mc":[{"id":"1.230180128","rc":[{"atl":[[4.3,0]],"id":51218587}],"con":true,"img":false}]}
{"op":"mcm","clk":"11541234017","pt":1719503637217,"mc":[{"id":"1.230180128","rc":[{"atl":[[3.8,1]],"id":51218587}],"con":true,"img":false}]}
{"op":"mcm","clk":"11541234026","pt":1719503637320,"mc":[{"id":"1.230180128","rc":[{"atl":[[3.8,1.84]],"id":51218587}],"con":true,"img":false}]}
{"op":"mcm","clk":"11541234063","pt":1719503637736,"mc":[{"id":"1.230180128","rc":[{"atl":[[3.85,0]],"id":51218587}],"con":true,"img":false}]}
{"op":"mcm","clk":"11541234096","pt":1719503638039,"mc":[{"id":"1.230180128","rc":[{"atl":[[11,1.65]],"id":50639934}],"con":true,"img":false}]}
{"op":"mcm","clk":"11541234104","pt":1719503638144,"mc":[{"id":"1.230180128","rc":[{"atl":[[3.8,0.84]],"id":51218587}],"con":true,"img":false}]}
{"op":"mcm","clk":"11541234115","pt":1719503638195,"mc":[{"id":"1.230180128","rc":[{"atl":[[10.5,1.65]],"id":50639934},{"atl":[[4.3,1]],"id":51218587}],"con":true,"img":false}]}
{"op":"mcm","clk":"11541234158","pt":1719503638724,"mc":[{"id":"1.230180128","rc":[{"atl":[[3.8,0]],"id":51218587}],"con":true,"img":false}]}
{"op":"mcm","clk":"11541234198","pt":1719503639127,"mc":[{"id":"1.230180128","rc":[{"atl":[[16.5,0]],"id":50639934}],"con":true,"img":false}]}
{"op":"mcm","clk":"11541234206","pt":1719503639229,"mc":[{"id":"1.230180128","rc":[{"atl":[[10,1]],"id":50639934}],"con":true,"img":false}]}
{"op":"mcm","clk":"11541234214","pt":1719503639334,"mc":[{"id":"1.230180128","rc":[{"atb":[[2.48,0.84]],"id":51218587}],"con":true,"img":false}]}
{"op":"mcm","clk":"11541234225","pt":1719503639436,"mc":[{"id":"1.230180128","rc":[{"atl":[[14,0]],"id":50639934}],"con":true,"img":false}]}
{"op":"mcm","clk":"11541234246","pt":1719503639592,"mc":[{"id":"1.230180128","rc":[{"atl":[[9.8,1]],"id":50639934}],"con":true,"img":false}]}
{"op":"mcm","clk":"11541234481","pt":1719503641815,"mc":[{"id":"1.230180128","rc":[{"atb":[[2.52,2.6]],"id":58821523}],"con":true,"img":false}]}
{"op":"mcm","clk":"11541234656","pt":1719503643522,"mc":[{"id":"1.230180128","rc":[{"atl":[[3.85,2]],"id":51218587}],"con":true,"img":false}]}
{"op":"mcm","clk":"11541234680","pt":1719503643832,"mc":[{"id":"1.230180128","rc":[{"atl":[[4.3,0]],"id":51218587}],"con":true,"img":false}]}
{"op":"mcm","clk":"11541234685","pt":1719503643944,"mc":[{"id":"1.230180128","rc":[{"atl":[[3.8,1]],"id":51218587}],"con":true,"img":false}]}
{"op":"mcm","clk":"11541234708","pt":1719503644144,"mc":[{"id":"1.230180128","rc":[{"atb":[[1.02,3.7]],"id":58821523},{"atl":[[1000,1.7]],"id":58821523},{"atb":[[1.03,176.13]],"id":50639934},{"atl":[[1000,1.88]],"id":50639934},{"atb":[[1.05,1.7]],"id":66050026},{"atl":[[1000,1.88]],"id":66050026}],"con":true,"img":false}]}
{"op":"mcm","clk":"11541234731","pt":1719503644304,"mc":[{"id":"1.230180128","rc":[{"atb":[[1.02,2.12]],"id":58821523},{"atl":[[1000,0.03]],"id":58821523},{"atb":[[1.03,174.53]],"id":50639934},{"atl":[[1000,0.2]],"id":50639934},{"atb":[[1.05,0.05]],"id":66050026},{"atl":[[1000,0.17]],"id":66050026}],"con":true,"img":false}]}
{"op":"mcm","clk":"11541234749","pt":1719503644512,"mc":[{"id":"1.230180128","rc":[{"atb":[[1.02,2]],"id":58821523},{"atl":[[1000,0]],"id":58821523},{"atb":[[1.03,174.42]],"id":50639934},{"atl":[[1000,0.17]],"id":50639934},{"atb":[[1.05,0]],"id":66050026}],"con":true,"img":false}]}
{"op":"mcm","clk":"11541234758","pt":1719503644617,"mc":[{"id":"1.230180128","rc":[{"atb":[[3.2,0.12]],"id":58821523},{"atl":[[8.2,1.12]],"id":58821523},{"atb":[[3.65,0.1]],"id":50639934},{"atl":[[9.8,1.03]],"id":50639934},{"atb":[[6.4,0.05]],"id":66050026}],"con":true,"img":false}]}
{"op":"mcm","clk":"11541234848","pt":1719503645545,"mc":[{"id":"1.230180128","rc":[{"atl":[[11,1.55]],"id":50639934}],"con":true,"img":false}]}
{"op":"mcm","clk":"11541234883","pt":1719503645803,"mc":[{"id":"1.230180128","rc":[{"atl":[[1000,0.29]],"id":50639934}],"con":true,"img":false}]}
{"op":"mcm","clk":"11541234906","pt":1719503646019,"mc":[{"id":"1.230180128","rc":[{"atl":[[1000,0.17]],"id":50639934}],"con":true,"img":false}]}
{"op":"mcm","clk":"11541234916","pt":1719503646117,"mc":[{"id":"1.230180128","rc":[{"atl":[[9.6,0.12]],"id":50639934}],"con":true,"img":false}]}
{"op":"mcm","clk":"11541235104","pt":1719503648340,"mc":[{"id":"1.230180128","rc":[{"atl":[[8,0]],"id":58821523},{"atb":[[2.44,0.84]],"id":51218587}],"con":true,"img":false}]}
{"op":"mcm","clk":"11541235123","pt":1719503648544,"mc":[{"id":"1.230180128","rc":[{"atl":[[1000,0.14]],"id":58821523}],"con":true,"img":false}]}
{"op":"mcm","clk":"11541235139","pt":1719503648751,"mc":[{"id":"1.230180128","rc":[{"atl":[[1000,0]],"id":58821523},{"atl":[[3.85,0]],"id":51218587}],"con":true,"img":false}]}
{"op":"mcm","clk":"11541235149","pt":1719503648855,"mc":[{"id":"1.230180128","rc":[{"atl":[[8,0.14]],"id":58821523},{"atb":[[2.46,0]],"id":51218587}],"con":true,"img":false}]}
{"op":"mcm","clk":"11541235161","pt":1719503648913,"mc":[{"id":"1.230180128","rc":[{"atb":[[2.42,2]],"id":51218587}],"con":true,"img":false}]}
{"op":"mcm","clk":"11541235196","pt":1719503649222,"mc":[{"id":"1.230180128","rc":[{"atb":[[2.48,0]],"id":51218587}],"con":true,"img":false}]}
{"op":"mcm","clk":"11541235283","pt":1719503650046,"mc":[{"id":"1.230180128","rc":[{"atb":[[3.05,3.9]],"id":58821523},{"atb":[[2.16,11.11]],"id":69213654}],"con":true,"img":false}]}
{"op":"mcm","clk":"11541235346","pt":1719503650621,"mc":[{"id":"1.230180128","rc":[{"atl":[[3.75,2]],"id":51218587}],"con":true,"img":false}]}
{"op":"mcm","clk":"11541235418","pt":1719503651238,"mc":[{"id":"1.230180128","rc":[{"atl":[[3.7,0.84]],"id":51218587}],"con":true,"img":false}]}
{"op":"mcm","clk":"11541235612","pt":1719503652734,"mc":[{"id":"1.230180128","rc":[{"atb":[[2.26,10.07]],"id":58821523}],"con":true,"img":false}]}
{"op":"mcm","clk":"11541235631","pt":1719503652946,"mc":[{"id":"1.230180128","rc":[{"atb":[[2.22,10.41]],"id":66050026}],"con":true,"img":false}]}
{"op":"mcm","clk":"11541235661","pt":1719503653248,"mc":[{"id":"1.230180128","rc":[{"atb":[[2.88,6.75]],"id":50639934},{"atb":[[1.86,14.76]],"id":51218587}],"con":true,"img":false}]}
{"op":"mcm","clk":"11541235689","pt":1719503653557,"mc":[{"id":"1.230180128","rc":[{"atb":[[3.15,5.91]],"id":60237218}],"con":true,"img":false}]}
{"op":"mcm","clk":"11541235698","pt":1719503653667,"mc":[{"id":"1.230180128","rc":[{"atl":[[3.8,0]],"id":51218587}],"con":true,"img":false}]}
{"op":"mcm","clk":"11541235710","pt":1719503653716,"mc":[{"id":"1.230180128","rc":[{"atb":[[2.16,11.29]],"id":50639934},{"atl":[[3.7,1.84]],"id":51218587}],"con":true,"img":false}]}
{"op":"mcm","clk":"11541235720","pt":1719503653818,"mc":[{"id":"1.230180128","rc":[{"atb":[[2.2,10.58]],"id":69213654}],"con":true,"img":false}]}
{"op":"mcm","clk":"11541235741","pt":1719503654032,"mc":[{"id":"1.230180128","rc":[{"atb":[[2.16,11.29]],"id":66050026}],"con":true,"img":false}]}
{"op":"mcm","clk":"11541235752","pt":1719503654129,"mc":[{"id":"1.230180128","rc":[{"atb":[[2.16,16.96]],"id":69213654}],"con":true,"img":false}]}
{"op":"mcm","clk":"11541235776","pt":1719503654447,"mc":[{"id":"1.230180128","rc":[{"atb":[[2.86,10.56]],"id":50639934}],"con":true,"img":false}]}
{"op":"mcm","clk":"11541235795","pt":1719503654643,"mc":[{"id":"1.230180128","rc":[{"atb":[[2.1,19.08]],"id":51218587}],"con":true,"img":false}]}
{"op":"mcm","clk":"11541235836","pt":1719503655059,"mc":[{"id":"1.230180128","rc":[{"atb":[[3.1,9.34]],"id":60237218}],"con":true,"img":false}]}
{"op":"mcm","clk":"11541235926","pt":1719503655933,"mc":[{"id":"1.230180128","rc":[{"atl":[[3.75,0]],"id":51218587}],"con":true,"img":false}]}
{"op":"mcm","clk":"11541235986","pt":1719503656654,"mc":[{"id":"1.230180128","rc":[{"atl":[[3.7,0.84]],"id":51218587}],"con":true,"img":false}]}
{"op":"mcm","clk":"11541236000","pt":1719503656757,"mc":[{"id":"1.230180128","rc":[{"atl":[[4.3,1]],"id":51218587}],"con":true,"img":false}]}
{"op":"mcm","clk":"11541236049","pt":1719503657323,"mc":[{"id":"1.230180128","rc":[{"atl":[[3.7,0]],"id":51218587}],"con":true,"img":false}]}
{"op":"mcm","clk":"11541236085","pt":1719503657738,"mc":[{"id":"1.230180128","rc":[{"atl":[[3.85,2]],"id":51218587}],"con":true,"img":false}]}
{"op":"mcm","clk":"11541236149","pt":1719503658361,"mc":[{"id":"1.230180128","rc":[{"atl":[[3.8,0.84]],"id":51218587}],"con":true,"img":false}]}
{"op":"mcm","clk":"11541236178","pt":1719503658571,"mc":[{"id":"1.230180128","rc":[{"atl":[[4.3,0]],"id":51218587}],"con":true,"img":false}]}
{"op":"mcm","clk":"11541236187","pt":1719503658622,"mc":[{"id":"1.230180128","rc":[{"atl":[[3.8,1.84]],"id":51218587}],"con":true,"img":false}]}
{"op":"mcm","clk":"11541236219","pt":1719503658934,"mc":[{"id":"1.230180128","rc":[{"atl":[[3.85,0]],"id":51218587}],"con":true,"img":false}]}
{"op":"mcm","clk":"11541236402","pt":1719503660744,"mc":[{"id":"1.230180128","rc":[{"atl":[[3.8,0.84]],"id":51218587},{"atb":[[6.2,0.84],[6.6,1.28]],"id":66050026}],"con":true,"img":false}]}
{"op":"mcm","clk":"11541236413","pt":1719503660842,"mc":[{"id":"1.230180128","rc":[{"atl":[[4.3,1]],"id":51218587}],"con":true,"img":false}]}
{"op":"mcm","clk":"11541236452","pt":1719503661268,"mc":[{"id":"1.230180128","rc":[{"atl":[[3.8,0]],"id":51218587}],"con":true,"img":false}]}
{"op":"mcm","clk":"11541236464","pt":1719503661365,"mc":[{"id":"1.230180128","rc":[{"atl":[[9.6,0]],"id":50639934}],"con":true,"img":false}]}
{"op":"mcm","clk":"11541236474","pt":1719503661463,"mc":[{"id":"1.230180128","rc":[{"atb":[[5.9,1.28]],"id":66050026}],"con":true,"img":false}]}
{"op":"mcm","clk":"11541236494","pt":1719503661669,"mc":[{"id":"1.230180128","rc":[{"atb":[[6.6,0]],"id":66050026}],"con":true,"img":false}]}
{"op":"mcm","clk":"11541236556","pt":1719503662249,"mc":[{"id":"1.230180128","rc":[{"atb":[[6.2,0]],"id":66050026}],"con":true,"img":false}]}
{"op":"mcm","clk":"11541236594","pt":1719503662558,"mc":[{"id":"1.230180128","rc":[{"atb":[[3.15,4.76]],"id":58821523},{"atb":[[3.6,9.98]],"id":50639934}],"con":true,"img":false}]}
{"op":"mcm","clk":"11541236612","pt":1719503662759,"mc":[{"id":"1.230180128","rc":[{"atl":[[1000,0.29]],"id":50639934}],"con":true,"img":false}]}
{"op":"mcm","clk":"11541236633","pt":1719503662970,"mc":[{"id":"1.230180128","rc":[{"atl":[[1000,0.17]],"id":50639934}],"con":true,"img":false}]}
{"op":"mcm","clk":"11541236643","pt":1719503663074,"mc":[{"id":"1.230180128","rc":[{"atl":[[9.6,0.12]],"id":50639934}],"con":true,"img":false}]}
{"op":"mcm","clk":"11541236743","pt":1719503664059,"mc":[{"id":"1.230180128","rc":[{"atl":[[8,0]],"id":58821523}],"con":true,"img":false}]}
{"op":"mcm","clk":"11541236787","pt":1719503664365,"mc":[{"id":"1.230180128","rc":[{"atl":[[1000,0.14]],"id":58821523}],"con":true,"img":false}]}
{"op":"mcm","clk":"11541236810","pt":1719503664568,"mc":[{"id":"1.230180128","rc":[{"atl":[[1000,0]],"id":58821523}],"con":true,"img":false}]}
{"op":"mcm","clk":"11541236818","pt":1719503664674,"mc":[{"id":"1.230180128","rc":[{"atl":[[8,0.14]],"id":58821523}],"con":true,"img":false}]}
{"op":"mcm","clk":"11541236840","pt":1719503664834,"mc":[{"id":"1.230180128","rc":[{"atl":[[3.85,2]],"id":51218587}],"con":true,"img":false}]}
{"op":"mcm","clk":"11541236932","pt":1719503665756,"mc":[{"id":"1.230180128","rc":[{"atl":[[3.8,0.84]],"id":51218587}],"con":true,"img":false}]}
{"op":"mcm","clk":"11541236989","pt":1719503666279,"mc":[{"id":"1.230180128","rc":[{"atb":[[11.5,2.57]],"id":69213654},{"atl":[[11.5,0]],"id":69213654},{"trd":[[11.5,1.99]],"ltp":11.5,"tv":1.99,"id":69213654}],"con":true,"img":false}]}
{"op":"mcm","clk":"11541236997","pt":1719503666378,"mc":[{"id":"1.230180128","rc":[{"atb":[[11.5,0]],"id":69213654},{"atl":[[13,1]],"id":69213654},{"trd":[[11.5,7.14]],"ltp":11.5,"tv":7.14,"id":69213654}],"con":true,"img":false}]}
{"op":"mcm","clk":"11541237006","pt":1719503666476,"mc":[{"id":"1.230180128","rc":[{"atb":[[4,1]],"id":50639934},{"atl":[[13.5,1]],"id":69213654},{"atb":[[6.4,1.05]],"id":66050026}],"con":true,"img":false}]}
{"op":"mcm","clk":"11541237024","pt":1719503666638,"mc":[{"id":"1.230180128","rc":[{"atl":[[4.3,0]],"id":51218587}],"con":true,"img":false}]}
{"op":"mcm","clk":"11541237037","pt":1719503666736,"mc":[{"id":"1.230180128","rc":[{"atb":[[3.65,9.08]],"id":50639934},{"atl":[[10,4.09]],"id":50639934},{"atl":[[3.8,1.84]],"id":51218587},{"atb":[[5.1,7.1]],"id":69213654},{"atl":[[29,1.97]],"id":69213654}],"con":true,"img":false}]}
{"op":"mcm","clk":"11541237049","pt":1719503666948,"mc":[{"id":"1.230180128","rc":[{"atb":[[3.2,1.83]],"id":58821523},{"atb":[[3.7,1.69]],"id":50639934},{"atb":[[5.2,1.65]],"id":60237218},{"atb":[[2.44,2.53]],"id":51218587},{"atb":[[5.2,1.64]],"id":69213654}],"con":true,"img":false}]}
{"op":"mcm","clk":"11541237059","pt":1719503667046,"mc":[{"id":"1.230180128","rc":[{"atb":[[3.6,0],[3.75,9.09]],"id":50639934}],"con":true,"img":false}]}
{"op":"mcm","clk":"11541237095","pt":1719503667453,"mc":[{"id":"1.230180128","rc":[{"atb":[[2.42,0]],"id":51218587}],"con":true,"img":false}]}
{"op":"mcm","clk":"11541237106","pt":1719503667556,"mc":[{"id":"1.230180128","rc":[{"atb":[[3.8,8.11],[3.7,0]],"id":50639934},{"atb":[[2.44,0.84],[2.46,2]],"id":51218587},{"atb":[[5.2,7.65]],"id":69213654}],"con":true,"img":false}]}
{"op":"mcm","clk":"11541237116","pt":1719503667659,"mc":[{"id":"1.230180128","rc":[{"atb":[[3.8,9.8]],"id":50639934},{"atb":[[2.42,1.68]],"id":51218587}],"con":true,"img":false}]}
{"op":"mcm","clk":"11541237170","pt":1719503668277,"mc":[{"id":"1.230180128","rc":[{"atb":[[2.48,0.84]],"id":51218587},{"atb":[[5.3,5.63]],"id":69213654}],"con":true,"img":false}]}
{"op":"mcm","clk":"11541237179","pt":1719503668331,"mc":[{"id":"1.230180128","rc":[{"atb":[[5.3,11.83]],"id":69213654}],"con":true,"img":false}]}
{"op":"mcm","clk":"11541237194","pt":1719503668534,"mc":[{"id":"1.230180128","rc":[{"atb":[[1.09,1]],"id":69213654}],"con":true,"img":false}]}
{"op":"mcm","clk":"11541237213","pt":1719503668742,"mc":[{"id":"1.230180128","rc":[{"atb":[[2.42,0],[2.38,10.1]],"id":51218587},{"atb":[[1.09,0.23],[5.2,6.01]],"id":69213654}],"con":true,"img":false}]}
{"op":"mcm","clk":"11541237223","pt":1719503668843,"mc":[{"id":"1.230180128","rc":[{"atb":[[2.46,0]],"id":51218587},{"atb":[[5.4,1.64]],"id":69213654}],"con":true,"img":false}]}
{"op":"mcm","clk":"11541237231","pt":1719503668954,"mc":[{"id":"1.230180128","rc":[{"atb":[[2.44,2.84]],"id":51218587},{"atb":[[1.09,0]],"id":69213654}],"con":true,"img":false}]}
{"op":"mcm","clk":"11541237238","pt":1719503669052,"mc":[{"id":"1.230180128","rc":[{"atb":[[5.4,1.87]],"id":69213654}],"con":true,"img":false}]}
{"op":"mcm","clk":"11541237250","pt":1719503669156,"mc":[{"id":"1.230180128","rc":[{"atb":[[5.4,7.42]],"id":69213654}],"con":true,"img":false}]}
{"op":"mcm","clk":"11541237257","pt":1719503669257,"mc":[{"id":"1.230180128","rc":[{"atb":[[2.48,0]],"id":51218587},{"atb":[[5.4,8.83]],"id":69213654}],"con":true,"img":false}]}
{"op":"mcm","clk":"11541237267","pt":1719503669358,"mc":[{"id":"1.230180128","rc":[{"atb":[[2.46,1.68]],"id":51218587},{"atb":[[5.3,7.04]],"id":69213654}],"con":true,"img":false}]}
{"op":"mcm","clk":"11541237280","pt":1719503669564,"mc":[{"id":"1.230180128","rc":[{"atb":[[5.5,4.61]],"id":69213654}],"con":true,"img":false}]}
{"op":"mcm","clk":"11541237297","pt":1719503669772,"mc":[{"id":"1.230180128","rc":[{"atb":[[2.44,0.84]],"id":51218587}],"con":true,"img":false}]}
{"op":"mcm","clk":"11541237307","pt":1719503669874,"mc":[{"id":"1.230180128","rc":[{"atb":[[2.48,2]],"id":51218587}],"con":true,"img":false}]}
{"op":"mcm","clk":"11541237315","pt":1719503669983,"mc":[{"id":"1.230180128","rc":[{"atb":[[2.46,0]],"id":51218587},{"atb":[[5.4,7.19]],"id":69213654}],"con":true,"img":false}]}
{"op":"mcm","clk":"11541237324","pt":1719503670031,"mc":[{"id":"1.230180128","rc":[{"atb":[[2.42,1.68]],"id":51218587},{"atl":[[3.85,0]],"id":51218587},{"atb":[[5.6,1.64],[5.1,1.54]],"id":69213654}],"con":true,"img":false}]}
{"op":"mcm","clk":"11541237343","pt":1719503670235,"mc":[{"id":"1.230180128","rc":[{"atb":[[2.44,0]],"id":51218587},{"atb":[[5.3,6.2],[5.5,10]],"id":69213654}],"con":true,"img":false}]}
{"op":"mcm","clk":"11541237379","pt":1719503670646,"mc":[{"id":"1.230180128","rc":[{"atb":[[5.5,5.39]],"id":69213654}],"con":true,"img":false}]}
{"op":"mcm","clk":"11541237395","pt":1719503670853,"mc":[{"id":"1.230180128","rc":[{"atb":[[2.48,0]],"id":51218587},{"atl":[[3.8,0.84]],"id":51218587},{"atb":[[5.2,0]],"id":69213654}],"con":true,"img":false}]}
{"op":"mcm","clk":"11541237402","pt":1719503670953,"mc":[{"id":"1.230180128","rc":[{"atb":[[2.44,2]],"id":51218587},{"atl":[[4.3,1]],"id":51218587},{"atb":[[5.6,7.28]],"id":69213654}],"con":true,"img":false}]}
{"op":"mcm","clk":"11541237435","pt":1719503671366,"mc":[{"id":"1.230180128","rc":[{"atl":[[3.8,0]],"id":51218587},{"atb":[[5.7,4.45]],"id":69213654}],"con":true,"img":false}]}
{"op":"mcm","clk":"11541237481","pt":1719503671883,"mc":[{"id":"1.230180128","rc":[{"atb":[[5.6,5.64]],"id":69213654}],"con":true,"img":false}]}
{"op":"mcm","clk":"11541237491","pt":1719503671938,"mc":[{"id":"1.230180128","rc":[{"atb":[[5.8,1.64],[5.3,0]],"id":69213654}],"con":true,"img":false}]}
{"op":"mcm","clk":"11541237501","pt":1719503672046,"mc":[{"id":"1.230180128","rc":[{"atl":[[3.85,2]],"id":51218587},{"atb":[[5.7,9.75]],"id":69213654}],"con":true,"img":false}]}
{"op":"mcm","clk":"11541237535","pt":1719503672454,"mc":[{"id":"1.230180128","rc":[{"atb":[[5.7,5.3]],"id":69213654}],"con":true,"img":false}]}
{"op":"mcm","clk":"11541237553","pt":1719503672663,"mc":[{"id":"1.230180128","rc":[{"atl":[[4.3,0]],"id":51218587}],"con":true,"img":false}]}
{"op":"mcm","clk":"11541237564","pt":1719503672766,"mc":[{"id":"1.230180128","rc":[{"atl":[[3.8,1]],"id":51218587}],"con":true,"img":false}]}
{"op":"mcm","clk":"11541237580","pt":1719503672866,"mc":[{"id":"1.230180128","rc":[{"spn":7.3,"spf":"NaN","id":50639934},{"atl":[[3.8,1.84]],"id":51218587},{"spn":9.4,"spf":"NaN","id":69213654},{"spn":14.2,"spf":"NaN","id":66050026}],"con":true,"img":false}]}
{"op":"mcm","clk":"11541237621","pt":1719503673176,"mc":[{"id":"1.230180128","rc":[{"atb":[[5,0]],"id":69213654}],"con":true,"img":false}]}
{"op":"mcm","clk":"11541237636","pt":1719503673281,"mc":[{"id":"1.230180128","rc":[{"atl":[[3.85,0]],"id":51218587}],"con":true,"img":false}]}
{"op":"mcm","clk":"11541237721","pt":1719503674156,"mc":[{"id":"1.230180128","rc":[{"atl":[[3.8,0.84]],"id":51218587}],"con":true,"img":false}]}
{"op":"mcm","clk":"11541237734","pt":1719503674259,"mc":[{"id":"1.230180128","rc":[{"atl":[[4.3,1]],"id":51218587}],"con":true,"img":false}]}
{"op":"mcm","clk":"11541237800","pt":1719503674873,"mc":[{"id":"1.230180128","rc":[{"atl":[[3.8,0]],"id":51218587}],"con":true,"img":false}]}
{"op":"mcm","clk":"11541237844","pt":1719503675342,"mc":[{"id":"1.230180128","rc":[{"atb":[[2.46,0.84]],"id":51218587}],"con":true,"img":false}]}
{"op":"mcm","clk":"11541237893","pt":1719503675959,"mc":[{"id":"1.230180128","rc":[{"atb":[[2.42,0]],"id":51218587}],"con":true,"img":false}]}
{"op":"mcm","clk":"11541237900","pt":1719503676063,"mc":[{"id":"1.230180128","rc":[{"atb":[[2.46,2.53]],"id":51218587},{"atl":[[13.5,0]],"id":69213654}],"con":true,"img":false}]}
{"op":"mcm","clk":"11541237943","pt":1719503676576,"mc":[{"id":"1.230180128","rc":[{"atb":[[2.46,0.84]],"id":51218587}],"con":true,"img":false}]}
{"op":"mcm","clk":"11541237954","pt":1719503676683,"mc":[{"id":"1.230180128","rc":[{"atb":[[2.42,1.68]],"id":51218587}],"con":true,"img":false}]}
{"op":"mcm","clk":"11541237978","pt":1719503676938,"mc":[{"id":"1.230180128","rc":[{"atb":[[2.44,0]],"id":51218587}],"con":true,"img":false}]}
{"op":"mcm","clk":"11541237990","pt":1719503677039,"mc":[{"id":"1.230180128","rc":[{"atb":[[2.48,2]],"id":51218587}],"con":true,"img":false}]}
{"op":"mcm","clk":"11541238002","pt":1719503677246,"mc":[{"id":"1.230180128","rc":[{"atb":[[2.46,0]],"id":51218587}],"con":true,"img":false}]}
{"op":"mcm","clk":"11541238075","pt":1719503677863,"mc":[{"id":"1.230180128","rc":[{"atb":[[2.38,6.94]],"id":51218587}],"con":true,"img":false}]}
{"op":"mcm","clk":"11541238086","pt":1719503677963,"mc":[{"id":"1.230180128","rc":[{"atb":[[2.4,1.61]],"id":51218587}],"con":true,"img":false}]}
{"op":"mcm","clk":"11541238117","pt":1719503678282,"mc":[{"id":"1.230180128","rc":[{"atb":[[2.18,0]],"id":69213654}],"con":true,"img":false}]}
{"op":"mcm","clk":"11541238130","pt":1719503678375,"mc":[{"id":"1.230180128","rc":[{"atb":[[2.42,0]],"id":51218587}],"con":true,"img":false}]}
{"op":"mcm","clk":"11541238143","pt":1719503678480,"mc":[{"id":"1.230180128","rc":[{"atb":[[2.4,3.29]],"id":51218587}],"con":true,"img":false}]}
{"op":"mcm","clk":"11541238155","pt":1719503678582,"mc":[{"id":"1.230180128","rc":[{"atl":[[9.6,0]],"id":50639934}],"con":true,"img":false}]}
{"op":"mcm","clk":"11541238166","pt":1719503678685,"mc":[{"id":"1.230180128","rc":[{"atb":[[2.4,6.45],[2.48,0]],"id":51218587}],"con":true,"img":false}]}
{"op":"mcm","clk":"11541238182","pt":1719503678789,"mc":[{"id":"1.230180128","rc":[{"atb":[[2.42,2]],"id":51218587}],"con":true,"img":false}]}
{"op":"mcm","clk":"11541238214","pt":1719503679050,"mc":[{"id":"1.230180128","rc":[{"atl":[[1000,0.29]],"id":50639934}],"con":true,"img":false}]}
{"op":"mcm","clk":"11541238225","pt":1719503679152,"mc":[{"id":"1.230180128","rc":[{"atl":[[3.85,2]],"id":51218587}],"con":true,"img":false}]}
{"op":"mcm","clk":"11541238237","pt":1719503679254,"mc":[{"id":"1.230180128","rc":[{"atl":[[1000,0.17]],"id":50639934}],"con":true,"img":false}]}
{"op":"mcm","clk":"11541238244","pt":1719503679363,"mc":[{"id":"1.230180128","rc":[{"atl":[[9.6,0.12]],"id":50639934}],"con":true,"img":false}]}
{"op":"mcm","clk":"11541238313","pt":1719503679868,"mc":[{"id":"1.230180128","rc":[{"atl":[[8,0]],"id":58821523},{"atl":[[3.8,0.84]],"id":51218587}],"con":true,"img":false}]}
{"op":"mcm","clk":"11541238341","pt":1719503680176,"mc":[{"id":"1.230180128","rc":[{"atl":[[4.3,0]],"id":51218587}],"con":true,"img":false}]}
{"op":"mcm","clk":"11541238352","pt":1719503680280,"mc":[{"id":"1.230180128","rc":[{"atb":[[3.2,4.17]],"id":58821523},{"atb":[[3.85,1.95]],"id":50639934},{"atl":[[3.8,1.84]],"id":51218587}],"con":true,"img":false}]}
{"op":"mcm","clk":"11541238365","pt":1719503680381,"mc":[{"id":"1.230180128","rc":[{"atb":[[3.9,9.09]],"id":50639934}],"con":true,"img":false}]}
{"op":"mcm","clk":"11541238372","pt":1719503680484,"mc":[{"id":"1.230180128","rc":[{"atb":[[3.75,0]],"id":50639934}],"con":true,"img":false}]}
{"op":"mcm","clk":"11541238394","pt":1719503680693,"mc":[{"id":"1.230180128","rc":[{"atl":[[3.85,0]],"id":51218587}],"con":true,"img":false}]}
{"op":"mcm","clk":"11541238413","pt":1719503680897,"mc":[{"id":"1.230180128","rc":[{"atl":[[1000,0.14]],"id":58821523},{"atb":[[3.8,8.11],[3.95,9.32]],"id":50639934}],"con":true,"img":false}]}
{"op":"mcm","clk":"11541238428","pt":1719503680957,"mc":[{"id":"1.230180128","rc":[{"atb":[[3.95,11.01]],"id":50639934}],"con":true,"img":false}]}
{"op":"mcm","clk":"11541238447","pt":1719503681157,"mc":[{"id":"1.230180128","rc":[{"atl":[[1000,0]],"id":58821523},{"atl":[[3.8,0.84]],"id":51218587}],"con":true,"img":false}]}
{"op":"mcm","clk":"11541238457","pt":1719503681266,"mc":[{"id":"1.230180128","rc":[{"atl":[[8,0.14]],"id":58821523},{"atl":[[4.3,1]],"id":51218587}],"con":true,"img":false}]}
{"op":"mcm","clk":"11541238510","pt":1719503681772,"mc":[{"id":"1.230180128","rc":[{"atl":[[3.8,0]],"id":51218587}],"con":true,"img":false}]}
{"op":"mcm","clk":"11541238590","pt":1719503682755,"mc":[{"id":"1.230180128","rc":[{"atb":[[2.44,0.84]],"id":51218587}],"con":true,"img":false}]}
{"op":"mcm","clk":"11541238632","pt":1719503683165,"mc":[{"id":"1.230180128","rc":[{"atb":[[2.4,4.77]],"id":51218587}],"con":true,"img":false}]}
{"op":"mcm","clk":"11541238641","pt":1719503683269,"mc":[{"id":"1.230180128","rc":[{"atb":[[2.44,2.53]],"id":51218587}],"con":true,"img":false}]}
{"op":"mcm","clk":"11541238684","pt":1719503683755,"mc":[{"id":"1.230180128","rc":[{"atb":[[2.44,0.84]],"id":51218587}],"con":true,"img":false}]}
{"op":"mcm","clk":"11541238692","pt":1719503683857,"mc":[{"id":"1.230180128","rc":[{"atb":[[2.42,3.68]],"id":51218587}],"con":true,"img":false}]}
{"op":"mcm","clk":"11541238718","pt":1719503684168,"mc":[{"id":"1.230180128","rc":[{"atb":[[2.42,1.68]],"id":51218587},{"atb":[[5.4,6.96]],"id":69213654}],"con":true,"img":false}]}
{"op":"mcm","clk":"11541238727","pt":1719503684270,"mc":[{"id":"1.230180128","rc":[{"atb":[[2.46,2]],"id":51218587}],"con":true,"img":false}]}
{"op":"mcm","clk":"11541238737","pt":1719503684373,"mc":[{"id":"1.230180128","rc":[{"atb":[[1.1,1]],"id":69213654}],"con":true,"img":false}]}
{"op":"mcm","clk":"11541238745","pt":1719503684478,"mc":[{"id":"1.230180128","rc":[{"atb":[[1.1,0.2]],"id":69213654}],"con":true,"img":false}]}
{"op":"mcm","clk":"11541238754","pt":1719503684580,"mc":[{"id":"1.230180128","rc":[{"atb":[[1.1,0]],"id":69213654}],"con":true,"img":false}]}
{"op":"mcm","clk":"11541238764","pt":1719503684685,"mc":[{"id":"1.230180128","rc":[{"atb":[[5.9,0.2]],"id":69213654}],"con":true,"img":false}]}
{"op":"mcm","clk":"11541238795","pt":1719503684998,"mc":[{"id":"1.230180128","rc":[{"atb":[[5.9,4.5]],"id":69213654}],"con":true,"img":false}]}
{"op":"mcm","clk":"11541238822","pt":1719503685301,"mc":[{"id":"1.230180128","rc":[{"atb":[[6,0.84]],"id":69213654}],"con":true,"img":false}]}
{"op":"mcm","clk":"11541238838","pt":1719503685458,"mc":[{"id":"1.230180128","rc":[{"atb":[[2.46,0]],"id":51218587},{"atb":[[5.4,1.41]],"id":69213654}],"con":true,"img":false}]}
{"op":"mcm","clk":"11541238851","pt":1719503685563,"mc":[{"id":"1.230180128","rc":[{"atb":[[2.44,2.84]],"id":51218587},{"atb":[[5.8,0],[5.9,0.2]],"id":69213654}],"con":true,"img":false}]}
{"op":"mcm","clk":"11541238861","pt":1719503685662,"mc":[{"id":"1.230180128","rc":[{"atb":[[6,7.12]],"id":69213654}],"con":true,"img":false}]}
{"op":"mcm","clk":"11541238915","pt":1719503686187,"mc":[{"id":"1.230180128","rc":[{"atb":[[2.42,0]],"id":51218587},{"atb":[[6,5.48]],"id":69213654}],"con":true,"img":false}]}
{"op":"mcm","clk":"11541238924","pt":1719503686283,"mc":[{"id":"1.230180128","rc":[{"atb":[[2.46,1.68]],"id":51218587},{"atl":[[3.85,2]],"id":51218587},{"atb":[[6.2,4.09]],"id":69213654}],"con":true,"img":false}]}
{"op":"mcm","clk":"11541238974","pt":1719503686799,"mc":[{"id":"1.230180128","rc":[{"atb":[[6.4,1.64]],"id":69213654}],"con":true,"img":false}]}
{"op":"mcm","clk":"11541238987","pt":1719503686857,"mc":[{"id":"1.230180128","rc":[{"atb":[[3.6,11.12]],"id":69213654}],"con":true,"img":false}]}
{"op":"mcm","clk":"11541238998","pt":1719503686967,"mc":[{"id":"1.230180128","rc":[{"atb":[[2.44,0.84]],"id":51218587}],"con":true,"img":false}]}
{"op":"mcm","clk":"11541239016","pt":1719503687122,"mc":[{"id":"1.230180128","rc":[{"atb":[[2.48,2]],"id":51218587},{"atb":[[5.5,0]],"id":69213654}],"con":true,"img":false}]}
{"op":"mcm","clk":"11541239026","pt":1719503687164,"mc":[{"id":"1.230180128","rc":[{"atb":[[6.4,5.85],[6.2,0]],"id":69213654}],"con":true,"img":false}]}
{"op":"mcm","clk":"11541239038","pt":1719503687267,"mc":[{"id":"1.230180128","rc":[{"atl":[[3.8,0.84]],"id":51218587}],"con":true,"img":false}]}
{"op":"mcm","clk":"11541239051","pt":1719503687371,"mc":[{"id":"1.230180128","rc":[{"atb":[[2.46,0]],"id":51218587},{"atb":[[6.6,3.85]],"id":69213654}],"con":true,"img":false}]}
{"op":"mcm","clk":"11541239066","pt":1719503687475,"mc":[{"id":"1.230180128","rc":[{"atb":[[2.42,1.68]],"id":51218587}],"con":true,"img":false}]}
{"op":"mcm","clk":"11541239094","pt":1719503687781,"mc":[{"id":"1.230180128","rc":[{"atb":[[2.44,0]],"id":51218587},{"atb":[[6,4.64]],"id":69213654}],"con":true,"img":false}]}
{"op":"mcm","clk":"11541239103","pt":1719503687889,"mc":[{"id":"1.230180128","rc":[{"atb":[[5.6,0]],"id":69213654}],"con":true,"img":false}]}
{"op":"mcm","clk":"11541239114","pt":1719503687992,"mc":[{"id":"1.230180128","rc":[{"atb":[[6.4,4.21]],"id":69213654}],"con":true,"img":false}]}
{"op":"mcm","clk":"11541239126","pt":1719503688090,"mc":[{"id":"1.230180128","rc":[{"atb":[[6.8,1.64],[6.6,7.99]],"id":69213654}],"con":true,"img":false}]}
{"op":"mcm","clk":"11541239154","pt":1719503688398,"mc":[{"id":"1.230180128","rc":[{"atb":[[2.48,0]],"id":51218587}],"con":true,"img":false}]}
{"op":"mcm","clk":"11541239164","pt":1719503688501,"mc":[{"id":"1.230180128","rc":[{"atb":[[2.44,2]],"id":51218587}],"con":true,"img":false}]}
{"op":"mcm","clk":"11541239176","pt":1719503688555,"mc":[{"id":"1.230180128","rc":[{"atb":[[3.2,4.05]],"id":58821523},{"atl":[[8.2,1.08]],"id":58821523},{"atb":[[3.65,8.98]],"id":50639934},{"atl":[[9.8,1]],"id":50639934},{"atb":[[6.4,1]],"id":66050026}],"con":true,"img":false}]}
{"op":"mcm","clk":"11541239187","pt":1719503688656,"mc":[{"id":"1.230180128","rc":[{"atb":[[7,0.71]],"id":60237218},{"atl":[[4.3,0]],"id":51218587},{"atb":[[6.6,4.14]],"id":69213654}],"con":true,"img":false}]}
{"op":"mcm","clk":"11541239193","pt":1719503688761,"mc":[{"id":"1.230180128","rc":[{"atl":[[3.8,1.84]],"id":51218587},{"atb":[[5.7,0]],"id":69213654}],"con":true,"img":false}]}
{"op":"mcm","clk":"11541239210","pt":1719503688966,"mc":[{"id":"1.230180128","rc":[{"atb":[[6.8,5.9]],"id":69213654}],"con":true,"img":false}]}
{"op":"mcm","clk":"11541239234","pt":1719503689279,"mc":[{"id":"1.230180128","rc":[{"atb":[[5.8,0.84]],"id":60237218}],"con":true,"img":false}]}
{"op":"mcm","clk":"11541239245","pt":1719503689377,"mc":[{"id":"1.230180128","rc":[{"atb":[[7,3.63]],"id":69213654}],"con":true,"img":false}]}
{"op":"mcm","clk":"11541239255","pt":1719503689483,"mc":[{"id":"1.230180128","rc":[{"atb":[[5.4,7],[5.1,0]],"id":60237218},{"atb":[[6,0]],"id":69213654}],"con":true,"img":false}]}
{"op":"mcm","clk":"11541239273","pt":1719503689685,"mc":[{"id":"1.230180128","rc":[{"atb":[[7,7.57]],"id":69213654}],"con":true,"img":false}]}
{"op":"mcm","clk":"11541239279","pt":1719503689800,"mc":[{"id":"1.230180128","rc":[{"atb":[[6.8,4.26]],"id":69213654}],"con":true,"img":false}]}
{"op":"mcm","clk":"11541239288","pt":1719503689892,"mc":[{"id":"1.230180128","rc":[{"atb":[[2.46,0.84]],"id":51218587},{"atb":[[7.2,1.64]],"id":69213654}],"con":true,"img":false}]}
{"op":"mcm","clk":"11541239350","pt":1719503690461,"mc":[{"id":"1.230180128","rc":[{"atb":[[7,3.94]],"id":69213654}],"con":true,"img":false}]}
{"op":"mcm","clk":"11541239370","pt":1719503690769,"mc":[{"id":"1.230180128","rc":[{"atl":[[8.2,0],[7.8,1.08]],"id":58821523}],"con":true,"img":false}]}
{"op":"mcm","clk":"11541239390","pt":1719503691081,"mc":[{"id":"1.230180128","rc":[{"atl":[[10.5,0.84],[9.4,0.89]],"id":50639934}],"con":true,"img":false}]}
{"op":"mcm","clk":"11541239413","pt":1719503691387,"mc":[{"id":"1.230180128","rc":[{"atl":[[7.8,0]],"id":58821523}],"con":true,"img":false}]}
{"op":"mcm","clk":"11541239423","pt":1719503691493,"mc":[{"id":"1.230180128","rc":[{"atl":[[10,3.09]],"id":50639934},{"atl":[[3.85,0]],"id":51218587}],"con":true,"img":false}]}
{"op":"mcm","clk":"11541239431","pt":1719503691595,"mc":[{"id":"1.230180128","rc":[{"atl":[[10.5,1.84]],"id":50639934}],"con":true,"img":false}]}
{"op":"mcm","clk":"11541239437","pt":1719503691697,"mc":[{"id":"1.230180128","rc":[{"atl":[[8.2,1.08]],"id":58821523},{"atl":[[9.4,0]],"id":50639934}],"con":true,"img":false}]}
{"op":"mcm","clk":"11541239444","pt":1719503691799,"mc":[{"id":"1.230180128","rc":[{"atl":[[10.5,1]],"id":50639934}],"con":true,"img":false}]}
{"op":"mcm","clk":"11541239458","pt":1719503692012,"mc":[{"id":"1.230180128","rc":[{"atl":[[9.6,1.01]],"id":50639934}],"con":true,"img":false}]}
{"op":"mcm","clk":"11541239511","pt":1719503692474,"mc":[{"id":"1.230180128","rc":[{"atl":[[10.5,0]],"id":50639934},{"atl":[[3.8,0.84]],"id":51218587}],"con":true,"img":false}]}
{"op":"mcm","clk":"11541239521","pt":1719503692578,"mc":[{"id":"1.230180128","rc":[{"atl":[[9.8,2]],"id":50639934},{"atl":[[4.3,1]],"id":51218587}],"con":true,"img":false}]}
{"op":"mcm","clk":"11541239552","pt":1719503692886,"mc":[{"id":"1.230180128","rc":[{"atl":[[3.8,0]],"id":51218587}],"con":true,"img":false}]}
{"op":"mcm","clk":"11541239595","pt":1719503693400,"mc":[{"id":"1.230180128","rc":[{"atb":[[7,0]],"id":60237218}],"con":true,"img":false}]}
{"op":"mcm","clk":"11541239615","pt":1719503693611,"mc":[{"id":"1.230180128","rc":[{"atl":[[9.6,3.65]],"id":50639934}],"con":true,"img":false}]}
{"op":"mcm","clk":"11541239626","pt":1719503693708,"mc":[{"id":"1.230180128","rc":[{"atl":[[3.85,2]],"id":51218587}],"con":true,"img":false}]}
{"op":"mcm","clk":"11541239634","pt":1719503693762,"mc":[{"id":"1.230180128","rc":[{"atl":[[9.4,2.7],[9.8,1]],"id":50639934}],"con":true,"img":false}]}
{"op":"mcm","clk":"11541239654","pt":1719503693967,"mc":[{"id":"1.230180128","rc":[{"atl":[[9.8,2]],"id":50639934}],"con":true,"img":false}]}
{"op":"mcm","clk":"11541239665","pt":1719503694070,"mc":[{"id":"1.230180128","rc":[{"atl":[[9.2,0.92]],"id":50639934}],"con":true,"img":false}]}
{"op":"mcm","clk":"11541239680","pt":1719503694281,"mc":[{"id":"1.230180128","rc":[{"atl":[[9.2,1.76],[9.8,1]],"id":50639934}],"con":true,"img":false}]}
{"op":"mcm","clk":"11541239690","pt":1719503694379,"mc":[{"id":"1.230180128","rc":[{"atl":[[9.4,0],[9.6,2.76]],"id":50639934},{"atl":[[3.8,0.84]],"id":51218587}],"con":true,"img":false}]}
{"op":"mcm","clk":"11541239698","pt":1719503694483,"mc":[{"id":"1.230180128","rc":[{"atl":[[9,1],[9.8,0]],"id":50639934},{"atl":[[4.3,0]],"id":51218587}],"con":true,"img":false}]}
{"op":"mcm","clk":"11541239703","pt":1719503694585,"mc":[{"id":"1.230180128","rc":[{"atl":[[9,3.81],[9.2,2.76],[9.6,2.64]],"id":50639934},{"atl":[[3.8,1.84]],"id":51218587}],"con":true,"img":false}]}
{"op":"mcm","clk":"11541239725","pt":1719503694791,"mc":[{"id":"1.230180128","rc":[{"atl":[[1000,0.29]],"id":50639934}],"con":true,"img":false}]}
{"op":"mcm","clk":"11541239755","pt":1719503695099,"mc":[{"id":"1.230180128","rc":[{"atl":[[1000,0.17]],"id":50639934},{"atl":[[3.85,0]],"id":51218587}],"con":true,"img":false}]}
{"op":"mcm","clk":"11541239768","pt":1719503695202,"mc":[{"id":"1.230180128","rc":[{"atl":[[9.4,0.12]],"id":50639934}],"con":true,"img":false}]}
{"op":"mcm","clk":"11541239778","pt":1719503695306,"mc":[{"id":"1.230180128","rc":[{"atb":[[3.1,4.14]],"id":50639934}],"con":true,"img":false}]}
{"op":"mcm","clk":"11541239799","pt":1719503695511,"mc":[{"id":"1.230180128","rc":[{"atl":[[11,0]],"id":50639934}],"con":true,"img":false}]}
{"op":"mcm","clk":"11541239838","pt":1719503695880,"mc":[{"id":"1.230180128","rc":[{"atb":[[2.38,6.58]],"id":51218587}],"con":true,"img":false}]}
{"op":"mcm","clk":"11541239850","pt":1719503695989,"mc":[{"id":"1.230180128","rc":[{"atb":[[2.38,7.08]],"id":51218587}],"con":true,"img":false}]}
{"op":"mcm","clk":"11541239910","pt":1719503696491,"mc":[{"id":"1.230180128","rc":[{"atl":[[8,0]],"id":58821523}],"con":true,"img":false}]}
{"op":"mcm","clk":"11541239944","pt":1719503696800,"mc":[{"id":"1.230180128","rc":[{"atl":[[1000,0.14]],"id":58821523}],"con":true,"img":false}]}
{"op":"mcm","clk":"11541239963","pt":1719503697006,"mc":[{"id":"1.230180128","rc":[{"atl":[[1000,0]],"id":58821523}],"con":true,"img":false}]}
{"op":"mcm","clk":"11541239974","pt":1719503697113,"mc":[{"id":"1.230180128","rc":[{"atl":[[8,0.14]],"id":58821523}],"con":true,"img":false}]}
{"op":"mcm","clk":"11541239986","pt":1719503697211,"mc":[{"id":"1.230180128","rc":[{"atl":[[1000,6.98]],"id":50639934}],"con":true,"img":false}]}
{"op":"mcm","clk":"11541239998","pt":1719503697315,"mc":[{"id":"1.230180128","rc":[{"atb":[[1.05,1.7],[1.04,3.4]],"id":50639934},{"atl":[[1000,3.63]],"id":50639934}],"con":true,"img":false}]}
{"op":"mcm","clk":"11541240010","pt":1719503697368,"mc":[{"id":"1.230180128","rc":[{"atl":[[1000,0.27]],"id":50639934}],"con":true,"img":false}]}
{"op":"mcm","clk":"11541240019","pt":1719503697472,"mc":[{"id":"1.230180128","rc":[{"atb":[[1.05,0.05],[1.04,0.12]],"id":50639934},{"atl":[[1000,0.22]],"id":50639934}],"con":true,"img":false}]}
{"op":"mcm","clk":"11541240032","pt":1719503697573,"mc":[{"id":"1.230180128","rc":[{"atl":[[1000,0.17],[8.8,0.04]],"id":50639934}],"con":true,"img":false}]}
{"op":"mcm","clk":"11541240043","pt":1719503697677,"mc":[{"id":"1.230180128","rc":[{"atb":[[1.05,0],[1.04,0]],"id":50639934},{"atl":[[8.8,0.09]],"id":50639934}],"con":true,"img":false}]}
{"op":"mcm","clk":"11541240053","pt":1719503697780,"mc":[{"id":"1.230180128","rc":[{"atb":[[4.1,0.18]],"id":50639934}],"con":true,"img":false}]}
{"op":"mcm","clk":"11541240182","pt":1719503699275,"mc":[{"id":"1.230180128","rc":[{"atb":[[5.7,2.02]],"id":60237218}],"con":true,"img":false}]}
{"op":"mcm","clk":"11541240222","pt":1719503699690,"mc":[{"id":"1.230180128","rc":[{"atl":[[9.2,1.76]],"id":50639934},{"atl":[[3.8,0.84]],"id":51218587}],"con":true,"img":false}]}
{"op":"mcm","clk":"11541240232","pt":1719503699791,"mc":[{"id":"1.230180128","rc":[{"atl":[[8.8,1.09]],"id":50639934},{"atl":[[4.3,1]],"id":51218587}],"con":true,"img":false}]}
{"op":"mcm","clk":"11541240239","pt":1719503699899,"mc":[{"id":"1.230180128","rc":[{"atl":[[9,2.81]],"id":50639934},{"atb":[[5.9,0]],"id":69213654}],"con":true,"img":false}]}
{"op":"mcm","clk":"11541240259","pt":1719503700104,"mc":[{"id":"1.230180128","rc":[{"atl":[[8.8,2.09]],"id":50639934}],"con":true,"img":false}]}
{"op":"mcm","clk":"11541240265","pt":1719503700210,"mc":[{"id":"1.230180128","rc":[{"atl":[[7.8,0.26]],"id":58821523},{"atl":[[8.6,0.26]],"id":50639934},{"atl":[[23,0.26]],"id":60237218},{"atl":[[3.75,0.26]],"id":51218587},{"atl":[[12.5,0.26]],"id":69213654},{"atl":[[21,0.26]],"id":66050026}],"con":true,"img":false}]}
{"op":"mcm","clk":"11541240277","pt":1719503700309,"mc":[{"id":"1.230180128","rc":[{"atl":[[9,0]],"id":50639934},{"atl":[[3.8,0]],"id":51218587},{"atl":[[140,0],[50,2]],"id":66050026}],"con":true,"img":false}]}
{"op":"mcm","clk":"11541240298","pt":1719503700514,"mc":[{"id":"1.230180128","rc":[{"atl":[[8.6,3.21]],"id":50639934}],"con":true,"img":false}]}
{"op":"mcm","clk":"11541240315","pt":1719503700719,"mc":[{"id":"1.230180128","rc":[{"atl":[[8.8,1.09]],"id":50639934},{"atl":[[3.85,2]],"id":51218587}],"con":true,"img":false}]}
{"op":"mcm","clk":"11541240329","pt":1719503700773,"mc":[{"id":"1.230180128","rc":[{"atl":[[8.8,0.09]],"id":50639934},{"atl":[[130,0]],"id":66050026}],"con":true,"img":false}]}
{"op":"mcm","clk":"11541240338","pt":1719503700879,"mc":[{"id":"1.230180128","rc":[{"atl":[[9.2,0.92],[8.4,2]],"id":50639934},{"atl":[[48,1]],"id":66050026}],"con":true,"img":false}]}
{"op":"mcm","clk":"11541240357","pt":1719503701087,"mc":[{"id":"1.230180128","rc":[{"atl":[[8.4,5.72]],"id":50639934}],"con":true,"img":false}]}
{"op":"mcm","clk":"11541240382","pt":1719503701292,"mc":[{"id":"1.230180128","rc":[{"atl":[[8.4,4.72],[8.6,0.26]],"id":50639934}],"con":true,"img":false}]}
{"op":"mcm","clk":"11541240392","pt":1719503701395,"mc":[{"id":"1.230180128","rc":[{"atb":[[2.24,0],[3.95,0.26]],"id":58821523},{"atb":[[5.1,0.26],[2.28,0]],"id":50639934},{"atl":[[8.2,0.84]],"id":50639934},{"atb":[[2.26,0],[5.9,0.26]],"id":60237218},{"atb":[[1.85,0],[2.48,0.26]],"id":51218587},{"atl":[[3.8,0.84]],"id":51218587},{"atb":[[7.4,0.26]],"id":69213654},{"atb":[[2.2,0],[6.6,0.26]],"id":66050026}],"con":true,"img":false}]}
{"op":"mcm","clk":"11541240400","pt":1719503701499,"mc":[{"id":"1.230180128","rc":[{"atl":[[8.2,4.94]],"id":50639934}],"con":true,"img":false}]}
{"op":"mcm","clk":"11541240410","pt":1719503701604,"mc":[{"id":"1.230180128","rc":[{"atb":[[2.52,0]],"id":58821523}],"con":true,"img":false}]}
{"op":"mcm","clk":"11541240429","pt":1719503701811,"mc":[{"id":"1.230180128","rc":[{"atl":[[8.4,3.72]],"id":50639934},{"atl":[[4.3,0]],"id":51218587},{"atb":[[7.4,1.1]],"id":69213654}],"con":true,"img":false}]}
{"op":"mcm","clk":"11541240438","pt":1719503701915,"mc":[{"id":"1.230180128","rc":[{"atl":[[8,1]],"id":50639934},{"atl":[[3.8,1.84]],"id":51218587},{"atb":[[6.4,0]],"id":69213654}],"con":true,"img":false}]}
{"op":"mcm","clk":"11541240446","pt":1719503701968,"mc":[{"id":"1.230180128","rc":[{"atl":[[3.85,0]],"id":51218587}],"con":true,"img":false}]}
{"op":"mcm","clk":"11541240454","pt":1719503702072,"mc":[{"id":"1.230180128","rc":[{"atl":[[10,3.61]],"id":58821523},{"atl":[[8.2,8.47]],"id":50639934},{"atb":[[7.4,4.65]],"id":69213654},{"atb":[[6,5.28]],"id":66050026},{"atl":[[48,1.51]],"id":66050026}],"con":true,"img":false}]}
{"op":"mcm","clk":"11541240461","pt":1719503702180,"mc":[{"id":"1.230180128","rc":[{"atb":[[5.1,0]],"id":50639934},{"atl":[[8.2,5.37]],"id":50639934},{"atb":[[2.44,0]],"id":51218587}],"con":true,"img":false}]}
{"op":"mcm","clk":"11541240473","pt":1719503702279,"mc":[{"id":"1.230180128","rc":[{"atl":[[8.2,4.37]],"id":50639934},{"atb":[[2.48,2.26]],"id":51218587}],"con":true,"img":false}]}
{"op":"mcm","clk":"11541240482","pt":1719503702383,"mc":[{"id":"1.230180128","rc":[{"atb":[[7.2,0],[7.6,3.34]],"id":69213654},{"atb":[[6.2,1.63]],"id":66050026}],"con":true,"img":false}]}
{"op":"mcm","clk":"11541240493","pt":1719503702485,"mc":[{"id":"1.230180128","rc":[{"atl":[[10,4.4]],"id":58821523},{"atl":[[8,2]],"id":50639934},{"atb":[[7.6,4.98]],"id":69213654}],"con":true,"img":false}]}
{"op":"mcm","clk":"11541240508","pt":1719503702693,"mc":[{"id":"1.230180128","rc":[{"atb":[[8,0.71]],"id":60237218},{"atb":[[6.6,0]],"id":69213654},{"atb":[[6.4,0]],"id":66050026}],"con":true,"img":false}]}
{"op":"mcm","clk":"11541240518","pt":1719503702794,"mc":[{"id":"1.230180128","rc":[{"atb":[[2.5,0.84]],"id":51218587},{"atl":[[3.8,0.84]],"id":51218587}],"con":true,"img":false}]}
{"op":"mcm","clk":"11541240527","pt":1719503702896,"mc":[{"id":"1.230180128","rc":[{"atl":[[4.3,1]],"id":51218587},{"atb":[[7.6,8.52]],"id":69213654},{"atb":[[6.4,4.77]],"id":66050026}],"con":true,"img":false}]}
{"op":"mcm","clk":"11541240538","pt":1719503703006,"mc":[{"id":"1.230180128","rc":[{"atb":[[2.42,0]],"id":51218587},{"atb":[[6.2,2.63]],"id":66050026}],"con":true,"img":false}]}
{"op":"mcm","clk":"11541240547","pt":1719503703101,"mc":[{"id":"1.230180128","rc":[{"atl":[[10,4.08]],"id":58821523},{"atl":[[7.8,3.25]],"id":50639934},{"atl":[[24,1.2]],"id":60237218}],"con":true,"img":false}]}
{"op":"mcm","clk":"11541240562","pt":1719503703310,"mc":[{"id":"1.230180128","rc":[{"atl":[[3.8,0]],"id":51218587},{"atb":[[5,6],[6.6,1.1]],"id":66050026}],"con":true,"img":false}]}
{"op":"mcm","clk":"11541240571","pt":1719503703413,"mc":[{"id":"1.230180128","rc":[{"atb":[[4.5,0.26]],"id":50639934},{"atb":[[5.8,6.6]],"id":60237218},{"atl":[[23,1.38]],"id":60237218}],"con":true,"img":false}]}
{"op":"mcm","clk":"11541240583","pt":1719503703618,"mc":[{"id":"1.230180128","rc":[{"atb":[[5.2,0]],"id":60237218},{"atb":[[6.2,1]],"id":66050026}],"con":true,"img":false}]}
{"op":"mcm","clk":"11541240592","pt":1719503703726,"mc":[{"id":"1.230180128","rc":[{"atb":[[5.9,1.91]],"id":60237218},{"atl":[[24,0.84],[1000,0.84]],"id":60237218},{"atb":[[2.48,0.26]],"id":51218587},{"atb":[[6.6,2.74]],"id":66050026}],"con":true,"img":false}]}
{"op":"mcm","clk":"11541240600","pt":1719503703774,"mc":[{"id":"1.230180128","rc":[{"atl":[[8,1],[8.2,3.53]],"id":50639934},{"atb":[[2.42,2]],"id":51218587}],"con":true,"img":false}]}
{"op":"mcm","clk":"11541240612","pt":1719503703879,"mc":[{"id":"1.230180128","rc":[{"atl":[[7.6,1]],"id":50639934}],"con":true,"img":false}]}
{"op":"mcm","clk":"11541240620","pt":1719503703987,"mc":[{"id":"1.230180128","rc":[{"atl":[[1000,0.38]],"id":60237218}],"con":true,"img":false}]}
{"op":"mcm","clk":"11541240644","pt":1719503704190,"mc":[{"id":"1.230180128","rc":[{"atl":[[7.8,0]],"id":50639934},{"atb":[[2.44,1.68]],"id":51218587}],"con":true,"img":false}]}
{"op":"mcm","clk":"11541240655","pt":1719503704292,"mc":[{"id":"1.230180128","rc":[{"atl":[[1000,0]],"id":60237218}],"con":true,"img":false}]}
{"op":"mcm","clk":"11541240666","pt":1719503704396,"mc":[{"id":"1.230180128","rc":[{"atb":[[6,8.89]],"id":60237218},{"atl":[[22,0.38]],"id":60237218},{"atb":[[2.5,0]],"id":51218587},{"atb":[[6.6,7.2]],"id":66050026}],"con":true,"img":false}]}
{"op":"mcm","clk":"11541240684","pt":1719503704602,"mc":[{"id":"1.230180128","rc":[{"atb":[[6.2,0]],"id":66050026}],"con":true,"img":false}]}
{"op":"mcm","clk":"11541240705","pt":1719503704812,"mc":[{"id":"1.230180128","rc":[{"atl":[[7.6,0]],"id":50639934},{"atb":[[5.9,0.26]],"id":60237218},{"atb":[[2.44,0]],"id":51218587},{"atb":[[6.8,1]],"id":66050026}],"con":true,"img":false}]}
{"op":"mcm","clk":"11541240716","pt":1719503704913,"mc":[{"id":"1.230180128","rc":[{"atl":[[8,2]],"id":50639934},{"atb":[[5.8,5.76],[6.2,1.65]],"id":60237218},{"atl":[[22,1.22]],"id":60237218},{"atb":[[2.42,3.68]],"id":51218587}],"con":true,"img":false}]}
{"op":"mcm","clk":"11541240731","pt":1719503705118,"mc":[{"id":"1.230180128","rc":[{"atb":[[6,4.66]],"id":60237218}],"con":true,"img":false}]}
{"op":"mcm","clk":"11541240739","pt":1719503705230,"mc":[{"id":"1.230180128","rc":[{"atb":[[6.4,4.21]],"id":60237218},{"atl":[[22,2.47]],"id":60237218}],"con":true,"img":false}]}
{"op":"mcm","clk":"11541240752","pt":1719503705275,"mc":[{"id":"1.230180128","rc":[{"atl":[[7.8,3.25]],"id":50639934},{"atb":[[2.46,0]],"id":51218587}],"con":true,"img":false}]}
{"op":"mcm","clk":"11541240761","pt":1719503705379,"mc":[{"id":"1.230180128","rc":[{"atb":[[6.2,0]],"id":60237218},{"atb":[[2.42,1.68]],"id":51218587}],"con":true,"img":false}]}
{"op":"mcm","clk":"11541240771","pt":1719503705480,"mc":[{"id":"1.230180128","rc":[{"atb":[[6.6,1.65]],"id":60237218},{"atb":[[2.48,2.26]],"id":51218587}],"con":true,"img":false}]}
{"op":"mcm","clk":"11541240802","pt":1719503705791,"mc":[{"id":"1.230180128","rc":[{"atl":[[8,1]],"id":50639934},{"atl":[[34,0]],"id":60237218}],"con":true,"img":false}]}
{"op":"mcm","clk":"11541240810","pt":1719503705896,"mc":[{"id":"1.230180128","rc":[{"atl":[[7.6,1]],"id":50639934},{"atl":[[21,1]],"id":60237218}],"con":true,"img":false}]}
{"op":"mcm","clk":"11541240820","pt":1719503706001,"mc":[{"id":"1.230180128","rc":[{"atb":[[2.42,0]],"id":51218587}],"con":true,"img":false}]}
{"op":"mcm","clk":"11541240829","pt":1719503706102,"mc":[{"id":"1.230180128","rc":[{"atb":[[6.8,4.73]],"id":60237218}],"con":true,"img":false}]}
{"op":"mcm","clk":"11541240837","pt":1719503706208,"mc":[{"id":"1.230180128","rc":[{"atl":[[3.75,0]],"id":51218587}],"con":true,"img":false}]}
{"op":"mcm","clk":"11541240864","pt":1719503706509,"mc":[{"id":"1.230180128","rc":[{"atl":[[7.8,0]],"id":50639934}],"con":true,"img":false}]}
{"op":"mcm","clk":"11541240873","pt":1719503706611,"mc":[{"id":"1.230180128","rc":[{"atb":[[6.6,0]],"id":60237218}],"con":true,"img":false}]}
{"op":"mcm","clk":"11541240884","pt":1719503706713,"mc":[{"id":"1.230180128","rc":[{"atb":[[7,5.28]],"id":60237218},{"atb":[[2.48,0.26]],"id":51218587}],"con":true,"img":false}]}
{"op":"mcm","clk":"11541240896","pt":1719503706831,"mc":[{"id":"1.230180128","rc":[{"atb":[[5.8,0]],"id":60237218},{"atb":[[2.42,2]],"id":51218587}],"con":true,"img":false}]}
{"op":"mcm","clk":"11541240905","pt":1719503706923,"mc":[{"id":"1.230180128","rc":[{"atb":[[7.2,4.26]],"id":60237218}],"con":true,"img":false}]}
