{"op":"mcm","clk":"11536380628","pt":1719425245554,"mc":[{"id":"1.230178308","marketDefinition":{"bspMarket":true,"turnInPlayEnabled":false,"persistenceEnabled":false,"marketBaseRate":5.0,"eventId":"33376062","eventTypeId":"4339","numberOfWinners":1,"bettingType":"ODDS","marketType":"WIN","marketTime":"2024-06-27T13:54:00.000Z","suspendTime":"2024-06-27T13:54:00.000Z","bspReconciled":false,"complete":true,"inPlay":false,"crossMatching":false,"runnersVoidable":false,"numberOfActiveRunners":6,"betDelay":0,"status":"OPEN","runners":[{"status":"ACTIVE","sortPriority":1,"id":39362025,"name":"1. Errill Merry"},{"status":"ACTIVE","sortPriority":2,"id":70218235,"name":"2. Boozed Jill"},{"status":"ACTIVE","sortPriority":3,"id":44798446,"name":"3. Fearmore Diva"},{"status":"ACTIVE","sortPriority":4,"id":48500723,"name":"4. Magical Legend"},{"status":"ACTIVE","sortPriority":5,"id":40953876,"name":"5. Coonough Chimes"},{"status":"ACTIVE","sortPriority":6,"id":55829870,"name":"6. Grumpy Cookie"}],"regulators":["MR_INT"],"venue":"Kinsley","countryCode":"GB","discountAllowed":false,"timezone":"Europe/London","openDate":"2024-06-27T13:36:00.000Z","version":5994643727,"name":"A6 462m","eventName":"Kinsley 27th Jun"},"rc":[],"con":true,"img":false}]}
{"op":"mcm","clk":"11536380881","pt":1719425247541,"mc":[{"id":"1.230178308","marketDefinition":{"bspMarket":true,"turnInPlayEnabled":false,"persistenceEnabled":false,"marketBaseRate":5.0,"eventId":"33376062","eventTypeId":"4339","numberOfWinners":1,"bettingType":"ODDS","marketType":"WIN","marketTime":"2024-06-27T13:54:00.000Z","suspendTime":"2024-06-27T13:54:00.000Z","bspReconciled":false,"complete":true,"inPlay":false,"crossMatching":false,"runnersVoidable":false,"numberOfActiveRunners":6,"betDelay":0,"status":"OPEN","runners":[{"status":"ACTIVE","sortPriority":1,"id":39362025,"name":"1. Errill Merry"},{"status":"ACTIVE","sortPriority":2,"id":70218235,"name":"2. Boozed Jill"},{"status":"ACTIVE","sortPriority":3,"id":44798446,"name":"3. Fearmore Diva"},{"status":"ACTIVE","sortPriority":4,"id":48500723,"name":"4. Magical Legend"},{"status":"ACTIVE","sortPriority":5,"id":40953876,"name":"5. Coonough Chimes"},{"status":"ACTIVE","sortPriority":6,"id":55829870,"name":"6. Grumpy Cookie"}],"regulators":["MR_INT"],"venue":"Kinsley","countryCode":"GB","discountAllowed":true,"timezone":"Europe/London","openDate":"2024-06-27T13:36:00.000Z","version":5994643727,"name":"A6 462m","eventName":"Kinsley 27th Jun"},"rc":[],"con":true,"img":false}]}
{"op":"mcm","clk":"11536614557","pt":1719428236107,"mc":[{"id":"1.230178308","rc":[{"atb":[[1.01,23.65]],"id":40953876},{"atl":[[990,0.84]],"id":40953876},{"spn":495.5,"spf":"NaN","id":40953876},{"atb":[[1.03,7.88]],"id":39362025},{"atl":[[1000,0.84]],"id":39362025},{"spn":500.51,"spf":"NaN","id":39362025},{"atb":[[1.03,7.88]],"id":48500723},{"atl":[[990,0.84]],"id":48500723},{"spn":495.51,"spf":"NaN","id":48500723},{"atb":[[1.01,23.65]],"id":44798446},{"atl":[[1000,0.84]],"id":44798446},{"spn":500.5,"spf":"NaN","id":44798446},{"atb":[[1.03,7.88]],"id":70218235},{"atl":[[990,0.84]],"id":70218235},{"spn":495.51,"spf":"NaN","id":70218235},{"atb":[[1.02,11.82]],"id":55829870},{"atl":[[1000,0.84]],"id":55829870},{"spn":500.51,"spf":"NaN","id":55829870}],"con":true,"img":false}]}
{"op":"mcm","clk":"11536836717","pt":1719431847445,"mc":[{"id":"1.230178308","rc":[{"atb":[[1.01,23.66]],"id":40953876},{"atl":[[990,0.22]],"id":40953876},{"atb":[[1.03,7.88]],"id":39362025},{"atl":[[1000,0.22]],"id":39362025},{"atb":[[1.03,7.88]],"id":48500723},{"atl":[[990,0.22]],"id":48500723},{"atb":[[1.01,23.66]],"id":44798446},{"atl":[[1000,0.22]],"id":44798446},{"atb":[[1.03,7.88]],"id":70218235},{"atl":[[990,0.22]],"id":70218235},{"atb":[[1.02,11.82]],"id":55829870},{"atl":[[1000,0.22]],"id":55829870}],"con":true,"img":false}]}
{"op":"mcm","clk":"11536862851","pt":1719432257864,"mc":[{"id":"1.230178308","rc":[{"spl":[[1.01,1]],"id":39362025},{"spn":1.03,"spf":1.0,"id":39362025}],"con":true,"img":false}]}
{"op":"mcm","clk":"11537232227","pt":1719437882514,"mc":[{"id":"1.230178308","marketDefinition":{"bspMarket":true,"turnInPlayEnabled":false,"persistenceEnabled":false,"marketBaseRate":5.0,"eventId":"33376062","eventTypeId":"4339","numberOfWinners":1,"bettingType":"ODDS","marketType":"WIN","marketTime":"2024-06-27T13:54:00.000Z","suspendTime":"2024-06-27T13:54:00.000Z","bspReconciled":false,"complete":true,"inPlay":false,"crossMatching":false,"runnersVoidable":false,"numberOfActiveRunners":6,"betDelay":0,"status":"OPEN","runners":[{"status":"ACTIVE","sortPriority":1,"id":39362025,"name":"1. Errill Merry"},{"status":"ACTIVE","sortPriority":2,"id":70218235,"name":"2. Boozed Jill"},{"status":"ACTIVE","sortPriority":3,"id":44798446,"name":"3. Fearmore Diva"},{"status":"ACTIVE","sortPriority":4,"id":48500723,"name":"4. Magical Legend"},{"status":"ACTIVE","sortPriority":5,"id":40953876,"name":"5. Coonough Chimes"},{"status":"ACTIVE","sortPriority":6,"id":55829870,"name":"6. Grumpy Cookie"}],"regulators":["MR_INT"],"venue":"Kinsley","countryCode":"GB","discountAllowed":true,"timezone":"Europe/London","openDate":"2024-06-27T13:36:00.000Z","version":5994643727,"name":"A6 462m","eventName":"Kinsley 27th Jun"},"rc":[{"atb":[[1.01,23.66]],"id":40953876},{"atl":[[990,0.22]],"id":40953876},{"spn":495.5,"spf":"NaN","id":40953876},{"spl":[[1.01,1]],"id":39362025},{"atb":[[1.03,7.88]],"id":39362025},{"atl":[[1000,0.22]],"id":39362025},{"spn":1.03,"spf":1.0,"id":39362025},{"atb":[[1.03,7.88]],"id":48500723},{"atl":[[990,0.22]],"id":48500723},{"spn":495.51,"spf":"NaN","id":48500723},{"atb":[[1.01,23.66]],"id":44798446},{"atl":[[1000,0.22]],"id":44798446},{"spn":500.5,"spf":"NaN","id":44798446},{"atb":[[1.03,7.88]],"id":70218235},{"atl":[[990,0.22]],"id":70218235},{"spn":495.51,"spf":"NaN","id":70218235},{"atb":[[1.02,11.82]],"id":55829870},{"atl":[[1000,0.22]],"id":55829870},{"spn":500.51,"spf":"NaN","id":55829870}],"con":true,"img":true}]}
{"op":"mcm","clk":"11537573354","pt":1719443282535,"mc":[{"id":"1.230178308","marketDefinition":{"bspMarket":true,"turnInPlayEnabled":false,"persistenceEnabled":false,"marketBaseRate":5.0,"eventId":"33376062","eventTypeId":"4339","numberOfWinners":1,"bettingType":"ODDS","marketType":"WIN","marketTime":"2024-06-27T13:54:00.000Z","suspendTime":"2024-06-27T13:54:00.000Z","bspReconciled":false,"complete":true,"inPlay":false,"crossMatching":false,"runnersVoidable":false,"numberOfActiveRunners":6,"betDelay":0,"status":"OPEN","runners":[{"status":"ACTIVE","sortPriority":1,"id":39362025,"name":"1. Errill Merry"},{"status":"ACTIVE","sortPriority":2,"id":70218235,"name":"2. Boozed Jill"},{"status":"ACTIVE","sortPriority":3,"id":44798446,"name":"3. Fearmore Diva"},{"status":"ACTIVE","sortPriority":4,"id":48500723,"name":"4. Magical Legend"},{"status":"ACTIVE","sortPriority":5,"id":40953876,"name":"5. Coonough Chimes"},{"status":"ACTIVE","sortPriority":6,"id":55829870,"name":"6. Grumpy Cookie"}],"regulators":["MR_INT"],"venue":"Kinsley","countryCode":"GB","discountAllowed":true,"timezone":"Europe/London","openDate":"2024-06-27T13:36:00.000Z","version":5994643727,"name":"A6 462m","eventName":"Kinsley 27th Jun"},"rc":[{"atb":[[1.01,23.66]],"id":40953876},{"atl":[[990,0.22]],"id":40953876},{"spn":495.5,"spf":"NaN","id":40953876},{"spl":[[1.01,1]],"id":39362025},{"atb":[[1.03,7.88]],"id":39362025},{"atl":[[1000,0.22]],"id":39362025},{"spn":1.03,"spf":1.0,"id":39362025},{"atb":[[1.03,7.88]],"id":48500723},{"atl":[[990,0.22]],"id":48500723},{"spn":495.51,"spf":"NaN","id":48500723},{"atb":[[1.01,23.66]],"id":44798446},{"atl":[[1000,0.22]],"id":44798446},{"spn":500.5,"spf":"NaN","id":44798446},{"atb":[[1.03,7.88]],"id":70218235},{"atl":[[990,0.22]],"id":70218235},{"spn":495.51,"spf":"NaN","id":70218235},{"atb":[[1.02,11.83]],"id":55829870},{"atl":[[1000,0.22]],"id":55829870},{"spn":500.51,"spf":"NaN","id":55829870}],"con":true,"img":true}]}
{"op":"mcm","clk":"11537954914","pt":1719448682555,"mc":[{"id":"1.230178308","marketDefinition":{"bspMarket":true,"turnInPlayEnabled":false,"persistenceEnabled":false,"marketBaseRate":5.0,"eventId":"33376062","eventTypeId":"4339","numberOfWinners":1,"bettingType":"ODDS","marketType":"WIN","marketTime":"2024-06-27T13:54:00.000Z","suspendTime":"2024-06-27T13:54:00.000Z","bspReconciled":false,"complete":true,"inPlay":false,"crossMatching":false,"runnersVoidable":false,"numberOfActiveRunners":6,"betDelay":0,"status":"OPEN","runners":[{"status":"ACTIVE","sortPriority":1,"id":39362025,"name":"1. Errill Merry"},{"status":"ACTIVE","sortPriority":2,"id":70218235,"name":"2. Boozed Jill"},{"status":"ACTIVE","sortPriority":3,"id":44798446,"name":"3. Fearmore Diva"},{"status":"ACTIVE","sortPriority":4,"id":48500723,"name":"4. Magical Legend"},{"status":"ACTIVE","sortPriority":5,"id":40953876,"name":"5. Coonough Chimes"},{"status":"ACTIVE","sortPriority":6,"id":55829870,"name":"6. Grumpy Cookie"}],"regulators":["MR_INT"],"venue":"Kinsley","countryCode":"GB","discountAllowed":true,"timezone":"Europe/London","openDate":"2024-06-27T13:36:00.000Z","version":5994643727,"name":"A6 462m","eventName":"Kinsley 27th Jun"},"rc":[{"atb":[[1.01,23.66]],"id":40953876},{"atl":[[990,0.22]],"id":40953876},{"spn":495.5,"spf":"NaN","id":40953876},{"spl":[[1.01,1]],"id":39362025},{"atb":[[1.03,7.88]],"id":39362025},{"atl":[[1000,0.22]],"id":39362025},{"spn":1.03,"spf":1.0,"id":39362025},{"atb":[[1.03,7.88]],"id":48500723},{"atl":[[990,0.22]],"id":48500723},{"spn":495.51,"spf":"NaN","id":48500723},{"atb":[[1.01,23.66]],"id":44798446},{"atl":[[1000,0.22]],"id":44798446},{"spn":500.5,"spf":"NaN","id":44798446},{"atb":[[1.03,7.88]],"id":70218235},{"atl":[[990,0.22]],"id":70218235},{"spn":495.51,"spf":"NaN","id":70218235},{"atb":[[1.02,11.82]],"id":55829870},{"atl":[[1000,0.22]],"id":55829870},{"spn":500.51,"spf":"NaN","id":55829870}],"con":true,"img":true}]}
{"op":"mcm","clk":"11538170577","pt":1719454082535,"mc":[{"id":"1.230178308","marketDefinition":{"bspMarket":true,"turnInPlayEnabled":false,"persistenceEnabled":false,"marketBaseRate":5.0,"eventId":"33376062","eventTypeId":"4339","numberOfWinners":1,"bettingType":"ODDS","marketType":"WIN","marketTime":"2024-06-27T13:54:00.000Z","suspendTime":"2024-06-27T13:54:00.000Z","bspReconciled":false,"complete":true,"inPlay":false,"crossMatching":false,"runnersVoidable":false,"numberOfActiveRunners":6,"betDelay":0,"status":"OPEN","runners":[{"status":"ACTIVE","sortPriority":1,"id":39362025,"name":"1. Errill Merry"},{"status":"ACTIVE","sortPriority":2,"id":70218235,"name":"2. Boozed Jill"},{"status":"ACTIVE","sortPriority":3,"id":44798446,"name":"3. Fearmore Diva"},{"status":"ACTIVE","sortPriority":4,"id":48500723,"name":"4. Magical Legend"},{"status":"ACTIVE","sortPriority":5,"id":40953876,"name":"5. Coonough Chimes"},{"status":"ACTIVE","sortPriority":6,"id":55829870,"name":"6. Grumpy Cookie"}],"regulators":["MR_INT"],"venue":"Kinsley","countryCode":"GB","discountAllowed":true,"timezone":"Europe/London","openDate":"2024-06-27T13:36:00.000Z","version":5994643727,"name":"A6 462m","eventName":"Kinsley 27th Jun"},"rc":[{"atb":[[1.01,23.67]],"id":40953876},{"atl":[[990,0.22]],"id":40953876},{"spn":495.5,"spf":"NaN","id":40953876},{"spl":[[1.01,1]],"id":39362025},{"atb":[[1.03,7.88]],"id":39362025},{"atl":[[1000,0.22]],"id":39362025},{"spn":1.03,"spf":1.0,"id":39362025},{"atb":[[1.03,7.88]],"id":48500723},{"atl":[[990,0.22]],"id":48500723},{"spn":495.51,"spf":"NaN","id":48500723},{"atb":[[1.01,23.67]],"id":44798446},{"atl":[[1000,0.22]],"id":44798446},{"spn":500.5,"spf":"NaN","id":44798446},{"atb":[[1.03,7.88]],"id":70218235},{"atl":[[990,0.22]],"id":70218235},{"spn":495.51,"spf":"NaN","id":70218235},{"atb":[[1.02,11.83]],"id":55829870},{"atl":[[1000,0.22]],"id":55829870},{"spn":500.51,"spf":"NaN","id":55829870}],"con":true,"img":true}]}
{"op":"mcm","clk":"11538368235","pt":1719459482563,"mc":[{"id":"1.230178308","marketDefinition":{"bspMarket":true,"turnInPlayEnabled":false,"persistenceEnabled":false,"marketBaseRate":5.0,"eventId":"33376062","eventTypeId":"4339","numberOfWinners":1,"bettingType":"ODDS","marketType":"WIN","marketTime":"2024-06-27T13:54:00.000Z","suspendTime":"2024-06-27T13:54:00.000Z","bspReconciled":false,"complete":true,"inPlay":false,"crossMatching":false,"runnersVoidable":false,"numberOfActiveRunners":6,"betDelay":0,"status":"OPEN","runners":[{"status":"ACTIVE","sortPriority":1,"id":39362025,"name":"1. Errill Merry"},{"status":"ACTIVE","sortPriority":2,"id":70218235,"name":"2. Boozed Jill"},{"status":"ACTIVE","sortPriority":3,"id":44798446,"name":"3. Fearmore Diva"},{"status":"ACTIVE","sortPriority":4,"id":48500723,"name":"4. Magical Legend"},{"status":"ACTIVE","sortPriority":5,"id":40953876,"name":"5. Coonough Chimes"},{"status":"ACTIVE","sortPriority":6,"id":55829870,"name":"6. Grumpy Cookie"}],"regulators":["MR_INT"],"venue":"Kinsley","countryCode":"GB","discountAllowed":true,"timezone":"Europe/London","openDate":"2024-06-27T13:36:00.000Z","version":5994643727,"name":"A6 462m","eventName":"Kinsley 27th Jun"},"rc":[{"atb":[[1.01,23.67]],"id":40953876},{"atl":[[990,0.22]],"id":40953876},{"spn":495.5,"spf":"NaN","id":40953876},{"spl":[[1.01,1]],"id":39362025},{"atb":[[1.03,7.88]],"id":39362025},{"atl":[[1000,0.22]],"id":39362025},{"spn":1.03,"spf":1.0,"id":39362025},{"atb":[[1.03,7.88]],"id":48500723},{"atl":[[990,0.22]],"id":48500723},{"spn":495.51,"spf":"NaN","id":48500723},{"atb":[[1.01,23.67]],"id":44798446},{"atl":[[1000,0.22]],"id":44798446},{"spn":500.5,"spf":"NaN","id":44798446},{"atb":[[1.03,7.88]],"id":70218235},{"atl":[[990,0.22]],"id":70218235},{"spn":495.51,"spf":"NaN","id":70218235},{"atb":[[1.02,11.83]],"id":55829870},{"atl":[[1000,0.22]],"id":55829870},{"spn":500.51,"spf":"NaN","id":55829870}],"con":true,"img":true}]}
{"op":"mcm","clk":"11538554268","pt":1719464050666,"mc":[{"id":"1.230178308","rc":[{"atb":[[1.01,23.67]],"id":40953876},{"atl":[[150,4]],"id":40953876},{"spn":75.5,"spf":"NaN","id":40953876},{"atb":[[1.03,7.88]],"id":39362025},{"atl":[[150,4]],"id":39362025},{"atb":[[1.03,7.88]],"id":48500723},{"atb":[[1.01,23.67]],"id":44798446},{"atl":[[150,4]],"id":44798446},{"spn":75.5,"spf":"NaN","id":44798446},{"atb":[[1.03,7.88]],"id":70218235},{"atl":[[150,4]],"id":70218235},{"spn":75.51,"spf":"NaN","id":70218235},{"atb":[[1.02,11.83]],"id":55829870},{"atl":[[150,4]],"id":55829870},{"spn":75.51,"spf":"NaN","id":55829870}],"con":true,"img":false}]}
{"op":"mcm","clk":"11538554274","pt":1719464050767,"mc":[{"id":"1.230178308","rc":[{"atl":[[150,4]],"id":48500723}],"con":true,"img":false}]}
{"op":"mcm","clk":"11538595361","pt":1719464882536,"mc":[{"id":"1.230178308","marketDefinition":{"bspMarket":true,"turnInPlayEnabled":false,"persistenceEnabled":false,"marketBaseRate":5.0,"eventId":"33376062","eventTypeId":"4339","numberOfWinners":1,"bettingType":"ODDS","marketType":"WIN","marketTime":"2024-06-27T13:54:00.000Z","suspendTime":"2024-06-27T13:54:00.000Z","bspReconciled":false,"complete":true,"inPlay":false,"crossMatching":false,"runnersVoidable":false,"numberOfActiveRunners":6,"betDelay":0,"status":"OPEN","runners":[{"status":"ACTIVE","sortPriority":1,"id":39362025,"name":"1. Errill Merry"},{"status":"ACTIVE","sortPriority":2,"id":70218235,"name":"2. Boozed Jill"},{"status":"ACTIVE","sortPriority":3,"id":44798446,"name":"3. Fearmore Diva"},{"status":"ACTIVE","sortPriority":4,"id":48500723,"name":"4. Magical Legend"},{"status":"ACTIVE","sortPriority":5,"id":40953876,"name":"5. Coonough Chimes"},{"status":"ACTIVE","sortPriority":6,"id":55829870,"name":"6. Grumpy Cookie"}],"regulators":["MR_INT"],"venue":"Kinsley","countryCode":"GB","discountAllowed":true,"timezone":"Europe/London","openDate":"2024-06-27T13:36:00.000Z","version":5994643727,"name":"A6 462m","eventName":"Kinsley 27th Jun"},"rc":[{"atb":[[1.01,23.67]],"id":40953876},{"atl":[[150,4],[990,0.22]],"id":40953876},{"spn":75.5,"spf":"NaN","id":40953876},{"spl":[[1.01,1]],"id":39362025},{"atb":[[1.03,7.88]],"id":39362025},{"atl":[[150,4],[1000,0.22]],"id":39362025},{"spn":1.03,"spf":1.0,"id":39362025},{"atb":[[1.03,7.88]],"id":48500723},{"atl":[[150,4],[990,0.22]],"id":48500723},{"spn":75.51,"spf":"NaN","id":48500723},{"atb":[[1.01,23.67]],"id":44798446},{"atl":[[150,4],[1000,0.22]],"id":44798446},{"spn":75.5,"spf":"NaN","id":44798446},{"atb":[[1.03,7.88]],"id":70218235},{"atl":[[150,4],[990,0.22]],"id":70218235},{"spn":75.51,"spf":"NaN","id":70218235},{"atb":[[1.02,11.83]],"id":55829870},{"atl":[[150,4],[1000,0.22]],"id":55829870},{"spn":75.51,"spf":"NaN","id":55829870}],"con":true,"img":true}]}
{"op":"mcm","clk":"11538748505","pt":1719468202601,"mc":[{"id":"1.230178308","rc":[{"atb":[[2,8.54],[1.01,23.67]],"id":40953876},{"spn":76.0,"spf":"NaN","id":40953876},{"atb":[[1.03,7.88],[2.08,8.88]],"id":39362025},{"spn":2.08,"spf":1.0,"id":39362025},{"atb":[[1.03,7.88],[2.08,13.32]],"id":48500723},{"spn":76.04,"spf":"NaN","id":48500723},{"atb":[[2,11.96],[1.01,23.67]],"id":44798446},{"spn":76.0,"spf":"NaN","id":44798446},{"atb":[[1.03,7.88],[2.06,13.2]],"id":70218235},{"spn":76.03,"spf":"NaN","id":70218235},{"atb":[[2.02,11.22],[1.02,11.83]],"id":55829870},{"spn":76.01,"spf":"NaN","id":55829870}],"con":true,"img":false}]}
{"op":"mcm","clk":"11538751174","pt":1719468256894,"mc":[{"id":"1.230178308","rc":[{"atb":[[2.08,3.16]],"id":70218235}],"con":true,"img":false}]}
{"op":"mcm","clk":"11538751184","pt":1719468257051,"mc":[{"id":"1.230178308","rc":[{"atb":[[2.1,3.16]],"id":39362025},{"atb":[[2.02,3.16]],"id":44798446}],"con":true,"img":false}]}
{"op":"mcm","clk":"11538751194","pt":1719468257253,"mc":[{"id":"1.230178308","rc":[{"atb":[[2.04,3.16]],"id":55829870}],"con":true,"img":false}]}
{"op":"mcm","clk":"11538751197","pt":1719468257354,"mc":[{"id":"1.230178308","rc":[{"atb":[[2.02,3.16]],"id":40953876}],"con":true,"img":false}]}
{"op":"mcm","clk":"11538751209","pt":1719468257560,"mc":[{"id":"1.230178308","rc":[{"atb":[[2.1,3.16]],"id":48500723}],"con":true,"img":false}]}
{"op":"mcm","clk":"11538752392","pt":1719468281752,"mc":[{"id":"1.230178308","marketDefinition":{"bspMarket":true,"turnInPlayEnabled":false,"persistenceEnabled":false,"marketBaseRate":5.0,"eventId":"33376062","eventTypeId":"4339","numberOfWinners":1,"bettingType":"ODDS","marketType":"WIN","marketTime":"2024-06-27T13:54:00.000Z","suspendTime":"2024-06-27T13:54:00.000Z","bspReconciled":false,"complete":true,"inPlay":false,"crossMatching":true,"runnersVoidable":false,"numberOfActiveRunners":6,"betDelay":0,"status":"OPEN","runners":[{"status":"ACTIVE","sortPriority":1,"id":39362025,"name":"1. Errill Merry"},{"status":"ACTIVE","sortPriority":2,"id":70218235,"name":"2. Boozed Jill"},{"status":"ACTIVE","sortPriority":3,"id":44798446,"name":"3. Fearmore Diva"},{"status":"ACTIVE","sortPriority":4,"id":48500723,"name":"4. Magical Legend"},{"status":"ACTIVE","sortPriority":5,"id":40953876,"name":"5. Coonough Chimes"},{"status":"ACTIVE","sortPriority":6,"id":55829870,"name":"6. Grumpy Cookie"}],"regulators":["MR_INT"],"venue":"Kinsley","countryCode":"GB","discountAllowed":true,"timezone":"Europe/London","openDate":"2024-06-27T13:36:00.000Z","version":5994643727,"name":"A6 462m","eventName":"Kinsley 27th Jun"},"rc":[],"con":true,"img":false}]}
{"op":"mcm","clk":"11538753374","pt":1719468299733,"mc":[{"id":"1.230178308","rc":[{"spn":76.01,"spf":"NaN","id":40953876},{"atb":[[2.1,6.55]],"id":39362025},{"spn":2.1,"spf":1.0,"id":39362025},{"spn":76.05,"spf":"NaN","id":48500723},{"spn":76.01,"spf":"NaN","id":44798446},{"spn":76.04,"spf":"NaN","id":70218235},{"spn":76.02,"spf":"NaN","id":55829870}],"con":true,"img":false}]}
{"op":"mcm","clk":"11538753414","pt":1719468300305,"mc":[{"id":"1.230178308","rc":[{"atb":[[2.08,6.55]],"id":70218235}],"con":true,"img":false}]}
{"op":"mcm","clk":"11538753424","pt":1719468300505,"mc":[{"id":"1.230178308","rc":[{"atb":[[2.02,6.55]],"id":44798446}],"con":true,"img":false}]}
{"op":"mcm","clk":"11538753443","pt":1719468300815,"mc":[{"id":"1.230178308","rc":[{"atb":[[2.1,6.55]],"id":48500723}],"con":true,"img":false}]}
{"op":"mcm","clk":"11538753471","pt":1719468301494,"mc":[{"id":"1.230178308","rc":[{"atb":[[2.02,6.55]],"id":40953876}],"con":true,"img":false}]}
{"op":"mcm","clk":"11538753479","pt":1719468301644,"mc":[{"id":"1.230178308","rc":[{"atb":[[2.04,6.55]],"id":55829870}],"con":true,"img":false}]}
{"op":"mcm","clk":"11538940377","pt":1719472107576,"mc":[{"id":"1.230178308","rc":[{"atb":[[2,0],[2.02,6.54],[1.01,23.65]],"id":40953876},{"atl":[[990,0.22]],"id":40953876},{"atb":[[1.03,7.88],[2.1,6.54],[2.08,0]],"id":39362025},{"atl":[[1000,0.22]],"id":39362025},{"atb":[[1.03,7.88],[2.1,6.54],[2.08,0]],"id":48500723},{"atl":[[990,0.22]],"id":48500723},{"atb":[[2,0],[2.02,6.54],[1.01,23.65]],"id":44798446},{"atl":[[1000,0.22]],"id":44798446},{"atb":[[2.06,0],[1.03,7.88],[2.08,6.54]],"id":70218235},{"atl":[[990,0.22]],"id":70218235},{"atb":[[2.02,0],[2.04,6.54],[1.02,11.82]],"id":55829870},{"atl":[[1000,0.22]],"id":55829870}],"con":true,"img":false}]}
{"op":"mcm","clk":"11538940381","pt":1719472107677,"mc":[{"id":"1.230178308","rc":[{"atb":[[2.04,8.54]],"id":40953876},{"atb":[[2.12,8.88]],"id":39362025},{"atb":[[2.12,13.32]],"id":48500723},{"atb":[[2.04,11.95]],"id":44798446},{"atb":[[2.1,13.19]],"id":70218235},{"atb":[[2.06,11.21]],"id":55829870}],"con":true,"img":false}]}
{"op":"mcm","clk":"11538944420","pt":1719472172333,"mc":[{"id":"1.230178308","rc":[{"spn":76.02,"spf":"NaN","id":40953876},{"spn":2.12,"spf":1.0,"id":39362025},{"atb":[[2.1,3.38]],"id":48500723},{"spn":76.06,"spf":"NaN","id":48500723},{"spn":76.02,"spf":"NaN","id":44798446},{"spn":76.05,"spf":"NaN","id":70218235},{"spn":76.03,"spf":"NaN","id":55829870}],"con":true,"img":false}]}
{"op":"mcm","clk":"11538944436","pt":1719472172640,"mc":[{"id":"1.230178308","rc":[{"atb":[[2.02,3.38]],"id":44798446}],"con":true,"img":false}]}
{"op":"mcm","clk":"11538944466","pt":1719472173049,"mc":[{"id":"1.230178308","rc":[{"atb":[[2.08,3.38]],"id":70218235}],"con":true,"img":false}]}
{"op":"mcm","clk":"11538944553","pt":1719472174328,"mc":[{"id":"1.230178308","rc":[{"atb":[[2.1,3.38]],"id":39362025}],"con":true,"img":false}]}
{"op":"mcm","clk":"11538944581","pt":1719472174839,"mc":[{"id":"1.230178308","rc":[{"atb":[[2.02,3.38]],"id":40953876}],"con":true,"img":false}]}
{"op":"mcm","clk":"11538944613","pt":1719472175453,"mc":[{"id":"1.230178308","rc":[{"atb":[[2.04,3.38]],"id":55829870}],"con":true,"img":false}]}
{"op":"mcm","clk":"11538944646","pt":1719472175960,"mc":[{"id":"1.230178308","rc":[{"atb":[[2.06,3.16]],"id":40953876}],"con":true,"img":false}]}
{"op":"mcm","clk":"11538944654","pt":1719472176164,"mc":[{"id":"1.230178308","rc":[{"atb":[[2.06,3.16]],"id":44798446},{"atb":[[2.12,3.16]],"id":70218235}],"con":true,"img":false}]}
{"op":"mcm","clk":"11538944681","pt":1719472176525,"mc":[{"id":"1.230178308","rc":[{"atb":[[2.14,3.16]],"id":39362025},{"atb":[[2.14,3.16]],"id":48500723}],"con":true,"img":false}]}
{"op":"mcm","clk":"11538944729","pt":1719472177244,"mc":[{"id":"1.230178308","rc":[{"atb":[[2.08,3.16]],"id":55829870}],"con":true,"img":false}]}
{"op":"mcm","clk":"11538946070","pt":1719472198982,"mc":[{"id":"1.230178308","rc":[{"atb":[[2.1,0]],"id":39362025},{"atb":[[2.08,0]],"id":70218235}],"con":true,"img":false}]}
{"op":"mcm","clk":"11538946099","pt":1719472199392,"mc":[{"id":"1.230178308","rc":[{"atb":[[2.02,0]],"id":44798446}],"con":true,"img":false}]}
{"op":"mcm","clk":"11538946121","pt":1719472199700,"mc":[{"id":"1.230178308","rc":[{"atb":[[2.1,0]],"id":48500723}],"con":true,"img":false}]}
{"op":"mcm","clk":"11538946206","pt":1719472201198,"mc":[{"id":"1.230178308","rc":[{"atb":[[2.02,0]],"id":40953876}],"con":true,"img":false}]}
{"op":"mcm","clk":"11538946288","pt":1719472202687,"mc":[{"id":"1.230178308","rc":[{"atb":[[2.04,0]],"id":55829870}],"con":true,"img":false}]}
{"op":"mcm","clk":"11538946911","pt":1719472212911,"mc":[{"id":"1.230178308","rc":[{"atb":[[2.14,6.54]],"id":39362025}],"con":true,"img":false}]}
{"op":"mcm","clk":"11538946969","pt":1719472213985,"mc":[{"id":"1.230178308","rc":[{"atb":[[2.12,6.54]],"id":70218235}],"con":true,"img":false}]}
{"op":"mcm","clk":"11538946992","pt":1719472214394,"mc":[{"id":"1.230178308","rc":[{"atb":[[2.06,6.54]],"id":44798446}],"con":true,"img":false}]}
{"op":"mcm","clk":"11538947049","pt":1719472215517,"mc":[{"id":"1.230178308","rc":[{"atb":[[2.14,6.54]],"id":48500723}],"con":true,"img":false}]}
{"op":"mcm","clk":"11538947424","pt":1719472222138,"mc":[{"id":"1.230178308","rc":[{"atb":[[2.06,6.54]],"id":40953876}],"con":true,"img":false}]}
{"op":"mcm","clk":"11538948075","pt":1719472233111,"mc":[{"id":"1.230178308","rc":[{"spn":76.03,"spf":"NaN","id":40953876},{"spn":2.14,"spf":1.0,"id":39362025},{"spn":76.07,"spf":"NaN","id":48500723},{"spn":76.03,"spf":"NaN","id":44798446},{"spn":76.06,"spf":"NaN","id":70218235},{"atb":[[2.08,6.54]],"id":55829870},{"spn":76.04,"spf":"NaN","id":55829870}],"con":true,"img":false}]}
{"op":"mcm","clk":"11539078903","pt":1719474873957,"mc":[{"id":"1.230178308","rc":[{"atb":[[2.14,2]],"id":70218235},{"spn":76.07,"spf":"NaN","id":70218235}],"con":true,"img":false}]}
{"op":"mcm","clk":"11539122508","pt":1719475682543,"mc":[{"id":"1.230178308","marketDefinition":{"bspMarket":true,"turnInPlayEnabled":false,"persistenceEnabled":false,"marketBaseRate":5.0,"eventId":"33376062","eventTypeId":"4339","numberOfWinners":1,"bettingType":"ODDS","marketType":"WIN","marketTime":"2024-06-27T13:54:00.000Z","suspendTime":"2024-06-27T13:54:00.000Z","bspReconciled":false,"complete":true,"inPlay":false,"crossMatching":true,"runnersVoidable":false,"numberOfActiveRunners":6,"betDelay":0,"status":"OPEN","runners":[{"status":"ACTIVE","sortPriority":1,"id":39362025,"name":"1. Errill Merry"},{"status":"ACTIVE","sortPriority":2,"id":70218235,"name":"2. Boozed Jill"},{"status":"ACTIVE","sortPriority":3,"id":44798446,"name":"3. Fearmore Diva"},{"status":"ACTIVE","sortPriority":4,"id":48500723,"name":"4. Magical Legend"},{"status":"ACTIVE","sortPriority":5,"id":40953876,"name":"5. Coonough Chimes"},{"status":"ACTIVE","sortPriority":6,"id":55829870,"name":"6. Grumpy Cookie"}],"regulators":["MR_INT"],"venue":"Kinsley","countryCode":"GB","discountAllowed":true,"timezone":"Europe/London","openDate":"2024-06-27T13:36:00.000Z","version":5994643727,"name":"A6 462m","eventName":"Kinsley 27th Jun"},"rc":[{"atb":[[1.01,23.66],[2.06,6.55],[2.04,8.54]],"id":40953876},{"atl":[[150,4],[990,0.22]],"id":40953876},{"spn":76.03,"spf":"NaN","id":40953876},{"spl":[[1.01,1]],"id":39362025},{"atb":[[1.03,7.88],[2.12,8.88],[2.14,6.55]],"id":39362025},{"atl":[[150,4],[1000,0.22]],"id":39362025},{"spn":2.14,"spf":1.0,"id":39362025},{"atb":[[1.03,7.88],[2.12,13.32],[2.14,6.55]],"id":48500723},{"atl":[[150,4],[990,0.22]],"id":48500723},{"spn":76.07,"spf":"NaN","id":48500723},{"atb":[[1.01,23.66],[2.06,6.55],[2.04,11.96]],"id":44798446},{"atl":[[150,4],[1000,0.22]],"id":44798446},{"spn":76.03,"spf":"NaN","id":44798446},{"atb":[[1.03,7.88],[2.12,6.55],[2.14,2],[2.1,13.19]],"id":70218235},{"atl":[[150,4],[990,0.22]],"id":70218235},{"spn":76.07,"spf":"NaN","id":70218235},{"atb":[[2.06,11.21],[1.02,11.82],[2.08,6.55]],"id":55829870},{"atl":[[150,4],[1000,0.22]],"id":55829870},{"spn":76.04,"spf":"NaN","id":55829870}],"con":true,"img":true}]}
{"op":"mcm","clk":"11539127699","pt":1719475707860,"mc":[{"id":"1.230178308","rc":[{"atb":[[1.01,23.66],[2.06,6.55],[2.04,0]],"id":40953876},{"atb":[[1.03,7.88],[2.12,0],[2.14,6.55]],"id":39362025},{"atb":[[1.03,7.88],[2.12,0],[2.14,6.55]],"id":48500723},{"atb":[[1.01,23.66],[2.06,6.55],[2.04,0]],"id":44798446},{"atb":[[1.03,7.88],[2.12,6.55],[2.1,0]],"id":70218235},{"atb":[[2.06,0],[1.02,11.82],[2.08,6.55]],"id":55829870}],"con":true,"img":false}]}
{"op":"mcm","clk":"11539127705","pt":1719475707966,"mc":[{"id":"1.230178308","rc":[{"atb":[[2.08,8.54]],"id":40953876},{"atb":[[2.16,8.88]],"id":39362025},{"atb":[[2.16,13.32]],"id":48500723},{"atb":[[2.08,11.96]],"id":44798446},{"atb":[[2.14,15.19]],"id":70218235},{"atb":[[2.1,11.21]],"id":55829870}],"con":true,"img":false}]}
{"op":"mcm","clk":"11539128816","pt":1719475724296,"mc":[{"id":"1.230178308","rc":[{"atb":[[2.14,3.38]],"id":48500723}],"con":true,"img":false}]}
{"op":"mcm","clk":"11539128833","pt":1719475724502,"mc":[{"id":"1.230178308","rc":[{"atb":[[2.12,3.38]],"id":70218235}],"con":true,"img":false}]}
{"op":"mcm","clk":"11539128851","pt":1719475724811,"mc":[{"id":"1.230178308","rc":[{"atb":[[2.06,3.38]],"id":44798446},{"atb":[[2.08,3.38]],"id":55829870}],"con":true,"img":false}]}
{"op":"mcm","clk":"11539128903","pt":1719475725629,"mc":[{"id":"1.230178308","rc":[{"atb":[[2.14,3.38]],"id":39362025}],"con":true,"img":false}]}
{"op":"mcm","clk":"11539128916","pt":1719475725832,"mc":[{"id":"1.230178308","rc":[{"atb":[[2.06,3.38]],"id":40953876},{"atb":[[2.16,3.16]],"id":70218235}],"con":true,"img":false}]}
{"op":"mcm","clk":"11539128926","pt":1719475726036,"mc":[{"id":"1.230178308","rc":[{"atb":[[2.12,3.16]],"id":55829870}],"con":true,"img":false}]}
{"op":"mcm","clk":"11539128955","pt":1719475726402,"mc":[{"id":"1.230178308","rc":[{"atb":[[2.1,3.16]],"id":44798446}],"con":true,"img":false}]}
{"op":"mcm","clk":"11539128979","pt":1719475726812,"mc":[{"id":"1.230178308","rc":[{"atb":[[2.1,3.16]],"id":40953876},{"atb":[[2.18,3.16]],"id":39362025}],"con":true,"img":false}]}
{"op":"mcm","clk":"11539129019","pt":1719475727426,"mc":[{"id":"1.230178308","rc":[{"atb":[[2.18,3.16]],"id":48500723}],"con":true,"img":false}]}
{"op":"mcm","clk":"11539136009","pt":1719475836310,"mc":[{"id":"1.230178308","rc":[{"spn":76.05,"spf":"NaN","id":40953876},{"atb":[[2.14,0]],"id":39362025},{"spn":2.18,"spf":1.0,"id":39362025},{"atb":[[2.14,0]],"id":48500723},{"spn":76.09,"spf":"NaN","id":48500723},{"spn":76.05,"spf":"NaN","id":44798446},{"spn":76.08,"spf":"NaN","id":70218235},{"spn":76.06,"spf":"NaN","id":55829870}],"con":true,"img":false}]}
{"op":"mcm","clk":"11539136030","pt":1719475836716,"mc":[{"id":"1.230178308","rc":[{"atb":[[2.06,0]],"id":44798446}],"con":true,"img":false}]}
{"op":"mcm","clk":"11539136036","pt":1719475836767,"mc":[{"id":"1.230178308","rc":[{"atb":[[2.12,0]],"id":70218235}],"con":true,"img":false}]}
{"op":"mcm","clk":"11539136060","pt":1719475837030,"mc":[{"id":"1.230178308","rc":[{"atb":[[2.06,0]],"id":40953876},{"atb":[[2.08,0]],"id":55829870}],"con":true,"img":false}]}
{"op":"mcm","clk":"11539136097","pt":1719475837753,"mc":[{"id":"1.230178308","rc":[{"atb":[[2.18,6.55]],"id":39362025}],"con":true,"img":false}]}
{"op":"mcm","clk":"11539136163","pt":1719475838831,"mc":[{"id":"1.230178308","rc":[{"atb":[[2.1,6.55]],"id":44798446}],"con":true,"img":false}]}
{"op":"mcm","clk":"11539136230","pt":1719475839962,"mc":[{"id":"1.230178308","rc":[{"atb":[[2.12,6.55]],"id":55829870}],"con":true,"img":false}]}
{"op":"mcm","clk":"11539136285","pt":1719475840833,"mc":[{"id":"1.230178308","rc":[{"atb":[[2.16,6.55]],"id":70218235}],"con":true,"img":false}]}
{"op":"mcm","clk":"11539136304","pt":1719475841140,"mc":[{"id":"1.230178308","rc":[{"atb":[[2.18,6.55]],"id":48500723}],"con":true,"img":false}]}
{"op":"mcm","clk":"11539136336","pt":1719475841652,"mc":[{"id":"1.230178308","rc":[{"atb":[[2.1,6.55]],"id":40953876}],"con":true,"img":false}]}
{"op":"mcm","clk":"11539288927","pt":1719478458587,"mc":[{"id":"1.230178308","rc":[{"atl":[[32,8]],"id":40953876},{"spn":17.05,"spf":"NaN","id":40953876},{"atl":[[46,12]],"id":39362025},{"atl":[[32,8]],"id":44798446},{"spn":17.05,"spf":"NaN","id":44798446}],"con":true,"img":false}]}
{"op":"mcm","clk":"11539288935","pt":1719478458687,"mc":[{"id":"1.230178308","rc":[{"atl":[[55,12]],"id":40953876},{"atl":[[27,8]],"id":39362025},{"atl":[[55,12]],"id":44798446},{"atl":[[42,12],[25,8]],"id":55829870}],"con":true,"img":false}]}
{"op":"mcm","clk":"11539341174","pt":1719479306838,"mc":[{"id":"1.230178308","rc":[{"atb":[[1.01,23.66],[2.1,6.54],[2.08,0]],"id":40953876},{"atb":[[1.03,7.88],[2.18,6.54],[2.16,0]],"id":39362025},{"atb":[[1.03,7.88],[2.18,6.54],[2.16,0]],"id":48500723},{"atb":[[1.01,23.66],[2.1,6.54],[2.08,0]],"id":44798446},{"atb":[[1.03,7.88],[2.16,6.54],[2.14,2]],"id":70218235},{"atb":[[1.02,11.82],[2.12,6.54],[2.1,0]],"id":55829870},{"spn":13.56,"spf":"NaN","id":55829870}],"con":true,"img":false}]}
{"op":"mcm","clk":"11539341177","pt":1719479306938,"mc":[{"id":"1.230178308","rc":[{"atb":[[2.12,8.54]],"id":40953876},{"atb":[[2.2,8.88]],"id":39362025},{"atb":[[2.2,13.32]],"id":48500723},{"atb":[[2.12,11.96]],"id":44798446},{"atb":[[2.18,13.19]],"id":70218235},{"atb":[[2.14,11.21]],"id":55829870}],"con":true,"img":false}]}
{"op":"mcm","clk":"11539347771","pt":1719479411382,"mc":[{"id":"1.230178308","rc":[{"spn":17.06,"spf":"NaN","id":40953876},{"spn":2.2,"spf":1.0,"id":39362025},{"spn":76.1,"spf":"NaN","id":48500723},{"spn":17.06,"spf":"NaN","id":44798446},{"atb":[[2.16,3.38]],"id":70218235},{"spn":76.09,"spf":"NaN","id":70218235},{"spn":13.57,"spf":"NaN","id":55829870}],"con":true,"img":false}]}
{"op":"mcm","clk":"11539347804","pt":1719479412006,"mc":[{"id":"1.230178308","rc":[{"atb":[[2.12,3.38]],"id":55829870}],"con":true,"img":false}]}
{"op":"mcm","clk":"11539347829","pt":1719479412314,"mc":[{"id":"1.230178308","rc":[{"atb":[[2.18,3.38]],"id":39362025}],"con":true,"img":false}]}
{"op":"mcm","clk":"11539347872","pt":1719479412880,"mc":[{"id":"1.230178308","rc":[{"atb":[[2.18,3.38]],"id":48500723}],"con":true,"img":false}]}
{"op":"mcm","clk":"11539347899","pt":1719479413401,"mc":[{"id":"1.230178308","rc":[{"atb":[[2.1,3.38]],"id":40953876}],"con":true,"img":false}]}
{"op":"mcm","clk":"11539347904","pt":1719479413501,"mc":[{"id":"1.230178308","rc":[{"atb":[[2.1,3.38]],"id":44798446}],"con":true,"img":false}]}
{"op":"mcm","clk":"11539350867","pt":1719479459271,"mc":[{"id":"1.230178308","rc":[{"atb":[[2.1,0]],"id":40953876},{"atb":[[2.18,0]],"id":39362025},{"atb":[[2.18,0]],"id":48500723},{"atb":[[2.1,0]],"id":44798446},{"atb":[[2.16,0]],"id":70218235},{"atb":[[2.12,0]],"id":55829870}],"con":true,"img":false}]}
{"op":"mcm","clk":"11539368678","pt":1719479719426,"mc":[{"id":"1.230178308","rc":[{"atb":[[2.22,3.16]],"id":39362025},{"spn":2.22,"spf":1.0,"id":39362025}],"con":true,"img":false}]}
{"op":"mcm","clk":"11539368782","pt":1719479720303,"mc":[{"id":"1.230178308","rc":[{"atb":[[2.22,3.16]],"id":48500723}],"con":true,"img":false}]}
{"op":"mcm","clk":"11539368806","pt":1719479720508,"mc":[{"id":"1.230178308","rc":[{"atb":[[2.2,3.16]],"id":70218235}],"con":true,"img":false}]}
{"op":"mcm","clk":"11539368824","pt":1719479720714,"mc":[{"id":"1.230178308","rc":[{"atb":[[2.16,3.16]],"id":55829870}],"con":true,"img":false}]}
{"op":"mcm","clk":"11539368845","pt":1719479720919,"mc":[{"id":"1.230178308","rc":[{"atb":[[2.14,3.16]],"id":44798446}],"con":true,"img":false}]}
{"op":"mcm","clk":"11539368881","pt":1719479721384,"mc":[{"id":"1.230178308","rc":[{"atb":[[2.14,3.16]],"id":40953876}],"con":true,"img":false}]}
{"op":"mcm","clk":"11539370316","pt":1719479740920,"mc":[{"id":"1.230178308","rc":[{"atb":[[2.14,6.54]],"id":44798446}],"con":true,"img":false}]}
{"op":"mcm","clk":"11539370353","pt":1719479741539,"mc":[{"id":"1.230178308","rc":[{"atb":[[2.22,6.54]],"id":39362025},{"atb":[[2.22,6.54]],"id":48500723}],"con":true,"img":false}]}
{"op":"mcm","clk":"11539370381","pt":1719479741810,"mc":[{"id":"1.230178308","rc":[{"atb":[[2.14,6.54]],"id":40953876},{"atb":[[2.16,6.54]],"id":55829870}],"con":true,"img":false}]}
{"op":"mcm","clk":"11539370410","pt":1719479742127,"mc":[{"id":"1.230178308","rc":[{"atb":[[2.2,6.54]],"id":70218235}],"con":true,"img":false}]}
{"op":"mcm","clk":"11539438484","pt":1719481082544,"mc":[{"id":"1.230178308","marketDefinition":{"bspMarket":true,"turnInPlayEnabled":false,"persistenceEnabled":false,"marketBaseRate":5.0,"eventId":"33376062","eventTypeId":"4339","numberOfWinners":1,"bettingType":"ODDS","marketType":"WIN","marketTime":"2024-06-27T13:54:00.000Z","suspendTime":"2024-06-27T13:54:00.000Z","bspReconciled":false,"complete":true,"inPlay":false,"crossMatching":true,"runnersVoidable":false,"numberOfActiveRunners":6,"betDelay":0,"status":"OPEN","runners":[{"status":"ACTIVE","sortPriority":1,"id":39362025,"name":"1. Errill Merry"},{"status":"ACTIVE","sortPriority":2,"id":70218235,"name":"2. Boozed Jill"},{"status":"ACTIVE","sortPriority":3,"id":44798446,"name":"3. Fearmore Diva"},{"status":"ACTIVE","sortPriority":4,"id":48500723,"name":"4. Magical Legend"},{"status":"ACTIVE","sortPriority":5,"id":40953876,"name":"5. Coonough Chimes"},{"status":"ACTIVE","sortPriority":6,"id":55829870,"name":"6. Grumpy Cookie"}],"regulators":["MR_INT"],"venue":"Kinsley","countryCode":"GB","discountAllowed":true,"timezone":"Europe/London","openDate":"2024-06-27T13:36:00.000Z","version":5994643727,"name":"A6 462m","eventName":"Kinsley 27th Jun"},"rc":[{"atb":[[1.01,23.66],[2.12,8.54],[2.14,6.54]],"id":40953876},{"atl":[[32,8],[150,4],[55,12],[990,0.22]],"id":40953876},{"spn":17.07,"spf":"NaN","id":40953876},{"spl":[[1.01,1]],"id":39362025},{"atb":[[1.03,7.88],[2.22,6.54],[2.2,8.88]],"id":39362025},{"atl":[[150,4],[46,12],[27,8],[1000,0.22]],"id":39362025},{"spn":2.22,"spf":1.0,"id":39362025},{"atb":[[1.03,7.88],[2.22,6.54],[2.2,13.32]],"id":48500723},{"atl":[[150,4],[990,0.22]],"id":48500723},{"spn":76.11,"spf":"NaN","id":48500723},{"atb":[[1.01,23.66],[2.12,11.96],[2.14,6.54]],"id":44798446},{"atl":[[32,8],[150,4],[55,12],[1000,0.22]],"id":44798446},{"spn":17.07,"spf":"NaN","id":44798446},{"atb":[[1.03,7.88],[2.18,13.19],[2.2,6.54],[2.14,2]],"id":70218235},{"atl":[[150,4],[990,0.22]],"id":70218235},{"spn":76.1,"spf":"NaN","id":70218235},{"atb":[[1.02,11.82],[2.16,6.54],[2.14,11.21]],"id":55829870},{"atl":[[150,4],[42,12],[25,8],[1000,0.22]],"id":55829870},{"spn":13.58,"spf":"NaN","id":55829870}],"con":true,"img":true}]}
{"op":"mcm","clk":"11539512669","pt":1719482376473,"mc":[{"id":"1.230178308","rc":[{"atb":[[8,2]],"id":40953876},{"spn":20.0,"spf":"NaN","id":40953876},{"atb":[[8,2]],"id":39362025},{"spn":8.0,"spf":1.0,"id":39362025},{"atb":[[4.3,2]],"id":48500723},{"spn":77.15,"spf":"NaN","id":48500723},{"atb":[[2.72,2]],"id":44798446},{"spn":17.36,"spf":"NaN","id":44798446},{"atb":[[7,2]],"id":70218235},{"spn":78.5,"spf":"NaN","id":70218235},{"atb":[[8,2]],"id":55829870},{"spn":16.5,"spf":"NaN","id":55829870}],"con":true,"img":false}]}
{"op":"mcm","clk":"11539513354","pt":1719482386592,"mc":[{"id":"1.230178308","rc":[{"atb":[[2.14,3.38]],"id":40953876},{"atb":[[2.22,3.38]],"id":39362025},{"atb":[[2.16,3.38]],"id":55829870}],"con":true,"img":false}]}
{"op":"mcm","clk":"11539545022","pt":1719482904748,"mc":[{"id":"1.230178308","rc":[{"atb":[[1.01,23.65],[2.12,0],[2.14,3.38]],"id":40953876},{"atb":[[1.03,7.88],[2.22,3.38],[2.2,0]],"id":39362025},{"atb":[[1.03,7.88],[2.22,6.54],[2.2,0]],"id":48500723},{"atb":[[1.01,23.65],[2.12,0],[2.14,6.54]],"id":44798446},{"atb":[[1.03,7.88],[2.18,0],[2.2,6.54]],"id":70218235},{"atb":[[1.02,11.82],[2.16,3.38],[2.14,0]],"id":55829870}],"con":true,"img":false}]}
{"op":"mcm","clk":"11539545028","pt":1719482904852,"mc":[{"id":"1.230178308","rc":[{"atb":[[2.16,8.54]],"id":40953876},{"atb":[[2.24,8.88]],"id":39362025},{"atb":[[2.24,13.32]],"id":48500723},{"atb":[[2.16,11.95]],"id":44798446},{"atb":[[2.22,13.19]],"id":70218235},{"atb":[[2.18,11.21]],"id":55829870}],"con":true,"img":false}]}
{"op":"mcm","clk":"11539545513","pt":1719482911572,"mc":[{"id":"1.230178308","rc":[{"atb":[[2.14,3.38]],"id":44798446}],"con":true,"img":false}]}
{"op":"mcm","clk":"11539545554","pt":1719482912307,"mc":[{"id":"1.230178308","rc":[{"atb":[[2.2,3.38]],"id":70218235}],"con":true,"img":false}]}
{"op":"mcm","clk":"11539545759","pt":1719482914890,"mc":[{"id":"1.230178308","rc":[{"atb":[[2.22,3.38]],"id":48500723}],"con":true,"img":false}]}
{"op":"mcm","clk":"11539545836","pt":1719482915973,"mc":[{"id":"1.230178308","rc":[{"atb":[[2.24,3.16]],"id":70218235}],"con":true,"img":false}]}
{"op":"mcm","clk":"11539545863","pt":1719482916282,"mc":[{"id":"1.230178308","rc":[{"atb":[[2.18,3.16]],"id":44798446}],"con":true,"img":false}]}
{"op":"mcm","clk":"11539545976","pt":1719482917673,"mc":[{"id":"1.230178308","rc":[{"atb":[[2.26,3.16]],"id":48500723}],"con":true,"img":false}]}
{"op":"mcm","clk":"11539550569","pt":1719482989464,"mc":[{"id":"1.230178308","rc":[{"atb":[[2.22,0]],"id":39362025}],"con":true,"img":false}]}
{"op":"mcm","clk":"11539550608","pt":1719482990136,"mc":[{"id":"1.230178308","rc":[{"atb":[[2.22,0]],"id":48500723}],"con":true,"img":false}]}
{"op":"mcm","clk":"11539550625","pt":1719482990445,"mc":[{"id":"1.230178308","rc":[{"atb":[[2.14,0]],"id":44798446},{"atb":[[2.16,0]],"id":55829870}],"con":true,"img":false}]}
{"op":"mcm","clk":"11539550660","pt":1719482990858,"mc":[{"id":"1.230178308","rc":[{"atb":[[2.14,0]],"id":40953876}],"con":true,"img":false}]}
{"op":"mcm","clk":"11539550751","pt":1719482992063,"mc":[{"id":"1.230178308","rc":[{"atb":[[2.26,3.38]],"id":39362025}],"con":true,"img":false}]}
{"op":"mcm","clk":"11539550810","pt":1719482993068,"mc":[{"id":"1.230178308","rc":[{"atb":[[2.2,0]],"id":70218235}],"con":true,"img":false}]}
{"op":"mcm","clk":"11539550825","pt":1719482993376,"mc":[{"id":"1.230178308","rc":[{"atb":[[2.26,6.54]],"id":48500723}],"con":true,"img":false}]}
{"op":"mcm","clk":"11539550830","pt":1719482993482,"mc":[{"id":"1.230178308","rc":[{"atb":[[2.18,6.54]],"id":44798446}],"con":true,"img":false}]}
{"op":"mcm","clk":"11539550839","pt":1719482993643,"mc":[{"id":"1.230178308","rc":[{"atb":[[2.2,3.38]],"id":55829870}],"con":true,"img":false}]}
{"op":"mcm","clk":"11539550845","pt":1719482993746,"mc":[{"id":"1.230178308","rc":[{"atb":[[2.18,3.38]],"id":40953876}],"con":true,"img":false}]}
{"op":"mcm","clk":"11539551237","pt":1719482999980,"mc":[{"id":"1.230178308","rc":[{"atb":[[2.24,6.54]],"id":70218235}],"con":true,"img":false}]}
{"op":"mcm","clk":"11539575045","pt":1719483351269,"mc":[{"id":"1.230178308","rc":[{"atb":[[1.51,196.08]],"id":40953876},{"atb":[[2.02,30.3],[1.51,196.08]],"id":39362025},{"atb":[[1.51,196.08]],"id":48500723},{"atb":[[1.51,196.08]],"id":70218235},{"atb":[[1.51,196.08]],"id":55829870}],"con":true,"img":false}]}
{"op":"mcm","clk":"11539575053","pt":1719483351370,"mc":[{"id":"1.230178308","rc":[{"atb":[[2.02,30.3]],"id":40953876},{"atb":[[2.02,30.3]],"id":55829870}],"con":true,"img":false}]}
{"op":"mcm","clk":"11539617344","pt":1719483886137,"mc":[{"id":"1.230178308","rc":[{"spl":[[1.01,1.71]],"id":39362025}],"con":true,"img":false}]}
{"op":"mcm","clk":"11539656912","pt":1719484451141,"mc":[{"id":"1.230178308","rc":[{"atb":[[3.3,6]],"id":40953876},{"atb":[[2.86,6]],"id":39362025},{"atb":[[3.75,6]],"id":48500723},{"atb":[[2.58,6]],"id":44798446},{"atb":[[4.1,6]],"id":70218235},{"atb":[[2.86,6]],"id":55829870}],"con":true,"img":false}]}
{"op":"mcm","clk":"11539657758","pt":1719484464066,"mc":[{"id":"1.230178308","rc":[{"atb":[[2.26,0]],"id":39362025}],"con":true,"img":false}]}
{"op":"mcm","clk":"11539657763","pt":1719484464169,"mc":[{"id":"1.230178308","rc":[{"atb":[[2.18,0]],"id":40953876},{"atb":[[2.26,3.16]],"id":48500723},{"atb":[[2.24,3.16]],"id":70218235}],"con":true,"img":false}]}
{"op":"mcm","clk":"11539657784","pt":1719484464478,"mc":[{"id":"1.230178308","rc":[{"atb":[[2.2,0]],"id":55829870}],"con":true,"img":false}]}
{"op":"mcm","clk":"11539657801","pt":1719484464739,"mc":[{"id":"1.230178308","rc":[{"atb":[[2.88,3.38]],"id":39362025}],"con":true,"img":false}]}
{"op":"mcm","clk":"11539657819","pt":1719484465049,"mc":[{"id":"1.230178308","rc":[{"atb":[[2.88,3.38]],"id":55829870}],"con":true,"img":false}]}
{"op":"mcm","clk":"11539658399","pt":1719484473686,"mc":[{"id":"1.230178308","rc":[{"atb":[[2.12,89.29]],"id":40953876},{"atb":[[2.12,89.29]],"id":70218235}],"con":true,"img":false}]}
{"op":"mcm","clk":"11539658668","pt":1719484477558,"mc":[{"id":"1.230178308","rc":[{"atb":[[2.26,0]],"id":48500723},{"atb":[[2.24,0]],"id":70218235}],"con":true,"img":false}]}
{"op":"mcm","clk":"11539810782","pt":1719486482531,"mc":[{"id":"1.230178308","marketDefinition":{"bspMarket":true,"turnInPlayEnabled":false,"persistenceEnabled":false,"marketBaseRate":5.0,"eventId":"33376062","eventTypeId":"4339","numberOfWinners":1,"bettingType":"ODDS","marketType":"WIN","marketTime":"2024-06-27T13:54:00.000Z","suspendTime":"2024-06-27T13:54:00.000Z","bspReconciled":false,"complete":true,"inPlay":false,"crossMatching":true,"runnersVoidable":false,"numberOfActiveRunners":6,"betDelay":0,"status":"OPEN","runners":[{"status":"ACTIVE","sortPriority":1,"id":39362025,"name":"1. Errill Merry"},{"status":"ACTIVE","sortPriority":2,"id":70218235,"name":"2. Boozed Jill"},{"status":"ACTIVE","sortPriority":3,"id":44798446,"name":"3. Fearmore Diva"},{"status":"ACTIVE","sortPriority":4,"id":48500723,"name":"4. Magical Legend"},{"status":"ACTIVE","sortPriority":5,"id":40953876,"name":"5. Coonough Chimes"},{"status":"ACTIVE","sortPriority":6,"id":55829870,"name":"6. Grumpy Cookie"}],"regulators":["MR_INT"],"venue":"Kinsley","countryCode":"GB","discountAllowed":true,"timezone":"Europe/London","openDate":"2024-06-27T13:36:00.000Z","version":5994643727,"name":"A6 462m","eventName":"Kinsley 27th Jun"},"rc":[{"atb":[[8,2],[2.02,30.3],[1.01,23.66],[2.12,89.29],[1.51,196.08],[3.3,6],[2.16,8.54]],"id":40953876},{"atl":[[32,8],[150,4],[55,12],[990,0.22]],"id":40953876},{"spn":20.0,"spf":"NaN","id":40953876},{"spl":[[1.01,1.71]],"id":39362025},{"atb":[[8,2],[2.24,8.88],[2.88,3.38],[2.02,30.3],[2.86,6],[1.03,7.88],[1.51,196.08]],"id":39362025},{"atl":[[150,4],[46,12],[27,8],[1000,0.22]],"id":39362025},{"spn":8.0,"spf":1.0,"id":39362025},{"atb":[[2.24,13.32],[4.3,2],[1.03,7.88],[1.51,196.08],[3.75,6]],"id":48500723},{"atl":[[150,4],[990,0.22]],"id":48500723},{"spn":77.15,"spf":"NaN","id":48500723},{"atb":[[2.72,2],[1.01,23.66],[2.18,6.54],[2.58,6],[2.16,11.96]],"id":44798446},{"atl":[[32,8],[150,4],[55,12],[1000,0.22]],"id":44798446},{"spn":17.36,"spf":"NaN","id":44798446},{"atb":[[1.03,7.88],[2.22,13.19],[4.1,6],[2.12,89.29],[1.51,196.08],[7,2],[2.14,2]],"id":70218235},{"atl":[[150,4],[990,0.22]],"id":70218235},{"spn":78.5,"spf":"NaN","id":70218235},{"atb":[[8,2],[2.88,3.38],[2.02,30.3],[2.86,6],[1.02,11.82],[2.18,11.21],[1.51,196.08]],"id":55829870},{"atl":[[150,4],[42,12],[25,8],[1000,0.22]],"id":55829870},{"spn":16.5,"spf":"NaN","id":55829870}],"con":true,"img":true}]}
{"op":"mcm","clk":"11539817045","pt":1719486503141,"mc":[{"id":"1.230178308","rc":[{"atb":[[1.01,23.66],[2.16,8.54]],"id":40953876},{"spl":[[1.01,1.71]],"id":39362025},{"atb":[[2.24,8.88],[2.88,3.38],[1.03,7.88]],"id":39362025},{"atb":[[2.24,13.32],[1.03,7.88]],"id":48500723},{"atb":[[1.01,23.66],[2.18,6.54],[2.16,0]],"id":44798446},{"atb":[[1.03,7.88],[2.22,13.19]],"id":70218235},{"atb":[[2.88,3.38],[1.02,11.82],[2.18,11.21]],"id":55829870}],"con":true,"img":false}]}
{"op":"mcm","clk":"11539817053","pt":1719486503245,"mc":[{"id":"1.230178308","rc":[{"atb":[[2.2,11.96]],"id":44798446}],"con":true,"img":false}]}
{"op":"mcm","clk":"11539820058","pt":1719486536966,"mc":[{"id":"1.230178308","rc":[{"atb":[[2.18,3.38]],"id":44798446}],"con":true,"img":false}]}
{"op":"mcm","clk":"11539820099","pt":1719486537591,"mc":[{"id":"1.230178308","rc":[{"atb":[[2.22,3.16]],"id":44798446}],"con":true,"img":false}]}
{"op":"mcm","clk":"11539826032","pt":1719486608440,"mc":[{"id":"1.230178308","rc":[{"atb":[[2.18,0]],"id":44798446}],"con":true,"img":false}]}
{"op":"mcm","clk":"11539826110","pt":1719486609323,"mc":[{"id":"1.230178308","rc":[{"atb":[[2.22,6.54]],"id":44798446}],"con":true,"img":false}]}
{"op":"mcm","clk":"11539840384","pt":1719486802731,"mc":[{"id":"1.230178308","rc":[{"atb":[[2.2,0]],"id":44798446}],"con":true,"img":false}]}
{"op":"mcm","clk":"11539840391","pt":1719486802834,"mc":[{"id":"1.230178308","rc":[{"atb":[[2.24,11.96]],"id":44798446}],"con":true,"img":false}]}
{"op":"mcm","clk":"11539841993","pt":1719486828649,"mc":[{"id":"1.230178308","rc":[{"atb":[[2.22,3.38]],"id":44798446}],"con":true,"img":false}]}
{"op":"mcm","clk":"11539843396","pt":1719486849199,"mc":[{"id":"1.230178308","rc":[{"atb":[[2.22,0]],"id":44798446}],"con":true,"img":false}]}
{"op":"mcm","clk":"11540014225","pt":1719488997405,"mc":[{"id":"1.230178308","rc":[{"atb":[[1.16,150]],"id":40953876},{"atl":[[560,2]],"id":40953876},{"atb":[[1.16,150]],"id":39362025},{"atl":[[370,2]],"id":39362025},{"atb":[[1.16,150]],"id":48500723},{"atl":[[270,2]],"id":48500723},{"atb":[[1.16,150]],"id":44798446},{"atl":[[550,2]],"id":44798446},{"atb":[[1.16,150]],"id":70218235},{"atl":[[390,2]],"id":70218235},{"atb":[[1.16,150]],"id":55829870},{"atl":[[500,2]],"id":55829870}],"con":true,"img":false}]}
{"op":"mcm","clk":"11540075596","pt":1719489753211,"mc":[{"id":"1.230178308","rc":[{"spl":[[1.01,1.71]],"id":39362025},{"atb":[[8,0]],"id":55829870},{"atl":[[8,3]],"id":55829870},{"trd":[[8,4]],"ltp":8.0,"tv":4.0,"id":55829870},{"spn":5.44,"spf":"NaN","id":55829870}],"con":true,"img":false}]}
{"op":"mcm","clk":"11540076238","pt":1719489760542,"mc":[{"id":"1.230178308","rc":[{"atb":[[2.26,3.16]],"id":44798446}],"con":true,"img":false}]}
{"op":"mcm","clk":"11540076531","pt":1719489764209,"mc":[{"id":"1.230178308","rc":[{"atb":[[2.26,6.54]],"id":44798446}],"con":true,"img":false}]}
{"op":"mcm","clk":"11540078296","pt":1719489784655,"mc":[{"id":"1.230178308","rc":[{"atb":[[2.9,6.24]],"id":39362025},{"atb":[[2.24,9.57]],"id":70218235}],"con":true,"img":false}]}
{"op":"mcm","clk":"11540078320","pt":1719489784862,"mc":[{"id":"1.230178308","rc":[{"atb":[[3.35,5.04]],"id":40953876},{"atb":[[2.2,9.88]],"id":55829870}],"con":true,"img":false}]}
{"op":"mcm","clk":"11540078339","pt":1719489785068,"mc":[{"id":"1.230178308","rc":[{"atb":[[2.26,9.41]],"id":48500723},{"atb":[[1.27,43.95]],"id":44798446}],"con":true,"img":false}]}
{"op":"mcm","clk":"11540078364","pt":1719489785329,"mc":[{"id":"1.230178308","rc":[{"atb":[[2.88,6.54]],"id":55829870}],"con":true,"img":false}]}
{"op":"mcm","clk":"11540080624","pt":1719489813995,"mc":[{"id":"1.230178308","rc":[{"atb":[[2.88,0]],"id":39362025}],"con":true,"img":false}]}
{"op":"mcm","clk":"11540080649","pt":1719489814463,"mc":[{"id":"1.230178308","rc":[{"atb":[[2.92,3.38]],"id":39362025}],"con":true,"img":false}]}
{"op":"mcm","clk":"11540083621","pt":1719489849317,"mc":[{"id":"1.230178308","rc":[{"atb":[[2.92,10.65]],"id":39362025}],"con":true,"img":false}]}
{"op":"mcm","clk":"11540083639","pt":1719489849522,"mc":[{"id":"1.230178308","rc":[{"atb":[[2.26,11.07]],"id":70218235}],"con":true,"img":false}]}
{"op":"mcm","clk":"11540083652","pt":1719489849629,"mc":[{"id":"1.230178308","rc":[{"atb":[[1.28,49.85]],"id":44798446}],"con":true,"img":false}]}
{"op":"mcm","clk":"11540083670","pt":1719489849833,"mc":[{"id":"1.230178308","rc":[{"atb":[[2.28,10.9]],"id":48500723}],"con":true,"img":false}]}
{"op":"mcm","clk":"11540083682","pt":1719489849937,"mc":[{"id":"1.230178308","rc":[{"atb":[[3.4,5.82]],"id":40953876}],"con":true,"img":false}]}
{"op":"mcm","clk":"11540083739","pt":1719489850510,"mc":[{"id":"1.230178308","rc":[{"atb":[[2.22,11.44]],"id":55829870}],"con":true,"img":false}]}
{"op":"mcm","clk":"11540084076","pt":1719489854238,"mc":[{"id":"1.230178308","rc":[{"atb":[[2.9,0]],"id":39362025}],"con":true,"img":false}]}
{"op":"mcm","clk":"11540086002","pt":1719489875235,"mc":[{"id":"1.230178308","rc":[{"atb":[[3.35,0]],"id":40953876},{"atb":[[2.26,0]],"id":48500723},{"atb":[[1.27,0]],"id":44798446},{"atb":[[2.24,0]],"id":70218235},{"atb":[[2.2,0]],"id":55829870}],"con":true,"img":false}]}
{"op":"mcm","clk":"11540086229","pt":1719489877632,"mc":[{"id":"1.230178308","rc":[{"atb":[[2.94,6.11]],"id":39362025}],"con":true,"img":false}]}
{"op":"mcm","clk":"11540086241","pt":1719489877736,"mc":[{"id":"1.230178308","rc":[{"atb":[[2.24,9.57]],"id":55829870}],"con":true,"img":false}]}
{"op":"mcm","clk":"11540086253","pt":1719489877838,"mc":[{"id":"1.230178308","rc":[{"atb":[[1.29,40.91]],"id":44798446}],"con":true,"img":false}]}
{"op":"mcm","clk":"11540086275","pt":1719489878045,"mc":[{"id":"1.230178308","rc":[{"atb":[[3.45,4.84]],"id":40953876}],"con":true,"img":false}]}
{"op":"mcm","clk":"11540086296","pt":1719489878249,"mc":[{"id":"1.230178308","rc":[{"atb":[[2.28,9.27]],"id":70218235}],"con":true,"img":false}]}
{"op":"mcm","clk":"11540086342","pt":1719489878458,"mc":[{"id":"1.230178308","rc":[{"atb":[[2.3,9.12]],"id":48500723}],"con":true,"img":false}]}
{"op":"mcm","clk":"11540087798","pt":1719489893873,"mc":[{"id":"1.230178308","rc":[{"atb":[[2.92,7.26]],"id":39362025}],"con":true,"img":false}]}
{"op":"mcm","clk":"11540087828","pt":1719489894189,"mc":[{"id":"1.230178308","rc":[{"atb":[[2.96,3.38]],"id":39362025}],"con":true,"img":false}]}
{"op":"mcm","clk":"11540090427","pt":1719489921496,"mc":[{"id":"1.230178308","rc":[{"atb":[[2.94,0]],"id":39362025}],"con":true,"img":false}]}
{"op":"mcm","clk":"11540090716","pt":1719489923873,"mc":[{"id":"1.230178308","rc":[{"atb":[[2.98,5.99]],"id":39362025}],"con":true,"img":false}]}
{"op":"mcm","clk":"11540092083","pt":1719489939289,"mc":[{"id":"1.230178308","rc":[{"atb":[[3.4,0]],"id":40953876},{"atb":[[2.92,0]],"id":39362025},{"atb":[[2.28,0]],"id":48500723},{"atb":[[1.28,0]],"id":44798446},{"atb":[[2.26,0]],"id":70218235},{"atb":[[2.22,0]],"id":55829870}],"con":true,"img":false}]}
{"op":"mcm","clk":"11540092705","pt":1719489946497,"mc":[{"id":"1.230178308","rc":[{"atb":[[2.96,0]],"id":39362025}],"con":true,"img":false}]}
{"op":"mcm","clk":"11540092721","pt":1719489946701,"mc":[{"id":"1.230178308","rc":[{"atb":[[2.32,10.57]],"id":48500723}],"con":true,"img":false}]}
{"op":"mcm","clk":"11540092730","pt":1719489946805,"mc":[{"id":"1.230178308","rc":[{"atb":[[1.3,46.52]],"id":44798446}],"con":true,"img":false}]}
{"op":"mcm","clk":"11540092752","pt":1719489947115,"mc":[{"id":"1.230178308","rc":[{"atb":[[3.5,5.58]],"id":40953876}],"con":true,"img":false}]}
{"op":"mcm","clk":"11540092759","pt":1719489947217,"mc":[{"id":"1.230178308","rc":[{"atb":[[2.26,11.07]],"id":55829870}],"con":true,"img":false}]}
{"op":"mcm","clk":"11540092772","pt":1719489947424,"mc":[{"id":"1.230178308","rc":[{"atb":[[3,3.38]],"id":39362025}],"con":true,"img":false}]}
{"op":"mcm","clk":"11540092783","pt":1719489947528,"mc":[{"id":"1.230178308","rc":[{"atb":[[2.3,10.73]],"id":70218235}],"con":true,"img":false}]}
{"op":"mcm","clk":"11540094578","pt":1719489967644,"mc":[{"id":"1.230178308","rc":[{"atb":[[3.45,0]],"id":40953876},{"atb":[[2.98,0]],"id":39362025},{"atb":[[2.3,0]],"id":48500723},{"atb":[[1.29,0]],"id":44798446},{"atb":[[2.28,0]],"id":70218235},{"atb":[[2.24,0]],"id":55829870}],"con":true,"img":false}]}
{"op":"mcm","clk":"11540094746","pt":1719489969509,"mc":[{"id":"1.230178308","rc":[{"atb":[[1.31,38.28]],"id":44798446}],"con":true,"img":false}]}
{"op":"mcm","clk":"11540094772","pt":1719489969722,"mc":[{"id":"1.230178308","rc":[{"atb":[[2.34,8.85]],"id":48500723}],"con":true,"img":false}]}
{"op":"mcm","clk":"11540096849","pt":1719489992462,"mc":[{"id":"1.230178308","rc":[{"atb":[[3.55,4.65]],"id":40953876},{"atb":[[3.05,5.79]],"id":39362025}],"con":true,"img":false}]}
{"op":"mcm","clk":"11540096876","pt":1719489992876,"mc":[{"id":"1.230178308","rc":[{"atb":[[2.32,8.98]],"id":70218235}],"con":true,"img":false}]}
{"op":"mcm","clk":"11540096897","pt":1719489993049,"mc":[{"id":"1.230178308","rc":[{"atb":[[2.28,9.27]],"id":55829870}],"con":true,"img":false}]}
{"op":"mcm","clk":"11540097981","pt":1719490004518,"mc":[{"id":"1.230178308","rc":[{"atb":[[3,0]],"id":39362025}],"con":true,"img":false}]}
{"op":"mcm","clk":"11540100718","pt":1719490034293,"mc":[{"id":"1.230178308","rc":[{"atb":[[3.5,0]],"id":40953876},{"atb":[[2.32,0]],"id":48500723},{"atb":[[1.3,0]],"id":44798446},{"atb":[[2.3,0]],"id":70218235},{"atb":[[2.26,0]],"id":55829870}],"con":true,"img":false}]}
{"op":"mcm","clk":"11540100800","pt":1719490035171,"mc":[{"id":"1.230178308","rc":[{"atb":[[3.05,0]],"id":39362025}],"con":true,"img":false}]}
{"op":"mcm","clk":"11540100983","pt":1719490036901,"mc":[{"id":"1.230178308","rc":[{"atb":[[2.88,6.31]],"id":39362025}],"con":true,"img":false}]}
{"op":"mcm","clk":"11540101461","pt":1719490041699,"mc":[{"id":"1.230178308","rc":[{"atb":[[2.34,10.41]],"id":70218235}],"con":true,"img":false}]}
{"op":"mcm","clk":"11540101472","pt":1719490041799,"mc":[{"id":"1.230178308","rc":[{"atb":[[1.32,43.62]],"id":44798446}],"con":true,"img":false}]}
{"op":"mcm","clk":"11540101498","pt":1719490042006,"mc":[{"id":"1.230178308","rc":[{"atb":[[2.36,10.26]],"id":48500723}],"con":true,"img":false}]}
{"op":"mcm","clk":"11540101527","pt":1719490042318,"mc":[{"id":"1.230178308","rc":[{"atb":[[2.3,10.73]],"id":55829870}],"con":true,"img":false}]}
{"op":"mcm","clk":"11540101536","pt":1719490042423,"mc":[{"id":"1.230178308","rc":[{"atb":[[3.6,5.37]],"id":40953876}],"con":true,"img":false}]}
{"op":"mcm","clk":"11540103049","pt":1719490057303,"mc":[{"id":"1.230178308","rc":[{"atb":[[3.55,0]],"id":40953876},{"atb":[[2.34,0]],"id":48500723},{"atb":[[1.31,0]],"id":44798446},{"atb":[[2.32,0]],"id":70218235},{"atb":[[2.28,0]],"id":55829870}],"con":true,"img":false}]}
{"op":"mcm","clk":"11540105422","pt":1719490081363,"mc":[{"id":"1.230178308","rc":[{"atb":[[1.33,35.95]],"id":44798446},{"atb":[[2.36,8.72]],"id":70218235}],"con":true,"img":false}]}
{"op":"mcm","clk":"11540105445","pt":1719490081568,"mc":[{"id":"1.230178308","rc":[{"atb":[[2.38,8.59]],"id":48500723},{"atb":[[2.32,8.98]],"id":55829870}],"con":true,"img":false}]}
{"op":"mcm","clk":"11540105901","pt":1719490085640,"mc":[{"id":"1.230178308","rc":[{"atb":[[2.9,3.38]],"id":39362025}],"con":true,"img":false}]}
{"op":"mcm","clk":"11540105910","pt":1719490085740,"mc":[{"id":"1.230178308","rc":[{"atb":[[2.9,10.72]],"id":39362025}],"con":true,"img":false}]}
{"op":"mcm","clk":"11540108159","pt":1719490107406,"mc":[{"id":"1.230178308","rc":[{"atb":[[3.6,0]],"id":40953876},{"atb":[[2.36,0]],"id":48500723},{"atb":[[1.32,0]],"id":44798446},{"atb":[[2.34,0]],"id":70218235},{"atb":[[2.3,0]],"id":55829870}],"con":true,"img":false}]}
{"op":"mcm","clk":"11540109841","pt":1719490126092,"mc":[{"id":"1.230178308","rc":[{"atb":[[2.88,0]],"id":39362025}],"con":true,"img":false}]}
{"op":"mcm","clk":"11540110226","pt":1719490129800,"mc":[{"id":"1.230178308","rc":[{"atb":[[1.34,41.05]],"id":44798446}],"con":true,"img":false}]}
{"op":"mcm","clk":"11540110244","pt":1719490129960,"mc":[{"id":"1.230178308","rc":[{"atb":[[2.38,10.11]],"id":70218235}],"con":true,"img":false}]}
{"op":"mcm","clk":"11540110264","pt":1719490130271,"mc":[{"id":"1.230178308","rc":[{"atb":[[3.35,5.93]],"id":40953876}],"con":true,"img":false}]}
{"op":"mcm","clk":"11540110300","pt":1719490130710,"mc":[{"id":"1.230178308","rc":[{"atb":[[2.4,9.96]],"id":48500723}],"con":true,"img":false}]}
{"op":"mcm","clk":"11540110313","pt":1719490130798,"mc":[{"id":"1.230178308","rc":[{"atb":[[2.9,7.34]],"id":39362025}],"con":true,"img":false}]}
{"op":"mcm","clk":"11540110339","pt":1719490131100,"mc":[{"id":"1.230178308","rc":[{"atb":[[2.34,10.41]],"id":55829870}],"con":true,"img":false}]}
{"op":"mcm","clk":"11540111956","pt":1719490148792,"mc":[{"id":"1.230178308","rc":[{"atb":[[2.38,0]],"id":48500723},{"atb":[[1.33,0]],"id":44798446},{"atb":[[2.36,0]],"id":70218235},{"atb":[[2.32,0]],"id":55829870}],"con":true,"img":false}]}
{"op":"mcm","clk":"11540112413","pt":1719490154114,"mc":[{"id":"1.230178308","rc":[{"atb":[[2.92,6.17]],"id":39362025}],"con":true,"img":false}]}
{"op":"mcm","clk":"11540112453","pt":1719490154578,"mc":[{"id":"1.230178308","rc":[{"atb":[[2.2,9.88]],"id":55829870}],"con":true,"img":false}]}
{"op":"mcm","clk":"11540113933","pt":1719490169587,"mc":[{"id":"1.230178308","rc":[{"atb":[[2.9,0]],"id":39362025}],"con":true,"img":false}]}
{"op":"mcm","clk":"11540115253","pt":1719490184842,"mc":[{"id":"1.230178308","rc":[{"atb":[[2.4,8.47]],"id":70218235}],"con":true,"img":false}]}
{"op":"mcm","clk":"11540115280","pt":1719490185148,"mc":[{"id":"1.230178308","rc":[{"atb":[[1.35,33.9]],"id":44798446}],"con":true,"img":false}]}
{"op":"mcm","clk":"11540115310","pt":1719490185407,"mc":[{"id":"1.230178308","rc":[{"atb":[[2.42,8.35]],"id":48500723}],"con":true,"img":false}]}
{"op":"mcm","clk":"11540115332","pt":1719490185714,"mc":[{"id":"1.230178308","rc":[{"atb":[[3.4,4.94]],"id":40953876}],"con":true,"img":false}]}
{"op":"mcm","clk":"11540117217","pt":1719490206736,"mc":[{"id":"1.230178308","rc":[{"atb":[[2.92,0]],"id":39362025}],"con":true,"img":false}]}
{"op":"mcm","clk":"11540117718","pt":1719490211662,"mc":[{"id":"1.230178308","rc":[{"atb":[[2.88,6.31]],"id":39362025}],"con":true,"img":false}]}
{"op":"mcm","clk":"11540118176","pt":1719490216523,"mc":[{"id":"1.230178308","rc":[{"atb":[[2.4,0]],"id":48500723},{"atb":[[1.34,0]],"id":44798446},{"atb":[[2.38,0]],"id":70218235},{"atb":[[2.34,0]],"id":55829870}],"con":true,"img":false}]}
{"op":"mcm","clk":"11540119764","pt":1719490232872,"mc":[{"id":"1.230178308","rc":[{"atb":[[2.22,11.44]],"id":55829870}],"con":true,"img":false}]}
{"op":"mcm","clk":"11540122233","pt":1719490258487,"mc":[{"id":"1.230178308","rc":[{"atb":[[2.42,0]],"id":48500723},{"atb":[[1.35,0]],"id":44798446},{"atb":[[2.4,0]],"id":70218235},{"atb":[[2.2,0]],"id":55829870}],"con":true,"img":false}]}
{"op":"mcm","clk":"11540122376","pt":1719490259881,"mc":[{"id":"1.230178308","rc":[{"atb":[[2.24,9.57]],"id":70218235}],"con":true,"img":false}]}
{"op":"mcm","clk":"11540122389","pt":1719490260088,"mc":[{"id":"1.230178308","rc":[{"atb":[[2.26,9.41]],"id":48500723},{"atb":[[2.24,9.57]],"id":55829870}],"con":true,"img":false}]}
{"op":"mcm","clk":"11540122438","pt":1719490260606,"mc":[{"id":"1.230178308","rc":[{"atb":[[1.27,43.95]],"id":44798446}],"con":true,"img":false}]}
{"op":"mcm","clk":"11540123707","pt":1719490273577,"mc":[{"id":"1.230178308","rc":[{"atb":[[3.35,0]],"id":40953876}],"con":true,"img":false}]}
{"op":"mcm","clk":"11540124407","pt":1719490281216,"mc":[{"id":"1.230178308","rc":[{"atb":[[2.9,3.38]],"id":39362025}],"con":true,"img":false}]}
{"op":"mcm","clk":"11540124446","pt":1719490281524,"mc":[{"id":"1.230178308","rc":[{"atb":[[3.45,5.69]],"id":40953876}],"con":true,"img":false}]}
{"op":"mcm","clk":"11540124489","pt":1719490281888,"mc":[{"id":"1.230178308","rc":[{"atb":[[2.9,10.72]],"id":39362025}],"con":true,"img":false}]}
{"op":"mcm","clk":"11540126505","pt":1719490301245,"mc":[{"id":"1.230178308","rc":[{"atb":[[2.22,0]],"id":55829870}],"con":true,"img":false}]}
{"op":"mcm","clk":"11540126810","pt":1719490303932,"mc":[{"id":"1.230178308","rc":[{"atb":[[3.4,0]],"id":40953876},{"atb":[[2.88,0]],"id":39362025}],"con":true,"img":false}]}
{"op":"mcm","clk":"11540127256","pt":1719490308241,"mc":[{"id":"1.230178308","rc":[{"atb":[[2.9,7.34]],"id":39362025}],"con":true,"img":false}]}
{"op":"mcm","clk":"11540127283","pt":1719490308439,"mc":[{"id":"1.230178308","rc":[{"atb":[[2.26,11.07]],"id":70218235}],"con":true,"img":false}]}
{"op":"mcm","clk":"11540127299","pt":1719490308541,"mc":[{"id":"1.230178308","rc":[{"atb":[[2.26,11.07]],"id":55829870}],"con":true,"img":false}]}
{"op":"mcm","clk":"11540127319","pt":1719490308748,"mc":[{"id":"1.230178308","rc":[{"atb":[[2.28,10.9]],"id":48500723}],"con":true,"img":false}]}
{"op":"mcm","clk":"11540127328","pt":1719490308853,"mc":[{"id":"1.230178308","rc":[{"atb":[[1.28,49.85]],"id":44798446}],"con":true,"img":false}]}
{"op":"mcm","clk":"11540128719","pt":1719490323163,"mc":[{"id":"1.230178308","rc":[{"atb":[[3.5,4.74]],"id":40953876}],"con":true,"img":false}]}
{"op":"mcm","clk":"11540128735","pt":1719490323269,"mc":[{"id":"1.230178308","rc":[{"atb":[[2.92,6.17]],"id":39362025}],"con":true,"img":false}]}
{"op":"mcm","clk":"11540130710","pt":1719490343171,"mc":[{"id":"1.230178308","rc":[{"atb":[[2.26,0]],"id":48500723},{"atb":[[1.27,0]],"id":44798446},{"atb":[[2.24,0]],"id":70218235},{"atb":[[2.24,0]],"id":55829870}],"con":true,"img":false}]}
{"op":"mcm","clk":"11540130864","pt":1719490344574,"mc":[{"id":"1.230178308","rc":[{"atb":[[2.28,9.27]],"id":70218235}],"con":true,"img":false}]}
{"op":"mcm","clk":"11540130877","pt":1719490344680,"mc":[{"id":"1.230178308","rc":[{"atb":[[1.29,40.91]],"id":44798446}],"con":true,"img":false}]}
{"op":"mcm","clk":"11540130887","pt":1719490344781,"mc":[{"id":"1.230178308","rc":[{"atb":[[2.3,9.12]],"id":48500723}],"con":true,"img":false}]}
{"op":"mcm","clk":"11540130893","pt":1719490344882,"mc":[{"id":"1.230178308","rc":[{"atb":[[2.28,9.27]],"id":55829870}],"con":true,"img":false}]}
{"op":"mcm","clk":"11540132983","pt":1719490365075,"mc":[{"id":"1.230178308","rc":[{"atb":[[3.45,0]],"id":40953876},{"atb":[[2.9,0]],"id":39362025}],"con":true,"img":false}]}
{"op":"mcm","clk":"11540135057","pt":1719490387026,"mc":[{"id":"1.230178308","rc":[{"atb":[[3.5,0]],"id":40953876},{"atb":[[2.92,0]],"id":39362025}],"con":true,"img":false}]}
{"op":"mcm","clk":"11540136032","pt":1719490397331,"mc":[{"id":"1.230178308","rc":[{"atb":[[2.24,0]],"id":48500723},{"atb":[[2.24,0]],"id":44798446},{"atb":[[2.22,0]],"id":70218235},{"atb":[[2.18,0]],"id":55829870}],"con":true,"img":false}]}
{"op":"mcm","clk":"11540136041","pt":1719490397438,"mc":[{"id":"1.230178308","rc":[{"atb":[[2.32,13.32]],"id":48500723},{"atb":[[2.28,11.96]],"id":44798446},{"atb":[[2.3,13.19]],"id":70218235},{"atb":[[2.3,11.21]],"id":55829870}],"con":true,"img":false}]}
{"op":"mcm","clk":"11540136185","pt":1719490399140,"mc":[{"id":"1.230178308","rc":[{"atb":[[2.88,6.31]],"id":39362025}],"con":true,"img":false}]}
{"op":"mcm","clk":"11540136196","pt":1719490399244,"mc":[{"id":"1.230178308","rc":[{"atb":[[3.35,5.04]],"id":40953876}],"con":true,"img":false}]}
{"op":"mcm","clk":"11540136228","pt":1719490399558,"mc":[{"id":"1.230178308","rc":[{"atb":[[2.26,3.38]],"id":44798446}],"con":true,"img":false}]}
{"op":"mcm","clk":"11540136301","pt":1719490400125,"mc":[{"id":"1.230178308","rc":[{"atb":[[2.3,3.16]],"id":44798446}],"con":true,"img":false}]}
{"op":"mcm","clk":"11540137312","pt":1719490410225,"mc":[{"id":"1.230178308","rc":[{"atb":[[2.28,0]],"id":48500723},{"atb":[[1.28,0]],"id":44798446},{"atb":[[2.26,0]],"id":70218235},{"atb":[[2.26,0]],"id":55829870}],"con":true,"img":false}]}
{"op":"mcm","clk":"11540141927","pt":1719490455304,"mc":[{"id":"1.230178308","rc":[{"atb":[[2.3,0]],"id":48500723},{"atb":[[2.28,0]],"id":70218235},{"atb":[[2.28,0]],"id":55829870}],"con":true,"img":false}]}
{"op":"mcm","clk":"11540142302","pt":1719490458693,"mc":[{"id":"1.230178308","rc":[{"atb":[[2.26,0]],"id":44798446}],"con":true,"img":false}]}
{"op":"mcm","clk":"11540142342","pt":1719490459004,"mc":[{"id":"1.230178308","rc":[{"atb":[[1.3,46.52]],"id":44798446}],"con":true,"img":false}]}
{"op":"mcm","clk":"11540142413","pt":1719490459675,"mc":[{"id":"1.230178308","rc":[{"atb":[[2.3,6.54]],"id":44798446}],"con":true,"img":false}]}
{"op":"mcm","clk":"11540144913","pt":1719490483611,"mc":[{"id":"1.230178308","rc":[{"atb":[[2.32,8.98]],"id":70218235}],"con":true,"img":false}]}
{"op":"mcm","clk":"11540145007","pt":1719490484639,"mc":[{"id":"1.230178308","rc":[{"atb":[[2.34,8.85]],"id":48500723}],"con":true,"img":false}]}
{"op":"mcm","clk":"11540145190","pt":1719490486298,"mc":[{"id":"1.230178308","rc":[{"atb":[[2.32,8.98]],"id":55829870}],"con":true,"img":false}]}
{"op":"mcm","clk":"11540147406","pt":1719490507918,"mc":[{"id":"1.230178308","rc":[{"atb":[[1.29,0]],"id":44798446}],"con":true,"img":false}]}
{"op":"mcm","clk":"11540147797","pt":1719490511752,"mc":[{"id":"1.230178308","rc":[{"atb":[[1.31,38.28]],"id":44798446}],"con":true,"img":false}]}
{"op":"mcm","clk":"11540152440","pt":1719490557604,"mc":[{"id":"1.230178308","rc":[{"atb":[[3.4,5.82]],"id":40953876},{"atb":[[2.9,3.38]],"id":39362025}],"con":true,"img":false}]}
{"op":"mcm","clk":"11540152467","pt":1719490557869,"mc":[{"id":"1.230178308","rc":[{"atb":[[2.9,10.72]],"id":39362025}],"con":true,"img":false}]}
{"op":"mcm","clk":"11540154295","pt":1719490578409,"mc":[{"id":"1.230178308","rc":[{"atb":[[1.3,0]],"id":44798446}],"con":true,"img":false}]}
{"op":"mcm","clk":"11540154754","pt":1719490583839,"mc":[{"id":"1.230178308","rc":[{"atb":[[2.34,10.41]],"id":70218235}],"con":true,"img":false}]}
{"op":"mcm","clk":"11540154779","pt":1719490584112,"mc":[{"id":"1.230178308","rc":[{"atb":[[1.32,43.62]],"id":44798446}],"con":true,"img":false}]}
{"op":"mcm","clk":"11540154798","pt":1719490584312,"mc":[{"id":"1.230178308","rc":[{"atb":[[2.36,10.26]],"id":48500723}],"con":true,"img":false}]}
{"op":"mcm","clk":"11540154800","pt":1719490584408,"mc":[{"id":"1.230178308","rc":[{"atb":[[2.34,10.41]],"id":55829870}],"con":true,"img":false}]}
{"op":"mcm","clk":"11540156796","pt":1719490602162,"mc":[{"id":"1.230178308","rc":[{"atb":[[3.35,0]],"id":40953876},{"atb":[[2.88,0]],"id":39362025},{"atb":[[1.31,0]],"id":44798446}],"con":true,"img":false}]}
{"op":"mcm","clk":"11540156957","pt":1719490603840,"mc":[{"id":"1.230178308","rc":[{"atb":[[2.92,6.17]],"id":39362025}],"con":true,"img":false}]}
{"op":"mcm","clk":"11540156982","pt":1719490604050,"mc":[{"id":"1.230178308","rc":[{"atb":[[3.45,4.84]],"id":40953876}],"con":true,"img":false}]}
{"op":"mcm","clk":"11540158660","pt":1719490623363,"mc":[{"id":"1.230178308","rc":[{"atb":[[1.33,35.95]],"id":44798446}],"con":true,"img":false}]}
{"op":"mcm","clk":"11540158780","pt":1719490624861,"mc":[{"id":"1.230178308","rc":[{"atb":[[2.34,0]],"id":48500723},{"atb":[[2.32,0]],"id":70218235}],"con":true,"img":false}]}
{"op":"mcm","clk":"11540159985","pt":1719490637961,"mc":[{"id":"1.230178308","rc":[{"atb":[[2.9,7.34]],"id":39362025}],"con":true,"img":false}]}
{"op":"mcm","clk":"11540160032","pt":1719490638475,"mc":[{"id":"1.230178308","rc":[{"atb":[[2.94,3.38]],"id":39362025}],"con":true,"img":false}]}
{"op":"mcm","clk":"11540160446","pt":1719490643797,"mc":[{"id":"1.230178308","rc":[{"atb":[[2.36,8.72]],"id":70218235}],"con":true,"img":false}]}
{"op":"mcm","clk":"11540160466","pt":1719490643961,"mc":[{"id":"1.230178308","rc":[{"atb":[[2.38,8.59]],"id":48500723}],"con":true,"img":false}]}
{"op":"mcm","clk":"11540162109","pt":1719490664992,"mc":[{"id":"1.230178308","rc":[{"atb":[[2.92,0]],"id":39362025}],"con":true,"img":false}]}
{"op":"mcm","clk":"11540162723","pt":1719490673097,"mc":[{"id":"1.230178308","rc":[{"atb":[[3.4,0]],"id":40953876},{"atb":[[2.9,0]],"id":39362025},{"atb":[[2.36,0]],"id":48500723},{"atb":[[1.32,0]],"id":44798446},{"atb":[[2.34,0]],"id":70218235}],"con":true,"img":false}]}
{"op":"mcm","clk":"11540163664","pt":1719490685693,"mc":[{"id":"1.230178308","rc":[{"atb":[[2.96,6.05]],"id":39362025}],"con":true,"img":false}]}
{"op":"mcm","clk":"11540164267","pt":1719490692415,"mc":[{"id":"1.230178308","rc":[{"atb":[[2.94,0]],"id":39362025}],"con":true,"img":false}]}
{"op":"mcm","clk":"11540164272","pt":1719490692510,"mc":[{"id":"1.230178308","rc":[{"atb":[[3.5,5.58]],"id":40953876}],"con":true,"img":false}]}
{"op":"mcm","clk":"11540164288","pt":1719490692718,"mc":[{"id":"1.230178308","rc":[{"atb":[[1.34,41.05]],"id":44798446}],"con":true,"img":false}]}
{"op":"mcm","clk":"11540164311","pt":1719490693027,"mc":[{"id":"1.230178308","rc":[{"atb":[[2.98,3.38]],"id":39362025}],"con":true,"img":false}]}
{"op":"mcm","clk":"11540164530","pt":1719490695919,"mc":[{"id":"1.230178308","rc":[{"atb":[[2.28,0]],"id":44798446},{"atb":[[2.3,0]],"id":55829870}],"con":true,"img":false}]}
{"op":"mcm","clk":"11540164537","pt":1719490696021,"mc":[{"id":"1.230178308","rc":[{"atb":[[2.32,11.96]],"id":44798446},{"atb":[[2.36,11.21]],"id":55829870}],"con":true,"img":false}]}
{"op":"mcm","clk":"11540166278","pt":1719490718136,"mc":[{"id":"1.230178308","rc":[{"atl":[[34,18]],"id":55829870}],"con":true,"img":false}]}
{"op":"mcm","clk":"11540166694","pt":1719490723945,"mc":[{"id":"1.230178308","rc":[{"atb":[[3.45,0]],"id":40953876},{"atb":[[2.38,0]],"id":48500723},{"atb":[[1.33,0]],"id":44798446},{"atb":[[2.36,0]],"id":70218235}],"con":true,"img":false}]}
{"op":"mcm","clk":"11540168770","pt":1719490749351,"mc":[{"id":"1.230178308","rc":[{"atb":[[2.3,3.38]],"id":44798446}],"con":true,"img":false}]}
{"op":"mcm","clk":"11540168786","pt":1719490749547,"mc":[{"id":"1.230178308","rc":[{"atb":[[2.34,8.85]],"id":48500723},{"atb":[[2.32,8.98]],"id":70218235}],"con":true,"img":false}]}
{"op":"mcm","clk":"11540168824","pt":1719490749962,"mc":[{"id":"1.230178308","rc":[{"atb":[[2.34,3.16]],"id":44798446}],"con":true,"img":false}]}
{"op":"mcm","clk":"11540170201","pt":1719490769655,"mc":[{"id":"1.230178308","rc":[{"atb":[[2.96,0]],"id":39362025},{"atb":[[2.32,0]],"id":55829870}],"con":true,"img":false}]}
{"op":"mcm","clk":"11540170206","pt":1719490769754,"mc":[{"id":"1.230178308","rc":[{"atb":[[3.55,4.65]],"id":40953876}],"con":true,"img":false}]}
{"op":"mcm","clk":"11540170212","pt":1719490769851,"mc":[{"id":"1.230178308","rc":[{"atb":[[1.35,33.9]],"id":44798446}],"con":true,"img":false}]}
{"op":"mcm","clk":"11540171659","pt":1719490791690,"mc":[{"id":"1.230178308","rc":[{"atb":[[2.3,0]],"id":44798446}],"con":true,"img":false}]}
{"op":"mcm","clk":"11540171728","pt":1719490792618,"mc":[{"id":"1.230178308","rc":[{"atb":[[2.98,10.43]],"id":39362025}],"con":true,"img":false}]}
{"op":"mcm","clk":"11540171748","pt":1719490792825,"mc":[{"id":"1.230178308","rc":[{"atb":[[3,5.93]],"id":39362025}],"con":true,"img":false}]}
{"op":"mcm","clk":"11540172861","pt":1719490806523,"mc":[{"id":"1.230178308","rc":[{"atb":[[3.5,0]],"id":40953876},{"atb":[[1.34,0]],"id":44798446}],"con":true,"img":false}]}
{"op":"mcm","clk":"11540173414","pt":1719490813494,"mc":[{"id":"1.230178308","rc":[{"atb":[[2.34,6.54]],"id":44798446}],"con":true,"img":false}]}
{"op":"mcm","clk":"11540173501","pt":1719490814896,"mc":[{"id":"1.230178308","rc":[{"atb":[[2.04,11.4]],"id":55829870}],"con":true,"img":false}]}
{"op":"mcm","clk":"11540174891","pt":1719490835917,"mc":[{"id":"1.230178308","rc":[{"atb":[[3.55,0]],"id":40953876},{"atb":[[1.35,0]],"id":44798446}],"con":true,"img":false}]}
{"op":"mcm","clk":"11540175815","pt":1719490849347,"mc":[{"id":"1.230178308","rc":[{"atb":[[2.98,7.05]],"id":39362025}],"con":true,"img":false}]}
{"op":"mcm","clk":"11540175829","pt":1719490849554,"mc":[{"id":"1.230178308","rc":[{"atb":[[2.34,10.41]],"id":70218235}],"con":true,"img":false}]}
{"op":"mcm","clk":"11540175835","pt":1719490849655,"mc":[{"id":"1.230178308","rc":[{"atb":[[3.35,5.93]],"id":40953876}],"con":true,"img":false}]}
{"op":"mcm","clk":"11540175852","pt":1719490849914,"mc":[{"id":"1.230178308","rc":[{"atb":[[3.05,3.38]],"id":39362025}],"con":true,"img":false}]}
{"op":"mcm","clk":"11540175857","pt":1719490850017,"mc":[{"id":"1.230178308","rc":[{"atb":[[2.36,10.26]],"id":48500723}],"con":true,"img":false}]}
{"op":"mcm","clk":"11540175877","pt":1719490850231,"mc":[{"id":"1.230178308","rc":[{"atb":[[1.27,51.7]],"id":44798446}],"con":true,"img":false}]}
{"op":"mcm","clk":"11540177264","pt":1719490869344,"mc":[{"id":"1.230178308","rc":[{"atb":[[2.98,0]],"id":39362025},{"atb":[[2.34,0]],"id":55829870}],"con":true,"img":false}]}
{"op":"mcm","clk":"11540177708","pt":1719490875238,"mc":[{"id":"1.230178308","rc":[{"atb":[[2.06,13.16]],"id":55829870}],"con":true,"img":false}]}
{"op":"mcm","clk":"11540177723","pt":1719490875446,"mc":[{"id":"1.230178308","rc":[{"atb":[[3.05,10.19]],"id":39362025}],"con":true,"img":false}]}
{"op":"mcm","clk":"11540178058","pt":1719490880286,"mc":[{"id":"1.230178308","rc":[{"atb":[[3,0]],"id":39362025},{"atb":[[2.34,0]],"id":48500723},{"atb":[[2.32,0]],"id":70218235}],"con":true,"img":false}]}
{"op":"mcm","clk":"11540178243","pt":1719490882880,"mc":[{"id":"1.230178308","rc":[{"atb":[[3.1,5.64]],"id":39362025}],"con":true,"img":false}]}
{"op":"mcm","clk":"11540178253","pt":1719490882979,"mc":[{"id":"1.230178308","rc":[{"atb":[[1.28,42.38]],"id":44798446}],"con":true,"img":false}]}
{"op":"mcm","clk":"11540178261","pt":1719490883086,"mc":[{"id":"1.230178308","rc":[{"atb":[[2.36,8.72]],"id":70218235}],"con":true,"img":false}]}
{"op":"mcm","clk":"11540178272","pt":1719490883188,"mc":[{"id":"1.230178308","rc":[{"atb":[[3.4,4.94]],"id":40953876}],"con":true,"img":false}]}
{"op":"mcm","clk":"11540178279","pt":1719490883291,"mc":[{"id":"1.230178308","rc":[{"atb":[[2.38,8.59]],"id":48500723}],"con":true,"img":false}]}
{"op":"mcm","clk":"11540179655","pt":1719490903703,"mc":[{"id":"1.230178308","rc":[{"atb":[[2.04,0]],"id":55829870}],"con":true,"img":false}]}
{"op":"mcm","clk":"11540180645","pt":1719490918016,"mc":[{"id":"1.230178308","rc":[{"atb":[[3.05,6.8]],"id":39362025}],"con":true,"img":false}]}
{"op":"mcm","clk":"11540181071","pt":1719490924534,"mc":[{"id":"1.230178308","rc":[{"atb":[[2.08,10.98]],"id":55829870}],"con":true,"img":false}]}
{"op":"mcm","clk":"11540183217","pt":1719490955065,"mc":[{"id":"1.230178308","rc":[{"atb":[[3.35,0]],"id":40953876},{"atb":[[3.05,0]],"id":39362025},{"atb":[[2.36,0]],"id":48500723},{"atb":[[1.27,0]],"id":44798446},{"atb":[[2.34,0]],"id":70218235},{"atb":[[2.06,0]],"id":55829870}],"con":true,"img":false}]}
{"op":"mcm","clk":"11540183827","pt":1719490964071,"mc":[{"id":"1.230178308","rc":[{"atb":[[3.15,6.49]],"id":39362025}],"con":true,"img":false}]}
{"op":"mcm","clk":"11540183841","pt":1719490964278,"mc":[{"id":"1.230178308","rc":[{"atb":[[2.38,10.11]],"id":70218235}],"con":true,"img":false}]}
{"op":"mcm","clk":"11540183852","pt":1719490964380,"mc":[{"id":"1.230178308","rc":[{"atb":[[1.29,48.12]],"id":44798446}],"con":true,"img":false}]}
{"op":"mcm","clk":"11540183877","pt":1719490964694,"mc":[{"id":"1.230178308","rc":[{"atb":[[2.4,9.96]],"id":48500723}],"con":true,"img":false}]}
{"op":"mcm","clk":"11540183884","pt":1719490964749,"mc":[{"id":"1.230178308","rc":[{"atb":[[3.45,5.69]],"id":40953876}],"con":true,"img":false}]}
{"op":"mcm","clk":"11540186117","pt":1719490998000,"mc":[{"id":"1.230178308","rc":[{"atb":[[3.4,0]],"id":40953876},{"atb":[[3.1,0]],"id":39362025},{"atb":[[2.38,0]],"id":48500723},{"atb":[[1.28,0]],"id":44798446},{"atb":[[2.36,0]],"id":70218235},{"atb":[[2.08,0]],"id":55829870}],"con":true,"img":false}]}
{"op":"mcm","clk":"11540186243","pt":1719491000017,"mc":[{"id":"1.230178308","rc":[{"atb":[[3.2,5.39]],"id":39362025}],"con":true,"img":false}]}
{"op":"mcm","clk":"11540186262","pt":1719491000322,"mc":[{"id":"1.230178308","rc":[{"atb":[[2.4,8.47]],"id":70218235}],"con":true,"img":false}]}
{"op":"mcm","clk":"11540186282","pt":1719491000533,"mc":[{"id":"1.230178308","rc":[{"atb":[[1.3,39.55]],"id":44798446}],"con":true,"img":false}]}
{"op":"mcm","clk":"11540186295","pt":1719491000743,"mc":[{"id":"1.230178308","rc":[{"atb":[[2.42,8.35]],"id":48500723}],"con":true,"img":false}]}
{"op":"mcm","clk":"11540186307","pt":1719491000898,"mc":[{"id":"1.230178308","rc":[{"atb":[[3.5,4.74]],"id":40953876}],"con":true,"img":false}]}
{"op":"mcm","clk":"11540186321","pt":1719491001100,"mc":[{"id":"1.230178308","rc":[{"atb":[[2.04,11.4]],"id":55829870}],"con":true,"img":false}]}
{"op":"mcm","clk":"11540186680","pt":1719491007313,"mc":[{"id":"1.230178308","rc":[{"atb":[[2.12,89.29]],"id":39362025}],"con":true,"img":false}]}
{"op":"mcm","clk":"11540190277","pt":1719491061909,"mc":[{"id":"1.230178308","rc":[{"atb":[[3.45,0]],"id":40953876},{"atb":[[3.15,0]],"id":39362025},{"atb":[[2.4,0]],"id":48500723},{"atb":[[1.29,0]],"id":44798446},{"atb":[[2.38,0]],"id":70218235}],"con":true,"img":false}]}
{"op":"mcm","clk":"11540191077","pt":1719491073102,"mc":[{"id":"1.230178308","rc":[{"atb":[[3.25,6.2]],"id":39362025},{"atb":[[1.31,45.03]],"id":44798446}],"con":true,"img":false}]}
{"op":"mcm","clk":"11540191095","pt":1719491073410,"mc":[{"id":"1.230178308","rc":[{"atb":[[2.44,9.69]],"id":48500723},{"atb":[[2.42,9.82]],"id":70218235}],"con":true,"img":false}]}
{"op":"mcm","clk":"11540191113","pt":1719491073679,"mc":[{"id":"1.230178308","rc":[{"atb":[[3.55,5.47]],"id":40953876},{"atb":[[2.06,13.16]],"id":55829870}],"con":true,"img":false}]}
{"op":"mcm","clk":"11540193584","pt":1719491106823,"mc":[{"id":"1.230178308","rc":[{"atb":[[3.5,0]],"id":40953876},{"atb":[[3.2,0]],"id":39362025},{"atb":[[2.42,0]],"id":48500723},{"atb":[[1.3,0]],"id":44798446},{"atb":[[2.4,0]],"id":70218235},{"atb":[[2.04,0]],"id":55829870}],"con":true,"img":false}]}
{"op":"mcm","clk":"11540193618","pt":1719491107341,"mc":[{"id":"1.230178308","rc":[{"atb":[[3.3,5.15]],"id":39362025}],"con":true,"img":false}]}
{"op":"mcm","clk":"11540193627","pt":1719491107446,"mc":[{"id":"1.230178308","rc":[{"atb":[[1.32,37.08]],"id":44798446}],"con":true,"img":false}]}
{"op":"mcm","clk":"11540193634","pt":1719491107549,"mc":[{"id":"1.230178308","rc":[{"atb":[[2.44,8.24]],"id":70218235}],"con":true,"img":false}]}
{"op":"mcm","clk":"11540193645","pt":1719491107653,"mc":[{"id":"1.230178308","rc":[{"atb":[[3.6,4.56]],"id":40953876}],"con":true,"img":false}]}
{"op":"mcm","clk":"11540193653","pt":1719491107757,"mc":[{"id":"1.230178308","rc":[{"atb":[[2.08,10.98]],"id":55829870}],"con":true,"img":false}]}
{"op":"mcm","clk":"11540193668","pt":1719491107920,"mc":[{"id":"1.230178308","rc":[{"atb":[[2.46,8.12]],"id":48500723}],"con":true,"img":false}]}
{"op":"mcm","clk":"11540195842","pt":1719491139187,"mc":[{"id":"1.230178308","rc":[{"atb":[[3.55,0]],"id":40953876},{"atb":[[3.25,0]],"id":39362025},{"atb":[[2.44,0]],"id":48500723},{"atb":[[1.31,0]],"id":44798446},{"atb":[[2.42,0]],"id":70218235},{"atb":[[2.06,0]],"id":55829870}],"con":true,"img":false}]}
{"op":"mcm","clk":"11540196690","pt":1719491151067,"mc":[{"id":"1.230178308","rc":[{"atb":[[2.48,9.43]],"id":48500723},{"atb":[[1.33,42.29]],"id":44798446}],"con":true,"img":false}]}
{"op":"mcm","clk":"11540196717","pt":1719491151377,"mc":[{"id":"1.230178308","rc":[{"atb":[[3.35,5.93]],"id":39362025},{"atb":[[2.46,9.55]],"id":70218235}],"con":true,"img":false}]}
{"op":"mcm","clk":"11540196754","pt":1719491151700,"mc":[{"id":"1.230178308","rc":[{"atb":[[2.1,12.68]],"id":55829870}],"con":true,"img":false}]}
{"op":"mcm","clk":"11540198232","pt":1719491171110,"mc":[{"id":"1.230178308","rc":[{"atb":[[3.6,0]],"id":40953876},{"atb":[[3.3,0]],"id":39362025},{"atb":[[2.46,0]],"id":48500723},{"atb":[[1.32,0]],"id":44798446},{"atb":[[2.44,0]],"id":70218235},{"atb":[[2.08,0]],"id":55829870}],"con":true,"img":false}]}
{"op":"mcm","clk":"11540200226","pt":1719491194154,"mc":[{"id":"1.230178308","rc":[{"atb":[[3.4,4.94]],"id":39362025}],"con":true,"img":false}]}
{"op":"mcm","clk":"11540200237","pt":1719491194362,"mc":[{"id":"1.230178308","rc":[{"atb":[[2.48,8.02]],"id":70218235}],"con":true,"img":false}]}
{"op":"mcm","clk":"11540200250","pt":1719491194566,"mc":[{"id":"1.230178308","rc":[{"atb":[[2.5,7.91]],"id":48500723}],"con":true,"img":false}]}
{"op":"mcm","clk":"11540200265","pt":1719491194770,"mc":[{"id":"1.230178308","rc":[{"atb":[[1.34,34.9]],"id":44798446}],"con":true,"img":false}]}
{"op":"mcm","clk":"11540200279","pt":1719491194975,"mc":[{"id":"1.230178308","rc":[{"atb":[[3.35,5.04]],"id":40953876}],"con":true,"img":false}]}
{"op":"mcm","clk":"11540200288","pt":1719491195078,"mc":[{"id":"1.230178308","rc":[{"atb":[[2.12,10.59]],"id":55829870}],"con":true,"img":false}]}
{"op":"mcm","clk":"11540203765","pt":1719491250502,"mc":[{"id":"1.230178308","rc":[{"atb":[[3.35,0]],"id":39362025},{"atb":[[2.48,0]],"id":48500723},{"atb":[[1.33,0]],"id":44798446},{"atb":[[2.46,0]],"id":70218235},{"atb":[[2.1,0]],"id":55829870}],"con":true,"img":false}]}
{"op":"mcm","clk":"11540204429","pt":1719491259436,"mc":[{"id":"1.230178308","rc":[{"atb":[[2.88,3.38]],"id":39362025}],"con":true,"img":false}]}
{"op":"mcm","clk":"11540204448","pt":1719491259649,"mc":[{"id":"1.230178308","rc":[{"atb":[[3.45,5.69]],"id":39362025}],"con":true,"img":false}]}
{"op":"mcm","clk":"11540204456","pt":1719491259696,"mc":[{"id":"1.230178308","rc":[{"atb":[[2.52,9.18]],"id":48500723}],"con":true,"img":false}]}
{"op":"mcm","clk":"11540204470","pt":1719491259899,"mc":[{"id":"1.230178308","rc":[{"atb":[[1.35,39.88]],"id":44798446}],"con":true,"img":false}]}
{"op":"mcm","clk":"11540204481","pt":1719491260008,"mc":[{"id":"1.230178308","rc":[{"atb":[[2.14,12.24]],"id":55829870}],"con":true,"img":false}]}
{"op":"mcm","clk":"11540204491","pt":1719491260207,"mc":[{"id":"1.230178308","rc":[{"atb":[[3.4,5.82]],"id":40953876}],"con":true,"img":false}]}
{"op":"mcm","clk":"11540204498","pt":1719491260309,"mc":[{"id":"1.230178308","rc":[{"atb":[[2.5,9.3]],"id":70218235}],"con":true,"img":false}]}
{"op":"mcm","clk":"11540205549","pt":1719491275730,"mc":[{"id":"1.230178308","rc":[{"atb":[[3.4,0]],"id":39362025},{"atb":[[2.5,0]],"id":48500723},{"atb":[[1.34,0]],"id":44798446},{"atb":[[2.48,0]],"id":70218235},{"atb":[[2.12,0]],"id":55829870}],"con":true,"img":false}]}
{"op":"mcm","clk":"11540207161","pt":1719491296642,"mc":[{"id":"1.230178308","rc":[{"atb":[[3.35,0]],"id":40953876}],"con":true,"img":false}]}
{"op":"mcm","clk":"11540207469","pt":1719491300664,"mc":[{"id":"1.230178308","rc":[{"atb":[[3.5,4.74]],"id":39362025}],"con":true,"img":false}]}
{"op":"mcm","clk":"11540207477","pt":1719491300764,"mc":[{"id":"1.230178308","rc":[{"atb":[[1.36,32.96]],"id":44798446}],"con":true,"img":false}]}
{"op":"mcm","clk":"11540207485","pt":1719491300867,"mc":[{"id":"1.230178308","rc":[{"atb":[[2.54,7.7]],"id":48500723}],"con":true,"img":false}]}
{"op":"mcm","clk":"11540207501","pt":1719491301073,"mc":[{"id":"1.230178308","rc":[{"atb":[[3.45,4.84]],"id":40953876},{"atb":[[2.16,10.22]],"id":55829870}],"con":true,"img":false}]}
{"op":"mcm","clk":"11540207523","pt":1719491301383,"mc":[{"id":"1.230178308","rc":[{"atb":[[2.52,7.8]],"id":70218235}],"con":true,"img":false}]}
{"op":"mcm","clk":"11540209587","pt":1719491329498,"mc":[{"id":"1.230178308","rc":[{"atb":[[3.45,0]],"id":39362025},{"atb":[[2.52,0]],"id":48500723},{"atb":[[1.35,0]],"id":44798446},{"atb":[[2.5,0]],"id":70218235},{"atb":[[2.14,0]],"id":55829870}],"con":true,"img":false}]}
{"op":"mcm","clk":"11540212982","pt":1719491375448,"mc":[{"id":"1.230178308","rc":[{"atb":[[3.4,0]],"id":40953876}],"con":true,"img":false}]}
{"op":"mcm","clk":"11540214047","pt":1719491390247,"mc":[{"id":"1.230178308","rc":[{"atb":[[3.5,0]],"id":39362025},{"atb":[[2.54,0]],"id":48500723},{"atb":[[1.36,0]],"id":44798446},{"atb":[[2.52,0]],"id":70218235},{"atb":[[2.16,0]],"id":55829870}],"con":true,"img":false}]}
{"op":"mcm","clk":"11540214396","pt":1719491395242,"mc":[{"id":"1.230178308","rc":[{"atb":[[2.9,6.24]],"id":39362025}],"con":true,"img":false}]}
{"op":"mcm","clk":"11540214403","pt":1719491395347,"mc":[{"id":"1.230178308","rc":[{"atb":[[1.27,43.95]],"id":44798446}],"con":true,"img":false}]}
{"op":"mcm","clk":"11540214415","pt":1719491395448,"mc":[{"id":"1.230178308","rc":[{"atb":[[2.32,8.98]],"id":70218235}],"con":true,"img":false}]}
{"op":"mcm","clk":"11540214427","pt":1719491395653,"mc":[{"id":"1.230178308","rc":[{"atb":[[2.34,8.85]],"id":48500723},{"atb":[[2.04,11.4]],"id":55829870}],"con":true,"img":false}]}
{"op":"mcm","clk":"11540214433","pt":1719491395756,"mc":[{"id":"1.230178308","rc":[{"atb":[[3.5,5.58]],"id":40953876}],"con":true,"img":false}]}
{"op":"mcm","clk":"11540216006","pt":1719491415392,"mc":[{"id":"1.230178308","rc":[{"atb":[[3.45,0]],"id":40953876}],"con":true,"img":false}]}
{"op":"mcm","clk":"11540217822","pt":1719491438488,"mc":[{"id":"1.230178308","rc":[{"atb":[[3.55,4.65]],"id":40953876}],"con":true,"img":false}]}
{"op":"mcm","clk":"11540218007","pt":1719491440937,"mc":[{"id":"1.230178308","rc":[{"atb":[[2.88,0]],"id":39362025}],"con":true,"img":false}]}
{"op":"mcm","clk":"11540218057","pt":1719491441512,"mc":[{"id":"1.230178308","rc":[{"atb":[[2.92,3.38]],"id":39362025}],"con":true,"img":false}]}
{"op":"mcm","clk":"11540219378","pt":1719491461240,"mc":[{"id":"1.230178308","rc":[{"atb":[[3.5,0]],"id":40953876}],"con":true,"img":false}]}
{"op":"mcm","clk":"11540221331","pt":1719491488247,"mc":[{"id":"1.230178308","rc":[{"atb":[[2.92,10.65]],"id":39362025}],"con":true,"img":false}]}
{"op":"mcm","clk":"11540221347","pt":1719491488453,"mc":[{"id":"1.230178308","rc":[{"atb":[[2.34,10.41]],"id":70218235}],"con":true,"img":false}]}
{"op":"mcm","clk":"11540221350","pt":1719491488552,"mc":[{"id":"1.230178308","rc":[{"atb":[[3.6,5.37]],"id":40953876}],"con":true,"img":false}]}
{"op":"mcm","clk":"11540221360","pt":1719491488761,"mc":[{"id":"1.230178308","rc":[{"atb":[[2.36,10.26]],"id":48500723}],"con":true,"img":false}]}
{"op":"mcm","clk":"11540221368","pt":1719491488865,"mc":[{"id":"1.230178308","rc":[{"atb":[[1.28,49.85]],"id":44798446}],"con":true,"img":false}]}
{"op":"mcm","clk":"11540221384","pt":1719491489179,"mc":[{"id":"1.230178308","rc":[{"atb":[[2.06,13.16]],"id":55829870}],"con":true,"img":false}]}
{"op":"mcm","clk":"11540221802","pt":1719491495586,"mc":[{"id":"1.230178308","rc":[{"atb":[[2.9,0]],"id":39362025}],"con":true,"img":false}]}
{"op":"mcm","clk":"11540222073","pt":1719491499060,"mc":[{"id":"1.230178308","rc":[{"atb":[[3.55,0]],"id":40953876}],"con":true,"img":false}]}
{"op":"mcm","clk":"11540222086","pt":1719491499267,"mc":[{"id":"1.230178308","rc":[{"atb":[[2.94,6.11]],"id":39362025}],"con":true,"img":false}]}
{"op":"mcm","clk":"11540223593","pt":1719491519726,"mc":[{"id":"1.230178308","rc":[{"atb":[[2.34,0]],"id":48500723},{"atb":[[1.27,0]],"id":44798446},{"atb":[[2.32,0]],"id":70218235},{"atb":[[2.04,0]],"id":55829870}],"con":true,"img":false}]}
{"op":"mcm","clk":"11540223612","pt":1719491519984,"mc":[{"id":"1.230178308","rc":[{"atb":[[1.29,40.91]],"id":44798446},{"atb":[[2.36,8.72]],"id":70218235}],"con":true,"img":false}]}
{"op":"mcm","clk":"11540223627","pt":1719491520200,"mc":[{"id":"1.230178308","rc":[{"atb":[[2.08,10.98]],"id":55829870}],"con":true,"img":false}]}
{"op":"mcm","clk":"11540223634","pt":1719491520302,"mc":[{"id":"1.230178308","rc":[{"atb":[[2.38,8.59]],"id":48500723}],"con":true,"img":false}]}
{"op":"mcm","clk":"11540224958","pt":1719491537205,"mc":[{"id":"1.230178308","rc":[{"atb":[[2.92,7.26]],"id":39362025}],"con":true,"img":false}]}
{"op":"mcm","clk":"11540224982","pt":1719491537515,"mc":[{"id":"1.230178308","rc":[{"atb":[[2.96,3.38]],"id":39362025}],"con":true,"img":false}]}
{"op":"mcm","clk":"11540226640","pt":1719491561252,"mc":[{"id":"1.230178308","rc":[{"atb":[[2.94,0]],"id":39362025}],"con":true,"img":false}]}
{"op":"mcm","clk":"11540227081","pt":1719491566810,"mc":[{"id":"1.230178308","rc":[{"atb":[[3.6,0]],"id":40953876},{"atb":[[2.92,0]],"id":39362025},{"atb":[[2.36,0]],"id":48500723},{"atb":[[1.28,0]],"id":44798446},{"atb":[[2.34,0]],"id":70218235},{"atb":[[2.06,0]],"id":55829870}],"con":true,"img":false}]}
{"op":"mcm","clk":"11540227743","pt":1719491576945,"mc":[{"id":"1.230178308","rc":[{"atb":[[2.98,5.99]],"id":39362025}],"con":true,"img":false}]}
{"op":"mcm","clk":"11540227836","pt":1719491578245,"mc":[{"id":"1.230178308","rc":[{"atb":[[2.96,0]],"id":39362025},{"atb":[[1.3,46.52]],"id":44798446}],"con":true,"img":false}]}
{"op":"mcm","clk":"11540227857","pt":1719491578556,"mc":[{"id":"1.230178308","rc":[{"atb":[[2.4,9.96]],"id":48500723},{"atb":[[2.38,10.11]],"id":70218235}],"con":true,"img":false}]}
{"op":"mcm","clk":"11540227877","pt":1719491578851,"mc":[{"id":"1.230178308","rc":[{"atb":[[3.35,5.93]],"id":40953876}],"con":true,"img":false}]}
{"op":"mcm","clk":"11540227895","pt":1719491579028,"mc":[{"id":"1.230178308","rc":[{"atb":[[2.1,12.68]],"id":55829870}],"con":true,"img":false}]}
{"op":"mcm","clk":"11540227904","pt":1719491579129,"mc":[{"id":"1.230178308","rc":[{"atb":[[3,3.38]],"id":39362025}],"con":true,"img":false}]}
{"op":"mcm","clk":"11540229253","pt":1719491598274,"mc":[{"id":"1.230178308","rc":[{"atb":[[2.38,0]],"id":48500723},{"atb":[[1.29,0]],"id":44798446},{"atb":[[2.36,0]],"id":70218235},{"atb":[[2.08,0]],"id":55829870}],"con":true,"img":false}]}
{"op":"mcm","clk":"11540230751","pt":1719491623064,"mc":[{"id":"1.230178308","rc":[{"atb":[[2.98,0]],"id":39362025}],"con":true,"img":false}]}
{"op":"mcm","clk":"11540230842","pt":1719491624870,"mc":[{"id":"1.230178308","rc":[{"atb":[[3,0]],"id":39362025}],"con":true,"img":false}]}
{"op":"mcm","clk":"11540230959","pt":1719491626986,"mc":[{"id":"1.230178308","rc":[{"atb":[[2.4,8.47]],"id":70218235},{"atb":[[2.12,10.59]],"id":55829870}],"con":true,"img":false}]}
{"op":"mcm","clk":"11540230965","pt":1719491627191,"mc":[{"id":"1.230178308","rc":[{"atb":[[2.42,8.35]],"id":48500723}],"con":true,"img":false}]}
{"op":"mcm","clk":"11540230971","pt":1719491627293,"mc":[{"id":"1.230178308","rc":[{"atb":[[3.4,4.94]],"id":40953876}],"con":true,"img":false}]}
{"op":"mcm","clk":"11540230974","pt":1719491627397,"mc":[{"id":"1.230178308","rc":[{"atb":[[1.31,38.28]],"id":44798446}],"con":true,"img":false}]}
{"op":"mcm","clk":"11540232060","pt":1719491644420,"mc":[{"id":"1.230178308","rc":[{"atb":[[2.88,6.31]],"id":39362025}],"con":true,"img":false}]}
{"op":"mcm","clk":"11540233011","pt":1719491658710,"mc":[{"id":"1.230178308","rc":[{"atb":[[2.4,0]],"id":48500723},{"atb":[[1.3,0]],"id":44798446},{"atb":[[2.38,0]],"id":70218235},{"atb":[[2.1,0]],"id":55829870}],"con":true,"img":false}]}
{"op":"mcm","clk":"11540234636","pt":1719491686138,"mc":[{"id":"1.230178308","rc":[{"atb":[[2.42,0]],"id":48500723},{"atb":[[1.31,0]],"id":44798446},{"atb":[[2.4,0]],"id":70218235},{"atb":[[2.12,0]],"id":55829870}],"con":true,"img":false}]}
{"op":"mcm","clk":"11540235117","pt":1719491692957,"mc":[{"id":"1.230178308","rc":[{"atb":[[3.35,0]],"id":40953876}],"con":true,"img":false}]}
{"op":"mcm","clk":"11540236555","pt":1719491714902,"mc":[{"id":"1.230178308","rc":[{"atb":[[2.9,3.38]],"id":39362025}],"con":true,"img":false}]}
{"op":"mcm","clk":"11540236572","pt":1719491715212,"mc":[{"id":"1.230178308","rc":[{"atb":[[2.9,10.72]],"id":39362025}],"con":true,"img":false}]}
{"op":"mcm","clk":"11540236588","pt":1719491715465,"mc":[{"id":"1.230178308","rc":[{"atb":[[3.45,5.69]],"id":40953876}],"con":true,"img":false}]}
{"op":"mcm","clk":"11540237507","pt":1719491730820,"mc":[{"id":"1.230178308","rc":[{"atb":[[3.4,0]],"id":40953876}],"con":true,"img":false}]}
{"op":"mcm","clk":"11540237526","pt":1719491731079,"mc":[{"id":"1.230178308","rc":[{"atb":[[2.32,8.98]],"id":70218235}],"con":true,"img":false}]}
{"op":"mcm","clk":"11540237532","pt":1719491731181,"mc":[{"id":"1.230178308","rc":[{"atb":[[2.34,8.85]],"id":48500723}],"con":true,"img":false}]}
{"op":"mcm","clk":"11540237538","pt":1719491731339,"mc":[{"id":"1.230178308","rc":[{"atb":[[1.27,43.95]],"id":44798446}],"con":true,"img":false}]}
{"op":"mcm","clk":"11540237553","pt":1719491731493,"mc":[{"id":"1.230178308","rc":[{"atb":[[2.04,11.4]],"id":55829870}],"con":true,"img":false}]}
{"op":"mcm","clk":"11540238850","pt":1719491752219,"mc":[{"id":"1.230178308","rc":[{"atb":[[2.88,0]],"id":39362025}],"con":true,"img":false}]}
{"op":"mcm","clk":"11540238967","pt":1719491753834,"mc":[{"id":"1.230178308","rc":[{"atb":[[2.92,6.17]],"id":39362025}],"con":true,"img":false}]}
{"op":"mcm","clk":"11540238975","pt":1719491753928,"mc":[{"id":"1.230178308","rc":[{"atb":[[3.5,4.74]],"id":40953876}],"con":true,"img":false}]}
{"op":"mcm","clk":"11540239184","pt":1719491757426,"mc":[{"id":"1.230178308","rc":[{"atb":[[2.9,7.34]],"id":39362025}],"con":true,"img":false}]}
{"op":"mcm","clk":"11540239204","pt":1719491757732,"mc":[{"id":"1.230178308","rc":[{"atb":[[2.94,3.38]],"id":39362025}],"con":true,"img":false}]}
{"op":"mcm","clk":"11540240425","pt":1719491777687,"mc":[{"id":"1.230178308","rc":[{"atb":[[3.45,0]],"id":40953876},{"atb":[[2.9,0]],"id":39362025}],"con":true,"img":false}]}
{"op":"mcm","clk":"11540241657","pt":1719491796906,"mc":[{"id":"1.230178308","rc":[{"atb":[[2.92,0]],"id":39362025}],"con":true,"img":false}]}
{"op":"mcm","clk":"11540241773","pt":1719491799485,"mc":[{"id":"1.230178308","rc":[{"atb":[[2.96,6.05]],"id":39362025}],"con":true,"img":false}]}
{"op":"mcm","clk":"11540241789","pt":1719491799796,"mc":[{"id":"1.230178308","rc":[{"atb":[[1.28,49.85]],"id":44798446}],"con":true,"img":false}]}
{"op":"mcm","clk":"11540241799","pt":1719491799900,"mc":[{"id":"1.230178308","rc":[{"atb":[[2.36,10.26]],"id":48500723}],"con":true,"img":false}]}
{"op":"mcm","clk":"11540241814","pt":1719491800107,"mc":[{"id":"1.230178308","rc":[{"atb":[[2.94,0]],"id":39362025}],"con":true,"img":false}]}
{"op":"mcm","clk":"11540241834","pt":1719491800367,"mc":[{"id":"1.230178308","rc":[{"atb":[[2.34,10.41]],"id":70218235},{"atb":[[2.06,13.16]],"id":55829870}],"con":true,"img":false}]}
{"op":"mcm","clk":"11540241846","pt":1719491800678,"mc":[{"id":"1.230178308","rc":[{"atb":[[3.55,5.47]],"id":40953876}],"con":true,"img":false}]}
{"op":"mcm","clk":"11540243409","pt":1719491826586,"mc":[{"id":"1.230178308","rc":[{"atb":[[3.5,0]],"id":40953876}],"con":true,"img":false}]}
{"op":"mcm","clk":"11540243672","pt":1719491830503,"mc":[{"id":"1.230178308","rc":[{"atb":[[3.6,4.56]],"id":40953876}],"con":true,"img":false}]}
{"op":"mcm","clk":"11540244622","pt":1719491846825,"mc":[{"id":"1.230178308","rc":[{"atb":[[2.96,0]],"id":39362025},{"atb":[[2.34,0]],"id":48500723},{"atb":[[1.27,0]],"id":44798446},{"atb":[[2.32,0]],"id":70218235},{"atb":[[2.04,0]],"id":55829870}],"con":true,"img":false}]}
{"op":"mcm","clk":"11540244849","pt":1719491851409,"mc":[{"id":"1.230178308","rc":[{"atb":[[2.88,6.31]],"id":39362025}],"con":true,"img":false}]}
{"op":"mcm","clk":"11540244855","pt":1719491851516,"mc":[{"id":"1.230178308","rc":[{"atb":[[2.08,10.98]],"id":55829870}],"con":true,"img":false}]}
{"op":"mcm","clk":"11540244861","pt":1719491851618,"mc":[{"id":"1.230178308","rc":[{"atb":[[2.36,8.72]],"id":70218235}],"con":true,"img":false}]}
{"op":"mcm","clk":"11540244865","pt":1719491851716,"mc":[{"id":"1.230178308","rc":[{"atb":[[1.29,40.91]],"id":44798446}],"con":true,"img":false}]}
{"op":"mcm","clk":"11540244870","pt":1719491851817,"mc":[{"id":"1.230178308","rc":[{"atb":[[2.38,8.59]],"id":48500723}],"con":true,"img":false}]}
{"op":"mcm","clk":"11540245346","pt":1719491862344,"mc":[{"id":"1.230178308","rc":[{"atb":[[3.55,0]],"id":40953876}],"con":true,"img":false}]}
{"op":"mcm","clk":"11540253468","pt":1719491907776,"mc":[{"id":"1.230178308","rc":[{"atb":[[3.6,0]],"id":40953876}],"con":true,"img":false}]}
{"op":"mcm","clk":"11540253734","pt":1719491912477,"mc":[{"id":"1.230178308","rc":[{"atb":[[3.35,5.04]],"id":40953876}],"con":true,"img":false}]}
{"op":"mcm","clk":"11540253990","pt":1719491916976,"mc":[{"id":"1.230178308","rc":[{"atb":[[2.36,0]],"id":48500723},{"atb":[[1.28,0]],"id":44798446},{"atb":[[2.34,0]],"id":70218235},{"atb":[[2.06,0]],"id":55829870}],"con":true,"img":false}]}
{"op":"mcm","clk":"11540254458","pt":1719491925890,"mc":[{"id":"1.230178308","rc":[{"atb":[[2.9,3.38]],"id":39362025}],"con":true,"img":false}]}
{"op":"mcm","clk":"11540254467","pt":1719491925994,"mc":[{"id":"1.230178308","rc":[{"atb":[[2.4,9.96]],"id":48500723}],"con":true,"img":false}]}
{"op":"mcm","clk":"11540254483","pt":1719491926202,"mc":[{"id":"1.230178308","rc":[{"atb":[[2.9,10.72]],"id":39362025}],"con":true,"img":false}]}
{"op":"mcm","clk":"11540254501","pt":1719491926418,"mc":[{"id":"1.230178308","rc":[{"atb":[[2.38,10.11]],"id":70218235}],"con":true,"img":false}]}
{"op":"mcm","clk":"11540254512","pt":1719491926566,"mc":[{"id":"1.230178308","rc":[{"atb":[[2.1,12.68]],"id":55829870}],"con":true,"img":false}]}
{"op":"mcm","clk":"11540254529","pt":1719491926874,"mc":[{"id":"1.230178308","rc":[{"atb":[[1.3,46.52]],"id":44798446}],"con":true,"img":false}]}
{"op":"mcm","clk":"11540256242","pt":1719491956477,"mc":[{"id":"1.230178308","rc":[{"atb":[[2.88,0]],"id":39362025},{"atb":[[2.38,0]],"id":48500723},{"atb":[[1.29,0]],"id":44798446},{"atb":[[2.36,0]],"id":70218235},{"atb":[[2.08,0]],"id":55829870}],"con":true,"img":false}]}
{"op":"mcm","clk":"11540256291","pt":1719491957456,"mc":[{"id":"1.230178308","rc":[{"atb":[[2.9,7.34]],"id":39362025}],"con":true,"img":false}]}
{"op":"mcm","clk":"11540256311","pt":1719491957765,"mc":[{"id":"1.230178308","rc":[{"atb":[[3.4,5.82]],"id":40953876}],"con":true,"img":false}]}
{"op":"mcm","clk":"11540256508","pt":1719491961178,"mc":[{"id":"1.230178308","rc":[{"atb":[[2.92,6.17]],"id":39362025}],"con":true,"img":false}]}
{"op":"mcm","clk":"11540256519","pt":1719491961388,"mc":[{"id":"1.230178308","rc":[{"atb":[[2.4,8.47]],"id":70218235}],"con":true,"img":false}]}
{"op":"mcm","clk":"11540256531","pt":1719491961594,"mc":[{"id":"1.230178308","rc":[{"atb":[[2.42,8.35]],"id":48500723}],"con":true,"img":false}]}
{"op":"mcm","clk":"11540256536","pt":1719491961693,"mc":[{"id":"1.230178308","rc":[{"atb":[[1.31,38.28]],"id":44798446}],"con":true,"img":false}]}
{"op":"mcm","clk":"11540256541","pt":1719491961755,"mc":[{"id":"1.230178308","rc":[{"atb":[[2.12,10.59]],"id":55829870}],"con":true,"img":false}]}
{"op":"mcm","clk":"11540257760","pt":1719491980712,"mc":[{"id":"1.230178308","rc":[{"atb":[[2.9,0]],"id":39362025},{"atb":[[2.4,0]],"id":48500723},{"atb":[[1.3,0]],"id":44798446},{"atb":[[2.38,0]],"id":70218235},{"atb":[[2.1,0]],"id":55829870}],"con":true,"img":false}]}
{"op":"mcm","clk":"11540257803","pt":1719491981289,"mc":[{"id":"1.230178308","rc":[{"atb":[[3.35,0]],"id":40953876}],"con":true,"img":false}]}
{"op":"mcm","clk":"11540258964","pt":1719492000550,"mc":[{"id":"1.230178308","rc":[{"atb":[[3.45,4.84]],"id":40953876}],"con":true,"img":false}]}
{"op":"mcm","clk":"11540260124","pt":1719492022011,"mc":[{"id":"1.230178308","rc":[{"atb":[[3.4,0]],"id":40953876}],"con":true,"img":false}]}
{"op":"mcm","clk":"11540260619","pt":1719492031533,"mc":[{"id":"1.230178308","rc":[{"atb":[[2.92,0]],"id":39362025},{"atb":[[2.42,0]],"id":48500723},{"atb":[[1.31,0]],"id":44798446},{"atb":[[2.4,0]],"id":70218235},{"atb":[[2.12,0]],"id":55829870}],"con":true,"img":false}]}
{"op":"mcm","clk":"11540260842","pt":1719492035633,"mc":[{"id":"1.230178308","rc":[{"atb":[[2.88,6.31]],"id":39362025},{"atb":[[1.27,43.95]],"id":44798446}],"con":true,"img":false}]}
{"op":"mcm","clk":"11540260850","pt":1719492035843,"mc":[{"id":"1.230178308","rc":[{"atb":[[2.32,8.98]],"id":70218235}],"con":true,"img":false}]}
{"op":"mcm","clk":"11540260854","pt":1719492035945,"mc":[{"id":"1.230178308","rc":[{"atb":[[2.34,8.85]],"id":48500723}],"con":true,"img":false}]}
{"op":"mcm","clk":"11540260862","pt":1719492036055,"mc":[{"id":"1.230178308","rc":[{"atb":[[2.04,11.4]],"id":55829870}],"con":true,"img":false}]}
{"op":"mcm","clk":"11540261958","pt":1719492056884,"mc":[{"id":"1.230178308","rc":[{"atb":[[3.45,0]],"id":40953876}],"con":true,"img":false}]}
{"op":"mcm","clk":"11540264157","pt":1719492096310,"mc":[{"id":"1.230178308","rc":[{"atb":[[3.35,5.04]],"id":40953876}],"con":true,"img":false}]}
{"op":"mcm","clk":"11540266278","pt":1719492130249,"mc":[{"id":"1.230178308","rc":[{"atb":[[2.9,3.38]],"id":39362025}],"con":true,"img":false}]}
{"op":"mcm","clk":"11540266298","pt":1719492130459,"mc":[{"id":"1.230178308","rc":[{"atb":[[2.9,10.72]],"id":39362025}],"con":true,"img":false}]}
{"op":"mcm","clk":"11540266304","pt":1719492130559,"mc":[{"id":"1.230178308","rc":[{"atb":[[2.34,10.41]],"id":70218235}],"con":true,"img":false}]}
{"op":"mcm","clk":"11540266329","pt":1719492130862,"mc":[{"id":"1.230178308","rc":[{"atb":[[1.28,49.85]],"id":44798446}],"con":true,"img":false}]}
{"op":"mcm","clk":"11540266342","pt":1719492131067,"mc":[{"id":"1.230178308","rc":[{"atb":[[2.36,10.26]],"id":48500723}],"con":true,"img":false}]}
{"op":"mcm","clk":"11540266347","pt":1719492131133,"mc":[{"id":"1.230178308","rc":[{"atb":[[2.06,13.16]],"id":55829870}],"con":true,"img":false}]}
{"op":"mcm","clk":"11540267548","pt":1719492154377,"mc":[{"id":"1.230178308","rc":[{"atb":[[2.88,0]],"id":39362025},{"atb":[[2.34,0]],"id":48500723},{"atb":[[1.27,0]],"id":44798446},{"atb":[[2.32,0]],"id":70218235},{"atb":[[2.04,0]],"id":55829870}],"con":true,"img":false}]}
{"op":"mcm","clk":"11540267567","pt":1719492154682,"mc":[{"id":"1.230178308","rc":[{"atb":[[2.92,6.17]],"id":39362025}],"con":true,"img":false}]}
{"op":"mcm","clk":"11540267573","pt":1719492154886,"mc":[{"id":"1.230178308","rc":[{"atb":[[2.36,8.72]],"id":70218235}],"con":true,"img":false}]}
{"op":"mcm","clk":"11540267581","pt":1719492155087,"mc":[{"id":"1.230178308","rc":[{"atb":[[2.38,8.59]],"id":48500723}],"con":true,"img":false}]}
{"op":"mcm","clk":"11540267588","pt":1719492155294,"mc":[{"id":"1.230178308","rc":[{"atb":[[1.29,40.91]],"id":44798446}],"con":true,"img":false}]}
{"op":"mcm","clk":"11540267598","pt":1719492155458,"mc":[{"id":"1.230178308","rc":[{"atb":[[2.08,10.98]],"id":55829870}],"con":true,"img":false}]}
{"op":"mcm","clk":"11540268340","pt":1719492170290,"mc":[{"id":"1.230178308","rc":[{"atb":[[2.9,7.34]],"id":39362025}],"con":true,"img":false}]}
{"op":"mcm","clk":"11540268356","pt":1719492170603,"mc":[{"id":"1.230178308","rc":[{"atb":[[3.4,5.82]],"id":40953876}],"con":true,"img":false}]}
{"op":"mcm","clk":"11540268372","pt":1719492170816,"mc":[{"id":"1.230178308","rc":[{"atb":[[2.94,3.38]],"id":39362025}],"con":true,"img":false}]}
{"op":"mcm","clk":"11540269414","pt":1719492191611,"mc":[{"id":"1.230178308","rc":[{"atb":[[2.9,0]],"id":39362025},{"atb":[[2.36,0]],"id":48500723},{"atb":[[1.28,0]],"id":44798446},{"atb":[[2.34,0]],"id":70218235},{"atb":[[2.06,0]],"id":55829870}],"con":true,"img":false}]}
{"op":"mcm","clk":"11540269624","pt":1719492195603,"mc":[{"id":"1.230178308","rc":[{"atb":[[2.94,10.57]],"id":39362025}],"con":true,"img":false}]}
{"op":"mcm","clk":"11540269637","pt":1719492195812,"mc":[{"id":"1.230178308","rc":[{"atb":[[2.38,10.11]],"id":70218235}],"con":true,"img":false}]}
{"op":"mcm","clk":"11540269649","pt":1719492196112,"mc":[{"id":"1.230178308","rc":[{"atb":[[1.3,46.52]],"id":44798446}],"con":true,"img":false}]}
{"op":"mcm","clk":"11540269662","pt":1719492196317,"mc":[{"id":"1.230178308","rc":[{"atb":[[2.1,12.68]],"id":55829870}],"con":true,"img":false}]}
{"op":"mcm","clk":"11540269668","pt":1719492196419,"mc":[{"id":"1.230178308","rc":[{"atb":[[2.4,9.96]],"id":48500723}],"con":true,"img":false}]}
{"op":"mcm","clk":"11540270117","pt":1719492206119,"mc":[{"id":"1.230178308","rc":[{"atb":[[3.35,0]],"id":40953876},{"atb":[[2.92,0]],"id":39362025}],"con":true,"img":false}]}
{"op":"mcm","clk":"11540270331","pt":1719492210612,"mc":[{"id":"1.230178308","rc":[{"atb":[[2.96,6.05]],"id":39362025}],"con":true,"img":false}]}
{"op":"mcm","clk":"11540270341","pt":1719492210814,"mc":[{"id":"1.230178308","rc":[{"atb":[[3.45,4.84]],"id":40953876}],"con":true,"img":false}]}
{"op":"mcm","clk":"11540271421","pt":1719492230527,"mc":[{"id":"1.230178308","rc":[{"atb":[[2.38,0]],"id":48500723},{"atb":[[1.29,0]],"id":44798446},{"atb":[[2.36,0]],"id":70218235},{"atb":[[2.08,0]],"id":55829870}],"con":true,"img":false}]}
{"op":"mcm","clk":"11540271701","pt":1719492234946,"mc":[{"id":"1.230178308","rc":[{"atb":[[2.4,8.47]],"id":70218235}],"con":true,"img":false}]}
{"op":"mcm","clk":"11540271706","pt":1719492235055,"mc":[{"id":"1.230178308","rc":[{"atb":[[1.31,38.28]],"id":44798446}],"con":true,"img":false}]}
{"op":"mcm","clk":"11540271712","pt":1719492235152,"mc":[{"id":"1.230178308","rc":[{"atb":[[2.42,8.35]],"id":48500723}],"con":true,"img":false}]}
{"op":"mcm","clk":"11540271721","pt":1719492235360,"mc":[{"id":"1.230178308","rc":[{"atb":[[2.12,10.59]],"id":55829870}],"con":true,"img":false}]}
{"op":"mcm","clk":"11540272382","pt":1719492247938,"mc":[{"id":"1.230178308","rc":[{"atb":[[2.94,7.19]],"id":39362025}],"con":true,"img":false}]}
{"op":"mcm","clk":"11540272400","pt":1719492248249,"mc":[{"id":"1.230178308","rc":[{"atb":[[2.98,3.38]],"id":39362025}],"con":true,"img":false}]}
{"op":"mcm","clk":"11540273638","pt":1719492270994,"mc":[{"id":"1.230178308","rc":[{"atb":[[3.4,0]],"id":40953876},{"atb":[[2.94,0]],"id":39362025},{"atb":[[2.4,0]],"id":48500723},{"atb":[[1.3,0]],"id":44798446},{"atb":[[2.38,0]],"id":70218235},{"atb":[[2.1,0]],"id":55829870}],"con":true,"img":false}]}
{"op":"mcm","clk":"11540273869","pt":1719492275690,"mc":[{"id":"1.230178308","rc":[{"atb":[[2.96,0]],"id":39362025}],"con":true,"img":false}]}
{"op":"mcm","clk":"11540273931","pt":1719492276993,"mc":[{"id":"1.230178308","rc":[{"atb":[[3,5.93]],"id":39362025}],"con":true,"img":false}]}
{"op":"mcm","clk":"11540274139","pt":1719492280603,"mc":[{"id":"1.230178308","rc":[{"atb":[[2.98,0]],"id":39362025}],"con":true,"img":false}]}
{"op":"mcm","clk":"11540274145","pt":1719492280704,"mc":[{"id":"1.230178308","rc":[{"atb":[[2.44,9.69]],"id":48500723}],"con":true,"img":false}]}
{"op":"mcm","clk":"11540274153","pt":1719492280909,"mc":[{"id":"1.230178308","rc":[{"atb":[[3.5,5.58]],"id":40953876}],"con":true,"img":false}]}
{"op":"mcm","clk":"11540274159","pt":1719492281014,"mc":[{"id":"1.230178308","rc":[{"atb":[[2.14,12.24]],"id":55829870}],"con":true,"img":false}]}
{"op":"mcm","clk":"11540274168","pt":1719492281175,"mc":[{"id":"1.230178308","rc":[{"atb":[[1.32,43.62]],"id":44798446}],"con":true,"img":false}]}
{"op":"mcm","clk":"11540274186","pt":1719492281481,"mc":[{"id":"1.230178308","rc":[{"atb":[[3.05,3.38]],"id":39362025},{"atb":[[2.42,9.82]],"id":70218235}],"con":true,"img":false}]}
{"op":"mcm","clk":"11540274999","pt":1719492297421,"mc":[{"id":"1.230178308","rc":[{"atb":[[3.45,0]],"id":40953876},{"atb":[[2.42,0]],"id":48500723},{"atb":[[1.31,0]],"id":44798446},{"atb":[[2.4,0]],"id":70218235},{"atb":[[2.12,0]],"id":55829870}],"con":true,"img":false}]}
{"op":"mcm","clk":"11540276284","pt":1719492318527,"mc":[{"id":"1.230178308","rc":[{"atb":[[3,0]],"id":39362025}],"con":true,"img":false}]}
{"op":"mcm","clk":"11540276330","pt":1719492319141,"mc":[{"id":"1.230178308","rc":[{"atb":[[3.1,5.64]],"id":39362025}],"con":true,"img":false}]}
{"op":"mcm","clk":"11540276336","pt":1719492319245,"mc":[{"id":"1.230178308","rc":[{"atb":[[2.44,8.24]],"id":70218235}],"con":true,"img":false}]}
{"op":"mcm","clk":"11540276341","pt":1719492319347,"mc":[{"id":"1.230178308","rc":[{"atb":[[1.33,35.95]],"id":44798446}],"con":true,"img":false}]}
{"op":"mcm","clk":"11540276354","pt":1719492319505,"mc":[{"id":"1.230178308","rc":[{"atb":[[2.46,8.12]],"id":48500723}],"con":true,"img":false}]}
{"op":"mcm","clk":"11540276374","pt":1719492319712,"mc":[{"id":"1.230178308","rc":[{"atb":[[2.16,10.22]],"id":55829870}],"con":true,"img":false}]}
{"op":"mcm","clk":"11540276390","pt":1719492319921,"mc":[{"id":"1.230178308","rc":[{"atb":[[3.55,4.65]],"id":40953876}],"con":true,"img":false}]}
{"op":"mcm","clk":"11540276441","pt":1719492320731,"mc":[{"id":"1.230178308","rc":[{"atb":[[3.05,0]],"id":39362025}],"con":true,"img":false}]}
{"op":"mcm","clk":"11540278529","pt":1719492354776,"mc":[{"id":"1.230178308","rc":[{"atb":[[3.5,0]],"id":40953876},{"atb":[[2.44,0]],"id":48500723},{"atb":[[1.32,0]],"id":44798446},{"atb":[[2.42,0]],"id":70218235},{"atb":[[2.14,0]],"id":55829870}],"con":true,"img":false}]}
{"op":"mcm","clk":"11540279037","pt":1719492363165,"mc":[{"id":"1.230178308","rc":[{"atb":[[3.15,6.49]],"id":39362025}],"con":true,"img":false}]}
{"op":"mcm","clk":"11540279360","pt":1719492367962,"mc":[{"id":"1.230178308","rc":[{"atb":[[3.1,0]],"id":39362025}],"con":true,"img":false}]}
{"op":"mcm","clk":"11540280190","pt":1719492382105,"mc":[{"id":"1.230178308","rc":[{"atb":[[3.55,0]],"id":40953876},{"atb":[[2.46,0]],"id":48500723},{"atb":[[1.33,0]],"id":44798446},{"atb":[[2.44,0]],"id":70218235},{"atb":[[2.16,0]],"id":55829870}],"con":true,"img":false}]}
{"op":"mcm","clk":"11540281486","pt":1719492400012,"mc":[{"id":"1.230178308","rc":[{"atb":[[3.35,5.04]],"id":40953876},{"atb":[[3.2,5.39]],"id":39362025}],"con":true,"img":false}]}
{"op":"mcm","clk":"11540281499","pt":1719492400212,"mc":[{"id":"1.230178308","rc":[{"atb":[[1.27,43.95]],"id":44798446},{"atb":[[2.04,11.4]],"id":55829870}],"con":true,"img":false}]}
{"op":"mcm","clk":"11540281512","pt":1719492400416,"mc":[{"id":"1.230178308","rc":[{"atb":[[2.32,8.98]],"id":70218235}],"con":true,"img":false}]}
{"op":"mcm","clk":"11540281520","pt":1719492400521,"mc":[{"id":"1.230178308","rc":[{"atb":[[2.34,8.85]],"id":48500723}],"con":true,"img":false}]}
{"op":"mcm","clk":"11540283768","pt":1719492439373,"mc":[{"id":"1.230178308","rc":[{"atb":[[3.15,0]],"id":39362025}],"con":true,"img":false}]}
{"op":"mcm","clk":"11540284189","pt":1719492447868,"mc":[{"id":"1.230178308","rc":[{"atb":[[3.25,6.2]],"id":39362025}],"con":true,"img":false}]}
{"op":"mcm","clk":"11540284201","pt":1719492448078,"mc":[{"id":"1.230178308","rc":[{"atb":[[2.34,10.41]],"id":70218235}],"con":true,"img":false}]}
{"op":"mcm","clk":"11540284210","pt":1719492448180,"mc":[{"id":"1.230178308","rc":[{"atb":[[1.28,49.85]],"id":44798446}],"con":true,"img":false}]}
{"op":"mcm","clk":"11540284220","pt":1719492448379,"mc":[{"id":"1.230178308","rc":[{"atb":[[2.36,10.26]],"id":48500723}],"con":true,"img":false}]}
{"op":"mcm","clk":"11540284228","pt":1719492448482,"mc":[{"id":"1.230178308","rc":[{"atb":[[3.4,5.82]],"id":40953876}],"con":true,"img":false}]}
{"op":"mcm","clk":"11540284255","pt":1719492448892,"mc":[{"id":"1.230178308","rc":[{"atb":[[2.06,13.16]],"id":55829870}],"con":true,"img":false}]}
{"op":"mcm","clk":"11540285808","pt":1719492473403,"mc":[{"id":"1.230178308","rc":[{"atb":[[3.35,0]],"id":40953876},{"atb":[[3.2,0]],"id":39362025},{"atb":[[2.34,0]],"id":48500723},{"atb":[[1.27,0]],"id":44798446},{"atb":[[2.32,0]],"id":70218235},{"atb":[[2.04,0]],"id":55829870}],"con":true,"img":false}]}
{"op":"mcm","clk":"11540285879","pt":1719492474228,"mc":[{"id":"1.230178308","rc":[{"atb":[[3.3,5.15]],"id":39362025}],"con":true,"img":false}]}
{"op":"mcm","clk":"11540285895","pt":1719492474433,"mc":[{"id":"1.230178308","rc":[{"atb":[[2.36,8.72]],"id":70218235}],"con":true,"img":false}]}
{"op":"mcm","clk":"11540285910","pt":1719492474601,"mc":[{"id":"1.230178308","rc":[{"atb":[[1.29,40.91]],"id":44798446}],"con":true,"img":false}]}
{"op":"mcm","clk":"11540285924","pt":1719492474799,"mc":[{"id":"1.230178308","rc":[{"atb":[[3.45,4.84]],"id":40953876}],"con":true,"img":false}]}
{"op":"mcm","clk":"11540285937","pt":1719492475053,"mc":[{"id":"1.230178308","rc":[{"atb":[[2.38,8.59]],"id":48500723}],"con":true,"img":false}]}
{"op":"mcm","clk":"11540285953","pt":1719492475308,"mc":[{"id":"1.230178308","rc":[{"atb":[[2.08,10.98]],"id":55829870}],"con":true,"img":false}]}
{"op":"mcm","clk":"11540288419","pt":1719492517071,"mc":[{"id":"1.230178308","rc":[{"atb":[[3.4,0]],"id":40953876},{"atb":[[3.25,0]],"id":39362025},{"atb":[[2.36,0]],"id":48500723},{"atb":[[1.28,0]],"id":44798446},{"atb":[[2.34,0]],"id":70218235},{"atb":[[2.06,0]],"id":55829870}],"con":true,"img":false}]}
{"op":"mcm","clk":"11540289077","pt":1719492526760,"mc":[{"id":"1.230178308","rc":[{"atb":[[3.35,5.93]],"id":39362025}],"con":true,"img":false}]}
{"op":"mcm","clk":"11540289085","pt":1719492526862,"mc":[{"id":"1.230178308","rc":[{"atb":[[1.3,46.52]],"id":44798446}],"con":true,"img":false}]}
{"op":"mcm","clk":"11540289095","pt":1719492527061,"mc":[{"id":"1.230178308","rc":[{"atb":[[2.4,9.96]],"id":48500723}],"con":true,"img":false}]}
{"op":"mcm","clk":"11540289113","pt":1719492527374,"mc":[{"id":"1.230178308","rc":[{"atb":[[3.5,5.58]],"id":40953876},{"atb":[[2.38,10.11]],"id":70218235}],"con":true,"img":false}]}
{"op":"mcm","clk":"11540289147","pt":1719492527690,"mc":[{"id":"1.230178308","rc":[{"atb":[[2.1,12.68]],"id":55829870}],"con":true,"img":false}]}
{"op":"mcm","clk":"11540290179","pt":1719492544018,"mc":[{"id":"1.230178308","rc":[{"atb":[[3.45,0]],"id":40953876},{"atb":[[3.3,0]],"id":39362025},{"atb":[[2.38,0]],"id":48500723},{"atb":[[1.29,0]],"id":44798446},{"atb":[[2.36,0]],"id":70218235},{"atb":[[2.08,0]],"id":55829870}],"con":true,"img":false}]}
{"op":"mcm","clk":"11540291274","pt":1719492561800,"mc":[{"id":"1.230178308","rc":[{"atb":[[3.4,4.94]],"id":39362025}],"con":true,"img":false}]}
{"op":"mcm","clk":"11540291278","pt":1719492561902,"mc":[{"id":"1.230178308","rc":[{"atb":[[2.42,8.35]],"id":48500723}],"con":true,"img":false}]}
{"op":"mcm","clk":"11540291286","pt":1719492562008,"mc":[{"id":"1.230178308","rc":[{"atb":[[1.31,38.28]],"id":44798446}],"con":true,"img":false}]}
{"op":"mcm","clk":"11540291292","pt":1719492562108,"mc":[{"id":"1.230178308","rc":[{"atb":[[2.4,8.47]],"id":70218235}],"con":true,"img":false}]}
{"op":"mcm","clk":"11540291303","pt":1719492562216,"mc":[{"id":"1.230178308","rc":[{"atb":[[3.55,4.65]],"id":40953876}],"con":true,"img":false}]}
{"op":"mcm","clk":"11540291312","pt":1719492562312,"mc":[{"id":"1.230178308","rc":[{"atb":[[2.12,10.59]],"id":55829870}],"con":true,"img":false}]}
{"op":"mcm","clk":"11540293668","pt":1719492598847,"mc":[{"id":"1.230178308","rc":[{"atb":[[3.5,0]],"id":40953876},{"atb":[[3.35,0]],"id":39362025},{"atb":[[2.4,0]],"id":48500723},{"atb":[[1.3,0]],"id":44798446},{"atb":[[2.38,0]],"id":70218235},{"atb":[[2.1,0]],"id":55829870}],"con":true,"img":false}]}
{"op":"mcm","clk":"11540294293","pt":1719492607082,"mc":[{"id":"1.230178308","rc":[{"atb":[[2.88,3.38]],"id":39362025}],"con":true,"img":false}]}
{"op":"mcm","clk":"11540294313","pt":1719492607237,"mc":[{"id":"1.230178308","rc":[{"atb":[[3.45,5.69]],"id":39362025}],"con":true,"img":false}]}
{"op":"mcm","clk":"11540294322","pt":1719492607341,"mc":[{"id":"1.230178308","rc":[{"atb":[[2.44,9.69]],"id":48500723}],"con":true,"img":false}]}
{"op":"mcm","clk":"11540294345","pt":1719492607549,"mc":[{"id":"1.230178308","rc":[{"atb":[[1.32,43.62]],"id":44798446}],"con":true,"img":false}]}
{"op":"mcm","clk":"11540294356","pt":1719492607656,"mc":[{"id":"1.230178308","rc":[{"atb":[[2.42,9.82]],"id":70218235}],"con":true,"img":false}]}
{"op":"mcm","clk":"11540294371","pt":1719492607860,"mc":[{"id":"1.230178308","rc":[{"atb":[[3.6,5.37]],"id":40953876}],"con":true,"img":false}]}
{"op":"mcm","clk":"11540294381","pt":1719492607962,"mc":[{"id":"1.230178308","rc":[{"atb":[[2.14,12.24]],"id":55829870}],"con":true,"img":false}]}
{"op":"mcm","clk":"11540296372","pt":1719492637014,"mc":[{"id":"1.230178308","rc":[{"spl":[[1.01,1]],"id":40953876}],"con":true,"img":false}]}
{"op":"mcm","clk":"11540296568","pt":1719492639905,"mc":[{"id":"1.230178308","rc":[{"atb":[[3.55,0]],"id":40953876},{"atb":[[3.4,0]],"id":39362025},{"atb":[[2.42,0]],"id":48500723},{"atb":[[1.31,0]],"id":44798446},{"atb":[[2.4,0]],"id":70218235},{"atb":[[2.12,0]],"id":55829870}],"con":true,"img":false}]}
{"op":"mcm","clk":"11540296625","pt":1719492640685,"mc":[{"id":"1.230178308","rc":[{"atb":[[3.5,4.74]],"id":39362025}],"con":true,"img":false}]}
{"op":"mcm","clk":"11540296630","pt":1719492640788,"mc":[{"id":"1.230178308","rc":[{"atb":[[1.33,35.95]],"id":44798446}],"con":true,"img":false}]}
{"op":"mcm","clk":"11540296637","pt":1719492640888,"mc":[{"id":"1.230178308","rc":[{"atb":[[2.46,8.12]],"id":48500723}],"con":true,"img":false}]}
{"op":"mcm","clk":"11540296645","pt":1719492640995,"mc":[{"id":"1.230178308","rc":[{"atb":[[2.16,10.22]],"id":55829870}],"con":true,"img":false}]}
{"op":"mcm","clk":"11540296648","pt":1719492641094,"mc":[{"id":"1.230178308","rc":[{"atb":[[2.44,8.24]],"id":70218235}],"con":true,"img":false}]}
{"op":"mcm","clk":"11540300392","pt":1719492682566,"mc":[{"id":"1.230178308","rc":[{"atb":[[3.6,0]],"id":40953876},{"spn":8.0,"spf":1.0,"id":40953876},{"atb":[[3.45,0]],"id":39362025},{"atb":[[2.44,0]],"id":48500723},{"atb":[[1.32,0]],"id":44798446},{"atb":[[2.42,0]],"id":70218235},{"atb":[[2.14,0]],"id":55829870}],"con":true,"img":false}]}
{"op":"mcm","clk":"11540300984","pt":1719492692152,"mc":[{"id":"1.230178308","rc":[{"atb":[[3.55,5.47]],"id":39362025}],"con":true,"img":false}]}
{"op":"mcm","clk":"11540300994","pt":1719492692257,"mc":[{"id":"1.230178308","rc":[{"atb":[[3.35,5.93]],"id":40953876}],"con":true,"img":false}]}
{"op":"mcm","clk":"11540301012","pt":1719492692463,"mc":[{"id":"1.230178308","rc":[{"atb":[[2.46,9.55]],"id":70218235}],"con":true,"img":false}]}
{"op":"mcm","clk":"11540301021","pt":1719492692566,"mc":[{"id":"1.230178308","rc":[{"atb":[[1.34,41.05]],"id":44798446}],"con":true,"img":false}]}
{"op":"mcm","clk":"11540301034","pt":1719492692773,"mc":[{"id":"1.230178308","rc":[{"atb":[[2.48,9.43]],"id":48500723}],"con":true,"img":false}]}
{"op":"mcm","clk":"11540301056","pt":1719492693083,"mc":[{"id":"1.230178308","rc":[{"atb":[[2.18,11.82]],"id":55829870}],"con":true,"img":false}]}
{"op":"mcm","clk":"11540302342","pt":1719492714612,"mc":[{"id":"1.230178308","rc":[{"atb":[[3.5,0]],"id":39362025},{"atb":[[2.46,0]],"id":48500723},{"atb":[[1.33,0]],"id":44798446},{"atb":[[2.44,0]],"id":70218235},{"atb":[[2.16,0]],"id":55829870}],"con":true,"img":false}]}
{"op":"mcm","clk":"11540302813","pt":1719492720711,"mc":[{"id":"1.230178308","rc":[{"atb":[[3.6,4.56]],"id":39362025},{"atb":[[2.5,7.91]],"id":48500723}],"con":true,"img":false}]}
{"op":"mcm","clk":"11540302845","pt":1719492721126,"mc":[{"id":"1.230178308","rc":[{"atb":[[2.2,9.88]],"id":55829870}],"con":true,"img":false}]}
{"op":"mcm","clk":"11540302861","pt":1719492721333,"mc":[{"id":"1.230178308","rc":[{"atb":[[3.4,4.94]],"id":40953876}],"con":true,"img":false}]}
{"op":"mcm","clk":"11540302895","pt":1719492721695,"mc":[{"id":"1.230178308","rc":[{"atb":[[1.35,33.9]],"id":44798446}],"con":true,"img":false}]}
{"op":"mcm","clk":"11540302906","pt":1719492721900,"mc":[{"id":"1.230178308","rc":[{"atb":[[2.48,8.02]],"id":70218235}],"con":true,"img":false}]}
{"op":"mcm","clk":"11540304546","pt":1719492746123,"mc":[{"id":"1.230178308","rc":[{"atb":[[3.35,0]],"id":40953876},{"atb":[[3.55,0]],"id":39362025},{"atb":[[2.48,0]],"id":48500723},{"atb":[[1.34,0]],"id":44798446},{"atb":[[2.46,0]],"id":70218235},{"atb":[[2.18,0]],"id":55829870}],"con":true,"img":false}]}
{"op":"mcm","clk":"11540306359","pt":1719492774463,"mc":[{"id":"1.230178308","rc":[{"atb":[[1.36,38.77]],"id":44798446}],"con":true,"img":false}]}
{"op":"mcm","clk":"11540306372","pt":1719492774669,"mc":[{"id":"1.230178308","rc":[{"atb":[[2.22,11.44]],"id":55829870}],"con":true,"img":false}]}
{"op":"mcm","clk":"11540306379","pt":1719492774773,"mc":[{"id":"1.230178308","rc":[{"atb":[[3.45,5.69]],"id":40953876}],"con":true,"img":false}]}
{"op":"mcm","clk":"11540306411","pt":1719492775286,"mc":[{"id":"1.230178308","rc":[{"atb":[[2.52,9.18]],"id":48500723}],"con":true,"img":false}]}
{"op":"mcm","clk":"11540307046","pt":1719492784283,"mc":[{"id":"1.230178308","rc":[{"atb":[[3.4,0]],"id":40953876},{"atb":[[3.6,0]],"id":39362025},{"atb":[[2.5,0]],"id":48500723},{"atb":[[1.35,0]],"id":44798446},{"atb":[[2.48,0]],"id":70218235},{"atb":[[2.2,0]],"id":55829870}],"con":true,"img":false}]}
{"op":"mcm","clk":"11540307112","pt":1719492785064,"mc":[{"id":"1.230178308","rc":[{"atb":[[2.9,6.24]],"id":39362025}],"con":true,"img":false}]}
{"op":"mcm","clk":"11540307124","pt":1719492785269,"mc":[{"id":"1.230178308","rc":[{"atb":[[2.32,8.98]],"id":70218235}],"con":true,"img":false}]}
{"op":"mcm","clk":"11540307836","pt":1719492795294,"mc":[{"id":"1.230178308","rc":[{"atb":[[2.88,0]],"id":39362025}],"con":true,"img":false}]}
{"op":"mcm","clk":"11540307862","pt":1719492795601,"mc":[{"id":"1.230178308","rc":[{"atb":[[2.92,3.38]],"id":39362025}],"con":true,"img":false}]}
{"op":"mcm","clk":"11540308478","pt":1719492805599,"mc":[{"id":"1.230178308","rc":[{"atb":[[1.37,32.07]],"id":44798446}],"con":true,"img":false}]}
{"op":"mcm","clk":"11540308497","pt":1719492805806,"mc":[{"id":"1.230178308","rc":[{"atb":[[2.54,7.7]],"id":48500723}],"con":true,"img":false}]}
{"op":"mcm","clk":"11540308517","pt":1719492806009,"mc":[{"id":"1.230178308","rc":[{"atb":[[3.5,4.74]],"id":40953876}],"con":true,"img":false}]}
{"op":"mcm","clk":"11540308534","pt":1719492806214,"mc":[{"id":"1.230178308","rc":[{"atb":[[2.24,9.57]],"id":55829870}],"con":true,"img":false}]}
{"op":"mcm","clk":"11540309627","pt":1719492820763,"mc":[{"id":"1.230178308","rc":[{"atb":[[3.45,0]],"id":40953876},{"atb":[[2.52,0]],"id":48500723},{"atb":[[1.36,0]],"id":44798446},{"atb":[[2.22,0]],"id":55829870}],"con":true,"img":false}]}
{"op":"mcm","clk":"11540310075","pt":1719492826119,"mc":[{"id":"1.230178308","rc":[{"atb":[[2.9,0]],"id":39362025}],"con":true,"img":false}]}
{"op":"mcm","clk":"11540310138","pt":1719492827051,"mc":[{"id":"1.230178308","rc":[{"atb":[[2.94,6.11]],"id":39362025}],"con":true,"img":false}]}
{"op":"mcm","clk":"11540310586","pt":1719492833058,"mc":[{"id":"1.230178308","rc":[{"atb":[[2.92,0]],"id":39362025}],"con":true,"img":false}]}
{"op":"mcm","clk":"11540310608","pt":1719492833321,"mc":[{"id":"1.230178308","rc":[{"atb":[[2.34,10.41]],"id":70218235}],"con":true,"img":false}]}
{"op":"mcm","clk":"11540310642","pt":1719492833632,"mc":[{"id":"1.230178308","rc":[{"atb":[[2.96,3.38]],"id":39362025}],"con":true,"img":false}]}
{"op":"mcm","clk":"11540311735","pt":1719492847757,"mc":[{"id":"1.230178308","rc":[{"atb":[[3.5,0]],"id":40953876},{"atb":[[2.54,0]],"id":48500723},{"atb":[[1.37,0]],"id":44798446},{"atb":[[2.24,0]],"id":55829870}],"con":true,"img":false}]}
{"op":"mcm","clk":"11540313371","pt":1719492868818,"mc":[{"id":"1.230178308","rc":[{"atb":[[2.94,0]],"id":39362025},{"atb":[[2.32,0]],"id":70218235}],"con":true,"img":false}]}
{"op":"mcm","clk":"11540313533","pt":1719492869400,"mc":[{"id":"1.230178308","rc":[{"atb":[[2.96,10.5]],"id":39362025}],"con":true,"img":false}]}
{"op":"mcm","clk":"11540315186","pt":1719492887896,"mc":[{"id":"1.230178308","rc":[{"atb":[[2.98,5.99]],"id":39362025}],"con":true,"img":false}]}
{"op":"mcm","clk":"11540315193","pt":1719492887998,"mc":[{"id":"1.230178308","rc":[{"atb":[[2.36,8.72]],"id":70218235}],"con":true,"img":false}]}
{"op":"mcm","clk":"11540315199","pt":1719492888101,"mc":[{"id":"1.230178308","rc":[{"atb":[[1.27,43.95]],"id":44798446}],"con":true,"img":false}]}
{"op":"mcm","clk":"11540315211","pt":1719492888310,"mc":[{"id":"1.230178308","rc":[{"atb":[[2.04,11.4]],"id":55829870}],"con":true,"img":false}]}
{"op":"mcm","clk":"11540315221","pt":1719492888515,"mc":[{"id":"1.230178308","rc":[{"atb":[[3.35,5.04]],"id":40953876}],"con":true,"img":false}]}
{"op":"mcm","clk":"11540315234","pt":1719492888678,"mc":[{"id":"1.230178308","rc":[{"atb":[[2.34,8.85]],"id":48500723}],"con":true,"img":false}]}
{"op":"mcm","clk":"11540316990","pt":1719492910828,"mc":[{"id":"1.230178308","rc":[{"atb":[[2.96,7.12]],"id":39362025}],"con":true,"img":false}]}
{"op":"mcm","clk":"11540317011","pt":1719492911200,"mc":[{"id":"1.230178308","rc":[{"atb":[[3,3.38]],"id":39362025}],"con":true,"img":false}]}
{"op":"mcm","clk":"11540319346","pt":1719492945762,"mc":[{"id":"1.230178308","rc":[{"atb":[[2.96,0]],"id":39362025},{"atb":[[2.34,0]],"id":70218235}],"con":true,"img":false}]}
{"op":"mcm","clk":"11540319667","pt":1719492950772,"mc":[{"id":"1.230178308","rc":[{"atb":[[2.98,0]],"id":39362025}],"con":true,"img":false}]}
{"op":"mcm","clk":"11540319970","pt":1719492955345,"mc":[{"id":"1.230178308","rc":[{"atb":[[3,0]],"id":39362025},{"atb":[[1.28,49.85]],"id":44798446}],"con":true,"img":false}]}
{"op":"mcm","clk":"11540319988","pt":1719492955651,"mc":[{"id":"1.230178308","rc":[{"atb":[[3.4,5.82]],"id":40953876},{"atb":[[2.38,10.11]],"id":70218235}],"con":true,"img":false}]}
{"op":"mcm","clk":"11540320003","pt":1719492955981,"mc":[{"id":"1.230178308","rc":[{"atb":[[2.36,10.26]],"id":48500723}],"con":true,"img":false}]}
{"op":"mcm","clk":"11540320022","pt":1719492956264,"mc":[{"id":"1.230178308","rc":[{"atb":[[2.06,13.16]],"id":55829870}],"con":true,"img":false}]}
{"op":"mcm","clk":"11540321126","pt":1719492970758,"mc":[{"id":"1.230178308","rc":[{"atb":[[2.36,0]],"id":70218235}],"con":true,"img":false}]}
{"op":"mcm","clk":"11540322579","pt":1719492992880,"mc":[{"id":"1.230178308","rc":[{"atb":[[3.35,0]],"id":40953876},{"atb":[[2.34,0]],"id":48500723},{"atb":[[1.27,0]],"id":44798446},{"atb":[[2.04,0]],"id":55829870}],"con":true,"img":false}]}
{"op":"mcm","clk":"11540322595","pt":1719492993084,"mc":[{"id":"1.230178308","rc":[{"atb":[[2.88,6.31]],"id":39362025},{"atb":[[2.4,8.47]],"id":70218235}],"con":true,"img":false}]}
{"op":"mcm","clk":"11540323854","pt":1719493010498,"mc":[{"id":"1.230178308","rc":[{"atb":[[1.29,40.91]],"id":44798446}],"con":true,"img":false}]}
{"op":"mcm","clk":"11540323862","pt":1719493010595,"mc":[{"id":"1.230178308","rc":[{"atb":[[3.45,4.84]],"id":40953876}],"con":true,"img":false}]}
{"op":"mcm","clk":"11540323868","pt":1719493010700,"mc":[{"id":"1.230178308","rc":[{"atb":[[2.38,8.59]],"id":48500723}],"con":true,"img":false}]}
{"op":"mcm","clk":"11540323879","pt":1719493010904,"mc":[{"id":"1.230178308","rc":[{"atb":[[2.08,10.98]],"id":55829870}],"con":true,"img":false}]}
{"op":"mcm","clk":"11540325485","pt":1719493036247,"mc":[{"id":"1.230178308","rc":[{"atb":[[3.4,0]],"id":40953876},{"atb":[[2.36,0]],"id":48500723},{"atb":[[1.28,0]],"id":44798446},{"atb":[[2.38,0]],"id":70218235},{"atb":[[2.06,0]],"id":55829870}],"con":true,"img":false}]}
{"op":"mcm","clk":"11540325546","pt":1719493037234,"mc":[{"id":"1.230178308","rc":[{"atb":[[3.45,0]],"id":40953876},{"atb":[[2.38,0]],"id":48500723},{"atb":[[1.29,0]],"id":44798446},{"atb":[[2.08,0]],"id":55829870}],"con":true,"img":false}]}
{"op":"mcm","clk":"11540326174","pt":1719493045558,"mc":[{"id":"1.230178308","rc":[{"atb":[[2.9,3.38]],"id":39362025}],"con":true,"img":false}]}
{"op":"mcm","clk":"11540326195","pt":1719493045766,"mc":[{"id":"1.230178308","rc":[{"atb":[[2.34,10.41]],"id":48500723}],"con":true,"img":false}]}
{"op":"mcm","clk":"11540326208","pt":1719493045824,"mc":[{"id":"1.230178308","rc":[{"atb":[[2.9,10.72]],"id":39362025}],"con":true,"img":false}]}
{"op":"mcm","clk":"11540326238","pt":1719493046136,"mc":[{"id":"1.230178308","rc":[{"atb":[[3.35,5.93]],"id":40953876}],"con":true,"img":false}]}
{"op":"mcm","clk":"11540326258","pt":1719493046342,"mc":[{"id":"1.230178308","rc":[{"atb":[[2.04,13.41]],"id":55829870}],"con":true,"img":false}]}
{"op":"mcm","clk":"11540326269","pt":1719493046443,"mc":[{"id":"1.230178308","rc":[{"atb":[[1.27,51.7]],"id":44798446}],"con":true,"img":false}]}
{"op":"mcm","clk":"11540326307","pt":1719493046959,"mc":[{"id":"1.230178308","rc":[{"atb":[[2.42,9.82]],"id":70218235}],"con":true,"img":false}]}
{"op":"mcm","clk":"11540327487","pt":1719493064382,"mc":[{"id":"1.230178308","rc":[{"atb":[[2.4,0]],"id":70218235}],"con":true,"img":false}]}
{"op":"mcm","clk":"11540327896","pt":1719493070181,"mc":[{"id":"1.230178308","rc":[{"atb":[[2.88,0]],"id":39362025}],"con":true,"img":false}]}
{"op":"mcm","clk":"11540327923","pt":1719493070539,"mc":[{"id":"1.230178308","rc":[{"atb":[[2.92,6.17]],"id":39362025}],"con":true,"img":false}]}
{"op":"mcm","clk":"11540327928","pt":1719493070649,"mc":[{"id":"1.230178308","rc":[{"atb":[[3.4,4.94]],"id":40953876}],"con":true,"img":false}]}
{"op":"mcm","clk":"11540327934","pt":1719493070745,"mc":[{"id":"1.230178308","rc":[{"atb":[[2.44,8.24]],"id":70218235}],"con":true,"img":false}]}
{"op":"mcm","clk":"11540327947","pt":1719493070957,"mc":[{"id":"1.230178308","rc":[{"atb":[[1.28,42.38]],"id":44798446}],"con":true,"img":false}]}
{"op":"mcm","clk":"11540327962","pt":1719493071171,"mc":[{"id":"1.230178308","rc":[{"atb":[[2.36,8.72]],"id":48500723},{"atb":[[2.06,11.19]],"id":55829870}],"con":true,"img":false}]}
{"op":"mcm","clk":"11540329256","pt":1719493088071,"mc":[{"id":"1.230178308","rc":[{"atb":[[2.9,7.34]],"id":39362025}],"con":true,"img":false}]}
{"op":"mcm","clk":"11540329348","pt":1719493089275,"mc":[{"id":"1.230178308","rc":[{"atb":[[2.94,3.38]],"id":39362025}],"con":true,"img":false}]}
{"op":"mcm","clk":"11540331208","pt":1719493116219,"mc":[{"id":"1.230178308","rc":[{"atb":[[3.35,0]],"id":40953876},{"atb":[[2.9,0]],"id":39362025},{"atb":[[2.34,0]],"id":48500723},{"atb":[[1.27,0]],"id":44798446},{"atb":[[2.42,0]],"id":70218235},{"atb":[[2.04,0]],"id":55829870}],"con":true,"img":false}]}
{"op":"mcm","clk":"11540331938","pt":1719493126106,"mc":[{"id":"1.230178308","rc":[{"atb":[[1.29,48.12]],"id":44798446},{"atb":[[2.46,9.55]],"id":70218235}],"con":true,"img":false}]}
{"op":"mcm","clk":"11540331969","pt":1719493126524,"mc":[{"id":"1.230178308","rc":[{"atb":[[3.45,5.69]],"id":40953876}],"con":true,"img":false}]}
{"op":"mcm","clk":"11540331978","pt":1719493126728,"mc":[{"id":"1.230178308","rc":[{"atb":[[2.08,12.92]],"id":55829870}],"con":true,"img":false}]}
{"op":"mcm","clk":"11540332011","pt":1719493127147,"mc":[{"id":"1.230178308","rc":[{"atb":[[2.38,10.11]],"id":48500723}],"con":true,"img":false}]}
{"op":"mcm","clk":"11540332019","pt":1719493127245,"mc":[{"id":"1.230178308","rc":[{"atb":[[2.94,10.57]],"id":39362025}],"con":true,"img":false}]}
{"op":"mcm","clk":"11540333033","pt":1719493141641,"mc":[{"id":"1.230178308","rc":[{"atb":[[2.92,0]],"id":39362025}],"con":true,"img":false}]}
{"op":"mcm","clk":"11540333334","pt":1719493146258,"mc":[{"id":"1.230178308","rc":[{"atb":[[3.4,0]],"id":40953876},{"atb":[[2.36,0]],"id":48500723},{"atb":[[1.28,0]],"id":44798446},{"atb":[[2.44,0]],"id":70218235},{"atb":[[2.06,0]],"id":55829870}],"con":true,"img":false}]}
{"op":"mcm","clk":"11540333399","pt":1719493147032,"mc":[{"id":"1.230178308","rc":[{"atb":[[2.96,6.05]],"id":39362025}],"con":true,"img":false}]}
{"op":"mcm","clk":"11540334973","pt":1719493169964,"mc":[{"id":"1.230178308","rc":[{"atb":[[2.48,8.02]],"id":70218235}],"con":true,"img":false}]}
{"op":"mcm","clk":"11540334979","pt":1719493170067,"mc":[{"id":"1.230178308","rc":[{"atb":[[1.3,39.55]],"id":44798446}],"con":true,"img":false}]}
{"op":"mcm","clk":"11540334996","pt":1719493170378,"mc":[{"id":"1.230178308","rc":[{"atb":[[3.5,4.74]],"id":40953876},{"atb":[[2.4,8.47]],"id":48500723}],"con":true,"img":false}]}
{"op":"mcm","clk":"11540335013","pt":1719493170584,"mc":[{"id":"1.230178308","rc":[{"atb":[[2.1,10.79]],"id":55829870}],"con":true,"img":false}]}
{"op":"mcm","clk":"11540335341","pt":1719493175260,"mc":[{"id":"1.230178308","rc":[{"atb":[[2.94,7.19]],"id":39362025}],"con":true,"img":false}]}
{"op":"mcm","clk":"11540335359","pt":1719493175573,"mc":[{"id":"1.230178308","rc":[{"atb":[[2.98,3.38]],"id":39362025}],"con":true,"img":false}]}
{"op":"mcm","clk":"11540336632","pt":1719493195883,"mc":[{"id":"1.230178308","rc":[{"atb":[[3.45,0]],"id":40953876},{"atb":[[2.94,0]],"id":39362025},{"atb":[[2.38,0]],"id":48500723},{"atb":[[1.29,0]],"id":44798446},{"atb":[[2.46,0]],"id":70218235},{"atb":[[2.08,0]],"id":55829870}],"con":true,"img":false}]}
{"op":"mcm","clk":"11540338060","pt":1719493216002,"mc":[{"id":"1.230178308","rc":[{"atb":[[1.01,23.68],[3.5,4.74],[2.16,8.55]],"id":40953876},{"atl":[[990,0.22]],"id":40953876},{"spl":[[1.01,1.71]],"id":39362025},{"atb":[[2.24,8.89],[1.03,7.89],[2.98,10.45],[2.96,6.04]],"id":39362025},{"atl":[[1000,0.22]],"id":39362025},{"atb":[[2.4,8.46],[2.32,13.33],[1.03,7.89]],"id":48500723},{"atl":[[990,0.22]],"id":48500723},{"atb":[[1.01,23.68],[2.32,11.97],[1.3,39.5],[2.34,6.54]],"id":44798446},{"atl":[[1000,0.22]],"id":44798446},{"atb":[[2.3,13.21],[1.03,7.89],[2.48,8.01]],"id":70218235},{"atl":[[990,0.22]],"id":70218235},{"atb":[[2.36,11.23],[2.88,6.54],[1.02,11.84],[2.1,10.77]],"id":55829870},{"atl":[[1000,0.22]],"id":55829870}],"con":true,"img":false}]}
{"op":"mcm","clk":"11540338069","pt":1719493216104,"mc":[{"id":"1.230178308","rc":[{"atb":[[2.5,9.31]],"id":70218235}],"con":true,"img":false}]}
{"op":"mcm","clk":"11540338087","pt":1719493216311,"mc":[{"id":"1.230178308","rc":[{"atb":[[1.31,45.08]],"id":44798446}],"con":true,"img":false}]}
{"op":"mcm","clk":"11540338110","pt":1719493216621,"mc":[{"id":"1.230178308","rc":[{"atb":[[3.55,5.47]],"id":40953876},{"atb":[[2.42,9.84]],"id":48500723}],"con":true,"img":false}]}
{"op":"mcm","clk":"11540338153","pt":1719493217191,"mc":[{"id":"1.230178308","rc":[{"atb":[[2.12,12.47]],"id":55829870}],"con":true,"img":false}]}
{"op":"mcm","clk":"11540338704","pt":1719493225312,"mc":[{"id":"1.230178308","rc":[{"atb":[[2.96,0]],"id":39362025}],"con":true,"img":false}]}
{"op":"mcm","clk":"11540339074","pt":1719493230632,"mc":[{"id":"1.230178308","rc":[{"atb":[[3,5.92]],"id":39362025}],"con":true,"img":false}]}
{"op":"mcm","clk":"11540339091","pt":1719493230842,"mc":[{"id":"1.230178308","rc":[{"atb":[[3.5,0]],"id":40953876},{"atb":[[2.4,0]],"id":48500723},{"atb":[[1.3,0]],"id":44798446},{"atb":[[2.48,0]],"id":70218235},{"atb":[[2.1,0]],"id":55829870}],"con":true,"img":false}]}
{"op":"mcm","clk":"11540340245","pt":1719493245727,"mc":[{"id":"1.230178308","rc":[{"atb":[[2.98,7.06]],"id":39362025}],"con":true,"img":false}]}
{"op":"mcm","clk":"11540340272","pt":1719493246137,"mc":[{"id":"1.230178308","rc":[{"atb":[[3.05,3.38]],"id":39362025}],"con":true,"img":false}]}
{"op":"mcm","clk":"11540340673","pt":1719493251728,"mc":[{"id":"1.230178308","rc":[{"atb":[[2.52,7.79]],"id":70218235}],"con":true,"img":false}]}
{"op":"mcm","clk":"11540340688","pt":1719493251930,"mc":[{"id":"1.230178308","rc":[{"atb":[[3.6,4.55]],"id":40953876},{"atb":[[2.44,8.23]],"id":48500723}],"con":true,"img":false}]}
{"op":"mcm","clk":"11540340697","pt":1719493252139,"mc":[{"id":"1.230178308","rc":[{"atb":[[1.32,37.03]],"id":44798446},{"atb":[[2.14,10.39]],"id":55829870}],"con":true,"img":false}]}
{"op":"mcm","clk":"11540342182","pt":1719493273069,"mc":[{"id":"1.230178308","rc":[{"atb":[[3,0]],"id":39362025}],"con":true,"img":false}]}
{"op":"mcm","clk":"11540342498","pt":1719493278171,"mc":[{"id":"1.230178308","rc":[{"atb":[[3.1,5.64]],"id":39362025}],"con":true,"img":false}]}
{"op":"mcm","clk":"11540342813","pt":1719493283283,"mc":[{"id":"1.230178308","rc":[{"atb":[[3.55,0]],"id":40953876},{"atb":[[2.98,0]],"id":39362025},{"atb":[[2.42,0]],"id":48500723},{"atb":[[1.31,0]],"id":44798446},{"atb":[[2.5,0]],"id":70218235},{"atb":[[2.12,0]],"id":55829870}],"con":true,"img":false}]}
{"op":"mcm","clk":"11540343626","pt":1719493292979,"mc":[{"id":"1.230178308","rc":[{"atb":[[3.05,0]],"id":39362025}],"con":true,"img":false}]}
{"op":"mcm","clk":"11540345423","pt":1719493319194,"mc":[{"id":"1.230178308","rc":[{"atb":[[3.15,6.5]],"id":39362025}],"con":true,"img":false}]}
{"op":"mcm","clk":"11540345436","pt":1719493319402,"mc":[{"id":"1.230178308","rc":[{"atb":[[2.54,9.07]],"id":70218235}],"con":true,"img":false}]}
{"op":"mcm","clk":"11540345445","pt":1719493319510,"mc":[{"id":"1.230178308","rc":[{"atb":[[1.33,42.34]],"id":44798446}],"con":true,"img":false}]}
{"op":"mcm","clk":"11540345466","pt":1719493319809,"mc":[{"id":"1.230178308","rc":[{"atb":[[2.46,9.57]],"id":48500723}],"con":true,"img":false}]}
{"op":"mcm","clk":"11540345474","pt":1719493319922,"mc":[{"id":"1.230178308","rc":[{"atb":[[2.16,12.04]],"id":55829870}],"con":true,"img":false}]}
{"op":"mcm","clk":"11540345895","pt":1719493325629,"mc":[{"id":"1.230178308","rc":[{"atb":[[3.6,0]],"id":40953876},{"atb":[[2.44,0]],"id":48500723},{"atb":[[1.32,0]],"id":44798446},{"atb":[[2.52,0]],"id":70218235},{"atb":[[2.14,0]],"id":55829870}],"con":true,"img":false}]}
{"op":"mcm","clk":"11540346265","pt":1719493330136,"mc":[{"id":"1.230178308","rc":[{"atb":[[3.1,0]],"id":39362025}],"con":true,"img":false}]}
{"op":"mcm","clk":"11540346309","pt":1719493330718,"mc":[{"id":"1.230178308","rc":[{"atb":[[3.35,5.04]],"id":40953876}],"con":true,"img":false}]}
{"op":"mcm","clk":"11540347673","pt":1719493350951,"mc":[{"id":"1.230178308","rc":[{"atb":[[3.2,5.38]],"id":39362025}],"con":true,"img":false}]}
{"op":"mcm","clk":"11540347680","pt":1719493351056,"mc":[{"id":"1.230178308","rc":[{"atb":[[2.56,7.6]],"id":70218235}],"con":true,"img":false}]}
{"op":"mcm","clk":"11540347693","pt":1719493351263,"mc":[{"id":"1.230178308","rc":[{"atb":[[1.34,34.85]],"id":44798446}],"con":true,"img":false}]}
{"op":"mcm","clk":"11540347703","pt":1719493351366,"mc":[{"id":"1.230178308","rc":[{"atb":[[2.48,8.01]],"id":48500723}],"con":true,"img":false}]}
{"op":"mcm","clk":"11540347706","pt":1719493351429,"mc":[{"id":"1.230178308","rc":[{"atb":[[2.18,10.04]],"id":55829870}],"con":true,"img":false}]}
{"op":"mcm","clk":"11540349191","pt":1719493375472,"mc":[{"id":"1.230178308","rc":[{"atb":[[3.15,0]],"id":39362025},{"atb":[[2.46,0]],"id":48500723},{"atb":[[1.33,0]],"id":44798446},{"atb":[[2.54,0]],"id":70218235},{"atb":[[2.16,0]],"id":55829870}],"con":true,"img":false}]}
{"op":"mcm","clk":"11540351288","pt":1719493406209,"mc":[{"id":"1.230178308","rc":[{"atb":[[3.4,5.82]],"id":40953876}],"con":true,"img":false}]}
{"op":"mcm","clk":"11540352530","pt":1719493423704,"mc":[{"id":"1.230178308","rc":[{"atb":[[3.2,0]],"id":39362025},{"atb":[[2.48,0]],"id":48500723},{"atb":[[1.34,0]],"id":44798446},{"atb":[[2.56,0]],"id":70218235},{"atb":[[2.18,0]],"id":55829870}],"con":true,"img":false}]}
{"op":"mcm","clk":"11540353028","pt":1719493429897,"mc":[{"id":"1.230178308","rc":[{"atb":[[2.88,6.3]],"id":39362025}],"con":true,"img":false}]}
{"op":"mcm","clk":"11540353050","pt":1719493430106,"mc":[{"id":"1.230178308","rc":[{"atb":[[2.32,8.97]],"id":70218235}],"con":true,"img":false}]}
{"op":"mcm","clk":"11540353071","pt":1719493430318,"mc":[{"id":"1.230178308","rc":[{"atb":[[1.27,43.89]],"id":44798446}],"con":true,"img":false}]}
{"op":"mcm","clk":"11540353086","pt":1719493430518,"mc":[{"id":"1.230178308","rc":[{"atb":[[2.34,8.84]],"id":48500723}],"con":true,"img":false}]}
{"op":"mcm","clk":"11540353106","pt":1719493430735,"mc":[{"id":"1.230178308","rc":[{"atb":[[2.04,11.39]],"id":55829870}],"con":true,"img":false}]}
{"op":"mcm","clk":"11540354206","pt":1719493445145,"mc":[{"id":"1.230178308","rc":[{"atb":[[3.35,0]],"id":40953876}],"con":true,"img":false}]}
{"op":"mcm","clk":"11540354756","pt":1719493451149,"mc":[{"id":"1.230178308","rc":[{"atb":[[3.45,4.83]],"id":40953876}],"con":true,"img":false}]}
{"op":"mcm","clk":"11540356683","pt":1719493475433,"mc":[{"id":"1.230178308","rc":[{"atb":[[3.4,0]],"id":40953876}],"con":true,"img":false}]}
{"op":"mcm","clk":"11540357624","pt":1719493486385,"mc":[{"id":"1.230178308","rc":[{"atb":[[2.9,3.38]],"id":39362025}],"con":true,"img":false}]}
{"op":"mcm","clk":"11540357635","pt":1719493486585,"mc":[{"id":"1.230178308","rc":[{"atb":[[2.9,10.73]],"id":39362025}],"con":true,"img":false}]}
{"op":"mcm","clk":"11540357644","pt":1719493486647,"mc":[{"id":"1.230178308","rc":[{"atb":[[2.34,10.42]],"id":70218235}],"con":true,"img":false}]}
{"op":"mcm","clk":"11540357662","pt":1719493486960,"mc":[{"id":"1.230178308","rc":[{"atb":[[2.36,10.27]],"id":48500723}],"con":true,"img":false}]}
{"op":"mcm","clk":"11540357668","pt":1719493487053,"mc":[{"id":"1.230178308","rc":[{"atb":[[1.28,49.91]],"id":44798446}],"con":true,"img":false}]}
{"op":"mcm","clk":"11540357683","pt":1719493487262,"mc":[{"id":"1.230178308","rc":[{"atb":[[2.06,13.17]],"id":55829870}],"con":true,"img":false}]}
{"op":"mcm","clk":"11540359485","pt":1719493510497,"mc":[{"id":"1.230178308","rc":[{"atb":[[3.45,0]],"id":40953876},{"atb":[[2.88,0]],"id":39362025},{"atb":[[2.34,0]],"id":48500723},{"atb":[[1.27,0]],"id":44798446},{"atb":[[2.32,0]],"id":70218235},{"atb":[[2.04,0]],"id":55829870}],"con":true,"img":false}]}
{"op":"mcm","clk":"11540360574","pt":1719493525046,"mc":[{"id":"1.230178308","rc":[{"atb":[[2.9,7.35]],"id":39362025}],"con":true,"img":false}]}
{"op":"mcm","clk":"11540360892","pt":1719493529745,"mc":[{"id":"1.230178308","rc":[{"atb":[[2.92,6.17]],"id":39362025},{"atb":[[1.29,40.86]],"id":44798446}],"con":true,"img":false}]}
{"op":"mcm","clk":"11540360907","pt":1719493529900,"mc":[{"id":"1.230178308","rc":[{"atb":[[3.35,5.04]],"id":40953876},{"atb":[[2.36,8.71]],"id":70218235}],"con":true,"img":false}]}
{"op":"mcm","clk":"11540360924","pt":1719493530109,"mc":[{"id":"1.230178308","rc":[{"atb":[[2.38,8.58]],"id":48500723},{"atb":[[2.08,10.97]],"id":55829870}],"con":true,"img":false}]}
{"op":"mcm","clk":"11540362957","pt":1719493556638,"mc":[{"id":"1.230178308","rc":[{"atb":[[2.9,0]],"id":39362025},{"atb":[[2.36,0]],"id":48500723},{"atb":[[1.28,0]],"id":44798446},{"atb":[[2.34,0]],"id":70218235},{"atb":[[2.06,0]],"id":55829870}],"con":true,"img":false}]}
{"op":"mcm","clk":"11540366930","pt":1719493604320,"mc":[{"id":"1.230178308","rc":[{"atb":[[2.94,7.19]],"id":39362025},{"atb":[[2.38,10.12]],"id":70218235}],"con":true,"img":false}]}
{"op":"mcm","clk":"11540366939","pt":1719493604424,"mc":[{"id":"1.230178308","rc":[{"atb":[[2.92,0]],"id":39362025},{"atb":[[2.38,0]],"id":48500723},{"atb":[[1.29,0]],"id":44798446},{"atb":[[2.36,0]],"id":70218235},{"atb":[[2.08,0]],"id":55829870}],"con":true,"img":false}]}
{"op":"mcm","clk":"11540366954","pt":1719493604629,"mc":[{"id":"1.230178308","rc":[{"atb":[[2.4,9.97]],"id":48500723},{"atb":[[1.3,46.58]],"id":44798446}],"con":true,"img":false}]}
{"op":"mcm","clk":"11540366975","pt":1719493604897,"mc":[{"id":"1.230178308","rc":[{"atb":[[2.1,12.7]],"id":55829870}],"con":true,"img":false}]}
{"op":"mcm","clk":"11540366995","pt":1719493605201,"mc":[{"id":"1.230178308","rc":[{"atb":[[2.94,10.58]],"id":39362025}],"con":true,"img":false}]}
{"op":"mcm","clk":"11540367003","pt":1719493605305,"mc":[{"id":"1.230178308","rc":[{"atb":[[3.4,5.82]],"id":40953876}],"con":true,"img":false}]}
{"op":"mcm","clk":"11540368997","pt":1719493630936,"mc":[{"id":"1.230178308","rc":[{"atb":[[3.35,0]],"id":40953876}],"con":true,"img":false}]}
{"op":"mcm","clk":"11540369007","pt":1719493631037,"mc":[{"id":"1.230178308","rc":[{"atb":[[2.4,8.46]],"id":70218235}],"con":true,"img":false}]}
{"op":"mcm","clk":"11540369015","pt":1719493631142,"mc":[{"id":"1.230178308","rc":[{"atb":[[2.12,10.57]],"id":55829870}],"con":true,"img":false}]}
{"op":"mcm","clk":"11540369035","pt":1719493631348,"mc":[{"id":"1.230178308","rc":[{"atb":[[2.42,8.34]],"id":48500723},{"atb":[[1.31,38.23]],"id":44798446}],"con":true,"img":false}]}
{"op":"mcm","clk":"11540369054","pt":1719493631557,"mc":[{"id":"1.230178308","rc":[{"atb":[[2.96,6.04]],"id":39362025}],"con":true,"img":false}]}
{"op":"mcm","clk":"11540370321","pt":1719493646970,"mc":[{"id":"1.230178308","rc":[{"atb":[[2.94,7.19]],"id":39362025}],"con":true,"img":false}]}
{"op":"mcm","clk":"11540370348","pt":1719493647439,"mc":[{"id":"1.230178308","rc":[{"atb":[[2.98,3.38]],"id":39362025}],"con":true,"img":false}]}
{"op":"mcm","clk":"11540370913","pt":1719493654672,"mc":[{"id":"1.230178308","rc":[{"atb":[[3.45,4.83]],"id":40953876}],"con":true,"img":false}]}
{"op":"mcm","clk":"11540371881","pt":1719493667957,"mc":[{"id":"1.230178308","rc":[{"atb":[[3.4,0]],"id":40953876},{"atb":[[2.94,0]],"id":39362025},{"atb":[[2.4,0]],"id":48500723},{"atb":[[1.3,0]],"id":44798446},{"atb":[[2.38,0]],"id":70218235},{"atb":[[2.1,0]],"id":55829870}],"con":true,"img":false}]}
{"op":"mcm","clk":"11540372556","pt":1719493676862,"mc":[{"id":"1.230178308","rc":[{"atb":[[2.98,10.45]],"id":39362025}],"con":true,"img":false}]}
{"op":"mcm","clk":"11540372576","pt":1719493677067,"mc":[{"id":"1.230178308","rc":[{"atb":[[1.32,43.67]],"id":44798446}],"con":true,"img":false}]}
{"op":"mcm","clk":"11540372586","pt":1719493677171,"mc":[{"id":"1.230178308","rc":[{"atb":[[2.42,9.84]],"id":70218235}],"con":true,"img":false}]}
{"op":"mcm","clk":"11540372610","pt":1719493677480,"mc":[{"id":"1.230178308","rc":[{"atb":[[2.44,9.7]],"id":48500723}],"con":true,"img":false}]}
{"op":"mcm","clk":"11540372614","pt":1719493677582,"mc":[{"id":"1.230178308","rc":[{"atb":[[2.14,12.26]],"id":55829870}],"con":true,"img":false}]}
{"op":"mcm","clk":"11540373340","pt":1719493687198,"mc":[{"id":"1.230178308","rc":[{"atb":[[2.96,0]],"id":39362025}],"con":true,"img":false}]}
{"op":"mcm","clk":"11540373668","pt":1719493691480,"mc":[{"id":"1.230178308","rc":[{"atb":[[3,5.92]],"id":39362025}],"con":true,"img":false}]}
{"op":"mcm","clk":"11540374739","pt":1719493706515,"mc":[{"id":"1.230178308","rc":[{"atb":[[3.45,0]],"id":40953876},{"atb":[[2.42,0]],"id":48500723},{"atb":[[1.31,0]],"id":44798446},{"atb":[[2.4,0]],"id":70218235},{"atb":[[2.12,0]],"id":55829870}],"con":true,"img":false}]}
{"op":"mcm","clk":"11540375135","pt":1719493711915,"mc":[{"id":"1.230178308","rc":[{"atb":[[2.44,8.23]],"id":70218235}],"con":true,"img":false}]}
{"op":"mcm","clk":"11540375152","pt":1719493712121,"mc":[{"id":"1.230178308","rc":[{"atb":[[2.46,8.11]],"id":48500723},{"atb":[[1.33,35.9]],"id":44798446}],"con":true,"img":false}]}
{"op":"mcm","clk":"11540375171","pt":1719493712327,"mc":[{"id":"1.230178308","rc":[{"atb":[[3.35,5.04]],"id":40953876},{"atb":[[2.16,10.21]],"id":55829870}],"con":true,"img":false}]}
{"op":"mcm","clk":"11540376107","pt":1719493725042,"mc":[{"id":"1.230178308","rc":[{"atb":[[2.98,7.06]],"id":39362025}],"con":true,"img":false}]}
{"op":"mcm","clk":"11540376133","pt":1719493725315,"mc":[{"id":"1.230178308","rc":[{"atb":[[3.05,3.38]],"id":39362025}],"con":true,"img":false}]}
{"op":"mcm","clk":"11540378245","pt":1719493752836,"mc":[{"id":"1.230178308","rc":[{"atb":[[3,0]],"id":39362025}],"con":true,"img":false}]}
{"op":"mcm","clk":"11540378362","pt":1719493754339,"mc":[{"id":"1.230178308","rc":[{"atb":[[2.98,0]],"id":39362025},{"atb":[[2.44,0]],"id":48500723},{"atb":[[1.32,0]],"id":44798446},{"atb":[[2.42,0]],"id":70218235},{"atb":[[2.14,0]],"id":55829870}],"con":true,"img":false}]}
{"op":"mcm","clk":"11540378448","pt":1719493755544,"mc":[{"id":"1.230178308","rc":[{"atb":[[3.1,5.64]],"id":39362025}],"con":true,"img":false}]}
{"op":"mcm","clk":"11540379361","pt":1719493765184,"mc":[{"id":"1.230178308","rc":[{"atb":[[3.05,0]],"id":39362025}],"con":true,"img":false}]}
{"op":"mcm","clk":"11540379375","pt":1719493765353,"mc":[{"id":"1.230178308","rc":[{"atb":[[2.46,9.57]],"id":70218235}],"con":true,"img":false}]}
{"op":"mcm","clk":"11540379385","pt":1719493765454,"mc":[{"id":"1.230178308","rc":[{"atb":[[1.34,41.1]],"id":44798446}],"con":true,"img":false}]}
{"op":"mcm","clk":"11540379411","pt":1719493765757,"mc":[{"id":"1.230178308","rc":[{"atb":[[2.48,9.44]],"id":48500723}],"con":true,"img":false}]}
{"op":"mcm","clk":"11540379419","pt":1719493765856,"mc":[{"id":"1.230178308","rc":[{"atb":[[3.4,5.82]],"id":40953876}],"con":true,"img":false}]}
{"op":"mcm","clk":"11540379438","pt":1719493766065,"mc":[{"id":"1.230178308","rc":[{"atb":[[2.18,11.84]],"id":55829870}],"con":true,"img":false}]}
{"op":"mcm","clk":"11540381235","pt":1719493786979,"mc":[{"id":"1.230178308","rc":[{"atb":[[2.46,0]],"id":48500723},{"atb":[[1.33,0]],"id":44798446},{"atb":[[2.44,0]],"id":70218235},{"atb":[[2.16,0]],"id":55829870}],"con":true,"img":false}]}
{"op":"mcm","clk":"11540381654","pt":1719493792292,"mc":[{"id":"1.230178308","rc":[{"atb":[[3.35,0]],"id":40953876},{"atb":[[3.1,0]],"id":39362025},{"atb":[[2.48,8.01]],"id":70218235}],"con":true,"img":false}]}
{"op":"mcm","clk":"11540381670","pt":1719493792491,"mc":[{"id":"1.230178308","rc":[{"atb":[[2.5,7.9]],"id":48500723}],"con":true,"img":false}]}
{"op":"mcm","clk":"11540381679","pt":1719493792596,"mc":[{"id":"1.230178308","rc":[{"atb":[[1.35,33.86]],"id":44798446}],"con":true,"img":false}]}
{"op":"mcm","clk":"11540381687","pt":1719493792697,"mc":[{"id":"1.230178308","rc":[{"atb":[[2.2,9.87]],"id":55829870}],"con":true,"img":false}]}
{"op":"mcm","clk":"11540383971","pt":1719493818925,"mc":[{"id":"1.230178308","rc":[{"atb":[[2.88,6.3]],"id":39362025}],"con":true,"img":false}]}
{"op":"mcm","clk":"11540383984","pt":1719493819121,"mc":[{"id":"1.230178308","rc":[{"atb":[[3.45,4.83]],"id":40953876}],"con":true,"img":false}]}
{"op":"mcm","clk":"11540384815","pt":1719493828956,"mc":[{"id":"1.230178308","rc":[{"atb":[[3.4,0]],"id":40953876},{"atb":[[2.48,0]],"id":48500723},{"atb":[[1.34,0]],"id":44798446},{"atb":[[2.46,0]],"id":70218235},{"atb":[[2.18,0]],"id":55829870}],"con":true,"img":false}]}
{"op":"mcm","clk":"11540386347","pt":1719493846874,"mc":[{"id":"1.230178308","rc":[{"atb":[[1.36,38.82]],"id":44798446}],"con":true,"img":false}]}
{"op":"mcm","clk":"11540386358","pt":1719493846979,"mc":[{"id":"1.230178308","rc":[{"atb":[[2.52,9.19]],"id":48500723}],"con":true,"img":false}]}
{"op":"mcm","clk":"11540386401","pt":1719493847349,"mc":[{"id":"1.230178308","rc":[{"atb":[[2.22,11.45]],"id":55829870}],"con":true,"img":false}]}
{"op":"mcm","clk":"11540386411","pt":1719493847458,"mc":[{"id":"1.230178308","rc":[{"atb":[[2.5,9.31]],"id":70218235}],"con":true,"img":false}]}
{"op":"mcm","clk":"11540388508","pt":1719493871879,"mc":[{"id":"1.230178308","rc":[{"atb":[[3.45,0]],"id":40953876},{"atb":[[2.5,0]],"id":48500723},{"atb":[[1.35,0]],"id":44798446},{"atb":[[2.48,0]],"id":70218235},{"atb":[[2.2,0]],"id":55829870}],"con":true,"img":false}]}
{"op":"mcm","clk":"11540388970","pt":1719493877590,"mc":[{"id":"1.230178308","rc":[{"atb":[[2.52,7.79]],"id":70218235},{"atb":[[2.24,9.55]],"id":55829870}],"con":true,"img":false}]}
{"op":"mcm","clk":"11540388981","pt":1719493877798,"mc":[{"id":"1.230178308","rc":[{"atb":[[1.37,32.02]],"id":44798446}],"con":true,"img":false}]}
{"op":"mcm","clk":"11540388988","pt":1719493877903,"mc":[{"id":"1.230178308","rc":[{"atb":[[3.35,5.04]],"id":40953876}],"con":true,"img":false}]}
{"op":"mcm","clk":"11540389005","pt":1719493878169,"mc":[{"id":"1.230178308","rc":[{"atb":[[2.54,7.69]],"id":48500723}],"con":true,"img":false}]}
{"op":"mcm","clk":"11540390034","pt":1719493891010,"mc":[{"id":"1.230178308","rc":[{"atb":[[2.9,3.38]],"id":39362025}],"con":true,"img":false}]}
{"op":"mcm","clk":"11540390044","pt":1719493891113,"mc":[{"id":"1.230178308","rc":[{"atb":[[2.9,10.73]],"id":39362025}],"con":true,"img":false}]}
{"op":"mcm","clk":"11540392193","pt":1719493922623,"mc":[{"id":"1.230178308","rc":[{"atb":[[2.52,0]],"id":48500723},{"atb":[[1.36,0]],"id":44798446},{"atb":[[2.5,0]],"id":70218235},{"atb":[[2.22,0]],"id":55829870}],"con":true,"img":false}]}
{"op":"mcm","clk":"11540392799","pt":1719493929947,"mc":[{"id":"1.230178308","rc":[{"atb":[[2.88,0]],"id":39362025}],"con":true,"img":false}]}
{"op":"mcm","clk":"11540393048","pt":1719493933469,"mc":[{"id":"1.230178308","rc":[{"atb":[[2.9,7.35]],"id":39362025},{"atb":[[1.38,36.77]],"id":44798446}],"con":true,"img":false}]}
{"op":"mcm","clk":"11540393068","pt":1719493933731,"mc":[{"id":"1.230178308","rc":[{"atb":[[3.4,5.82]],"id":40953876},{"atb":[[2.54,9.07]],"id":70218235}],"con":true,"img":false}]}
{"op":"mcm","clk":"11540393087","pt":1719493934043,"mc":[{"id":"1.230178308","rc":[{"atb":[[2.26,11.08]],"id":55829870}],"con":true,"img":false}]}
{"op":"mcm","clk":"11540393109","pt":1719493934361,"mc":[{"id":"1.230178308","rc":[{"atb":[[2.56,8.96]],"id":48500723}],"con":true,"img":false}]}
{"op":"mcm","clk":"11540393290","pt":1719493936842,"mc":[{"id":"1.230178308","rc":[{"atb":[[2.92,6.17]],"id":39362025}],"con":true,"img":false}]}
{"op":"mcm","clk":"11540394609","pt":1719493953798,"mc":[{"id":"1.230178308","rc":[{"atb":[[2.9,0]],"id":39362025}],"con":true,"img":false}]}
{"op":"mcm","clk":"11540395985","pt":1719493971577,"mc":[{"id":"1.230178308","rc":[{"atb":[[3.35,0]],"id":40953876},{"atb":[[2.54,0]],"id":48500723},{"atb":[[1.37,0]],"id":44798446},{"atb":[[2.52,0]],"id":70218235},{"atb":[[2.24,0]],"id":55829870}],"con":true,"img":false}]}
{"op":"mcm","clk":"11540396456","pt":1719493977615,"mc":[{"id":"1.230178308","rc":[{"atb":[[2.92,0]],"id":39362025}],"con":true,"img":false}]}
{"op":"mcm","clk":"11540396485","pt":1719493977985,"mc":[{"id":"1.230178308","rc":[{"atb":[[2.56,7.6]],"id":70218235}],"con":true,"img":false}]}
{"op":"mcm","clk":"11540396493","pt":1719493978088,"mc":[{"id":"1.230178308","rc":[{"atb":[[2.28,9.25]],"id":55829870}],"con":true,"img":false}]}
{"op":"mcm","clk":"11540396498","pt":1719493978186,"mc":[{"id":"1.230178308","rc":[{"atb":[[1.39,30.38]],"id":44798446}],"con":true,"img":false}]}
{"op":"mcm","clk":"11540396504","pt":1719493978289,"mc":[{"id":"1.230178308","rc":[{"atb":[[2.58,7.49]],"id":48500723}],"con":true,"img":false}]}
{"op":"mcm","clk":"11540396507","pt":1719493978397,"mc":[{"id":"1.230178308","rc":[{"atb":[[3.45,4.83]],"id":40953876}],"con":true,"img":false}]}
{"op":"mcm","clk":"11540397739","pt":1719493994898,"mc":[{"id":"1.230178308","rc":[{"atb":[[2.32,0]],"id":44798446}],"con":true,"img":false}]}
{"op":"mcm","clk":"11540397747","pt":1719493995003,"mc":[{"id":"1.230178308","rc":[{"atb":[[2.36,11.97]],"id":44798446}],"con":true,"img":false}]}
{"op":"mcm","clk":"11540398142","pt":1719493999606,"mc":[{"id":"1.230178308","rc":[{"atb":[[3.4,0]],"id":40953876},{"atb":[[2.56,0]],"id":48500723},{"atb":[[1.38,0]],"id":44798446},{"atb":[[2.54,0]],"id":70218235},{"atb":[[2.26,0]],"id":55829870}],"con":true,"img":false}]}
{"op":"mcm","clk":"11540398205","pt":1719494000331,"mc":[{"id":"1.230178308","rc":[{"atb":[[2.34,3.38]],"id":44798446}],"con":true,"img":false}]}
{"op":"mcm","clk":"11540398228","pt":1719494000538,"mc":[{"id":"1.230178308","rc":[{"atb":[[2.38,3.16]],"id":44798446}],"con":true,"img":false}]}
{"op":"mcm","clk":"11540400404","pt":1719494026757,"mc":[{"id":"1.230178308","rc":[{"atb":[[2.34,0]],"id":44798446}],"con":true,"img":false}]}
{"op":"mcm","clk":"11540400428","pt":1719494027023,"mc":[{"id":"1.230178308","rc":[{"atb":[[2.38,6.54]],"id":44798446}],"con":true,"img":false}]}
{"op":"mcm","clk":"11540400647","pt":1719494029836,"mc":[{"id":"1.230178308","rc":[{"atb":[[3.45,0]],"id":40953876},{"atb":[[2.58,0]],"id":48500723},{"atb":[[1.39,0]],"id":44798446},{"atb":[[2.56,0]],"id":70218235},{"atb":[[2.28,0]],"id":55829870}],"con":true,"img":false}]}
{"op":"mcm","clk":"11540402754","pt":1719494054472,"mc":[{"id":"1.230178308","rc":[{"atb":[[2.88,6.3]],"id":39362025}],"con":true,"img":false}]}
{"op":"mcm","clk":"11540402763","pt":1719494054568,"mc":[{"id":"1.230178308","rc":[{"atb":[[3.35,5.04]],"id":40953876}],"con":true,"img":false}]}
{"op":"mcm","clk":"11540402768","pt":1719494054673,"mc":[{"id":"1.230178308","rc":[{"atb":[[2.34,8.84]],"id":48500723}],"con":true,"img":false}]}
{"op":"mcm","clk":"11540402780","pt":1719494054878,"mc":[{"id":"1.230178308","rc":[{"atb":[[2.32,8.97]],"id":70218235}],"con":true,"img":false}]}
{"op":"mcm","clk":"11540402788","pt":1719494054982,"mc":[{"id":"1.230178308","rc":[{"atb":[[1.27,43.89]],"id":44798446}],"con":true,"img":false}]}
{"op":"mcm","clk":"11540402796","pt":1719494055085,"mc":[{"id":"1.230178308","rc":[{"atb":[[2.04,11.39]],"id":55829870}],"con":true,"img":false}]}
{"op":"mcm","clk":"11540408731","pt":1719494145496,"mc":[{"id":"1.230178308","rc":[{"atb":[[2.9,3.38]],"id":39362025},{"atb":[[1.28,49.91]],"id":44798446}],"con":true,"img":false}]}
{"op":"mcm","clk":"11540408757","pt":1719494145797,"mc":[{"id":"1.230178308","rc":[{"atb":[[2.36,10.27]],"id":48500723},{"atb":[[2.34,10.42]],"id":70218235}],"con":true,"img":false}]}
{"op":"mcm","clk":"11540408782","pt":1719494146070,"mc":[{"id":"1.230178308","rc":[{"atb":[[2.9,10.73]],"id":39362025},{"atb":[[2.06,13.17]],"id":55829870}],"con":true,"img":false}]}
{"op":"mcm","clk":"11540408804","pt":1719494146378,"mc":[{"id":"1.230178308","rc":[{"atb":[[3.4,5.82]],"id":40953876}],"con":true,"img":false}]}
{"op":"mcm","clk":"11540410788","pt":1719494176893,"mc":[{"id":"1.230178308","rc":[{"atb":[[3.35,0]],"id":40953876},{"atb":[[2.88,0]],"id":39362025},{"atb":[[2.34,0]],"id":48500723},{"atb":[[1.27,0]],"id":44798446},{"atb":[[2.32,0]],"id":70218235},{"atb":[[2.04,0]],"id":55829870}],"con":true,"img":false}]}
{"op":"mcm","clk":"11540411574","pt":1719494188137,"mc":[{"id":"1.230178308","rc":[{"atb":[[2.9,7.35]],"id":39362025}],"con":true,"img":false}]}
{"op":"mcm","clk":"11540412130","pt":1719494196112,"mc":[{"id":"1.230178308","rc":[{"atb":[[2.92,6.17]],"id":39362025}],"con":true,"img":false}]}
{"op":"mcm","clk":"11540412140","pt":1719494196216,"mc":[{"id":"1.230178308","rc":[{"atb":[[1.29,40.86]],"id":44798446}],"con":true,"img":false}]}
{"op":"mcm","clk":"11540412146","pt":1719494196319,"mc":[{"id":"1.230178308","rc":[{"atb":[[2.38,8.58]],"id":48500723}],"con":true,"img":false}]}
{"op":"mcm","clk":"11540412152","pt":1719494196425,"mc":[{"id":"1.230178308","rc":[{"atb":[[3.45,4.83]],"id":40953876}],"con":true,"img":false}]}
{"op":"mcm","clk":"11540412158","pt":1719494196526,"mc":[{"id":"1.230178308","rc":[{"atb":[[2.36,8.71]],"id":70218235}],"con":true,"img":false}]}
{"op":"mcm","clk":"11540412168","pt":1719494196733,"mc":[{"id":"1.230178308","rc":[{"atb":[[2.08,10.97]],"id":55829870}],"con":true,"img":false}]}
{"op":"mcm","clk":"11540414029","pt":1719494225074,"mc":[{"id":"1.230178308","rc":[{"atb":[[3.4,0]],"id":40953876},{"atb":[[2.9,0]],"id":39362025},{"atb":[[2.36,0]],"id":48500723},{"atb":[[1.28,0]],"id":44798446},{"atb":[[2.34,0]],"id":70218235},{"atb":[[2.06,0]],"id":55829870}],"con":true,"img":false}]}
{"op":"mcm","clk":"11540416333","pt":1719494257105,"mc":[{"id":"1.230178308","rc":[{"atl":[[30,1.55]],"id":40953876}],"con":true,"img":false}]}
{"op":"mcm","clk":"11540416846","pt":1719494264288,"mc":[{"id":"1.230178308","rc":[{"atb":[[3.45,0]],"id":40953876},{"atb":[[2.92,0]],"id":39362025},{"atb":[[2.38,0]],"id":48500723},{"atb":[[1.29,0]],"id":44798446},{"atb":[[2.36,0]],"id":70218235},{"atb":[[2.08,0]],"id":55829870}],"con":true,"img":false}]}
{"op":"mcm","clk":"11540417523","pt":1719494273801,"mc":[{"id":"1.230178308","rc":[{"atb":[[2.88,6.3]],"id":39362025}],"con":true,"img":false}]}
{"op":"mcm","clk":"11540417536","pt":1719494273905,"mc":[{"id":"1.230178308","rc":[{"atb":[[2.04,11.39]],"id":55829870}],"con":true,"img":false}]}
{"op":"mcm","clk":"11540417584","pt":1719494274526,"mc":[{"id":"1.230178308","rc":[{"atb":[[1.27,43.89]],"id":44798446}],"con":true,"img":false}]}
{"op":"mcm","clk":"11540417590","pt":1719494274577,"mc":[{"id":"1.230178308","rc":[{"atb":[[2.34,8.84]],"id":48500723}],"con":true,"img":false}]}
{"op":"mcm","clk":"11540417612","pt":1719494274886,"mc":[{"id":"1.230178308","rc":[{"atb":[[3.35,5.04]],"id":40953876}],"con":true,"img":false}]}
{"op":"mcm","clk":"11540417630","pt":1719494275096,"mc":[{"id":"1.230178308","rc":[{"atb":[[2.32,8.97]],"id":70218235}],"con":true,"img":false}]}
{"op":"mcm","clk":"11540419265","pt":1719494295721,"mc":[{"id":"1.230178308","rc":[{"atb":[[2.32,0]],"id":48500723},{"atb":[[2.3,0]],"id":70218235}],"con":true,"img":false}]}
{"op":"mcm","clk":"11540419277","pt":1719494295829,"mc":[{"id":"1.230178308","rc":[{"atb":[[2.36,13.33]],"id":48500723},{"atb":[[2.34,13.21]],"id":70218235}],"con":true,"img":false}]}
{"op":"mcm","clk":"11540421287","pt":1719494319681,"mc":[{"id":"1.230178308","rc":[{"atb":[[2.34,0]],"id":48500723},{"atb":[[2.32,0]],"id":70218235}],"con":true,"img":false}]}
{"op":"mcm","clk":"11540423410","pt":1719494344181,"mc":[{"id":"1.230178308","rc":[{"atb":[[2.36,8.71]],"id":70218235}],"con":true,"img":false}]}
{"op":"mcm","clk":"11540423432","pt":1719494344388,"mc":[{"id":"1.230178308","rc":[{"atb":[[2.38,8.58]],"id":48500723}],"con":true,"img":false}]}
{"op":"mcm","clk":"11540427404","pt":1719494390258,"mc":[{"id":"1.230178308","rc":[{"atb":[[2.9,3.38]],"id":39362025}],"con":true,"img":false}]}
{"op":"mcm","clk":"11540427411","pt":1719494390352,"mc":[{"id":"1.230178308","rc":[{"atb":[[1.28,49.91]],"id":44798446}],"con":true,"img":false}]}
{"op":"mcm","clk":"11540427424","pt":1719494390522,"mc":[{"id":"1.230178308","rc":[{"atb":[[2.9,10.73]],"id":39362025}],"con":true,"img":false}]}
{"op":"mcm","clk":"11540427434","pt":1719494390626,"mc":[{"id":"1.230178308","rc":[{"atb":[[2.06,13.17]],"id":55829870}],"con":true,"img":false}]}
{"op":"mcm","clk":"11540427451","pt":1719494390835,"mc":[{"id":"1.230178308","rc":[{"atb":[[3.4,5.82]],"id":40953876}],"con":true,"img":false}]}
{"op":"mcm","clk":"11540431396","pt":1719494433677,"mc":[{"id":"1.230178308","rc":[{"atb":[[3.35,0]],"id":40953876},{"atb":[[2.88,0]],"id":39362025},{"atb":[[1.27,0]],"id":44798446},{"atb":[[2.04,0]],"id":55829870}],"con":true,"img":false}]}
{"op":"mcm","clk":"11540431436","pt":1719494434100,"mc":[{"id":"1.230178308","rc":[{"atb":[[2.4,9.97]],"id":48500723},{"atb":[[2.38,10.12]],"id":70218235}],"con":true,"img":false}]}
{"op":"mcm","clk":"11540433310","pt":1719494454739,"mc":[{"id":"1.230178308","rc":[{"atb":[[2.92,6.17]],"id":39362025}],"con":true,"img":false}]}
{"op":"mcm","clk":"11540433319","pt":1719494454833,"mc":[{"id":"1.230178308","rc":[{"atb":[[1.29,40.86]],"id":44798446}],"con":true,"img":false}]}
{"op":"mcm","clk":"11540433337","pt":1719494455043,"mc":[{"id":"1.230178308","rc":[{"atb":[[2.08,10.97]],"id":55829870}],"con":true,"img":false}]}
{"op":"mcm","clk":"11540433356","pt":1719494455204,"mc":[{"id":"1.230178308","rc":[{"atb":[[3.45,4.83]],"id":40953876}],"con":true,"img":false}]}
{"op":"mcm","clk":"11540435387","pt":1719494477841,"mc":[{"id":"1.230178308","rc":[{"atb":[[2.9,7.35]],"id":39362025}],"con":true,"img":false}]}
{"op":"mcm","clk":"11540435458","pt":1719494478728,"mc":[{"id":"1.230178308","rc":[{"atb":[[2.94,3.38]],"id":39362025}],"con":true,"img":false}]}
{"op":"mcm","clk":"11540436681","pt":1719494492339,"mc":[{"id":"1.230178308","rc":[{"atb":[[2.38,0]],"id":48500723},{"atb":[[2.36,0]],"id":70218235}],"con":true,"img":false}]}
{"op":"mcm","clk":"11540437180","pt":1719494497752,"mc":[{"id":"1.230178308","rc":[{"atb":[[2.4,8.46]],"id":70218235}],"con":true,"img":false}]}
{"op":"mcm","clk":"11540437229","pt":1719494498269,"mc":[{"id":"1.230178308","rc":[{"atb":[[2.42,8.34]],"id":48500723}],"con":true,"img":false}]}
{"op":"mcm","clk":"11540437816","pt":1719494504862,"mc":[{"id":"1.230178308","rc":[{"atb":[[3.4,0]],"id":40953876},{"atb":[[2.9,0]],"id":39362025},{"atb":[[1.28,0]],"id":44798446},{"atb":[[2.06,0]],"id":55829870}],"con":true,"img":false}]}
{"op":"mcm","clk":"11540438674","pt":1719494515497,"mc":[{"id":"1.230178308","rc":[{"atb":[[2.94,10.58]],"id":39362025}],"con":true,"img":false}]}
{"op":"mcm","clk":"11540438690","pt":1719494515751,"mc":[{"id":"1.230178308","rc":[{"atb":[[1.3,46.58]],"id":44798446}],"con":true,"img":false}]}
{"op":"mcm","clk":"11540438711","pt":1719494516066,"mc":[{"id":"1.230178308","rc":[{"atb":[[3.5,5.58]],"id":40953876}],"con":true,"img":false}]}
{"op":"mcm","clk":"11540438732","pt":1719494516378,"mc":[{"id":"1.230178308","rc":[{"atb":[[2.1,12.7]],"id":55829870}],"con":true,"img":false}]}
{"op":"mcm","clk":"11540439494","pt":1719494525881,"mc":[{"id":"1.230178308","rc":[{"atb":[[2.92,0]],"id":39362025}],"con":true,"img":false}]}
{"op":"mcm","clk":"11540440526","pt":1719494538296,"mc":[{"id":"1.230178308","rc":[{"atb":[[3.45,0]],"id":40953876},{"atb":[[1.29,0]],"id":44798446},{"atb":[[2.08,0]],"id":55829870}],"con":true,"img":false}]}
{"op":"mcm","clk":"11540440700","pt":1719494540218,"mc":[{"id":"1.230178308","rc":[{"atb":[[2.96,6.04]],"id":39362025}],"con":true,"img":false}]}
{"op":"mcm","clk":"11540440889","pt":1719494542444,"mc":[{"id":"1.230178308","rc":[{"atb":[[2.4,0]],"id":48500723},{"atb":[[2.38,0]],"id":70218235}],"con":true,"img":false}]}
{"op":"mcm","clk":"11540441871","pt":1719494553851,"mc":[{"id":"1.230178308","rc":[{"atb":[[2.94,7.19]],"id":39362025},{"atb":[[2.44,9.7]],"id":48500723}],"con":true,"img":false}]}
{"op":"mcm","clk":"11540441898","pt":1719494554112,"mc":[{"id":"1.230178308","rc":[{"atb":[[2.42,9.84]],"id":70218235}],"con":true,"img":false}]}
{"op":"mcm","clk":"11540442012","pt":1719494555451,"mc":[{"id":"1.230178308","rc":[{"atb":[[2.98,3.38]],"id":39362025}],"con":true,"img":false}]}
{"op":"mcm","clk":"11540442541","pt":1719494561565,"mc":[{"id":"1.230178308","rc":[{"atb":[[3.55,4.64]],"id":40953876},{"atb":[[1.31,38.23]],"id":44798446}],"con":true,"img":false}]}
{"op":"mcm","clk":"11540442567","pt":1719494561829,"mc":[{"id":"1.230178308","rc":[{"atb":[[2.12,10.57]],"id":55829870}],"con":true,"img":false}]}
{"op":"mcm","clk":"11540444839","pt":1719494587245,"mc":[{"id":"1.230178308","rc":[{"atb":[[3.5,0]],"id":40953876},{"atb":[[2.94,0]],"id":39362025},{"atb":[[1.3,0]],"id":44798446},{"atb":[[2.1,0]],"id":55829870}],"con":true,"img":false}]}
{"op":"mcm","clk":"11540445825","pt":1719494598460,"mc":[{"id":"1.230178308","rc":[{"atb":[[2.96,0]],"id":39362025},{"atb":[[2.42,0]],"id":48500723},{"atb":[[2.4,0]],"id":70218235}],"con":true,"img":false}]}
{"op":"mcm","clk":"11540446003","pt":1719494600389,"mc":[{"id":"1.230178308","rc":[{"atb":[[2.98,0]],"id":39362025}],"con":true,"img":false}]}
{"op":"mcm","clk":"11540446821","pt":1719494609363,"mc":[{"id":"1.230178308","rc":[{"atb":[[2.44,8.23]],"id":70218235}],"con":true,"img":false}]}
{"op":"mcm","clk":"11540446842","pt":1719494609674,"mc":[{"id":"1.230178308","rc":[{"atb":[[2.46,8.11]],"id":48500723}],"con":true,"img":false}]}
{"op":"mcm","clk":"11540448953","pt":1719494632792,"mc":[{"id":"1.230178308","rc":[{"atb":[[3.55,0]],"id":40953876},{"atb":[[1.31,0]],"id":44798446},{"atb":[[2.12,0]],"id":55829870}],"con":true,"img":false}]}
{"op":"mcm","clk":"11540449793","pt":1719494642915,"mc":[{"id":"1.230178308","rc":[{"atb":[[2.44,0]],"id":48500723},{"atb":[[2.42,0]],"id":70218235}],"con":true,"img":false}]}
{"op":"mcm","clk":"11540449984","pt":1719494645105,"mc":[{"id":"1.230178308","rc":[{"atb":[[2.88,6.3]],"id":39362025}],"con":true,"img":false}]}
{"op":"mcm","clk":"11540449993","pt":1719494645209,"mc":[{"id":"1.230178308","rc":[{"atb":[[3.35,5.04]],"id":40953876}],"con":true,"img":false}]}
{"op":"mcm","clk":"11540450005","pt":1719494645327,"mc":[{"id":"1.230178308","rc":[{"atb":[[2.04,11.39]],"id":55829870}],"con":true,"img":false}]}
{"op":"mcm","clk":"11540450050","pt":1719494645898,"mc":[{"id":"1.230178308","rc":[{"atb":[[1.27,43.89]],"id":44798446}],"con":true,"img":false}]}
{"op":"mcm","clk":"11540450385","pt":1719494650529,"mc":[{"id":"1.230178308","rc":[{"atb":[[8,0]],"id":40953876},{"trd":[[8,4]],"ltp":8.0,"tv":4.0,"id":40953876},{"spn":3.35,"spf":1.0,"id":40953876}],"con":true,"img":false}]}
{"op":"mcm","clk":"11540451628","pt":1719494665651,"mc":[{"id":"1.230178308","rc":[{"atb":[[2.46,0]],"id":48500723},{"atb":[[2.44,0]],"id":70218235}],"con":true,"img":false}]}
{"op":"mcm","clk":"11540451819","pt":1719494668047,"mc":[{"id":"1.230178308","rc":[{"atb":[[2.36,10.27]],"id":70218235}],"con":true,"img":false}]}
{"op":"mcm","clk":"11540451836","pt":1719494668250,"mc":[{"id":"1.230178308","rc":[{"atb":[[2.38,10.12]],"id":48500723}],"con":true,"img":false}]}
{"op":"mcm","clk":"11540454297","pt":1719494696299,"mc":[{"id":"1.230178308","rc":[{"atb":[[3.35,0]],"id":40953876}],"con":true,"img":false}]}
{"op":"mcm","clk":"11540454590","pt":1719494700176,"mc":[{"id":"1.230178308","rc":[{"atb":[[2.9,3.38]],"id":39362025}],"con":true,"img":false}]}
{"op":"mcm","clk":"11540454613","pt":1719494700387,"mc":[{"id":"1.230178308","rc":[{"atb":[[1.28,49.91]],"id":44798446}],"con":true,"img":false}]}
{"op":"mcm","clk":"11540454626","pt":1719494700490,"mc":[{"id":"1.230178308","rc":[{"atb":[[2.9,10.73]],"id":39362025}],"con":true,"img":false}]}
{"op":"mcm","clk":"11540454660","pt":1719494700801,"mc":[{"id":"1.230178308","rc":[{"atb":[[2.18,11.84]],"id":40953876}],"con":true,"img":false}]}
{"op":"mcm","clk":"11540454734","pt":1719494701686,"mc":[{"id":"1.230178308","rc":[{"atb":[[2.06,13.17]],"id":55829870}],"con":true,"img":false}]}
{"op":"mcm","clk":"11540454905","pt":1719494703299,"mc":[{"id":"1.230178308","rc":[{"atb":[[2.38,8.58]],"id":70218235}],"con":true,"img":false}]}
{"op":"mcm","clk":"11540454911","pt":1719494703402,"mc":[{"id":"1.230178308","rc":[{"atb":[[2.4,8.46]],"id":48500723}],"con":true,"img":false}]}
{"op":"mcm","clk":"11540456649","pt":1719494723922,"mc":[{"id":"1.230178308","rc":[{"spn":3.3,"spf":1.0,"id":40953876},{"atb":[[2.88,0]],"id":39362025},{"atb":[[1.27,0]],"id":44798446},{"atb":[[2.04,0]],"id":55829870}],"con":true,"img":false}]}
{"op":"mcm","clk":"11540456853","pt":1719494726511,"mc":[{"id":"1.230178308","rc":[{"atb":[[2.92,6.17]],"id":39362025}],"con":true,"img":false}]}
{"op":"mcm","clk":"11540456870","pt":1719494726717,"mc":[{"id":"1.230178308","rc":[{"atb":[[2.2,9.87]],"id":40953876}],"con":true,"img":false}]}
{"op":"mcm","clk":"11540456892","pt":1719494727028,"mc":[{"id":"1.230178308","rc":[{"atb":[[1.29,40.86]],"id":44798446}],"con":true,"img":false}]}
{"op":"mcm","clk":"11540456904","pt":1719494727087,"mc":[{"id":"1.230178308","rc":[{"atb":[[2.08,10.97]],"id":55829870}],"con":true,"img":false}]}
{"op":"mcm","clk":"11540458668","pt":1719494748617,"mc":[{"id":"1.230178308","rc":[{"atb":[[2.9,7.35]],"id":39362025}],"con":true,"img":false}]}
{"op":"mcm","clk":"11540458722","pt":1719494749232,"mc":[{"id":"1.230178308","rc":[{"atb":[[2.94,3.38]],"id":39362025}],"con":true,"img":false}]}
{"op":"mcm","clk":"11540460057","pt":1719494763956,"mc":[{"id":"1.230178308","rc":[{"atb":[[2.28,2.1]],"id":40953876},{"atb":[[2.46,2.1]],"id":70218235}],"con":true,"img":false}]}
{"op":"mcm","clk":"11540460598","pt":1719494770247,"mc":[{"id":"1.230178308","rc":[{"atb":[[2.18,0]],"id":40953876},{"atb":[[2.9,0]],"id":39362025},{"atb":[[2.38,0]],"id":48500723},{"atb":[[1.28,0]],"id":44798446},{"atb":[[2.36,0]],"id":70218235},{"atb":[[2.06,0]],"id":55829870}],"con":true,"img":false}]}
{"op":"mcm","clk":"11540461210","pt":1719494777275,"mc":[{"id":"1.230178308","rc":[{"atb":[[2.4,0]],"id":48500723},{"atb":[[2.38,0]],"id":70218235}],"con":true,"img":false}]}
{"op":"mcm","clk":"11540462254","pt":1719494790080,"mc":[{"id":"1.230178308","rc":[{"atb":[[2.36,8.71]],"id":70218235}],"con":true,"img":false}]}
{"op":"mcm","clk":"11540462273","pt":1719494790286,"mc":[{"id":"1.230178308","rc":[{"atb":[[2.38,8.58]],"id":48500723}],"con":true,"img":false}]}
{"op":"mcm","clk":"11540463260","pt":1719494802878,"mc":[{"id":"1.230178308","rc":[{"atb":[[2.94,10.58]],"id":39362025}],"con":true,"img":false}]}
{"op":"mcm","clk":"11540463280","pt":1719494803087,"mc":[{"id":"1.230178308","rc":[{"atb":[[1.3,46.58]],"id":44798446}],"con":true,"img":false}]}
{"op":"mcm","clk":"11540463288","pt":1719494803183,"mc":[{"id":"1.230178308","rc":[{"atb":[[2.22,11.45]],"id":40953876}],"con":true,"img":false}]}
{"op":"mcm","clk":"11540463302","pt":1719494803389,"mc":[{"id":"1.230178308","rc":[{"atb":[[2.1,12.7]],"id":55829870}],"con":true,"img":false}]}
{"op":"mcm","clk":"11540464333","pt":1719494816281,"mc":[{"id":"1.230178308","rc":[{"atb":[[2.2,0]],"id":40953876},{"atb":[[2.92,0]],"id":39362025},{"atb":[[1.29,0]],"id":44798446},{"atb":[[2.08,0]],"id":55829870}],"con":true,"img":false}]}
{"op":"mcm","clk":"11540464762","pt":1719494821404,"mc":[{"id":"1.230178308","rc":[{"atb":[[2.96,6.04]],"id":39362025}],"con":true,"img":false}]}
{"op":"mcm","clk":"11540465889","pt":1719494833944,"mc":[{"id":"1.230178308","rc":[{"atb":[[1.31,38.23]],"id":44798446}],"con":true,"img":false}]}
{"op":"mcm","clk":"11540465904","pt":1719494834113,"mc":[{"id":"1.230178308","rc":[{"atb":[[2.12,10.57]],"id":55829870}],"con":true,"img":false}]}
{"op":"mcm","clk":"11540465925","pt":1719494834305,"mc":[{"id":"1.230178308","rc":[{"atb":[[2.24,9.55]],"id":40953876}],"con":true,"img":false}]}
{"op":"mcm","clk":"11540467109","pt":1719494846029,"mc":[{"id":"1.230178308","rc":[{"atb":[[2.94,7.19]],"id":39362025},{"atb":[[2.4,9.97]],"id":48500723}],"con":true,"img":false}]}
{"op":"mcm","clk":"11540467138","pt":1719494846339,"mc":[{"id":"1.230178308","rc":[{"atb":[[2.38,10.12]],"id":70218235}],"con":true,"img":false}]}
{"op":"mcm","clk":"11540467260","pt":1719494847731,"mc":[{"id":"1.230178308","rc":[{"atb":[[2.98,3.38]],"id":39362025}],"con":true,"img":false}]}
{"op":"mcm","clk":"11540469669","pt":1719494875962,"mc":[{"id":"1.230178308","rc":[{"atb":[[2.22,0]],"id":40953876},{"atb":[[2.94,0]],"id":39362025},{"atb":[[1.3,0]],"id":44798446},{"atb":[[2.1,0]],"id":55829870}],"con":true,"img":false}]}
{"op":"mcm","clk":"11540469735","pt":1719494876672,"mc":[{"id":"1.230178308","rc":[{"atb":[[2.96,0]],"id":39362025},{"atb":[[2.38,0]],"id":48500723},{"atb":[[2.36,0]],"id":70218235}],"con":true,"img":false}]}
{"op":"mcm","clk":"11540470734","pt":1719494887394,"mc":[{"id":"1.230178308","rc":[{"atb":[[2.98,0]],"id":39362025}],"con":true,"img":false}]}
{"op":"mcm","clk":"11540470754","pt":1719494887669,"mc":[{"id":"1.230178308","rc":[{"atb":[[1.32,43.67]],"id":44798446}],"con":true,"img":false}]}
{"op":"mcm","clk":"11540470779","pt":1719494887988,"mc":[{"id":"1.230178308","rc":[{"atb":[[2.14,12.26]],"id":55829870}],"con":true,"img":false}]}
{"op":"mcm","clk":"11540470803","pt":1719494888300,"mc":[{"id":"1.230178308","rc":[{"atb":[[2.26,11.08]],"id":40953876}],"con":true,"img":false}]}
{"op":"mcm","clk":"11540471425","pt":1719494895307,"mc":[{"id":"1.230178308","rc":[{"atb":[[2.16,0]],"id":40953876}],"con":true,"img":false}]}
{"op":"mcm","clk":"11540471438","pt":1719494895410,"mc":[{"id":"1.230178308","rc":[{"atb":[[2.26,19.64]],"id":40953876}],"con":true,"img":false}]}
{"op":"mcm","clk":"11540471560","pt":1719494896990,"mc":[{"id":"1.230178308","rc":[{"atb":[[2.4,8.46]],"id":70218235}],"con":true,"img":false}]}
{"op":"mcm","clk":"11540471577","pt":1719494897201,"mc":[{"id":"1.230178308","rc":[{"atb":[[2.42,8.34]],"id":48500723}],"con":true,"img":false}]}
{"op":"mcm","clk":"11540473230","pt":1719494917542,"mc":[{"id":"1.230178308","rc":[{"atb":[[2.24,0]],"id":40953876},{"atb":[[1.31,0]],"id":44798446},{"atb":[[2.12,0]],"id":55829870}],"con":true,"img":false}]}
{"op":"mcm","clk":"11540473256","pt":1719494917819,"mc":[{"id":"1.230178308","rc":[{"atb":[[2.4,0]],"id":48500723},{"atb":[[2.38,0]],"id":70218235}],"con":true,"img":false}]}
{"op":"mcm","clk":"11540474048","pt":1719494926239,"mc":[{"id":"1.230178308","rc":[{"atb":[[2.88,6.3]],"id":39362025}],"con":true,"img":false}]}
{"op":"mcm","clk":"11540474067","pt":1719494926441,"mc":[{"id":"1.230178308","rc":[{"atb":[[2.28,11.36]],"id":40953876},{"atb":[[1.33,35.9]],"id":44798446}],"con":true,"img":false}]}
{"op":"mcm","clk":"11540474084","pt":1719494926647,"mc":[{"id":"1.230178308","rc":[{"atb":[[2.16,10.21]],"id":55829870}],"con":true,"img":false}]}
{"op":"mcm","clk":"11540475869","pt":1719494947468,"mc":[{"id":"1.230178308","rc":[{"atb":[[2.42,0]],"id":48500723},{"atb":[[2.4,0]],"id":70218235}],"con":true,"img":false}]}
{"op":"mcm","clk":"11540476332","pt":1719494953576,"mc":[{"id":"1.230178308","rc":[{"atb":[[2.36,8.71]],"id":70218235}],"con":true,"img":false}]}
{"op":"mcm","clk":"11540476341","pt":1719494953672,"mc":[{"id":"1.230178308","rc":[{"atb":[[2.38,8.58]],"id":48500723}],"con":true,"img":false}]}
{"op":"mcm","clk":"11540476719","pt":1719494957553,"mc":[{"id":"1.230178308","rc":[{"atl":[[190,4]],"id":39362025},{"atl":[[190,4]],"id":48500723},{"atl":[[190,4]],"id":44798446},{"atl":[[190,4]],"id":70218235}],"con":true,"img":false}]}
{"op":"mcm","clk":"11540476729","pt":1719494957653,"mc":[{"id":"1.230178308","rc":[{"atl":[[190,4]],"id":40953876},{"atl":[[190,4]],"id":55829870}],"con":true,"img":false}]}
{"op":"mcm","clk":"11540478088","pt":1719494975382,"mc":[{"id":"1.230178308","rc":[{"atb":[[2.26,8.55]],"id":40953876},{"atb":[[1.32,0]],"id":44798446},{"atb":[[2.14,0]],"id":55829870}],"con":true,"img":false}]}
{"op":"mcm","clk":"11540478376","pt":1719494978793,"mc":[{"id":"1.230178308","rc":[{"atb":[[2.9,3.38]],"id":39362025}],"con":true,"img":false}]}
{"op":"mcm","clk":"11540478388","pt":1719494979001,"mc":[{"id":"1.230178308","rc":[{"atb":[[2.3,10.74]],"id":40953876}],"con":true,"img":false}]}
{"op":"mcm","clk":"11540478394","pt":1719494979104,"mc":[{"id":"1.230178308","rc":[{"atb":[[1.34,41.1]],"id":44798446}],"con":true,"img":false}]}
{"op":"mcm","clk":"11540478421","pt":1719494979417,"mc":[{"id":"1.230178308","rc":[{"atb":[[2.18,11.84]],"id":55829870}],"con":true,"img":false}]}
{"op":"mcm","clk":"11540478432","pt":1719494979520,"mc":[{"id":"1.230178308","rc":[{"atb":[[2.9,10.73]],"id":39362025}],"con":true,"img":false}]}
{"op":"mcm","clk":"11540479387","pt":1719494990113,"mc":[{"id":"1.230178308","rc":[{"atb":[[1.02,2]],"id":39362025}],"con":true,"img":false}]}
{"op":"mcm","clk":"11540479416","pt":1719494990424,"mc":[{"id":"1.230178308","rc":[{"atb":[[1.02,2]],"id":70218235}],"con":true,"img":false}]}
{"op":"mcm","clk":"11540479437","pt":1719494990726,"mc":[{"id":"1.230178308","rc":[{"atb":[[2.74,2]],"id":44798446}],"con":true,"img":false}]}
{"op":"mcm","clk":"11540479461","pt":1719494990988,"mc":[{"id":"1.230178308","rc":[{"atb":[[1.02,2]],"id":48500723}],"con":true,"img":false}]}
{"op":"mcm","clk":"11540479504","pt":1719494991415,"mc":[{"id":"1.230178308","rc":[{"atb":[[1.02,2]],"id":40953876}],"con":true,"img":false}]}
{"op":"mcm","clk":"11540479527","pt":1719494991725,"mc":[{"id":"1.230178308","rc":[{"atb":[[1.02,13.84]],"id":55829870}],"con":true,"img":false}]}
{"op":"mcm","clk":"11540479872","pt":1719494995623,"mc":[{"id":"1.230178308","rc":[{"atb":[[4,1.68]],"id":55829870}],"con":true,"img":false}]}
{"op":"mcm","clk":"11540480243","pt":1719495000129,"mc":[{"id":"1.230178308","rc":[{"atb":[[4.4,1.68]],"id":40953876}],"con":true,"img":false}]}
{"op":"mcm","clk":"11540480545","pt":1719495003415,"mc":[{"id":"1.230178308","rc":[{"atb":[[5,1.11]],"id":48500723}],"con":true,"img":false}]}
{"op":"mcm","clk":"11540480698","pt":1719495005050,"mc":[{"id":"1.230178308","rc":[{"atb":[[1.02,0]],"id":48500723}],"con":true,"img":false}]}
{"op":"mcm","clk":"11540480704","pt":1719495005128,"mc":[{"id":"1.230178308","rc":[{"atb":[[5.1,2]],"id":48500723}],"con":true,"img":false}]}
{"op":"mcm","clk":"11540481729","pt":1719495017238,"mc":[{"id":"1.230178308","rc":[{"atb":[[2.28,2.1]],"id":40953876},{"spn":4.4,"spf":1.0,"id":40953876},{"atb":[[2.88,0]],"id":39362025},{"spn":77.55,"spf":"NaN","id":48500723},{"atb":[[1.33,0]],"id":44798446},{"spn":17.37,"spf":"NaN","id":44798446},{"atb":[[2.16,0]],"id":55829870},{"spn":6.0,"spf":"NaN","id":55829870}],"con":true,"img":false}]}
{"op":"mcm","clk":"11540481869","pt":1719495018955,"mc":[{"id":"1.230178308","rc":[{"atb":[[2.92,6.17]],"id":39362025}],"con":true,"img":false}]}
{"op":"mcm","clk":"11540481874","pt":1719495019055,"mc":[{"id":"1.230178308","rc":[{"atb":[[2.32,8.97]],"id":40953876}],"con":true,"img":false}]}
{"op":"mcm","clk":"11540481907","pt":1719495019459,"mc":[{"id":"1.230178308","rc":[{"atb":[[1.35,33.86]],"id":44798446}],"con":true,"img":false}]}
{"op":"mcm","clk":"11540482077","pt":1719495021962,"mc":[{"id":"1.230178308","rc":[{"atb":[[2.9,7.35]],"id":39362025}],"con":true,"img":false}]}
{"op":"mcm","clk":"11540482086","pt":1719495022066,"mc":[{"id":"1.230178308","rc":[{"atb":[[2.4,9.97]],"id":48500723}],"con":true,"img":false}]}
{"op":"mcm","clk":"11540482181","pt":1719495023279,"mc":[{"id":"1.230178308","rc":[{"atb":[[2.94,3.38]],"id":39362025}],"con":true,"img":false}]}
{"op":"mcm","clk":"11540482203","pt":1719495023538,"mc":[{"id":"1.230178308","rc":[{"atb":[[2.38,10.12]],"id":70218235}],"con":true,"img":false}]}
{"op":"mcm","clk":"11540483427","pt":1719495038283,"mc":[{"id":"1.230178308","rc":[{"atb":[[2.38,8.58]],"id":55829870}],"con":true,"img":false}]}
{"op":"mcm","clk":"11540485275","pt":1719495058607,"mc":[{"id":"1.230178308","rc":[{"atb":[[2.92,0]],"id":39362025},{"atb":[[2.38,0]],"id":48500723},{"atb":[[2.36,0]],"id":70218235}],"con":true,"img":false}]}
{"op":"mcm","clk":"11540485401","pt":1719495060004,"mc":[{"id":"1.230178308","rc":[{"atb":[[2.3,0]],"id":40953876},{"atb":[[2.9,0]],"id":39362025},{"atb":[[1.34,0]],"id":44798446},{"atb":[[2.18,0]],"id":55829870}],"con":true,"img":false}]}
{"op":"mcm","clk":"11540485427","pt":1719495060303,"mc":[{"id":"1.230178308","rc":[{"atb":[[2.96,6.04]],"id":39362025}],"con":true,"img":false}]}
{"op":"mcm","clk":"11540485439","pt":1719495060409,"mc":[{"id":"1.230178308","rc":[{"atb":[[2.42,8.34]],"id":48500723}],"con":true,"img":false}]}
{"op":"mcm","clk":"11540485447","pt":1719495060512,"mc":[{"id":"1.230178308","rc":[{"atb":[[2.4,8.46]],"id":70218235}],"con":true,"img":false}]}
{"op":"mcm","clk":"11540485658","pt":1719495062632,"mc":[{"id":"1.230178308","rc":[{"atb":[[4.4,0]],"id":40953876},{"atb":[[5,0]],"id":48500723},{"atb":[[4,0]],"id":55829870}],"con":true,"img":false}]}
{"op":"mcm","clk":"11540485810","pt":1719495063927,"mc":[{"id":"1.230178308","rc":[{"atb":[[5.1,0]],"id":48500723}],"con":true,"img":false}]}
{"op":"mcm","clk":"11540485817","pt":1719495064030,"mc":[{"id":"1.230178308","rc":[{"atb":[[4.4,2]],"id":48500723}],"con":true,"img":false}]}
{"op":"mcm","clk":"11540485901","pt":1719495064819,"mc":[{"id":"1.230178308","rc":[{"atb":[[3.75,18.19]],"id":55829870}],"con":true,"img":false}]}
{"op":"mcm","clk":"11540485933","pt":1719495065122,"mc":[{"id":"1.230178308","rc":[{"atl":[[14,7.5]],"id":48500723}],"con":true,"img":false}]}
{"op":"mcm","clk":"11540486516","pt":1719495071334,"mc":[{"id":"1.230178308","rc":[{"atb":[[2.94,0]],"id":39362025}],"con":true,"img":false}]}
{"op":"mcm","clk":"11540486528","pt":1719495071537,"mc":[{"id":"1.230178308","rc":[{"atb":[[2.88,3.16]],"id":55829870}],"con":true,"img":false}]}
{"op":"mcm","clk":"11540486535","pt":1719495071643,"mc":[{"id":"1.230178308","rc":[{"atb":[[2.34,10.42]],"id":40953876}],"con":true,"img":false}]}
{"op":"mcm","clk":"11540486612","pt":1719495072525,"mc":[{"id":"1.230178308","rc":[{"atb":[[2.98,3.38]],"id":39362025}],"con":true,"img":false}]}
{"op":"mcm","clk":"11540486877","pt":1719495075322,"mc":[{"id":"1.230178308","rc":[{"atb":[[2.88,0]],"id":55829870}],"con":true,"img":false}]}
{"op":"mcm","clk":"11540486929","pt":1719495075943,"mc":[{"id":"1.230178308","rc":[{"atl":[[14,0]],"id":48500723},{"atb":[[3.75,0]],"id":55829870}],"con":true,"img":false}]}
{"op":"mcm","clk":"11540489798","pt":1719495108279,"mc":[{"id":"1.230178308","rc":[{"atb":[[2.32,0]],"id":40953876},{"spn":3.3,"spf":1.0,"id":40953876},{"atb":[[2.96,0]],"id":39362025},{"spn":77.2,"spf":"NaN","id":48500723},{"atb":[[1.35,0]],"id":44798446},{"spn":5.43,"spf":"NaN","id":55829870}],"con":true,"img":false}]}
{"op":"mcm","clk":"11540489911","pt":1719495109451,"mc":[{"id":"1.230178308","rc":[{"atb":[[2.4,0]],"id":48500723},{"atb":[[2.38,0]],"id":70218235}],"con":true,"img":false}]}
{"op":"mcm","clk":"11540490259","pt":1719495113488,"mc":[{"id":"1.230178308","rc":[{"atb":[[2.98,0]],"id":39362025}],"con":true,"img":false}]}
{"op":"mcm","clk":"11540490282","pt":1719495113649,"mc":[{"id":"1.230178308","rc":[{"atb":[[2.42,9.84]],"id":70218235}],"con":true,"img":false}]}
{"op":"mcm","clk":"11540490291","pt":1719495113750,"mc":[{"id":"1.230178308","rc":[{"atb":[[3,5.92]],"id":39362025},{"atb":[[2.44,9.7]],"id":48500723}],"con":true,"img":false}]}
{"op":"mcm","clk":"11540490300","pt":1719495113856,"mc":[{"id":"1.230178308","rc":[{"atb":[[2.36,8.71]],"id":40953876}],"con":true,"img":false}]}
{"op":"mcm","clk":"11540490305","pt":1719495113962,"mc":[{"id":"1.230178308","rc":[{"atb":[[1.27,43.89]],"id":44798446}],"con":true,"img":false}]}
{"op":"mcm","clk":"11540491791","pt":1719495129299,"mc":[{"id":"1.230178308","rc":[{"atb":[[2.38,0]],"id":55829870}],"con":true,"img":false}]}
{"op":"mcm","clk":"11540492315","pt":1719495134795,"mc":[{"id":"1.230178308","rc":[{"atb":[[2.42,0]],"id":48500723},{"atb":[[2.4,0]],"id":70218235}],"con":true,"img":false}]}
{"op":"mcm","clk":"11540492343","pt":1719495135104,"mc":[{"id":"1.230178308","rc":[{"atb":[[2.04,11.39]],"id":55829870}],"con":true,"img":false}]}
{"op":"mcm","clk":"11540493555","pt":1719495147489,"mc":[{"id":"1.230178308","rc":[{"atb":[[2.34,0]],"id":40953876}],"con":true,"img":false}]}
{"op":"mcm","clk":"11540493741","pt":1719495149419,"mc":[{"id":"1.230178308","rc":[{"spl":[[1.01,5.71]],"id":39362025}],"con":true,"img":false}]}
{"op":"mcm","clk":"11540494044","pt":1719495152628,"mc":[{"id":"1.230178308","rc":[{"atb":[[2.44,8.23]],"id":70218235}],"con":true,"img":false}]}
{"op":"mcm","clk":"11540494083","pt":1719495152889,"mc":[{"id":"1.230178308","rc":[{"atb":[[2.46,8.11]],"id":48500723}],"con":true,"img":false}]}
{"op":"mcm","clk":"11540495270","pt":1719495165533,"mc":[{"id":"1.230178308","rc":[{"atb":[[3,0]],"id":39362025}],"con":true,"img":false}]}
{"op":"mcm","clk":"11540495414","pt":1719495166930,"mc":[{"id":"1.230178308","rc":[{"spl":[[1.01,5]],"id":40953876}],"con":true,"img":false}]}
{"op":"mcm","clk":"11540495934","pt":1719495172438,"mc":[{"id":"1.230178308","rc":[{"atb":[[2.88,6.3]],"id":39362025},{"spn":4.67,"spf":1.0,"id":39362025}],"con":true,"img":false}]}
{"op":"mcm","clk":"11540497241","pt":1719495185527,"mc":[{"id":"1.230178308","rc":[{"atb":[[2.36,0]],"id":40953876}],"con":true,"img":false}]}
{"op":"mcm","clk":"11540497384","pt":1719495187036,"mc":[{"id":"1.230178308","rc":[{"atb":[[2.44,0]],"id":48500723},{"atb":[[2.42,0]],"id":70218235}],"con":true,"img":false}]}
{"op":"mcm","clk":"11540497743","pt":1719495190956,"mc":[{"id":"1.230178308","rc":[{"atb":[[2.06,13.17]],"id":55829870}],"con":true,"img":false}]}
{"op":"mcm","clk":"11540497772","pt":1719495191270,"mc":[{"id":"1.230178308","rc":[{"atb":[[1.28,49.91]],"id":44798446}],"con":true,"img":false}]}
{"op":"mcm","clk":"11540497835","pt":1719495192151,"mc":[{"id":"1.230178308","rc":[{"atb":[[2.28,11.36]],"id":40953876}],"con":true,"img":false}]}
{"op":"mcm","clk":"11540499763","pt":1719495213291,"mc":[{"id":"1.230178308","rc":[{"atb":[[2.46,0]],"id":48500723},{"atb":[[1.27,0]],"id":44798446},{"atb":[[2.44,0]],"id":70218235},{"atb":[[2.04,0]],"id":55829870}],"con":true,"img":false}]}
{"op":"mcm","clk":"11540499850","pt":1719495214176,"mc":[{"id":"1.230178308","rc":[{"atb":[[1.29,40.86]],"id":44798446},{"atb":[[2.36,8.71]],"id":70218235}],"con":true,"img":false}]}
{"op":"mcm","clk":"11540499869","pt":1719495214384,"mc":[{"id":"1.230178308","rc":[{"atb":[[2.38,8.58]],"id":48500723}],"con":true,"img":false}]}
{"op":"mcm","clk":"11540499875","pt":1719495214487,"mc":[{"id":"1.230178308","rc":[{"atb":[[2.08,10.97]],"id":55829870}],"con":true,"img":false}]}
{"op":"mcm","clk":"11540500153","pt":1719495218099,"mc":[{"id":"1.230178308","rc":[{"atb":[[2.9,3.38]],"id":39362025}],"con":true,"img":false}]}
{"op":"mcm","clk":"11540500169","pt":1719495218404,"mc":[{"id":"1.230178308","rc":[{"atb":[[2.9,10.73]],"id":39362025}],"con":true,"img":false}]}
{"op":"mcm","clk":"11540502244","pt":1719495244937,"mc":[{"id":"1.230178308","rc":[{"atb":[[1.05,1]],"id":40953876},{"atl":[[1000,0.04]],"id":40953876},{"spn":4.68,"spf":1.0,"id":39362025},{"atb":[[1.04,1]],"id":55829870}],"con":true,"img":false}]}
{"op":"mcm","clk":"11540502257","pt":1719495245095,"mc":[{"id":"1.230178308","rc":[{"atb":[[1.05,0.43]],"id":40953876},{"atl":[[1000,0]],"id":40953876},{"atb":[[1.04,0.53]],"id":55829870}],"con":true,"img":false}]}
{"op":"mcm","clk":"11540502263","pt":1719495245198,"mc":[{"id":"1.230178308","rc":[{"atl":[[29,0.04]],"id":40953876}],"con":true,"img":false}]}
{"op":"mcm","clk":"11540502275","pt":1719495245301,"mc":[{"id":"1.230178308","rc":[{"atb":[[1.05,0]],"id":40953876},{"atb":[[1.04,0]],"id":55829870}],"con":true,"img":false}]}
{"op":"mcm","clk":"11540502284","pt":1719495245416,"mc":[{"id":"1.230178308","rc":[{"atb":[[3.35,0.43]],"id":40953876},{"atb":[[2.88,0.53]],"id":55829870}],"con":true,"img":false}]}
{"op":"mcm","clk":"11540502808","pt":1719495251812,"mc":[{"id":"1.230178308","rc":[{"atb":[[1.28,0]],"id":44798446},{"atb":[[2.06,0]],"id":55829870}],"con":true,"img":false}]}
{"op":"mcm","clk":"11540503014","pt":1719495254214,"mc":[{"id":"1.230178308","rc":[{"atb":[[2.88,0]],"id":39362025}],"con":true,"img":false}]}
{"op":"mcm","clk":"11540503231","pt":1719495256434,"mc":[{"id":"1.230178308","rc":[{"atb":[[2.92,6.17]],"id":39362025}],"con":true,"img":false}]}
{"op":"mcm","clk":"11540503616","pt":1719495260428,"mc":[{"id":"1.230178308","rc":[{"atl":[[29,0]],"id":40953876}],"con":true,"img":false}]}
{"op":"mcm","clk":"11540503638","pt":1719495260635,"mc":[{"id":"1.230178308","rc":[{"atb":[[3.35,0]],"id":40953876},{"atb":[[2.88,0]],"id":55829870}],"con":true,"img":false}]}
{"op":"mcm","clk":"11540503764","pt":1719495262035,"mc":[{"id":"1.230178308","rc":[{"atb":[[1.05,1]],"id":40953876},{"atl":[[1000,0.04]],"id":40953876},{"atb":[[1.04,1]],"id":55829870}],"con":true,"img":false}]}
{"op":"mcm","clk":"11540503775","pt":1719495262137,"mc":[{"id":"1.230178308","rc":[{"atl":[[1000,0]],"id":40953876}],"con":true,"img":false}]}
{"op":"mcm","clk":"11540503785","pt":1719495262243,"mc":[{"id":"1.230178308","rc":[{"atb":[[1.05,0.43]],"id":40953876},{"atl":[[29,0.04]],"id":40953876},{"atb":[[1.04,0.53]],"id":55829870}],"con":true,"img":false}]}
{"op":"mcm","clk":"11540503795","pt":1719495262350,"mc":[{"id":"1.230178308","rc":[{"atb":[[1.05,0]],"id":40953876},{"atb":[[1.04,0]],"id":55829870}],"con":true,"img":false}]}
{"op":"mcm","clk":"11540503803","pt":1719495262450,"mc":[{"id":"1.230178308","rc":[{"atb":[[3.35,0.43]],"id":40953876},{"atb":[[2.88,0.53]],"id":55829870}],"con":true,"img":false}]}
{"op":"mcm","clk":"11540503859","pt":1719495262917,"mc":[{"id":"1.230178308","rc":[{"atb":[[2.9,7.35]],"id":39362025},{"atb":[[1.3,46.58]],"id":44798446}],"con":true,"img":false}]}
{"op":"mcm","clk":"11540503878","pt":1719495263228,"mc":[{"id":"1.230178308","rc":[{"atb":[[2.4,9.97]],"id":48500723},{"atb":[[2.38,10.12]],"id":70218235}],"con":true,"img":false}]}
{"op":"mcm","clk":"11540503908","pt":1719495263542,"mc":[{"id":"1.230178308","rc":[{"atb":[[2.3,10.74]],"id":40953876}],"con":true,"img":false}]}
{"op":"mcm","clk":"11540503927","pt":1719495263749,"mc":[{"id":"1.230178308","rc":[{"atb":[[2.1,12.7]],"id":55829870}],"con":true,"img":false}]}
{"op":"mcm","clk":"11540503939","pt":1719495263851,"mc":[{"id":"1.230178308","rc":[{"atb":[[2.94,3.38]],"id":39362025}],"con":true,"img":false}]}
{"op":"mcm","clk":"11540505195","pt":1719495277442,"mc":[{"id":"1.230178308","rc":[{"atl":[[29,0]],"id":40953876}],"con":true,"img":false}]}
{"op":"mcm","clk":"11540505215","pt":1719495277649,"mc":[{"id":"1.230178308","rc":[{"atb":[[3.35,0]],"id":40953876},{"atb":[[2.88,0]],"id":55829870}],"con":true,"img":false}]}
{"op":"mcm","clk":"11540505374","pt":1719495279259,"mc":[{"id":"1.230178308","rc":[{"atb":[[1.05,1]],"id":40953876},{"atl":[[1000,0.04]],"id":40953876},{"atb":[[1.04,1]],"id":55829870}],"con":true,"img":false}]}
{"op":"mcm","clk":"11540505385","pt":1719495279360,"mc":[{"id":"1.230178308","rc":[{"atl":[[1000,0]],"id":40953876}],"con":true,"img":false}]}
{"op":"mcm","clk":"11540505421","pt":1719495279462,"mc":[{"id":"1.230178308","rc":[{"atb":[[1.05,0.43]],"id":40953876},{"atl":[[29,0.04]],"id":40953876},{"atb":[[1.04,0.53]],"id":55829870}],"con":true,"img":false}]}
{"op":"mcm","clk":"11540505448","pt":1719495279779,"mc":[{"id":"1.230178308","rc":[{"atb":[[1.05,0]],"id":40953876},{"atb":[[1.04,0]],"id":55829870}],"con":true,"img":false}]}
{"op":"mcm","clk":"11540505457","pt":1719495279876,"mc":[{"id":"1.230178308","rc":[{"atb":[[3.35,0.43]],"id":40953876},{"atb":[[2.88,0.53]],"id":55829870}],"con":true,"img":false}]}
{"op":"mcm","clk":"11540506328","pt":1719495288685,"mc":[{"id":"1.230178308","rc":[{"atb":[[1.29,0]],"id":44798446},{"atb":[[2.08,0]],"id":55829870}],"con":true,"img":false}]}
{"op":"mcm","clk":"11540506892","pt":1719495294763,"mc":[{"id":"1.230178308","rc":[{"atl":[[29,0]],"id":40953876}],"con":true,"img":false}]}
{"op":"mcm","clk":"11540506898","pt":1719495294867,"mc":[{"id":"1.230178308","rc":[{"atb":[[2.9,0]],"id":39362025},{"atb":[[1.31,38.23]],"id":44798446}],"con":true,"img":false}]}
{"op":"mcm","clk":"11540506909","pt":1719495294971,"mc":[{"id":"1.230178308","rc":[{"atb":[[2.12,10.57]],"id":55829870}],"con":true,"img":false}]}
{"op":"mcm","clk":"11540506922","pt":1719495295076,"mc":[{"id":"1.230178308","rc":[{"atb":[[3.35,0]],"id":40953876},{"atb":[[2.88,0]],"id":55829870}],"con":true,"img":false}]}
{"op":"mcm","clk":"11540507020","pt":1719495296068,"mc":[{"id":"1.230178308","rc":[{"atb":[[1.05,1]],"id":40953876},{"atl":[[1000,0.04]],"id":40953876},{"atb":[[1.04,1]],"id":55829870}],"con":true,"img":false}]}
{"op":"mcm","clk":"11540507039","pt":1719495296277,"mc":[{"id":"1.230178308","rc":[{"atb":[[1.05,0.43]],"id":40953876},{"atl":[[1000,0]],"id":40953876},{"atb":[[1.04,0.53]],"id":55829870}],"con":true,"img":false}]}
{"op":"mcm","clk":"11540507053","pt":1719495296381,"mc":[{"id":"1.230178308","rc":[{"atl":[[29,0.04]],"id":40953876}],"con":true,"img":false}]}
{"op":"mcm","clk":"11540507061","pt":1719495296485,"mc":[{"id":"1.230178308","rc":[{"atb":[[1.05,0]],"id":40953876},{"atb":[[1.04,0]],"id":55829870}],"con":true,"img":false}]}
{"op":"mcm","clk":"11540507096","pt":1719495296798,"mc":[{"id":"1.230178308","rc":[{"atb":[[3.35,0.43]],"id":40953876},{"atb":[[2.88,0.53]],"id":55829870}],"con":true,"img":false}]}
{"op":"mcm","clk":"11540507941","pt":1719495305487,"mc":[{"id":"1.230178308","rc":[{"atl":[[29,0.88]],"id":40953876},{"spn":3.3,"spf":1.0,"id":40953876},{"spn":4.7,"spf":1.0,"id":39362025},{"atl":[[140,0.84]],"id":48500723},{"spn":72.2,"spf":"NaN","id":48500723},{"spn":5.44,"spf":"NaN","id":55829870}],"con":true,"img":false}]}
{"op":"mcm","clk":"11540507993","pt":1719495306113,"mc":[{"id":"1.230178308","rc":[{"atb":[[2.94,10.58]],"id":39362025}],"con":true,"img":false}]}
{"op":"mcm","clk":"11540508049","pt":1719495306603,"mc":[{"id":"1.230178308","rc":[{"atb":[[2.28,2.1]],"id":40953876},{"atb":[[2.92,0]],"id":39362025},{"atb":[[2.38,0]],"id":48500723},{"atb":[[2.36,0]],"id":70218235}],"con":true,"img":false}]}
{"op":"mcm","clk":"11540508524","pt":1719495311914,"mc":[{"id":"1.230178308","rc":[{"atl":[[29,0.84]],"id":40953876}],"con":true,"img":false}]}
{"op":"mcm","clk":"11540508534","pt":1719495311969,"mc":[{"id":"1.230178308","rc":[{"atb":[[3.35,0]],"id":40953876},{"atb":[[2.88,0]],"id":55829870}],"con":true,"img":false}]}
{"op":"mcm","clk":"11540508620","pt":1719495313009,"mc":[{"id":"1.230178308","rc":[{"atb":[[2.32,8.97]],"id":40953876}],"con":true,"img":false}]}
{"op":"mcm","clk":"11540508644","pt":1719495313218,"mc":[{"id":"1.230178308","rc":[{"atb":[[1.05,1]],"id":40953876},{"atl":[[1000,0.04]],"id":40953876},{"atb":[[2.96,6.04]],"id":39362025},{"atb":[[2.4,8.46]],"id":70218235},{"atb":[[1.04,1]],"id":55829870}],"con":true,"img":false}]}
{"op":"mcm","clk":"11540508655","pt":1719495313375,"mc":[{"id":"1.230178308","rc":[{"atb":[[1.05,0.43]],"id":40953876},{"atl":[[1000,0]],"id":40953876},{"atb":[[2.42,8.34]],"id":48500723},{"atb":[[1.04,0.53]],"id":55829870}],"con":true,"img":false}]}
{"op":"mcm","clk":"11540508666","pt":1719495313481,"mc":[{"id":"1.230178308","rc":[{"atl":[[29,0.88]],"id":40953876}],"con":true,"img":false}]}
{"op":"mcm","clk":"11540508674","pt":1719495313581,"mc":[{"id":"1.230178308","rc":[{"atb":[[1.05,0]],"id":40953876},{"atb":[[1.04,0]],"id":55829870}],"con":true,"img":false}]}
{"op":"mcm","clk":"11540508680","pt":1719495313687,"mc":[{"id":"1.230178308","rc":[{"atb":[[3.35,0.43]],"id":40953876},{"atb":[[2.88,0.53]],"id":55829870}],"con":true,"img":false}]}
{"op":"mcm","clk":"11540510087","pt":1719495328720,"mc":[{"id":"1.230178308","rc":[{"atl":[[29,0.84]],"id":40953876}],"con":true,"img":false}]}
{"op":"mcm","clk":"11540510104","pt":1719495328924,"mc":[{"id":"1.230178308","rc":[{"atb":[[3.35,0]],"id":40953876},{"atb":[[2.88,0]],"id":55829870}],"con":true,"img":false}]}
{"op":"mcm","clk":"11540510221","pt":1719495330224,"mc":[{"id":"1.230178308","rc":[{"atb":[[1.05,1]],"id":40953876},{"atl":[[1000,0.04]],"id":40953876}],"con":true,"img":false}]}
{"op":"mcm","clk":"11540510234","pt":1719495330328,"mc":[{"id":"1.230178308","rc":[{"atb":[[1.05,0.43]],"id":40953876},{"atb":[[1.04,1]],"id":55829870}],"con":true,"img":false}]}
{"op":"mcm","clk":"11540510248","pt":1719495330431,"mc":[{"id":"1.230178308","rc":[{"atl":[[1000,0]],"id":40953876}],"con":true,"img":false}]}
{"op":"mcm","clk":"11540510254","pt":1719495330485,"mc":[{"id":"1.230178308","rc":[{"atb":[[1.05,0]],"id":40953876},{"atl":[[29,0.88]],"id":40953876},{"atb":[[1.04,0.53]],"id":55829870}],"con":true,"img":false}]}
{"op":"mcm","clk":"11540510266","pt":1719495330587,"mc":[{"id":"1.230178308","rc":[{"atb":[[3.35,0.43]],"id":40953876}],"con":true,"img":false}]}
{"op":"mcm","clk":"11540510278","pt":1719495330694,"mc":[{"id":"1.230178308","rc":[{"atb":[[1.04,0]],"id":55829870}],"con":true,"img":false}]}
{"op":"mcm","clk":"11540510286","pt":1719495330799,"mc":[{"id":"1.230178308","rc":[{"atb":[[2.88,0.53]],"id":55829870}],"con":true,"img":false}]}
{"op":"mcm","clk":"11540510567","pt":1719495333947,"mc":[{"id":"1.230178308","rc":[{"atb":[[1.3,0]],"id":44798446},{"atb":[[2.1,0]],"id":55829870}],"con":true,"img":false}]}
{"op":"mcm","clk":"11540511587","pt":1719495345776,"mc":[{"id":"1.230178308","rc":[{"atb":[[3.35,0]],"id":40953876},{"atl":[[29,0.84]],"id":40953876}],"con":true,"img":false}]}
{"op":"mcm","clk":"11540511607","pt":1719495345987,"mc":[{"id":"1.230178308","rc":[{"atb":[[2.88,0]],"id":55829870}],"con":true,"img":false}]}
{"op":"mcm","clk":"11540511729","pt":1719495347244,"mc":[{"id":"1.230178308","rc":[{"atl":[[1000,0.04]],"id":40953876},{"atb":[[1.04,1]],"id":55829870}],"con":true,"img":false}]}
{"op":"mcm","clk":"11540511741","pt":1719495347367,"mc":[{"id":"1.230178308","rc":[{"atb":[[1.05,1]],"id":40953876},{"atb":[[1.04,0.53]],"id":55829870}],"con":true,"img":false}]}
