{"op":"mcm","clk":"11536832974","pt":1719431775500,"mc":[{"id":"1.230180114","marketDefinition":{"bspMarket":true,"turnInPlayEnabled":false,"persistenceEnabled":false,"marketBaseRate":5.0,"eventId":"33376437","eventTypeId":"4339","numberOfWinners":1,"bettingType":"ODDS","marketType":"WIN","marketTime":"2024-06-27T13:52:00.000Z","suspendTime":"2024-06-27T13:52:00.000Z","bspReconciled":false,"complete":true,"inPlay":false,"crossMatching":false,"runnersVoidable":false,"numberOfActiveRunners":6,"betDelay":0,"status":"OPEN","runners":[{"status":"ACTIVE","sortPriority":1,"id":39682601,"name":"1. Lilys Pearl"},{"status":"ACTIVE","sortPriority":2,"id":61150133,"name":"2. Mind The Mud"},{"status":"ACTIVE","sortPriority":3,"id":43289758,"name":"3. Salacres Harry"},{"status":"ACTIVE","sortPriority":4,"id":44213406,"name":"4. Go Bye Baby"},{"status":"ACTIVE","sortPriority":5,"id":41804643,"name":"5. Salacres Harold"},{"status":"ACTIVE","sortPriority":6,"id":63387150,"name":"6. Salacres Dolce"}],"regulators":["MR_INT"],"venue":"Towcester","countryCode":"GB","discountAllowed":false,"timezone":"Europe/London","openDate":"2024-06-27T13:33:00.000Z","version":5994767089,"name":"D4 270m","eventName":"Towcester 27th Jun"},"rc":[],"con":true,"img":false}]}
{"op":"mcm","clk":"11536833109","pt":1719431777486,"mc":[{"id":"1.230180114","marketDefinition":{"bspMarket":true,"turnInPlayEnabled":false,"persistenceEnabled":false,"marketBaseRate":5.0,"eventId":"33376437","eventTypeId":"4339","numberOfWinners":1,"bettingType":"ODDS","marketType":"WIN","marketTime":"2024-06-27T13:52:00.000Z","suspendTime":"2024-06-27T13:52:00.000Z","bspReconciled":false,"complete":true,"inPlay":false,"crossMatching":false,"runnersVoidable":false,"numberOfActiveRunners":6,"betDelay":0,"status":"OPEN","runners":[{"status":"ACTIVE","sortPriority":1,"id":39682601,"name":"1. Lilys Pearl"},{"status":"ACTIVE","sortPriority":2,"id":61150133,"name":"2. Mind The Mud"},{"status":"ACTIVE","sortPriority":3,"id":43289758,"name":"3. Salacres Harry"},{"status":"ACTIVE","sortPriority":4,"id":44213406,"name":"4. Go Bye Baby"},{"status":"ACTIVE","sortPriority":5,"id":41804643,"name":"5. Salacres Harold"},{"status":"ACTIVE","sortPriority":6,"id":63387150,"name":"6. Salacres Dolce"}],"regulators":["MR_INT"],"venue":"Towcester","countryCode":"GB","discountAllowed":true,"timezone":"Europe/London","openDate":"2024-06-27T13:33:00.000Z","version":5994767089,"name":"D4 270m","eventName":"Towcester 27th Jun"},"rc":[],"con":true,"img":false}]}
{"op":"mcm","clk":"11537083794","pt":1719435431506,"mc":[{"id":"1.230180114","rc":[{"atb":[[1.03,10.99]],"id":41804643},{"atl":[[990,0.84]],"id":41804643},{"spn":495.51,"spf":"NaN","id":41804643},{"atb":[[1.01,32.96]],"id":61150133},{"atl":[[1000,0.84]],"id":61150133},{"spn":500.5,"spf":"NaN","id":61150133},{"atb":[[1.02,16.48]],"id":44213406},{"atl":[[1000,0.84]],"id":44213406},{"spn":500.51,"spf":"NaN","id":44213406},{"atb":[[1.01,32.96]],"id":39682601},{"atl":[[1000,0.84]],"id":39682601},{"spn":500.5,"spf":"NaN","id":39682601},{"atb":[[1.03,10.99]],"id":63387150},{"atl":[[1000,0.84]],"id":63387150},{"spn":500.51,"spf":"NaN","id":63387150},{"atb":[[1.01,32.96]],"id":43289758},{"atl":[[990,0.84]],"id":43289758},{"spn":495.5,"spf":"NaN","id":43289758}],"con":true,"img":false}]}
{"op":"mcm","clk":"11537233752","pt":1719437882661,"mc":[{"id":"1.230180114","marketDefinition":{"bspMarket":true,"turnInPlayEnabled":false,"persistenceEnabled":false,"marketBaseRate":5.0,"eventId":"33376437","eventTypeId":"4339","numberOfWinners":1,"bettingType":"ODDS","marketType":"WIN","marketTime":"2024-06-27T13:52:00.000Z","suspendTime":"2024-06-27T13:52:00.000Z","bspReconciled":false,"complete":true,"inPlay":false,"crossMatching":false,"runnersVoidable":false,"numberOfActiveRunners":6,"betDelay":0,"status":"OPEN","runners":[{"status":"ACTIVE","sortPriority":1,"id":39682601,"name":"1. Lilys Pearl"},{"status":"ACTIVE","sortPriority":2,"id":61150133,"name":"2. Mind The Mud"},{"status":"ACTIVE","sortPriority":3,"id":43289758,"name":"3. Salacres Harry"},{"status":"ACTIVE","sortPriority":4,"id":44213406,"name":"4. Go Bye Baby"},{"status":"ACTIVE","sortPriority":5,"id":41804643,"name":"5. Salacres Harold"},{"status":"ACTIVE","sortPriority":6,"id":63387150,"name":"6. Salacres Dolce"}],"regulators":["MR_INT"],"venue":"Towcester","countryCode":"GB","discountAllowed":true,"timezone":"Europe/London","openDate":"2024-06-27T13:33:00.000Z","version":5994767089,"name":"D4 270m","eventName":"Towcester 27th Jun"},"rc":[{"atb":[[1.03,10.99]],"id":41804643},{"atl":[[990,0.84]],"id":41804643},{"spn":495.51,"spf":"NaN","id":41804643},{"atb":[[1.01,32.96]],"id":61150133},{"atl":[[1000,0.84]],"id":61150133},{"spn":500.5,"spf":"NaN","id":61150133},{"atb":[[1.02,16.48]],"id":44213406},{"atl":[[1000,0.84]],"id":44213406},{"spn":500.51,"spf":"NaN","id":44213406},{"atb":[[1.01,32.96]],"id":39682601},{"atl":[[1000,0.84]],"id":39682601},{"spn":500.5,"spf":"NaN","id":39682601},{"atb":[[1.03,10.99]],"id":63387150},{"atl":[[1000,0.84]],"id":63387150},{"spn":500.51,"spf":"NaN","id":63387150},{"atb":[[1.01,32.96]],"id":43289758},{"atl":[[990,0.84]],"id":43289758},{"spn":495.5,"spf":"NaN","id":43289758}],"con":true,"img":true}]}
{"op":"mcm","clk":"11537302062","pt":1719439029051,"mc":[{"id":"1.230180114","rc":[{"atb":[[1.03,10.99]],"id":41804643},{"atl":[[990,0.17]],"id":41804643},{"atb":[[1.01,32.96]],"id":61150133},{"atl":[[1000,0.17]],"id":61150133},{"atb":[[1.02,16.48]],"id":44213406},{"atl":[[1000,0.17]],"id":44213406},{"atb":[[1.01,32.96]],"id":39682601},{"atl":[[1000,0.17]],"id":39682601},{"atb":[[1.03,10.99]],"id":63387150},{"atl":[[1000,0.17]],"id":63387150},{"atb":[[1.01,32.96]],"id":43289758},{"atl":[[990,0.17]],"id":43289758}],"con":true,"img":false}]}
{"op":"mcm","clk":"11537574905","pt":1719443282712,"mc":[{"id":"1.230180114","marketDefinition":{"bspMarket":true,"turnInPlayEnabled":false,"persistenceEnabled":false,"marketBaseRate":5.0,"eventId":"33376437","eventTypeId":"4339","numberOfWinners":1,"bettingType":"ODDS","marketType":"WIN","marketTime":"2024-06-27T13:52:00.000Z","suspendTime":"2024-06-27T13:52:00.000Z","bspReconciled":false,"complete":true,"inPlay":false,"crossMatching":false,"runnersVoidable":false,"numberOfActiveRunners":6,"betDelay":0,"status":"OPEN","runners":[{"status":"ACTIVE","sortPriority":1,"id":39682601,"name":"1. Lilys Pearl"},{"status":"ACTIVE","sortPriority":2,"id":61150133,"name":"2. Mind The Mud"},{"status":"ACTIVE","sortPriority":3,"id":43289758,"name":"3. Salacres Harry"},{"status":"ACTIVE","sortPriority":4,"id":44213406,"name":"4. Go Bye Baby"},{"status":"ACTIVE","sortPriority":5,"id":41804643,"name":"5. Salacres Harold"},{"status":"ACTIVE","sortPriority":6,"id":63387150,"name":"6. Salacres Dolce"}],"regulators":["MR_INT"],"venue":"Towcester","countryCode":"GB","discountAllowed":true,"timezone":"Europe/London","openDate":"2024-06-27T13:33:00.000Z","version":5994767089,"name":"D4 270m","eventName":"Towcester 27th Jun"},"rc":[{"atb":[[1.03,10.99]],"id":41804643},{"atl":[[990,0.17]],"id":41804643},{"spn":495.51,"spf":"NaN","id":41804643},{"atb":[[1.01,32.96]],"id":61150133},{"atl":[[1000,0.17]],"id":61150133},{"spn":500.5,"spf":"NaN","id":61150133},{"atb":[[1.02,16.48]],"id":44213406},{"atl":[[1000,0.17]],"id":44213406},{"spn":500.51,"spf":"NaN","id":44213406},{"atb":[[1.01,32.96]],"id":39682601},{"atl":[[1000,0.17]],"id":39682601},{"spn":500.5,"spf":"NaN","id":39682601},{"atb":[[1.03,10.99]],"id":63387150},{"atl":[[1000,0.17]],"id":63387150},{"spn":500.51,"spf":"NaN","id":63387150},{"atb":[[1.01,32.96]],"id":43289758},{"atl":[[990,0.17]],"id":43289758},{"spn":495.5,"spf":"NaN","id":43289758}],"con":true,"img":true}]}
{"op":"mcm","clk":"11537956525","pt":1719448682753,"mc":[{"id":"1.230180114","marketDefinition":{"bspMarket":true,"turnInPlayEnabled":false,"persistenceEnabled":false,"marketBaseRate":5.0,"eventId":"33376437","eventTypeId":"4339","numberOfWinners":1,"bettingType":"ODDS","marketType":"WIN","marketTime":"2024-06-27T13:52:00.000Z","suspendTime":"2024-06-27T13:52:00.000Z","bspReconciled":false,"complete":true,"inPlay":false,"crossMatching":false,"runnersVoidable":false,"numberOfActiveRunners":6,"betDelay":0,"status":"OPEN","runners":[{"status":"ACTIVE","sortPriority":1,"id":39682601,"name":"1. Lilys Pearl"},{"status":"ACTIVE","sortPriority":2,"id":61150133,"name":"2. Mind The Mud"},{"status":"ACTIVE","sortPriority":3,"id":43289758,"name":"3. Salacres Harry"},{"status":"ACTIVE","sortPriority":4,"id":44213406,"name":"4. Go Bye Baby"},{"status":"ACTIVE","sortPriority":5,"id":41804643,"name":"5. Salacres Harold"},{"status":"ACTIVE","sortPriority":6,"id":63387150,"name":"6. Salacres Dolce"}],"regulators":["MR_INT"],"venue":"Towcester","countryCode":"GB","discountAllowed":true,"timezone":"Europe/London","openDate":"2024-06-27T13:33:00.000Z","version":5994767089,"name":"D4 270m","eventName":"Towcester 27th Jun"},"rc":[{"atb":[[1.03,10.99]],"id":41804643},{"atl":[[990,0.17]],"id":41804643},{"spn":495.51,"spf":"NaN","id":41804643},{"atb":[[1.01,32.96]],"id":61150133},{"atl":[[1000,0.17]],"id":61150133},{"spn":500.5,"spf":"NaN","id":61150133},{"atb":[[1.02,16.48]],"id":44213406},{"atl":[[1000,0.17]],"id":44213406},{"spn":500.51,"spf":"NaN","id":44213406},{"atb":[[1.01,32.96]],"id":39682601},{"atl":[[1000,0.17]],"id":39682601},{"spn":500.5,"spf":"NaN","id":39682601},{"atb":[[1.03,10.99]],"id":63387150},{"atl":[[1000,0.17]],"id":63387150},{"spn":500.51,"spf":"NaN","id":63387150},{"atb":[[1.01,32.96]],"id":43289758},{"atl":[[990,0.17]],"id":43289758},{"spn":495.5,"spf":"NaN","id":43289758}],"con":true,"img":true}]}
{"op":"mcm","clk":"11538172142","pt":1719454082696,"mc":[{"id":"1.230180114","marketDefinition":{"bspMarket":true,"turnInPlayEnabled":false,"persistenceEnabled":false,"marketBaseRate":5.0,"eventId":"33376437","eventTypeId":"4339","numberOfWinners":1,"bettingType":"ODDS","marketType":"WIN","marketTime":"2024-06-27T13:52:00.000Z","suspendTime":"2024-06-27T13:52:00.000Z","bspReconciled":false,"complete":true,"inPlay":false,"crossMatching":false,"runnersVoidable":false,"numberOfActiveRunners":6,"betDelay":0,"status":"OPEN","runners":[{"status":"ACTIVE","sortPriority":1,"id":39682601,"name":"1. Lilys Pearl"},{"status":"ACTIVE","sortPriority":2,"id":61150133,"name":"2. Mind The Mud"},{"status":"ACTIVE","sortPriority":3,"id":43289758,"name":"3. Salacres Harry"},{"status":"ACTIVE","sortPriority":4,"id":44213406,"name":"4. Go Bye Baby"},{"status":"ACTIVE","sortPriority":5,"id":41804643,"name":"5. Salacres Harold"},{"status":"ACTIVE","sortPriority":6,"id":63387150,"name":"6. Salacres Dolce"}],"regulators":["MR_INT"],"venue":"Towcester","countryCode":"GB","discountAllowed":true,"timezone":"Europe/London","openDate":"2024-06-27T13:33:00.000Z","version":5994767089,"name":"D4 270m","eventName":"Towcester 27th Jun"},"rc":[{"atb":[[1.03,10.99]],"id":41804643},{"atl":[[990,0.17]],"id":41804643},{"spn":495.51,"spf":"NaN","id":41804643},{"atb":[[1.01,32.97]],"id":61150133},{"atl":[[1000,0.17]],"id":61150133},{"spn":500.5,"spf":"NaN","id":61150133},{"atb":[[1.02,16.48]],"id":44213406},{"atl":[[1000,0.17]],"id":44213406},{"spn":500.51,"spf":"NaN","id":44213406},{"atb":[[1.01,32.97]],"id":39682601},{"atl":[[1000,0.17]],"id":39682601},{"spn":500.5,"spf":"NaN","id":39682601},{"atb":[[1.03,10.99]],"id":63387150},{"atl":[[1000,0.17]],"id":63387150},{"spn":500.51,"spf":"NaN","id":63387150},{"atb":[[1.01,32.97]],"id":43289758},{"atl":[[990,0.17]],"id":43289758},{"spn":495.5,"spf":"NaN","id":43289758}],"con":true,"img":true}]}
{"op":"mcm","clk":"11538369809","pt":1719459482782,"mc":[{"id":"1.230180114","marketDefinition":{"bspMarket":true,"turnInPlayEnabled":false,"persistenceEnabled":false,"marketBaseRate":5.0,"eventId":"33376437","eventTypeId":"4339","numberOfWinners":1,"bettingType":"ODDS","marketType":"WIN","marketTime":"2024-06-27T13:52:00.000Z","suspendTime":"2024-06-27T13:52:00.000Z","bspReconciled":false,"complete":true,"inPlay":false,"crossMatching":false,"runnersVoidable":false,"numberOfActiveRunners":6,"betDelay":0,"status":"OPEN","runners":[{"status":"ACTIVE","sortPriority":1,"id":39682601,"name":"1. Lilys Pearl"},{"status":"ACTIVE","sortPriority":2,"id":61150133,"name":"2. Mind The Mud"},{"status":"ACTIVE","sortPriority":3,"id":43289758,"name":"3. Salacres Harry"},{"status":"ACTIVE","sortPriority":4,"id":44213406,"name":"4. Go Bye Baby"},{"status":"ACTIVE","sortPriority":5,"id":41804643,"name":"5. Salacres Harold"},{"status":"ACTIVE","sortPriority":6,"id":63387150,"name":"6. Salacres Dolce"}],"regulators":["MR_INT"],"venue":"Towcester","countryCode":"GB","discountAllowed":true,"timezone":"Europe/London","openDate":"2024-06-27T13:33:00.000Z","version":5994767089,"name":"D4 270m","eventName":"Towcester 27th Jun"},"rc":[{"atb":[[1.03,10.99]],"id":41804643},{"atl":[[990,0.17]],"id":41804643},{"spn":495.51,"spf":"NaN","id":41804643},{"atb":[[1.01,32.97]],"id":61150133},{"atl":[[1000,0.17]],"id":61150133},{"spn":500.5,"spf":"NaN","id":61150133},{"atb":[[1.02,16.48]],"id":44213406},{"atl":[[1000,0.17]],"id":44213406},{"spn":500.51,"spf":"NaN","id":44213406},{"atb":[[1.01,32.97]],"id":39682601},{"atl":[[1000,0.17]],"id":39682601},{"spn":500.5,"spf":"NaN","id":39682601},{"atb":[[1.03,10.99]],"id":63387150},{"atl":[[1000,0.17]],"id":63387150},{"spn":500.51,"spf":"NaN","id":63387150},{"atb":[[1.01,32.97]],"id":43289758},{"atl":[[990,0.17]],"id":43289758},{"spn":495.5,"spf":"NaN","id":43289758}],"con":true,"img":true}]}
{"op":"mcm","clk":"11538549508","pt":1719463936429,"mc":[{"id":"1.230180114","rc":[{"atb":[[1.03,10.99]],"id":41804643},{"atb":[[1.01,32.97]],"id":61150133},{"atl":[[150,4]],"id":61150133},{"spn":75.5,"spf":"NaN","id":61150133},{"atb":[[1.02,16.48]],"id":44213406},{"atb":[[1.01,32.97]],"id":39682601},{"atl":[[150,4]],"id":39682601},{"spn":75.5,"spf":"NaN","id":39682601},{"atb":[[1.03,10.99]],"id":63387150},{"atb":[[1.01,32.97]],"id":43289758},{"atl":[[150,4]],"id":43289758},{"spn":75.5,"spf":"NaN","id":43289758}],"con":true,"img":false}]}
{"op":"mcm","clk":"11538549514","pt":1719463936528,"mc":[{"id":"1.230180114","rc":[{"atl":[[150,4]],"id":41804643},{"atl":[[150,4]],"id":44213406},{"atl":[[150,4]],"id":63387150}],"con":true,"img":false}]}
{"op":"mcm","clk":"11538596939","pt":1719464882725,"mc":[{"id":"1.230180114","marketDefinition":{"bspMarket":true,"turnInPlayEnabled":false,"persistenceEnabled":false,"marketBaseRate":5.0,"eventId":"33376437","eventTypeId":"4339","numberOfWinners":1,"bettingType":"ODDS","marketType":"WIN","marketTime":"2024-06-27T13:52:00.000Z","suspendTime":"2024-06-27T13:52:00.000Z","bspReconciled":false,"complete":true,"inPlay":false,"crossMatching":false,"runnersVoidable":false,"numberOfActiveRunners":6,"betDelay":0,"status":"OPEN","runners":[{"status":"ACTIVE","sortPriority":1,"id":39682601,"name":"1. Lilys Pearl"},{"status":"ACTIVE","sortPriority":2,"id":61150133,"name":"2. Mind The Mud"},{"status":"ACTIVE","sortPriority":3,"id":43289758,"name":"3. Salacres Harry"},{"status":"ACTIVE","sortPriority":4,"id":44213406,"name":"4. Go Bye Baby"},{"status":"ACTIVE","sortPriority":5,"id":41804643,"name":"5. Salacres Harold"},{"status":"ACTIVE","sortPriority":6,"id":63387150,"name":"6. Salacres Dolce"}],"regulators":["MR_INT"],"venue":"Towcester","countryCode":"GB","discountAllowed":true,"timezone":"Europe/London","openDate":"2024-06-27T13:33:00.000Z","version":5994767089,"name":"D4 270m","eventName":"Towcester 27th Jun"},"rc":[{"atb":[[1.03,10.99]],"id":41804643},{"atl":[[150,4],[990,0.17]],"id":41804643},{"spn":75.51,"spf":"NaN","id":41804643},{"atb":[[1.01,32.97]],"id":61150133},{"atl":[[150,4],[1000,0.17]],"id":61150133},{"spn":75.5,"spf":"NaN","id":61150133},{"atb":[[1.02,16.48]],"id":44213406},{"atl":[[150,4],[1000,0.17]],"id":44213406},{"spn":75.51,"spf":"NaN","id":44213406},{"atb":[[1.01,32.97]],"id":39682601},{"atl":[[150,4],[1000,0.17]],"id":39682601},{"spn":75.5,"spf":"NaN","id":39682601},{"atb":[[1.03,10.99]],"id":63387150},{"atl":[[150,4],[1000,0.17]],"id":63387150},{"spn":75.51,"spf":"NaN","id":63387150},{"atb":[[1.01,32.97]],"id":43289758},{"atl":[[150,4],[990,0.17]],"id":43289758},{"spn":75.5,"spf":"NaN","id":43289758}],"con":true,"img":true}]}
{"op":"mcm","clk":"11538748540","pt":1719468203367,"mc":[{"id":"1.230180114","rc":[{"atb":[[1.03,10.99],[2.08,10.66]],"id":41804643},{"spn":76.04,"spf":"NaN","id":41804643},{"atb":[[1.01,32.97],[2.08,9.77]],"id":61150133},{"spn":76.04,"spf":"NaN","id":61150133},{"atb":[[1.02,16.48],[2.08,10.66]],"id":44213406},{"spn":76.04,"spf":"NaN","id":44213406},{"atb":[[1.01,32.97],[2.04,9.58]],"id":39682601},{"spn":76.02,"spf":"NaN","id":39682601},{"atb":[[1.03,10.99],[2.1,9.86]],"id":63387150},{"spn":76.05,"spf":"NaN","id":63387150},{"atb":[[1.01,32.97],[2.08,11.55]],"id":43289758},{"spn":76.04,"spf":"NaN","id":43289758}],"con":true,"img":false}]}
{"op":"mcm","clk":"11538751222","pt":1719468257763,"mc":[{"id":"1.230180114","rc":[{"atb":[[2.1,3.16]],"id":61150133}],"con":true,"img":false}]}
{"op":"mcm","clk":"11538751231","pt":1719468257967,"mc":[{"id":"1.230180114","rc":[{"atb":[[2.06,3.16]],"id":39682601}],"con":true,"img":false}]}
{"op":"mcm","clk":"11538751240","pt":1719468258172,"mc":[{"id":"1.230180114","rc":[{"atb":[[2.1,3.16]],"id":41804643},{"atb":[[2.12,3.16]],"id":63387150}],"con":true,"img":false}]}
{"op":"mcm","clk":"11538751256","pt":1719468258681,"mc":[{"id":"1.230180114","rc":[{"atb":[[2.1,3.16]],"id":44213406}],"con":true,"img":false}]}
{"op":"mcm","clk":"11538751294","pt":1719468259454,"mc":[{"id":"1.230180114","rc":[{"atb":[[2.1,3.16]],"id":43289758}],"con":true,"img":false}]}
{"op":"mcm","clk":"11538752363","pt":1719468281717,"mc":[{"id":"1.230180114","marketDefinition":{"bspMarket":true,"turnInPlayEnabled":false,"persistenceEnabled":false,"marketBaseRate":5.0,"eventId":"33376437","eventTypeId":"4339","numberOfWinners":1,"bettingType":"ODDS","marketType":"WIN","marketTime":"2024-06-27T13:52:00.000Z","suspendTime":"2024-06-27T13:52:00.000Z","bspReconciled":false,"complete":true,"inPlay":false,"crossMatching":true,"runnersVoidable":false,"numberOfActiveRunners":6,"betDelay":0,"status":"OPEN","runners":[{"status":"ACTIVE","sortPriority":1,"id":39682601,"name":"1. Lilys Pearl"},{"status":"ACTIVE","sortPriority":2,"id":61150133,"name":"2. Mind The Mud"},{"status":"ACTIVE","sortPriority":3,"id":43289758,"name":"3. Salacres Harry"},{"status":"ACTIVE","sortPriority":4,"id":44213406,"name":"4. Go Bye Baby"},{"status":"ACTIVE","sortPriority":5,"id":41804643,"name":"5. Salacres Harold"},{"status":"ACTIVE","sortPriority":6,"id":63387150,"name":"6. Salacres Dolce"}],"regulators":["MR_INT"],"venue":"Towcester","countryCode":"GB","discountAllowed":true,"timezone":"Europe/London","openDate":"2024-06-27T13:33:00.000Z","version":5994767089,"name":"D4 270m","eventName":"Towcester 27th Jun"},"rc":[],"con":true,"img":false}]}
{"op":"mcm","clk":"11538753460","pt":1719468301233,"mc":[{"id":"1.230180114","rc":[{"spn":76.05,"spf":"NaN","id":41804643},{"spn":76.05,"spf":"NaN","id":61150133},{"spn":76.05,"spf":"NaN","id":44213406},{"atb":[[2.06,6.55]],"id":39682601},{"spn":76.03,"spf":"NaN","id":39682601},{"spn":76.06,"spf":"NaN","id":63387150},{"spn":76.05,"spf":"NaN","id":43289758}],"con":true,"img":false}]}
{"op":"mcm","clk":"11538753465","pt":1719468301334,"mc":[{"id":"1.230180114","rc":[{"atb":[[2.1,6.55]],"id":61150133}],"con":true,"img":false}]}
{"op":"mcm","clk":"11538753490","pt":1719468301848,"mc":[{"id":"1.230180114","rc":[{"atb":[[2.1,6.55]],"id":41804643}],"con":true,"img":false}]}
{"op":"mcm","clk":"11538753496","pt":1719468301903,"mc":[{"id":"1.230180114","rc":[{"atb":[[2.1,6.55]],"id":44213406}],"con":true,"img":false}]}
{"op":"mcm","clk":"11538753513","pt":1719468302109,"mc":[{"id":"1.230180114","rc":[{"atb":[[2.1,6.55]],"id":43289758}],"con":true,"img":false}]}
{"op":"mcm","clk":"11538753538","pt":1719468302421,"mc":[{"id":"1.230180114","rc":[{"atb":[[2.12,6.55]],"id":63387150}],"con":true,"img":false}]}
{"op":"mcm","clk":"11538940468","pt":1719472109314,"mc":[{"id":"1.230180114","rc":[{"atb":[[1.03,10.98],[2.1,6.54],[2.08,0]],"id":41804643},{"atl":[[990,0.17]],"id":41804643},{"atb":[[1.01,32.94],[2.1,6.54],[2.08,0]],"id":61150133},{"atl":[[1000,0.17]],"id":61150133},{"atb":[[1.02,16.47],[2.1,6.54],[2.08,0]],"id":44213406},{"atl":[[1000,0.17]],"id":44213406},{"atb":[[1.01,32.94],[2.06,6.54],[2.04,0]],"id":39682601},{"atl":[[1000,0.17]],"id":39682601},{"atb":[[1.03,10.98],[2.12,6.54],[2.1,0]],"id":63387150},{"atl":[[1000,0.17]],"id":63387150},{"atb":[[1.01,32.94],[2.1,6.54],[2.08,0]],"id":43289758},{"atl":[[990,0.17]],"id":43289758}],"con":true,"img":false}]}
{"op":"mcm","clk":"11538940471","pt":1719472109417,"mc":[{"id":"1.230180114","rc":[{"atb":[[2.12,10.65]],"id":41804643},{"atb":[[2.12,9.76]],"id":61150133},{"atb":[[2.12,10.65]],"id":44213406},{"atb":[[2.08,9.58]],"id":39682601},{"atb":[[2.14,9.86]],"id":63387150},{"atb":[[2.12,11.54]],"id":43289758}],"con":true,"img":false}]}
{"op":"mcm","clk":"11538944406","pt":1719472172021,"mc":[{"id":"1.230180114","rc":[{"spn":76.06,"spf":"NaN","id":41804643},{"spn":76.06,"spf":"NaN","id":61150133},{"spn":76.06,"spf":"NaN","id":44213406},{"spn":76.04,"spf":"NaN","id":39682601},{"spn":76.07,"spf":"NaN","id":63387150},{"atb":[[2.1,3.38]],"id":43289758},{"spn":76.06,"spf":"NaN","id":43289758}],"con":true,"img":false}]}
{"op":"mcm","clk":"11538944444","pt":1719472172793,"mc":[{"id":"1.230180114","rc":[{"atb":[[2.1,3.38]],"id":44213406}],"con":true,"img":false}]}
{"op":"mcm","clk":"11538944475","pt":1719472173200,"mc":[{"id":"1.230180114","rc":[{"atb":[[2.1,3.38]],"id":41804643}],"con":true,"img":false}]}
{"op":"mcm","clk":"11538944530","pt":1719472173918,"mc":[{"id":"1.230180114","rc":[{"atb":[[2.06,3.38]],"id":39682601}],"con":true,"img":false}]}
{"op":"mcm","clk":"11538944534","pt":1719472174020,"mc":[{"id":"1.230180114","rc":[{"atb":[[2.12,3.38]],"id":63387150}],"con":true,"img":false}]}
{"op":"mcm","clk":"11538944545","pt":1719472174223,"mc":[{"id":"1.230180114","rc":[{"atb":[[2.14,3.16]],"id":44213406}],"con":true,"img":false}]}
{"op":"mcm","clk":"11538944564","pt":1719472174631,"mc":[{"id":"1.230180114","rc":[{"atb":[[2.14,3.16]],"id":41804643}],"con":true,"img":false}]}
{"op":"mcm","clk":"11538944596","pt":1719472175093,"mc":[{"id":"1.230180114","rc":[{"atb":[[2.16,3.16]],"id":63387150}],"con":true,"img":false}]}
{"op":"mcm","clk":"11538944609","pt":1719472175399,"mc":[{"id":"1.230180114","rc":[{"atb":[[2.1,3.16]],"id":39682601}],"con":true,"img":false}]}
{"op":"mcm","clk":"11538944630","pt":1719472175707,"mc":[{"id":"1.230180114","rc":[{"atb":[[2.14,3.16]],"id":43289758}],"con":true,"img":false}]}
{"op":"mcm","clk":"11538944665","pt":1719472176319,"mc":[{"id":"1.230180114","rc":[{"atb":[[2.1,3.38]],"id":61150133}],"con":true,"img":false}]}
{"op":"mcm","clk":"11538944690","pt":1719472176728,"mc":[{"id":"1.230180114","rc":[{"atb":[[2.14,3.16]],"id":61150133}],"con":true,"img":false}]}
{"op":"mcm","clk":"11538946124","pt":1719472199749,"mc":[{"id":"1.230180114","rc":[{"atb":[[2.1,0]],"id":44213406}],"con":true,"img":false}]}
{"op":"mcm","clk":"11538946143","pt":1719472200072,"mc":[{"id":"1.230180114","rc":[{"atb":[[2.1,0]],"id":61150133}],"con":true,"img":false}]}
{"op":"mcm","clk":"11538946167","pt":1719472200523,"mc":[{"id":"1.230180114","rc":[{"atb":[[2.12,0]],"id":63387150}],"con":true,"img":false}]}
{"op":"mcm","clk":"11538946248","pt":1719472201964,"mc":[{"id":"1.230180114","rc":[{"atb":[[2.1,0]],"id":41804643}],"con":true,"img":false}]}
{"op":"mcm","clk":"11538946372","pt":1719472204171,"mc":[{"id":"1.230180114","rc":[{"atb":[[2.1,0]],"id":43289758}],"con":true,"img":false}]}
{"op":"mcm","clk":"11538946399","pt":1719472204529,"mc":[{"id":"1.230180114","rc":[{"atb":[[2.06,0]],"id":39682601}],"con":true,"img":false}]}
{"op":"mcm","clk":"11538947056","pt":1719472215670,"mc":[{"id":"1.230180114","rc":[{"atb":[[2.14,6.54]],"id":44213406}],"con":true,"img":false}]}
{"op":"mcm","clk":"11538947360","pt":1719472221161,"mc":[{"id":"1.230180114","rc":[{"atb":[[2.14,6.54]],"id":41804643}],"con":true,"img":false}]}
{"op":"mcm","clk":"11538947401","pt":1719472221777,"mc":[{"id":"1.230180114","rc":[{"atb":[[2.14,6.54]],"id":43289758}],"con":true,"img":false}]}
{"op":"mcm","clk":"11538947411","pt":1719472221988,"mc":[{"id":"1.230180114","rc":[{"atb":[[2.16,6.54]],"id":63387150}],"con":true,"img":false}]}
{"op":"mcm","clk":"11538947460","pt":1719472222752,"mc":[{"id":"1.230180114","rc":[{"atb":[[2.14,6.54]],"id":61150133}],"con":true,"img":false}]}
{"op":"mcm","clk":"11538947680","pt":1719472226700,"mc":[{"id":"1.230180114","rc":[{"atb":[[2.1,6.54]],"id":39682601}],"con":true,"img":false}]}
{"op":"mcm","clk":"11539071681","pt":1719474758880,"mc":[{"id":"1.230180114","rc":[{"atb":[[2.16,2]],"id":41804643},{"spn":76.08,"spf":"NaN","id":41804643},{"spn":76.07,"spf":"NaN","id":61150133},{"spn":76.07,"spf":"NaN","id":44213406},{"spn":76.05,"spf":"NaN","id":39682601},{"spn":76.08,"spf":"NaN","id":63387150},{"spn":76.07,"spf":"NaN","id":43289758}],"con":true,"img":false}]}
{"op":"mcm","clk":"11539124127","pt":1719475682712,"mc":[{"id":"1.230180114","marketDefinition":{"bspMarket":true,"turnInPlayEnabled":false,"persistenceEnabled":false,"marketBaseRate":5.0,"eventId":"33376437","eventTypeId":"4339","numberOfWinners":1,"bettingType":"ODDS","marketType":"WIN","marketTime":"2024-06-27T13:52:00.000Z","suspendTime":"2024-06-27T13:52:00.000Z","bspReconciled":false,"complete":true,"inPlay":false,"crossMatching":true,"runnersVoidable":false,"numberOfActiveRunners":6,"betDelay":0,"status":"OPEN","runners":[{"status":"ACTIVE","sortPriority":1,"id":39682601,"name":"1. Lilys Pearl"},{"status":"ACTIVE","sortPriority":2,"id":61150133,"name":"2. Mind The Mud"},{"status":"ACTIVE","sortPriority":3,"id":43289758,"name":"3. Salacres Harry"},{"status":"ACTIVE","sortPriority":4,"id":44213406,"name":"4. Go Bye Baby"},{"status":"ACTIVE","sortPriority":5,"id":41804643,"name":"5. Salacres Harold"},{"status":"ACTIVE","sortPriority":6,"id":63387150,"name":"6. Salacres Dolce"}],"regulators":["MR_INT"],"venue":"Towcester","countryCode":"GB","discountAllowed":true,"timezone":"Europe/London","openDate":"2024-06-27T13:33:00.000Z","version":5994767089,"name":"D4 270m","eventName":"Towcester 27th Jun"},"rc":[{"atb":[[1.03,10.99],[2.12,10.66],[2.16,2],[2.14,6.55]],"id":41804643},{"atl":[[150,4],[990,0.17]],"id":41804643},{"spn":76.08,"spf":"NaN","id":41804643},{"atb":[[1.01,32.96],[2.12,9.77],[2.14,6.55]],"id":61150133},{"atl":[[150,4],[1000,0.17]],"id":61150133},{"spn":76.07,"spf":"NaN","id":61150133},{"atb":[[1.02,16.48],[2.12,10.66],[2.14,6.55]],"id":44213406},{"atl":[[150,4],[1000,0.17]],"id":44213406},{"spn":76.07,"spf":"NaN","id":44213406},{"atb":[[1.01,32.96],[2.1,6.55],[2.08,9.58]],"id":39682601},{"atl":[[150,4],[1000,0.17]],"id":39682601},{"spn":76.05,"spf":"NaN","id":39682601},{"atb":[[1.03,10.99],[2.16,6.55],[2.14,9.86]],"id":63387150},{"atl":[[150,4],[1000,0.17]],"id":63387150},{"spn":76.08,"spf":"NaN","id":63387150},{"atb":[[1.01,32.96],[2.12,11.54],[2.14,6.55]],"id":43289758},{"atl":[[150,4],[990,0.17]],"id":43289758},{"spn":76.07,"spf":"NaN","id":43289758}],"con":true,"img":true}]}
{"op":"mcm","clk":"11539127783","pt":1719475709346,"mc":[{"id":"1.230180114","rc":[{"atb":[[1.03,10.99],[2.12,0],[2.14,6.55]],"id":41804643},{"atb":[[1.01,32.96],[2.12,0],[2.14,6.55]],"id":61150133},{"atb":[[1.02,16.48],[2.12,0],[2.14,6.55]],"id":44213406},{"atb":[[1.01,32.96],[2.1,6.55],[2.08,0]],"id":39682601},{"atb":[[1.03,10.99],[2.16,6.55],[2.14,0]],"id":63387150},{"atb":[[1.01,32.96],[2.12,0],[2.14,6.55]],"id":43289758}],"con":true,"img":false}]}
{"op":"mcm","clk":"11539127790","pt":1719475709447,"mc":[{"id":"1.230180114","rc":[{"atb":[[2.16,12.66]],"id":41804643},{"atb":[[2.16,9.77]],"id":61150133},{"atb":[[2.16,10.66]],"id":44213406},{"atb":[[2.12,9.58]],"id":39682601},{"atb":[[2.18,9.86]],"id":63387150},{"atb":[[2.16,11.54]],"id":43289758}],"con":true,"img":false}]}
{"op":"mcm","clk":"11539128841","pt":1719475724650,"mc":[{"id":"1.230180114","rc":[{"atb":[[2.14,3.38]],"id":44213406}],"con":true,"img":false}]}
{"op":"mcm","clk":"11539128865","pt":1719475725061,"mc":[{"id":"1.230180114","rc":[{"atb":[[2.16,3.38]],"id":63387150}],"con":true,"img":false}]}
{"op":"mcm","clk":"11539128885","pt":1719475725371,"mc":[{"id":"1.230180114","rc":[{"atb":[[2.14,3.38]],"id":61150133}],"con":true,"img":false}]}
{"op":"mcm","clk":"11539128944","pt":1719475726242,"mc":[{"id":"1.230180114","rc":[{"atb":[[2.1,3.38]],"id":39682601},{"atb":[[2.14,3.38]],"id":43289758}],"con":true,"img":false}]}
{"op":"mcm","clk":"11539128957","pt":1719475726446,"mc":[{"id":"1.230180114","rc":[{"atb":[[2.14,3.16]],"id":39682601}],"con":true,"img":false}]}
{"op":"mcm","clk":"11539128999","pt":1719475727164,"mc":[{"id":"1.230180114","rc":[{"atb":[[2.2,3.16]],"id":63387150}],"con":true,"img":false}]}
{"op":"mcm","clk":"11539129022","pt":1719475727471,"mc":[{"id":"1.230180114","rc":[{"atb":[[2.18,3.16]],"id":43289758}],"con":true,"img":false}]}
{"op":"mcm","clk":"11539129035","pt":1719475727676,"mc":[{"id":"1.230180114","rc":[{"atb":[[2.18,3.16]],"id":61150133}],"con":true,"img":false}]}
{"op":"mcm","clk":"11539129044","pt":1719475727881,"mc":[{"id":"1.230180114","rc":[{"atb":[[2.18,3.16]],"id":44213406}],"con":true,"img":false}]}
{"op":"mcm","clk":"11539129136","pt":1719475729285,"mc":[{"id":"1.230180114","rc":[{"atb":[[2.14,3.38]],"id":41804643}],"con":true,"img":false}]}
{"op":"mcm","clk":"11539129221","pt":1719475730669,"mc":[{"id":"1.230180114","rc":[{"atb":[[2.18,3.16]],"id":41804643}],"con":true,"img":false}]}
{"op":"mcm","clk":"11539136077","pt":1719475837386,"mc":[{"id":"1.230180114","rc":[{"spn":76.09,"spf":"NaN","id":41804643},{"spn":76.09,"spf":"NaN","id":61150133},{"spn":76.09,"spf":"NaN","id":44213406},{"atb":[[2.1,0]],"id":39682601},{"spn":76.07,"spf":"NaN","id":39682601},{"atb":[[2.16,0]],"id":63387150},{"spn":76.1,"spf":"NaN","id":63387150},{"spn":76.09,"spf":"NaN","id":43289758}],"con":true,"img":false}]}
{"op":"mcm","clk":"11539136108","pt":1719475837899,"mc":[{"id":"1.230180114","rc":[{"atb":[[2.14,0]],"id":43289758}],"con":true,"img":false}]}
{"op":"mcm","clk":"11539136123","pt":1719475838206,"mc":[{"id":"1.230180114","rc":[{"atb":[[2.14,0]],"id":44213406}],"con":true,"img":false}]}
{"op":"mcm","clk":"11539136128","pt":1719475838309,"mc":[{"id":"1.230180114","rc":[{"atb":[[2.14,0]],"id":41804643}],"con":true,"img":false}]}
{"op":"mcm","clk":"11539136213","pt":1719475839701,"mc":[{"id":"1.230180114","rc":[{"atb":[[2.14,0]],"id":61150133}],"con":true,"img":false}]}
{"op":"mcm","clk":"11539136294","pt":1719475840982,"mc":[{"id":"1.230180114","rc":[{"atb":[[2.14,6.55]],"id":39682601}],"con":true,"img":false}]}
{"op":"mcm","clk":"11539136347","pt":1719475841903,"mc":[{"id":"1.230180114","rc":[{"atb":[[2.18,6.55]],"id":41804643}],"con":true,"img":false}]}
{"op":"mcm","clk":"11539136390","pt":1719475842729,"mc":[{"id":"1.230180114","rc":[{"atb":[[2.18,6.55]],"id":43289758}],"con":true,"img":false}]}
{"op":"mcm","clk":"11539136398","pt":1719475842790,"mc":[{"id":"1.230180114","rc":[{"atb":[[2.18,6.55]],"id":44213406}],"con":true,"img":false}]}
{"op":"mcm","clk":"11539136424","pt":1719475843095,"mc":[{"id":"1.230180114","rc":[{"atb":[[2.2,6.55]],"id":63387150}],"con":true,"img":false}]}
{"op":"mcm","clk":"11539136589","pt":1719475845586,"mc":[{"id":"1.230180114","rc":[{"atb":[[2.18,6.55]],"id":61150133}],"con":true,"img":false}]}
{"op":"mcm","clk":"11539280990","pt":1719478343953,"mc":[{"id":"1.230180114","rc":[{"atl":[[42,12],[25,8]],"id":61150133},{"spn":13.59,"spf":"NaN","id":61150133},{"atl":[[40,12],[23,8]],"id":39682601},{"spn":12.57,"spf":"NaN","id":39682601},{"atl":[[32,8],[55,12]],"id":43289758},{"spn":17.09,"spf":"NaN","id":43289758}],"con":true,"img":false}]}
{"op":"mcm","clk":"11539341286","pt":1719479308390,"mc":[{"id":"1.230180114","rc":[{"atb":[[1.03,10.98],[2.18,6.54],[2.16,2]],"id":41804643},{"atb":[[1.01,32.95],[2.18,6.54],[2.16,0]],"id":61150133},{"atb":[[1.02,16.47],[2.18,6.54],[2.16,0]],"id":44213406},{"atb":[[1.01,32.95],[2.12,0],[2.14,6.54]],"id":39682601},{"atb":[[1.03,10.98],[2.18,0],[2.2,6.54]],"id":63387150},{"atb":[[1.01,32.95],[2.18,6.54],[2.16,0]],"id":43289758}],"con":true,"img":false}]}
{"op":"mcm","clk":"11539341295","pt":1719479308493,"mc":[{"id":"1.230180114","rc":[{"atb":[[2.2,10.65]],"id":41804643},{"atb":[[2.2,9.77]],"id":61150133},{"atb":[[2.2,10.65]],"id":44213406},{"atb":[[2.16,9.58]],"id":39682601},{"atb":[[2.22,9.86]],"id":63387150},{"atb":[[2.2,11.54]],"id":43289758}],"con":true,"img":false}]}
{"op":"mcm","clk":"11539347890","pt":1719479413297,"mc":[{"id":"1.230180114","rc":[{"atb":[[2.18,3.38]],"id":41804643},{"spn":76.1,"spf":"NaN","id":41804643},{"atb":[[2.18,3.38]],"id":61150133},{"spn":13.6,"spf":"NaN","id":61150133},{"atb":[[2.18,3.38]],"id":44213406},{"spn":76.1,"spf":"NaN","id":44213406},{"atb":[[2.14,3.38]],"id":39682601},{"spn":12.58,"spf":"NaN","id":39682601},{"atb":[[2.2,3.38]],"id":63387150},{"spn":76.11,"spf":"NaN","id":63387150},{"atb":[[2.18,3.38]],"id":43289758},{"spn":17.1,"spf":"NaN","id":43289758}],"con":true,"img":false}]}
{"op":"mcm","clk":"11539350847","pt":1719479458963,"mc":[{"id":"1.230180114","rc":[{"atb":[[2.18,0]],"id":41804643},{"atb":[[2.18,0]],"id":61150133},{"atb":[[2.18,0]],"id":44213406},{"atb":[[2.14,0]],"id":39682601},{"atb":[[2.2,0]],"id":63387150},{"atb":[[2.18,0]],"id":43289758}],"con":true,"img":false}]}
{"op":"mcm","clk":"11539368710","pt":1719479719678,"mc":[{"id":"1.230180114","rc":[{"atb":[[2.22,3.16]],"id":61150133},{"spn":13.61,"spf":"NaN","id":61150133}],"con":true,"img":false}]}
{"op":"mcm","clk":"11539368732","pt":1719479719888,"mc":[{"id":"1.230180114","rc":[{"atb":[[2.24,3.16]],"id":63387150},{"atb":[[2.22,3.16]],"id":43289758}],"con":true,"img":false}]}
{"op":"mcm","clk":"11539368811","pt":1719479720556,"mc":[{"id":"1.230180114","rc":[{"atb":[[2.22,3.16]],"id":44213406}],"con":true,"img":false}]}
{"op":"mcm","clk":"11539368830","pt":1719479720762,"mc":[{"id":"1.230180114","rc":[{"atb":[[2.22,3.16]],"id":41804643}],"con":true,"img":false}]}
{"op":"mcm","clk":"11539368871","pt":1719479721276,"mc":[{"id":"1.230180114","rc":[{"atb":[[2.18,3.16]],"id":39682601}],"con":true,"img":false}]}
{"op":"mcm","clk":"11539370404","pt":1719479742122,"mc":[{"id":"1.230180114","rc":[{"atb":[[2.18,6.54]],"id":39682601}],"con":true,"img":false}]}
{"op":"mcm","clk":"11539370434","pt":1719479742385,"mc":[{"id":"1.230180114","rc":[{"atb":[[2.22,6.54]],"id":61150133}],"con":true,"img":false}]}
{"op":"mcm","clk":"11539370461","pt":1719479742695,"mc":[{"id":"1.230180114","rc":[{"atb":[[2.22,6.54]],"id":44213406}],"con":true,"img":false}]}
{"op":"mcm","clk":"11539370483","pt":1719479742909,"mc":[{"id":"1.230180114","rc":[{"atb":[[2.22,6.54]],"id":41804643}],"con":true,"img":false}]}
{"op":"mcm","clk":"11539370494","pt":1719479743006,"mc":[{"id":"1.230180114","rc":[{"atb":[[2.24,6.54]],"id":63387150}],"con":true,"img":false}]}
{"op":"mcm","clk":"11539370526","pt":1719479743415,"mc":[{"id":"1.230180114","rc":[{"atb":[[2.22,6.54]],"id":43289758}],"con":true,"img":false}]}
{"op":"mcm","clk":"11539440240","pt":1719481082685,"mc":[{"id":"1.230180114","marketDefinition":{"bspMarket":true,"turnInPlayEnabled":false,"persistenceEnabled":false,"marketBaseRate":5.0,"eventId":"33376437","eventTypeId":"4339","numberOfWinners":1,"bettingType":"ODDS","marketType":"WIN","marketTime":"2024-06-27T13:52:00.000Z","suspendTime":"2024-06-27T13:52:00.000Z","bspReconciled":false,"complete":true,"inPlay":false,"crossMatching":true,"runnersVoidable":false,"numberOfActiveRunners":6,"betDelay":0,"status":"OPEN","runners":[{"status":"ACTIVE","sortPriority":1,"id":39682601,"name":"1. Lilys Pearl"},{"status":"ACTIVE","sortPriority":2,"id":61150133,"name":"2. Mind The Mud"},{"status":"ACTIVE","sortPriority":3,"id":43289758,"name":"3. Salacres Harry"},{"status":"ACTIVE","sortPriority":4,"id":44213406,"name":"4. Go Bye Baby"},{"status":"ACTIVE","sortPriority":5,"id":41804643,"name":"5. Salacres Harold"},{"status":"ACTIVE","sortPriority":6,"id":63387150,"name":"6. Salacres Dolce"}],"regulators":["MR_INT"],"venue":"Towcester","countryCode":"GB","discountAllowed":true,"timezone":"Europe/London","openDate":"2024-06-27T13:33:00.000Z","version":5994767089,"name":"D4 270m","eventName":"Towcester 27th Jun"},"rc":[{"atb":[[1.03,10.98],[2.22,6.54],[2.2,10.65],[2.16,2]],"id":41804643},{"atl":[[150,4],[990,0.17]],"id":41804643},{"spn":76.11,"spf":"NaN","id":41804643},{"atb":[[1.01,32.95],[2.22,6.54],[2.2,9.77]],"id":61150133},{"atl":[[150,4],[42,12],[25,8],[1000,0.17]],"id":61150133},{"spn":13.61,"spf":"NaN","id":61150133},{"atb":[[2.22,6.54],[1.02,16.47],[2.2,10.65]],"id":44213406},{"atl":[[150,4],[1000,0.17]],"id":44213406},{"spn":76.11,"spf":"NaN","id":44213406},{"atb":[[1.01,32.95],[2.18,6.54],[2.16,9.58]],"id":39682601},{"atl":[[150,4],[40,12],[23,8],[1000,0.17]],"id":39682601},{"spn":12.59,"spf":"NaN","id":39682601},{"atb":[[2.24,6.54],[1.03,10.98],[2.22,9.86]],"id":63387150},{"atl":[[150,4],[1000,0.17]],"id":63387150},{"spn":76.12,"spf":"NaN","id":63387150},{"atb":[[1.01,32.95],[2.22,6.54],[2.2,11.54]],"id":43289758},{"atl":[[32,8],[150,4],[55,12],[990,0.17]],"id":43289758},{"spn":17.11,"spf":"NaN","id":43289758}],"con":true,"img":true}]}
{"op":"mcm","clk":"11539496614","pt":1719482100579,"mc":[{"id":"1.230180114","rc":[{"atb":[[8,2]],"id":41804643},{"spn":79.0,"spf":"NaN","id":41804643},{"atb":[[8,2]],"id":61150133},{"spn":16.5,"spf":"NaN","id":61150133},{"atb":[[8,2]],"id":44213406},{"spn":79.0,"spf":"NaN","id":44213406},{"atb":[[2.42,2]],"id":39682601},{"spn":12.71,"spf":"NaN","id":39682601},{"atb":[[8,2]],"id":63387150},{"spn":79.0,"spf":"NaN","id":63387150},{"atb":[[4.9,2]],"id":43289758},{"spn":18.45,"spf":"NaN","id":43289758}],"con":true,"img":false}]}
{"op":"mcm","clk":"11539496808","pt":1719482103997,"mc":[{"id":"1.230180114","rc":[{"atb":[[2.22,3.38]],"id":41804643},{"atb":[[2.22,3.38]],"id":61150133},{"atb":[[2.22,3.38]],"id":44213406},{"atb":[[2.18,3.38]],"id":39682601},{"atb":[[2.24,3.38]],"id":63387150}],"con":true,"img":false}]}
{"op":"mcm","clk":"11539498855","pt":1719482146004,"mc":[{"id":"1.230180114","rc":[{"atb":[[2.18,0]],"id":39682601}],"con":true,"img":false}]}
{"op":"mcm","clk":"11539545049","pt":1719482905367,"mc":[{"id":"1.230180114","rc":[{"atb":[[1.03,10.98],[2.22,3.38],[2.2,0]],"id":41804643},{"atb":[[1.01,32.95],[2.22,3.38],[2.2,0]],"id":61150133},{"atb":[[2.22,3.38],[1.02,16.47],[2.2,0]],"id":44213406},{"atb":[[1.01,32.95],[2.16,9.58]],"id":39682601},{"atb":[[2.24,3.38],[1.03,10.98],[2.22,0]],"id":63387150},{"atb":[[1.01,32.95],[2.22,6.54],[2.2,0]],"id":43289758}],"con":true,"img":false}]}
{"op":"mcm","clk":"11539545057","pt":1719482905469,"mc":[{"id":"1.230180114","rc":[{"atb":[[2.24,10.65]],"id":41804643},{"atb":[[2.24,9.76]],"id":61150133},{"atb":[[2.24,10.65]],"id":44213406},{"atb":[[2.26,9.86]],"id":63387150},{"atb":[[2.24,11.54]],"id":43289758}],"con":true,"img":false}]}
{"op":"mcm","clk":"11539545536","pt":1719482912088,"mc":[{"id":"1.230180114","rc":[{"atb":[[2.22,3.38]],"id":43289758}],"con":true,"img":false}]}
{"op":"mcm","clk":"11539545832","pt":1719482915971,"mc":[{"id":"1.230180114","rc":[{"atb":[[2.26,3.16]],"id":43289758}],"con":true,"img":false}]}
{"op":"mcm","clk":"11539550873","pt":1719482994116,"mc":[{"id":"1.230180114","rc":[{"atb":[[2.24,0]],"id":63387150}],"con":true,"img":false}]}
{"op":"mcm","clk":"11539550885","pt":1719482994225,"mc":[{"id":"1.230180114","rc":[{"atb":[[2.22,0]],"id":43289758}],"con":true,"img":false}]}
{"op":"mcm","clk":"11539550908","pt":1719482994498,"mc":[{"id":"1.230180114","rc":[{"atb":[[2.22,0]],"id":61150133}],"con":true,"img":false}]}
{"op":"mcm","clk":"11539550936","pt":1719482994816,"mc":[{"id":"1.230180114","rc":[{"atb":[[2.22,0]],"id":41804643}],"con":true,"img":false}]}
{"op":"mcm","clk":"11539551061","pt":1719482996982,"mc":[{"id":"1.230180114","rc":[{"atb":[[2.26,6.54]],"id":43289758}],"con":true,"img":false}]}
{"op":"mcm","clk":"11539551093","pt":1719482997499,"mc":[{"id":"1.230180114","rc":[{"atb":[[2.26,3.38]],"id":61150133},{"atb":[[2.28,3.38]],"id":63387150}],"con":true,"img":false}]}
{"op":"mcm","clk":"11539551185","pt":1719482999100,"mc":[{"id":"1.230180114","rc":[{"atb":[[2.22,0]],"id":44213406}],"con":true,"img":false}]}
{"op":"mcm","clk":"11539551258","pt":1719483000299,"mc":[{"id":"1.230180114","rc":[{"atb":[[2.26,3.38]],"id":41804643}],"con":true,"img":false}]}
{"op":"mcm","clk":"11539551317","pt":1719483001285,"mc":[{"id":"1.230180114","rc":[{"atb":[[2.26,3.38]],"id":44213406}],"con":true,"img":false}]}
{"op":"mcm","clk":"11539557483","pt":1719483096154,"mc":[{"id":"1.230180114","rc":[{"atb":[[2.02,30.3],[1.51,196.08]],"id":41804643},{"atb":[[2.02,30.3],[1.51,196.08]],"id":61150133},{"atb":[[2.02,30.3],[1.51,196.08]],"id":44213406},{"atb":[[2.02,30.3],[1.51,196.08]],"id":63387150},{"atb":[[1.51,196.08]],"id":43289758}],"con":true,"img":false}]}
{"op":"mcm","clk":"11539653663","pt":1719484408237,"mc":[{"id":"1.230180114","rc":[{"atb":[[3.9,6]],"id":41804643},{"atb":[[3.75,6]],"id":61150133},{"atb":[[3.9,6]],"id":44213406},{"atb":[[1.92,6]],"id":39682601},{"atb":[[3.9,6]],"id":63387150},{"atb":[[2.72,6]],"id":43289758}],"con":true,"img":false}]}
{"op":"mcm","clk":"11539653756","pt":1719484409433,"mc":[{"id":"1.230180114","rc":[{"atb":[[2.26,3.38]],"id":43289758}],"con":true,"img":false}]}
{"op":"mcm","clk":"11539653774","pt":1719484409638,"mc":[{"id":"1.230180114","rc":[{"atb":[[2.74,3.16]],"id":43289758}],"con":true,"img":false}]}
{"op":"mcm","clk":"11539654443","pt":1719484417651,"mc":[{"id":"1.230180114","rc":[{"atb":[[2.12,89.29]],"id":41804643},{"atb":[[2.12,89.29]],"id":61150133},{"atb":[[2.12,89.29]],"id":44213406},{"atb":[[2.12,89.29]],"id":63387150}],"con":true,"img":false}]}
{"op":"mcm","clk":"11539654510","pt":1719484418434,"mc":[{"id":"1.230180114","rc":[{"atb":[[2.26,0]],"id":41804643},{"atb":[[2.26,0]],"id":61150133},{"atb":[[2.26,0]],"id":44213406},{"atb":[[2.28,0]],"id":63387150}],"con":true,"img":false}]}
{"op":"mcm","clk":"11539812653","pt":1719486482672,"mc":[{"id":"1.230180114","marketDefinition":{"bspMarket":true,"turnInPlayEnabled":false,"persistenceEnabled":false,"marketBaseRate":5.0,"eventId":"33376437","eventTypeId":"4339","numberOfWinners":1,"bettingType":"ODDS","marketType":"WIN","marketTime":"2024-06-27T13:52:00.000Z","suspendTime":"2024-06-27T13:52:00.000Z","bspReconciled":false,"complete":true,"inPlay":false,"crossMatching":true,"runnersVoidable":false,"numberOfActiveRunners":6,"betDelay":0,"status":"OPEN","runners":[{"status":"ACTIVE","sortPriority":1,"id":39682601,"name":"1. Lilys Pearl"},{"status":"ACTIVE","sortPriority":2,"id":61150133,"name":"2. Mind The Mud"},{"status":"ACTIVE","sortPriority":3,"id":43289758,"name":"3. Salacres Harry"},{"status":"ACTIVE","sortPriority":4,"id":44213406,"name":"4. Go Bye Baby"},{"status":"ACTIVE","sortPriority":5,"id":41804643,"name":"5. Salacres Harold"},{"status":"ACTIVE","sortPriority":6,"id":63387150,"name":"6. Salacres Dolce"}],"regulators":["MR_INT"],"venue":"Towcester","countryCode":"GB","discountAllowed":true,"timezone":"Europe/London","openDate":"2024-06-27T13:33:00.000Z","version":5994767089,"name":"D4 270m","eventName":"Towcester 27th Jun"},"rc":[{"atb":[[8,2],[2.24,10.65],[2.02,30.3],[1.03,10.98],[2.12,89.29],[1.51,196.08],[3.9,6],[2.16,2]],"id":41804643},{"atl":[[150,4],[990,0.17]],"id":41804643},{"spn":79.0,"spf":"NaN","id":41804643},{"atb":[[8,2],[2.24,9.77],[2.02,30.3],[1.01,32.95],[2.12,89.29],[1.51,196.08],[3.75,6]],"id":61150133},{"atl":[[150,4],[42,12],[25,8],[1000,0.17]],"id":61150133},{"spn":16.5,"spf":"NaN","id":61150133},{"atb":[[8,2],[2.24,10.65],[2.02,30.3],[1.02,16.47],[2.12,89.29],[1.51,196.08],[3.9,6]],"id":44213406},{"atl":[[150,4],[1000,0.17]],"id":44213406},{"spn":79.0,"spf":"NaN","id":44213406},{"atb":[[1.92,6],[1.01,32.95],[2.42,2],[2.16,9.58]],"id":39682601},{"atl":[[150,4],[40,12],[23,8],[1000,0.17]],"id":39682601},{"spn":12.71,"spf":"NaN","id":39682601},{"atb":[[8,2],[2.02,30.3],[1.03,10.98],[2.12,89.29],[2.26,9.86],[1.51,196.08],[3.9,6]],"id":63387150},{"atl":[[150,4],[1000,0.17]],"id":63387150},{"spn":79.0,"spf":"NaN","id":63387150},{"atb":[[2.24,11.54],[2.72,6],[1.01,32.95],[2.74,3.16],[4.9,2],[2.26,3.38],[1.51,196.08]],"id":43289758},{"atl":[[32,8],[150,4],[55,12],[990,0.17]],"id":43289758},{"spn":18.45,"spf":"NaN","id":43289758}],"con":true,"img":true}]}
{"op":"mcm","clk":"11540014204","pt":1719488997247,"mc":[{"id":"1.230180114","rc":[{"atb":[[2.24,10.65],[1.03,10.98],[1.16,150]],"id":41804643},{"atl":[[560,2]],"id":41804643},{"atb":[[2.24,9.77],[1.01,32.95],[1.16,150]],"id":61150133},{"atl":[[390,2]],"id":61150133},{"atb":[[2.24,10.65],[1.16,150],[1.02,16.47]],"id":44213406},{"atl":[[270,2]],"id":44213406},{"atb":[[1.01,32.95],[1.16,150],[2.16,9.58]],"id":39682601},{"atl":[[370,2]],"id":39682601},{"atb":[[1.03,10.98],[1.16,150],[2.26,9.86]],"id":63387150},{"atl":[[500,2]],"id":63387150},{"atb":[[2.24,11.54],[1.01,32.95],[2.74,3.16],[1.16,150],[2.26,3.38]],"id":43289758},{"atl":[[550,2]],"id":43289758}],"con":true,"img":false}]}
{"op":"mcm","clk":"11540042514","pt":1719489339132,"mc":[{"id":"1.230180114","rc":[{"atb":[[1.02,120.97]],"id":41804643},{"atl":[[970,0.87]],"id":41804643},{"atb":[[1.02,75.28]],"id":61150133},{"atl":[[980,0.96]],"id":61150133},{"atb":[[1.03,98.97]],"id":44213406},{"atl":[[980,1.38]],"id":44213406},{"atb":[[1.04,159.03]],"id":39682601},{"atl":[[990,0.87]],"id":39682601},{"atb":[[1.02,89.67]],"id":63387150},{"atl":[[990,2.01]],"id":63387150},{"atb":[[1.03,104.05]],"id":43289758},{"atl":[[980,2.07]],"id":43289758}],"con":true,"img":false}]}
{"op":"mcm","clk":"11540071197","pt":1719489698390,"mc":[{"id":"1.230180114","rc":[{"atb":[[8,0]],"id":44213406},{"trd":[[8,4]],"ltp":8.0,"tv":4.0,"id":44213406},{"spn":76.95,"spf":"NaN","id":44213406},{"atb":[[2.74,3.16]],"id":43289758}],"con":true,"img":false}]}
{"op":"mcm","clk":"11540071233","pt":1719489698960,"mc":[{"id":"1.230180114","rc":[{"atl":[[150,35]],"id":44213406}],"con":true,"img":false}]}
{"op":"mcm","clk":"11540072346","pt":1719489713573,"mc":[{"id":"1.230180114","rc":[{"atb":[[2.18,3.16]],"id":39682601}],"con":true,"img":false}]}
{"op":"mcm","clk":"11540072638","pt":1719489717494,"mc":[{"id":"1.230180114","rc":[{"atb":[[2.18,6.54]],"id":39682601}],"con":true,"img":false}]}
{"op":"mcm","clk":"11540074356","pt":1719489738015,"mc":[{"id":"1.230180114","rc":[{"atb":[[1.93,12.76]],"id":39682601},{"atb":[[2.74,9.98]],"id":43289758}],"con":true,"img":false}]}
{"op":"mcm","clk":"11540074378","pt":1719489738327,"mc":[{"id":"1.230180114","rc":[{"atb":[[2.26,9.41]],"id":44213406}],"con":true,"img":false}]}
{"op":"mcm","clk":"11540076566","pt":1719489764569,"mc":[{"id":"1.230180114","rc":[{"atb":[[2.26,0],[2.76,7.92]],"id":43289758}],"con":true,"img":false}]}
{"op":"mcm","clk":"11540076595","pt":1719489764876,"mc":[{"id":"1.230180114","rc":[{"atb":[[2.76,11.31]],"id":43289758}],"con":true,"img":false}]}
{"op":"mcm","clk":"11540076877","pt":1719489767986,"mc":[{"id":"1.230180114","rc":[{"atl":[[150,5]],"id":44213406}],"con":true,"img":false}]}
{"op":"mcm","clk":"11540078368","pt":1719489785403,"mc":[{"id":"1.230180114","rc":[{"atb":[[2.74,6.81]],"id":43289758}],"con":true,"img":false}]}
{"op":"mcm","clk":"11540078390","pt":1719489785562,"mc":[{"id":"1.230180114","rc":[{"atb":[[2.78,3.16]],"id":43289758}],"con":true,"img":false}]}
{"op":"mcm","clk":"11540080069","pt":1719489805674,"mc":[{"id":"1.230180114","rc":[{"atb":[[2.74,0]],"id":43289758}],"con":true,"img":false}]}
{"op":"mcm","clk":"11540080396","pt":1719489810317,"mc":[{"id":"1.230180114","rc":[{"atb":[[2.78,9.83]],"id":43289758}],"con":true,"img":false}]}
{"op":"mcm","clk":"11540080679","pt":1719489814926,"mc":[{"id":"1.230180114","rc":[{"atb":[[2.28,10.9]],"id":44213406}],"con":true,"img":false}]}
{"op":"mcm","clk":"11540080689","pt":1719489815133,"mc":[{"id":"1.230180114","rc":[{"atb":[[2.76,7.92]],"id":43289758}],"con":true,"img":false}]}
{"op":"mcm","clk":"11540080701","pt":1719489815188,"mc":[{"id":"1.230180114","rc":[{"atb":[[1.94,14.85]],"id":39682601}],"con":true,"img":false}]}
{"op":"mcm","clk":"11540080717","pt":1719489815394,"mc":[{"id":"1.230180114","rc":[{"atb":[[2.8,3.38]],"id":43289758}],"con":true,"img":false}]}
{"op":"mcm","clk":"11540082949","pt":1719489842667,"mc":[{"id":"1.230180114","rc":[{"atb":[[2.76,0]],"id":43289758}],"con":true,"img":false}]}
{"op":"mcm","clk":"11540083812","pt":1719489851341,"mc":[{"id":"1.230180114","rc":[{"atb":[[2.8,11.13]],"id":43289758}],"con":true,"img":false}]}
{"op":"mcm","clk":"11540084090","pt":1719489854354,"mc":[{"id":"1.230180114","rc":[{"atb":[[2.26,0]],"id":44213406},{"atb":[[2.78,3.16]],"id":43289758}],"con":true,"img":false}]}
{"op":"mcm","clk":"11540084107","pt":1719489854548,"mc":[{"id":"1.230180114","rc":[{"atb":[[2.78,0]],"id":43289758}],"con":true,"img":false}]}
{"op":"mcm","clk":"11540084125","pt":1719489854756,"mc":[{"id":"1.230180114","rc":[{"atb":[[2.82,3.16]],"id":43289758}],"con":true,"img":false}]}
{"op":"mcm","clk":"11540086269","pt":1719489877992,"mc":[{"id":"1.230180114","rc":[{"atb":[[2.3,9.12]],"id":44213406}],"con":true,"img":false}]}
{"op":"mcm","clk":"11540086299","pt":1719489878301,"mc":[{"id":"1.230180114","rc":[{"atb":[[2.82,9.68]],"id":43289758}],"con":true,"img":false}]}
{"op":"mcm","clk":"11540087820","pt":1719489894088,"mc":[{"id":"1.230180114","rc":[{"atb":[[2.8,7.74]],"id":43289758}],"con":true,"img":false}]}
{"op":"mcm","clk":"11540087878","pt":1719489894608,"mc":[{"id":"1.230180114","rc":[{"atb":[[2.84,3.38]],"id":43289758}],"con":true,"img":false}]}
{"op":"mcm","clk":"11540090455","pt":1719489921758,"mc":[{"id":"1.230180114","rc":[{"atb":[[2.82,3.16]],"id":43289758}],"con":true,"img":false}]}
{"op":"mcm","clk":"11540090720","pt":1719489923936,"mc":[{"id":"1.230180114","rc":[{"atb":[[2.86,6.37]],"id":43289758}],"con":true,"img":false}]}
{"op":"mcm","clk":"11540092124","pt":1719489939759,"mc":[{"id":"1.230180114","rc":[{"atb":[[2.28,0]],"id":44213406},{"atb":[[2.8,0]],"id":43289758}],"con":true,"img":false}]}
{"op":"mcm","clk":"11540092794","pt":1719489947582,"mc":[{"id":"1.230180114","rc":[{"atb":[[2.82,0]],"id":43289758}],"con":true,"img":false}]}
{"op":"mcm","clk":"11540092852","pt":1719489948152,"mc":[{"id":"1.230180114","rc":[{"atb":[[2.84,0]],"id":43289758}],"con":true,"img":false}]}
{"op":"mcm","clk":"11540092887","pt":1719489948470,"mc":[{"id":"1.230180114","rc":[{"atb":[[2.32,10.57]],"id":44213406}],"con":true,"img":false}]}
{"op":"mcm","clk":"11540092908","pt":1719489948678,"mc":[{"id":"1.230180114","rc":[{"atb":[[2.88,3.38]],"id":43289758}],"con":true,"img":false}]}
{"op":"mcm","clk":"11540094591","pt":1719489967801,"mc":[{"id":"1.230180114","rc":[{"atb":[[2.3,0]],"id":44213406}],"con":true,"img":false}]}
{"op":"mcm","clk":"11540094783","pt":1719489969877,"mc":[{"id":"1.230180114","rc":[{"atb":[[2.74,3.16]],"id":43289758}],"con":true,"img":false}]}
{"op":"mcm","clk":"11540096634","pt":1719489990004,"mc":[{"id":"1.230180114","rc":[{"atb":[[2.86,0]],"id":43289758}],"con":true,"img":false}]}
{"op":"mcm","clk":"11540096864","pt":1719489992724,"mc":[{"id":"1.230180114","rc":[{"atb":[[2.9,6.24]],"id":43289758}],"con":true,"img":false}]}
{"op":"mcm","clk":"11540096888","pt":1719489993036,"mc":[{"id":"1.230180114","rc":[{"atb":[[2.34,8.85]],"id":44213406}],"con":true,"img":false}]}
{"op":"mcm","clk":"11540098025","pt":1719490004943,"mc":[{"id":"1.230180114","rc":[{"atb":[[2.88,0]],"id":43289758}],"con":true,"img":false}]}
{"op":"mcm","clk":"11540098059","pt":1719490005246,"mc":[{"id":"1.230180114","rc":[{"atb":[[2.92,3.38]],"id":43289758}],"con":true,"img":false}]}
{"op":"mcm","clk":"11540098408","pt":1719490009074,"mc":[{"id":"1.230180114","rc":[{"atl":[[150,33]],"id":44213406}],"con":true,"img":false}]}
{"op":"mcm","clk":"11540100747","pt":1719490034656,"mc":[{"id":"1.230180114","rc":[{"atb":[[2.32,0]],"id":44213406}],"con":true,"img":false}]}
{"op":"mcm","clk":"11540100804","pt":1719490035272,"mc":[{"id":"1.230180114","rc":[{"atb":[[2.9,0]],"id":43289758}],"con":true,"img":false}]}
{"op":"mcm","clk":"11540100975","pt":1719490036895,"mc":[{"id":"1.230180114","rc":[{"atb":[[2.94,6.11]],"id":43289758}],"con":true,"img":false}]}
{"op":"mcm","clk":"11540101557","pt":1719490042589,"mc":[{"id":"1.230180114","rc":[{"atb":[[2.36,10.26]],"id":44213406}],"con":true,"img":false}]}
{"op":"mcm","clk":"11540101581","pt":1719490042796,"mc":[{"id":"1.230180114","rc":[{"atb":[[2.92,0]],"id":43289758}],"con":true,"img":false}]}
{"op":"mcm","clk":"11540101617","pt":1719490043097,"mc":[{"id":"1.230180114","rc":[{"atb":[[2.96,3.38]],"id":43289758}],"con":true,"img":false}]}
{"op":"mcm","clk":"11540103020","pt":1719490057102,"mc":[{"id":"1.230180114","rc":[{"atb":[[2.34,0]],"id":44213406}],"con":true,"img":false}]}
{"op":"mcm","clk":"11540105266","pt":1719490080009,"mc":[{"id":"1.230180114","rc":[{"atb":[[2.94,0]],"id":43289758}],"con":true,"img":false}]}
{"op":"mcm","clk":"11540105463","pt":1719490081731,"mc":[{"id":"1.230180114","rc":[{"atb":[[2.38,8.59]],"id":44213406}],"con":true,"img":false}]}
{"op":"mcm","clk":"11540105473","pt":1719490081830,"mc":[{"id":"1.230180114","rc":[{"atb":[[2.98,5.99]],"id":43289758}],"con":true,"img":false}]}
{"op":"mcm","clk":"11540105985","pt":1719490086203,"mc":[{"id":"1.230180114","rc":[{"atb":[[2.96,0]],"id":43289758}],"con":true,"img":false}]}
{"op":"mcm","clk":"11540106077","pt":1719490086924,"mc":[{"id":"1.230180114","rc":[{"atb":[[3,3.38]],"id":43289758}],"con":true,"img":false}]}
{"op":"mcm","clk":"11540108193","pt":1719490107745,"mc":[{"id":"1.230180114","rc":[{"atb":[[2.36,0]],"id":44213406}],"con":true,"img":false}]}
{"op":"mcm","clk":"11540109858","pt":1719490126292,"mc":[{"id":"1.230180114","rc":[{"atb":[[2.98,0]],"id":43289758}],"con":true,"img":false}]}
{"op":"mcm","clk":"11540109868","pt":1719490126342,"mc":[{"id":"1.230180114","rc":[{"atb":[[2.74,0]],"id":43289758}],"con":true,"img":false}]}
{"op":"mcm","clk":"11540109889","pt":1719490126545,"mc":[{"id":"1.230180114","rc":[{"atb":[[3,6.54]],"id":43289758}],"con":true,"img":false}]}
{"op":"mcm","clk":"11540110368","pt":1719490131569,"mc":[{"id":"1.230180114","rc":[{"atb":[[2.4,9.96]],"id":44213406},{"atb":[[3,3.16]],"id":43289758}],"con":true,"img":false}]}
{"op":"mcm","clk":"11540111994","pt":1719490149099,"mc":[{"id":"1.230180114","rc":[{"atb":[[2.38,0]],"id":44213406}],"con":true,"img":false}]}
{"op":"mcm","clk":"11540112431","pt":1719490154314,"mc":[{"id":"1.230180114","rc":[{"atb":[[3.05,5.79]],"id":43289758}],"con":true,"img":false}]}
{"op":"mcm","clk":"11540112471","pt":1719490154885,"mc":[{"id":"1.230180114","rc":[{"atb":[[3,0]],"id":43289758}],"con":true,"img":false}]}
{"op":"mcm","clk":"11540115353","pt":1719490186058,"mc":[{"id":"1.230180114","rc":[{"atb":[[2.74,3.16]],"id":43289758}],"con":true,"img":false}]}
{"op":"mcm","clk":"11540115372","pt":1719490186263,"mc":[{"id":"1.230180114","rc":[{"atb":[[2.42,8.35]],"id":44213406}],"con":true,"img":false}]}
{"op":"mcm","clk":"11540117199","pt":1719490206579,"mc":[{"id":"1.230180114","rc":[{"atb":[[3.05,0]],"id":43289758}],"con":true,"img":false}]}
{"op":"mcm","clk":"11540117744","pt":1719490211876,"mc":[{"id":"1.230180114","rc":[{"atb":[[2.74,9.98]],"id":43289758}],"con":true,"img":false}]}
{"op":"mcm","clk":"11540118214","pt":1719490217193,"mc":[{"id":"1.230180114","rc":[{"atb":[[2.4,0]],"id":44213406}],"con":true,"img":false}]}
{"op":"mcm","clk":"11540122273","pt":1719490258802,"mc":[{"id":"1.230180114","rc":[{"atb":[[2.42,0]],"id":44213406}],"con":true,"img":false}]}
{"op":"mcm","clk":"11540122412","pt":1719490260301,"mc":[{"id":"1.230180114","rc":[{"atb":[[2.26,9.41]],"id":44213406}],"con":true,"img":false}]}
{"op":"mcm","clk":"11540124423","pt":1719490281319,"mc":[{"id":"1.230180114","rc":[{"atb":[[2.76,3.38]],"id":43289758}],"con":true,"img":false}]}
{"op":"mcm","clk":"11540124481","pt":1719490281841,"mc":[{"id":"1.230180114","rc":[{"atb":[[2.76,11.31]],"id":43289758}],"con":true,"img":false}]}
{"op":"mcm","clk":"11540126560","pt":1719490301545,"mc":[{"id":"1.230180114","rc":[{"atb":[[2.74,6.81]],"id":43289758}],"con":true,"img":false}]}
{"op":"mcm","clk":"11540126591","pt":1719490301753,"mc":[{"id":"1.230180114","rc":[{"atb":[[2.78,3.16]],"id":43289758}],"con":true,"img":false}]}
{"op":"mcm","clk":"11540126764","pt":1719490303456,"mc":[{"id":"1.230180114","rc":[{"atb":[[2.74,0]],"id":43289758}],"con":true,"img":false}]}
{"op":"mcm","clk":"11540127362","pt":1719490309163,"mc":[{"id":"1.230180114","rc":[{"atb":[[2.28,10.9]],"id":44213406}],"con":true,"img":false}]}
{"op":"mcm","clk":"11540127381","pt":1719490309370,"mc":[{"id":"1.230180114","rc":[{"atb":[[2.76,7.92]],"id":43289758}],"con":true,"img":false}]}
{"op":"mcm","clk":"11540128749","pt":1719490323374,"mc":[{"id":"1.230180114","rc":[{"atb":[[2.78,9.83]],"id":43289758}],"con":true,"img":false}]}
{"op":"mcm","clk":"11540130742","pt":1719490343423,"mc":[{"id":"1.230180114","rc":[{"atb":[[2.26,0]],"id":44213406}],"con":true,"img":false}]}
{"op":"mcm","clk":"11540130906","pt":1719490344989,"mc":[{"id":"1.230180114","rc":[{"atb":[[2.3,9.12]],"id":44213406}],"con":true,"img":false}]}
{"op":"mcm","clk":"11540132985","pt":1719490365122,"mc":[{"id":"1.230180114","rc":[{"atb":[[2.76,0]],"id":43289758}],"con":true,"img":false}]}
{"op":"mcm","clk":"11540133039","pt":1719490365740,"mc":[{"id":"1.230180114","rc":[{"atb":[[2.78,6.66]],"id":43289758}],"con":true,"img":false}]}
{"op":"mcm","clk":"11540133658","pt":1719490372463,"mc":[{"id":"1.230180114","rc":[{"atb":[[2.8,7.74]],"id":43289758}],"con":true,"img":false}]}
{"op":"mcm","clk":"11540135072","pt":1719490387179,"mc":[{"id":"1.230180114","rc":[{"atb":[[2.78,0]],"id":43289758}],"con":true,"img":false}]}
{"op":"mcm","clk":"11540136054","pt":1719490397588,"mc":[{"id":"1.230180114","rc":[{"atb":[[2.24,0]],"id":44213406},{"atb":[[2.16,0]],"id":39682601}],"con":true,"img":false}]}
{"op":"mcm","clk":"11540136064","pt":1719490397668,"mc":[{"id":"1.230180114","rc":[{"atb":[[2.32,10.65]],"id":44213406},{"atb":[[2.2,9.58]],"id":39682601}],"con":true,"img":false}]}
{"op":"mcm","clk":"11540136178","pt":1719490399085,"mc":[{"id":"1.230180114","rc":[{"atb":[[2.82,6.51]],"id":43289758}],"con":true,"img":false}]}
{"op":"mcm","clk":"11540136210","pt":1719490399347,"mc":[{"id":"1.230180114","rc":[{"atb":[[2.82,9.68]],"id":43289758}],"con":true,"img":false}]}
{"op":"mcm","clk":"11540136280","pt":1719490399970,"mc":[{"id":"1.230180114","rc":[{"atb":[[2.18,3.38]],"id":39682601}],"con":true,"img":false}]}
{"op":"mcm","clk":"11540136313","pt":1719490400278,"mc":[{"id":"1.230180114","rc":[{"atb":[[2.22,3.16]],"id":39682601}],"con":true,"img":false}]}
{"op":"mcm","clk":"11540137336","pt":1719490410475,"mc":[{"id":"1.230180114","rc":[{"atb":[[2.28,0]],"id":44213406}],"con":true,"img":false}]}
{"op":"mcm","clk":"11540141948","pt":1719490455516,"mc":[{"id":"1.230180114","rc":[{"atb":[[2.3,0]],"id":44213406}],"con":true,"img":false}]}
{"op":"mcm","clk":"11540142363","pt":1719490459220,"mc":[{"id":"1.230180114","rc":[{"atb":[[2.18,0]],"id":39682601}],"con":true,"img":false}]}
{"op":"mcm","clk":"11540142453","pt":1719490460040,"mc":[{"id":"1.230180114","rc":[{"atb":[[2.22,6.54]],"id":39682601}],"con":true,"img":false}]}
{"op":"mcm","clk":"11540144935","pt":1719490483824,"mc":[{"id":"1.230180114","rc":[{"atb":[[2.34,8.85]],"id":44213406}],"con":true,"img":false}]}
{"op":"mcm","clk":"11540149673","pt":1719490530415,"mc":[{"id":"1.230180114","rc":[{"atb":[[2.8,0]],"id":43289758}],"con":true,"img":false}]}
{"op":"mcm","clk":"11540150312","pt":1719490535994,"mc":[{"id":"1.230180114","rc":[{"atb":[[2.82,6.51]],"id":43289758}],"con":true,"img":false}]}
{"op":"mcm","clk":"11540152324","pt":1719490556512,"mc":[{"id":"1.230180114","rc":[{"atb":[[2.82,0]],"id":43289758}],"con":true,"img":false}]}
{"op":"mcm","clk":"11540152348","pt":1719490556724,"mc":[{"id":"1.230180114","rc":[{"atb":[[2.84,6.44]],"id":43289758}],"con":true,"img":false}]}
{"op":"mcm","clk":"11540154057","pt":1719490575730,"mc":[{"id":"1.230180114","rc":[{"atb":[[8,0]],"id":41804643},{"atb":[[8,0]],"id":61150133},{"atb":[[2.42,0]],"id":39682601},{"atb":[[8,0]],"id":63387150},{"atb":[[4.9,0]],"id":43289758}],"con":true,"img":false}]}
{"op":"mcm","clk":"11540154757","pt":1719490583840,"mc":[{"id":"1.230180114","rc":[{"atb":[[2.36,10.26]],"id":44213406}],"con":true,"img":false}]}
{"op":"mcm","clk":"11540156268","pt":1719490596178,"mc":[{"id":"1.230180114","rc":[{"atb":[[3.95,2]],"id":41804643}],"con":true,"img":false}]}
{"op":"mcm","clk":"11540156740","pt":1719490601480,"mc":[{"id":"1.230180114","rc":[{"atb":[[1.93,0]],"id":39682601},{"atb":[[2.84,0]],"id":43289758}],"con":true,"img":false}]}
{"op":"mcm","clk":"11540156962","pt":1719490603890,"mc":[{"id":"1.230180114","rc":[{"atb":[[2.74,3.16]],"id":43289758}],"con":true,"img":false}]}
{"op":"mcm","clk":"11540156990","pt":1719490604158,"mc":[{"id":"1.230180114","rc":[{"atb":[[1.17,69.81]],"id":39682601},{"atb":[[2.28,9.27]],"id":63387150}],"con":true,"img":false}]}
{"op":"mcm","clk":"11540157009","pt":1719490604359,"mc":[{"id":"1.230180114","rc":[{"atb":[[2.26,9.41]],"id":41804643}],"con":true,"img":false}]}
{"op":"mcm","clk":"11540157027","pt":1719490604566,"mc":[{"id":"1.230180114","rc":[{"atb":[[2.26,9.41]],"id":61150133}],"con":true,"img":false}]}
{"op":"mcm","clk":"11540158670","pt":1719490623520,"mc":[{"id":"1.230180114","rc":[{"spn":76.97,"spf":"NaN","id":41804643},{"spn":14.37,"spf":"NaN","id":61150133},{"spn":12.61,"spf":"NaN","id":39682601},{"spn":76.95,"spf":"NaN","id":63387150},{"atb":[[1.52,22.82]],"id":43289758},{"spn":17.37,"spf":"NaN","id":43289758}],"con":true,"img":false}]}
{"op":"mcm","clk":"11540158716","pt":1719490624207,"mc":[{"id":"1.230180114","marketDefinition":{"bspMarket":true,"turnInPlayEnabled":false,"persistenceEnabled":false,"marketBaseRate":5.0,"eventId":"33376437","eventTypeId":"4339","numberOfWinners":1,"bettingType":"ODDS","marketType":"WIN","marketTime":"2024-06-27T13:52:00.000Z","suspendTime":"2024-06-27T13:52:00.000Z","bspReconciled":false,"complete":true,"inPlay":false,"crossMatching":true,"runnersVoidable":false,"numberOfActiveRunners":6,"betDelay":0,"status":"SUSPENDED","runners":[{"status":"ACTIVE","sortPriority":1,"id":39682601,"name":"1. Lilys Pearl"},{"status":"ACTIVE","sortPriority":2,"id":61150133,"name":"2. Mind The Mud"},{"status":"ACTIVE","sortPriority":3,"id":43289758,"name":"3. Salacres Harry"},{"status":"ACTIVE","sortPriority":4,"id":44213406,"name":"4. Go Bye Baby"},{"status":"ACTIVE","sortPriority":5,"id":41804643,"name":"5. Salacres Harold"},{"status":"ACTIVE","sortPriority":6,"id":63387150,"name":"6. Salacres Dolce"}],"regulators":["MR_INT"],"venue":"Towcester","countryCode":"GB","discountAllowed":true,"timezone":"Europe/London","openDate":"2024-06-27T13:33:00.000Z","version":5995359782,"name":"D4 270m","eventName":"Towcester 27th Jun"},"rc":[],"con":true,"img":false}]}
{"op":"mcm","clk":"11540158716","pt":1719490624207,"mc":[{"id":"1.230180114","rc":[{"atb":[[2.24,0],[2.02,0],[1.16,0],[1.03,0],[3.95,0],[1.02,0],[2.12,0],[2.26,0],[1.51,0],[3.9,0],[2.16,0]],"id":41804643},{"atl":[[560,0],[150,0],[970,0],[990,0]],"id":41804643},{"atb":[[2.24,0],[2.02,0],[1.01,0],[1.16,0],[1.02,0],[2.12,0],[2.26,0],[1.51,0],[3.75,0]],"id":61150133},{"atl":[[150,0],[42,0],[390,0],[25,0],[980,0],[1000,0]],"id":61150133},{"atb":[[2.36,0],[2.02,0],[2.32,0],[1.16,0],[1.03,0],[1.02,0],[2.12,0],[1.51,0],[3.9,0],[2.34,0]],"id":44213406},{"atl":[[270,0],[150,0],[980,0],[1000,0]],"id":44213406},{"atb":[[1.92,0],[1.01,0],[1.16,0],[2.22,0],[2.2,0],[1.94,0],[1.17,0],[1.04,0]],"id":39682601},{"atl":[[150,0],[40,0],[23,0],[370,0],[990,0],[1000,0]],"id":39682601},{"atb":[[2.02,0],[1.16,0],[1.03,0],[1.02,0],[2.28,0],[2.12,0],[2.26,0],[1.51,0],[3.9,0]],"id":63387150},{"atl":[[150,0],[990,0],[500,0],[1000,0]],"id":63387150},{"atb":[[2.24,0],[2.72,0],[1.01,0],[2.74,0],[1.16,0],[1.03,0],[1.51,0],[1.52,0]],"id":43289758},{"atl":[[32,0],[550,0],[150,0],[55,0],[980,0],[990,0]],"id":43289758}],"con":true,"img":false}]}
{"op":"mcm","clk":"11540158764","pt":1719490624717,"mc":[{"id":"1.230180114","marketDefinition":{"bspMarket":true,"turnInPlayEnabled":false,"persistenceEnabled":false,"marketBaseRate":5.0,"eventId":"33376437","eventTypeId":"4339","numberOfWinners":1,"bettingType":"ODDS","marketType":"WIN","marketTime":"2024-06-27T13:52:00.000Z","suspendTime":"2024-06-27T13:52:00.000Z","bspReconciled":false,"complete":true,"inPlay":false,"crossMatching":true,"runnersVoidable":false,"numberOfActiveRunners":5,"betDelay":0,"status":"SUSPENDED","runners":[{"status":"ACTIVE","sortPriority":1,"id":39682601,"name":"1. Lilys Pearl"},{"status":"ACTIVE","sortPriority":2,"id":61150133,"name":"2. Mind The Mud"},{"status":"ACTIVE","sortPriority":3,"id":44213406,"name":"4. Go Bye Baby"},{"status":"ACTIVE","sortPriority":4,"id":41804643,"name":"5. Salacres Harold"},{"status":"ACTIVE","sortPriority":5,"id":63387150,"name":"6. Salacres Dolce"},{"status":"REMOVED","sortPriority":6,"removalDate":"2024-06-27T12:17:04.000Z","id":43289758,"name":"3. Salacres Harry"}],"regulators":["MR_INT"],"venue":"Towcester","countryCode":"GB","discountAllowed":true,"timezone":"Europe/London","openDate":"2024-06-27T13:33:00.000Z","version":5995359792,"name":"D4 270m","eventName":"Towcester 27th Jun"},"rc":[],"con":true,"img":false}]}
{"op":"mcm","clk":"11540158764","pt":1719490624717,"mc":[{"id":"1.230180114","rc":[{"trd":[[8,0]],"ltp":8.0,"tv":0.0,"id":44213406}],"con":true,"img":false}]}
{"op":"mcm","clk":"11540158771","pt":1719490624818,"mc":[{"id":"1.230180114","marketDefinition":{"bspMarket":true,"turnInPlayEnabled":false,"persistenceEnabled":false,"marketBaseRate":5.0,"eventId":"33376437","eventTypeId":"4339","numberOfWinners":1,"bettingType":"ODDS","marketType":"WIN","marketTime":"2024-06-27T13:52:00.000Z","suspendTime":"2024-06-27T13:52:00.000Z","bspReconciled":false,"complete":true,"inPlay":false,"crossMatching":true,"runnersVoidable":false,"numberOfActiveRunners":5,"betDelay":0,"status":"OPEN","runners":[{"status":"ACTIVE","sortPriority":1,"id":39682601,"name":"1. Lilys Pearl"},{"status":"ACTIVE","sortPriority":2,"id":61150133,"name":"2. Mind The Mud"},{"status":"ACTIVE","sortPriority":3,"id":44213406,"name":"4. Go Bye Baby"},{"status":"ACTIVE","sortPriority":4,"id":41804643,"name":"5. Salacres Harold"},{"status":"ACTIVE","sortPriority":5,"id":63387150,"name":"6. Salacres Dolce"},{"status":"REMOVED","sortPriority":6,"removalDate":"2024-06-27T12:17:04.000Z","id":43289758,"name":"3. Salacres Harry"}],"regulators":["MR_INT"],"venue":"Towcester","countryCode":"GB","discountAllowed":true,"timezone":"Europe/London","openDate":"2024-06-27T13:33:00.000Z","version":5995359798,"name":"D4 270m","eventName":"Towcester 27th Jun"},"rc":[],"con":true,"img":false}]}
{"op":"mcm","clk":"11540158998","pt":1719490627031,"mc":[{"id":"1.230180114","rc":[{"atb":[[1.16,150]],"id":41804643},{"atl":[[270,2]],"id":41804643},{"spn":76.97,"spf":"NaN","id":41804643},{"atb":[[1.16,150]],"id":61150133},{"atl":[[390,2]],"id":61150133},{"spn":14.37,"spf":"NaN","id":61150133},{"atb":[[1.16,150]],"id":44213406},{"atl":[[550,2]],"id":44213406},{"spn":76.95,"spf":"NaN","id":44213406},{"atb":[[1.16,150]],"id":39682601},{"atl":[[370,2]],"id":39682601},{"spn":12.61,"spf":"NaN","id":39682601},{"atb":[[1.16,150]],"id":63387150},{"atl":[[560,2]],"id":63387150},{"spn":76.95,"spf":"NaN","id":63387150}],"con":true,"img":false}]}
{"op":"mcm","clk":"11540159010","pt":1719490627084,"mc":[{"id":"1.230180114","rc":[{"atl":[[550,31]],"id":44213406}],"con":true,"img":false}]}
{"op":"mcm","clk":"11540159749","pt":1719490635624,"mc":[{"id":"1.230180114","rc":[{"atl":[[550,3]],"id":44213406}],"con":true,"img":false}]}
{"op":"mcm","clk":"11540160009","pt":1719490638221,"mc":[{"id":"1.230180114","rc":[{"atl":[[550,33]],"id":44213406}],"con":true,"img":false}]}
{"op":"mcm","clk":"11540160264","pt":1719490641317,"mc":[{"id":"1.230180114","rc":[{"atl":[[550,2]],"id":44213406}],"con":true,"img":false}]}
{"op":"mcm","clk":"11540160507","pt":1719490644534,"mc":[{"id":"1.230180114","rc":[{"atb":[[1.51,196.08]],"id":41804643},{"atb":[[1.51,196.08]],"id":61150133},{"atb":[[1.51,196.08]],"id":63387150}],"con":true,"img":false}]}
{"op":"mcm","clk":"11540160517","pt":1719490644633,"mc":[{"id":"1.230180114","rc":[{"atl":[[150,4]],"id":41804643},{"atl":[[150,4]],"id":61150133},{"atb":[[1.51,196.08]],"id":44213406},{"atl":[[150,4]],"id":44213406},{"atl":[[150,4]],"id":39682601},{"atl":[[150,4]],"id":63387150}],"con":true,"img":false}]}
{"op":"mcm","clk":"11540164548","pt":1719490696182,"mc":[{"id":"1.230180114","rc":[{"atb":[[1.7,20.25]],"id":41804643},{"spn":75.85,"spf":"NaN","id":41804643},{"atb":[[1.71,17.46]],"id":61150133},{"spn":75.85,"spf":"NaN","id":61150133},{"atb":[[1.75,22.33]],"id":44213406},{"spn":75.87,"spf":"NaN","id":44213406},{"atb":[[1.71,21.82]],"id":39682601},{"spn":75.85,"spf":"NaN","id":39682601},{"atb":[[1.7,20.25]],"id":63387150},{"spn":75.85,"spf":"NaN","id":63387150}],"con":true,"img":false}]}
{"op":"mcm","clk":"11540293705","pt":1719492599569,"mc":[{"id":"1.230180114","rc":[{"spl":[[1.01,1]],"id":39682601},{"spn":1.71,"spf":1.0,"id":39682601}],"con":true,"img":false}]}
{"op":"mcm","clk":"11540317736","pt":1719492922748,"mc":[{"id":"1.230180114","rc":[{"atb":[[1.01,108.28]],"id":41804643},{"atl":[[990,1.32]],"id":41804643},{"atb":[[1.01,107.43]],"id":61150133},{"atl":[[990,0.86]],"id":61150133},{"atb":[[1.01,160.73]],"id":44213406},{"atl":[[980,0.86]],"id":44213406},{"atb":[[1.02,77.82]],"id":39682601},{"atl":[[980,1.86]],"id":39682601},{"atb":[[1.01,71.9]],"id":63387150},{"atl":[[970,1.31]],"id":63387150}],"con":true,"img":false}]}
{"op":"mcm","clk":"11540325013","pt":1719493028847,"mc":[{"id":"1.230180114","rc":[{"atb":[[1.03,5.94]],"id":41804643},{"atl":[[990,2.17]],"id":41804643},{"atb":[[1.01,125.26]],"id":61150133},{"atl":[[1000,0.84]],"id":61150133},{"atb":[[1.01,178.56]],"id":44213406},{"atl":[[990,0.84]],"id":44213406},{"atb":[[1.01,17.83]],"id":39682601},{"atl":[[990,0.84]],"id":39682601},{"atb":[[1.02,8.91]],"id":63387150},{"atl":[[1000,0.84]],"id":63387150}],"con":true,"img":false}]}
{"op":"mcm","clk":"11540325334","pt":1719493033910,"mc":[{"id":"1.230180114","rc":[{"atl":[[150,47]],"id":44213406}],"con":true,"img":false}]}
{"op":"mcm","clk":"11540338448","pt":1719493221468,"mc":[{"id":"1.230180114","rc":[{"atb":[[1.01,108.41],[1.03,5.95],[1.7,20.27]],"id":41804643},{"atl":[[990,2.17]],"id":41804643},{"atb":[[1.01,125.41],[1.71,17.48]],"id":61150133},{"atl":[[990,0.86],[1000,0.84]],"id":61150133},{"atb":[[1.01,178.77],[1.75,22.35]],"id":44213406},{"atl":[[150,45],[980,0.86],[990,0.84]],"id":44213406},{"atb":[[1.01,17.85],[1.02,77.91],[1.71,21.85]],"id":39682601},{"atl":[[980,1.87],[990,0.84]],"id":39682601},{"atb":[[1.01,71.99],[1.02,8.92],[1.7,20.27]],"id":63387150},{"atl":[[970,1.31],[1000,0.84]],"id":63387150}],"con":true,"img":false}]}
{"op":"mcm","clk":"11540342864","pt":1719493284006,"mc":[{"id":"1.230180114","rc":[{"atl":[[150,44]],"id":44213406}],"con":true,"img":false}]}
{"op":"mcm","clk":"11540370235","pt":1719493645788,"mc":[{"id":"1.230180114","rc":[{"atb":[[4,1]],"id":39682601},{"spn":4.0,"spf":1.0,"id":39682601}],"con":true,"img":false}]}
{"op":"mcm","clk":"11540370621","pt":1719493650914,"mc":[{"id":"1.230180114","rc":[{"atb":[[4,0]],"id":39682601}],"con":true,"img":false}]}
{"op":"mcm","clk":"11540372686","pt":1719493678633,"mc":[{"id":"1.230180114","rc":[{"atb":[[4,1]],"id":44213406}],"con":true,"img":false}]}
{"op":"mcm","clk":"11540373563","pt":1719493690019,"mc":[{"id":"1.230180114","rc":[{"atb":[[6,1]],"id":61150133}],"con":true,"img":false}]}
{"op":"mcm","clk":"11540374443","pt":1719493702151,"mc":[{"id":"1.230180114","rc":[{"atb":[[4.5,1]],"id":41804643}],"con":true,"img":false}]}
{"op":"mcm","clk":"11540384583","pt":1719493826472,"mc":[{"id":"1.230180114","rc":[{"spn":77.25,"spf":"NaN","id":41804643},{"spn":78.0,"spf":"NaN","id":61150133},{"atb":[[4.5,1]],"id":44213406},{"spn":77.25,"spf":"NaN","id":44213406},{"spn":1.71,"spf":1.0,"id":39682601}],"con":true,"img":false}]}
{"op":"mcm","clk":"11540387254","pt":1719493857649,"mc":[{"id":"1.230180114","rc":[{"atb":[[4.5,0]],"id":41804643},{"atb":[[6,0]],"id":61150133},{"atb":[[4,0],[4.5,0]],"id":44213406}],"con":true,"img":false}]}
{"op":"mcm","clk":"11540394719","pt":1719493955256,"mc":[{"id":"1.230180114","rc":[{"spn":75.85,"spf":"NaN","id":41804643},{"spn":75.85,"spf":"NaN","id":61150133},{"spn":75.87,"spf":"NaN","id":44213406},{"atb":[[1.72,1.55]],"id":39682601},{"spn":1.72,"spf":1.0,"id":39682601}],"con":true,"img":false}]}
{"op":"mcm","clk":"11540394741","pt":1719493955569,"mc":[{"id":"1.230180114","rc":[{"atb":[[1.71,1.82]],"id":63387150}],"con":true,"img":false}]}
{"op":"mcm","clk":"11540394769","pt":1719493955876,"mc":[{"id":"1.230180114","rc":[{"atb":[[1.71,1.71]],"id":41804643}],"con":true,"img":false}]}
{"op":"mcm","clk":"11540394834","pt":1719493956651,"mc":[{"id":"1.230180114","rc":[{"atb":[[1.76,1.56]],"id":44213406}],"con":true,"img":false}]}
{"op":"mcm","clk":"11540394862","pt":1719493957068,"mc":[{"id":"1.230180114","rc":[{"atb":[[1.72,1.71]],"id":61150133}],"con":true,"img":false}]}
{"op":"mcm","clk":"11540416819","pt":1719494263823,"mc":[{"id":"1.230180114","rc":[{"spn":75.85,"spf":"NaN","id":41804643},{"spn":75.86,"spf":"NaN","id":61150133},{"atl":[[150,54]],"id":44213406},{"spn":75.88,"spf":"NaN","id":44213406},{"spn":75.85,"spf":"NaN","id":63387150}],"con":true,"img":false}]}
{"op":"mcm","clk":"11540420950","pt":1719494315376,"mc":[{"id":"1.230180114","rc":[{"atl":[[150,24]],"id":44213406}],"con":true,"img":false}]}
{"op":"mcm","clk":"11540465221","pt":1719494826750,"mc":[{"id":"1.230180114","rc":[{"atl":[[190,4]],"id":41804643},{"atl":[[190,4]],"id":61150133},{"atl":[[190,4]],"id":44213406},{"atl":[[190,4]],"id":39682601},{"atl":[[190,4]],"id":63387150}],"con":true,"img":false}]}
{"op":"mcm","clk":"11540465231","pt":1719494826850,"mc":[{"id":"1.230180114","rc":[{"atl":[[150,25.7]],"id":44213406}],"con":true,"img":false}]}
{"op":"mcm","clk":"11540465254","pt":1719494827054,"mc":[{"id":"1.230180114","rc":[{"atl":[[150,27.4]],"id":44213406}],"con":true,"img":false}]}
{"op":"mcm","clk":"11540465275","pt":1719494827259,"mc":[{"id":"1.230180114","rc":[{"atl":[[150,29.1]],"id":44213406}],"con":true,"img":false}]}
{"op":"mcm","clk":"11540465288","pt":1719494827464,"mc":[{"id":"1.230180114","rc":[{"atl":[[150,30.8]],"id":44213406}],"con":true,"img":false}]}
{"op":"mcm","clk":"11540468664","pt":1719494863629,"mc":[{"id":"1.230180114","rc":[{"atb":[[1.02,79.91]],"id":39682601}],"con":true,"img":false}]}
{"op":"mcm","clk":"11540468689","pt":1719494864003,"mc":[{"id":"1.230180114","rc":[{"atb":[[1.73,2]],"id":61150133}],"con":true,"img":false}]}
{"op":"mcm","clk":"11540468743","pt":1719494864518,"mc":[{"id":"1.230180114","rc":[{"atb":[[1.77,2]],"id":44213406}],"con":true,"img":false}]}
{"op":"mcm","clk":"11540468780","pt":1719494864934,"mc":[{"id":"1.230180114","rc":[{"atb":[[1.72,2]],"id":41804643}],"con":true,"img":false}]}
{"op":"mcm","clk":"11540468822","pt":1719494865408,"mc":[{"id":"1.230180114","rc":[{"atb":[[1.72,2]],"id":63387150}],"con":true,"img":false}]}
{"op":"mcm","clk":"11540468873","pt":1719494866136,"mc":[{"id":"1.230180114","rc":[{"atb":[[1.71,0]],"id":63387150}],"con":true,"img":false}]}
{"op":"mcm","clk":"11540468901","pt":1719494866396,"mc":[{"id":"1.230180114","rc":[{"atb":[[1.71,0]],"id":41804643}],"con":true,"img":false}]}
{"op":"mcm","clk":"11540468923","pt":1719494866709,"mc":[{"id":"1.230180114","rc":[{"atb":[[1.76,0]],"id":44213406}],"con":true,"img":false}]}
{"op":"mcm","clk":"11540468941","pt":1719494867029,"mc":[{"id":"1.230180114","rc":[{"atb":[[1.72,0]],"id":61150133}],"con":true,"img":false}]}
{"op":"mcm","clk":"11540468986","pt":1719494867505,"mc":[{"id":"1.230180114","rc":[{"atb":[[1.77,0]],"id":44213406}],"con":true,"img":false}]}
{"op":"mcm","clk":"11540468997","pt":1719494867608,"mc":[{"id":"1.230180114","rc":[{"atb":[[1.76,2]],"id":44213406}],"con":true,"img":false}]}
{"op":"mcm","clk":"11540469025","pt":1719494867917,"mc":[{"id":"1.230180114","rc":[{"atb":[[1.72,0]],"id":41804643}],"con":true,"img":false}]}
{"op":"mcm","clk":"11540469031","pt":1719494868028,"mc":[{"id":"1.230180114","rc":[{"atb":[[1.71,2]],"id":41804643}],"con":true,"img":false}]}
{"op":"mcm","clk":"11540469073","pt":1719494868438,"mc":[{"id":"1.230180114","rc":[{"atb":[[1.72,0]],"id":63387150}],"con":true,"img":false}]}
{"op":"mcm","clk":"11540469079","pt":1719494868541,"mc":[{"id":"1.230180114","rc":[{"atb":[[1.71,2]],"id":63387150}],"con":true,"img":false}]}
{"op":"mcm","clk":"11540469255","pt":1719494870723,"mc":[{"id":"1.230180114","rc":[{"atb":[[1.73,0]],"id":61150133}],"con":true,"img":false}]}
{"op":"mcm","clk":"11540469261","pt":1719494870829,"mc":[{"id":"1.230180114","rc":[{"atb":[[1.72,2]],"id":61150133}],"con":true,"img":false}]}
{"op":"mcm","clk":"11540469361","pt":1719494872136,"mc":[{"id":"1.230180114","rc":[{"atb":[[1.72,1.52]],"id":63387150}],"con":true,"img":false}]}
{"op":"mcm","clk":"11540469381","pt":1719494872445,"mc":[{"id":"1.230180114","rc":[{"atb":[[1.72,1.66]],"id":41804643}],"con":true,"img":false}]}
{"op":"mcm","clk":"11540469395","pt":1719494872613,"mc":[{"id":"1.230180114","rc":[{"atb":[[1.71,0]],"id":63387150}],"con":true,"img":false}]}
{"op":"mcm","clk":"11540469403","pt":1719494872711,"mc":[{"id":"1.230180114","rc":[{"atb":[[1.77,1.57]],"id":44213406}],"con":true,"img":false}]}
{"op":"mcm","clk":"11540469411","pt":1719494872817,"mc":[{"id":"1.230180114","rc":[{"atb":[[1.73,2]],"id":63387150}],"con":true,"img":false}]}
{"op":"mcm","clk":"11540469429","pt":1719494873051,"mc":[{"id":"1.230180114","rc":[{"atb":[[1.73,1.64]],"id":61150133}],"con":true,"img":false}]}
{"op":"mcm","clk":"11540469562","pt":1719494874652,"mc":[{"id":"1.230180114","rc":[{"atb":[[1.72,0]],"id":61150133}],"con":true,"img":false}]}
{"op":"mcm","clk":"11540469572","pt":1719494874705,"mc":[{"id":"1.230180114","rc":[{"atb":[[1.74,2]],"id":61150133}],"con":true,"img":false}]}
{"op":"mcm","clk":"11540469597","pt":1719494875022,"mc":[{"id":"1.230180114","rc":[{"atb":[[1.76,0]],"id":44213406}],"con":true,"img":false}]}
{"op":"mcm","clk":"11540469604","pt":1719494875124,"mc":[{"id":"1.230180114","rc":[{"atb":[[1.78,2]],"id":44213406},{"atb":[[1.72,0]],"id":63387150}],"con":true,"img":false}]}
{"op":"mcm","clk":"11540469629","pt":1719494875538,"mc":[{"id":"1.230180114","rc":[{"atb":[[1.71,0]],"id":41804643}],"con":true,"img":false}]}
{"op":"mcm","clk":"11540469640","pt":1719494875643,"mc":[{"id":"1.230180114","rc":[{"atb":[[1.73,2]],"id":41804643}],"con":true,"img":false}]}
{"op":"mcm","clk":"11540469846","pt":1719494878037,"mc":[{"id":"1.230180114","rc":[{"atb":[[1.73,0]],"id":63387150}],"con":true,"img":false}]}
{"op":"mcm","clk":"11540469859","pt":1719494878145,"mc":[{"id":"1.230180114","rc":[{"atb":[[1.71,2]],"id":63387150}],"con":true,"img":false}]}
{"op":"mcm","clk":"11540469867","pt":1719494878233,"mc":[{"id":"1.230180114","rc":[{"atb":[[1.74,1.67]],"id":63387150}],"con":true,"img":false}]}
{"op":"mcm","clk":"11540469888","pt":1719494878546,"mc":[{"id":"1.230180114","rc":[{"atb":[[1.72,0]],"id":41804643}],"con":true,"img":false}]}
{"op":"mcm","clk":"11540469932","pt":1719494878910,"mc":[{"id":"1.230180114","rc":[{"atb":[[1.77,0]],"id":44213406}],"con":true,"img":false}]}
{"op":"mcm","clk":"11540469961","pt":1719494879226,"mc":[{"id":"1.230180114","rc":[{"atb":[[1.73,0]],"id":61150133}],"con":true,"img":false}]}
{"op":"mcm","clk":"11540470009","pt":1719494879954,"mc":[{"id":"1.230180114","rc":[{"atb":[[1.74,0]],"id":61150133}],"con":true,"img":false}]}
{"op":"mcm","clk":"11540470020","pt":1719494880054,"mc":[{"id":"1.230180114","rc":[{"atb":[[1.72,2]],"id":61150133}],"con":true,"img":false}]}
{"op":"mcm","clk":"11540470054","pt":1719494880322,"mc":[{"id":"1.230180114","rc":[{"atb":[[1.78,0]],"id":44213406}],"con":true,"img":false}]}
{"op":"mcm","clk":"11540470063","pt":1719494880425,"mc":[{"id":"1.230180114","rc":[{"atb":[[1.76,2]],"id":44213406}],"con":true,"img":false}]}
{"op":"mcm","clk":"11540470100","pt":1719494880841,"mc":[{"id":"1.230180114","rc":[{"atb":[[1.73,0]],"id":41804643}],"con":true,"img":false}]}
{"op":"mcm","clk":"11540470112","pt":1719494880948,"mc":[{"id":"1.230180114","rc":[{"atb":[[1.71,2]],"id":41804643}],"con":true,"img":false}]}
{"op":"mcm","clk":"11540470154","pt":1719494881211,"mc":[{"id":"1.230180114","rc":[{"atb":[[1.71,0]],"id":63387150}],"con":true,"img":false}]}
{"op":"mcm","clk":"11540470160","pt":1719494881315,"mc":[{"id":"1.230180114","rc":[{"atb":[[1.75,2]],"id":63387150}],"con":true,"img":false}]}
{"op":"mcm","clk":"11540470418","pt":1719494884165,"mc":[{"id":"1.230180114","rc":[{"atb":[[1.74,0]],"id":63387150}],"con":true,"img":false}]}
{"op":"mcm","clk":"11540470448","pt":1719494884467,"mc":[{"id":"1.230180114","rc":[{"atb":[[1.72,1.98]],"id":41804643}],"con":true,"img":false}]}
{"op":"mcm","clk":"11540470479","pt":1719494884781,"mc":[{"id":"1.230180114","rc":[{"atb":[[1.77,1.86]],"id":44213406}],"con":true,"img":false}]}
{"op":"mcm","clk":"11540470498","pt":1719494884941,"mc":[{"id":"1.230180114","rc":[{"atb":[[1.71,0]],"id":41804643}],"con":true,"img":false}]}
{"op":"mcm","clk":"11540470506","pt":1719494885061,"mc":[{"id":"1.230180114","rc":[{"atb":[[1.73,2]],"id":41804643},{"atb":[[1.73,1.6]],"id":61150133}],"con":true,"img":false}]}
{"op":"mcm","clk":"11540470560","pt":1719494885581,"mc":[{"id":"1.230180114","rc":[{"atb":[[1.75,0]],"id":63387150}],"con":true,"img":false}]}
{"op":"mcm","clk":"11540470570","pt":1719494885679,"mc":[{"id":"1.230180114","rc":[{"atb":[[1.71,2]],"id":63387150}],"con":true,"img":false}]}
{"op":"mcm","clk":"11540470708","pt":1719494887140,"mc":[{"id":"1.230180114","rc":[{"atb":[[1.72,0]],"id":41804643},{"spn":75.86,"spf":"NaN","id":41804643},{"spn":75.86,"spf":"NaN","id":61150133},{"spn":75.88,"spf":"NaN","id":44213406}],"con":true,"img":false}]}
{"op":"mcm","clk":"11540470747","pt":1719494887560,"mc":[{"id":"1.230180114","rc":[{"atb":[[1.72,0]],"id":61150133}],"con":true,"img":false}]}
{"op":"mcm","clk":"11540470749","pt":1719494887657,"mc":[{"id":"1.230180114","rc":[{"atb":[[1.74,2]],"id":61150133}],"con":true,"img":false}]}
{"op":"mcm","clk":"11540470764","pt":1719494887879,"mc":[{"id":"1.230180114","rc":[{"atb":[[1.76,0]],"id":44213406}],"con":true,"img":false}]}
{"op":"mcm","clk":"11540470771","pt":1719494887987,"mc":[{"id":"1.230180114","rc":[{"atb":[[1.78,2]],"id":44213406}],"con":true,"img":false}]}
{"op":"mcm","clk":"11540470887","pt":1719494889348,"mc":[{"id":"1.230180114","rc":[{"atb":[[1.73,0]],"id":41804643}],"con":true,"img":false}]}
{"op":"mcm","clk":"11540470894","pt":1719494889447,"mc":[{"id":"1.230180114","rc":[{"atb":[[1.71,2]],"id":41804643}],"con":true,"img":false}]}
{"op":"mcm","clk":"11540470967","pt":1719494890181,"mc":[{"id":"1.230180114","rc":[{"atb":[[1.72,1.87]],"id":63387150}],"con":true,"img":false}]}
{"op":"mcm","clk":"11540470992","pt":1719494890509,"mc":[{"id":"1.230180114","rc":[{"atb":[[1.72,1.84]],"id":41804643}],"con":true,"img":false}]}
{"op":"mcm","clk":"11540471020","pt":1719494890756,"mc":[{"id":"1.230180114","rc":[{"atb":[[1.77,0]],"id":44213406}],"con":true,"img":false}]}
{"op":"mcm","clk":"11540471044","pt":1719494891066,"mc":[{"id":"1.230180114","rc":[{"atb":[[1.73,0]],"id":61150133}],"con":true,"img":false}]}
{"op":"mcm","clk":"11540471258","pt":1719494893591,"mc":[{"id":"1.230180114","rc":[{"atb":[[1.74,0]],"id":61150133}],"con":true,"img":false}]}
{"op":"mcm","clk":"11540471270","pt":1719494893682,"mc":[{"id":"1.230180114","rc":[{"atb":[[1.72,2]],"id":61150133}],"con":true,"img":false}]}
{"op":"mcm","clk":"11540471320","pt":1719494894161,"mc":[{"id":"1.230180114","rc":[{"atb":[[1.78,0]],"id":44213406}],"con":true,"img":false}]}
{"op":"mcm","clk":"11540471327","pt":1719494894272,"mc":[{"id":"1.230180114","rc":[{"atb":[[1.76,2]],"id":44213406}],"con":true,"img":false}]}
{"op":"mcm","clk":"11540471375","pt":1719494894888,"mc":[{"id":"1.230180114","rc":[{"atb":[[1.71,0]],"id":41804643}],"con":true,"img":false}]}
{"op":"mcm","clk":"11540471385","pt":1719494894991,"mc":[{"id":"1.230180114","rc":[{"atb":[[1.73,2]],"id":41804643}],"con":true,"img":false}]}
{"op":"mcm","clk":"11540471430","pt":1719494895372,"mc":[{"id":"1.230180114","rc":[{"atb":[[1.71,0]],"id":63387150}],"con":true,"img":false}]}
{"op":"mcm","clk":"11540471442","pt":1719494895477,"mc":[{"id":"1.230180114","rc":[{"atb":[[1.73,2]],"id":63387150}],"con":true,"img":false}]}
{"op":"mcm","clk":"11540471499","pt":1719494896302,"mc":[{"id":"1.230180114","rc":[{"atb":[[1.72,0]],"id":63387150}],"con":true,"img":false}]}
{"op":"mcm","clk":"11540471527","pt":1719494896574,"mc":[{"id":"1.230180114","rc":[{"atb":[[1.72,0]],"id":41804643}],"con":true,"img":false}]}
{"op":"mcm","clk":"11540471548","pt":1719494896882,"mc":[{"id":"1.230180114","rc":[{"atb":[[1.77,1.62]],"id":44213406}],"con":true,"img":false}]}
{"op":"mcm","clk":"11540471573","pt":1719494897200,"mc":[{"id":"1.230180114","rc":[{"atb":[[1.73,1.68]],"id":61150133}],"con":true,"img":false}]}
{"op":"mcm","clk":"11540471692","pt":1719494898616,"mc":[{"id":"1.230180114","rc":[{"atb":[[1.72,0]],"id":61150133}],"con":true,"img":false}]}
{"op":"mcm","clk":"11540471703","pt":1719494898660,"mc":[{"id":"1.230180114","rc":[{"atb":[[1.74,2]],"id":61150133}],"con":true,"img":false}]}
{"op":"mcm","clk":"11540471728","pt":1719494898976,"mc":[{"id":"1.230180114","rc":[{"atb":[[1.76,0]],"id":44213406}],"con":true,"img":false}]}
{"op":"mcm","clk":"11540471737","pt":1719494899077,"mc":[{"id":"1.230180114","rc":[{"atb":[[1.78,2]],"id":44213406}],"con":true,"img":false}]}
{"op":"mcm","clk":"11540471751","pt":1719494899305,"mc":[{"id":"1.230180114","rc":[{"atb":[[1.73,0]],"id":61150133}],"con":true,"img":false}]}
{"op":"mcm","clk":"11540471755","pt":1719494899384,"mc":[{"id":"1.230180114","rc":[{"atb":[[1.73,0]],"id":41804643}],"con":true,"img":false}]}
{"op":"mcm","clk":"11540471760","pt":1719494899493,"mc":[{"id":"1.230180114","rc":[{"atb":[[1.71,2]],"id":41804643}],"con":true,"img":false}]}
{"op":"mcm","clk":"11540471800","pt":1719494900058,"mc":[{"id":"1.230180114","rc":[{"atb":[[1.73,0]],"id":63387150}],"con":true,"img":false}]}
{"op":"mcm","clk":"11540471805","pt":1719494900171,"mc":[{"id":"1.230180114","rc":[{"atb":[[1.71,2]],"id":63387150}],"con":true,"img":false}]}
{"op":"mcm","clk":"11540471962","pt":1719494902203,"mc":[{"id":"1.230180114","rc":[{"atb":[[1.74,0]],"id":61150133}],"con":true,"img":false}]}
{"op":"mcm","clk":"11540471971","pt":1719494902295,"mc":[{"id":"1.230180114","rc":[{"atb":[[1.72,2]],"id":61150133},{"atb":[[1.72,1.52]],"id":63387150}],"con":true,"img":false}]}
{"op":"mcm","clk":"11540471992","pt":1719494902599,"mc":[{"id":"1.230180114","rc":[{"atb":[[1.72,1.52]],"id":41804643}],"con":true,"img":false}]}
{"op":"mcm","clk":"11540472015","pt":1719494902877,"mc":[{"id":"1.230180114","rc":[{"atb":[[1.77,0]],"id":44213406}],"con":true,"img":false}]}
{"op":"mcm","clk":"11540472042","pt":1719494903191,"mc":[{"id":"1.230180114","rc":[{"atb":[[1.75,1.65]],"id":61150133}],"con":true,"img":false}]}
{"op":"mcm","clk":"11540472118","pt":1719494904083,"mc":[{"id":"1.230180114","rc":[{"atb":[[1.72,0]],"id":61150133}],"con":true,"img":false}]}
{"op":"mcm","clk":"11540472126","pt":1719494904179,"mc":[{"id":"1.230180114","rc":[{"atb":[[1.76,2]],"id":61150133}],"con":true,"img":false}]}
{"op":"mcm","clk":"11540472160","pt":1719494904701,"mc":[{"id":"1.230180114","rc":[{"atb":[[1.78,0]],"id":44213406}],"con":true,"img":false}]}
{"op":"mcm","clk":"11540472169","pt":1719494904811,"mc":[{"id":"1.230180114","rc":[{"atb":[[1.76,2]],"id":44213406}],"con":true,"img":false}]}
{"op":"mcm","clk":"11540472198","pt":1719494905103,"mc":[{"id":"1.230180114","rc":[{"atb":[[1.71,0]],"id":41804643}],"con":true,"img":false}]}
{"op":"mcm","clk":"11540472210","pt":1719494905212,"mc":[{"id":"1.230180114","rc":[{"atb":[[1.73,2]],"id":41804643}],"con":true,"img":false}]}
{"op":"mcm","clk":"11540472228","pt":1719494905386,"mc":[{"id":"1.230180114","rc":[{"atb":[[1.75,0]],"id":61150133}],"con":true,"img":false}]}
{"op":"mcm","clk":"11540472240","pt":1719494905483,"mc":[{"id":"1.230180114","rc":[{"atb":[[1.71,0]],"id":63387150}],"con":true,"img":false}]}
{"op":"mcm","clk":"11540472250","pt":1719494905586,"mc":[{"id":"1.230180114","rc":[{"atb":[[1.73,2]],"id":63387150}],"con":true,"img":false}]}
{"op":"mcm","clk":"11540472424","pt":1719494907611,"mc":[{"id":"1.230180114","rc":[{"atb":[[1.76,0]],"id":61150133}],"con":true,"img":false}]}
{"op":"mcm","clk":"11540472432","pt":1719494907704,"mc":[{"id":"1.230180114","rc":[{"atb":[[1.72,2]],"id":61150133}],"con":true,"img":false}]}
{"op":"mcm","clk":"11540472482","pt":1719494908287,"mc":[{"id":"1.230180114","rc":[{"atb":[[1.72,0]],"id":63387150}],"con":true,"img":false}]}
{"op":"mcm","clk":"11540472511","pt":1719494908596,"mc":[{"id":"1.230180114","rc":[{"atb":[[1.72,0]],"id":41804643}],"con":true,"img":false}]}
{"op":"mcm","clk":"11540472540","pt":1719494908912,"mc":[{"id":"1.230180114","rc":[{"atb":[[1.77,1.57]],"id":44213406}],"con":true,"img":false}]}
{"op":"mcm","clk":"11540472564","pt":1719494909217,"mc":[{"id":"1.230180114","rc":[{"atb":[[1.73,1.64]],"id":61150133}],"con":true,"img":false}]}
{"op":"mcm","clk":"11540472605","pt":1719494909792,"mc":[{"id":"1.230180114","rc":[{"atb":[[1.76,0]],"id":44213406}],"con":true,"img":false}]}
{"op":"mcm","clk":"11540472612","pt":1719494909896,"mc":[{"id":"1.230180114","rc":[{"atb":[[1.78,2]],"id":44213406}],"con":true,"img":false}]}
{"op":"mcm","clk":"11540472649","pt":1719494910319,"mc":[{"id":"1.230180114","rc":[{"atb":[[1.73,0]],"id":41804643}],"con":true,"img":false}]}
{"op":"mcm","clk":"11540472658","pt":1719494910415,"mc":[{"id":"1.230180114","rc":[{"atb":[[1.71,2]],"id":41804643}],"con":true,"img":false}]}
{"op":"mcm","clk":"11540472685","pt":1719494910824,"mc":[{"id":"1.230180114","rc":[{"atb":[[1.73,0]],"id":63387150}],"con":true,"img":false}]}
{"op":"mcm","clk":"11540472691","pt":1719494910891,"mc":[{"id":"1.230180114","rc":[{"atb":[[1.71,2]],"id":63387150}],"con":true,"img":false}]}
{"op":"mcm","clk":"11540472728","pt":1719494911413,"mc":[{"id":"1.230180114","rc":[{"atb":[[1.77,0]],"id":44213406}],"con":true,"img":false}]}
{"op":"mcm","clk":"11540472874","pt":1719494913220,"mc":[{"id":"1.230180114","rc":[{"atb":[[1.72,0]],"id":61150133}],"con":true,"img":false}]}
{"op":"mcm","clk":"11540472881","pt":1719494913275,"mc":[{"id":"1.230180114","rc":[{"atb":[[1.74,2]],"id":61150133}],"con":true,"img":false}]}
{"op":"mcm","clk":"11540472919","pt":1719494913699,"mc":[{"id":"1.230180114","rc":[{"atb":[[1.78,0]],"id":44213406}],"con":true,"img":false}]}
{"op":"mcm","clk":"11540472928","pt":1719494913804,"mc":[{"id":"1.230180114","rc":[{"atb":[[1.76,2]],"id":44213406}],"con":true,"img":false}]}
{"op":"mcm","clk":"11540472966","pt":1719494914320,"mc":[{"id":"1.230180114","rc":[{"atb":[[1.72,1.7]],"id":63387150}],"con":true,"img":false}]}
{"op":"mcm","clk":"11540472994","pt":1719494914578,"mc":[{"id":"1.230180114","rc":[{"atb":[[1.72,1.9]],"id":41804643}],"con":true,"img":false}]}
{"op":"mcm","clk":"11540473018","pt":1719494914896,"mc":[{"id":"1.230180114","rc":[{"atb":[[1.77,1.84]],"id":44213406}],"con":true,"img":false}]}
{"op":"mcm","clk":"11540473038","pt":1719494915206,"mc":[{"id":"1.230180114","rc":[{"atb":[[1.73,0]],"id":61150133}],"con":true,"img":false}]}
{"op":"mcm","clk":"11540473082","pt":1719494915829,"mc":[{"id":"1.230180114","rc":[{"atb":[[1.74,0]],"id":61150133}],"con":true,"img":false}]}
{"op":"mcm","clk":"11540473088","pt":1719494915876,"mc":[{"id":"1.230180114","rc":[{"atb":[[1.72,2]],"id":61150133}],"con":true,"img":false}]}
{"op":"mcm","clk":"11540473125","pt":1719494916298,"mc":[{"id":"1.230180114","rc":[{"atb":[[1.76,0]],"id":44213406}],"con":true,"img":false}]}
{"op":"mcm","clk":"11540473136","pt":1719494916410,"mc":[{"id":"1.230180114","rc":[{"atb":[[1.78,2]],"id":44213406}],"con":true,"img":false}]}
{"op":"mcm","clk":"11540473156","pt":1719494916716,"mc":[{"id":"1.230180114","rc":[{"atb":[[1.71,0]],"id":41804643}],"con":true,"img":false}]}
{"op":"mcm","clk":"11540473162","pt":1719494916811,"mc":[{"id":"1.230180114","rc":[{"atb":[[1.73,2]],"id":41804643}],"con":true,"img":false}]}
{"op":"mcm","clk":"11540473191","pt":1719494917186,"mc":[{"id":"1.230180114","rc":[{"atb":[[1.71,0]],"id":63387150}],"con":true,"img":false}]}
{"op":"mcm","clk":"11540473201","pt":1719494917296,"mc":[{"id":"1.230180114","rc":[{"atb":[[1.73,2]],"id":63387150}],"con":true,"img":false}]}
{"op":"mcm","clk":"11540473241","pt":1719494917704,"mc":[{"id":"1.230180114","rc":[{"atb":[[1.72,0]],"id":41804643}],"con":true,"img":false}]}
{"op":"mcm","clk":"11540473270","pt":1719494918014,"mc":[{"id":"1.230180114","rc":[{"atb":[[1.77,0]],"id":44213406}],"con":true,"img":false}]}
{"op":"mcm","clk":"11540473301","pt":1719494918323,"mc":[{"id":"1.230180114","rc":[{"atb":[[1.73,1.67]],"id":61150133}],"con":true,"img":false}]}
{"op":"mcm","clk":"11540473372","pt":1719494919111,"mc":[{"id":"1.230180114","rc":[{"atb":[[1.72,0]],"id":61150133}],"con":true,"img":false}]}
{"op":"mcm","clk":"11540473381","pt":1719494919214,"mc":[{"id":"1.230180114","rc":[{"atb":[[1.74,2]],"id":61150133}],"con":true,"img":false}]}
{"op":"mcm","clk":"11540473456","pt":1719494919934,"mc":[{"id":"1.230180114","rc":[{"atb":[[1.78,0]],"id":44213406}],"con":true,"img":false}]}
{"op":"mcm","clk":"11540473470","pt":1719494919993,"mc":[{"id":"1.230180114","rc":[{"atb":[[1.76,2]],"id":44213406}],"con":true,"img":false}]}
{"op":"mcm","clk":"11540473504","pt":1719494920309,"mc":[{"id":"1.230180114","rc":[{"atb":[[1.73,0]],"id":41804643}],"con":true,"img":false}]}
{"op":"mcm","clk":"11540473518","pt":1719494920417,"mc":[{"id":"1.230180114","rc":[{"atb":[[1.71,2]],"id":41804643}],"con":true,"img":false}]}
{"op":"mcm","clk":"11540473526","pt":1719494920522,"mc":[{"id":"1.230180114","rc":[{"atb":[[1.72,0]],"id":63387150}],"con":true,"img":false}]}
{"op":"mcm","clk":"11540473550","pt":1719494920820,"mc":[{"id":"1.230180114","rc":[{"atb":[[1.74,1.8]],"id":41804643}],"con":true,"img":false}]}
{"op":"mcm","clk":"11540473575","pt":1719494921203,"mc":[{"id":"1.230180114","rc":[{"atb":[[1.79,1.95]],"id":44213406}],"con":true,"img":false}]}
{"op":"mcm","clk":"11540473606","pt":1719494921529,"mc":[{"id":"1.230180114","rc":[{"atb":[[1.73,0]],"id":61150133}],"con":true,"img":false}]}
{"op":"mcm","clk":"11540473740","pt":1719494922802,"mc":[{"id":"1.230180114","rc":[{"atb":[[1.74,0]],"id":61150133}],"con":true,"img":false}]}
{"op":"mcm","clk":"11540473749","pt":1719494922912,"mc":[{"id":"1.230180114","rc":[{"atb":[[1.72,2]],"id":61150133}],"con":true,"img":false}]}
{"op":"mcm","clk":"11540473778","pt":1719494923219,"mc":[{"id":"1.230180114","rc":[{"atb":[[1.76,0]],"id":44213406}],"con":true,"img":false}]}
{"op":"mcm","clk":"11540473789","pt":1719494923318,"mc":[{"id":"1.230180114","rc":[{"atb":[[1.8,2]],"id":44213406}],"con":true,"img":false}]}
{"op":"mcm","clk":"11540473816","pt":1719494923589,"mc":[{"id":"1.230180114","rc":[{"atb":[[1.71,0]],"id":41804643}],"con":true,"img":false}]}
{"op":"mcm","clk":"11540473827","pt":1719494923691,"mc":[{"id":"1.230180114","rc":[{"atb":[[1.75,2]],"id":41804643}],"con":true,"img":false}]}
{"op":"mcm","clk":"11540473863","pt":1719494924106,"mc":[{"id":"1.230180114","rc":[{"atb":[[1.73,0]],"id":63387150}],"con":true,"img":false}]}
{"op":"mcm","clk":"11540473870","pt":1719494924209,"mc":[{"id":"1.230180114","rc":[{"atb":[[1.71,2]],"id":63387150}],"con":true,"img":false}]}
{"op":"mcm","clk":"11540474057","pt":1719494926394,"mc":[{"id":"1.230180114","rc":[{"atb":[[1.72,1.84]],"id":63387150}],"con":true,"img":false}]}
{"op":"mcm","clk":"11540474088","pt":1719494926701,"mc":[{"id":"1.230180114","rc":[{"atb":[[1.74,0]],"id":41804643}],"con":true,"img":false}]}
{"op":"mcm","clk":"11540474112","pt":1719494927024,"mc":[{"id":"1.230180114","rc":[{"atb":[[1.79,0]],"id":44213406}],"con":true,"img":false}]}
{"op":"mcm","clk":"11540474135","pt":1719494927330,"mc":[{"id":"1.230180114","rc":[{"atb":[[1.73,1.59]],"id":61150133}],"con":true,"img":false}]}
{"op":"mcm","clk":"11540474167","pt":1719494927691,"mc":[{"id":"1.230180114","rc":[{"atb":[[1.72,0]],"id":61150133}],"con":true,"img":false}]}
{"op":"mcm","clk":"11540474178","pt":1719494927801,"mc":[{"id":"1.230180114","rc":[{"atb":[[1.74,2]],"id":61150133}],"con":true,"img":false}]}
{"op":"mcm","clk":"11540474201","pt":1719494928107,"mc":[{"id":"1.230180114","rc":[{"atb":[[1.8,0]],"id":44213406}],"con":true,"img":false}]}
{"op":"mcm","clk":"11540474213","pt":1719494928220,"mc":[{"id":"1.230180114","rc":[{"atb":[[1.76,2]],"id":44213406}],"con":true,"img":false}]}
{"op":"mcm","clk":"11540474247","pt":1719494928623,"mc":[{"id":"1.230180114","rc":[{"atb":[[1.75,0]],"id":41804643}],"con":true,"img":false}]}
{"op":"mcm","clk":"11540474257","pt":1719494928726,"mc":[{"id":"1.230180114","rc":[{"atb":[[1.71,2]],"id":41804643}],"con":true,"img":false}]}
{"op":"mcm","clk":"11540474317","pt":1719494929200,"mc":[{"id":"1.230180114","rc":[{"atb":[[1.71,0]],"id":63387150}],"con":true,"img":false}]}
{"op":"mcm","clk":"11540474322","pt":1719494929300,"mc":[{"id":"1.230180114","rc":[{"atb":[[1.73,2]],"id":63387150}],"con":true,"img":false}]}
{"op":"mcm","clk":"11540474359","pt":1719494929723,"mc":[{"id":"1.230180114","rc":[{"atb":[[1.73,0]],"id":61150133}],"con":true,"img":false}]}
{"op":"mcm","clk":"11540474456","pt":1719494931017,"mc":[{"id":"1.230180114","rc":[{"atb":[[1.74,0]],"id":61150133}],"con":true,"img":false}]}
{"op":"mcm","clk":"11540474465","pt":1719494931121,"mc":[{"id":"1.230180114","rc":[{"atb":[[1.72,2]],"id":61150133}],"con":true,"img":false}]}
{"op":"mcm","clk":"11540474583","pt":1719494932428,"mc":[{"id":"1.230180114","rc":[{"atb":[[1.72,0]],"id":63387150}],"con":true,"img":false}]}
{"op":"mcm","clk":"11540474611","pt":1719494932739,"mc":[{"id":"1.230180114","rc":[{"atb":[[1.72,1.72]],"id":41804643}],"con":true,"img":false}]}
{"op":"mcm","clk":"11540474631","pt":1719494933006,"mc":[{"id":"1.230180114","rc":[{"atb":[[1.77,1.62]],"id":44213406}],"con":true,"img":false}]}
{"op":"mcm","clk":"11540474656","pt":1719494933317,"mc":[{"id":"1.230180114","rc":[{"atb":[[1.73,1.6]],"id":61150133}],"con":true,"img":false}]}
{"op":"mcm","clk":"11540474743","pt":1719494934294,"mc":[{"id":"1.230180114","rc":[{"atb":[[1.72,0]],"id":61150133}],"con":true,"img":false}]}
{"op":"mcm","clk":"11540474752","pt":1719494934399,"mc":[{"id":"1.230180114","rc":[{"atb":[[1.74,2]],"id":61150133}],"con":true,"img":false}]}
{"op":"mcm","clk":"11540474768","pt":1719494934617,"mc":[{"id":"1.230180114","rc":[{"atb":[[1.76,0]],"id":44213406}],"con":true,"img":false}]}
{"op":"mcm","clk":"11540474775","pt":1719494934720,"mc":[{"id":"1.230180114","rc":[{"atb":[[1.78,2]],"id":44213406}],"con":true,"img":false}]}
{"op":"mcm","clk":"11540474802","pt":1719494935035,"mc":[{"id":"1.230180114","rc":[{"atb":[[1.71,0]],"id":41804643}],"con":true,"img":false}]}
{"op":"mcm","clk":"11540474811","pt":1719494935138,"mc":[{"id":"1.230180114","rc":[{"atb":[[1.73,2]],"id":41804643}],"con":true,"img":false}]}
{"op":"mcm","clk":"11540474829","pt":1719494935350,"mc":[{"id":"1.230180114","rc":[{"atb":[[1.74,1.6]],"id":63387150}],"con":true,"img":false}]}
{"op":"mcm","clk":"11540474849","pt":1719494935556,"mc":[{"id":"1.230180114","rc":[{"atb":[[1.73,0]],"id":63387150}],"con":true,"img":false}]}
{"op":"mcm","clk":"11540474855","pt":1719494935651,"mc":[{"id":"1.230180114","rc":[{"atb":[[1.77,0]],"id":44213406},{"atb":[[1.71,2]],"id":63387150}],"con":true,"img":false}]}
{"op":"mcm","clk":"11540474886","pt":1719494935922,"mc":[{"id":"1.230180114","rc":[{"atb":[[1.73,0]],"id":61150133}],"con":true,"img":false}]}
{"op":"mcm","clk":"11540475049","pt":1719494937837,"mc":[{"id":"1.230180114","rc":[{"atb":[[1.74,0]],"id":61150133}],"con":true,"img":false}]}
{"op":"mcm","clk":"11540475057","pt":1719494937943,"mc":[{"id":"1.230180114","rc":[{"atb":[[1.72,2]],"id":61150133}],"con":true,"img":false}]}
{"op":"mcm","clk":"11540475093","pt":1719494938306,"mc":[{"id":"1.230180114","rc":[{"atb":[[1.78,0]],"id":44213406}],"con":true,"img":false}]}
{"op":"mcm","clk":"11540475099","pt":1719494938406,"mc":[{"id":"1.230180114","rc":[{"atb":[[1.72,0]],"id":41804643},{"atb":[[1.76,2]],"id":44213406}],"con":true,"img":false}]}
{"op":"mcm","clk":"11540475114","pt":1719494938632,"mc":[{"id":"1.230180114","rc":[{"atb":[[1.71,0]],"id":63387150}],"con":true,"img":false}]}
{"op":"mcm","clk":"11540475121","pt":1719494938723,"mc":[{"id":"1.230180114","rc":[{"atb":[[1.79,1.93]],"id":44213406},{"atb":[[1.75,2]],"id":63387150}],"con":true,"img":false}]}
{"op":"mcm","clk":"11540475144","pt":1719494939034,"mc":[{"id":"1.230180114","rc":[{"atb":[[1.72,3.59]],"id":61150133}],"con":true,"img":false}]}
{"op":"mcm","clk":"11540475316","pt":1719494941103,"mc":[{"id":"1.230180114","rc":[{"atb":[[1.76,0]],"id":44213406}],"con":true,"img":false}]}
{"op":"mcm","clk":"11540475327","pt":1719494941208,"mc":[{"id":"1.230180114","rc":[{"atb":[[1.8,2]],"id":44213406}],"con":true,"img":false}]}
{"op":"mcm","clk":"11540475369","pt":1719494941726,"mc":[{"id":"1.230180114","rc":[{"atb":[[1.73,0]],"id":41804643},{"atb":[[1.74,0]],"id":63387150}],"con":true,"img":false}]}
{"op":"mcm","clk":"11540475375","pt":1719494941831,"mc":[{"id":"1.230180114","rc":[{"atb":[[1.71,2]],"id":41804643}],"con":true,"img":false}]}
{"op":"mcm","clk":"11540475395","pt":1719494942043,"mc":[{"id":"1.230180114","rc":[{"atb":[[1.74,1.98]],"id":41804643}],"con":true,"img":false}]}
{"op":"mcm","clk":"11540475545","pt":1719494943718,"mc":[{"id":"1.230180114","rc":[{"atb":[[1.71,0]],"id":41804643}],"con":true,"img":false}]}
{"op":"mcm","clk":"11540475557","pt":1719494943824,"mc":[{"id":"1.230180114","rc":[{"atb":[[1.75,2]],"id":41804643}],"con":true,"img":false}]}
{"op":"mcm","clk":"11540475587","pt":1719494944232,"mc":[{"id":"1.230180114","rc":[{"atb":[[1.75,0]],"id":63387150}],"con":true,"img":false}]}
{"op":"mcm","clk":"11540475595","pt":1719494944347,"mc":[{"id":"1.230180114","rc":[{"atb":[[1.71,2]],"id":63387150}],"con":true,"img":false}]}
{"op":"mcm","clk":"11540475615","pt":1719494944546,"mc":[{"id":"1.230180114","rc":[{"atb":[[1.74,0]],"id":41804643}],"con":true,"img":false}]}
{"op":"mcm","clk":"11540475640","pt":1719494944810,"mc":[{"id":"1.230180114","rc":[{"atb":[[1.79,0]],"id":44213406}],"con":true,"img":false}]}
{"op":"mcm","clk":"11540475775","pt":1719494946436,"mc":[{"id":"1.230180114","rc":[{"atb":[[1.8,0]],"id":44213406}],"con":true,"img":false}]}
{"op":"mcm","clk":"11540475791","pt":1719494946535,"mc":[{"id":"1.230180114","rc":[{"atb":[[1.76,2]],"id":44213406}],"con":true,"img":false}]}
{"op":"mcm","clk":"11540475837","pt":1719494947100,"mc":[{"id":"1.230180114","rc":[{"atb":[[1.75,0]],"id":41804643}],"con":true,"img":false}]}
{"op":"mcm","clk":"11540475846","pt":1719494947211,"mc":[{"id":"1.230180114","rc":[{"atb":[[1.71,2]],"id":41804643},{"spn":75.85,"spf":"NaN","id":41804643},{"spn":75.86,"spf":"NaN","id":61150133},{"spn":75.88,"spf":"NaN","id":44213406}],"con":true,"img":false}]}
{"op":"mcm","clk":"11540475881","pt":1719494947624,"mc":[{"id":"1.230180114","rc":[{"atb":[[1.72,1.76]],"id":63387150}],"con":true,"img":false}]}
{"op":"mcm","clk":"11540475907","pt":1719494947945,"mc":[{"id":"1.230180114","rc":[{"atb":[[1.76,1.51]],"id":41804643}],"con":true,"img":false}]}
{"op":"mcm","clk":"11540475934","pt":1719494948242,"mc":[{"id":"1.230180114","rc":[{"atb":[[1.77,1.61]],"id":44213406}],"con":true,"img":false}]}
{"op":"mcm","clk":"11540476002","pt":1719494949024,"mc":[{"id":"1.230180114","rc":[{"atb":[[1.76,0]],"id":44213406}],"con":true,"img":false}]}
{"op":"mcm","clk":"11540476010","pt":1719494949132,"mc":[{"id":"1.230180114","rc":[{"atb":[[1.78,2]],"id":44213406}],"con":true,"img":false}]}
{"op":"mcm","clk":"11540476035","pt":1719494949438,"mc":[{"id":"1.230180114","rc":[{"atb":[[1.71,0]],"id":41804643}],"con":true,"img":false}]}
{"op":"mcm","clk":"11540476046","pt":1719494949542,"mc":[{"id":"1.230180114","rc":[{"atb":[[1.77,2]],"id":41804643}],"con":true,"img":false}]}
{"op":"mcm","clk":"11540476088","pt":1719494950118,"mc":[{"id":"1.230180114","rc":[{"atb":[[1.71,0]],"id":63387150}],"con":true,"img":false}]}
{"op":"mcm","clk":"11540476092","pt":1719494950222,"mc":[{"id":"1.230180114","rc":[{"atb":[[1.73,2]],"id":63387150}],"con":true,"img":false}]}
{"op":"mcm","clk":"11540476118","pt":1719494950634,"mc":[{"id":"1.230180114","rc":[{"atb":[[1.76,0]],"id":41804643}],"con":true,"img":false}]}
{"op":"mcm","clk":"11540476138","pt":1719494950944,"mc":[{"id":"1.230180114","rc":[{"atb":[[1.77,0]],"id":44213406}],"con":true,"img":false}]}
{"op":"mcm","clk":"11540476243","pt":1719494952423,"mc":[{"id":"1.230180114","rc":[{"atb":[[1.78,0]],"id":44213406}],"con":true,"img":false}]}
{"op":"mcm","clk":"11540476252","pt":1719494952526,"mc":[{"id":"1.230180114","rc":[{"atb":[[1.76,2]],"id":44213406}],"con":true,"img":false}]}
{"op":"mcm","clk":"11540476287","pt":1719494953047,"mc":[{"id":"1.230180114","rc":[{"atb":[[1.77,0]],"id":41804643}],"con":true,"img":false}]}
{"op":"mcm","clk":"11540476291","pt":1719494953147,"mc":[{"id":"1.230180114","rc":[{"atb":[[1.71,2]],"id":41804643}],"con":true,"img":false}]}
{"op":"mcm","clk":"11540476343","pt":1719494953724,"mc":[{"id":"1.230180114","rc":[{"atb":[[1.72,0]],"id":63387150}],"con":true,"img":false}]}
{"op":"mcm","clk":"11540476370","pt":1719494954039,"mc":[{"id":"1.230180114","rc":[{"atb":[[1.78,1.64]],"id":41804643}],"con":true,"img":false}]}
{"op":"mcm","clk":"11540476400","pt":1719494954359,"mc":[{"id":"1.230180114","rc":[{"atb":[[1.77,1.88]],"id":44213406}],"con":true,"img":false}]}
{"op":"mcm","clk":"11540476555","pt":1719494956030,"mc":[{"id":"1.230180114","rc":[{"atb":[[1.76,0]],"id":44213406}],"con":true,"img":false}]}
{"op":"mcm","clk":"11540476567","pt":1719494956129,"mc":[{"id":"1.230180114","rc":[{"atb":[[1.78,2]],"id":44213406}],"con":true,"img":false}]}
{"op":"mcm","clk":"11540476590","pt":1719494956342,"mc":[{"id":"1.230180114","rc":[{"atb":[[1.71,0]],"id":41804643}],"con":true,"img":false}]}
{"op":"mcm","clk":"11540476603","pt":1719494956447,"mc":[{"id":"1.230180114","rc":[{"atb":[[1.79,2]],"id":41804643}],"con":true,"img":false}]}
{"op":"mcm","clk":"11540476627","pt":1719494956655,"mc":[{"id":"1.230180114","rc":[{"atb":[[1.73,0],[1.74,1.77]],"id":63387150}],"con":true,"img":false}]}
{"op":"mcm","clk":"11540476635","pt":1719494956754,"mc":[{"id":"1.230180114","rc":[{"atb":[[1.71,2]],"id":63387150}],"con":true,"img":false}]}
{"op":"mcm","clk":"11540476757","pt":1719494958056,"mc":[{"id":"1.230180114","rc":[{"atb":[[1.71,0]],"id":63387150}],"con":true,"img":false}]}
{"op":"mcm","clk":"11540476762","pt":1719494958160,"mc":[{"id":"1.230180114","rc":[{"atb":[[1.75,2]],"id":63387150}],"con":true,"img":false}]}
{"op":"mcm","clk":"11540476924","pt":1719494960375,"mc":[{"id":"1.230180114","rc":[{"atb":[[1.74,0]],"id":63387150}],"con":true,"img":false}]}
{"op":"mcm","clk":"11540476939","pt":1719494960644,"mc":[{"id":"1.230180114","rc":[{"atb":[[1.78,0]],"id":41804643}],"con":true,"img":false}]}
{"op":"mcm","clk":"11540476968","pt":1719494961055,"mc":[{"id":"1.230180114","rc":[{"atb":[[1.77,0]],"id":44213406}],"con":true,"img":false}]}
{"op":"mcm","clk":"11540477003","pt":1719494961737,"mc":[{"id":"1.230180114","rc":[{"atb":[[1.78,0]],"id":44213406}],"con":true,"img":false}]}
{"op":"mcm","clk":"11540477009","pt":1719494961837,"mc":[{"id":"1.230180114","rc":[{"atb":[[1.76,2]],"id":44213406}],"con":true,"img":false}]}
{"op":"mcm","clk":"11540477036","pt":1719494962253,"mc":[{"id":"1.230180114","rc":[{"atb":[[1.79,0]],"id":41804643}],"con":true,"img":false}]}
{"op":"mcm","clk":"11540477041","pt":1719494962357,"mc":[{"id":"1.230180114","rc":[{"atb":[[1.71,2]],"id":41804643}],"con":true,"img":false}]}
{"op":"mcm","clk":"11540477061","pt":1719494962666,"mc":[{"id":"1.230180114","rc":[{"atb":[[1.75,0]],"id":63387150}],"con":true,"img":false}]}
{"op":"mcm","clk":"11540477068","pt":1719494962770,"mc":[{"id":"1.230180114","rc":[{"atb":[[1.71,2]],"id":63387150}],"con":true,"img":false}]}
{"op":"mcm","clk":"11540477290","pt":1719494965837,"mc":[{"id":"1.230180114","rc":[{"atb":[[1.72,1.64]],"id":63387150}],"con":true,"img":false}]}
{"op":"mcm","clk":"11540477305","pt":1719494966149,"mc":[{"id":"1.230180114","rc":[{"atb":[[1.72,1.81]],"id":41804643}],"con":true,"img":false}]}
{"op":"mcm","clk":"11540477329","pt":1719494966463,"mc":[{"id":"1.230180114","rc":[{"atb":[[1.77,1.98]],"id":44213406}],"con":true,"img":false}]}
{"op":"mcm","clk":"11540477395","pt":1719494967262,"mc":[{"id":"1.230180114","rc":[{"atb":[[1.76,0]],"id":44213406}],"con":true,"img":false}]}
{"op":"mcm","clk":"11540477405","pt":1719494967362,"mc":[{"id":"1.230180114","rc":[{"atb":[[1.78,2]],"id":44213406}],"con":true,"img":false}]}
{"op":"mcm","clk":"11540477433","pt":1719494967670,"mc":[{"id":"1.230180114","rc":[{"atb":[[1.71,0]],"id":41804643}],"con":true,"img":false}]}
{"op":"mcm","clk":"11540477444","pt":1719494967768,"mc":[{"id":"1.230180114","rc":[{"atb":[[1.73,2]],"id":41804643}],"con":true,"img":false}]}
{"op":"mcm","clk":"11540477455","pt":1719494967976,"mc":[{"id":"1.230180114","rc":[{"atb":[[1.71,0]],"id":63387150}],"con":true,"img":false}]}
{"op":"mcm","clk":"11540477462","pt":1719494968080,"mc":[{"id":"1.230180114","rc":[{"atb":[[1.73,2]],"id":63387150}],"con":true,"img":false}]}
{"op":"mcm","clk":"11540477516","pt":1719494968673,"mc":[{"id":"1.230180114","rc":[{"atb":[[1.72,0]],"id":63387150}],"con":true,"img":false}]}
{"op":"mcm","clk":"11540477546","pt":1719494969072,"mc":[{"id":"1.230180114","rc":[{"atb":[[1.72,0]],"id":41804643}],"con":true,"img":false}]}
{"op":"mcm","clk":"11540477565","pt":1719494969513,"mc":[{"id":"1.230180114","rc":[{"atb":[[1.77,0]],"id":44213406}],"con":true,"img":false}]}
{"op":"mcm","clk":"11540477623","pt":1719494970174,"mc":[{"id":"1.230180114","rc":[{"atb":[[1.78,0]],"id":44213406}],"con":true,"img":false}]}
{"op":"mcm","clk":"11540477630","pt":1719494970269,"mc":[{"id":"1.230180114","rc":[{"atb":[[1.76,2]],"id":44213406}],"con":true,"img":false}]}
{"op":"mcm","clk":"11540477672","pt":1719494970781,"mc":[{"id":"1.230180114","rc":[{"atb":[[1.73,0]],"id":41804643}],"con":true,"img":false}]}
{"op":"mcm","clk":"11540477679","pt":1719494970892,"mc":[{"id":"1.230180114","rc":[{"atb":[[1.71,2]],"id":41804643}],"con":true,"img":false}]}
{"op":"mcm","clk":"11540477696","pt":1719494971049,"mc":[{"id":"1.230180114","rc":[{"atb":[[1.73,0]],"id":63387150}],"con":true,"img":false}]}
{"op":"mcm","clk":"11540477705","pt":1719494971162,"mc":[{"id":"1.230180114","rc":[{"atb":[[1.71,2]],"id":63387150}],"con":true,"img":false}]}
{"op":"mcm","clk":"11540477996","pt":1719494974690,"mc":[{"id":"1.230180114","rc":[{"atb":[[1.72,1.73]],"id":63387150}],"con":true,"img":false}]}
{"op":"mcm","clk":"11540478033","pt":1719494974959,"mc":[{"id":"1.230180114","rc":[{"atb":[[1.72,1.89]],"id":41804643}],"con":true,"img":false}]}
{"op":"mcm","clk":"11540478071","pt":1719494975281,"mc":[{"id":"1.230180114","rc":[{"atb":[[1.77,1.99]],"id":44213406}],"con":true,"img":false}]}
{"op":"mcm","clk":"11540478154","pt":1719494976050,"mc":[{"id":"1.230180114","rc":[{"atb":[[1.76,0]],"id":44213406}],"con":true,"img":false}]}
{"op":"mcm","clk":"11540478168","pt":1719494976164,"mc":[{"id":"1.230180114","rc":[{"atb":[[1.78,2]],"id":44213406}],"con":true,"img":false}]}
{"op":"mcm","clk":"11540478211","pt":1719494976683,"mc":[{"id":"1.230180114","rc":[{"atb":[[1.71,0]],"id":41804643}],"con":true,"img":false}]}
{"op":"mcm","clk":"11540478216","pt":1719494976781,"mc":[{"id":"1.230180114","rc":[{"atb":[[1.73,2]],"id":41804643}],"con":true,"img":false}]}
{"op":"mcm","clk":"11540478246","pt":1719494977086,"mc":[{"id":"1.230180114","rc":[{"atb":[[1.71,0]],"id":63387150}],"con":true,"img":false}]}
{"op":"mcm","clk":"11540478257","pt":1719494977193,"mc":[{"id":"1.230180114","rc":[{"atb":[[1.73,2]],"id":63387150}],"con":true,"img":false}]}
{"op":"mcm","clk":"11540478293","pt":1719494977763,"mc":[{"id":"1.230180114","rc":[{"atb":[[1.72,0]],"id":63387150}],"con":true,"img":false}]}
{"op":"mcm","clk":"11540478320","pt":1719494978084,"mc":[{"id":"1.230180114","rc":[{"atb":[[1.72,0]],"id":41804643}],"con":true,"img":false}]}
{"op":"mcm","clk":"11540478352","pt":1719494978491,"mc":[{"id":"1.230180114","rc":[{"atb":[[1.77,0]],"id":44213406}],"con":true,"img":false}]}
{"op":"mcm","clk":"11540478464","pt":1719494979991,"mc":[{"id":"1.230180114","rc":[{"atb":[[1.78,0]],"id":44213406}],"con":true,"img":false}]}
{"op":"mcm","clk":"11540478470","pt":1719494980090,"mc":[{"id":"1.230180114","rc":[{"atb":[[1.76,2]],"id":44213406}],"con":true,"img":false}]}
{"op":"mcm","clk":"11540478492","pt":1719494980355,"mc":[{"id":"1.230180114","rc":[{"atb":[[1.73,0]],"id":41804643}],"con":true,"img":false}]}
{"op":"mcm","clk":"11540478498","pt":1719494980465,"mc":[{"id":"1.230180114","rc":[{"atb":[[1.71,2]],"id":41804643}],"con":true,"img":false}]}
{"op":"mcm","clk":"11540478536","pt":1719494980881,"mc":[{"id":"1.230180114","rc":[{"atb":[[1.73,0]],"id":63387150}],"con":true,"img":false}]}
{"op":"mcm","clk":"11540478546","pt":1719494980986,"mc":[{"id":"1.230180114","rc":[{"atb":[[1.71,2]],"id":63387150}],"con":true,"img":false}]}
{"op":"mcm","clk":"11540478776","pt":1719494983796,"mc":[{"id":"1.230180114","rc":[{"atb":[[1.72,1.53]],"id":63387150}],"con":true,"img":false}]}
{"op":"mcm","clk":"11540478797","pt":1719494984054,"mc":[{"id":"1.230180114","rc":[{"atb":[[1.72,1.6]],"id":41804643}],"con":true,"img":false}]}
{"op":"mcm","clk":"11540478829","pt":1719494984372,"mc":[{"id":"1.230180114","rc":[{"atb":[[1.77,1.71]],"id":44213406}],"con":true,"img":false}]}
{"op":"mcm","clk":"11540478906","pt":1719494985457,"mc":[{"id":"1.230180114","rc":[{"atb":[[1.76,0]],"id":44213406}],"con":true,"img":false}]}
{"op":"mcm","clk":"11540478918","pt":1719494985566,"mc":[{"id":"1.230180114","rc":[{"atb":[[1.78,2]],"id":44213406}],"con":true,"img":false}]}
{"op":"mcm","clk":"11540478945","pt":1719494985871,"mc":[{"id":"1.230180114","rc":[{"atb":[[1.71,0]],"id":41804643}],"con":true,"img":false}]}
{"op":"mcm","clk":"11540478954","pt":1719494985973,"mc":[{"id":"1.230180114","rc":[{"atb":[[1.73,2]],"id":41804643}],"con":true,"img":false}]}
{"op":"mcm","clk":"11540478998","pt":1719494986592,"mc":[{"id":"1.230180114","rc":[{"atb":[[1.71,0]],"id":63387150}],"con":true,"img":false}]}
{"op":"mcm","clk":"11540479006","pt":1719494986697,"mc":[{"id":"1.230180114","rc":[{"atb":[[1.73,2]],"id":63387150}],"con":true,"img":false}]}
{"op":"mcm","clk":"11540479020","pt":1719494986918,"mc":[{"id":"1.230180114","rc":[{"atb":[[1.72,0]],"id":41804643}],"con":true,"img":false}]}
{"op":"mcm","clk":"11540479049","pt":1719494987174,"mc":[{"id":"1.230180114","rc":[{"atb":[[1.77,0]],"id":44213406}],"con":true,"img":false}]}
{"op":"mcm","clk":"11540479251","pt":1719494988759,"mc":[{"id":"1.230180114","rc":[{"atb":[[1.78,0]],"id":44213406}],"con":true,"img":false}]}
{"op":"mcm","clk":"11540479260","pt":1719494988858,"mc":[{"id":"1.230180114","rc":[{"atb":[[1.76,2]],"id":44213406}],"con":true,"img":false}]}
{"op":"mcm","clk":"11540479301","pt":1719494989275,"mc":[{"id":"1.230180114","rc":[{"atb":[[1.73,0]],"id":41804643}],"con":true,"img":false}]}
{"op":"mcm","clk":"11540479310","pt":1719494989379,"mc":[{"id":"1.230180114","rc":[{"atb":[[1.71,2]],"id":41804643}],"con":true,"img":false}]}
{"op":"mcm","clk":"11540479421","pt":1719494990466,"mc":[{"id":"1.230180114","rc":[{"atb":[[1.72,0]],"id":63387150}],"con":true,"img":false}]}
{"op":"mcm","clk":"11540479442","pt":1719494990779,"mc":[{"id":"1.230180114","rc":[{"atb":[[1.71,3.71]],"id":41804643}],"con":true,"img":false}]}
{"op":"mcm","clk":"11540479469","pt":1719494991087,"mc":[{"id":"1.230180114","rc":[{"atb":[[1.77,1.56]],"id":44213406}],"con":true,"img":false}]}
{"op":"mcm","clk":"11540479680","pt":1719494993587,"mc":[{"id":"1.230180114","rc":[{"atb":[[1.74,1.51]],"id":63387150}],"con":true,"img":false}]}
{"op":"mcm","clk":"11540479688","pt":1719494993687,"mc":[{"id":"1.230180114","rc":[{"atb":[[1.76,0]],"id":44213406}],"con":true,"img":false}]}
{"op":"mcm","clk":"11540479694","pt":1719494993798,"mc":[{"id":"1.230180114","rc":[{"atb":[[1.78,2]],"id":44213406}],"con":true,"img":false}]}
{"op":"mcm","clk":"11540479750","pt":1719494994364,"mc":[{"id":"1.230180114","rc":[{"atb":[[1.73,0]],"id":63387150}],"con":true,"img":false}]}
{"op":"mcm","clk":"11540479758","pt":1719494994469,"mc":[{"id":"1.230180114","rc":[{"atb":[[1.71,2]],"id":63387150}],"con":true,"img":false}]}
{"op":"mcm","clk":"11540479880","pt":1719494995769,"mc":[{"id":"1.230180114","rc":[{"atb":[[1.77,0]],"id":44213406}],"con":true,"img":false}]}
{"op":"mcm","clk":"11540480019","pt":1719494997382,"mc":[{"id":"1.230180114","rc":[{"atb":[[1.78,0]],"id":44213406}],"con":true,"img":false}]}
{"op":"mcm","clk":"11540480029","pt":1719494997481,"mc":[{"id":"1.230180114","rc":[{"atb":[[1.76,2]],"id":44213406}],"con":true,"img":false}]}
{"op":"mcm","clk":"11540480054","pt":1719494997795,"mc":[{"id":"1.230180114","rc":[{"atb":[[1.71,0]],"id":63387150}],"con":true,"img":false}]}
{"op":"mcm","clk":"11540480067","pt":1719494997909,"mc":[{"id":"1.230180114","rc":[{"atb":[[1.75,2]],"id":63387150}],"con":true,"img":false}]}
{"op":"mcm","clk":"11540480135","pt":1719494998784,"mc":[{"id":"1.230180114","rc":[{"atb":[[1.74,0]],"id":63387150}],"con":true,"img":false}]}
{"op":"mcm","clk":"11540480161","pt":1719494999091,"mc":[{"id":"1.230180114","rc":[{"atb":[[1.77,1.62]],"id":44213406}],"con":true,"img":false}]}
{"op":"mcm","clk":"11540480258","pt":1719495000501,"mc":[{"id":"1.230180114","rc":[{"atb":[[1.76,0]],"id":44213406}],"con":true,"img":false}]}
{"op":"mcm","clk":"11540480262","pt":1719495000605,"mc":[{"id":"1.230180114","rc":[{"atb":[[1.78,2]],"id":44213406}],"con":true,"img":false}]}
{"op":"mcm","clk":"11540480304","pt":1719495000972,"mc":[{"id":"1.230180114","rc":[{"atb":[[1.75,0]],"id":63387150}],"con":true,"img":false}]}
{"op":"mcm","clk":"11540480311","pt":1719495001101,"mc":[{"id":"1.230180114","rc":[{"atb":[[1.71,2]],"id":63387150}],"con":true,"img":false}]}
{"op":"mcm","clk":"11540480386","pt":1719495001783,"mc":[{"id":"1.230180114","rc":[{"atb":[[1.72,1.59]],"id":63387150}],"con":true,"img":false}]}
{"op":"mcm","clk":"11540480411","pt":1719495002097,"mc":[{"id":"1.230180114","rc":[{"atb":[[1.77,0]],"id":44213406}],"con":true,"img":false}]}
{"op":"mcm","clk":"11540480558","pt":1719495003604,"mc":[{"id":"1.230180114","rc":[{"atb":[[1.78,0]],"id":44213406}],"con":true,"img":false}]}
{"op":"mcm","clk":"11540480568","pt":1719495003707,"mc":[{"id":"1.230180114","rc":[{"atb":[[1.76,2]],"id":44213406}],"con":true,"img":false}]}
{"op":"mcm","clk":"11540480614","pt":1719495004072,"mc":[{"id":"1.230180114","rc":[{"atb":[[1.71,0]],"id":63387150}],"con":true,"img":false}]}
{"op":"mcm","clk":"11540480623","pt":1719495004177,"mc":[{"id":"1.230180114","rc":[{"atb":[[1.73,2]],"id":63387150}],"con":true,"img":false}]}
{"op":"mcm","clk":"11540480680","pt":1719495004905,"mc":[{"id":"1.230180114","rc":[{"atb":[[1.72,0]],"id":63387150}],"con":true,"img":false}]}
{"op":"mcm","clk":"11540480706","pt":1719495005218,"mc":[{"id":"1.230180114","rc":[{"atb":[[1.77,1.64]],"id":44213406}],"con":true,"img":false}]}
{"op":"mcm","clk":"11540480842","pt":1719495006989,"mc":[{"id":"1.230180114","rc":[{"atb":[[1.76,0]],"id":44213406}],"con":true,"img":false}]}
{"op":"mcm","clk":"11540480857","pt":1719495007092,"mc":[{"id":"1.230180114","rc":[{"atb":[[1.78,2]],"id":44213406}],"con":true,"img":false}]}
{"op":"mcm","clk":"11540480873","pt":1719495007299,"mc":[{"id":"1.230180114","rc":[{"spn":75.89,"spf":"NaN","id":44213406},{"atb":[[1.73,0]],"id":63387150},{"spn":75.85,"spf":"NaN","id":63387150}],"con":true,"img":false}]}
{"op":"mcm","clk":"11540480884","pt":1719495007402,"mc":[{"id":"1.230180114","rc":[{"atb":[[1.71,2]],"id":63387150}],"con":true,"img":false}]}
{"op":"mcm","clk":"11540480924","pt":1719495007811,"mc":[{"id":"1.230180114","rc":[{"atb":[[1.71,3.62]],"id":63387150}],"con":true,"img":false}]}
{"op":"mcm","clk":"11540480956","pt":1719495008070,"mc":[{"id":"1.230180114","rc":[{"atb":[[1.77,0]],"id":44213406}],"con":true,"img":false}]}
{"op":"mcm","clk":"11540481077","pt":1719495009424,"mc":[{"id":"1.230180114","rc":[{"atb":[[1.78,0]],"id":44213406}],"con":true,"img":false}]}
{"op":"mcm","clk":"11540481084","pt":1719495009531,"mc":[{"id":"1.230180114","rc":[{"atb":[[1.76,2]],"id":44213406}],"con":true,"img":false}]}
{"op":"mcm","clk":"11540481433","pt":1719495013918,"mc":[{"id":"1.230180114","rc":[{"atb":[[1.77,1.6]],"id":44213406}],"con":true,"img":false}]}
{"op":"mcm","clk":"11540481525","pt":1719495014907,"mc":[{"id":"1.230180114","rc":[{"atb":[[1.76,0]],"id":44213406}],"con":true,"img":false}]}
{"op":"mcm","clk":"11540481535","pt":1719495015004,"mc":[{"id":"1.230180114","rc":[{"atb":[[1.78,2]],"id":44213406}],"con":true,"img":false}]}
{"op":"mcm","clk":"11540481706","pt":1719495017024,"mc":[{"id":"1.230180114","rc":[{"atb":[[1.77,0]],"id":44213406}],"con":true,"img":false}]}
{"op":"mcm","clk":"11540481772","pt":1719495017800,"mc":[{"id":"1.230180114","rc":[{"atb":[[1.78,0]],"id":44213406}],"con":true,"img":false}]}
{"op":"mcm","clk":"11540481784","pt":1719495017904,"mc":[{"id":"1.230180114","rc":[{"atb":[[1.76,2]],"id":44213406}],"con":true,"img":false}]}
{"op":"mcm","clk":"11540481938","pt":1719495019931,"mc":[{"id":"1.230180114","rc":[{"atb":[[1.77,1.85]],"id":44213406}],"con":true,"img":false}]}
{"op":"mcm","clk":"11540482046","pt":1719495021638,"mc":[{"id":"1.230180114","rc":[{"atb":[[1.76,0]],"id":44213406}],"con":true,"img":false}]}
{"op":"mcm","clk":"11540482054","pt":1719495021747,"mc":[{"id":"1.230180114","rc":[{"atb":[[1.78,2]],"id":44213406}],"con":true,"img":false}]}
{"op":"mcm","clk":"11540482162","pt":1719495023056,"mc":[{"id":"1.230180114","rc":[{"atb":[[1.77,0]],"id":44213406}],"con":true,"img":false}]}
{"op":"mcm","clk":"11540482232","pt":1719495023942,"mc":[{"id":"1.230180114","rc":[{"atb":[[1.78,0]],"id":44213406}],"con":true,"img":false}]}
{"op":"mcm","clk":"11540482243","pt":1719495024050,"mc":[{"id":"1.230180114","rc":[{"atb":[[1.76,2]],"id":44213406}],"con":true,"img":false}]}
{"op":"mcm","clk":"11540482390","pt":1719495026040,"mc":[{"id":"1.230180114","rc":[{"atb":[[1.77,1.95]],"id":44213406}],"con":true,"img":false}]}
{"op":"mcm","clk":"11540482521","pt":1719495027746,"mc":[{"id":"1.230180114","rc":[{"atb":[[1.76,0]],"id":44213406}],"con":true,"img":false}]}
{"op":"mcm","clk":"11540482534","pt":1719495027855,"mc":[{"id":"1.230180114","rc":[{"atb":[[1.78,2]],"id":44213406}],"con":true,"img":false}]}
{"op":"mcm","clk":"11540482659","pt":1719495029141,"mc":[{"id":"1.230180114","rc":[{"atb":[[1.77,0]],"id":44213406}],"con":true,"img":false}]}
{"op":"mcm","clk":"11540482730","pt":1719495030026,"mc":[{"id":"1.230180114","rc":[{"atb":[[1.78,0]],"id":44213406}],"con":true,"img":false}]}
{"op":"mcm","clk":"11540482738","pt":1719495030130,"mc":[{"id":"1.230180114","rc":[{"atb":[[1.76,2]],"id":44213406}],"con":true,"img":false}]}
{"op":"mcm","clk":"11540482894","pt":1719495032059,"mc":[{"id":"1.230180114","rc":[{"atb":[[1.77,1.77]],"id":44213406}],"con":true,"img":false}]}
{"op":"mcm","clk":"11540483075","pt":1719495034346,"mc":[{"id":"1.230180114","rc":[{"atb":[[1.76,0]],"id":44213406}],"con":true,"img":false}]}
{"op":"mcm","clk":"11540483082","pt":1719495034445,"mc":[{"id":"1.230180114","rc":[{"atb":[[1.78,2]],"id":44213406}],"con":true,"img":false}]}
{"op":"mcm","clk":"11540483133","pt":1719495035167,"mc":[{"id":"1.230180114","rc":[{"atb":[[1.77,0]],"id":44213406}],"con":true,"img":false}]}
{"op":"mcm","clk":"11540483268","pt":1719495036526,"mc":[{"id":"1.230180114","rc":[{"atb":[[1.78,0]],"id":44213406}],"con":true,"img":false}]}
{"op":"mcm","clk":"11540483280","pt":1719495036630,"mc":[{"id":"1.230180114","rc":[{"atb":[[1.76,2]],"id":44213406}],"con":true,"img":false}]}
{"op":"mcm","clk":"11540483664","pt":1719495041176,"mc":[{"id":"1.230180114","rc":[{"atb":[[1.77,1.96]],"id":44213406}],"con":true,"img":false}]}
{"op":"mcm","clk":"11540483831","pt":1719495043162,"mc":[{"id":"1.230180114","rc":[{"atb":[[1.76,0]],"id":44213406}],"con":true,"img":false}]}
{"op":"mcm","clk":"11540483839","pt":1719495043258,"mc":[{"id":"1.230180114","rc":[{"atb":[[1.78,2]],"id":44213406}],"con":true,"img":false}]}
{"op":"mcm","clk":"11540483920","pt":1719495044143,"mc":[{"id":"1.230180114","rc":[{"atb":[[1.77,0]],"id":44213406}],"con":true,"img":false}]}
{"op":"mcm","clk":"11540484054","pt":1719495045645,"mc":[{"id":"1.230180114","rc":[{"atb":[[1.78,0]],"id":44213406}],"con":true,"img":false}]}
{"op":"mcm","clk":"11540484062","pt":1719495045746,"mc":[{"id":"1.230180114","rc":[{"atb":[[1.76,2]],"id":44213406}],"con":true,"img":false}]}
{"op":"mcm","clk":"11540484195","pt":1719495047147,"mc":[{"id":"1.230180114","rc":[{"atb":[[1.77,1.6]],"id":44213406}],"con":true,"img":false}]}
{"op":"mcm","clk":"11540484268","pt":1719495047981,"mc":[{"id":"1.230180114","rc":[{"atb":[[1.76,0]],"id":44213406}],"con":true,"img":false}]}
{"op":"mcm","clk":"11540484279","pt":1719495048094,"mc":[{"id":"1.230180114","rc":[{"atb":[[1.78,2]],"id":44213406}],"con":true,"img":false}]}
{"op":"mcm","clk":"11540484449","pt":1719495050151,"mc":[{"id":"1.230180114","rc":[{"atb":[[1.77,0]],"id":44213406}],"con":true,"img":false}]}
{"op":"mcm","clk":"11540484514","pt":1719495050875,"mc":[{"id":"1.230180114","rc":[{"atb":[[1.78,0]],"id":44213406}],"con":true,"img":false}]}
{"op":"mcm","clk":"11540484526","pt":1719495050972,"mc":[{"id":"1.230180114","rc":[{"atb":[[1.76,2]],"id":44213406}],"con":true,"img":false}]}
{"op":"mcm","clk":"11540484774","pt":1719495053164,"mc":[{"id":"1.230180114","rc":[{"atb":[[1.77,1.68]],"id":44213406}],"con":true,"img":false}]}
{"op":"mcm","clk":"11540485021","pt":1719495055653,"mc":[{"id":"1.230180114","rc":[{"atb":[[1.76,0]],"id":44213406}],"con":true,"img":false}]}
{"op":"mcm","clk":"11540485030","pt":1719495055762,"mc":[{"id":"1.230180114","rc":[{"atb":[[1.78,2]],"id":44213406}],"con":true,"img":false}]}
{"op":"mcm","clk":"11540485344","pt":1719495059384,"mc":[{"id":"1.230180114","rc":[{"atb":[[1.77,0]],"id":44213406}],"con":true,"img":false}]}
{"op":"mcm","clk":"11540485493","pt":1719495060987,"mc":[{"id":"1.230180114","rc":[{"atb":[[1.78,0]],"id":44213406}],"con":true,"img":false}]}
{"op":"mcm","clk":"11540485502","pt":1719495061091,"mc":[{"id":"1.230180114","rc":[{"atb":[[1.76,2]],"id":44213406}],"con":true,"img":false}]}
{"op":"mcm","clk":"11540485940","pt":1719495065187,"mc":[{"id":"1.230180114","rc":[{"atb":[[1.77,1.58]],"id":44213406}],"con":true,"img":false}]}
{"op":"mcm","clk":"11540486015","pt":1719495066009,"mc":[{"id":"1.230180114","rc":[{"atb":[[1.76,0]],"id":44213406}],"con":true,"img":false}]}
{"op":"mcm","clk":"11540486028","pt":1719495066106,"mc":[{"id":"1.230180114","rc":[{"atb":[[1.78,2]],"id":44213406}],"con":true,"img":false}]}
{"op":"mcm","clk":"11540486250","pt":1719495068331,"mc":[{"id":"1.230180114","rc":[{"atb":[[1.77,0]],"id":44213406},{"spn":75.85,"spf":"NaN","id":63387150}],"con":true,"img":false}]}
{"op":"mcm","clk":"11540486385","pt":1719495070033,"mc":[{"id":"1.230180114","rc":[{"atb":[[1.78,0]],"id":44213406}],"con":true,"img":false}]}
{"op":"mcm","clk":"11540486394","pt":1719495070092,"mc":[{"id":"1.230180114","rc":[{"atb":[[1.76,2]],"id":44213406}],"con":true,"img":false}]}
{"op":"mcm","clk":"11540486510","pt":1719495071325,"mc":[{"id":"1.230180114","rc":[{"atb":[[1.77,1.89]],"id":44213406}],"con":true,"img":false}]}
{"op":"mcm","clk":"11540486649","pt":1719495073093,"mc":[{"id":"1.230180114","rc":[{"atb":[[1.76,0]],"id":44213406}],"con":true,"img":false}]}
{"op":"mcm","clk":"11540486660","pt":1719495073191,"mc":[{"id":"1.230180114","rc":[{"atb":[[1.78,2]],"id":44213406}],"con":true,"img":false}]}
{"op":"mcm","clk":"11540486773","pt":1719495074331,"mc":[{"id":"1.230180114","rc":[{"atb":[[1.77,0]],"id":44213406}],"con":true,"img":false}]}
{"op":"mcm","clk":"11540486938","pt":1719495076142,"mc":[{"id":"1.230180114","rc":[{"atb":[[1.78,0]],"id":44213406}],"con":true,"img":false}]}
{"op":"mcm","clk":"11540486946","pt":1719495076197,"mc":[{"id":"1.230180114","rc":[{"atb":[[1.76,2]],"id":44213406}],"con":true,"img":false}]}
{"op":"mcm","clk":"11540487035","pt":1719495077331,"mc":[{"id":"1.230180114","rc":[{"atb":[[1.77,1.65]],"id":44213406}],"con":true,"img":false}]}
{"op":"mcm","clk":"11540487131","pt":1719495078524,"mc":[{"id":"1.230180114","rc":[{"atb":[[1.76,0]],"id":44213406}],"con":true,"img":false}]}
{"op":"mcm","clk":"11540487141","pt":1719495078629,"mc":[{"id":"1.230180114","rc":[{"atb":[[1.78,2]],"id":44213406}],"con":true,"img":false}]}
{"op":"mcm","clk":"11540487287","pt":1719495080743,"mc":[{"id":"1.230180114","rc":[{"atb":[[1.77,0]],"id":44213406}],"con":true,"img":false}]}
{"op":"mcm","clk":"11540487349","pt":1719495081321,"mc":[{"id":"1.230180114","rc":[{"atb":[[1.78,0]],"id":44213406}],"con":true,"img":false}]}
{"op":"mcm","clk":"11540487358","pt":1719495081417,"mc":[{"id":"1.230180114","rc":[{"atb":[[1.76,2]],"id":44213406}],"con":true,"img":false}]}
{"op":"mcm","clk":"11540487533","pt":1719495083647,"mc":[{"id":"1.230180114","rc":[{"atb":[[1.77,1.56]],"id":44213406}],"con":true,"img":false}]}
{"op":"mcm","clk":"11540487743","pt":1719495085920,"mc":[{"id":"1.230180114","rc":[{"atb":[[1.76,0]],"id":44213406}],"con":true,"img":false}]}
{"op":"mcm","clk":"11540487755","pt":1719495086023,"mc":[{"id":"1.230180114","rc":[{"atb":[[1.78,2]],"id":44213406}],"con":true,"img":false}]}
{"op":"mcm","clk":"11540488098","pt":1719495089462,"mc":[{"id":"1.230180114","rc":[{"atb":[[1.77,0]],"id":44213406}],"con":true,"img":false}]}
{"op":"mcm","clk":"11540488185","pt":1719495090438,"mc":[{"id":"1.230180114","rc":[{"atb":[[1.78,0]],"id":44213406}],"con":true,"img":false}]}
{"op":"mcm","clk":"11540488191","pt":1719495090547,"mc":[{"id":"1.230180114","rc":[{"atb":[[1.76,2]],"id":44213406}],"con":true,"img":false}]}
{"op":"mcm","clk":"11540488628","pt":1719495095572,"mc":[{"id":"1.230180114","rc":[{"atb":[[1.77,1.88]],"id":44213406}],"con":true,"img":false}]}
{"op":"mcm","clk":"11540488767","pt":1719495097032,"mc":[{"id":"1.230180114","rc":[{"atb":[[1.76,0]],"id":44213406}],"con":true,"img":false}]}
{"op":"mcm","clk":"11540488780","pt":1719495097128,"mc":[{"id":"1.230180114","rc":[{"atb":[[1.78,2]],"id":44213406}],"con":true,"img":false}]}
{"op":"mcm","clk":"11540488900","pt":1719495098573,"mc":[{"id":"1.230180114","rc":[{"atb":[[1.77,0]],"id":44213406}],"con":true,"img":false}]}
{"op":"mcm","clk":"11540488986","pt":1719495099556,"mc":[{"id":"1.230180114","rc":[{"atb":[[1.78,0]],"id":44213406}],"con":true,"img":false}]}
{"op":"mcm","clk":"11540488998","pt":1719495099666,"mc":[{"id":"1.230180114","rc":[{"atb":[[1.76,2]],"id":44213406}],"con":true,"img":false}]}
{"op":"mcm","clk":"11540489187","pt":1719495101836,"mc":[{"id":"1.230180114","rc":[{"atb":[[1.77,1.59]],"id":44213406}],"con":true,"img":false}]}
{"op":"mcm","clk":"11540489317","pt":1719495103135,"mc":[{"id":"1.230180114","rc":[{"atb":[[1.76,0]],"id":44213406}],"con":true,"img":false}]}
{"op":"mcm","clk":"11540489323","pt":1719495103239,"mc":[{"id":"1.230180114","rc":[{"atb":[[1.78,2]],"id":44213406}],"con":true,"img":false}]}
{"op":"mcm","clk":"11540489448","pt":1719495104747,"mc":[{"id":"1.230180114","rc":[{"atb":[[1.77,0]],"id":44213406}],"con":true,"img":false}]}
{"op":"mcm","clk":"11540489509","pt":1719495105471,"mc":[{"id":"1.230180114","rc":[{"atb":[[1.78,0]],"id":44213406}],"con":true,"img":false}]}
{"op":"mcm","clk":"11540489520","pt":1719495105568,"mc":[{"id":"1.230180114","rc":[{"atb":[[1.76,2]],"id":44213406}],"con":true,"img":false}]}
{"op":"mcm","clk":"11540489670","pt":1719495107074,"mc":[{"id":"1.230180114","rc":[{"spl":[[1.01,5]],"id":39682601}],"con":true,"img":false}]}
{"op":"mcm","clk":"11540490025","pt":1719495110687,"mc":[{"id":"1.230180114","rc":[{"atb":[[1.77,1.72]],"id":44213406}],"con":true,"img":false}]}
{"op":"mcm","clk":"11540490193","pt":1719495112655,"mc":[{"id":"1.230180114","rc":[{"atb":[[1.76,0]],"id":44213406}],"con":true,"img":false}]}
{"op":"mcm","clk":"11540490203","pt":1719495112762,"mc":[{"id":"1.230180114","rc":[{"atb":[[1.78,2]],"id":44213406}],"con":true,"img":false}]}
{"op":"mcm","clk":"11540490267","pt":1719495113592,"mc":[{"id":"1.230180114","rc":[{"atb":[[1.77,0]],"id":44213406}],"con":true,"img":false}]}
{"op":"mcm","clk":"11540490428","pt":1719495115054,"mc":[{"id":"1.230180114","rc":[{"atb":[[1.78,0]],"id":44213406}],"con":true,"img":false}]}
{"op":"mcm","clk":"11540490441","pt":1719495115155,"mc":[{"id":"1.230180114","rc":[{"atb":[[1.76,2]],"id":44213406}],"con":true,"img":false}]}
{"op":"mcm","clk":"11540490585","pt":1719495116553,"mc":[{"id":"1.230180114","rc":[{"atb":[[1.77,1.94]],"id":44213406}],"con":true,"img":false}]}
{"op":"mcm","clk":"11540490635","pt":1719495117169,"mc":[{"id":"1.230180114","rc":[{"atb":[[1.76,0]],"id":44213406}],"con":true,"img":false}]}
{"op":"mcm","clk":"11540490643","pt":1719495117274,"mc":[{"id":"1.230180114","rc":[{"atb":[[1.78,2]],"id":44213406}],"con":true,"img":false}]}
{"op":"mcm","clk":"11540490879","pt":1719495119654,"mc":[{"id":"1.230180114","rc":[{"atb":[[1.77,0]],"id":44213406}],"con":true,"img":false}]}
{"op":"mcm","clk":"11540491029","pt":1719495121159,"mc":[{"id":"1.230180114","rc":[{"atb":[[1.78,0]],"id":44213406}],"con":true,"img":false}]}
{"op":"mcm","clk":"11540491037","pt":1719495121265,"mc":[{"id":"1.230180114","rc":[{"atb":[[1.76,2]],"id":44213406}],"con":true,"img":false}]}
{"op":"mcm","clk":"11540491049","pt":1719495121363,"mc":[{"id":"1.230180114","rc":[{"spl":[[1.01,4]],"id":41804643}],"con":true,"img":false}]}
{"op":"mcm","clk":"11540491186","pt":1719495122557,"mc":[{"id":"1.230180114","rc":[{"atb":[[1.77,1.53]],"id":44213406}],"con":true,"img":false}]}
{"op":"mcm","clk":"11540491239","pt":1719495123178,"mc":[{"id":"1.230180114","rc":[{"atb":[[1.78,1.28]],"id":44213406},{"atl":[[1000,0.01]],"id":44213406}],"con":true,"img":false}]}
{"op":"mcm","clk":"11540491249","pt":1719495123282,"mc":[{"id":"1.230180114","rc":[{"atb":[[1.76,0]],"id":44213406}],"con":true,"img":false}]}
{"op":"mcm","clk":"11540491257","pt":1719495123383,"mc":[{"id":"1.230180114","rc":[{"atb":[[1.78,3.28]],"id":44213406}],"con":true,"img":false}]}
{"op":"mcm","clk":"11540491281","pt":1719495123594,"mc":[{"id":"1.230180114","rc":[{"atl":[[1000,0]],"id":44213406}],"con":true,"img":false}]}
{"op":"mcm","clk":"11540491289","pt":1719495123694,"mc":[{"id":"1.230180114","rc":[{"atl":[[140,0.01]],"id":44213406}],"con":true,"img":false}]}
{"op":"mcm","clk":"11540491304","pt":1719495123905,"mc":[{"id":"1.230180114","rc":[{"atl":[[140,20.01],[150,10.8]],"id":44213406}],"con":true,"img":false}]}
{"op":"mcm","clk":"11540491324","pt":1719495124107,"mc":[{"id":"1.230180114","rc":[{"atl":[[150,9.1]],"id":44213406}],"con":true,"img":false}]}
{"op":"mcm","clk":"11540491337","pt":1719495124165,"mc":[{"id":"1.230180114","rc":[{"atl":[[130,1.7]],"id":44213406}],"con":true,"img":false}]}
{"op":"mcm","clk":"11540491343","pt":1719495124262,"mc":[{"id":"1.230180114","rc":[{"atl":[[130,21.7],[140,0.01]],"id":44213406}],"con":true,"img":false}]}
{"op":"mcm","clk":"11540491362","pt":1719495124474,"mc":[{"id":"1.230180114","rc":[{"atl":[[130,20]],"id":44213406}],"con":true,"img":false}]}
{"op":"mcm","clk":"11540491378","pt":1719495124579,"mc":[{"id":"1.230180114","rc":[{"atl":[[150,10.8]],"id":44213406}],"con":true,"img":false}]}
{"op":"mcm","clk":"11540491398","pt":1719495124784,"mc":[{"id":"1.230180114","rc":[{"atl":[[150,9.1]],"id":44213406}],"con":true,"img":false}]}
{"op":"mcm","clk":"11540491403","pt":1719495124882,"mc":[{"id":"1.230180114","rc":[{"atl":[[120,1.7]],"id":44213406}],"con":true,"img":false}]}
{"op":"mcm","clk":"11540491414","pt":1719495124986,"mc":[{"id":"1.230180114","rc":[{"atl":[[120,21.7]],"id":44213406}],"con":true,"img":false}]}
{"op":"mcm","clk":"11540491429","pt":1719495125089,"mc":[{"id":"1.230180114","rc":[{"atl":[[130,0]],"id":44213406}],"con":true,"img":false}]}
{"op":"mcm","clk":"11540491445","pt":1719495125301,"mc":[{"id":"1.230180114","rc":[{"atl":[[120,20]],"id":44213406}],"con":true,"img":false}]}
{"op":"mcm","clk":"11540491454","pt":1719495125400,"mc":[{"id":"1.230180114","rc":[{"atl":[[150,10.8]],"id":44213406}],"con":true,"img":false}]}
{"op":"mcm","clk":"11540491462","pt":1719495125503,"mc":[{"id":"1.230180114","rc":[{"atl":[[150,9.1]],"id":44213406}],"con":true,"img":false}]}
{"op":"mcm","clk":"11540491473","pt":1719495125558,"mc":[{"id":"1.230180114","rc":[{"atb":[[1.77,0]],"id":44213406},{"atl":[[110,1.7]],"id":44213406}],"con":true,"img":false}]}
{"op":"mcm","clk":"11540491480","pt":1719495125663,"mc":[{"id":"1.230180114","rc":[{"atl":[[110,21.7]],"id":44213406}],"con":true,"img":false}]}
{"op":"mcm","clk":"11540491488","pt":1719495125764,"mc":[{"id":"1.230180114","rc":[{"atl":[[120,0]],"id":44213406}],"con":true,"img":false}]}
{"op":"mcm","clk":"11540491503","pt":1719495125992,"mc":[{"id":"1.230180114","rc":[{"atl":[[110,20]],"id":44213406}],"con":true,"img":false}]}
{"op":"mcm","clk":"11540491510","pt":1719495126074,"mc":[{"id":"1.230180114","rc":[{"atl":[[150,10.8]],"id":44213406}],"con":true,"img":false}]}
{"op":"mcm","clk":"11540491528","pt":1719495126279,"mc":[{"id":"1.230180114","rc":[{"atl":[[150,9.1]],"id":44213406}],"con":true,"img":false}]}
{"op":"mcm","clk":"11540491539","pt":1719495126384,"mc":[{"id":"1.230180114","rc":[{"atl":[[100,1.7]],"id":44213406}],"con":true,"img":false}]}
{"op":"mcm","clk":"11540491543","pt":1719495126509,"mc":[{"id":"1.230180114","rc":[{"atl":[[100,21.7]],"id":44213406}],"con":true,"img":false}]}
{"op":"mcm","clk":"11540491554","pt":1719495126558,"mc":[{"id":"1.230180114","rc":[{"atl":[[110,0]],"id":44213406}],"con":true,"img":false}]}
{"op":"mcm","clk":"11540491579","pt":1719495126767,"mc":[{"id":"1.230180114","rc":[{"atl":[[140,0.84]],"id":41804643},{"atl":[[95,0.84],[100,20]],"id":44213406}],"con":true,"img":false}]}
{"op":"mcm","clk":"11540491587","pt":1719495126874,"mc":[{"id":"1.230180114","rc":[{"atl":[[150,10.8]],"id":44213406}],"con":true,"img":false}]}
{"op":"mcm","clk":"11540491599","pt":1719495126981,"mc":[{"id":"1.230180114","rc":[{"atl":[[95,20.84],[100,0]],"id":44213406}],"con":true,"img":false}]}
{"op":"mcm","clk":"11540491612","pt":1719495127082,"mc":[{"id":"1.230180114","rc":[{"atl":[[150,9.1]],"id":44213406}],"con":true,"img":false}]}
{"op":"mcm","clk":"11540491626","pt":1719495127180,"mc":[{"id":"1.230180114","rc":[{"atl":[[95,22.54]],"id":44213406}],"con":true,"img":false}]}
{"op":"mcm","clk":"11540491685","pt":1719495128007,"mc":[{"id":"1.230180114","rc":[{"atb":[[1.78,1.28]],"id":44213406}],"con":true,"img":false}]}
{"op":"mcm","clk":"11540491691","pt":1719495128057,"mc":[{"id":"1.230180114","rc":[{"atb":[[1.76,2]],"id":44213406}],"con":true,"img":false}]}
{"op":"mcm","clk":"11540491739","pt":1719495128677,"mc":[{"id":"1.230180114","rc":[{"spn":1.7,"spf":1.0,"id":41804643},{"atb":[[1.79,1.84]],"id":44213406},{"spn":48.39,"spf":"NaN","id":44213406},{"spn":1.71,"spf":1.0,"id":39682601}],"con":true,"img":false}]}
{"op":"mcm","clk":"11540492039","pt":1719495132004,"mc":[{"id":"1.230180114","rc":[{"atb":[[1.76,0]],"id":44213406}],"con":true,"img":false}]}
{"op":"mcm","clk":"11540492046","pt":1719495132101,"mc":[{"id":"1.230180114","rc":[{"atb":[[1.8,2]],"id":44213406}],"con":true,"img":false}]}
{"op":"mcm","clk":"11540492663","pt":1719495138418,"mc":[{"id":"1.230180114","rc":[{"atb":[[1.78,0]],"id":44213406}],"con":true,"img":false}]}
{"op":"mcm","clk":"11540492712","pt":1719495138894,"mc":[{"id":"1.230180114","rc":[{"atl":[[140,0]],"id":44213406}],"con":true,"img":false}]}
{"op":"mcm","clk":"11540492862","pt":1719495140283,"mc":[{"id":"1.230180114","rc":[{"atb":[[1.81,1.23]],"id":44213406},{"atl":[[1000,0.01]],"id":44213406}],"con":true,"img":false}]}
{"op":"mcm","clk":"11540492872","pt":1719495140391,"mc":[{"id":"1.230180114","rc":[{"atl":[[1000,0]],"id":44213406}],"con":true,"img":false}]}
{"op":"mcm","clk":"11540492881","pt":1719495140492,"mc":[{"id":"1.230180114","rc":[{"atl":[[90,0.01]],"id":44213406}],"con":true,"img":false}]}
{"op":"mcm","clk":"11540492891","pt":1719495140594,"mc":[{"id":"1.230180114","rc":[{"atl":[[90,20.01],[95,2.54]],"id":44213406}],"con":true,"img":false}]}
{"op":"mcm","clk":"11540492902","pt":1719495140699,"mc":[{"id":"1.230180114","rc":[{"atb":[[1.79,0]],"id":44213406},{"atl":[[95,0.84]],"id":44213406}],"con":true,"img":false}]}
{"op":"mcm","clk":"11540492915","pt":1719495140803,"mc":[{"id":"1.230180114","rc":[{"atl":[[85,1.7]],"id":44213406}],"con":true,"img":false}]}
{"op":"mcm","clk":"11540492923","pt":1719495140907,"mc":[{"id":"1.230180114","rc":[{"atl":[[85,21.7],[90,0.01]],"id":44213406}],"con":true,"img":false}]}
{"op":"mcm","clk":"11540492940","pt":1719495141114,"mc":[{"id":"1.230180114","rc":[{"atl":[[85,20]],"id":44213406}],"con":true,"img":false}]}
{"op":"mcm","clk":"11540492948","pt":1719495141218,"mc":[{"id":"1.230180114","rc":[{"atl":[[150,10.8]],"id":44213406}],"con":true,"img":false}]}
{"op":"mcm","clk":"11540492967","pt":1719495141376,"mc":[{"id":"1.230180114","rc":[{"atl":[[150,9.1]],"id":44213406}],"con":true,"img":false}]}
{"op":"mcm","clk":"11540492976","pt":1719495141534,"mc":[{"id":"1.230180114","rc":[{"atl":[[80,1.7]],"id":44213406}],"con":true,"img":false}]}
{"op":"mcm","clk":"11540493000","pt":1719495141691,"mc":[{"id":"1.230180114","rc":[{"atl":[[80,21.7],[85,0]],"id":44213406}],"con":true,"img":false}]}
{"op":"mcm","clk":"11540493021","pt":1719495141898,"mc":[{"id":"1.230180114","rc":[{"atl":[[80,20]],"id":44213406}],"con":true,"img":false}]}
{"op":"mcm","clk":"11540493033","pt":1719495142006,"mc":[{"id":"1.230180114","rc":[{"atl":[[150,10.8]],"id":44213406}],"con":true,"img":false}]}
{"op":"mcm","clk":"11540493053","pt":1719495142214,"mc":[{"id":"1.230180114","rc":[{"atl":[[150,9.1]],"id":44213406}],"con":true,"img":false}]}
{"op":"mcm","clk":"11540493068","pt":1719495142314,"mc":[{"id":"1.230180114","rc":[{"atl":[[75,1.7]],"id":44213406}],"con":true,"img":false}]}
{"op":"mcm","clk":"11540493073","pt":1719495142417,"mc":[{"id":"1.230180114","rc":[{"atb":[[1.8,0]],"id":44213406},{"atl":[[75,21.7]],"id":44213406}],"con":true,"img":false}]}
{"op":"mcm","clk":"11540493081","pt":1719495142520,"mc":[{"id":"1.230180114","rc":[{"atb":[[1.82,2]],"id":44213406},{"atl":[[80,0]],"id":44213406}],"con":true,"img":false}]}
{"op":"mcm","clk":"11540493091","pt":1719495142625,"mc":[{"id":"1.230180114","rc":[{"atl":[[75,20]],"id":44213406}],"con":true,"img":false}]}
{"op":"mcm","clk":"11540493102","pt":1719495142729,"mc":[{"id":"1.230180114","rc":[{"atl":[[150,10.8]],"id":44213406}],"con":true,"img":false}]}
{"op":"mcm","clk":"11540493120","pt":1719495142885,"mc":[{"id":"1.230180114","rc":[{"atl":[[150,9.1]],"id":44213406}],"con":true,"img":false}]}
{"op":"mcm","clk":"11540493132","pt":1719495142993,"mc":[{"id":"1.230180114","rc":[{"atl":[[70,1.7]],"id":44213406}],"con":true,"img":false}]}
{"op":"mcm","clk":"11540493145","pt":1719495143093,"mc":[{"id":"1.230180114","rc":[{"atl":[[70,21.7]],"id":44213406}],"con":true,"img":false}]}
{"op":"mcm","clk":"11540493155","pt":1719495143196,"mc":[{"id":"1.230180114","rc":[{"atl":[[75,0]],"id":44213406}],"con":true,"img":false}]}
{"op":"mcm","clk":"11540493175","pt":1719495143403,"mc":[{"id":"1.230180114","rc":[{"atl":[[70,20]],"id":44213406}],"con":true,"img":false}]}
{"op":"mcm","clk":"11540493180","pt":1719495143512,"mc":[{"id":"1.230180114","rc":[{"atl":[[150,10.8]],"id":44213406}],"con":true,"img":false}]}
{"op":"mcm","clk":"11540493202","pt":1719495143722,"mc":[{"id":"1.230180114","rc":[{"atl":[[150,9.1]],"id":44213406}],"con":true,"img":false}]}
{"op":"mcm","clk":"11540493216","pt":1719495143826,"mc":[{"id":"1.230180114","rc":[{"atl":[[65,1.7]],"id":44213406}],"con":true,"img":false}]}
{"op":"mcm","clk":"11540493225","pt":1719495143929,"mc":[{"id":"1.230180114","rc":[{"atl":[[65,21.7]],"id":44213406}],"con":true,"img":false}]}
{"op":"mcm","clk":"11540493238","pt":1719495144036,"mc":[{"id":"1.230180114","rc":[{"atl":[[70,0]],"id":44213406}],"con":true,"img":false}]}
{"op":"mcm","clk":"11540493257","pt":1719495144187,"mc":[{"id":"1.230180114","rc":[{"atl":[[65,20]],"id":44213406}],"con":true,"img":false}]}
{"op":"mcm","clk":"11540493269","pt":1719495144294,"mc":[{"id":"1.230180114","rc":[{"atl":[[150,10.8]],"id":44213406}],"con":true,"img":false}]}
{"op":"mcm","clk":"11540493287","pt":1719495144497,"mc":[{"id":"1.230180114","rc":[{"atl":[[150,9.1]],"id":44213406}],"con":true,"img":false}]}
{"op":"mcm","clk":"11540493295","pt":1719495144598,"mc":[{"id":"1.230180114","rc":[{"atl":[[60,1.7]],"id":44213406}],"con":true,"img":false}]}
{"op":"mcm","clk":"11540493303","pt":1719495144700,"mc":[{"id":"1.230180114","rc":[{"atl":[[60,21.7]],"id":44213406}],"con":true,"img":false}]}
{"op":"mcm","clk":"11540493309","pt":1719495144806,"mc":[{"id":"1.230180114","rc":[{"atl":[[65,0]],"id":44213406}],"con":true,"img":false}]}
{"op":"mcm","clk":"11540493325","pt":1719495145012,"mc":[{"id":"1.230180114","rc":[{"atl":[[60,20]],"id":44213406}],"con":true,"img":false}]}
{"op":"mcm","clk":"11540493334","pt":1719495145116,"mc":[{"id":"1.230180114","rc":[{"atl":[[150,10.8]],"id":44213406}],"con":true,"img":false}]}
{"op":"mcm","clk":"11540493352","pt":1719495145327,"mc":[{"id":"1.230180114","rc":[{"atl":[[150,9.1]],"id":44213406}],"con":true,"img":false}]}
{"op":"mcm","clk":"11540493361","pt":1719495145429,"mc":[{"id":"1.230180114","rc":[{"atl":[[55,1.7]],"id":44213406}],"con":true,"img":false}]}
{"op":"mcm","clk":"11540493368","pt":1719495145534,"mc":[{"id":"1.230180114","rc":[{"atl":[[55,21.7],[60,0]],"id":44213406}],"con":true,"img":false}]}
{"op":"mcm","clk":"11540493384","pt":1719495145694,"mc":[{"id":"1.230180114","rc":[{"atl":[[55,20]],"id":44213406}],"con":true,"img":false}]}
{"op":"mcm","clk":"11540493394","pt":1719495145789,"mc":[{"id":"1.230180114","rc":[{"atl":[[150,10.8]],"id":44213406}],"con":true,"img":false}]}
{"op":"mcm","clk":"11540493402","pt":1719495145896,"mc":[{"id":"1.230180114","rc":[{"atl":[[150,9.1]],"id":44213406}],"con":true,"img":false}]}
{"op":"mcm","clk":"11540493412","pt":1719495146000,"mc":[{"id":"1.230180114","rc":[{"atl":[[50,1.7]],"id":44213406}],"con":true,"img":false}]}
{"op":"mcm","clk":"11540493423","pt":1719495146100,"mc":[{"id":"1.230180114","rc":[{"atl":[[50,21.7],[55,0]],"id":44213406}],"con":true,"img":false}]}
{"op":"mcm","clk":"11540493440","pt":1719495146305,"mc":[{"id":"1.230180114","rc":[{"atl":[[50,20]],"id":44213406}],"con":true,"img":false}]}
{"op":"mcm","clk":"11540493450","pt":1719495146412,"mc":[{"id":"1.230180114","rc":[{"atl":[[150,10.8]],"id":44213406}],"con":true,"img":false}]}
{"op":"mcm","clk":"11540493467","pt":1719495146614,"mc":[{"id":"1.230180114","rc":[{"atl":[[150,9.1]],"id":44213406}],"con":true,"img":false}]}
{"op":"mcm","clk":"11540493471","pt":1719495146722,"mc":[{"id":"1.230180114","rc":[{"atl":[[48,1.7]],"id":44213406}],"con":true,"img":false}]}
{"op":"mcm","clk":"11540493492","pt":1719495146922,"mc":[{"id":"1.230180114","rc":[{"atl":[[48,21.7],[50,0]],"id":44213406}],"con":true,"img":false}]}
{"op":"mcm","clk":"11540493516","pt":1719495147126,"mc":[{"id":"1.230180114","rc":[{"atl":[[48,20]],"id":44213406}],"con":true,"img":false}]}
{"op":"mcm","clk":"11540493524","pt":1719495147234,"mc":[{"id":"1.230180114","rc":[{"atl":[[150,10.8]],"id":44213406}],"con":true,"img":false}]}
{"op":"mcm","clk":"11540493546","pt":1719495147440,"mc":[{"id":"1.230180114","rc":[{"atl":[[150,9.1]],"id":44213406}],"con":true,"img":false}]}
{"op":"mcm","clk":"11540493559","pt":1719495147490,"mc":[{"id":"1.230180114","rc":[{"atl":[[46,1.7]],"id":44213406}],"con":true,"img":false}]}
{"op":"mcm","clk":"11540493568","pt":1719495147598,"mc":[{"id":"1.230180114","rc":[{"atl":[[46,21.7]],"id":44213406}],"con":true,"img":false}]}
{"op":"mcm","clk":"11540493581","pt":1719495147697,"mc":[{"id":"1.230180114","rc":[{"atl":[[48,0]],"id":44213406}],"con":true,"img":false}]}
{"op":"mcm","clk":"11540493597","pt":1719495147902,"mc":[{"id":"1.230180114","rc":[{"atl":[[46,20]],"id":44213406}],"con":true,"img":false}]}
{"op":"mcm","clk":"11540493602","pt":1719495148015,"mc":[{"id":"1.230180114","rc":[{"atl":[[150,10.8]],"id":44213406}],"con":true,"img":false}]}
{"op":"mcm","clk":"11540493620","pt":1719495148219,"mc":[{"id":"1.230180114","rc":[{"atl":[[150,9.1]],"id":44213406}],"con":true,"img":false}]}
{"op":"mcm","clk":"11540493629","pt":1719495148318,"mc":[{"id":"1.230180114","rc":[{"atl":[[44,1.7]],"id":44213406}],"con":true,"img":false}]}
{"op":"mcm","clk":"11540493637","pt":1719495148443,"mc":[{"id":"1.230180114","rc":[{"atl":[[44,21.7]],"id":44213406}],"con":true,"img":false}]}
{"op":"mcm","clk":"11540493649","pt":1719495148491,"mc":[{"id":"1.230180114","rc":[{"atl":[[46,0]],"id":44213406}],"con":true,"img":false}]}
{"op":"mcm","clk":"11540493655","pt":1719495148597,"mc":[{"id":"1.230180114","rc":[{"atl":[[44,20]],"id":44213406}],"con":true,"img":false}]}
{"op":"mcm","clk":"11540493667","pt":1719495148708,"mc":[{"id":"1.230180114","rc":[{"atl":[[150,10.8]],"id":44213406}],"con":true,"img":false}]}
{"op":"mcm","clk":"11540493677","pt":1719495148806,"mc":[{"id":"1.230180114","rc":[{"atl":[[150,9.1]],"id":44213406}],"con":true,"img":false}]}
{"op":"mcm","clk":"11540493686","pt":1719495148914,"mc":[{"id":"1.230180114","rc":[{"atl":[[42,1.7]],"id":44213406}],"con":true,"img":false}]}
{"op":"mcm","clk":"11540493702","pt":1719495149018,"mc":[{"id":"1.230180114","rc":[{"atl":[[42,21.7],[44,0]],"id":44213406}],"con":true,"img":false}]}
{"op":"mcm","clk":"11540493716","pt":1719495149113,"mc":[{"id":"1.230180114","rc":[{"atl":[[42,20]],"id":44213406}],"con":true,"img":false}]}
{"op":"mcm","clk":"11540493729","pt":1719495149215,"mc":[{"id":"1.230180114","rc":[{"atl":[[150,10.8]],"id":44213406}],"con":true,"img":false}]}
{"op":"mcm","clk":"11540493744","pt":1719495149420,"mc":[{"id":"1.230180114","rc":[{"atl":[[150,9.1]],"id":44213406}],"con":true,"img":false}]}
{"op":"mcm","clk":"11540493751","pt":1719495149524,"mc":[{"id":"1.230180114","rc":[{"atl":[[40,1.7]],"id":44213406}],"con":true,"img":false}]}
{"op":"mcm","clk":"11540493759","pt":1719495149630,"mc":[{"id":"1.230180114","rc":[{"atl":[[40,21.7],[42,0]],"id":44213406}],"con":true,"img":false}]}
{"op":"mcm","clk":"11540493780","pt":1719495149836,"mc":[{"id":"1.230180114","rc":[{"atl":[[40,20]],"id":44213406}],"con":true,"img":false}]}
{"op":"mcm","clk":"11540493789","pt":1719495149944,"mc":[{"id":"1.230180114","rc":[{"atl":[[150,10.8]],"id":44213406}],"con":true,"img":false}]}
{"op":"mcm","clk":"11540493805","pt":1719495150099,"mc":[{"id":"1.230180114","rc":[{"atl":[[150,9.1]],"id":44213406}],"con":true,"img":false}]}
{"op":"mcm","clk":"11540493814","pt":1719495150196,"mc":[{"id":"1.230180114","rc":[{"atl":[[38,1.7]],"id":44213406}],"con":true,"img":false}]}
{"op":"mcm","clk":"11540493836","pt":1719495150401,"mc":[{"id":"1.230180114","rc":[{"atl":[[38,21.7],[40,0]],"id":44213406}],"con":true,"img":false}]}
{"op":"mcm","clk":"11540493855","pt":1719495150608,"mc":[{"id":"1.230180114","rc":[{"atl":[[38,20]],"id":44213406}],"con":true,"img":false}]}
{"op":"mcm","clk":"11540493863","pt":1719495150711,"mc":[{"id":"1.230180114","rc":[{"atl":[[150,10.8]],"id":44213406}],"con":true,"img":false}]}
{"op":"mcm","clk":"11540493876","pt":1719495150923,"mc":[{"id":"1.230180114","rc":[{"atl":[[150,9.1]],"id":44213406}],"con":true,"img":false}]}
{"op":"mcm","clk":"11540493887","pt":1719495151024,"mc":[{"id":"1.230180114","rc":[{"atl":[[36,1.7]],"id":44213406}],"con":true,"img":false}]}
{"op":"mcm","clk":"11540493898","pt":1719495151126,"mc":[{"id":"1.230180114","rc":[{"atl":[[36,21.7],[38,0]],"id":44213406}],"con":true,"img":false}]}
{"op":"mcm","clk":"11540493920","pt":1719495151331,"mc":[{"id":"1.230180114","rc":[{"atl":[[36,20]],"id":44213406}],"con":true,"img":false}]}
{"op":"mcm","clk":"11540493931","pt":1719495151441,"mc":[{"id":"1.230180114","rc":[{"atl":[[150,10.8]],"id":44213406}],"con":true,"img":false}]}
{"op":"mcm","clk":"11540493953","pt":1719495151598,"mc":[{"id":"1.230180114","rc":[{"atl":[[150,9.1]],"id":44213406}],"con":true,"img":false}]}
{"op":"mcm","clk":"11540493964","pt":1719495151701,"mc":[{"id":"1.230180114","rc":[{"atl":[[34,1.7]],"id":44213406}],"con":true,"img":false}]}
{"op":"mcm","clk":"11540493984","pt":1719495151914,"mc":[{"id":"1.230180114","rc":[{"atl":[[34,21.7],[36,0]],"id":44213406}],"con":true,"img":false}]}
{"op":"mcm","clk":"11540494013","pt":1719495152113,"mc":[{"id":"1.230180114","rc":[{"atl":[[34,20]],"id":44213406}],"con":true,"img":false}]}
{"op":"mcm","clk":"11540494019","pt":1719495152217,"mc":[{"id":"1.230180114","rc":[{"atl":[[150,10.8]],"id":44213406}],"con":true,"img":false}]}
{"op":"mcm","clk":"11540494025","pt":1719495152320,"mc":[{"id":"1.230180114","rc":[{"atl":[[150,9.1]],"id":44213406}],"con":true,"img":false}]}
{"op":"mcm","clk":"11540494032","pt":1719495152425,"mc":[{"id":"1.230180114","rc":[{"atl":[[32,1.7]],"id":44213406}],"con":true,"img":false}]}
{"op":"mcm","clk":"11540494039","pt":1719495152529,"mc":[{"id":"1.230180114","rc":[{"atl":[[32,21.7]],"id":44213406}],"con":true,"img":false}]}
{"op":"mcm","clk":"11540494047","pt":1719495152634,"mc":[{"id":"1.230180114","rc":[{"atl":[[34,0]],"id":44213406}],"con":true,"img":false}]}
{"op":"mcm","clk":"11540494061","pt":1719495152735,"mc":[{"id":"1.230180114","rc":[{"atl":[[32,20]],"id":44213406}],"con":true,"img":false}]}
{"op":"mcm","clk":"11540494071","pt":1719495152860,"mc":[{"id":"1.230180114","rc":[{"atl":[[150,10.8]],"id":44213406}],"con":true,"img":false}]}
{"op":"mcm","clk":"11540494086","pt":1719495152944,"mc":[{"id":"1.230180114","rc":[{"atl":[[150,9.1]],"id":44213406}],"con":true,"img":false}]}
{"op":"mcm","clk":"11540494096","pt":1719495153049,"mc":[{"id":"1.230180114","rc":[{"atl":[[30,1.7]],"id":44213406}],"con":true,"img":false}]}
{"op":"mcm","clk":"11540494121","pt":1719495153203,"mc":[{"id":"1.230180114","rc":[{"atl":[[32,0],[30,21.7]],"id":44213406}],"con":true,"img":false}]}
{"op":"mcm","clk":"11540494128","pt":1719495153307,"mc":[{"id":"1.230180114","rc":[{"atl":[[30,20]],"id":44213406}],"con":true,"img":false}]}
{"op":"mcm","clk":"11540494140","pt":1719495153411,"mc":[{"id":"1.230180114","rc":[{"atl":[[150,10.8]],"id":44213406}],"con":true,"img":false}]}
{"op":"mcm","clk":"11540494149","pt":1719495153514,"mc":[{"id":"1.230180114","rc":[{"atl":[[150,9.1]],"id":44213406}],"con":true,"img":false}]}
{"op":"mcm","clk":"11540494159","pt":1719495153616,"mc":[{"id":"1.230180114","rc":[{"atl":[[29,1.7]],"id":44213406}],"con":true,"img":false}]}
{"op":"mcm","clk":"11540494168","pt":1719495153720,"mc":[{"id":"1.230180114","rc":[{"atl":[[29,21.7]],"id":44213406}],"con":true,"img":false}]}
{"op":"mcm","clk":"11540494179","pt":1719495153824,"mc":[{"id":"1.230180114","rc":[{"atl":[[30,0]],"id":44213406}],"con":true,"img":false}]}
{"op":"mcm","clk":"11540494197","pt":1719495154037,"mc":[{"id":"1.230180114","rc":[{"atl":[[29,20]],"id":44213406}],"con":true,"img":false}]}
{"op":"mcm","clk":"11540494202","pt":1719495154139,"mc":[{"id":"1.230180114","rc":[{"atl":[[150,10.8]],"id":44213406}],"con":true,"img":false}]}
{"op":"mcm","clk":"11540494223","pt":1719495154342,"mc":[{"id":"1.230180114","rc":[{"atl":[[150,9.1]],"id":44213406}],"con":true,"img":false}]}
{"op":"mcm","clk":"11540494234","pt":1719495154394,"mc":[{"id":"1.230180114","rc":[{"atl":[[28,1.7]],"id":44213406}],"con":true,"img":false}]}
{"op":"mcm","clk":"11540494246","pt":1719495154499,"mc":[{"id":"1.230180114","rc":[{"atl":[[28,21.7]],"id":44213406}],"con":true,"img":false}]}
{"op":"mcm","clk":"11540494258","pt":1719495154603,"mc":[{"id":"1.230180114","rc":[{"atl":[[29,0]],"id":44213406}],"con":true,"img":false}]}
{"op":"mcm","clk":"11540494269","pt":1719495154706,"mc":[{"id":"1.230180114","rc":[{"atl":[[28,20]],"id":44213406}],"con":true,"img":false}]}
{"op":"mcm","clk":"11540494282","pt":1719495154811,"mc":[{"id":"1.230180114","rc":[{"atl":[[150,10.8]],"id":44213406}],"con":true,"img":false}]}
{"op":"mcm","clk":"11540494300","pt":1719495155023,"mc":[{"id":"1.230180114","rc":[{"atl":[[150,9.1]],"id":44213406}],"con":true,"img":false}]}
{"op":"mcm","clk":"11540494306","pt":1719495155122,"mc":[{"id":"1.230180114","rc":[{"atl":[[27,1.7]],"id":44213406}],"con":true,"img":false}]}
{"op":"mcm","clk":"11540494317","pt":1719495155226,"mc":[{"id":"1.230180114","rc":[{"atl":[[27,21.7],[28,0]],"id":44213406}],"con":true,"img":false}]}
{"op":"mcm","clk":"11540494326","pt":1719495155330,"mc":[{"id":"1.230180114","rc":[{"atl":[[27,20]],"id":44213406}],"con":true,"img":false}]}
{"op":"mcm","clk":"11540494336","pt":1719495155435,"mc":[{"id":"1.230180114","rc":[{"atb":[[1.81,0]],"id":44213406},{"atl":[[150,10.8]],"id":44213406}],"con":true,"img":false}]}
{"op":"mcm","clk":"11540494343","pt":1719495155541,"mc":[{"id":"1.230180114","rc":[{"atl":[[150,9.1]],"id":44213406}],"con":true,"img":false}]}
{"op":"mcm","clk":"11540494354","pt":1719495155640,"mc":[{"id":"1.230180114","rc":[{"atl":[[90,0],[26,1.7]],"id":44213406}],"con":true,"img":false}]}
{"op":"mcm","clk":"11540494361","pt":1719495155744,"mc":[{"id":"1.230180114","rc":[{"atl":[[26,21.7],[27,0]],"id":44213406}],"con":true,"img":false}]}
{"op":"mcm","clk":"11540494379","pt":1719495155900,"mc":[{"id":"1.230180114","rc":[{"atl":[[26,20]],"id":44213406}],"con":true,"img":false}]}
{"op":"mcm","clk":"11540494387","pt":1719495156008,"mc":[{"id":"1.230180114","rc":[{"atl":[[150,10.8]],"id":44213406}],"con":true,"img":false}]}
{"op":"mcm","clk":"11540494402","pt":1719495156209,"mc":[{"id":"1.230180114","rc":[{"atl":[[150,9.1]],"id":44213406}],"con":true,"img":false}]}
{"op":"mcm","clk":"11540494409","pt":1719495156313,"mc":[{"id":"1.230180114","rc":[{"atl":[[25,1.7]],"id":44213406}],"con":true,"img":false}]}
{"op":"mcm","clk":"11540494416","pt":1719495156415,"mc":[{"id":"1.230180114","rc":[{"atl":[[25,21.7],[26,0]],"id":44213406}],"con":true,"img":false}]}
{"op":"mcm","clk":"11540494424","pt":1719495156519,"mc":[{"id":"1.230180114","rc":[{"atl":[[25,20]],"id":44213406}],"con":true,"img":false}]}
{"op":"mcm","clk":"11540494434","pt":1719495156623,"mc":[{"id":"1.230180114","rc":[{"atl":[[150,10.8]],"id":44213406}],"con":true,"img":false}]}
{"op":"mcm","clk":"11540494443","pt":1719495156724,"mc":[{"id":"1.230180114","rc":[{"atb":[[1.82,0]],"id":44213406}],"con":true,"img":false}]}
{"op":"mcm","clk":"11540494449","pt":1719495156830,"mc":[{"id":"1.230180114","rc":[{"atb":[[1.76,2]],"id":44213406},{"atl":[[150,9.1]],"id":44213406}],"con":true,"img":false}]}
{"op":"mcm","clk":"11540494455","pt":1719495156928,"mc":[{"id":"1.230180114","rc":[{"atl":[[24,1.7]],"id":44213406}],"con":true,"img":false}]}
{"op":"mcm","clk":"11540494461","pt":1719495157037,"mc":[{"id":"1.230180114","rc":[{"atb":[[1.83,1.74]],"id":44213406},{"atl":[[24,21.7]],"id":44213406}],"con":true,"img":false}]}
{"op":"mcm","clk":"11540494467","pt":1719495157135,"mc":[{"id":"1.230180114","rc":[{"atl":[[25,0]],"id":44213406}],"con":true,"img":false}]}
{"op":"mcm","clk":"11540494474","pt":1719495157237,"mc":[{"id":"1.230180114","rc":[{"atl":[[24,20]],"id":44213406}],"con":true,"img":false}]}
{"op":"mcm","clk":"11540494479","pt":1719495157367,"mc":[{"id":"1.230180114","rc":[{"atb":[[1.84,1.19]],"id":44213406},{"atl":[[150,10.8],[1000,0.05]],"id":44213406}],"con":true,"img":false}]}
{"op":"mcm","clk":"11540494484","pt":1719495157448,"mc":[{"id":"1.230180114","rc":[{"atl":[[1000,0]],"id":44213406}],"con":true,"img":false}]}
{"op":"mcm","clk":"11540494488","pt":1719495157552,"mc":[{"id":"1.230180114","rc":[{"atl":[[150,9.1],[23,0.05]],"id":44213406}],"con":true,"img":false}]}
{"op":"mcm","clk":"11540494495","pt":1719495157659,"mc":[{"id":"1.230180114","rc":[{"atl":[[23,1.75]],"id":44213406}],"con":true,"img":false}]}
{"op":"mcm","clk":"11540494504","pt":1719495157706,"mc":[{"id":"1.230180114","rc":[{"atl":[[23,20.05],[24,0]],"id":44213406}],"con":true,"img":false}]}
{"op":"mcm","clk":"11540494512","pt":1719495157810,"mc":[{"id":"1.230180114","rc":[{"atl":[[23,21.75]],"id":44213406}],"con":true,"img":false}]}
{"op":"mcm","clk":"11540494524","pt":1719495157916,"mc":[{"id":"1.230180114","rc":[{"atl":[[23,20.05]],"id":44213406}],"con":true,"img":false}]}
{"op":"mcm","clk":"11540494530","pt":1719495158020,"mc":[{"id":"1.230180114","rc":[{"atl":[[150,10.8]],"id":44213406}],"con":true,"img":false}]}
{"op":"mcm","clk":"11540494537","pt":1719495158118,"mc":[{"id":"1.230180114","rc":[{"atl":[[150,9.1]],"id":44213406}],"con":true,"img":false}]}
{"op":"mcm","clk":"11540494545","pt":1719495158221,"mc":[{"id":"1.230180114","rc":[{"atl":[[22,1.7]],"id":44213406}],"con":true,"img":false}]}
{"op":"mcm","clk":"11540494557","pt":1719495158327,"mc":[{"id":"1.230180114","rc":[{"atl":[[22,21.7],[23,0.05]],"id":44213406}],"con":true,"img":false}]}
{"op":"mcm","clk":"11540494569","pt":1719495158429,"mc":[{"id":"1.230180114","rc":[{"atl":[[22,20]],"id":44213406}],"con":true,"img":false}]}
{"op":"mcm","clk":"11540494581","pt":1719495158542,"mc":[{"id":"1.230180114","rc":[{"atl":[[150,10.8]],"id":44213406}],"con":true,"img":false}]}
{"op":"mcm","clk":"11540494590","pt":1719495158636,"mc":[{"id":"1.230180114","rc":[{"atl":[[150,9.1]],"id":44213406}],"con":true,"img":false}]}
{"op":"mcm","clk":"11540494602","pt":1719495158743,"mc":[{"id":"1.230180114","rc":[{"atl":[[21,1.7]],"id":44213406}],"con":true,"img":false}]}
{"op":"mcm","clk":"11540494615","pt":1719495158842,"mc":[{"id":"1.230180114","rc":[{"atl":[[21,21.7],[22,0]],"id":44213406}],"con":true,"img":false}]}
{"op":"mcm","clk":"11540494623","pt":1719495158942,"mc":[{"id":"1.230180114","rc":[{"atb":[[1.76,0]],"id":44213406}],"con":true,"img":false}]}
{"op":"mcm","clk":"11540494633","pt":1719495159051,"mc":[{"id":"1.230180114","rc":[{"atb":[[1.85,2]],"id":44213406},{"atl":[[21,20]],"id":44213406}],"con":true,"img":false}]}
{"op":"mcm","clk":"11540494641","pt":1719495159148,"mc":[{"id":"1.230180114","rc":[{"atb":[[1.83,0]],"id":44213406},{"atl":[[150,10.8]],"id":44213406}],"con":true,"img":false}]}
{"op":"mcm","clk":"11540494650","pt":1719495159201,"mc":[{"id":"1.230180114","rc":[{"atl":[[150,9.1]],"id":44213406}],"con":true,"img":false}]}
{"op":"mcm","clk":"11540494662","pt":1719495159306,"mc":[{"id":"1.230180114","rc":[{"atl":[[20,1.7]],"id":44213406}],"con":true,"img":false}]}
{"op":"mcm","clk":"11540494687","pt":1719495159517,"mc":[{"id":"1.230180114","rc":[{"atl":[[20,21.7],[21,0]],"id":44213406}],"con":true,"img":false}]}
{"op":"mcm","clk":"11540494701","pt":1719495159619,"mc":[{"id":"1.230180114","rc":[{"atl":[[20,20]],"id":44213406}],"con":true,"img":false}]}
{"op":"mcm","clk":"11540494715","pt":1719495159719,"mc":[{"id":"1.230180114","rc":[{"atl":[[150,10.8]],"id":44213406}],"con":true,"img":false}]}
{"op":"mcm","clk":"11540494753","pt":1719495160037,"mc":[{"id":"1.230180114","rc":[{"atl":[[150,9.1]],"id":44213406}],"con":true,"img":false}]}
{"op":"mcm","clk":"11540494768","pt":1719495160131,"mc":[{"id":"1.230180114","rc":[{"atl":[[19.5,1.7]],"id":44213406}],"con":true,"img":false}]}
{"op":"mcm","clk":"11540494777","pt":1719495160236,"mc":[{"id":"1.230180114","rc":[{"atl":[[19.5,21.7],[20,0]],"id":44213406}],"con":true,"img":false}]}
{"op":"mcm","clk":"11540494786","pt":1719495160342,"mc":[{"id":"1.230180114","rc":[{"atl":[[19.5,20]],"id":44213406}],"con":true,"img":false}]}
{"op":"mcm","clk":"11540494794","pt":1719495160445,"mc":[{"id":"1.230180114","rc":[{"atl":[[150,10.8]],"id":44213406}],"con":true,"img":false}]}
{"op":"mcm","clk":"11540494803","pt":1719495160555,"mc":[{"id":"1.230180114","rc":[{"atl":[[150,9.1]],"id":44213406}],"con":true,"img":false}]}
{"op":"mcm","clk":"11540494807","pt":1719495160655,"mc":[{"id":"1.230180114","rc":[{"atl":[[19,1.7]],"id":44213406}],"con":true,"img":false}]}
{"op":"mcm","clk":"11540494817","pt":1719495160709,"mc":[{"id":"1.230180114","rc":[{"atl":[[19,21.7]],"id":44213406}],"con":true,"img":false}]}
{"op":"mcm","clk":"11540494826","pt":1719495160809,"mc":[{"id":"1.230180114","rc":[{"atl":[[19.5,0]],"id":44213406}],"con":true,"img":false}]}
{"op":"mcm","clk":"11540494846","pt":1719495161022,"mc":[{"id":"1.230180114","rc":[{"atl":[[19,20]],"id":44213406}],"con":true,"img":false}]}
{"op":"mcm","clk":"11540494853","pt":1719495161122,"mc":[{"id":"1.230180114","rc":[{"atl":[[150,10.8]],"id":44213406}],"con":true,"img":false}]}
{"op":"mcm","clk":"11540494863","pt":1719495161228,"mc":[{"id":"1.230180114","rc":[{"atl":[[150,9.1]],"id":44213406}],"con":true,"img":false}]}
{"op":"mcm","clk":"11540494871","pt":1719495161332,"mc":[{"id":"1.230180114","rc":[{"atl":[[18.5,1.7]],"id":44213406}],"con":true,"img":false}]}
{"op":"mcm","clk":"11540494881","pt":1719495161441,"mc":[{"id":"1.230180114","rc":[{"atl":[[18.5,21.7],[19,0]],"id":44213406}],"con":true,"img":false}]}
{"op":"mcm","clk":"11540494894","pt":1719495161540,"mc":[{"id":"1.230180114","rc":[{"atl":[[18.5,20]],"id":44213406}],"con":true,"img":false}]}
{"op":"mcm","clk":"11540494903","pt":1719495161644,"mc":[{"id":"1.230180114","rc":[{"atl":[[150,10.8]],"id":44213406}],"con":true,"img":false}]}
{"op":"mcm","clk":"11540494911","pt":1719495161747,"mc":[{"id":"1.230180114","rc":[{"atl":[[150,9.1]],"id":44213406}],"con":true,"img":false}]}
{"op":"mcm","clk":"11540494919","pt":1719495161853,"mc":[{"id":"1.230180114","rc":[{"atl":[[18,1.7]],"id":44213406}],"con":true,"img":false}]}
{"op":"mcm","clk":"11540494929","pt":1719495161955,"mc":[{"id":"1.230180114","rc":[{"atl":[[18.5,0]],"id":44213406}],"con":true,"img":false}]}
{"op":"mcm","clk":"11540494938","pt":1719495162012,"mc":[{"id":"1.230180114","rc":[{"atl":[[18,21.7]],"id":44213406}],"con":true,"img":false}]}
{"op":"mcm","clk":"11540494945","pt":1719495162111,"mc":[{"id":"1.230180114","rc":[{"atb":[[1.86,1.85]],"id":44213406},{"atl":[[18,20]],"id":44213406}],"con":true,"img":false}]}
{"op":"mcm","clk":"11540494956","pt":1719495162218,"mc":[{"id":"1.230180114","rc":[{"atl":[[150,10.8]],"id":44213406}],"con":true,"img":false}]}
{"op":"mcm","clk":"11540494964","pt":1719495162318,"mc":[{"id":"1.230180114","rc":[{"atl":[[150,9.1]],"id":44213406}],"con":true,"img":false}]}
{"op":"mcm","clk":"11540494973","pt":1719495162420,"mc":[{"id":"1.230180114","rc":[{"atl":[[17.5,1.7]],"id":44213406}],"con":true,"img":false}]}
{"op":"mcm","clk":"11540494983","pt":1719495162524,"mc":[{"id":"1.230180114","rc":[{"atl":[[17.5,21.7],[18,0]],"id":44213406}],"con":true,"img":false}]}
{"op":"mcm","clk":"11540494990","pt":1719495162626,"mc":[{"id":"1.230180114","rc":[{"atl":[[17.5,20]],"id":44213406}],"con":true,"img":false}]}
{"op":"mcm","clk":"11540495001","pt":1719495162731,"mc":[{"id":"1.230180114","rc":[{"atl":[[150,10.8]],"id":44213406}],"con":true,"img":false}]}
{"op":"mcm","clk":"11540495010","pt":1719495162837,"mc":[{"id":"1.230180114","rc":[{"atl":[[150,9.1]],"id":44213406}],"con":true,"img":false}]}
{"op":"mcm","clk":"11540495018","pt":1719495162939,"mc":[{"id":"1.230180114","rc":[{"atl":[[17,1.7]],"id":44213406}],"con":true,"img":false}]}
{"op":"mcm","clk":"11540495026","pt":1719495163048,"mc":[{"id":"1.230180114","rc":[{"atl":[[17,21.7],[17.5,0]],"id":44213406}],"con":true,"img":false}]}
{"op":"mcm","clk":"11540495047","pt":1719495163250,"mc":[{"id":"1.230180114","rc":[{"atl":[[17,20]],"id":44213406}],"con":true,"img":false}]}
{"op":"mcm","clk":"11540495056","pt":1719495163350,"mc":[{"id":"1.230180114","rc":[{"atl":[[150,10.8]],"id":44213406}],"con":true,"img":false}]}
{"op":"mcm","clk":"11540495065","pt":1719495163454,"mc":[{"id":"1.230180114","rc":[{"atl":[[150,9.1]],"id":44213406}],"con":true,"img":false}]}
{"op":"mcm","clk":"11540495074","pt":1719495163512,"mc":[{"id":"1.230180114","rc":[{"atl":[[16.5,1.7]],"id":44213406}],"con":true,"img":false}]}
{"op":"mcm","clk":"11540495094","pt":1719495163717,"mc":[{"id":"1.230180114","rc":[{"atl":[[16.5,21.7],[17,0]],"id":44213406}],"con":true,"img":false}]}
{"op":"mcm","clk":"11540495113","pt":1719495163926,"mc":[{"id":"1.230180114","rc":[{"atb":[[1.85,0]],"id":44213406},{"atl":[[16.5,20]],"id":44213406}],"con":true,"img":false}]}
{"op":"mcm","clk":"11540495125","pt":1719495164034,"mc":[{"id":"1.230180114","rc":[{"atb":[[1.87,2]],"id":44213406},{"atl":[[150,10.8]],"id":44213406}],"con":true,"img":false}]}
{"op":"mcm","clk":"11540495139","pt":1719495164135,"mc":[{"id":"1.230180114","rc":[{"atl":[[150,9.1]],"id":44213406}],"con":true,"img":false}]}
{"op":"mcm","clk":"11540495150","pt":1719495164236,"mc":[{"id":"1.230180114","rc":[{"atl":[[16,1.7]],"id":44213406}],"con":true,"img":false}]}
{"op":"mcm","clk":"11540495159","pt":1719495164348,"mc":[{"id":"1.230180114","rc":[{"atl":[[16,21.7],[16.5,0]],"id":44213406}],"con":true,"img":false}]}
{"op":"mcm","clk":"11540495174","pt":1719495164446,"mc":[{"id":"1.230180114","rc":[{"atl":[[16,20]],"id":44213406}],"con":true,"img":false}]}
{"op":"mcm","clk":"11540495182","pt":1719495164546,"mc":[{"id":"1.230180114","rc":[{"atl":[[150,10.8]],"id":44213406}],"con":true,"img":false}]}
{"op":"mcm","clk":"11540495191","pt":1719495164652,"mc":[{"id":"1.230180114","rc":[{"atl":[[150,9.1]],"id":44213406}],"con":true,"img":false}]}
{"op":"mcm","clk":"11540495200","pt":1719495164759,"mc":[{"id":"1.230180114","rc":[{"atl":[[15.5,1.7]],"id":44213406}],"con":true,"img":false}]}
{"op":"mcm","clk":"11540495213","pt":1719495164870,"mc":[{"id":"1.230180114","rc":[{"atl":[[15.5,21.7]],"id":44213406}],"con":true,"img":false}]}
{"op":"mcm","clk":"11540495225","pt":1719495164962,"mc":[{"id":"1.230180114","rc":[{"atl":[[16,0]],"id":44213406}],"con":true,"img":false}]}
{"op":"mcm","clk":"11540495242","pt":1719495165130,"mc":[{"id":"1.230180114","rc":[{"atl":[[15.5,20]],"id":44213406}],"con":true,"img":false}]}
{"op":"mcm","clk":"11540495251","pt":1719495165223,"mc":[{"id":"1.230180114","rc":[{"atl":[[150,10.8]],"id":44213406}],"con":true,"img":false}]}
{"op":"mcm","clk":"11540495266","pt":1719495165434,"mc":[{"id":"1.230180114","rc":[{"atl":[[150,9.1]],"id":44213406}],"con":true,"img":false}]}
{"op":"mcm","clk":"11540495275","pt":1719495165539,"mc":[{"id":"1.230180114","rc":[{"atl":[[15,1.7]],"id":44213406}],"con":true,"img":false}]}
{"op":"mcm","clk":"11540495285","pt":1719495165639,"mc":[{"id":"1.230180114","rc":[{"atl":[[15,21.7],[15.5,0]],"id":44213406}],"con":true,"img":false}]}
{"op":"mcm","clk":"11540495297","pt":1719495165748,"mc":[{"id":"1.230180114","rc":[{"atl":[[15,20]],"id":44213406}],"con":true,"img":false}]}
{"op":"mcm","clk":"11540495306","pt":1719495165847,"mc":[{"id":"1.230180114","rc":[{"atl":[[150,10.8]],"id":44213406}],"con":true,"img":false}]}
{"op":"mcm","clk":"11540495317","pt":1719495165950,"mc":[{"id":"1.230180114","rc":[{"atl":[[150,9.1]],"id":44213406}],"con":true,"img":false}]}
{"op":"mcm","clk":"11540495328","pt":1719495166055,"mc":[{"id":"1.230180114","rc":[{"atl":[[14.5,1.7]],"id":44213406}],"con":true,"img":false}]}
{"op":"mcm","clk":"11540495337","pt":1719495166153,"mc":[{"id":"1.230180114","rc":[{"atl":[[14.5,21.7],[15,0]],"id":44213406}],"con":true,"img":false}]}
{"op":"mcm","clk":"11540495344","pt":1719495166258,"mc":[{"id":"1.230180114","rc":[{"atl":[[14.5,20]],"id":44213406}],"con":true,"img":false}]}
{"op":"mcm","clk":"11540495357","pt":1719495166317,"mc":[{"id":"1.230180114","rc":[{"atl":[[150,10.8]],"id":44213406}],"con":true,"img":false}]}
{"op":"mcm","clk":"11540495383","pt":1719495166525,"mc":[{"id":"1.230180114","rc":[{"atl":[[150,9.1]],"id":44213406}],"con":true,"img":false}]}
{"op":"mcm","clk":"11540495392","pt":1719495166623,"mc":[{"id":"1.230180114","rc":[{"atl":[[14,1.7]],"id":44213406}],"con":true,"img":false}]}
{"op":"mcm","clk":"11540495403","pt":1719495166725,"mc":[{"id":"1.230180114","rc":[{"atl":[[14,21.7]],"id":44213406}],"con":true,"img":false}]}
{"op":"mcm","clk":"11540495409","pt":1719495166827,"mc":[{"id":"1.230180114","rc":[{"atl":[[14.5,0]],"id":44213406}],"con":true,"img":false}]}
{"op":"mcm","clk":"11540495420","pt":1719495166937,"mc":[{"id":"1.230180114","rc":[{"atl":[[14,20]],"id":44213406}],"con":true,"img":false}]}
{"op":"mcm","clk":"11540495433","pt":1719495167054,"mc":[{"id":"1.230180114","rc":[{"atl":[[150,10.8]],"id":44213406}],"con":true,"img":false}]}
{"op":"mcm","clk":"11540495443","pt":1719495167141,"mc":[{"id":"1.230180114","rc":[{"atl":[[150,9.1]],"id":44213406}],"con":true,"img":false}]}
{"op":"mcm","clk":"11540495450","pt":1719495167245,"mc":[{"id":"1.230180114","rc":[{"atl":[[13.5,1.7]],"id":44213406}],"con":true,"img":false}]}
{"op":"mcm","clk":"11540495458","pt":1719495167347,"mc":[{"id":"1.230180114","rc":[{"atl":[[13.5,21.7],[14,0]],"id":44213406}],"con":true,"img":false}]}
{"op":"mcm","clk":"11540495469","pt":1719495167459,"mc":[{"id":"1.230180114","rc":[{"atl":[[13.5,20]],"id":44213406}],"con":true,"img":false}]}
{"op":"mcm","clk":"11540495478","pt":1719495167559,"mc":[{"id":"1.230180114","rc":[{"atl":[[150,10.8]],"id":44213406}],"con":true,"img":false}]}
{"op":"mcm","clk":"11540495486","pt":1719495167658,"mc":[{"id":"1.230180114","rc":[{"atl":[[150,9.1]],"id":44213406}],"con":true,"img":false}]}
{"op":"mcm","clk":"11540495494","pt":1719495167758,"mc":[{"id":"1.230180114","rc":[{"atl":[[13,1.7]],"id":44213406}],"con":true,"img":false}]}
{"op":"mcm","clk":"11540495502","pt":1719495167866,"mc":[{"id":"1.230180114","rc":[{"atl":[[13,21.7],[13.5,0]],"id":44213406}],"con":true,"img":false}]}
{"op":"mcm","clk":"11540495516","pt":1719495168024,"mc":[{"id":"1.230180114","rc":[{"atl":[[13,20]],"id":44213406}],"con":true,"img":false}]}
{"op":"mcm","clk":"11540495526","pt":1719495168120,"mc":[{"id":"1.230180114","rc":[{"atl":[[150,10.8]],"id":44213406}],"con":true,"img":false}]}
{"op":"mcm","clk":"11540495536","pt":1719495168234,"mc":[{"id":"1.230180114","rc":[{"atl":[[150,9.1]],"id":44213406}],"con":true,"img":false}]}
{"op":"mcm","clk":"11540495543","pt":1719495168332,"mc":[{"id":"1.230180114","rc":[{"atl":[[12.5,1.7]],"id":44213406}],"con":true,"img":false}]}
{"op":"mcm","clk":"11540495554","pt":1719495168546,"mc":[{"id":"1.230180114","rc":[{"atl":[[12.5,21.7],[13,0]],"id":44213406}],"con":true,"img":false}]}
{"op":"mcm","clk":"11540495574","pt":1719495168751,"mc":[{"id":"1.230180114","rc":[{"atl":[[12.5,20]],"id":44213406}],"con":true,"img":false}]}
{"op":"mcm","clk":"11540495583","pt":1719495168867,"mc":[{"id":"1.230180114","rc":[{"atl":[[150,10.8]],"id":44213406}],"con":true,"img":false}]}
{"op":"mcm","clk":"11540495598","pt":1719495169064,"mc":[{"id":"1.230180114","rc":[{"atl":[[150,9.1]],"id":44213406}],"con":true,"img":false}]}
{"op":"mcm","clk":"11540495606","pt":1719495169113,"mc":[{"id":"1.230180114","rc":[{"atl":[[12,1.7]],"id":44213406}],"con":true,"img":false}]}
{"op":"mcm","clk":"11540495616","pt":1719495169240,"mc":[{"id":"1.230180114","rc":[{"atl":[[12,21.7],[12.5,0]],"id":44213406}],"con":true,"img":false}]}
{"op":"mcm","clk":"11540495636","pt":1719495169442,"mc":[{"id":"1.230180114","rc":[{"atl":[[12,20]],"id":44213406}],"con":true,"img":false}]}
{"op":"mcm","clk":"11540495643","pt":1719495169534,"mc":[{"id":"1.230180114","rc":[{"atl":[[150,10.8]],"id":44213406}],"con":true,"img":false}]}
{"op":"mcm","clk":"11540495666","pt":1719495169748,"mc":[{"id":"1.230180114","rc":[{"atl":[[150,9.1]],"id":44213406}],"con":true,"img":false}]}
{"op":"mcm","clk":"11540495676","pt":1719495169850,"mc":[{"id":"1.230180114","rc":[{"atl":[[11.5,1.7]],"id":44213406}],"con":true,"img":false}]}
{"op":"mcm","clk":"11540495697","pt":1719495170063,"mc":[{"id":"1.230180114","rc":[{"atl":[[11.5,21.7],[12,0]],"id":44213406}],"con":true,"img":false}]}
{"op":"mcm","clk":"11540495706","pt":1719495170160,"mc":[{"id":"1.230180114","rc":[{"atl":[[11.5,20]],"id":44213406}],"con":true,"img":false}]}
{"op":"mcm","clk":"11540495716","pt":1719495170266,"mc":[{"id":"1.230180114","rc":[{"atl":[[150,10.8]],"id":44213406}],"con":true,"img":false}]}
{"op":"mcm","clk":"11540495739","pt":1719495170471,"mc":[{"id":"1.230180114","rc":[{"atl":[[150,9.1]],"id":44213406}],"con":true,"img":false}]}
{"op":"mcm","clk":"11540495751","pt":1719495170578,"mc":[{"id":"1.230180114","rc":[{"atl":[[11,1.7]],"id":44213406}],"con":true,"img":false}]}
{"op":"mcm","clk":"11540495772","pt":1719495170735,"mc":[{"id":"1.230180114","rc":[{"atl":[[11,21.7],[11.5,0]],"id":44213406}],"con":true,"img":false}]}
{"op":"mcm","clk":"11540495791","pt":1719495170947,"mc":[{"id":"1.230180114","rc":[{"atl":[[11,20]],"id":44213406}],"con":true,"img":false}]}
{"op":"mcm","clk":"11540495803","pt":1719495171052,"mc":[{"id":"1.230180114","rc":[{"atl":[[150,10.8]],"id":44213406}],"con":true,"img":false}]}
{"op":"mcm","clk":"11540495814","pt":1719495171151,"mc":[{"id":"1.230180114","rc":[{"atl":[[150,9.1]],"id":44213406}],"con":true,"img":false}]}
{"op":"mcm","clk":"11540495824","pt":1719495171257,"mc":[{"id":"1.230180114","rc":[{"atl":[[10.5,1.7]],"id":44213406}],"con":true,"img":false}]}
{"op":"mcm","clk":"11540495836","pt":1719495171357,"mc":[{"id":"1.230180114","rc":[{"atl":[[10.5,21.7],[11,0]],"id":44213406}],"con":true,"img":false}]}
{"op":"mcm","clk":"11540495848","pt":1719495171461,"mc":[{"id":"1.230180114","rc":[{"atl":[[10.5,20]],"id":44213406}],"con":true,"img":false}]}
{"op":"mcm","clk":"11540495855","pt":1719495171561,"mc":[{"id":"1.230180114","rc":[{"atl":[[150,10.8]],"id":44213406}],"con":true,"img":false}]}
{"op":"mcm","clk":"11540495876","pt":1719495171767,"mc":[{"id":"1.230180114","rc":[{"atl":[[150,9.1]],"id":44213406}],"con":true,"img":false}]}
{"op":"mcm","clk":"11540495887","pt":1719495171872,"mc":[{"id":"1.230180114","rc":[{"atl":[[10,1.7]],"id":44213406}],"con":true,"img":false}]}
{"op":"mcm","clk":"11540495896","pt":1719495171971,"mc":[{"id":"1.230180114","rc":[{"atl":[[10,21.7],[10.5,0]],"id":44213406}],"con":true,"img":false}]}
{"op":"mcm","clk":"11540495915","pt":1719495172133,"mc":[{"id":"1.230180114","rc":[{"atl":[[10,20]],"id":44213406}],"con":true,"img":false}]}
{"op":"mcm","clk":"11540495923","pt":1719495172243,"mc":[{"id":"1.230180114","rc":[{"atl":[[150,10.8]],"id":44213406}],"con":true,"img":false}]}
{"op":"mcm","clk":"11540495929","pt":1719495172340,"mc":[{"id":"1.230180114","rc":[{"atl":[[150,9.1]],"id":44213406}],"con":true,"img":false}]}
{"op":"mcm","clk":"11540495938","pt":1719495172448,"mc":[{"id":"1.230180114","rc":[{"atb":[[1.84,0]],"id":44213406},{"atl":[[9.8,1.7]],"id":44213406}],"con":true,"img":false}]}
{"op":"mcm","clk":"11540495958","pt":1719495172660,"mc":[{"id":"1.230180114","rc":[{"atl":[[10,0],[9.8,21.7]],"id":44213406}],"con":true,"img":false}]}
{"op":"mcm","clk":"11540495967","pt":1719495172753,"mc":[{"id":"1.230180114","rc":[{"atl":[[23,0],[9.8,20]],"id":44213406}],"con":true,"img":false}]}
{"op":"mcm","clk":"11540495978","pt":1719495172864,"mc":[{"id":"1.230180114","rc":[{"atl":[[150,10.8]],"id":44213406}],"con":true,"img":false}]}
{"op":"mcm","clk":"11540495990","pt":1719495172964,"mc":[{"id":"1.230180114","rc":[{"atl":[[150,9.1]],"id":44213406}],"con":true,"img":false}]}
{"op":"mcm","clk":"11540495999","pt":1719495173076,"mc":[{"id":"1.230180114","rc":[{"atl":[[9.6,1.7]],"id":44213406}],"con":true,"img":false}]}
{"op":"mcm","clk":"11540496010","pt":1719495173162,"mc":[{"id":"1.230180114","rc":[{"atl":[[9.6,21.7],[9.8,0]],"id":44213406}],"con":true,"img":false}]}
{"op":"mcm","clk":"11540496022","pt":1719495173272,"mc":[{"id":"1.230180114","rc":[{"atl":[[9.6,20]],"id":44213406}],"con":true,"img":false}]}
{"op":"mcm","clk":"11540496033","pt":1719495173371,"mc":[{"id":"1.230180114","rc":[{"atl":[[150,10.8]],"id":44213406}],"con":true,"img":false}]}
{"op":"mcm","clk":"11540496049","pt":1719495173526,"mc":[{"id":"1.230180114","rc":[{"atl":[[150,9.1]],"id":44213406}],"con":true,"img":false}]}
{"op":"mcm","clk":"11540496060","pt":1719495173648,"mc":[{"id":"1.230180114","rc":[{"atl":[[9.4,1.7]],"id":44213406}],"con":true,"img":false}]}
{"op":"mcm","clk":"11540496080","pt":1719495173852,"mc":[{"id":"1.230180114","rc":[{"atl":[[9.6,0],[9.4,21.7]],"id":44213406}],"con":true,"img":false}]}
{"op":"mcm","clk":"11540496089","pt":1719495173947,"mc":[{"id":"1.230180114","rc":[{"atb":[[1.86,0]],"id":44213406}],"con":true,"img":false}]}
{"op":"mcm","clk":"11540496095","pt":1719495174051,"mc":[{"id":"1.230180114","rc":[{"atl":[[9.4,20]],"id":44213406}],"con":true,"img":false}]}
{"op":"mcm","clk":"11540496104","pt":1719495174154,"mc":[{"id":"1.230180114","rc":[{"atl":[[150,10.8]],"id":44213406}],"con":true,"img":false}]}
{"op":"mcm","clk":"11540496108","pt":1719495174259,"mc":[{"id":"1.230180114","rc":[{"atl":[[150,9.1]],"id":44213406}],"con":true,"img":false}]}
{"op":"mcm","clk":"11540496115","pt":1719495174360,"mc":[{"id":"1.230180114","rc":[{"atl":[[9.2,1.7]],"id":44213406}],"con":true,"img":false}]}
{"op":"mcm","clk":"11540496121","pt":1719495174463,"mc":[{"id":"1.230180114","rc":[{"atl":[[9.2,21.7],[9.4,0]],"id":44213406}],"con":true,"img":false}]}
{"op":"mcm","clk":"11540496129","pt":1719495174564,"mc":[{"id":"1.230180114","rc":[{"atb":[[1.88,1.14]],"id":44213406},{"atl":[[9.2,20]],"id":44213406}],"con":true,"img":false}]}
{"op":"mcm","clk":"11540496135","pt":1719495174678,"mc":[{"id":"1.230180114","rc":[{"atl":[[150,10.8]],"id":44213406}],"con":true,"img":false}]}
{"op":"mcm","clk":"11540496148","pt":1719495174832,"mc":[{"id":"1.230180114","rc":[{"atl":[[150,9.1]],"id":44213406}],"con":true,"img":false}]}
{"op":"mcm","clk":"11540496154","pt":1719495174931,"mc":[{"id":"1.230180114","rc":[{"atb":[[1.87,0]],"id":44213406},{"atl":[[9,1.7]],"id":44213406}],"con":true,"img":false}]}
{"op":"mcm","clk":"11540496168","pt":1719495175044,"mc":[{"id":"1.230180114","rc":[{"atb":[[1.76,2]],"id":44213406},{"atl":[[9,21.7]],"id":44213406}],"con":true,"img":false}]}
{"op":"mcm","clk":"11540496181","pt":1719495175149,"mc":[{"id":"1.230180114","rc":[{"atl":[[9.2,0]],"id":44213406}],"con":true,"img":false}]}
{"op":"mcm","clk":"11540496199","pt":1719495175351,"mc":[{"id":"1.230180114","rc":[{"atl":[[9,20]],"id":44213406}],"con":true,"img":false}]}
{"op":"mcm","clk":"11540496207","pt":1719495175458,"mc":[{"id":"1.230180114","rc":[{"atl":[[150,10.8]],"id":44213406}],"con":true,"img":false}]}
{"op":"mcm","clk":"11540496220","pt":1719495175566,"mc":[{"id":"1.230180114","rc":[{"atl":[[150,9.1]],"id":44213406}],"con":true,"img":false}]}
{"op":"mcm","clk":"11540496230","pt":1719495175665,"mc":[{"id":"1.230180114","rc":[{"atl":[[8.8,1.7]],"id":44213406}],"con":true,"img":false}]}
{"op":"mcm","clk":"11540496239","pt":1719495175767,"mc":[{"id":"1.230180114","rc":[{"atl":[[9,0],[8.8,21.7]],"id":44213406}],"con":true,"img":false}]}
{"op":"mcm","clk":"11540496246","pt":1719495175868,"mc":[{"id":"1.230180114","rc":[{"atl":[[8.8,20]],"id":44213406}],"con":true,"img":false}]}
{"op":"mcm","clk":"11540496258","pt":1719495175972,"mc":[{"id":"1.230180114","rc":[{"atl":[[150,10.8]],"id":44213406}],"con":true,"img":false}]}
{"op":"mcm","clk":"11540496267","pt":1719495176094,"mc":[{"id":"1.230180114","rc":[{"atl":[[150,9.1]],"id":44213406}],"con":true,"img":false}]}
{"op":"mcm","clk":"11540496276","pt":1719495176172,"mc":[{"id":"1.230180114","rc":[{"atl":[[8.6,1.7]],"id":44213406}],"con":true,"img":false}]}
{"op":"mcm","clk":"11540496285","pt":1719495176277,"mc":[{"id":"1.230180114","rc":[{"atl":[[8.6,21.7],[8.8,0]],"id":44213406}],"con":true,"img":false}]}
{"op":"mcm","clk":"11540496296","pt":1719495176380,"mc":[{"id":"1.230180114","rc":[{"atl":[[8.6,20]],"id":44213406}],"con":true,"img":false}]}
{"op":"mcm","clk":"11540496303","pt":1719495176483,"mc":[{"id":"1.230180114","rc":[{"atb":[[1.76,0]],"id":44213406},{"atl":[[150,10.8]],"id":44213406}],"con":true,"img":false}]}
{"op":"mcm","clk":"11540496313","pt":1719495176552,"mc":[{"id":"1.230180114","rc":[{"atb":[[1.89,2]],"id":44213406},{"atl":[[150,9.1]],"id":44213406}],"con":true,"img":false}]}
{"op":"mcm","clk":"11540496325","pt":1719495176654,"mc":[{"id":"1.230180114","rc":[{"atl":[[8.4,1.7]],"id":44213406}],"con":true,"img":false}]}
{"op":"mcm","clk":"11540496350","pt":1719495176853,"mc":[{"id":"1.230180114","rc":[{"atl":[[8.6,0],[8.4,21.7]],"id":44213406}],"con":true,"img":false}]}
{"op":"mcm","clk":"11540496362","pt":1719495176956,"mc":[{"id":"1.230180114","rc":[{"atb":[[1.89,3.99]],"id":44213406}],"con":true,"img":false}]}
{"op":"mcm","clk":"11540496374","pt":1719495177056,"mc":[{"id":"1.230180114","rc":[{"atl":[[8.4,20]],"id":44213406}],"con":true,"img":false}]}
{"op":"mcm","clk":"11540496392","pt":1719495177164,"mc":[{"id":"1.230180114","rc":[{"atl":[[150,10.8]],"id":44213406}],"con":true,"img":false}]}
{"op":"mcm","clk":"11540496408","pt":1719495177363,"mc":[{"id":"1.230180114","rc":[{"atl":[[150,9.1]],"id":44213406}],"con":true,"img":false}]}
{"op":"mcm","clk":"11540496420","pt":1719495177464,"mc":[{"id":"1.230180114","rc":[{"atl":[[8.2,1.7]],"id":44213406}],"con":true,"img":false}]}
{"op":"mcm","clk":"11540496435","pt":1719495177578,"mc":[{"id":"1.230180114","rc":[{"atl":[[8.2,21.7],[8.4,0]],"id":44213406}],"con":true,"img":false}]}
{"op":"mcm","clk":"11540496446","pt":1719495177673,"mc":[{"id":"1.230180114","rc":[{"atl":[[8.2,20]],"id":44213406}],"con":true,"img":false}]}
{"op":"mcm","clk":"11540496455","pt":1719495177780,"mc":[{"id":"1.230180114","rc":[{"atl":[[150,10.8]],"id":44213406}],"con":true,"img":false}]}
{"op":"mcm","clk":"11540496464","pt":1719495177837,"mc":[{"id":"1.230180114","rc":[{"atl":[[150,9.1]],"id":44213406}],"con":true,"img":false}]}
{"op":"mcm","clk":"11540496474","pt":1719495177941,"mc":[{"id":"1.230180114","rc":[{"atl":[[8,1.7]],"id":44213406}],"con":true,"img":false}]}
{"op":"mcm","clk":"11540496485","pt":1719495178047,"mc":[{"id":"1.230180114","rc":[{"atl":[[8,21.7],[8.2,0]],"id":44213406}],"con":true,"img":false}]}
{"op":"mcm","clk":"11540496498","pt":1719495178148,"mc":[{"id":"1.230180114","rc":[{"atl":[[8,20]],"id":44213406}],"con":true,"img":false}]}
{"op":"mcm","clk":"11540496510","pt":1719495178253,"mc":[{"id":"1.230180114","rc":[{"atl":[[150,10.8]],"id":44213406}],"con":true,"img":false}]}
{"op":"mcm","clk":"11540496531","pt":1719495178451,"mc":[{"id":"1.230180114","rc":[{"atl":[[150,9.1]],"id":44213406}],"con":true,"img":false}]}
{"op":"mcm","clk":"11540496537","pt":1719495178556,"mc":[{"id":"1.230180114","rc":[{"atl":[[7.8,1.7]],"id":44213406}],"con":true,"img":false}]}
{"op":"mcm","clk":"11540496554","pt":1719495178759,"mc":[{"id":"1.230180114","rc":[{"atl":[[8,0],[7.8,21.7]],"id":44213406}],"con":true,"img":false}]}
{"op":"mcm","clk":"11540496560","pt":1719495178877,"mc":[{"id":"1.230180114","rc":[{"atl":[[7.8,20]],"id":44213406}],"con":true,"img":false}]}
{"op":"mcm","clk":"11540496568","pt":1719495178983,"mc":[{"id":"1.230180114","rc":[{"atl":[[150,10.8]],"id":44213406}],"con":true,"img":false}]}
{"op":"mcm","clk":"11540496576","pt":1719495179084,"mc":[{"id":"1.230180114","rc":[{"atl":[[150,9.1]],"id":44213406}],"con":true,"img":false}]}
{"op":"mcm","clk":"11540496584","pt":1719495179178,"mc":[{"id":"1.230180114","rc":[{"atl":[[7.6,1.7]],"id":44213406}],"con":true,"img":false}]}
{"op":"mcm","clk":"11540496591","pt":1719495179284,"mc":[{"id":"1.230180114","rc":[{"atl":[[7.6,21.7],[7.8,0]],"id":44213406}],"con":true,"img":false}]}
{"op":"mcm","clk":"11540496597","pt":1719495179337,"mc":[{"id":"1.230180114","rc":[{"atl":[[7.6,20]],"id":44213406}],"con":true,"img":false}]}
{"op":"mcm","clk":"11540496602","pt":1719495179447,"mc":[{"id":"1.230180114","rc":[{"atl":[[150,10.8]],"id":44213406}],"con":true,"img":false}]}
{"op":"mcm","clk":"11540496610","pt":1719495179547,"mc":[{"id":"1.230180114","rc":[{"atl":[[150,9.1]],"id":44213406}],"con":true,"img":false}]}
{"op":"mcm","clk":"11540496615","pt":1719495179648,"mc":[{"id":"1.230180114","rc":[{"atl":[[7.4,1.7]],"id":44213406}],"con":true,"img":false}]}
{"op":"mcm","clk":"11540496621","pt":1719495179762,"mc":[{"id":"1.230180114","rc":[{"atl":[[7.4,21.7]],"id":44213406}],"con":true,"img":false}]}
{"op":"mcm","clk":"11540496630","pt":1719495179859,"mc":[{"id":"1.230180114","rc":[{"atl":[[7.6,0]],"id":44213406}],"con":true,"img":false}]}
{"op":"mcm","clk":"11540496649","pt":1719495180072,"mc":[{"id":"1.230180114","rc":[{"atl":[[7.4,20]],"id":44213406}],"con":true,"img":false}]}
{"op":"mcm","clk":"11540496658","pt":1719495180167,"mc":[{"id":"1.230180114","rc":[{"atl":[[150,10.8]],"id":44213406}],"con":true,"img":false}]}
{"op":"mcm","clk":"11540496669","pt":1719495180283,"mc":[{"id":"1.230180114","rc":[{"atl":[[150,9.1]],"id":44213406}],"con":true,"img":false}]}
{"op":"mcm","clk":"11540496680","pt":1719495180384,"mc":[{"id":"1.230180114","rc":[{"atl":[[7.2,1.7]],"id":44213406}],"con":true,"img":false}]}
{"op":"mcm","clk":"11540496702","pt":1719495180594,"mc":[{"id":"1.230180114","rc":[{"atl":[[7.2,21.7],[7.4,0]],"id":44213406}],"con":true,"img":false}]}
{"op":"mcm","clk":"11540496711","pt":1719495180687,"mc":[{"id":"1.230180114","rc":[{"atl":[[7.2,20]],"id":44213406}],"con":true,"img":false}]}
{"op":"mcm","clk":"11540496721","pt":1719495180748,"mc":[{"id":"1.230180114","rc":[{"atl":[[150,10.8]],"id":44213406}],"con":true,"img":false}]}
{"op":"mcm","clk":"11540496726","pt":1719495180838,"mc":[{"id":"1.230180114","rc":[{"atl":[[150,9.1]],"id":44213406}],"con":true,"img":false}]}
{"op":"mcm","clk":"11540496738","pt":1719495180951,"mc":[{"id":"1.230180114","rc":[{"atl":[[7,1.7]],"id":44213406}],"con":true,"img":false}]}
{"op":"mcm","clk":"11540496752","pt":1719495181063,"mc":[{"id":"1.230180114","rc":[{"atl":[[7.2,0],[7,21.7]],"id":44213406}],"con":true,"img":false}]}
{"op":"mcm","clk":"11540496771","pt":1719495181262,"mc":[{"id":"1.230180114","rc":[{"atl":[[7,20]],"id":44213406}],"con":true,"img":false}]}
{"op":"mcm","clk":"11540496778","pt":1719495181371,"mc":[{"id":"1.230180114","rc":[{"atl":[[150,10.8]],"id":44213406}],"con":true,"img":false}]}
{"op":"mcm","clk":"11540496790","pt":1719495181469,"mc":[{"id":"1.230180114","rc":[{"atl":[[150,9.1]],"id":44213406}],"con":true,"img":false}]}
{"op":"mcm","clk":"11540496800","pt":1719495181575,"mc":[{"id":"1.230180114","rc":[{"atl":[[6.8,1.7]],"id":44213406}],"con":true,"img":false}]}
{"op":"mcm","clk":"11540496816","pt":1719495181775,"mc":[{"id":"1.230180114","rc":[{"atl":[[6.8,21.7],[7,0]],"id":44213406}],"con":true,"img":false}]}
{"op":"mcm","clk":"11540496827","pt":1719495181890,"mc":[{"id":"1.230180114","rc":[{"atl":[[6.8,20]],"id":44213406}],"con":true,"img":false}]}
{"op":"mcm","clk":"11540496836","pt":1719495181987,"mc":[{"id":"1.230180114","rc":[{"atl":[[150,10.8]],"id":44213406}],"con":true,"img":false}]}
{"op":"mcm","clk":"11540496852","pt":1719495182056,"mc":[{"id":"1.230180114","rc":[{"atl":[[150,9.1]],"id":44213406}],"con":true,"img":false}]}
{"op":"mcm","clk":"11540496861","pt":1719495182153,"mc":[{"id":"1.230180114","rc":[{"atl":[[6.6,1.7]],"id":44213406}],"con":true,"img":false}]}
{"op":"mcm","clk":"11540496874","pt":1719495182256,"mc":[{"id":"1.230180114","rc":[{"atl":[[6.8,0],[6.6,21.7]],"id":44213406}],"con":true,"img":false}]}
{"op":"mcm","clk":"11540496894","pt":1719495182455,"mc":[{"id":"1.230180114","rc":[{"atl":[[6.6,20]],"id":44213406}],"con":true,"img":false}]}
{"op":"mcm","clk":"11540496913","pt":1719495182576,"mc":[{"id":"1.230180114","rc":[{"atl":[[150,10.8]],"id":44213406}],"con":true,"img":false}]}
{"op":"mcm","clk":"11540496923","pt":1719495182679,"mc":[{"id":"1.230180114","rc":[{"atl":[[150,9.1]],"id":44213406}],"con":true,"img":false}]}
{"op":"mcm","clk":"11540496935","pt":1719495182779,"mc":[{"id":"1.230180114","rc":[{"atl":[[6.4,1.7]],"id":44213406}],"con":true,"img":false}]}
{"op":"mcm","clk":"11540496953","pt":1719495182978,"mc":[{"id":"1.230180114","rc":[{"atl":[[6.4,21.7],[6.6,0]],"id":44213406}],"con":true,"img":false}]}
{"op":"mcm","clk":"11540496967","pt":1719495183096,"mc":[{"id":"1.230180114","rc":[{"atl":[[6.4,20]],"id":44213406}],"con":true,"img":false}]}
{"op":"mcm","clk":"11540496978","pt":1719495183134,"mc":[{"id":"1.230180114","rc":[{"atl":[[150,10.8]],"id":44213406}],"con":true,"img":false}]}
{"op":"mcm","clk":"11540496991","pt":1719495183253,"mc":[{"id":"1.230180114","rc":[{"atl":[[150,9.1]],"id":44213406}],"con":true,"img":false}]}
{"op":"mcm","clk":"11540497001","pt":1719495183343,"mc":[{"id":"1.230180114","rc":[{"atl":[[6.2,1.7]],"id":44213406}],"con":true,"img":false}]}
{"op":"mcm","clk":"11540497024","pt":1719495183559,"mc":[{"id":"1.230180114","rc":[{"atl":[[6.2,21.7]],"id":44213406}],"con":true,"img":false}]}
{"op":"mcm","clk":"11540497032","pt":1719495183654,"mc":[{"id":"1.230180114","rc":[{"atl":[[6.4,0]],"id":44213406}],"con":true,"img":false}]}
{"op":"mcm","clk":"11540497059","pt":1719495183871,"mc":[{"id":"1.230180114","rc":[{"atl":[[6.2,20]],"id":44213406}],"con":true,"img":false}]}
{"op":"mcm","clk":"11540497067","pt":1719495183965,"mc":[{"id":"1.230180114","rc":[{"atl":[[150,10.8]],"id":44213406}],"con":true,"img":false}]}
{"op":"mcm","clk":"11540497079","pt":1719495184085,"mc":[{"id":"1.230180114","rc":[{"atl":[[150,9.1]],"id":44213406}],"con":true,"img":false}]}
{"op":"mcm","clk":"11540497091","pt":1719495184172,"mc":[{"id":"1.230180114","rc":[{"atl":[[6,1.7]],"id":44213406}],"con":true,"img":false}]}
{"op":"mcm","clk":"11540497118","pt":1719495184397,"mc":[{"id":"1.230180114","rc":[{"atl":[[6.2,0],[6,21.7]],"id":44213406}],"con":true,"img":false}]}
{"op":"mcm","clk":"11540497127","pt":1719495184444,"mc":[{"id":"1.230180114","rc":[{"atl":[[6,20]],"id":44213406}],"con":true,"img":false}]}
{"op":"mcm","clk":"11540497138","pt":1719495184548,"mc":[{"id":"1.230180114","rc":[{"atl":[[150,10.8]],"id":44213406}],"con":true,"img":false}]}
{"op":"mcm","clk":"11540497151","pt":1719495184748,"mc":[{"id":"1.230180114","rc":[{"atl":[[150,9.1]],"id":44213406}],"con":true,"img":false}]}
{"op":"mcm","clk":"11540497161","pt":1719495184858,"mc":[{"id":"1.230180114","rc":[{"atl":[[5.9,1.7]],"id":44213406}],"con":true,"img":false}]}
{"op":"mcm","clk":"11540497176","pt":1719495184987,"mc":[{"id":"1.230180114","rc":[{"atl":[[6,0],[5.9,21.7]],"id":44213406}],"con":true,"img":false}]}
{"op":"mcm","clk":"11540497200","pt":1719495185166,"mc":[{"id":"1.230180114","rc":[{"atl":[[5.9,20]],"id":44213406}],"con":true,"img":false}]}
{"op":"mcm","clk":"11540497212","pt":1719495185279,"mc":[{"id":"1.230180114","rc":[{"atl":[[150,10.8]],"id":44213406}],"con":true,"img":false}]}
{"op":"mcm","clk":"11540497229","pt":1719495185476,"mc":[{"id":"1.230180114","rc":[{"atl":[[150,9.1]],"id":44213406}],"con":true,"img":false}]}
{"op":"mcm","clk":"11540497243","pt":1719495185578,"mc":[{"id":"1.230180114","rc":[{"atl":[[5.8,1.7]],"id":44213406}],"con":true,"img":false}]}
{"op":"mcm","clk":"11540497254","pt":1719495185631,"mc":[{"id":"1.230180114","rc":[{"atl":[[5.8,21.7],[5.9,0]],"id":44213406}],"con":true,"img":false}]}
{"op":"mcm","clk":"11540497270","pt":1719495185841,"mc":[{"id":"1.230180114","rc":[{"atl":[[5.8,20]],"id":44213406}],"con":true,"img":false}]}
{"op":"mcm","clk":"11540497277","pt":1719495185943,"mc":[{"id":"1.230180114","rc":[{"atl":[[150,10.8]],"id":44213406}],"con":true,"img":false}]}
{"op":"mcm","clk":"11540497303","pt":1719495186168,"mc":[{"id":"1.230180114","rc":[{"atl":[[150,9.1]],"id":44213406}],"con":true,"img":false}]}
{"op":"mcm","clk":"11540497311","pt":1719495186255,"mc":[{"id":"1.230180114","rc":[{"atl":[[5.7,1.7]],"id":44213406}],"con":true,"img":false}]}
{"op":"mcm","clk":"11540497323","pt":1719495186360,"mc":[{"id":"1.230180114","rc":[{"atl":[[5.8,0],[5.7,21.7]],"id":44213406}],"con":true,"img":false}]}
{"op":"mcm","clk":"11540497344","pt":1719495186572,"mc":[{"id":"1.230180114","rc":[{"atl":[[5.7,20]],"id":44213406}],"con":true,"img":false}]}
{"op":"mcm","clk":"11540497356","pt":1719495186671,"mc":[{"id":"1.230180114","rc":[{"atl":[[150,10.8]],"id":44213406}],"con":true,"img":false}]}
{"op":"mcm","clk":"11540497376","pt":1719495186882,"mc":[{"id":"1.230180114","rc":[{"atl":[[150,9.1]],"id":44213406}],"con":true,"img":false}]}
{"op":"mcm","clk":"11540497381","pt":1719495186965,"mc":[{"id":"1.230180114","rc":[{"atl":[[5.6,1.7]],"id":44213406}],"con":true,"img":false}]}
{"op":"mcm","clk":"11540497386","pt":1719495187070,"mc":[{"id":"1.230180114","rc":[{"atl":[[5.6,21.7]],"id":44213406}],"con":true,"img":false}]}
{"op":"mcm","clk":"11540497401","pt":1719495187201,"mc":[{"id":"1.230180114","rc":[{"atl":[[5.7,0]],"id":44213406}],"con":true,"img":false}]}
{"op":"mcm","clk":"11540497420","pt":1719495187343,"mc":[{"id":"1.230180114","rc":[{"atl":[[5.6,20]],"id":44213406}],"con":true,"img":false}]}
{"op":"mcm","clk":"11540497428","pt":1719495187449,"mc":[{"id":"1.230180114","rc":[{"atl":[[150,10.8]],"id":44213406}],"con":true,"img":false}]}
{"op":"mcm","clk":"11540497446","pt":1719495187655,"mc":[{"id":"1.230180114","rc":[{"atl":[[150,9.1]],"id":44213406}],"con":true,"img":false}]}
{"op":"mcm","clk":"11540497457","pt":1719495187757,"mc":[{"id":"1.230180114","rc":[{"atl":[[5.5,1.7]],"id":44213406}],"con":true,"img":false}]}
{"op":"mcm","clk":"11540497467","pt":1719495187860,"mc":[{"id":"1.230180114","rc":[{"atl":[[5.6,0],[5.5,21.7]],"id":44213406}],"con":true,"img":false}]}
{"op":"mcm","clk":"11540497484","pt":1719495188073,"mc":[{"id":"1.230180114","rc":[{"atl":[[5.5,20]],"id":44213406}],"con":true,"img":false}]}
{"op":"mcm","clk":"11540497495","pt":1719495188168,"mc":[{"id":"1.230180114","rc":[{"atl":[[150,10.8]],"id":44213406}],"con":true,"img":false}]}
{"op":"mcm","clk":"11540497513","pt":1719495188380,"mc":[{"id":"1.230180114","rc":[{"atl":[[150,9.1]],"id":44213406}],"con":true,"img":false}]}
{"op":"mcm","clk":"11540497520","pt":1719495188487,"mc":[{"id":"1.230180114","rc":[{"atl":[[5.4,1.7]],"id":44213406}],"con":true,"img":false}]}
{"op":"mcm","clk":"11540497548","pt":1719495188685,"mc":[{"id":"1.230180114","rc":[{"atl":[[5.4,21.7]],"id":44213406},{"spn":3.64,"spf":"NaN","id":44213406}],"con":true,"img":false}]}
{"op":"mcm","clk":"11540497557","pt":1719495188749,"mc":[{"id":"1.230180114","rc":[{"atl":[[5.5,0]],"id":44213406}],"con":true,"img":false}]}
{"op":"mcm","clk":"11540497567","pt":1719495188845,"mc":[{"id":"1.230180114","rc":[{"atl":[[5.4,20]],"id":44213406}],"con":true,"img":false}]}
{"op":"mcm","clk":"11540497574","pt":1719495188943,"mc":[{"id":"1.230180114","rc":[{"atl":[[150,10.8]],"id":44213406}],"con":true,"img":false}]}
{"op":"mcm","clk":"11540497583","pt":1719495189059,"mc":[{"id":"1.230180114","rc":[{"atl":[[150,9.1]],"id":44213406}],"con":true,"img":false}]}
{"op":"mcm","clk":"11540497592","pt":1719495189149,"mc":[{"id":"1.230180114","rc":[{"atl":[[5.3,1.7]],"id":44213406}],"con":true,"img":false}]}
{"op":"mcm","clk":"11540497598","pt":1719495189252,"mc":[{"id":"1.230180114","rc":[{"atl":[[5.3,21.7]],"id":44213406}],"con":true,"img":false}]}
{"op":"mcm","clk":"11540497604","pt":1719495189363,"mc":[{"id":"1.230180114","rc":[{"atl":[[5.4,0]],"id":44213406}],"con":true,"img":false}]}
{"op":"mcm","clk":"11540497621","pt":1719495189563,"mc":[{"id":"1.230180114","rc":[{"atl":[[5.3,20]],"id":44213406}],"con":true,"img":false}]}
{"op":"mcm","clk":"11540497630","pt":1719495189668,"mc":[{"id":"1.230180114","rc":[{"atl":[[150,10.8]],"id":44213406}],"con":true,"img":false}]}
{"op":"mcm","clk":"11540497649","pt":1719495189875,"mc":[{"id":"1.230180114","rc":[{"atb":[[1.88,0]],"id":44213406},{"atl":[[150,9.1]],"id":44213406}],"con":true,"img":false}]}
{"op":"mcm","clk":"11540497662","pt":1719495189975,"mc":[{"id":"1.230180114","rc":[{"atl":[[5.2,1.7]],"id":44213406}],"con":true,"img":false}]}
{"op":"mcm","clk":"11540497677","pt":1719495190186,"mc":[{"id":"1.230180114","rc":[{"atl":[[5.2,21.7]],"id":44213406}],"con":true,"img":false}]}
