{"op":"mcm","clk":"11536832966","pt":1719431775485,"mc":[{"id":"1.230180122","marketDefinition":{"bspMarket":true,"turnInPlayEnabled":false,"persistenceEnabled":false,"marketBaseRate":5.0,"eventId":"33376437","eventTypeId":"4339","numberOfWinners":1,"bettingType":"ODDS","marketType":"WIN","marketTime":"2024-06-27T15:07:00.000Z","suspendTime":"2024-06-27T15:07:00.000Z","bspReconciled":false,"complete":true,"inPlay":false,"crossMatching":false,"runnersVoidable":false,"numberOfActiveRunners":6,"betDelay":0,"status":"OPEN","runners":[{"status":"ACTIVE","sortPriority":1,"id":67487132,"name":"1. Salacres Belleza"},{"status":"ACTIVE","sortPriority":2,"id":43318163,"name":"2. Walking Dead"},{"status":"ACTIVE","sortPriority":3,"id":40028187,"name":"3. The Grafter"},{"status":"ACTIVE","sortPriority":4,"id":70396461,"name":"4. Late Yahoo"},{"status":"ACTIVE","sortPriority":5,"id":47703807,"name":"5. Fabulous Twirl"},{"status":"ACTIVE","sortPriority":6,"id":57697855,"name":"6. Salacres Driller"}],"regulators":["MR_INT"],"venue":"Towcester","countryCode":"GB","discountAllowed":false,"timezone":"Europe/London","openDate":"2024-06-27T13:33:00.000Z","version":5994767067,"name":"A5 500m","eventName":"Towcester 27th Jun"},"rc":[],"con":true,"img":false}]}
{"op":"mcm","clk":"11536833115","pt":1719431777496,"mc":[{"id":"1.230180122","marketDefinition":{"bspMarket":true,"turnInPlayEnabled":false,"persistenceEnabled":false,"marketBaseRate":5.0,"eventId":"33376437","eventTypeId":"4339","numberOfWinners":1,"bettingType":"ODDS","marketType":"WIN","marketTime":"2024-06-27T15:07:00.000Z","suspendTime":"2024-06-27T15:07:00.000Z","bspReconciled":false,"complete":true,"inPlay":false,"crossMatching":false,"runnersVoidable":false,"numberOfActiveRunners":6,"betDelay":0,"status":"OPEN","runners":[{"status":"ACTIVE","sortPriority":1,"id":67487132,"name":"1. Salacres Belleza"},{"status":"ACTIVE","sortPriority":2,"id":43318163,"name":"2. Walking Dead"},{"status":"ACTIVE","sortPriority":3,"id":40028187,"name":"3. The Grafter"},{"status":"ACTIVE","sortPriority":4,"id":70396461,"name":"4. Late Yahoo"},{"status":"ACTIVE","sortPriority":5,"id":47703807,"name":"5. Fabulous Twirl"},{"status":"ACTIVE","sortPriority":6,"id":57697855,"name":"6. Salacres Driller"}],"regulators":["MR_INT"],"venue":"Towcester","countryCode":"GB","discountAllowed":true,"timezone":"Europe/London","openDate":"2024-06-27T13:33:00.000Z","version":5994767067,"name":"A5 500m","eventName":"Towcester 27th Jun"},"rc":[],"con":true,"img":false}]}
{"op":"mcm","clk":"11537083773","pt":1719435430993,"mc":[{"id":"1.230180122","rc":[{"atb":[[1.03,10.99]],"id":40028187},{"atl":[[990,0.84]],"id":40028187},{"spn":495.51,"spf":"NaN","id":40028187},{"atb":[[1.02,16.48]],"id":43318163},{"atl":[[1000,0.84]],"id":43318163},{"spn":500.51,"spf":"NaN","id":43318163},{"atb":[[1.02,16.48]],"id":47703807},{"atl":[[1000,0.84]],"id":47703807},{"spn":500.51,"spf":"NaN","id":47703807},{"atb":[[1.01,32.96]],"id":67487132},{"atl":[[990,0.84]],"id":67487132},{"spn":495.5,"spf":"NaN","id":67487132},{"atb":[[1.02,16.48]],"id":70396461},{"atl":[[1000,0.84]],"id":70396461},{"spn":500.51,"spf":"NaN","id":70396461},{"atb":[[1.01,32.96]],"id":57697855},{"atl":[[990,0.84]],"id":57697855},{"spn":495.5,"spf":"NaN","id":57697855}],"con":true,"img":false}]}
{"op":"mcm","clk":"11537233734","pt":1719437882655,"mc":[{"id":"1.230180122","marketDefinition":{"bspMarket":true,"turnInPlayEnabled":false,"persistenceEnabled":false,"marketBaseRate":5.0,"eventId":"33376437","eventTypeId":"4339","numberOfWinners":1,"bettingType":"ODDS","marketType":"WIN","marketTime":"2024-06-27T15:07:00.000Z","suspendTime":"2024-06-27T15:07:00.000Z","bspReconciled":false,"complete":true,"inPlay":false,"crossMatching":false,"runnersVoidable":false,"numberOfActiveRunners":6,"betDelay":0,"status":"OPEN","runners":[{"status":"ACTIVE","sortPriority":1,"id":67487132,"name":"1. Salacres Belleza"},{"status":"ACTIVE","sortPriority":2,"id":43318163,"name":"2. Walking Dead"},{"status":"ACTIVE","sortPriority":3,"id":40028187,"name":"3. The Grafter"},{"status":"ACTIVE","sortPriority":4,"id":70396461,"name":"4. Late Yahoo"},{"status":"ACTIVE","sortPriority":5,"id":47703807,"name":"5. Fabulous Twirl"},{"status":"ACTIVE","sortPriority":6,"id":57697855,"name":"6. Salacres Driller"}],"regulators":["MR_INT"],"venue":"Towcester","countryCode":"GB","discountAllowed":true,"timezone":"Europe/London","openDate":"2024-06-27T13:33:00.000Z","version":5994767067,"name":"A5 500m","eventName":"Towcester 27th Jun"},"rc":[{"atb":[[1.03,10.99]],"id":40028187},{"atl":[[990,0.84]],"id":40028187},{"spn":495.51,"spf":"NaN","id":40028187},{"atb":[[1.02,16.48]],"id":43318163},{"atl":[[1000,0.84]],"id":43318163},{"spn":500.51,"spf":"NaN","id":43318163},{"atb":[[1.02,16.48]],"id":47703807},{"atl":[[1000,0.84]],"id":47703807},{"spn":500.51,"spf":"NaN","id":47703807},{"atb":[[1.01,32.96]],"id":67487132},{"atl":[[990,0.84]],"id":67487132},{"spn":495.5,"spf":"NaN","id":67487132},{"atb":[[1.02,16.48]],"id":70396461},{"atl":[[1000,0.84]],"id":70396461},{"spn":500.51,"spf":"NaN","id":70396461},{"atb":[[1.01,32.96]],"id":57697855},{"atl":[[990,0.84]],"id":57697855},{"spn":495.5,"spf":"NaN","id":57697855}],"con":true,"img":true}]}
{"op":"mcm","clk":"11537302003","pt":1719439028128,"mc":[{"id":"1.230180122","rc":[{"atb":[[1.03,10.99]],"id":40028187},{"atl":[[990,0.17]],"id":40028187},{"atb":[[1.02,16.48]],"id":43318163},{"atl":[[1000,0.17]],"id":43318163},{"atb":[[1.02,16.48]],"id":47703807},{"atl":[[1000,0.17]],"id":47703807},{"atb":[[1.01,32.96]],"id":67487132},{"atl":[[990,0.17]],"id":67487132},{"atb":[[1.02,16.48]],"id":70396461},{"atl":[[1000,0.17]],"id":70396461},{"atb":[[1.01,32.96]],"id":57697855},{"atl":[[990,0.17]],"id":57697855}],"con":true,"img":false}]}
{"op":"mcm","clk":"11537574885","pt":1719443282706,"mc":[{"id":"1.230180122","marketDefinition":{"bspMarket":true,"turnInPlayEnabled":false,"persistenceEnabled":false,"marketBaseRate":5.0,"eventId":"33376437","eventTypeId":"4339","numberOfWinners":1,"bettingType":"ODDS","marketType":"WIN","marketTime":"2024-06-27T15:07:00.000Z","suspendTime":"2024-06-27T15:07:00.000Z","bspReconciled":false,"complete":true,"inPlay":false,"crossMatching":false,"runnersVoidable":false,"numberOfActiveRunners":6,"betDelay":0,"status":"OPEN","runners":[{"status":"ACTIVE","sortPriority":1,"id":67487132,"name":"1. Salacres Belleza"},{"status":"ACTIVE","sortPriority":2,"id":43318163,"name":"2. Walking Dead"},{"status":"ACTIVE","sortPriority":3,"id":40028187,"name":"3. The Grafter"},{"status":"ACTIVE","sortPriority":4,"id":70396461,"name":"4. Late Yahoo"},{"status":"ACTIVE","sortPriority":5,"id":47703807,"name":"5. Fabulous Twirl"},{"status":"ACTIVE","sortPriority":6,"id":57697855,"name":"6. Salacres Driller"}],"regulators":["MR_INT"],"venue":"Towcester","countryCode":"GB","discountAllowed":true,"timezone":"Europe/London","openDate":"2024-06-27T13:33:00.000Z","version":5994767067,"name":"A5 500m","eventName":"Towcester 27th Jun"},"rc":[{"atb":[[1.03,10.99]],"id":40028187},{"atl":[[990,0.17]],"id":40028187},{"spn":495.51,"spf":"NaN","id":40028187},{"atb":[[1.02,16.48]],"id":43318163},{"atl":[[1000,0.17]],"id":43318163},{"spn":500.51,"spf":"NaN","id":43318163},{"atb":[[1.02,16.48]],"id":47703807},{"atl":[[1000,0.17]],"id":47703807},{"spn":500.51,"spf":"NaN","id":47703807},{"atb":[[1.01,32.96]],"id":67487132},{"atl":[[990,0.17]],"id":67487132},{"spn":495.5,"spf":"NaN","id":67487132},{"atb":[[1.02,16.48]],"id":70396461},{"atl":[[1000,0.17]],"id":70396461},{"spn":500.51,"spf":"NaN","id":70396461},{"atb":[[1.01,32.96]],"id":57697855},{"atl":[[990,0.17]],"id":57697855},{"spn":495.5,"spf":"NaN","id":57697855}],"con":true,"img":true}]}
{"op":"mcm","clk":"11537956505","pt":1719448682747,"mc":[{"id":"1.230180122","marketDefinition":{"bspMarket":true,"turnInPlayEnabled":false,"persistenceEnabled":false,"marketBaseRate":5.0,"eventId":"33376437","eventTypeId":"4339","numberOfWinners":1,"bettingType":"ODDS","marketType":"WIN","marketTime":"2024-06-27T15:07:00.000Z","suspendTime":"2024-06-27T15:07:00.000Z","bspReconciled":false,"complete":true,"inPlay":false,"crossMatching":false,"runnersVoidable":false,"numberOfActiveRunners":6,"betDelay":0,"status":"OPEN","runners":[{"status":"ACTIVE","sortPriority":1,"id":67487132,"name":"1. Salacres Belleza"},{"status":"ACTIVE","sortPriority":2,"id":43318163,"name":"2. Walking Dead"},{"status":"ACTIVE","sortPriority":3,"id":40028187,"name":"3. The Grafter"},{"status":"ACTIVE","sortPriority":4,"id":70396461,"name":"4. Late Yahoo"},{"status":"ACTIVE","sortPriority":5,"id":47703807,"name":"5. Fabulous Twirl"},{"status":"ACTIVE","sortPriority":6,"id":57697855,"name":"6. Salacres Driller"}],"regulators":["MR_INT"],"venue":"Towcester","countryCode":"GB","discountAllowed":true,"timezone":"Europe/London","openDate":"2024-06-27T13:33:00.000Z","version":5994767067,"name":"A5 500m","eventName":"Towcester 27th Jun"},"rc":[{"atb":[[1.03,10.99]],"id":40028187},{"atl":[[990,0.17]],"id":40028187},{"spn":495.51,"spf":"NaN","id":40028187},{"atb":[[1.02,16.48]],"id":43318163},{"atl":[[1000,0.17]],"id":43318163},{"spn":500.51,"spf":"NaN","id":43318163},{"atb":[[1.02,16.48]],"id":47703807},{"atl":[[1000,0.17]],"id":47703807},{"spn":500.51,"spf":"NaN","id":47703807},{"atb":[[1.01,32.96]],"id":67487132},{"atl":[[990,0.17]],"id":67487132},{"spn":495.5,"spf":"NaN","id":67487132},{"atb":[[1.02,16.48]],"id":70396461},{"atl":[[1000,0.17]],"id":70396461},{"spn":500.51,"spf":"NaN","id":70396461},{"atb":[[1.01,32.96]],"id":57697855},{"atl":[[990,0.17]],"id":57697855},{"spn":495.5,"spf":"NaN","id":57697855}],"con":true,"img":true}]}
{"op":"mcm","clk":"11538172122","pt":1719454082690,"mc":[{"id":"1.230180122","marketDefinition":{"bspMarket":true,"turnInPlayEnabled":false,"persistenceEnabled":false,"marketBaseRate":5.0,"eventId":"33376437","eventTypeId":"4339","numberOfWinners":1,"bettingType":"ODDS","marketType":"WIN","marketTime":"2024-06-27T15:07:00.000Z","suspendTime":"2024-06-27T15:07:00.000Z","bspReconciled":false,"complete":true,"inPlay":false,"crossMatching":false,"runnersVoidable":false,"numberOfActiveRunners":6,"betDelay":0,"status":"OPEN","runners":[{"status":"ACTIVE","sortPriority":1,"id":67487132,"name":"1. Salacres Belleza"},{"status":"ACTIVE","sortPriority":2,"id":43318163,"name":"2. Walking Dead"},{"status":"ACTIVE","sortPriority":3,"id":40028187,"name":"3. The Grafter"},{"status":"ACTIVE","sortPriority":4,"id":70396461,"name":"4. Late Yahoo"},{"status":"ACTIVE","sortPriority":5,"id":47703807,"name":"5. Fabulous Twirl"},{"status":"ACTIVE","sortPriority":6,"id":57697855,"name":"6. Salacres Driller"}],"regulators":["MR_INT"],"venue":"Towcester","countryCode":"GB","discountAllowed":true,"timezone":"Europe/London","openDate":"2024-06-27T13:33:00.000Z","version":5994767067,"name":"A5 500m","eventName":"Towcester 27th Jun"},"rc":[{"atb":[[1.03,10.99]],"id":40028187},{"atl":[[990,0.17]],"id":40028187},{"spn":495.51,"spf":"NaN","id":40028187},{"atb":[[1.02,16.48]],"id":43318163},{"atl":[[1000,0.17]],"id":43318163},{"spn":500.51,"spf":"NaN","id":43318163},{"atb":[[1.02,16.48]],"id":47703807},{"atl":[[1000,0.17]],"id":47703807},{"spn":500.51,"spf":"NaN","id":47703807},{"atb":[[1.01,32.97]],"id":67487132},{"atl":[[990,0.17]],"id":67487132},{"spn":495.5,"spf":"NaN","id":67487132},{"atb":[[1.02,16.48]],"id":70396461},{"atl":[[1000,0.17]],"id":70396461},{"spn":500.51,"spf":"NaN","id":70396461},{"atb":[[1.01,32.97]],"id":57697855},{"atl":[[990,0.17]],"id":57697855},{"spn":495.5,"spf":"NaN","id":57697855}],"con":true,"img":true}]}
{"op":"mcm","clk":"11538369789","pt":1719459482775,"mc":[{"id":"1.230180122","marketDefinition":{"bspMarket":true,"turnInPlayEnabled":false,"persistenceEnabled":false,"marketBaseRate":5.0,"eventId":"33376437","eventTypeId":"4339","numberOfWinners":1,"bettingType":"ODDS","marketType":"WIN","marketTime":"2024-06-27T15:07:00.000Z","suspendTime":"2024-06-27T15:07:00.000Z","bspReconciled":false,"complete":true,"inPlay":false,"crossMatching":false,"runnersVoidable":false,"numberOfActiveRunners":6,"betDelay":0,"status":"OPEN","runners":[{"status":"ACTIVE","sortPriority":1,"id":67487132,"name":"1. Salacres Belleza"},{"status":"ACTIVE","sortPriority":2,"id":43318163,"name":"2. Walking Dead"},{"status":"ACTIVE","sortPriority":3,"id":40028187,"name":"3. The Grafter"},{"status":"ACTIVE","sortPriority":4,"id":70396461,"name":"4. Late Yahoo"},{"status":"ACTIVE","sortPriority":5,"id":47703807,"name":"5. Fabulous Twirl"},{"status":"ACTIVE","sortPriority":6,"id":57697855,"name":"6. Salacres Driller"}],"regulators":["MR_INT"],"venue":"Towcester","countryCode":"GB","discountAllowed":true,"timezone":"Europe/London","openDate":"2024-06-27T13:33:00.000Z","version":5994767067,"name":"A5 500m","eventName":"Towcester 27th Jun"},"rc":[{"atb":[[1.03,10.99]],"id":40028187},{"atl":[[990,0.17]],"id":40028187},{"spn":495.51,"spf":"NaN","id":40028187},{"atb":[[1.02,16.48]],"id":43318163},{"atl":[[1000,0.17]],"id":43318163},{"spn":500.51,"spf":"NaN","id":43318163},{"atb":[[1.02,16.48]],"id":47703807},{"atl":[[1000,0.17]],"id":47703807},{"spn":500.51,"spf":"NaN","id":47703807},{"atb":[[1.01,32.97]],"id":67487132},{"atl":[[990,0.17]],"id":67487132},{"spn":495.5,"spf":"NaN","id":67487132},{"atb":[[1.02,16.48]],"id":70396461},{"atl":[[1000,0.17]],"id":70396461},{"spn":500.51,"spf":"NaN","id":70396461},{"atb":[[1.01,32.97]],"id":57697855},{"atl":[[990,0.17]],"id":57697855},{"spn":495.5,"spf":"NaN","id":57697855}],"con":true,"img":true}]}
{"op":"mcm","clk":"11538596919","pt":1719464882719,"mc":[{"id":"1.230180122","marketDefinition":{"bspMarket":true,"turnInPlayEnabled":false,"persistenceEnabled":false,"marketBaseRate":5.0,"eventId":"33376437","eventTypeId":"4339","numberOfWinners":1,"bettingType":"ODDS","marketType":"WIN","marketTime":"2024-06-27T15:07:00.000Z","suspendTime":"2024-06-27T15:07:00.000Z","bspReconciled":false,"complete":true,"inPlay":false,"crossMatching":false,"runnersVoidable":false,"numberOfActiveRunners":6,"betDelay":0,"status":"OPEN","runners":[{"status":"ACTIVE","sortPriority":1,"id":67487132,"name":"1. Salacres Belleza"},{"status":"ACTIVE","sortPriority":2,"id":43318163,"name":"2. Walking Dead"},{"status":"ACTIVE","sortPriority":3,"id":40028187,"name":"3. The Grafter"},{"status":"ACTIVE","sortPriority":4,"id":70396461,"name":"4. Late Yahoo"},{"status":"ACTIVE","sortPriority":5,"id":47703807,"name":"5. Fabulous Twirl"},{"status":"ACTIVE","sortPriority":6,"id":57697855,"name":"6. Salacres Driller"}],"regulators":["MR_INT"],"venue":"Towcester","countryCode":"GB","discountAllowed":true,"timezone":"Europe/London","openDate":"2024-06-27T13:33:00.000Z","version":5994767067,"name":"A5 500m","eventName":"Towcester 27th Jun"},"rc":[{"atb":[[1.03,10.99]],"id":40028187},{"atl":[[990,0.17]],"id":40028187},{"spn":495.51,"spf":"NaN","id":40028187},{"atb":[[1.02,16.48]],"id":43318163},{"atl":[[1000,0.17]],"id":43318163},{"spn":500.51,"spf":"NaN","id":43318163},{"atb":[[1.02,16.48]],"id":47703807},{"atl":[[1000,0.17]],"id":47703807},{"spn":500.51,"spf":"NaN","id":47703807},{"atb":[[1.01,32.97]],"id":67487132},{"atl":[[990,0.17]],"id":67487132},{"spn":495.5,"spf":"NaN","id":67487132},{"atb":[[1.02,16.48]],"id":70396461},{"atl":[[1000,0.17]],"id":70396461},{"spn":500.51,"spf":"NaN","id":70396461},{"atb":[[1.01,32.97]],"id":57697855},{"atl":[[990,0.17]],"id":57697855},{"spn":495.5,"spf":"NaN","id":57697855}],"con":true,"img":true}]}
{"op":"mcm","clk":"11538748566","pt":1719468203776,"mc":[{"id":"1.230180122","rc":[{"atb":[[1.03,10.99],[2.08,13.32]],"id":40028187},{"spn":496.04,"spf":"NaN","id":40028187},{"atb":[[2,11.11],[1.02,16.48]],"id":43318163},{"spn":501.0,"spf":"NaN","id":43318163},{"atb":[[1.02,16.48],[2.1,12.55]],"id":47703807},{"spn":501.05,"spf":"NaN","id":47703807},{"atb":[[1.01,32.97],[2.1,13.45]],"id":67487132},{"spn":496.05,"spf":"NaN","id":67487132},{"atb":[[1.02,16.48],[2.04,11.33]],"id":70396461},{"spn":501.02,"spf":"NaN","id":70396461},{"atb":[[1.01,32.97],[2.06,8.8]],"id":57697855},{"spn":496.03,"spf":"NaN","id":57697855}],"con":true,"img":false}]}
{"op":"mcm","clk":"11538750813","pt":1719468250375,"mc":[{"id":"1.230180122","rc":[{"atb":[[2.02,3.16]],"id":43318163}],"con":true,"img":false}]}
{"op":"mcm","clk":"11538750830","pt":1719468250641,"mc":[{"id":"1.230180122","rc":[{"atb":[[2.12,3.16]],"id":67487132},{"atb":[[2.06,3.16]],"id":70396461}],"con":true,"img":false}]}
{"op":"mcm","clk":"11538750840","pt":1719468250842,"mc":[{"id":"1.230180122","rc":[{"atb":[[2.1,3.16]],"id":40028187},{"atb":[[2.12,3.16]],"id":47703807}],"con":true,"img":false}]}
{"op":"mcm","clk":"11538750881","pt":1719468251662,"mc":[{"id":"1.230180122","rc":[{"atb":[[2.08,3.16]],"id":57697855}],"con":true,"img":false}]}
{"op":"mcm","clk":"11538752901","pt":1719468291019,"mc":[{"id":"1.230180122","rc":[{"spn":496.05,"spf":"NaN","id":40028187},{"atb":[[2.02,6.55]],"id":43318163},{"spn":501.01,"spf":"NaN","id":43318163},{"spn":501.06,"spf":"NaN","id":47703807},{"spn":496.06,"spf":"NaN","id":67487132},{"spn":501.03,"spf":"NaN","id":70396461},{"spn":496.04,"spf":"NaN","id":57697855}],"con":true,"img":false}]}
{"op":"mcm","clk":"11538752908","pt":1719468291122,"mc":[{"id":"1.230180122","rc":[{"atb":[[2.12,6.55]],"id":67487132}],"con":true,"img":false}]}
{"op":"mcm","clk":"11538752920","pt":1719468291324,"mc":[{"id":"1.230180122","rc":[{"atb":[[2.12,6.55]],"id":47703807}],"con":true,"img":false}]}
{"op":"mcm","clk":"11538752941","pt":1719468291633,"mc":[{"id":"1.230180122","rc":[{"atb":[[2.1,6.55]],"id":40028187},{"atb":[[2.08,6.55]],"id":57697855}],"con":true,"img":false}]}
{"op":"mcm","clk":"11538752972","pt":1719468292197,"mc":[{"id":"1.230180122","rc":[{"atb":[[2.06,6.55]],"id":70396461}],"con":true,"img":false}]}
{"op":"mcm","clk":"11538754062","pt":1719468311802,"mc":[{"id":"1.230180122","marketDefinition":{"bspMarket":true,"turnInPlayEnabled":false,"persistenceEnabled":false,"marketBaseRate":5.0,"eventId":"33376437","eventTypeId":"4339","numberOfWinners":1,"bettingType":"ODDS","marketType":"WIN","marketTime":"2024-06-27T15:07:00.000Z","suspendTime":"2024-06-27T15:07:00.000Z","bspReconciled":false,"complete":true,"inPlay":false,"crossMatching":true,"runnersVoidable":false,"numberOfActiveRunners":6,"betDelay":0,"status":"OPEN","runners":[{"status":"ACTIVE","sortPriority":1,"id":67487132,"name":"1. Salacres Belleza"},{"status":"ACTIVE","sortPriority":2,"id":43318163,"name":"2. Walking Dead"},{"status":"ACTIVE","sortPriority":3,"id":40028187,"name":"3. The Grafter"},{"status":"ACTIVE","sortPriority":4,"id":70396461,"name":"4. Late Yahoo"},{"status":"ACTIVE","sortPriority":5,"id":47703807,"name":"5. Fabulous Twirl"},{"status":"ACTIVE","sortPriority":6,"id":57697855,"name":"6. Salacres Driller"}],"regulators":["MR_INT"],"venue":"Towcester","countryCode":"GB","discountAllowed":true,"timezone":"Europe/London","openDate":"2024-06-27T13:33:00.000Z","version":5994767067,"name":"A5 500m","eventName":"Towcester 27th Jun"},"rc":[],"con":true,"img":false}]}
{"op":"mcm","clk":"11538759355","pt":1719468420282,"mc":[{"id":"1.230180122","rc":[{"atl":[[150,4]],"id":43318163},{"spn":76.01,"spf":"NaN","id":43318163},{"atl":[[150,4]],"id":67487132},{"spn":76.06,"spf":"NaN","id":67487132},{"atl":[[150,4]],"id":70396461},{"spn":76.03,"spf":"NaN","id":70396461},{"atl":[[150,4]],"id":57697855},{"spn":76.04,"spf":"NaN","id":57697855}],"con":true,"img":false}]}
{"op":"mcm","clk":"11538759359","pt":1719468420386,"mc":[{"id":"1.230180122","rc":[{"atl":[[150,4]],"id":40028187},{"atl":[[150,4]],"id":47703807}],"con":true,"img":false}]}
{"op":"mcm","clk":"11538853410","pt":1719470282739,"mc":[{"id":"1.230180122","marketDefinition":{"bspMarket":true,"turnInPlayEnabled":false,"persistenceEnabled":false,"marketBaseRate":5.0,"eventId":"33376437","eventTypeId":"4339","numberOfWinners":1,"bettingType":"ODDS","marketType":"WIN","marketTime":"2024-06-27T15:07:00.000Z","suspendTime":"2024-06-27T15:07:00.000Z","bspReconciled":false,"complete":true,"inPlay":false,"crossMatching":true,"runnersVoidable":false,"numberOfActiveRunners":6,"betDelay":0,"status":"OPEN","runners":[{"status":"ACTIVE","sortPriority":1,"id":67487132,"name":"1. Salacres Belleza"},{"status":"ACTIVE","sortPriority":2,"id":43318163,"name":"2. Walking Dead"},{"status":"ACTIVE","sortPriority":3,"id":40028187,"name":"3. The Grafter"},{"status":"ACTIVE","sortPriority":4,"id":70396461,"name":"4. Late Yahoo"},{"status":"ACTIVE","sortPriority":5,"id":47703807,"name":"5. Fabulous Twirl"},{"status":"ACTIVE","sortPriority":6,"id":57697855,"name":"6. Salacres Driller"}],"regulators":["MR_INT"],"venue":"Towcester","countryCode":"GB","discountAllowed":true,"timezone":"Europe/London","openDate":"2024-06-27T13:33:00.000Z","version":5994767067,"name":"A5 500m","eventName":"Towcester 27th Jun"},"rc":[{"atb":[[1.03,10.99],[2.1,6.55],[2.08,13.32]],"id":40028187},{"atl":[[150,4],[990,0.17]],"id":40028187},{"spn":76.05,"spf":"NaN","id":40028187},{"atb":[[2,11.11],[2.02,6.55],[1.02,16.48]],"id":43318163},{"atl":[[150,4],[1000,0.17]],"id":43318163},{"spn":76.01,"spf":"NaN","id":43318163},{"atb":[[1.02,16.48],[2.12,6.55],[2.1,12.55]],"id":47703807},{"atl":[[150,4],[1000,0.17]],"id":47703807},{"spn":76.06,"spf":"NaN","id":47703807},{"atb":[[1.01,32.97],[2.12,6.55],[2.1,13.45]],"id":67487132},{"atl":[[150,4],[990,0.17]],"id":67487132},{"spn":76.06,"spf":"NaN","id":67487132},{"atb":[[2.06,6.55],[2.04,11.33],[1.02,16.48]],"id":70396461},{"atl":[[150,4],[1000,0.17]],"id":70396461},{"spn":76.03,"spf":"NaN","id":70396461},{"atb":[[1.01,32.97],[2.06,8.8],[2.08,6.55]],"id":57697855},{"atl":[[150,4],[990,0.17]],"id":57697855},{"spn":76.04,"spf":"NaN","id":57697855}],"con":true,"img":true}]}
{"op":"mcm","clk":"11538937214","pt":1719472048250,"mc":[{"id":"1.230180122","rc":[{"atb":[[1.03,10.98],[2.1,6.54],[2.08,13.32]],"id":40028187},{"atl":[[990,0.17]],"id":40028187},{"spn":76.05,"spf":"NaN","id":40028187},{"atb":[[2,11.1],[2.02,6.54],[1.02,16.47]],"id":43318163},{"atl":[[1000,0.17]],"id":43318163},{"atb":[[1.02,16.47],[2.12,6.54],[2.1,12.55]],"id":47703807},{"atl":[[1000,0.17]],"id":47703807},{"spn":76.06,"spf":"NaN","id":47703807},{"atb":[[1.01,32.94],[2.12,6.54],[2.1,13.44]],"id":67487132},{"atl":[[28,0.6],[990,0.17]],"id":67487132},{"spn":15.06,"spf":"NaN","id":67487132},{"atb":[[2.06,6.54],[2.04,11.32],[1.02,16.47]],"id":70396461},{"atl":[[1000,0.17]],"id":70396461},{"atb":[[1.01,32.94],[2.06,8.79],[2.08,6.54]],"id":57697855},{"atl":[[990,0.17]],"id":57697855}],"con":true,"img":false}]}
{"op":"mcm","clk":"11538940536","pt":1719472110490,"mc":[{"id":"1.230180122","rc":[{"atb":[[2.08,0]],"id":40028187},{"atb":[[2,0]],"id":43318163},{"atb":[[2.1,0]],"id":47703807},{"atb":[[2.1,0]],"id":67487132},{"atb":[[2.04,0]],"id":70396461},{"atb":[[2.06,0]],"id":57697855}],"con":true,"img":false}]}
{"op":"mcm","clk":"11538940543","pt":1719472110591,"mc":[{"id":"1.230180122","rc":[{"atb":[[2.12,13.32]],"id":40028187},{"atb":[[2.04,11.1]],"id":43318163},{"atb":[[2.14,12.55]],"id":47703807},{"atb":[[2.14,13.44]],"id":67487132},{"atb":[[2.08,11.32]],"id":70396461},{"atb":[[2.1,8.79]],"id":57697855}],"con":true,"img":false}]}
{"op":"mcm","clk":"11538943505","pt":1719472156562,"mc":[{"id":"1.230180122","rc":[{"atb":[[2.12,3.38]],"id":67487132}],"con":true,"img":false}]}
{"op":"mcm","clk":"11538943525","pt":1719472156971,"mc":[{"id":"1.230180122","rc":[{"atb":[[2.1,3.38]],"id":40028187}],"con":true,"img":false}]}
{"op":"mcm","clk":"11538943593","pt":1719472158503,"mc":[{"id":"1.230180122","rc":[{"atb":[[2.12,3.38]],"id":47703807}],"con":true,"img":false}]}
{"op":"mcm","clk":"11538943606","pt":1719472158759,"mc":[{"id":"1.230180122","rc":[{"atb":[[2.16,3.16]],"id":67487132}],"con":true,"img":false}]}
{"op":"mcm","clk":"11538943623","pt":1719472159068,"mc":[{"id":"1.230180122","rc":[{"atb":[[2.06,3.38]],"id":70396461}],"con":true,"img":false}]}
{"op":"mcm","clk":"11538943662","pt":1719472159885,"mc":[{"id":"1.230180122","rc":[{"atb":[[2.08,3.38]],"id":57697855}],"con":true,"img":false}]}
{"op":"mcm","clk":"11538943676","pt":1719472160087,"mc":[{"id":"1.230180122","rc":[{"atb":[[2.14,3.16]],"id":40028187}],"con":true,"img":false}]}
{"op":"mcm","clk":"11538943688","pt":1719472160295,"mc":[{"id":"1.230180122","rc":[{"atb":[[2.16,3.16]],"id":47703807}],"con":true,"img":false}]}
{"op":"mcm","clk":"11538943884","pt":1719472163375,"mc":[{"id":"1.230180122","rc":[{"atb":[[2.02,3.38]],"id":43318163}],"con":true,"img":false}]}
{"op":"mcm","clk":"11538943971","pt":1719472164610,"mc":[{"id":"1.230180122","rc":[{"atb":[[2.12,3.16]],"id":57697855}],"con":true,"img":false}]}
{"op":"mcm","clk":"11538944019","pt":1719472165384,"mc":[{"id":"1.230180122","rc":[{"atb":[[2.1,3.16]],"id":70396461}],"con":true,"img":false}]}
{"op":"mcm","clk":"11538944059","pt":1719472166198,"mc":[{"id":"1.230180122","rc":[{"atb":[[2.06,3.16]],"id":43318163}],"con":true,"img":false}]}
{"op":"mcm","clk":"11538944617","pt":1719472175501,"mc":[{"id":"1.230180122","rc":[{"spn":76.07,"spf":"NaN","id":40028187},{"spn":76.03,"spf":"NaN","id":43318163},{"spn":76.08,"spf":"NaN","id":47703807},{"atb":[[2.12,0]],"id":67487132},{"spn":15.08,"spf":"NaN","id":67487132},{"spn":76.05,"spf":"NaN","id":70396461},{"spn":76.06,"spf":"NaN","id":57697855}],"con":true,"img":false}]}
{"op":"mcm","clk":"11538944651","pt":1719472176113,"mc":[{"id":"1.230180122","rc":[{"atb":[[2.08,0]],"id":57697855}],"con":true,"img":false}]}
{"op":"mcm","clk":"11538944657","pt":1719472176225,"mc":[{"id":"1.230180122","rc":[{"atb":[[2.12,0]],"id":47703807}],"con":true,"img":false}]}
{"op":"mcm","clk":"11538944678","pt":1719472176523,"mc":[{"id":"1.230180122","rc":[{"atb":[[2.06,0]],"id":70396461}],"con":true,"img":false}]}
{"op":"mcm","clk":"11538944696","pt":1719472176833,"mc":[{"id":"1.230180122","rc":[{"atb":[[2.1,0]],"id":40028187}],"con":true,"img":false}]}
{"op":"mcm","clk":"11538944771","pt":1719472178013,"mc":[{"id":"1.230180122","rc":[{"atb":[[2.02,0]],"id":43318163}],"con":true,"img":false}]}
{"op":"mcm","clk":"11538945767","pt":1719472194558,"mc":[{"id":"1.230180122","rc":[{"atb":[[2.16,6.54]],"id":47703807}],"con":true,"img":false}]}
{"op":"mcm","clk":"11538945828","pt":1719472195337,"mc":[{"id":"1.230180122","rc":[{"atb":[[2.16,6.54]],"id":67487132}],"con":true,"img":false}]}
{"op":"mcm","clk":"11538945898","pt":1719472196359,"mc":[{"id":"1.230180122","rc":[{"atb":[[2.14,6.54]],"id":40028187}],"con":true,"img":false}]}
{"op":"mcm","clk":"11538945918","pt":1719472196618,"mc":[{"id":"1.230180122","rc":[{"atb":[[2.1,6.54]],"id":70396461}],"con":true,"img":false}]}
{"op":"mcm","clk":"11538945936","pt":1719472196820,"mc":[{"id":"1.230180122","rc":[{"atb":[[2.06,6.54]],"id":43318163}],"con":true,"img":false}]}
{"op":"mcm","clk":"11538945991","pt":1719472197648,"mc":[{"id":"1.230180122","rc":[{"atb":[[2.12,6.54]],"id":57697855}],"con":true,"img":false}]}
{"op":"mcm","clk":"11539124107","pt":1719475682706,"mc":[{"id":"1.230180122","marketDefinition":{"bspMarket":true,"turnInPlayEnabled":false,"persistenceEnabled":false,"marketBaseRate":5.0,"eventId":"33376437","eventTypeId":"4339","numberOfWinners":1,"bettingType":"ODDS","marketType":"WIN","marketTime":"2024-06-27T15:07:00.000Z","suspendTime":"2024-06-27T15:07:00.000Z","bspReconciled":false,"complete":true,"inPlay":false,"crossMatching":true,"runnersVoidable":false,"numberOfActiveRunners":6,"betDelay":0,"status":"OPEN","runners":[{"status":"ACTIVE","sortPriority":1,"id":67487132,"name":"1. Salacres Belleza"},{"status":"ACTIVE","sortPriority":2,"id":43318163,"name":"2. Walking Dead"},{"status":"ACTIVE","sortPriority":3,"id":40028187,"name":"3. The Grafter"},{"status":"ACTIVE","sortPriority":4,"id":70396461,"name":"4. Late Yahoo"},{"status":"ACTIVE","sortPriority":5,"id":47703807,"name":"5. Fabulous Twirl"},{"status":"ACTIVE","sortPriority":6,"id":57697855,"name":"6. Salacres Driller"}],"regulators":["MR_INT"],"venue":"Towcester","countryCode":"GB","discountAllowed":true,"timezone":"Europe/London","openDate":"2024-06-27T13:33:00.000Z","version":5994767067,"name":"A5 500m","eventName":"Towcester 27th Jun"},"rc":[{"atb":[[1.03,10.99],[2.12,13.32],[2.14,6.55]],"id":40028187},{"atl":[[150,4],[990,0.17]],"id":40028187},{"spn":76.07,"spf":"NaN","id":40028187},{"atb":[[2.06,6.55],[2.04,11.1],[1.02,16.48]],"id":43318163},{"atl":[[150,4],[1000,0.17]],"id":43318163},{"spn":76.03,"spf":"NaN","id":43318163},{"atb":[[1.02,16.48],[2.16,6.55],[2.14,12.55]],"id":47703807},{"atl":[[150,4],[1000,0.17]],"id":47703807},{"spn":76.08,"spf":"NaN","id":47703807},{"atb":[[1.01,32.96],[2.16,6.55],[2.14,13.45]],"id":67487132},{"atl":[[150,4],[28,0.6],[990,0.17]],"id":67487132},{"spn":15.08,"spf":"NaN","id":67487132},{"atb":[[1.02,16.48],[2.1,6.55],[2.08,11.32]],"id":70396461},{"atl":[[150,4],[1000,0.17]],"id":70396461},{"spn":76.05,"spf":"NaN","id":70396461},{"atb":[[1.01,32.96],[2.12,6.55],[2.1,8.79]],"id":57697855},{"atl":[[150,4],[990,0.17]],"id":57697855},{"spn":76.06,"spf":"NaN","id":57697855}],"con":true,"img":true}]}
{"op":"mcm","clk":"11539127865","pt":1719475710536,"mc":[{"id":"1.230180122","rc":[{"atb":[[1.03,10.99],[2.12,0],[2.14,6.55]],"id":40028187},{"atb":[[2.06,6.55],[2.04,0],[1.02,16.48]],"id":43318163},{"atb":[[1.02,16.48],[2.16,6.55],[2.14,0]],"id":47703807},{"atb":[[1.01,32.96],[2.16,6.55],[2.14,0]],"id":67487132},{"atb":[[1.02,16.48],[2.1,6.55],[2.08,0]],"id":70396461},{"atb":[[1.01,32.96],[2.12,6.55],[2.1,0]],"id":57697855}],"con":true,"img":false}]}
{"op":"mcm","clk":"11539127870","pt":1719475710634,"mc":[{"id":"1.230180122","rc":[{"atb":[[2.16,13.32]],"id":40028187},{"atb":[[2.08,11.1]],"id":43318163},{"atb":[[2.18,12.55]],"id":47703807},{"atb":[[2.18,13.45]],"id":67487132},{"atb":[[2.12,11.32]],"id":70396461},{"atb":[[2.14,8.79]],"id":57697855}],"con":true,"img":false}]}
{"op":"mcm","clk":"11539134446","pt":1719475812541,"mc":[{"id":"1.230180122","rc":[{"atb":[[2.14,3.38]],"id":40028187},{"spn":76.08,"spf":"NaN","id":40028187},{"atb":[[2.06,3.38]],"id":43318163},{"spn":76.04,"spf":"NaN","id":43318163},{"atb":[[2.16,3.38]],"id":47703807},{"spn":76.09,"spf":"NaN","id":47703807},{"atb":[[2.16,3.38]],"id":67487132},{"spn":15.09,"spf":"NaN","id":67487132},{"atb":[[2.1,3.38]],"id":70396461},{"spn":76.06,"spf":"NaN","id":70396461},{"atb":[[2.12,3.38]],"id":57697855},{"spn":76.07,"spf":"NaN","id":57697855}],"con":true,"img":false}]}
{"op":"mcm","clk":"11539134450","pt":1719475812643,"mc":[{"id":"1.230180122","rc":[{"atb":[[2.16,0]],"id":67487132}],"con":true,"img":false}]}
{"op":"mcm","clk":"11539134465","pt":1719475812852,"mc":[{"id":"1.230180122","rc":[{"atb":[[2.14,0]],"id":40028187}],"con":true,"img":false}]}
{"op":"mcm","clk":"11539134480","pt":1719475813163,"mc":[{"id":"1.230180122","rc":[{"atb":[[2.16,0]],"id":47703807}],"con":true,"img":false}]}
{"op":"mcm","clk":"11539134498","pt":1719475813572,"mc":[{"id":"1.230180122","rc":[{"atb":[[2.1,0]],"id":70396461}],"con":true,"img":false}]}
{"op":"mcm","clk":"11539134533","pt":1719475814141,"mc":[{"id":"1.230180122","rc":[{"atb":[[2.06,0]],"id":43318163}],"con":true,"img":false}]}
{"op":"mcm","clk":"11539134594","pt":1719475815168,"mc":[{"id":"1.230180122","rc":[{"atb":[[2.12,0]],"id":57697855}],"con":true,"img":false}]}
{"op":"mcm","clk":"11539134774","pt":1719475818259,"mc":[{"id":"1.230180122","rc":[{"atb":[[2.2,3.38]],"id":47703807}],"con":true,"img":false}]}
{"op":"mcm","clk":"11539134782","pt":1719475818363,"mc":[{"id":"1.230180122","rc":[{"atb":[[2.1,3.38]],"id":43318163}],"con":true,"img":false}]}
{"op":"mcm","clk":"11539134795","pt":1719475818570,"mc":[{"id":"1.230180122","rc":[{"atb":[[2.18,3.38]],"id":40028187}],"con":true,"img":false}]}
{"op":"mcm","clk":"11539134821","pt":1719475818984,"mc":[{"id":"1.230180122","rc":[{"atb":[[2.16,3.38]],"id":57697855}],"con":true,"img":false}]}
{"op":"mcm","clk":"11539134871","pt":1719475819756,"mc":[{"id":"1.230180122","rc":[{"atb":[[2.2,3.38]],"id":67487132}],"con":true,"img":false}]}
{"op":"mcm","clk":"11539135037","pt":1719475821860,"mc":[{"id":"1.230180122","rc":[{"atb":[[2.14,3.38]],"id":70396461}],"con":true,"img":false}]}
{"op":"mcm","clk":"11539153552","pt":1719476120789,"mc":[{"id":"1.230180122","rc":[{"spn":76.09,"spf":"NaN","id":40028187},{"atb":[[2.1,6.55]],"id":43318163},{"spn":76.05,"spf":"NaN","id":43318163},{"spn":76.1,"spf":"NaN","id":47703807},{"atb":[[2.2,6.55]],"id":67487132},{"spn":15.1,"spf":"NaN","id":67487132},{"spn":76.07,"spf":"NaN","id":70396461},{"spn":76.08,"spf":"NaN","id":57697855}],"con":true,"img":false}]}
{"op":"mcm","clk":"11539153597","pt":1719476121465,"mc":[{"id":"1.230180122","rc":[{"atb":[[2.18,6.55]],"id":40028187}],"con":true,"img":false}]}
{"op":"mcm","clk":"11539153609","pt":1719476121664,"mc":[{"id":"1.230180122","rc":[{"atb":[[2.14,6.55]],"id":70396461}],"con":true,"img":false}]}
{"op":"mcm","clk":"11539153615","pt":1719476121764,"mc":[{"id":"1.230180122","rc":[{"atb":[[2.2,6.55]],"id":47703807}],"con":true,"img":false}]}
{"op":"mcm","clk":"11539153618","pt":1719476121865,"mc":[{"id":"1.230180122","rc":[{"atb":[[2.16,6.55]],"id":57697855}],"con":true,"img":false}]}
{"op":"mcm","clk":"11539338784","pt":1719479263255,"mc":[{"id":"1.230180122","rc":[{"atb":[[1.03,10.98],[2.18,6.54],[2.26,2],[2.16,13.32]],"id":40028187},{"spn":76.13,"spf":"NaN","id":40028187},{"atb":[[1.02,16.47],[2.1,6.54],[2.08,11.1]],"id":43318163},{"atb":[[1.02,16.47],[2.18,12.55],[2.2,6.54]],"id":47703807},{"atb":[[1.01,32.95],[2.18,13.45],[2.2,6.54]],"id":67487132},{"atb":[[1.02,16.47],[2.12,11.32],[2.14,6.54]],"id":70396461},{"atb":[[1.01,32.95],[2.16,6.54],[2.14,8.79]],"id":57697855}],"con":true,"img":false}]}
{"op":"mcm","clk":"11539341347","pt":1719479309371,"mc":[{"id":"1.230180122","rc":[{"atb":[[2.16,0]],"id":40028187},{"atb":[[2.08,0]],"id":43318163},{"atb":[[2.18,0]],"id":47703807},{"atb":[[2.18,0]],"id":67487132},{"atb":[[2.12,0]],"id":70396461},{"atb":[[2.14,0]],"id":57697855}],"con":true,"img":false}]}
{"op":"mcm","clk":"11539341354","pt":1719479309471,"mc":[{"id":"1.230180122","rc":[{"atb":[[2.2,13.32]],"id":40028187},{"atb":[[2.12,11.1]],"id":43318163},{"atb":[[2.22,12.55]],"id":47703807},{"atb":[[2.22,13.45]],"id":67487132},{"atb":[[2.16,11.32]],"id":70396461},{"atb":[[2.18,8.79]],"id":57697855}],"con":true,"img":false}]}
{"op":"mcm","clk":"11539347185","pt":1719479403021,"mc":[{"id":"1.230180122","rc":[{"atb":[[2.1,3.38]],"id":43318163},{"spn":76.06,"spf":"NaN","id":43318163},{"spn":76.11,"spf":"NaN","id":47703807},{"spn":15.11,"spf":"NaN","id":67487132},{"spn":76.08,"spf":"NaN","id":70396461},{"spn":76.09,"spf":"NaN","id":57697855}],"con":true,"img":false}]}
{"op":"mcm","clk":"11539347256","pt":1719479403998,"mc":[{"id":"1.230180122","rc":[{"atb":[[2.14,3.38]],"id":70396461}],"con":true,"img":false}]}
{"op":"mcm","clk":"11539347307","pt":1719479404678,"mc":[{"id":"1.230180122","rc":[{"atb":[[2.2,3.38]],"id":47703807},{"atb":[[2.16,3.38]],"id":57697855}],"con":true,"img":false}]}
{"op":"mcm","clk":"11539347518","pt":1719479407622,"mc":[{"id":"1.230180122","rc":[{"atb":[[2.18,3.38]],"id":40028187}],"con":true,"img":false}]}
{"op":"mcm","clk":"11539347565","pt":1719479408300,"mc":[{"id":"1.230180122","rc":[{"atb":[[2.2,3.38]],"id":67487132}],"con":true,"img":false}]}
{"op":"mcm","clk":"11539349795","pt":1719479444445,"mc":[{"id":"1.230180122","rc":[{"atb":[[2.1,0]],"id":43318163}],"con":true,"img":false}]}
{"op":"mcm","clk":"11539349850","pt":1719479445262,"mc":[{"id":"1.230180122","rc":[{"atb":[[2.18,0]],"id":40028187}],"con":true,"img":false}]}
{"op":"mcm","clk":"11539349890","pt":1719479445838,"mc":[{"id":"1.230180122","rc":[{"atb":[[2.2,0]],"id":67487132}],"con":true,"img":false}]}
{"op":"mcm","clk":"11539350006","pt":1719479447433,"mc":[{"id":"1.230180122","rc":[{"atb":[[2.2,0]],"id":47703807},{"atb":[[2.16,0]],"id":57697855}],"con":true,"img":false}]}
{"op":"mcm","clk":"11539350045","pt":1719479448152,"mc":[{"id":"1.230180122","rc":[{"atb":[[2.14,0]],"id":70396461}],"con":true,"img":false}]}
{"op":"mcm","clk":"11539350085","pt":1719479448862,"mc":[{"id":"1.230180122","rc":[{"atb":[[2.2,3.38]],"id":57697855}],"con":true,"img":false}]}
{"op":"mcm","clk":"11539350113","pt":1719479449328,"mc":[{"id":"1.230180122","rc":[{"atb":[[2.14,3.38]],"id":43318163}],"con":true,"img":false}]}
{"op":"mcm","clk":"11539350178","pt":1719479450357,"mc":[{"id":"1.230180122","rc":[{"atb":[[2.22,3.38]],"id":40028187},{"atb":[[2.24,3.38]],"id":67487132}],"con":true,"img":false}]}
{"op":"mcm","clk":"11539350249","pt":1719479451278,"mc":[{"id":"1.230180122","rc":[{"atb":[[2.18,3.38]],"id":70396461}],"con":true,"img":false}]}
{"op":"mcm","clk":"11539350340","pt":1719479452228,"mc":[{"id":"1.230180122","rc":[{"atb":[[2.24,3.38]],"id":47703807}],"con":true,"img":false}]}
{"op":"mcm","clk":"11539368012","pt":1719479711233,"mc":[{"id":"1.230180122","rc":[{"atb":[[2.14,6.54]],"id":43318163},{"spn":76.07,"spf":"NaN","id":43318163},{"spn":76.12,"spf":"NaN","id":47703807},{"spn":15.12,"spf":"NaN","id":67487132},{"spn":76.09,"spf":"NaN","id":70396461},{"spn":76.1,"spf":"NaN","id":57697855}],"con":true,"img":false}]}
{"op":"mcm","clk":"11539368048","pt":1719479711644,"mc":[{"id":"1.230180122","rc":[{"atb":[[2.2,6.54]],"id":57697855}],"con":true,"img":false}]}
{"op":"mcm","clk":"11539368144","pt":1719479712835,"mc":[{"id":"1.230180122","rc":[{"atb":[[2.22,6.54]],"id":40028187}],"con":true,"img":false}]}
{"op":"mcm","clk":"11539368185","pt":1719479713345,"mc":[{"id":"1.230180122","rc":[{"atb":[[2.18,6.54]],"id":70396461}],"con":true,"img":false}]}
{"op":"mcm","clk":"11539368211","pt":1719479713657,"mc":[{"id":"1.230180122","rc":[{"atb":[[2.24,6.54]],"id":47703807}],"con":true,"img":false}]}
{"op":"mcm","clk":"11539368228","pt":1719479713860,"mc":[{"id":"1.230180122","rc":[{"atb":[[2.24,6.54]],"id":67487132}],"con":true,"img":false}]}
{"op":"mcm","clk":"11539541359","pt":1719482843777,"mc":[{"id":"1.230180122","rc":[{"atb":[[1.03,10.98],[2.22,6.54],[2.2,13.32]],"id":40028187},{"atb":[[1.02,16.47],[2.12,11.1],[2.14,6.54]],"id":43318163},{"atb":[[2.24,6.54],[2.22,12.55],[1.02,16.47]],"id":47703807},{"atb":[[2.24,6.54],[1.01,32.95],[2.22,13.44]],"id":67487132},{"atl":[[25,8]],"id":67487132},{"spn":13.62,"spf":"NaN","id":67487132},{"atb":[[1.02,16.47],[2.18,6.54],[2.16,11.32]],"id":70396461},{"atl":[[18.5,8]],"id":70396461},{"spn":10.34,"spf":"NaN","id":70396461},{"atb":[[1.01,32.95],[2.18,8.79],[2.2,6.54]],"id":57697855}],"con":true,"img":false}]}
{"op":"mcm","clk":"11539541364","pt":1719482843871,"mc":[{"id":"1.230180122","rc":[{"atl":[[42,12]],"id":67487132},{"atl":[[32,12]],"id":70396461},{"atl":[[48,12],[28,8]],"id":57697855}],"con":true,"img":false}]}
{"op":"mcm","clk":"11539545351","pt":1719482909083,"mc":[{"id":"1.230180122","rc":[{"atb":[[2.2,0]],"id":40028187},{"atb":[[2.12,0]],"id":43318163},{"atb":[[2.22,0]],"id":47703807},{"atb":[[2.22,0]],"id":67487132},{"atb":[[2.16,0]],"id":70396461},{"atb":[[2.18,0]],"id":57697855},{"spn":15.1,"spf":"NaN","id":57697855}],"con":true,"img":false}]}
{"op":"mcm","clk":"11539545361","pt":1719482909183,"mc":[{"id":"1.230180122","rc":[{"atb":[[2.24,13.32]],"id":40028187},{"atb":[[2.16,11.1]],"id":43318163},{"atb":[[2.26,12.55]],"id":47703807},{"atb":[[2.26,13.44]],"id":67487132},{"atb":[[2.2,11.32]],"id":70396461},{"atb":[[2.22,8.79]],"id":57697855}],"con":true,"img":false}]}
{"op":"mcm","clk":"11539548835","pt":1719482962559,"mc":[{"id":"1.230180122","rc":[{"atb":[[2.2,3.16]],"id":57697855}],"con":true,"img":false}]}
{"op":"mcm","clk":"11539548911","pt":1719482963859,"mc":[{"id":"1.230180122","rc":[{"atb":[[2.24,3.16]],"id":67487132}],"con":true,"img":false}]}
{"op":"mcm","clk":"11539548952","pt":1719482964271,"mc":[{"id":"1.230180122","rc":[{"atb":[[2.22,3.16]],"id":40028187}],"con":true,"img":false}]}
{"op":"mcm","clk":"11539548980","pt":1719482964847,"mc":[{"id":"1.230180122","rc":[{"atb":[[2.14,3.16]],"id":43318163}],"con":true,"img":false}]}
{"op":"mcm","clk":"11539548991","pt":1719482965052,"mc":[{"id":"1.230180122","rc":[{"atb":[[2.24,3.16]],"id":47703807}],"con":true,"img":false}]}
{"op":"mcm","clk":"11539549033","pt":1719482965666,"mc":[{"id":"1.230180122","rc":[{"atb":[[2.18,3.16]],"id":70396461}],"con":true,"img":false}]}
{"op":"mcm","clk":"11539549193","pt":1719482968552,"mc":[{"id":"1.230180122","rc":[{"atb":[[2.24,3.38]],"id":57697855}],"con":true,"img":false}]}
{"op":"mcm","clk":"11539549205","pt":1719482968860,"mc":[{"id":"1.230180122","rc":[{"atb":[[2.26,5.38]],"id":40028187}],"con":true,"img":false}]}
{"op":"mcm","clk":"11539549292","pt":1719482970355,"mc":[{"id":"1.230180122","rc":[{"spn":76.08,"spf":"NaN","id":43318163},{"spn":76.13,"spf":"NaN","id":47703807},{"spn":13.63,"spf":"NaN","id":67487132},{"atb":[[2.22,3.38]],"id":70396461},{"spn":10.36,"spf":"NaN","id":70396461},{"spn":15.12,"spf":"NaN","id":57697855}],"con":true,"img":false}]}
{"op":"mcm","clk":"11539549304","pt":1719482970559,"mc":[{"id":"1.230180122","rc":[{"atb":[[2.28,3.38]],"id":47703807}],"con":true,"img":false}]}
{"op":"mcm","clk":"11539549312","pt":1719482970663,"mc":[{"id":"1.230180122","rc":[{"atb":[[2.18,3.38]],"id":43318163}],"con":true,"img":false}]}
{"op":"mcm","clk":"11539549346","pt":1719482971180,"mc":[{"id":"1.230180122","rc":[{"atb":[[2.28,3.38]],"id":67487132}],"con":true,"img":false}]}
{"op":"mcm","clk":"11539553407","pt":1719483029464,"mc":[{"id":"1.230180122","rc":[{"atb":[[2.22,0]],"id":40028187},{"atb":[[2.14,0]],"id":43318163},{"atb":[[2.24,0]],"id":47703807},{"atb":[[2.24,0]],"id":67487132},{"atb":[[2.18,0]],"id":70396461},{"atb":[[2.2,0]],"id":57697855}],"con":true,"img":false}]}
{"op":"mcm","clk":"11539573345","pt":1719483326619,"mc":[{"id":"1.230180122","rc":[{"spn":76.09,"spf":"NaN","id":43318163},{"spn":76.14,"spf":"NaN","id":47703807},{"spn":13.64,"spf":"NaN","id":67487132},{"atb":[[2.24,6.54]],"id":57697855}],"con":true,"img":false}]}
{"op":"mcm","clk":"11539573368","pt":1719483326961,"mc":[{"id":"1.230180122","rc":[{"atb":[[2.18,6.54]],"id":43318163}],"con":true,"img":false}]}
{"op":"mcm","clk":"11539573400","pt":1719483327310,"mc":[{"id":"1.230180122","rc":[{"atb":[[2.22,6.54]],"id":70396461}],"con":true,"img":false}]}
{"op":"mcm","clk":"11539573428","pt":1719483327626,"mc":[{"id":"1.230180122","rc":[{"atb":[[2.28,6.54]],"id":67487132}],"con":true,"img":false}]}
{"op":"mcm","clk":"11539573449","pt":1719483327828,"mc":[{"id":"1.230180122","rc":[{"atb":[[2.28,6.54]],"id":47703807}],"con":true,"img":false}]}
{"op":"mcm","clk":"11539573477","pt":1719483328242,"mc":[{"id":"1.230180122","rc":[{"atb":[[2.26,8.54]],"id":40028187}],"con":true,"img":false}]}
{"op":"mcm","clk":"11539725479","pt":1719485330088,"mc":[{"id":"1.230180122","rc":[{"atb":[[3.3,6]],"id":40028187},{"spn":76.65,"spf":"NaN","id":40028187},{"atb":[[3.3,6]],"id":43318163},{"spn":76.65,"spf":"NaN","id":43318163},{"atb":[[3.75,6]],"id":47703807},{"spn":76.87,"spf":"NaN","id":47703807},{"atb":[[3.1,6]],"id":67487132},{"spn":14.05,"spf":"NaN","id":67487132},{"atb":[[2.58,6]],"id":70396461},{"spn":10.54,"spf":"NaN","id":70396461},{"atb":[[3.1,6]],"id":57697855},{"spn":15.55,"spf":"NaN","id":57697855}],"con":true,"img":false}]}
{"op":"mcm","clk":"11539727205","pt":1719485348803,"mc":[{"id":"1.230180122","rc":[{"atb":[[2.26,5.38]],"id":40028187},{"atb":[[2.18,3.38]],"id":43318163},{"atb":[[2.28,3.38]],"id":47703807},{"atb":[[2.28,3.38]],"id":67487132},{"atb":[[2.24,3.38]],"id":57697855}],"con":true,"img":false}]}
{"op":"mcm","clk":"11539727899","pt":1719485356428,"mc":[{"id":"1.230180122","rc":[{"atb":[[3.35,2]],"id":40028187}],"con":true,"img":false}]}
{"op":"mcm","clk":"11539728428","pt":1719485362839,"mc":[{"id":"1.230180122","rc":[{"atb":[[2.26,2]],"id":40028187},{"atb":[[2.18,0]],"id":43318163},{"atb":[[2.28,0]],"id":47703807},{"atb":[[2.28,0]],"id":67487132},{"atb":[[2.24,0]],"id":57697855}],"con":true,"img":false}]}
{"op":"mcm","clk":"11539804381","pt":1719486424861,"mc":[{"id":"1.230180122","rc":[{"atb":[[2.24,13.32],[1.03,10.98],[5,1]],"id":40028187},{"spn":77.5,"spf":"NaN","id":40028187},{"atb":[[5,1],[1.02,16.47],[2.16,11.1]],"id":43318163},{"spn":77.5,"spf":"NaN","id":43318163},{"atb":[[5,1],[1.02,16.47],[2.26,12.55]],"id":47703807},{"spn":77.5,"spf":"NaN","id":47703807},{"atb":[[1.01,32.95],[2.26,13.45],[4.7,1]],"id":67487132},{"spn":14.85,"spf":"NaN","id":67487132},{"atb":[[2.22,6.54],[3.95,1],[1.02,16.47],[2.2,11.32]],"id":70396461},{"spn":11.22,"spf":"NaN","id":70396461},{"atb":[[1.01,32.95],[2.22,8.79],[4.7,1]],"id":57697855},{"spn":16.35,"spf":"NaN","id":57697855}],"con":true,"img":false}]}
{"op":"mcm","clk":"11539805486","pt":1719486438266,"mc":[{"id":"1.230180122","rc":[{"atb":[[1.51,196.08]],"id":40028187},{"atb":[[1.51,196.08]],"id":43318163},{"atb":[[1.51,196.08]],"id":47703807},{"atb":[[1.51,196.08]],"id":67487132},{"atb":[[1.51,196.08]],"id":57697855}],"con":true,"img":false}]}
{"op":"mcm","clk":"11539817354","pt":1719486506560,"mc":[{"id":"1.230180122","rc":[{"atb":[[2.2,0]],"id":70396461}],"con":true,"img":false}]}
{"op":"mcm","clk":"11539817364","pt":1719486506614,"mc":[{"id":"1.230180122","rc":[{"atb":[[2.24,11.32]],"id":70396461}],"con":true,"img":false}]}
{"op":"mcm","clk":"11539819030","pt":1719486524565,"mc":[{"id":"1.230180122","rc":[{"atb":[[2.22,3.38]],"id":70396461}],"con":true,"img":false}]}
{"op":"mcm","clk":"11539819071","pt":1719486525077,"mc":[{"id":"1.230180122","rc":[{"atb":[[2.26,3.16]],"id":70396461}],"con":true,"img":false}]}
{"op":"mcm","clk":"11539825750","pt":1719486604785,"mc":[{"id":"1.230180122","rc":[{"atb":[[2.22,0]],"id":70396461}],"con":true,"img":false}]}
{"op":"mcm","clk":"11539826084","pt":1719486609062,"mc":[{"id":"1.230180122","rc":[{"atb":[[2.26,6.54]],"id":70396461}],"con":true,"img":false}]}
{"op":"mcm","clk":"11539840618","pt":1719486806433,"mc":[{"id":"1.230180122","rc":[{"atb":[[2.24,0]],"id":70396461}],"con":true,"img":false}]}
{"op":"mcm","clk":"11539840627","pt":1719486806535,"mc":[{"id":"1.230180122","rc":[{"atb":[[2.28,11.32]],"id":70396461}],"con":true,"img":false}]}
{"op":"mcm","clk":"11539841535","pt":1719486821449,"mc":[{"id":"1.230180122","rc":[{"atb":[[2.26,3.38]],"id":70396461}],"con":true,"img":false}]}
{"op":"mcm","clk":"11539843131","pt":1719486845447,"mc":[{"id":"1.230180122","rc":[{"atb":[[2.26,0]],"id":70396461}],"con":true,"img":false}]}
{"op":"mcm","clk":"11539848891","pt":1719486926795,"mc":[{"id":"1.230180122","rc":[{"atb":[[2.3,3.38]],"id":70396461}],"con":true,"img":false}]}
{"op":"mcm","clk":"11539850371","pt":1719486945605,"mc":[{"id":"1.230180122","rc":[{"atb":[[2.3,6.54]],"id":70396461}],"con":true,"img":false}]}
{"op":"mcm","clk":"11539884768","pt":1719487391711,"mc":[{"id":"1.230180122","rc":[{"atb":[[2.12,89.29]],"id":40028187},{"atb":[[2.12,89.29]],"id":43318163},{"atb":[[2.12,89.29]],"id":47703807},{"atb":[[1.51,196.08]],"id":70396461}],"con":true,"img":false}]}
{"op":"mcm","clk":"11540014363","pt":1719488999045,"mc":[{"id":"1.230180122","rc":[{"atl":[[550,2]],"id":40028187},{"atl":[[390,2]],"id":43318163},{"atb":[[1.16,150]],"id":47703807},{"atl":[[560,2]],"id":47703807},{"atb":[[1.16,150]],"id":67487132},{"atl":[[370,2]],"id":67487132},{"atb":[[1.16,150]],"id":70396461},{"atl":[[270,2]],"id":70396461},{"atb":[[1.16,150]],"id":57697855},{"atl":[[500,2]],"id":57697855}],"con":true,"img":false}]}
{"op":"mcm","clk":"11540014372","pt":1719488999145,"mc":[{"id":"1.230180122","rc":[{"atb":[[1.16,150]],"id":40028187},{"atb":[[1.16,150]],"id":43318163}],"con":true,"img":false}]}
{"op":"mcm","clk":"11540136248","pt":1719490399656,"mc":[{"id":"1.230180122","rc":[{"atb":[[2.3,6.54],[2.28,0]],"id":70396461}],"con":true,"img":false}]}
{"op":"mcm","clk":"11540136260","pt":1719490399757,"mc":[{"id":"1.230180122","rc":[{"atb":[[2.32,11.32]],"id":70396461}],"con":true,"img":false}]}
{"op":"mcm","clk":"11540141574","pt":1719490452016,"mc":[{"id":"1.230180122","rc":[{"atb":[[2.3,3.16]],"id":70396461}],"con":true,"img":false}]}
{"op":"mcm","clk":"11540141804","pt":1719490454314,"mc":[{"id":"1.230180122","rc":[{"atb":[[2.34,3.38]],"id":70396461}],"con":true,"img":false}]}
{"op":"mcm","clk":"11540144049","pt":1719490475919,"mc":[{"id":"1.230180122","rc":[{"atb":[[2.3,0]],"id":70396461}],"con":true,"img":false}]}
{"op":"mcm","clk":"11540145583","pt":1719490490237,"mc":[{"id":"1.230180122","rc":[{"atb":[[2.34,6.54]],"id":70396461}],"con":true,"img":false}]}
{"op":"mcm","clk":"11540164663","pt":1719490697678,"mc":[{"id":"1.230180122","rc":[{"atb":[[2.32,0]],"id":70396461}],"con":true,"img":false}]}
{"op":"mcm","clk":"11540164672","pt":1719490697802,"mc":[{"id":"1.230180122","rc":[{"atb":[[2.36,11.32]],"id":70396461}],"con":true,"img":false}]}
{"op":"mcm","clk":"11540168674","pt":1719490748151,"mc":[{"id":"1.230180122","rc":[{"atb":[[2.34,3.38]],"id":70396461}],"con":true,"img":false}]}
{"op":"mcm","clk":"11540168717","pt":1719490748672,"mc":[{"id":"1.230180122","rc":[{"atb":[[2.38,3.16]],"id":70396461}],"con":true,"img":false}]}
{"op":"mcm","clk":"11540171232","pt":1719490786020,"mc":[{"id":"1.230180122","rc":[{"atb":[[2.34,0]],"id":70396461}],"con":true,"img":false}]}
{"op":"mcm","clk":"11540173297","pt":1719490812154,"mc":[{"id":"1.230180122","rc":[{"atb":[[2.38,6.54]],"id":70396461}],"con":true,"img":false}]}
{"op":"mcm","clk":"11540334702","pt":1719493167060,"mc":[{"id":"1.230180122","rc":[{"atb":[[1.04,91.36]],"id":40028187},{"atl":[[970,1.76]],"id":40028187},{"atb":[[1.03,164.11]],"id":43318163},{"atl":[[990,0.85]],"id":43318163},{"atb":[[1.03,65.98]],"id":47703807},{"atl":[[960,1.91]],"id":47703807},{"atb":[[1.02,151.42]],"id":67487132},{"atl":[[980,0.85]],"id":67487132},{"atb":[[1.02,172.98]],"id":70396461},{"atl":[[960,1.85]],"id":70396461},{"atb":[[1.03,153.96]],"id":57697855},{"atl":[[980,1.18]],"id":57697855}],"con":true,"img":false}]}
{"op":"mcm","clk":"11540493655","pt":1719495148597,"mc":[{"id":"1.230180122","rc":[{"atb":[[2.24,13.33],[1.03,11],[1.04,91.47]],"id":40028187},{"atl":[[970,1.77],[990,0.17]],"id":40028187},{"atb":[[1.03,164.3],[1.02,16.49],[2.16,11.12]],"id":43318163},{"atl":[[990,0.85],[1000,0.17]],"id":43318163},{"atb":[[1.03,66.06],[1.02,16.49],[2.26,12.56]],"id":47703807},{"atl":[[960,1.91],[1000,0.17]],"id":47703807},{"atb":[[1.01,32.99],[1.02,151.6],[2.26,13.46]],"id":67487132},{"atl":[[980,0.85],[990,0.17]],"id":67487132},{"atb":[[2.36,11.34],[2.38,6.54],[1.02,173.18]],"id":70396461},{"atl":[[960,1.85],[1000,0.17]],"id":70396461},{"spl":[[1.01,1]],"id":57697855},{"atb":[[1.01,32.99],[1.03,154.14],[2.22,8.8]],"id":57697855},{"atl":[[980,1.18],[990,0.17]],"id":57697855},{"spn":4.7,"spf":1.0,"id":57697855}],"con":true,"img":false}]}
{"op":"mcm","clk":"11540685098","pt":1719497282631,"mc":[{"id":"1.230180122","marketDefinition":{"bspMarket":true,"turnInPlayEnabled":false,"persistenceEnabled":false,"marketBaseRate":5.0,"eventId":"33376437","eventTypeId":"4339","numberOfWinners":1,"bettingType":"ODDS","marketType":"WIN","marketTime":"2024-06-27T15:07:00.000Z","suspendTime":"2024-06-27T15:07:00.000Z","bspReconciled":false,"complete":true,"inPlay":false,"crossMatching":true,"runnersVoidable":false,"numberOfActiveRunners":6,"betDelay":0,"status":"OPEN","runners":[{"status":"ACTIVE","sortPriority":1,"id":67487132,"name":"1. Salacres Belleza"},{"status":"ACTIVE","sortPriority":2,"id":43318163,"name":"2. Walking Dead"},{"status":"ACTIVE","sortPriority":3,"id":40028187,"name":"3. The Grafter"},{"status":"ACTIVE","sortPriority":4,"id":70396461,"name":"4. Late Yahoo"},{"status":"ACTIVE","sortPriority":5,"id":47703807,"name":"5. Fabulous Twirl"},{"status":"ACTIVE","sortPriority":6,"id":57697855,"name":"6. Salacres Driller"}],"regulators":["MR_INT"],"venue":"Towcester","countryCode":"GB","discountAllowed":true,"timezone":"Europe/London","openDate":"2024-06-27T13:33:00.000Z","version":5994767067,"name":"A5 500m","eventName":"Towcester 27th Jun"},"rc":[{"atb":[[2.24,13.33],[5,1],[1.16,150],[1.03,10.99],[3.35,2],[2.12,89.29],[2.26,2],[1.51,196.08],[3.3,6],[1.04,91.43]],"id":40028187},{"atl":[[550,2],[150,4],[970,1.76],[990,0.17]],"id":40028187},{"spn":77.5,"spf":"NaN","id":40028187},{"atb":[[5,1],[1.16,150],[1.03,164.23],[1.02,16.49],[2.12,89.29],[1.51,196.08],[3.3,6],[2.16,11.11]],"id":43318163},{"atl":[[150,4],[390,2],[990,0.85],[1000,0.17]],"id":43318163},{"spn":77.5,"spf":"NaN","id":43318163},{"atb":[[5,1],[1.16,150],[1.03,66.03],[1.02,16.49],[2.12,89.29],[2.26,12.56],[1.51,196.08],[3.75,6]],"id":47703807},{"atl":[[560,2],[150,4],[960,1.91],[1000,0.17]],"id":47703807},{"spn":77.5,"spf":"NaN","id":47703807},{"atb":[[1.01,32.98],[1.16,150],[3.1,6],[1.02,151.54],[2.26,13.46],[1.51,196.08],[4.7,1]],"id":67487132},{"atl":[[150,4],[42,12],[370,2],[25,8],[28,0.6],[980,0.85],[990,0.17]],"id":67487132},{"spn":14.85,"spf":"NaN","id":67487132},{"atb":[[2.36,11.33],[1.16,150],[3.95,1],[2.38,6.54],[1.02,173.11],[2.58,6],[1.51,196.08]],"id":70396461},{"atl":[[32,12],[270,2],[18.5,8],[150,4],[960,1.85],[1000,0.17]],"id":70396461},{"spn":11.22,"spf":"NaN","id":70396461},{"spl":[[1.01,1]],"id":57697855},{"atb":[[1.01,32.98],[1.16,150],[1.03,154.08],[3.1,6],[2.22,8.8],[1.51,196.08],[4.7,1]],"id":57697855},{"atl":[[150,4],[48,12],[28,8],[980,1.18],[990,0.17],[500,2]],"id":57697855},{"spn":4.7,"spf":1.0,"id":57697855}],"con":true,"img":true}]}
{"op":"mcm","clk":"11540794602","pt":1719498456581,"mc":[{"id":"1.230180122","rc":[{"atb":[[2.24,13.33],[1.03,10.99],[1.04,91.43]],"id":40028187},{"atl":[[970,1.76]],"id":40028187},{"atb":[[1.03,164.23],[1.02,16.49],[2.16,11.11]],"id":43318163},{"atl":[[990,0.85]],"id":43318163},{"atb":[[1.03,66.03],[1.02,16.49],[2.26,12.56]],"id":47703807},{"atl":[[960,1.91]],"id":47703807},{"atb":[[1.01,32.98],[1.02,151.54],[2.26,13.46]],"id":67487132},{"atl":[[980,0.85]],"id":67487132},{"atb":[[2.36,11.33],[2.38,6.54],[1.02,173.11]],"id":70396461},{"atl":[[960,1.85]],"id":70396461},{"atb":[[1.01,32.98],[1.03,154.08],[2.22,8.8]],"id":57697855},{"atl":[[27,1.63],[980,1.18]],"id":57697855}],"con":true,"img":false}]}
{"op":"mcm","clk":"11540794622","pt":1719498456890,"mc":[{"id":"1.230180122","rc":[{"atl":[[18,1.52]],"id":70396461}],"con":true,"img":false}]}
{"op":"mcm","clk":"11540794651","pt":1719498457200,"mc":[{"id":"1.230180122","rc":[{"atl":[[24,1.59]],"id":67487132}],"con":true,"img":false}]}
{"op":"mcm","clk":"11540852366","pt":1719499122929,"mc":[{"id":"1.230180122","rc":[{"atb":[[4.7,1]],"id":40028187},{"atb":[[4.7,1]],"id":43318163},{"atb":[[6,1]],"id":47703807},{"spn":78.0,"spf":"NaN","id":47703807},{"atb":[[3.7,1]],"id":67487132},{"spn":14.35,"spf":"NaN","id":67487132},{"atb":[[3.1,1]],"id":70396461},{"spn":10.97,"spf":"NaN","id":70396461},{"atb":[[3.7,1]],"id":57697855}],"con":true,"img":false}]}
{"op":"mcm","clk":"11540853236","pt":1719499136150,"mc":[{"id":"1.230180122","rc":[{"atb":[[2.12,89.29]],"id":67487132},{"atb":[[2.12,89.29]],"id":57697855}],"con":true,"img":false}]}
{"op":"mcm","clk":"11540867226","pt":1719499322371,"mc":[{"id":"1.230180122","rc":[{"atl":[[190,4]],"id":40028187},{"atl":[[190,4]],"id":43318163},{"atl":[[190,4]],"id":47703807},{"atl":[[190,4]],"id":67487132},{"atl":[[190,4]],"id":70396461},{"atl":[[190,4]],"id":57697855}],"con":true,"img":false}]}
{"op":"mcm","clk":"11540870825","pt":1719499367944,"mc":[{"id":"1.230180122","rc":[{"atb":[[1.02,153.54]],"id":67487132}],"con":true,"img":false}]}
{"op":"mcm","clk":"11540870838","pt":1719499368105,"mc":[{"id":"1.230180122","rc":[{"atb":[[1.02,18.49]],"id":43318163}],"con":true,"img":false}]}
{"op":"mcm","clk":"11540870860","pt":1719499368307,"mc":[{"id":"1.230180122","rc":[{"atb":[[1.02,2]],"id":40028187}],"con":true,"img":false}]}
{"op":"mcm","clk":"11540870887","pt":1719499368723,"mc":[{"id":"1.230180122","rc":[{"atb":[[1.02,175.11]],"id":70396461}],"con":true,"img":false}]}
{"op":"mcm","clk":"11540870914","pt":1719499369039,"mc":[{"id":"1.230180122","rc":[{"atb":[[1.02,18.49]],"id":47703807}],"con":true,"img":false}]}
{"op":"mcm","clk":"11540870935","pt":1719499369341,"mc":[{"id":"1.230180122","rc":[{"atb":[[1.02,2]],"id":57697855}],"con":true,"img":false}]}
{"op":"mcm","clk":"11540889082","pt":1719499603995,"mc":[{"id":"1.230180122","rc":[{"spl":[[1.01,1]],"id":47703807},{"spn":6.0,"spf":1.0,"id":47703807}],"con":true,"img":false}]}
{"op":"mcm","clk":"11540896438","pt":1719499694710,"mc":[{"id":"1.230180122","rc":[{"atb":[[4.7,0]],"id":57697855},{"trd":[[4.7,1.99]],"ltp":4.7,"tv":1.99,"id":57697855},{"spn":3.7,"spf":1.0,"id":57697855}],"con":true,"img":false}]}
{"op":"mcm","clk":"11540896625","pt":1719499697390,"mc":[{"id":"1.230180122","rc":[{"atb":[[4.2,1]],"id":57697855}],"con":true,"img":false}]}
{"op":"mcm","clk":"11540913327","pt":1719499891018,"mc":[{"id":"1.230180122","rc":[{"atl":[[23,0.84]],"id":67487132},{"spn":13.85,"spf":"NaN","id":67487132},{"atl":[[17.5,0.84]],"id":70396461},{"spn":10.72,"spf":"NaN","id":70396461},{"atl":[[26,0.84]],"id":57697855},{"spn":4.2,"spf":1.0,"id":57697855}],"con":true,"img":false}]}
{"op":"mcm","clk":"11540915789","pt":1719499920135,"mc":[{"id":"1.230180122","rc":[{"atl":[[17.5,2.84]],"id":70396461}],"con":true,"img":false}]}
{"op":"mcm","clk":"11540915793","pt":1719499920224,"mc":[{"id":"1.230180122","rc":[{"atb":[[2.6,6.55]],"id":70396461},{"atl":[[18,7.4]],"id":70396461}],"con":true,"img":false}]}
{"op":"mcm","clk":"11540915827","pt":1719499920658,"mc":[{"id":"1.230180122","rc":[{"atb":[[3.4,2]],"id":40028187},{"atl":[[75,2]],"id":40028187},{"atb":[[3.35,11.12]],"id":43318163},{"atl":[[100,2]],"id":43318163},{"atb":[[3.8,12.56]],"id":47703807},{"atl":[[140,2]],"id":47703807},{"atb":[[3.15,8.8]],"id":57697855},{"atl":[[27,5.48]],"id":57697855}],"con":true,"img":false}]}
{"op":"mcm","clk":"11540915837","pt":1719499920759,"mc":[{"id":"1.230180122","rc":[{"atb":[[3.15,13.46]],"id":67487132},{"atl":[[24,3.59]],"id":67487132}],"con":true,"img":false}]}
{"op":"mcm","clk":"11540915922","pt":1719499921639,"mc":[{"id":"1.230180122","rc":[{"atb":[[1.1,1.69]],"id":57697855}],"con":true,"img":false}]}
{"op":"mcm","clk":"11540915948","pt":1719499921846,"mc":[{"id":"1.230180122","rc":[{"atb":[[1.1,1.69]],"id":67487132}],"con":true,"img":false}]}
{"op":"mcm","clk":"11540915967","pt":1719499922054,"mc":[{"id":"1.230180122","rc":[{"atb":[[1.14,1.69]],"id":47703807}],"con":true,"img":false}]}
{"op":"mcm","clk":"11540915973","pt":1719499922153,"mc":[{"id":"1.230180122","rc":[{"atb":[[1.09,1.69]],"id":70396461}],"con":true,"img":false}]}
{"op":"mcm","clk":"11540915984","pt":1719499922261,"mc":[{"id":"1.230180122","rc":[{"atb":[[1.12,1.69]],"id":40028187}],"con":true,"img":false}]}
{"op":"mcm","clk":"11540915992","pt":1719499922354,"mc":[{"id":"1.230180122","rc":[{"atb":[[4.6,1]],"id":47703807},{"atl":[[15.5,1]],"id":47703807},{"atl":[[6.8,1]],"id":70396461}],"con":true,"img":false}]}
{"op":"mcm","clk":"11540916000","pt":1719499922476,"mc":[{"id":"1.230180122","rc":[{"atb":[[1.12,1.69]],"id":43318163}],"con":true,"img":false}]}
{"op":"mcm","clk":"11540916012","pt":1719499922564,"mc":[{"id":"1.230180122","rc":[{"atb":[[1.1,0.06]],"id":67487132}],"con":true,"img":false}]}
{"op":"mcm","clk":"11540916044","pt":1719499922934,"mc":[{"id":"1.230180122","rc":[{"atb":[[1.03,12.7]],"id":40028187},{"atl":[[1000,1.7]],"id":40028187},{"atb":[[1.03,165.94]],"id":43318163},{"atl":[[1000,1.88]],"id":43318163},{"atb":[[1.14,0.05]],"id":47703807},{"atb":[[1.02,155.24]],"id":67487132},{"atl":[[1000,1.7]],"id":67487132}],"con":true,"img":false}]}
{"op":"mcm","clk":"11540916063","pt":1719499923137,"mc":[{"id":"1.230180122","rc":[{"atb":[[1.03,11.08]],"id":40028187},{"atl":[[1000,0]],"id":40028187},{"atb":[[1.03,164.32]],"id":43318163},{"atl":[[1000,0.17]],"id":43318163},{"atb":[[1.02,153.65]],"id":67487132},{"atl":[[1000,0.01]],"id":67487132},{"atl":[[17.5,0.84],[18,5.88]],"id":70396461}],"con":true,"img":false}]}
{"op":"mcm","clk":"11540916078","pt":1719499923356,"mc":[{"id":"1.230180122","rc":[{"atb":[[1.03,10.99]],"id":40028187},{"atb":[[1.03,164.23]],"id":43318163},{"atb":[[1.02,153.54]],"id":67487132},{"atl":[[1000,0]],"id":67487132}],"con":true,"img":false}]}
{"op":"mcm","clk":"11540916091","pt":1719499923450,"mc":[{"id":"1.230180122","rc":[{"atb":[[4.8,0.08]],"id":40028187},{"atb":[[4.8,0.08]],"id":43318163},{"atb":[[3.75,0.11]],"id":67487132},{"atl":[[23,0.86]],"id":67487132}],"con":true,"img":false}]}
{"op":"mcm","clk":"11540916102","pt":1719499923677,"mc":[{"id":"1.230180122","rc":[{"atb":[[1.1,0.06]],"id":57697855}],"con":true,"img":false}]}
{"op":"mcm","clk":"11540916115","pt":1719499923757,"mc":[{"id":"1.230180122","rc":[{"atb":[[1.1,0]],"id":67487132}],"con":true,"img":false}]}
{"op":"mcm","clk":"11540916124","pt":1719499923860,"mc":[{"id":"1.230180122","rc":[{"atb":[[4.8,0.06]],"id":67487132}],"con":true,"img":false}]}
{"op":"mcm","clk":"11540916135","pt":1719499923960,"mc":[{"id":"1.230180122","rc":[{"atb":[[1.09,0.07]],"id":70396461}],"con":true,"img":false}]}
{"op":"mcm","clk":"11540916151","pt":1719499924170,"mc":[{"id":"1.230180122","rc":[{"atb":[[1.12,0.05]],"id":40028187}],"con":true,"img":false}]}
{"op":"mcm","clk":"11540916175","pt":1719499924435,"mc":[{"id":"1.230180122","rc":[{"atb":[[1.12,0.05]],"id":43318163}],"con":true,"img":false}]}
{"op":"mcm","clk":"11540916213","pt":1719499925042,"mc":[{"id":"1.230180122","rc":[{"atb":[[1.14,0]],"id":47703807}],"con":true,"img":false}]}
{"op":"mcm","clk":"11540916222","pt":1719499925143,"mc":[{"id":"1.230180122","rc":[{"atb":[[6.2,0.05]],"id":47703807}],"con":true,"img":false}]}
{"op":"mcm","clk":"11540916289","pt":1719499926073,"mc":[{"id":"1.230180122","rc":[{"atb":[[2.38,3.15]],"id":70396461}],"con":true,"img":false}]}
{"op":"mcm","clk":"11540916303","pt":1719499926235,"mc":[{"id":"1.230180122","rc":[{"atb":[[1.1,0]],"id":57697855}],"con":true,"img":false}]}
{"op":"mcm","clk":"11540916310","pt":1719499926332,"mc":[{"id":"1.230180122","rc":[{"atb":[[4.3,0.06]],"id":57697855}],"con":true,"img":false}]}
{"op":"mcm","clk":"11540916327","pt":1719499926539,"mc":[{"id":"1.230180122","rc":[{"atb":[[2.62,3.38]],"id":70396461}],"con":true,"img":false}]}
{"op":"mcm","clk":"11540916334","pt":1719499926647,"mc":[{"id":"1.230180122","rc":[{"atb":[[1.09,0]],"id":70396461}],"con":true,"img":false}]}
{"op":"mcm","clk":"11540916349","pt":1719499926757,"mc":[{"id":"1.230180122","rc":[{"atb":[[4,0.07]],"id":70396461}],"con":true,"img":false}]}
{"op":"mcm","clk":"11540916364","pt":1719499926958,"mc":[{"id":"1.230180122","rc":[{"atb":[[2.88,6],[2.6,0]],"id":70396461}],"con":true,"img":false}]}
{"op":"mcm","clk":"11540916374","pt":1719499927059,"mc":[{"id":"1.230180122","rc":[{"atb":[[1.12,0]],"id":40028187}],"con":true,"img":false}]}
{"op":"mcm","clk":"11540916382","pt":1719499927158,"mc":[{"id":"1.230180122","rc":[{"atb":[[5.1,0.05]],"id":40028187}],"con":true,"img":false}]}
{"op":"mcm","clk":"11540916411","pt":1719499927463,"mc":[{"id":"1.230180122","rc":[{"atb":[[1.12,0]],"id":43318163}],"con":true,"img":false}]}
{"op":"mcm","clk":"11540916420","pt":1719499927565,"mc":[{"id":"1.230180122","rc":[{"atb":[[5.1,0.05]],"id":43318163}],"con":true,"img":false}]}
{"op":"mcm","clk":"11540916575","pt":1719499929445,"mc":[{"id":"1.230180122","rc":[{"atb":[[2.38,0]],"id":70396461}],"con":true,"img":false}]}
{"op":"mcm","clk":"11540916610","pt":1719499929857,"mc":[{"id":"1.230180122","rc":[{"atb":[[2.9,3.15]],"id":70396461}],"con":true,"img":false}]}
{"op":"mcm","clk":"11540916680","pt":1719499930775,"mc":[{"id":"1.230180122","rc":[{"atb":[[3.8,0]],"id":47703807},{"atb":[[3.45,8.8]],"id":57697855}],"con":true,"img":false}]}
{"op":"mcm","clk":"11540916697","pt":1719499930894,"mc":[{"id":"1.230180122","rc":[{"atl":[[70,2],[75,0]],"id":40028187},{"atb":[[3.35,0],[3.95,11.12]],"id":43318163},{"atl":[[95,2],[100,0]],"id":43318163},{"atb":[[4.6,7]],"id":47703807},{"atb":[[3.15,0]],"id":57697855}],"con":true,"img":false}]}
{"op":"mcm","clk":"11540916842","pt":1719499932545,"mc":[{"id":"1.230180122","rc":[{"atl":[[6.6,2]],"id":70396461}],"con":true,"img":false}]}
{"op":"mcm","clk":"11540916849","pt":1719499932645,"mc":[{"id":"1.230180122","rc":[{"atl":[[18,0],[7.4,5.88]],"id":70396461}],"con":true,"img":false}]}
{"op":"mcm","clk":"11540917224","pt":1719499937747,"mc":[{"id":"1.230180122","rc":[{"atl":[[6.6,0]],"id":70396461}],"con":true,"img":false}]}
{"op":"mcm","clk":"11540917233","pt":1719499937847,"mc":[{"id":"1.230180122","rc":[{"atl":[[17.5,6.9],[7.4,0]],"id":70396461}],"con":true,"img":false}]}
{"op":"mcm","clk":"11540917405","pt":1719499940161,"mc":[{"id":"1.230180122","rc":[{"atl":[[6.6,2]],"id":70396461}],"con":true,"img":false}]}
{"op":"mcm","clk":"11540917817","pt":1719499945483,"mc":[{"id":"1.230180122","rc":[{"atl":[[6.6,0]],"id":70396461}],"con":true,"img":false}]}
{"op":"mcm","clk":"11540917950","pt":1719499947280,"mc":[{"id":"1.230180122","rc":[{"atl":[[6.6,2]],"id":70396461}],"con":true,"img":false}]}
{"op":"mcm","clk":"11540917985","pt":1719499947788,"mc":[{"id":"1.230180122","rc":[{"atl":[[17.5,0.84],[7.4,8]],"id":70396461}],"con":true,"img":false}]}
{"op":"mcm","clk":"11540918026","pt":1719499948467,"mc":[{"id":"1.230180122","rc":[{"atl":[[26,1.82]],"id":57697855}],"con":true,"img":false}]}
{"op":"mcm","clk":"11540918112","pt":1719499949789,"mc":[{"id":"1.230180122","rc":[{"atl":[[27,3.85]],"id":57697855}],"con":true,"img":false}]}
{"op":"mcm","clk":"11540918309","pt":1719499952696,"mc":[{"id":"1.230180122","rc":[{"spn":37.55,"spf":"NaN","id":40028187},{"spn":50.05,"spf":"NaN","id":43318163},{"spn":6.01,"spf":1.0,"id":47703807},{"spn":13.9,"spf":"NaN","id":67487132},{"atl":[[6.6,0]],"id":70396461},{"spn":5.4,"spf":"NaN","id":70396461},{"spn":4.2,"spf":1.0,"id":57697855}],"con":true,"img":false}]}
{"op":"mcm","clk":"11540918326","pt":1719499952895,"mc":[{"id":"1.230180122","rc":[{"atl":[[17.5,6.9],[7.4,0]],"id":70396461}],"con":true,"img":false}]}
{"op":"mcm","clk":"11540918444","pt":1719499954792,"mc":[{"id":"1.230180122","rc":[{"atl":[[6.6,2]],"id":70396461}],"con":true,"img":false}]}
{"op":"mcm","clk":"11540918452","pt":1719499954894,"mc":[{"id":"1.230180122","rc":[{"atl":[[17.5,0.84],[7.4,8]],"id":70396461}],"con":true,"img":false}]}
{"op":"mcm","clk":"11540918521","pt":1719499956001,"mc":[{"id":"1.230180122","rc":[{"atl":[[25,1.68]],"id":57697855}],"con":true,"img":false}]}
{"op":"mcm","clk":"11540918530","pt":1719499956101,"mc":[{"id":"1.230180122","rc":[{"atl":[[25,3.68],[27,0]],"id":57697855}],"con":true,"img":false}]}
{"op":"mcm","clk":"11540918553","pt":1719499956478,"mc":[{"id":"1.230180122","rc":[{"atl":[[26,0.84]],"id":57697855}],"con":true,"img":false}]}
{"op":"mcm","clk":"11540918570","pt":1719499956681,"mc":[{"id":"1.230180122","rc":[{"atl":[[24,1.05]],"id":57697855}],"con":true,"img":false}]}
{"op":"mcm","clk":"11540918646","pt":1719499957802,"mc":[{"id":"1.230180122","rc":[{"atb":[[6,2.02]],"id":47703807}],"con":true,"img":false}]}
{"op":"mcm","clk":"11540918842","pt":1719499960191,"mc":[{"id":"1.230180122","rc":[{"atl":[[6.6,0]],"id":70396461}],"con":true,"img":false}]}
{"op":"mcm","clk":"11540918850","pt":1719499960290,"mc":[{"id":"1.230180122","rc":[{"atl":[[17.5,6.9],[7.4,0]],"id":70396461}],"con":true,"img":false}]}
{"op":"mcm","clk":"11540918970","pt":1719499961789,"mc":[{"id":"1.230180122","rc":[{"atb":[[4.8,0]],"id":40028187},{"atb":[[4.8,0]],"id":43318163},{"atb":[[3.75,0]],"id":67487132},{"atl":[[23,0.84]],"id":67487132}],"con":true,"img":false}]}
{"op":"mcm","clk":"11540918984","pt":1719499961987,"mc":[{"id":"1.230180122","rc":[{"atl":[[6.6,2]],"id":70396461}],"con":true,"img":false}]}
{"op":"mcm","clk":"11540918991","pt":1719499962095,"mc":[{"id":"1.230180122","rc":[{"atl":[[23,1.94]],"id":67487132},{"atl":[[17.5,0.84],[7.4,8]],"id":70396461}],"con":true,"img":false}]}
{"op":"mcm","clk":"11540919089","pt":1719499963385,"mc":[{"id":"1.230180122","rc":[{"atb":[[2.62,0]],"id":70396461}],"con":true,"img":false}]}
{"op":"mcm","clk":"11540919117","pt":1719499963690,"mc":[{"id":"1.230180122","rc":[{"atb":[[2.9,6.54]],"id":70396461}],"con":true,"img":false}]}
{"op":"mcm","clk":"11540919229","pt":1719499965077,"mc":[{"id":"1.230180122","rc":[{"atl":[[24,2]],"id":67487132}],"con":true,"img":false}]}
{"op":"mcm","clk":"11540919412","pt":1719499967597,"mc":[{"id":"1.230180122","rc":[{"atl":[[6.6,0]],"id":70396461}],"con":true,"img":false}]}
{"op":"mcm","clk":"11540919422","pt":1719499967701,"mc":[{"id":"1.230180122","rc":[{"atl":[[17.5,6.9],[7.4,0]],"id":70396461}],"con":true,"img":false}]}
{"op":"mcm","clk":"11540919534","pt":1719499969084,"mc":[{"id":"1.230180122","rc":[{"atl":[[6.6,2]],"id":70396461}],"con":true,"img":false}]}
{"op":"mcm","clk":"11540919552","pt":1719499969301,"mc":[{"id":"1.230180122","rc":[{"atl":[[17.5,0.84],[7.4,8]],"id":70396461}],"con":true,"img":false}]}
{"op":"mcm","clk":"11540919674","pt":1719499970783,"mc":[{"id":"1.230180122","rc":[{"atl":[[22,1.69]],"id":67487132}],"con":true,"img":false}]}
{"op":"mcm","clk":"11540919686","pt":1719499970996,"mc":[{"id":"1.230180122","rc":[{"atl":[[22,3.69],[23,0.84],[24,0]],"id":67487132}],"con":true,"img":false}]}
{"op":"mcm","clk":"11540919697","pt":1719499971095,"mc":[{"id":"1.230180122","rc":[{"atl":[[22,1.69],[23,4.22]],"id":67487132}],"con":true,"img":false}]}
{"op":"mcm","clk":"11540919707","pt":1719499971205,"mc":[{"id":"1.230180122","rc":[{"atl":[[23,0.84],[24,4.35]],"id":67487132}],"con":true,"img":false}]}
{"op":"mcm","clk":"11540919723","pt":1719499971405,"mc":[{"id":"1.230180122","rc":[{"atl":[[22,3.69]],"id":67487132}],"con":true,"img":false}]}
{"op":"mcm","clk":"11540919729","pt":1719499971508,"mc":[{"id":"1.230180122","rc":[{"atl":[[24,0]],"id":67487132}],"con":true,"img":false}]}
{"op":"mcm","clk":"11540919982","pt":1719499974601,"mc":[{"id":"1.230180122","rc":[{"atl":[[6.6,0]],"id":70396461}],"con":true,"img":false}]}
{"op":"mcm","clk":"11540919990","pt":1719499974702,"mc":[{"id":"1.230180122","rc":[{"atl":[[17.5,6.9],[7.4,0]],"id":70396461}],"con":true,"img":false}]}
{"op":"mcm","clk":"11540920105","pt":1719499976192,"mc":[{"id":"1.230180122","rc":[{"atl":[[6.6,2]],"id":70396461}],"con":true,"img":false}]}
{"op":"mcm","clk":"11540920111","pt":1719499976294,"mc":[{"id":"1.230180122","rc":[{"atl":[[17.5,0.84]],"id":70396461}],"con":true,"img":false}]}
{"op":"mcm","clk":"11540920119","pt":1719499976399,"mc":[{"id":"1.230180122","rc":[{"atl":[[7.4,8]],"id":70396461}],"con":true,"img":false}]}
{"op":"mcm","clk":"11540920528","pt":1719499981595,"mc":[{"id":"1.230180122","rc":[{"atl":[[6.6,0]],"id":70396461}],"con":true,"img":false}]}
{"op":"mcm","clk":"11540920543","pt":1719499981804,"mc":[{"id":"1.230180122","rc":[{"atl":[[17.5,6.9],[7.4,0]],"id":70396461}],"con":true,"img":false}]}
{"op":"mcm","clk":"11540920733","pt":1719499983926,"mc":[{"id":"1.230180122","rc":[{"atl":[[6.6,2]],"id":70396461}],"con":true,"img":false}]}
{"op":"mcm","clk":"11540921148","pt":1719499989220,"mc":[{"id":"1.230180122","rc":[{"atl":[[6.6,0]],"id":70396461}],"con":true,"img":false}]}
{"op":"mcm","clk":"11540921264","pt":1719499991023,"mc":[{"id":"1.230180122","rc":[{"atl":[[6.6,2]],"id":70396461}],"con":true,"img":false}]}
{"op":"mcm","clk":"11540921285","pt":1719499991322,"mc":[{"id":"1.230180122","rc":[{"atl":[[17.5,0.84],[7.4,8]],"id":70396461}],"con":true,"img":false}]}
{"op":"mcm","clk":"11540921627","pt":1719499996218,"mc":[{"id":"1.230180122","rc":[{"atl":[[6.6,0]],"id":70396461}],"con":true,"img":false}]}
{"op":"mcm","clk":"11540921635","pt":1719499996322,"mc":[{"id":"1.230180122","rc":[{"atl":[[17.5,6.9],[7.4,0]],"id":70396461}],"con":true,"img":false}]}
{"op":"mcm","clk":"11540921794","pt":1719499999046,"mc":[{"id":"1.230180122","rc":[{"atl":[[6.6,2]],"id":70396461}],"con":true,"img":false}]}
{"op":"mcm","clk":"11540922166","pt":1719500004236,"mc":[{"id":"1.230180122","rc":[{"atl":[[6.6,0]],"id":70396461}],"con":true,"img":false}]}
{"op":"mcm","clk":"11540922286","pt":1719500006144,"mc":[{"id":"1.230180122","rc":[{"atl":[[6.6,2]],"id":70396461}],"con":true,"img":false}]}
{"op":"mcm","clk":"11540922296","pt":1719500006239,"mc":[{"id":"1.230180122","rc":[{"atl":[[17.5,0.84],[7.4,8]],"id":70396461}],"con":true,"img":false}]}
{"op":"mcm","clk":"11540922691","pt":1719500011454,"mc":[{"id":"1.230180122","rc":[{"atl":[[6.6,0]],"id":70396461}],"con":true,"img":false}]}
{"op":"mcm","clk":"11540922702","pt":1719500011555,"mc":[{"id":"1.230180122","rc":[{"atl":[[17.5,6.9],[7.4,0]],"id":70396461}],"con":true,"img":false}]}
{"op":"mcm","clk":"11540922845","pt":1719500013259,"mc":[{"id":"1.230180122","rc":[{"spn":13.4,"spf":"NaN","id":67487132},{"atl":[[6.6,2]],"id":70396461},{"spn":5.3,"spf":"NaN","id":70396461}],"con":true,"img":false}]}
{"op":"mcm","clk":"11540922861","pt":1719500013461,"mc":[{"id":"1.230180122","rc":[{"atl":[[17.5,0.84],[7.4,8]],"id":70396461}],"con":true,"img":false}]}
{"op":"mcm","clk":"11540923228","pt":1719500018462,"mc":[{"id":"1.230180122","rc":[{"atl":[[6.6,0]],"id":70396461}],"con":true,"img":false}]}
{"op":"mcm","clk":"11540923237","pt":1719500018571,"mc":[{"id":"1.230180122","rc":[{"atl":[[17.5,6.9]],"id":70396461}],"con":true,"img":false}]}
{"op":"mcm","clk":"11540923247","pt":1719500018668,"mc":[{"id":"1.230180122","rc":[{"atl":[[7.4,0]],"id":70396461}],"con":true,"img":false}]}
{"op":"mcm","clk":"11540923408","pt":1719500020878,"mc":[{"id":"1.230180122","rc":[{"atl":[[6.6,2]],"id":70396461}],"con":true,"img":false}]}
{"op":"mcm","clk":"11540923534","pt":1719500022641,"mc":[{"id":"1.230180122","rc":[{"atl":[[17.5,0.84],[7.4,8]],"id":70396461}],"con":true,"img":false}]}
{"op":"mcm","clk":"11540923766","pt":1719500025667,"mc":[{"id":"1.230180122","rc":[{"atb":[[6.2,0.89]],"id":47703807},{"atl":[[21,0.84]],"id":67487132},{"atl":[[6.4,0.84]],"id":70396461}],"con":true,"img":false}]}
{"op":"mcm","clk":"11540923796","pt":1719500026086,"mc":[{"id":"1.230180122","rc":[{"atl":[[6.6,0]],"id":70396461}],"con":true,"img":false}]}
{"op":"mcm","clk":"11540923842","pt":1719500026662,"mc":[{"id":"1.230180122","rc":[{"atl":[[6.4,0]],"id":70396461}],"con":true,"img":false}]}
{"op":"mcm","clk":"11540923943","pt":1719500027761,"mc":[{"id":"1.230180122","rc":[{"atl":[[17.5,6.9],[7.4,0]],"id":70396461}],"con":true,"img":false}]}
{"op":"mcm","clk":"11540923971","pt":1719500028063,"mc":[{"id":"1.230180122","rc":[{"atl":[[6.6,2]],"id":70396461}],"con":true,"img":false}]}
{"op":"mcm","clk":"11540924253","pt":1719500031760,"mc":[{"id":"1.230180122","rc":[{"atl":[[17.5,0.84],[7.4,8]],"id":70396461}],"con":true,"img":false}]}
{"op":"mcm","clk":"11540924357","pt":1719500033188,"mc":[{"id":"1.230180122","rc":[{"atl":[[6.4,0.84]],"id":70396461}],"con":true,"img":false}]}
{"op":"mcm","clk":"11540924368","pt":1719500033248,"mc":[{"id":"1.230180122","rc":[{"atl":[[6.6,0]],"id":70396461}],"con":true,"img":false}]}
{"op":"mcm","clk":"11540924398","pt":1719500033664,"mc":[{"id":"1.230180122","rc":[{"atl":[[6.4,0]],"id":70396461}],"con":true,"img":false}]}
{"op":"mcm","clk":"11540924412","pt":1719500033873,"mc":[{"id":"1.230180122","rc":[{"atl":[[17.5,6.9],[7.4,0]],"id":70396461}],"con":true,"img":false}]}
{"op":"mcm","clk":"11540924536","pt":1719500035672,"mc":[{"id":"1.230180122","rc":[{"atl":[[6.6,2]],"id":70396461}],"con":true,"img":false}]}
{"op":"mcm","clk":"11540924939","pt":1719500040687,"mc":[{"id":"1.230180122","rc":[{"atl":[[6.4,0.84]],"id":70396461}],"con":true,"img":false}]}
{"op":"mcm","clk":"11540924958","pt":1719500040896,"mc":[{"id":"1.230180122","rc":[{"atl":[[6.6,0]],"id":70396461}],"con":true,"img":false}]}
{"op":"mcm","clk":"11540924985","pt":1719500041200,"mc":[{"id":"1.230180122","rc":[{"atl":[[6.4,0]],"id":70396461}],"con":true,"img":false}]}
{"op":"mcm","clk":"11540925109","pt":1719500042760,"mc":[{"id":"1.230180122","rc":[{"atl":[[6.6,2]],"id":70396461}],"con":true,"img":false}]}
{"op":"mcm","clk":"11540925126","pt":1719500042971,"mc":[{"id":"1.230180122","rc":[{"atl":[[17.5,0.84],[7.4,8]],"id":70396461}],"con":true,"img":false}]}
{"op":"mcm","clk":"11540925138","pt":1719500043073,"mc":[{"id":"1.230180122","rc":[{"atb":[[1.03,12.7]],"id":40028187},{"atl":[[1000,1.7]],"id":40028187},{"atb":[[1.03,165.94]],"id":43318163},{"atl":[[1000,1.88]],"id":43318163},{"atb":[[4.8,0],[1.03,1.7]],"id":67487132},{"atl":[[1000,1.7]],"id":67487132}],"con":true,"img":false}]}
{"op":"mcm","clk":"11540925153","pt":1719500043281,"mc":[{"id":"1.230180122","rc":[{"atb":[[1.03,11.07]],"id":40028187},{"atl":[[1000,0]],"id":40028187},{"atb":[[5.1,0],[1.03,164.32]],"id":43318163},{"atl":[[1000,0.17]],"id":43318163},{"atb":[[1.03,0.11]],"id":67487132},{"atl":[[1000,0.01]],"id":67487132}],"con":true,"img":false}]}
{"op":"mcm","clk":"11540925166","pt":1719500043484,"mc":[{"id":"1.230180122","rc":[{"atb":[[5.1,0]],"id":40028187}],"con":true,"img":false}]}
{"op":"mcm","clk":"11540925171","pt":1719500043590,"mc":[{"id":"1.230180122","rc":[{"atb":[[1.03,10.99]],"id":40028187},{"atb":[[1.03,164.23]],"id":43318163},{"atb":[[1.03,0]],"id":67487132},{"atl":[[1000,0]],"id":67487132},{"atb":[[4,0]],"id":70396461}],"con":true,"img":false}]}
{"op":"mcm","clk":"11540925178","pt":1719500043678,"mc":[{"id":"1.230180122","rc":[{"atb":[[4.8,0.08]],"id":40028187},{"atb":[[4.8,0.08]],"id":43318163},{"atb":[[3.75,0.11]],"id":67487132},{"atl":[[21,0.86]],"id":67487132}],"con":true,"img":false}]}
{"op":"mcm","clk":"11540925190","pt":1719500043884,"mc":[{"id":"1.230180122","rc":[{"atb":[[4.3,0]],"id":57697855}],"con":true,"img":false}]}
{"op":"mcm","clk":"11540925197","pt":1719500043987,"mc":[{"id":"1.230180122","rc":[{"atb":[[6.2,0.84]],"id":47703807}],"con":true,"img":false}]}
{"op":"mcm","clk":"11540925214","pt":1719500044198,"mc":[{"id":"1.230180122","rc":[{"atb":[[1.12,1.69]],"id":40028187},{"atb":[[1.12,1.69]],"id":43318163}],"con":true,"img":false}]}
{"op":"mcm","clk":"11540925241","pt":1719500044607,"mc":[{"id":"1.230180122","rc":[{"atb":[[1.14,1.69]],"id":47703807},{"atb":[[1.09,1.69]],"id":70396461}],"con":true,"img":false}]}
{"op":"mcm","clk":"11540925262","pt":1719500044868,"mc":[{"id":"1.230180122","rc":[{"atb":[[1.1,1.69]],"id":67487132},{"atb":[[1.1,1.69]],"id":57697855}],"con":true,"img":false}]}
{"op":"mcm","clk":"11540925284","pt":1719500045183,"mc":[{"id":"1.230180122","rc":[{"atb":[[1.12,0.05]],"id":40028187},{"atb":[[1.12,0.05]],"id":43318163}],"con":true,"img":false}]}
{"op":"mcm","clk":"11540925308","pt":1719500045481,"mc":[{"id":"1.230180122","rc":[{"atb":[[1.14,0.05]],"id":47703807},{"atb":[[1.09,0.07]],"id":70396461}],"con":true,"img":false}]}
{"op":"mcm","clk":"11540925335","pt":1719500045793,"mc":[{"id":"1.230180122","rc":[{"atb":[[1.1,0.06]],"id":67487132},{"atb":[[1.1,0.06]],"id":57697855}],"con":true,"img":false}]}
{"op":"mcm","clk":"11540925361","pt":1719500046100,"mc":[{"id":"1.230180122","rc":[{"atb":[[1.12,0]],"id":43318163}],"con":true,"img":false}]}
{"op":"mcm","clk":"11540925370","pt":1719500046208,"mc":[{"id":"1.230180122","rc":[{"atb":[[5.1,0.05]],"id":43318163}],"con":true,"img":false}]}
{"op":"mcm","clk":"11540925394","pt":1719500046470,"mc":[{"id":"1.230180122","rc":[{"atb":[[1.12,0]],"id":40028187}],"con":true,"img":false}]}
{"op":"mcm","clk":"11540925399","pt":1719500046571,"mc":[{"id":"1.230180122","rc":[{"atb":[[5.1,0.05]],"id":40028187}],"con":true,"img":false}]}
{"op":"mcm","clk":"11540925425","pt":1719500046887,"mc":[{"id":"1.230180122","rc":[{"atb":[[1.14,0]],"id":47703807}],"con":true,"img":false}]}
{"op":"mcm","clk":"11540925436","pt":1719500046977,"mc":[{"id":"1.230180122","rc":[{"atb":[[6.2,0.89]],"id":47703807}],"con":true,"img":false}]}
{"op":"mcm","clk":"11540925460","pt":1719500047291,"mc":[{"id":"1.230180122","rc":[{"atb":[[1.09,0]],"id":70396461}],"con":true,"img":false}]}
{"op":"mcm","clk":"11540925467","pt":1719500047390,"mc":[{"id":"1.230180122","rc":[{"atb":[[4,0.07]],"id":70396461}],"con":true,"img":false}]}
{"op":"mcm","clk":"11540925490","pt":1719500047694,"mc":[{"id":"1.230180122","rc":[{"atb":[[1.1,0]],"id":57697855}],"con":true,"img":false}]}
{"op":"mcm","clk":"11540925500","pt":1719500047802,"mc":[{"id":"1.230180122","rc":[{"atb":[[4.3,0.06]],"id":57697855}],"con":true,"img":false}]}
{"op":"mcm","clk":"11540925521","pt":1719500048014,"mc":[{"id":"1.230180122","rc":[{"atl":[[6.6,0]],"id":70396461}],"con":true,"img":false}]}
{"op":"mcm","clk":"11540925530","pt":1719500048109,"mc":[{"id":"1.230180122","rc":[{"atb":[[1.1,0]],"id":67487132}],"con":true,"img":false}]}
{"op":"mcm","clk":"11540925539","pt":1719500048179,"mc":[{"id":"1.230180122","rc":[{"atb":[[4.8,0.06]],"id":67487132},{"atl":[[17.5,6.9],[6.4,0.84],[7.4,0]],"id":70396461}],"con":true,"img":false}]}
{"op":"mcm","clk":"11540925579","pt":1719500048687,"mc":[{"id":"1.230180122","rc":[{"atl":[[6.4,0]],"id":70396461}],"con":true,"img":false}]}
{"op":"mcm","clk":"11540925685","pt":1719500050078,"mc":[{"id":"1.230180122","rc":[{"atl":[[6.6,2]],"id":70396461}],"con":true,"img":false}]}
{"op":"mcm","clk":"11540925845","pt":1719500051882,"mc":[{"id":"1.230180122","rc":[{"atl":[[17.5,0.84],[7.4,8]],"id":70396461}],"con":true,"img":false}]}
{"op":"mcm","clk":"11540926110","pt":1719500055291,"mc":[{"id":"1.230180122","rc":[{"atl":[[6.6,0]],"id":70396461}],"con":true,"img":false}]}
{"op":"mcm","clk":"11540926121","pt":1719500055393,"mc":[{"id":"1.230180122","rc":[{"atl":[[17.5,6.9],[7.4,0]],"id":70396461}],"con":true,"img":false}]}
{"op":"mcm","clk":"11540926215","pt":1719500056589,"mc":[{"id":"1.230180122","rc":[{"atl":[[1000,1.17]],"id":70396461}],"con":true,"img":false}]}
{"op":"mcm","clk":"11540926234","pt":1719500056790,"mc":[{"id":"1.230180122","rc":[{"atl":[[1000,0.19]],"id":70396461}],"con":true,"img":false}]}
{"op":"mcm","clk":"11540926246","pt":1719500057004,"mc":[{"id":"1.230180122","rc":[{"atl":[[1000,0.17]],"id":70396461}],"con":true,"img":false}]}
{"op":"mcm","clk":"11540926256","pt":1719500057099,"mc":[{"id":"1.230180122","rc":[{"atl":[[6.6,0.02]],"id":70396461}],"con":true,"img":false}]}
{"op":"mcm","clk":"11540926263","pt":1719500057201,"mc":[{"id":"1.230180122","rc":[{"atl":[[6.6,2.02]],"id":70396461}],"con":true,"img":false}]}
{"op":"mcm","clk":"11540926274","pt":1719500057301,"mc":[{"id":"1.230180122","rc":[{"atl":[[17.5,0.84],[7.4,8]],"id":70396461}],"con":true,"img":false}]}
{"op":"mcm","clk":"11540926315","pt":1719500057710,"mc":[{"id":"1.230180122","rc":[{"atl":[[6.4,0.84]],"id":70396461}],"con":true,"img":false}]}
{"op":"mcm","clk":"11540926392","pt":1719500058718,"mc":[{"id":"1.230180122","rc":[{"atl":[[6.6,2]],"id":70396461}],"con":true,"img":false}]}
{"op":"mcm","clk":"11540926402","pt":1719500058799,"mc":[{"id":"1.230180122","rc":[{"atl":[[6.2,0.02]],"id":70396461}],"con":true,"img":false}]}
{"op":"mcm","clk":"11540926702","pt":1719500062501,"mc":[{"id":"1.230180122","rc":[{"atl":[[6.6,0]],"id":70396461}],"con":true,"img":false}]}
{"op":"mcm","clk":"11540926750","pt":1719500063110,"mc":[{"id":"1.230180122","rc":[{"atl":[[6.4,0]],"id":70396461}],"con":true,"img":false}]}
{"op":"mcm","clk":"11540926830","pt":1719500064199,"mc":[{"id":"1.230180122","rc":[{"atl":[[6.6,2]],"id":70396461}],"con":true,"img":false}]}
{"op":"mcm","clk":"11540926896","pt":1719500065115,"mc":[{"id":"1.230180122","rc":[{"atl":[[6.4,0.84]],"id":70396461}],"con":true,"img":false}]}
{"op":"mcm","clk":"11540927224","pt":1719500069416,"mc":[{"id":"1.230180122","rc":[{"atl":[[6.6,0]],"id":70396461}],"con":true,"img":false}]}
{"op":"mcm","clk":"11540927246","pt":1719500069718,"mc":[{"id":"1.230180122","rc":[{"atl":[[6.4,0]],"id":70396461}],"con":true,"img":false}]}
{"op":"mcm","clk":"11540927390","pt":1719500071320,"mc":[{"id":"1.230180122","rc":[{"atl":[[6.6,2]],"id":70396461}],"con":true,"img":false}]}
{"op":"mcm","clk":"11540927457","pt":1719500072136,"mc":[{"id":"1.230180122","rc":[{"atl":[[6.4,0.84]],"id":70396461}],"con":true,"img":false}]}
{"op":"mcm","clk":"11540927810","pt":1719500076530,"mc":[{"id":"1.230180122","rc":[{"spn":6.17,"spf":1.0,"id":47703807},{"spn":12.9,"spf":"NaN","id":67487132},{"atl":[[6.6,0]],"id":70396461},{"spn":5.1,"spf":"NaN","id":70396461}],"con":true,"img":false}]}
{"op":"mcm","clk":"11540927871","pt":1719500077214,"mc":[{"id":"1.230180122","rc":[{"atl":[[6.4,0]],"id":70396461}],"con":true,"img":false}]}
{"op":"mcm","clk":"11540927958","pt":1719500078538,"mc":[{"id":"1.230180122","rc":[{"atl":[[6.6,2]],"id":70396461}],"con":true,"img":false}]}
{"op":"mcm","clk":"11540928031","pt":1719500079624,"mc":[{"id":"1.230180122","rc":[{"atl":[[6.4,0.84]],"id":70396461}],"con":true,"img":false}]}
{"op":"mcm","clk":"11540928154","pt":1719500081342,"mc":[{"id":"1.230180122","rc":[{"atb":[[4.8,0]],"id":40028187},{"atb":[[4.8,0]],"id":43318163},{"atb":[[3.75,0]],"id":67487132},{"atl":[[21,0.84]],"id":67487132}],"con":true,"img":false}]}
{"op":"mcm","clk":"11540928344","pt":1719500083711,"mc":[{"id":"1.230180122","rc":[{"atl":[[6.6,0]],"id":70396461}],"con":true,"img":false}]}
{"op":"mcm","clk":"11540928375","pt":1719500084226,"mc":[{"id":"1.230180122","rc":[{"atl":[[6.4,0]],"id":70396461}],"con":true,"img":false}]}
{"op":"mcm","clk":"11540928521","pt":1719500085824,"mc":[{"id":"1.230180122","rc":[{"atl":[[6.6,2]],"id":70396461}],"con":true,"img":false}]}
{"op":"mcm","clk":"11540928616","pt":1719500086742,"mc":[{"id":"1.230180122","rc":[{"atl":[[6.4,0.84]],"id":70396461}],"con":true,"img":false}]}
{"op":"mcm","clk":"11540928955","pt":1719500091032,"mc":[{"id":"1.230180122","rc":[{"atl":[[6.6,0]],"id":70396461}],"con":true,"img":false}]}
{"op":"mcm","clk":"11540929014","pt":1719500091761,"mc":[{"id":"1.230180122","rc":[{"atl":[[6.4,0]],"id":70396461}],"con":true,"img":false}]}
{"op":"mcm","clk":"11540929108","pt":1719500092944,"mc":[{"id":"1.230180122","rc":[{"atl":[[6.6,2]],"id":70396461}],"con":true,"img":false}]}
{"op":"mcm","clk":"11540929218","pt":1719500094139,"mc":[{"id":"1.230180122","rc":[{"atl":[[6.4,0.84]],"id":70396461}],"con":true,"img":false}]}
{"op":"mcm","clk":"11540929526","pt":1719500098162,"mc":[{"id":"1.230180122","rc":[{"atl":[[6.6,0]],"id":70396461}],"con":true,"img":false}]}
{"op":"mcm","clk":"11540929576","pt":1719500098731,"mc":[{"id":"1.230180122","rc":[{"atl":[[6.4,0]],"id":70396461}],"con":true,"img":false}]}
{"op":"mcm","clk":"11540929765","pt":1719500100850,"mc":[{"id":"1.230180122","rc":[{"atl":[[6.6,2]],"id":70396461}],"con":true,"img":false}]}
{"op":"mcm","clk":"11540929843","pt":1719500101658,"mc":[{"id":"1.230180122","rc":[{"atl":[[6.4,0.84]],"id":70396461}],"con":true,"img":false}]}
{"op":"mcm","clk":"11540930222","pt":1719500106055,"mc":[{"id":"1.230180122","rc":[{"atl":[[6.6,0]],"id":70396461}],"con":true,"img":false}]}
{"op":"mcm","clk":"11540930281","pt":1719500106626,"mc":[{"id":"1.230180122","rc":[{"atl":[[6.4,0]],"id":70396461}],"con":true,"img":false}]}
{"op":"mcm","clk":"11540930447","pt":1719500108238,"mc":[{"id":"1.230180122","rc":[{"atl":[[6.6,2]],"id":70396461}],"con":true,"img":false}]}
{"op":"mcm","clk":"11540930485","pt":1719500108654,"mc":[{"id":"1.230180122","rc":[{"atl":[[6.4,0.84]],"id":70396461}],"con":true,"img":false}]}
{"op":"mcm","clk":"11540930874","pt":1719500113558,"mc":[{"id":"1.230180122","rc":[{"atl":[[6.6,0]],"id":70396461}],"con":true,"img":false}]}
{"op":"mcm","clk":"11540930914","pt":1719500114174,"mc":[{"id":"1.230180122","rc":[{"atl":[[6.4,0]],"id":70396461}],"con":true,"img":false}]}
{"op":"mcm","clk":"11540931003","pt":1719500115360,"mc":[{"id":"1.230180122","rc":[{"atl":[[6.6,2]],"id":70396461}],"con":true,"img":false}]}
{"op":"mcm","clk":"11540931060","pt":1719500116136,"mc":[{"id":"1.230180122","rc":[{"atl":[[6.4,0.84]],"id":70396461}],"con":true,"img":false}]}
{"op":"mcm","clk":"11540931237","pt":1719500118046,"mc":[{"id":"1.230180122","rc":[{"atl":[[1000,1.02]],"id":43318163},{"atl":[[1000,0.84]],"id":67487132}],"con":true,"img":false}]}
{"op":"mcm","clk":"11540931267","pt":1719500118359,"mc":[{"id":"1.230180122","rc":[{"atl":[[1000,0.84]],"id":40028187},{"atb":[[6.4,1.32]],"id":47703807}],"con":true,"img":false}]}
{"op":"mcm","clk":"11540931297","pt":1719500118666,"mc":[{"id":"1.230180122","rc":[{"atl":[[1000,1.02]],"id":47703807},{"atl":[[1000,0.84]],"id":57697855}],"con":true,"img":false}]}
{"op":"mcm","clk":"11540931329","pt":1719500118975,"mc":[{"id":"1.230180122","rc":[{"atl":[[1000,0.12]],"id":40028187},{"atl":[[1000,0.27]],"id":43318163}],"con":true,"img":false}]}
{"op":"mcm","clk":"11540931351","pt":1719500119273,"mc":[{"id":"1.230180122","rc":[{"atb":[[6.4,0],[6.2,2.21]],"id":47703807}],"con":true,"img":false}]}
{"op":"mcm","clk":"11540931381","pt":1719500119643,"mc":[{"id":"1.230180122","rc":[{"atl":[[1000,0]],"id":40028187},{"atl":[[1000,0.42]],"id":67487132}],"con":true,"img":false}]}
{"op":"mcm","clk":"11540931392","pt":1719500119752,"mc":[{"id":"1.230180122","rc":[{"atl":[[65,0.12]],"id":40028187}],"con":true,"img":false}]}
{"op":"mcm","clk":"11540931413","pt":1719500119964,"mc":[{"id":"1.230180122","rc":[{"atl":[[1000,0.36]],"id":57697855}],"con":true,"img":false}]}
{"op":"mcm","clk":"11540931437","pt":1719500120170,"mc":[{"id":"1.230180122","rc":[{"atl":[[1000,0.17]],"id":43318163}],"con":true,"img":false}]}
{"op":"mcm","clk":"11540931449","pt":1719500120276,"mc":[{"id":"1.230180122","rc":[{"atl":[[90,0.09]],"id":43318163}],"con":true,"img":false}]}
{"op":"mcm","clk":"11540931478","pt":1719500120579,"mc":[{"id":"1.230180122","rc":[{"atl":[[1000,0]],"id":67487132},{"atl":[[6.6,0]],"id":70396461}],"con":true,"img":false}]}
{"op":"mcm","clk":"11540931486","pt":1719500120639,"mc":[{"id":"1.230180122","rc":[{"atl":[[20,0.42]],"id":67487132}],"con":true,"img":false}]}
{"op":"mcm","clk":"11540931520","pt":1719500121155,"mc":[{"id":"1.230180122","rc":[{"atl":[[6.4,0]],"id":70396461},{"atl":[[1000,0]],"id":57697855}],"con":true,"img":false}]}
{"op":"mcm","clk":"11540931528","pt":1719500121253,"mc":[{"id":"1.230180122","rc":[{"atl":[[23,0.36]],"id":57697855}],"con":true,"img":false}]}
{"op":"mcm","clk":"11540931554","pt":1719500121576,"mc":[{"id":"1.230180122","rc":[{"atl":[[1000,1.87]],"id":47703807}],"con":true,"img":false}]}
{"op":"mcm","clk":"11540931582","pt":1719500121876,"mc":[{"id":"1.230180122","rc":[{"atl":[[1000,1.59]],"id":47703807}],"con":true,"img":false}]}
{"op":"mcm","clk":"11540931607","pt":1719500122176,"mc":[{"id":"1.230180122","rc":[{"atl":[[1000,1.02]],"id":47703807}],"con":true,"img":false}]}
{"op":"mcm","clk":"11540931619","pt":1719500122244,"mc":[{"id":"1.230180122","rc":[{"atl":[[15,0.56]],"id":47703807}],"con":true,"img":false}]}
{"op":"mcm","clk":"11540931664","pt":1719500122960,"mc":[{"id":"1.230180122","rc":[{"atl":[[6.6,2]],"id":70396461}],"con":true,"img":false}]}
{"op":"mcm","clk":"11540931722","pt":1719500123682,"mc":[{"id":"1.230180122","rc":[{"atl":[[6.4,0.84]],"id":70396461}],"con":true,"img":false}]}
{"op":"mcm","clk":"11540932076","pt":1719500128283,"mc":[{"id":"1.230180122","rc":[{"atl":[[6.6,0]],"id":70396461}],"con":true,"img":false}]}
{"op":"mcm","clk":"11540932107","pt":1719500128658,"mc":[{"id":"1.230180122","rc":[{"atl":[[6.4,0]],"id":70396461}],"con":true,"img":false}]}
{"op":"mcm","clk":"11540932239","pt":1719500130089,"mc":[{"id":"1.230180122","rc":[{"atl":[[1000,1.87]],"id":47703807},{"atl":[[6.6,2]],"id":70396461}],"con":true,"img":false}]}
{"op":"mcm","clk":"11540932267","pt":1719500130371,"mc":[{"id":"1.230180122","rc":[{"atl":[[1000,1.02]],"id":47703807}],"con":true,"img":false}]}
{"op":"mcm","clk":"11540932282","pt":1719500130464,"mc":[{"id":"1.230180122","rc":[{"atl":[[1000,0.74]],"id":47703807}],"con":true,"img":false}]}
{"op":"mcm","clk":"11540932307","pt":1719500130672,"mc":[{"id":"1.230180122","rc":[{"atl":[[6.4,0.84]],"id":70396461}],"con":true,"img":false}]}
{"op":"mcm","clk":"11540932319","pt":1719500130783,"mc":[{"id":"1.230180122","rc":[{"atl":[[1000,0.17]],"id":47703807}],"con":true,"img":false}]}
{"op":"mcm","clk":"11540932329","pt":1719500130886,"mc":[{"id":"1.230180122","rc":[{"atl":[[15,1.13]],"id":47703807}],"con":true,"img":false}]}
{"op":"mcm","clk":"11540932342","pt":1719500130990,"mc":[{"id":"1.230180122","rc":[{"atl":[[140,0],[22,4]],"id":47703807}],"con":true,"img":false}]}
{"op":"mcm","clk":"11540932700","pt":1719500135284,"mc":[{"id":"1.230180122","rc":[{"atl":[[6.6,0]],"id":70396461}],"con":true,"img":false}]}
{"op":"mcm","clk":"11540932736","pt":1719500135788,"mc":[{"id":"1.230180122","rc":[{"atl":[[6.4,0]],"id":70396461}],"con":true,"img":false}]}
{"op":"mcm","clk":"11540932846","pt":1719500137289,"mc":[{"id":"1.230180122","rc":[{"spn":35.05,"spf":"NaN","id":40028187},{"spn":47.55,"spf":"NaN","id":43318163},{"spn":6.2,"spf":1.0,"id":47703807},{"spn":12.4,"spf":"NaN","id":67487132},{"atl":[[6.6,2]],"id":70396461}],"con":true,"img":false}]}
{"op":"mcm","clk":"11540932918","pt":1719500138276,"mc":[{"id":"1.230180122","rc":[{"atl":[[6.4,0.84]],"id":70396461}],"con":true,"img":false}]}
{"op":"mcm","clk":"11540933291","pt":1719500142599,"mc":[{"id":"1.230180122","rc":[{"atl":[[6.6,0]],"id":70396461}],"con":true,"img":false}]}
{"op":"mcm","clk":"11540933344","pt":1719500143184,"mc":[{"id":"1.230180122","rc":[{"atl":[[6.4,0]],"id":70396461}],"con":true,"img":false}]}
{"op":"mcm","clk":"11540933459","pt":1719500144788,"mc":[{"id":"1.230180122","rc":[{"atl":[[6.6,2]],"id":70396461}],"con":true,"img":false}]}
{"op":"mcm","clk":"11540933534","pt":1719500145699,"mc":[{"id":"1.230180122","rc":[{"atl":[[6.4,0.84]],"id":70396461}],"con":true,"img":false}]}
{"op":"mcm","clk":"11540933890","pt":1719500149994,"mc":[{"id":"1.230180122","rc":[{"atl":[[6.6,0]],"id":70396461}],"con":true,"img":false}]}
{"op":"mcm","clk":"11540933950","pt":1719500150705,"mc":[{"id":"1.230180122","rc":[{"atl":[[6.4,0]],"id":70396461}],"con":true,"img":false}]}
{"op":"mcm","clk":"11540934038","pt":1719500151897,"mc":[{"id":"1.230180122","rc":[{"atl":[[6.6,2]],"id":70396461}],"con":true,"img":false}]}
{"op":"mcm","clk":"11540934113","pt":1719500152682,"mc":[{"id":"1.230180122","rc":[{"atl":[[6.4,0.84]],"id":70396461}],"con":true,"img":false}]}
{"op":"mcm","clk":"11540934442","pt":1719500157106,"mc":[{"id":"1.230180122","rc":[{"atl":[[6.6,0]],"id":70396461}],"con":true,"img":false}]}
{"op":"mcm","clk":"11540934483","pt":1719500157716,"mc":[{"id":"1.230180122","rc":[{"atl":[[6.4,0]],"id":70396461}],"con":true,"img":false}]}
{"op":"mcm","clk":"11540934593","pt":1719500159109,"mc":[{"id":"1.230180122","rc":[{"atl":[[6.6,2]],"id":70396461}],"con":true,"img":false}]}
{"op":"mcm","clk":"11540934630","pt":1719500159624,"mc":[{"id":"1.230180122","rc":[{"atl":[[6.4,0.84]],"id":70396461}],"con":true,"img":false}]}
{"op":"mcm","clk":"11540935026","pt":1719500164399,"mc":[{"id":"1.230180122","rc":[{"atl":[[6.6,0]],"id":70396461}],"con":true,"img":false}]}
{"op":"mcm","clk":"11540935044","pt":1719500164713,"mc":[{"id":"1.230180122","rc":[{"atl":[[6.4,0]],"id":70396461}],"con":true,"img":false}]}
{"op":"mcm","clk":"11540935053","pt":1719500164819,"mc":[{"id":"1.230180122","rc":[{"atb":[[5.1,0]],"id":43318163}],"con":true,"img":false}]}
{"op":"mcm","clk":"11540935092","pt":1719500165319,"mc":[{"id":"1.230180122","rc":[{"atb":[[4,0]],"id":70396461}],"con":true,"img":false}]}
{"op":"mcm","clk":"11540935119","pt":1719500165629,"mc":[{"id":"1.230180122","rc":[{"atb":[[4.8,0]],"id":67487132}],"con":true,"img":false}]}
{"op":"mcm","clk":"11540935153","pt":1719500165998,"mc":[{"id":"1.230180122","rc":[{"atb":[[6.2,2.16]],"id":47703807}],"con":true,"img":false}]}
{"op":"mcm","clk":"11540935188","pt":1719500166316,"mc":[{"id":"1.230180122","rc":[{"atb":[[4.3,0]],"id":57697855}],"con":true,"img":false}]}
{"op":"mcm","clk":"11540935221","pt":1719500166618,"mc":[{"id":"1.230180122","rc":[{"atb":[[1.1,1.69]],"id":67487132}],"con":true,"img":false}]}
{"op":"mcm","clk":"11540935232","pt":1719500166721,"mc":[{"id":"1.230180122","rc":[{"atl":[[6.6,2]],"id":70396461}],"con":true,"img":false}]}
{"op":"mcm","clk":"11540935242","pt":1719500166824,"mc":[{"id":"1.230180122","rc":[{"atb":[[1.12,1.69]],"id":43318163}],"con":true,"img":false}]}
{"op":"mcm","clk":"11540935262","pt":1719500167037,"mc":[{"id":"1.230180122","rc":[{"atb":[[1.14,1.69]],"id":47703807}],"con":true,"img":false}]}
{"op":"mcm","clk":"11540935271","pt":1719500167144,"mc":[{"id":"1.230180122","rc":[{"atl":[[6.4,0.84]],"id":70396461}],"con":true,"img":false}]}
{"op":"mcm","clk":"11540935296","pt":1719500167414,"mc":[{"id":"1.230180122","rc":[{"atb":[[1.1,0.06]],"id":67487132}],"con":true,"img":false}]}
{"op":"mcm","clk":"11540935339","pt":1719500167930,"mc":[{"id":"1.230180122","rc":[{"atb":[[1.12,0.05]],"id":43318163}],"con":true,"img":false}]}
{"op":"mcm","clk":"11540935370","pt":1719500168244,"mc":[{"id":"1.230180122","rc":[{"atb":[[1.14,0.05]],"id":47703807}],"con":true,"img":false}]}
{"op":"mcm","clk":"11540935406","pt":1719500168616,"mc":[{"id":"1.230180122","rc":[{"atb":[[1.1,0]],"id":67487132}],"con":true,"img":false}]}
{"op":"mcm","clk":"11540935419","pt":1719500168726,"mc":[{"id":"1.230180122","rc":[{"atb":[[4.8,0.06]],"id":67487132}],"con":true,"img":false}]}
{"op":"mcm","clk":"11540935456","pt":1719500169026,"mc":[{"id":"1.230180122","rc":[{"atb":[[1.09,1.69]],"id":70396461}],"con":true,"img":false}]}
{"op":"mcm","clk":"11540935472","pt":1719500169137,"mc":[{"id":"1.230180122","rc":[{"atb":[[5.1,0]],"id":40028187}],"con":true,"img":false}]}
{"op":"mcm","clk":"11540935496","pt":1719500169336,"mc":[{"id":"1.230180122","rc":[{"atb":[[1.12,0]],"id":43318163},{"atb":[[1.1,1.69]],"id":57697855}],"con":true,"img":false}]}
{"op":"mcm","clk":"11540935508","pt":1719500169443,"mc":[{"id":"1.230180122","rc":[{"atb":[[5.1,0.05]],"id":43318163}],"con":true,"img":false}]}
{"op":"mcm","clk":"11540935560","pt":1719500169918,"mc":[{"id":"1.230180122","rc":[{"atb":[[1.14,0]],"id":47703807}],"con":true,"img":false}]}
{"op":"mcm","clk":"11540935570","pt":1719500170018,"mc":[{"id":"1.230180122","rc":[{"atb":[[6.4,0.05]],"id":47703807}],"con":true,"img":false}]}
{"op":"mcm","clk":"11540935607","pt":1719500170324,"mc":[{"id":"1.230180122","rc":[{"atb":[[1.09,0.07]],"id":70396461}],"con":true,"img":false}]}
{"op":"mcm","clk":"11540935624","pt":1719500170530,"mc":[{"id":"1.230180122","rc":[{"atl":[[1000,1.7]],"id":67487132},{"atb":[[1.1,0.06]],"id":57697855}],"con":true,"img":false}]}
{"op":"mcm","clk":"11540935633","pt":1719500170633,"mc":[{"id":"1.230180122","rc":[{"atb":[[1.12,1.69],[1.03,12.7]],"id":40028187},{"atl":[[1000,1.7]],"id":40028187},{"atb":[[1.03,165.94]],"id":43318163},{"atl":[[1000,1.88]],"id":43318163},{"atb":[[1.03,1.7]],"id":67487132}],"con":true,"img":false}]}
{"op":"mcm","clk":"11540935640","pt":1719500170739,"mc":[{"id":"1.230180122","rc":[{"atl":[[1000,0.01]],"id":67487132}],"con":true,"img":false}]}
{"op":"mcm","clk":"11540935650","pt":1719500170840,"mc":[{"id":"1.230180122","rc":[{"atb":[[1.03,11.07]],"id":40028187},{"atl":[[1000,0]],"id":40028187},{"atb":[[1.03,164.31]],"id":43318163},{"atl":[[1000,0.17]],"id":43318163},{"atb":[[1.03,0.1]],"id":67487132},{"atb":[[1.09,0]],"id":70396461}],"con":true,"img":false}]}
{"op":"mcm","clk":"11540935662","pt":1719500170939,"mc":[{"id":"1.230180122","rc":[{"atl":[[1000,0]],"id":67487132},{"atb":[[4,0.07]],"id":70396461}],"con":true,"img":false}]}
{"op":"mcm","clk":"11540935670","pt":1719500171042,"mc":[{"id":"1.230180122","rc":[{"atb":[[1.03,10.99]],"id":40028187},{"atb":[[1.03,164.23]],"id":43318163},{"atb":[[1.03,0]],"id":67487132},{"atl":[[21,0.86]],"id":67487132}],"con":true,"img":false}]}
{"op":"mcm","clk":"11540935679","pt":1719500171146,"mc":[{"id":"1.230180122","rc":[{"atb":[[4.8,0.07]],"id":40028187},{"atb":[[4.8,0.07]],"id":43318163},{"atb":[[3.75,0.1]],"id":67487132}],"con":true,"img":false}]}
{"op":"mcm","clk":"11540935718","pt":1719500171628,"mc":[{"id":"1.230180122","rc":[{"atb":[[1.1,0]],"id":57697855}],"con":true,"img":false}]}
{"op":"mcm","clk":"11540935722","pt":1719500171722,"mc":[{"id":"1.230180122","rc":[{"atb":[[4.3,0.06]],"id":57697855}],"con":true,"img":false}]}
{"op":"mcm","clk":"11540935742","pt":1719500171934,"mc":[{"id":"1.230180122","rc":[{"atl":[[6.6,0]],"id":70396461}],"con":true,"img":false}]}
{"op":"mcm","clk":"11540935763","pt":1719500172136,"mc":[{"id":"1.230180122","rc":[{"atb":[[1.12,0.05]],"id":40028187}],"con":true,"img":false}]}
{"op":"mcm","clk":"11540935791","pt":1719500172448,"mc":[{"id":"1.230180122","rc":[{"atb":[[1.12,0]],"id":40028187}],"con":true,"img":false}]}
{"op":"mcm","clk":"11540935801","pt":1719500172550,"mc":[{"id":"1.230180122","rc":[{"atb":[[5.1,0.05]],"id":40028187}],"con":true,"img":false}]}
{"op":"mcm","clk":"11540935810","pt":1719500172652,"mc":[{"id":"1.230180122","rc":[{"atl":[[6.4,0]],"id":70396461}],"con":true,"img":false}]}
{"op":"mcm","clk":"11540935908","pt":1719500173849,"mc":[{"id":"1.230180122","rc":[{"atl":[[6.6,2]],"id":70396461}],"con":true,"img":false}]}
{"op":"mcm","clk":"11540935976","pt":1719500174639,"mc":[{"id":"1.230180122","rc":[{"atl":[[6.4,0.84]],"id":70396461}],"con":true,"img":false}]}
{"op":"mcm","clk":"11540936339","pt":1719500179140,"mc":[{"id":"1.230180122","rc":[{"atl":[[6.6,0]],"id":70396461}],"con":true,"img":false}]}
{"op":"mcm","clk":"11540936381","pt":1719500179651,"mc":[{"id":"1.230180122","rc":[{"atl":[[6.4,0]],"id":70396461}],"con":true,"img":false}]}
{"op":"mcm","clk":"11540936482","pt":1719500180941,"mc":[{"id":"1.230180122","rc":[{"atl":[[6.6,2]],"id":70396461}],"con":true,"img":false}]}
{"op":"mcm","clk":"11540936531","pt":1719500181630,"mc":[{"id":"1.230180122","rc":[{"atl":[[6.4,0.84]],"id":70396461}],"con":true,"img":false}]}
{"op":"mcm","clk":"11540936943","pt":1719500186150,"mc":[{"id":"1.230180122","rc":[{"atl":[[6.6,0]],"id":70396461}],"con":true,"img":false}]}
{"op":"mcm","clk":"11540936989","pt":1719500186755,"mc":[{"id":"1.230180122","rc":[{"atl":[[6.4,0]],"id":70396461}],"con":true,"img":false}]}
{"op":"mcm","clk":"11540937128","pt":1719500188547,"mc":[{"id":"1.230180122","rc":[{"atl":[[6.6,2]],"id":70396461}],"con":true,"img":false}]}
{"op":"mcm","clk":"11540937180","pt":1719500189161,"mc":[{"id":"1.230180122","rc":[{"atl":[[6.4,0.84]],"id":70396461}],"con":true,"img":false}]}
{"op":"mcm","clk":"11540937538","pt":1719500193728,"mc":[{"id":"1.230180122","rc":[{"atl":[[6.6,0]],"id":70396461}],"con":true,"img":false}]}
{"op":"mcm","clk":"11540937568","pt":1719500194149,"mc":[{"id":"1.230180122","rc":[{"atl":[[6.4,0]],"id":70396461}],"con":true,"img":false}]}
{"op":"mcm","clk":"11540937730","pt":1719500195758,"mc":[{"id":"1.230180122","rc":[{"atl":[[6.6,2]],"id":70396461}],"con":true,"img":false}]}
{"op":"mcm","clk":"11540937805","pt":1719500196637,"mc":[{"id":"1.230180122","rc":[{"atl":[[6.4,0.84]],"id":70396461}],"con":true,"img":false}]}
{"op":"mcm","clk":"11540938039","pt":1719500199273,"mc":[{"id":"1.230180122","rc":[{"atl":[[14.5,0.84]],"id":47703807},{"spn":6.21,"spf":1.0,"id":47703807},{"atl":[[23,0]],"id":67487132},{"atl":[[17.5,0]],"id":70396461},{"atl":[[26,0]],"id":57697855}],"con":true,"img":false}]}
{"op":"mcm","clk":"11540938076","pt":1719500199651,"mc":[{"id":"1.230180122","rc":[{"atl":[[14.5,1.69]],"id":47703807}],"con":true,"img":false}]}
{"op":"mcm","clk":"11540938103","pt":1719500199951,"mc":[{"id":"1.230180122","rc":[{"atb":[[5.1,1.71]],"id":43318163},{"atb":[[4.8,1.82]],"id":67487132}],"con":true,"img":false}]}
{"op":"mcm","clk":"11540938121","pt":1719500200166,"mc":[{"id":"1.230180122","rc":[{"atb":[[5.1,1.71]],"id":40028187},{"atl":[[1000,1.02]],"id":47703807}],"con":true,"img":false}]}
{"op":"mcm","clk":"11540938144","pt":1719500200469,"mc":[{"id":"1.230180122","rc":[{"atl":[[15,0.56]],"id":47703807}],"con":true,"img":false}]}
{"op":"mcm","clk":"11540938156","pt":1719500200568,"mc":[{"id":"1.230180122","rc":[{"atl":[[1000,0.77]],"id":47703807}],"con":true,"img":false}]}
{"op":"mcm","clk":"11540938165","pt":1719500200679,"mc":[{"id":"1.230180122","rc":[{"atb":[[5.2,0.84]],"id":40028187},{"atb":[[5.2,0.84]],"id":43318163},{"atb":[[4.9,0.84]],"id":67487132}],"con":true,"img":false}]}
{"op":"mcm","clk":"11540938191","pt":1719500200941,"mc":[{"id":"1.230180122","rc":[{"atl":[[1000,0.17]],"id":47703807}],"con":true,"img":false}]}
{"op":"mcm","clk":"11540938199","pt":1719500201044,"mc":[{"id":"1.230180122","rc":[{"atl":[[14,0.6]],"id":47703807},{"atl":[[6.6,0]],"id":70396461}],"con":true,"img":false}]}
{"op":"mcm","clk":"11540938249","pt":1719500201769,"mc":[{"id":"1.230180122","rc":[{"atl":[[6.4,0]],"id":70396461}],"con":true,"img":false}]}
{"op":"mcm","clk":"11540938337","pt":1719500202847,"mc":[{"id":"1.230180122","rc":[{"atl":[[6.6,2]],"id":70396461}],"con":true,"img":false}]}
{"op":"mcm","clk":"11540938398","pt":1719500203671,"mc":[{"id":"1.230180122","rc":[{"atl":[[6.4,0.84]],"id":70396461}],"con":true,"img":false}]}
{"op":"mcm","clk":"11540938723","pt":1719500208061,"mc":[{"id":"1.230180122","rc":[{"atl":[[6.6,0]],"id":70396461}],"con":true,"img":false}]}
{"op":"mcm","clk":"11540938763","pt":1719500208737,"mc":[{"id":"1.230180122","rc":[{"atl":[[6.4,0]],"id":70396461}],"con":true,"img":false}]}
{"op":"mcm","clk":"11540938767","pt":1719500208836,"mc":[{"id":"1.230180122","rc":[{"atb":[[4.8,0]],"id":40028187},{"atb":[[4.8,0]],"id":43318163},{"atb":[[3.75,0]],"id":67487132},{"atl":[[21,0.84]],"id":67487132}],"con":true,"img":false}]}
{"op":"mcm","clk":"11540938882","pt":1719500210457,"mc":[{"id":"1.230180122","rc":[{"atl":[[6.6,2]],"id":70396461}],"con":true,"img":false}]}
{"op":"mcm","clk":"11540938932","pt":1719500211173,"mc":[{"id":"1.230180122","rc":[{"atl":[[6.4,0.84]],"id":70396461}],"con":true,"img":false}]}
{"op":"mcm","clk":"11540939282","pt":1719500215785,"mc":[{"id":"1.230180122","rc":[{"atl":[[6.6,0]],"id":70396461}],"con":true,"img":false}]}
{"op":"mcm","clk":"11540939314","pt":1719500216162,"mc":[{"id":"1.230180122","rc":[{"atl":[[6.4,0]],"id":70396461}],"con":true,"img":false}]}
{"op":"mcm","clk":"11540939438","pt":1719500217558,"mc":[{"id":"1.230180122","rc":[{"atl":[[6.6,2]],"id":70396461}],"con":true,"img":false}]}
{"op":"mcm","clk":"11540939488","pt":1719500218282,"mc":[{"id":"1.230180122","rc":[{"atl":[[6.4,0.84]],"id":70396461}],"con":true,"img":false}]}
{"op":"mcm","clk":"11540939735","pt":1719500221281,"mc":[{"id":"1.230180122","rc":[{"atb":[[1.01,33.98]],"id":67487132}],"con":true,"img":false}]}
{"op":"mcm","clk":"11540939847","pt":1719500222883,"mc":[{"id":"1.230180122","rc":[{"atl":[[6.6,0]],"id":70396461}],"con":true,"img":false}]}
{"op":"mcm","clk":"11540939855","pt":1719500222993,"mc":[{"id":"1.230180122","rc":[{"atb":[[6.6,1]],"id":47703807}],"con":true,"img":false}]}
{"op":"mcm","clk":"11540939861","pt":1719500223085,"mc":[{"id":"1.230180122","rc":[{"atb":[[5.2,1.84]],"id":40028187},{"atl":[[21,1.84]],"id":67487132}],"con":true,"img":false}]}
{"op":"mcm","clk":"11540939876","pt":1719500223295,"mc":[{"id":"1.230180122","rc":[{"atl":[[6.4,0]],"id":70396461}],"con":true,"img":false}]}
{"op":"mcm","clk":"11540939935","pt":1719500224276,"mc":[{"id":"1.230180122","rc":[{"atl":[[22,2]],"id":67487132}],"con":true,"img":false}]}
{"op":"mcm","clk":"11540939947","pt":1719500224486,"mc":[{"id":"1.230180122","rc":[{"atl":[[21,0.84]],"id":67487132}],"con":true,"img":false}]}
{"op":"mcm","clk":"11540939962","pt":1719500224690,"mc":[{"id":"1.230180122","rc":[{"atl":[[6.6,2]],"id":70396461}],"con":true,"img":false}]}
{"op":"mcm","clk":"11540939977","pt":1719500224895,"mc":[{"id":"1.230180122","rc":[{"atl":[[22,3]],"id":67487132}],"con":true,"img":false}]}
{"op":"mcm","clk":"11540940024","pt":1719500225671,"mc":[{"id":"1.230180122","rc":[{"atl":[[6.4,0.84]],"id":70396461}],"con":true,"img":false}]}
{"op":"mcm","clk":"11540940340","pt":1719500229902,"mc":[{"id":"1.230180122","rc":[{"atl":[[6.6,0]],"id":70396461}],"con":true,"img":false}]}
{"op":"mcm","clk":"11540940372","pt":1719500230310,"mc":[{"id":"1.230180122","rc":[{"atl":[[6.4,0]],"id":70396461}],"con":true,"img":false}]}
{"op":"mcm","clk":"11540940532","pt":1719500232275,"mc":[{"id":"1.230180122","rc":[{"atl":[[6.6,2]],"id":70396461}],"con":true,"img":false}]}
{"op":"mcm","clk":"11540940558","pt":1719500232690,"mc":[{"id":"1.230180122","rc":[{"atl":[[6.4,0.84]],"id":70396461}],"con":true,"img":false}]}
{"op":"mcm","clk":"11540940568","pt":1719500232895,"mc":[{"id":"1.230180122","rc":[{"atl":[[20,2.01]],"id":67487132}],"con":true,"img":false}]}
{"op":"mcm","clk":"11540940583","pt":1719500233098,"mc":[{"id":"1.230180122","rc":[{"atl":[[20,4.02]],"id":67487132}],"con":true,"img":false}]}
{"op":"mcm","clk":"11540940590","pt":1719500233194,"mc":[{"id":"1.230180122","rc":[{"atl":[[19.5,0.84],[22,1]],"id":67487132}],"con":true,"img":false}]}
{"op":"mcm","clk":"11540940598","pt":1719500233298,"mc":[{"id":"1.230180122","rc":[{"atl":[[22,0]],"id":67487132}],"con":true,"img":false}]}
{"op":"mcm","clk":"11540940613","pt":1719500233504,"mc":[{"id":"1.230180122","rc":[{"atl":[[19.5,1.84]],"id":67487132}],"con":true,"img":false}]}
{"op":"mcm","clk":"11540940660","pt":1719500234184,"mc":[{"id":"1.230180122","rc":[{"atl":[[21,0]],"id":67487132}],"con":true,"img":false}]}
{"op":"mcm","clk":"11540940795","pt":1719500236308,"mc":[{"id":"1.230180122","rc":[{"atl":[[20,2.43]],"id":67487132}],"con":true,"img":false}]}
{"op":"mcm","clk":"11540940877","pt":1719500237587,"mc":[{"id":"1.230180122","rc":[{"atl":[[6.6,0]],"id":70396461}],"con":true,"img":false}]}
{"op":"mcm","clk":"11540940924","pt":1719500238315,"mc":[{"id":"1.230180122","rc":[{"atl":[[6.4,0]],"id":70396461}],"con":true,"img":false}]}
{"op":"mcm","clk":"11540940982","pt":1719500239389,"mc":[{"id":"1.230180122","rc":[{"atl":[[6.6,2]],"id":70396461}],"con":true,"img":false}]}
{"op":"mcm","clk":"11540940989","pt":1719500239593,"mc":[{"id":"1.230180122","rc":[{"atl":[[19,1.52]],"id":67487132}],"con":true,"img":false}]}
{"op":"mcm","clk":"11540940996","pt":1719500239798,"mc":[{"id":"1.230180122","rc":[{"atl":[[19.5,0.84]],"id":67487132},{"atl":[[6.4,0.84]],"id":70396461}],"con":true,"img":false}]}
{"op":"mcm","clk":"11540941005","pt":1719500240004,"mc":[{"id":"1.230180122","rc":[{"atl":[[19.5,1.84]],"id":67487132}],"con":true,"img":false}]}
{"op":"mcm","clk":"11540941011","pt":1719500240108,"mc":[{"id":"1.230180122","rc":[{"atl":[[19,3.52],[20,0.42]],"id":67487132}],"con":true,"img":false}]}
{"op":"mcm","clk":"11540941024","pt":1719500240307,"mc":[{"id":"1.230180122","rc":[{"atl":[[19.5,0.84]],"id":67487132}],"con":true,"img":false}]}
{"op":"mcm","clk":"11540941033","pt":1719500240512,"mc":[{"id":"1.230180122","rc":[{"atl":[[18.5,1]],"id":67487132}],"con":true,"img":false}]}
{"op":"mcm","clk":"11540941039","pt":1719500240615,"mc":[{"id":"1.230180122","rc":[{"atl":[[18.5,1.84]],"id":67487132}],"con":true,"img":false}]}
{"op":"mcm","clk":"11540941084","pt":1719500241198,"mc":[{"id":"1.230180122","rc":[{"atl":[[19.5,0]],"id":67487132}],"con":true,"img":false}]}
{"op":"mcm","clk":"11540941158","pt":1719500242416,"mc":[{"id":"1.230180122","rc":[{"atl":[[19,2]],"id":67487132}],"con":true,"img":false}]}
{"op":"mcm","clk":"11540941283","pt":1719500244233,"mc":[{"id":"1.230180122","rc":[{"atl":[[65,1.12]],"id":40028187},{"atl":[[90,1.09]],"id":43318163},{"atl":[[14,1.6]],"id":47703807},{"atl":[[18,1]],"id":67487132},{"atl":[[6.4,1.84]],"id":70396461},{"atl":[[24,2.05]],"id":57697855}],"con":true,"img":false}]}
{"op":"mcm","clk":"11540941310","pt":1719500244606,"mc":[{"id":"1.230180122","rc":[{"atl":[[6.6,0]],"id":70396461},{"atl":[[23,1.21]],"id":57697855}],"con":true,"img":false}]}
{"op":"mcm","clk":"11540941324","pt":1719500244705,"mc":[{"id":"1.230180122","rc":[{"atl":[[23,3.27],[25,1.68]],"id":57697855}],"con":true,"img":false}]}
{"op":"mcm","clk":"11540941356","pt":1719500245218,"mc":[{"id":"1.230180122","rc":[{"atl":[[24,1]],"id":57697855}],"con":true,"img":false}]}
{"op":"mcm","clk":"11540941368","pt":1719500245425,"mc":[{"id":"1.230180122","rc":[{"atl":[[6.4,0.84]],"id":70396461},{"atl":[[22,1.15],[24,0],[25,0]],"id":57697855}],"con":true,"img":false}]}
{"op":"mcm","clk":"11540941375","pt":1719500245512,"mc":[{"id":"1.230180122","rc":[{"atb":[[1.25,20]],"id":40028187},{"atb":[[1.25,20]],"id":43318163},{"atb":[[1.25,20]],"id":47703807},{"atb":[[1.25,20]],"id":67487132},{"atb":[[1.25,20]],"id":70396461},{"atl":[[7.2,1]],"id":70396461},{"atb":[[1.25,20]],"id":57697855},{"atl":[[22,2.15]],"id":57697855}],"con":true,"img":false}]}
{"op":"mcm","clk":"11540941391","pt":1719500245723,"mc":[{"id":"1.230180122","rc":[{"atl":[[6.4,0]],"id":70396461},{"atl":[[1000,0.84]],"id":57697855}],"con":true,"img":false}]}
{"op":"mcm","clk":"11540941400","pt":1719500245930,"mc":[{"id":"1.230180122","rc":[{"atb":[[4.9,1.63]],"id":67487132},{"atb":[[3.7,1.78]],"id":57697855}],"con":true,"img":false}]}
{"op":"mcm","clk":"11540941416","pt":1719500246093,"mc":[{"id":"1.230180122","rc":[{"atl":[[23,2.9]],"id":57697855}],"con":true,"img":false}]}
{"op":"mcm","clk":"11540941437","pt":1719500246402,"mc":[{"id":"1.230180122","rc":[{"atl":[[1000,0.4]],"id":57697855}],"con":true,"img":false}]}
{"op":"mcm","clk":"11540941443","pt":1719500246507,"mc":[{"id":"1.230180122","rc":[{"atl":[[6.6,2]],"id":70396461}],"con":true,"img":false}]}
{"op":"mcm","clk":"11540941456","pt":1719500246717,"mc":[{"id":"1.230180122","rc":[{"atl":[[1000,0]],"id":57697855}],"con":true,"img":false}]}
{"op":"mcm","clk":"11540941466","pt":1719500246818,"mc":[{"id":"1.230180122","rc":[{"atl":[[21,0.4]],"id":57697855}],"con":true,"img":false}]}
{"op":"mcm","clk":"11540941485","pt":1719500247122,"mc":[{"id":"1.230180122","rc":[{"atl":[[6.4,0.84]],"id":70396461}],"con":true,"img":false}]}
{"op":"mcm","clk":"11540941499","pt":1719500247335,"mc":[{"id":"1.230180122","rc":[{"atl":[[7.2,0]],"id":70396461}],"con":true,"img":false}]}
{"op":"mcm","clk":"11540941510","pt":1719500247424,"mc":[{"id":"1.230180122","rc":[{"atl":[[6.4,1.84]],"id":70396461}],"con":true,"img":false}]}
{"op":"mcm","clk":"11540941608","pt":1719500249023,"mc":[{"id":"1.230180122","rc":[{"atb":[[4.9,0]],"id":67487132},{"atl":[[18,3]],"id":67487132},{"trd":[[4.9,3.27]],"ltp":4.9,"tv":3.27,"id":67487132}],"con":true,"img":false}]}
{"op":"mcm","clk":"11540941622","pt":1719500249229,"mc":[{"id":"1.230180122","rc":[{"atl":[[17.5,2],[19,0]],"id":67487132}],"con":true,"img":false}]}
{"op":"mcm","clk":"11540941630","pt":1719500249333,"mc":[{"id":"1.230180122","rc":[{"atl":[[17.5,3.44],[18.5,0.84]],"id":67487132}],"con":true,"img":false}]}
{"op":"mcm","clk":"11540941641","pt":1719500249394,"mc":[{"id":"1.230180122","rc":[{"atl":[[17.5,1.44],[18,7]],"id":67487132}],"con":true,"img":false}]}
{"op":"mcm","clk":"11540941650","pt":1719500249497,"mc":[{"id":"1.230180122","rc":[{"atl":[[17,1],[18,5]],"id":67487132}],"con":true,"img":false}]}
{"op":"mcm","clk":"11540941656","pt":1719500249600,"mc":[{"id":"1.230180122","rc":[{"atb":[[5.3,1.6],[5.1,0.05]],"id":40028187},{"atl":[[17,1.84],[18,1],[18.5,6.55]],"id":67487132}],"con":true,"img":false}]}
{"op":"mcm","clk":"11540941665","pt":1719500249709,"mc":[{"id":"1.230180122","rc":[{"atl":[[17.5,3.44],[18.5,0]],"id":67487132}],"con":true,"img":false}]}
{"op":"mcm","clk":"11540941671","pt":1719500249802,"mc":[{"id":"1.230180122","rc":[{"atl":[[17,0.84]],"id":67487132}],"con":true,"img":false}]}
{"op":"mcm","clk":"11540941679","pt":1719500249911,"mc":[{"id":"1.230180122","rc":[{"atb":[[6.8,1.24],[6.2,0.84]],"id":47703807}],"con":true,"img":false}]}
{"op":"mcm","clk":"11540941685","pt":1719500250011,"mc":[{"id":"1.230180122","rc":[{"atl":[[17.5,2],[18,2]],"id":67487132}],"con":true,"img":false}]}
{"op":"mcm","clk":"11540941692","pt":1719500250113,"mc":[{"id":"1.230180122","rc":[{"atb":[[6.2,0]],"id":47703807}],"con":true,"img":false}]}
{"op":"mcm","clk":"11540941699","pt":1719500250216,"mc":[{"id":"1.230180122","rc":[{"atl":[[17,2.33]],"id":67487132}],"con":true,"img":false}]}
{"op":"mcm","clk":"11540941711","pt":1719500250421,"mc":[{"id":"1.230180122","rc":[{"atl":[[1000,0.06]],"id":67487132}],"con":true,"img":false}]}
{"op":"mcm","clk":"11540941731","pt":1719500250721,"mc":[{"id":"1.230180122","rc":[{"atl":[[1000,0]],"id":67487132}],"con":true,"img":false}]}
{"op":"mcm","clk":"11540941738","pt":1719500250831,"mc":[{"id":"1.230180122","rc":[{"atl":[[17,2.39]],"id":67487132}],"con":true,"img":false}]}
{"op":"mcm","clk":"11540941808","pt":1719500251817,"mc":[{"id":"1.230180122","rc":[{"atl":[[6.6,0]],"id":70396461}],"con":true,"img":false}]}
{"op":"mcm","clk":"11540941830","pt":1719500252132,"mc":[{"id":"1.230180122","rc":[{"atl":[[21,1.25]],"id":57697855}],"con":true,"img":false}]}
{"op":"mcm","clk":"11540941842","pt":1719500252224,"mc":[{"id":"1.230180122","rc":[{"atl":[[21,3.4],[23,0.84]],"id":57697855}],"con":true,"img":false}]}
{"op":"mcm","clk":"11540941853","pt":1719500252330,"mc":[{"id":"1.230180122","rc":[{"atl":[[21,1.25],[22,5.06]],"id":57697855}],"con":true,"img":false}]}
{"op":"mcm","clk":"11540941866","pt":1719500252533,"mc":[{"id":"1.230180122","rc":[{"atl":[[22,3.91]],"id":57697855}],"con":true,"img":false}]}
{"op":"mcm","clk":"11540941873","pt":1719500252638,"mc":[{"id":"1.230180122","rc":[{"atl":[[18,1]],"id":67487132}],"con":true,"img":false}]}
{"op":"mcm","clk":"11540941882","pt":1719500252742,"mc":[{"id":"1.230180122","rc":[{"atl":[[16.5,1]],"id":67487132}],"con":true,"img":false}]}
{"op":"mcm","clk":"11540941910","pt":1719500253110,"mc":[{"id":"1.230180122","rc":[{"atl":[[17,0.9]],"id":67487132},{"atl":[[6.4,0.84]],"id":70396461},{"atl":[[22,2.91]],"id":57697855}],"con":true,"img":false}]}
{"op":"mcm","clk":"11540941919","pt":1719500253212,"mc":[{"id":"1.230180122","rc":[{"atl":[[7.2,1]],"id":70396461},{"atl":[[27,1]],"id":57697855}],"con":true,"img":false}]}
{"op":"mcm","clk":"11540941943","pt":1719500253626,"mc":[{"id":"1.230180122","rc":[{"atl":[[6.6,2]],"id":70396461}],"con":true,"img":false}]}
{"op":"mcm","clk":"11540941951","pt":1719500253735,"mc":[{"id":"1.230180122","rc":[{"atl":[[6.4,0]],"id":70396461}],"con":true,"img":false}]}
{"op":"mcm","clk":"11540941967","pt":1719500253924,"mc":[{"id":"1.230180122","rc":[{"atl":[[16.5,0]],"id":67487132},{"atl":[[27,0]],"id":57697855}],"con":true,"img":false}]}
{"op":"mcm","clk":"11540941972","pt":1719500254032,"mc":[{"id":"1.230180122","rc":[{"atl":[[17,1.9]],"id":67487132},{"atl":[[21,2.25]],"id":57697855}],"con":true,"img":false}]}
{"op":"mcm","clk":"11540941986","pt":1719500254233,"mc":[{"id":"1.230180122","rc":[{"atl":[[16.5,1.54]],"id":67487132},{"atl":[[20,1.26]],"id":57697855}],"con":true,"img":false}]}
{"op":"mcm","clk":"11540941993","pt":1719500254338,"mc":[{"id":"1.230180122","rc":[{"atl":[[20,3.51],[22,0]],"id":57697855}],"con":true,"img":false}]}
{"op":"mcm","clk":"11540942012","pt":1719500254643,"mc":[{"id":"1.230180122","rc":[{"atl":[[6.4,0.84]],"id":70396461}],"con":true,"img":false}]}
{"op":"mcm","clk":"11540942018","pt":1719500254703,"mc":[{"id":"1.230180122","rc":[{"atl":[[23,0]],"id":57697855}],"con":true,"img":false}]}
{"op":"mcm","clk":"11540942029","pt":1719500254917,"mc":[{"id":"1.230180122","rc":[{"atl":[[17,0.9]],"id":67487132},{"atl":[[7.2,0]],"id":70396461},{"atl":[[21,1.25]],"id":57697855}],"con":true,"img":false}]}
{"op":"mcm","clk":"11540942036","pt":1719500255010,"mc":[{"id":"1.230180122","rc":[{"atl":[[16,1]],"id":67487132},{"atl":[[6.4,1.84]],"id":70396461},{"atl":[[19.5,1]],"id":57697855}],"con":true,"img":false}]}
{"op":"mcm","clk":"11540942055","pt":1719500255319,"mc":[{"id":"1.230180122","rc":[{"atl":[[16.5,0],[18,0]],"id":67487132},{"atl":[[20,2.25]],"id":57697855}],"con":true,"img":false}]}
{"op":"mcm","clk":"11540942071","pt":1719500255626,"mc":[{"id":"1.230180122","rc":[{"atl":[[6.6,0]],"id":70396461},{"atl":[[19,1.72]],"id":57697855}],"con":true,"img":false}]}
{"op":"mcm","clk":"11540942076","pt":1719500255722,"mc":[{"id":"1.230180122","rc":[{"atb":[[4.8,0]],"id":67487132},{"atl":[[17,1.9]],"id":67487132},{"trd":[[4.8,3.65]],"ltp":4.8,"tv":3.65,"id":67487132},{"atl":[[19,3.72],[20,0]],"id":57697855}],"con":true,"img":false}]}
{"op":"mcm","clk":"11540942083","pt":1719500255838,"mc":[{"id":"1.230180122","rc":[{"atl":[[16,0]],"id":67487132}],"con":true,"img":false}]}
{"op":"mcm","clk":"11540942094","pt":1719500255946,"mc":[{"id":"1.230180122","rc":[{"atl":[[17,2.9],[15.5,1.59]],"id":67487132},{"atl":[[18.5,1.37]],"id":57697855}],"con":true,"img":false}]}
{"op":"mcm","clk":"11540942104","pt":1719500256145,"mc":[{"id":"1.230180122","rc":[{"atb":[[5.1,0]],"id":40028187},{"atb":[[5.1,1.65]],"id":43318163},{"atb":[[6.4,0]],"id":47703807},{"atl":[[17,1.9]],"id":67487132},{"atb":[[4,0]],"id":70396461},{"atb":[[4.3,0]],"id":57697855},{"atl":[[21,0.4]],"id":57697855}],"con":true,"img":false}]}
{"op":"mcm","clk":"11540942128","pt":1719500256520,"mc":[{"id":"1.230180122","rc":[{"atl":[[17.5,0],[15.5,3.59]],"id":67487132}],"con":true,"img":false}]}
{"op":"mcm","clk":"11540942141","pt":1719500256725,"mc":[{"id":"1.230180122","rc":[{"atl":[[15,1]],"id":67487132}],"con":true,"img":false}]}
{"op":"mcm","clk":"11540942157","pt":1719500256937,"mc":[{"id":"1.230180122","rc":[{"atl":[[17,0.9]],"id":67487132},{"atl":[[6.4,0.84]],"id":70396461},{"atl":[[19.5,0]],"id":57697855}],"con":true,"img":false}]}
{"op":"mcm","clk":"11540942164","pt":1719500257028,"mc":[{"id":"1.230180122","rc":[{"atl":[[15,2]],"id":67487132},{"atl":[[7.2,1]],"id":70396461},{"atl":[[18.5,2.37]],"id":57697855}],"con":true,"img":false}]}
{"op":"mcm","clk":"11540942179","pt":1719500257237,"mc":[{"id":"1.230180122","rc":[{"atl":[[17,0.06]],"id":67487132},{"atl":[[6.4,0]],"id":70396461}],"con":true,"img":false}]}
{"op":"mcm","clk":"11540942201","pt":1719500257613,"mc":[{"id":"1.230180122","rc":[{"atl":[[14.5,0.84]],"id":67487132}],"con":true,"img":false}]}
{"op":"mcm","clk":"11540942335","pt":1719500259425,"mc":[{"id":"1.230180122","rc":[{"spn":35.15,"spf":"NaN","id":40028187},{"atb":[[5.3,1.6]],"id":43318163},{"spn":47.65,"spf":"NaN","id":43318163},{"spn":6.8,"spf":1.0,"id":47703807},{"spn":9.6,"spf":"NaN","id":67487132},{"spn":5.07,"spf":"NaN","id":70396461},{"spn":4.2,"spf":1.0,"id":57697855}],"con":true,"img":false}]}
{"op":"mcm","clk":"11540942345","pt":1719500259534,"mc":[{"id":"1.230180122","rc":[{"atb":[[5.1,0]],"id":43318163}],"con":true,"img":false}]}
{"op":"mcm","clk":"11540942353","pt":1719500259633,"mc":[{"id":"1.230180122","rc":[{"atl":[[18,0.84]],"id":57697855}],"con":true,"img":false}]}
{"op":"mcm","clk":"11540942362","pt":1719500259738,"mc":[{"id":"1.230180122","rc":[{"atb":[[5.3,0]],"id":43318163}],"con":true,"img":false}]}
{"op":"mcm","clk":"11540942389","pt":1719500260034,"mc":[{"id":"1.230180122","rc":[{"atb":[[5.2,2.44]],"id":43318163}],"con":true,"img":false}]}
{"op":"mcm","clk":"11540942397","pt":1719500260137,"mc":[{"id":"1.230180122","rc":[{"atb":[[5.1,0.84],[5.2,1.6]],"id":43318163}],"con":true,"img":false}]}
{"op":"mcm","clk":"11540942426","pt":1719500260551,"mc":[{"id":"1.230180122","rc":[{"atl":[[19,2]],"id":57697855}],"con":true,"img":false}]}
{"op":"mcm","clk":"11540942443","pt":1719500260716,"mc":[{"id":"1.230180122","rc":[{"atl":[[6.6,2]],"id":70396461}],"con":true,"img":false}]}
{"op":"mcm","clk":"11540942457","pt":1719500260926,"mc":[{"id":"1.230180122","rc":[{"atl":[[15.5,2]],"id":67487132}],"con":true,"img":false}]}
{"op":"mcm","clk":"11540942531","pt":1719500262152,"mc":[{"id":"1.230180122","rc":[{"atl":[[6.4,0.84]],"id":70396461}],"con":true,"img":false}]}
{"op":"mcm","clk":"11540942577","pt":1719500262844,"mc":[{"id":"1.230180122","rc":[{"atl":[[7.2,0]],"id":70396461}],"con":true,"img":false}]}
{"op":"mcm","clk":"11540942586","pt":1719500262930,"mc":[{"id":"1.230180122","rc":[{"atl":[[6.4,1.84]],"id":70396461}],"con":true,"img":false}]}
{"op":"mcm","clk":"11540942620","pt":1719500263448,"mc":[{"id":"1.230180122","rc":[{"atl":[[14.5,4.84]],"id":67487132}],"con":true,"img":false}]}
{"op":"mcm","clk":"11540942628","pt":1719500263552,"mc":[{"id":"1.230180122","rc":[{"atl":[[14,2]],"id":67487132}],"con":true,"img":false}]}
{"op":"mcm","clk":"11540942636","pt":1719500263654,"mc":[{"id":"1.230180122","rc":[{"atl":[[14,0],[14.5,8.84],[15,1],[15.5,0]],"id":67487132},{"atl":[[18,2.35]],"id":57697855}],"con":true,"img":false}]}
{"op":"mcm","clk":"11540942644","pt":1719500263762,"mc":[{"id":"1.230180122","rc":[{"atl":[[18,4.71],[19,0]],"id":57697855}],"con":true,"img":false}]}
{"op":"mcm","clk":"11540942664","pt":1719500263936,"mc":[{"id":"1.230180122","rc":[{"atl":[[14,1]],"id":67487132}],"con":true,"img":false}]}
{"op":"mcm","clk":"11540942670","pt":1719500264025,"mc":[{"id":"1.230180122","rc":[{"atl":[[18.5,1]],"id":57697855}],"con":true,"img":false}]}
{"op":"mcm","clk":"11540942679","pt":1719500264131,"mc":[{"id":"1.230180122","rc":[{"atl":[[15,0]],"id":67487132},{"atl":[[18.5,0]],"id":57697855}],"con":true,"img":false}]}
{"op":"mcm","clk":"11540942686","pt":1719500264235,"mc":[{"id":"1.230180122","rc":[{"atl":[[14,2]],"id":67487132},{"atl":[[17.5,2.44]],"id":57697855}],"con":true,"img":false}]}
{"op":"mcm","clk":"11540942696","pt":1719500264336,"mc":[{"id":"1.230180122","rc":[{"atl":[[17,6.31],[14.5,4.84]],"id":67487132}],"con":true,"img":false}]}
{"op":"mcm","clk":"11540942700","pt":1719500264430,"mc":[{"id":"1.230180122","rc":[{"atl":[[17,0.06],[14,4]],"id":67487132}],"con":true,"img":false}]}
{"op":"mcm","clk":"11540942707","pt":1719500264531,"mc":[{"id":"1.230180122","rc":[{"atl":[[17,6.31],[14,2]],"id":67487132}],"con":true,"img":false}]}
{"op":"mcm","clk":"11540942713","pt":1719500264636,"mc":[{"id":"1.230180122","rc":[{"atl":[[17,0.06],[14,6]],"id":67487132}],"con":true,"img":false}]}
{"op":"mcm","clk":"11540942728","pt":1719500264847,"mc":[{"id":"1.230180122","rc":[{"atl":[[13.5,1.87]],"id":67487132}],"con":true,"img":false}]}
{"op":"mcm","clk":"11540942757","pt":1719500265252,"mc":[{"id":"1.230180122","rc":[{"atl":[[13,0.84],[14,5]],"id":67487132}],"con":true,"img":false}]}
{"op":"mcm","clk":"11540942770","pt":1719500265356,"mc":[{"id":"1.230180122","rc":[{"atl":[[13,1.84],[14.5,4]],"id":67487132}],"con":true,"img":false}]}
{"op":"mcm","clk":"11540942779","pt":1719500265462,"mc":[{"id":"1.230180122","rc":[{"atl":[[13,3.84],[14,1]],"id":67487132}],"con":true,"img":false}]}
{"op":"mcm","clk":"11540942816","pt":1719500265928,"mc":[{"id":"1.230180122","rc":[{"atl":[[13.5,0]],"id":67487132},{"atl":[[6.6,0]],"id":70396461}],"con":true,"img":false}]}
{"op":"mcm","clk":"11540942824","pt":1719500266029,"mc":[{"id":"1.230180122","rc":[{"atl":[[17,0]],"id":67487132}],"con":true,"img":false}]}
{"op":"mcm","clk":"11540942832","pt":1719500266136,"mc":[{"id":"1.230180122","rc":[{"atl":[[12.5,2.03]],"id":67487132}],"con":true,"img":false}]}
{"op":"mcm","clk":"11540942842","pt":1719500266243,"mc":[{"id":"1.230180122","rc":[{"atl":[[1000,0.08]],"id":67487132}],"con":true,"img":false}]}
{"op":"mcm","clk":"11540942859","pt":1719500266452,"mc":[{"id":"1.230180122","rc":[{"atl":[[1000,0]],"id":67487132}],"con":true,"img":false}]}
{"op":"mcm","clk":"11540942870","pt":1719500266545,"mc":[{"id":"1.230180122","rc":[{"atl":[[13.5,0.08]],"id":67487132},{"atl":[[18,3.2]],"id":57697855}],"con":true,"img":false}]}
{"op":"mcm","clk":"11540942885","pt":1719500266752,"mc":[{"id":"1.230180122","rc":[{"atl":[[17,0.84]],"id":57697855}],"con":true,"img":false}]}
{"op":"mcm","clk":"11540942920","pt":1719500267267,"mc":[{"id":"1.230180122","rc":[{"atl":[[13,2.84]],"id":67487132},{"atl":[[6.4,0.84]],"id":70396461}],"con":true,"img":false}]}
{"op":"mcm","clk":"11540942931","pt":1719500267329,"mc":[{"id":"1.230180122","rc":[{"atl":[[12,1]],"id":67487132},{"atl":[[7.2,1]],"id":70396461}],"con":true,"img":false}]}
{"op":"mcm","clk":"11540942953","pt":1719500267643,"mc":[{"id":"1.230180122","rc":[{"atl":[[14,0]],"id":67487132}],"con":true,"img":false}]}
{"op":"mcm","clk":"11540942960","pt":1719500267728,"mc":[{"id":"1.230180122","rc":[{"atl":[[12.5,0]],"id":67487132},{"atl":[[6.4,0]],"id":70396461}],"con":true,"img":false}]}
{"op":"mcm","clk":"11540942969","pt":1719500267841,"mc":[{"id":"1.230180122","rc":[{"atl":[[12,2]],"id":67487132},{"atl":[[6.6,2]],"id":70396461}],"con":true,"img":false}]}
{"op":"mcm","clk":"11540942995","pt":1719500268243,"mc":[{"id":"1.230180122","rc":[{"atl":[[12,1],[13,2]],"id":67487132},{"atl":[[7.2,0]],"id":70396461}],"con":true,"img":false}]}
{"op":"mcm","clk":"11540943002","pt":1719500268353,"mc":[{"id":"1.230180122","rc":[{"atl":[[12.5,1]],"id":67487132},{"atl":[[6.4,1]],"id":70396461}],"con":true,"img":false}]}
{"op":"mcm","clk":"11540943029","pt":1719500268760,"mc":[{"id":"1.230180122","rc":[{"atl":[[14.5,0]],"id":67487132}],"con":true,"img":false}]}
{"op":"mcm","clk":"11540943314","pt":1719500272567,"mc":[{"id":"1.230180122","rc":[{"atl":[[17,2.52]],"id":57697855}],"con":true,"img":false}]}
{"op":"mcm","clk":"11540943324","pt":1719500272631,"mc":[{"id":"1.230180122","rc":[{"atl":[[17,5.05],[18,0.84]],"id":57697855}],"con":true,"img":false}]}
{"op":"mcm","clk":"11540943334","pt":1719500272734,"mc":[{"id":"1.230180122","rc":[{"atl":[[17,2.52],[17.5,7.5]],"id":57697855}],"con":true,"img":false}]}
{"op":"mcm","clk":"11540943355","pt":1719500273043,"mc":[{"id":"1.230180122","rc":[{"atl":[[6.6,0]],"id":70396461},{"atl":[[17.5,6.5]],"id":57697855}],"con":true,"img":false}]}
{"op":"mcm","clk":"11540943358","pt":1719500273147,"mc":[{"id":"1.230180122","rc":[{"atl":[[16.5,1],[17.5,5.06]],"id":57697855}],"con":true,"img":false}]}
{"op":"mcm","clk":"11540943370","pt":1719500273251,"mc":[{"id":"1.230180122","rc":[{"atl":[[18,0]],"id":57697855}],"con":true,"img":false}]}
{"op":"mcm","clk":"11540943417","pt":1719500274072,"mc":[{"id":"1.230180122","rc":[{"atl":[[6.4,0]],"id":70396461}],"con":true,"img":false}]}
{"op":"mcm","clk":"11540943425","pt":1719500274170,"mc":[{"id":"1.230180122","rc":[{"atl":[[7.2,1]],"id":70396461}],"con":true,"img":false}]}
{"op":"mcm","clk":"11540943554","pt":1719500275874,"mc":[{"id":"1.230180122","rc":[{"atl":[[6.6,2]],"id":70396461}],"con":true,"img":false}]}
{"op":"mcm","clk":"11540943581","pt":1719500276172,"mc":[{"id":"1.230180122","rc":[{"atl":[[6.4,0.84]],"id":70396461}],"con":true,"img":false}]}
{"op":"mcm","clk":"11540943649","pt":1719500277052,"mc":[{"id":"1.230180122","rc":[{"atl":[[7.2,0]],"id":70396461}],"con":true,"img":false}]}
{"op":"mcm","clk":"11540943660","pt":1719500277153,"mc":[{"id":"1.230180122","rc":[{"atl":[[6.4,1.84]],"id":70396461}],"con":true,"img":false}]}
{"op":"mcm","clk":"11540943700","pt":1719500277566,"mc":[{"id":"1.230180122","rc":[{"atl":[[12,3]],"id":67487132}],"con":true,"img":false}]}
{"op":"mcm","clk":"11540943710","pt":1719500277664,"mc":[{"id":"1.230180122","rc":[{"atb":[[2.26,11.39]],"id":40028187}],"con":true,"img":false}]}
{"op":"mcm","clk":"11540943735","pt":1719500277979,"mc":[{"id":"1.230180122","rc":[{"atb":[[2.18,10.03]],"id":43318163},{"atl":[[6.6,0]],"id":70396461},{"atb":[[2.24,9.55]],"id":57697855}],"con":true,"img":false}]}
{"op":"mcm","clk":"11540943750","pt":1719500278129,"mc":[{"id":"1.230180122","rc":[{"atl":[[11.5,0.84],[12.5,0]],"id":67487132},{"atb":[[2.6,7.4]],"id":70396461}],"con":true,"img":false}]}
{"op":"mcm","clk":"11540943762","pt":1719500278239,"mc":[{"id":"1.230180122","rc":[{"atl":[[11.5,1.84]],"id":67487132}],"con":true,"img":false}]}
{"op":"mcm","clk":"11540943767","pt":1719500278333,"mc":[{"id":"1.230180122","rc":[{"atb":[[2.28,9.25]],"id":67487132}],"con":true,"img":false}]}
{"op":"mcm","clk":"11540943775","pt":1719500278442,"mc":[{"id":"1.230180122","rc":[{"atl":[[11.5,3.84],[13,0]],"id":67487132}],"con":true,"img":false}]}
{"op":"mcm","clk":"11540943801","pt":1719500278747,"mc":[{"id":"1.230180122","rc":[{"atl":[[12,2]],"id":67487132}],"con":true,"img":false}]}
{"op":"mcm","clk":"11540943816","pt":1719500278958,"mc":[{"id":"1.230180122","rc":[{"atl":[[11,1]],"id":67487132},{"atb":[[3.75,17.66]],"id":57697855}],"con":true,"img":false}]}
{"op":"mcm","clk":"11540943875","pt":1719500279770,"mc":[{"id":"1.230180122","rc":[{"atl":[[6.4,0.84]],"id":70396461}],"con":true,"img":false}]}
{"op":"mcm","clk":"11540943882","pt":1719500279883,"mc":[{"id":"1.230180122","rc":[{"atl":[[7.2,1]],"id":70396461}],"con":true,"img":false}]}
{"op":"mcm","clk":"11540943907","pt":1719500280240,"mc":[{"id":"1.230180122","rc":[{"atl":[[6.4,0]],"id":70396461}],"con":true,"img":false}]}
{"op":"mcm","clk":"11540943923","pt":1719500280459,"mc":[{"id":"1.230180122","rc":[{"atb":[[6.8,5.56]],"id":47703807},{"atb":[[3.2,10.26]],"id":67487132},{"atl":[[11,3.62]],"id":67487132},{"atb":[[2.92,14.31]],"id":70396461},{"atl":[[7.2,5.26]],"id":70396461}],"con":true,"img":false}]}
{"op":"mcm","clk":"11540943942","pt":1719500280656,"mc":[{"id":"1.230180122","rc":[{"atb":[[6.6,0]],"id":47703807}],"con":true,"img":false}]}
{"op":"mcm","clk":"11540943958","pt":1719500280870,"mc":[{"id":"1.230180122","rc":[{"atb":[[7,1]],"id":47703807}],"con":true,"img":false}]}
{"op":"mcm","clk":"11540943981","pt":1719500281080,"mc":[{"id":"1.230180122","rc":[{"atl":[[10.5,2.42]],"id":67487132}],"con":true,"img":false}]}
{"op":"mcm","clk":"11540944006","pt":1719500281437,"mc":[{"id":"1.230180122","rc":[{"atl":[[11.5,2.84]],"id":67487132}],"con":true,"img":false}]}
{"op":"mcm","clk":"11540944013","pt":1719500281542,"mc":[{"id":"1.230180122","rc":[{"atl":[[10,1]],"id":67487132}],"con":true,"img":false}]}
{"op":"mcm","clk":"11540944020","pt":1719500281646,"mc":[{"id":"1.230180122","rc":[{"atl":[[10.5,4.83]],"id":67487132}],"con":true,"img":false}]}
{"op":"mcm","clk":"11540944028","pt":1719500281755,"mc":[{"id":"1.230180122","rc":[{"atl":[[11.5,2],[13.5,0]],"id":67487132}],"con":true,"img":false}]}
{"op":"mcm","clk":"11540944045","pt":1719500281970,"mc":[{"id":"1.230180122","rc":[{"atl":[[11,2.62]],"id":67487132}],"con":true,"img":false}]}
{"op":"mcm","clk":"11540944072","pt":1719500282225,"mc":[{"id":"1.230180122","rc":[{"atl":[[1000,0.11]],"id":67487132}],"con":true,"img":false}]}
{"op":"mcm","clk":"11540944083","pt":1719500282281,"mc":[{"id":"1.230180122","rc":[{"atl":[[10.5,2.41]],"id":67487132}],"con":true,"img":false}]}
{"op":"mcm","clk":"11540944102","pt":1719500282495,"mc":[{"id":"1.230180122","rc":[{"atl":[[10,2],[1000,0]],"id":67487132}],"con":true,"img":false}]}
{"op":"mcm","clk":"11540944112","pt":1719500282546,"mc":[{"id":"1.230180122","rc":[{"atl":[[9.8,0.11]],"id":67487132}],"con":true,"img":false}]}
{"op":"mcm","clk":"11540944125","pt":1719500282792,"mc":[{"id":"1.230180122","rc":[{"atl":[[12,0]],"id":67487132}],"con":true,"img":false}]}
{"op":"mcm","clk":"11540944153","pt":1719500283060,"mc":[{"id":"1.230180122","rc":[{"atl":[[9.8,2.64]],"id":67487132},{"atl":[[6.6,2]],"id":70396461}],"con":true,"img":false}]}
{"op":"mcm","clk":"11540944170","pt":1719500283269,"mc":[{"id":"1.230180122","rc":[{"atl":[[10,1]],"id":67487132}],"con":true,"img":false}]}
{"op":"mcm","clk":"11540944178","pt":1719500283375,"mc":[{"id":"1.230180122","rc":[{"atl":[[7.2,4.26]],"id":70396461}],"con":true,"img":false}]}
{"op":"mcm","clk":"11540944191","pt":1719500283481,"mc":[{"id":"1.230180122","rc":[{"atl":[[9.6,1]],"id":67487132},{"atl":[[6.4,1]],"id":70396461}],"con":true,"img":false}]}
{"op":"mcm","clk":"11540944210","pt":1719500283681,"mc":[{"id":"1.230180122","rc":[{"atl":[[6.4,6.13]],"id":70396461}],"con":true,"img":false}]}
{"op":"mcm","clk":"11540944240","pt":1719500284046,"mc":[{"id":"1.230180122","rc":[{"atl":[[6.6,0]],"id":70396461}],"con":true,"img":false}]}
{"op":"mcm","clk":"11540944256","pt":1719500284354,"mc":[{"id":"1.230180122","rc":[{"atl":[[10,0]],"id":67487132}],"con":true,"img":false}]}
{"op":"mcm","clk":"11540944264","pt":1719500284461,"mc":[{"id":"1.230180122","rc":[{"atl":[[9.6,2]],"id":67487132}],"con":true,"img":false}]}
{"op":"mcm","clk":"11540944301","pt":1719500284975,"mc":[{"id":"1.230180122","rc":[{"atl":[[10.5,7.05]],"id":67487132}],"con":true,"img":false}]}
{"op":"mcm","clk":"11540944306","pt":1719500285072,"mc":[{"id":"1.230180122","rc":[{"atl":[[11.5,0]],"id":67487132}],"con":true,"img":false}]}
{"op":"mcm","clk":"11540944314","pt":1719500285186,"mc":[{"id":"1.230180122","rc":[{"atl":[[9.4,0.84],[9.6,1]],"id":67487132}],"con":true,"img":false}]}
{"op":"mcm","clk":"11540944322","pt":1719500285279,"mc":[{"id":"1.230180122","rc":[{"atl":[[10,1]],"id":67487132}],"con":true,"img":false}]}
{"op":"mcm","clk":"11540944358","pt":1719500285759,"mc":[{"id":"1.230180122","rc":[{"atl":[[6.4,5.13]],"id":70396461}],"con":true,"img":false}]}
{"op":"mcm","clk":"11540944366","pt":1719500285866,"mc":[{"id":"1.230180122","rc":[{"atl":[[7,1]],"id":70396461}],"con":true,"img":false}]}
{"op":"mcm","clk":"11540944427","pt":1719500286579,"mc":[{"id":"1.230180122","rc":[{"atb":[[4.7,0]],"id":67487132},{"trd":[[4.7,1.99]],"ltp":4.7,"tv":1.99,"id":67487132},{"atl":[[7,0]],"id":70396461}],"con":true,"img":false}]}
{"op":"mcm","clk":"11540944435","pt":1719500286686,"mc":[{"id":"1.230180122","rc":[{"atb":[[3.25,10.26],[3.15,0]],"id":67487132},{"atl":[[6.2,1.02]],"id":70396461}],"con":true,"img":false}]}
{"op":"mcm","clk":"11540944474","pt":1719500287161,"mc":[{"id":"1.230180122","rc":[{"atl":[[9.4,3.54]],"id":67487132}],"con":true,"img":false}]}
{"op":"mcm","clk":"11540944500","pt":1719500287577,"mc":[{"id":"1.230180122","rc":[{"atl":[[9.6,0]],"id":67487132}],"con":true,"img":false}]}
{"op":"mcm","clk":"11540944508","pt":1719500287675,"mc":[{"id":"1.230180122","rc":[{"atl":[[9.2,1],[1000,1]],"id":67487132}],"con":true,"img":false}]}
{"op":"mcm","clk":"11540944524","pt":1719500287994,"mc":[{"id":"1.230180122","rc":[{"atl":[[10,0],[1000,0.02]],"id":67487132}],"con":true,"img":false}]}
{"op":"mcm","clk":"11540944531","pt":1719500288084,"mc":[{"id":"1.230180122","rc":[{"atl":[[9.2,2]],"id":67487132}],"con":true,"img":false}]}
{"op":"mcm","clk":"11540944537","pt":1719500288195,"mc":[{"id":"1.230180122","rc":[{"atl":[[9.4,0.84],[1000,0]],"id":67487132}],"con":true,"img":false}]}
{"op":"mcm","clk":"11540944545","pt":1719500288258,"mc":[{"id":"1.230180122","rc":[{"atl":[[9.2,2.02]],"id":67487132}],"con":true,"img":false}]}
{"op":"mcm","clk":"11540944555","pt":1719500288359,"mc":[{"id":"1.230180122","rc":[{"atl":[[9,2.81]],"id":67487132}],"con":true,"img":false}]}
{"op":"mcm","clk":"11540944567","pt":1719500288566,"mc":[{"id":"1.230180122","rc":[{"atl":[[9.2,1.02]],"id":67487132}],"con":true,"img":false}]}
{"op":"mcm","clk":"11540944574","pt":1719500288661,"mc":[{"id":"1.230180122","rc":[{"atl":[[9.6,1]],"id":67487132}],"con":true,"img":false}]}
{"op":"mcm","clk":"11540944581","pt":1719500288764,"mc":[{"id":"1.230180122","rc":[{"atl":[[9.4,0]],"id":67487132}],"con":true,"img":false}]}
{"op":"mcm","clk":"11540944640","pt":1719500289550,"mc":[{"id":"1.230180122","rc":[{"atl":[[9.6,0]],"id":67487132}],"con":true,"img":false}]}
{"op":"mcm","clk":"11540944646","pt":1719500289663,"mc":[{"id":"1.230180122","rc":[{"atl":[[9.2,1],[8.8,1]],"id":67487132}],"con":true,"img":false}]}
{"op":"mcm","clk":"11540944654","pt":1719500289757,"mc":[{"id":"1.230180122","rc":[{"atl":[[8.8,1.02]],"id":67487132}],"con":true,"img":false}]}
{"op":"mcm","clk":"11540944659","pt":1719500289857,"mc":[{"id":"1.230180122","rc":[{"atl":[[9,0]],"id":67487132}],"con":true,"img":false}]}
{"op":"mcm","clk":"11540944678","pt":1719500290074,"mc":[{"id":"1.230180122","rc":[{"atb":[[1.04,93.13]],"id":40028187},{"atl":[[1000,1.7]],"id":40028187},{"atb":[[1.04,1.7]],"id":43318163},{"atl":[[1000,1.88]],"id":43318163},{"atb":[[1.02,155.24]],"id":67487132},{"atl":[[1000,1.7]],"id":67487132}],"con":true,"img":false}]}
{"op":"mcm","clk":"11540944684","pt":1719500290163,"mc":[{"id":"1.230180122","rc":[{"atb":[[1.04,91.49]],"id":40028187},{"atl":[[1000,0]],"id":40028187},{"atb":[[1.04,0.06]],"id":43318163},{"atl":[[1000,0.17]],"id":43318163},{"atb":[[1.02,153.66]],"id":67487132},{"atl":[[8.6,2]],"id":67487132}],"con":true,"img":false}]}
{"op":"mcm","clk":"11540944696","pt":1719500290280,"mc":[{"id":"1.230180122","rc":[{"atb":[[1.02,153.54]],"id":67487132},{"atl":[[1000,0.03]],"id":67487132}],"con":true,"img":false}]}
{"op":"mcm","clk":"11540944707","pt":1719500290383,"mc":[{"id":"1.230180122","rc":[{"atb":[[1.04,91.43]],"id":40028187},{"atb":[[1.04,0]],"id":43318163},{"atb":[[3.3,0.12]],"id":67487132},{"atl":[[1000,0]],"id":67487132}],"con":true,"img":false}]}
{"op":"mcm","clk":"11540944717","pt":1719500290485,"mc":[{"id":"1.230180122","rc":[{"atb":[[5.3,1.66]],"id":40028187},{"atb":[[5.2,1.66]],"id":43318163},{"atl":[[8.4,3.02],[8.8,1.05]],"id":67487132}],"con":true,"img":false}]}
{"op":"mcm","clk":"11540944737","pt":1719500290685,"mc":[{"id":"1.230180122","rc":[{"atl":[[9.2,0],[8.8,1.03]],"id":67487132}],"con":true,"img":false}]}
{"op":"mcm","clk":"11540944747","pt":1719500290796,"mc":[{"id":"1.230180122","rc":[{"atl":[[8.4,3.04]],"id":67487132}],"con":true,"img":false}]}
{"op":"mcm","clk":"11540944769","pt":1719500290993,"mc":[{"id":"1.230180122","rc":[{"atb":[[3.3,11.92]],"id":67487132},{"atl":[[8.2,1],[8.4,6.22]],"id":67487132}],"con":true,"img":false}]}
{"op":"mcm","clk":"11540944808","pt":1719500291462,"mc":[{"id":"1.230180122","rc":[{"atl":[[8.2,5.11]],"id":67487132}],"con":true,"img":false}]}
{"op":"mcm","clk":"11540944831","pt":1719500291675,"mc":[{"id":"1.230180122","rc":[{"atb":[[4.2,1]],"id":67487132},{"atl":[[11,0],[8.4,3.2],[8.6,0]],"id":67487132}],"con":true,"img":false}]}
{"op":"mcm","clk":"11540944839","pt":1719500291780,"mc":[{"id":"1.230180122","rc":[{"atl":[[8.4,3.18],[8.8,0.03]],"id":67487132}],"con":true,"img":false}]}
{"op":"mcm","clk":"11540944850","pt":1719500291885,"mc":[{"id":"1.230180122","rc":[{"atl":[[8,3.19],[8.2,9.74]],"id":67487132}],"con":true,"img":false}]}
{"op":"mcm","clk":"11540944869","pt":1719500292092,"mc":[{"id":"1.230180122","rc":[{"atl":[[8.2,8.74]],"id":67487132}],"con":true,"img":false}]}
{"op":"mcm","clk":"11540944878","pt":1719500292192,"mc":[{"id":"1.230180122","rc":[{"atl":[[7.8,0.84]],"id":67487132}],"con":true,"img":false}]}
{"op":"mcm","clk":"11540944887","pt":1719500292298,"mc":[{"id":"1.230180122","rc":[{"atl":[[8,4.19]],"id":67487132}],"con":true,"img":false}]}
{"op":"mcm","clk":"11540944908","pt":1719500292501,"mc":[{"id":"1.230180122","rc":[{"atl":[[10.5,4.64]],"id":67487132}],"con":true,"img":false}]}
{"op":"mcm","clk":"11540944918","pt":1719500292568,"mc":[{"id":"1.230180122","rc":[{"atl":[[7.8,4.52]],"id":67487132}],"con":true,"img":false}]}
{"op":"mcm","clk":"11540944928","pt":1719500292663,"mc":[{"id":"1.230180122","rc":[{"atl":[[8.2,7.74]],"id":67487132}],"con":true,"img":false}]}
{"op":"mcm","clk":"11540944936","pt":1719500292756,"mc":[{"id":"1.230180122","rc":[{"atl":[[7.8,5.52]],"id":67487132}],"con":true,"img":false}]}
{"op":"mcm","clk":"11540944952","pt":1719500292967,"mc":[{"id":"1.230180122","rc":[{"atl":[[8,1.02]],"id":67487132}],"con":true,"img":false}]}
{"op":"mcm","clk":"11540944962","pt":1719500293075,"mc":[{"id":"1.230180122","rc":[{"atl":[[7.6,3.34]],"id":67487132}],"con":true,"img":false}]}
{"op":"mcm","clk":"11540944977","pt":1719500293286,"mc":[{"id":"1.230180122","rc":[{"atl":[[9.8,0.11]],"id":67487132}],"con":true,"img":false}]}
{"op":"mcm","clk":"11540944984","pt":1719500293378,"mc":[{"id":"1.230180122","rc":[{"atb":[[2.9,3.15]],"id":70396461}],"con":true,"img":false}]}
{"op":"mcm","clk":"11540944994","pt":1719500293499,"mc":[{"id":"1.230180122","rc":[{"atl":[[7.6,7.32]],"id":67487132}],"con":true,"img":false}]}
{"op":"mcm","clk":"11540945011","pt":1719500293687,"mc":[{"id":"1.230180122","rc":[{"atl":[[7.8,4.52]],"id":67487132}],"con":true,"img":false}]}
{"op":"mcm","clk":"11540945018","pt":1719500293791,"mc":[{"id":"1.230180122","rc":[{"atl":[[7.4,1]],"id":67487132}],"con":true,"img":false}]}
{"op":"mcm","clk":"11540945053","pt":1719500294159,"mc":[{"id":"1.230180122","rc":[{"atl":[[7.6,3.98]],"id":67487132}],"con":true,"img":false}]}
{"op":"mcm","clk":"11540945220","pt":1719500296277,"mc":[{"id":"1.230180122","rc":[{"atb":[[2.9,0]],"id":70396461}],"con":true,"img":false}]}
{"op":"mcm","clk":"11540945273","pt":1719500296802,"mc":[{"id":"1.230180122","rc":[{"atl":[[8.2,3.62]],"id":67487132}],"con":true,"img":false}]}
{"op":"mcm","clk":"11540945309","pt":1719500297260,"mc":[{"id":"1.230180122","rc":[{"atl":[[6,2]],"id":70396461}],"con":true,"img":false}]}
{"op":"mcm","clk":"11540945320","pt":1719500297378,"mc":[{"id":"1.230180122","rc":[{"atl":[[6,7.42]],"id":70396461}],"con":true,"img":false}]}
{"op":"mcm","clk":"11540945345","pt":1719500297681,"mc":[{"id":"1.230180122","rc":[{"atl":[[6.4,4.29],[5.9,0.84]],"id":70396461}],"con":true,"img":false}]}
{"op":"mcm","clk":"11540945349","pt":1719500297774,"mc":[{"id":"1.230180122","rc":[{"atl":[[9.8,0]],"id":67487132},{"atl":[[6.2,1]],"id":70396461}],"con":true,"img":false}]}
{"op":"mcm","clk":"11540945362","pt":1719500297888,"mc":[{"id":"1.230180122","rc":[{"atl":[[5.9,5.16]],"id":70396461}],"con":true,"img":false}]}
{"op":"mcm","clk":"11540945393","pt":1719500298294,"mc":[{"id":"1.230180122","rc":[{"atl":[[6,5.42]],"id":70396461}],"con":true,"img":false}]}
{"op":"mcm","clk":"11540945405","pt":1719500298399,"mc":[{"id":"1.230180122","rc":[{"atl":[[5.9,10.87]],"id":70396461}],"con":true,"img":false}]}
{"op":"mcm","clk":"11540945412","pt":1719500298463,"mc":[{"id":"1.230180122","rc":[{"atb":[[7.2,1.17]],"id":47703807}],"con":true,"img":false}]}
{"op":"mcm","clk":"11540945436","pt":1719500298774,"mc":[{"id":"1.230180122","rc":[{"atb":[[6.8,4.32]],"id":47703807},{"atl":[[1000,0.84]],"id":57697855}],"con":true,"img":false}]}
{"op":"mcm","clk":"11540945464","pt":1719500299175,"mc":[{"id":"1.230180122","rc":[{"atl":[[21,0],[1000,0.52]],"id":57697855}],"con":true,"img":false}]}
{"op":"mcm","clk":"11540945473","pt":1719500299285,"mc":[{"id":"1.230180122","rc":[{"atb":[[7.2,4.94]],"id":47703807}],"con":true,"img":false}]}
{"op":"mcm","clk":"11540945495","pt":1719500299586,"mc":[{"id":"1.230180122","rc":[{"atl":[[1000,0]],"id":57697855}],"con":true,"img":false}]}
{"op":"mcm","clk":"11540945504","pt":1719500299692,"mc":[{"id":"1.230180122","rc":[{"atb":[[7.4,0.84]],"id":47703807},{"atl":[[16,0.52]],"id":57697855}],"con":true,"img":false}]}
{"op":"mcm","clk":"11540945515","pt":1719500299852,"mc":[{"id":"1.230180122","rc":[{"atb":[[7.4,4.27],[7,0]],"id":47703807},{"atl":[[16.5,3.53],[17.5,0]],"id":57697855}],"con":true,"img":false}]}
{"op":"mcm","clk":"11540945541","pt":1719500300160,"mc":[{"id":"1.230180122","rc":[{"atl":[[16,1.37]],"id":57697855}],"con":true,"img":false}]}
{"op":"mcm","clk":"11540945550","pt":1719500300275,"mc":[{"id":"1.230180122","rc":[{"atb":[[7.4,8],[7.6,1]],"id":47703807}],"con":true,"img":false}]}
{"op":"mcm","clk":"11540945570","pt":1719500300570,"mc":[{"id":"1.230180122","rc":[{"atb":[[7.4,4.57]],"id":47703807}],"con":true,"img":false}]}
{"op":"mcm","clk":"11540945575","pt":1719500300677,"mc":[{"id":"1.230180122","rc":[{"atl":[[1000,1.7]],"id":67487132}],"con":true,"img":false}]}
{"op":"mcm","clk":"11540945585","pt":1719500300776,"mc":[{"id":"1.230180122","rc":[{"atb":[[1.04,6.81]],"id":67487132},{"atl":[[1000,6.81]],"id":67487132}],"con":true,"img":false}]}
{"op":"mcm","clk":"11540945594","pt":1719500300895,"mc":[{"id":"1.230180122","rc":[{"atl":[[1000,5.13]],"id":67487132}],"con":true,"img":false}]}
{"op":"mcm","clk":"11540945602","pt":1719500300982,"mc":[{"id":"1.230180122","rc":[{"atb":[[1.04,5.17]],"id":67487132},{"atl":[[1000,1.79]],"id":67487132}],"con":true,"img":false}]}
{"op":"mcm","clk":"11540945612","pt":1719500301114,"mc":[{"id":"1.230180122","rc":[{"atb":[[1.04,0.27]],"id":67487132},{"atl":[[1000,0.08]],"id":67487132}],"con":true,"img":false}]}
{"op":"mcm","clk":"11540945622","pt":1719500301197,"mc":[{"id":"1.230180122","rc":[{"atb":[[1.04,0.2]],"id":67487132},{"atl":[[7.4,1.03],[1000,0.02]],"id":67487132}],"con":true,"img":false}]}
{"op":"mcm","clk":"11540945628","pt":1719500301293,"mc":[{"id":"1.230180122","rc":[{"atb":[[3.75,0.07],[1.04,0]],"id":67487132},{"atl":[[7.4,1.09],[1000,0]],"id":67487132}],"con":true,"img":false}]}
{"op":"mcm","clk":"11540945639","pt":1719500301405,"mc":[{"id":"1.230180122","rc":[{"atb":[[3.75,0.27]],"id":67487132},{"atl":[[7.4,1.11]],"id":67487132}],"con":true,"img":false}]}
{"op":"mcm","clk":"11540945663","pt":1719500301658,"mc":[{"id":"1.230180122","rc":[{"atl":[[6.2,0]],"id":70396461}],"con":true,"img":false}]}
{"op":"mcm","clk":"11540945671","pt":1719500301763,"mc":[{"id":"1.230180122","rc":[{"atb":[[5,0]],"id":47703807},{"atl":[[5.8,1]],"id":70396461}],"con":true,"img":false}]}
{"op":"mcm","clk":"11540945680","pt":1719500301883,"mc":[{"id":"1.230180122","rc":[{"atl":[[8.4,0]],"id":67487132}],"con":true,"img":false}]}
{"op":"mcm","clk":"11540945694","pt":1719500302073,"mc":[{"id":"1.230180122","rc":[{"atl":[[7.4,5.14]],"id":67487132},{"atl":[[5.9,6.57]],"id":70396461}],"con":true,"img":false}]}
{"op":"mcm","clk":"11540945708","pt":1719500302287,"mc":[{"id":"1.230180122","rc":[{"atl":[[8,0.02],[7.2,3.53]],"id":67487132}],"con":true,"img":false}]}
{"op":"mcm","clk":"11540945716","pt":1719500302382,"mc":[{"id":"1.230180122","rc":[{"atl":[[7.2,4.53]],"id":67487132}],"con":true,"img":false}]}
{"op":"mcm","clk":"11540945736","pt":1719500302699,"mc":[{"id":"1.230180122","rc":[{"atl":[[7,0.84]],"id":67487132}],"con":true,"img":false}]}
{"op":"mcm","clk":"11540945745","pt":1719500302798,"mc":[{"id":"1.230180122","rc":[{"atl":[[7.8,3.68]],"id":67487132},{"atl":[[5.9,6.55]],"id":70396461}],"con":true,"img":false}]}
{"op":"mcm","clk":"11540945752","pt":1719500302858,"mc":[{"id":"1.230180122","rc":[{"atl":[[8.2,0]],"id":67487132},{"atl":[[5.7,0.02]],"id":70396461}],"con":true,"img":false}]}
{"op":"mcm","clk":"11540945762","pt":1719500302968,"mc":[{"id":"1.230180122","rc":[{"atl":[[7,5.09]],"id":67487132}],"con":true,"img":false}]}
{"op":"mcm","clk":"11540945799","pt":1719500303384,"mc":[{"id":"1.230180122","rc":[{"atl":[[7.4,4.14],[7.2,1]],"id":67487132}],"con":true,"img":false}]}
{"op":"mcm","clk":"11540945805","pt":1719500303482,"mc":[{"id":"1.230180122","rc":[{"atl":[[6.8,1]],"id":67487132}],"con":true,"img":false}]}
{"op":"mcm","clk":"11540945813","pt":1719500303593,"mc":[{"id":"1.230180122","rc":[{"atl":[[6.8,4.73]],"id":67487132}],"con":true,"img":false}]}
{"op":"mcm","clk":"11540945872","pt":1719500304367,"mc":[{"id":"1.230180122","rc":[{"atl":[[5.7,2.02]],"id":70396461}],"con":true,"img":false}]}
{"op":"mcm","clk":"11540945882","pt":1719500304467,"mc":[{"id":"1.230180122","rc":[{"atl":[[7.8,0]],"id":67487132}],"con":true,"img":false}]}
{"op":"mcm","clk":"11540945891","pt":1719500304573,"mc":[{"id":"1.230180122","rc":[{"atl":[[5.6,4.53]],"id":70396461}],"con":true,"img":false}]}
{"op":"mcm","clk":"11540945899","pt":1719500304672,"mc":[{"id":"1.230180122","rc":[{"atl":[[6.8,9.45]],"id":67487132},{"atl":[[5.9,5.71]],"id":70396461}],"con":true,"img":false}]}
{"op":"mcm","clk":"11540945907","pt":1719500304774,"mc":[{"id":"1.230180122","rc":[{"atl":[[5.6,5.38]],"id":70396461}],"con":true,"img":false}]}
{"op":"mcm","clk":"11540945916","pt":1719500304885,"mc":[{"id":"1.230180122","rc":[{"atl":[[7.2,0]],"id":67487132}],"con":true,"img":false}]}
{"op":"mcm","clk":"11540945937","pt":1719500305084,"mc":[{"id":"1.230180122","rc":[{"atl":[[6.6,5.62]],"id":67487132},{"atl":[[5.7,0.02]],"id":70396461}],"con":true,"img":false}]}
{"op":"mcm","clk":"11540945964","pt":1719500305399,"mc":[{"id":"1.230180122","rc":[{"atl":[[6.8,8.45]],"id":67487132},{"atl":[[5.8,0]],"id":70396461}],"con":true,"img":false}]}
{"op":"mcm","clk":"11540945977","pt":1719500305502,"mc":[{"id":"1.230180122","rc":[{"atl":[[6.4,1],[7.6,0]],"id":67487132},{"atl":[[7.2,0],[5.5,1]],"id":70396461}],"con":true,"img":false}]}
{"op":"mcm","clk":"11540945985","pt":1719500305609,"mc":[{"id":"1.230180122","rc":[{"atl":[[6.8,4.72]],"id":67487132}],"con":true,"img":false}]}
{"op":"mcm","clk":"11540945995","pt":1719500305706,"mc":[{"id":"1.230180122","rc":[{"atl":[[6.6,9.82],[7,4.25]],"id":67487132},{"atl":[[5.6,11.05],[5.7,0]],"id":70396461}],"con":true,"img":false}]}
{"op":"mcm","clk":"11540946001","pt":1719500305811,"mc":[{"id":"1.230180122","rc":[{"atl":[[5.5,1.02]],"id":70396461}],"con":true,"img":false}]}
{"op":"mcm","clk":"11540946008","pt":1719500305924,"mc":[{"id":"1.230180122","rc":[{"atl":[[6.6,8.82]],"id":67487132}],"con":true,"img":false}]}
{"op":"mcm","clk":"11540946041","pt":1719500306281,"mc":[{"id":"1.230180122","rc":[{"atl":[[5.6,6.51]],"id":70396461}],"con":true,"img":false}]}
{"op":"mcm","clk":"11540946054","pt":1719500306476,"mc":[{"id":"1.230180122","rc":[{"atl":[[6.4,2]],"id":67487132}],"con":true,"img":false}]}
{"op":"mcm","clk":"11540946085","pt":1719500306896,"mc":[{"id":"1.230180122","rc":[{"atl":[[6.2,4.09]],"id":67487132}],"con":true,"img":false}]}
{"op":"mcm","clk":"11540946127","pt":1719500307363,"mc":[{"id":"1.230180122","rc":[{"atl":[[6.4,1]],"id":67487132}],"con":true,"img":false}]}
{"op":"mcm","clk":"11540946133","pt":1719500307471,"mc":[{"id":"1.230180122","rc":[{"atl":[[6,1]],"id":67487132}],"con":true,"img":false}]}
{"op":"mcm","clk":"11540946141","pt":1719500307574,"mc":[{"id":"1.230180122","rc":[{"atl":[[7.4,0.11]],"id":67487132}],"con":true,"img":false}]}
{"op":"mcm","clk":"11540946146","pt":1719500307674,"mc":[{"id":"1.230180122","rc":[{"atl":[[6.2,9.41]],"id":67487132}],"con":true,"img":false}]}
{"op":"mcm","clk":"11540946174","pt":1719500307994,"mc":[{"id":"1.230180122","rc":[{"atl":[[6.2,5.32]],"id":67487132}],"con":true,"img":false}]}
{"op":"mcm","clk":"11540946477","pt":1719500311612,"mc":[{"id":"1.230180122","rc":[{"atl":[[5.4,2]],"id":70396461},{"atb":[[3.7,1]],"id":57697855}],"con":true,"img":false}]}
{"op":"mcm","clk":"11540946486","pt":1719500311705,"mc":[{"id":"1.230180122","rc":[{"atl":[[1000,0.78]],"id":67487132}],"con":true,"img":false}]}
{"op":"mcm","clk":"11540946496","pt":1719500311763,"mc":[{"id":"1.230180122","rc":[{"atl":[[6.4,0]],"id":70396461}],"con":true,"img":false}]}
{"op":"mcm","clk":"11540946502","pt":1719500311868,"mc":[{"id":"1.230180122","rc":[{"atl":[[6.6,4.2]],"id":67487132}],"con":true,"img":false}]}
{"op":"mcm","clk":"11540946510","pt":1719500311975,"mc":[{"id":"1.230180122","rc":[{"atl":[[5.4,8]],"id":70396461}],"con":true,"img":false}]}
{"op":"mcm","clk":"11540946519","pt":1719500312074,"mc":[{"id":"1.230180122","rc":[{"atl":[[1000,0.55]],"id":67487132}],"con":true,"img":false}]}
{"op":"mcm","clk":"11540946528","pt":1719500312182,"mc":[{"id":"1.230180122","rc":[{"atl":[[5.3,4.79]],"id":70396461}],"con":true,"img":false}]}
{"op":"mcm","clk":"11540946541","pt":1719500312298,"mc":[{"id":"1.230180122","rc":[{"atl":[[5.3,5.63],[5.6,5.67]],"id":70396461}],"con":true,"img":false}]}
{"op":"mcm","clk":"11540946556","pt":1719500312486,"mc":[{"id":"1.230180122","rc":[{"atl":[[1000,0]],"id":67487132}],"con":true,"img":false}]}
{"op":"mcm","clk":"11540946568","pt":1719500312604,"mc":[{"id":"1.230180122","rc":[{"atl":[[7,4.8]],"id":67487132},{"atl":[[6,0]],"id":70396461}],"con":true,"img":false}]}
{"op":"mcm","clk":"11540946577","pt":1719500312704,"mc":[{"id":"1.230180122","rc":[{"atl":[[5.3,11.96],[5.5,0.02]],"id":70396461}],"con":true,"img":false}]}
{"op":"mcm","clk":"11540946587","pt":1719500312815,"mc":[{"id":"1.230180122","rc":[{"atl":[[5.3,12.96],[5.5,0]],"id":70396461}],"con":true,"img":false}]}
{"op":"mcm","clk":"11540946595","pt":1719500312907,"mc":[{"id":"1.230180122","rc":[{"atl":[[5.2,0.02]],"id":70396461}],"con":true,"img":false}]}
{"op":"mcm","clk":"11540946872","pt":1719500316882,"mc":[{"id":"1.230180122","rc":[{"atl":[[5.4,6]],"id":70396461}],"con":true,"img":false}]}
{"op":"mcm","clk":"11540946988","pt":1719500318382,"mc":[{"id":"1.230180122","rc":[{"atl":[[6,3]],"id":67487132}],"con":true,"img":false}]}
{"op":"mcm","clk":"11540947007","pt":1719500318599,"mc":[{"id":"1.230180122","rc":[{"atl":[[5.9,4.3]],"id":67487132}],"con":true,"img":false}]}
{"op":"mcm","clk":"11540947015","pt":1719500318696,"mc":[{"id":"1.230180122","rc":[{"atl":[[5.9,5.14]],"id":67487132}],"con":true,"img":false}]}
{"op":"mcm","clk":"11540947042","pt":1719500318999,"mc":[{"id":"1.230180122","rc":[{"atl":[[7,0.55]],"id":67487132}],"con":true,"img":false}]}
{"op":"mcm","clk":"11540947053","pt":1719500319117,"mc":[{"id":"1.230180122","rc":[{"atl":[[5.9,10.29]],"id":67487132}],"con":true,"img":false}]}
{"op":"mcm","clk":"11540947078","pt":1719500319418,"mc":[{"id":"1.230180122","rc":[{"atl":[[6.4,0]],"id":67487132}],"con":true,"img":false}]}
{"op":"mcm","clk":"11540947100","pt":1719500319572,"mc":[{"id":"1.230180122","rc":[{"spn":47.6,"spf":"NaN","id":43318163},{"spn":7.6,"spf":1.0,"id":47703807},{"atl":[[5.8,1]],"id":67487132},{"spn":5.0,"spf":"NaN","id":67487132},{"spn":4.57,"spf":"NaN","id":70396461}],"con":true,"img":false}]}
{"op":"mcm","clk":"11540947144","pt":1719500320191,"mc":[{"id":"1.230180122","rc":[{"atl":[[5.9,5.99]],"id":67487132}],"con":true,"img":false}]}
{"op":"mcm","clk":"11540947153","pt":1719500320291,"mc":[{"id":"1.230180122","rc":[{"atb":[[2.94,2.55]],"id":70396461},{"atb":[[3.75,19.66]],"id":57697855}],"con":true,"img":false}]}
{"op":"mcm","clk":"11540947172","pt":1719500320498,"mc":[{"id":"1.230180122","rc":[{"atb":[[2.96,13.74]],"id":70396461}],"con":true,"img":false}]}
{"op":"mcm","clk":"11540947338","pt":1719500322416,"mc":[{"id":"1.230180122","rc":[{"atb":[[5.3,1.6]],"id":40028187},{"atb":[[5.2,1.6]],"id":43318163},{"atb":[[3.3,11.8],[3.75,0]],"id":67487132},{"atl":[[7.4,0],[8.8,0]],"id":67487132}],"con":true,"img":false}]}
{"op":"mcm","clk":"11540947417","pt":1719500323608,"mc":[{"id":"1.230180122","rc":[{"atl":[[6,2]],"id":67487132}],"con":true,"img":false}]}
{"op":"mcm","clk":"11540947426","pt":1719500323711,"mc":[{"id":"1.230180122","rc":[{"atl":[[5.8,2],[6,0]],"id":67487132}],"con":true,"img":false}]}
{"op":"mcm","clk":"11540947432","pt":1719500323815,"mc":[{"id":"1.230180122","rc":[{"atl":[[6.8,0]],"id":67487132}],"con":true,"img":false}]}
{"op":"mcm","clk":"11540947441","pt":1719500323922,"mc":[{"id":"1.230180122","rc":[{"atl":[[5.8,6.72]],"id":67487132}],"con":true,"img":false}]}
{"op":"mcm","clk":"11540947462","pt":1719500324075,"mc":[{"id":"1.230180122","rc":[{"atl":[[5.7,4.45]],"id":67487132}],"con":true,"img":false}]}
{"op":"mcm","clk":"11540947507","pt":1719500324695,"mc":[{"id":"1.230180122","rc":[{"atl":[[5.9,5.15],[6.6,0]],"id":67487132}],"con":true,"img":false}]}
{"op":"mcm","clk":"11540947518","pt":1719500324798,"mc":[{"id":"1.230180122","rc":[{"atl":[[5.7,9.27]],"id":67487132}],"con":true,"img":false}]}
{"op":"mcm","clk":"11540947534","pt":1719500325006,"mc":[{"id":"1.230180122","rc":[{"atl":[[5.8,5.72]],"id":67487132}],"con":true,"img":false}]}
{"op":"mcm","clk":"11540947541","pt":1719500325112,"mc":[{"id":"1.230180122","rc":[{"atl":[[5.6,1]],"id":67487132}],"con":true,"img":false}]}
{"op":"mcm","clk":"11540947550","pt":1719500325208,"mc":[{"id":"1.230180122","rc":[{"atl":[[5.8,4.72]],"id":67487132}],"con":true,"img":false}]}
{"op":"mcm","clk":"11540947558","pt":1719500325312,"mc":[{"id":"1.230180122","rc":[{"atl":[[5.6,2]],"id":67487132}],"con":true,"img":false}]}
{"op":"mcm","clk":"11540947577","pt":1719500325517,"mc":[{"id":"1.230180122","rc":[{"atl":[[6.2,0]],"id":67487132}],"con":true,"img":false}]}
{"op":"mcm","clk":"11540947594","pt":1719500325673,"mc":[{"id":"1.230180122","rc":[{"atl":[[5.6,7.52],[5.7,4.82]],"id":67487132}],"con":true,"img":false}]}
{"op":"mcm","clk":"11540947602","pt":1719500325776,"mc":[{"id":"1.230180122","rc":[{"atl":[[5.5,0.84]],"id":67487132}],"con":true,"img":false}]}
{"op":"mcm","clk":"11540947610","pt":1719500325888,"mc":[{"id":"1.230180122","rc":[{"atl":[[5.5,5.46]],"id":67487132}],"con":true,"img":false}]}
{"op":"mcm","clk":"11540947621","pt":1719500325981,"mc":[{"id":"1.230180122","rc":[{"spb":[[1000,1500.43]],"id":40028187},{"atl":[[5.6,6.52]],"id":67487132}],"con":true,"img":false}]}
{"op":"mcm","clk":"11540947627","pt":1719500326088,"mc":[{"id":"1.230180122","rc":[{"atl":[[5.4,1]],"id":67487132}],"con":true,"img":false}]}
{"op":"mcm","clk":"11540947638","pt":1719500326225,"mc":[{"id":"1.230180122","rc":[{"atl":[[5.6,5.52]],"id":67487132},{"atb":[[3.3,1]],"id":57697855},{"atl":[[8.2,1]],"id":57697855}],"con":true,"img":false}]}
{"op":"mcm","clk":"11540947644","pt":1719500326290,"mc":[{"id":"1.230180122","rc":[{"atl":[[11,1]],"id":40028187},{"atl":[[11,1]],"id":43318163},{"atl":[[5.9,0],[5.4,2]],"id":67487132}],"con":true,"img":false}]}
{"op":"mcm","clk":"11540947657","pt":1719500326400,"mc":[{"id":"1.230180122","rc":[{"atl":[[5.4,7.02]],"id":67487132}],"con":true,"img":false}]}
{"op":"mcm","clk":"11540947667","pt":1719500326497,"mc":[{"id":"1.230180122","rc":[{"atl":[[5.5,0.84]],"id":67487132}],"con":true,"img":false}]}
{"op":"mcm","clk":"11540947690","pt":1719500326804,"mc":[{"id":"1.230180122","rc":[{"atl":[[17,1.68]],"id":57697855}],"con":true,"img":false}]}
{"op":"mcm","clk":"11540947737","pt":1719500327331,"mc":[{"id":"1.230180122","rc":[{"atl":[[5.4,6.02]],"id":67487132}],"con":true,"img":false}]}
{"op":"mcm","clk":"11540947749","pt":1719500327425,"mc":[{"id":"1.230180122","rc":[{"atl":[[5.5,1.84]],"id":67487132}],"con":true,"img":false}]}
{"op":"mcm","clk":"11540947758","pt":1719500327481,"mc":[{"id":"1.230180122","rc":[{"atb":[[5.3,7.67]],"id":40028187},{"atl":[[60,0.43]],"id":40028187},{"atb":[[5.2,7.54]],"id":43318163},{"atl":[[90,1.39]],"id":43318163},{"atb":[[3.8,9.38]],"id":57697855},{"atl":[[15.5,1.89]],"id":57697855}],"con":true,"img":false}]}
{"op":"mcm","clk":"11540947768","pt":1719500327580,"mc":[{"id":"1.230180122","rc":[{"atl":[[5.3,4.79],[5.4,5.02]],"id":67487132}],"con":true,"img":false}]}
{"op":"mcm","clk":"11540947790","pt":1719500327796,"mc":[{"id":"1.230180122","rc":[{"atb":[[3.7,2.85],[3.4,0],[5.2,0.84]],"id":40028187},{"atb":[[4.3,10.04],[3.95,0]],"id":43318163},{"atl":[[65,2],[95,0]],"id":43318163},{"atb":[[4.6,1],[5.2,8.64]],"id":47703807},{"atl":[[19.5,4],[22,0]],"id":47703807},{"atl":[[10.5,0],[5.2,1],[8.8,9.51]],"id":67487132},{"atb":[[2.98,13.74],[2.88,0]],"id":70396461},{"atl":[[7.4,0],[6.2,11.42]],"id":70396461}],"con":true,"img":false}]}
{"op":"mcm","clk":"11540947802","pt":1719500328002,"mc":[{"id":"1.230180122","rc":[{"atb":[[5.4,1]],"id":40028187}],"con":true,"img":false}]}
{"op":"mcm","clk":"11540947821","pt":1719500328207,"mc":[{"id":"1.230180122","rc":[{"atb":[[5.5,1.54]],"id":40028187},{"atl":[[5.8,0],[5.3,0]],"id":67487132}],"con":true,"img":false}]}
{"op":"mcm","clk":"11540947830","pt":1719500328307,"mc":[{"id":"1.230180122","rc":[{"atb":[[5.4,1.84]],"id":40028187},{"atb":[[5.3,0.84]],"id":43318163},{"atl":[[90,0.39],[60,0.44]],"id":43318163},{"atl":[[5.5,0],[5.2,6.24]],"id":67487132},{"atb":[[3,13.53]],"id":70396461},{"atl":[[16.5,2.53]],"id":57697855}],"con":true,"img":false}]}
{"op":"mcm","clk":"11540947837","pt":1719500328410,"mc":[{"id":"1.230180122","rc":[{"atl":[[60,1.44]],"id":43318163},{"atl":[[5.2,7.24]],"id":67487132},{"atl":[[15,1]],"id":57697855}],"con":true,"img":false}]}
{"op":"mcm","clk":"11540947850","pt":1719500328525,"mc":[{"id":"1.230180122","rc":[{"atb":[[5.3,6.07]],"id":40028187}],"con":true,"img":false}]}
{"op":"mcm","clk":"11540947862","pt":1719500328725,"mc":[{"id":"1.230180122","rc":[{"atb":[[5.2,0]],"id":40028187},{"atb":[[3.2,2.09]],"id":70396461},{"atl":[[16,0.52]],"id":57697855}],"con":true,"img":false}]}
{"op":"mcm","clk":"11540947914","pt":1719500329299,"mc":[{"id":"1.230180122","rc":[{"atl":[[5.4,0],[5.6,0],[5.2,1],[5.7,0]],"id":67487132}],"con":true,"img":false}]}
{"op":"mcm","clk":"11540947922","pt":1719500329415,"mc":[{"id":"1.230180122","rc":[{"atb":[[5.5,6.96]],"id":40028187},{"atl":[[5.3,1],[6.8,4.05]],"id":67487132},{"atb":[[3.25,12.4]],"id":70396461}],"con":true,"img":false}]}
{"op":"mcm","clk":"11540947946","pt":1719500329712,"mc":[{"id":"1.230180122","rc":[{"atb":[[5.6,4.53]],"id":40028187},{"atl":[[5.2,0]],"id":67487132}],"con":true,"img":false}]}
{"op":"mcm","clk":"11540947967","pt":1719500329916,"mc":[{"id":"1.230180122","rc":[{"atl":[[5.3,2]],"id":67487132}],"con":true,"img":false}]}
{"op":"mcm","clk":"11540947976","pt":1719500330025,"mc":[{"id":"1.230180122","rc":[{"atb":[[5.6,10.1]],"id":40028187}],"con":true,"img":false}]}
{"op":"mcm","clk":"11540947993","pt":1719500330182,"mc":[{"id":"1.230180122","rc":[{"atb":[[5.4,0]],"id":40028187},{"atb":[[2.62,7.83]],"id":70396461}],"con":true,"img":false}]}
{"op":"mcm","clk":"11540948009","pt":1719500330388,"mc":[{"id":"1.230180122","rc":[{"atb":[[5.7,1]],"id":40028187},{"atb":[[2.2,10.58]],"id":43318163}],"con":true,"img":false}]}
{"op":"mcm","clk":"11540948020","pt":1719500330495,"mc":[{"id":"1.230180122","rc":[{"atb":[[2.3,9.76]],"id":67487132}],"con":true,"img":false}]}
{"op":"mcm","clk":"11540948037","pt":1719500330702,"mc":[{"id":"1.230180122","rc":[{"atb":[[5.6,5.57]],"id":40028187}],"con":true,"img":false}]}
{"op":"mcm","clk":"11540948087","pt":1719500331415,"mc":[{"id":"1.230180122","rc":[{"atl":[[5.2,3.02]],"id":67487132}],"con":true,"img":false}]}
{"op":"mcm","clk":"11540948107","pt":1719500331725,"mc":[{"id":"1.230180122","rc":[{"atl":[[5.2,8.58]],"id":67487132}],"con":true,"img":false}]}
{"op":"mcm","clk":"11540948120","pt":1719500331888,"mc":[{"id":"1.230180122","rc":[{"atl":[[5.3,1]],"id":67487132}],"con":true,"img":false}]}
{"op":"mcm","clk":"11540948127","pt":1719500331993,"mc":[{"id":"1.230180122","rc":[{"atl":[[5.1,1]],"id":67487132}],"con":true,"img":false}]}
{"op":"mcm","clk":"11540948270","pt":1719500333587,"mc":[{"id":"1.230180122","rc":[{"atl":[[5.3,0]],"id":67487132}],"con":true,"img":false}]}
{"op":"mcm","clk":"11540948282","pt":1719500333697,"mc":[{"id":"1.230180122","rc":[{"atl":[[5.1,2]],"id":67487132}],"con":true,"img":false}]}
{"op":"mcm","clk":"11540948305","pt":1719500333906,"mc":[{"id":"1.230180122","rc":[{"atl":[[16.5,4],[19.5,0]],"id":47703807},{"atl":[[7.8,6.05],[8.8,0]],"id":67487132}],"con":true,"img":false}]}
{"op":"mcm","clk":"11540948311","pt":1719500334000,"mc":[{"id":"1.230180122","rc":[{"atl":[[5.2,5.56]],"id":67487132},{"atb":[[3.6,10.38],[3.45,0]],"id":57697855}],"con":true,"img":false}]}
{"op":"mcm","clk":"11540948325","pt":1719500334202,"mc":[{"id":"1.230180122","rc":[{"atl":[[5,0.84]],"id":67487132}],"con":true,"img":false}]}
{"op":"mcm","clk":"11540948434","pt":1719500335496,"mc":[{"id":"1.230180122","rc":[{"atl":[[15.5,2.64]],"id":47703807},{"atl":[[5,6.48]],"id":67487132}],"con":true,"img":false}]}
{"op":"mcm","clk":"11540948526","pt":1719500336733,"mc":[{"id":"1.230180122","rc":[{"atl":[[5.1,1]],"id":67487132}],"con":true,"img":false}]}
{"op":"mcm","clk":"11540948540","pt":1719500336891,"mc":[{"id":"1.230180122","rc":[{"atb":[[4.2,0]],"id":67487132},{"atl":[[4.9,1]],"id":67487132},{"trd":[[4.2,2]],"ltp":4.2,"tv":2.0,"id":67487132}],"con":true,"img":false}]}
{"op":"mcm","clk":"11540948614","pt":1719500337924,"mc":[{"id":"1.230180122","rc":[{"atb":[[3.8,7.22],[4.2,0]],"id":57697855},{"atl":[[15,2.17]],"id":57697855},{"trd":[[3.8,4.32],[4.2,2]],"ltp":3.8,"tv":6.32,"id":57697855}],"con":true,"img":false}]}
{"op":"mcm","clk":"11540948631","pt":1719500338129,"mc":[{"id":"1.230180122","rc":[{"atl":[[15,1]],"id":57697855}],"con":true,"img":false}]}
{"op":"mcm","clk":"11540948782","pt":1719500340341,"mc":[{"id":"1.230180122","rc":[{"atb":[[1.03,11.99]],"id":40028187},{"atb":[[1.03,165.23]],"id":43318163},{"atb":[[1.03,67.03]],"id":47703807}],"con":true,"img":false}]}
{"op":"mcm","clk":"11540948792","pt":1719500340445,"mc":[{"id":"1.230180122","rc":[{"atl":[[17,0.26]],"id":40028187},{"atl":[[13,0.26]],"id":43318163},{"atl":[[13.5,0.26]],"id":47703807},{"atl":[[4.9,1.26]],"id":67487132},{"atl":[[5.1,0.26]],"id":70396461},{"atl":[[10,0.26]],"id":57697855}],"con":true,"img":false}]}
{"op":"mcm","clk":"11540948798","pt":1719500340500,"mc":[{"id":"1.230180122","rc":[{"atb":[[1.03,11.88]],"id":40028187},{"atb":[[1.03,165.21]],"id":43318163},{"atb":[[1.03,66.7]],"id":47703807},{"atb":[[3.35,3.4]],"id":67487132},{"atl":[[4.9,5.14]],"id":67487132}],"con":true,"img":false}]}
{"op":"mcm","clk":"11540948806","pt":1719500340605,"mc":[{"id":"1.230180122","rc":[{"atl":[[13.5,1.1]],"id":47703807}],"con":true,"img":false}]}
{"op":"mcm","clk":"11540948814","pt":1719500340707,"mc":[{"id":"1.230180122","rc":[{"atb":[[1.03,10.99]],"id":40028187},{"atb":[[1.03,164.23]],"id":43318163},{"atb":[[1.03,66.03]],"id":47703807}],"con":true,"img":false}]}
{"op":"mcm","clk":"11540948824","pt":1719500340812,"mc":[{"id":"1.230180122","rc":[{"atb":[[5.7,1.89]],"id":40028187},{"atb":[[5.2,8.52]],"id":43318163},{"atb":[[7.6,1.67]],"id":47703807}],"con":true,"img":false}]}
{"op":"mcm","clk":"11540948838","pt":1719500341018,"mc":[{"id":"1.230180122","rc":[{"atb":[[5.8,4.37]],"id":40028187}],"con":true,"img":false}]}
{"op":"mcm","clk":"11540948855","pt":1719500341224,"mc":[{"id":"1.230180122","rc":[{"atb":[[5.8,5.22]],"id":40028187},{"atl":[[4.8,0.84]],"id":67487132}],"con":true,"img":false}]}
{"op":"mcm","clk":"11540948866","pt":1719500341329,"mc":[{"id":"1.230180122","rc":[{"atb":[[5.8,10.32]],"id":40028187},{"atb":[[7.6,5.15]],"id":47703807},{"atb":[[3.4,11.1]],"id":67487132},{"atl":[[4.9,11.43]],"id":67487132}],"con":true,"img":false}]}
{"op":"mcm","clk":"11540948878","pt":1719500341432,"mc":[{"id":"1.230180122","rc":[{"atb":[[5.9,0.26]],"id":40028187},{"atb":[[5.4,0.26]],"id":43318163},{"atb":[[7.8,0.26]],"id":47703807},{"atb":[[3.6,0.26]],"id":67487132},{"atb":[[3.7,0.26]],"id":70396461},{"atb":[[3.85,0.26]],"id":57697855}],"con":true,"img":false}]}
{"op":"mcm","clk":"11540948887","pt":1719500341536,"mc":[{"id":"1.230180122","rc":[{"atb":[[5.7,0.89]],"id":40028187}],"con":true,"img":false}]}
{"op":"mcm","clk":"11540948896","pt":1719500341639,"mc":[{"id":"1.230180122","rc":[{"atb":[[5.9,1.26]],"id":40028187},{"atb":[[5.4,1.82],[5.2,6.92]],"id":43318163},{"atb":[[7.8,1.1]],"id":47703807}],"con":true,"img":false}]}
{"op":"mcm","clk":"11540948904","pt":1719500341747,"mc":[{"id":"1.230180122","rc":[{"atb":[[7.8,4.36]],"id":47703807},{"atl":[[4.8,6.13]],"id":67487132},{"atb":[[3.85,6.61]],"id":57697855}],"con":true,"img":false}]}
{"op":"mcm","clk":"11540948922","pt":1719500341949,"mc":[{"id":"1.230180122","rc":[{"atb":[[3.85,1]],"id":67487132},{"atb":[[3.85,7.61]],"id":57697855}],"con":true,"img":false}]}
{"op":"mcm","clk":"11540948931","pt":1719500342009,"mc":[{"id":"1.230180122","rc":[{"atb":[[5.3,0],[5,0]],"id":40028187},{"atb":[[6.8,0]],"id":47703807},{"atl":[[6.8,0]],"id":67487132}],"con":true,"img":false}]}
{"op":"mcm","clk":"11540948941","pt":1719500342117,"mc":[{"id":"1.230180122","rc":[{"atb":[[5.1,0],[5.5,0.84]],"id":43318163},{"atb":[[7.4,3.73]],"id":47703807},{"atl":[[5,5.64]],"id":67487132}],"con":true,"img":false}]}
{"op":"mcm","clk":"11540948951","pt":1719500342237,"mc":[{"id":"1.230180122","rc":[{"atb":[[5.9,6.58]],"id":40028187},{"atb":[[5.3,2.41],[5.4,7.84]],"id":43318163},{"atb":[[7.8,8.15]],"id":47703807},{"atl":[[4.8,13.4]],"id":67487132},{"atb":[[3.85,16.38]],"id":57697855}],"con":true,"img":false}]}
{"op":"mcm","clk":"11540948964","pt":1719500342324,"mc":[{"id":"1.230180122","rc":[{"atb":[[5.8,5.94]],"id":40028187}],"con":true,"img":false}]}
{"op":"mcm","clk":"11540948973","pt":1719500342420,"mc":[{"id":"1.230180122","rc":[{"atb":[[7.6,4.15]],"id":47703807}],"con":true,"img":false}]}
{"op":"mcm","clk":"11540948979","pt":1719500342522,"mc":[{"id":"1.230180122","rc":[{"atb":[[6,4.23]],"id":40028187},{"atb":[[5.5,7]],"id":43318163}],"con":true,"img":false}]}
{"op":"mcm","clk":"11540948983","pt":1719500342625,"mc":[{"id":"1.230180122","rc":[{"atb":[[5.4,6.28]],"id":43318163},{"atb":[[8,1]],"id":47703807}],"con":true,"img":false}]}
{"op":"mcm","clk":"11540949002","pt":1719500342936,"mc":[{"id":"1.230180122","rc":[{"atb":[[5.3,0.84]],"id":43318163}],"con":true,"img":false}]}
{"op":"mcm","clk":"11540949014","pt":1719500343045,"mc":[{"id":"1.230180122","rc":[{"atb":[[5.5,1.54]],"id":40028187}],"con":true,"img":false}]}
{"op":"mcm","clk":"11540949023","pt":1719500343148,"mc":[{"id":"1.230180122","rc":[{"atb":[[5.8,5.1],[6,9.01]],"id":40028187},{"atb":[[5.3,0],[5.5,12.58]],"id":43318163}],"con":true,"img":false}]}
{"op":"mcm","clk":"11540949042","pt":1719500343310,"mc":[{"id":"1.230180122","rc":[{"atb":[[5.9,5.58]],"id":40028187}],"con":true,"img":false}]}
{"op":"mcm","clk":"11540949050","pt":1719500343421,"mc":[{"id":"1.230180122","rc":[{"atb":[[7.8,4.89]],"id":47703807}],"con":true,"img":false}]}
{"op":"mcm","clk":"11540949069","pt":1719500343624,"mc":[{"id":"1.230180122","rc":[{"atb":[[6.2,1]],"id":40028187}],"con":true,"img":false}]}
{"op":"mcm","clk":"11540949087","pt":1719500343828,"mc":[{"id":"1.230180122","rc":[{"atl":[[4.9,10.43]],"id":67487132}],"con":true,"img":false}]}
{"op":"mcm","clk":"11540949097","pt":1719500343930,"mc":[{"id":"1.230180122","rc":[{"atl":[[4.7,1]],"id":67487132}],"con":true,"img":false}]}
{"op":"mcm","clk":"11540949104","pt":1719500344041,"mc":[{"id":"1.230180122","rc":[{"atb":[[3.45,3.27]],"id":67487132}],"con":true,"img":false}]}
{"op":"mcm","clk":"11540949115","pt":1719500344138,"mc":[{"id":"1.230180122","rc":[{"atl":[[5.1,0]],"id":67487132}],"con":true,"img":false}]}
{"op":"mcm","clk":"11540949123","pt":1719500344242,"mc":[{"id":"1.230180122","rc":[{"atb":[[6,4.78]],"id":40028187},{"atl":[[4.8,10.21],[4.9,6.55]],"id":67487132}],"con":true,"img":false}]}
{"op":"mcm","clk":"11540949129","pt":1719500344347,"mc":[{"id":"1.230180122","rc":[{"atl":[[4.7,2]],"id":67487132}],"con":true,"img":false}]}
{"op":"mcm","clk":"11540949165","pt":1719500344918,"mc":[{"id":"1.230180122","rc":[{"atl":[[5.2,0]],"id":67487132}],"con":true,"img":false}]}
{"op":"mcm","clk":"11540949224","pt":1719500345122,"mc":[{"id":"1.230180122","rc":[{"atb":[[3.5,11.14]],"id":67487132},{"atl":[[4.7,8.7]],"id":67487132}],"con":true,"img":false}]}
{"op":"mcm","clk":"11540949376","pt":1719500347035,"mc":[{"id":"1.230180122","rc":[{"atb":[[5,0]],"id":43318163},{"atl":[[7,0]],"id":67487132}],"con":true,"img":false}]}
{"op":"mcm","clk":"11540949384","pt":1719500347138,"mc":[{"id":"1.230180122","rc":[{"atb":[[5.6,1.41]],"id":43318163},{"atl":[[4.7,10.86]],"id":67487132},{"atb":[[3.9,1.41]],"id":57697855}],"con":true,"img":false}]}
{"op":"mcm","clk":"11540949393","pt":1719500347244,"mc":[{"id":"1.230180122","rc":[{"atl":[[13,0]],"id":43318163}],"con":true,"img":false}]}
{"op":"mcm","clk":"11540949419","pt":1719500347603,"mc":[{"id":"1.230180122","rc":[{"atb":[[3.25,13.33],[3.7,0]],"id":40028187},{"atb":[[3.6,0],[3.3,0],[3.65,14.44]],"id":57697855}],"con":true,"img":false}]}
{"op":"mcm","clk":"11540949425","pt":1719500347658,"mc":[{"id":"1.230180122","rc":[{"atb":[[5.6,6.55]],"id":43318163},{"atb":[[3.9,9.51]],"id":57697855}],"con":true,"img":false}]}
{"op":"mcm","clk":"11540949436","pt":1719500347760,"mc":[{"id":"1.230180122","rc":[{"atb":[[5.5,7.96]],"id":43318163},{"atb":[[3.85,10.03]],"id":57697855}],"con":true,"img":false}]}
{"op":"mcm","clk":"11540949446","pt":1719500347924,"mc":[{"id":"1.230180122","rc":[{"atb":[[5.7,4.45]],"id":43318163},{"atb":[[3.95,6.34]],"id":57697855}],"con":true,"img":false}]}
{"op":"mcm","clk":"11540949466","pt":1719500348225,"mc":[{"id":"1.230180122","rc":[{"atb":[[5.5,7.12]],"id":43318163},{"atl":[[4.6,0.84]],"id":67487132}],"con":true,"img":false}]}
{"op":"mcm","clk":"11540949471","pt":1719500348326,"mc":[{"id":"1.230180122","rc":[{"atb":[[5.2,0.98]],"id":43318163}],"con":true,"img":false}]}
{"op":"mcm","clk":"11540949479","pt":1719500348435,"mc":[{"id":"1.230180122","rc":[{"atb":[[5.7,9.26]],"id":43318163},{"atl":[[15,0.26]],"id":43318163},{"atb":[[3.95,15.09]],"id":57697855}],"con":true,"img":false}]}
{"op":"mcm","clk":"11540949525","pt":1719500349113,"mc":[{"id":"1.230180122","rc":[{"atb":[[5.8,0.84]],"id":43318163}],"con":true,"img":false}]}
{"op":"mcm","clk":"11540949534","pt":1719500349213,"mc":[{"id":"1.230180122","rc":[{"atl":[[15,0]],"id":43318163}],"con":true,"img":false}]}
{"op":"mcm","clk":"11540949626","pt":1719500350556,"mc":[{"id":"1.230180122","rc":[{"atl":[[14.5,4.36]],"id":57697855}],"con":true,"img":false}]}
{"op":"mcm","clk":"11540949646","pt":1719500350723,"mc":[{"id":"1.230180122","rc":[{"atl":[[19,0.26]],"id":43318163}],"con":true,"img":false}]}
{"op":"mcm","clk":"11540949685","pt":1719500351131,"mc":[{"id":"1.230180122","rc":[{"atl":[[14,1.83]],"id":57697855}],"con":true,"img":false}]}
{"op":"mcm","clk":"11540949692","pt":1719500351238,"mc":[{"id":"1.230180122","rc":[{"atl":[[13.5,2],[16.5,0]],"id":57697855}],"con":true,"img":false}]}
{"op":"mcm","clk":"11540949779","pt":1719500352061,"mc":[{"id":"1.230180122","rc":[{"atl":[[13,2.18]],"id":57697855}],"con":true,"img":false}]}
{"op":"mcm","clk":"11540949829","pt":1719500352426,"mc":[{"id":"1.230180122","rc":[{"atb":[[5.6,5.14]],"id":43318163},{"atb":[[3.9,8.1]],"id":57697855}],"con":true,"img":false}]}
{"op":"mcm","clk":"11540949836","pt":1719500352533,"mc":[{"id":"1.230180122","rc":[{"atb":[[5.8,2.25]],"id":43318163},{"atb":[[4,1.41]],"id":57697855}],"con":true,"img":false}]}
{"op":"mcm","clk":"11540949851","pt":1719500352736,"mc":[{"id":"1.230180122","rc":[{"atl":[[14.5,0]],"id":57697855}],"con":true,"img":false}]}
{"op":"mcm","clk":"11540949860","pt":1719500352841,"mc":[{"id":"1.230180122","rc":[{"atb":[[5.4,0.26]],"id":43318163}],"con":true,"img":false}]}
{"op":"mcm","clk":"11540949867","pt":1719500352942,"mc":[{"id":"1.230180122","rc":[{"atb":[[5.8,8.06]],"id":43318163}],"con":true,"img":false}]}
{"op":"mcm","clk":"11540949873","pt":1719500353049,"mc":[{"id":"1.230180122","rc":[{"atb":[[5.7,4.81]],"id":43318163},{"atb":[[3.95,8.75]],"id":57697855}],"con":true,"img":false}]}
{"op":"mcm","clk":"11540949886","pt":1719500353253,"mc":[{"id":"1.230180122","rc":[{"atb":[[5.9,4.3]],"id":43318163}],"con":true,"img":false}]}
{"op":"mcm","clk":"11540949920","pt":1719500353620,"mc":[{"id":"1.230180122","rc":[{"atb":[[5.5,1.54]],"id":43318163}],"con":true,"img":false}]}
{"op":"mcm","clk":"11540949929","pt":1719500353722,"mc":[{"id":"1.230180122","rc":[{"atl":[[15,0]],"id":57697855}],"con":true,"img":false}]}
{"op":"mcm","clk":"11540949939","pt":1719500353827,"mc":[{"id":"1.230180122","rc":[{"atb":[[5.9,9.12]],"id":43318163},{"atl":[[12.5,1]],"id":57697855}],"con":true,"img":false}]}
{"op":"mcm","clk":"11540950020","pt":1719500355167,"mc":[{"id":"1.230180122","rc":[{"atb":[[5.7,0]],"id":40028187},{"atb":[[5.2,0]],"id":43318163},{"atb":[[7.6,3.48]],"id":47703807}],"con":true,"img":false}]}
{"op":"mcm","clk":"11540950083","pt":1719500356149,"mc":[{"id":"1.230180122","rc":[{"atb":[[6,0.84]],"id":43318163}],"con":true,"img":false}]}
{"op":"mcm","clk":"11540950150","pt":1719500357037,"mc":[{"id":"1.230180122","rc":[{"atl":[[12,2],[13.5,0]],"id":57697855}],"con":true,"img":false}]}
{"op":"mcm","clk":"11540950198","pt":1719500357958,"mc":[{"id":"1.230180122","rc":[{"atl":[[11.5,2.34],[12.5,0]],"id":57697855}],"con":true,"img":false}]}
{"op":"mcm","clk":"11540950204","pt":1719500358060,"mc":[{"id":"1.230180122","rc":[{"atl":[[11.5,3.34]],"id":57697855}],"con":true,"img":false}]}
{"op":"mcm","clk":"11540950266","pt":1719500359045,"mc":[{"id":"1.230180122","rc":[{"atl":[[16,0]],"id":57697855}],"con":true,"img":false}]}
{"op":"mcm","clk":"11540950276","pt":1719500359143,"mc":[{"id":"1.230180122","rc":[{"atl":[[8,1.05]],"id":57697855}],"con":true,"img":false}]}
{"op":"mcm","clk":"11540950368","pt":1719500360346,"mc":[{"id":"1.230180122","rc":[{"atb":[[3.95,0],[3.9,7.89]],"id":57697855}],"con":true,"img":false}]}
{"op":"mcm","clk":"11540950384","pt":1719500360545,"mc":[{"id":"1.230180122","rc":[{"atb":[[3.25,14.71]],"id":70396461}],"con":true,"img":false}]}
{"op":"mcm","clk":"11540950509","pt":1719500362356,"mc":[{"id":"1.230180122","rc":[{"atl":[[4.2,2]],"id":57697855}],"con":true,"img":false}]}
{"op":"mcm","clk":"11540950518","pt":1719500362458,"mc":[{"id":"1.230180122","rc":[{"atl":[[4.2,0]],"id":57697855},{"trd":[[4.2,6]],"ltp":4.2,"tv":6.0,"id":57697855}],"con":true,"img":false}]}
{"op":"mcm","clk":"11540950525","pt":1719500362561,"mc":[{"id":"1.230180122","rc":[{"atl":[[15.5,1]],"id":47703807},{"atl":[[4.8,9.79],[4.7,4.16]],"id":67487132}],"con":true,"img":false}]}
{"op":"mcm","clk":"11540950533","pt":1719500362665,"mc":[{"id":"1.230180122","rc":[{"atl":[[16,1.77]],"id":47703807}],"con":true,"img":false}]}
{"op":"mcm","clk":"11540950547","pt":1719500362873,"mc":[{"id":"1.230180122","rc":[{"atl":[[9,2.06],[12,0]],"id":57697855}],"con":true,"img":false}]}
{"op":"mcm","clk":"11540950554","pt":1719500362984,"mc":[{"id":"1.230180122","rc":[{"atl":[[7.8,2.76]],"id":57697855}],"con":true,"img":false}]}
{"op":"mcm","clk":"11540950577","pt":1719500363135,"mc":[{"id":"1.230180122","rc":[{"atb":[[1.03,11.99]],"id":40028187},{"atb":[[1.03,165.23]],"id":43318163}],"con":true,"img":false}]}
{"op":"mcm","clk":"11540950589","pt":1719500363237,"mc":[{"id":"1.230180122","rc":[{"atb":[[3.7,16.78]],"id":57697855},{"atl":[[8.8,2.12]],"id":57697855}],"con":true,"img":false}]}
{"op":"mcm","clk":"11540950600","pt":1719500363343,"mc":[{"id":"1.230180122","rc":[{"atb":[[1.03,11.81]],"id":40028187},{"atb":[[1.03,165.09]],"id":43318163},{"atb":[[3.65,0]],"id":57697855},{"atl":[[9,0],[15.5,0]],"id":57697855}],"con":true,"img":false}]}
{"op":"mcm","clk":"11540950611","pt":1719500363448,"mc":[{"id":"1.230180122","rc":[{"atl":[[7.6,3.34]],"id":57697855}],"con":true,"img":false}]}
{"op":"mcm","clk":"11540950622","pt":1719500363551,"mc":[{"id":"1.230180122","rc":[{"atb":[[1.03,10.99]],"id":40028187},{"atb":[[1.03,164.23]],"id":43318163}],"con":true,"img":false}]}
{"op":"mcm","clk":"11540950631","pt":1719500363657,"mc":[{"id":"1.230180122","rc":[{"atb":[[6.2,1.82]],"id":40028187},{"atb":[[5.9,9.98]],"id":43318163},{"atl":[[7.6,4.19]],"id":57697855}],"con":true,"img":false}]}
{"op":"mcm","clk":"11540950640","pt":1719500363759,"mc":[{"id":"1.230180122","rc":[{"atl":[[4.7,11.1]],"id":67487132},{"atl":[[7.8,6.08]],"id":57697855}],"con":true,"img":false}]}
{"op":"mcm","clk":"11540950655","pt":1719500363965,"mc":[{"id":"1.230180122","rc":[{"atl":[[4.7,10.1]],"id":67487132}],"con":true,"img":false}]}
{"op":"mcm","clk":"11540950659","pt":1719500364070,"mc":[{"id":"1.230180122","rc":[{"atb":[[6.4,3.97]],"id":40028187},{"atl":[[11.5,2.34]],"id":57697855}],"con":true,"img":false}]}
{"op":"mcm","clk":"11540950664","pt":1719500364183,"mc":[{"id":"1.230180122","rc":[{"atb":[[6.4,4.81]],"id":40028187},{"atl":[[4.6,1.84]],"id":67487132},{"atl":[[7.4,1]],"id":57697855}],"con":true,"img":false}]}
{"op":"mcm","clk":"11540950673","pt":1719500364287,"mc":[{"id":"1.230180122","rc":[{"atb":[[5.6,0]],"id":40028187},{"atl":[[7.8,3.32],[14,0]],"id":57697855}],"con":true,"img":false}]}
{"op":"mcm","clk":"11540950684","pt":1719500364436,"mc":[{"id":"1.230180122","rc":[{"atb":[[6.4,9.93]],"id":40028187},{"atl":[[7.6,7.76]],"id":57697855}],"con":true,"img":false}]}
{"op":"mcm","clk":"11540950696","pt":1719500364647,"mc":[{"id":"1.230180122","rc":[{"atb":[[6.2,0.82]],"id":40028187},{"atl":[[4.8,8.95]],"id":67487132},{"atl":[[7.6,4.41],[4.2,2]],"id":57697855}],"con":true,"img":false}]}
{"op":"mcm","clk":"11540950706","pt":1719500364750,"mc":[{"id":"1.230180122","rc":[{"atl":[[4.2,0]],"id":57697855},{"trd":[[4.2,10]],"ltp":4.2,"tv":10.0,"id":57697855}],"con":true,"img":false}]}
{"op":"mcm","clk":"11540950715","pt":1719500364853,"mc":[{"id":"1.230180122","rc":[{"atb":[[6.6,1]],"id":40028187}],"con":true,"img":false}]}
{"op":"mcm","clk":"11540950731","pt":1719500365062,"mc":[{"id":"1.230180122","rc":[{"atl":[[4.7,9.1]],"id":67487132}],"con":true,"img":false}]}
{"op":"mcm","clk":"11540950740","pt":1719500365160,"mc":[{"id":"1.230180122","rc":[{"atl":[[4.5,1]],"id":67487132}],"con":true,"img":false}]}
{"op":"mcm","clk":"11540950747","pt":1719500365273,"mc":[{"id":"1.230180122","rc":[{"atb":[[6.4,5.96]],"id":40028187},{"atb":[[5.8,6.65],[6,2.25]],"id":43318163},{"atl":[[5.2,0.8]],"id":70396461}],"con":true,"img":false}]}
{"op":"mcm","clk":"11540950757","pt":1719500365367,"mc":[{"id":"1.230180122","rc":[{"atb":[[4,0]],"id":57697855}],"con":true,"img":false}]}
{"op":"mcm","clk":"11540950784","pt":1719500365783,"mc":[{"id":"1.230180122","rc":[{"atb":[[5.8,5.81]],"id":43318163},{"atb":[[3.95,0.84]],"id":57697855}],"con":true,"img":false}]}
{"op":"mcm","clk":"11540950794","pt":1719500365885,"mc":[{"id":"1.230180122","rc":[{"atb":[[5.9,5.68],[5.6,0]],"id":43318163},{"atl":[[5.3,8.17],[5.2,0.47]],"id":70396461}],"con":true,"img":false}]}
{"op":"mcm","clk":"11540950802","pt":1719500365940,"mc":[{"id":"1.230180122","rc":[{"atb":[[6,7.73]],"id":43318163}],"con":true,"img":false}]}
{"op":"mcm","clk":"11540950809","pt":1719500366047,"mc":[{"id":"1.230180122","rc":[{"atb":[[2.26,2]],"id":40028187},{"atb":[[6.2,4.09],[2.18,0]],"id":43318163},{"atb":[[2.28,0]],"id":67487132},{"atb":[[2.6,0]],"id":70396461},{"atl":[[5.2,5.36]],"id":70396461},{"atb":[[3.95,7.19]],"id":57697855}],"con":true,"img":false}]}
{"op":"mcm","clk":"11540950871","pt":1719500366663,"mc":[{"id":"1.230180122","rc":[{"atl":[[4.2,2]],"id":57697855}],"con":true,"img":false}]}
{"op":"mcm","clk":"11540950879","pt":1719500366776,"mc":[{"id":"1.230180122","rc":[{"atb":[[6.4,0.84],[5.7,0]],"id":43318163},{"atl":[[5.3,7.17],[5.9,0],[5.1,1.1]],"id":70396461},{"atl":[[4.2,0]],"id":57697855},{"trd":[[4.2,14]],"ltp":4.2,"tv":14.0,"id":57697855}],"con":true,"img":false}]}
{"op":"mcm","clk":"11540950890","pt":1719500366870,"mc":[{"id":"1.230180122","rc":[{"atb":[[6.2,8.96]],"id":43318163},{"atl":[[5.1,8.82]],"id":70396461}],"con":true,"img":false}]}
{"op":"mcm","clk":"11540950910","pt":1719500367083,"mc":[{"id":"1.230180122","rc":[{"atl":[[5.2,4.9]],"id":70396461}],"con":true,"img":false}]}
{"op":"mcm","clk":"11540950918","pt":1719500367191,"mc":[{"id":"1.230180122","rc":[{"atb":[[6.6,1.84]],"id":40028187},{"atb":[[6.4,1.69]],"id":43318163},{"atb":[[8,1.84]],"id":47703807},{"atb":[[3.55,0.84]],"id":67487132},{"atb":[[3.3,0.84]],"id":70396461},{"atl":[[5,0.45],[5.2,0.02]],"id":70396461},{"atb":[[4,0.84]],"id":57697855}],"con":true,"img":false}]}
{"op":"mcm","clk":"11540950928","pt":1719500367237,"mc":[{"id":"1.230180122","rc":[{"atl":[[5.3,6.33]],"id":70396461}],"con":true,"img":false}]}
{"op":"mcm","clk":"11540950937","pt":1719500367343,"mc":[{"id":"1.230180122","rc":[{"atb":[[8.2,3.09]],"id":47703807}],"con":true,"img":false}]}
{"op":"mcm","clk":"11540950948","pt":1719500367443,"mc":[{"id":"1.230180122","rc":[{"atb":[[5.8,0]],"id":40028187},{"atb":[[5.8,0]],"id":43318163},{"atb":[[7.2,1.17]],"id":47703807}],"con":true,"img":false}]}
{"op":"mcm","clk":"11540950965","pt":1719500367648,"mc":[{"id":"1.230180122","rc":[{"atb":[[6.6,6.38]],"id":40028187},{"atb":[[6.4,6.29]],"id":43318163},{"atb":[[8.2,6.16]],"id":47703807}],"con":true,"img":false}]}
{"op":"mcm","clk":"11540950972","pt":1719500367756,"mc":[{"id":"1.230180122","rc":[{"atb":[[6,6.89]],"id":43318163},{"atb":[[7.8,4.05],[8.4,0.84]],"id":47703807}],"con":true,"img":false}]}
{"op":"mcm","clk":"11540950981","pt":1719500367854,"mc":[{"id":"1.230180122","rc":[{"atb":[[8,0.84]],"id":47703807}],"con":true,"img":false}]}
{"op":"mcm","clk":"11540950989","pt":1719500367959,"mc":[{"id":"1.230180122","rc":[{"atb":[[6.2,4.87]],"id":43318163},{"atb":[[8.4,1.84]],"id":47703807}],"con":true,"img":false}]}
{"op":"mcm","clk":"11540950998","pt":1719500368067,"mc":[{"id":"1.230180122","rc":[{"atl":[[5.1,7.82]],"id":70396461}],"con":true,"img":false}]}
{"op":"mcm","clk":"11540951009","pt":1719500368166,"mc":[{"id":"1.230180122","rc":[{"atb":[[6.8,3.73]],"id":40028187},{"atb":[[6.6,3.85]],"id":43318163},{"atl":[[5.2,1.02]],"id":70396461}],"con":true,"img":false}]}
{"op":"mcm","clk":"11540951018","pt":1719500368275,"mc":[{"id":"1.230180122","rc":[{"atb":[[5.9,0.26]],"id":40028187},{"atb":[[4.3,0],[5.9,0.86],[3.75,10.58]],"id":43318163},{"atb":[[7.4,0]],"id":47703807},{"atl":[[16.5,0],[18,4]],"id":47703807},{"atl":[[8.6,2.12],[8.8,0]],"id":57697855}],"con":true,"img":false}]}
{"op":"mcm","clk":"11540951040","pt":1719500368476,"mc":[{"id":"1.230180122","rc":[{"atb":[[6.8,8.18]],"id":40028187},{"atb":[[6.6,8.29]],"id":43318163},{"atb":[[8.4,5.5]],"id":47703807}],"con":true,"img":false}]}
{"op":"mcm","clk":"11540951045","pt":1719500368582,"mc":[{"id":"1.230180122","rc":[{"atb":[[6.6,4.81]],"id":40028187},{"atb":[[6.4,5.72]],"id":43318163},{"atb":[[8,0.27]],"id":47703807},{"atb":[[3.55,0.25]],"id":67487132},{"atb":[[3.3,0.26]],"id":70396461},{"atb":[[4,0.27]],"id":57697855}],"con":true,"img":false}]}
{"op":"mcm","clk":"11540951050","pt":1719500368640,"mc":[{"id":"1.230180122","rc":[{"atb":[[6.4,5.12]],"id":40028187}],"con":true,"img":false}]}
{"op":"mcm","clk":"11540951055","pt":1719500368787,"mc":[{"id":"1.230180122","rc":[{"atb":[[8.2,3.07]],"id":47703807}],"con":true,"img":false}]}
{"op":"mcm","clk":"11540951062","pt":1719500368945,"mc":[{"id":"1.230180122","rc":[{"atb":[[7,1]],"id":40028187},{"atl":[[4.2,2]],"id":57697855}],"con":true,"img":false}]}
{"op":"mcm","clk":"11540951074","pt":1719500369053,"mc":[{"id":"1.230180122","rc":[{"atb":[[8.6,2.95]],"id":47703807},{"atl":[[5,5.53]],"id":70396461}],"con":true,"img":false}]}
{"op":"mcm","clk":"11540951078","pt":1719500369096,"mc":[{"id":"1.230180122","rc":[{"atl":[[4.8,8.26],[4.7,2.16]],"id":67487132},{"atl":[[5.2,0.02]],"id":70396461},{"atl":[[4.2,0]],"id":57697855},{"trd":[[4.2,18]],"ltp":4.2,"tv":18.0,"id":57697855}],"con":true,"img":false}]}
{"op":"mcm","clk":"11540951087","pt":1719500369156,"mc":[{"id":"1.230180122","rc":[{"atl":[[5,6.53]],"id":70396461},{"atl":[[4.5,4.69],[7.6,3.57]],"id":57697855}],"con":true,"img":false}]}
{"op":"mcm","clk":"11540951095","pt":1719500369255,"mc":[{"id":"1.230180122","rc":[{"atb":[[7,2.62]],"id":40028187},{"atb":[[6.8,1.65]],"id":43318163},{"atb":[[3.55,2.02]],"id":67487132},{"atl":[[4.6,0.84]],"id":67487132},{"atb":[[3.3,1.93]],"id":70396461},{"atb":[[4,2.04]],"id":57697855},{"atl":[[4.5,0]],"id":57697855},{"trd":[[4.5,9.38]],"ltp":4.5,"tv":9.38,"id":57697855}],"con":true,"img":false}]}
{"op":"mcm","clk":"11540951109","pt":1719500369465,"mc":[{"id":"1.230180122","rc":[{"atl":[[4.7,3.16]],"id":67487132}],"con":true,"img":false}]}
{"op":"mcm","clk":"11540951128","pt":1719500369670,"mc":[{"id":"1.230180122","rc":[{"atb":[[6.8,4.45],[6.6,4.54]],"id":40028187},{"atb":[[6.4,5.44],[6.6,4.44]],"id":43318163},{"atb":[[8,0]],"id":47703807},{"atb":[[3.95,0.84]],"id":57697855}],"con":true,"img":false}]}
{"op":"mcm","clk":"11540951138","pt":1719500369778,"mc":[{"id":"1.230180122","rc":[{"atb":[[7,2.9]],"id":40028187},{"atb":[[6.8,1.93]],"id":43318163},{"atb":[[8.6,3.23]],"id":47703807}],"con":true,"img":false}]}
{"op":"mcm","clk":"11540951148","pt":1719500369883,"mc":[{"id":"1.230180122","rc":[{"atb":[[7.2,3.53]],"id":40028187},{"atb":[[6,1.41]],"id":43318163},{"atb":[[7.6,0]],"id":47703807},{"atb":[[3.2,0]],"id":67487132},{"atb":[[2.92,0]],"id":70396461},{"atl":[[5.6,0]],"id":70396461},{"atb":[[4,0.27]],"id":57697855}],"con":true,"img":false}]}
{"op":"mcm","clk":"11540951157","pt":1719500369985,"mc":[{"id":"1.230180122","rc":[{"atb":[[6.8,5.79]],"id":43318163},{"atb":[[8.6,6.81]],"id":47703807},{"atb":[[3.6,10.37]],"id":67487132},{"atl":[[4.6,7.42]],"id":67487132},{"atb":[[3.35,11.77]],"id":70396461},{"atl":[[5,12.07]],"id":70396461},{"atb":[[3.95,2.6]],"id":57697855}],"con":true,"img":false}]}
{"op":"mcm","clk":"11540951165","pt":1719500370091,"mc":[{"id":"1.230180122","rc":[{"atl":[[4.5,0]],"id":67487132}],"con":true,"img":false}]}
{"op":"mcm","clk":"11540951174","pt":1719500370190,"mc":[{"id":"1.230180122","rc":[{"atb":[[6.4,4.6]],"id":43318163},{"atb":[[8.4,4.5]],"id":47703807},{"atl":[[4.6,8.42]],"id":67487132}],"con":true,"img":false}]}
{"op":"mcm","clk":"11540951192","pt":1719500370350,"mc":[{"id":"1.230180122","rc":[{"atl":[[4.7,2.16]],"id":67487132},{"atb":[[3.2,0]],"id":70396461}],"con":true,"img":false}]}
{"op":"mcm","clk":"11540951201","pt":1719500370480,"mc":[{"id":"1.230180122","rc":[{"atb":[[7,1.27]],"id":40028187},{"atb":[[7,3.63]],"id":43318163},{"atb":[[8.8,2.69]],"id":47703807},{"atb":[[3.55,0.25]],"id":67487132},{"atb":[[3.3,0.26]],"id":70396461},{"atb":[[4,6.62]],"id":57697855}],"con":true,"img":false}]}
{"op":"mcm","clk":"11540951209","pt":1719500370551,"mc":[{"id":"1.230180122","rc":[{"atb":[[7.4,1.62]],"id":40028187},{"atb":[[3.65,1.76]],"id":67487132},{"atl":[[4.5,1]],"id":67487132},{"atb":[[3.4,1.67]],"id":70396461},{"atb":[[3.75,24.66]],"id":57697855}],"con":true,"img":false}]}
{"op":"mcm","clk":"11540951215","pt":1719500370656,"mc":[{"id":"1.230180122","rc":[{"atl":[[4.2,2]],"id":57697855}],"con":true,"img":false}]}
{"op":"mcm","clk":"11540951223","pt":1719500370764,"mc":[{"id":"1.230180122","rc":[{"atb":[[3.75,19.66]],"id":57697855},{"atl":[[4.2,0]],"id":57697855},{"trd":[[4.2,22]],"ltp":4.2,"tv":22.0,"id":57697855}],"con":true,"img":false}]}
{"op":"mcm","clk":"11540951228","pt":1719500370870,"mc":[{"id":"1.230180122","rc":[{"atb":[[6,0]],"id":40028187},{"atb":[[6.2,0]],"id":43318163},{"atb":[[7.8,0.26]],"id":47703807},{"atl":[[4.6,1.84]],"id":67487132}],"con":true,"img":false}]}
{"op":"mcm","clk":"11540951234","pt":1719500370971,"mc":[{"id":"1.230180122","rc":[{"atb":[[7,1]],"id":40028187},{"atb":[[6.8,5.51]],"id":43318163},{"atb":[[8.6,6.53]],"id":47703807},{"atb":[[3.55,0]],"id":67487132},{"atb":[[3.3,0]],"id":70396461}],"con":true,"img":false}]}
{"op":"mcm","clk":"11540951241","pt":1719500371072,"mc":[{"id":"1.230180122","rc":[{"atb":[[7.4,1.9],[7.2,4.07]],"id":40028187},{"atb":[[6.8,3.86],[7.2,0.27],[7,7.59]],"id":43318163},{"atb":[[8.6,3.58],[8.8,4.18]],"id":47703807},{"atb":[[3.65,2.02]],"id":67487132},{"atl":[[4.5,0],[4.7,8.28]],"id":67487132},{"atb":[[3.4,1.93]],"id":70396461},{"atb":[[3.95,0.84]],"id":57697855}],"con":true,"img":false}]}
{"op":"mcm","clk":"11540951246","pt":1719500371176,"mc":[{"id":"1.230180122","rc":[{"atb":[[7.2,1.93]],"id":43318163},{"atb":[[4.1,1.76]],"id":57697855}],"con":true,"img":false}]}
{"op":"mcm","clk":"11540951254","pt":1719500371278,"mc":[{"id":"1.230180122","rc":[{"atb":[[9,2.81],[8.4,3.66]],"id":47703807}],"con":true,"img":false}]}
{"op":"mcm","clk":"11540951260","pt":1719500371385,"mc":[{"id":"1.230180122","rc":[{"atl":[[4.6,2.84]],"id":67487132}],"con":true,"img":false}]}
{"op":"mcm","clk":"11540951281","pt":1719500371649,"mc":[{"id":"1.230180122","rc":[{"atb":[[6.4,0],[7.6,0.84]],"id":40028187},{"atb":[[6.4,0]],"id":43318163},{"atb":[[8.2,0]],"id":47703807},{"atb":[[3.3,0]],"id":67487132},{"atl":[[5,0]],"id":67487132},{"atb":[[2.96,0]],"id":70396461},{"atb":[[3.95,0]],"id":57697855}],"con":true,"img":false}]}
{"op":"mcm","clk":"11540951295","pt":1719500371860,"mc":[{"id":"1.230180122","rc":[{"atb":[[7.4,5.4]],"id":40028187},{"atb":[[7.2,5.72],[7,3.96]],"id":43318163},{"atb":[[9,5.79]],"id":47703807},{"atb":[[3.7,9.16]],"id":67487132},{"atl":[[4.6,10.12]],"id":67487132},{"atb":[[3.45,10.14]],"id":70396461},{"atb":[[4,0.27]],"id":57697855}],"con":true,"img":false}]}
{"op":"mcm","clk":"11540951304","pt":1719500371961,"mc":[{"id":"1.230180122","rc":[{"atl":[[1000,0.78]],"id":67487132},{"atb":[[2.64,7.22]],"id":70396461}],"con":true,"img":false}]}
{"op":"mcm","clk":"11540951311","pt":1719500372065,"mc":[{"id":"1.230180122","rc":[{"atb":[[7.6,4.19],[7,0]],"id":40028187},{"atb":[[7.4,3.42]],"id":43318163},{"atb":[[8.8,3.18]],"id":47703807},{"atb":[[2.32,8.97]],"id":67487132}],"con":true,"img":false}]}
{"op":"mcm","clk":"11540951334","pt":1719500372276,"mc":[{"id":"1.230180122","rc":[{"atb":[[7.4,3.77],[7.8,1]],"id":40028187},{"atb":[[7.2,4.06]],"id":43318163},{"atb":[[9.2,1],[8.8,2.91]],"id":47703807},{"atb":[[3.65,0]],"id":67487132},{"atb":[[3.4,0]],"id":70396461},{"atb":[[4,0],[4.1,0]],"id":57697855}],"con":true,"img":false}]}
{"op":"mcm","clk":"11540951343","pt":1719500372380,"mc":[{"id":"1.230180122","rc":[{"atb":[[3.35,7.03],[7.8,2.62]],"id":40028187},{"atb":[[7.6,1.65],[6.6,0]],"id":43318163},{"atb":[[9.2,1.27]],"id":47703807},{"atb":[[3.75,2.02]],"id":67487132},{"atl":[[1000,0.67]],"id":67487132},{"atb":[[3.5,1.93]],"id":70396461},{"atb":[[3.95,2.04]],"id":57697855}],"con":true,"img":false}]}
{"op":"mcm","clk":"11540951352","pt":1719500372482,"mc":[{"id":"1.230180122","rc":[{"atb":[[7.4,7.14]],"id":43318163}],"con":true,"img":false}]}
{"op":"mcm","clk":"11540951371","pt":1719500372691,"mc":[{"id":"1.230180122","rc":[{"atb":[[7.6,0.84]],"id":40028187},{"atb":[[7.4,3.72]],"id":43318163},{"atb":[[9,2.98]],"id":47703807}],"con":true,"img":false}]}
{"op":"mcm","clk":"11540951382","pt":1719500372792,"mc":[{"id":"1.230180122","rc":[{"atl":[[1000,0]],"id":67487132},{"atb":[[4,0.84]],"id":57697855}],"con":true,"img":false}]}
{"op":"mcm","clk":"11540951392","pt":1719500372848,"mc":[{"id":"1.230180122","rc":[{"atb":[[7.8,1]],"id":40028187},{"atl":[[5.7,0.67]],"id":67487132},{"atb":[[4,7.19]],"id":57697855}],"con":true,"img":false}]}
{"op":"mcm","clk":"11540951398","pt":1719500372945,"mc":[{"id":"1.230180122","rc":[{"atb":[[7.6,2.47]],"id":40028187}],"con":true,"img":false}]}
{"op":"mcm","clk":"11540951405","pt":1719500373056,"mc":[{"id":"1.230180122","rc":[{"atb":[[6.8,0]],"id":43318163},{"atb":[[3,0]],"id":70396461}],"con":true,"img":false}]}
{"op":"mcm","clk":"11540951437","pt":1719500373356,"mc":[{"id":"1.230180122","rc":[{"atb":[[7.6,5.88]],"id":43318163},{"atb":[[3.55,10.33]],"id":70396461}],"con":true,"img":false}]}
{"op":"mcm","clk":"11540951443","pt":1719500373464,"mc":[{"id":"1.230180122","rc":[{"atb":[[7.4,3.5]],"id":40028187},{"atb":[[7.2,3.79]],"id":43318163},{"atb":[[9.2,1]],"id":47703807},{"atb":[[3.95,1.76]],"id":57697855}],"con":true,"img":false}]}
{"op":"mcm","clk":"11540951454","pt":1719500373572,"mc":[{"id":"1.230180122","rc":[{"atb":[[2.82,13.33],[3.25,0],[7.6,2.75]],"id":40028187},{"atb":[[3.75,0],[7.6,6.16],[3.4,10.58]],"id":43318163},{"atl":[[11,0],[12,1]],"id":43318163},{"atb":[[1.13,0.27]],"id":47703807},{"atb":[[3.55,15.78],[4.1,0.27],[3.7,1]],"id":57697855},{"atl":[[8.4,2.12],[8.6,0]],"id":57697855}],"con":true,"img":false}]}
{"op":"mcm","clk":"11540951462","pt":1719500373671,"mc":[{"id":"1.230180122","rc":[{"atl":[[65,0]],"id":43318163},{"atl":[[4.2,2]],"id":57697855}],"con":true,"img":false}]}
{"op":"mcm","clk":"11540951469","pt":1719500373780,"mc":[{"id":"1.230180122","rc":[{"atb":[[7.8,0.84]],"id":43318163},{"atl":[[19,2.26]],"id":43318163},{"atl":[[4.9,0.84]],"id":70396461},{"atl":[[4.2,0]],"id":57697855},{"trd":[[4.2,26]],"ltp":4.2,"tv":26.0,"id":57697855}],"con":true,"img":false}]}
{"op":"mcm","clk":"11540951478","pt":1719500373879,"mc":[{"id":"1.230180122","rc":[{"atb":[[7.4,0],[7.8,4.1],[7.2,0],[7.6,1.93],[7,0]],"id":43318163},{"atl":[[19,0.26],[55,2]],"id":43318163}],"con":true,"img":false}]}
{"op":"mcm","clk":"11540951498","pt":1719500374081,"mc":[{"id":"1.230180122","rc":[{"atb":[[6.2,5.33],[7.6,0.27]],"id":43318163},{"atb":[[3.5,0.26]],"id":70396461},{"atl":[[1000,0.69]],"id":57697855}],"con":true,"img":false}]}
{"op":"mcm","clk":"11540951505","pt":1719500374185,"mc":[{"id":"1.230180122","rc":[{"atl":[[60,0.44]],"id":43318163},{"atb":[[3.6,1.67]],"id":70396461},{"atl":[[1000,0]],"id":57697855}],"con":true,"img":false}]}
{"op":"mcm","clk":"11540951515","pt":1719500374293,"mc":[{"id":"1.230180122","rc":[{"atl":[[50,1]],"id":43318163},{"atl":[[7.4,1.69]],"id":57697855}],"con":true,"img":false}]}
{"op":"mcm","clk":"11540951539","pt":1719500374449,"mc":[{"id":"1.230180122","rc":[{"atb":[[7.8,0.84]],"id":43318163}],"con":true,"img":false}]}
{"op":"mcm","clk":"11540951556","pt":1719500374657,"mc":[{"id":"1.230180122","rc":[{"atb":[[6.4,1.65],[7.6,0]],"id":43318163},{"atb":[[3.5,0]],"id":70396461}],"con":true,"img":false}]}
{"op":"mcm","clk":"11540951565","pt":1719500374766,"mc":[{"id":"1.230180122","rc":[{"atb":[[6.4,1.93]],"id":43318163},{"atb":[[3.6,1.93],[3.25,2.31]],"id":70396461},{"atl":[[13,0],[7.2,0.84]],"id":57697855}],"con":true,"img":false}]}
{"op":"mcm","clk":"11540951573","pt":1719500374863,"mc":[{"id":"1.230180122","rc":[{"atl":[[50,1.46]],"id":43318163},{"atb":[[3.65,9.82]],"id":70396461},{"atl":[[7.4,5.43]],"id":57697855}],"con":true,"img":false}]}
{"op":"mcm","clk":"11540951590","pt":1719500375070,"mc":[{"id":"1.230180122","rc":[{"atb":[[6.6,3.85]],"id":43318163},{"atl":[[1000,0.59]],"id":43318163},{"atl":[[7.2,5.34],[17,0]],"id":57697855}],"con":true,"img":false}]}
{"op":"mcm","clk":"11540951599","pt":1719500375172,"mc":[{"id":"1.230180122","rc":[{"atb":[[7.8,0]],"id":43318163}],"con":true,"img":false}]}
{"op":"mcm","clk":"11540951606","pt":1719500375274,"mc":[{"id":"1.230180122","rc":[{"atb":[[6.4,0.27]],"id":43318163},{"atl":[[1000,0.17]],"id":43318163},{"atb":[[3.6,0.26]],"id":70396461}],"con":true,"img":false}]}
