{"op":"mcm","clk":"11536380658","pt":1719425245601,"mc":[{"id":"1.230178324","marketDefinition":{"bspMarket":true,"turnInPlayEnabled":false,"persistenceEnabled":false,"marketBaseRate":5.0,"eventId":"33376062","eventTypeId":"4339","numberOfWinners":1,"bettingType":"ODDS","marketType":"WIN","marketTime":"2024-06-27T16:24:00.000Z","suspendTime":"2024-06-27T16:24:00.000Z","bspReconciled":false,"complete":true,"inPlay":false,"crossMatching":false,"runnersVoidable":false,"numberOfActiveRunners":6,"betDelay":0,"status":"OPEN","runners":[{"status":"ACTIVE","sortPriority":1,"id":69769647,"name":"1. Teebay"},{"status":"ACTIVE","sortPriority":2,"id":63579394,"name":"2. Apple Jam"},{"status":"ACTIVE","sortPriority":3,"id":40626946,"name":"3. Jaxleg Swift"},{"status":"ACTIVE","sortPriority":4,"id":45129701,"name":"4. Darkies Dream"},{"status":"ACTIVE","sortPriority":5,"id":70902602,"name":"5. Jamaica Joel"},{"status":"ACTIVE","sortPriority":6,"id":57055802,"name":"6. Songful Bird"}],"regulators":["MR_INT"],"venue":"Kinsley","countryCode":"GB","discountAllowed":false,"timezone":"Europe/London","openDate":"2024-06-27T13:36:00.000Z","version":5994643785,"name":"D5 268m","eventName":"Kinsley 27th Jun"},"rc":[],"con":true,"img":false}]}
{"op":"mcm","clk":"11536381028","pt":1719425248531,"mc":[{"id":"1.230178324","marketDefinition":{"bspMarket":true,"turnInPlayEnabled":false,"persistenceEnabled":false,"marketBaseRate":5.0,"eventId":"33376062","eventTypeId":"4339","numberOfWinners":1,"bettingType":"ODDS","marketType":"WIN","marketTime":"2024-06-27T16:24:00.000Z","suspendTime":"2024-06-27T16:24:00.000Z","bspReconciled":false,"complete":true,"inPlay":false,"crossMatching":false,"runnersVoidable":false,"numberOfActiveRunners":6,"betDelay":0,"status":"OPEN","runners":[{"status":"ACTIVE","sortPriority":1,"id":69769647,"name":"1. Teebay"},{"status":"ACTIVE","sortPriority":2,"id":63579394,"name":"2. Apple Jam"},{"status":"ACTIVE","sortPriority":3,"id":40626946,"name":"3. Jaxleg Swift"},{"status":"ACTIVE","sortPriority":4,"id":45129701,"name":"4. Darkies Dream"},{"status":"ACTIVE","sortPriority":5,"id":70902602,"name":"5. Jamaica Joel"},{"status":"ACTIVE","sortPriority":6,"id":57055802,"name":"6. Songful Bird"}],"regulators":["MR_INT"],"venue":"Kinsley","countryCode":"GB","discountAllowed":true,"timezone":"Europe/London","openDate":"2024-06-27T13:36:00.000Z","version":5994643785,"name":"D5 268m","eventName":"Kinsley 27th Jun"},"rc":[],"con":true,"img":false}]}
{"op":"mcm","clk":"11536614467","pt":1719428234804,"mc":[{"id":"1.230178324","rc":[{"atb":[[1.01,23.65]],"id":70902602},{"atl":[[990,0.84]],"id":70902602},{"spn":495.5,"spf":"NaN","id":70902602},{"atb":[[1.02,11.82]],"id":63579394},{"atl":[[990,0.84]],"id":63579394},{"spn":495.51,"spf":"NaN","id":63579394},{"atb":[[1.02,11.82]],"id":69769647},{"atl":[[990,0.84]],"id":69769647},{"spn":495.51,"spf":"NaN","id":69769647},{"atb":[[1.01,23.65]],"id":57055802},{"atl":[[990,0.84]],"id":57055802},{"spn":495.5,"spf":"NaN","id":57055802},{"atb":[[1.01,23.65]],"id":40626946},{"atl":[[1000,0.84]],"id":40626946},{"spn":500.5,"spf":"NaN","id":40626946},{"atb":[[1.01,23.65]],"id":45129701},{"atl":[[990,0.84]],"id":45129701},{"spn":495.5,"spf":"NaN","id":45129701}],"con":true,"img":false}]}
{"op":"mcm","clk":"11536836566","pt":1719431844920,"mc":[{"id":"1.230178324","rc":[{"atb":[[1.01,23.66]],"id":70902602},{"atl":[[990,0.22]],"id":70902602},{"atb":[[1.02,11.82]],"id":63579394},{"atl":[[990,0.22]],"id":63579394},{"atb":[[1.02,11.82]],"id":69769647},{"atl":[[990,0.22]],"id":69769647},{"atb":[[1.01,23.66]],"id":57055802},{"atl":[[990,0.22]],"id":57055802},{"atb":[[1.01,23.66]],"id":40626946},{"atl":[[1000,0.22]],"id":40626946},{"atb":[[1.01,23.66]],"id":45129701},{"atl":[[990,0.22]],"id":45129701}],"con":true,"img":false}]}
{"op":"mcm","clk":"11537232271","pt":1719437882523,"mc":[{"id":"1.230178324","marketDefinition":{"bspMarket":true,"turnInPlayEnabled":false,"persistenceEnabled":false,"marketBaseRate":5.0,"eventId":"33376062","eventTypeId":"4339","numberOfWinners":1,"bettingType":"ODDS","marketType":"WIN","marketTime":"2024-06-27T16:24:00.000Z","suspendTime":"2024-06-27T16:24:00.000Z","bspReconciled":false,"complete":true,"inPlay":false,"crossMatching":false,"runnersVoidable":false,"numberOfActiveRunners":6,"betDelay":0,"status":"OPEN","runners":[{"status":"ACTIVE","sortPriority":1,"id":69769647,"name":"1. Teebay"},{"status":"ACTIVE","sortPriority":2,"id":63579394,"name":"2. Apple Jam"},{"status":"ACTIVE","sortPriority":3,"id":40626946,"name":"3. Jaxleg Swift"},{"status":"ACTIVE","sortPriority":4,"id":45129701,"name":"4. Darkies Dream"},{"status":"ACTIVE","sortPriority":5,"id":70902602,"name":"5. Jamaica Joel"},{"status":"ACTIVE","sortPriority":6,"id":57055802,"name":"6. Songful Bird"}],"regulators":["MR_INT"],"venue":"Kinsley","countryCode":"GB","discountAllowed":true,"timezone":"Europe/London","openDate":"2024-06-27T13:36:00.000Z","version":5994643785,"name":"D5 268m","eventName":"Kinsley 27th Jun"},"rc":[{"atb":[[1.01,23.66]],"id":70902602},{"atl":[[990,0.22]],"id":70902602},{"spn":495.5,"spf":"NaN","id":70902602},{"atb":[[1.02,11.82]],"id":63579394},{"atl":[[990,0.22]],"id":63579394},{"spn":495.51,"spf":"NaN","id":63579394},{"atb":[[1.02,11.82]],"id":69769647},{"atl":[[990,0.22]],"id":69769647},{"spn":495.51,"spf":"NaN","id":69769647},{"atb":[[1.01,23.66]],"id":57055802},{"atl":[[990,0.22]],"id":57055802},{"spn":495.5,"spf":"NaN","id":57055802},{"atb":[[1.01,23.66]],"id":40626946},{"atl":[[1000,0.22]],"id":40626946},{"spn":500.5,"spf":"NaN","id":40626946},{"atb":[[1.01,23.66]],"id":45129701},{"atl":[[990,0.22]],"id":45129701},{"spn":495.5,"spf":"NaN","id":45129701}],"con":true,"img":true}]}
{"op":"mcm","clk":"11537573398","pt":1719443282541,"mc":[{"id":"1.230178324","marketDefinition":{"bspMarket":true,"turnInPlayEnabled":false,"persistenceEnabled":false,"marketBaseRate":5.0,"eventId":"33376062","eventTypeId":"4339","numberOfWinners":1,"bettingType":"ODDS","marketType":"WIN","marketTime":"2024-06-27T16:24:00.000Z","suspendTime":"2024-06-27T16:24:00.000Z","bspReconciled":false,"complete":true,"inPlay":false,"crossMatching":false,"runnersVoidable":false,"numberOfActiveRunners":6,"betDelay":0,"status":"OPEN","runners":[{"status":"ACTIVE","sortPriority":1,"id":69769647,"name":"1. Teebay"},{"status":"ACTIVE","sortPriority":2,"id":63579394,"name":"2. Apple Jam"},{"status":"ACTIVE","sortPriority":3,"id":40626946,"name":"3. Jaxleg Swift"},{"status":"ACTIVE","sortPriority":4,"id":45129701,"name":"4. Darkies Dream"},{"status":"ACTIVE","sortPriority":5,"id":70902602,"name":"5. Jamaica Joel"},{"status":"ACTIVE","sortPriority":6,"id":57055802,"name":"6. Songful Bird"}],"regulators":["MR_INT"],"venue":"Kinsley","countryCode":"GB","discountAllowed":true,"timezone":"Europe/London","openDate":"2024-06-27T13:36:00.000Z","version":5994643785,"name":"D5 268m","eventName":"Kinsley 27th Jun"},"rc":[{"atb":[[1.01,23.66]],"id":70902602},{"atl":[[990,0.22]],"id":70902602},{"spn":495.5,"spf":"NaN","id":70902602},{"atb":[[1.02,11.83]],"id":63579394},{"atl":[[990,0.22]],"id":63579394},{"spn":495.51,"spf":"NaN","id":63579394},{"atb":[[1.02,11.83]],"id":69769647},{"atl":[[990,0.22]],"id":69769647},{"spn":495.51,"spf":"NaN","id":69769647},{"atb":[[1.01,23.66]],"id":57055802},{"atl":[[990,0.22]],"id":57055802},{"spn":495.5,"spf":"NaN","id":57055802},{"atb":[[1.01,23.66]],"id":40626946},{"atl":[[1000,0.22]],"id":40626946},{"spn":500.5,"spf":"NaN","id":40626946},{"atb":[[1.01,23.66]],"id":45129701},{"atl":[[990,0.22]],"id":45129701},{"spn":495.5,"spf":"NaN","id":45129701}],"con":true,"img":true}]}
{"op":"mcm","clk":"11537954958","pt":1719448682566,"mc":[{"id":"1.230178324","marketDefinition":{"bspMarket":true,"turnInPlayEnabled":false,"persistenceEnabled":false,"marketBaseRate":5.0,"eventId":"33376062","eventTypeId":"4339","numberOfWinners":1,"bettingType":"ODDS","marketType":"WIN","marketTime":"2024-06-27T16:24:00.000Z","suspendTime":"2024-06-27T16:24:00.000Z","bspReconciled":false,"complete":true,"inPlay":false,"crossMatching":false,"runnersVoidable":false,"numberOfActiveRunners":6,"betDelay":0,"status":"OPEN","runners":[{"status":"ACTIVE","sortPriority":1,"id":69769647,"name":"1. Teebay"},{"status":"ACTIVE","sortPriority":2,"id":63579394,"name":"2. Apple Jam"},{"status":"ACTIVE","sortPriority":3,"id":40626946,"name":"3. Jaxleg Swift"},{"status":"ACTIVE","sortPriority":4,"id":45129701,"name":"4. Darkies Dream"},{"status":"ACTIVE","sortPriority":5,"id":70902602,"name":"5. Jamaica Joel"},{"status":"ACTIVE","sortPriority":6,"id":57055802,"name":"6. Songful Bird"}],"regulators":["MR_INT"],"venue":"Kinsley","countryCode":"GB","discountAllowed":true,"timezone":"Europe/London","openDate":"2024-06-27T13:36:00.000Z","version":5994643785,"name":"D5 268m","eventName":"Kinsley 27th Jun"},"rc":[{"atb":[[1.01,23.66]],"id":70902602},{"atl":[[990,0.22]],"id":70902602},{"spn":495.5,"spf":"NaN","id":70902602},{"atb":[[1.02,11.82]],"id":63579394},{"atl":[[990,0.22]],"id":63579394},{"spn":495.51,"spf":"NaN","id":63579394},{"atb":[[1.02,11.82]],"id":69769647},{"atl":[[990,0.22]],"id":69769647},{"spn":495.51,"spf":"NaN","id":69769647},{"atb":[[1.01,23.66]],"id":57055802},{"atl":[[990,0.22]],"id":57055802},{"spn":495.5,"spf":"NaN","id":57055802},{"atb":[[1.01,23.66]],"id":40626946},{"atl":[[1000,0.22]],"id":40626946},{"spn":500.5,"spf":"NaN","id":40626946},{"atb":[[1.01,23.66]],"id":45129701},{"atl":[[990,0.22]],"id":45129701},{"spn":495.5,"spf":"NaN","id":45129701}],"con":true,"img":true}]}
{"op":"mcm","clk":"11538170621","pt":1719454082548,"mc":[{"id":"1.230178324","marketDefinition":{"bspMarket":true,"turnInPlayEnabled":false,"persistenceEnabled":false,"marketBaseRate":5.0,"eventId":"33376062","eventTypeId":"4339","numberOfWinners":1,"bettingType":"ODDS","marketType":"WIN","marketTime":"2024-06-27T16:24:00.000Z","suspendTime":"2024-06-27T16:24:00.000Z","bspReconciled":false,"complete":true,"inPlay":false,"crossMatching":false,"runnersVoidable":false,"numberOfActiveRunners":6,"betDelay":0,"status":"OPEN","runners":[{"status":"ACTIVE","sortPriority":1,"id":69769647,"name":"1. Teebay"},{"status":"ACTIVE","sortPriority":2,"id":63579394,"name":"2. Apple Jam"},{"status":"ACTIVE","sortPriority":3,"id":40626946,"name":"3. Jaxleg Swift"},{"status":"ACTIVE","sortPriority":4,"id":45129701,"name":"4. Darkies Dream"},{"status":"ACTIVE","sortPriority":5,"id":70902602,"name":"5. Jamaica Joel"},{"status":"ACTIVE","sortPriority":6,"id":57055802,"name":"6. Songful Bird"}],"regulators":["MR_INT"],"venue":"Kinsley","countryCode":"GB","discountAllowed":true,"timezone":"Europe/London","openDate":"2024-06-27T13:36:00.000Z","version":5994643785,"name":"D5 268m","eventName":"Kinsley 27th Jun"},"rc":[{"atb":[[1.01,23.67]],"id":70902602},{"atl":[[990,0.22]],"id":70902602},{"spn":495.5,"spf":"NaN","id":70902602},{"atb":[[1.02,11.83]],"id":63579394},{"atl":[[990,0.22]],"id":63579394},{"spn":495.51,"spf":"NaN","id":63579394},{"atb":[[1.02,11.83]],"id":69769647},{"atl":[[990,0.22]],"id":69769647},{"spn":495.51,"spf":"NaN","id":69769647},{"atb":[[1.01,23.67]],"id":57055802},{"atl":[[990,0.22]],"id":57055802},{"spn":495.5,"spf":"NaN","id":57055802},{"atb":[[1.01,23.67]],"id":40626946},{"atl":[[1000,0.22]],"id":40626946},{"spn":500.5,"spf":"NaN","id":40626946},{"atb":[[1.01,23.67]],"id":45129701},{"atl":[[990,0.22]],"id":45129701},{"spn":495.5,"spf":"NaN","id":45129701}],"con":true,"img":true}]}
{"op":"mcm","clk":"11538368279","pt":1719459482598,"mc":[{"id":"1.230178324","marketDefinition":{"bspMarket":true,"turnInPlayEnabled":false,"persistenceEnabled":false,"marketBaseRate":5.0,"eventId":"33376062","eventTypeId":"4339","numberOfWinners":1,"bettingType":"ODDS","marketType":"WIN","marketTime":"2024-06-27T16:24:00.000Z","suspendTime":"2024-06-27T16:24:00.000Z","bspReconciled":false,"complete":true,"inPlay":false,"crossMatching":false,"runnersVoidable":false,"numberOfActiveRunners":6,"betDelay":0,"status":"OPEN","runners":[{"status":"ACTIVE","sortPriority":1,"id":69769647,"name":"1. Teebay"},{"status":"ACTIVE","sortPriority":2,"id":63579394,"name":"2. Apple Jam"},{"status":"ACTIVE","sortPriority":3,"id":40626946,"name":"3. Jaxleg Swift"},{"status":"ACTIVE","sortPriority":4,"id":45129701,"name":"4. Darkies Dream"},{"status":"ACTIVE","sortPriority":5,"id":70902602,"name":"5. Jamaica Joel"},{"status":"ACTIVE","sortPriority":6,"id":57055802,"name":"6. Songful Bird"}],"regulators":["MR_INT"],"venue":"Kinsley","countryCode":"GB","discountAllowed":true,"timezone":"Europe/London","openDate":"2024-06-27T13:36:00.000Z","version":5994643785,"name":"D5 268m","eventName":"Kinsley 27th Jun"},"rc":[{"atb":[[1.01,23.67]],"id":70902602},{"atl":[[990,0.22]],"id":70902602},{"spn":495.5,"spf":"NaN","id":70902602},{"atb":[[1.02,11.83]],"id":63579394},{"atl":[[990,0.22]],"id":63579394},{"spn":495.51,"spf":"NaN","id":63579394},{"atb":[[1.02,11.83]],"id":69769647},{"atl":[[990,0.22]],"id":69769647},{"spn":495.51,"spf":"NaN","id":69769647},{"atb":[[1.01,23.67]],"id":57055802},{"atl":[[990,0.22]],"id":57055802},{"spn":495.5,"spf":"NaN","id":57055802},{"atb":[[1.01,23.67]],"id":40626946},{"atl":[[1000,0.22]],"id":40626946},{"spn":500.5,"spf":"NaN","id":40626946},{"atb":[[1.01,23.67]],"id":45129701},{"atl":[[990,0.22]],"id":45129701},{"spn":495.5,"spf":"NaN","id":45129701}],"con":true,"img":true}]}
{"op":"mcm","clk":"11538595405","pt":1719464882547,"mc":[{"id":"1.230178324","marketDefinition":{"bspMarket":true,"turnInPlayEnabled":false,"persistenceEnabled":false,"marketBaseRate":5.0,"eventId":"33376062","eventTypeId":"4339","numberOfWinners":1,"bettingType":"ODDS","marketType":"WIN","marketTime":"2024-06-27T16:24:00.000Z","suspendTime":"2024-06-27T16:24:00.000Z","bspReconciled":false,"complete":true,"inPlay":false,"crossMatching":false,"runnersVoidable":false,"numberOfActiveRunners":6,"betDelay":0,"status":"OPEN","runners":[{"status":"ACTIVE","sortPriority":1,"id":69769647,"name":"1. Teebay"},{"status":"ACTIVE","sortPriority":2,"id":63579394,"name":"2. Apple Jam"},{"status":"ACTIVE","sortPriority":3,"id":40626946,"name":"3. Jaxleg Swift"},{"status":"ACTIVE","sortPriority":4,"id":45129701,"name":"4. Darkies Dream"},{"status":"ACTIVE","sortPriority":5,"id":70902602,"name":"5. Jamaica Joel"},{"status":"ACTIVE","sortPriority":6,"id":57055802,"name":"6. Songful Bird"}],"regulators":["MR_INT"],"venue":"Kinsley","countryCode":"GB","discountAllowed":true,"timezone":"Europe/London","openDate":"2024-06-27T13:36:00.000Z","version":5994643785,"name":"D5 268m","eventName":"Kinsley 27th Jun"},"rc":[{"atb":[[1.01,23.67]],"id":70902602},{"atl":[[990,0.22]],"id":70902602},{"spn":495.5,"spf":"NaN","id":70902602},{"atb":[[1.02,11.83]],"id":63579394},{"atl":[[990,0.22]],"id":63579394},{"spn":495.51,"spf":"NaN","id":63579394},{"atb":[[1.02,11.83]],"id":69769647},{"atl":[[990,0.22]],"id":69769647},{"spn":495.51,"spf":"NaN","id":69769647},{"atb":[[1.01,23.67]],"id":57055802},{"atl":[[990,0.22]],"id":57055802},{"spn":495.5,"spf":"NaN","id":57055802},{"atb":[[1.01,23.67]],"id":40626946},{"atl":[[1000,0.22]],"id":40626946},{"spn":500.5,"spf":"NaN","id":40626946},{"atb":[[1.01,23.67]],"id":45129701},{"atl":[[990,0.22]],"id":45129701},{"spn":495.5,"spf":"NaN","id":45129701}],"con":true,"img":true}]}
{"op":"mcm","clk":"11538748636","pt":1719468205114,"mc":[{"id":"1.230178324","rc":[{"atb":[[2,8.54],[1.01,23.67]],"id":70902602},{"spn":496.0,"spf":"NaN","id":70902602},{"atb":[[2.02,8.63],[1.02,11.83]],"id":63579394},{"spn":496.01,"spf":"NaN","id":63579394},{"atb":[[1.02,11.83],[2.08,13.32]],"id":69769647},{"spn":496.04,"spf":"NaN","id":69769647},{"atb":[[2,11.96],[1.01,23.67]],"id":57055802},{"spn":496.0,"spf":"NaN","id":57055802},{"atb":[[1.01,23.67],[2.1,12.55]],"id":40626946},{"spn":501.05,"spf":"NaN","id":40626946},{"atb":[[2,10.25],[1.01,23.67]],"id":45129701},{"spn":496.0,"spf":"NaN","id":45129701}],"con":true,"img":false}]}
{"op":"mcm","clk":"11538750364","pt":1719468242445,"mc":[{"id":"1.230178324","rc":[{"atb":[[2.04,3.16]],"id":63579394},{"atb":[[2.12,3.16]],"id":40626946}],"con":true,"img":false}]}
{"op":"mcm","clk":"11538750373","pt":1719468242645,"mc":[{"id":"1.230178324","rc":[{"atb":[[2.02,3.16]],"id":57055802}],"con":true,"img":false}]}
{"op":"mcm","clk":"11538750383","pt":1719468242850,"mc":[{"id":"1.230178324","rc":[{"atb":[[2.1,3.16]],"id":69769647}],"con":true,"img":false}]}
{"op":"mcm","clk":"11538750390","pt":1719468242954,"mc":[{"id":"1.230178324","rc":[{"atb":[[2.02,3.16]],"id":70902602}],"con":true,"img":false}]}
{"op":"mcm","clk":"11538750469","pt":1719468244240,"mc":[{"id":"1.230178324","rc":[{"atb":[[2.02,3.16]],"id":45129701}],"con":true,"img":false}]}
{"op":"mcm","clk":"11538752193","pt":1719468277991,"mc":[{"id":"1.230178324","rc":[{"spn":496.01,"spf":"NaN","id":70902602},{"atb":[[2.04,6.55]],"id":63579394},{"spn":496.02,"spf":"NaN","id":63579394},{"spn":496.05,"spf":"NaN","id":69769647},{"spn":496.01,"spf":"NaN","id":57055802},{"spn":501.06,"spf":"NaN","id":40626946},{"spn":496.01,"spf":"NaN","id":45129701}],"con":true,"img":false}]}
{"op":"mcm","clk":"11538752207","pt":1719468278297,"mc":[{"id":"1.230178324","rc":[{"atb":[[2.12,6.55]],"id":40626946}],"con":true,"img":false}]}
{"op":"mcm","clk":"11538752222","pt":1719468278610,"mc":[{"id":"1.230178324","rc":[{"atb":[[2.02,6.55]],"id":57055802},{"atb":[[2.02,6.55]],"id":45129701}],"con":true,"img":false}]}
{"op":"mcm","clk":"11538752243","pt":1719468279121,"mc":[{"id":"1.230178324","rc":[{"atb":[[2.02,6.55]],"id":70902602}],"con":true,"img":false}]}
{"op":"mcm","clk":"11538752247","pt":1719468279224,"mc":[{"id":"1.230178324","rc":[{"atb":[[2.1,6.55]],"id":69769647}],"con":true,"img":false}]}
{"op":"mcm","clk":"11538752361","pt":1719468281716,"mc":[{"id":"1.230178324","marketDefinition":{"bspMarket":true,"turnInPlayEnabled":false,"persistenceEnabled":false,"marketBaseRate":5.0,"eventId":"33376062","eventTypeId":"4339","numberOfWinners":1,"bettingType":"ODDS","marketType":"WIN","marketTime":"2024-06-27T16:24:00.000Z","suspendTime":"2024-06-27T16:24:00.000Z","bspReconciled":false,"complete":true,"inPlay":false,"crossMatching":true,"runnersVoidable":false,"numberOfActiveRunners":6,"betDelay":0,"status":"OPEN","runners":[{"status":"ACTIVE","sortPriority":1,"id":69769647,"name":"1. Teebay"},{"status":"ACTIVE","sortPriority":2,"id":63579394,"name":"2. Apple Jam"},{"status":"ACTIVE","sortPriority":3,"id":40626946,"name":"3. Jaxleg Swift"},{"status":"ACTIVE","sortPriority":4,"id":45129701,"name":"4. Darkies Dream"},{"status":"ACTIVE","sortPriority":5,"id":70902602,"name":"5. Jamaica Joel"},{"status":"ACTIVE","sortPriority":6,"id":57055802,"name":"6. Songful Bird"}],"regulators":["MR_INT"],"venue":"Kinsley","countryCode":"GB","discountAllowed":true,"timezone":"Europe/London","openDate":"2024-06-27T13:36:00.000Z","version":5994643785,"name":"D5 268m","eventName":"Kinsley 27th Jun"},"rc":[],"con":true,"img":false}]}
{"op":"mcm","clk":"11538940691","pt":1719472112647,"mc":[{"id":"1.230178324","rc":[{"atb":[[2,0],[2.02,6.54],[1.01,23.65]],"id":70902602},{"atl":[[990,0.22]],"id":70902602},{"atb":[[2.02,0],[2.04,6.54],[1.02,11.82]],"id":63579394},{"atl":[[990,0.22]],"id":63579394},{"atb":[[1.02,11.82],[2.1,6.54],[2.08,0]],"id":69769647},{"atl":[[990,0.22]],"id":69769647},{"atb":[[2,0],[2.02,6.54],[1.01,23.65]],"id":57055802},{"atl":[[990,0.22]],"id":57055802},{"atb":[[1.01,23.65],[2.12,6.54],[2.1,0]],"id":40626946},{"atl":[[1000,0.22]],"id":40626946},{"atb":[[2,0],[2.02,6.54],[1.01,23.65]],"id":45129701},{"atl":[[990,0.22]],"id":45129701}],"con":true,"img":false}]}
{"op":"mcm","clk":"11538940699","pt":1719472112749,"mc":[{"id":"1.230178324","rc":[{"atb":[[2.06,8.62]],"id":63579394},{"atb":[[2.04,8.54]],"id":70902602},{"atb":[[2.12,13.32]],"id":69769647},{"atb":[[2.04,11.95]],"id":57055802},{"atb":[[2.14,12.55]],"id":40626946},{"atb":[[2.04,10.25]],"id":45129701}],"con":true,"img":false}]}
{"op":"mcm","clk":"11538942645","pt":1719472143614,"mc":[{"id":"1.230178324","rc":[{"atb":[[2.04,3.38]],"id":63579394},{"atb":[[2.1,3.38]],"id":69769647}],"con":true,"img":false}]}
{"op":"mcm","clk":"11538942654","pt":1719472143818,"mc":[{"id":"1.230178324","rc":[{"atb":[[2.02,3.38]],"id":45129701}],"con":true,"img":false}]}
{"op":"mcm","clk":"11538942684","pt":1719472144280,"mc":[{"id":"1.230178324","rc":[{"atb":[[2.06,3.16]],"id":45129701}],"con":true,"img":false}]}
{"op":"mcm","clk":"11538942701","pt":1719472144488,"mc":[{"id":"1.230178324","rc":[{"atb":[[2.02,3.38]],"id":57055802}],"con":true,"img":false}]}
{"op":"mcm","clk":"11538942715","pt":1719472144695,"mc":[{"id":"1.230178324","rc":[{"atb":[[2.02,3.38]],"id":70902602}],"con":true,"img":false}]}
{"op":"mcm","clk":"11538942723","pt":1719472144797,"mc":[{"id":"1.230178324","rc":[{"atb":[[2.08,3.16]],"id":63579394}],"con":true,"img":false}]}
{"op":"mcm","clk":"11538942730","pt":1719472144897,"mc":[{"id":"1.230178324","rc":[{"atb":[[2.14,3.16]],"id":69769647}],"con":true,"img":false}]}
{"op":"mcm","clk":"11538942936","pt":1719472147534,"mc":[{"id":"1.230178324","rc":[{"atb":[[2.06,3.16]],"id":70902602}],"con":true,"img":false}]}
{"op":"mcm","clk":"11538942973","pt":1719472148000,"mc":[{"id":"1.230178324","rc":[{"atb":[[2.06,3.16]],"id":57055802}],"con":true,"img":false}]}
{"op":"mcm","clk":"11538943056","pt":1719472149327,"mc":[{"id":"1.230178324","rc":[{"atb":[[2.12,3.38]],"id":40626946}],"con":true,"img":false}]}
{"op":"mcm","clk":"11538943199","pt":1719472151636,"mc":[{"id":"1.230178324","rc":[{"atb":[[2.04,0]],"id":63579394}],"con":true,"img":false}]}
{"op":"mcm","clk":"11538943215","pt":1719472151898,"mc":[{"id":"1.230178324","rc":[{"atb":[[2.1,0]],"id":69769647}],"con":true,"img":false}]}
{"op":"mcm","clk":"11538943238","pt":1719472152305,"mc":[{"id":"1.230178324","rc":[{"atb":[[2.12,0]],"id":40626946}],"con":true,"img":false}]}
{"op":"mcm","clk":"11538943244","pt":1719472152407,"mc":[{"id":"1.230178324","rc":[{"atb":[[2.02,0]],"id":45129701}],"con":true,"img":false}]}
{"op":"mcm","clk":"11538943299","pt":1719472153432,"mc":[{"id":"1.230178324","rc":[{"atb":[[2.16,3.16]],"id":40626946}],"con":true,"img":false}]}
{"op":"mcm","clk":"11538943306","pt":1719472153536,"mc":[{"id":"1.230178324","rc":[{"atb":[[2.02,0]],"id":70902602}],"con":true,"img":false}]}
{"op":"mcm","clk":"11538943328","pt":1719472153902,"mc":[{"id":"1.230178324","rc":[{"atb":[[2.02,0]],"id":57055802}],"con":true,"img":false}]}
{"op":"mcm","clk":"11538943851","pt":1719472162813,"mc":[{"id":"1.230178324","rc":[{"atb":[[2.14,6.54]],"id":69769647}],"con":true,"img":false}]}
{"op":"mcm","clk":"11538943867","pt":1719472163120,"mc":[{"id":"1.230178324","rc":[{"atb":[[2.06,6.54]],"id":45129701}],"con":true,"img":false}]}
{"op":"mcm","clk":"11538943876","pt":1719472163227,"mc":[{"id":"1.230178324","rc":[{"atb":[[2.06,6.54]],"id":70902602}],"con":true,"img":false}]}
{"op":"mcm","clk":"11538943969","pt":1719472164511,"mc":[{"id":"1.230178324","rc":[{"atb":[[2.16,6.54]],"id":40626946}],"con":true,"img":false}]}
{"op":"mcm","clk":"11538944002","pt":1719472165026,"mc":[{"id":"1.230178324","rc":[{"atb":[[2.08,6.54]],"id":63579394}],"con":true,"img":false}]}
{"op":"mcm","clk":"11538944134","pt":1719472167325,"mc":[{"id":"1.230178324","rc":[{"atb":[[2.06,6.54]],"id":57055802}],"con":true,"img":false}]}
{"op":"mcm","clk":"11538988500","pt":1719473050508,"mc":[{"id":"1.230178324","rc":[{"atl":[[150,4]],"id":63579394},{"spn":76.04,"spf":"NaN","id":63579394},{"spn":496.03,"spf":"NaN","id":70902602},{"atl":[[150,4]],"id":69769647},{"spn":76.07,"spf":"NaN","id":69769647},{"spn":496.03,"spf":"NaN","id":57055802},{"atl":[[150,4]],"id":40626946},{"spn":76.08,"spf":"NaN","id":40626946},{"spn":496.03,"spf":"NaN","id":45129701}],"con":true,"img":false}]}
{"op":"mcm","clk":"11538988504","pt":1719473050610,"mc":[{"id":"1.230178324","rc":[{"atl":[[150,4]],"id":70902602},{"atl":[[150,4]],"id":57055802},{"atl":[[150,4]],"id":45129701}],"con":true,"img":false}]}
{"op":"mcm","clk":"11539122552","pt":1719475682554,"mc":[{"id":"1.230178324","marketDefinition":{"bspMarket":true,"turnInPlayEnabled":false,"persistenceEnabled":false,"marketBaseRate":5.0,"eventId":"33376062","eventTypeId":"4339","numberOfWinners":1,"bettingType":"ODDS","marketType":"WIN","marketTime":"2024-06-27T16:24:00.000Z","suspendTime":"2024-06-27T16:24:00.000Z","bspReconciled":false,"complete":true,"inPlay":false,"crossMatching":true,"runnersVoidable":false,"numberOfActiveRunners":6,"betDelay":0,"status":"OPEN","runners":[{"status":"ACTIVE","sortPriority":1,"id":69769647,"name":"1. Teebay"},{"status":"ACTIVE","sortPriority":2,"id":63579394,"name":"2. Apple Jam"},{"status":"ACTIVE","sortPriority":3,"id":40626946,"name":"3. Jaxleg Swift"},{"status":"ACTIVE","sortPriority":4,"id":45129701,"name":"4. Darkies Dream"},{"status":"ACTIVE","sortPriority":5,"id":70902602,"name":"5. Jamaica Joel"},{"status":"ACTIVE","sortPriority":6,"id":57055802,"name":"6. Songful Bird"}],"regulators":["MR_INT"],"venue":"Kinsley","countryCode":"GB","discountAllowed":true,"timezone":"Europe/London","openDate":"2024-06-27T13:36:00.000Z","version":5994643785,"name":"D5 268m","eventName":"Kinsley 27th Jun"},"rc":[{"atb":[[1.01,23.66],[2.06,6.55],[2.04,8.54]],"id":70902602},{"atl":[[150,4],[990,0.22]],"id":70902602},{"spn":76.03,"spf":"NaN","id":70902602},{"atb":[[2.06,8.63],[1.02,11.82],[2.08,6.55]],"id":63579394},{"atl":[[150,4],[990,0.22]],"id":63579394},{"spn":76.04,"spf":"NaN","id":63579394},{"atb":[[1.02,11.82],[2.12,13.32],[2.14,6.55]],"id":69769647},{"atl":[[150,4],[990,0.22]],"id":69769647},{"spn":76.07,"spf":"NaN","id":69769647},{"atb":[[1.01,23.66],[2.06,6.55],[2.04,11.96]],"id":57055802},{"atl":[[150,4],[990,0.22]],"id":57055802},{"spn":76.03,"spf":"NaN","id":57055802},{"atb":[[1.01,23.66],[2.16,6.55],[2.14,12.55]],"id":40626946},{"atl":[[150,4],[1000,0.22]],"id":40626946},{"spn":76.08,"spf":"NaN","id":40626946},{"atb":[[1.01,23.66],[2.06,6.55],[2.04,10.25]],"id":45129701},{"atl":[[150,4],[990,0.22]],"id":45129701},{"spn":76.03,"spf":"NaN","id":45129701}],"con":true,"img":true}]}
{"op":"mcm","clk":"11539128004","pt":1719475712711,"mc":[{"id":"1.230178324","rc":[{"atb":[[1.01,23.66],[2.06,6.55],[2.04,0]],"id":70902602},{"spn":76.03,"spf":"NaN","id":70902602},{"atb":[[2.06,0],[1.02,11.82],[2.08,6.55]],"id":63579394},{"atb":[[1.02,11.82],[2.12,0],[2.14,6.55]],"id":69769647},{"atb":[[1.01,23.66],[2.06,6.55],[2.04,0]],"id":57055802},{"spn":76.03,"spf":"NaN","id":57055802},{"atb":[[1.01,23.66],[2.16,6.55],[2.14,0]],"id":40626946},{"atb":[[1.01,23.66],[2.06,6.55],[2.04,0]],"id":45129701},{"spn":76.03,"spf":"NaN","id":45129701}],"con":true,"img":false}]}
{"op":"mcm","clk":"11539128011","pt":1719475712818,"mc":[{"id":"1.230178324","rc":[{"atb":[[2.08,8.54]],"id":70902602},{"atb":[[2.1,8.63]],"id":63579394},{"atb":[[2.16,13.32]],"id":69769647},{"atb":[[2.08,11.96]],"id":57055802},{"atb":[[2.18,12.55]],"id":40626946},{"atb":[[2.08,10.25]],"id":45129701}],"con":true,"img":false}]}
{"op":"mcm","clk":"11539134277","pt":1719475810326,"mc":[{"id":"1.230178324","rc":[{"atb":[[2.06,3.38]],"id":70902602},{"spn":76.04,"spf":"NaN","id":70902602},{"atb":[[2.08,3.38]],"id":63579394},{"spn":76.05,"spf":"NaN","id":63579394},{"atb":[[2.14,3.38]],"id":69769647},{"spn":76.08,"spf":"NaN","id":69769647},{"atb":[[2.06,3.38]],"id":57055802},{"spn":76.04,"spf":"NaN","id":57055802},{"atb":[[2.16,3.38]],"id":40626946},{"spn":76.09,"spf":"NaN","id":40626946},{"atb":[[2.06,3.38]],"id":45129701},{"spn":76.04,"spf":"NaN","id":45129701}],"con":true,"img":false}]}
{"op":"mcm","clk":"11539153143","pt":1719476114725,"mc":[{"id":"1.230178324","rc":[{"atb":[[2.18,3.16]],"id":69769647},{"spn":76.09,"spf":"NaN","id":69769647}],"con":true,"img":false}]}
{"op":"mcm","clk":"11539153148","pt":1719476114826,"mc":[{"id":"1.230178324","rc":[{"atb":[[2.12,3.16]],"id":63579394}],"con":true,"img":false}]}
{"op":"mcm","clk":"11539153163","pt":1719476114985,"mc":[{"id":"1.230178324","rc":[{"atb":[[2.1,3.16]],"id":70902602},{"atb":[[2.1,3.16]],"id":45129701}],"con":true,"img":false}]}
{"op":"mcm","clk":"11539153174","pt":1719476115186,"mc":[{"id":"1.230178324","rc":[{"atb":[[2.1,3.16]],"id":57055802}],"con":true,"img":false}]}
{"op":"mcm","clk":"11539153184","pt":1719476115297,"mc":[{"id":"1.230178324","rc":[{"atb":[[2.2,3.16]],"id":40626946}],"con":true,"img":false}]}
{"op":"mcm","clk":"11539438528","pt":1719481082549,"mc":[{"id":"1.230178324","marketDefinition":{"bspMarket":true,"turnInPlayEnabled":false,"persistenceEnabled":false,"marketBaseRate":5.0,"eventId":"33376062","eventTypeId":"4339","numberOfWinners":1,"bettingType":"ODDS","marketType":"WIN","marketTime":"2024-06-27T16:24:00.000Z","suspendTime":"2024-06-27T16:24:00.000Z","bspReconciled":false,"complete":true,"inPlay":false,"crossMatching":true,"runnersVoidable":false,"numberOfActiveRunners":6,"betDelay":0,"status":"OPEN","runners":[{"status":"ACTIVE","sortPriority":1,"id":69769647,"name":"1. Teebay"},{"status":"ACTIVE","sortPriority":2,"id":63579394,"name":"2. Apple Jam"},{"status":"ACTIVE","sortPriority":3,"id":40626946,"name":"3. Jaxleg Swift"},{"status":"ACTIVE","sortPriority":4,"id":45129701,"name":"4. Darkies Dream"},{"status":"ACTIVE","sortPriority":5,"id":70902602,"name":"5. Jamaica Joel"},{"status":"ACTIVE","sortPriority":6,"id":57055802,"name":"6. Songful Bird"}],"regulators":["MR_INT"],"venue":"Kinsley","countryCode":"GB","discountAllowed":true,"timezone":"Europe/London","openDate":"2024-06-27T13:36:00.000Z","version":5994643785,"name":"D5 268m","eventName":"Kinsley 27th Jun"},"rc":[{"atb":[[1.01,23.66],[2.06,3.38],[2.1,3.16],[2.08,8.54]],"id":70902602},{"atl":[[150,4],[990,0.22]],"id":70902602},{"spn":76.05,"spf":"NaN","id":70902602},{"atb":[[1.02,11.82],[2.12,3.16],[2.1,8.62],[2.08,3.38]],"id":63579394},{"atl":[[150,4],[990,0.22]],"id":63579394},{"spn":76.06,"spf":"NaN","id":63579394},{"atb":[[1.02,11.82],[2.18,3.16],[2.16,13.32],[2.14,3.38]],"id":69769647},{"atl":[[150,4],[990,0.22]],"id":69769647},{"spn":76.09,"spf":"NaN","id":69769647},{"atb":[[1.01,23.66],[2.06,3.38],[2.1,3.16],[2.08,11.96]],"id":57055802},{"atl":[[150,4],[990,0.22]],"id":57055802},{"spn":76.05,"spf":"NaN","id":57055802},{"atb":[[1.01,23.66],[2.18,12.55],[2.2,3.16],[2.16,3.38]],"id":40626946},{"atl":[[150,4],[1000,0.22]],"id":40626946},{"spn":76.1,"spf":"NaN","id":40626946},{"atb":[[1.01,23.66],[2.06,3.38],[2.1,3.16],[2.08,10.25]],"id":45129701},{"atl":[[150,4],[990,0.22]],"id":45129701},{"spn":76.05,"spf":"NaN","id":45129701}],"con":true,"img":true}]}
{"op":"mcm","clk":"11539617878","pt":1719483893616,"mc":[{"id":"1.230178324","rc":[{"atb":[[1.01,23.65],[2.06,3.38],[2.1,3.16],[2.08,8.54]],"id":70902602},{"spn":76.05,"spf":"NaN","id":70902602},{"atb":[[1.02,11.82],[2.12,3.16],[2.1,8.62],[2.08,3.38]],"id":63579394},{"spn":76.06,"spf":"NaN","id":63579394},{"atb":[[1.02,11.82],[2.18,3.16],[2.16,13.32],[2.14,3.38]],"id":69769647},{"atb":[[1.01,23.65],[2.06,3.38],[2.12,2],[2.1,3.16],[2.08,11.95]],"id":57055802},{"spn":76.06,"spf":"NaN","id":57055802},{"atb":[[1.01,23.65],[2.18,12.55],[2.2,3.16],[2.16,3.38]],"id":40626946},{"spn":76.1,"spf":"NaN","id":40626946},{"atb":[[1.01,23.65],[2.06,3.38],[2.1,3.16],[2.08,10.25]],"id":45129701},{"spn":76.05,"spf":"NaN","id":45129701}],"con":true,"img":false}]}
{"op":"mcm","clk":"11539620202","pt":1719483921774,"mc":[{"id":"1.230178324","rc":[{"atb":[[2.12,0]],"id":57055802}],"con":true,"img":false}]}
{"op":"mcm","clk":"11539628141","pt":1719484033450,"mc":[{"id":"1.230178324","rc":[{"atb":[[2.12,2]],"id":57055802}],"con":true,"img":false}]}
{"op":"mcm","clk":"11539629969","pt":1719484061576,"mc":[{"id":"1.230178324","rc":[{"atb":[[2.12,0]],"id":57055802}],"con":true,"img":false}]}
{"op":"mcm","clk":"11539636851","pt":1719484173262,"mc":[{"id":"1.230178324","rc":[{"atb":[[2.12,2]],"id":57055802}],"con":true,"img":false}]}
{"op":"mcm","clk":"11539638580","pt":1719484201399,"mc":[{"id":"1.230178324","rc":[{"atb":[[2.12,0]],"id":57055802}],"con":true,"img":false}]}
{"op":"mcm","clk":"11539797654","pt":1719486341876,"mc":[{"id":"1.230178324","rc":[{"atb":[[1.01,23.66],[2.06,3.38],[2.86,6],[2.1,3.16],[2.08,8.54]],"id":70902602},{"spn":76.43,"spf":"NaN","id":70902602},{"atb":[[1.02,11.82],[2.12,3.16],[2.1,8.62],[2.08,3.38],[3.75,6]],"id":63579394},{"spn":76.87,"spf":"NaN","id":63579394},{"atb":[[1.02,11.82],[2.18,3.16],[2.16,19.32],[2.14,3.38]],"id":69769647},{"atb":[[1.01,23.66],[2.06,3.38],[4.1,6],[2.1,3.16],[2.08,11.96]],"id":57055802},{"spn":77.05,"spf":"NaN","id":57055802},{"atb":[[1.01,23.66],[2.18,12.55],[2.2,3.16],[3.3,6],[2.16,3.38]],"id":40626946},{"spn":76.65,"spf":"NaN","id":40626946},{"atb":[[1.01,23.66],[2.06,3.38],[3.55,6],[2.1,3.16],[2.08,10.25]],"id":45129701},{"spn":76.77,"spf":"NaN","id":45129701}],"con":true,"img":false}]}
{"op":"mcm","clk":"11539799581","pt":1719486364394,"mc":[{"id":"1.230178324","rc":[{"atb":[[2.1,0]],"id":70902602}],"con":true,"img":false}]}
{"op":"mcm","clk":"11539799591","pt":1719486364497,"mc":[{"id":"1.230178324","rc":[{"atb":[[2.12,0]],"id":63579394},{"atb":[[2.1,0]],"id":57055802},{"atb":[[2.2,0]],"id":40626946},{"atb":[[2.1,0]],"id":45129701}],"con":true,"img":false}]}
{"op":"mcm","clk":"11539799602","pt":1719486364600,"mc":[{"id":"1.230178324","rc":[{"atb":[[2.88,3.16]],"id":70902602}],"con":true,"img":false}]}
{"op":"mcm","clk":"11539810825","pt":1719486482541,"mc":[{"id":"1.230178324","marketDefinition":{"bspMarket":true,"turnInPlayEnabled":false,"persistenceEnabled":false,"marketBaseRate":5.0,"eventId":"33376062","eventTypeId":"4339","numberOfWinners":1,"bettingType":"ODDS","marketType":"WIN","marketTime":"2024-06-27T16:24:00.000Z","suspendTime":"2024-06-27T16:24:00.000Z","bspReconciled":false,"complete":true,"inPlay":false,"crossMatching":true,"runnersVoidable":false,"numberOfActiveRunners":6,"betDelay":0,"status":"OPEN","runners":[{"status":"ACTIVE","sortPriority":1,"id":69769647,"name":"1. Teebay"},{"status":"ACTIVE","sortPriority":2,"id":63579394,"name":"2. Apple Jam"},{"status":"ACTIVE","sortPriority":3,"id":40626946,"name":"3. Jaxleg Swift"},{"status":"ACTIVE","sortPriority":4,"id":45129701,"name":"4. Darkies Dream"},{"status":"ACTIVE","sortPriority":5,"id":70902602,"name":"5. Jamaica Joel"},{"status":"ACTIVE","sortPriority":6,"id":57055802,"name":"6. Songful Bird"}],"regulators":["MR_INT"],"venue":"Kinsley","countryCode":"GB","discountAllowed":true,"timezone":"Europe/London","openDate":"2024-06-27T13:36:00.000Z","version":5994643785,"name":"D5 268m","eventName":"Kinsley 27th Jun"},"rc":[{"atb":[[2.88,3.16],[1.01,23.66],[2.86,6],[2.06,3.38],[2.08,8.54]],"id":70902602},{"atl":[[150,4],[990,0.22]],"id":70902602},{"spn":76.44,"spf":"NaN","id":70902602},{"atb":[[1.02,11.82],[2.1,8.62],[3.75,6],[2.08,3.38]],"id":63579394},{"atl":[[150,4],[990,0.22]],"id":63579394},{"spn":76.87,"spf":"NaN","id":63579394},{"atb":[[1.02,11.82],[2.18,3.16],[2.16,19.32],[2.14,3.38]],"id":69769647},{"atl":[[150,4],[990,0.22]],"id":69769647},{"spn":76.09,"spf":"NaN","id":69769647},{"atb":[[1.01,23.66],[2.06,3.38],[4.1,6],[2.08,11.96]],"id":57055802},{"atl":[[150,4],[990,0.22]],"id":57055802},{"spn":77.05,"spf":"NaN","id":57055802},{"atb":[[1.01,23.66],[2.18,12.55],[3.3,6],[2.16,3.38]],"id":40626946},{"atl":[[150,4],[1000,0.22]],"id":40626946},{"spn":76.65,"spf":"NaN","id":40626946},{"atb":[[1.01,23.66],[2.06,3.38],[3.55,6],[2.08,10.25]],"id":45129701},{"atl":[[150,4],[990,0.22]],"id":45129701},{"spn":76.77,"spf":"NaN","id":45129701}],"con":true,"img":true}]}
{"op":"mcm","clk":"11539888566","pt":1719487447352,"mc":[{"id":"1.230178324","rc":[{"atl":[[46,12],[27,8]],"id":70902602},{"spn":14.94,"spf":"NaN","id":70902602},{"atl":[[36,12],[21,8]],"id":69769647},{"spn":11.59,"spf":"NaN","id":69769647},{"atl":[[36,8],[60,12]],"id":40626946},{"spn":19.65,"spf":"NaN","id":40626946},{"atl":[[36,8],[60,12]],"id":45129701},{"spn":19.77,"spf":"NaN","id":45129701}],"con":true,"img":false}]}
{"op":"mcm","clk":"11540014547","pt":1719489000924,"mc":[{"id":"1.230178324","rc":[{"atb":[[1.16,150]],"id":70902602},{"atl":[[560,2]],"id":70902602},{"atb":[[1.16,150]],"id":63579394},{"atl":[[390,2]],"id":63579394},{"atb":[[1.16,150]],"id":69769647},{"atl":[[370,2]],"id":69769647},{"atl":[[500,2]],"id":57055802},{"atb":[[1.16,150]],"id":40626946},{"atl":[[550,2]],"id":40626946},{"atb":[[1.16,150]],"id":45129701},{"atl":[[270,2]],"id":45129701}],"con":true,"img":false}]}
{"op":"mcm","clk":"11540014556","pt":1719489001029,"mc":[{"id":"1.230178324","rc":[{"atb":[[1.16,150]],"id":57055802}],"con":true,"img":false}]}
{"op":"mcm","clk":"11540188852","pt":1719491041548,"mc":[{"id":"1.230178324","rc":[{"atb":[[5,1]],"id":63579394},{"spn":77.5,"spf":"NaN","id":63579394},{"atb":[[2.88,3.16],[3.75,1]],"id":70902602},{"spn":15.37,"spf":"NaN","id":70902602},{"atb":[[5,1],[2.18,3.16]],"id":69769647},{"spn":13.0,"spf":"NaN","id":69769647},{"atb":[[5,1]],"id":57055802},{"spn":77.5,"spf":"NaN","id":57055802},{"atb":[[4.7,1]],"id":40626946},{"spn":20.35,"spf":"NaN","id":40626946},{"atb":[[5,1]],"id":45129701},{"spn":20.5,"spf":"NaN","id":45129701}],"con":true,"img":false}]}
{"op":"mcm","clk":"11540190292","pt":1719491062069,"mc":[{"id":"1.230178324","rc":[{"atb":[[1.51,196.08]],"id":63579394},{"atb":[[1.51,196.08]],"id":57055802},{"atb":[[1.51,196.08]],"id":40626946},{"atb":[[1.51,196.08]],"id":45129701}],"con":true,"img":false}]}
{"op":"mcm","clk":"11540258290","pt":1719491989610,"mc":[{"id":"1.230178324","rc":[{"atb":[[2.12,89.29]],"id":63579394},{"atb":[[2.12,89.29]],"id":57055802},{"atb":[[2.12,89.29]],"id":40626946},{"atb":[[2.12,89.29]],"id":45129701}],"con":true,"img":false}]}
{"op":"mcm","clk":"11540258294","pt":1719491989713,"mc":[{"id":"1.230178324","rc":[{"atb":[[1.51,196.08]],"id":70902602},{"atb":[[1.51,196.08]],"id":69769647}],"con":true,"img":false}]}
{"op":"mcm","clk":"11540397844","pt":1719493996140,"mc":[{"id":"1.230178324","rc":[{"atb":[[2.88,3.16],[1.01,23.68],[2.06,3.38],[2.08,8.55]],"id":70902602},{"atl":[[990,0.22]],"id":70902602},{"atb":[[1.02,11.84],[2.1,0],[2.08,3.38]],"id":63579394},{"atl":[[990,0.22]],"id":63579394},{"atb":[[1.02,11.84],[2.18,3.16],[2.16,19.33],[2.14,3.38]],"id":69769647},{"atl":[[990,0.22]],"id":69769647},{"atb":[[1.01,23.68],[2.06,3.38],[2.08,0]],"id":57055802},{"atl":[[990,0.22]],"id":57055802},{"atb":[[1.01,23.68],[2.18,12.56],[2.16,3.38]],"id":40626946},{"atl":[[1000,0.22]],"id":40626946},{"atb":[[1.01,23.68],[2.06,3.38],[2.08,0]],"id":45129701},{"atl":[[990,0.22]],"id":45129701}],"con":true,"img":false}]}
{"op":"mcm","clk":"11540397852","pt":1719493996243,"mc":[{"id":"1.230178324","rc":[{"atb":[[2.14,8.63]],"id":63579394},{"atb":[[2.14,11.97]],"id":57055802},{"atb":[[2.14,10.26]],"id":45129701}],"con":true,"img":false}]}
{"op":"mcm","clk":"11540608516","pt":1719496399569,"mc":[{"id":"1.230178324","rc":[{"atb":[[5.5,1]],"id":63579394},{"spn":77.75,"spf":"NaN","id":63579394},{"atb":[[3.7,1]],"id":70902602},{"atb":[[2.9,1]],"id":69769647},{"atb":[[7,1]],"id":57055802},{"spn":78.5,"spf":"NaN","id":57055802},{"atb":[[4.8,1]],"id":40626946},{"spn":20.4,"spf":"NaN","id":40626946},{"atb":[[5,2]],"id":45129701}],"con":true,"img":false}]}
{"op":"mcm","clk":"11540683362","pt":1719497282515,"mc":[{"id":"1.230178324","marketDefinition":{"bspMarket":true,"turnInPlayEnabled":false,"persistenceEnabled":false,"marketBaseRate":5.0,"eventId":"33376062","eventTypeId":"4339","numberOfWinners":1,"bettingType":"ODDS","marketType":"WIN","marketTime":"2024-06-27T16:24:00.000Z","suspendTime":"2024-06-27T16:24:00.000Z","bspReconciled":false,"complete":true,"inPlay":false,"crossMatching":true,"runnersVoidable":false,"numberOfActiveRunners":6,"betDelay":0,"status":"OPEN","runners":[{"status":"ACTIVE","sortPriority":1,"id":69769647,"name":"1. Teebay"},{"status":"ACTIVE","sortPriority":2,"id":63579394,"name":"2. Apple Jam"},{"status":"ACTIVE","sortPriority":3,"id":40626946,"name":"3. Jaxleg Swift"},{"status":"ACTIVE","sortPriority":4,"id":45129701,"name":"4. Darkies Dream"},{"status":"ACTIVE","sortPriority":5,"id":70902602,"name":"5. Jamaica Joel"},{"status":"ACTIVE","sortPriority":6,"id":57055802,"name":"6. Songful Bird"}],"regulators":["MR_INT"],"venue":"Kinsley","countryCode":"GB","discountAllowed":true,"timezone":"Europe/London","openDate":"2024-06-27T13:36:00.000Z","version":5994643785,"name":"D5 268m","eventName":"Kinsley 27th Jun"},"rc":[{"atb":[[5,1],[1.16,150],[5.5,1],[1.02,11.83],[2.12,89.29],[1.51,196.08],[2.14,8.63],[3.75,6],[2.08,3.38]],"id":63579394},{"atl":[[150,4],[390,2],[990,0.22]],"id":63579394},{"spn":77.75,"spf":"NaN","id":63579394},{"atb":[[2.88,3.15],[1.01,23.67],[2.86,6],[2.06,3.38],[1.16,150],[3.7,1],[1.51,196.08],[3.75,1],[2.08,8.55]],"id":70902602},{"atl":[[560,2],[150,4],[46,12],[27,8],[990,0.22]],"id":70902602},{"spn":15.37,"spf":"NaN","id":70902602},{"atb":[[5,1],[2.9,1],[1.16,150],[1.02,11.83],[2.18,3.15],[1.51,196.08],[2.16,19.33],[2.14,3.38]],"id":69769647},{"atl":[[36,12],[150,4],[21,8],[370,2],[990,0.22]],"id":69769647},{"spn":13.0,"spf":"NaN","id":69769647},{"atb":[[1.01,23.67],[5,1],[2.06,3.38],[1.16,150],[4.1,6],[2.12,89.29],[1.51,196.08],[7,1],[2.14,11.97]],"id":57055802},{"atl":[[150,4],[990,0.22],[500,2]],"id":57055802},{"spn":78.5,"spf":"NaN","id":57055802},{"atb":[[4.8,1],[1.01,23.67],[1.16,150],[2.12,89.29],[2.18,12.56],[1.51,196.08],[3.3,6],[2.16,3.38],[4.7,1]],"id":40626946},{"atl":[[550,2],[36,8],[150,4],[60,12],[1000,0.22]],"id":40626946},{"spn":20.4,"spf":"NaN","id":40626946},{"atb":[[1.01,23.67],[5,2],[2.06,3.38],[1.16,150],[2.12,89.29],[3.55,6],[1.51,196.08],[2.14,10.26]],"id":45129701},{"atl":[[270,2],[36,8],[150,4],[60,12],[990,0.22]],"id":45129701},{"spn":20.5,"spf":"NaN","id":45129701}],"con":true,"img":true}]}
{"op":"mcm","clk":"11540715679","pt":1719497593044,"mc":[{"id":"1.230178324","rc":[{"atb":[[1.02,11.83],[2.14,8.63],[2.08,3.38]],"id":63579394},{"atb":[[2.88,3.15],[1.01,23.67],[2.06,3.38],[2.08,8.55]],"id":70902602},{"atb":[[1.02,11.83],[2.18,3.15],[2.16,6],[2.14,3.38]],"id":69769647},{"atb":[[1.01,23.67],[2.06,3.38],[2.14,11.97]],"id":57055802},{"atb":[[1.01,23.67],[2.18,12.56],[2.16,3.38]],"id":40626946},{"atb":[[1.01,23.67],[2.06,3.38],[2.14,10.26]],"id":45129701}],"con":true,"img":false}]}
{"op":"mcm","clk":"11540715694","pt":1719497593146,"mc":[{"id":"1.230178324","rc":[{"atb":[[2.2,13.33]],"id":69769647}],"con":true,"img":false}]}
{"op":"mcm","clk":"11540717638","pt":1719497617978,"mc":[{"id":"1.230178324","rc":[{"atb":[[2.18,0]],"id":69769647}],"con":true,"img":false}]}
{"op":"mcm","clk":"11540717658","pt":1719497618190,"mc":[{"id":"1.230178324","rc":[{"atb":[[2.22,3.15]],"id":69769647}],"con":true,"img":false}]}
{"op":"mcm","clk":"11540733223","pt":1719497795689,"mc":[{"id":"1.230178324","rc":[{"spl":[[1.01,1]],"id":69769647},{"spn":5.0,"spf":1.0,"id":69769647}],"con":true,"img":false}]}
{"op":"mcm","clk":"11540741905","pt":1719497892377,"mc":[{"id":"1.230178324","rc":[{"atb":[[2.2,0]],"id":69769647}],"con":true,"img":false}]}
{"op":"mcm","clk":"11540741913","pt":1719497892479,"mc":[{"id":"1.230178324","rc":[{"atb":[[2.24,13.33]],"id":69769647}],"con":true,"img":false}]}
{"op":"mcm","clk":"11540742269","pt":1719497896299,"mc":[{"id":"1.230178324","rc":[{"atb":[[2.22,0]],"id":69769647}],"con":true,"img":false}]}
{"op":"mcm","clk":"11540742290","pt":1719497896456,"mc":[{"id":"1.230178324","rc":[{"atb":[[2.26,3.15]],"id":69769647}],"con":true,"img":false}]}
{"op":"mcm","clk":"11540768823","pt":1719498192294,"mc":[{"id":"1.230178324","rc":[{"atb":[[2.24,0]],"id":69769647}],"con":true,"img":false}]}
{"op":"mcm","clk":"11540768831","pt":1719498192398,"mc":[{"id":"1.230178324","rc":[{"atb":[[2.28,13.33]],"id":69769647}],"con":true,"img":false}]}
{"op":"mcm","clk":"11540769051","pt":1719498194192,"mc":[{"id":"1.230178324","rc":[{"atb":[[2.26,0]],"id":69769647}],"con":true,"img":false}]}
{"op":"mcm","clk":"11540769076","pt":1719498194400,"mc":[{"id":"1.230178324","rc":[{"atb":[[2.3,3.15]],"id":69769647}],"con":true,"img":false}]}
{"op":"mcm","clk":"11540797853","pt":1719498492182,"mc":[{"id":"1.230178324","rc":[{"atb":[[2.28,0]],"id":69769647}],"con":true,"img":false}]}
{"op":"mcm","clk":"11540797862","pt":1719498492249,"mc":[{"id":"1.230178324","rc":[{"atb":[[2.32,13.33]],"id":69769647}],"con":true,"img":false}]}
{"op":"mcm","clk":"11540798501","pt":1719498498367,"mc":[{"id":"1.230178324","rc":[{"atb":[[2.3,0]],"id":69769647}],"con":true,"img":false}]}
{"op":"mcm","clk":"11540798521","pt":1719498498575,"mc":[{"id":"1.230178324","rc":[{"atb":[[2.34,3.15]],"id":69769647}],"con":true,"img":false}]}
{"op":"mcm","clk":"11540815874","pt":1719498682394,"mc":[{"id":"1.230178324","rc":[{"atb":[[5.5,0]],"id":63579394},{"spn":77.5,"spf":"NaN","id":63579394},{"atb":[[3.7,0]],"id":70902602},{"atb":[[2.9,0]],"id":69769647},{"atb":[[7,0]],"id":57055802},{"spn":77.5,"spf":"NaN","id":57055802},{"atb":[[4.8,0]],"id":40626946},{"spn":20.35,"spf":"NaN","id":40626946},{"atb":[[5,1]],"id":45129701}],"con":true,"img":false}]}
{"op":"mcm","clk":"11540843893","pt":1719499013643,"mc":[{"id":"1.230178324","rc":[{"atb":[[3.7,1]],"id":45129701}],"con":true,"img":false}]}
{"op":"mcm","clk":"11540955228","pt":1719500414938,"mc":[{"id":"1.230178324","rc":[{"atb":[[2.88,3.16],[1.01,23.68],[2.06,3.38],[2.08,8.55],[2.7,3.7]],"id":70902602},{"atb":[[4,2.5],[1.02,11.83],[2.14,8.63],[2.08,3.38]],"id":63579394},{"atb":[[2.32,13.33],[1.02,11.83],[3,3.33],[2.14,3.38],[2.34,3.16]],"id":69769647},{"atb":[[4.5,2.22],[1.01,23.68],[2.06,3.38],[2.14,11.97]],"id":57055802},{"atb":[[1.01,23.68],[2.18,12.56],[3.5,2.85],[2.16,3.38]],"id":40626946},{"atb":[[4,2.5],[1.01,23.68],[2.06,3.38],[2.14,10.26]],"id":45129701}],"con":true,"img":false}]}
{"op":"mcm","clk":"11541197371","pt":1719503255865,"mc":[{"id":"1.230178324","rc":[{"atl":[[34,1.67]],"id":45129701},{"spn":19.5,"spf":"NaN","id":45129701}],"con":true,"img":false}]}
{"op":"mcm","clk":"11541197417","pt":1719503256369,"mc":[{"id":"1.230178324","rc":[{"atl":[[34,1.74]],"id":40626946}],"con":true,"img":false}]}
{"op":"mcm","clk":"11541197445","pt":1719503256679,"mc":[{"id":"1.230178324","rc":[{"atl":[[26,1.71]],"id":70902602}],"con":true,"img":false}]}
{"op":"mcm","clk":"11541242086","pt":1719503718409,"mc":[{"id":"1.230178324","rc":[{"spn":14.87,"spf":"NaN","id":70902602},{"atb":[[2.18,6.67]],"id":69769647},{"spn":19.35,"spf":"NaN","id":40626946}],"con":true,"img":false}]}
{"op":"mcm","clk":"11541242600","pt":1719503722914,"mc":[{"id":"1.230178324","rc":[{"atb":[[2.18,0]],"id":69769647}],"con":true,"img":false}]}
{"op":"mcm","clk":"11541247828","pt":1719503776742,"mc":[{"id":"1.230178324","rc":[{"atb":[[2.7,0]],"id":70902602},{"atb":[[4,0]],"id":63579394},{"atb":[[3,0]],"id":69769647},{"atb":[[4.5,0]],"id":57055802},{"atb":[[3.5,0]],"id":40626946},{"atb":[[4,0]],"id":45129701}],"con":true,"img":false}]}
{"op":"mcm","clk":"11541255876","pt":1719503854954,"mc":[{"id":"1.230178324","rc":[{"spl":[[1.01,5]],"id":69769647},{"spn":2.86,"spf":1.0,"id":69769647}],"con":true,"img":false}]}
{"op":"mcm","clk":"11541266097","pt":1719503948181,"mc":[{"id":"1.230178324","rc":[{"atl":[[190,4]],"id":63579394},{"atl":[[190,4]],"id":70902602},{"atl":[[190,4]],"id":40626946}],"con":true,"img":false}]}
{"op":"mcm","clk":"11541266106","pt":1719503948234,"mc":[{"id":"1.230178324","rc":[{"atl":[[190,4]],"id":69769647},{"atl":[[190,4]],"id":57055802},{"atl":[[190,4]],"id":45129701}],"con":true,"img":false}]}
{"op":"mcm","clk":"11541269931","pt":1719503987624,"mc":[{"id":"1.230178324","rc":[{"atb":[[1.02,13.83]],"id":69769647}],"con":true,"img":false}]}
{"op":"mcm","clk":"11541269954","pt":1719503987832,"mc":[{"id":"1.230178324","rc":[{"atb":[[1.02,13.83]],"id":63579394}],"con":true,"img":false}]}
{"op":"mcm","clk":"11541269973","pt":1719503987986,"mc":[{"id":"1.230178324","rc":[{"atb":[[1.02,2]],"id":40626946}],"con":true,"img":false}]}
{"op":"mcm","clk":"11541270001","pt":1719503988299,"mc":[{"id":"1.230178324","rc":[{"atb":[[1.02,2]],"id":45129701}],"con":true,"img":false}]}
{"op":"mcm","clk":"11541270036","pt":1719503988705,"mc":[{"id":"1.230178324","rc":[{"atb":[[1.02,2]],"id":70902602}],"con":true,"img":false}]}
{"op":"mcm","clk":"11541270057","pt":1719503988920,"mc":[{"id":"1.230178324","rc":[{"atb":[[1.02,2]],"id":57055802}],"con":true,"img":false}]}
{"op":"mcm","clk":"11541277489","pt":1719504058690,"mc":[{"id":"1.230178324","rc":[{"atb":[[2.88,3.16],[1.01,23.67],[2.06,3.38],[2.08,8.54]],"id":70902602},{"atl":[[990,0.22]],"id":70902602},{"atb":[[1.02,13.83],[2.14,8.63],[2.08,3.38]],"id":63579394},{"atl":[[990,0.22]],"id":63579394},{"atb":[[2.32,13.32],[1.02,13.83],[2.46,15],[2.14,3.38],[2.34,3.16]],"id":69769647},{"atl":[[990,0.22]],"id":69769647},{"spn":2.96,"spf":1.0,"id":69769647},{"atb":[[1.01,23.67],[2.06,3.38],[2.14,11.96]],"id":57055802},{"atl":[[990,0.22]],"id":57055802},{"atb":[[1.01,23.67],[2.18,12.55],[2.16,3.38]],"id":40626946},{"atl":[[1000,0.22]],"id":40626946},{"atb":[[1.01,23.67],[2.06,3.38],[2.14,10.25]],"id":45129701},{"atl":[[990,0.22]],"id":45129701}],"con":true,"img":false}]}
{"op":"mcm","clk":"11541277506","pt":1719504058895,"mc":[{"id":"1.230178324","rc":[{"atb":[[2.46,0]],"id":69769647}],"con":true,"img":false}]}
{"op":"mcm","clk":"11541298669","pt":1719504253411,"mc":[{"id":"1.230178324","rc":[{"atb":[[5,0]],"id":69769647},{"trd":[[5,1.99]],"ltp":5.0,"tv":1.99,"id":69769647},{"spn":2.33,"spf":1.0,"id":69769647}],"con":true,"img":false}]}
{"op":"mcm","clk":"11541298790","pt":1719504254493,"mc":[{"id":"1.230178324","rc":[{"atb":[[1.03,1]],"id":69769647},{"atl":[[1000,0.05]],"id":69769647}],"con":true,"img":false}]}
{"op":"mcm","clk":"11541298809","pt":1719504254697,"mc":[{"id":"1.230178324","rc":[{"atb":[[1.03,0.74]],"id":69769647},{"atl":[[1000,0]],"id":69769647}],"con":true,"img":false}]}
{"op":"mcm","clk":"11541298818","pt":1719504254802,"mc":[{"id":"1.230178324","rc":[{"atl":[[20,0.05]],"id":69769647}],"con":true,"img":false}]}
{"op":"mcm","clk":"11541298832","pt":1719504254906,"mc":[{"id":"1.230178324","rc":[{"atb":[[1.03,0]],"id":69769647}],"con":true,"img":false}]}
{"op":"mcm","clk":"11541298840","pt":1719504255009,"mc":[{"id":"1.230178324","rc":[{"atb":[[2.36,0.74]],"id":69769647}],"con":true,"img":false}]}
{"op":"mcm","clk":"11541298978","pt":1719504256412,"mc":[{"id":"1.230178324","rc":[{"atb":[[4.5,1]],"id":69769647}],"con":true,"img":false}]}
{"op":"mcm","clk":"11541299850","pt":1719504264597,"mc":[{"id":"1.230178324","rc":[{"atb":[[4.5,0]],"id":69769647},{"trd":[[4.5,1.99]],"ltp":4.5,"tv":1.99,"id":69769647}],"con":true,"img":false}]}
{"op":"mcm","clk":"11541300046","pt":1719504266512,"mc":[{"id":"1.230178324","rc":[{"atb":[[4,1]],"id":69769647}],"con":true,"img":false}]}
{"op":"mcm","clk":"11541300432","pt":1719504269994,"mc":[{"id":"1.230178324","rc":[{"atl":[[20,0]],"id":69769647}],"con":true,"img":false}]}
{"op":"mcm","clk":"11541300456","pt":1719504270202,"mc":[{"id":"1.230178324","rc":[{"atb":[[2.36,0]],"id":69769647}],"con":true,"img":false}]}
{"op":"mcm","clk":"11541300483","pt":1719504270513,"mc":[{"id":"1.230178324","rc":[{"atl":[[1000,0.05]],"id":69769647}],"con":true,"img":false}]}
{"op":"mcm","clk":"11541300500","pt":1719504270720,"mc":[{"id":"1.230178324","rc":[{"atl":[[1000,0]],"id":69769647}],"con":true,"img":false}]}
{"op":"mcm","clk":"11541300509","pt":1719504270825,"mc":[{"id":"1.230178324","rc":[{"atl":[[20,0.05]],"id":69769647}],"con":true,"img":false}]}
{"op":"mcm","clk":"11541301045","pt":1719504276036,"mc":[{"id":"1.230178324","rc":[{"atb":[[4,0]],"id":69769647},{"trd":[[4,1.99]],"ltp":4.0,"tv":1.99,"id":69769647}],"con":true,"img":false}]}
{"op":"mcm","clk":"11541302111","pt":1719504285956,"mc":[{"id":"1.230178324","rc":[{"atl":[[20,0]],"id":69769647}],"con":true,"img":false}]}
{"op":"mcm","clk":"11541302136","pt":1719504286110,"mc":[{"id":"1.230178324","rc":[{"atl":[[1000,0.05]],"id":69769647}],"con":true,"img":false}]}
{"op":"mcm","clk":"11541302142","pt":1719504286206,"mc":[{"id":"1.230178324","rc":[{"atb":[[1.03,1]],"id":69769647}],"con":true,"img":false}]}
{"op":"mcm","clk":"11541302157","pt":1719504286310,"mc":[{"id":"1.230178324","rc":[{"atb":[[1.03,0.74]],"id":69769647},{"atl":[[1000,0]],"id":69769647}],"con":true,"img":false}]}
{"op":"mcm","clk":"11541302170","pt":1719504286416,"mc":[{"id":"1.230178324","rc":[{"atb":[[1.03,0]],"id":69769647},{"atl":[[20,0.05]],"id":69769647}],"con":true,"img":false}]}
{"op":"mcm","clk":"11541302181","pt":1719504286520,"mc":[{"id":"1.230178324","rc":[{"atb":[[2.36,0.74]],"id":69769647}],"con":true,"img":false}]}
{"op":"mcm","clk":"11541303670","pt":1719504299962,"mc":[{"id":"1.230178324","rc":[{"atb":[[2.16,10.21]],"id":63579394}],"con":true,"img":false}]}
{"op":"mcm","clk":"11541303688","pt":1719504300163,"mc":[{"id":"1.230178324","rc":[{"atb":[[1.52,22.8]],"id":69769647}],"con":true,"img":false}]}
{"op":"mcm","clk":"11541303700","pt":1719504300282,"mc":[{"id":"1.230178324","rc":[{"atb":[[2.1,10.78]],"id":70902602}],"con":true,"img":false}]}
{"op":"mcm","clk":"11541303709","pt":1719504300376,"mc":[{"id":"1.230178324","rc":[{"atb":[[2.16,10.21]],"id":45129701}],"con":true,"img":false}]}
{"op":"mcm","clk":"11541303728","pt":1719504300536,"mc":[{"id":"1.230178324","rc":[{"atb":[[2.2,9.87]],"id":40626946}],"con":true,"img":false}]}
{"op":"mcm","clk":"11541303773","pt":1719504300963,"mc":[{"id":"1.230178324","rc":[{"atb":[[2.16,10.21]],"id":57055802}],"con":true,"img":false}]}
{"op":"mcm","clk":"11541303808","pt":1719504301274,"mc":[{"id":"1.230178324","rc":[{"atb":[[2.28,2.09]],"id":40626946},{"atb":[[2.24,2.09]],"id":45129701}],"con":true,"img":false}]}
{"op":"mcm","clk":"11541303863","pt":1719504301638,"mc":[{"id":"1.230178324","rc":[{"atl":[[20,0]],"id":69769647}],"con":true,"img":false}]}
{"op":"mcm","clk":"11541303875","pt":1719504301746,"mc":[{"id":"1.230178324","rc":[{"atb":[[2.36,0]],"id":69769647}],"con":true,"img":false}]}
{"op":"mcm","clk":"11541303929","pt":1719504302275,"mc":[{"id":"1.230178324","rc":[{"atb":[[2.24,2.09]],"id":57055802}],"con":true,"img":false}]}
{"op":"mcm","clk":"11541303946","pt":1719504302480,"mc":[{"id":"1.230178324","rc":[{"atb":[[1.03,1]],"id":69769647},{"atl":[[1000,0.05]],"id":69769647}],"con":true,"img":false}]}
{"op":"mcm","clk":"11541303967","pt":1719504302642,"mc":[{"id":"1.230178324","rc":[{"atb":[[1.03,0.74]],"id":69769647},{"atl":[[1000,0]],"id":69769647}],"con":true,"img":false}]}
{"op":"mcm","clk":"11541303978","pt":1719504302767,"mc":[{"id":"1.230178324","rc":[{"atl":[[20,0.05]],"id":69769647}],"con":true,"img":false}]}
{"op":"mcm","clk":"11541303991","pt":1719504302871,"mc":[{"id":"1.230178324","rc":[{"atb":[[1.03,0]],"id":69769647}],"con":true,"img":false}]}
{"op":"mcm","clk":"11541304001","pt":1719504302973,"mc":[{"id":"1.230178324","rc":[{"atb":[[2.36,0.74]],"id":69769647}],"con":true,"img":false}]}
{"op":"mcm","clk":"11541305522","pt":1719504317869,"mc":[{"id":"1.230178324","rc":[{"atl":[[20,0]],"id":69769647},{"spn":2.33,"spf":1.0,"id":69769647}],"con":true,"img":false}]}
{"op":"mcm","clk":"11541305552","pt":1719504318183,"mc":[{"id":"1.230178324","rc":[{"atb":[[2.36,0]],"id":69769647}],"con":true,"img":false}]}
{"op":"mcm","clk":"11541305582","pt":1719504318495,"mc":[{"id":"1.230178324","rc":[{"atb":[[1.03,1]],"id":69769647},{"atl":[[1000,0.05]],"id":69769647}],"con":true,"img":false}]}
{"op":"mcm","clk":"11541305602","pt":1719504318652,"mc":[{"id":"1.230178324","rc":[{"atb":[[1.03,0.74]],"id":69769647},{"atl":[[1000,0]],"id":69769647}],"con":true,"img":false}]}
{"op":"mcm","clk":"11541305610","pt":1719504318755,"mc":[{"id":"1.230178324","rc":[{"atl":[[20,0.05]],"id":69769647}],"con":true,"img":false}]}
{"op":"mcm","clk":"11541305617","pt":1719504318857,"mc":[{"id":"1.230178324","rc":[{"atb":[[1.03,0]],"id":69769647}],"con":true,"img":false}]}
{"op":"mcm","clk":"11541305621","pt":1719504318961,"mc":[{"id":"1.230178324","rc":[{"atb":[[2.36,0.74]],"id":69769647}],"con":true,"img":false}]}
{"op":"mcm","clk":"11541307131","pt":1719504333995,"mc":[{"id":"1.230178324","rc":[{"atl":[[20,0]],"id":69769647}],"con":true,"img":false}]}
{"op":"mcm","clk":"11541307148","pt":1719504334201,"mc":[{"id":"1.230178324","rc":[{"atb":[[2.36,0]],"id":69769647}],"con":true,"img":false}]}
{"op":"mcm","clk":"11541307172","pt":1719504334514,"mc":[{"id":"1.230178324","rc":[{"atb":[[1.03,1]],"id":69769647},{"atl":[[1000,0.05]],"id":69769647}],"con":true,"img":false}]}
{"op":"mcm","clk":"11541307188","pt":1719504334668,"mc":[{"id":"1.230178324","rc":[{"atb":[[1.03,0.74]],"id":69769647},{"atl":[[1000,0]],"id":69769647}],"con":true,"img":false}]}
{"op":"mcm","clk":"11541307200","pt":1719504334773,"mc":[{"id":"1.230178324","rc":[{"atl":[[20,0.05]],"id":69769647}],"con":true,"img":false}]}
{"op":"mcm","clk":"11541307218","pt":1719504334888,"mc":[{"id":"1.230178324","rc":[{"atb":[[1.03,0]],"id":69769647}],"con":true,"img":false}]}
{"op":"mcm","clk":"11541307226","pt":1719504334980,"mc":[{"id":"1.230178324","rc":[{"atb":[[2.36,0.74]],"id":69769647}],"con":true,"img":false}]}
{"op":"mcm","clk":"11541308928","pt":1719504349885,"mc":[{"id":"1.230178324","rc":[{"atl":[[20,0]],"id":69769647}],"con":true,"img":false}]}
{"op":"mcm","clk":"11541308953","pt":1719504350196,"mc":[{"id":"1.230178324","rc":[{"atb":[[2.36,0]],"id":69769647}],"con":true,"img":false}]}
{"op":"mcm","clk":"11541309042","pt":1719504351189,"mc":[{"id":"1.230178324","rc":[{"atb":[[1.03,1]],"id":69769647},{"atl":[[1000,0.05]],"id":69769647}],"con":true,"img":false}]}
{"op":"mcm","clk":"11541309062","pt":1719504351395,"mc":[{"id":"1.230178324","rc":[{"atb":[[1.03,0.74]],"id":69769647},{"atl":[[1000,0]],"id":69769647}],"con":true,"img":false}]}
{"op":"mcm","clk":"11541309069","pt":1719504351501,"mc":[{"id":"1.230178324","rc":[{"atl":[[20,0.05]],"id":69769647}],"con":true,"img":false}]}
{"op":"mcm","clk":"11541309075","pt":1719504351605,"mc":[{"id":"1.230178324","rc":[{"atb":[[1.03,0]],"id":69769647}],"con":true,"img":false}]}
{"op":"mcm","clk":"11541309085","pt":1719504351711,"mc":[{"id":"1.230178324","rc":[{"atb":[[2.36,0.74]],"id":69769647}],"con":true,"img":false}]}
{"op":"mcm","clk":"11541310612","pt":1719504366729,"mc":[{"id":"1.230178324","rc":[{"atl":[[20,0]],"id":69769647}],"con":true,"img":false}]}
{"op":"mcm","clk":"11541310635","pt":1719504366935,"mc":[{"id":"1.230178324","rc":[{"atb":[[2.36,0]],"id":69769647}],"con":true,"img":false}]}
{"op":"mcm","clk":"11541310654","pt":1719504367100,"mc":[{"id":"1.230178324","rc":[{"atb":[[1.03,1]],"id":69769647},{"atl":[[1000,0.05]],"id":69769647}],"con":true,"img":false}]}
{"op":"mcm","clk":"11541310670","pt":1719504367308,"mc":[{"id":"1.230178324","rc":[{"atb":[[1.03,0.74]],"id":69769647},{"atl":[[1000,0]],"id":69769647}],"con":true,"img":false}]}
{"op":"mcm","clk":"11541310682","pt":1719504367405,"mc":[{"id":"1.230178324","rc":[{"atl":[[20,0.05]],"id":69769647}],"con":true,"img":false}]}
{"op":"mcm","clk":"11541310691","pt":1719504367507,"mc":[{"id":"1.230178324","rc":[{"atb":[[1.03,0]],"id":69769647}],"con":true,"img":false}]}
{"op":"mcm","clk":"11541310702","pt":1719504367611,"mc":[{"id":"1.230178324","rc":[{"atb":[[2.36,0.74]],"id":69769647}],"con":true,"img":false}]}
{"op":"mcm","clk":"11541312047","pt":1719504382719,"mc":[{"id":"1.230178324","rc":[{"atl":[[20,0]],"id":69769647}],"con":true,"img":false}]}
{"op":"mcm","clk":"11541312063","pt":1719504382922,"mc":[{"id":"1.230178324","rc":[{"atb":[[2.36,0]],"id":69769647}],"con":true,"img":false}]}
{"op":"mcm","clk":"11541312183","pt":1719504383951,"mc":[{"id":"1.230178324","rc":[{"atb":[[1.03,1]],"id":69769647},{"atl":[[1000,0.05]],"id":69769647}],"con":true,"img":false}]}
{"op":"mcm","clk":"11541312204","pt":1719504384125,"mc":[{"id":"1.230178324","rc":[{"atb":[[1.03,0.74]],"id":69769647},{"atl":[[1000,0]],"id":69769647}],"con":true,"img":false}]}
{"op":"mcm","clk":"11541312213","pt":1719504384226,"mc":[{"id":"1.230178324","rc":[{"atl":[[20,0.05]],"id":69769647}],"con":true,"img":false}]}
{"op":"mcm","clk":"11541312224","pt":1719504384329,"mc":[{"id":"1.230178324","rc":[{"atb":[[1.03,0]],"id":69769647}],"con":true,"img":false}]}
{"op":"mcm","clk":"11541312233","pt":1719504384426,"mc":[{"id":"1.230178324","rc":[{"atb":[[2.36,0.74]],"id":69769647}],"con":true,"img":false}]}
{"op":"mcm","clk":"11541313473","pt":1719504399544,"mc":[{"id":"1.230178324","rc":[{"atl":[[20,0]],"id":69769647}],"con":true,"img":false}]}
{"op":"mcm","clk":"11541313480","pt":1719504399645,"mc":[{"id":"1.230178324","rc":[{"atb":[[2.36,0]],"id":69769647}],"con":true,"img":false}]}
{"op":"mcm","clk":"11541313533","pt":1719504400268,"mc":[{"id":"1.230178324","rc":[{"atb":[[1.03,1]],"id":69769647},{"atl":[[1000,0.05]],"id":69769647}],"con":true,"img":false}]}
{"op":"mcm","clk":"11541313564","pt":1719504400537,"mc":[{"id":"1.230178324","rc":[{"atb":[[1.03,0.74]],"id":69769647},{"atl":[[1000,0]],"id":69769647}],"con":true,"img":false}]}
{"op":"mcm","clk":"11541313574","pt":1719504400640,"mc":[{"id":"1.230178324","rc":[{"atl":[[20,0.05]],"id":69769647}],"con":true,"img":false}]}
{"op":"mcm","clk":"11541313586","pt":1719504400745,"mc":[{"id":"1.230178324","rc":[{"atb":[[1.03,0]],"id":69769647}],"con":true,"img":false}]}
{"op":"mcm","clk":"11541313596","pt":1719504400847,"mc":[{"id":"1.230178324","rc":[{"atb":[[2.36,0.74]],"id":69769647}],"con":true,"img":false}]}
{"op":"mcm","clk":"11541315031","pt":1719504415853,"mc":[{"id":"1.230178324","rc":[{"atl":[[20,0]],"id":69769647}],"con":true,"img":false}]}
{"op":"mcm","clk":"11541315058","pt":1719504416072,"mc":[{"id":"1.230178324","rc":[{"atb":[[2.36,0]],"id":69769647}],"con":true,"img":false}]}
{"op":"mcm","clk":"11541315080","pt":1719504416277,"mc":[{"id":"1.230178324","rc":[{"atb":[[1.03,1]],"id":69769647},{"atl":[[1000,0.05]],"id":69769647}],"con":true,"img":false}]}
{"op":"mcm","clk":"11541315104","pt":1719504416482,"mc":[{"id":"1.230178324","rc":[{"atb":[[1.03,0.74]],"id":69769647},{"atl":[[1000,0]],"id":69769647}],"con":true,"img":false}]}
{"op":"mcm","clk":"11541315112","pt":1719504416579,"mc":[{"id":"1.230178324","rc":[{"atl":[[20,0.05]],"id":69769647}],"con":true,"img":false}]}
{"op":"mcm","clk":"11541315125","pt":1719504416683,"mc":[{"id":"1.230178324","rc":[{"atb":[[1.03,0]],"id":69769647}],"con":true,"img":false}]}
{"op":"mcm","clk":"11541315136","pt":1719504416785,"mc":[{"id":"1.230178324","rc":[{"atb":[[2.36,0.74]],"id":69769647}],"con":true,"img":false}]}
{"op":"mcm","clk":"11541316594","pt":1719504431789,"mc":[{"id":"1.230178324","rc":[{"atl":[[20,0]],"id":69769647}],"con":true,"img":false}]}
{"op":"mcm","clk":"11541316616","pt":1719504431998,"mc":[{"id":"1.230178324","rc":[{"atb":[[2.36,0]],"id":69769647}],"con":true,"img":false}]}
{"op":"mcm","clk":"11541316657","pt":1719504432372,"mc":[{"id":"1.230178324","rc":[{"atb":[[1.03,1]],"id":69769647},{"atl":[[1000,0.05]],"id":69769647}],"con":true,"img":false}]}
{"op":"mcm","clk":"11541316676","pt":1719504432579,"mc":[{"id":"1.230178324","rc":[{"atb":[[1.03,0.74]],"id":69769647},{"atl":[[1000,0]],"id":69769647}],"con":true,"img":false}]}
{"op":"mcm","clk":"11541316695","pt":1719504432792,"mc":[{"id":"1.230178324","rc":[{"atl":[[20,0.05]],"id":69769647}],"con":true,"img":false}]}
{"op":"mcm","clk":"11541316707","pt":1719504432891,"mc":[{"id":"1.230178324","rc":[{"atb":[[1.03,0]],"id":69769647}],"con":true,"img":false}]}
{"op":"mcm","clk":"11541316721","pt":1719504433017,"mc":[{"id":"1.230178324","rc":[{"atb":[[2.36,0.74]],"id":69769647}],"con":true,"img":false}]}
{"op":"mcm","clk":"11541316989","pt":1719504436292,"mc":[{"id":"1.230178324","rc":[{"atl":[[25,0.84]],"id":70902602},{"atl":[[32,0.84]],"id":40626946},{"atl":[[32,0.84]],"id":45129701}],"con":true,"img":false}]}
{"op":"mcm","clk":"11541317997","pt":1719504447997,"mc":[{"id":"1.230178324","rc":[{"spn":14.37,"spf":"NaN","id":70902602},{"atl":[[20,0]],"id":69769647},{"spn":18.35,"spf":"NaN","id":40626946},{"spn":18.5,"spf":"NaN","id":45129701}],"con":true,"img":false}]}
{"op":"mcm","clk":"11541318016","pt":1719504448205,"mc":[{"id":"1.230178324","rc":[{"atb":[[2.36,0]],"id":69769647}],"con":true,"img":false}]}
{"op":"mcm","clk":"11541318059","pt":1719504448722,"mc":[{"id":"1.230178324","rc":[{"atb":[[1.03,1]],"id":69769647},{"atl":[[1000,0.05]],"id":69769647}],"con":true,"img":false}]}
{"op":"mcm","clk":"11541318080","pt":1719504448984,"mc":[{"id":"1.230178324","rc":[{"atb":[[1.03,0.74]],"id":69769647},{"atl":[[1000,0]],"id":69769647}],"con":true,"img":false}]}
{"op":"mcm","clk":"11541318089","pt":1719504449089,"mc":[{"id":"1.230178324","rc":[{"atl":[[20,0.05]],"id":69769647}],"con":true,"img":false}]}
{"op":"mcm","clk":"11541318097","pt":1719504449191,"mc":[{"id":"1.230178324","rc":[{"atb":[[1.03,0]],"id":69769647}],"con":true,"img":false}]}
{"op":"mcm","clk":"11541318105","pt":1719504449293,"mc":[{"id":"1.230178324","rc":[{"atb":[[2.36,0.74]],"id":69769647}],"con":true,"img":false}]}
{"op":"mcm","clk":"11541318243","pt":1719504450999,"mc":[{"id":"1.230178324","rc":[{"atb":[[5,2.02]],"id":63579394}],"con":true,"img":false}]}
{"op":"mcm","clk":"11541319068","pt":1719504461626,"mc":[{"id":"1.230178324","rc":[{"atb":[[2.18,3.14]],"id":69769647}],"con":true,"img":false}]}
{"op":"mcm","clk":"11541319100","pt":1719504461988,"mc":[{"id":"1.230178324","rc":[{"atb":[[2.18,0]],"id":69769647}],"con":true,"img":false}]}
{"op":"mcm","clk":"11541319289","pt":1719504464321,"mc":[{"id":"1.230178324","rc":[{"atl":[[20,0]],"id":69769647}],"con":true,"img":false}]}
{"op":"mcm","clk":"11541319307","pt":1719504464530,"mc":[{"id":"1.230178324","rc":[{"atb":[[2.36,0]],"id":69769647}],"con":true,"img":false}]}
{"op":"mcm","clk":"11541319339","pt":1719504464893,"mc":[{"id":"1.230178324","rc":[{"atb":[[1.03,1]],"id":69769647},{"atl":[[1000,0.05]],"id":69769647}],"con":true,"img":false}]}
{"op":"mcm","clk":"11541319357","pt":1719504465152,"mc":[{"id":"1.230178324","rc":[{"atb":[[1.03,0.74]],"id":69769647},{"atl":[[1000,0]],"id":69769647}],"con":true,"img":false}]}
{"op":"mcm","clk":"11541319369","pt":1719504465204,"mc":[{"id":"1.230178324","rc":[{"atl":[[20,0.05]],"id":69769647}],"con":true,"img":false}]}
{"op":"mcm","clk":"11541319387","pt":1719504465413,"mc":[{"id":"1.230178324","rc":[{"atb":[[1.03,0]],"id":69769647}],"con":true,"img":false}]}
{"op":"mcm","clk":"11541319396","pt":1719504465515,"mc":[{"id":"1.230178324","rc":[{"atb":[[2.36,0.74]],"id":69769647}],"con":true,"img":false}]}
{"op":"mcm","clk":"11541320487","pt":1719504480440,"mc":[{"id":"1.230178324","rc":[{"atl":[[20,0]],"id":69769647}],"con":true,"img":false}]}
{"op":"mcm","clk":"11541320529","pt":1719504480857,"mc":[{"id":"1.230178324","rc":[{"atb":[[2.36,0]],"id":69769647}],"con":true,"img":false}]}
{"op":"mcm","clk":"11541320621","pt":1719504482112,"mc":[{"id":"1.230178324","rc":[{"atb":[[1.03,1]],"id":69769647},{"atl":[[1000,0.05]],"id":69769647}],"con":true,"img":false}]}
{"op":"mcm","clk":"11541320655","pt":1719504482704,"mc":[{"id":"1.230178324","rc":[{"atb":[[1.03,0.74]],"id":69769647},{"atl":[[1000,0]],"id":69769647}],"con":true,"img":false}]}
{"op":"mcm","clk":"11541320666","pt":1719504482718,"mc":[{"id":"1.230178324","rc":[{"atl":[[20,0.05]],"id":69769647}],"con":true,"img":false}]}
{"op":"mcm","clk":"11541320675","pt":1719504482739,"mc":[{"id":"1.230178324","rc":[{"atb":[[1.03,0]],"id":69769647}],"con":true,"img":false}]}
{"op":"mcm","clk":"11541320681","pt":1719504482830,"mc":[{"id":"1.230178324","rc":[{"atb":[[2.36,0.74]],"id":69769647}],"con":true,"img":false}]}
{"op":"mcm","clk":"11541321185","pt":1719504488928,"mc":[{"id":"1.230178324","rc":[{"atb":[[2.14,0]],"id":63579394},{"atb":[[2.08,0]],"id":70902602},{"atb":[[2.14,0]],"id":57055802},{"atb":[[2.18,0]],"id":40626946},{"atb":[[2.14,0]],"id":45129701}],"con":true,"img":false}]}
{"op":"mcm","clk":"11541321196","pt":1719504489033,"mc":[{"id":"1.230178324","rc":[{"atb":[[2.18,8.63]],"id":63579394},{"atb":[[2.12,8.54]],"id":70902602},{"atb":[[2.18,11.96]],"id":57055802},{"atb":[[2.22,12.55]],"id":40626946},{"atb":[[2.18,10.25]],"id":45129701}],"con":true,"img":false}]}
{"op":"mcm","clk":"11541321257","pt":1719504489760,"mc":[{"id":"1.230178324","rc":[{"atb":[[2.26,2.09]],"id":63579394}],"con":true,"img":false}]}
{"op":"mcm","clk":"11541321840","pt":1719504497822,"mc":[{"id":"1.230178324","rc":[{"atl":[[20,0]],"id":69769647}],"con":true,"img":false}]}
{"op":"mcm","clk":"11541321863","pt":1719504498131,"mc":[{"id":"1.230178324","rc":[{"atb":[[2.36,0]],"id":69769647}],"con":true,"img":false}]}
{"op":"mcm","clk":"11541321918","pt":1719504498963,"mc":[{"id":"1.230178324","rc":[{"atb":[[1.03,1]],"id":69769647},{"atl":[[1000,0.05]],"id":69769647}],"con":true,"img":false}]}
{"op":"mcm","clk":"11541321928","pt":1719504499130,"mc":[{"id":"1.230178324","rc":[{"atb":[[1.03,0.74]],"id":69769647},{"atl":[[1000,0]],"id":69769647}],"con":true,"img":false}]}
{"op":"mcm","clk":"11541321936","pt":1719504499229,"mc":[{"id":"1.230178324","rc":[{"atl":[[20,0.05]],"id":69769647}],"con":true,"img":false}]}
{"op":"mcm","clk":"11541321942","pt":1719504499334,"mc":[{"id":"1.230178324","rc":[{"atb":[[1.03,0]],"id":69769647}],"con":true,"img":false}]}
{"op":"mcm","clk":"11541321957","pt":1719504499536,"mc":[{"id":"1.230178324","rc":[{"atb":[[2.36,0.74]],"id":69769647}],"con":true,"img":false}]}
{"op":"mcm","clk":"11541323088","pt":1719504514764,"mc":[{"id":"1.230178324","rc":[{"atl":[[20,0]],"id":69769647}],"con":true,"img":false}]}
{"op":"mcm","clk":"11541323094","pt":1719504514870,"mc":[{"id":"1.230178324","rc":[{"atb":[[2.36,0]],"id":69769647}],"con":true,"img":false}]}
{"op":"mcm","clk":"11541323111","pt":1719504515079,"mc":[{"id":"1.230178324","rc":[{"atb":[[1.03,1]],"id":69769647},{"atl":[[1000,0.05]],"id":69769647}],"con":true,"img":false}]}
{"op":"mcm","clk":"11541323126","pt":1719504515239,"mc":[{"id":"1.230178324","rc":[{"atb":[[1.03,0.74]],"id":69769647},{"atl":[[1000,0]],"id":69769647}],"con":true,"img":false}]}
{"op":"mcm","clk":"11541323137","pt":1719504515342,"mc":[{"id":"1.230178324","rc":[{"atl":[[20,0.05]],"id":69769647}],"con":true,"img":false}]}
{"op":"mcm","clk":"11541323145","pt":1719504515447,"mc":[{"id":"1.230178324","rc":[{"atb":[[1.03,0]],"id":69769647}],"con":true,"img":false}]}
{"op":"mcm","clk":"11541323153","pt":1719504515553,"mc":[{"id":"1.230178324","rc":[{"atb":[[2.36,0.74]],"id":69769647}],"con":true,"img":false}]}
{"op":"mcm","clk":"11541323955","pt":1719504525978,"mc":[{"id":"1.230178324","rc":[{"atb":[[2.16,0]],"id":63579394},{"atb":[[2.1,0]],"id":70902602},{"atb":[[2.16,0]],"id":57055802},{"atb":[[2.2,0]],"id":40626946},{"atb":[[2.16,0]],"id":45129701}],"con":true,"img":false}]}
{"op":"mcm","clk":"11541324282","pt":1719504530579,"mc":[{"id":"1.230178324","rc":[{"atl":[[20,0]],"id":69769647}],"con":true,"img":false}]}
{"op":"mcm","clk":"11541324303","pt":1719504530882,"mc":[{"id":"1.230178324","rc":[{"atb":[[2.36,0]],"id":69769647}],"con":true,"img":false}]}
{"op":"mcm","clk":"11541324317","pt":1719504531084,"mc":[{"id":"1.230178324","rc":[{"atb":[[1.03,1]],"id":69769647},{"atl":[[1000,0.05]],"id":69769647}],"con":true,"img":false}]}
{"op":"mcm","clk":"11541324331","pt":1719504531291,"mc":[{"id":"1.230178324","rc":[{"atb":[[1.03,0.74]],"id":69769647},{"atl":[[1000,0]],"id":69769647}],"con":true,"img":false}]}
{"op":"mcm","clk":"11541324341","pt":1719504531352,"mc":[{"id":"1.230178324","rc":[{"atl":[[20,0.05]],"id":69769647}],"con":true,"img":false}]}
{"op":"mcm","clk":"11541324351","pt":1719504531449,"mc":[{"id":"1.230178324","rc":[{"atb":[[1.03,0]],"id":69769647}],"con":true,"img":false}]}
{"op":"mcm","clk":"11541324359","pt":1719504531556,"mc":[{"id":"1.230178324","rc":[{"atb":[[2.36,0.74]],"id":69769647}],"con":true,"img":false}]}
{"op":"mcm","clk":"11541324674","pt":1719504535796,"mc":[{"id":"1.230178324","rc":[{"atb":[[2.2,9.87]],"id":63579394}],"con":true,"img":false}]}
{"op":"mcm","clk":"11541324691","pt":1719504536000,"mc":[{"id":"1.230178324","rc":[{"atb":[[2.24,9.56]],"id":40626946}],"con":true,"img":false}]}
{"op":"mcm","clk":"11541324707","pt":1719504536206,"mc":[{"id":"1.230178324","rc":[{"atb":[[2.14,10.4]],"id":70902602},{"atb":[[2.2,9.87]],"id":45129701}],"con":true,"img":false}]}
{"op":"mcm","clk":"11541324722","pt":1719504536367,"mc":[{"id":"1.230178324","rc":[{"atb":[[2.2,9.87]],"id":57055802}],"con":true,"img":false}]}
{"op":"mcm","clk":"11541324826","pt":1719504537984,"mc":[{"id":"1.230178324","rc":[{"atb":[[1.06,1.69]],"id":69769647}],"con":true,"img":false}]}
{"op":"mcm","clk":"11541324836","pt":1719504538182,"mc":[{"id":"1.230178324","rc":[{"atb":[[1.09,1.69]],"id":70902602},{"atb":[[1.12,1.69]],"id":63579394}],"con":true,"img":false}]}
{"op":"mcm","clk":"11541324849","pt":1719504538386,"mc":[{"id":"1.230178324","rc":[{"atb":[[1.1,1.69]],"id":40626946},{"atb":[[1.12,1.69]],"id":45129701}],"con":true,"img":false}]}
{"op":"mcm","clk":"11541324873","pt":1719504538696,"mc":[{"id":"1.230178324","rc":[{"atb":[[1.12,0.05]],"id":63579394}],"con":true,"img":false}]}
{"op":"mcm","clk":"11541324880","pt":1719504538800,"mc":[{"id":"1.230178324","rc":[{"atb":[[1.12,1.69]],"id":57055802}],"con":true,"img":false}]}
{"op":"mcm","clk":"11541324897","pt":1719504539008,"mc":[{"id":"1.230178324","rc":[{"atb":[[1.06,0.12]],"id":69769647}],"con":true,"img":false}]}
{"op":"mcm","clk":"11541324904","pt":1719504539074,"mc":[{"id":"1.230178324","rc":[{"atb":[[1.12,0]],"id":63579394}],"con":true,"img":false}]}
{"op":"mcm","clk":"11541324912","pt":1719504539216,"mc":[{"id":"1.230178324","rc":[{"atb":[[5.1,0.05]],"id":63579394},{"atb":[[1.1,0.06]],"id":40626946}],"con":true,"img":false}]}
{"op":"mcm","clk":"11541324935","pt":1719504539482,"mc":[{"id":"1.230178324","rc":[{"atb":[[1.09,0.07]],"id":70902602},{"atb":[[1.12,0.05]],"id":45129701}],"con":true,"img":false}]}
{"op":"mcm","clk":"11541324966","pt":1719504539793,"mc":[{"id":"1.230178324","rc":[{"atb":[[1.06,0]],"id":69769647},{"atb":[[1.12,0.05]],"id":57055802}],"con":true,"img":false}]}
{"op":"mcm","clk":"11541324973","pt":1719504539898,"mc":[{"id":"1.230178324","rc":[{"atb":[[2.36,0.86]],"id":69769647}],"con":true,"img":false}]}
{"op":"mcm","clk":"11541324999","pt":1719504540214,"mc":[{"id":"1.230178324","rc":[{"atb":[[1.1,0]],"id":40626946}],"con":true,"img":false}]}
{"op":"mcm","clk":"11541325009","pt":1719504540283,"mc":[{"id":"1.230178324","rc":[{"atb":[[4.8,0.06],[3.35,6]],"id":40626946},{"atl":[[34,4.77]],"id":40626946}],"con":true,"img":false}]}
{"op":"mcm","clk":"11541325015","pt":1719504540375,"mc":[{"id":"1.230178324","rc":[{"atb":[[2.9,6]],"id":70902602},{"atl":[[26,5.71]],"id":70902602},{"atb":[[3.85,6]],"id":63579394},{"atl":[[130,2]],"id":63579394},{"atb":[[2.36,4.02]],"id":69769647},{"atl":[[20,5.31]],"id":69769647},{"atb":[[4.2,6]],"id":57055802},{"atl":[[140,2]],"id":57055802},{"atb":[[3.6,6]],"id":45129701},{"atl":[[34,4.7]],"id":45129701}],"con":true,"img":false}]}
{"op":"mcm","clk":"11541325027","pt":1719504540588,"mc":[{"id":"1.230178324","rc":[{"atb":[[1.12,0]],"id":45129701}],"con":true,"img":false}]}
{"op":"mcm","clk":"11541325032","pt":1719504540683,"mc":[{"id":"1.230178324","rc":[{"atb":[[5.1,0.05]],"id":45129701}],"con":true,"img":false}]}
{"op":"mcm","clk":"11541325053","pt":1719504540995,"mc":[{"id":"1.230178324","rc":[{"atb":[[1.09,0]],"id":70902602}],"con":true,"img":false}]}
{"op":"mcm","clk":"11541325060","pt":1719504541096,"mc":[{"id":"1.230178324","rc":[{"atb":[[3.8,0.07]],"id":70902602}],"con":true,"img":false}]}
{"op":"mcm","clk":"11541325084","pt":1719504541406,"mc":[{"id":"1.230178324","rc":[{"atb":[[1.12,0]],"id":57055802}],"con":true,"img":false}]}
{"op":"mcm","clk":"11541325091","pt":1719504541512,"mc":[{"id":"1.230178324","rc":[{"atb":[[5.1,0.05]],"id":57055802}],"con":true,"img":false}]}
{"op":"mcm","clk":"11541325427","pt":1719504545912,"mc":[{"id":"1.230178324","rc":[{"atb":[[1.03,1.7]],"id":63579394},{"atl":[[1000,1.7]],"id":63579394},{"atb":[[1.01,1.7]],"id":69769647},{"atl":[[1000,1.7]],"id":69769647},{"atb":[[1.02,3.7]],"id":40626946},{"atl":[[1000,1.93]],"id":40626946}],"con":true,"img":false}]}
{"op":"mcm","clk":"11541325451","pt":1719504546222,"mc":[{"id":"1.230178324","rc":[{"atb":[[1.03,0.07]],"id":63579394},{"atl":[[1000,0]],"id":63579394},{"atb":[[1.01,0.23]],"id":69769647},{"atl":[[1000,0.01]],"id":69769647},{"atb":[[1.02,2.13]],"id":40626946},{"atl":[[1000,0.23]],"id":40626946}],"con":true,"img":false}]}
{"op":"mcm","clk":"11541325466","pt":1719504546386,"mc":[{"id":"1.230178324","rc":[{"atb":[[1.03,0]],"id":63579394},{"atb":[[1.01,0]],"id":69769647},{"atl":[[1000,0]],"id":69769647},{"atb":[[1.02,2]],"id":40626946},{"atl":[[1000,0.22]],"id":40626946}],"con":true,"img":false}]}
{"op":"mcm","clk":"11541325471","pt":1719504546481,"mc":[{"id":"1.230178324","rc":[{"atb":[[5.1,0.13]],"id":63579394},{"atb":[[2.38,0.23]],"id":69769647},{"atl":[[19.5,0.01],[20,5.26]],"id":69769647},{"atb":[[3.4,0.13]],"id":40626946},{"atl":[[32,0.85]],"id":40626946}],"con":true,"img":false}]}
{"op":"mcm","clk":"11541325488","pt":1719504546792,"mc":[{"id":"1.230178324","rc":[{"atb":[[2.36,3.28]],"id":69769647}],"con":true,"img":false}]}
{"op":"mcm","clk":"11541325514","pt":1719504547206,"mc":[{"id":"1.230178324","rc":[{"atb":[[1.03,1]],"id":69769647},{"atl":[[1000,0.05]],"id":69769647}],"con":true,"img":false}]}
{"op":"mcm","clk":"11541325523","pt":1719504547309,"mc":[{"id":"1.230178324","rc":[{"atb":[[1.03,0.72]],"id":69769647},{"atl":[[1000,0]],"id":69769647}],"con":true,"img":false}]}
{"op":"mcm","clk":"11541325532","pt":1719504547412,"mc":[{"id":"1.230178324","rc":[{"atl":[[19.5,0.06]],"id":69769647}],"con":true,"img":false}]}
{"op":"mcm","clk":"11541325539","pt":1719504547514,"mc":[{"id":"1.230178324","rc":[{"atb":[[1.03,0]],"id":69769647}],"con":true,"img":false}]}
{"op":"mcm","clk":"11541325548","pt":1719504547618,"mc":[{"id":"1.230178324","rc":[{"atb":[[2.38,0.95]],"id":69769647}],"con":true,"img":false}]}
{"op":"mcm","clk":"11541325968","pt":1719504553623,"mc":[{"id":"1.230178324","rc":[{"atb":[[2.88,0]],"id":70902602}],"con":true,"img":false}]}
{"op":"mcm","clk":"11541325982","pt":1719504553790,"mc":[{"id":"1.230178324","rc":[{"atb":[[2.92,3.16]],"id":70902602}],"con":true,"img":false}]}
{"op":"mcm","clk":"11541326492","pt":1719504560703,"mc":[{"id":"1.230178324","rc":[{"atl":[[7.2,1]],"id":70902602},{"atl":[[12.5,1]],"id":63579394},{"atb":[[2.54,1]],"id":69769647},{"atl":[[9.2,1]],"id":69769647},{"atb":[[4.6,1]],"id":57055802},{"atl":[[17,1]],"id":57055802},{"atl":[[10.5,1]],"id":40626946},{"atl":[[11.5,1]],"id":45129701}],"con":true,"img":false}]}
{"op":"mcm","clk":"11541326503","pt":1719504560801,"mc":[{"id":"1.230178324","rc":[{"atl":[[130,0],[100,2]],"id":63579394},{"atb":[[4.6,7],[4.2,0]],"id":57055802}],"con":true,"img":false}]}
{"op":"mcm","clk":"11541326545","pt":1719504561214,"mc":[{"id":"1.230178324","rc":[{"atl":[[7.2,0]],"id":70902602},{"trd":[[7.2,1.99]],"ltp":7.2,"tv":1.99,"id":70902602}],"con":true,"img":false}]}
{"op":"mcm","clk":"11541326657","pt":1719504562607,"mc":[{"id":"1.230178324","rc":[{"atb":[[1.06,1]],"id":70902602},{"atl":[[1000,0.04]],"id":70902602},{"atl":[[19.5,0.01]],"id":69769647}],"con":true,"img":false}]}
{"op":"mcm","clk":"11541326666","pt":1719504562708,"mc":[{"id":"1.230178324","rc":[{"atb":[[1.06,0.36]],"id":70902602}],"con":true,"img":false}]}
{"op":"mcm","clk":"11541326676","pt":1719504562815,"mc":[{"id":"1.230178324","rc":[{"atl":[[1000,0]],"id":70902602},{"atb":[[2.38,0.23]],"id":69769647}],"con":true,"img":false}]}
{"op":"mcm","clk":"11541326686","pt":1719504562921,"mc":[{"id":"1.230178324","rc":[{"atb":[[1.06,0]],"id":70902602},{"atl":[[25,0.88]],"id":70902602}],"con":true,"img":false}]}
{"op":"mcm","clk":"11541326695","pt":1719504563022,"mc":[{"id":"1.230178324","rc":[{"atb":[[3.8,0.43]],"id":70902602}],"con":true,"img":false}]}
{"op":"mcm","clk":"11541326705","pt":1719504563126,"mc":[{"id":"1.230178324","rc":[{"atb":[[1.04,1]],"id":69769647},{"atl":[[1000,0.12]],"id":69769647}],"con":true,"img":false}]}
{"op":"mcm","clk":"11541326714","pt":1719504563224,"mc":[{"id":"1.230178324","rc":[{"atb":[[1.04,0.64]],"id":69769647},{"atl":[[1000,0]],"id":69769647}],"con":true,"img":false}]}
{"op":"mcm","clk":"11541326721","pt":1719504563328,"mc":[{"id":"1.230178324","rc":[{"atl":[[9,0.12]],"id":69769647}],"con":true,"img":false}]}
{"op":"mcm","clk":"11541326731","pt":1719504563432,"mc":[{"id":"1.230178324","rc":[{"atb":[[1.04,0]],"id":69769647}],"con":true,"img":false}]}
{"op":"mcm","clk":"11541326737","pt":1719504563533,"mc":[{"id":"1.230178324","rc":[{"atb":[[2.56,0.64]],"id":69769647}],"con":true,"img":false}]}
{"op":"mcm","clk":"11541327288","pt":1719504570711,"mc":[{"id":"1.230178324","rc":[{"atl":[[7.2,1]],"id":70902602}],"con":true,"img":false}]}
{"op":"mcm","clk":"11541327405","pt":1719504572137,"mc":[{"id":"1.230178324","rc":[{"atb":[[2.54,0],[3.2,1]],"id":69769647}],"con":true,"img":false}]}
{"op":"mcm","clk":"11541327423","pt":1719504572346,"mc":[{"id":"1.230178324","rc":[{"atb":[[2.54,2],[2.36,0.12]],"id":69769647}],"con":true,"img":false}]}
{"op":"mcm","clk":"11541327444","pt":1719504572548,"mc":[{"id":"1.230178324","rc":[{"atb":[[2.54,0],[2.38,3.39]],"id":69769647}],"con":true,"img":false}]}
{"op":"mcm","clk":"11541327504","pt":1719504573121,"mc":[{"id":"1.230178324","rc":[{"atl":[[7.2,0]],"id":70902602},{"trd":[[7.2,3.99]],"ltp":7.2,"tv":3.99,"id":70902602}],"con":true,"img":false}]}
{"op":"mcm","clk":"11541327541","pt":1719504573533,"mc":[{"id":"1.230178324","rc":[{"atb":[[2.54,1],[3.2,0]],"id":69769647}],"con":true,"img":false}]}
{"op":"mcm","clk":"11541327960","pt":1719504578165,"mc":[{"id":"1.230178324","rc":[{"atl":[[25,0.84]],"id":70902602},{"spn":14.4,"spf":"NaN","id":70902602},{"spn":8.8,"spf":"NaN","id":63579394},{"spn":2.43,"spf":1.0,"id":69769647},{"spn":11.05,"spf":"NaN","id":57055802},{"spn":7.65,"spf":"NaN","id":40626946},{"spn":8.3,"spf":"NaN","id":45129701}],"con":true,"img":false}]}
{"op":"mcm","clk":"11541327967","pt":1719504578247,"mc":[{"id":"1.230178324","rc":[{"atb":[[3.8,0.07]],"id":70902602}],"con":true,"img":false}]}
{"op":"mcm","clk":"11541327994","pt":1719504578552,"mc":[{"id":"1.230178324","rc":[{"atb":[[1.06,1]],"id":70902602},{"atl":[[1000,0.04]],"id":70902602},{"atl":[[9,0]],"id":69769647}],"con":true,"img":false}]}
{"op":"mcm","clk":"11541328012","pt":1719504578760,"mc":[{"id":"1.230178324","rc":[{"atb":[[1.06,0.36]],"id":70902602},{"atl":[[1000,0]],"id":70902602}],"con":true,"img":false}]}
{"op":"mcm","clk":"11541328022","pt":1719504578817,"mc":[{"id":"1.230178324","rc":[{"atl":[[25,0.88]],"id":70902602},{"atb":[[2.56,0]],"id":69769647}],"con":true,"img":false}]}
{"op":"mcm","clk":"11541328031","pt":1719504578918,"mc":[{"id":"1.230178324","rc":[{"atb":[[1.06,0]],"id":70902602}],"con":true,"img":false}]}
{"op":"mcm","clk":"11541328041","pt":1719504579027,"mc":[{"id":"1.230178324","rc":[{"atb":[[3.8,0.43]],"id":70902602}],"con":true,"img":false}]}
{"op":"mcm","clk":"11541328183","pt":1719504580058,"mc":[{"id":"1.230178324","rc":[{"atb":[[1.04,1]],"id":69769647},{"atl":[[1000,0.12]],"id":69769647}],"con":true,"img":false}]}
{"op":"mcm","clk":"11541328202","pt":1719504580257,"mc":[{"id":"1.230178324","rc":[{"atb":[[1.04,0.64]],"id":69769647},{"atl":[[1000,0]],"id":69769647}],"con":true,"img":false}]}
{"op":"mcm","clk":"11541328213","pt":1719504580319,"mc":[{"id":"1.230178324","rc":[{"atl":[[9,0.12]],"id":69769647}],"con":true,"img":false}]}
{"op":"mcm","clk":"11541328231","pt":1719504580520,"mc":[{"id":"1.230178324","rc":[{"atb":[[1.04,0]],"id":69769647}],"con":true,"img":false}]}
{"op":"mcm","clk":"11541328240","pt":1719504580621,"mc":[{"id":"1.230178324","rc":[{"atb":[[2.56,0.64]],"id":69769647}],"con":true,"img":false}]}
{"op":"mcm","clk":"11541328248","pt":1719504580725,"mc":[{"id":"1.230178324","rc":[{"atl":[[7.2,1]],"id":70902602}],"con":true,"img":false}]}
{"op":"mcm","clk":"11541328316","pt":1719504581652,"mc":[{"id":"1.230178324","rc":[{"atl":[[7.2,0]],"id":70902602},{"trd":[[7.2,5.99]],"ltp":7.2,"tv":5.99,"id":70902602}],"con":true,"img":false}]}
{"op":"mcm","clk":"11541328333","pt":1719504581859,"mc":[{"id":"1.230178324","rc":[{"atb":[[3.8,5.01]],"id":70902602}],"con":true,"img":false}]}
{"op":"mcm","clk":"11541328913","pt":1719504588755,"mc":[{"id":"1.230178324","rc":[{"atb":[[5.1,0.05]],"id":63579394},{"atb":[[2.38,3.16]],"id":69769647},{"atl":[[19.5,0]],"id":69769647},{"atb":[[3.4,0]],"id":40626946},{"atl":[[32,0.84]],"id":40626946}],"con":true,"img":false}]}
{"op":"mcm","clk":"11541329085","pt":1719504590726,"mc":[{"id":"1.230178324","rc":[{"atl":[[7.2,1]],"id":70902602}],"con":true,"img":false}]}
{"op":"mcm","clk":"11541329201","pt":1719504592028,"mc":[{"id":"1.230178324","rc":[{"atb":[[2.92,0]],"id":70902602}],"con":true,"img":false}]}
{"op":"mcm","clk":"11541329336","pt":1719504593635,"mc":[{"id":"1.230178324","rc":[{"atl":[[7.2,0]],"id":70902602},{"trd":[[7.2,7.99]],"ltp":7.2,"tv":7.99,"id":70902602}],"con":true,"img":false}]}
{"op":"mcm","clk":"11541329380","pt":1719504594046,"mc":[{"id":"1.230178324","rc":[{"atl":[[25,0.84]],"id":70902602}],"con":true,"img":false}]}
{"op":"mcm","clk":"11541329403","pt":1719504594250,"mc":[{"id":"1.230178324","rc":[{"atb":[[3.8,4.65]],"id":70902602}],"con":true,"img":false}]}
{"op":"mcm","clk":"11541329427","pt":1719504594563,"mc":[{"id":"1.230178324","rc":[{"atb":[[1.06,1]],"id":70902602},{"atl":[[1000,0.04]],"id":70902602}],"con":true,"img":false}]}
{"op":"mcm","clk":"11541329443","pt":1719504594768,"mc":[{"id":"1.230178324","rc":[{"atb":[[1.06,0.35]],"id":70902602},{"atl":[[1000,0]],"id":70902602}],"con":true,"img":false}]}
{"op":"mcm","clk":"11541329452","pt":1719504594873,"mc":[{"id":"1.230178324","rc":[{"atl":[[25,0.88]],"id":70902602}],"con":true,"img":false}]}
{"op":"mcm","clk":"11541329463","pt":1719504594933,"mc":[{"id":"1.230178324","rc":[{"atb":[[1.06,0]],"id":70902602}],"con":true,"img":false}]}
{"op":"mcm","clk":"11541329468","pt":1719504595042,"mc":[{"id":"1.230178324","rc":[{"atb":[[3.85,0.35]],"id":70902602}],"con":true,"img":false}]}
{"op":"mcm","clk":"11541329475","pt":1719504595138,"mc":[{"id":"1.230178324","rc":[{"atb":[[3,6],[2.9,0]],"id":70902602}],"con":true,"img":false}]}
{"op":"mcm","clk":"11541329503","pt":1719504595547,"mc":[{"id":"1.230178324","rc":[{"atl":[[9,0]],"id":69769647}],"con":true,"img":false}]}
{"op":"mcm","clk":"11541329514","pt":1719504595755,"mc":[{"id":"1.230178324","rc":[{"atb":[[2.56,0]],"id":69769647}],"con":true,"img":false}]}
{"op":"mcm","clk":"11541329548","pt":1719504595960,"mc":[{"id":"1.230178324","rc":[{"atb":[[1.04,1]],"id":69769647},{"atl":[[1000,0.12]],"id":69769647}],"con":true,"img":false}]}
{"op":"mcm","clk":"11541329571","pt":1719504596166,"mc":[{"id":"1.230178324","rc":[{"atb":[[1.04,0.64]],"id":69769647},{"atl":[[1000,0]],"id":69769647}],"con":true,"img":false}]}
{"op":"mcm","clk":"11541329579","pt":1719504596270,"mc":[{"id":"1.230178324","rc":[{"atl":[[9,0.12]],"id":69769647}],"con":true,"img":false}]}
{"op":"mcm","clk":"11541329592","pt":1719504596376,"mc":[{"id":"1.230178324","rc":[{"atb":[[1.04,0]],"id":69769647}],"con":true,"img":false}]}
{"op":"mcm","clk":"11541329601","pt":1719504596437,"mc":[{"id":"1.230178324","rc":[{"atb":[[2.56,0.64]],"id":69769647}],"con":true,"img":false}]}
{"op":"mcm","clk":"11541330181","pt":1719504603066,"mc":[{"id":"1.230178324","rc":[{"atb":[[2.7,1]],"id":69769647}],"con":true,"img":false}]}
{"op":"mcm","clk":"11541330192","pt":1719504603170,"mc":[{"id":"1.230178324","rc":[{"atb":[[2.54,2],[2.38,0]],"id":69769647}],"con":true,"img":false}]}
{"op":"mcm","clk":"11541330294","pt":1719504604366,"mc":[{"id":"1.230178324","rc":[{"atb":[[2.54,3],[2.7,0]],"id":69769647}],"con":true,"img":false}]}
{"op":"mcm","clk":"11541330318","pt":1719504604580,"mc":[{"id":"1.230178324","rc":[{"atb":[[2.36,3.76]],"id":69769647}],"con":true,"img":false}]}
{"op":"mcm","clk":"11541330328","pt":1719504604680,"mc":[{"id":"1.230178324","rc":[{"atb":[[2.54,1]],"id":69769647}],"con":true,"img":false}]}
{"op":"mcm","clk":"11541330865","pt":1719504610062,"mc":[{"id":"1.230178324","rc":[{"atl":[[25,0.84]],"id":70902602}],"con":true,"img":false}]}
{"op":"mcm","clk":"11541330874","pt":1719504610161,"mc":[{"id":"1.230178324","rc":[{"atb":[[3.85,0]],"id":70902602}],"con":true,"img":false}]}
{"op":"mcm","clk":"11541330907","pt":1719504610577,"mc":[{"id":"1.230178324","rc":[{"atb":[[1.06,1]],"id":70902602},{"atl":[[1000,0.04]],"id":70902602}],"con":true,"img":false}]}
{"op":"mcm","clk":"11541330924","pt":1719504610784,"mc":[{"id":"1.230178324","rc":[{"atb":[[1.06,0.35]],"id":70902602},{"atl":[[1000,0]],"id":70902602}],"con":true,"img":false}]}
{"op":"mcm","clk":"11541330933","pt":1719504610960,"mc":[{"id":"1.230178324","rc":[{"atl":[[25,0.88]],"id":70902602},{"atb":[[1.52,0]],"id":69769647}],"con":true,"img":false}]}
{"op":"mcm","clk":"11541330941","pt":1719504610974,"mc":[{"id":"1.230178324","rc":[{"atb":[[1.06,0]],"id":70902602}],"con":true,"img":false}]}
{"op":"mcm","clk":"11541330951","pt":1719504611049,"mc":[{"id":"1.230178324","rc":[{"atb":[[3.85,0.35]],"id":70902602}],"con":true,"img":false}]}
{"op":"mcm","clk":"11541330985","pt":1719504611462,"mc":[{"id":"1.230178324","rc":[{"atl":[[9,0]],"id":69769647}],"con":true,"img":false}]}
{"op":"mcm","clk":"11541331007","pt":1719504611670,"mc":[{"id":"1.230178324","rc":[{"atb":[[2.56,0]],"id":69769647}],"con":true,"img":false}]}
{"op":"mcm","clk":"11541331066","pt":1719504612410,"mc":[{"id":"1.230178324","rc":[{"atb":[[1.04,1]],"id":69769647},{"atl":[[1000,0.12]],"id":69769647}],"con":true,"img":false}]}
{"op":"mcm","clk":"11541331086","pt":1719504612672,"mc":[{"id":"1.230178324","rc":[{"atb":[[1.04,0.64]],"id":69769647},{"atl":[[1000,0]],"id":69769647}],"con":true,"img":false}]}
{"op":"mcm","clk":"11541331094","pt":1719504612785,"mc":[{"id":"1.230178324","rc":[{"atl":[[9,0.12]],"id":69769647}],"con":true,"img":false}]}
{"op":"mcm","clk":"11541331108","pt":1719504612986,"mc":[{"id":"1.230178324","rc":[{"atb":[[1.04,0]],"id":69769647}],"con":true,"img":false}]}
{"op":"mcm","clk":"11541331118","pt":1719504613089,"mc":[{"id":"1.230178324","rc":[{"atb":[[2.56,0.64]],"id":69769647}],"con":true,"img":false}]}
{"op":"mcm","clk":"11541331696","pt":1719504620478,"mc":[{"id":"1.230178324","rc":[{"atb":[[2.54,0],[2.7,1]],"id":69769647}],"con":true,"img":false}]}
{"op":"mcm","clk":"11541331704","pt":1719504620572,"mc":[{"id":"1.230178324","rc":[{"atb":[[2.36,0.12],[2.54,3.77]],"id":69769647}],"con":true,"img":false}]}
{"op":"mcm","clk":"11541332109","pt":1719504626068,"mc":[{"id":"1.230178324","rc":[{"atl":[[25,0.84]],"id":70902602}],"con":true,"img":false}]}
{"op":"mcm","clk":"11541332129","pt":1719504626275,"mc":[{"id":"1.230178324","rc":[{"atb":[[3.85,0]],"id":70902602}],"con":true,"img":false}]}
{"op":"mcm","clk":"11541332213","pt":1719504627155,"mc":[{"id":"1.230178324","rc":[{"atb":[[1.06,1]],"id":70902602},{"atl":[[1000,0.04]],"id":70902602}],"con":true,"img":false}]}
{"op":"mcm","clk":"11541332230","pt":1719504627363,"mc":[{"id":"1.230178324","rc":[{"atb":[[1.06,0.35]],"id":70902602},{"atl":[[1000,0]],"id":70902602}],"con":true,"img":false}]}
{"op":"mcm","clk":"11541332236","pt":1719504627464,"mc":[{"id":"1.230178324","rc":[{"atl":[[25,0.88]],"id":70902602}],"con":true,"img":false}]}
{"op":"mcm","clk":"11541332244","pt":1719504627571,"mc":[{"id":"1.230178324","rc":[{"atb":[[1.06,0]],"id":70902602}],"con":true,"img":false}]}
{"op":"mcm","clk":"11541332254","pt":1719504627672,"mc":[{"id":"1.230178324","rc":[{"atb":[[3.85,0.35]],"id":70902602}],"con":true,"img":false}]}
{"op":"mcm","clk":"11541332323","pt":1719504628081,"mc":[{"id":"1.230178324","rc":[{"atl":[[9,0]],"id":69769647}],"con":true,"img":false}]}
{"op":"mcm","clk":"11541332337","pt":1719504628288,"mc":[{"id":"1.230178324","rc":[{"atb":[[2.56,0]],"id":69769647}],"con":true,"img":false}]}
{"op":"mcm","clk":"11541332346","pt":1719504628393,"mc":[{"id":"1.230178324","rc":[{"atb":[[2.36,4.89],[2.54,0]],"id":69769647}],"con":true,"img":false}]}
{"op":"mcm","clk":"11541332362","pt":1719504628598,"mc":[{"id":"1.230178324","rc":[{"atb":[[1.04,1]],"id":69769647},{"atl":[[1000,0.12]],"id":69769647}],"con":true,"img":false}]}
{"op":"mcm","clk":"11541332378","pt":1719504628766,"mc":[{"id":"1.230178324","rc":[{"atb":[[1.04,0.58]],"id":69769647}],"con":true,"img":false}]}
{"op":"mcm","clk":"11541332385","pt":1719504628871,"mc":[{"id":"1.230178324","rc":[{"atl":[[1000,0]],"id":69769647}],"con":true,"img":false}]}
{"op":"mcm","clk":"11541332396","pt":1719504628972,"mc":[{"id":"1.230178324","rc":[{"atb":[[1.04,0]],"id":69769647},{"atl":[[9,0.12]],"id":69769647}],"con":true,"img":false}]}
{"op":"mcm","clk":"11541332405","pt":1719504629073,"mc":[{"id":"1.230178324","rc":[{"atb":[[2.72,0.58]],"id":69769647}],"con":true,"img":false}]}
{"op":"mcm","clk":"11541332437","pt":1719504629481,"mc":[{"id":"1.230178324","rc":[{"atb":[[1.57,20.8]],"id":69769647}],"con":true,"img":false}]}
{"op":"mcm","clk":"11541332445","pt":1719504629586,"mc":[{"id":"1.230178324","rc":[{"atl":[[9.2,0],[9.4,1]],"id":69769647}],"con":true,"img":false}]}
{"op":"mcm","clk":"11541332454","pt":1719504629688,"mc":[{"id":"1.230178324","rc":[{"atl":[[20,0],[9.4,9]],"id":69769647}],"con":true,"img":false}]}
{"op":"mcm","clk":"11541332467","pt":1719504629792,"mc":[{"id":"1.230178324","rc":[{"atl":[[20,5.26],[9.4,1]],"id":69769647}],"con":true,"img":false}]}
{"op":"mcm","clk":"11541333564","pt":1719504642685,"mc":[{"id":"1.230178324","rc":[{"atl":[[25,0.84]],"id":70902602},{"spn":14.42,"spf":"NaN","id":70902602},{"spn":2.46,"spf":1.0,"id":69769647}],"con":true,"img":false}]}
{"op":"mcm","clk":"11541333572","pt":1719504642789,"mc":[{"id":"1.230178324","rc":[{"atb":[[3.85,0]],"id":70902602}],"con":true,"img":false}]}
{"op":"mcm","clk":"11541333606","pt":1719504643206,"mc":[{"id":"1.230178324","rc":[{"atb":[[1.06,1]],"id":70902602},{"atl":[[1000,0.04]],"id":70902602}],"con":true,"img":false}]}
{"op":"mcm","clk":"11541333621","pt":1719504643414,"mc":[{"id":"1.230178324","rc":[{"atb":[[1.06,0.35]],"id":70902602},{"atl":[[1000,0]],"id":70902602}],"con":true,"img":false}]}
{"op":"mcm","clk":"11541333630","pt":1719504643517,"mc":[{"id":"1.230178324","rc":[{"atl":[[25,0.88]],"id":70902602}],"con":true,"img":false}]}
{"op":"mcm","clk":"11541333638","pt":1719504643620,"mc":[{"id":"1.230178324","rc":[{"atb":[[1.06,0]],"id":70902602}],"con":true,"img":false}]}
{"op":"mcm","clk":"11541333648","pt":1719504643724,"mc":[{"id":"1.230178324","rc":[{"atb":[[3.85,0.35]],"id":70902602}],"con":true,"img":false}]}
{"op":"mcm","clk":"11541333687","pt":1719504644190,"mc":[{"id":"1.230178324","rc":[{"atb":[[2.72,0]],"id":69769647},{"atl":[[9,0]],"id":69769647}],"con":true,"img":false}]}
{"op":"mcm","clk":"11541333748","pt":1719504644918,"mc":[{"id":"1.230178324","rc":[{"atb":[[1.04,1]],"id":69769647},{"atl":[[1000,0.12]],"id":69769647}],"con":true,"img":false}]}
{"op":"mcm","clk":"11541333767","pt":1719504645083,"mc":[{"id":"1.230178324","rc":[{"atb":[[1.04,0.58]],"id":69769647},{"atl":[[1000,0]],"id":69769647}],"con":true,"img":false}]}
{"op":"mcm","clk":"11541333777","pt":1719504645191,"mc":[{"id":"1.230178324","rc":[{"atl":[[9.2,0.12]],"id":69769647}],"con":true,"img":false}]}
{"op":"mcm","clk":"11541333785","pt":1719504645311,"mc":[{"id":"1.230178324","rc":[{"atb":[[1.04,0]],"id":69769647}],"con":true,"img":false}]}
{"op":"mcm","clk":"11541333792","pt":1719504645387,"mc":[{"id":"1.230178324","rc":[{"atb":[[2.72,0.58]],"id":69769647}],"con":true,"img":false}]}
{"op":"mcm","clk":"11541333831","pt":1719504645800,"mc":[{"id":"1.230178324","rc":[{"atb":[[3.85,1.19]],"id":70902602},{"atb":[[5.1,0.9]],"id":63579394}],"con":true,"img":false}]}
{"op":"mcm","clk":"11541334956","pt":1719504658334,"mc":[{"id":"1.230178324","rc":[{"atb":[[2.36,4.77]],"id":69769647}],"con":true,"img":false}]}
{"op":"mcm","clk":"11541334981","pt":1719504658642,"mc":[{"id":"1.230178324","rc":[{"atb":[[5.1,0.84]],"id":63579394},{"atl":[[25,0.84]],"id":70902602}],"con":true,"img":false}]}
{"op":"mcm","clk":"11541334992","pt":1719504658748,"mc":[{"id":"1.230178324","rc":[{"atb":[[3.8,0.07],[3.9,3.86]],"id":70902602}],"con":true,"img":false}]}
{"op":"mcm","clk":"11541335011","pt":1719504658912,"mc":[{"id":"1.230178324","rc":[{"atb":[[3.85,0.84]],"id":70902602},{"atb":[[4.8,0]],"id":40626946}],"con":true,"img":false}]}
{"op":"mcm","clk":"11541335034","pt":1719504659220,"mc":[{"id":"1.230178324","rc":[{"atb":[[5.1,0]],"id":45129701}],"con":true,"img":false}]}
{"op":"mcm","clk":"11541335043","pt":1719504659324,"mc":[{"id":"1.230178324","rc":[{"atb":[[3.95,0.84],[1.06,1]],"id":70902602}],"con":true,"img":false}]}
{"op":"mcm","clk":"11541335053","pt":1719504659427,"mc":[{"id":"1.230178324","rc":[{"atb":[[1.06,0.34]],"id":70902602},{"atl":[[1000,0.04]],"id":70902602}],"con":true,"img":false}]}
{"op":"mcm","clk":"11541335062","pt":1719504659529,"mc":[{"id":"1.230178324","rc":[{"atb":[[3.8,0],[1.06,0]],"id":70902602},{"atl":[[1000,0]],"id":70902602},{"atb":[[5.1,0]],"id":57055802}],"con":true,"img":false}]}
{"op":"mcm","clk":"11541335073","pt":1719504659634,"mc":[{"id":"1.230178324","rc":[{"atb":[[3.95,1.18]],"id":70902602},{"atl":[[25,0.88]],"id":70902602},{"atb":[[4.6,1],[4.2,8]],"id":57055802}],"con":true,"img":false}]}
{"op":"mcm","clk":"11541335083","pt":1719504659738,"mc":[{"id":"1.230178324","rc":[{"atb":[[1.06,1.69]],"id":69769647},{"atb":[[1.12,1.69]],"id":45129701}],"con":true,"img":false}]}
{"op":"mcm","clk":"11541335103","pt":1719504659945,"mc":[{"id":"1.230178324","rc":[{"atb":[[1.12,1.69]],"id":63579394},{"atb":[[1.1,1.69]],"id":40626946}],"con":true,"img":false}]}
{"op":"mcm","clk":"11541335117","pt":1719504660153,"mc":[{"id":"1.230178324","rc":[{"atb":[[1.09,1.69]],"id":70902602}],"con":true,"img":false}]}
{"op":"mcm","clk":"11541335128","pt":1719504660206,"mc":[{"id":"1.230178324","rc":[{"atb":[[1.06,0.12]],"id":69769647}],"con":true,"img":false}]}
{"op":"mcm","clk":"11541335146","pt":1719504660414,"mc":[{"id":"1.230178324","rc":[{"atl":[[9.2,0]],"id":69769647},{"atb":[[1.12,0.05]],"id":45129701}],"con":true,"img":false}]}
{"op":"mcm","clk":"11541335157","pt":1719504660517,"mc":[{"id":"1.230178324","rc":[{"atb":[[1.12,0.05]],"id":63579394}],"con":true,"img":false}]}
{"op":"mcm","clk":"11541335166","pt":1719504660620,"mc":[{"id":"1.230178324","rc":[{"atb":[[2.72,0]],"id":69769647}],"con":true,"img":false}]}
{"op":"mcm","clk":"11541335176","pt":1719504660724,"mc":[{"id":"1.230178324","rc":[{"atb":[[1.12,1.69]],"id":57055802},{"atb":[[1.1,0.06]],"id":40626946}],"con":true,"img":false}]}
{"op":"mcm","clk":"11541335194","pt":1719504660931,"mc":[{"id":"1.230178324","rc":[{"atb":[[1.04,1]],"id":69769647},{"atl":[[1000,0.12]],"id":69769647}],"con":true,"img":false}]}
{"op":"mcm","clk":"11541335201","pt":1719504661037,"mc":[{"id":"1.230178324","rc":[{"atb":[[1.09,0.07]],"id":70902602}],"con":true,"img":false}]}
{"op":"mcm","clk":"11541335209","pt":1719504661159,"mc":[{"id":"1.230178324","rc":[{"atb":[[1.06,0],[1.04,0.58]],"id":69769647},{"atl":[[1000,0]],"id":69769647}],"con":true,"img":false}]}
{"op":"mcm","clk":"11541335218","pt":1719504661244,"mc":[{"id":"1.230178324","rc":[{"atb":[[2.38,0.12]],"id":69769647},{"atl":[[9.2,0.12]],"id":69769647}],"con":true,"img":false}]}
{"op":"mcm","clk":"11541335230","pt":1719504661348,"mc":[{"id":"1.230178324","rc":[{"atb":[[1.04,0]],"id":69769647}],"con":true,"img":false}]}
{"op":"mcm","clk":"11541335242","pt":1719504661453,"mc":[{"id":"1.230178324","rc":[{"atb":[[2.72,0.58]],"id":69769647}],"con":true,"img":false}]}
{"op":"mcm","clk":"11541335257","pt":1719504661509,"mc":[{"id":"1.230178324","rc":[{"atb":[[1.12,0]],"id":45129701}],"con":true,"img":false}]}
{"op":"mcm","clk":"11541335266","pt":1719504661614,"mc":[{"id":"1.230178324","rc":[{"atb":[[5.1,0.05]],"id":45129701}],"con":true,"img":false}]}
{"op":"mcm","clk":"11541335293","pt":1719504661922,"mc":[{"id":"1.230178324","rc":[{"atb":[[1.12,0]],"id":63579394}],"con":true,"img":false}]}
{"op":"mcm","clk":"11541335304","pt":1719504662026,"mc":[{"id":"1.230178324","rc":[{"atb":[[5.1,0.9]],"id":63579394}],"con":true,"img":false}]}
{"op":"mcm","clk":"11541335331","pt":1719504662336,"mc":[{"id":"1.230178324","rc":[{"atb":[[1.1,0]],"id":40626946}],"con":true,"img":false}]}
{"op":"mcm","clk":"11541335341","pt":1719504662440,"mc":[{"id":"1.230178324","rc":[{"atb":[[4.8,0.06]],"id":40626946}],"con":true,"img":false}]}
{"op":"mcm","clk":"11541335367","pt":1719504662749,"mc":[{"id":"1.230178324","rc":[{"atb":[[1.12,0.05]],"id":57055802}],"con":true,"img":false}]}
{"op":"mcm","clk":"11541335374","pt":1719504662805,"mc":[{"id":"1.230178324","rc":[{"atb":[[1.09,0]],"id":70902602}],"con":true,"img":false}]}
{"op":"mcm","clk":"11541335383","pt":1719504662908,"mc":[{"id":"1.230178324","rc":[{"atb":[[3.95,1.26]],"id":70902602}],"con":true,"img":false}]}
{"op":"mcm","clk":"11541335406","pt":1719504663216,"mc":[{"id":"1.230178324","rc":[{"atb":[[1.12,0]],"id":57055802}],"con":true,"img":false}]}
{"op":"mcm","clk":"11541335420","pt":1719504663319,"mc":[{"id":"1.230178324","rc":[{"atb":[[5.1,0.05]],"id":57055802}],"con":true,"img":false}]}
{"op":"mcm","clk":"11541335431","pt":1719504663425,"mc":[{"id":"1.230178324","rc":[{"atb":[[4.6,7],[4.2,0]],"id":57055802}],"con":true,"img":false}]}
{"op":"mcm","clk":"11541335458","pt":1719504663836,"mc":[{"id":"1.230178324","rc":[{"atb":[[1.04,1.7]],"id":63579394},{"atl":[[1000,1.7]],"id":63579394},{"atb":[[1.02,15.53]],"id":69769647},{"atl":[[1000,1.7]],"id":69769647},{"atb":[[1.02,3.7]],"id":40626946},{"atl":[[1000,1.93]],"id":40626946}],"con":true,"img":false}]}
{"op":"mcm","clk":"11541335471","pt":1719504664044,"mc":[{"id":"1.230178324","rc":[{"atb":[[1.04,0.07]],"id":63579394},{"atl":[[1000,0]],"id":63579394},{"atb":[[1.02,14.05]],"id":69769647},{"atl":[[1000,0.01]],"id":69769647},{"atb":[[1.02,2.12]],"id":40626946},{"atl":[[1000,0.23]],"id":40626946}],"con":true,"img":false}]}
{"op":"mcm","clk":"11541335486","pt":1719504664247,"mc":[{"id":"1.230178324","rc":[{"atb":[[1.04,0]],"id":63579394},{"atb":[[1.02,13.83]],"id":69769647},{"atl":[[1000,0]],"id":69769647},{"atb":[[1.02,2]],"id":40626946},{"atl":[[1000,0.22]],"id":40626946}],"con":true,"img":false}]}
{"op":"mcm","clk":"11541335492","pt":1719504664303,"mc":[{"id":"1.230178324","rc":[{"atb":[[5.1,0.98]],"id":63579394},{"atb":[[2.4,0.21]],"id":69769647},{"atl":[[19.5,0.01]],"id":69769647},{"atb":[[3.4,0.12]],"id":40626946},{"atl":[[30,0.01]],"id":40626946}],"con":true,"img":false}]}
{"op":"mcm","clk":"11541336405","pt":1719504674564,"mc":[{"id":"1.230178324","rc":[{"atb":[[3.9,0]],"id":70902602}],"con":true,"img":false}]}
{"op":"mcm","clk":"11541336422","pt":1719504674771,"mc":[{"id":"1.230178324","rc":[{"atb":[[3.95,0.41]],"id":70902602}],"con":true,"img":false}]}
{"op":"mcm","clk":"11541336431","pt":1719504674874,"mc":[{"id":"1.230178324","rc":[{"atb":[[3.95,0.07]],"id":70902602},{"atl":[[25,0.84]],"id":70902602}],"con":true,"img":false}]}
{"op":"mcm","clk":"11541336450","pt":1719504675126,"mc":[{"id":"1.230178324","rc":[{"atb":[[1.07,1]],"id":70902602},{"atl":[[1000,0.04]],"id":70902602}],"con":true,"img":false}]}
{"op":"mcm","clk":"11541336464","pt":1719504675332,"mc":[{"id":"1.230178324","rc":[{"atb":[[3.85,0],[1.07,0.33]],"id":70902602},{"atl":[[1000,0]],"id":70902602}],"con":true,"img":false}]}
{"op":"mcm","clk":"11541336471","pt":1719504675433,"mc":[{"id":"1.230178324","rc":[{"atl":[[25,0.88]],"id":70902602}],"con":true,"img":false}]}
{"op":"mcm","clk":"11541336482","pt":1719504675654,"mc":[{"id":"1.230178324","rc":[{"atb":[[1.07,0]],"id":70902602}],"con":true,"img":false}]}
{"op":"mcm","clk":"11541336491","pt":1719504675744,"mc":[{"id":"1.230178324","rc":[{"atb":[[4,0.33]],"id":70902602}],"con":true,"img":false}]}
{"op":"mcm","clk":"11541336541","pt":1719504676427,"mc":[{"id":"1.230178324","rc":[{"atl":[[9.2,0]],"id":69769647}],"con":true,"img":false}]}
{"op":"mcm","clk":"11541336552","pt":1719504676632,"mc":[{"id":"1.230178324","rc":[{"atb":[[2.72,0]],"id":69769647}],"con":true,"img":false}]}
{"op":"mcm","clk":"11541336571","pt":1719504677044,"mc":[{"id":"1.230178324","rc":[{"atb":[[1.04,1]],"id":69769647},{"atl":[[1000,0.12]],"id":69769647}],"con":true,"img":false}]}
{"op":"mcm","clk":"11541336578","pt":1719504677147,"mc":[{"id":"1.230178324","rc":[{"atb":[[1.04,0.58]],"id":69769647},{"atl":[[1000,0]],"id":69769647}],"con":true,"img":false}]}
{"op":"mcm","clk":"11541336583","pt":1719504677253,"mc":[{"id":"1.230178324","rc":[{"atb":[[1.04,0]],"id":69769647},{"atl":[[9.2,0.12]],"id":69769647}],"con":true,"img":false}]}
{"op":"mcm","clk":"11541336590","pt":1719504677356,"mc":[{"id":"1.230178324","rc":[{"atb":[[2.72,0.58]],"id":69769647}],"con":true,"img":false}]}
{"op":"mcm","clk":"11541336596","pt":1719504677461,"mc":[{"id":"1.230178324","rc":[{"atb":[[3.8,7]],"id":70902602}],"con":true,"img":false}]}
{"op":"mcm","clk":"11541336611","pt":1719504677726,"mc":[{"id":"1.230178324","rc":[{"atb":[[3.85,0.84]],"id":70902602}],"con":true,"img":false}]}
{"op":"mcm","clk":"11541336680","pt":1719504678864,"mc":[{"id":"1.230178324","rc":[{"atb":[[1.57,0]],"id":69769647}],"con":true,"img":false}]}
{"op":"mcm","clk":"11541337012","pt":1719504683033,"mc":[{"id":"1.230178324","rc":[{"atb":[[2.18,10.04]],"id":69769647}],"con":true,"img":false}]}
{"op":"mcm","clk":"11541337228","pt":1719504685168,"mc":[{"id":"1.230178324","rc":[{"atb":[[3.8,0]],"id":70902602}],"con":true,"img":false}]}
{"op":"mcm","clk":"11541337288","pt":1719504685741,"mc":[{"id":"1.230178324","rc":[{"atb":[[3.85,0]],"id":70902602}],"con":true,"img":false}]}
{"op":"mcm","clk":"11541337729","pt":1719504690640,"mc":[{"id":"1.230178324","rc":[{"atl":[[25,0.84]],"id":70902602}],"con":true,"img":false}]}
{"op":"mcm","clk":"11541337752","pt":1719504690952,"mc":[{"id":"1.230178324","rc":[{"atb":[[4,0]],"id":70902602}],"con":true,"img":false}]}
{"op":"mcm","clk":"11541337779","pt":1719504691261,"mc":[{"id":"1.230178324","rc":[{"atb":[[1.06,1]],"id":70902602},{"atl":[[1000,0.04]],"id":70902602}],"con":true,"img":false}]}
{"op":"mcm","clk":"11541337789","pt":1719504691365,"mc":[{"id":"1.230178324","rc":[{"atb":[[1.06,0.36]],"id":70902602}],"con":true,"img":false}]}
{"op":"mcm","clk":"11541337797","pt":1719504691469,"mc":[{"id":"1.230178324","rc":[{"atl":[[1000,0]],"id":70902602}],"con":true,"img":false}]}
{"op":"mcm","clk":"11541337805","pt":1719504691575,"mc":[{"id":"1.230178324","rc":[{"atb":[[1.06,0]],"id":70902602},{"atl":[[25,0.88]],"id":70902602}],"con":true,"img":false}]}
{"op":"mcm","clk":"11541337813","pt":1719504691679,"mc":[{"id":"1.230178324","rc":[{"atb":[[3.8,0.36]],"id":70902602}],"con":true,"img":false}]}
{"op":"mcm","clk":"11541337883","pt":1719504692459,"mc":[{"id":"1.230178324","rc":[{"atl":[[9.2,0]],"id":69769647}],"con":true,"img":false}]}
{"op":"mcm","clk":"11541337897","pt":1719504692564,"mc":[{"id":"1.230178324","rc":[{"atb":[[2.72,0]],"id":69769647}],"con":true,"img":false}]}
{"op":"mcm","clk":"11541337937","pt":1719504692978,"mc":[{"id":"1.230178324","rc":[{"atb":[[1.04,1]],"id":69769647},{"atl":[[1000,0.12]],"id":69769647}],"con":true,"img":false}]}
{"op":"mcm","clk":"11541337954","pt":1719504693189,"mc":[{"id":"1.230178324","rc":[{"atb":[[1.04,0.58]],"id":69769647},{"atl":[[1000,0]],"id":69769647}],"con":true,"img":false}]}
{"op":"mcm","clk":"11541337964","pt":1719504693251,"mc":[{"id":"1.230178324","rc":[{"atb":[[1.04,0]],"id":69769647},{"atl":[[9.2,0.12]],"id":69769647}],"con":true,"img":false}]}
{"op":"mcm","clk":"11541337975","pt":1719504693345,"mc":[{"id":"1.230178324","rc":[{"atb":[[2.72,0.58]],"id":69769647}],"con":true,"img":false}]}
{"op":"mcm","clk":"11541338180","pt":1719504695680,"mc":[{"id":"1.230178324","rc":[{"atb":[[3.8,7.36]],"id":70902602}],"con":true,"img":false}]}
{"op":"mcm","clk":"11541338233","pt":1719504696254,"mc":[{"id":"1.230178324","rc":[{"atb":[[3.85,0.84]],"id":70902602}],"con":true,"img":false}]}
{"op":"mcm","clk":"11541339156","pt":1719504706696,"mc":[{"id":"1.230178324","rc":[{"spn":14.47,"spf":"NaN","id":70902602},{"atb":[[5.1,0.9]],"id":63579394},{"atb":[[2.4,0]],"id":69769647},{"atl":[[19.5,0]],"id":69769647},{"spn":2.47,"spf":1.0,"id":69769647},{"atb":[[3.4,0]],"id":40626946},{"atl":[[30,0]],"id":40626946}],"con":true,"img":false}]}
{"op":"mcm","clk":"11541339169","pt":1719504706798,"mc":[{"id":"1.230178324","rc":[{"atl":[[25,0.84]],"id":70902602}],"con":true,"img":false}]}
{"op":"mcm","clk":"11541339175","pt":1719504706902,"mc":[{"id":"1.230178324","rc":[{"atb":[[3.8,7]],"id":70902602}],"con":true,"img":false}]}
{"op":"mcm","clk":"11541339254","pt":1719504707686,"mc":[{"id":"1.230178324","rc":[{"atb":[[1.06,1]],"id":70902602},{"atl":[[1000,0.04]],"id":70902602}],"con":true,"img":false}]}
{"op":"mcm","clk":"11541339273","pt":1719504707892,"mc":[{"id":"1.230178324","rc":[{"atb":[[1.06,0.35]],"id":70902602},{"atl":[[1000,0]],"id":70902602}],"con":true,"img":false}]}
{"op":"mcm","clk":"11541339280","pt":1719504707997,"mc":[{"id":"1.230178324","rc":[{"atl":[[25,0.88]],"id":70902602}],"con":true,"img":false}]}
{"op":"mcm","clk":"11541339290","pt":1719504708101,"mc":[{"id":"1.230178324","rc":[{"atb":[[1.06,0]],"id":70902602}],"con":true,"img":false}]}
{"op":"mcm","clk":"11541339302","pt":1719504708203,"mc":[{"id":"1.230178324","rc":[{"atb":[[3.85,1.19]],"id":70902602}],"con":true,"img":false}]}
{"op":"mcm","clk":"11541339321","pt":1719504708367,"mc":[{"id":"1.230178324","rc":[{"atl":[[9.2,0]],"id":69769647}],"con":true,"img":false}]}
{"op":"mcm","clk":"11541339338","pt":1719504708567,"mc":[{"id":"1.230178324","rc":[{"atb":[[2.72,0]],"id":69769647}],"con":true,"img":false}]}
{"op":"mcm","clk":"11541339366","pt":1719504708877,"mc":[{"id":"1.230178324","rc":[{"atb":[[1.04,1]],"id":69769647},{"atl":[[1000,0.12]],"id":69769647}],"con":true,"img":false}]}
{"op":"mcm","clk":"11541339385","pt":1719504709083,"mc":[{"id":"1.230178324","rc":[{"atb":[[1.04,0.58]],"id":69769647},{"atl":[[1000,0]],"id":69769647}],"con":true,"img":false}]}
{"op":"mcm","clk":"11541339396","pt":1719504709190,"mc":[{"id":"1.230178324","rc":[{"atl":[[9.2,0.12]],"id":69769647}],"con":true,"img":false}]}
{"op":"mcm","clk":"11541339406","pt":1719504709290,"mc":[{"id":"1.230178324","rc":[{"atb":[[1.04,0]],"id":69769647}],"con":true,"img":false}]}
{"op":"mcm","clk":"11541339416","pt":1719504709394,"mc":[{"id":"1.230178324","rc":[{"atb":[[2.72,0.58]],"id":69769647}],"con":true,"img":false}]}
{"op":"mcm","clk":"11541339792","pt":1719504713606,"mc":[{"id":"1.230178324","rc":[{"atb":[[3.8,0],[3.9,3.86]],"id":70902602}],"con":true,"img":false}]}
{"op":"mcm","clk":"11541339854","pt":1719504714279,"mc":[{"id":"1.230178324","rc":[{"atb":[[3.95,0.92]],"id":70902602}],"con":true,"img":false}]}
{"op":"mcm","clk":"11541340636","pt":1719504723218,"mc":[{"id":"1.230178324","rc":[{"atl":[[25,0.84]],"id":70902602}],"con":true,"img":false}]}
{"op":"mcm","clk":"11541340664","pt":1719504723493,"mc":[{"id":"1.230178324","rc":[{"atb":[[3.85,0.84]],"id":70902602}],"con":true,"img":false}]}
{"op":"mcm","clk":"11541340697","pt":1719504723900,"mc":[{"id":"1.230178324","rc":[{"atb":[[1.06,1]],"id":70902602},{"atl":[[1000,0.04]],"id":70902602}],"con":true,"img":false}]}
{"op":"mcm","clk":"11541340711","pt":1719504724108,"mc":[{"id":"1.230178324","rc":[{"atb":[[1.06,0.34]],"id":70902602},{"atl":[[1000,0]],"id":70902602}],"con":true,"img":false}]}
{"op":"mcm","clk":"11541340720","pt":1719504724211,"mc":[{"id":"1.230178324","rc":[{"atl":[[25,0.88]],"id":70902602}],"con":true,"img":false}]}
{"op":"mcm","clk":"11541340727","pt":1719504724314,"mc":[{"id":"1.230178324","rc":[{"atb":[[1.06,0]],"id":70902602}],"con":true,"img":false}]}
{"op":"mcm","clk":"11541340734","pt":1719504724416,"mc":[{"id":"1.230178324","rc":[{"atb":[[3.95,1.26]],"id":70902602},{"atl":[[9.2,0]],"id":69769647}],"con":true,"img":false}]}
{"op":"mcm","clk":"11541340754","pt":1719504724689,"mc":[{"id":"1.230178324","rc":[{"atb":[[2.72,0]],"id":69769647}],"con":true,"img":false}]}
{"op":"mcm","clk":"11541340782","pt":1719504724995,"mc":[{"id":"1.230178324","rc":[{"atb":[[1.04,1]],"id":69769647},{"atl":[[1000,0.12]],"id":69769647}],"con":true,"img":false}]}
{"op":"mcm","clk":"11541340798","pt":1719504725198,"mc":[{"id":"1.230178324","rc":[{"atb":[[1.04,0.58]],"id":69769647},{"atl":[[1000,0]],"id":69769647}],"con":true,"img":false}]}
{"op":"mcm","clk":"11541340809","pt":1719504725307,"mc":[{"id":"1.230178324","rc":[{"atl":[[9.2,0.12]],"id":69769647}],"con":true,"img":false}]}
{"op":"mcm","clk":"11541340818","pt":1719504725414,"mc":[{"id":"1.230178324","rc":[{"atb":[[1.04,0]],"id":69769647}],"con":true,"img":false}]}
{"op":"mcm","clk":"11541340828","pt":1719504725518,"mc":[{"id":"1.230178324","rc":[{"atb":[[2.72,0.58]],"id":69769647}],"con":true,"img":false}]}
{"op":"mcm","clk":"11541341341","pt":1719504731105,"mc":[{"id":"1.230178324","rc":[{"atb":[[4,3.86],[3.9,0]],"id":70902602}],"con":true,"img":false}]}
{"op":"mcm","clk":"11541341413","pt":1719504731827,"mc":[{"id":"1.230178324","rc":[{"atb":[[3.85,0],[4.1,0.84]],"id":70902602}],"con":true,"img":false}]}
{"op":"mcm","clk":"11541341898","pt":1719504737896,"mc":[{"id":"1.230178324","rc":[{"atl":[[32,0]],"id":40626946},{"atl":[[32,0]],"id":45129701}],"con":true,"img":false}]}
{"op":"mcm","clk":"11541341906","pt":1719504738049,"mc":[{"id":"1.230178324","rc":[{"atb":[[3.05,3.16]],"id":70902602}],"con":true,"img":false}]}
{"op":"mcm","clk":"11541342039","pt":1719504739506,"mc":[{"id":"1.230178324","rc":[{"atl":[[25,0.84]],"id":70902602}],"con":true,"img":false}]}
{"op":"mcm","clk":"11541342046","pt":1719504739609,"mc":[{"id":"1.230178324","rc":[{"atb":[[3.95,0.92]],"id":70902602}],"con":true,"img":false}]}
{"op":"mcm","clk":"11541342070","pt":1719504739924,"mc":[{"id":"1.230178324","rc":[{"atb":[[1.07,1]],"id":70902602},{"atl":[[1000,0.04]],"id":70902602}],"con":true,"img":false}]}
{"op":"mcm","clk":"11541342092","pt":1719504740230,"mc":[{"id":"1.230178324","rc":[{"atb":[[1.07,0.32]],"id":70902602},{"atl":[[1000,0]],"id":70902602}],"con":true,"img":false}]}
{"op":"mcm","clk":"11541342103","pt":1719504740332,"mc":[{"id":"1.230178324","rc":[{"atl":[[25,0.88]],"id":70902602}],"con":true,"img":false}]}
{"op":"mcm","clk":"11541342111","pt":1719504740400,"mc":[{"id":"1.230178324","rc":[{"atb":[[1.07,0]],"id":70902602}],"con":true,"img":false}]}
{"op":"mcm","clk":"11541342121","pt":1719504740505,"mc":[{"id":"1.230178324","rc":[{"atb":[[4.1,1.16]],"id":70902602},{"atl":[[9.2,0]],"id":69769647}],"con":true,"img":false}]}
{"op":"mcm","clk":"11541342136","pt":1719504740706,"mc":[{"id":"1.230178324","rc":[{"atb":[[5.2,1.62]],"id":63579394},{"atb":[[2.72,0]],"id":69769647},{"atl":[[9,0.93]],"id":69769647}],"con":true,"img":false}]}
{"op":"mcm","clk":"11541342163","pt":1719504741019,"mc":[{"id":"1.230178324","rc":[{"atl":[[1000,0.84]],"id":63579394},{"atl":[[1000,0.84]],"id":70902602},{"atb":[[1.04,1]],"id":69769647},{"atl":[[1000,0.12]],"id":69769647}],"con":true,"img":false}]}
{"op":"mcm","clk":"11541342192","pt":1719504741322,"mc":[{"id":"1.230178324","rc":[{"atb":[[4.2,2.01]],"id":70902602},{"atb":[[1.04,0.58]],"id":69769647},{"atl":[[1000,0]],"id":69769647}],"con":true,"img":false}]}
{"op":"mcm","clk":"11541342202","pt":1719504741425,"mc":[{"id":"1.230178324","rc":[{"atl":[[9.2,0.12]],"id":69769647}],"con":true,"img":false}]}
{"op":"mcm","clk":"11541342213","pt":1719504741529,"mc":[{"id":"1.230178324","rc":[{"atb":[[1.04,0]],"id":69769647},{"atl":[[20,0],[9.4,6.26]],"id":69769647}],"con":true,"img":false}]}
{"op":"mcm","clk":"11541342225","pt":1719504741631,"mc":[{"id":"1.230178324","rc":[{"atb":[[2.72,0.58]],"id":69769647}],"con":true,"img":false}]}
{"op":"mcm","clk":"11541342233","pt":1719504741733,"mc":[{"id":"1.230178324","rc":[{"atb":[[5.1,2.53]],"id":63579394}],"con":true,"img":false}]}
{"op":"mcm","clk":"11541342243","pt":1719504741839,"mc":[{"id":"1.230178324","rc":[{"atb":[[4.3,0.84],[3.95,0.07]],"id":70902602},{"atl":[[1000,0.84]],"id":57055802}],"con":true,"img":false}]}
{"op":"mcm","clk":"11541342264","pt":1719504742103,"mc":[{"id":"1.230178324","rc":[{"atl":[[1000,0.7]],"id":63579394}],"con":true,"img":false}]}
{"op":"mcm","clk":"11541342278","pt":1719504742209,"mc":[{"id":"1.230178324","rc":[{"atl":[[1000,0.35]],"id":70902602}],"con":true,"img":false}]}
{"op":"mcm","clk":"11541342303","pt":1719504742417,"mc":[{"id":"1.230178324","rc":[{"atl":[[1000,0.84]],"id":45129701}],"con":true,"img":false}]}
{"op":"mcm","clk":"11541342336","pt":1719504742824,"mc":[{"id":"1.230178324","rc":[{"atl":[[9,0]],"id":69769647},{"atl":[[1000,0.51]],"id":57055802}],"con":true,"img":false}]}
{"op":"mcm","clk":"11541342347","pt":1719504742924,"mc":[{"id":"1.230178324","rc":[{"atl":[[20,5.26],[9.4,1]],"id":69769647}],"con":true,"img":false}]}
{"op":"mcm","clk":"11541342368","pt":1719504743131,"mc":[{"id":"1.230178324","rc":[{"atb":[[5.2,0]],"id":63579394},{"atl":[[1000,0]],"id":63579394}],"con":true,"img":false}]}
{"op":"mcm","clk":"11541342380","pt":1719504743234,"mc":[{"id":"1.230178324","rc":[{"atl":[[12,0.7]],"id":63579394}],"con":true,"img":false}]}
{"op":"mcm","clk":"11541342421","pt":1719504743546,"mc":[{"id":"1.230178324","rc":[{"atb":[[5.1,0.9]],"id":63579394},{"atl":[[9.2,1.05]],"id":69769647}],"con":true,"img":false}]}
{"op":"mcm","clk":"11541342442","pt":1719504743708,"mc":[{"id":"1.230178324","rc":[{"atl":[[9.2,3.05],[20,0]],"id":69769647}],"con":true,"img":false}]}
{"op":"mcm","clk":"11541342452","pt":1719504743812,"mc":[{"id":"1.230178324","rc":[{"atb":[[5.3,1.59]],"id":63579394},{"atl":[[12,1.54]],"id":63579394},{"atl":[[1000,0]],"id":70902602},{"atl":[[9.2,1.05],[20,5.26]],"id":69769647}],"con":true,"img":false}]}
{"op":"mcm","clk":"11541342460","pt":1719504743916,"mc":[{"id":"1.230178324","rc":[{"atl":[[24,0.35]],"id":70902602},{"atl":[[9.2,4.11],[20,0]],"id":69769647}],"con":true,"img":false}]}
{"op":"mcm","clk":"11541342470","pt":1719504744011,"mc":[{"id":"1.230178324","rc":[{"atb":[[4,0]],"id":70902602},{"atl":[[100,0],[15,4]],"id":63579394},{"atl":[[9.2,1.05],[20,5.26]],"id":69769647}],"con":true,"img":false}]}
{"op":"mcm","clk":"11541342482","pt":1719504744125,"mc":[{"id":"1.230178324","rc":[{"atl":[[9.2,5.17],[20,0]],"id":69769647}],"con":true,"img":false}]}
{"op":"mcm","clk":"11541342503","pt":1719504744324,"mc":[{"id":"1.230178324","rc":[{"atl":[[1000,0.77]],"id":45129701}],"con":true,"img":false}]}
{"op":"mcm","clk":"11541342528","pt":1719504744633,"mc":[{"id":"1.230178324","rc":[{"atl":[[1000,0]],"id":57055802}],"con":true,"img":false}]}
{"op":"mcm","clk":"11541342538","pt":1719504744733,"mc":[{"id":"1.230178324","rc":[{"atl":[[16.5,0.51]],"id":57055802}],"con":true,"img":false}]}
{"op":"mcm","clk":"11541342546","pt":1719504744837,"mc":[{"id":"1.230178324","rc":[{"atl":[[9,0.84]],"id":69769647}],"con":true,"img":false}]}
{"op":"mcm","clk":"11541342573","pt":1719504745105,"mc":[{"id":"1.230178324","rc":[{"atb":[[2.54,1],[2.7,0]],"id":69769647}],"con":true,"img":false}]}
{"op":"mcm","clk":"11541342579","pt":1719504745208,"mc":[{"id":"1.230178324","rc":[{"atb":[[2.36,0],[2.54,4.16]],"id":69769647},{"atl":[[1000,0]],"id":45129701}],"con":true,"img":false}]}
{"op":"mcm","clk":"11541342590","pt":1719504745314,"mc":[{"id":"1.230178324","rc":[{"atl":[[11,0.77]],"id":45129701}],"con":true,"img":false}]}
{"op":"mcm","clk":"11541342639","pt":1719504745820,"mc":[{"id":"1.230178324","rc":[{"atb":[[2.56,0.84]],"id":69769647},{"atl":[[11,1.61]],"id":45129701}],"con":true,"img":false}]}
{"op":"mcm","clk":"11541342651","pt":1719504745925,"mc":[{"id":"1.230178324","rc":[{"atl":[[34,1.67],[19,5.56]],"id":45129701}],"con":true,"img":false}]}
{"op":"mcm","clk":"11541342853","pt":1719504748352,"mc":[{"id":"1.230178324","rc":[{"atb":[[4.3,2.84]],"id":70902602}],"con":true,"img":false}]}
{"op":"mcm","clk":"11541342911","pt":1719504748927,"mc":[{"id":"1.230178324","rc":[{"atb":[[4.1,0.32]],"id":70902602},{"atb":[[2.7,1]],"id":69769647}],"con":true,"img":false}]}
{"op":"mcm","clk":"11541342923","pt":1719504749031,"mc":[{"id":"1.230178324","rc":[{"atb":[[2.54,3.16]],"id":69769647}],"con":true,"img":false}]}
{"op":"mcm","clk":"11541342966","pt":1719504749647,"mc":[{"id":"1.230178324","rc":[{"atb":[[1.05,3.4]],"id":63579394},{"atl":[[1000,3.4]],"id":63579394},{"atl":[[9.6,8]],"id":69769647}],"con":true,"img":false}]}
{"op":"mcm","clk":"11541342975","pt":1719504749708,"mc":[{"id":"1.230178324","rc":[{"atl":[[9.2,1.05]],"id":69769647}],"con":true,"img":false}]}
{"op":"mcm","clk":"11541342988","pt":1719504749912,"mc":[{"id":"1.230178324","rc":[{"atb":[[1.05,0.09]],"id":63579394},{"atl":[[1000,0.03]],"id":63579394}],"con":true,"img":false}]}
{"op":"mcm","clk":"11541343010","pt":1719504750219,"mc":[{"id":"1.230178324","rc":[{"atb":[[1.05,0]],"id":63579394},{"atl":[[1000,0]],"id":63579394}],"con":true,"img":false}]}
{"op":"mcm","clk":"11541343017","pt":1719504750322,"mc":[{"id":"1.230178324","rc":[{"atb":[[5.2,0.09]],"id":63579394},{"atl":[[12,1.58]],"id":63579394}],"con":true,"img":false}]}
{"op":"mcm","clk":"11541343445","pt":1719504755556,"mc":[{"id":"1.230178324","rc":[{"atl":[[25,0.84]],"id":70902602}],"con":true,"img":false}]}
{"op":"mcm","clk":"11541343458","pt":1719504755725,"mc":[{"id":"1.230178324","rc":[{"atb":[[4.1,0]],"id":70902602}],"con":true,"img":false}]}
{"op":"mcm","clk":"11541343465","pt":1719504755823,"mc":[{"id":"1.230178324","rc":[{"atb":[[5.3,0],[5.2,1.69]],"id":63579394}],"con":true,"img":false}]}
{"op":"mcm","clk":"11541343496","pt":1719504756132,"mc":[{"id":"1.230178324","rc":[{"atb":[[1.07,1]],"id":70902602},{"atl":[[1000,0.04]],"id":70902602}],"con":true,"img":false}]}
{"op":"mcm","clk":"11541343506","pt":1719504756233,"mc":[{"id":"1.230178324","rc":[{"atb":[[1.07,0.29]],"id":70902602},{"atl":[[1000,0]],"id":70902602},{"atb":[[5.3,0.84]],"id":63579394}],"con":true,"img":false}]}
{"op":"mcm","clk":"11541343517","pt":1719504756337,"mc":[{"id":"1.230178324","rc":[{"atl":[[24,0.39]],"id":70902602}],"con":true,"img":false}]}
{"op":"mcm","clk":"11541343526","pt":1719504756435,"mc":[{"id":"1.230178324","rc":[{"atb":[[1.07,0]],"id":70902602}],"con":true,"img":false}]}
{"op":"mcm","clk":"11541343532","pt":1719504756538,"mc":[{"id":"1.230178324","rc":[{"atb":[[4.4,0.29]],"id":70902602}],"con":true,"img":false}]}
{"op":"mcm","clk":"11541343541","pt":1719504756640,"mc":[{"id":"1.230178324","rc":[{"atl":[[9.2,0.93]],"id":69769647}],"con":true,"img":false}]}
{"op":"mcm","clk":"11541343560","pt":1719504756848,"mc":[{"id":"1.230178324","rc":[{"atb":[[2.72,0]],"id":69769647}],"con":true,"img":false}]}
{"op":"mcm","clk":"11541343585","pt":1719504757116,"mc":[{"id":"1.230178324","rc":[{"atb":[[1.04,1]],"id":69769647},{"atl":[[1000,0.12]],"id":69769647}],"con":true,"img":false}]}
{"op":"mcm","clk":"11541343615","pt":1719504757472,"mc":[{"id":"1.230178324","rc":[{"atb":[[1.04,0.58]],"id":69769647},{"atl":[[1000,0]],"id":69769647}],"con":true,"img":false}]}
{"op":"mcm","clk":"11541343624","pt":1719504757532,"mc":[{"id":"1.230178324","rc":[{"atl":[[9,0.96]],"id":69769647}],"con":true,"img":false}]}
{"op":"mcm","clk":"11541343638","pt":1719504757734,"mc":[{"id":"1.230178324","rc":[{"atb":[[1.04,0]],"id":69769647}],"con":true,"img":false}]}
{"op":"mcm","clk":"11541343648","pt":1719504757841,"mc":[{"id":"1.230178324","rc":[{"atb":[[2.72,0.58]],"id":69769647}],"con":true,"img":false}]}
{"op":"mcm","clk":"11541344145","pt":1719504763130,"mc":[{"id":"1.230178324","rc":[{"atb":[[2.14,0]],"id":70902602}],"con":true,"img":false}]}
{"op":"mcm","clk":"11541344600","pt":1719504768750,"mc":[{"id":"1.230178324","rc":[{"atb":[[2.88,6.3]],"id":70902602},{"spn":14.2,"spf":"NaN","id":70902602},{"spn":8.65,"spf":"NaN","id":63579394},{"spn":2.59,"spf":1.0,"id":69769647},{"spn":10.8,"spf":"NaN","id":57055802},{"spn":8.05,"spf":"NaN","id":45129701}],"con":true,"img":false}]}
{"op":"mcm","clk":"11541344764","pt":1719504770759,"mc":[{"id":"1.230178324","rc":[{"atl":[[8.8,0.96]],"id":69769647}],"con":true,"img":false}]}
{"op":"mcm","clk":"11541344772","pt":1719504770862,"mc":[{"id":"1.230178324","rc":[{"atl":[[9.2,0]],"id":69769647}],"con":true,"img":false}]}
{"op":"mcm","clk":"11541344791","pt":1719504771028,"mc":[{"id":"1.230178324","rc":[{"atb":[[5.4,1.56]],"id":63579394}],"con":true,"img":false}]}
{"op":"mcm","clk":"11541344804","pt":1719504771228,"mc":[{"id":"1.230178324","rc":[{"atb":[[5.2,0.09]],"id":63579394}],"con":true,"img":false}]}
{"op":"mcm","clk":"11541344813","pt":1719504771334,"mc":[{"id":"1.230178324","rc":[{"atb":[[5.1,0.05]],"id":63579394}],"con":true,"img":false}]}
{"op":"mcm","clk":"11541344829","pt":1719504771544,"mc":[{"id":"1.230178324","rc":[{"atl":[[24,0.35]],"id":70902602}],"con":true,"img":false}]}
{"op":"mcm","clk":"11541344849","pt":1719504771857,"mc":[{"id":"1.230178324","rc":[{"atb":[[4.4,0]],"id":70902602}],"con":true,"img":false}]}
{"op":"mcm","clk":"11541344856","pt":1719504771955,"mc":[{"id":"1.230178324","rc":[{"atb":[[5.4,0]],"id":63579394}],"con":true,"img":false}]}
{"op":"mcm","clk":"11541344867","pt":1719504772058,"mc":[{"id":"1.230178324","rc":[{"atb":[[5.3,2.41]],"id":63579394}],"con":true,"img":false}]}
{"op":"mcm","clk":"11541344886","pt":1719504772267,"mc":[{"id":"1.230178324","rc":[{"atb":[[1.07,1]],"id":70902602},{"atl":[[1000,0.04]],"id":70902602}],"con":true,"img":false}]}
{"op":"mcm","clk":"11541344909","pt":1719504772540,"mc":[{"id":"1.230178324","rc":[{"atb":[[1.07,0.29]],"id":70902602},{"atl":[[1000,0]],"id":70902602}],"con":true,"img":false}]}
{"op":"mcm","clk":"11541344937","pt":1719504772850,"mc":[{"id":"1.230178324","rc":[{"atb":[[1.07,0]],"id":70902602},{"atl":[[24,0.39]],"id":70902602},{"atl":[[9,0.84]],"id":69769647}],"con":true,"img":false}]}
{"op":"mcm","clk":"11541344949","pt":1719504772956,"mc":[{"id":"1.230178324","rc":[{"atb":[[4.4,0.29]],"id":70902602}],"con":true,"img":false}]}
{"op":"mcm","clk":"11541344968","pt":1719504773168,"mc":[{"id":"1.230178324","rc":[{"atb":[[2.72,0]],"id":69769647}],"con":true,"img":false}]}
{"op":"mcm","clk":"11541345013","pt":1719504773541,"mc":[{"id":"1.230178324","rc":[{"atb":[[1.04,1]],"id":69769647},{"atl":[[1000,0.13]],"id":69769647}],"con":true,"img":false}]}
{"op":"mcm","clk":"11541345039","pt":1719504773855,"mc":[{"id":"1.230178324","rc":[{"atb":[[1.04,0.58]],"id":69769647},{"atl":[[1000,0]],"id":69769647}],"con":true,"img":false}]}
{"op":"mcm","clk":"11541345052","pt":1719504773962,"mc":[{"id":"1.230178324","rc":[{"atl":[[8.8,1.09]],"id":69769647}],"con":true,"img":false}]}
{"op":"mcm","clk":"11541345061","pt":1719504774060,"mc":[{"id":"1.230178324","rc":[{"atb":[[1.04,0]],"id":69769647}],"con":true,"img":false}]}
{"op":"mcm","clk":"11541345068","pt":1719504774162,"mc":[{"id":"1.230178324","rc":[{"atb":[[2.72,0.58]],"id":69769647}],"con":true,"img":false}]}
{"op":"mcm","clk":"11541345080","pt":1719504774264,"mc":[{"id":"1.230178324","rc":[{"atl":[[9.2,0.96]],"id":69769647}],"con":true,"img":false}]}
{"op":"mcm","clk":"11541345090","pt":1719504774367,"mc":[{"id":"1.230178324","rc":[{"atl":[[8.8,0.13]],"id":69769647}],"con":true,"img":false}]}
{"op":"mcm","clk":"11541345101","pt":1719504774469,"mc":[{"id":"1.230178324","rc":[{"atb":[[2.54,4.16],[2.7,0]],"id":69769647}],"con":true,"img":false}]}
{"op":"mcm","clk":"11541345112","pt":1719504774530,"mc":[{"id":"1.230178324","rc":[{"atl":[[8.6,0.98],[9.2,0]],"id":69769647}],"con":true,"img":false}]}
{"op":"mcm","clk":"11541345476","pt":1719504778579,"mc":[{"id":"1.230178324","rc":[{"atb":[[2.54,3.16],[2.7,1]],"id":69769647}],"con":true,"img":false}]}
{"op":"mcm","clk":"11541345999","pt":1719504784560,"mc":[{"id":"1.230178324","rc":[{"atb":[[1.06,1.7]],"id":63579394},{"atl":[[1000,1.7]],"id":63579394},{"atb":[[2.38,0],[1.02,15.53]],"id":69769647},{"atl":[[1000,1.7]],"id":69769647},{"atb":[[1.02,3.7]],"id":40626946},{"atl":[[1000,1.93]],"id":40626946}],"con":true,"img":false}]}
{"op":"mcm","clk":"11541346012","pt":1719504784756,"mc":[{"id":"1.230178324","rc":[{"atb":[[1.06,0.04]],"id":63579394},{"atl":[[1000,0.01]],"id":63579394},{"atb":[[1.02,14.01]],"id":69769647},{"atl":[[1000,0.03]],"id":69769647},{"atb":[[1.02,2.12]],"id":40626946},{"atl":[[1000,0.23]],"id":40626946}],"con":true,"img":false}]}
{"op":"mcm","clk":"11541346019","pt":1719504784856,"mc":[{"id":"1.230178324","rc":[{"atb":[[5.1,0]],"id":63579394},{"atl":[[9.2,0.98]],"id":69769647}],"con":true,"img":false}]}
{"op":"mcm","clk":"11541346025","pt":1719504784956,"mc":[{"id":"1.230178324","rc":[{"atl":[[8.6,0]],"id":69769647}],"con":true,"img":false}]}
{"op":"mcm","clk":"11541346035","pt":1719504785066,"mc":[{"id":"1.230178324","rc":[{"atb":[[1.06,0]],"id":63579394},{"atl":[[1000,0]],"id":63579394},{"atb":[[1.02,13.83]],"id":69769647},{"atl":[[1000,0]],"id":69769647},{"atb":[[1.02,2]],"id":40626946},{"atl":[[1000,0.22]],"id":40626946}],"con":true,"img":false}]}
{"op":"mcm","clk":"11541346045","pt":1719504785173,"mc":[{"id":"1.230178324","rc":[{"atb":[[5.4,0.04]],"id":63579394},{"atl":[[12,1.6]],"id":63579394},{"atb":[[2.58,0.18]],"id":69769647},{"atl":[[8.8,0.16]],"id":69769647},{"atb":[[3.4,0.12]],"id":40626946},{"atl":[[32,0]],"id":40626946},{"atb":[[5.1,0]],"id":45129701}],"con":true,"img":false}]}
{"op":"mcm","clk":"11541346053","pt":1719504785268,"mc":[{"id":"1.230178324","rc":[{"atl":[[8.6,0.98],[9.2,0]],"id":69769647},{"atb":[[4.8,0]],"id":40626946}],"con":true,"img":false}]}
{"op":"mcm","clk":"11541346068","pt":1719504785380,"mc":[{"id":"1.230178324","rc":[{"atb":[[2.54,0],[2.58,2.18]],"id":69769647}],"con":true,"img":false}]}
{"op":"mcm","clk":"11541346081","pt":1719504785484,"mc":[{"id":"1.230178324","rc":[{"atb":[[1.12,1.69]],"id":63579394},{"atb":[[5.1,0]],"id":57055802},{"atb":[[3.2,1.57]],"id":45129701}],"con":true,"img":false}]}
{"op":"mcm","clk":"11541346097","pt":1719504785684,"mc":[{"id":"1.230178324","rc":[{"atb":[[4.6,1],[4.2,8]],"id":57055802}],"con":true,"img":false}]}
{"op":"mcm","clk":"11541346106","pt":1719504785789,"mc":[{"id":"1.230178324","rc":[{"atb":[[1.06,1.69]],"id":69769647},{"atb":[[4.8,1.76]],"id":40626946}],"con":true,"img":false}]}
{"op":"mcm","clk":"11541346112","pt":1719504785847,"mc":[{"id":"1.230178324","rc":[{"atb":[[1.12,1.69]],"id":45129701}],"con":true,"img":false}]}
{"op":"mcm","clk":"11541346137","pt":1719504786065,"mc":[{"id":"1.230178324","rc":[{"atb":[[3.95,0]],"id":70902602}],"con":true,"img":false}]}
{"op":"mcm","clk":"11541346146","pt":1719504786164,"mc":[{"id":"1.230178324","rc":[{"atb":[[1.1,1.69]],"id":40626946}],"con":true,"img":false}]}
{"op":"mcm","clk":"11541346158","pt":1719504786261,"mc":[{"id":"1.230178324","rc":[{"atb":[[4.9,0.84]],"id":40626946}],"con":true,"img":false}]}
{"op":"mcm","clk":"11541346170","pt":1719504786368,"mc":[{"id":"1.230178324","rc":[{"atb":[[1.06,0.11]],"id":69769647}],"con":true,"img":false}]}
{"op":"mcm","clk":"11541346180","pt":1719504786478,"mc":[{"id":"1.230178324","rc":[{"atb":[[1.12,1.69]],"id":57055802}],"con":true,"img":false}]}
{"op":"mcm","clk":"11541346197","pt":1719504786686,"mc":[{"id":"1.230178324","rc":[{"atb":[[1.12,0.05]],"id":63579394}],"con":true,"img":false}]}
{"op":"mcm","clk":"11541346209","pt":1719504786786,"mc":[{"id":"1.230178324","rc":[{"atb":[[1.12,0.05]],"id":45129701}],"con":true,"img":false}]}
{"op":"mcm","clk":"11541346226","pt":1719504786950,"mc":[{"id":"1.230178324","rc":[{"atb":[[1.1,1.69]],"id":70902602}],"con":true,"img":false}]}
{"op":"mcm","clk":"11541346253","pt":1719504787265,"mc":[{"id":"1.230178324","rc":[{"atb":[[1.06,0]],"id":69769647},{"atb":[[1.1,0.06]],"id":40626946}],"con":true,"img":false}]}
{"op":"mcm","clk":"11541346261","pt":1719504787362,"mc":[{"id":"1.230178324","rc":[{"atb":[[2.58,2.3]],"id":69769647}],"con":true,"img":false}]}
{"op":"mcm","clk":"11541346298","pt":1719504787778,"mc":[{"id":"1.230178324","rc":[{"atb":[[1.12,0.05]],"id":57055802}],"con":true,"img":false}]}
{"op":"mcm","clk":"11541346333","pt":1719504788093,"mc":[{"id":"1.230178324","rc":[{"atl":[[24,0.35]],"id":70902602},{"atb":[[1.12,0]],"id":63579394}],"con":true,"img":false}]}
{"op":"mcm","clk":"11541346339","pt":1719504788147,"mc":[{"id":"1.230178324","rc":[{"atb":[[5.4,0.1]],"id":63579394},{"atb":[[4.4,0]],"id":70902602}],"con":true,"img":false}]}
{"op":"mcm","clk":"11541346359","pt":1719504788359,"mc":[{"id":"1.230178324","rc":[{"atb":[[1.07,1]],"id":70902602},{"atl":[[1000,0.04]],"id":70902602},{"atb":[[1.12,0]],"id":45129701}],"con":true,"img":false}]}
{"op":"mcm","clk":"11541346368","pt":1719504788454,"mc":[{"id":"1.230178324","rc":[{"atb":[[5.1,0.05]],"id":45129701}],"con":true,"img":false}]}
{"op":"mcm","clk":"11541346377","pt":1719504788563,"mc":[{"id":"1.230178324","rc":[{"atb":[[1.07,0.29]],"id":70902602},{"atl":[[1000,0]],"id":70902602}],"con":true,"img":false}]}
{"op":"mcm","clk":"11541346386","pt":1719504788670,"mc":[{"id":"1.230178324","rc":[{"atl":[[24,0.39]],"id":70902602}],"con":true,"img":false}]}
{"op":"mcm","clk":"11541346400","pt":1719504788871,"mc":[{"id":"1.230178324","rc":[{"atb":[[1.1,0.06],[1.07,0]],"id":70902602}],"con":true,"img":false}]}
{"op":"mcm","clk":"11541346409","pt":1719504788977,"mc":[{"id":"1.230178324","rc":[{"atb":[[4.4,0.29]],"id":70902602},{"atb":[[2.18,0]],"id":63579394},{"atb":[[2.18,0]],"id":57055802},{"atb":[[2.22,0],[1.1,0]],"id":40626946},{"atb":[[2.18,0]],"id":45129701}],"con":true,"img":false}]}
{"op":"mcm","clk":"11541346419","pt":1719504789079,"mc":[{"id":"1.230178324","rc":[{"atb":[[2.22,8.63]],"id":63579394},{"atb":[[2.22,11.96]],"id":57055802},{"atb":[[4.8,1.82],[2.26,12.55]],"id":40626946},{"atb":[[2.22,10.25]],"id":45129701}],"con":true,"img":false}]}
{"op":"mcm","clk":"11541346434","pt":1719504789243,"mc":[{"id":"1.230178324","rc":[{"atl":[[8.8,0.03]],"id":69769647}],"con":true,"img":false}]}
{"op":"mcm","clk":"11541346444","pt":1719504789348,"mc":[{"id":"1.230178324","rc":[{"atb":[[2.72,0]],"id":69769647},{"atb":[[1.12,0]],"id":57055802}],"con":true,"img":false}]}
{"op":"mcm","clk":"11541346452","pt":1719504789451,"mc":[{"id":"1.230178324","rc":[{"atb":[[5.1,0.05]],"id":57055802}],"con":true,"img":false}]}
{"op":"mcm","clk":"11541346470","pt":1719504789667,"mc":[{"id":"1.230178324","rc":[{"atb":[[1.04,1]],"id":69769647},{"atl":[[1000,0.13]],"id":69769647}],"con":true,"img":false}]}
{"op":"mcm","clk":"11541346479","pt":1719504789772,"mc":[{"id":"1.230178324","rc":[{"atb":[[1.1,0]],"id":70902602}],"con":true,"img":false}]}
{"op":"mcm","clk":"11541346486","pt":1719504789881,"mc":[{"id":"1.230178324","rc":[{"atb":[[4.4,0.35]],"id":70902602},{"atb":[[1.04,0.58]],"id":69769647},{"atl":[[1000,0]],"id":69769647}],"con":true,"img":false}]}
{"op":"mcm","clk":"11541346495","pt":1719504789978,"mc":[{"id":"1.230178324","rc":[{"atl":[[8.6,1.11]],"id":69769647}],"con":true,"img":false}]}
{"op":"mcm","clk":"11541346503","pt":1719504790074,"mc":[{"id":"1.230178324","rc":[{"atb":[[1.04,0]],"id":69769647}],"con":true,"img":false}]}
{"op":"mcm","clk":"11541346513","pt":1719504790186,"mc":[{"id":"1.230178324","rc":[{"atb":[[2.72,0.58]],"id":69769647}],"con":true,"img":false}]}
{"op":"mcm","clk":"11541346780","pt":1719504793350,"mc":[{"id":"1.230178324","rc":[{"atb":[[4.6,7]],"id":57055802}],"con":true,"img":false}]}
{"op":"mcm","clk":"11541346789","pt":1719504793458,"mc":[{"id":"1.230178324","rc":[{"atb":[[4.2,0]],"id":57055802}],"con":true,"img":false}]}
{"op":"mcm","clk":"11541347389","pt":1719504800880,"mc":[{"id":"1.230178324","rc":[{"atb":[[4.5,1.87]],"id":70902602}],"con":true,"img":false}]}
{"op":"mcm","clk":"11541347398","pt":1719504800989,"mc":[{"id":"1.230178324","rc":[{"atb":[[4.2,0]],"id":70902602}],"con":true,"img":false}]}
{"op":"mcm","clk":"11541347406","pt":1719504801093,"mc":[{"id":"1.230178324","rc":[{"atb":[[4.3,0.84],[4.5,3.47]],"id":70902602}],"con":true,"img":false}]}
{"op":"mcm","clk":"11541347426","pt":1719504801302,"mc":[{"id":"1.230178324","rc":[{"atb":[[4.3,0],[4.6,0.84]],"id":70902602}],"con":true,"img":false}]}
{"op":"mcm","clk":"11541347442","pt":1719504801467,"mc":[{"id":"1.230178324","rc":[{"atb":[[4.5,1.6]],"id":70902602}],"con":true,"img":false}]}
{"op":"mcm","clk":"11541347472","pt":1719504801774,"mc":[{"id":"1.230178324","rc":[{"atb":[[4.4,2.23]],"id":70902602}],"con":true,"img":false}]}
{"op":"mcm","clk":"11541347628","pt":1719504803691,"mc":[{"id":"1.230178324","rc":[{"atb":[[3,0],[2.66,8.55]],"id":70902602},{"atb":[[3.85,0],[3.4,8.63]],"id":63579394},{"atb":[[4.6,1],[4.1,12]],"id":57055802}],"con":true,"img":false}]}
{"op":"mcm","clk":"11541347637","pt":1719504803796,"mc":[{"id":"1.230178324","rc":[{"atb":[[5.3,0],[5.4,0]],"id":63579394},{"atl":[[5.3,2.4]],"id":63579394},{"trd":[[5.3,4.83],[5.4,0.2]],"ltp":5.3,"tv":5.03,"id":63579394},{"atb":[[2.72,0],[2.7,0]],"id":69769647},{"atl":[[2.7,8.07]],"id":69769647},{"trd":[[2.7,2],[2.72,1.16]],"ltp":2.7,"tv":3.16,"id":69769647},{"atb":[[4.8,0],[4.9,0]],"id":40626946},{"atl":[[4.8,2.75]],"id":40626946},{"trd":[[4.8,3.65],[4.9,1.69]],"ltp":4.8,"tv":5.34,"id":40626946}],"con":true,"img":false}]}
{"op":"mcm","clk":"11541347644","pt":1719504803899,"mc":[{"id":"1.230178324","rc":[{"atl":[[5.3,0]],"id":63579394},{"trd":[[5.3,9.62]],"ltp":5.3,"tv":9.62,"id":63579394},{"atl":[[24,0.35]],"id":70902602},{"atb":[[2.64,1],[2.58,0.3],[2.36,10.05],[2.7,0.26]],"id":69769647},{"atl":[[2.7,0]],"id":69769647},{"trd":[[2.7,18.14]],"ltp":2.7,"tv":18.14,"id":69769647},{"atb":[[4.8,0.26]],"id":40626946},{"atl":[[4.8,0],[34,1.74],[13,4.77]],"id":40626946},{"trd":[[4.8,9.15]],"ltp":4.8,"tv":9.15,"id":40626946}],"con":true,"img":false}]}
{"op":"mcm","clk":"11541347653","pt":1719504804007,"mc":[{"id":"1.230178324","rc":[{"atb":[[2.56,5.46],[2.36,0],[2.7,8.33]],"id":69769647},{"atl":[[32,3.23]],"id":40626946}],"con":true,"img":false}]}
{"op":"mcm","clk":"11541347662","pt":1719504804074,"mc":[{"id":"1.230178324","rc":[{"atb":[[4.4,2.16],[4.6,2.68]],"id":70902602},{"atb":[[2.58,0.18]],"id":69769647},{"atb":[[5.1,0]],"id":57055802},{"atl":[[13,0]],"id":40626946},{"atb":[[5.1,0],[5.2,1.62]],"id":45129701}],"con":true,"img":false}]}
{"op":"mcm","clk":"11541347668","pt":1719504804169,"mc":[{"id":"1.230178324","rc":[{"atb":[[4.4,1.87],[2.88,7.5]],"id":70902602},{"atb":[[2.72,2],[2.56,0.84],[1.04,150.64]],"id":69769647}],"con":true,"img":false}]}
{"op":"mcm","clk":"11541347675","pt":1719504804268,"mc":[{"id":"1.230178324","rc":[{"atb":[[5.1,0.84]],"id":63579394},{"atb":[[2.56,0]],"id":69769647}],"con":true,"img":false}]}
{"op":"mcm","clk":"11541347681","pt":1719504804372,"mc":[{"id":"1.230178324","rc":[{"atb":[[5.2,1.62]],"id":57055802}],"con":true,"img":false}]}
{"op":"mcm","clk":"11541347688","pt":1719504804476,"mc":[{"id":"1.230178324","rc":[{"atb":[[4.4,0]],"id":70902602},{"atb":[[2.72,4.45]],"id":69769647},{"atb":[[3.4,2.63]],"id":40626946}],"con":true,"img":false}]}
{"op":"mcm","clk":"11541347696","pt":1719504804578,"mc":[{"id":"1.230178324","rc":[{"atl":[[25,1.63]],"id":70902602}],"con":true,"img":false}]}
{"op":"mcm","clk":"11541347705","pt":1719504804682,"mc":[{"id":"1.230178324","rc":[{"atb":[[2.7,0.26]],"id":69769647},{"atl":[[9.2,0.98]],"id":69769647}],"con":true,"img":false}]}
{"op":"mcm","clk":"11541347718","pt":1719504804791,"mc":[{"id":"1.230178324","rc":[{"atl":[[9.4,2.07]],"id":69769647},{"atb":[[5.1,1.62]],"id":45129701}],"con":true,"img":false}]}
{"op":"mcm","clk":"11541347730","pt":1719504804991,"mc":[{"id":"1.230178324","rc":[{"atl":[[24,1.41]],"id":70902602},{"atb":[[5.2,0]],"id":45129701}],"con":true,"img":false}]}
{"op":"mcm","clk":"11541347743","pt":1719504805101,"mc":[{"id":"1.230178324","rc":[{"atl":[[24,3.41],[26,1.71]],"id":70902602},{"atb":[[2.72,2.84]],"id":69769647},{"atl":[[8.6,0.13]],"id":69769647}],"con":true,"img":false}]}
{"op":"mcm","clk":"11541347750","pt":1719504805155,"mc":[{"id":"1.230178324","rc":[{"atl":[[24,1.41],[25,5.8]],"id":70902602},{"atl":[[8.6,0]],"id":69769647}],"con":true,"img":false}]}
{"op":"mcm","clk":"11541347759","pt":1719504805254,"mc":[{"id":"1.230178324","rc":[{"atl":[[25,5.49]],"id":70902602}],"con":true,"img":false}]}
{"op":"mcm","clk":"11541347766","pt":1719504805360,"mc":[{"id":"1.230178324","rc":[{"atl":[[960,1.84]],"id":63579394},{"atb":[[2.7,0]],"id":69769647},{"atb":[[5.2,0]],"id":57055802},{"atb":[[4.8,0]],"id":40626946}],"con":true,"img":false}]}
{"op":"mcm","clk":"11541347789","pt":1719504805672,"mc":[{"id":"1.230178324","rc":[{"atb":[[5.1,1.62]],"id":57055802}],"con":true,"img":false}]}
{"op":"mcm","clk":"11541347803","pt":1719504805877,"mc":[{"id":"1.230178324","rc":[{"atb":[[2.72,2]],"id":69769647},{"atb":[[3.4,2.06]],"id":40626946}],"con":true,"img":false}]}
{"op":"mcm","clk":"11541348084","pt":1719504809268,"mc":[{"id":"1.230178324","rc":[{"atb":[[2.72,0],[2.58,3.34]],"id":69769647}],"con":true,"img":false}]}
{"op":"mcm","clk":"11541348113","pt":1719504809576,"mc":[{"id":"1.230178324","rc":[{"atl":[[990,1.81]],"id":69769647}],"con":true,"img":false}]}
{"op":"mcm","clk":"11541348138","pt":1719504809987,"mc":[{"id":"1.230178324","rc":[{"atb":[[3.05,0]],"id":70902602}],"con":true,"img":false}]}
{"op":"mcm","clk":"11541348146","pt":1719504810087,"mc":[{"id":"1.230178324","rc":[{"atb":[[4.5,0],[4.6,4.25]],"id":70902602}],"con":true,"img":false}]}
{"op":"mcm","clk":"11541348152","pt":1719504810192,"mc":[{"id":"1.230178324","rc":[{"atl":[[990,1.82]],"id":45129701}],"con":true,"img":false}]}
{"op":"mcm","clk":"11541348163","pt":1719504810396,"mc":[{"id":"1.230178324","rc":[{"atl":[[9,1.89]],"id":69769647}],"con":true,"img":false}]}
{"op":"mcm","clk":"11541348175","pt":1719504810513,"mc":[{"id":"1.230178324","rc":[{"atb":[[2.66,0.95]],"id":69769647}],"con":true,"img":false}]}
{"op":"mcm","clk":"11541348536","pt":1719504815173,"mc":[{"id":"1.230178324","rc":[{"atb":[[5.2,0]],"id":63579394},{"trd":[[5.2,0.18]],"ltp":5.2,"tv":0.18,"id":63579394}],"con":true,"img":false}]}
{"op":"mcm","clk":"11541348568","pt":1719504815648,"mc":[{"id":"1.230178324","rc":[{"atl":[[990,0.85]],"id":40626946}],"con":true,"img":false}]}
{"op":"mcm","clk":"11541348612","pt":1719504816206,"mc":[{"id":"1.230178324","rc":[{"atb":[[1.03,126.94]],"id":70902602}],"con":true,"img":false}]}
{"op":"mcm","clk":"11541348619","pt":1719504816306,"mc":[{"id":"1.230178324","rc":[{"atb":[[1.01,0.71]],"id":69769647}],"con":true,"img":false}]}
{"op":"mcm","clk":"11541348670","pt":1719504816890,"mc":[{"id":"1.230178324","rc":[{"atb":[[1.01,0.28]],"id":69769647}],"con":true,"img":false}]}
{"op":"mcm","clk":"11541348687","pt":1719504817093,"mc":[{"id":"1.230178324","rc":[{"atb":[[1.01,1]],"id":69769647}],"con":true,"img":false}]}
{"op":"mcm","clk":"11541348714","pt":1719504817403,"mc":[{"id":"1.230178324","rc":[{"atb":[[1.01,0.71]],"id":69769647}],"con":true,"img":false}]}
{"op":"mcm","clk":"11541348719","pt":1719504817498,"mc":[{"id":"1.230178324","rc":[{"atb":[[1.01,1],[2.66,1.23]],"id":69769647}],"con":true,"img":false}]}
{"op":"mcm","clk":"11541348735","pt":1719504817707,"mc":[{"id":"1.230178324","rc":[{"atb":[[2.58,0.18],[2.66,3.23]],"id":69769647}],"con":true,"img":false}]}
{"op":"mcm","clk":"11541348778","pt":1719504818133,"mc":[{"id":"1.230178324","rc":[{"atb":[[1.01,0.71]],"id":69769647}],"con":true,"img":false}]}
{"op":"mcm","clk":"11541348788","pt":1719504818190,"mc":[{"id":"1.230178324","rc":[{"atb":[[1.01,0.28],[2.64,1.28]],"id":69769647}],"con":true,"img":false}]}
{"op":"mcm","clk":"11541348797","pt":1719504818293,"mc":[{"id":"1.230178324","rc":[{"atb":[[2.68,0.84]],"id":69769647}],"con":true,"img":false}]}
{"op":"mcm","clk":"11541348807","pt":1719504818396,"mc":[{"id":"1.230178324","rc":[{"atb":[[2.6,5]],"id":69769647}],"con":true,"img":false}]}
{"op":"mcm","clk":"11541348827","pt":1719504818605,"mc":[{"id":"1.230178324","rc":[{"atl":[[960,0.84]],"id":57055802}],"con":true,"img":false}]}
{"op":"mcm","clk":"11541348835","pt":1719504818705,"mc":[{"id":"1.230178324","rc":[{"atb":[[1.01,0]],"id":69769647}],"con":true,"img":false}]}
{"op":"mcm","clk":"11541348842","pt":1719504818812,"mc":[{"id":"1.230178324","rc":[{"atb":[[2.6,5.28]],"id":69769647}],"con":true,"img":false}]}
{"op":"mcm","clk":"11541348855","pt":1719504818913,"mc":[{"id":"1.230178324","rc":[{"atb":[[2.68,1.69]],"id":69769647}],"con":true,"img":false}]}
{"op":"mcm","clk":"11541348886","pt":1719504819226,"mc":[{"id":"1.230178324","rc":[{"atb":[[1.03,160.79]],"id":57055802}],"con":true,"img":false}]}
{"op":"mcm","clk":"11541348909","pt":1719504819490,"mc":[{"id":"1.230178324","rc":[{"atb":[[2.68,3.3]],"id":69769647}],"con":true,"img":false}]}
{"op":"mcm","clk":"11541348980","pt":1719504820413,"mc":[{"id":"1.230178324","rc":[{"atb":[[1.01,0.71]],"id":69769647}],"con":true,"img":false}]}
{"op":"mcm","clk":"11541348987","pt":1719504820512,"mc":[{"id":"1.230178324","rc":[{"atb":[[2.68,2.73]],"id":69769647}],"con":true,"img":false}]}
{"op":"mcm","clk":"11541349002","pt":1719504820719,"mc":[{"id":"1.230178324","rc":[{"atb":[[2.66,8.05],[2.68,1.12]],"id":69769647}],"con":true,"img":false}]}
{"op":"mcm","clk":"11541349012","pt":1719504820825,"mc":[{"id":"1.230178324","rc":[{"atb":[[1.01,0.28]],"id":69769647}],"con":true,"img":false}]}
{"op":"mcm","clk":"11541349024","pt":1719504820981,"mc":[{"id":"1.230178324","rc":[{"atb":[[2.66,9.28]],"id":69769647}],"con":true,"img":false}]}
{"op":"mcm","clk":"11541349054","pt":1719504821297,"mc":[{"id":"1.230178324","rc":[{"atb":[[1.01,0]],"id":69769647}],"con":true,"img":false}]}
{"op":"mcm","clk":"11541349062","pt":1719504821396,"mc":[{"id":"1.230178324","rc":[{"atb":[[1.01,0.71],[2.62,0.28]],"id":69769647}],"con":true,"img":false}]}
{"op":"mcm","clk":"11541349080","pt":1719504821603,"mc":[{"id":"1.230178324","rc":[{"atl":[[12,1.54]],"id":63579394},{"atb":[[2.58,0]],"id":69769647},{"atl":[[8.8,0]],"id":69769647},{"atb":[[3.4,1.93],[1.04,130.33]],"id":40626946},{"atl":[[32,3.23]],"id":40626946}],"con":true,"img":false}]}
{"op":"mcm","clk":"11541349108","pt":1719504822015,"mc":[{"id":"1.230178324","rc":[{"atb":[[1.01,0.28]],"id":69769647}],"con":true,"img":false}]}
{"op":"mcm","clk":"11541349158","pt":1719504822629,"mc":[{"id":"1.230178324","rc":[{"atb":[[1.01,0]],"id":69769647}],"con":true,"img":false}]}
{"op":"mcm","clk":"11541349168","pt":1719504822694,"mc":[{"id":"1.230178324","rc":[{"atb":[[2.68,1.41]],"id":69769647}],"con":true,"img":false}]}
{"op":"mcm","clk":"11541349247","pt":1719504823628,"mc":[{"id":"1.230178324","rc":[{"atb":[[1.01,0.71]],"id":69769647}],"con":true,"img":false}]}
{"op":"mcm","clk":"11541349296","pt":1719504824104,"mc":[{"id":"1.230178324","rc":[{"atb":[[1.01,0.28]],"id":69769647}],"con":true,"img":false}]}
{"op":"mcm","clk":"11541349342","pt":1719504824613,"mc":[{"id":"1.230178324","rc":[{"atb":[[1.01,0]],"id":69769647}],"con":true,"img":false}]}
{"op":"mcm","clk":"11541349352","pt":1719504824716,"mc":[{"id":"1.230178324","rc":[{"atb":[[2.7,0.28]],"id":69769647}],"con":true,"img":false}]}
{"op":"mcm","clk":"11541349431","pt":1719504825702,"mc":[{"id":"1.230178324","rc":[{"atl":[[9,0.84]],"id":69769647}],"con":true,"img":false}]}
{"op":"mcm","clk":"11541349446","pt":1719504825901,"mc":[{"id":"1.230178324","rc":[{"atb":[[5.1,0]],"id":63579394},{"trd":[[5.1,1.69]],"ltp":5.1,"tv":1.69,"id":63579394}],"con":true,"img":false}]}
{"op":"mcm","clk":"11541349453","pt":1719504826006,"mc":[{"id":"1.230178324","rc":[{"atb":[[2.66,8.33]],"id":69769647}],"con":true,"img":false}]}
{"op":"mcm","clk":"11541349461","pt":1719504826116,"mc":[{"id":"1.230178324","rc":[{"atl":[[1000,0.71]],"id":69769647}],"con":true,"img":false}]}
{"op":"mcm","clk":"11541349478","pt":1719504826320,"mc":[{"id":"1.230178324","rc":[{"atl":[[8.8,1.05]],"id":69769647}],"con":true,"img":false}]}
{"op":"mcm","clk":"11541349487","pt":1719504826423,"mc":[{"id":"1.230178324","rc":[{"atb":[[3.8,2.86]],"id":63579394},{"atb":[[2.7,1.21]],"id":69769647},{"atb":[[3.4,5.26]],"id":40626946}],"con":true,"img":false}]}
{"op":"mcm","clk":"11541349496","pt":1719504826525,"mc":[{"id":"1.230178324","rc":[{"atl":[[1000,1.42]],"id":69769647}],"con":true,"img":false}]}
{"op":"mcm","clk":"11541349505","pt":1719504826629,"mc":[{"id":"1.230178324","rc":[{"atb":[[2.66,6.33],[2.7,3.21]],"id":69769647},{"atl":[[1000,1]],"id":69769647}],"con":true,"img":false}]}
{"op":"mcm","clk":"11541349528","pt":1719504826932,"mc":[{"id":"1.230178324","rc":[{"atl":[[1000,1.71]],"id":69769647}],"con":true,"img":false}]}
{"op":"mcm","clk":"11541349539","pt":1719504827043,"mc":[{"id":"1.230178324","rc":[{"atl":[[1000,1.28]],"id":69769647}],"con":true,"img":false}]}
{"op":"mcm","clk":"11541349550","pt":1719504827141,"mc":[{"id":"1.230178324","rc":[{"atl":[[1000,1]],"id":69769647}],"con":true,"img":false}]}
{"op":"mcm","clk":"11541349559","pt":1719504827223,"mc":[{"id":"1.230178324","rc":[{"atl":[[9,1.13]],"id":69769647}],"con":true,"img":false}]}
{"op":"mcm","clk":"11541349567","pt":1719504827317,"mc":[{"id":"1.230178324","rc":[{"atb":[[2.72,1.6]],"id":69769647}],"con":true,"img":false}]}
{"op":"mcm","clk":"11541349574","pt":1719504827406,"mc":[{"id":"1.230178324","rc":[{"atl":[[1000,0.28]],"id":69769647}],"con":true,"img":false}]}
{"op":"mcm","clk":"11541349584","pt":1719504827510,"mc":[{"id":"1.230178324","rc":[{"atl":[[8.8,1.33]],"id":69769647}],"con":true,"img":false}]}
{"op":"mcm","clk":"11541349593","pt":1719504827613,"mc":[{"id":"1.230178324","rc":[{"atb":[[2.68,1.13]],"id":69769647}],"con":true,"img":false}]}
{"op":"mcm","clk":"11541349601","pt":1719504827718,"mc":[{"id":"1.230178324","rc":[{"atb":[[2.72,1.88]],"id":69769647}],"con":true,"img":false}]}
{"op":"mcm","clk":"11541349615","pt":1719504827930,"mc":[{"id":"1.230178324","rc":[{"atb":[[1.54,11.7]],"id":69769647},{"atl":[[1000,0]],"id":69769647}],"con":true,"img":false}]}
{"op":"mcm","clk":"11541349625","pt":1719504828027,"mc":[{"id":"1.230178324","rc":[{"atb":[[2.34,0]],"id":69769647},{"atl":[[8.6,0.28]],"id":69769647}],"con":true,"img":false}]}
{"op":"mcm","clk":"11541349640","pt":1719504828233,"mc":[{"id":"1.230178324","rc":[{"atb":[[2.16,5.45]],"id":63579394}],"con":true,"img":false}]}
{"op":"mcm","clk":"11541349647","pt":1719504828336,"mc":[{"id":"1.230178324","rc":[{"atb":[[2.66,5.1],[2.68,0.28]],"id":69769647},{"atb":[[2.16,8.83]],"id":40626946}],"con":true,"img":false}]}
{"op":"mcm","clk":"11541349651","pt":1719504828437,"mc":[{"id":"1.230178324","rc":[{"atb":[[2.16,5.45]],"id":45129701}],"con":true,"img":false}]}
{"op":"mcm","clk":"11541349672","pt":1719504828612,"mc":[{"id":"1.230178324","rc":[{"atb":[[2.36,5.8]],"id":69769647},{"atb":[[2.16,5.45]],"id":57055802}],"con":true,"img":false}]}
{"op":"mcm","clk":"11541349693","pt":1719504828817,"mc":[{"id":"1.230178324","rc":[{"atb":[[2.16,12.26]],"id":63579394},{"spn":8.5,"spf":"NaN","id":63579394},{"spn":14.3,"spf":"NaN","id":70902602},{"atb":[[2.66,6.24]],"id":69769647},{"spn":2.7,"spf":1.0,"id":69769647},{"spn":7.6,"spf":"NaN","id":40626946}],"con":true,"img":false}]}
{"op":"mcm","clk":"11541349708","pt":1719504829023,"mc":[{"id":"1.230178324","rc":[{"atb":[[2.16,15.65]],"id":40626946}],"con":true,"img":false}]}
{"op":"mcm","clk":"11541349725","pt":1719504829225,"mc":[{"id":"1.230178324","rc":[{"atb":[[2.16,12.26]],"id":45129701}],"con":true,"img":false}]}
{"op":"mcm","clk":"11541349743","pt":1719504829435,"mc":[{"id":"1.230178324","rc":[{"atb":[[1.03,137.94]],"id":63579394},{"atb":[[1.97,9.77]],"id":69769647}],"con":true,"img":false}]}
{"op":"mcm","clk":"11541349763","pt":1719504829643,"mc":[{"id":"1.230178324","rc":[{"atb":[[2.12,7.76]],"id":69769647}],"con":true,"img":false}]}
{"op":"mcm","clk":"11541349770","pt":1719504829734,"mc":[{"id":"1.230178324","rc":[{"atb":[[2.8,5.27]],"id":40626946}],"con":true,"img":false}]}
{"op":"mcm","clk":"11541349787","pt":1719504829945,"mc":[{"id":"1.230178324","rc":[{"atb":[[2.68,3.44]],"id":69769647}],"con":true,"img":false}]}
{"op":"mcm","clk":"11541349809","pt":1719504830110,"mc":[{"id":"1.230178324","rc":[{"atb":[[2.98,4.39]],"id":40626946}],"con":true,"img":false}]}
{"op":"mcm","clk":"11541349842","pt":1719504830624,"mc":[{"id":"1.230178324","rc":[{"atb":[[3.4,6.39]],"id":40626946}],"con":true,"img":false}]}
{"op":"mcm","clk":"11541349886","pt":1719504831247,"mc":[{"id":"1.230178324","rc":[{"atl":[[980,2.25]],"id":70902602}],"con":true,"img":false}]}
{"op":"mcm","clk":"11541350284","pt":1719504836640,"mc":[{"id":"1.230178324","rc":[{"atb":[[5,0]],"id":63579394},{"trd":[[5,4.03]],"ltp":5.0,"tv":4.03,"id":63579394}],"con":true,"img":false}]}
{"op":"mcm","clk":"11541350290","pt":1719504836739,"mc":[{"id":"1.230178324","rc":[{"atb":[[2.72,6.53]],"id":69769647}],"con":true,"img":false}]}
{"op":"mcm","clk":"11541350299","pt":1719504836842,"mc":[{"id":"1.230178324","rc":[{"atb":[[2.74,3.45],[2.7,1.21]],"id":69769647}],"con":true,"img":false}]}
{"op":"mcm","clk":"11541350309","pt":1719504836944,"mc":[{"id":"1.230178324","rc":[{"atb":[[3.85,1.73]],"id":63579394}],"con":true,"img":false}]}
{"op":"mcm","clk":"11541350331","pt":1719504837323,"mc":[{"id":"1.230178324","rc":[{"atb":[[3.9,0.84]],"id":63579394},{"atb":[[2.66,5.1]],"id":69769647}],"con":true,"img":false}]}
{"op":"mcm","clk":"11541350336","pt":1719504837427,"mc":[{"id":"1.230178324","rc":[{"atb":[[2.72,7.67]],"id":69769647}],"con":true,"img":false}]}
{"op":"mcm","clk":"11541350342","pt":1719504837529,"mc":[{"id":"1.230178324","rc":[{"atb":[[2.72,6.07]],"id":69769647}],"con":true,"img":false}]}
{"op":"mcm","clk":"11541350348","pt":1719504837627,"mc":[{"id":"1.230178324","rc":[{"atl":[[11.5,1.05]],"id":63579394},{"atb":[[2.76,1.6]],"id":69769647}],"con":true,"img":false}]}
{"op":"mcm","clk":"11541350356","pt":1719504837839,"mc":[{"id":"1.230178324","rc":[{"atb":[[3.9,2.23]],"id":63579394}],"con":true,"img":false}]}
{"op":"mcm","clk":"11541350362","pt":1719504837937,"mc":[{"id":"1.230178324","rc":[{"atb":[[2.72,5.79]],"id":69769647}],"con":true,"img":false}]}
{"op":"mcm","clk":"11541350368","pt":1719504838040,"mc":[{"id":"1.230178324","rc":[{"atb":[[2.76,1.88]],"id":69769647}],"con":true,"img":false}]}
{"op":"mcm","clk":"11541350382","pt":1719504838240,"mc":[{"id":"1.230178324","rc":[{"atb":[[3.85,0]],"id":63579394}],"con":true,"img":false}]}
{"op":"mcm","clk":"11541350389","pt":1719504838345,"mc":[{"id":"1.230178324","rc":[{"atb":[[3.9,3.96]],"id":63579394}],"con":true,"img":false}]}
{"op":"mcm","clk":"11541350427","pt":1719504838820,"mc":[{"id":"1.230178324","rc":[{"atb":[[1.01,0.71]],"id":69769647}],"con":true,"img":false}]}
{"op":"mcm","clk":"11541350452","pt":1719504839132,"mc":[{"id":"1.230178324","rc":[{"atb":[[4.5,1]],"id":63579394},{"atb":[[3.75,1]],"id":69769647}],"con":true,"img":false}]}
{"op":"mcm","clk":"11541350473","pt":1719504839343,"mc":[{"id":"1.230178324","rc":[{"atb":[[3.9,3.39]],"id":63579394},{"atb":[[1.01,1],[2.76,6.43]],"id":69769647}],"con":true,"img":false}]}
{"op":"mcm","clk":"11541350499","pt":1719504839647,"mc":[{"id":"1.230178324","rc":[{"atb":[[2.72,4.65]],"id":69769647}],"con":true,"img":false}]}
{"op":"mcm","clk":"11541350509","pt":1719504839751,"mc":[{"id":"1.230178324","rc":[{"atb":[[2.76,7.57]],"id":69769647}],"con":true,"img":false}]}
{"op":"mcm","clk":"11541350524","pt":1719504839949,"mc":[{"id":"1.230178324","rc":[{"atb":[[1.01,0.28]],"id":69769647}],"con":true,"img":false}]}
{"op":"mcm","clk":"11541350533","pt":1719504840018,"mc":[{"id":"1.230178324","rc":[{"atb":[[2.72,4.93]],"id":69769647}],"con":true,"img":false}]}
{"op":"mcm","clk":"11541350555","pt":1719504840326,"mc":[{"id":"1.230178324","rc":[{"atb":[[1.01,1]],"id":69769647}],"con":true,"img":false}]}
{"op":"mcm","clk":"11541350563","pt":1719504840427,"mc":[{"id":"1.230178324","rc":[{"atb":[[1.01,0.71]],"id":69769647}],"con":true,"img":false}]}
{"op":"mcm","clk":"11541350573","pt":1719504840535,"mc":[{"id":"1.230178324","rc":[{"atb":[[2.74,3.73]],"id":69769647}],"con":true,"img":false}]}
{"op":"mcm","clk":"11541350597","pt":1719504840846,"mc":[{"id":"1.230178324","rc":[{"atb":[[1.01,0.28]],"id":69769647}],"con":true,"img":false}]}
{"op":"mcm","clk":"11541350607","pt":1719504840949,"mc":[{"id":"1.230178324","rc":[{"atl":[[1000,1.7]],"id":63579394}],"con":true,"img":false}]}
{"op":"mcm","clk":"11541350615","pt":1719504841048,"mc":[{"id":"1.230178324","rc":[{"atb":[[1.03,139.65]],"id":63579394}],"con":true,"img":false}]}
{"op":"mcm","clk":"11541350624","pt":1719504841152,"mc":[{"id":"1.230178324","rc":[{"atl":[[1000,0.02]],"id":63579394}],"con":true,"img":false}]}
{"op":"mcm","clk":"11541350632","pt":1719504841252,"mc":[{"id":"1.230178324","rc":[{"atb":[[1.03,138.04]],"id":63579394}],"con":true,"img":false}]}
{"op":"mcm","clk":"11541350643","pt":1719504841322,"mc":[{"id":"1.230178324","rc":[{"atb":[[1.01,0]],"id":69769647}],"con":true,"img":false}]}
{"op":"mcm","clk":"11541350655","pt":1719504841425,"mc":[{"id":"1.230178324","rc":[{"atb":[[1.03,137.94]],"id":63579394},{"atl":[[1000,0]],"id":63579394},{"atb":[[2.76,7.86]],"id":69769647}],"con":true,"img":false}]}
{"op":"mcm","clk":"11541350663","pt":1719504841529,"mc":[{"id":"1.230178324","rc":[{"atb":[[3.95,0.09]],"id":63579394},{"atl":[[11.5,1.07]],"id":63579394},{"atb":[[1.01,1]],"id":69769647}],"con":true,"img":false}]}
{"op":"mcm","clk":"11541350685","pt":1719504841751,"mc":[{"id":"1.230178324","rc":[{"atb":[[2.2,0]],"id":63579394},{"atb":[[2.2,0]],"id":57055802},{"atb":[[2.24,0]],"id":40626946},{"atb":[[2.2,0]],"id":45129701}],"con":true,"img":false}]}
{"op":"mcm","clk":"11541350693","pt":1719504841866,"mc":[{"id":"1.230178324","rc":[{"atb":[[2.7,0.28]],"id":69769647},{"atl":[[8.4,1]],"id":69769647},{"atl":[[180,1]],"id":57055802},{"atb":[[3.45,1]],"id":40626946},{"atb":[[5.3,1]],"id":45129701}],"con":true,"img":false}]}
{"op":"mcm","clk":"11541350698","pt":1719504841927,"mc":[{"id":"1.230178324","rc":[{"atb":[[5.3,1]],"id":63579394}],"con":true,"img":false}]}
{"op":"mcm","clk":"11541350712","pt":1719504842041,"mc":[{"id":"1.230178324","rc":[{"atl":[[8.8,0.28]],"id":69769647}],"con":true,"img":false}]}
{"op":"mcm","clk":"11541350724","pt":1719504842159,"mc":[{"id":"1.230178324","rc":[{"atb":[[5.4,1.56],[5.1,0]],"id":45129701}],"con":true,"img":false}]}
{"op":"mcm","clk":"11541350745","pt":1719504842359,"mc":[{"id":"1.230178324","rc":[{"atb":[[3.9,2.54]],"id":63579394}],"con":true,"img":false}]}
{"op":"mcm","clk":"11541350811","pt":1719504842941,"mc":[{"id":"1.230178324","rc":[{"atb":[[3.9,0.81]],"id":63579394}],"con":true,"img":false}]}
{"op":"mcm","clk":"11541350821","pt":1719504843042,"mc":[{"id":"1.230178324","rc":[{"atb":[[3.85,1.73]],"id":63579394}],"con":true,"img":false}]}
{"op":"mcm","clk":"11541351010","pt":1719504844922,"mc":[{"id":"1.230178324","rc":[{"atl":[[13.5,4],[15,0]],"id":63579394},{"atl":[[8.8,2.28]],"id":69769647},{"atl":[[17.5,5.56]],"id":45129701}],"con":true,"img":false}]}
{"op":"mcm","clk":"11541351018","pt":1719504845034,"mc":[{"id":"1.230178324","rc":[{"atl":[[9.6,0]],"id":69769647},{"atl":[[19,0]],"id":45129701}],"con":true,"img":false}]}
{"op":"mcm","clk":"11541351195","pt":1719504847294,"mc":[{"id":"1.230178324","rc":[{"atb":[[2.24,11.66]],"id":57055802}],"con":true,"img":false}]}
{"op":"mcm","clk":"11541351226","pt":1719504847559,"mc":[{"id":"1.230178324","rc":[{"atb":[[2.18,0]],"id":69769647},{"atb":[[2.24,11.66]],"id":45129701}],"con":true,"img":false}]}
{"op":"mcm","clk":"11541351251","pt":1719504847865,"mc":[{"id":"1.230178324","rc":[{"atb":[[2.24,9.56]],"id":63579394},{"atb":[[2.68,0.28]],"id":69769647}],"con":true,"img":false}]}
{"op":"mcm","clk":"11541351274","pt":1719504848089,"mc":[{"id":"1.230178324","rc":[{"atb":[[2.28,11.36]],"id":40626946}],"con":true,"img":false}]}
{"op":"mcm","clk":"11541351283","pt":1719504848177,"mc":[{"id":"1.230178324","rc":[{"atb":[[5.3,0]],"id":63579394},{"trd":[[5.3,11.62]],"ltp":5.3,"tv":11.62,"id":63579394},{"atb":[[3.75,0]],"id":69769647},{"trd":[[3.75,1.99]],"ltp":3.75,"tv":1.99,"id":69769647}],"con":true,"img":false}]}
{"op":"mcm","clk":"11541351293","pt":1719504848238,"mc":[{"id":"1.230178324","rc":[{"atb":[[2.74,0.28],[2.78,8.1]],"id":69769647}],"con":true,"img":false}]}
{"op":"mcm","clk":"11541351306","pt":1719504848343,"mc":[{"id":"1.230178324","rc":[{"atl":[[12,2.54]],"id":63579394}],"con":true,"img":false}]}
{"op":"mcm","clk":"11541351317","pt":1719504848443,"mc":[{"id":"1.230178324","rc":[{"atl":[[8.4,0]],"id":69769647},{"atl":[[180,0]],"id":57055802}],"con":true,"img":false}]}
{"op":"mcm","clk":"11541351343","pt":1719504848752,"mc":[{"id":"1.230178324","rc":[{"atb":[[2.76,6.72]],"id":69769647}],"con":true,"img":false}]}
{"op":"mcm","clk":"11541351354","pt":1719504848856,"mc":[{"id":"1.230178324","rc":[{"atb":[[2.78,9.24]],"id":69769647},{"atl":[[8.8,3.42]],"id":69769647}],"con":true,"img":false}]}
{"op":"mcm","clk":"11541351365","pt":1719504848959,"mc":[{"id":"1.230178324","rc":[{"atb":[[2.8,0.84]],"id":69769647},{"atl":[[8.6,1.13]],"id":69769647}],"con":true,"img":false}]}
{"op":"mcm","clk":"11541351375","pt":1719504849056,"mc":[{"id":"1.230178324","rc":[{"atb":[[2.76,5.11]],"id":69769647}],"con":true,"img":false}]}
{"op":"mcm","clk":"11541351385","pt":1719504849166,"mc":[{"id":"1.230178324","rc":[{"atb":[[2.8,2.45]],"id":69769647}],"con":true,"img":false}]}
{"op":"mcm","clk":"11541351477","pt":1719504850051,"mc":[{"id":"1.230178324","rc":[{"atb":[[1.01,1.71]],"id":69769647}],"con":true,"img":false}]}
{"op":"mcm","clk":"11541351514","pt":1719504850469,"mc":[{"id":"1.230178324","rc":[{"atb":[[1.01,2.42]],"id":69769647}],"con":true,"img":false}]}
{"op":"mcm","clk":"11541351534","pt":1719504850666,"mc":[{"id":"1.230178324","rc":[{"atb":[[1.01,2]],"id":69769647}],"con":true,"img":false}]}
{"op":"mcm","clk":"11541351568","pt":1719504850978,"mc":[{"id":"1.230178324","rc":[{"atb":[[1.01,1.57]],"id":69769647}],"con":true,"img":false}]}
{"op":"mcm","clk":"11541351587","pt":1719504851187,"mc":[{"id":"1.230178324","rc":[{"atb":[[1.01,1.28]],"id":69769647}],"con":true,"img":false}]}
{"op":"mcm","clk":"11541351597","pt":1719504851292,"mc":[{"id":"1.230178324","rc":[{"atb":[[2.78,9.52]],"id":69769647}],"con":true,"img":false}]}
{"op":"mcm","clk":"11541351628","pt":1719504851559,"mc":[{"id":"1.230178324","rc":[{"atb":[[1.01,1]],"id":69769647}],"con":true,"img":false}]}
{"op":"mcm","clk":"11541351637","pt":1719504851666,"mc":[{"id":"1.230178324","rc":[{"atb":[[2.8,2.74]],"id":69769647},{"atb":[[1.04,122.71]],"id":45129701}],"con":true,"img":false}]}
{"op":"mcm","clk":"11541351755","pt":1719504853009,"mc":[{"id":"1.230178324","rc":[{"atl":[[11.5,0.02]],"id":63579394}],"con":true,"img":false}]}
{"op":"mcm","clk":"11541351783","pt":1719504853273,"mc":[{"id":"1.230178324","rc":[{"atb":[[3.9,0.27]],"id":63579394}],"con":true,"img":false}]}
{"op":"mcm","clk":"11541351823","pt":1719504853689,"mc":[{"id":"1.230178324","rc":[{"atb":[[1.25,20]],"id":63579394},{"atb":[[1.25,20]],"id":70902602},{"atb":[[1.25,20]],"id":69769647},{"atb":[[1.25,20]],"id":57055802},{"atb":[[1.25,20]],"id":40626946},{"atb":[[1.25,20]],"id":45129701}],"con":true,"img":false}]}
{"op":"mcm","clk":"11541351953","pt":1719504855292,"mc":[{"id":"1.230178324","rc":[{"atb":[[1.01,24.38]],"id":70902602}],"con":true,"img":false}]}
{"op":"mcm","clk":"11541351990","pt":1719504855708,"mc":[{"id":"1.230178324","rc":[{"atb":[[1.01,23.95]],"id":70902602},{"atl":[[11.5,1.07]],"id":63579394},{"atl":[[8.4,1.05]],"id":69769647}],"con":true,"img":false}]}
{"op":"mcm","clk":"11541352007","pt":1719504855916,"mc":[{"id":"1.230178324","rc":[{"atb":[[1.03,138.47]],"id":63579394},{"atb":[[2.82,0.86]],"id":69769647},{"atl":[[8.8,1.42],[8.4,3.05]],"id":69769647}],"con":true,"img":false}]}
{"op":"mcm","clk":"11541352016","pt":1719504856019,"mc":[{"id":"1.230178324","rc":[{"atb":[[1.01,24.67]],"id":70902602}],"con":true,"img":false}]}
{"op":"mcm","clk":"11541352036","pt":1719504856226,"mc":[{"id":"1.230178324","rc":[{"atb":[[1.01,24.38]],"id":70902602},{"atb":[[1.03,138.38]],"id":63579394}],"con":true,"img":false}]}
{"op":"mcm","clk":"11541352044","pt":1719504856277,"mc":[{"id":"1.230178324","rc":[{"atb":[[4.6,4.53]],"id":70902602}],"con":true,"img":false}]}
{"op":"mcm","clk":"11541352051","pt":1719504856382,"mc":[{"id":"1.230178324","rc":[{"atb":[[1.01,23.95]],"id":70902602},{"atb":[[1.03,137.94]],"id":63579394},{"atl":[[8.2,0.84]],"id":69769647}],"con":true,"img":false}]}
{"op":"mcm","clk":"11541352064","pt":1719504856485,"mc":[{"id":"1.230178324","rc":[{"atb":[[4.6,0.43]],"id":63579394},{"atl":[[9,0.28]],"id":69769647}],"con":true,"img":false}]}
{"op":"mcm","clk":"11541352072","pt":1719504856589,"mc":[{"id":"1.230178324","rc":[{"atl":[[8.4,3.84]],"id":69769647}],"con":true,"img":false}]}
{"op":"mcm","clk":"11541352096","pt":1719504856900,"mc":[{"id":"1.230178324","rc":[{"atb":[[1.01,23.67]],"id":70902602}],"con":true,"img":false}]}
{"op":"mcm","clk":"11541352107","pt":1719504857003,"mc":[{"id":"1.230178324","rc":[{"atb":[[4.5,0.28]],"id":70902602}],"con":true,"img":false}]}
{"op":"mcm","clk":"11541352132","pt":1719504857312,"mc":[{"id":"1.230178324","rc":[{"atl":[[8.4,3.58]],"id":69769647}],"con":true,"img":false}]}
{"op":"mcm","clk":"11541352149","pt":1719504857519,"mc":[{"id":"1.230178324","rc":[{"atl":[[8.4,4.78]],"id":69769647}],"con":true,"img":false}]}
{"op":"mcm","clk":"11541352201","pt":1719504858147,"mc":[{"id":"1.230178324","rc":[{"atb":[[1.01,24.38]],"id":70902602}],"con":true,"img":false}]}
{"op":"mcm","clk":"11541352250","pt":1719504858611,"mc":[{"id":"1.230178324","rc":[{"atb":[[1.01,24.67]],"id":70902602}],"con":true,"img":false}]}
{"op":"mcm","clk":"11541352294","pt":1719504859182,"mc":[{"id":"1.230178324","rc":[{"atb":[[1.01,23.95]],"id":70902602}],"con":true,"img":false}]}
{"op":"mcm","clk":"11541352303","pt":1719504859288,"mc":[{"id":"1.230178324","rc":[{"atb":[[4.4,0.28]],"id":70902602}],"con":true,"img":false}]}
{"op":"mcm","clk":"11541352341","pt":1719504859702,"mc":[{"id":"1.230178324","rc":[{"atb":[[1.01,23.67]],"id":70902602}],"con":true,"img":false}]}
{"op":"mcm","clk":"11541352350","pt":1719504859807,"mc":[{"id":"1.230178324","rc":[{"atb":[[4.2,0.28]],"id":70902602}],"con":true,"img":false}]}
{"op":"mcm","clk":"11541352467","pt":1719504861102,"mc":[{"id":"1.230178324","rc":[{"atl":[[16,4],[13.5,0]],"id":63579394},{"atl":[[8,1.05],[9.2,0],[8.4,2.78],[9.6,8]],"id":69769647},{"atl":[[17.5,0],[21,5]],"id":45129701}],"con":true,"img":false}]}
{"op":"mcm","clk":"11541352476","pt":1719504861203,"mc":[{"id":"1.230178324","rc":[{"atb":[[1.01,24.38]],"id":70902602}],"con":true,"img":false}]}
{"op":"mcm","clk":"11541352493","pt":1719504861412,"mc":[{"id":"1.230178324","rc":[{"atl":[[1000,0.84]],"id":63579394},{"atl":[[8,0]],"id":69769647}],"con":true,"img":false}]}
{"op":"mcm","clk":"11541352499","pt":1719504861515,"mc":[{"id":"1.230178324","rc":[{"atl":[[8.4,2.25]],"id":69769647}],"con":true,"img":false}]}
{"op":"mcm","clk":"11541352510","pt":1719504861620,"mc":[{"id":"1.230178324","rc":[{"atl":[[1000,0.52]],"id":69769647}],"con":true,"img":false}]}
{"op":"mcm","clk":"11541352522","pt":1719504861724,"mc":[{"id":"1.230178324","rc":[{"atl":[[12,1.84]],"id":63579394},{"atb":[[1.01,23.95]],"id":70902602},{"atl":[[10,0.84]],"id":40626946}],"con":true,"img":false}]}
{"op":"mcm","clk":"11541352538","pt":1719504861879,"mc":[{"id":"1.230178324","rc":[{"atb":[[2.8,7.18]],"id":69769647}],"con":true,"img":false}]}
{"op":"mcm","clk":"11541352543","pt":1719504861984,"mc":[{"id":"1.230178324","rc":[{"atl":[[1000,0.77]],"id":63579394},{"atl":[[8.2,1.9]],"id":69769647}],"con":true,"img":false}]}
{"op":"mcm","clk":"11541352565","pt":1719504862350,"mc":[{"id":"1.230178324","rc":[{"atb":[[1.01,23.67]],"id":70902602}],"con":true,"img":false}]}
{"op":"mcm","clk":"11541352573","pt":1719504862402,"mc":[{"id":"1.230178324","rc":[{"atb":[[4.3,0.28]],"id":70902602},{"atl":[[1000,0]],"id":63579394},{"atl":[[8.6,0.28]],"id":69769647}],"con":true,"img":false}]}
{"op":"mcm","clk":"11541352582","pt":1719504862504,"mc":[{"id":"1.230178324","rc":[{"atl":[[11,0.77]],"id":63579394},{"atb":[[2.78,8.38],[1.01,1.71]],"id":69769647}],"con":true,"img":false}]}
{"op":"mcm","clk":"11541352591","pt":1719504862609,"mc":[{"id":"1.230178324","rc":[{"atb":[[2.8,8.32]],"id":69769647}],"con":true,"img":false}]}
{"op":"mcm","clk":"11541352621","pt":1719504862922,"mc":[{"id":"1.230178324","rc":[{"atl":[[11,1.61]],"id":63579394}],"con":true,"img":false}]}
{"op":"mcm","clk":"11541352634","pt":1719504863025,"mc":[{"id":"1.230178324","rc":[{"atb":[[1.01,1.28]],"id":69769647},{"atl":[[34,0]],"id":40626946}],"con":true,"img":false}]}
{"op":"mcm","clk":"11541352684","pt":1719504863393,"mc":[{"id":"1.230178324","rc":[{"atb":[[1.01,1],[1.54,0]],"id":69769647}],"con":true,"img":false}]}
{"op":"mcm","clk":"11541352696","pt":1719504863499,"mc":[{"id":"1.230178324","rc":[{"atb":[[2.82,1.15]],"id":69769647}],"con":true,"img":false}]}
{"op":"mcm","clk":"11541352741","pt":1719504864015,"mc":[{"id":"1.230178324","rc":[{"atb":[[2.76,4.83]],"id":69769647}],"con":true,"img":false}]}
{"op":"mcm","clk":"11541352749","pt":1719504864120,"mc":[{"id":"1.230178324","rc":[{"atb":[[2.82,1.43]],"id":69769647}],"con":true,"img":false}]}
{"op":"mcm","clk":"11541352809","pt":1719504865000,"mc":[{"id":"1.230178324","rc":[{"atb":[[2.86,2.09]],"id":69769647}],"con":true,"img":false}]}
{"op":"mcm","clk":"11541352839","pt":1719504865414,"mc":[{"id":"1.230178324","rc":[{"atb":[[2.88,0.84],[2.82,1.15]],"id":69769647}],"con":true,"img":false}]}
{"op":"mcm","clk":"11541352846","pt":1719504865516,"mc":[{"id":"1.230178324","rc":[{"atb":[[2.8,7.47],[2.86,2.37]],"id":69769647}],"con":true,"img":false}]}
{"op":"mcm","clk":"11541352924","pt":1719504866447,"mc":[{"id":"1.230178324","rc":[{"atb":[[3.05,4.24]],"id":63579394},{"atb":[[2.78,5.22]],"id":69769647}],"con":true,"img":false}]}
{"op":"mcm","clk":"11541352927","pt":1719504866497,"mc":[{"id":"1.230178324","rc":[{"atb":[[1.01,24.38]],"id":40626946}],"con":true,"img":false}]}
{"op":"mcm","clk":"11541352936","pt":1719504866603,"mc":[{"id":"1.230178324","rc":[{"atb":[[2.84,4.35]],"id":69769647}],"con":true,"img":false}]}
{"op":"mcm","clk":"11541352944","pt":1719504866706,"mc":[{"id":"1.230178324","rc":[{"atb":[[2.84,5.15]],"id":63579394}],"con":true,"img":false}]}
{"op":"mcm","clk":"11541352971","pt":1719504867018,"mc":[{"id":"1.230178324","rc":[{"atb":[[1.01,23.95]],"id":40626946}],"con":true,"img":false}]}
{"op":"mcm","clk":"11541352981","pt":1719504867117,"mc":[{"id":"1.230178324","rc":[{"atb":[[2.8,5.86]],"id":69769647}],"con":true,"img":false}]}
{"op":"mcm","clk":"11541352989","pt":1719504867219,"mc":[{"id":"1.230178324","rc":[{"atb":[[2.88,2.45]],"id":69769647}],"con":true,"img":false}]}
{"op":"mcm","clk":"11541352996","pt":1719504867324,"mc":[{"id":"1.230178324","rc":[{"atb":[[2.8,4.72]],"id":69769647}],"con":true,"img":false}]}
{"op":"mcm","clk":"11541353003","pt":1719504867426,"mc":[{"id":"1.230178324","rc":[{"atb":[[2.84,5.49]],"id":69769647}],"con":true,"img":false}]}
{"op":"mcm","clk":"11541353011","pt":1719504867530,"mc":[{"id":"1.230178324","rc":[{"atb":[[1.01,24.38]],"id":40626946}],"con":true,"img":false}]}
{"op":"mcm","clk":"11541353023","pt":1719504867634,"mc":[{"id":"1.230178324","rc":[{"atb":[[4.7,1.28]],"id":40626946}],"con":true,"img":false}]}
{"op":"mcm","clk":"11541353031","pt":1719504867687,"mc":[{"id":"1.230178324","rc":[{"atb":[[1.01,25.1]],"id":40626946}],"con":true,"img":false}]}
{"op":"mcm","clk":"11541353055","pt":1719504867998,"mc":[{"id":"1.230178324","rc":[{"atb":[[1.01,25.38]],"id":40626946}],"con":true,"img":false}]}
{"op":"mcm","clk":"11541353077","pt":1719504868307,"mc":[{"id":"1.230178324","rc":[{"atb":[[1.01,24.95]],"id":40626946}],"con":true,"img":false}]}
{"op":"mcm","clk":"11541353102","pt":1719504868614,"mc":[{"id":"1.230178324","rc":[{"atb":[[1.01,24.52]],"id":40626946}],"con":true,"img":false}]}
{"op":"mcm","clk":"11541353111","pt":1719504868719,"mc":[{"id":"1.230178324","rc":[{"atb":[[1.01,24.24]],"id":40626946}],"con":true,"img":false}]}
{"op":"mcm","clk":"11541353124","pt":1719504868824,"mc":[{"id":"1.230178324","rc":[{"atb":[[1.01,23.95],[4.5,0.28]],"id":40626946}],"con":true,"img":false}]}
{"op":"mcm","clk":"11541353135","pt":1719504868926,"mc":[{"id":"1.230178324","rc":[{"atb":[[4.4,0.28]],"id":40626946}],"con":true,"img":false}]}
{"op":"mcm","clk":"11541353155","pt":1719504869134,"mc":[{"id":"1.230178324","rc":[{"atb":[[1.01,23.67]],"id":40626946},{"atl":[[10,2.44]],"id":40626946}],"con":true,"img":false}]}
{"op":"mcm","clk":"11541353167","pt":1719504869192,"mc":[{"id":"1.230178324","rc":[{"atb":[[4.2,0.28]],"id":40626946}],"con":true,"img":false}]}
{"op":"mcm","clk":"11541353180","pt":1719504869296,"mc":[{"id":"1.230178324","rc":[{"atl":[[32,0],[13,8]],"id":40626946}],"con":true,"img":false}]}
{"op":"mcm","clk":"11541353189","pt":1719504869395,"mc":[{"id":"1.230178324","rc":[{"atb":[[3.4,4.72]],"id":40626946}],"con":true,"img":false}]}
{"op":"mcm","clk":"11541353199","pt":1719504869496,"mc":[{"id":"1.230178324","rc":[{"atb":[[3.45,2.66]],"id":40626946}],"con":true,"img":false}]}
{"op":"mcm","clk":"11541353221","pt":1719504869810,"mc":[{"id":"1.230178324","rc":[{"atb":[[3.4,4.45]],"id":40626946}],"con":true,"img":false}]}
{"op":"mcm","clk":"11541353232","pt":1719504869910,"mc":[{"id":"1.230178324","rc":[{"atb":[[3.5,0.27]],"id":40626946},{"atl":[[9.8,0.84]],"id":40626946}],"con":true,"img":false}]}
{"op":"mcm","clk":"11541353238","pt":1719504870014,"mc":[{"id":"1.230178324","rc":[{"atb":[[2.88,6.71]],"id":69769647}],"con":true,"img":false}]}
{"op":"mcm","clk":"11541353264","pt":1719504870326,"mc":[{"id":"1.230178324","rc":[{"atb":[[2.84,4.35]],"id":69769647}],"con":true,"img":false}]}
{"op":"mcm","clk":"11541353271","pt":1719504870430,"mc":[{"id":"1.230178324","rc":[{"atb":[[2.88,7.85]],"id":69769647}],"con":true,"img":false}]}
{"op":"mcm","clk":"11541353293","pt":1719504870588,"mc":[{"id":"1.230178324","rc":[{"atb":[[1.01,24.38]],"id":40626946}],"con":true,"img":false}]}
{"op":"mcm","clk":"11541353328","pt":1719504870900,"mc":[{"id":"1.230178324","rc":[{"atb":[[3.4,3.33]],"id":40626946}],"con":true,"img":false}]}
{"op":"mcm","clk":"11541353350","pt":1719504871105,"mc":[{"id":"1.230178324","rc":[{"atl":[[8.4,1.2]],"id":69769647},{"atb":[[1.01,23.95]],"id":40626946}],"con":true,"img":false}]}
{"op":"mcm","clk":"11541353367","pt":1719504871316,"mc":[{"id":"1.230178324","rc":[{"atl":[[11.5,0.02]],"id":63579394}],"con":true,"img":false}]}
{"op":"mcm","clk":"11541353378","pt":1719504871419,"mc":[{"id":"1.230178324","rc":[{"atb":[[1.01,24.67]],"id":40626946}],"con":true,"img":false}]}
{"op":"mcm","clk":"11541353394","pt":1719504871625,"mc":[{"id":"1.230178324","rc":[{"atb":[[2.82,0.28]],"id":69769647},{"atb":[[1.01,24.38]],"id":40626946}],"con":true,"img":false}]}
{"op":"mcm","clk":"11541353404","pt":1719504871730,"mc":[{"id":"1.230178324","rc":[{"atb":[[4.3,0.28]],"id":40626946}],"con":true,"img":false}]}
{"op":"mcm","clk":"11541353423","pt":1719504871940,"mc":[{"id":"1.230178324","rc":[{"atb":[[4.6,0]],"id":63579394},{"atb":[[1.01,23.95]],"id":40626946}],"con":true,"img":false}]}
{"op":"mcm","clk":"11541353435","pt":1719504872002,"mc":[{"id":"1.230178324","rc":[{"atl":[[11,0.77]],"id":63579394}],"con":true,"img":false}]}
{"op":"mcm","clk":"11541353451","pt":1719504872206,"mc":[{"id":"1.230178324","rc":[{"atb":[[1.05,1.7],[1.04,132.03]],"id":40626946},{"atl":[[1000,5.33]],"id":40626946}],"con":true,"img":false}]}
{"op":"mcm","clk":"11541353468","pt":1719504872411,"mc":[{"id":"1.230178324","rc":[{"atb":[[1.01,23.67]],"id":40626946},{"atl":[[1000,0.29]],"id":40626946}],"con":true,"img":false}]}
{"op":"mcm","clk":"11541353477","pt":1719504872514,"mc":[{"id":"1.230178324","rc":[{"atb":[[4.6,0.28],[1.05,0.05],[1.04,130.38]],"id":40626946}],"con":true,"img":false}]}
{"op":"mcm","clk":"11541353493","pt":1719504872722,"mc":[{"id":"1.230178324","rc":[{"atb":[[3.45,1.66],[1.05,0],[1.04,130.33]],"id":40626946},{"atl":[[1000,0.22]],"id":40626946}],"con":true,"img":false}]}
{"op":"mcm","clk":"11541353505","pt":1719504872828,"mc":[{"id":"1.230178324","rc":[{"atb":[[4.4,1.28],[4.5,0.39]],"id":40626946},{"atl":[[9.8,0.91]],"id":40626946}],"con":true,"img":false}]}
{"op":"mcm","clk":"11541353525","pt":1719504873038,"mc":[{"id":"1.230178324","rc":[{"atl":[[1000,0.94]],"id":40626946}],"con":true,"img":false}]}
{"op":"mcm","clk":"11541353556","pt":1719504873408,"mc":[{"id":"1.230178324","rc":[{"atl":[[1000,1.22]],"id":40626946}],"con":true,"img":false}]}
{"op":"mcm","clk":"11541353615","pt":1719504874139,"mc":[{"id":"1.230178324","rc":[{"atl":[[9.8,1.19]],"id":40626946}],"con":true,"img":false}]}
{"op":"mcm","clk":"11541353644","pt":1719504874399,"mc":[{"id":"1.230178324","rc":[{"atl":[[9.6,0.88],[10,1.6]],"id":40626946}],"con":true,"img":false}]}
{"op":"mcm","clk":"11541353662","pt":1719504874606,"mc":[{"id":"1.230178324","rc":[{"atl":[[1000,0.51]],"id":40626946}],"con":true,"img":false}]}
{"op":"mcm","clk":"11541353672","pt":1719504874710,"mc":[{"id":"1.230178324","rc":[{"atl":[[10,1.88]],"id":40626946}],"con":true,"img":false}]}
{"op":"mcm","clk":"11541353709","pt":1719504875126,"mc":[{"id":"1.230178324","rc":[{"atl":[[1000,0.22]],"id":40626946}],"con":true,"img":false}]}
{"op":"mcm","clk":"11541353717","pt":1719504875228,"mc":[{"id":"1.230178324","rc":[{"atl":[[10,0.28],[10.5,1.28]],"id":40626946}],"con":true,"img":false}]}
{"op":"mcm","clk":"11541353857","pt":1719504876995,"mc":[{"id":"1.230178324","rc":[{"atl":[[1000,0.94]],"id":40626946}],"con":true,"img":false}]}
{"op":"mcm","clk":"11541353904","pt":1719504877510,"mc":[{"id":"1.230178324","rc":[{"atl":[[1000,0.51]],"id":40626946}],"con":true,"img":false}]}
{"op":"mcm","clk":"11541353945","pt":1719504878027,"mc":[{"id":"1.230178324","rc":[{"atl":[[1000,0.22]],"id":40626946}],"con":true,"img":false}]}
{"op":"mcm","clk":"11541353958","pt":1719504878129,"mc":[{"id":"1.230178324","rc":[{"atl":[[9.6,1.16]],"id":40626946}],"con":true,"img":false}]}
{"op":"mcm","clk":"11541354199","pt":1719504881151,"mc":[{"id":"1.230178324","rc":[{"atl":[[9.4,1.61]],"id":40626946}],"con":true,"img":false}]}
{"op":"mcm","clk":"11541354212","pt":1719504881312,"mc":[{"id":"1.230178324","rc":[{"atb":[[2.86,2.09]],"id":69769647}],"con":true,"img":false}]}
{"op":"mcm","clk":"11541354221","pt":1719504881417,"mc":[{"id":"1.230178324","rc":[{"atb":[[2.9,0.27]],"id":69769647}],"con":true,"img":false}]}
{"op":"mcm","clk":"11541354516","pt":1719504884634,"mc":[{"id":"1.230178324","rc":[{"atb":[[2.7,4.18]],"id":70902602},{"atb":[[2.34,8.84]],"id":69769647}],"con":true,"img":false}]}
{"op":"mcm","clk":"11541354529","pt":1719504884841,"mc":[{"id":"1.230178324","rc":[{"atb":[[1.54,11.7]],"id":69769647}],"con":true,"img":false}]}
{"op":"mcm","clk":"11541354790","pt":1719504887647,"mc":[{"id":"1.230178324","rc":[{"atl":[[8,1.05]],"id":69769647}],"con":true,"img":false}]}
{"op":"mcm","clk":"11541354799","pt":1719504887755,"mc":[{"id":"1.230178324","rc":[{"atl":[[11.5,1.07]],"id":63579394},{"atb":[[2.9,1.1]],"id":69769647}],"con":true,"img":false}]}
{"op":"mcm","clk":"11541354807","pt":1719504887855,"mc":[{"id":"1.230178324","rc":[{"atl":[[7.8,1.08]],"id":69769647}],"con":true,"img":false}]}
{"op":"mcm","clk":"11541354818","pt":1719504887908,"mc":[{"id":"1.230178324","rc":[{"atb":[[1.03,138.47]],"id":63579394},{"atl":[[8.2,0.84]],"id":69769647}],"con":true,"img":false}]}
{"op":"mcm","clk":"11541354837","pt":1719504888241,"mc":[{"id":"1.230178324","rc":[{"atb":[[1.03,138.38]],"id":63579394}],"con":true,"img":false}]}
{"op":"mcm","clk":"11541354854","pt":1719504888448,"mc":[{"id":"1.230178324","rc":[{"atb":[[1.03,137.94]],"id":63579394},{"atl":[[11,1.61]],"id":63579394}],"con":true,"img":false}]}
{"op":"mcm","clk":"11541354865","pt":1719504888549,"mc":[{"id":"1.230178324","rc":[{"atb":[[4.6,0.43]],"id":63579394}],"con":true,"img":false}]}
{"op":"mcm","clk":"11541354891","pt":1719504888816,"mc":[{"id":"1.230178324","rc":[{"atl":[[1000,1.24]],"id":69769647}],"con":true,"img":false}]}
{"op":"mcm","clk":"11541354931","pt":1719504889333,"mc":[{"id":"1.230178324","rc":[{"spn":7.8,"spf":"NaN","id":63579394},{"atl":[[1000,0.81]],"id":69769647},{"spn":2.88,"spf":1.0,"id":69769647},{"spn":7.05,"spf":"NaN","id":40626946},{"spn":8.2,"spf":"NaN","id":45129701}],"con":true,"img":false}]}
{"op":"mcm","clk":"11541354946","pt":1719504889542,"mc":[{"id":"1.230178324","rc":[{"atl":[[1000,1.53]],"id":69769647}],"con":true,"img":false}]}
{"op":"mcm","clk":"11541354972","pt":1719504889952,"mc":[{"id":"1.230178324","rc":[{"atl":[[1000,1.24]],"id":69769647}],"con":true,"img":false}]}
{"op":"mcm","clk":"11541354980","pt":1719504890057,"mc":[{"id":"1.230178324","rc":[{"atl":[[8.2,1.13],[1000,0.81]],"id":69769647}],"con":true,"img":false}]}
{"op":"mcm","clk":"11541354996","pt":1719504890214,"mc":[{"id":"1.230178324","rc":[{"atl":[[8,2.3],[1000,1.53]],"id":69769647}],"con":true,"img":false}]}
{"op":"mcm","clk":"11541355019","pt":1719504890629,"mc":[{"id":"1.230178324","rc":[{"atl":[[1000,1.24]],"id":69769647}],"con":true,"img":false}]}
{"op":"mcm","clk":"11541355024","pt":1719504890734,"mc":[{"id":"1.230178324","rc":[{"atl":[[8.2,1.41],[1000,0.81]],"id":69769647}],"con":true,"img":false}]}
{"op":"mcm","clk":"11541355041","pt":1719504890941,"mc":[{"id":"1.230178324","rc":[{"atl":[[1000,1.53]],"id":69769647}],"con":true,"img":false}]}
{"op":"mcm","clk":"11541355063","pt":1719504891251,"mc":[{"id":"1.230178324","rc":[{"atl":[[1000,1.24]],"id":69769647}],"con":true,"img":false}]}
{"op":"mcm","clk":"11541355070","pt":1719504891355,"mc":[{"id":"1.230178324","rc":[{"atl":[[8,2.58]],"id":69769647}],"con":true,"img":false}]}
{"op":"mcm","clk":"11541355086","pt":1719504891561,"mc":[{"id":"1.230178324","rc":[{"atl":[[1000,0.81]],"id":69769647}],"con":true,"img":false}]}
{"op":"mcm","clk":"11541355117","pt":1719504891929,"mc":[{"id":"1.230178324","rc":[{"atl":[[1000,0.52]],"id":69769647}],"con":true,"img":false}]}
{"op":"mcm","clk":"11541355128","pt":1719504892031,"mc":[{"id":"1.230178324","rc":[{"atl":[[7.8,1.36]],"id":69769647}],"con":true,"img":false}]}
{"op":"mcm","clk":"11541355590","pt":1719504897660,"mc":[{"id":"1.230178324","rc":[{"atb":[[4.5,13.86]],"id":63579394}],"con":true,"img":false}]}
{"op":"mcm","clk":"11541355651","pt":1719504898340,"mc":[{"id":"1.230178324","rc":[{"atb":[[3.85,0]],"id":63579394}],"con":true,"img":false}]}
{"op":"mcm","clk":"11541355658","pt":1719504898442,"mc":[{"id":"1.230178324","rc":[{"atb":[[4.6,3.01]],"id":63579394}],"con":true,"img":false}]}
{"op":"mcm","clk":"11541355686","pt":1719504898754,"mc":[{"id":"1.230178324","rc":[{"atb":[[3.9,0]],"id":63579394}],"con":true,"img":false}]}
{"op":"mcm","clk":"11541355694","pt":1719504898858,"mc":[{"id":"1.230178324","rc":[{"atb":[[4.7,0.27]],"id":63579394}],"con":true,"img":false}]}
{"op":"mcm","clk":"11541355702","pt":1719504898964,"mc":[{"id":"1.230178324","rc":[{"atb":[[4.6,1.28]],"id":63579394}],"con":true,"img":false}]}
{"op":"mcm","clk":"11541355739","pt":1719504899447,"mc":[{"id":"1.230178324","rc":[{"atb":[[4.6,3.01]],"id":63579394},{"atl":[[9,0]],"id":69769647}],"con":true,"img":false}]}
{"op":"mcm","clk":"11541355792","pt":1719504900165,"mc":[{"id":"1.230178324","rc":[{"atb":[[4.7,6.53]],"id":63579394},{"atb":[[4.7,8.66]],"id":40626946}],"con":true,"img":false}]}
{"op":"mcm","clk":"11541355815","pt":1719504900429,"mc":[{"id":"1.230178324","rc":[{"atb":[[4.7,7.75]],"id":63579394},{"atl":[[8.8,1.14]],"id":69769647}],"con":true,"img":false}]}
{"op":"mcm","clk":"11541355846","pt":1719504900755,"mc":[{"id":"1.230178324","rc":[{"atb":[[4.6,1.28]],"id":63579394},{"atb":[[3.45,0]],"id":40626946}],"con":true,"img":false}]}
{"op":"mcm","clk":"11541355856","pt":1719504900858,"mc":[{"id":"1.230178324","rc":[{"atb":[[4.8,1.73]],"id":63579394},{"atb":[[4.8,1.66]],"id":40626946}],"con":true,"img":false}]}
{"op":"mcm","clk":"11541355875","pt":1719504901068,"mc":[{"id":"1.230178324","rc":[{"atb":[[4.8,8.42]],"id":63579394},{"atb":[[4.8,7.98]],"id":40626946}],"con":true,"img":false}]}
{"op":"mcm","clk":"11541355883","pt":1719504901123,"mc":[{"id":"1.230178324","rc":[{"atb":[[4.4,0.28]],"id":40626946}],"con":true,"img":false}]}
{"op":"mcm","clk":"11541355892","pt":1719504901228,"mc":[{"id":"1.230178324","rc":[{"atl":[[8.6,0]],"id":69769647}],"con":true,"img":false}]}
{"op":"mcm","clk":"11541355905","pt":1719504901336,"mc":[{"id":"1.230178324","rc":[{"atb":[[4.9,1]],"id":40626946}],"con":true,"img":false}]}
{"op":"mcm","clk":"11541355916","pt":1719504901442,"mc":[{"id":"1.230178324","rc":[{"atb":[[4.6,0.43]],"id":63579394}],"con":true,"img":false}]}
{"op":"mcm","clk":"11541355938","pt":1719504901648,"mc":[{"id":"1.230178324","rc":[{"atb":[[4.7,6.26]],"id":63579394},{"atb":[[3.5,0]],"id":40626946}],"con":true,"img":false}]}
{"op":"mcm","clk":"11541355950","pt":1719504901753,"mc":[{"id":"1.230178324","rc":[{"atb":[[4.8,9.65],[4.9,0.27]],"id":63579394},{"atb":[[4.9,1.27]],"id":40626946}],"con":true,"img":false}]}
{"op":"mcm","clk":"11541355977","pt":1719504902072,"mc":[{"id":"1.230178324","rc":[{"atl":[[1000,1.24]],"id":69769647}],"con":true,"img":false}]}
{"op":"mcm","clk":"11541356006","pt":1719504902330,"mc":[{"id":"1.230178324","rc":[{"atb":[[4.5,1]],"id":63579394}],"con":true,"img":false}]}
{"op":"mcm","clk":"11541356015","pt":1719504902433,"mc":[{"id":"1.230178324","rc":[{"atb":[[4.8,11.76]],"id":63579394}],"con":true,"img":false}]}
{"op":"mcm","clk":"11541356025","pt":1719504902538,"mc":[{"id":"1.230178324","rc":[{"atl":[[1000,0.81]],"id":69769647},{"atb":[[4.9,7.39]],"id":40626946}],"con":true,"img":false}]}
{"op":"mcm","clk":"11541356074","pt":1719504903057,"mc":[{"id":"1.230178324","rc":[{"atl":[[1000,0.52]],"id":69769647}],"con":true,"img":false}]}
{"op":"mcm","clk":"11541356085","pt":1719504903165,"mc":[{"id":"1.230178324","rc":[{"atb":[[2.9,0.27]],"id":69769647},{"atl":[[7.6,0.28]],"id":69769647},{"atb":[[4.8,6.32]],"id":40626946}],"con":true,"img":false}]}
{"op":"mcm","clk":"11541356098","pt":1719504903267,"mc":[{"id":"1.230178324","rc":[{"atl":[[11.5,0.02]],"id":63579394},{"atb":[[5,1.66]],"id":40626946}],"con":true,"img":false}]}
{"op":"mcm","clk":"11541356127","pt":1719504903475,"mc":[{"id":"1.230178324","rc":[{"atl":[[8,1.53]],"id":69769647},{"atb":[[5,7.8]],"id":40626946}],"con":true,"img":false}]}
{"op":"mcm","clk":"11541356151","pt":1719504903636,"mc":[{"id":"1.230178324","rc":[{"atl":[[8.2,0.84]],"id":69769647},{"atb":[[4.9,6.39]],"id":40626946}],"con":true,"img":false}]}
{"op":"mcm","clk":"11541356176","pt":1719504903849,"mc":[{"id":"1.230178324","rc":[{"atb":[[4.6,0]],"id":63579394},{"atb":[[5.1,1]],"id":40626946}],"con":true,"img":false}]}
{"op":"mcm","clk":"11541356187","pt":1719504903950,"mc":[{"id":"1.230178324","rc":[{"atl":[[11,0.77]],"id":63579394},{"atb":[[2.9,3.44]],"id":69769647}],"con":true,"img":false}]}
{"op":"mcm","clk":"11541356195","pt":1719504904053,"mc":[{"id":"1.230178324","rc":[{"atb":[[4.9,1.68]],"id":63579394}],"con":true,"img":false}]}
{"op":"mcm","clk":"11541356204","pt":1719504904158,"mc":[{"id":"1.230178324","rc":[{"atb":[[4.9,7.71],[2.16,5.45]],"id":63579394},{"atb":[[2.92,3.7]],"id":69769647},{"atb":[[2.16,8.83]],"id":40626946}],"con":true,"img":false}]}
{"op":"mcm","clk":"11541356226","pt":1719504904365,"mc":[{"id":"1.230178324","rc":[{"atb":[[4.8,10.02]],"id":63579394},{"atb":[[2.88,6.24]],"id":69769647}],"con":true,"img":false}]}
{"op":"mcm","clk":"11541356234","pt":1719504904469,"mc":[{"id":"1.230178324","rc":[{"atb":[[4.9,9.44]],"id":63579394},{"atb":[[2.92,6.16]],"id":69769647}],"con":true,"img":false}]}
{"op":"mcm","clk":"11541356244","pt":1719504904574,"mc":[{"id":"1.230178324","rc":[{"atb":[[2.9,3.16]],"id":69769647},{"atb":[[4.9,6.12],[4.7,7.66]],"id":40626946}],"con":true,"img":false}]}
{"op":"mcm","clk":"11541356255","pt":1719504904638,"mc":[{"id":"1.230178324","rc":[{"atb":[[4.8,8.8]],"id":63579394},{"atb":[[2.94,0.27],[2.88,5.1]],"id":69769647},{"atb":[[5.1,1.27]],"id":40626946}],"con":true,"img":false}]}
{"op":"mcm","clk":"11541356265","pt":1719504904733,"mc":[{"id":"1.230178324","rc":[{"atb":[[4.9,10.67]],"id":63579394},{"atb":[[2.92,7.3]],"id":69769647},{"atl":[[1000,1.24]],"id":69769647},{"atb":[[5,9.8]],"id":40626946}],"con":true,"img":false}]}
{"op":"mcm","clk":"11541356290","pt":1719504905043,"mc":[{"id":"1.230178324","rc":[{"atb":[[2.88,4.26]],"id":69769647},{"atb":[[4.7,0.28]],"id":40626946}],"con":true,"img":false}]}
{"op":"mcm","clk":"11541356299","pt":1719504905152,"mc":[{"id":"1.230178324","rc":[{"atl":[[1000,0.81]],"id":69769647},{"atb":[[5.1,7.79]],"id":40626946}],"con":true,"img":false}]}
{"op":"mcm","clk":"11541356317","pt":1719504905358,"mc":[{"id":"1.230178324","rc":[{"atb":[[5,5.07]],"id":63579394}],"con":true,"img":false}]}
{"op":"mcm","clk":"11541356328","pt":1719504905462,"mc":[{"id":"1.230178324","rc":[{"atb":[[5,5.92]],"id":63579394},{"atb":[[2.98,2.09],[2.86,0]],"id":69769647},{"atb":[[5,8.14]],"id":40626946}],"con":true,"img":false}]}
{"op":"mcm","clk":"11541356337","pt":1719504905565,"mc":[{"id":"1.230178324","rc":[{"atb":[[5.2,1.66]],"id":40626946}],"con":true,"img":false}]}
{"op":"mcm","clk":"11541356347","pt":1719504905669,"mc":[{"id":"1.230178324","rc":[{"atb":[[2.94,4.39]],"id":69769647},{"atl":[[1000,0.52]],"id":69769647}],"con":true,"img":false}]}
{"op":"mcm","clk":"11541356364","pt":1719504905771,"mc":[{"id":"1.230178324","rc":[{"atl":[[7.4,0.28]],"id":69769647}],"con":true,"img":false}]}
{"op":"mcm","clk":"11541356372","pt":1719504905878,"mc":[{"id":"1.230178324","rc":[{"atb":[[4.9,9.44]],"id":63579394},{"atb":[[2.92,6.16]],"id":69769647}],"con":true,"img":false}]}
{"op":"mcm","clk":"11541356380","pt":1719504905946,"mc":[{"id":"1.230178324","rc":[{"atb":[[4.9,9.17],[5,7.15]],"id":63579394},{"atb":[[2.94,5.26],[2.92,5.31]],"id":69769647},{"atb":[[4.8,0],[5.1,7.52]],"id":40626946}],"con":true,"img":false}]}
{"op":"mcm","clk":"11541356385","pt":1719504906054,"mc":[{"id":"1.230178324","rc":[{"atb":[[5.1,0.27]],"id":63579394},{"atb":[[2.98,2.37]],"id":69769647},{"atb":[[5.2,1.93]],"id":40626946}],"con":true,"img":false}]}
{"op":"mcm","clk":"11541356392","pt":1719504906147,"mc":[{"id":"1.230178324","rc":[{"atb":[[4.9,7.44]],"id":63579394},{"atb":[[2.92,3.7]],"id":69769647}],"con":true,"img":false}]}
{"op":"mcm","clk":"11541356401","pt":1719504906255,"mc":[{"id":"1.230178324","rc":[{"atb":[[5.1,2]],"id":63579394},{"atb":[[2.98,3.98]],"id":69769647}],"con":true,"img":false}]}
{"op":"mcm","clk":"11541356410","pt":1719504906358,"mc":[{"id":"1.230178324","rc":[{"atb":[[5,13.55]],"id":63579394},{"atb":[[5.2,7.76]],"id":40626946}],"con":true,"img":false}]}
{"op":"mcm","clk":"11541356419","pt":1719504906465,"mc":[{"id":"1.230178324","rc":[{"atl":[[8.2,0],[7.6,1.13]],"id":69769647}],"con":true,"img":false}]}
{"op":"mcm","clk":"11541356427","pt":1719504906573,"mc":[{"id":"1.230178324","rc":[{"atb":[[2.94,4.12]],"id":69769647}],"con":true,"img":false}]}
{"op":"mcm","clk":"11541356439","pt":1719504906677,"mc":[{"id":"1.230178324","rc":[{"atb":[[2.88,5.4]],"id":69769647}],"con":true,"img":false}]}
{"op":"mcm","clk":"11541356458","pt":1719504906833,"mc":[{"id":"1.230178324","rc":[{"atb":[[5,8.47],[4.7,0]],"id":63579394}],"con":true,"img":false}]}
{"op":"mcm","clk":"11541356476","pt":1719504907042,"mc":[{"id":"1.230178324","rc":[{"atb":[[5.2,4.88]],"id":63579394},{"atb":[[5.3,4.79]],"id":40626946}],"con":true,"img":false}]}
{"op":"mcm","clk":"11541356504","pt":1719504907354,"mc":[{"id":"1.230178324","rc":[{"atb":[[5.1,5.72]],"id":63579394},{"atb":[[5.2,6.1]],"id":40626946}],"con":true,"img":false}]}
{"op":"mcm","clk":"11541356514","pt":1719504907456,"mc":[{"id":"1.230178324","rc":[{"atb":[[5.3,1.73],[5.1,5.45]],"id":63579394},{"atb":[[1.01,1.71]],"id":69769647},{"atb":[[5.4,1.66],[5.2,5.83]],"id":40626946}],"con":true,"img":false}]}
{"op":"mcm","clk":"11541356522","pt":1719504907559,"mc":[{"id":"1.230178324","rc":[{"atb":[[5.3,2]],"id":63579394},{"atb":[[1.02,15.53]],"id":69769647},{"atl":[[1000,2.23]],"id":69769647},{"atb":[[5.4,1.93]],"id":40626946}],"con":true,"img":false}]}
{"op":"mcm","clk":"11541356529","pt":1719504907662,"mc":[{"id":"1.230178324","rc":[{"atb":[[5.2,0]],"id":63579394},{"atb":[[4.9,0],[5.3,0],[5.1,6.52]],"id":40626946}],"con":true,"img":false}]}
{"op":"mcm","clk":"11541356541","pt":1719504907766,"mc":[{"id":"1.230178324","rc":[{"atl":[[1000,0.57]],"id":69769647},{"atb":[[5.3,5.63]],"id":40626946}],"con":true,"img":false}]}
{"op":"mcm","clk":"11541356552","pt":1719504907870,"mc":[{"id":"1.230178324","rc":[{"atb":[[1.02,13.97]],"id":69769647},{"atb":[[5.4,2.93]],"id":40626946}],"con":true,"img":false}]}
{"op":"mcm","clk":"11541356561","pt":1719504907973,"mc":[{"id":"1.230178324","rc":[{"atb":[[5.3,0.27],[5,7.62]],"id":63579394},{"atb":[[1.01,1.28]],"id":69769647},{"atl":[[1000,0.52]],"id":69769647},{"atb":[[5.4,1.27]],"id":40626946}],"con":true,"img":false}]}
{"op":"mcm","clk":"11541356571","pt":1719504908079,"mc":[{"id":"1.230178324","rc":[{"atb":[[5.2,1.73]],"id":63579394},{"atb":[[1.02,13.83],[1.01,2]],"id":69769647},{"atl":[[7.6,1.17]],"id":69769647},{"atb":[[5.3,7.29]],"id":40626946}],"con":true,"img":false}]}
{"op":"mcm","clk":"11541356584","pt":1719504908182,"mc":[{"id":"1.230178324","rc":[{"atb":[[3,0.14]],"id":69769647}],"con":true,"img":false}]}
{"op":"mcm","clk":"11541356593","pt":1719504908235,"mc":[{"id":"1.230178324","rc":[{"atb":[[5.3,5.06]],"id":63579394}],"con":true,"img":false}]}
{"op":"mcm","clk":"11541356606","pt":1719504908340,"mc":[{"id":"1.230178324","rc":[{"atb":[[4.8,2.11]],"id":63579394},{"atb":[[1.01,1.71]],"id":69769647},{"atb":[[5,2]],"id":40626946}],"con":true,"img":false}]}
{"op":"mcm","clk":"11541356611","pt":1719504908441,"mc":[{"id":"1.230178324","rc":[{"atb":[[1.01,1.28],[2.86,0.28]],"id":69769647}],"con":true,"img":false}]}
{"op":"mcm","clk":"11541356623","pt":1719504908547,"mc":[{"id":"1.230178324","rc":[{"atb":[[5.3,11.56],[5.2,0]],"id":63579394},{"atb":[[5.4,6.69]],"id":40626946}],"con":true,"img":false}]}
{"op":"mcm","clk":"11541356630","pt":1719504908654,"mc":[{"id":"1.230178324","rc":[{"atb":[[5.4,1.73]],"id":63579394}],"con":true,"img":false}]}
{"op":"mcm","clk":"11541356652","pt":1719504908859,"mc":[{"id":"1.230178324","rc":[{"atb":[[5.3,6.5]],"id":63579394}],"con":true,"img":false}]}
{"op":"mcm","clk":"11541356663","pt":1719504908966,"mc":[{"id":"1.230178324","rc":[{"atb":[[5.4,2]],"id":63579394},{"atb":[[1.01,1]],"id":69769647},{"atb":[[5.5,4.61]],"id":40626946}],"con":true,"img":false}]}
{"op":"mcm","clk":"11541356674","pt":1719504909068,"mc":[{"id":"1.230178324","rc":[{"atb":[[2.84,4.63]],"id":69769647},{"atb":[[5.3,5.63]],"id":40626946}],"con":true,"img":false}]}
{"op":"mcm","clk":"11541356686","pt":1719504909171,"mc":[{"id":"1.230178324","rc":[{"atb":[[5.5,6.27]],"id":40626946}],"con":true,"img":false}]}
{"op":"mcm","clk":"11541356723","pt":1719504909582,"mc":[{"id":"1.230178324","rc":[{"atb":[[4.5,0],[5.5,4.61]],"id":63579394}],"con":true,"img":false}]}
{"op":"mcm","clk":"11541356756","pt":1719504909952,"mc":[{"id":"1.230178324","rc":[{"atb":[[2.28,9.26]],"id":40626946}],"con":true,"img":false}]}
{"op":"mcm","clk":"11541356776","pt":1719504910165,"mc":[{"id":"1.230178324","rc":[{"atb":[[4.9,1.41]],"id":63579394},{"atb":[[5.1,0]],"id":40626946}],"con":true,"img":false}]}
{"op":"mcm","clk":"11541356786","pt":1719504910267,"mc":[{"id":"1.230178324","rc":[{"atb":[[5.4,0.27]],"id":63579394},{"atb":[[1.01,1.71]],"id":69769647},{"atb":[[5.5,8.05]],"id":40626946}],"con":true,"img":false}]}
{"op":"mcm","clk":"11541356796","pt":1719504910369,"mc":[{"id":"1.230178324","rc":[{"atb":[[5.5,9.58],[5.6,1.73]],"id":63579394},{"atb":[[5.5,13.36]],"id":40626946}],"con":true,"img":false}]}
{"op":"mcm","clk":"11541356805","pt":1719504910472,"mc":[{"id":"1.230178324","rc":[{"atb":[[5.4,5.69]],"id":40626946}],"con":true,"img":false}]}
{"op":"mcm","clk":"11541356825","pt":1719504910676,"mc":[{"id":"1.230178324","rc":[{"atb":[[5.5,4.97]],"id":63579394},{"atb":[[5.6,1]],"id":40626946}],"con":true,"img":false}]}
{"op":"mcm","clk":"11541356833","pt":1719504910779,"mc":[{"id":"1.230178324","rc":[{"atb":[[1.01,2]],"id":69769647}],"con":true,"img":false}]}
{"op":"mcm","clk":"11541356851","pt":1719504910986,"mc":[{"id":"1.230178324","rc":[{"atb":[[5,1.22]],"id":63579394}],"con":true,"img":false}]}
{"op":"mcm","clk":"11541356872","pt":1719504911145,"mc":[{"id":"1.230178324","rc":[{"atb":[[5.6,7.01]],"id":63579394}],"con":true,"img":false}]}
{"op":"mcm","clk":"11541356881","pt":1719504911249,"mc":[{"id":"1.230178324","rc":[{"atb":[[5.5,8.75]],"id":40626946}],"con":true,"img":false}]}
{"op":"mcm","clk":"11541356892","pt":1719504911352,"mc":[{"id":"1.230178324","rc":[{"atb":[[2.88,5.68]],"id":69769647}],"con":true,"img":false}]}
{"op":"mcm","clk":"11541356902","pt":1719504911458,"mc":[{"id":"1.230178324","rc":[{"atb":[[5.7,4.45]],"id":63579394}],"con":true,"img":false}]}
{"op":"mcm","clk":"11541356929","pt":1719504911770,"mc":[{"id":"1.230178324","rc":[{"atb":[[1.01,2.28]],"id":69769647}],"con":true,"img":false}]}
{"op":"mcm","clk":"11541356936","pt":1719504911884,"mc":[{"id":"1.230178324","rc":[{"atb":[[3,0.98],[1.01,2]],"id":69769647}],"con":true,"img":false}]}
{"op":"mcm","clk":"11541356948","pt":1719504911977,"mc":[{"id":"1.230178324","rc":[{"atb":[[5.1,0]],"id":63579394},{"atb":[[2.9,3.44]],"id":69769647}],"con":true,"img":false}]}
{"op":"mcm","clk":"11541356955","pt":1719504912079,"mc":[{"id":"1.230178324","rc":[{"atb":[[5.7,10.12],[5.6,5.28]],"id":63579394}],"con":true,"img":false}]}
{"op":"mcm","clk":"11541356966","pt":1719504912183,"mc":[{"id":"1.230178324","rc":[{"atb":[[5.8,1.73]],"id":63579394}],"con":true,"img":false}]}
{"op":"mcm","clk":"11541356972","pt":1719504912285,"mc":[{"id":"1.230178324","rc":[{"atb":[[1.01,1.28]],"id":69769647}],"con":true,"img":false}]}
{"op":"mcm","clk":"11541356984","pt":1719504912340,"mc":[{"id":"1.230178324","rc":[{"atb":[[2.92,3.99]],"id":69769647}],"con":true,"img":false}]}
{"op":"mcm","clk":"11541356994","pt":1719504912446,"mc":[{"id":"1.230178324","rc":[{"atb":[[2.88,4.54],[1.01,2]],"id":69769647}],"con":true,"img":false}]}
{"op":"mcm","clk":"11541357002","pt":1719504912547,"mc":[{"id":"1.230178324","rc":[{"atb":[[5.7,5.67]],"id":63579394},{"atb":[[2.98,5.12]],"id":69769647}],"con":true,"img":false}]}
{"op":"mcm","clk":"11541357013","pt":1719504912659,"mc":[{"id":"1.230178324","rc":[{"atb":[[5.8,0]],"id":63579394},{"trd":[[5.8,3.46]],"ltp":5.8,"tv":3.46,"id":63579394},{"atb":[[1.01,1.71]],"id":69769647}],"con":true,"img":false}]}
{"op":"mcm","clk":"11541357023","pt":1719504912752,"mc":[{"id":"1.230178324","rc":[{"atb":[[5.9,4.29]],"id":63579394},{"atb":[[2.94,4.4]],"id":69769647}],"con":true,"img":false}]}
{"op":"mcm","clk":"11541357042","pt":1719504912969,"mc":[{"id":"1.230178324","rc":[{"atb":[[1.01,2]],"id":69769647}],"con":true,"img":false}]}
{"op":"mcm","clk":"11541357082","pt":1719504913578,"mc":[{"id":"1.230178324","rc":[{"atb":[[1.01,1.28]],"id":69769647}],"con":true,"img":false}]}
{"op":"mcm","clk":"11541357088","pt":1719504913686,"mc":[{"id":"1.230178324","rc":[{"atb":[[2.96,0.28]],"id":69769647}],"con":true,"img":false}]}
{"op":"mcm","clk":"11541357119","pt":1719504914049,"mc":[{"id":"1.230178324","rc":[{"atb":[[1.01,1]],"id":69769647}],"con":true,"img":false}]}
{"op":"mcm","clk":"11541357126","pt":1719504914156,"mc":[{"id":"1.230178324","rc":[{"atb":[[2.98,5.41]],"id":69769647}],"con":true,"img":false}]}
{"op":"mcm","clk":"11541357207","pt":1719504915248,"mc":[{"id":"1.230178324","rc":[{"atb":[[1.01,1.71]],"id":69769647}],"con":true,"img":false}]}
{"op":"mcm","clk":"11541357248","pt":1719504915770,"mc":[{"id":"1.230178324","rc":[{"atb":[[1.01,1.28]],"id":69769647}],"con":true,"img":false}]}
{"op":"mcm","clk":"11541357281","pt":1719504916186,"mc":[{"id":"1.230178324","rc":[{"atb":[[1.01,1]],"id":69769647}],"con":true,"img":false}]}
{"op":"mcm","clk":"11541357291","pt":1719504916285,"mc":[{"id":"1.230178324","rc":[{"atb":[[3,1.27]],"id":69769647}],"con":true,"img":false}]}
{"op":"mcm","clk":"11541357390","pt":1719504917378,"mc":[{"id":"1.230178324","rc":[{"atl":[[7.4,1.33]],"id":69769647}],"con":true,"img":false}]}
{"op":"mcm","clk":"11541357397","pt":1719504917479,"mc":[{"id":"1.230178324","rc":[{"atl":[[11.5,1.07]],"id":63579394},{"atb":[[3.05,0.76]],"id":69769647}],"con":true,"img":false}]}
{"op":"mcm","clk":"11541357408","pt":1719504917580,"mc":[{"id":"1.230178324","rc":[{"atb":[[5.7,7.37]],"id":63579394},{"atb":[[3,5.27]],"id":69769647}],"con":true,"img":false}]}
