{"op":"mcm","clk":"11536380665","pt":1719425245609,"mc":[{"id":"1.230178325","marketDefinition":{"bspMarket":true,"turnInPlayEnabled":false,"persistenceEnabled":false,"marketBaseRate":5.0,"eventId":"33376062","eventTypeId":"4339","numberOfWinners":2,"bettingType":"ODDS","marketType":"PLACE","marketTime":"2024-06-27T16:24:00.000Z","suspendTime":"2024-06-27T16:24:00.000Z","bspReconciled":false,"complete":true,"inPlay":false,"crossMatching":false,"runnersVoidable":false,"numberOfActiveRunners":6,"betDelay":0,"status":"OPEN","runners":[{"status":"ACTIVE","sortPriority":1,"id":69769647,"name":"1. Teebay"},{"status":"ACTIVE","sortPriority":2,"id":63579394,"name":"2. Apple Jam"},{"status":"ACTIVE","sortPriority":3,"id":40626946,"name":"3. Jaxleg Swift"},{"status":"ACTIVE","sortPriority":4,"id":45129701,"name":"4. Darkies Dream"},{"status":"ACTIVE","sortPriority":5,"id":70902602,"name":"5. Jamaica Joel"},{"status":"ACTIVE","sortPriority":6,"id":57055802,"name":"6. Songful Bird"}],"regulators":["MR_INT"],"venue":"Kinsley","countryCode":"GB","discountAllowed":false,"timezone":"Europe/London","openDate":"2024-06-27T13:36:00.000Z","version":5994643799,"name":"To Be Placed","eventName":"Kinsley 27th Jun"},"rc":[],"con":true,"img":false}]}
{"op":"mcm","clk":"11536381029","pt":1719425248538,"mc":[{"id":"1.230178325","marketDefinition":{"bspMarket":true,"turnInPlayEnabled":false,"persistenceEnabled":false,"marketBaseRate":5.0,"eventId":"33376062","eventTypeId":"4339","numberOfWinners":2,"bettingType":"ODDS","marketType":"PLACE","marketTime":"2024-06-27T16:24:00.000Z","suspendTime":"2024-06-27T16:24:00.000Z","bspReconciled":false,"complete":true,"inPlay":false,"crossMatching":false,"runnersVoidable":false,"numberOfActiveRunners":6,"betDelay":0,"status":"OPEN","runners":[{"status":"ACTIVE","sortPriority":1,"id":69769647,"name":"1. Teebay"},{"status":"ACTIVE","sortPriority":2,"id":63579394,"name":"2. Apple Jam"},{"status":"ACTIVE","sortPriority":3,"id":40626946,"name":"3. Jaxleg Swift"},{"status":"ACTIVE","sortPriority":4,"id":45129701,"name":"4. Darkies Dream"},{"status":"ACTIVE","sortPriority":5,"id":70902602,"name":"5. Jamaica Joel"},{"status":"ACTIVE","sortPriority":6,"id":57055802,"name":"6. Songful Bird"}],"regulators":["MR_INT"],"venue":"Kinsley","countryCode":"GB","discountAllowed":true,"timezone":"Europe/London","openDate":"2024-06-27T13:36:00.000Z","version":5994643799,"name":"To Be Placed","eventName":"Kinsley 27th Jun"},"rc":[],"con":true,"img":false}]}
{"op":"mcm","clk":"11536837117","pt":1719431854920,"mc":[{"id":"1.230178325","rc":[{"atb":[[1.03,7.48]],"id":70902602},{"atl":[[1000,0.84]],"id":70902602},{"spn":500.51,"spf":"NaN","id":70902602},{"atb":[[1.03,7.48]],"id":63579394},{"atl":[[1000,0.84]],"id":63579394},{"spn":500.51,"spf":"NaN","id":63579394},{"atb":[[1.02,11.22]],"id":69769647},{"atl":[[990,0.84]],"id":69769647},{"spn":495.51,"spf":"NaN","id":69769647},{"atb":[[1.03,7.48]],"id":57055802},{"atl":[[990,0.84]],"id":57055802},{"spn":495.51,"spf":"NaN","id":57055802},{"atb":[[1.03,7.48]],"id":40626946},{"atl":[[1000,0.84]],"id":40626946},{"spn":500.51,"spf":"NaN","id":40626946},{"atb":[[1.02,11.22]],"id":45129701},{"atl":[[990,0.84]],"id":45129701},{"spn":495.51,"spf":"NaN","id":45129701}],"con":true,"img":false}]}
{"op":"mcm","clk":"11537083873","pt":1719435432999,"mc":[{"id":"1.230178325","rc":[{"atl":[[1000,0.32]],"id":70902602},{"atl":[[1000,0.32]],"id":63579394},{"atl":[[990,0.32]],"id":69769647},{"atl":[[990,0.32]],"id":57055802},{"atl":[[1000,0.32]],"id":40626946},{"atl":[[990,0.32]],"id":45129701}],"con":true,"img":false}]}
{"op":"mcm","clk":"11537232273","pt":1719437882523,"mc":[{"id":"1.230178325","marketDefinition":{"bspMarket":true,"turnInPlayEnabled":false,"persistenceEnabled":false,"marketBaseRate":5.0,"eventId":"33376062","eventTypeId":"4339","numberOfWinners":2,"bettingType":"ODDS","marketType":"PLACE","marketTime":"2024-06-27T16:24:00.000Z","suspendTime":"2024-06-27T16:24:00.000Z","bspReconciled":false,"complete":true,"inPlay":false,"crossMatching":false,"runnersVoidable":false,"numberOfActiveRunners":6,"betDelay":0,"status":"OPEN","runners":[{"status":"ACTIVE","sortPriority":1,"id":69769647,"name":"1. Teebay"},{"status":"ACTIVE","sortPriority":2,"id":63579394,"name":"2. Apple Jam"},{"status":"ACTIVE","sortPriority":3,"id":40626946,"name":"3. Jaxleg Swift"},{"status":"ACTIVE","sortPriority":4,"id":45129701,"name":"4. Darkies Dream"},{"status":"ACTIVE","sortPriority":5,"id":70902602,"name":"5. Jamaica Joel"},{"status":"ACTIVE","sortPriority":6,"id":57055802,"name":"6. Songful Bird"}],"regulators":["MR_INT"],"venue":"Kinsley","countryCode":"GB","discountAllowed":true,"timezone":"Europe/London","openDate":"2024-06-27T13:36:00.000Z","version":5994643799,"name":"To Be Placed","eventName":"Kinsley 27th Jun"},"rc":[{"atb":[[1.03,7.48]],"id":63579394},{"atl":[[1000,0.33]],"id":63579394},{"spn":500.51,"spf":"NaN","id":63579394},{"atb":[[1.03,7.48]],"id":70902602},{"atl":[[1000,0.33]],"id":70902602},{"spn":500.51,"spf":"NaN","id":70902602},{"atb":[[1.02,11.22]],"id":69769647},{"atl":[[990,0.33]],"id":69769647},{"spn":495.51,"spf":"NaN","id":69769647},{"atb":[[1.03,7.48]],"id":57055802},{"atl":[[990,0.33]],"id":57055802},{"spn":495.51,"spf":"NaN","id":57055802},{"atb":[[1.03,7.48]],"id":40626946},{"atl":[[1000,0.33]],"id":40626946},{"spn":500.51,"spf":"NaN","id":40626946},{"atb":[[1.02,11.22]],"id":45129701},{"atl":[[990,0.33]],"id":45129701},{"spn":495.51,"spf":"NaN","id":45129701}],"con":true,"img":true}]}
{"op":"mcm","clk":"11537302160","pt":1719439030891,"mc":[{"id":"1.230178325","rc":[{"atb":[[1.03,7.48]],"id":63579394},{"atl":[[1000,0.17]],"id":63579394},{"atb":[[1.03,7.48]],"id":70902602},{"atl":[[1000,0.17]],"id":70902602},{"atb":[[1.02,11.22]],"id":69769647},{"atl":[[990,0.17]],"id":69769647},{"atb":[[1.03,7.48]],"id":57055802},{"atl":[[990,0.17]],"id":57055802},{"atb":[[1.03,7.48]],"id":40626946},{"atl":[[1000,0.17]],"id":40626946},{"atb":[[1.02,11.22]],"id":45129701},{"atl":[[990,0.17]],"id":45129701}],"con":true,"img":false}]}
{"op":"mcm","clk":"11537573400","pt":1719443282542,"mc":[{"id":"1.230178325","marketDefinition":{"bspMarket":true,"turnInPlayEnabled":false,"persistenceEnabled":false,"marketBaseRate":5.0,"eventId":"33376062","eventTypeId":"4339","numberOfWinners":2,"bettingType":"ODDS","marketType":"PLACE","marketTime":"2024-06-27T16:24:00.000Z","suspendTime":"2024-06-27T16:24:00.000Z","bspReconciled":false,"complete":true,"inPlay":false,"crossMatching":false,"runnersVoidable":false,"numberOfActiveRunners":6,"betDelay":0,"status":"OPEN","runners":[{"status":"ACTIVE","sortPriority":1,"id":69769647,"name":"1. Teebay"},{"status":"ACTIVE","sortPriority":2,"id":63579394,"name":"2. Apple Jam"},{"status":"ACTIVE","sortPriority":3,"id":40626946,"name":"3. Jaxleg Swift"},{"status":"ACTIVE","sortPriority":4,"id":45129701,"name":"4. Darkies Dream"},{"status":"ACTIVE","sortPriority":5,"id":70902602,"name":"5. Jamaica Joel"},{"status":"ACTIVE","sortPriority":6,"id":57055802,"name":"6. Songful Bird"}],"regulators":["MR_INT"],"venue":"Kinsley","countryCode":"GB","discountAllowed":true,"timezone":"Europe/London","openDate":"2024-06-27T13:36:00.000Z","version":5994643799,"name":"To Be Placed","eventName":"Kinsley 27th Jun"},"rc":[{"atb":[[1.03,7.48]],"id":63579394},{"atl":[[1000,0.17]],"id":63579394},{"spn":500.51,"spf":"NaN","id":63579394},{"atb":[[1.03,7.48]],"id":70902602},{"atl":[[1000,0.17]],"id":70902602},{"spn":500.51,"spf":"NaN","id":70902602},{"atb":[[1.02,11.22]],"id":69769647},{"atl":[[990,0.17]],"id":69769647},{"spn":495.51,"spf":"NaN","id":69769647},{"atb":[[1.03,7.48]],"id":57055802},{"atl":[[990,0.17]],"id":57055802},{"spn":495.51,"spf":"NaN","id":57055802},{"atb":[[1.03,7.48]],"id":40626946},{"atl":[[1000,0.17]],"id":40626946},{"spn":500.51,"spf":"NaN","id":40626946},{"atb":[[1.02,11.22]],"id":45129701},{"atl":[[990,0.17]],"id":45129701},{"spn":495.51,"spf":"NaN","id":45129701}],"con":true,"img":true}]}
{"op":"mcm","clk":"11537954960","pt":1719448682567,"mc":[{"id":"1.230178325","marketDefinition":{"bspMarket":true,"turnInPlayEnabled":false,"persistenceEnabled":false,"marketBaseRate":5.0,"eventId":"33376062","eventTypeId":"4339","numberOfWinners":2,"bettingType":"ODDS","marketType":"PLACE","marketTime":"2024-06-27T16:24:00.000Z","suspendTime":"2024-06-27T16:24:00.000Z","bspReconciled":false,"complete":true,"inPlay":false,"crossMatching":false,"runnersVoidable":false,"numberOfActiveRunners":6,"betDelay":0,"status":"OPEN","runners":[{"status":"ACTIVE","sortPriority":1,"id":69769647,"name":"1. Teebay"},{"status":"ACTIVE","sortPriority":2,"id":63579394,"name":"2. Apple Jam"},{"status":"ACTIVE","sortPriority":3,"id":40626946,"name":"3. Jaxleg Swift"},{"status":"ACTIVE","sortPriority":4,"id":45129701,"name":"4. Darkies Dream"},{"status":"ACTIVE","sortPriority":5,"id":70902602,"name":"5. Jamaica Joel"},{"status":"ACTIVE","sortPriority":6,"id":57055802,"name":"6. Songful Bird"}],"regulators":["MR_INT"],"venue":"Kinsley","countryCode":"GB","discountAllowed":true,"timezone":"Europe/London","openDate":"2024-06-27T13:36:00.000Z","version":5994643799,"name":"To Be Placed","eventName":"Kinsley 27th Jun"},"rc":[{"atb":[[1.03,7.48]],"id":63579394},{"atl":[[1000,0.17]],"id":63579394},{"spn":500.51,"spf":"NaN","id":63579394},{"atb":[[1.03,7.48]],"id":70902602},{"atl":[[1000,0.17]],"id":70902602},{"spn":500.51,"spf":"NaN","id":70902602},{"atb":[[1.02,11.22]],"id":69769647},{"atl":[[990,0.17]],"id":69769647},{"spn":495.51,"spf":"NaN","id":69769647},{"atb":[[1.03,7.48]],"id":57055802},{"atl":[[990,0.17]],"id":57055802},{"spn":495.51,"spf":"NaN","id":57055802},{"atb":[[1.03,7.48]],"id":40626946},{"atl":[[1000,0.17]],"id":40626946},{"spn":500.51,"spf":"NaN","id":40626946},{"atb":[[1.02,11.22]],"id":45129701},{"atl":[[990,0.17]],"id":45129701},{"spn":495.51,"spf":"NaN","id":45129701}],"con":true,"img":true}]}
{"op":"mcm","clk":"11538170623","pt":1719454082549,"mc":[{"id":"1.230178325","marketDefinition":{"bspMarket":true,"turnInPlayEnabled":false,"persistenceEnabled":false,"marketBaseRate":5.0,"eventId":"33376062","eventTypeId":"4339","numberOfWinners":2,"bettingType":"ODDS","marketType":"PLACE","marketTime":"2024-06-27T16:24:00.000Z","suspendTime":"2024-06-27T16:24:00.000Z","bspReconciled":false,"complete":true,"inPlay":false,"crossMatching":false,"runnersVoidable":false,"numberOfActiveRunners":6,"betDelay":0,"status":"OPEN","runners":[{"status":"ACTIVE","sortPriority":1,"id":69769647,"name":"1. Teebay"},{"status":"ACTIVE","sortPriority":2,"id":63579394,"name":"2. Apple Jam"},{"status":"ACTIVE","sortPriority":3,"id":40626946,"name":"3. Jaxleg Swift"},{"status":"ACTIVE","sortPriority":4,"id":45129701,"name":"4. Darkies Dream"},{"status":"ACTIVE","sortPriority":5,"id":70902602,"name":"5. Jamaica Joel"},{"status":"ACTIVE","sortPriority":6,"id":57055802,"name":"6. Songful Bird"}],"regulators":["MR_INT"],"venue":"Kinsley","countryCode":"GB","discountAllowed":true,"timezone":"Europe/London","openDate":"2024-06-27T13:36:00.000Z","version":5994643799,"name":"To Be Placed","eventName":"Kinsley 27th Jun"},"rc":[{"atb":[[1.03,7.49]],"id":63579394},{"atl":[[1000,0.17]],"id":63579394},{"spn":500.51,"spf":"NaN","id":63579394},{"atb":[[1.03,7.49]],"id":70902602},{"atl":[[1000,0.17]],"id":70902602},{"spn":500.51,"spf":"NaN","id":70902602},{"atb":[[1.02,11.23]],"id":69769647},{"atl":[[990,0.17]],"id":69769647},{"spn":495.51,"spf":"NaN","id":69769647},{"atb":[[1.03,7.49]],"id":57055802},{"atl":[[990,0.17]],"id":57055802},{"spn":495.51,"spf":"NaN","id":57055802},{"atb":[[1.03,7.49]],"id":40626946},{"atl":[[1000,0.17]],"id":40626946},{"spn":500.51,"spf":"NaN","id":40626946},{"atb":[[1.02,11.23]],"id":45129701},{"atl":[[990,0.17]],"id":45129701},{"spn":495.51,"spf":"NaN","id":45129701}],"con":true,"img":true}]}
{"op":"mcm","clk":"11538368281","pt":1719459482599,"mc":[{"id":"1.230178325","marketDefinition":{"bspMarket":true,"turnInPlayEnabled":false,"persistenceEnabled":false,"marketBaseRate":5.0,"eventId":"33376062","eventTypeId":"4339","numberOfWinners":2,"bettingType":"ODDS","marketType":"PLACE","marketTime":"2024-06-27T16:24:00.000Z","suspendTime":"2024-06-27T16:24:00.000Z","bspReconciled":false,"complete":true,"inPlay":false,"crossMatching":false,"runnersVoidable":false,"numberOfActiveRunners":6,"betDelay":0,"status":"OPEN","runners":[{"status":"ACTIVE","sortPriority":1,"id":69769647,"name":"1. Teebay"},{"status":"ACTIVE","sortPriority":2,"id":63579394,"name":"2. Apple Jam"},{"status":"ACTIVE","sortPriority":3,"id":40626946,"name":"3. Jaxleg Swift"},{"status":"ACTIVE","sortPriority":4,"id":45129701,"name":"4. Darkies Dream"},{"status":"ACTIVE","sortPriority":5,"id":70902602,"name":"5. Jamaica Joel"},{"status":"ACTIVE","sortPriority":6,"id":57055802,"name":"6. Songful Bird"}],"regulators":["MR_INT"],"venue":"Kinsley","countryCode":"GB","discountAllowed":true,"timezone":"Europe/London","openDate":"2024-06-27T13:36:00.000Z","version":5994643799,"name":"To Be Placed","eventName":"Kinsley 27th Jun"},"rc":[{"atb":[[1.03,7.49]],"id":63579394},{"atl":[[1000,0.17]],"id":63579394},{"spn":500.51,"spf":"NaN","id":63579394},{"atb":[[1.03,7.49]],"id":70902602},{"atl":[[1000,0.17]],"id":70902602},{"spn":500.51,"spf":"NaN","id":70902602},{"atb":[[1.02,11.23]],"id":69769647},{"atl":[[990,0.17]],"id":69769647},{"spn":495.51,"spf":"NaN","id":69769647},{"atb":[[1.03,7.49]],"id":57055802},{"atl":[[990,0.17]],"id":57055802},{"spn":495.51,"spf":"NaN","id":57055802},{"atb":[[1.03,7.49]],"id":40626946},{"atl":[[1000,0.17]],"id":40626946},{"spn":500.51,"spf":"NaN","id":40626946},{"atb":[[1.02,11.23]],"id":45129701},{"atl":[[990,0.17]],"id":45129701},{"spn":495.51,"spf":"NaN","id":45129701}],"con":true,"img":true}]}
{"op":"mcm","clk":"11538595407","pt":1719464882547,"mc":[{"id":"1.230178325","marketDefinition":{"bspMarket":true,"turnInPlayEnabled":false,"persistenceEnabled":false,"marketBaseRate":5.0,"eventId":"33376062","eventTypeId":"4339","numberOfWinners":2,"bettingType":"ODDS","marketType":"PLACE","marketTime":"2024-06-27T16:24:00.000Z","suspendTime":"2024-06-27T16:24:00.000Z","bspReconciled":false,"complete":true,"inPlay":false,"crossMatching":false,"runnersVoidable":false,"numberOfActiveRunners":6,"betDelay":0,"status":"OPEN","runners":[{"status":"ACTIVE","sortPriority":1,"id":69769647,"name":"1. Teebay"},{"status":"ACTIVE","sortPriority":2,"id":63579394,"name":"2. Apple Jam"},{"status":"ACTIVE","sortPriority":3,"id":40626946,"name":"3. Jaxleg Swift"},{"status":"ACTIVE","sortPriority":4,"id":45129701,"name":"4. Darkies Dream"},{"status":"ACTIVE","sortPriority":5,"id":70902602,"name":"5. Jamaica Joel"},{"status":"ACTIVE","sortPriority":6,"id":57055802,"name":"6. Songful Bird"}],"regulators":["MR_INT"],"venue":"Kinsley","countryCode":"GB","discountAllowed":true,"timezone":"Europe/London","openDate":"2024-06-27T13:36:00.000Z","version":5994643799,"name":"To Be Placed","eventName":"Kinsley 27th Jun"},"rc":[{"atb":[[1.03,7.48]],"id":63579394},{"atl":[[1000,0.17]],"id":63579394},{"spn":500.51,"spf":"NaN","id":63579394},{"atb":[[1.03,7.48]],"id":70902602},{"atl":[[1000,0.17]],"id":70902602},{"spn":500.51,"spf":"NaN","id":70902602},{"atb":[[1.02,11.23]],"id":69769647},{"atl":[[990,0.17]],"id":69769647},{"spn":495.51,"spf":"NaN","id":69769647},{"atb":[[1.03,7.48]],"id":57055802},{"atl":[[990,0.17]],"id":57055802},{"spn":495.51,"spf":"NaN","id":57055802},{"atb":[[1.03,7.48]],"id":40626946},{"atl":[[1000,0.17]],"id":40626946},{"spn":500.51,"spf":"NaN","id":40626946},{"atb":[[1.02,11.23]],"id":45129701},{"atl":[[990,0.17]],"id":45129701},{"spn":495.51,"spf":"NaN","id":45129701}],"con":true,"img":true}]}
{"op":"mcm","clk":"11538907317","pt":1719471508370,"mc":[{"id":"1.230178325","rc":[{"atb":[[1.03,7.48]],"id":63579394},{"atl":[[1000,1.17]],"id":63579394},{"atb":[[1.03,7.48]],"id":70902602},{"atl":[[1000,1.17]],"id":70902602},{"atb":[[1.02,11.23]],"id":69769647},{"atl":[[1000,1]],"id":69769647},{"atb":[[1.03,7.48]],"id":57055802},{"atl":[[1000,1]],"id":57055802},{"atb":[[1.03,7.48]],"id":40626946},{"atl":[[1000,1.17]],"id":40626946},{"atb":[[1.02,11.23]],"id":45129701},{"atl":[[1000,1]],"id":45129701}],"con":true,"img":false}]}
{"op":"mcm","clk":"11538907323","pt":1719471508471,"mc":[{"id":"1.230178325","rc":[{"atb":[[1.07,2.48]],"id":63579394},{"atb":[[1.07,2.48]],"id":70902602},{"atb":[[1.07,2.48]],"id":69769647},{"atb":[[1.07,2.48]],"id":57055802},{"atb":[[1.07,2.48]],"id":40626946},{"atb":[[1.07,2.48]],"id":45129701}],"con":true,"img":false}]}
{"op":"mcm","clk":"11538907326","pt":1719471508570,"mc":[{"id":"1.230178325","rc":[{"atl":[[1000,0.65]],"id":70902602},{"atl":[[1000,0.65]],"id":63579394},{"atl":[[1000,0.48]],"id":69769647},{"atl":[[1000,0.48]],"id":57055802},{"atl":[[1000,0.65]],"id":40626946},{"atl":[[1000,0.48]],"id":45129701}],"con":true,"img":false}]}
{"op":"mcm","clk":"11538907336","pt":1719471508775,"mc":[{"id":"1.230178325","rc":[{"atl":[[1000,0.17]],"id":63579394},{"atl":[[1000,0.17]],"id":70902602},{"atl":[[1000,0]],"id":69769647},{"atl":[[1000,0]],"id":57055802},{"atl":[[1000,0.17]],"id":40626946},{"atl":[[1000,0]],"id":45129701}],"con":true,"img":false}]}
{"op":"mcm","clk":"11538907343","pt":1719471508878,"mc":[{"id":"1.230178325","rc":[{"atl":[[75,0.48]],"id":63579394},{"atl":[[75,0.48]],"id":70902602},{"atl":[[75,0.48]],"id":69769647},{"atl":[[75,0.48]],"id":57055802},{"atl":[[75,0.48]],"id":40626946},{"atl":[[75,0.48]],"id":45129701}],"con":true,"img":false}]}
{"op":"mcm","clk":"11539122554","pt":1719475682555,"mc":[{"id":"1.230178325","marketDefinition":{"bspMarket":true,"turnInPlayEnabled":false,"persistenceEnabled":false,"marketBaseRate":5.0,"eventId":"33376062","eventTypeId":"4339","numberOfWinners":2,"bettingType":"ODDS","marketType":"PLACE","marketTime":"2024-06-27T16:24:00.000Z","suspendTime":"2024-06-27T16:24:00.000Z","bspReconciled":false,"complete":true,"inPlay":false,"crossMatching":false,"runnersVoidable":false,"numberOfActiveRunners":6,"betDelay":0,"status":"OPEN","runners":[{"status":"ACTIVE","sortPriority":1,"id":69769647,"name":"1. Teebay"},{"status":"ACTIVE","sortPriority":2,"id":63579394,"name":"2. Apple Jam"},{"status":"ACTIVE","sortPriority":3,"id":40626946,"name":"3. Jaxleg Swift"},{"status":"ACTIVE","sortPriority":4,"id":45129701,"name":"4. Darkies Dream"},{"status":"ACTIVE","sortPriority":5,"id":70902602,"name":"5. Jamaica Joel"},{"status":"ACTIVE","sortPriority":6,"id":57055802,"name":"6. Songful Bird"}],"regulators":["MR_INT"],"venue":"Kinsley","countryCode":"GB","discountAllowed":true,"timezone":"Europe/London","openDate":"2024-06-27T13:36:00.000Z","version":5994643799,"name":"To Be Placed","eventName":"Kinsley 27th Jun"},"rc":[{"atb":[[1.03,7.48],[1.07,2.48]],"id":70902602},{"atl":[[75,0.48],[1000,0.17]],"id":70902602},{"spn":38.03,"spf":"NaN","id":70902602},{"atb":[[1.03,7.48],[1.07,2.48]],"id":63579394},{"atl":[[75,0.48],[1000,0.17]],"id":63579394},{"spn":38.03,"spf":"NaN","id":63579394},{"atb":[[1.02,11.22],[1.07,2.48]],"id":69769647},{"atl":[[75,0.48],[990,0.17]],"id":69769647},{"spn":38.03,"spf":"NaN","id":69769647},{"atb":[[1.03,7.48],[1.07,2.48]],"id":57055802},{"atl":[[75,0.48],[990,0.17]],"id":57055802},{"spn":38.03,"spf":"NaN","id":57055802},{"atb":[[1.03,7.48],[1.07,2.48]],"id":40626946},{"atl":[[75,0.48],[1000,0.17]],"id":40626946},{"spn":38.03,"spf":"NaN","id":40626946},{"atb":[[1.02,11.22],[1.07,2.48]],"id":45129701},{"atl":[[75,0.48],[990,0.17]],"id":45129701},{"spn":38.03,"spf":"NaN","id":45129701}],"con":true,"img":true}]}
{"op":"mcm","clk":"11539438530","pt":1719481082550,"mc":[{"id":"1.230178325","marketDefinition":{"bspMarket":true,"turnInPlayEnabled":false,"persistenceEnabled":false,"marketBaseRate":5.0,"eventId":"33376062","eventTypeId":"4339","numberOfWinners":2,"bettingType":"ODDS","marketType":"PLACE","marketTime":"2024-06-27T16:24:00.000Z","suspendTime":"2024-06-27T16:24:00.000Z","bspReconciled":false,"complete":true,"inPlay":false,"crossMatching":false,"runnersVoidable":false,"numberOfActiveRunners":6,"betDelay":0,"status":"OPEN","runners":[{"status":"ACTIVE","sortPriority":1,"id":69769647,"name":"1. Teebay"},{"status":"ACTIVE","sortPriority":2,"id":63579394,"name":"2. Apple Jam"},{"status":"ACTIVE","sortPriority":3,"id":40626946,"name":"3. Jaxleg Swift"},{"status":"ACTIVE","sortPriority":4,"id":45129701,"name":"4. Darkies Dream"},{"status":"ACTIVE","sortPriority":5,"id":70902602,"name":"5. Jamaica Joel"},{"status":"ACTIVE","sortPriority":6,"id":57055802,"name":"6. Songful Bird"}],"regulators":["MR_INT"],"venue":"Kinsley","countryCode":"GB","discountAllowed":true,"timezone":"Europe/London","openDate":"2024-06-27T13:36:00.000Z","version":5994643799,"name":"To Be Placed","eventName":"Kinsley 27th Jun"},"rc":[{"atb":[[1.03,7.48],[1.07,2.48]],"id":70902602},{"atl":[[75,0.48],[1000,0.17]],"id":70902602},{"spn":38.03,"spf":"NaN","id":70902602},{"atb":[[1.03,7.48],[1.07,2.48]],"id":63579394},{"atl":[[75,0.48],[1000,0.17]],"id":63579394},{"spn":38.03,"spf":"NaN","id":63579394},{"atb":[[1.02,11.22],[1.07,2.48]],"id":69769647},{"atl":[[75,0.48],[990,0.17]],"id":69769647},{"spn":38.03,"spf":"NaN","id":69769647},{"atb":[[1.03,7.48],[1.07,2.48]],"id":57055802},{"atl":[[75,0.48],[990,0.17]],"id":57055802},{"spn":38.03,"spf":"NaN","id":57055802},{"atb":[[1.03,7.48],[1.07,2.48]],"id":40626946},{"atl":[[75,0.48],[1000,0.17]],"id":40626946},{"spn":38.03,"spf":"NaN","id":40626946},{"atb":[[1.02,11.22],[1.07,2.48]],"id":45129701},{"atl":[[75,0.48],[990,0.17]],"id":45129701},{"spn":38.03,"spf":"NaN","id":45129701}],"con":true,"img":true}]}
{"op":"mcm","clk":"11540683364","pt":1719497282515,"mc":[{"id":"1.230178325","marketDefinition":{"bspMarket":true,"turnInPlayEnabled":false,"persistenceEnabled":false,"marketBaseRate":5.0,"eventId":"33376062","eventTypeId":"4339","numberOfWinners":2,"bettingType":"ODDS","marketType":"PLACE","marketTime":"2024-06-27T16:24:00.000Z","suspendTime":"2024-06-27T16:24:00.000Z","bspReconciled":false,"complete":true,"inPlay":false,"crossMatching":false,"runnersVoidable":false,"numberOfActiveRunners":6,"betDelay":0,"status":"OPEN","runners":[{"status":"ACTIVE","sortPriority":1,"id":69769647,"name":"1. Teebay"},{"status":"ACTIVE","sortPriority":2,"id":63579394,"name":"2. Apple Jam"},{"status":"ACTIVE","sortPriority":3,"id":40626946,"name":"3. Jaxleg Swift"},{"status":"ACTIVE","sortPriority":4,"id":45129701,"name":"4. Darkies Dream"},{"status":"ACTIVE","sortPriority":5,"id":70902602,"name":"5. Jamaica Joel"},{"status":"ACTIVE","sortPriority":6,"id":57055802,"name":"6. Songful Bird"}],"regulators":["MR_INT"],"venue":"Kinsley","countryCode":"GB","discountAllowed":true,"timezone":"Europe/London","openDate":"2024-06-27T13:36:00.000Z","version":5994643799,"name":"To Be Placed","eventName":"Kinsley 27th Jun"},"rc":[{"atb":[[1.03,7.49],[1.07,2.48]],"id":70902602},{"atl":[[75,0.48],[1000,0.17]],"id":70902602},{"spn":38.03,"spf":"NaN","id":70902602},{"atb":[[1.03,7.49],[1.07,2.48]],"id":63579394},{"atl":[[75,0.48],[1000,0.17]],"id":63579394},{"spn":38.03,"spf":"NaN","id":63579394},{"atb":[[1.02,11.23],[1.07,2.48]],"id":69769647},{"atl":[[75,0.48],[990,0.17]],"id":69769647},{"spn":38.03,"spf":"NaN","id":69769647},{"atb":[[1.03,7.49],[1.07,2.48]],"id":57055802},{"atl":[[75,0.48],[990,0.17]],"id":57055802},{"spn":38.03,"spf":"NaN","id":57055802},{"atb":[[1.03,7.49],[1.07,2.48]],"id":40626946},{"atl":[[75,0.48],[1000,0.17]],"id":40626946},{"spn":38.03,"spf":"NaN","id":40626946},{"atb":[[1.02,11.23],[1.07,2.48]],"id":45129701},{"atl":[[75,0.48],[990,0.17]],"id":45129701},{"spn":38.03,"spf":"NaN","id":45129701}],"con":true,"img":true}]}
{"op":"mcm","clk":"11540933409","pt":1719500144047,"mc":[{"id":"1.230178325","rc":[{"atb":[[1.03,7.49]],"id":70902602},{"atl":[[980,1.32]],"id":70902602},{"spn":38.03,"spf":"NaN","id":70902602},{"atb":[[1.03,7.49]],"id":63579394},{"atl":[[970,2.11]],"id":63579394},{"spn":38.03,"spf":"NaN","id":63579394},{"atb":[[1.02,11.23]],"id":69769647},{"atl":[[960,0.93]],"id":69769647},{"spn":38.03,"spf":"NaN","id":69769647},{"atb":[[1.03,7.49]],"id":57055802},{"atl":[[960,2.04]],"id":57055802},{"spn":38.03,"spf":"NaN","id":57055802},{"atb":[[1.03,7.49]],"id":40626946},{"atl":[[990,1.96]],"id":40626946},{"spn":38.03,"spf":"NaN","id":40626946},{"atb":[[1.02,11.23]],"id":45129701},{"atl":[[970,1.61]],"id":45129701},{"spn":38.03,"spf":"NaN","id":45129701}],"con":true,"img":false}]}
{"op":"mcm","clk":"11541139075","pt":1719502682530,"mc":[{"id":"1.230178325","marketDefinition":{"bspMarket":true,"turnInPlayEnabled":false,"persistenceEnabled":false,"marketBaseRate":5.0,"eventId":"33376062","eventTypeId":"4339","numberOfWinners":2,"bettingType":"ODDS","marketType":"PLACE","marketTime":"2024-06-27T16:24:00.000Z","suspendTime":"2024-06-27T16:24:00.000Z","bspReconciled":false,"complete":true,"inPlay":false,"crossMatching":false,"runnersVoidable":false,"numberOfActiveRunners":6,"betDelay":0,"status":"OPEN","runners":[{"status":"ACTIVE","sortPriority":1,"id":69769647,"name":"1. Teebay"},{"status":"ACTIVE","sortPriority":2,"id":63579394,"name":"2. Apple Jam"},{"status":"ACTIVE","sortPriority":3,"id":40626946,"name":"3. Jaxleg Swift"},{"status":"ACTIVE","sortPriority":4,"id":45129701,"name":"4. Darkies Dream"},{"status":"ACTIVE","sortPriority":5,"id":70902602,"name":"5. Jamaica Joel"},{"status":"ACTIVE","sortPriority":6,"id":57055802,"name":"6. Songful Bird"}],"regulators":["MR_INT"],"venue":"Kinsley","countryCode":"GB","discountAllowed":true,"timezone":"Europe/London","openDate":"2024-06-27T13:36:00.000Z","version":5994643799,"name":"To Be Placed","eventName":"Kinsley 27th Jun"},"rc":[{"atb":[[1.03,7.49],[1.07,2.48]],"id":70902602},{"atl":[[75,0.48],[980,1.32],[1000,0.17]],"id":70902602},{"spn":38.03,"spf":"NaN","id":70902602},{"atb":[[1.03,7.49],[1.07,2.48]],"id":63579394},{"atl":[[75,0.48],[970,2.11],[1000,0.17]],"id":63579394},{"spn":38.03,"spf":"NaN","id":63579394},{"atb":[[1.02,11.23],[1.07,2.48]],"id":69769647},{"atl":[[75,0.48],[960,0.93],[990,0.17]],"id":69769647},{"spn":38.03,"spf":"NaN","id":69769647},{"atb":[[1.03,7.49],[1.07,2.48]],"id":57055802},{"atl":[[75,0.48],[960,2.04],[990,0.17]],"id":57055802},{"spn":38.03,"spf":"NaN","id":57055802},{"atb":[[1.03,7.49],[1.07,2.48]],"id":40626946},{"atl":[[75,0.48],[990,1.96],[1000,0.17]],"id":40626946},{"spn":38.03,"spf":"NaN","id":40626946},{"atb":[[1.02,11.23],[1.07,2.48]],"id":45129701},{"atl":[[75,0.48],[970,1.61],[990,0.17]],"id":45129701},{"spn":38.03,"spf":"NaN","id":45129701}],"con":true,"img":true}]}
{"op":"mcm","clk":"11541205710","pt":1719503343579,"mc":[{"id":"1.230178325","rc":[{"atb":[[1.03,7.49],[1.04,1]],"id":70902602},{"atl":[[980,1.32]],"id":70902602},{"atb":[[1.03,7.49],[1.04,1]],"id":63579394},{"atl":[[970,2.11]],"id":63579394},{"atb":[[1.02,11.23],[1.04,1]],"id":69769647},{"atl":[[960,0.93]],"id":69769647},{"atb":[[1.03,7.49],[1.04,1]],"id":57055802},{"atl":[[960,2.04]],"id":57055802},{"atb":[[1.03,7.49],[1.04,1]],"id":40626946},{"atl":[[990,1.96]],"id":40626946},{"atb":[[1.02,11.23],[1.04,1]],"id":45129701},{"atl":[[970,1.61]],"id":45129701}],"con":true,"img":false}]}
{"op":"mcm","clk":"11541205722","pt":1719503343682,"mc":[{"id":"1.230178325","rc":[{"atb":[[1.04,0.25]],"id":70902602},{"atb":[[1.04,0.25]],"id":63579394},{"atb":[[1.04,0.25]],"id":69769647},{"atb":[[1.04,0.25]],"id":57055802},{"atb":[[1.04,0.25]],"id":40626946},{"atb":[[1.04,0.25]],"id":45129701}],"con":true,"img":false}]}
{"op":"mcm","clk":"11541205739","pt":1719503343888,"mc":[{"id":"1.230178325","rc":[{"atb":[[1.04,0]],"id":70902602},{"atb":[[1.04,0]],"id":63579394},{"atb":[[1.04,0]],"id":69769647},{"atb":[[1.04,0]],"id":57055802},{"atb":[[1.04,0]],"id":40626946},{"atb":[[1.04,0]],"id":45129701}],"con":true,"img":false}]}
{"op":"mcm","clk":"11541205749","pt":1719503343992,"mc":[{"id":"1.230178325","rc":[{"atb":[[1.2,0.25]],"id":70902602},{"atb":[[1.2,0.25]],"id":63579394},{"atb":[[1.2,0.25]],"id":69769647},{"atb":[[1.2,0.25]],"id":57055802},{"atb":[[1.2,0.25]],"id":40626946},{"atb":[[1.2,0.25]],"id":45129701}],"con":true,"img":false}]}
{"op":"mcm","clk":"11541238178","pt":1719503678737,"mc":[{"id":"1.230178325","rc":[{"spn":38.1,"spf":"NaN","id":70902602},{"atb":[[1.09,43.92]],"id":63579394},{"spn":38.1,"spf":"NaN","id":63579394},{"spn":38.1,"spf":"NaN","id":69769647},{"spn":38.1,"spf":"NaN","id":57055802},{"spn":38.1,"spf":"NaN","id":40626946},{"spn":38.1,"spf":"NaN","id":45129701}],"con":true,"img":false}]}
{"op":"mcm","clk":"11541238210","pt":1719503679047,"mc":[{"id":"1.230178325","rc":[{"atb":[[1.09,43.92]],"id":57055802},{"atb":[[1.09,43.92]],"id":45129701}],"con":true,"img":false}]}
{"op":"mcm","clk":"11541238656","pt":1719503683375,"mc":[{"id":"1.230178325","marketDefinition":{"bspMarket":true,"turnInPlayEnabled":false,"persistenceEnabled":false,"marketBaseRate":5.0,"eventId":"33376062","eventTypeId":"4339","numberOfWinners":2,"bettingType":"ODDS","marketType":"PLACE","marketTime":"2024-06-27T16:24:00.000Z","suspendTime":"2024-06-27T16:24:00.000Z","bspReconciled":false,"complete":true,"inPlay":false,"crossMatching":true,"runnersVoidable":false,"numberOfActiveRunners":6,"betDelay":0,"status":"OPEN","runners":[{"status":"ACTIVE","sortPriority":1,"id":69769647,"name":"1. Teebay"},{"status":"ACTIVE","sortPriority":2,"id":63579394,"name":"2. Apple Jam"},{"status":"ACTIVE","sortPriority":3,"id":40626946,"name":"3. Jaxleg Swift"},{"status":"ACTIVE","sortPriority":4,"id":45129701,"name":"4. Darkies Dream"},{"status":"ACTIVE","sortPriority":5,"id":70902602,"name":"5. Jamaica Joel"},{"status":"ACTIVE","sortPriority":6,"id":57055802,"name":"6. Songful Bird"}],"regulators":["MR_INT"],"venue":"Kinsley","countryCode":"GB","discountAllowed":true,"timezone":"Europe/London","openDate":"2024-06-27T13:36:00.000Z","version":5994643799,"name":"To Be Placed","eventName":"Kinsley 27th Jun"},"rc":[],"con":true,"img":false}]}
{"op":"mcm","clk":"11541301700","pt":1719504282011,"mc":[{"id":"1.230178325","rc":[{"atb":[[1.03,7.48],[1.09,43.91]],"id":63579394},{"atl":[[970,2.11]],"id":63579394},{"atb":[[1.03,7.48]],"id":70902602},{"atl":[[980,1.32]],"id":70902602},{"atb":[[1.02,11.23],[1.09,43.91]],"id":69769647},{"atl":[[960,0.93]],"id":69769647},{"atb":[[1.03,7.48],[1.09,43.91]],"id":57055802},{"atl":[[960,2.03]],"id":57055802},{"atb":[[1.03,7.48]],"id":40626946},{"atl":[[990,1.96]],"id":40626946},{"atb":[[1.02,11.23],[1.09,43.91]],"id":45129701},{"atl":[[970,1.61]],"id":45129701}],"con":true,"img":false}]}
{"op":"mcm","clk":"11541325023","pt":1719504540481,"mc":[{"id":"1.230178325","rc":[{"atb":[[2.02,1],[1.62,2.48]],"id":63579394},{"atl":[[19,2],[6,1]],"id":63579394},{"spn":4.01,"spf":"NaN","id":63579394},{"atb":[[1.59,1],[1.35,2.48]],"id":70902602},{"atl":[[9.6,2],[4.2,1]],"id":70902602},{"spn":2.89,"spf":"NaN","id":70902602},{"atb":[[1.55,1],[1.39,2.48]],"id":69769647},{"atl":[[10.5,2],[3.9,1]],"id":69769647},{"spn":2.72,"spf":"NaN","id":69769647},{"atb":[[2.46,1],[1.86,2.48]],"id":57055802},{"atl":[[55,2],[7.8,1]],"id":57055802},{"spn":5.13,"spf":"NaN","id":57055802},{"atb":[[1.16,4.99],[1.78,1]],"id":40626946},{"atl":[[9.2,2],[5.3,1]],"id":40626946},{"spn":3.54,"spf":"NaN","id":40626946},{"atb":[[2.02,1],[1.68,2.48]],"id":45129701},{"atl":[[5.6,1],[24,2]],"id":45129701},{"spn":3.81,"spf":"NaN","id":45129701}],"con":true,"img":false}]}
{"op":"mcm","clk":"11541325245","pt":1719504543477,"mc":[{"id":"1.230178325","rc":[{"atb":[[1.45,2.48]],"id":70902602},{"atb":[[1.62,0],[1.7,2.48]],"id":63579394},{"atb":[[1.49,2.48],[1.39,0]],"id":69769647},{"atb":[[1.99,2.48],[1.86,0]],"id":57055802},{"atb":[[1.16,0],[1.25,2.48]],"id":40626946},{"atb":[[1.68,0],[1.77,2.48]],"id":45129701}],"con":true,"img":false}]}
{"op":"mcm","clk":"11541325254","pt":1719504543580,"mc":[{"id":"1.230178325","rc":[{"atb":[[1.35,0]],"id":70902602}],"con":true,"img":false}]}
{"op":"mcm","clk":"11541325488","pt":1719504546792,"mc":[{"id":"1.230178325","rc":[{"atb":[[1.01,1.7]],"id":63579394},{"atl":[[1000,1.87]],"id":63579394},{"atb":[[1.01,1.7]],"id":69769647},{"atl":[[1000,1.7]],"id":69769647},{"atb":[[1.01,1.7]],"id":40626946},{"atl":[[1000,1.87]],"id":40626946}],"con":true,"img":false}]}
{"op":"mcm","clk":"11541325508","pt":1719504547104,"mc":[{"id":"1.230178325","rc":[{"atb":[[1.01,0.44]],"id":63579394},{"atl":[[1000,0.19]],"id":63579394},{"atb":[[1.01,0.63]],"id":69769647},{"atl":[[1000,0.03]],"id":69769647},{"atb":[[1.01,1.22]],"id":40626946},{"atl":[[1000,0.21]],"id":40626946}],"con":true,"img":false}]}
{"op":"mcm","clk":"11541325523","pt":1719504547309,"mc":[{"id":"1.230178325","rc":[{"atb":[[1.01,0]],"id":63579394},{"atl":[[1000,0.17]],"id":63579394},{"atb":[[1.01,0]],"id":69769647},{"atl":[[1000,0]],"id":69769647},{"atb":[[1.01,0]],"id":40626946},{"atl":[[1000,0.17]],"id":40626946}],"con":true,"img":false}]}
{"op":"mcm","clk":"11541325532","pt":1719504547412,"mc":[{"id":"1.230178325","rc":[{"atb":[[1.71,0.44]],"id":63579394},{"atl":[[18.5,0.01]],"id":63579394},{"atb":[[1.5,0.63]],"id":69769647},{"atl":[[10,0.03]],"id":69769647},{"atb":[[1.26,1.22]],"id":40626946},{"atl":[[9,0.03]],"id":40626946}],"con":true,"img":false}]}
{"op":"mcm","clk":"11541326492","pt":1719504560703,"mc":[{"id":"1.230178325","rc":[{"atl":[[5.8,1],[6,0]],"id":63579394},{"atl":[[4,1],[4.2,0]],"id":70902602},{"atb":[[1.55,0],[1.66,1]],"id":69769647},{"atl":[[3.85,1],[3.9,0]],"id":69769647},{"atb":[[2.4,1],[2.46,0]],"id":57055802},{"atl":[[7.4,1],[7.8,0]],"id":57055802},{"atl":[[5.1,1],[5.3,0]],"id":40626946},{"atl":[[5.6,0],[5.3,1]],"id":45129701}],"con":true,"img":false}]}
{"op":"mcm","clk":"11541326503","pt":1719504560801,"mc":[{"id":"1.230178325","rc":[{"atl":[[17,2],[19,0],[5.3,1]],"id":63579394},{"atb":[[1.45,0],[1.51,2.48]],"id":70902602},{"atl":[[9.6,0],[3.6,1],[9,2]],"id":70902602},{"atb":[[1.57,2],[1.49,0]],"id":69769647},{"atl":[[10.5,0],[9.8,2],[4.2,1]],"id":69769647},{"atb":[[1.99,0],[2.1,2.48]],"id":57055802},{"atl":[[44,2],[55,0],[6.6,1]],"id":57055802},{"atb":[[1.25,0],[1.35,2]],"id":40626946},{"atl":[[8.6,2],[9.2,0],[4.6,1]],"id":40626946},{"atl":[[22,2],[24,0]],"id":45129701}],"con":true,"img":false}]}
{"op":"mcm","clk":"11541326514","pt":1719504560912,"mc":[{"id":"1.230178325","rc":[{"atl":[[4,0]],"id":70902602},{"atl":[[5.8,0]],"id":63579394},{"atl":[[3.85,0]],"id":69769647},{"atl":[[7.4,0]],"id":57055802},{"atl":[[5.1,0]],"id":40626946}],"con":true,"img":false}]}
{"op":"mcm","clk":"11541326563","pt":1719504561420,"mc":[{"id":"1.230178325","rc":[{"atl":[[3.6,0],[3.7,1]],"id":70902602}],"con":true,"img":false}]}
{"op":"mcm","clk":"11541326657","pt":1719504562607,"mc":[{"id":"1.230178325","rc":[{"atb":[[2.02,0],[2.12,1]],"id":63579394},{"atb":[[1.88,1],[1.78,0]],"id":40626946},{"atb":[[2.02,0],[2.12,1]],"id":45129701}],"con":true,"img":false}]}
{"op":"mcm","clk":"11541326695","pt":1719504563022,"mc":[{"id":"1.230178325","rc":[{"atb":[[2.02,1],[2.12,0]],"id":63579394},{"atb":[[1.88,0],[1.78,1]],"id":40626946},{"atb":[[2.02,1],[2.12,0]],"id":45129701}],"con":true,"img":false}]}
{"op":"mcm","clk":"11541327232","pt":1719504570040,"mc":[{"id":"1.230178325","rc":[{"atb":[[2.12,1]],"id":63579394},{"atb":[[1.88,1],[1.78,0]],"id":40626946},{"atb":[[2.02,0],[2.12,1]],"id":45129701}],"con":true,"img":false}]}
{"op":"mcm","clk":"11541327239","pt":1719504570135,"mc":[{"id":"1.230178325","rc":[{"atb":[[2.02,0]],"id":63579394},{"atb":[[1.81,2.48],[1.77,0]],"id":45129701}],"con":true,"img":false}]}
{"op":"mcm","clk":"11541327288","pt":1719504570711,"mc":[{"id":"1.230178325","rc":[{"atb":[[1.55,1]],"id":69769647}],"con":true,"img":false}]}
{"op":"mcm","clk":"11541327299","pt":1719504570813,"mc":[{"id":"1.230178325","rc":[{"atb":[[1.66,0]],"id":69769647},{"atl":[[7.4,1],[6.6,0]],"id":57055802}],"con":true,"img":false}]}
{"op":"mcm","clk":"11541327305","pt":1719504570914,"mc":[{"id":"1.230178325","rc":[{"atl":[[5.8,1],[5.3,0]],"id":63579394},{"atl":[[4,1],[3.7,0]],"id":70902602},{"atl":[[5.1,1]],"id":40626946}],"con":true,"img":false}]}
{"op":"mcm","clk":"11541327321","pt":1719504571022,"mc":[{"id":"1.230178325","rc":[{"atl":[[4.6,0]],"id":40626946}],"con":true,"img":false}]}
{"op":"mcm","clk":"11541327360","pt":1719504571534,"mc":[{"id":"1.230178325","rc":[{"atb":[[2.02,1],[2.12,0]],"id":63579394},{"atb":[[1.55,0],[1.66,1]],"id":69769647},{"atb":[[1.88,0],[1.78,1]],"id":40626946},{"atb":[[2.02,1],[2.12,0]],"id":45129701}],"con":true,"img":false}]}
{"op":"mcm","clk":"11541327372","pt":1719504571638,"mc":[{"id":"1.230178325","rc":[{"atb":[[1.74,2],[1.7,0]],"id":63579394}],"con":true,"img":false}]}
{"op":"mcm","clk":"11541327423","pt":1719504572346,"mc":[{"id":"1.230178325","rc":[{"atl":[[5.8,0],[5.3,1]],"id":63579394},{"atl":[[4,0],[3.6,1]],"id":70902602},{"atl":[[7.4,0],[6.6,1]],"id":57055802},{"atl":[[5.1,0],[4.6,1]],"id":40626946}],"con":true,"img":false}]}
{"op":"mcm","clk":"11541327444","pt":1719504572548,"mc":[{"id":"1.230178325","rc":[{"atl":[[4,2],[9,0]],"id":70902602}],"con":true,"img":false}]}
{"op":"mcm","clk":"11541327561","pt":1719504573742,"mc":[{"id":"1.230178325","rc":[{"atl":[[3.6,0],[3.7,1]],"id":70902602}],"con":true,"img":false}]}
{"op":"mcm","clk":"11541327627","pt":1719504574522,"mc":[{"id":"1.230178325","rc":[{"atb":[[1.09,0]],"id":69769647}],"con":true,"img":false}]}
{"op":"mcm","clk":"11541327683","pt":1719504575242,"mc":[{"id":"1.230178325","rc":[{"atb":[[1.55,1],[1.66,0]],"id":69769647}],"con":true,"img":false}]}
{"op":"mcm","clk":"11541327907","pt":1719504577715,"mc":[{"id":"1.230178325","rc":[{"atl":[[4,0],[9,3]],"id":70902602}],"con":true,"img":false}]}
{"op":"mcm","clk":"11541328012","pt":1719504578760,"mc":[{"id":"1.230178325","rc":[{"atl":[[4,1],[3.7,0]],"id":70902602},{"atl":[[5.8,1],[5.3,0]],"id":63579394},{"atl":[[3.85,1],[4.2,0]],"id":69769647},{"atl":[[7.4,1],[6.6,0]],"id":57055802},{"atl":[[5.1,1],[4.6,0]],"id":40626946}],"con":true,"img":false}]}
{"op":"mcm","clk":"11541328031","pt":1719504578918,"mc":[{"id":"1.230178325","rc":[{"atb":[[1.55,0],[1.66,1]],"id":69769647}],"con":true,"img":false}]}
{"op":"mcm","clk":"11541328041","pt":1719504579027,"mc":[{"id":"1.230178325","rc":[{"atl":[[5.8,0],[5.3,1]],"id":63579394},{"atl":[[4,0],[3.7,1]],"id":70902602},{"atl":[[3.85,0],[4.2,1]],"id":69769647},{"atl":[[7.4,0],[6.6,1]],"id":57055802},{"atl":[[5.1,0],[4.6,1]],"id":40626946}],"con":true,"img":false}]}
{"op":"mcm","clk":"11541328267","pt":1719504580937,"mc":[{"id":"1.230178325","rc":[{"atl":[[3.6,1],[3.7,0]],"id":70902602}],"con":true,"img":false}]}
{"op":"mcm","clk":"11541328333","pt":1719504581859,"mc":[{"id":"1.230178325","rc":[{"atl":[[3.6,0],[3.7,1]],"id":70902602}],"con":true,"img":false}]}
{"op":"mcm","clk":"11541328505","pt":1719504583840,"mc":[{"id":"1.230178325","rc":[{"atb":[[1.55,1],[1.66,0]],"id":69769647}],"con":true,"img":false}]}
{"op":"mcm","clk":"11541328939","pt":1719504589065,"mc":[{"id":"1.230178325","rc":[{"atl":[[5.8,1],[5.3,0]],"id":63579394},{"atl":[[7.4,1],[6.6,0]],"id":57055802},{"atl":[[5.1,1],[4.6,0]],"id":40626946}],"con":true,"img":false}]}
{"op":"mcm","clk":"11541329001","pt":1719504589745,"mc":[{"id":"1.230178325","rc":[{"atb":[[1.71,0]],"id":63579394},{"atl":[[18.5,0]],"id":63579394},{"atb":[[1.5,0]],"id":69769647},{"atl":[[10,0]],"id":69769647},{"atb":[[1.26,0]],"id":40626946},{"atl":[[9,0]],"id":40626946}],"con":true,"img":false}]}
{"op":"mcm","clk":"11541329107","pt":1719504590933,"mc":[{"id":"1.230178325","rc":[{"atl":[[4,1],[3.7,0]],"id":70902602},{"atl":[[3.85,1],[4.2,0]],"id":69769647}],"con":true,"img":false}]}
{"op":"mcm","clk":"11541329287","pt":1719504593161,"mc":[{"id":"1.230178325","rc":[{"atb":[[1.53,7.45]],"id":70902602}],"con":true,"img":false}]}
{"op":"mcm","clk":"11541329308","pt":1719504593366,"mc":[{"id":"1.230178325","rc":[{"atb":[[1.54,2.48],[1.51,0]],"id":70902602}],"con":true,"img":false}]}
{"op":"mcm","clk":"11541329535","pt":1719504595860,"mc":[{"id":"1.230178325","rc":[{"atb":[[1.56,2.11]],"id":70902602}],"con":true,"img":false}]}
{"op":"mcm","clk":"11541329560","pt":1719504596066,"mc":[{"id":"1.230178325","rc":[{"atb":[[1.56,4.59],[1.54,0]],"id":70902602}],"con":true,"img":false}]}
{"op":"mcm","clk":"11541329571","pt":1719504596166,"mc":[{"id":"1.230178325","rc":[{"atb":[[1.56,2.11],[1.54,3.12]],"id":70902602}],"con":true,"img":false}]}
{"op":"mcm","clk":"11541329579","pt":1719504596270,"mc":[{"id":"1.230178325","rc":[{"atb":[[1.56,6.71],[1.54,0]],"id":70902602}],"con":true,"img":false}]}
{"op":"mcm","clk":"11541329592","pt":1719504596376,"mc":[{"id":"1.230178325","rc":[{"atb":[[1.56,2.11],[1.54,3.12]],"id":70902602}],"con":true,"img":false}]}
{"op":"mcm","clk":"11541329601","pt":1719504596437,"mc":[{"id":"1.230178325","rc":[{"atb":[[1.56,8.83],[1.54,0]],"id":70902602}],"con":true,"img":false}]}
{"op":"mcm","clk":"11541330181","pt":1719504603066,"mc":[{"id":"1.230178325","rc":[{"spn":2.79,"spf":"NaN","id":70902602},{"spn":3.91,"spf":"NaN","id":63579394},{"atb":[[1.59,1],[1.55,0]],"id":69769647},{"spn":2.72,"spf":"NaN","id":69769647},{"spn":4.9,"spf":"NaN","id":57055802},{"spn":3.44,"spf":"NaN","id":40626946},{"spn":3.66,"spf":"NaN","id":45129701}],"con":true,"img":false}]}
{"op":"mcm","clk":"11541330201","pt":1719504603273,"mc":[{"id":"1.230178325","rc":[{"atl":[[5.1,0],[4.9,1]],"id":40626946}],"con":true,"img":false}]}
{"op":"mcm","clk":"11541330278","pt":1719504604162,"mc":[{"id":"1.230178325","rc":[{"atb":[[1.02,13.23]],"id":69769647}],"con":true,"img":false}]}
{"op":"mcm","clk":"11541330294","pt":1719504604366,"mc":[{"id":"1.230178325","rc":[{"atb":[[1.59,0],[1.55,1]],"id":69769647}],"con":true,"img":false}]}
{"op":"mcm","clk":"11541330309","pt":1719504604469,"mc":[{"id":"1.230178325","rc":[{"atb":[[1.02,2]],"id":63579394}],"con":true,"img":false}]}
{"op":"mcm","clk":"11541330318","pt":1719504604580,"mc":[{"id":"1.230178325","rc":[{"atb":[[1.55,0]],"id":69769647}],"con":true,"img":false}]}
{"op":"mcm","clk":"11541330338","pt":1719504604787,"mc":[{"id":"1.230178325","rc":[{"atb":[[1.02,2]],"id":40626946}],"con":true,"img":false}]}
{"op":"mcm","clk":"11541330362","pt":1719504604948,"mc":[{"id":"1.230178325","rc":[{"atb":[[1.02,13.23]],"id":45129701}],"con":true,"img":false}]}
{"op":"mcm","clk":"11541330400","pt":1719504605268,"mc":[{"id":"1.230178325","rc":[{"atb":[[1.02,2]],"id":70902602}],"con":true,"img":false}]}
{"op":"mcm","clk":"11541330430","pt":1719504605569,"mc":[{"id":"1.230178325","rc":[{"atb":[[1.02,2]],"id":57055802}],"con":true,"img":false}]}
{"op":"mcm","clk":"11541330589","pt":1719504607082,"mc":[{"id":"1.230178325","rc":[{"atb":[[1.55,1]],"id":69769647}],"con":true,"img":false}]}
{"op":"mcm","clk":"11541330892","pt":1719504610366,"mc":[{"id":"1.230178325","rc":[{"atl":[[5.1,1],[4.9,0]],"id":40626946}],"con":true,"img":false}]}
{"op":"mcm","clk":"11541331108","pt":1719504612986,"mc":[{"id":"1.230178325","rc":[{"atb":[[1.53,0]],"id":70902602}],"con":true,"img":false}]}
{"op":"mcm","clk":"11541331157","pt":1719504613572,"mc":[{"id":"1.230178325","rc":[{"atb":[[1.58,6.81]],"id":70902602}],"con":true,"img":false}]}
{"op":"mcm","clk":"11541331165","pt":1719504613674,"mc":[{"id":"1.230178325","rc":[{"atb":[[1.02,0]],"id":70902602}],"con":true,"img":false}]}
{"op":"mcm","clk":"11541331173","pt":1719504613768,"mc":[{"id":"1.230178325","rc":[{"atb":[[1.56,2.11],[1.59,7.81],[1.57,2]],"id":70902602}],"con":true,"img":false}]}
{"op":"mcm","clk":"11541331406","pt":1719504616168,"mc":[{"id":"1.230178325","rc":[{"atb":[[1.57,0]],"id":70902602}],"con":true,"img":false}]}
{"op":"mcm","clk":"11541331412","pt":1719504616273,"mc":[{"id":"1.230178325","rc":[{"atb":[[1.6,2]],"id":70902602}],"con":true,"img":false}]}
{"op":"mcm","clk":"11541331587","pt":1719504618872,"mc":[{"id":"1.230178325","rc":[{"atb":[[1.09,0]],"id":63579394},{"atb":[[1.09,0]],"id":57055802},{"atb":[[1.09,0]],"id":45129701}],"con":true,"img":false}]}
{"op":"mcm","clk":"11541331678","pt":1719504620187,"mc":[{"id":"1.230178325","rc":[{"atb":[[1.06,2.5]],"id":57055802},{"atb":[[1.06,2.5]],"id":45129701}],"con":true,"img":false}]}
{"op":"mcm","clk":"11541331696","pt":1719504620478,"mc":[{"id":"1.230178325","rc":[{"atb":[[1.59,1],[1.55,0]],"id":69769647}],"con":true,"img":false}]}
{"op":"mcm","clk":"11541331710","pt":1719504620677,"mc":[{"id":"1.230178325","rc":[{"atl":[[5.1,0],[4.9,1]],"id":40626946}],"con":true,"img":false}]}
{"op":"mcm","clk":"11541331894","pt":1719504623181,"mc":[{"id":"1.230178325","rc":[{"atb":[[1.06,0]],"id":57055802},{"atb":[[1.06,0]],"id":45129701}],"con":true,"img":false}]}
{"op":"mcm","clk":"11541332454","pt":1719504629688,"mc":[{"id":"1.230178325","rc":[{"atb":[[1.57,0],[1.55,3]],"id":69769647}],"con":true,"img":false}]}
{"op":"mcm","clk":"11541332467","pt":1719504629792,"mc":[{"id":"1.230178325","rc":[{"atb":[[1.59,3],[1.55,0]],"id":69769647}],"con":true,"img":false}]}
{"op":"mcm","clk":"11541332541","pt":1719504630583,"mc":[{"id":"1.230178325","rc":[{"atb":[[1.58,0]],"id":70902602}],"con":true,"img":false}]}
{"op":"mcm","clk":"11541332571","pt":1719504630895,"mc":[{"id":"1.230178325","rc":[{"atb":[[1.62,6.37]],"id":70902602}],"con":true,"img":false}]}
{"op":"mcm","clk":"11541332577","pt":1719504631024,"mc":[{"id":"1.230178325","rc":[{"atb":[[1.59,1]],"id":70902602}],"con":true,"img":false}]}
{"op":"mcm","clk":"11541332584","pt":1719504631116,"mc":[{"id":"1.230178325","rc":[{"atb":[[1.63,6.37]],"id":70902602}],"con":true,"img":false}]}
{"op":"mcm","clk":"11541332612","pt":1719504631369,"mc":[{"id":"1.230178325","rc":[{"atb":[[1.6,0]],"id":70902602}],"con":true,"img":false}]}
{"op":"mcm","clk":"11541332622","pt":1719504631474,"mc":[{"id":"1.230178325","rc":[{"atb":[[1.63,8.37]],"id":70902602}],"con":true,"img":false}]}
{"op":"mcm","clk":"11541333062","pt":1719504636302,"mc":[{"id":"1.230178325","rc":[{"atl":[[4,0],[3.95,1]],"id":70902602},{"atl":[[5.8,0],[5.7,1]],"id":63579394},{"atl":[[4,1],[3.85,0]],"id":69769647},{"atl":[[7.2,1],[7.4,0]],"id":57055802}],"con":true,"img":false}]}
{"op":"mcm","clk":"11541333075","pt":1719504636407,"mc":[{"id":"1.230178325","rc":[{"atl":[[10.5,3],[9.8,0]],"id":69769647}],"con":true,"img":false}]}
{"op":"mcm","clk":"11541334088","pt":1719504648713,"mc":[{"id":"1.230178325","rc":[{"atb":[[1.62,0]],"id":70902602}],"con":true,"img":false}]}
{"op":"mcm","clk":"11541334163","pt":1719504649609,"mc":[{"id":"1.230178325","rc":[{"atb":[[1.65,6.07]],"id":70902602}],"con":true,"img":false}]}
{"op":"mcm","clk":"11541334171","pt":1719504649709,"mc":[{"id":"1.230178325","rc":[{"atb":[[1.63,2],[1.66,6.08]],"id":70902602}],"con":true,"img":false}]}
{"op":"mcm","clk":"11541334322","pt":1719504651320,"mc":[{"id":"1.230178325","rc":[{"atb":[[1.63,0]],"id":70902602}],"con":true,"img":false}]}
{"op":"mcm","clk":"11541334336","pt":1719504651420,"mc":[{"id":"1.230178325","rc":[{"atb":[[1.67,2]],"id":70902602}],"con":true,"img":false}]}
{"op":"mcm","clk":"11541335529","pt":1719504664816,"mc":[{"id":"1.230178325","rc":[{"spn":2.81,"spf":"NaN","id":70902602},{"atb":[[1.01,1.7]],"id":63579394},{"atl":[[1000,1.87]],"id":63579394},{"spn":3.86,"spf":"NaN","id":63579394},{"atb":[[1.01,1.7]],"id":69769647},{"atl":[[1000,1.7]],"id":69769647},{"spn":2.79,"spf":"NaN","id":69769647},{"spn":4.8,"spf":"NaN","id":57055802},{"atb":[[1.01,1.7]],"id":40626946},{"atl":[[1000,1.87]],"id":40626946},{"spn":3.34,"spf":"NaN","id":40626946}],"con":true,"img":false}]}
{"op":"mcm","clk":"11541335537","pt":1719504664916,"mc":[{"id":"1.230178325","rc":[{"atb":[[1.01,0.4]],"id":63579394}],"con":true,"img":false}]}
{"op":"mcm","clk":"11541335538","pt":1719504665019,"mc":[{"id":"1.230178325","rc":[{"atl":[[1000,0.19]],"id":63579394},{"atb":[[1.01,0.51]],"id":69769647},{"atl":[[1000,0.03]],"id":69769647},{"atb":[[1.01,0.85]],"id":40626946},{"atl":[[1000,0.21]],"id":40626946}],"con":true,"img":false}]}
{"op":"mcm","clk":"11541335549","pt":1719504665124,"mc":[{"id":"1.230178325","rc":[{"atb":[[1.01,0]],"id":63579394}],"con":true,"img":false}]}
{"op":"mcm","clk":"11541335558","pt":1719504665229,"mc":[{"id":"1.230178325","rc":[{"atb":[[1.75,0.4]],"id":63579394},{"atl":[[1000,0]],"id":69769647},{"atb":[[1.01,0]],"id":40626946}],"con":true,"img":false}]}
{"op":"mcm","clk":"11541335567","pt":1719504665328,"mc":[{"id":"1.230178325","rc":[{"atl":[[1000,0.17]],"id":63579394},{"atb":[[1.01,0]],"id":69769647},{"atl":[[10,0.03]],"id":69769647},{"atb":[[1.36,0.85]],"id":40626946},{"atl":[[1000,0.17]],"id":40626946}],"con":true,"img":false}]}
{"op":"mcm","clk":"11541335574","pt":1719504665436,"mc":[{"id":"1.230178325","rc":[{"atl":[[16.5,0.01]],"id":63579394},{"atb":[[1.6,0.51]],"id":69769647},{"atl":[[8.4,0.04]],"id":40626946}],"con":true,"img":false}]}
{"op":"mcm","clk":"11541335701","pt":1719504666939,"mc":[{"id":"1.230178325","rc":[{"atb":[[1.65,0]],"id":70902602}],"con":true,"img":false}]}
{"op":"mcm","clk":"11541335722","pt":1719504667147,"mc":[{"id":"1.230178325","rc":[{"atb":[[1.69,5.73]],"id":70902602}],"con":true,"img":false}]}
{"op":"mcm","clk":"11541335732","pt":1719504667249,"mc":[{"id":"1.230178325","rc":[{"atb":[[1.7,5.73],[1.66,0]],"id":70902602}],"con":true,"img":false}]}
{"op":"mcm","clk":"11541335961","pt":1719504669220,"mc":[{"id":"1.230178325","rc":[{"atb":[[1.67,0]],"id":70902602}],"con":true,"img":false}]}
{"op":"mcm","clk":"11541335968","pt":1719504669322,"mc":[{"id":"1.230178325","rc":[{"atb":[[1.71,2]],"id":70902602}],"con":true,"img":false}]}
{"op":"mcm","clk":"11541339264","pt":1719504707789,"mc":[{"id":"1.230178325","rc":[{"atb":[[1.75,0]],"id":63579394},{"atl":[[16.5,0]],"id":63579394},{"atb":[[1.6,0]],"id":69769647},{"atl":[[10,0]],"id":69769647},{"atb":[[1.36,0]],"id":40626946},{"atl":[[8.4,0]],"id":40626946}],"con":true,"img":false}]}
{"op":"mcm","clk":"11541340369","pt":1719504720301,"mc":[{"id":"1.230178325","rc":[{"atb":[[1.71,5.75]],"id":70902602},{"atl":[[3.9,3.75]],"id":70902602}],"con":true,"img":false}]}
{"op":"mcm","clk":"11541340380","pt":1719504720405,"mc":[{"id":"1.230178325","rc":[{"atb":[[1.99,5],[2.06,2.5],[1.95,10]],"id":70902602},{"atl":[[5.1,2.5],[5.5,5],[5.9,10]],"id":70902602},{"atb":[[2.36,10],[2.52,2.5],[2.04,1.5],[2.44,5]],"id":63579394},{"atl":[[5.6,1.5],[6.2,5],[5.7,3.5],[7,10]],"id":63579394},{"atb":[[1.6,2.61],[1.67,10],[1.75,2.5],[1.71,5]],"id":69769647},{"atl":[[4.8,2.5],[5.6,10],[3.95,2.61],[5.2,5]],"id":69769647},{"atb":[[2.52,5],[2.6,2.5],[2.44,10],[2.48,1.5]],"id":57055802},{"atl":[[8.6,2.5],[10.5,10],[7,1.5],[9.4,5]],"id":57055802},{"atb":[[1.89,2.5],[1.81,10],[1.85,5],[1.78,2.5]],"id":40626946},{"atl":[[4.8,1.5],[6.4,10],[5.8,5],[5.4,2.5]],"id":40626946},{"atb":[[2.54,2.5],[2.38,10],[2.04,1.5],[2.46,5]],"id":45129701},{"atl":[[8,10],[7.2,5],[6.4,2.5],[5.2,1.5]],"id":45129701}],"con":true,"img":false}]}
{"op":"mcm","clk":"11541340391","pt":1719504720509,"mc":[{"id":"1.230178325","rc":[{"atb":[[1.7,0],[1.91,5.73]],"id":70902602},{"atl":[[5.1,7.25],[9,0]],"id":70902602},{"atb":[[1.59,1]],"id":69769647},{"atl":[[10.5,0]],"id":69769647},{"atb":[[2.1,0],[2.48,3.5]],"id":57055802},{"atl":[[44,0],[9.4,7]],"id":57055802},{"atb":[[1.81,0],[2.38,12]],"id":45129701},{"atl":[[6.4,4.5],[22,0]],"id":45129701}],"con":true,"img":false}]}
{"op":"mcm","clk":"11541340401","pt":1719504720615,"mc":[{"id":"1.230178325","rc":[{"atb":[[1.74,0],[2.26,2]],"id":63579394},{"atl":[[17,0],[6.2,7]],"id":63579394},{"atb":[[1.67,12.48]],"id":69769647},{"atl":[[4.8,4.5]],"id":69769647},{"atb":[[1.74,2],[1.35,0]],"id":40626946},{"atl":[[8.6,0],[5.4,4.5]],"id":40626946}],"con":true,"img":false}]}
{"op":"mcm","clk":"11541340416","pt":1719504720821,"mc":[{"id":"1.230178325","rc":[{"atl":[[3.85,0.84]],"id":70902602},{"atl":[[3.9,0.84]],"id":69769647}],"con":true,"img":false}]}
{"op":"mcm","clk":"11541340434","pt":1719504721030,"mc":[{"id":"1.230178325","rc":[{"atl":[[5.1,2.5],[3.95,6]],"id":70902602},{"atl":[[4.8,2.5],[4.1,5]],"id":69769647}],"con":true,"img":false}]}
{"op":"mcm","clk":"11541340443","pt":1719504721136,"mc":[{"id":"1.230178325","rc":[{"atb":[[1.02,11.23]],"id":69769647}],"con":true,"img":false}]}
{"op":"mcm","clk":"11541340453","pt":1719504721189,"mc":[{"id":"1.230178325","rc":[{"atb":[[1.76,2]],"id":69769647}],"con":true,"img":false}]}
{"op":"mcm","clk":"11541340464","pt":1719504721293,"mc":[{"id":"1.230178325","rc":[{"atb":[[1.67,10],[1.76,4.5]],"id":69769647}],"con":true,"img":false}]}
{"op":"mcm","clk":"11541340482","pt":1719504721502,"mc":[{"id":"1.230178325","rc":[{"atb":[[1.02,0]],"id":63579394}],"con":true,"img":false}]}
{"op":"mcm","clk":"11541340491","pt":1719504721606,"mc":[{"id":"1.230178325","rc":[{"atb":[[2.54,2]],"id":63579394}],"con":true,"img":false}]}
{"op":"mcm","clk":"11541340506","pt":1719504721812,"mc":[{"id":"1.230178325","rc":[{"atb":[[1.02,0]],"id":40626946}],"con":true,"img":false}]}
{"op":"mcm","clk":"11541340514","pt":1719504721914,"mc":[{"id":"1.230178325","rc":[{"atb":[[1.9,2]],"id":40626946}],"con":true,"img":false}]}
{"op":"mcm","clk":"11541340523","pt":1719504722018,"mc":[{"id":"1.230178325","rc":[{"atb":[[2.42,2.11]],"id":63579394},{"atb":[[1.74,2.11]],"id":69769647},{"atb":[[2.54,2.11]],"id":57055802},{"atb":[[1.84,2.11]],"id":40626946},{"atb":[[2.44,2.11]],"id":45129701}],"con":true,"img":false}]}
{"op":"mcm","clk":"11541340539","pt":1719504722226,"mc":[{"id":"1.230178325","rc":[{"atb":[[2.54,7.11],[2.48,1.5]],"id":57055802}],"con":true,"img":false}]}
{"op":"mcm","clk":"11541340552","pt":1719504722298,"mc":[{"id":"1.230178325","rc":[{"atb":[[2.54,2.11],[2.52,10]],"id":57055802},{"atb":[[1.02,11.23]],"id":45129701}],"con":true,"img":false}]}
{"op":"mcm","clk":"11541340559","pt":1719504722390,"mc":[{"id":"1.230178325","rc":[{"atb":[[2.56,2]],"id":45129701}],"con":true,"img":false}]}
{"op":"mcm","clk":"11541340595","pt":1719504722801,"mc":[{"id":"1.230178325","rc":[{"atb":[[1.71,3.75]],"id":70902602}],"con":true,"img":false}]}
{"op":"mcm","clk":"11541340605","pt":1719504722904,"mc":[{"id":"1.230178325","rc":[{"atb":[[2.08,2]],"id":70902602}],"con":true,"img":false}]}
{"op":"mcm","clk":"11541340636","pt":1719504723218,"mc":[{"id":"1.230178325","rc":[{"atb":[[1.02,0]],"id":57055802}],"con":true,"img":false}]}
{"op":"mcm","clk":"11541340645","pt":1719504723323,"mc":[{"id":"1.230178325","rc":[{"atb":[[2.62,2]],"id":57055802}],"con":true,"img":false}]}
{"op":"mcm","clk":"11541340664","pt":1719504723493,"mc":[{"id":"1.230178325","rc":[{"atb":[[2.52,5],[2.62,4.12]],"id":57055802}],"con":true,"img":false}]}
{"op":"mcm","clk":"11541341153","pt":1719504728919,"mc":[{"id":"1.230178325","rc":[{"spn":2.96,"spf":"NaN","id":70902602},{"spn":4.07,"spf":"NaN","id":63579394},{"spn":2.83,"spf":"NaN","id":69769647},{"spn":4.81,"spf":"NaN","id":57055802},{"spn":3.35,"spf":"NaN","id":40626946},{"atb":[[2.42,4.62],[2.38,10]],"id":45129701},{"spn":3.88,"spf":"NaN","id":45129701}],"con":true,"img":false}]}
{"op":"mcm","clk":"11541341886","pt":1719504737796,"mc":[{"id":"1.230178325","rc":[{"atb":[[2.08,6.69]],"id":70902602},{"atl":[[3.85,5.53]],"id":70902602}],"con":true,"img":false}]}
{"op":"mcm","clk":"11541341898","pt":1719504737896,"mc":[{"id":"1.230178325","rc":[{"atb":[[1.71,0]],"id":70902602},{"atl":[[3.9,0]],"id":70902602},{"atb":[[1.76,7.96]],"id":69769647},{"atl":[[3.9,4.3]],"id":69769647},{"atb":[[2.64,3.46]],"id":57055802},{"atb":[[1.9,5.38]],"id":40626946},{"atb":[[2.56,5.38]],"id":45129701}],"con":true,"img":false}]}
{"op":"mcm","clk":"11541341906","pt":1719504738049,"mc":[{"id":"1.230178325","rc":[{"atl":[[5.1,14.04],[3.95,1]],"id":70902602},{"atb":[[2.54,6.5]],"id":63579394},{"atb":[[1.6,0],[1.75,11.5],[1.76,5.46]],"id":69769647},{"atl":[[3.95,0]],"id":69769647},{"atb":[[2.48,0]],"id":57055802},{"atb":[[1.78,1]],"id":40626946},{"atb":[[2.04,0]],"id":45129701}],"con":true,"img":false}]}
{"op":"mcm","clk":"11541341925","pt":1719504738209,"mc":[{"id":"1.230178325","rc":[{"atb":[[2.04,0]],"id":63579394}],"con":true,"img":false}]}
{"op":"mcm","clk":"11541341937","pt":1719504738317,"mc":[{"id":"1.230178325","rc":[{"atb":[[1.84,0],[1.88,2.11]],"id":40626946},{"atb":[[2.52,2.11],[2.44,0]],"id":45129701}],"con":true,"img":false}]}
{"op":"mcm","clk":"11541341959","pt":1719504738621,"mc":[{"id":"1.230178325","rc":[{"atb":[[2.62,2.12]],"id":57055802}],"con":true,"img":false}]}
{"op":"mcm","clk":"11541341971","pt":1719504738724,"mc":[{"id":"1.230178325","rc":[{"atb":[[2.66,2]],"id":57055802}],"con":true,"img":false}]}
{"op":"mcm","clk":"11541341980","pt":1719504738827,"mc":[{"id":"1.230178325","rc":[{"atb":[[2.6,8.08],[2.62,0]],"id":57055802}],"con":true,"img":false}]}
{"op":"mcm","clk":"11541341990","pt":1719504738932,"mc":[{"id":"1.230178325","rc":[{"atb":[[2.66,4.12],[2.6,2.5]],"id":57055802}],"con":true,"img":false}]}
{"op":"mcm","clk":"11541342006","pt":1719504739140,"mc":[{"id":"1.230178325","rc":[{"atb":[[2.66,2],[2.6,7.96]],"id":57055802}],"con":true,"img":false}]}
{"op":"mcm","clk":"11541342028","pt":1719504739347,"mc":[{"id":"1.230178325","rc":[{"atb":[[2.66,5.46],[2.6,2.5]],"id":57055802}],"con":true,"img":false}]}
{"op":"mcm","clk":"11541342573","pt":1719504745105,"mc":[{"id":"1.230178325","rc":[{"atb":[[1.59,0]],"id":69769647}],"con":true,"img":false}]}
{"op":"mcm","clk":"11541342620","pt":1719504745613,"mc":[{"id":"1.230178325","rc":[{"atl":[[4.9,0]],"id":40626946}],"con":true,"img":false}]}
{"op":"mcm","clk":"11541342631","pt":1719504745718,"mc":[{"id":"1.230178325","rc":[{"atl":[[5.1,1]],"id":40626946}],"con":true,"img":false}]}
{"op":"mcm","clk":"11541342651","pt":1719504745925,"mc":[{"id":"1.230178325","rc":[{"atl":[[4.8,0]],"id":40626946}],"con":true,"img":false}]}
{"op":"mcm","clk":"11541342660","pt":1719504746026,"mc":[{"id":"1.230178325","rc":[{"atl":[[5,3.46]],"id":40626946}],"con":true,"img":false}]}
{"op":"mcm","clk":"11541342670","pt":1719504746128,"mc":[{"id":"1.230178325","rc":[{"atl":[[4.9,3.46],[5.4,2.5]],"id":40626946}],"con":true,"img":false}]}
{"op":"mcm","clk":"11541342687","pt":1719504746337,"mc":[{"id":"1.230178325","rc":[{"atl":[[5.1,7.92],[4.9,0.84]],"id":40626946}],"con":true,"img":false}]}
{"op":"mcm","clk":"11541342864","pt":1719504748418,"mc":[{"id":"1.230178325","rc":[{"atb":[[1.88,3.11],[1.78,0]],"id":40626946}],"con":true,"img":false}]}
{"op":"mcm","clk":"11541342911","pt":1719504748927,"mc":[{"id":"1.230178325","rc":[{"atb":[[1.7,1]],"id":69769647},{"atl":[[4,0],[4.2,1]],"id":69769647},{"atb":[[1.88,2.11]],"id":40626946}],"con":true,"img":false}]}
{"op":"mcm","clk":"11541342923","pt":1719504749031,"mc":[{"id":"1.230178325","rc":[{"atl":[[4.1,0],[4.2,10.31]],"id":69769647}],"con":true,"img":false}]}
{"op":"mcm","clk":"11541342966","pt":1719504749647,"mc":[{"id":"1.230178325","rc":[{"atb":[[1.85,11.46],[1.91,0]],"id":70902602},{"atb":[[1.74,0],[1.68,7.5]],"id":40626946},{"atb":[[2.32,9.62],[2.42,0]],"id":45129701}],"con":true,"img":false}]}
{"op":"mcm","clk":"11541343025","pt":1719504750423,"mc":[{"id":"1.230178325","rc":[{"atb":[[2.5,2.11]],"id":63579394}],"con":true,"img":false}]}
{"op":"mcm","clk":"11541343031","pt":1719504750531,"mc":[{"id":"1.230178325","rc":[{"atb":[[2.42,0]],"id":63579394}],"con":true,"img":false}]}
{"op":"mcm","clk":"11541343050","pt":1719504750730,"mc":[{"id":"1.230178325","rc":[{"atl":[[5.3,1],[5.7,2.5]],"id":63579394},{"atl":[[3.85,6.53],[3.95,0]],"id":70902602},{"atl":[[7.2,0],[6.6,1]],"id":57055802}],"con":true,"img":false}]}
{"op":"mcm","clk":"11541343059","pt":1719504750833,"mc":[{"id":"1.230178325","rc":[{"atl":[[6.2,5],[5.5,3.46],[5.7,9.5]],"id":63579394},{"atl":[[6.8,3]],"id":57055802}],"con":true,"img":false}]}
{"op":"mcm","clk":"11541343076","pt":1719504751039,"mc":[{"id":"1.230178325","rc":[{"atl":[[5.6,0]],"id":63579394},{"atl":[[7,0]],"id":57055802}],"con":true,"img":false}]}
{"op":"mcm","clk":"11541343101","pt":1719504751353,"mc":[{"id":"1.230178325","rc":[{"atb":[[2.36,0],[2.54,2],[2.52,0],[2.44,0]],"id":63579394},{"atl":[[6.2,0],[5.5,0],[5.7,7],[7,0]],"id":63579394},{"atb":[[1.99,0],[2.06,0],[1.95,0],[2.08,1.99]],"id":70902602},{"atl":[[5.1,11.54],[3.85,1.84],[5.5,0],[5.9,0]],"id":70902602},{"atb":[[1.67,0],[1.75,9],[1.71,0],[1.76,2]],"id":69769647},{"atl":[[4.8,0],[5.6,0],[5.2,0],[3.9,0.84]],"id":69769647},{"atb":[[2.52,0],[2.64,0],[2.6,0],[2.44,0]],"id":57055802},{"atl":[[8.6,0],[10.5,0],[6.8,0],[9.4,2]],"id":57055802},{"atb":[[1.89,0],[1.81,0],[1.85,0],[1.9,2]],"id":40626946},{"atl":[[6.4,0],[5,0],[5.8,0],[5.4,0]],"id":40626946},{"atb":[[2.56,2],[2.54,0],[2.38,0],[2.46,0]],"id":45129701},{"atl":[[8,0],[7.2,0],[6.4,2],[5.2,0]],"id":45129701}],"con":true,"img":false}]}
{"op":"mcm","clk":"11541343111","pt":1719504751421,"mc":[{"id":"1.230178325","rc":[{"atl":[[5.1,0],[5.5,13.39]],"id":70902602}],"con":true,"img":false}]}
{"op":"mcm","clk":"11541343117","pt":1719504751510,"mc":[{"id":"1.230178325","rc":[{"atl":[[9.6,11.63],[5.5,0]],"id":70902602}],"con":true,"img":false}]}
{"op":"mcm","clk":"11541343146","pt":1719504751828,"mc":[{"id":"1.230178325","rc":[{"atl":[[3.9,0]],"id":69769647},{"atl":[[4.9,0]],"id":40626946}],"con":true,"img":false}]}
{"op":"mcm","clk":"11541343164","pt":1719504752037,"mc":[{"id":"1.230178325","rc":[{"atl":[[9.4,11.9]],"id":40626946}],"con":true,"img":false}]}
{"op":"mcm","clk":"11541343172","pt":1719504752139,"mc":[{"id":"1.230178325","rc":[{"atl":[[5.1,1]],"id":40626946}],"con":true,"img":false}]}
{"op":"mcm","clk":"11541343181","pt":1719504752236,"mc":[{"id":"1.230178325","rc":[{"atb":[[2.54,0]],"id":63579394}],"con":true,"img":false}]}
{"op":"mcm","clk":"11541343193","pt":1719504752342,"mc":[{"id":"1.230178325","rc":[{"atb":[[2.52,2]],"id":63579394},{"atl":[[18.5,5.71],[5.7,0]],"id":63579394},{"atl":[[4.1,0.84]],"id":69769647}],"con":true,"img":false}]}
{"op":"mcm","clk":"11541343228","pt":1719504752860,"mc":[{"id":"1.230178325","rc":[{"atb":[[1.7,0]],"id":69769647},{"atb":[[1.88,3.11],[1.9,0]],"id":40626946},{"atl":[[5.1,0],[4.6,1]],"id":40626946}],"con":true,"img":false}]}
{"op":"mcm","clk":"11541343239","pt":1719504752926,"mc":[{"id":"1.230178325","rc":[{"atb":[[1.89,2]],"id":40626946}],"con":true,"img":false}]}
{"op":"mcm","clk":"11541343266","pt":1719504753233,"mc":[{"id":"1.230178325","rc":[{"atb":[[2.56,0]],"id":45129701}],"con":true,"img":false}]}
{"op":"mcm","clk":"11541343272","pt":1719504753333,"mc":[{"id":"1.230178325","rc":[{"atb":[[2.54,2]],"id":45129701}],"con":true,"img":false}]}
{"op":"mcm","clk":"11541343280","pt":1719504753431,"mc":[{"id":"1.230178325","rc":[{"atl":[[6.4,0],[23,3]],"id":45129701}],"con":true,"img":false}]}
{"op":"mcm","clk":"11541343294","pt":1719504753643,"mc":[{"id":"1.230178325","rc":[{"atb":[[2.08,0]],"id":70902602}],"con":true,"img":false}]}
{"op":"mcm","clk":"11541343304","pt":1719504753744,"mc":[{"id":"1.230178325","rc":[{"atb":[[1.86,2]],"id":70902602}],"con":true,"img":false}]}
{"op":"mcm","clk":"11541343335","pt":1719504754160,"mc":[{"id":"1.230178325","rc":[{"atl":[[11.5,9.52],[4.2,1]],"id":69769647},{"atb":[[2.66,3.46]],"id":57055802}],"con":true,"img":false}]}
{"op":"mcm","clk":"11541343341","pt":1719504754222,"mc":[{"id":"1.230178325","rc":[{"atb":[[2.54,9.03],[1.02,2],[2.66,0]],"id":57055802},{"atl":[[50,2.04],[9.4,0]],"id":57055802}],"con":true,"img":false}]}
{"op":"mcm","clk":"11541343351","pt":1719504754323,"mc":[{"id":"1.230178325","rc":[{"atb":[[2.4,6.58],[2.54,2.11]],"id":57055802}],"con":true,"img":false}]}
{"op":"mcm","clk":"11541343367","pt":1719504754530,"mc":[{"id":"1.230178325","rc":[{"atb":[[2.4,1],[2.54,4.11]],"id":57055802}],"con":true,"img":false}]}
{"op":"mcm","clk":"11541343387","pt":1719504754733,"mc":[{"id":"1.230178325","rc":[{"atb":[[2.54,2.11],[1.97,8.7]],"id":57055802}],"con":true,"img":false}]}
{"op":"mcm","clk":"11541343395","pt":1719504754836,"mc":[{"id":"1.230178325","rc":[{"atb":[[2.54,4.11],[1.97,0]],"id":57055802}],"con":true,"img":false}]}
{"op":"mcm","clk":"11541343405","pt":1719504754938,"mc":[{"id":"1.230178325","rc":[{"atb":[[2.54,2.11],[1.97,3.12]],"id":57055802}],"con":true,"img":false}]}
{"op":"mcm","clk":"11541343445","pt":1719504755556,"mc":[{"id":"1.230178325","rc":[{"atb":[[1.69,0]],"id":70902602}],"con":true,"img":false}]}
{"op":"mcm","clk":"11541343478","pt":1719504755927,"mc":[{"id":"1.230178325","rc":[{"atl":[[3.85,0.84],[3.95,1]],"id":70902602},{"atl":[[7.2,1],[6.6,0]],"id":57055802},{"atl":[[4.6,0],[4.9,1]],"id":40626946}],"con":true,"img":false}]}
{"op":"mcm","clk":"11541343487","pt":1719504756029,"mc":[{"id":"1.230178325","rc":[{"atl":[[5.3,0],[5.7,1]],"id":63579394}],"con":true,"img":false}]}
{"op":"mcm","clk":"11541343517","pt":1719504756337,"mc":[{"id":"1.230178325","rc":[{"atl":[[3.85,0]],"id":70902602},{"atb":[[1.7,1]],"id":69769647},{"atb":[[1.88,2.11]],"id":40626946}],"con":true,"img":false}]}
{"op":"mcm","clk":"11541343526","pt":1719504756435,"mc":[{"id":"1.230178325","rc":[{"atl":[[3.85,1],[3.95,0]],"id":70902602},{"atl":[[5.3,1],[5.7,0]],"id":63579394},{"atl":[[7.2,0],[6.6,1]],"id":57055802},{"atl":[[4.6,1],[4.9,0]],"id":40626946}],"con":true,"img":false}]}
{"op":"mcm","clk":"11541343550","pt":1719504756745,"mc":[{"id":"1.230178325","rc":[{"atl":[[3.85,0],[3.9,1]],"id":70902602}],"con":true,"img":false}]}
{"op":"mcm","clk":"11541344124","pt":1719504762920,"mc":[{"id":"1.230178325","rc":[{"atb":[[2.54,4.23]],"id":57055802}],"con":true,"img":false}]}
{"op":"mcm","clk":"11541344136","pt":1719504763021,"mc":[{"id":"1.230178325","rc":[{"atb":[[1.97,0]],"id":57055802}],"con":true,"img":false}]}
{"op":"mcm","clk":"11541344867","pt":1719504772058,"mc":[{"id":"1.230178325","rc":[{"atl":[[3.85,1],[3.9,0]],"id":70902602}],"con":true,"img":false}]}
{"op":"mcm","clk":"11541344968","pt":1719504773168,"mc":[{"id":"1.230178325","rc":[{"atl":[[3.9,1]],"id":70902602}],"con":true,"img":false}]}
{"op":"mcm","clk":"11541344980","pt":1719504773272,"mc":[{"id":"1.230178325","rc":[{"atl":[[3.85,0]],"id":70902602}],"con":true,"img":false}]}
{"op":"mcm","clk":"11541345112","pt":1719504774530,"mc":[{"id":"1.230178325","rc":[{"atb":[[1.7,0]],"id":69769647}],"con":true,"img":false}]}
{"op":"mcm","clk":"11541345130","pt":1719504774736,"mc":[{"id":"1.230178325","rc":[{"atl":[[3.95,1],[3.9,0]],"id":70902602},{"atl":[[5.3,0],[5.7,1]],"id":63579394},{"atl":[[4,1]],"id":69769647},{"atl":[[7.2,1],[6.6,0]],"id":57055802},{"atl":[[5.1,1],[4.6,0]],"id":40626946}],"con":true,"img":false}]}
{"op":"mcm","clk":"11541345140","pt":1719504774839,"mc":[{"id":"1.230178325","rc":[{"atl":[[4.2,0]],"id":69769647}],"con":true,"img":false}]}
{"op":"mcm","clk":"11541345149","pt":1719504774944,"mc":[{"id":"1.230178325","rc":[{"atl":[[4.3,2],[11.5,0]],"id":69769647}],"con":true,"img":false}]}
{"op":"mcm","clk":"11541345476","pt":1719504778579,"mc":[{"id":"1.230178325","rc":[{"atb":[[1.7,1]],"id":69769647}],"con":true,"img":false}]}
{"op":"mcm","clk":"11541345772","pt":1719504781781,"mc":[{"id":"1.230178325","rc":[{"atb":[[1.7,0]],"id":69769647},{"atl":[[4,0],[4.2,1]],"id":69769647}],"con":true,"img":false}]}
{"op":"mcm","clk":"11541346012","pt":1719504784756,"mc":[{"id":"1.230178325","rc":[{"atl":[[5.1,0],[4.9,1]],"id":40626946}],"con":true,"img":false}]}
{"op":"mcm","clk":"11541346045","pt":1719504785173,"mc":[{"id":"1.230178325","rc":[{"atl":[[4,1],[4.2,0]],"id":69769647}],"con":true,"img":false}]}
{"op":"mcm","clk":"11541346088","pt":1719504785579,"mc":[{"id":"1.230178325","rc":[{"atb":[[1.02,1.7]],"id":63579394},{"atl":[[1000,1.87]],"id":63579394},{"atb":[[1.01,1.7]],"id":69769647},{"atl":[[1000,1.7]],"id":69769647},{"atb":[[1.01,1.7]],"id":40626946},{"atl":[[1000,1.87]],"id":40626946}],"con":true,"img":false}]}
{"op":"mcm","clk":"11541346112","pt":1719504785847,"mc":[{"id":"1.230178325","rc":[{"atb":[[1.02,0.19]],"id":63579394},{"atl":[[1000,0.19]],"id":63579394},{"atb":[[1.01,0.38]],"id":69769647},{"atl":[[1000,0.09]],"id":69769647},{"atb":[[1.01,0.32]],"id":40626946},{"atl":[[1000,0.21]],"id":40626946}],"con":true,"img":false}]}
{"op":"mcm","clk":"11541346122","pt":1719504785947,"mc":[{"id":"1.230178325","rc":[{"atb":[[1.7,1]],"id":69769647}],"con":true,"img":false}]}
{"op":"mcm","clk":"11541346137","pt":1719504786065,"mc":[{"id":"1.230178325","rc":[{"atb":[[1.02,0]],"id":63579394},{"atl":[[1000,0.17]],"id":63579394},{"atb":[[1.01,0]],"id":69769647},{"atl":[[1000,0]],"id":69769647},{"atb":[[1.01,0]],"id":40626946},{"atl":[[1000,0.17]],"id":40626946}],"con":true,"img":false}]}
{"op":"mcm","clk":"11541346146","pt":1719504786164,"mc":[{"id":"1.230178325","rc":[{"atb":[[2.54,0.19]],"id":63579394},{"atl":[[18,0.01]],"id":63579394},{"atb":[[1.77,0.38]],"id":69769647},{"atl":[[4,1.09]],"id":69769647},{"atb":[[1.9,0.32]],"id":40626946},{"atl":[[9.2,0.03]],"id":40626946}],"con":true,"img":false}]}
{"op":"mcm","clk":"11541346180","pt":1719504786478,"mc":[{"id":"1.230178325","rc":[{"atl":[[5.3,1],[5.7,0]],"id":63579394},{"atl":[[3.95,0],[3.9,1]],"id":70902602},{"atl":[[4,0.09],[4.2,1]],"id":69769647},{"atl":[[6.6,1]],"id":57055802},{"atl":[[4.6,1],[4.9,0]],"id":40626946}],"con":true,"img":false}]}
{"op":"mcm","clk":"11541346188","pt":1719504786583,"mc":[{"id":"1.230178325","rc":[{"atl":[[7.2,0]],"id":57055802}],"con":true,"img":false}]}
{"op":"mcm","clk":"11541346349","pt":1719504788258,"mc":[{"id":"1.230178325","rc":[{"atl":[[3.85,1],[3.9,0]],"id":70902602}],"con":true,"img":false}]}
{"op":"mcm","clk":"11541346425","pt":1719504789140,"mc":[{"id":"1.230178325","rc":[{"atl":[[3.9,1]],"id":70902602},{"spn":2.85,"spf":"NaN","id":70902602},{"spn":3.92,"spf":"NaN","id":63579394},{"spn":2.88,"spf":"NaN","id":69769647},{"spn":4.57,"spf":"NaN","id":57055802},{"spn":3.25,"spf":"NaN","id":40626946},{"spn":3.92,"spf":"NaN","id":45129701}],"con":true,"img":false}]}
{"op":"mcm","clk":"11541346434","pt":1719504789243,"mc":[{"id":"1.230178325","rc":[{"atl":[[3.85,0]],"id":70902602}],"con":true,"img":false}]}
{"op":"mcm","clk":"11541347406","pt":1719504801093,"mc":[{"id":"1.230178325","rc":[{"atl":[[3.95,1],[3.9,0]],"id":70902602}],"con":true,"img":false}]}
{"op":"mcm","clk":"11541347442","pt":1719504801467,"mc":[{"id":"1.230178325","rc":[{"atl":[[4,1],[3.95,0]],"id":70902602}],"con":true,"img":false}]}
{"op":"mcm","clk":"11541347644","pt":1719504803899,"mc":[{"id":"1.230178325","rc":[{"atl":[[5.2,2.34]],"id":63579394},{"atl":[[4.1,4.25]],"id":69769647},{"atl":[[4.5,2.04]],"id":40626946},{"atl":[[5.2,2.34]],"id":45129701}],"con":true,"img":false}]}
{"op":"mcm","clk":"11541347653","pt":1719504804007,"mc":[{"id":"1.230178325","rc":[{"atl":[[5.2,0],[5.7,3.34]],"id":63579394},{"atl":[[4,0],[8,1]],"id":70902602},{"atb":[[1.7,0]],"id":69769647},{"atl":[[4.1,0.84]],"id":69769647},{"atl":[[4.5,4.04],[9.4,0]],"id":40626946},{"atl":[[23,0],[5.2,0],[6.6,3.34]],"id":45129701}],"con":true,"img":false}]}
{"op":"mcm","clk":"11541347662","pt":1719504804074,"mc":[{"id":"1.230178325","rc":[{"atl":[[18.5,0]],"id":63579394},{"atl":[[4.5,2.04],[9.2,3.07]],"id":40626946}],"con":true,"img":false}]}
{"op":"mcm","clk":"11541347668","pt":1719504804169,"mc":[{"id":"1.230178325","rc":[{"atl":[[18,4.35],[5.7,0]],"id":63579394},{"atl":[[4.5,4.04],[9.2,0.03]],"id":40626946},{"atl":[[23,4.34],[6.6,0]],"id":45129701}],"con":true,"img":false}]}
{"op":"mcm","clk":"11541347675","pt":1719504804268,"mc":[{"id":"1.230178325","rc":[{"atl":[[4.4,0.84]],"id":40626946}],"con":true,"img":false}]}
{"op":"mcm","clk":"11541347681","pt":1719504804372,"mc":[{"id":"1.230178325","rc":[{"atl":[[8,0],[4,1]],"id":70902602},{"atb":[[1.7,1]],"id":69769647},{"atl":[[7.6,1.61]],"id":45129701}],"con":true,"img":false}]}
{"op":"mcm","clk":"11541347780","pt":1719504805564,"mc":[{"id":"1.230178325","rc":[{"atl":[[4,0],[4.1,1]],"id":70902602}],"con":true,"img":false}]}
{"op":"mcm","clk":"11541347789","pt":1719504805672,"mc":[{"id":"1.230178325","rc":[{"atl":[[9.6,0],[8,2]],"id":70902602}],"con":true,"img":false}]}
{"op":"mcm","clk":"11541347803","pt":1719504805877,"mc":[{"id":"1.230178325","rc":[{"atl":[[4,1],[4.1,0]],"id":70902602}],"con":true,"img":false}]}
{"op":"mcm","clk":"11541348103","pt":1719504809473,"mc":[{"id":"1.230178325","rc":[{"atl":[[4,0],[4.1,1]],"id":70902602}],"con":true,"img":false}]}
{"op":"mcm","clk":"11541348208","pt":1719504810872,"mc":[{"id":"1.230178325","rc":[{"atl":[[8,0],[9.6,3]],"id":70902602}],"con":true,"img":false}]}
{"op":"mcm","clk":"11541348280","pt":1719504811695,"mc":[{"id":"1.230178325","rc":[{"atl":[[23,0],[7.6,3.61]],"id":45129701}],"con":true,"img":false}]}
{"op":"mcm","clk":"11541349158","pt":1719504822629,"mc":[{"id":"1.230178325","rc":[{"atb":[[2.54,0]],"id":63579394},{"atl":[[18,4.34]],"id":63579394},{"atb":[[1.77,0]],"id":69769647},{"atl":[[4,0]],"id":69769647},{"atb":[[1.9,0]],"id":40626946},{"atl":[[9.2,0]],"id":40626946}],"con":true,"img":false}]}
{"op":"mcm","clk":"11541349835","pt":1719504830521,"mc":[{"id":"1.230178325","rc":[{"atb":[[1.88,4.48]],"id":70902602}],"con":true,"img":false}]}
{"op":"mcm","clk":"11541349932","pt":1719504831719,"mc":[{"id":"1.230178325","rc":[{"atb":[[1.86,0]],"id":70902602}],"con":true,"img":false}]}
{"op":"mcm","clk":"11541349942","pt":1719504831823,"mc":[{"id":"1.230178325","rc":[{"atb":[[1.89,2]],"id":70902602}],"con":true,"img":false}]}
{"op":"mcm","clk":"11541350299","pt":1719504836842,"mc":[{"id":"1.230178325","rc":[{"atl":[[4.1,0],[4.2,1]],"id":70902602}],"con":true,"img":false}]}
{"op":"mcm","clk":"11541350473","pt":1719504839343,"mc":[{"id":"1.230178325","rc":[{"atl":[[3.9,1],[4.2,0]],"id":70902602}],"con":true,"img":false}]}
{"op":"mcm","clk":"11541350483","pt":1719504839439,"mc":[{"id":"1.230178325","rc":[{"atl":[[4.2,2]],"id":70902602}],"con":true,"img":false}]}
{"op":"mcm","clk":"11541350499","pt":1719504839647,"mc":[{"id":"1.230178325","rc":[{"atl":[[9.6,0]],"id":70902602}],"con":true,"img":false}]}
{"op":"mcm","clk":"11541350712","pt":1719504842041,"mc":[{"id":"1.230178325","rc":[{"atl":[[3.85,1],[3.8,1],[3.9,0]],"id":70902602}],"con":true,"img":false}]}
{"op":"mcm","clk":"11541350745","pt":1719504842359,"mc":[{"id":"1.230178325","rc":[{"atl":[[3.85,0]],"id":70902602}],"con":true,"img":false}]}
{"op":"mcm","clk":"11541350977","pt":1719504844606,"mc":[{"id":"1.230178325","rc":[{"atl":[[9.6,3],[4.2,0]],"id":70902602}],"con":true,"img":false}]}
{"op":"mcm","clk":"11541351293","pt":1719504848238,"mc":[{"id":"1.230178325","rc":[{"atl":[[4.1,1],[3.8,0]],"id":70902602}],"con":true,"img":false}]}
{"op":"mcm","clk":"11541351953","pt":1719504855292,"mc":[{"id":"1.230178325","rc":[{"atb":[[1.08,50]],"id":70902602},{"spn":2.99,"spf":"NaN","id":70902602},{"atb":[[1.08,50]],"id":63579394},{"spn":3.91,"spf":"NaN","id":63579394},{"atb":[[1.08,50]],"id":69769647},{"spn":2.93,"spf":"NaN","id":69769647},{"atb":[[1.08,50]],"id":57055802},{"atb":[[1.08,50]],"id":40626946},{"spn":3.14,"spf":"NaN","id":40626946},{"atb":[[1.08,50]],"id":45129701}],"con":true,"img":false}]}
{"op":"mcm","clk":"11541354486","pt":1719504884224,"mc":[{"id":"1.230178325","rc":[{"atb":[[1.74,3.11]],"id":69769647},{"atb":[[2.4,0]],"id":57055802}],"con":true,"img":false}]}
{"op":"mcm","clk":"11541354494","pt":1719504884328,"mc":[{"id":"1.230178325","rc":[{"atb":[[1.7,0]],"id":69769647}],"con":true,"img":false}]}
{"op":"mcm","clk":"11541354684","pt":1719504886507,"mc":[{"id":"1.230178325","rc":[{"atb":[[1.07,4.48]],"id":57055802}],"con":true,"img":false}]}
{"op":"mcm","clk":"11541354799","pt":1719504887755,"mc":[{"id":"1.230178325","rc":[{"atl":[[5.3,0],[5.7,1]],"id":63579394},{"atb":[[1.07,2.48]],"id":57055802},{"atl":[[7.2,1],[6.6,0]],"id":57055802},{"atl":[[4.6,0],[4.9,1]],"id":40626946}],"con":true,"img":false}]}
{"op":"mcm","clk":"11541354807","pt":1719504887855,"mc":[{"id":"1.230178325","rc":[{"atb":[[1.74,2.11]],"id":69769647}],"con":true,"img":false}]}
{"op":"mcm","clk":"11541355927","pt":1719504901543,"mc":[{"id":"1.230178325","rc":[{"atl":[[4,1]],"id":70902602}],"con":true,"img":false}]}
{"op":"mcm","clk":"11541355938","pt":1719504901648,"mc":[{"id":"1.230178325","rc":[{"atl":[[4.1,0]],"id":70902602}],"con":true,"img":false}]}
{"op":"mcm","clk":"11541356308","pt":1719504905256,"mc":[{"id":"1.230178325","rc":[{"atb":[[1.91,4.33]],"id":40626946}],"con":true,"img":false}]}
{"op":"mcm","clk":"11541356337","pt":1719504905565,"mc":[{"id":"1.230178325","rc":[{"atl":[[4,0],[3.95,1]],"id":70902602}],"con":true,"img":false}]}
{"op":"mcm","clk":"11541356476","pt":1719504907042,"mc":[{"id":"1.230178325","rc":[{"atb":[[1.89,0]],"id":40626946}],"con":true,"img":false}]}
{"op":"mcm","clk":"11541356484","pt":1719504907144,"mc":[{"id":"1.230178325","rc":[{"atb":[[1.92,2]],"id":40626946}],"con":true,"img":false}]}
{"op":"mcm","clk":"11541356623","pt":1719504908547,"mc":[{"id":"1.230178325","rc":[{"atb":[[1.02,1.7]],"id":63579394},{"atl":[[1000,1.87]],"id":63579394},{"atb":[[1.01,1.7]],"id":69769647},{"atl":[[1000,1.7]],"id":69769647},{"atb":[[1.01,1.7]],"id":40626946},{"atl":[[1000,1.87]],"id":40626946}],"con":true,"img":false}]}
{"op":"mcm","clk":"11541356641","pt":1719504908758,"mc":[{"id":"1.230178325","rc":[{"atb":[[1.02,0.18]],"id":63579394},{"atl":[[1000,0.19]],"id":63579394},{"atb":[[1.01,0.36]],"id":69769647},{"atl":[[1000,0.09]],"id":69769647},{"atb":[[1.01,0.3]],"id":40626946},{"atl":[[1000,0.26]],"id":40626946}],"con":true,"img":false}]}
{"op":"mcm","clk":"11541356663","pt":1719504908966,"mc":[{"id":"1.230178325","rc":[{"atb":[[1.02,0]],"id":63579394},{"atl":[[1000,0.17]],"id":63579394},{"atb":[[1.01,0]],"id":69769647},{"atl":[[1000,0]],"id":69769647},{"atb":[[1.01,0]],"id":40626946},{"atl":[[1000,0.17]],"id":40626946}],"con":true,"img":false}]}
{"op":"mcm","clk":"11541356674","pt":1719504909068,"mc":[{"id":"1.230178325","rc":[{"atb":[[2.54,0.18]],"id":63579394},{"atl":[[17.5,0.01]],"id":63579394},{"atb":[[1.77,0.36]],"id":69769647},{"atl":[[4.1,0.93]],"id":69769647},{"atb":[[1.93,0.3]],"id":40626946},{"atl":[[4.4,0.93]],"id":40626946}],"con":true,"img":false}]}
{"op":"mcm","clk":"11541357207","pt":1719504915248,"mc":[{"id":"1.230178325","rc":[{"atb":[[1.19,3.8]],"id":57055802}],"con":true,"img":false}]}
{"op":"mcm","clk":"11541357752","pt":1719504922170,"mc":[{"id":"1.230178325","rc":[{"spn":4.12,"spf":"NaN","id":63579394},{"atb":[[1.88,0]],"id":70902602},{"spn":2.92,"spf":"NaN","id":70902602},{"spn":2.93,"spf":"NaN","id":69769647},{"spn":4.87,"spf":"NaN","id":57055802},{"spn":3.16,"spf":"NaN","id":40626946}],"con":true,"img":false}]}
{"op":"mcm","clk":"11541357802","pt":1719504922906,"mc":[{"id":"1.230178325","rc":[{"atb":[[1.89,0]],"id":70902602}],"con":true,"img":false}]}
{"op":"mcm","clk":"11541357811","pt":1719504922951,"mc":[{"id":"1.230178325","rc":[{"atb":[[1.86,2]],"id":70902602}],"con":true,"img":false}]}
{"op":"mcm","clk":"11541357821","pt":1719504923053,"mc":[{"id":"1.230178325","rc":[{"atb":[[1.57,12.46],[1.85,0]],"id":70902602}],"con":true,"img":false}]}
{"op":"mcm","clk":"11541357827","pt":1719504923157,"mc":[{"id":"1.230178325","rc":[{"atb":[[1.57,0],[1.85,4]],"id":70902602}],"con":true,"img":false}]}
{"op":"mcm","clk":"11541357995","pt":1719504925181,"mc":[{"id":"1.230178325","rc":[{"atb":[[1.91,0]],"id":40626946}],"con":true,"img":false}]}
{"op":"mcm","clk":"11541358002","pt":1719504925285,"mc":[{"id":"1.230178325","rc":[{"atb":[[1.88,4.48]],"id":70902602}],"con":true,"img":false}]}
{"op":"mcm","clk":"11541358048","pt":1719504926058,"mc":[{"id":"1.230178325","rc":[{"atb":[[1.92,0]],"id":40626946}],"con":true,"img":false}]}
{"op":"mcm","clk":"11541358056","pt":1719504926162,"mc":[{"id":"1.230178325","rc":[{"atb":[[1.89,2],[1.94,4.2]],"id":40626946}],"con":true,"img":false}]}
{"op":"mcm","clk":"11541358088","pt":1719504926676,"mc":[{"id":"1.230178325","rc":[{"atb":[[1.86,0]],"id":70902602}],"con":true,"img":false}]}
{"op":"mcm","clk":"11541358098","pt":1719504926779,"mc":[{"id":"1.230178325","rc":[{"atb":[[1.89,2]],"id":70902602}],"con":true,"img":false}]}
{"op":"mcm","clk":"11541358209","pt":1719504928596,"mc":[{"id":"1.230178325","rc":[{"atb":[[1.89,0]],"id":40626946}],"con":true,"img":false}]}
{"op":"mcm","clk":"11541358216","pt":1719504928701,"mc":[{"id":"1.230178325","rc":[{"atb":[[1.95,2]],"id":40626946}],"con":true,"img":false}]}
{"op":"mcm","clk":"11541358406","pt":1719504931188,"mc":[{"id":"1.230178325","rc":[{"atb":[[1.89,4.21]],"id":70902602},{"atb":[[2.52,4.98]],"id":63579394},{"atb":[[1.76,4.31]],"id":69769647},{"atb":[[2.56,2.7]],"id":57055802},{"atb":[[1.95,5]],"id":40626946},{"atb":[[2.54,4]],"id":45129701}],"con":true,"img":false}]}
{"op":"mcm","clk":"11541358415","pt":1719504931292,"mc":[{"id":"1.230178325","rc":[{"atb":[[1.77,4.67]],"id":69769647}],"con":true,"img":false}]}
{"op":"mcm","clk":"11541358423","pt":1719504931395,"mc":[{"id":"1.230178325","rc":[{"atb":[[1.75,0]],"id":69769647}],"con":true,"img":false}]}
{"op":"mcm","clk":"11541358451","pt":1719504931759,"mc":[{"id":"1.230178325","rc":[{"atb":[[1.76,2.31]],"id":69769647}],"con":true,"img":false}]}
{"op":"mcm","clk":"11541358459","pt":1719504931863,"mc":[{"id":"1.230178325","rc":[{"atb":[[1.78,2],[1.77,0.36],[1.76,11.67]],"id":69769647}],"con":true,"img":false}]}
{"op":"mcm","clk":"11541358467","pt":1719504931966,"mc":[{"id":"1.230178325","rc":[{"atb":[[1.19,0]],"id":57055802}],"con":true,"img":false}]}
{"op":"mcm","clk":"11541358509","pt":1719504932484,"mc":[{"id":"1.230178325","rc":[{"atb":[[1.74,3.11]],"id":69769647}],"con":true,"img":false}]}
{"op":"mcm","clk":"11541358526","pt":1719504932691,"mc":[{"id":"1.230178325","rc":[{"atl":[[3.85,1],[3.95,0]],"id":70902602},{"atl":[[5.3,1],[5.7,0]],"id":63579394},{"atl":[[7.2,0],[6.6,1]],"id":57055802},{"atl":[[4.6,1],[4.9,0]],"id":40626946}],"con":true,"img":false}]}
{"op":"mcm","clk":"11541358534","pt":1719504932793,"mc":[{"id":"1.230178325","rc":[{"atl":[[3.8,1]],"id":70902602}],"con":true,"img":false}]}
{"op":"mcm","clk":"11541358563","pt":1719504933056,"mc":[{"id":"1.230178325","rc":[{"atl":[[3.85,0]],"id":70902602}],"con":true,"img":false}]}
{"op":"mcm","clk":"11541358581","pt":1719504933263,"mc":[{"id":"1.230178325","rc":[{"atl":[[3.85,1],[3.8,0]],"id":70902602}],"con":true,"img":false}]}
{"op":"mcm","clk":"11541358601","pt":1719504933468,"mc":[{"id":"1.230178325","rc":[{"atb":[[1.78,0]],"id":69769647}],"con":true,"img":false}]}
{"op":"mcm","clk":"11541358609","pt":1719504933573,"mc":[{"id":"1.230178325","rc":[{"atb":[[1.77,2.36]],"id":69769647}],"con":true,"img":false}]}
{"op":"mcm","clk":"11541358682","pt":1719504934508,"mc":[{"id":"1.230178325","rc":[{"atl":[[3.85,0],[3.8,1]],"id":70902602}],"con":true,"img":false}]}
{"op":"mcm","clk":"11541358691","pt":1719504934612,"mc":[{"id":"1.230178325","rc":[{"atl":[[3.95,1],[3.8,0]],"id":70902602},{"atl":[[5.3,0],[5.7,1]],"id":63579394},{"atb":[[1.74,2.11]],"id":69769647},{"atl":[[7.2,1],[6.6,0]],"id":57055802},{"atl":[[4.6,0],[4.9,1]],"id":40626946}],"con":true,"img":false}]}
{"op":"mcm","clk":"11541358744","pt":1719504935078,"mc":[{"id":"1.230178325","rc":[{"atb":[[1.74,3.11]],"id":69769647}],"con":true,"img":false}]}
{"op":"mcm","clk":"11541358764","pt":1719504935285,"mc":[{"id":"1.230178325","rc":[{"atb":[[1.74,2.11]],"id":69769647}],"con":true,"img":false}]}
{"op":"mcm","clk":"11541358821","pt":1719504935908,"mc":[{"id":"1.230178325","rc":[{"atb":[[1.74,3.11]],"id":69769647}],"con":true,"img":false}]}
{"op":"mcm","clk":"11541358843","pt":1719504936066,"mc":[{"id":"1.230178325","rc":[{"atl":[[3.8,1]],"id":70902602},{"atl":[[5.3,1],[5.7,0]],"id":63579394},{"atl":[[7.2,0],[6.6,1]],"id":57055802},{"atl":[[4.6,1]],"id":40626946}],"con":true,"img":false}]}
{"op":"mcm","clk":"11541358853","pt":1719504936168,"mc":[{"id":"1.230178325","rc":[{"atl":[[3.95,0]],"id":70902602},{"atl":[[4.9,0]],"id":40626946}],"con":true,"img":false}]}
{"op":"mcm","clk":"11541358961","pt":1719504937415,"mc":[{"id":"1.230178325","rc":[{"atb":[[1.74,2.11]],"id":69769647}],"con":true,"img":false}]}
{"op":"mcm","clk":"11541359153","pt":1719504939389,"mc":[{"id":"1.230178325","rc":[{"atl":[[3.95,1],[3.8,0]],"id":70902602},{"atl":[[5.3,0],[5.7,1]],"id":63579394},{"atl":[[7.2,1],[6.6,0]],"id":57055802},{"atl":[[4.6,0],[4.9,1]],"id":40626946}],"con":true,"img":false}]}
{"op":"mcm","clk":"11541359368","pt":1719504941776,"mc":[{"id":"1.230178325","rc":[{"atb":[[2.54,0]],"id":63579394},{"atl":[[17.5,0]],"id":63579394},{"atb":[[1.77,2]],"id":69769647},{"atl":[[4.1,0.84]],"id":69769647},{"atb":[[1.93,0]],"id":40626946},{"atl":[[4.4,0.84]],"id":40626946}],"con":true,"img":false}]}
{"op":"mcm","clk":"11541359673","pt":1719504945399,"mc":[{"id":"1.230178325","rc":[{"atb":[[1.76,9.36]],"id":69769647}],"con":true,"img":false}]}
{"op":"mcm","clk":"11541359696","pt":1719504945607,"mc":[{"id":"1.230178325","rc":[{"atb":[[1.77,6]],"id":69769647}],"con":true,"img":false}]}
{"op":"mcm","clk":"11541359702","pt":1719504945712,"mc":[{"id":"1.230178325","rc":[{"atb":[[1.78,6],[1.76,0]],"id":69769647}],"con":true,"img":false}]}
{"op":"mcm","clk":"11541359815","pt":1719504946794,"mc":[{"id":"1.230178325","rc":[{"atb":[[1.77,4]],"id":69769647}],"con":true,"img":false}]}
{"op":"mcm","clk":"11541359825","pt":1719504946899,"mc":[{"id":"1.230178325","rc":[{"atb":[[1.79,2]],"id":69769647}],"con":true,"img":false}]}
{"op":"mcm","clk":"11541360421","pt":1719504953687,"mc":[{"id":"1.230178325","rc":[{"atl":[[7.6,2]],"id":45129701}],"con":true,"img":false}]}
{"op":"mcm","clk":"11541360428","pt":1719504953791,"mc":[{"id":"1.230178325","rc":[{"atl":[[4.7,1.68]],"id":69769647}],"con":true,"img":false}]}
{"op":"mcm","clk":"11541360436","pt":1719504953895,"mc":[{"id":"1.230178325","rc":[{"atl":[[23,3],[7.6,0]],"id":45129701}],"con":true,"img":false}]}
{"op":"mcm","clk":"11541360453","pt":1719504954100,"mc":[{"id":"1.230178325","rc":[{"atl":[[4.7,0]],"id":69769647}],"con":true,"img":false}]}
{"op":"mcm","clk":"11541360519","pt":1719504954819,"mc":[{"id":"1.230178325","rc":[{"atl":[[4.5,1.82]],"id":69769647}],"con":true,"img":false}]}
{"op":"mcm","clk":"11541360555","pt":1719504955085,"mc":[{"id":"1.230178325","rc":[{"atl":[[4.5,0]],"id":69769647}],"con":true,"img":false}]}
{"op":"mcm","clk":"11541360582","pt":1719504955389,"mc":[{"id":"1.230178325","rc":[{"atl":[[4.4,1.76]],"id":69769647}],"con":true,"img":false}]}
{"op":"mcm","clk":"11541360754","pt":1719504957514,"mc":[{"id":"1.230178325","rc":[{"atl":[[4.4,0]],"id":69769647}],"con":true,"img":false}]}
{"op":"mcm","clk":"11541360784","pt":1719504957822,"mc":[{"id":"1.230178325","rc":[{"atb":[[1.88,0]],"id":70902602},{"atl":[[4.3,4.56]],"id":69769647}],"con":true,"img":false}]}
{"op":"mcm","clk":"11541360943","pt":1719504959424,"mc":[{"id":"1.230178325","rc":[{"atb":[[1.77,0]],"id":69769647}],"con":true,"img":false}]}
{"op":"mcm","clk":"11541360957","pt":1719504959528,"mc":[{"id":"1.230178325","rc":[{"atb":[[1.79,5]],"id":69769647}],"con":true,"img":false}]}
{"op":"mcm","clk":"11541360968","pt":1719504959591,"mc":[{"id":"1.230178325","rc":[{"atb":[[1.8,5],[1.78,0]],"id":69769647}],"con":true,"img":false}]}
{"op":"mcm","clk":"11541360978","pt":1719504959693,"mc":[{"id":"1.230178325","rc":[{"atl":[[4.3,2]],"id":69769647}],"con":true,"img":false}]}
{"op":"mcm","clk":"11541361007","pt":1719504959893,"mc":[{"id":"1.230178325","rc":[{"atb":[[1.79,3]],"id":69769647},{"atl":[[4.2,3.01]],"id":69769647}],"con":true,"img":false}]}
{"op":"mcm","clk":"11541361019","pt":1719504960000,"mc":[{"id":"1.230178325","rc":[{"atb":[[1.81,2]],"id":69769647}],"con":true,"img":false}]}
{"op":"mcm","clk":"11541361095","pt":1719504960520,"mc":[{"id":"1.230178325","rc":[{"atl":[[4.2,1]],"id":69769647}],"con":true,"img":false}]}
{"op":"mcm","clk":"11541361127","pt":1719504960729,"mc":[{"id":"1.230178325","rc":[{"atl":[[4.2,2.88]],"id":69769647}],"con":true,"img":false}]}
{"op":"mcm","clk":"11541361221","pt":1719504961514,"mc":[{"id":"1.230178325","rc":[{"atl":[[4.2,1]],"id":69769647}],"con":true,"img":false}]}
{"op":"mcm","clk":"11541361252","pt":1719504961825,"mc":[{"id":"1.230178325","rc":[{"atl":[[4.1,2.84]],"id":69769647}],"con":true,"img":false}]}
{"op":"mcm","clk":"11541361270","pt":1719504961994,"mc":[{"id":"1.230178325","rc":[{"atb":[[1.84,5]],"id":70902602},{"atb":[[1.7,5.54]],"id":69769647},{"atb":[[1.93,5.17]],"id":40626946},{"atb":[[2.3,4.07]],"id":45129701}],"con":true,"img":false}]}
{"op":"mcm","clk":"11541361332","pt":1719504962604,"mc":[{"id":"1.230178325","rc":[{"atl":[[4.1,0.84]],"id":69769647}],"con":true,"img":false}]}
{"op":"mcm","clk":"11541361376","pt":1719504963016,"mc":[{"id":"1.230178325","rc":[{"atb":[[2.54,7.47]],"id":57055802}],"con":true,"img":false}]}
{"op":"mcm","clk":"11541361455","pt":1719504963812,"mc":[{"id":"1.230178325","rc":[{"atl":[[3.95,5.16]],"id":69769647}],"con":true,"img":false}]}
{"op":"mcm","clk":"11541361475","pt":1719504964009,"mc":[{"id":"1.230178325","rc":[{"atl":[[3.95,0]],"id":69769647}],"con":true,"img":false}]}
{"op":"mcm","clk":"11541361513","pt":1719504964424,"mc":[{"id":"1.230178325","rc":[{"atl":[[3.9,2]],"id":69769647}],"con":true,"img":false}]}
{"op":"mcm","clk":"11541361563","pt":1719504964900,"mc":[{"id":"1.230178325","rc":[{"atl":[[3.9,0]],"id":69769647}],"con":true,"img":false}]}
{"op":"mcm","clk":"11541361574","pt":1719504964997,"mc":[{"id":"1.230178325","rc":[{"atl":[[3.85,0.84],[4.1,0]],"id":69769647}],"con":true,"img":false}]}
{"op":"mcm","clk":"11541361590","pt":1719504965203,"mc":[{"id":"1.230178325","rc":[{"atl":[[3.85,2.25]],"id":69769647}],"con":true,"img":false}]}
{"op":"mcm","clk":"11541361607","pt":1719504965410,"mc":[{"id":"1.230178325","rc":[{"atl":[[3.85,1.41]],"id":69769647}],"con":true,"img":false}]}
{"op":"mcm","clk":"11541361623","pt":1719504965617,"mc":[{"id":"1.230178325","rc":[{"atb":[[1.7,0]],"id":69769647}],"con":true,"img":false}]}
{"op":"mcm","clk":"11541361641","pt":1719504965823,"mc":[{"id":"1.230178325","rc":[{"atb":[[1.84,3.18]],"id":70902602}],"con":true,"img":false}]}
{"op":"mcm","clk":"11541361704","pt":1719504966513,"mc":[{"id":"1.230178325","rc":[{"atl":[[3.85,0]],"id":69769647}],"con":true,"img":false}]}
{"op":"mcm","clk":"11541361713","pt":1719504966603,"mc":[{"id":"1.230178325","rc":[{"atl":[[4.3,0],[11.5,3]],"id":69769647}],"con":true,"img":false}]}
{"op":"mcm","clk":"11541361999","pt":1719504969418,"mc":[{"id":"1.230178325","rc":[{"atl":[[4.1,1],[4.2,0]],"id":69769647}],"con":true,"img":false}]}
{"op":"mcm","clk":"11541362008","pt":1719504969508,"mc":[{"id":"1.230178325","rc":[{"atl":[[4.3,2]],"id":69769647}],"con":true,"img":false}]}
{"op":"mcm","clk":"11541362019","pt":1719504969613,"mc":[{"id":"1.230178325","rc":[{"atl":[[11.5,0]],"id":69769647}],"con":true,"img":false}]}
{"op":"mcm","clk":"11541362043","pt":1719504969819,"mc":[{"id":"1.230178325","rc":[{"atl":[[3.85,1],[3.95,0]],"id":70902602},{"atl":[[7.2,0],[6.8,1]],"id":57055802}],"con":true,"img":false}]}
{"op":"mcm","clk":"11541362086","pt":1719504970234,"mc":[{"id":"1.230178325","rc":[{"atl":[[3.85,0],[3.95,1]],"id":70902602},{"atl":[[7.2,1],[6.8,0]],"id":57055802}],"con":true,"img":false}]}
{"op":"mcm","clk":"11541362127","pt":1719504970608,"mc":[{"id":"1.230178325","rc":[{"atl":[[4.2,1]],"id":69769647}],"con":true,"img":false}]}
{"op":"mcm","clk":"11541362138","pt":1719504970712,"mc":[{"id":"1.230178325","rc":[{"atl":[[4.1,0]],"id":69769647}],"con":true,"img":false}]}
{"op":"mcm","clk":"11541362177","pt":1719504971118,"mc":[{"id":"1.230178325","rc":[{"spl":[[1.01,1]],"id":40626946}],"con":true,"img":false}]}
{"op":"mcm","clk":"11541362379","pt":1719504973514,"mc":[{"id":"1.230178325","rc":[{"atb":[[1.79,0]],"id":69769647}],"con":true,"img":false}]}
{"op":"mcm","clk":"11541362390","pt":1719504973617,"mc":[{"id":"1.230178325","rc":[{"atb":[[1.81,4]],"id":69769647}],"con":true,"img":false}]}
{"op":"mcm","clk":"11541362399","pt":1719504973721,"mc":[{"id":"1.230178325","rc":[{"atb":[[1.8,0],[1.82,4]],"id":69769647}],"con":true,"img":false}]}
{"op":"mcm","clk":"11541362495","pt":1719504974612,"mc":[{"id":"1.230178325","rc":[{"atb":[[1.81,2]],"id":69769647},{"atl":[[4.3,0],[11.5,3]],"id":69769647}],"con":true,"img":false}]}
{"op":"mcm","clk":"11541362503","pt":1719504974710,"mc":[{"id":"1.230178325","rc":[{"atb":[[1.83,2]],"id":69769647}],"con":true,"img":false}]}
{"op":"mcm","clk":"11541362620","pt":1719504976054,"mc":[{"id":"1.230178325","rc":[{"atb":[[1.44,6.36],[2.32,2.5],[1.85,0],[2.24,5],[1.9,4.64],[2.16,10]],"id":70902602},{"atl":[[9.6,0],[5.6,2.5],[18.5,4],[4.6,1],[3.95,4.64],[6,5],[6.8,10]],"id":70902602},{"atb":[[2.52,8.07],[2.18,5],[2.26,2.5],[2.1,10],[2.08,4.24]],"id":63579394},{"atl":[[5.6,3.09],[18,0],[5.3,5],[4.9,2.5],[5.7,11],[14.5,2.12]],"id":63579394},{"atb":[[1.83,5],[1.82,0]],"id":69769647},{"atl":[[4.3,10],[3.95,5],[4.1,3],[8.2,2],[11.5,0],[3.75,2.5]],"id":69769647},{"atb":[[2.58,2.28],[2.78,2.5],[2.62,10],[2.7,5]],"id":57055802},{"atl":[[34,2.04],[9.2,10],[7.6,2.5],[50,0],[7,2.28],[8.4,5]],"id":57055802},{"atb":[[2.04,10],[1.68,0],[2.12,5],[1.95,11.18],[1.93,0],[1.82,9.2],[2.2,2.5]],"id":40626946},{"atl":[[7.2,10],[6.4,5],[5.8,2.5],[4.4,7.02]],"id":40626946},{"atb":[[2.8,2.5],[2.72,5],[2.54,7.84],[2.32,0],[2.64,10],[2.56,4]],"id":45129701},{"atl":[[18.5,2],[8.2,10],[23,0],[7.4,5],[5.2,3.84],[6.6,2.5]],"id":45129701}],"con":true,"img":false}]}
{"op":"mcm","clk":"11541362629","pt":1719504976115,"mc":[{"id":"1.230178325","rc":[{"atb":[[1.84,0]],"id":70902602},{"atb":[[2.54,4.23]],"id":57055802},{"atb":[[2.3,0]],"id":45129701}],"con":true,"img":false}]}
{"op":"mcm","clk":"11541362639","pt":1719504976209,"mc":[{"id":"1.230178325","rc":[{"atb":[[1.44,0],[1.7,8]],"id":70902602},{"atl":[[18.5,0],[3.95,0],[15,4]],"id":70902602},{"atb":[[2.28,7.1],[2.08,0]],"id":63579394},{"atl":[[12,2.12],[14.5,0]],"id":63579394},{"atb":[[1.59,5],[1.63,2.5],[1.55,10],[1.65,4.12]],"id":69769647},{"atl":[[4.1,5],[8.2,0]],"id":69769647},{"atb":[[2.54,2.11],[2.62,12.7]],"id":57055802},{"atl":[[34,0],[26,2.04]],"id":57055802},{"atb":[[2.56,0],[2.62,4]],"id":45129701},{"atl":[[18.5,0],[6.6,4.5]],"id":45129701}],"con":true,"img":false}]}
{"op":"mcm","clk":"11541362649","pt":1719504976324,"mc":[{"id":"1.230178325","rc":[{"atl":[[4,5.36]],"id":70902602}],"con":true,"img":false}]}
{"op":"mcm","clk":"11541362678","pt":1719504976626,"mc":[{"id":"1.230178325","rc":[{"atl":[[4,0]],"id":70902602}],"con":true,"img":false}]}
{"op":"mcm","clk":"11541362689","pt":1719504976752,"mc":[{"id":"1.230178325","rc":[{"atl":[[4.1,5.62]],"id":70902602},{"atb":[[1.95,9.18]],"id":40626946}],"con":true,"img":false}]}
{"op":"mcm","clk":"11541362700","pt":1719504976811,"mc":[{"id":"1.230178325","rc":[{"atb":[[1.02,2]],"id":40626946}],"con":true,"img":false}]}
{"op":"mcm","clk":"11541362711","pt":1719504976918,"mc":[{"id":"1.230178325","rc":[{"atl":[[3.95,0.84]],"id":70902602},{"atl":[[4.8,0.84]],"id":63579394},{"atl":[[3.7,0.84]],"id":69769647},{"atl":[[6.8,0.84]],"id":57055802},{"atl":[[5.1,0.84]],"id":45129701}],"con":true,"img":false}]}
{"op":"mcm","clk":"11541362731","pt":1719504977118,"mc":[{"id":"1.230178325","rc":[{"atb":[[2.54,5.84]],"id":45129701}],"con":true,"img":false}]}
{"op":"mcm","clk":"11541362742","pt":1719504977220,"mc":[{"id":"1.230178325","rc":[{"atb":[[2.82,2]],"id":45129701}],"con":true,"img":false}]}
{"op":"mcm","clk":"11541362751","pt":1719504977324,"mc":[{"id":"1.230178325","rc":[{"atb":[[1.59,0]],"id":70902602},{"atl":[[4.3,11],[4.2,0]],"id":69769647}],"con":true,"img":false}]}
{"op":"mcm","clk":"11541362761","pt":1719504977428,"mc":[{"id":"1.230178325","rc":[{"atb":[[1.82,0],[1.75,10]],"id":40626946}],"con":true,"img":false}]}
{"op":"mcm","clk":"11541362769","pt":1719504977531,"mc":[{"id":"1.230178325","rc":[{"atb":[[1.89,2.21]],"id":70902602},{"atl":[[3.95,0]],"id":70902602},{"atl":[[4.3,10],[4.4,1]],"id":69769647}],"con":true,"img":false}]}
{"op":"mcm","clk":"11541362780","pt":1719504977633,"mc":[{"id":"1.230178325","rc":[{"atb":[[2.34,2]],"id":70902602}],"con":true,"img":false}]}
{"op":"mcm","clk":"11541362828","pt":1719504978051,"mc":[{"id":"1.230178325","rc":[{"atb":[[1.02,0]],"id":57055802}],"con":true,"img":false}]}
{"op":"mcm","clk":"11541362838","pt":1719504978114,"mc":[{"id":"1.230178325","rc":[{"atb":[[2.8,2]],"id":57055802}],"con":true,"img":false}]}
{"op":"mcm","clk":"11541362855","pt":1719504978308,"mc":[{"id":"1.230178325","rc":[{"atl":[[4.1,0]],"id":70902602}],"con":true,"img":false}]}
{"op":"mcm","clk":"11541362862","pt":1719504978414,"mc":[{"id":"1.230178325","rc":[{"atl":[[4.2,3.75]],"id":70902602}],"con":true,"img":false}]}
{"op":"mcm","clk":"11541363115","pt":1719504981051,"mc":[{"id":"1.230178325","rc":[{"atl":[[4.8,1],[4.6,0]],"id":70902602}],"con":true,"img":false}]}
{"op":"mcm","clk":"11541363227","pt":1719504982038,"mc":[{"id":"1.230178325","rc":[{"atl":[[5.6,7.5],[15,0]],"id":70902602},{"atl":[[5.3,10],[12,0]],"id":63579394},{"atl":[[3.95,10],[4.1,3]],"id":69769647},{"atb":[[2.8,4.5],[2.62,10]],"id":57055802},{"atl":[[7.2,4.13],[26,0]],"id":57055802},{"atb":[[2.62,0],[2.68,5.84]],"id":45129701},{"atl":[[5.3,5.69],[6.6,2.5]],"id":45129701}],"con":true,"img":false}]}
{"op":"mcm","clk":"11541363238","pt":1719504982142,"mc":[{"id":"1.230178325","rc":[{"atb":[[1.89,0]],"id":70902602},{"atb":[[2.56,0]],"id":57055802},{"atb":[[1.95,6.18]],"id":40626946},{"atb":[[2.54,3.84]],"id":45129701}],"con":true,"img":false}]}
{"op":"mcm","clk":"11541363250","pt":1719504982247,"mc":[{"id":"1.230178325","rc":[{"atb":[[2.34,4]],"id":70902602},{"spn":3.27,"spf":"NaN","id":70902602},{"spn":3.66,"spf":"NaN","id":63579394},{"spn":2.76,"spf":"NaN","id":69769647},{"spn":4.8,"spf":"NaN","id":57055802},{"atb":[[2.2,5.33]],"id":40626946},{"spn":2.2,"spf":1.0,"id":40626946},{"spn":3.96,"spf":"NaN","id":45129701}],"con":true,"img":false}]}
{"op":"mcm","clk":"11541363356","pt":1719504983237,"mc":[{"id":"1.230178325","rc":[{"atl":[[5.3,11],[5.2,1],[5.7,10]],"id":63579394},{"atb":[[1.78,1]],"id":69769647},{"atl":[[4.3,11],[4.4,0]],"id":69769647},{"atl":[[7.2,3.13],[6.8,1.84]],"id":57055802},{"atb":[[1.82,10.33],[1.75,0]],"id":40626946},{"atl":[[4.8,1],[4.9,0],[4.4,8.02]],"id":40626946},{"atl":[[5.3,4.69],[5.2,4.84]],"id":45129701}],"con":true,"img":false}]}
{"op":"mcm","clk":"11541363363","pt":1719504983344,"mc":[{"id":"1.230178325","rc":[{"atb":[[1.74,3.11]],"id":69769647}],"con":true,"img":false}]}
{"op":"mcm","clk":"11541363389","pt":1719504983552,"mc":[{"id":"1.230178325","rc":[{"atb":[[1.78,0]],"id":69769647},{"atl":[[4.8,0]],"id":40626946},{"atl":[[5.3,5.69],[5.2,3.84]],"id":45129701}],"con":true,"img":false}]}
{"op":"mcm","clk":"11541363479","pt":1719504984439,"mc":[{"id":"1.230178325","rc":[{"atl":[[4.1,0.84]],"id":70902602}],"con":true,"img":false}]}
{"op":"mcm","clk":"11541363511","pt":1719504984751,"mc":[{"id":"1.230178325","rc":[{"atl":[[5.2,0]],"id":63579394}],"con":true,"img":false}]}
{"op":"mcm","clk":"11541363647","pt":1719504985943,"mc":[{"id":"1.230178325","rc":[{"atb":[[2.28,11.34]],"id":63579394}],"con":true,"img":false}]}
{"op":"mcm","clk":"11541363656","pt":1719504986045,"mc":[{"id":"1.230178325","rc":[{"atb":[[1.7,0],[1.62,9.64]],"id":70902602},{"atl":[[4.9,1]],"id":70902602}],"con":true,"img":false}]}
{"op":"mcm","clk":"11541363667","pt":1719504986149,"mc":[{"id":"1.230178325","rc":[{"atl":[[4.8,0]],"id":70902602},{"atb":[[1.83,2]],"id":69769647}],"con":true,"img":false}]}
{"op":"mcm","clk":"11541363730","pt":1719504986726,"mc":[{"id":"1.230178325","rc":[{"atb":[[2.28,7.1]],"id":63579394}],"con":true,"img":false}]}
{"op":"mcm","clk":"11541363748","pt":1719504986931,"mc":[{"id":"1.230178325","rc":[{"atb":[[2.3,4.06]],"id":70902602},{"atb":[[1.83,0],[1.68,5.54]],"id":69769647},{"atb":[[2.18,4.3]],"id":40626946}],"con":true,"img":false}]}
{"op":"mcm","clk":"11541363757","pt":1719504987035,"mc":[{"id":"1.230178325","rc":[{"atb":[[1.82,2]],"id":69769647}],"con":true,"img":false}]}
{"op":"mcm","clk":"11541363777","pt":1719504987243,"mc":[{"id":"1.230178325","rc":[{"atb":[[2.62,10],[2.68,0]],"id":45129701}],"con":true,"img":false}]}
{"op":"mcm","clk":"11541363821","pt":1719504987728,"mc":[{"id":"1.230178325","rc":[{"atl":[[5.6,2.5],[4.9,6]],"id":70902602}],"con":true,"img":false}]}
{"op":"mcm","clk":"11541363874","pt":1719504988341,"mc":[{"id":"1.230178325","rc":[{"atb":[[1.74,2.11]],"id":69769647}],"con":true,"img":false}]}
{"op":"mcm","clk":"11541363884","pt":1719504988444,"mc":[{"id":"1.230178325","rc":[{"atb":[[2.34,9.81]],"id":70902602},{"atl":[[4.8,8.04]],"id":63579394},{"atl":[[3.6,3.38]],"id":69769647},{"atb":[[2.8,8.72]],"id":57055802},{"atl":[[6.6,4.22]],"id":57055802},{"atb":[[2.2,12.31]],"id":40626946},{"atb":[[2.82,6.76]],"id":45129701},{"atl":[[5.1,5.6]],"id":45129701}],"con":true,"img":false}]}
{"op":"mcm","clk":"11541363895","pt":1719504988548,"mc":[{"id":"1.230178325","rc":[{"atl":[[5.3,10],[5.7,11]],"id":63579394},{"atb":[[1.9,0]],"id":70902602},{"atb":[[1.74,3.11]],"id":69769647},{"atl":[[4.3,10],[4.1,4],[3.75,5.5]],"id":69769647},{"atl":[[7,0]],"id":57055802},{"atb":[[1.95,0]],"id":40626946},{"atl":[[4.8,1],[4.4,7.02]],"id":40626946},{"atl":[[5.2,0]],"id":45129701}],"con":true,"img":false}]}
{"op":"mcm","clk":"11541363905","pt":1719504988653,"mc":[{"id":"1.230178325","rc":[{"atl":[[5.6,0]],"id":63579394},{"atl":[[3.95,5],[4.1,1]],"id":69769647},{"atb":[[2.8,6.22],[2.58,0],[2.7,12]],"id":57055802},{"atb":[[2.54,0]],"id":45129701},{"atl":[[5.3,0.99],[6.6,13.8]],"id":45129701}],"con":true,"img":false}]}
{"op":"mcm","clk":"11541363915","pt":1719504988756,"mc":[{"id":"1.230178325","rc":[{"atl":[[4.3,4.39]],"id":63579394},{"atb":[[2.8,11.22],[2.7,5]],"id":57055802}],"con":true,"img":false}]}
{"op":"mcm","clk":"11541363924","pt":1719504988823,"mc":[{"id":"1.230178325","rc":[{"atl":[[5.3,5],[4.2,4.39]],"id":63579394},{"atb":[[2.8,6.22]],"id":57055802}],"con":true,"img":false}]}
{"op":"mcm","clk":"11541363931","pt":1719504988921,"mc":[{"id":"1.230178325","rc":[{"atb":[[2.7,15]],"id":57055802},{"atb":[[2.7,3.14]],"id":45129701}],"con":true,"img":false}]}
{"op":"mcm","clk":"11541363940","pt":1719504989026,"mc":[{"id":"1.230178325","rc":[{"atl":[[3.7,0],[3.55,0.84]],"id":69769647},{"atb":[[2.8,11.22],[2.7,5]],"id":57055802},{"atl":[[6.4,0.84]],"id":57055802}],"con":true,"img":false}]}
{"op":"mcm","clk":"11541363959","pt":1719504989237,"mc":[{"id":"1.230178325","rc":[{"atb":[[2.3,0]],"id":70902602},{"atb":[[2.8,6.22],[2.7,15]],"id":57055802},{"atl":[[7.2,0],[6.8,6.91]],"id":57055802},{"atb":[[2.7,0]],"id":45129701}],"con":true,"img":false}]}
{"op":"mcm","clk":"11541363974","pt":1719504989434,"mc":[{"id":"1.230178325","rc":[{"atl":[[4.8,7.2],[4.1,0.84]],"id":63579394},{"atb":[[2.8,11.22],[2.7,5]],"id":57055802}],"con":true,"img":false}]}
{"op":"mcm","clk":"11541363994","pt":1719504989642,"mc":[{"id":"1.230178325","rc":[{"atl":[[6.8,1.84],[7,8.44]],"id":57055802}],"con":true,"img":false}]}
{"op":"mcm","clk":"11541364019","pt":1719504989848,"mc":[{"id":"1.230178325","rc":[{"atl":[[4.3,11],[4.1,0]],"id":69769647},{"atl":[[7.2,6.07],[7,0]],"id":57055802},{"atb":[[1.76,10],[1.82,0]],"id":40626946},{"atl":[[4.8,0],[4.4,8.02]],"id":40626946}],"con":true,"img":false}]}
{"op":"mcm","clk":"11541364029","pt":1719504989950,"mc":[{"id":"1.230178325","rc":[{"atl":[[5.2,1],[5.7,10]],"id":63579394},{"atl":[[4.5,5.04]],"id":40626946},{"atl":[[5.3,0],[5.2,1]],"id":45129701}],"con":true,"img":false}]}
{"op":"mcm","clk":"11541364035","pt":1719504990055,"mc":[{"id":"1.230178325","rc":[{"atl":[[5.3,11.22],[6.6,2.5]],"id":45129701}],"con":true,"img":false}]}
{"op":"mcm","clk":"11541364123","pt":1719504990830,"mc":[{"id":"1.230178325","rc":[{"atb":[[2.34,7.81]],"id":70902602},{"atb":[[1.81,0]],"id":69769647},{"atb":[[2.2,9.48]],"id":40626946}],"con":true,"img":false}]}
{"op":"mcm","clk":"11541364140","pt":1719504990934,"mc":[{"id":"1.230178325","rc":[{"atb":[[2.36,3.59]],"id":70902602},{"atb":[[2.22,3]],"id":40626946}],"con":true,"img":false}]}
{"op":"mcm","clk":"11541364161","pt":1719504991142,"mc":[{"id":"1.230178325","rc":[{"atb":[[1.54,10]],"id":70902602},{"atl":[[5,1],[4.9,5]],"id":70902602},{"atl":[[7.2,0],[7,5]],"id":57055802},{"atl":[[4.4,7.02]],"id":40626946}],"con":true,"img":false}]}
{"op":"mcm","clk":"11541364172","pt":1719504991245,"mc":[{"id":"1.230178325","rc":[{"atb":[[1.62,0]],"id":70902602}],"con":true,"img":false}]}
{"op":"mcm","clk":"11541364193","pt":1719504991454,"mc":[{"id":"1.230178325","rc":[{"atb":[[1.82,0]],"id":69769647}],"con":true,"img":false}]}
{"op":"mcm","clk":"11541364203","pt":1719504991557,"mc":[{"id":"1.230178325","rc":[{"atb":[[1.6,7.24],[1.74,7.73],[1.65,0],[1.75,2],[1.66,1]],"id":69769647},{"atl":[[4.3,10]],"id":69769647},{"atl":[[4.8,1],[4.5,4.04]],"id":40626946}],"con":true,"img":false}]}
{"op":"mcm","clk":"11541364215","pt":1719504991625,"mc":[{"id":"1.230178325","rc":[{"atl":[[4.1,1]],"id":69769647},{"atb":[[2.18,0]],"id":40626946}],"con":true,"img":false}]}
{"op":"mcm","clk":"11541364238","pt":1719504991835,"mc":[{"id":"1.230178325","rc":[{"atb":[[2.34,5.81]],"id":70902602}],"con":true,"img":false}]}
{"op":"mcm","clk":"11541364251","pt":1719504991939,"mc":[{"id":"1.230178325","rc":[{"atb":[[2.38,2]],"id":70902602}],"con":true,"img":false}]}
{"op":"mcm","clk":"11541364278","pt":1719504992241,"mc":[{"id":"1.230178325","rc":[{"atb":[[1.68,0]],"id":69769647}],"con":true,"img":false}]}
{"op":"mcm","clk":"11541364310","pt":1719504992554,"mc":[{"id":"1.230178325","rc":[{"atl":[[4.3,0]],"id":63579394}],"con":true,"img":false}]}
{"op":"mcm","clk":"11541364321","pt":1719504992657,"mc":[{"id":"1.230178325","rc":[{"atl":[[4.8,12.44]],"id":63579394}],"con":true,"img":false}]}
{"op":"mcm","clk":"11541364330","pt":1719504992730,"mc":[{"id":"1.230178325","rc":[{"atl":[[4.2,0]],"id":63579394}],"con":true,"img":false}]}
{"op":"mcm","clk":"11541364339","pt":1719504992833,"mc":[{"id":"1.230178325","rc":[{"atl":[[5.2,0]],"id":63579394}],"con":true,"img":false}]}
{"op":"mcm","clk":"11541364351","pt":1719504992922,"mc":[{"id":"1.230178325","rc":[{"atb":[[2.8,16.02],[2.62,0]],"id":45129701}],"con":true,"img":false}]}
{"op":"mcm","clk":"11541364394","pt":1719504993335,"mc":[{"id":"1.230178325","rc":[{"atl":[[5.7,11]],"id":63579394}],"con":true,"img":false}]}
{"op":"mcm","clk":"11541364405","pt":1719504993440,"mc":[{"id":"1.230178325","rc":[{"atl":[[4.5,2.48],[4.1,0]],"id":63579394}],"con":true,"img":false}]}
{"op":"mcm","clk":"11541364424","pt":1719504993665,"mc":[{"id":"1.230178325","rc":[{"atl":[[4.8,7.2],[4.5,2.5]],"id":63579394}],"con":true,"img":false}]}
{"op":"mcm","clk":"11541364445","pt":1719504993923,"mc":[{"id":"1.230178325","rc":[{"atl":[[4.5,0],[4.9,17.42]],"id":63579394}],"con":true,"img":false}]}
{"op":"mcm","clk":"11541364462","pt":1719504994113,"mc":[{"id":"1.230178325","rc":[{"atl":[[4.3,4.39]],"id":63579394}],"con":true,"img":false}]}
{"op":"mcm","clk":"11541364492","pt":1719504994856,"mc":[{"id":"1.230178325","rc":[{"atb":[[1.69,2.11]],"id":69769647}],"con":true,"img":false}]}
{"op":"mcm","clk":"11541364502","pt":1719504994873,"mc":[{"id":"1.230178325","rc":[{"atb":[[1.74,5.62]],"id":69769647}],"con":true,"img":false}]}
{"op":"mcm","clk":"11541364568","pt":1719504995289,"mc":[{"id":"1.230178325","rc":[{"atb":[[2.22,4.53]],"id":70902602}],"con":true,"img":false}]}
{"op":"mcm","clk":"11541364679","pt":1719504996154,"mc":[{"id":"1.230178325","rc":[{"atl":[[5,0],[5.2,1]],"id":70902602}],"con":true,"img":false}]}
{"op":"mcm","clk":"11541364710","pt":1719504996464,"mc":[{"id":"1.230178325","rc":[{"atl":[[4.2,0.84]],"id":63579394},{"atb":[[1.73,1]],"id":69769647}],"con":true,"img":false}]}
{"op":"mcm","clk":"11541364724","pt":1719504996529,"mc":[{"id":"1.230178325","rc":[{"atb":[[1.66,0]],"id":69769647}],"con":true,"img":false}]}
{"op":"mcm","clk":"11541364764","pt":1719504996944,"mc":[{"id":"1.230178325","rc":[{"atl":[[5.2,1],[5.7,10]],"id":63579394},{"atb":[[1.73,0],[1.66,1]],"id":69769647},{"atl":[[4.3,11],[4.1,0]],"id":69769647},{"atl":[[4.8,0],[4.5,5.04]],"id":40626946}],"con":true,"img":false}]}
{"op":"mcm","clk":"11541364827","pt":1719504997664,"mc":[{"id":"1.230178325","rc":[{"atl":[[5.2,0]],"id":63579394},{"atl":[[4.8,1],[4.5,4.04]],"id":40626946}],"con":true,"img":false}]}
{"op":"mcm","clk":"11541364867","pt":1719504998037,"mc":[{"id":"1.230178325","rc":[{"atb":[[2.8,2.5],[2.78,22.78]],"id":45129701}],"con":true,"img":false}]}
{"op":"mcm","clk":"11541364983","pt":1719504999134,"mc":[{"id":"1.230178325","rc":[{"atb":[[1.73,1],[1.66,0]],"id":69769647},{"atl":[[4.3,10],[4.1,1]],"id":69769647}],"con":true,"img":false}]}
{"op":"mcm","clk":"11541365011","pt":1719504999447,"mc":[{"id":"1.230178325","rc":[{"atl":[[4.3,11.59],[5.2,1]],"id":63579394},{"atb":[[1.75,5.06]],"id":69769647},{"atl":[[4.8,0],[4.5,5.04]],"id":40626946},{"atb":[[2.84,3]],"id":45129701}],"con":true,"img":false}]}
{"op":"mcm","clk":"11541365022","pt":1719504999547,"mc":[{"id":"1.230178325","rc":[{"atl":[[4.9,2.5]],"id":63579394}],"con":true,"img":false}]}
{"op":"mcm","clk":"11541365043","pt":1719504999769,"mc":[{"id":"1.230178325","rc":[{"atb":[[1.73,0],[1.66,1]],"id":69769647},{"atl":[[4.3,11],[4.1,0]],"id":69769647}],"con":true,"img":false}]}
{"op":"mcm","clk":"11541365050","pt":1719504999857,"mc":[{"id":"1.230178325","rc":[{"atl":[[5.2,0]],"id":63579394},{"atl":[[4.8,1],[4.5,4.04]],"id":40626946}],"con":true,"img":false}]}
{"op":"mcm","clk":"11541365061","pt":1719504999964,"mc":[{"id":"1.230178325","rc":[{"atl":[[4.3,7.2]],"id":63579394}],"con":true,"img":false}]}
{"op":"mcm","clk":"11541365095","pt":1719505000332,"mc":[{"id":"1.230178325","rc":[{"atl":[[5.7,11]],"id":63579394},{"atb":[[2.82,4.76]],"id":45129701}],"con":true,"img":false}]}
{"op":"mcm","clk":"11541365102","pt":1719505000438,"mc":[{"id":"1.230178325","rc":[{"atb":[[2.86,2]],"id":45129701}],"con":true,"img":false}]}
{"op":"mcm","clk":"11541365123","pt":1719505000647,"mc":[{"id":"1.230178325","rc":[{"atl":[[4.2,11.57]],"id":63579394},{"atb":[[2.4,5.5]],"id":70902602},{"atl":[[3.55,7.17]],"id":69769647},{"atl":[[6.4,5.88]],"id":57055802},{"atb":[[2.22,9.78]],"id":40626946},{"atl":[[4.3,6.78]],"id":40626946},{"atb":[[2.86,7.82]],"id":45129701}],"con":true,"img":false}]}
{"op":"mcm","clk":"11541365133","pt":1719505000750,"mc":[{"id":"1.230178325","rc":[{"atl":[[3.5,5.5],[3.75,2.5]],"id":69769647},{"atl":[[6.8,11.95],[7,0]],"id":57055802},{"atl":[[4.5,2.04],[4.2,6.78]],"id":40626946}],"con":true,"img":false}]}
{"op":"mcm","clk":"11541365144","pt":1719505000856,"mc":[{"id":"1.230178325","rc":[{"atl":[[4.8,0]],"id":63579394},{"atb":[[2.34,0]],"id":70902602},{"atl":[[3.6,0],[3.5,0],[3.75,13.06]],"id":69769647},{"atl":[[6.6,0]],"id":57055802},{"atb":[[2.2,2.5]],"id":40626946},{"atl":[[4.4,14.4],[4.2,0]],"id":40626946},{"atb":[[2.82,0]],"id":45129701}],"con":true,"img":false}]}
{"op":"mcm","clk":"11541365154","pt":1719505000959,"mc":[{"id":"1.230178325","rc":[{"atl":[[3.6,12.68],[3.75,2.5]],"id":69769647},{"atl":[[7.6,17.65]],"id":57055802}],"con":true,"img":false}]}
{"op":"mcm","clk":"11541365163","pt":1719505001064,"mc":[{"id":"1.230178325","rc":[{"atl":[[6.8,1.84]],"id":57055802}],"con":true,"img":false}]}
{"op":"mcm","clk":"11541365182","pt":1719505001272,"mc":[{"id":"1.230178325","rc":[{"atl":[[4.4,2.02]],"id":63579394},{"atl":[[4.3,10],[4.1,1]],"id":69769647},{"atb":[[2.8,13.32],[2.78,0]],"id":45129701}],"con":true,"img":false}]}
{"op":"mcm","clk":"11541365192","pt":1719505001333,"mc":[{"id":"1.230178325","rc":[{"atb":[[2.86,19.82]],"id":45129701},{"atl":[[5.1,10.88]],"id":45129701}],"con":true,"img":false}]}
{"op":"mcm","clk":"11541365202","pt":1719505001432,"mc":[{"id":"1.230178325","rc":[{"atl":[[6.8,1]],"id":57055802},{"atl":[[4.2,0.84]],"id":40626946}],"con":true,"img":false}]}
{"op":"mcm","clk":"11541365213","pt":1719505001538,"mc":[{"id":"1.230178325","rc":[{"atl":[[4.4,0]],"id":63579394}],"con":true,"img":false}]}
{"op":"mcm","clk":"11541365225","pt":1719505001640,"mc":[{"id":"1.230178325","rc":[{"atb":[[2.38,0]],"id":70902602}],"con":true,"img":false}]}
{"op":"mcm","clk":"11541365238","pt":1719505001745,"mc":[{"id":"1.230178325","rc":[{"atb":[[2.42,2]],"id":70902602}],"con":true,"img":false}]}
{"op":"mcm","clk":"11541365251","pt":1719505001848,"mc":[{"id":"1.230178325","rc":[{"atb":[[2.44,5.5],[2.4,0]],"id":70902602},{"atl":[[4.2,16.03]],"id":63579394}],"con":true,"img":false}]}
{"op":"mcm","clk":"11541365308","pt":1719505002326,"mc":[{"id":"1.230178325","rc":[{"atb":[[1.73,1],[1.66,0]],"id":69769647}],"con":true,"img":false}]}
{"op":"mcm","clk":"11541365319","pt":1719505002429,"mc":[{"id":"1.230178325","rc":[{"atl":[[4.3,11],[4.1,0]],"id":69769647},{"atl":[[4.5,3.04]],"id":40626946}],"con":true,"img":false}]}
{"op":"mcm","clk":"11541365329","pt":1719505002532,"mc":[{"id":"1.230178325","rc":[{"atl":[[4.8,0]],"id":40626946}],"con":true,"img":false}]}
{"op":"mcm","clk":"11541365348","pt":1719505002739,"mc":[{"id":"1.230178325","rc":[{"atb":[[1.73,0],[1.66,1]],"id":69769647},{"atl":[[4.3,10],[4.1,1]],"id":69769647},{"atl":[[4.8,1],[4.5,2.04]],"id":40626946}],"con":true,"img":false}]}
{"op":"mcm","clk":"11541365356","pt":1719505002843,"mc":[{"id":"1.230178325","rc":[{"atb":[[2.42,0]],"id":70902602}],"con":true,"img":false}]}
{"op":"mcm","clk":"11541365363","pt":1719505002948,"mc":[{"id":"1.230178325","rc":[{"atb":[[2.46,2]],"id":70902602}],"con":true,"img":false}]}
{"op":"mcm","clk":"11541365369","pt":1719505003052,"mc":[{"id":"1.230178325","rc":[{"atb":[[2.44,0],[2.48,5.5]],"id":70902602}],"con":true,"img":false}]}
{"op":"mcm","clk":"11541365417","pt":1719505003676,"mc":[{"id":"1.230178325","rc":[{"atb":[[1.75,13.07]],"id":69769647}],"con":true,"img":false}]}
{"op":"mcm","clk":"11541365429","pt":1719505003733,"mc":[{"id":"1.230178325","rc":[{"atb":[[1.74,0]],"id":69769647}],"con":true,"img":false}]}
{"op":"mcm","clk":"11541365467","pt":1719505004152,"mc":[{"id":"1.230178325","rc":[{"atb":[[2.46,0]],"id":70902602}],"con":true,"img":false}]}
{"op":"mcm","clk":"11541365477","pt":1719505004255,"mc":[{"id":"1.230178325","rc":[{"atb":[[2.5,2],[2.48,0]],"id":70902602}],"con":true,"img":false}]}
{"op":"mcm","clk":"11541365486","pt":1719505004357,"mc":[{"id":"1.230178325","rc":[{"atb":[[2.5,6.19]],"id":70902602}],"con":true,"img":false}]}
{"op":"mcm","clk":"11541365522","pt":1719505004875,"mc":[{"id":"1.230178325","rc":[{"atl":[[4.8,0],[4.9,1]],"id":40626946},{"atl":[[5.3,12.22],[5.2,0]],"id":45129701}],"con":true,"img":false}]}
{"op":"mcm","clk":"11541365542","pt":1719505005036,"mc":[{"id":"1.230178325","rc":[{"atl":[[4.3,0],[4.2,23.23]],"id":63579394}],"con":true,"img":false}]}
{"op":"mcm","clk":"11541365578","pt":1719505005451,"mc":[{"id":"1.230178325","rc":[{"atl":[[3.95,6],[4.1,0]],"id":69769647}],"con":true,"img":false}]}
{"op":"mcm","clk":"11541365599","pt":1719505005659,"mc":[{"id":"1.230178325","rc":[{"atl":[[4.8,1],[4.9,0]],"id":40626946},{"atl":[[5.3,11.22],[5.2,1]],"id":45129701}],"con":true,"img":false}]}
{"op":"mcm","clk":"11541365638","pt":1719505006073,"mc":[{"id":"1.230178325","rc":[{"atl":[[3.6,0],[3.75,22.36]],"id":69769647}],"con":true,"img":false}]}
{"op":"mcm","clk":"11541365681","pt":1719505006545,"mc":[{"id":"1.230178325","rc":[{"atl":[[5.3,6],[4.9,0],[5.2,0]],"id":70902602},{"atb":[[1.75,5.06]],"id":69769647}],"con":true,"img":false}]}
{"op":"mcm","clk":"11541365700","pt":1719505006753,"mc":[{"id":"1.230178325","rc":[{"atb":[[2.82,22.82]],"id":45129701}],"con":true,"img":false}]}
{"op":"mcm","clk":"11541365712","pt":1719505006859,"mc":[{"id":"1.230178325","rc":[{"atb":[[2.8,2.5]],"id":45129701}],"con":true,"img":false}]}
{"op":"mcm","clk":"11541365752","pt":1719505007273,"mc":[{"id":"1.230178325","rc":[{"atl":[[4.2,18.77]],"id":63579394}],"con":true,"img":false}]}
{"op":"mcm","clk":"11541365804","pt":1719505007741,"mc":[{"id":"1.230178325","rc":[{"atl":[[4.1,4.44]],"id":63579394}],"con":true,"img":false}]}
{"op":"mcm","clk":"11541365871","pt":1719505008467,"mc":[{"id":"1.230178325","rc":[{"atl":[[4,0.84]],"id":63579394},{"atb":[[2.36,0]],"id":70902602},{"atb":[[1.75,2]],"id":69769647},{"atb":[[2.84,0]],"id":45129701}],"con":true,"img":false}]}
{"op":"mcm","clk":"11541365895","pt":1719505008635,"mc":[{"id":"1.230178325","rc":[{"atb":[[2.52,3]],"id":70902602},{"atb":[[1.73,2.59]],"id":69769647},{"atb":[[2.82,2.59]],"id":57055802},{"atb":[[2.88,3.5]],"id":45129701}],"con":true,"img":false}]}
{"op":"mcm","clk":"11541365904","pt":1719505008736,"mc":[{"id":"1.230178325","rc":[{"atb":[[2.82,8.95]],"id":57055802}],"con":true,"img":false}]}
{"op":"mcm","clk":"11541365912","pt":1719505008837,"mc":[{"id":"1.230178325","rc":[{"atb":[[2.8,7]],"id":57055802}],"con":true,"img":false}]}
{"op":"mcm","clk":"11541365924","pt":1719505008939,"mc":[{"id":"1.230178325","rc":[{"atl":[[3.95,5],[4.2,1]],"id":69769647},{"atl":[[4.8,0],[4.9,1]],"id":40626946},{"atl":[[5.3,12.22],[5.2,0]],"id":45129701}],"con":true,"img":false}]}
{"op":"mcm","clk":"11541365934","pt":1719505009045,"mc":[{"id":"1.230178325","rc":[{"atl":[[4.5,3.04]],"id":40626946}],"con":true,"img":false}]}
{"op":"mcm","clk":"11541365949","pt":1719505009247,"mc":[{"id":"1.230178325","rc":[{"atl":[[4.9,0]],"id":40626946}],"con":true,"img":false}]}
{"op":"mcm","clk":"11541365967","pt":1719505009453,"mc":[{"id":"1.230178325","rc":[{"atb":[[2.86,7.82]],"id":45129701}],"con":true,"img":false}]}
{"op":"mcm","clk":"11541365980","pt":1719505009662,"mc":[{"id":"1.230178325","rc":[{"atb":[[2.5,5.73]],"id":63579394}],"con":true,"img":false}]}
{"op":"mcm","clk":"11541366021","pt":1719505010078,"mc":[{"id":"1.230178325","rc":[{"atb":[[1.75,0]],"id":69769647}],"con":true,"img":false}]}
{"op":"mcm","clk":"11541366030","pt":1719505010180,"mc":[{"id":"1.230178325","rc":[{"atb":[[1.74,2],[1.75,5.69]],"id":69769647},{"atb":[[2.88,15.1]],"id":45129701}],"con":true,"img":false}]}
{"op":"mcm","clk":"11541366066","pt":1719505010545,"mc":[{"id":"1.230178325","rc":[{"atb":[[2.36,3.91]],"id":70902602},{"atb":[[1.67,5.54]],"id":69769647},{"atb":[[2.2,6.77]],"id":40626946},{"atb":[[2.86,5.82]],"id":45129701}],"con":true,"img":false}]}
{"op":"mcm","clk":"11541366075","pt":1719505010649,"mc":[{"id":"1.230178325","rc":[{"atb":[[2.84,5.25],[2.9,2]],"id":45129701}],"con":true,"img":false}]}
{"op":"mcm","clk":"11541366113","pt":1719505011061,"mc":[{"id":"1.230178325","rc":[{"atb":[[2.5,4.19]],"id":70902602},{"atb":[[2.88,3.5]],"id":45129701}],"con":true,"img":false}]}
{"op":"mcm","clk":"11541366119","pt":1719505011163,"mc":[{"id":"1.230178325","rc":[{"atb":[[2.54,2]],"id":70902602},{"atl":[[3.95,34.54],[3.75,2.5]],"id":69769647}],"con":true,"img":false}]}
{"op":"mcm","clk":"11541366130","pt":1719505011268,"mc":[{"id":"1.230178325","rc":[{"atb":[[2.84,0]],"id":45129701}],"con":true,"img":false}]}
{"op":"mcm","clk":"11541366137","pt":1719505011374,"mc":[{"id":"1.230178325","rc":[{"atl":[[4.1,1],[3.8,1],[4.2,0]],"id":69769647},{"atl":[[4.5,2.04],[4.6,1],[4.7,1]],"id":40626946},{"atl":[[5.3,11.22],[5.2,1]],"id":45129701}],"con":true,"img":false}]}
{"op":"mcm","clk":"11541366156","pt":1719505011580,"mc":[{"id":"1.230178325","rc":[{"atl":[[3.95,5],[3.8,10.68]],"id":69769647},{"atb":[[1.83,11.77],[1.76,0]],"id":40626946}],"con":true,"img":false}]}
{"op":"mcm","clk":"11541366166","pt":1719505011638,"mc":[{"id":"1.230178325","rc":[{"atb":[[2.8,5]],"id":57055802}],"con":true,"img":false}]}
{"op":"mcm","clk":"11541366178","pt":1719505011739,"mc":[{"id":"1.230178325","rc":[{"atb":[[2.84,2]],"id":57055802},{"atl":[[4.7,0]],"id":40626946},{"atl":[[5.3,0],[5.2,22.78]],"id":45129701}],"con":true,"img":false}]}
{"op":"mcm","clk":"11541366189","pt":1719505011844,"mc":[{"id":"1.230178325","rc":[{"atb":[[1.43,8.1],[1.54,0]],"id":70902602},{"atl":[[5.6,3.5],[5.3,0]],"id":70902602},{"atb":[[2.52,4.98]],"id":63579394},{"atb":[[1.6,0],[1.54,7.59],[1.75,0]],"id":69769647},{"atl":[[3.8,9.68]],"id":69769647}],"con":true,"img":false}]}
{"op":"mcm","clk":"11541366198","pt":1719505011953,"mc":[{"id":"1.230178325","rc":[{"atl":[[5.8,6.25]],"id":70902602},{"atb":[[2.8,0],[2.84,7]],"id":57055802}],"con":true,"img":false}]}
{"op":"mcm","clk":"11541366208","pt":1719505012051,"mc":[{"id":"1.230178325","rc":[{"atb":[[2.82,13.95]],"id":57055802}],"con":true,"img":false}]}
{"op":"mcm","clk":"11541366217","pt":1719505012158,"mc":[{"id":"1.230178325","rc":[{"atb":[[2.84,2]],"id":57055802},{"atb":[[2.9,12.99]],"id":45129701}],"con":true,"img":false}]}
{"op":"mcm","clk":"11541366250","pt":1719505012675,"mc":[{"id":"1.230178325","rc":[{"atb":[[2.56,4.88]],"id":70902602},{"atl":[[4,8.88]],"id":63579394},{"atl":[[4.1,10.16]],"id":40626946},{"atb":[[2.92,12.53]],"id":45129701}],"con":true,"img":false}]}
{"op":"mcm","clk":"11541366268","pt":1719505012883,"mc":[{"id":"1.230178325","rc":[{"atb":[[2.5,0],[2.36,0]],"id":70902602},{"atl":[[4.2,8.04]],"id":63579394},{"atl":[[4.3,0]],"id":40626946},{"atb":[[2.86,0]],"id":45129701}],"con":true,"img":false}]}
{"op":"mcm","clk":"11541366307","pt":1719505013351,"mc":[{"id":"1.230178325","rc":[{"atl":[[4.2,7.2]],"id":63579394},{"atl":[[4,0.84],[4.4,13.56]],"id":40626946}],"con":true,"img":false}]}
{"op":"mcm","clk":"11541366322","pt":1719505013558,"mc":[{"id":"1.230178325","rc":[{"atl":[[4.2,11.85]],"id":40626946},{"atb":[[2.9,2]],"id":45129701}],"con":true,"img":false}]}
{"op":"mcm","clk":"11541366330","pt":1719505013663,"mc":[{"id":"1.230178325","rc":[{"atb":[[1.66,0]],"id":69769647},{"atl":[[4.1,0],[3.8,10.68]],"id":69769647},{"atl":[[6.8,0],[7,1]],"id":57055802},{"atl":[[4.6,0],[4.4,0]],"id":40626946},{"atl":[[5.6,1]],"id":45129701}],"con":true,"img":false}]}
{"op":"mcm","clk":"11541366340","pt":1719505013768,"mc":[{"id":"1.230178325","rc":[{"atl":[[4.1,22.22],[4.2,0]],"id":63579394},{"atl":[[7,12.78]],"id":57055802},{"atb":[[2.82,0],[2.8,18.53]],"id":45129701},{"atl":[[5.2,21.78]],"id":45129701}],"con":true,"img":false}]}
{"op":"mcm","clk":"11541366349","pt":1719505013874,"mc":[{"id":"1.230178325","rc":[{"atl":[[7.6,2.5]],"id":57055802}],"con":true,"img":false}]}
{"op":"mcm","clk":"11541366358","pt":1719505013978,"mc":[{"id":"1.230178325","rc":[{"atl":[[4.1,4.44],[4.2,31.11]],"id":63579394},{"atl":[[7.6,17.65],[7,1]],"id":57055802},{"atb":[[2.8,2.5],[2.82,10]],"id":45129701}],"con":true,"img":false}]}
{"op":"mcm","clk":"11541366377","pt":1719505014185,"mc":[{"id":"1.230178325","rc":[{"atb":[[1.66,1]],"id":69769647}],"con":true,"img":false}]}
{"op":"mcm","clk":"11541366388","pt":1719505014289,"mc":[{"id":"1.230178325","rc":[{"atl":[[4.1,0]],"id":63579394},{"atb":[[2.92,24.42]],"id":45129701}],"con":true,"img":false}]}
{"op":"mcm","clk":"11541366412","pt":1719505014549,"mc":[{"id":"1.230178325","rc":[{"atb":[[2.5,2.11]],"id":63579394},{"atb":[[2.9,0]],"id":45129701}],"con":true,"img":false}]}
{"op":"mcm","clk":"11541366421","pt":1719505014653,"mc":[{"id":"1.230178325","rc":[{"atb":[[2.94,2]],"id":45129701}],"con":true,"img":false}]}
{"op":"mcm","clk":"11541366429","pt":1719505014759,"mc":[{"id":"1.230178325","rc":[{"atl":[[5.6,1],[5.7,10]],"id":63579394},{"atl":[[6.8,1],[7,0]],"id":57055802},{"atl":[[5.6,0],[5.2,22.78]],"id":45129701}],"con":true,"img":false}]}
{"op":"mcm","clk":"11541366454","pt":1719505015073,"mc":[{"id":"1.230178325","rc":[{"atb":[[2.54,0]],"id":70902602}],"con":true,"img":false}]}
{"op":"mcm","clk":"11541366460","pt":1719505015177,"mc":[{"id":"1.230178325","rc":[{"atb":[[2.58,2]],"id":70902602},{"atb":[[2.92,23.3]],"id":45129701}],"con":true,"img":false}]}
{"op":"mcm","clk":"11541366465","pt":1719505015281,"mc":[{"id":"1.230178325","rc":[{"atb":[[2.6,4.88],[2.56,0]],"id":70902602}],"con":true,"img":false}]}
{"op":"mcm","clk":"11541366480","pt":1719505015488,"mc":[{"id":"1.230178325","rc":[{"atl":[[4.1,4.31]],"id":63579394},{"atb":[[2.92,12.53]],"id":45129701}],"con":true,"img":false}]}
{"op":"mcm","clk":"11541366489","pt":1719505015593,"mc":[{"id":"1.230178325","rc":[{"atb":[[1.66,0]],"id":69769647},{"atb":[[2.94,12.77]],"id":45129701}],"con":true,"img":false}]}
{"op":"mcm","clk":"11541366523","pt":1719505015960,"mc":[{"id":"1.230178325","rc":[{"atl":[[4.1,0]],"id":63579394},{"atb":[[1.66,1]],"id":69769647}],"con":true,"img":false}]}
{"op":"mcm","clk":"11541366551","pt":1719505016270,"mc":[{"id":"1.230178325","rc":[{"atl":[[4,13.58]],"id":63579394}],"con":true,"img":false}]}
{"op":"mcm","clk":"11541366598","pt":1719505016850,"mc":[{"id":"1.230178325","rc":[{"atb":[[1.74,5.82],[1.66,0]],"id":69769647}],"con":true,"img":false}]}
{"op":"mcm","clk":"11541366610","pt":1719505016954,"mc":[{"id":"1.230178325","rc":[{"atb":[[2.58,0]],"id":70902602},{"atb":[[1.74,2]],"id":69769647}],"con":true,"img":false}]}
{"op":"mcm","clk":"11541366619","pt":1719505017056,"mc":[{"id":"1.230178325","rc":[{"atb":[[2.62,2]],"id":70902602}],"con":true,"img":false}]}
{"op":"mcm","clk":"11541366629","pt":1719505017161,"mc":[{"id":"1.230178325","rc":[{"atb":[[2.6,0],[2.64,4.88],[2.52,0]],"id":70902602},{"atb":[[2.82,11.36]],"id":57055802},{"atb":[[2.88,0]],"id":45129701}],"con":true,"img":false}]}
{"op":"mcm","clk":"11541366637","pt":1719505017267,"mc":[{"id":"1.230178325","rc":[{"atb":[[2.62,4]],"id":70902602},{"atb":[[2.84,6]],"id":57055802},{"atb":[[2.96,3]],"id":45129701}],"con":true,"img":false}]}
{"op":"mcm","clk":"11541366663","pt":1719505017475,"mc":[{"id":"1.230178325","rc":[{"atb":[[2.82,6.36],[2.86,6]],"id":57055802},{"atb":[[2.94,2]],"id":45129701}],"con":true,"img":false}]}
{"op":"mcm","clk":"11541366702","pt":1719505017996,"mc":[{"id":"1.230178325","rc":[{"atb":[[2.94,0]],"id":45129701}],"con":true,"img":false}]}
{"op":"mcm","clk":"11541366713","pt":1719505018051,"mc":[{"id":"1.230178325","rc":[{"atb":[[1.02,13.23]],"id":45129701}],"con":true,"img":false}]}
{"op":"mcm","clk":"11541366748","pt":1719505018369,"mc":[{"id":"1.230178325","rc":[{"atb":[[2.62,2]],"id":70902602}],"con":true,"img":false}]}
{"op":"mcm","clk":"11541366760","pt":1719505018470,"mc":[{"id":"1.230178325","rc":[{"atb":[[2.66,2]],"id":70902602}],"con":true,"img":false}]}
{"op":"mcm","clk":"11541366789","pt":1719505018774,"mc":[{"id":"1.230178325","rc":[{"atb":[[2.3,2.11],[1.56,0]],"id":70902602},{"atb":[[2.84,4]],"id":57055802}],"con":true,"img":false}]}
{"op":"mcm","clk":"11541366799","pt":1719505018879,"mc":[{"id":"1.230178325","rc":[{"atb":[[2.88,2]],"id":57055802}],"con":true,"img":false}]}
{"op":"mcm","clk":"11541366807","pt":1719505018982,"mc":[{"id":"1.230178325","rc":[{"atb":[[2.96,14.19]],"id":45129701}],"con":true,"img":false}]}
{"op":"mcm","clk":"11541366824","pt":1719505019085,"mc":[{"id":"1.230178325","rc":[{"atl":[[5.3,23.26],[5.2,1]],"id":45129701}],"con":true,"img":false}]}
{"op":"mcm","clk":"11541366870","pt":1719505019559,"mc":[{"id":"1.230178325","rc":[{"atb":[[2.66,14.27]],"id":70902602},{"atl":[[4.1,9.12]],"id":70902602}],"con":true,"img":false}]}
{"op":"mcm","clk":"11541366885","pt":1719505019765,"mc":[{"id":"1.230178325","rc":[{"atl":[[4,1]],"id":70902602}],"con":true,"img":false}]}
{"op":"mcm","clk":"11541366909","pt":1719505019974,"mc":[{"id":"1.230178325","rc":[{"atl":[[4.2,0]],"id":70902602}],"con":true,"img":false}]}
{"op":"mcm","clk":"11541366921","pt":1719505020078,"mc":[{"id":"1.230178325","rc":[{"atb":[[1.66,1]],"id":69769647}],"con":true,"img":false}]}
{"op":"mcm","clk":"11541366964","pt":1719505020494,"mc":[{"id":"1.230178325","rc":[{"atb":[[2.88,9.42]],"id":57055802}],"con":true,"img":false}]}
{"op":"mcm","clk":"11541366983","pt":1719505020657,"mc":[{"id":"1.230178325","rc":[{"atb":[[2.82,0]],"id":57055802}],"con":true,"img":false}]}
{"op":"mcm","clk":"11541367009","pt":1719505020969,"mc":[{"id":"1.230178325","rc":[{"atl":[[5.6,0]],"id":63579394}],"con":true,"img":false}]}
{"op":"mcm","clk":"11541367035","pt":1719505021285,"mc":[{"id":"1.230178325","rc":[{"atl":[[4,8.88]],"id":63579394}],"con":true,"img":false}]}
{"op":"mcm","clk":"11541367047","pt":1719505021393,"mc":[{"id":"1.230178325","rc":[{"atl":[[4.9,28.14]],"id":63579394}],"con":true,"img":false}]}
{"op":"mcm","clk":"11541367059","pt":1719505021452,"mc":[{"id":"1.230178325","rc":[{"atl":[[5.7,11],[4.2,0]],"id":63579394}],"con":true,"img":false}]}
{"op":"mcm","clk":"11541367093","pt":1719505021762,"mc":[{"id":"1.230178325","rc":[{"atl":[[4.2,2.33]],"id":63579394}],"con":true,"img":false}]}
{"op":"mcm","clk":"11541367123","pt":1719505022075,"mc":[{"id":"1.230178325","rc":[{"atl":[[4.2,0]],"id":63579394}],"con":true,"img":false}]}
{"op":"mcm","clk":"11541367152","pt":1719505022391,"mc":[{"id":"1.230178325","rc":[{"atl":[[4.1,4.62]],"id":63579394}],"con":true,"img":false}]}
{"op":"mcm","clk":"11541367293","pt":1719505023858,"mc":[{"id":"1.230178325","rc":[{"atb":[[1.67,0]],"id":69769647},{"atb":[[2.2,2.5]],"id":40626946},{"atl":[[5.1,5.6]],"id":45129701}],"con":true,"img":false}]}
{"op":"mcm","clk":"11541367316","pt":1719505024066,"mc":[{"id":"1.230178325","rc":[{"atl":[[4,0],[4.1,0.1]],"id":70902602},{"trd":[[4.1,18.02],[4,1.99]],"ltp":4.1,"tv":20.0,"id":70902602},{"atl":[[4.9,1]],"id":40626946}],"con":true,"img":false}]}
{"op":"mcm","clk":"11541367328","pt":1719505024174,"mc":[{"id":"1.230178325","rc":[{"atb":[[2.68,1]],"id":70902602}],"con":true,"img":false}]}
{"op":"mcm","clk":"11541367339","pt":1719505024274,"mc":[{"id":"1.230178325","rc":[{"atb":[[2.68,2]],"id":70902602}],"con":true,"img":false}]}
{"op":"mcm","clk":"11541367348","pt":1719505024380,"mc":[{"id":"1.230178325","rc":[{"atb":[[2.68,8.28]],"id":70902602},{"atl":[[4,11.92]],"id":40626946},{"atb":[[2.98,16.9]],"id":45129701}],"con":true,"img":false}]}
{"op":"mcm","clk":"11541367360","pt":1719505024485,"mc":[{"id":"1.230178325","rc":[{"atb":[[2.64,0]],"id":70902602},{"atb":[[2.92,0]],"id":45129701}],"con":true,"img":false}]}
{"op":"mcm","clk":"11541367373","pt":1719505024589,"mc":[{"id":"1.230178325","rc":[{"atl":[[4.1,0]],"id":40626946}],"con":true,"img":false}]}
{"op":"mcm","clk":"11541367381","pt":1719505024693,"mc":[{"id":"1.230178325","rc":[{"atb":[[2.66,2],[2.7,1.94]],"id":70902602},{"atb":[[2.9,1.94]],"id":57055802},{"atb":[[2.24,1.94]],"id":40626946},{"atl":[[4.4,23.79],[4.2,0.84]],"id":40626946},{"atb":[[3,1.94],[2.96,3]],"id":45129701}],"con":true,"img":false}]}
{"op":"mcm","clk":"11541367391","pt":1719505024798,"mc":[{"id":"1.230178325","rc":[{"atb":[[2.9,7.94],[2.86,0]],"id":57055802},{"atb":[[2.24,11.15]],"id":40626946}],"con":true,"img":false}]}
{"op":"mcm","clk":"11541367403","pt":1719505024854,"mc":[{"id":"1.230178325","rc":[{"atl":[[5.5,0.84]],"id":70902602},{"atb":[[2.88,15.42]],"id":57055802},{"atb":[[2.22,3]],"id":40626946},{"atl":[[4.2,0]],"id":40626946},{"atl":[[5.1,10.95]],"id":45129701}],"con":true,"img":false}]}
{"op":"mcm","clk":"11541367412","pt":1719505024982,"mc":[{"id":"1.230178325","rc":[{"atb":[[2.9,1.94]],"id":57055802}],"con":true,"img":false}]}
{"op":"mcm","clk":"11541367423","pt":1719505025077,"mc":[{"id":"1.230178325","rc":[{"atb":[[2.68,7.28]],"id":70902602}],"con":true,"img":false}]}
{"op":"mcm","clk":"11541367451","pt":1719505025373,"mc":[{"id":"1.230178325","rc":[{"atb":[[2.7,14.5]],"id":70902602},{"atb":[[3,12.33]],"id":45129701}],"con":true,"img":false}]}
{"op":"mcm","clk":"11541367462","pt":1719505025476,"mc":[{"id":"1.230178325","rc":[{"atb":[[2.66,0]],"id":70902602}],"con":true,"img":false}]}
{"op":"mcm","clk":"11541367471","pt":1719505025582,"mc":[{"id":"1.230178325","rc":[{"atb":[[2.7,16.5]],"id":70902602}],"con":true,"img":false}]}
{"op":"mcm","clk":"11541367493","pt":1719505025902,"mc":[{"id":"1.230178325","rc":[{"atb":[[2.62,0]],"id":70902602},{"atb":[[2.52,2]],"id":63579394},{"atb":[[1.73,0]],"id":69769647},{"atb":[[2.84,0]],"id":57055802},{"atb":[[2.22,0]],"id":40626946},{"atb":[[2.96,0]],"id":45129701}],"con":true,"img":false}]}
{"op":"mcm","clk":"11541367517","pt":1719505026062,"mc":[{"id":"1.230178325","rc":[{"atb":[[2.72,3]],"id":70902602},{"atb":[[2.9,4.44]],"id":57055802},{"atb":[[2.26,3.41]],"id":40626946},{"atb":[[3.05,3.04]],"id":45129701}],"con":true,"img":false}]}
{"op":"mcm","clk":"11541367580","pt":1719505026694,"mc":[{"id":"1.230178325","rc":[{"atl":[[4.9,2.5],[4.2,13.51]],"id":63579394}],"con":true,"img":false}]}
{"op":"mcm","clk":"11541367603","pt":1719505026867,"mc":[{"id":"1.230178325","rc":[{"atb":[[2.72,7.88]],"id":70902602},{"atb":[[1.74,0]],"id":69769647}],"con":true,"img":false}]}
{"op":"mcm","clk":"11541367614","pt":1719505026962,"mc":[{"id":"1.230178325","rc":[{"atl":[[5.6,0],[6,0],[6.8,0],[5.7,1]],"id":70902602},{"atb":[[1.7,2],[1.66,0],[1.69,5.86]],"id":69769647}],"con":true,"img":false}]}
{"op":"mcm","clk":"11541367626","pt":1719505027073,"mc":[{"id":"1.230178325","rc":[{"atb":[[2.74,1],[2.68,1]],"id":70902602}],"con":true,"img":false}]}
{"op":"mcm","clk":"11541367668","pt":1719505027482,"mc":[{"id":"1.230178325","rc":[{"atb":[[2.7,14.5]],"id":70902602},{"atl":[[5.5,0]],"id":70902602}],"con":true,"img":false}]}
{"op":"mcm","clk":"11541367676","pt":1719505027586,"mc":[{"id":"1.230178325","rc":[{"atb":[[2.74,3]],"id":70902602}],"con":true,"img":false}]}
{"op":"mcm","clk":"11541367684","pt":1719505027692,"mc":[{"id":"1.230178325","rc":[{"atl":[[8.6,10],[7,2.5],[7.8,5]],"id":70902602}],"con":true,"img":false}]}
{"op":"mcm","clk":"11541367693","pt":1719505027796,"mc":[{"id":"1.230178325","rc":[{"atb":[[2.7,12.56]],"id":70902602},{"atb":[[2.24,9.21]],"id":40626946},{"atb":[[3,10.39]],"id":45129701}],"con":true,"img":false}]}
{"op":"mcm","clk":"11541367701","pt":1719505027902,"mc":[{"id":"1.230178325","rc":[{"atb":[[2.7,0]],"id":70902602},{"atl":[[4,17.77],[4.2,0]],"id":63579394},{"atb":[[2.88,13.42]],"id":57055802},{"atb":[[3,0]],"id":45129701}],"con":true,"img":false}]}
{"op":"mcm","clk":"11541367712","pt":1719505027962,"mc":[{"id":"1.230178325","rc":[{"atl":[[4,8.88],[4.2,22.4]],"id":63579394},{"atb":[[2.74,4.94]],"id":70902602},{"atb":[[2.92,2]],"id":57055802},{"atb":[[2.28,1.94]],"id":40626946},{"atb":[[3.1,1.94]],"id":45129701}],"con":true,"img":false}]}
{"op":"mcm","clk":"11541367751","pt":1719505028062,"mc":[{"id":"1.230178325","rc":[{"atl":[[4,17.77],[4.2,0]],"id":63579394},{"atb":[[1.64,1]],"id":69769647}],"con":true,"img":false}]}
{"op":"mcm","clk":"11541367784","pt":1719505028269,"mc":[{"id":"1.230178325","rc":[{"atl":[[4,8.88],[4.2,22.4]],"id":63579394}],"con":true,"img":false}]}
{"op":"mcm","clk":"11541367828","pt":1719505028794,"mc":[{"id":"1.230178325","rc":[{"atb":[[2.74,9.4]],"id":70902602}],"con":true,"img":false}]}
{"op":"mcm","clk":"11541367838","pt":1719505028897,"mc":[{"id":"1.230178325","rc":[{"atl":[[4.1,0]],"id":63579394}],"con":true,"img":false}]}
{"op":"mcm","clk":"11541367846","pt":1719505029004,"mc":[{"id":"1.230178325","rc":[{"atb":[[2.72,3]],"id":70902602}],"con":true,"img":false}]}
{"op":"mcm","clk":"11541367865","pt":1719505029180,"mc":[{"id":"1.230178325","rc":[{"atb":[[2.8,2.5],[2.72,8],[2.32,0],[2.64,10],[2.24,0],[2.16,0]],"id":70902602},{"atl":[[5.1,5],[4.7,2.5]],"id":63579394},{"atl":[[4.3,0],[3.95,0],[3.35,2.5],[3.55,12.17]],"id":69769647},{"atb":[[2.04,0],[2.12,0],[2.24,11.71],[2.2,0]],"id":40626946},{"atb":[[2.82,12.5]],"id":45129701}],"con":true,"img":false}]}
{"op":"mcm","clk":"11541367872","pt":1719505029266,"mc":[{"id":"1.230178325","rc":[{"atl":[[5.3,0],[4.9,0],[5.7,1]],"id":63579394},{"atl":[[3.5,3.38]],"id":69769647},{"atb":[[2.8,0],[2.72,0],[2.64,0]],"id":45129701}],"con":true,"img":false}]}
{"op":"mcm","clk":"11541367879","pt":1719505029369,"mc":[{"id":"1.230178325","rc":[{"atb":[[2.74,8.4]],"id":70902602},{"atl":[[3.45,5],[3.8,1],[3.55,5.84]],"id":69769647}],"con":true,"img":false}]}
{"op":"mcm","clk":"11541367889","pt":1719505029472,"mc":[{"id":"1.230178325","rc":[{"atl":[[3.45,0],[3.55,16.52]],"id":69769647}],"con":true,"img":false}]}
{"op":"mcm","clk":"11541367907","pt":1719505029682,"mc":[{"id":"1.230178325","rc":[{"atl":[[4.2,24.99]],"id":63579394}],"con":true,"img":false}]}
{"op":"mcm","clk":"11541367921","pt":1719505029891,"mc":[{"id":"1.230178325","rc":[{"atb":[[1.64,0]],"id":69769647},{"atl":[[3.55,15.68],[3.3,0.84]],"id":69769647}],"con":true,"img":false}]}
{"op":"mcm","clk":"11541367940","pt":1719505030099,"mc":[{"id":"1.230178325","rc":[{"atb":[[1.64,1]],"id":69769647}],"con":true,"img":false}]}
{"op":"mcm","clk":"11541367948","pt":1719505030204,"mc":[{"id":"1.230178325","rc":[{"atb":[[2.92,6.45],[2.88,7.42]],"id":57055802}],"con":true,"img":false}]}
{"op":"mcm","clk":"11541367959","pt":1719505030278,"mc":[{"id":"1.230178325","rc":[{"atb":[[2.74,22.26]],"id":70902602},{"atb":[[3.1,11.77]],"id":45129701}],"con":true,"img":false}]}
{"op":"mcm","clk":"11541368006","pt":1719505030780,"mc":[{"id":"1.230178325","rc":[{"atb":[[2.74,20.32]],"id":70902602},{"atb":[[2.9,2.5]],"id":57055802},{"atb":[[2.28,0]],"id":40626946}],"con":true,"img":false}]}
{"op":"mcm","clk":"11541368024","pt":1719505030991,"mc":[{"id":"1.230178325","rc":[{"atb":[[2.82,1.94]],"id":70902602},{"atb":[[2.94,1.94]],"id":57055802},{"atb":[[2.28,1.94]],"id":40626946}],"con":true,"img":false}]}
{"op":"mcm","clk":"11541368034","pt":1719505031097,"mc":[{"id":"1.230178325","rc":[{"atb":[[2.74,19.9]],"id":70902602}],"con":true,"img":false}]}
{"op":"mcm","clk":"11541368043","pt":1719505031202,"mc":[{"id":"1.230178325","rc":[{"atb":[[2.22,0]],"id":70902602}],"con":true,"img":false}]}
{"op":"mcm","clk":"11541368053","pt":1719505031307,"mc":[{"id":"1.230178325","rc":[{"atl":[[5.6,3.34]],"id":70902602},{"atl":[[4.2,22.4]],"id":63579394}],"con":true,"img":false}]}
{"op":"mcm","clk":"11541368063","pt":1719505031381,"mc":[{"id":"1.230178325","rc":[{"atb":[[2.84,1],[2.74,6.46]],"id":70902602}],"con":true,"img":false}]}
{"op":"mcm","clk":"11541368072","pt":1719505031470,"mc":[{"id":"1.230178325","rc":[{"atb":[[2.8,15.94]],"id":70902602},{"atl":[[4.2,27.15]],"id":63579394}],"con":true,"img":false}]}
{"op":"mcm","clk":"11541368103","pt":1719505031788,"mc":[{"id":"1.230178325","rc":[{"atl":[[4.2,22.4]],"id":63579394}],"con":true,"img":false}]}
{"op":"mcm","clk":"11541368115","pt":1719505031895,"mc":[{"id":"1.230178325","rc":[{"atl":[[5.5,0.84]],"id":70902602}],"con":true,"img":false}]}
{"op":"mcm","clk":"11541368125","pt":1719505031998,"mc":[{"id":"1.230178325","rc":[{"atl":[[3.3,3.38]],"id":69769647},{"atb":[[2.94,8.23]],"id":57055802}],"con":true,"img":false}]}
{"op":"mcm","clk":"11541368138","pt":1719505032106,"mc":[{"id":"1.230178325","rc":[{"atl":[[4.1,4.8]],"id":63579394},{"atb":[[1.64,0],[1.63,3.5],[1.69,2.11]],"id":69769647},{"atl":[[3.25,3.38]],"id":69769647},{"atb":[[2.92,2],[2.96,6.45]],"id":57055802}],"con":true,"img":false}]}
{"op":"mcm","clk":"11541368152","pt":1719505032164,"mc":[{"id":"1.230178325","rc":[{"atb":[[2.5,6.93]],"id":63579394},{"atl":[[3.55,5]],"id":69769647},{"atb":[[2.88,0]],"id":57055802}],"con":true,"img":false}]}
{"op":"mcm","clk":"11541368163","pt":1719505032272,"mc":[{"id":"1.230178325","rc":[{"atb":[[2.94,21.13]],"id":57055802}],"con":true,"img":false}]}
{"op":"mcm","clk":"11541368173","pt":1719505032374,"mc":[{"id":"1.230178325","rc":[{"atb":[[2.5,5.73]],"id":63579394},{"atb":[[2.8,2.5]],"id":70902602},{"atb":[[2.96,0]],"id":57055802}],"con":true,"img":false}]}
{"op":"mcm","clk":"11541368201","pt":1719505032793,"mc":[{"id":"1.230178325","rc":[{"atb":[[2.74,4.46]],"id":70902602}],"con":true,"img":false}]}
{"op":"mcm","clk":"11541368211","pt":1719505032899,"mc":[{"id":"1.230178325","rc":[{"atb":[[1.02,2]],"id":70902602}],"con":true,"img":false}]}
{"op":"mcm","clk":"11541368230","pt":1719505033112,"mc":[{"id":"1.230178325","rc":[{"atb":[[1.65,5.54]],"id":69769647},{"atb":[[2.22,4.17]],"id":40626946}],"con":true,"img":false}]}
{"op":"mcm","clk":"11541368241","pt":1719505033169,"mc":[{"id":"1.230178325","rc":[{"atb":[[2.84,14.44]],"id":70902602}],"con":true,"img":false}]}
{"op":"mcm","clk":"11541368289","pt":1719505033666,"mc":[{"id":"1.230178325","rc":[{"atb":[[2.92,0]],"id":57055802}],"con":true,"img":false}]}
{"op":"mcm","clk":"11541368298","pt":1719505033772,"mc":[{"id":"1.230178325","rc":[{"atb":[[2.98,2]],"id":57055802}],"con":true,"img":false}]}
{"op":"mcm","clk":"11541368307","pt":1719505033876,"mc":[{"id":"1.230178325","rc":[{"atb":[[2.82,0]],"id":70902602},{"atb":[[2.28,0]],"id":40626946}],"con":true,"img":false}]}
{"op":"mcm","clk":"11541368316","pt":1719505033979,"mc":[{"id":"1.230178325","rc":[{"atb":[[2.84,13.44]],"id":70902602}],"con":true,"img":false}]}
{"op":"mcm","clk":"11541368330","pt":1719505034083,"mc":[{"id":"1.230178325","rc":[{"atb":[[2.86,1.94]],"id":70902602},{"atb":[[2.28,1.94]],"id":40626946}],"con":true,"img":false}]}
{"op":"mcm","clk":"11541368364","pt":1719505034503,"mc":[{"id":"1.230178325","rc":[{"atb":[[2.72,5]],"id":70902602},{"atb":[[2.9,0]],"id":57055802},{"atb":[[2.26,0]],"id":40626946},{"atb":[[3.05,0]],"id":45129701}],"con":true,"img":false}]}
{"op":"mcm","clk":"11541368375","pt":1719505034610,"mc":[{"id":"1.230178325","rc":[{"atb":[[2.84,11.01],[2.86,4.94]],"id":70902602},{"atb":[[2.98,5.1]],"id":57055802},{"atb":[[2.28,4.44]],"id":40626946},{"atb":[[3.15,3.4]],"id":45129701}],"con":true,"img":false}]}
{"op":"mcm","clk":"11541368392","pt":1719505034779,"mc":[{"id":"1.230178325","rc":[{"atb":[[2.84,0]],"id":70902602}],"con":true,"img":false}]}
{"op":"mcm","clk":"11541368401","pt":1719505034875,"mc":[{"id":"1.230178325","rc":[{"atb":[[2.86,15.95]],"id":70902602},{"atl":[[3.3,0.84]],"id":69769647}],"con":true,"img":false}]}
{"op":"mcm","clk":"11541368443","pt":1719505035288,"mc":[{"id":"1.230178325","rc":[{"atb":[[1.43,0],[1.37,9.46]],"id":70902602},{"atb":[[1.63,2.5]],"id":69769647},{"atl":[[3.8,0]],"id":69769647},{"atl":[[7.2,1],[6.8,0],[7,1]],"id":57055802},{"atl":[[4.8,1],[4.9,0]],"id":40626946},{"atl":[[5.2,0],[5.7,1]],"id":45129701}],"con":true,"img":false}]}
{"op":"mcm","clk":"11541368453","pt":1719505035393,"mc":[{"id":"1.230178325","rc":[{"atl":[[7.2,7.89],[7.6,2.5]],"id":57055802}],"con":true,"img":false}]}
{"op":"mcm","clk":"11541368465","pt":1719505035497,"mc":[{"id":"1.230178325","rc":[{"atb":[[1.76,8.65]],"id":40626946},{"atb":[[3.1,1.94]],"id":45129701}],"con":true,"img":false}]}
{"op":"mcm","clk":"11541368478","pt":1719505035603,"mc":[{"id":"1.230178325","rc":[{"atb":[[1.37,0],[1.43,9.46]],"id":70902602},{"atb":[[1.83,0]],"id":40626946}],"con":true,"img":false}]}
{"op":"mcm","clk":"11541368489","pt":1719505035708,"mc":[{"id":"1.230178325","rc":[{"atb":[[2.88,1]],"id":70902602}],"con":true,"img":false}]}
{"op":"mcm","clk":"11541368500","pt":1719505035779,"mc":[{"id":"1.230178325","rc":[{"atb":[[2.88,5.38]],"id":70902602},{"atl":[[3.95,12.12]],"id":40626946},{"atb":[[3.15,14.17]],"id":45129701}],"con":true,"img":false}]}
{"op":"mcm","clk":"11541368511","pt":1719505035890,"mc":[{"id":"1.230178325","rc":[{"atb":[[2.68,0]],"id":70902602},{"atl":[[5.5,1.37]],"id":70902602}],"con":true,"img":false}]}
{"op":"mcm","clk":"11541368521","pt":1719505035983,"mc":[{"id":"1.230178325","rc":[{"atb":[[2.74,0],[2.9,1],[1.04,0.52]],"id":70902602},{"atl":[[4.1,0]],"id":63579394},{"atl":[[4,0.84]],"id":40626946},{"atb":[[2.98,0]],"id":45129701}],"con":true,"img":false}]}
{"op":"mcm","clk":"11541368533","pt":1719505036094,"mc":[{"id":"1.230178325","rc":[{"atb":[[2.86,4.94]],"id":70902602},{"atl":[[3.75,3.5]],"id":69769647},{"atl":[[7.2,6.89]],"id":57055802},{"atl":[[5.8,1],[5.7,0]],"id":45129701}],"con":true,"img":false}]}
{"op":"mcm","clk":"11541368544","pt":1719505036188,"mc":[{"id":"1.230178325","rc":[{"atb":[[1.04,0.27]],"id":70902602},{"atl":[[4.2,0],[4.7,29.53]],"id":63579394},{"atb":[[2.28,16.56]],"id":40626946}],"con":true,"img":false}]}
{"op":"mcm","clk":"11541368553","pt":1719505036293,"mc":[{"id":"1.230178325","rc":[{"atb":[[2.24,2.49]],"id":40626946},{"atl":[[3.9,0.84]],"id":40626946},{"atb":[[3.15,26]],"id":45129701}],"con":true,"img":false}]}
{"op":"mcm","clk":"11541368564","pt":1719505036396,"mc":[{"id":"1.230178325","rc":[{"atb":[[1.04,0]],"id":70902602},{"atl":[[4,13.81],[4.4,0]],"id":40626946}],"con":true,"img":false}]}
{"op":"mcm","clk":"11541368575","pt":1719505036500,"mc":[{"id":"1.230178325","rc":[{"atb":[[2.88,5.65]],"id":70902602}],"con":true,"img":false}]}
{"op":"mcm","clk":"11541368586","pt":1719505036602,"mc":[{"id":"1.230178325","rc":[{"atl":[[3.95,4.79]],"id":63579394}],"con":true,"img":false}]}
{"op":"mcm","clk":"11541368598","pt":1719505036707,"mc":[{"id":"1.230178325","rc":[{"atl":[[3.9,9.63],[4.2,13.68],[4.7,2.5]],"id":63579394},{"atb":[[2.22,3.55]],"id":40626946}],"con":true,"img":false}]}
{"op":"mcm","clk":"11541368618","pt":1719505036894,"mc":[{"id":"1.230178325","rc":[{"atl":[[4,0.84]],"id":63579394},{"atb":[[2.84,3.13],[2.9,14.52],[2.86,3]],"id":70902602},{"atb":[[2.94,19.19]],"id":57055802},{"atb":[[3.1,0]],"id":45129701}],"con":true,"img":false}]}
{"op":"mcm","clk":"11541368641","pt":1719505037078,"mc":[{"id":"1.230178325","rc":[{"atb":[[2.9,16.46]],"id":70902602},{"atl":[[5.8,7.25],[5.7,0]],"id":70902602},{"atl":[[3.95,0]],"id":63579394},{"atb":[[1.59,0],[1.63,0],[1.55,0]],"id":69769647},{"atl":[[3.55,6],[3.75,2.5]],"id":69769647},{"atb":[[3,1.94]],"id":57055802},{"atb":[[3.2,1.94]],"id":45129701}],"con":true,"img":false}]}
{"op":"mcm","clk":"11541368663","pt":1719505037285,"mc":[{"id":"1.230178325","rc":[{"atl":[[3.85,0.84],[3.9,0]],"id":63579394},{"atl":[[3.2,0.84],[3.35,6.73],[3.25,0]],"id":69769647}],"con":true,"img":false}]}
{"op":"mcm","clk":"11541368673","pt":1719505037388,"mc":[{"id":"1.230178325","rc":[{"atl":[[4,0],[3.95,9.63],[4.1,4.99]],"id":63579394}],"con":true,"img":false}]}
{"op":"mcm","clk":"11541368684","pt":1719505037492,"mc":[{"id":"1.230178325","rc":[{"atb":[[3,7.04],[2.94,6.29]],"id":57055802}],"con":true,"img":false}]}
{"op":"mcm","clk":"11541368694","pt":1719505037596,"mc":[{"id":"1.230178325","rc":[{"atb":[[2.22,0]],"id":40626946}],"con":true,"img":false}]}
{"op":"mcm","clk":"11541368703","pt":1719505037702,"mc":[{"id":"1.230178325","rc":[{"atl":[[3.2,3.38]],"id":69769647}],"con":true,"img":false}]}
{"op":"mcm","clk":"11541368711","pt":1719505037805,"mc":[{"id":"1.230178325","rc":[{"atl":[[3.35,2.49],[3.15,3.39]],"id":69769647},{"atb":[[2.8,3.38],[3.15,23.32]],"id":45129701}],"con":true,"img":false}]}
{"op":"mcm","clk":"11541368722","pt":1719505037910,"mc":[{"id":"1.230178325","rc":[{"atl":[[3.85,0]],"id":63579394},{"atl":[[3.2,2.53]],"id":69769647},{"atb":[[2.8,0]],"id":45129701}],"con":true,"img":false}]}
{"op":"mcm","clk":"11541368732","pt":1719505037974,"mc":[{"id":"1.230178325","rc":[{"atb":[[3.15,14.17]],"id":45129701}],"con":true,"img":false}]}
{"op":"mcm","clk":"11541368753","pt":1719505038072,"mc":[{"id":"1.230178325","rc":[{"atb":[[3.2,11.09]],"id":45129701}],"con":true,"img":false}]}
{"op":"mcm","clk":"11541368801","pt":1719505038277,"mc":[{"id":"1.230178325","rc":[{"atb":[[2.92,4.76]],"id":70902602}],"con":true,"img":false}]}
{"op":"mcm","clk":"11541368815","pt":1719505038483,"mc":[{"id":"1.230178325","rc":[{"atb":[[2.88,1.27],[2.9,15.46]],"id":70902602},{"atl":[[3.3,0]],"id":69769647},{"atb":[[2.98,3.1]],"id":57055802}],"con":true,"img":false}]}
{"op":"mcm","clk":"11541368819","pt":1719505038587,"mc":[{"id":"1.230178325","rc":[{"atb":[[2.9,13.18]],"id":70902602},{"atb":[[3.05,2]],"id":57055802}],"con":true,"img":false}]}
{"op":"mcm","clk":"11541368835","pt":1719505038711,"mc":[{"id":"1.230178325","rc":[{"atl":[[3.55,5],[3.5,4.38]],"id":69769647},{"atl":[[7.2,7.89]],"id":57055802}],"con":true,"img":false}]}
{"op":"mcm","clk":"11541368842","pt":1719505038804,"mc":[{"id":"1.230178325","rc":[{"atb":[[2.9,1.94]],"id":70902602},{"atl":[[7,0]],"id":57055802}],"con":true,"img":false}]}
{"op":"mcm","clk":"11541368860","pt":1719505038919,"mc":[{"id":"1.230178325","rc":[{"atb":[[2.92,16]],"id":70902602}],"con":true,"img":false}]}
{"op":"mcm","clk":"11541368889","pt":1719505039183,"mc":[{"id":"1.230178325","rc":[{"atl":[[3.2,0]],"id":69769647}],"con":true,"img":false}]}
{"op":"mcm","clk":"11541368897","pt":1719505039296,"mc":[{"id":"1.230178325","rc":[{"atl":[[3.45,1],[3.5,3.38]],"id":69769647},{"atl":[[7.2,6.89],[7.4,1]],"id":57055802},{"atl":[[4.8,0],[4.6,1]],"id":40626946},{"atl":[[5.8,0],[5.9,1]],"id":45129701}],"con":true,"img":false}]}
{"op":"mcm","clk":"11541368902","pt":1719505039388,"mc":[{"id":"1.230178325","rc":[{"atl":[[4.5,3.04]],"id":40626946}],"con":true,"img":false}]}
{"op":"mcm","clk":"11541368940","pt":1719505039911,"mc":[{"id":"1.230178325","rc":[{"atb":[[2.9,0]],"id":70902602}],"con":true,"img":false}]}
{"op":"mcm","clk":"11541368954","pt":1719505040015,"mc":[{"id":"1.230178325","rc":[{"atb":[[2.94,1.94]],"id":70902602}],"con":true,"img":false}]}
{"op":"mcm","clk":"11541368964","pt":1719505040075,"mc":[{"id":"1.230178325","rc":[{"atb":[[2.94,4.43],[2.92,4.76]],"id":70902602}],"con":true,"img":false}]}
{"op":"mcm","clk":"11541368974","pt":1719505040181,"mc":[{"id":"1.230178325","rc":[{"atb":[[2.92,0]],"id":70902602}],"con":true,"img":false}]}
{"op":"mcm","clk":"11541368991","pt":1719505040385,"mc":[{"id":"1.230178325","rc":[{"atl":[[5.3,0],[5.4,22.73]],"id":45129701}],"con":true,"img":false}]}
{"op":"mcm","clk":"11541368998","pt":1719505040489,"mc":[{"id":"1.230178325","rc":[{"atb":[[2.96,1]],"id":70902602},{"atl":[[7.2,0],[7.4,13.78]],"id":57055802},{"atl":[[4.5,2.04],[4.6,0],[4.4,1]],"id":40626946}],"con":true,"img":false}]}
{"op":"mcm","clk":"11541369005","pt":1719505040589,"mc":[{"id":"1.230178325","rc":[{"atl":[[3.1,3.46]],"id":69769647},{"atl":[[7.4,12.78],[7.6,3.5]],"id":57055802},{"atl":[[5.9,0]],"id":45129701}],"con":true,"img":false}]}
{"op":"mcm","clk":"11541369015","pt":1719505040694,"mc":[{"id":"1.230178325","rc":[{"atl":[[7.4,0],[7.6,18.65]],"id":57055802}],"con":true,"img":false}]}
{"op":"mcm","clk":"11541369022","pt":1719505040798,"mc":[{"id":"1.230178325","rc":[{"atl":[[3.5,0]],"id":69769647}],"con":true,"img":false}]}
{"op":"mcm","clk":"11541369032","pt":1719505040901,"mc":[{"id":"1.230178325","rc":[{"atb":[[2.96,11.74]],"id":70902602}],"con":true,"img":false}]}
{"op":"mcm","clk":"11541369038","pt":1719505041005,"mc":[{"id":"1.230178325","rc":[{"atl":[[7.6,17.65],[7.8,1]],"id":57055802},{"atl":[[4.4,0]],"id":40626946},{"atl":[[5.9,1]],"id":45129701}],"con":true,"img":false}]}
{"op":"mcm","clk":"11541369084","pt":1719505041584,"mc":[{"id":"1.230178325","rc":[{"atb":[[1.65,0]],"id":69769647}],"con":true,"img":false}]}
{"op":"mcm","clk":"11541369092","pt":1719505041686,"mc":[{"id":"1.230178325","rc":[{"atb":[[1.43,5],[1.39,10],[1.47,2.5]],"id":69769647}],"con":true,"img":false}]}
{"op":"mcm","clk":"11541369116","pt":1719505041890,"mc":[{"id":"1.230178325","rc":[{"atl":[[4,19.26],[4.2,0]],"id":63579394}],"con":true,"img":false}]}
{"op":"mcm","clk":"11541369225","pt":1719505042619,"mc":[{"id":"1.230178325","rc":[{"spn":3.23,"spf":"NaN","id":63579394},{"atl":[[5.5,4.9]],"id":70902602},{"spn":3.53,"spf":"NaN","id":70902602},{"spn":2.4,"spf":"NaN","id":69769647},{"spn":4.72,"spf":"NaN","id":57055802},{"spn":2.28,"spf":1.0,"id":40626946},{"spn":4.15,"spf":"NaN","id":45129701}],"con":true,"img":false}]}
{"op":"mcm","clk":"11541369244","pt":1719505042829,"mc":[{"id":"1.230178325","rc":[{"atl":[[5.6,0]],"id":70902602},{"atl":[[3.05,2.53]],"id":69769647}],"con":true,"img":false}]}
{"op":"mcm","clk":"11541369257","pt":1719505042885,"mc":[{"id":"1.230178325","rc":[{"atb":[[2.94,2.49]],"id":70902602},{"atl":[[3.35,9.35],[3.15,0]],"id":69769647}],"con":true,"img":false}]}
{"op":"mcm","clk":"11541369267","pt":1719505042989,"mc":[{"id":"1.230178325","rc":[{"atb":[[2.98,1.94]],"id":70902602},{"atl":[[4.1,0]],"id":63579394},{"atl":[[3.35,2.5],[3.05,5.92]],"id":69769647}],"con":true,"img":false}]}
{"op":"mcm","clk":"11541369291","pt":1719505043197,"mc":[{"id":"1.230178325","rc":[{"atb":[[2.86,0]],"id":70902602},{"atl":[[4,0],[4.7,29.53]],"id":63579394},{"atb":[[2.98,0]],"id":57055802},{"atb":[[2.28,14.06]],"id":40626946},{"atb":[[3.15,10.77]],"id":45129701}],"con":true,"img":false}]}
{"op":"mcm","clk":"11541369300","pt":1719505043301,"mc":[{"id":"1.230178325","rc":[{"atb":[[2.96,10.74]],"id":70902602},{"atb":[[3.05,8.74]],"id":57055802},{"atb":[[1.94,0]],"id":40626946}],"con":true,"img":false}]}
{"op":"mcm","clk":"11541369310","pt":1719505043405,"mc":[{"id":"1.230178325","rc":[{"atb":[[2.98,5.21]],"id":70902602},{"atl":[[5.1,29.39],[4.7,2.5]],"id":63579394},{"atb":[[3.05,11.74]],"id":57055802},{"atb":[[2.3,3.08]],"id":40626946},{"atb":[[3.25,2]],"id":45129701}],"con":true,"img":false}]}
{"op":"mcm","clk":"11541369318","pt":1719505043508,"mc":[{"id":"1.230178325","rc":[{"atb":[[2.96,10.71]],"id":70902602},{"atb":[[2.94,0]],"id":57055802},{"atb":[[3.2,1.94]],"id":45129701}],"con":true,"img":false}]}
{"op":"mcm","clk":"11541369350","pt":1719505043823,"mc":[{"id":"1.230178325","rc":[{"atb":[[2.96,0]],"id":70902602}],"con":true,"img":false}]}
{"op":"mcm","clk":"11541369359","pt":1719505043927,"mc":[{"id":"1.230178325","rc":[{"atb":[[2.98,15.92]],"id":70902602}],"con":true,"img":false}]}
{"op":"mcm","clk":"11541369383","pt":1719505044087,"mc":[{"id":"1.230178325","rc":[{"atl":[[4.2,2.78]],"id":63579394},{"atl":[[3.45,0]],"id":69769647},{"atl":[[7.2,1],[7.8,0]],"id":57055802},{"atl":[[4.9,1]],"id":40626946}],"con":true,"img":false}]}
{"op":"mcm","clk":"11541369427","pt":1719505044396,"mc":[{"id":"1.230178325","rc":[{"atl":[[3.9,0.84]],"id":63579394},{"atl":[[3,0.84]],"id":69769647}],"con":true,"img":false}]}
{"op":"mcm","clk":"11541369435","pt":1719505044499,"mc":[{"id":"1.230178325","rc":[{"atl":[[5.7,0]],"id":63579394},{"atb":[[3.25,12.9]],"id":45129701}],"con":true,"img":false}]}
{"op":"mcm","clk":"11541369450","pt":1719505044708,"mc":[{"id":"1.230178325","rc":[{"atl":[[4.2,0]],"id":63579394}],"con":true,"img":false}]}
{"op":"mcm","clk":"11541369466","pt":1719505044916,"mc":[{"id":"1.230178325","rc":[{"atl":[[4.1,4.99]],"id":63579394}],"con":true,"img":false}]}
{"op":"mcm","clk":"11541369580","pt":1719505045902,"mc":[{"id":"1.230178325","rc":[{"atb":[[3,5.1]],"id":57055802},{"atb":[[2.28,12.12]],"id":40626946},{"atb":[[3.2,0]],"id":45129701}],"con":true,"img":false}]}
{"op":"mcm","clk":"11541369586","pt":1719505046005,"mc":[{"id":"1.230178325","rc":[{"atb":[[3,1]],"id":70902602},{"atb":[[3.1,1.94]],"id":57055802},{"atb":[[2.32,1.94]],"id":40626946},{"atb":[[3.3,1.94]],"id":45129701}],"con":true,"img":false}]}
{"op":"mcm","clk":"11541369630","pt":1719505046492,"mc":[{"id":"1.230178325","rc":[{"atb":[[2.84,0]],"id":70902602}],"con":true,"img":false}]}
{"op":"mcm","clk":"11541369662","pt":1719505046907,"mc":[{"id":"1.230178325","rc":[{"atb":[[3.05,1]],"id":70902602}],"con":true,"img":false}]}
{"op":"mcm","clk":"11541369671","pt":1719505047010,"mc":[{"id":"1.230178325","rc":[{"atb":[[3,6.54]],"id":70902602},{"atl":[[3.45,1]],"id":69769647},{"atl":[[3.9,12.24]],"id":40626946},{"atb":[[3.3,18.24]],"id":45129701}],"con":true,"img":false}]}
{"op":"mcm","clk":"11541369695","pt":1719505047114,"mc":[{"id":"1.230178325","rc":[{"atb":[[3,5.54],[2.88,0.27]],"id":70902602},{"atl":[[4.4,1]],"id":40626946},{"atl":[[5.9,0]],"id":45129701}],"con":true,"img":false}]}
{"op":"mcm","clk":"11541369725","pt":1719505047216,"mc":[{"id":"1.230178325","rc":[{"atb":[[2.94,0]],"id":70902602},{"atl":[[3.85,12.25],[4.9,0],[4,0.84]],"id":40626946},{"atb":[[3.25,2],[3.15,0]],"id":45129701}],"con":true,"img":false}]}
{"op":"mcm","clk":"11541369733","pt":1719505047320,"mc":[{"id":"1.230178325","rc":[{"atl":[[3.95,0]],"id":40626946}],"con":true,"img":false}]}
{"op":"mcm","clk":"11541369739","pt":1719505047424,"mc":[{"id":"1.230178325","rc":[{"atb":[[2.32,20.12]],"id":40626946},{"atl":[[4,24.37],[3.85,0]],"id":40626946}],"con":true,"img":false}]}
{"op":"mcm","clk":"11541369754","pt":1719505047590,"mc":[{"id":"1.230178325","rc":[{"atb":[[2.28,0]],"id":40626946}],"con":true,"img":false}]}
{"op":"mcm","clk":"11541369780","pt":1719505047902,"mc":[{"id":"1.230178325","rc":[{"atb":[[2.98,5.21]],"id":70902602},{"atl":[[3.9,8.89]],"id":63579394}],"con":true,"img":false}]}
{"op":"mcm","clk":"11541369791","pt":1719505048004,"mc":[{"id":"1.230178325","rc":[{"atb":[[3.3,27.57]],"id":45129701}],"con":true,"img":false}]}
{"op":"mcm","clk":"11541369799","pt":1719505048108,"mc":[{"id":"1.230178325","rc":[{"atl":[[3.95,0]],"id":63579394}],"con":true,"img":false}]}
{"op":"mcm","clk":"11541369848","pt":1719505048597,"mc":[{"id":"1.230178325","rc":[{"atl":[[4,17.8],[5.1,5]],"id":63579394}],"con":true,"img":false}]}
{"op":"mcm","clk":"11541369873","pt":1719505048905,"mc":[{"id":"1.230178325","rc":[{"atb":[[2.98,3.27],[3.05,11.85]],"id":70902602},{"atb":[[3.1,0]],"id":57055802}],"con":true,"img":false}]}
{"op":"mcm","clk":"11541369892","pt":1719505049110,"mc":[{"id":"1.230178325","rc":[{"atb":[[3.05,13.79]],"id":70902602},{"atb":[[3.1,1.94]],"id":57055802}],"con":true,"img":false}]}
{"op":"mcm","clk":"11541369908","pt":1719505049221,"mc":[{"id":"1.230178325","rc":[{"atb":[[2.8,0],[2.72,0],[1.43,0],[3.1,1],[3,0],[2.64,0],[2.14,9.46],[3.05,12.79]],"id":70902602},{"atl":[[8.6,0],[5.8,0],[5.5,9.8],[7,0],[7.8,0],[6.6,2.5],[4.7,1]],"id":70902602},{"atb":[[2.5,11.47],[2.52,11.63],[2.28,0]],"id":63579394},{"atl":[[4,0],[4.3,17.8]],"id":63579394},{"atb":[[1.54,0],[1.7,8.31]],"id":69769647},{"atl":[[3.45,0]],"id":69769647},{"atb":[[3.1,7.04],[3,0]],"id":57055802},{"atl":[[7.2,0],[7.6,3.5],[8.4,16.78]],"id":57055802},{"atb":[[2.24,0],[2.32,1.94],[1.89,2.5],[1.88,8.27],[1.76,0]],"id":40626946},{"atl":[[4.9,1],[4.4,0]],"id":40626946},{"atb":[[2.82,2.5],[2.88,29.58]],"id":45129701},{"atl":[[5.5,22.22],[5.4,0]],"id":45129701}],"con":true,"img":false}]}
{"op":"mcm","clk":"11541369927","pt":1719505049434,"mc":[{"id":"1.230178325","rc":[{"atb":[[3.1,2.5],[3.15,1],[2.14,0]],"id":70902602},{"atl":[[5.8,1],[4.7,0]],"id":70902602},{"atb":[[2.5,5.73],[2.52,1.99]],"id":63579394},{"atb":[[1.7,2]],"id":69769647},{"atb":[[2.74,14.1]],"id":57055802},{"atl":[[7.2,1],[7.6,14.28]],"id":57055802},{"atb":[[2.3,6.85],[1.88,2.11],[1.77,5.58]],"id":40626946},{"atb":[[2.88,0],[2.64,30.08]],"id":45129701},{"atl":[[5.5,0],[5.4,21.92]],"id":45129701}],"con":true,"img":false}]}
{"op":"mcm","clk":"11541369937","pt":1719505049495,"mc":[{"id":"1.230178325","rc":[{"atb":[[1.44,5.39]],"id":70902602},{"atl":[[5.5,4.9]],"id":70902602},{"atb":[[2.2,22.96]],"id":63579394},{"atb":[[1.49,10.43]],"id":69769647},{"atb":[[2.74,0],[3.1,1.94],[3,18.79]],"id":57055802},{"atl":[[8.4,5]],"id":57055802},{"atb":[[2.64,0],[2.84,54.35]],"id":45129701}],"con":true,"img":false}]}
{"op":"mcm","clk":"11541369948","pt":1719505049589,"mc":[{"id":"1.230178325","rc":[{"atl":[[6,2]],"id":70902602}],"con":true,"img":false}]}
{"op":"mcm","clk":"11541369984","pt":1719505049999,"mc":[{"id":"1.230178325","rc":[{"atb":[[3.05,9.74]],"id":57055802},{"atl":[[5.1,10.9]],"id":45129701}],"con":true,"img":false}]}
{"op":"mcm","clk":"11541369993","pt":1719505050105,"mc":[{"id":"1.230178325","rc":[{"atb":[[3.1,1.5]],"id":70902602},{"atl":[[4.1,0]],"id":63579394},{"atb":[[3.15,2]],"id":57055802}],"con":true,"img":false}]}
{"op":"mcm","clk":"11541370014","pt":1719505050312,"mc":[{"id":"1.230178325","rc":[{"atl":[[5.1,5.6]],"id":45129701}],"con":true,"img":false}]}
{"op":"mcm","clk":"11541370021","pt":1719505050416,"mc":[{"id":"1.230178325","rc":[{"atl":[[6.6,20.36],[5.4,5.3]],"id":45129701}],"con":true,"img":false}]}
{"op":"mcm","clk":"11541370071","pt":1719505050992,"mc":[{"id":"1.230178325","rc":[{"atb":[[2.5,3.62],[2.32,2.11]],"id":63579394}],"con":true,"img":false}]}
{"op":"mcm","clk":"11541370091","pt":1719505051205,"mc":[{"id":"1.230178325","rc":[{"atb":[[3.15,2.88]],"id":70902602},{"atb":[[3.15,0]],"id":57055802}],"con":true,"img":false}]}
{"op":"mcm","clk":"11541370104","pt":1719505051301,"mc":[{"id":"1.230178325","rc":[{"atb":[[3.1,0]],"id":70902602},{"atl":[[5.5,4.37]],"id":70902602},{"atb":[[3.1,3.94]],"id":57055802}],"con":true,"img":false}]}
{"op":"mcm","clk":"11541370140","pt":1719505051719,"mc":[{"id":"1.230178325","rc":[{"atl":[[3,5.03]],"id":69769647}],"con":true,"img":false}]}
{"op":"mcm","clk":"11541370145","pt":1719505051823,"mc":[{"id":"1.230178325","rc":[{"atb":[[2.88,0]],"id":70902602},{"atl":[[4.2,2.78]],"id":63579394}],"con":true,"img":false}]}
{"op":"mcm","clk":"11541370155","pt":1719505051928,"mc":[{"id":"1.230178325","rc":[{"atb":[[3.05,10.85],[2.86,2.5],[2.78,5],[2.7,10]],"id":70902602},{"atl":[[3.1,0]],"id":69769647},{"atb":[[2.32,0]],"id":40626946}],"con":true,"img":false}]}
{"op":"mcm","clk":"11541370164","pt":1719505052033,"mc":[{"id":"1.230178325","rc":[{"atb":[[2.98,0],[3.2,1.94]],"id":70902602},{"atb":[[3.05,6.74]],"id":57055802},{"atb":[[2.3,3.77],[2.32,1.94]],"id":40626946},{"atb":[[3.25,0]],"id":45129701}],"con":true,"img":false}]}
{"op":"mcm","clk":"11541370173","pt":1719505052088,"mc":[{"id":"1.230178325","rc":[{"atb":[[3.15,6.06]],"id":70902602},{"atb":[[3.1,6.94]],"id":57055802},{"atb":[[2.32,4.94]],"id":40626946}],"con":true,"img":false}]}
{"op":"mcm","clk":"11541370184","pt":1719505052191,"mc":[{"id":"1.230178325","rc":[{"atb":[[3.25,1]],"id":70902602}],"con":true,"img":false}]}
{"op":"mcm","clk":"11541370197","pt":1719505052397,"mc":[{"id":"1.230178325","rc":[{"atl":[[4.2,0]],"id":63579394}],"con":true,"img":false}]}
{"op":"mcm","clk":"11541370207","pt":1719505052506,"mc":[{"id":"1.230178325","rc":[{"atl":[[4,0],[4.4,29.41]],"id":40626946}],"con":true,"img":false}]}
{"op":"mcm","clk":"11541370231","pt":1719505052815,"mc":[{"id":"1.230178325","rc":[{"atl":[[4.1,4.99]],"id":63579394}],"con":true,"img":false}]}
{"op":"mcm","clk":"11541370249","pt":1719505053021,"mc":[{"id":"1.230178325","rc":[{"atb":[[3.3,18.24]],"id":45129701}],"con":true,"img":false}]}
{"op":"mcm","clk":"11541370295","pt":1719505053598,"mc":[{"id":"1.230178325","rc":[{"atl":[[3.05,3.39]],"id":69769647}],"con":true,"img":false}]}
{"op":"mcm","clk":"11541370315","pt":1719505053801,"mc":[{"id":"1.230178325","rc":[{"atl":[[3.35,10.93],[3.05,0]],"id":69769647}],"con":true,"img":false}]}
{"op":"mcm","clk":"11541370364","pt":1719505054472,"mc":[{"id":"1.230178325","rc":[{"atl":[[4,17.8],[4.3,0]],"id":63579394},{"atb":[[3.15,10.27]],"id":57055802}],"con":true,"img":false}]}
{"op":"mcm","clk":"11541370372","pt":1719505054519,"mc":[{"id":"1.230178325","rc":[{"atb":[[1.63,5.54]],"id":69769647},{"atb":[[2.3,7.69]],"id":40626946}],"con":true,"img":false}]}
{"op":"mcm","clk":"11541370380","pt":1719505054624,"mc":[{"id":"1.230178325","rc":[{"atl":[[3.35,2.5],[3.55,21.97]],"id":69769647},{"atb":[[3.05,0]],"id":57055802}],"con":true,"img":false}]}
{"op":"mcm","clk":"11541370413","pt":1719505055038,"mc":[{"id":"1.230178325","rc":[{"atb":[[3.2,0]],"id":70902602},{"atb":[[3.1,3]],"id":57055802}],"con":true,"img":false}]}
{"op":"mcm","clk":"11541370426","pt":1719505055142,"mc":[{"id":"1.230178325","rc":[{"atb":[[3.2,1.94]],"id":70902602},{"atb":[[1.02,2]],"id":57055802}],"con":true,"img":false}]}
{"op":"mcm","clk":"11541370435","pt":1719505055223,"mc":[{"id":"1.230178325","rc":[{"atb":[[3.25,0]],"id":70902602}],"con":true,"img":false}]}
{"op":"mcm","clk":"11541370456","pt":1719505055467,"mc":[{"id":"1.230178325","rc":[{"atb":[[3.05,0]],"id":70902602}],"con":true,"img":false}]}
{"op":"mcm","clk":"11541370463","pt":1719505055503,"mc":[{"id":"1.230178325","rc":[{"atl":[[6.6,2.5],[5.4,16.52]],"id":45129701}],"con":true,"img":false}]}
{"op":"mcm","clk":"11541370528","pt":1719505056226,"mc":[{"id":"1.230178325","rc":[{"atl":[[6.2,1]],"id":45129701}],"con":true,"img":false}]}
{"op":"mcm","clk":"11541370545","pt":1719505056432,"mc":[{"id":"1.230178325","rc":[{"atl":[[5.4,11.22]],"id":45129701}],"con":true,"img":false}]}
{"op":"mcm","clk":"11541370553","pt":1719505056535,"mc":[{"id":"1.230178325","rc":[{"atl":[[6.2,17.83],[5.4,0]],"id":45129701}],"con":true,"img":false}]}
{"op":"mcm","clk":"11541370566","pt":1719505056592,"mc":[{"id":"1.230178325","rc":[{"atb":[[3.2,12.22]],"id":70902602}],"con":true,"img":false}]}
{"op":"mcm","clk":"11541370579","pt":1719505056802,"mc":[{"id":"1.230178325","rc":[{"atl":[[7.2,0],[7.6,15.28]],"id":57055802}],"con":true,"img":false}]}
{"op":"mcm","clk":"11541370586","pt":1719505056899,"mc":[{"id":"1.230178325","rc":[{"atl":[[4.8,1],[4.9,0]],"id":40626946}],"con":true,"img":false}]}
{"op":"mcm","clk":"11541370595","pt":1719505057008,"mc":[{"id":"1.230178325","rc":[{"atb":[[1.44,0],[2.12,11.06],[2.86,0],[3.15,3.18],[2.78,0],[2.7,0]],"id":70902602},{"atl":[[5.8,0],[4.7,1],[5.4,5.16]],"id":70902602},{"atb":[[2.5,7.62],[2.52,8.45],[2.2,0]],"id":63579394},{"atl":[[4,0],[4.3,17.8]],"id":63579394},{"atb":[[1.7,9.78],[1.49,0]],"id":69769647},{"atl":[[3.45,1],[3.55,20.97]],"id":69769647},{"atb":[[3.1,23.54],[3,0]],"id":57055802},{"atl":[[9.2,0],[8.2,1],[7.6,0],[8.4,13.51]],"id":57055802},{"atb":[[2.3,3.92],[1.88,12.01],[1.77,0]],"id":40626946},{"atl":[[5,1]],"id":40626946},{"atb":[[2.64,36.5],[2.84,0]],"id":45129701}],"con":true,"img":false}]}
{"op":"mcm","clk":"11541370601","pt":1719505057108,"mc":[{"id":"1.230178325","rc":[{"atl":[[5.5,0.84]],"id":70902602},{"atb":[[2.5,3.62],[2.32,7.73]],"id":63579394},{"atl":[[4.1,0]],"id":63579394},{"atb":[[1.7,7.66]],"id":69769647},{"atb":[[3,13.27]],"id":57055802},{"atl":[[9.2,11.78],[8.4,0]],"id":57055802},{"atb":[[1.88,2.11],[1.77,7.45]],"id":40626946}],"con":true,"img":false}]}
{"op":"mcm","clk":"11541370612","pt":1719505057211,"mc":[{"id":"1.230178325","rc":[{"atl":[[4.3,0],[4.7,29.2]],"id":63579394},{"atb":[[3.25,1],[2.14,2.5]],"id":70902602},{"atl":[[6,0],[5.4,7.16]],"id":70902602},{"atb":[[1.61,5]],"id":69769647},{"atb":[[3.1,3]],"id":57055802},{"atl":[[11,2.5],[13,5],[15,10]],"id":57055802},{"atl":[[4.8,0],[5,0]],"id":40626946}],"con":true,"img":false}]}
{"op":"mcm","clk":"11541370622","pt":1719505057315,"mc":[{"id":"1.230178325","rc":[{"atl":[[5.3,1]],"id":63579394},{"atb":[[2.62,11]],"id":57055802}],"con":true,"img":false}]}
{"op":"mcm","clk":"11541370630","pt":1719505057418,"mc":[{"id":"1.230178325","rc":[{"atl":[[5.1,29.39],[4.7,2.5]],"id":63579394},{"atb":[[3.1,23.54],[3,0]],"id":57055802},{"atl":[[5,1]],"id":40626946}],"con":true,"img":false}]}
{"op":"mcm","clk":"11541370638","pt":1719505057522,"mc":[{"id":"1.230178325","rc":[{"atb":[[3.1,3],[3,13.27]],"id":57055802}],"con":true,"img":false}]}
{"op":"mcm","clk":"11541370685","pt":1719505057934,"mc":[{"id":"1.230178325","rc":[{"atl":[[5.8,1],[5.3,0]],"id":63579394},{"atl":[[3.45,0],[3.55,21.97]],"id":69769647},{"atl":[[5.1,1],[5,0],[4.9,1]],"id":40626946}],"con":true,"img":false}]}
{"op":"mcm","clk":"11541370696","pt":1719505058037,"mc":[{"id":"1.230178325","rc":[{"atb":[[1.65,9.78],[1.61,0]],"id":69769647},{"atl":[[8.2,0],[7.6,1]],"id":57055802}],"con":true,"img":false}]}
{"op":"mcm","clk":"11541370711","pt":1719505058141,"mc":[{"id":"1.230178325","rc":[{"atl":[[5.8,0],[5.3,1],[5.7,1]],"id":63579394},{"atl":[[4.6,1],[4.7,0]],"id":70902602},{"atl":[[3.45,1],[3.55,20.97]],"id":69769647},{"atl":[[9.2,0],[7.6,0],[7.8,1],[8.4,6.89]],"id":57055802},{"atl":[[4.8,1],[4.9,0],[5.1,0],[5,1]],"id":40626946}],"con":true,"img":false}]}
{"op":"mcm","clk":"11541370724","pt":1719505058248,"mc":[{"id":"1.230178325","rc":[{"atl":[[4.7,2]],"id":70902602},{"atb":[[1.6,13.2],[1.65,0]],"id":69769647},{"atl":[[9.2,6.89],[8.2,1],[8.4,0]],"id":57055802}],"con":true,"img":false}]}
{"op":"mcm","clk":"11541370734","pt":1719505058303,"mc":[{"id":"1.230178325","rc":[{"atl":[[5.4,5.16]],"id":70902602}],"con":true,"img":false}]}
{"op":"mcm","clk":"11541370751","pt":1719505058506,"mc":[{"id":"1.230178325","rc":[{"atl":[[5.7,0]],"id":63579394},{"atb":[[1.6,0],[1.65,9.78]],"id":69769647},{"atl":[[3.45,0],[3.55,21.97]],"id":69769647},{"atl":[[9.2,0],[8.2,0],[7.8,0],[8.4,5]],"id":57055802},{"atl":[[4.8,0],[5.1,1],[5,0]],"id":40626946}],"con":true,"img":false}]}
{"op":"mcm","clk":"11541370761","pt":1719505058608,"mc":[{"id":"1.230178325","rc":[{"atl":[[5.8,1],[5.3,0]],"id":63579394},{"atl":[[7.6,1]],"id":57055802},{"atl":[[4.9,1]],"id":40626946}],"con":true,"img":false}]}
{"op":"mcm","clk":"11541370780","pt":1719505058814,"mc":[{"id":"1.230178325","rc":[{"atl":[[5.1,0]],"id":40626946}],"con":true,"img":false}]}
{"op":"mcm","clk":"11541370790","pt":1719505058921,"mc":[{"id":"1.230178325","rc":[{"atl":[[5.5,0]],"id":70902602},{"atb":[[2.8,6.25]],"id":45129701}],"con":true,"img":false}]}
{"op":"mcm","clk":"11541370827","pt":1719505059338,"mc":[{"id":"1.230178325","rc":[{"atl":[[5.8,0],[5.3,1],[5.7,1]],"id":63579394},{"atb":[[1.65,0],[1.61,13.2]],"id":69769647},{"atl":[[9.2,10],[8.2,1],[8.4,0]],"id":57055802},{"atl":[[4.8,1],[5,1],[4.9,0]],"id":40626946}],"con":true,"img":false}]}
{"op":"mcm","clk":"11541370837","pt":1719505059403,"mc":[{"id":"1.230178325","rc":[{"atl":[[3.45,1],[3.55,20.97]],"id":69769647},{"atl":[[7.6,0]],"id":57055802}],"con":true,"img":false}]}
{"op":"mcm","clk":"11541370864","pt":1719505059710,"mc":[{"id":"1.230178325","rc":[{"atb":[[2.32,2.11],[2.06,12.74],[2.52,1.99]],"id":63579394},{"atl":[[5.7,0]],"id":63579394},{"atb":[[2.12,0],[3.25,3.25],[3.3,1],[1.24,5.68]],"id":70902602},{"atl":[[5.6,1],[4.6,0],[5.8,3],[4.7,0]],"id":70902602},{"atb":[[1.7,2],[1.42,10.54],[1.61,0]],"id":69769647},{"atl":[[3.45,8.54],[3.55,5]],"id":69769647},{"atb":[[3,0]],"id":57055802},{"atl":[[8.2,0],[7.8,1]],"id":57055802},{"atb":[[1.63,7.84],[2.32,11.59],[1.77,0]],"id":40626946},{"atb":[[2.86,36.5],[2.64,0]],"id":45129701}],"con":true,"img":false}]}
{"op":"mcm","clk":"11541370876","pt":1719505059813,"mc":[{"id":"1.230178325","rc":[{"atb":[[2.5,0]],"id":63579394},{"atb":[[1.63,0]],"id":69769647},{"atl":[[4.8,0],[5,0]],"id":40626946}],"con":true,"img":false}]}
{"op":"mcm","clk":"11541370885","pt":1719505059914,"mc":[{"id":"1.230178325","rc":[{"atb":[[2.06,0],[2.2,11.36]],"id":63579394},{"atb":[[3.25,2.25],[1.51,5.68],[1.24,0]],"id":70902602},{"atb":[[1.42,0],[1.49,13.2]],"id":69769647},{"atb":[[3.05,13.27]],"id":57055802},{"atl":[[9.2,0],[8.2,11.78]],"id":57055802},{"atb":[[1.63,0],[1.78,7.45]],"id":40626946}],"con":true,"img":false}]}
{"op":"mcm","clk":"11541370898","pt":1719505060018,"mc":[{"id":"1.230178325","rc":[{"atl":[[5.3,0],[5.2,1]],"id":63579394},{"atl":[[3.45,7.54],[3.4,1]],"id":69769647},{"atl":[[9.2,6.89],[8.2,0],[7.6,1],[7.8,0]],"id":57055802},{"atl":[[5,1]],"id":40626946},{"atb":[[2.8,0]],"id":45129701}],"con":true,"img":false}]}
{"op":"mcm","clk":"11541370918","pt":1719505060223,"mc":[{"id":"1.230178325","rc":[{"atb":[[3.2,1.94]],"id":70902602}],"con":true,"img":false}]}
{"op":"mcm","clk":"11541370927","pt":1719505060325,"mc":[{"id":"1.230178325","rc":[{"atb":[[3.3,3.21]],"id":70902602},{"atl":[[5.3,0.84]],"id":70902602},{"atl":[[5.3,1],[5.2,0]],"id":63579394},{"atl":[[7.6,0],[7.8,1]],"id":57055802},{"atl":[[5.1,1],[5,0]],"id":40626946}],"con":true,"img":false}]}
{"op":"mcm","clk":"11541370945","pt":1719505060531,"mc":[{"id":"1.230178325","rc":[{"atb":[[3.25,0]],"id":70902602},{"atb":[[2.52,0]],"id":63579394}],"con":true,"img":false}]}
{"op":"mcm","clk":"11541370954","pt":1719505060636,"mc":[{"id":"1.230178325","rc":[{"atb":[[2.32,10.66],[2.34,2]],"id":63579394},{"atb":[[3.15,0]],"id":70902602},{"atb":[[3.1,0]],"id":57055802},{"atb":[[2.32,8.59]],"id":40626946}],"con":true,"img":false}]}
{"op":"mcm","clk":"11541370961","pt":1719505060741,"mc":[{"id":"1.230178325","rc":[{"atb":[[2.34,5]],"id":63579394},{"atb":[[3.35,2.73]],"id":70902602},{"atb":[[3.2,3],[3.15,0]],"id":57055802},{"atb":[[2.34,3]],"id":40626946},{"atb":[[3.35,3]],"id":45129701}],"con":true,"img":false}]}
{"op":"mcm","clk":"11541370972","pt":1719505060804,"mc":[{"id":"1.230178325","rc":[{"atb":[[3.4,1]],"id":70902602},{"atl":[[3.4,0],[3.3,1]],"id":69769647},{"atb":[[3.1,9.58],[2.62,10],[2.7,6]],"id":57055802},{"atb":[[2.34,12.39]],"id":40626946},{"atb":[[3.35,20.58]],"id":45129701}],"con":true,"img":false}]}
{"op":"mcm","clk":"11541370983","pt":1719505060902,"mc":[{"id":"1.230178325","rc":[{"atb":[[3.2,0]],"id":70902602},{"atb":[[1.84,7.45],[1.78,0]],"id":40626946}],"con":true,"img":false}]}
{"op":"mcm","clk":"11541370993","pt":1719505061006,"mc":[{"id":"1.230178325","rc":[{"atb":[[3.4,10.81],[3.3,2.21]],"id":70902602},{"atb":[[3.2,14.44]],"id":57055802},{"atb":[[2.32,1.94]],"id":40626946},{"atb":[[3.3,1.94]],"id":45129701}],"con":true,"img":false}]}
{"op":"mcm","clk":"11541371004","pt":1719505061110,"mc":[{"id":"1.230178325","rc":[{"atb":[[3.35,4.67]],"id":70902602},{"atb":[[2.34,6.94]],"id":63579394}],"con":true,"img":false}]}
{"op":"mcm","clk":"11541371053","pt":1719505061621,"mc":[{"id":"1.230178325","rc":[{"atl":[[5.1,30.39],[5.3,0]],"id":63579394},{"atl":[[3.4,1],[3.3,0]],"id":69769647},{"atl":[[7.4,1],[7.8,0]],"id":57055802},{"atb":[[2.3,0]],"id":40626946},{"atl":[[4.5,3.04],[5.1,0]],"id":40626946},{"atl":[[6.4,1],[6.2,16.83]],"id":45129701}],"con":true,"img":false}]}
{"op":"mcm","clk":"11541371065","pt":1719505061724,"mc":[{"id":"1.230178325","rc":[{"atl":[[7.6,1]],"id":57055802},{"atl":[[4.6,1]],"id":40626946}],"con":true,"img":false}]}
{"op":"mcm","clk":"11541371079","pt":1719505061930,"mc":[{"id":"1.230178325","rc":[{"atl":[[5.1,29.39],[5.2,1]],"id":63579394},{"atl":[[7.4,0]],"id":57055802},{"atl":[[5,1]],"id":40626946}],"con":true,"img":false}]}
{"op":"mcm","clk":"11541371087","pt":1719505062035,"mc":[{"id":"1.230178325","rc":[{"atl":[[4.5,2.04],[4.6,0]],"id":40626946}],"con":true,"img":false}]}
{"op":"mcm","clk":"11541371098","pt":1719505062138,"mc":[{"id":"1.230178325","rc":[{"atb":[[3.45,5.17]],"id":70902602}],"con":true,"img":false}]}
{"op":"mcm","clk":"11541371122","pt":1719505062298,"mc":[{"id":"1.230178325","rc":[{"atb":[[3.3,0]],"id":70902602}],"con":true,"img":false}]}
{"op":"mcm","clk":"11541371157","pt":1719505062706,"mc":[{"id":"1.230178325","rc":[{"atl":[[5.1,30.39],[5.2,0]],"id":63579394},{"atl":[[7.4,1]],"id":57055802},{"atl":[[4.5,3.04],[5,0]],"id":40626946}],"con":true,"img":false}]}
{"op":"mcm","clk":"11541371167","pt":1719505062811,"mc":[{"id":"1.230178325","rc":[{"atl":[[7.6,0]],"id":57055802}],"con":true,"img":false}]}
{"op":"mcm","clk":"11541371185","pt":1719505063020,"mc":[{"id":"1.230178325","rc":[{"atb":[[2.32,14.74]],"id":63579394}],"con":true,"img":false}]}
{"op":"mcm","clk":"11541371251","pt":1719505063646,"mc":[{"id":"1.230178325","rc":[{"atb":[[1.05,0.52]],"id":70902602},{"atl":[[5.3,1.37]],"id":70902602},{"atl":[[7.4,0],[7.6,1]],"id":57055802},{"atl":[[4.5,2.04],[4.6,1]],"id":40626946}],"con":true,"img":false}]}
{"op":"mcm","clk":"11541371270","pt":1719505063807,"mc":[{"id":"1.230178325","rc":[{"atb":[[1.05,0.21]],"id":70902602}],"con":true,"img":false}]}
{"op":"mcm","clk":"11541371288","pt":1719505064010,"mc":[{"id":"1.230178325","rc":[{"atb":[[3.35,2.73],[1.05,0]],"id":70902602},{"atb":[[2.32,0]],"id":40626946},{"atb":[[3.3,0]],"id":45129701}],"con":true,"img":false}]}
{"op":"mcm","clk":"11541371296","pt":1719505064112,"mc":[{"id":"1.230178325","rc":[{"atb":[[3.5,0.21]],"id":70902602}],"con":true,"img":false}]}
{"op":"mcm","clk":"11541371312","pt":1719505064216,"mc":[{"id":"1.230178325","rc":[{"atl":[[5.1,29.39],[5.3,1]],"id":63579394},{"atl":[[3.4,0],[3.3,1]],"id":69769647},{"atl":[[7.6,0],[7.8,1]],"id":57055802},{"atb":[[2.36,1.94]],"id":40626946},{"atl":[[5.1,1],[4.6,0]],"id":40626946}],"con":true,"img":false}]}
{"op":"mcm","clk":"11541371390","pt":1719505064942,"mc":[{"id":"1.230178325","rc":[{"atl":[[3.45,0],[3.35,8.54]],"id":69769647}],"con":true,"img":false}]}
{"op":"mcm","clk":"11541371437","pt":1719505065314,"mc":[{"id":"1.230178325","rc":[{"atb":[[3.25,12.35],[2.62,0]],"id":57055802}],"con":true,"img":false}]}
{"op":"mcm","clk":"11541371451","pt":1719505065416,"mc":[{"id":"1.230178325","rc":[{"atb":[[1.44,5.46],[1.51,0]],"id":70902602},{"atl":[[5.6,0],[5.8,4]],"id":70902602},{"atb":[[3.1,28.88],[3.05,0],[2.86,2.5]],"id":57055802},{"atb":[[1.84,0],[1.78,5]],"id":40626946}],"con":true,"img":false}]}
{"op":"mcm","clk":"11541371474","pt":1719505065618,"mc":[{"id":"1.230178325","rc":[{"atl":[[5.3,0],[5.2,1]],"id":63579394}],"con":true,"img":false}]}
{"op":"mcm","clk":"11541371569","pt":1719505066447,"mc":[{"id":"1.230178325","rc":[{"atb":[[3.2,14.14]],"id":57055802}],"con":true,"img":false}]}
{"op":"mcm","clk":"11541371587","pt":1719505066632,"mc":[{"id":"1.230178325","rc":[{"atb":[[3.2,3]],"id":57055802}],"con":true,"img":false}]}
{"op":"mcm","clk":"11541371597","pt":1719505066710,"mc":[{"id":"1.230178325","rc":[{"atb":[[3.25,23.49]],"id":57055802}],"con":true,"img":false}]}
{"op":"mcm","clk":"11541371605","pt":1719505066816,"mc":[{"id":"1.230178325","rc":[{"atl":[[4.2,2.99]],"id":63579394}],"con":true,"img":false}]}
{"op":"mcm","clk":"11541371614","pt":1719505066916,"mc":[{"id":"1.230178325","rc":[{"atl":[[5.1,5],[4.2,20.79]],"id":63579394}],"con":true,"img":false}]}
{"op":"mcm","clk":"11541371623","pt":1719505067019,"mc":[{"id":"1.230178325","rc":[{"atl":[[4.7,14.39]],"id":63579394}],"con":true,"img":false}]}
{"op":"mcm","clk":"11541371633","pt":1719505067122,"mc":[{"id":"1.230178325","rc":[{"atl":[[4.2,2.99]],"id":63579394}],"con":true,"img":false}]}
{"op":"mcm","clk":"11541371643","pt":1719505067228,"mc":[{"id":"1.230178325","rc":[{"atl":[[4.2,20.79],[4.7,2.5]],"id":63579394}],"con":true,"img":false}]}
{"op":"mcm","clk":"11541371681","pt":1719505067641,"mc":[{"id":"1.230178325","rc":[{"atl":[[4.2,17.8]],"id":63579394}],"con":true,"img":false}]}
{"op":"mcm","clk":"11541371697","pt":1719505067849,"mc":[{"id":"1.230178325","rc":[{"atb":[[2.34,18.83]],"id":63579394},{"atl":[[4.2,19.29]],"id":63579394},{"atl":[[5.3,6.27]],"id":70902602}],"con":true,"img":false}]}
{"op":"mcm","clk":"11541371708","pt":1719505067952,"mc":[{"id":"1.230178325","rc":[{"atl":[[5.4,0]],"id":70902602}],"con":true,"img":false}]}
{"op":"mcm","clk":"11541371719","pt":1719505068010,"mc":[{"id":"1.230178325","rc":[{"atb":[[2.32,6.19]],"id":63579394}],"con":true,"img":false}]}
{"op":"mcm","clk":"11541371754","pt":1719505068366,"mc":[{"id":"1.230178325","rc":[{"atl":[[4.2,17.8]],"id":63579394}],"con":true,"img":false}]}
{"op":"mcm","clk":"11541371786","pt":1719505068622,"mc":[{"id":"1.230178325","rc":[{"atl":[[4.1,4.91]],"id":63579394}],"con":true,"img":false}]}
{"op":"mcm","clk":"11541371839","pt":1719505069140,"mc":[{"id":"1.230178325","rc":[{"atb":[[2.36,0]],"id":40626946}],"con":true,"img":false}]}
{"op":"mcm","clk":"11541371853","pt":1719505069242,"mc":[{"id":"1.230178325","rc":[{"atb":[[3.5,2.15]],"id":70902602},{"atb":[[2.36,1.94]],"id":40626946}],"con":true,"img":false}]}
{"op":"mcm","clk":"11541371862","pt":1719505069347,"mc":[{"id":"1.230178325","rc":[{"atb":[[3.35,0]],"id":70902602},{"atb":[[3.2,0]],"id":57055802},{"atb":[[2.34,9.39]],"id":40626946}],"con":true,"img":false}]}
{"op":"mcm","clk":"11541371872","pt":1719505069450,"mc":[{"id":"1.230178325","rc":[{"atb":[[3.5,4.15]],"id":70902602},{"atb":[[3.3,3.21]],"id":57055802},{"atb":[[2.36,5.94]],"id":40626946}],"con":true,"img":false}]}
{"op":"mcm","clk":"11541371889","pt":1719505069608,"mc":[{"id":"1.230178325","rc":[{"atb":[[3.25,22.71]],"id":57055802}],"con":true,"img":false}]}
{"op":"mcm","clk":"11541371907","pt":1719505069816,"mc":[{"id":"1.230178325","rc":[{"atb":[[3.25,12.35]],"id":57055802}],"con":true,"img":false}]}
{"op":"mcm","clk":"11541371914","pt":1719505069926,"mc":[{"id":"1.230178325","rc":[{"atb":[[3.3,13.57]],"id":57055802}],"con":true,"img":false}]}
{"op":"mcm","clk":"11541371973","pt":1719505070431,"mc":[{"id":"1.230178325","rc":[{"atb":[[2.22,12.4],[2.2,0]],"id":63579394},{"atb":[[3.35,3]],"id":45129701}],"con":true,"img":false}]}
{"op":"mcm","clk":"11541371982","pt":1719505070534,"mc":[{"id":"1.230178325","rc":[{"atb":[[3.55,8]],"id":70902602},{"atb":[[2.36,17.44]],"id":40626946}],"con":true,"img":false}]}
{"op":"mcm","clk":"11541371995","pt":1719505070638,"mc":[{"id":"1.230178325","rc":[{"atl":[[2.96,5.37]],"id":69769647}],"con":true,"img":false}]}
{"op":"mcm","clk":"11541372007","pt":1719505070751,"mc":[{"id":"1.230178325","rc":[{"atb":[[3.45,0],[3.4,9.81]],"id":70902602},{"atb":[[2.02,0]],"id":63579394},{"atl":[[3,0.84],[3.25,1],[3.3,0]],"id":69769647},{"atl":[[8,1],[7.8,0]],"id":57055802},{"atb":[[2.34,0]],"id":40626946},{"atl":[[7,1]],"id":45129701}],"con":true,"img":false}]}
{"op":"mcm","clk":"11541372021","pt":1719505070845,"mc":[{"id":"1.230178325","rc":[{"atl":[[3.25,11.41]],"id":69769647},{"atl":[[8,7.89],[9.2,0]],"id":57055802},{"atl":[[6.4,0]],"id":45129701}],"con":true,"img":false}]}
{"op":"mcm","clk":"11541372033","pt":1719505070949,"mc":[{"id":"1.230178325","rc":[{"atl":[[3.35,2.5]],"id":69769647},{"atl":[[8,1],[9.2,12.2]],"id":57055802}],"con":true,"img":false}]}
{"op":"mcm","clk":"11541372068","pt":1719505071258,"mc":[{"id":"1.230178325","rc":[{"atl":[[3.25,10.41]],"id":69769647}],"con":true,"img":false}]}
{"op":"mcm","clk":"11541372076","pt":1719505071315,"mc":[{"id":"1.230178325","rc":[{"atl":[[5.2,2.34]],"id":70902602},{"atl":[[3.85,2.31]],"id":63579394},{"atl":[[3,0],[3.15,1],[2.94,2.61]],"id":69769647},{"atl":[[6.2,3.21]],"id":57055802},{"atl":[[3.85,2.31]],"id":40626946},{"atl":[[5,2.56]],"id":45129701}],"con":true,"img":false}]}
{"op":"mcm","clk":"11541372086","pt":1719505071417,"mc":[{"id":"1.230178325","rc":[{"atb":[[2.4,2.11],[2.32,4.07]],"id":63579394},{"atl":[[3.8,8.33]],"id":63579394},{"atl":[[3.25,0],[2.94,5.23]],"id":69769647},{"atl":[[9.2,0],[6,13.68],[7.8,9.1]],"id":57055802},{"atl":[[3.85,25.62],[4.4,0]],"id":40626946},{"atl":[[6.2,0],[4.9,6.46],[5.9,8.17]],"id":45129701}],"con":true,"img":false}]}
{"op":"mcm","clk":"11541372096","pt":1719505071518,"mc":[{"id":"1.230178325","rc":[{"atb":[[2.4,11.42]],"id":63579394},{"atb":[[3.5,2.21]],"id":70902602},{"atb":[[3.35,13.68],[3.2,6]],"id":57055802}],"con":true,"img":false}]}
{"op":"mcm","clk":"11541372106","pt":1719505071624,"mc":[{"id":"1.230178325","rc":[{"atb":[[2.34,6.94]],"id":63579394},{"atl":[[3.9,0.84]],"id":63579394},{"atb":[[3.25,0]],"id":57055802},{"atl":[[6.4,0.84]],"id":57055802},{"atl":[[3.9,0.84]],"id":40626946},{"atl":[[5.1,0.84]],"id":45129701}],"con":true,"img":false}]}
{"op":"mcm","clk":"11541372116","pt":1719505071729,"mc":[{"id":"1.230178325","rc":[{"atl":[[3.75,2.46]],"id":63579394},{"atl":[[6,15.38]],"id":57055802},{"atl":[[4.9,9.14]],"id":45129701}],"con":true,"img":false}]}
{"op":"mcm","clk":"11541372126","pt":1719505071830,"mc":[{"id":"1.230178325","rc":[{"atl":[[3.75,3.3]],"id":63579394},{"atl":[[5.1,0.84]],"id":70902602},{"atl":[[5.9,0.84]],"id":57055802},{"atl":[[3.8,0.84]],"id":40626946},{"atl":[[4.8,0.84]],"id":45129701}],"con":true,"img":false}]}
{"op":"mcm","clk":"11541372137","pt":1719505071933,"mc":[{"id":"1.230178325","rc":[{"atl":[[3.9,0]],"id":63579394},{"atl":[[6.4,0]],"id":57055802},{"atl":[[5.1,0]],"id":45129701}],"con":true,"img":false}]}
{"op":"mcm","clk":"11541372147","pt":1719505072037,"mc":[{"id":"1.230178325","rc":[{"atb":[[3.2,0]],"id":57055802}],"con":true,"img":false}]}
{"op":"mcm","clk":"11541372179","pt":1719505072245,"mc":[{"id":"1.230178325","rc":[{"atb":[[2.32,0]],"id":63579394},{"atb":[[3.3,12.13]],"id":57055802},{"atl":[[8,0],[7.8,10.1]],"id":57055802}],"con":true,"img":false}]}
{"op":"mcm","clk":"11541372189","pt":1719505072348,"mc":[{"id":"1.230178325","rc":[{"atb":[[2.34,4.94]],"id":63579394},{"atl":[[3.85,13.95],[4.2,0]],"id":63579394},{"atl":[[5.9,5.77]],"id":57055802},{"atl":[[4.8,6.32]],"id":45129701}],"con":true,"img":false}]}
{"op":"mcm","clk":"11541372197","pt":1719505072451,"mc":[{"id":"1.230178325","rc":[{"atb":[[2.42,2]],"id":63579394}],"con":true,"img":false}]}
{"op":"mcm","clk":"11541372205","pt":1719505072554,"mc":[{"id":"1.230178325","rc":[{"atl":[[3.15,0],[3.25,1]],"id":69769647},{"atb":[[3.3,3.21]],"id":57055802}],"con":true,"img":false}]}
{"op":"mcm","clk":"11541372214","pt":1719505072668,"mc":[{"id":"1.230178325","rc":[{"atb":[[3.35,22.6]],"id":57055802}],"con":true,"img":false}]}
{"op":"mcm","clk":"11541372234","pt":1719505072823,"mc":[{"id":"1.230178325","rc":[{"atl":[[3.25,0],[3.15,1]],"id":69769647},{"atl":[[7.8,9.1]],"id":57055802}],"con":true,"img":false}]}
{"op":"mcm","clk":"11541372246","pt":1719505072921,"mc":[{"id":"1.230178325","rc":[{"atl":[[3.85,2.31],[3.9,16.66]],"id":63579394}],"con":true,"img":false}]}
{"op":"mcm","clk":"11541372325","pt":1719505073751,"mc":[{"id":"1.230178325","rc":[{"atb":[[1.63,5.54]],"id":69769647},{"atl":[[2.92,2.53]],"id":69769647}],"con":true,"img":false}]}
{"op":"mcm","clk":"11541372383","pt":1719505074323,"mc":[{"id":"1.230178325","rc":[{"atl":[[7.4,1]],"id":57055802}],"con":true,"img":false}]}
{"op":"mcm","clk":"11541372431","pt":1719505074840,"mc":[{"id":"1.230178325","rc":[{"atb":[[2.34,3.83]],"id":40626946}],"con":true,"img":false}]}
{"op":"mcm","clk":"11541372439","pt":1719505074945,"mc":[{"id":"1.230178325","rc":[{"atl":[[7.4,0],[7.6,1]],"id":57055802}],"con":true,"img":false}]}
{"op":"mcm","clk":"11541372498","pt":1719505075460,"mc":[{"id":"1.230178325","rc":[{"atl":[[3.15,0],[3.25,1]],"id":69769647},{"atb":[[3.35,10]],"id":45129701}],"con":true,"img":false}]}
{"op":"mcm","clk":"11541372619","pt":1719505076551,"mc":[{"id":"1.230178325","rc":[{"atb":[[2.34,3]],"id":63579394}],"con":true,"img":false}]}
{"op":"mcm","clk":"11541372641","pt":1719505076757,"mc":[{"id":"1.230178325","rc":[{"atb":[[2.42,3.94]],"id":63579394}],"con":true,"img":false}]}
{"op":"mcm","clk":"11541372768","pt":1719505078056,"mc":[{"id":"1.230178325","rc":[{"atb":[[2.34,0]],"id":63579394},{"atl":[[3.85,13.95]],"id":63579394},{"atb":[[3.5,0.21]],"id":70902602},{"atb":[[3.3,0]],"id":57055802},{"atb":[[2.36,13.44]],"id":40626946}],"con":true,"img":false}]}
{"op":"mcm","clk":"11541372781","pt":1719505078159,"mc":[{"id":"1.230178325","rc":[{"atl":[[3.9,0]],"id":63579394}],"con":true,"img":false}]}
{"op":"mcm","clk":"11541372796","pt":1719505078263,"mc":[{"id":"1.230178325","rc":[{"atb":[[2.42,6.84]],"id":63579394},{"atb":[[3.6,3]],"id":70902602},{"atb":[[3.4,4]],"id":57055802},{"atb":[[2.38,4.3]],"id":40626946}],"con":true,"img":false}]}
{"op":"mcm","clk":"11541372823","pt":1719505078421,"mc":[{"id":"1.230178325","rc":[{"atb":[[3.6,5.39],[3.65,1]],"id":70902602},{"atl":[[5.1,3.23]],"id":70902602},{"atb":[[2.42,18.22]],"id":63579394},{"atl":[[2.9,0.84]],"id":69769647},{"atb":[[3.4,19.87]],"id":57055802},{"atb":[[2.38,10.4]],"id":40626946}],"con":true,"img":false}]}
{"op":"mcm","clk":"11541372841","pt":1719505078632,"mc":[{"id":"1.230178325","rc":[{"atb":[[3.55,0]],"id":70902602},{"atl":[[5.3,1.37]],"id":70902602},{"atb":[[2.4,2.11]],"id":63579394},{"atb":[[3.35,8.92]],"id":57055802},{"atb":[[2.36,1.94]],"id":40626946}],"con":true,"img":false}]}
{"op":"mcm","clk":"11541372867","pt":1719505078936,"mc":[{"id":"1.230178325","rc":[{"atl":[[5.3,0.52]],"id":70902602}],"con":true,"img":false}]}
{"op":"mcm","clk":"11541372875","pt":1719505079040,"mc":[{"id":"1.230178325","rc":[{"atl":[[5.3,0]],"id":70902602},{"atl":[[3.8,16.66]],"id":63579394},{"atb":[[2.36,0],[1.97,7.66]],"id":40626946}],"con":true,"img":false}]}
{"op":"mcm","clk":"11541372883","pt":1719505079147,"mc":[{"id":"1.230178325","rc":[{"atl":[[3.85,2.31]],"id":63579394},{"atb":[[1.78,0]],"id":40626946}],"con":true,"img":false}]}
{"op":"mcm","clk":"11541372894","pt":1719505079252,"mc":[{"id":"1.230178325","rc":[{"atb":[[2.4,1.94]],"id":40626946}],"con":true,"img":false}]}
{"op":"mcm","clk":"11541372924","pt":1719505079569,"mc":[{"id":"1.230178325","rc":[{"atb":[[3.5,0]],"id":70902602}],"con":true,"img":false}]}
{"op":"mcm","clk":"11541372944","pt":1719505079741,"mc":[{"id":"1.230178325","rc":[{"atb":[[2.84,2.5],[2.14,0],[2.76,5],[2.68,10]],"id":70902602},{"atl":[[3.75,0]],"id":69769647},{"atb":[[1.89,0],[2.12,10],[2.34,0],[2.28,2.5],[2.2,5]],"id":40626946},{"atb":[[2.82,0],[2.92,2.5],[2.84,5],[2.76,10]],"id":45129701}],"con":true,"img":false}]}
{"op":"mcm","clk":"11541372970","pt":1719505080038,"mc":[{"id":"1.230178325","rc":[{"atb":[[2.44,2.87]],"id":63579394},{"atb":[[3.45,3.01]],"id":57055802},{"atb":[[2.42,2.94]],"id":40626946}],"con":true,"img":false}]}
{"op":"mcm","clk":"11541373000","pt":1719505080353,"mc":[{"id":"1.230178325","rc":[{"atb":[[3.35,0]],"id":57055802}],"con":true,"img":false}]}
{"op":"mcm","clk":"11541373012","pt":1719505080460,"mc":[{"id":"1.230178325","rc":[{"atb":[[2.92,22.5],[2.86,0]],"id":45129701}],"con":true,"img":false}]}
{"op":"mcm","clk":"11541373021","pt":1719505080562,"mc":[{"id":"1.230178325","rc":[{"atb":[[2.42,16.22]],"id":63579394}],"con":true,"img":false}]}
{"op":"mcm","clk":"11541373031","pt":1719505080664,"mc":[{"id":"1.230178325","rc":[{"atb":[[2.46,2]],"id":63579394}],"con":true,"img":false}]}
{"op":"mcm","clk":"11541373044","pt":1719505080772,"mc":[{"id":"1.230178325","rc":[{"atb":[[2.48,2.75]],"id":63579394}],"con":true,"img":false}]}
{"op":"mcm","clk":"11541373068","pt":1719505080941,"mc":[{"id":"1.230178325","rc":[{"atl":[[5,2.56]],"id":70902602},{"atl":[[2.9,2.67]],"id":69769647},{"atl":[[5.8,1.83]],"id":57055802},{"atl":[[4.7,2.94]],"id":45129701}],"con":true,"img":false}]}
{"op":"mcm","clk":"11541373080","pt":1719505081035,"mc":[{"id":"1.230178325","rc":[{"atb":[[3.65,5.19]],"id":70902602},{"atb":[[2.42,6.61]],"id":40626946}],"con":true,"img":false}]}
{"op":"mcm","clk":"11541373089","pt":1719505081137,"mc":[{"id":"1.230178325","rc":[{"atb":[[3.6,3]],"id":70902602},{"atl":[[2.88,3.92],[2.9,5.35],[2.94,2.61]],"id":69769647},{"atb":[[2.38,4.3]],"id":40626946}],"con":true,"img":false}]}
{"op":"mcm","clk":"11541373103","pt":1719505081242,"mc":[{"id":"1.230178325","rc":[{"atl":[[2.86,1.9]],"id":69769647}],"con":true,"img":false}]}
{"op":"mcm","clk":"11541373114","pt":1719505081349,"mc":[{"id":"1.230178325","rc":[{"atl":[[2.86,5.82],[2.9,2.67],[2.96,0]],"id":69769647},{"atl":[[5.9,5.46]],"id":57055802},{"atl":[[4.8,0.84]],"id":45129701}],"con":true,"img":false}]}
{"op":"mcm","clk":"11541373124","pt":1719505081452,"mc":[{"id":"1.230178325","rc":[{"atl":[[4.9,0.84]],"id":70902602},{"atb":[[2.46,0]],"id":63579394},{"atl":[[2.94,1.77]],"id":69769647},{"atl":[[5.7,0.84]],"id":57055802},{"atl":[[4.6,0.84]],"id":45129701}],"con":true,"img":false}]}
{"op":"mcm","clk":"11541373132","pt":1719505081559,"mc":[{"id":"1.230178325","rc":[{"atb":[[2.5,2],[2.42,14.28]],"id":63579394},{"atb":[[2.4,0]],"id":40626946}],"con":true,"img":false}]}
{"op":"mcm","clk":"11541373138","pt":1719505081664,"mc":[{"id":"1.230178325","rc":[{"atb":[[2.44,0],[2.48,0]],"id":63579394}],"con":true,"img":false}]}
{"op":"mcm","clk":"11541373147","pt":1719505081767,"mc":[{"id":"1.230178325","rc":[{"atb":[[2.44,1.94]],"id":40626946}],"con":true,"img":false}]}
{"op":"mcm","clk":"11541373159","pt":1719505081828,"mc":[{"id":"1.230178325","rc":[{"atb":[[2.52,2.64]],"id":63579394},{"atb":[[3.45,12.64]],"id":57055802},{"atb":[[2.46,2.81]],"id":40626946}],"con":true,"img":false}]}
{"op":"mcm","clk":"11541373168","pt":1719505081941,"mc":[{"id":"1.230178325","rc":[{"atl":[[3.7,4.22]],"id":63579394},{"atl":[[2.9,1.83]],"id":69769647},{"atl":[[5.9,0.84],[5.7,7.2]],"id":57055802},{"atl":[[3.8,5.53]],"id":40626946},{"atl":[[4.6,6.8]],"id":45129701}],"con":true,"img":false}]}
{"op":"mcm","clk":"11541373177","pt":1719505082035,"mc":[{"id":"1.230178325","rc":[{"atb":[[3.5,13.58]],"id":57055802},{"atl":[[5.8,6.45]],"id":57055802},{"atl":[[4.6,13.07]],"id":45129701}],"con":true,"img":false}]}
{"op":"mcm","clk":"11541373188","pt":1719505082135,"mc":[{"id":"1.230178325","rc":[{"atl":[[3.8,8.33],[3.65,2.63]],"id":63579394},{"atb":[[3.55,2.81],[3.4,4]],"id":57055802},{"atl":[[6,1.7]],"id":57055802},{"atl":[[3.85,14.56],[3.75,2.34]],"id":40626946},{"atl":[[4.9,2.68]],"id":45129701}],"con":true,"img":false}]}
{"op":"mcm","clk":"11541373209","pt":1719505082345,"mc":[{"id":"1.230178325","rc":[{"atl":[[3.65,3.47]],"id":63579394},{"atl":[[2.92,0]],"id":69769647},{"atl":[[5.9,0],[7.6,0]],"id":57055802},{"atl":[[3.85,2.31],[3.9,0],[3.75,7.88]],"id":40626946},{"atl":[[4.8,0]],"id":45129701}],"con":true,"img":false}]}
{"op":"mcm","clk":"11541373241","pt":1719505082660,"mc":[{"id":"1.230178325","rc":[{"atb":[[2.5,0]],"id":63579394}],"con":true,"img":false}]}
{"op":"mcm","clk":"11541373256","pt":1719505082763,"mc":[{"id":"1.230178325","rc":[{"atb":[[2.54,2]],"id":63579394}],"con":true,"img":false}]}
{"op":"mcm","clk":"11541373269","pt":1719505082868,"mc":[{"id":"1.230178325","rc":[{"atb":[[2.56,2.52],[2.52,0]],"id":63579394},{"atb":[[3.45,11.53]],"id":57055802},{"atl":[[5.8,1.83]],"id":57055802}],"con":true,"img":false}]}
{"op":"mcm","clk":"11541373281","pt":1719505082973,"mc":[{"id":"1.230178325","rc":[{"atl":[[3.75,2.46]],"id":63579394},{"atl":[[3.7,0.84]],"id":40626946}],"con":true,"img":false}]}
{"op":"mcm","clk":"11541373293","pt":1719505083033,"mc":[{"id":"1.230178325","rc":[{"atb":[[3.45,3.01]],"id":57055802}],"con":true,"img":false}]}
{"op":"mcm","clk":"11541373308","pt":1719505083180,"mc":[{"id":"1.230178325","rc":[{"atl":[[3.75,11.06]],"id":63579394},{"atb":[[3.55,11.33]],"id":57055802}],"con":true,"img":false}]}
{"op":"mcm","clk":"11541373368","pt":1719505083647,"mc":[{"id":"1.230178325","rc":[{"atb":[[2.56,16.98],[2.42,11.38]],"id":63579394},{"atb":[[3.6,0]],"id":70902602},{"atb":[[3.4,0]],"id":57055802},{"atl":[[5.7,12.11]],"id":57055802},{"atb":[[2.38,0]],"id":40626946},{"atb":[[3.35,7]],"id":45129701}],"con":true,"img":false}]}
{"op":"mcm","clk":"11541373384","pt":1719505083751,"mc":[{"id":"1.230178325","rc":[{"atb":[[2.54,0]],"id":63579394},{"atb":[[3.7,2.95]],"id":70902602},{"atl":[[2.84,2.53]],"id":69769647},{"atb":[[3.6,3.6]],"id":57055802},{"atb":[[2.48,2.9]],"id":40626946},{"atb":[[3.35,0]],"id":45129701}],"con":true,"img":false}]}
{"op":"mcm","clk":"11541373396","pt":1719505083855,"mc":[{"id":"1.230178325","rc":[{"atb":[[3.75,1]],"id":70902602},{"atb":[[2.58,2]],"id":63579394},{"atb":[[3.65,2.63]],"id":57055802},{"atb":[[2.48,5.65]],"id":40626946},{"atb":[[3.3,9],[2.94,1.77]],"id":45129701}],"con":true,"img":false}]}
{"op":"mcm","clk":"11541373419","pt":1719505084063,"mc":[{"id":"1.230178325","rc":[{"atb":[[3.65,4.19]],"id":70902602}],"con":true,"img":false}]}
{"op":"mcm","clk":"11541373454","pt":1719505084375,"mc":[{"id":"1.230178325","rc":[{"atb":[[1.44,0],[1.51,7.14]],"id":70902602},{"atl":[[3.85,14.86],[3.8,0]],"id":63579394}],"con":true,"img":false}]}
{"op":"mcm","clk":"11541373463","pt":1719505084436,"mc":[{"id":"1.230178325","rc":[{"atb":[[2.56,15.84]],"id":63579394},{"atb":[[3.55,11.07]],"id":57055802}],"con":true,"img":false}]}
{"op":"mcm","clk":"11541373490","pt":1719505084737,"mc":[{"id":"1.230178325","rc":[{"atb":[[2.56,2.52]],"id":63579394},{"atb":[[3.55,2.81]],"id":57055802}],"con":true,"img":false}]}
{"op":"mcm","clk":"11541373500","pt":1719505084841,"mc":[{"id":"1.230178325","rc":[{"atb":[[2.58,15.32]],"id":63579394},{"atb":[[3.65,10.89]],"id":57055802}],"con":true,"img":false}]}
{"op":"mcm","clk":"11541373509","pt":1719505084945,"mc":[{"id":"1.230178325","rc":[{"atb":[[2.5,3.62]],"id":63579394}],"con":true,"img":false}]}
{"op":"mcm","clk":"11541373633","pt":1719505086263,"mc":[{"id":"1.230178325","rc":[{"atl":[[2.84,0]],"id":69769647}],"con":true,"img":false}]}
{"op":"mcm","clk":"11541373687","pt":1719505086836,"mc":[{"id":"1.230178325","rc":[{"atb":[[1.63,0],[1.49,0],[1.42,10]],"id":69769647},{"atl":[[3.35,0],[3.55,0]],"id":69769647}],"con":true,"img":false}]}
{"op":"mcm","clk":"11541373754","pt":1719505087668,"mc":[{"id":"1.230178325","rc":[{"atb":[[1.46,2.11],[1.69,0]],"id":69769647}],"con":true,"img":false}]}
{"op":"mcm","clk":"11541373834","pt":1719505088261,"mc":[{"id":"1.230178325","rc":[{"atb":[[1.7,0]],"id":69769647}],"con":true,"img":false}]}
{"op":"mcm","clk":"11541373848","pt":1719505088351,"mc":[{"id":"1.230178325","rc":[{"atb":[[1.48,4.31],[1.47,7.31]],"id":69769647}],"con":true,"img":false}]}
{"op":"mcm","clk":"11541373897","pt":1719505088763,"mc":[{"id":"1.230178325","rc":[{"atl":[[3.75,2.46]],"id":63579394},{"atl":[[4.1,0],[4.9,3.51]],"id":70902602},{"atb":[[2.48,11.91]],"id":40626946}],"con":true,"img":false}]}
{"op":"mcm","clk":"11541373910","pt":1719505088869,"mc":[{"id":"1.230178325","rc":[{"atb":[[1.41,1]],"id":69769647},{"atb":[[3.7,4.81]],"id":57055802}],"con":true,"img":false}]}
{"op":"mcm","clk":"11541373922","pt":1719505088972,"mc":[{"id":"1.230178325","rc":[{"atl":[[5.1,0.84]],"id":70902602},{"atb":[[3.75,2.46]],"id":57055802},{"atb":[[2.42,2.94]],"id":40626946}],"con":true,"img":false}]}
{"op":"mcm","clk":"11541373935","pt":1719505089076,"mc":[{"id":"1.230178325","rc":[{"atl":[[2.76,2.53]],"id":69769647},{"atb":[[3.5,0]],"id":57055802}],"con":true,"img":false}]}
{"op":"mcm","clk":"11541373946","pt":1719505089137,"mc":[{"id":"1.230178325","rc":[{"atl":[[2.86,1.9],[2.76,6.45]],"id":69769647}],"con":true,"img":false}]}
{"op":"mcm","clk":"11541373975","pt":1719505089444,"mc":[{"id":"1.230178325","rc":[{"atl":[[5.1,0]],"id":70902602},{"atb":[[3.6,0]],"id":57055802}],"con":true,"img":false}]}
{"op":"mcm","clk":"11541373985","pt":1719505089542,"mc":[{"id":"1.230178325","rc":[{"atb":[[1.49,4]],"id":69769647}],"con":true,"img":false}]}
{"op":"mcm","clk":"11541373994","pt":1719505089645,"mc":[{"id":"1.230178325","rc":[{"atb":[[1.5,2.29]],"id":69769647}],"con":true,"img":false}]}
{"op":"mcm","clk":"11541374003","pt":1719505089748,"mc":[{"id":"1.230178325","rc":[{"atl":[[4.8,0.52]],"id":70902602}],"con":true,"img":false}]}
{"op":"mcm","clk":"11541374014","pt":1719505089851,"mc":[{"id":"1.230178325","rc":[{"atb":[[1.06,0.52]],"id":70902602},{"atb":[[3.65,2.63]],"id":57055802}],"con":true,"img":false}]}
{"op":"mcm","clk":"11541374025","pt":1719505089956,"mc":[{"id":"1.230178325","rc":[{"atl":[[4.9,9.38]],"id":70902602},{"atl":[[3.75,11.4]],"id":63579394}],"con":true,"img":false}]}
{"op":"mcm","clk":"11541374037","pt":1719505090059,"mc":[{"id":"1.230178325","rc":[{"atb":[[1.06,0.18]],"id":70902602}],"con":true,"img":false}]}
{"op":"mcm","clk":"11541374059","pt":1719505090372,"mc":[{"id":"1.230178325","rc":[{"atb":[[1.06,0]],"id":70902602}],"con":true,"img":false}]}
{"op":"mcm","clk":"11541374069","pt":1719505090475,"mc":[{"id":"1.230178325","rc":[{"atb":[[3.8,0.18]],"id":70902602},{"atb":[[1.48,2.31]],"id":69769647},{"atb":[[3.75,10.43]],"id":57055802}],"con":true,"img":false}]}
{"op":"mcm","clk":"11541374076","pt":1719505090578,"mc":[{"id":"1.230178325","rc":[{"atb":[[3.85,1]],"id":70902602},{"atb":[[1.51,2]],"id":69769647}],"con":true,"img":false}]}
{"op":"mcm","clk":"11541374084","pt":1719505090683,"mc":[{"id":"1.230178325","rc":[{"atb":[[3.75,0]],"id":70902602},{"atb":[[1.52,2.27]],"id":69769647}],"con":true,"img":false}]}
{"op":"mcm","clk":"11541374095","pt":1719505090747,"mc":[{"id":"1.230178325","rc":[{"atl":[[2.78,3.13]],"id":69769647}],"con":true,"img":false}]}
{"op":"mcm","clk":"11541374161","pt":1719505091463,"mc":[{"id":"1.230178325","rc":[{"atl":[[2.74,3.42]],"id":69769647}],"con":true,"img":false}]}
{"op":"mcm","clk":"11541374172","pt":1719505091568,"mc":[{"id":"1.230178325","rc":[{"atl":[[2.76,3.92]],"id":69769647}],"con":true,"img":false}]}
{"op":"mcm","clk":"11541374190","pt":1719505091774,"mc":[{"id":"1.230178325","rc":[{"atl":[[2.88,0]],"id":69769647}],"con":true,"img":false}]}
{"op":"mcm","clk":"11541374201","pt":1719505091877,"mc":[{"id":"1.230178325","rc":[{"atb":[[1.51,0]],"id":69769647}],"con":true,"img":false}]}
{"op":"mcm","clk":"11541374212","pt":1719505091937,"mc":[{"id":"1.230178325","rc":[{"atb":[[1.53,2]],"id":69769647}],"con":true,"img":false}]}
{"op":"mcm","clk":"11541374223","pt":1719505092044,"mc":[{"id":"1.230178325","rc":[{"atb":[[1.48,0],[1.5,0],[1.52,0]],"id":69769647}],"con":true,"img":false}]}
{"op":"mcm","clk":"11541374240","pt":1719505092249,"mc":[{"id":"1.230178325","rc":[{"atl":[[3.65,9.35]],"id":63579394},{"atl":[[3.75,14.14]],"id":40626946}],"con":true,"img":false}]}
{"op":"mcm","clk":"11541374249","pt":1719505092384,"mc":[{"id":"1.230178325","rc":[{"atb":[[1.54,2.27]],"id":69769647},{"atb":[[3.8,5.58]],"id":57055802}],"con":true,"img":false}]}
{"op":"mcm","clk":"11541374255","pt":1719505092455,"mc":[{"id":"1.230178325","rc":[{"atl":[[3.7,0]],"id":63579394},{"atb":[[3.8,7.97],[3.7,0]],"id":57055802},{"atl":[[3.8,0.84]],"id":40626946}],"con":true,"img":false}]}
{"op":"mcm","clk":"11541374273","pt":1719505092671,"mc":[{"id":"1.230178325","rc":[{"atb":[[1.53,0]],"id":69769647}],"con":true,"img":false}]}
{"op":"mcm","clk":"11541374283","pt":1719505092775,"mc":[{"id":"1.230178325","rc":[{"atb":[[1.5,2]],"id":69769647}],"con":true,"img":false}]}
{"op":"mcm","clk":"11541374291","pt":1719505092878,"mc":[{"id":"1.230178325","rc":[{"atb":[[1.54,0]],"id":69769647},{"atb":[[3.75,2.46]],"id":57055802}],"con":true,"img":false}]}
{"op":"mcm","clk":"11541374300","pt":1719505092948,"mc":[{"id":"1.230178325","rc":[{"atb":[[1.51,2.25]],"id":69769647},{"atl":[[2.64,2.53]],"id":69769647}],"con":true,"img":false}]}
{"op":"mcm","clk":"11541374321","pt":1719505093150,"mc":[{"id":"1.230178325","rc":[{"atb":[[1.48,5.54]],"id":69769647}],"con":true,"img":false}]}
{"op":"mcm","clk":"11541374350","pt":1719505093452,"mc":[{"id":"1.230178325","rc":[{"atb":[[1.5,0]],"id":69769647}],"con":true,"img":false}]}
{"op":"mcm","clk":"11541374359","pt":1719505093560,"mc":[{"id":"1.230178325","rc":[{"atb":[[1.52,2]],"id":69769647},{"atb":[[3.8,16.87]],"id":57055802}],"con":true,"img":false}]}
