{"op":"mcm","clk":"11536832979","pt":1719431775511,"mc":[{"id":"1.230180129","marketDefinition":{"bspMarket":true,"turnInPlayEnabled":false,"persistenceEnabled":false,"marketBaseRate":5.0,"eventId":"33376437","eventTypeId":"4339","numberOfWinners":2,"bettingType":"ODDS","marketType":"PLACE","marketTime":"2024-06-27T16:03:00.000Z","suspendTime":"2024-06-27T16:03:00.000Z","bspReconciled":false,"complete":true,"inPlay":false,"crossMatching":false,"runnersVoidable":false,"numberOfActiveRunners":6,"betDelay":0,"status":"OPEN","runners":[{"status":"ACTIVE","sortPriority":1,"id":66050026,"name":"1. Salacres Elunico"},{"status":"ACTIVE","sortPriority":2,"id":58821523,"name":"2. Makeit Missy"},{"status":"ACTIVE","sortPriority":3,"id":50639934,"name":"3. Greencroft Annie"},{"status":"ACTIVE","sortPriority":4,"id":69213654,"name":"4. Salacres Crafty"},{"status":"ACTIVE","sortPriority":5,"id":51218587,"name":"5. Golden Bullet"},{"status":"ACTIVE","sortPriority":6,"id":60237218,"name":"6. Arwens Link"}],"regulators":["MR_INT"],"venue":"Towcester","countryCode":"GB","discountAllowed":false,"timezone":"Europe/London","openDate":"2024-06-27T13:33:00.000Z","version":5994767105,"name":"To Be Placed","eventName":"Towcester 27th Jun"},"rc":[],"con":true,"img":false}]}
{"op":"mcm","clk":"11536833127","pt":1719431777510,"mc":[{"id":"1.230180129","marketDefinition":{"bspMarket":true,"turnInPlayEnabled":false,"persistenceEnabled":false,"marketBaseRate":5.0,"eventId":"33376437","eventTypeId":"4339","numberOfWinners":2,"bettingType":"ODDS","marketType":"PLACE","marketTime":"2024-06-27T16:03:00.000Z","suspendTime":"2024-06-27T16:03:00.000Z","bspReconciled":false,"complete":true,"inPlay":false,"crossMatching":false,"runnersVoidable":false,"numberOfActiveRunners":6,"betDelay":0,"status":"OPEN","runners":[{"status":"ACTIVE","sortPriority":1,"id":66050026,"name":"1. Salacres Elunico"},{"status":"ACTIVE","sortPriority":2,"id":58821523,"name":"2. Makeit Missy"},{"status":"ACTIVE","sortPriority":3,"id":50639934,"name":"3. Greencroft Annie"},{"status":"ACTIVE","sortPriority":4,"id":69213654,"name":"4. Salacres Crafty"},{"status":"ACTIVE","sortPriority":5,"id":51218587,"name":"5. Golden Bullet"},{"status":"ACTIVE","sortPriority":6,"id":60237218,"name":"6. Arwens Link"}],"regulators":["MR_INT"],"venue":"Towcester","countryCode":"GB","discountAllowed":true,"timezone":"Europe/London","openDate":"2024-06-27T13:33:00.000Z","version":5994767105,"name":"To Be Placed","eventName":"Towcester 27th Jun"},"rc":[],"con":true,"img":false}]}
{"op":"mcm","clk":"11537084005","pt":1719435435724,"mc":[{"id":"1.230180129","rc":[{"atb":[[1.01,51.84]],"id":58821523},{"atl":[[990,0.84]],"id":58821523},{"spn":495.5,"spf":"NaN","id":58821523},{"atb":[[1.02,25.92]],"id":50639934},{"atl":[[1000,0.84]],"id":50639934},{"spn":500.51,"spf":"NaN","id":50639934},{"atb":[[1.01,51.84]],"id":60237218},{"atl":[[1000,0.84]],"id":60237218},{"spn":500.5,"spf":"NaN","id":60237218},{"atb":[[1.02,25.92]],"id":51218587},{"atl":[[990,0.84]],"id":51218587},{"spn":495.51,"spf":"NaN","id":51218587},{"atb":[[1.02,25.92]],"id":69213654},{"atl":[[990,0.84]],"id":69213654},{"spn":495.51,"spf":"NaN","id":69213654},{"atb":[[1.01,51.84]],"id":66050026},{"atl":[[1000,0.84]],"id":66050026},{"spn":500.5,"spf":"NaN","id":66050026}],"con":true,"img":false}]}
{"op":"mcm","clk":"11537235630","pt":1719437882798,"mc":[{"id":"1.230180129","marketDefinition":{"bspMarket":true,"turnInPlayEnabled":false,"persistenceEnabled":false,"marketBaseRate":5.0,"eventId":"33376437","eventTypeId":"4339","numberOfWinners":2,"bettingType":"ODDS","marketType":"PLACE","marketTime":"2024-06-27T16:03:00.000Z","suspendTime":"2024-06-27T16:03:00.000Z","bspReconciled":false,"complete":true,"inPlay":false,"crossMatching":false,"runnersVoidable":false,"numberOfActiveRunners":6,"betDelay":0,"status":"OPEN","runners":[{"status":"ACTIVE","sortPriority":1,"id":66050026,"name":"1. Salacres Elunico"},{"status":"ACTIVE","sortPriority":2,"id":58821523,"name":"2. Makeit Missy"},{"status":"ACTIVE","sortPriority":3,"id":50639934,"name":"3. Greencroft Annie"},{"status":"ACTIVE","sortPriority":4,"id":69213654,"name":"4. Salacres Crafty"},{"status":"ACTIVE","sortPriority":5,"id":51218587,"name":"5. Golden Bullet"},{"status":"ACTIVE","sortPriority":6,"id":60237218,"name":"6. Arwens Link"}],"regulators":["MR_INT"],"venue":"Towcester","countryCode":"GB","discountAllowed":true,"timezone":"Europe/London","openDate":"2024-06-27T13:33:00.000Z","version":5994767105,"name":"To Be Placed","eventName":"Towcester 27th Jun"},"rc":[{"atb":[[1.01,51.85]],"id":58821523},{"atl":[[990,0.84]],"id":58821523},{"spn":495.5,"spf":"NaN","id":58821523},{"atb":[[1.02,25.92]],"id":50639934},{"atl":[[1000,0.84]],"id":50639934},{"spn":500.51,"spf":"NaN","id":50639934},{"atb":[[1.01,51.85]],"id":60237218},{"atl":[[1000,0.84]],"id":60237218},{"spn":500.5,"spf":"NaN","id":60237218},{"atb":[[1.02,25.92]],"id":51218587},{"atl":[[990,0.84]],"id":51218587},{"spn":495.51,"spf":"NaN","id":51218587},{"atb":[[1.02,25.92]],"id":69213654},{"atl":[[990,0.84]],"id":69213654},{"spn":495.51,"spf":"NaN","id":69213654},{"atb":[[1.01,51.85]],"id":66050026},{"atl":[[1000,0.84]],"id":66050026},{"spn":500.5,"spf":"NaN","id":66050026}],"con":true,"img":true}]}
{"op":"mcm","clk":"11537302582","pt":1719439039936,"mc":[{"id":"1.230180129","rc":[{"atb":[[1.01,51.85]],"id":58821523},{"atl":[[990,0.23]],"id":58821523},{"atb":[[1.02,25.92]],"id":50639934},{"atl":[[1000,0.23]],"id":50639934},{"atb":[[1.01,51.85]],"id":60237218},{"atl":[[1000,0.23]],"id":60237218},{"atb":[[1.02,25.92]],"id":51218587},{"atl":[[990,0.23]],"id":51218587},{"atb":[[1.02,25.92]],"id":69213654},{"atl":[[990,0.23]],"id":69213654},{"atb":[[1.01,51.85]],"id":66050026},{"atl":[[1000,0.23]],"id":66050026}],"con":true,"img":false}]}
{"op":"mcm","clk":"11537576918","pt":1719443282842,"mc":[{"id":"1.230180129","marketDefinition":{"bspMarket":true,"turnInPlayEnabled":false,"persistenceEnabled":false,"marketBaseRate":5.0,"eventId":"33376437","eventTypeId":"4339","numberOfWinners":2,"bettingType":"ODDS","marketType":"PLACE","marketTime":"2024-06-27T16:03:00.000Z","suspendTime":"2024-06-27T16:03:00.000Z","bspReconciled":false,"complete":true,"inPlay":false,"crossMatching":false,"runnersVoidable":false,"numberOfActiveRunners":6,"betDelay":0,"status":"OPEN","runners":[{"status":"ACTIVE","sortPriority":1,"id":66050026,"name":"1. Salacres Elunico"},{"status":"ACTIVE","sortPriority":2,"id":58821523,"name":"2. Makeit Missy"},{"status":"ACTIVE","sortPriority":3,"id":50639934,"name":"3. Greencroft Annie"},{"status":"ACTIVE","sortPriority":4,"id":69213654,"name":"4. Salacres Crafty"},{"status":"ACTIVE","sortPriority":5,"id":51218587,"name":"5. Golden Bullet"},{"status":"ACTIVE","sortPriority":6,"id":60237218,"name":"6. Arwens Link"}],"regulators":["MR_INT"],"venue":"Towcester","countryCode":"GB","discountAllowed":true,"timezone":"Europe/London","openDate":"2024-06-27T13:33:00.000Z","version":5994767105,"name":"To Be Placed","eventName":"Towcester 27th Jun"},"rc":[{"atb":[[1.01,51.85]],"id":58821523},{"atl":[[990,0.23]],"id":58821523},{"spn":495.5,"spf":"NaN","id":58821523},{"atb":[[1.02,25.92]],"id":50639934},{"atl":[[1000,0.23]],"id":50639934},{"spn":500.51,"spf":"NaN","id":50639934},{"atb":[[1.01,51.85]],"id":60237218},{"atl":[[1000,0.23]],"id":60237218},{"spn":500.5,"spf":"NaN","id":60237218},{"atb":[[1.02,25.92]],"id":51218587},{"atl":[[990,0.23]],"id":51218587},{"spn":495.51,"spf":"NaN","id":51218587},{"atb":[[1.02,25.92]],"id":69213654},{"atl":[[990,0.23]],"id":69213654},{"spn":495.51,"spf":"NaN","id":69213654},{"atb":[[1.01,51.85]],"id":66050026},{"atl":[[1000,0.23]],"id":66050026},{"spn":500.5,"spf":"NaN","id":66050026}],"con":true,"img":true}]}
{"op":"mcm","clk":"11537958605","pt":1719448682890,"mc":[{"id":"1.230180129","marketDefinition":{"bspMarket":true,"turnInPlayEnabled":false,"persistenceEnabled":false,"marketBaseRate":5.0,"eventId":"33376437","eventTypeId":"4339","numberOfWinners":2,"bettingType":"ODDS","marketType":"PLACE","marketTime":"2024-06-27T16:03:00.000Z","suspendTime":"2024-06-27T16:03:00.000Z","bspReconciled":false,"complete":true,"inPlay":false,"crossMatching":false,"runnersVoidable":false,"numberOfActiveRunners":6,"betDelay":0,"status":"OPEN","runners":[{"status":"ACTIVE","sortPriority":1,"id":66050026,"name":"1. Salacres Elunico"},{"status":"ACTIVE","sortPriority":2,"id":58821523,"name":"2. Makeit Missy"},{"status":"ACTIVE","sortPriority":3,"id":50639934,"name":"3. Greencroft Annie"},{"status":"ACTIVE","sortPriority":4,"id":69213654,"name":"4. Salacres Crafty"},{"status":"ACTIVE","sortPriority":5,"id":51218587,"name":"5. Golden Bullet"},{"status":"ACTIVE","sortPriority":6,"id":60237218,"name":"6. Arwens Link"}],"regulators":["MR_INT"],"venue":"Towcester","countryCode":"GB","discountAllowed":true,"timezone":"Europe/London","openDate":"2024-06-27T13:33:00.000Z","version":5994767105,"name":"To Be Placed","eventName":"Towcester 27th Jun"},"rc":[{"atb":[[1.01,51.85]],"id":58821523},{"atl":[[990,0.23]],"id":58821523},{"spn":495.5,"spf":"NaN","id":58821523},{"atb":[[1.02,25.92]],"id":50639934},{"atl":[[1000,0.23]],"id":50639934},{"spn":500.51,"spf":"NaN","id":50639934},{"atb":[[1.01,51.85]],"id":60237218},{"atl":[[1000,0.23]],"id":60237218},{"spn":500.5,"spf":"NaN","id":60237218},{"atb":[[1.02,25.92]],"id":51218587},{"atl":[[990,0.23]],"id":51218587},{"spn":495.51,"spf":"NaN","id":51218587},{"atb":[[1.02,25.92]],"id":69213654},{"atl":[[990,0.23]],"id":69213654},{"spn":495.51,"spf":"NaN","id":69213654},{"atb":[[1.01,51.85]],"id":66050026},{"atl":[[1000,0.23]],"id":66050026},{"spn":500.5,"spf":"NaN","id":66050026}],"con":true,"img":true}]}
{"op":"mcm","clk":"11538174181","pt":1719454082861,"mc":[{"id":"1.230180129","marketDefinition":{"bspMarket":true,"turnInPlayEnabled":false,"persistenceEnabled":false,"marketBaseRate":5.0,"eventId":"33376437","eventTypeId":"4339","numberOfWinners":2,"bettingType":"ODDS","marketType":"PLACE","marketTime":"2024-06-27T16:03:00.000Z","suspendTime":"2024-06-27T16:03:00.000Z","bspReconciled":false,"complete":true,"inPlay":false,"crossMatching":false,"runnersVoidable":false,"numberOfActiveRunners":6,"betDelay":0,"status":"OPEN","runners":[{"status":"ACTIVE","sortPriority":1,"id":66050026,"name":"1. Salacres Elunico"},{"status":"ACTIVE","sortPriority":2,"id":58821523,"name":"2. Makeit Missy"},{"status":"ACTIVE","sortPriority":3,"id":50639934,"name":"3. Greencroft Annie"},{"status":"ACTIVE","sortPriority":4,"id":69213654,"name":"4. Salacres Crafty"},{"status":"ACTIVE","sortPriority":5,"id":51218587,"name":"5. Golden Bullet"},{"status":"ACTIVE","sortPriority":6,"id":60237218,"name":"6. Arwens Link"}],"regulators":["MR_INT"],"venue":"Towcester","countryCode":"GB","discountAllowed":true,"timezone":"Europe/London","openDate":"2024-06-27T13:33:00.000Z","version":5994767105,"name":"To Be Placed","eventName":"Towcester 27th Jun"},"rc":[{"atb":[[1.01,51.86]],"id":58821523},{"atl":[[990,0.23]],"id":58821523},{"spn":495.5,"spf":"NaN","id":58821523},{"atb":[[1.02,25.93]],"id":50639934},{"atl":[[1000,0.23]],"id":50639934},{"spn":500.51,"spf":"NaN","id":50639934},{"atb":[[1.01,51.86]],"id":60237218},{"atl":[[1000,0.23]],"id":60237218},{"spn":500.5,"spf":"NaN","id":60237218},{"atb":[[1.02,25.93]],"id":51218587},{"atl":[[990,0.23]],"id":51218587},{"spn":495.51,"spf":"NaN","id":51218587},{"atb":[[1.02,25.93]],"id":69213654},{"atl":[[990,0.23]],"id":69213654},{"spn":495.51,"spf":"NaN","id":69213654},{"atb":[[1.01,51.86]],"id":66050026},{"atl":[[1000,0.23]],"id":66050026},{"spn":500.5,"spf":"NaN","id":66050026}],"con":true,"img":true}]}
{"op":"mcm","clk":"11538371894","pt":1719459482934,"mc":[{"id":"1.230180129","marketDefinition":{"bspMarket":true,"turnInPlayEnabled":false,"persistenceEnabled":false,"marketBaseRate":5.0,"eventId":"33376437","eventTypeId":"4339","numberOfWinners":2,"bettingType":"ODDS","marketType":"PLACE","marketTime":"2024-06-27T16:03:00.000Z","suspendTime":"2024-06-27T16:03:00.000Z","bspReconciled":false,"complete":true,"inPlay":false,"crossMatching":false,"runnersVoidable":false,"numberOfActiveRunners":6,"betDelay":0,"status":"OPEN","runners":[{"status":"ACTIVE","sortPriority":1,"id":66050026,"name":"1. Salacres Elunico"},{"status":"ACTIVE","sortPriority":2,"id":58821523,"name":"2. Makeit Missy"},{"status":"ACTIVE","sortPriority":3,"id":50639934,"name":"3. Greencroft Annie"},{"status":"ACTIVE","sortPriority":4,"id":69213654,"name":"4. Salacres Crafty"},{"status":"ACTIVE","sortPriority":5,"id":51218587,"name":"5. Golden Bullet"},{"status":"ACTIVE","sortPriority":6,"id":60237218,"name":"6. Arwens Link"}],"regulators":["MR_INT"],"venue":"Towcester","countryCode":"GB","discountAllowed":true,"timezone":"Europe/London","openDate":"2024-06-27T13:33:00.000Z","version":5994767105,"name":"To Be Placed","eventName":"Towcester 27th Jun"},"rc":[{"atb":[[1.01,51.87]],"id":58821523},{"atl":[[990,0.23]],"id":58821523},{"spn":495.5,"spf":"NaN","id":58821523},{"atb":[[1.02,25.93]],"id":50639934},{"atl":[[1000,0.23]],"id":50639934},{"spn":500.51,"spf":"NaN","id":50639934},{"atb":[[1.01,51.87]],"id":60237218},{"atl":[[1000,0.23]],"id":60237218},{"spn":500.5,"spf":"NaN","id":60237218},{"atb":[[1.02,25.93]],"id":51218587},{"atl":[[990,0.23]],"id":51218587},{"spn":495.51,"spf":"NaN","id":51218587},{"atb":[[1.02,25.93]],"id":69213654},{"atl":[[990,0.23]],"id":69213654},{"spn":495.51,"spf":"NaN","id":69213654},{"atb":[[1.01,51.87]],"id":66050026},{"atl":[[1000,0.23]],"id":66050026},{"spn":500.5,"spf":"NaN","id":66050026}],"con":true,"img":true}]}
{"op":"mcm","clk":"11538598971","pt":1719464882861,"mc":[{"id":"1.230180129","marketDefinition":{"bspMarket":true,"turnInPlayEnabled":false,"persistenceEnabled":false,"marketBaseRate":5.0,"eventId":"33376437","eventTypeId":"4339","numberOfWinners":2,"bettingType":"ODDS","marketType":"PLACE","marketTime":"2024-06-27T16:03:00.000Z","suspendTime":"2024-06-27T16:03:00.000Z","bspReconciled":false,"complete":true,"inPlay":false,"crossMatching":false,"runnersVoidable":false,"numberOfActiveRunners":6,"betDelay":0,"status":"OPEN","runners":[{"status":"ACTIVE","sortPriority":1,"id":66050026,"name":"1. Salacres Elunico"},{"status":"ACTIVE","sortPriority":2,"id":58821523,"name":"2. Makeit Missy"},{"status":"ACTIVE","sortPriority":3,"id":50639934,"name":"3. Greencroft Annie"},{"status":"ACTIVE","sortPriority":4,"id":69213654,"name":"4. Salacres Crafty"},{"status":"ACTIVE","sortPriority":5,"id":51218587,"name":"5. Golden Bullet"},{"status":"ACTIVE","sortPriority":6,"id":60237218,"name":"6. Arwens Link"}],"regulators":["MR_INT"],"venue":"Towcester","countryCode":"GB","discountAllowed":true,"timezone":"Europe/London","openDate":"2024-06-27T13:33:00.000Z","version":5994767105,"name":"To Be Placed","eventName":"Towcester 27th Jun"},"rc":[{"atb":[[1.01,51.86]],"id":58821523},{"atl":[[990,0.23]],"id":58821523},{"spn":495.5,"spf":"NaN","id":58821523},{"atb":[[1.02,25.93]],"id":50639934},{"atl":[[1000,0.23]],"id":50639934},{"spn":500.51,"spf":"NaN","id":50639934},{"atb":[[1.01,51.86]],"id":60237218},{"atl":[[1000,0.23]],"id":60237218},{"spn":500.5,"spf":"NaN","id":60237218},{"atb":[[1.02,25.93]],"id":51218587},{"atl":[[990,0.23]],"id":51218587},{"spn":495.51,"spf":"NaN","id":51218587},{"atb":[[1.02,25.93]],"id":69213654},{"atl":[[990,0.23]],"id":69213654},{"spn":495.51,"spf":"NaN","id":69213654},{"atb":[[1.01,51.86]],"id":66050026},{"atl":[[1000,0.23]],"id":66050026},{"spn":500.5,"spf":"NaN","id":66050026}],"con":true,"img":true}]}
{"op":"mcm","clk":"11538906744","pt":1719471498682,"mc":[{"id":"1.230180129","rc":[{"atb":[[1.01,51.86],[1.07,2.48]],"id":58821523},{"atl":[[1000,1]],"id":58821523},{"spn":495.53,"spf":"NaN","id":58821523},{"atb":[[1.02,25.93],[1.07,2.48]],"id":50639934},{"atl":[[1000,1.23]],"id":50639934},{"spn":500.53,"spf":"NaN","id":50639934},{"atb":[[1.01,51.86],[1.07,2.48]],"id":60237218},{"atl":[[1000,1.23]],"id":60237218},{"spn":500.53,"spf":"NaN","id":60237218},{"atb":[[1.02,25.93],[1.07,2.48]],"id":51218587},{"atl":[[1000,1]],"id":51218587},{"spn":495.53,"spf":"NaN","id":51218587},{"atb":[[1.02,25.93],[1.07,2.48]],"id":69213654},{"atl":[[1000,1]],"id":69213654},{"spn":495.53,"spf":"NaN","id":69213654},{"atb":[[1.01,51.86],[1.07,2.48]],"id":66050026},{"atl":[[1000,1.23]],"id":66050026},{"spn":500.53,"spf":"NaN","id":66050026}],"con":true,"img":false}]}
{"op":"mcm","clk":"11538906751","pt":1719471498887,"mc":[{"id":"1.230180129","rc":[{"atl":[[1000,0.48]],"id":58821523},{"atl":[[1000,0.71]],"id":50639934},{"atl":[[1000,0.71]],"id":60237218},{"atl":[[1000,0.48]],"id":51218587},{"atl":[[1000,0.48]],"id":69213654},{"atl":[[1000,0.71]],"id":66050026}],"con":true,"img":false}]}
{"op":"mcm","clk":"11538906762","pt":1719471499095,"mc":[{"id":"1.230180129","rc":[{"atl":[[1000,0]],"id":58821523},{"atl":[[1000,0.23]],"id":50639934},{"atl":[[1000,0.23]],"id":60237218},{"atl":[[1000,0]],"id":51218587},{"atl":[[1000,0]],"id":69213654},{"atl":[[1000,0.23]],"id":66050026}],"con":true,"img":false}]}
{"op":"mcm","clk":"11538906767","pt":1719471499194,"mc":[{"id":"1.230180129","rc":[{"atl":[[75,0.48]],"id":58821523},{"atl":[[75,0.48]],"id":50639934},{"atl":[[75,0.48]],"id":60237218},{"atl":[[75,0.48]],"id":51218587},{"atl":[[75,0.48]],"id":69213654},{"atl":[[75,0.48]],"id":66050026}],"con":true,"img":false}]}
{"op":"mcm","clk":"11539126203","pt":1719475682882,"mc":[{"id":"1.230180129","marketDefinition":{"bspMarket":true,"turnInPlayEnabled":false,"persistenceEnabled":false,"marketBaseRate":5.0,"eventId":"33376437","eventTypeId":"4339","numberOfWinners":2,"bettingType":"ODDS","marketType":"PLACE","marketTime":"2024-06-27T16:03:00.000Z","suspendTime":"2024-06-27T16:03:00.000Z","bspReconciled":false,"complete":true,"inPlay":false,"crossMatching":false,"runnersVoidable":false,"numberOfActiveRunners":6,"betDelay":0,"status":"OPEN","runners":[{"status":"ACTIVE","sortPriority":1,"id":66050026,"name":"1. Salacres Elunico"},{"status":"ACTIVE","sortPriority":2,"id":58821523,"name":"2. Makeit Missy"},{"status":"ACTIVE","sortPriority":3,"id":50639934,"name":"3. Greencroft Annie"},{"status":"ACTIVE","sortPriority":4,"id":69213654,"name":"4. Salacres Crafty"},{"status":"ACTIVE","sortPriority":5,"id":51218587,"name":"5. Golden Bullet"},{"status":"ACTIVE","sortPriority":6,"id":60237218,"name":"6. Arwens Link"}],"regulators":["MR_INT"],"venue":"Towcester","countryCode":"GB","discountAllowed":true,"timezone":"Europe/London","openDate":"2024-06-27T13:33:00.000Z","version":5994767105,"name":"To Be Placed","eventName":"Towcester 27th Jun"},"rc":[{"atb":[[1.01,51.84],[1.07,2.48]],"id":58821523},{"atl":[[75,0.48],[990,0.23]],"id":58821523},{"spn":38.03,"spf":"NaN","id":58821523},{"atb":[[1.02,25.92],[1.07,2.48]],"id":50639934},{"atl":[[75,0.48],[1000,0.23]],"id":50639934},{"spn":38.03,"spf":"NaN","id":50639934},{"atb":[[1.01,51.84],[1.07,2.48]],"id":60237218},{"atl":[[75,0.48],[1000,0.23]],"id":60237218},{"spn":38.03,"spf":"NaN","id":60237218},{"atb":[[1.02,25.92],[1.07,2.48]],"id":51218587},{"atl":[[75,0.48],[990,0.23]],"id":51218587},{"spn":38.03,"spf":"NaN","id":51218587},{"atb":[[1.02,25.92],[1.07,2.48]],"id":69213654},{"atl":[[75,0.48],[990,0.23]],"id":69213654},{"spn":38.03,"spf":"NaN","id":69213654},{"atb":[[1.01,51.84],[1.07,2.48]],"id":66050026},{"atl":[[75,0.48],[1000,0.23]],"id":66050026},{"spn":38.03,"spf":"NaN","id":66050026}],"con":true,"img":true}]}
{"op":"mcm","clk":"11539347439","pt":1719479406593,"mc":[{"id":"1.230180129","rc":[{"spl":[[1.71,6]],"id":58821523},{"atb":[[1.01,51.83]],"id":58821523},{"atl":[[990,0.23]],"id":58821523},{"spn":1.39,"spf":1.0,"id":58821523},{"atb":[[1.02,25.91]],"id":50639934},{"atl":[[1000,0.23]],"id":50639934},{"spn":38.03,"spf":"NaN","id":50639934},{"atb":[[1.01,51.83]],"id":60237218},{"atl":[[1000,0.23]],"id":60237218},{"spn":38.03,"spf":"NaN","id":60237218},{"atb":[[1.02,25.91]],"id":51218587},{"atl":[[990,0.23]],"id":51218587},{"spn":38.03,"spf":"NaN","id":51218587},{"atb":[[1.02,25.91]],"id":69213654},{"atl":[[990,0.23]],"id":69213654},{"spn":38.03,"spf":"NaN","id":69213654},{"atb":[[1.01,51.83]],"id":66050026},{"atl":[[1000,0.23]],"id":66050026},{"spn":38.03,"spf":"NaN","id":66050026}],"con":true,"img":false}]}
{"op":"mcm","clk":"11540687345","pt":1719497282743,"mc":[{"id":"1.230180129","marketDefinition":{"bspMarket":true,"turnInPlayEnabled":false,"persistenceEnabled":false,"marketBaseRate":5.0,"eventId":"33376437","eventTypeId":"4339","numberOfWinners":2,"bettingType":"ODDS","marketType":"PLACE","marketTime":"2024-06-27T16:03:00.000Z","suspendTime":"2024-06-27T16:03:00.000Z","bspReconciled":false,"complete":true,"inPlay":false,"crossMatching":false,"runnersVoidable":false,"numberOfActiveRunners":6,"betDelay":0,"status":"OPEN","runners":[{"status":"ACTIVE","sortPriority":1,"id":66050026,"name":"1. Salacres Elunico"},{"status":"ACTIVE","sortPriority":2,"id":58821523,"name":"2. Makeit Missy"},{"status":"ACTIVE","sortPriority":3,"id":50639934,"name":"3. Greencroft Annie"},{"status":"ACTIVE","sortPriority":4,"id":69213654,"name":"4. Salacres Crafty"},{"status":"ACTIVE","sortPriority":5,"id":51218587,"name":"5. Golden Bullet"},{"status":"ACTIVE","sortPriority":6,"id":60237218,"name":"6. Arwens Link"}],"regulators":["MR_INT"],"venue":"Towcester","countryCode":"GB","discountAllowed":true,"timezone":"Europe/London","openDate":"2024-06-27T13:33:00.000Z","version":5994767105,"name":"To Be Placed","eventName":"Towcester 27th Jun"},"rc":[{"spl":[[1.71,6]],"id":58821523},{"atb":[[1.01,51.87],[1.07,2.48]],"id":58821523},{"atl":[[75,0.48],[990,0.23]],"id":58821523},{"spn":1.39,"spf":1.0,"id":58821523},{"atb":[[1.02,25.93],[1.07,2.48]],"id":50639934},{"atl":[[75,0.48],[1000,0.23]],"id":50639934},{"spn":38.03,"spf":"NaN","id":50639934},{"atb":[[1.01,51.87],[1.07,2.48]],"id":60237218},{"atl":[[75,0.48],[1000,0.23]],"id":60237218},{"spn":38.03,"spf":"NaN","id":60237218},{"atb":[[1.02,25.93],[1.07,2.48]],"id":51218587},{"atl":[[75,0.48],[990,0.23]],"id":51218587},{"spn":38.03,"spf":"NaN","id":51218587},{"atb":[[1.02,25.93],[1.07,2.48]],"id":69213654},{"atl":[[75,0.48],[990,0.23]],"id":69213654},{"spn":38.03,"spf":"NaN","id":69213654},{"atb":[[1.01,51.87],[1.07,2.48]],"id":66050026},{"atl":[[75,0.48],[1000,0.23]],"id":66050026},{"spn":38.03,"spf":"NaN","id":66050026}],"con":true,"img":true}]}
{"op":"mcm","clk":"11541119684","pt":1719502443154,"mc":[{"id":"1.230180129","rc":[{"atb":[[1.01,51.88],[1.04,1]],"id":58821523},{"atl":[[990,0.23]],"id":58821523},{"atb":[[1.02,25.94],[1.04,1]],"id":50639934},{"atl":[[1000,0.23]],"id":50639934},{"atb":[[1.01,51.88],[1.04,1]],"id":60237218},{"atl":[[1000,0.23]],"id":60237218},{"atb":[[1.02,25.94],[1.04,1]],"id":51218587},{"atl":[[990,0.23]],"id":51218587},{"atb":[[1.02,25.94],[1.04,1]],"id":69213654},{"atl":[[990,0.23]],"id":69213654},{"atb":[[1.01,51.88],[1.04,1]],"id":66050026},{"atl":[[1000,0.23]],"id":66050026}],"con":true,"img":false}]}
{"op":"mcm","clk":"11541119702","pt":1719502443370,"mc":[{"id":"1.230180129","rc":[{"atb":[[1.04,0.25]],"id":58821523},{"atb":[[1.04,0.25]],"id":50639934},{"atb":[[1.04,0.25]],"id":60237218},{"atb":[[1.04,0.25]],"id":51218587},{"atb":[[1.04,0.25]],"id":69213654},{"atb":[[1.04,0.25]],"id":66050026}],"con":true,"img":false}]}
{"op":"mcm","clk":"11541119727","pt":1719502443573,"mc":[{"id":"1.230180129","rc":[{"atb":[[1.04,0]],"id":58821523},{"atb":[[1.04,0]],"id":50639934},{"atb":[[1.04,0]],"id":60237218},{"atb":[[1.04,0]],"id":51218587},{"atb":[[1.04,0]],"id":69213654},{"atb":[[1.04,0]],"id":66050026}],"con":true,"img":false}]}
{"op":"mcm","clk":"11541119739","pt":1719502443679,"mc":[{"id":"1.230180129","rc":[{"atb":[[1.2,0.25]],"id":58821523},{"atb":[[1.2,0.25]],"id":50639934},{"atb":[[1.2,0.25]],"id":60237218},{"atb":[[1.2,0.25]],"id":51218587},{"atb":[[1.2,0.25]],"id":69213654},{"atb":[[1.2,0.25]],"id":66050026}],"con":true,"img":false}]}
{"op":"mcm","clk":"11541122401","pt":1719502479512,"mc":[{"id":"1.230180129","rc":[{"atb":[[1.09,43.92]],"id":50639934},{"atb":[[1.09,43.92]],"id":66050026}],"con":true,"img":false}]}
{"op":"mcm","clk":"11541122415","pt":1719502479719,"mc":[{"id":"1.230180129","rc":[{"atb":[[1.09,43.92]],"id":60237218},{"atb":[[1.09,43.92]],"id":51218587}],"con":true,"img":false}]}
{"op":"mcm","clk":"11541122426","pt":1719502479920,"mc":[{"id":"1.230180129","rc":[{"atb":[[1.09,43.92]],"id":69213654}],"con":true,"img":false}]}
{"op":"mcm","clk":"11541122968","pt":1719502487200,"mc":[{"id":"1.230180129","rc":[{"atb":[[1.1,59.27]],"id":66050026}],"con":true,"img":false}]}
{"op":"mcm","clk":"11541122991","pt":1719502487511,"mc":[{"id":"1.230180129","rc":[{"atb":[[1.1,59.27]],"id":51218587}],"con":true,"img":false}]}
{"op":"mcm","clk":"11541123011","pt":1719502487819,"mc":[{"id":"1.230180129","rc":[{"atb":[[1.1,59.27]],"id":60237218}],"con":true,"img":false}]}
{"op":"mcm","clk":"11541123885","pt":1719502498724,"mc":[{"id":"1.230180129","rc":[{"atb":[[1.11,50.31]],"id":66050026}],"con":true,"img":false}]}
{"op":"mcm","clk":"11541123893","pt":1719502498820,"mc":[{"id":"1.230180129","rc":[{"atb":[[1.11,50.31]],"id":51218587}],"con":true,"img":false}]}
{"op":"mcm","clk":"11541123905","pt":1719502499030,"mc":[{"id":"1.230180129","rc":[{"atb":[[1.11,50.31]],"id":60237218}],"con":true,"img":false}]}
{"op":"mcm","clk":"11541123914","pt":1719502499129,"mc":[{"id":"1.230180129","rc":[{"atb":[[1.09,0]],"id":66050026}],"con":true,"img":false}]}
{"op":"mcm","clk":"11541123942","pt":1719502499547,"mc":[{"id":"1.230180129","rc":[{"atb":[[1.09,0]],"id":60237218}],"con":true,"img":false}]}
{"op":"mcm","clk":"11541123951","pt":1719502499647,"mc":[{"id":"1.230180129","rc":[{"atb":[[1.09,0]],"id":51218587}],"con":true,"img":false}]}
{"op":"mcm","clk":"11541124003","pt":1719502500320,"mc":[{"id":"1.230180129","rc":[{"atb":[[1.12,32.94]],"id":51218587}],"con":true,"img":false}]}
{"op":"mcm","clk":"11541124021","pt":1719502500532,"mc":[{"id":"1.230180129","rc":[{"atb":[[1.12,32.94]],"id":66050026}],"con":true,"img":false}]}
{"op":"mcm","clk":"11541124064","pt":1719502501049,"mc":[{"id":"1.230180129","rc":[{"atb":[[1.12,32.94]],"id":60237218}],"con":true,"img":false}]}
{"op":"mcm","clk":"11541124968","pt":1719502512456,"mc":[{"id":"1.230180129","marketDefinition":{"bspMarket":true,"turnInPlayEnabled":false,"persistenceEnabled":false,"marketBaseRate":5.0,"eventId":"33376437","eventTypeId":"4339","numberOfWinners":2,"bettingType":"ODDS","marketType":"PLACE","marketTime":"2024-06-27T16:03:00.000Z","suspendTime":"2024-06-27T16:03:00.000Z","bspReconciled":false,"complete":true,"inPlay":false,"crossMatching":true,"runnersVoidable":false,"numberOfActiveRunners":6,"betDelay":0,"status":"OPEN","runners":[{"status":"ACTIVE","sortPriority":1,"id":66050026,"name":"1. Salacres Elunico"},{"status":"ACTIVE","sortPriority":2,"id":58821523,"name":"2. Makeit Missy"},{"status":"ACTIVE","sortPriority":3,"id":50639934,"name":"3. Greencroft Annie"},{"status":"ACTIVE","sortPriority":4,"id":69213654,"name":"4. Salacres Crafty"},{"status":"ACTIVE","sortPriority":5,"id":51218587,"name":"5. Golden Bullet"},{"status":"ACTIVE","sortPriority":6,"id":60237218,"name":"6. Arwens Link"}],"regulators":["MR_INT"],"venue":"Towcester","countryCode":"GB","discountAllowed":true,"timezone":"Europe/London","openDate":"2024-06-27T13:33:00.000Z","version":5994767105,"name":"To Be Placed","eventName":"Towcester 27th Jun"},"rc":[],"con":true,"img":false}]}
{"op":"mcm","clk":"11541125458","pt":1719502519264,"mc":[{"id":"1.230180129","rc":[{"spn":1.45,"spf":1.0,"id":58821523},{"spn":38.1,"spf":"NaN","id":50639934},{"spn":38.1,"spf":"NaN","id":60237218},{"atb":[[1.1,0]],"id":51218587},{"spn":38.1,"spf":"NaN","id":51218587},{"spn":38.1,"spf":"NaN","id":69213654},{"atb":[[1.1,0]],"id":66050026},{"spn":38.1,"spf":"NaN","id":66050026}],"con":true,"img":false}]}
{"op":"mcm","clk":"11541125485","pt":1719502519654,"mc":[{"id":"1.230180129","rc":[{"atb":[[1.1,0]],"id":60237218}],"con":true,"img":false}]}
{"op":"mcm","clk":"11541125552","pt":1719502520528,"mc":[{"id":"1.230180129","rc":[{"atb":[[1.13,45.59]],"id":66050026}],"con":true,"img":false}]}
{"op":"mcm","clk":"11541125572","pt":1719502520838,"mc":[{"id":"1.230180129","rc":[{"atb":[[1.13,45.59]],"id":51218587}],"con":true,"img":false}]}
{"op":"mcm","clk":"11541125577","pt":1719502520941,"mc":[{"id":"1.230180129","rc":[{"atb":[[1.13,45.59]],"id":60237218}],"con":true,"img":false}]}
{"op":"mcm","clk":"11541126599","pt":1719502534678,"mc":[{"id":"1.230180129","rc":[{"atb":[[1.11,0]],"id":51218587},{"atb":[[1.11,0]],"id":66050026}],"con":true,"img":false}]}
{"op":"mcm","clk":"11541126613","pt":1719502534884,"mc":[{"id":"1.230180129","rc":[{"atb":[[1.12,0]],"id":66050026}],"con":true,"img":false}]}
{"op":"mcm","clk":"11541126630","pt":1719502535144,"mc":[{"id":"1.230180129","rc":[{"atb":[[1.11,0]],"id":60237218}],"con":true,"img":false}]}
{"op":"mcm","clk":"11541126643","pt":1719502535350,"mc":[{"id":"1.230180129","rc":[{"atb":[[1.12,0]],"id":60237218},{"atb":[[1.12,0]],"id":51218587}],"con":true,"img":false}]}
{"op":"mcm","clk":"11541126674","pt":1719502535768,"mc":[{"id":"1.230180129","rc":[{"atb":[[1.14,39.52]],"id":51218587}],"con":true,"img":false}]}
{"op":"mcm","clk":"11541126691","pt":1719502535973,"mc":[{"id":"1.230180129","rc":[{"atb":[[1.14,39.52]],"id":66050026}],"con":true,"img":false}]}
{"op":"mcm","clk":"11541126725","pt":1719502536386,"mc":[{"id":"1.230180129","rc":[{"atb":[[1.14,39.52]],"id":60237218},{"atb":[[1.15,26.34]],"id":51218587}],"con":true,"img":false}]}
{"op":"mcm","clk":"11541126753","pt":1719502536850,"mc":[{"id":"1.230180129","rc":[{"atb":[[1.15,26.34]],"id":60237218},{"atb":[[1.15,26.34]],"id":66050026}],"con":true,"img":false}]}
{"op":"mcm","clk":"11541127620","pt":1719502550776,"mc":[{"id":"1.230180129","rc":[{"atb":[[1.13,0]],"id":51218587},{"atb":[[1.13,0]],"id":66050026}],"con":true,"img":false}]}
{"op":"mcm","clk":"11541127634","pt":1719502551077,"mc":[{"id":"1.230180129","rc":[{"atb":[[1.13,0]],"id":60237218}],"con":true,"img":false}]}
{"op":"mcm","clk":"11541127704","pt":1719502552066,"mc":[{"id":"1.230180129","rc":[{"atb":[[1.16,37.04]],"id":66050026}],"con":true,"img":false}]}
{"op":"mcm","clk":"11541127725","pt":1719502552372,"mc":[{"id":"1.230180129","rc":[{"atb":[[1.16,37.04]],"id":60237218},{"atb":[[1.16,37.04]],"id":51218587}],"con":true,"img":false}]}
{"op":"mcm","clk":"11541127798","pt":1719502553303,"mc":[{"id":"1.230180129","rc":[{"atb":[[1.14,0]],"id":51218587}],"con":true,"img":false}]}
{"op":"mcm","clk":"11541127806","pt":1719502553407,"mc":[{"id":"1.230180129","rc":[{"atb":[[1.15,0]],"id":51218587}],"con":true,"img":false}]}
{"op":"mcm","clk":"11541127812","pt":1719502553462,"mc":[{"id":"1.230180129","rc":[{"atb":[[1.15,0]],"id":60237218}],"con":true,"img":false}]}
{"op":"mcm","clk":"11541127831","pt":1719502553769,"mc":[{"id":"1.230180129","rc":[{"atb":[[1.14,0]],"id":66050026}],"con":true,"img":false}]}
{"op":"mcm","clk":"11541127851","pt":1719502553976,"mc":[{"id":"1.230180129","rc":[{"atb":[[1.14,0]],"id":60237218}],"con":true,"img":false}]}
{"op":"mcm","clk":"11541127866","pt":1719502554183,"mc":[{"id":"1.230180129","rc":[{"atb":[[1.17,32.55]],"id":51218587}],"con":true,"img":false}]}
{"op":"mcm","clk":"11541127888","pt":1719502554491,"mc":[{"id":"1.230180129","rc":[{"atb":[[1.18,21.96]],"id":51218587}],"con":true,"img":false}]}
{"op":"mcm","clk":"11541127902","pt":1719502554698,"mc":[{"id":"1.230180129","rc":[{"atb":[[1.15,0]],"id":66050026}],"con":true,"img":false}]}
{"op":"mcm","clk":"11541127921","pt":1719502554909,"mc":[{"id":"1.230180129","rc":[{"atb":[[1.18,21.96]],"id":60237218}],"con":true,"img":false}]}
{"op":"mcm","clk":"11541127937","pt":1719502555060,"mc":[{"id":"1.230180129","rc":[{"atb":[[1.17,32.55]],"id":60237218},{"atb":[[1.17,32.55]],"id":66050026}],"con":true,"img":false}]}
{"op":"mcm","clk":"11541127962","pt":1719502555472,"mc":[{"id":"1.230180129","rc":[{"atb":[[1.18,21.96]],"id":66050026}],"con":true,"img":false}]}
{"op":"mcm","clk":"11541130197","pt":1719502582796,"mc":[{"id":"1.230180129","rc":[{"atb":[[1.16,0]],"id":51218587},{"atb":[[1.16,0]],"id":66050026}],"con":true,"img":false}]}
{"op":"mcm","clk":"11541130255","pt":1719502583412,"mc":[{"id":"1.230180129","rc":[{"atb":[[1.16,0]],"id":60237218}],"con":true,"img":false}]}
{"op":"mcm","clk":"11541130293","pt":1719502583986,"mc":[{"id":"1.230180129","rc":[{"atb":[[1.19,31.19]],"id":66050026}],"con":true,"img":false}]}
{"op":"mcm","clk":"11541130303","pt":1719502584192,"mc":[{"id":"1.230180129","rc":[{"atb":[[1.19,31.19]],"id":51218587}],"con":true,"img":false}]}
{"op":"mcm","clk":"11541130342","pt":1719502584808,"mc":[{"id":"1.230180129","rc":[{"atb":[[1.19,31.19]],"id":60237218}],"con":true,"img":false}]}
{"op":"mcm","clk":"11541130629","pt":1719502588327,"mc":[{"id":"1.230180129","rc":[{"atb":[[1.17,0]],"id":51218587},{"atb":[[1.17,0]],"id":66050026}],"con":true,"img":false}]}
{"op":"mcm","clk":"11541130646","pt":1719502588631,"mc":[{"id":"1.230180129","rc":[{"atb":[[1.17,0]],"id":60237218},{"atb":[[1.18,0]],"id":51218587}],"con":true,"img":false}]}
{"op":"mcm","clk":"11541130657","pt":1719502588844,"mc":[{"id":"1.230180129","rc":[{"atb":[[1.18,0]],"id":66050026}],"con":true,"img":false}]}
{"op":"mcm","clk":"11541130675","pt":1719502589102,"mc":[{"id":"1.230180129","rc":[{"atb":[[1.18,0]],"id":60237218}],"con":true,"img":false}]}
{"op":"mcm","clk":"11541130721","pt":1719502589616,"mc":[{"id":"1.230180129","rc":[{"atb":[[1.2,27.92]],"id":66050026}],"con":true,"img":false}]}
{"op":"mcm","clk":"11541130740","pt":1719502589822,"mc":[{"id":"1.230180129","rc":[{"atb":[[1.2,27.92],[1.21,18.82]],"id":51218587}],"con":true,"img":false}]}
{"op":"mcm","clk":"11541130755","pt":1719502590028,"mc":[{"id":"1.230180129","rc":[{"atb":[[1.2,27.92]],"id":60237218}],"con":true,"img":false}]}
{"op":"mcm","clk":"11541130769","pt":1719502590241,"mc":[{"id":"1.230180129","rc":[{"atb":[[1.21,18.82]],"id":60237218}],"con":true,"img":false}]}
{"op":"mcm","clk":"11541130789","pt":1719502590392,"mc":[{"id":"1.230180129","rc":[{"atb":[[1.21,18.82]],"id":66050026}],"con":true,"img":false}]}
{"op":"mcm","clk":"11541132706","pt":1719502616307,"mc":[{"id":"1.230180129","rc":[{"atb":[[1.19,0]],"id":51218587},{"atb":[[1.19,0]],"id":66050026}],"con":true,"img":false}]}
{"op":"mcm","clk":"11541132732","pt":1719502616615,"mc":[{"id":"1.230180129","rc":[{"atb":[[1.19,0]],"id":60237218}],"con":true,"img":false}]}
{"op":"mcm","clk":"11541132757","pt":1719502616923,"mc":[{"id":"1.230180129","rc":[{"atb":[[1.22,26.94]],"id":51218587},{"atb":[[1.22,26.94]],"id":66050026}],"con":true,"img":false}]}
{"op":"mcm","clk":"11541132804","pt":1719502617540,"mc":[{"id":"1.230180129","rc":[{"atb":[[1.22,26.94]],"id":60237218}],"con":true,"img":false}]}
{"op":"mcm","clk":"11541133376","pt":1719502625358,"mc":[{"id":"1.230180129","rc":[{"atb":[[1.2,0.25]],"id":51218587},{"atb":[[1.2,0.25]],"id":66050026}],"con":true,"img":false}]}
{"op":"mcm","clk":"11541133420","pt":1719502625935,"mc":[{"id":"1.230180129","rc":[{"atb":[[1.2,0.25]],"id":60237218},{"atb":[[1.21,0]],"id":66050026}],"con":true,"img":false}]}
{"op":"mcm","clk":"11541133460","pt":1719502626353,"mc":[{"id":"1.230180129","rc":[{"atb":[[1.23,24.05],[1.24,16.46]],"id":66050026}],"con":true,"img":false}]}
{"op":"mcm","clk":"11541133478","pt":1719502626515,"mc":[{"id":"1.230180129","rc":[{"atb":[[1.21,0]],"id":51218587}],"con":true,"img":false}]}
{"op":"mcm","clk":"11541133497","pt":1719502626721,"mc":[{"id":"1.230180129","rc":[{"atb":[[1.21,0]],"id":60237218},{"atb":[[1.23,24.05]],"id":51218587}],"con":true,"img":false}]}
{"op":"mcm","clk":"11541133517","pt":1719502626929,"mc":[{"id":"1.230180129","rc":[{"atb":[[1.23,24.05]],"id":60237218}],"con":true,"img":false}]}
{"op":"mcm","clk":"11541133536","pt":1719502627137,"mc":[{"id":"1.230180129","rc":[{"atb":[[1.24,16.46]],"id":51218587}],"con":true,"img":false}]}
{"op":"mcm","clk":"11541133570","pt":1719502627655,"mc":[{"id":"1.230180129","rc":[{"atb":[[1.24,16.46]],"id":60237218}],"con":true,"img":false}]}
{"op":"mcm","clk":"11541133665","pt":1719502629152,"mc":[{"id":"1.230180129","rc":[{"atb":[[1.15,41.18]],"id":51218587}],"con":true,"img":false}]}
{"op":"mcm","clk":"11541134684","pt":1719502643053,"mc":[{"id":"1.230180129","rc":[{"spn":38.12,"spf":"NaN","id":60237218},{"atb":[[1.15,0]],"id":51218587},{"spn":38.12,"spf":"NaN","id":51218587},{"spn":38.12,"spf":"NaN","id":66050026}],"con":true,"img":false}]}
{"op":"mcm","clk":"11541135064","pt":1719502647959,"mc":[{"id":"1.230180129","rc":[{"atb":[[1.22,0]],"id":51218587}],"con":true,"img":false}]}
{"op":"mcm","clk":"11541135078","pt":1719502648156,"mc":[{"id":"1.230180129","rc":[{"atb":[[1.22,0]],"id":60237218}],"con":true,"img":false}]}
{"op":"mcm","clk":"11541135137","pt":1719502648875,"mc":[{"id":"1.230180129","rc":[{"atb":[[1.22,0]],"id":66050026}],"con":true,"img":false}]}
{"op":"mcm","clk":"11541135167","pt":1719502649444,"mc":[{"id":"1.230180129","rc":[{"atb":[[1.25,23.7]],"id":51218587}],"con":true,"img":false}]}
{"op":"mcm","clk":"11541135217","pt":1719502650164,"mc":[{"id":"1.230180129","rc":[{"atb":[[1.25,23.7]],"id":60237218},{"atb":[[1.25,23.7]],"id":66050026}],"con":true,"img":false}]}
{"op":"mcm","clk":"11541136007","pt":1719502661277,"mc":[{"id":"1.230180129","rc":[{"atb":[[1.23,0]],"id":51218587},{"atb":[[1.23,0]],"id":66050026}],"con":true,"img":false}]}
{"op":"mcm","clk":"11541136022","pt":1719502661476,"mc":[{"id":"1.230180129","rc":[{"atb":[[1.23,0]],"id":60237218}],"con":true,"img":false}]}
{"op":"mcm","clk":"11541136035","pt":1719502661680,"mc":[{"id":"1.230180129","rc":[{"atb":[[1.27,20.49]],"id":66050026}],"con":true,"img":false}]}
{"op":"mcm","clk":"11541136048","pt":1719502661886,"mc":[{"id":"1.230180129","rc":[{"atb":[[1.24,0]],"id":66050026}],"con":true,"img":false}]}
{"op":"mcm","clk":"11541136062","pt":1719502662102,"mc":[{"id":"1.230180129","rc":[{"atb":[[1.27,20.49],[1.24,0]],"id":60237218}],"con":true,"img":false}]}
{"op":"mcm","clk":"11541136075","pt":1719502662253,"mc":[{"id":"1.230180129","rc":[{"atb":[[1.27,20.49]],"id":51218587}],"con":true,"img":false}]}
{"op":"mcm","clk":"11541136087","pt":1719502662457,"mc":[{"id":"1.230180129","rc":[{"atb":[[1.24,0]],"id":51218587}],"con":true,"img":false}]}
{"op":"mcm","clk":"11541136103","pt":1719502662769,"mc":[{"id":"1.230180129","rc":[{"atb":[[1.27,35.14]],"id":60237218},{"atb":[[1.27,35.14]],"id":66050026}],"con":true,"img":false}]}
{"op":"mcm","clk":"11541136113","pt":1719502662974,"mc":[{"id":"1.230180129","rc":[{"atb":[[1.27,35.14]],"id":51218587}],"con":true,"img":false}]}
{"op":"mcm","clk":"11541137577","pt":1719502681883,"mc":[{"id":"1.230180129","rc":[{"atb":[[1.25,0]],"id":66050026}],"con":true,"img":false}]}
{"op":"mcm","clk":"11541137603","pt":1719502682207,"mc":[{"id":"1.230180129","rc":[{"atb":[[1.25,0]],"id":60237218}],"con":true,"img":false}]}
{"op":"mcm","clk":"11541143274","pt":1719502682884,"mc":[{"id":"1.230180129","rc":[{"atb":[[1.25,0]],"id":51218587}],"con":true,"img":false}]}
{"op":"mcm","clk":"11541143345","pt":1719502683610,"mc":[{"id":"1.230180129","rc":[{"atb":[[1.29,20.44]],"id":60237218}],"con":true,"img":false}]}
{"op":"mcm","clk":"11541143355","pt":1719502683689,"mc":[{"id":"1.230180129","rc":[{"atb":[[1.29,20.44]],"id":66050026}],"con":true,"img":false}]}
{"op":"mcm","clk":"11541143425","pt":1719502684505,"mc":[{"id":"1.230180129","rc":[{"atb":[[1.29,20.44]],"id":51218587}],"con":true,"img":false}]}
{"op":"mcm","clk":"11541144536","pt":1719502698493,"mc":[{"id":"1.230180129","rc":[{"atb":[[1.27,14.64]],"id":51218587},{"atb":[[1.27,14.64]],"id":66050026}],"con":true,"img":false}]}
{"op":"mcm","clk":"11541144545","pt":1719502698697,"mc":[{"id":"1.230180129","rc":[{"atb":[[1.31,17.85]],"id":51218587}],"con":true,"img":false}]}
{"op":"mcm","clk":"11541144553","pt":1719502698806,"mc":[{"id":"1.230180129","rc":[{"atb":[[1.27,0]],"id":51218587}],"con":true,"img":false}]}
{"op":"mcm","clk":"11541144562","pt":1719502698911,"mc":[{"id":"1.230180129","rc":[{"atb":[[1.27,14.64]],"id":60237218}],"con":true,"img":false}]}
{"op":"mcm","clk":"11541144581","pt":1719502699122,"mc":[{"id":"1.230180129","rc":[{"atb":[[1.27,0]],"id":66050026}],"con":true,"img":false}]}
{"op":"mcm","clk":"11541144598","pt":1719502699323,"mc":[{"id":"1.230180129","rc":[{"atb":[[1.31,17.85]],"id":60237218},{"atb":[[1.31,17.85]],"id":66050026}],"con":true,"img":false}]}
{"op":"mcm","clk":"11541144614","pt":1719502699531,"mc":[{"id":"1.230180129","rc":[{"atb":[[1.27,0]],"id":60237218},{"atb":[[1.31,30.6]],"id":51218587}],"con":true,"img":false}]}
{"op":"mcm","clk":"11541144644","pt":1719502699896,"mc":[{"id":"1.230180129","rc":[{"atb":[[1.31,30.6]],"id":66050026}],"con":true,"img":false}]}
{"op":"mcm","clk":"11541144662","pt":1719502700105,"mc":[{"id":"1.230180129","rc":[{"atb":[[1.31,30.6]],"id":60237218}],"con":true,"img":false}]}
{"op":"mcm","clk":"11541145905","pt":1719502714931,"mc":[{"id":"1.230180129","rc":[{"spn":38.15,"spf":"NaN","id":60237218},{"spn":38.15,"spf":"NaN","id":51218587},{"atb":[[1.29,0]],"id":66050026},{"spn":38.15,"spf":"NaN","id":66050026}],"con":true,"img":false}]}
{"op":"mcm","clk":"11541145965","pt":1719502715508,"mc":[{"id":"1.230180129","rc":[{"atb":[[1.11,38.48]],"id":50639934}],"con":true,"img":false}]}
{"op":"mcm","clk":"11541145985","pt":1719502715712,"mc":[{"id":"1.230180129","rc":[{"atb":[[1.29,0]],"id":51218587}],"con":true,"img":false}]}
{"op":"mcm","clk":"11541145996","pt":1719502715812,"mc":[{"id":"1.230180129","rc":[{"atb":[[1.29,0]],"id":60237218}],"con":true,"img":false}]}
{"op":"mcm","clk":"11541146017","pt":1719502716035,"mc":[{"id":"1.230180129","rc":[{"atb":[[1.09,0]],"id":50639934},{"atb":[[1.33,12.82]],"id":66050026}],"con":true,"img":false}]}
{"op":"mcm","clk":"11541146024","pt":1719502716123,"mc":[{"id":"1.230180129","rc":[{"atb":[[1.33,12.82]],"id":51218587}],"con":true,"img":false}]}
{"op":"mcm","clk":"11541146046","pt":1719502716330,"mc":[{"id":"1.230180129","rc":[{"atb":[[1.33,12.82]],"id":60237218}],"con":true,"img":false}]}
{"op":"mcm","clk":"11541146053","pt":1719502716434,"mc":[{"id":"1.230180129","rc":[{"atb":[[1.13,30.4]],"id":50639934}],"con":true,"img":false}]}
{"op":"mcm","clk":"11541146071","pt":1719502716638,"mc":[{"id":"1.230180129","rc":[{"atb":[[1.11,38.48]],"id":69213654}],"con":true,"img":false}]}
{"op":"mcm","clk":"11541146138","pt":1719502717418,"mc":[{"id":"1.230180129","rc":[{"atb":[[1.33,30.78]],"id":51218587}],"con":true,"img":false}]}
{"op":"mcm","clk":"11541146181","pt":1719502717945,"mc":[{"id":"1.230180129","rc":[{"atb":[[1.33,30.78]],"id":60237218},{"atb":[[1.33,30.78]],"id":66050026}],"con":true,"img":false}]}
{"op":"mcm","clk":"11541147528","pt":1719502734551,"mc":[{"id":"1.230180129","rc":[{"atb":[[1.31,12.75]],"id":51218587},{"atb":[[1.31,12.75]],"id":66050026}],"con":true,"img":false}]}
{"op":"mcm","clk":"11541147547","pt":1719502734752,"mc":[{"id":"1.230180129","rc":[{"atb":[[1.31,12.75]],"id":60237218},{"atb":[[1.31,0]],"id":66050026}],"con":true,"img":false}]}
{"op":"mcm","clk":"11541147578","pt":1719502735125,"mc":[{"id":"1.230180129","rc":[{"atb":[[1.35,15.81]],"id":51218587}],"con":true,"img":false}]}
{"op":"mcm","clk":"11541147595","pt":1719502735332,"mc":[{"id":"1.230180129","rc":[{"atb":[[1.09,0]],"id":69213654}],"con":true,"img":false}]}
{"op":"mcm","clk":"11541147609","pt":1719502735528,"mc":[{"id":"1.230180129","rc":[{"atb":[[1.35,15.81]],"id":66050026}],"con":true,"img":false}]}
{"op":"mcm","clk":"11541147628","pt":1719502735736,"mc":[{"id":"1.230180129","rc":[{"atb":[[1.35,15.81]],"id":60237218}],"con":true,"img":false}]}
{"op":"mcm","clk":"11541147638","pt":1719502735845,"mc":[{"id":"1.230180129","rc":[{"atb":[[1.35,27.1]],"id":66050026}],"con":true,"img":false}]}
{"op":"mcm","clk":"11541147648","pt":1719502735944,"mc":[{"id":"1.230180129","rc":[{"atb":[[1.31,0]],"id":60237218}],"con":true,"img":false}]}
{"op":"mcm","clk":"11541147706","pt":1719502736584,"mc":[{"id":"1.230180129","rc":[{"atb":[[1.35,27.1]],"id":60237218},{"atb":[[1.13,30.4]],"id":69213654}],"con":true,"img":false}]}
{"op":"mcm","clk":"11541148831","pt":1719502749030,"mc":[{"id":"1.230180129","rc":[{"atb":[[1.33,12.82]],"id":51218587}],"con":true,"img":false}]}
{"op":"mcm","clk":"11541148842","pt":1719502749136,"mc":[{"id":"1.230180129","rc":[{"atb":[[1.33,12.82]],"id":66050026}],"con":true,"img":false}]}
{"op":"mcm","clk":"11541148862","pt":1719502749344,"mc":[{"id":"1.230180129","rc":[{"atb":[[1.11,0]],"id":69213654}],"con":true,"img":false}]}
{"op":"mcm","clk":"11541148873","pt":1719502749449,"mc":[{"id":"1.230180129","rc":[{"atb":[[1.33,12.82]],"id":60237218}],"con":true,"img":false}]}
{"op":"mcm","clk":"11541148907","pt":1719502749759,"mc":[{"id":"1.230180129","rc":[{"atb":[[1.11,0]],"id":50639934}],"con":true,"img":false}]}
{"op":"mcm","clk":"11541148940","pt":1719502750037,"mc":[{"id":"1.230180129","rc":[{"atb":[[1.37,16.02]],"id":51218587},{"atb":[[1.33,0]],"id":66050026}],"con":true,"img":false}]}
{"op":"mcm","clk":"11541149010","pt":1719502750657,"mc":[{"id":"1.230180129","rc":[{"atb":[[1.33,0]],"id":60237218}],"con":true,"img":false}]}
{"op":"mcm","clk":"11541149068","pt":1719502751168,"mc":[{"id":"1.230180129","rc":[{"atb":[[1.15,28.22]],"id":69213654}],"con":true,"img":false}]}
{"op":"mcm","clk":"11541149076","pt":1719502751278,"mc":[{"id":"1.230180129","rc":[{"atb":[[1.37,16.02]],"id":60237218}],"con":true,"img":false}]}
{"op":"mcm","clk":"11541149127","pt":1719502751697,"mc":[{"id":"1.230180129","rc":[{"atb":[[1.37,16.02]],"id":66050026}],"con":true,"img":false}]}
{"op":"mcm","clk":"11541149156","pt":1719502751949,"mc":[{"id":"1.230180129","rc":[{"atb":[[1.37,27.45]],"id":66050026}],"con":true,"img":false}]}
{"op":"mcm","clk":"11541149178","pt":1719502752262,"mc":[{"id":"1.230180129","rc":[{"atb":[[1.15,28.22]],"id":50639934},{"atb":[[1.37,27.45]],"id":60237218}],"con":true,"img":false}]}
{"op":"mcm","clk":"11541149313","pt":1719502753770,"mc":[{"id":"1.230180129","rc":[{"atb":[[1.35,11.29]],"id":60237218},{"atb":[[1.35,11.29]],"id":66050026}],"con":true,"img":false}]}
{"op":"mcm","clk":"11541149330","pt":1719502753978,"mc":[{"id":"1.230180129","rc":[{"atb":[[1.35,0]],"id":66050026}],"con":true,"img":false}]}
{"op":"mcm","clk":"11541149339","pt":1719502754035,"mc":[{"id":"1.230180129","rc":[{"atb":[[1.13,0]],"id":50639934}],"con":true,"img":false}]}
{"op":"mcm","clk":"11541149361","pt":1719502754247,"mc":[{"id":"1.230180129","rc":[{"atb":[[1.35,0]],"id":60237218}],"con":true,"img":false}]}
{"op":"mcm","clk":"11541149386","pt":1719502754464,"mc":[{"id":"1.230180129","rc":[{"atb":[[1.13,0]],"id":69213654}],"con":true,"img":false}]}
{"op":"mcm","clk":"11541149418","pt":1719502754862,"mc":[{"id":"1.230180129","rc":[{"atb":[[1.17,23.25]],"id":50639934},{"atb":[[1.39,10.13]],"id":66050026}],"con":true,"img":false}]}
{"op":"mcm","clk":"11541149461","pt":1719502755286,"mc":[{"id":"1.230180129","rc":[{"atb":[[1.39,24.32]],"id":66050026}],"con":true,"img":false}]}
{"op":"mcm","clk":"11541149477","pt":1719502755433,"mc":[{"id":"1.230180129","rc":[{"atb":[[1.39,10.13]],"id":60237218}],"con":true,"img":false}]}
{"op":"mcm","clk":"11541149492","pt":1719502755637,"mc":[{"id":"1.230180129","rc":[{"atb":[[1.39,24.32]],"id":60237218}],"con":true,"img":false}]}
{"op":"mcm","clk":"11541149541","pt":1719502756166,"mc":[{"id":"1.230180129","rc":[{"atb":[[1.17,23.25]],"id":69213654}],"con":true,"img":false}]}
{"op":"mcm","clk":"11541150382","pt":1719502764390,"mc":[{"id":"1.230180129","rc":[{"atb":[[1.26,2]],"id":60237218}],"con":true,"img":false}]}
{"op":"mcm","clk":"11541151022","pt":1719502770873,"mc":[{"id":"1.230180129","rc":[{"atb":[[1.26,0]],"id":60237218}],"con":true,"img":false}]}
{"op":"mcm","clk":"11541152284","pt":1719502785580,"mc":[{"id":"1.230180129","rc":[{"atb":[[1.15,0]],"id":50639934},{"spn":38.19,"spf":"NaN","id":60237218},{"spn":38.18,"spf":"NaN","id":51218587},{"spn":38.19,"spf":"NaN","id":66050026}],"con":true,"img":false}]}
{"op":"mcm","clk":"11541152297","pt":1719502785748,"mc":[{"id":"1.230180129","rc":[{"atb":[[1.37,11.43]],"id":66050026}],"con":true,"img":false}]}
{"op":"mcm","clk":"11541152322","pt":1719502785997,"mc":[{"id":"1.230180129","rc":[{"atb":[[1.37,16.02]],"id":60237218}],"con":true,"img":false}]}
{"op":"mcm","clk":"11541152332","pt":1719502786100,"mc":[{"id":"1.230180129","rc":[{"atb":[[1.37,0]],"id":66050026}],"con":true,"img":false}]}
{"op":"mcm","clk":"11541152363","pt":1719502786418,"mc":[{"id":"1.230180129","rc":[{"atb":[[1.37,0]],"id":60237218}],"con":true,"img":false}]}
{"op":"mcm","clk":"11541152395","pt":1719502786676,"mc":[{"id":"1.230180129","rc":[{"atb":[[1.15,0]],"id":69213654}],"con":true,"img":false}]}
{"op":"mcm","clk":"11541152458","pt":1719502787312,"mc":[{"id":"1.230180129","rc":[{"atb":[[1.19,22.28]],"id":50639934}],"con":true,"img":false}]}
{"op":"mcm","clk":"11541152492","pt":1719502787607,"mc":[{"id":"1.230180129","rc":[{"atb":[[1.41,10.33]],"id":66050026}],"con":true,"img":false}]}
{"op":"mcm","clk":"11541152516","pt":1719502787816,"mc":[{"id":"1.230180129","rc":[{"atb":[[1.41,10.33]],"id":60237218}],"con":true,"img":false}]}
{"op":"mcm","clk":"11541152555","pt":1719502788181,"mc":[{"id":"1.230180129","rc":[{"atb":[[1.41,24.78]],"id":66050026}],"con":true,"img":false}]}
{"op":"mcm","clk":"11541152578","pt":1719502788496,"mc":[{"id":"1.230180129","rc":[{"atb":[[1.19,22.28]],"id":69213654}],"con":true,"img":false}]}
{"op":"mcm","clk":"11541152588","pt":1719502788598,"mc":[{"id":"1.230180129","rc":[{"atb":[[1.41,24.78]],"id":60237218}],"con":true,"img":false}]}
{"op":"mcm","clk":"11541152827","pt":1719502791095,"mc":[{"id":"1.230180129","rc":[{"atb":[[1.17,0]],"id":69213654}],"con":true,"img":false}]}
{"op":"mcm","clk":"11541152852","pt":1719502791307,"mc":[{"id":"1.230180129","rc":[{"atb":[[1.39,10.13]],"id":66050026}],"con":true,"img":false}]}
{"op":"mcm","clk":"11541152890","pt":1719502791721,"mc":[{"id":"1.230180129","rc":[{"atb":[[1.39,10.13]],"id":60237218}],"con":true,"img":false}]}
{"op":"mcm","clk":"11541152898","pt":1719502791775,"mc":[{"id":"1.230180129","rc":[{"atb":[[1.17,0]],"id":50639934}],"con":true,"img":false}]}
{"op":"mcm","clk":"11541152917","pt":1719502791982,"mc":[{"id":"1.230180129","rc":[{"atb":[[1.43,12.87]],"id":66050026}],"con":true,"img":false}]}
{"op":"mcm","clk":"11541152925","pt":1719502792088,"mc":[{"id":"1.230180129","rc":[{"atb":[[1.21,18.82]],"id":69213654}],"con":true,"img":false}]}
{"op":"mcm","clk":"11541152940","pt":1719502792296,"mc":[{"id":"1.230180129","rc":[{"atb":[[1.39,0]],"id":60237218}],"con":true,"img":false}]}
{"op":"mcm","clk":"11541152981","pt":1719502792712,"mc":[{"id":"1.230180129","rc":[{"atb":[[1.21,18.82]],"id":50639934},{"atb":[[1.43,12.87]],"id":60237218}],"con":true,"img":false}]}
{"op":"mcm","clk":"11541153001","pt":1719502792874,"mc":[{"id":"1.230180129","rc":[{"atb":[[1.39,0]],"id":66050026}],"con":true,"img":false}]}
{"op":"mcm","clk":"11541153017","pt":1719502793081,"mc":[{"id":"1.230180129","rc":[{"atb":[[1.43,22.06]],"id":60237218},{"atb":[[1.43,22.06]],"id":66050026}],"con":true,"img":false}]}
{"op":"mcm","clk":"11541155464","pt":1719502817314,"mc":[{"id":"1.230180129","rc":[{"atb":[[1.33,0]],"id":51218587}],"con":true,"img":false}]}
{"op":"mcm","clk":"11541155757","pt":1719502820113,"mc":[{"id":"1.230180129","rc":[{"atb":[[1.41,0]],"id":66050026}],"con":true,"img":false}]}
{"op":"mcm","clk":"11541155792","pt":1719502820428,"mc":[{"id":"1.230180129","rc":[{"atb":[[1.19,0]],"id":50639934},{"atb":[[1.19,0]],"id":69213654}],"con":true,"img":false}]}
{"op":"mcm","clk":"11541155817","pt":1719502820730,"mc":[{"id":"1.230180129","rc":[{"atb":[[1.41,14.45]],"id":60237218}],"con":true,"img":false}]}
{"op":"mcm","clk":"11541155889","pt":1719502821301,"mc":[{"id":"1.230180129","rc":[{"atb":[[1.45,9.4]],"id":60237218},{"atb":[[1.23,18.4]],"id":69213654}],"con":true,"img":false}]}
{"op":"mcm","clk":"11541155928","pt":1719502821622,"mc":[{"id":"1.230180129","rc":[{"atb":[[1.23,18.4]],"id":50639934}],"con":true,"img":false}]}
{"op":"mcm","clk":"11541155941","pt":1719502821715,"mc":[{"id":"1.230180129","rc":[{"atb":[[1.41,0]],"id":60237218}],"con":true,"img":false}]}
{"op":"mcm","clk":"11541155990","pt":1719502822232,"mc":[{"id":"1.230180129","rc":[{"atb":[[1.45,9.4]],"id":66050026}],"con":true,"img":false}]}
{"op":"mcm","clk":"11541156018","pt":1719502822544,"mc":[{"id":"1.230180129","rc":[{"atb":[[1.46,12.88]],"id":66050026}],"con":true,"img":false}]}
{"op":"mcm","clk":"11541156047","pt":1719502822811,"mc":[{"id":"1.230180129","rc":[{"atb":[[1.46,12.88]],"id":60237218}],"con":true,"img":false}]}
{"op":"mcm","clk":"11541156405","pt":1719502827431,"mc":[{"id":"1.230180129","rc":[{"atb":[[1.31,0]],"id":51218587}],"con":true,"img":false}]}
{"op":"mcm","clk":"11541156586","pt":1719502829755,"mc":[{"id":"1.230180129","rc":[{"atb":[[1.43,12.87]],"id":60237218}],"con":true,"img":false}]}
{"op":"mcm","clk":"11541156601","pt":1719502829913,"mc":[{"id":"1.230180129","rc":[{"atb":[[1.43,0]],"id":66050026}],"con":true,"img":false}]}
{"op":"mcm","clk":"11541156616","pt":1719502830118,"mc":[{"id":"1.230180129","rc":[{"atb":[[1.21,0]],"id":50639934}],"con":true,"img":false}]}
{"op":"mcm","clk":"11541156632","pt":1719502830326,"mc":[{"id":"1.230180129","rc":[{"atb":[[1.48,8.23]],"id":60237218},{"atb":[[1.21,0]],"id":69213654}],"con":true,"img":false}]}
{"op":"mcm","clk":"11541156653","pt":1719502830551,"mc":[{"id":"1.230180129","rc":[{"atb":[[1.43,0]],"id":60237218}],"con":true,"img":false}]}
{"op":"mcm","clk":"11541156697","pt":1719502831159,"mc":[{"id":"1.230180129","rc":[{"atb":[[1.25,15.81]],"id":50639934}],"con":true,"img":false}]}
{"op":"mcm","clk":"11541156709","pt":1719502831275,"mc":[{"id":"1.230180129","rc":[{"atb":[[1.49,11.29]],"id":66050026}],"con":true,"img":false}]}
{"op":"mcm","clk":"11541156731","pt":1719502831533,"mc":[{"id":"1.230180129","rc":[{"atb":[[1.25,15.81]],"id":69213654}],"con":true,"img":false}]}
{"op":"mcm","clk":"11541156741","pt":1719502831643,"mc":[{"id":"1.230180129","rc":[{"atb":[[1.49,11.29]],"id":60237218}],"con":true,"img":false}]}
{"op":"mcm","clk":"11541156759","pt":1719502831837,"mc":[{"id":"1.230180129","rc":[{"atb":[[1.48,8.23]],"id":66050026}],"con":true,"img":false}]}
{"op":"mcm","clk":"11541158105","pt":1719502847441,"mc":[{"id":"1.230180129","rc":[{"spn":38.12,"spf":"NaN","id":50639934},{"atb":[[1.48,0]],"id":60237218},{"spn":38.24,"spf":"NaN","id":60237218},{"spn":38.12,"spf":"NaN","id":69213654},{"atb":[[1.48,0]],"id":66050026},{"spn":38.24,"spf":"NaN","id":66050026}],"con":true,"img":false}]}
{"op":"mcm","clk":"11541158717","pt":1719502854482,"mc":[{"id":"1.230180129","rc":[{"atb":[[1.45,0]],"id":66050026}],"con":true,"img":false}]}
{"op":"mcm","clk":"11541158786","pt":1719502855160,"mc":[{"id":"1.230180129","rc":[{"atb":[[1.46,0]],"id":66050026}],"con":true,"img":false}]}
{"op":"mcm","clk":"11541158820","pt":1719502855463,"mc":[{"id":"1.230180129","rc":[{"atb":[[1.23,0]],"id":69213654}],"con":true,"img":false}]}
{"op":"mcm","clk":"11541158850","pt":1719502855791,"mc":[{"id":"1.230180129","rc":[{"atb":[[1.45,0]],"id":60237218},{"atb":[[1.51,8.29]],"id":66050026}],"con":true,"img":false}]}
{"op":"mcm","clk":"11541158883","pt":1719502856049,"mc":[{"id":"1.230180129","rc":[{"atb":[[1.23,0]],"id":50639934}],"con":true,"img":false}]}
{"op":"mcm","clk":"11541158918","pt":1719502856363,"mc":[{"id":"1.230180129","rc":[{"atb":[[1.46,0]],"id":60237218}],"con":true,"img":false}]}
{"op":"mcm","clk":"11541158993","pt":1719502857144,"mc":[{"id":"1.230180129","rc":[{"atb":[[1.52,11.39]],"id":66050026}],"con":true,"img":false}]}
{"op":"mcm","clk":"11541159000","pt":1719502857251,"mc":[{"id":"1.230180129","rc":[{"atb":[[1.27,15.68]],"id":69213654}],"con":true,"img":false}]}
{"op":"mcm","clk":"11541159021","pt":1719502857455,"mc":[{"id":"1.230180129","rc":[{"atb":[[1.51,8.29]],"id":60237218}],"con":true,"img":false}]}
{"op":"mcm","clk":"11541159054","pt":1719502857766,"mc":[{"id":"1.230180129","rc":[{"atb":[[1.52,11.39]],"id":60237218}],"con":true,"img":false}]}
{"op":"mcm","clk":"11541159101","pt":1719502858279,"mc":[{"id":"1.230180129","rc":[{"atb":[[1.27,15.68]],"id":50639934}],"con":true,"img":false}]}
{"op":"mcm","clk":"11541159782","pt":1719502864673,"mc":[{"id":"1.230180129","rc":[{"atb":[[1.54,7.32]],"id":60237218}],"con":true,"img":false}]}
{"op":"mcm","clk":"11541159791","pt":1719502864778,"mc":[{"id":"1.230180129","rc":[{"atb":[[1.54,7.32]],"id":66050026}],"con":true,"img":false}]}
{"op":"mcm","clk":"11541159812","pt":1719502864985,"mc":[{"id":"1.230180129","rc":[{"atb":[[1.25,0]],"id":50639934},{"atb":[[1.49,0]],"id":60237218}],"con":true,"img":false}]}
{"op":"mcm","clk":"11541159825","pt":1719502865192,"mc":[{"id":"1.230180129","rc":[{"atb":[[1.49,0]],"id":66050026}],"con":true,"img":false}]}
{"op":"mcm","clk":"11541159843","pt":1719502865351,"mc":[{"id":"1.230180129","rc":[{"atb":[[1.25,0]],"id":69213654}],"con":true,"img":false}]}
{"op":"mcm","clk":"11541159866","pt":1719502865559,"mc":[{"id":"1.230180129","rc":[{"atb":[[1.29,13.62]],"id":50639934}],"con":true,"img":false}]}
{"op":"mcm","clk":"11541159902","pt":1719502865971,"mc":[{"id":"1.230180129","rc":[{"atb":[[1.29,13.62]],"id":69213654}],"con":true,"img":false}]}
{"op":"mcm","clk":"11541159924","pt":1719502866280,"mc":[{"id":"1.230180129","rc":[{"atb":[[1.55,10.06]],"id":66050026}],"con":true,"img":false}]}
{"op":"mcm","clk":"11541159948","pt":1719502866485,"mc":[{"id":"1.230180129","rc":[{"atb":[[1.55,10.06]],"id":60237218}],"con":true,"img":false}]}
{"op":"mcm","clk":"11541161872","pt":1719502889576,"mc":[{"id":"1.230180129","rc":[{"atb":[[1.27,0]],"id":50639934},{"atb":[[1.52,0]],"id":60237218}],"con":true,"img":false}]}
{"op":"mcm","clk":"11541161902","pt":1719502889879,"mc":[{"id":"1.230180129","rc":[{"atb":[[1.51,0]],"id":60237218}],"con":true,"img":false}]}
{"op":"mcm","clk":"11541161925","pt":1719502890247,"mc":[{"id":"1.230180129","rc":[{"atb":[[1.51,0]],"id":66050026}],"con":true,"img":false}]}
{"op":"mcm","clk":"11541161946","pt":1719502890568,"mc":[{"id":"1.230180129","rc":[{"atb":[[1.57,7.42]],"id":60237218}],"con":true,"img":false}]}
{"op":"mcm","clk":"11541161968","pt":1719502890863,"mc":[{"id":"1.230180129","rc":[{"atb":[[1.58,10.22]],"id":60237218},{"atb":[[1.27,0]],"id":69213654}],"con":true,"img":false}]}
{"op":"mcm","clk":"11541161995","pt":1719502891176,"mc":[{"id":"1.230180129","rc":[{"atb":[[1.52,0]],"id":66050026}],"con":true,"img":false}]}
{"op":"mcm","clk":"11541162059","pt":1719502891951,"mc":[{"id":"1.230180129","rc":[{"atb":[[1.31,13.65]],"id":50639934}],"con":true,"img":false}]}
{"op":"mcm","clk":"11541162104","pt":1719502892367,"mc":[{"id":"1.230180129","rc":[{"atb":[[1.57,7.42]],"id":66050026}],"con":true,"img":false}]}
{"op":"mcm","clk":"11541162113","pt":1719502892470,"mc":[{"id":"1.230180129","rc":[{"atb":[[1.58,10.22]],"id":66050026}],"con":true,"img":false}]}
{"op":"mcm","clk":"11541162133","pt":1719502892685,"mc":[{"id":"1.230180129","rc":[{"atb":[[1.31,13.65]],"id":69213654}],"con":true,"img":false}]}
{"op":"mcm","clk":"11541162685","pt":1719502899899,"mc":[{"id":"1.230180129","rc":[{"atb":[[1.55,0]],"id":66050026}],"con":true,"img":false}]}
{"op":"mcm","clk":"11541162712","pt":1719502900218,"mc":[{"id":"1.230180129","rc":[{"atb":[[1.55,0]],"id":60237218},{"atb":[[1.54,0]],"id":66050026}],"con":true,"img":false}]}
{"op":"mcm","clk":"11541162733","pt":1719502900411,"mc":[{"id":"1.230180129","rc":[{"atb":[[1.29,0]],"id":50639934},{"atb":[[1.29,0]],"id":69213654}],"con":true,"img":false}]}
{"op":"mcm","clk":"11541162764","pt":1719502900674,"mc":[{"id":"1.230180129","rc":[{"atb":[[1.54,0]],"id":60237218}],"con":true,"img":false}]}
{"op":"mcm","clk":"11541162812","pt":1719502901395,"mc":[{"id":"1.230180129","rc":[{"atb":[[1.33,11.97]],"id":50639934},{"atb":[[1.61,9.07]],"id":60237218}],"con":true,"img":false}]}
{"op":"mcm","clk":"11541162832","pt":1719502901706,"mc":[{"id":"1.230180129","rc":[{"atb":[[1.61,9.07]],"id":66050026}],"con":true,"img":false}]}
{"op":"mcm","clk":"11541162847","pt":1719502901908,"mc":[{"id":"1.230180129","rc":[{"atb":[[1.6,6.58]],"id":60237218}],"con":true,"img":false}]}
{"op":"mcm","clk":"11541162861","pt":1719502902066,"mc":[{"id":"1.230180129","rc":[{"atb":[[1.6,6.58]],"id":66050026}],"con":true,"img":false}]}
{"op":"mcm","clk":"11541162873","pt":1719502902265,"mc":[{"id":"1.230180129","rc":[{"atb":[[1.33,11.97]],"id":69213654}],"con":true,"img":false}]}
{"op":"mcm","clk":"11541164573","pt":1719502924300,"mc":[{"id":"1.230180129","rc":[{"spn":38.16,"spf":"NaN","id":50639934},{"spn":38.3,"spf":"NaN","id":60237218},{"spn":38.16,"spf":"NaN","id":69213654},{"atb":[[1.57,0]],"id":66050026},{"spn":38.3,"spf":"NaN","id":66050026}],"con":true,"img":false}]}
{"op":"mcm","clk":"11541164587","pt":1719502924507,"mc":[{"id":"1.230180129","rc":[{"atb":[[1.31,0]],"id":50639934}],"con":true,"img":false}]}
{"op":"mcm","clk":"11541164618","pt":1719502924816,"mc":[{"id":"1.230180129","rc":[{"atb":[[1.57,0]],"id":60237218}],"con":true,"img":false}]}
{"op":"mcm","clk":"11541164667","pt":1719502925487,"mc":[{"id":"1.230180129","rc":[{"atb":[[1.63,6.72]],"id":66050026}],"con":true,"img":false}]}
{"op":"mcm","clk":"11541164673","pt":1719502925593,"mc":[{"id":"1.230180129","rc":[{"atb":[[1.31,0]],"id":69213654}],"con":true,"img":false}]}
{"op":"mcm","clk":"11541164697","pt":1719502925900,"mc":[{"id":"1.230180129","rc":[{"atb":[[1.35,12.09]],"id":50639934}],"con":true,"img":false}]}
{"op":"mcm","clk":"11541164723","pt":1719502926204,"mc":[{"id":"1.230180129","rc":[{"atb":[[1.63,6.72]],"id":60237218}],"con":true,"img":false}]}
{"op":"mcm","clk":"11541164753","pt":1719502926514,"mc":[{"id":"1.230180129","rc":[{"atb":[[1.35,12.09]],"id":69213654}],"con":true,"img":false}]}
{"op":"mcm","clk":"11541165714","pt":1719502937625,"mc":[{"id":"1.230180129","rc":[{"atb":[[1.6,0]],"id":66050026}],"con":true,"img":false}]}
{"op":"mcm","clk":"11541165722","pt":1719502937723,"mc":[{"id":"1.230180129","rc":[{"atb":[[1.33,0]],"id":50639934}],"con":true,"img":false}]}
{"op":"mcm","clk":"11541165736","pt":1719502937931,"mc":[{"id":"1.230180129","rc":[{"atb":[[1.33,0]],"id":69213654}],"con":true,"img":false}]}
{"op":"mcm","clk":"11541165749","pt":1719502938139,"mc":[{"id":"1.230180129","rc":[{"atb":[[1.65,6.07]],"id":66050026}],"con":true,"img":false}]}
{"op":"mcm","clk":"11541165761","pt":1719502938292,"mc":[{"id":"1.230180129","rc":[{"atb":[[1.6,0]],"id":60237218}],"con":true,"img":false}]}
{"op":"mcm","clk":"11541165788","pt":1719502938704,"mc":[{"id":"1.230180129","rc":[{"atb":[[1.65,6.07]],"id":60237218}],"con":true,"img":false}]}
{"op":"mcm","clk":"11541165794","pt":1719502938802,"mc":[{"id":"1.230180129","rc":[{"atb":[[1.37,10.68]],"id":69213654}],"con":true,"img":false}]}
{"op":"mcm","clk":"11541165809","pt":1719502939008,"mc":[{"id":"1.230180129","rc":[{"atb":[[1.37,10.68]],"id":50639934}],"con":true,"img":false}]}
{"op":"mcm","clk":"11541167429","pt":1719502956516,"mc":[{"id":"1.230180129","rc":[{"atb":[[1.63,0]],"id":66050026}],"con":true,"img":false}]}
{"op":"mcm","clk":"11541167449","pt":1719502956719,"mc":[{"id":"1.230180129","rc":[{"atb":[[1.35,0]],"id":69213654}],"con":true,"img":false}]}
{"op":"mcm","clk":"11541167462","pt":1719502956825,"mc":[{"id":"1.230180129","rc":[{"atb":[[1.63,0]],"id":60237218}],"con":true,"img":false}]}
{"op":"mcm","clk":"11541167518","pt":1719502957339,"mc":[{"id":"1.230180129","rc":[{"atb":[[1.35,0]],"id":50639934}],"con":true,"img":false}]}
{"op":"mcm","clk":"11541167559","pt":1719502957752,"mc":[{"id":"1.230180129","rc":[{"atb":[[1.67,6.31]],"id":66050026}],"con":true,"img":false}]}
{"op":"mcm","clk":"11541167587","pt":1719502958056,"mc":[{"id":"1.230180129","rc":[{"atb":[[1.39,10.85]],"id":50639934}],"con":true,"img":false}]}
{"op":"mcm","clk":"11541167615","pt":1719502958364,"mc":[{"id":"1.230180129","rc":[{"atb":[[1.67,6.31]],"id":60237218}],"con":true,"img":false}]}
{"op":"mcm","clk":"11541167630","pt":1719502958520,"mc":[{"id":"1.230180129","rc":[{"atb":[[1.39,10.85]],"id":69213654}],"con":true,"img":false}]}
{"op":"mcm","clk":"11541167724","pt":1719502959553,"mc":[{"id":"1.230180129","rc":[{"atb":[[1.65,0]],"id":66050026}],"con":true,"img":false}]}
{"op":"mcm","clk":"11541167752","pt":1719502959863,"mc":[{"id":"1.230180129","rc":[{"atb":[[1.69,5.73]],"id":66050026}],"con":true,"img":false}]}
{"op":"mcm","clk":"11541167760","pt":1719502959967,"mc":[{"id":"1.230180129","rc":[{"atb":[[1.65,0]],"id":60237218}],"con":true,"img":false}]}
{"op":"mcm","clk":"11541167772","pt":1719502960073,"mc":[{"id":"1.230180129","rc":[{"atb":[[1.37,0]],"id":69213654}],"con":true,"img":false}]}
{"op":"mcm","clk":"11541167794","pt":1719502960237,"mc":[{"id":"1.230180129","rc":[{"atb":[[1.69,5.73]],"id":60237218}],"con":true,"img":false}]}
{"op":"mcm","clk":"11541167806","pt":1719502960335,"mc":[{"id":"1.230180129","rc":[{"atb":[[1.37,0]],"id":50639934}],"con":true,"img":false}]}
{"op":"mcm","clk":"11541167812","pt":1719502960436,"mc":[{"id":"1.230180129","rc":[{"atb":[[1.41,9.64]],"id":69213654}],"con":true,"img":false}]}
{"op":"mcm","clk":"11541167821","pt":1719502960540,"mc":[{"id":"1.230180129","rc":[{"atb":[[1.41,9.64]],"id":50639934}],"con":true,"img":false}]}
{"op":"mcm","clk":"11541170503","pt":1719502988674,"mc":[{"id":"1.230180129","rc":[{"spn":38.2,"spf":"NaN","id":50639934},{"atb":[[1.58,0]],"id":60237218},{"spn":38.34,"spf":"NaN","id":60237218},{"spn":38.2,"spf":"NaN","id":69213654},{"atb":[[1.58,0]],"id":66050026},{"spn":38.34,"spf":"NaN","id":66050026}],"con":true,"img":false}]}
{"op":"mcm","clk":"11541170866","pt":1719502992524,"mc":[{"id":"1.230180129","rc":[{"atb":[[1.67,0]],"id":66050026}],"con":true,"img":false}]}
{"op":"mcm","clk":"11541170886","pt":1719502992777,"mc":[{"id":"1.230180129","rc":[{"atb":[[1.39,0]],"id":69213654}],"con":true,"img":false}]}
{"op":"mcm","clk":"11541170901","pt":1719502992984,"mc":[{"id":"1.230180129","rc":[{"atb":[[1.67,0]],"id":60237218}],"con":true,"img":false}]}
{"op":"mcm","clk":"11541170946","pt":1719502993506,"mc":[{"id":"1.230180129","rc":[{"atb":[[1.39,0]],"id":50639934}],"con":true,"img":false}]}
{"op":"mcm","clk":"11541171016","pt":1719502994178,"mc":[{"id":"1.230180129","rc":[{"atb":[[1.71,5.96]],"id":66050026}],"con":true,"img":false}]}
{"op":"mcm","clk":"11541171039","pt":1719502994391,"mc":[{"id":"1.230180129","rc":[{"atb":[[1.71,5.96]],"id":60237218}],"con":true,"img":false}]}
{"op":"mcm","clk":"11541171069","pt":1719502994704,"mc":[{"id":"1.230180129","rc":[{"atb":[[1.43,9.84]],"id":69213654}],"con":true,"img":false}]}
{"op":"mcm","clk":"11541171093","pt":1719502994905,"mc":[{"id":"1.230180129","rc":[{"atb":[[1.43,9.84]],"id":50639934}],"con":true,"img":false}]}
{"op":"mcm","clk":"11541171207","pt":1719502995999,"mc":[{"id":"1.230180129","rc":[{"atb":[[1.69,0]],"id":66050026}],"con":true,"img":false}]}
{"op":"mcm","clk":"11541171226","pt":1719502996209,"mc":[{"id":"1.230180129","rc":[{"atb":[[1.69,0]],"id":60237218},{"atb":[[1.41,0]],"id":69213654}],"con":true,"img":false}]}
{"op":"mcm","clk":"11541171245","pt":1719502996369,"mc":[{"id":"1.230180129","rc":[{"atb":[[1.41,0]],"id":50639934}],"con":true,"img":false}]}
{"op":"mcm","clk":"11541171260","pt":1719502996581,"mc":[{"id":"1.230180129","rc":[{"atb":[[1.45,8.78]],"id":69213654}],"con":true,"img":false}]}
{"op":"mcm","clk":"11541171278","pt":1719502996783,"mc":[{"id":"1.230180129","rc":[{"atb":[[1.45,8.78]],"id":50639934},{"atb":[[1.73,5.41]],"id":60237218}],"con":true,"img":false}]}
{"op":"mcm","clk":"11541171285","pt":1719502996990,"mc":[{"id":"1.230180129","rc":[{"atb":[[1.73,5.41]],"id":66050026}],"con":true,"img":false}]}
{"op":"mcm","clk":"11541173971","pt":1719503026560,"mc":[{"id":"1.230180129","rc":[{"atb":[[1.43,0]],"id":50639934},{"atb":[[1.71,0]],"id":66050026}],"con":true,"img":false}]}
{"op":"mcm","clk":"11541173992","pt":1719503026825,"mc":[{"id":"1.230180129","rc":[{"atb":[[1.43,0]],"id":69213654}],"con":true,"img":false}]}
{"op":"mcm","clk":"11541174017","pt":1719503027032,"mc":[{"id":"1.230180129","rc":[{"atb":[[1.71,0]],"id":60237218}],"con":true,"img":false}]}
{"op":"mcm","clk":"11541174072","pt":1719503027646,"mc":[{"id":"1.230180129","rc":[{"atb":[[1.75,5.64]],"id":66050026}],"con":true,"img":false}]}
{"op":"mcm","clk":"11541174088","pt":1719503027854,"mc":[{"id":"1.230180129","rc":[{"atb":[[1.47,9]],"id":69213654}],"con":true,"img":false}]}
{"op":"mcm","clk":"11541174097","pt":1719503027958,"mc":[{"id":"1.230180129","rc":[{"atb":[[1.75,5.64]],"id":60237218}],"con":true,"img":false}]}
{"op":"mcm","clk":"11541174112","pt":1719503028162,"mc":[{"id":"1.230180129","rc":[{"atb":[[1.47,9]],"id":50639934}],"con":true,"img":false}]}
{"op":"mcm","clk":"11541174512","pt":1719503032254,"mc":[{"id":"1.230180129","rc":[{"atb":[[1.45,0]],"id":50639934}],"con":true,"img":false}]}
{"op":"mcm","clk":"11541174523","pt":1719503032348,"mc":[{"id":"1.230180129","rc":[{"atb":[[1.45,0]],"id":69213654}],"con":true,"img":false}]}
{"op":"mcm","clk":"11541174543","pt":1719503032553,"mc":[{"id":"1.230180129","rc":[{"atb":[[1.73,0]],"id":66050026}],"con":true,"img":false}]}
{"op":"mcm","clk":"11541174563","pt":1719503032756,"mc":[{"id":"1.230180129","rc":[{"atb":[[1.49,8.06]],"id":69213654}],"con":true,"img":false}]}
{"op":"mcm","clk":"11541174620","pt":1719503033272,"mc":[{"id":"1.230180129","rc":[{"atb":[[1.49,8.06]],"id":50639934}],"con":true,"img":false}]}
{"op":"mcm","clk":"11541174672","pt":1719503033749,"mc":[{"id":"1.230180129","rc":[{"atb":[[1.73,0]],"id":60237218},{"atb":[[1.77,5.13]],"id":66050026}],"con":true,"img":false}]}
{"op":"mcm","clk":"11541174698","pt":1719503033957,"mc":[{"id":"1.230180129","rc":[{"atb":[[1.77,5.13]],"id":60237218}],"con":true,"img":false}]}
{"op":"mcm","clk":"11541177376","pt":1719503061199,"mc":[{"id":"1.230180129","rc":[{"atb":[[1.47,0]],"id":50639934},{"spn":38.24,"spf":"NaN","id":50639934},{"spn":38.38,"spf":"NaN","id":60237218},{"spn":38.24,"spf":"NaN","id":69213654},{"spn":38.38,"spf":"NaN","id":66050026}],"con":true,"img":false}]}
{"op":"mcm","clk":"11541177401","pt":1719503061359,"mc":[{"id":"1.230180129","rc":[{"atb":[[1.47,0]],"id":69213654}],"con":true,"img":false}]}
{"op":"mcm","clk":"11541177411","pt":1719503061463,"mc":[{"id":"1.230180129","rc":[{"atb":[[1.75,0]],"id":60237218}],"con":true,"img":false}]}
{"op":"mcm","clk":"11541177429","pt":1719503061670,"mc":[{"id":"1.230180129","rc":[{"atb":[[1.75,0]],"id":66050026}],"con":true,"img":false}]}
{"op":"mcm","clk":"11541177524","pt":1719503062670,"mc":[{"id":"1.230180129","rc":[{"atb":[[1.51,8.29]],"id":69213654}],"con":true,"img":false}]}
{"op":"mcm","clk":"11541177552","pt":1719503062980,"mc":[{"id":"1.230180129","rc":[{"atb":[[1.79,5.35]],"id":66050026}],"con":true,"img":false}]}
{"op":"mcm","clk":"11541177572","pt":1719503063189,"mc":[{"id":"1.230180129","rc":[{"atb":[[1.51,8.29]],"id":50639934}],"con":true,"img":false}]}
{"op":"mcm","clk":"11541177593","pt":1719503063504,"mc":[{"id":"1.230180129","rc":[{"atb":[[1.79,5.35]],"id":60237218}],"con":true,"img":false}]}
{"op":"mcm","clk":"11541178062","pt":1719503068403,"mc":[{"id":"1.230180129","rc":[{"atb":[[1.61,0]],"id":60237218},{"atb":[[1.61,0]],"id":66050026}],"con":true,"img":false}]}
{"op":"mcm","clk":"11541178190","pt":1719503069595,"mc":[{"id":"1.230180129","rc":[{"atb":[[1.77,0]],"id":66050026}],"con":true,"img":false}]}
{"op":"mcm","clk":"11541178229","pt":1719503069914,"mc":[{"id":"1.230180129","rc":[{"atb":[[1.77,0]],"id":60237218}],"con":true,"img":false}]}
{"op":"mcm","clk":"11541178296","pt":1719503070490,"mc":[{"id":"1.230180129","rc":[{"atb":[[1.49,0]],"id":69213654}],"con":true,"img":false}]}
{"op":"mcm","clk":"11541178317","pt":1719503070689,"mc":[{"id":"1.230180129","rc":[{"atb":[[1.49,0]],"id":50639934}],"con":true,"img":false}]}
{"op":"mcm","clk":"11541178341","pt":1719503070895,"mc":[{"id":"1.230180129","rc":[{"atb":[[1.81,4.87]],"id":66050026}],"con":true,"img":false}]}
{"op":"mcm","clk":"11541178358","pt":1719503071103,"mc":[{"id":"1.230180129","rc":[{"atb":[[1.81,4.87]],"id":60237218}],"con":true,"img":false}]}
{"op":"mcm","clk":"11541178435","pt":1719503071686,"mc":[{"id":"1.230180129","rc":[{"atb":[[1.53,7.45]],"id":69213654}],"con":true,"img":false}]}
{"op":"mcm","clk":"11541178460","pt":1719503071900,"mc":[{"id":"1.230180129","rc":[{"atb":[[1.53,7.45]],"id":50639934}],"con":true,"img":false}]}
{"op":"mcm","clk":"11541180804","pt":1719503096022,"mc":[{"id":"1.230180129","rc":[{"atb":[[1.79,0]],"id":66050026}],"con":true,"img":false}]}
{"op":"mcm","clk":"11541180830","pt":1719503096329,"mc":[{"id":"1.230180129","rc":[{"atb":[[1.51,0]],"id":50639934}],"con":true,"img":false}]}
{"op":"mcm","clk":"11541180864","pt":1719503096693,"mc":[{"id":"1.230180129","rc":[{"atb":[[1.79,0]],"id":60237218}],"con":true,"img":false}]}
{"op":"mcm","clk":"11541180921","pt":1719503097413,"mc":[{"id":"1.230180129","rc":[{"atb":[[1.51,0]],"id":69213654}],"con":true,"img":false}]}
{"op":"mcm","clk":"11541180971","pt":1719503098030,"mc":[{"id":"1.230180129","rc":[{"atb":[[1.83,5.09]],"id":66050026}],"con":true,"img":false}]}
{"op":"mcm","clk":"11541180989","pt":1719503098338,"mc":[{"id":"1.230180129","rc":[{"atb":[[1.55,7.69]],"id":50639934},{"atb":[[1.83,5.09]],"id":60237218}],"con":true,"img":false}]}
{"op":"mcm","clk":"11541181075","pt":1719503099421,"mc":[{"id":"1.230180129","rc":[{"atb":[[1.55,7.69]],"id":69213654}],"con":true,"img":false}]}
{"op":"mcm","clk":"11541181711","pt":1719503105613,"mc":[{"id":"1.230180129","rc":[{"atb":[[1.81,0]],"id":60237218}],"con":true,"img":false}]}
{"op":"mcm","clk":"11541181747","pt":1719503106025,"mc":[{"id":"1.230180129","rc":[{"atb":[[1.53,0]],"id":69213654}],"con":true,"img":false}]}
{"op":"mcm","clk":"11541181782","pt":1719503106335,"mc":[{"id":"1.230180129","rc":[{"atb":[[1.53,0]],"id":50639934},{"atb":[[1.81,0]],"id":66050026}],"con":true,"img":false}]}
{"op":"mcm","clk":"11541181890","pt":1719503107430,"mc":[{"id":"1.230180129","rc":[{"atb":[[1.57,6.93]],"id":50639934}],"con":true,"img":false}]}
{"op":"mcm","clk":"11541181922","pt":1719503107833,"mc":[{"id":"1.230180129","rc":[{"atb":[[1.85,4.64]],"id":60237218}],"con":true,"img":false}]}
{"op":"mcm","clk":"11541181930","pt":1719503107937,"mc":[{"id":"1.230180129","rc":[{"atb":[[1.85,4.64]],"id":66050026}],"con":true,"img":false}]}
{"op":"mcm","clk":"11541181964","pt":1719503108146,"mc":[{"id":"1.230180129","rc":[{"atb":[[1.57,6.93]],"id":69213654}],"con":true,"img":false}]}
{"op":"mcm","clk":"11541184208","pt":1719503131599,"mc":[{"id":"1.230180129","rc":[{"atb":[[1.55,0]],"id":50639934},{"spn":38.28,"spf":"NaN","id":50639934},{"spn":38.42,"spf":"NaN","id":60237218},{"spn":38.28,"spf":"NaN","id":69213654},{"atb":[[1.83,0]],"id":66050026},{"spn":38.42,"spf":"NaN","id":66050026}],"con":true,"img":false}]}
{"op":"mcm","clk":"11541184233","pt":1719503131850,"mc":[{"id":"1.230180129","rc":[{"atb":[[1.83,0]],"id":60237218}],"con":true,"img":false}]}
{"op":"mcm","clk":"11541184289","pt":1719503132271,"mc":[{"id":"1.230180129","rc":[{"atb":[[1.55,0]],"id":69213654}],"con":true,"img":false}]}
{"op":"mcm","clk":"11541184415","pt":1719503133465,"mc":[{"id":"1.230180129","rc":[{"atb":[[1.87,4.86]],"id":66050026}],"con":true,"img":false}]}
{"op":"mcm","clk":"11541184447","pt":1719503133769,"mc":[{"id":"1.230180129","rc":[{"atb":[[1.59,7.17]],"id":50639934}],"con":true,"img":false}]}
{"op":"mcm","clk":"11541184459","pt":1719503133868,"mc":[{"id":"1.230180129","rc":[{"atb":[[1.87,4.86]],"id":60237218}],"con":true,"img":false}]}
{"op":"mcm","clk":"11541184487","pt":1719503134085,"mc":[{"id":"1.230180129","rc":[{"atb":[[1.59,7.17]],"id":69213654}],"con":true,"img":false}]}
{"op":"mcm","clk":"11541185309","pt":1719503142108,"mc":[{"id":"1.230180129","rc":[{"atb":[[1.85,0]],"id":66050026}],"con":true,"img":false}]}
{"op":"mcm","clk":"11541185330","pt":1719503142263,"mc":[{"id":"1.230180129","rc":[{"atb":[[1.57,0]],"id":50639934},{"atb":[[1.85,0]],"id":60237218}],"con":true,"img":false}]}
{"op":"mcm","clk":"11541185395","pt":1719503143081,"mc":[{"id":"1.230180129","rc":[{"atb":[[1.57,0]],"id":69213654}],"con":true,"img":false}]}
{"op":"mcm","clk":"11541185419","pt":1719503143295,"mc":[{"id":"1.230180129","rc":[{"atb":[[1.89,4.44]],"id":66050026}],"con":true,"img":false}]}
{"op":"mcm","clk":"11541185425","pt":1719503143395,"mc":[{"id":"1.230180129","rc":[{"atb":[[1.89,4.44]],"id":60237218}],"con":true,"img":false}]}
{"op":"mcm","clk":"11541185471","pt":1719503143763,"mc":[{"id":"1.230180129","rc":[{"atb":[[1.61,6.48]],"id":50639934}],"con":true,"img":false}]}
{"op":"mcm","clk":"11541185477","pt":1719503143857,"mc":[{"id":"1.230180129","rc":[{"atb":[[1.61,6.48]],"id":69213654}],"con":true,"img":false}]}
{"op":"mcm","clk":"11541187818","pt":1719503168017,"mc":[{"id":"1.230180129","rc":[{"atb":[[1.87,0]],"id":66050026}],"con":true,"img":false}]}
{"op":"mcm","clk":"11541187831","pt":1719503168117,"mc":[{"id":"1.230180129","rc":[{"atb":[[1.59,0]],"id":50639934}],"con":true,"img":false}]}
{"op":"mcm","clk":"11541187916","pt":1719503168687,"mc":[{"id":"1.230180129","rc":[{"atb":[[1.87,0]],"id":60237218}],"con":true,"img":false}]}
{"op":"mcm","clk":"11541187945","pt":1719503168987,"mc":[{"id":"1.230180129","rc":[{"atb":[[1.59,0]],"id":69213654}],"con":true,"img":false}]}
{"op":"mcm","clk":"11541188025","pt":1719503169726,"mc":[{"id":"1.230180129","rc":[{"atb":[[1.91,4.64]],"id":66050026}],"con":true,"img":false}]}
{"op":"mcm","clk":"11541188096","pt":1719503170293,"mc":[{"id":"1.230180129","rc":[{"atb":[[1.63,6.72]],"id":50639934}],"con":true,"img":false}]}
{"op":"mcm","clk":"11541188164","pt":1719503170915,"mc":[{"id":"1.230180129","rc":[{"atb":[[1.63,6.72]],"id":69213654}],"con":true,"img":false}]}
{"op":"mcm","clk":"11541188178","pt":1719503171010,"mc":[{"id":"1.230180129","rc":[{"atb":[[1.91,4.64]],"id":60237218}],"con":true,"img":false}]}
{"op":"mcm","clk":"11541188954","pt":1719503177929,"mc":[{"id":"1.230180129","rc":[{"atb":[[1.89,0]],"id":66050026}],"con":true,"img":false}]}
{"op":"mcm","clk":"11541188980","pt":1719503178153,"mc":[{"id":"1.230180129","rc":[{"atb":[[1.89,0]],"id":60237218}],"con":true,"img":false}]}
{"op":"mcm","clk":"11541189074","pt":1719503178933,"mc":[{"id":"1.230180129","rc":[{"atb":[[1.93,4.25]],"id":66050026}],"con":true,"img":false}]}
{"op":"mcm","clk":"11541189095","pt":1719503179127,"mc":[{"id":"1.230180129","rc":[{"atb":[[1.93,4.25]],"id":60237218}],"con":true,"img":false}]}
{"op":"mcm","clk":"11541191828","pt":1719503201820,"mc":[{"id":"1.230180129","rc":[{"spn":38.31,"spf":"NaN","id":50639934},{"spn":38.46,"spf":"NaN","id":60237218},{"spn":38.31,"spf":"NaN","id":69213654},{"atb":[[1.91,0]],"id":66050026},{"spn":38.46,"spf":"NaN","id":66050026}],"con":true,"img":false}]}
{"op":"mcm","clk":"11541191848","pt":1719503201937,"mc":[{"id":"1.230180129","rc":[{"atb":[[1.91,0]],"id":60237218}],"con":true,"img":false}]}
{"op":"mcm","clk":"11541192030","pt":1719503203477,"mc":[{"id":"1.230180129","rc":[{"atb":[[1.95,4.45]],"id":60237218},{"atb":[[1.95,4.45]],"id":66050026}],"con":true,"img":false}]}
{"op":"mcm","clk":"11541196739","pt":1719503249750,"mc":[{"id":"1.230180129","rc":[{"atb":[[1.61,0]],"id":50639934},{"atb":[[1.61,0]],"id":69213654}],"con":true,"img":false}]}
{"op":"mcm","clk":"11541199655","pt":1719503280443,"mc":[{"id":"1.230180129","rc":[{"atb":[[1.64,2.48],[1.74,1]],"id":50639934},{"atl":[[5,1],[10,2]],"id":50639934},{"spn":3.37,"spf":"NaN","id":50639934},{"atb":[[1.96,4.25]],"id":60237218},{"atl":[[34,2]],"id":60237218},{"spn":17.98,"spf":"NaN","id":60237218},{"atb":[[2.42,1]],"id":66050026},{"atl":[[8.2,1]],"id":66050026},{"spn":5.31,"spf":"NaN","id":66050026}],"con":true,"img":false}]}
{"op":"mcm","clk":"11541199663","pt":1719503280549,"mc":[{"id":"1.230180129","rc":[{"atb":[[1.36,2.48],[1.51,1]],"id":58821523},{"atl":[[7.2,2],[3.85,1]],"id":58821523},{"atb":[[2.62,1]],"id":60237218},{"atl":[[9.4,1]],"id":60237218},{"atb":[[1.31,31.83]],"id":51218587},{"atl":[[2.52,1],[3.8,2]],"id":51218587},{"atb":[[1.64,2.48],[1.74,1]],"id":69213654},{"atl":[[9.6,2],[5,1]],"id":69213654},{"atb":[[1.96,4.25]],"id":66050026},{"atl":[[38,2]],"id":66050026}],"con":true,"img":false}]}
{"op":"mcm","clk":"11541199822","pt":1719503282374,"mc":[{"id":"1.230180129","rc":[{"atb":[[1.01,53.59]],"id":58821523},{"atl":[[1000,1.7]],"id":58821523},{"atb":[[1.01,1.7]],"id":50639934},{"atl":[[1000,1.94]],"id":50639934},{"atb":[[1.01,53.59]],"id":66050026},{"atl":[[1000,1.94]],"id":66050026}],"con":true,"img":false}]}
{"op":"mcm","clk":"11541199847","pt":1719503282641,"mc":[{"id":"1.230180129","rc":[{"atb":[[1.01,52.74]],"id":58821523},{"atl":[[1000,0.05]],"id":58821523},{"atb":[[1.01,0.48]],"id":50639934},{"atl":[[1000,0.27]],"id":50639934},{"atb":[[1.01,52.21]],"id":66050026},{"atl":[[1000,0.24]],"id":66050026}],"con":true,"img":false}]}
{"op":"mcm","clk":"11541199864","pt":1719503282845,"mc":[{"id":"1.230180129","rc":[{"atb":[[1.01,51.88]],"id":58821523},{"atl":[[1000,0]],"id":58821523},{"atb":[[1.01,0]],"id":50639934},{"atl":[[1000,0.23]],"id":50639934},{"atb":[[1.01,51.88]],"id":66050026},{"atl":[[1000,0.23]],"id":66050026}],"con":true,"img":false}]}
{"op":"mcm","clk":"11541199876","pt":1719503282948,"mc":[{"id":"1.230180129","rc":[{"atb":[[1.37,0.85]],"id":58821523},{"atl":[[7,0.05]],"id":58821523},{"atb":[[1.65,0.48]],"id":50639934},{"atl":[[9.8,0.03]],"id":50639934},{"atb":[[1.97,0.32]],"id":66050026},{"atl":[[36,0]],"id":66050026}],"con":true,"img":false}]}
{"op":"mcm","clk":"11541199908","pt":1719503283261,"mc":[{"id":"1.230180129","rc":[{"atb":[[1.66,2.11]],"id":50639934},{"atb":[[1.96,6.36]],"id":60237218},{"atb":[[1.4,2.11]],"id":51218587},{"atb":[[1.66,2.11]],"id":69213654},{"atb":[[1.96,6.36]],"id":66050026}],"con":true,"img":false}]}
{"op":"mcm","clk":"11541199923","pt":1719503283465,"mc":[{"id":"1.230180129","rc":[{"atb":[[1.64,0],[1.66,4.23]],"id":50639934}],"con":true,"img":false}]}
{"op":"mcm","clk":"11541200713","pt":1719503290688,"mc":[{"id":"1.230180129","rc":[{"atb":[[1.64,0],[1.66,4.59]],"id":69213654}],"con":true,"img":false}]}
{"op":"mcm","clk":"11541202177","pt":1719503306380,"mc":[{"id":"1.230180129","rc":[{"atb":[[1.63,0]],"id":50639934},{"atb":[[1.63,0]],"id":69213654}],"con":true,"img":false}]}
{"op":"mcm","clk":"11541202312","pt":1719503307881,"mc":[{"id":"1.230180129","rc":[{"atb":[[1.36,0],[1.46,2]],"id":58821523},{"atb":[[2.06,4.45],[1.96,2.11]],"id":60237218},{"atl":[[34,0],[60,2]],"id":60237218},{"atb":[[1.37,32.04],[1.31,0]],"id":51218587},{"atl":[[3.8,0],[6.6,3]],"id":51218587},{"atl":[[9.6,0],[14,3]],"id":69213654},{"atb":[[1.96,2.11],[2.14,4.45]],"id":66050026}],"con":true,"img":false}]}
{"op":"mcm","clk":"11541202320","pt":1719503307987,"mc":[{"id":"1.230180129","rc":[{"atl":[[4.5,1],[3.85,0]],"id":58821523},{"atl":[[5,0],[5.8,1]],"id":50639934},{"atl":[[10.5,1],[9.4,0]],"id":60237218},{"atl":[[2.52,0],[2.76,1]],"id":51218587},{"atl":[[5.8,1]],"id":69213654},{"atl":[[8.2,0],[9.8,1]],"id":66050026}],"con":true,"img":false}]}
{"op":"mcm","clk":"11541202331","pt":1719503308090,"mc":[{"id":"1.230180129","rc":[{"atl":[[5,0]],"id":69213654}],"con":true,"img":false}]}
{"op":"mcm","clk":"11541202338","pt":1719503308194,"mc":[{"id":"1.230180129","rc":[{"atl":[[7.6,8.98]],"id":51218587}],"con":true,"img":false}]}
{"op":"mcm","clk":"11541202872","pt":1719503313705,"mc":[{"id":"1.230180129","rc":[{"atl":[[7.6,0]],"id":51218587}],"con":true,"img":false}]}
{"op":"mcm","clk":"11541202895","pt":1719503313912,"mc":[{"id":"1.230180129","rc":[{"atb":[[1.34,3.5]],"id":51218587}],"con":true,"img":false}]}
{"op":"mcm","clk":"11541203006","pt":1719503315311,"mc":[{"id":"1.230180129","rc":[{"atb":[[1.34,0]],"id":51218587}],"con":true,"img":false}]}
{"op":"mcm","clk":"11541203251","pt":1719503317694,"mc":[{"id":"1.230180129","rc":[{"atb":[[1.53,2]],"id":58821523},{"atb":[[2.16,4.45]],"id":60237218},{"atb":[[1.4,17.92]],"id":51218587},{"atb":[[2.26,2.12],[2.14,0]],"id":66050026}],"con":true,"img":false}]}
{"op":"mcm","clk":"11541203265","pt":1719503317792,"mc":[{"id":"1.230180129","rc":[{"atb":[[1.46,0]],"id":58821523},{"atb":[[2.06,0]],"id":60237218},{"atb":[[1.37,16.02]],"id":51218587}],"con":true,"img":false}]}
{"op":"mcm","clk":"11541203606","pt":1719503321309,"mc":[{"id":"1.230180129","rc":[{"atb":[[1.37,0]],"id":58821523},{"atl":[[7,0]],"id":58821523},{"atb":[[1.65,0]],"id":50639934},{"atl":[[9.8,0]],"id":50639934},{"atb":[[1.97,0]],"id":66050026},{"atl":[[36,0]],"id":66050026}],"con":true,"img":false}]}
{"op":"mcm","clk":"11541203613","pt":1719503321417,"mc":[{"id":"1.230180129","rc":[{"atl":[[7.2,0],[9.2,3]],"id":58821523},{"atl":[[14,3]],"id":50639934},{"atl":[[65,2]],"id":66050026}],"con":true,"img":false}]}
{"op":"mcm","clk":"11541203624","pt":1719503321513,"mc":[{"id":"1.230180129","rc":[{"atl":[[10,0]],"id":50639934},{"atl":[[38,0]],"id":66050026}],"con":true,"img":false}]}
{"op":"mcm","clk":"11541204029","pt":1719503326014,"mc":[{"id":"1.230180129","rc":[{"atl":[[7.6,9.98]],"id":51218587}],"con":true,"img":false}]}
{"op":"mcm","clk":"11541204182","pt":1719503328017,"mc":[{"id":"1.230180129","rc":[{"atl":[[7.6,0]],"id":51218587}],"con":true,"img":false}]}
{"op":"mcm","clk":"11541204643","pt":1719503333190,"mc":[{"id":"1.230180129","rc":[{"atb":[[2.28,2]],"id":66050026}],"con":true,"img":false}]}
{"op":"mcm","clk":"11541204660","pt":1719503333291,"mc":[{"id":"1.230180129","rc":[{"atl":[[7.6,9.98]],"id":51218587}],"con":true,"img":false}]}
{"op":"mcm","clk":"11541204691","pt":1719503333501,"mc":[{"id":"1.230180129","rc":[{"atb":[[1.02,2]],"id":58821523}],"con":true,"img":false}]}
{"op":"mcm","clk":"11541204746","pt":1719503334132,"mc":[{"id":"1.230180129","rc":[{"atb":[[1.67,2]],"id":50639934}],"con":true,"img":false}]}
{"op":"mcm","clk":"11541204773","pt":1719503334394,"mc":[{"id":"1.230180129","rc":[{"atb":[[1.67,2]],"id":69213654}],"con":true,"img":false}]}
{"op":"mcm","clk":"11541204809","pt":1719503334709,"mc":[{"id":"1.230180129","rc":[{"atb":[[1.41,2]],"id":51218587}],"con":true,"img":false}]}
{"op":"mcm","clk":"11541204848","pt":1719503335116,"mc":[{"id":"1.230180129","rc":[{"atb":[[2.18,2]],"id":60237218},{"atl":[[7.6,0]],"id":51218587}],"con":true,"img":false}]}
{"op":"mcm","clk":"11541204963","pt":1719503336514,"mc":[{"id":"1.230180129","rc":[{"atb":[[1.67,0]],"id":50639934}],"con":true,"img":false}]}
{"op":"mcm","clk":"11541204971","pt":1719503336619,"mc":[{"id":"1.230180129","rc":[{"atb":[[1.02,27.94]],"id":50639934}],"con":true,"img":false}]}
{"op":"mcm","clk":"11541205016","pt":1719503337087,"mc":[{"id":"1.230180129","rc":[{"atb":[[1.67,0]],"id":69213654}],"con":true,"img":false}]}
{"op":"mcm","clk":"11541205024","pt":1719503337238,"mc":[{"id":"1.230180129","rc":[{"atb":[[1.02,27.94]],"id":69213654}],"con":true,"img":false}]}
{"op":"mcm","clk":"11541205092","pt":1719503338118,"mc":[{"id":"1.230180129","rc":[{"atb":[[1.02,25.94]],"id":50639934}],"con":true,"img":false}]}
{"op":"mcm","clk":"11541205104","pt":1719503338221,"mc":[{"id":"1.230180129","rc":[{"atb":[[1.67,2]],"id":50639934}],"con":true,"img":false}]}
{"op":"mcm","clk":"11541205146","pt":1719503338636,"mc":[{"id":"1.230180129","rc":[{"atb":[[1.02,25.94]],"id":69213654}],"con":true,"img":false}]}
{"op":"mcm","clk":"11541205157","pt":1719503338740,"mc":[{"id":"1.230180129","rc":[{"atb":[[1.67,2]],"id":69213654}],"con":true,"img":false}]}
{"op":"mcm","clk":"11541205238","pt":1719503339525,"mc":[{"id":"1.230180129","rc":[{"atb":[[1.67,0]],"id":50639934}],"con":true,"img":false}]}
{"op":"mcm","clk":"11541205250","pt":1719503339626,"mc":[{"id":"1.230180129","rc":[{"atb":[[1.02,27.94]],"id":50639934}],"con":true,"img":false}]}
{"op":"mcm","clk":"11541205303","pt":1719503340097,"mc":[{"id":"1.230180129","rc":[{"atb":[[1.67,0]],"id":69213654}],"con":true,"img":false}]}
{"op":"mcm","clk":"11541205315","pt":1719503340215,"mc":[{"id":"1.230180129","rc":[{"atb":[[1.02,27.94]],"id":69213654}],"con":true,"img":false}]}
{"op":"mcm","clk":"11541205351","pt":1719503340520,"mc":[{"id":"1.230180129","rc":[{"spn":1.62,"spf":1.0,"id":58821523},{"spn":3.77,"spf":"NaN","id":50639934},{"spn":6.56,"spf":"NaN","id":60237218},{"atl":[[7.6,9.98]],"id":51218587},{"spn":2.08,"spf":"NaN","id":51218587},{"spn":3.77,"spf":"NaN","id":69213654},{"spn":6.11,"spf":"NaN","id":66050026}],"con":true,"img":false}]}
{"op":"mcm","clk":"11541205469","pt":1719503341341,"mc":[{"id":"1.230180129","rc":[{"atb":[[1.02,25.94]],"id":50639934}],"con":true,"img":false}]}
{"op":"mcm","clk":"11541205482","pt":1719503341401,"mc":[{"id":"1.230180129","rc":[{"atb":[[1.67,2]],"id":50639934}],"con":true,"img":false}]}
{"op":"mcm","clk":"11541205525","pt":1719503341815,"mc":[{"id":"1.230180129","rc":[{"atb":[[1.02,25.94]],"id":69213654}],"con":true,"img":false}]}
{"op":"mcm","clk":"11541205540","pt":1719503341916,"mc":[{"id":"1.230180129","rc":[{"atb":[[1.67,2]],"id":69213654}],"con":true,"img":false}]}
{"op":"mcm","clk":"11541205578","pt":1719503342344,"mc":[{"id":"1.230180129","rc":[{"atl":[[7.6,0]],"id":51218587}],"con":true,"img":false}]}
{"op":"mcm","clk":"11541205619","pt":1719503342699,"mc":[{"id":"1.230180129","rc":[{"atb":[[1.67,0]],"id":50639934}],"con":true,"img":false}]}
{"op":"mcm","clk":"11541205630","pt":1719503342803,"mc":[{"id":"1.230180129","rc":[{"atb":[[1.02,27.94]],"id":50639934}],"con":true,"img":false}]}
{"op":"mcm","clk":"11541205679","pt":1719503343331,"mc":[{"id":"1.230180129","rc":[{"atb":[[1.67,0]],"id":69213654}],"con":true,"img":false}]}
{"op":"mcm","clk":"11541205695","pt":1719503343497,"mc":[{"id":"1.230180129","rc":[{"atb":[[1.02,27.94]],"id":69213654}],"con":true,"img":false}]}
{"op":"mcm","clk":"11541205779","pt":1719503344306,"mc":[{"id":"1.230180129","rc":[{"atb":[[1.02,25.94]],"id":50639934}],"con":true,"img":false}]}
{"op":"mcm","clk":"11541205789","pt":1719503344411,"mc":[{"id":"1.230180129","rc":[{"atb":[[1.67,2]],"id":50639934}],"con":true,"img":false}]}
{"op":"mcm","clk":"11541205830","pt":1719503344827,"mc":[{"id":"1.230180129","rc":[{"atb":[[1.02,25.94]],"id":69213654}],"con":true,"img":false}]}
{"op":"mcm","clk":"11541205839","pt":1719503344933,"mc":[{"id":"1.230180129","rc":[{"atb":[[1.67,2]],"id":69213654}],"con":true,"img":false}]}
{"op":"mcm","clk":"11541205908","pt":1719503345611,"mc":[{"id":"1.230180129","rc":[{"atb":[[1.67,0]],"id":50639934}],"con":true,"img":false}]}
{"op":"mcm","clk":"11541205922","pt":1719503345710,"mc":[{"id":"1.230180129","rc":[{"atb":[[1.02,27.94]],"id":50639934}],"con":true,"img":false}]}
{"op":"mcm","clk":"11541205949","pt":1719503346027,"mc":[{"id":"1.230180129","rc":[{"atb":[[1.67,0]],"id":69213654}],"con":true,"img":false}]}
{"op":"mcm","clk":"11541205959","pt":1719503346126,"mc":[{"id":"1.230180129","rc":[{"atb":[[1.02,27.94]],"id":69213654}],"con":true,"img":false}]}
{"op":"mcm","clk":"11541206036","pt":1719503346902,"mc":[{"id":"1.230180129","rc":[{"atb":[[1.02,25.94]],"id":50639934}],"con":true,"img":false}]}
{"op":"mcm","clk":"11541206048","pt":1719503347013,"mc":[{"id":"1.230180129","rc":[{"atb":[[1.67,2]],"id":50639934}],"con":true,"img":false}]}
{"op":"mcm","clk":"11541206090","pt":1719503347418,"mc":[{"id":"1.230180129","rc":[{"atl":[[7.6,9.98]],"id":51218587}],"con":true,"img":false}]}
{"op":"mcm","clk":"11541206101","pt":1719503347520,"mc":[{"id":"1.230180129","rc":[{"atb":[[1.02,25.94]],"id":69213654}],"con":true,"img":false}]}
{"op":"mcm","clk":"11541206112","pt":1719503347626,"mc":[{"id":"1.230180129","rc":[{"atb":[[1.67,2]],"id":69213654}],"con":true,"img":false}]}
{"op":"mcm","clk":"11541206197","pt":1719503348508,"mc":[{"id":"1.230180129","rc":[{"atb":[[1.67,0]],"id":50639934}],"con":true,"img":false}]}
{"op":"mcm","clk":"11541206209","pt":1719503348614,"mc":[{"id":"1.230180129","rc":[{"atb":[[1.02,27.94]],"id":50639934}],"con":true,"img":false}]}
{"op":"mcm","clk":"11541206249","pt":1719503348931,"mc":[{"id":"1.230180129","rc":[{"atb":[[1.67,0]],"id":69213654}],"con":true,"img":false}]}
{"op":"mcm","clk":"11541206261","pt":1719503349023,"mc":[{"id":"1.230180129","rc":[{"atb":[[1.02,27.94]],"id":69213654}],"con":true,"img":false}]}
{"op":"mcm","clk":"11541206327","pt":1719503349746,"mc":[{"id":"1.230180129","rc":[{"atl":[[7.6,0]],"id":51218587}],"con":true,"img":false}]}
{"op":"mcm","clk":"11541206358","pt":1719503350014,"mc":[{"id":"1.230180129","rc":[{"atb":[[1.02,25.94]],"id":50639934}],"con":true,"img":false}]}
{"op":"mcm","clk":"11541206371","pt":1719503350122,"mc":[{"id":"1.230180129","rc":[{"atb":[[1.67,2]],"id":50639934}],"con":true,"img":false}]}
{"op":"mcm","clk":"11541206408","pt":1719503350536,"mc":[{"id":"1.230180129","rc":[{"atb":[[1.02,25.94]],"id":69213654}],"con":true,"img":false}]}
{"op":"mcm","clk":"11541206421","pt":1719503350631,"mc":[{"id":"1.230180129","rc":[{"atb":[[1.67,2]],"id":69213654}],"con":true,"img":false}]}
{"op":"mcm","clk":"11541206501","pt":1719503351453,"mc":[{"id":"1.230180129","rc":[{"atb":[[1.67,0]],"id":50639934}],"con":true,"img":false}]}
{"op":"mcm","clk":"11541206509","pt":1719503351555,"mc":[{"id":"1.230180129","rc":[{"atb":[[1.02,27.94]],"id":50639934}],"con":true,"img":false}]}
{"op":"mcm","clk":"11541206525","pt":1719503351726,"mc":[{"id":"1.230180129","rc":[{"atb":[[1.67,0]],"id":69213654}],"con":true,"img":false}]}
{"op":"mcm","clk":"11541206535","pt":1719503351821,"mc":[{"id":"1.230180129","rc":[{"atb":[[1.02,27.94]],"id":69213654}],"con":true,"img":false}]}
{"op":"mcm","clk":"11541206585","pt":1719503352537,"mc":[{"id":"1.230180129","rc":[{"atb":[[1.02,25.94]],"id":50639934}],"con":true,"img":false}]}
{"op":"mcm","clk":"11541206591","pt":1719503352641,"mc":[{"id":"1.230180129","rc":[{"atb":[[1.67,2]],"id":50639934}],"con":true,"img":false}]}
{"op":"mcm","clk":"11541206620","pt":1719503352951,"mc":[{"id":"1.230180129","rc":[{"atb":[[1.02,25.94]],"id":69213654}],"con":true,"img":false}]}
{"op":"mcm","clk":"11541206633","pt":1719503353056,"mc":[{"id":"1.230180129","rc":[{"atb":[[1.67,2]],"id":69213654}],"con":true,"img":false}]}
{"op":"mcm","clk":"11541206677","pt":1719503353624,"mc":[{"id":"1.230180129","rc":[{"atb":[[1.67,0]],"id":50639934}],"con":true,"img":false}]}
{"op":"mcm","clk":"11541206684","pt":1719503353734,"mc":[{"id":"1.230180129","rc":[{"atb":[[1.02,27.94]],"id":50639934}],"con":true,"img":false}]}
{"op":"mcm","clk":"11541206705","pt":1719503354040,"mc":[{"id":"1.230180129","rc":[{"atb":[[1.67,0]],"id":69213654}],"con":true,"img":false}]}
{"op":"mcm","clk":"11541206712","pt":1719503354146,"mc":[{"id":"1.230180129","rc":[{"atb":[[1.02,27.94]],"id":69213654}],"con":true,"img":false}]}
{"op":"mcm","clk":"11541206759","pt":1719503354822,"mc":[{"id":"1.230180129","rc":[{"atb":[[1.02,25.94]],"id":50639934}],"con":true,"img":false}]}
{"op":"mcm","clk":"11541206770","pt":1719503354918,"mc":[{"id":"1.230180129","rc":[{"atb":[[1.67,2]],"id":50639934}],"con":true,"img":false}]}
{"op":"mcm","clk":"11541206804","pt":1719503355330,"mc":[{"id":"1.230180129","rc":[{"atl":[[7.6,9.98]],"id":51218587}],"con":true,"img":false}]}
{"op":"mcm","clk":"11541206812","pt":1719503355433,"mc":[{"id":"1.230180129","rc":[{"atb":[[1.02,25.94]],"id":69213654}],"con":true,"img":false}]}
{"op":"mcm","clk":"11541206822","pt":1719503355535,"mc":[{"id":"1.230180129","rc":[{"atb":[[1.67,2]],"id":69213654}],"con":true,"img":false}]}
{"op":"mcm","clk":"11541206871","pt":1719503356161,"mc":[{"id":"1.230180129","rc":[{"atb":[[1.67,0]],"id":50639934}],"con":true,"img":false}]}
{"op":"mcm","clk":"11541206881","pt":1719503356261,"mc":[{"id":"1.230180129","rc":[{"atb":[[1.02,27.94]],"id":50639934}],"con":true,"img":false}]}
{"op":"mcm","clk":"11541206904","pt":1719503356541,"mc":[{"id":"1.230180129","rc":[{"atb":[[1.67,0]],"id":69213654}],"con":true,"img":false}]}
{"op":"mcm","clk":"11541206913","pt":1719503356644,"mc":[{"id":"1.230180129","rc":[{"atb":[[1.02,27.94]],"id":69213654}],"con":true,"img":false}]}
{"op":"mcm","clk":"11541206924","pt":1719503356856,"mc":[{"id":"1.230180129","rc":[{"atl":[[7.6,0]],"id":51218587}],"con":true,"img":false}]}
{"op":"mcm","clk":"11541206967","pt":1719503357526,"mc":[{"id":"1.230180129","rc":[{"atb":[[1.02,25.94]],"id":50639934}],"con":true,"img":false}]}
{"op":"mcm","clk":"11541206976","pt":1719503357624,"mc":[{"id":"1.230180129","rc":[{"atb":[[1.67,2]],"id":50639934}],"con":true,"img":false}]}
{"op":"mcm","clk":"11541207008","pt":1719503358038,"mc":[{"id":"1.230180129","rc":[{"atb":[[1.02,25.94]],"id":69213654}],"con":true,"img":false}]}
{"op":"mcm","clk":"11541207016","pt":1719503358140,"mc":[{"id":"1.230180129","rc":[{"atb":[[1.67,2]],"id":69213654}],"con":true,"img":false}]}
{"op":"mcm","clk":"11541207109","pt":1719503359327,"mc":[{"id":"1.230180129","rc":[{"atb":[[1.67,0]],"id":50639934}],"con":true,"img":false}]}
{"op":"mcm","clk":"11541207122","pt":1719503359431,"mc":[{"id":"1.230180129","rc":[{"atb":[[1.02,27.94]],"id":50639934}],"con":true,"img":false}]}
{"op":"mcm","clk":"11541207159","pt":1719503359851,"mc":[{"id":"1.230180129","rc":[{"atb":[[1.67,0]],"id":69213654}],"con":true,"img":false}]}
{"op":"mcm","clk":"11541207171","pt":1719503359946,"mc":[{"id":"1.230180129","rc":[{"atb":[[1.02,27.94]],"id":69213654}],"con":true,"img":false}]}
{"op":"mcm","clk":"11541207227","pt":1719503360567,"mc":[{"id":"1.230180129","rc":[{"atb":[[1.02,25.94]],"id":50639934}],"con":true,"img":false}]}
{"op":"mcm","clk":"11541207238","pt":1719503360670,"mc":[{"id":"1.230180129","rc":[{"atb":[[1.67,2]],"id":50639934}],"con":true,"img":false}]}
{"op":"mcm","clk":"11541207262","pt":1719503360931,"mc":[{"id":"1.230180129","rc":[{"atb":[[1.02,25.94]],"id":69213654}],"con":true,"img":false}]}
{"op":"mcm","clk":"11541207267","pt":1719503361037,"mc":[{"id":"1.230180129","rc":[{"atb":[[1.67,2]],"id":69213654}],"con":true,"img":false}]}
{"op":"mcm","clk":"11541207324","pt":1719503361754,"mc":[{"id":"1.230180129","rc":[{"atb":[[1.67,0]],"id":50639934}],"con":true,"img":false}]}
{"op":"mcm","clk":"11541207331","pt":1719503361863,"mc":[{"id":"1.230180129","rc":[{"atb":[[1.02,27.94]],"id":50639934}],"con":true,"img":false}]}
{"op":"mcm","clk":"11541207355","pt":1719503362167,"mc":[{"id":"1.230180129","rc":[{"atb":[[1.67,0]],"id":69213654}],"con":true,"img":false}]}
{"op":"mcm","clk":"11541207364","pt":1719503362225,"mc":[{"id":"1.230180129","rc":[{"atb":[[1.02,27.94]],"id":69213654}],"con":true,"img":false}]}
{"op":"mcm","clk":"11541207373","pt":1719503362325,"mc":[{"id":"1.230180129","rc":[{"atl":[[7.6,9.98]],"id":51218587}],"con":true,"img":false}]}
{"op":"mcm","clk":"11541207432","pt":1719503363074,"mc":[{"id":"1.230180129","rc":[{"atb":[[1.02,25.94]],"id":50639934}],"con":true,"img":false}]}
{"op":"mcm","clk":"11541207440","pt":1719503363178,"mc":[{"id":"1.230180129","rc":[{"atb":[[1.67,2]],"id":50639934}],"con":true,"img":false}]}
{"op":"mcm","clk":"11541207475","pt":1719503363439,"mc":[{"id":"1.230180129","rc":[{"atb":[[1.02,25.94]],"id":69213654}],"con":true,"img":false}]}
{"op":"mcm","clk":"11541207486","pt":1719503363544,"mc":[{"id":"1.230180129","rc":[{"atb":[[1.67,2]],"id":69213654}],"con":true,"img":false}]}
{"op":"mcm","clk":"11541207508","pt":1719503363764,"mc":[{"id":"1.230180129","rc":[{"atl":[[7.6,0]],"id":51218587}],"con":true,"img":false}]}
{"op":"mcm","clk":"11541207556","pt":1719503364216,"mc":[{"id":"1.230180129","rc":[{"atb":[[1.67,0]],"id":50639934}],"con":true,"img":false}]}
{"op":"mcm","clk":"11541207560","pt":1719503364267,"mc":[{"id":"1.230180129","rc":[{"atb":[[1.02,27.94]],"id":50639934},{"atb":[[1.93,0]],"id":60237218},{"atb":[[1.93,0]],"id":66050026}],"con":true,"img":false}]}
{"op":"mcm","clk":"11541207603","pt":1719503364635,"mc":[{"id":"1.230180129","rc":[{"atb":[[1.67,0]],"id":69213654}],"con":true,"img":false}]}
{"op":"mcm","clk":"11541207614","pt":1719503364736,"mc":[{"id":"1.230180129","rc":[{"atb":[[1.02,27.94]],"id":69213654}],"con":true,"img":false}]}
{"op":"mcm","clk":"11541207683","pt":1719503365567,"mc":[{"id":"1.230180129","rc":[{"atb":[[1.02,25.94]],"id":50639934}],"con":true,"img":false}]}
{"op":"mcm","clk":"11541207709","pt":1719503365680,"mc":[{"id":"1.230180129","rc":[{"atb":[[1.67,2]],"id":50639934}],"con":true,"img":false}]}
{"op":"mcm","clk":"11541207827","pt":1719503366000,"mc":[{"id":"1.230180129","rc":[{"atb":[[1.02,25.94]],"id":69213654}],"con":true,"img":false}]}
{"op":"mcm","clk":"11541207893","pt":1719503366181,"mc":[{"id":"1.230180129","rc":[{"atb":[[1.67,2]],"id":69213654}],"con":true,"img":false}]}
{"op":"mcm","clk":"11541208111","pt":1719503367102,"mc":[{"id":"1.230180129","rc":[{"atb":[[1.67,0]],"id":50639934}],"con":true,"img":false}]}
{"op":"mcm","clk":"11541208164","pt":1719503367330,"mc":[{"id":"1.230180129","rc":[{"atb":[[1.02,27.94]],"id":50639934}],"con":true,"img":false}]}
{"op":"mcm","clk":"11541208234","pt":1719503367681,"mc":[{"id":"1.230180129","rc":[{"atb":[[1.67,0]],"id":69213654}],"con":true,"img":false}]}
{"op":"mcm","clk":"11541208253","pt":1719503367767,"mc":[{"id":"1.230180129","rc":[{"atb":[[1.02,27.94]],"id":69213654}],"con":true,"img":false}]}
{"op":"mcm","clk":"11541208339","pt":1719503368304,"mc":[{"id":"1.230180129","rc":[{"atb":[[1.02,25.94]],"id":50639934}],"con":true,"img":false}]}
{"op":"mcm","clk":"11541208355","pt":1719503368352,"mc":[{"id":"1.230180129","rc":[{"atb":[[1.67,2]],"id":50639934}],"con":true,"img":false}]}
{"op":"mcm","clk":"11541208396","pt":1719503368622,"mc":[{"id":"1.230180129","rc":[{"atb":[[1.02,25.94]],"id":69213654}],"con":true,"img":false}]}
{"op":"mcm","clk":"11541208413","pt":1719503368784,"mc":[{"id":"1.230180129","rc":[{"atb":[[1.67,2]],"id":69213654}],"con":true,"img":false}]}
{"op":"mcm","clk":"11541208444","pt":1719503369051,"mc":[{"id":"1.230180129","rc":[{"atl":[[7.6,9.98]],"id":51218587}],"con":true,"img":false}]}
{"op":"mcm","clk":"11541208506","pt":1719503369667,"mc":[{"id":"1.230180129","rc":[{"atb":[[1.67,0]],"id":50639934}],"con":true,"img":false}]}
{"op":"mcm","clk":"11541208518","pt":1719503369773,"mc":[{"id":"1.230180129","rc":[{"atb":[[1.02,27.94]],"id":50639934}],"con":true,"img":false}]}
{"op":"mcm","clk":"11541208565","pt":1719503370244,"mc":[{"id":"1.230180129","rc":[{"atb":[[1.67,0]],"id":69213654}],"con":true,"img":false}]}
{"op":"mcm","clk":"11541208577","pt":1719503370344,"mc":[{"id":"1.230180129","rc":[{"atb":[[1.02,27.94]],"id":69213654}],"con":true,"img":false}]}
{"op":"mcm","clk":"11541208677","pt":1719503371286,"mc":[{"id":"1.230180129","rc":[{"atb":[[1.02,25.94]],"id":50639934}],"con":true,"img":false}]}
{"op":"mcm","clk":"11541208690","pt":1719503371385,"mc":[{"id":"1.230180129","rc":[{"atb":[[1.67,2]],"id":50639934},{"atl":[[7.6,0]],"id":51218587}],"con":true,"img":false}]}
{"op":"mcm","clk":"11541208728","pt":1719503371651,"mc":[{"id":"1.230180129","rc":[{"atb":[[1.02,25.94]],"id":69213654}],"con":true,"img":false}]}
{"op":"mcm","clk":"11541208743","pt":1719503371755,"mc":[{"id":"1.230180129","rc":[{"atb":[[1.67,2]],"id":69213654}],"con":true,"img":false}]}
{"op":"mcm","clk":"11541208811","pt":1719503372277,"mc":[{"id":"1.230180129","rc":[{"atb":[[1.67,0]],"id":50639934}],"con":true,"img":false}]}
{"op":"mcm","clk":"11541208827","pt":1719503372385,"mc":[{"id":"1.230180129","rc":[{"atb":[[1.02,27.94]],"id":50639934}],"con":true,"img":false}]}
{"op":"mcm","clk":"11541208874","pt":1719503372653,"mc":[{"id":"1.230180129","rc":[{"atb":[[1.67,0]],"id":69213654}],"con":true,"img":false}]}
{"op":"mcm","clk":"11541208885","pt":1719503372763,"mc":[{"id":"1.230180129","rc":[{"atb":[[1.02,27.94]],"id":69213654}],"con":true,"img":false}]}
{"op":"mcm","clk":"11541208953","pt":1719503373277,"mc":[{"id":"1.230180129","rc":[{"atb":[[1.02,25.94]],"id":50639934}],"con":true,"img":false}]}
{"op":"mcm","clk":"11541208964","pt":1719503373381,"mc":[{"id":"1.230180129","rc":[{"atb":[[1.67,2]],"id":50639934}],"con":true,"img":false}]}
{"op":"mcm","clk":"11541208989","pt":1719503373644,"mc":[{"id":"1.230180129","rc":[{"atb":[[1.02,25.94]],"id":69213654}],"con":true,"img":false}]}
{"op":"mcm","clk":"11541208998","pt":1719503373753,"mc":[{"id":"1.230180129","rc":[{"atb":[[1.67,2]],"id":69213654}],"con":true,"img":false}]}
{"op":"mcm","clk":"11541209070","pt":1719503374384,"mc":[{"id":"1.230180129","rc":[{"atb":[[1.67,0]],"id":50639934}],"con":true,"img":false}]}
{"op":"mcm","clk":"11541209082","pt":1719503374488,"mc":[{"id":"1.230180129","rc":[{"atb":[[1.02,27.94]],"id":50639934}],"con":true,"img":false}]}
{"op":"mcm","clk":"11541209120","pt":1719503374756,"mc":[{"id":"1.230180129","rc":[{"atb":[[1.67,0]],"id":69213654}],"con":true,"img":false}]}
{"op":"mcm","clk":"11541209135","pt":1719503374858,"mc":[{"id":"1.230180129","rc":[{"atb":[[1.02,27.94]],"id":69213654}],"con":true,"img":false}]}
{"op":"mcm","clk":"11541209160","pt":1719503375063,"mc":[{"id":"1.230180129","rc":[{"atb":[[1.95,0]],"id":60237218},{"atb":[[1.95,0]],"id":66050026}],"con":true,"img":false}]}
{"op":"mcm","clk":"11541209192","pt":1719503375374,"mc":[{"id":"1.230180129","rc":[{"atb":[[1.02,25.94]],"id":50639934}],"con":true,"img":false}]}
{"op":"mcm","clk":"11541209202","pt":1719503375480,"mc":[{"id":"1.230180129","rc":[{"atb":[[1.67,2]],"id":50639934}],"con":true,"img":false}]}
{"op":"mcm","clk":"11541209231","pt":1719503375801,"mc":[{"id":"1.230180129","rc":[{"atb":[[1.02,25.94]],"id":69213654}],"con":true,"img":false}]}
{"op":"mcm","clk":"11541209243","pt":1719503375904,"mc":[{"id":"1.230180129","rc":[{"atb":[[1.67,2]],"id":69213654}],"con":true,"img":false}]}
{"op":"mcm","clk":"11541209407","pt":1719503376863,"mc":[{"id":"1.230180129","rc":[{"atl":[[7.6,9.98]],"id":51218587}],"con":true,"img":false}]}
{"op":"mcm","clk":"11541209448","pt":1719503377190,"mc":[{"id":"1.230180129","rc":[{"atb":[[1.67,0]],"id":50639934}],"con":true,"img":false}]}
{"op":"mcm","clk":"11541209458","pt":1719503377246,"mc":[{"id":"1.230180129","rc":[{"atb":[[1.02,27.94]],"id":50639934}],"con":true,"img":false}]}
{"op":"mcm","clk":"11541209511","pt":1719503378028,"mc":[{"id":"1.230180129","rc":[{"atb":[[1.67,0]],"id":69213654}],"con":true,"img":false}]}
{"op":"mcm","clk":"11541209524","pt":1719503378187,"mc":[{"id":"1.230180129","rc":[{"atb":[[1.02,27.94]],"id":69213654}],"con":true,"img":false}]}
{"op":"mcm","clk":"11541209547","pt":1719503378344,"mc":[{"id":"1.230180129","rc":[{"atl":[[7.6,0]],"id":51218587}],"con":true,"img":false}]}
{"op":"mcm","clk":"11541209637","pt":1719503379287,"mc":[{"id":"1.230180129","rc":[{"atb":[[1.02,25.94]],"id":50639934}],"con":true,"img":false}]}
{"op":"mcm","clk":"11541209657","pt":1719503379396,"mc":[{"id":"1.230180129","rc":[{"atb":[[1.67,2]],"id":50639934}],"con":true,"img":false}]}
{"op":"mcm","clk":"11541209747","pt":1719503379872,"mc":[{"id":"1.230180129","rc":[{"atb":[[1.02,25.94]],"id":69213654}],"con":true,"img":false}]}
{"op":"mcm","clk":"11541209758","pt":1719503379975,"mc":[{"id":"1.230180129","rc":[{"atb":[[1.67,2]],"id":69213654}],"con":true,"img":false}]}
{"op":"mcm","clk":"11541209852","pt":1719503380984,"mc":[{"id":"1.230180129","rc":[{"atb":[[1.67,0]],"id":50639934}],"con":true,"img":false}]}
{"op":"mcm","clk":"11541209863","pt":1719503381090,"mc":[{"id":"1.230180129","rc":[{"atb":[[1.02,27.94]],"id":50639934}],"con":true,"img":false}]}
{"op":"mcm","clk":"11541209901","pt":1719503381463,"mc":[{"id":"1.230180129","rc":[{"atb":[[1.67,0]],"id":69213654}],"con":true,"img":false}]}
{"op":"mcm","clk":"11541209913","pt":1719503381571,"mc":[{"id":"1.230180129","rc":[{"atb":[[1.02,27.94]],"id":69213654}],"con":true,"img":false}]}
{"op":"mcm","clk":"11541209961","pt":1719503382096,"mc":[{"id":"1.230180129","rc":[{"atb":[[1.02,25.94]],"id":50639934}],"con":true,"img":false}]}
{"op":"mcm","clk":"11541209973","pt":1719503382195,"mc":[{"id":"1.230180129","rc":[{"atb":[[1.67,2]],"id":50639934}],"con":true,"img":false}]}
{"op":"mcm","clk":"11541210009","pt":1719503382664,"mc":[{"id":"1.230180129","rc":[{"atb":[[1.02,25.94]],"id":69213654}],"con":true,"img":false}]}
{"op":"mcm","clk":"11541210018","pt":1719503382769,"mc":[{"id":"1.230180129","rc":[{"atb":[[1.67,2]],"id":69213654}],"con":true,"img":false}]}
{"op":"mcm","clk":"11541210081","pt":1719503383491,"mc":[{"id":"1.230180129","rc":[{"atb":[[1.67,0]],"id":50639934}],"con":true,"img":false}]}
{"op":"mcm","clk":"11541210088","pt":1719503383592,"mc":[{"id":"1.230180129","rc":[{"atb":[[1.02,27.94]],"id":50639934}],"con":true,"img":false}]}
{"op":"mcm","clk":"11541210116","pt":1719503383901,"mc":[{"id":"1.230180129","rc":[{"atl":[[7.6,9.98]],"id":51218587}],"con":true,"img":false}]}
{"op":"mcm","clk":"11541210140","pt":1719503384166,"mc":[{"id":"1.230180129","rc":[{"atb":[[1.67,0]],"id":69213654}],"con":true,"img":false}]}
{"op":"mcm","clk":"11541210155","pt":1719503384320,"mc":[{"id":"1.230180129","rc":[{"atb":[[1.02,27.94]],"id":69213654}],"con":true,"img":false}]}
{"op":"mcm","clk":"11541210227","pt":1719503385099,"mc":[{"id":"1.230180129","rc":[{"atb":[[1.02,25.94]],"id":50639934}],"con":true,"img":false}]}
{"op":"mcm","clk":"11541210234","pt":1719503385204,"mc":[{"id":"1.230180129","rc":[{"atb":[[1.67,2]],"id":50639934}],"con":true,"img":false}]}
{"op":"mcm","clk":"11541210262","pt":1719503385470,"mc":[{"id":"1.230180129","rc":[{"atb":[[1.02,25.94]],"id":69213654}],"con":true,"img":false}]}
{"op":"mcm","clk":"11541210269","pt":1719503385570,"mc":[{"id":"1.230180129","rc":[{"atl":[[7.6,0]],"id":51218587},{"atb":[[1.67,2]],"id":69213654}],"con":true,"img":false}]}
{"op":"mcm","clk":"11541210340","pt":1719503386399,"mc":[{"id":"1.230180129","rc":[{"atb":[[1.67,0]],"id":50639934}],"con":true,"img":false}]}
{"op":"mcm","clk":"11541210352","pt":1719503386502,"mc":[{"id":"1.230180129","rc":[{"atb":[[1.02,27.94]],"id":50639934}],"con":true,"img":false}]}
{"op":"mcm","clk":"11541210400","pt":1719503386971,"mc":[{"id":"1.230180129","rc":[{"atb":[[1.67,0]],"id":69213654}],"con":true,"img":false}]}
{"op":"mcm","clk":"11541210410","pt":1719503387074,"mc":[{"id":"1.230180129","rc":[{"atb":[[1.02,27.94]],"id":69213654}],"con":true,"img":false}]}
{"op":"mcm","clk":"11541210503","pt":1719503387911,"mc":[{"id":"1.230180129","rc":[{"atb":[[1.02,25.94]],"id":50639934}],"con":true,"img":false}]}
{"op":"mcm","clk":"11541210518","pt":1719503388018,"mc":[{"id":"1.230180129","rc":[{"atb":[[1.67,2]],"id":50639934}],"con":true,"img":false}]}
{"op":"mcm","clk":"11541210545","pt":1719503388275,"mc":[{"id":"1.230180129","rc":[{"atb":[[1.02,25.94]],"id":69213654}],"con":true,"img":false}]}
{"op":"mcm","clk":"11541210556","pt":1719503388378,"mc":[{"id":"1.230180129","rc":[{"atb":[[1.67,2]],"id":69213654}],"con":true,"img":false}]}
{"op":"mcm","clk":"11541210608","pt":1719503388996,"mc":[{"id":"1.230180129","rc":[{"atb":[[1.67,0]],"id":50639934}],"con":true,"img":false}]}
{"op":"mcm","clk":"11541210615","pt":1719503389099,"mc":[{"id":"1.230180129","rc":[{"atb":[[1.02,27.94]],"id":50639934}],"con":true,"img":false}]}
{"op":"mcm","clk":"11541210655","pt":1719503389575,"mc":[{"id":"1.230180129","rc":[{"atb":[[1.67,0]],"id":69213654}],"con":true,"img":false}]}
{"op":"mcm","clk":"11541210666","pt":1719503389671,"mc":[{"id":"1.230180129","rc":[{"atb":[[1.02,27.94]],"id":69213654}],"con":true,"img":false}]}
{"op":"mcm","clk":"11541210728","pt":1719503390290,"mc":[{"id":"1.230180129","rc":[{"atb":[[1.02,25.94]],"id":50639934}],"con":true,"img":false}]}
{"op":"mcm","clk":"11541210739","pt":1719503390394,"mc":[{"id":"1.230180129","rc":[{"atb":[[1.67,2]],"id":50639934}],"con":true,"img":false}]}
{"op":"mcm","clk":"11541210769","pt":1719503390706,"mc":[{"id":"1.230180129","rc":[{"atb":[[1.02,25.94]],"id":69213654}],"con":true,"img":false}]}
{"op":"mcm","clk":"11541210779","pt":1719503390764,"mc":[{"id":"1.230180129","rc":[{"atb":[[1.67,2]],"id":69213654}],"con":true,"img":false}]}
{"op":"mcm","clk":"11541210808","pt":1719503391071,"mc":[{"id":"1.230180129","rc":[{"atl":[[7.6,9.98]],"id":51218587}],"con":true,"img":false}]}
{"op":"mcm","clk":"11541210835","pt":1719503391379,"mc":[{"id":"1.230180129","rc":[{"atb":[[1.67,0]],"id":50639934}],"con":true,"img":false}]}
{"op":"mcm","clk":"11541210840","pt":1719503391485,"mc":[{"id":"1.230180129","rc":[{"atb":[[1.02,27.94]],"id":50639934}],"con":true,"img":false}]}
{"op":"mcm","clk":"11541210877","pt":1719503391896,"mc":[{"id":"1.230180129","rc":[{"atb":[[1.67,0]],"id":69213654}],"con":true,"img":false}]}
{"op":"mcm","clk":"11541210887","pt":1719503392002,"mc":[{"id":"1.230180129","rc":[{"atb":[[1.02,27.94]],"id":69213654}],"con":true,"img":false}]}
{"op":"mcm","clk":"11541210976","pt":1719503392886,"mc":[{"id":"1.230180129","rc":[{"atl":[[7.6,0]],"id":51218587}],"con":true,"img":false}]}
{"op":"mcm","clk":"11541210988","pt":1719503392995,"mc":[{"id":"1.230180129","rc":[{"atb":[[1.02,25.94]],"id":50639934}],"con":true,"img":false}]}
{"op":"mcm","clk":"11541210999","pt":1719503393092,"mc":[{"id":"1.230180129","rc":[{"atb":[[1.67,2]],"id":50639934}],"con":true,"img":false}]}
{"op":"mcm","clk":"11541211028","pt":1719503393402,"mc":[{"id":"1.230180129","rc":[{"atb":[[1.02,25.94]],"id":69213654}],"con":true,"img":false}]}
{"op":"mcm","clk":"11541211040","pt":1719503393506,"mc":[{"id":"1.230180129","rc":[{"atb":[[1.67,2]],"id":69213654}],"con":true,"img":false}]}
{"op":"mcm","clk":"11541211101","pt":1719503394080,"mc":[{"id":"1.230180129","rc":[{"atb":[[1.67,0]],"id":50639934},{"atb":[[1.91,3.75]],"id":60237218}],"con":true,"img":false}]}
{"op":"mcm","clk":"11541211114","pt":1719503394187,"mc":[{"id":"1.230180129","rc":[{"atb":[[1.02,27.94]],"id":50639934}],"con":true,"img":false}]}
{"op":"mcm","clk":"11541211186","pt":1719503394925,"mc":[{"id":"1.230180129","rc":[{"atb":[[1.67,0]],"id":69213654}],"con":true,"img":false}]}
{"op":"mcm","clk":"11541211196","pt":1719503394968,"mc":[{"id":"1.230180129","rc":[{"atb":[[1.02,27.94]],"id":69213654}],"con":true,"img":false}]}
{"op":"mcm","clk":"11541211265","pt":1719503395699,"mc":[{"id":"1.230180129","rc":[{"atb":[[1.02,25.94]],"id":50639934}],"con":true,"img":false}]}
{"op":"mcm","clk":"11541211273","pt":1719503395804,"mc":[{"id":"1.230180129","rc":[{"atb":[[1.67,2]],"id":50639934}],"con":true,"img":false}]}
{"op":"mcm","clk":"11541211283","pt":1719503395917,"mc":[{"id":"1.230180129","rc":[{"atb":[[1.91,0]],"id":60237218}],"con":true,"img":false}]}
{"op":"mcm","clk":"11541211302","pt":1719503396118,"mc":[{"id":"1.230180129","rc":[{"atb":[[1.02,25.94]],"id":69213654}],"con":true,"img":false}]}
{"op":"mcm","clk":"11541211311","pt":1719503396231,"mc":[{"id":"1.230180129","rc":[{"atb":[[1.67,2]],"id":69213654}],"con":true,"img":false}]}
{"op":"mcm","clk":"11541211370","pt":1719503396896,"mc":[{"id":"1.230180129","rc":[{"atb":[[1.67,0]],"id":50639934}],"con":true,"img":false}]}
{"op":"mcm","clk":"11541211376","pt":1719503397000,"mc":[{"id":"1.230180129","rc":[{"atb":[[1.02,27.94]],"id":50639934}],"con":true,"img":false}]}
{"op":"mcm","clk":"11541211408","pt":1719503397310,"mc":[{"id":"1.230180129","rc":[{"atb":[[1.67,0]],"id":69213654}],"con":true,"img":false}]}
{"op":"mcm","clk":"11541211419","pt":1719503397414,"mc":[{"id":"1.230180129","rc":[{"atb":[[1.02,27.94]],"id":69213654}],"con":true,"img":false}]}
{"op":"mcm","clk":"11541211481","pt":1719503397986,"mc":[{"id":"1.230180129","rc":[{"atb":[[1.02,25.94]],"id":50639934}],"con":true,"img":false}]}
{"op":"mcm","clk":"11541211487","pt":1719503398093,"mc":[{"id":"1.230180129","rc":[{"atb":[[1.67,2]],"id":50639934}],"con":true,"img":false}]}
{"op":"mcm","clk":"11541211525","pt":1719503398504,"mc":[{"id":"1.230180129","rc":[{"atb":[[1.02,25.94]],"id":69213654}],"con":true,"img":false}]}
{"op":"mcm","clk":"11541211533","pt":1719503398606,"mc":[{"id":"1.230180129","rc":[{"atb":[[1.67,2]],"id":69213654}],"con":true,"img":false}]}
{"op":"mcm","clk":"11541211551","pt":1719503398816,"mc":[{"id":"1.230180129","rc":[{"atl":[[7.6,9.98]],"id":51218587}],"con":true,"img":false}]}
{"op":"mcm","clk":"11541211602","pt":1719503399284,"mc":[{"id":"1.230180129","rc":[{"atb":[[1.67,0]],"id":50639934}],"con":true,"img":false}]}
{"op":"mcm","clk":"11541211612","pt":1719503399387,"mc":[{"id":"1.230180129","rc":[{"atb":[[1.02,27.94]],"id":50639934}],"con":true,"img":false}]}
{"op":"mcm","clk":"11541211650","pt":1719503399800,"mc":[{"id":"1.230180129","rc":[{"atb":[[1.35,0]],"id":51218587},{"atb":[[1.67,0]],"id":69213654}],"con":true,"img":false}]}
{"op":"mcm","clk":"11541211663","pt":1719503399903,"mc":[{"id":"1.230180129","rc":[{"atl":[[7.6,0]],"id":51218587},{"atb":[[1.02,27.94]],"id":69213654}],"con":true,"img":false}]}
{"op":"mcm","clk":"11541211745","pt":1719503400699,"mc":[{"id":"1.230180129","rc":[{"atb":[[1.02,25.94]],"id":50639934}],"con":true,"img":false}]}
{"op":"mcm","clk":"11541211761","pt":1719503400802,"mc":[{"id":"1.230180129","rc":[{"atb":[[1.67,2]],"id":50639934}],"con":true,"img":false}]}
{"op":"mcm","clk":"11541211788","pt":1719503401009,"mc":[{"id":"1.230180129","rc":[{"atb":[[1.02,25.94]],"id":69213654}],"con":true,"img":false}]}
{"op":"mcm","clk":"11541211798","pt":1719503401114,"mc":[{"id":"1.230180129","rc":[{"atb":[[1.67,2]],"id":69213654}],"con":true,"img":false}]}
{"op":"mcm","clk":"11541211874","pt":1719503401794,"mc":[{"id":"1.230180129","rc":[{"atb":[[1.67,0]],"id":50639934}],"con":true,"img":false}]}
{"op":"mcm","clk":"11541211881","pt":1719503401902,"mc":[{"id":"1.230180129","rc":[{"atb":[[1.02,27.94]],"id":50639934}],"con":true,"img":false}]}
{"op":"mcm","clk":"11541211915","pt":1719503402321,"mc":[{"id":"1.230180129","rc":[{"atb":[[1.01,53.59]],"id":58821523},{"atl":[[1000,1.7]],"id":58821523},{"atl":[[1000,1.94]],"id":50639934},{"atb":[[1.67,0]],"id":69213654},{"atb":[[1.01,53.59]],"id":66050026},{"atl":[[1000,1.94]],"id":66050026}],"con":true,"img":false}]}
{"op":"mcm","clk":"11541211924","pt":1719503402426,"mc":[{"id":"1.230180129","rc":[{"atb":[[1.01,1.7]],"id":50639934},{"atb":[[1.02,27.94]],"id":69213654}],"con":true,"img":false}]}
{"op":"mcm","clk":"11541211935","pt":1719503402480,"mc":[{"id":"1.230180129","rc":[{"atb":[[1.01,52.45]],"id":58821523},{"atl":[[1000,0.03]],"id":58821523},{"atl":[[1000,0.26]],"id":50639934},{"atb":[[1.01,52.12]],"id":66050026},{"atl":[[1000,0.24]],"id":66050026}],"con":true,"img":false}]}
{"op":"mcm","clk":"11541211949","pt":1719503402584,"mc":[{"id":"1.230180129","rc":[{"atb":[[1.01,0.45]],"id":50639934}],"con":true,"img":false}]}
{"op":"mcm","clk":"11541211960","pt":1719503402691,"mc":[{"id":"1.230180129","rc":[{"atb":[[1.01,51.88]],"id":58821523},{"atl":[[1000,0]],"id":58821523},{"atl":[[1000,0.23]],"id":50639934},{"atb":[[1.01,51.88]],"id":66050026},{"atl":[[1000,0.23]],"id":66050026}],"con":true,"img":false}]}
{"op":"mcm","clk":"11541211972","pt":1719503402794,"mc":[{"id":"1.230180129","rc":[{"atb":[[1.54,0.56]],"id":58821523},{"atl":[[9,0.03]],"id":58821523},{"atb":[[1.01,0]],"id":50639934},{"atl":[[13.5,0.02]],"id":50639934},{"atb":[[2.3,0.23]],"id":66050026},{"atl":[[60,0]],"id":66050026}],"con":true,"img":false}]}
{"op":"mcm","clk":"11541211985","pt":1719503402903,"mc":[{"id":"1.230180129","rc":[{"atb":[[1.67,0.45]],"id":50639934},{"atb":[[2.3,2.23]],"id":66050026}],"con":true,"img":false}]}
{"op":"mcm","clk":"11541211997","pt":1719503403010,"mc":[{"id":"1.230180129","rc":[{"atb":[[2.26,0]],"id":66050026}],"con":true,"img":false}]}
{"op":"mcm","clk":"11541212009","pt":1719503403113,"mc":[{"id":"1.230180129","rc":[{"atb":[[1.02,25.94]],"id":50639934}],"con":true,"img":false}]}
{"op":"mcm","clk":"11541212021","pt":1719503403212,"mc":[{"id":"1.230180129","rc":[{"atb":[[1.67,2.45]],"id":50639934}],"con":true,"img":false}]}
{"op":"mcm","clk":"11541212050","pt":1719503403526,"mc":[{"id":"1.230180129","rc":[{"atb":[[1.02,25.94]],"id":69213654}],"con":true,"img":false}]}
{"op":"mcm","clk":"11541212059","pt":1719503403629,"mc":[{"id":"1.230180129","rc":[{"atb":[[1.67,2]],"id":69213654}],"con":true,"img":false}]}
{"op":"mcm","clk":"11541212131","pt":1719503404303,"mc":[{"id":"1.230180129","rc":[{"atb":[[2.28,0]],"id":66050026}],"con":true,"img":false}]}
{"op":"mcm","clk":"11541212141","pt":1719503404407,"mc":[{"id":"1.230180129","rc":[{"atb":[[2.32,2]],"id":66050026}],"con":true,"img":false}]}
{"op":"mcm","clk":"11541212180","pt":1719503404717,"mc":[{"id":"1.230180129","rc":[{"atb":[[1.67,0.45]],"id":50639934}],"con":true,"img":false}]}
{"op":"mcm","clk":"11541212189","pt":1719503404822,"mc":[{"id":"1.230180129","rc":[{"atb":[[1.02,27.94]],"id":50639934}],"con":true,"img":false}]}
{"op":"mcm","clk":"11541212213","pt":1719503405094,"mc":[{"id":"1.230180129","rc":[{"atb":[[1.67,0]],"id":69213654}],"con":true,"img":false}]}
{"op":"mcm","clk":"11541212227","pt":1719503405200,"mc":[{"id":"1.230180129","rc":[{"atb":[[1.02,27.94]],"id":69213654}],"con":true,"img":false}]}
{"op":"mcm","clk":"11541212269","pt":1719503405603,"mc":[{"id":"1.230180129","rc":[{"atl":[[7.6,9.98]],"id":51218587}],"con":true,"img":false}]}
{"op":"mcm","clk":"11541212319","pt":1719503406121,"mc":[{"id":"1.230180129","rc":[{"atb":[[1.02,25.94]],"id":50639934}],"con":true,"img":false}]}
{"op":"mcm","clk":"11541212334","pt":1719503406223,"mc":[{"id":"1.230180129","rc":[{"atb":[[1.67,2.45]],"id":50639934}],"con":true,"img":false}]}
{"op":"mcm","clk":"11541212364","pt":1719503406535,"mc":[{"id":"1.230180129","rc":[{"atb":[[1.02,25.94]],"id":69213654}],"con":true,"img":false}]}
{"op":"mcm","clk":"11541212375","pt":1719503406587,"mc":[{"id":"1.230180129","rc":[{"atb":[[1.67,2]],"id":69213654}],"con":true,"img":false}]}
{"op":"mcm","clk":"11541212400","pt":1719503406799,"mc":[{"id":"1.230180129","rc":[{"atl":[[7.6,0]],"id":51218587}],"con":true,"img":false}]}
{"op":"mcm","clk":"11541212487","pt":1719503407628,"mc":[{"id":"1.230180129","rc":[{"atb":[[1.67,0.45]],"id":50639934}],"con":true,"img":false}]}
{"op":"mcm","clk":"11541212498","pt":1719503407727,"mc":[{"id":"1.230180129","rc":[{"atb":[[1.02,27.94]],"id":50639934}],"con":true,"img":false}]}
{"op":"mcm","clk":"11541212534","pt":1719503408095,"mc":[{"id":"1.230180129","rc":[{"atb":[[1.67,0]],"id":69213654}],"con":true,"img":false}]}
{"op":"mcm","clk":"11541212547","pt":1719503408212,"mc":[{"id":"1.230180129","rc":[{"atb":[[1.02,27.94]],"id":69213654}],"con":true,"img":false}]}
{"op":"mcm","clk":"11541212622","pt":1719503408924,"mc":[{"id":"1.230180129","rc":[{"atb":[[1.02,25.94]],"id":50639934}],"con":true,"img":false}]}
{"op":"mcm","clk":"11541212630","pt":1719503409027,"mc":[{"id":"1.230180129","rc":[{"atb":[[1.67,2.45]],"id":50639934}],"con":true,"img":false}]}
{"op":"mcm","clk":"11541212660","pt":1719503409245,"mc":[{"id":"1.230180129","rc":[{"atb":[[1.02,25.94]],"id":69213654}],"con":true,"img":false}]}
{"op":"mcm","clk":"11541212667","pt":1719503409332,"mc":[{"id":"1.230180129","rc":[{"atb":[[1.67,2]],"id":69213654}],"con":true,"img":false}]}
{"op":"mcm","clk":"11541212731","pt":1719503410006,"mc":[{"id":"1.230180129","rc":[{"atb":[[1.67,0.45]],"id":50639934}],"con":true,"img":false}]}
{"op":"mcm","clk":"11541212740","pt":1719503410117,"mc":[{"id":"1.230180129","rc":[{"atb":[[1.02,27.94]],"id":50639934},{"atb":[[1.37,0]],"id":51218587}],"con":true,"img":false}]}
{"op":"mcm","clk":"11541212795","pt":1719503410599,"mc":[{"id":"1.230180129","rc":[{"atb":[[1.67,0]],"id":69213654}],"con":true,"img":false}]}
{"op":"mcm","clk":"11541212813","pt":1719503410753,"mc":[{"id":"1.230180129","rc":[{"atb":[[1.02,27.94]],"id":69213654}],"con":true,"img":false}]}
{"op":"mcm","clk":"11541212881","pt":1719503411422,"mc":[{"id":"1.230180129","rc":[{"atb":[[1.02,25.94]],"id":50639934}],"con":true,"img":false}]}
{"op":"mcm","clk":"11541212889","pt":1719503411526,"mc":[{"id":"1.230180129","rc":[{"atb":[[1.67,2.45]],"id":50639934}],"con":true,"img":false}]}
{"op":"mcm","clk":"11541212928","pt":1719503411895,"mc":[{"id":"1.230180129","rc":[{"atb":[[1.02,25.94]],"id":69213654}],"con":true,"img":false}]}
{"op":"mcm","clk":"11541212937","pt":1719503411995,"mc":[{"id":"1.230180129","rc":[{"atb":[[1.67,2]],"id":69213654}],"con":true,"img":false}]}
{"op":"mcm","clk":"11541212974","pt":1719503412406,"mc":[{"id":"1.230180129","rc":[{"atb":[[1.41,0]],"id":51218587}],"con":true,"img":false}]}
{"op":"mcm","clk":"11541212979","pt":1719503412510,"mc":[{"id":"1.230180129","rc":[{"atb":[[1.02,27.94]],"id":51218587}],"con":true,"img":false}]}
{"op":"mcm","clk":"11541212988","pt":1719503412715,"mc":[{"id":"1.230180129","rc":[{"atl":[[7.6,9.98]],"id":51218587}],"con":true,"img":false}]}
{"op":"mcm","clk":"11541213020","pt":1719503413134,"mc":[{"id":"1.230180129","rc":[{"atb":[[1.67,0.45]],"id":50639934}],"con":true,"img":false}]}
{"op":"mcm","clk":"11541213030","pt":1719503413231,"mc":[{"id":"1.230180129","rc":[{"atb":[[1.02,27.94]],"id":50639934}],"con":true,"img":false}]}
{"op":"mcm","clk":"11541213056","pt":1719503413540,"mc":[{"id":"1.230180129","rc":[{"atb":[[1.67,0]],"id":69213654}],"con":true,"img":false}]}
{"op":"mcm","clk":"11541213067","pt":1719503413594,"mc":[{"id":"1.230180129","rc":[{"atb":[[1.02,27.94]],"id":69213654}],"con":true,"img":false}]}
{"op":"mcm","clk":"11541213107","pt":1719503414112,"mc":[{"id":"1.230180129","rc":[{"atb":[[1.02,25.94]],"id":51218587}],"con":true,"img":false}]}
{"op":"mcm","clk":"11541213117","pt":1719503414217,"mc":[{"id":"1.230180129","rc":[{"atb":[[1.41,2]],"id":51218587}],"con":true,"img":false}]}
{"op":"mcm","clk":"11541213153","pt":1719503414519,"mc":[{"id":"1.230180129","rc":[{"atl":[[7.6,0]],"id":51218587}],"con":true,"img":false}]}
{"op":"mcm","clk":"11541213170","pt":1719503414728,"mc":[{"id":"1.230180129","rc":[{"atb":[[1.02,25.94]],"id":50639934}],"con":true,"img":false}]}
{"op":"mcm","clk":"11541213179","pt":1719503414833,"mc":[{"id":"1.230180129","rc":[{"atb":[[1.67,2.45]],"id":50639934}],"con":true,"img":false}]}
{"op":"mcm","clk":"11541213196","pt":1719503415043,"mc":[{"id":"1.230180129","rc":[{"atb":[[1.02,25.94]],"id":69213654}],"con":true,"img":false}]}
{"op":"mcm","clk":"11541213206","pt":1719503415095,"mc":[{"id":"1.230180129","rc":[{"atb":[[1.67,2]],"id":69213654}],"con":true,"img":false}]}
{"op":"mcm","clk":"11541213247","pt":1719503415613,"mc":[{"id":"1.230180129","rc":[{"atb":[[1.41,0]],"id":51218587}],"con":true,"img":false}]}
{"op":"mcm","clk":"11541213254","pt":1719503415717,"mc":[{"id":"1.230180129","rc":[{"atb":[[1.02,27.94]],"id":51218587}],"con":true,"img":false}]}
{"op":"mcm","clk":"11541213325","pt":1719503416492,"mc":[{"id":"1.230180129","rc":[{"atb":[[1.67,0.45]],"id":50639934}],"con":true,"img":false}]}
{"op":"mcm","clk":"11541213334","pt":1719503416596,"mc":[{"id":"1.230180129","rc":[{"atb":[[1.02,27.94]],"id":50639934}],"con":true,"img":false}]}
{"op":"mcm","clk":"11541213373","pt":1719503417115,"mc":[{"id":"1.230180129","rc":[{"atb":[[1.67,0]],"id":69213654}],"con":true,"img":false}]}
{"op":"mcm","clk":"11541213380","pt":1719503417214,"mc":[{"id":"1.230180129","rc":[{"atb":[[1.02,27.94]],"id":69213654}],"con":true,"img":false}]}
{"op":"mcm","clk":"11541213416","pt":1719503417630,"mc":[{"id":"1.230180129","rc":[{"atb":[[1.02,25.94]],"id":51218587}],"con":true,"img":false}]}
{"op":"mcm","clk":"11541213426","pt":1719503417730,"mc":[{"id":"1.230180129","rc":[{"atb":[[1.41,2]],"id":51218587}],"con":true,"img":false}]}
{"op":"mcm","clk":"11541213494","pt":1719503418504,"mc":[{"id":"1.230180129","rc":[{"atb":[[1.02,25.94]],"id":50639934}],"con":true,"img":false}]}
{"op":"mcm","clk":"11541213501","pt":1719503418608,"mc":[{"id":"1.230180129","rc":[{"atb":[[1.67,2.45]],"id":50639934}],"con":true,"img":false}]}
{"op":"mcm","clk":"11541213528","pt":1719503418923,"mc":[{"id":"1.230180129","rc":[{"atb":[[1.02,25.94]],"id":69213654}],"con":true,"img":false}]}
{"op":"mcm","clk":"11541213535","pt":1719503419027,"mc":[{"id":"1.230180129","rc":[{"atb":[[1.67,2]],"id":69213654}],"con":true,"img":false}]}
{"op":"mcm","clk":"11541213557","pt":1719503419332,"mc":[{"id":"1.230180129","rc":[{"atb":[[1.41,0]],"id":51218587}],"con":true,"img":false}]}
{"op":"mcm","clk":"11541213571","pt":1719503419439,"mc":[{"id":"1.230180129","rc":[{"atb":[[1.02,27.94]],"id":51218587}],"con":true,"img":false}]}
{"op":"mcm","clk":"11541213612","pt":1719503419954,"mc":[{"id":"1.230180129","rc":[{"atb":[[1.67,0.45]],"id":50639934}],"con":true,"img":false}]}
{"op":"mcm","clk":"11541213618","pt":1719503420056,"mc":[{"id":"1.230180129","rc":[{"atb":[[1.02,27.94]],"id":50639934}],"con":true,"img":false}]}
{"op":"mcm","clk":"11541213651","pt":1719503420417,"mc":[{"id":"1.230180129","rc":[{"atl":[[7.6,10.01]],"id":51218587}],"con":true,"img":false}]}
{"op":"mcm","clk":"11541213657","pt":1719503420520,"mc":[{"id":"1.230180129","rc":[{"atb":[[1.67,0]],"id":69213654}],"con":true,"img":false}]}
{"op":"mcm","clk":"11541213663","pt":1719503420623,"mc":[{"id":"1.230180129","rc":[{"atb":[[1.02,27.94]],"id":69213654}],"con":true,"img":false}]}
{"op":"mcm","clk":"11541213706","pt":1719503421137,"mc":[{"id":"1.230180129","rc":[{"atb":[[1.02,25.94]],"id":51218587}],"con":true,"img":false}]}
{"op":"mcm","clk":"11541213715","pt":1719503421247,"mc":[{"id":"1.230180129","rc":[{"atb":[[1.41,2]],"id":51218587}],"con":true,"img":false}]}
{"op":"mcm","clk":"11541213746","pt":1719503421506,"mc":[{"id":"1.230180129","rc":[{"atl":[[7.6,0]],"id":51218587}],"con":true,"img":false}]}
{"op":"mcm","clk":"11541213762","pt":1719503421711,"mc":[{"id":"1.230180129","rc":[{"atb":[[1.02,25.94]],"id":50639934}],"con":true,"img":false}]}
{"op":"mcm","clk":"11541213772","pt":1719503421820,"mc":[{"id":"1.230180129","rc":[{"atb":[[1.67,2.45]],"id":50639934}],"con":true,"img":false}]}
{"op":"mcm","clk":"11541213798","pt":1719503422127,"mc":[{"id":"1.230180129","rc":[{"atb":[[1.02,25.94]],"id":69213654}],"con":true,"img":false}]}
{"op":"mcm","clk":"11541213809","pt":1719503422228,"mc":[{"id":"1.230180129","rc":[{"atb":[[1.67,2]],"id":69213654}],"con":true,"img":false}]}
{"op":"mcm","clk":"11541213831","pt":1719503422539,"mc":[{"id":"1.230180129","rc":[{"atb":[[1.41,0]],"id":51218587}],"con":true,"img":false}]}
{"op":"mcm","clk":"11541213839","pt":1719503422640,"mc":[{"id":"1.230180129","rc":[{"atb":[[1.02,27.94]],"id":51218587}],"con":true,"img":false}]}
{"op":"mcm","clk":"11541213897","pt":1719503423313,"mc":[{"id":"1.230180129","rc":[{"atb":[[1.67,0.45]],"id":50639934}],"con":true,"img":false}]}
{"op":"mcm","clk":"11541213905","pt":1719503423416,"mc":[{"id":"1.230180129","rc":[{"atb":[[1.02,27.94]],"id":50639934}],"con":true,"img":false}]}
{"op":"mcm","clk":"11541213927","pt":1719503423624,"mc":[{"id":"1.230180129","rc":[{"atb":[[1.67,0]],"id":69213654}],"con":true,"img":false}]}
{"op":"mcm","clk":"11541213937","pt":1719503423725,"mc":[{"id":"1.230180129","rc":[{"atb":[[1.02,27.94]],"id":69213654}],"con":true,"img":false}]}
{"op":"mcm","clk":"11541213951","pt":1719503423936,"mc":[{"id":"1.230180129","rc":[{"atb":[[1.02,25.94]],"id":51218587}],"con":true,"img":false}]}
{"op":"mcm","clk":"11541213961","pt":1719503424040,"mc":[{"id":"1.230180129","rc":[{"atb":[[1.41,2]],"id":51218587}],"con":true,"img":false}]}
{"op":"mcm","clk":"11541214049","pt":1719503424918,"mc":[{"id":"1.230180129","rc":[{"atb":[[1.02,25.94]],"id":50639934}],"con":true,"img":false}]}
{"op":"mcm","clk":"11541214060","pt":1719503425022,"mc":[{"id":"1.230180129","rc":[{"atb":[[1.67,2.45]],"id":50639934}],"con":true,"img":false}]}
{"op":"mcm","clk":"11541214112","pt":1719503425534,"mc":[{"id":"1.230180129","rc":[{"atb":[[1.02,25.94]],"id":69213654}],"con":true,"img":false}]}
{"op":"mcm","clk":"11541214120","pt":1719503425636,"mc":[{"id":"1.230180129","rc":[{"atb":[[1.67,2]],"id":69213654}],"con":true,"img":false}]}
{"op":"mcm","clk":"11541214147","pt":1719503425945,"mc":[{"id":"1.230180129","rc":[{"atb":[[1.41,0]],"id":51218587}],"con":true,"img":false}]}
{"op":"mcm","clk":"11541214157","pt":1719503426004,"mc":[{"id":"1.230180129","rc":[{"atb":[[1.02,27.94]],"id":51218587}],"con":true,"img":false}]}
{"op":"mcm","clk":"11541214220","pt":1719503426725,"mc":[{"id":"1.230180129","rc":[{"atb":[[1.67,0.45]],"id":50639934}],"con":true,"img":false}]}
{"op":"mcm","clk":"11541214234","pt":1719503426834,"mc":[{"id":"1.230180129","rc":[{"atb":[[1.02,27.94]],"id":50639934}],"con":true,"img":false}]}
{"op":"mcm","clk":"11541214251","pt":1719503427040,"mc":[{"id":"1.230180129","rc":[{"atl":[[7.6,9.98]],"id":51218587}],"con":true,"img":false}]}
{"op":"mcm","clk":"11541214266","pt":1719503427143,"mc":[{"id":"1.230180129","rc":[{"atb":[[1.67,0]],"id":69213654}],"con":true,"img":false}]}
{"op":"mcm","clk":"11541214273","pt":1719503427242,"mc":[{"id":"1.230180129","rc":[{"atb":[[1.02,27.94]],"id":69213654}],"con":true,"img":false}]}
{"op":"mcm","clk":"11541214297","pt":1719503427501,"mc":[{"id":"1.230180129","rc":[{"atb":[[1.02,25.94]],"id":51218587}],"con":true,"img":false}]}
{"op":"mcm","clk":"11541214301","pt":1719503427611,"mc":[{"id":"1.230180129","rc":[{"atb":[[1.41,2]],"id":51218587}],"con":true,"img":false}]}
{"op":"mcm","clk":"11541214331","pt":1719503428025,"mc":[{"id":"1.230180129","rc":[{"atb":[[1.51,3.57],[1.53,0]],"id":58821523},{"atb":[[1.4,2.11],[1.37,19.93]],"id":51218587}],"con":true,"img":false}]}
{"op":"mcm","clk":"11541214341","pt":1719503428124,"mc":[{"id":"1.230180129","rc":[{"atb":[[1.02,25.94]],"id":50639934}],"con":true,"img":false}]}
{"op":"mcm","clk":"11541214348","pt":1719503428230,"mc":[{"id":"1.230180129","rc":[{"atb":[[1.67,2.45]],"id":50639934}],"con":true,"img":false}]}
{"op":"mcm","clk":"11541214377","pt":1719503428542,"mc":[{"id":"1.230180129","rc":[{"atl":[[7.6,0]],"id":51218587}],"con":true,"img":false}]}
{"op":"mcm","clk":"11541214394","pt":1719503428743,"mc":[{"id":"1.230180129","rc":[{"atb":[[1.02,25.94]],"id":69213654}],"con":true,"img":false}]}
{"op":"mcm","clk":"11541214404","pt":1719503428845,"mc":[{"id":"1.230180129","rc":[{"atb":[[1.67,2]],"id":69213654}],"con":true,"img":false}]}
{"op":"mcm","clk":"11541214434","pt":1719503429206,"mc":[{"id":"1.230180129","rc":[{"atb":[[1.41,0]],"id":51218587}],"con":true,"img":false}]}
{"op":"mcm","clk":"11541214443","pt":1719503429311,"mc":[{"id":"1.230180129","rc":[{"atb":[[1.02,27.94]],"id":51218587}],"con":true,"img":false}]}
{"op":"mcm","clk":"11541214512","pt":1719503430268,"mc":[{"id":"1.230180129","rc":[{"atb":[[1.67,0.45]],"id":50639934}],"con":true,"img":false}]}
{"op":"mcm","clk":"11541214522","pt":1719503430361,"mc":[{"id":"1.230180129","rc":[{"atb":[[1.02,27.94]],"id":50639934}],"con":true,"img":false}]}
{"op":"mcm","clk":"11541214556","pt":1719503430949,"mc":[{"id":"1.230180129","rc":[{"atb":[[1.67,0]],"id":69213654}],"con":true,"img":false}]}
{"op":"mcm","clk":"11541214564","pt":1719503430955,"mc":[{"id":"1.230180129","rc":[{"atb":[[1.02,27.94]],"id":69213654}],"con":true,"img":false}]}
{"op":"mcm","clk":"11541214635","pt":1719503431645,"mc":[{"id":"1.230180129","rc":[{"atb":[[1.02,25.94]],"id":50639934}],"con":true,"img":false}]}
{"op":"mcm","clk":"11541214643","pt":1719503431746,"mc":[{"id":"1.230180129","rc":[{"atb":[[1.67,2.45]],"id":50639934}],"con":true,"img":false}]}
{"op":"mcm","clk":"11541214679","pt":1719503432054,"mc":[{"id":"1.230180129","rc":[{"atb":[[1.02,25.94]],"id":69213654}],"con":true,"img":false}]}
{"op":"mcm","clk":"11541214691","pt":1719503432171,"mc":[{"id":"1.230180129","rc":[{"atb":[[1.67,2]],"id":69213654}],"con":true,"img":false}]}
{"op":"mcm","clk":"11541214750","pt":1719503432637,"mc":[{"id":"1.230180129","rc":[{"atb":[[1.67,0.45]],"id":50639934}],"con":true,"img":false}]}
{"op":"mcm","clk":"11541214762","pt":1719503432744,"mc":[{"id":"1.230180129","rc":[{"atb":[[1.02,27.94]],"id":50639934}],"con":true,"img":false}]}
{"op":"mcm","clk":"11541214796","pt":1719503433160,"mc":[{"id":"1.230180129","rc":[{"atb":[[1.67,0]],"id":69213654}],"con":true,"img":false}]}
{"op":"mcm","clk":"11541214804","pt":1719503433264,"mc":[{"id":"1.230180129","rc":[{"atb":[[1.02,27.94]],"id":69213654}],"con":true,"img":false}]}
{"op":"mcm","clk":"11541214850","pt":1719503433736,"mc":[{"id":"1.230180129","rc":[{"atb":[[1.02,25.94]],"id":50639934}],"con":true,"img":false}]}
{"op":"mcm","clk":"11541214859","pt":1719503433841,"mc":[{"id":"1.230180129","rc":[{"atb":[[1.67,2.45]],"id":50639934}],"con":true,"img":false}]}
{"op":"mcm","clk":"11541214893","pt":1719503434252,"mc":[{"id":"1.230180129","rc":[{"atb":[[1.02,25.94]],"id":69213654}],"con":true,"img":false}]}
{"op":"mcm","clk":"11541214903","pt":1719503434355,"mc":[{"id":"1.230180129","rc":[{"atb":[[1.67,2]],"id":69213654}],"con":true,"img":false}]}
{"op":"mcm","clk":"11541214975","pt":1719503435039,"mc":[{"id":"1.230180129","rc":[{"atb":[[1.67,0.45]],"id":50639934}],"con":true,"img":false}]}
{"op":"mcm","clk":"11541214985","pt":1719503435146,"mc":[{"id":"1.230180129","rc":[{"atb":[[1.02,27.94]],"id":50639934}],"con":true,"img":false}]}
{"op":"mcm","clk":"11541215019","pt":1719503435449,"mc":[{"id":"1.230180129","rc":[{"atb":[[1.67,0]],"id":69213654}],"con":true,"img":false}]}
{"op":"mcm","clk":"11541215027","pt":1719503435555,"mc":[{"id":"1.230180129","rc":[{"atb":[[1.02,27.94]],"id":69213654}],"con":true,"img":false}]}
{"op":"mcm","clk":"11541215073","pt":1719503436122,"mc":[{"id":"1.230180129","rc":[{"atb":[[1.02,25.94]],"id":50639934}],"con":true,"img":false}]}
{"op":"mcm","clk":"11541215080","pt":1719503436250,"mc":[{"id":"1.230180129","rc":[{"atb":[[1.67,2.45]],"id":50639934}],"con":true,"img":false}]}
{"op":"mcm","clk":"11541215114","pt":1719503436746,"mc":[{"id":"1.230180129","rc":[{"atb":[[1.02,25.94]],"id":69213654}],"con":true,"img":false}]}
{"op":"mcm","clk":"11541215124","pt":1719503436850,"mc":[{"id":"1.230180129","rc":[{"atb":[[1.67,2]],"id":69213654}],"con":true,"img":false}]}
{"op":"mcm","clk":"11541215134","pt":1719503436952,"mc":[{"id":"1.230180129","rc":[{"atb":[[1.39,14.19]],"id":51218587}],"con":true,"img":false}]}
{"op":"mcm","clk":"11541215168","pt":1719503437464,"mc":[{"id":"1.230180129","rc":[{"atb":[[1.67,0.45]],"id":50639934}],"con":true,"img":false}]}
{"op":"mcm","clk":"11541215177","pt":1719503437570,"mc":[{"id":"1.230180129","rc":[{"atb":[[1.02,27.94]],"id":50639934}],"con":true,"img":false}]}
{"op":"mcm","clk":"11541215223","pt":1719503438254,"mc":[{"id":"1.230180129","rc":[{"atb":[[1.67,0]],"id":69213654}],"con":true,"img":false}]}
{"op":"mcm","clk":"11541215232","pt":1719503438352,"mc":[{"id":"1.230180129","rc":[{"atb":[[1.02,27.94]],"id":69213654}],"con":true,"img":false}]}
{"op":"mcm","clk":"11541215254","pt":1719503438673,"mc":[{"id":"1.230180129","rc":[{"atb":[[1.02,25.94]],"id":51218587}],"con":true,"img":false}]}
{"op":"mcm","clk":"11541215263","pt":1719503438766,"mc":[{"id":"1.230180129","rc":[{"atb":[[1.41,2]],"id":51218587}],"con":true,"img":false}]}
{"op":"mcm","clk":"11541215324","pt":1719503439555,"mc":[{"id":"1.230180129","rc":[{"atb":[[1.02,25.94]],"id":50639934}],"con":true,"img":false}]}
{"op":"mcm","clk":"11541215332","pt":1719503439663,"mc":[{"id":"1.230180129","rc":[{"atb":[[1.67,2.45]],"id":50639934}],"con":true,"img":false}]}
{"op":"mcm","clk":"11541215348","pt":1719503439865,"mc":[{"id":"1.230180129","rc":[{"atb":[[1.02,25.94]],"id":69213654}],"con":true,"img":false}]}
{"op":"mcm","clk":"11541215357","pt":1719503439963,"mc":[{"id":"1.230180129","rc":[{"atb":[[1.67,2]],"id":69213654}],"con":true,"img":false}]}
{"op":"mcm","clk":"11541215395","pt":1719503440441,"mc":[{"id":"1.230180129","rc":[{"atb":[[1.67,0.45]],"id":50639934}],"con":true,"img":false}]}
{"op":"mcm","clk":"11541215403","pt":1719503440540,"mc":[{"id":"1.230180129","rc":[{"atb":[[1.02,27.94]],"id":50639934}],"con":true,"img":false}]}
{"op":"mcm","clk":"11541215426","pt":1719503440851,"mc":[{"id":"1.230180129","rc":[{"atb":[[1.67,0]],"id":69213654}],"con":true,"img":false}]}
{"op":"mcm","clk":"11541215432","pt":1719503440955,"mc":[{"id":"1.230180129","rc":[{"atb":[[1.02,27.94]],"id":69213654}],"con":true,"img":false}]}
{"op":"mcm","clk":"11541215480","pt":1719503441583,"mc":[{"id":"1.230180129","rc":[{"atb":[[1.02,25.94]],"id":50639934}],"con":true,"img":false}]}
{"op":"mcm","clk":"11541215499","pt":1719503441732,"mc":[{"id":"1.230180129","rc":[{"atb":[[1.67,2.45]],"id":50639934}],"con":true,"img":false}]}
{"op":"mcm","clk":"11541215531","pt":1719503442051,"mc":[{"id":"1.230180129","rc":[{"atb":[[1.02,25.94]],"id":69213654}],"con":true,"img":false}]}
{"op":"mcm","clk":"11541215544","pt":1719503442151,"mc":[{"id":"1.230180129","rc":[{"atb":[[1.67,2]],"id":69213654}],"con":true,"img":false}]}
{"op":"mcm","clk":"11541215593","pt":1719503442774,"mc":[{"id":"1.230180129","rc":[{"atb":[[1.67,0.45]],"id":50639934}],"con":true,"img":false}]}
{"op":"mcm","clk":"11541215604","pt":1719503442841,"mc":[{"id":"1.230180129","rc":[{"atb":[[1.02,27.94]],"id":50639934}],"con":true,"img":false}]}
{"op":"mcm","clk":"11541215637","pt":1719503443144,"mc":[{"id":"1.230180129","rc":[{"atb":[[1.67,0]],"id":69213654}],"con":true,"img":false}]}
{"op":"mcm","clk":"11541215650","pt":1719503443252,"mc":[{"id":"1.230180129","rc":[{"atb":[[1.02,27.94]],"id":69213654}],"con":true,"img":false}]}
{"op":"mcm","clk":"11541215687","pt":1719503443664,"mc":[{"id":"1.230180129","rc":[{"atb":[[1.02,25.94]],"id":50639934}],"con":true,"img":false}]}
{"op":"mcm","clk":"11541215697","pt":1719503443767,"mc":[{"id":"1.230180129","rc":[{"atb":[[1.67,2.45]],"id":50639934}],"con":true,"img":false}]}
{"op":"mcm","clk":"11541215725","pt":1719503444144,"mc":[{"id":"1.230180129","rc":[{"atb":[[1.02,25.94]],"id":69213654}],"con":true,"img":false}]}
{"op":"mcm","clk":"11541215733","pt":1719503444234,"mc":[{"id":"1.230180129","rc":[{"atb":[[1.67,2]],"id":69213654}],"con":true,"img":false}]}
{"op":"mcm","clk":"11541215778","pt":1719503444857,"mc":[{"id":"1.230180129","rc":[{"atb":[[1.67,0.45]],"id":50639934}],"con":true,"img":false}]}
{"op":"mcm","clk":"11541215790","pt":1719503444962,"mc":[{"id":"1.230180129","rc":[{"atb":[[1.02,27.94]],"id":50639934}],"con":true,"img":false}]}
{"op":"mcm","clk":"11541215823","pt":1719503445270,"mc":[{"id":"1.230180129","rc":[{"atb":[[1.67,0]],"id":69213654}],"con":true,"img":false}]}
{"op":"mcm","clk":"11541215830","pt":1719503445375,"mc":[{"id":"1.230180129","rc":[{"atb":[[1.02,27.94]],"id":69213654}],"con":true,"img":false}]}
{"op":"mcm","clk":"11541215883","pt":1719503445945,"mc":[{"id":"1.230180129","rc":[{"atb":[[1.02,25.94]],"id":50639934}],"con":true,"img":false}]}
{"op":"mcm","clk":"11541215888","pt":1719503446052,"mc":[{"id":"1.230180129","rc":[{"atb":[[1.67,2.45]],"id":50639934}],"con":true,"img":false}]}
{"op":"mcm","clk":"11541215927","pt":1719503446573,"mc":[{"id":"1.230180129","rc":[{"atb":[[1.02,25.94]],"id":69213654}],"con":true,"img":false}]}
{"op":"mcm","clk":"11541215939","pt":1719503446669,"mc":[{"id":"1.230180129","rc":[{"atb":[[1.67,2]],"id":69213654}],"con":true,"img":false}]}
{"op":"mcm","clk":"11541215992","pt":1719503447243,"mc":[{"id":"1.230180129","rc":[{"atb":[[1.67,0.45]],"id":50639934}],"con":true,"img":false}]}
{"op":"mcm","clk":"11541215998","pt":1719503447352,"mc":[{"id":"1.230180129","rc":[{"atb":[[1.02,27.94]],"id":50639934}],"con":true,"img":false}]}
{"op":"mcm","clk":"11541216025","pt":1719503447666,"mc":[{"id":"1.230180129","rc":[{"atb":[[1.67,0]],"id":69213654}],"con":true,"img":false}]}
{"op":"mcm","clk":"11541216035","pt":1719503447758,"mc":[{"id":"1.230180129","rc":[{"atb":[[1.02,27.94]],"id":69213654}],"con":true,"img":false}]}
{"op":"mcm","clk":"11541216108","pt":1719503448697,"mc":[{"id":"1.230180129","rc":[{"atb":[[1.02,25.94]],"id":50639934}],"con":true,"img":false}]}
{"op":"mcm","clk":"11541216122","pt":1719503448748,"mc":[{"id":"1.230180129","rc":[{"atb":[[1.67,2.45]],"id":50639934}],"con":true,"img":false}]}
{"op":"mcm","clk":"11541216152","pt":1719503449167,"mc":[{"id":"1.230180129","rc":[{"atb":[[1.02,25.94]],"id":69213654}],"con":true,"img":false}]}
{"op":"mcm","clk":"11541216162","pt":1719503449266,"mc":[{"id":"1.230180129","rc":[{"atb":[[1.54,0]],"id":58821523},{"atl":[[9,0]],"id":58821523},{"atb":[[1.67,2]],"id":50639934},{"atl":[[13.5,0]],"id":50639934},{"atb":[[1.67,2]],"id":69213654},{"atb":[[2.3,2]],"id":66050026},{"atl":[[60,0]],"id":66050026}],"con":true,"img":false}]}
{"op":"mcm","clk":"11541216178","pt":1719503449473,"mc":[{"id":"1.230180129","rc":[{"atb":[[1.51,1],[1.47,7.14]],"id":58821523}],"con":true,"img":false}]}
{"op":"mcm","clk":"11541216212","pt":1719503449784,"mc":[{"id":"1.230180129","rc":[{"atb":[[1.67,0]],"id":50639934}],"con":true,"img":false}]}
{"op":"mcm","clk":"11541216222","pt":1719503449889,"mc":[{"id":"1.230180129","rc":[{"atb":[[1.02,27.94]],"id":50639934}],"con":true,"img":false}]}
{"op":"mcm","clk":"11541216261","pt":1719503450354,"mc":[{"id":"1.230180129","rc":[{"atb":[[1.67,0]],"id":69213654}],"con":true,"img":false}]}
{"op":"mcm","clk":"11541216269","pt":1719503450458,"mc":[{"id":"1.230180129","rc":[{"atb":[[1.02,27.94]],"id":69213654}],"con":true,"img":false}]}
{"op":"mcm","clk":"11541216308","pt":1719503451083,"mc":[{"id":"1.230180129","rc":[{"atb":[[1.02,0]],"id":58821523}],"con":true,"img":false}]}
{"op":"mcm","clk":"11541216317","pt":1719503451189,"mc":[{"id":"1.230180129","rc":[{"atb":[[1.48,2]],"id":58821523}],"con":true,"img":false}]}
{"op":"mcm","clk":"11541216348","pt":1719503451550,"mc":[{"id":"1.230180129","rc":[{"atb":[[1.02,25.94]],"id":50639934}],"con":true,"img":false}]}
{"op":"mcm","clk":"11541216354","pt":1719503451659,"mc":[{"id":"1.230180129","rc":[{"atb":[[1.67,2]],"id":50639934}],"con":true,"img":false}]}
{"op":"mcm","clk":"11541216376","pt":1719503451963,"mc":[{"id":"1.230180129","rc":[{"atb":[[1.02,25.94]],"id":69213654}],"con":true,"img":false}]}
{"op":"mcm","clk":"11541216385","pt":1719503452067,"mc":[{"id":"1.230180129","rc":[{"atb":[[1.67,2]],"id":69213654}],"con":true,"img":false}]}
{"op":"mcm","clk":"11541216443","pt":1719503452684,"mc":[{"id":"1.230180129","rc":[{"atb":[[1.48,0]],"id":58821523}],"con":true,"img":false}]}
{"op":"mcm","clk":"11541216456","pt":1719503452787,"mc":[{"id":"1.230180129","rc":[{"atb":[[1.02,2]],"id":58821523}],"con":true,"img":false}]}
{"op":"mcm","clk":"11541216498","pt":1719503453263,"mc":[{"id":"1.230180129","rc":[{"atb":[[1.67,0]],"id":50639934}],"con":true,"img":false}]}
{"op":"mcm","clk":"11541216506","pt":1719503453359,"mc":[{"id":"1.230180129","rc":[{"atb":[[1.02,27.94]],"id":50639934}],"con":true,"img":false}]}
{"op":"mcm","clk":"11541216539","pt":1719503453877,"mc":[{"id":"1.230180129","rc":[{"atb":[[1.67,0]],"id":69213654}],"con":true,"img":false}]}
{"op":"mcm","clk":"11541216546","pt":1719503453984,"mc":[{"id":"1.230180129","rc":[{"atb":[[1.02,27.94]],"id":69213654}],"con":true,"img":false}]}
{"op":"mcm","clk":"11541216605","pt":1719503454860,"mc":[{"id":"1.230180129","rc":[{"atb":[[1.02,0]],"id":58821523}],"con":true,"img":false}]}
{"op":"mcm","clk":"11541216610","pt":1719503454963,"mc":[{"id":"1.230180129","rc":[{"atb":[[1.48,2]],"id":58821523}],"con":true,"img":false}]}
{"op":"mcm","clk":"11541216655","pt":1719503455483,"mc":[{"id":"1.230180129","rc":[{"atb":[[1.02,25.94]],"id":50639934}],"con":true,"img":false}]}
{"op":"mcm","clk":"11541216661","pt":1719503455589,"mc":[{"id":"1.230180129","rc":[{"atb":[[1.67,2]],"id":50639934}],"con":true,"img":false}]}
{"op":"mcm","clk":"11541216694","pt":1719503455952,"mc":[{"id":"1.230180129","rc":[{"atb":[[1.02,25.94]],"id":69213654}],"con":true,"img":false}]}
{"op":"mcm","clk":"11541216703","pt":1719503456057,"mc":[{"id":"1.230180129","rc":[{"atb":[[1.67,2]],"id":69213654}],"con":true,"img":false}]}
{"op":"mcm","clk":"11541216756","pt":1719503456781,"mc":[{"id":"1.230180129","rc":[{"atb":[[1.48,0]],"id":58821523}],"con":true,"img":false}]}
{"op":"mcm","clk":"11541216765","pt":1719503456885,"mc":[{"id":"1.230180129","rc":[{"atb":[[1.02,2]],"id":58821523}],"con":true,"img":false}]}
{"op":"mcm","clk":"11541216790","pt":1719503457255,"mc":[{"id":"1.230180129","rc":[{"atb":[[1.67,0]],"id":50639934}],"con":true,"img":false}]}
{"op":"mcm","clk":"11541216799","pt":1719503457351,"mc":[{"id":"1.230180129","rc":[{"atb":[[1.02,27.94]],"id":50639934}],"con":true,"img":false}]}
{"op":"mcm","clk":"11541216827","pt":1719503457770,"mc":[{"id":"1.230180129","rc":[{"atb":[[1.67,0]],"id":69213654}],"con":true,"img":false}]}
{"op":"mcm","clk":"11541216838","pt":1719503457869,"mc":[{"id":"1.230180129","rc":[{"atb":[[1.02,27.94]],"id":69213654}],"con":true,"img":false}]}
{"op":"mcm","clk":"11541216898","pt":1719503458696,"mc":[{"id":"1.230180129","rc":[{"atb":[[1.02,0]],"id":58821523}],"con":true,"img":false}]}
{"op":"mcm","clk":"11541216909","pt":1719503458798,"mc":[{"id":"1.230180129","rc":[{"atb":[[1.48,2]],"id":58821523}],"con":true,"img":false}]}
{"op":"mcm","clk":"11541216941","pt":1719503459167,"mc":[{"id":"1.230180129","rc":[{"atb":[[1.02,25.94]],"id":50639934}],"con":true,"img":false}]}
{"op":"mcm","clk":"11541216952","pt":1719503459264,"mc":[{"id":"1.230180129","rc":[{"atb":[[1.67,2]],"id":50639934}],"con":true,"img":false}]}
{"op":"mcm","clk":"11541217004","pt":1719503459885,"mc":[{"id":"1.230180129","rc":[{"atb":[[1.02,25.94]],"id":69213654}],"con":true,"img":false}]}
{"op":"mcm","clk":"11541217013","pt":1719503459989,"mc":[{"id":"1.230180129","rc":[{"atb":[[1.67,2]],"id":69213654}],"con":true,"img":false}]}
{"op":"mcm","clk":"11541217062","pt":1719503460663,"mc":[{"id":"1.230180129","rc":[{"atb":[[1.48,0]],"id":58821523}],"con":true,"img":false}]}
{"op":"mcm","clk":"11541217069","pt":1719503460765,"mc":[{"id":"1.230180129","rc":[{"atb":[[1.02,2]],"id":58821523},{"spn":1.61,"spf":1.0,"id":58821523}],"con":true,"img":false}]}
{"op":"mcm","clk":"11541217088","pt":1719503461076,"mc":[{"id":"1.230180129","rc":[{"atb":[[1.67,0]],"id":50639934}],"con":true,"img":false}]}
{"op":"mcm","clk":"11541217098","pt":1719503461182,"mc":[{"id":"1.230180129","rc":[{"atb":[[1.02,27.94]],"id":50639934}],"con":true,"img":false}]}
{"op":"mcm","clk":"11541217115","pt":1719503461390,"mc":[{"id":"1.230180129","rc":[{"atb":[[1.67,0]],"id":69213654}],"con":true,"img":false}]}
{"op":"mcm","clk":"11541217124","pt":1719503461492,"mc":[{"id":"1.230180129","rc":[{"atb":[[1.02,27.94]],"id":69213654}],"con":true,"img":false}]}
{"op":"mcm","clk":"11541217161","pt":1719503462062,"mc":[{"id":"1.230180129","rc":[{"atb":[[1.02,0]],"id":58821523}],"con":true,"img":false}]}
{"op":"mcm","clk":"11541217170","pt":1719503462170,"mc":[{"id":"1.230180129","rc":[{"atb":[[1.48,2]],"id":58821523}],"con":true,"img":false}]}
{"op":"mcm","clk":"11541217203","pt":1719503462479,"mc":[{"id":"1.230180129","rc":[{"atb":[[1.02,25.94]],"id":50639934}],"con":true,"img":false}]}
{"op":"mcm","clk":"11541217215","pt":1719503462583,"mc":[{"id":"1.230180129","rc":[{"atb":[[1.67,2]],"id":50639934}],"con":true,"img":false}]}
{"op":"mcm","clk":"11541217258","pt":1719503463006,"mc":[{"id":"1.230180129","rc":[{"atb":[[1.02,25.94]],"id":69213654}],"con":true,"img":false}]}
{"op":"mcm","clk":"11541217271","pt":1719503463108,"mc":[{"id":"1.230180129","rc":[{"atb":[[1.67,2]],"id":69213654}],"con":true,"img":false}]}
{"op":"mcm","clk":"11541217357","pt":1719503463994,"mc":[{"id":"1.230180129","rc":[{"atb":[[1.48,0]],"id":58821523}],"con":true,"img":false}]}
{"op":"mcm","clk":"11541217371","pt":1719503464101,"mc":[{"id":"1.230180129","rc":[{"atb":[[1.02,2]],"id":58821523}],"con":true,"img":false}]}
{"op":"mcm","clk":"11541217400","pt":1719503464410,"mc":[{"id":"1.230180129","rc":[{"atb":[[1.67,0]],"id":50639934}],"con":true,"img":false}]}
{"op":"mcm","clk":"11541217409","pt":1719503464460,"mc":[{"id":"1.230180129","rc":[{"atb":[[1.02,27.94]],"id":50639934}],"con":true,"img":false}]}
{"op":"mcm","clk":"11541217448","pt":1719503464878,"mc":[{"id":"1.230180129","rc":[{"atb":[[1.67,0]],"id":69213654}],"con":true,"img":false}]}
{"op":"mcm","clk":"11541217457","pt":1719503464982,"mc":[{"id":"1.230180129","rc":[{"atb":[[1.02,27.94]],"id":69213654}],"con":true,"img":false}]}
{"op":"mcm","clk":"11541217513","pt":1719503465661,"mc":[{"id":"1.230180129","rc":[{"atb":[[1.02,0]],"id":58821523}],"con":true,"img":false}]}
{"op":"mcm","clk":"11541217521","pt":1719503465762,"mc":[{"id":"1.230180129","rc":[{"atb":[[1.48,2]],"id":58821523}],"con":true,"img":false}]}
{"op":"mcm","clk":"11541217550","pt":1719503466182,"mc":[{"id":"1.230180129","rc":[{"atb":[[1.02,25.94]],"id":50639934}],"con":true,"img":false}]}
{"op":"mcm","clk":"11541217561","pt":1719503466282,"mc":[{"id":"1.230180129","rc":[{"atb":[[1.67,2]],"id":50639934}],"con":true,"img":false}]}
{"op":"mcm","clk":"11541217593","pt":1719503466703,"mc":[{"id":"1.230180129","rc":[{"atb":[[1.02,25.94]],"id":69213654}],"con":true,"img":false}]}
{"op":"mcm","clk":"11541217605","pt":1719503466804,"mc":[{"id":"1.230180129","rc":[{"atb":[[1.67,2]],"id":69213654}],"con":true,"img":false}]}
{"op":"mcm","clk":"11541217651","pt":1719503467280,"mc":[{"id":"1.230180129","rc":[{"atb":[[1.48,0]],"id":58821523}],"con":true,"img":false}]}
{"op":"mcm","clk":"11541217662","pt":1719503467375,"mc":[{"id":"1.230180129","rc":[{"atb":[[1.02,2]],"id":58821523}],"con":true,"img":false}]}
{"op":"mcm","clk":"11541217691","pt":1719503467790,"mc":[{"id":"1.230180129","rc":[{"atb":[[1.67,0]],"id":50639934}],"con":true,"img":false}]}
{"op":"mcm","clk":"11541217700","pt":1719503467897,"mc":[{"id":"1.230180129","rc":[{"atb":[[1.02,27.94]],"id":50639934}],"con":true,"img":false}]}
{"op":"mcm","clk":"11541217710","pt":1719503468008,"mc":[{"id":"1.230180129","rc":[{"atb":[[1.41,2.5]],"id":50639934}],"con":true,"img":false}]}
{"op":"mcm","clk":"11541217722","pt":1719503468106,"mc":[{"id":"1.230180129","rc":[{"atb":[[1.41,0]],"id":50639934}],"con":true,"img":false}]}
{"op":"mcm","clk":"11541217734","pt":1719503468231,"mc":[{"id":"1.230180129","rc":[{"atb":[[1.67,0]],"id":69213654}],"con":true,"img":false}]}
{"op":"mcm","clk":"11541217743","pt":1719503468325,"mc":[{"id":"1.230180129","rc":[{"atb":[[1.02,27.94]],"id":69213654}],"con":true,"img":false}]}
{"op":"mcm","clk":"11541217851","pt":1719503469214,"mc":[{"id":"1.230180129","rc":[{"atb":[[1.02,0]],"id":58821523}],"con":true,"img":false}]}
{"op":"mcm","clk":"11541217862","pt":1719503469309,"mc":[{"id":"1.230180129","rc":[{"atb":[[1.48,2]],"id":58821523}],"con":true,"img":false}]}
{"op":"mcm","clk":"11541217908","pt":1719503469774,"mc":[{"id":"1.230180129","rc":[{"atb":[[1.02,25.94]],"id":50639934}],"con":true,"img":false}]}
{"op":"mcm","clk":"11541217922","pt":1719503469872,"mc":[{"id":"1.230180129","rc":[{"atb":[[1.67,2]],"id":50639934}],"con":true,"img":false}]}
{"op":"mcm","clk":"11541217950","pt":1719503470182,"mc":[{"id":"1.230180129","rc":[{"atb":[[1.02,25.94]],"id":69213654}],"con":true,"img":false}]}
{"op":"mcm","clk":"11541217959","pt":1719503470287,"mc":[{"id":"1.230180129","rc":[{"atb":[[1.67,2]],"id":69213654}],"con":true,"img":false}]}
{"op":"mcm","clk":"11541217997","pt":1719503470774,"mc":[{"id":"1.230180129","rc":[{"atb":[[1.48,0]],"id":58821523}],"con":true,"img":false}]}
{"op":"mcm","clk":"11541218003","pt":1719503470881,"mc":[{"id":"1.230180129","rc":[{"atb":[[1.02,2]],"id":58821523}],"con":true,"img":false}]}
{"op":"mcm","clk":"11541218023","pt":1719503471187,"mc":[{"id":"1.230180129","rc":[{"atb":[[1.67,0]],"id":50639934}],"con":true,"img":false}]}
{"op":"mcm","clk":"11541218027","pt":1719503471292,"mc":[{"id":"1.230180129","rc":[{"atb":[[1.02,27.94]],"id":50639934}],"con":true,"img":false}]}
{"op":"mcm","clk":"11541218070","pt":1719503471812,"mc":[{"id":"1.230180129","rc":[{"atb":[[1.67,0]],"id":69213654}],"con":true,"img":false}]}
{"op":"mcm","clk":"11541218076","pt":1719503471917,"mc":[{"id":"1.230180129","rc":[{"atb":[[1.02,27.94]],"id":69213654}],"con":true,"img":false}]}
{"op":"mcm","clk":"11541218216","pt":1719503473382,"mc":[{"id":"1.230180129","rc":[{"atb":[[1.02,0]],"id":58821523}],"con":true,"img":false}]}
{"op":"mcm","clk":"11541218226","pt":1719503473486,"mc":[{"id":"1.230180129","rc":[{"atb":[[1.48,2]],"id":58821523}],"con":true,"img":false}]}
{"op":"mcm","clk":"11541218281","pt":1719503474105,"mc":[{"id":"1.230180129","rc":[{"atb":[[1.02,25.94]],"id":50639934}],"con":true,"img":false}]}
{"op":"mcm","clk":"11541218288","pt":1719503474214,"mc":[{"id":"1.230180129","rc":[{"atb":[[1.67,2]],"id":50639934}],"con":true,"img":false}]}
{"op":"mcm","clk":"11541218320","pt":1719503474572,"mc":[{"id":"1.230180129","rc":[{"atb":[[1.02,25.94]],"id":69213654}],"con":true,"img":false}]}
{"op":"mcm","clk":"11541218328","pt":1719503474676,"mc":[{"id":"1.230180129","rc":[{"atb":[[1.67,2]],"id":69213654}],"con":true,"img":false}]}
{"op":"mcm","clk":"11541218392","pt":1719503475411,"mc":[{"id":"1.230180129","rc":[{"atb":[[1.48,0]],"id":58821523}],"con":true,"img":false}]}
{"op":"mcm","clk":"11541218398","pt":1719503475514,"mc":[{"id":"1.230180129","rc":[{"atb":[[1.02,2]],"id":58821523}],"con":true,"img":false}]}
{"op":"mcm","clk":"11541218427","pt":1719503475881,"mc":[{"id":"1.230180129","rc":[{"atb":[[1.67,0]],"id":50639934}],"con":true,"img":false}]}
{"op":"mcm","clk":"11541218442","pt":1719503475990,"mc":[{"id":"1.230180129","rc":[{"atb":[[1.02,27.94]],"id":50639934}],"con":true,"img":false}]}
{"op":"mcm","clk":"11541218475","pt":1719503476403,"mc":[{"id":"1.230180129","rc":[{"atb":[[1.67,0]],"id":69213654}],"con":true,"img":false}]}
{"op":"mcm","clk":"11541218482","pt":1719503476507,"mc":[{"id":"1.230180129","rc":[{"atb":[[1.02,27.94]],"id":69213654}],"con":true,"img":false}]}
{"op":"mcm","clk":"11541218550","pt":1719503477393,"mc":[{"id":"1.230180129","rc":[{"atb":[[1.02,0]],"id":58821523}],"con":true,"img":false}]}
{"op":"mcm","clk":"11541218560","pt":1719503477501,"mc":[{"id":"1.230180129","rc":[{"atb":[[1.48,2]],"id":58821523}],"con":true,"img":false}]}
{"op":"mcm","clk":"11541218587","pt":1719503477909,"mc":[{"id":"1.230180129","rc":[{"atb":[[1.02,25.94]],"id":50639934}],"con":true,"img":false}]}
{"op":"mcm","clk":"11541218596","pt":1719503478012,"mc":[{"id":"1.230180129","rc":[{"atb":[[1.67,2]],"id":50639934}],"con":true,"img":false}]}
{"op":"mcm","clk":"11541218631","pt":1719503478377,"mc":[{"id":"1.230180129","rc":[{"atb":[[1.02,25.94]],"id":69213654}],"con":true,"img":false}]}
{"op":"mcm","clk":"11541218640","pt":1719503478485,"mc":[{"id":"1.230180129","rc":[{"atb":[[1.67,2]],"id":69213654}],"con":true,"img":false}]}
{"op":"mcm","clk":"11541218704","pt":1719503479307,"mc":[{"id":"1.230180129","rc":[{"atb":[[1.48,0]],"id":58821523}],"con":true,"img":false}]}
{"op":"mcm","clk":"11541218715","pt":1719503479410,"mc":[{"id":"1.230180129","rc":[{"atb":[[1.02,2]],"id":58821523}],"con":true,"img":false}]}
{"op":"mcm","clk":"11541218730","pt":1719503479617,"mc":[{"id":"1.230180129","rc":[{"atb":[[1.67,0]],"id":50639934}],"con":true,"img":false}]}
{"op":"mcm","clk":"11541218739","pt":1719503479720,"mc":[{"id":"1.230180129","rc":[{"atb":[[1.02,27.94]],"id":50639934}],"con":true,"img":false}]}
{"op":"mcm","clk":"11541218774","pt":1719503480085,"mc":[{"id":"1.230180129","rc":[{"atb":[[1.67,0]],"id":69213654}],"con":true,"img":false}]}
{"op":"mcm","clk":"11541218788","pt":1719503480193,"mc":[{"id":"1.230180129","rc":[{"atb":[[1.02,27.94]],"id":69213654}],"con":true,"img":false}]}
{"op":"mcm","clk":"11541218838","pt":1719503480810,"mc":[{"id":"1.230180129","rc":[{"atb":[[1.02,0]],"id":58821523}],"con":true,"img":false}]}
{"op":"mcm","clk":"11541218846","pt":1719503480911,"mc":[{"id":"1.230180129","rc":[{"atb":[[1.48,2]],"id":58821523}],"con":true,"img":false}]}
{"op":"mcm","clk":"11541218867","pt":1719503481331,"mc":[{"id":"1.230180129","rc":[{"atb":[[1.02,25.94]],"id":50639934}],"con":true,"img":false}]}
{"op":"mcm","clk":"11541218876","pt":1719503481381,"mc":[{"id":"1.230180129","rc":[{"atb":[[1.67,2]],"id":50639934}],"con":true,"img":false}]}
{"op":"mcm","clk":"11541218907","pt":1719503481801,"mc":[{"id":"1.230180129","rc":[{"atb":[[1.02,25.94]],"id":69213654}],"con":true,"img":false}]}
{"op":"mcm","clk":"11541218921","pt":1719503481898,"mc":[{"id":"1.230180129","rc":[{"atb":[[1.67,2]],"id":69213654}],"con":true,"img":false}]}
{"op":"mcm","clk":"11541218988","pt":1719503482741,"mc":[{"id":"1.230180129","rc":[{"atb":[[1.48,0]],"id":58821523}],"con":true,"img":false}]}
{"op":"mcm","clk":"11541219001","pt":1719503482784,"mc":[{"id":"1.230180129","rc":[{"atb":[[1.02,2]],"id":58821523}],"con":true,"img":false}]}
{"op":"mcm","clk":"11541219034","pt":1719503483200,"mc":[{"id":"1.230180129","rc":[{"atb":[[1.67,0]],"id":50639934}],"con":true,"img":false}]}
{"op":"mcm","clk":"11541219044","pt":1719503483307,"mc":[{"id":"1.230180129","rc":[{"atb":[[1.02,27.94]],"id":50639934}],"con":true,"img":false}]}
{"op":"mcm","clk":"11541219077","pt":1719503483613,"mc":[{"id":"1.230180129","rc":[{"atb":[[1.67,0]],"id":69213654}],"con":true,"img":false}]}
{"op":"mcm","clk":"11541219091","pt":1719503483717,"mc":[{"id":"1.230180129","rc":[{"atb":[[1.02,27.94]],"id":69213654}],"con":true,"img":false}]}
{"op":"mcm","clk":"11541219156","pt":1719503484404,"mc":[{"id":"1.230180129","rc":[{"atb":[[1.02,0]],"id":58821523}],"con":true,"img":false}]}
{"op":"mcm","clk":"11541219164","pt":1719503484502,"mc":[{"id":"1.230180129","rc":[{"atb":[[1.48,2]],"id":58821523}],"con":true,"img":false}]}
{"op":"mcm","clk":"11541219192","pt":1719503484923,"mc":[{"id":"1.230180129","rc":[{"atb":[[1.02,25.94]],"id":50639934}],"con":true,"img":false}]}
{"op":"mcm","clk":"11541219201","pt":1719503485027,"mc":[{"id":"1.230180129","rc":[{"atb":[[1.67,2]],"id":50639934}],"con":true,"img":false}]}
{"op":"mcm","clk":"11541219235","pt":1719503485392,"mc":[{"id":"1.230180129","rc":[{"atb":[[1.02,25.94]],"id":69213654}],"con":true,"img":false}]}
{"op":"mcm","clk":"11541219242","pt":1719503485497,"mc":[{"id":"1.230180129","rc":[{"atb":[[1.67,2]],"id":69213654}],"con":true,"img":false}]}
{"op":"mcm","clk":"11541219310","pt":1719503486327,"mc":[{"id":"1.230180129","rc":[{"atb":[[1.48,0]],"id":58821523}],"con":true,"img":false}]}
{"op":"mcm","clk":"11541219321","pt":1719503486425,"mc":[{"id":"1.230180129","rc":[{"atb":[[1.02,2]],"id":58821523}],"con":true,"img":false}]}
{"op":"mcm","clk":"11541219376","pt":1719503486997,"mc":[{"id":"1.230180129","rc":[{"atb":[[1.67,0]],"id":50639934}],"con":true,"img":false}]}
{"op":"mcm","clk":"11541219386","pt":1719503487100,"mc":[{"id":"1.230180129","rc":[{"atb":[[1.02,27.94]],"id":50639934}],"con":true,"img":false}]}
{"op":"mcm","clk":"11541219419","pt":1719503487516,"mc":[{"id":"1.230180129","rc":[{"atb":[[1.67,0]],"id":69213654}],"con":true,"img":false}]}
{"op":"mcm","clk":"11541219429","pt":1719503487618,"mc":[{"id":"1.230180129","rc":[{"atb":[[1.02,27.94]],"id":69213654}],"con":true,"img":false}]}
{"op":"mcm","clk":"11541219474","pt":1719503488187,"mc":[{"id":"1.230180129","rc":[{"atb":[[1.02,0]],"id":58821523}],"con":true,"img":false}]}
{"op":"mcm","clk":"11541219480","pt":1719503488299,"mc":[{"id":"1.230180129","rc":[{"atb":[[1.48,2]],"id":58821523}],"con":true,"img":false}]}
{"op":"mcm","clk":"11541219502","pt":1719503488602,"mc":[{"id":"1.230180129","rc":[{"atb":[[1.02,25.94]],"id":50639934}],"con":true,"img":false}]}
{"op":"mcm","clk":"11541219514","pt":1719503488711,"mc":[{"id":"1.230180129","rc":[{"atb":[[1.67,2]],"id":50639934}],"con":true,"img":false}]}
{"op":"mcm","clk":"11541219542","pt":1719503489122,"mc":[{"id":"1.230180129","rc":[{"atb":[[1.02,25.94]],"id":69213654}],"con":true,"img":false}]}
{"op":"mcm","clk":"11541219549","pt":1719503489224,"mc":[{"id":"1.230180129","rc":[{"atb":[[1.67,2]],"id":69213654}],"con":true,"img":false}]}
{"op":"mcm","clk":"11541219594","pt":1719503489891,"mc":[{"id":"1.230180129","rc":[{"atb":[[1.48,0]],"id":58821523}],"con":true,"img":false}]}
{"op":"mcm","clk":"11541219603","pt":1719503490018,"mc":[{"id":"1.230180129","rc":[{"atb":[[1.02,2]],"id":58821523}],"con":true,"img":false}]}
{"op":"mcm","clk":"11541219641","pt":1719503490508,"mc":[{"id":"1.230180129","rc":[{"atb":[[1.67,0]],"id":50639934}],"con":true,"img":false}]}
{"op":"mcm","clk":"11541219649","pt":1719503490611,"mc":[{"id":"1.230180129","rc":[{"atb":[[1.02,27.94]],"id":50639934}],"con":true,"img":false}]}
{"op":"mcm","clk":"11541219673","pt":1719503491226,"mc":[{"id":"1.230180129","rc":[{"atb":[[1.67,0]],"id":69213654}],"con":true,"img":false}]}
{"op":"mcm","clk":"11541219682","pt":1719503491243,"mc":[{"id":"1.230180129","rc":[{"atb":[[1.02,27.94]],"id":69213654}],"con":true,"img":false}]}
{"op":"mcm","clk":"11541219733","pt":1719503491700,"mc":[{"id":"1.230180129","rc":[{"atb":[[1.02,0]],"id":58821523}],"con":true,"img":false}]}
{"op":"mcm","clk":"11541219746","pt":1719503491799,"mc":[{"id":"1.230180129","rc":[{"atb":[[1.48,2]],"id":58821523}],"con":true,"img":false}]}
{"op":"mcm","clk":"11541219783","pt":1719503492211,"mc":[{"id":"1.230180129","rc":[{"atb":[[1.02,25.94]],"id":50639934}],"con":true,"img":false}]}
{"op":"mcm","clk":"11541219796","pt":1719503492317,"mc":[{"id":"1.230180129","rc":[{"atb":[[1.67,2]],"id":50639934}],"con":true,"img":false}]}
{"op":"mcm","clk":"11541219853","pt":1719503492930,"mc":[{"id":"1.230180129","rc":[{"atb":[[1.48,0]],"id":58821523}],"con":true,"img":false}]}
{"op":"mcm","clk":"11541219865","pt":1719503493037,"mc":[{"id":"1.230180129","rc":[{"atb":[[1.02,2]],"id":58821523}],"con":true,"img":false}]}
{"op":"mcm","clk":"11541219904","pt":1719503493393,"mc":[{"id":"1.230180129","rc":[{"atb":[[1.67,0]],"id":50639934}],"con":true,"img":false}]}
{"op":"mcm","clk":"11541219913","pt":1719503493495,"mc":[{"id":"1.230180129","rc":[{"atb":[[1.02,27.94]],"id":50639934}],"con":true,"img":false}]}
{"op":"mcm","clk":"11541219944","pt":1719503493906,"mc":[{"id":"1.230180129","rc":[{"atb":[[1.02,25.94]],"id":69213654}],"con":true,"img":false}]}
{"op":"mcm","clk":"11541219951","pt":1719503494011,"mc":[{"id":"1.230180129","rc":[{"atb":[[1.67,2]],"id":69213654}],"con":true,"img":false}]}
{"op":"mcm","clk":"11541220011","pt":1719503494728,"mc":[{"id":"1.230180129","rc":[{"atb":[[1.02,0]],"id":58821523}],"con":true,"img":false}]}
{"op":"mcm","clk":"11541220020","pt":1719503494833,"mc":[{"id":"1.230180129","rc":[{"atb":[[1.48,2]],"id":58821523}],"con":true,"img":false}]}
{"op":"mcm","clk":"11541220032","pt":1719503494933,"mc":[{"id":"1.230180129","rc":[{"atb":[[1.68,5.81]],"id":50639934}],"con":true,"img":false}]}
{"op":"mcm","clk":"11541220041","pt":1719503495036,"mc":[{"id":"1.230180129","rc":[{"atb":[[1.66,2.11]],"id":50639934}],"con":true,"img":false}]}
{"op":"mcm","clk":"11541220052","pt":1719503495087,"mc":[{"id":"1.230180129","rc":[{"atb":[[1.02,25.94],[1.69,4.24]],"id":50639934}],"con":true,"img":false}]}
{"op":"mcm","clk":"11541220060","pt":1719503495195,"mc":[{"id":"1.230180129","rc":[{"atb":[[1.67,2]],"id":50639934}],"con":true,"img":false}]}
{"op":"mcm","clk":"11541220091","pt":1719503495499,"mc":[{"id":"1.230180129","rc":[{"atb":[[1.67,0]],"id":69213654}],"con":true,"img":false}]}
{"op":"mcm","clk":"11541220101","pt":1719503495602,"mc":[{"id":"1.230180129","rc":[{"atb":[[1.02,27.94]],"id":69213654}],"con":true,"img":false}]}
{"op":"mcm","clk":"11541220147","pt":1719503496116,"mc":[{"id":"1.230180129","rc":[{"atb":[[1.48,0]],"id":58821523}],"con":true,"img":false}]}
{"op":"mcm","clk":"11541220159","pt":1719503496226,"mc":[{"id":"1.230180129","rc":[{"atb":[[1.02,2]],"id":58821523}],"con":true,"img":false}]}
{"op":"mcm","clk":"11541220207","pt":1719503496734,"mc":[{"id":"1.230180129","rc":[{"atb":[[1.67,0]],"id":50639934}],"con":true,"img":false}]}
{"op":"mcm","clk":"11541220218","pt":1719503496840,"mc":[{"id":"1.230180129","rc":[{"atb":[[1.7,2]],"id":50639934}],"con":true,"img":false}]}
{"op":"mcm","clk":"11541220230","pt":1719503496992,"mc":[{"id":"1.230180129","rc":[{"atb":[[1.02,25.94]],"id":69213654}],"con":true,"img":false}]}
{"op":"mcm","clk":"11541220240","pt":1719503497094,"mc":[{"id":"1.230180129","rc":[{"atb":[[1.67,2]],"id":69213654}],"con":true,"img":false}]}
{"op":"mcm","clk":"11541220288","pt":1719503497717,"mc":[{"id":"1.230180129","rc":[{"atb":[[1.02,0]],"id":58821523}],"con":true,"img":false}]}
{"op":"mcm","clk":"11541220298","pt":1719503497818,"mc":[{"id":"1.230180129","rc":[{"atb":[[1.48,2]],"id":58821523}],"con":true,"img":false}]}
{"op":"mcm","clk":"11541220336","pt":1719503498229,"mc":[{"id":"1.230180129","rc":[{"atb":[[1.67,0]],"id":69213654}],"con":true,"img":false}]}
{"op":"mcm","clk":"11541220346","pt":1719503498329,"mc":[{"id":"1.230180129","rc":[{"atb":[[1.02,27.94]],"id":69213654}],"con":true,"img":false}]}
{"op":"mcm","clk":"11541220408","pt":1719503498945,"mc":[{"id":"1.230180129","rc":[{"atb":[[1.48,0]],"id":58821523}],"con":true,"img":false}]}
{"op":"mcm","clk":"11541220418","pt":1719503499001,"mc":[{"id":"1.230180129","rc":[{"atb":[[1.02,2]],"id":58821523}],"con":true,"img":false}]}
{"op":"mcm","clk":"11541220450","pt":1719503499310,"mc":[{"id":"1.230180129","rc":[{"atb":[[1.02,25.94]],"id":69213654}],"con":true,"img":false}]}
{"op":"mcm","clk":"11541220456","pt":1719503499411,"mc":[{"id":"1.230180129","rc":[{"atb":[[1.67,2]],"id":69213654}],"con":true,"img":false}]}
{"op":"mcm","clk":"11541220502","pt":1719503499924,"mc":[{"id":"1.230180129","rc":[{"atb":[[1.02,0]],"id":58821523}],"con":true,"img":false}]}
{"op":"mcm","clk":"11541220510","pt":1719503500027,"mc":[{"id":"1.230180129","rc":[{"atb":[[1.48,2]],"id":58821523}],"con":true,"img":false}]}
{"op":"mcm","clk":"11541220544","pt":1719503500441,"mc":[{"id":"1.230180129","rc":[{"atb":[[1.67,0]],"id":69213654}],"con":true,"img":false}]}
{"op":"mcm","clk":"11541220553","pt":1719503500550,"mc":[{"id":"1.230180129","rc":[{"atb":[[1.02,27.94]],"id":69213654}],"con":true,"img":false}]}
{"op":"mcm","clk":"11541220606","pt":1719503501110,"mc":[{"id":"1.230180129","rc":[{"atb":[[1.48,0]],"id":58821523}],"con":true,"img":false}]}
{"op":"mcm","clk":"11541220611","pt":1719503501212,"mc":[{"id":"1.230180129","rc":[{"atb":[[1.02,2]],"id":58821523}],"con":true,"img":false}]}
{"op":"mcm","clk":"11541220634","pt":1719503501526,"mc":[{"id":"1.230180129","rc":[{"atb":[[1.02,25.94]],"id":69213654}],"con":true,"img":false}]}
{"op":"mcm","clk":"11541220642","pt":1719503501624,"mc":[{"id":"1.230180129","rc":[{"atb":[[1.67,2]],"id":69213654}],"con":true,"img":false}]}
{"op":"mcm","clk":"11541220687","pt":1719503502145,"mc":[{"id":"1.230180129","rc":[{"atb":[[1.02,0]],"id":58821523}],"con":true,"img":false}]}
{"op":"mcm","clk":"11541220699","pt":1719503502251,"mc":[{"id":"1.230180129","rc":[{"atb":[[1.48,2]],"id":58821523}],"con":true,"img":false}]}
{"op":"mcm","clk":"11541220736","pt":1719503502606,"mc":[{"id":"1.230180129","rc":[{"atb":[[1.67,0]],"id":69213654}],"con":true,"img":false}]}
{"op":"mcm","clk":"11541220745","pt":1719503502709,"mc":[{"id":"1.230180129","rc":[{"atb":[[1.02,27.94]],"id":69213654}],"con":true,"img":false}]}
{"op":"mcm","clk":"11541220810","pt":1719503503327,"mc":[{"id":"1.230180129","rc":[{"atb":[[1.48,0]],"id":58821523}],"con":true,"img":false}]}
{"op":"mcm","clk":"11541220822","pt":1719503503430,"mc":[{"id":"1.230180129","rc":[{"atb":[[1.02,2]],"id":58821523}],"con":true,"img":false}]}
{"op":"mcm","clk":"11541220859","pt":1719503503843,"mc":[{"id":"1.230180129","rc":[{"atb":[[1.02,25.94]],"id":69213654}],"con":true,"img":false}]}
{"op":"mcm","clk":"11541220871","pt":1719503503947,"mc":[{"id":"1.230180129","rc":[{"atb":[[1.67,2]],"id":69213654}],"con":true,"img":false}]}
{"op":"mcm","clk":"11541220962","pt":1719503504724,"mc":[{"id":"1.230180129","rc":[{"atb":[[1.02,0]],"id":58821523}],"con":true,"img":false}]}
{"op":"mcm","clk":"11541220973","pt":1719503504831,"mc":[{"id":"1.230180129","rc":[{"atb":[[1.48,2]],"id":58821523}],"con":true,"img":false}]}
{"op":"mcm","clk":"11541221002","pt":1719503505139,"mc":[{"id":"1.230180129","rc":[{"atb":[[1.67,0]],"id":69213654}],"con":true,"img":false}]}
{"op":"mcm","clk":"11541221012","pt":1719503505243,"mc":[{"id":"1.230180129","rc":[{"atb":[[1.02,27.94]],"id":69213654}],"con":true,"img":false}]}
{"op":"mcm","clk":"11541221054","pt":1719503505598,"mc":[{"id":"1.230180129","rc":[{"atb":[[1.48,0]],"id":58821523}],"con":true,"img":false}]}
{"op":"mcm","clk":"11541221066","pt":1719503505702,"mc":[{"id":"1.230180129","rc":[{"atb":[[1.02,2]],"id":58821523}],"con":true,"img":false}]}
{"op":"mcm","clk":"11541221093","pt":1719503506013,"mc":[{"id":"1.230180129","rc":[{"atb":[[1.02,25.94]],"id":69213654}],"con":true,"img":false}]}
{"op":"mcm","clk":"11541221104","pt":1719503506116,"mc":[{"id":"1.230180129","rc":[{"atb":[[1.67,2]],"id":69213654}],"con":true,"img":false}]}
{"op":"mcm","clk":"11541221169","pt":1719503506841,"mc":[{"id":"1.230180129","rc":[{"atb":[[1.02,0]],"id":58821523}],"con":true,"img":false}]}
{"op":"mcm","clk":"11541221181","pt":1719503506946,"mc":[{"id":"1.230180129","rc":[{"atb":[[1.48,2]],"id":58821523}],"con":true,"img":false}]}
{"op":"mcm","clk":"11541221234","pt":1719503507309,"mc":[{"id":"1.230180129","rc":[{"atb":[[1.67,0]],"id":69213654}],"con":true,"img":false}]}
{"op":"mcm","clk":"11541221245","pt":1719503507418,"mc":[{"id":"1.230180129","rc":[{"atb":[[1.02,27.94]],"id":69213654}],"con":true,"img":false}]}
{"op":"mcm","clk":"11541221301","pt":1719503508030,"mc":[{"id":"1.230180129","rc":[{"atb":[[1.48,0]],"id":58821523}],"con":true,"img":false}]}
{"op":"mcm","clk":"11541221313","pt":1719503508132,"mc":[{"id":"1.230180129","rc":[{"atb":[[1.02,2]],"id":58821523}],"con":true,"img":false}]}
{"op":"mcm","clk":"11541221346","pt":1719503508550,"mc":[{"id":"1.230180129","rc":[{"atb":[[1.02,25.94]],"id":69213654}],"con":true,"img":false}]}
{"op":"mcm","clk":"11541221356","pt":1719503508647,"mc":[{"id":"1.230180129","rc":[{"atb":[[1.67,2]],"id":69213654}],"con":true,"img":false}]}
{"op":"mcm","clk":"11541221404","pt":1719503509217,"mc":[{"id":"1.230180129","rc":[{"atb":[[1.02,0]],"id":58821523}],"con":true,"img":false}]}
{"op":"mcm","clk":"11541221414","pt":1719503509314,"mc":[{"id":"1.230180129","rc":[{"atb":[[1.48,2]],"id":58821523}],"con":true,"img":false}]}
{"op":"mcm","clk":"11541221432","pt":1719503509520,"mc":[{"id":"1.230180129","rc":[{"atb":[[1.67,0]],"id":69213654}],"con":true,"img":false}]}
{"op":"mcm","clk":"11541221440","pt":1719503509633,"mc":[{"id":"1.230180129","rc":[{"atb":[[1.02,27.94]],"id":69213654}],"con":true,"img":false}]}
{"op":"mcm","clk":"11541221786","pt":1719503513446,"mc":[{"id":"1.230180129","rc":[{"atb":[[1.68,0]],"id":50639934}],"con":true,"img":false}]}
{"op":"mcm","clk":"11541221808","pt":1719503513652,"mc":[{"id":"1.230180129","rc":[{"atb":[[1.72,5.48]],"id":50639934}],"con":true,"img":false}]}
{"op":"mcm","clk":"11541221827","pt":1719503513861,"mc":[{"id":"1.230180129","rc":[{"atb":[[1.73,4.24],[1.69,0]],"id":50639934}],"con":true,"img":false}]}
{"op":"mcm","clk":"11541222317","pt":1719503518572,"mc":[{"id":"1.230180129","rc":[{"atb":[[1.48,0]],"id":58821523}],"con":true,"img":false}]}
{"op":"mcm","clk":"11541222325","pt":1719503518675,"mc":[{"id":"1.230180129","rc":[{"atb":[[1.02,2]],"id":58821523}],"con":true,"img":false}]}
{"op":"mcm","clk":"11541222354","pt":1719503519033,"mc":[{"id":"1.230180129","rc":[{"atb":[[1.7,0]],"id":50639934}],"con":true,"img":false}]}
{"op":"mcm","clk":"11541222361","pt":1719503519135,"mc":[{"id":"1.230180129","rc":[{"atb":[[1.74,3]],"id":50639934}],"con":true,"img":false}]}
{"op":"mcm","clk":"11541222385","pt":1719503519454,"mc":[{"id":"1.230180129","rc":[{"atb":[[1.02,25.94]],"id":69213654}],"con":true,"img":false}]}
{"op":"mcm","clk":"11541222397","pt":1719503519558,"mc":[{"id":"1.230180129","rc":[{"atb":[[1.67,2]],"id":69213654}],"con":true,"img":false}]}
{"op":"mcm","clk":"11541222467","pt":1719503520375,"mc":[{"id":"1.230180129","rc":[{"atb":[[1.02,0]],"id":58821523}],"con":true,"img":false}]}
{"op":"mcm","clk":"11541222476","pt":1719503520484,"mc":[{"id":"1.230180129","rc":[{"atb":[[1.48,2]],"id":58821523}],"con":true,"img":false}]}
{"op":"mcm","clk":"11541222512","pt":1719503520739,"mc":[{"id":"1.230180129","rc":[{"atb":[[1.67,0]],"id":69213654}],"con":true,"img":false}]}
{"op":"mcm","clk":"11541222524","pt":1719503520843,"mc":[{"id":"1.230180129","rc":[{"atb":[[1.02,27.94]],"id":69213654}],"con":true,"img":false}]}
{"op":"mcm","clk":"11541222650","pt":1719503522035,"mc":[{"id":"1.230180129","rc":[{"atb":[[1.48,0]],"id":58821523}],"con":true,"img":false}]}
{"op":"mcm","clk":"11541222661","pt":1719503522136,"mc":[{"id":"1.230180129","rc":[{"atb":[[1.02,2]],"id":58821523}],"con":true,"img":false}]}
{"op":"mcm","clk":"11541222750","pt":1719503522963,"mc":[{"id":"1.230180129","rc":[{"atb":[[1.02,25.94]],"id":69213654}],"con":true,"img":false}]}
{"op":"mcm","clk":"11541222760","pt":1719503523068,"mc":[{"id":"1.230180129","rc":[{"atb":[[1.67,2]],"id":69213654}],"con":true,"img":false}]}
{"op":"mcm","clk":"11541222839","pt":1719503523751,"mc":[{"id":"1.230180129","rc":[{"atb":[[1.02,0]],"id":58821523}],"con":true,"img":false}]}
{"op":"mcm","clk":"11541222851","pt":1719503523842,"mc":[{"id":"1.230180129","rc":[{"atb":[[1.48,2]],"id":58821523}],"con":true,"img":false}]}
{"op":"mcm","clk":"11541222897","pt":1719503524260,"mc":[{"id":"1.230180129","rc":[{"atb":[[1.67,0]],"id":69213654}],"con":true,"img":false}]}
{"op":"mcm","clk":"11541222911","pt":1719503524364,"mc":[{"id":"1.230180129","rc":[{"atb":[[1.02,27.94]],"id":69213654}],"con":true,"img":false}]}
{"op":"mcm","clk":"11541222927","pt":1719503524466,"mc":[{"id":"1.230180129","rc":[{"atb":[[1.01,53.59]],"id":58821523},{"atl":[[1000,1.7]],"id":58821523},{"atb":[[1.01,1.7]],"id":50639934},{"atl":[[1000,1.94]],"id":50639934},{"atb":[[1.02,1.7]],"id":66050026},{"atl":[[1000,1.94]],"id":66050026}],"con":true,"img":false}]}
{"op":"mcm","clk":"11541222953","pt":1719503524673,"mc":[{"id":"1.230180129","rc":[{"atb":[[1.01,52.49]],"id":58821523},{"atl":[[1000,0.03]],"id":58821523},{"atb":[[1.01,0.39]],"id":50639934},{"atl":[[1000,0.26]],"id":50639934},{"atb":[[1.02,0.22]],"id":66050026},{"atl":[[1000,0.23]],"id":66050026}],"con":true,"img":false}]}
{"op":"mcm","clk":"11541222967","pt":1719503524880,"mc":[{"id":"1.230180129","rc":[{"atb":[[1.01,51.88]],"id":58821523},{"atl":[[1000,0]],"id":58821523},{"atb":[[1.01,0]],"id":50639934},{"atl":[[1000,0.23]],"id":50639934},{"atb":[[1.02,0]],"id":66050026}],"con":true,"img":false}]}
{"op":"mcm","clk":"11541222977","pt":1719503524982,"mc":[{"id":"1.230180129","rc":[{"atb":[[1.49,0.6]],"id":58821523},{"atl":[[9,0.03]],"id":58821523},{"atb":[[1.75,0.39]],"id":50639934},{"atl":[[13.5,0.02]],"id":50639934},{"atb":[[2.34,0.22]],"id":66050026}],"con":true,"img":false}]}
{"op":"mcm","clk":"11541222986","pt":1719503525037,"mc":[{"id":"1.230180129","rc":[{"atb":[[1.49,2.6],[1.47,0]],"id":58821523},{"atb":[[2.3,0],[2.34,2.22]],"id":66050026}],"con":true,"img":false}]}
{"op":"mcm","clk":"11541223034","pt":1719503525448,"mc":[{"id":"1.230180129","rc":[{"atb":[[1.48,0]],"id":58821523}],"con":true,"img":false}]}
{"op":"mcm","clk":"11541223042","pt":1719503525558,"mc":[{"id":"1.230180129","rc":[{"atb":[[1.02,2]],"id":58821523}],"con":true,"img":false}]}
{"op":"mcm","clk":"11541223051","pt":1719503525661,"mc":[{"id":"1.230180129","rc":[{"atb":[[1.49,0.6],[1.47,3.6]],"id":58821523}],"con":true,"img":false}]}
{"op":"mcm","clk":"11541223085","pt":1719503525965,"mc":[{"id":"1.230180129","rc":[{"atb":[[1.02,25.94]],"id":69213654}],"con":true,"img":false}]}
{"op":"mcm","clk":"11541223099","pt":1719503526070,"mc":[{"id":"1.230180129","rc":[{"atb":[[1.67,2]],"id":69213654}],"con":true,"img":false}]}
{"op":"mcm","clk":"11541223245","pt":1719503527359,"mc":[{"id":"1.230180129","rc":[{"atb":[[2.32,0]],"id":66050026}],"con":true,"img":false}]}
{"op":"mcm","clk":"11541223256","pt":1719503527465,"mc":[{"id":"1.230180129","rc":[{"atb":[[2.36,2],[2.16,3.22],[2.34,0.22]],"id":66050026}],"con":true,"img":false}]}
{"op":"mcm","clk":"11541223269","pt":1719503527572,"mc":[{"id":"1.230180129","rc":[{"atb":[[2.36,4],[2.16,0]],"id":66050026}],"con":true,"img":false}]}
{"op":"mcm","clk":"11541223280","pt":1719503527668,"mc":[{"id":"1.230180129","rc":[{"atb":[[2.36,2]],"id":66050026}],"con":true,"img":false}]}
{"op":"mcm","clk":"11541223289","pt":1719503527772,"mc":[{"id":"1.230180129","rc":[{"atb":[[2.34,3.22]],"id":66050026}],"con":true,"img":false}]}
{"op":"mcm","clk":"11541223304","pt":1719503527977,"mc":[{"id":"1.230180129","rc":[{"atb":[[1.02,0]],"id":58821523}],"con":true,"img":false}]}
{"op":"mcm","clk":"11541223314","pt":1719503528084,"mc":[{"id":"1.230180129","rc":[{"atb":[[1.48,2]],"id":58821523}],"con":true,"img":false}]}
{"op":"mcm","clk":"11541223395","pt":1719503528755,"mc":[{"id":"1.230180129","rc":[{"atb":[[1.67,0]],"id":69213654}],"con":true,"img":false}]}
{"op":"mcm","clk":"11541223407","pt":1719503528856,"mc":[{"id":"1.230180129","rc":[{"atb":[[1.02,27.94]],"id":69213654}],"con":true,"img":false}]}
{"op":"mcm","clk":"11541223486","pt":1719503529578,"mc":[{"id":"1.230180129","rc":[{"atb":[[1.48,0]],"id":58821523}],"con":true,"img":false}]}
{"op":"mcm","clk":"11541223498","pt":1719503529679,"mc":[{"id":"1.230180129","rc":[{"atb":[[1.02,2]],"id":58821523}],"con":true,"img":false}]}
{"op":"mcm","clk":"11541223559","pt":1719503530248,"mc":[{"id":"1.230180129","rc":[{"atb":[[1.02,25.94]],"id":69213654}],"con":true,"img":false}]}
{"op":"mcm","clk":"11541223569","pt":1719503530351,"mc":[{"id":"1.230180129","rc":[{"atb":[[1.67,2]],"id":69213654}],"con":true,"img":false}]}
{"op":"mcm","clk":"11541223897","pt":1719503533247,"mc":[{"id":"1.230180129","rc":[{"atb":[[1.02,0]],"id":58821523}],"con":true,"img":false}]}
{"op":"mcm","clk":"11541223906","pt":1719503533349,"mc":[{"id":"1.230180129","rc":[{"atb":[[1.48,2]],"id":58821523}],"con":true,"img":false}]}
{"op":"mcm","clk":"11541223914","pt":1719503533454,"mc":[{"id":"1.230180129","rc":[{"atb":[[1.49,2.6],[1.47,0]],"id":58821523}],"con":true,"img":false}]}
{"op":"mcm","clk":"11541223966","pt":1719503533971,"mc":[{"id":"1.230180129","rc":[{"atb":[[1.67,0]],"id":69213654}],"con":true,"img":false}]}
{"op":"mcm","clk":"11541223990","pt":1719503534179,"mc":[{"id":"1.230180129","rc":[{"atb":[[1.02,27.94]],"id":69213654}],"con":true,"img":false}]}
{"op":"mcm","clk":"11541224170","pt":1719503535983,"mc":[{"id":"1.230180129","rc":[{"atb":[[1.48,0]],"id":58821523}],"con":true,"img":false}]}
{"op":"mcm","clk":"11541224178","pt":1719503536086,"mc":[{"id":"1.230180129","rc":[{"atb":[[1.02,2]],"id":58821523}],"con":true,"img":false}]}
{"op":"mcm","clk":"11541224236","pt":1719503536659,"mc":[{"id":"1.230180129","rc":[{"atb":[[1.02,25.94]],"id":69213654}],"con":true,"img":false}]}
{"op":"mcm","clk":"11541224250","pt":1719503536758,"mc":[{"id":"1.230180129","rc":[{"atb":[[1.67,2]],"id":69213654}],"con":true,"img":false}]}
{"op":"mcm","clk":"11541224428","pt":1719503538464,"mc":[{"id":"1.230180129","rc":[{"atb":[[1.67,0]],"id":69213654}],"con":true,"img":false}]}
{"op":"mcm","clk":"11541224437","pt":1719503538564,"mc":[{"id":"1.230180129","rc":[{"atb":[[1.49,0.6],[1.47,3.6]],"id":58821523},{"atb":[[1.02,27.94]],"id":69213654}],"con":true,"img":false}]}
{"op":"mcm","clk":"11541224555","pt":1719503539750,"mc":[{"id":"1.230180129","rc":[{"atb":[[1.02,0]],"id":58821523}],"con":true,"img":false}]}
{"op":"mcm","clk":"11541224565","pt":1719503539853,"mc":[{"id":"1.230180129","rc":[{"atb":[[1.48,2]],"id":58821523}],"con":true,"img":false}]}
{"op":"mcm","clk":"11541224591","pt":1719503540169,"mc":[{"id":"1.230180129","rc":[{"atb":[[1.02,25.94]],"id":69213654}],"con":true,"img":false}]}
{"op":"mcm","clk":"11541224598","pt":1719503540274,"mc":[{"id":"1.230180129","rc":[{"atb":[[1.67,2]],"id":69213654}],"con":true,"img":false}]}
{"op":"mcm","clk":"11541224647","pt":1719503540989,"mc":[{"id":"1.230180129","rc":[{"atb":[[1.48,0]],"id":58821523}],"con":true,"img":false}]}
{"op":"mcm","clk":"11541224654","pt":1719503541092,"mc":[{"id":"1.230180129","rc":[{"atb":[[1.02,2]],"id":58821523}],"con":true,"img":false}]}
{"op":"mcm","clk":"11541224674","pt":1719503541408,"mc":[{"id":"1.230180129","rc":[{"atb":[[1.67,0]],"id":69213654}],"con":true,"img":false}]}
{"op":"mcm","clk":"11541224684","pt":1719503541503,"mc":[{"id":"1.230180129","rc":[{"atb":[[1.02,27.94]],"id":69213654}],"con":true,"img":false}]}
{"op":"mcm","clk":"11541224813","pt":1719503542799,"mc":[{"id":"1.230180129","rc":[{"atb":[[1.02,0]],"id":58821523}],"con":true,"img":false}]}
{"op":"mcm","clk":"11541224825","pt":1719503542894,"mc":[{"id":"1.230180129","rc":[{"atb":[[1.48,2]],"id":58821523}],"con":true,"img":false}]}
{"op":"mcm","clk":"11541224854","pt":1719503543200,"mc":[{"id":"1.230180129","rc":[{"atb":[[1.02,25.94]],"id":69213654}],"con":true,"img":false}]}
{"op":"mcm","clk":"11541224867","pt":1719503543303,"mc":[{"id":"1.230180129","rc":[{"atb":[[1.67,2]],"id":69213654}],"con":true,"img":false}]}
{"op":"mcm","clk":"11541224951","pt":1719503544079,"mc":[{"id":"1.230180129","rc":[{"atb":[[1.48,0]],"id":58821523}],"con":true,"img":false}]}
{"op":"mcm","clk":"11541224964","pt":1719503544182,"mc":[{"id":"1.230180129","rc":[{"atb":[[1.02,2]],"id":58821523}],"con":true,"img":false}]}
{"op":"mcm","clk":"11541225008","pt":1719503544594,"mc":[{"id":"1.230180129","rc":[{"atb":[[1.67,0]],"id":69213654}],"con":true,"img":false}]}
{"op":"mcm","clk":"11541225019","pt":1719503544697,"mc":[{"id":"1.230180129","rc":[{"atb":[[1.02,27.94]],"id":69213654}],"con":true,"img":false}]}
{"op":"mcm","clk":"11541225143","pt":1719503545987,"mc":[{"id":"1.230180129","rc":[{"atb":[[1.02,0]],"id":58821523}],"con":true,"img":false}]}
{"op":"mcm","clk":"11541225154","pt":1719503546089,"mc":[{"id":"1.230180129","rc":[{"atb":[[1.48,2]],"id":58821523}],"con":true,"img":false}]}
{"op":"mcm","clk":"11541225164","pt":1719503546191,"mc":[{"id":"1.230180129","rc":[{"atb":[[1.49,2.6],[1.47,0]],"id":58821523}],"con":true,"img":false}]}
{"op":"mcm","clk":"11541225187","pt":1719503546396,"mc":[{"id":"1.230180129","rc":[{"atb":[[1.02,25.94]],"id":69213654}],"con":true,"img":false}]}
{"op":"mcm","clk":"11541225198","pt":1719503546499,"mc":[{"id":"1.230180129","rc":[{"atb":[[1.67,2]],"id":69213654}],"con":true,"img":false}]}
{"op":"mcm","clk":"11541225352","pt":1719503547995,"mc":[{"id":"1.230180129","rc":[{"atb":[[1.48,0]],"id":58821523}],"con":true,"img":false}]}
{"op":"mcm","clk":"11541225365","pt":1719503548097,"mc":[{"id":"1.230180129","rc":[{"atb":[[1.02,2]],"id":58821523}],"con":true,"img":false}]}
{"op":"mcm","clk":"11541225389","pt":1719503548407,"mc":[{"id":"1.230180129","rc":[{"atb":[[1.67,0]],"id":69213654}],"con":true,"img":false}]}
{"op":"mcm","clk":"11541225400","pt":1719503548515,"mc":[{"id":"1.230180129","rc":[{"atb":[[1.02,27.94]],"id":69213654}],"con":true,"img":false}]}
{"op":"mcm","clk":"11541225558","pt":1719503550208,"mc":[{"id":"1.230180129","rc":[{"atb":[[1.02,25.94]],"id":69213654}],"con":true,"img":false}]}
{"op":"mcm","clk":"11541225572","pt":1719503550311,"mc":[{"id":"1.230180129","rc":[{"atb":[[1.67,2]],"id":69213654}],"con":true,"img":false}]}
{"op":"mcm","clk":"11541225682","pt":1719503551296,"mc":[{"id":"1.230180129","rc":[{"atb":[[1.47,3.6]],"id":58821523}],"con":true,"img":false}]}
{"op":"mcm","clk":"11541225694","pt":1719503551399,"mc":[{"id":"1.230180129","rc":[{"atb":[[1.49,0.6]],"id":58821523}],"con":true,"img":false}]}
{"op":"mcm","clk":"11541225704","pt":1719503551510,"mc":[{"id":"1.230180129","rc":[{"atb":[[1.67,0]],"id":69213654}],"con":true,"img":false}]}
{"op":"mcm","clk":"11541225715","pt":1719503551605,"mc":[{"id":"1.230180129","rc":[{"atb":[[1.02,27.94]],"id":69213654}],"con":true,"img":false}]}
{"op":"mcm","clk":"11541225780","pt":1719503552379,"mc":[{"id":"1.230180129","rc":[{"atb":[[1.02,0]],"id":58821523}],"con":true,"img":false}]}
{"op":"mcm","clk":"11541225784","pt":1719503552487,"mc":[{"id":"1.230180129","rc":[{"atb":[[1.48,2]],"id":58821523}],"con":true,"img":false}]}
{"op":"mcm","clk":"11541225821","pt":1719503552893,"mc":[{"id":"1.230180129","rc":[{"atb":[[1.02,25.94]],"id":69213654}],"con":true,"img":false}]}
{"op":"mcm","clk":"11541225831","pt":1719503552997,"mc":[{"id":"1.230180129","rc":[{"atb":[[1.67,2]],"id":69213654}],"con":true,"img":false}]}
{"op":"mcm","clk":"11541225880","pt":1719503553716,"mc":[{"id":"1.230180129","rc":[{"atb":[[1.49,2.6],[1.47,0]],"id":58821523}],"con":true,"img":false}]}
{"op":"mcm","clk":"11541225929","pt":1719503554385,"mc":[{"id":"1.230180129","rc":[{"atb":[[1.48,0]],"id":58821523}],"con":true,"img":false}]}
{"op":"mcm","clk":"11541225938","pt":1719503554489,"mc":[{"id":"1.230180129","rc":[{"atb":[[1.02,2]],"id":58821523}],"con":true,"img":false}]}
{"op":"mcm","clk":"11541225950","pt":1719503554591,"mc":[{"id":"1.230180129","rc":[{"atb":[[1.49,0.6],[1.47,3.6]],"id":58821523}],"con":true,"img":false}]}
{"op":"mcm","clk":"11541225970","pt":1719503554797,"mc":[{"id":"1.230180129","rc":[{"atb":[[1.67,0]],"id":69213654}],"con":true,"img":false}]}
{"op":"mcm","clk":"11541225981","pt":1719503554899,"mc":[{"id":"1.230180129","rc":[{"atb":[[1.02,27.94]],"id":69213654}],"con":true,"img":false}]}
{"op":"mcm","clk":"11541226056","pt":1719503555722,"mc":[{"id":"1.230180129","rc":[{"atb":[[1.02,0]],"id":58821523}],"con":true,"img":false}]}
{"op":"mcm","clk":"11541226067","pt":1719503555773,"mc":[{"id":"1.230180129","rc":[{"atb":[[1.48,2]],"id":58821523}],"con":true,"img":false}]}
{"op":"mcm","clk":"11541226077","pt":1719503555877,"mc":[{"id":"1.230180129","rc":[{"atb":[[1.49,2.6],[1.47,0]],"id":58821523}],"con":true,"img":false}]}
{"op":"mcm","clk":"11541226103","pt":1719503556185,"mc":[{"id":"1.230180129","rc":[{"atb":[[1.02,25.94]],"id":69213654}],"con":true,"img":false}]}
{"op":"mcm","clk":"11541226112","pt":1719503556289,"mc":[{"id":"1.230180129","rc":[{"atb":[[1.67,2]],"id":69213654}],"con":true,"img":false}]}
{"op":"mcm","clk":"11541226208","pt":1719503557527,"mc":[{"id":"1.230180129","rc":[{"atb":[[1.48,0]],"id":58821523}],"con":true,"img":false}]}
{"op":"mcm","clk":"11541226220","pt":1719503557586,"mc":[{"id":"1.230180129","rc":[{"atb":[[1.02,2]],"id":58821523}],"con":true,"img":false}]}
{"op":"mcm","clk":"11541226254","pt":1719503557993,"mc":[{"id":"1.230180129","rc":[{"atb":[[1.67,0]],"id":69213654}],"con":true,"img":false}]}
{"op":"mcm","clk":"11541226264","pt":1719503558094,"mc":[{"id":"1.230180129","rc":[{"atb":[[1.02,27.94]],"id":69213654}],"con":true,"img":false}]}
{"op":"mcm","clk":"11541226362","pt":1719503559125,"mc":[{"id":"1.230180129","rc":[{"atb":[[1.02,25.94]],"id":69213654}],"con":true,"img":false}]}
{"op":"mcm","clk":"11541226371","pt":1719503559230,"mc":[{"id":"1.230180129","rc":[{"atb":[[1.67,2]],"id":69213654}],"con":true,"img":false}]}
{"op":"mcm","clk":"11541226438","pt":1719503559904,"mc":[{"id":"1.230180129","rc":[{"atb":[[1.67,0]],"id":69213654}],"con":true,"img":false}]}
{"op":"mcm","clk":"11541226449","pt":1719503560003,"mc":[{"id":"1.230180129","rc":[{"atb":[[1.02,27.94]],"id":69213654}],"con":true,"img":false}]}
{"op":"mcm","clk":"11541226541","pt":1719503560947,"mc":[{"id":"1.230180129","rc":[{"atb":[[1.02,25.94]],"id":69213654}],"con":true,"img":false}]}
{"op":"mcm","clk":"11541226552","pt":1719503560992,"mc":[{"id":"1.230180129","rc":[{"atb":[[1.49,0.6],[1.47,3.6]],"id":58821523},{"atb":[[1.67,2]],"id":69213654}],"con":true,"img":false}]}
{"op":"mcm","clk":"11541226642","pt":1719503561925,"mc":[{"id":"1.230180129","rc":[{"atb":[[1.02,0]],"id":58821523}],"con":true,"img":false}]}
{"op":"mcm","clk":"11541226652","pt":1719503562036,"mc":[{"id":"1.230180129","rc":[{"atb":[[1.48,2]],"id":58821523}],"con":true,"img":false}]}
{"op":"mcm","clk":"11541226676","pt":1719503562290,"mc":[{"id":"1.230180129","rc":[{"atb":[[1.67,0]],"id":69213654}],"con":true,"img":false}]}
{"op":"mcm","clk":"11541226688","pt":1719503562395,"mc":[{"id":"1.230180129","rc":[{"atb":[[1.02,27.94]],"id":69213654}],"con":true,"img":false}]}
{"op":"mcm","clk":"11541226790","pt":1719503563331,"mc":[{"id":"1.230180129","rc":[{"atb":[[1.49,2.6],[1.48,0],[1.47,0]],"id":58821523}],"con":true,"img":false}]}
{"op":"mcm","clk":"11541226803","pt":1719503563425,"mc":[{"id":"1.230180129","rc":[{"atb":[[1.02,2]],"id":58821523}],"con":true,"img":false}]}
{"op":"mcm","clk":"11541226817","pt":1719503563535,"mc":[{"id":"1.230180129","rc":[{"atb":[[1.49,0.6],[1.47,3.6]],"id":58821523}],"con":true,"img":false}]}
{"op":"mcm","clk":"11541226874","pt":1719503564001,"mc":[{"id":"1.230180129","rc":[{"atb":[[1.02,25.94]],"id":69213654}],"con":true,"img":false}]}
{"op":"mcm","clk":"11541226893","pt":1719503564104,"mc":[{"id":"1.230180129","rc":[{"atb":[[1.67,2]],"id":69213654}],"con":true,"img":false}]}
{"op":"mcm","clk":"11541227024","pt":1719503565500,"mc":[{"id":"1.230180129","rc":[{"atb":[[1.02,0]],"id":58821523}],"con":true,"img":false}]}
{"op":"mcm","clk":"11541227035","pt":1719503565596,"mc":[{"id":"1.230180129","rc":[{"atb":[[1.48,2]],"id":58821523}],"con":true,"img":false}]}
{"op":"mcm","clk":"11541227077","pt":1719503566013,"mc":[{"id":"1.230180129","rc":[{"atb":[[1.67,0]],"id":69213654}],"con":true,"img":false}]}
{"op":"mcm","clk":"11541227086","pt":1719503566115,"mc":[{"id":"1.230180129","rc":[{"atb":[[1.02,27.94]],"id":69213654}],"con":true,"img":false}]}
{"op":"mcm","clk":"11541227209","pt":1719503567201,"mc":[{"id":"1.230180129","rc":[{"atb":[[1.48,0]],"id":58821523}],"con":true,"img":false}]}
{"op":"mcm","clk":"11541227224","pt":1719503567309,"mc":[{"id":"1.230180129","rc":[{"atb":[[1.02,2]],"id":58821523}],"con":true,"img":false}]}
{"op":"mcm","clk":"11541227251","pt":1719503567617,"mc":[{"id":"1.230180129","rc":[{"atb":[[1.49,0]],"id":58821523},{"atl":[[9,0]],"id":58821523},{"atb":[[1.75,0]],"id":50639934},{"atl":[[13.5,0]],"id":50639934},{"atb":[[2.34,3]],"id":66050026}],"con":true,"img":false}]}
{"op":"mcm","clk":"11541227259","pt":1719503567723,"mc":[{"id":"1.230180129","rc":[{"atb":[[1.02,25.94]],"id":69213654}],"con":true,"img":false}]}
{"op":"mcm","clk":"11541227269","pt":1719503567825,"mc":[{"id":"1.230180129","rc":[{"atb":[[1.67,2]],"id":69213654}],"con":true,"img":false}]}
{"op":"mcm","clk":"11541227334","pt":1719503568544,"mc":[{"id":"1.230180129","rc":[{"atb":[[1.67,0]],"id":69213654}],"con":true,"img":false}]}
{"op":"mcm","clk":"11541227346","pt":1719503568651,"mc":[{"id":"1.230180129","rc":[{"atb":[[1.02,27.94]],"id":69213654}],"con":true,"img":false}]}
{"op":"mcm","clk":"11541227483","pt":1719503569952,"mc":[{"id":"1.230180129","rc":[{"atb":[[1.02,25.94]],"id":69213654}],"con":true,"img":false}]}
{"op":"mcm","clk":"11541227499","pt":1719503570007,"mc":[{"id":"1.230180129","rc":[{"atb":[[1.67,2]],"id":69213654}],"con":true,"img":false}]}
{"op":"mcm","clk":"11541227588","pt":1719503570933,"mc":[{"id":"1.230180129","rc":[{"atb":[[1.67,0]],"id":69213654}],"con":true,"img":false}]}
{"op":"mcm","clk":"11541227598","pt":1719503571039,"mc":[{"id":"1.230180129","rc":[{"atb":[[1.02,27.94]],"id":69213654}],"con":true,"img":false}]}
{"op":"mcm","clk":"11541227731","pt":1719503572027,"mc":[{"id":"1.230180129","rc":[{"atb":[[1.02,25.94]],"id":69213654}],"con":true,"img":false}]}
{"op":"mcm","clk":"11541227740","pt":1719503572129,"mc":[{"id":"1.230180129","rc":[{"atb":[[1.67,2]],"id":69213654}],"con":true,"img":false}]}
{"op":"mcm","clk":"11541227814","pt":1719503572851,"mc":[{"id":"1.230180129","rc":[{"atb":[[1.67,0]],"id":69213654}],"con":true,"img":false}]}
{"op":"mcm","clk":"11541227824","pt":1719503572955,"mc":[{"id":"1.230180129","rc":[{"atb":[[1.02,27.94]],"id":69213654}],"con":true,"img":false}]}
{"op":"mcm","clk":"11541227907","pt":1719503573738,"mc":[{"id":"1.230180129","rc":[{"atb":[[1.02,25.94]],"id":69213654}],"con":true,"img":false}]}
{"op":"mcm","clk":"11541227919","pt":1719503573837,"mc":[{"id":"1.230180129","rc":[{"atb":[[1.67,2]],"id":69213654}],"con":true,"img":false}]}
{"op":"mcm","clk":"11541228029","pt":1719503575048,"mc":[{"id":"1.230180129","rc":[{"atb":[[1.67,0]],"id":69213654}],"con":true,"img":false}]}
{"op":"mcm","clk":"11541228038","pt":1719503575148,"mc":[{"id":"1.230180129","rc":[{"atb":[[1.02,27.94]],"id":69213654}],"con":true,"img":false}]}
{"op":"mcm","clk":"11541228181","pt":1719503576551,"mc":[{"id":"1.230180129","rc":[{"atb":[[1.02,25.94]],"id":69213654}],"con":true,"img":false}]}
{"op":"mcm","clk":"11541228197","pt":1719503576654,"mc":[{"id":"1.230180129","rc":[{"atb":[[1.67,2]],"id":69213654}],"con":true,"img":false}]}
{"op":"mcm","clk":"11541228298","pt":1719503577677,"mc":[{"id":"1.230180129","rc":[{"atb":[[1.67,0]],"id":69213654}],"con":true,"img":false}]}
{"op":"mcm","clk":"11541228307","pt":1719503577743,"mc":[{"id":"1.230180129","rc":[{"atb":[[1.02,27.94]],"id":69213654}],"con":true,"img":false}]}
{"op":"mcm","clk":"11541228385","pt":1719503578665,"mc":[{"id":"1.230180129","rc":[{"atb":[[1.02,25.94]],"id":69213654}],"con":true,"img":false}]}
{"op":"mcm","clk":"11541228394","pt":1719503578775,"mc":[{"id":"1.230180129","rc":[{"atb":[[1.67,2]],"id":69213654}],"con":true,"img":false}]}
{"op":"mcm","clk":"11541228484","pt":1719503579864,"mc":[{"id":"1.230180129","rc":[{"atb":[[1.67,0]],"id":69213654}],"con":true,"img":false}]}
{"op":"mcm","clk":"11541228493","pt":1719503579959,"mc":[{"id":"1.230180129","rc":[{"atb":[[1.02,27.94]],"id":69213654}],"con":true,"img":false}]}
{"op":"mcm","clk":"11541228615","pt":1719503581155,"mc":[{"id":"1.230180129","rc":[{"atb":[[1.02,25.94]],"id":69213654}],"con":true,"img":false}]}
{"op":"mcm","clk":"11541228626","pt":1719503581258,"mc":[{"id":"1.230180129","rc":[{"atb":[[1.67,2]],"id":69213654}],"con":true,"img":false}]}
{"op":"mcm","clk":"11541228890","pt":1719503583487,"mc":[{"id":"1.230180129","rc":[{"atb":[[1.67,0]],"id":69213654}],"con":true,"img":false}]}
{"op":"mcm","clk":"11541228901","pt":1719503583587,"mc":[{"id":"1.230180129","rc":[{"atb":[[1.02,27.94]],"id":69213654}],"con":true,"img":false}]}
{"op":"mcm","clk":"11541229052","pt":1719503585086,"mc":[{"id":"1.230180129","rc":[{"atb":[[1.02,25.94]],"id":69213654}],"con":true,"img":false}]}
{"op":"mcm","clk":"11541229065","pt":1719503585185,"mc":[{"id":"1.230180129","rc":[{"atl":[[7.2,9.98]],"id":51218587},{"atb":[[1.67,2]],"id":69213654}],"con":true,"img":false}]}
{"op":"mcm","clk":"11541229192","pt":1719503586498,"mc":[{"id":"1.230180129","rc":[{"atl":[[7.2,0]],"id":51218587}],"con":true,"img":false}]}
{"op":"mcm","clk":"11541229205","pt":1719503586579,"mc":[{"id":"1.230180129","rc":[{"atb":[[1.67,0]],"id":69213654}],"con":true,"img":false}]}
{"op":"mcm","clk":"11541229216","pt":1719503586683,"mc":[{"id":"1.230180129","rc":[{"atb":[[1.02,27.94]],"id":69213654}],"con":true,"img":false}]}
{"op":"mcm","clk":"11541229301","pt":1719503587466,"mc":[{"id":"1.230180129","rc":[{"atb":[[1.02,25.94]],"id":69213654}],"con":true,"img":false}]}
{"op":"mcm","clk":"11541229309","pt":1719503587565,"mc":[{"id":"1.230180129","rc":[{"atb":[[1.67,2]],"id":69213654}],"con":true,"img":false}]}
{"op":"mcm","clk":"11541229379","pt":1719503588385,"mc":[{"id":"1.230180129","rc":[{"atb":[[1.67,0]],"id":69213654}],"con":true,"img":false}]}
{"op":"mcm","clk":"11541229385","pt":1719503588493,"mc":[{"id":"1.230180129","rc":[{"atb":[[1.02,27.94]],"id":69213654}],"con":true,"img":false}]}
{"op":"mcm","clk":"11541229410","pt":1719503588753,"mc":[{"id":"1.230180129","rc":[{"atl":[[7.6,3.9]],"id":51218587}],"con":true,"img":false}]}
{"op":"mcm","clk":"11541229431","pt":1719503588966,"mc":[{"id":"1.230180129","rc":[{"atl":[[7.6,0]],"id":51218587}],"con":true,"img":false}]}
{"op":"mcm","clk":"11541229465","pt":1719503589272,"mc":[{"id":"1.230180129","rc":[{"atb":[[1.02,25.94]],"id":69213654}],"con":true,"img":false}]}
{"op":"mcm","clk":"11541229476","pt":1719503589372,"mc":[{"id":"1.230180129","rc":[{"atb":[[1.67,2]],"id":69213654}],"con":true,"img":false}]}
{"op":"mcm","clk":"11541229650","pt":1719503591086,"mc":[{"id":"1.230180129","rc":[{"atb":[[1.67,0]],"id":69213654}],"con":true,"img":false}]}
{"op":"mcm","clk":"11541229661","pt":1719503591180,"mc":[{"id":"1.230180129","rc":[{"atb":[[1.02,27.94]],"id":69213654}],"con":true,"img":false}]}
{"op":"mcm","clk":"11541229791","pt":1719503592589,"mc":[{"id":"1.230180129","rc":[{"atb":[[1.02,25.94]],"id":69213654}],"con":true,"img":false}]}
{"op":"mcm","clk":"11541229804","pt":1719503592669,"mc":[{"id":"1.230180129","rc":[{"atb":[[1.67,2]],"id":69213654}],"con":true,"img":false}]}
{"op":"mcm","clk":"11541229822","pt":1719503592875,"mc":[{"id":"1.230180129","rc":[{"atb":[[1.64,3.75]],"id":69213654}],"con":true,"img":false}]}
