{"op":"mcm","clk":"11536832975","pt":1719431775503,"mc":[{"id":"1.230180118","marketDefinition":{"bspMarket":true,"turnInPlayEnabled":false,"persistenceEnabled":false,"marketBaseRate":5.0,"eventId":"33376437","eventTypeId":"4339","numberOfWinners":1,"bettingType":"ODDS","marketType":"WIN","marketTime":"2024-06-27T14:29:00.000Z","suspendTime":"2024-06-27T14:29:00.000Z","bspReconciled":false,"complete":true,"inPlay":false,"crossMatching":false,"runnersVoidable":false,"numberOfActiveRunners":6,"betDelay":0,"status":"OPEN","runners":[{"status":"ACTIVE","sortPriority":1,"id":69475360,"name":"1. Flitwick Lopes"},{"status":"ACTIVE","sortPriority":2,"id":50772801,"name":"2. Dunbally Girl"},{"status":"ACTIVE","sortPriority":3,"id":69624671,"name":"3. Salacres Eleanor"},{"status":"ACTIVE","sortPriority":4,"id":62145089,"name":"4. Lamorna Lill Moo"},{"status":"ACTIVE","sortPriority":5,"id":60276470,"name":"5. Salems Decision"},{"status":"ACTIVE","sortPriority":6,"id":48534288,"name":"6. Fabulous Glamour"}],"regulators":["MR_INT"],"venue":"Towcester","countryCode":"GB","discountAllowed":false,"timezone":"Europe/London","openDate":"2024-06-27T13:33:00.000Z","version":5994767093,"name":"A6 500m","eventName":"Towcester 27th Jun"},"rc":[],"con":true,"img":false}]}
{"op":"mcm","clk":"11536833122","pt":1719431777502,"mc":[{"id":"1.230180118","marketDefinition":{"bspMarket":true,"turnInPlayEnabled":false,"persistenceEnabled":false,"marketBaseRate":5.0,"eventId":"33376437","eventTypeId":"4339","numberOfWinners":1,"bettingType":"ODDS","marketType":"WIN","marketTime":"2024-06-27T14:29:00.000Z","suspendTime":"2024-06-27T14:29:00.000Z","bspReconciled":false,"complete":true,"inPlay":false,"crossMatching":false,"runnersVoidable":false,"numberOfActiveRunners":6,"betDelay":0,"status":"OPEN","runners":[{"status":"ACTIVE","sortPriority":1,"id":69475360,"name":"1. Flitwick Lopes"},{"status":"ACTIVE","sortPriority":2,"id":50772801,"name":"2. Dunbally Girl"},{"status":"ACTIVE","sortPriority":3,"id":69624671,"name":"3. Salacres Eleanor"},{"status":"ACTIVE","sortPriority":4,"id":62145089,"name":"4. Lamorna Lill Moo"},{"status":"ACTIVE","sortPriority":5,"id":60276470,"name":"5. Salems Decision"},{"status":"ACTIVE","sortPriority":6,"id":48534288,"name":"6. Fabulous Glamour"}],"regulators":["MR_INT"],"venue":"Towcester","countryCode":"GB","discountAllowed":true,"timezone":"Europe/London","openDate":"2024-06-27T13:33:00.000Z","version":5994767093,"name":"A6 500m","eventName":"Towcester 27th Jun"},"rc":[],"con":true,"img":false}]}
{"op":"mcm","clk":"11537083964","pt":1719435434799,"mc":[{"id":"1.230180118","rc":[{"atb":[[1.03,17.28]],"id":50772801},{"atl":[[1000,0.84]],"id":50772801},{"spn":500.51,"spf":"NaN","id":50772801},{"atb":[[1.01,51.84]],"id":62145089},{"atl":[[990,0.84]],"id":62145089},{"spn":495.5,"spf":"NaN","id":62145089},{"atb":[[1.03,17.28]],"id":69624671},{"atl":[[1000,0.84]],"id":69624671},{"spn":500.51,"spf":"NaN","id":69624671},{"atb":[[1.03,17.28]],"id":60276470},{"atl":[[990,0.84]],"id":60276470},{"spn":495.51,"spf":"NaN","id":60276470},{"atb":[[1.03,17.28]],"id":48534288},{"atl":[[1000,0.84]],"id":48534288},{"spn":500.51,"spf":"NaN","id":48534288},{"atb":[[1.02,25.92]],"id":69475360},{"atl":[[1000,0.84]],"id":69475360},{"spn":500.51,"spf":"NaN","id":69475360}],"con":true,"img":false}]}
{"op":"mcm","clk":"11537233727","pt":1719437882650,"mc":[{"id":"1.230180118","marketDefinition":{"bspMarket":true,"turnInPlayEnabled":false,"persistenceEnabled":false,"marketBaseRate":5.0,"eventId":"33376437","eventTypeId":"4339","numberOfWinners":1,"bettingType":"ODDS","marketType":"WIN","marketTime":"2024-06-27T14:29:00.000Z","suspendTime":"2024-06-27T14:29:00.000Z","bspReconciled":false,"complete":true,"inPlay":false,"crossMatching":false,"runnersVoidable":false,"numberOfActiveRunners":6,"betDelay":0,"status":"OPEN","runners":[{"status":"ACTIVE","sortPriority":1,"id":69475360,"name":"1. Flitwick Lopes"},{"status":"ACTIVE","sortPriority":2,"id":50772801,"name":"2. Dunbally Girl"},{"status":"ACTIVE","sortPriority":3,"id":69624671,"name":"3. Salacres Eleanor"},{"status":"ACTIVE","sortPriority":4,"id":62145089,"name":"4. Lamorna Lill Moo"},{"status":"ACTIVE","sortPriority":5,"id":60276470,"name":"5. Salems Decision"},{"status":"ACTIVE","sortPriority":6,"id":48534288,"name":"6. Fabulous Glamour"}],"regulators":["MR_INT"],"venue":"Towcester","countryCode":"GB","discountAllowed":true,"timezone":"Europe/London","openDate":"2024-06-27T13:33:00.000Z","version":5994767093,"name":"A6 500m","eventName":"Towcester 27th Jun"},"rc":[{"atb":[[1.03,17.28]],"id":50772801},{"atl":[[1000,0.84]],"id":50772801},{"spn":500.51,"spf":"NaN","id":50772801},{"atb":[[1.01,51.85]],"id":62145089},{"atl":[[990,0.84]],"id":62145089},{"spn":495.5,"spf":"NaN","id":62145089},{"atb":[[1.03,17.28]],"id":69624671},{"atl":[[1000,0.84]],"id":69624671},{"spn":500.51,"spf":"NaN","id":69624671},{"atb":[[1.03,17.28]],"id":60276470},{"atl":[[990,0.84]],"id":60276470},{"spn":495.51,"spf":"NaN","id":60276470},{"atb":[[1.03,17.28]],"id":48534288},{"atl":[[1000,0.84]],"id":48534288},{"spn":500.51,"spf":"NaN","id":48534288},{"atb":[[1.02,25.92]],"id":69475360},{"atl":[[1000,0.84]],"id":69475360},{"spn":500.51,"spf":"NaN","id":69475360}],"con":true,"img":true}]}
{"op":"mcm","clk":"11537302500","pt":1719439038346,"mc":[{"id":"1.230180118","rc":[{"atb":[[1.03,17.28]],"id":50772801},{"atl":[[1000,0.23]],"id":50772801},{"atb":[[1.01,51.85]],"id":62145089},{"atl":[[990,0.23]],"id":62145089},{"atb":[[1.03,17.28]],"id":69624671},{"atl":[[1000,0.23]],"id":69624671},{"atb":[[1.03,17.28]],"id":60276470},{"atl":[[990,0.23]],"id":60276470},{"atb":[[1.03,17.28]],"id":48534288},{"atl":[[1000,0.23]],"id":48534288},{"atb":[[1.02,25.92]],"id":69475360},{"atl":[[1000,0.23]],"id":69475360}],"con":true,"img":false}]}
{"op":"mcm","clk":"11537574875","pt":1719443282701,"mc":[{"id":"1.230180118","marketDefinition":{"bspMarket":true,"turnInPlayEnabled":false,"persistenceEnabled":false,"marketBaseRate":5.0,"eventId":"33376437","eventTypeId":"4339","numberOfWinners":1,"bettingType":"ODDS","marketType":"WIN","marketTime":"2024-06-27T14:29:00.000Z","suspendTime":"2024-06-27T14:29:00.000Z","bspReconciled":false,"complete":true,"inPlay":false,"crossMatching":false,"runnersVoidable":false,"numberOfActiveRunners":6,"betDelay":0,"status":"OPEN","runners":[{"status":"ACTIVE","sortPriority":1,"id":69475360,"name":"1. Flitwick Lopes"},{"status":"ACTIVE","sortPriority":2,"id":50772801,"name":"2. Dunbally Girl"},{"status":"ACTIVE","sortPriority":3,"id":69624671,"name":"3. Salacres Eleanor"},{"status":"ACTIVE","sortPriority":4,"id":62145089,"name":"4. Lamorna Lill Moo"},{"status":"ACTIVE","sortPriority":5,"id":60276470,"name":"5. Salems Decision"},{"status":"ACTIVE","sortPriority":6,"id":48534288,"name":"6. Fabulous Glamour"}],"regulators":["MR_INT"],"venue":"Towcester","countryCode":"GB","discountAllowed":true,"timezone":"Europe/London","openDate":"2024-06-27T13:33:00.000Z","version":5994767093,"name":"A6 500m","eventName":"Towcester 27th Jun"},"rc":[{"atb":[[1.03,17.28]],"id":50772801},{"atl":[[1000,0.23]],"id":50772801},{"spn":500.51,"spf":"NaN","id":50772801},{"atb":[[1.01,51.85]],"id":62145089},{"atl":[[990,0.23]],"id":62145089},{"spn":495.5,"spf":"NaN","id":62145089},{"atb":[[1.03,17.28]],"id":69624671},{"atl":[[1000,0.23]],"id":69624671},{"spn":500.51,"spf":"NaN","id":69624671},{"atb":[[1.03,17.28]],"id":60276470},{"atl":[[990,0.23]],"id":60276470},{"spn":495.51,"spf":"NaN","id":60276470},{"atb":[[1.03,17.28]],"id":48534288},{"atl":[[1000,0.23]],"id":48534288},{"spn":500.51,"spf":"NaN","id":48534288},{"atb":[[1.02,25.92]],"id":69475360},{"atl":[[1000,0.23]],"id":69475360},{"spn":500.51,"spf":"NaN","id":69475360}],"con":true,"img":true}]}
{"op":"mcm","clk":"11537956495","pt":1719448682742,"mc":[{"id":"1.230180118","marketDefinition":{"bspMarket":true,"turnInPlayEnabled":false,"persistenceEnabled":false,"marketBaseRate":5.0,"eventId":"33376437","eventTypeId":"4339","numberOfWinners":1,"bettingType":"ODDS","marketType":"WIN","marketTime":"2024-06-27T14:29:00.000Z","suspendTime":"2024-06-27T14:29:00.000Z","bspReconciled":false,"complete":true,"inPlay":false,"crossMatching":false,"runnersVoidable":false,"numberOfActiveRunners":6,"betDelay":0,"status":"OPEN","runners":[{"status":"ACTIVE","sortPriority":1,"id":69475360,"name":"1. Flitwick Lopes"},{"status":"ACTIVE","sortPriority":2,"id":50772801,"name":"2. Dunbally Girl"},{"status":"ACTIVE","sortPriority":3,"id":69624671,"name":"3. Salacres Eleanor"},{"status":"ACTIVE","sortPriority":4,"id":62145089,"name":"4. Lamorna Lill Moo"},{"status":"ACTIVE","sortPriority":5,"id":60276470,"name":"5. Salems Decision"},{"status":"ACTIVE","sortPriority":6,"id":48534288,"name":"6. Fabulous Glamour"}],"regulators":["MR_INT"],"venue":"Towcester","countryCode":"GB","discountAllowed":true,"timezone":"Europe/London","openDate":"2024-06-27T13:33:00.000Z","version":5994767093,"name":"A6 500m","eventName":"Towcester 27th Jun"},"rc":[{"atb":[[1.03,17.28]],"id":50772801},{"atl":[[1000,0.23]],"id":50772801},{"spn":500.51,"spf":"NaN","id":50772801},{"atb":[[1.01,51.85]],"id":62145089},{"atl":[[990,0.23]],"id":62145089},{"spn":495.5,"spf":"NaN","id":62145089},{"atb":[[1.03,17.28]],"id":69624671},{"atl":[[1000,0.23]],"id":69624671},{"spn":500.51,"spf":"NaN","id":69624671},{"atb":[[1.03,17.28]],"id":60276470},{"atl":[[990,0.23]],"id":60276470},{"spn":495.51,"spf":"NaN","id":60276470},{"atb":[[1.03,17.28]],"id":48534288},{"atl":[[1000,0.23]],"id":48534288},{"spn":500.51,"spf":"NaN","id":48534288},{"atb":[[1.02,25.92]],"id":69475360},{"atl":[[1000,0.23]],"id":69475360},{"spn":500.51,"spf":"NaN","id":69475360}],"con":true,"img":true}]}
{"op":"mcm","clk":"11538172112","pt":1719454082685,"mc":[{"id":"1.230180118","marketDefinition":{"bspMarket":true,"turnInPlayEnabled":false,"persistenceEnabled":false,"marketBaseRate":5.0,"eventId":"33376437","eventTypeId":"4339","numberOfWinners":1,"bettingType":"ODDS","marketType":"WIN","marketTime":"2024-06-27T14:29:00.000Z","suspendTime":"2024-06-27T14:29:00.000Z","bspReconciled":false,"complete":true,"inPlay":false,"crossMatching":false,"runnersVoidable":false,"numberOfActiveRunners":6,"betDelay":0,"status":"OPEN","runners":[{"status":"ACTIVE","sortPriority":1,"id":69475360,"name":"1. Flitwick Lopes"},{"status":"ACTIVE","sortPriority":2,"id":50772801,"name":"2. Dunbally Girl"},{"status":"ACTIVE","sortPriority":3,"id":69624671,"name":"3. Salacres Eleanor"},{"status":"ACTIVE","sortPriority":4,"id":62145089,"name":"4. Lamorna Lill Moo"},{"status":"ACTIVE","sortPriority":5,"id":60276470,"name":"5. Salems Decision"},{"status":"ACTIVE","sortPriority":6,"id":48534288,"name":"6. Fabulous Glamour"}],"regulators":["MR_INT"],"venue":"Towcester","countryCode":"GB","discountAllowed":true,"timezone":"Europe/London","openDate":"2024-06-27T13:33:00.000Z","version":5994767093,"name":"A6 500m","eventName":"Towcester 27th Jun"},"rc":[{"atb":[[1.03,17.29]],"id":50772801},{"atl":[[1000,0.23]],"id":50772801},{"spn":500.51,"spf":"NaN","id":50772801},{"atb":[[1.01,51.86]],"id":62145089},{"atl":[[990,0.23]],"id":62145089},{"spn":495.5,"spf":"NaN","id":62145089},{"atb":[[1.03,17.29]],"id":69624671},{"atl":[[1000,0.23]],"id":69624671},{"spn":500.51,"spf":"NaN","id":69624671},{"atb":[[1.03,17.29]],"id":60276470},{"atl":[[990,0.23]],"id":60276470},{"spn":495.51,"spf":"NaN","id":60276470},{"atb":[[1.03,17.29]],"id":48534288},{"atl":[[1000,0.23]],"id":48534288},{"spn":500.51,"spf":"NaN","id":48534288},{"atb":[[1.02,25.93]],"id":69475360},{"atl":[[1000,0.23]],"id":69475360},{"spn":500.51,"spf":"NaN","id":69475360}],"con":true,"img":true}]}
{"op":"mcm","clk":"11538369779","pt":1719459482770,"mc":[{"id":"1.230180118","marketDefinition":{"bspMarket":true,"turnInPlayEnabled":false,"persistenceEnabled":false,"marketBaseRate":5.0,"eventId":"33376437","eventTypeId":"4339","numberOfWinners":1,"bettingType":"ODDS","marketType":"WIN","marketTime":"2024-06-27T14:29:00.000Z","suspendTime":"2024-06-27T14:29:00.000Z","bspReconciled":false,"complete":true,"inPlay":false,"crossMatching":false,"runnersVoidable":false,"numberOfActiveRunners":6,"betDelay":0,"status":"OPEN","runners":[{"status":"ACTIVE","sortPriority":1,"id":69475360,"name":"1. Flitwick Lopes"},{"status":"ACTIVE","sortPriority":2,"id":50772801,"name":"2. Dunbally Girl"},{"status":"ACTIVE","sortPriority":3,"id":69624671,"name":"3. Salacres Eleanor"},{"status":"ACTIVE","sortPriority":4,"id":62145089,"name":"4. Lamorna Lill Moo"},{"status":"ACTIVE","sortPriority":5,"id":60276470,"name":"5. Salems Decision"},{"status":"ACTIVE","sortPriority":6,"id":48534288,"name":"6. Fabulous Glamour"}],"regulators":["MR_INT"],"venue":"Towcester","countryCode":"GB","discountAllowed":true,"timezone":"Europe/London","openDate":"2024-06-27T13:33:00.000Z","version":5994767093,"name":"A6 500m","eventName":"Towcester 27th Jun"},"rc":[{"atb":[[1.03,17.29]],"id":50772801},{"atl":[[1000,0.23]],"id":50772801},{"spn":500.51,"spf":"NaN","id":50772801},{"atb":[[1.01,51.87]],"id":62145089},{"atl":[[990,0.23]],"id":62145089},{"spn":495.5,"spf":"NaN","id":62145089},{"atb":[[1.03,17.29]],"id":69624671},{"atl":[[1000,0.23]],"id":69624671},{"spn":500.51,"spf":"NaN","id":69624671},{"atb":[[1.03,17.29]],"id":60276470},{"atl":[[990,0.23]],"id":60276470},{"spn":495.51,"spf":"NaN","id":60276470},{"atb":[[1.03,17.29]],"id":48534288},{"atl":[[1000,0.23]],"id":48534288},{"spn":500.51,"spf":"NaN","id":48534288},{"atb":[[1.02,25.93]],"id":69475360},{"atl":[[1000,0.23]],"id":69475360},{"spn":500.51,"spf":"NaN","id":69475360}],"con":true,"img":true}]}
{"op":"mcm","clk":"11538596909","pt":1719464882714,"mc":[{"id":"1.230180118","marketDefinition":{"bspMarket":true,"turnInPlayEnabled":false,"persistenceEnabled":false,"marketBaseRate":5.0,"eventId":"33376437","eventTypeId":"4339","numberOfWinners":1,"bettingType":"ODDS","marketType":"WIN","marketTime":"2024-06-27T14:29:00.000Z","suspendTime":"2024-06-27T14:29:00.000Z","bspReconciled":false,"complete":true,"inPlay":false,"crossMatching":false,"runnersVoidable":false,"numberOfActiveRunners":6,"betDelay":0,"status":"OPEN","runners":[{"status":"ACTIVE","sortPriority":1,"id":69475360,"name":"1. Flitwick Lopes"},{"status":"ACTIVE","sortPriority":2,"id":50772801,"name":"2. Dunbally Girl"},{"status":"ACTIVE","sortPriority":3,"id":69624671,"name":"3. Salacres Eleanor"},{"status":"ACTIVE","sortPriority":4,"id":62145089,"name":"4. Lamorna Lill Moo"},{"status":"ACTIVE","sortPriority":5,"id":60276470,"name":"5. Salems Decision"},{"status":"ACTIVE","sortPriority":6,"id":48534288,"name":"6. Fabulous Glamour"}],"regulators":["MR_INT"],"venue":"Towcester","countryCode":"GB","discountAllowed":true,"timezone":"Europe/London","openDate":"2024-06-27T13:33:00.000Z","version":5994767093,"name":"A6 500m","eventName":"Towcester 27th Jun"},"rc":[{"atb":[[1.03,17.29]],"id":50772801},{"atl":[[1000,0.23]],"id":50772801},{"spn":500.51,"spf":"NaN","id":50772801},{"atb":[[1.01,51.86]],"id":62145089},{"atl":[[990,0.23]],"id":62145089},{"spn":495.5,"spf":"NaN","id":62145089},{"atb":[[1.03,17.29]],"id":69624671},{"atl":[[1000,0.23]],"id":69624671},{"spn":500.51,"spf":"NaN","id":69624671},{"atb":[[1.03,17.29]],"id":60276470},{"atl":[[990,0.23]],"id":60276470},{"spn":495.51,"spf":"NaN","id":60276470},{"atb":[[1.03,17.29]],"id":48534288},{"atl":[[1000,0.23]],"id":48534288},{"spn":500.51,"spf":"NaN","id":48534288},{"atb":[[1.02,25.93]],"id":69475360},{"atl":[[1000,0.23]],"id":69475360},{"spn":500.51,"spf":"NaN","id":69475360}],"con":true,"img":true}]}
{"op":"mcm","clk":"11538660801","pt":1719466164033,"mc":[{"id":"1.230180118","rc":[{"atb":[[1.03,17.29]],"id":50772801},{"atl":[[150,4]],"id":50772801},{"spn":75.51,"spf":"NaN","id":50772801},{"atb":[[1.01,51.86]],"id":62145089},{"atb":[[1.03,17.29]],"id":69624671},{"atb":[[1.03,17.29]],"id":60276470},{"atb":[[1.03,17.29]],"id":48534288},{"atb":[[1.02,25.93]],"id":69475360},{"atl":[[150,4]],"id":69475360},{"spn":75.51,"spf":"NaN","id":69475360}],"con":true,"img":false}]}
{"op":"mcm","clk":"11538660811","pt":1719466164136,"mc":[{"id":"1.230180118","rc":[{"atl":[[150,4]],"id":62145089},{"atl":[[150,4]],"id":69624671},{"atl":[[150,4]],"id":60276470},{"atl":[[150,4]],"id":48534288}],"con":true,"img":false}]}
{"op":"mcm","clk":"11538748551","pt":1719468203568,"mc":[{"id":"1.230180118","rc":[{"atb":[[2.08,13.32]],"id":50772801},{"spn":76.04,"spf":"NaN","id":50772801},{"atb":[[2.04,8.71]],"id":62145089},{"spn":76.02,"spf":"NaN","id":62145089},{"atb":[[2,12.82]],"id":69624671},{"spn":76.0,"spf":"NaN","id":69624671},{"atb":[[2.1,13.45]],"id":60276470},{"spn":76.05,"spf":"NaN","id":60276470},{"atb":[[2.1,8.97]],"id":48534288},{"spn":76.05,"spf":"NaN","id":48534288},{"atb":[[2.06,11.44]],"id":69475360},{"spn":76.03,"spf":"NaN","id":69475360}],"con":true,"img":false}]}
{"op":"mcm","clk":"11538751023","pt":1719468253871,"mc":[{"id":"1.230180118","rc":[{"atb":[[2.1,3.16]],"id":50772801}],"con":true,"img":false}]}
{"op":"mcm","clk":"11538751032","pt":1719468253973,"mc":[{"id":"1.230180118","rc":[{"atb":[[2.08,3.16]],"id":69475360}],"con":true,"img":false}]}
{"op":"mcm","clk":"11538751036","pt":1719468254075,"mc":[{"id":"1.230180118","rc":[{"atb":[[2.12,3.16]],"id":60276470}],"con":true,"img":false}]}
{"op":"mcm","clk":"11538751069","pt":1719468254792,"mc":[{"id":"1.230180118","rc":[{"atb":[[2.02,3.16]],"id":69624671}],"con":true,"img":false}]}
{"op":"mcm","clk":"11538751124","pt":1719468255865,"mc":[{"id":"1.230180118","rc":[{"atb":[[2.06,3.16]],"id":62145089}],"con":true,"img":false}]}
{"op":"mcm","clk":"11538751140","pt":1719468256275,"mc":[{"id":"1.230180118","rc":[{"atb":[[2.12,3.16]],"id":48534288}],"con":true,"img":false}]}
{"op":"mcm","clk":"11538752383","pt":1719468281744,"mc":[{"id":"1.230180118","marketDefinition":{"bspMarket":true,"turnInPlayEnabled":false,"persistenceEnabled":false,"marketBaseRate":5.0,"eventId":"33376437","eventTypeId":"4339","numberOfWinners":1,"bettingType":"ODDS","marketType":"WIN","marketTime":"2024-06-27T14:29:00.000Z","suspendTime":"2024-06-27T14:29:00.000Z","bspReconciled":false,"complete":true,"inPlay":false,"crossMatching":true,"runnersVoidable":false,"numberOfActiveRunners":6,"betDelay":0,"status":"OPEN","runners":[{"status":"ACTIVE","sortPriority":1,"id":69475360,"name":"1. Flitwick Lopes"},{"status":"ACTIVE","sortPriority":2,"id":50772801,"name":"2. Dunbally Girl"},{"status":"ACTIVE","sortPriority":3,"id":69624671,"name":"3. Salacres Eleanor"},{"status":"ACTIVE","sortPriority":4,"id":62145089,"name":"4. Lamorna Lill Moo"},{"status":"ACTIVE","sortPriority":5,"id":60276470,"name":"5. Salems Decision"},{"status":"ACTIVE","sortPriority":6,"id":48534288,"name":"6. Fabulous Glamour"}],"regulators":["MR_INT"],"venue":"Towcester","countryCode":"GB","discountAllowed":true,"timezone":"Europe/London","openDate":"2024-06-27T13:33:00.000Z","version":5994767093,"name":"A6 500m","eventName":"Towcester 27th Jun"},"rc":[],"con":true,"img":false}]}
{"op":"mcm","clk":"11538753195","pt":1719468296425,"mc":[{"id":"1.230180118","rc":[{"atb":[[2.1,6.55]],"id":50772801},{"spn":76.05,"spf":"NaN","id":50772801},{"spn":76.03,"spf":"NaN","id":62145089},{"spn":76.01,"spf":"NaN","id":69624671},{"spn":76.06,"spf":"NaN","id":60276470},{"spn":76.06,"spf":"NaN","id":48534288},{"spn":76.04,"spf":"NaN","id":69475360}],"con":true,"img":false}]}
{"op":"mcm","clk":"11538753203","pt":1719468296628,"mc":[{"id":"1.230180118","rc":[{"atb":[[2.02,6.55]],"id":69624671}],"con":true,"img":false}]}
{"op":"mcm","clk":"11538753210","pt":1719468296733,"mc":[{"id":"1.230180118","rc":[{"atb":[[2.08,6.55]],"id":69475360}],"con":true,"img":false}]}
{"op":"mcm","clk":"11538753221","pt":1719468296943,"mc":[{"id":"1.230180118","rc":[{"atb":[[2.12,6.55]],"id":60276470}],"con":true,"img":false}]}
{"op":"mcm","clk":"11538753226","pt":1719468297045,"mc":[{"id":"1.230180118","rc":[{"atb":[[2.06,6.55]],"id":62145089}],"con":true,"img":false}]}
{"op":"mcm","clk":"11538753291","pt":1719468298235,"mc":[{"id":"1.230180118","rc":[{"atb":[[2.12,6.55]],"id":48534288}],"con":true,"img":false}]}
{"op":"mcm","clk":"11538937131","pt":1719472046653,"mc":[{"id":"1.230180118","rc":[{"atb":[[1.03,17.27],[2.1,6.54],[2.08,13.32]],"id":50772801},{"atl":[[1000,0.23]],"id":50772801},{"atb":[[1.01,51.82],[2.06,6.54],[2.04,8.71]],"id":62145089},{"atl":[[990,0.23]],"id":62145089},{"atb":[[2,12.81],[2.02,6.54],[1.03,17.27]],"id":69624671},{"atl":[[21,4],[11.5,2],[1000,0.23],[15.5,3]],"id":69624671},{"spn":6.76,"spf":"NaN","id":69624671},{"atb":[[1.03,17.27],[2.12,6.54],[2.1,13.44]],"id":60276470},{"atl":[[990,0.23]],"id":60276470},{"atb":[[1.03,17.27],[2.12,6.54],[2.1,8.96]],"id":48534288},{"atl":[[1000,0.23]],"id":48534288},{"atb":[[2.06,11.43],[1.02,25.91],[2.08,6.54]],"id":69475360},{"atl":[[1000,0.23]],"id":69475360}],"con":true,"img":false}]}
{"op":"mcm","clk":"11538940497","pt":1719472109929,"mc":[{"id":"1.230180118","rc":[{"atb":[[2.08,0]],"id":50772801},{"atb":[[2.04,0]],"id":62145089},{"atb":[[2,0]],"id":69624671},{"atb":[[2.1,0]],"id":60276470},{"atb":[[2.1,0]],"id":48534288},{"atb":[[2.06,0]],"id":69475360}],"con":true,"img":false}]}
{"op":"mcm","clk":"11538940507","pt":1719472110027,"mc":[{"id":"1.230180118","rc":[{"atb":[[2.12,13.32]],"id":50772801},{"atb":[[2.08,8.71]],"id":62145089},{"atb":[[2.04,12.81]],"id":69624671},{"atb":[[2.14,13.44]],"id":60276470},{"atb":[[2.14,8.96]],"id":48534288},{"atb":[[2.1,11.43]],"id":69475360}],"con":true,"img":false}]}
{"op":"mcm","clk":"11538944164","pt":1719472167992,"mc":[{"id":"1.230180118","rc":[{"atb":[[2.02,3.38]],"id":69624671}],"con":true,"img":false}]}
{"op":"mcm","clk":"11538944182","pt":1719472168296,"mc":[{"id":"1.230180118","rc":[{"atb":[[2.08,3.38]],"id":69475360}],"con":true,"img":false}]}
{"op":"mcm","clk":"11538944199","pt":1719472168604,"mc":[{"id":"1.230180118","rc":[{"atb":[[2.1,3.38]],"id":50772801}],"con":true,"img":false}]}
{"op":"mcm","clk":"11538944231","pt":1719472169216,"mc":[{"id":"1.230180118","rc":[{"atb":[[2.06,3.38]],"id":62145089}],"con":true,"img":false}]}
{"op":"mcm","clk":"11538944242","pt":1719472169421,"mc":[{"id":"1.230180118","rc":[{"atb":[[2.12,3.38]],"id":60276470}],"con":true,"img":false}]}
{"op":"mcm","clk":"11538944279","pt":1719472169987,"mc":[{"id":"1.230180118","rc":[{"spn":76.06,"spf":"NaN","id":50772801},{"spn":76.04,"spf":"NaN","id":62145089},{"spn":6.77,"spf":"NaN","id":69624671},{"spn":76.07,"spf":"NaN","id":60276470},{"spn":76.07,"spf":"NaN","id":48534288},{"atb":[[2.12,3.16]],"id":69475360},{"spn":76.06,"spf":"NaN","id":69475360}],"con":true,"img":false}]}
{"op":"mcm","clk":"11538944333","pt":1719472170907,"mc":[{"id":"1.230180118","rc":[{"atb":[[2.1,3.16]],"id":62145089}],"con":true,"img":false}]}
{"op":"mcm","clk":"11538944383","pt":1719472171612,"mc":[{"id":"1.230180118","rc":[{"atb":[[2.06,3.16]],"id":69624671}],"con":true,"img":false}]}
{"op":"mcm","clk":"11538944513","pt":1719472173715,"mc":[{"id":"1.230180118","rc":[{"atb":[[2.12,3.38]],"id":48534288}],"con":true,"img":false}]}
{"op":"mcm","clk":"11538944554","pt":1719472174427,"mc":[{"id":"1.230180118","rc":[{"atb":[[2.14,3.16]],"id":50772801}],"con":true,"img":false}]}
{"op":"mcm","clk":"11538944642","pt":1719472175909,"mc":[{"id":"1.230180118","rc":[{"atb":[[2.16,3.16]],"id":60276470}],"con":true,"img":false}]}
{"op":"mcm","clk":"11538944665","pt":1719472176319,"mc":[{"id":"1.230180118","rc":[{"atb":[[2.16,3.16]],"id":48534288}],"con":true,"img":false}]}
{"op":"mcm","clk":"11538945155","pt":1719472184432,"mc":[{"id":"1.230180118","rc":[{"atb":[[2.08,0]],"id":69475360}],"con":true,"img":false}]}
{"op":"mcm","clk":"11538945218","pt":1719472185512,"mc":[{"id":"1.230180118","rc":[{"atb":[[2.06,0]],"id":62145089}],"con":true,"img":false}]}
{"op":"mcm","clk":"11538945258","pt":1719472186329,"mc":[{"id":"1.230180118","rc":[{"atb":[[2.12,0]],"id":60276470}],"con":true,"img":false}]}
{"op":"mcm","clk":"11538945328","pt":1719472187411,"mc":[{"id":"1.230180118","rc":[{"atb":[[2.02,0]],"id":69624671}],"con":true,"img":false}]}
{"op":"mcm","clk":"11538945374","pt":1719472188227,"mc":[{"id":"1.230180118","rc":[{"atb":[[2.1,0]],"id":50772801}],"con":true,"img":false}]}
{"op":"mcm","clk":"11538945385","pt":1719472188434,"mc":[{"id":"1.230180118","rc":[{"atb":[[2.12,0]],"id":48534288}],"con":true,"img":false}]}
{"op":"mcm","clk":"11538946372","pt":1719472204171,"mc":[{"id":"1.230180118","rc":[{"atb":[[2.12,6.54]],"id":69475360}],"con":true,"img":false}]}
{"op":"mcm","clk":"11538946491","pt":1719472206283,"mc":[{"id":"1.230180118","rc":[{"atb":[[2.16,6.54]],"id":60276470}],"con":true,"img":false}]}
{"op":"mcm","clk":"11538946543","pt":1719472207058,"mc":[{"id":"1.230180118","rc":[{"atb":[[2.1,6.54]],"id":62145089}],"con":true,"img":false}]}
{"op":"mcm","clk":"11538946700","pt":1719472209376,"mc":[{"id":"1.230180118","rc":[{"atb":[[2.16,6.54]],"id":48534288}],"con":true,"img":false}]}
{"op":"mcm","clk":"11538946750","pt":1719472210251,"mc":[{"id":"1.230180118","rc":[{"atb":[[2.06,6.54]],"id":69624671}],"con":true,"img":false}]}
{"op":"mcm","clk":"11538946782","pt":1719472210657,"mc":[{"id":"1.230180118","rc":[{"atb":[[2.14,6.54]],"id":50772801}],"con":true,"img":false}]}
{"op":"mcm","clk":"11539124097","pt":1719475682701,"mc":[{"id":"1.230180118","marketDefinition":{"bspMarket":true,"turnInPlayEnabled":false,"persistenceEnabled":false,"marketBaseRate":5.0,"eventId":"33376437","eventTypeId":"4339","numberOfWinners":1,"bettingType":"ODDS","marketType":"WIN","marketTime":"2024-06-27T14:29:00.000Z","suspendTime":"2024-06-27T14:29:00.000Z","bspReconciled":false,"complete":true,"inPlay":false,"crossMatching":true,"runnersVoidable":false,"numberOfActiveRunners":6,"betDelay":0,"status":"OPEN","runners":[{"status":"ACTIVE","sortPriority":1,"id":69475360,"name":"1. Flitwick Lopes"},{"status":"ACTIVE","sortPriority":2,"id":50772801,"name":"2. Dunbally Girl"},{"status":"ACTIVE","sortPriority":3,"id":69624671,"name":"3. Salacres Eleanor"},{"status":"ACTIVE","sortPriority":4,"id":62145089,"name":"4. Lamorna Lill Moo"},{"status":"ACTIVE","sortPriority":5,"id":60276470,"name":"5. Salems Decision"},{"status":"ACTIVE","sortPriority":6,"id":48534288,"name":"6. Fabulous Glamour"}],"regulators":["MR_INT"],"venue":"Towcester","countryCode":"GB","discountAllowed":true,"timezone":"Europe/London","openDate":"2024-06-27T13:33:00.000Z","version":5994767093,"name":"A6 500m","eventName":"Towcester 27th Jun"},"rc":[{"atb":[[1.03,17.28],[2.12,13.32],[2.14,6.55]],"id":50772801},{"atl":[[150,4],[1000,0.23]],"id":50772801},{"spn":76.07,"spf":"NaN","id":50772801},{"atb":[[1.01,51.84],[2.1,6.55],[2.08,8.71]],"id":62145089},{"atl":[[150,4],[990,0.23]],"id":62145089},{"spn":76.05,"spf":"NaN","id":62145089},{"atb":[[2.06,6.55],[1.03,17.28],[2.04,12.81]],"id":69624671},{"atl":[[150,4],[21,4],[11.5,2],[15.5,3],[1000,0.23]],"id":69624671},{"spn":6.78,"spf":"NaN","id":69624671},{"atb":[[1.03,17.28],[2.16,6.55],[2.14,13.45]],"id":60276470},{"atl":[[150,4],[990,0.23]],"id":60276470},{"spn":76.08,"spf":"NaN","id":60276470},{"atb":[[1.03,17.28],[2.16,6.55],[2.14,8.96]],"id":48534288},{"atl":[[150,4],[1000,0.23]],"id":48534288},{"spn":76.08,"spf":"NaN","id":48534288},{"atb":[[1.02,25.92],[2.12,6.55],[2.1,11.43]],"id":69475360},{"atl":[[150,4],[1000,0.23]],"id":69475360},{"spn":76.06,"spf":"NaN","id":69475360}],"con":true,"img":true}]}
{"op":"mcm","clk":"11539127821","pt":1719475709959,"mc":[{"id":"1.230180118","rc":[{"atb":[[1.03,17.28],[2.12,0],[2.14,6.55]],"id":50772801},{"atl":[[1000,0.23]],"id":50772801},{"spn":76.07,"spf":"NaN","id":50772801},{"atb":[[1.01,51.84],[2.1,6.55],[2.08,0]],"id":62145089},{"atl":[[990,0.23]],"id":62145089},{"spn":76.05,"spf":"NaN","id":62145089},{"atb":[[2.06,6.55],[1.03,17.28],[2.04,0]],"id":69624671},{"atl":[[1000,0.23]],"id":69624671},{"spn":6.78,"spf":"NaN","id":69624671},{"atb":[[1.03,17.28],[2.16,6.55],[2.14,0]],"id":60276470},{"atl":[[990,0.23]],"id":60276470},{"spn":76.08,"spf":"NaN","id":60276470},{"atb":[[1.03,17.28],[2.16,6.55],[2.14,0]],"id":48534288},{"atl":[[1000,0.23]],"id":48534288},{"spn":76.08,"spf":"NaN","id":48534288},{"atb":[[1.02,25.92],[2.12,6.55],[2.1,0]],"id":69475360},{"atl":[[1000,0.23]],"id":69475360}],"con":true,"img":false}]}
{"op":"mcm","clk":"11539127828","pt":1719475710064,"mc":[{"id":"1.230180118","rc":[{"atb":[[2.16,13.32]],"id":50772801},{"atb":[[2.12,8.71]],"id":62145089},{"atb":[[2.08,12.81]],"id":69624671},{"atb":[[2.18,13.45]],"id":60276470},{"atb":[[2.18,8.96]],"id":48534288},{"atb":[[2.14,11.43]],"id":69475360}],"con":true,"img":false}]}
{"op":"mcm","clk":"11539128372","pt":1719475716871,"mc":[{"id":"1.230180118","rc":[{"atb":[[2.16,3.38]],"id":60276470}],"con":true,"img":false}]}
{"op":"mcm","clk":"11539128440","pt":1719475718056,"mc":[{"id":"1.230180118","rc":[{"atb":[[2.14,3.38]],"id":50772801}],"con":true,"img":false}]}
{"op":"mcm","clk":"11539128447","pt":1719475718159,"mc":[{"id":"1.230180118","rc":[{"atb":[[2.06,3.38]],"id":69624671}],"con":true,"img":false}]}
{"op":"mcm","clk":"11539128522","pt":1719475719340,"mc":[{"id":"1.230180118","rc":[{"atb":[[2.18,3.16]],"id":50772801}],"con":true,"img":false}]}
{"op":"mcm","clk":"11539128529","pt":1719475719442,"mc":[{"id":"1.230180118","rc":[{"atb":[[2.12,3.38]],"id":69475360}],"con":true,"img":false}]}
{"op":"mcm","clk":"11539128555","pt":1719475719957,"mc":[{"id":"1.230180118","rc":[{"atb":[[2.1,3.16]],"id":69624671}],"con":true,"img":false}]}
{"op":"mcm","clk":"11539128567","pt":1719475720266,"mc":[{"id":"1.230180118","rc":[{"atb":[[2.2,3.16]],"id":60276470}],"con":true,"img":false}]}
{"op":"mcm","clk":"11539128648","pt":1719475721552,"mc":[{"id":"1.230180118","rc":[{"atb":[[2.1,3.38]],"id":62145089}],"con":true,"img":false}]}
{"op":"mcm","clk":"11539128668","pt":1719475721968,"mc":[{"id":"1.230180118","rc":[{"atb":[[2.16,3.38]],"id":48534288}],"con":true,"img":false}]}
{"op":"mcm","clk":"11539128680","pt":1719475722181,"mc":[{"id":"1.230180118","rc":[{"atb":[[2.14,3.16]],"id":62145089}],"con":true,"img":false}]}
{"op":"mcm","clk":"11539128742","pt":1719475723060,"mc":[{"id":"1.230180118","rc":[{"atb":[[2.16,3.16]],"id":69475360}],"con":true,"img":false}]}
{"op":"mcm","clk":"11539128781","pt":1719475723673,"mc":[{"id":"1.230180118","rc":[{"atb":[[2.2,3.16]],"id":48534288}],"con":true,"img":false}]}
{"op":"mcm","clk":"11539135271","pt":1719475824993,"mc":[{"id":"1.230180118","rc":[{"atb":[[2.14,0]],"id":50772801},{"spn":76.09,"spf":"NaN","id":50772801},{"spn":76.07,"spf":"NaN","id":62145089},{"spn":6.8,"spf":"NaN","id":69624671},{"spn":76.1,"spf":"NaN","id":60276470},{"spn":76.1,"spf":"NaN","id":48534288},{"spn":76.08,"spf":"NaN","id":69475360}],"con":true,"img":false}]}
{"op":"mcm","clk":"11539135298","pt":1719475825359,"mc":[{"id":"1.230180118","rc":[{"atb":[[2.16,0]],"id":48534288},{"atb":[[2.12,0]],"id":69475360}],"con":true,"img":false}]}
{"op":"mcm","clk":"11539135323","pt":1719475825665,"mc":[{"id":"1.230180118","rc":[{"atb":[[2.06,0]],"id":69624671}],"con":true,"img":false}]}
{"op":"mcm","clk":"11539135349","pt":1719475825970,"mc":[{"id":"1.230180118","rc":[{"atb":[[2.1,0]],"id":62145089}],"con":true,"img":false}]}
{"op":"mcm","clk":"11539135428","pt":1719475826898,"mc":[{"id":"1.230180118","rc":[{"atb":[[2.16,0]],"id":60276470}],"con":true,"img":false}]}
{"op":"mcm","clk":"11539135531","pt":1719475828385,"mc":[{"id":"1.230180118","rc":[{"atb":[[2.16,6.55]],"id":69475360}],"con":true,"img":false}]}
{"op":"mcm","clk":"11539135547","pt":1719475828699,"mc":[{"id":"1.230180118","rc":[{"atb":[[2.1,6.55]],"id":69624671}],"con":true,"img":false}]}
{"op":"mcm","clk":"11539135577","pt":1719475829105,"mc":[{"id":"1.230180118","rc":[{"atb":[[2.2,6.55]],"id":60276470}],"con":true,"img":false}]}
{"op":"mcm","clk":"11539135622","pt":1719475829772,"mc":[{"id":"1.230180118","rc":[{"atb":[[2.2,6.55]],"id":48534288}],"con":true,"img":false}]}
{"op":"mcm","clk":"11539135672","pt":1719475830801,"mc":[{"id":"1.230180118","rc":[{"atb":[[2.18,6.55]],"id":50772801}],"con":true,"img":false}]}
{"op":"mcm","clk":"11539135697","pt":1719475831210,"mc":[{"id":"1.230180118","rc":[{"atb":[[2.14,6.55]],"id":62145089}],"con":true,"img":false}]}
{"op":"mcm","clk":"11539200502","pt":1719476995297,"mc":[{"id":"1.230180118","rc":[{"atb":[[2.2,2]],"id":50772801},{"spn":76.1,"spf":"NaN","id":50772801}],"con":true,"img":false}]}
{"op":"mcm","clk":"11539341324","pt":1719479308863,"mc":[{"id":"1.230180118","rc":[{"atb":[[1.03,17.28],[2.18,6.54],[2.16,0]],"id":50772801},{"atb":[[1.01,51.83],[2.12,0],[2.14,6.54]],"id":62145089},{"atb":[[1.03,17.28],[2.1,6.54],[2.08,0]],"id":69624671},{"atb":[[1.03,17.28],[2.18,0],[2.2,6.54]],"id":60276470},{"atb":[[1.03,17.28],[2.18,0],[2.2,6.54]],"id":48534288},{"atb":[[1.02,25.91],[2.16,6.54],[2.14,0]],"id":69475360}],"con":true,"img":false}]}
{"op":"mcm","clk":"11539341329","pt":1719479308970,"mc":[{"id":"1.230180118","rc":[{"atb":[[2.2,15.32]],"id":50772801},{"atb":[[2.16,8.71]],"id":62145089},{"atb":[[2.12,12.81]],"id":69624671},{"atb":[[2.22,13.45]],"id":60276470},{"atb":[[2.22,8.96]],"id":48534288},{"atb":[[2.18,11.43]],"id":69475360}],"con":true,"img":false}]}
{"op":"mcm","clk":"11539347351","pt":1719479405401,"mc":[{"id":"1.230180118","rc":[{"spn":76.08,"spf":"NaN","id":62145089},{"spn":6.81,"spf":"NaN","id":69624671},{"spn":76.11,"spf":"NaN","id":60276470},{"atb":[[2.2,3.38]],"id":48534288},{"spn":76.11,"spf":"NaN","id":48534288},{"spn":76.09,"spf":"NaN","id":69475360}],"con":true,"img":false}]}
{"op":"mcm","clk":"11539347361","pt":1719479405608,"mc":[{"id":"1.230180118","rc":[{"atb":[[2.18,3.38]],"id":50772801}],"con":true,"img":false}]}
{"op":"mcm","clk":"11539347458","pt":1719479406800,"mc":[{"id":"1.230180118","rc":[{"atb":[[2.1,3.38]],"id":69624671}],"con":true,"img":false}]}
{"op":"mcm","clk":"11539347586","pt":1719479408652,"mc":[{"id":"1.230180118","rc":[{"atb":[[2.16,3.38]],"id":69475360}],"con":true,"img":false}]}
{"op":"mcm","clk":"11539347631","pt":1719479409321,"mc":[{"id":"1.230180118","rc":[{"atb":[[2.14,3.38]],"id":62145089}],"con":true,"img":false}]}
{"op":"mcm","clk":"11539347670","pt":1719479409998,"mc":[{"id":"1.230180118","rc":[{"atb":[[2.2,3.38]],"id":60276470}],"con":true,"img":false}]}
{"op":"mcm","clk":"11539350755","pt":1719479457578,"mc":[{"id":"1.230180118","rc":[{"atb":[[2.18,0]],"id":50772801},{"atb":[[2.14,0]],"id":62145089},{"atb":[[2.1,0]],"id":69624671},{"atb":[[2.2,0]],"id":60276470},{"atb":[[2.2,0]],"id":48534288},{"atb":[[2.16,0]],"id":69475360}],"con":true,"img":false}]}
{"op":"mcm","clk":"11539368372","pt":1719479715471,"mc":[{"id":"1.230180118","rc":[{"atb":[[2.24,3.16]],"id":48534288},{"spn":76.12,"spf":"NaN","id":48534288}],"con":true,"img":false}]}
{"op":"mcm","clk":"11539368406","pt":1719479715875,"mc":[{"id":"1.230180118","rc":[{"atb":[[2.18,3.16]],"id":62145089},{"atb":[[2.14,3.16]],"id":69624671}],"con":true,"img":false}]}
{"op":"mcm","clk":"11539368474","pt":1719479716646,"mc":[{"id":"1.230180118","rc":[{"atb":[[2.24,3.16]],"id":60276470}],"con":true,"img":false}]}
{"op":"mcm","clk":"11539368502","pt":1719479717160,"mc":[{"id":"1.230180118","rc":[{"atb":[[2.2,3.16]],"id":69475360}],"con":true,"img":false}]}
{"op":"mcm","clk":"11539368568","pt":1719479718039,"mc":[{"id":"1.230180118","rc":[{"atb":[[2.22,3.16]],"id":50772801}],"con":true,"img":false}]}
{"op":"mcm","clk":"11539370042","pt":1719479736869,"mc":[{"id":"1.230180118","rc":[{"atb":[[2.2,6.54]],"id":69475360}],"con":true,"img":false}]}
{"op":"mcm","clk":"11539370060","pt":1719479737185,"mc":[{"id":"1.230180118","rc":[{"atb":[[2.22,6.54]],"id":50772801},{"atb":[[2.14,6.54]],"id":69624671}],"con":true,"img":false}]}
{"op":"mcm","clk":"11539370082","pt":1719479737496,"mc":[{"id":"1.230180118","rc":[{"atb":[[2.24,6.54]],"id":60276470},{"atb":[[2.24,6.54]],"id":48534288}],"con":true,"img":false}]}
{"op":"mcm","clk":"11539370097","pt":1719479737773,"mc":[{"id":"1.230180118","rc":[{"atb":[[2.18,6.54]],"id":62145089}],"con":true,"img":false}]}
{"op":"mcm","clk":"11539409404","pt":1719480548980,"mc":[{"id":"1.230180118","rc":[{"spn":76.11,"spf":"NaN","id":50772801},{"spn":76.09,"spf":"NaN","id":62145089},{"spn":6.82,"spf":"NaN","id":69624671},{"spn":76.12,"spf":"NaN","id":60276470},{"atl":[[32,8]],"id":69475360},{"spn":17.1,"spf":"NaN","id":69475360}],"con":true,"img":false}]}
{"op":"mcm","clk":"11539409408","pt":1719480549072,"mc":[{"id":"1.230180118","rc":[{"atl":[[32,8],[55,12]],"id":62145089},{"atl":[[40,12],[23,8]],"id":69624671},{"atl":[[48,12],[28,8]],"id":60276470},{"atl":[[55,12]],"id":69475360}],"con":true,"img":false}]}
{"op":"mcm","clk":"11539440201","pt":1719481082674,"mc":[{"id":"1.230180118","marketDefinition":{"bspMarket":true,"turnInPlayEnabled":false,"persistenceEnabled":false,"marketBaseRate":5.0,"eventId":"33376437","eventTypeId":"4339","numberOfWinners":1,"bettingType":"ODDS","marketType":"WIN","marketTime":"2024-06-27T14:29:00.000Z","suspendTime":"2024-06-27T14:29:00.000Z","bspReconciled":false,"complete":true,"inPlay":false,"crossMatching":true,"runnersVoidable":false,"numberOfActiveRunners":6,"betDelay":0,"status":"OPEN","runners":[{"status":"ACTIVE","sortPriority":1,"id":69475360,"name":"1. Flitwick Lopes"},{"status":"ACTIVE","sortPriority":2,"id":50772801,"name":"2. Dunbally Girl"},{"status":"ACTIVE","sortPriority":3,"id":69624671,"name":"3. Salacres Eleanor"},{"status":"ACTIVE","sortPriority":4,"id":62145089,"name":"4. Lamorna Lill Moo"},{"status":"ACTIVE","sortPriority":5,"id":60276470,"name":"5. Salems Decision"},{"status":"ACTIVE","sortPriority":6,"id":48534288,"name":"6. Fabulous Glamour"}],"regulators":["MR_INT"],"venue":"Towcester","countryCode":"GB","discountAllowed":true,"timezone":"Europe/London","openDate":"2024-06-27T13:33:00.000Z","version":5994767093,"name":"A6 500m","eventName":"Towcester 27th Jun"},"rc":[{"atb":[[1.03,17.28],[2.22,6.54],[2.2,15.32]],"id":50772801},{"atl":[[150,4],[1000,0.23]],"id":50772801},{"spn":76.11,"spf":"NaN","id":50772801},{"atb":[[1.01,51.83],[2.18,6.54],[2.16,8.71]],"id":62145089},{"atl":[[32,8],[150,4],[55,12],[990,0.23]],"id":62145089},{"spn":17.09,"spf":"NaN","id":62145089},{"atb":[[1.03,17.28],[2.12,12.81],[2.14,6.54]],"id":69624671},{"atl":[[150,4],[40,12],[21,4],[11.5,2],[23,8],[15.5,3],[1000,0.23]],"id":69624671},{"spn":6.82,"spf":"NaN","id":69624671},{"atb":[[2.24,6.54],[1.03,17.28],[2.22,13.45]],"id":60276470},{"atl":[[150,4],[48,12],[28,8],[990,0.23]],"id":60276470},{"spn":15.12,"spf":"NaN","id":60276470},{"atb":[[2.24,6.54],[1.03,17.28],[2.22,8.96]],"id":48534288},{"atl":[[150,4],[1000,0.23]],"id":48534288},{"spn":76.12,"spf":"NaN","id":48534288},{"atb":[[1.02,25.91],[2.18,11.43],[2.2,6.54]],"id":69475360},{"atl":[[32,8],[150,4],[55,12],[1000,0.23]],"id":69475360},{"spn":17.1,"spf":"NaN","id":69475360}],"con":true,"img":true}]}
{"op":"mcm","clk":"11539545310","pt":1719482908468,"mc":[{"id":"1.230180118","rc":[{"atb":[[1.03,17.27],[2.22,6.54],[2.2,2]],"id":50772801},{"atb":[[1.01,51.83],[2.18,6.54],[2.16,0]],"id":62145089},{"spn":17.09,"spf":"NaN","id":62145089},{"atb":[[1.03,17.27],[2.12,0],[2.14,6.54]],"id":69624671},{"atb":[[2.24,6.54],[1.03,17.27],[2.22,0]],"id":60276470},{"spn":15.12,"spf":"NaN","id":60276470},{"atb":[[2.24,6.54],[1.03,17.27],[2.22,0]],"id":48534288},{"atb":[[1.02,25.91],[2.18,0],[2.2,6.54]],"id":69475360}],"con":true,"img":false}]}
{"op":"mcm","clk":"11539545316","pt":1719482908570,"mc":[{"id":"1.230180118","rc":[{"atb":[[2.24,13.32]],"id":50772801},{"atb":[[2.2,8.71]],"id":62145089},{"atb":[[2.16,12.81]],"id":69624671},{"atb":[[2.26,13.44]],"id":60276470},{"atb":[[2.26,8.96]],"id":48534288},{"atb":[[2.22,11.43]],"id":69475360}],"con":true,"img":false}]}
{"op":"mcm","clk":"11539550036","pt":1719482981284,"mc":[{"id":"1.230180118","rc":[{"spn":76.12,"spf":"NaN","id":50772801},{"spn":17.1,"spf":"NaN","id":62145089},{"spn":6.83,"spf":"NaN","id":69624671},{"spn":15.13,"spf":"NaN","id":60276470},{"atb":[[2.24,3.16]],"id":48534288},{"spn":76.13,"spf":"NaN","id":48534288},{"spn":17.11,"spf":"NaN","id":69475360}],"con":true,"img":false}]}
{"op":"mcm","clk":"11539550078","pt":1719482982101,"mc":[{"id":"1.230180118","rc":[{"atb":[[2.24,3.16]],"id":60276470}],"con":true,"img":false}]}
{"op":"mcm","clk":"11539550083","pt":1719482982211,"mc":[{"id":"1.230180118","rc":[{"atb":[[2.22,3.16]],"id":50772801}],"con":true,"img":false}]}
{"op":"mcm","clk":"11539550093","pt":1719482982463,"mc":[{"id":"1.230180118","rc":[{"atb":[[2.18,3.16]],"id":62145089}],"con":true,"img":false}]}
{"op":"mcm","clk":"11539550161","pt":1719482983608,"mc":[{"id":"1.230180118","rc":[{"atb":[[2.26,3.38]],"id":50772801},{"atb":[[2.2,3.16]],"id":69475360}],"con":true,"img":false}]}
{"op":"mcm","clk":"11539550219","pt":1719482984395,"mc":[{"id":"1.230180118","rc":[{"atb":[[2.14,3.16]],"id":69624671}],"con":true,"img":false}]}
{"op":"mcm","clk":"11539550241","pt":1719482984695,"mc":[{"id":"1.230180118","rc":[{"atb":[[2.28,3.38]],"id":48534288}],"con":true,"img":false}]}
{"op":"mcm","clk":"11539550326","pt":1719482986192,"mc":[{"id":"1.230180118","rc":[{"atb":[[2.18,3.38]],"id":69624671}],"con":true,"img":false}]}
{"op":"mcm","clk":"11539550393","pt":1719482986914,"mc":[{"id":"1.230180118","rc":[{"atb":[[2.28,3.38]],"id":60276470}],"con":true,"img":false}]}
{"op":"mcm","clk":"11539550418","pt":1719482987178,"mc":[{"id":"1.230180118","rc":[{"atb":[[2.24,3.38]],"id":69475360}],"con":true,"img":false}]}
{"op":"mcm","clk":"11539550427","pt":1719482987390,"mc":[{"id":"1.230180118","rc":[{"atb":[[2.22,3.38]],"id":62145089}],"con":true,"img":false}]}
{"op":"mcm","clk":"11539553496","pt":1719483030563,"mc":[{"id":"1.230180118","rc":[{"atb":[[2.22,0]],"id":50772801},{"atb":[[2.18,0]],"id":62145089},{"atb":[[2.14,0]],"id":69624671},{"atb":[[2.24,0]],"id":60276470},{"atb":[[2.24,0]],"id":48534288},{"atb":[[2.2,0]],"id":69475360}],"con":true,"img":false}]}
{"op":"mcm","clk":"11539573538","pt":1719483329018,"mc":[{"id":"1.230180118","rc":[{"spn":76.13,"spf":"NaN","id":50772801},{"spn":17.11,"spf":"NaN","id":62145089},{"atb":[[2.18,6.54]],"id":69624671},{"spn":6.84,"spf":"NaN","id":69624671},{"spn":15.14,"spf":"NaN","id":60276470},{"spn":76.14,"spf":"NaN","id":48534288},{"spn":17.12,"spf":"NaN","id":69475360}],"con":true,"img":false}]}
{"op":"mcm","clk":"11539573554","pt":1719483329227,"mc":[{"id":"1.230180118","rc":[{"atb":[[2.28,6.54]],"id":60276470}],"con":true,"img":false}]}
{"op":"mcm","clk":"11539573635","pt":1719483330354,"mc":[{"id":"1.230180118","rc":[{"atb":[[2.28,6.54]],"id":48534288}],"con":true,"img":false}]}
{"op":"mcm","clk":"11539573651","pt":1719483330560,"mc":[{"id":"1.230180118","rc":[{"atb":[[2.24,6.54]],"id":69475360}],"con":true,"img":false}]}
{"op":"mcm","clk":"11539573655","pt":1719483330667,"mc":[{"id":"1.230180118","rc":[{"atb":[[2.22,6.54]],"id":62145089}],"con":true,"img":false}]}
{"op":"mcm","clk":"11539573666","pt":1719483330716,"mc":[{"id":"1.230180118","rc":[{"atb":[[2.26,6.54]],"id":50772801}],"con":true,"img":false}]}
{"op":"mcm","clk":"11539634634","pt":1719484141632,"mc":[{"id":"1.230180118","rc":[{"atb":[[5,1]],"id":50772801},{"spn":77.5,"spf":"NaN","id":50772801},{"atb":[[5,1]],"id":62145089},{"spn":18.5,"spf":"NaN","id":62145089},{"atb":[[5,1]],"id":69624671},{"spn":8.25,"spf":"NaN","id":69624671},{"atb":[[3.75,1]],"id":60276470},{"spn":15.87,"spf":"NaN","id":60276470},{"atb":[[5,1]],"id":48534288},{"spn":77.5,"spf":"NaN","id":48534288},{"atb":[[3.75,1]],"id":69475360},{"spn":17.87,"spf":"NaN","id":69475360}],"con":true,"img":false}]}
{"op":"mcm","clk":"11539687378","pt":1719484868338,"mc":[{"id":"1.230180118","rc":[{"atb":[[4.1,6]],"id":50772801},{"atb":[[3.55,6]],"id":62145089},{"atb":[[3.3,6]],"id":69624671},{"atb":[[2.86,6]],"id":60276470},{"atb":[[3.75,6]],"id":48534288},{"atb":[[2.44,6]],"id":69475360}],"con":true,"img":false}]}
{"op":"mcm","clk":"11539688063","pt":1719484877166,"mc":[{"id":"1.230180118","rc":[{"atb":[[2.26,3.16]],"id":50772801},{"atb":[[2.22,3.16]],"id":62145089},{"atb":[[2.18,3.16]],"id":69624671},{"atb":[[2.28,3.16]],"id":60276470},{"atb":[[2.28,3.16]],"id":48534288}],"con":true,"img":false}]}
{"op":"mcm","clk":"11539689209","pt":1719484891381,"mc":[{"id":"1.230180118","rc":[{"atb":[[2.26,0]],"id":50772801},{"atb":[[2.22,0]],"id":62145089},{"atb":[[2.18,0]],"id":69624671},{"atb":[[2.28,0]],"id":60276470},{"atb":[[2.28,0]],"id":48534288}],"con":true,"img":false}]}
{"op":"mcm","clk":"11539709203","pt":1719485135923,"mc":[{"id":"1.230180118","rc":[{"atb":[[2.12,89.29],[1.51,196.08]],"id":50772801},{"atb":[[2.12,89.29],[1.51,196.08]],"id":62145089},{"atb":[[2.12,89.29],[1.51,196.08]],"id":69624671},{"atb":[[1.51,196.08]],"id":60276470},{"atb":[[2.12,89.29],[1.51,196.08]],"id":48534288},{"atb":[[1.51,196.08]],"id":69475360}],"con":true,"img":false}]}
{"op":"mcm","clk":"11539785006","pt":1719486168581,"mc":[{"id":"1.230180118","rc":[{"atb":[[2.24,13.32],[1.03,17.28]],"id":50772801},{"atb":[[1.01,51.83],[2.2,8.71]],"id":62145089},{"atb":[[5,0],[1.03,17.28],[2.16,12.81],[4.7,1]],"id":69624671},{"spn":8.1,"spf":"NaN","id":69624671},{"atb":[[1.03,17.28],[2.26,13.45],[3.9,1],[3.75,0]],"id":60276470},{"spn":15.95,"spf":"NaN","id":60276470},{"atb":[[1.03,17.28],[2.26,8.96]],"id":48534288},{"atb":[[2.24,6.54],[2.22,11.43],[1.02,25.91],[3.9,1],[3.75,0]],"id":69475360},{"spn":17.95,"spf":"NaN","id":69475360}],"con":true,"img":false}]}
{"op":"mcm","clk":"11539817146","pt":1719486504234,"mc":[{"id":"1.230180118","rc":[{"atb":[[2.22,0]],"id":69475360}],"con":true,"img":false}]}
{"op":"mcm","clk":"11539817159","pt":1719486504338,"mc":[{"id":"1.230180118","rc":[{"atb":[[2.26,11.43]],"id":69475360}],"con":true,"img":false}]}
{"op":"mcm","clk":"11539819138","pt":1719486525955,"mc":[{"id":"1.230180118","rc":[{"atb":[[2.24,3.38]],"id":69475360}],"con":true,"img":false}]}
{"op":"mcm","clk":"11539819184","pt":1719486526477,"mc":[{"id":"1.230180118","rc":[{"atb":[[2.28,3.16]],"id":69475360}],"con":true,"img":false}]}
{"op":"mcm","clk":"11539825697","pt":1719486603964,"mc":[{"id":"1.230180118","rc":[{"atb":[[2.24,0]],"id":69475360}],"con":true,"img":false}]}
{"op":"mcm","clk":"11539826057","pt":1719486608753,"mc":[{"id":"1.230180118","rc":[{"atb":[[2.28,6.54]],"id":69475360}],"con":true,"img":false}]}
{"op":"mcm","clk":"11539840446","pt":1719486803718,"mc":[{"id":"1.230180118","rc":[{"atb":[[2.26,0]],"id":69475360}],"con":true,"img":false}]}
{"op":"mcm","clk":"11539840456","pt":1719486803817,"mc":[{"id":"1.230180118","rc":[{"atb":[[2.3,11.43]],"id":69475360}],"con":true,"img":false}]}
{"op":"mcm","clk":"11539841590","pt":1719486822651,"mc":[{"id":"1.230180118","rc":[{"atb":[[2.28,3.38]],"id":69475360}],"con":true,"img":false}]}
{"op":"mcm","clk":"11539843226","pt":1719486846984,"mc":[{"id":"1.230180118","rc":[{"atb":[[2.28,0]],"id":69475360}],"con":true,"img":false}]}
{"op":"mcm","clk":"11539849057","pt":1719486928987,"mc":[{"id":"1.230180118","rc":[{"atb":[[2.32,3.38]],"id":69475360}],"con":true,"img":false}]}
{"op":"mcm","clk":"11539850438","pt":1719486946326,"mc":[{"id":"1.230180118","rc":[{"atb":[[2.32,6.54]],"id":69475360}],"con":true,"img":false}]}
{"op":"mcm","clk":"11539914697","pt":1719487755316,"mc":[{"id":"1.230180118","rc":[{"atl":[[34,18]],"id":69624671}],"con":true,"img":false}]}
{"op":"mcm","clk":"11540014283","pt":1719488998168,"mc":[{"id":"1.230180118","rc":[{"atb":[[1.16,150]],"id":50772801},{"atl":[[390,2]],"id":50772801},{"atl":[[270,2]],"id":62145089},{"atl":[[550,2]],"id":69624671},{"atl":[[560,2]],"id":60276470},{"atl":[[500,2]],"id":48534288},{"atb":[[1.16,150]],"id":69475360},{"atl":[[370,2]],"id":69475360}],"con":true,"img":false}]}
{"op":"mcm","clk":"11540014296","pt":1719488998322,"mc":[{"id":"1.230180118","rc":[{"atb":[[1.16,150]],"id":62145089},{"atb":[[1.16,150]],"id":69624671},{"atb":[[1.16,150]],"id":60276470},{"atb":[[1.16,150]],"id":48534288}],"con":true,"img":false}]}
{"op":"mcm","clk":"11540136200","pt":1719490399249,"mc":[{"id":"1.230180118","rc":[{"atb":[[2.32,6.54],[2.3,0]],"id":69475360}],"con":true,"img":false}]}
{"op":"mcm","clk":"11540136210","pt":1719490399347,"mc":[{"id":"1.230180118","rc":[{"atb":[[2.34,11.43]],"id":69475360}],"con":true,"img":false}]}
{"op":"mcm","clk":"11540141792","pt":1719490454211,"mc":[{"id":"1.230180118","rc":[{"atb":[[2.32,3.16]],"id":69475360}],"con":true,"img":false}]}
{"op":"mcm","clk":"11540141916","pt":1719490455203,"mc":[{"id":"1.230180118","rc":[{"atb":[[2.36,3.38]],"id":69475360}],"con":true,"img":false}]}
{"op":"mcm","clk":"11540144579","pt":1719490480759,"mc":[{"id":"1.230180118","rc":[{"atb":[[2.32,0]],"id":69475360}],"con":true,"img":false}]}
{"op":"mcm","clk":"11540145871","pt":1719490493045,"mc":[{"id":"1.230180118","rc":[{"atb":[[2.36,6.54]],"id":69475360}],"con":true,"img":false}]}
{"op":"mcm","clk":"11540326927","pt":1719493055931,"mc":[{"id":"1.230180118","rc":[{"atb":[[1.02,76.13]],"id":50772801},{"atl":[[970,0.87]],"id":50772801},{"atb":[[1.03,139.58]],"id":62145089},{"atl":[[980,1.54]],"id":62145089},{"atb":[[1.03,178.85]],"id":69624671},{"atl":[[970,1.88]],"id":69624671},{"atb":[[1.03,128.94]],"id":60276470},{"atl":[[960,1.28]],"id":60276470},{"atb":[[1.03,163.63]],"id":48534288},{"atl":[[970,0.96]],"id":48534288},{"atb":[[1.04,97.28]],"id":69475360},{"atl":[[990,2.13]],"id":69475360}],"con":true,"img":false}]}
{"op":"mcm","clk":"11540478257","pt":1719494977193,"mc":[{"id":"1.230180118","rc":[{"atb":[[2.24,13.33],[1.03,17.3],[1.02,76.22]],"id":50772801},{"atl":[[970,0.87],[1000,0.23]],"id":50772801},{"atb":[[1.01,51.9],[1.03,139.74],[2.2,8.72]],"id":62145089},{"atl":[[980,1.54],[990,0.23]],"id":62145089},{"atb":[[1.03,179.07],[2.16,12.83]],"id":69624671},{"atl":[[970,1.88],[1000,0.23]],"id":69624671},{"atb":[[1.03,129.1],[2.26,13.46]],"id":60276470},{"atl":[[960,1.28],[990,0.23]],"id":60276470},{"atb":[[1.03,163.82],[2.26,8.97]],"id":48534288},{"atl":[[150,27],[970,0.96],[1000,0.23]],"id":48534288},{"atb":[[2.36,6.54],[1.02,25.95],[2.34,11.45],[1.04,97.39]],"id":69475360},{"atl":[[990,2.13],[1000,0.23]],"id":69475360}],"con":true,"img":false}]}
{"op":"mcm","clk":"11540486112","pt":1719495066947,"mc":[{"id":"1.230180118","rc":[{"atl":[[150,24]],"id":48534288}],"con":true,"img":false}]}
{"op":"mcm","clk":"11540491691","pt":1719495128057,"mc":[{"id":"1.230180118","rc":[{"spl":[[1.01,1]],"id":69624671},{"spn":4.7,"spf":1.0,"id":69624671}],"con":true,"img":false}]}
{"op":"mcm","clk":"11540497014","pt":1719495183459,"mc":[{"id":"1.230180118","rc":[{"atl":[[150,15]],"id":48534288}],"con":true,"img":false}]}
{"op":"mcm","clk":"11540504777","pt":1719495272772,"mc":[{"id":"1.230180118","rc":[{"atl":[[150,26]],"id":48534288}],"con":true,"img":false}]}
{"op":"mcm","clk":"11540522511","pt":1719495480484,"mc":[{"id":"1.230180118","rc":[{"atl":[[150,34]],"id":48534288}],"con":true,"img":false}]}
{"op":"mcm","clk":"11540547521","pt":1719495770523,"mc":[{"id":"1.230180118","rc":[{"atl":[[150,12]],"id":48534288}],"con":true,"img":false}]}
{"op":"mcm","clk":"11540550233","pt":1719495798673,"mc":[{"id":"1.230180118","rc":[{"atl":[[150,10]],"id":48534288}],"con":true,"img":false}]}
{"op":"mcm","clk":"11540567591","pt":1719495980152,"mc":[{"id":"1.230180118","rc":[{"atl":[[150,26]],"id":48534288}],"con":true,"img":false}]}
{"op":"mcm","clk":"11540568531","pt":1719495989883,"mc":[{"id":"1.230180118","rc":[{"atl":[[150,22]],"id":48534288}],"con":true,"img":false}]}
{"op":"mcm","clk":"11540604458","pt":1719496356720,"mc":[{"id":"1.230180118","rc":[{"atl":[[27,1.61]],"id":60276470},{"spn":15.45,"spf":"NaN","id":60276470}],"con":true,"img":false}]}
{"op":"mcm","clk":"11540645165","pt":1719496834988,"mc":[{"id":"1.230180118","rc":[{"atb":[[2.24,13.33],[1.03,17.29],[1.02,76.19]],"id":50772801},{"atl":[[970,0.87],[1000,0.23]],"id":50772801},{"atb":[[1.01,51.87],[1.03,139.68],[2.2,8.71]],"id":62145089},{"atl":[[980,1.54],[990,0.23]],"id":62145089},{"atb":[[1.03,178.99],[2.16,12.82]],"id":69624671},{"atl":[[970,1.88],[1000,0.23]],"id":69624671},{"atb":[[1.03,129.04],[2.26,13.46]],"id":60276470},{"atl":[[960,1.28],[990,0.23]],"id":60276470},{"atb":[[1.03,163.75],[2.26,8.97]],"id":48534288},{"atl":[[150,38],[970,0.96],[1000,0.23]],"id":48534288},{"atb":[[2.36,6.54],[1.02,25.93],[2.34,11.44],[1.04,97.35]],"id":69475360},{"atl":[[990,2.13],[1000,0.23]],"id":69475360}],"con":true,"img":false}]}
{"op":"mcm","clk":"11540645175","pt":1719496835088,"mc":[{"id":"1.230180118","rc":[{"atl":[[150,39]],"id":48534288}],"con":true,"img":false}]}
{"op":"mcm","clk":"11540645184","pt":1719496835193,"mc":[{"id":"1.230180118","rc":[{"atl":[[150,40]],"id":48534288}],"con":true,"img":false}]}
{"op":"mcm","clk":"11540647252","pt":1719496859536,"mc":[{"id":"1.230180118","rc":[{"spl":[[1.01,4]],"id":60276470}],"con":true,"img":false}]}
{"op":"mcm","clk":"11540647309","pt":1719496860111,"mc":[{"id":"1.230180118","rc":[{"atl":[[150,39]],"id":48534288}],"con":true,"img":false}]}
{"op":"mcm","clk":"11540647333","pt":1719496860328,"mc":[{"id":"1.230180118","rc":[{"atl":[[150,38]],"id":48534288}],"con":true,"img":false}]}
{"op":"mcm","clk":"11540648232","pt":1719496870241,"mc":[{"id":"1.230180118","rc":[{"atl":[[150,39]],"id":48534288}],"con":true,"img":false}]}
{"op":"mcm","clk":"11540652309","pt":1719496925389,"mc":[{"id":"1.230180118","rc":[{"spn":3.12,"spf":1.0,"id":60276470},{"atl":[[150,35]],"id":48534288}],"con":true,"img":false}]}
{"op":"mcm","clk":"11540652326","pt":1719496925600,"mc":[{"id":"1.230180118","rc":[{"atl":[[150,34]],"id":48534288}],"con":true,"img":false}]}
{"op":"mcm","clk":"11540652344","pt":1719496925801,"mc":[{"id":"1.230180118","rc":[{"atl":[[150,35.03]],"id":48534288}],"con":true,"img":false}]}
{"op":"mcm","clk":"11540662015","pt":1719497048040,"mc":[{"id":"1.230180118","rc":[{"atl":[[190,4]],"id":50772801},{"atl":[[190,4]],"id":62145089},{"atl":[[190,4]],"id":69624671},{"atl":[[190,4]],"id":60276470},{"atl":[[190,4]],"id":48534288},{"atl":[[190,4]],"id":69475360}],"con":true,"img":false}]}
{"op":"mcm","clk":"11540663093","pt":1719497060504,"mc":[{"id":"1.230180118","rc":[{"atb":[[1.02,27.93]],"id":69475360}],"con":true,"img":false}]}
{"op":"mcm","clk":"11540663119","pt":1719497060819,"mc":[{"id":"1.230180118","rc":[{"atb":[[1.02,78.19]],"id":50772801}],"con":true,"img":false}]}
{"op":"mcm","clk":"11540663143","pt":1719497061132,"mc":[{"id":"1.230180118","rc":[{"atb":[[1.02,2]],"id":69624671}],"con":true,"img":false}]}
{"op":"mcm","clk":"11540663166","pt":1719497061443,"mc":[{"id":"1.230180118","rc":[{"atb":[[1.02,2]],"id":62145089}],"con":true,"img":false}]}
{"op":"mcm","clk":"11540663185","pt":1719497061748,"mc":[{"id":"1.230180118","rc":[{"atb":[[1.02,2]],"id":60276470}],"con":true,"img":false}]}
{"op":"mcm","clk":"11540663206","pt":1719497062015,"mc":[{"id":"1.230180118","rc":[{"atb":[[1.02,2]],"id":48534288}],"con":true,"img":false}]}
{"op":"mcm","clk":"11540693751","pt":1719497353118,"mc":[{"id":"1.230180118","rc":[{"spl":[[1.01,4]],"id":69475360},{"spn":2.8,"spf":1.0,"id":69475360}],"con":true,"img":false}]}
{"op":"mcm","clk":"11540696906","pt":1719497388726,"mc":[{"id":"1.230180118","rc":[{"spl":[[1.01,8]],"id":69475360}],"con":true,"img":false}]}
{"op":"mcm","clk":"11540699551","pt":1719497414669,"mc":[{"id":"1.230180118","rc":[{"atb":[[4.7,0]],"id":69624671},{"trd":[[4.7,1.99]],"ltp":4.7,"tv":1.99,"id":69624671},{"spn":3.3,"spf":1.0,"id":69624671},{"spn":2.61,"spf":1.0,"id":69475360}],"con":true,"img":false}]}
{"op":"mcm","clk":"11540699775","pt":1719497416833,"mc":[{"id":"1.230180118","rc":[{"atl":[[150,39.03]],"id":48534288}],"con":true,"img":false}]}
{"op":"mcm","clk":"11540699821","pt":1719497417347,"mc":[{"id":"1.230180118","rc":[{"atl":[[1000,0.33]],"id":69624671}],"con":true,"img":false}]}
{"op":"mcm","clk":"11540699841","pt":1719497417553,"mc":[{"id":"1.230180118","rc":[{"atl":[[1000,0.23]],"id":69624671}],"con":true,"img":false}]}
{"op":"mcm","clk":"11540699849","pt":1719497417663,"mc":[{"id":"1.230180118","rc":[{"atl":[[11,0.1]],"id":69624671}],"con":true,"img":false}]}
{"op":"mcm","clk":"11540699976","pt":1719497418952,"mc":[{"id":"1.230180118","rc":[{"atb":[[4.2,1]],"id":69624671}],"con":true,"img":false}]}
{"op":"mcm","clk":"11540700115","pt":1719497420752,"mc":[{"id":"1.230180118","rc":[{"atl":[[11,0.94]],"id":69624671},{"atl":[[26,0.84]],"id":60276470}],"con":true,"img":false}]}
{"op":"mcm","clk":"11540700364","pt":1719497423646,"mc":[{"id":"1.230180118","rc":[{"atl":[[150,38]],"id":48534288}],"con":true,"img":false}]}
{"op":"mcm","clk":"11540700383","pt":1719497423847,"mc":[{"id":"1.230180118","rc":[{"atl":[[150,41.79]],"id":48534288}],"con":true,"img":false}]}
{"op":"mcm","clk":"11540700653","pt":1719497426638,"mc":[{"id":"1.230180118","rc":[{"atb":[[4.2,0]],"id":69624671},{"trd":[[4.2,1.99]],"ltp":4.2,"tv":1.99,"id":69624671}],"con":true,"img":false}]}
{"op":"mcm","clk":"11540700870","pt":1719497428957,"mc":[{"id":"1.230180118","rc":[{"atb":[[3.85,1]],"id":69624671}],"con":true,"img":false}]}
{"op":"mcm","clk":"11540701231","pt":1719497432749,"mc":[{"id":"1.230180118","rc":[{"atl":[[11,0.84]],"id":69624671}],"con":true,"img":false}]}
{"op":"mcm","clk":"11540701277","pt":1719497433174,"mc":[{"id":"1.230180118","rc":[{"atl":[[1000,0.33]],"id":69624671}],"con":true,"img":false}]}
{"op":"mcm","clk":"11540701293","pt":1719497433373,"mc":[{"id":"1.230180118","rc":[{"atl":[[1000,0.23]],"id":69624671}],"con":true,"img":false}]}
{"op":"mcm","clk":"11540701299","pt":1719497433478,"mc":[{"id":"1.230180118","rc":[{"atl":[[11,0.94]],"id":69624671}],"con":true,"img":false}]}
{"op":"mcm","clk":"11540702770","pt":1719497448584,"mc":[{"id":"1.230180118","rc":[{"atl":[[11,0.84]],"id":69624671}],"con":true,"img":false}]}
{"op":"mcm","clk":"11540702811","pt":1719497449000,"mc":[{"id":"1.230180118","rc":[{"atl":[[1000,0.33]],"id":69624671}],"con":true,"img":false}]}
{"op":"mcm","clk":"11540702826","pt":1719497449202,"mc":[{"id":"1.230180118","rc":[{"atl":[[1000,0.23]],"id":69624671}],"con":true,"img":false}]}
{"op":"mcm","clk":"11540702839","pt":1719497449305,"mc":[{"id":"1.230180118","rc":[{"atl":[[11,0.94]],"id":69624671}],"con":true,"img":false}]}
{"op":"mcm","clk":"11540703400","pt":1719497454603,"mc":[{"id":"1.230180118","rc":[{"atb":[[2.26,9.39]],"id":50772801},{"atb":[[2.28,9.25]],"id":48534288}],"con":true,"img":false}]}
{"op":"mcm","clk":"11540703416","pt":1719497454804,"mc":[{"id":"1.230180118","rc":[{"atb":[[2.22,9.71]],"id":62145089},{"atb":[[2.18,10.03]],"id":69624671}],"con":true,"img":false}]}
{"op":"mcm","clk":"11540703430","pt":1719497455009,"mc":[{"id":"1.230180118","rc":[{"atb":[[2.28,9.25]],"id":60276470}],"con":true,"img":false}]}
{"op":"mcm","clk":"11540703471","pt":1719497455421,"mc":[{"id":"1.230180118","rc":[{"atb":[[2.26,2.09]],"id":69624671}],"con":true,"img":false}]}
{"op":"mcm","clk":"11540704357","pt":1719497464496,"mc":[{"id":"1.230180118","rc":[{"atl":[[11,0.84]],"id":69624671}],"con":true,"img":false}]}
{"op":"mcm","clk":"11540704392","pt":1719497464808,"mc":[{"id":"1.230180118","rc":[{"atl":[[1000,0.33]],"id":69624671}],"con":true,"img":false}]}
{"op":"mcm","clk":"11540704413","pt":1719497465014,"mc":[{"id":"1.230180118","rc":[{"atl":[[1000,0.23]],"id":69624671}],"con":true,"img":false}]}
{"op":"mcm","clk":"11540704425","pt":1719497465116,"mc":[{"id":"1.230180118","rc":[{"atl":[[11,0.94]],"id":69624671}],"con":true,"img":false}]}
{"op":"mcm","clk":"11540705929","pt":1719497480341,"mc":[{"id":"1.230180118","rc":[{"atl":[[11,0.84]],"id":69624671},{"spn":3.85,"spf":1.0,"id":69624671}],"con":true,"img":false}]}
{"op":"mcm","clk":"11540705956","pt":1719497480595,"mc":[{"id":"1.230180118","rc":[{"atl":[[1000,0.33]],"id":69624671}],"con":true,"img":false}]}
{"op":"mcm","clk":"11540705974","pt":1719497480809,"mc":[{"id":"1.230180118","rc":[{"atl":[[1000,0.23]],"id":69624671}],"con":true,"img":false}]}
{"op":"mcm","clk":"11540705987","pt":1719497480907,"mc":[{"id":"1.230180118","rc":[{"atl":[[11,0.94]],"id":69624671}],"con":true,"img":false}]}
{"op":"mcm","clk":"11540706352","pt":1719497484829,"mc":[{"id":"1.230180118","rc":[{"atb":[[2.24,11.26]],"id":62145089}],"con":true,"img":false}]}
{"op":"mcm","clk":"11540706362","pt":1719497484926,"mc":[{"id":"1.230180118","rc":[{"atb":[[2.2,11.64]],"id":69624671}],"con":true,"img":false}]}
{"op":"mcm","clk":"11540706373","pt":1719497485133,"mc":[{"id":"1.230180118","rc":[{"atb":[[2.3,10.74]],"id":48534288}],"con":true,"img":false}]}
{"op":"mcm","clk":"11540706395","pt":1719497485441,"mc":[{"id":"1.230180118","rc":[{"atb":[[2.28,10.91]],"id":50772801}],"con":true,"img":false}]}
{"op":"mcm","clk":"11540706425","pt":1719497485803,"mc":[{"id":"1.230180118","rc":[{"atb":[[2.3,10.74]],"id":60276470}],"con":true,"img":false}]}
{"op":"mcm","clk":"11540706456","pt":1719497486122,"mc":[{"id":"1.230180118","rc":[{"atb":[[2.32,2.09]],"id":62145089}],"con":true,"img":false}]}
{"op":"mcm","clk":"11540707251","pt":1719497496126,"mc":[{"id":"1.230180118","rc":[{"atl":[[11,0.84]],"id":69624671}],"con":true,"img":false}]}
{"op":"mcm","clk":"11540707429","pt":1719497498344,"mc":[{"id":"1.230180118","rc":[{"atl":[[1000,0.33]],"id":69624671}],"con":true,"img":false}]}
{"op":"mcm","clk":"11540707448","pt":1719497498545,"mc":[{"id":"1.230180118","rc":[{"atl":[[1000,0.23]],"id":69624671}],"con":true,"img":false}]}
{"op":"mcm","clk":"11540707457","pt":1719497498649,"mc":[{"id":"1.230180118","rc":[{"atl":[[11,0.94]],"id":69624671}],"con":true,"img":false}]}
{"op":"mcm","clk":"11540708703","pt":1719497513766,"mc":[{"id":"1.230180118","rc":[{"atl":[[11,0.84]],"id":69624671}],"con":true,"img":false}]}
{"op":"mcm","clk":"11540708752","pt":1719497514330,"mc":[{"id":"1.230180118","rc":[{"atl":[[1000,0.33]],"id":69624671}],"con":true,"img":false}]}
{"op":"mcm","clk":"11540708774","pt":1719497514644,"mc":[{"id":"1.230180118","rc":[{"atl":[[1000,0.23]],"id":69624671}],"con":true,"img":false}]}
{"op":"mcm","clk":"11540708781","pt":1719497514740,"mc":[{"id":"1.230180118","rc":[{"atl":[[11,0.94]],"id":69624671}],"con":true,"img":false}]}
{"op":"mcm","clk":"11540710339","pt":1719497529977,"mc":[{"id":"1.230180118","rc":[{"atl":[[11,0.84]],"id":69624671}],"con":true,"img":false}]}
{"op":"mcm","clk":"11540710356","pt":1719497530180,"mc":[{"id":"1.230180118","rc":[{"atl":[[1000,0.33]],"id":69624671}],"con":true,"img":false}]}
{"op":"mcm","clk":"11540710368","pt":1719497530291,"mc":[{"id":"1.230180118","rc":[{"atl":[[1000,0.23]],"id":69624671}],"con":true,"img":false}]}
{"op":"mcm","clk":"11540710380","pt":1719497530389,"mc":[{"id":"1.230180118","rc":[{"atl":[[11,0.94]],"id":69624671}],"con":true,"img":false}]}
{"op":"mcm","clk":"11540710499","pt":1719497531789,"mc":[{"id":"1.230180118","rc":[{"atb":[[2.26,0]],"id":50772801},{"atb":[[2.22,0]],"id":62145089},{"atb":[[2.18,0]],"id":69624671},{"atb":[[2.28,0]],"id":60276470},{"atb":[[2.28,0]],"id":48534288}],"con":true,"img":false}]}
{"op":"mcm","clk":"11540711500","pt":1719497543475,"mc":[{"id":"1.230180118","rc":[{"atb":[[2.22,9.71]],"id":69624671}],"con":true,"img":false}]}
{"op":"mcm","clk":"11540711507","pt":1719497543576,"mc":[{"id":"1.230180118","rc":[{"atb":[[2.3,9.11]],"id":50772801}],"con":true,"img":false}]}
{"op":"mcm","clk":"11540711517","pt":1719497543786,"mc":[{"id":"1.230180118","rc":[{"atb":[[2.26,9.39]],"id":62145089}],"con":true,"img":false}]}
{"op":"mcm","clk":"11540711525","pt":1719497543885,"mc":[{"id":"1.230180118","rc":[{"atb":[[2.32,8.97]],"id":60276470}],"con":true,"img":false}]}
{"op":"mcm","clk":"11540711529","pt":1719497543987,"mc":[{"id":"1.230180118","rc":[{"atb":[[2.32,8.97]],"id":48534288}],"con":true,"img":false}]}
{"op":"mcm","clk":"11540711575","pt":1719497544714,"mc":[{"id":"1.230180118","rc":[{"atb":[[2.38,2.09]],"id":50772801},{"atb":[[2.4,2.09]],"id":60276470}],"con":true,"img":false}]}
{"op":"mcm","clk":"11540711656","pt":1719497545589,"mc":[{"id":"1.230180118","rc":[{"atl":[[11,0.84]],"id":69624671}],"con":true,"img":false}]}
{"op":"mcm","clk":"11540711673","pt":1719497545794,"mc":[{"id":"1.230180118","rc":[{"atl":[[1000,0.33]],"id":69624671}],"con":true,"img":false}]}
{"op":"mcm","clk":"11540711692","pt":1719497546003,"mc":[{"id":"1.230180118","rc":[{"atl":[[1000,0.23]],"id":69624671}],"con":true,"img":false}]}
{"op":"mcm","clk":"11540711705","pt":1719497546109,"mc":[{"id":"1.230180118","rc":[{"atl":[[11,0.94]],"id":69624671}],"con":true,"img":false}]}
{"op":"mcm","clk":"11540713079","pt":1719497561316,"mc":[{"id":"1.230180118","rc":[{"atl":[[11,0.84]],"id":69624671}],"con":true,"img":false}]}
{"op":"mcm","clk":"11540713102","pt":1719497561626,"mc":[{"id":"1.230180118","rc":[{"atl":[[1000,0.33]],"id":69624671}],"con":true,"img":false}]}
{"op":"mcm","clk":"11540713119","pt":1719497561832,"mc":[{"id":"1.230180118","rc":[{"atl":[[1000,0.23]],"id":69624671}],"con":true,"img":false}]}
{"op":"mcm","clk":"11540713129","pt":1719497561890,"mc":[{"id":"1.230180118","rc":[{"atl":[[11,0.94]],"id":69624671}],"con":true,"img":false}]}
{"op":"mcm","clk":"11540714361","pt":1719497577134,"mc":[{"id":"1.230180118","rc":[{"atl":[[11,0.84]],"id":69624671}],"con":true,"img":false}]}
{"op":"mcm","clk":"11540714397","pt":1719497577547,"mc":[{"id":"1.230180118","rc":[{"atl":[[1000,0.33]],"id":69624671}],"con":true,"img":false}]}
{"op":"mcm","clk":"11540714414","pt":1719497577704,"mc":[{"id":"1.230180118","rc":[{"atl":[[1000,0.23]],"id":69624671}],"con":true,"img":false}]}
{"op":"mcm","clk":"11540714420","pt":1719497577810,"mc":[{"id":"1.230180118","rc":[{"atl":[[11,0.94]],"id":69624671}],"con":true,"img":false}]}
{"op":"mcm","clk":"11540714600","pt":1719497580037,"mc":[{"id":"1.230180118","rc":[{"atb":[[3.9,0]],"id":69475360},{"atl":[[3.9,3]],"id":69475360},{"trd":[[3.9,2]],"ltp":3.9,"tv":2.0,"id":69475360}],"con":true,"img":false}]}
{"op":"mcm","clk":"11540714698","pt":1719497581332,"mc":[{"id":"1.230180118","rc":[{"atb":[[2.46,1.7]],"id":69475360}],"con":true,"img":false}]}
{"op":"mcm","clk":"11540714926","pt":1719497583929,"mc":[{"id":"1.230180118","rc":[{"atb":[[1.03,1]],"id":69475360}],"con":true,"img":false}]}
{"op":"mcm","clk":"11540714943","pt":1719497584136,"mc":[{"id":"1.230180118","rc":[{"atb":[[1.03,0.68]],"id":69475360}],"con":true,"img":false}]}
{"op":"mcm","clk":"11540714966","pt":1719497584351,"mc":[{"id":"1.230180118","rc":[{"atb":[[1.03,0]],"id":69475360}],"con":true,"img":false}]}
{"op":"mcm","clk":"11540714981","pt":1719497584452,"mc":[{"id":"1.230180118","rc":[{"atb":[[2.48,0.68]],"id":69475360}],"con":true,"img":false}]}
{"op":"mcm","clk":"11540715056","pt":1719497585245,"mc":[{"id":"1.230180118","rc":[{"atb":[[3.65,1]],"id":69475360}],"con":true,"img":false}]}
{"op":"mcm","clk":"11540715217","pt":1719497587236,"mc":[{"id":"1.230180118","rc":[{"atb":[[2.28,0]],"id":50772801},{"atb":[[2.24,0]],"id":62145089},{"atb":[[2.2,0]],"id":69624671},{"atb":[[2.3,0]],"id":60276470},{"atb":[[2.3,0]],"id":48534288}],"con":true,"img":false}]}
{"op":"mcm","clk":"11540715234","pt":1719497587451,"mc":[{"id":"1.230180118","rc":[{"atb":[[2.46,0]],"id":69475360}],"con":true,"img":false}]}
{"op":"mcm","clk":"11540715351","pt":1719497589468,"mc":[{"id":"1.230180118","rc":[{"atl":[[3.9,0]],"id":69475360},{"trd":[[3.9,7.99]],"ltp":3.9,"tv":7.99,"id":69475360}],"con":true,"img":false}]}
{"op":"mcm","clk":"11540715629","pt":1719497592535,"mc":[{"id":"1.230180118","rc":[{"atb":[[2.24,0]],"id":50772801},{"atb":[[2.2,0]],"id":62145089},{"atb":[[2.16,0]],"id":69624671},{"atb":[[2.26,0]],"id":60276470},{"atb":[[2.26,0]],"id":48534288}],"con":true,"img":false}]}
{"op":"mcm","clk":"11540715638","pt":1719497592850,"mc":[{"id":"1.230180118","rc":[{"atb":[[2.32,13.33]],"id":50772801},{"atb":[[2.28,8.71]],"id":62145089},{"atb":[[2.24,12.82]],"id":69624671},{"atb":[[2.34,13.46]],"id":60276470},{"atb":[[2.34,8.97]],"id":48534288}],"con":true,"img":false}]}
{"op":"mcm","clk":"11540715689","pt":1719497593145,"mc":[{"id":"1.230180118","rc":[{"atl":[[11,0.84]],"id":69624671}],"con":true,"img":false}]}
{"op":"mcm","clk":"11540715716","pt":1719497593452,"mc":[{"id":"1.230180118","rc":[{"atl":[[1000,0.33]],"id":69624671}],"con":true,"img":false}]}
{"op":"mcm","clk":"11540715729","pt":1719497593556,"mc":[{"id":"1.230180118","rc":[{"atl":[[1000,0.23]],"id":69624671}],"con":true,"img":false}]}
{"op":"mcm","clk":"11540715733","pt":1719497593659,"mc":[{"id":"1.230180118","rc":[{"atl":[[11,0.94]],"id":69624671}],"con":true,"img":false}]}
{"op":"mcm","clk":"11540716202","pt":1719497599672,"mc":[{"id":"1.230180118","rc":[{"atb":[[2.48,0]],"id":69475360}],"con":true,"img":false}]}
{"op":"mcm","clk":"11540716238","pt":1719497600040,"mc":[{"id":"1.230180118","rc":[{"atl":[[1000,0.26]],"id":69475360}],"con":true,"img":false}]}
{"op":"mcm","clk":"11540716255","pt":1719497600240,"mc":[{"id":"1.230180118","rc":[{"atl":[[1000,0.23]],"id":69475360}],"con":true,"img":false}]}
{"op":"mcm","clk":"11540716261","pt":1719497600341,"mc":[{"id":"1.230180118","rc":[{"atl":[[30,0.03]],"id":69475360}],"con":true,"img":false}]}
{"op":"mcm","clk":"11540716899","pt":1719497608976,"mc":[{"id":"1.230180118","rc":[{"atl":[[11,0.84]],"id":69624671},{"spn":2.58,"spf":1.0,"id":69475360}],"con":true,"img":false}]}
{"op":"mcm","clk":"11540717054","pt":1719497610882,"mc":[{"id":"1.230180118","rc":[{"atl":[[1000,0.33]],"id":69624671}],"con":true,"img":false}]}
{"op":"mcm","clk":"11540717071","pt":1719497611084,"mc":[{"id":"1.230180118","rc":[{"atl":[[1000,0.23]],"id":69624671}],"con":true,"img":false}]}
{"op":"mcm","clk":"11540717082","pt":1719497611181,"mc":[{"id":"1.230180118","rc":[{"atl":[[11,0.94]],"id":69624671}],"con":true,"img":false}]}
{"op":"mcm","clk":"11540717437","pt":1719497615559,"mc":[{"id":"1.230180118","rc":[{"atl":[[30,0]],"id":69475360}],"con":true,"img":false}]}
{"op":"mcm","clk":"11540717470","pt":1719497615969,"mc":[{"id":"1.230180118","rc":[{"atl":[[1000,0.26]],"id":69475360}],"con":true,"img":false}]}
{"op":"mcm","clk":"11540717489","pt":1719497616173,"mc":[{"id":"1.230180118","rc":[{"atl":[[1000,0.23]],"id":69475360}],"con":true,"img":false}]}
{"op":"mcm","clk":"11540717496","pt":1719497616278,"mc":[{"id":"1.230180118","rc":[{"atl":[[30,0.03]],"id":69475360}],"con":true,"img":false}]}
{"op":"mcm","clk":"11540717569","pt":1719497617103,"mc":[{"id":"1.230180118","rc":[{"atb":[[2.3,0]],"id":50772801},{"atb":[[2.26,0]],"id":62145089},{"atb":[[2.22,0]],"id":69624671},{"atb":[[2.32,0]],"id":60276470},{"atb":[[2.32,0]],"id":48534288}],"con":true,"img":false}]}
{"op":"mcm","clk":"11540717784","pt":1719497619582,"mc":[{"id":"1.230180118","rc":[{"atb":[[2.36,8.71]],"id":60276470}],"con":true,"img":false}]}
{"op":"mcm","clk":"11540717792","pt":1719497619684,"mc":[{"id":"1.230180118","rc":[{"atb":[[2.34,8.83]],"id":50772801}],"con":true,"img":false}]}
{"op":"mcm","clk":"11540717799","pt":1719497619786,"mc":[{"id":"1.230180118","rc":[{"atb":[[2.26,11.49]],"id":69624671}],"con":true,"img":false}]}
{"op":"mcm","clk":"11540717807","pt":1719497619894,"mc":[{"id":"1.230180118","rc":[{"atb":[[2.3,9.11]],"id":62145089}],"con":true,"img":false}]}
{"op":"mcm","clk":"11540717844","pt":1719497620261,"mc":[{"id":"1.230180118","rc":[{"atb":[[2.36,8.71]],"id":48534288}],"con":true,"img":false}]}
{"op":"mcm","clk":"11540718341","pt":1719497626387,"mc":[{"id":"1.230180118","rc":[{"atl":[[11,0.84]],"id":69624671}],"con":true,"img":false}]}
{"op":"mcm","clk":"11540718415","pt":1719497627258,"mc":[{"id":"1.230180118","rc":[{"atl":[[1000,0.33]],"id":69624671}],"con":true,"img":false}]}
{"op":"mcm","clk":"11540718428","pt":1719497627361,"mc":[{"id":"1.230180118","rc":[{"atl":[[1000,0.23]],"id":69624671}],"con":true,"img":false}]}
{"op":"mcm","clk":"11540718439","pt":1719497627464,"mc":[{"id":"1.230180118","rc":[{"atl":[[11,0.94]],"id":69624671}],"con":true,"img":false}]}
{"op":"mcm","clk":"11540718828","pt":1719497631587,"mc":[{"id":"1.230180118","rc":[{"atl":[[30,0]],"id":69475360}],"con":true,"img":false}]}
{"op":"mcm","clk":"11540718845","pt":1719497631795,"mc":[{"id":"1.230180118","rc":[{"atl":[[1000,0.26]],"id":69475360}],"con":true,"img":false}]}
{"op":"mcm","clk":"11540718857","pt":1719497632006,"mc":[{"id":"1.230180118","rc":[{"atl":[[1000,0.23]],"id":69475360}],"con":true,"img":false}]}
{"op":"mcm","clk":"11540718868","pt":1719497632108,"mc":[{"id":"1.230180118","rc":[{"atl":[[30,0.03]],"id":69475360}],"con":true,"img":false}]}
{"op":"mcm","clk":"11540719518","pt":1719497640081,"mc":[{"id":"1.230180118","rc":[{"atb":[[1.12,1.69]],"id":50772801},{"atb":[[1.08,1.69]],"id":69475360}],"con":true,"img":false}]}
{"op":"mcm","clk":"11540719529","pt":1719497640188,"mc":[{"id":"1.230180118","rc":[{"atb":[[4.2,6]],"id":50772801},{"atl":[[140,2]],"id":50772801}],"con":true,"img":false}]}
{"op":"mcm","clk":"11540719544","pt":1719497640287,"mc":[{"id":"1.230180118","rc":[{"atb":[[1.12,1.69],[3.6,6]],"id":62145089},{"atl":[[30,3.45]],"id":62145089},{"atb":[[1.09,1.69]],"id":69624671},{"atb":[[3.8,8.71]],"id":48534288},{"atl":[[140,2]],"id":48534288},{"atb":[[2.46,6.55]],"id":69475360},{"atl":[[30,3.48]],"id":69475360}],"con":true,"img":false}]}
{"op":"mcm","clk":"11540719556","pt":1719497640390,"mc":[{"id":"1.230180118","rc":[{"atb":[[3.1,12.83]],"id":69624671},{"atl":[[11.5,5]],"id":69624671},{"atb":[[2.88,6]],"id":60276470},{"atl":[[27,5.46]],"id":60276470},{"atl":[[140,36],[150,4]],"id":48534288}],"con":true,"img":false}]}
{"op":"mcm","clk":"11540719570","pt":1719497640492,"mc":[{"id":"1.230180118","rc":[{"atl":[[130,3.79]],"id":48534288}],"con":true,"img":false}]}
{"op":"mcm","clk":"11540719582","pt":1719497640597,"mc":[{"id":"1.230180118","rc":[{"atb":[[1.12,0.05]],"id":50772801},{"atb":[[1.12,1.69]],"id":48534288},{"atl":[[130,37.79],[140,2]],"id":48534288},{"atl":[[29,2]],"id":69475360}],"con":true,"img":false}]}
{"op":"mcm","clk":"11540719612","pt":1719497640906,"mc":[{"id":"1.230180118","rc":[{"atb":[[1.09,0.07]],"id":69624671}],"con":true,"img":false}]}
{"op":"mcm","clk":"11540719619","pt":1719497641014,"mc":[{"id":"1.230180118","rc":[{"atb":[[1.09,1.69]],"id":60276470}],"con":true,"img":false}]}
{"op":"mcm","clk":"11540719650","pt":1719497641317,"mc":[{"id":"1.230180118","rc":[{"atb":[[1.12,0.05]],"id":62145089}],"con":true,"img":false}]}
{"op":"mcm","clk":"11540719660","pt":1719497641424,"mc":[{"id":"1.230180118","rc":[{"atb":[[1.08,0.08]],"id":69475360}],"con":true,"img":false}]}
{"op":"mcm","clk":"11540719680","pt":1719497641578,"mc":[{"id":"1.230180118","rc":[{"atb":[[1.12,0]],"id":50772801}],"con":true,"img":false}]}
{"op":"mcm","clk":"11540719689","pt":1719497641680,"mc":[{"id":"1.230180118","rc":[{"atb":[[5.1,0.05]],"id":50772801},{"atb":[[1.12,0.05]],"id":48534288}],"con":true,"img":false}]}
{"op":"mcm","clk":"11540719717","pt":1719497641989,"mc":[{"id":"1.230180118","rc":[{"atb":[[1.09,0]],"id":69624671}],"con":true,"img":false}]}
{"op":"mcm","clk":"11540719727","pt":1719497642096,"mc":[{"id":"1.230180118","rc":[{"atb":[[3.9,0.07]],"id":69624671}],"con":true,"img":false}]}
{"op":"mcm","clk":"11540719749","pt":1719497642298,"mc":[{"id":"1.230180118","rc":[{"atb":[[4.6,1]],"id":48534288},{"atl":[[15.5,1]],"id":48534288}],"con":true,"img":false}]}
{"op":"mcm","clk":"11540719758","pt":1719497642402,"mc":[{"id":"1.230180118","rc":[{"atb":[[1.12,0]],"id":62145089},{"atb":[[1.09,0.07]],"id":60276470},{"atl":[[130,0],[15.5,35]],"id":48534288}],"con":true,"img":false}]}
{"op":"mcm","clk":"11540719767","pt":1719497642506,"mc":[{"id":"1.230180118","rc":[{"atb":[[5.1,0.05]],"id":62145089},{"atl":[[15,3.79]],"id":48534288}],"con":true,"img":false}]}
{"op":"mcm","clk":"11540719777","pt":1719497642612,"mc":[{"id":"1.230180118","rc":[{"atl":[[11,0.84]],"id":69624671},{"atl":[[15,37.79]],"id":48534288}],"con":true,"img":false}]}
{"op":"mcm","clk":"11540719786","pt":1719497642718,"mc":[{"id":"1.230180118","rc":[{"atl":[[15.5,1]],"id":48534288}],"con":true,"img":false}]}
{"op":"mcm","clk":"11540719802","pt":1719497642923,"mc":[{"id":"1.230180118","rc":[{"atb":[[1.08,0]],"id":69475360}],"con":true,"img":false}]}
{"op":"mcm","clk":"11540719813","pt":1719497643031,"mc":[{"id":"1.230180118","rc":[{"atl":[[1000,0.33]],"id":69624671},{"atb":[[3.7,0.08]],"id":69475360}],"con":true,"img":false}]}
{"op":"mcm","clk":"11540719825","pt":1719497643133,"mc":[{"id":"1.230180118","rc":[{"atl":[[1000,0.23]],"id":69624671}],"con":true,"img":false}]}
{"op":"mcm","clk":"11540719845","pt":1719497643231,"mc":[{"id":"1.230180118","rc":[{"atl":[[11,0.94]],"id":69624671}],"con":true,"img":false}]}
{"op":"mcm","clk":"11540719857","pt":1719497643284,"mc":[{"id":"1.230180118","rc":[{"atb":[[1.12,0]],"id":48534288}],"con":true,"img":false}]}
{"op":"mcm","clk":"11540719868","pt":1719497643391,"mc":[{"id":"1.230180118","rc":[{"atb":[[5.1,0.05]],"id":48534288}],"con":true,"img":false}]}
{"op":"mcm","clk":"11540719907","pt":1719497643804,"mc":[{"id":"1.230180118","rc":[{"atb":[[1.09,0]],"id":60276470}],"con":true,"img":false}]}
{"op":"mcm","clk":"11540719914","pt":1719497643905,"mc":[{"id":"1.230180118","rc":[{"atb":[[3.95,0.07]],"id":60276470}],"con":true,"img":false}]}
{"op":"mcm","clk":"11540720080","pt":1719497645814,"mc":[{"id":"1.230180118","rc":[{"atl":[[29,0]],"id":69475360}],"con":true,"img":false}]}
{"op":"mcm","clk":"11540720204","pt":1719497647406,"mc":[{"id":"1.230180118","rc":[{"atl":[[30,3.45]],"id":69475360}],"con":true,"img":false}]}
{"op":"mcm","clk":"11540720220","pt":1719497647611,"mc":[{"id":"1.230180118","rc":[{"atl":[[1000,0.27]],"id":69475360}],"con":true,"img":false}]}
{"op":"mcm","clk":"11540720240","pt":1719497647824,"mc":[{"id":"1.230180118","rc":[{"atl":[[1000,0.23]],"id":69475360}],"con":true,"img":false}]}
{"op":"mcm","clk":"11540720249","pt":1719497647922,"mc":[{"id":"1.230180118","rc":[{"atl":[[29,0.04]],"id":69475360}],"con":true,"img":false}]}
{"op":"mcm","clk":"11540720297","pt":1719497648437,"mc":[{"id":"1.230180118","rc":[{"atl":[[1000,1.93]],"id":69475360}],"con":true,"img":false}]}
{"op":"mcm","clk":"11540720306","pt":1719497648491,"mc":[{"id":"1.230180118","rc":[{"atb":[[1.03,18.99]],"id":50772801},{"atl":[[1000,1.93]],"id":50772801},{"atb":[[1.02,3.7]],"id":69624671},{"atl":[[1000,1.93]],"id":69624671},{"atb":[[1.02,29.64]],"id":69475360}],"con":true,"img":false}]}
{"op":"mcm","clk":"11540720313","pt":1719497648596,"mc":[{"id":"1.230180118","rc":[{"atl":[[1000,0.24]],"id":69475360}],"con":true,"img":false}]}
{"op":"mcm","clk":"11540720319","pt":1719497648704,"mc":[{"id":"1.230180118","rc":[{"atb":[[1.03,17.39]],"id":50772801},{"atl":[[1000,0.23]],"id":50772801},{"atb":[[1.02,2.13]],"id":69624671},{"atl":[[1000,0.26]],"id":69624671},{"atb":[[1.02,28.15]],"id":69475360}],"con":true,"img":false}]}
{"op":"mcm","clk":"11540720329","pt":1719497648803,"mc":[{"id":"1.230180118","rc":[{"atl":[[1000,0.23]],"id":69475360}],"con":true,"img":false}]}
{"op":"mcm","clk":"11540720336","pt":1719497648909,"mc":[{"id":"1.230180118","rc":[{"atb":[[1.03,17.29]],"id":50772801},{"atb":[[1.02,2]],"id":69624671},{"atl":[[1000,0.23]],"id":69624671},{"atb":[[1.02,27.93]],"id":69475360},{"atl":[[29,0.05]],"id":69475360}],"con":true,"img":false}]}
{"op":"mcm","clk":"11540720345","pt":1719497649017,"mc":[{"id":"1.230180118","rc":[{"atb":[[4.3,0.09]],"id":50772801},{"atb":[[3.35,0.13]],"id":69624671},{"atl":[[11,0.97]],"id":69624671},{"atb":[[2.48,0.21]],"id":69475360}],"con":true,"img":false}]}
{"op":"mcm","clk":"11540720454","pt":1719497650405,"mc":[{"id":"1.230180118","rc":[{"atb":[[4.6,7],[3.8,0]],"id":48534288},{"atl":[[140,0],[27,3.85]],"id":48534288}],"con":true,"img":false}]}
{"op":"mcm","clk":"11540720462","pt":1719497650501,"mc":[{"id":"1.230180118","rc":[{"atb":[[2.6,6.98]],"id":69475360}],"con":true,"img":false}]}
{"op":"mcm","clk":"11540720471","pt":1719497650606,"mc":[{"id":"1.230180118","rc":[{"atb":[[2.62,6.55],[2.46,0]],"id":69475360}],"con":true,"img":false}]}
{"op":"mcm","clk":"11540720681","pt":1719497652621,"mc":[{"id":"1.230180118","rc":[{"atl":[[29,2.05]],"id":69475360}],"con":true,"img":false}]}
{"op":"mcm","clk":"11540720790","pt":1719497654015,"mc":[{"id":"1.230180118","rc":[{"atb":[[3.85,0],[3.9,0]],"id":69624671},{"atl":[[3.85,3.92]],"id":69624671},{"trd":[[3.85,2],[3.9,0.15]],"ltp":3.85,"tv":2.15,"id":69624671}],"con":true,"img":false}]}
{"op":"mcm","clk":"11540720800","pt":1719497654117,"mc":[{"id":"1.230180118","rc":[{"atl":[[3.85,0]],"id":69624671},{"trd":[[3.85,9.83]],"ltp":3.85,"tv":9.83,"id":69624671}],"con":true,"img":false}]}
{"op":"mcm","clk":"11540720817","pt":1719497654423,"mc":[{"id":"1.230180118","rc":[{"atb":[[5.1,0]],"id":50772801},{"atb":[[5.1,0]],"id":62145089},{"atb":[[3.95,0]],"id":60276470},{"atb":[[5.1,0]],"id":48534288},{"atb":[[3.7,0]],"id":69475360}],"con":true,"img":false}]}
{"op":"mcm","clk":"11540720892","pt":1719497655515,"mc":[{"id":"1.230180118","rc":[{"atb":[[4.6,1],[3.8,8.71]],"id":48534288}],"con":true,"img":false}]}
{"op":"mcm","clk":"11540720904","pt":1719497655713,"mc":[{"id":"1.230180118","rc":[{"atb":[[4.3,1]],"id":69624671},{"atl":[[11,2.03]],"id":69624671},{"atb":[[3.95,1],[3.9,0]],"id":60276470},{"atb":[[3.95,1],[3.65,0]],"id":69475360}],"con":true,"img":false}]}
{"op":"mcm","clk":"11540720910","pt":1719497655814,"mc":[{"id":"1.230180118","rc":[{"atb":[[3.35,0.8],[3.15,3.72]],"id":69624671}],"con":true,"img":false}]}
{"op":"mcm","clk":"11540721011","pt":1719497657411,"mc":[{"id":"1.230180118","rc":[{"atb":[[4.9,1]],"id":50772801},{"atl":[[16,1]],"id":50772801},{"atb":[[4,1]],"id":62145089},{"atl":[[11.5,1]],"id":62145089},{"atb":[[3.15,4.72]],"id":69624671},{"atl":[[8,1]],"id":69624671},{"atb":[[2.98,1]],"id":60276470},{"atl":[[7,1]],"id":60276470},{"atl":[[16,1],[15.5,0]],"id":48534288},{"atb":[[2.8,1]],"id":69475360},{"atl":[[7,1]],"id":69475360}],"con":true,"img":false}]}
{"op":"mcm","clk":"11540721026","pt":1719497657615,"mc":[{"id":"1.230180118","rc":[{"atl":[[15,34]],"id":48534288}],"con":true,"img":false}]}
{"op":"mcm","clk":"11540721035","pt":1719497657718,"mc":[{"id":"1.230180118","rc":[{"atl":[[16,4.79]],"id":48534288}],"con":true,"img":false}]}
{"op":"mcm","clk":"11540721045","pt":1719497657822,"mc":[{"id":"1.230180118","rc":[{"atl":[[16,1]],"id":48534288},{"atl":[[29,0.05]],"id":69475360}],"con":true,"img":false}]}
{"op":"mcm","clk":"11540721053","pt":1719497657924,"mc":[{"id":"1.230180118","rc":[{"atl":[[14.5,3.79]],"id":48534288}],"con":true,"img":false}]}
{"op":"mcm","clk":"11540721058","pt":1719497658031,"mc":[{"id":"1.230180118","rc":[{"atl":[[14.5,37.79]],"id":48534288}],"con":true,"img":false}]}
{"op":"mcm","clk":"11540721071","pt":1719497658136,"mc":[{"id":"1.230180118","rc":[{"atl":[[15,0]],"id":48534288}],"con":true,"img":false}]}
{"op":"mcm","clk":"11540721082","pt":1719497658338,"mc":[{"id":"1.230180118","rc":[{"atl":[[14.5,34]],"id":48534288}],"con":true,"img":false}]}
{"op":"mcm","clk":"11540721090","pt":1719497658440,"mc":[{"id":"1.230180118","rc":[{"atl":[[11,1.93]],"id":69624671},{"atl":[[16,4.79]],"id":48534288}],"con":true,"img":false}]}
{"op":"mcm","clk":"11540721099","pt":1719497658542,"mc":[{"id":"1.230180118","rc":[{"atl":[[16,1]],"id":48534288}],"con":true,"img":false}]}
{"op":"mcm","clk":"11540721106","pt":1719497658643,"mc":[{"id":"1.230180118","rc":[{"atl":[[14,3.79]],"id":48534288}],"con":true,"img":false}]}
{"op":"mcm","clk":"11540721112","pt":1719497658745,"mc":[{"id":"1.230180118","rc":[{"atl":[[1000,0.38]],"id":69624671},{"atl":[[14,37.79]],"id":48534288}],"con":true,"img":false}]}
{"op":"mcm","clk":"11540721121","pt":1719497658849,"mc":[{"id":"1.230180118","rc":[{"atl":[[14.5,0]],"id":48534288}],"con":true,"img":false}]}
{"op":"mcm","clk":"11540721131","pt":1719497658953,"mc":[{"id":"1.230180118","rc":[{"atl":[[1000,0.23]],"id":69624671}],"con":true,"img":false}]}
{"op":"mcm","clk":"11540721138","pt":1719497659012,"mc":[{"id":"1.230180118","rc":[{"atl":[[7.8,0.15]],"id":69624671},{"atl":[[14,34]],"id":48534288}],"con":true,"img":false}]}
{"op":"mcm","clk":"11540721146","pt":1719497659108,"mc":[{"id":"1.230180118","rc":[{"atl":[[16,4.79]],"id":48534288}],"con":true,"img":false}]}
{"op":"mcm","clk":"11540721158","pt":1719497659313,"mc":[{"id":"1.230180118","rc":[{"atl":[[16,1]],"id":48534288}],"con":true,"img":false}]}
{"op":"mcm","clk":"11540721165","pt":1719497659415,"mc":[{"id":"1.230180118","rc":[{"atl":[[13.5,3.79]],"id":48534288}],"con":true,"img":false}]}
{"op":"mcm","clk":"11540721175","pt":1719497659521,"mc":[{"id":"1.230180118","rc":[{"atb":[[3.35,4.2]],"id":69624671},{"atl":[[13.5,37.79],[14,0]],"id":48534288}],"con":true,"img":false}]}
{"op":"mcm","clk":"11540721200","pt":1719497659825,"mc":[{"id":"1.230180118","rc":[{"atl":[[13.5,34]],"id":48534288}],"con":true,"img":false}]}
{"op":"mcm","clk":"11540721208","pt":1719497659934,"mc":[{"id":"1.230180118","rc":[{"atl":[[16,4.79]],"id":48534288}],"con":true,"img":false}]}
{"op":"mcm","clk":"11540721223","pt":1719497660132,"mc":[{"id":"1.230180118","rc":[{"atl":[[16,1]],"id":48534288}],"con":true,"img":false}]}
{"op":"mcm","clk":"11540721234","pt":1719497660235,"mc":[{"id":"1.230180118","rc":[{"atl":[[13,3.79]],"id":48534288}],"con":true,"img":false}]}
{"op":"mcm","clk":"11540721240","pt":1719497660337,"mc":[{"id":"1.230180118","rc":[{"atl":[[13,37.79],[13.5,0]],"id":48534288}],"con":true,"img":false}]}
{"op":"mcm","clk":"11540721249","pt":1719497660440,"mc":[{"id":"1.230180118","rc":[{"atl":[[22,4.76],[13,34],[27,0]],"id":48534288}],"con":true,"img":false}]}
{"op":"mcm","clk":"11540721256","pt":1719497660544,"mc":[{"id":"1.230180118","rc":[{"atl":[[16,4.79]],"id":48534288}],"con":true,"img":false}]}
{"op":"mcm","clk":"11540721270","pt":1719497660747,"mc":[{"id":"1.230180118","rc":[{"atl":[[16,1]],"id":48534288}],"con":true,"img":false}]}
{"op":"mcm","clk":"11540721278","pt":1719497660855,"mc":[{"id":"1.230180118","rc":[{"atl":[[12.5,3.79]],"id":48534288},{"atl":[[6.8,2]],"id":69475360}],"con":true,"img":false}]}
{"op":"mcm","clk":"11540721288","pt":1719497660905,"mc":[{"id":"1.230180118","rc":[{"atl":[[12.5,37.79],[13,0]],"id":48534288},{"atl":[[8,3.45],[30,0]],"id":69475360}],"con":true,"img":false}]}
{"op":"mcm","clk":"11540721296","pt":1719497661010,"mc":[{"id":"1.230180118","rc":[{"atl":[[12.5,34]],"id":48534288}],"con":true,"img":false}]}
{"op":"mcm","clk":"11540721307","pt":1719497661110,"mc":[{"id":"1.230180118","rc":[{"atl":[[16,4.79]],"id":48534288}],"con":true,"img":false}]}
{"op":"mcm","clk":"11540721323","pt":1719497661315,"mc":[{"id":"1.230180118","rc":[{"atl":[[16,1]],"id":48534288}],"con":true,"img":false}]}
{"op":"mcm","clk":"11540721328","pt":1719497661420,"mc":[{"id":"1.230180118","rc":[{"atl":[[12,3.79]],"id":48534288}],"con":true,"img":false}]}
{"op":"mcm","clk":"11540721334","pt":1719497661521,"mc":[{"id":"1.230180118","rc":[{"atl":[[12,37.79]],"id":48534288}],"con":true,"img":false}]}
{"op":"mcm","clk":"11540721341","pt":1719497661625,"mc":[{"id":"1.230180118","rc":[{"atl":[[12.5,0]],"id":48534288}],"con":true,"img":false}]}
{"op":"mcm","clk":"11540721351","pt":1719497661828,"mc":[{"id":"1.230180118","rc":[{"atl":[[12,34]],"id":48534288}],"con":true,"img":false}]}
{"op":"mcm","clk":"11540721357","pt":1719497661932,"mc":[{"id":"1.230180118","rc":[{"atl":[[16,4.79]],"id":48534288}],"con":true,"img":false}]}
{"op":"mcm","clk":"11540721372","pt":1719497662142,"mc":[{"id":"1.230180118","rc":[{"atl":[[16,1]],"id":48534288}],"con":true,"img":false}]}
{"op":"mcm","clk":"11540721380","pt":1719497662239,"mc":[{"id":"1.230180118","rc":[{"atl":[[11.5,3.79]],"id":48534288}],"con":true,"img":false}]}
{"op":"mcm","clk":"11540721387","pt":1719497662347,"mc":[{"id":"1.230180118","rc":[{"atl":[[11.5,37.79]],"id":48534288}],"con":true,"img":false}]}
{"op":"mcm","clk":"11540721396","pt":1719497662445,"mc":[{"id":"1.230180118","rc":[{"atl":[[12,0]],"id":48534288}],"con":true,"img":false}]}
{"op":"mcm","clk":"11540721406","pt":1719497662650,"mc":[{"id":"1.230180118","rc":[{"atl":[[11.5,34]],"id":48534288}],"con":true,"img":false}]}
{"op":"mcm","clk":"11540721415","pt":1719497662704,"mc":[{"id":"1.230180118","rc":[{"atl":[[16,4.79]],"id":48534288}],"con":true,"img":false}]}
{"op":"mcm","clk":"11540721434","pt":1719497662911,"mc":[{"id":"1.230180118","rc":[{"atl":[[16,1]],"id":48534288}],"con":true,"img":false}]}
{"op":"mcm","clk":"11540721446","pt":1719497663018,"mc":[{"id":"1.230180118","rc":[{"atl":[[11,3.79]],"id":48534288}],"con":true,"img":false}]}
{"op":"mcm","clk":"11540721455","pt":1719497663124,"mc":[{"id":"1.230180118","rc":[{"atl":[[11,37.79],[11.5,0]],"id":48534288},{"atl":[[29,0.01]],"id":69475360}],"con":true,"img":false}]}
{"op":"mcm","clk":"11540721474","pt":1719497663322,"mc":[{"id":"1.230180118","rc":[{"atl":[[11,34]],"id":48534288},{"atl":[[1000,0.41]],"id":69475360}],"con":true,"img":false}]}
{"op":"mcm","clk":"11540721482","pt":1719497663426,"mc":[{"id":"1.230180118","rc":[{"atl":[[16,4.79]],"id":48534288}],"con":true,"img":false}]}
{"op":"mcm","clk":"11540721492","pt":1719497663530,"mc":[{"id":"1.230180118","rc":[{"atl":[[1000,0.23]],"id":69475360}],"con":true,"img":false}]}
{"op":"mcm","clk":"11540721500","pt":1719497663633,"mc":[{"id":"1.230180118","rc":[{"atl":[[16,1]],"id":48534288},{"atl":[[6.6,0.18]],"id":69475360}],"con":true,"img":false}]}
{"op":"mcm","clk":"11540721508","pt":1719497663735,"mc":[{"id":"1.230180118","rc":[{"atl":[[10.5,3.79]],"id":48534288}],"con":true,"img":false}]}
{"op":"mcm","clk":"11540721519","pt":1719497663838,"mc":[{"id":"1.230180118","rc":[{"atl":[[10.5,37.79],[11,0]],"id":48534288}],"con":true,"img":false}]}
{"op":"mcm","clk":"11540721542","pt":1719497664049,"mc":[{"id":"1.230180118","rc":[{"atl":[[10.5,34]],"id":48534288}],"con":true,"img":false}]}
{"op":"mcm","clk":"11540721552","pt":1719497664155,"mc":[{"id":"1.230180118","rc":[{"atl":[[16,4.79]],"id":48534288},{"atb":[[2.36,3.38],[2.6,12.9]],"id":69475360}],"con":true,"img":false}]}
{"op":"mcm","clk":"11540721574","pt":1719497664357,"mc":[{"id":"1.230180118","rc":[{"atl":[[16,1]],"id":48534288}],"con":true,"img":false}]}
{"op":"mcm","clk":"11540721584","pt":1719497664408,"mc":[{"id":"1.230180118","rc":[{"atl":[[10,3.79]],"id":48534288},{"atb":[[2.64,3.15]],"id":69475360}],"con":true,"img":false}]}
{"op":"mcm","clk":"11540721593","pt":1719497664511,"mc":[{"id":"1.230180118","rc":[{"atl":[[10,37.79]],"id":48534288}],"con":true,"img":false}]}
{"op":"mcm","clk":"11540721598","pt":1719497664614,"mc":[{"id":"1.230180118","rc":[{"atl":[[10.5,0]],"id":48534288}],"con":true,"img":false}]}
{"op":"mcm","clk":"11540721608","pt":1719497664820,"mc":[{"id":"1.230180118","rc":[{"atl":[[10,34]],"id":48534288}],"con":true,"img":false}]}
{"op":"mcm","clk":"11540721614","pt":1719497664929,"mc":[{"id":"1.230180118","rc":[{"atl":[[16,4.79]],"id":48534288}],"con":true,"img":false}]}
{"op":"mcm","clk":"11540721632","pt":1719497665133,"mc":[{"id":"1.230180118","rc":[{"atl":[[16,1]],"id":48534288}],"con":true,"img":false}]}
{"op":"mcm","clk":"11540721641","pt":1719497665238,"mc":[{"id":"1.230180118","rc":[{"atl":[[9.8,3.79]],"id":48534288}],"con":true,"img":false}]}
{"op":"mcm","clk":"11540721649","pt":1719497665338,"mc":[{"id":"1.230180118","rc":[{"atl":[[9.8,37.79]],"id":48534288}],"con":true,"img":false}]}
{"op":"mcm","clk":"11540721658","pt":1719497665438,"mc":[{"id":"1.230180118","rc":[{"atl":[[10,0]],"id":48534288}],"con":true,"img":false}]}
{"op":"mcm","clk":"11540721669","pt":1719497665642,"mc":[{"id":"1.230180118","rc":[{"atl":[[9.8,34]],"id":48534288}],"con":true,"img":false}]}
{"op":"mcm","clk":"11540721675","pt":1719497665751,"mc":[{"id":"1.230180118","rc":[{"atl":[[16,4.79]],"id":48534288}],"con":true,"img":false}]}
{"op":"mcm","clk":"11540721685","pt":1719497665948,"mc":[{"id":"1.230180118","rc":[{"atl":[[16,1]],"id":48534288}],"con":true,"img":false}]}
{"op":"mcm","clk":"11540721688","pt":1719497666057,"mc":[{"id":"1.230180118","rc":[{"atl":[[9.6,3.79]],"id":48534288},{"atl":[[6.8,0]],"id":69475360}],"con":true,"img":false}]}
{"op":"mcm","clk":"11540721695","pt":1719497666154,"mc":[{"id":"1.230180118","rc":[{"atl":[[9.6,37.79]],"id":48534288}],"con":true,"img":false}]}
{"op":"mcm","clk":"11540721704","pt":1719497666255,"mc":[{"id":"1.230180118","rc":[{"atl":[[9.8,0]],"id":48534288}],"con":true,"img":false}]}
{"op":"mcm","clk":"11540721719","pt":1719497666465,"mc":[{"id":"1.230180118","rc":[{"atl":[[9.6,34]],"id":48534288}],"con":true,"img":false}]}
{"op":"mcm","clk":"11540721730","pt":1719497666572,"mc":[{"id":"1.230180118","rc":[{"atl":[[16,4.79]],"id":48534288}],"con":true,"img":false}]}
{"op":"mcm","clk":"11540721753","pt":1719497666822,"mc":[{"id":"1.230180118","rc":[{"atl":[[16,1]],"id":48534288}],"con":true,"img":false}]}
{"op":"mcm","clk":"11540721760","pt":1719497666936,"mc":[{"id":"1.230180118","rc":[{"atl":[[9.4,3.79]],"id":48534288}],"con":true,"img":false}]}
{"op":"mcm","clk":"11540721776","pt":1719497667135,"mc":[{"id":"1.230180118","rc":[{"atl":[[9.6,0],[9.4,37.79]],"id":48534288}],"con":true,"img":false}]}
{"op":"mcm","clk":"11540721791","pt":1719497667336,"mc":[{"id":"1.230180118","rc":[{"atl":[[9.4,34]],"id":48534288}],"con":true,"img":false}]}
{"op":"mcm","clk":"11540721803","pt":1719497667439,"mc":[{"id":"1.230180118","rc":[{"atl":[[16,4.79]],"id":48534288}],"con":true,"img":false}]}
{"op":"mcm","clk":"11540721815","pt":1719497667542,"mc":[{"id":"1.230180118","rc":[{"atl":[[16,1]],"id":48534288}],"con":true,"img":false}]}
{"op":"mcm","clk":"11540721826","pt":1719497667653,"mc":[{"id":"1.230180118","rc":[{"atl":[[9.2,3.79]],"id":48534288}],"con":true,"img":false}]}
{"op":"mcm","clk":"11540721845","pt":1719497667871,"mc":[{"id":"1.230180118","rc":[{"atl":[[9.2,37.79]],"id":48534288}],"con":true,"img":false}]}
{"op":"mcm","clk":"11540721856","pt":1719497667958,"mc":[{"id":"1.230180118","rc":[{"atl":[[9.4,0]],"id":48534288}],"con":true,"img":false}]}
{"op":"mcm","clk":"11540721863","pt":1719497668059,"mc":[{"id":"1.230180118","rc":[{"atl":[[9.2,34]],"id":48534288}],"con":true,"img":false}]}
{"op":"mcm","clk":"11540721871","pt":1719497668161,"mc":[{"id":"1.230180118","rc":[{"atl":[[16,4.79]],"id":48534288}],"con":true,"img":false}]}
{"op":"mcm","clk":"11540721883","pt":1719497668362,"mc":[{"id":"1.230180118","rc":[{"atl":[[16,1]],"id":48534288}],"con":true,"img":false}]}
{"op":"mcm","clk":"11540721892","pt":1719497668413,"mc":[{"id":"1.230180118","rc":[{"atl":[[9,3.79]],"id":48534288},{"atl":[[6.8,2]],"id":69475360}],"con":true,"img":false}]}
{"op":"mcm","clk":"11540721899","pt":1719497668515,"mc":[{"id":"1.230180118","rc":[{"atl":[[9,37.79]],"id":48534288}],"con":true,"img":false}]}
{"op":"mcm","clk":"11540721905","pt":1719497668620,"mc":[{"id":"1.230180118","rc":[{"atl":[[9.2,0]],"id":48534288}],"con":true,"img":false}]}
{"op":"mcm","clk":"11540721918","pt":1719497668831,"mc":[{"id":"1.230180118","rc":[{"atl":[[9,34]],"id":48534288}],"con":true,"img":false}]}
{"op":"mcm","clk":"11540721927","pt":1719497668929,"mc":[{"id":"1.230180118","rc":[{"atl":[[16,4.79]],"id":48534288}],"con":true,"img":false}]}
{"op":"mcm","clk":"11540721943","pt":1719497669139,"mc":[{"id":"1.230180118","rc":[{"spn":10.5,"spf":"NaN","id":50772801},{"spn":8.25,"spf":"NaN","id":62145089},{"spn":4.3,"spf":1.0,"id":69624671},{"spn":3.17,"spf":1.0,"id":60276470},{"atl":[[16,1]],"id":48534288},{"spn":7.0,"spf":"NaN","id":48534288},{"spn":2.81,"spf":1.0,"id":69475360}],"con":true,"img":false}]}
{"op":"mcm","clk":"11540721952","pt":1719497669235,"mc":[{"id":"1.230180118","rc":[{"atl":[[8.8,3.79]],"id":48534288}],"con":true,"img":false}]}
{"op":"mcm","clk":"11540721968","pt":1719497669441,"mc":[{"id":"1.230180118","rc":[{"atl":[[9,0],[8.8,37.79]],"id":48534288}],"con":true,"img":false}]}
{"op":"mcm","clk":"11540721983","pt":1719497669648,"mc":[{"id":"1.230180118","rc":[{"atb":[[4.3,0]],"id":69624671},{"trd":[[4.3,1.99]],"ltp":4.3,"tv":1.99,"id":69624671},{"atb":[[5,0]],"id":48534288},{"atl":[[8.8,34]],"id":48534288},{"trd":[[5,1.99]],"ltp":5.0,"tv":1.99,"id":48534288}],"con":true,"img":false}]}
{"op":"mcm","clk":"11540721993","pt":1719497669758,"mc":[{"id":"1.230180118","rc":[{"atl":[[16,4.79]],"id":48534288}],"con":true,"img":false}]}
{"op":"mcm","clk":"11540722004","pt":1719497669854,"mc":[{"id":"1.230180118","rc":[{"atb":[[3.4,6.34]],"id":69624671},{"atl":[[8.6,2.95]],"id":48534288}],"con":true,"img":false}]}
{"op":"mcm","clk":"11540722015","pt":1719497669960,"mc":[{"id":"1.230180118","rc":[{"atl":[[16,1],[8.6,36.95]],"id":48534288}],"con":true,"img":false}]}
{"op":"mcm","clk":"11540722024","pt":1719497670059,"mc":[{"id":"1.230180118","rc":[{"atl":[[8.6,40.74],[8.8,0]],"id":48534288}],"con":true,"img":false}]}
{"op":"mcm","clk":"11540722031","pt":1719497670116,"mc":[{"id":"1.230180118","rc":[{"atl":[[8.6,36.95]],"id":48534288}],"con":true,"img":false}]}
{"op":"mcm","clk":"11540722041","pt":1719497670215,"mc":[{"id":"1.230180118","rc":[{"atl":[[16,4.79]],"id":48534288}],"con":true,"img":false}]}
{"op":"mcm","clk":"11540722063","pt":1719497670422,"mc":[{"id":"1.230180118","rc":[{"atl":[[16,1]],"id":48534288}],"con":true,"img":false}]}
{"op":"mcm","clk":"11540722073","pt":1719497670526,"mc":[{"id":"1.230180118","rc":[{"atl":[[8.4,3.79]],"id":48534288}],"con":true,"img":false}]}
{"op":"mcm","clk":"11540722085","pt":1719497670629,"mc":[{"id":"1.230180118","rc":[{"atl":[[8.6,2.95],[8.4,37.79]],"id":48534288}],"con":true,"img":false}]}
{"op":"mcm","clk":"11540722112","pt":1719497670943,"mc":[{"id":"1.230180118","rc":[{"atb":[[4.5,1]],"id":48534288}],"con":true,"img":false}]}
{"op":"mcm","clk":"11540722115","pt":1719497671045,"mc":[{"id":"1.230180118","rc":[{"atb":[[3.35,3.53]],"id":69624671}],"con":true,"img":false}]}
{"op":"mcm","clk":"11540722140","pt":1719497671257,"mc":[{"id":"1.230180118","rc":[{"atl":[[11,0.87]],"id":69624671},{"atl":[[8.6,0]],"id":48534288},{"atl":[[8,0],[9.2,8]],"id":69475360}],"con":true,"img":false}]}
{"op":"mcm","clk":"11540722150","pt":1719497671457,"mc":[{"id":"1.230180118","rc":[{"atl":[[8.2,3.09],[8.4,34]],"id":48534288}],"con":true,"img":false}]}
{"op":"mcm","clk":"11540722155","pt":1719497671560,"mc":[{"id":"1.230180118","rc":[{"atl":[[16,4.79],[8.2,37.09]],"id":48534288}],"con":true,"img":false}]}
{"op":"mcm","clk":"11540722159","pt":1719497671663,"mc":[{"id":"1.230180118","rc":[{"atl":[[8.4,0]],"id":48534288}],"con":true,"img":false}]}
{"op":"mcm","clk":"11540722164","pt":1719497671714,"mc":[{"id":"1.230180118","rc":[{"atl":[[16,1]],"id":48534288}],"con":true,"img":false}]}
{"op":"mcm","clk":"11540722172","pt":1719497671874,"mc":[{"id":"1.230180118","rc":[{"atl":[[8,3.79]],"id":48534288}],"con":true,"img":false}]}
{"op":"mcm","clk":"11540722180","pt":1719497671922,"mc":[{"id":"1.230180118","rc":[{"atl":[[8,37.79]],"id":48534288}],"con":true,"img":false}]}
{"op":"mcm","clk":"11540722187","pt":1719497672030,"mc":[{"id":"1.230180118","rc":[{"atl":[[8.2,3.09]],"id":48534288}],"con":true,"img":false}]}
{"op":"mcm","clk":"11540722195","pt":1719497672129,"mc":[{"id":"1.230180118","rc":[{"atl":[[8.2,0]],"id":48534288}],"con":true,"img":false}]}
{"op":"mcm","clk":"11540722202","pt":1719497672235,"mc":[{"id":"1.230180118","rc":[{"atb":[[6,1.11]],"id":50772801}],"con":true,"img":false}]}
{"op":"mcm","clk":"11540722208","pt":1719497672332,"mc":[{"id":"1.230180118","rc":[{"atb":[[5,3.22],[4.2,0]],"id":50772801},{"atl":[[8,34],[7.8,3.25]],"id":48534288}],"con":true,"img":false}]}
{"op":"mcm","clk":"11540722215","pt":1719497672437,"mc":[{"id":"1.230180118","rc":[{"atb":[[3.45,3.27]],"id":69624671},{"atl":[[16,4.79]],"id":48534288}],"con":true,"img":false}]}
{"op":"mcm","clk":"11540722221","pt":1719497672539,"mc":[{"id":"1.230180118","rc":[{"atl":[[8,0],[7.8,37.25]],"id":48534288}],"con":true,"img":false}]}
{"op":"mcm","clk":"11540722223","pt":1719497672642,"mc":[{"id":"1.230180118","rc":[{"atl":[[16,1]],"id":48534288}],"con":true,"img":false}]}
{"op":"mcm","clk":"11540722234","pt":1719497672746,"mc":[{"id":"1.230180118","rc":[{"atl":[[7.6,3.79]],"id":48534288}],"con":true,"img":false}]}
{"op":"mcm","clk":"11540722242","pt":1719497672848,"mc":[{"id":"1.230180118","rc":[{"atl":[[7.6,37.79],[7.8,3.25]],"id":48534288}],"con":true,"img":false}]}
{"op":"mcm","clk":"11540722259","pt":1719497673060,"mc":[{"id":"1.230180118","rc":[{"atb":[[3.4,0]],"id":69624671},{"atl":[[7.8,0]],"id":48534288}],"con":true,"img":false}]}
{"op":"mcm","clk":"11540722278","pt":1719497673266,"mc":[{"id":"1.230180118","rc":[{"atl":[[7.4,3.42],[7.6,34]],"id":48534288}],"con":true,"img":false}]}
{"op":"mcm","clk":"11540722290","pt":1719497673369,"mc":[{"id":"1.230180118","rc":[{"atl":[[16,4.79],[7.4,37.42],[7.6,0]],"id":48534288}],"con":true,"img":false}]}
{"op":"mcm","clk":"11540722304","pt":1719497673519,"mc":[{"id":"1.230180118","rc":[{"atl":[[16,1]],"id":48534288}],"con":true,"img":false}]}
{"op":"mcm","clk":"11540722314","pt":1719497673622,"mc":[{"id":"1.230180118","rc":[{"atl":[[7.2,3.79]],"id":48534288},{"atl":[[6.8,0]],"id":69475360}],"con":true,"img":false}]}
{"op":"mcm","clk":"11540722320","pt":1719497673729,"mc":[{"id":"1.230180118","rc":[{"atl":[[7.2,37.79],[7.4,3.42]],"id":48534288}],"con":true,"img":false}]}
{"op":"mcm","clk":"11540722340","pt":1719497673937,"mc":[{"id":"1.230180118","rc":[{"atl":[[7.4,0]],"id":48534288}],"con":true,"img":false}]}
{"op":"mcm","clk":"11540722350","pt":1719497674036,"mc":[{"id":"1.230180118","rc":[{"atl":[[7.2,34]],"id":48534288}],"con":true,"img":false}]}
{"op":"mcm","clk":"11540722364","pt":1719497674330,"mc":[{"id":"1.230180118","rc":[{"atl":[[16,4.79],[7,3.63]],"id":48534288}],"con":true,"img":false}]}
{"op":"mcm","clk":"11540722378","pt":1719497674338,"mc":[{"id":"1.230180118","rc":[{"atl":[[7.8,0]],"id":69624671}],"con":true,"img":false}]}
{"op":"mcm","clk":"11540722384","pt":1719497674348,"mc":[{"id":"1.230180118","rc":[{"atl":[[16,1]],"id":48534288}],"con":true,"img":false}]}
{"op":"mcm","clk":"11540722392","pt":1719497674447,"mc":[{"id":"1.230180118","rc":[{"atl":[[7.2,0],[7,41.42]],"id":48534288}],"con":true,"img":false}]}
{"op":"mcm","clk":"11540722400","pt":1719497674548,"mc":[{"id":"1.230180118","rc":[{"atl":[[1000,0.38]],"id":69624671}],"con":true,"img":false}]}
{"op":"mcm","clk":"11540722407","pt":1719497674652,"mc":[{"id":"1.230180118","rc":[{"atl":[[7,37.63]],"id":48534288}],"con":true,"img":false}]}
{"op":"mcm","clk":"11540722415","pt":1719497674754,"mc":[{"id":"1.230180118","rc":[{"atl":[[1000,0.23]],"id":69624671},{"atl":[[16,4.79]],"id":48534288}],"con":true,"img":false}]}
{"op":"mcm","clk":"11540722425","pt":1719497674856,"mc":[{"id":"1.230180118","rc":[{"atl":[[7.8,0.15]],"id":69624671}],"con":true,"img":false}]}
{"op":"mcm","clk":"11540722432","pt":1719497674959,"mc":[{"id":"1.230180118","rc":[{"atl":[[1000,2.23]],"id":48534288}],"con":true,"img":false}]}
{"op":"mcm","clk":"11540722443","pt":1719497675169,"mc":[{"id":"1.230180118","rc":[{"atl":[[1000,0.73]],"id":48534288}],"con":true,"img":false}]}
{"op":"mcm","clk":"11540722457","pt":1719497675320,"mc":[{"id":"1.230180118","rc":[{"atb":[[6,0]],"id":50772801},{"atl":[[1000,0.23]],"id":48534288}],"con":true,"img":false}]}
{"op":"mcm","clk":"11540722466","pt":1719497675423,"mc":[{"id":"1.230180118","rc":[{"atl":[[6.8,0.5]],"id":48534288}],"con":true,"img":false}]}
{"op":"mcm","clk":"11540722473","pt":1719497675528,"mc":[{"id":"1.230180118","rc":[{"atl":[[6.8,34.5],[7,3.63]],"id":48534288}],"con":true,"img":false}]}
{"op":"mcm","clk":"11540722490","pt":1719497675835,"mc":[{"id":"1.230180118","rc":[{"atl":[[7,0]],"id":48534288}],"con":true,"img":false}]}
{"op":"mcm","clk":"11540722501","pt":1719497676046,"mc":[{"id":"1.230180118","rc":[{"atl":[[7.8,2.15]],"id":69624671},{"atl":[[6.6,3.85]],"id":48534288}],"con":true,"img":false}]}
{"op":"mcm","clk":"11540722507","pt":1719497676148,"mc":[{"id":"1.230180118","rc":[{"atb":[[3.45,0]],"id":69624671},{"atl":[[11.5,2],[8.8,3.15]],"id":69624671},{"atl":[[6.8,0.5]],"id":48534288}],"con":true,"img":false}]}
{"op":"mcm","clk":"11540722542","pt":1719497676656,"mc":[{"id":"1.230180118","rc":[{"atl":[[7.6,1.05]],"id":69624671}],"con":true,"img":false}]}
{"op":"mcm","clk":"11540722552","pt":1719497676759,"mc":[{"id":"1.230180118","rc":[{"atb":[[3.4,0.65]],"id":69624671},{"atl":[[6.6,0]],"id":48534288}],"con":true,"img":false}]}
{"op":"mcm","clk":"11540722558","pt":1719497676862,"mc":[{"id":"1.230180118","rc":[{"atl":[[6.8,34.5]],"id":48534288}],"con":true,"img":false}]}
{"op":"mcm","clk":"11540722568","pt":1719497676965,"mc":[{"id":"1.230180118","rc":[{"atb":[[3.4,7]],"id":69624671},{"atl":[[15.5,1.64]],"id":48534288}],"con":true,"img":false}]}
{"op":"mcm","clk":"11540722608","pt":1719497677428,"mc":[{"id":"1.230180118","rc":[{"atb":[[4.3,4.31],[5,0.99]],"id":50772801}],"con":true,"img":false}]}
{"op":"mcm","clk":"11540722622","pt":1719497677635,"mc":[{"id":"1.230180118","rc":[{"atl":[[15.5,0]],"id":48534288}],"con":true,"img":false}]}
{"op":"mcm","clk":"11540722633","pt":1719497677840,"mc":[{"id":"1.230180118","rc":[{"atl":[[7.8,0.15]],"id":69624671},{"atl":[[6.6,3.85]],"id":48534288}],"con":true,"img":false}]}
{"op":"mcm","clk":"11540722647","pt":1719497678051,"mc":[{"id":"1.230180118","rc":[{"atl":[[6.8,0.5]],"id":48534288}],"con":true,"img":false}]}
{"op":"mcm","clk":"11540722702","pt":1719497678560,"mc":[{"id":"1.230180118","rc":[{"atl":[[6.6,0]],"id":48534288}],"con":true,"img":false}]}
{"op":"mcm","clk":"11540722710","pt":1719497678663,"mc":[{"id":"1.230180118","rc":[{"atl":[[6.4,3.97],[6.8,34.5]],"id":48534288}],"con":true,"img":false}]}
{"op":"mcm","clk":"11540722717","pt":1719497678767,"mc":[{"id":"1.230180118","rc":[{"atl":[[6.6,0]],"id":69475360}],"con":true,"img":false}]}
{"op":"mcm","clk":"11540722725","pt":1719497678869,"mc":[{"id":"1.230180118","rc":[{"atl":[[6.8,0.5]],"id":48534288}],"con":true,"img":false}]}
{"op":"mcm","clk":"11540722729","pt":1719497678973,"mc":[{"id":"1.230180118","rc":[{"atl":[[9.2,0],[29,3.58],[1000,0.4]],"id":69475360}],"con":true,"img":false}]}
{"op":"mcm","clk":"11540722736","pt":1719497679076,"mc":[{"id":"1.230180118","rc":[{"atl":[[1000,0.23]],"id":69475360}],"con":true,"img":false}]}
{"op":"mcm","clk":"11540722746","pt":1719497679186,"mc":[{"id":"1.230180118","rc":[{"atl":[[6.8,0.17]],"id":69475360}],"con":true,"img":false}]}
{"op":"mcm","clk":"11540722751","pt":1719497679234,"mc":[{"id":"1.230180118","rc":[{"atl":[[6.4,0]],"id":48534288}],"con":true,"img":false}]}
{"op":"mcm","clk":"11540722781","pt":1719497679340,"mc":[{"id":"1.230180118","rc":[{"atl":[[6.8,34.5]],"id":48534288}],"con":true,"img":false}]}
{"op":"mcm","clk":"11540722788","pt":1719497679441,"mc":[{"id":"1.230180118","rc":[{"atl":[[15.5,1.64]],"id":48534288}],"con":true,"img":false}]}
{"op":"mcm","clk":"11540722840","pt":1719497680159,"mc":[{"id":"1.230180118","rc":[{"atl":[[15.5,0]],"id":48534288}],"con":true,"img":false}]}
{"op":"mcm","clk":"11540722866","pt":1719497680365,"mc":[{"id":"1.230180118","rc":[{"atb":[[4.6,0]],"id":48534288},{"atl":[[6.6,3.85]],"id":48534288},{"trd":[[4.6,1.99]],"ltp":4.6,"tv":1.99,"id":48534288}],"con":true,"img":false}]}
{"op":"mcm","clk":"11540722877","pt":1719497680474,"mc":[{"id":"1.230180118","rc":[{"atb":[[3.45,3.27]],"id":69624671},{"atl":[[6.8,0.5]],"id":48534288}],"con":true,"img":false}]}
{"op":"mcm","clk":"11540722920","pt":1719497681035,"mc":[{"id":"1.230180118","rc":[{"atb":[[3.9,1]],"id":60276470},{"atb":[[5,1]],"id":48534288},{"atb":[[3.65,1]],"id":69475360}],"con":true,"img":false}]}
{"op":"mcm","clk":"11540722928","pt":1719497681141,"mc":[{"id":"1.230180118","rc":[{"atb":[[3.4,0.65]],"id":69624671},{"atb":[[3.95,0],[2.98,7]],"id":60276470},{"atb":[[4.5,0]],"id":48534288},{"atl":[[6.8,0],[6.6,0]],"id":48534288},{"atb":[[2.8,4.16],[2.62,0],[3.95,0]],"id":69475360}],"con":true,"img":false}]}
{"op":"mcm","clk":"11540722937","pt":1719497681240,"mc":[{"id":"1.230180118","rc":[{"atb":[[2.88,0]],"id":60276470},{"atl":[[16,38.79],[26,4]],"id":48534288}],"con":true,"img":false}]}
{"op":"mcm","clk":"11540722971","pt":1719497681350,"mc":[{"id":"1.230180118","rc":[{"atl":[[22,0]],"id":48534288}],"con":true,"img":false}]}
{"op":"mcm","clk":"11540723000","pt":1719497681861,"mc":[{"id":"1.230180118","rc":[{"atb":[[3.5,6.34]],"id":69624671},{"atl":[[15.5,1.64]],"id":48534288}],"con":true,"img":false}]}
{"op":"mcm","clk":"11540723006","pt":1719497681969,"mc":[{"id":"1.230180118","rc":[{"atl":[[15.5,35.64]],"id":48534288},{"atb":[[2.64,0]],"id":69475360}],"con":true,"img":false}]}
{"op":"mcm","clk":"11540723011","pt":1719497682067,"mc":[{"id":"1.230180118","rc":[{"atb":[[2.16,5.44]],"id":50772801},{"atl":[[16,1]],"id":48534288}],"con":true,"img":false}]}
{"op":"mcm","clk":"11540723024","pt":1719497682174,"mc":[{"id":"1.230180118","rc":[{"atl":[[15,3.79]],"id":48534288}],"con":true,"img":false}]}
{"op":"mcm","clk":"11540723030","pt":1719497682272,"mc":[{"id":"1.230180118","rc":[{"atb":[[2.16,5.44]],"id":62145089},{"atb":[[2.16,5.44]],"id":69624671},{"atl":[[15,37.79],[15.5,1.64]],"id":48534288}],"con":true,"img":false}]}
{"op":"mcm","clk":"11540723047","pt":1719497682480,"mc":[{"id":"1.230180118","rc":[{"atb":[[2.16,5.44]],"id":48534288},{"atb":[[2.8,3.16],[2.98,1]],"id":69475360}],"con":true,"img":false}]}
{"op":"mcm","clk":"11540723068","pt":1719497682638,"mc":[{"id":"1.230180118","rc":[{"atl":[[15.5,0]],"id":48534288}],"con":true,"img":false}]}
{"op":"mcm","clk":"11540723080","pt":1719497682848,"mc":[{"id":"1.230180118","rc":[{"atl":[[14.5,1.75],[15,34]],"id":48534288}],"con":true,"img":false}]}
{"op":"mcm","clk":"11540723087","pt":1719497682946,"mc":[{"id":"1.230180118","rc":[{"atl":[[16,4.79],[14.5,35.75],[15,0]],"id":48534288}],"con":true,"img":false}]}
{"op":"mcm","clk":"11540723104","pt":1719497683156,"mc":[{"id":"1.230180118","rc":[{"atl":[[16,1]],"id":48534288}],"con":true,"img":false}]}
{"op":"mcm","clk":"11540723116","pt":1719497683254,"mc":[{"id":"1.230180118","rc":[{"atl":[[14,3.79]],"id":48534288}],"con":true,"img":false}]}
{"op":"mcm","clk":"11540723123","pt":1719497683358,"mc":[{"id":"1.230180118","rc":[{"atb":[[4.3,4.22]],"id":50772801},{"atb":[[3.35,3.4]],"id":69624671},{"atl":[[11,0.84]],"id":69624671},{"atl":[[14,37.79],[14.5,1.75]],"id":48534288},{"atb":[[2.48,0]],"id":69475360},{"atl":[[29,3.57]],"id":69475360}],"con":true,"img":false}]}
{"op":"mcm","clk":"11540723137","pt":1719497683565,"mc":[{"id":"1.230180118","rc":[{"atl":[[7.4,2]],"id":69624671}],"con":true,"img":false}]}
{"op":"mcm","clk":"11540723160","pt":1719497683872,"mc":[{"id":"1.230180118","rc":[{"atl":[[14.5,0]],"id":48534288}],"con":true,"img":false}]}
{"op":"mcm","clk":"11540723165","pt":1719497683975,"mc":[{"id":"1.230180118","rc":[{"atl":[[13.5,1.87],[14,34]],"id":48534288}],"con":true,"img":false}]}
{"op":"mcm","clk":"11540723173","pt":1719497684083,"mc":[{"id":"1.230180118","rc":[{"atl":[[16,4.79],[13.5,35.87],[14,0]],"id":48534288}],"con":true,"img":false}]}
{"op":"mcm","clk":"11540723189","pt":1719497684288,"mc":[{"id":"1.230180118","rc":[{"atl":[[16,1]],"id":48534288}],"con":true,"img":false}]}
{"op":"mcm","clk":"11540723196","pt":1719497684339,"mc":[{"id":"1.230180118","rc":[{"atl":[[13,3.79]],"id":48534288}],"con":true,"img":false}]}
{"op":"mcm","clk":"11540723206","pt":1719497684445,"mc":[{"id":"1.230180118","rc":[{"atl":[[13,37.79],[13.5,1.87]],"id":48534288}],"con":true,"img":false}]}
{"op":"mcm","clk":"11540723213","pt":1719497684548,"mc":[{"id":"1.230180118","rc":[{"atl":[[13.5,0]],"id":48534288}],"con":true,"img":false}]}
{"op":"mcm","clk":"11540723229","pt":1719497684754,"mc":[{"id":"1.230180118","rc":[{"atb":[[2.36,10.26]],"id":50772801},{"atl":[[12.5,2.03],[13,34]],"id":48534288}],"con":true,"img":false}]}
{"op":"mcm","clk":"11540723239","pt":1719497684858,"mc":[{"id":"1.230180118","rc":[{"atb":[[2.32,12.68]],"id":62145089},{"atb":[[3.55,3.14]],"id":69624671},{"atl":[[7.6,2.37]],"id":69624671},{"atl":[[16,4.79],[12.5,36.03],[13,0]],"id":48534288}],"con":true,"img":false}]}
{"op":"mcm","clk":"11540723259","pt":1719497685066,"mc":[{"id":"1.230180118","rc":[{"atb":[[2.28,10.91]],"id":69624671},{"atl":[[16,1]],"id":48534288}],"con":true,"img":false}]}
{"op":"mcm","clk":"11540723270","pt":1719497685171,"mc":[{"id":"1.230180118","rc":[{"atb":[[2.38,10.12]],"id":48534288},{"atl":[[12,3.79]],"id":48534288}],"con":true,"img":false}]}
{"op":"mcm","clk":"11540723282","pt":1719497685284,"mc":[{"id":"1.230180118","rc":[{"atl":[[12,37.79]],"id":48534288}],"con":true,"img":false}]}
{"op":"mcm","clk":"11540723289","pt":1719497685375,"mc":[{"id":"1.230180118","rc":[{"atb":[[2.38,10.12]],"id":60276470},{"atl":[[12.5,2.03]],"id":48534288}],"con":true,"img":false}]}
{"op":"mcm","clk":"11540723295","pt":1719497685478,"mc":[{"id":"1.230180118","rc":[{"atb":[[3.5,0]],"id":69624671},{"atl":[[12.5,0]],"id":48534288}],"con":true,"img":false}]}
{"op":"mcm","clk":"11540723314","pt":1719497685634,"mc":[{"id":"1.230180118","rc":[{"atl":[[11.5,2.2],[12,34]],"id":48534288}],"con":true,"img":false}]}
{"op":"mcm","clk":"11540723325","pt":1719497685737,"mc":[{"id":"1.230180118","rc":[{"atl":[[16,4.79],[11.5,36.2]],"id":48534288}],"con":true,"img":false}]}
{"op":"mcm","clk":"11540723332","pt":1719497685839,"mc":[{"id":"1.230180118","rc":[{"atl":[[12,0]],"id":48534288}],"con":true,"img":false}]}
{"op":"mcm","clk":"11540723343","pt":1719497685944,"mc":[{"id":"1.230180118","rc":[{"atl":[[16,1]],"id":48534288}],"con":true,"img":false}]}
{"op":"mcm","clk":"11540723350","pt":1719497686044,"mc":[{"id":"1.230180118","rc":[{"atl":[[11,3.79]],"id":48534288}],"con":true,"img":false}]}
{"op":"mcm","clk":"11540723362","pt":1719497686155,"mc":[{"id":"1.230180118","rc":[{"atl":[[11,37.79],[11.5,2.2]],"id":48534288}],"con":true,"img":false}]}
{"op":"mcm","clk":"11540723377","pt":1719497686361,"mc":[{"id":"1.230180118","rc":[{"atl":[[11.5,0]],"id":48534288}],"con":true,"img":false}]}
{"op":"mcm","clk":"11540723394","pt":1719497686559,"mc":[{"id":"1.230180118","rc":[{"atl":[[10.5,2.42],[11,34]],"id":48534288}],"con":true,"img":false}]}
{"op":"mcm","clk":"11540723405","pt":1719497686661,"mc":[{"id":"1.230180118","rc":[{"atl":[[16,4.79],[10.5,36.42],[11,0]],"id":48534288}],"con":true,"img":false}]}
{"op":"mcm","clk":"11540723421","pt":1719497686868,"mc":[{"id":"1.230180118","rc":[{"atl":[[16,1]],"id":48534288}],"con":true,"img":false}]}
{"op":"mcm","clk":"11540723430","pt":1719497686970,"mc":[{"id":"1.230180118","rc":[{"atl":[[10,3.79]],"id":48534288}],"con":true,"img":false}]}
{"op":"mcm","clk":"11540723441","pt":1719497687073,"mc":[{"id":"1.230180118","rc":[{"atl":[[10,37.79],[10.5,2.42]],"id":48534288}],"con":true,"img":false}]}
{"op":"mcm","clk":"11540723472","pt":1719497687485,"mc":[{"id":"1.230180118","rc":[{"atl":[[10.5,0]],"id":48534288}],"con":true,"img":false}]}
{"op":"mcm","clk":"11540723488","pt":1719497687642,"mc":[{"id":"1.230180118","rc":[{"atl":[[10,34],[9.8,2.59]],"id":48534288}],"con":true,"img":false}]}
{"op":"mcm","clk":"11540723497","pt":1719497687744,"mc":[{"id":"1.230180118","rc":[{"atl":[[16,4.79],[9.8,36.59]],"id":48534288}],"con":true,"img":false}]}
{"op":"mcm","clk":"11540723505","pt":1719497687847,"mc":[{"id":"1.230180118","rc":[{"atl":[[10,0]],"id":48534288}],"con":true,"img":false}]}
{"op":"mcm","clk":"11540723512","pt":1719497687954,"mc":[{"id":"1.230180118","rc":[{"atl":[[16,1]],"id":48534288}],"con":true,"img":false}]}
{"op":"mcm","clk":"11540723524","pt":1719497688055,"mc":[{"id":"1.230180118","rc":[{"atl":[[9.6,3.79]],"id":48534288}],"con":true,"img":false}]}
{"op":"mcm","clk":"11540723534","pt":1719497688164,"mc":[{"id":"1.230180118","rc":[{"atl":[[9.6,37.79],[9.8,2.59]],"id":48534288}],"con":true,"img":false}]}
{"op":"mcm","clk":"11540723612","pt":1719497688476,"mc":[{"id":"1.230180118","rc":[{"atl":[[9.8,0]],"id":48534288}],"con":true,"img":false}]}
{"op":"mcm","clk":"11540723665","pt":1719497688682,"mc":[{"id":"1.230180118","rc":[{"atl":[[9.6,34],[9.4,2.7]],"id":48534288}],"con":true,"img":false}]}
{"op":"mcm","clk":"11540723672","pt":1719497688784,"mc":[{"id":"1.230180118","rc":[{"atl":[[7.4,0]],"id":69624671},{"atl":[[16,4.79],[9.4,36.7]],"id":48534288}],"con":true,"img":false}]}
{"op":"mcm","clk":"11540723681","pt":1719497688889,"mc":[{"id":"1.230180118","rc":[{"atl":[[9.6,0]],"id":48534288}],"con":true,"img":false}]}
{"op":"mcm","clk":"11540723685","pt":1719497688941,"mc":[{"id":"1.230180118","rc":[{"atb":[[3.55,0]],"id":69624671},{"atl":[[16,1]],"id":48534288}],"con":true,"img":false}]}
{"op":"mcm","clk":"11540723693","pt":1719497689046,"mc":[{"id":"1.230180118","rc":[{"atl":[[9.2,3.79]],"id":48534288}],"con":true,"img":false}]}
{"op":"mcm","clk":"11540723699","pt":1719497689153,"mc":[{"id":"1.230180118","rc":[{"atl":[[9.2,37.79]],"id":48534288}],"con":true,"img":false}]}
{"op":"mcm","clk":"11540723707","pt":1719497689252,"mc":[{"id":"1.230180118","rc":[{"atl":[[9.4,2.7]],"id":48534288}],"con":true,"img":false}]}
{"op":"mcm","clk":"11540723738","pt":1719497689663,"mc":[{"id":"1.230180118","rc":[{"atl":[[9.4,0]],"id":48534288}],"con":true,"img":false}]}
{"op":"mcm","clk":"11540723750","pt":1719497689868,"mc":[{"id":"1.230180118","rc":[{"atl":[[9,2.81],[9.2,34]],"id":48534288}],"con":true,"img":false}]}
{"op":"mcm","clk":"11540723760","pt":1719497689975,"mc":[{"id":"1.230180118","rc":[{"atl":[[16,4.79],[9,36.81],[9.2,0]],"id":48534288}],"con":true,"img":false}]}
{"op":"mcm","clk":"11540723769","pt":1719497690074,"mc":[{"id":"1.230180118","rc":[{"atl":[[7.8,0]],"id":69624671}],"con":true,"img":false}]}
{"op":"mcm","clk":"11540723782","pt":1719497690182,"mc":[{"id":"1.230180118","rc":[{"atl":[[16,1]],"id":48534288}],"con":true,"img":false}]}
{"op":"mcm","clk":"11540723788","pt":1719497690281,"mc":[{"id":"1.230180118","rc":[{"atl":[[8.8,3.79]],"id":48534288}],"con":true,"img":false}]}
{"op":"mcm","clk":"11540723795","pt":1719497690387,"mc":[{"id":"1.230180118","rc":[{"atl":[[1000,0.39]],"id":69624671},{"atl":[[9,2.81],[8.8,37.79]],"id":48534288}],"con":true,"img":false}]}
{"op":"mcm","clk":"11540723803","pt":1719497690491,"mc":[{"id":"1.230180118","rc":[{"atl":[[7.6,1.05]],"id":69624671}],"con":true,"img":false}]}
{"op":"mcm","clk":"11540723815","pt":1719497690602,"mc":[{"id":"1.230180118","rc":[{"atl":[[1000,0.23]],"id":69624671}],"con":true,"img":false}]}
{"op":"mcm","clk":"11540723821","pt":1719497690647,"mc":[{"id":"1.230180118","rc":[{"atl":[[7.4,0.16]],"id":69624671}],"con":true,"img":false}]}
{"op":"mcm","clk":"11540723830","pt":1719497690750,"mc":[{"id":"1.230180118","rc":[{"atb":[[5,0]],"id":48534288},{"trd":[[5,3.99]],"ltp":5.0,"tv":3.99,"id":48534288}],"con":true,"img":false}]}
{"op":"mcm","clk":"11540723837","pt":1719497690858,"mc":[{"id":"1.230180118","rc":[{"atl":[[9,0]],"id":48534288}],"con":true,"img":false}]}
{"op":"mcm","clk":"11540723857","pt":1719497691058,"mc":[{"id":"1.230180118","rc":[{"atb":[[3.5,6.34]],"id":69624671},{"atb":[[4.5,1]],"id":48534288},{"atl":[[8.6,2.95],[8.8,34]],"id":48534288}],"con":true,"img":false}]}
{"op":"mcm","clk":"11540723864","pt":1719497691161,"mc":[{"id":"1.230180118","rc":[{"atb":[[4.4,1.68]],"id":50772801},{"atb":[[3.65,1.74]],"id":62145089},{"atb":[[3.5,8.04]],"id":69624671},{"atb":[[3.85,1.58]],"id":48534288},{"atl":[[16,4.79]],"id":48534288}],"con":true,"img":false}]}
{"op":"mcm","clk":"11540723872","pt":1719497691265,"mc":[{"id":"1.230180118","rc":[{"atl":[[8.6,1.17]],"id":69624671},{"atl":[[8.6,36.95],[8.8,0]],"id":48534288}],"con":true,"img":false}]}
{"op":"mcm","clk":"11540723884","pt":1719497691370,"mc":[{"id":"1.230180118","rc":[{"atb":[[4.3,0],[4.5,4.22]],"id":50772801},{"atl":[[16,1]],"id":48534288}],"con":true,"img":false}]}
{"op":"mcm","clk":"11540723895","pt":1719497691478,"mc":[{"id":"1.230180118","rc":[{"atl":[[8.4,3.79]],"id":48534288}],"con":true,"img":false}]}
{"op":"mcm","clk":"11540723909","pt":1719497691582,"mc":[{"id":"1.230180118","rc":[{"atl":[[8.6,2.95],[8.4,37.79]],"id":48534288}],"con":true,"img":false}]}
{"op":"mcm","clk":"11540723930","pt":1719497691783,"mc":[{"id":"1.230180118","rc":[{"atl":[[8.6,0]],"id":48534288}],"con":true,"img":false}]}
{"op":"mcm","clk":"11540723946","pt":1719497691881,"mc":[{"id":"1.230180118","rc":[{"atl":[[7.6,0]],"id":69624671},{"atl":[[8.4,34]],"id":48534288}],"con":true,"img":false}]}
{"op":"mcm","clk":"11540723958","pt":1719497691984,"mc":[{"id":"1.230180118","rc":[{"atl":[[7.4,2.16]],"id":69624671},{"atl":[[16,4.79],[8.2,3.09]],"id":48534288}],"con":true,"img":false}]}
{"op":"mcm","clk":"11540723970","pt":1719497692089,"mc":[{"id":"1.230180118","rc":[{"atb":[[3.4,0]],"id":69624671},{"atl":[[16,1],[8.2,37.09],[8.4,0]],"id":48534288}],"con":true,"img":false}]}
{"op":"mcm","clk":"11540723978","pt":1719497692195,"mc":[{"id":"1.230180118","rc":[{"atl":[[8.2,40.88]],"id":48534288}],"con":true,"img":false}]}
{"op":"mcm","clk":"11540723992","pt":1719497692350,"mc":[{"id":"1.230180118","rc":[{"atl":[[8.2,37.09]],"id":48534288}],"con":true,"img":false}]}
{"op":"mcm","clk":"11540723998","pt":1719497692452,"mc":[{"id":"1.230180118","rc":[{"atl":[[16,4.79]],"id":48534288}],"con":true,"img":false}]}
{"op":"mcm","clk":"11540724005","pt":1719497692564,"mc":[{"id":"1.230180118","rc":[{"atl":[[7.4,3.21]],"id":69624671},{"atl":[[16,1]],"id":48534288}],"con":true,"img":false}]}
{"op":"mcm","clk":"11540724010","pt":1719497692656,"mc":[{"id":"1.230180118","rc":[{"atb":[[3.55,0.62]],"id":69624671},{"atl":[[8,3.79]],"id":48534288}],"con":true,"img":false}]}
{"op":"mcm","clk":"11540724016","pt":1719497692760,"mc":[{"id":"1.230180118","rc":[{"atb":[[3.55,3.76]],"id":69624671},{"atl":[[8,37.79],[8.2,3.09]],"id":48534288}],"con":true,"img":false}]}
{"op":"mcm","clk":"11540724028","pt":1719497692967,"mc":[{"id":"1.230180118","rc":[{"atb":[[4.6,0.84]],"id":50772801},{"atb":[[3.65,2.59]],"id":62145089},{"atb":[[3.55,4.6]],"id":69624671},{"atb":[[3,0.84]],"id":60276470},{"atb":[[3.85,2.42]],"id":48534288}],"con":true,"img":false}]}
{"op":"mcm","clk":"11540724036","pt":1719497693069,"mc":[{"id":"1.230180118","rc":[{"atb":[[3.5,6.34]],"id":69624671}],"con":true,"img":false}]}
{"op":"mcm","clk":"11540724044","pt":1719497693179,"mc":[{"id":"1.230180118","rc":[{"atb":[[3.6,1.69]],"id":69624671}],"con":true,"img":false}]}
{"op":"mcm","clk":"11540724051","pt":1719497693275,"mc":[{"id":"1.230180118","rc":[{"atb":[[3.5,0]],"id":69624671},{"atl":[[8.2,0]],"id":48534288}],"con":true,"img":false}]}
{"op":"mcm","clk":"11540724066","pt":1719497693482,"mc":[{"id":"1.230180118","rc":[{"atb":[[3.65,6.34]],"id":69624671},{"atl":[[8,34],[7.8,3.25]],"id":48534288}],"con":true,"img":false}]}
{"op":"mcm","clk":"11540724074","pt":1719497693592,"mc":[{"id":"1.230180118","rc":[{"atb":[[3.85,8.84],[4.5,0]],"id":50772801},{"atl":[[16,0],[20,1]],"id":50772801},{"atl":[[11,1],[11.5,0]],"id":62145089},{"atb":[[3.6,0]],"id":69624671},{"atl":[[8,0],[8.6,5.38],[7.6,1],[8.8,0]],"id":69624671},{"atb":[[3,2.46]],"id":60276470},{"atl":[[6.8,1],[7,0]],"id":60276470},{"atb":[[4.6,1]],"id":48534288},{"atl":[[8,0],[16,4.79],[7.8,37.25]],"id":48534288},{"atl":[[6.8,1.17],[7,0]],"id":69475360}],"con":true,"img":false}]}
{"op":"mcm","clk":"11540724082","pt":1719497693650,"mc":[{"id":"1.230180118","rc":[{"atb":[[3.8,0],[3.9,6]],"id":48534288},{"atl":[[16,1]],"id":48534288}],"con":true,"img":false}]}
{"op":"mcm","clk":"11540724088","pt":1719497693760,"mc":[{"id":"1.230180118","rc":[{"atl":[[7.6,3.79]],"id":48534288}],"con":true,"img":false}]}
{"op":"mcm","clk":"11540724097","pt":1719497693857,"mc":[{"id":"1.230180118","rc":[{"atl":[[7.6,37.79]],"id":48534288}],"con":true,"img":false}]}
{"op":"mcm","clk":"11540724105","pt":1719497693964,"mc":[{"id":"1.230180118","rc":[{"atl":[[7.8,3.25]],"id":48534288}],"con":true,"img":false}]}
{"op":"mcm","clk":"11540724120","pt":1719497694174,"mc":[{"id":"1.230180118","rc":[{"atb":[[3.7,1.69]],"id":69624671},{"atl":[[7.8,0]],"id":48534288}],"con":true,"img":false}]}
{"op":"mcm","clk":"11540724132","pt":1719497694274,"mc":[{"id":"1.230180118","rc":[{"atb":[[4.4,0]],"id":50772801},{"atb":[[3,0.84]],"id":60276470}],"con":true,"img":false}]}
{"op":"mcm","clk":"11540724140","pt":1719497694371,"mc":[{"id":"1.230180118","rc":[{"atl":[[7.4,3.42],[7.6,34]],"id":48534288},{"atl":[[6.8,1]],"id":69475360}],"con":true,"img":false}]}
{"op":"mcm","clk":"11540724146","pt":1719497694474,"mc":[{"id":"1.230180118","rc":[{"atl":[[16,4.79],[7.4,37.42],[7.6,0]],"id":48534288}],"con":true,"img":false}]}
{"op":"mcm","clk":"11540724163","pt":1719497694690,"mc":[{"id":"1.230180118","rc":[{"atl":[[16,1]],"id":48534288},{"atl":[[1000,0.4]],"id":69475360}],"con":true,"img":false}]}
{"op":"mcm","clk":"11540724169","pt":1719497694782,"mc":[{"id":"1.230180118","rc":[{"atb":[[3,2.46]],"id":60276470},{"atl":[[7.2,3.79]],"id":48534288}],"con":true,"img":false}]}
{"op":"mcm","clk":"11540724176","pt":1719497694886,"mc":[{"id":"1.230180118","rc":[{"atl":[[7.2,37.79],[7.4,3.42]],"id":48534288},{"atl":[[1000,0.23]],"id":69475360}],"con":true,"img":false}]}
{"op":"mcm","clk":"11540724188","pt":1719497694993,"mc":[{"id":"1.230180118","rc":[{"atb":[[4.6,0.26]],"id":50772801},{"atb":[[3.65,2]],"id":62145089},{"atb":[[3.55,4.04]],"id":69624671},{"atb":[[3,1.88]],"id":60276470},{"atl":[[6.8,1.17]],"id":69475360}],"con":true,"img":false}]}
{"op":"mcm","clk":"11540724203","pt":1719497695197,"mc":[{"id":"1.230180118","rc":[{"atb":[[3.65,0]],"id":69624671},{"atl":[[7.4,0]],"id":48534288}],"con":true,"img":false}]}
{"op":"mcm","clk":"11540724219","pt":1719497695353,"mc":[{"id":"1.230180118","rc":[{"atl":[[7.2,34],[7,3.63]],"id":48534288}],"con":true,"img":false}]}
{"op":"mcm","clk":"11540724227","pt":1719497695452,"mc":[{"id":"1.230180118","rc":[{"atb":[[3.7,0]],"id":69624671},{"atb":[[3,0.27]],"id":60276470},{"atl":[[16,4.79],[7.2,0],[7,37.63]],"id":48534288}],"con":true,"img":false}]}
{"op":"mcm","clk":"11540724306","pt":1719497696585,"mc":[{"id":"1.230180118","rc":[{"atl":[[1000,2.23]],"id":48534288}],"con":true,"img":false}]}
{"op":"mcm","clk":"11540724320","pt":1719497696800,"mc":[{"id":"1.230180118","rc":[{"atl":[[1000,0.73]],"id":48534288}],"con":true,"img":false}]}
{"op":"mcm","clk":"11540724336","pt":1719497696946,"mc":[{"id":"1.230180118","rc":[{"atb":[[4.6,0]],"id":50772801},{"atb":[[3.55,3.76]],"id":69624671},{"atb":[[5,1.05]],"id":48534288},{"atl":[[1000,0.23]],"id":48534288}],"con":true,"img":false}]}
{"op":"mcm","clk":"11540724344","pt":1719497697051,"mc":[{"id":"1.230180118","rc":[{"atb":[[4.2,0.26]],"id":50772801},{"atb":[[1.13,0.27]],"id":69624671},{"atl":[[6.8,0.5]],"id":48534288}],"con":true,"img":false}]}
{"op":"mcm","clk":"11540724351","pt":1719497697158,"mc":[{"id":"1.230180118","rc":[{"atl":[[7.4,1.21]],"id":69624671},{"atl":[[6.8,34.5],[7,3.63]],"id":48534288}],"con":true,"img":false}]}
{"op":"mcm","clk":"11540724393","pt":1719497697563,"mc":[{"id":"1.230180118","rc":[{"atl":[[7,0]],"id":48534288}],"con":true,"img":false}]}
{"op":"mcm","clk":"11540724406","pt":1719497697768,"mc":[{"id":"1.230180118","rc":[{"atb":[[3.6,6.34]],"id":69624671}],"con":true,"img":false}]}
{"op":"mcm","clk":"11540724452","pt":1719497698487,"mc":[{"id":"1.230180118","rc":[{"atb":[[3.65,1.69]],"id":69624671},{"atl":[[6.6,3.85]],"id":48534288}],"con":true,"img":false}]}
{"op":"mcm","clk":"11540724468","pt":1719497698698,"mc":[{"id":"1.230180118","rc":[{"atl":[[6.8,0.5]],"id":48534288}],"con":true,"img":false}]}
{"op":"mcm","clk":"11540724487","pt":1719497698954,"mc":[{"id":"1.230180118","rc":[{"atb":[[1.13,0]],"id":69624671}],"con":true,"img":false}]}
{"op":"mcm","clk":"11540724491","pt":1719497699056,"mc":[{"id":"1.230180118","rc":[{"atb":[[3.65,1.97]],"id":69624671}],"con":true,"img":false}]}
{"op":"mcm","clk":"11540724497","pt":1719497699168,"mc":[{"id":"1.230180118","rc":[{"atb":[[3.6,0]],"id":69624671},{"atl":[[6.6,0]],"id":48534288}],"con":true,"img":false}]}
{"op":"mcm","clk":"11540724509","pt":1719497699260,"mc":[{"id":"1.230180118","rc":[{"atl":[[6.8,34.5]],"id":48534288}],"con":true,"img":false}]}
{"op":"mcm","clk":"11540724517","pt":1719497699369,"mc":[{"id":"1.230180118","rc":[{"atl":[[15.5,1.64]],"id":48534288},{"atl":[[6.6,2]],"id":69475360}],"con":true,"img":false}]}
{"op":"mcm","clk":"11540724528","pt":1719497699466,"mc":[{"id":"1.230180118","rc":[{"atl":[[6.8,34]],"id":48534288},{"atl":[[9,8],[29,0]],"id":69475360}],"con":true,"img":false}]}
{"op":"mcm","clk":"11540724548","pt":1719497699773,"mc":[{"id":"1.230180118","rc":[{"atb":[[3.65,0.27]],"id":69624671}],"con":true,"img":false}]}
{"op":"mcm","clk":"11540724567","pt":1719497700084,"mc":[{"id":"1.230180118","rc":[{"atl":[[15.5,0]],"id":48534288}],"con":true,"img":false}]}
{"op":"mcm","clk":"11540724585","pt":1719497700295,"mc":[{"id":"1.230180118","rc":[{"atb":[[3.6,8.04]],"id":69624671},{"atl":[[6.6,3.85]],"id":48534288}],"con":true,"img":false}]}
{"op":"mcm","clk":"11540724597","pt":1719497700358,"mc":[{"id":"1.230180118","rc":[{"atb":[[5.5,1]],"id":50772801},{"atl":[[20,0],[21,1]],"id":50772801},{"atl":[[6.8,0]],"id":48534288}],"con":true,"img":false}]}
{"op":"mcm","clk":"11540724608","pt":1719497700462,"mc":[{"id":"1.230180118","rc":[{"atb":[[4.9,0]],"id":50772801}],"con":true,"img":false}]}
{"op":"mcm","clk":"11540724657","pt":1719497700881,"mc":[{"id":"1.230180118","rc":[{"atb":[[1.03,180.69]],"id":69624671},{"atl":[[1000,1.93]],"id":69624671}],"con":true,"img":false}]}
{"op":"mcm","clk":"11540724670","pt":1719497700978,"mc":[{"id":"1.230180118","rc":[{"atl":[[6.6,0]],"id":48534288}],"con":true,"img":false}]}
{"op":"mcm","clk":"11540724680","pt":1719497701082,"mc":[{"id":"1.230180118","rc":[{"atl":[[16,38.79]],"id":48534288}],"con":true,"img":false}]}
{"op":"mcm","clk":"11540724688","pt":1719497701189,"mc":[{"id":"1.230180118","rc":[{"atb":[[1.03,179.07]],"id":69624671},{"atl":[[1000,0.26]],"id":69624671},{"atb":[[5,0]],"id":48534288},{"atl":[[22,4.76],[26,0],[15.5,1.64]],"id":48534288},{"trd":[[5,6.1]],"ltp":5.0,"tv":6.1,"id":48534288}],"con":true,"img":false}]}
{"op":"mcm","clk":"11540724700","pt":1719497701289,"mc":[{"id":"1.230180118","rc":[{"atl":[[15.5,35.64]],"id":48534288}],"con":true,"img":false}]}
{"op":"mcm","clk":"11540724721","pt":1719497701391,"mc":[{"id":"1.230180118","rc":[{"atl":[[16,1]],"id":48534288}],"con":true,"img":false}]}
{"op":"mcm","clk":"11540724729","pt":1719497701503,"mc":[{"id":"1.230180118","rc":[{"atb":[[1.03,178.99]],"id":69624671},{"atl":[[1000,0.23]],"id":69624671},{"atb":[[3.85,0.84]],"id":48534288},{"atl":[[15,3.79]],"id":48534288}],"con":true,"img":false}]}
{"op":"mcm","clk":"11540724742","pt":1719497701606,"mc":[{"id":"1.230180118","rc":[{"atb":[[3.65,0.35]],"id":69624671},{"atl":[[7.4,1.24]],"id":69624671},{"atb":[[3.95,1.58]],"id":48534288},{"atl":[[15,37.79],[15.5,1.64]],"id":48534288}],"con":true,"img":false}]}
{"op":"mcm","clk":"11540724766","pt":1719497701810,"mc":[{"id":"1.230180118","rc":[{"atl":[[29,0.78]],"id":62145089},{"atl":[[26,1.69]],"id":60276470},{"atl":[[14.5,0.86]],"id":48534288}],"con":true,"img":false}]}
{"op":"mcm","clk":"11540724777","pt":1719497701864,"mc":[{"id":"1.230180118","rc":[{"atl":[[15.5,0]],"id":48534288}],"con":true,"img":false}]}
{"op":"mcm","clk":"11540724783","pt":1719497701965,"mc":[{"id":"1.230180118","rc":[{"atl":[[14.5,34.86],[15,3.79]],"id":48534288}],"con":true,"img":false}]}
{"op":"mcm","clk":"11540724793","pt":1719497702072,"mc":[{"id":"1.230180118","rc":[{"atb":[[3.95,0]],"id":48534288},{"atl":[[15,0]],"id":48534288}],"con":true,"img":false}]}
{"op":"mcm","clk":"11540724805","pt":1719497702176,"mc":[{"id":"1.230180118","rc":[{"atl":[[16,4.79]],"id":48534288}],"con":true,"img":false}]}
{"op":"mcm","clk":"11540724815","pt":1719497702280,"mc":[{"id":"1.230180118","rc":[{"atb":[[3.2,3.59]],"id":69624671}],"con":true,"img":false}]}
{"op":"mcm","clk":"11540724828","pt":1719497702384,"mc":[{"id":"1.230180118","rc":[{"atl":[[16,1]],"id":48534288},{"atb":[[2.62,3.15]],"id":69475360}],"con":true,"img":false}]}
{"op":"mcm","clk":"11540724841","pt":1719497702492,"mc":[{"id":"1.230180118","rc":[{"atl":[[14,3.79]],"id":48534288},{"atb":[[2.64,4.33]],"id":69475360}],"con":true,"img":false}]}
{"op":"mcm","clk":"11540724854","pt":1719497702591,"mc":[{"id":"1.230180118","rc":[{"atb":[[2.16,12.25]],"id":62145089},{"atl":[[14,39.6],[14.5,0.86]],"id":48534288}],"con":true,"img":false}]}
{"op":"mcm","clk":"11540724878","pt":1719497702799,"mc":[{"id":"1.230180118","rc":[{"atb":[[2.38,15.85]],"id":60276470},{"atl":[[14,35.81]],"id":48534288}],"con":true,"img":false}]}
{"op":"mcm","clk":"11540724889","pt":1719497702854,"mc":[{"id":"1.230180118","rc":[{"atl":[[16,4.79]],"id":48534288}],"con":true,"img":false}]}
{"op":"mcm","clk":"11540724895","pt":1719497702954,"mc":[{"id":"1.230180118","rc":[{"atb":[[3.85,0.25]],"id":48534288}],"con":true,"img":false}]}
{"op":"mcm","clk":"11540724908","pt":1719497703059,"mc":[{"id":"1.230180118","rc":[{"atl":[[16,1],[14.5,0]],"id":48534288}],"con":true,"img":false}]}
{"op":"mcm","clk":"11540724917","pt":1719497703162,"mc":[{"id":"1.230180118","rc":[{"atb":[[3.85,0],[4.2,6.26]],"id":50772801},{"atl":[[13.5,4.65]],"id":48534288}],"con":true,"img":false}]}
{"op":"mcm","clk":"11540724962","pt":1719497703369,"mc":[{"id":"1.230180118","rc":[{"atl":[[13.5,38.65],[14,1.81]],"id":48534288}],"con":true,"img":false}]}
{"op":"mcm","clk":"11540724991","pt":1719497703581,"mc":[{"id":"1.230180118","rc":[{"atl":[[16,0],[15,1]],"id":48534288}],"con":true,"img":false}]}
{"op":"mcm","clk":"11540725018","pt":1719497703894,"mc":[{"id":"1.230180118","rc":[{"atb":[[4.3,1.68]],"id":50772801},{"atl":[[14,0]],"id":48534288}],"con":true,"img":false}]}
{"op":"mcm","clk":"11540725045","pt":1719497704105,"mc":[{"id":"1.230180118","rc":[{"atl":[[13.5,34.86]],"id":48534288}],"con":true,"img":false}]}
{"op":"mcm","clk":"11540725058","pt":1719497704151,"mc":[{"id":"1.230180118","rc":[{"atl":[[15,4.79]],"id":48534288}],"con":true,"img":false}]}
{"op":"mcm","clk":"11540725065","pt":1719497704260,"mc":[{"id":"1.230180118","rc":[{"atl":[[15,1]],"id":48534288}],"con":true,"img":false}]}
{"op":"mcm","clk":"11540725077","pt":1719497704359,"mc":[{"id":"1.230180118","rc":[{"atl":[[13,3.79]],"id":48534288}],"con":true,"img":false}]}
{"op":"mcm","clk":"11540725086","pt":1719497704467,"mc":[{"id":"1.230180118","rc":[{"atb":[[3.65,3.37]],"id":69624671},{"atl":[[13,37.79]],"id":48534288}],"con":true,"img":false}]}
{"op":"mcm","clk":"11540725094","pt":1719497704567,"mc":[{"id":"1.230180118","rc":[{"atl":[[12.5,2.03],[13.5,0.86]],"id":48534288},{"atl":[[6.6,0]],"id":69475360}],"con":true,"img":false}]}
{"op":"mcm","clk":"11540725104","pt":1719497704668,"mc":[{"id":"1.230180118","rc":[{"atl":[[12.5,36.03],[13,0]],"id":48534288},{"atl":[[30,3.45]],"id":69475360}],"con":true,"img":false}]}
{"op":"mcm","clk":"11540725114","pt":1719497704772,"mc":[{"id":"1.230180118","rc":[{"atl":[[12,3.79]],"id":48534288},{"atl":[[9,0]],"id":69475360}],"con":true,"img":false}]}
{"op":"mcm","clk":"11540725127","pt":1719497704874,"mc":[{"id":"1.230180118","rc":[{"atl":[[12,37.79],[13.5,0]],"id":48534288}],"con":true,"img":false}]}
{"op":"mcm","clk":"11540725136","pt":1719497704982,"mc":[{"id":"1.230180118","rc":[{"atb":[[3.85,0]],"id":48534288},{"atl":[[12,38.65],[12.5,2.03]],"id":48534288}],"con":true,"img":false}]}
{"op":"mcm","clk":"11540725149","pt":1719497705085,"mc":[{"id":"1.230180118","rc":[{"atb":[[3.95,0.25]],"id":48534288}],"con":true,"img":false}]}
{"op":"mcm","clk":"11540725159","pt":1719497705189,"mc":[{"id":"1.230180118","rc":[{"atb":[[3.6,6.34]],"id":69624671}],"con":true,"img":false}]}
{"op":"mcm","clk":"11540725170","pt":1719497705287,"mc":[{"id":"1.230180118","rc":[{"atb":[[3.7,1.69]],"id":69624671}],"con":true,"img":false}]}
{"op":"mcm","clk":"11540725180","pt":1719497705393,"mc":[{"id":"1.230180118","rc":[{"atb":[[3.6,0]],"id":69624671},{"atl":[[12.5,0]],"id":48534288},{"atl":[[29,0.78]],"id":69475360}],"con":true,"img":false}]}
{"op":"mcm","clk":"11540725202","pt":1719497705596,"mc":[{"id":"1.230180118","rc":[{"atb":[[3.75,6.34]],"id":69624671},{"atl":[[11.5,2.2],[12,34.86]],"id":48534288}],"con":true,"img":false}]}
{"op":"mcm","clk":"11540725213","pt":1719497705699,"mc":[{"id":"1.230180118","rc":[{"atb":[[3.7,0]],"id":69624671},{"atl":[[11.5,36.2],[15,4.79]],"id":48534288}],"con":true,"img":false}]}
{"op":"mcm","clk":"11540725224","pt":1719497705751,"mc":[{"id":"1.230180118","rc":[{"atl":[[12,0.86]],"id":48534288}],"con":true,"img":false}]}
{"op":"mcm","clk":"11540725235","pt":1719497705907,"mc":[{"id":"1.230180118","rc":[{"atl":[[7.4,1.08]],"id":69624671},{"atl":[[15,1]],"id":48534288}],"con":true,"img":false}]}
{"op":"mcm","clk":"11540725242","pt":1719497706019,"mc":[{"id":"1.230180118","rc":[{"atl":[[11,3.79]],"id":48534288}],"con":true,"img":false}]}
{"op":"mcm","clk":"11540725252","pt":1719497706061,"mc":[{"id":"1.230180118","rc":[{"atl":[[1000,0.39]],"id":69624671},{"atl":[[12,0]],"id":48534288}],"con":true,"img":false}]}
{"op":"mcm","clk":"11540725261","pt":1719497706169,"mc":[{"id":"1.230180118","rc":[{"atl":[[11,38.65],[11.5,2.2]],"id":48534288}],"con":true,"img":false}]}
{"op":"mcm","clk":"11540725281","pt":1719497706275,"mc":[{"id":"1.230180118","rc":[{"atb":[[3.8,1.69]],"id":69624671},{"atl":[[1000,0.23]],"id":69624671},{"atl":[[11.5,0]],"id":48534288}],"con":true,"img":false}]}
{"op":"mcm","clk":"11540725294","pt":1719497706379,"mc":[{"id":"1.230180118","rc":[{"atl":[[7.2,0.16]],"id":69624671},{"atl":[[11,34.86]],"id":48534288}],"con":true,"img":false}]}
{"op":"mcm","clk":"11540725301","pt":1719497706474,"mc":[{"id":"1.230180118","rc":[{"atl":[[10.5,2.42],[15,4.79]],"id":48534288}],"con":true,"img":false}]}
{"op":"mcm","clk":"11540725309","pt":1719497706585,"mc":[{"id":"1.230180118","rc":[{"atl":[[10.5,36.42],[11,0.86]],"id":48534288}],"con":true,"img":false}]}
{"op":"mcm","clk":"11540725321","pt":1719497706682,"mc":[{"id":"1.230180118","rc":[{"atl":[[11,0],[15,1]],"id":48534288}],"con":true,"img":false}]}
{"op":"mcm","clk":"11540725332","pt":1719497706788,"mc":[{"id":"1.230180118","rc":[{"atl":[[10,3.79],[10.5,37.28]],"id":48534288}],"con":true,"img":false}]}
{"op":"mcm","clk":"11540725345","pt":1719497706887,"mc":[{"id":"1.230180118","rc":[{"atl":[[10,37.79],[10.5,3.28]],"id":48534288},{"atl":[[6.6,2]],"id":69475360}],"con":true,"img":false}]}
{"op":"mcm","clk":"11540725359","pt":1719497707098,"mc":[{"id":"1.230180118","rc":[{"atb":[[3.65,3.09]],"id":69624671}],"con":true,"img":false}]}
{"op":"mcm","clk":"11540725369","pt":1719497707207,"mc":[{"id":"1.230180118","rc":[{"atb":[[3.8,1.97],[3.75,0]],"id":69624671},{"atl":[[10.5,0]],"id":48534288}],"con":true,"img":false}]}
{"op":"mcm","clk":"11540725384","pt":1719497707251,"mc":[{"id":"1.230180118","rc":[{"atl":[[9.8,0.86]],"id":48534288}],"con":true,"img":false}]}
{"op":"mcm","clk":"11540725392","pt":1719497707356,"mc":[{"id":"1.230180118","rc":[{"atl":[[10,34],[9.8,37.45]],"id":48534288}],"con":true,"img":false}]}
{"op":"mcm","clk":"11540725401","pt":1719497707460,"mc":[{"id":"1.230180118","rc":[{"atb":[[3.8,0.27]],"id":69624671},{"atl":[[10,0],[15,4.79]],"id":48534288}],"con":true,"img":false}]}
{"op":"mcm","clk":"11540725412","pt":1719497707568,"mc":[{"id":"1.230180118","rc":[{"atl":[[15,1]],"id":48534288}],"con":true,"img":false}]}
{"op":"mcm","clk":"11540725423","pt":1719497707670,"mc":[{"id":"1.230180118","rc":[{"atl":[[9.6,3.79]],"id":48534288}],"con":true,"img":false}]}
{"op":"mcm","clk":"11540725446","pt":1719497707877,"mc":[{"id":"1.230180118","rc":[{"atl":[[7.4,0.03]],"id":69624671},{"atl":[[9.6,37.79],[9.8,3.45]],"id":48534288}],"con":true,"img":false}]}
{"op":"mcm","clk":"11540725468","pt":1719497708082,"mc":[{"id":"1.230180118","rc":[{"atb":[[3.55,3.14]],"id":69624671},{"atl":[[9.8,0.86]],"id":48534288}],"con":true,"img":false}]}
{"op":"mcm","clk":"11540725493","pt":1719497708286,"mc":[{"id":"1.230180118","rc":[{"atb":[[3.7,6.34]],"id":69624671},{"atl":[[9.6,34],[9.4,2.7]],"id":48534288}],"con":true,"img":false}]}
{"op":"mcm","clk":"11540725507","pt":1719497708394,"mc":[{"id":"1.230180118","rc":[{"atl":[[9.6,0],[15,4.79],[9.4,36.7]],"id":48534288}],"con":true,"img":false}]}
{"op":"mcm","clk":"11540725515","pt":1719497708492,"mc":[{"id":"1.230180118","rc":[{"atl":[[7.2,1.21]],"id":69624671},{"atl":[[9.8,0]],"id":48534288}],"con":true,"img":false}]}
{"op":"mcm","clk":"11540725525","pt":1719497708595,"mc":[{"id":"1.230180118","rc":[{"atb":[[3.85,0.55]],"id":69624671},{"atl":[[15,1],[9.4,37.56]],"id":48534288}],"con":true,"img":false}]}
{"op":"mcm","clk":"11540725536","pt":1719497708702,"mc":[{"id":"1.230180118","rc":[{"atb":[[3.75,1.69]],"id":69624671},{"atl":[[9.2,3.79]],"id":48534288}],"con":true,"img":false}]}
{"op":"mcm","clk":"11540725546","pt":1719497708802,"mc":[{"id":"1.230180118","rc":[{"atl":[[9.2,37.79],[9.4,3.56]],"id":48534288}],"con":true,"img":false}]}
{"op":"mcm","clk":"11540725565","pt":1719497708959,"mc":[{"id":"1.230180118","rc":[{"atb":[[3.7,0]],"id":69624671},{"atl":[[9.4,0.86]],"id":48534288}],"con":true,"img":false}]}
{"op":"mcm","clk":"11540725586","pt":1719497709175,"mc":[{"id":"1.230180118","rc":[{"atl":[[9.2,34]],"id":48534288}],"con":true,"img":false}]}
{"op":"mcm","clk":"11540725597","pt":1719497709267,"mc":[{"id":"1.230180118","rc":[{"atl":[[15,4.79]],"id":48534288}],"con":true,"img":false}]}
{"op":"mcm","clk":"11540725608","pt":1719497709375,"mc":[{"id":"1.230180118","rc":[{"atb":[[3.75,0]],"id":69624671}],"con":true,"img":false}]}
{"op":"mcm","clk":"11540725622","pt":1719497709481,"mc":[{"id":"1.230180118","rc":[{"atl":[[15,1]],"id":48534288}],"con":true,"img":false}]}
{"op":"mcm","clk":"11540725631","pt":1719497709582,"mc":[{"id":"1.230180118","rc":[{"atl":[[9,3.79]],"id":48534288}],"con":true,"img":false}]}
{"op":"mcm","clk":"11540725643","pt":1719497709682,"mc":[{"id":"1.230180118","rc":[{"atb":[[3.7,6.34]],"id":69624671},{"atl":[[9,6.6]],"id":48534288}],"con":true,"img":false}]}
{"op":"mcm","clk":"11540725652","pt":1719497709790,"mc":[{"id":"1.230180118","rc":[{"atl":[[9,40.6]],"id":48534288}],"con":true,"img":false}]}
{"op":"mcm","clk":"11540725664","pt":1719497709888,"mc":[{"id":"1.230180118","rc":[{"atl":[[9.2,0]],"id":48534288}],"con":true,"img":false}]}
{"op":"mcm","clk":"11540725685","pt":1719497710095,"mc":[{"id":"1.230180118","rc":[{"atl":[[9,36.81]],"id":48534288}],"con":true,"img":false}]}
{"op":"mcm","clk":"11540725694","pt":1719497710196,"mc":[{"id":"1.230180118","rc":[{"atl":[[15,4.79]],"id":48534288},{"atl":[[6.8,1]],"id":69475360}],"con":true,"img":false}]}
{"op":"mcm","clk":"11540725706","pt":1719497710298,"mc":[{"id":"1.230180118","rc":[{"atl":[[9.4,0]],"id":48534288}],"con":true,"img":false}]}
{"op":"mcm","clk":"11540725715","pt":1719497710407,"mc":[{"id":"1.230180118","rc":[{"atl":[[8.8,0.86],[15,1]],"id":48534288},{"atl":[[1000,0.42]],"id":69475360}],"con":true,"img":false}]}
{"op":"mcm","clk":"11540725725","pt":1719497710511,"mc":[{"id":"1.230180118","rc":[{"atl":[[8.8,38.65]],"id":48534288}],"con":true,"img":false}]}
{"op":"mcm","clk":"11540725733","pt":1719497710557,"mc":[{"id":"1.230180118","rc":[{"atl":[[9,2.81]],"id":48534288}],"con":true,"img":false}]}
{"op":"mcm","clk":"11540725741","pt":1719497710664,"mc":[{"id":"1.230180118","rc":[{"atl":[[1000,0.23]],"id":69475360}],"con":true,"img":false}]}
{"op":"mcm","clk":"11540725749","pt":1719497710763,"mc":[{"id":"1.230180118","rc":[{"atl":[[6.4,0.19]],"id":69475360}],"con":true,"img":false}]}
{"op":"mcm","clk":"11540725763","pt":1719497710969,"mc":[{"id":"1.230180118","rc":[{"atl":[[9,0]],"id":48534288}],"con":true,"img":false}]}
{"op":"mcm","clk":"11540725771","pt":1719497711076,"mc":[{"id":"1.230180118","rc":[{"atb":[[3.8,0]],"id":69624671}],"con":true,"img":false}]}
{"op":"mcm","clk":"11540725781","pt":1719497711173,"mc":[{"id":"1.230180118","rc":[{"atb":[[3.75,0.27]],"id":69624671},{"atl":[[8.6,2.95],[8.8,34.86]],"id":48534288}],"con":true,"img":false}]}
{"op":"mcm","clk":"11540725789","pt":1719497711286,"mc":[{"id":"1.230180118","rc":[{"atl":[[8.6,36.95],[8.8,0.86],[15,4.79]],"id":48534288}],"con":true,"img":false}]}
{"op":"mcm","clk":"11540725815","pt":1719497711484,"mc":[{"id":"1.230180118","rc":[{"atl":[[8.8,0],[15,1]],"id":48534288}],"con":true,"img":false}]}
{"op":"mcm","clk":"11540725826","pt":1719497711587,"mc":[{"id":"1.230180118","rc":[{"atl":[[8.4,4.65]],"id":48534288}],"con":true,"img":false}]}
{"op":"mcm","clk":"11540725838","pt":1719497711690,"mc":[{"id":"1.230180118","rc":[{"atl":[[8.6,2.95],[8.4,38.65]],"id":48534288}],"con":true,"img":false}]}
{"op":"mcm","clk":"11540725856","pt":1719497711900,"mc":[{"id":"1.230180118","rc":[{"atl":[[8.6,0]],"id":48534288}],"con":true,"img":false}]}
{"op":"mcm","clk":"11540725879","pt":1719497712106,"mc":[{"id":"1.230180118","rc":[{"atl":[[8.2,3.09],[8.4,34.86]],"id":48534288},{"atl":[[6.6,0]],"id":69475360}],"con":true,"img":false}]}
{"op":"mcm","clk":"11540725889","pt":1719497712209,"mc":[{"id":"1.230180118","rc":[{"atb":[[3.75,3.18]],"id":69624671},{"atl":[[8.2,37.09],[15,4.79]],"id":48534288}],"con":true,"img":false}]}
{"op":"mcm","clk":"11540725898","pt":1719497712259,"mc":[{"id":"1.230180118","rc":[{"atl":[[8.4,0.86],[15,1]],"id":48534288}],"con":true,"img":false}]}
{"op":"mcm","clk":"11540725904","pt":1719497712362,"mc":[{"id":"1.230180118","rc":[{"atl":[[8,3.79]],"id":48534288}],"con":true,"img":false}]}
{"op":"mcm","clk":"11540725912","pt":1719497712471,"mc":[{"id":"1.230180118","rc":[{"atb":[[4.6,0]],"id":48534288},{"atl":[[8,34],[8.2,3.09]],"id":48534288},{"trd":[[4.6,3.99]],"ltp":4.6,"tv":3.99,"id":48534288}],"con":true,"img":false}]}
{"op":"mcm","clk":"11540725924","pt":1719497712568,"mc":[{"id":"1.230180118","rc":[{"atl":[[15,4.79]],"id":48534288}],"con":true,"img":false}]}
{"op":"mcm","clk":"11540725932","pt":1719497712671,"mc":[{"id":"1.230180118","rc":[{"atl":[[8.4,0]],"id":48534288}],"con":true,"img":false}]}
{"op":"mcm","clk":"11540725944","pt":1719497712774,"mc":[{"id":"1.230180118","rc":[{"atb":[[3.7,0]],"id":69624671},{"atl":[[8.2,0],[7.8,0.86],[15,1]],"id":48534288}],"con":true,"img":false}]}
{"op":"mcm","clk":"11540725953","pt":1719497712876,"mc":[{"id":"1.230180118","rc":[{"atb":[[3.8,1.69]],"id":69624671},{"atl":[[8,0],[7.8,38.65]],"id":48534288}],"con":true,"img":false}]}
{"op":"mcm","clk":"11540725973","pt":1719497713089,"mc":[{"id":"1.230180118","rc":[{"atb":[[3.75,2.91]],"id":69624671},{"atb":[[3.95,0]],"id":48534288}],"con":true,"img":false}]}
{"op":"mcm","clk":"11540725987","pt":1719497713192,"mc":[{"id":"1.230180118","rc":[{"atb":[[1.13,0.27]],"id":69624671},{"atb":[[1.14,0.25]],"id":48534288}],"con":true,"img":false}]}
{"op":"mcm","clk":"11540726016","pt":1719497713499,"mc":[{"id":"1.230180118","rc":[{"atb":[[3.8,0]],"id":69624671},{"atl":[[7.6,3.34]],"id":48534288}],"con":true,"img":false}]}
{"op":"mcm","clk":"11540726026","pt":1719497713601,"mc":[{"id":"1.230180118","rc":[{"atb":[[4.6,1]],"id":48534288},{"atl":[[7.6,37.34],[7.8,0.86]],"id":48534288}],"con":true,"img":false}]}
{"op":"mcm","clk":"11540726038","pt":1719497713656,"mc":[{"id":"1.230180118","rc":[{"atl":[[7.4,3.79]],"id":48534288}],"con":true,"img":false}]}
{"op":"mcm","clk":"11540726048","pt":1719497713761,"mc":[{"id":"1.230180118","rc":[{"atl":[[7.4,37.79],[7.8,0]],"id":48534288}],"con":true,"img":false}]}
{"op":"mcm","clk":"11540726057","pt":1719497713865,"mc":[{"id":"1.230180118","rc":[{"atl":[[7.4,38.65],[7.6,3.34]],"id":48534288}],"con":true,"img":false}]}
{"op":"mcm","clk":"11540726081","pt":1719497714174,"mc":[{"id":"1.230180118","rc":[{"atl":[[7.6,0]],"id":48534288}],"con":true,"img":false}]}
{"op":"mcm","clk":"11540726099","pt":1719497714380,"mc":[{"id":"1.230180118","rc":[{"atl":[[7.2,3.53],[7.4,34.86]],"id":48534288},{"atl":[[6.6,2]],"id":69475360}],"con":true,"img":false}]}
{"op":"mcm","clk":"11540726106","pt":1719497714482,"mc":[{"id":"1.230180118","rc":[{"atl":[[7.2,37.53],[7.4,0.86],[15,4.79]],"id":48534288},{"atl":[[9,3.45],[30,0]],"id":69475360}],"con":true,"img":false}]}
{"op":"mcm","clk":"11540726114","pt":1719497714586,"mc":[{"id":"1.230180118","rc":[{"atl":[[15,1]],"id":48534288}],"con":true,"img":false}]}
{"op":"mcm","clk":"11540726123","pt":1719497714687,"mc":[{"id":"1.230180118","rc":[{"atl":[[7,3.79]],"id":48534288}],"con":true,"img":false}]}
{"op":"mcm","clk":"11540726135","pt":1719497714794,"mc":[{"id":"1.230180118","rc":[{"atl":[[7,37.79]],"id":48534288}],"con":true,"img":false}]}
{"op":"mcm","clk":"11540726147","pt":1719497714899,"mc":[{"id":"1.230180118","rc":[{"atl":[[7.2,3.53]],"id":48534288}],"con":true,"img":false}]}
{"op":"mcm","clk":"11540726173","pt":1719497715108,"mc":[{"id":"1.230180118","rc":[{"atb":[[5.8,1],[5.5,0]],"id":50772801},{"atl":[[7.2,0],[7.4,0]],"id":48534288}],"con":true,"img":false}]}
{"op":"mcm","clk":"11540726185","pt":1719497715160,"mc":[{"id":"1.230180118","rc":[{"atb":[[5.1,2],[4.2,0.26]],"id":50772801},{"atl":[[6.8,0.86],[7,34]],"id":48534288}],"con":true,"img":false}]}
{"op":"mcm","clk":"11540726194","pt":1719497715266,"mc":[{"id":"1.230180118","rc":[{"atl":[[6.8,34.86],[7,0],[15,4.79]],"id":48534288}],"con":true,"img":false}]}
{"op":"mcm","clk":"11540726231","pt":1719497715682,"mc":[{"id":"1.230180118","rc":[{"atl":[[6.8,34]],"id":48534288}],"con":true,"img":false}]}
{"op":"mcm","clk":"11540726239","pt":1719497715787,"mc":[{"id":"1.230180118","rc":[{"atl":[[6.6,3.85]],"id":48534288}],"con":true,"img":false}]}
{"op":"mcm","clk":"11540726257","pt":1719497716004,"mc":[{"id":"1.230180118","rc":[{"atb":[[4.3,0]],"id":50772801},{"atl":[[6.8,0]],"id":48534288}],"con":true,"img":false}]}
{"op":"mcm","clk":"11540726265","pt":1719497716097,"mc":[{"id":"1.230180118","rc":[{"atl":[[14.5,1]],"id":48534288}],"con":true,"img":false}]}
{"op":"mcm","clk":"11540726311","pt":1719497716465,"mc":[{"id":"1.230180118","rc":[{"atl":[[6.6,0]],"id":48534288}],"con":true,"img":false}]}
{"op":"mcm","clk":"11540726339","pt":1719497716670,"mc":[{"id":"1.230180118","rc":[{"atl":[[6.4,3.97],[14.5,35],[15,1]],"id":48534288}],"con":true,"img":false}]}
{"op":"mcm","clk":"11540726347","pt":1719497716773,"mc":[{"id":"1.230180118","rc":[{"atb":[[3.75,0]],"id":69624671},{"atl":[[14,3.79]],"id":48534288}],"con":true,"img":false}]}
{"op":"mcm","clk":"11540726359","pt":1719497716877,"mc":[{"id":"1.230180118","rc":[{"atl":[[14.5,1]],"id":48534288}],"con":true,"img":false}]}
{"op":"mcm","clk":"11540726366","pt":1719497716980,"mc":[{"id":"1.230180118","rc":[{"atb":[[4.2,0]],"id":50772801}],"con":true,"img":false}]}
{"op":"mcm","clk":"11540726374","pt":1719497717083,"mc":[{"id":"1.230180118","rc":[{"atb":[[1.13,0.26]],"id":50772801}],"con":true,"img":false}]}
{"op":"mcm","clk":"11540726393","pt":1719497717294,"mc":[{"id":"1.230180118","rc":[{"atl":[[6.4,0]],"id":48534288}],"con":true,"img":false}]}
{"op":"mcm","clk":"11540726405","pt":1719497717399,"mc":[{"id":"1.230180118","rc":[{"atl":[[14,37.79]],"id":48534288}],"con":true,"img":false}]}
{"op":"mcm","clk":"11540726415","pt":1719497717507,"mc":[{"id":"1.230180118","rc":[{"atb":[[3.7,6.34]],"id":69624671}],"con":true,"img":false}]}
{"op":"mcm","clk":"11540726438","pt":1719497717703,"mc":[{"id":"1.230180118","rc":[{"atb":[[3.75,1.69]],"id":69624671}],"con":true,"img":false}]}
{"op":"mcm","clk":"11540726471","pt":1719497717962,"mc":[{"id":"1.230180118","rc":[{"atl":[[13.5,0.86]],"id":48534288}],"con":true,"img":false}]}
{"op":"mcm","clk":"11540726482","pt":1719497718066,"mc":[{"id":"1.230180118","rc":[{"atl":[[13.5,34.86]],"id":48534288}],"con":true,"img":false}]}
{"op":"mcm","clk":"11540726492","pt":1719497718175,"mc":[{"id":"1.230180118","rc":[{"atb":[[3.7,0]],"id":69624671},{"atl":[[14,3.79]],"id":48534288}],"con":true,"img":false}]}
{"op":"mcm","clk":"11540726505","pt":1719497718284,"mc":[{"id":"1.230180118","rc":[{"atl":[[14,0]],"id":48534288}],"con":true,"img":false}]}
{"op":"mcm","clk":"11540726515","pt":1719497718378,"mc":[{"id":"1.230180118","rc":[{"atl":[[13,5.74]],"id":48534288}],"con":true,"img":false}]}
{"op":"mcm","clk":"11540726521","pt":1719497718479,"mc":[{"id":"1.230180118","rc":[{"atl":[[13,39.74],[13.5,0.86]],"id":48534288}],"con":true,"img":false}]}
{"op":"mcm","clk":"11540726537","pt":1719497718685,"mc":[{"id":"1.230180118","rc":[{"atl":[[13,35.95],[13.5,0]],"id":48534288},{"atl":[[4.3,8]],"id":69475360}],"con":true,"img":false}]}
{"op":"mcm","clk":"11540726546","pt":1719497718793,"mc":[{"id":"1.230180118","rc":[{"atl":[[12.5,0.86],[14.5,4.79]],"id":48534288}],"con":true,"img":false}]}
{"op":"mcm","clk":"11540726555","pt":1719497718892,"mc":[{"id":"1.230180118","rc":[{"atb":[[3.75,0]],"id":69624671},{"atl":[[12.5,34.86]],"id":48534288}],"con":true,"img":false}]}
{"op":"mcm","clk":"11540726562","pt":1719497718998,"mc":[{"id":"1.230180118","rc":[{"atb":[[1.14,0]],"id":48534288},{"atl":[[13,1.95],[14.5,1]],"id":48534288}],"con":true,"img":false}]}
{"op":"mcm","clk":"11540726569","pt":1719497719099,"mc":[{"id":"1.230180118","rc":[{"atb":[[4.6,4.58],[3.95,0.25]],"id":48534288},{"atl":[[12.5,38.65],[13,0]],"id":48534288},{"atl":[[6.6,0]],"id":69475360}],"con":true,"img":false}]}
{"op":"mcm","clk":"11540726577","pt":1719497719211,"mc":[{"id":"1.230180118","rc":[{"atb":[[3.9,0],[4.7,2]],"id":48534288}],"con":true,"img":false}]}
{"op":"mcm","clk":"11540726584","pt":1719497719306,"mc":[{"id":"1.230180118","rc":[{"atb":[[3.7,6.34]],"id":69624671},{"atl":[[12,2.11],[12.5,34.86]],"id":48534288}],"con":true,"img":false}]}
{"op":"mcm","clk":"11540726593","pt":1719497719408,"mc":[{"id":"1.230180118","rc":[{"atl":[[12,36.11],[14.5,4.79]],"id":48534288}],"con":true,"img":false}]}
{"op":"mcm","clk":"11540726602","pt":1719497719511,"mc":[{"id":"1.230180118","rc":[{"atl":[[12.5,0.86],[14.5,1]],"id":48534288}],"con":true,"img":false}]}
{"op":"mcm","clk":"11540726609","pt":1719497719570,"mc":[{"id":"1.230180118","rc":[{"atl":[[11.5,3.79]],"id":48534288}],"con":true,"img":false}]}
{"op":"mcm","clk":"11540726630","pt":1719497719769,"mc":[{"id":"1.230180118","rc":[{"atl":[[11.5,34]],"id":48534288}],"con":true,"img":false}]}
{"op":"mcm","clk":"11540726639","pt":1719497719872,"mc":[{"id":"1.230180118","rc":[{"atl":[[12,2.11],[12.5,0],[14.5,4.79]],"id":48534288}],"con":true,"img":false}]}
{"op":"mcm","clk":"11540726646","pt":1719497719975,"mc":[{"id":"1.230180118","rc":[{"atl":[[11,0.86]],"id":48534288}],"con":true,"img":false}]}
{"op":"mcm","clk":"11540726655","pt":1719497720076,"mc":[{"id":"1.230180118","rc":[{"atl":[[11,34.86],[12,0],[14.5,1]],"id":48534288}],"con":true,"img":false}]}
{"op":"mcm","clk":"11540726661","pt":1719497720179,"mc":[{"id":"1.230180118","rc":[{"atl":[[11,38.65],[11.5,0]],"id":48534288}],"con":true,"img":false}]}
{"op":"mcm","clk":"11540726670","pt":1719497720284,"mc":[{"id":"1.230180118","rc":[{"atl":[[10.5,2.42]],"id":48534288}],"con":true,"img":false}]}
{"op":"mcm","clk":"11540726672","pt":1719497720387,"mc":[{"id":"1.230180118","rc":[{"atl":[[10.5,36.42],[11,0.86]],"id":48534288}],"con":true,"img":false}]}
{"op":"mcm","clk":"11540726681","pt":1719497720489,"mc":[{"id":"1.230180118","rc":[{"atl":[[11,0],[14.5,4.79]],"id":48534288}],"con":true,"img":false}]}
{"op":"mcm","clk":"11540726690","pt":1719497720589,"mc":[{"id":"1.230180118","rc":[{"atl":[[10.5,37.28]],"id":48534288}],"con":true,"img":false}]}
{"op":"mcm","clk":"11540726698","pt":1719497720695,"mc":[{"id":"1.230180118","rc":[{"atl":[[14.5,1]],"id":48534288}],"con":true,"img":false}]}
{"op":"mcm","clk":"11540726709","pt":1719497720800,"mc":[{"id":"1.230180118","rc":[{"atl":[[10,3.79]],"id":48534288}],"con":true,"img":false}]}
{"op":"mcm","clk":"11540726721","pt":1719497720899,"mc":[{"id":"1.230180118","rc":[{"atl":[[10,37.79]],"id":48534288}],"con":true,"img":false}]}
{"op":"mcm","clk":"11540726731","pt":1719497721003,"mc":[{"id":"1.230180118","rc":[{"atl":[[10.5,0]],"id":48534288},{"atb":[[2.62,10.47]],"id":69475360}],"con":true,"img":false}]}
{"op":"mcm","clk":"11540726739","pt":1719497721106,"mc":[{"id":"1.230180118","rc":[{"atl":[[10,34],[9.8,0.86]],"id":48534288},{"atb":[[2.78,4.88]],"id":69475360}],"con":true,"img":false}]}
{"op":"mcm","clk":"11540726750","pt":1719497721214,"mc":[{"id":"1.230180118","rc":[{"atb":[[3.75,2.91]],"id":69624671},{"atb":[[2.84,5.14]],"id":48534288},{"atl":[[10,0],[9.8,37.45],[14.5,4.79]],"id":48534288}],"con":true,"img":false}]}
{"op":"mcm","clk":"11540726768","pt":1719497721368,"mc":[{"id":"1.230180118","rc":[{"atb":[[3.05,4.24]],"id":48534288},{"atl":[[14.5,1]],"id":48534288}],"con":true,"img":false}]}
{"op":"mcm","clk":"11540726777","pt":1719497721470,"mc":[{"id":"1.230180118","rc":[{"atl":[[9.8,41.24]],"id":48534288}],"con":true,"img":false}]}
{"op":"mcm","clk":"11540726783","pt":1719497721575,"mc":[{"id":"1.230180118","rc":[{"atl":[[7.2,1.05]],"id":69624671},{"atb":[[2.16,12.25]],"id":48534288}],"con":true,"img":false}]}
{"op":"mcm","clk":"11540726799","pt":1719497721782,"mc":[{"id":"1.230180118","rc":[{"atl":[[1000,0.4]],"id":69624671},{"atb":[[2.72,2.09]],"id":69475360}],"con":true,"img":false}]}
{"op":"mcm","clk":"11540726804","pt":1719497721886,"mc":[{"id":"1.230180118","rc":[{"atb":[[3.8,1.69],[3.7,0]],"id":69624671},{"atl":[[1000,0.23]],"id":69624671}],"con":true,"img":false}]}
{"op":"mcm","clk":"11540726812","pt":1719497721989,"mc":[{"id":"1.230180118","rc":[{"atl":[[7,0.17]],"id":69624671}],"con":true,"img":false}]}
{"op":"mcm","clk":"11540726849","pt":1719497722611,"mc":[{"id":"1.230180118","rc":[{"atb":[[3.8,0]],"id":69624671}],"con":true,"img":false}]}
{"op":"mcm","clk":"11540726955","pt":1719497723703,"mc":[{"id":"1.230180118","rc":[{"atb":[[2.36,0]],"id":69475360}],"con":true,"img":false}]}
{"op":"mcm","clk":"11540726975","pt":1719497723911,"mc":[{"id":"1.230180118","rc":[{"atb":[[2.16,11.87]],"id":50772801},{"atb":[[3.85,0]],"id":69624671}],"con":true,"img":false}]}
{"op":"mcm","clk":"11540726986","pt":1719497723965,"mc":[{"id":"1.230180118","rc":[{"atb":[[2.16,11.87]],"id":69624671},{"atl":[[7.2,0]],"id":69624671}],"con":true,"img":false}]}
{"op":"mcm","clk":"11540727025","pt":1719497724379,"mc":[{"id":"1.230180118","rc":[{"atb":[[2.16,18.68]],"id":62145089}],"con":true,"img":false}]}
{"op":"mcm","clk":"11540727031","pt":1719497724482,"mc":[{"id":"1.230180118","rc":[{"atb":[[3.2,7.82]],"id":69624671},{"atl":[[7,1.22]],"id":69624671}],"con":true,"img":false}]}
{"op":"mcm","clk":"11540727041","pt":1719497724587,"mc":[{"id":"1.230180118","rc":[{"atb":[[3.85,0.55]],"id":69624671}],"con":true,"img":false}]}
{"op":"mcm","clk":"11540727050","pt":1719497724689,"mc":[{"id":"1.230180118","rc":[{"atb":[[2.16,19.9]],"id":50772801}],"con":true,"img":false}]}
{"op":"mcm","clk":"11540727080","pt":1719497725102,"mc":[{"id":"1.230180118","rc":[{"atb":[[2.16,18.68]],"id":48534288}],"con":true,"img":false}]}
{"op":"mcm","clk":"11540727086","pt":1719497725212,"mc":[{"id":"1.230180118","rc":[{"atb":[[2.16,26.7]],"id":62145089}],"con":true,"img":false}]}
{"op":"mcm","clk":"11540727102","pt":1719497725414,"mc":[{"id":"1.230180118","rc":[{"atb":[[2.64,7.72]],"id":69475360}],"con":true,"img":false}]}
{"op":"mcm","clk":"11540727130","pt":1719497725876,"mc":[{"id":"1.230180118","rc":[{"atb":[[3.65,8.02]],"id":62145089},{"atb":[[3,6.58]],"id":60276470},{"atb":[[3.95,3.26]],"id":48534288},{"atb":[[2.8,10.98]],"id":69475360}],"con":true,"img":false}]}
{"op":"mcm","clk":"11540727137","pt":1719497725976,"mc":[{"id":"1.230180118","rc":[{"atl":[[6.4,0]],"id":69475360}],"con":true,"img":false}]}
{"op":"mcm","clk":"11540727146","pt":1719497726184,"mc":[{"id":"1.230180118","rc":[{"atb":[[3.05,1.61]],"id":60276470},{"atl":[[14.5,0]],"id":48534288},{"atb":[[2.82,1.65]],"id":69475360}],"con":true,"img":false}]}
{"op":"mcm","clk":"11540727204","pt":1719497727006,"mc":[{"id":"1.230180118","rc":[{"atl":[[1000,1.93]],"id":69475360}],"con":true,"img":false}]}
{"op":"mcm","clk":"11540727212","pt":1719497727111,"mc":[{"id":"1.230180118","rc":[{"atb":[[1.03,1.7]],"id":69475360}],"con":true,"img":false}]}
{"op":"mcm","clk":"11540727227","pt":1719497727320,"mc":[{"id":"1.230180118","rc":[{"atl":[[1000,0.3]],"id":69475360}],"con":true,"img":false}]}
{"op":"mcm","clk":"11540727238","pt":1719497727369,"mc":[{"id":"1.230180118","rc":[{"atb":[[1.03,0.1]],"id":69475360}],"con":true,"img":false}]}
{"op":"mcm","clk":"11540727254","pt":1719497727577,"mc":[{"id":"1.230180118","rc":[{"atl":[[1000,0.23]],"id":69475360}],"con":true,"img":false}]}
{"op":"mcm","clk":"11540727262","pt":1719497727679,"mc":[{"id":"1.230180118","rc":[{"atb":[[1.03,0]],"id":69475360},{"atl":[[4.2,0.06]],"id":69475360}],"con":true,"img":false}]}
{"op":"mcm","clk":"11540727274","pt":1719497727782,"mc":[{"id":"1.230180118","rc":[{"atb":[[3,0.1]],"id":69475360}],"con":true,"img":false}]}
{"op":"mcm","clk":"11540727283","pt":1719497727896,"mc":[{"id":"1.230180118","rc":[{"atb":[[2.8,7.82],[2.98,3]],"id":69475360}],"con":true,"img":false}]}
{"op":"mcm","clk":"11540727301","pt":1719497728095,"mc":[{"id":"1.230180118","rc":[{"atb":[[2.82,0]],"id":69475360}],"con":true,"img":false}]}
{"op":"mcm","clk":"11540727452","pt":1719497729807,"mc":[{"id":"1.230180118","rc":[{"spn":13.4,"spf":"NaN","id":50772801},{"spn":8.0,"spf":"NaN","id":62145089},{"atl":[[11,0]],"id":69624671},{"spn":3.8,"spf":1.0,"id":69624671},{"atl":[[26,0.85]],"id":60276470},{"spn":3.24,"spf":1.0,"id":60276470},{"spn":7.25,"spf":"NaN","id":48534288},{"spn":2.97,"spf":1.0,"id":69475360}],"con":true,"img":false}]}
{"op":"mcm","clk":"11540727685","pt":1719497732693,"mc":[{"id":"1.230180118","rc":[{"atb":[[5,2.1]],"id":48534288}],"con":true,"img":false}]}
{"op":"mcm","clk":"11540727693","pt":1719497732800,"mc":[{"id":"1.230180118","rc":[{"atb":[[4.7,4.16]],"id":48534288}],"con":true,"img":false}]}
{"op":"mcm","clk":"11540727726","pt":1719497733210,"mc":[{"id":"1.230180118","rc":[{"atb":[[3.65,0]],"id":69475360},{"atl":[[3.65,1]],"id":69475360},{"trd":[[3.65,2]],"ltp":3.65,"tv":2.0,"id":69475360}],"con":true,"img":false}]}
{"op":"mcm","clk":"11540727732","pt":1719497733320,"mc":[{"id":"1.230180118","rc":[{"atb":[[3.75,0]],"id":69624671},{"atb":[[2.82,4.88],[2.98,1]],"id":69475360}],"con":true,"img":false}]}
{"op":"mcm","clk":"11540727742","pt":1719497733369,"mc":[{"id":"1.230180118","rc":[{"atb":[[4.8,1.58]],"id":48534288}],"con":true,"img":false}]}
{"op":"mcm","clk":"11540727769","pt":1719497733780,"mc":[{"id":"1.230180118","rc":[{"atb":[[3.7,6.34]],"id":69624671}],"con":true,"img":false}]}
{"op":"mcm","clk":"11540727782","pt":1719497733993,"mc":[{"id":"1.230180118","rc":[{"atb":[[3.75,1.69]],"id":69624671},{"atb":[[2.84,1.65]],"id":69475360}],"con":true,"img":false}]}
{"op":"mcm","clk":"11540727795","pt":1719497734203,"mc":[{"id":"1.230180118","rc":[{"atl":[[4.2,2.56]],"id":69475360}],"con":true,"img":false}]}
{"op":"mcm","clk":"11540727812","pt":1719497734403,"mc":[{"id":"1.230180118","rc":[{"atb":[[3.7,0]],"id":69624671}],"con":true,"img":false}]}
{"op":"mcm","clk":"11540727822","pt":1719497734502,"mc":[{"id":"1.230180118","rc":[{"atb":[[2.34,0]],"id":50772801},{"atb":[[2.3,0]],"id":62145089},{"atb":[[2.26,2.09]],"id":69624671},{"atb":[[2.36,0]],"id":60276470},{"atb":[[2.36,0]],"id":48534288}],"con":true,"img":false}]}
{"op":"mcm","clk":"11540727838","pt":1719497734708,"mc":[{"id":"1.230180118","rc":[{"atb":[[3.75,0]],"id":69624671}],"con":true,"img":false}]}
{"op":"mcm","clk":"11540727856","pt":1719497735019,"mc":[{"id":"1.230180118","rc":[{"atb":[[3.7,6.34]],"id":69624671},{"atb":[[3.95,3]],"id":48534288}],"con":true,"img":false}]}
{"op":"mcm","clk":"11540727865","pt":1719497735071,"mc":[{"id":"1.230180118","rc":[{"atb":[[4.8,1.83]],"id":48534288}],"con":true,"img":false}]}
{"op":"mcm","clk":"11540727881","pt":1719497735276,"mc":[{"id":"1.230180118","rc":[{"atb":[[2.7,3.31]],"id":69475360}],"con":true,"img":false}]}
{"op":"mcm","clk":"11540727977","pt":1719497736415,"mc":[{"id":"1.230180118","rc":[{"atb":[[3.9,1]],"id":69624671},{"atb":[[3.4,1]],"id":69475360}],"con":true,"img":false}]}
{"op":"mcm","clk":"11540727986","pt":1719497736520,"mc":[{"id":"1.230180118","rc":[{"atb":[[4.8,0.25]],"id":48534288},{"atb":[[2.84,6]],"id":69475360}],"con":true,"img":false}]}
{"op":"mcm","clk":"11540727997","pt":1719497736629,"mc":[{"id":"1.230180118","rc":[{"atb":[[3.7,0]],"id":69624671}],"con":true,"img":false}]}
{"op":"mcm","clk":"11540728046","pt":1719497737192,"mc":[{"id":"1.230180118","rc":[{"atl":[[7,1.05]],"id":69624671}],"con":true,"img":false}]}
{"op":"mcm","clk":"11540728063","pt":1719497737398,"mc":[{"id":"1.230180118","rc":[{"atb":[[2.7,0]],"id":69475360}],"con":true,"img":false}]}
{"op":"mcm","clk":"11540728091","pt":1719497737810,"mc":[{"id":"1.230180118","rc":[{"atb":[[3.95,0]],"id":48534288}],"con":true,"img":false}]}
{"op":"mcm","clk":"11540728145","pt":1719497738589,"mc":[{"id":"1.230180118","rc":[{"atl":[[1000,0.4]],"id":69624671}],"con":true,"img":false}]}
{"op":"mcm","clk":"11540728164","pt":1719497738790,"mc":[{"id":"1.230180118","rc":[{"atl":[[1000,0.23]],"id":69624671}],"con":true,"img":false}]}
{"op":"mcm","clk":"11540728175","pt":1719497738892,"mc":[{"id":"1.230180118","rc":[{"atl":[[6.8,0.17]],"id":69624671}],"con":true,"img":false}]}
{"op":"mcm","clk":"11540728248","pt":1719497739720,"mc":[{"id":"1.230180118","rc":[{"atl":[[7,0]],"id":69624671}],"con":true,"img":false}]}
{"op":"mcm","clk":"11540728272","pt":1719497739978,"mc":[{"id":"1.230180118","rc":[{"atb":[[3.85,0]],"id":69624671}],"con":true,"img":false}]}
{"op":"mcm","clk":"11540728278","pt":1719497740081,"mc":[{"id":"1.230180118","rc":[{"atb":[[2.38,10.68]],"id":50772801},{"atb":[[2.62,7.31]],"id":69475360}],"con":true,"img":false}]}
{"op":"mcm","clk":"11540728302","pt":1719497740288,"mc":[{"id":"1.230180118","rc":[{"atb":[[2.4,8.45]],"id":48534288}],"con":true,"img":false}]}
{"op":"mcm","clk":"11540728316","pt":1719497740396,"mc":[{"id":"1.230180118","rc":[{"atb":[[2.16,19.9]],"id":62145089},{"atl":[[7.4,1.08]],"id":69624671}],"con":true,"img":false}]}
{"op":"mcm","clk":"11540728327","pt":1719497740495,"mc":[{"id":"1.230180118","rc":[{"atb":[[2.3,9.11],[3.95,0.53]],"id":69624671}],"con":true,"img":false}]}
{"op":"mcm","clk":"11540728347","pt":1719497740702,"mc":[{"id":"1.230180118","rc":[{"atb":[[2.36,16.07]],"id":50772801},{"atb":[[2.64,3.38]],"id":69475360}],"con":true,"img":false}]}
{"op":"mcm","clk":"11540728370","pt":1719497740908,"mc":[{"id":"1.230180118","rc":[{"atb":[[2.34,8.83]],"id":62145089}],"con":true,"img":false}]}
{"op":"mcm","clk":"11540728532","pt":1719497742514,"mc":[{"id":"1.230180118","rc":[{"atb":[[2.82,0],[2.98,5.88]],"id":69475360}],"con":true,"img":false}]}
{"op":"mcm","clk":"11540728818","pt":1719497745602,"mc":[{"id":"1.230180118","rc":[{"atl":[[9.6,0.84]],"id":48534288}],"con":true,"img":false}]}
{"op":"mcm","clk":"11540728827","pt":1719497745707,"mc":[{"id":"1.230180118","rc":[{"atl":[[9.6,34.84],[9.8,7.24]],"id":48534288}],"con":true,"img":false}]}
{"op":"mcm","clk":"11540728850","pt":1719497746012,"mc":[{"id":"1.230180118","rc":[{"atl":[[9.8,0.86]],"id":48534288}],"con":true,"img":false}]}
{"op":"mcm","clk":"11540728856","pt":1719497746113,"mc":[{"id":"1.230180118","rc":[{"atl":[[9.4,3.79]],"id":48534288}],"con":true,"img":false}]}
{"op":"mcm","clk":"11540728865","pt":1719497746222,"mc":[{"id":"1.230180118","rc":[{"atl":[[9.6,0.84],[9.4,40.49]],"id":48534288}],"con":true,"img":false}]}
{"op":"mcm","clk":"11540728877","pt":1719497746324,"mc":[{"id":"1.230180118","rc":[{"atl":[[9.8,0]],"id":48534288}],"con":true,"img":false}]}
{"op":"mcm","clk":"11540728888","pt":1719497746433,"mc":[{"id":"1.230180118","rc":[{"atl":[[9.2,0.86],[9.4,36.7]],"id":48534288}],"con":true,"img":false}]}
{"op":"mcm","clk":"11540728902","pt":1719497746526,"mc":[{"id":"1.230180118","rc":[{"atl":[[9.8,3.79]],"id":48534288}],"con":true,"img":false}]}
{"op":"mcm","clk":"11540728909","pt":1719497746639,"mc":[{"id":"1.230180118","rc":[{"atl":[[9.2,34.86]],"id":48534288}],"con":true,"img":false}]}
{"op":"mcm","clk":"11540728919","pt":1719497746731,"mc":[{"id":"1.230180118","rc":[{"atl":[[9.8,0],[9.4,2.7]],"id":48534288}],"con":true,"img":false}]}
{"op":"mcm","clk":"11540728925","pt":1719497746834,"mc":[{"id":"1.230180118","rc":[{"atl":[[9.2,38.65]],"id":48534288}],"con":true,"img":false}]}
{"op":"mcm","clk":"11540728932","pt":1719497746887,"mc":[{"id":"1.230180118","rc":[{"atl":[[9.4,0]],"id":48534288}],"con":true,"img":false}]}
{"op":"mcm","clk":"11540728937","pt":1719497746989,"mc":[{"id":"1.230180118","rc":[{"atb":[[4.8,0]],"id":48534288}],"con":true,"img":false}]}
{"op":"mcm","clk":"11540728944","pt":1719497747118,"mc":[{"id":"1.230180118","rc":[{"atb":[[1.14,0.25]],"id":48534288},{"atl":[[9.6,0],[9.2,34.86]],"id":48534288}],"con":true,"img":false}]}
{"op":"mcm","clk":"11540728952","pt":1719497747200,"mc":[{"id":"1.230180118","rc":[{"atl":[[15,4.79]],"id":48534288}],"con":true,"img":false}]}
{"op":"mcm","clk":"11540728968","pt":1719497747403,"mc":[{"id":"1.230180118","rc":[{"atl":[[15,1]],"id":48534288}],"con":true,"img":false}]}
{"op":"mcm","clk":"11540728978","pt":1719497747504,"mc":[{"id":"1.230180118","rc":[{"atl":[[9,6.6],[9.2,34]],"id":48534288}],"con":true,"img":false}]}
{"op":"mcm","clk":"11540728986","pt":1719497747606,"mc":[{"id":"1.230180118","rc":[{"atl":[[9,40.6],[9.2,0]],"id":48534288}],"con":true,"img":false}]}
{"op":"mcm","clk":"11540728993","pt":1719497747711,"mc":[{"id":"1.230180118","rc":[{"atl":[[9,36.81]],"id":48534288}],"con":true,"img":false}]}
{"op":"mcm","clk":"11540729002","pt":1719497747813,"mc":[{"id":"1.230180118","rc":[{"atl":[[15,4.79]],"id":48534288}],"con":true,"img":false}]}
{"op":"mcm","clk":"11540729021","pt":1719497748024,"mc":[{"id":"1.230180118","rc":[{"atl":[[15,1]],"id":48534288},{"atl":[[3.65,0]],"id":69475360},{"trd":[[3.65,3.99]],"ltp":3.65,"tv":3.99,"id":69475360}],"con":true,"img":false}]}
{"op":"mcm","clk":"11540729028","pt":1719497748122,"mc":[{"id":"1.230180118","rc":[{"atl":[[8.8,4.65]],"id":48534288}],"con":true,"img":false}]}
{"op":"mcm","clk":"11540729035","pt":1719497748229,"mc":[{"id":"1.230180118","rc":[{"atl":[[8.8,38.65]],"id":48534288}],"con":true,"img":false}]}
{"op":"mcm","clk":"11540729047","pt":1719497748330,"mc":[{"id":"1.230180118","rc":[{"atl":[[9,2.81]],"id":48534288}],"con":true,"img":false}]}
{"op":"mcm","clk":"11540729071","pt":1719497748640,"mc":[{"id":"1.230180118","rc":[{"atl":[[4.1,0.84]],"id":69475360}],"con":true,"img":false}]}
{"op":"mcm","clk":"11540729079","pt":1719497748755,"mc":[{"id":"1.230180118","rc":[{"atl":[[9,0]],"id":48534288}],"con":true,"img":false}]}
{"op":"mcm","clk":"11540729101","pt":1719497748899,"mc":[{"id":"1.230180118","rc":[{"atl":[[8.8,34.86]],"id":48534288}],"con":true,"img":false}]}
{"op":"mcm","clk":"11540729114","pt":1719497749006,"mc":[{"id":"1.230180118","rc":[{"atl":[[15,4.79]],"id":48534288}],"con":true,"img":false}]}
{"op":"mcm","clk":"11540729130","pt":1719497749206,"mc":[{"id":"1.230180118","rc":[{"atb":[[2.98,4.88]],"id":69475360}],"con":true,"img":false}]}
{"op":"mcm","clk":"11540729137","pt":1719497749310,"mc":[{"id":"1.230180118","rc":[{"atb":[[2.38,5.72]],"id":60276470},{"atb":[[2.38,0]],"id":48534288},{"atl":[[8.8,34],[15,1]],"id":48534288}],"con":true,"img":false}]}
{"op":"mcm","clk":"11540729147","pt":1719497749417,"mc":[{"id":"1.230180118","rc":[{"atl":[[8.6,6.74]],"id":48534288}],"con":true,"img":false}]}
{"op":"mcm","clk":"11540729157","pt":1719497749522,"mc":[{"id":"1.230180118","rc":[{"atl":[[8.6,40.74],[8.8,0]],"id":48534288}],"con":true,"img":false}]}
{"op":"mcm","clk":"11540729177","pt":1719497749725,"mc":[{"id":"1.230180118","rc":[{"atl":[[8.6,36.95]],"id":48534288}],"con":true,"img":false}]}
{"op":"mcm","clk":"11540729187","pt":1719497749826,"mc":[{"id":"1.230180118","rc":[{"atl":[[15,4.79]],"id":48534288}],"con":true,"img":false}]}
{"op":"mcm","clk":"11540729198","pt":1719497749933,"mc":[{"id":"1.230180118","rc":[{"atl":[[8.4,0.86]],"id":48534288}],"con":true,"img":false}]}
{"op":"mcm","clk":"11540729206","pt":1719497750038,"mc":[{"id":"1.230180118","rc":[{"atl":[[8.4,34.86],[15,1]],"id":48534288}],"con":true,"img":false}]}
{"op":"mcm","clk":"11540729215","pt":1719497750136,"mc":[{"id":"1.230180118","rc":[{"atl":[[8.6,2.95],[8.4,38.65]],"id":48534288}],"con":true,"img":false}]}
{"op":"mcm","clk":"11540729227","pt":1719497750239,"mc":[{"id":"1.230180118","rc":[{"atl":[[8.6,0]],"id":48534288}],"con":true,"img":false}]}
{"op":"mcm","clk":"11540729241","pt":1719497750394,"mc":[{"id":"1.230180118","rc":[{"atl":[[8.2,3.09],[8.4,34.86]],"id":48534288}],"con":true,"img":false}]}
{"op":"mcm","clk":"11540729249","pt":1719497750501,"mc":[{"id":"1.230180118","rc":[{"atb":[[3,0.27]],"id":60276470},{"atl":[[8.2,37.09],[15,4.79]],"id":48534288},{"atb":[[2.8,0]],"id":69475360}],"con":true,"img":false}]}
{"op":"mcm","clk":"11540729256","pt":1719497750605,"mc":[{"id":"1.230180118","rc":[{"atl":[[8.4,0.86]],"id":48534288}],"con":true,"img":false}]}
{"op":"mcm","clk":"11540729267","pt":1719497750706,"mc":[{"id":"1.230180118","rc":[{"atl":[[15,1]],"id":48534288}],"con":true,"img":false}]}
{"op":"mcm","clk":"11540729278","pt":1719497750815,"mc":[{"id":"1.230180118","rc":[{"atl":[[8,3.79]],"id":48534288}],"con":true,"img":false}]}
{"op":"mcm","clk":"11540729289","pt":1719497750912,"mc":[{"id":"1.230180118","rc":[{"atl":[[8.2,3.09]],"id":48534288},{"atb":[[3,4.1]],"id":69475360}],"con":true,"img":false}]}
{"op":"mcm","clk":"11540729300","pt":1719497751018,"mc":[{"id":"1.230180118","rc":[{"atl":[[8,37.79]],"id":48534288}],"con":true,"img":false}]}
{"op":"mcm","clk":"11540729311","pt":1719497751219,"mc":[{"id":"1.230180118","rc":[{"atb":[[3.05,0]],"id":60276470},{"atl":[[8.2,0]],"id":48534288}],"con":true,"img":false}]}
{"op":"mcm","clk":"11540729330","pt":1719497751425,"mc":[{"id":"1.230180118","rc":[{"atl":[[8,34],[7.8,3.25]],"id":48534288}],"con":true,"img":false}]}
{"op":"mcm","clk":"11540729340","pt":1719497751526,"mc":[{"id":"1.230180118","rc":[{"atl":[[7.8,37.25],[15,4.79]],"id":48534288}],"con":true,"img":false}]}
{"op":"mcm","clk":"11540729347","pt":1719497751640,"mc":[{"id":"1.230180118","rc":[{"atl":[[8,0],[15,1]],"id":48534288},{"atb":[[2.98,0],[3.05,4.88]],"id":69475360}],"con":true,"img":false}]}
{"op":"mcm","clk":"11540729354","pt":1719497751739,"mc":[{"id":"1.230180118","rc":[{"atl":[[7.6,3.79],[8.4,0]],"id":48534288}],"con":true,"img":false}]}
{"op":"mcm","clk":"11540729364","pt":1719497751839,"mc":[{"id":"1.230180118","rc":[{"atl":[[7.6,38.65],[7.8,3.25]],"id":48534288}],"con":true,"img":false}]}
{"op":"mcm","clk":"11540729392","pt":1719497752099,"mc":[{"id":"1.230180118","rc":[{"atl":[[7.8,0]],"id":48534288}],"con":true,"img":false}]}
{"op":"mcm","clk":"11540729407","pt":1719497752308,"mc":[{"id":"1.230180118","rc":[{"atl":[[7.4,3.42],[7.6,34.86]],"id":48534288}],"con":true,"img":false}]}
{"op":"mcm","clk":"11540729416","pt":1719497752415,"mc":[{"id":"1.230180118","rc":[{"atl":[[7.4,37.42],[15,4.79]],"id":48534288}],"con":true,"img":false}]}
{"op":"mcm","clk":"11540729428","pt":1719497752516,"mc":[{"id":"1.230180118","rc":[{"atl":[[7.6,0.86]],"id":48534288}],"con":true,"img":false}]}
{"op":"mcm","clk":"11540729436","pt":1719497752620,"mc":[{"id":"1.230180118","rc":[{"atl":[[7.2,0.84],[15,1]],"id":48534288}],"con":true,"img":false}]}
{"op":"mcm","clk":"11540729447","pt":1719497752729,"mc":[{"id":"1.230180118","rc":[{"atl":[[7.2,38.63]],"id":48534288}],"con":true,"img":false}]}
{"op":"mcm","clk":"11540729459","pt":1719497752830,"mc":[{"id":"1.230180118","rc":[{"atl":[[7.4,3.42]],"id":48534288}],"con":true,"img":false}]}
{"op":"mcm","clk":"11540729479","pt":1719497753037,"mc":[{"id":"1.230180118","rc":[{"atl":[[7.4,0],[7.6,0]],"id":48534288}],"con":true,"img":false}]}
{"op":"mcm","clk":"11540729491","pt":1719497753140,"mc":[{"id":"1.230180118","rc":[{"atl":[[7,0.86]],"id":48534288}],"con":true,"img":false}]}
{"op":"mcm","clk":"11540729500","pt":1719497753243,"mc":[{"id":"1.230180118","rc":[{"atl":[[7.2,0.84],[7,38.49]],"id":48534288}],"con":true,"img":false}]}
{"op":"mcm","clk":"11540729515","pt":1719497753346,"mc":[{"id":"1.230180118","rc":[{"atl":[[15,4.79]],"id":48534288}],"con":true,"img":false}]}
{"op":"mcm","clk":"11540729528","pt":1719497753398,"mc":[{"id":"1.230180118","rc":[{"atl":[[1000,2.23]],"id":48534288}],"con":true,"img":false}]}
{"op":"mcm","clk":"11540729554","pt":1719497753712,"mc":[{"id":"1.230180118","rc":[{"atl":[[1000,0.73]],"id":48534288}],"con":true,"img":false}]}
{"op":"mcm","clk":"11540729571","pt":1719497753919,"mc":[{"id":"1.230180118","rc":[{"atl":[[1000,0.23]],"id":48534288}],"con":true,"img":false}]}
{"op":"mcm","clk":"11540729582","pt":1719497754018,"mc":[{"id":"1.230180118","rc":[{"atl":[[6.8,0]],"id":69624671},{"atl":[[7,38.99]],"id":48534288}],"con":true,"img":false}]}
{"op":"mcm","clk":"11540729604","pt":1719497754225,"mc":[{"id":"1.230180118","rc":[{"atb":[[3.1,3.81]],"id":69475360}],"con":true,"img":false}]}
{"op":"mcm","clk":"11540729610","pt":1719497754327,"mc":[{"id":"1.230180118","rc":[{"atl":[[1000,0.39]],"id":69624671}],"con":true,"img":false}]}
{"op":"mcm","clk":"11540729627","pt":1719497754537,"mc":[{"id":"1.230180118","rc":[{"atl":[[1000,0.23]],"id":69624671}],"con":true,"img":false}]}
{"op":"mcm","clk":"11540729641","pt":1719497754645,"mc":[{"id":"1.230180118","rc":[{"atl":[[7.2,0.16]],"id":69624671}],"con":true,"img":false}]}
{"op":"mcm","clk":"11540729747","pt":1719497755825,"mc":[{"id":"1.230180118","rc":[{"atl":[[7.4,0.03]],"id":69624671}],"con":true,"img":false}]}
{"op":"mcm","clk":"11540729769","pt":1719497756137,"mc":[{"id":"1.230180118","rc":[{"atb":[[3.95,0]],"id":69624671}],"con":true,"img":false}]}
{"op":"mcm","clk":"11540729793","pt":1719497756444,"mc":[{"id":"1.230180118","rc":[{"atl":[[7.2,1.21]],"id":69624671}],"con":true,"img":false}]}
{"op":"mcm","clk":"11540729804","pt":1719497756557,"mc":[{"id":"1.230180118","rc":[{"atb":[[3.95,0.53]],"id":69624671}],"con":true,"img":false}]}
{"op":"mcm","clk":"11540730092","pt":1719497760055,"mc":[{"id":"1.230180118","rc":[{"atl":[[6.8,0.84]],"id":48534288}],"con":true,"img":false}]}
{"op":"mcm","clk":"11540730108","pt":1719497760266,"mc":[{"id":"1.230180118","rc":[{"atb":[[5,0]],"id":48534288},{"atl":[[6.8,34.84],[7,4.99]],"id":48534288},{"trd":[[5,10.31]],"ltp":5.0,"tv":10.31,"id":48534288}],"con":true,"img":false}]}
{"op":"mcm","clk":"11540730141","pt":1719497760624,"mc":[{"id":"1.230180118","rc":[{"atb":[[4.8,0.84]],"id":48534288},{"atl":[[7.2,0]],"id":48534288},{"atb":[[3.05,0],[3.15,4.1]],"id":69475360}],"con":true,"img":false}]}
{"op":"mcm","clk":"11540730155","pt":1719497760779,"mc":[{"id":"1.230180118","rc":[{"atl":[[7,0.5]],"id":48534288}],"con":true,"img":false}]}
{"op":"mcm","clk":"11540730163","pt":1719497760832,"mc":[{"id":"1.230180118","rc":[{"atl":[[6.6,0.86]],"id":48534288},{"atb":[[2.86,3.15]],"id":69475360}],"con":true,"img":false}]}
{"op":"mcm","clk":"11540730169","pt":1719497760937,"mc":[{"id":"1.230180118","rc":[{"atl":[[6.6,4.71]],"id":48534288},{"atb":[[2.64,0]],"id":69475360}],"con":true,"img":false}]}
{"op":"mcm","clk":"11540730176","pt":1719497761039,"mc":[{"id":"1.230180118","rc":[{"atl":[[6.8,0.84]],"id":48534288}],"con":true,"img":false}]}
{"op":"mcm","clk":"11540730185","pt":1719497761142,"mc":[{"id":"1.230180118","rc":[{"atb":[[2.4,12.07]],"id":60276470}],"con":true,"img":false}]}
{"op":"mcm","clk":"11540730204","pt":1719497761350,"mc":[{"id":"1.230180118","rc":[{"spl":[[1.01,1.69]],"id":48534288},{"atl":[[6.6,3.85]],"id":48534288}],"con":true,"img":false}]}
{"op":"mcm","clk":"11540730213","pt":1719497761450,"mc":[{"id":"1.230180118","rc":[{"atb":[[2.94,5.28]],"id":48534288}],"con":true,"img":false}]}
{"op":"mcm","clk":"11540730235","pt":1719497761713,"mc":[{"id":"1.230180118","rc":[{"atb":[[2.16,26.7]],"id":48534288}],"con":true,"img":false}]}
{"op":"mcm","clk":"11540730267","pt":1719497762026,"mc":[{"id":"1.230180118","rc":[{"atb":[[2.66,5.04]],"id":69475360}],"con":true,"img":false}]}
{"op":"mcm","clk":"11540730274","pt":1719497762128,"mc":[{"id":"1.230180118","rc":[{"atb":[[2.76,6.34]],"id":48534288}],"con":true,"img":false}]}
{"op":"mcm","clk":"11540730307","pt":1719497762439,"mc":[{"id":"1.230180118","rc":[{"atb":[[4.5,6.88]],"id":48534288}],"con":true,"img":false}]}
{"op":"mcm","clk":"11540730318","pt":1719497762542,"mc":[{"id":"1.230180118","rc":[{"atb":[[2.86,6.54]],"id":69475360}],"con":true,"img":false}]}
{"op":"mcm","clk":"11540730343","pt":1719497762852,"mc":[{"id":"1.230180118","rc":[{"atl":[[7,0]],"id":48534288}],"con":true,"img":false}]}
{"op":"mcm","clk":"11540730361","pt":1719497763062,"mc":[{"id":"1.230180118","rc":[{"atb":[[1.14,0]],"id":48534288}],"con":true,"img":false}]}
{"op":"mcm","clk":"11540730370","pt":1719497763162,"mc":[{"id":"1.230180118","rc":[{"atb":[[4.8,1.1]],"id":48534288}],"con":true,"img":false}]}
{"op":"mcm","clk":"11540730392","pt":1719497763318,"mc":[{"id":"1.230180118","rc":[{"atb":[[4.5,1]],"id":48534288},{"atl":[[6.6,0]],"id":48534288}],"con":true,"img":false}]}
{"op":"mcm","clk":"11540730403","pt":1719497763423,"mc":[{"id":"1.230180118","rc":[{"atl":[[6.8,34.84]],"id":48534288}],"con":true,"img":false}]}
{"op":"mcm","clk":"11540730410","pt":1719497763525,"mc":[{"id":"1.230180118","rc":[{"atl":[[6.8,34]],"id":48534288}],"con":true,"img":false}]}
{"op":"mcm","clk":"11540730438","pt":1719497763834,"mc":[{"id":"1.230180118","rc":[{"atl":[[3.95,2]],"id":69475360}],"con":true,"img":false}]}
{"op":"mcm","clk":"11540730457","pt":1719497764039,"mc":[{"id":"1.230180118","rc":[{"atl":[[3.9,0.84]],"id":69475360}],"con":true,"img":false}]}
{"op":"mcm","clk":"11540730467","pt":1719497764143,"mc":[{"id":"1.230180118","rc":[{"atl":[[4.1,0]],"id":69475360}],"con":true,"img":false}]}
{"op":"mcm","clk":"11540730485","pt":1719497764354,"mc":[{"id":"1.230180118","rc":[{"atl":[[6.6,3.85]],"id":48534288}],"con":true,"img":false}]}
{"op":"mcm","clk":"11540730503","pt":1719497764554,"mc":[{"id":"1.230180118","rc":[{"atl":[[6.8,0]],"id":48534288}],"con":true,"img":false}]}
{"op":"mcm","clk":"11540730542","pt":1719497764915,"mc":[{"id":"1.230180118","rc":[{"atb":[[4.8,0.84]],"id":48534288},{"atl":[[6.6,0]],"id":48534288}],"con":true,"img":false}]}
{"op":"mcm","clk":"11540730549","pt":1719497765019,"mc":[{"id":"1.230180118","rc":[{"atb":[[1.14,0.25]],"id":48534288},{"atl":[[15,38.79]],"id":48534288}],"con":true,"img":false}]}
{"op":"mcm","clk":"11540730560","pt":1719497765124,"mc":[{"id":"1.230180118","rc":[{"atl":[[14.5,1.75]],"id":48534288}],"con":true,"img":false}]}
{"op":"mcm","clk":"11540730572","pt":1719497765232,"mc":[{"id":"1.230180118","rc":[{"atl":[[14.5,35.75],[15,1]],"id":48534288}],"con":true,"img":false}]}
{"op":"mcm","clk":"11540730582","pt":1719497765329,"mc":[{"id":"1.230180118","rc":[{"atl":[[14,3.79]],"id":48534288}],"con":true,"img":false}]}
{"op":"mcm","clk":"11540730598","pt":1719497765435,"mc":[{"id":"1.230180118","rc":[{"atl":[[14,37.79]],"id":48534288}],"con":true,"img":false}]}
{"op":"mcm","clk":"11540730607","pt":1719497765540,"mc":[{"id":"1.230180118","rc":[{"atl":[[13.5,0.86],[14.5,1.75]],"id":48534288}],"con":true,"img":false}]}
{"op":"mcm","clk":"11540730620","pt":1719497765642,"mc":[{"id":"1.230180118","rc":[{"atl":[[13.5,34.86]],"id":48534288}],"con":true,"img":false}]}
{"op":"mcm","clk":"11540730631","pt":1719497765744,"mc":[{"id":"1.230180118","rc":[{"atb":[[1.03,164.28]],"id":48534288},{"atl":[[13.5,35.91],[14,0],[14.5,0]],"id":48534288}],"con":true,"img":false}]}
{"op":"mcm","clk":"11540730639","pt":1719497765848,"mc":[{"id":"1.230180118","rc":[{"atl":[[13,3.79]],"id":48534288}],"con":true,"img":false}]}
{"op":"mcm","clk":"11540730653","pt":1719497765953,"mc":[{"id":"1.230180118","rc":[{"atb":[[1.03,164.17]],"id":48534288},{"atl":[[13,39.74],[13.5,1.91]],"id":48534288}],"con":true,"img":false}]}
{"op":"mcm","clk":"11540730669","pt":1719497766166,"mc":[{"id":"1.230180118","rc":[{"atb":[[1.03,163.75]],"id":48534288},{"atl":[[13.5,1.05]],"id":48534288}],"con":true,"img":false}]}
{"op":"mcm","clk":"11540730678","pt":1719497766264,"mc":[{"id":"1.230180118","rc":[{"atb":[[4.8,1.26]],"id":48534288},{"atl":[[12.5,0.86]],"id":48534288}],"con":true,"img":false}]}
{"op":"mcm","clk":"11540730696","pt":1719497766416,"mc":[{"id":"1.230180118","rc":[{"atl":[[12.5,34.86]],"id":48534288}],"con":true,"img":false}]}
{"op":"mcm","clk":"11540730707","pt":1719497766518,"mc":[{"id":"1.230180118","rc":[{"atl":[[13,0]],"id":48534288}],"con":true,"img":false}]}
{"op":"mcm","clk":"11540730715","pt":1719497766621,"mc":[{"id":"1.230180118","rc":[{"atl":[[12,3.79]],"id":48534288}],"con":true,"img":false}]}
{"op":"mcm","clk":"11540730725","pt":1719497766724,"mc":[{"id":"1.230180118","rc":[{"atl":[[12,39.9],[12.5,0.86]],"id":48534288}],"con":true,"img":false}]}
{"op":"mcm","clk":"11540730739","pt":1719497766936,"mc":[{"id":"1.230180118","rc":[{"atl":[[12,36.11]],"id":48534288}],"con":true,"img":false}]}
{"op":"mcm","clk":"11540730749","pt":1719497767038,"mc":[{"id":"1.230180118","rc":[{"atl":[[13.5,4.84]],"id":48534288}],"con":true,"img":false}]}
{"op":"mcm","clk":"11540730759","pt":1719497767244,"mc":[{"id":"1.230180118","rc":[{"atl":[[13.5,1.05]],"id":48534288}],"con":true,"img":false}]}
{"op":"mcm","clk":"11540730770","pt":1719497767359,"mc":[{"id":"1.230180118","rc":[{"atl":[[11.5,3.79],[12.5,0]],"id":48534288}],"con":true,"img":false}]}
{"op":"mcm","clk":"11540730778","pt":1719497767449,"mc":[{"id":"1.230180118","rc":[{"atl":[[11.5,38.65],[12,2.11]],"id":48534288}],"con":true,"img":false}]}
{"op":"mcm","clk":"11540730791","pt":1719497767662,"mc":[{"id":"1.230180118","rc":[{"atl":[[11,0.84]],"id":48534288}],"con":true,"img":false}]}
{"op":"mcm","clk":"11540730799","pt":1719497767760,"mc":[{"id":"1.230180118","rc":[{"atl":[[11,34.84],[11.5,4.65]],"id":48534288}],"con":true,"img":false}]}
{"op":"mcm","clk":"11540730811","pt":1719497767870,"mc":[{"id":"1.230180118","rc":[{"atl":[[12,0]],"id":48534288}],"con":true,"img":false}]}
{"op":"mcm","clk":"11540730815","pt":1719497767915,"mc":[{"id":"1.230180118","rc":[{"atl":[[11.5,0.86]],"id":48534288}],"con":true,"img":false}]}
{"op":"mcm","clk":"11540730824","pt":1719497768076,"mc":[{"id":"1.230180118","rc":[{"atl":[[10.5,6.21],[11.5,0]],"id":48534288}],"con":true,"img":false}]}
{"op":"mcm","clk":"11540730833","pt":1719497768129,"mc":[{"id":"1.230180118","rc":[{"atl":[[10.5,7.07]],"id":48534288}],"con":true,"img":false}]}
{"op":"mcm","clk":"11540730840","pt":1719497768233,"mc":[{"id":"1.230180118","rc":[{"atl":[[10.5,41.07],[11,0.84]],"id":48534288}],"con":true,"img":false}]}
{"op":"mcm","clk":"11540730862","pt":1719497768435,"mc":[{"id":"1.230180118","rc":[{"atl":[[10.5,37.28]],"id":48534288}],"con":true,"img":false}]}
{"op":"mcm","clk":"11540730870","pt":1719497768536,"mc":[{"id":"1.230180118","rc":[{"atl":[[13.5,4.84]],"id":48534288}],"con":true,"img":false}]}
{"op":"mcm","clk":"11540730880","pt":1719497768648,"mc":[{"id":"1.230180118","rc":[{"atl":[[13.5,1.05]],"id":48534288}],"con":true,"img":false}]}
{"op":"mcm","clk":"11540730892","pt":1719497768746,"mc":[{"id":"1.230180118","rc":[{"atl":[[10,3.79]],"id":48534288}],"con":true,"img":false}]}
{"op":"mcm","clk":"11540730898","pt":1719497768847,"mc":[{"id":"1.230180118","rc":[{"atl":[[10,37.79]],"id":48534288}],"con":true,"img":false}]}
{"op":"mcm","clk":"11540730906","pt":1719497768958,"mc":[{"id":"1.230180118","rc":[{"atl":[[10.5,3.28]],"id":48534288}],"con":true,"img":false}]}
{"op":"mcm","clk":"11540730916","pt":1719497769060,"mc":[{"id":"1.230180118","rc":[{"atl":[[11,0]],"id":48534288}],"con":true,"img":false}]}
{"op":"mcm","clk":"11540730923","pt":1719497769163,"mc":[{"id":"1.230180118","rc":[{"atl":[[10.5,2.42]],"id":48534288}],"con":true,"img":false}]}
{"op":"mcm","clk":"11540730933","pt":1719497769269,"mc":[{"id":"1.230180118","rc":[{"atl":[[9.8,0.86]],"id":48534288}],"con":true,"img":false}]}
{"op":"mcm","clk":"11540730947","pt":1719497769374,"mc":[{"id":"1.230180118","rc":[{"atl":[[10,3.79],[9.8,34.86]],"id":48534288}],"con":true,"img":false}]}
{"op":"mcm","clk":"11540730958","pt":1719497769420,"mc":[{"id":"1.230180118","rc":[{"atl":[[10.5,0]],"id":48534288}],"con":true,"img":false}]}
{"op":"mcm","clk":"11540730966","pt":1719497769523,"mc":[{"id":"1.230180118","rc":[{"atl":[[10,0]],"id":48534288}],"con":true,"img":false}]}
{"op":"mcm","clk":"11540730978","pt":1719497769623,"mc":[{"id":"1.230180118","rc":[{"atl":[[9.6,3.79]],"id":48534288}],"con":true,"img":false}]}
{"op":"mcm","clk":"11540730990","pt":1719497769726,"mc":[{"id":"1.230180118","rc":[{"atl":[[9.6,37.79],[9.8,34]],"id":48534288}],"con":true,"img":false}]}
{"op":"mcm","clk":"11540730996","pt":1719497769829,"mc":[{"id":"1.230180118","rc":[{"atb":[[1.04,1.7]],"id":50772801},{"atl":[[1000,1.93]],"id":50772801},{"atl":[[7.2,1.05]],"id":69624671},{"atl":[[9.8,0]],"id":48534288}],"con":true,"img":false}]}
{"op":"mcm","clk":"11540731014","pt":1719497770044,"mc":[{"id":"1.230180118","rc":[{"atb":[[1.04,0.07]],"id":50772801},{"atl":[[1000,0.23]],"id":50772801},{"atl":[[9.6,34]],"id":48534288}],"con":true,"img":false}]}
{"op":"mcm","clk":"11540731025","pt":1719497770148,"mc":[{"id":"1.230180118","rc":[{"atl":[[1000,0.4]],"id":69624671},{"atl":[[13.5,4.84]],"id":48534288}],"con":true,"img":false}]}
{"op":"mcm","clk":"11540731032","pt":1719497770249,"mc":[{"id":"1.230180118","rc":[{"atb":[[1.04,0]],"id":50772801},{"atl":[[9.4,2.7]],"id":48534288}],"con":true,"img":false}]}
{"op":"mcm","clk":"11540731041","pt":1719497770354,"mc":[{"id":"1.230180118","rc":[{"atb":[[5.2,0.07]],"id":50772801},{"atl":[[1000,0.23]],"id":69624671},{"atl":[[13.5,1.05],[9.4,36.7]],"id":48534288}],"con":true,"img":false}]}
{"op":"mcm","clk":"11540731053","pt":1719497770459,"mc":[{"id":"1.230180118","rc":[{"atl":[[7,0.17]],"id":69624671},{"atl":[[9.6,0],[9.4,40.49]],"id":48534288}],"con":true,"img":false}]}
{"op":"mcm","clk":"11540731070","pt":1719497770664,"mc":[{"id":"1.230180118","rc":[{"atl":[[9.4,36.7]],"id":48534288}],"con":true,"img":false}]}
{"op":"mcm","clk":"11540731081","pt":1719497770767,"mc":[{"id":"1.230180118","rc":[{"atl":[[13.5,4.84]],"id":48534288}],"con":true,"img":false}]}
{"op":"mcm","clk":"11540731110","pt":1719497771081,"mc":[{"id":"1.230180118","rc":[{"atl":[[13.5,1.05]],"id":48534288}],"con":true,"img":false}]}
{"op":"mcm","clk":"11540731120","pt":1719497771123,"mc":[{"id":"1.230180118","rc":[{"atl":[[9.2,3.79]],"id":48534288}],"con":true,"img":false}]}
{"op":"mcm","clk":"11540731133","pt":1719497771236,"mc":[{"id":"1.230180118","rc":[{"atl":[[9.2,37.79],[9.4,2.7]],"id":48534288}],"con":true,"img":false}]}
{"op":"mcm","clk":"11540731163","pt":1719497771535,"mc":[{"id":"1.230180118","rc":[{"atl":[[9,0.86]],"id":48534288}],"con":true,"img":false}]}
{"op":"mcm","clk":"11540731169","pt":1719497771638,"mc":[{"id":"1.230180118","rc":[{"atl":[[9,34.86],[9.4,0]],"id":48534288}],"con":true,"img":false}]}
{"op":"mcm","clk":"11540731176","pt":1719497771741,"mc":[{"id":"1.230180118","rc":[{"atl":[[9.2,3.79]],"id":48534288}],"con":true,"img":false}]}
{"op":"mcm","clk":"11540731185","pt":1719497771847,"mc":[{"id":"1.230180118","rc":[{"atb":[[3.95,0]],"id":69624671},{"atl":[[9.2,0],[8.8,2.88]],"id":48534288}],"con":true,"img":false}]}
{"op":"mcm","clk":"11540731195","pt":1719497771949,"mc":[{"id":"1.230180118","rc":[{"atl":[[7.2,0]],"id":69624671},{"atl":[[9,0.86],[8.8,40.67]],"id":48534288}],"con":true,"img":false}]}
{"op":"mcm","clk":"11540731206","pt":1719497772155,"mc":[{"id":"1.230180118","rc":[{"atl":[[8.8,36.88]],"id":48534288}],"con":true,"img":false}]}
{"op":"mcm","clk":"11540731217","pt":1719497772263,"mc":[{"id":"1.230180118","rc":[{"atl":[[7,1.22]],"id":69624671},{"atl":[[13.5,4.84]],"id":48534288}],"con":true,"img":false}]}
{"op":"mcm","clk":"11540731226","pt":1719497772365,"mc":[{"id":"1.230180118","rc":[{"atb":[[3.95,0.53]],"id":69624671}],"con":true,"img":false}]}
{"op":"mcm","clk":"11540731240","pt":1719497772465,"mc":[{"id":"1.230180118","rc":[{"atl":[[13.5,1.05]],"id":48534288}],"con":true,"img":false}]}
{"op":"mcm","clk":"11540731246","pt":1719497772519,"mc":[{"id":"1.230180118","rc":[{"atl":[[8.6,3.79]],"id":48534288}],"con":true,"img":false}]}
{"op":"mcm","clk":"11540731258","pt":1719497772628,"mc":[{"id":"1.230180118","rc":[{"atl":[[8.6,37.79],[8.8,2.88]],"id":48534288},{"atb":[[3.2,3.64]],"id":69475360}],"con":true,"img":false}]}
{"op":"mcm","clk":"11540731275","pt":1719497772831,"mc":[{"id":"1.230180118","rc":[{"atl":[[9,0]],"id":48534288}],"con":true,"img":false}]}
{"op":"mcm","clk":"11540731283","pt":1719497772935,"mc":[{"id":"1.230180118","rc":[{"atl":[[8.8,0],[8.4,0.86]],"id":48534288}],"con":true,"img":false}]}
{"op":"mcm","clk":"11540731290","pt":1719497773037,"mc":[{"id":"1.230180118","rc":[{"atl":[[8.6,0],[8.4,34.86]],"id":48534288},{"atl":[[3.9,0]],"id":69475360},{"trd":[[3.9,9.69]],"ltp":3.9,"tv":9.69,"id":69475360}],"con":true,"img":false}]}
{"op":"mcm","clk":"11540731295","pt":1719497773142,"mc":[{"id":"1.230180118","rc":[{"atl":[[13.5,4.84]],"id":48534288}],"con":true,"img":false}]}
{"op":"mcm","clk":"11540731315","pt":1719497773347,"mc":[{"id":"1.230180118","rc":[{"atl":[[13.5,1.05],[8.4,34]],"id":48534288}],"con":true,"img":false}]}
{"op":"mcm","clk":"11540731323","pt":1719497773450,"mc":[{"id":"1.230180118","rc":[{"atl":[[8.2,3.79]],"id":48534288}],"con":true,"img":false}]}
{"op":"mcm","clk":"11540731328","pt":1719497773559,"mc":[{"id":"1.230180118","rc":[{"atl":[[8.2,40.88]],"id":48534288}],"con":true,"img":false}]}
{"op":"mcm","clk":"11540731336","pt":1719497773668,"mc":[{"id":"1.230180118","rc":[{"atl":[[8.4,0]],"id":48534288}],"con":true,"img":false}]}
{"op":"mcm","clk":"11540731347","pt":1719497773866,"mc":[{"id":"1.230180118","rc":[{"atl":[[8.2,37.09]],"id":48534288}],"con":true,"img":false}]}
{"op":"mcm","clk":"11540731354","pt":1719497773966,"mc":[{"id":"1.230180118","rc":[{"atl":[[13.5,4.84]],"id":48534288}],"con":true,"img":false}]}
{"op":"mcm","clk":"11540731363","pt":1719497774126,"mc":[{"id":"1.230180118","rc":[{"atl":[[13.5,1.05]],"id":48534288}],"con":true,"img":false}]}
{"op":"mcm","clk":"11540731375","pt":1719497774231,"mc":[{"id":"1.230180118","rc":[{"atl":[[8,3.79]],"id":48534288}],"con":true,"img":false}]}
{"op":"mcm","clk":"11540731391","pt":1719497774429,"mc":[{"id":"1.230180118","rc":[{"atl":[[8,37.79],[8.2,3.09]],"id":48534288}],"con":true,"img":false}]}
{"op":"mcm","clk":"11540731403","pt":1719497774537,"mc":[{"id":"1.230180118","rc":[{"atl":[[7.8,0.86]],"id":48534288}],"con":true,"img":false}]}
{"op":"mcm","clk":"11540731413","pt":1719497774636,"mc":[{"id":"1.230180118","rc":[{"atl":[[8.2,0],[7.8,34.86]],"id":48534288}],"con":true,"img":false}]}
{"op":"mcm","clk":"11540731418","pt":1719497774739,"mc":[{"id":"1.230180118","rc":[{"atl":[[8,3.79]],"id":48534288}],"con":true,"img":false}]}
{"op":"mcm","clk":"11540731428","pt":1719497774844,"mc":[{"id":"1.230180118","rc":[{"atl":[[8,0]],"id":48534288}],"con":true,"img":false}]}
{"op":"mcm","clk":"11540731434","pt":1719497774944,"mc":[{"id":"1.230180118","rc":[{"atl":[[7.6,7.13]],"id":48534288}],"con":true,"img":false}]}
{"op":"mcm","clk":"11540731443","pt":1719497775049,"mc":[{"id":"1.230180118","rc":[{"atl":[[7.6,41.98],[7.8,0.86]],"id":48534288}],"con":true,"img":false}]}
{"op":"mcm","clk":"11540731453","pt":1719497775153,"mc":[{"id":"1.230180118","rc":[{"atl":[[7.8,0]],"id":48534288}],"con":true,"img":false}]}
{"op":"mcm","clk":"11540731466","pt":1719497775264,"mc":[{"id":"1.230180118","rc":[{"atl":[[7.4,0.86],[7.6,38.19]],"id":48534288}],"con":true,"img":false}]}
{"op":"mcm","clk":"11540731472","pt":1719497775357,"mc":[{"id":"1.230180118","rc":[{"atl":[[7.4,34.86],[13.5,4.84]],"id":48534288}],"con":true,"img":false}]}
{"op":"mcm","clk":"11540731485","pt":1719497775463,"mc":[{"id":"1.230180118","rc":[{"atl":[[7.6,4.19],[13.5,1.05]],"id":48534288}],"con":true,"img":false}]}
{"op":"mcm","clk":"11540731494","pt":1719497775566,"mc":[{"id":"1.230180118","rc":[{"atl":[[7.2,3.79],[7.6,0.84]],"id":48534288}],"con":true,"img":false}]}
{"op":"mcm","clk":"11540731507","pt":1719497775671,"mc":[{"id":"1.230180118","rc":[{"atl":[[7.2,37.79],[7.4,0.86],[7,3.63]],"id":48534288}],"con":true,"img":false}]}
{"op":"mcm","clk":"11540731518","pt":1719497775734,"mc":[{"id":"1.230180118","rc":[{"atl":[[7,37.63]],"id":48534288}],"con":true,"img":false}]}
{"op":"mcm","clk":"11540731526","pt":1719497775826,"mc":[{"id":"1.230180118","rc":[{"atl":[[7.2,3.79]],"id":48534288}],"con":true,"img":false}]}
{"op":"mcm","clk":"11540731561","pt":1719497776137,"mc":[{"id":"1.230180118","rc":[{"atl":[[7.6,0]],"id":48534288}],"con":true,"img":false}]}
{"op":"mcm","clk":"11540731673","pt":1719497777433,"mc":[{"id":"1.230180118","rc":[{"atl":[[1000,2.23]],"id":48534288}],"con":true,"img":false}]}
{"op":"mcm","clk":"11540731681","pt":1719497777534,"mc":[{"id":"1.230180118","rc":[{"atb":[[2.64,4.33]],"id":69475360}],"con":true,"img":false}]}
{"op":"mcm","clk":"11540731696","pt":1719497777639,"mc":[{"id":"1.230180118","rc":[{"atl":[[1000,0.73]],"id":48534288}],"con":true,"img":false}]}
{"op":"mcm","clk":"11540731703","pt":1719497777753,"mc":[{"id":"1.230180118","rc":[{"atb":[[2.16,26.7]],"id":62145089}],"con":true,"img":false}]}
{"op":"mcm","clk":"11540731710","pt":1719497777845,"mc":[{"id":"1.230180118","rc":[{"atl":[[1000,0.23]],"id":48534288}],"con":true,"img":false}]}
{"op":"mcm","clk":"11540731717","pt":1719497777949,"mc":[{"id":"1.230180118","rc":[{"atl":[[6.8,0.5]],"id":48534288}],"con":true,"img":false}]}
{"op":"mcm","clk":"11540731725","pt":1719497778051,"mc":[{"id":"1.230180118","rc":[{"atl":[[6.8,34.5],[7,3.63]],"id":48534288}],"con":true,"img":false}]}
{"op":"mcm","clk":"11540731743","pt":1719497778262,"mc":[{"id":"1.230180118","rc":[{"atl":[[7.4,0],[6.8,18.5]],"id":48534288}],"con":true,"img":false}]}
{"op":"mcm","clk":"11540731749","pt":1719497778362,"mc":[{"id":"1.230180118","rc":[{"atl":[[6.8,19.36]],"id":48534288}],"con":true,"img":false}]}
{"op":"mcm","clk":"11540731769","pt":1719497778570,"mc":[{"id":"1.230180118","rc":[{"atl":[[7,0]],"id":48534288}],"con":true,"img":false}]}
{"op":"mcm","clk":"11540731785","pt":1719497778776,"mc":[{"id":"1.230180118","rc":[{"atl":[[6.6,3.85]],"id":48534288}],"con":true,"img":false}]}
{"op":"mcm","clk":"11540731797","pt":1719497778828,"mc":[{"id":"1.230180118","rc":[{"atl":[[6.8,1.36]],"id":48534288}],"con":true,"img":false}]}
{"op":"mcm","clk":"11540731836","pt":1719497779343,"mc":[{"id":"1.230180118","rc":[{"atl":[[6.8,0.5]],"id":48534288}],"con":true,"img":false}]}
{"op":"mcm","clk":"11540731872","pt":1719497779864,"mc":[{"id":"1.230180118","rc":[{"atl":[[6.6,0]],"id":48534288}],"con":true,"img":false}]}
{"op":"mcm","clk":"11540731882","pt":1719497779964,"mc":[{"id":"1.230180118","rc":[{"atl":[[6.8,18.5]],"id":48534288}],"con":true,"img":false}]}
{"op":"mcm","clk":"11540731928","pt":1719497780436,"mc":[{"id":"1.230180118","rc":[{"atl":[[6.6,3.85]],"id":48534288}],"con":true,"img":false}]}
{"op":"mcm","clk":"11540731933","pt":1719497780531,"mc":[{"id":"1.230180118","rc":[{"atl":[[6.6,4.71]],"id":48534288}],"con":true,"img":false}]}
{"op":"mcm","clk":"11540731942","pt":1719497780636,"mc":[{"id":"1.230180118","rc":[{"atl":[[6.8,0]],"id":48534288}],"con":true,"img":false}]}
{"op":"mcm","clk":"11540731968","pt":1719497781153,"mc":[{"id":"1.230180118","rc":[{"atl":[[13.5,0],[6.6,3.85]],"id":48534288}],"con":true,"img":false}]}
{"op":"mcm","clk":"11540732006","pt":1719497781565,"mc":[{"id":"1.230180118","rc":[{"atb":[[4.8,0.84]],"id":48534288}],"con":true,"img":false}]}
{"op":"mcm","clk":"11540732020","pt":1719497781872,"mc":[{"id":"1.230180118","rc":[{"atl":[[6.6,0]],"id":48534288}],"con":true,"img":false}]}
{"op":"mcm","clk":"11540732031","pt":1719497781928,"mc":[{"id":"1.230180118","rc":[{"atl":[[7.2,21.79]],"id":48534288}],"con":true,"img":false}]}
{"op":"mcm","clk":"11540732040","pt":1719497782026,"mc":[{"id":"1.230180118","rc":[{"atl":[[7,0.84]],"id":48534288}],"con":true,"img":false}]}
{"op":"mcm","clk":"11540732047","pt":1719497782134,"mc":[{"id":"1.230180118","rc":[{"atl":[[7,18.84]],"id":48534288}],"con":true,"img":false}]}
{"op":"mcm","clk":"11540732055","pt":1719497782237,"mc":[{"id":"1.230180118","rc":[{"atl":[[7.2,3.79]],"id":48534288}],"con":true,"img":false}]}
{"op":"mcm","clk":"11540732062","pt":1719497782339,"mc":[{"id":"1.230180118","rc":[{"atl":[[6.8,0.86]],"id":48534288}],"con":true,"img":false}]}
{"op":"mcm","clk":"11540732073","pt":1719497782438,"mc":[{"id":"1.230180118","rc":[{"atl":[[6.8,22.59],[7,0.84]],"id":48534288}],"con":true,"img":false}]}
