{"op":"mcm","clk":"11547086386","pt":1719432856306,"mc":[{"id":"1.230178170","marketDefinition":{"bspMarket":false,"turnInPlayEnabled":false,"persistenceEnabled":false,"marketBaseRate":5.0,"eventId":"33376048","eventTypeId":"4339","numberOfWinners":1,"bettingType":"ODDS","marketType":"FORECAST","marketTime":"2024-06-27T14:44:00.000Z","suspendTime":"2024-06-27T14:44:00.000Z","bspReconciled":false,"complete":true,"inPlay":false,"crossMatching":false,"runnersVoidable":false,"numberOfActiveRunners":30,"betDelay":0,"status":"OPEN","runners":[{"status":"ACTIVE","sortPriority":1,"id":52385882,"name":"1 - 2"},{"status":"ACTIVE","sortPriority":2,"id":52385883,"name":"1 - 3"},{"status":"ACTIVE","sortPriority":3,"id":52385884,"name":"1 - 4"},{"status":"ACTIVE","sortPriority":4,"id":52385885,"name":"1 - 5"},{"status":"ACTIVE","sortPriority":5,"id":52385886,"name":"1 - 6"},{"status":"ACTIVE","sortPriority":6,"id":52385889,"name":"2 - 1"},{"status":"ACTIVE","sortPriority":7,"id":52385890,"name":"2 - 3"},{"status":"ACTIVE","sortPriority":8,"id":52385891,"name":"2 - 4"},{"status":"ACTIVE","sortPriority":9,"id":52385892,"name":"2 - 5"},{"status":"ACTIVE","sortPriority":10,"id":52385893,"name":"2 - 6"},{"status":"ACTIVE","sortPriority":11,"id":52385896,"name":"3 - 1"},{"status":"ACTIVE","sortPriority":12,"id":52385897,"name":"3 - 2"},{"status":"ACTIVE","sortPriority":13,"id":52385898,"name":"3 - 4"},{"status":"ACTIVE","sortPriority":14,"id":52385899,"name":"3 - 5"},{"status":"ACTIVE","sortPriority":15,"id":52385900,"name":"3 - 6"},{"status":"ACTIVE","sortPriority":16,"id":52385903,"name":"4 - 1"},{"status":"ACTIVE","sortPriority":17,"id":52385904,"name":"4 - 2"},{"status":"ACTIVE","sortPriority":18,"id":52385905,"name":"4 - 3"},{"status":"ACTIVE","sortPriority":19,"id":52385906,"name":"4 - 5"},{"status":"ACTIVE","sortPriority":20,"id":52385907,"name":"4 - 6"},{"status":"ACTIVE","sortPriority":21,"id":52385910,"name":"5 - 1"},{"status":"ACTIVE","sortPriority":22,"id":52385911,"name":"5 - 2"},{"status":"ACTIVE","sortPriority":23,"id":52385912,"name":"5 - 3"},{"status":"ACTIVE","sortPriority":24,"id":52385913,"name":"5 - 4"},{"status":"ACTIVE","sortPriority":25,"id":52385914,"name":"5 - 6"},{"status":"ACTIVE","sortPriority":26,"id":52385917,"name":"6 - 1"},{"status":"ACTIVE","sortPriority":27,"id":52385918,"name":"6 - 2"},{"status":"ACTIVE","sortPriority":28,"id":52385919,"name":"6 - 3"},{"status":"ACTIVE","sortPriority":29,"id":52385920,"name":"6 - 4"},{"status":"ACTIVE","sortPriority":30,"id":52385921,"name":"6 - 5"}],"regulators":["MR_INT"],"venue":"Perry Barr","countryCode":"GB","discountAllowed":false,"timezone":"Europe/London","openDate":"2024-06-27T13:29:00.000Z","version":5994794110,"name":"Forecast","eventName":"Perry Barr (F/C) 27th Jun"},"rc":[],"con":true,"img":false}]}
{"op":"mcm","clk":"11547086543","pt":1719432858308,"mc":[{"id":"1.230178170","marketDefinition":{"bspMarket":false,"turnInPlayEnabled":false,"persistenceEnabled":false,"marketBaseRate":5.0,"eventId":"33376048","eventTypeId":"4339","numberOfWinners":1,"bettingType":"ODDS","marketType":"FORECAST","marketTime":"2024-06-27T14:44:00.000Z","suspendTime":"2024-06-27T14:44:00.000Z","bspReconciled":false,"complete":true,"inPlay":false,"crossMatching":false,"runnersVoidable":false,"numberOfActiveRunners":30,"betDelay":0,"status":"OPEN","runners":[{"status":"ACTIVE","sortPriority":1,"id":52385882,"name":"1 - 2"},{"status":"ACTIVE","sortPriority":2,"id":52385883,"name":"1 - 3"},{"status":"ACTIVE","sortPriority":3,"id":52385884,"name":"1 - 4"},{"status":"ACTIVE","sortPriority":4,"id":52385885,"name":"1 - 5"},{"status":"ACTIVE","sortPriority":5,"id":52385886,"name":"1 - 6"},{"status":"ACTIVE","sortPriority":6,"id":52385889,"name":"2 - 1"},{"status":"ACTIVE","sortPriority":7,"id":52385890,"name":"2 - 3"},{"status":"ACTIVE","sortPriority":8,"id":52385891,"name":"2 - 4"},{"status":"ACTIVE","sortPriority":9,"id":52385892,"name":"2 - 5"},{"status":"ACTIVE","sortPriority":10,"id":52385893,"name":"2 - 6"},{"status":"ACTIVE","sortPriority":11,"id":52385896,"name":"3 - 1"},{"status":"ACTIVE","sortPriority":12,"id":52385897,"name":"3 - 2"},{"status":"ACTIVE","sortPriority":13,"id":52385898,"name":"3 - 4"},{"status":"ACTIVE","sortPriority":14,"id":52385899,"name":"3 - 5"},{"status":"ACTIVE","sortPriority":15,"id":52385900,"name":"3 - 6"},{"status":"ACTIVE","sortPriority":16,"id":52385903,"name":"4 - 1"},{"status":"ACTIVE","sortPriority":17,"id":52385904,"name":"4 - 2"},{"status":"ACTIVE","sortPriority":18,"id":52385905,"name":"4 - 3"},{"status":"ACTIVE","sortPriority":19,"id":52385906,"name":"4 - 5"},{"status":"ACTIVE","sortPriority":20,"id":52385907,"name":"4 - 6"},{"status":"ACTIVE","sortPriority":21,"id":52385910,"name":"5 - 1"},{"status":"ACTIVE","sortPriority":22,"id":52385911,"name":"5 - 2"},{"status":"ACTIVE","sortPriority":23,"id":52385912,"name":"5 - 3"},{"status":"ACTIVE","sortPriority":24,"id":52385913,"name":"5 - 4"},{"status":"ACTIVE","sortPriority":25,"id":52385914,"name":"5 - 6"},{"status":"ACTIVE","sortPriority":26,"id":52385917,"name":"6 - 1"},{"status":"ACTIVE","sortPriority":27,"id":52385918,"name":"6 - 2"},{"status":"ACTIVE","sortPriority":28,"id":52385919,"name":"6 - 3"},{"status":"ACTIVE","sortPriority":29,"id":52385920,"name":"6 - 4"},{"status":"ACTIVE","sortPriority":30,"id":52385921,"name":"6 - 5"}],"regulators":["MR_INT"],"venue":"Perry Barr","countryCode":"GB","discountAllowed":true,"timezone":"Europe/London","openDate":"2024-06-27T13:29:00.000Z","version":5994794110,"name":"Forecast","eventName":"Perry Barr (F/C) 27th Jun"},"rc":[],"con":true,"img":false}]}
{"op":"mcm","clk":"11547344333","pt":1719439057811,"mc":[{"id":"1.230178170","rc":[{"atb":[[1.01,23.42]],"id":52385910},{"atb":[[1.03,7.81]],"id":52385912},{"atb":[[1.03,7.81]],"id":52385906},{"atb":[[1.02,11.71]],"id":52385918},{"atb":[[1.03,7.81]],"id":52385920},{"atb":[[1.02,11.71]],"id":52385889},{"atb":[[1.01,23.42]],"id":52385914},{"atb":[[1.03,7.81]],"id":52385883},{"atb":[[1.01,23.42]],"id":52385885},{"atb":[[1.03,7.81]],"id":52385896},{"atb":[[1.01,23.42]],"id":52385890},{"atb":[[1.02,11.71]],"id":52385892},{"atb":[[1.03,7.81]],"id":52385904},{"atb":[[1.01,23.42]],"id":52385898},{"atb":[[1.02,11.71]],"id":52385900},{"atb":[[1.03,7.81]],"id":52385911},{"atb":[[1.02,11.71]],"id":52385913},{"atb":[[1.01,23.42]],"id":52385907},{"atb":[[1.02,11.71]],"id":52385886},{"atb":[[1.03,7.81]],"id":52385919},{"atb":[[1.03,7.81]],"id":52385921},{"atb":[[1.03,7.81]],"id":52385882},{"atb":[[1.01,23.42]],"id":52385884},{"atb":[[1.01,23.42]],"id":52385917},{"atb":[[1.01,23.42]],"id":52385897},{"atb":[[1.02,11.71]],"id":52385891},{"atb":[[1.01,23.42]],"id":52385893},{"atb":[[1.01,23.42]],"id":52385903},{"atb":[[1.03,7.81]],"id":52385905},{"atb":[[1.03,7.81]],"id":52385899}],"con":true,"img":false}]}
{"op":"mcm","clk":"11547371013","pt":1719439682592,"mc":[{"id":"1.230178170","marketDefinition":{"bspMarket":false,"turnInPlayEnabled":false,"persistenceEnabled":false,"marketBaseRate":5.0,"eventId":"33376048","eventTypeId":"4339","numberOfWinners":1,"bettingType":"ODDS","marketType":"FORECAST","marketTime":"2024-06-27T14:44:00.000Z","suspendTime":"2024-06-27T14:44:00.000Z","bspReconciled":false,"complete":true,"inPlay":false,"crossMatching":false,"runnersVoidable":false,"numberOfActiveRunners":30,"betDelay":0,"status":"OPEN","runners":[{"status":"ACTIVE","sortPriority":1,"id":52385882,"name":"1 - 2"},{"status":"ACTIVE","sortPriority":2,"id":52385883,"name":"1 - 3"},{"status":"ACTIVE","sortPriority":3,"id":52385884,"name":"1 - 4"},{"status":"ACTIVE","sortPriority":4,"id":52385885,"name":"1 - 5"},{"status":"ACTIVE","sortPriority":5,"id":52385886,"name":"1 - 6"},{"status":"ACTIVE","sortPriority":6,"id":52385889,"name":"2 - 1"},{"status":"ACTIVE","sortPriority":7,"id":52385890,"name":"2 - 3"},{"status":"ACTIVE","sortPriority":8,"id":52385891,"name":"2 - 4"},{"status":"ACTIVE","sortPriority":9,"id":52385892,"name":"2 - 5"},{"status":"ACTIVE","sortPriority":10,"id":52385893,"name":"2 - 6"},{"status":"ACTIVE","sortPriority":11,"id":52385896,"name":"3 - 1"},{"status":"ACTIVE","sortPriority":12,"id":52385897,"name":"3 - 2"},{"status":"ACTIVE","sortPriority":13,"id":52385898,"name":"3 - 4"},{"status":"ACTIVE","sortPriority":14,"id":52385899,"name":"3 - 5"},{"status":"ACTIVE","sortPriority":15,"id":52385900,"name":"3 - 6"},{"status":"ACTIVE","sortPriority":16,"id":52385903,"name":"4 - 1"},{"status":"ACTIVE","sortPriority":17,"id":52385904,"name":"4 - 2"},{"status":"ACTIVE","sortPriority":18,"id":52385905,"name":"4 - 3"},{"status":"ACTIVE","sortPriority":19,"id":52385906,"name":"4 - 5"},{"status":"ACTIVE","sortPriority":20,"id":52385907,"name":"4 - 6"},{"status":"ACTIVE","sortPriority":21,"id":52385910,"name":"5 - 1"},{"status":"ACTIVE","sortPriority":22,"id":52385911,"name":"5 - 2"},{"status":"ACTIVE","sortPriority":23,"id":52385912,"name":"5 - 3"},{"status":"ACTIVE","sortPriority":24,"id":52385913,"name":"5 - 4"},{"status":"ACTIVE","sortPriority":25,"id":52385914,"name":"5 - 6"},{"status":"ACTIVE","sortPriority":26,"id":52385917,"name":"6 - 1"},{"status":"ACTIVE","sortPriority":27,"id":52385918,"name":"6 - 2"},{"status":"ACTIVE","sortPriority":28,"id":52385919,"name":"6 - 3"},{"status":"ACTIVE","sortPriority":29,"id":52385920,"name":"6 - 4"},{"status":"ACTIVE","sortPriority":30,"id":52385921,"name":"6 - 5"}],"regulators":["MR_INT"],"venue":"Perry Barr","countryCode":"GB","discountAllowed":true,"timezone":"Europe/London","openDate":"2024-06-27T13:29:00.000Z","version":5994794110,"name":"Forecast","eventName":"Perry Barr (F/C) 27th Jun"},"rc":[{"atb":[[1.01,23.41]],"id":52385910},{"atb":[[1.03,7.8]],"id":52385912},{"atb":[[1.03,7.8]],"id":52385906},{"atb":[[1.02,11.7]],"id":52385918},{"atb":[[1.03,7.8]],"id":52385920},{"atb":[[1.02,11.7]],"id":52385889},{"atb":[[1.01,23.41]],"id":52385914},{"atb":[[1.03,7.8]],"id":52385883},{"atb":[[1.01,23.41]],"id":52385885},{"atb":[[1.03,7.8]],"id":52385896},{"atb":[[1.01,23.41]],"id":52385890},{"atb":[[1.02,11.7]],"id":52385892},{"atb":[[1.03,7.8]],"id":52385904},{"atb":[[1.01,23.41]],"id":52385898},{"atb":[[1.02,11.7]],"id":52385900},{"atb":[[1.03,7.8]],"id":52385911},{"atb":[[1.02,11.7]],"id":52385913},{"atb":[[1.01,23.41]],"id":52385907},{"atb":[[1.02,11.7]],"id":52385886},{"atb":[[1.03,7.8]],"id":52385919},{"atb":[[1.03,7.8]],"id":52385921},{"atb":[[1.03,7.8]],"id":52385882},{"atb":[[1.01,23.41]],"id":52385884},{"atb":[[1.01,23.41]],"id":52385917},{"atb":[[1.01,23.41]],"id":52385897},{"atb":[[1.02,11.7]],"id":52385891},{"atb":[[1.01,23.41]],"id":52385893},{"atb":[[1.01,23.41]],"id":52385903},{"atb":[[1.03,7.8]],"id":52385905},{"atb":[[1.03,7.8]],"id":52385899}],"con":true,"img":true}]}
{"op":"mcm","clk":"11547659681","pt":1719445082619,"mc":[{"id":"1.230178170","marketDefinition":{"bspMarket":false,"turnInPlayEnabled":false,"persistenceEnabled":false,"marketBaseRate":5.0,"eventId":"33376048","eventTypeId":"4339","numberOfWinners":1,"bettingType":"ODDS","marketType":"FORECAST","marketTime":"2024-06-27T14:44:00.000Z","suspendTime":"2024-06-27T14:44:00.000Z","bspReconciled":false,"complete":true,"inPlay":false,"crossMatching":false,"runnersVoidable":false,"numberOfActiveRunners":30,"betDelay":0,"status":"OPEN","runners":[{"status":"ACTIVE","sortPriority":1,"id":52385882,"name":"1 - 2"},{"status":"ACTIVE","sortPriority":2,"id":52385883,"name":"1 - 3"},{"status":"ACTIVE","sortPriority":3,"id":52385884,"name":"1 - 4"},{"status":"ACTIVE","sortPriority":4,"id":52385885,"name":"1 - 5"},{"status":"ACTIVE","sortPriority":5,"id":52385886,"name":"1 - 6"},{"status":"ACTIVE","sortPriority":6,"id":52385889,"name":"2 - 1"},{"status":"ACTIVE","sortPriority":7,"id":52385890,"name":"2 - 3"},{"status":"ACTIVE","sortPriority":8,"id":52385891,"name":"2 - 4"},{"status":"ACTIVE","sortPriority":9,"id":52385892,"name":"2 - 5"},{"status":"ACTIVE","sortPriority":10,"id":52385893,"name":"2 - 6"},{"status":"ACTIVE","sortPriority":11,"id":52385896,"name":"3 - 1"},{"status":"ACTIVE","sortPriority":12,"id":52385897,"name":"3 - 2"},{"status":"ACTIVE","sortPriority":13,"id":52385898,"name":"3 - 4"},{"status":"ACTIVE","sortPriority":14,"id":52385899,"name":"3 - 5"},{"status":"ACTIVE","sortPriority":15,"id":52385900,"name":"3 - 6"},{"status":"ACTIVE","sortPriority":16,"id":52385903,"name":"4 - 1"},{"status":"ACTIVE","sortPriority":17,"id":52385904,"name":"4 - 2"},{"status":"ACTIVE","sortPriority":18,"id":52385905,"name":"4 - 3"},{"status":"ACTIVE","sortPriority":19,"id":52385906,"name":"4 - 5"},{"status":"ACTIVE","sortPriority":20,"id":52385907,"name":"4 - 6"},{"status":"ACTIVE","sortPriority":21,"id":52385910,"name":"5 - 1"},{"status":"ACTIVE","sortPriority":22,"id":52385911,"name":"5 - 2"},{"status":"ACTIVE","sortPriority":23,"id":52385912,"name":"5 - 3"},{"status":"ACTIVE","sortPriority":24,"id":52385913,"name":"5 - 4"},{"status":"ACTIVE","sortPriority":25,"id":52385914,"name":"5 - 6"},{"status":"ACTIVE","sortPriority":26,"id":52385917,"name":"6 - 1"},{"status":"ACTIVE","sortPriority":27,"id":52385918,"name":"6 - 2"},{"status":"ACTIVE","sortPriority":28,"id":52385919,"name":"6 - 3"},{"status":"ACTIVE","sortPriority":29,"id":52385920,"name":"6 - 4"},{"status":"ACTIVE","sortPriority":30,"id":52385921,"name":"6 - 5"}],"regulators":["MR_INT"],"venue":"Perry Barr","countryCode":"GB","discountAllowed":true,"timezone":"Europe/London","openDate":"2024-06-27T13:29:00.000Z","version":5994794110,"name":"Forecast","eventName":"Perry Barr (F/C) 27th Jun"},"rc":[{"atb":[[1.01,23.42]],"id":52385910},{"atb":[[1.03,7.81]],"id":52385912},{"atb":[[1.03,7.81]],"id":52385906},{"atb":[[1.02,11.71]],"id":52385918},{"atb":[[1.03,7.81]],"id":52385920},{"atb":[[1.02,11.71]],"id":52385889},{"atb":[[1.01,23.42]],"id":52385914},{"atb":[[1.03,7.81]],"id":52385883},{"atb":[[1.01,23.42]],"id":52385885},{"atb":[[1.03,7.81]],"id":52385896},{"atb":[[1.01,23.42]],"id":52385890},{"atb":[[1.02,11.71]],"id":52385892},{"atb":[[1.03,7.81]],"id":52385904},{"atb":[[1.01,23.42]],"id":52385898},{"atb":[[1.02,11.71]],"id":52385900},{"atb":[[1.03,7.81]],"id":52385911},{"atb":[[1.02,11.71]],"id":52385913},{"atb":[[1.01,23.42]],"id":52385907},{"atb":[[1.02,11.71]],"id":52385886},{"atb":[[1.03,7.81]],"id":52385919},{"atb":[[1.03,7.81]],"id":52385921},{"atb":[[1.03,7.81]],"id":52385882},{"atb":[[1.01,23.42]],"id":52385884},{"atb":[[1.01,23.42]],"id":52385917},{"atb":[[1.01,23.42]],"id":52385897},{"atb":[[1.02,11.71]],"id":52385891},{"atb":[[1.01,23.42]],"id":52385893},{"atb":[[1.01,23.42]],"id":52385903},{"atb":[[1.03,7.81]],"id":52385905},{"atb":[[1.03,7.81]],"id":52385899}],"con":true,"img":true}]}
{"op":"mcm","clk":"11548031725","pt":1719450482634,"mc":[{"id":"1.230178170","marketDefinition":{"bspMarket":false,"turnInPlayEnabled":false,"persistenceEnabled":false,"marketBaseRate":5.0,"eventId":"33376048","eventTypeId":"4339","numberOfWinners":1,"bettingType":"ODDS","marketType":"FORECAST","marketTime":"2024-06-27T14:44:00.000Z","suspendTime":"2024-06-27T14:44:00.000Z","bspReconciled":false,"complete":true,"inPlay":false,"crossMatching":false,"runnersVoidable":false,"numberOfActiveRunners":30,"betDelay":0,"status":"OPEN","runners":[{"status":"ACTIVE","sortPriority":1,"id":52385882,"name":"1 - 2"},{"status":"ACTIVE","sortPriority":2,"id":52385883,"name":"1 - 3"},{"status":"ACTIVE","sortPriority":3,"id":52385884,"name":"1 - 4"},{"status":"ACTIVE","sortPriority":4,"id":52385885,"name":"1 - 5"},{"status":"ACTIVE","sortPriority":5,"id":52385886,"name":"1 - 6"},{"status":"ACTIVE","sortPriority":6,"id":52385889,"name":"2 - 1"},{"status":"ACTIVE","sortPriority":7,"id":52385890,"name":"2 - 3"},{"status":"ACTIVE","sortPriority":8,"id":52385891,"name":"2 - 4"},{"status":"ACTIVE","sortPriority":9,"id":52385892,"name":"2 - 5"},{"status":"ACTIVE","sortPriority":10,"id":52385893,"name":"2 - 6"},{"status":"ACTIVE","sortPriority":11,"id":52385896,"name":"3 - 1"},{"status":"ACTIVE","sortPriority":12,"id":52385897,"name":"3 - 2"},{"status":"ACTIVE","sortPriority":13,"id":52385898,"name":"3 - 4"},{"status":"ACTIVE","sortPriority":14,"id":52385899,"name":"3 - 5"},{"status":"ACTIVE","sortPriority":15,"id":52385900,"name":"3 - 6"},{"status":"ACTIVE","sortPriority":16,"id":52385903,"name":"4 - 1"},{"status":"ACTIVE","sortPriority":17,"id":52385904,"name":"4 - 2"},{"status":"ACTIVE","sortPriority":18,"id":52385905,"name":"4 - 3"},{"status":"ACTIVE","sortPriority":19,"id":52385906,"name":"4 - 5"},{"status":"ACTIVE","sortPriority":20,"id":52385907,"name":"4 - 6"},{"status":"ACTIVE","sortPriority":21,"id":52385910,"name":"5 - 1"},{"status":"ACTIVE","sortPriority":22,"id":52385911,"name":"5 - 2"},{"status":"ACTIVE","sortPriority":23,"id":52385912,"name":"5 - 3"},{"status":"ACTIVE","sortPriority":24,"id":52385913,"name":"5 - 4"},{"status":"ACTIVE","sortPriority":25,"id":52385914,"name":"5 - 6"},{"status":"ACTIVE","sortPriority":26,"id":52385917,"name":"6 - 1"},{"status":"ACTIVE","sortPriority":27,"id":52385918,"name":"6 - 2"},{"status":"ACTIVE","sortPriority":28,"id":52385919,"name":"6 - 3"},{"status":"ACTIVE","sortPriority":29,"id":52385920,"name":"6 - 4"},{"status":"ACTIVE","sortPriority":30,"id":52385921,"name":"6 - 5"}],"regulators":["MR_INT"],"venue":"Perry Barr","countryCode":"GB","discountAllowed":true,"timezone":"Europe/London","openDate":"2024-06-27T13:29:00.000Z","version":5994794110,"name":"Forecast","eventName":"Perry Barr (F/C) 27th Jun"},"rc":[{"atb":[[1.01,23.42]],"id":52385910},{"atb":[[1.03,7.81]],"id":52385912},{"atb":[[1.03,7.81]],"id":52385906},{"atb":[[1.02,11.71]],"id":52385918},{"atb":[[1.03,7.81]],"id":52385920},{"atb":[[1.02,11.71]],"id":52385889},{"atb":[[1.01,23.42]],"id":52385914},{"atb":[[1.03,7.81]],"id":52385883},{"atb":[[1.01,23.42]],"id":52385885},{"atb":[[1.03,7.81]],"id":52385896},{"atb":[[1.01,23.42]],"id":52385890},{"atb":[[1.02,11.71]],"id":52385892},{"atb":[[1.03,7.81]],"id":52385904},{"atb":[[1.01,23.42]],"id":52385898},{"atb":[[1.02,11.71]],"id":52385900},{"atb":[[1.03,7.81]],"id":52385911},{"atb":[[1.02,11.71]],"id":52385913},{"atb":[[1.01,23.42]],"id":52385907},{"atb":[[1.02,11.71]],"id":52385886},{"atb":[[1.03,7.81]],"id":52385919},{"atb":[[1.03,7.81]],"id":52385921},{"atb":[[1.03,7.81]],"id":52385882},{"atb":[[1.01,23.42]],"id":52385884},{"atb":[[1.01,23.42]],"id":52385917},{"atb":[[1.01,23.42]],"id":52385897},{"atb":[[1.02,11.71]],"id":52385891},{"atb":[[1.01,23.42]],"id":52385893},{"atb":[[1.01,23.42]],"id":52385903},{"atb":[[1.03,7.81]],"id":52385905},{"atb":[[1.03,7.81]],"id":52385899}],"con":true,"img":true}]}
{"op":"mcm","clk":"11548270789","pt":1719455882654,"mc":[{"id":"1.230178170","marketDefinition":{"bspMarket":false,"turnInPlayEnabled":false,"persistenceEnabled":false,"marketBaseRate":5.0,"eventId":"33376048","eventTypeId":"4339","numberOfWinners":1,"bettingType":"ODDS","marketType":"FORECAST","marketTime":"2024-06-27T14:44:00.000Z","suspendTime":"2024-06-27T14:44:00.000Z","bspReconciled":false,"complete":true,"inPlay":false,"crossMatching":false,"runnersVoidable":false,"numberOfActiveRunners":30,"betDelay":0,"status":"OPEN","runners":[{"status":"ACTIVE","sortPriority":1,"id":52385882,"name":"1 - 2"},{"status":"ACTIVE","sortPriority":2,"id":52385883,"name":"1 - 3"},{"status":"ACTIVE","sortPriority":3,"id":52385884,"name":"1 - 4"},{"status":"ACTIVE","sortPriority":4,"id":52385885,"name":"1 - 5"},{"status":"ACTIVE","sortPriority":5,"id":52385886,"name":"1 - 6"},{"status":"ACTIVE","sortPriority":6,"id":52385889,"name":"2 - 1"},{"status":"ACTIVE","sortPriority":7,"id":52385890,"name":"2 - 3"},{"status":"ACTIVE","sortPriority":8,"id":52385891,"name":"2 - 4"},{"status":"ACTIVE","sortPriority":9,"id":52385892,"name":"2 - 5"},{"status":"ACTIVE","sortPriority":10,"id":52385893,"name":"2 - 6"},{"status":"ACTIVE","sortPriority":11,"id":52385896,"name":"3 - 1"},{"status":"ACTIVE","sortPriority":12,"id":52385897,"name":"3 - 2"},{"status":"ACTIVE","sortPriority":13,"id":52385898,"name":"3 - 4"},{"status":"ACTIVE","sortPriority":14,"id":52385899,"name":"3 - 5"},{"status":"ACTIVE","sortPriority":15,"id":52385900,"name":"3 - 6"},{"status":"ACTIVE","sortPriority":16,"id":52385903,"name":"4 - 1"},{"status":"ACTIVE","sortPriority":17,"id":52385904,"name":"4 - 2"},{"status":"ACTIVE","sortPriority":18,"id":52385905,"name":"4 - 3"},{"status":"ACTIVE","sortPriority":19,"id":52385906,"name":"4 - 5"},{"status":"ACTIVE","sortPriority":20,"id":52385907,"name":"4 - 6"},{"status":"ACTIVE","sortPriority":21,"id":52385910,"name":"5 - 1"},{"status":"ACTIVE","sortPriority":22,"id":52385911,"name":"5 - 2"},{"status":"ACTIVE","sortPriority":23,"id":52385912,"name":"5 - 3"},{"status":"ACTIVE","sortPriority":24,"id":52385913,"name":"5 - 4"},{"status":"ACTIVE","sortPriority":25,"id":52385914,"name":"5 - 6"},{"status":"ACTIVE","sortPriority":26,"id":52385917,"name":"6 - 1"},{"status":"ACTIVE","sortPriority":27,"id":52385918,"name":"6 - 2"},{"status":"ACTIVE","sortPriority":28,"id":52385919,"name":"6 - 3"},{"status":"ACTIVE","sortPriority":29,"id":52385920,"name":"6 - 4"},{"status":"ACTIVE","sortPriority":30,"id":52385921,"name":"6 - 5"}],"regulators":["MR_INT"],"venue":"Perry Barr","countryCode":"GB","discountAllowed":true,"timezone":"Europe/London","openDate":"2024-06-27T13:29:00.000Z","version":5994794110,"name":"Forecast","eventName":"Perry Barr (F/C) 27th Jun"},"rc":[{"atb":[[1.01,23.42]],"id":52385910},{"atb":[[1.03,7.81]],"id":52385912},{"atb":[[1.03,7.81]],"id":52385906},{"atb":[[1.02,11.71]],"id":52385918},{"atb":[[1.03,7.81]],"id":52385920},{"atb":[[1.02,11.71]],"id":52385889},{"atb":[[1.01,23.42]],"id":52385914},{"atb":[[1.03,7.81]],"id":52385883},{"atb":[[1.01,23.42]],"id":52385885},{"atb":[[1.03,7.81]],"id":52385896},{"atb":[[1.01,23.42]],"id":52385890},{"atb":[[1.02,11.71]],"id":52385892},{"atb":[[1.03,7.81]],"id":52385904},{"atb":[[1.01,23.42]],"id":52385898},{"atb":[[1.02,11.71]],"id":52385900},{"atb":[[1.03,7.81]],"id":52385911},{"atb":[[1.02,11.71]],"id":52385913},{"atb":[[1.01,23.42]],"id":52385907},{"atb":[[1.02,11.71]],"id":52385886},{"atb":[[1.03,7.81]],"id":52385919},{"atb":[[1.03,7.81]],"id":52385921},{"atb":[[1.03,7.81]],"id":52385882},{"atb":[[1.01,23.42]],"id":52385884},{"atb":[[1.01,23.42]],"id":52385917},{"atb":[[1.01,23.42]],"id":52385897},{"atb":[[1.02,11.71]],"id":52385891},{"atb":[[1.01,23.42]],"id":52385893},{"atb":[[1.01,23.42]],"id":52385903},{"atb":[[1.03,7.81]],"id":52385905},{"atb":[[1.03,7.81]],"id":52385899}],"con":true,"img":true}]}
{"op":"mcm","clk":"11548414840","pt":1719460931149,"mc":[{"id":"1.230178170","rc":[{"atb":[[1.01,23.42],[1.16,100]],"id":52385910},{"atb":[[1.03,7.81],[1.16,100]],"id":52385912},{"atb":[[1.03,7.81],[1.16,100]],"id":52385906},{"atb":[[1.16,100],[1.02,11.71]],"id":52385918},{"atb":[[1.03,7.81],[1.16,100]],"id":52385920},{"atb":[[1.16,100],[1.02,11.71]],"id":52385889},{"atb":[[1.01,23.42],[1.16,100]],"id":52385914},{"atb":[[1.03,7.81],[1.16,100]],"id":52385883},{"atb":[[1.01,23.42],[1.16,100]],"id":52385885},{"atb":[[1.03,7.81],[1.16,100]],"id":52385896},{"atb":[[1.01,23.42],[1.16,100]],"id":52385890},{"atb":[[1.16,100],[1.02,11.71]],"id":52385892},{"atb":[[1.03,7.81],[1.16,100]],"id":52385904},{"atb":[[1.01,23.42],[1.16,100]],"id":52385898},{"atb":[[1.16,100],[1.02,11.71]],"id":52385900},{"atb":[[1.03,7.81],[1.16,100]],"id":52385911},{"atb":[[1.16,100],[1.02,11.71]],"id":52385913},{"atb":[[1.01,23.42],[1.16,100]],"id":52385907},{"atb":[[1.16,100],[1.02,11.71]],"id":52385886},{"atb":[[1.03,7.81],[1.16,100]],"id":52385919},{"atb":[[1.03,7.81],[1.16,100]],"id":52385921},{"atb":[[1.03,7.81],[1.16,100]],"id":52385882},{"atb":[[1.01,23.42],[1.16,100]],"id":52385884},{"atb":[[1.01,23.42],[1.16,100]],"id":52385917},{"atb":[[1.01,23.42],[1.16,100]],"id":52385897},{"atb":[[1.16,100],[1.02,11.71]],"id":52385891},{"atb":[[1.01,23.42],[1.16,100]],"id":52385893},{"atb":[[1.01,23.42],[1.16,100]],"id":52385903},{"atb":[[1.03,7.81],[1.16,100]],"id":52385905},{"atb":[[1.03,7.81],[1.16,100]],"id":52385899}],"con":true,"img":false}]}
{"op":"mcm","clk":"11548535725","pt":1719466682820,"mc":[{"id":"1.230178170","marketDefinition":{"bspMarket":false,"turnInPlayEnabled":false,"persistenceEnabled":false,"marketBaseRate":5.0,"eventId":"33376048","eventTypeId":"4339","numberOfWinners":1,"bettingType":"ODDS","marketType":"FORECAST","marketTime":"2024-06-27T14:44:00.000Z","suspendTime":"2024-06-27T14:44:00.000Z","bspReconciled":false,"complete":true,"inPlay":false,"crossMatching":false,"runnersVoidable":false,"numberOfActiveRunners":30,"betDelay":0,"status":"OPEN","runners":[{"status":"ACTIVE","sortPriority":1,"id":52385882,"name":"1 - 2"},{"status":"ACTIVE","sortPriority":2,"id":52385883,"name":"1 - 3"},{"status":"ACTIVE","sortPriority":3,"id":52385884,"name":"1 - 4"},{"status":"ACTIVE","sortPriority":4,"id":52385885,"name":"1 - 5"},{"status":"ACTIVE","sortPriority":5,"id":52385886,"name":"1 - 6"},{"status":"ACTIVE","sortPriority":6,"id":52385889,"name":"2 - 1"},{"status":"ACTIVE","sortPriority":7,"id":52385890,"name":"2 - 3"},{"status":"ACTIVE","sortPriority":8,"id":52385891,"name":"2 - 4"},{"status":"ACTIVE","sortPriority":9,"id":52385892,"name":"2 - 5"},{"status":"ACTIVE","sortPriority":10,"id":52385893,"name":"2 - 6"},{"status":"ACTIVE","sortPriority":11,"id":52385896,"name":"3 - 1"},{"status":"ACTIVE","sortPriority":12,"id":52385897,"name":"3 - 2"},{"status":"ACTIVE","sortPriority":13,"id":52385898,"name":"3 - 4"},{"status":"ACTIVE","sortPriority":14,"id":52385899,"name":"3 - 5"},{"status":"ACTIVE","sortPriority":15,"id":52385900,"name":"3 - 6"},{"status":"ACTIVE","sortPriority":16,"id":52385903,"name":"4 - 1"},{"status":"ACTIVE","sortPriority":17,"id":52385904,"name":"4 - 2"},{"status":"ACTIVE","sortPriority":18,"id":52385905,"name":"4 - 3"},{"status":"ACTIVE","sortPriority":19,"id":52385906,"name":"4 - 5"},{"status":"ACTIVE","sortPriority":20,"id":52385907,"name":"4 - 6"},{"status":"ACTIVE","sortPriority":21,"id":52385910,"name":"5 - 1"},{"status":"ACTIVE","sortPriority":22,"id":52385911,"name":"5 - 2"},{"status":"ACTIVE","sortPriority":23,"id":52385912,"name":"5 - 3"},{"status":"ACTIVE","sortPriority":24,"id":52385913,"name":"5 - 4"},{"status":"ACTIVE","sortPriority":25,"id":52385914,"name":"5 - 6"},{"status":"ACTIVE","sortPriority":26,"id":52385917,"name":"6 - 1"},{"status":"ACTIVE","sortPriority":27,"id":52385918,"name":"6 - 2"},{"status":"ACTIVE","sortPriority":28,"id":52385919,"name":"6 - 3"},{"status":"ACTIVE","sortPriority":29,"id":52385920,"name":"6 - 4"},{"status":"ACTIVE","sortPriority":30,"id":52385921,"name":"6 - 5"}],"regulators":["MR_INT"],"venue":"Perry Barr","countryCode":"GB","discountAllowed":true,"timezone":"Europe/London","openDate":"2024-06-27T13:29:00.000Z","version":5994794110,"name":"Forecast","eventName":"Perry Barr (F/C) 27th Jun"},"rc":[{"atb":[[1.01,23.42],[1.16,100]],"id":52385910},{"atb":[[1.16,100],[1.03,7.81]],"id":52385912},{"atb":[[1.16,100],[1.03,7.81]],"id":52385906},{"atb":[[1.16,100],[1.02,11.71]],"id":52385918},{"atb":[[1.16,100],[1.03,7.81]],"id":52385920},{"atb":[[1.16,100],[1.02,11.71]],"id":52385889},{"atb":[[1.01,23.42],[1.16,100]],"id":52385914},{"atb":[[1.16,100],[1.03,7.81]],"id":52385883},{"atb":[[1.01,23.42],[1.16,100]],"id":52385885},{"atb":[[1.16,100],[1.03,7.81]],"id":52385896},{"atb":[[1.01,23.42],[1.16,100]],"id":52385890},{"atb":[[1.16,100],[1.02,11.71]],"id":52385892},{"atb":[[1.16,100],[1.03,7.81]],"id":52385904},{"atb":[[1.01,23.42],[1.16,100]],"id":52385898},{"atb":[[1.16,100],[1.02,11.71]],"id":52385900},{"atb":[[1.16,100],[1.03,7.81]],"id":52385911},{"atb":[[1.16,100],[1.02,11.71]],"id":52385913},{"atb":[[1.01,23.42],[1.16,100]],"id":52385907},{"atb":[[1.16,100],[1.02,11.71]],"id":52385886},{"atb":[[1.16,100],[1.03,7.81]],"id":52385919},{"atb":[[1.16,100],[1.03,7.81]],"id":52385921},{"atb":[[1.16,100],[1.03,7.81]],"id":52385882},{"atb":[[1.01,23.42],[1.16,100]],"id":52385884},{"atb":[[1.01,23.42],[1.16,100]],"id":52385917},{"atb":[[1.01,23.42],[1.16,100]],"id":52385897},{"atb":[[1.16,100],[1.02,11.71]],"id":52385891},{"atb":[[1.01,23.42],[1.16,100]],"id":52385893},{"atb":[[1.01,23.42],[1.16,100]],"id":52385903},{"atb":[[1.16,100],[1.03,7.81]],"id":52385905},{"atb":[[1.16,100],[1.03,7.81]],"id":52385899}],"con":true,"img":true}]}
{"op":"mcm","clk":"11548656206","pt":1719472082590,"mc":[{"id":"1.230178170","marketDefinition":{"bspMarket":false,"turnInPlayEnabled":false,"persistenceEnabled":false,"marketBaseRate":5.0,"eventId":"33376048","eventTypeId":"4339","numberOfWinners":1,"bettingType":"ODDS","marketType":"FORECAST","marketTime":"2024-06-27T14:44:00.000Z","suspendTime":"2024-06-27T14:44:00.000Z","bspReconciled":false,"complete":true,"inPlay":false,"crossMatching":false,"runnersVoidable":false,"numberOfActiveRunners":30,"betDelay":0,"status":"OPEN","runners":[{"status":"ACTIVE","sortPriority":1,"id":52385882,"name":"1 - 2"},{"status":"ACTIVE","sortPriority":2,"id":52385883,"name":"1 - 3"},{"status":"ACTIVE","sortPriority":3,"id":52385884,"name":"1 - 4"},{"status":"ACTIVE","sortPriority":4,"id":52385885,"name":"1 - 5"},{"status":"ACTIVE","sortPriority":5,"id":52385886,"name":"1 - 6"},{"status":"ACTIVE","sortPriority":6,"id":52385889,"name":"2 - 1"},{"status":"ACTIVE","sortPriority":7,"id":52385890,"name":"2 - 3"},{"status":"ACTIVE","sortPriority":8,"id":52385891,"name":"2 - 4"},{"status":"ACTIVE","sortPriority":9,"id":52385892,"name":"2 - 5"},{"status":"ACTIVE","sortPriority":10,"id":52385893,"name":"2 - 6"},{"status":"ACTIVE","sortPriority":11,"id":52385896,"name":"3 - 1"},{"status":"ACTIVE","sortPriority":12,"id":52385897,"name":"3 - 2"},{"status":"ACTIVE","sortPriority":13,"id":52385898,"name":"3 - 4"},{"status":"ACTIVE","sortPriority":14,"id":52385899,"name":"3 - 5"},{"status":"ACTIVE","sortPriority":15,"id":52385900,"name":"3 - 6"},{"status":"ACTIVE","sortPriority":16,"id":52385903,"name":"4 - 1"},{"status":"ACTIVE","sortPriority":17,"id":52385904,"name":"4 - 2"},{"status":"ACTIVE","sortPriority":18,"id":52385905,"name":"4 - 3"},{"status":"ACTIVE","sortPriority":19,"id":52385906,"name":"4 - 5"},{"status":"ACTIVE","sortPriority":20,"id":52385907,"name":"4 - 6"},{"status":"ACTIVE","sortPriority":21,"id":52385910,"name":"5 - 1"},{"status":"ACTIVE","sortPriority":22,"id":52385911,"name":"5 - 2"},{"status":"ACTIVE","sortPriority":23,"id":52385912,"name":"5 - 3"},{"status":"ACTIVE","sortPriority":24,"id":52385913,"name":"5 - 4"},{"status":"ACTIVE","sortPriority":25,"id":52385914,"name":"5 - 6"},{"status":"ACTIVE","sortPriority":26,"id":52385917,"name":"6 - 1"},{"status":"ACTIVE","sortPriority":27,"id":52385918,"name":"6 - 2"},{"status":"ACTIVE","sortPriority":28,"id":52385919,"name":"6 - 3"},{"status":"ACTIVE","sortPriority":29,"id":52385920,"name":"6 - 4"},{"status":"ACTIVE","sortPriority":30,"id":52385921,"name":"6 - 5"}],"regulators":["MR_INT"],"venue":"Perry Barr","countryCode":"GB","discountAllowed":true,"timezone":"Europe/London","openDate":"2024-06-27T13:29:00.000Z","version":5994794110,"name":"Forecast","eventName":"Perry Barr (F/C) 27th Jun"},"rc":[{"atb":[[1.01,23.41],[1.16,100]],"id":52385910},{"atb":[[1.16,100],[1.03,7.8]],"id":52385912},{"atb":[[1.16,100],[1.03,7.8]],"id":52385906},{"atb":[[1.16,100],[1.02,11.7]],"id":52385918},{"atb":[[1.16,100],[1.03,7.8]],"id":52385920},{"atb":[[1.16,100],[1.02,11.7]],"id":52385889},{"atb":[[1.01,23.41],[1.16,100]],"id":52385914},{"atb":[[1.16,100],[1.03,7.8]],"id":52385883},{"atb":[[1.01,23.41],[1.16,100]],"id":52385885},{"atb":[[1.16,100],[1.03,7.8]],"id":52385896},{"atb":[[1.01,23.41],[1.16,100]],"id":52385890},{"atb":[[1.16,100],[1.02,11.7]],"id":52385892},{"atb":[[1.16,100],[1.03,7.8]],"id":52385904},{"atb":[[1.01,23.41],[1.16,100]],"id":52385898},{"atb":[[1.16,100],[1.02,11.7]],"id":52385900},{"atb":[[1.16,100],[1.03,7.8]],"id":52385911},{"atb":[[1.16,100],[1.02,11.7]],"id":52385913},{"atb":[[1.01,23.41],[1.16,100]],"id":52385907},{"atb":[[1.16,100],[1.02,11.7]],"id":52385886},{"atb":[[1.16,100],[1.03,7.8]],"id":52385919},{"atb":[[1.16,100],[1.03,7.8]],"id":52385921},{"atb":[[1.16,100],[1.03,7.8]],"id":52385882},{"atb":[[1.01,23.41],[1.16,100]],"id":52385884},{"atb":[[1.01,23.41],[1.16,100]],"id":52385917},{"atb":[[1.01,23.41],[1.16,100]],"id":52385897},{"atb":[[1.16,100],[1.02,11.7]],"id":52385891},{"atb":[[1.01,23.41],[1.16,100]],"id":52385893},{"atb":[[1.01,23.41],[1.16,100]],"id":52385903},{"atb":[[1.16,100],[1.03,7.8]],"id":52385905},{"atb":[[1.16,100],[1.03,7.8]],"id":52385899}],"con":true,"img":true}]}
{"op":"mcm","clk":"11548861952","pt":1719477482591,"mc":[{"id":"1.230178170","marketDefinition":{"bspMarket":false,"turnInPlayEnabled":false,"persistenceEnabled":false,"marketBaseRate":5.0,"eventId":"33376048","eventTypeId":"4339","numberOfWinners":1,"bettingType":"ODDS","marketType":"FORECAST","marketTime":"2024-06-27T14:44:00.000Z","suspendTime":"2024-06-27T14:44:00.000Z","bspReconciled":false,"complete":true,"inPlay":false,"crossMatching":false,"runnersVoidable":false,"numberOfActiveRunners":30,"betDelay":0,"status":"OPEN","runners":[{"status":"ACTIVE","sortPriority":1,"id":52385882,"name":"1 - 2"},{"status":"ACTIVE","sortPriority":2,"id":52385883,"name":"1 - 3"},{"status":"ACTIVE","sortPriority":3,"id":52385884,"name":"1 - 4"},{"status":"ACTIVE","sortPriority":4,"id":52385885,"name":"1 - 5"},{"status":"ACTIVE","sortPriority":5,"id":52385886,"name":"1 - 6"},{"status":"ACTIVE","sortPriority":6,"id":52385889,"name":"2 - 1"},{"status":"ACTIVE","sortPriority":7,"id":52385890,"name":"2 - 3"},{"status":"ACTIVE","sortPriority":8,"id":52385891,"name":"2 - 4"},{"status":"ACTIVE","sortPriority":9,"id":52385892,"name":"2 - 5"},{"status":"ACTIVE","sortPriority":10,"id":52385893,"name":"2 - 6"},{"status":"ACTIVE","sortPriority":11,"id":52385896,"name":"3 - 1"},{"status":"ACTIVE","sortPriority":12,"id":52385897,"name":"3 - 2"},{"status":"ACTIVE","sortPriority":13,"id":52385898,"name":"3 - 4"},{"status":"ACTIVE","sortPriority":14,"id":52385899,"name":"3 - 5"},{"status":"ACTIVE","sortPriority":15,"id":52385900,"name":"3 - 6"},{"status":"ACTIVE","sortPriority":16,"id":52385903,"name":"4 - 1"},{"status":"ACTIVE","sortPriority":17,"id":52385904,"name":"4 - 2"},{"status":"ACTIVE","sortPriority":18,"id":52385905,"name":"4 - 3"},{"status":"ACTIVE","sortPriority":19,"id":52385906,"name":"4 - 5"},{"status":"ACTIVE","sortPriority":20,"id":52385907,"name":"4 - 6"},{"status":"ACTIVE","sortPriority":21,"id":52385910,"name":"5 - 1"},{"status":"ACTIVE","sortPriority":22,"id":52385911,"name":"5 - 2"},{"status":"ACTIVE","sortPriority":23,"id":52385912,"name":"5 - 3"},{"status":"ACTIVE","sortPriority":24,"id":52385913,"name":"5 - 4"},{"status":"ACTIVE","sortPriority":25,"id":52385914,"name":"5 - 6"},{"status":"ACTIVE","sortPriority":26,"id":52385917,"name":"6 - 1"},{"status":"ACTIVE","sortPriority":27,"id":52385918,"name":"6 - 2"},{"status":"ACTIVE","sortPriority":28,"id":52385919,"name":"6 - 3"},{"status":"ACTIVE","sortPriority":29,"id":52385920,"name":"6 - 4"},{"status":"ACTIVE","sortPriority":30,"id":52385921,"name":"6 - 5"}],"regulators":["MR_INT"],"venue":"Perry Barr","countryCode":"GB","discountAllowed":true,"timezone":"Europe/London","openDate":"2024-06-27T13:29:00.000Z","version":5994794110,"name":"Forecast","eventName":"Perry Barr (F/C) 27th Jun"},"rc":[{"atb":[[1.01,23.41],[1.16,100]],"id":52385910},{"atb":[[1.16,100],[1.03,7.8]],"id":52385912},{"atb":[[1.16,100],[1.03,7.8]],"id":52385906},{"atb":[[1.16,100],[1.02,11.7]],"id":52385918},{"atb":[[1.16,100],[1.03,7.8]],"id":52385920},{"atb":[[1.16,100],[1.02,11.7]],"id":52385889},{"atb":[[1.01,23.41],[1.16,100]],"id":52385914},{"atb":[[1.16,100],[1.03,7.8]],"id":52385883},{"atb":[[1.01,23.41],[1.16,100]],"id":52385885},{"atb":[[1.16,100],[1.03,7.8]],"id":52385896},{"atb":[[1.01,23.41],[1.16,100]],"id":52385890},{"atb":[[1.16,100],[1.02,11.7]],"id":52385892},{"atb":[[1.16,100],[1.03,7.8]],"id":52385904},{"atb":[[1.01,23.41],[1.16,100]],"id":52385898},{"atb":[[1.16,100],[1.02,11.7]],"id":52385900},{"atb":[[1.16,100],[1.03,7.8]],"id":52385911},{"atb":[[1.16,100],[1.02,11.7]],"id":52385913},{"atb":[[1.01,23.41],[1.16,100]],"id":52385907},{"atb":[[1.16,100],[1.02,11.7]],"id":52385886},{"atb":[[1.16,100],[1.03,7.8]],"id":52385919},{"atb":[[1.16,100],[1.03,7.8]],"id":52385921},{"atb":[[1.16,100],[1.03,7.8]],"id":52385882},{"atb":[[1.01,23.41],[1.16,100]],"id":52385884},{"atb":[[1.01,23.41],[1.16,100]],"id":52385917},{"atb":[[1.01,23.41],[1.16,100]],"id":52385897},{"atb":[[1.16,100],[1.02,11.7]],"id":52385891},{"atb":[[1.01,23.41],[1.16,100]],"id":52385893},{"atb":[[1.01,23.41],[1.16,100]],"id":52385903},{"atb":[[1.16,100],[1.03,7.8]],"id":52385905},{"atb":[[1.16,100],[1.03,7.8]],"id":52385899}],"con":true,"img":true}]}
{"op":"mcm","clk":"11549140216","pt":1719482882591,"mc":[{"id":"1.230178170","marketDefinition":{"bspMarket":false,"turnInPlayEnabled":false,"persistenceEnabled":false,"marketBaseRate":5.0,"eventId":"33376048","eventTypeId":"4339","numberOfWinners":1,"bettingType":"ODDS","marketType":"FORECAST","marketTime":"2024-06-27T14:44:00.000Z","suspendTime":"2024-06-27T14:44:00.000Z","bspReconciled":false,"complete":true,"inPlay":false,"crossMatching":false,"runnersVoidable":false,"numberOfActiveRunners":30,"betDelay":0,"status":"OPEN","runners":[{"status":"ACTIVE","sortPriority":1,"id":52385882,"name":"1 - 2"},{"status":"ACTIVE","sortPriority":2,"id":52385883,"name":"1 - 3"},{"status":"ACTIVE","sortPriority":3,"id":52385884,"name":"1 - 4"},{"status":"ACTIVE","sortPriority":4,"id":52385885,"name":"1 - 5"},{"status":"ACTIVE","sortPriority":5,"id":52385886,"name":"1 - 6"},{"status":"ACTIVE","sortPriority":6,"id":52385889,"name":"2 - 1"},{"status":"ACTIVE","sortPriority":7,"id":52385890,"name":"2 - 3"},{"status":"ACTIVE","sortPriority":8,"id":52385891,"name":"2 - 4"},{"status":"ACTIVE","sortPriority":9,"id":52385892,"name":"2 - 5"},{"status":"ACTIVE","sortPriority":10,"id":52385893,"name":"2 - 6"},{"status":"ACTIVE","sortPriority":11,"id":52385896,"name":"3 - 1"},{"status":"ACTIVE","sortPriority":12,"id":52385897,"name":"3 - 2"},{"status":"ACTIVE","sortPriority":13,"id":52385898,"name":"3 - 4"},{"status":"ACTIVE","sortPriority":14,"id":52385899,"name":"3 - 5"},{"status":"ACTIVE","sortPriority":15,"id":52385900,"name":"3 - 6"},{"status":"ACTIVE","sortPriority":16,"id":52385903,"name":"4 - 1"},{"status":"ACTIVE","sortPriority":17,"id":52385904,"name":"4 - 2"},{"status":"ACTIVE","sortPriority":18,"id":52385905,"name":"4 - 3"},{"status":"ACTIVE","sortPriority":19,"id":52385906,"name":"4 - 5"},{"status":"ACTIVE","sortPriority":20,"id":52385907,"name":"4 - 6"},{"status":"ACTIVE","sortPriority":21,"id":52385910,"name":"5 - 1"},{"status":"ACTIVE","sortPriority":22,"id":52385911,"name":"5 - 2"},{"status":"ACTIVE","sortPriority":23,"id":52385912,"name":"5 - 3"},{"status":"ACTIVE","sortPriority":24,"id":52385913,"name":"5 - 4"},{"status":"ACTIVE","sortPriority":25,"id":52385914,"name":"5 - 6"},{"status":"ACTIVE","sortPriority":26,"id":52385917,"name":"6 - 1"},{"status":"ACTIVE","sortPriority":27,"id":52385918,"name":"6 - 2"},{"status":"ACTIVE","sortPriority":28,"id":52385919,"name":"6 - 3"},{"status":"ACTIVE","sortPriority":29,"id":52385920,"name":"6 - 4"},{"status":"ACTIVE","sortPriority":30,"id":52385921,"name":"6 - 5"}],"regulators":["MR_INT"],"venue":"Perry Barr","countryCode":"GB","discountAllowed":true,"timezone":"Europe/London","openDate":"2024-06-27T13:29:00.000Z","version":5994794110,"name":"Forecast","eventName":"Perry Barr (F/C) 27th Jun"},"rc":[{"atb":[[1.01,23.41],[1.16,100]],"id":52385910},{"atb":[[1.16,100],[1.03,7.8]],"id":52385912},{"atb":[[1.16,100],[1.03,7.8]],"id":52385906},{"atb":[[1.16,100],[1.02,11.7]],"id":52385918},{"atb":[[1.16,100],[1.03,7.8]],"id":52385920},{"atb":[[1.16,100],[1.02,11.7]],"id":52385889},{"atb":[[1.01,23.41],[1.16,100]],"id":52385914},{"atb":[[1.16,100],[1.03,7.8]],"id":52385883},{"atb":[[1.01,23.41],[1.16,100]],"id":52385885},{"atb":[[1.16,100],[1.03,7.8]],"id":52385896},{"atb":[[1.01,23.41],[1.16,100]],"id":52385890},{"atb":[[1.16,100],[1.02,11.7]],"id":52385892},{"atb":[[1.16,100],[1.03,7.8]],"id":52385904},{"atb":[[1.01,23.41],[1.16,100]],"id":52385898},{"atb":[[1.16,100],[1.02,11.7]],"id":52385900},{"atb":[[1.16,100],[1.03,7.8]],"id":52385911},{"atb":[[1.16,100],[1.02,11.7]],"id":52385913},{"atb":[[1.01,23.41],[1.16,100]],"id":52385907},{"atb":[[1.16,100],[1.02,11.7]],"id":52385886},{"atb":[[1.16,100],[1.03,7.8]],"id":52385919},{"atb":[[1.16,100],[1.03,7.8]],"id":52385921},{"atb":[[1.16,100],[1.03,7.8]],"id":52385882},{"atb":[[1.01,23.41],[1.16,100]],"id":52385884},{"atb":[[1.01,23.41],[1.16,100]],"id":52385917},{"atb":[[1.01,23.41],[1.16,100]],"id":52385897},{"atb":[[1.16,100],[1.02,11.7]],"id":52385891},{"atb":[[1.01,23.41],[1.16,100]],"id":52385893},{"atb":[[1.01,23.41],[1.16,100]],"id":52385903},{"atb":[[1.16,100],[1.03,7.8]],"id":52385905},{"atb":[[1.16,100],[1.03,7.8]],"id":52385899}],"con":true,"img":true}]}
{"op":"mcm","clk":"11549606651","pt":1719488282608,"mc":[{"id":"1.230178170","marketDefinition":{"bspMarket":false,"turnInPlayEnabled":false,"persistenceEnabled":false,"marketBaseRate":5.0,"eventId":"33376048","eventTypeId":"4339","numberOfWinners":1,"bettingType":"ODDS","marketType":"FORECAST","marketTime":"2024-06-27T14:44:00.000Z","suspendTime":"2024-06-27T14:44:00.000Z","bspReconciled":false,"complete":true,"inPlay":false,"crossMatching":false,"runnersVoidable":false,"numberOfActiveRunners":30,"betDelay":0,"status":"OPEN","runners":[{"status":"ACTIVE","sortPriority":1,"id":52385882,"name":"1 - 2"},{"status":"ACTIVE","sortPriority":2,"id":52385883,"name":"1 - 3"},{"status":"ACTIVE","sortPriority":3,"id":52385884,"name":"1 - 4"},{"status":"ACTIVE","sortPriority":4,"id":52385885,"name":"1 - 5"},{"status":"ACTIVE","sortPriority":5,"id":52385886,"name":"1 - 6"},{"status":"ACTIVE","sortPriority":6,"id":52385889,"name":"2 - 1"},{"status":"ACTIVE","sortPriority":7,"id":52385890,"name":"2 - 3"},{"status":"ACTIVE","sortPriority":8,"id":52385891,"name":"2 - 4"},{"status":"ACTIVE","sortPriority":9,"id":52385892,"name":"2 - 5"},{"status":"ACTIVE","sortPriority":10,"id":52385893,"name":"2 - 6"},{"status":"ACTIVE","sortPriority":11,"id":52385896,"name":"3 - 1"},{"status":"ACTIVE","sortPriority":12,"id":52385897,"name":"3 - 2"},{"status":"ACTIVE","sortPriority":13,"id":52385898,"name":"3 - 4"},{"status":"ACTIVE","sortPriority":14,"id":52385899,"name":"3 - 5"},{"status":"ACTIVE","sortPriority":15,"id":52385900,"name":"3 - 6"},{"status":"ACTIVE","sortPriority":16,"id":52385903,"name":"4 - 1"},{"status":"ACTIVE","sortPriority":17,"id":52385904,"name":"4 - 2"},{"status":"ACTIVE","sortPriority":18,"id":52385905,"name":"4 - 3"},{"status":"ACTIVE","sortPriority":19,"id":52385906,"name":"4 - 5"},{"status":"ACTIVE","sortPriority":20,"id":52385907,"name":"4 - 6"},{"status":"ACTIVE","sortPriority":21,"id":52385910,"name":"5 - 1"},{"status":"ACTIVE","sortPriority":22,"id":52385911,"name":"5 - 2"},{"status":"ACTIVE","sortPriority":23,"id":52385912,"name":"5 - 3"},{"status":"ACTIVE","sortPriority":24,"id":52385913,"name":"5 - 4"},{"status":"ACTIVE","sortPriority":25,"id":52385914,"name":"5 - 6"},{"status":"ACTIVE","sortPriority":26,"id":52385917,"name":"6 - 1"},{"status":"ACTIVE","sortPriority":27,"id":52385918,"name":"6 - 2"},{"status":"ACTIVE","sortPriority":28,"id":52385919,"name":"6 - 3"},{"status":"ACTIVE","sortPriority":29,"id":52385920,"name":"6 - 4"},{"status":"ACTIVE","sortPriority":30,"id":52385921,"name":"6 - 5"}],"regulators":["MR_INT"],"venue":"Perry Barr","countryCode":"GB","discountAllowed":true,"timezone":"Europe/London","openDate":"2024-06-27T13:29:00.000Z","version":5994794110,"name":"Forecast","eventName":"Perry Barr (F/C) 27th Jun"},"rc":[{"atb":[[1.01,23.41],[1.16,100]],"id":52385910},{"atb":[[1.16,100],[1.03,7.8]],"id":52385912},{"atb":[[1.16,100],[1.03,7.8]],"id":52385906},{"atb":[[1.16,100],[1.02,11.7]],"id":52385918},{"atb":[[1.16,100],[1.03,7.8]],"id":52385920},{"atb":[[1.16,100],[1.02,11.7]],"id":52385889},{"atb":[[1.01,23.41],[1.16,100]],"id":52385914},{"atb":[[1.16,100],[1.03,7.8]],"id":52385883},{"atb":[[1.01,23.41],[1.16,100]],"id":52385885},{"atb":[[1.16,100],[1.03,7.8]],"id":52385896},{"atb":[[1.01,23.41],[1.16,100]],"id":52385890},{"atb":[[1.16,100],[1.02,11.7]],"id":52385892},{"atb":[[1.16,100],[1.03,7.8]],"id":52385904},{"atb":[[1.01,23.41],[1.16,100]],"id":52385898},{"atb":[[1.16,100],[1.02,11.7]],"id":52385900},{"atb":[[1.16,100],[1.03,7.8]],"id":52385911},{"atb":[[1.16,100],[1.02,11.7]],"id":52385913},{"atb":[[1.01,23.41],[1.16,100]],"id":52385907},{"atb":[[1.16,100],[1.02,11.7]],"id":52385886},{"atb":[[1.16,100],[1.03,7.8]],"id":52385919},{"atb":[[1.16,100],[1.03,7.8]],"id":52385921},{"atb":[[1.16,100],[1.03,7.8]],"id":52385882},{"atb":[[1.01,23.41],[1.16,100]],"id":52385884},{"atb":[[1.01,23.41],[1.16,100]],"id":52385917},{"atb":[[1.01,23.41],[1.16,100]],"id":52385897},{"atb":[[1.16,100],[1.02,11.7]],"id":52385891},{"atb":[[1.01,23.41],[1.16,100]],"id":52385893},{"atb":[[1.01,23.41],[1.16,100]],"id":52385903},{"atb":[[1.16,100],[1.03,7.8]],"id":52385905},{"atb":[[1.16,100],[1.03,7.8]],"id":52385899}],"con":true,"img":true}]}
{"op":"mcm","clk":"11549635862","pt":1719488678888,"mc":[{"id":"1.230178170","rc":[{"atb":[[1.01,329.53]],"id":52385910},{"atb":[[1.01,306.12],[1.03,7.8]],"id":52385912},{"atb":[[1.01,306.12],[1.03,7.8]],"id":52385906},{"atb":[[1.02,11.7]],"id":52385918},{"atb":[[1.03,7.8]],"id":52385920},{"atb":[[1.01,306.12],[1.02,11.7]],"id":52385889},{"atb":[[1.01,23.41]],"id":52385914},{"atb":[[1.01,306.12],[1.03,7.8]],"id":52385883},{"atb":[[1.01,329.53]],"id":52385885},{"atb":[[1.01,306.12],[1.03,7.8]],"id":52385896},{"atb":[[1.01,329.53]],"id":52385890},{"atb":[[1.01,306.12],[1.02,11.7]],"id":52385892},{"atb":[[1.03,7.8]],"id":52385904},{"atb":[[1.01,329.53]],"id":52385898},{"atb":[[1.01,306.12],[1.02,11.7]],"id":52385900},{"atb":[[1.01,306.12],[1.03,7.8]],"id":52385911},{"atb":[[1.01,306.12],[1.02,11.7]],"id":52385913},{"atb":[[1.01,23.41]],"id":52385907},{"atb":[[1.01,306.12],[1.02,11.7]],"id":52385886},{"atb":[[1.03,7.8]],"id":52385919},{"atb":[[1.03,7.8]],"id":52385921},{"atb":[[1.01,306.12],[1.03,7.8]],"id":52385882},{"atb":[[1.01,329.53]],"id":52385884},{"atb":[[1.01,329.53]],"id":52385917},{"atb":[[1.01,23.41]],"id":52385897},{"atb":[[1.01,306.12],[1.02,11.7]],"id":52385891},{"atb":[[1.01,329.53]],"id":52385893},{"atb":[[1.01,329.53]],"id":52385903},{"atb":[[1.01,306.12],[1.03,7.8]],"id":52385905},{"atb":[[1.03,7.8]],"id":52385899}],"con":true,"img":false}]}
{"op":"mcm","clk":"11549635871","pt":1719488678942,"mc":[{"id":"1.230178170","rc":[{"atb":[[1.01,329.53]],"id":52385914},{"atb":[[1.01,306.12]],"id":52385904},{"atb":[[1.01,329.53]],"id":52385907},{"atb":[[1.01,329.53]],"id":52385897},{"atb":[[1.01,306.12]],"id":52385899}],"con":true,"img":false}]}
{"op":"mcm","clk":"11549635924","pt":1719488679565,"mc":[{"id":"1.230178170","rc":[{"atb":[[1.01,306.12]],"id":52385918},{"atb":[[1.01,306.12]],"id":52385920},{"atb":[[1.17,120.05]],"id":52385889},{"atb":[[1.17,120.05]],"id":52385883},{"atb":[[1.17,120.05]],"id":52385885},{"atb":[[1.17,120.05]],"id":52385896},{"atb":[[1.17,120.05]],"id":52385890},{"atb":[[1.17,120.05]],"id":52385892},{"atb":[[1.17,120.05]],"id":52385904},{"atb":[[1.17,120.05]],"id":52385898},{"atb":[[1.17,120.05]],"id":52385900},{"atb":[[1.17,120.05]],"id":52385886},{"atb":[[1.01,306.12]],"id":52385919},{"atb":[[1.01,306.12]],"id":52385921},{"atb":[[1.17,120.05]],"id":52385882},{"atb":[[1.17,120.05]],"id":52385884},{"atb":[[1.17,120.05]],"id":52385897},{"atb":[[1.17,120.05]],"id":52385891},{"atb":[[1.17,120.05]],"id":52385893},{"atb":[[1.17,120.05]],"id":52385903},{"atb":[[1.17,120.05]],"id":52385899}],"con":true,"img":false}]}
{"op":"mcm","clk":"11549635933","pt":1719488679666,"mc":[{"id":"1.230178170","rc":[{"atb":[[1.17,120.05]],"id":52385910},{"atb":[[1.17,120.05]],"id":52385906},{"atb":[[1.17,120.05]],"id":52385911},{"atb":[[1.17,120.05]],"id":52385907},{"atb":[[1.17,120.05]],"id":52385905}],"con":true,"img":false}]}
{"op":"mcm","clk":"11549635995","pt":1719488680284,"mc":[{"id":"1.230178170","rc":[{"atb":[[1.17,120.05]],"id":52385912},{"atb":[[1.17,120.05]],"id":52385918},{"atb":[[1.17,120.05]],"id":52385920},{"atb":[[1.17,120.05]],"id":52385913},{"atb":[[1.17,120.05]],"id":52385919},{"atb":[[1.17,120.05]],"id":52385921},{"atb":[[1.17,120.05]],"id":52385917}],"con":true,"img":false}]}
{"op":"mcm","clk":"11549635999","pt":1719488680385,"mc":[{"id":"1.230178170","rc":[{"atb":[[1.17,120.05]],"id":52385914}],"con":true,"img":false}]}
{"op":"mcm","clk":"11549970606","pt":1719493210061,"mc":[{"id":"1.230178170","rc":[{"atb":[[1.01,329.56],[1.16,0]],"id":52385910},{"atb":[[1.16,0],[1.03,7.81]],"id":52385912},{"atb":[[1.16,0],[1.03,7.81]],"id":52385906},{"atb":[[1.16,0],[1.02,11.72]],"id":52385918},{"atb":[[1.16,0],[1.03,7.81]],"id":52385920},{"atb":[[1.16,0],[1.02,11.72]],"id":52385889},{"atb":[[1.01,329.56],[1.16,0]],"id":52385914},{"atb":[[1.16,0],[1.03,7.81]],"id":52385883},{"atb":[[1.01,329.56],[1.16,0]],"id":52385885},{"atb":[[1.16,0],[1.03,7.81]],"id":52385896},{"atb":[[1.01,329.56],[1.16,0]],"id":52385890},{"atb":[[1.16,0],[1.02,11.72]],"id":52385892},{"atb":[[1.16,0],[1.03,7.81]],"id":52385904},{"atb":[[1.01,329.56],[1.16,0]],"id":52385898},{"atb":[[1.16,0],[1.02,11.72]],"id":52385900},{"atb":[[1.16,0],[1.03,7.81]],"id":52385911},{"atb":[[1.16,0],[1.02,11.72]],"id":52385913},{"atb":[[1.01,329.56],[1.16,0]],"id":52385907},{"atb":[[1.16,0],[1.02,11.72]],"id":52385886},{"atb":[[1.16,0],[1.03,7.81]],"id":52385919},{"atb":[[1.16,0],[1.03,7.81]],"id":52385921},{"atb":[[1.16,0],[1.03,7.81]],"id":52385882},{"atb":[[1.01,329.56],[1.16,0]],"id":52385884},{"atb":[[1.01,329.56],[1.16,0]],"id":52385917},{"atb":[[1.01,329.56],[1.16,0]],"id":52385897},{"atb":[[1.16,0],[1.02,11.72]],"id":52385891},{"atb":[[1.01,329.56],[1.16,0]],"id":52385893},{"atb":[[1.01,329.56],[1.16,0]],"id":52385903},{"atb":[[1.16,0],[1.03,7.81]],"id":52385905},{"atb":[[1.16,0],[1.03,7.81]],"id":52385899}],"con":true,"img":false}]}
{"op":"mcm","clk":"11549975467","pt":1719493270027,"mc":[{"id":"1.230178170","rc":[{"atb":[[1.18,150]],"id":52385910},{"atb":[[1.18,150]],"id":52385912},{"atb":[[1.18,150]],"id":52385906},{"atb":[[1.18,150]],"id":52385918},{"atb":[[1.18,150]],"id":52385920},{"atb":[[1.18,150]],"id":52385889},{"atb":[[1.18,150]],"id":52385914},{"atb":[[1.18,150]],"id":52385883},{"atb":[[1.18,150]],"id":52385885},{"atb":[[1.18,150]],"id":52385896},{"atb":[[1.18,150]],"id":52385890},{"atb":[[1.18,150]],"id":52385892},{"atb":[[1.18,150]],"id":52385904},{"atb":[[1.18,150]],"id":52385898},{"atb":[[1.18,150]],"id":52385900},{"atb":[[1.18,150]],"id":52385911},{"atb":[[1.18,150]],"id":52385913},{"atb":[[1.18,150]],"id":52385907},{"atb":[[1.18,150]],"id":52385886},{"atb":[[1.18,150]],"id":52385919},{"atb":[[1.18,150]],"id":52385921},{"atb":[[1.18,150]],"id":52385882},{"atb":[[1.18,150]],"id":52385884},{"atb":[[1.18,150]],"id":52385917},{"atb":[[1.18,150]],"id":52385897},{"atb":[[1.18,150]],"id":52385891},{"atb":[[1.18,150]],"id":52385893},{"atb":[[1.18,150]],"id":52385903},{"atb":[[1.18,150]],"id":52385905},{"atb":[[1.18,150]],"id":52385899}],"con":true,"img":false}]}
{"op":"mcm","clk":"11549991855","pt":1719493460971,"mc":[{"id":"1.230178170","rc":[{"atb":[[1.17,0]],"id":52385889}],"con":true,"img":false}]}
{"op":"mcm","clk":"11550042919","pt":1719493901151,"mc":[{"id":"1.230178170","rc":[{"atb":[[1.17,0]],"id":52385893}],"con":true,"img":false}]}
{"op":"mcm","clk":"11550066174","pt":1719494131224,"mc":[{"id":"1.230178170","rc":[{"atb":[[1.17,0]],"id":52385890}],"con":true,"img":false}]}
{"op":"mcm","clk":"11550090704","pt":1719494361178,"mc":[{"id":"1.230178170","rc":[{"atb":[[1.17,0]],"id":52385903}],"con":true,"img":false}]}
{"op":"mcm","clk":"11550116619","pt":1719494591356,"mc":[{"id":"1.230178170","rc":[{"atb":[[1.17,0]],"id":52385891}],"con":true,"img":false}]}
{"op":"mcm","clk":"11550140851","pt":1719494821458,"mc":[{"id":"1.230178170","rc":[{"atb":[[1.17,0]],"id":52385885}],"con":true,"img":false}]}
{"op":"mcm","clk":"11550161216","pt":1719495051550,"mc":[{"id":"1.230178170","rc":[{"atb":[[1.17,0]],"id":52385900}],"con":true,"img":false}]}
{"op":"mcm","clk":"11550179003","pt":1719495281654,"mc":[{"id":"1.230178170","rc":[{"atb":[[1.17,0]],"id":52385896}],"con":true,"img":false}]}
{"op":"mcm","clk":"11550198005","pt":1719495511849,"mc":[{"id":"1.230178170","rc":[{"atb":[[1.17,0]],"id":52385904}],"con":true,"img":false}]}
{"op":"mcm","clk":"11550219176","pt":1719495751864,"mc":[{"id":"1.230178170","rc":[{"atb":[[1.17,0]],"id":52385899}],"con":true,"img":false}]}
{"op":"mcm","clk":"11550240825","pt":1719495992050,"mc":[{"id":"1.230178170","rc":[{"atb":[[1.17,0]],"id":52385884}],"con":true,"img":false}]}
{"op":"mcm","clk":"11550259958","pt":1719496232200,"mc":[{"id":"1.230178170","rc":[{"atb":[[1.17,0]],"id":52385883}],"con":true,"img":false}]}
{"op":"mcm","clk":"11550274287","pt":1719496462318,"mc":[{"id":"1.230178170","rc":[{"atb":[[1.17,0]],"id":52385892}],"con":true,"img":false}]}
{"op":"mcm","clk":"11550280842","pt":1719496567345,"mc":[{"id":"1.230178170","rc":[{"atb":[[1.2,10]],"id":52385882}],"con":true,"img":false}]}
{"op":"mcm","clk":"11550281095","pt":1719496570540,"mc":[{"id":"1.230178170","rc":[{"atb":[[3.5,50]],"id":52385882}],"con":true,"img":false}]}
{"op":"mcm","clk":"11550281224","pt":1719496572517,"mc":[{"id":"1.230178170","marketDefinition":{"bspMarket":false,"turnInPlayEnabled":false,"persistenceEnabled":false,"marketBaseRate":5.0,"eventId":"33376048","eventTypeId":"4339","numberOfWinners":1,"bettingType":"ODDS","marketType":"FORECAST","marketTime":"2024-06-27T14:44:00.000Z","suspendTime":"2024-06-27T14:44:00.000Z","bspReconciled":false,"complete":true,"inPlay":false,"crossMatching":true,"runnersVoidable":false,"numberOfActiveRunners":30,"betDelay":0,"status":"OPEN","runners":[{"status":"ACTIVE","sortPriority":1,"id":52385882,"name":"1 - 2"},{"status":"ACTIVE","sortPriority":2,"id":52385883,"name":"1 - 3"},{"status":"ACTIVE","sortPriority":3,"id":52385884,"name":"1 - 4"},{"status":"ACTIVE","sortPriority":4,"id":52385885,"name":"1 - 5"},{"status":"ACTIVE","sortPriority":5,"id":52385886,"name":"1 - 6"},{"status":"ACTIVE","sortPriority":6,"id":52385889,"name":"2 - 1"},{"status":"ACTIVE","sortPriority":7,"id":52385890,"name":"2 - 3"},{"status":"ACTIVE","sortPriority":8,"id":52385891,"name":"2 - 4"},{"status":"ACTIVE","sortPriority":9,"id":52385892,"name":"2 - 5"},{"status":"ACTIVE","sortPriority":10,"id":52385893,"name":"2 - 6"},{"status":"ACTIVE","sortPriority":11,"id":52385896,"name":"3 - 1"},{"status":"ACTIVE","sortPriority":12,"id":52385897,"name":"3 - 2"},{"status":"ACTIVE","sortPriority":13,"id":52385898,"name":"3 - 4"},{"status":"ACTIVE","sortPriority":14,"id":52385899,"name":"3 - 5"},{"status":"ACTIVE","sortPriority":15,"id":52385900,"name":"3 - 6"},{"status":"ACTIVE","sortPriority":16,"id":52385903,"name":"4 - 1"},{"status":"ACTIVE","sortPriority":17,"id":52385904,"name":"4 - 2"},{"status":"ACTIVE","sortPriority":18,"id":52385905,"name":"4 - 3"},{"status":"ACTIVE","sortPriority":19,"id":52385906,"name":"4 - 5"},{"status":"ACTIVE","sortPriority":20,"id":52385907,"name":"4 - 6"},{"status":"ACTIVE","sortPriority":21,"id":52385910,"name":"5 - 1"},{"status":"ACTIVE","sortPriority":22,"id":52385911,"name":"5 - 2"},{"status":"ACTIVE","sortPriority":23,"id":52385912,"name":"5 - 3"},{"status":"ACTIVE","sortPriority":24,"id":52385913,"name":"5 - 4"},{"status":"ACTIVE","sortPriority":25,"id":52385914,"name":"5 - 6"},{"status":"ACTIVE","sortPriority":26,"id":52385917,"name":"6 - 1"},{"status":"ACTIVE","sortPriority":27,"id":52385918,"name":"6 - 2"},{"status":"ACTIVE","sortPriority":28,"id":52385919,"name":"6 - 3"},{"status":"ACTIVE","sortPriority":29,"id":52385920,"name":"6 - 4"},{"status":"ACTIVE","sortPriority":30,"id":52385921,"name":"6 - 5"}],"regulators":["MR_INT"],"venue":"Perry Barr","countryCode":"GB","discountAllowed":true,"timezone":"Europe/London","openDate":"2024-06-27T13:29:00.000Z","version":5994794110,"name":"Forecast","eventName":"Perry Barr (F/C) 27th Jun"},"rc":[],"con":true,"img":false}]}
{"op":"mcm","clk":"11550281471","pt":1719496575839,"mc":[{"id":"1.230178170","rc":[{"atb":[[3.5,0]],"id":52385882}],"con":true,"img":false}]}
{"op":"mcm","clk":"11550281710","pt":1719496579244,"mc":[{"id":"1.230178170","rc":[{"atb":[[1.2,0]],"id":52385882},{"trd":[[1.2,20]],"ltp":1.2,"tv":20.0,"id":52385882}],"con":true,"img":false}]}
{"op":"mcm","clk":"11550282379","pt":1719496589055,"mc":[{"id":"1.230178170","rc":[{"atb":[[1.2,11.9]],"id":52385889}],"con":true,"img":false}]}
{"op":"mcm","clk":"11550282392","pt":1719496589261,"mc":[{"id":"1.230178170","rc":[{"atb":[[3.5,50]],"id":52385889}],"con":true,"img":false}]}
{"op":"mcm","clk":"11550282409","pt":1719496589570,"mc":[{"id":"1.230178170","rc":[{"atb":[[1.03,1]],"id":52385910},{"atb":[[1.03,8.81]],"id":52385912},{"atb":[[1.03,8.81]],"id":52385906},{"atb":[[1.03,1]],"id":52385918},{"atb":[[1.03,8.81]],"id":52385920},{"atb":[[1.03,1]],"id":52385889},{"atb":[[1.03,1]],"id":52385914},{"atb":[[1.03,8.81]],"id":52385883},{"atb":[[1.03,1]],"id":52385885},{"atb":[[1.03,8.81]],"id":52385896},{"atb":[[1.03,1]],"id":52385890},{"atb":[[1.03,1]],"id":52385892},{"atb":[[1.03,8.81]],"id":52385904},{"atb":[[1.03,1]],"id":52385898},{"atb":[[1.03,1]],"id":52385900},{"atb":[[1.03,8.81]],"id":52385911},{"atb":[[1.03,1]],"id":52385913},{"atb":[[1.03,1]],"id":52385907},{"atb":[[1.03,1]],"id":52385886},{"atb":[[1.03,8.81]],"id":52385919},{"atb":[[1.03,8.81]],"id":52385921},{"atb":[[1.03,8.81]],"id":52385882},{"atb":[[1.03,1]],"id":52385884},{"atb":[[1.03,1]],"id":52385917},{"atb":[[1.03,1]],"id":52385897},{"atb":[[1.03,1]],"id":52385891},{"atb":[[1.03,1]],"id":52385893},{"atb":[[1.03,1]],"id":52385903},{"atb":[[1.03,8.81]],"id":52385905},{"atb":[[1.03,8.81]],"id":52385899}],"con":true,"img":false}]}
{"op":"mcm","clk":"11550282418","pt":1719496589677,"mc":[{"id":"1.230178170","rc":[{"atb":[[1.03,0.9]],"id":52385910},{"atb":[[1.03,8.71]],"id":52385912},{"atb":[[1.03,8.71]],"id":52385906},{"atb":[[1.03,0.9]],"id":52385918},{"atb":[[1.03,8.71]],"id":52385920},{"atb":[[1.03,0.9]],"id":52385889},{"atb":[[1.03,0.9]],"id":52385914},{"atb":[[1.03,8.71]],"id":52385883},{"atb":[[1.03,0.9]],"id":52385885},{"atb":[[1.03,8.71]],"id":52385896},{"atb":[[1.03,0.9]],"id":52385890},{"atb":[[1.03,0.9]],"id":52385892},{"atb":[[1.03,8.71]],"id":52385904},{"atb":[[1.03,0.9]],"id":52385898},{"atb":[[1.03,0.9]],"id":52385900},{"atb":[[1.03,8.71]],"id":52385911},{"atb":[[1.03,0.9]],"id":52385913},{"atb":[[1.03,0.9]],"id":52385907},{"atb":[[1.03,0.9]],"id":52385886},{"atb":[[1.03,8.71]],"id":52385919},{"atb":[[1.03,8.71]],"id":52385921},{"atb":[[1.03,8.71]],"id":52385882},{"atb":[[1.03,0.9]],"id":52385884},{"atb":[[1.03,0.9]],"id":52385917},{"atb":[[1.03,0.9]],"id":52385897},{"atb":[[1.03,0.9]],"id":52385891},{"atb":[[1.03,0.9]],"id":52385893},{"atb":[[1.03,0.9]],"id":52385903},{"atb":[[1.03,8.71]],"id":52385905},{"atb":[[1.03,8.71]],"id":52385899}],"con":true,"img":false}]}
{"op":"mcm","clk":"11550282434","pt":1719496589833,"mc":[{"id":"1.230178170","rc":[{"atb":[[1.03,0]],"id":52385910},{"atb":[[1.03,7.81]],"id":52385912},{"atb":[[1.03,7.81]],"id":52385906},{"atb":[[1.03,0]],"id":52385918},{"atb":[[1.03,7.81]],"id":52385920},{"atb":[[1.03,0]],"id":52385889},{"atb":[[1.03,0]],"id":52385914},{"atb":[[1.03,7.81]],"id":52385883},{"atb":[[1.03,0]],"id":52385885},{"atb":[[1.03,7.81]],"id":52385896},{"atb":[[1.03,0]],"id":52385890},{"atb":[[1.03,0]],"id":52385892},{"atb":[[1.03,7.81]],"id":52385904},{"atb":[[1.03,0]],"id":52385898},{"atb":[[1.03,0]],"id":52385900},{"atb":[[1.03,7.81]],"id":52385911},{"atb":[[1.03,0]],"id":52385913},{"atb":[[1.03,0]],"id":52385907},{"atb":[[1.03,0]],"id":52385886},{"atb":[[1.03,7.81]],"id":52385919},{"atb":[[1.03,7.81]],"id":52385921},{"atb":[[1.03,7.81]],"id":52385882},{"atb":[[1.03,0]],"id":52385884},{"atb":[[1.03,0]],"id":52385917},{"atb":[[1.03,0]],"id":52385897},{"atb":[[1.03,0]],"id":52385891},{"atb":[[1.03,0]],"id":52385893},{"atb":[[1.03,0]],"id":52385903},{"atb":[[1.03,7.81]],"id":52385905},{"atb":[[1.03,7.81]],"id":52385899}],"con":true,"img":false}]}
{"op":"mcm","clk":"11550282440","pt":1719496589939,"mc":[{"id":"1.230178170","rc":[{"atb":[[3.05,0.9]],"id":52385910},{"atb":[[3.05,0.9]],"id":52385912},{"atb":[[3.05,0.9]],"id":52385906},{"atb":[[3.05,0.9]],"id":52385918},{"atb":[[3.05,0.9]],"id":52385920},{"atb":[[3.05,0.9]],"id":52385889},{"atb":[[3.05,0.9]],"id":52385914},{"atb":[[3.05,0.9]],"id":52385883},{"atb":[[3.05,0.9]],"id":52385885},{"atb":[[3.05,0.9]],"id":52385896},{"atb":[[3.05,0.9]],"id":52385890},{"atb":[[3.05,0.9]],"id":52385892},{"atb":[[3.05,0.9]],"id":52385904},{"atb":[[3.05,0.9]],"id":52385898},{"atb":[[3.05,0.9]],"id":52385900},{"atb":[[3.05,0.9]],"id":52385911},{"atb":[[3.05,0.9]],"id":52385913},{"atb":[[3.05,0.9]],"id":52385907},{"atb":[[3.05,0.9]],"id":52385886},{"atb":[[3.05,0.9]],"id":52385919},{"atb":[[3.05,0.9]],"id":52385921},{"atb":[[3.05,0.9]],"id":52385882},{"atb":[[3.05,0.9]],"id":52385884},{"atb":[[3.05,0.9]],"id":52385917},{"atb":[[3.05,0.9]],"id":52385897},{"atb":[[3.05,0.9]],"id":52385891},{"atb":[[3.05,0.9]],"id":52385893},{"atb":[[3.05,0.9]],"id":52385903},{"atb":[[3.05,0.9]],"id":52385905},{"atb":[[3.05,0.9]],"id":52385899}],"con":true,"img":false}]}
{"op":"mcm","clk":"11550282728","pt":1719496594534,"mc":[{"id":"1.230178170","rc":[{"atb":[[3.5,0]],"id":52385889}],"con":true,"img":false}]}
{"op":"mcm","clk":"11550283021","pt":1719496598554,"mc":[{"id":"1.230178170","rc":[{"atb":[[1.21,10]],"id":52385889}],"con":true,"img":false}]}
{"op":"mcm","clk":"11550283037","pt":1719496598762,"mc":[{"id":"1.230178170","rc":[{"atb":[[1.2,10.9],[1.21,0],[3.05,0]],"id":52385889},{"trd":[[1.2,2],[1.21,20],[3.05,1.8]],"ltp":1.2,"tv":23.8,"id":52385889}],"con":true,"img":false}]}
{"op":"mcm","clk":"11550283560","pt":1719496605641,"mc":[{"id":"1.230178170","rc":[{"atb":[[1.2,0]],"id":52385889}],"con":true,"img":false}]}
{"op":"mcm","clk":"11550284948","pt":1719496622401,"mc":[{"id":"1.230178170","rc":[{"atb":[[3.05,0]],"id":52385910},{"atb":[[3.05,0]],"id":52385912},{"atb":[[3.05,0]],"id":52385906},{"atb":[[3.05,0]],"id":52385918},{"atb":[[3.05,0]],"id":52385920},{"atb":[[3.05,0]],"id":52385914},{"atb":[[3.05,0]],"id":52385883},{"atb":[[3.05,0]],"id":52385885},{"atb":[[3.05,0]],"id":52385896},{"atb":[[3.05,0]],"id":52385890},{"atb":[[3.05,0]],"id":52385892},{"atb":[[3.05,0]],"id":52385904},{"atb":[[3.05,0]],"id":52385898},{"atb":[[3.05,0]],"id":52385900},{"atb":[[3.05,0]],"id":52385911},{"atb":[[3.05,0]],"id":52385913},{"atb":[[3.05,0]],"id":52385907},{"atb":[[3.05,0]],"id":52385886},{"atb":[[3.05,0]],"id":52385919},{"atb":[[3.05,0]],"id":52385921},{"atb":[[3.05,0]],"id":52385882},{"atb":[[3.05,0]],"id":52385884},{"atb":[[3.05,0]],"id":52385917},{"atb":[[3.05,0]],"id":52385897},{"atb":[[3.05,0]],"id":52385891},{"atb":[[3.05,0]],"id":52385893},{"atb":[[3.05,0]],"id":52385903},{"atb":[[3.05,0]],"id":52385905},{"atb":[[3.05,0]],"id":52385899}],"con":true,"img":false}]}
{"op":"mcm","clk":"11550285170","pt":1719496624681,"mc":[{"id":"1.230178170","rc":[{"atb":[[1.03,1]],"id":52385910},{"atb":[[1.03,8.81]],"id":52385912},{"atb":[[1.03,8.81]],"id":52385906},{"atb":[[1.03,1]],"id":52385918},{"atb":[[1.03,8.81]],"id":52385920},{"atb":[[1.03,1]],"id":52385889},{"atb":[[1.03,1]],"id":52385914},{"atb":[[1.03,8.81]],"id":52385883},{"atb":[[1.03,1]],"id":52385885},{"atb":[[1.03,8.81]],"id":52385896},{"atb":[[1.03,1]],"id":52385890},{"atb":[[1.03,1]],"id":52385892},{"atb":[[1.03,8.81]],"id":52385904},{"atb":[[1.03,1]],"id":52385898},{"atb":[[1.03,1]],"id":52385900},{"atb":[[1.03,8.81]],"id":52385911},{"atb":[[1.03,1]],"id":52385913},{"atb":[[1.03,1]],"id":52385907},{"atb":[[1.03,1]],"id":52385886},{"atb":[[1.03,8.81]],"id":52385919},{"atb":[[1.03,8.81]],"id":52385921},{"atb":[[1.03,8.81]],"id":52385882},{"atb":[[1.03,1]],"id":52385884},{"atb":[[1.03,1]],"id":52385917},{"atb":[[1.03,1]],"id":52385897},{"atb":[[1.03,1]],"id":52385891},{"atb":[[1.03,1]],"id":52385893},{"atb":[[1.03,1]],"id":52385903},{"atb":[[1.03,8.81]],"id":52385905},{"atb":[[1.03,8.81]],"id":52385899}],"con":true,"img":false}]}
{"op":"mcm","clk":"11550285192","pt":1719496624993,"mc":[{"id":"1.230178170","rc":[{"atb":[[1.03,0.9]],"id":52385910},{"atb":[[1.03,8.71]],"id":52385912},{"atb":[[1.03,8.71]],"id":52385906},{"atb":[[1.03,0.9]],"id":52385918},{"atb":[[1.03,8.71]],"id":52385920},{"atb":[[1.03,0.9]],"id":52385889},{"atb":[[1.03,0.9]],"id":52385914},{"atb":[[1.03,8.71]],"id":52385883},{"atb":[[1.03,0.9]],"id":52385885},{"atb":[[1.03,8.71]],"id":52385896},{"atb":[[1.03,0.9]],"id":52385890},{"atb":[[1.03,0.9]],"id":52385892},{"atb":[[1.03,8.71]],"id":52385904},{"atb":[[1.03,0.9]],"id":52385898},{"atb":[[1.03,0.9]],"id":52385900},{"atb":[[1.03,8.71]],"id":52385911},{"atb":[[1.03,0.9]],"id":52385913},{"atb":[[1.03,0.9]],"id":52385907},{"atb":[[1.03,0.9]],"id":52385886},{"atb":[[1.03,8.71]],"id":52385919},{"atb":[[1.03,8.71]],"id":52385921},{"atb":[[1.03,8.71]],"id":52385882},{"atb":[[1.03,0.9]],"id":52385884},{"atb":[[1.03,0.9]],"id":52385917},{"atb":[[1.03,0.9]],"id":52385897},{"atb":[[1.03,0.9]],"id":52385891},{"atb":[[1.03,0.9]],"id":52385893},{"atb":[[1.03,0.9]],"id":52385903},{"atb":[[1.03,8.71]],"id":52385905},{"atb":[[1.03,8.71]],"id":52385899}],"con":true,"img":false}]}
{"op":"mcm","clk":"11550285208","pt":1719496625300,"mc":[{"id":"1.230178170","rc":[{"atb":[[1.03,0]],"id":52385910},{"atb":[[1.03,7.81]],"id":52385912},{"atb":[[1.03,7.81]],"id":52385906},{"atb":[[1.03,0]],"id":52385918},{"atb":[[1.03,7.81]],"id":52385920},{"atb":[[1.03,0]],"id":52385889},{"atb":[[1.03,0]],"id":52385914},{"atb":[[1.03,7.81]],"id":52385883},{"atb":[[1.03,0]],"id":52385885},{"atb":[[1.03,7.81]],"id":52385896},{"atb":[[1.03,0]],"id":52385890},{"atb":[[1.03,0]],"id":52385892},{"atb":[[1.03,7.81]],"id":52385904},{"atb":[[1.03,0]],"id":52385898},{"atb":[[1.03,0]],"id":52385900},{"atb":[[1.03,7.81]],"id":52385911},{"atb":[[1.03,0]],"id":52385913},{"atb":[[1.03,0]],"id":52385907},{"atb":[[1.03,0]],"id":52385886},{"atb":[[1.03,7.81]],"id":52385919},{"atb":[[1.03,7.81]],"id":52385921},{"atb":[[1.03,7.81]],"id":52385882},{"atb":[[1.03,0]],"id":52385884},{"atb":[[1.03,0]],"id":52385917},{"atb":[[1.03,0]],"id":52385897},{"atb":[[1.03,0]],"id":52385891},{"atb":[[1.03,0]],"id":52385893},{"atb":[[1.03,0]],"id":52385903},{"atb":[[1.03,7.81]],"id":52385905},{"atb":[[1.03,7.81]],"id":52385899}],"con":true,"img":false}]}
{"op":"mcm","clk":"11550285217","pt":1719496625403,"mc":[{"id":"1.230178170","rc":[{"atb":[[3.05,0.9]],"id":52385910},{"atb":[[3.05,0.9]],"id":52385912},{"atb":[[3.05,0.9]],"id":52385906},{"atb":[[3.05,0.9]],"id":52385918},{"atb":[[3.05,0.9]],"id":52385920},{"atb":[[3.05,0.9]],"id":52385889},{"atb":[[3.05,0.9]],"id":52385914},{"atb":[[3.05,0.9]],"id":52385883},{"atb":[[3.05,0.9]],"id":52385885},{"atb":[[3.05,0.9]],"id":52385896},{"atb":[[3.05,0.9]],"id":52385890},{"atb":[[3.05,0.9]],"id":52385892},{"atb":[[3.05,0.9]],"id":52385904},{"atb":[[3.05,0.9]],"id":52385898},{"atb":[[3.05,0.9]],"id":52385900},{"atb":[[3.05,0.9]],"id":52385911},{"atb":[[3.05,0.9]],"id":52385913},{"atb":[[3.05,0.9]],"id":52385907},{"atb":[[3.05,0.9]],"id":52385886},{"atb":[[3.05,0.9]],"id":52385919},{"atb":[[3.05,0.9]],"id":52385921},{"atb":[[3.05,0.9]],"id":52385882},{"atb":[[3.05,0.9]],"id":52385884},{"atb":[[3.05,0.9]],"id":52385917},{"atb":[[3.05,0.9]],"id":52385897},{"atb":[[3.05,0.9]],"id":52385891},{"atb":[[3.05,0.9]],"id":52385893},{"atb":[[3.05,0.9]],"id":52385903},{"atb":[[3.05,0.9]],"id":52385905},{"atb":[[3.05,0.9]],"id":52385899}],"con":true,"img":false}]}
{"op":"mcm","clk":"11550292655","pt":1719496712316,"mc":[{"id":"1.230178170","rc":[{"atb":[[1.17,0]],"id":52385886}],"con":true,"img":false}]}
{"op":"mcm","clk":"11550315252","pt":1719496962588,"mc":[{"id":"1.230178170","rc":[{"atb":[[1.01,329.55]],"id":52385910},{"atb":[[1.03,7.81]],"id":52385912},{"atb":[[1.03,7.81]],"id":52385906},{"atb":[[1.02,11.71]],"id":52385918},{"atb":[[1.03,7.81]],"id":52385920},{"atb":[[1.02,11.71]],"id":52385889},{"atb":[[1.01,329.55]],"id":52385914},{"atb":[[1.03,7.81]],"id":52385883},{"atb":[[1.01,329.55]],"id":52385885},{"atb":[[1.03,7.81]],"id":52385896},{"atb":[[1.01,329.55]],"id":52385890},{"atb":[[1.02,11.71]],"id":52385892},{"atb":[[1.03,7.81]],"id":52385904},{"atb":[[1.01,329.55],[1.17,0]],"id":52385898},{"atb":[[1.02,11.71]],"id":52385900},{"atb":[[1.03,7.81]],"id":52385911},{"atb":[[1.02,11.71]],"id":52385913},{"atb":[[1.01,329.55]],"id":52385907},{"atb":[[1.02,11.71]],"id":52385886},{"atb":[[1.03,7.81]],"id":52385919},{"atb":[[1.03,7.81]],"id":52385921},{"atb":[[1.03,7.81]],"id":52385882},{"atb":[[1.01,329.55]],"id":52385884},{"atb":[[1.01,329.55]],"id":52385917},{"atb":[[1.01,329.55]],"id":52385897},{"atb":[[1.02,11.71]],"id":52385891},{"atb":[[1.01,329.55]],"id":52385893},{"atb":[[1.01,329.55]],"id":52385903},{"atb":[[1.03,7.81]],"id":52385905},{"atb":[[1.03,7.81]],"id":52385899}],"con":true,"img":false}]}
{"op":"mcm","clk":"11550338037","pt":1719497212603,"mc":[{"id":"1.230178170","rc":[{"atb":[[1.17,0]],"id":52385882}],"con":true,"img":false}]}
{"op":"mcm","clk":"11550358753","pt":1719497462833,"mc":[{"id":"1.230178170","rc":[{"atb":[[1.17,0]],"id":52385897}],"con":true,"img":false}]}
{"op":"mcm","clk":"11550376825","pt":1719497692863,"mc":[{"id":"1.230178170","rc":[{"atb":[[1.17,0]],"id":52385906}],"con":true,"img":false}]}
{"op":"mcm","clk":"11550384088","pt":1719497775360,"mc":[{"id":"1.230178170","rc":[{"atb":[[17.5,14.48]],"id":52385883}],"con":true,"img":false}]}
{"op":"mcm","clk":"11550384103","pt":1719497775466,"mc":[{"id":"1.230178170","rc":[{"atb":[[20,11.9]],"id":52385910},{"atb":[[20,11.86]],"id":52385885},{"atb":[[19,12.7]],"id":52385886},{"atb":[[21,11.23]],"id":52385882},{"atb":[[18,15.18]],"id":52385884},{"atb":[[18.5,14.87]],"id":52385917}],"con":true,"img":false}]}
{"op":"mcm","clk":"11550384524","pt":1719497780431,"mc":[{"id":"1.230178170","rc":[{"atb":[[3.5,50]],"id":52385910},{"atb":[[3.5,50]],"id":52385883},{"atb":[[3.5,50]],"id":52385885},{"atb":[[3.5,50]],"id":52385886},{"atb":[[3.5,50]],"id":52385882},{"atb":[[3.5,50]],"id":52385884},{"atb":[[3.5,50]],"id":52385917}],"con":true,"img":false}]}
{"op":"mcm","clk":"11550384749","pt":1719497783059,"mc":[{"id":"1.230178170","rc":[{"atb":[[20,0]],"id":52385910},{"atb":[[17.5,0]],"id":52385883},{"atb":[[20,0]],"id":52385885},{"atb":[[21,0]],"id":52385882},{"atb":[[18,0]],"id":52385884},{"atb":[[18.5,0]],"id":52385917}],"con":true,"img":false}]}
{"op":"mcm","clk":"11550384759","pt":1719497783167,"mc":[{"id":"1.230178170","rc":[{"atb":[[19,0]],"id":52385886}],"con":true,"img":false}]}
{"op":"mcm","clk":"11550384981","pt":1719497785757,"mc":[{"id":"1.230178170","rc":[{"atb":[[3.5,0]],"id":52385886}],"con":true,"img":false}]}
{"op":"mcm","clk":"11550384999","pt":1719497785967,"mc":[{"id":"1.230178170","rc":[{"atb":[[3.5,0]],"id":52385885}],"con":true,"img":false}]}
{"op":"mcm","clk":"11550385017","pt":1719497786182,"mc":[{"id":"1.230178170","rc":[{"atb":[[3.5,0]],"id":52385884}],"con":true,"img":false}]}
{"op":"mcm","clk":"11550385033","pt":1719497786382,"mc":[{"id":"1.230178170","rc":[{"atb":[[3.5,0]],"id":52385917}],"con":true,"img":false}]}
{"op":"mcm","clk":"11550385052","pt":1719497786537,"mc":[{"id":"1.230178170","rc":[{"atb":[[3.5,0]],"id":52385882}],"con":true,"img":false}]}
{"op":"mcm","clk":"11550385073","pt":1719497786743,"mc":[{"id":"1.230178170","rc":[{"atb":[[3.5,0]],"id":52385883}],"con":true,"img":false}]}
{"op":"mcm","clk":"11550385087","pt":1719497786958,"mc":[{"id":"1.230178170","rc":[{"atb":[[3.5,0]],"id":52385910}],"con":true,"img":false}]}
{"op":"mcm","clk":"11550398385","pt":1719497942972,"mc":[{"id":"1.230178170","rc":[{"atb":[[1.17,0]],"id":52385905}],"con":true,"img":false}]}
{"op":"mcm","clk":"11550413768","pt":1719498140679,"mc":[{"id":"1.230178170","rc":[{"atb":[[20,12.37]],"id":52385910},{"atb":[[17.5,14.7]],"id":52385883},{"atb":[[20,12.31]],"id":52385885},{"atb":[[19,13.53]],"id":52385886},{"atb":[[21,10.79]],"id":52385882},{"atb":[[18,14.97]],"id":52385884},{"atb":[[18.5,15.09]],"id":52385917}],"con":true,"img":false}]}
{"op":"mcm","clk":"11550413783","pt":1719498140881,"mc":[{"id":"1.230178170","rc":[{"atb":[[20,0]],"id":52385910},{"atb":[[17.5,0]],"id":52385883},{"atb":[[20,0]],"id":52385885},{"atb":[[19,0]],"id":52385886},{"atb":[[21,0]],"id":52385882},{"atb":[[18,0]],"id":52385884},{"atb":[[18.5,0]],"id":52385917}],"con":true,"img":false}]}
{"op":"mcm","clk":"11550416997","pt":1719498183016,"mc":[{"id":"1.230178170","rc":[{"atb":[[1.17,0]],"id":52385910}],"con":true,"img":false}]}
{"op":"mcm","clk":"11550418745","pt":1719498203541,"mc":[{"id":"1.230178170","rc":[{"atb":[[20,12.93]],"id":52385910},{"atb":[[17.5,13.47]],"id":52385883},{"atb":[[20,12.35]],"id":52385885},{"atb":[[19,14.33]],"id":52385886},{"atb":[[21,13.03]],"id":52385882},{"atb":[[18,12.92]],"id":52385884},{"atb":[[18.5,12.88]],"id":52385917}],"con":true,"img":false}]}
{"op":"mcm","clk":"11550418830","pt":1719498204471,"mc":[{"id":"1.230178170","rc":[{"atb":[[20,0]],"id":52385910},{"atb":[[17.5,0]],"id":52385883},{"atb":[[20,0]],"id":52385885},{"atb":[[19,0]],"id":52385886},{"atb":[[21,0]],"id":52385882},{"atb":[[18,0]],"id":52385884},{"atb":[[18.5,0]],"id":52385917}],"con":true,"img":false}]}
{"op":"mcm","clk":"11550425804","pt":1719498292155,"mc":[{"id":"1.230178170","rc":[{"atb":[[20,11.9]],"id":52385910}],"con":true,"img":false}]}
{"op":"mcm","clk":"11550425820","pt":1719498292363,"mc":[{"id":"1.230178170","rc":[{"atb":[[20,0]],"id":52385910}],"con":true,"img":false}]}
{"op":"mcm","clk":"11550431258","pt":1719498364229,"mc":[{"id":"1.230178170","rc":[{"atb":[[18,5]],"id":52385910},{"atb":[[19,5]],"id":52385912},{"atb":[[16,6]],"id":52385906},{"atb":[[16,6]],"id":52385918},{"atb":[[16,6]],"id":52385920},{"atb":[[11,9]],"id":52385889},{"atb":[[15,6]],"id":52385914},{"atb":[[16,6]],"id":52385883},{"atb":[[20,5]],"id":52385885},{"atb":[[13,8]],"id":52385896},{"atb":[[15,6]],"id":52385890},{"atb":[[16,6]],"id":52385892},{"atb":[[15,6]],"id":52385904},{"atb":[[12,8]],"id":52385898},{"atb":[[14,7]],"id":52385900},{"atb":[[19,5]],"id":52385911},{"atb":[[18,5]],"id":52385913},{"atb":[[16,6]],"id":52385907},{"atb":[[18,5]],"id":52385886},{"atb":[[17,6]],"id":52385919},{"atb":[[16,6]],"id":52385921},{"atb":[[12,8]],"id":52385882},{"atb":[[19,5]],"id":52385884},{"atb":[[17,6]],"id":52385917},{"atb":[[12,8]],"id":52385897},{"atb":[[15,6]],"id":52385891},{"atb":[[16,6]],"id":52385893},{"atb":[[16,6]],"id":52385903},{"atb":[[16,6]],"id":52385905},{"atb":[[16,6]],"id":52385899}],"con":true,"img":false}]}
{"op":"mcm","clk":"11550432591","pt":1719498380747,"mc":[{"id":"1.230178170","rc":[{"atb":[[21,10.96]],"id":52385911}],"con":true,"img":false}]}
{"op":"mcm","clk":"11550432607","pt":1719498380910,"mc":[{"id":"1.230178170","rc":[{"atb":[[21,0]],"id":52385911}],"con":true,"img":false}]}
{"op":"mcm","clk":"11550434245","pt":1719498403673,"mc":[{"id":"1.230178170","rc":[{"atb":[[17.5,15]],"id":52385883},{"atb":[[19,12.5]],"id":52385886},{"atb":[[22,11.59]],"id":52385882},{"atb":[[18,12.5]],"id":52385884}],"con":true,"img":false}]}
{"op":"mcm","clk":"11550434414","pt":1719498405855,"mc":[{"id":"1.230178170","rc":[{"atb":[[17.5,0]],"id":52385883},{"atb":[[19,0]],"id":52385886},{"atb":[[22,0]],"id":52385882},{"atb":[[18,0]],"id":52385884}],"con":true,"img":false}]}
{"op":"mcm","clk":"11550436418","pt":1719498433201,"mc":[{"id":"1.230178170","rc":[{"atb":[[1.17,0]],"id":52385907}],"con":true,"img":false}]}
{"op":"mcm","clk":"11550443498","pt":1719498524502,"mc":[{"id":"1.230178170","rc":[{"atb":[[19.5,12.5]],"id":52385910},{"atb":[[17.5,13.82]],"id":52385883},{"atb":[[19,12.5]],"id":52385886},{"atb":[[22,12.44]],"id":52385882},{"atb":[[18,12.5]],"id":52385884},{"atb":[[19,14.01]],"id":52385917}],"con":true,"img":false}]}
{"op":"mcm","clk":"11550443580","pt":1719498525690,"mc":[{"id":"1.230178170","rc":[{"atb":[[19.5,0]],"id":52385910},{"atb":[[17.5,0]],"id":52385883},{"atb":[[19,0]],"id":52385886},{"atb":[[22,0]],"id":52385882},{"atb":[[18,0]],"id":52385884},{"atb":[[19,0]],"id":52385917}],"con":true,"img":false}]}
{"op":"mcm","clk":"11550444579","pt":1719498540090,"mc":[{"id":"1.230178170","rc":[{"atb":[[4.9,25.64]],"id":52385898},{"atl":[[430,2]],"id":52385898}],"con":true,"img":false}]}
{"op":"mcm","clk":"11550444587","pt":1719498540234,"mc":[{"id":"1.230178170","rc":[{"atb":[[9,12.5]],"id":52385910},{"atl":[[610,2]],"id":52385910},{"atb":[[8.8,12.82]],"id":52385912},{"atl":[[610,2]],"id":52385912},{"atb":[[7.4,12]],"id":52385906},{"atl":[[540,2]],"id":52385906},{"atb":[[8.6,13.16]],"id":52385918},{"atl":[[590,2]],"id":52385918},{"atb":[[5.2,23.81]],"id":52385920},{"atl":[[460,2]],"id":52385920},{"atb":[[7.4,15.62]],"id":52385889},{"atl":[[540,2]],"id":52385889},{"atb":[[7.4,15.62]],"id":52385914},{"atl":[[540,2]],"id":52385914},{"atb":[[8.8,12]],"id":52385883},{"atl":[[600,2]],"id":52385883},{"atb":[[13.5,8]],"id":52385885},{"atl":[[820,2]],"id":52385885},{"atb":[[5.6,16]],"id":52385896},{"atl":[[490,2]],"id":52385896},{"atb":[[8,14.29]],"id":52385890},{"atl":[[560,2]],"id":52385890},{"atb":[[10.5,10.53]],"id":52385892},{"atl":[[760,2]],"id":52385892},{"atb":[[6.4,12]],"id":52385904},{"atl":[[520,2]],"id":52385904},{"atb":[[5.3,14]],"id":52385900},{"atl":[[470,2]],"id":52385900},{"atb":[[10,11.11]],"id":52385911},{"atl":[[720,2]],"id":52385911},{"atb":[[7,16.67]],"id":52385913},{"atl":[[530,2]],"id":52385913},{"atb":[[4.8,26.32]],"id":52385907},{"atl":[[420,2]],"id":52385907},{"atb":[[8.6,11.72]],"id":52385886},{"atl":[[590,2]],"id":52385886},{"atb":[[6.8,17.24]],"id":52385919},{"atl":[[530,2]],"id":52385919},{"atb":[[8.8,12.82]],"id":52385921},{"atl":[[600,2]],"id":52385921},{"atb":[[9.8,11.36]],"id":52385882},{"atl":[[670,2]],"id":52385882},{"atb":[[7.6,15.15]],"id":52385884},{"atl":[[550,2]],"id":52385884},{"atb":[[7,16.67]],"id":52385917},{"atl":[[530,2]],"id":52385917},{"atb":[[7.2,16.13]],"id":52385897},{"atl":[[530,2]],"id":52385897},{"atb":[[6.6,12]],"id":52385891},{"atl":[[520,2]],"id":52385891},{"atb":[[7.8,14.71]],"id":52385893},{"atl":[[550,2]],"id":52385893},{"atb":[[5.2,23.81]],"id":52385903},{"atl":[[460,2]],"id":52385903},{"atb":[[5.1,12]],"id":52385905},{"atl":[[460,2]],"id":52385905},{"atb":[[8.6,12]],"id":52385899},{"atl":[[590,2]],"id":52385899}],"con":true,"img":false}]}
{"op":"mcm","clk":"11550444717","pt":1719498541600,"mc":[{"id":"1.230178170","rc":[{"atl":[[520,2],[550,0]],"id":52385893}],"con":true,"img":false}]}
{"op":"mcm","clk":"11550445349","pt":1719498550215,"mc":[{"id":"1.230178170","rc":[{"atl":[[410,2],[430,0]],"id":52385898}],"con":true,"img":false}]}
{"op":"mcm","clk":"11550445358","pt":1719498550327,"mc":[{"id":"1.230178170","rc":[{"atl":[[550,2],[610,0]],"id":52385910},{"atb":[[10,11.11],[8.8,0]],"id":52385912},{"atl":[[560,2],[610,0]],"id":52385912},{"atb":[[7.4,0],[8.4,12]],"id":52385906},{"atl":[[540,0],[510,2]],"id":52385906},{"atb":[[8.6,0],[9.8,11.36]],"id":52385918},{"atl":[[540,2],[590,0]],"id":52385918},{"atb":[[5.8,20.83],[5.2,0]],"id":52385920},{"atl":[[420,2],[460,0]],"id":52385920},{"atl":[[540,0],[500,2]],"id":52385889},{"atb":[[7.4,0],[8.4,13.51]],"id":52385914},{"atl":[[540,0],[510,2]],"id":52385914},{"atb":[[8.8,0],[9.4,11.9]],"id":52385883},{"atl":[[530,2],[600,0]],"id":52385883},{"atl":[[680,2],[820,0]],"id":52385885},{"atl":[[430,2],[490,0]],"id":52385896},{"atb":[[8,0],[9.2,12.2]],"id":52385890},{"atl":[[520,2],[560,0]],"id":52385890},{"atb":[[10.5,0],[12.5,8.7]],"id":52385892},{"atl":[[660,2],[760,0]],"id":52385892},{"atb":[[6.4,0],[7.4,12]],"id":52385904},{"atl":[[520,0],[470,2]],"id":52385904},{"atb":[[5.5,22.22],[4.9,0]],"id":52385898},{"atl":[[390,2],[410,0]],"id":52385898},{"atb":[[5.3,0],[6,14]],"id":52385900},{"atb":[[10,0],[11.5,9.52]],"id":52385911},{"atl":[[640,2],[720,0]],"id":52385911},{"atb":[[8,14.29],[7,0]],"id":52385913},{"atl":[[530,0],[490,2]],"id":52385913},{"atb":[[4.8,0],[5.4,22.73]],"id":52385907},{"atl":[[380,2],[420,0]],"id":52385907},{"atl":[[520,2],[590,0]],"id":52385886},{"atb":[[6.8,0],[7.8,14.71]],"id":52385919},{"atl":[[530,0],[490,2]],"id":52385919},{"atb":[[10,11.11],[8.8,0]],"id":52385921},{"atl":[[550,2],[600,0]],"id":52385921},{"atb":[[10.5,10.53],[9.8,0]],"id":52385882},{"atl":[[570,2],[670,0]],"id":52385882},{"atl":[[550,0],[490,2]],"id":52385884},{"atl":[[530,0],[480,2]],"id":52385917},{"atb":[[7.2,0],[8.2,13.89]],"id":52385897},{"atl":[[530,0],[500,2]],"id":52385897},{"atb":[[7.6,12],[6.6,0]],"id":52385891},{"atl":[[520,0],[480,2]],"id":52385891},{"atb":[[8.8,12.82],[7.8,0]],"id":52385893},{"atl":[[520,0],[510,2]],"id":52385893},{"atl":[[410,2],[460,0]],"id":52385903},{"atb":[[5.1,0],[5.7,12]],"id":52385905},{"atl":[[460,0]],"id":52385905},{"atb":[[8.6,0],[9.8,11.36]],"id":52385899},{"atl":[[540,2],[590,0]],"id":52385899}],"con":true,"img":false}]}
{"op":"mcm","clk":"11550445367","pt":1719498550417,"mc":[{"id":"1.230178170","rc":[{"atb":[[8.2,13.89],[7.4,0]],"id":52385889},{"atl":[[430,2],[470,0]],"id":52385900},{"atl":[[420,2]],"id":52385905}],"con":true,"img":false}]}
{"op":"mcm","clk":"11550446390","pt":1719498565429,"mc":[{"id":"1.230178170","rc":[{"atb":[[16,0]],"id":52385906},{"atb":[[15,0]],"id":52385904},{"atb":[[12,0]],"id":52385898},{"atb":[[18,0]],"id":52385913},{"atb":[[19,0]],"id":52385884},{"atb":[[15,0]],"id":52385891},{"atb":[[16,0]],"id":52385903},{"atb":[[16,0]],"id":52385905}],"con":true,"img":false}]}
{"op":"mcm","clk":"11550446403","pt":1719498565533,"mc":[{"id":"1.230178170","rc":[{"atb":[[3.6,24],[14,6],[8.4,0]],"id":52385906},{"atb":[[7.4,0],[3.35,24],[13,6]],"id":52385904},{"atb":[[2.9,52.63],[5.5,0],[11,8]],"id":52385898},{"atb":[[16,5],[3.5,40]],"id":52385913},{"atb":[[17,5],[3.45,40.82]],"id":52385884},{"atb":[[7.6,0],[3.4,24],[14,6]],"id":52385891},{"atb":[[2.92,52.08],[5.2,0],[13,6]],"id":52385903},{"atb":[[13,6],[5.7,0],[2.94,51.55]],"id":52385905}],"con":true,"img":false}]}
{"op":"mcm","clk":"11550446411","pt":1719498565635,"mc":[{"id":"1.230178170","rc":[{"atb":[[3.6,0],[8.4,13.51]],"id":52385906},{"atb":[[3.35,0],[7.4,15.62]],"id":52385904},{"atb":[[2.9,0],[5.5,22.22]],"id":52385898},{"atb":[[8,0]],"id":52385913},{"atb":[[7.6,0],[7.8,14.71]],"id":52385884},{"atb":[[3.4,0],[7.6,15.15]],"id":52385891},{"atb":[[5.6,21.74],[2.92,0]],"id":52385903},{"atb":[[5.7,21.28],[2.94,0]],"id":52385905}],"con":true,"img":false}]}
{"op":"mcm","clk":"11550446418","pt":1719498565736,"mc":[{"id":"1.230178170","rc":[{"atb":[[8,14.29],[3.5,0]],"id":52385913},{"atb":[[3.45,0]],"id":52385884}],"con":true,"img":false}]}
{"op":"mcm","clk":"11550446809","pt":1719498570947,"mc":[{"id":"1.230178170","rc":[{"atb":[[9,0],[10.5,10.53]],"id":52385910},{"atb":[[9,12.5],[8.4,0]],"id":52385906},{"atb":[[8.6,13.16],[8.2,0]],"id":52385889},{"atb":[[9,12.5],[8.4,0]],"id":52385914},{"atb":[[10,11.11],[9.4,0]],"id":52385883},{"atb":[[6.4,16]],"id":52385896},{"atb":[[9.2,0],[9.8,11.36]],"id":52385890},{"atb":[[12.5,0],[13.5,8]],"id":52385892},{"atb":[[8.6,0],[9.8,11.36]],"id":52385886},{"atb":[[10.5,0],[11,10]],"id":52385882},{"atb":[[8,14.29],[7,0]],"id":52385917},{"atb":[[8.8,0],[9.4,11.9]],"id":52385893}],"con":true,"img":false}]}
{"op":"mcm","clk":"11550446816","pt":1719498571050,"mc":[{"id":"1.230178170","rc":[{"atb":[[5.6,0]],"id":52385896}],"con":true,"img":false}]}
{"op":"mcm","clk":"11550447203","pt":1719498577360,"mc":[{"id":"1.230178170","rc":[{"atb":[[16,0]],"id":52385907}],"con":true,"img":false}]}
{"op":"mcm","clk":"11550447210","pt":1719498577467,"mc":[{"id":"1.230178170","rc":[{"atb":[[14,6],[2.94,51.55],[5.4,0]],"id":52385907}],"con":true,"img":false}]}
{"op":"mcm","clk":"11550447227","pt":1719498577567,"mc":[{"id":"1.230178170","rc":[{"atb":[[5.7,21.28],[2.94,0]],"id":52385907}],"con":true,"img":false}]}
{"op":"mcm","clk":"11550448164","pt":1719498589281,"mc":[{"id":"1.230178170","rc":[{"atb":[[14,0]],"id":52385906},{"atb":[[16,0]],"id":52385920},{"atb":[[13,0]],"id":52385904},{"atb":[[11,0]],"id":52385898},{"atb":[[14,0]],"id":52385907},{"atb":[[14,0]],"id":52385891},{"atb":[[13,0]],"id":52385903},{"atb":[[13,0]],"id":52385905}],"con":true,"img":false}]}
{"op":"mcm","clk":"11550448171","pt":1719498589383,"mc":[{"id":"1.230178170","rc":[{"atb":[[12,6]],"id":52385906},{"atb":[[14,6]],"id":52385920},{"atb":[[11,6]],"id":52385904},{"atb":[[10,8]],"id":52385898},{"atb":[[12,6]],"id":52385907},{"atb":[[13,6]],"id":52385891},{"atb":[[11,6]],"id":52385903},{"atb":[[10,6]],"id":52385905}],"con":true,"img":false}]}
{"op":"mcm","clk":"11550448182","pt":1719498589491,"mc":[{"id":"1.230178170","rc":[{"atb":[[9,0],[3.75,25]],"id":52385906},{"atb":[[5.8,0],[3,50]],"id":52385920},{"atb":[[3.45,31.24],[7.4,0]],"id":52385904},{"atb":[[5.5,0],[2.96,51.02]],"id":52385898},{"atb":[[5.7,0],[2.94,51.55]],"id":52385907},{"atb":[[7.6,0],[3.5,30.3]],"id":52385891},{"atb":[[5.6,0],[3,50]],"id":52385903},{"atb":[[3,50],[5.7,0]],"id":52385905}],"con":true,"img":false}]}
{"op":"mcm","clk":"11550448223","pt":1719498589989,"mc":[{"id":"1.230178170","rc":[{"atl":[[540,0],[580,2]],"id":52385918},{"atl":[[460,2]],"id":52385900}],"con":true,"img":false}]}
{"op":"mcm","clk":"11550448236","pt":1719498590115,"mc":[{"id":"1.230178170","rc":[{"atl":[[430,0]],"id":52385900}],"con":true,"img":false}]}
{"op":"mcm","clk":"11550448877","pt":1719498599091,"mc":[{"id":"1.230178170","rc":[{"atb":[[9,12.5],[3.75,0]],"id":52385906},{"atb":[[7.8,14.71]],"id":52385904},{"atb":[[5.8,20.83]],"id":52385898},{"atb":[[5.7,21.28],[2.94,0]],"id":52385907},{"atb":[[3,0],[6,20]],"id":52385905}],"con":true,"img":false}]}
{"op":"mcm","clk":"11550448884","pt":1719498599192,"mc":[{"id":"1.230178170","rc":[{"atb":[[3,0],[6,20]],"id":52385920},{"atb":[[3.45,0]],"id":52385904},{"atb":[[2.96,0]],"id":52385898},{"atb":[[8,14.29],[3.5,0]],"id":52385891},{"atb":[[3,0],[6,20]],"id":52385903}],"con":true,"img":false}]}
{"op":"mcm","clk":"11550451124","pt":1719498628906,"mc":[{"id":"1.230178170","rc":[{"atl":[[540,2],[580,0]],"id":52385918},{"atl":[[430,2],[460,0]],"id":52385900}],"con":true,"img":false}]}
{"op":"mcm","clk":"11550452092","pt":1719498643415,"mc":[{"id":"1.230178170","rc":[{"atb":[[19,0]],"id":52385912},{"atb":[[14,0]],"id":52385920},{"atb":[[15,0]],"id":52385914},{"atb":[[14,0]],"id":52385900}],"con":true,"img":false}]}
{"op":"mcm","clk":"11550452105","pt":1719498643521,"mc":[{"id":"1.230178170","rc":[{"atb":[[17,5],[4.1,32.26]],"id":52385912},{"atb":[[3,50],[13,6]],"id":52385920},{"atb":[[14,6]],"id":52385914},{"atb":[[13,7]],"id":52385900}],"con":true,"img":false}]}
{"op":"mcm","clk":"11550452116","pt":1719498643626,"mc":[{"id":"1.230178170","rc":[{"atb":[[10,0]],"id":52385912},{"atb":[[9,0],[3.75,36.36]],"id":52385914},{"atb":[[3.05,28.9]],"id":52385900}],"con":true,"img":false}]}
{"op":"mcm","clk":"11550452123","pt":1719498643727,"mc":[{"id":"1.230178170","rc":[{"atb":[[10.5,10.53],[4.1,0]],"id":52385912},{"atb":[[6,0]],"id":52385920},{"atb":[[9,12.5]],"id":52385914},{"atb":[[6.2,14],[6,0],[3.05,0.9]],"id":52385900}],"con":true,"img":false}]}
{"op":"mcm","clk":"11550452129","pt":1719498643820,"mc":[{"id":"1.230178170","rc":[{"atb":[[3,0],[6,20]],"id":52385920},{"atb":[[3.75,0]],"id":52385914}],"con":true,"img":false}]}
{"op":"mcm","clk":"11550452247","pt":1719498645420,"mc":[{"id":"1.230178170","rc":[{"atb":[[16,0]],"id":52385921}],"con":true,"img":false}]}
{"op":"mcm","clk":"11550452256","pt":1719498645527,"mc":[{"id":"1.230178170","rc":[{"atb":[[10,0],[4.1,32.26],[14,6]],"id":52385921}],"con":true,"img":false}]}
{"op":"mcm","clk":"11550452261","pt":1719498645629,"mc":[{"id":"1.230178170","rc":[{"atb":[[10.5,10.53],[4.1,0]],"id":52385921}],"con":true,"img":false}]}
{"op":"mcm","clk":"11550454068","pt":1719498670384,"mc":[{"id":"1.230178170","rc":[{"atb":[[9,0],[7.8,14.71]],"id":52385906},{"atb":[[8.6,0],[7.6,15.15]],"id":52385889},{"atb":[[8.6,13.16],[9.8,0]],"id":52385890},{"atb":[[11.5,9.52],[13.5,0]],"id":52385892},{"atb":[[5.8,0],[5.2,23.81]],"id":52385898},{"atb":[[5.1,24.39]],"id":52385907},{"atb":[[8.6,13.16],[9.8,0]],"id":52385886},{"atb":[[10.5,0],[9.4,11.9]],"id":52385921},{"atb":[[11,0],[9.8,11.36]],"id":52385882},{"atb":[[5.3,23.26],[6,0]],"id":52385903},{"atb":[[6,0],[5.4,22.73]],"id":52385905}],"con":true,"img":false}]}
{"op":"mcm","clk":"11550454076","pt":1719498670485,"mc":[{"id":"1.230178170","rc":[{"atb":[[5.7,0]],"id":52385907}],"con":true,"img":false}]}
{"op":"mcm","clk":"11550454272","pt":1719498673389,"mc":[{"id":"1.230178170","rc":[{"atb":[[1.17,0]],"id":52385911}],"con":true,"img":false}]}
{"op":"mcm","clk":"11550456712","pt":1719498705520,"mc":[{"id":"1.230178170","rc":[{"atb":[[21,8.75]],"id":52385910},{"atb":[[18.5,10]],"id":52385883},{"atb":[[20,8.75]],"id":52385886},{"atb":[[23,11.14]],"id":52385882},{"atb":[[19,8.75]],"id":52385884}],"con":true,"img":false}]}
{"op":"mcm","clk":"11550456735","pt":1719498705793,"mc":[{"id":"1.230178170","rc":[{"atb":[[21,0]],"id":52385910},{"atb":[[18.5,0]],"id":52385883},{"atb":[[20,0]],"id":52385886},{"atb":[[23,0]],"id":52385882},{"atb":[[19,0]],"id":52385884}],"con":true,"img":false}]}
{"op":"mcm","clk":"11550458959","pt":1719498733317,"mc":[{"id":"1.230178170","rc":[{"atb":[[12,0]],"id":52385897}],"con":true,"img":false}]}
{"op":"mcm","clk":"11550458966","pt":1719498733421,"mc":[{"id":"1.230178170","rc":[{"atb":[[8.2,0],[11,8],[3.4,41.67]],"id":52385897}],"con":true,"img":false}]}
{"op":"mcm","clk":"11550459406","pt":1719498739354,"mc":[{"id":"1.230178170","rc":[{"atb":[[13,0]],"id":52385896},{"atb":[[10,0]],"id":52385898},{"atb":[[13,0]],"id":52385900}],"con":true,"img":false}]}
{"op":"mcm","clk":"11550459413","pt":1719498739454,"mc":[{"id":"1.230178170","rc":[{"atb":[[12,8]],"id":52385896},{"atb":[[9,8]],"id":52385898},{"atb":[[12,7]],"id":52385900}],"con":true,"img":false}]}
{"op":"mcm","clk":"11550459421","pt":1719498739546,"mc":[{"id":"1.230178170","rc":[{"atb":[[6.4,0],[2.94,51.55]],"id":52385896},{"atb":[[5.2,0],[2.84,54.35]],"id":52385898},{"atb":[[6.2,0],[2.94,51.55]],"id":52385900}],"con":true,"img":false}]}
{"op":"mcm","clk":"11550459603","pt":1719498741630,"mc":[{"id":"1.230178170","rc":[{"atb":[[3.4,0],[7.6,15.15]],"id":52385897}],"con":true,"img":false}]}
{"op":"mcm","clk":"11550460020","pt":1719498747663,"mc":[{"id":"1.230178170","rc":[{"atb":[[5.7,21.28],[2.94,0]],"id":52385896},{"atb":[[5.2,23.81]],"id":52385898},{"atb":[[5.7,21.28],[2.94,0]],"id":52385900}],"con":true,"img":false}]}
{"op":"mcm","clk":"11550460026","pt":1719498747725,"mc":[{"id":"1.230178170","rc":[{"atb":[[2.84,0]],"id":52385898}],"con":true,"img":false}]}
{"op":"mcm","clk":"11550466985","pt":1719498832346,"mc":[{"id":"1.230178170","rc":[{"atb":[[16,0]],"id":52385913}],"con":true,"img":false}]}
{"op":"mcm","clk":"11550466997","pt":1719498832452,"mc":[{"id":"1.230178170","rc":[{"atb":[[3.4,41.67],[14,5]],"id":52385913}],"con":true,"img":false}]}
{"op":"mcm","clk":"11550467009","pt":1719498832518,"mc":[{"id":"1.230178170","rc":[{"atb":[[8,0],[7.6,15.15]],"id":52385913}],"con":true,"img":false}]}
{"op":"mcm","clk":"11550467025","pt":1719498832720,"mc":[{"id":"1.230178170","rc":[{"atb":[[3.4,0]],"id":52385913}],"con":true,"img":false}]}
{"op":"mcm","clk":"11550468453","pt":1719498852157,"mc":[{"id":"1.230178170","rc":[{"atb":[[8.8,12.82]],"id":52385910},{"atb":[[7.6,15.15]],"id":52385914},{"atb":[[6.6,17.86]],"id":52385904},{"atb":[[9.2,12.2]],"id":52385882},{"atb":[[8.6,13.16]],"id":52385899}],"con":true,"img":false}]}
{"op":"mcm","clk":"11550468460","pt":1719498852259,"mc":[{"id":"1.230178170","rc":[{"atb":[[10.5,0]],"id":52385910},{"atb":[[9,12.5],[10.5,0]],"id":52385912},{"atb":[[8.6,13.16]],"id":52385918},{"atb":[[6,0],[5.2,23.81]],"id":52385920},{"atb":[[9,0]],"id":52385914},{"atb":[[10,0],[8.4,13.51]],"id":52385883},{"atb":[[7.8,0]],"id":52385904},{"atb":[[9.8,0]],"id":52385882},{"atb":[[8,0],[6.8,17.24]],"id":52385917},{"atb":[[8,0],[6.8,17.24]],"id":52385891},{"atb":[[7.8,14.71],[9.4,0]],"id":52385893},{"atb":[[9.8,0]],"id":52385899}],"con":true,"img":false}]}
{"op":"mcm","clk":"11550468466","pt":1719498852360,"mc":[{"id":"1.230178170","rc":[{"atb":[[9.8,0]],"id":52385918}],"con":true,"img":false}]}
{"op":"mcm","clk":"11550468533","pt":1719498853338,"mc":[{"id":"1.230178170","rc":[{"atb":[[18,0]],"id":52385910},{"atb":[[12,0]],"id":52385906},{"atb":[[14,0]],"id":52385914},{"atb":[[19,0]],"id":52385911},{"atb":[[14,0]],"id":52385913},{"atb":[[14,0]],"id":52385921}],"con":true,"img":false}]}
{"op":"mcm","clk":"11550468539","pt":1719498853442,"mc":[{"id":"1.230178170","rc":[{"atb":[[3.7,37.04],[8.8,0],[15,5]],"id":52385910},{"atb":[[11,6],[3.35,29.42],[7.8,0]],"id":52385906},{"atb":[[11,6],[7.6,0],[3.4,41.67]],"id":52385914},{"atb":[[4,19.04],[17,5],[11.5,0]],"id":52385911},{"atb":[[7.6,0],[12,5],[3.3,43.48]],"id":52385913},{"atb":[[3.7,37.04],[12,6],[9.4,0]],"id":52385921}],"con":true,"img":false}]}
{"op":"mcm","clk":"11550468581","pt":1719498854168,"mc":[{"id":"1.230178170","rc":[{"atb":[[10.5,5],[12.5,2.5],[15.5,14]],"id":52385910},{"atl":[[65,2.5],[540,1.11],[85,5]],"id":52385910},{"atb":[[17.5,14],[9,0],[10,11.11],[10.5,2.5],[9.4,5]],"id":52385912},{"atl":[[65,2.5],[550,1.09],[85,5]],"id":52385912},{"atb":[[9.6,2.5],[11.5,16],[8.8,5]],"id":52385906},{"atl":[[70,5],[50,2.5],[500,1.2]],"id":52385906},{"atb":[[16.5,16],[8.6,0],[18,5],[20,2.5],[9.4,11.9]],"id":52385918},{"atl":[[530,1.13],[70,2.5],[90,5]],"id":52385918},{"atb":[[10.5,2.5],[5.2,0],[13.5,16],[5.7,21.28],[9.4,5]],"id":52385920},{"atl":[[65,5],[48,2.5],[410,1.47]],"id":52385920},{"atb":[[1.2,2.5],[11.5,22]],"id":52385889},{"atl":[[70,2.5],[90,5],[490,1.23]],"id":52385889},{"atb":[[9.6,5],[11,8.5],[11.5,16]],"id":52385914},{"atl":[[65,5],[48,2.5],[500,1.2]],"id":52385914},{"atb":[[16,11],[16.5,16],[18,2.5]],"id":52385883},{"atl":[[520,1.16],[80,5],[60,2.5]],"id":52385883},{"atb":[[21,14],[12.5,5],[14.5,2.5]],"id":52385885},{"atl":[[160,5],[670,0.9],[120,2.5]],"id":52385885},{"atb":[[11.5,2.5],[12.5,20],[9.8,5]],"id":52385896},{"atl":[[75,5],[420,1.43],[55,2.5]],"id":52385896},{"atb":[[16,2.5],[14,5],[15.5,16]],"id":52385890},{"atl":[[65,2.5],[85,5],[510,1.18]],"id":52385890},{"atb":[[16,8.5],[16.5,16],[11.5,0],[12.5,8.7],[14,5]],"id":52385892},{"atl":[[140,5],[650,0.92],[100,2.5]],"id":52385892},{"atb":[[11,11],[11.5,16],[13,2.5]],"id":52385904},{"atl":[[42,2.5],[50,5],[460,1.31]],"id":52385904},{"atb":[[8,2.5],[7.2,5],[9.2,20]],"id":52385898},{"atl":[[40,2.5],[380,1.58],[48,5]],"id":52385898},{"atb":[[8.6,2.5],[12.5,18],[7.8,5]],"id":52385900},{"atl":[[70,5],[50,2.5],[420,1.43]],"id":52385900},{"atb":[[17.5,14],[10.5,2.5],[9.4,5]],"id":52385911},{"atl":[[630,0.95],[90,2.5],[120,5]],"id":52385911},{"atb":[[9,2.5],[8.2,5],[12.5,14]],"id":52385913},{"atl":[[46,2.5],[60,5],[480,1.25]],"id":52385913},{"atb":[[12,22],[6.6,2.5],[5.9,5]],"id":52385907},{"atl":[[40,2.5],[370,1.63],[48,5]],"id":52385907},{"atb":[[18.5,14],[13,5],[15,2.5]],"id":52385886},{"atl":[[70,2.5],[90,5],[510,1.18]],"id":52385886},{"atb":[[17.5,16],[12.5,5],[14.5,2.5]],"id":52385919},{"atl":[[80,5],[60,2.5],[480,1.25]],"id":52385919},{"atb":[[10.5,5],[12.5,18.5]],"id":52385921},{"atl":[[65,2.5],[540,1.11],[85,5]],"id":52385921},{"atb":[[1.2,2.5],[9.2,0],[10,11.11],[12.5,20]],"id":52385882},{"atl":[[560,1.07],[75,2.5],[95,5]],"id":52385882},{"atb":[[17.5,14],[10,5],[12,2.5]],"id":52385884},{"atl":[[75,5],[55,2.5],[480,1.25]],"id":52385884},{"atb":[[17.5,16],[11.5,5],[13.5,2.5]],"id":52385917},{"atl":[[70,2.5],[90,5],[470,1.28]],"id":52385917},{"atb":[[11.5,20],[12.5,5],[14.5,2.5]],"id":52385897},{"atl":[[75,5],[55,2.5],[490,1.23]],"id":52385897},{"atb":[[11,5],[13,8.5],[13.5,16]],"id":52385891},{"atl":[[75,5],[55,2.5],[470,1.28]],"id":52385891},{"atb":[[16,11],[16.5,16],[18,2.5]],"id":52385893},{"atl":[[70,2.5],[90,5],[500,1.2]],"id":52385893},{"atb":[[11.5,16],[7.8,2.5],[7,5]],"id":52385903},{"atl":[[40,2.5],[48,5],[400,1.5]],"id":52385903},{"atb":[[9.6,2.5],[10.5,16],[8.8,5]],"id":52385905},{"atl":[[34,2.5],[42,5],[410,1.47]],"id":52385905},{"atb":[[16.5,16],[9.6,16.63],[8.6,0],[11,2.5]],"id":52385899},{"atl":[[65,2.5],[530,1.13],[85,5]],"id":52385899}],"con":true,"img":false}]}
{"op":"mcm","clk":"11550468588","pt":1719498854278,"mc":[{"id":"1.230178170","rc":[{"atb":[[8.2,13.89],[7.6,0]],"id":52385889},{"atb":[[9.6,11.63],[8.4,0]],"id":52385883},{"atb":[[8.6,0],[9.2,12.2]],"id":52385890},{"atb":[[7.4,15.62],[6.6,0]],"id":52385904},{"atb":[[8.2,13.89],[7.6,0]],"id":52385897},{"atb":[[8.8,12.82],[7.8,0]],"id":52385893}],"con":true,"img":false}]}
{"op":"mcm","clk":"11550468597","pt":1719498854385,"mc":[{"id":"1.230178170","rc":[{"atl":[[550,0],[170,2]],"id":52385910},{"atl":[[560,0],[190,2]],"id":52385912},{"atl":[[130,2],[510,0]],"id":52385906},{"atl":[[540,0],[180,2]],"id":52385918},{"atl":[[75,2]],"id":52385920},{"atl":[[130,2],[500,0]],"id":52385889},{"atl":[[130,2],[510,0]],"id":52385914},{"atl":[[530,0],[170,2]],"id":52385883},{"atl":[[680,0],[340,2]],"id":52385885},{"atl":[[80,2],[430,0]],"id":52385896},{"atl":[[520,0],[150,2]],"id":52385890},{"atl":[[660,0],[330,2]],"id":52385892},{"atl":[[110,2],[470,0]],"id":52385904},{"atl":[[60,2]],"id":52385898},{"atl":[[80,2],[430,0]],"id":52385900},{"atl":[[290,2],[640,0]],"id":52385911},{"atl":[[490,0],[120,2]],"id":52385913},{"atl":[[380,0],[55,2]],"id":52385907},{"atl":[[520,0],[150,2]],"id":52385886},{"atl":[[490,0],[120,2]],"id":52385919},{"atl":[[550,0],[180,2]],"id":52385921},{"atb":[[10.5,10.53]],"id":52385882},{"atl":[[570,0],[220,2]],"id":52385882},{"atl":[[490,0],[120,2]],"id":52385884},{"atl":[[110,2],[480,0]],"id":52385917},{"atl":[[130,2],[500,0]],"id":52385897},{"atl":[[110,2],[480,0]],"id":52385891},{"atl":[[140,2],[510,0]],"id":52385893},{"atl":[[70,2],[410,0]],"id":52385903},{"atl":[[75,2],[420,0]],"id":52385905},{"atl":[[540,0],[170,2]],"id":52385899}],"con":true,"img":false}]}
{"op":"mcm","clk":"11550468603","pt":1719498854438,"mc":[{"id":"1.230178170","rc":[{"atl":[[420,0]],"id":52385920},{"atl":[[390,0]],"id":52385898},{"atb":[[10,0]],"id":52385882}],"con":true,"img":false}]}
{"op":"mcm","clk":"11550468660","pt":1719498855282,"mc":[{"id":"1.230178170","rc":[{"atb":[[11,0]],"id":52385897}],"con":true,"img":false}]}
{"op":"mcm","clk":"11550468677","pt":1719498855450,"mc":[{"id":"1.230178170","rc":[{"atb":[[16,0]],"id":52385918}],"con":true,"img":false}]}
{"op":"mcm","clk":"11550468692","pt":1719498855658,"mc":[{"id":"1.230178170","rc":[{"atb":[[11,0]],"id":52385889},{"atb":[[16,5]],"id":52385883},{"atb":[[12,0]],"id":52385896},{"atb":[[15,0]],"id":52385890},{"atb":[[16,2.5]],"id":52385892},{"atb":[[11,5]],"id":52385904},{"atb":[[9,0]],"id":52385898},{"atb":[[12,0]],"id":52385900},{"atb":[[18,0]],"id":52385886},{"atb":[[12,0]],"id":52385882},{"atb":[[13,2.5]],"id":52385891},{"atb":[[16,5]],"id":52385893},{"atb":[[11,0]],"id":52385903},{"atb":[[10,0]],"id":52385905}],"con":true,"img":false}]}
{"op":"mcm","clk":"11550468700","pt":1719498855759,"mc":[{"id":"1.230178170","rc":[{"atb":[[11.5,0],[15,9]],"id":52385889},{"atb":[[18,8.5]],"id":52385883},{"atb":[[16,8]],"id":52385896},{"atb":[[20,6]],"id":52385890},{"atb":[[18,6]],"id":52385892},{"atb":[[13,8.5]],"id":52385904},{"atb":[[9.2,0],[12,8]],"id":52385898},{"atb":[[12.5,0],[15,7]],"id":52385900},{"atb":[[20,5]],"id":52385886},{"atb":[[15,8]],"id":52385882},{"atb":[[16,6]],"id":52385891},{"atb":[[20,6]],"id":52385893},{"atb":[[11.5,0],[13,6]],"id":52385903},{"atb":[[10.5,0],[12,6]],"id":52385905}],"con":true,"img":false}]}
{"op":"mcm","clk":"11550468709","pt":1719498855862,"mc":[{"id":"1.230178170","rc":[{"atb":[[15.5,15]],"id":52385889},{"atb":[[16,23],[12.5,0]],"id":52385896},{"atb":[[12,18]],"id":52385898},{"atb":[[15,17]],"id":52385900},{"atb":[[13,16]],"id":52385903},{"atb":[[12.5,10]],"id":52385905}],"con":true,"img":false}]}
{"op":"mcm","clk":"11550468734","pt":1719498856275,"mc":[{"id":"1.230178170","rc":[{"atb":[[15,6]],"id":52385897}],"con":true,"img":false}]}
{"op":"mcm","clk":"11550468770","pt":1719498856646,"mc":[{"id":"1.230178170","rc":[{"atb":[[6.4,18.52],[5.7,0]],"id":52385896},{"atb":[[5.8,20.83],[5.2,0]],"id":52385898},{"atb":[[6.4,18.52],[5.7,0]],"id":52385900},{"atb":[[5.1,0],[5.7,21.28]],"id":52385907},{"atb":[[8.6,0],[9.8,11.36]],"id":52385886},{"atb":[[8,14.29],[6.8,0]],"id":52385917},{"atb":[[8,14.29],[6.8,0]],"id":52385891},{"atb":[[5.3,0],[6,20]],"id":52385903},{"atb":[[6,20],[5.4,0]],"id":52385905}],"con":true,"img":false}]}
{"op":"mcm","clk":"11550469118","pt":1719498860177,"mc":[{"id":"1.230178170","rc":[{"atb":[[6,2]],"id":52385910},{"atb":[[6,2]],"id":52385912},{"atb":[[6,2]],"id":52385906},{"atb":[[6,2]],"id":52385918},{"atb":[[6,2]],"id":52385920},{"atb":[[6,2]],"id":52385889},{"atb":[[6,2]],"id":52385914},{"atb":[[6,2]],"id":52385883},{"atb":[[6,2]],"id":52385885},{"atb":[[6,2]],"id":52385896},{"atb":[[6,2]],"id":52385890},{"atb":[[6,2]],"id":52385892},{"atb":[[6,2]],"id":52385904},{"atb":[[6,2]],"id":52385898},{"atb":[[6,2]],"id":52385900},{"atb":[[6,2]],"id":52385911},{"atb":[[6,2]],"id":52385913},{"atb":[[6,2]],"id":52385907},{"atb":[[6,2]],"id":52385886},{"atb":[[6,2]],"id":52385919},{"atb":[[6,2]],"id":52385921},{"atb":[[6,2]],"id":52385882},{"atb":[[6,2]],"id":52385884},{"atb":[[6,2]],"id":52385917},{"atb":[[6,2]],"id":52385897},{"atb":[[6,2]],"id":52385891},{"atb":[[6,2]],"id":52385893},{"atb":[[6,22]],"id":52385903},{"atb":[[6,22]],"id":52385905},{"atb":[[6,2]],"id":52385899}],"con":true,"img":false}]}
{"op":"mcm","clk":"11550469144","pt":1719498860487,"mc":[{"id":"1.230178170","rc":[{"atb":[[10,10]],"id":52385910},{"atb":[[8.8,17]],"id":52385906},{"atb":[[3.4,0],[8.8,12.82]],"id":52385914},{"atb":[[4,0],[12.5,8.7]],"id":52385911},{"atb":[[8.2,15],[3.3,0]],"id":52385913},{"atb":[[10.5,15.53],[3.7,0]],"id":52385921}],"con":true,"img":false}]}
{"op":"mcm","clk":"11550469155","pt":1719498860580,"mc":[{"id":"1.230178170","rc":[{"atb":[[3.7,0]],"id":52385910},{"atb":[[3.35,0]],"id":52385906}],"con":true,"img":false}]}
{"op":"mcm","clk":"11550469372","pt":1719498863374,"mc":[{"id":"1.230178170","rc":[{"atb":[[15,0]],"id":52385910},{"atb":[[11,0]],"id":52385906},{"atb":[[11,2.5]],"id":52385914},{"atb":[[17,0]],"id":52385911},{"atb":[[12,0]],"id":52385913},{"atb":[[12,0]],"id":52385921}],"con":true,"img":false}]}
{"op":"mcm","clk":"11550469381","pt":1719498863476,"mc":[{"id":"1.230178170","rc":[{"atb":[[18,5]],"id":52385910},{"atb":[[12,6]],"id":52385906},{"atb":[[14,6]],"id":52385914},{"atb":[[20,5]],"id":52385911},{"atb":[[15,5]],"id":52385913},{"atb":[[14,6]],"id":52385921}],"con":true,"img":false}]}
{"op":"mcm","clk":"11550469530","pt":1719498865289,"mc":[{"id":"1.230178170","rc":[{"atb":[[12,10]],"id":52385898},{"atb":[[15,10]],"id":52385900},{"atb":[[13,10]],"id":52385903}],"con":true,"img":false}]}
{"op":"mcm","clk":"11550469538","pt":1719498865391,"mc":[{"id":"1.230178170","rc":[{"atb":[[11,8]],"id":52385898},{"atb":[[14,7]],"id":52385900},{"atb":[[12,6]],"id":52385903}],"con":true,"img":false}]}
{"op":"mcm","clk":"11550469553","pt":1719498865559,"mc":[{"id":"1.230178170","rc":[{"atb":[[12,0]],"id":52385898},{"atb":[[15,0]],"id":52385900},{"atb":[[13,0]],"id":52385903}],"con":true,"img":false}]}
{"op":"mcm","clk":"11550469559","pt":1719498865666,"mc":[{"id":"1.230178170","rc":[{"atb":[[11.5,15]],"id":52385898},{"atb":[[14,22]],"id":52385900},{"atb":[[12.5,15]],"id":52385903}],"con":true,"img":false}]}
{"op":"mcm","clk":"11550469889","pt":1719498869074,"mc":[{"id":"1.230178170","rc":[{"atb":[[26,15]],"id":52385910},{"atl":[[60,10.17]],"id":52385910},{"atb":[[22,15]],"id":52385912},{"atl":[[55,11.11]],"id":52385912},{"atb":[[20,15]],"id":52385906},{"atl":[[48,12.77]],"id":52385906},{"atb":[[26,15]],"id":52385918},{"atl":[[65,9.38]],"id":52385918},{"atl":[[32,15]],"id":52385920},{"atl":[[65,9.38]],"id":52385889},{"atb":[[24,15]],"id":52385914},{"atl":[[46,13.33]],"id":52385914},{"atb":[[22,20]],"id":52385883},{"atl":[[55,11.11]],"id":52385883},{"atb":[[27,15]],"id":52385885},{"atl":[[110,5.5]],"id":52385885},{"atl":[[38,15]],"id":52385896},{"atb":[[23,15]],"id":52385890},{"atl":[[60,10.17]],"id":52385890},{"atb":[[29,15]],"id":52385892},{"atl":[[95,6.38]],"id":52385892},{"atb":[[21,20]],"id":52385904},{"atl":[[40,15.38]],"id":52385904},{"atl":[[26,15]],"id":52385898},{"atl":[[36,15]],"id":52385900},{"atb":[[27,20]],"id":52385911},{"atl":[[85,7.14]],"id":52385911},{"atb":[[21,15]],"id":52385913},{"atl":[[34,15]],"id":52385913},{"atl":[[26,10]],"id":52385907},{"atb":[[24,15]],"id":52385886},{"atl":[[65,9.38]],"id":52385886},{"atb":[[19,15]],"id":52385919},{"atl":[[38,15]],"id":52385919},{"atb":[[24,22]],"id":52385921},{"atl":[[60,10.17]],"id":52385921},{"atb":[[29,21.43]],"id":52385882},{"atl":[[70,8.7]],"id":52385882},{"atb":[[22,15]],"id":52385884},{"atl":[[50,12.24]],"id":52385884},{"atl":[[65,9.38]],"id":52385917},{"atb":[[22,15]],"id":52385897},{"atl":[[38,15]],"id":52385897},{"atb":[[16.5,15]],"id":52385891},{"atl":[[50,12.24]],"id":52385891},{"atb":[[27,15]],"id":52385893},{"atl":[[65,9.38]],"id":52385893},{"atl":[[30,15]],"id":52385903},{"atl":[[24,15]],"id":52385905},{"atb":[[20,15]],"id":52385899},{"atl":[[60,10.17]],"id":52385899}],"con":true,"img":false}]}
{"op":"mcm","clk":"11550469900","pt":1719498869179,"mc":[{"id":"1.230178170","rc":[{"atb":[[17.5,0]],"id":52385912},{"atl":[[550,0],[150,2]],"id":52385912},{"atl":[[100,2]],"id":52385906},{"atl":[[100,2]],"id":52385914},{"atl":[[420,0]],"id":52385896},{"atl":[[120,2]],"id":52385890},{"atb":[[16.5,0]],"id":52385892},{"atl":[[260,2]],"id":52385892},{"atl":[[90,2],[110,0],[460,0]],"id":52385904},{"atb":[[17.5,0]],"id":52385911},{"atb":[[18.5,0]],"id":52385886},{"atl":[[150,0],[120,2],[510,0]],"id":52385886},{"atl":[[95,2],[120,0],[480,0]],"id":52385919},{"atl":[[540,0],[140,2],[180,0]],"id":52385921},{"atl":[[90,7],[110,0]],"id":52385917},{"atl":[[90,2]],"id":52385891}],"con":true,"img":false}]}
{"op":"mcm","clk":"11550469910","pt":1719498869282,"mc":[{"id":"1.230178170","rc":[{"atb":[[15.5,0]],"id":52385910},{"atl":[[540,0],[140,2],[170,0]],"id":52385910},{"atl":[[190,0]],"id":52385912},{"atb":[[11.5,0]],"id":52385906},{"atl":[[130,0],[500,0]],"id":52385906},{"atb":[[16.5,0]],"id":52385918},{"atl":[[530,0],[140,2],[180,0]],"id":52385918},{"atl":[[65,7],[75,0],[410,0]],"id":52385920},{"atl":[[130,0],[100,2],[490,0]],"id":52385889},{"atb":[[11.5,0]],"id":52385914},{"atl":[[130,0],[500,0]],"id":52385914},{"atb":[[16.5,0]],"id":52385883},{"atl":[[520,0],[130,2],[170,0]],"id":52385883},{"atb":[[21,0]],"id":52385885},{"atl":[[270,2],[670,0],[340,0]],"id":52385885},{"atb":[[15.5,0]],"id":52385890},{"atl":[[150,0],[510,0]],"id":52385890},{"atl":[[330,0],[650,0]],"id":52385892},{"atb":[[11.5,0]],"id":52385904},{"atl":[[380,0],[50,2.04],[60,0]],"id":52385898},{"atl":[[70,7],[80,0],[420,0]],"id":52385900},{"atl":[[290,0],[630,0],[220,2]],"id":52385911},{"atb":[[12.5,0]],"id":52385913},{"atl":[[90,2],[120,0],[480,0]],"id":52385913},{"atl":[[370,0],[48,7.13],[55,0]],"id":52385907},{"atb":[[17.5,0]],"id":52385919},{"atb":[[12.5,2.5]],"id":52385921},{"atb":[[12.5,0]],"id":52385882},{"atl":[[560,0],[170,2],[220,0]],"id":52385882},{"atb":[[17.5,0]],"id":52385884},{"atl":[[95,2],[120,0],[480,0]],"id":52385884},{"atl":[[470,0]],"id":52385917},{"atb":[[11.5,0]],"id":52385897},{"atl":[[130,0],[100,2],[490,0]],"id":52385897},{"atb":[[13.5,0]],"id":52385891},{"atl":[[110,0],[470,0]],"id":52385891},{"atb":[[16.5,0]],"id":52385893},{"atl":[[140,0],[110,2],[500,0]],"id":52385893},{"atl":[[70,0],[400,0],[55,2]],"id":52385903},{"atl":[[75,0],[410,0],[60,2]],"id":52385905},{"atb":[[16.5,0]],"id":52385899},{"atl":[[530,0],[140,2],[170,0]],"id":52385899}],"con":true,"img":false}]}
{"op":"mcm","clk":"11550470026","pt":1719498870288,"mc":[{"id":"1.230178170","rc":[{"atb":[[18,0]],"id":52385892}],"con":true,"img":false}]}
{"op":"mcm","clk":"11550470041","pt":1719498870393,"mc":[{"id":"1.230178170","rc":[{"atb":[[20,6]],"id":52385892}],"con":true,"img":false}]}
{"op":"mcm","clk":"11550470187","pt":1719498871799,"mc":[{"id":"1.230178170","rc":[{"atb":[[10.5,3.87]],"id":52385906},{"atl":[[38,2.5]],"id":52385906},{"atb":[[11.5,19.2]],"id":52385898},{"atl":[[25,2.5]],"id":52385898},{"atb":[[13.5,5.18]],"id":52385913},{"atb":[[10.5,5.25]],"id":52385905},{"atl":[[23,3.12]],"id":52385905}],"con":true,"img":false}]}
{"op":"mcm","clk":"11550470433","pt":1719498874385,"mc":[{"id":"1.230178170","rc":[{"atb":[[17,0]],"id":52385912}],"con":true,"img":false}]}
{"op":"mcm","clk":"11550470447","pt":1719498874470,"mc":[{"id":"1.230178170","rc":[{"atb":[[19,5]],"id":52385912}],"con":true,"img":false}]}
{"op":"mcm","clk":"11550471198","pt":1719498883286,"mc":[{"id":"1.230178170","rc":[{"atb":[[13,0]],"id":52385920},{"atb":[[14,0]],"id":52385921}],"con":true,"img":false}]}
{"op":"mcm","clk":"11550471204","pt":1719498883394,"mc":[{"id":"1.230178170","rc":[{"atb":[[15,6]],"id":52385920},{"atb":[[16,6]],"id":52385921}],"con":true,"img":false}]}
{"op":"mcm","clk":"11550471212","pt":1719498883516,"mc":[{"id":"1.230178170","rc":[{"atb":[[13.5,0],[15,32]],"id":52385920}],"con":true,"img":false}]}
{"op":"mcm","clk":"11550471231","pt":1719498883693,"mc":[{"id":"1.230178170","rc":[{"atl":[[38,18.72]],"id":52385906},{"atl":[[30,19]],"id":52385920},{"atl":[[36,17.14]],"id":52385896},{"atl":[[24,21]],"id":52385898},{"atl":[[34,18.18]],"id":52385900},{"atb":[[28,22.22]],"id":52385911},{"atl":[[25,19.26]],"id":52385907},{"atl":[[23,25.62]],"id":52385905}],"con":true,"img":false}]}
{"op":"mcm","clk":"11550471242","pt":1719498883795,"mc":[{"id":"1.230178170","rc":[{"atl":[[65,2]],"id":52385896}],"con":true,"img":false}]}
{"op":"mcm","clk":"11550471252","pt":1719498883900,"mc":[{"id":"1.230178170","rc":[{"atl":[[48,0]],"id":52385906},{"atl":[[32,0]],"id":52385920},{"atl":[[38,0],[80,0]],"id":52385896},{"atl":[[26,0]],"id":52385898},{"atl":[[36,0]],"id":52385900},{"atb":[[27,0]],"id":52385911},{"atl":[[26,0]],"id":52385907},{"atl":[[24,0]],"id":52385905}],"con":true,"img":false}]}
{"op":"mcm","clk":"11550471397","pt":1719498885915,"mc":[{"id":"1.230178170","rc":[{"atl":[[32,1]],"id":52385883}],"con":true,"img":false}]}
{"op":"mcm","clk":"11550472440","pt":1719498898805,"mc":[{"id":"1.230178170","rc":[{"atb":[[11.5,15]],"id":52385898},{"atl":[[25,0]],"id":52385898}],"con":true,"img":false}]}
{"op":"mcm","clk":"11550472457","pt":1719498899014,"mc":[{"id":"1.230178170","rc":[{"atb":[[12,5.03]],"id":52385898},{"atl":[[24,0],[29,3.9]],"id":52385898},{"atl":[[46,5.4]],"id":52385913}],"con":true,"img":false}]}
{"op":"mcm","clk":"11550472468","pt":1719498899109,"mc":[{"id":"1.230178170","rc":[{"atb":[[12,25.09]],"id":52385898},{"atl":[[25,25]],"id":52385898}],"con":true,"img":false}]}
{"op":"mcm","clk":"11550472487","pt":1719498899315,"mc":[{"id":"1.230178170","rc":[{"atb":[[11.5,0]],"id":52385898}],"con":true,"img":false}]}
{"op":"mcm","clk":"11550472548","pt":1719498900091,"mc":[{"id":"1.230178170","rc":[{"atl":[[36,1]],"id":52385884}],"con":true,"img":false}]}
{"op":"mcm","clk":"11550472561","pt":1719498900204,"mc":[{"id":"1.230178170","rc":[{"atl":[[36,16]],"id":52385884}],"con":true,"img":false}]}
{"op":"mcm","clk":"11550472577","pt":1719498900414,"mc":[{"id":"1.230178170","rc":[{"atl":[[50,0]],"id":52385884}],"con":true,"img":false}]}
{"op":"mcm","clk":"11550472902","pt":1719498904086,"mc":[{"id":"1.230178170","rc":[{"atl":[[34,0]],"id":52385900}],"con":true,"img":false}]}
{"op":"mcm","clk":"11550472911","pt":1719498904189,"mc":[{"id":"1.230178170","rc":[{"atl":[[36,17.14]],"id":52385900}],"con":true,"img":false}]}
{"op":"mcm","clk":"11550472950","pt":1719498904609,"mc":[{"id":"1.230178170","rc":[{"atl":[[38,0]],"id":52385919}],"con":true,"img":false}]}
{"op":"mcm","clk":"11550472962","pt":1719498904711,"mc":[{"id":"1.230178170","rc":[{"atl":[[40,15.38]],"id":52385919}],"con":true,"img":false}]}
{"op":"mcm","clk":"11550473287","pt":1719498908091,"mc":[{"id":"1.230178170","rc":[{"atb":[[21,0]],"id":52385904}],"con":true,"img":false}]}
{"op":"mcm","clk":"11550473298","pt":1719498908185,"mc":[{"id":"1.230178170","rc":[{"atb":[[20,27]],"id":52385904}],"con":true,"img":false}]}
{"op":"mcm","clk":"11550473321","pt":1719498908495,"mc":[{"id":"1.230178170","rc":[{"atb":[[20,0]],"id":52385906}],"con":true,"img":false}]}
{"op":"mcm","clk":"11550473328","pt":1719498908599,"mc":[{"id":"1.230178170","rc":[{"atb":[[19.5,17.74]],"id":52385906}],"con":true,"img":false}]}
{"op":"mcm","clk":"11550473592","pt":1719498912009,"mc":[{"id":"1.230178170","rc":[{"atb":[[19.5,0]],"id":52385906},{"atb":[[20,0]],"id":52385904}],"con":true,"img":false}]}
{"op":"mcm","clk":"11550473607","pt":1719498912111,"mc":[{"id":"1.230178170","rc":[{"atb":[[18.5,22]],"id":52385906},{"atb":[[19.5,27]],"id":52385904},{"atb":[[14,22.5]],"id":52385905}],"con":true,"img":false}]}
{"op":"mcm","clk":"11550473624","pt":1719498912318,"mc":[{"id":"1.230178170","rc":[{"atb":[[12.5,0]],"id":52385905}],"con":true,"img":false}]}
{"op":"mcm","clk":"11550473633","pt":1719498912421,"mc":[{"id":"1.230178170","rc":[{"atl":[[36,0]],"id":52385896}],"con":true,"img":false}]}
{"op":"mcm","clk":"11550473642","pt":1719498912525,"mc":[{"id":"1.230178170","rc":[{"atl":[[75,7],[38,15]],"id":52385896}],"con":true,"img":false}]}
{"op":"mcm","clk":"11550473654","pt":1719498912730,"mc":[{"id":"1.230178170","rc":[{"atl":[[65,0]],"id":52385896}],"con":true,"img":false}]}
{"op":"mcm","clk":"11550473664","pt":1719498912789,"mc":[{"id":"1.230178170","rc":[{"atl":[[65,2],[75,5]],"id":52385896}],"con":true,"img":false}]}
{"op":"mcm","clk":"11550473697","pt":1719498913299,"mc":[{"id":"1.230178170","rc":[{"atb":[[17,0]],"id":52385884},{"atb":[[17,0],[1.17,0]],"id":52385917},{"atb":[[12,0]],"id":52385903}],"con":true,"img":false}]}
{"op":"mcm","clk":"11550473703","pt":1719498913400,"mc":[{"id":"1.230178170","rc":[{"atb":[[16.5,5],[18.5,2.5],[10.5,0],[12.5,0]],"id":52385910},{"atb":[[10.5,0],[13,5],[15,2.5],[9.4,0]],"id":52385912},{"atl":[[65,2],[44,2.5],[48,0],[55,5]],"id":52385920},{"atl":[[65,11.88],[70,0],[85,5],[90,0]],"id":52385889},{"atb":[[9.6,0],[11,0],[11.5,5],[13.5,2.5]],"id":52385914},{"atb":[[17.5,2.5],[12.5,0],[14.5,0],[15.5,5]],"id":52385885},{"atl":[[65,0],[80,5],[85,0],[60,12.67]],"id":52385890},{"atb":[[16.5,5],[18.5,2.5]],"id":52385892},{"atb":[[8,0],[7.2,0],[8.2,2.5],[7.4,5]],"id":52385898},{"atl":[[70,2],[50,0]],"id":52385900},{"atb":[[10.5,0],[12.5,13.7],[14.5,2.5],[9.4,0]],"id":52385911},{"atl":[[32,2.5],[48,2.13]],"id":52385907},{"atb":[[16.5,2.5],[10.5,10.53],[12.5,0],[14.5,5]],"id":52385921},{"atb":[[19,5]],"id":52385884},{"atl":[[75,0],[46,2.5],[55,0],[60,5]],"id":52385884},{"atb":[[17.5,0],[19,6]],"id":52385917},{"atl":[[75,0],[46,2.5],[55,0],[60,5]],"id":52385891},{"atl":[[65,11.88],[70,0],[85,5],[90,0]],"id":52385893},{"atb":[[12.5,0],[13,6]],"id":52385903},{"atl":[[38,5],[40,0],[48,0],[30,17.5]],"id":52385903},{"atl":[[32,2.5],[34,0],[40,5],[42,0]],"id":52385905},{"atb":[[9.6,11.63],[11,0],[11.5,5],[13.5,2.5]],"id":52385899}],"con":true,"img":false}]}
{"op":"mcm","clk":"11550473711","pt":1719498913504,"mc":[{"id":"1.230178170","rc":[{"atb":[[16,0],[14,0]],"id":52385892},{"atl":[[34,2.5],[40,0],[42,5],[48,0]],"id":52385898},{"atl":[[65,5],[48,2.5]],"id":52385900},{"atb":[[9,0],[8.2,10],[11.5,2.5],[9.8,5]],"id":52385913},{"atb":[[19,23]],"id":52385917},{"atl":[[44,13.95]],"id":52385891},{"atb":[[13,21]],"id":52385903}],"con":true,"img":false}]}
{"op":"mcm","clk":"11550473718","pt":1719498913607,"mc":[{"id":"1.230178170","rc":[{"atl":[[44,2.5],[46,2.9],[55,5],[60,0]],"id":52385913},{"atl":[[50,0]],"id":52385891}],"con":true,"img":false}]}
{"op":"mcm","clk":"11550473739","pt":1719498913915,"mc":[{"id":"1.230178170","rc":[{"atl":[[36,0]],"id":52385900},{"atl":[[40,0]],"id":52385919}],"con":true,"img":false}]}
{"op":"mcm","clk":"11550473759","pt":1719498914225,"mc":[{"id":"1.230178170","rc":[{"atl":[[38,15]],"id":52385900},{"atl":[[42,14.63]],"id":52385919}],"con":true,"img":false}]}
{"op":"mcm","clk":"11550473781","pt":1719498914485,"mc":[{"id":"1.230178170","rc":[{"atb":[[19.5,0]],"id":52385904}],"con":true,"img":false}]}
{"op":"mcm","clk":"11550473786","pt":1719498914638,"mc":[{"id":"1.230178170","rc":[{"atb":[[18.5,27]],"id":52385904}],"con":true,"img":false}]}
{"op":"mcm","clk":"11550473932","pt":1719498916499,"mc":[{"id":"1.230178170","rc":[{"atl":[[23,1]],"id":52385896}],"con":true,"img":false}]}
{"op":"mcm","clk":"11550474054","pt":1719498918021,"mc":[{"id":"1.230178170","rc":[{"atl":[[140,0],[180,2]],"id":52385918},{"atl":[[130,2],[100,0]],"id":52385889},{"atl":[[270,0],[340,2]],"id":52385885},{"atl":[[260,0],[330,2]],"id":52385892},{"atl":[[280,2],[220,0]],"id":52385911},{"atl":[[90,5],[110,2]],"id":52385917},{"atl":[[90,0],[120,2]],"id":52385891}],"con":true,"img":false}]}
{"op":"mcm","clk":"11550474090","pt":1719498918539,"mc":[{"id":"1.230178170","rc":[{"atl":[[90,2.5],[120,5]],"id":52385912},{"atb":[[6.4,12]],"id":52385906},{"atl":[[34,2.5],[42,5]],"id":52385906},{"atb":[[5,25],[9.4,0]],"id":52385918},{"atb":[[8.8,0]],"id":52385914},{"atb":[[3.45,17]],"id":52385883},{"atl":[[210,2]],"id":52385883},{"atb":[[16,6.67],[12.5,0]],"id":52385892},{"atb":[[5.8,0]],"id":52385898},{"atb":[[8.6,0],[7.8,0]],"id":52385900},{"atl":[[40,5.06]],"id":52385907},{"atl":[[70,0],[90,0]],"id":52385886},{"atb":[[7.8,0]],"id":52385919},{"atl":[[42,0],[95,0]],"id":52385919},{"atb":[[10.5,0]],"id":52385921},{"atl":[[140,0]],"id":52385921},{"atb":[[13.5,8]],"id":52385882},{"atb":[[16,0],[18,0]],"id":52385893}],"con":true,"img":false}]}
{"op":"mcm","clk":"11550474098","pt":1719498918644,"mc":[{"id":"1.230178170","rc":[{"atb":[[10,0],[5.3,23.26]],"id":52385910},{"atl":[[140,0],[200,2]],"id":52385910},{"atb":[[10,0]],"id":52385912},{"atl":[[65,0],[270,2],[150,0],[85,0],[55,0]],"id":52385912},{"atb":[[8,12],[18.5,0],[8.8,5]],"id":52385906},{"atl":[[70,2],[36,17.14],[50,0],[100,0]],"id":52385906},{"atb":[[5,0],[8.2,13.89]],"id":52385918},{"atb":[[10.5,0],[11.5,2.5],[9.4,0],[17,15],[5.1,24.39],[9.8,5],[5.7,0]],"id":52385920},{"atb":[[9.6,11.63],[18.5,34.29],[8.2,0]],"id":52385889},{"atb":[[4.9,25.64]],"id":52385914},{"atb":[[9.6,0],[6.6,17.86]],"id":52385883},{"atl":[[130,0],[75,2.5],[80,0],[160,2],[60,0]],"id":52385883},{"atb":[[16.5,6.45],[13.5,0]],"id":52385885},{"atb":[[6.4,0],[11.5,0],[13,5],[15,2.5],[1.69,144.93],[19.5,15],[9.8,0]],"id":52385896},{"atl":[[65,0],[110,2]],"id":52385896},{"atb":[[9.2,0],[7.6,12]],"id":52385890},{"atl":[[170,2],[120,0]],"id":52385890},{"atl":[[130,5],[140,0],[95,8.88],[100,0]],"id":52385892},{"atb":[[18.5,0],[9.2,2.5],[11,0],[7.4,0],[6,22],[13,6],[8.4,5]],"id":52385904},{"atl":[[34,18.18],[38,5],[42,0],[90,0],[50,0],[30,2.5],[60,2]],"id":52385904},{"atb":[[3.95,33.9],[14.5,23.8]],"id":52385898},{"atb":[[18.5,20],[6.4,0],[11,5],[13,2.5]],"id":52385900},{"atl":[[130,2],[70,0]],"id":52385900},{"atb":[[8.2,13.89],[12.5,5]],"id":52385911},{"atb":[[8.2,0],[9.6,10],[21,0]],"id":52385913},{"atb":[[12,6]],"id":52385907},{"atl":[[48,0]],"id":52385907},{"atb":[[3.7,11.72],[9.8,0],[26,20]],"id":52385886},{"atl":[[65,11.88],[85,5],[190,2],[120,0]],"id":52385886},{"atb":[[12.5,0],[14.5,0],[16,5],[18,2.5],[20,22]],"id":52385919},{"atl":[[190,2],[55,11.11]],"id":52385919},{"atb":[[7.2,12]],"id":52385921},{"atl":[[200,2]],"id":52385921},{"atb":[[10.5,0]],"id":52385882},{"atl":[[65,2.5],[75,0],[85,5],[95,0]],"id":52385882},{"atb":[[9.8,10],[7.8,0]],"id":52385884},{"atb":[[8,0],[17,2.5],[11.5,0],[2.44,69.44],[13.5,0],[15,5]],"id":52385917},{"atb":[[8.2,0],[3.35,42.55],[12.5,0],[13,5],[14.5,0],[15,8.5]],"id":52385897},{"atl":[[38,0],[160,2],[100,0]],"id":52385897},{"atb":[[8,0],[18,22],[6.6,12]],"id":52385891},{"atb":[[17,5],[19,2.5],[10.5,10.53],[8.8,0]],"id":52385893},{"atl":[[150,2],[110,0]],"id":52385893},{"atb":[[5.3,23.26],[6,2],[13,6]],"id":52385903},{"atb":[[6,2],[14,0],[7,16.67]],"id":52385905},{"atb":[[9.6,0],[1.75,133.33]],"id":52385899},{"atl":[[65,0],[140,0],[85,0],[90,2.5],[120,5],[250,2]],"id":52385899}],"con":true,"img":false}]}
{"op":"mcm","clk":"11550474106","pt":1719498918697,"mc":[{"id":"1.230178170","rc":[{"atb":[[6.4,0]],"id":52385906},{"atb":[[3.45,0]],"id":52385883},{"atl":[[210,0]],"id":52385883}],"con":true,"img":false}]}
{"op":"mcm","clk":"11550474117","pt":1719498918801,"mc":[{"id":"1.230178170","rc":[{"atb":[[5.3,0],[8.4,10]],"id":52385910},{"atl":[[150,2],[200,0]],"id":52385910},{"atl":[[270,0],[200,2],[110,5]],"id":52385912},{"atb":[[12.5,19.74]],"id":52385906},{"atb":[[18,0],[18.5,5],[20,0],[21,2.5]],"id":52385918},{"atb":[[17,0],[5.1,0],[6.6,17.86],[15,6]],"id":52385920},{"atb":[[7.4,11]],"id":52385914},{"atb":[[16,8],[19.5,0],[3.7,37.04],[1.69,0]],"id":52385896},{"atb":[[10,11],[7.6,0]],"id":52385890},{"atl":[[130,2],[170,0]],"id":52385890},{"atb":[[7.2,16.13],[6,2],[13,21]],"id":52385904},{"atl":[[40,0]],"id":52385904},{"atb":[[3.95,0],[12,5.03],[14.5,0],[5.4,22.73]],"id":52385898},{"atb":[[18.5,0],[14,7]],"id":52385900},{"atl":[[130,0],[95,2]],"id":52385900},{"atb":[[8.2,0],[12,9.09]],"id":52385911},{"atb":[[20,15.8]],"id":52385913},{"atb":[[6.2,8.5],[6.8,15.12],[5.7,0]],"id":52385907},{"atb":[[13,0],[15,0],[16,5],[18,2.5],[3.7,0],[24,0],[6.6,10]],"id":52385886},{"atl":[[140,2],[190,0]],"id":52385886},{"atb":[[19,0]],"id":52385919},{"atl":[[140,2],[190,0]],"id":52385919},{"atb":[[7.2,0],[10,11]],"id":52385921},{"atl":[[150,2],[200,0]],"id":52385921},{"atl":[[60,10.17]],"id":52385882},{"atb":[[2.44,0],[4.9,25.64]],"id":52385917},{"atb":[[3.35,0],[6,19]],"id":52385897},{"atl":[[70,8.7],[160,0],[120,2]],"id":52385897},{"atb":[[16.5,0],[8.2,12],[6.6,0]],"id":52385891},{"atl":[[150,0],[110,2]],"id":52385893},{"atb":[[8,20],[6.4,10],[5.3,0]],"id":52385903},{"atb":[[13.5,20.5]],"id":52385905},{"atl":[[190,2],[250,0]],"id":52385899}],"con":true,"img":false}]}
{"op":"mcm","clk":"11550474123","pt":1719498918908,"mc":[{"id":"1.230178170","rc":[{"atl":[[38,2.5]],"id":52385906},{"atb":[[15.5,0]],"id":52385889},{"atb":[[4.9,0]],"id":52385914},{"atb":[[11.5,17.86]],"id":52385898},{"atb":[[15,15]],"id":52385900},{"atl":[[60,0]],"id":52385899}],"con":true,"img":false}]}
{"op":"mcm","clk":"11550474131","pt":1719498919010,"mc":[{"id":"1.230178170","rc":[{"atb":[[14.5,15]],"id":52385920},{"atb":[[16,18]],"id":52385896},{"atl":[[70,0]],"id":52385882}],"con":true,"img":false}]}
{"op":"mcm","clk":"11550474139","pt":1719498919114,"mc":[{"id":"1.230178170","rc":[{"atl":[[65,9.38]],"id":52385899}],"con":true,"img":false}]}
{"op":"mcm","clk":"11550474146","pt":1719498919217,"mc":[{"id":"1.230178170","rc":[{"atl":[[38,0]],"id":52385900},{"atl":[[55,11.11]],"id":52385921}],"con":true,"img":false}]}
{"op":"mcm","clk":"11550474161","pt":1719498919321,"mc":[{"id":"1.230178170","rc":[{"atb":[[15,0]],"id":52385920},{"atb":[[13,15]],"id":52385904},{"atb":[[14,0]],"id":52385900},{"atl":[[44,13.95]],"id":52385900},{"atb":[[15,0]],"id":52385913},{"atb":[[12,0]],"id":52385905}],"con":true,"img":false}]}
{"op":"mcm","clk":"11550474168","pt":1719498919424,"mc":[{"id":"1.230178170","rc":[{"atb":[[14,6]],"id":52385920},{"atb":[[12,6]],"id":52385904},{"atb":[[16,7]],"id":52385900},{"atb":[[14,5]],"id":52385913},{"atl":[[60,0]],"id":52385921},{"atb":[[11,6]],"id":52385905}],"con":true,"img":false}]}
{"op":"mcm","clk":"11550474322","pt":1719498921639,"mc":[{"id":"1.230178170","rc":[{"atb":[[26,0]],"id":52385886}],"con":true,"img":false}]}
{"op":"mcm","clk":"11550474331","pt":1719498921695,"mc":[{"id":"1.230178170","rc":[{"atb":[[25,15]],"id":52385886}],"con":true,"img":false}]}
{"op":"mcm","clk":"11550474346","pt":1719498921901,"mc":[{"id":"1.230178170","rc":[{"atb":[[15,22]],"id":52385904}],"con":true,"img":false}]}
{"op":"mcm","clk":"11550474364","pt":1719498922109,"mc":[{"id":"1.230178170","rc":[{"atb":[[13,0]],"id":52385904}],"con":true,"img":false}]}
{"op":"mcm","clk":"11550474383","pt":1719498922314,"mc":[{"id":"1.230178170","rc":[{"atb":[[17,19.74],[12,0]],"id":52385906},{"atb":[[17,0]],"id":52385919}],"con":true,"img":false}]}
{"op":"mcm","clk":"11550474391","pt":1719498922415,"mc":[{"id":"1.230178170","rc":[{"atb":[[11,6]],"id":52385906},{"atb":[[19,6]],"id":52385919}],"con":true,"img":false}]}
{"op":"mcm","clk":"11550474399","pt":1719498922518,"mc":[{"id":"1.230178170","rc":[{"atb":[[12.5,0]],"id":52385906}],"con":true,"img":false}]}
{"op":"mcm","clk":"11550474465","pt":1719498923406,"mc":[{"id":"1.230178170","rc":[{"atb":[[13,0]],"id":52385903}],"con":true,"img":false}]}
{"op":"mcm","clk":"11550474476","pt":1719498923505,"mc":[{"id":"1.230178170","rc":[{"atb":[[12,6]],"id":52385903}],"con":true,"img":false}]}
{"op":"mcm","clk":"11550474492","pt":1719498923708,"mc":[{"id":"1.230178170","rc":[{"atb":[[9.6,10],[8.4,0]],"id":52385910},{"atl":[[85,2.5],[90,0],[110,10],[120,0]],"id":52385912},{"atb":[[8.2,0]],"id":52385918},{"atb":[[7.6,15.15],[6.6,0]],"id":52385883},{"atl":[[70,2.5],[90,5]],"id":52385883},{"atb":[[18,5.88]],"id":52385885},{"atb":[[3.7,0]],"id":52385896},{"atl":[[110,0]],"id":52385896},{"atb":[[8.6,5],[9.2,0],[8.4,0],[9.4,2.5]],"id":52385904},{"atl":[[80,0],[60,0]],"id":52385919},{"atl":[[140,2],[170,0]],"id":52385882},{"atb":[[4.9,0],[4.2,31.25]],"id":52385917},{"atl":[[46,2.22],[60,0]],"id":52385905},{"atb":[[2.58,63.29],[1.75,0]],"id":52385899},{"atl":[[85,2.5],[90,0],[110,5],[120,0]],"id":52385899}],"con":true,"img":false}]}
{"op":"mcm","clk":"11550474501","pt":1719498923817,"mc":[{"id":"1.230178170","rc":[{"atb":[[1.89,112.36]],"id":52385912},{"atb":[[6.2,18.89]],"id":52385918},{"atl":[[75,0]],"id":52385883},{"atb":[[4,33.33]],"id":52385896},{"atl":[[80,2]],"id":52385896},{"atl":[[75,2.5],[95,5]],"id":52385919}],"con":true,"img":false}]}
{"op":"mcm","clk":"11550474508","pt":1719498923914,"mc":[{"id":"1.230178170","rc":[{"atb":[[16.5,0]],"id":52385885},{"atl":[[55,0]],"id":52385919}],"con":true,"img":false}]}
{"op":"mcm","clk":"11550474514","pt":1719498924015,"mc":[{"id":"1.230178170","rc":[{"atl":[[70,8.7]],"id":52385919}],"con":true,"img":false}]}
{"op":"mcm","clk":"11550474533","pt":1719498924326,"mc":[{"id":"1.230178170","rc":[{"atl":[[250,2]],"id":52385885},{"atl":[[230,2]],"id":52385892},{"atl":[[230,2]],"id":52385911},{"atl":[[55,0]],"id":52385921},{"atl":[[75,2],[120,0]],"id":52385891}],"con":true,"img":false}]}
{"op":"mcm","clk":"11550474539","pt":1719498924430,"mc":[{"id":"1.230178170","rc":[{"atl":[[340,0]],"id":52385885},{"atl":[[330,0]],"id":52385892},{"atl":[[280,0]],"id":52385911},{"atl":[[60,10.17]],"id":52385921}],"con":true,"img":false}]}
{"op":"mcm","clk":"11550474654","pt":1719498925824,"mc":[{"id":"1.230178170","rc":[{"atl":[[38,0]],"id":52385906},{"atl":[[29,0]],"id":52385898},{"atl":[[23,22.5]],"id":52385905}],"con":true,"img":false}]}
{"op":"mcm","clk":"11550474664","pt":1719498925926,"mc":[{"id":"1.230178170","rc":[{"atl":[[34,5.8]],"id":52385906},{"atb":[[10,4.4]],"id":52385904},{"atl":[[30,5.5]],"id":52385904},{"atl":[[34,5.5]],"id":52385898},{"atb":[[14,3.47]],"id":52385882},{"atl":[[55,2.15]],"id":52385882},{"atb":[[17,4.63]],"id":52385884},{"atb":[[18.5,4]],"id":52385891},{"atl":[[42,2.8]],"id":52385891},{"atb":[[12.5,5.24]],"id":52385903},{"atl":[[29,3.19]],"id":52385903},{"atl":[[32,5.53]],"id":52385905}],"con":true,"img":false}]}
{"op":"mcm","clk":"11550474678","pt":1719498926133,"mc":[{"id":"1.230178170","rc":[{"atl":[[40,2.56],[55,0],[28,22.22]],"id":52385903}],"con":true,"img":false}]}
{"op":"mcm","clk":"11550474695","pt":1719498926338,"mc":[{"id":"1.230178170","rc":[{"atl":[[30,2.5]],"id":52385903}],"con":true,"img":false}]}
{"op":"mcm","clk":"11550474758","pt":1719498927109,"mc":[{"id":"1.230178170","rc":[{"atl":[[40,15.38]],"id":52385891}],"con":true,"img":false}]}
{"op":"mcm","clk":"11550474765","pt":1719498927218,"mc":[{"id":"1.230178170","rc":[{"atb":[[24,20]],"id":52385917}],"con":true,"img":false}]}
{"op":"mcm","clk":"11550474780","pt":1719498927420,"mc":[{"id":"1.230178170","rc":[{"atb":[[19,6]],"id":52385917},{"atl":[[44,0]],"id":52385891}],"con":true,"img":false}]}
{"op":"mcm","clk":"11550474821","pt":1719498927935,"mc":[{"id":"1.230178170","rc":[{"atl":[[42,14.63]],"id":52385900}],"con":true,"img":false}]}
{"op":"mcm","clk":"11550474838","pt":1719498928140,"mc":[{"id":"1.230178170","rc":[{"atl":[[44,0]],"id":52385900}],"con":true,"img":false}]}
{"op":"mcm","clk":"11550474893","pt":1719498928818,"mc":[{"id":"1.230178170","rc":[{"atb":[[1.33,120.05]],"id":52385912},{"atl":[[150,5],[160,0],[110,8],[120,0]],"id":52385885},{"atb":[[4,0],[3.5,10]],"id":52385896},{"atb":[[22,0]],"id":52385884},{"atb":[[5,25],[6,2]],"id":52385897},{"atb":[[1.14,156.96],[2.58,0]],"id":52385899}],"con":true,"img":false}]}
{"op":"mcm","clk":"11550474903","pt":1719498928919,"mc":[{"id":"1.230178170","rc":[{"atb":[[1.89,0]],"id":52385912}],"con":true,"img":false}]}
{"op":"mcm","clk":"11550474909","pt":1719498929020,"mc":[{"id":"1.230178170","rc":[{"atb":[[17.5,19.26]],"id":52385884}],"con":true,"img":false}]}
{"op":"mcm","clk":"11550475141","pt":1719498932226,"mc":[{"id":"1.230178170","rc":[{"atl":[[27,23.08]],"id":52385906},{"atb":[[16.5,22]],"id":52385920},{"atb":[[21,15]],"id":52385896},{"atl":[[29,21.43]],"id":52385904},{"atb":[[14,27]],"id":52385898},{"atb":[[19.5,19]],"id":52385900},{"atb":[[26,20]],"id":52385886},{"atb":[[18.5,24]],"id":52385891}],"con":true,"img":false}]}
{"op":"mcm","clk":"11550475157","pt":1719498932432,"mc":[{"id":"1.230178170","rc":[{"atl":[[70,8.7]],"id":52385912},{"atl":[[36,0]],"id":52385906},{"atb":[[14.5,0]],"id":52385920},{"atb":[[16,8]],"id":52385896},{"atl":[[34,0]],"id":52385904},{"atb":[[11.5,0]],"id":52385898},{"atb":[[15,0]],"id":52385900},{"atb":[[25,0]],"id":52385886},{"atl":[[55,13.26]],"id":52385882},{"atl":[[50,12.24]],"id":52385897},{"atb":[[18,0]],"id":52385891},{"atl":[[38,7.7],[40,0]],"id":52385903}],"con":true,"img":false}]}
{"op":"mcm","clk":"11550475163","pt":1719498932535,"mc":[{"id":"1.230178170","rc":[{"atb":[[20,31.58]],"id":52385900},{"atb":[[21,22]],"id":52385919}],"con":true,"img":false}]}
{"op":"mcm","clk":"11550475172","pt":1719498932639,"mc":[{"id":"1.230178170","rc":[{"atl":[[110,5]],"id":52385912},{"atb":[[26,0]],"id":52385886},{"atl":[[60,0]],"id":52385882},{"atl":[[70,0]],"id":52385897}],"con":true,"img":false}]}
{"op":"mcm","clk":"11550475181","pt":1719498932740,"mc":[{"id":"1.230178170","rc":[{"atl":[[21,1]],"id":52385898},{"atb":[[19.5,0]],"id":52385900},{"atb":[[26,20]],"id":52385886},{"atb":[[20,0]],"id":52385919}],"con":true,"img":false}]}
{"op":"mcm","clk":"11550475188","pt":1719498932844,"mc":[{"id":"1.230178170","rc":[{"atl":[[55,11.11]],"id":52385921}],"con":true,"img":false}]}
{"op":"mcm","clk":"11550475201","pt":1719498933052,"mc":[{"id":"1.230178170","rc":[{"atl":[[60,0]],"id":52385921}],"con":true,"img":false}]}
{"op":"mcm","clk":"11550475210","pt":1719498933157,"mc":[{"id":"1.230178170","rc":[{"atb":[[25,3.75]],"id":52385886}],"con":true,"img":false}]}
{"op":"mcm","clk":"11550475249","pt":1719498933519,"mc":[{"id":"1.230178170","rc":[{"atb":[[25,0]],"id":52385886}],"con":true,"img":false}]}
{"op":"mcm","clk":"11550475268","pt":1719498933725,"mc":[{"id":"1.230178170","rc":[{"atb":[[26,0]],"id":52385886}],"con":true,"img":false}]}
{"op":"mcm","clk":"11550475279","pt":1719498933826,"mc":[{"id":"1.230178170","rc":[{"atb":[[25,20]],"id":52385886}],"con":true,"img":false}]}
{"op":"mcm","clk":"11550475391","pt":1719498935427,"mc":[{"id":"1.230178170","rc":[{"atb":[[29,0]],"id":52385882}],"con":true,"img":false}]}
{"op":"mcm","clk":"11550475394","pt":1719498935526,"mc":[{"id":"1.230178170","rc":[{"atb":[[13,8.33],[13.5,0],[29,21.43]],"id":52385882}],"con":true,"img":false}]}
{"op":"mcm","clk":"11550475411","pt":1719498935734,"mc":[{"id":"1.230178170","rc":[{"atb":[[7.6,10]],"id":52385918},{"atl":[[70,11.2],[90,5]],"id":52385919},{"atb":[[5.1,24.39],[4.2,0]],"id":52385917}],"con":true,"img":false}]}
{"op":"mcm","clk":"11550475423","pt":1719498935836,"mc":[{"id":"1.230178170","rc":[{"atb":[[1.33,0]],"id":52385912},{"atb":[[6.2,0]],"id":52385918},{"atl":[[75,0],[95,0]],"id":52385919},{"atb":[[1.14,0]],"id":52385899}],"con":true,"img":false}]}
{"op":"mcm","clk":"11550475606","pt":1719498938117,"mc":[{"id":"1.230178170","rc":[{"atb":[[16,0],[16.5,2.5],[14,0],[14.5,5]],"id":52385890}],"con":true,"img":false}]}
{"op":"mcm","clk":"11550475839","pt":1719498940832,"mc":[{"id":"1.230178170","rc":[{"atb":[[1.74,120.05]],"id":52385912},{"atb":[[8.6,11],[7.4,0]],"id":52385914},{"atb":[[6.4,18.52],[7.6,0]],"id":52385883},{"atb":[[3,50],[3.5,0]],"id":52385896},{"atb":[[8.6,12],[10,0]],"id":52385890},{"atb":[[4.6,27.78],[5.4,0]],"id":52385898},{"atl":[[30,20.36]],"id":52385913},{"atb":[[5,0],[3.95,33.9]],"id":52385897}],"con":true,"img":false}]}
{"op":"mcm","clk":"11550475860","pt":1719498941035,"mc":[{"id":"1.230178170","rc":[{"atl":[[34,0]],"id":52385913}],"con":true,"img":false}]}
{"op":"mcm","clk":"11550476025","pt":1719498942341,"mc":[{"id":"1.230178170","rc":[{"atb":[[22,20]],"id":52385884}],"con":true,"img":false}]}
{"op":"mcm","clk":"11550476052","pt":1719498942550,"mc":[{"id":"1.230178170","rc":[{"atb":[[26,20]],"id":52385886},{"atb":[[17.5,0]],"id":52385884}],"con":true,"img":false}]}
{"op":"mcm","clk":"11550476077","pt":1719498942755,"mc":[{"id":"1.230178170","rc":[{"atb":[[25,0]],"id":52385886}],"con":true,"img":false}]}
{"op":"mcm","clk":"11550476140","pt":1719498943231,"mc":[{"id":"1.230178170","rc":[{"atb":[[18,2.5]],"id":52385883},{"atb":[[12,0]],"id":52385904},{"atb":[[26,0]],"id":52385886}],"con":true,"img":false}]}
{"op":"mcm","clk":"11550476152","pt":1719498943333,"mc":[{"id":"1.230178170","rc":[{"atb":[[20,6]],"id":52385883},{"atb":[[13,6]],"id":52385904},{"atb":[[25,20]],"id":52385886}],"con":true,"img":false}]}
{"op":"mcm","clk":"11550476207","pt":1719498943847,"mc":[{"id":"1.230178170","rc":[{"atl":[[65,11.88],[70,0],[85,5],[90,0]],"id":52385917}],"con":true,"img":false}]}
{"op":"mcm","clk":"11550476385","pt":1719498945968,"mc":[{"id":"1.230178170","rc":[{"atb":[[1.74,0]],"id":52385912},{"atb":[[9,10],[7.6,0]],"id":52385918},{"atb":[[3,0],[2.6,62.5]],"id":52385896},{"atb":[[7.4,12]],"id":52385890},{"atb":[[17,27]],"id":52385898},{"atl":[[30,0]],"id":52385913},{"atb":[[8,10],[6.6,0]],"id":52385886},{"atb":[[5.1,0],[6.2,11]],"id":52385917},{"atb":[[3.95,0],[3.3,43.48]],"id":52385897},{"atl":[[70,2.5],[75,0],[90,5],[55,0]],"id":52385897},{"atl":[[65,0]],"id":52385899}],"con":true,"img":false}]}
{"op":"mcm","clk":"11550476396","pt":1719498946080,"mc":[{"id":"1.230178170","rc":[{"atb":[[9.6,0],[11.5,9.52]],"id":52385910},{"atb":[[9,0],[7.8,10]],"id":52385918},{"atb":[[6.4,0],[10,11]],"id":52385883},{"atb":[[2.6,0],[3.5,40]],"id":52385896},{"atb":[[8.6,0]],"id":52385890},{"atb":[[3.85,35.09],[4.6,0],[14,0]],"id":52385898},{"atl":[[80,2],[44,16.45],[90,0]],"id":52385913},{"atb":[[8,0],[12,9.09]],"id":52385886},{"atb":[[7.4,11]],"id":52385917},{"atb":[[2.5,66.67],[3.3,0]],"id":52385897},{"atl":[[80,7.59]],"id":52385899}],"con":true,"img":false}]}
{"op":"mcm","clk":"11550476409","pt":1719498946132,"mc":[{"id":"1.230178170","rc":[{"atb":[[6.2,0]],"id":52385917},{"atl":[[50,0]],"id":52385897}],"con":true,"img":false}]}
{"op":"mcm","clk":"11550476421","pt":1719498946237,"mc":[{"id":"1.230178170","rc":[{"atb":[[11,0]],"id":52385898},{"atl":[[65,9.38]],"id":52385897}],"con":true,"img":false}]}
{"op":"mcm","clk":"11550476859","pt":1719498949558,"mc":[{"id":"1.230178170","rc":[{"atl":[[16.5,1]],"id":52385903}],"con":true,"img":false}]}
{"op":"mcm","clk":"11550477073","pt":1719498951156,"mc":[{"id":"1.230178170","rc":[{"atl":[[150,2],[180,0]],"id":52385918},{"atb":[[16.5,0]],"id":52385920},{"atb":[[3.2,13],[3.5,0]],"id":52385896},{"atl":[[50,12.24]],"id":52385921},{"atb":[[2.5,0],[2.04,96.15]],"id":52385897}],"con":true,"img":false}]}
{"op":"mcm","clk":"11550477080","pt":1719498951257,"mc":[{"id":"1.230178170","rc":[{"atb":[[16,22]],"id":52385920},{"atl":[[55,0]],"id":52385921}],"con":true,"img":false}]}
{"op":"mcm","clk":"11550477222","pt":1719498952255,"mc":[{"id":"1.230178170","rc":[{"atb":[[18,0]],"id":52385910},{"atb":[[11,0]],"id":52385906},{"atb":[[14,0]],"id":52385914},{"atb":[[14,0]],"id":52385913}],"con":true,"img":false}]}
{"op":"mcm","clk":"11550477234","pt":1719498952353,"mc":[{"id":"1.230178170","rc":[{"atb":[[20,5]],"id":52385910},{"atb":[[12,6]],"id":52385906},{"atb":[[16,6]],"id":52385914},{"atb":[[16,5]],"id":52385913}],"con":true,"img":false}]}
{"op":"mcm","clk":"11550477297","pt":1719498952872,"mc":[{"id":"1.230178170","rc":[{"atl":[[34,2.5]],"id":52385906},{"atl":[[30,2.5]],"id":52385904},{"atb":[[12,0]],"id":52385898},{"atl":[[46,0]],"id":52385913},{"atl":[[42,0]],"id":52385891},{"atb":[[12.5,0]],"id":52385903},{"atl":[[29,0]],"id":52385903},{"atl":[[32,2.5]],"id":52385905}],"con":true,"img":false}]}
{"op":"mcm","clk":"11550477311","pt":1719498952979,"mc":[{"id":"1.230178170","rc":[{"atl":[[40,0]],"id":52385891}],"con":true,"img":false}]}
{"op":"mcm","clk":"11550477321","pt":1719498953035,"mc":[{"id":"1.230178170","rc":[{"atb":[[18.5,5.28]],"id":52385910},{"atl":[[55,2.6]],"id":52385910},{"atb":[[17.5,5]],"id":52385912},{"atl":[[60,2]],"id":52385912},{"atl":[[26,2.5]],"id":52385906},{"atb":[[27,2.7]],"id":52385918},{"atb":[[16.5,4.7]],"id":52385920},{"atb":[[13.5,6]],"id":52385889},{"atl":[[60,2.3]],"id":52385889},{"atb":[[14.5,3.26]],"id":52385914},{"atb":[[18.5,3.3]],"id":52385883},{"atl":[[50,2.4]],"id":52385883},{"atb":[[15.5,4.6]],"id":52385896},{"atb":[[18,4.7]],"id":52385890},{"atl":[[55,2.51]],"id":52385890},{"atb":[[19,3.3]],"id":52385892},{"atl":[[80,2]],"id":52385892},{"atl":[[28,3.22]],"id":52385904},{"atb":[[10,4.2]],"id":52385898},{"atb":[[21,4.6]],"id":52385900},{"atb":[[18,4.6]],"id":52385911},{"atl":[[70,2]],"id":52385911},{"atl":[[42,3]],"id":52385913},{"atb":[[12.5,4.31]],"id":52385907},{"atb":[[26,3]],"id":52385886},{"atb":[[22,2.68]],"id":52385919},{"atb":[[25,4]],"id":52385921},{"atb":[[25,3]],"id":52385917},{"atb":[[13.5,4.59]],"id":52385897},{"atl":[[60,2.63]],"id":52385897},{"atl":[[38,3.11],[42,14.63]],"id":52385891},{"atb":[[28,3.7]],"id":52385893},{"atb":[[10,4.8]],"id":52385903},{"atl":[[27,4]],"id":52385903},{"atl":[[22,2.67]],"id":52385905},{"atb":[[14,3.86]],"id":52385899},{"atl":[[55,2]],"id":52385899}],"con":true,"img":false}]}
{"op":"mcm","clk":"11550477346","pt":1719498953247,"mc":[{"id":"1.230178170","rc":[{"atl":[[55,13.71]],"id":52385910},{"atl":[[60,6]],"id":52385912},{"atl":[[26,22.24]],"id":52385906},{"atb":[[28,15.4]],"id":52385918},{"atl":[[130,0],[85,7],[55,11.11]],"id":52385889},{"atl":[[55,13.62]],"id":52385890},{"atl":[[80,9.59]],"id":52385892},{"atl":[[27,20.8]],"id":52385904},{"atb":[[22,24]],"id":52385900},{"atl":[[70,9.53]],"id":52385911},{"atb":[[27,20]],"id":52385886},{"atb":[[23,22]],"id":52385919},{"atb":[[26,18]],"id":52385921},{"atb":[[25,25]],"id":52385917},{"atb":[[28,25.7]],"id":52385893},{"atl":[[22,25.17]],"id":52385905}],"con":true,"img":false}]}
{"op":"mcm","clk":"11550477370","pt":1719498953450,"mc":[{"id":"1.230178170","rc":[{"atl":[[60,0]],"id":52385910},{"atl":[[70,0]],"id":52385912},{"atl":[[27,0]],"id":52385906},{"atb":[[26,0]],"id":52385918},{"atl":[[65,2.49]],"id":52385889},{"atl":[[60,2.5]],"id":52385890},{"atl":[[95,2.5]],"id":52385892},{"atl":[[29,0]],"id":52385904},{"atb":[[20,0]],"id":52385900},{"atl":[[85,0]],"id":52385911},{"atb":[[25,0]],"id":52385886},{"atb":[[21,0]],"id":52385919},{"atb":[[24,0]],"id":52385921},{"atb":[[24,0]],"id":52385917},{"atb":[[27,0]],"id":52385893},{"atl":[[23,0]],"id":52385905}],"con":true,"img":false}]}
{"op":"mcm","clk":"11550477424","pt":1719498953963,"mc":[{"id":"1.230178170","rc":[{"atl":[[30,20.36]],"id":52385913}],"con":true,"img":false}]}
{"op":"mcm","clk":"11550477444","pt":1719498954128,"mc":[{"id":"1.230178170","rc":[{"atl":[[44,2.5]],"id":52385913}],"con":true,"img":false}]}
{"op":"mcm","clk":"11550477465","pt":1719498954332,"mc":[{"id":"1.230178170","rc":[{"atb":[[16,0]],"id":52385921}],"con":true,"img":false}]}
{"op":"mcm","clk":"11550477604","pt":1719498955673,"mc":[{"id":"1.230178170","rc":[{"atb":[[9.6,0],[9.8,2.5],[8.8,0]],"id":52385906}],"con":true,"img":false}]}
{"op":"mcm","clk":"11550477665","pt":1719498956248,"mc":[{"id":"1.230178170","rc":[{"atl":[[44,13.95]],"id":52385914}],"con":true,"img":false}]}
{"op":"mcm","clk":"11550477674","pt":1719498956353,"mc":[{"id":"1.230178170","rc":[{"atb":[[1.09,156.96]],"id":52385912},{"atb":[[3.6,13],[3.2,0]],"id":52385896},{"atb":[[5.3,23.26],[7.4,0]],"id":52385890},{"atl":[[70,2.5],[80,0],[90,5],[60,0]],"id":52385890},{"atb":[[22,0]],"id":52385884},{"atb":[[2.04,0]],"id":52385897},{"atb":[[19.5,18.22]],"id":52385891},{"atb":[[10.5,0],[8.4,12]],"id":52385893},{"atb":[[14.5,22.5]],"id":52385905}],"con":true,"img":false}]}
{"op":"mcm","clk":"11550477686","pt":1719498956451,"mc":[{"id":"1.230178170","rc":[{"atl":[[46,0]],"id":52385914},{"atb":[[15,0]],"id":52385904}],"con":true,"img":false}]}
{"op":"mcm","clk":"11550477695","pt":1719498956554,"mc":[{"id":"1.230178170","rc":[{"atb":[[14.5,15.24]],"id":52385904},{"atb":[[17,23.89]],"id":52385884},{"atb":[[18.5,4],[19.5,0]],"id":52385891},{"atb":[[13.5,0],[14.5,0]],"id":52385905}],"con":true,"img":false}]}
{"op":"mcm","clk":"11550477721","pt":1719498956764,"mc":[{"id":"1.230178170","rc":[{"atb":[[19,14.22]],"id":52385891},{"atb":[[14,15]],"id":52385905}],"con":true,"img":false}]}
{"op":"mcm","clk":"11550477919","pt":1719498958369,"mc":[{"id":"1.230178170","rc":[{"atb":[[13,0]],"id":52385904},{"atb":[[12,0]],"id":52385907},{"atb":[[11,0]],"id":52385905}],"con":true,"img":false}]}
{"op":"mcm","clk":"11550477933","pt":1719498958474,"mc":[{"id":"1.230178170","rc":[{"atb":[[14,6]],"id":52385904},{"atb":[[13,6]],"id":52385907},{"atb":[[12,6]],"id":52385905}],"con":true,"img":false}]}
{"op":"mcm","clk":"11550478012","pt":1719498959048,"mc":[{"id":"1.230178170","rc":[{"atl":[[29,20.36]],"id":52385913},{"atl":[[55,2.2]],"id":52385899}],"con":true,"img":false}]}
{"op":"mcm","clk":"11550478038","pt":1719498959255,"mc":[{"id":"1.230178170","rc":[{"atl":[[30,0]],"id":52385913},{"atl":[[55,11.11]],"id":52385897},{"atl":[[80,0]],"id":52385899}],"con":true,"img":false}]}
{"op":"mcm","clk":"11550478054","pt":1719498959362,"mc":[{"id":"1.230178170","rc":[{"atl":[[65,0]],"id":52385897}],"con":true,"img":false}]}
{"op":"mcm","clk":"11550478280","pt":1719498961375,"mc":[{"id":"1.230178170","rc":[{"atb":[[3.2,10]],"id":52385896},{"atb":[[4.7,27.03]],"id":52385890},{"atb":[[3.35,42.55]],"id":52385898}],"con":true,"img":false}]}
{"op":"mcm","clk":"11550478292","pt":1719498961478,"mc":[{"id":"1.230178170","rc":[{"atb":[[1.09,0]],"id":52385912},{"atb":[[3.6,0]],"id":52385896},{"atb":[[5.3,0]],"id":52385890},{"atb":[[3.85,0]],"id":52385898},{"atl":[[29,0]],"id":52385913}],"con":true,"img":false}]}
{"op":"mcm","clk":"11550478302","pt":1719498961534,"mc":[{"id":"1.230178170","rc":[{"atl":[[40,15.38]],"id":52385913}],"con":true,"img":false}]}
{"op":"mcm","clk":"11550478378","pt":1719498962372,"mc":[{"id":"1.230178170","rc":[{"atb":[[12,0]],"id":52385906}],"con":true,"img":false}]}
{"op":"mcm","clk":"11550478388","pt":1719498962466,"mc":[{"id":"1.230178170","rc":[{"atb":[[14,6]],"id":52385906}],"con":true,"img":false}]}
{"op":"mcm","clk":"11550478559","pt":1719498964175,"mc":[{"id":"1.230178170","rc":[{"atb":[[16.5,26.7]],"id":52385920}],"con":true,"img":false}]}
{"op":"mcm","clk":"11550478567","pt":1719498964278,"mc":[{"id":"1.230178170","rc":[{"atb":[[16,0]],"id":52385920}],"con":true,"img":false}]}
{"op":"mcm","clk":"11550478574","pt":1719498964332,"mc":[{"id":"1.230178170","rc":[{"atb":[[19,0]],"id":52385919}],"con":true,"img":false}]}
{"op":"mcm","clk":"11550478599","pt":1719498964641,"mc":[{"id":"1.230178170","rc":[{"atb":[[16,0]],"id":52385899}],"con":true,"img":false}]}
{"op":"mcm","clk":"11550478612","pt":1719498964742,"mc":[{"id":"1.230178170","rc":[{"atb":[[18,6]],"id":52385899}],"con":true,"img":false}]}
{"op":"mcm","clk":"11550478713","pt":1719498965875,"mc":[{"id":"1.230178170","rc":[{"atl":[[25,0]],"id":52385907}],"con":true,"img":false}]}
{"op":"mcm","clk":"11550478721","pt":1719498965989,"mc":[{"id":"1.230178170","rc":[{"atl":[[26,22.12]],"id":52385907},{"atl":[[36,17.14]],"id":52385891}],"con":true,"img":false}]}
{"op":"mcm","clk":"11550478740","pt":1719498966139,"mc":[{"id":"1.230178170","rc":[{"atl":[[26,0]],"id":52385907},{"atl":[[42,0]],"id":52385891}],"con":true,"img":false}]}
{"op":"mcm","clk":"11550478753","pt":1719498966244,"mc":[{"id":"1.230178170","rc":[{"atl":[[30,20.69]],"id":52385907}],"con":true,"img":false}]}
{"op":"mcm","clk":"11550478773","pt":1719498966458,"mc":[{"id":"1.230178170","rc":[{"atb":[[7.8,0],[6.6,10]],"id":52385918},{"atb":[[16.5,4.7]],"id":52385920},{"atb":[[23,27.27]],"id":52385889},{"atb":[[10,0],[12.5,8.7]],"id":52385883},{"atb":[[3.2,0],[3.7,10]],"id":52385896},{"atb":[[1.95,105.26],[4.7,0]],"id":52385890},{"atb":[[16,0],[11,10]],"id":52385892},{"atl":[[130,0],[150,5],[95,0],[110,2.5]],"id":52385892},{"atb":[[3.6,38.46],[3.35,0]],"id":52385898},{"atb":[[5.8,10],[12,0]],"id":52385911},{"atl":[[150,5],[90,0],[110,2.5],[120,0]],"id":52385911},{"atb":[[1.31,120.05]],"id":52385919},{"atl":[[50,12.24]],"id":52385919},{"atb":[[10,0],[13,8.33]],"id":52385921},{"atl":[[80,2],[95,0]],"id":52385884},{"atb":[[7.4,0],[9.4,11]],"id":52385917},{"atb":[[8.2,0],[9.4,10]],"id":52385891},{"atb":[[6.6,12],[8.4,0]],"id":52385893}],"con":true,"img":false}]}
{"op":"mcm","clk":"11550478785","pt":1719498966553,"mc":[{"id":"1.230178170","rc":[{"atb":[[7.6,10]],"id":52385918},{"atb":[[3.7,0],[4.2,10]],"id":52385896},{"atb":[[2.84,54.35]],"id":52385890},{"atb":[[7.2,10]],"id":52385911},{"atl":[[70,2.5]],"id":52385919}],"con":true,"img":false}]}
{"op":"mcm","clk":"11550478793","pt":1719498966653,"mc":[{"id":"1.230178170","rc":[{"atb":[[6.6,0]],"id":52385918},{"atb":[[18.5,0],[23,0]],"id":52385889},{"atb":[[1.95,0]],"id":52385890},{"atb":[[5.8,0]],"id":52385911}],"con":true,"img":false}]}
{"op":"mcm","clk":"11550478803","pt":1719498966757,"mc":[{"id":"1.230178170","rc":[{"atb":[[10,11.11],[22,28.57]],"id":52385889}],"con":true,"img":false}]}
{"op":"mcm","clk":"11550478815","pt":1719498966876,"mc":[{"id":"1.230178170","rc":[{"atb":[[9.6,0]],"id":52385889}],"con":true,"img":false}]}
{"op":"mcm","clk":"11550479036","pt":1719498969152,"mc":[{"id":"1.230178170","rc":[{"atb":[[19.5,20]],"id":52385891}],"con":true,"img":false}]}
{"op":"mcm","clk":"11550479055","pt":1719498969357,"mc":[{"id":"1.230178170","rc":[{"atb":[[19,25]],"id":52385884},{"atb":[[19,0]],"id":52385891},{"atl":[[16.5,1]],"id":52385905}],"con":true,"img":false}]}
{"op":"mcm","clk":"11550479077","pt":1719498969563,"mc":[{"id":"1.230178170","rc":[{"atb":[[17,4.62]],"id":52385884}],"con":true,"img":false}]}
{"op":"mcm","clk":"11550479100","pt":1719498969775,"mc":[{"id":"1.230178170","rc":[{"atb":[[17,2.5],[13,0]],"id":52385912},{"atl":[[38,2.5],[44,0],[46,5],[55,0]],"id":52385920},{"atb":[[11.5,0],[13.5,0],[15,2.5]],"id":52385914},{"atb":[[16.5,0],[18.5,0],[19,8.3],[22,2.5]],"id":52385892},{"atb":[[10,6.7],[9.2,5],[8.2,0],[7.4,0]],"id":52385898},{"atb":[[16.5,2.5],[12.5,0]],"id":52385911},{"atb":[[11.5,0],[12,2.5],[9.8,0]],"id":52385913},{"atl":[[32,0],[34,5],[40,2.56],[28,2.5]],"id":52385907},{"atl":[[38,2.5],[60,0]],"id":52385884},{"atl":[[38,2.7],[27,6.5],[30,0]],"id":52385903},{"atl":[[40,0],[27,2.5]],"id":52385905},{"atb":[[11.5,0],[15.5,2.5]],"id":52385899}],"con":true,"img":false}]}
{"op":"mcm","clk":"11550479108","pt":1719498969869,"mc":[{"id":"1.230178170","rc":[{"atl":[[32,3.23],[40,0]],"id":52385907}],"con":true,"img":false}]}
{"op":"mcm","clk":"11550479118","pt":1719498969971,"mc":[{"id":"1.230178170","rc":[{"atl":[[42,5.5],[44,0],[50,5],[55,0]],"id":52385913}],"con":true,"img":false}]}
{"op":"mcm","clk":"11550479273","pt":1719498971781,"mc":[{"id":"1.230178170","rc":[{"atl":[[130,5],[85,0],[95,2.5],[110,0]],"id":52385912},{"atb":[[7.2,12],[8.6,0]],"id":52385914},{"atl":[[65,0],[80,5],[48,0],[60,2.5]],"id":52385914},{"atb":[[4.8,9.2]],"id":52385911},{"atb":[[1.81,120.05],[1.31,0]],"id":52385919},{"atb":[[6.6,0],[7.8,11]],"id":52385893}],"con":true,"img":false}]}
{"op":"mcm","clk":"11550479284","pt":1719498971883,"mc":[{"id":"1.230178170","rc":[{"atb":[[7.2,0]],"id":52385911}],"con":true,"img":false}]}
{"op":"mcm","clk":"11550479327","pt":1719498972362,"mc":[{"id":"1.230178170","rc":[{"atb":[[2.84,0]],"id":52385890}],"con":true,"img":false}]}
{"op":"mcm","clk":"11550479334","pt":1719498972454,"mc":[{"id":"1.230178170","rc":[{"atb":[[3.15,46.51]],"id":52385890}],"con":true,"img":false}]}
{"op":"mcm","clk":"11550479499","pt":1719498974472,"mc":[{"id":"1.230178170","rc":[{"atl":[[65,9.38],[80,5],[85,0],[60,2.5]],"id":52385886}],"con":true,"img":false}]}
{"op":"mcm","clk":"11550479512","pt":1719498974580,"mc":[{"id":"1.230178170","rc":[{"atb":[[13,0],[15,0],[15.5,7.1]],"id":52385896},{"atb":[[11,0],[13,0],[13.5,2.5]],"id":52385900},{"atl":[[140,0],[60,12.67],[120,2]],"id":52385886},{"atb":[[16,5],[18,2.5],[13,0],[15,6]],"id":52385897},{"atb":[[17,0],[18,5],[19,0],[20,8.5]],"id":52385893}],"con":true,"img":false}]}
{"op":"mcm","clk":"11550479532","pt":1719498974782,"mc":[{"id":"1.230178170","rc":[{"atb":[[17.5,22]],"id":52385906},{"atl":[[65,0]],"id":52385886}],"con":true,"img":false}]}
{"op":"mcm","clk":"11550479549","pt":1719498974988,"mc":[{"id":"1.230178170","rc":[{"atb":[[17,0]],"id":52385906}],"con":true,"img":false}]}
{"op":"mcm","clk":"11550479590","pt":1719498975358,"mc":[{"id":"1.230178170","rc":[{"atb":[[15,0]],"id":52385897}],"con":true,"img":false}]}
{"op":"mcm","clk":"11550479728","pt":1719498977002,"mc":[{"id":"1.230178170","rc":[{"atb":[[13,8.33]],"id":52385912},{"atl":[[140,2],[200,0]],"id":52385912},{"atb":[[8,0],[10,11.11]],"id":52385906},{"atl":[[34,0],[42,0],[46,2.5],[60,5]],"id":52385906},{"atb":[[7.6,0],[13,7.7]],"id":52385918},{"atl":[[85,5],[100,2]],"id":52385889},{"atb":[[7.2,0],[10.5,9.26]],"id":52385914},{"atb":[[12.5,0],[14,7.69],[24,18.6]],"id":52385883},{"atb":[[18,0],[21,5],[28,21.76]],"id":52385885},{"atb":[[21,0],[10.5,5],[12.5,2.5],[4.2,0],[8.4,13.51],[15.5,4.6]],"id":52385896},{"atb":[[16.5,6.45],[11,0]],"id":52385892},{"atl":[[140,5],[150,0],[100,2.5],[110,0]],"id":52385892},{"atb":[[9.2,10.4],[7.2,0],[17.5,20.8]],"id":52385904},{"atl":[[38,0],[30,0]],"id":52385904},{"atb":[[17,0],[3.6,0],[7,13.4]],"id":52385898},{"atb":[[22,0],[7.8,11.6]],"id":52385900},{"atl":[[65,7],[95,0]],"id":52385900},{"atb":[[4.8,0],[15.5,6.9]],"id":52385911},{"atl":[[150,0],[90,2.5],[110,0],[120,5]],"id":52385911},{"atl":[[32,0],[38,2.7]],"id":52385907},{"atb":[[1.81,0],[10.5,7.68]],"id":52385919},{"atl":[[140,0],[90,7]],"id":52385919},{"atb":[[13,0],[30,20.69],[15.5,6.9]],"id":52385882},{"atl":[[65,0],[110,5]],"id":52385882},{"atb":[[11.5,9.26],[9.8,0]],"id":52385884},{"atl":[[70,5],[38,0],[46,0],[50,2.5]],"id":52385884},{"atb":[[10.5,9.59]],"id":52385897},{"atl":[[65,2.5],[70,0],[85,5],[90,0],[95,2],[120,0]],"id":52385897},{"atb":[[22,20]],"id":52385891},{"atb":[[11.5,9.52],[7.8,0]],"id":52385893},{"atb":[[12.5,25]],"id":52385903},{"atl":[[38,0],[55,2]],"id":52385903},{"atb":[[12.5,7.72]],"id":52385899},{"atl":[[130,2],[190,0]],"id":52385899}],"con":true,"img":false}]}
{"op":"mcm","clk":"11550479736","pt":1719498977058,"mc":[{"id":"1.230178170","rc":[{"atl":[[70,0],[120,2]],"id":52385906},{"atl":[[140,2]],"id":52385889},{"atb":[[22,0]],"id":52385883},{"atb":[[27,0]],"id":52385885},{"atl":[[380,2],[250,0]],"id":52385885},{"atb":[[16,38.2]],"id":52385896},{"atl":[[330,2],[230,0]],"id":52385892},{"atb":[[14.5,0]],"id":52385904},{"atl":[[100,2],[60,0]],"id":52385904},{"atb":[[10.5,24.4]],"id":52385898},{"atl":[[65,5],[80,2]],"id":52385900},{"atl":[[38,0],[50,2.04]],"id":52385907},{"atl":[[90,5],[120,2]],"id":52385919},{"atl":[[260,2],[140,0]],"id":52385882},{"atl":[[130,2],[80,0]],"id":52385884},{"atl":[[130,2],[95,0]],"id":52385897},{"atl":[[75,0],[110,2]],"id":52385891},{"atb":[[8,0]],"id":52385903}],"con":true,"img":false}]}
{"op":"mcm","clk":"11550479745","pt":1719498977162,"mc":[{"id":"1.230178170","rc":[{"atb":[[16.5,24.1]],"id":52385920},{"atl":[[100,0]],"id":52385889},{"atb":[[18,5.88],[21,0]],"id":52385885},{"atb":[[17.5,0]],"id":52385904},{"atl":[[40,2.5],[48,5]],"id":52385904},{"atb":[[5.8,20.83],[7,0]],"id":52385898},{"atb":[[6.4,11.6],[7.8,0]],"id":52385900},{"atl":[[50,0]],"id":52385919},{"atb":[[29,0]],"id":52385882},{"atl":[[75,2.5],[85,0],[95,5],[110,0]],"id":52385882},{"atb":[[25,3]],"id":52385917},{"atb":[[19.5,0],[22,0]],"id":52385891},{"atb":[[15.5,22.5]],"id":52385905},{"atl":[[70,2],[46,0]],"id":52385905},{"atl":[[190,2]],"id":52385899}],"con":true,"img":false}]}
{"op":"mcm","clk":"11550479753","pt":1719498977272,"mc":[{"id":"1.230178170","rc":[{"atb":[[26,0]],"id":52385910},{"atb":[[22,0]],"id":52385889},{"atb":[[14,21.24]],"id":52385904},{"atb":[[7.2,13.4],[5.8,0]],"id":52385898},{"atl":[[55,11.11]],"id":52385919},{"atb":[[15,0]],"id":52385882},{"atb":[[19.5,14.22]],"id":52385891},{"atb":[[14,0]],"id":52385905},{"atb":[[12.5,0]],"id":52385899},{"atl":[[130,0]],"id":52385899}],"con":true,"img":false}]}
{"op":"mcm","clk":"11550479768","pt":1719498977483,"mc":[{"id":"1.230178170","rc":[{"atb":[[11.5,0],[25,20],[13,8.33]],"id":52385910},{"atb":[[10,0],[21,17],[11,10]],"id":52385889},{"atb":[[20,0]],"id":52385885},{"atl":[[55,0]],"id":52385919},{"atb":[[30,0]],"id":52385882},{"atb":[[19.5,0],[20,20]],"id":52385891},{"atb":[[13.5,10.5]],"id":52385899}],"con":true,"img":false}]}
{"op":"mcm","clk":"11550479776","pt":1719498977600,"mc":[{"id":"1.230178170","rc":[{"atl":[[30,0]],"id":52385920},{"atb":[[23,0]],"id":52385890},{"atb":[[29,0]],"id":52385892},{"atl":[[42,0]],"id":52385900},{"atb":[[28,0]],"id":52385911},{"atl":[[65,9.38]],"id":52385919},{"atb":[[28,22.22],[14.5,7.41]],"id":52385882}],"con":true,"img":false}]}
{"op":"mcm","clk":"11550479784","pt":1719498977687,"mc":[{"id":"1.230178170","rc":[{"atb":[[25,0],[27,20.56]],"id":52385910},{"atl":[[28,22]],"id":52385920},{"atb":[[21,0]],"id":52385889},{"atb":[[26,22]],"id":52385890},{"atb":[[30,20.69]],"id":52385892},{"atl":[[40,15.38]],"id":52385900},{"atb":[[29,20]],"id":52385911},{"atb":[[15.5,0]],"id":52385882},{"atb":[[24,15.26]],"id":52385897},{"atb":[[16,0],[20,0]],"id":52385891},{"atb":[[29,21.43]],"id":52385893}],"con":true,"img":false}]}
{"op":"mcm","clk":"11550479794","pt":1719498977790,"mc":[{"id":"1.230178170","rc":[{"atb":[[20,30]],"id":52385889},{"atb":[[19.5,20]],"id":52385891},{"atb":[[28,3.7]],"id":52385893}],"con":true,"img":false}]}
{"op":"mcm","clk":"11550479806","pt":1719498977890,"mc":[{"id":"1.230178170","rc":[{"atb":[[11,9]],"id":52385898},{"atb":[[22,0]],"id":52385897}],"con":true,"img":false}]}
{"op":"mcm","clk":"11550479835","pt":1719498978201,"mc":[{"id":"1.230178170","rc":[{"atb":[[12,0]],"id":52385903}],"con":true,"img":false}]}
{"op":"mcm","clk":"11550479847","pt":1719498978257,"mc":[{"id":"1.230178170","rc":[{"atb":[[12.5,8.7],[3.15,0]],"id":52385890},{"atb":[[12.5,0],[13,6]],"id":52385903}],"con":true,"img":false}]}
{"op":"mcm","clk":"11550479857","pt":1719498978359,"mc":[{"id":"1.230178170","rc":[{"atb":[[13,27.6]],"id":52385903}],"con":true,"img":false}]}
{"op":"mcm","clk":"11550479877","pt":1719498978569,"mc":[{"id":"1.230178170","rc":[{"atl":[[24,22]],"id":52385907}],"con":true,"img":false}]}
{"op":"mcm","clk":"11550479894","pt":1719498978771,"mc":[{"id":"1.230178170","rc":[{"atl":[[30,0]],"id":52385907}],"con":true,"img":false}]}
{"op":"mcm","clk":"11550479918","pt":1719498979079,"mc":[{"id":"1.230178170","rc":[{"atl":[[42,14.63]],"id":52385919}],"con":true,"img":false}]}
{"op":"mcm","clk":"11550479943","pt":1719498979388,"mc":[{"id":"1.230178170","rc":[{"atl":[[65,0]],"id":52385919}],"con":true,"img":false}]}
{"op":"mcm","clk":"11550479959","pt":1719498979597,"mc":[{"id":"1.230178170","rc":[{"atl":[[130,0],[70,2.5],[90,5],[95,0]],"id":52385912},{"atl":[[65,2.5],[70,0],[90,0]],"id":52385883},{"atb":[[8.6,0],[10,6.9],[9.2,15.4],[9.4,0]],"id":52385904},{"atl":[[70,2.5],[85,0],[90,5],[110,0]],"id":52385899}],"con":true,"img":false}]}
{"op":"mcm","clk":"11550480007","pt":1719498980169,"mc":[{"id":"1.230178170","rc":[{"atb":[[17.5,0]],"id":52385912},{"atb":[[27,0]],"id":52385918},{"atl":[[60,0]],"id":52385889},{"atb":[[14.5,0]],"id":52385914},{"atb":[[18.5,0]],"id":52385883},{"atl":[[50,0]],"id":52385883},{"atb":[[15.5,0]],"id":52385896},{"atb":[[18,0]],"id":52385890},{"atb":[[19,5]],"id":52385892},{"atb":[[10,2.49]],"id":52385904},{"atl":[[28,0]],"id":52385904},{"atb":[[10,2.5]],"id":52385898},{"atl":[[42,2.5]],"id":52385913},{"atb":[[12.5,0]],"id":52385907},{"atb":[[26,0]],"id":52385886},{"atb":[[22,0]],"id":52385919},{"atb":[[25,0]],"id":52385921},{"atb":[[17,0]],"id":52385884},{"atb":[[13.5,0]],"id":52385897},{"atl":[[60,0]],"id":52385897},{"atb":[[18.5,0]],"id":52385891},{"atl":[[38,0]],"id":52385891},{"atb":[[28,0]],"id":52385893},{"atb":[[10,0]],"id":52385903},{"atb":[[14,0]],"id":52385899},{"atl":[[55,0.2]],"id":52385899}],"con":true,"img":false}]}
{"op":"mcm","clk":"11550480025","pt":1719498980385,"mc":[{"id":"1.230178170","rc":[{"atb":[[23,3.01]],"id":52385912},{"atb":[[29,3]],"id":52385918},{"atl":[[50,3]],"id":52385889},{"atb":[[15.5,4]],"id":52385914},{"atl":[[42,3.1]],"id":52385914},{"atb":[[25,2.9]],"id":52385883},{"atb":[[29,3]],"id":52385885},{"atl":[[90,2]],"id":52385885},{"atb":[[16.5,5.2]],"id":52385896},{"atb":[[27,2]],"id":52385890},{"atb":[[21,2.92]],"id":52385892},{"atb":[[14.5,3.3]],"id":52385904},{"atl":[[26,3.73],[27,0]],"id":52385904},{"atb":[[11.5,3.68]],"id":52385898},{"atl":[[38,3.2]],"id":52385913},{"atb":[[10.5,3.8]],"id":52385907},{"atl":[[23,4]],"id":52385907},{"atb":[[28,2.7]],"id":52385886},{"atb":[[23,0],[24,4]],"id":52385919},{"atb":[[21,3],[26,0]],"id":52385921},{"atl":[[48,2]],"id":52385921},{"atb":[[19.5,4.5]],"id":52385884},{"atl":[[50,5.3]],"id":52385884},{"atl":[[60,2.71]],"id":52385917},{"atb":[[25,2.7]],"id":52385897},{"atl":[[50,3]],"id":52385897},{"atb":[[20,3.1]],"id":52385891},{"atl":[[46,4.5]],"id":52385891},{"atb":[[30,3.93]],"id":52385893},{"atb":[[9.2,5.95]],"id":52385903},{"atb":[[21,3]],"id":52385899},{"atl":[[70,4.5],[55,0]],"id":52385899}],"con":true,"img":false}]}
{"op":"mcm","clk":"11550480034","pt":1719498980493,"mc":[{"id":"1.230178170","rc":[{"atb":[[24,20]],"id":52385912},{"atb":[[29,19]],"id":52385918},{"atl":[[48,12.77]],"id":52385889},{"atl":[[40,15.38]],"id":52385914},{"atl":[[90,8.74]],"id":52385885},{"atl":[[38,16.22]],"id":52385904},{"atl":[[36,17.14]],"id":52385913},{"atl":[[22,20]],"id":52385907},{"atb":[[28,22.7]],"id":52385886},{"atb":[[24,17]],"id":52385919},{"atb":[[25,20],[13,0],[13.5,8]],"id":52385921},{"atl":[[48,12.38]],"id":52385921},{"atl":[[55,11.11]],"id":52385917},{"atl":[[48,11.4]],"id":52385897},{"atb":[[22,19]],"id":52385899},{"atl":[[60,10.17]],"id":52385899}],"con":true,"img":false}]}
{"op":"mcm","clk":"11550480041","pt":1719498980583,"mc":[{"id":"1.230178170","rc":[{"atb":[[22,0]],"id":52385912},{"atb":[[28,0]],"id":52385918},{"atl":[[55,0]],"id":52385889},{"atl":[[44,0]],"id":52385914},{"atl":[[110,2.5]],"id":52385885},{"atl":[[40,0]],"id":52385913},{"atl":[[24,0]],"id":52385907},{"atb":[[27,0]],"id":52385886},{"atl":[[50,0]],"id":52385921},{"atl":[[65,2.49]],"id":52385917},{"atl":[[55,0]],"id":52385897},{"atb":[[20,0]],"id":52385899}],"con":true,"img":false}]}
{"op":"mcm","clk":"11550480062","pt":1719498980795,"mc":[{"id":"1.230178170","rc":[{"atb":[[25,0]],"id":52385921},{"atl":[[90,2],[110,0]],"id":52385917}],"con":true,"img":false}]}
{"op":"mcm","clk":"11550480072","pt":1719498980890,"mc":[{"id":"1.230178170","rc":[{"atb":[[23,16]],"id":52385921}],"con":true,"img":false}]}
{"op":"mcm","clk":"11550480112","pt":1719498981303,"mc":[{"id":"1.230178170","rc":[{"atb":[[20,0],[30,0]],"id":52385892},{"atb":[[29,0]],"id":52385911}],"con":true,"img":false}]}
{"op":"mcm","clk":"11550480122","pt":1719498981356,"mc":[{"id":"1.230178170","rc":[{"atb":[[28,15.84]],"id":52385892},{"atb":[[26,20]],"id":52385911}],"con":true,"img":false}]}
{"op":"mcm","clk":"11550480136","pt":1719498981461,"mc":[{"id":"1.230178170","rc":[{"atb":[[15.5,0]],"id":52385905}],"con":true,"img":false}]}
{"op":"mcm","clk":"11550480147","pt":1719498981561,"mc":[{"id":"1.230178170","rc":[{"atb":[[28,0]],"id":52385892},{"atb":[[26,0]],"id":52385911},{"atb":[[15,15.5]],"id":52385905}],"con":true,"img":false}]}
{"op":"mcm","clk":"11550480160","pt":1719498981667,"mc":[{"id":"1.230178170","rc":[{"atb":[[24,10.84]],"id":52385892},{"atb":[[23,19.2]],"id":52385911},{"atb":[[22,19]],"id":52385891},{"atb":[[15,0]],"id":52385905}],"con":true,"img":false}]}
{"op":"mcm","clk":"11550480173","pt":1719498981775,"mc":[{"id":"1.230178170","rc":[{"atb":[[17.5,0]],"id":52385906},{"atb":[[19.5,0]],"id":52385891},{"atb":[[13,15.5]],"id":52385905}],"con":true,"img":false}]}
{"op":"mcm","clk":"11550480181","pt":1719498981874,"mc":[{"id":"1.230178170","rc":[{"atb":[[17,22]],"id":52385906},{"atb":[[19.5,25.1]],"id":52385884}],"con":true,"img":false}]}
{"op":"mcm","clk":"11550480197","pt":1719498982075,"mc":[{"id":"1.230178170","rc":[{"atb":[[17,0]],"id":52385906},{"atb":[[19,5]],"id":52385884}],"con":true,"img":false}]}
{"op":"mcm","clk":"11550480206","pt":1719498982178,"mc":[{"id":"1.230178170","rc":[{"atb":[[17.5,22]],"id":52385906}],"con":true,"img":false}]}
{"op":"mcm","clk":"11550480222","pt":1719498982382,"mc":[{"id":"1.230178170","rc":[{"atb":[[17.5,0]],"id":52385906}],"con":true,"img":false}]}
{"op":"mcm","clk":"11550480229","pt":1719498982487,"mc":[{"id":"1.230178170","rc":[{"atb":[[15.5,22]],"id":52385906}],"con":true,"img":false}]}
{"op":"mcm","clk":"11550480258","pt":1719498982809,"mc":[{"id":"1.230178170","rc":[{"atl":[[85,2]],"id":52385891}],"con":true,"img":false}]}
{"op":"mcm","clk":"11550480267","pt":1719498982901,"mc":[{"id":"1.230178170","rc":[{"atl":[[140,0],[100,2]],"id":52385889},{"atl":[[270,2],[380,0]],"id":52385885},{"atl":[[260,2],[330,0]],"id":52385892},{"atl":[[42,2.44],[50,0]],"id":52385907},{"atl":[[260,0],[170,2]],"id":52385882},{"atl":[[130,0],[90,2]],"id":52385884},{"atl":[[110,0]],"id":52385891}],"con":true,"img":false}]}
{"op":"mcm","clk":"11550480273","pt":1719498982956,"mc":[{"id":"1.230178170","rc":[{"atb":[[8.6,9.2]],"id":52385900},{"atl":[[150,2],[190,0]],"id":52385899}],"con":true,"img":false}]}
{"op":"mcm","clk":"11550480285","pt":1719498983109,"mc":[{"id":"1.230178170","rc":[{"atb":[[6.4,0]],"id":52385900}],"con":true,"img":false}]}
{"op":"mcm","clk":"11550480307","pt":1719498983319,"mc":[{"id":"1.230178170","rc":[{"atb":[[13,0],[8.8,10.56]],"id":52385910},{"atl":[[150,0],[120,2]],"id":52385910},{"atb":[[13,0]],"id":52385912},{"atl":[[130,5],[70,0],[140,0],[90,0],[95,2.5],[250,2]],"id":52385912},{"atb":[[10,0],[7.8,12]],"id":52385906},{"atl":[[34,2.5],[75,2],[42,5],[46,0],[60,0],[120,0]],"id":52385906},{"atb":[[9.2,12.2],[13,0]],"id":52385918},{"atl":[[130,2]],"id":52385918},{"atb":[[16.5,4.7]],"id":52385920},{"atl":[[46,7.22]],"id":52385920},{"atb":[[10.5,0],[7.6,12]],"id":52385914},{"atb":[[11,10],[14,0]],"id":52385883},{"atb":[[5,10.2],[8.4,0]],"id":52385896},{"atb":[[12.5,0]],"id":52385890},{"atb":[[16.5,0],[12,9.09]],"id":52385892},{"atb":[[9.2,5],[7.6,15.15]],"id":52385904},{"atl":[[65,2],[100,0]],"id":52385904},{"atb":[[4.8,26.32],[7.2,0]],"id":52385898},{"atb":[[8.6,0],[22,19.2]],"id":52385900},{"atb":[[5,9.2],[15.5,0]],"id":52385911},{"atl":[[150,5],[90,0],[110,2.5],[120,0]],"id":52385911},{"atl":[[65,2],[80,0]],"id":52385913},{"atb":[[4,33.33],[10.5,0]],"id":52385919},{"atl":[[42,0]],"id":52385919},{"atl":[[150,0],[110,2]],"id":52385921},{"atb":[[11.5,0],[8.8,10]],"id":52385884},{"atb":[[25,14.42]],"id":52385917},{"atl":[[75,2],[90,0]],"id":52385917},{"atb":[[10.5,0],[2.42,70.42]],"id":52385897},{"atb":[[22,0]],"id":52385891},{"atl":[[65,2]],"id":52385891},{"atb":[[11.5,0],[8.4,13.51]],"id":52385893},{"atb":[[13,6]],"id":52385903},{"atl":[[36,2.86],[55,0]],"id":52385903},{"atb":[[13.5,2.5]],"id":52385899},{"atl":[[70,2],[140,5],[90,0],[100,2.5],[60,0]],"id":52385899}],"con":true,"img":false}]}
{"op":"mcm","clk":"11550480315","pt":1719498983380,"mc":[{"id":"1.230178170","rc":[{"atl":[[150,0]],"id":52385918},{"atl":[[65,0]],"id":52385920},{"atb":[[23,27.27]],"id":52385889},{"atb":[[5,25]],"id":52385890},{"atb":[[1.91,109.89]],"id":52385900},{"atl":[[48,12.77]],"id":52385919},{"atb":[[20,22.1]],"id":52385891},{"atl":[[85,0]],"id":52385891},{"atl":[[70,0],[40,2.56]],"id":52385905}],"con":true,"img":false}]}
{"op":"mcm","clk":"11550480327","pt":1719498983476,"mc":[{"id":"1.230178170","rc":[{"atb":[[20,0]],"id":52385889},{"atl":[[70,10.25]],"id":52385899}],"con":true,"img":false}]}
{"op":"mcm","clk":"11550480348","pt":1719498983787,"mc":[{"id":"1.230178170","rc":[{"atl":[[25,22]],"id":52385906}],"con":true,"img":false}]}
{"op":"mcm","clk":"11550480372","pt":1719498983992,"mc":[{"id":"1.230178170","rc":[{"atl":[[26,2.5]],"id":52385906}],"con":true,"img":false}]}
{"op":"mcm","clk":"11550480403","pt":1719498984308,"mc":[{"id":"1.230178170","rc":[{"atl":[[75,5],[80,0],[55,2.5],[60,0]],"id":52385914},{"atl":[[40,0]],"id":52385900}],"con":true,"img":false}]}
{"op":"mcm","clk":"11550480410","pt":1719498984413,"mc":[{"id":"1.230178170","rc":[{"atl":[[28,0]],"id":52385920}],"con":true,"img":false}]}
{"op":"mcm","clk":"11550480418","pt":1719498984518,"mc":[{"id":"1.230178170","rc":[{"atl":[[44,13.95]],"id":52385900}],"con":true,"img":false}]}
{"op":"mcm","clk":"11550480426","pt":1719498984613,"mc":[{"id":"1.230178170","rc":[{"atl":[[29,21.4]],"id":52385920}],"con":true,"img":false}]}
{"op":"mcm","clk":"11550480617","pt":1719498987201,"mc":[{"id":"1.230178170","rc":[{"atb":[[16,19.74]],"id":52385906}],"con":true,"img":false}]}
{"op":"mcm","clk":"11550480632","pt":1719498987404,"mc":[{"id":"1.230178170","rc":[{"atb":[[15.5,0]],"id":52385906}],"con":true,"img":false}]}
{"op":"mcm","clk":"11550480691","pt":1719498988108,"mc":[{"id":"1.230178170","rc":[{"atl":[[80,0],[100,2]],"id":52385900},{"atl":[[220,2]],"id":52385899}],"con":true,"img":false}]}
{"op":"mcm","clk":"11550480696","pt":1719498988163,"mc":[{"id":"1.230178170","rc":[{"atl":[[150,0]],"id":52385899}],"con":true,"img":false}]}
{"op":"mcm","clk":"11550480710","pt":1719498988371,"mc":[{"id":"1.230178170","rc":[{"atl":[[65,0],[85,2]],"id":52385913},{"atl":[[90,2]],"id":52385917}],"con":true,"img":false}]}
{"op":"mcm","clk":"11550480716","pt":1719498988477,"mc":[{"id":"1.230178170","rc":[{"atl":[[75,0]],"id":52385917}],"con":true,"img":false}]}
{"op":"mcm","clk":"11550480726","pt":1719498988585,"mc":[{"id":"1.230178170","rc":[{"atl":[[90,2],[100,0]],"id":52385889},{"atl":[[32,3.23],[42,0]],"id":52385907},{"atl":[[140,2],[170,0]],"id":52385882},{"atl":[[75,2],[90,0]],"id":52385884}],"con":true,"img":false}]}
{"op":"mcm","clk":"11550480737","pt":1719498988679,"mc":[{"id":"1.230178170","rc":[{"atb":[[2.1,90.91]],"id":52385900},{"atb":[[23,0]],"id":52385911}],"con":true,"img":false}]}
{"op":"mcm","clk":"11550480750","pt":1719498988783,"mc":[{"id":"1.230178170","rc":[{"atb":[[1.91,0]],"id":52385900},{"atb":[[28,20]],"id":52385911}],"con":true,"img":false}]}
{"op":"mcm","clk":"11550480767","pt":1719498988988,"mc":[{"id":"1.230178170","rc":[{"atb":[[2.54,64.94],[2.42,0]],"id":52385897}],"con":true,"img":false}]}
{"op":"mcm","clk":"11550480797","pt":1719498989400,"mc":[{"id":"1.230178170","rc":[{"atb":[[26,17.8]],"id":52385883},{"atb":[[30,20.69]],"id":52385885},{"atb":[[14.5,17.36]],"id":52385904},{"atb":[[11,0]],"id":52385898},{"atb":[[30,20.69]],"id":52385882},{"atb":[[12,0]],"id":52385905}],"con":true,"img":false}]}
{"op":"mcm","clk":"11550480807","pt":1719498989502,"mc":[{"id":"1.230178170","rc":[{"atb":[[21,15.4]],"id":52385896},{"atb":[[12,9],[14,29]],"id":52385898},{"atb":[[13,21.5]],"id":52385905}],"con":true,"img":false}]}
{"op":"mcm","clk":"11550480816","pt":1719498989605,"mc":[{"id":"1.230178170","rc":[{"atb":[[24,0]],"id":52385883},{"atb":[[28,0]],"id":52385885},{"atb":[[14,6]],"id":52385904},{"atb":[[28,0]],"id":52385882}],"con":true,"img":false}]}
{"op":"mcm","clk":"11550480825","pt":1719498989709,"mc":[{"id":"1.230178170","rc":[{"atb":[[16,8]],"id":52385896},{"atb":[[10.5,0]],"id":52385898}],"con":true,"img":false}]}
{"op":"mcm","clk":"11550480864","pt":1719498990072,"mc":[{"id":"1.230178170","rc":[{"atb":[[28,22]],"id":52385890},{"atb":[[29,15.84]],"id":52385892},{"atb":[[26,11.4]],"id":52385897},{"atb":[[30,24.62]],"id":52385893}],"con":true,"img":false}]}
{"op":"mcm","clk":"11550480876","pt":1719498990179,"mc":[{"id":"1.230178170","rc":[{"atb":[[26,0]],"id":52385890},{"atb":[[24,0]],"id":52385892},{"atb":[[24,0]],"id":52385897},{"atb":[[29,0]],"id":52385893}],"con":true,"img":false}]}
{"op":"mcm","clk":"11550480955","pt":1719498991004,"mc":[{"id":"1.230178170","rc":[{"atl":[[65,2.5],[70,0],[85,5],[90,0]],"id":52385919}],"con":true,"img":false}]}
{"op":"mcm","clk":"11550481112","pt":1719498992824,"mc":[{"id":"1.230178170","rc":[{"atl":[[26,23.19]],"id":52385904},{"atb":[[24,16]],"id":52385921}],"con":true,"img":false}]}
{"op":"mcm","clk":"11550481122","pt":1719498992873,"mc":[{"id":"1.230178170","rc":[{"atl":[[38,0]],"id":52385904},{"atb":[[23,0]],"id":52385921}],"con":true,"img":false}]}
{"op":"mcm","clk":"11550481155","pt":1719498993283,"mc":[{"id":"1.230178170","rc":[{"atb":[[16.5,0],[17,5],[19,2.5],[14.5,0]],"id":52385890}],"con":true,"img":false}]}
{"op":"mcm","clk":"11550481255","pt":1719498994414,"mc":[{"id":"1.230178170","rc":[{"atb":[[2.54,0],[2.34,74.63]],"id":52385897}],"con":true,"img":false}]}
{"op":"mcm","clk":"11550481624","pt":1719498998199,"mc":[{"id":"1.230178170","rc":[{"atb":[[28,0]],"id":52385911}],"con":true,"img":false}]}
{"op":"mcm","clk":"11550481636","pt":1719498998305,"mc":[{"id":"1.230178170","rc":[{"atb":[[29,0]],"id":52385892},{"atb":[[27,20]],"id":52385911},{"atb":[[16,0]],"id":52385913}],"con":true,"img":false}]}
{"op":"mcm","clk":"11550481648","pt":1719498998406,"mc":[{"id":"1.230178170","rc":[{"atb":[[28,15.84]],"id":52385892},{"atb":[[18,5]],"id":52385913}],"con":true,"img":false}]}
{"op":"mcm","clk":"11550481658","pt":1719498998509,"mc":[{"id":"1.230178170","rc":[{"atb":[[22,12.28],[27,0]],"id":52385911}],"con":true,"img":false}]}
{"op":"mcm","clk":"11550481668","pt":1719498998612,"mc":[{"id":"1.230178170","rc":[{"atb":[[28,0]],"id":52385892},{"atb":[[21,20],[22,0]],"id":52385911},{"atb":[[30,0]],"id":52385882},{"atl":[[65,0],[75,5],[85,0],[55,13.61]],"id":52385917}],"con":true,"img":false}]}
{"op":"mcm","clk":"11550481678","pt":1719498998717,"mc":[{"id":"1.230178170","rc":[{"atb":[[30,15.84]],"id":52385892},{"atb":[[13,8.33],[14.5,0],[30,20.69]],"id":52385882}],"con":true,"img":false}]}
{"op":"mcm","clk":"11550481850","pt":1719499000697,"mc":[{"id":"1.230178170","rc":[{"atb":[[5,0],[5.5,10.2]],"id":52385896},{"atb":[[2.42,70.42],[2.1,0]],"id":52385900},{"atb":[[4,0],[4.7,27.03]],"id":52385919},{"atb":[[2.9,52.63],[2.34,0]],"id":52385897}],"con":true,"img":false}]}
{"op":"mcm","clk":"11550481857","pt":1719499000786,"mc":[{"id":"1.230178170","rc":[{"atl":[[34,18.18]],"id":52385913}],"con":true,"img":false}]}
{"op":"mcm","clk":"11550481867","pt":1719499000909,"mc":[{"id":"1.230178170","rc":[{"atb":[[29,20]],"id":52385911},{"atl":[[36,0]],"id":52385913},{"atb":[[30,0]],"id":52385882}],"con":true,"img":false}]}
{"op":"mcm","clk":"11550481876","pt":1719499001003,"mc":[{"id":"1.230178170","rc":[{"atb":[[21,0]],"id":52385911},{"atb":[[13.5,16.94]],"id":52385882}],"con":true,"img":false}]}
{"op":"mcm","clk":"11550481893","pt":1719499001325,"mc":[{"id":"1.230178170","rc":[{"atb":[[16,6]],"id":52385882},{"atb":[[22,20]],"id":52385891}],"con":true,"img":false}]}
{"op":"mcm","clk":"11550481910","pt":1719499001508,"mc":[{"id":"1.230178170","rc":[{"atb":[[16.5,22]],"id":52385882},{"atb":[[20,3.1]],"id":52385891}],"con":true,"img":false}]}
{"op":"mcm","clk":"11550481926","pt":1719499001721,"mc":[{"id":"1.230178170","rc":[{"atb":[[13.5,0]],"id":52385882}],"con":true,"img":false}]}
{"op":"mcm","clk":"11550482364","pt":1719499007406,"mc":[{"id":"1.230178170","rc":[{"atb":[[23,0]],"id":52385912},{"atl":[[26,0]],"id":52385906},{"atl":[[50,0]],"id":52385889},{"atl":[[42,0]],"id":52385914},{"atb":[[25,0]],"id":52385883},{"atb":[[29,0]],"id":52385885},{"atb":[[16.5,0]],"id":52385896},{"atb":[[27,0]],"id":52385890},{"atl":[[55,11.11]],"id":52385890},{"atb":[[21,0]],"id":52385892},{"atl":[[26,19.46]],"id":52385904},{"atb":[[11.5,0]],"id":52385898},{"atb":[[21,0]],"id":52385900},{"atb":[[18,0]],"id":52385911},{"atl":[[38,0]],"id":52385913},{"atb":[[10.5,0]],"id":52385907},{"atl":[[23,0]],"id":52385907},{"atb":[[28,20]],"id":52385886},{"atb":[[21,0]],"id":52385921},{"atb":[[14,0]],"id":52385882},{"atb":[[25,11.42]],"id":52385917},{"atl":[[60,0]],"id":52385917},{"atb":[[25,0]],"id":52385897},{"atl":[[50,0]],"id":52385897},{"atb":[[20,0]],"id":52385891},{"atl":[[46,2.5]],"id":52385891},{"atb":[[9.2,0]],"id":52385903},{"atb":[[10.5,0]],"id":52385905},{"atb":[[21,0]],"id":52385899}],"con":true,"img":false}]}
{"op":"mcm","clk":"11550482380","pt":1719499007612,"mc":[{"id":"1.230178170","rc":[{"atb":[[24,0],[25,3.7]],"id":52385912},{"atl":[[24,3.8],[25,0]],"id":52385906},{"atl":[[60,2.1]],"id":52385918},{"atl":[[65,5.02],[48,0]],"id":52385889},{"atl":[[40,0],[50,2.51]],"id":52385914},{"atb":[[21,3.6],[26,0]],"id":52385883},{"atl":[[50,2.4]],"id":52385883},{"atb":[[25,3.3],[30,0]],"id":52385885},{"atb":[[22,3.56]],"id":52385896},{"atb":[[28,0],[29,3]],"id":52385890},{"atl":[[70,4.5],[55,0]],"id":52385890},{"atb":[[32,2.8]],"id":52385892},{"atl":[[40,4.5],[26,0]],"id":52385904},{"atb":[[14.5,4]],"id":52385898},{"atb":[[22,0],[23,3.1]],"id":52385900},{"atb":[[30,3]],"id":52385911},{"atl":[[32,3.4]],"id":52385913},{"atb":[[9.4,4.62]],"id":52385907},{"atl":[[21,4],[22,0]],"id":52385907},{"atb":[[18.5,3],[28,0]],"id":52385886},{"atl":[[80,7]],"id":52385886},{"atl":[[65,5.5]],"id":52385919},{"atb":[[18.5,3]],"id":52385921},{"atb":[[17,4.71]],"id":52385882},{"atb":[[17.5,3.4]],"id":52385917},{"atl":[[50,2.01]],"id":52385917},{"atb":[[26,0],[27,3.2]],"id":52385897},{"atl":[[65,5.4],[48,0]],"id":52385897},{"atb":[[23,2.56]],"id":52385891},{"atb":[[8.4,5.2]],"id":52385903},{"atb":[[13.5,3.8]],"id":52385905},{"atb":[[22,0],[23,3]],"id":52385899}],"con":true,"img":false}]}
{"op":"mcm","clk":"11550482389","pt":1719499007717,"mc":[{"id":"1.230178170","rc":[{"atb":[[26,17.4]],"id":52385912},{"atl":[[24,19.14]],"id":52385906},{"atl":[[60,12.27]],"id":52385918},{"atl":[[50,12.24]],"id":52385889},{"atl":[[42,13.02]],"id":52385914},{"atb":[[25,12]],"id":52385883},{"atb":[[29,16.6]],"id":52385885},{"atb":[[22,26.68]],"id":52385896},{"atb":[[30,15]],"id":52385890},{"atl":[[60,10.17]],"id":52385890},{"atb":[[34,15.6]],"id":52385892},{"atl":[[27,19]],"id":52385904},{"atb":[[14.5,33]],"id":52385898},{"atb":[[23,19.3]],"id":52385900},{"atl":[[20,17.24]],"id":52385907},{"atb":[[27,16]],"id":52385886},{"atl":[[48,12.77]],"id":52385917},{"atb":[[28,11.4]],"id":52385897},{"atl":[[80,7.59]],"id":52385897},{"atb":[[13.5,16.4]],"id":52385905},{"atb":[[24,16]],"id":52385899}],"con":true,"img":false}]}
{"op":"mcm","clk":"11550482402","pt":1719499007824,"mc":[{"id":"1.230178170","rc":[{"atl":[[85,7],[90,0]],"id":52385889},{"atb":[[17.5,19]],"id":52385904},{"atb":[[2.54,64.94],[2.42,0]],"id":52385900},{"atb":[[25,0]],"id":52385917},{"atb":[[2.9,0],[3.05,49.68]],"id":52385897}],"con":true,"img":false}]}
{"op":"mcm","clk":"11550482409","pt":1719499007924,"mc":[{"id":"1.230178170","rc":[{"atl":[[65,0]],"id":52385918},{"atl":[[50,0]],"id":52385889},{"atl":[[42,0]],"id":52385914},{"atb":[[21,0]],"id":52385896},{"atl":[[60,0]],"id":52385890},{"atb":[[30,0]],"id":52385892},{"atl":[[27,0]],"id":52385904},{"atb":[[14,0]],"id":52385898},{"atl":[[55,2.5]],"id":52385917},{"atb":[[13,6]],"id":52385905}],"con":true,"img":false}]}
{"op":"mcm","clk":"11550482417","pt":1719499008028,"mc":[{"id":"1.230178170","rc":[{"atl":[[60,10.17]],"id":52385889},{"atl":[[46,13.33]],"id":52385914},{"atl":[[65,9.38]],"id":52385890},{"atb":[[14.5,3.3]],"id":52385904},{"atl":[[29,21.43]],"id":52385904},{"atb":[[19.5,32.43]],"id":52385917}],"con":true,"img":false}]}
{"op":"mcm","clk":"11550482432","pt":1719499008236,"mc":[{"id":"1.230178170","rc":[{"atl":[[46,0]],"id":52385914}],"con":true,"img":false}]}
{"op":"mcm","clk":"11550482441","pt":1719499008333,"mc":[{"id":"1.230178170","rc":[{"atl":[[48,12.77]],"id":52385914},{"atl":[[29,0]],"id":52385904}],"con":true,"img":false}]}
{"op":"mcm","clk":"11550482448","pt":1719499008386,"mc":[{"id":"1.230178170","rc":[{"atl":[[32,19.35]],"id":52385904}],"con":true,"img":false}]}
{"op":"mcm","clk":"11550482480","pt":1719499008910,"mc":[{"id":"1.230178170","rc":[{"atl":[[180,2],[250,0]],"id":52385912},{"atl":[[70,2],[85,5]],"id":52385889},{"atl":[[85,2],[100,0]],"id":52385914},{"atl":[[160,0],[110,2]],"id":52385883},{"atl":[[270,0],[190,2]],"id":52385885},{"atl":[[260,0],[210,2]],"id":52385892},{"atl":[[65,0],[55,2]],"id":52385904},{"atl":[[80,2],[100,0]],"id":52385900},{"atl":[[70,2],[85,0]],"id":52385913},{"atl":[[32,0],[27,3.85]],"id":52385907},{"atl":[[90,2],[120,0]],"id":52385886},{"atl":[[140,0],[110,2]],"id":52385882},{"atl":[[75,0],[60,2]],"id":52385884},{"atl":[[70,2],[90,0]],"id":52385917},{"atl":[[170,2],[220,0]],"id":52385899}],"con":true,"img":false}]}
{"op":"mcm","clk":"11550482486","pt":1719499008998,"mc":[{"id":"1.230178170","rc":[{"atb":[[20,20.6]],"id":52385884}],"con":true,"img":false}]}
{"op":"mcm","clk":"11550482494","pt":1719499009102,"mc":[{"id":"1.230178170","rc":[{"atb":[[18,22]],"id":52385906}],"con":true,"img":false}]}
{"op":"mcm","clk":"11550482500","pt":1719499009213,"mc":[{"id":"1.230178170","rc":[{"atb":[[16,0]],"id":52385906},{"atb":[[19.5,4.5]],"id":52385884}],"con":true,"img":false}]}
{"op":"mcm","clk":"11550482575","pt":1719499010340,"mc":[{"id":"1.230178170","rc":[{"atb":[[32,19.35]],"id":52385911}],"con":true,"img":false}]}
{"op":"mcm","clk":"11550482586","pt":1719499010491,"mc":[{"id":"1.230178170","rc":[{"atb":[[29,0]],"id":52385911}],"con":true,"img":false}]}
{"op":"mcm","clk":"11550482601","pt":1719499010695,"mc":[{"id":"1.230178170","rc":[{"atb":[[17.5,22]],"id":52385882}],"con":true,"img":false}]}
{"op":"mcm","clk":"11550482613","pt":1719499010909,"mc":[{"id":"1.230178170","rc":[{"atb":[[16.5,0]],"id":52385882}],"con":true,"img":false}]}
{"op":"mcm","clk":"11550482758","pt":1719499012708,"mc":[{"id":"1.230178170","rc":[{"atl":[[32,20.63]],"id":52385913}],"con":true,"img":false}]}
{"op":"mcm","clk":"11550482769","pt":1719499012913,"mc":[{"id":"1.230178170","rc":[{"atl":[[34,0]],"id":52385913}],"con":true,"img":false}]}
{"op":"mcm","clk":"11550482929","pt":1719499014715,"mc":[{"id":"1.230178170","rc":[{"atb":[[30,20.69]],"id":52385882}],"con":true,"img":false}]}
{"op":"mcm","clk":"11550482942","pt":1719499014916,"mc":[{"id":"1.230178170","rc":[{"atb":[[17.5,0]],"id":52385882}],"con":true,"img":false}]}
{"op":"mcm","clk":"11550482955","pt":1719499015025,"mc":[{"id":"1.230178170","rc":[{"atb":[[25,0]],"id":52385883},{"atb":[[29,0]],"id":52385885}],"con":true,"img":false}]}
{"op":"mcm","clk":"11550482962","pt":1719499015133,"mc":[{"id":"1.230178170","rc":[{"atb":[[22,19.2]],"id":52385883},{"atb":[[26,21.76]],"id":52385885}],"con":true,"img":false}]}
{"op":"mcm","clk":"11550483073","pt":1719499016519,"mc":[{"id":"1.230178170","rc":[{"atb":[[10.5,10.28],[8.8,0]],"id":52385910},{"atb":[[16.5,26.1]],"id":52385920},{"atb":[[16,6.67],[18,0]],"id":52385885},{"atl":[[130,5],[150,0],[95,2.5],[110,0]],"id":52385885},{"atb":[[5.5,0],[6,15]],"id":52385896},{"atb":[[5,0],[4.1,32.26]],"id":52385890},{"atl":[[140,0],[160,5],[100,0],[120,2.5]],"id":52385892},{"atb":[[2.54,0],[1.78,128.21]],"id":52385900},{"atb":[[5,0],[3.75,7.81]],"id":52385911},{"atl":[[85,2],[90,0]],"id":52385886},{"atb":[[3.7,37.04],[4.7,0]],"id":52385919},{"atl":[[48,0]],"id":52385919},{"atb":[[20,0]],"id":52385884},{"atb":[[1.7,142.86],[3.05,0.9]],"id":52385897}],"con":true,"img":false}]}
{"op":"mcm","clk":"11550483084","pt":1719499016634,"mc":[{"id":"1.230178170","rc":[{"atb":[[17.5,0]],"id":52385904},{"atl":[[60,10.17]],"id":52385919}],"con":true,"img":false}]}
{"op":"mcm","clk":"11550483091","pt":1719499016727,"mc":[{"id":"1.230178170","rc":[{"atb":[[17,22]],"id":52385904}],"con":true,"img":false}]}
{"op":"mcm","clk":"11550483106","pt":1719499016930,"mc":[{"id":"1.230178170","rc":[{"atb":[[17,0]],"id":52385904}],"con":true,"img":false}]}
{"op":"mcm","clk":"11550483114","pt":1719499017035,"mc":[{"id":"1.230178170","rc":[{"atb":[[16.5,19]],"id":52385904}],"con":true,"img":false}]}
{"op":"mcm","clk":"11550483163","pt":1719499017609,"mc":[{"id":"1.230178170","rc":[{"atb":[[10,2.5],[9.8,0]],"id":52385906},{"atl":[[70,5],[75,0],[50,2.5],[55,0]],"id":52385896}],"con":true,"img":false}]}
{"op":"mcm","clk":"11550483212","pt":1719499018126,"mc":[{"id":"1.230178170","rc":[{"atl":[[36,0]],"id":52385891}],"con":true,"img":false}]}
{"op":"mcm","clk":"11550483222","pt":1719499018234,"mc":[{"id":"1.230178170","rc":[{"atl":[[38,15.12]],"id":52385891}],"con":true,"img":false}]}
{"op":"mcm","clk":"11550483241","pt":1719499018435,"mc":[{"id":"1.230178170","rc":[{"atl":[[38,0]],"id":52385891}],"con":true,"img":false}]}
{"op":"mcm","clk":"11550483251","pt":1719499018539,"mc":[{"id":"1.230178170","rc":[{"atl":[[44,13.95]],"id":52385891}],"con":true,"img":false}]}
{"op":"mcm","clk":"11550483320","pt":1719499019313,"mc":[{"id":"1.230178170","rc":[{"atb":[[20,0]],"id":52385883}],"con":true,"img":false}]}
{"op":"mcm","clk":"11550483342","pt":1719499019514,"mc":[{"id":"1.230178170","rc":[{"atb":[[23,12.2]],"id":52385883},{"atb":[[27,16.6]],"id":52385885},{"atl":[[30,20.69]],"id":52385904},{"atb":[[16,29]],"id":52385898},{"atl":[[60,10.17]],"id":52385897}],"con":true,"img":false}]}
{"op":"mcm","clk":"11550483360","pt":1719499019714,"mc":[{"id":"1.230178170","rc":[{"atb":[[22,0]],"id":52385883},{"atb":[[26,0]],"id":52385885},{"atl":[[32,0]],"id":52385904},{"atb":[[14.5,4]],"id":52385898},{"atl":[[80,0]],"id":52385897}],"con":true,"img":false}]}
{"op":"mcm","clk":"11550483419","pt":1719499020336,"mc":[{"id":"1.230178170","rc":[{"atb":[[25,0]],"id":52385912},{"atl":[[65,2.49]],"id":52385889},{"atl":[[50,0]],"id":52385914},{"atb":[[21,0]],"id":52385883},{"atb":[[25,0]],"id":52385885},{"atl":[[90,6.74]],"id":52385885},{"atb":[[22,23.12]],"id":52385896},{"atb":[[29,0]],"id":52385890},{"atl":[[70,2.5]],"id":52385890},{"atb":[[32,0]],"id":52385892},{"atb":[[14.5,0]],"id":52385904},{"atl":[[40,2.5]],"id":52385904},{"atb":[[30,0]],"id":52385911},{"atb":[[9.4,0]],"id":52385907},{"atl":[[21,0]],"id":52385907},{"atl":[[80,5]],"id":52385886},{"atl":[[65,2.5]],"id":52385919},{"atb":[[18.5,0]],"id":52385921},{"atb":[[17,0]],"id":52385882},{"atl":[[50,2.5]],"id":52385884},{"atb":[[17.5,0]],"id":52385917},{"atl":[[50,0]],"id":52385917},{"atb":[[27,0]],"id":52385897},{"atb":[[23,0]],"id":52385899}],"con":true,"img":false}]}
{"op":"mcm","clk":"11550483438","pt":1719499020543,"mc":[{"id":"1.230178170","rc":[{"atb":[[24,3.42],[27,2.3]],"id":52385912},{"atl":[[38,5.77]],"id":52385920},{"atl":[[55,2]],"id":52385889},{"atl":[[46,2],[48,0]],"id":52385914},{"atb":[[23,14.91]],"id":52385883},{"atb":[[27,20.2]],"id":52385885},{"atl":[[75,3]],"id":52385885},{"atb":[[22,0],[23,2.6]],"id":52385896},{"atl":[[23,0]],"id":52385896},{"trd":[[23,2]],"ltp":23.0,"tv":2.0,"id":52385896},{"atb":[[32,3.3],[28,3.25]],"id":52385890},{"atl":[[60,2]],"id":52385890},{"atb":[[36,2.6]],"id":52385892},{"atb":[[17,4.21]],"id":52385904},{"atl":[[30,24.28]],"id":52385904},{"atb":[[32,0],[34,3]],"id":52385911},{"atb":[[8.6,4]],"id":52385907},{"atl":[[25,2.37]],"id":52385907},{"atl":[[55,2.5]],"id":52385886},{"atl":[[55,2.51]],"id":52385919},{"atb":[[16.5,6.28]],"id":52385921},{"atb":[[16.5,3.17]],"id":52385882},{"atl":[[34,3]],"id":52385884},{"atb":[[20,4]],"id":52385917},{"atl":[[46,2.7],[48,0]],"id":52385917},{"atb":[[29,2]],"id":52385897},{"atb":[[25,3.6]],"id":52385899}],"con":true,"img":false}]}
{"op":"mcm","clk":"11550483447","pt":1719499020646,"mc":[{"id":"1.230178170","rc":[{"atl":[[50,12.24]],"id":52385889},{"atl":[[50,12.24]],"id":52385914},{"atl":[[75,11.11]],"id":52385885},{"atb":[[21,21]],"id":52385896},{"atl":[[70,7],[38,0],[80,0]],"id":52385896},{"atb":[[34,13.1]],"id":52385890},{"atl":[[60,12.17]],"id":52385890},{"atb":[[38,15.2]],"id":52385892},{"atb":[[17,26.21]],"id":52385904},{"atb":[[30,20]],"id":52385911},{"atl":[[50,12.24]],"id":52385886},{"atl":[[32,15]],"id":52385884},{"atb":[[20,17.4]],"id":52385917},{"atl":[[50,12.24]],"id":52385917},{"atb":[[26,3.3],[30,20.69]],"id":52385897},{"atb":[[22,3.25],[26,22]],"id":52385899}],"con":true,"img":false}]}
{"op":"mcm","clk":"11550483454","pt":1719499020701,"mc":[{"id":"1.230178170","rc":[{"atb":[[28,16.84]],"id":52385912},{"atb":[[24,3.32]],"id":52385885},{"atl":[[90,0]],"id":52385885},{"atl":[[40,15.2]],"id":52385896},{"atb":[[28,0]],"id":52385890},{"atb":[[34,0]],"id":52385892},{"atb":[[19.5,0]],"id":52385917},{"atb":[[28,0]],"id":52385897},{"atb":[[24,0]],"id":52385899}],"con":true,"img":false}]}
{"op":"mcm","clk":"11550483463","pt":1719499020803,"mc":[{"id":"1.230178170","rc":[{"atl":[[60,0]],"id":52385889},{"atb":[[30,0]],"id":52385890},{"atl":[[65,0]],"id":52385890},{"atb":[[16.5,0]],"id":52385904},{"atl":[[60,2.5]],"id":52385886},{"atl":[[36,1]],"id":52385884}],"con":true,"img":false}]}
{"op":"mcm","clk":"11550483473","pt":1719499020911,"mc":[{"id":"1.230178170","rc":[{"atb":[[26,0]],"id":52385912},{"atb":[[24,0]],"id":52385885},{"atl":[[38,16.22]],"id":52385896},{"atb":[[26,0]],"id":52385897}],"con":true,"img":false}]}
{"op":"mcm","clk":"11550483484","pt":1719499021016,"mc":[{"id":"1.230178170","rc":[{"atb":[[24,0]],"id":52385912},{"atl":[[40,0]],"id":52385896},{"atb":[[22,0]],"id":52385899}],"con":true,"img":false}]}
{"op":"mcm","clk":"11550483498","pt":1719499021226,"mc":[{"id":"1.230178170","rc":[{"atl":[[38,0]],"id":52385896}],"con":true,"img":false}]}
{"op":"mcm","clk":"11550483506","pt":1719499021321,"mc":[{"id":"1.230178170","rc":[{"atl":[[42,14.63]],"id":52385896}],"con":true,"img":false}]}
{"op":"mcm","clk":"11550483551","pt":1719499022040,"mc":[{"id":"1.230178170","rc":[{"atb":[[36,17.14]],"id":52385911}],"con":true,"img":false}]}
{"op":"mcm","clk":"11550483570","pt":1719499022202,"mc":[{"id":"1.230178170","rc":[{"atb":[[30,0]],"id":52385911}],"con":true,"img":false}]}
{"op":"mcm","clk":"11550483583","pt":1719499022404,"mc":[{"id":"1.230178170","rc":[{"atb":[[20,0]],"id":52385911}],"con":true,"img":false}]}
{"op":"mcm","clk":"11550483593","pt":1719499022621,"mc":[{"id":"1.230178170","rc":[{"atb":[[9.2,0],[6.8,17.2]],"id":52385918},{"atb":[[1.8,125],[4.1,0]],"id":52385890},{"atl":[[70,0],[85,2.5],[90,0],[110,5]],"id":52385890},{"atb":[[12,0],[8.4,10]],"id":52385892},{"atb":[[3.9,34.48]],"id":52385898},{"atb":[[1.55,150],[1.78,0]],"id":52385900},{"atb":[[1.94,106.38],[3.75,0]],"id":52385911},{"atb":[[27,0]],"id":52385886},{"atl":[[80,7],[85,0]],"id":52385886},{"atb":[[3.7,0],[3.3,43.48]],"id":52385919},{"atb":[[7.6,10],[8.8,0]],"id":52385884},{"atb":[[1.7,0]],"id":52385897},{"atl":[[65,2.9],[80,2.5],[85,0],[100,5]],"id":52385897},{"atb":[[23,17.68]],"id":52385891},{"atb":[[8.4,0],[5.9,20.41]],"id":52385893}],"con":true,"img":false}]}
{"op":"mcm","clk":"11550483602","pt":1719499022718,"mc":[{"id":"1.230178170","rc":[{"atb":[[4.8,0]],"id":52385898},{"atb":[[1.55,0]],"id":52385900},{"atb":[[26,16]],"id":52385886},{"atb":[[22,0]],"id":52385891}],"con":true,"img":false}]}
{"op":"mcm","clk":"11550483644","pt":1719499023336,"mc":[{"id":"1.230178170","rc":[{"atb":[[17,0],[17.5,2.5],[15,0]],"id":52385912},{"atb":[[16.5,2.5],[15,0]],"id":52385914},{"atb":[[19,0],[20,5],[22,0],[24,2.5]],"id":52385892},{"atb":[[16.5,0],[16,5],[18,2.5],[14.5,0]],"id":52385911},{"atb":[[12,0],[12.5,2.5]],"id":52385913},{"atl":[[32,17.5],[70,0],[40,5],[50,0]],"id":52385884},{"atl":[[25,2.5],[27,4],[29,5]],"id":52385903},{"atb":[[16,2.5],[13.5,0],[15.5,0]],"id":52385899}],"con":true,"img":false}]}
{"op":"mcm","clk":"11550483697","pt":1719499024113,"mc":[{"id":"1.230178170","rc":[{"atl":[[25,0]],"id":52385898}],"con":true,"img":false}]}
{"op":"mcm","clk":"11550483993","pt":1719499027722,"mc":[{"id":"1.230178170","rc":[{"atb":[[1.45,222.22]],"id":52385890},{"atl":[[65,5],[80,2],[48,2.5],[60,0]],"id":52385886}],"con":true,"img":false}]}
{"op":"mcm","clk":"11550484002","pt":1719499027828,"mc":[{"id":"1.230178170","rc":[{"atb":[[14,2.5]],"id":52385896},{"atb":[[1.8,0]],"id":52385890},{"atb":[[17.5,5],[19.5,2.5]],"id":52385897},{"atb":[[18,0],[19,5],[20,6],[22,2.5]],"id":52385893}],"con":true,"img":false}]}
{"op":"mcm","clk":"11550484011","pt":1719499027929,"mc":[{"id":"1.230178170","rc":[{"atb":[[10.5,0],[12.5,0]],"id":52385896},{"atb":[[1.94,0],[2.48,67.57]],"id":52385911},{"atb":[[16,0],[18,0]],"id":52385897}],"con":true,"img":false}]}
{"op":"mcm","clk":"11550484032","pt":1719499028138,"mc":[{"id":"1.230178170","rc":[{"atb":[[9,10],[6.8,0]],"id":52385918},{"atb":[[7.6,11],[6.6,0]],"id":52385920},{"atb":[[23,0]],"id":52385889},{"atb":[[6,2],[4.9,16]],"id":52385896},{"atb":[[2.72,58.14]],"id":52385890},{"atl":[[80,2.5],[85,0],[100,5],[110,0]],"id":52385890},{"atb":[[12,7.6],[8.4,0]],"id":52385892},{"atb":[[10,0],[9.2,0],[11,2.5],[3,50],[3.9,0]],"id":52385898},{"atb":[[12.5,5],[13.5,0],[14.5,2.5]],"id":52385900},{"atb":[[4.4,29.41],[2.48,0]],"id":52385911},{"atb":[[2.26,79.37]],"id":52385919},{"atb":[[23,2.56]],"id":52385891},{"atb":[[8.4,11]],"id":52385893}],"con":true,"img":false}]}
{"op":"mcm","clk":"11550484042","pt":1719499028243,"mc":[{"id":"1.230178170","rc":[{"atb":[[9.6,11.63],[22,28.57]],"id":52385889},{"atb":[[1.45,0]],"id":52385890},{"atb":[[3.3,0]],"id":52385919},{"atl":[[55,13.62]],"id":52385919},{"atb":[[30,0]],"id":52385882},{"atb":[[5.9,0]],"id":52385893}],"con":true,"img":false}]}
{"op":"mcm","clk":"11550484047","pt":1719499028341,"mc":[{"id":"1.230178170","rc":[{"atb":[[11,0]],"id":52385889},{"atb":[[29,21.43]],"id":52385882}],"con":true,"img":false}]}
{"op":"mcm","clk":"11550484056","pt":1719499028447,"mc":[{"id":"1.230178170","rc":[{"atb":[[22,0]],"id":52385889},{"atl":[[60,0]],"id":52385919}],"con":true,"img":false}]}
{"op":"mcm","clk":"11550484069","pt":1719499028551,"mc":[{"id":"1.230178170","rc":[{"atb":[[19.5,30]],"id":52385889},{"atb":[[29,0]],"id":52385882}],"con":true,"img":false}]}
{"op":"mcm","clk":"11550484077","pt":1719499028655,"mc":[{"id":"1.230178170","rc":[{"atb":[[29,16.34]],"id":52385882}],"con":true,"img":false}]}
{"op":"mcm","clk":"11550484179","pt":1719499029843,"mc":[{"id":"1.230178170","rc":[{"atl":[[42,14.63]],"id":52385891}],"con":true,"img":false}]}
{"op":"mcm","clk":"11550484195","pt":1719499030045,"mc":[{"id":"1.230178170","rc":[{"atl":[[44,0]],"id":52385891}],"con":true,"img":false}]}
{"op":"mcm","clk":"11550484219","pt":1719499030358,"mc":[{"id":"1.230178170","rc":[{"atl":[[34,2.5],[40,0],[42,5],[48,0]],"id":52385904},{"atl":[[95,0],[55,15.76]],"id":52385882}],"con":true,"img":false}]}
{"op":"mcm","clk":"11550484347","pt":1719499032114,"mc":[{"id":"1.230178170","rc":[{"atl":[[46,15.33]],"id":52385914},{"atb":[[23,29.87]],"id":52385896},{"atl":[[46,13.33]],"id":52385886},{"atl":[[44,13.95]],"id":52385917}],"con":true,"img":false}]}
{"op":"mcm","clk":"11550484356","pt":1719499032219,"mc":[{"id":"1.230178170","rc":[{"atl":[[40,15.38]],"id":52385896}],"con":true,"img":false}]}
{"op":"mcm","clk":"11550484366","pt":1719499032321,"mc":[{"id":"1.230178170","rc":[{"atb":[[21,0]],"id":52385896},{"atl":[[50,0]],"id":52385886},{"atl":[[50,0]],"id":52385917}],"con":true,"img":false}]}
{"op":"mcm","clk":"11550484376","pt":1719499032424,"mc":[{"id":"1.230178170","rc":[{"atl":[[50,0]],"id":52385914},{"atl":[[42,0]],"id":52385896}],"con":true,"img":false}]}
{"op":"mcm","clk":"11550484390","pt":1719499032634,"mc":[{"id":"1.230178170","rc":[{"atl":[[65,0],[60,2.5]],"id":52385883},{"atb":[[10,0],[9.2,0],[10.5,2.5],[9.4,5]],"id":52385904}],"con":true,"img":false}]}
{"op":"mcm","clk":"11550484445","pt":1719499033356,"mc":[{"id":"1.230178170","rc":[{"atb":[[27,0]],"id":52385912},{"atl":[[60,10.17]],"id":52385918},{"atl":[[55,0]],"id":52385889},{"atb":[[15.5,0]],"id":52385914},{"atb":[[23,12.2]],"id":52385883},{"atb":[[23,27.27]],"id":52385896},{"atb":[[32,0]],"id":52385890},{"atl":[[60,10.17]],"id":52385890},{"atb":[[36,0]],"id":52385892},{"atb":[[14.5,0]],"id":52385898},{"atl":[[34,2.5]],"id":52385898},{"atb":[[34,0]],"id":52385911},{"atb":[[13.5,0]],"id":52385913},{"atb":[[8.6,0]],"id":52385907},{"atl":[[25,0]],"id":52385907},{"atl":[[55,0]],"id":52385886},{"atb":[[16.5,2.5]],"id":52385921},{"atl":[[34,0]],"id":52385884},{"atl":[[46,0]],"id":52385917},{"atb":[[29,0]],"id":52385897},{"atl":[[65,0]],"id":52385897},{"atb":[[23,0]],"id":52385891},{"atl":[[27,0]],"id":52385903},{"atb":[[25,0]],"id":52385899}],"con":true,"img":false}]}
{"op":"mcm","clk":"11550484456","pt":1719499033459,"mc":[{"id":"1.230178170","rc":[{"atb":[[18.5,0],[20,5],[21,0],[24,2.5]],"id":52385918},{"atl":[[60,0]],"id":52385918},{"atl":[[29,0]],"id":52385920},{"atl":[[65,0],[80,5],[85,0],[60,2.5]],"id":52385889},{"atb":[[23,0]],"id":52385896},{"atb":[[34,0]],"id":52385890},{"atl":[[60,0]],"id":52385890},{"atb":[[36,0]],"id":52385911},{"atl":[[20,0]],"id":52385907},{"atb":[[16,0],[18,0],[18.5,5],[21,2.5]],"id":52385919},{"atb":[[16.5,0],[16,5],[18,2.5],[14.5,0]],"id":52385921},{"atl":[[44,0]],"id":52385917},{"atl":[[60,0]],"id":52385897},{"atb":[[22,20]],"id":52385891},{"atb":[[15.5,17]],"id":52385905}],"con":true,"img":false}]}
{"op":"mcm","clk":"11550484466","pt":1719499033570,"mc":[{"id":"1.230178170","rc":[{"atl":[[65,0],[75,5],[85,2],[55,16.21],[120,0]],"id":52385910},{"atb":[[6,12],[29,3.7]],"id":52385912},{"atl":[[130,0],[140,2],[80,2.5],[180,0],[95,0],[100,5]],"id":52385912},{"atb":[[9,0]],"id":52385918},{"atl":[[130,0],[180,2]],"id":52385918},{"atb":[[10.5,5],[11.5,0],[12.5,2.5],[17,26.44],[7.6,0],[9.8,0],[4.7,27.03]],"id":52385920},{"atl":[[46,5],[60,2]],"id":52385920},{"atl":[[48,3]],"id":52385889},{"atb":[[16.5,5.9],[7.6,0]],"id":52385914},{"atl":[[85,0]],"id":52385914},{"atb":[[16.5,4]],"id":52385883},{"atl":[[150,2],[190,0]],"id":52385885},{"atb":[[4.9,0],[14.5,5],[4.2,16]],"id":52385896},{"atl":[[38,2.72]],"id":52385896},{"atb":[[2.72,0],[27,2.4]],"id":52385890},{"atl":[[80,4.85]],"id":52385890},{"atb":[[40,3]],"id":52385892},{"atl":[[150,5],[160,0],[110,2.5],[120,0]],"id":52385892},{"atb":[[16.5,3.38],[3,0],[2.84,54.35]],"id":52385898},{"atl":[[32,3]],"id":52385898},{"atl":[[80,0],[44,0],[48,0],[110,2]],"id":52385900},{"atb":[[4.4,0],[28,3.6],[14.5,7.41]],"id":52385911},{"atl":[[130,5],[150,0],[170,2],[95,2.5],[110,0],[230,0]],"id":52385911},{"atb":[[9.6,0],[8,14.29],[20,0],[21,3.3]],"id":52385913},{"atl":[[70,0],[38,2.5],[42,0],[46,5],[50,0],[55,2]],"id":52385913},{"atb":[[13.5,5]],"id":52385907},{"atl":[[27,3],[30,3.45]],"id":52385907},{"atl":[[44,3.1]],"id":52385886},{"atb":[[2.26,0]],"id":52385919},{"atb":[[10,11.11],[13.5,0],[15,4]],"id":52385921},{"atl":[[30,2.4]],"id":52385884},{"atb":[[25,17],[6.6,12],[9.4,0]],"id":52385917},{"atl":[[70,0],[42,3],[85,2]],"id":52385917},{"atb":[[32,3.6]],"id":52385897},{"atl":[[75,2]],"id":52385897},{"atb":[[18,3.4]],"id":52385891},{"atb":[[1.4,239.78],[8.4,0]],"id":52385893},{"atl":[[65,9.38],[80,2.5],[85,0],[100,5]],"id":52385893},{"atb":[[7.8,0],[7,0]],"id":52385903},{"atl":[[36,0],[24,2.77],[28,25.92]],"id":52385903},{"atb":[[27,4]],"id":52385899}],"con":true,"img":false}]}
{"op":"mcm","clk":"11550484473","pt":1719499033625,"mc":[{"id":"1.230178170","rc":[{"atb":[[18,0]],"id":52385906},{"atl":[[70,0],[140,5],[85,7.14],[90,0],[100,2.5]],"id":52385918},{"atl":[[44,13.95]],"id":52385920},{"atb":[[10.5,10.53]],"id":52385914},{"atl":[[75,7]],"id":52385914},{"atb":[[22,19]],"id":52385896},{"atb":[[32,10]],"id":52385890},{"atl":[[65,9.38]],"id":52385890},{"atb":[[34,15]],"id":52385911},{"atl":[[27,15.7]],"id":52385907},{"atl":[[65,0],[110,5]],"id":52385919},{"atl":[[46,10]],"id":52385917},{"atl":[[65,9.38]],"id":52385897},{"atb":[[13.5,3.8],[15.5,0]],"id":52385905}],"con":true,"img":false}]}
{"op":"mcm","clk":"11550484480","pt":1719499033722,"mc":[{"id":"1.230178170","rc":[{"atb":[[30,17.4]],"id":52385912},{"atb":[[16.5,4.7]],"id":52385920},{"atl":[[46,13.33]],"id":52385889},{"atl":[[38,18.16]],"id":52385896},{"atb":[[42,14.63]],"id":52385892},{"atl":[[60,10.17]],"id":52385900},{"atb":[[18,25]],"id":52385913},{"atl":[[29,14]],"id":52385884},{"atb":[[20,4]],"id":52385917},{"atb":[[34,12.2]],"id":52385897},{"atl":[[75,2.5],[80,0],[95,5],[100,0]],"id":52385893},{"atb":[[28,22]],"id":52385899}],"con":true,"img":false}]}
{"op":"mcm","clk":"11550484488","pt":1719499033826,"mc":[{"id":"1.230178170","rc":[{"atb":[[14,28]],"id":52385906},{"atb":[[16.5,16.14]],"id":52385898},{"atb":[[13.5,48.6]],"id":52385905}],"con":true,"img":false}]}
{"op":"mcm","clk":"11550484499","pt":1719499033931,"mc":[{"id":"1.230178170","rc":[{"atb":[[28,0]],"id":52385912},{"atl":[[75,8.11],[85,0]],"id":52385918},{"atl":[[50,0]],"id":52385889},{"atl":[[40,0]],"id":52385896},{"atb":[[32,0]],"id":52385890},{"atl":[[65,0]],"id":52385890},{"atb":[[38,0]],"id":52385892},{"atb":[[34,0]],"id":52385911},{"atl":[[32,2.5]],"id":52385884},{"atb":[[30,0]],"id":52385897},{"atl":[[65,0]],"id":52385897},{"atb":[[26,0]],"id":52385899}],"con":true,"img":false}]}
{"op":"mcm","clk":"11550484508","pt":1719499034034,"mc":[{"id":"1.230178170","rc":[{"atb":[[29,21.43]],"id":52385890},{"atl":[[75,8.11]],"id":52385890},{"atb":[[16,0]],"id":52385898},{"atb":[[30,17.2]],"id":52385911},{"atl":[[70,8.7]],"id":52385897}],"con":true,"img":false}]}
{"op":"mcm","clk":"11550484517","pt":1719499034139,"mc":[{"id":"1.230178170","rc":[{"atl":[[75,0]],"id":52385918}],"con":true,"img":false}]}
{"op":"mcm","clk":"11550484524","pt":1719499034238,"mc":[{"id":"1.230178170","rc":[{"atl":[[90,6.74]],"id":52385918},{"atb":[[29,0]],"id":52385890}],"con":true,"img":false}]}
{"op":"mcm","clk":"11550484534","pt":1719499034341,"mc":[{"id":"1.230178170","rc":[{"atb":[[29,21.43]],"id":52385890},{"atb":[[13,0]],"id":52385907}],"con":true,"img":false}]}
{"op":"mcm","clk":"11550484545","pt":1719499034444,"mc":[{"id":"1.230178170","rc":[{"atl":[[90,0]],"id":52385918},{"atb":[[14,6]],"id":52385907}],"con":true,"img":false}]}
{"op":"mcm","clk":"11550484553","pt":1719499034546,"mc":[{"id":"1.230178170","rc":[{"atl":[[100,8.56]],"id":52385918},{"atb":[[29,0]],"id":52385890}],"con":true,"img":false}]}
{"op":"mcm","clk":"11550484563","pt":1719499034751,"mc":[{"id":"1.230178170","rc":[{"atb":[[27,22.1]],"id":52385890}],"con":true,"img":false}]}
{"op":"mcm","clk":"11550484670","pt":1719499036144,"mc":[{"id":"1.230178170","rc":[{"atl":[[32,2.5],[34,0],[40,5],[42,0]],"id":52385906}],"con":true,"img":false}]}
{"op":"mcm","clk":"11550484760","pt":1719499037334,"mc":[{"id":"1.230178170","rc":[{"atb":[[23,0]],"id":52385883}],"con":true,"img":false}]}
{"op":"mcm","clk":"11550484775","pt":1719499037540,"mc":[{"id":"1.230178170","rc":[{"atb":[[11,0],[22,9.8],[12.5,8]],"id":52385883}],"con":true,"img":false}]}
{"op":"mcm","clk":"11550484787","pt":1719499037743,"mc":[{"id":"1.230178170","rc":[{"atb":[[22,0]],"id":52385883}],"con":true,"img":false}]}
{"op":"mcm","clk":"11550484790","pt":1719499037842,"mc":[{"id":"1.230178170","rc":[{"atb":[[19.5,13]],"id":52385883},{"atb":[[28,22.22]],"id":52385885},{"atb":[[27,16.2]],"id":52385886}],"con":true,"img":false}]}
{"op":"mcm","clk":"11550484800","pt":1719499038050,"mc":[{"id":"1.230178170","rc":[{"atb":[[27,3.6]],"id":52385885},{"atb":[[26,0]],"id":52385886}],"con":true,"img":false}]}
