{"op":"mcm","clk":"11536832977","pt":1719431775509,"mc":[{"id":"1.230180125","marketDefinition":{"bspMarket":true,"turnInPlayEnabled":false,"persistenceEnabled":false,"marketBaseRate":5.0,"eventId":"33376437","eventTypeId":"4339","numberOfWinners":2,"bettingType":"ODDS","marketType":"PLACE","marketTime":"2024-06-27T15:26:00.000Z","suspendTime":"2024-06-27T15:26:00.000Z","bspReconciled":false,"complete":true,"inPlay":false,"crossMatching":false,"runnersVoidable":false,"numberOfActiveRunners":6,"betDelay":0,"status":"OPEN","runners":[{"status":"ACTIVE","sortPriority":1,"id":42767337,"name":"1. Salacres Liam"},{"status":"ACTIVE","sortPriority":2,"id":56263473,"name":"2. Makeit Spot"},{"status":"ACTIVE","sortPriority":3,"id":67245400,"name":"3. Lillibeth Royale"},{"status":"ACTIVE","sortPriority":4,"id":65992794,"name":"4. Come Back Kid"},{"status":"ACTIVE","sortPriority":5,"id":70902709,"name":"5. Cloud Canine"},{"status":"ACTIVE","sortPriority":6,"id":51567147,"name":"6. Coolemore North"}],"regulators":["MR_INT"],"venue":"Towcester","countryCode":"GB","discountAllowed":false,"timezone":"Europe/London","openDate":"2024-06-27T13:33:00.000Z","version":5994767109,"name":"To Be Placed","eventName":"Towcester 27th Jun"},"rc":[],"con":true,"img":false}]}
{"op":"mcm","clk":"11536833129","pt":1719431777510,"mc":[{"id":"1.230180125","marketDefinition":{"bspMarket":true,"turnInPlayEnabled":false,"persistenceEnabled":false,"marketBaseRate":5.0,"eventId":"33376437","eventTypeId":"4339","numberOfWinners":2,"bettingType":"ODDS","marketType":"PLACE","marketTime":"2024-06-27T15:26:00.000Z","suspendTime":"2024-06-27T15:26:00.000Z","bspReconciled":false,"complete":true,"inPlay":false,"crossMatching":false,"runnersVoidable":false,"numberOfActiveRunners":6,"betDelay":0,"status":"OPEN","runners":[{"status":"ACTIVE","sortPriority":1,"id":42767337,"name":"1. Salacres Liam"},{"status":"ACTIVE","sortPriority":2,"id":56263473,"name":"2. Makeit Spot"},{"status":"ACTIVE","sortPriority":3,"id":67245400,"name":"3. Lillibeth Royale"},{"status":"ACTIVE","sortPriority":4,"id":65992794,"name":"4. Come Back Kid"},{"status":"ACTIVE","sortPriority":5,"id":70902709,"name":"5. Cloud Canine"},{"status":"ACTIVE","sortPriority":6,"id":51567147,"name":"6. Coolemore North"}],"regulators":["MR_INT"],"venue":"Towcester","countryCode":"GB","discountAllowed":true,"timezone":"Europe/London","openDate":"2024-06-27T13:33:00.000Z","version":5994767109,"name":"To Be Placed","eventName":"Towcester 27th Jun"},"rc":[],"con":true,"img":false}]}
{"op":"mcm","clk":"11537083946","pt":1719435434393,"mc":[{"id":"1.230180125","rc":[{"atb":[[1.02,16.48]],"id":56263473},{"atl":[[1000,0.84]],"id":56263473},{"spn":500.51,"spf":"NaN","id":56263473},{"atb":[[1.02,16.48]],"id":65992794},{"atl":[[990,0.84]],"id":65992794},{"spn":495.51,"spf":"NaN","id":65992794},{"atb":[[1.02,16.48]],"id":67245400},{"atl":[[1000,0.84]],"id":67245400},{"spn":500.51,"spf":"NaN","id":67245400},{"atb":[[1.02,16.48]],"id":42767337},{"atl":[[990,0.84]],"id":42767337},{"spn":495.51,"spf":"NaN","id":42767337},{"atb":[[1.03,10.99]],"id":51567147},{"atl":[[990,0.84]],"id":51567147},{"spn":495.51,"spf":"NaN","id":51567147},{"atb":[[1.02,16.48]],"id":70902709},{"atl":[[990,0.84]],"id":70902709},{"spn":495.51,"spf":"NaN","id":70902709}],"con":true,"img":false}]}
{"op":"mcm","clk":"11537233733","pt":1719437882654,"mc":[{"id":"1.230180125","marketDefinition":{"bspMarket":true,"turnInPlayEnabled":false,"persistenceEnabled":false,"marketBaseRate":5.0,"eventId":"33376437","eventTypeId":"4339","numberOfWinners":2,"bettingType":"ODDS","marketType":"PLACE","marketTime":"2024-06-27T15:26:00.000Z","suspendTime":"2024-06-27T15:26:00.000Z","bspReconciled":false,"complete":true,"inPlay":false,"crossMatching":false,"runnersVoidable":false,"numberOfActiveRunners":6,"betDelay":0,"status":"OPEN","runners":[{"status":"ACTIVE","sortPriority":1,"id":42767337,"name":"1. Salacres Liam"},{"status":"ACTIVE","sortPriority":2,"id":56263473,"name":"2. Makeit Spot"},{"status":"ACTIVE","sortPriority":3,"id":67245400,"name":"3. Lillibeth Royale"},{"status":"ACTIVE","sortPriority":4,"id":65992794,"name":"4. Come Back Kid"},{"status":"ACTIVE","sortPriority":5,"id":70902709,"name":"5. Cloud Canine"},{"status":"ACTIVE","sortPriority":6,"id":51567147,"name":"6. Coolemore North"}],"regulators":["MR_INT"],"venue":"Towcester","countryCode":"GB","discountAllowed":true,"timezone":"Europe/London","openDate":"2024-06-27T13:33:00.000Z","version":5994767109,"name":"To Be Placed","eventName":"Towcester 27th Jun"},"rc":[{"atb":[[1.02,16.48]],"id":56263473},{"atl":[[1000,0.84]],"id":56263473},{"spn":500.51,"spf":"NaN","id":56263473},{"atb":[[1.02,16.48]],"id":65992794},{"atl":[[990,0.84]],"id":65992794},{"spn":495.51,"spf":"NaN","id":65992794},{"atb":[[1.02,16.48]],"id":67245400},{"atl":[[1000,0.84]],"id":67245400},{"spn":500.51,"spf":"NaN","id":67245400},{"atb":[[1.02,16.48]],"id":42767337},{"atl":[[990,0.84]],"id":42767337},{"spn":495.51,"spf":"NaN","id":42767337},{"atb":[[1.03,10.99]],"id":51567147},{"atl":[[990,0.84]],"id":51567147},{"spn":495.51,"spf":"NaN","id":51567147},{"atb":[[1.02,16.48]],"id":70902709},{"atl":[[990,0.84]],"id":70902709},{"spn":495.51,"spf":"NaN","id":70902709}],"con":true,"img":true}]}
{"op":"mcm","clk":"11537302229","pt":1719439032538,"mc":[{"id":"1.230180125","rc":[{"atb":[[1.02,16.48]],"id":56263473},{"atl":[[1000,0.17]],"id":56263473},{"atb":[[1.02,16.48]],"id":65992794},{"atl":[[990,0.17]],"id":65992794},{"atb":[[1.02,16.48]],"id":67245400},{"atl":[[1000,0.17]],"id":67245400},{"atb":[[1.02,16.48]],"id":42767337},{"atl":[[990,0.17]],"id":42767337},{"atb":[[1.03,10.99]],"id":51567147},{"atl":[[990,0.17]],"id":51567147},{"atb":[[1.02,16.48]],"id":70902709},{"atl":[[990,0.17]],"id":70902709}],"con":true,"img":false}]}
{"op":"mcm","clk":"11537574884","pt":1719443282705,"mc":[{"id":"1.230180125","marketDefinition":{"bspMarket":true,"turnInPlayEnabled":false,"persistenceEnabled":false,"marketBaseRate":5.0,"eventId":"33376437","eventTypeId":"4339","numberOfWinners":2,"bettingType":"ODDS","marketType":"PLACE","marketTime":"2024-06-27T15:26:00.000Z","suspendTime":"2024-06-27T15:26:00.000Z","bspReconciled":false,"complete":true,"inPlay":false,"crossMatching":false,"runnersVoidable":false,"numberOfActiveRunners":6,"betDelay":0,"status":"OPEN","runners":[{"status":"ACTIVE","sortPriority":1,"id":42767337,"name":"1. Salacres Liam"},{"status":"ACTIVE","sortPriority":2,"id":56263473,"name":"2. Makeit Spot"},{"status":"ACTIVE","sortPriority":3,"id":67245400,"name":"3. Lillibeth Royale"},{"status":"ACTIVE","sortPriority":4,"id":65992794,"name":"4. Come Back Kid"},{"status":"ACTIVE","sortPriority":5,"id":70902709,"name":"5. Cloud Canine"},{"status":"ACTIVE","sortPriority":6,"id":51567147,"name":"6. Coolemore North"}],"regulators":["MR_INT"],"venue":"Towcester","countryCode":"GB","discountAllowed":true,"timezone":"Europe/London","openDate":"2024-06-27T13:33:00.000Z","version":5994767109,"name":"To Be Placed","eventName":"Towcester 27th Jun"},"rc":[{"atb":[[1.02,16.48]],"id":56263473},{"atl":[[1000,0.17]],"id":56263473},{"spn":500.51,"spf":"NaN","id":56263473},{"atb":[[1.02,16.48]],"id":65992794},{"atl":[[990,0.17]],"id":65992794},{"spn":495.51,"spf":"NaN","id":65992794},{"atb":[[1.02,16.48]],"id":67245400},{"atl":[[1000,0.17]],"id":67245400},{"spn":500.51,"spf":"NaN","id":67245400},{"atb":[[1.02,16.48]],"id":42767337},{"atl":[[990,0.17]],"id":42767337},{"spn":495.51,"spf":"NaN","id":42767337},{"atb":[[1.03,10.99]],"id":51567147},{"atl":[[990,0.17]],"id":51567147},{"spn":495.51,"spf":"NaN","id":51567147},{"atb":[[1.02,16.48]],"id":70902709},{"atl":[[990,0.17]],"id":70902709},{"spn":495.51,"spf":"NaN","id":70902709}],"con":true,"img":true}]}
{"op":"mcm","clk":"11537956504","pt":1719448682746,"mc":[{"id":"1.230180125","marketDefinition":{"bspMarket":true,"turnInPlayEnabled":false,"persistenceEnabled":false,"marketBaseRate":5.0,"eventId":"33376437","eventTypeId":"4339","numberOfWinners":2,"bettingType":"ODDS","marketType":"PLACE","marketTime":"2024-06-27T15:26:00.000Z","suspendTime":"2024-06-27T15:26:00.000Z","bspReconciled":false,"complete":true,"inPlay":false,"crossMatching":false,"runnersVoidable":false,"numberOfActiveRunners":6,"betDelay":0,"status":"OPEN","runners":[{"status":"ACTIVE","sortPriority":1,"id":42767337,"name":"1. Salacres Liam"},{"status":"ACTIVE","sortPriority":2,"id":56263473,"name":"2. Makeit Spot"},{"status":"ACTIVE","sortPriority":3,"id":67245400,"name":"3. Lillibeth Royale"},{"status":"ACTIVE","sortPriority":4,"id":65992794,"name":"4. Come Back Kid"},{"status":"ACTIVE","sortPriority":5,"id":70902709,"name":"5. Cloud Canine"},{"status":"ACTIVE","sortPriority":6,"id":51567147,"name":"6. Coolemore North"}],"regulators":["MR_INT"],"venue":"Towcester","countryCode":"GB","discountAllowed":true,"timezone":"Europe/London","openDate":"2024-06-27T13:33:00.000Z","version":5994767109,"name":"To Be Placed","eventName":"Towcester 27th Jun"},"rc":[{"atb":[[1.02,16.48]],"id":56263473},{"atl":[[1000,0.17]],"id":56263473},{"spn":500.51,"spf":"NaN","id":56263473},{"atb":[[1.02,16.48]],"id":65992794},{"atl":[[990,0.17]],"id":65992794},{"spn":495.51,"spf":"NaN","id":65992794},{"atb":[[1.02,16.48]],"id":67245400},{"atl":[[1000,0.17]],"id":67245400},{"spn":500.51,"spf":"NaN","id":67245400},{"atb":[[1.02,16.48]],"id":42767337},{"atl":[[990,0.17]],"id":42767337},{"spn":495.51,"spf":"NaN","id":42767337},{"atb":[[1.03,10.99]],"id":51567147},{"atl":[[990,0.17]],"id":51567147},{"spn":495.51,"spf":"NaN","id":51567147},{"atb":[[1.02,16.48]],"id":70902709},{"atl":[[990,0.17]],"id":70902709},{"spn":495.51,"spf":"NaN","id":70902709}],"con":true,"img":true}]}
{"op":"mcm","clk":"11538172121","pt":1719454082689,"mc":[{"id":"1.230180125","marketDefinition":{"bspMarket":true,"turnInPlayEnabled":false,"persistenceEnabled":false,"marketBaseRate":5.0,"eventId":"33376437","eventTypeId":"4339","numberOfWinners":2,"bettingType":"ODDS","marketType":"PLACE","marketTime":"2024-06-27T15:26:00.000Z","suspendTime":"2024-06-27T15:26:00.000Z","bspReconciled":false,"complete":true,"inPlay":false,"crossMatching":false,"runnersVoidable":false,"numberOfActiveRunners":6,"betDelay":0,"status":"OPEN","runners":[{"status":"ACTIVE","sortPriority":1,"id":42767337,"name":"1. Salacres Liam"},{"status":"ACTIVE","sortPriority":2,"id":56263473,"name":"2. Makeit Spot"},{"status":"ACTIVE","sortPriority":3,"id":67245400,"name":"3. Lillibeth Royale"},{"status":"ACTIVE","sortPriority":4,"id":65992794,"name":"4. Come Back Kid"},{"status":"ACTIVE","sortPriority":5,"id":70902709,"name":"5. Cloud Canine"},{"status":"ACTIVE","sortPriority":6,"id":51567147,"name":"6. Coolemore North"}],"regulators":["MR_INT"],"venue":"Towcester","countryCode":"GB","discountAllowed":true,"timezone":"Europe/London","openDate":"2024-06-27T13:33:00.000Z","version":5994767109,"name":"To Be Placed","eventName":"Towcester 27th Jun"},"rc":[{"atb":[[1.02,16.48]],"id":56263473},{"atl":[[1000,0.17]],"id":56263473},{"spn":500.51,"spf":"NaN","id":56263473},{"atb":[[1.02,16.48]],"id":65992794},{"atl":[[990,0.17]],"id":65992794},{"spn":495.51,"spf":"NaN","id":65992794},{"atb":[[1.02,16.48]],"id":67245400},{"atl":[[1000,0.17]],"id":67245400},{"spn":500.51,"spf":"NaN","id":67245400},{"atb":[[1.02,16.48]],"id":42767337},{"atl":[[990,0.17]],"id":42767337},{"spn":495.51,"spf":"NaN","id":42767337},{"atb":[[1.03,10.99]],"id":51567147},{"atl":[[990,0.17]],"id":51567147},{"spn":495.51,"spf":"NaN","id":51567147},{"atb":[[1.02,16.48]],"id":70902709},{"atl":[[990,0.17]],"id":70902709},{"spn":495.51,"spf":"NaN","id":70902709}],"con":true,"img":true}]}
{"op":"mcm","clk":"11538369788","pt":1719459482774,"mc":[{"id":"1.230180125","marketDefinition":{"bspMarket":true,"turnInPlayEnabled":false,"persistenceEnabled":false,"marketBaseRate":5.0,"eventId":"33376437","eventTypeId":"4339","numberOfWinners":2,"bettingType":"ODDS","marketType":"PLACE","marketTime":"2024-06-27T15:26:00.000Z","suspendTime":"2024-06-27T15:26:00.000Z","bspReconciled":false,"complete":true,"inPlay":false,"crossMatching":false,"runnersVoidable":false,"numberOfActiveRunners":6,"betDelay":0,"status":"OPEN","runners":[{"status":"ACTIVE","sortPriority":1,"id":42767337,"name":"1. Salacres Liam"},{"status":"ACTIVE","sortPriority":2,"id":56263473,"name":"2. Makeit Spot"},{"status":"ACTIVE","sortPriority":3,"id":67245400,"name":"3. Lillibeth Royale"},{"status":"ACTIVE","sortPriority":4,"id":65992794,"name":"4. Come Back Kid"},{"status":"ACTIVE","sortPriority":5,"id":70902709,"name":"5. Cloud Canine"},{"status":"ACTIVE","sortPriority":6,"id":51567147,"name":"6. Coolemore North"}],"regulators":["MR_INT"],"venue":"Towcester","countryCode":"GB","discountAllowed":true,"timezone":"Europe/London","openDate":"2024-06-27T13:33:00.000Z","version":5994767109,"name":"To Be Placed","eventName":"Towcester 27th Jun"},"rc":[{"atb":[[1.02,16.48]],"id":56263473},{"atl":[[1000,0.17]],"id":56263473},{"spn":500.51,"spf":"NaN","id":56263473},{"atb":[[1.02,16.48]],"id":65992794},{"atl":[[990,0.17]],"id":65992794},{"spn":495.51,"spf":"NaN","id":65992794},{"atb":[[1.02,16.48]],"id":67245400},{"atl":[[1000,0.17]],"id":67245400},{"spn":500.51,"spf":"NaN","id":67245400},{"atb":[[1.02,16.48]],"id":42767337},{"atl":[[990,0.17]],"id":42767337},{"spn":495.51,"spf":"NaN","id":42767337},{"atb":[[1.03,10.99]],"id":51567147},{"atl":[[990,0.17]],"id":51567147},{"spn":495.51,"spf":"NaN","id":51567147},{"atb":[[1.02,16.48]],"id":70902709},{"atl":[[990,0.17]],"id":70902709},{"spn":495.51,"spf":"NaN","id":70902709}],"con":true,"img":true}]}
{"op":"mcm","clk":"11538596918","pt":1719464882718,"mc":[{"id":"1.230180125","marketDefinition":{"bspMarket":true,"turnInPlayEnabled":false,"persistenceEnabled":false,"marketBaseRate":5.0,"eventId":"33376437","eventTypeId":"4339","numberOfWinners":2,"bettingType":"ODDS","marketType":"PLACE","marketTime":"2024-06-27T15:26:00.000Z","suspendTime":"2024-06-27T15:26:00.000Z","bspReconciled":false,"complete":true,"inPlay":false,"crossMatching":false,"runnersVoidable":false,"numberOfActiveRunners":6,"betDelay":0,"status":"OPEN","runners":[{"status":"ACTIVE","sortPriority":1,"id":42767337,"name":"1. Salacres Liam"},{"status":"ACTIVE","sortPriority":2,"id":56263473,"name":"2. Makeit Spot"},{"status":"ACTIVE","sortPriority":3,"id":67245400,"name":"3. Lillibeth Royale"},{"status":"ACTIVE","sortPriority":4,"id":65992794,"name":"4. Come Back Kid"},{"status":"ACTIVE","sortPriority":5,"id":70902709,"name":"5. Cloud Canine"},{"status":"ACTIVE","sortPriority":6,"id":51567147,"name":"6. Coolemore North"}],"regulators":["MR_INT"],"venue":"Towcester","countryCode":"GB","discountAllowed":true,"timezone":"Europe/London","openDate":"2024-06-27T13:33:00.000Z","version":5994767109,"name":"To Be Placed","eventName":"Towcester 27th Jun"},"rc":[{"atb":[[1.02,16.48]],"id":56263473},{"atl":[[1000,0.17]],"id":56263473},{"spn":500.51,"spf":"NaN","id":56263473},{"atb":[[1.02,16.48]],"id":65992794},{"atl":[[990,0.17]],"id":65992794},{"spn":495.51,"spf":"NaN","id":65992794},{"atb":[[1.02,16.48]],"id":67245400},{"atl":[[1000,0.17]],"id":67245400},{"spn":500.51,"spf":"NaN","id":67245400},{"atb":[[1.02,16.48]],"id":42767337},{"atl":[[990,0.17]],"id":42767337},{"spn":495.51,"spf":"NaN","id":42767337},{"atb":[[1.03,10.99]],"id":51567147},{"atl":[[990,0.17]],"id":51567147},{"spn":495.51,"spf":"NaN","id":51567147},{"atb":[[1.02,16.48]],"id":70902709},{"atl":[[990,0.17]],"id":70902709},{"spn":495.51,"spf":"NaN","id":70902709}],"con":true,"img":true}]}
{"op":"mcm","clk":"11538906751","pt":1719471498887,"mc":[{"id":"1.230180125","rc":[{"atb":[[1.02,16.48],[1.07,2.48]],"id":56263473},{"atl":[[1000,1.17]],"id":56263473},{"spn":500.53,"spf":"NaN","id":56263473},{"atb":[[1.02,16.48],[1.07,2.48]],"id":65992794},{"atl":[[1000,1]],"id":65992794},{"spn":495.53,"spf":"NaN","id":65992794},{"atb":[[1.02,16.48],[1.07,2.48]],"id":67245400},{"atl":[[1000,1.17]],"id":67245400},{"spn":500.53,"spf":"NaN","id":67245400},{"atb":[[1.02,16.48],[1.07,2.48]],"id":42767337},{"atl":[[1000,1]],"id":42767337},{"spn":495.53,"spf":"NaN","id":42767337},{"atb":[[1.03,10.99],[1.07,2.48]],"id":51567147},{"atl":[[1000,1]],"id":51567147},{"spn":495.53,"spf":"NaN","id":51567147},{"atb":[[1.02,16.48],[1.07,2.48]],"id":70902709},{"atl":[[1000,1]],"id":70902709},{"spn":495.53,"spf":"NaN","id":70902709}],"con":true,"img":false}]}
{"op":"mcm","clk":"11538906762","pt":1719471499095,"mc":[{"id":"1.230180125","rc":[{"atl":[[1000,0.65]],"id":56263473},{"atl":[[1000,0.48]],"id":65992794},{"atl":[[1000,0.65]],"id":67245400},{"atl":[[1000,0.48]],"id":42767337},{"atl":[[1000,0.48]],"id":51567147},{"atl":[[1000,0.48]],"id":70902709}],"con":true,"img":false}]}
{"op":"mcm","clk":"11538906770","pt":1719471499300,"mc":[{"id":"1.230180125","rc":[{"atl":[[1000,0.17]],"id":56263473},{"atl":[[1000,0]],"id":65992794},{"atl":[[1000,0.17]],"id":67245400},{"atl":[[1000,0]],"id":42767337},{"atl":[[1000,0]],"id":51567147},{"atl":[[1000,0]],"id":70902709}],"con":true,"img":false}]}
{"op":"mcm","clk":"11538906777","pt":1719471499404,"mc":[{"id":"1.230180125","rc":[{"atl":[[75,0.48]],"id":56263473},{"atl":[[75,0.48]],"id":65992794},{"atl":[[75,0.48]],"id":67245400},{"atl":[[75,0.48]],"id":42767337},{"atl":[[75,0.48]],"id":51567147},{"atl":[[75,0.48]],"id":70902709}],"con":true,"img":false}]}
{"op":"mcm","clk":"11539124106","pt":1719475682705,"mc":[{"id":"1.230180125","marketDefinition":{"bspMarket":true,"turnInPlayEnabled":false,"persistenceEnabled":false,"marketBaseRate":5.0,"eventId":"33376437","eventTypeId":"4339","numberOfWinners":2,"bettingType":"ODDS","marketType":"PLACE","marketTime":"2024-06-27T15:26:00.000Z","suspendTime":"2024-06-27T15:26:00.000Z","bspReconciled":false,"complete":true,"inPlay":false,"crossMatching":false,"runnersVoidable":false,"numberOfActiveRunners":6,"betDelay":0,"status":"OPEN","runners":[{"status":"ACTIVE","sortPriority":1,"id":42767337,"name":"1. Salacres Liam"},{"status":"ACTIVE","sortPriority":2,"id":56263473,"name":"2. Makeit Spot"},{"status":"ACTIVE","sortPriority":3,"id":67245400,"name":"3. Lillibeth Royale"},{"status":"ACTIVE","sortPriority":4,"id":65992794,"name":"4. Come Back Kid"},{"status":"ACTIVE","sortPriority":5,"id":70902709,"name":"5. Cloud Canine"},{"status":"ACTIVE","sortPriority":6,"id":51567147,"name":"6. Coolemore North"}],"regulators":["MR_INT"],"venue":"Towcester","countryCode":"GB","discountAllowed":true,"timezone":"Europe/London","openDate":"2024-06-27T13:33:00.000Z","version":5994767109,"name":"To Be Placed","eventName":"Towcester 27th Jun"},"rc":[{"atb":[[1.02,16.48],[1.07,2.48]],"id":56263473},{"atl":[[75,0.48],[1000,0.17]],"id":56263473},{"spn":38.03,"spf":"NaN","id":56263473},{"atb":[[1.02,16.48],[1.07,2.48]],"id":65992794},{"atl":[[75,0.48],[990,0.17]],"id":65992794},{"spn":38.03,"spf":"NaN","id":65992794},{"atb":[[1.02,16.48],[1.07,2.48]],"id":67245400},{"atl":[[75,0.48],[1000,0.17]],"id":67245400},{"spn":38.03,"spf":"NaN","id":67245400},{"atb":[[1.02,16.48],[1.07,2.48]],"id":42767337},{"atl":[[75,0.48],[990,0.17]],"id":42767337},{"spn":38.03,"spf":"NaN","id":42767337},{"atb":[[1.03,10.99],[1.07,2.48]],"id":51567147},{"atl":[[75,0.48],[990,0.17]],"id":51567147},{"spn":38.03,"spf":"NaN","id":51567147},{"atb":[[1.02,16.48],[1.07,2.48]],"id":70902709},{"atl":[[75,0.48],[990,0.17]],"id":70902709},{"spn":38.03,"spf":"NaN","id":70902709}],"con":true,"img":true}]}
{"op":"mcm","clk":"11539341337","pt":1719479309070,"mc":[{"id":"1.230180125","rc":[{"atb":[[1.02,16.47]],"id":56263473},{"spn":38.03,"spf":"NaN","id":56263473},{"spl":[[1.71,6]],"id":65992794},{"atb":[[1.02,16.47]],"id":65992794},{"spn":1.39,"spf":1.0,"id":65992794},{"atb":[[1.02,16.47]],"id":67245400},{"spn":38.03,"spf":"NaN","id":67245400},{"atb":[[1.02,16.47]],"id":42767337},{"spn":38.03,"spf":"NaN","id":42767337},{"atb":[[1.03,10.98]],"id":51567147},{"spn":38.03,"spf":"NaN","id":51567147},{"atb":[[1.02,16.47]],"id":70902709},{"spn":38.03,"spf":"NaN","id":70902709}],"con":true,"img":false}]}
{"op":"mcm","clk":"11540161447","pt":1719490656302,"mc":[{"id":"1.230180125","marketDefinition":{"bspMarket":true,"turnInPlayEnabled":false,"persistenceEnabled":false,"marketBaseRate":5.0,"eventId":"33376437","eventTypeId":"4339","numberOfWinners":2,"bettingType":"ODDS","marketType":"PLACE","marketTime":"2024-06-27T15:26:00.000Z","suspendTime":"2024-06-27T15:26:00.000Z","bspReconciled":false,"complete":true,"inPlay":false,"crossMatching":false,"runnersVoidable":false,"numberOfActiveRunners":6,"betDelay":0,"status":"SUSPENDED","runners":[{"status":"ACTIVE","sortPriority":1,"id":42767337,"name":"1. Salacres Liam"},{"status":"ACTIVE","sortPriority":2,"id":56263473,"name":"2. Makeit Spot"},{"status":"ACTIVE","sortPriority":3,"id":67245400,"name":"3. Lillibeth Royale"},{"status":"ACTIVE","sortPriority":4,"id":65992794,"name":"4. Come Back Kid"},{"status":"ACTIVE","sortPriority":5,"id":70902709,"name":"5. Cloud Canine"},{"status":"ACTIVE","sortPriority":6,"id":51567147,"name":"6. Coolemore North"}],"regulators":["MR_INT"],"venue":"Towcester","countryCode":"GB","discountAllowed":true,"timezone":"Europe/London","openDate":"2024-06-27T13:33:00.000Z","version":5995360156,"name":"To Be Placed","eventName":"Towcester 27th Jun"},"rc":[],"con":true,"img":false}]}
{"op":"mcm","clk":"11540161621","pt":1719490658770,"mc":[{"id":"1.230180125","marketDefinition":{"bspMarket":true,"turnInPlayEnabled":false,"persistenceEnabled":false,"marketBaseRate":5.0,"eventId":"33376437","eventTypeId":"4339","numberOfWinners":2,"bettingType":"ODDS","marketType":"PLACE","marketTime":"2024-06-27T15:26:00.000Z","suspendTime":"2024-06-27T15:26:00.000Z","bspReconciled":false,"complete":true,"inPlay":false,"crossMatching":false,"runnersVoidable":false,"numberOfActiveRunners":6,"betDelay":0,"status":"SUSPENDED","runners":[{"status":"ACTIVE","sortPriority":1,"id":42767337,"name":"1. Salacres Liam"},{"status":"ACTIVE","sortPriority":2,"id":56263473,"name":"2. Makeit Spot"},{"status":"ACTIVE","sortPriority":3,"id":67245400,"name":"3. Lillibeth Royale"},{"status":"ACTIVE","sortPriority":4,"id":65992794,"name":"4. Come Back Kid"},{"status":"ACTIVE","sortPriority":5,"id":70902709,"name":"5. Cloud Canine"},{"status":"ACTIVE","sortPriority":6,"id":51567147,"name":"6. Coolemore North"}],"regulators":["MR_INT"],"venue":"Towcester","countryCode":"GB","discountAllowed":true,"timezone":"Europe/London","openDate":"2024-06-27T13:33:00.000Z","version":5995360162,"name":"To Be Placed","eventName":"Towcester 27th Jun"},"rc":[],"con":true,"img":false}]}
{"op":"mcm","clk":"11540161621","pt":1719490658770,"mc":[{"id":"1.230180125","rc":[{"atb":[[1.02,0],[1.07,0]],"id":56263473},{"atl":[[75,0],[1000,0]],"id":56263473},{"atb":[[1.02,0],[1.07,0]],"id":65992794},{"atl":[[75,0],[990,0]],"id":65992794},{"atb":[[1.02,0],[1.07,0]],"id":67245400},{"atl":[[75,0],[1000,0]],"id":67245400},{"atb":[[1.02,0],[1.07,0]],"id":42767337},{"atl":[[75,0],[990,0]],"id":42767337},{"atb":[[1.03,0],[1.07,0]],"id":51567147},{"atl":[[75,0],[990,0]],"id":51567147},{"atb":[[1.02,0],[1.07,0]],"id":70902709},{"atl":[[75,0],[990,0]],"id":70902709}],"con":true,"img":false}]}
{"op":"mcm","clk":"11540161678","pt":1719490659312,"mc":[{"id":"1.230180125","marketDefinition":{"bspMarket":true,"turnInPlayEnabled":false,"persistenceEnabled":false,"marketBaseRate":5.0,"eventId":"33376437","eventTypeId":"4339","numberOfWinners":2,"bettingType":"ODDS","marketType":"PLACE","marketTime":"2024-06-27T15:26:00.000Z","suspendTime":"2024-06-27T15:26:00.000Z","bspReconciled":false,"complete":true,"inPlay":false,"crossMatching":false,"runnersVoidable":false,"numberOfActiveRunners":5,"betDelay":0,"status":"SUSPENDED","runners":[{"status":"ACTIVE","sortPriority":1,"id":42767337,"name":"1. Salacres Liam"},{"status":"ACTIVE","sortPriority":2,"id":67245400,"name":"3. Lillibeth Royale"},{"status":"ACTIVE","sortPriority":3,"id":65992794,"name":"4. Come Back Kid"},{"status":"ACTIVE","sortPriority":4,"id":70902709,"name":"5. Cloud Canine"},{"status":"ACTIVE","sortPriority":5,"id":51567147,"name":"6. Coolemore North"},{"status":"REMOVED","sortPriority":6,"removalDate":"2024-06-27T12:17:39.000Z","id":56263473,"name":"2. Makeit Spot"}],"regulators":["MR_INT"],"venue":"Towcester","countryCode":"GB","discountAllowed":true,"timezone":"Europe/London","openDate":"2024-06-27T13:33:00.000Z","version":5995360206,"name":"To Be Placed","eventName":"Towcester 27th Jun"},"rc":[],"con":true,"img":false}]}
{"op":"mcm","clk":"11540161690","pt":1719490659439,"mc":[{"id":"1.230180125","marketDefinition":{"bspMarket":true,"turnInPlayEnabled":false,"persistenceEnabled":false,"marketBaseRate":5.0,"eventId":"33376437","eventTypeId":"4339","numberOfWinners":2,"bettingType":"ODDS","marketType":"PLACE","marketTime":"2024-06-27T15:26:00.000Z","suspendTime":"2024-06-27T15:26:00.000Z","bspReconciled":false,"complete":true,"inPlay":false,"crossMatching":false,"runnersVoidable":false,"numberOfActiveRunners":5,"betDelay":0,"status":"OPEN","runners":[{"status":"ACTIVE","sortPriority":1,"id":42767337,"name":"1. Salacres Liam"},{"status":"ACTIVE","sortPriority":2,"id":67245400,"name":"3. Lillibeth Royale"},{"status":"ACTIVE","sortPriority":3,"id":65992794,"name":"4. Come Back Kid"},{"status":"ACTIVE","sortPriority":4,"id":70902709,"name":"5. Cloud Canine"},{"status":"ACTIVE","sortPriority":5,"id":51567147,"name":"6. Coolemore North"},{"status":"REMOVED","sortPriority":6,"removalDate":"2024-06-27T12:17:39.000Z","id":56263473,"name":"2. Makeit Spot"}],"regulators":["MR_INT"],"venue":"Towcester","countryCode":"GB","discountAllowed":true,"timezone":"Europe/London","openDate":"2024-06-27T13:33:00.000Z","version":5995360214,"name":"To Be Placed","eventName":"Towcester 27th Jun"},"rc":[],"con":true,"img":false}]}
{"op":"mcm","clk":"11540161690","pt":1719490659439,"mc":[{"id":"1.230180125","rc":[{"spn":1.0,"spf":1.0,"id":65992794}],"con":true,"img":false}]}
{"op":"mcm","clk":"11540184201","pt":1719490969771,"mc":[{"id":"1.230180125","rc":[{"atb":[[1.01,102.04]],"id":42767337},{"spn":"Infinity","spf":"NaN","id":42767337}],"con":true,"img":false}]}
{"op":"mcm","clk":"11540184211","pt":1719490969866,"mc":[{"id":"1.230180125","rc":[{"atb":[[1.01,102.04]],"id":65992794},{"atb":[[1.01,102.04]],"id":67245400}],"con":true,"img":false}]}
{"op":"mcm","clk":"11540184218","pt":1719490969978,"mc":[{"id":"1.230180125","rc":[{"atb":[[1.01,102.04]],"id":70902709}],"con":true,"img":false}]}
{"op":"mcm","clk":"11540184227","pt":1719490970077,"mc":[{"id":"1.230180125","rc":[{"atb":[[1.01,102.04]],"id":51567147}],"con":true,"img":false}]}
{"op":"mcm","clk":"11540249561","pt":1719491882656,"mc":[{"id":"1.230180125","marketDefinition":{"bspMarket":true,"turnInPlayEnabled":false,"persistenceEnabled":false,"marketBaseRate":5.0,"eventId":"33376437","eventTypeId":"4339","numberOfWinners":2,"bettingType":"ODDS","marketType":"PLACE","marketTime":"2024-06-27T15:26:00.000Z","suspendTime":"2024-06-27T15:26:00.000Z","bspReconciled":false,"complete":true,"inPlay":false,"crossMatching":false,"runnersVoidable":false,"numberOfActiveRunners":5,"betDelay":0,"status":"OPEN","runners":[{"status":"ACTIVE","sortPriority":1,"id":42767337,"name":"1. Salacres Liam"},{"status":"ACTIVE","sortPriority":2,"id":67245400,"name":"3. Lillibeth Royale"},{"status":"ACTIVE","sortPriority":3,"id":65992794,"name":"4. Come Back Kid"},{"status":"ACTIVE","sortPriority":4,"id":70902709,"name":"5. Cloud Canine"},{"status":"ACTIVE","sortPriority":5,"id":51567147,"name":"6. Coolemore North"},{"status":"REMOVED","sortPriority":6,"removalDate":"2024-06-27T12:17:39.000Z","id":56263473,"name":"2. Makeit Spot"}],"regulators":["MR_INT"],"venue":"Towcester","countryCode":"GB","discountAllowed":true,"timezone":"Europe/London","openDate":"2024-06-27T13:33:00.000Z","version":5995360214,"name":"To Be Placed","eventName":"Towcester 27th Jun"},"rc":[{"spl":[[1.71,6]],"id":65992794},{"atb":[[1.01,102.04]],"id":65992794},{"spn":1.0,"spf":1.0,"id":65992794},{"atb":[[1.01,102.04]],"id":67245400},{"spn":"Infinity","spf":"NaN","id":67245400},{"atb":[[1.01,102.04]],"id":42767337},{"spn":"Infinity","spf":"NaN","id":42767337},{"atb":[[1.01,102.04]],"id":51567147},{"spn":"Infinity","spf":"NaN","id":51567147},{"atb":[[1.01,102.04]],"id":70902709},{"spn":"Infinity","spf":"NaN","id":70902709}],"con":true,"img":true}]}
{"op":"mcm","clk":"11540325020","pt":1719493028889,"mc":[{"id":"1.230180125","rc":[{"atb":[[1.01,119.87]],"id":65992794},{"atl":[[990,0.84]],"id":65992794},{"atb":[[1.02,8.91]],"id":67245400},{"atl":[[1000,0.84]],"id":67245400},{"spn":500.51,"spf":"NaN","id":67245400},{"atb":[[1.01,119.87]],"id":42767337},{"atl":[[1000,0.84]],"id":42767337},{"spn":500.5,"spf":"NaN","id":42767337},{"atb":[[1.01,119.87]],"id":51567147},{"atl":[[990,0.84]],"id":51567147},{"spn":495.5,"spf":"NaN","id":51567147},{"atb":[[1.03,5.94]],"id":70902709},{"atl":[[990,0.84]],"id":70902709},{"spn":495.51,"spf":"NaN","id":70902709}],"con":true,"img":false}]}
{"op":"mcm","clk":"11540628516","pt":1719496629482,"mc":[{"id":"1.230180125","rc":[{"atb":[[1.01,119.89]],"id":65992794},{"atl":[[990,0.17]],"id":65992794},{"atb":[[1.02,8.92]],"id":67245400},{"atl":[[1000,0.17]],"id":67245400},{"atb":[[1.01,119.89]],"id":42767337},{"atl":[[1000,0.17]],"id":42767337},{"atb":[[1.01,119.89]],"id":51567147},{"atl":[[990,0.17]],"id":51567147},{"atb":[[1.03,5.95]],"id":70902709},{"atl":[[990,0.17]],"id":70902709}],"con":true,"img":false}]}
{"op":"mcm","clk":"11540685096","pt":1719497282630,"mc":[{"id":"1.230180125","marketDefinition":{"bspMarket":true,"turnInPlayEnabled":false,"persistenceEnabled":false,"marketBaseRate":5.0,"eventId":"33376437","eventTypeId":"4339","numberOfWinners":2,"bettingType":"ODDS","marketType":"PLACE","marketTime":"2024-06-27T15:26:00.000Z","suspendTime":"2024-06-27T15:26:00.000Z","bspReconciled":false,"complete":true,"inPlay":false,"crossMatching":false,"runnersVoidable":false,"numberOfActiveRunners":5,"betDelay":0,"status":"OPEN","runners":[{"status":"ACTIVE","sortPriority":1,"id":42767337,"name":"1. Salacres Liam"},{"status":"ACTIVE","sortPriority":2,"id":67245400,"name":"3. Lillibeth Royale"},{"status":"ACTIVE","sortPriority":3,"id":65992794,"name":"4. Come Back Kid"},{"status":"ACTIVE","sortPriority":4,"id":70902709,"name":"5. Cloud Canine"},{"status":"ACTIVE","sortPriority":5,"id":51567147,"name":"6. Coolemore North"},{"status":"REMOVED","sortPriority":6,"removalDate":"2024-06-27T12:17:39.000Z","id":56263473,"name":"2. Makeit Spot"}],"regulators":["MR_INT"],"venue":"Towcester","countryCode":"GB","discountAllowed":true,"timezone":"Europe/London","openDate":"2024-06-27T13:33:00.000Z","version":5995360214,"name":"To Be Placed","eventName":"Towcester 27th Jun"},"rc":[{"spl":[[1.71,6]],"id":65992794},{"atb":[[1.01,119.88]],"id":65992794},{"atl":[[990,0.17]],"id":65992794},{"spn":1.0,"spf":1.0,"id":65992794},{"atb":[[1.01,102.04],[1.02,8.92]],"id":67245400},{"atl":[[1000,0.17]],"id":67245400},{"spn":500.51,"spf":"NaN","id":67245400},{"atb":[[1.01,119.88]],"id":42767337},{"atl":[[1000,0.17]],"id":42767337},{"spn":500.5,"spf":"NaN","id":42767337},{"atb":[[1.01,119.88]],"id":51567147},{"atl":[[990,0.17]],"id":51567147},{"spn":495.5,"spf":"NaN","id":51567147},{"atb":[[1.01,102.04],[1.03,5.95]],"id":70902709},{"atl":[[990,0.17]],"id":70902709},{"spn":495.51,"spf":"NaN","id":70902709}],"con":true,"img":true}]}
{"op":"mcm","clk":"11541006960","pt":1719501060109,"mc":[{"id":"1.230180125","rc":[{"atb":[[1.01,119.88],[1.25,1],[1.02,119.89]],"id":65992794},{"atl":[[5.2,2],[2.7,1]],"id":65992794},{"spn":1.48,"spf":1.0,"id":65992794},{"atb":[[1.79,55.48],[1.74,1],[1.02,8.92]],"id":67245400},{"atl":[[38,2],[6,1]],"id":67245400},{"spn":3.89,"spf":"NaN","id":67245400},{"atb":[[1.01,119.88],[1.97,1],[1.85,117.65]],"id":42767337},{"atl":[[50,2],[6.6,1]],"id":42767337},{"spn":4.28,"spf":"NaN","id":42767337},{"atb":[[1.46,1],[1.01,119.88],[1.61,119.89]],"id":51567147},{"atl":[[18,2],[4.4,1]],"id":51567147},{"spn":3.0,"spf":"NaN","id":51567147},{"atb":[[1.03,5.95],[1.55,1],[1.7,54]],"id":70902709},{"atl":[[5.3,1],[27,2]],"id":70902709},{"spn":3.5,"spf":"NaN","id":70902709}],"con":true,"img":false}]}
{"op":"mcm","clk":"11541007278","pt":1719501064632,"mc":[{"id":"1.230180125","rc":[{"atl":[[1000,1.7]],"id":65992794},{"atb":[[1.01,103.74]],"id":67245400},{"atl":[[1000,1.88]],"id":67245400},{"atb":[[1.01,121.59]],"id":42767337},{"atl":[[1000,1.88]],"id":42767337}],"con":true,"img":false}]}
{"op":"mcm","clk":"11541007289","pt":1719501064698,"mc":[{"id":"1.230180125","rc":[{"atb":[[1.03,10.59]],"id":65992794}],"con":true,"img":false}]}
{"op":"mcm","clk":"11541007300","pt":1719501064799,"mc":[{"id":"1.230180125","rc":[{"atl":[[1000,0.07]],"id":65992794},{"atb":[[1.01,102.43]],"id":67245400},{"atl":[[1000,0.18]],"id":67245400},{"atb":[[1.01,120.25]],"id":42767337}],"con":true,"img":false}]}
{"op":"mcm","clk":"11541007311","pt":1719501064897,"mc":[{"id":"1.230180125","rc":[{"atl":[[1000,0.18]],"id":42767337}],"con":true,"img":false}]}
{"op":"mcm","clk":"11541007321","pt":1719501064998,"mc":[{"id":"1.230180125","rc":[{"atl":[[1000,0]],"id":65992794},{"atb":[[1.01,102.04]],"id":67245400},{"atl":[[1000,0.17]],"id":67245400},{"atb":[[1.01,119.88]],"id":42767337}],"con":true,"img":false}]}
{"op":"mcm","clk":"11541007329","pt":1719501065111,"mc":[{"id":"1.230180125","rc":[{"atl":[[5.1,0.07]],"id":65992794},{"atb":[[1.8,0.39]],"id":67245400},{"atl":[[36,0]],"id":67245400},{"atb":[[1.86,0.37]],"id":42767337},{"atl":[[1000,0.17]],"id":42767337}],"con":true,"img":false}]}
{"op":"mcm","clk":"11541007335","pt":1719501065206,"mc":[{"id":"1.230180125","rc":[{"atl":[[48,0]],"id":42767337}],"con":true,"img":false}]}
{"op":"mcm","clk":"11541007772","pt":1719501071885,"mc":[{"id":"1.230180125","marketDefinition":{"bspMarket":true,"turnInPlayEnabled":false,"persistenceEnabled":false,"marketBaseRate":5.0,"eventId":"33376437","eventTypeId":"4339","numberOfWinners":2,"bettingType":"ODDS","marketType":"PLACE","marketTime":"2024-06-27T15:26:00.000Z","suspendTime":"2024-06-27T15:26:00.000Z","bspReconciled":false,"complete":true,"inPlay":false,"crossMatching":true,"runnersVoidable":false,"numberOfActiveRunners":5,"betDelay":0,"status":"OPEN","runners":[{"status":"ACTIVE","sortPriority":1,"id":42767337,"name":"1. Salacres Liam"},{"status":"ACTIVE","sortPriority":2,"id":67245400,"name":"3. Lillibeth Royale"},{"status":"ACTIVE","sortPriority":3,"id":65992794,"name":"4. Come Back Kid"},{"status":"ACTIVE","sortPriority":4,"id":70902709,"name":"5. Cloud Canine"},{"status":"ACTIVE","sortPriority":5,"id":51567147,"name":"6. Coolemore North"},{"status":"REMOVED","sortPriority":6,"removalDate":"2024-06-27T12:17:39.000Z","id":56263473,"name":"2. Makeit Spot"}],"regulators":["MR_INT"],"venue":"Towcester","countryCode":"GB","discountAllowed":true,"timezone":"Europe/London","openDate":"2024-06-27T13:33:00.000Z","version":5995360214,"name":"To Be Placed","eventName":"Towcester 27th Jun"},"rc":[],"con":true,"img":false}]}
{"op":"mcm","clk":"11541008312","pt":1719501080252,"mc":[{"id":"1.230180125","rc":[{"atb":[[1.86,2.37]],"id":42767337}],"con":true,"img":false}]}
{"op":"mcm","clk":"11541008342","pt":1719501080626,"mc":[{"id":"1.230180125","rc":[{"atb":[[1.8,2.39]],"id":67245400}],"con":true,"img":false}]}
{"op":"mcm","clk":"11541008367","pt":1719501081032,"mc":[{"id":"1.230180125","rc":[{"atb":[[1.04,2]],"id":65992794}],"con":true,"img":false}]}
{"op":"mcm","clk":"11541008396","pt":1719501081347,"mc":[{"id":"1.230180125","rc":[{"atb":[[1.71,2]],"id":70902709}],"con":true,"img":false}]}
{"op":"mcm","clk":"11541008413","pt":1719501081546,"mc":[{"id":"1.230180125","rc":[{"atb":[[1.62,2]],"id":51567147}],"con":true,"img":false}]}
{"op":"mcm","clk":"11541008495","pt":1719501082722,"mc":[{"id":"1.230180125","rc":[{"atb":[[1.8,0.39]],"id":67245400}],"con":true,"img":false}]}
{"op":"mcm","clk":"11541008504","pt":1719501082827,"mc":[{"id":"1.230180125","rc":[{"atb":[[1.02,10.92]],"id":67245400}],"con":true,"img":false}]}
{"op":"mcm","clk":"11541008542","pt":1719501083441,"mc":[{"id":"1.230180125","rc":[{"atb":[[1.71,0]],"id":70902709}],"con":true,"img":false}]}
{"op":"mcm","clk":"11541008553","pt":1719501083541,"mc":[{"id":"1.230180125","rc":[{"atb":[[1.02,2]],"id":70902709}],"con":true,"img":false}]}
{"op":"mcm","clk":"11541008669","pt":1719501085142,"mc":[{"id":"1.230180125","rc":[{"atb":[[1.02,8.92]],"id":67245400}],"con":true,"img":false}]}
{"op":"mcm","clk":"11541008683","pt":1719501085248,"mc":[{"id":"1.230180125","rc":[{"atb":[[1.8,2.39]],"id":67245400}],"con":true,"img":false}]}
{"op":"mcm","clk":"11541008701","pt":1719501085557,"mc":[{"id":"1.230180125","rc":[{"atb":[[1.02,0]],"id":70902709}],"con":true,"img":false}]}
{"op":"mcm","clk":"11541008709","pt":1719501085658,"mc":[{"id":"1.230180125","rc":[{"atb":[[1.71,2]],"id":70902709}],"con":true,"img":false}]}
{"op":"mcm","clk":"11541008778","pt":1719501086746,"mc":[{"id":"1.230180125","rc":[{"atb":[[1.8,0.39]],"id":67245400}],"con":true,"img":false}]}
{"op":"mcm","clk":"11541008787","pt":1719501086847,"mc":[{"id":"1.230180125","rc":[{"atb":[[1.02,10.92]],"id":67245400}],"con":true,"img":false}]}
{"op":"mcm","clk":"11541008796","pt":1719501086961,"mc":[{"id":"1.230180125","rc":[{"atb":[[1.79,0],[1.9,2]],"id":67245400},{"atb":[[1.98,2.37],[1.85,0]],"id":42767337},{"atb":[[1.63,2],[1.61,0]],"id":51567147},{"atb":[[1.74,2],[1.7,0]],"id":70902709}],"con":true,"img":false}]}
{"op":"mcm","clk":"11541008809","pt":1719501087159,"mc":[{"id":"1.230180125","rc":[{"atb":[[1.71,0]],"id":70902709}],"con":true,"img":false}]}
{"op":"mcm","clk":"11541008816","pt":1719501087213,"mc":[{"id":"1.230180125","rc":[{"atb":[[1.02,2]],"id":70902709}],"con":true,"img":false}]}
{"op":"mcm","clk":"11541008913","pt":1719501088923,"mc":[{"id":"1.230180125","rc":[{"atb":[[1.86,0.37]],"id":42767337}],"con":true,"img":false}]}
{"op":"mcm","clk":"11541008922","pt":1719501089030,"mc":[{"id":"1.230180125","rc":[{"atb":[[1.99,2]],"id":42767337}],"con":true,"img":false}]}
{"op":"mcm","clk":"11541008959","pt":1719501089442,"mc":[{"id":"1.230180125","rc":[{"atb":[[1.62,0]],"id":51567147}],"con":true,"img":false}]}
{"op":"mcm","clk":"11541008969","pt":1719501089546,"mc":[{"id":"1.230180125","rc":[{"atb":[[1.64,2]],"id":51567147}],"con":true,"img":false}]}
{"op":"mcm","clk":"11541009972","pt":1719501103643,"mc":[{"id":"1.230180125","rc":[{"atb":[[1.03,0]],"id":65992794},{"atl":[[5.1,0]],"id":65992794},{"atb":[[1.8,0]],"id":67245400},{"atl":[[36,0]],"id":67245400},{"atb":[[1.86,0]],"id":42767337},{"atl":[[48,0]],"id":42767337}],"con":true,"img":false}]}
{"op":"mcm","clk":"11541010046","pt":1719501104575,"mc":[{"id":"1.230180125","rc":[{"atb":[[1.04,0]],"id":65992794}],"con":true,"img":false}]}
{"op":"mcm","clk":"11541010054","pt":1719501104679,"mc":[{"id":"1.230180125","rc":[{"atb":[[1.03,2]],"id":65992794}],"con":true,"img":false}]}
{"op":"mcm","clk":"11541016073","pt":1719501178223,"mc":[{"id":"1.230180125","rc":[{"atl":[[2.92,1],[2.7,0]],"id":65992794},{"spn":3.95,"spf":"NaN","id":67245400},{"spn":4.29,"spf":"NaN","id":42767337},{"spn":3.02,"spf":"NaN","id":51567147},{"spn":3.52,"spf":"NaN","id":70902709}],"con":true,"img":false}]}
{"op":"mcm","clk":"11541017127","pt":1719501189441,"mc":[{"id":"1.230180125","rc":[{"atl":[[1000,1.7]],"id":65992794},{"atl":[[1000,1.88]],"id":67245400},{"atl":[[1000,1.88]],"id":42767337}],"con":true,"img":false}]}
{"op":"mcm","clk":"11541017137","pt":1719501189546,"mc":[{"id":"1.230180125","rc":[{"atb":[[1.04,7.66]],"id":65992794},{"atb":[[1.01,103.74]],"id":67245400},{"atb":[[1.01,121.59]],"id":42767337}],"con":true,"img":false}]}
{"op":"mcm","clk":"11541017149","pt":1719501189652,"mc":[{"id":"1.230180125","rc":[{"atl":[[1000,0.07]],"id":65992794},{"atl":[[1000,0.18]],"id":67245400},{"atl":[[1000,0.18]],"id":42767337}],"con":true,"img":false}]}
{"op":"mcm","clk":"11541017158","pt":1719501189747,"mc":[{"id":"1.230180125","rc":[{"atb":[[1.01,102.37]],"id":67245400},{"atb":[[1.01,120.19]],"id":42767337}],"con":true,"img":false}]}
{"op":"mcm","clk":"11541017169","pt":1719501189866,"mc":[{"id":"1.230180125","rc":[{"atl":[[1000,0]],"id":65992794},{"atl":[[1000,0.17]],"id":67245400},{"atl":[[1000,0.17]],"id":42767337}],"con":true,"img":false}]}
{"op":"mcm","clk":"11541017181","pt":1719501189956,"mc":[{"id":"1.230180125","rc":[{"atl":[[5.1,0.07]],"id":65992794},{"atb":[[1.01,102.04]],"id":67245400},{"atl":[[36,0]],"id":67245400},{"atb":[[1.01,119.88]],"id":42767337},{"atl":[[48,0]],"id":42767337}],"con":true,"img":false}]}
{"op":"mcm","clk":"11541017195","pt":1719501190061,"mc":[{"id":"1.230180125","rc":[{"atb":[[1.91,0.33]],"id":67245400},{"atb":[[2,0.3]],"id":42767337}],"con":true,"img":false}]}
{"op":"mcm","clk":"11541017254","pt":1719501190578,"mc":[{"id":"1.230180125","rc":[{"atb":[[1.03,0]],"id":65992794}],"con":true,"img":false}]}
{"op":"mcm","clk":"11541017268","pt":1719501190633,"mc":[{"id":"1.230180125","rc":[{"atb":[[1.05,2]],"id":65992794}],"con":true,"img":false}]}
{"op":"mcm","clk":"11541020323","pt":1719501225736,"mc":[{"id":"1.230180125","rc":[{"atb":[[1.04,0]],"id":65992794},{"atl":[[5.1,0]],"id":65992794},{"atb":[[1.91,0]],"id":67245400},{"atl":[[36,0]],"id":67245400},{"atb":[[2,0]],"id":42767337},{"atl":[[48,0]],"id":42767337}],"con":true,"img":false}]}
{"op":"mcm","clk":"11541020352","pt":1719501225990,"mc":[{"id":"1.230180125","rc":[{"atb":[[1.05,0]],"id":65992794}],"con":true,"img":false}]}
{"op":"mcm","clk":"11541020362","pt":1719501226105,"mc":[{"id":"1.230180125","rc":[{"atb":[[1.03,2]],"id":65992794}],"con":true,"img":false}]}
{"op":"mcm","clk":"11541027104","pt":1719501302608,"mc":[{"id":"1.230180125","rc":[{"atl":[[1000,1.7]],"id":65992794},{"atb":[[1.01,103.74]],"id":67245400},{"atl":[[1000,1.88]],"id":67245400},{"atb":[[1.01,121.59]],"id":42767337},{"atl":[[1000,1.88]],"id":42767337}],"con":true,"img":false}]}
{"op":"mcm","clk":"11541027115","pt":1719501302717,"mc":[{"id":"1.230180125","rc":[{"atb":[[1.04,7.37]],"id":65992794}],"con":true,"img":false}]}
{"op":"mcm","clk":"11541027127","pt":1719501302821,"mc":[{"id":"1.230180125","rc":[{"atl":[[1000,0.07]],"id":65992794},{"atb":[[1.01,102.36]],"id":67245400},{"atl":[[1000,0.18]],"id":67245400},{"atb":[[1.01,120.18]],"id":42767337},{"atl":[[1000,0.18]],"id":42767337}],"con":true,"img":false}]}
{"op":"mcm","clk":"11541027160","pt":1719501303132,"mc":[{"id":"1.230180125","rc":[{"atl":[[1000,0]],"id":65992794},{"atb":[[1.01,102.04]],"id":67245400},{"atl":[[1000,0.17]],"id":67245400},{"atb":[[1.01,119.88]],"id":42767337},{"atl":[[1000,0.17]],"id":42767337}],"con":true,"img":false}]}
{"op":"mcm","clk":"11541027173","pt":1719501303187,"mc":[{"id":"1.230180125","rc":[{"atb":[[1.03,0]],"id":65992794},{"atl":[[5.1,0.07]],"id":65992794},{"atb":[[1.91,0.32]],"id":67245400},{"atl":[[36,0]],"id":67245400},{"atb":[[2,0.29]],"id":42767337},{"atl":[[48,0]],"id":42767337}],"con":true,"img":false}]}
{"op":"mcm","clk":"11541027184","pt":1719501303295,"mc":[{"id":"1.230180125","rc":[{"atb":[[1.05,2]],"id":65992794}],"con":true,"img":false}]}
{"op":"mcm","clk":"11541029697","pt":1719501328032,"mc":[{"id":"1.230180125","rc":[{"atb":[[1.76,5.57]],"id":70902709}],"con":true,"img":false}]}
{"op":"mcm","clk":"11541029710","pt":1719501328135,"mc":[{"id":"1.230180125","rc":[{"atb":[[1.74,0],[1.77,2]],"id":70902709}],"con":true,"img":false}]}
{"op":"mcm","clk":"11541029733","pt":1719501328444,"mc":[{"id":"1.230180125","rc":[{"atb":[[1.66,6.41]],"id":51567147}],"con":true,"img":false}]}
{"op":"mcm","clk":"11541029740","pt":1719501328547,"mc":[{"id":"1.230180125","rc":[{"atb":[[1.63,0],[1.67,2]],"id":51567147}],"con":true,"img":false}]}
{"op":"mcm","clk":"11541029867","pt":1719501329836,"mc":[{"id":"1.230180125","rc":[{"atb":[[1.64,0]],"id":51567147}],"con":true,"img":false}]}
{"op":"mcm","clk":"11541029875","pt":1719501329962,"mc":[{"id":"1.230180125","rc":[{"atb":[[1.68,2]],"id":51567147}],"con":true,"img":false}]}
{"op":"mcm","clk":"11541030652","pt":1719501339450,"mc":[{"id":"1.230180125","rc":[{"atb":[[1.79,5]],"id":70902709}],"con":true,"img":false}]}
{"op":"mcm","clk":"11541030661","pt":1719501339553,"mc":[{"id":"1.230180125","rc":[{"atb":[[1.8,5],[1.77,0]],"id":70902709}],"con":true,"img":false}]}
{"op":"mcm","clk":"11541030696","pt":1719501339873,"mc":[{"id":"1.230180125","rc":[{"atb":[[1.7,5.64]],"id":51567147}],"con":true,"img":false}]}
{"op":"mcm","clk":"11541030707","pt":1719501339974,"mc":[{"id":"1.230180125","rc":[{"atb":[[1.67,0],[1.71,2]],"id":51567147},{"atb":[[1.02,0]],"id":70902709}],"con":true,"img":false}]}
{"op":"mcm","clk":"11541030713","pt":1719501340076,"mc":[{"id":"1.230180125","rc":[{"atb":[[1.81,2]],"id":70902709}],"con":true,"img":false}]}
{"op":"mcm","clk":"11541030790","pt":1719501340857,"mc":[{"id":"1.230180125","rc":[{"atb":[[1.04,0]],"id":65992794},{"atl":[[5.1,0]],"id":65992794},{"atb":[[1.91,0]],"id":67245400},{"atl":[[36,0]],"id":67245400},{"atb":[[2,0]],"id":42767337},{"atl":[[48,0]],"id":42767337}],"con":true,"img":false}]}
{"op":"mcm","clk":"11541030845","pt":1719501341432,"mc":[{"id":"1.230180125","rc":[{"atb":[[1.05,0]],"id":65992794}],"con":true,"img":false}]}
{"op":"mcm","clk":"11541030854","pt":1719501341534,"mc":[{"id":"1.230180125","rc":[{"atb":[[1.03,2]],"id":65992794}],"con":true,"img":false}]}
{"op":"mcm","clk":"11541030884","pt":1719501341957,"mc":[{"id":"1.230180125","rc":[{"atb":[[1.68,0]],"id":51567147}],"con":true,"img":false}]}
{"op":"mcm","clk":"11541030892","pt":1719501342060,"mc":[{"id":"1.230180125","rc":[{"atb":[[1.72,2]],"id":51567147}],"con":true,"img":false}]}
{"op":"mcm","clk":"11541032262","pt":1719501357458,"mc":[{"id":"1.230180125","rc":[{"atb":[[1.7,0]],"id":51567147},{"atb":[[1.79,0]],"id":70902709}],"con":true,"img":false}]}
{"op":"mcm","clk":"11541032278","pt":1719501357669,"mc":[{"id":"1.230180125","rc":[{"atb":[[1.74,5.34]],"id":51567147},{"atb":[[1.83,4.75]],"id":70902709}],"con":true,"img":false}]}
{"op":"mcm","clk":"11541032295","pt":1719501357873,"mc":[{"id":"1.230180125","rc":[{"atb":[[1.75,2],[1.71,0]],"id":51567147},{"atb":[[1.8,0],[1.84,4.76]],"id":70902709}],"con":true,"img":false}]}
{"op":"mcm","clk":"11541032348","pt":1719501358455,"mc":[{"id":"1.230180125","rc":[{"atb":[[1.81,0]],"id":70902709}],"con":true,"img":false}]}
{"op":"mcm","clk":"11541032361","pt":1719501358558,"mc":[{"id":"1.230180125","rc":[{"atb":[[1.85,2]],"id":70902709}],"con":true,"img":false}]}
{"op":"mcm","clk":"11541032401","pt":1719501359069,"mc":[{"id":"1.230180125","rc":[{"atb":[[1.72,0]],"id":51567147}],"con":true,"img":false}]}
{"op":"mcm","clk":"11541032411","pt":1719501359172,"mc":[{"id":"1.230180125","rc":[{"atb":[[1.76,2]],"id":51567147}],"con":true,"img":false}]}
{"op":"mcm","clk":"11541033104","pt":1719501366781,"mc":[{"id":"1.230180125","rc":[{"atb":[[1.66,0]],"id":51567147},{"spn":3.08,"spf":"NaN","id":51567147},{"spn":3.57,"spf":"NaN","id":70902709}],"con":true,"img":false}]}
{"op":"mcm","clk":"11541033112","pt":1719501366877,"mc":[{"id":"1.230180125","rc":[{"atb":[[1.76,0]],"id":70902709}],"con":true,"img":false}]}
{"op":"mcm","clk":"11541033200","pt":1719501367778,"mc":[{"id":"1.230180125","rc":[{"atb":[[1.78,5.42]],"id":51567147}],"con":true,"img":false}]}
{"op":"mcm","clk":"11541033214","pt":1719501367885,"mc":[{"id":"1.230180125","rc":[{"atb":[[1.79,2],[1.75,0]],"id":51567147}],"con":true,"img":false}]}
{"op":"mcm","clk":"11541033232","pt":1719501368087,"mc":[{"id":"1.230180125","rc":[{"atb":[[1.87,4.86]],"id":70902709}],"con":true,"img":false}]}
{"op":"mcm","clk":"11541033242","pt":1719501368190,"mc":[{"id":"1.230180125","rc":[{"atb":[[1.88,4.76]],"id":70902709}],"con":true,"img":false}]}
{"op":"mcm","clk":"11541033253","pt":1719501368304,"mc":[{"id":"1.230180125","rc":[{"atb":[[1.84,0]],"id":70902709}],"con":true,"img":false}]}
{"op":"mcm","clk":"11541033283","pt":1719501368561,"mc":[{"id":"1.230180125","rc":[{"atb":[[1.76,0]],"id":51567147}],"con":true,"img":false}]}
{"op":"mcm","clk":"11541033296","pt":1719501368662,"mc":[{"id":"1.230180125","rc":[{"atb":[[1.8,2]],"id":51567147}],"con":true,"img":false}]}
{"op":"mcm","clk":"11541033512","pt":1719501370899,"mc":[{"id":"1.230180125","rc":[{"atb":[[1.85,0]],"id":70902709}],"con":true,"img":false}]}
{"op":"mcm","clk":"11541033522","pt":1719501370995,"mc":[{"id":"1.230180125","rc":[{"atb":[[1.89,2]],"id":70902709}],"con":true,"img":false}]}
{"op":"mcm","clk":"11541033646","pt":1719501372404,"mc":[{"id":"1.230180125","rc":[{"atb":[[1.08,50]],"id":65992794},{"atb":[[1.08,50]],"id":67245400},{"atb":[[1.08,50]],"id":42767337},{"atb":[[1.08,50]],"id":51567147},{"atb":[[1.08,50]],"id":70902709}],"con":true,"img":false}]}
{"op":"mcm","clk":"11541033659","pt":1719501372501,"mc":[{"id":"1.230180125","rc":[{"atb":[[1.02,0],[1.09,50]],"id":65992794}],"con":true,"img":false}]}
{"op":"mcm","clk":"11541033708","pt":1719501372972,"mc":[{"id":"1.230180125","rc":[{"atb":[[1.99,0]],"id":42767337}],"con":true,"img":false}]}
{"op":"mcm","clk":"11541033717","pt":1719501373075,"mc":[{"id":"1.230180125","rc":[{"atb":[[1.02,2]],"id":42767337}],"con":true,"img":false}]}
{"op":"mcm","clk":"11541033749","pt":1719501373488,"mc":[{"id":"1.230180125","rc":[{"atb":[[1.03,0]],"id":65992794}],"con":true,"img":false}]}
{"op":"mcm","clk":"11541033756","pt":1719501373598,"mc":[{"id":"1.230180125","rc":[{"atb":[[1.1,2]],"id":65992794}],"con":true,"img":false}]}
{"op":"mcm","clk":"11541034002","pt":1719501376489,"mc":[{"id":"1.230180125","rc":[{"atb":[[1.12,32.94]],"id":65992794}],"con":true,"img":false}]}
{"op":"mcm","clk":"11541034022","pt":1719501376694,"mc":[{"id":"1.230180125","rc":[{"atb":[[1.09,0],[1.13,32.94]],"id":65992794}],"con":true,"img":false}]}
{"op":"mcm","clk":"11541034051","pt":1719501377014,"mc":[{"id":"1.230180125","rc":[{"atb":[[1.83,0]],"id":70902709}],"con":true,"img":false}]}
{"op":"mcm","clk":"11541034074","pt":1719501377164,"mc":[{"id":"1.230180125","rc":[{"atb":[[1.91,4.34]],"id":70902709}],"con":true,"img":false}]}
{"op":"mcm","clk":"11541034083","pt":1719501377267,"mc":[{"id":"1.230180125","rc":[{"atb":[[1.1,0]],"id":65992794},{"atb":[[1.92,4.34],[1.88,0]],"id":70902709}],"con":true,"img":false}]}
{"op":"mcm","clk":"11541034094","pt":1719501377373,"mc":[{"id":"1.230180125","rc":[{"atb":[[1.14,2]],"id":65992794}],"con":true,"img":false}]}
{"op":"mcm","clk":"11541034148","pt":1719501378199,"mc":[{"id":"1.230180125","rc":[{"atb":[[1.89,0]],"id":70902709}],"con":true,"img":false}]}
{"op":"mcm","clk":"11541034157","pt":1719501378300,"mc":[{"id":"1.230180125","rc":[{"atb":[[1.93,2]],"id":70902709}],"con":true,"img":false}]}
{"op":"mcm","clk":"11541035525","pt":1719501394522,"mc":[{"id":"1.230180125","rc":[{"atb":[[1.12,0]],"id":65992794}],"con":true,"img":false}]}
{"op":"mcm","clk":"11541035541","pt":1719501394681,"mc":[{"id":"1.230180125","rc":[{"atb":[[1.16,24.7]],"id":65992794}],"con":true,"img":false}]}
{"op":"mcm","clk":"11541035550","pt":1719501394780,"mc":[{"id":"1.230180125","rc":[{"atb":[[1.17,24.71]],"id":65992794}],"con":true,"img":false}]}
{"op":"mcm","clk":"11541035557","pt":1719501394887,"mc":[{"id":"1.230180125","rc":[{"atb":[[1.13,0]],"id":65992794}],"con":true,"img":false}]}
{"op":"mcm","clk":"11541035620","pt":1719501395912,"mc":[{"id":"1.230180125","rc":[{"atb":[[1.14,0]],"id":65992794}],"con":true,"img":false}]}
{"op":"mcm","clk":"11541035630","pt":1719501396015,"mc":[{"id":"1.230180125","rc":[{"atb":[[1.18,2]],"id":65992794}],"con":true,"img":false}]}
{"op":"mcm","clk":"11541036153","pt":1719501403115,"mc":[{"id":"1.230180125","rc":[{"atb":[[1.15,3.75]],"id":65992794},{"atb":[[1.07,3.75]],"id":67245400}],"con":true,"img":false}]}
{"op":"mcm","clk":"11541036210","pt":1719501403731,"mc":[{"id":"1.230180125","rc":[{"atb":[[1.96,3.75]],"id":42767337}],"con":true,"img":false}]}
{"op":"mcm","clk":"11541036337","pt":1719501405594,"mc":[{"id":"1.230180125","rc":[{"atb":[[1.2,21.16]],"id":65992794}],"con":true,"img":false}]}
{"op":"mcm","clk":"11541036351","pt":1719501405794,"mc":[{"id":"1.230180125","rc":[{"atb":[[1.21,21.17],[1.17,0]],"id":65992794}],"con":true,"img":false}]}
{"op":"mcm","clk":"11541036408","pt":1719501406617,"mc":[{"id":"1.230180125","rc":[{"atb":[[1.15,0]],"id":65992794}],"con":true,"img":false}]}
{"op":"mcm","clk":"11541036451","pt":1719501407241,"mc":[{"id":"1.230180125","rc":[{"atb":[[1.18,0]],"id":65992794}],"con":true,"img":false}]}
{"op":"mcm","clk":"11541036461","pt":1719501407339,"mc":[{"id":"1.230180125","rc":[{"atb":[[1.22,2]],"id":65992794}],"con":true,"img":false}]}
{"op":"mcm","clk":"11541036911","pt":1719501414143,"mc":[{"id":"1.230180125","rc":[{"atb":[[1.16,0]],"id":65992794}],"con":true,"img":false}]}
{"op":"mcm","clk":"11541036930","pt":1719501414403,"mc":[{"id":"1.230180125","rc":[{"atb":[[1.22,27.15]],"id":65992794}],"con":true,"img":false}]}
{"op":"mcm","clk":"11541036945","pt":1719501414607,"mc":[{"id":"1.230180125","rc":[{"atb":[[1.21,0],[1.23,21.17]],"id":65992794}],"con":true,"img":false}]}
{"op":"mcm","clk":"11541036989","pt":1719501415225,"mc":[{"id":"1.230180125","rc":[{"atb":[[1.22,25.15]],"id":65992794}],"con":true,"img":false}]}
{"op":"mcm","clk":"11541036993","pt":1719501415335,"mc":[{"id":"1.230180125","rc":[{"atb":[[1.24,2]],"id":65992794}],"con":true,"img":false}]}
{"op":"mcm","clk":"11541037163","pt":1719501417522,"mc":[{"id":"1.230180125","rc":[{"atb":[[1.96,0]],"id":42767337}],"con":true,"img":false}]}
{"op":"mcm","clk":"11541037707","pt":1719501424244,"mc":[{"id":"1.230180125","rc":[{"atb":[[1.01,121.59]],"id":65992794},{"atl":[[1000,1.7]],"id":65992794},{"atb":[[1.01,103.74]],"id":67245400},{"atl":[[1000,1.88]],"id":67245400},{"atb":[[1.01,121.59]],"id":42767337},{"atl":[[1000,1.88]],"id":42767337}],"con":true,"img":false}]}
{"op":"mcm","clk":"11541037730","pt":1719501424447,"mc":[{"id":"1.230180125","rc":[{"atb":[[1.01,121.02]],"id":65992794},{"atl":[[1000,0.06]],"id":65992794},{"atb":[[1.01,102.35]],"id":67245400},{"atl":[[1000,0.18]],"id":67245400},{"atb":[[1.01,120.17]],"id":42767337}],"con":true,"img":false}]}
{"op":"mcm","clk":"11541037742","pt":1719501424558,"mc":[{"id":"1.230180125","rc":[{"atl":[[1000,0.18]],"id":42767337}],"con":true,"img":false}]}
{"op":"mcm","clk":"11541037751","pt":1719501424655,"mc":[{"id":"1.230180125","rc":[{"atb":[[1.01,119.88]],"id":65992794},{"atl":[[1000,0]],"id":65992794},{"atb":[[1.01,102.04]],"id":67245400},{"atl":[[1000,0.17]],"id":67245400},{"atb":[[1.01,119.88]],"id":42767337}],"con":true,"img":false}]}
{"op":"mcm","clk":"11541037763","pt":1719501424762,"mc":[{"id":"1.230180125","rc":[{"atb":[[1.25,2.13]],"id":65992794},{"atl":[[5.1,0.06]],"id":65992794},{"atb":[[1.91,0.31]],"id":67245400},{"atl":[[36,0]],"id":67245400},{"atb":[[1.99,0.28]],"id":42767337},{"atl":[[1000,0.17]],"id":42767337}],"con":true,"img":false}]}
{"op":"mcm","clk":"11541037771","pt":1719501424860,"mc":[{"id":"1.230180125","rc":[{"atl":[[48,0]],"id":42767337}],"con":true,"img":false}]}
{"op":"mcm","clk":"11541037781","pt":1719501424917,"mc":[{"id":"1.230180125","rc":[{"atb":[[1.25,4.27]],"id":65992794}],"con":true,"img":false}]}
{"op":"mcm","clk":"11541037788","pt":1719501425015,"mc":[{"id":"1.230180125","rc":[{"atb":[[1.23,0]],"id":65992794}],"con":true,"img":false}]}
{"op":"mcm","clk":"11541037819","pt":1719501425427,"mc":[{"id":"1.230180125","rc":[{"atb":[[1.07,0]],"id":67245400}],"con":true,"img":false}]}
{"op":"mcm","clk":"11541037860","pt":1719501425945,"mc":[{"id":"1.230180125","rc":[{"atb":[[1.24,0]],"id":65992794}],"con":true,"img":false}]}
{"op":"mcm","clk":"11541037869","pt":1719501426053,"mc":[{"id":"1.230180125","rc":[{"atb":[[1.26,2]],"id":65992794}],"con":true,"img":false}]}
{"op":"mcm","clk":"11541038262","pt":1719501430757,"mc":[{"id":"1.230180125","rc":[{"spn":1.48,"spf":1.0,"id":65992794},{"spn":3.95,"spf":"NaN","id":67245400},{"spn":3.1,"spf":"NaN","id":51567147},{"atb":[[1.91,0]],"id":70902709},{"spn":3.61,"spf":"NaN","id":70902709}],"con":true,"img":false}]}
{"op":"mcm","clk":"11541038279","pt":1719501430961,"mc":[{"id":"1.230180125","rc":[{"atb":[[1.74,0]],"id":51567147}],"con":true,"img":false}]}
{"op":"mcm","clk":"11541038293","pt":1719501431168,"mc":[{"id":"1.230180125","rc":[{"atb":[[1.82,4.82]],"id":51567147},{"atb":[[1.95,4.15]],"id":70902709}],"con":true,"img":false}]}
{"op":"mcm","clk":"11541038311","pt":1719501431322,"mc":[{"id":"1.230180125","rc":[{"atb":[[1.83,2],[1.79,0]],"id":51567147},{"atb":[[1.92,0],[1.96,4.16]],"id":70902709}],"con":true,"img":false}]}
{"op":"mcm","clk":"11541038359","pt":1719501431841,"mc":[{"id":"1.230180125","rc":[{"atl":[[2.92,0]],"id":65992794}],"con":true,"img":false}]}
{"op":"mcm","clk":"11541038374","pt":1719501431944,"mc":[{"id":"1.230180125","rc":[{"atl":[[2.82,1]],"id":65992794}],"con":true,"img":false}]}
{"op":"mcm","clk":"11541038415","pt":1719501432461,"mc":[{"id":"1.230180125","rc":[{"atb":[[1.93,0]],"id":70902709}],"con":true,"img":false}]}
{"op":"mcm","clk":"11541038427","pt":1719501432575,"mc":[{"id":"1.230180125","rc":[{"atb":[[1.97,2]],"id":70902709}],"con":true,"img":false}]}
{"op":"mcm","clk":"11541038485","pt":1719501433241,"mc":[{"id":"1.230180125","rc":[{"atb":[[1.8,0]],"id":51567147}],"con":true,"img":false}]}
{"op":"mcm","clk":"11541038490","pt":1719501433368,"mc":[{"id":"1.230180125","rc":[{"atb":[[1.84,2]],"id":51567147}],"con":true,"img":false}]}
{"op":"mcm","clk":"11541039021","pt":1719501440037,"mc":[{"id":"1.230180125","rc":[{"atb":[[1.2,0]],"id":65992794}],"con":true,"img":false}]}
{"op":"mcm","clk":"11541039730","pt":1719501449081,"mc":[{"id":"1.230180125","rc":[{"atb":[[1.92,4.29]],"id":67245400}],"con":true,"img":false}]}
{"op":"mcm","clk":"11541039740","pt":1719501449185,"mc":[{"id":"1.230180125","rc":[{"atb":[[1.9,0],[1.93,2]],"id":67245400}],"con":true,"img":false}]}
{"op":"mcm","clk":"11541039767","pt":1719501449470,"mc":[{"id":"1.230180125","rc":[{"atb":[[1.82,0]],"id":51567147}],"con":true,"img":false}]}
{"op":"mcm","clk":"11541039786","pt":1719501449686,"mc":[{"id":"1.230180125","rc":[{"atb":[[1.86,4.59]],"id":51567147}],"con":true,"img":false}]}
{"op":"mcm","clk":"11541039811","pt":1719501449887,"mc":[{"id":"1.230180125","rc":[{"atb":[[1.83,0],[1.87,2]],"id":51567147}],"con":true,"img":false}]}
{"op":"mcm","clk":"11541039928","pt":1719501451277,"mc":[{"id":"1.230180125","rc":[{"atb":[[1.84,0]],"id":51567147}],"con":true,"img":false}]}
{"op":"mcm","clk":"11541039934","pt":1719501451380,"mc":[{"id":"1.230180125","rc":[{"atb":[[1.88,2]],"id":51567147}],"con":true,"img":false}]}
{"op":"mcm","clk":"11541040726","pt":1719501460982,"mc":[{"id":"1.230180125","rc":[{"atl":[[2.82,0],[2.72,1]],"id":65992794}],"con":true,"img":false}]}
{"op":"mcm","clk":"11541041068","pt":1719501465795,"mc":[{"id":"1.230180125","rc":[{"atb":[[1.28,14.11]],"id":65992794}],"con":true,"img":false}]}
{"op":"mcm","clk":"11541041074","pt":1719501465895,"mc":[{"id":"1.230180125","rc":[{"atb":[[1.25,2.13],[1.29,4.28]],"id":65992794},{"atb":[[1.92,0]],"id":67245400}],"con":true,"img":false}]}
{"op":"mcm","clk":"11541041087","pt":1719501466098,"mc":[{"id":"1.230180125","rc":[{"atb":[[1.9,10.92],[1.93,0],[1.95,4.15]],"id":67245400}],"con":true,"img":false}]}
{"op":"mcm","clk":"11541041098","pt":1719501466257,"mc":[{"id":"1.230180125","rc":[{"atb":[[1.9,0],[1.96,4.16]],"id":67245400}],"con":true,"img":false}]}
{"op":"mcm","clk":"11541041130","pt":1719501466776,"mc":[{"id":"1.230180125","rc":[{"atb":[[1.26,0]],"id":65992794}],"con":true,"img":false}]}
{"op":"mcm","clk":"11541041137","pt":1719501466882,"mc":[{"id":"1.230180125","rc":[{"atb":[[1.3,2]],"id":65992794}],"con":true,"img":false}]}
{"op":"mcm","clk":"11541041468","pt":1719501471277,"mc":[{"id":"1.230180125","rc":[{"atb":[[1.25,1]],"id":65992794},{"atl":[[5.1,0]],"id":65992794},{"atb":[[1.91,0]],"id":67245400},{"atl":[[36,0]],"id":67245400},{"atb":[[1.99,0]],"id":42767337},{"atl":[[48,0]],"id":42767337}],"con":true,"img":false}]}
{"op":"mcm","clk":"11541041575","pt":1719501472812,"mc":[{"id":"1.230180125","rc":[{"atb":[[1.07,3.75]],"id":42767337}],"con":true,"img":false}]}
{"op":"mcm","clk":"11541042042","pt":1719501478795,"mc":[{"id":"1.230180125","rc":[{"atb":[[1.78,0]],"id":51567147},{"atb":[[1.87,0]],"id":70902709}],"con":true,"img":false}]}
{"op":"mcm","clk":"11541042234","pt":1719501481073,"mc":[{"id":"1.230180125","rc":[{"atb":[[1.3,21.75]],"id":65992794}],"con":true,"img":false}]}
{"op":"mcm","clk":"11541042252","pt":1719501481299,"mc":[{"id":"1.230180125","rc":[{"atb":[[1.29,0],[1.31,14.12]],"id":65992794}],"con":true,"img":false}]}
{"op":"mcm","clk":"11541042261","pt":1719501481399,"mc":[{"id":"1.230180125","rc":[{"atb":[[1.9,4.7]],"id":51567147}],"con":true,"img":false}]}
{"op":"mcm","clk":"11541042270","pt":1719501481506,"mc":[{"id":"1.230180125","rc":[{"atb":[[1.87,0]],"id":51567147}],"con":true,"img":false}]}
{"op":"mcm","clk":"11541042279","pt":1719501481612,"mc":[{"id":"1.230180125","rc":[{"atb":[[1.07,0]],"id":42767337},{"atb":[[1.91,2]],"id":51567147}],"con":true,"img":false}]}
{"op":"mcm","clk":"11541042320","pt":1719501482087,"mc":[{"id":"1.230180125","rc":[{"atb":[[1.3,19.75]],"id":65992794}],"con":true,"img":false}]}
{"op":"mcm","clk":"11541042332","pt":1719501482191,"mc":[{"id":"1.230180125","rc":[{"atb":[[1.32,2]],"id":65992794}],"con":true,"img":false}]}
{"op":"mcm","clk":"11541042361","pt":1719501482511,"mc":[{"id":"1.230180125","rc":[{"atb":[[1.88,0]],"id":51567147}],"con":true,"img":false}]}
{"op":"mcm","clk":"11541042369","pt":1719501482610,"mc":[{"id":"1.230180125","rc":[{"atb":[[1.92,2]],"id":51567147}],"con":true,"img":false}]}
{"op":"mcm","clk":"11541042387","pt":1719501482780,"mc":[{"id":"1.230180125","rc":[{"atb":[[1.29,3]],"id":65992794}],"con":true,"img":false}]}
{"op":"mcm","clk":"11541042403","pt":1719501482979,"mc":[{"id":"1.230180125","rc":[{"atb":[[1.28,18.73]],"id":65992794}],"con":true,"img":false}]}
{"op":"mcm","clk":"11541042444","pt":1719501483401,"mc":[{"id":"1.230180125","rc":[{"atb":[[1.29,0]],"id":65992794}],"con":true,"img":false}]}
{"op":"mcm","clk":"11541042504","pt":1719501483971,"mc":[{"id":"1.230180125","rc":[{"atb":[[1.28,14.11]],"id":65992794}],"con":true,"img":false}]}
{"op":"mcm","clk":"11541042665","pt":1719501485822,"mc":[{"id":"1.230180125","rc":[{"atb":[[1.22,0]],"id":65992794}],"con":true,"img":false}]}
{"op":"mcm","clk":"11541042691","pt":1719501486074,"mc":[{"id":"1.230180125","rc":[{"atb":[[1.86,0]],"id":51567147}],"con":true,"img":false}]}
{"op":"mcm","clk":"11541042709","pt":1719501486185,"mc":[{"id":"1.230180125","rc":[{"atb":[[1.33,16.76]],"id":65992794}],"con":true,"img":false}]}
{"op":"mcm","clk":"11541042748","pt":1719501486593,"mc":[{"id":"1.230180125","rc":[{"atb":[[1.94,4.2]],"id":51567147}],"con":true,"img":false}]}
{"op":"mcm","clk":"11541042762","pt":1719501486706,"mc":[{"id":"1.230180125","rc":[{"atb":[[1.91,0]],"id":51567147}],"con":true,"img":false}]}
{"op":"mcm","clk":"11541042769","pt":1719501486804,"mc":[{"id":"1.230180125","rc":[{"atb":[[1.95,2]],"id":51567147}],"con":true,"img":false}]}
{"op":"mcm","clk":"11541042808","pt":1719501487218,"mc":[{"id":"1.230180125","rc":[{"atb":[[1.32,35.54],[1.31,0]],"id":65992794}],"con":true,"img":false}]}
{"op":"mcm","clk":"11541042899","pt":1719501488328,"mc":[{"id":"1.230180125","rc":[{"atb":[[1.32,33.54]],"id":65992794}],"con":true,"img":false}]}
{"op":"mcm","clk":"11541042903","pt":1719501488418,"mc":[{"id":"1.230180125","rc":[{"atb":[[1.34,2]],"id":65992794}],"con":true,"img":false}]}
{"op":"mcm","clk":"11541042947","pt":1719501488892,"mc":[{"id":"1.230180125","rc":[{"atb":[[1.92,0]],"id":51567147}],"con":true,"img":false}]}
{"op":"mcm","clk":"11541042956","pt":1719501488999,"mc":[{"id":"1.230180125","rc":[{"atb":[[1.96,2]],"id":51567147}],"con":true,"img":false}]}
{"op":"mcm","clk":"11541043270","pt":1719501493310,"mc":[{"id":"1.230180125","rc":[{"atb":[[1.25,0]],"id":65992794},{"atl":[[4,2],[5.2,0]],"id":65992794},{"spn":1.52,"spf":1.0,"id":65992794},{"atl":[[38,0],[29,2]],"id":67245400},{"spn":3.98,"spf":"NaN","id":67245400},{"atl":[[38,2],[50,0]],"id":42767337},{"spn":4.29,"spf":"NaN","id":42767337},{"atl":[[18,0],[15,2]],"id":51567147},{"spn":3.18,"spf":"NaN","id":51567147},{"spn":3.63,"spf":"NaN","id":70902709}],"con":true,"img":false}]}
{"op":"mcm","clk":"11541043659","pt":1719501498236,"mc":[{"id":"1.230180125","rc":[{"atb":[[1.96,3.12]],"id":42767337}],"con":true,"img":false}]}
{"op":"mcm","clk":"11541043679","pt":1719501498495,"mc":[{"id":"1.230180125","rc":[{"atl":[[6.4,1],[6,0]],"id":67245400}],"con":true,"img":false}]}
{"op":"mcm","clk":"11541043960","pt":1719501502126,"mc":[{"id":"1.230180125","rc":[{"atl":[[2.72,0],[2.7,1]],"id":65992794}],"con":true,"img":false}]}
{"op":"mcm","clk":"11541044005","pt":1719501502637,"mc":[{"id":"1.230180125","rc":[{"atb":[[1.33,0]],"id":65992794}],"con":true,"img":false}]}
{"op":"mcm","clk":"11541044016","pt":1719501502808,"mc":[{"id":"1.230180125","rc":[{"atb":[[1.34,18.27]],"id":65992794}],"con":true,"img":false}]}
{"op":"mcm","clk":"11541044228","pt":1719501505910,"mc":[{"id":"1.230180125","rc":[{"atb":[[1.95,7.9]],"id":67245400},{"atb":[[1.95,3.75]],"id":42767337},{"atb":[[1.95,9.15]],"id":70902709}],"con":true,"img":false}]}
{"op":"mcm","clk":"11541044235","pt":1719501506008,"mc":[{"id":"1.230180125","rc":[{"atb":[[1.9,10.92],[1.96,0]],"id":67245400}],"con":true,"img":false}]}
{"op":"mcm","clk":"11541044240","pt":1719501506106,"mc":[{"id":"1.230180125","rc":[{"atb":[[1.9,0],[1.96,4.16]],"id":67245400}],"con":true,"img":false}]}
{"op":"mcm","clk":"11541044280","pt":1719501506644,"mc":[{"id":"1.230180125","rc":[{"atb":[[1.95,4.15]],"id":67245400},{"atb":[[1.02,0]],"id":42767337}],"con":true,"img":false}]}
{"op":"mcm","clk":"11541044287","pt":1719501506731,"mc":[{"id":"1.230180125","rc":[{"atb":[[1.99,2]],"id":42767337}],"con":true,"img":false}]}
{"op":"mcm","clk":"11541044302","pt":1719501506939,"mc":[{"id":"1.230180125","rc":[{"atb":[[1.94,9.2]],"id":51567147}],"con":true,"img":false}]}
{"op":"mcm","clk":"11541044309","pt":1719501506992,"mc":[{"id":"1.230180125","rc":[{"atb":[[1.96,0]],"id":42767337}],"con":true,"img":false}]}
{"op":"mcm","clk":"11541044371","pt":1719501507730,"mc":[{"id":"1.230180125","rc":[{"atb":[[1.29,3.12]],"id":65992794},{"atb":[[1.95,0]],"id":42767337}],"con":true,"img":false}]}
{"op":"mcm","clk":"11541044430","pt":1719501508396,"mc":[{"id":"1.230180125","rc":[{"atb":[[1.99,0]],"id":42767337}],"con":true,"img":false}]}
{"op":"mcm","clk":"11541044438","pt":1719501508500,"mc":[{"id":"1.230180125","rc":[{"atb":[[1.02,2]],"id":42767337}],"con":true,"img":false}]}
{"op":"mcm","clk":"11541044455","pt":1719501508739,"mc":[{"id":"1.230180125","rc":[{"atb":[[1.31,5.37]],"id":65992794}],"con":true,"img":false}]}
{"op":"mcm","clk":"11541044488","pt":1719501509134,"mc":[{"id":"1.230180125","rc":[{"atb":[[1.29,0]],"id":65992794}],"con":true,"img":false}]}
{"op":"mcm","clk":"11541044689","pt":1719501511729,"mc":[{"id":"1.230180125","rc":[{"atl":[[2.68,1],[2.7,0]],"id":65992794}],"con":true,"img":false}]}
{"op":"mcm","clk":"11541044955","pt":1719501514950,"mc":[{"id":"1.230180125","rc":[{"atb":[[2,5.92]],"id":70902709}],"con":true,"img":false}]}
{"op":"mcm","clk":"11541044970","pt":1719501515159,"mc":[{"id":"1.230180125","rc":[{"atb":[[2.02,4.16],[1.96,0]],"id":70902709}],"con":true,"img":false}]}
{"op":"mcm","clk":"11541044979","pt":1719501515251,"mc":[{"id":"1.230180125","rc":[{"atb":[[2,5.92]],"id":51567147}],"con":true,"img":false}]}
{"op":"mcm","clk":"11541044995","pt":1719501515453,"mc":[{"id":"1.230180125","rc":[{"atb":[[2.02,2],[1.95,0]],"id":51567147}],"con":true,"img":false}]}
{"op":"mcm","clk":"11541045086","pt":1719501516547,"mc":[{"id":"1.230180125","rc":[{"atb":[[1.97,0]],"id":70902709}],"con":true,"img":false}]}
{"op":"mcm","clk":"11541045093","pt":1719501516652,"mc":[{"id":"1.230180125","rc":[{"atb":[[2.04,2]],"id":70902709}],"con":true,"img":false}]}
{"op":"mcm","clk":"11541045114","pt":1719501516968,"mc":[{"id":"1.230180125","rc":[{"atb":[[1.96,0]],"id":51567147}],"con":true,"img":false}]}
{"op":"mcm","clk":"11541045127","pt":1719501517055,"mc":[{"id":"1.230180125","rc":[{"atb":[[2.04,2]],"id":51567147}],"con":true,"img":false}]}
{"op":"mcm","clk":"11541045317","pt":1719501519256,"mc":[{"id":"1.230180125","rc":[{"atb":[[1.95,5]],"id":70902709}],"con":true,"img":false}]}
{"op":"mcm","clk":"11541045390","pt":1719501520247,"mc":[{"id":"1.230180125","rc":[{"atl":[[6.4,0],[6.8,1]],"id":67245400}],"con":true,"img":false}]}
{"op":"mcm","clk":"11541045440","pt":1719501520862,"mc":[{"id":"1.230180125","rc":[{"atb":[[2,11.46]],"id":70902709}],"con":true,"img":false}]}
{"op":"mcm","clk":"11541045556","pt":1719501522268,"mc":[{"id":"1.230180125","rc":[{"atb":[[1.07,3.75]],"id":42767337}],"con":true,"img":false}]}
{"op":"mcm","clk":"11541045876","pt":1719501526168,"mc":[{"id":"1.230180125","rc":[{"atb":[[1.07,0]],"id":42767337}],"con":true,"img":false}]}
{"op":"mcm","clk":"11541046070","pt":1719501528743,"mc":[{"id":"1.230180125","rc":[{"atb":[[1.95,0]],"id":70902709}],"con":true,"img":false}]}
{"op":"mcm","clk":"11541046130","pt":1719501529661,"mc":[{"id":"1.230180125","rc":[{"atb":[[1.95,7.9]],"id":67245400},{"atb":[[1.97,4.75]],"id":42767337}],"con":true,"img":false}]}
{"op":"mcm","clk":"11541046138","pt":1719501529771,"mc":[{"id":"1.230180125","rc":[{"atb":[[1.9,10.92],[1.96,0]],"id":67245400}],"con":true,"img":false}]}
{"op":"mcm","clk":"11541046145","pt":1719501529868,"mc":[{"id":"1.230180125","rc":[{"atb":[[1.9,0],[1.96,4.16]],"id":67245400}],"con":true,"img":false}]}
{"op":"mcm","clk":"11541046154","pt":1719501529970,"mc":[{"id":"1.230180125","rc":[{"atb":[[1.99,5]],"id":70902709}],"con":true,"img":false}]}
{"op":"mcm","clk":"11541046180","pt":1719501530240,"mc":[{"id":"1.230180125","rc":[{"atb":[[1.95,4.15]],"id":67245400},{"atb":[[1.94,4.2]],"id":51567147}],"con":true,"img":false}]}
{"op":"mcm","clk":"11541046209","pt":1719501530749,"mc":[{"id":"1.230180125","rc":[{"atb":[[1.99,0]],"id":70902709}],"con":true,"img":false}]}
{"op":"mcm","clk":"11541046266","pt":1719501531370,"mc":[{"id":"1.230180125","rc":[{"atb":[[1.29,3.12]],"id":65992794}],"con":true,"img":false}]}
{"op":"mcm","clk":"11541046282","pt":1719501531578,"mc":[{"id":"1.230180125","rc":[{"atb":[[1.31,6.41]],"id":65992794}],"con":true,"img":false}]}
{"op":"mcm","clk":"11541046304","pt":1719501531751,"mc":[{"id":"1.230180125","rc":[{"atb":[[1.31,5.37]],"id":65992794}],"con":true,"img":false}]}
{"op":"mcm","clk":"11541046368","pt":1719501532463,"mc":[{"id":"1.230180125","rc":[{"atb":[[2,10.92]],"id":51567147}],"con":true,"img":false}]}
{"op":"mcm","clk":"11541046662","pt":1719501536242,"mc":[{"id":"1.230180125","rc":[{"atb":[[1.97,1]],"id":42767337},{"atb":[[2,5.92]],"id":51567147}],"con":true,"img":false}]}
{"op":"mcm","clk":"11541046701","pt":1719501536756,"mc":[{"id":"1.230180125","rc":[{"atb":[[1.31,0]],"id":65992794}],"con":true,"img":false}]}
{"op":"mcm","clk":"11541046721","pt":1719501536966,"mc":[{"id":"1.230180125","rc":[{"atb":[[1.29,0]],"id":65992794}],"con":true,"img":false}]}
{"op":"mcm","clk":"11541047388","pt":1719501545176,"mc":[{"id":"1.230180125","rc":[{"atb":[[1.96,3.25]],"id":42767337}],"con":true,"img":false}]}
{"op":"mcm","clk":"11541047774","pt":1719501549890,"mc":[{"id":"1.230180125","rc":[{"atl":[[6.4,1],[6.8,0]],"id":67245400}],"con":true,"img":false}]}
{"op":"mcm","clk":"11541047976","pt":1719501552208,"mc":[{"id":"1.230180125","rc":[{"atb":[[1.96,7]],"id":42767337}],"con":true,"img":false}]}
{"op":"mcm","clk":"11541047983","pt":1719501552298,"mc":[{"id":"1.230180125","rc":[{"atb":[[1.94,3.75]],"id":67245400}],"con":true,"img":false}]}
{"op":"mcm","clk":"11541047994","pt":1719501552397,"mc":[{"id":"1.230180125","rc":[{"atb":[[1.28,0]],"id":65992794},{"atb":[[1.95,0]],"id":67245400},{"atb":[[1.99,5]],"id":70902709}],"con":true,"img":false}]}
{"op":"mcm","clk":"11541048003","pt":1719501552467,"mc":[{"id":"1.230180125","rc":[{"atb":[[1.9,10.92],[1.96,0]],"id":67245400}],"con":true,"img":false}]}
{"op":"mcm","clk":"11541048039","pt":1719501552876,"mc":[{"id":"1.230180125","rc":[{"atb":[[1.94,0]],"id":67245400}],"con":true,"img":false}]}
{"op":"mcm","clk":"11541048114","pt":1719501553797,"mc":[{"id":"1.230180125","rc":[{"atb":[[1.29,3.12]],"id":65992794},{"atb":[[1.95,5.82]],"id":67245400},{"spn":4.17,"spf":"NaN","id":67245400},{"spn":3.22,"spf":"NaN","id":51567147},{"spn":3.67,"spf":"NaN","id":70902709}],"con":true,"img":false}]}
{"op":"mcm","clk":"11541048130","pt":1719501553969,"mc":[{"id":"1.230180125","rc":[{"atb":[[1.9,0],[1.96,5.83]],"id":67245400}],"con":true,"img":false}]}
{"op":"mcm","clk":"11541048141","pt":1719501554073,"mc":[{"id":"1.230180125","rc":[{"atb":[[1.29,0]],"id":65992794}],"con":true,"img":false}]}
{"op":"mcm","clk":"11541048192","pt":1719501554786,"mc":[{"id":"1.230180125","rc":[{"atb":[[1.99,5]],"id":51567147}],"con":true,"img":false}]}
{"op":"mcm","clk":"11541048317","pt":1719501556387,"mc":[{"id":"1.230180125","rc":[{"atl":[[6.4,0],[6,1]],"id":67245400}],"con":true,"img":false}]}
{"op":"mcm","clk":"11541048427","pt":1719501557677,"mc":[{"id":"1.230180125","rc":[{"atb":[[1.96,3.75]],"id":42767337}],"con":true,"img":false}]}
{"op":"mcm","clk":"11541049209","pt":1719501566009,"mc":[{"id":"1.230180125","rc":[{"atb":[[1.96,7]],"id":42767337}],"con":true,"img":false}]}
{"op":"mcm","clk":"11541049817","pt":1719501573120,"mc":[{"id":"1.230180125","rc":[{"atb":[[1.94,0]],"id":51567147}],"con":true,"img":false}]}
{"op":"mcm","clk":"11541049862","pt":1719501573640,"mc":[{"id":"1.230180125","rc":[{"atb":[[1.95,9.57]],"id":67245400}],"con":true,"img":false}]}
{"op":"mcm","clk":"11541049974","pt":1719501574853,"mc":[{"id":"1.230180125","rc":[{"atb":[[1.31,5.37]],"id":65992794}],"con":true,"img":false}]}
{"op":"mcm","clk":"11541050007","pt":1719501575119,"mc":[{"id":"1.230180125","rc":[{"atb":[[1.29,8.06]],"id":65992794}],"con":true,"img":false}]}
{"op":"mcm","clk":"11541050025","pt":1719501575323,"mc":[{"id":"1.230180125","rc":[{"atb":[[1.29,0]],"id":65992794}],"con":true,"img":false}]}
{"op":"mcm","clk":"11541050043","pt":1719501575523,"mc":[{"id":"1.230180125","rc":[{"atb":[[1.31,0]],"id":65992794}],"con":true,"img":false}]}
{"op":"mcm","clk":"11541050615","pt":1719501582319,"mc":[{"id":"1.230180125","rc":[{"atl":[[2.68,0],[2.7,1]],"id":65992794}],"con":true,"img":false}]}
{"op":"mcm","clk":"11541050780","pt":1719501584645,"mc":[{"id":"1.230180125","rc":[{"atb":[[1.3,0]],"id":65992794},{"atb":[[1.9,0]],"id":51567147},{"atb":[[2,5.53]],"id":70902709}],"con":true,"img":false}]}
{"op":"mcm","clk":"11541050828","pt":1719501585328,"mc":[{"id":"1.230180125","rc":[{"atb":[[1.34,16.27]],"id":65992794}],"con":true,"img":false}]}
{"op":"mcm","clk":"11541050833","pt":1719501585442,"mc":[{"id":"1.230180125","rc":[{"atb":[[1.02,2]],"id":65992794}],"con":true,"img":false}]}
{"op":"mcm","clk":"11541050850","pt":1719501585647,"mc":[{"id":"1.230180125","rc":[{"atb":[[2,5.92]],"id":67245400}],"con":true,"img":false}]}
{"op":"mcm","clk":"11541050859","pt":1719501585736,"mc":[{"id":"1.230180125","rc":[{"atb":[[2.02,5.93],[1.96,0]],"id":67245400}],"con":true,"img":false}]}
{"op":"mcm","clk":"11541050883","pt":1719501586046,"mc":[{"id":"1.230180125","rc":[{"atb":[[1.95,5.82]],"id":67245400}],"con":true,"img":false}]}
{"op":"mcm","clk":"11541050920","pt":1719501586353,"mc":[{"id":"1.230180125","rc":[{"atb":[[1.02,8.92]],"id":67245400}],"con":true,"img":false}]}
{"op":"mcm","clk":"11541050929","pt":1719501586461,"mc":[{"id":"1.230180125","rc":[{"atb":[[2.04,2]],"id":67245400}],"con":true,"img":false}]}
{"op":"mcm","clk":"11541051533","pt":1719501593965,"mc":[{"id":"1.230180125","rc":[{"atb":[[2.02,10.93]],"id":67245400}],"con":true,"img":false}]}
{"op":"mcm","clk":"11541051647","pt":1719501595249,"mc":[{"id":"1.230180125","rc":[{"atb":[[1.31,5.37]],"id":65992794}],"con":true,"img":false}]}
{"op":"mcm","clk":"11541051694","pt":1719501595865,"mc":[{"id":"1.230180125","rc":[{"atb":[[1.02,0]],"id":65992794}],"con":true,"img":false}]}
{"op":"mcm","clk":"11541051703","pt":1719501595970,"mc":[{"id":"1.230180125","rc":[{"atb":[[1.35,2]],"id":65992794}],"con":true,"img":false}]}
{"op":"mcm","clk":"11541051758","pt":1719501596655,"mc":[{"id":"1.230180125","rc":[{"atb":[[1.31,0]],"id":65992794}],"con":true,"img":false}]}
{"op":"mcm","clk":"11541052025","pt":1719501599655,"mc":[{"id":"1.230180125","rc":[{"atb":[[2.04,0]],"id":51567147},{"trd":[[2.04,4]],"ltp":2.04,"tv":4.0,"id":51567147}],"con":true,"img":false}]}
{"op":"mcm","clk":"11541052032","pt":1719501599759,"mc":[{"id":"1.230180125","rc":[{"atl":[[4.3,1]],"id":51567147}],"con":true,"img":false}]}
{"op":"mcm","clk":"11541052051","pt":1719501599965,"mc":[{"id":"1.230180125","rc":[{"atb":[[2.04,3.94]],"id":67245400},{"atb":[[2.02,3.94]],"id":51567147},{"atb":[[2.04,3.94]],"id":70902709}],"con":true,"img":false}]}
{"op":"mcm","clk":"11541052071","pt":1719501600174,"mc":[{"id":"1.230180125","rc":[{"atb":[[2.02,5],[2.06,5.93]],"id":67245400},{"atb":[[2.02,0],[2.06,4.16]],"id":70902709}],"con":true,"img":false}]}
{"op":"mcm","clk":"11541052118","pt":1719501600675,"mc":[{"id":"1.230180125","rc":[{"atb":[[2.02,0]],"id":67245400},{"atb":[[1.99,0]],"id":51567147},{"atb":[[1.99,0]],"id":70902709}],"con":true,"img":false}]}
{"op":"mcm","clk":"11541052135","pt":1719501600866,"mc":[{"id":"1.230180125","rc":[{"atb":[[2.04,1.94]],"id":67245400}],"con":true,"img":false}]}
{"op":"mcm","clk":"11541052142","pt":1719501600968,"mc":[{"id":"1.230180125","rc":[{"atb":[[2.06,0],[2.08,2]],"id":67245400}],"con":true,"img":false}]}
{"op":"mcm","clk":"11541052152","pt":1719501601075,"mc":[{"id":"1.230180125","rc":[{"atb":[[2.04,13.8]],"id":67245400}],"con":true,"img":false}]}
{"op":"mcm","clk":"11541052169","pt":1719501601287,"mc":[{"id":"1.230180125","rc":[{"atb":[[2.04,1.94]],"id":70902709}],"con":true,"img":false}]}
{"op":"mcm","clk":"11541052180","pt":1719501601386,"mc":[{"id":"1.230180125","rc":[{"atb":[[2.06,0],[2.04,10.26],[2.08,2]],"id":70902709}],"con":true,"img":false}]}
{"op":"mcm","clk":"11541052225","pt":1719501601863,"mc":[{"id":"1.230180125","rc":[{"atb":[[2,9.67]],"id":51567147},{"atb":[[2,9.28]],"id":70902709}],"con":true,"img":false}]}
{"op":"mcm","clk":"11541052281","pt":1719501602595,"mc":[{"id":"1.230180125","rc":[{"atb":[[2.08,0]],"id":67245400}],"con":true,"img":false}]}
{"op":"mcm","clk":"11541052289","pt":1719501602650,"mc":[{"id":"1.230180125","rc":[{"atb":[[2.06,2]],"id":67245400}],"con":true,"img":false}]}
{"op":"mcm","clk":"11541052315","pt":1719501603069,"mc":[{"id":"1.230180125","rc":[{"atb":[[2.08,0]],"id":70902709}],"con":true,"img":false}]}
{"op":"mcm","clk":"11541052325","pt":1719501603167,"mc":[{"id":"1.230180125","rc":[{"atb":[[2.06,2]],"id":70902709}],"con":true,"img":false}]}
{"op":"mcm","clk":"11541052611","pt":1719501606468,"mc":[{"id":"1.230180125","rc":[{"atb":[[2.02,3.12]],"id":70902709}],"con":true,"img":false}]}
{"op":"mcm","clk":"11541052633","pt":1719501606670,"mc":[{"id":"1.230180125","rc":[{"atb":[[2.02,0]],"id":70902709}],"con":true,"img":false}]}
{"op":"mcm","clk":"11541052790","pt":1719501608594,"mc":[{"id":"1.230180125","rc":[{"atb":[[2,3.75]],"id":70902709}],"con":true,"img":false}]}
{"op":"mcm","clk":"11541052904","pt":1719501610002,"mc":[{"id":"1.230180125","rc":[{"atb":[[1.95,0]],"id":67245400}],"con":true,"img":false}]}
{"op":"mcm","clk":"11541052921","pt":1719501610209,"mc":[{"id":"1.230180125","rc":[{"atb":[[2.1,5.02]],"id":67245400},{"atb":[[2.06,5.21]],"id":51567147}],"con":true,"img":false}]}
{"op":"mcm","clk":"11541052929","pt":1719501610270,"mc":[{"id":"1.230180125","rc":[{"atb":[[2.04,1.94],[2.12,5.03]],"id":67245400},{"atb":[[2.02,1.94],[2.08,5.22]],"id":51567147}],"con":true,"img":false}]}
{"op":"mcm","clk":"11541052979","pt":1719501610989,"mc":[{"id":"1.230180125","rc":[{"atb":[[2.06,0]],"id":67245400}],"con":true,"img":false}]}
{"op":"mcm","clk":"11541052986","pt":1719501611102,"mc":[{"id":"1.230180125","rc":[{"atb":[[2.14,2]],"id":67245400}],"con":true,"img":false}]}
{"op":"mcm","clk":"11541053067","pt":1719501612087,"mc":[{"id":"1.230180125","rc":[{"atb":[[2.04,0]],"id":67245400},{"atb":[[2.02,0]],"id":51567147}],"con":true,"img":false}]}
{"op":"mcm","clk":"11541053086","pt":1719501612289,"mc":[{"id":"1.230180125","rc":[{"atb":[[2.14,3.94]],"id":67245400},{"atb":[[2.1,1.94]],"id":51567147}],"con":true,"img":false}]}
{"op":"mcm","clk":"11541053171","pt":1719501613379,"mc":[{"id":"1.230180125","rc":[{"atb":[[2.12,9.81]],"id":67245400}],"con":true,"img":false}]}
{"op":"mcm","clk":"11541053256","pt":1719501614471,"mc":[{"id":"1.230180125","rc":[{"atb":[[1.31,5]],"id":65992794},{"spn":1.53,"spf":1.0,"id":65992794},{"spn":4.07,"spf":"NaN","id":67245400},{"spn":3.2,"spf":"NaN","id":51567147},{"spn":3.68,"spf":"NaN","id":70902709}],"con":true,"img":false}]}
{"op":"mcm","clk":"11541053294","pt":1719501614784,"mc":[{"id":"1.230180125","rc":[{"atb":[[1.31,0]],"id":65992794}],"con":true,"img":false}]}
{"op":"mcm","clk":"11541053319","pt":1719501614993,"mc":[{"id":"1.230180125","rc":[{"atl":[[4,1.99]],"id":51567147}],"con":true,"img":false}]}
{"op":"mcm","clk":"11541053333","pt":1719501615097,"mc":[{"id":"1.230180125","rc":[{"atb":[[2.1,0]],"id":51567147},{"atl":[[4.3,0],[5,2],[15,0]],"id":51567147}],"con":true,"img":false}]}
{"op":"mcm","clk":"11541053350","pt":1719501615199,"mc":[{"id":"1.230180125","rc":[{"atl":[[4,0]],"id":51567147}],"con":true,"img":false}]}
{"op":"mcm","clk":"11541053367","pt":1719501615303,"mc":[{"id":"1.230180125","rc":[{"atb":[[2.1,1.94]],"id":51567147},{"atl":[[5,0],[15,3]],"id":51567147}],"con":true,"img":false}]}
{"op":"mcm","clk":"11541053384","pt":1719501615514,"mc":[{"id":"1.230180125","rc":[{"atb":[[2.12,4.78],[2.16,5.03]],"id":67245400}],"con":true,"img":false}]}
{"op":"mcm","clk":"11541053462","pt":1719501616291,"mc":[{"id":"1.230180125","rc":[{"atb":[[2.12,0]],"id":67245400}],"con":true,"img":false}]}
{"op":"mcm","clk":"11541053524","pt":1719501616974,"mc":[{"id":"1.230180125","rc":[{"atb":[[2,3.75]],"id":51567147}],"con":true,"img":false}]}
{"op":"mcm","clk":"11541053531","pt":1719501617075,"mc":[{"id":"1.230180125","rc":[{"atl":[[4.3,1]],"id":51567147}],"con":true,"img":false}]}
{"op":"mcm","clk":"11541053557","pt":1719501617383,"mc":[{"id":"1.230180125","rc":[{"atl":[[4.1,2.84]],"id":51567147}],"con":true,"img":false}]}
{"op":"mcm","clk":"11541053581","pt":1719501617692,"mc":[{"id":"1.230180125","rc":[{"atb":[[2.14,1.94]],"id":67245400},{"atl":[[4,0.84]],"id":51567147}],"con":true,"img":false}]}
{"op":"mcm","clk":"11541053588","pt":1719501617792,"mc":[{"id":"1.230180125","rc":[{"atb":[[2.18,2]],"id":67245400},{"atl":[[4.3,0]],"id":51567147}],"con":true,"img":false}]}
{"op":"mcm","clk":"11541053613","pt":1719501618105,"mc":[{"id":"1.230180125","rc":[{"atb":[[2.14,0]],"id":67245400},{"atb":[[2.1,0]],"id":51567147}],"con":true,"img":false}]}
{"op":"mcm","clk":"11541053626","pt":1719501618207,"mc":[{"id":"1.230180125","rc":[{"atb":[[2.18,3.94]],"id":67245400},{"atb":[[2.1,1.94]],"id":51567147}],"con":true,"img":false}]}
{"op":"mcm","clk":"11541053644","pt":1719501618365,"mc":[{"id":"1.230180125","rc":[{"atl":[[4.1,0]],"id":51567147}],"con":true,"img":false}]}
{"op":"mcm","clk":"11541053662","pt":1719501618578,"mc":[{"id":"1.230180125","rc":[{"atl":[[4.1,1.84]],"id":51567147}],"con":true,"img":false}]}
{"op":"mcm","clk":"11541053673","pt":1719501618677,"mc":[{"id":"1.230180125","rc":[{"atl":[[4,0]],"id":51567147}],"con":true,"img":false}]}
{"op":"mcm","clk":"11541053762","pt":1719501619809,"mc":[{"id":"1.230180125","rc":[{"atb":[[2,5.07]],"id":51567147},{"atb":[[2,5]],"id":70902709}],"con":true,"img":false}]}
{"op":"mcm","clk":"11541053772","pt":1719501619866,"mc":[{"id":"1.230180125","rc":[{"atl":[[4,1]],"id":51567147}],"con":true,"img":false}]}
{"op":"mcm","clk":"11541053814","pt":1719501620386,"mc":[{"id":"1.230180125","rc":[{"atl":[[5,2],[15,0]],"id":51567147}],"con":true,"img":false}]}
{"op":"mcm","clk":"11541053840","pt":1719501620589,"mc":[{"id":"1.230180125","rc":[{"atb":[[2.2,5.03]],"id":67245400}],"con":true,"img":false}]}
{"op":"mcm","clk":"11541053851","pt":1719501620694,"mc":[{"id":"1.230180125","rc":[{"atb":[[2.16,0]],"id":67245400}],"con":true,"img":false}]}
{"op":"mcm","clk":"11541053904","pt":1719501621107,"mc":[{"id":"1.230180125","rc":[{"atb":[[2.18,2]],"id":67245400},{"atb":[[2.1,0]],"id":51567147}],"con":true,"img":false}]}
{"op":"mcm","clk":"11541053916","pt":1719501621208,"mc":[{"id":"1.230180125","rc":[{"atb":[[2.22,1.94]],"id":67245400},{"atb":[[2.1,1.94]],"id":51567147}],"con":true,"img":false}]}
{"op":"mcm","clk":"11541053931","pt":1719501621312,"mc":[{"id":"1.230180125","rc":[{"atb":[[2,0]],"id":51567147}],"con":true,"img":false}]}
{"op":"mcm","clk":"11541054005","pt":1719501621893,"mc":[{"id":"1.230180125","rc":[{"atb":[[2.18,0]],"id":67245400}],"con":true,"img":false}]}
{"op":"mcm","clk":"11541054017","pt":1719501622005,"mc":[{"id":"1.230180125","rc":[{"atb":[[2.22,3.94]],"id":67245400}],"con":true,"img":false}]}
{"op":"mcm","clk":"11541054125","pt":1719501623084,"mc":[{"id":"1.230180125","rc":[{"atl":[[4.1,0]],"id":51567147}],"con":true,"img":false}]}
{"op":"mcm","clk":"11541054132","pt":1719501623186,"mc":[{"id":"1.230180125","rc":[{"atl":[[4,0]],"id":51567147}],"con":true,"img":false}]}
{"op":"mcm","clk":"11541054209","pt":1719501624118,"mc":[{"id":"1.230180125","rc":[{"atb":[[2.1,0]],"id":51567147}],"con":true,"img":false}]}
{"op":"mcm","clk":"11541054220","pt":1719501624174,"mc":[{"id":"1.230180125","rc":[{"atb":[[2.1,1.94]],"id":51567147}],"con":true,"img":false}]}
{"op":"mcm","clk":"11541054284","pt":1719501624893,"mc":[{"id":"1.230180125","rc":[{"atl":[[5,0],[15,3]],"id":51567147}],"con":true,"img":false}]}
{"op":"mcm","clk":"11541054367","pt":1719501625676,"mc":[{"id":"1.230180125","rc":[{"atb":[[2.24,5.03],[2.2,0]],"id":67245400}],"con":true,"img":false}]}
{"op":"mcm","clk":"11541054378","pt":1719501625781,"mc":[{"id":"1.230180125","rc":[{"atl":[[4.3,1]],"id":51567147}],"con":true,"img":false}]}
{"op":"mcm","clk":"11541054419","pt":1719501626294,"mc":[{"id":"1.230180125","rc":[{"atl":[[4,2.98]],"id":51567147}],"con":true,"img":false}]}
{"op":"mcm","clk":"11541054425","pt":1719501626417,"mc":[{"id":"1.230180125","rc":[{"atl":[[4.3,0]],"id":51567147}],"con":true,"img":false}]}
{"op":"mcm","clk":"11541054459","pt":1719501626677,"mc":[{"id":"1.230180125","rc":[{"atl":[[3.95,0.84]],"id":51567147}],"con":true,"img":false}]}
{"op":"mcm","clk":"11541054494","pt":1719501627091,"mc":[{"id":"1.230180125","rc":[{"atb":[[2.22,2]],"id":67245400},{"atb":[[2.1,0]],"id":51567147}],"con":true,"img":false}]}
{"op":"mcm","clk":"11541054519","pt":1719501627297,"mc":[{"id":"1.230180125","rc":[{"atb":[[2.26,1.94]],"id":67245400},{"atb":[[2.1,1.94]],"id":51567147}],"con":true,"img":false}]}
{"op":"mcm","clk":"11541054636","pt":1719501628694,"mc":[{"id":"1.230180125","rc":[{"atb":[[2.22,0]],"id":67245400}],"con":true,"img":false}]}
{"op":"mcm","clk":"11541054644","pt":1719501628793,"mc":[{"id":"1.230180125","rc":[{"atb":[[2.26,3.94]],"id":67245400},{"atl":[[3.9,1]],"id":51567147}],"con":true,"img":false}]}
{"op":"mcm","clk":"11541054751","pt":1719501630088,"mc":[{"id":"1.230180125","rc":[{"atl":[[5,2],[15,0]],"id":51567147}],"con":true,"img":false}]}
{"op":"mcm","clk":"11541054762","pt":1719501630192,"mc":[{"id":"1.230180125","rc":[{"atb":[[2.1,0]],"id":51567147}],"con":true,"img":false}]}
{"op":"mcm","clk":"11541054778","pt":1719501630406,"mc":[{"id":"1.230180125","rc":[{"atb":[[2.1,1.94]],"id":51567147}],"con":true,"img":false}]}
{"op":"mcm","clk":"11541054816","pt":1719501630819,"mc":[{"id":"1.230180125","rc":[{"atb":[[2.24,0],[2.28,5.03]],"id":67245400}],"con":true,"img":false}]}
{"op":"mcm","clk":"11541054880","pt":1719501631388,"mc":[{"id":"1.230180125","rc":[{"atb":[[2.26,1.94]],"id":67245400}],"con":true,"img":false}]}
{"op":"mcm","clk":"11541054891","pt":1719501631490,"mc":[{"id":"1.230180125","rc":[{"atb":[[2.3,2]],"id":67245400}],"con":true,"img":false}]}
{"op":"mcm","clk":"11541054909","pt":1719501631700,"mc":[{"id":"1.230180125","rc":[{"atb":[[2.2,4.5]],"id":67245400}],"con":true,"img":false}]}
{"op":"mcm","clk":"11541055017","pt":1719501632837,"mc":[{"id":"1.230180125","rc":[{"atb":[[1.31,5]],"id":65992794}],"con":true,"img":false}]}
{"op":"mcm","clk":"11541055062","pt":1719501633310,"mc":[{"id":"1.230180125","rc":[{"atb":[[1.31,0]],"id":65992794},{"atb":[[2.26,0]],"id":67245400},{"atb":[[2.1,0]],"id":51567147}],"con":true,"img":false}]}
{"op":"mcm","clk":"11541055072","pt":1719501633415,"mc":[{"id":"1.230180125","rc":[{"atb":[[2.3,3.94]],"id":67245400},{"atb":[[2.1,1.94]],"id":51567147}],"con":true,"img":false}]}
{"op":"mcm","clk":"11541055275","pt":1719501635890,"mc":[{"id":"1.230180125","rc":[{"atb":[[2.32,4.5],[2.28,0]],"id":67245400}],"con":true,"img":false}]}
{"op":"mcm","clk":"11541055303","pt":1719501636304,"mc":[{"id":"1.230180125","rc":[{"atb":[[2.3,2]],"id":67245400},{"atb":[[2.1,0]],"id":51567147}],"con":true,"img":false}]}
{"op":"mcm","clk":"11541055312","pt":1719501636402,"mc":[{"id":"1.230180125","rc":[{"atb":[[2.32,0],[2.3,11]],"id":67245400}],"con":true,"img":false}]}
{"op":"mcm","clk":"11541055319","pt":1719501636508,"mc":[{"id":"1.230180125","rc":[{"atb":[[2.34,1.94]],"id":67245400},{"atb":[[2.1,1.94]],"id":51567147}],"con":true,"img":false}]}
{"op":"mcm","clk":"11541055578","pt":1719501639404,"mc":[{"id":"1.230180125","rc":[{"atb":[[2.34,0]],"id":67245400},{"atb":[[2.06,10],[2.1,0]],"id":51567147}],"con":true,"img":false}]}
{"op":"mcm","clk":"11541055598","pt":1719501639608,"mc":[{"id":"1.230180125","rc":[{"atb":[[2.32,1.94]],"id":67245400},{"atb":[[2.1,1.94]],"id":51567147}],"con":true,"img":false}]}
{"op":"mcm","clk":"11541055826","pt":1719501642514,"mc":[{"id":"1.230180125","rc":[{"atb":[[2.32,0]],"id":67245400},{"atb":[[2.1,0]],"id":51567147}],"con":true,"img":false}]}
{"op":"mcm","clk":"11541055836","pt":1719501642621,"mc":[{"id":"1.230180125","rc":[{"atb":[[2.32,1.94]],"id":67245400},{"atb":[[2.1,1.94]],"id":51567147}],"con":true,"img":false}]}
{"op":"mcm","clk":"11541056045","pt":1719501645612,"mc":[{"id":"1.230180125","rc":[{"atb":[[2.32,0]],"id":67245400},{"atb":[[2.1,0]],"id":51567147}],"con":true,"img":false}]}
{"op":"mcm","clk":"11541056055","pt":1719501645715,"mc":[{"id":"1.230180125","rc":[{"atb":[[2.32,1.94]],"id":67245400},{"atb":[[2.1,1.94]],"id":51567147}],"con":true,"img":false}]}
{"op":"mcm","clk":"11541056316","pt":1719501648712,"mc":[{"id":"1.230180125","rc":[{"atb":[[2.32,0]],"id":67245400},{"atb":[[2.1,0]],"id":51567147}],"con":true,"img":false}]}
{"op":"mcm","clk":"11541056331","pt":1719501648918,"mc":[{"id":"1.230180125","rc":[{"atb":[[2.32,1.94]],"id":67245400},{"atb":[[2.1,1.94]],"id":51567147}],"con":true,"img":false}]}
{"op":"mcm","clk":"11541056420","pt":1719501650687,"mc":[{"id":"1.230180125","rc":[{"atb":[[1.31,5]],"id":65992794}],"con":true,"img":false}]}
{"op":"mcm","clk":"11541056490","pt":1719501650947,"mc":[{"id":"1.230180125","rc":[{"atb":[[1.31,0]],"id":65992794}],"con":true,"img":false}]}
{"op":"mcm","clk":"11541056573","pt":1719501651826,"mc":[{"id":"1.230180125","rc":[{"atb":[[2.32,0]],"id":67245400},{"atb":[[2.1,0]],"id":51567147}],"con":true,"img":false}]}
{"op":"mcm","clk":"11541056591","pt":1719501652037,"mc":[{"id":"1.230180125","rc":[{"atb":[[2.32,1.94]],"id":67245400},{"atb":[[2.1,1.94]],"id":51567147}],"con":true,"img":false}]}
{"op":"mcm","clk":"11541056820","pt":1719501654961,"mc":[{"id":"1.230180125","rc":[{"atb":[[2.32,0]],"id":67245400},{"atb":[[2.1,0]],"id":51567147}],"con":true,"img":false}]}
{"op":"mcm","clk":"11541056837","pt":1719501655149,"mc":[{"id":"1.230180125","rc":[{"atb":[[2.32,1.94]],"id":67245400},{"atb":[[2.1,1.94]],"id":51567147}],"con":true,"img":false}]}
{"op":"mcm","clk":"11541056900","pt":1719501655932,"mc":[{"id":"1.230180125","rc":[{"atb":[[2,0]],"id":67245400}],"con":true,"img":false}]}
{"op":"mcm","clk":"11541057073","pt":1719501658058,"mc":[{"id":"1.230180125","rc":[{"atb":[[2.32,0]],"id":67245400},{"atb":[[2.1,0]],"id":51567147}],"con":true,"img":false}]}
{"op":"mcm","clk":"11541057080","pt":1719501658161,"mc":[{"id":"1.230180125","rc":[{"atb":[[2.32,1.94]],"id":67245400},{"atb":[[2.1,1.94]],"id":51567147}],"con":true,"img":false}]}
{"op":"mcm","clk":"11541057106","pt":1719501658422,"mc":[{"id":"1.230180125","rc":[{"atb":[[2.12,5.29]],"id":51567147}],"con":true,"img":false}]}
{"op":"mcm","clk":"11541057266","pt":1719501660551,"mc":[{"id":"1.230180125","rc":[{"atb":[[2.06,5.21]],"id":51567147}],"con":true,"img":false}]}
{"op":"mcm","clk":"11541057311","pt":1719501661075,"mc":[{"id":"1.230180125","rc":[{"atb":[[2.32,0]],"id":67245400},{"atb":[[2.1,0]],"id":51567147}],"con":true,"img":false}]}
{"op":"mcm","clk":"11541057319","pt":1719501661129,"mc":[{"id":"1.230180125","rc":[{"atb":[[2.32,1.94]],"id":67245400},{"atb":[[2.14,1.94]],"id":51567147}],"con":true,"img":false}]}
{"op":"mcm","clk":"11541057382","pt":1719501661963,"mc":[{"id":"1.230180125","rc":[{"atl":[[2.64,1],[2.7,0]],"id":65992794},{"atb":[[1.97,0],[1.86,1]],"id":42767337}],"con":true,"img":false}]}
{"op":"mcm","clk":"11541057394","pt":1719501662060,"mc":[{"id":"1.230180125","rc":[{"atb":[[2,0]],"id":70902709}],"con":true,"img":false}]}
{"op":"mcm","clk":"11541057411","pt":1719501662270,"mc":[{"id":"1.230180125","rc":[{"atb":[[1.96,3.75]],"id":42767337}],"con":true,"img":false}]}
{"op":"mcm","clk":"11541057431","pt":1719501662433,"mc":[{"id":"1.230180125","rc":[{"atl":[[2.56,1],[2.64,0]],"id":65992794}],"con":true,"img":false}]}
{"op":"mcm","clk":"11541057444","pt":1719501662543,"mc":[{"id":"1.230180125","rc":[{"atl":[[4,0],[2.7,2]],"id":65992794},{"atb":[[1.96,0]],"id":42767337}],"con":true,"img":false}]}
{"op":"mcm","clk":"11541057498","pt":1719501663062,"mc":[{"id":"1.230180125","rc":[{"atb":[[2.06,9.95]],"id":51567147}],"con":true,"img":false}]}
{"op":"mcm","clk":"11541057506","pt":1719501663161,"mc":[{"id":"1.230180125","rc":[{"atb":[[2.06,0]],"id":70902709}],"con":true,"img":false}]}
{"op":"mcm","clk":"11541057515","pt":1719501663264,"mc":[{"id":"1.230180125","rc":[{"atb":[[1.02,2]],"id":70902709}],"con":true,"img":false}]}
{"op":"mcm","clk":"11541057561","pt":1719501663639,"mc":[{"id":"1.230180125","rc":[{"atb":[[1.97,3.75]],"id":42767337}],"con":true,"img":false}]}
{"op":"mcm","clk":"11541057594","pt":1719501663949,"mc":[{"id":"1.230180125","rc":[{"atb":[[2.32,0]],"id":67245400},{"atb":[[2.14,0]],"id":51567147}],"con":true,"img":false}]}
{"op":"mcm","clk":"11541057607","pt":1719501664050,"mc":[{"id":"1.230180125","rc":[{"atb":[[1.97,0]],"id":42767337},{"atb":[[2.06,5.21]],"id":51567147}],"con":true,"img":false}]}
{"op":"mcm","clk":"11541057618","pt":1719501664156,"mc":[{"id":"1.230180125","rc":[{"atb":[[2.32,1.94]],"id":67245400},{"atb":[[2.14,1.94]],"id":51567147}],"con":true,"img":false}]}
{"op":"mcm","clk":"11541057635","pt":1719501664362,"mc":[{"id":"1.230180125","rc":[{"atb":[[1.54,3.75]],"id":70902709}],"con":true,"img":false}]}
{"op":"mcm","clk":"11541057643","pt":1719501664463,"mc":[{"id":"1.230180125","rc":[{"atb":[[1.02,0]],"id":70902709}],"con":true,"img":false}]}
{"op":"mcm","clk":"11541057652","pt":1719501664570,"mc":[{"id":"1.230180125","rc":[{"atb":[[2.06,2]],"id":70902709}],"con":true,"img":false}]}
{"op":"mcm","clk":"11541057700","pt":1719501665138,"mc":[{"id":"1.230180125","rc":[{"atb":[[1.54,0]],"id":70902709}],"con":true,"img":false}]}
{"op":"mcm","clk":"11541057726","pt":1719501665455,"mc":[{"id":"1.230180125","rc":[{"atb":[[2.06,0]],"id":70902709}],"con":true,"img":false}]}
{"op":"mcm","clk":"11541057737","pt":1719501665556,"mc":[{"id":"1.230180125","rc":[{"atb":[[1.02,2]],"id":70902709}],"con":true,"img":false}]}
{"op":"mcm","clk":"11541057753","pt":1719501665765,"mc":[{"id":"1.230180125","rc":[{"atb":[[2.1,5.02]],"id":70902709}],"con":true,"img":false}]}
{"op":"mcm","clk":"11541057762","pt":1719501665862,"mc":[{"id":"1.230180125","rc":[{"atb":[[2.12,5.03]],"id":70902709}],"con":true,"img":false}]}
{"op":"mcm","clk":"11541057773","pt":1719501665966,"mc":[{"id":"1.230180125","rc":[{"atb":[[2.04,1.94]],"id":70902709}],"con":true,"img":false}]}
{"op":"mcm","clk":"11541057835","pt":1719501666644,"mc":[{"id":"1.230180125","rc":[{"atl":[[4,3],[2.7,0]],"id":65992794}],"con":true,"img":false}]}
{"op":"mcm","clk":"11541057862","pt":1719501667064,"mc":[{"id":"1.230180125","rc":[{"atb":[[2.32,0]],"id":67245400},{"atb":[[2.14,0]],"id":51567147},{"atb":[[2.04,0]],"id":70902709}],"con":true,"img":false}]}
{"op":"mcm","clk":"11541057882","pt":1719501667266,"mc":[{"id":"1.230180125","rc":[{"atb":[[2.32,1.94]],"id":67245400},{"atb":[[2.14,1.94]],"id":51567147},{"atb":[[2.14,1.94]],"id":70902709}],"con":true,"img":false}]}
{"op":"mcm","clk":"11541057944","pt":1719501668071,"mc":[{"id":"1.230180125","rc":[{"atb":[[1.85,2.5]],"id":42767337}],"con":true,"img":false}]}
{"op":"mcm","clk":"11541057982","pt":1719501668380,"mc":[{"id":"1.230180125","rc":[{"atb":[[1.01,121.59]],"id":65992794},{"atl":[[1000,1.7]],"id":65992794},{"atb":[[1.02,10.62]],"id":67245400},{"atl":[[1000,1.88]],"id":67245400},{"atb":[[1.01,121.59]],"id":42767337},{"atl":[[1000,1.88]],"id":42767337}],"con":true,"img":false}]}
{"op":"mcm","clk":"11541058004","pt":1719501668538,"mc":[{"id":"1.230180125","rc":[{"atb":[[1.01,120.61]],"id":65992794},{"atl":[[1000,0.08]],"id":65992794},{"atb":[[1.02,9.11]],"id":67245400},{"atl":[[1000,0.18]],"id":67245400},{"atb":[[1.01,120.15]],"id":42767337},{"atl":[[1000,0.18]],"id":42767337}],"con":true,"img":false}]}
{"op":"mcm","clk":"11541058024","pt":1719501668741,"mc":[{"id":"1.230180125","rc":[{"atb":[[1.01,119.88]],"id":65992794},{"atl":[[1000,0]],"id":65992794},{"atb":[[1.02,8.92]],"id":67245400},{"atl":[[1000,0.17]],"id":67245400},{"atb":[[1.01,119.88]],"id":42767337},{"atl":[[1000,0.17]],"id":42767337}],"con":true,"img":false}]}
{"op":"mcm","clk":"11541058032","pt":1719501668851,"mc":[{"id":"1.230180125","rc":[{"atb":[[1.36,0.72]],"id":65992794},{"atl":[[3.95,0.08]],"id":65992794},{"atb":[[2.34,0.19]],"id":67245400},{"atl":[[28,0.01]],"id":67245400},{"atb":[[1.99,0.26]],"id":42767337},{"atl":[[36,0]],"id":42767337}],"con":true,"img":false}]}
{"op":"mcm","clk":"11541058057","pt":1719501669158,"mc":[{"id":"1.230180125","rc":[{"atb":[[1.85,0]],"id":42767337}],"con":true,"img":false}]}
{"op":"mcm","clk":"11541058068","pt":1719501669262,"mc":[{"id":"1.230180125","rc":[{"atb":[[2.3,9]],"id":67245400}],"con":true,"img":false}]}
{"op":"mcm","clk":"11541058074","pt":1719501669367,"mc":[{"id":"1.230180125","rc":[{"atb":[[2.34,2.19]],"id":67245400}],"con":true,"img":false}]}
{"op":"mcm","clk":"11541058094","pt":1719501669579,"mc":[{"id":"1.230180125","rc":[{"atb":[[2.3,0],[2.34,4.39]],"id":67245400}],"con":true,"img":false}]}
{"op":"mcm","clk":"11541058131","pt":1719501670045,"mc":[{"id":"1.230180125","rc":[{"atb":[[2.32,0]],"id":67245400},{"atb":[[2.14,0]],"id":51567147},{"atb":[[2.14,0]],"id":70902709}],"con":true,"img":false}]}
{"op":"mcm","clk":"11541058143","pt":1719501670155,"mc":[{"id":"1.230180125","rc":[{"atb":[[2.36,1.94]],"id":67245400},{"atb":[[2.14,1.94]],"id":51567147},{"atb":[[2.14,1.94]],"id":70902709}],"con":true,"img":false}]}
{"op":"mcm","clk":"11541058394","pt":1719501673065,"mc":[{"id":"1.230180125","rc":[{"atb":[[2.36,0]],"id":67245400},{"atb":[[2.14,0]],"id":51567147},{"atb":[[2.14,0]],"id":70902709}],"con":true,"img":false}]}
{"op":"mcm","clk":"11541058412","pt":1719501673277,"mc":[{"id":"1.230180125","rc":[{"atb":[[2.36,1.94]],"id":67245400},{"atb":[[2.14,1.94]],"id":51567147},{"atb":[[2.14,1.94]],"id":70902709}],"con":true,"img":false}]}
{"op":"mcm","clk":"11541058557","pt":1719501674841,"mc":[{"id":"1.230180125","rc":[{"spn":1.53,"spf":1.0,"id":65992794},{"spn":4.18,"spf":"NaN","id":67245400},{"spn":4.29,"spf":"NaN","id":42767337},{"spn":3.02,"spf":"NaN","id":51567147},{"atb":[[2.14,1.65]],"id":70902709},{"trd":[[2.14,0.57]],"ltp":2.14,"tv":0.57,"id":70902709},{"spn":3.72,"spf":"NaN","id":70902709}],"con":true,"img":false}]}
{"op":"mcm","clk":"11541058573","pt":1719501675046,"mc":[{"id":"1.230180125","rc":[{"atl":[[5.2,1]],"id":70902709}],"con":true,"img":false}]}
{"op":"mcm","clk":"11541058659","pt":1719501675981,"mc":[{"id":"1.230180125","rc":[{"spl":[[1.01,10]],"id":51567147}],"con":true,"img":false}]}
{"op":"mcm","clk":"11541058670","pt":1719501676042,"mc":[{"id":"1.230180125","rc":[{"atb":[[2.36,0]],"id":67245400},{"atb":[[2.14,0]],"id":51567147},{"atb":[[2.14,0]],"id":70902709}],"con":true,"img":false}]}
{"op":"mcm","clk":"11541058690","pt":1719501676245,"mc":[{"id":"1.230180125","rc":[{"atb":[[2.36,1.94]],"id":67245400},{"atb":[[2.14,1.94]],"id":51567147},{"atb":[[2.14,1.94]],"id":70902709}],"con":true,"img":false}]}
{"op":"mcm","clk":"11541058832","pt":1719501678058,"mc":[{"id":"1.230180125","rc":[{"atb":[[2.12,9.88]],"id":70902709}],"con":true,"img":false}]}
{"op":"mcm","clk":"11541058847","pt":1719501678265,"mc":[{"id":"1.230180125","rc":[{"atl":[[2.56,0],[2.52,1]],"id":65992794}],"con":true,"img":false}]}
{"op":"mcm","clk":"11541058895","pt":1719501678842,"mc":[{"id":"1.230180125","rc":[{"atb":[[2.1,4.57]],"id":51567147}],"con":true,"img":false}]}
{"op":"mcm","clk":"11541058911","pt":1719501679049,"mc":[{"id":"1.230180125","rc":[{"atb":[[1.34,18.43]],"id":65992794}],"con":true,"img":false}]}
{"op":"mcm","clk":"11541058918","pt":1719501679159,"mc":[{"id":"1.230180125","rc":[{"atb":[[2.36,0]],"id":67245400},{"atb":[[2.14,0]],"id":51567147},{"atb":[[2.14,0]],"id":70902709}],"con":true,"img":false}]}
{"op":"mcm","clk":"11541058940","pt":1719501679358,"mc":[{"id":"1.230180125","rc":[{"atb":[[2.36,1.94]],"id":67245400},{"atb":[[2.14,1.94]],"id":51567147},{"atb":[[2.14,1.94]],"id":70902709}],"con":true,"img":false}]}
{"op":"mcm","clk":"11541058961","pt":1719501679574,"mc":[{"id":"1.230180125","rc":[{"atb":[[1.98,4.87]],"id":42767337}],"con":true,"img":false}]}
{"op":"mcm","clk":"11541058972","pt":1719501679676,"mc":[{"id":"1.230180125","rc":[{"atb":[[1.34,16.27]],"id":65992794}],"con":true,"img":false}]}
{"op":"mcm","clk":"11541059028","pt":1719501680357,"mc":[{"id":"1.230180125","rc":[{"atb":[[2.1,3.91]],"id":51567147}],"con":true,"img":false}]}
{"op":"mcm","clk":"11541059099","pt":1719501681087,"mc":[{"id":"1.230180125","rc":[{"atb":[[1.02,0]],"id":42767337}],"con":true,"img":false}]}
{"op":"mcm","clk":"11541059110","pt":1719501681147,"mc":[{"id":"1.230180125","rc":[{"atb":[[1.99,2.26]],"id":42767337}],"con":true,"img":false}]}
{"op":"mcm","clk":"11541059203","pt":1719501682281,"mc":[{"id":"1.230180125","rc":[{"atb":[[2.36,0]],"id":67245400},{"atb":[[2.14,0]],"id":51567147},{"atb":[[2.14,0]],"id":70902709}],"con":true,"img":false}]}
{"op":"mcm","clk":"11541059210","pt":1719501682391,"mc":[{"id":"1.230180125","rc":[{"atb":[[2.36,1.94]],"id":67245400},{"atb":[[2.14,1.94]],"id":51567147},{"atb":[[2.14,1.94]],"id":70902709}],"con":true,"img":false}]}
{"op":"mcm","clk":"11541059220","pt":1719501682497,"mc":[{"id":"1.230180125","rc":[{"atb":[[1.99,0.26]],"id":42767337}],"con":true,"img":false}]}
{"op":"mcm","clk":"11541059228","pt":1719501682552,"mc":[{"id":"1.230180125","rc":[{"atb":[[1.02,2]],"id":42767337}],"con":true,"img":false}]}
{"op":"mcm","clk":"11541059240","pt":1719501682653,"mc":[{"id":"1.230180125","rc":[{"atb":[[2.12,5.03]],"id":70902709}],"con":true,"img":false}]}
{"op":"mcm","clk":"11541059339","pt":1719501683850,"mc":[{"id":"1.230180125","rc":[{"atl":[[2.56,1]],"id":65992794}],"con":true,"img":false}]}
{"op":"mcm","clk":"11541059351","pt":1719501683954,"mc":[{"id":"1.230180125","rc":[{"atl":[[2.52,0]],"id":65992794},{"atb":[[2.1,0]],"id":70902709}],"con":true,"img":false}]}
{"op":"mcm","clk":"11541059406","pt":1719501684576,"mc":[{"id":"1.230180125","rc":[{"atb":[[1.02,0]],"id":42767337}],"con":true,"img":false}]}
{"op":"mcm","clk":"11541059415","pt":1719501684678,"mc":[{"id":"1.230180125","rc":[{"atl":[[4.4,3.12]],"id":65992794},{"atb":[[1.99,2.26]],"id":42767337}],"con":true,"img":false}]}
{"op":"mcm","clk":"11541059442","pt":1719501684986,"mc":[{"id":"1.230180125","rc":[{"atl":[[2.7,3.18]],"id":65992794},{"atb":[[1.02,0]],"id":70902709}],"con":true,"img":false}]}
{"op":"mcm","clk":"11541059449","pt":1719501685089,"mc":[{"id":"1.230180125","rc":[{"atl":[[4,0],[2.68,3]],"id":65992794},{"atb":[[2.14,3.94]],"id":70902709}],"con":true,"img":false}]}
{"op":"mcm","clk":"11541059456","pt":1719501685146,"mc":[{"id":"1.230180125","rc":[{"atb":[[2.12,0],[2.16,3.95]],"id":70902709}],"con":true,"img":false}]}
{"op":"mcm","clk":"11541059465","pt":1719501685250,"mc":[{"id":"1.230180125","rc":[{"atl":[[4.4,0]],"id":65992794}],"con":true,"img":false}]}
{"op":"mcm","clk":"11541059474","pt":1719501685360,"mc":[{"id":"1.230180125","rc":[{"atb":[[2.36,0]],"id":67245400},{"atb":[[2.14,0]],"id":51567147}],"con":true,"img":false}]}
{"op":"mcm","clk":"11541059492","pt":1719501685562,"mc":[{"id":"1.230180125","rc":[{"atb":[[2.36,1.94]],"id":67245400},{"atb":[[2.14,1.94]],"id":51567147}],"con":true,"img":false}]}
{"op":"mcm","clk":"11541059578","pt":1719501686603,"mc":[{"id":"1.230180125","rc":[{"atl":[[2.66,2.54]],"id":65992794}],"con":true,"img":false}]}
{"op":"mcm","clk":"11541059589","pt":1719501686705,"mc":[{"id":"1.230180125","rc":[{"atb":[[1.99,0.26]],"id":42767337}],"con":true,"img":false}]}
{"op":"mcm","clk":"11541059599","pt":1719501686767,"mc":[{"id":"1.230180125","rc":[{"atb":[[1.02,2]],"id":42767337}],"con":true,"img":false}]}
{"op":"mcm","clk":"11541059619","pt":1719501687066,"mc":[{"id":"1.230180125","rc":[{"atb":[[2.14,1.94]],"id":70902709}],"con":true,"img":false}]}
{"op":"mcm","clk":"11541059626","pt":1719501687169,"mc":[{"id":"1.230180125","rc":[{"atb":[[1.02,2]],"id":70902709}],"con":true,"img":false}]}
{"op":"mcm","clk":"11541059720","pt":1719501688470,"mc":[{"id":"1.230180125","rc":[{"atb":[[2.36,0]],"id":67245400},{"atb":[[1.02,0]],"id":42767337},{"atb":[[2.14,0]],"id":51567147},{"atb":[[2.14,0]],"id":70902709}],"con":true,"img":false}]}
{"op":"mcm","clk":"11541059729","pt":1719501688577,"mc":[{"id":"1.230180125","rc":[{"atb":[[1.99,2.26]],"id":42767337}],"con":true,"img":false}]}
{"op":"mcm","clk":"11541059737","pt":1719501688679,"mc":[{"id":"1.230180125","rc":[{"atb":[[2.36,1.94]],"id":67245400},{"atb":[[2.14,1.94]],"id":51567147},{"atb":[[2.18,1.94]],"id":70902709}],"con":true,"img":false}]}
{"op":"mcm","clk":"11541059775","pt":1719501689295,"mc":[{"id":"1.230180125","rc":[{"atl":[[2.7,0]],"id":65992794}],"con":true,"img":false}]}
{"op":"mcm","clk":"11541059789","pt":1719501689507,"mc":[{"id":"1.230180125","rc":[{"atl":[[2.56,0],[2.52,1]],"id":65992794}],"con":true,"img":false}]}
{"op":"mcm","clk":"11541059821","pt":1719501689872,"mc":[{"id":"1.230180125","rc":[{"atb":[[1.02,10.62]],"id":67245400}],"con":true,"img":false}]}
{"op":"mcm","clk":"11541059832","pt":1719501690085,"mc":[{"id":"1.230180125","rc":[{"atb":[[1.02,9.05]],"id":67245400}],"con":true,"img":false}]}
{"op":"mcm","clk":"11541059845","pt":1719501690293,"mc":[{"id":"1.230180125","rc":[{"atb":[[1.02,8.92]],"id":67245400}],"con":true,"img":false}]}
{"op":"mcm","clk":"11541059852","pt":1719501690395,"mc":[{"id":"1.230180125","rc":[{"atb":[[2.38,0.13]],"id":67245400}],"con":true,"img":false}]}
{"op":"mcm","clk":"11541059960","pt":1719501691699,"mc":[{"id":"1.230180125","rc":[{"atb":[[2.14,0]],"id":51567147},{"atb":[[2.18,0]],"id":70902709}],"con":true,"img":false}]}
{"op":"mcm","clk":"11541059966","pt":1719501691798,"mc":[{"id":"1.230180125","rc":[{"atb":[[1.99,0.26]],"id":42767337},{"atb":[[2.16,0]],"id":70902709}],"con":true,"img":false}]}
{"op":"mcm","clk":"11541059975","pt":1719501691904,"mc":[{"id":"1.230180125","rc":[{"atb":[[2.14,1.94]],"id":51567147},{"atb":[[1.56,1],[1.55,0],[2.18,1.94],[1.65,1],[1.76,7.9]],"id":70902709}],"con":true,"img":false}]}
{"op":"mcm","clk":"11541059982","pt":1719501691963,"mc":[{"id":"1.230180125","rc":[{"atb":[[1.02,2]],"id":42767337}],"con":true,"img":false}]}
{"op":"mcm","clk":"11541059991","pt":1719501692065,"mc":[{"id":"1.230180125","rc":[{"atb":[[2.18,3.94],[1.76,0]],"id":70902709}],"con":true,"img":false}]}
{"op":"mcm","clk":"11541059998","pt":1719501692177,"mc":[{"id":"1.230180125","rc":[{"atb":[[2.34,2.39]],"id":67245400}],"con":true,"img":false}]}
{"op":"mcm","clk":"11541060008","pt":1719501692277,"mc":[{"id":"1.230180125","rc":[{"atb":[[2.38,2.13]],"id":67245400}],"con":true,"img":false}]}
{"op":"mcm","clk":"11541060014","pt":1719501692385,"mc":[{"id":"1.230180125","rc":[{"atb":[[2.38,4.26],[2.34,0.19]],"id":67245400}],"con":true,"img":false}]}
{"op":"mcm","clk":"11541060022","pt":1719501692485,"mc":[{"id":"1.230180125","rc":[{"atb":[[2.36,6.2],[2.38,2.13]],"id":67245400},{"atb":[[1.02,0]],"id":70902709}],"con":true,"img":false}]}
{"op":"mcm","clk":"11541060030","pt":1719501692586,"mc":[{"id":"1.230180125","rc":[{"atb":[[1.56,0],[2.18,5.94]],"id":70902709}],"con":true,"img":false}]}
{"op":"mcm","clk":"11541060070","pt":1719501693215,"mc":[{"id":"1.230180125","rc":[{"atb":[[2.1,4.57]],"id":51567147},{"atb":[[2.14,3.75]],"id":70902709}],"con":true,"img":false}]}
{"op":"mcm","clk":"11541060119","pt":1719501694001,"mc":[{"id":"1.230180125","rc":[{"atb":[[1.02,0]],"id":42767337}],"con":true,"img":false}]}
{"op":"mcm","clk":"11541060127","pt":1719501694097,"mc":[{"id":"1.230180125","rc":[{"atb":[[1.34,21.64]],"id":65992794},{"atb":[[1.99,2.26]],"id":42767337}],"con":true,"img":false}]}
{"op":"mcm","clk":"11541060131","pt":1719501694205,"mc":[{"id":"1.230180125","rc":[{"atb":[[1.98,6.12]],"id":42767337}],"con":true,"img":false}]}
{"op":"mcm","clk":"11541060134","pt":1719501694307,"mc":[{"id":"1.230180125","rc":[{"atb":[[2.14,0]],"id":70902709}],"con":true,"img":false}]}
{"op":"mcm","clk":"11541060142","pt":1719501694366,"mc":[{"id":"1.230180125","rc":[{"atb":[[2.18,3.94]],"id":70902709}],"con":true,"img":false}]}
{"op":"mcm","clk":"11541060148","pt":1719501694467,"mc":[{"id":"1.230180125","rc":[{"atb":[[1.02,2]],"id":70902709}],"con":true,"img":false}]}
{"op":"mcm","clk":"11541060161","pt":1719501694692,"mc":[{"id":"1.230180125","rc":[{"atb":[[2.36,4.26]],"id":67245400},{"atb":[[2.14,0]],"id":51567147}],"con":true,"img":false}]}
{"op":"mcm","clk":"11541060165","pt":1719501694796,"mc":[{"id":"1.230180125","rc":[{"atb":[[2.4,1.94]],"id":67245400},{"atb":[[2.14,1.94]],"id":51567147}],"con":true,"img":false}]}
{"op":"mcm","clk":"11541060173","pt":1719501694899,"mc":[{"id":"1.230180125","rc":[{"atb":[[2.4,4.07],[2.36,0]],"id":67245400}],"con":true,"img":false}]}
{"op":"mcm","clk":"11541060185","pt":1719501695109,"mc":[{"id":"1.230180125","rc":[{"atl":[[2.56,1],[2.52,0]],"id":65992794}],"con":true,"img":false}]}
{"op":"mcm","clk":"11541060194","pt":1719501695213,"mc":[{"id":"1.230180125","rc":[{"atl":[[2.64,2.54],[2.68,0]],"id":65992794}],"con":true,"img":false}]}
{"op":"mcm","clk":"11541060240","pt":1719501695789,"mc":[{"id":"1.230180125","rc":[{"atb":[[2.1,3.91]],"id":51567147}],"con":true,"img":false}]}
{"op":"mcm","clk":"11541060260","pt":1719501696105,"mc":[{"id":"1.230180125","rc":[{"atb":[[1.99,0.26]],"id":42767337}],"con":true,"img":false}]}
{"op":"mcm","clk":"11541060265","pt":1719501696209,"mc":[{"id":"1.230180125","rc":[{"atb":[[1.02,2]],"id":42767337}],"con":true,"img":false}]}
{"op":"mcm","clk":"11541060291","pt":1719501696470,"mc":[{"id":"1.230180125","rc":[{"atb":[[2.38,0.13]],"id":67245400}],"con":true,"img":false}]}
{"op":"mcm","clk":"11541060301","pt":1719501696578,"mc":[{"id":"1.230180125","rc":[{"atb":[[2.42,2]],"id":67245400}],"con":true,"img":false}]}
{"op":"mcm","clk":"11541060368","pt":1719501697402,"mc":[{"id":"1.230180125","rc":[{"atl":[[2.66,0]],"id":65992794}],"con":true,"img":false}]}
{"op":"mcm","clk":"11541060381","pt":1719501697612,"mc":[{"id":"1.230180125","rc":[{"atl":[[3.95,3.62],[2.64,0]],"id":65992794}],"con":true,"img":false}]}
{"op":"mcm","clk":"11541060390","pt":1719501697720,"mc":[{"id":"1.230180125","rc":[{"atb":[[2.14,0]],"id":51567147}],"con":true,"img":false}]}
{"op":"mcm","clk":"11541060403","pt":1719501697877,"mc":[{"id":"1.230180125","rc":[{"atb":[[2.14,1.94]],"id":51567147}],"con":true,"img":false}]}
{"op":"mcm","clk":"11541060443","pt":1719501698391,"mc":[{"id":"1.230180125","rc":[{"atb":[[1.02,0]],"id":42767337}],"con":true,"img":false}]}
{"op":"mcm","clk":"11541060450","pt":1719501698496,"mc":[{"id":"1.230180125","rc":[{"atb":[[1.99,2.26]],"id":42767337}],"con":true,"img":false}]}
{"op":"mcm","clk":"11541060532","pt":1719501699380,"mc":[{"id":"1.230180125","rc":[{"atb":[[1.99,0.26]],"id":42767337}],"con":true,"img":false}]}
{"op":"mcm","clk":"11541060537","pt":1719501699481,"mc":[{"id":"1.230180125","rc":[{"atb":[[1.02,2]],"id":42767337}],"con":true,"img":false}]}
{"op":"mcm","clk":"11541060559","pt":1719501699793,"mc":[{"id":"1.230180125","rc":[{"atl":[[2.66,3.25]],"id":65992794}],"con":true,"img":false}]}
{"op":"mcm","clk":"11541060578","pt":1719501699998,"mc":[{"id":"1.230180125","rc":[{"atl":[[3.9,0]],"id":51567147}],"con":true,"img":false}]}
{"op":"mcm","clk":"11541060608","pt":1719501700307,"mc":[{"id":"1.230180125","rc":[{"atb":[[1.02,0]],"id":42767337}],"con":true,"img":false}]}
{"op":"mcm","clk":"11541060619","pt":1719501700411,"mc":[{"id":"1.230180125","rc":[{"atb":[[1.99,2.26]],"id":42767337}],"con":true,"img":false}]}
{"op":"mcm","clk":"11541060628","pt":1719501700516,"mc":[{"id":"1.230180125","rc":[{"atl":[[2.56,0],[2.52,1]],"id":65992794},{"atb":[[2.1,0]],"id":67245400},{"atb":[[2.06,0]],"id":51567147}],"con":true,"img":false}]}
{"op":"mcm","clk":"11541060644","pt":1719501700722,"mc":[{"id":"1.230180125","rc":[{"atb":[[1.36,0]],"id":65992794},{"atl":[[3.95,3.54]],"id":65992794},{"atb":[[2.38,0],[2.34,0]],"id":67245400},{"atl":[[28,0]],"id":67245400},{"atb":[[1.99,2]],"id":42767337},{"atl":[[36,0]],"id":42767337}],"con":true,"img":false}]}
{"op":"mcm","clk":"11541060655","pt":1719501700780,"mc":[{"id":"1.230180125","rc":[{"atb":[[2.14,0]],"id":51567147}],"con":true,"img":false}]}
{"op":"mcm","clk":"11541060667","pt":1719501700984,"mc":[{"id":"1.230180125","rc":[{"atb":[[2.14,1.94]],"id":51567147}],"con":true,"img":false}]}
{"op":"mcm","clk":"11541060686","pt":1719501701303,"mc":[{"id":"1.230180125","rc":[{"atl":[[4.4,3]],"id":65992794}],"con":true,"img":false}]}
{"op":"mcm","clk":"11541060724","pt":1719501701813,"mc":[{"id":"1.230180125","rc":[{"atb":[[1.99,0]],"id":42767337}],"con":true,"img":false}]}
{"op":"mcm","clk":"11541060732","pt":1719501701919,"mc":[{"id":"1.230180125","rc":[{"atb":[[1.02,2]],"id":42767337}],"con":true,"img":false}]}
{"op":"mcm","clk":"11541060770","pt":1719501702288,"mc":[{"id":"1.230180125","rc":[{"atb":[[2.2,0]],"id":67245400}],"con":true,"img":false}]}
{"op":"mcm","clk":"11541060784","pt":1719501702494,"mc":[{"id":"1.230180125","rc":[{"atb":[[1.02,0]],"id":42767337}],"con":true,"img":false}]}
{"op":"mcm","clk":"11541060791","pt":1719501702597,"mc":[{"id":"1.230180125","rc":[{"atb":[[1.99,2]],"id":42767337}],"con":true,"img":false}]}
{"op":"mcm","clk":"11541060811","pt":1719501703008,"mc":[{"id":"1.230180125","rc":[{"atb":[[1.98,2.37]],"id":42767337}],"con":true,"img":false}]}
{"op":"mcm","clk":"11541060831","pt":1719501703319,"mc":[{"id":"1.230180125","rc":[{"atb":[[1.99,0]],"id":42767337}],"con":true,"img":false}]}
{"op":"mcm","clk":"11541060839","pt":1719501703373,"mc":[{"id":"1.230180125","rc":[{"atb":[[2.38,3.75]],"id":67245400},{"atb":[[1.02,2]],"id":42767337}],"con":true,"img":false}]}
{"op":"mcm","clk":"11541060859","pt":1719501703686,"mc":[{"id":"1.230180125","rc":[{"atb":[[2.42,0]],"id":67245400}],"con":true,"img":false}]}
{"op":"mcm","clk":"11541060864","pt":1719501703796,"mc":[{"id":"1.230180125","rc":[{"atb":[[2.38,0],[1.02,10.92]],"id":67245400},{"atb":[[2.14,0]],"id":51567147}],"con":true,"img":false}]}
{"op":"mcm","clk":"11541060873","pt":1719501703895,"mc":[{"id":"1.230180125","rc":[{"atb":[[2.14,1.94]],"id":51567147}],"con":true,"img":false}]}
{"op":"mcm","clk":"11541060986","pt":1719501705299,"mc":[{"id":"1.230180125","rc":[{"atb":[[1.73,3.75]],"id":67245400}],"con":true,"img":false}]}
{"op":"mcm","clk":"11541061061","pt":1719501706231,"mc":[{"id":"1.230180125","rc":[{"atb":[[1.07,3.75]],"id":42767337},{"atb":[[2.14,0]],"id":51567147}],"con":true,"img":false}]}
{"op":"mcm","clk":"11541061081","pt":1719501706391,"mc":[{"id":"1.230180125","rc":[{"atb":[[1.73,0]],"id":67245400},{"atb":[[2.14,1.94]],"id":51567147}],"con":true,"img":false}]}
{"op":"mcm","clk":"11541061167","pt":1719501707595,"mc":[{"id":"1.230180125","rc":[{"atb":[[1.07,0]],"id":42767337},{"atb":[[2.16,3.75]],"id":70902709}],"con":true,"img":false}]}
{"op":"mcm","clk":"11541061206","pt":1719501708099,"mc":[{"id":"1.230180125","rc":[{"atb":[[2.1,4.57]],"id":51567147}],"con":true,"img":false}]}
{"op":"mcm","clk":"11541061257","pt":1719501708825,"mc":[{"id":"1.230180125","rc":[{"atb":[[2.14,0]],"id":51567147}],"con":true,"img":false}]}
{"op":"mcm","clk":"11541061270","pt":1719501709027,"mc":[{"id":"1.230180125","rc":[{"atb":[[2.14,1.94]],"id":51567147}],"con":true,"img":false}]}
{"op":"mcm","clk":"11541061337","pt":1719501709914,"mc":[{"id":"1.230180125","rc":[{"atl":[[2.56,1],[2.52,0]],"id":65992794},{"atb":[[2.1,3.91]],"id":51567147}],"con":true,"img":false}]}
{"op":"mcm","clk":"11541061343","pt":1719501710018,"mc":[{"id":"1.230180125","rc":[{"atl":[[3.95,0],[2.66,6.5]],"id":65992794}],"con":true,"img":false}]}
{"op":"mcm","clk":"11541061349","pt":1719501710126,"mc":[{"id":"1.230180125","rc":[{"atl":[[3.95,4.25],[2.66,3.25]],"id":65992794}],"con":true,"img":false}]}
{"op":"mcm","clk":"11541061368","pt":1719501710430,"mc":[{"id":"1.230180125","rc":[{"atl":[[4.4,0]],"id":65992794}],"con":true,"img":false}]}
{"op":"mcm","clk":"11541061430","pt":1719501711318,"mc":[{"id":"1.230180125","rc":[{"atb":[[2.14,0]],"id":51567147}],"con":true,"img":false}]}
{"op":"mcm","clk":"11541061445","pt":1719501711526,"mc":[{"id":"1.230180125","rc":[{"atb":[[2.14,1.94]],"id":51567147}],"con":true,"img":false}]}
{"op":"mcm","clk":"11541061635","pt":1719501713815,"mc":[{"id":"1.230180125","rc":[{"atb":[[2.14,0]],"id":51567147}],"con":true,"img":false}]}
{"op":"mcm","clk":"11541061653","pt":1719501714010,"mc":[{"id":"1.230180125","rc":[{"atb":[[2.14,1.94]],"id":51567147}],"con":true,"img":false}]}
{"op":"mcm","clk":"11541061851","pt":1719501716025,"mc":[{"id":"1.230180125","rc":[{"atl":[[4,0]],"id":51567147}],"con":true,"img":false}]}
{"op":"mcm","clk":"11541061879","pt":1719501716335,"mc":[{"id":"1.230180125","rc":[{"atb":[[2.14,0]],"id":51567147},{"atl":[[4,1.99]],"id":51567147}],"con":true,"img":false}]}
{"op":"mcm","clk":"11541061897","pt":1719501716494,"mc":[{"id":"1.230180125","rc":[{"atb":[[2.14,1.94]],"id":51567147}],"con":true,"img":false}]}
{"op":"mcm","clk":"11541061955","pt":1719501717112,"mc":[{"id":"1.230180125","rc":[{"atb":[[1.97,3.75]],"id":42767337}],"con":true,"img":false}]}
{"op":"mcm","clk":"11541061969","pt":1719501717316,"mc":[{"id":"1.230180125","rc":[{"atb":[[2.2,2.5]],"id":67245400}],"con":true,"img":false}]}
{"op":"mcm","clk":"11541062098","pt":1719501718836,"mc":[{"id":"1.230180125","rc":[{"atb":[[2.14,0]],"id":51567147}],"con":true,"img":false}]}
{"op":"mcm","clk":"11541062105","pt":1719501718915,"mc":[{"id":"1.230180125","rc":[{"atb":[[2.14,1.94]],"id":51567147}],"con":true,"img":false}]}
{"op":"mcm","clk":"11541062294","pt":1719501721245,"mc":[{"id":"1.230180125","rc":[{"atb":[[1.36,1.13]],"id":65992794},{"atb":[[2.42,1]],"id":67245400},{"atb":[[1.99,1]],"id":42767337},{"atb":[[2.16,1]],"id":51567147},{"atb":[[2.2,1]],"id":70902709}],"con":true,"img":false}]}
{"op":"mcm","clk":"11541062303","pt":1719501721303,"mc":[{"id":"1.230180125","rc":[{"atl":[[2.64,25.68]],"id":65992794},{"atb":[[1.99,6.92]],"id":42767337},{"atb":[[2.14,0]],"id":51567147},{"atb":[[2.18,15.75]],"id":70902709}],"con":true,"img":false}]}
{"op":"mcm","clk":"11541062310","pt":1719501721402,"mc":[{"id":"1.230180125","rc":[{"atb":[[1.36,14.74],[1.34,16.27],[1.35,28.31]],"id":65992794},{"atl":[[2.56,13.84],[3.95,0],[2.66,0],[2.62,4.25]],"id":65992794},{"atb":[[2.4,15.96],[2.42,6.94],[2.2,0]],"id":67245400},{"atl":[[6,6.75]],"id":67245400},{"atb":[[2,3.75],[1.98,14.21]],"id":42767337},{"atl":[[4,15.51],[3.95,7.61]],"id":51567147},{"atb":[[2.2,6.9],[2.16,0]],"id":70902709},{"atl":[[5.3,12.45],[5.2,6.72]],"id":70902709}],"con":true,"img":false}]}
{"op":"mcm","clk":"11541062320","pt":1719501721508,"mc":[{"id":"1.230180125","rc":[{"atb":[[2.02,1],[1.98,11.84]],"id":42767337},{"atb":[[2.14,1.94]],"id":51567147}],"con":true,"img":false}]}
{"op":"mcm","clk":"11541062328","pt":1719501721608,"mc":[{"id":"1.230180125","rc":[{"atl":[[2.6,27.68],[2.62,0]],"id":65992794},{"atb":[[2.4,13.83],[2.44,6.94]],"id":67245400},{"atl":[[7.8,13.52],[29,0]],"id":67245400},{"atb":[[2.1,4.57]],"id":51567147},{"atb":[[2.22,6.9],[2.18,13.75]],"id":70902709},{"atl":[[27,0],[6.6,17.86]],"id":70902709}],"con":true,"img":false}]}
{"op":"mcm","clk":"11541062337","pt":1719501721712,"mc":[{"id":"1.230180125","rc":[{"atb":[[2.46,1]],"id":67245400},{"atl":[[5.5,9.62]],"id":67245400},{"atb":[[2.24,1]],"id":70902709}],"con":true,"img":false}]}
{"op":"mcm","clk":"11541062344","pt":1719501721823,"mc":[{"id":"1.230180125","rc":[{"atl":[[2.54,0.84]],"id":65992794},{"atl":[[5.9,0.84]],"id":67245400},{"atl":[[5.1,0.84]],"id":70902709}],"con":true,"img":false}]}
{"op":"mcm","clk":"11541062352","pt":1719501721926,"mc":[{"id":"1.230180125","rc":[{"atb":[[1.97,0]],"id":42767337},{"atb":[[2.1,0]],"id":51567147},{"atl":[[5.2,5.72]],"id":70902709}],"con":true,"img":false}]}
{"op":"mcm","clk":"11541062391","pt":1719501722332,"mc":[{"id":"1.230180125","rc":[{"atl":[[5.9,0]],"id":67245400}],"con":true,"img":false}]}
{"op":"mcm","clk":"11541062410","pt":1719501722777,"mc":[{"id":"1.230180125","rc":[{"atb":[[1.02,0]],"id":42767337}],"con":true,"img":false}]}
{"op":"mcm","clk":"11541062419","pt":1719501722788,"mc":[{"id":"1.230180125","rc":[{"atb":[[2.02,3]],"id":42767337},{"atb":[[2.06,8.06]],"id":70902709}],"con":true,"img":false}]}
{"op":"mcm","clk":"11541062441","pt":1719501722905,"mc":[{"id":"1.230180125","rc":[{"atb":[[1.35,26.31]],"id":65992794},{"atl":[[2.54,3.38]],"id":65992794},{"atb":[[2,0],[2.04,3.75]],"id":42767337},{"atb":[[2.06,0]],"id":70902709}],"con":true,"img":false}]}
{"op":"mcm","clk":"11541062451","pt":1719501723008,"mc":[{"id":"1.230180125","rc":[{"atb":[[1.37,2]],"id":65992794}],"con":true,"img":false}]}
{"op":"mcm","clk":"11541062460","pt":1719501723117,"mc":[{"id":"1.230180125","rc":[{"atb":[[2.02,10.5],[2.04,0]],"id":42767337}],"con":true,"img":false}]}
{"op":"mcm","clk":"11541062479","pt":1719501723323,"mc":[{"id":"1.230180125","rc":[{"atb":[[1.02,0]],"id":70902709}],"con":true,"img":false}]}
{"op":"mcm","clk":"11541062486","pt":1719501723423,"mc":[{"id":"1.230180125","rc":[{"atb":[[2.24,3]],"id":70902709}],"con":true,"img":false}]}
{"op":"mcm","clk":"11541062494","pt":1719501723526,"mc":[{"id":"1.230180125","rc":[{"atb":[[2.22,0],[2.26,6.9]],"id":70902709}],"con":true,"img":false}]}
{"op":"mcm","clk":"11541062502","pt":1719501723627,"mc":[{"id":"1.230180125","rc":[{"atb":[[2.38,3.25]],"id":67245400},{"atb":[[2.26,0],[2.16,3.38]],"id":70902709}],"con":true,"img":false}]}
{"op":"mcm","clk":"11541062508","pt":1719501723731,"mc":[{"id":"1.230180125","rc":[{"atb":[[2.24,9.9]],"id":70902709}],"con":true,"img":false}]}
{"op":"mcm","clk":"11541062517","pt":1719501723839,"mc":[{"id":"1.230180125","rc":[{"atb":[[2.4,11.88]],"id":67245400},{"atb":[[2.14,0]],"id":51567147},{"atb":[[2.22,6.9],[2.18,11.8]],"id":70902709}],"con":true,"img":false}]}
{"op":"mcm","clk":"11541062527","pt":1719501723935,"mc":[{"id":"1.230180125","rc":[{"atb":[[2.24,3]],"id":70902709},{"atl":[[5,1]],"id":70902709}],"con":true,"img":false}]}
{"op":"mcm","clk":"11541062538","pt":1719501724037,"mc":[{"id":"1.230180125","rc":[{"atb":[[2.04,1.94]],"id":42767337},{"atb":[[2.14,1.94]],"id":51567147},{"atb":[[2.28,1.94]],"id":70902709}],"con":true,"img":false}]}
{"op":"mcm","clk":"11541062565","pt":1719501724303,"mc":[{"id":"1.230180125","rc":[{"atl":[[2.54,16.37]],"id":65992794},{"atb":[[2.02,22.18],[2.04,7.78]],"id":42767337},{"atb":[[2.26,11.79]],"id":70902709},{"atl":[[5,6.75]],"id":70902709}],"con":true,"img":false}]}
{"op":"mcm","clk":"11541062573","pt":1719501724456,"mc":[{"id":"1.230180125","rc":[{"atb":[[1.37,15.58],[1.35,30.43]],"id":65992794},{"atb":[[2.46,6.93],[2.44,18.8]],"id":67245400},{"atl":[[5.4,5.79]],"id":67245400},{"atl":[[6.6,6.7]],"id":42767337},{"atb":[[2.16,7.98],[2.14,15.91]],"id":51567147},{"atb":[[2.28,7.84],[2.16,0]],"id":70902709},{"atl":[[5.1,12.36]],"id":70902709}],"con":true,"img":false}]}
{"op":"mcm","clk":"11541062585","pt":1719501724659,"mc":[{"id":"1.230180125","rc":[{"atb":[[2.48,6.94]],"id":67245400},{"atl":[[38,0],[8.8,12.82]],"id":42767337}],"con":true,"img":false}]}
{"op":"mcm","clk":"11541062596","pt":1719501724805,"mc":[{"id":"1.230180125","rc":[{"atb":[[1.35,26.31]],"id":65992794},{"atb":[[2.44,11.86]],"id":67245400}],"con":true,"img":false}]}
{"op":"mcm","clk":"11541062604","pt":1719501724811,"mc":[{"id":"1.230180125","rc":[{"atl":[[6.4,0.84]],"id":42767337}],"con":true,"img":false}]}
{"op":"mcm","clk":"11541062609","pt":1719501724916,"mc":[{"id":"1.230180125","rc":[{"atb":[[1.38,2.04]],"id":65992794},{"atb":[[2.5,1]],"id":67245400},{"atb":[[2.06,1]],"id":42767337},{"atb":[[2.3,1.19]],"id":70902709}],"con":true,"img":false}]}
{"op":"mcm","clk":"11541062616","pt":1719501725018,"mc":[{"id":"1.230180125","rc":[{"atl":[[2.52,16.37],[2.6,0]],"id":65992794},{"atb":[[2.38,0]],"id":67245400},{"atl":[[6.4,10.68]],"id":42767337},{"atb":[[2.16,15.97],[2.08,0]],"id":51567147}],"con":true,"img":false}]}
{"op":"mcm","clk":"11541062642","pt":1719501725327,"mc":[{"id":"1.230180125","rc":[{"atl":[[2.5,2.69]],"id":65992794},{"atl":[[5.3,2.25]],"id":67245400},{"atl":[[6.4,0.84],[6.2,3.21]],"id":42767337},{"atl":[[3.9,2.25]],"id":51567147},{"atl":[[4.9,2.68]],"id":70902709}],"con":true,"img":false}]}
{"op":"mcm","clk":"11541062653","pt":1719501725430,"mc":[{"id":"1.230180125","rc":[{"atl":[[2.56,12.84],[2.52,17.37]],"id":65992794},{"atl":[[5,5.75]],"id":70902709}],"con":true,"img":false}]}
{"op":"mcm","clk":"11541062675","pt":1719501725739,"mc":[{"id":"1.230180125","rc":[{"atl":[[2.54,15.52]],"id":65992794},{"atb":[[2.02,20.18]],"id":42767337},{"atl":[[6.2,12.6]],"id":42767337},{"atl":[[3.85,0.84]],"id":51567147},{"atl":[[5.1,11.52]],"id":70902709}],"con":true,"img":false}]}
{"op":"mcm","clk":"11541062682","pt":1719501725837,"mc":[{"id":"1.230180125","rc":[{"atb":[[2.06,3]],"id":42767337}],"con":true,"img":false}]}
{"op":"mcm","clk":"11541062697","pt":1719501726001,"mc":[{"id":"1.230180125","rc":[{"atl":[[2.58,4.69]],"id":65992794},{"atl":[[5.5,0]],"id":67245400}],"con":true,"img":false}]}
{"op":"mcm","clk":"11541062702","pt":1719501726102,"mc":[{"id":"1.230180125","rc":[{"atb":[[2.48,18.66]],"id":67245400},{"atl":[[6,5.72]],"id":42767337},{"atl":[[3.85,7.67]],"id":51567147},{"atl":[[4.9,8.45]],"id":70902709}],"con":true,"img":false}]}
{"op":"mcm","clk":"11541062712","pt":1719501726202,"mc":[{"id":"1.230180125","rc":[{"atl":[[2.5,15.74],[2.52,43.49]],"id":65992794},{"atb":[[2.5,6.86]],"id":67245400},{"atl":[[6.4,12.29]],"id":42767337},{"atl":[[3.9,15.92]],"id":51567147}],"con":true,"img":false}]}
{"op":"mcm","clk":"11541062722","pt":1719501726312,"mc":[{"id":"1.230180125","rc":[{"atl":[[2.54,12.98]],"id":65992794},{"atl":[[5.4,12.04]],"id":67245400},{"atl":[[5.9,1.76]],"id":42767337},{"atl":[[3.8,2.39]],"id":51567147}],"con":true,"img":false}]}
{"op":"mcm","clk":"11541062756","pt":1719501726717,"mc":[{"id":"1.230180125","rc":[{"atl":[[6.4,11.44],[5.9,7.49]],"id":42767337},{"atl":[[3.95,6.76],[3.8,9.23]],"id":51567147}],"con":true,"img":false}]}
{"op":"mcm","clk":"11541062775","pt":1719501726924,"mc":[{"id":"1.230180125","rc":[{"atb":[[1.38,15.66]],"id":65992794},{"atl":[[2.58,0]],"id":65992794},{"atl":[[5.3,7.97]],"id":67245400},{"atb":[[2.06,8.84],[2.04,5.83]],"id":42767337},{"atb":[[2.18,7],[2.14,13.97]],"id":51567147},{"atb":[[2.3,7.09]],"id":70902709}],"con":true,"img":false}]}
{"op":"mcm","clk":"11541062782","pt":1719501727033,"mc":[{"id":"1.230180125","rc":[{"atb":[[1.37,13.58]],"id":65992794},{"atb":[[2.52,1.94]],"id":67245400},{"atb":[[2.08,1.94]],"id":42767337},{"atb":[[2.18,8.94],[2.2,1.49]],"id":51567147}],"con":true,"img":false}]}
{"op":"mcm","clk":"11541062789","pt":1719501727131,"mc":[{"id":"1.230180125","rc":[{"atb":[[1.39,2]],"id":65992794}],"con":true,"img":false}]}
{"op":"mcm","clk":"11541062797","pt":1719501727232,"mc":[{"id":"1.230180125","rc":[{"atb":[[1.4,2.59]],"id":65992794},{"atb":[[2.54,1.12]],"id":67245400},{"atb":[[2.1,1]],"id":42767337}],"con":true,"img":false}]}
{"op":"mcm","clk":"11541062840","pt":1719501727696,"mc":[{"id":"1.230180125","rc":[{"atb":[[2.24,1]],"id":70902709}],"con":true,"img":false}]}
{"op":"mcm","clk":"11541062849","pt":1719501727799,"mc":[{"id":"1.230180125","rc":[{"atb":[[2.3,9.09]],"id":70902709},{"atl":[[4.8,1]],"id":70902709}],"con":true,"img":false}]}
{"op":"mcm","clk":"11541062855","pt":1719501727899,"mc":[{"id":"1.230180125","rc":[{"atl":[[4.7,2.94]],"id":70902709}],"con":true,"img":false}]}
{"op":"mcm","clk":"11541062876","pt":1719501728212,"mc":[{"id":"1.230180125","rc":[{"atl":[[5.4,5.79]],"id":67245400},{"atb":[[2.02,12.68],[2.08,7.78]],"id":42767337}],"con":true,"img":false}]}
{"op":"mcm","clk":"11541062886","pt":1719501728321,"mc":[{"id":"1.230180125","rc":[{"atb":[[1.36,22.48]],"id":65992794}],"con":true,"img":false}]}
{"op":"mcm","clk":"11541062897","pt":1719501728415,"mc":[{"id":"1.230180125","rc":[{"atb":[[1.4,16.19],[1.36,14.74],[1.39,28.31]],"id":65992794},{"atb":[[2.1,6.84],[2.08,19.47]],"id":42767337},{"atb":[[2.2,8.48],[2.14,17.47]],"id":51567147}],"con":true,"img":false}]}
{"op":"mcm","clk":"11541062909","pt":1719501728526,"mc":[{"id":"1.230180125","rc":[{"atl":[[5.3,12.33]],"id":67245400}],"con":true,"img":false}]}
{"op":"mcm","clk":"11541062922","pt":1719501728624,"mc":[{"id":"1.230180125","rc":[{"atb":[[2.12,8.85],[2.08,13.63]],"id":42767337},{"spl":[[4.8,0.16],[5.1,0.15],[5,0.15],[5.3,0.14],[4.9,0.16],[5.2,0.15],[6.6,0.14],[4.7,0.08]],"id":70902709},{"atl":[[4.8,0]],"id":70902709}],"con":true,"img":false}]}
{"op":"mcm","clk":"11541062934","pt":1719501728726,"mc":[{"id":"1.230180125","rc":[{"atl":[[2.48,2.54]],"id":65992794},{"atb":[[2.14,1]],"id":42767337}],"con":true,"img":false}]}
{"op":"mcm","clk":"11541062951","pt":1719501728934,"mc":[{"id":"1.230180125","rc":[{"atl":[[2.46,2.81]],"id":65992794},{"atb":[[2.32,9.09]],"id":70902709}],"con":true,"img":false}]}
{"op":"mcm","clk":"11541062963","pt":1719501729042,"mc":[{"id":"1.230180125","rc":[{"atl":[[2.48,15.63]],"id":65992794},{"atl":[[5.2,5.74]],"id":67245400},{"atb":[[2.22,0]],"id":70902709}],"con":true,"img":false}]}
{"op":"mcm","clk":"11541062969","pt":1719501729135,"mc":[{"id":"1.230180125","rc":[{"atb":[[2.34,1.4]],"id":70902709}],"con":true,"img":false}]}
{"op":"mcm","clk":"11541062975","pt":1719501729240,"mc":[{"id":"1.230180125","rc":[{"atl":[[2.56,0],[2.46,15.91],[2.44,0.84]],"id":65992794},{"atl":[[5.2,6.58]],"id":67245400},{"atl":[[4,13.52]],"id":51567147},{"atl":[[4.6,0.84]],"id":70902709}],"con":true,"img":false}]}
{"op":"mcm","clk":"11541063008","pt":1719501729706,"mc":[{"id":"1.230180125","rc":[{"spl":[[2.54,0.31],[2.5,0.31],[2.52,0.31],[2.46,0.32],[2.44,0.16],[2.64,0.3],[2.48,0.31],[990,0.3]],"id":65992794}],"con":true,"img":false}]}
{"op":"mcm","clk":"11541063014","pt":1719501729813,"mc":[{"id":"1.230180125","rc":[{"atb":[[2.54,3.12],[2.48,11.72]],"id":67245400}],"con":true,"img":false}]}
{"op":"mcm","clk":"11541063020","pt":1719501729916,"mc":[{"id":"1.230180125","rc":[{"atb":[[2.06,6.84]],"id":42767337}],"con":true,"img":false}]}
{"op":"mcm","clk":"11541063027","pt":1719501730012,"mc":[{"id":"1.230180125","rc":[{"atb":[[2.14,3]],"id":42767337}],"con":true,"img":false}]}
{"op":"mcm","clk":"11541063034","pt":1719501730121,"mc":[{"id":"1.230180125","rc":[{"atb":[[2.52,0]],"id":67245400},{"atb":[[2.12,14.14],[2.08,11.68]],"id":42767337},{"atb":[[2.18,7]],"id":51567147},{"atb":[[2.28,5.89]],"id":70902709}],"con":true,"img":false}]}
{"op":"mcm","clk":"11541063041","pt":1719501730221,"mc":[{"id":"1.230180125","rc":[{"atb":[[2.14,4.94]],"id":42767337},{"atb":[[2.22,1.94]],"id":51567147},{"atb":[[2.34,3.34]],"id":70902709}],"con":true,"img":false}]}
{"op":"mcm","clk":"11541063047","pt":1719501730326,"mc":[{"id":"1.230180125","rc":[{"atl":[[2.52,42.49]],"id":65992794},{"atb":[[2.24,1.75]],"id":51567147}],"con":true,"img":false}]}
{"op":"mcm","clk":"11541063076","pt":1719501730635,"mc":[{"id":"1.230180125","rc":[{"atl":[[5.3,7.97]],"id":67245400}],"con":true,"img":false}]}
{"op":"mcm","clk":"11541063087","pt":1719501730736,"mc":[{"id":"1.230180125","rc":[{"atl":[[4.5,1]],"id":70902709}],"con":true,"img":false}]}
{"op":"mcm","clk":"11541063113","pt":1719501731048,"mc":[{"id":"1.230180125","rc":[{"atb":[[1.39,26.31]],"id":65992794},{"atl":[[2.48,13.09]],"id":65992794}],"con":true,"img":false}]}
{"op":"mcm","clk":"11541063122","pt":1719501731145,"mc":[{"id":"1.230180125","rc":[{"atb":[[1.41,2]],"id":65992794},{"atl":[[2.44,13.93]],"id":65992794},{"atb":[[2.14,13.97]],"id":51567147},{"atl":[[4.5,6.78],[4.6,12.41]],"id":70902709}],"con":true,"img":false}]}
{"op":"mcm","clk":"11541063131","pt":1719501731249,"mc":[{"id":"1.230180125","rc":[{"atb":[[1.42,3.23]],"id":65992794},{"atl":[[2.54,0]],"id":65992794},{"atb":[[2.54,8.95]],"id":67245400},{"atb":[[1.99,1],[1.98,0],[2.12,25.85],[2.14,10.8]],"id":42767337},{"atb":[[2.24,8.72],[2.22,15.89]],"id":51567147},{"atb":[[2.32,20.91],[2.34,9.25]],"id":70902709}],"con":true,"img":false}]}
{"op":"mcm","clk":"11541063140","pt":1719501731303,"mc":[{"id":"1.230180125","rc":[{"atl":[[2.56,1]],"id":65992794}],"con":true,"img":false}]}
{"op":"mcm","clk":"11541063147","pt":1719501731408,"mc":[{"id":"1.230180125","rc":[{"atb":[[1.41,28.31],[1.36,1.13],[1.42,16.85]],"id":65992794}],"con":true,"img":false}]}
{"op":"mcm","clk":"11541063155","pt":1719501731509,"mc":[{"id":"1.230180125","rc":[{"atl":[[6.2,3.21]],"id":42767337}],"con":true,"img":false}]}
{"op":"mcm","clk":"11541063164","pt":1719501731614,"mc":[{"id":"1.230180125","rc":[{"atl":[[5.1,4.7]],"id":67245400}],"con":true,"img":false}]}
{"op":"mcm","clk":"11541063185","pt":1719501731923,"mc":[{"id":"1.230180125","rc":[{"atb":[[2.3,7.09]],"id":70902709}],"con":true,"img":false}]}
{"op":"mcm","clk":"11541063193","pt":1719501732030,"mc":[{"id":"1.230180125","rc":[{"atb":[[2.34,11.25]],"id":70902709}],"con":true,"img":false}]}
{"op":"mcm","clk":"11541063211","pt":1719501732232,"mc":[{"id":"1.230180125","rc":[{"atl":[[2.42,2.94]],"id":65992794},{"atl":[[5,2.56]],"id":67245400},{"atb":[[2.36,5.89],[2.2,1]],"id":70902709},{"atl":[[4.4,3.42]],"id":70902709}],"con":true,"img":false}]}
{"op":"mcm","clk":"11541063216","pt":1719501732335,"mc":[{"id":"1.230180125","rc":[{"atl":[[5.8,0.84],[5.7,3.99]],"id":42767337},{"atl":[[4,15.51]],"id":51567147},{"atb":[[2.38,1.58]],"id":70902709}],"con":true,"img":false}]}
{"op":"mcm","clk":"11541063224","pt":1719501732439,"mc":[{"id":"1.230180125","rc":[{"atl":[[2.5,2.69],[2.42,15.96]],"id":65992794},{"atl":[[5.1,16.2],[5,8.31],[6,1]],"id":67245400},{"atl":[[4.5,5.78],[5.2,0],[4.4,9.18]],"id":70902709}],"con":true,"img":false}]}
{"op":"mcm","clk":"11541063238","pt":1719501732652,"mc":[{"id":"1.230180125","rc":[{"atl":[[4,13.52]],"id":51567147}],"con":true,"img":false}]}
{"op":"mcm","clk":"11541063251","pt":1719501732746,"mc":[{"id":"1.230180125","rc":[{"atl":[[5.2,5.74]],"id":67245400},{"atl":[[3.75,0.84]],"id":51567147},{"atl":[[4.6,11.57]],"id":70902709}],"con":true,"img":false}]}
{"op":"mcm","clk":"11541063278","pt":1719501733109,"mc":[{"id":"1.230180125","rc":[{"atb":[[2.22,13.94]],"id":51567147},{"atb":[[2.34,9.31]],"id":70902709}],"con":true,"img":false}]}
{"op":"mcm","clk":"11541063295","pt":1719501733319,"mc":[{"id":"1.230180125","rc":[{"atl":[[2.4,2.54]],"id":65992794},{"atb":[[2.26,1.94]],"id":51567147},{"atb":[[2.38,3.52]],"id":70902709}],"con":true,"img":false}]}
{"op":"mcm","clk":"11541063307","pt":1719501733421,"mc":[{"id":"1.230180125","rc":[{"atb":[[2.28,2.12]],"id":51567147}],"con":true,"img":false}]}
{"op":"mcm","clk":"11541063316","pt":1719501733528,"mc":[{"id":"1.230180125","rc":[{"atl":[[2.52,55.24],[2.38,3.08]],"id":65992794},{"atb":[[2.12,30.46]],"id":42767337},{"atl":[[5.6,1.98],[5.8,12.38],[5.7,9.75]],"id":42767337},{"atl":[[3.75,7.66]],"id":51567147},{"atb":[[2.38,9.42],[2.28,0]],"id":70902709}],"con":true,"img":false}]}
{"op":"mcm","clk":"11541063324","pt":1719501733626,"mc":[{"id":"1.230180125","rc":[{"atl":[[4,15.51],[3.7,2.54]],"id":51567147}],"con":true,"img":false}]}
{"op":"mcm","clk":"11541063332","pt":1719501733733,"mc":[{"id":"1.230180125","rc":[{"atl":[[2.44,13.09]],"id":65992794}],"con":true,"img":false}]}
{"op":"mcm","clk":"11541063343","pt":1719501733834,"mc":[{"id":"1.230180125","rc":[{"atl":[[2.52,42.49]],"id":65992794},{"atb":[[2.12,21.61],[2.16,10.8]],"id":42767337}],"con":true,"img":false}]}
{"op":"mcm","clk":"11541063354","pt":1719501733942,"mc":[{"id":"1.230180125","rc":[{"atb":[[2.12,20.26],[2.18,1.24]],"id":42767337},{"atl":[[5.6,7.75],[6.6,1]],"id":42767337},{"atl":[[3.95,0],[3.7,9.37]],"id":51567147}],"con":true,"img":false}]}
{"op":"mcm","clk":"11541063368","pt":1719501734151,"mc":[{"id":"1.230180125","rc":[{"atb":[[2.32,11.82],[2.4,9.31]],"id":70902709}],"con":true,"img":false}]}
{"op":"mcm","clk":"11541063378","pt":1719501734252,"mc":[{"id":"1.230180125","rc":[{"atl":[[5.8,11.53]],"id":42767337},{"atb":[[2.28,9.08],[2.26,15.88],[2.16,8.99]],"id":51567147},{"atl":[[3.85,6.83]],"id":51567147},{"atb":[[2.42,1.75]],"id":70902709}],"con":true,"img":false}]}
{"op":"mcm","clk":"11541063390","pt":1719501734303,"mc":[{"id":"1.230180125","rc":[{"atb":[[2.3,1.19],[2.42,7.63]],"id":70902709},{"atl":[[4.3,1]],"id":70902709}],"con":true,"img":false}]}
{"op":"mcm","clk":"11541063398","pt":1719501734402,"mc":[{"id":"1.230180125","rc":[{"atl":[[2.4,0]],"id":65992794},{"atb":[[2.12,17]],"id":42767337},{"atl":[[4.2,3.82]],"id":70902709}],"con":true,"img":false}]}
{"op":"mcm","clk":"11541063419","pt":1719501734623,"mc":[{"id":"1.230180125","rc":[{"atb":[[2.04,0],[2.14,8.8],[2.02,1],[2.18,7.14],[2.16,22.6]],"id":42767337}],"con":true,"img":false}]}
{"op":"mcm","clk":"11541063430","pt":1719501734717,"mc":[{"id":"1.230180125","rc":[{"atl":[[2.38,15.91]],"id":65992794},{"atl":[[5.1,11.5]],"id":67245400},{"atb":[[2.18,9.14]],"id":42767337}],"con":true,"img":false}]}
{"op":"mcm","clk":"11541063440","pt":1719501734818,"mc":[{"id":"1.230180125","rc":[{"atl":[[2.4,25.66],[2.48,0]],"id":65992794},{"atl":[[4.3,12.55],[5,0],[5.3,1],[4.2,9.59]],"id":70902709}],"con":true,"img":false}]}
{"op":"mcm","clk":"11541063455","pt":1719501734919,"mc":[{"id":"1.230180125","rc":[{"spn":1.56,"spf":1.0,"id":65992794},{"atl":[[4.9,5.49]],"id":67245400},{"spn":3.72,"spf":"NaN","id":67245400},{"atl":[[5.7,5.76]],"id":42767337},{"spn":3.89,"spf":"NaN","id":42767337},{"spn":2.27,"spf":1.0,"id":51567147},{"spn":3.31,"spf":1.0,"id":70902709}],"con":true,"img":false}]}
{"op":"mcm","clk":"11541063467","pt":1719501735027,"mc":[{"id":"1.230180125","rc":[{"atl":[[4.8,2.8]],"id":67245400}],"con":true,"img":false}]}
{"op":"mcm","clk":"11541063473","pt":1719501735126,"mc":[{"id":"1.230180125","rc":[{"atl":[[4.3,11.55]],"id":70902709}],"con":true,"img":false}]}
{"op":"mcm","clk":"11541063481","pt":1719501735234,"mc":[{"id":"1.230180125","rc":[{"atl":[[4.8,8.64],[4.9,17.18],[5.4,0]],"id":67245400}],"con":true,"img":false}]}
{"op":"mcm","clk":"11541063489","pt":1719501735332,"mc":[{"id":"1.230180125","rc":[{"atl":[[5.5,1.97]],"id":42767337}],"con":true,"img":false}]}
{"op":"mcm","clk":"11541063498","pt":1719501735438,"mc":[{"id":"1.230180125","rc":[{"atb":[[1.41,26.31]],"id":65992794},{"atl":[[5.4,2.15]],"id":42767337}],"con":true,"img":false}]}
{"op":"mcm","clk":"11541063507","pt":1719501735538,"mc":[{"id":"1.230180125","rc":[{"atb":[[1.43,2]],"id":65992794}],"con":true,"img":false}]}
{"op":"mcm","clk":"11541063515","pt":1719501735640,"mc":[{"id":"1.230180125","rc":[{"atb":[[2.34,14.59]],"id":70902709}],"con":true,"img":false}]}
{"op":"mcm","clk":"11541063538","pt":1719501735946,"mc":[{"id":"1.230180125","rc":[{"atb":[[2.34,9.31]],"id":70902709}],"con":true,"img":false}]}
{"op":"mcm","clk":"11541063544","pt":1719501736054,"mc":[{"id":"1.230180125","rc":[{"atb":[[1.43,15.19],[1.37,0]],"id":65992794},{"atl":[[5.5,13.61],[6,0],[5.4,7.97]],"id":42767337}],"con":true,"img":false}]}
{"op":"mcm","clk":"11541063552","pt":1719501736152,"mc":[{"id":"1.230180125","rc":[{"atb":[[2.14,6.85]],"id":42767337},{"atb":[[2.26,13.93]],"id":51567147},{"atb":[[2.34,7.31],[2.38,7.47]],"id":70902709}],"con":true,"img":false}]}
{"op":"mcm","clk":"11541063560","pt":1719501736211,"mc":[{"id":"1.230180125","rc":[{"atb":[[1.44,3.72]],"id":65992794},{"atl":[[2.36,0.84]],"id":65992794},{"atl":[[4.7,0.84]],"id":67245400},{"atb":[[2.42,9.63]],"id":70902709},{"atl":[[4.1,0.84]],"id":70902709}],"con":true,"img":false}]}
{"op":"mcm","clk":"11541063568","pt":1719501736312,"mc":[{"id":"1.230180125","rc":[{"atb":[[1.44,16.84],[1.38,2.04]],"id":65992794},{"atl":[[2.36,3.38]],"id":65992794},{"atl":[[5.3,2.24]],"id":67245400},{"atb":[[2.2,1.94]],"id":42767337},{"atb":[[2.3,1.94]],"id":51567147},{"atb":[[2.44,1.94]],"id":70902709}],"con":true,"img":false}]}
{"op":"mcm","clk":"11541063576","pt":1719501736414,"mc":[{"id":"1.230180125","rc":[{"atl":[[4.7,6.74]],"id":67245400}],"con":true,"img":false}]}
{"op":"mcm","clk":"11541063584","pt":1719501736519,"mc":[{"id":"1.230180125","rc":[{"atl":[[2.34,3.22]],"id":65992794},{"atb":[[2.22,1.57]],"id":42767337},{"atb":[[2.32,2.29]],"id":51567147},{"atb":[[2.46,1.95]],"id":70902709}],"con":true,"img":false}]}
{"op":"mcm","clk":"11541063592","pt":1719501736621,"mc":[{"id":"1.230180125","rc":[{"atl":[[4.6,3.09]],"id":67245400}],"con":true,"img":false}]}
{"op":"mcm","clk":"11541063612","pt":1719501736829,"mc":[{"id":"1.230180125","rc":[{"atl":[[4.6,9],[5.2,0]],"id":67245400},{"atb":[[2.22,7.47],[2.08,0],[2.06,1],[2.2,13.76]],"id":42767337},{"atb":[[2.32,9.16],[2.3,15.69],[2.14,0],[2.18,0]],"id":51567147},{"atb":[[2.44,13.67],[2.34,1.4],[2.46,7.81],[2.18,0]],"id":70902709}],"con":true,"img":false}]}
{"op":"mcm","clk":"11541063648","pt":1719501737247,"mc":[{"id":"1.230180125","rc":[{"atb":[[1.41,30.06]],"id":65992794}],"con":true,"img":false}]}
{"op":"mcm","clk":"11541063657","pt":1719501737352,"mc":[{"id":"1.230180125","rc":[{"atl":[[4,1]],"id":70902709}],"con":true,"img":false}]}
{"op":"mcm","clk":"11541063666","pt":1719501737450,"mc":[{"id":"1.230180125","rc":[{"atl":[[3.95,2.19]],"id":70902709}],"con":true,"img":false}]}
{"op":"mcm","clk":"11541063697","pt":1719501737815,"mc":[{"id":"1.230180125","rc":[{"atl":[[4.1,0]],"id":70902709}],"con":true,"img":false}]}
{"op":"mcm","clk":"11541063705","pt":1719501737914,"mc":[{"id":"1.230180125","rc":[{"atl":[[2.36,28.88],[2.46,2.81],[2.64,0],[2.34,15.96]],"id":65992794},{"atl":[[4,0]],"id":70902709}],"con":true,"img":false}]}
{"op":"mcm","clk":"11541063721","pt":1719501738130,"mc":[{"id":"1.230180125","rc":[{"atb":[[1.41,26.31]],"id":65992794},{"atl":[[5.5,11.64]],"id":42767337},{"atl":[[3.95,0]],"id":70902709}],"con":true,"img":false}]}
{"op":"mcm","clk":"11541063731","pt":1719501738225,"mc":[{"id":"1.230180125","rc":[{"atl":[[4.1,11.56],[3.9,2.25]],"id":70902709}],"con":true,"img":false}]}
{"op":"mcm","clk":"11541063744","pt":1719501738332,"mc":[{"id":"1.230180125","rc":[{"atl":[[4.9,2.68],[5.1,0],[3.95,5.77],[4.1,15.6]],"id":70902709}],"con":true,"img":false}]}
{"op":"mcm","clk":"11541063762","pt":1719501738531,"mc":[{"id":"1.230180125","rc":[{"atl":[[5.5,15.03]],"id":42767337}],"con":true,"img":false}]}
{"op":"mcm","clk":"11541063777","pt":1719501738749,"mc":[{"id":"1.230180125","rc":[{"atl":[[2.36,26.34]],"id":65992794}],"con":true,"img":false}]}
{"op":"mcm","clk":"11541063787","pt":1719501738847,"mc":[{"id":"1.230180125","rc":[{"atb":[[2.18,7.14]],"id":42767337}],"con":true,"img":false}]}
{"op":"mcm","clk":"11541063798","pt":1719501738944,"mc":[{"id":"1.230180125","rc":[{"atb":[[2.24,11.14],[2.16,11.8]],"id":42767337}],"con":true,"img":false}]}
{"op":"mcm","clk":"11541063809","pt":1719501739051,"mc":[{"id":"1.230180125","rc":[{"atb":[[2.26,1.81]],"id":42767337}],"con":true,"img":false}]}
{"op":"mcm","clk":"11541063823","pt":1719501739261,"mc":[{"id":"1.230180125","rc":[{"atb":[[2.2,11.81]],"id":42767337},{"atb":[[2.3,13.74]],"id":51567147},{"atb":[[2.44,11.72]],"id":70902709}],"con":true,"img":false}]}
{"op":"mcm","clk":"11541063832","pt":1719501739359,"mc":[{"id":"1.230180125","rc":[{"atb":[[1.43,13.19]],"id":65992794}],"con":true,"img":false}]}
{"op":"mcm","clk":"11541063841","pt":1719501739410,"mc":[{"id":"1.230180125","rc":[{"atb":[[1.45,2]],"id":65992794},{"atb":[[2.56,1.94]],"id":67245400},{"atb":[[2.24,13.08]],"id":42767337},{"atb":[[2.48,1.94]],"id":70902709}],"con":true,"img":false}]}
{"op":"mcm","clk":"11541063849","pt":1719501739513,"mc":[{"id":"1.230180125","rc":[{"atb":[[1.46,4.16]],"id":65992794},{"atb":[[2.58,2.04]],"id":67245400},{"atb":[[2.5,2.16]],"id":70902709},{"atl":[[4.5,0],[3.9,8.02]],"id":70902709}],"con":true,"img":false}]}
{"op":"mcm","clk":"11541063858","pt":1719501739615,"mc":[{"id":"1.230180125","rc":[{"atb":[[2.54,6.95],[2.58,4.08]],"id":67245400},{"atb":[[2.42,7.63]],"id":70902709}],"con":true,"img":false}]}
{"op":"mcm","clk":"11541063865","pt":1719501739718,"mc":[{"id":"1.230180125","rc":[{"atl":[[5.3,0.84]],"id":42767337},{"atb":[[2.48,3.94]],"id":70902709}],"con":true,"img":false}]}
{"op":"mcm","clk":"11541063874","pt":1719501739826,"mc":[{"id":"1.230180125","rc":[{"atl":[[3.65,0.84]],"id":51567147}],"con":true,"img":false}]}
{"op":"mcm","clk":"11541063880","pt":1719501739925,"mc":[{"id":"1.230180125","rc":[{"atl":[[2.52,26.12],[2.34,31.93]],"id":65992794},{"atl":[[6.8,16.95],[7.8,0]],"id":67245400},{"atl":[[7.6,15.15],[8.8,0]],"id":42767337},{"atb":[[2.2,31.39],[2.16,1]],"id":51567147},{"atl":[[4.5,18.48],[5,0]],"id":51567147},{"atb":[[2.4,0],[2.46,15.62]],"id":70902709},{"atl":[[5.7,17.21],[6.6,0]],"id":70902709}],"con":true,"img":false}]}
{"op":"mcm","clk":"11541063888","pt":1719501740034,"mc":[{"id":"1.230180125","rc":[{"atl":[[3.85,1]],"id":70902709}],"con":true,"img":false}]}
{"op":"mcm","clk":"11541063898","pt":1719501740137,"mc":[{"id":"1.230180125","rc":[{"atb":[[1.46,17.1],[1.45,27.89],[1.35,0],[1.4,2.59]],"id":65992794},{"atl":[[5.3,6.72],[5.9,1.76]],"id":42767337},{"atl":[[3.85,0],[3.65,7.61]],"id":51567147},{"atl":[[3.85,6.77],[4.4,3.42]],"id":70902709}],"con":true,"img":false}]}
{"op":"mcm","clk":"11541063908","pt":1719501740238,"mc":[{"id":"1.230180125","rc":[{"atl":[[2.32,12.66]],"id":65992794},{"atl":[[5.2,2.34]],"id":42767337},{"atl":[[3.6,2.71]],"id":51567147}],"con":true,"img":false}]}
{"op":"mcm","clk":"11541063919","pt":1719501740335,"mc":[{"id":"1.230180125","rc":[{"atl":[[2.3,3.38],[2.44,0]],"id":65992794},{"atb":[[2.58,10.05],[2.56,13.9],[2.42,1]],"id":67245400},{"atb":[[2.5,7.99],[2.26,0],[2.48,15.61],[2.36,0]],"id":70902709}],"con":true,"img":false}]}
{"op":"mcm","clk":"11541063928","pt":1719501740440,"mc":[{"id":"1.230180125","rc":[{"atb":[[2.4,0]],"id":67245400},{"atl":[[5.5,11.64]],"id":42767337},{"atl":[[4,13.52]],"id":51567147}],"con":true,"img":false}]}
{"op":"mcm","clk":"11541063957","pt":1719501740749,"mc":[{"id":"1.230180125","rc":[{"atb":[[1.45,25.89]],"id":65992794},{"atl":[[2.36,25.49]],"id":65992794},{"atl":[[5.1,5.45]],"id":42767337},{"atl":[[3.75,6.81]],"id":51567147}],"con":true,"img":false}]}
{"op":"mcm","clk":"11541063968","pt":1719501740859,"mc":[{"id":"1.230180125","rc":[{"atb":[[1.47,2]],"id":65992794},{"atl":[[5,2.56]],"id":42767337}],"con":true,"img":false}]}
{"op":"mcm","clk":"11541063979","pt":1719501740954,"mc":[{"id":"1.230180125","rc":[{"atl":[[2.32,15.2]],"id":65992794},{"atb":[[2.12,5.29],[2.26,7.85],[2.1,1],[2.24,25.17]],"id":42767337}],"con":true,"img":false}]}
{"op":"mcm","clk":"11541063986","pt":1719501741065,"mc":[{"id":"1.230180125","rc":[{"atb":[[1.48,4.55],[1.42,3.23],[1.47,19.39]],"id":65992794},{"atb":[[2.48,13.61]],"id":70902709}],"con":true,"img":false}]}
{"op":"mcm","clk":"11541063992","pt":1719501741158,"mc":[{"id":"1.230180125","rc":[{"atb":[[2.52,2]],"id":70902709}],"con":true,"img":false}]}
{"op":"mcm","clk":"11541064002","pt":1719501741264,"mc":[{"id":"1.230180125","rc":[{"atb":[[2.54,2.29]],"id":70902709}],"con":true,"img":false}]}
{"op":"mcm","clk":"11541064013","pt":1719501741321,"mc":[{"id":"1.230180125","rc":[{"atl":[[2.3,15.92]],"id":65992794},{"atl":[[5.3,5.87],[5.1,17.38],[5,8.52],[5.7,0]],"id":42767337}],"con":true,"img":false}]}
{"op":"mcm","clk":"11541064024","pt":1719501741421,"mc":[{"id":"1.230180125","rc":[{"atl":[[2.42,2.94]],"id":65992794},{"atl":[[6.4,0]],"id":42767337}],"con":true,"img":false}]}
{"op":"mcm","clk":"11541064033","pt":1719501741521,"mc":[{"id":"1.230180125","rc":[{"atb":[[1.43,0],[1.48,17.28]],"id":65992794},{"atl":[[3.6,9.36],[3.8,2.39]],"id":51567147}],"con":true,"img":false}]}
{"op":"mcm","clk":"11541064041","pt":1719501741629,"mc":[{"id":"1.230180125","rc":[{"atb":[[2.54,8.11],[2.32,0],[2.52,13.64],[2.38,1.58]],"id":70902709}],"con":true,"img":false}]}
{"op":"mcm","clk":"11541064050","pt":1719501741737,"mc":[{"id":"1.230180125","rc":[{"atb":[[2.24,23.17]],"id":42767337}],"con":true,"img":false}]}
{"op":"mcm","clk":"11541064061","pt":1719501741834,"mc":[{"id":"1.230180125","rc":[{"atb":[[2.28,2]],"id":42767337}],"con":true,"img":false}]}
{"op":"mcm","clk":"11541064070","pt":1719501741935,"mc":[{"id":"1.230180125","rc":[{"atb":[[2.3,2.02]],"id":42767337}],"con":true,"img":false}]}
{"op":"mcm","clk":"11541064081","pt":1719501742039,"mc":[{"id":"1.230180125","rc":[{"atb":[[1.38,12.81]],"id":65992794}],"con":true,"img":false}]}
{"op":"mcm","clk":"11541064091","pt":1719501742142,"mc":[{"id":"1.230180125","rc":[{"atb":[[1.47,17.39]],"id":65992794},{"atl":[[2.32,12.66]],"id":65992794}],"con":true,"img":false}]}
{"op":"mcm","clk":"11541064098","pt":1719501742250,"mc":[{"id":"1.230180125","rc":[{"atb":[[1.49,2]],"id":65992794}],"con":true,"img":false}]}
{"op":"mcm","clk":"11541064116","pt":1719501742452,"mc":[{"id":"1.230180125","rc":[{"atb":[[2.56,11.95]],"id":67245400},{"atb":[[2.24,21.22]],"id":42767337},{"atb":[[2.48,11.67]],"id":70902709}],"con":true,"img":false}]}
{"op":"mcm","clk":"11541064125","pt":1719501742556,"mc":[{"id":"1.230180125","rc":[{"atb":[[1.38,2.04]],"id":65992794},{"atb":[[2.32,1.94]],"id":42767337},{"atb":[[2.34,1.94]],"id":51567147},{"atb":[[2.56,1.94],[2.52,11.64]],"id":70902709}],"con":true,"img":false}]}
{"op":"mcm","clk":"11541064132","pt":1719501742656,"mc":[{"id":"1.230180125","rc":[{"atb":[[2.56,3.94]],"id":70902709}],"con":true,"img":false}]}
{"op":"mcm","clk":"11541064139","pt":1719501742763,"mc":[{"id":"1.230180125","rc":[{"atb":[[2.34,8.58],[2.2,24.4]],"id":51567147}],"con":true,"img":false}]}
{"op":"mcm","clk":"11541064149","pt":1719501742819,"mc":[{"id":"1.230180125","rc":[{"atb":[[2.34,2.02]],"id":42767337},{"atb":[[2.36,2.57]],"id":51567147},{"atb":[[2.58,2.31]],"id":70902709}],"con":true,"img":false}]}
{"op":"mcm","clk":"11541064164","pt":1719501743028,"mc":[{"id":"1.230180125","rc":[{"atb":[[1.44,3.72],[1.49,14.94]],"id":65992794},{"atb":[[2.36,9.2],[2.24,1.75]],"id":51567147},{"atb":[[2.44,0],[2.58,8.15],[2.56,15.64],[2.42,1.75]],"id":70902709}],"con":true,"img":false}]}
{"op":"mcm","clk":"11541064183","pt":1719501743332,"mc":[{"id":"1.230180125","rc":[{"atl":[[2.28,0.84]],"id":65992794},{"atl":[[4.5,0.84]],"id":67245400},{"atl":[[3.8,0.84]],"id":70902709}],"con":true,"img":false}]}
{"op":"mcm","clk":"11541064189","pt":1719501743437,"mc":[{"id":"1.230180125","rc":[{"atl":[[2.28,3.38]],"id":65992794},{"atl":[[5.1,11.93]],"id":42767337},{"atl":[[3.55,2.54]],"id":51567147}],"con":true,"img":false}]}
{"op":"mcm","clk":"11541064197","pt":1719501743543,"mc":[{"id":"1.230180125","rc":[{"atl":[[2.26,3.55]],"id":65992794},{"atl":[[3.5,2.9]],"id":51567147},{"atl":[[3.85,5.77]],"id":70902709}],"con":true,"img":false}]}
{"op":"mcm","clk":"11541064208","pt":1719501743649,"mc":[{"id":"1.230180125","rc":[{"atl":[[4.5,6.87],[5,2.56]],"id":67245400},{"atb":[[2.32,14.21],[2.14,1],[2.34,8.15],[2.16,0]],"id":42767337}],"con":true,"img":false}]}
{"op":"mcm","clk":"11541064216","pt":1719501743751,"mc":[{"id":"1.230180125","rc":[{"atl":[[4.9,11.69],[4.4,3.42]],"id":67245400},{"atl":[[5,10.5]],"id":42767337},{"atl":[[3.65,6.76]],"id":51567147}],"con":true,"img":false}]}
{"op":"mcm","clk":"11541064228","pt":1719501743854,"mc":[{"id":"1.230180125","rc":[{"atb":[[2.58,22.43]],"id":70902709},{"atl":[[3.8,9.21]],"id":70902709}],"con":true,"img":false}]}
{"op":"mcm","clk":"11541064243","pt":1719501744065,"mc":[{"id":"1.230180125","rc":[{"atl":[[4.8,2.8],[4.4,9.46]],"id":67245400},{"atb":[[2.6,5.83]],"id":70902709}],"con":true,"img":false}]}
{"op":"mcm","clk":"11541064252","pt":1719501744116,"mc":[{"id":"1.230180125","rc":[{"atb":[[2.24,12.08],[2.36,8.15]],"id":42767337},{"atb":[[2.46,9.76]],"id":70902709}],"con":true,"img":false}]}
{"op":"mcm","clk":"11541064265","pt":1719501744326,"mc":[{"id":"1.230180125","rc":[{"atl":[[2.26,16.02]],"id":65992794},{"atl":[[4.7,15.57]],"id":67245400},{"atl":[[3.75,5.73]],"id":70902709}],"con":true,"img":false}]}
{"op":"mcm","clk":"11541064271","pt":1719501744424,"mc":[{"id":"1.230180125","rc":[{"atl":[[2.38,3.08],[2.52,0],[2.28,28.33]],"id":65992794},{"atl":[[4.2,3.82]],"id":70902709}],"con":true,"img":false}]}
{"op":"mcm","clk":"11541064293","pt":1719501744736,"mc":[{"id":"1.230180125","rc":[{"atb":[[2.38,6.13],[2.28,0]],"id":42767337}],"con":true,"img":false}]}
{"op":"mcm","clk":"11541064298","pt":1719501744838,"mc":[{"id":"1.230180125","rc":[{"atb":[[2.38,8.13],[2.18,1.24]],"id":42767337}],"con":true,"img":false}]}
{"op":"mcm","clk":"11541064306","pt":1719501744945,"mc":[{"id":"1.230180125","rc":[{"atb":[[2.58,20.82]],"id":70902709},{"atl":[[3.8,0.84]],"id":70902709}],"con":true,"img":false}]}
{"op":"mcm","clk":"11541064314","pt":1719501745050,"mc":[{"id":"1.230180125","rc":[{"atb":[[1.48,12.73],[1.47,12.84]],"id":65992794},{"atb":[[2.58,8.01]],"id":67245400}],"con":true,"img":false}]}
{"op":"mcm","clk":"11541064328","pt":1719501745250,"mc":[{"id":"1.230180125","rc":[{"atb":[[2.58,8.15]],"id":70902709}],"con":true,"img":false}]}
{"op":"mcm","clk":"11541064335","pt":1719501745351,"mc":[{"id":"1.230180125","rc":[{"atb":[[2.6,18.5]],"id":70902709}],"con":true,"img":false}]}
{"op":"mcm","clk":"11541064344","pt":1719501745456,"mc":[{"id":"1.230180125","rc":[{"atb":[[2.32,12.26]],"id":42767337},{"atb":[[2.34,6.63]],"id":51567147},{"atb":[[2.56,13.69]],"id":70902709},{"atl":[[3.7,1]],"id":70902709}],"con":true,"img":false}]}
{"op":"mcm","clk":"11541064353","pt":1719501745561,"mc":[{"id":"1.230180125","rc":[{"atb":[[2.4,1.94]],"id":42767337},{"atb":[[2.38,1.94]],"id":51567147},{"atb":[[2.62,1.94]],"id":70902709}],"con":true,"img":false}]}
{"op":"mcm","clk":"11541064359","pt":1719501745665,"mc":[{"id":"1.230180125","rc":[{"atb":[[2.5,2.16],[2.62,7.75],[2.56,11.69]],"id":70902709}],"con":true,"img":false}]}
{"op":"mcm","clk":"11541064364","pt":1719501745720,"mc":[{"id":"1.230180125","rc":[{"atl":[[3.55,15.43],[3.5,9.34]],"id":51567147},{"atb":[[2.62,9.75]],"id":70902709},{"atl":[[3.95,0],[3.7,6.7]],"id":70902709}],"con":true,"img":false}]}
{"op":"mcm","clk":"11541064372","pt":1719501745822,"mc":[{"id":"1.230180125","rc":[{"atl":[[3.75,0]],"id":51567147}],"con":true,"img":false}]}
{"op":"mcm","clk":"11541064378","pt":1719501745941,"mc":[{"id":"1.230180125","rc":[{"atl":[[2.28,25.79]],"id":65992794},{"atl":[[3.55,12.89]],"id":51567147}],"con":true,"img":false}]}
{"op":"mcm","clk":"11541064398","pt":1719501746240,"mc":[{"id":"1.230180125","rc":[{"atb":[[1.86,0]],"id":42767337},{"atl":[[5.3,0],[3.8,0]],"id":70902709}],"con":true,"img":false}]}
{"op":"mcm","clk":"11541064408","pt":1719501746342,"mc":[{"id":"1.230180125","rc":[{"atb":[[2.22,1.57],[2.4,8.06]],"id":42767337}],"con":true,"img":false}]}
{"op":"mcm","clk":"11541064412","pt":1719501746444,"mc":[{"id":"1.230180125","rc":[{"atb":[[2.38,8.54],[2.28,2.12]],"id":51567147},{"atb":[[2.6,5.83]],"id":70902709}],"con":true,"img":false}]}
{"op":"mcm","clk":"11541064429","pt":1719501746764,"mc":[{"id":"1.230180125","rc":[{"atl":[[4.9,0.84]],"id":42767337}],"con":true,"img":false}]}
{"op":"mcm","clk":"11541064436","pt":1719501746867,"mc":[{"id":"1.230180125","rc":[{"atl":[[3.7,15.72]],"id":70902709}],"con":true,"img":false}]}
{"op":"mcm","clk":"11541064443","pt":1719501746917,"mc":[{"id":"1.230180125","rc":[{"atb":[[2.38,6.13]],"id":42767337}],"con":true,"img":false}]}
{"op":"mcm","clk":"11541064449","pt":1719501747077,"mc":[{"id":"1.230180125","rc":[{"atb":[[2.42,2]],"id":42767337}],"con":true,"img":false}]}
{"op":"mcm","clk":"11541064461","pt":1719501747235,"mc":[{"id":"1.230180125","rc":[{"atb":[[2.3,17.74]],"id":51567147}],"con":true,"img":false}]}
{"op":"mcm","clk":"11541064469","pt":1719501747330,"mc":[{"id":"1.230180125","rc":[{"atl":[[3.45,0.84]],"id":51567147}],"con":true,"img":false}]}
{"op":"mcm","clk":"11541064486","pt":1719501747637,"mc":[{"id":"1.230180125","rc":[{"atb":[[2.3,13.74]],"id":51567147}],"con":true,"img":false}]}
{"op":"mcm","clk":"11541064502","pt":1719501747847,"mc":[{"id":"1.230180125","rc":[{"atl":[[2.24,2.54]],"id":65992794},{"atl":[[3.45,3.38]],"id":51567147}],"con":true,"img":false}]}
{"op":"mcm","clk":"11541064510","pt":1719501747950,"mc":[{"id":"1.230180125","rc":[{"atl":[[2.22,3.73]],"id":65992794},{"atb":[[2.62,23.77]],"id":70902709}],"con":true,"img":false}]}
{"op":"mcm","clk":"11541064536","pt":1719501748260,"mc":[{"id":"1.230180125","rc":[{"atl":[[2.28,24.95]],"id":65992794}],"con":true,"img":false}]}
{"op":"mcm","clk":"11541064555","pt":1719501748423,"mc":[{"id":"1.230180125","rc":[{"atl":[[2.22,16.55],[2.34,19.19],[2.24,28.19],[2.4,0]],"id":65992794},{"atl":[[4.9,6.86],[5.6,1.98]],"id":42767337},{"atl":[[3.65,5.71]],"id":70902709}],"con":true,"img":false}]}
{"op":"mcm","clk":"11541064565","pt":1719501748523,"mc":[{"id":"1.230180125","rc":[{"atl":[[4.8,2.8]],"id":42767337},{"atl":[[3.9,2.25]],"id":70902709}],"con":true,"img":false}]}
{"op":"mcm","clk":"11541064573","pt":1719501748625,"mc":[{"id":"1.230180125","rc":[{"atl":[[3.7,14.72]],"id":70902709}],"con":true,"img":false}]}
{"op":"mcm","clk":"11541064586","pt":1719501748832,"mc":[{"id":"1.230180125","rc":[{"atl":[[3.45,6.39]],"id":51567147}],"con":true,"img":false}]}
{"op":"mcm","clk":"11541064593","pt":1719501748934,"mc":[{"id":"1.230180125","rc":[{"atb":[[2.42,8.13]],"id":42767337}],"con":true,"img":false}]}
{"op":"mcm","clk":"11541064600","pt":1719501749045,"mc":[{"id":"1.230180125","rc":[{"atb":[[1.46,12.94]],"id":65992794},{"atb":[[2.26,1.81]],"id":42767337},{"atb":[[2.54,2.29],[2.64,5.82]],"id":70902709}],"con":true,"img":false}]}
{"op":"mcm","clk":"11541064619","pt":1719501749250,"mc":[{"id":"1.230180125","rc":[{"atl":[[2.24,25.65]],"id":65992794},{"atb":[[2.44,8.07]],"id":42767337}],"con":true,"img":false}]}
{"op":"mcm","clk":"11541064629","pt":1719501749360,"mc":[{"id":"1.230180125","rc":[{"atb":[[2.36,0]],"id":42767337},{"atb":[[2.62,22.51]],"id":70902709},{"atl":[[3.7,13.95]],"id":70902709}],"con":true,"img":false}]}
{"op":"mcm","clk":"11541064638","pt":1719501749457,"mc":[{"id":"1.230180125","rc":[{"atb":[[1.47,17.09]],"id":65992794}],"con":true,"img":false}]}
{"op":"mcm","clk":"11541064644","pt":1719501749563,"mc":[{"id":"1.230180125","rc":[{"atb":[[1.47,12.84]],"id":65992794},{"atb":[[2.62,9.75]],"id":70902709},{"atl":[[3.7,5.7]],"id":70902709}],"con":true,"img":false}]}
{"op":"mcm","clk":"11541064655","pt":1719501749668,"mc":[{"id":"1.230180125","rc":[{"atb":[[2.64,18.58]],"id":70902709},{"atl":[[3.65,13.96]],"id":70902709}],"con":true,"img":false}]}
{"op":"mcm","clk":"11541064664","pt":1719501749769,"mc":[{"id":"1.230180125","rc":[{"atl":[[4.4,0]],"id":51567147}],"con":true,"img":false}]}
{"op":"mcm","clk":"11541064671","pt":1719501749867,"mc":[{"id":"1.230180125","rc":[{"atl":[[4.8,8.82],[5.4,2.15]],"id":42767337},{"atb":[[2.4,2.98]],"id":51567147},{"atl":[[3.7,2.54],[3.4,6.31]],"id":51567147},{"atb":[[2.58,2.31],[2.66,8.05]],"id":70902709}],"con":true,"img":false}]}
{"op":"mcm","clk":"11541064676","pt":1719501749921,"mc":[{"id":"1.230180125","rc":[{"atb":[[1.49,2]],"id":65992794}],"con":true,"img":false}]}
{"op":"mcm","clk":"11541064685","pt":1719501750134,"mc":[{"id":"1.230180125","rc":[{"atb":[[2.32,2.29],[2.4,9.42]],"id":51567147},{"atl":[[3.6,5.61],[3.85,0]],"id":70902709}],"con":true,"img":false}]}
{"op":"mcm","clk":"11541064692","pt":1719501750231,"mc":[{"id":"1.230180125","rc":[{"atb":[[2.46,6.14]],"id":42767337},{"atb":[[2.64,5.82]],"id":70902709}],"con":true,"img":false}]}
{"op":"mcm","clk":"11541064704","pt":1719501750334,"mc":[{"id":"1.230180125","rc":[{"atl":[[4.7,5.89]],"id":67245400},{"atb":[[2.34,2.02]],"id":42767337}],"con":true,"img":false}]}
{"op":"mcm","clk":"11541064716","pt":1719501750539,"mc":[{"id":"1.230180125","rc":[{"atl":[[4.6,15.15]],"id":67245400}],"con":true,"img":false}]}
{"op":"mcm","clk":"11541064727","pt":1719501750643,"mc":[{"id":"1.230180125","rc":[{"atl":[[3.55,1]],"id":70902709}],"con":true,"img":false}]}
{"op":"mcm","clk":"11541064738","pt":1719501750747,"mc":[{"id":"1.230180125","rc":[{"atl":[[2.2,0.85]],"id":65992794},{"atl":[[4.3,0.84]],"id":67245400},{"atl":[[3.55,1.84]],"id":70902709}],"con":true,"img":false}]}
{"op":"mcm","clk":"11541064746","pt":1719501750848,"mc":[{"id":"1.230180125","rc":[{"atb":[[2.42,6.13]],"id":42767337}],"con":true,"img":false}]}
{"op":"mcm","clk":"11541064754","pt":1719501750958,"mc":[{"id":"1.230180125","rc":[{"atl":[[2.32,0],[2.2,13.94]],"id":65992794},{"atb":[[2.48,2]],"id":42767337},{"atb":[[2.4,25.12]],"id":51567147},{"atl":[[3.4,15.69]],"id":51567147}],"con":true,"img":false}]}
{"op":"mcm","clk":"11541064761","pt":1719501751058,"mc":[{"id":"1.230180125","rc":[{"atl":[[2.18,3.93]],"id":65992794}],"con":true,"img":false}]}
{"op":"mcm","clk":"11541064771","pt":1719501751163,"mc":[{"id":"1.230180125","rc":[{"atb":[[2.62,7.75]],"id":70902709}],"con":true,"img":false}]}
{"op":"mcm","clk":"11541064781","pt":1719501751270,"mc":[{"id":"1.230180125","rc":[{"atb":[[2.68,2]],"id":70902709},{"atl":[[3.65,5.71]],"id":70902709}],"con":true,"img":false}]}
{"op":"mcm","clk":"11541064791","pt":1719501751379,"mc":[{"id":"1.230180125","rc":[{"atl":[[2.3,3.38],[2.18,17.12]],"id":65992794},{"atb":[[2.48,8.13],[2.38,0]],"id":42767337},{"atb":[[2.34,0],[2.42,6.41]],"id":51567147},{"atl":[[3.4,18.8]],"id":51567147}],"con":true,"img":false}]}
{"op":"mcm","clk":"11541064802","pt":1719501751468,"mc":[{"id":"1.230180125","rc":[{"atl":[[4.7,0]],"id":67245400},{"atl":[[3.35,6.28],[3.65,0]],"id":51567147},{"atl":[[3.55,7.5],[3.75,0]],"id":70902709}],"con":true,"img":false}]}
{"op":"mcm","clk":"11541064813","pt":1719501751573,"mc":[{"id":"1.230180125","rc":[{"atb":[[1.44,0]],"id":65992794},{"atl":[[4.3,6.9]],"id":67245400},{"atb":[[2.4,6.12]],"id":42767337},{"atb":[[2.38,6.6]],"id":51567147},{"atb":[[2.6,0],[2.62,5.81],[2.68,7.76]],"id":70902709}],"con":true,"img":false}]}
{"op":"mcm","clk":"11541064824","pt":1719501751633,"mc":[{"id":"1.230180125","rc":[{"atl":[[2.18,19.66]],"id":65992794},{"atl":[[4.2,3.82]],"id":67245400},{"atb":[[2.48,10.08]],"id":42767337},{"atb":[[2.42,8.36]],"id":51567147},{"atb":[[2.66,23.24],[2.68,9.71]],"id":70902709},{"atl":[[3.5,2.54]],"id":70902709}],"con":true,"img":false}]}
{"op":"mcm","clk":"11541064830","pt":1719501751731,"mc":[{"id":"1.230180125","rc":[{"atb":[[2.4,9.42]],"id":51567147},{"atl":[[3.45,3.85],[3.4,9.42]],"id":51567147},{"atb":[[2.66,21.35]],"id":70902709}],"con":true,"img":false}]}
{"op":"mcm","clk":"11541064842","pt":1719501751846,"mc":[{"id":"1.230180125","rc":[{"atb":[[1.42,0]],"id":65992794},{"atl":[[3.45,3.01]],"id":51567147},{"atl":[[3.55,6.5]],"id":70902709}],"con":true,"img":false}]}
{"op":"mcm","clk":"11541064849","pt":1719501751946,"mc":[{"id":"1.230180125","rc":[{"atl":[[4.6,9]],"id":67245400},{"atl":[[3.55,14.35]],"id":70902709}],"con":true,"img":false}]}
{"op":"mcm","clk":"11541064868","pt":1719501752155,"mc":[{"id":"1.230180125","rc":[{"atl":[[2.26,3.55],[2.16,13.17]],"id":65992794},{"atl":[[4.4,13.51]],"id":67245400},{"atl":[[5,8.52]],"id":42767337}],"con":true,"img":false}]}
{"op":"mcm","clk":"11541064876","pt":1719501752259,"mc":[{"id":"1.230180125","rc":[{"atl":[[2.14,4.13]],"id":65992794},{"atl":[[4.5,6.02]],"id":67245400},{"atb":[[2.66,8.05]],"id":70902709}],"con":true,"img":false}]}
{"op":"mcm","clk":"11541064885","pt":1719501752356,"mc":[{"id":"1.230180125","rc":[{"atb":[[2.68,23.01]],"id":70902709}],"con":true,"img":false}]}
{"op":"mcm","clk":"11541064905","pt":1719501752559,"mc":[{"id":"1.230180125","rc":[{"atl":[[4.9,18.61]],"id":42767337},{"atl":[[3.55,6.5]],"id":70902709}],"con":true,"img":false}]}
{"op":"mcm","clk":"11541064917","pt":1719501752661,"mc":[{"id":"1.230180125","rc":[{"atb":[[2.42,23.54]],"id":51567147},{"atl":[[3.35,16.51]],"id":51567147}],"con":true,"img":false}]}
{"op":"mcm","clk":"11541064934","pt":1719501752868,"mc":[{"id":"1.230180125","rc":[{"atl":[[2.2,13.08]],"id":65992794}],"con":true,"img":false}]}
{"op":"mcm","clk":"11541064951","pt":1719501753028,"mc":[{"id":"1.230180125","rc":[{"atl":[[4.9,6.86]],"id":42767337}],"con":true,"img":false}]}
{"op":"mcm","clk":"11541064975","pt":1719501753334,"mc":[{"id":"1.230180125","rc":[{"atl":[[4.8,10.77]],"id":42767337}],"con":true,"img":false}]}
{"op":"mcm","clk":"11541064980","pt":1719501753439,"mc":[{"id":"1.230180125","rc":[{"atl":[[3.5,12.32]],"id":70902709}],"con":true,"img":false}]}
{"op":"mcm","clk":"11541065008","pt":1719501753753,"mc":[{"id":"1.230180125","rc":[{"atl":[[4.7,0.84]],"id":42767337}],"con":true,"img":false}]}
{"op":"mcm","clk":"11541065014","pt":1719501753850,"mc":[{"id":"1.230180125","rc":[{"atl":[[4.8,8.82]],"id":42767337},{"atl":[[3.45,1]],"id":70902709}],"con":true,"img":false}]}
{"op":"mcm","clk":"11541065039","pt":1719501754166,"mc":[{"id":"1.230180125","rc":[{"atl":[[4.9,18.48]],"id":42767337}],"con":true,"img":false}]}
{"op":"mcm","clk":"11541065058","pt":1719501754371,"mc":[{"id":"1.230180125","rc":[{"atb":[[2.5,8.07],[2.44,0]],"id":42767337}],"con":true,"img":false}]}
{"op":"mcm","clk":"11541065083","pt":1719501754573,"mc":[{"id":"1.230180125","rc":[{"atl":[[2.18,17.12]],"id":65992794},{"atl":[[3.3,2.54]],"id":51567147}],"con":true,"img":false}]}
{"op":"mcm","clk":"11541065098","pt":1719501754629,"mc":[{"id":"1.230180125","rc":[{"atb":[[2.48,8.13]],"id":42767337}],"con":true,"img":false}]}
{"op":"mcm","clk":"11541065109","pt":1719501754731,"mc":[{"id":"1.230180125","rc":[{"atl":[[3.3,3.38]],"id":51567147}],"con":true,"img":false}]}
{"op":"mcm","clk":"11541065132","pt":1719501755043,"mc":[{"id":"1.230180125","rc":[{"atb":[[1.49,15.58]],"id":65992794},{"atl":[[4.6,3.09],[4.2,10.02]],"id":67245400},{"atb":[[2.4,0]],"id":42767337},{"atb":[[2.44,6.3],[2.36,2.57]],"id":51567147},{"atl":[[3.35,6.28]],"id":51567147},{"atb":[[2.62,0],[2.7,5.67]],"id":70902709}],"con":true,"img":false}]}
{"op":"mcm","clk":"11541065142","pt":1719501755147,"mc":[{"id":"1.230180125","rc":[{"atb":[[1.34,0]],"id":65992794},{"atb":[[2.52,6.21]],"id":42767337}],"con":true,"img":false}]}
{"op":"mcm","clk":"11541065151","pt":1719501755243,"mc":[{"id":"1.230180125","rc":[{"atb":[[2.48,6.13]],"id":42767337}],"con":true,"img":false}]}
{"op":"mcm","clk":"11541065159","pt":1719501755346,"mc":[{"id":"1.230180125","rc":[{"atb":[[2.52,8.21]],"id":42767337}],"con":true,"img":false}]}
{"op":"mcm","clk":"11541065172","pt":1719501755555,"mc":[{"id":"1.230180125","rc":[{"atb":[[2.44,3.6]],"id":42767337}],"con":true,"img":false}]}
{"op":"mcm","clk":"11541065180","pt":1719501755670,"mc":[{"id":"1.230180125","rc":[{"atb":[[1.48,0],[1.49,2]],"id":65992794},{"atl":[[2.22,3.73],[2.14,17.51]],"id":65992794}],"con":true,"img":false}]}
{"op":"mcm","clk":"11541065189","pt":1719501755763,"mc":[{"id":"1.230180125","rc":[{"atb":[[2.44,0]],"id":42767337},{"atl":[[5.3,0],[4.7,6.93]],"id":42767337},{"atb":[[2.46,2.81]],"id":51567147},{"atl":[[3.6,2.71],[3.3,9.53]],"id":51567147},{"atb":[[2.72,2.16]],"id":70902709}],"con":true,"img":false}]}
{"op":"mcm","clk":"11541065197","pt":1719501755878,"mc":[{"id":"1.230180125","rc":[{"atl":[[4.6,3.09]],"id":42767337},{"atb":[[2.42,8.36]],"id":51567147},{"atb":[[2.68,21.73]],"id":70902709}],"con":true,"img":false}]}
{"op":"mcm","clk":"11541065212","pt":1719501756064,"mc":[{"id":"1.230180125","rc":[{"atl":[[3.3,19.32]],"id":51567147}],"con":true,"img":false}]}
{"op":"mcm","clk":"11541065221","pt":1719501756166,"mc":[{"id":"1.230180125","rc":[{"atb":[[2.68,9.71]],"id":70902709}],"con":true,"img":false}]}
{"op":"mcm","clk":"11541065229","pt":1719501756277,"mc":[{"id":"1.230180125","rc":[{"atl":[[4.9,17.63]],"id":42767337},{"atb":[[2.56,17.62],[2.7,17.69]],"id":70902709},{"atl":[[3.7,9.02]],"id":70902709}],"con":true,"img":false}]}
{"op":"mcm","clk":"11541065239","pt":1719501756372,"mc":[{"id":"1.230180125","rc":[{"atb":[[1.49,0]],"id":65992794}],"con":true,"img":false}]}
{"op":"mcm","clk":"11541065248","pt":1719501756429,"mc":[{"id":"1.230180125","rc":[{"atb":[[1.48,2]],"id":65992794}],"con":true,"img":false}]}
{"op":"mcm","clk":"11541065255","pt":1719501756529,"mc":[{"id":"1.230180125","rc":[{"atl":[[4.6,9.18],[5,2.56]],"id":42767337},{"atb":[[2.38,0],[2.46,9.02]],"id":51567147},{"atb":[[2.7,5.67]],"id":70902709},{"atl":[[3.7,5.7]],"id":70902709}],"con":true,"img":false}]}
{"op":"mcm","clk":"11541065279","pt":1719501756839,"mc":[{"id":"1.230180125","rc":[{"atl":[[2.12,2.54]],"id":65992794},{"atb":[[2.46,23.94]],"id":51567147},{"atl":[[3.25,6.11],[3.5,2.9]],"id":51567147},{"atb":[[2.68,7.71]],"id":70902709},{"atl":[[3.5,9.78]],"id":70902709}],"con":true,"img":false}]}
{"op":"mcm","clk":"11541065283","pt":1719501756940,"mc":[{"id":"1.230180125","rc":[{"atl":[[2.1,4.38]],"id":65992794},{"atb":[[2.74,2]],"id":70902709}],"con":true,"img":false}]}
{"op":"mcm","clk":"11541065288","pt":1719501757050,"mc":[{"id":"1.230180125","rc":[{"atb":[[2.76,2.08],[2.56,11.69]],"id":70902709}],"con":true,"img":false}]}
{"op":"mcm","clk":"11541065297","pt":1719501757150,"mc":[{"id":"1.230180125","rc":[{"atl":[[2.12,28.86],[2.1,17.82],[2.36,0],[2.2,0]],"id":65992794},{"atb":[[2.48,6.2],[2.4,2.98]],"id":51567147},{"atb":[[2.72,13.47],[2.64,0],[2.74,7.65]],"id":70902709}],"con":true,"img":false}]}
{"op":"mcm","clk":"11541065304","pt":1719501757249,"mc":[{"id":"1.230180125","rc":[{"atb":[[2.5,2.69]],"id":51567147},{"atb":[[2.48,0]],"id":70902709}],"con":true,"img":false}]}
{"op":"mcm","clk":"11541065320","pt":1719501757455,"mc":[{"id":"1.230180125","rc":[{"atb":[[2.46,9.02]],"id":51567147},{"atl":[[3.3,18.97]],"id":51567147}],"con":true,"img":false}]}
{"op":"mcm","clk":"11541065335","pt":1719501757661,"mc":[{"id":"1.230180125","rc":[{"atb":[[2.42,6.41]],"id":51567147},{"atb":[[2.68,5.76]],"id":70902709}],"con":true,"img":false}]}
{"op":"mcm","clk":"11541065341","pt":1719501757764,"mc":[{"id":"1.230180125","rc":[{"atl":[[2.08,0.84]],"id":65992794},{"atl":[[4.1,0.84]],"id":67245400}],"con":true,"img":false}]}
{"op":"mcm","clk":"11541065348","pt":1719501757864,"mc":[{"id":"1.230180125","rc":[{"atb":[[2.54,1.94]],"id":42767337},{"atb":[[2.52,1.94]],"id":51567147},{"atb":[[2.74,5.65],[2.78,1.94]],"id":70902709}],"con":true,"img":false}]}
{"op":"mcm","clk":"11541065352","pt":1719501757969,"mc":[{"id":"1.230180125","rc":[{"atb":[[2.54,2.58]],"id":51567147},{"atl":[[3.3,9.53]],"id":51567147},{"atb":[[2.8,2],[2.78,3.94]],"id":70902709}],"con":true,"img":false}]}
{"op":"mcm","clk":"11541065355","pt":1719501758071,"mc":[{"id":"1.230180125","rc":[{"atl":[[3.25,15.55],[3.3,6.99]],"id":51567147}],"con":true,"img":false}]}
{"op":"mcm","clk":"11541065363","pt":1719501758177,"mc":[{"id":"1.230180125","rc":[{"atb":[[2.76,14.76]],"id":70902709}],"con":true,"img":false}]}
{"op":"mcm","clk":"11541065403","pt":1719501758636,"mc":[{"id":"1.230180125","rc":[{"atb":[[2.78,1.94]],"id":70902709}],"con":true,"img":false}]}
{"op":"mcm","clk":"11541065411","pt":1719501758738,"mc":[{"id":"1.230180125","rc":[{"atb":[[2.82,2]],"id":70902709}],"con":true,"img":false}]}
{"op":"mcm","clk":"11541065418","pt":1719501758844,"mc":[{"id":"1.230180125","rc":[{"atb":[[1.48,15.78]],"id":65992794},{"atl":[[2.08,14.35],[2.18,3.93]],"id":65992794},{"atl":[[4.5,0],[4.1,7.08]],"id":67245400},{"atb":[[2.54,8.13],[2.42,0]],"id":42767337},{"atb":[[2.54,8.75],[2.22,0],[2.42,0],[2.52,14.3]],"id":51567147},{"atl":[[3.2,6.11],[3.4,3.1]],"id":51567147},{"atb":[[2.52,0],[2.66,2.29],[2.78,13.25],[2.8,7.65],[2.84,1.93]],"id":70902709}],"con":true,"img":false}]}
{"op":"mcm","clk":"11541065426","pt":1719501758946,"mc":[{"id":"1.230180125","rc":[{"atl":[[2.06,4.63]],"id":65992794},{"atl":[[4,2.11]],"id":67245400}],"con":true,"img":false}]}
{"op":"mcm","clk":"11541065432","pt":1719501759054,"mc":[{"id":"1.230180125","rc":[{"atb":[[2.76,13.95]],"id":70902709}],"con":true,"img":false}]}
{"op":"mcm","clk":"11541065440","pt":1719501759161,"mc":[{"id":"1.230180125","rc":[{"atl":[[2.12,26.31]],"id":65992794},{"atb":[[2.5,18.9]],"id":51567147},{"atb":[[2.68,0],[2.82,13.3],[2.84,7.57],[2.56,0]],"id":70902709}],"con":true,"img":false}]}
{"op":"mcm","clk":"11541065451","pt":1719501759260,"mc":[{"id":"1.230180125","rc":[{"atl":[[4.3,6.05]],"id":67245400},{"atl":[[3.3,6.14]],"id":51567147}],"con":true,"img":false}]}
{"op":"mcm","clk":"11541065461","pt":1719501759370,"mc":[{"id":"1.230180125","rc":[{"atb":[[2.76,2.08]],"id":70902709}],"con":true,"img":false}]}
{"op":"mcm","clk":"11541065471","pt":1719501759468,"mc":[{"id":"1.230180125","rc":[{"atb":[[2.5,0],[2.56,8.13]],"id":42767337},{"atb":[[2.82,25.17]],"id":70902709}],"con":true,"img":false}]}
{"op":"mcm","clk":"11541065499","pt":1719501759775,"mc":[{"id":"1.230180125","rc":[{"atb":[[2.52,6.21]],"id":42767337}],"con":true,"img":false}]}
{"op":"mcm","clk":"11541065509","pt":1719501759879,"mc":[{"id":"1.230180125","rc":[{"atb":[[1.48,2],[1.47,0]],"id":65992794},{"atl":[[2.06,18.46],[2.16,0]],"id":65992794},{"atb":[[2.54,5.83]],"id":67245400},{"atb":[[2.58,6.15],[2.56,10.13],[2.46,0]],"id":42767337},{"atl":[[3.4,0]],"id":51567147}],"con":true,"img":false}]}
{"op":"mcm","clk":"11541065517","pt":1719501759980,"mc":[{"id":"1.230180125","rc":[{"atl":[[4.4,3.42],[4,8.31]],"id":67245400},{"atb":[[2.6,8.13],[2.56,2]],"id":42767337},{"atl":[[4.9,6.01]],"id":42767337}],"con":true,"img":false}]}
{"op":"mcm","clk":"11541065525","pt":1719501760084,"mc":[{"id":"1.230180125","rc":[{"atl":[[3.25,6.11]],"id":51567147},{"atb":[[2.82,11.3]],"id":70902709}],"con":true,"img":false}]}
{"op":"mcm","clk":"11541065534","pt":1719501760145,"mc":[{"id":"1.230180125","rc":[{"atl":[[4.9,11.73]],"id":42767337},{"atb":[[2.86,2]],"id":70902709}],"con":true,"img":false}]}
{"op":"mcm","clk":"11541065556","pt":1719501760346,"mc":[{"id":"1.230180125","rc":[{"atb":[[2.62,6.15],[2.48,0]],"id":42767337},{"atb":[[2.88,1.86],[2.7,0],[2.86,7.61]],"id":70902709}],"con":true,"img":false}]}
{"op":"mcm","clk":"11541065568","pt":1719501760446,"mc":[{"id":"1.230180125","rc":[{"atb":[[2.6,0],[2.64,6.16]],"id":42767337},{"atl":[[4.9,6.01]],"id":42767337}],"con":true,"img":false}]}
{"op":"mcm","clk":"11541065576","pt":1719501760548,"mc":[{"id":"1.230180125","rc":[{"atb":[[1.48,9.89]],"id":65992794},{"atl":[[2.06,26.35]],"id":65992794},{"atb":[[2.58,15.91]],"id":67245400},{"atl":[[4,16.21]],"id":67245400},{"atb":[[2.54,6.18],[2.58,14.05]],"id":42767337},{"atl":[[4.6,17.08]],"id":42767337},{"atb":[[2.52,12.35]],"id":51567147},{"atb":[[2.84,15.47],[2.78,11.3]],"id":70902709}],"con":true,"img":false}]}
{"op":"mcm","clk":"11541065581","pt":1719501760656,"mc":[{"id":"1.230180125","rc":[{"atb":[[2.54,16.65]],"id":51567147}],"con":true,"img":false}]}
{"op":"mcm","clk":"11541065591","pt":1719501760755,"mc":[{"id":"1.230180125","rc":[{"atl":[[2.08,13.5]],"id":65992794},{"atl":[[4.4,8.83]],"id":67245400},{"atb":[[2.64,8.1]],"id":42767337},{"atl":[[4.9,8.63],[4.5,0.84]],"id":42767337},{"atb":[[2.56,1.94]],"id":51567147},{"atl":[[3.2,16.86]],"id":51567147},{"atb":[[2.88,17.25]],"id":70902709}],"con":true,"img":false}]}
{"op":"mcm","clk":"11541065599","pt":1719501760861,"mc":[{"id":"1.230180125","rc":[{"atb":[[2.58,2.48]],"id":51567147}],"con":true,"img":false}]}
{"op":"mcm","clk":"11541065612","pt":1719501761067,"mc":[{"id":"1.230180125","rc":[{"atb":[[2.12,0],[2.52,18.09]],"id":42767337},{"atb":[[2.12,0]],"id":51567147}],"con":true,"img":false}]}
{"op":"mcm","clk":"11541065644","pt":1719501761481,"mc":[{"id":"1.230180125","rc":[{"atl":[[2.04,2.54]],"id":65992794},{"atb":[[2.56,0]],"id":42767337}],"con":true,"img":false}]}
{"op":"mcm","clk":"11541065654","pt":1719501761543,"mc":[{"id":"1.230180125","rc":[{"atl":[[2.02,4.91]],"id":65992794},{"atb":[[2.66,2]],"id":42767337}],"con":true,"img":false}]}
{"op":"mcm","clk":"11541065662","pt":1719501761632,"mc":[{"id":"1.230180125","rc":[{"atb":[[2.58,6.15],[2.52,6.21]],"id":42767337},{"atl":[[4.6,9.18]],"id":42767337},{"atb":[[2.54,8.75]],"id":51567147},{"atb":[[2.84,7.57]],"id":70902709}],"con":true,"img":false}]}
{"op":"mcm","clk":"11541065670","pt":1719501761742,"mc":[{"id":"1.230180125","rc":[{"atb":[[2.64,16]],"id":42767337},{"atl":[[4.5,8.74]],"id":42767337},{"atb":[[2.58,10.37]],"id":51567147},{"atl":[[3.15,0.84]],"id":51567147},{"atb":[[2.88,25.15]],"id":70902709}],"con":true,"img":false}]}
{"op":"mcm","clk":"11541065675","pt":1719501761838,"mc":[{"id":"1.230180125","rc":[{"atl":[[4.4,3.42]],"id":42767337}],"con":true,"img":false}]}
{"op":"mcm","clk":"11541065679","pt":1719501761946,"mc":[{"id":"1.230180125","rc":[{"atb":[[2.86,5.61]],"id":70902709}],"con":true,"img":false}]}
{"op":"mcm","clk":"11541065690","pt":1719501762046,"mc":[{"id":"1.230180125","rc":[{"atb":[[2.48,10.86]],"id":51567147},{"atb":[[2.9,2]],"id":70902709}],"con":true,"img":false}]}
{"op":"mcm","clk":"11541065700","pt":1719501762157,"mc":[{"id":"1.230180125","rc":[{"atb":[[2.48,6.2]],"id":51567147},{"atb":[[2.92,1.8]],"id":70902709},{"atl":[[3.45,0]],"id":70902709}],"con":true,"img":false}]}
{"op":"mcm","clk":"11541065706","pt":1719501762249,"mc":[{"id":"1.230180125","rc":[{"atl":[[4.7,6.08]],"id":42767337}],"con":true,"img":false}]}
{"op":"mcm","clk":"11541065715","pt":1719501762356,"mc":[{"id":"1.230180125","rc":[{"atl":[[1.93,11.99]],"id":65992794},{"atb":[[2.88,24.92]],"id":70902709}],"con":true,"img":false}]}
{"op":"mcm","clk":"11541065721","pt":1719501762456,"mc":[{"id":"1.230180125","rc":[{"atl":[[1.92,2.85]],"id":65992794}],"con":true,"img":false}]}
{"op":"mcm","clk":"11541065737","pt":1719501762661,"mc":[{"id":"1.230180125","rc":[{"atl":[[2.06,18.46]],"id":65992794},{"atb":[[2.64,8.1]],"id":42767337},{"atl":[[4.5,0.84]],"id":42767337},{"atl":[[3.45,0.84]],"id":70902709}],"con":true,"img":false}]}
{"op":"mcm","clk":"11541065744","pt":1719501762764,"mc":[{"id":"1.230180125","rc":[{"atb":[[1.44,4.75]],"id":65992794},{"atl":[[2.04,0],[1.93,38.3],[2.14,4.13],[1.92,16.57],[2.02,12.8],[2.28,0]],"id":65992794},{"atl":[[4.3,0],[3.95,6.26]],"id":67245400},{"atb":[[2.66,9.89]],"id":42767337},{"atl":[[5.8,0],[4.9,2.62],[4.4,17.4],[4.5,13.01]],"id":42767337},{"atb":[[2.44,0],[2.6,6.12],[2.26,0],[2.56,14.2]],"id":51567147},{"atb":[[2.88,11.7]],"id":70902709}],"con":true,"img":false}]}
{"op":"mcm","clk":"11541065747","pt":1719501762864,"mc":[{"id":"1.230180125","rc":[{"atb":[[1.44,0]],"id":65992794},{"atl":[[3.9,2.25]],"id":67245400},{"atb":[[2.62,2.38]],"id":51567147},{"atb":[[2.92,15.02]],"id":70902709}],"con":true,"img":false}]}
{"op":"mcm","clk":"11541065774","pt":1719501763283,"mc":[{"id":"1.230180125","rc":[{"atl":[[4.1,6.23]],"id":67245400}],"con":true,"img":false}]}
{"op":"mcm","clk":"11541065791","pt":1719501763433,"mc":[{"id":"1.230180125","rc":[{"atl":[[1.93,26.31]],"id":65992794},{"atl":[[3.9,8.52],[4.2,3.82]],"id":67245400},{"atl":[[4.8,2.8],[4.3,6.09]],"id":42767337},{"atb":[[2.62,8.48],[2.46,2.81]],"id":51567147},{"atb":[[2.9,0]],"id":70902709}],"con":true,"img":false}]}
{"op":"mcm","clk":"11541065801","pt":1719501763538,"mc":[{"id":"1.230180125","rc":[{"atl":[[4,8.31]],"id":67245400},{"atb":[[2.64,6.16]],"id":42767337},{"atl":[[4.2,3.82]],"id":42767337},{"atb":[[2.56,12.25]],"id":51567147},{"atb":[[2.94,2],[2.88,1.86]],"id":70902709}],"con":true,"img":false}]}
{"op":"mcm","clk":"11541065809","pt":1719501763639,"mc":[{"id":"1.230180125","rc":[{"atl":[[2.1,25.66],[2.02,4.91]],"id":65992794},{"atl":[[3.9,16.42]],"id":67245400},{"atb":[[2.58,2.48]],"id":51567147},{"atb":[[2.96,1.74],[2.92,22.91]],"id":70902709}],"con":true,"img":false}]}
{"op":"mcm","clk":"11541065814","pt":1719501763739,"mc":[{"id":"1.230180125","rc":[{"atl":[[1.92,24.46]],"id":65992794},{"atb":[[2.6,6.36],[2.46,1]],"id":67245400},{"atb":[[2.64,18.51],[2.52,0],[2.2,0],[2.68,6.17]],"id":42767337},{"atb":[[2.64,1.94],[2.62,16.38]],"id":51567147},{"atb":[[2.94,7.63],[2.74,0],[2.72,2.16],[2.92,34.18]],"id":70902709}],"con":true,"img":false}]}
{"op":"mcm","clk":"11541065819","pt":1719501763842,"mc":[{"id":"1.230180125","rc":[{"atb":[[2.58,13.87],[2.62,11.96]],"id":67245400},{"atl":[[4.5,12.17]],"id":42767337},{"atb":[[2.66,2.29]],"id":51567147}],"con":true,"img":false}]}
{"op":"mcm","clk":"11541065823","pt":1719501763945,"mc":[{"id":"1.230180125","rc":[{"atl":[[1.89,6.34]],"id":65992794},{"atb":[[2.92,33.02]],"id":70902709}],"con":true,"img":false}]}
{"op":"mcm","clk":"11541065830","pt":1719501764048,"mc":[{"id":"1.230180125","rc":[{"atl":[[2.1,17.82],[1.88,3.04]],"id":65992794},{"atl":[[3.85,6.28],[4.1,0],[3.9,23.54]],"id":67245400},{"atb":[[2.68,19.15]],"id":42767337},{"atl":[[4.2,17.42],[4.7,0]],"id":42767337}],"con":true,"img":false}]}
{"op":"mcm","clk":"11541065836","pt":1719501764156,"mc":[{"id":"1.230180125","rc":[{"atl":[[1.89,0],[2.1,4.38],[2.24,0],[1.88,17.03],[1.91,26.31]],"id":65992794},{"atb":[[2.5,1],[2.64,6.35]],"id":67245400},{"atl":[[3.8,2.39]],"id":67245400},{"atb":[[2.3,0],[2.64,14.03],[2.48,0],[2.66,8.33]],"id":51567147},{"atb":[[2.96,7.36],[2.8,2],[2.92,20.96]],"id":70902709}],"con":true,"img":false}]}
{"op":"mcm","clk":"11541065843","pt":1719501764254,"mc":[{"id":"1.230180125","rc":[{"atl":[[4.6,3.09],[4.1,6.09]],"id":42767337},{"atb":[[2.94,19.69]],"id":70902709}],"con":true,"img":false}]}
{"op":"mcm","clk":"11541065848","pt":1719501764355,"mc":[{"id":"1.230180125","rc":[{"atl":[[3.8,8.66],[4,2.11]],"id":67245400},{"atl":[[4,2.11]],"id":42767337}],"con":true,"img":false}]}
{"op":"mcm","clk":"11541065861","pt":1719501764560,"mc":[{"id":"1.230180125","rc":[{"atl":[[1.89,3.4]],"id":65992794},{"atb":[[2.58,5.97]],"id":67245400},{"atb":[[2.66,2]],"id":42767337},{"atl":[[4.4,9.5],[4,8.2]],"id":42767337},{"atb":[[2.62,8.48]],"id":51567147},{"atb":[[2.92,13.06]],"id":70902709}],"con":true,"img":false}]}
{"op":"mcm","clk":"11541065867","pt":1719501764662,"mc":[{"id":"1.230180125","rc":[{"atb":[[1.32,0],[1.39,52.21]],"id":65992794},{"atb":[[2.62,19.85]],"id":67245400},{"atb":[[2.68,27.05]],"id":42767337},{"atl":[[4.4,3.42],[4.2,25.31]],"id":42767337},{"atb":[[2.66,16.22]],"id":51567147},{"atb":[[2.96,15.25]],"id":70902709}],"con":true,"img":false}]}
{"op":"mcm","clk":"11541065875","pt":1719501764770,"mc":[{"id":"1.230180125","rc":[{"atl":[[1.87,0.85]],"id":65992794},{"atl":[[3.75,0.84]],"id":67245400}],"con":true,"img":false}]}
{"op":"mcm","clk":"11541065897","pt":1719501765077,"mc":[{"id":"1.230180125","rc":[{"atl":[[1.88,19.57]],"id":65992794},{"atl":[[3.9,16.42]],"id":67245400},{"atb":[[2.66,0]],"id":42767337},{"atl":[[4.2,25.17]],"id":42767337}],"con":true,"img":false}]}
{"op":"mcm","clk":"11541065906","pt":1719501765185,"mc":[{"id":"1.230180125","rc":[{"atb":[[1.02,2]],"id":42767337}],"con":true,"img":false}]}
{"op":"mcm","clk":"11541065916","pt":1719501765281,"mc":[{"id":"1.230180125","rc":[{"atb":[[2.54,0]],"id":42767337},{"atb":[[2.54,2.58]],"id":51567147},{"atb":[[2.98,5.61]],"id":70902709}],"con":true,"img":false}]}
{"op":"mcm","clk":"11541065926","pt":1719501765334,"mc":[{"id":"1.230180125","rc":[{"atl":[[1.87,14.88],[2.08,0]],"id":65992794},{"atb":[[2.7,6.16]],"id":42767337},{"atb":[[2.68,6.02]],"id":51567147},{"atb":[[2.84,1.93]],"id":70902709}],"con":true,"img":false}]}
{"op":"mcm","clk":"11541065936","pt":1719501765440,"mc":[{"id":"1.230180125","rc":[{"atl":[[1.89,0],[1.86,3.15]],"id":65992794},{"atl":[[3.75,7.14],[3.95,0]],"id":67245400},{"atl":[[4.2,17.81]],"id":42767337},{"atb":[[2.7,2.21]],"id":51567147},{"atb":[[3,1.68]],"id":70902709}],"con":true,"img":false}]}
{"op":"mcm","clk":"11541065945","pt":1719501765541,"mc":[{"id":"1.230180125","rc":[{"atb":[[1.48,31.99]],"id":65992794},{"atl":[[1.86,23.69]],"id":65992794},{"atl":[[3.75,14.74],[3.7,2.54]],"id":67245400},{"atl":[[4,15.56]],"id":42767337}],"con":true,"img":false}]}
{"op":"mcm","clk":"11541065956","pt":1719501765641,"mc":[{"id":"1.230180125","rc":[{"atb":[[1.02,2]],"id":65992794},{"atl":[[1.92,16.57]],"id":65992794},{"atb":[[2.62,11.96]],"id":67245400},{"atl":[[3.9,8.52]],"id":67245400},{"atb":[[2.72,18.51],[2.64,12.35]],"id":42767337},{"atl":[[4.2,9.92]],"id":42767337}],"con":true,"img":false}]}
{"op":"mcm","clk":"11541065964","pt":1719501765744,"mc":[{"id":"1.230180125","rc":[{"atl":[[1.87,28.45]],"id":65992794},{"atb":[[2.64,14.25]],"id":67245400},{"atl":[[3.75,22.64]],"id":67245400},{"atl":[[4,23.46]],"id":42767337}],"con":true,"img":false}]}
{"op":"mcm","clk":"11541065968","pt":1719501765847,"mc":[{"id":"1.230180125","rc":[{"atl":[[1.87,27.59]],"id":65992794}],"con":true,"img":false}]}
{"op":"mcm","clk":"11541065973","pt":1719501765951,"mc":[{"id":"1.230180125","rc":[{"atb":[[2.94,17.69]],"id":70902709}],"con":true,"img":false}]}
{"op":"mcm","clk":"11541065978","pt":1719501766054,"mc":[{"id":"1.230180125","rc":[{"atb":[[1.02,2]],"id":70902709}],"con":true,"img":false}]}
{"op":"mcm","clk":"11541065986","pt":1719501766162,"mc":[{"id":"1.230180125","rc":[{"atl":[[1.85,14.04],[2.06,4.63]],"id":65992794},{"atl":[[3.7,8.84],[3.9,2.25]],"id":67245400},{"atb":[[2.58,0],[2.74,6.16]],"id":42767337},{"atl":[[4.3,0],[3.95,6.1]],"id":42767337},{"atb":[[2.6,0],[2.7,8.22]],"id":51567147},{"atb":[[3,7.29],[2.86,0]],"id":70902709}],"con":true,"img":false}]}
{"op":"mcm","clk":"11541065993","pt":1719501766262,"mc":[{"id":"1.230180125","rc":[{"atl":[[1.84,3.26]],"id":65992794},{"atl":[[3.9,2.25]],"id":42767337}],"con":true,"img":false}]}
{"op":"mcm","clk":"11541066000","pt":1719501766368,"mc":[{"id":"1.230180125","rc":[{"atb":[[1.46,18.31]],"id":65992794}],"con":true,"img":false}]}
{"op":"mcm","clk":"11541066006","pt":1719501766462,"mc":[{"id":"1.230180125","rc":[{"atl":[[1.86,3.15]],"id":65992794},{"atl":[[3.75,15.04]],"id":67245400},{"atb":[[2.68,26.64]],"id":42767337},{"atl":[[4,16.1]],"id":42767337}],"con":true,"img":false}]}
{"op":"mcm","clk":"11541066019","pt":1719501766667,"mc":[{"id":"1.230180125","rc":[{"atb":[[2.68,18.74]],"id":42767337},{"atb":[[2.64,12.08],[2.66,8.33]],"id":51567147},{"atb":[[2.96,7.36]],"id":70902709}],"con":true,"img":false}]}
{"op":"mcm","clk":"11541066025","pt":1719501766770,"mc":[{"id":"1.230180125","rc":[{"atl":[[1.84,17.3]],"id":65992794},{"atb":[[2.72,26.4]],"id":42767337},{"atl":[[3.9,8.36]],"id":42767337},{"atb":[[2.7,16.12]],"id":51567147},{"atb":[[3,15.18]],"id":70902709}],"con":true,"img":false}]}
{"op":"mcm","clk":"11541066032","pt":1719501766874,"mc":[{"id":"1.230180125","rc":[{"atl":[[1.92,2.85]],"id":65992794},{"atl":[[4.2,3.82]],"id":42767337}],"con":true,"img":false}]}
{"op":"mcm","clk":"11541066040","pt":1719501766976,"mc":[{"id":"1.230180125","rc":[{"atb":[[2.54,0],[2.66,6.34]],"id":67245400},{"atb":[[2.72,6.01]],"id":51567147},{"atb":[[2.94,12.06],[3.05,5.6]],"id":70902709}],"con":true,"img":false}]}
{"op":"mcm","clk":"11541066050","pt":1719501767080,"mc":[{"id":"1.230180125","rc":[{"atb":[[2.68,6.17]],"id":42767337},{"atb":[[2.62,2.38],[2.74,2.12]],"id":51567147},{"atb":[[3.05,8.61]],"id":70902709}],"con":true,"img":false}]}
{"op":"mcm","clk":"11541066061","pt":1719501767186,"mc":[{"id":"1.230180125","rc":[{"atb":[[1.46,12.94]],"id":65992794},{"atb":[[2.74,18.73]],"id":42767337}],"con":true,"img":false}]}
{"op":"mcm","clk":"11541066087","pt":1719501767553,"mc":[{"id":"1.230180125","rc":[{"atl":[[1.88,17.03]],"id":65992794},{"atb":[[2.72,18.51]],"id":42767337},{"atl":[[4,8.2]],"id":42767337}],"con":true,"img":false}]}
{"op":"mcm","clk":"11541066096","pt":1719501767644,"mc":[{"id":"1.230180125","rc":[{"atb":[[2.74,26.63]],"id":42767337},{"atl":[[3.9,16.25]],"id":42767337},{"atb":[[2.9,6.75]],"id":70902709}],"con":true,"img":false}]}
{"op":"mcm","clk":"11541066102","pt":1719501767752,"mc":[{"id":"1.230180125","rc":[{"atl":[[1.84,42.71]],"id":65992794},{"atl":[[3.7,17.47]],"id":67245400},{"atb":[[2.9,0]],"id":70902709}],"con":true,"img":false}]}
{"op":"mcm","clk":"11541066120","pt":1719501767954,"mc":[{"id":"1.230180125","rc":[{"atl":[[3.9,25.2]],"id":42767337}],"con":true,"img":false}]}
{"op":"mcm","clk":"11541066147","pt":1719501768268,"mc":[{"id":"1.230180125","rc":[{"atl":[[3.85,0.84]],"id":42767337}],"con":true,"img":false}]}
{"op":"mcm","clk":"11541066177","pt":1719501768676,"mc":[{"id":"1.230180125","rc":[{"atb":[[2.64,6.35]],"id":67245400},{"atb":[[2.7,8.22]],"id":51567147},{"atb":[[3,7.29]],"id":70902709}],"con":true,"img":false}]}
{"op":"mcm","clk":"11541066182","pt":1719501768778,"mc":[{"id":"1.230180125","rc":[{"atl":[[1.88,3.04],[1.83,14.12],[1.76,2.54]],"id":65992794},{"atb":[[2.66,14.24]],"id":67245400},{"atl":[[3.85,0],[3.65,6.27]],"id":67245400},{"atl":[[3.85,6.96],[4.1,0]],"id":42767337},{"atb":[[2.74,16.01],[2.66,2.29]],"id":51567147},{"atb":[[3.05,16.51]],"id":70902709}],"con":true,"img":false}]}
{"op":"mcm","clk":"11541066187","pt":1719501768885,"mc":[{"id":"1.230180125","rc":[{"atl":[[1.75,3.84]],"id":65992794},{"atl":[[3.6,2.71]],"id":67245400},{"atl":[[3.8,2.39]],"id":42767337}],"con":true,"img":false}]}
{"op":"mcm","clk":"11541066193","pt":1719501768984,"mc":[{"id":"1.230180125","rc":[{"atb":[[2.62,0],[2.68,6.36]],"id":67245400}],"con":true,"img":false}]}
{"op":"mcm","clk":"11541066200","pt":1719501769090,"mc":[{"id":"1.230180125","rc":[{"atl":[[2.12,0],[1.87,13.56],[1.76,28.86],[1.75,17.98]],"id":65992794},{"atl":[[3.6,8.98]],"id":67245400},{"atl":[[3.8,8.51],[4,2.11]],"id":42767337},{"atb":[[2.76,5.99]],"id":51567147}],"con":true,"img":false}]}
{"op":"mcm","clk":"11541066210","pt":1719501769147,"mc":[{"id":"1.230180125","rc":[{"atl":[[3.8,2.39],[3.75,14.19]],"id":67245400},{"atb":[[2.78,2.04],[2.68,0]],"id":51567147},{"atb":[[2.96,1.74]],"id":70902709}],"con":true,"img":false}]}
{"op":"mcm","clk":"11541066216","pt":1719501769249,"mc":[{"id":"1.230180125","rc":[{"atb":[[3.1,5.6]],"id":70902709}],"con":true,"img":false}]}
{"op":"mcm","clk":"11541066243","pt":1719501769559,"mc":[{"id":"1.230180125","rc":[{"atl":[[1.84,41.71]],"id":65992794},{"atl":[[3.7,8.84]],"id":67245400},{"atl":[[3.9,24.63]],"id":42767337}],"con":true,"img":false}]}
{"op":"mcm","clk":"11541066254","pt":1719501769661,"mc":[{"id":"1.230180125","rc":[{"atl":[[1000,3.4]],"id":65992794},{"atl":[[1000,5.28]],"id":67245400},{"atl":[[1000,5.28]],"id":42767337},{"atl":[[3.45,0]],"id":51567147}],"con":true,"img":false}]}
{"op":"mcm","clk":"11541066261","pt":1719501769761,"mc":[{"id":"1.230180125","rc":[{"atb":[[1.01,121.59]],"id":65992794},{"atl":[[1000,8.51],[1.84,17.3]],"id":65992794},{"atb":[[1.02,14.33]],"id":67245400},{"atl":[[1000,8.69]],"id":67245400},{"atb":[[1.03,1.7],[1.02,3.7]],"id":42767337},{"atl":[[1000,8.69],[3.9,16.25]],"id":42767337}],"con":true,"img":false}]}
{"op":"mcm","clk":"11541066271","pt":1719501769865,"mc":[{"id":"1.230180125","rc":[{"atb":[[1.01,123.29]],"id":65992794},{"atl":[[1.75,42.39]],"id":65992794},{"atb":[[1.03,1.7]],"id":67245400},{"atl":[[1000,5.43]],"id":67245400},{"atb":[[1.03,5.1]],"id":42767337},{"atl":[[3.8,16.89],[1000,5.42]],"id":42767337}],"con":true,"img":false}]}
{"op":"mcm","clk":"11541066279","pt":1719501769970,"mc":[{"id":"1.230180125","rc":[{"atb":[[1.01,124.99]],"id":65992794},{"atb":[[1.03,3.4]],"id":67245400},{"atb":[[1.03,6.81]],"id":42767337}],"con":true,"img":false}]}
{"op":"mcm","clk":"11541066286","pt":1719501770072,"mc":[{"id":"1.230180125","rc":[{"atb":[[1.01,125.41]],"id":65992794},{"atl":[[1000,1.24]],"id":65992794},{"atb":[[1.03,5.1],[1.02,11.15]],"id":67245400},{"atl":[[1000,0.53]],"id":67245400},{"atb":[[1.03,5.21]],"id":42767337},{"atl":[[1000,0.5]],"id":42767337}],"con":true,"img":false}]}
{"op":"mcm","clk":"11541066295","pt":1719501770181,"mc":[{"id":"1.230180125","rc":[{"atb":[[1.03,3.51]],"id":67245400},{"atb":[[1.02,2.11]],"id":42767337}],"con":true,"img":false}]}
{"op":"mcm","clk":"11541066305","pt":1719501770277,"mc":[{"id":"1.230180125","rc":[{"atb":[[1.01,122.75]],"id":65992794},{"atl":[[1000,0.26]],"id":65992794},{"atl":[[1000,0.3]],"id":67245400},{"atb":[[1.03,1.88]],"id":42767337},{"atl":[[1000,0.23]],"id":42767337}],"con":true,"img":false}]}
{"op":"mcm","clk":"11541066312","pt":1719501770383,"mc":[{"id":"1.230180125","rc":[{"atl":[[1000,0],[1.72,0.97]],"id":65992794},{"atb":[[1.03,0.29],[1.02,11.04]],"id":67245400},{"atl":[[3.6,17.47],[3.55,0.22]],"id":67245400},{"atb":[[1.03,0.28],[2.76,0.11]],"id":42767337},{"atl":[[3.75,0.27],[1000,0.17]],"id":42767337}],"con":true,"img":false}]}
{"op":"mcm","clk":"11541066320","pt":1719501770488,"mc":[{"id":"1.230180125","rc":[{"atb":[[1.01,121]],"id":65992794},{"atl":[[1.72,1.24]],"id":65992794},{"atb":[[2.7,0.11]],"id":67245400},{"atl":[[3.75,0.32]],"id":42767337}],"con":true,"img":false}]}
{"op":"mcm","clk":"11541066328","pt":1719501770590,"mc":[{"id":"1.230180125","rc":[{"atb":[[1.01,120.19],[1.49,0.34]],"id":65992794},{"atl":[[1.93,0],[1.71,4.16],[1.74,26.31],[1.85,0],[1.72,15.42]],"id":65992794},{"atb":[[1.03,0],[2.58,0],[1.02,10.92],[2.68,12.67]],"id":67245400},{"atl":[[1000,0.17]],"id":67245400},{"atb":[[1.03,0.08],[1.02,2]],"id":42767337},{"atb":[[2.7,2.21]],"id":51567147}],"con":true,"img":false}]}
{"op":"mcm","clk":"11541066339","pt":1719501770687,"mc":[{"id":"1.230180125","rc":[{"atb":[[1.01,119.88],[1.49,1.15]],"id":65992794},{"atb":[[2.66,6.34],[2.7,0.52]],"id":67245400},{"atl":[[3.55,0.35]],"id":67245400},{"atb":[[1.03,0],[2.76,0.42]],"id":42767337},{"atb":[[2.74,8.11],[2.78,8.04]],"id":51567147},{"atb":[[3.05,8.61]],"id":70902709}],"con":true,"img":false}]}
{"op":"mcm","clk":"11541066347","pt":1719501770745,"mc":[{"id":"1.230180125","rc":[{"atb":[[1.49,1.45]],"id":65992794},{"atb":[[2.68,20.57]],"id":67245400},{"atb":[[2.72,0],[2.76,19.01]],"id":42767337},{"atb":[[2.78,15.94]],"id":51567147},{"atl":[[3.6,0],[3.5,0],[3.7,0]],"id":51567147},{"atb":[[3.1,13.5]],"id":70902709}],"con":true,"img":false}]}
{"op":"mcm","clk":"11541066356","pt":1719501770851,"mc":[{"id":"1.230180125","rc":[{"atl":[[3.85,6.12]],"id":42767337}],"con":true,"img":false}]}
{"op":"mcm","clk":"11541066365","pt":1719501770951,"mc":[{"id":"1.230180125","rc":[{"atl":[[1.76,26.31]],"id":65992794},{"atl":[[3.55,2.89]],"id":67245400}],"con":true,"img":false}]}
{"op":"mcm","clk":"11541066371","pt":1719501771055,"mc":[{"id":"1.230180125","rc":[{"atl":[[3.55,9.15],[3.5,2.9],[3.75,7.89]],"id":67245400},{"atl":[[3.75,6.45],[3.95,0]],"id":42767337}],"con":true,"img":false}]}
{"op":"mcm","clk":"11541066379","pt":1719501771166,"mc":[{"id":"1.230180125","rc":[{"atb":[[1.48,28.82]],"id":65992794},{"atl":[[3.6,8.98]],"id":67245400},{"atb":[[2.74,14.06]],"id":42767337},{"atl":[[3.7,2.54]],"id":42767337}],"con":true,"img":false}]}
{"op":"mcm","clk":"11541066390","pt":1719501771264,"mc":[{"id":"1.230180125","rc":[{"atb":[[1.48,7.89]],"id":65992794},{"atl":[[1.87,7.89]],"id":65992794},{"atb":[[2.66,0],[2.68,14.25]],"id":67245400},{"atl":[[3.5,9.22],[3.7,2.53]],"id":67245400},{"atb":[[2.8,6],[2.72,0]],"id":51567147}],"con":true,"img":false}]}
{"op":"mcm","clk":"11541066398","pt":1719501771363,"mc":[{"id":"1.230180125","rc":[{"atb":[[1.49,22.38]],"id":65992794},{"atb":[[2.82,1.97]],"id":51567147}],"con":true,"img":false}]}
{"op":"mcm","clk":"11541066406","pt":1719501771472,"mc":[{"id":"1.230180125","rc":[{"atb":[[1.46,0]],"id":65992794},{"atl":[[1.71,18.43],[1.84,3.26]],"id":65992794},{"atl":[[4.4,3.42]],"id":67245400}],"con":true,"img":false}]}
{"op":"mcm","clk":"11541066416","pt":1719501771565,"mc":[{"id":"1.230180125","rc":[{"atb":[[2.7,9.22]],"id":42767337},{"atl":[[4,5.14],[3.7,8.64],[3.9,10.14]],"id":42767337}],"con":true,"img":false}]}
{"op":"mcm","clk":"11541066424","pt":1719501771666,"mc":[{"id":"1.230180125","rc":[{"atb":[[1.48,0]],"id":65992794},{"atb":[[2.68,6.36]],"id":67245400},{"atb":[[2.74,6.16],[2.7,6.16]],"id":42767337},{"atl":[[4.9,0],[4,2.11]],"id":42767337},{"atl":[[3.8,0]],"id":51567147}],"con":true,"img":false}]}
{"op":"mcm","clk":"11541066432","pt":1719501771773,"mc":[{"id":"1.230180125","rc":[{"atb":[[1.49,30.28]],"id":65992794},{"atb":[[2.7,8.42]],"id":67245400},{"atb":[[2.76,26.91]],"id":42767337}],"con":true,"img":false}]}
{"op":"mcm","clk":"11541066438","pt":1719501771871,"mc":[{"id":"1.230180125","rc":[{"atb":[[2.82,7.96]],"id":51567147}],"con":true,"img":false}]}
{"op":"mcm","clk":"11541066441","pt":1719501771975,"mc":[{"id":"1.230180125","rc":[{"atb":[[2.74,2.12]],"id":51567147}],"con":true,"img":false}]}
{"op":"mcm","clk":"11541066456","pt":1719501772181,"mc":[{"id":"1.230180125","rc":[{"atl":[[1.69,0.84]],"id":65992794},{"atl":[[3.55,6.61],[3.45,0.84]],"id":67245400},{"atl":[[3.8,8.51]],"id":42767337}],"con":true,"img":false}]}
{"op":"mcm","clk":"11541066465","pt":1719501772283,"mc":[{"id":"1.230180125","rc":[{"atb":[[1.49,9.35]],"id":65992794},{"atb":[[2.64,0]],"id":67245400}],"con":true,"img":false}]}
{"op":"mcm","clk":"11541066472","pt":1719501772388,"mc":[{"id":"1.230180125","rc":[{"atb":[[1.46,20.93]],"id":65992794}],"con":true,"img":false}]}
{"op":"mcm","clk":"11541066480","pt":1719501772445,"mc":[{"id":"1.230180125","rc":[{"atl":[[3.5,18.12]],"id":67245400},{"atl":[[3.9,13.67]],"id":51567147}],"con":true,"img":false}]}
{"op":"mcm","clk":"11541066486","pt":1719501772542,"mc":[{"id":"1.230180125","rc":[{"atb":[[2.78,8.04]],"id":51567147}],"con":true,"img":false}]}
{"op":"mcm","clk":"11541066494","pt":1719501772646,"mc":[{"id":"1.230180125","rc":[{"atb":[[2.82,15.85]],"id":51567147}],"con":true,"img":false}]}
{"op":"mcm","clk":"11541066517","pt":1719501772974,"mc":[{"id":"1.230180125","rc":[{"atl":[[3.7,16.08]],"id":42767337}],"con":true,"img":false}]}
{"op":"mcm","clk":"11541066605","pt":1719501773909,"mc":[{"id":"1.230180125","rc":[{"atl":[[3.45,7.24],[3.65,0]],"id":67245400},{"atb":[[2.84,5.97],[2.76,0]],"id":51567147},{"atl":[[3.2,10.75]],"id":51567147}],"con":true,"img":false}]}
{"op":"mcm","clk":"11541066616","pt":1719501774071,"mc":[{"id":"1.230180125","rc":[{"atb":[[2.5,0],[2.6,0],[2.46,0]],"id":67245400},{"atl":[[3.4,3.11]],"id":67245400},{"atb":[[2.86,1.9]],"id":51567147},{"atl":[[3.55,0.84]],"id":70902709}],"con":true,"img":false}]}
{"op":"mcm","clk":"11541066625","pt":1719501774167,"mc":[{"id":"1.230180125","rc":[{"atb":[[2.72,6.37],[2.68,0]],"id":67245400}],"con":true,"img":false}]}
{"op":"mcm","clk":"11541066633","pt":1719501774272,"mc":[{"id":"1.230180125","rc":[{"atl":[[1.7,26.31],[1.91,0],[1.83,0],[1.69,14.86]],"id":65992794},{"atl":[[3.6,2.71],[3.4,9.55]],"id":67245400},{"atl":[[3.65,6.07]],"id":42767337},{"atb":[[2.78,2.04],[2.86,7.81]],"id":51567147},{"atl":[[3.25,0]],"id":51567147}],"con":true,"img":false}]}
{"op":"mcm","clk":"11541066640","pt":1719501774378,"mc":[{"id":"1.230180125","rc":[{"atl":[[3.85,0]],"id":42767337}],"con":true,"img":false}]}
{"op":"mcm","clk":"11541066647","pt":1719501774478,"mc":[{"id":"1.230180125","rc":[{"atl":[[1.68,4.41]],"id":65992794},{"atl":[[3.6,2.71]],"id":42767337}],"con":true,"img":false}]}
{"op":"mcm","clk":"11541066671","pt":1719501774783,"mc":[{"id":"1.230180125","rc":[{"atl":[[1.68,18.44]],"id":65992794},{"atl":[[3.6,8.78],[3.8,2.38]],"id":42767337}],"con":true,"img":false}]}
