{"op":"mcm","clk":"11536833039","pt":1719431776484,"mc":[{"id":"1.230180134","marketDefinition":{"bspMarket":true,"turnInPlayEnabled":false,"persistenceEnabled":false,"marketBaseRate":5.0,"eventId":"33376437","eventTypeId":"4339","numberOfWinners":1,"bettingType":"ODDS","marketType":"WIN","marketTime":"2024-06-27T16:54:00.000Z","suspendTime":"2024-06-27T16:54:00.000Z","bspReconciled":false,"complete":true,"inPlay":false,"crossMatching":false,"runnersVoidable":false,"numberOfActiveRunners":5,"betDelay":0,"status":"OPEN","runners":[{"status":"ACTIVE","sortPriority":1,"id":4065261,"name":"2. Manx Storm"},{"status":"ACTIVE","sortPriority":2,"id":69176457,"name":"3. Franco Eve"},{"status":"ACTIVE","sortPriority":3,"id":41401491,"name":"4. Connors Bullet"},{"status":"ACTIVE","sortPriority":4,"id":65040144,"name":"5. Diegos Talavara"},{"status":"ACTIVE","sortPriority":5,"id":52032624,"name":"6. Limekiln Chic"}],"regulators":["MR_INT"],"venue":"Towcester","countryCode":"GB","discountAllowed":false,"timezone":"Europe/London","openDate":"2024-06-27T13:33:00.000Z","version":5994767143,"name":"A7 500m","eventName":"Towcester 27th Jun"},"rc":[],"con":true,"img":false}]}
{"op":"mcm","clk":"11536833150","pt":1719431777535,"mc":[{"id":"1.230180134","marketDefinition":{"bspMarket":true,"turnInPlayEnabled":false,"persistenceEnabled":false,"marketBaseRate":5.0,"eventId":"33376437","eventTypeId":"4339","numberOfWinners":1,"bettingType":"ODDS","marketType":"WIN","marketTime":"2024-06-27T16:54:00.000Z","suspendTime":"2024-06-27T16:54:00.000Z","bspReconciled":false,"complete":true,"inPlay":false,"crossMatching":false,"runnersVoidable":false,"numberOfActiveRunners":5,"betDelay":0,"status":"OPEN","runners":[{"status":"ACTIVE","sortPriority":1,"id":4065261,"name":"2. Manx Storm"},{"status":"ACTIVE","sortPriority":2,"id":69176457,"name":"3. Franco Eve"},{"status":"ACTIVE","sortPriority":3,"id":41401491,"name":"4. Connors Bullet"},{"status":"ACTIVE","sortPriority":4,"id":65040144,"name":"5. Diegos Talavara"},{"status":"ACTIVE","sortPriority":5,"id":52032624,"name":"6. Limekiln Chic"}],"regulators":["MR_INT"],"venue":"Towcester","countryCode":"GB","discountAllowed":true,"timezone":"Europe/London","openDate":"2024-06-27T13:33:00.000Z","version":5994767143,"name":"A7 500m","eventName":"Towcester 27th Jun"},"rc":[],"con":true,"img":false}]}
{"op":"mcm","clk":"11537083722","pt":1719435429514,"mc":[{"id":"1.230180134","rc":[{"atb":[[1.02,16.48]],"id":41401491},{"atl":[[990,0.84]],"id":41401491},{"spn":495.51,"spf":"NaN","id":41401491},{"atb":[[1.03,10.99]],"id":52032624},{"atl":[[990,0.84]],"id":52032624},{"spn":495.51,"spf":"NaN","id":52032624},{"atb":[[1.02,16.48]],"id":4065261},{"atl":[[1000,0.84]],"id":4065261},{"spn":500.51,"spf":"NaN","id":4065261},{"atb":[[1.03,10.99]],"id":69176457},{"atl":[[990,0.84]],"id":69176457},{"spn":495.51,"spf":"NaN","id":69176457},{"atb":[[1.02,16.48]],"id":65040144},{"atl":[[990,0.84]],"id":65040144},{"spn":495.51,"spf":"NaN","id":65040144}],"con":true,"img":false}]}
{"op":"mcm","clk":"11537235638","pt":1719437882800,"mc":[{"id":"1.230180134","marketDefinition":{"bspMarket":true,"turnInPlayEnabled":false,"persistenceEnabled":false,"marketBaseRate":5.0,"eventId":"33376437","eventTypeId":"4339","numberOfWinners":1,"bettingType":"ODDS","marketType":"WIN","marketTime":"2024-06-27T16:54:00.000Z","suspendTime":"2024-06-27T16:54:00.000Z","bspReconciled":false,"complete":true,"inPlay":false,"crossMatching":false,"runnersVoidable":false,"numberOfActiveRunners":5,"betDelay":0,"status":"OPEN","runners":[{"status":"ACTIVE","sortPriority":1,"id":4065261,"name":"2. Manx Storm"},{"status":"ACTIVE","sortPriority":2,"id":69176457,"name":"3. Franco Eve"},{"status":"ACTIVE","sortPriority":3,"id":41401491,"name":"4. Connors Bullet"},{"status":"ACTIVE","sortPriority":4,"id":65040144,"name":"5. Diegos Talavara"},{"status":"ACTIVE","sortPriority":5,"id":52032624,"name":"6. Limekiln Chic"}],"regulators":["MR_INT"],"venue":"Towcester","countryCode":"GB","discountAllowed":true,"timezone":"Europe/London","openDate":"2024-06-27T13:33:00.000Z","version":5994767143,"name":"A7 500m","eventName":"Towcester 27th Jun"},"rc":[{"atb":[[1.02,16.48]],"id":41401491},{"atl":[[990,0.84]],"id":41401491},{"spn":495.51,"spf":"NaN","id":41401491},{"atb":[[1.03,10.99]],"id":52032624},{"atl":[[990,0.84]],"id":52032624},{"spn":495.51,"spf":"NaN","id":52032624},{"atb":[[1.02,16.48]],"id":4065261},{"atl":[[1000,0.84]],"id":4065261},{"spn":500.51,"spf":"NaN","id":4065261},{"atb":[[1.03,10.99]],"id":69176457},{"atl":[[990,0.84]],"id":69176457},{"spn":495.51,"spf":"NaN","id":69176457},{"atb":[[1.02,16.48]],"id":65040144},{"atl":[[990,0.84]],"id":65040144},{"spn":495.51,"spf":"NaN","id":65040144}],"con":true,"img":true}]}
{"op":"mcm","clk":"11537301849","pt":1719439025254,"mc":[{"id":"1.230180134","rc":[{"atb":[[1.02,16.48]],"id":41401491},{"atl":[[990,0.17]],"id":41401491},{"atb":[[1.03,10.99]],"id":52032624},{"atl":[[990,0.17]],"id":52032624},{"atb":[[1.02,16.48]],"id":4065261},{"atl":[[1000,0.17]],"id":4065261},{"atb":[[1.03,10.99]],"id":69176457},{"atl":[[990,0.17]],"id":69176457},{"atb":[[1.02,16.48]],"id":65040144},{"atl":[[990,0.17]],"id":65040144}],"con":true,"img":false}]}
{"op":"mcm","clk":"11537576926","pt":1719443282845,"mc":[{"id":"1.230180134","marketDefinition":{"bspMarket":true,"turnInPlayEnabled":false,"persistenceEnabled":false,"marketBaseRate":5.0,"eventId":"33376437","eventTypeId":"4339","numberOfWinners":1,"bettingType":"ODDS","marketType":"WIN","marketTime":"2024-06-27T16:54:00.000Z","suspendTime":"2024-06-27T16:54:00.000Z","bspReconciled":false,"complete":true,"inPlay":false,"crossMatching":false,"runnersVoidable":false,"numberOfActiveRunners":5,"betDelay":0,"status":"OPEN","runners":[{"status":"ACTIVE","sortPriority":1,"id":4065261,"name":"2. Manx Storm"},{"status":"ACTIVE","sortPriority":2,"id":69176457,"name":"3. Franco Eve"},{"status":"ACTIVE","sortPriority":3,"id":41401491,"name":"4. Connors Bullet"},{"status":"ACTIVE","sortPriority":4,"id":65040144,"name":"5. Diegos Talavara"},{"status":"ACTIVE","sortPriority":5,"id":52032624,"name":"6. Limekiln Chic"}],"regulators":["MR_INT"],"venue":"Towcester","countryCode":"GB","discountAllowed":true,"timezone":"Europe/London","openDate":"2024-06-27T13:33:00.000Z","version":5994767143,"name":"A7 500m","eventName":"Towcester 27th Jun"},"rc":[{"atb":[[1.02,16.48]],"id":41401491},{"atl":[[990,0.17]],"id":41401491},{"spn":495.51,"spf":"NaN","id":41401491},{"atb":[[1.03,10.99]],"id":52032624},{"atl":[[990,0.17]],"id":52032624},{"spn":495.51,"spf":"NaN","id":52032624},{"atb":[[1.02,16.48]],"id":4065261},{"atl":[[1000,0.17]],"id":4065261},{"spn":500.51,"spf":"NaN","id":4065261},{"atb":[[1.03,10.99]],"id":69176457},{"atl":[[990,0.17]],"id":69176457},{"spn":495.51,"spf":"NaN","id":69176457},{"atb":[[1.02,16.48]],"id":65040144},{"atl":[[990,0.17]],"id":65040144},{"spn":495.51,"spf":"NaN","id":65040144}],"con":true,"img":true}]}
{"op":"mcm","clk":"11537958614","pt":1719448682891,"mc":[{"id":"1.230180134","marketDefinition":{"bspMarket":true,"turnInPlayEnabled":false,"persistenceEnabled":false,"marketBaseRate":5.0,"eventId":"33376437","eventTypeId":"4339","numberOfWinners":1,"bettingType":"ODDS","marketType":"WIN","marketTime":"2024-06-27T16:54:00.000Z","suspendTime":"2024-06-27T16:54:00.000Z","bspReconciled":false,"complete":true,"inPlay":false,"crossMatching":false,"runnersVoidable":false,"numberOfActiveRunners":5,"betDelay":0,"status":"OPEN","runners":[{"status":"ACTIVE","sortPriority":1,"id":4065261,"name":"2. Manx Storm"},{"status":"ACTIVE","sortPriority":2,"id":69176457,"name":"3. Franco Eve"},{"status":"ACTIVE","sortPriority":3,"id":41401491,"name":"4. Connors Bullet"},{"status":"ACTIVE","sortPriority":4,"id":65040144,"name":"5. Diegos Talavara"},{"status":"ACTIVE","sortPriority":5,"id":52032624,"name":"6. Limekiln Chic"}],"regulators":["MR_INT"],"venue":"Towcester","countryCode":"GB","discountAllowed":true,"timezone":"Europe/London","openDate":"2024-06-27T13:33:00.000Z","version":5994767143,"name":"A7 500m","eventName":"Towcester 27th Jun"},"rc":[{"atb":[[1.02,16.48]],"id":41401491},{"atl":[[990,0.17]],"id":41401491},{"spn":495.51,"spf":"NaN","id":41401491},{"atb":[[1.03,10.99]],"id":52032624},{"atl":[[990,0.17]],"id":52032624},{"spn":495.51,"spf":"NaN","id":52032624},{"atb":[[1.02,16.48]],"id":4065261},{"atl":[[1000,0.17]],"id":4065261},{"spn":500.51,"spf":"NaN","id":4065261},{"atb":[[1.03,10.99]],"id":69176457},{"atl":[[990,0.17]],"id":69176457},{"spn":495.51,"spf":"NaN","id":69176457},{"atb":[[1.02,16.48]],"id":65040144},{"atl":[[990,0.17]],"id":65040144},{"spn":495.51,"spf":"NaN","id":65040144}],"con":true,"img":true}]}
{"op":"mcm","clk":"11538174190","pt":1719454082863,"mc":[{"id":"1.230180134","marketDefinition":{"bspMarket":true,"turnInPlayEnabled":false,"persistenceEnabled":false,"marketBaseRate":5.0,"eventId":"33376437","eventTypeId":"4339","numberOfWinners":1,"bettingType":"ODDS","marketType":"WIN","marketTime":"2024-06-27T16:54:00.000Z","suspendTime":"2024-06-27T16:54:00.000Z","bspReconciled":false,"complete":true,"inPlay":false,"crossMatching":false,"runnersVoidable":false,"numberOfActiveRunners":5,"betDelay":0,"status":"OPEN","runners":[{"status":"ACTIVE","sortPriority":1,"id":4065261,"name":"2. Manx Storm"},{"status":"ACTIVE","sortPriority":2,"id":69176457,"name":"3. Franco Eve"},{"status":"ACTIVE","sortPriority":3,"id":41401491,"name":"4. Connors Bullet"},{"status":"ACTIVE","sortPriority":4,"id":65040144,"name":"5. Diegos Talavara"},{"status":"ACTIVE","sortPriority":5,"id":52032624,"name":"6. Limekiln Chic"}],"regulators":["MR_INT"],"venue":"Towcester","countryCode":"GB","discountAllowed":true,"timezone":"Europe/London","openDate":"2024-06-27T13:33:00.000Z","version":5994767143,"name":"A7 500m","eventName":"Towcester 27th Jun"},"rc":[{"atb":[[1.02,16.48]],"id":41401491},{"atl":[[990,0.17]],"id":41401491},{"spn":495.51,"spf":"NaN","id":41401491},{"atb":[[1.03,10.99]],"id":52032624},{"atl":[[990,0.17]],"id":52032624},{"spn":495.51,"spf":"NaN","id":52032624},{"atb":[[1.02,16.48]],"id":4065261},{"atl":[[1000,0.17]],"id":4065261},{"spn":500.51,"spf":"NaN","id":4065261},{"atb":[[1.03,10.99]],"id":69176457},{"atl":[[990,0.17]],"id":69176457},{"spn":495.51,"spf":"NaN","id":69176457},{"atb":[[1.02,16.48]],"id":65040144},{"atl":[[990,0.17]],"id":65040144},{"spn":495.51,"spf":"NaN","id":65040144}],"con":true,"img":true}]}
{"op":"mcm","clk":"11538371903","pt":1719459482937,"mc":[{"id":"1.230180134","marketDefinition":{"bspMarket":true,"turnInPlayEnabled":false,"persistenceEnabled":false,"marketBaseRate":5.0,"eventId":"33376437","eventTypeId":"4339","numberOfWinners":1,"bettingType":"ODDS","marketType":"WIN","marketTime":"2024-06-27T16:54:00.000Z","suspendTime":"2024-06-27T16:54:00.000Z","bspReconciled":false,"complete":true,"inPlay":false,"crossMatching":false,"runnersVoidable":false,"numberOfActiveRunners":5,"betDelay":0,"status":"OPEN","runners":[{"status":"ACTIVE","sortPriority":1,"id":4065261,"name":"2. Manx Storm"},{"status":"ACTIVE","sortPriority":2,"id":69176457,"name":"3. Franco Eve"},{"status":"ACTIVE","sortPriority":3,"id":41401491,"name":"4. Connors Bullet"},{"status":"ACTIVE","sortPriority":4,"id":65040144,"name":"5. Diegos Talavara"},{"status":"ACTIVE","sortPriority":5,"id":52032624,"name":"6. Limekiln Chic"}],"regulators":["MR_INT"],"venue":"Towcester","countryCode":"GB","discountAllowed":true,"timezone":"Europe/London","openDate":"2024-06-27T13:33:00.000Z","version":5994767143,"name":"A7 500m","eventName":"Towcester 27th Jun"},"rc":[{"atb":[[1.02,16.48]],"id":41401491},{"atl":[[990,0.17]],"id":41401491},{"spn":495.51,"spf":"NaN","id":41401491},{"atb":[[1.03,10.99]],"id":52032624},{"atl":[[990,0.17]],"id":52032624},{"spn":495.51,"spf":"NaN","id":52032624},{"atb":[[1.02,16.48]],"id":4065261},{"atl":[[1000,0.17]],"id":4065261},{"spn":500.51,"spf":"NaN","id":4065261},{"atb":[[1.03,10.99]],"id":69176457},{"atl":[[990,0.17]],"id":69176457},{"spn":495.51,"spf":"NaN","id":69176457},{"atb":[[1.02,16.48]],"id":65040144},{"atl":[[990,0.17]],"id":65040144},{"spn":495.51,"spf":"NaN","id":65040144}],"con":true,"img":true}]}
{"op":"mcm","clk":"11538598980","pt":1719464882863,"mc":[{"id":"1.230180134","marketDefinition":{"bspMarket":true,"turnInPlayEnabled":false,"persistenceEnabled":false,"marketBaseRate":5.0,"eventId":"33376437","eventTypeId":"4339","numberOfWinners":1,"bettingType":"ODDS","marketType":"WIN","marketTime":"2024-06-27T16:54:00.000Z","suspendTime":"2024-06-27T16:54:00.000Z","bspReconciled":false,"complete":true,"inPlay":false,"crossMatching":false,"runnersVoidable":false,"numberOfActiveRunners":5,"betDelay":0,"status":"OPEN","runners":[{"status":"ACTIVE","sortPriority":1,"id":4065261,"name":"2. Manx Storm"},{"status":"ACTIVE","sortPriority":2,"id":69176457,"name":"3. Franco Eve"},{"status":"ACTIVE","sortPriority":3,"id":41401491,"name":"4. Connors Bullet"},{"status":"ACTIVE","sortPriority":4,"id":65040144,"name":"5. Diegos Talavara"},{"status":"ACTIVE","sortPriority":5,"id":52032624,"name":"6. Limekiln Chic"}],"regulators":["MR_INT"],"venue":"Towcester","countryCode":"GB","discountAllowed":true,"timezone":"Europe/London","openDate":"2024-06-27T13:33:00.000Z","version":5994767143,"name":"A7 500m","eventName":"Towcester 27th Jun"},"rc":[{"atb":[[1.02,16.48]],"id":41401491},{"atl":[[990,0.17]],"id":41401491},{"spn":495.51,"spf":"NaN","id":41401491},{"atb":[[1.03,10.99]],"id":52032624},{"atl":[[990,0.17]],"id":52032624},{"spn":495.51,"spf":"NaN","id":52032624},{"atb":[[1.02,16.48]],"id":4065261},{"atl":[[1000,0.17]],"id":4065261},{"spn":500.51,"spf":"NaN","id":4065261},{"atb":[[1.03,10.99]],"id":69176457},{"atl":[[990,0.17]],"id":69176457},{"spn":495.51,"spf":"NaN","id":69176457},{"atb":[[1.02,16.48]],"id":65040144},{"atl":[[990,0.17]],"id":65040144},{"spn":495.51,"spf":"NaN","id":65040144}],"con":true,"img":true}]}
{"op":"mcm","clk":"11538748680","pt":1719468205983,"mc":[{"id":"1.230180134","rc":[{"atb":[[1.74,16.29],[1.02,16.48]],"id":41401491},{"spn":495.87,"spf":"NaN","id":41401491},{"atb":[[1.03,10.99],[1.71,21.83]],"id":52032624},{"spn":495.85,"spf":"NaN","id":52032624},{"atb":[[1.02,16.48],[1.71,17.46]],"id":4065261},{"spn":500.85,"spf":"NaN","id":4065261},{"atb":[[1.03,10.99],[1.71,20.37]],"id":69176457},{"spn":495.85,"spf":"NaN","id":69176457},{"atb":[[1.02,16.48],[1.71,14.55]],"id":65040144},{"spn":495.85,"spf":"NaN","id":65040144}],"con":true,"img":false}]}
{"op":"mcm","clk":"11538750250","pt":1719468240218,"mc":[{"id":"1.230180134","rc":[{"atb":[[1.72,3.16]],"id":4065261},{"atb":[[1.72,3.16]],"id":65040144}],"con":true,"img":false}]}
{"op":"mcm","clk":"11538750276","pt":1719468240840,"mc":[{"id":"1.230180134","rc":[{"atb":[[1.72,3.16]],"id":69176457}],"con":true,"img":false}]}
{"op":"mcm","clk":"11538750310","pt":1719468241454,"mc":[{"id":"1.230180134","rc":[{"atb":[[1.72,3.16]],"id":52032624}],"con":true,"img":false}]}
{"op":"mcm","clk":"11538752053","pt":1719468274913,"mc":[{"id":"1.230180134","rc":[{"spn":495.86,"spf":"NaN","id":52032624},{"spn":500.86,"spf":"NaN","id":4065261},{"atb":[[1.72,6.55]],"id":69176457},{"spn":495.86,"spf":"NaN","id":69176457},{"spn":495.86,"spf":"NaN","id":65040144}],"con":true,"img":false}]}
{"op":"mcm","clk":"11538752061","pt":1719468275013,"mc":[{"id":"1.230180134","rc":[{"atb":[[1.72,6.55]],"id":52032624}],"con":true,"img":false}]}
{"op":"mcm","clk":"11538752069","pt":1719468275174,"mc":[{"id":"1.230180134","rc":[{"atb":[[1.72,6.55]],"id":4065261}],"con":true,"img":false}]}
{"op":"mcm","clk":"11538752087","pt":1719468275579,"mc":[{"id":"1.230180134","rc":[{"atb":[[1.72,6.55]],"id":65040144}],"con":true,"img":false}]}
{"op":"mcm","clk":"11538752388","pt":1719468281750,"mc":[{"id":"1.230180134","marketDefinition":{"bspMarket":true,"turnInPlayEnabled":false,"persistenceEnabled":false,"marketBaseRate":5.0,"eventId":"33376437","eventTypeId":"4339","numberOfWinners":1,"bettingType":"ODDS","marketType":"WIN","marketTime":"2024-06-27T16:54:00.000Z","suspendTime":"2024-06-27T16:54:00.000Z","bspReconciled":false,"complete":true,"inPlay":false,"crossMatching":true,"runnersVoidable":false,"numberOfActiveRunners":5,"betDelay":0,"status":"OPEN","runners":[{"status":"ACTIVE","sortPriority":1,"id":4065261,"name":"2. Manx Storm"},{"status":"ACTIVE","sortPriority":2,"id":69176457,"name":"3. Franco Eve"},{"status":"ACTIVE","sortPriority":3,"id":41401491,"name":"4. Connors Bullet"},{"status":"ACTIVE","sortPriority":4,"id":65040144,"name":"5. Diegos Talavara"},{"status":"ACTIVE","sortPriority":5,"id":52032624,"name":"6. Limekiln Chic"}],"regulators":["MR_INT"],"venue":"Towcester","countryCode":"GB","discountAllowed":true,"timezone":"Europe/London","openDate":"2024-06-27T13:33:00.000Z","version":5994767143,"name":"A7 500m","eventName":"Towcester 27th Jun"},"rc":[],"con":true,"img":false}]}
{"op":"mcm","clk":"11538938984","pt":1719472081444,"mc":[{"id":"1.230180134","rc":[{"atb":[[1.74,16.28],[1.02,16.47]],"id":41401491},{"atl":[[21,4],[11.5,2],[990,0.17],[15.5,3]],"id":41401491},{"spn":6.62,"spf":"NaN","id":41401491},{"atb":[[1.72,6.54],[1.03,10.98],[1.71,21.82]],"id":52032624},{"atl":[[990,0.17]],"id":52032624},{"atb":[[1.72,6.54],[1.02,16.47],[1.71,17.45]],"id":4065261},{"atl":[[1000,0.17]],"id":4065261},{"atb":[[1.72,6.54],[1.03,10.98],[1.71,20.36]],"id":69176457},{"atl":[[990,0.17]],"id":69176457},{"atb":[[1.72,6.54],[1.02,16.47],[1.71,14.54]],"id":65040144},{"atl":[[990,0.17]],"id":65040144}],"con":true,"img":false}]}
{"op":"mcm","clk":"11538940823","pt":1719472114706,"mc":[{"id":"1.230180134","rc":[{"atb":[[1.71,0]],"id":52032624},{"atb":[[1.71,0]],"id":4065261},{"atb":[[1.71,0]],"id":69176457},{"atb":[[1.71,0]],"id":65040144}],"con":true,"img":false}]}
{"op":"mcm","clk":"11538940828","pt":1719472114808,"mc":[{"id":"1.230180134","rc":[{"atb":[[1.73,21.82]],"id":52032624},{"atb":[[1.73,17.45]],"id":4065261},{"atb":[[1.73,20.36]],"id":69176457},{"atb":[[1.73,14.54]],"id":65040144}],"con":true,"img":false}]}
{"op":"mcm","clk":"11538942154","pt":1719472136224,"mc":[{"id":"1.230180134","rc":[{"atb":[[1.72,3.38]],"id":4065261}],"con":true,"img":false}]}
{"op":"mcm","clk":"11538942178","pt":1719472136534,"mc":[{"id":"1.230180134","rc":[{"atb":[[1.72,3.38]],"id":52032624}],"con":true,"img":false}]}
{"op":"mcm","clk":"11538942195","pt":1719472136737,"mc":[{"id":"1.230180134","rc":[{"atb":[[1.72,3.38]],"id":65040144}],"con":true,"img":false}]}
{"op":"mcm","clk":"11538942273","pt":1719472137861,"mc":[{"id":"1.230180134","rc":[{"atb":[[1.72,3.38]],"id":69176457}],"con":true,"img":false}]}
{"op":"mcm","clk":"11538942367","pt":1719472139565,"mc":[{"id":"1.230180134","rc":[{"atb":[[1.74,3.16]],"id":4065261}],"con":true,"img":false}]}
{"op":"mcm","clk":"11538942376","pt":1719472139757,"mc":[{"id":"1.230180134","rc":[{"atb":[[1.74,3.16]],"id":65040144}],"con":true,"img":false}]}
{"op":"mcm","clk":"11538942449","pt":1719472140735,"mc":[{"id":"1.230180134","rc":[{"atb":[[1.74,3.16]],"id":52032624},{"atb":[[1.74,3.16]],"id":69176457}],"con":true,"img":false}]}
{"op":"mcm","clk":"11538942874","pt":1719472146759,"mc":[{"id":"1.230180134","rc":[{"spn":495.87,"spf":"NaN","id":52032624},{"atb":[[1.72,0]],"id":4065261},{"spn":500.87,"spf":"NaN","id":4065261},{"spn":495.87,"spf":"NaN","id":69176457},{"spn":495.87,"spf":"NaN","id":65040144}],"con":true,"img":false}]}
{"op":"mcm","clk":"11538942911","pt":1719472147279,"mc":[{"id":"1.230180134","rc":[{"atb":[[1.72,0]],"id":65040144}],"con":true,"img":false}]}
{"op":"mcm","clk":"11538942929","pt":1719472147482,"mc":[{"id":"1.230180134","rc":[{"atb":[[1.72,0]],"id":52032624}],"con":true,"img":false}]}
{"op":"mcm","clk":"11538942984","pt":1719472148151,"mc":[{"id":"1.230180134","rc":[{"atb":[[1.72,0]],"id":69176457}],"con":true,"img":false}]}
{"op":"mcm","clk":"11538943435","pt":1719472155488,"mc":[{"id":"1.230180134","rc":[{"atb":[[1.74,6.54]],"id":52032624}],"con":true,"img":false}]}
{"op":"mcm","clk":"11538943452","pt":1719472155795,"mc":[{"id":"1.230180134","rc":[{"atb":[[1.74,6.54]],"id":4065261}],"con":true,"img":false}]}
{"op":"mcm","clk":"11538943479","pt":1719472156204,"mc":[{"id":"1.230180134","rc":[{"atb":[[1.74,6.54]],"id":65040144}],"con":true,"img":false}]}
{"op":"mcm","clk":"11538943582","pt":1719472158197,"mc":[{"id":"1.230180134","rc":[{"atb":[[1.74,6.54]],"id":69176457}],"con":true,"img":false}]}
{"op":"mcm","clk":"11539077568","pt":1719474853080,"mc":[{"id":"1.230180134","rc":[{"atl":[[150,4]],"id":41401491},{"atl":[[150,4]],"id":52032624},{"spn":75.87,"spf":"NaN","id":52032624},{"atl":[[150,4]],"id":4065261},{"spn":75.87,"spf":"NaN","id":4065261},{"atl":[[150,4]],"id":69176457},{"spn":75.87,"spf":"NaN","id":69176457},{"atl":[[150,4]],"id":65040144},{"spn":75.87,"spf":"NaN","id":65040144}],"con":true,"img":false}]}
{"op":"mcm","clk":"11539126212","pt":1719475682884,"mc":[{"id":"1.230180134","marketDefinition":{"bspMarket":true,"turnInPlayEnabled":false,"persistenceEnabled":false,"marketBaseRate":5.0,"eventId":"33376437","eventTypeId":"4339","numberOfWinners":1,"bettingType":"ODDS","marketType":"WIN","marketTime":"2024-06-27T16:54:00.000Z","suspendTime":"2024-06-27T16:54:00.000Z","bspReconciled":false,"complete":true,"inPlay":false,"crossMatching":true,"runnersVoidable":false,"numberOfActiveRunners":5,"betDelay":0,"status":"OPEN","runners":[{"status":"ACTIVE","sortPriority":1,"id":4065261,"name":"2. Manx Storm"},{"status":"ACTIVE","sortPriority":2,"id":69176457,"name":"3. Franco Eve"},{"status":"ACTIVE","sortPriority":3,"id":41401491,"name":"4. Connors Bullet"},{"status":"ACTIVE","sortPriority":4,"id":65040144,"name":"5. Diegos Talavara"},{"status":"ACTIVE","sortPriority":5,"id":52032624,"name":"6. Limekiln Chic"}],"regulators":["MR_INT"],"venue":"Towcester","countryCode":"GB","discountAllowed":true,"timezone":"Europe/London","openDate":"2024-06-27T13:33:00.000Z","version":5994767143,"name":"A7 500m","eventName":"Towcester 27th Jun"},"rc":[{"atb":[[1.74,16.28],[1.02,16.48]],"id":41401491},{"atl":[[150,4],[21,4],[11.5,2],[990,0.17],[15.5,3]],"id":41401491},{"spn":6.62,"spf":"NaN","id":41401491},{"atb":[[1.73,21.82],[1.03,10.99],[1.74,6.55]],"id":52032624},{"atl":[[150,4],[990,0.17]],"id":52032624},{"spn":75.87,"spf":"NaN","id":52032624},{"atb":[[1.73,17.46],[1.74,6.55],[1.02,16.48]],"id":4065261},{"atl":[[150,4],[1000,0.17]],"id":4065261},{"spn":75.87,"spf":"NaN","id":4065261},{"atb":[[1.73,20.37],[1.03,10.99],[1.74,6.55]],"id":69176457},{"atl":[[150,4],[990,0.17]],"id":69176457},{"spn":75.87,"spf":"NaN","id":69176457},{"atb":[[1.73,14.55],[1.74,6.55],[1.02,16.48]],"id":65040144},{"atl":[[150,4],[990,0.17]],"id":65040144},{"spn":75.87,"spf":"NaN","id":65040144}],"con":true,"img":true}]}
{"op":"mcm","clk":"11539128191","pt":1719475714768,"mc":[{"id":"1.230180134","rc":[{"atb":[[1.74,16.28],[1.02,16.48]],"id":41401491},{"atb":[[1.73,0],[1.03,10.99],[1.74,6.55]],"id":52032624},{"atb":[[1.73,0],[1.74,6.55],[1.02,16.48]],"id":4065261},{"atb":[[1.73,0],[1.03,10.99],[1.74,6.55]],"id":69176457},{"atb":[[1.73,0],[1.74,6.55],[1.02,16.48]],"id":65040144}],"con":true,"img":false}]}
{"op":"mcm","clk":"11539128197","pt":1719475714870,"mc":[{"id":"1.230180134","rc":[{"atb":[[1.75,21.82]],"id":52032624},{"atb":[[1.75,17.46]],"id":4065261},{"atb":[[1.75,20.37]],"id":69176457},{"atb":[[1.75,14.55]],"id":65040144}],"con":true,"img":false}]}
{"op":"mcm","clk":"11539132263","pt":1719475781920,"mc":[{"id":"1.230180134","rc":[{"spn":75.87,"spf":"NaN","id":52032624},{"atb":[[1.74,3.16]],"id":4065261},{"spn":75.87,"spf":"NaN","id":4065261},{"spn":75.87,"spf":"NaN","id":69176457},{"spn":75.87,"spf":"NaN","id":65040144}],"con":true,"img":false}]}
{"op":"mcm","clk":"11539132330","pt":1719475783002,"mc":[{"id":"1.230180134","rc":[{"atb":[[1.74,3.16]],"id":52032624}],"con":true,"img":false}]}
{"op":"mcm","clk":"11539132354","pt":1719475783410,"mc":[{"id":"1.230180134","rc":[{"atb":[[1.74,3.16]],"id":65040144}],"con":true,"img":false}]}
{"op":"mcm","clk":"11539132372","pt":1719475783720,"mc":[{"id":"1.230180134","rc":[{"atb":[[1.74,3.16]],"id":69176457}],"con":true,"img":false}]}
{"op":"mcm","clk":"11539132620","pt":1719475787531,"mc":[{"id":"1.230180134","rc":[{"atb":[[1.76,3.38]],"id":52032624}],"con":true,"img":false}]}
{"op":"mcm","clk":"11539132765","pt":1719475789340,"mc":[{"id":"1.230180134","rc":[{"atb":[[1.76,3.38]],"id":69176457}],"con":true,"img":false}]}
{"op":"mcm","clk":"11539132781","pt":1719475789541,"mc":[{"id":"1.230180134","rc":[{"atb":[[1.76,3.38]],"id":4065261}],"con":true,"img":false}]}
{"op":"mcm","clk":"11539132811","pt":1719475790056,"mc":[{"id":"1.230180134","rc":[{"atb":[[1.76,3.38]],"id":65040144}],"con":true,"img":false}]}
{"op":"mcm","clk":"11539134216","pt":1719475809447,"mc":[{"id":"1.230180134","rc":[{"atb":[[1.74,0]],"id":52032624},{"atb":[[1.74,0]],"id":4065261},{"atb":[[1.74,0]],"id":69176457},{"atb":[[1.74,0]],"id":65040144}],"con":true,"img":false}]}
{"op":"mcm","clk":"11539152973","pt":1719476112663,"mc":[{"id":"1.230180134","rc":[{"spn":75.88,"spf":"NaN","id":52032624},{"spn":75.88,"spf":"NaN","id":4065261},{"atb":[[1.76,6.55]],"id":69176457},{"spn":75.88,"spf":"NaN","id":69176457},{"atb":[[1.76,6.55]],"id":65040144},{"spn":75.88,"spf":"NaN","id":65040144}],"con":true,"img":false}]}
{"op":"mcm","clk":"11539152992","pt":1719476112866,"mc":[{"id":"1.230180134","rc":[{"atb":[[1.76,6.55]],"id":4065261}],"con":true,"img":false}]}
{"op":"mcm","clk":"11539153039","pt":1719476113485,"mc":[{"id":"1.230180134","rc":[{"atb":[[1.76,6.55]],"id":52032624}],"con":true,"img":false}]}
{"op":"mcm","clk":"11539341594","pt":1719479313273,"mc":[{"id":"1.230180134","rc":[{"atb":[[1.74,16.28],[1.02,16.47]],"id":41401491},{"atb":[[1.03,10.98],[1.75,0],[1.76,6.54]],"id":52032624},{"atb":[[1.02,16.47],[1.75,0],[1.76,6.54]],"id":4065261},{"atb":[[1.03,10.98],[1.75,0],[1.76,6.54]],"id":69176457},{"atb":[[1.02,16.47],[1.75,0],[1.76,6.54]],"id":65040144}],"con":true,"img":false}]}
{"op":"mcm","clk":"11539341602","pt":1719479313373,"mc":[{"id":"1.230180134","rc":[{"atb":[[1.77,21.82]],"id":52032624},{"atb":[[1.77,17.46]],"id":4065261},{"atb":[[1.77,20.37]],"id":69176457},{"atb":[[1.77,14.55]],"id":65040144}],"con":true,"img":false}]}
{"op":"mcm","clk":"11539346049","pt":1719479384978,"mc":[{"id":"1.230180134","rc":[{"spn":75.88,"spf":"NaN","id":52032624},{"atb":[[1.76,3.38]],"id":4065261},{"spn":75.88,"spf":"NaN","id":4065261},{"atb":[[1.76,3.38]],"id":69176457},{"spn":75.88,"spf":"NaN","id":69176457},{"spn":75.88,"spf":"NaN","id":65040144}],"con":true,"img":false}]}
{"op":"mcm","clk":"11539346108","pt":1719479385865,"mc":[{"id":"1.230180134","rc":[{"atb":[[1.76,3.38]],"id":52032624}],"con":true,"img":false}]}
{"op":"mcm","clk":"11539346129","pt":1719479386173,"mc":[{"id":"1.230180134","rc":[{"atb":[[1.76,3.38]],"id":65040144}],"con":true,"img":false}]}
{"op":"mcm","clk":"11539347856","pt":1719479412620,"mc":[{"id":"1.230180134","rc":[{"atb":[[1.76,0]],"id":69176457}],"con":true,"img":false}]}
{"op":"mcm","clk":"11539347882","pt":1719479413093,"mc":[{"id":"1.230180134","rc":[{"atb":[[1.76,0]],"id":65040144}],"con":true,"img":false}]}
{"op":"mcm","clk":"11539348005","pt":1719479415212,"mc":[{"id":"1.230180134","rc":[{"atb":[[1.76,0]],"id":52032624}],"con":true,"img":false}]}
{"op":"mcm","clk":"11539348034","pt":1719479415732,"mc":[{"id":"1.230180134","rc":[{"atb":[[1.76,0]],"id":4065261}],"con":true,"img":false}]}
{"op":"mcm","clk":"11539348148","pt":1719479417709,"mc":[{"id":"1.230180134","rc":[{"atb":[[1.78,3.38]],"id":69176457}],"con":true,"img":false}]}
{"op":"mcm","clk":"11539348219","pt":1719479418906,"mc":[{"id":"1.230180134","rc":[{"atb":[[1.78,3.38]],"id":65040144}],"con":true,"img":false}]}
{"op":"mcm","clk":"11539348248","pt":1719479419424,"mc":[{"id":"1.230180134","rc":[{"atb":[[1.78,3.38]],"id":4065261}],"con":true,"img":false}]}
{"op":"mcm","clk":"11539348278","pt":1719479420138,"mc":[{"id":"1.230180134","rc":[{"atb":[[1.78,3.38]],"id":52032624}],"con":true,"img":false}]}
{"op":"mcm","clk":"11539367306","pt":1719479702518,"mc":[{"id":"1.230180134","rc":[{"spn":75.89,"spf":"NaN","id":52032624},{"atb":[[1.78,6.54]],"id":4065261},{"spn":75.89,"spf":"NaN","id":4065261},{"spn":75.89,"spf":"NaN","id":69176457},{"spn":75.89,"spf":"NaN","id":65040144}],"con":true,"img":false}]}
{"op":"mcm","clk":"11539367329","pt":1719479702729,"mc":[{"id":"1.230180134","rc":[{"atb":[[1.78,6.54]],"id":65040144}],"con":true,"img":false}]}
{"op":"mcm","clk":"11539367483","pt":1719479704521,"mc":[{"id":"1.230180134","rc":[{"atb":[[1.78,6.54]],"id":69176457}],"con":true,"img":false}]}
{"op":"mcm","clk":"11539367561","pt":1719479705553,"mc":[{"id":"1.230180134","rc":[{"atb":[[1.78,6.54]],"id":52032624}],"con":true,"img":false}]}
{"op":"mcm","clk":"11539475617","pt":1719481726219,"mc":[{"id":"1.230180134","rc":[{"spb":[[1000,28.65]],"id":65040144},{"spn":150.0,"spf":"Infinity","id":65040144}],"con":true,"img":false}]}
{"op":"mcm","clk":"11539545678","pt":1719482913615,"mc":[{"id":"1.230180134","rc":[{"atb":[[1.74,16.28],[1.02,16.47]],"id":41401491},{"atb":[[1.03,10.98],[1.78,6.54],[1.77,0]],"id":52032624},{"atb":[[1.02,16.47],[1.78,6.54],[1.77,0]],"id":4065261},{"atb":[[1.03,10.98],[1.78,6.54],[1.77,0]],"id":69176457},{"atb":[[1.02,16.47],[1.78,6.54],[1.77,0]],"id":65040144},{"spb":[[1000,28.62]],"id":65040144}],"con":true,"img":false}]}
{"op":"mcm","clk":"11539545684","pt":1719482913710,"mc":[{"id":"1.230180134","rc":[{"atb":[[1.79,21.82]],"id":52032624},{"atb":[[1.79,17.45]],"id":4065261},{"atb":[[1.79,20.36]],"id":69176457},{"atb":[[1.79,14.54]],"id":65040144}],"con":true,"img":false}]}
{"op":"mcm","clk":"11539547496","pt":1719482940198,"mc":[{"id":"1.230180134","rc":[{"atb":[[1.78,3.16]],"id":4065261},{"atb":[[1.78,3.16]],"id":69176457}],"con":true,"img":false}]}
{"op":"mcm","clk":"11539547554","pt":1719482941336,"mc":[{"id":"1.230180134","rc":[{"atb":[[1.78,3.16]],"id":52032624}],"con":true,"img":false}]}
{"op":"mcm","clk":"11539547571","pt":1719482941709,"mc":[{"id":"1.230180134","rc":[{"atb":[[1.78,3.16]],"id":65040144}],"con":true,"img":false}]}
{"op":"mcm","clk":"11539547743","pt":1719482944646,"mc":[{"id":"1.230180134","rc":[{"atb":[[1.8,3.38]],"id":69176457}],"con":true,"img":false}]}
{"op":"mcm","clk":"11539547753","pt":1719482944839,"mc":[{"id":"1.230180134","rc":[{"atb":[[1.8,3.38]],"id":4065261}],"con":true,"img":false}]}
{"op":"mcm","clk":"11539547766","pt":1719482945053,"mc":[{"id":"1.230180134","rc":[{"atb":[[1.8,3.38]],"id":52032624}],"con":true,"img":false}]}
{"op":"mcm","clk":"11539547787","pt":1719482945355,"mc":[{"id":"1.230180134","rc":[{"atb":[[1.8,3.38]],"id":65040144}],"con":true,"img":false}]}
{"op":"mcm","clk":"11539552693","pt":1719483020165,"mc":[{"id":"1.230180134","rc":[{"spn":75.9,"spf":"NaN","id":52032624},{"atb":[[1.78,0]],"id":4065261},{"spn":75.9,"spf":"NaN","id":4065261},{"atb":[[1.78,0]],"id":69176457},{"spn":75.9,"spf":"NaN","id":69176457}],"con":true,"img":false}]}
{"op":"mcm","clk":"11539552751","pt":1719483020741,"mc":[{"id":"1.230180134","rc":[{"atb":[[1.78,0]],"id":65040144}],"con":true,"img":false}]}
{"op":"mcm","clk":"11539552781","pt":1719483021065,"mc":[{"id":"1.230180134","rc":[{"atb":[[1.8,6.54]],"id":69176457}],"con":true,"img":false}]}
{"op":"mcm","clk":"11539552797","pt":1719483021254,"mc":[{"id":"1.230180134","rc":[{"atb":[[1.8,6.54]],"id":4065261}],"con":true,"img":false}]}
{"op":"mcm","clk":"11539552904","pt":1719483022447,"mc":[{"id":"1.230180134","rc":[{"atb":[[1.78,0]],"id":52032624}],"con":true,"img":false}]}
{"op":"mcm","clk":"11539552917","pt":1719483022762,"mc":[{"id":"1.230180134","rc":[{"atb":[[1.8,6.54]],"id":65040144}],"con":true,"img":false}]}
{"op":"mcm","clk":"11539552974","pt":1719483023441,"mc":[{"id":"1.230180134","rc":[{"atb":[[1.8,6.54]],"id":52032624}],"con":true,"img":false}]}
{"op":"mcm","clk":"11539753455","pt":1719485688329,"mc":[{"id":"1.230180134","rc":[{"atb":[[2.26,2]],"id":52032624},{"spn":76.13,"spf":"NaN","id":52032624}],"con":true,"img":false}]}
{"op":"mcm","clk":"11539793026","pt":1719486282024,"mc":[{"id":"1.230180134","rc":[{"atb":[[1.74,16.28],[1.02,16.47]],"id":41401491},{"atb":[[1.8,6.54],[1.79,21.82],[1.03,10.98]],"id":52032624},{"atb":[[1.8,6.54],[1.79,17.46],[1.02,16.47]],"id":4065261},{"atb":[[1.8,6.54],[1.79,20.37],[1.03,10.98]],"id":69176457},{"atb":[[1.8,6.54],[1.79,14.55],[1.02,16.47]],"id":65040144},{"spb":[[1000,100.23]],"id":65040144}],"con":true,"img":false}]}
{"op":"mcm","clk":"11539817770","pt":1719486511142,"mc":[{"id":"1.230180134","rc":[{"atb":[[1.79,0]],"id":52032624},{"atb":[[1.79,0]],"id":4065261},{"atb":[[1.79,0]],"id":69176457},{"atb":[[1.79,0]],"id":65040144}],"con":true,"img":false}]}
{"op":"mcm","clk":"11539817777","pt":1719486511240,"mc":[{"id":"1.230180134","rc":[{"atb":[[1.81,21.82]],"id":52032624},{"atb":[[1.81,17.46]],"id":4065261},{"atb":[[1.81,20.37]],"id":69176457},{"atb":[[1.81,14.55]],"id":65040144}],"con":true,"img":false}]}
{"op":"mcm","clk":"11539818064","pt":1719486514557,"mc":[{"id":"1.230180134","rc":[{"atb":[[1.8,3.38]],"id":65040144}],"con":true,"img":false}]}
{"op":"mcm","clk":"11539818080","pt":1719486514758,"mc":[{"id":"1.230180134","rc":[{"atb":[[1.8,3.38]],"id":52032624},{"atb":[[1.8,3.38]],"id":4065261}],"con":true,"img":false}]}
{"op":"mcm","clk":"11539818122","pt":1719486515223,"mc":[{"id":"1.230180134","rc":[{"atb":[[1.8,3.38]],"id":69176457}],"con":true,"img":false}]}
{"op":"mcm","clk":"11539818137","pt":1719486515430,"mc":[{"id":"1.230180134","rc":[{"atb":[[1.82,3.16]],"id":65040144}],"con":true,"img":false}]}
{"op":"mcm","clk":"11539818186","pt":1719486516044,"mc":[{"id":"1.230180134","rc":[{"atb":[[1.82,3.16]],"id":69176457}],"con":true,"img":false}]}
{"op":"mcm","clk":"11539818337","pt":1719486517464,"mc":[{"id":"1.230180134","rc":[{"atb":[[1.82,3.16]],"id":4065261}],"con":true,"img":false}]}
{"op":"mcm","clk":"11539818414","pt":1719486518047,"mc":[{"id":"1.230180134","rc":[{"atb":[[1.82,3.16]],"id":52032624}],"con":true,"img":false}]}
{"op":"mcm","clk":"11539824216","pt":1719486584221,"mc":[{"id":"1.230180134","rc":[{"atb":[[1.8,0]],"id":4065261},{"spn":75.91,"spf":"NaN","id":4065261},{"spn":75.91,"spf":"NaN","id":69176457}],"con":true,"img":false}]}
{"op":"mcm","clk":"11539824224","pt":1719486584327,"mc":[{"id":"1.230180134","rc":[{"atb":[[1.8,0]],"id":69176457}],"con":true,"img":false}]}
{"op":"mcm","clk":"11539824274","pt":1719486585049,"mc":[{"id":"1.230180134","rc":[{"atb":[[1.8,0]],"id":52032624}],"con":true,"img":false}]}
{"op":"mcm","clk":"11539824333","pt":1719486585835,"mc":[{"id":"1.230180134","rc":[{"atb":[[1.8,0]],"id":65040144}],"con":true,"img":false}]}
{"op":"mcm","clk":"11539825565","pt":1719486602148,"mc":[{"id":"1.230180134","rc":[{"atb":[[1.82,6.54]],"id":52032624}],"con":true,"img":false}]}
{"op":"mcm","clk":"11539825578","pt":1719486602356,"mc":[{"id":"1.230180134","rc":[{"atb":[[1.82,6.54]],"id":69176457}],"con":true,"img":false}]}
{"op":"mcm","clk":"11539825588","pt":1719486602556,"mc":[{"id":"1.230180134","rc":[{"atb":[[1.82,6.54]],"id":4065261}],"con":true,"img":false}]}
{"op":"mcm","clk":"11539825668","pt":1719486603649,"mc":[{"id":"1.230180134","rc":[{"atb":[[1.82,6.54]],"id":65040144}],"con":true,"img":false}]}
{"op":"mcm","clk":"11539840903","pt":1719486811229,"mc":[{"id":"1.230180134","rc":[{"atb":[[1.81,0]],"id":52032624},{"atb":[[1.81,0]],"id":4065261},{"atb":[[1.81,0]],"id":69176457},{"atb":[[1.81,0]],"id":65040144}],"con":true,"img":false}]}
{"op":"mcm","clk":"11539840909","pt":1719486811332,"mc":[{"id":"1.230180134","rc":[{"atb":[[1.83,21.82]],"id":52032624},{"atb":[[1.83,17.46]],"id":4065261},{"atb":[[1.83,20.37]],"id":69176457},{"atb":[[1.83,14.55]],"id":65040144}],"con":true,"img":false}]}
{"op":"mcm","clk":"11539841427","pt":1719486819749,"mc":[{"id":"1.230180134","rc":[{"atb":[[1.82,3.38]],"id":52032624},{"atb":[[1.82,3.38]],"id":4065261},{"atb":[[1.82,3.38]],"id":69176457},{"atb":[[1.82,3.38]],"id":65040144}],"con":true,"img":false}]}
{"op":"mcm","clk":"11539842910","pt":1719486842153,"mc":[{"id":"1.230180134","rc":[{"atb":[[1.82,0]],"id":52032624},{"atb":[[1.82,0]],"id":4065261},{"atb":[[1.82,0]],"id":69176457},{"atb":[[1.82,0]],"id":65040144}],"con":true,"img":false}]}
{"op":"mcm","clk":"11539848397","pt":1719486919592,"mc":[{"id":"1.230180134","rc":[{"spn":75.91,"spf":"NaN","id":4065261},{"spn":75.91,"spf":"NaN","id":69176457},{"atb":[[1.84,3.38]],"id":65040144}],"con":true,"img":false}]}
{"op":"mcm","clk":"11539848418","pt":1719486919757,"mc":[{"id":"1.230180134","rc":[{"atb":[[1.84,3.38]],"id":69176457}],"con":true,"img":false}]}
{"op":"mcm","clk":"11539848423","pt":1719486919904,"mc":[{"id":"1.230180134","rc":[{"atb":[[1.84,3.38]],"id":4065261}],"con":true,"img":false}]}
{"op":"mcm","clk":"11539848503","pt":1719486921199,"mc":[{"id":"1.230180134","rc":[{"atb":[[1.84,3.38]],"id":52032624}],"con":true,"img":false}]}
{"op":"mcm","clk":"11539850136","pt":1719486942714,"mc":[{"id":"1.230180134","rc":[{"atb":[[1.84,6.54]],"id":4065261}],"con":true,"img":false}]}
{"op":"mcm","clk":"11539850157","pt":1719486942913,"mc":[{"id":"1.230180134","rc":[{"atb":[[1.84,6.54]],"id":69176457}],"con":true,"img":false}]}
{"op":"mcm","clk":"11539850174","pt":1719486943123,"mc":[{"id":"1.230180134","rc":[{"atb":[[1.84,6.54]],"id":65040144}],"con":true,"img":false}]}
{"op":"mcm","clk":"11539850194","pt":1719486943325,"mc":[{"id":"1.230180134","rc":[{"atb":[[1.84,6.54]],"id":52032624}],"con":true,"img":false}]}
{"op":"mcm","clk":"11540014619","pt":1719489001551,"mc":[{"id":"1.230180134","rc":[{"atb":[[1.16,150]],"id":41401491},{"atl":[[550,2]],"id":41401491},{"atl":[[560,2]],"id":52032624},{"atb":[[1.16,150]],"id":4065261},{"atl":[[370,2]],"id":4065261},{"spn":75.92,"spf":"NaN","id":4065261},{"atb":[[1.16,150]],"id":69176457},{"atl":[[390,2]],"id":69176457},{"spn":75.92,"spf":"NaN","id":69176457},{"atb":[[1.16,150]],"id":65040144},{"atl":[[270,2]],"id":65040144}],"con":true,"img":false}]}
{"op":"mcm","clk":"11540014630","pt":1719489001656,"mc":[{"id":"1.230180134","rc":[{"atb":[[1.16,150]],"id":52032624}],"con":true,"img":false}]}
{"op":"mcm","clk":"11540034999","pt":1719489244823,"mc":[{"id":"1.230180134","rc":[{"atl":[[36,12],[21,8]],"id":69176457},{"spn":11.42,"spf":"NaN","id":69176457}],"con":true,"img":false}]}
{"op":"mcm","clk":"11540035008","pt":1719489244917,"mc":[{"id":"1.230180134","rc":[{"atl":[[16,8],[27,12]],"id":41401491},{"atl":[[32,8],[55,12]],"id":65040144}],"con":true,"img":false}]}
{"op":"mcm","clk":"11540136580","pt":1719490402968,"mc":[{"id":"1.230180134","rc":[{"atb":[[1.83,0],[1.84,6.54]],"id":52032624},{"atb":[[1.83,0],[1.84,6.54]],"id":4065261},{"atb":[[1.83,0],[1.84,6.54]],"id":69176457},{"atb":[[1.83,0],[1.84,6.54]],"id":65040144},{"spb":[[1000,100.39]],"id":65040144},{"spn":32.0,"spf":"Infinity","id":65040144}],"con":true,"img":false}]}
{"op":"mcm","clk":"11540136592","pt":1719490403066,"mc":[{"id":"1.230180134","rc":[{"atb":[[1.85,21.82]],"id":52032624},{"atb":[[1.85,17.46]],"id":4065261},{"atb":[[1.85,20.37]],"id":69176457},{"atb":[[1.85,14.55]],"id":65040144}],"con":true,"img":false}]}
{"op":"mcm","clk":"11540139993","pt":1719490436711,"mc":[{"id":"1.230180134","rc":[{"atb":[[1.84,3.16]],"id":4065261}],"con":true,"img":false}]}
{"op":"mcm","clk":"11540140035","pt":1719490437130,"mc":[{"id":"1.230180134","rc":[{"atb":[[1.84,3.16]],"id":65040144}],"con":true,"img":false}]}
{"op":"mcm","clk":"11540140050","pt":1719490437234,"mc":[{"id":"1.230180134","rc":[{"atb":[[1.84,3.16]],"id":52032624}],"con":true,"img":false}]}
{"op":"mcm","clk":"11540140116","pt":1719490437901,"mc":[{"id":"1.230180134","rc":[{"atb":[[1.84,3.16]],"id":69176457}],"con":true,"img":false}]}
{"op":"mcm","clk":"11540141384","pt":1719490450195,"mc":[{"id":"1.230180134","rc":[{"atb":[[1.86,3.38]],"id":4065261}],"con":true,"img":false}]}
{"op":"mcm","clk":"11540141482","pt":1719490451128,"mc":[{"id":"1.230180134","rc":[{"atb":[[1.86,3.38]],"id":65040144}],"con":true,"img":false}]}
{"op":"mcm","clk":"11540141515","pt":1719490451399,"mc":[{"id":"1.230180134","rc":[{"atb":[[1.86,3.38]],"id":52032624}],"con":true,"img":false}]}
{"op":"mcm","clk":"11540141637","pt":1719490452589,"mc":[{"id":"1.230180134","rc":[{"atb":[[1.86,3.38]],"id":69176457}],"con":true,"img":false}]}
{"op":"mcm","clk":"11540143093","pt":1719490465835,"mc":[{"id":"1.230180134","rc":[{"atb":[[1.84,0]],"id":4065261},{"spn":75.93,"spf":"NaN","id":4065261},{"spn":11.43,"spf":"NaN","id":69176457}],"con":true,"img":false}]}
{"op":"mcm","clk":"11540143138","pt":1719490466348,"mc":[{"id":"1.230180134","rc":[{"atb":[[1.84,0]],"id":52032624}],"con":true,"img":false}]}
{"op":"mcm","clk":"11540143156","pt":1719490466553,"mc":[{"id":"1.230180134","rc":[{"atb":[[1.84,0]],"id":65040144}],"con":true,"img":false}]}
{"op":"mcm","clk":"11540143337","pt":1719490468520,"mc":[{"id":"1.230180134","rc":[{"atb":[[1.84,0]],"id":69176457}],"con":true,"img":false}]}
{"op":"mcm","clk":"11540145010","pt":1719490484643,"mc":[{"id":"1.230180134","rc":[{"atb":[[1.86,6.54]],"id":65040144}],"con":true,"img":false}]}
{"op":"mcm","clk":"11540145221","pt":1719490486670,"mc":[{"id":"1.230180134","rc":[{"atb":[[1.86,6.54]],"id":52032624}],"con":true,"img":false}]}
{"op":"mcm","clk":"11540145300","pt":1719490487432,"mc":[{"id":"1.230180134","rc":[{"atb":[[1.86,6.54]],"id":69176457}],"con":true,"img":false}]}
{"op":"mcm","clk":"11540145375","pt":1719490488155,"mc":[{"id":"1.230180134","rc":[{"atb":[[1.86,6.54]],"id":4065261}],"con":true,"img":false}]}
{"op":"mcm","clk":"11540164845","pt":1719490699794,"mc":[{"id":"1.230180134","rc":[{"atb":[[1.85,0]],"id":52032624},{"atb":[[1.85,0]],"id":4065261},{"atb":[[1.85,0]],"id":69176457},{"atb":[[1.85,0]],"id":65040144}],"con":true,"img":false}]}
{"op":"mcm","clk":"11540164852","pt":1719490699895,"mc":[{"id":"1.230180134","rc":[{"atb":[[1.87,21.82]],"id":52032624},{"atb":[[1.87,17.46]],"id":4065261},{"atb":[[1.87,20.37]],"id":69176457},{"atb":[[1.87,14.55]],"id":65040144}],"con":true,"img":false}]}
{"op":"mcm","clk":"11540168201","pt":1719490742154,"mc":[{"id":"1.230180134","rc":[{"atb":[[1.86,3.38]],"id":52032624}],"con":true,"img":false}]}
{"op":"mcm","clk":"11540168274","pt":1719490743038,"mc":[{"id":"1.230180134","rc":[{"atb":[[1.86,3.38]],"id":65040144}],"con":true,"img":false}]}
{"op":"mcm","clk":"11540168303","pt":1719490743558,"mc":[{"id":"1.230180134","rc":[{"atb":[[1.86,3.38]],"id":4065261}],"con":true,"img":false}]}
{"op":"mcm","clk":"11540168324","pt":1719490743870,"mc":[{"id":"1.230180134","rc":[{"atb":[[1.86,3.38]],"id":69176457}],"con":true,"img":false}]}
{"op":"mcm","clk":"11540168376","pt":1719490744641,"mc":[{"id":"1.230180134","rc":[{"atb":[[1.88,3.16]],"id":4065261}],"con":true,"img":false}]}
{"op":"mcm","clk":"11540168428","pt":1719490745259,"mc":[{"id":"1.230180134","rc":[{"atb":[[1.88,3.16]],"id":65040144}],"con":true,"img":false}]}
{"op":"mcm","clk":"11540168473","pt":1719490745674,"mc":[{"id":"1.230180134","rc":[{"atb":[[1.88,3.16]],"id":69176457}],"con":true,"img":false}]}
{"op":"mcm","clk":"11540168536","pt":1719490746449,"mc":[{"id":"1.230180134","rc":[{"atb":[[1.88,3.16]],"id":52032624}],"con":true,"img":false}]}
{"op":"mcm","clk":"11540170620","pt":1719490776907,"mc":[{"id":"1.230180134","rc":[{"spn":75.94,"spf":"NaN","id":4065261},{"atb":[[1.86,0]],"id":69176457},{"spn":11.44,"spf":"NaN","id":69176457}],"con":true,"img":false}]}
{"op":"mcm","clk":"11540170645","pt":1719490777270,"mc":[{"id":"1.230180134","rc":[{"atb":[[1.86,0]],"id":4065261}],"con":true,"img":false}]}
{"op":"mcm","clk":"11540170660","pt":1719490777476,"mc":[{"id":"1.230180134","rc":[{"atb":[[1.86,0]],"id":65040144}],"con":true,"img":false}]}
{"op":"mcm","clk":"11540170683","pt":1719490777887,"mc":[{"id":"1.230180134","rc":[{"atb":[[1.86,0]],"id":52032624}],"con":true,"img":false}]}
{"op":"mcm","clk":"11540173011","pt":1719490808436,"mc":[{"id":"1.230180134","rc":[{"atb":[[1.88,6.54]],"id":69176457}],"con":true,"img":false}]}
{"op":"mcm","clk":"11540173066","pt":1719490809156,"mc":[{"id":"1.230180134","rc":[{"atb":[[1.88,6.54]],"id":52032624}],"con":true,"img":false}]}
{"op":"mcm","clk":"11540173083","pt":1719490809460,"mc":[{"id":"1.230180134","rc":[{"atb":[[1.88,6.54]],"id":65040144}],"con":true,"img":false}]}
{"op":"mcm","clk":"11540173125","pt":1719490810035,"mc":[{"id":"1.230180134","rc":[{"atb":[[1.88,6.54]],"id":4065261}],"con":true,"img":false}]}
{"op":"mcm","clk":"11540311356","pt":1719492843481,"mc":[{"id":"1.230180134","rc":[{"atb":[[2.14,1.98]],"id":41401491},{"spn":6.82,"spf":"NaN","id":41401491},{"atb":[[5,1]],"id":52032624},{"spn":77.5,"spf":"NaN","id":52032624},{"atb":[[5,1]],"id":4065261},{"spn":77.5,"spf":"NaN","id":4065261},{"atb":[[3.55,1]],"id":69176457},{"spn":12.27,"spf":"NaN","id":69176457},{"atb":[[5,1]],"id":65040144}],"con":true,"img":false}]}
{"op":"mcm","clk":"11540382365","pt":1719493800460,"mc":[{"id":"1.230180134","rc":[{"atb":[[1.74,16.3],[1.02,16.49]],"id":41401491},{"atl":[[990,0.17]],"id":41401491},{"atb":[[1.03,11],[1.88,6.54],[1.51,196.08],[1.87,21.85]],"id":52032624},{"atl":[[990,0.17]],"id":52032624},{"atb":[[1.88,6.54],[1.02,16.49],[1.51,196.08],[1.87,17.48]],"id":4065261},{"atl":[[1000,0.17]],"id":4065261},{"atb":[[1.03,11],[1.88,6.54],[1.51,196.08],[1.87,20.39]],"id":69176457},{"atl":[[990,0.17]],"id":69176457},{"atb":[[1.88,6.54],[1.02,16.49],[1.51,196.08],[1.87,14.56]],"id":65040144},{"atl":[[990,0.17]],"id":65040144},{"spb":[[1000,100.5]],"id":65040144}],"con":true,"img":false}]}
{"op":"mcm","clk":"11540398193","pt":1719494000227,"mc":[{"id":"1.230180134","rc":[{"atb":[[1.87,0]],"id":52032624},{"atb":[[1.87,0]],"id":4065261},{"atb":[[1.87,0]],"id":69176457},{"atb":[[1.87,0]],"id":65040144}],"con":true,"img":false}]}
{"op":"mcm","clk":"11540398201","pt":1719494000279,"mc":[{"id":"1.230180134","rc":[{"atb":[[1.89,21.85]],"id":52032624},{"atb":[[1.89,17.48]],"id":4065261},{"atb":[[1.89,20.39]],"id":69176457},{"atb":[[1.89,14.56]],"id":65040144}],"con":true,"img":false}]}
{"op":"mcm","clk":"11540399592","pt":1719494017135,"mc":[{"id":"1.230180134","rc":[{"atb":[[1.88,3.16]],"id":69176457}],"con":true,"img":false}]}
{"op":"mcm","clk":"11540399611","pt":1719494017450,"mc":[{"id":"1.230180134","rc":[{"atb":[[1.88,3.16]],"id":4065261}],"con":true,"img":false}]}
{"op":"mcm","clk":"11540399634","pt":1719494017713,"mc":[{"id":"1.230180134","rc":[{"atb":[[1.88,3.16]],"id":65040144}],"con":true,"img":false}]}
{"op":"mcm","clk":"11540399676","pt":1719494018118,"mc":[{"id":"1.230180134","rc":[{"atb":[[1.88,3.16]],"id":52032624}],"con":true,"img":false}]}
{"op":"mcm","clk":"11540399739","pt":1719494018843,"mc":[{"id":"1.230180134","rc":[{"atb":[[1.9,3.38]],"id":69176457}],"con":true,"img":false}]}
{"op":"mcm","clk":"11540399751","pt":1719494019054,"mc":[{"id":"1.230180134","rc":[{"atb":[[1.9,3.38]],"id":4065261}],"con":true,"img":false}]}
{"op":"mcm","clk":"11540399802","pt":1719494019517,"mc":[{"id":"1.230180134","rc":[{"atb":[[1.9,3.38]],"id":65040144}],"con":true,"img":false}]}
{"op":"mcm","clk":"11540399806","pt":1719494019624,"mc":[{"id":"1.230180134","rc":[{"atb":[[1.9,3.38]],"id":52032624}],"con":true,"img":false}]}
{"op":"mcm","clk":"11540401435","pt":1719494039135,"mc":[{"id":"1.230180134","rc":[{"atb":[[1.88,0]],"id":4065261}],"con":true,"img":false}]}
{"op":"mcm","clk":"11540401451","pt":1719494039160,"mc":[{"id":"1.230180134","rc":[{"atb":[[1.88,0]],"id":52032624}],"con":true,"img":false}]}
{"op":"mcm","clk":"11540401481","pt":1719494039364,"mc":[{"id":"1.230180134","rc":[{"atb":[[1.88,0]],"id":69176457}],"con":true,"img":false}]}
{"op":"mcm","clk":"11540401628","pt":1719494041138,"mc":[{"id":"1.230180134","rc":[{"atb":[[1.88,0]],"id":65040144}],"con":true,"img":false}]}
{"op":"mcm","clk":"11540402256","pt":1719494048060,"mc":[{"id":"1.230180134","rc":[{"atb":[[1.9,6.54]],"id":52032624}],"con":true,"img":false}]}
{"op":"mcm","clk":"11540402310","pt":1719494048798,"mc":[{"id":"1.230180134","rc":[{"atb":[[1.9,6.54]],"id":4065261}],"con":true,"img":false}]}
{"op":"mcm","clk":"11540402352","pt":1719494049290,"mc":[{"id":"1.230180134","rc":[{"atb":[[1.9,6.54]],"id":69176457}],"con":true,"img":false}]}
{"op":"mcm","clk":"11540402466","pt":1719494050848,"mc":[{"id":"1.230180134","rc":[{"atb":[[1.9,6.54]],"id":65040144}],"con":true,"img":false}]}
{"op":"mcm","clk":"11540419469","pt":1719494298166,"mc":[{"id":"1.230180134","rc":[{"atb":[[1.89,0]],"id":52032624},{"atb":[[1.89,0]],"id":4065261},{"atb":[[1.89,0]],"id":69176457},{"atb":[[1.89,0]],"id":65040144}],"con":true,"img":false}]}
{"op":"mcm","clk":"11540419473","pt":1719494298273,"mc":[{"id":"1.230180134","rc":[{"atb":[[1.91,21.85]],"id":52032624},{"atb":[[1.91,17.48]],"id":4065261},{"atb":[[1.91,20.39]],"id":69176457},{"atb":[[1.91,14.56]],"id":65040144}],"con":true,"img":false}]}
{"op":"mcm","clk":"11540422390","pt":1719494333021,"mc":[{"id":"1.230180134","rc":[{"atb":[[1.9,3.38]],"id":4065261}],"con":true,"img":false}]}
{"op":"mcm","clk":"11540422408","pt":1719494333226,"mc":[{"id":"1.230180134","rc":[{"atb":[[1.9,3.38]],"id":69176457}],"con":true,"img":false}]}
{"op":"mcm","clk":"11540422445","pt":1719494333644,"mc":[{"id":"1.230180134","rc":[{"atb":[[1.9,3.38]],"id":65040144}],"con":true,"img":false}]}
{"op":"mcm","clk":"11540422544","pt":1719494334633,"mc":[{"id":"1.230180134","rc":[{"atb":[[1.9,3.38]],"id":52032624}],"con":true,"img":false}]}
{"op":"mcm","clk":"11540422652","pt":1719494335945,"mc":[{"id":"1.230180134","rc":[{"atb":[[1.92,3.16]],"id":4065261}],"con":true,"img":false}]}
{"op":"mcm","clk":"11540422720","pt":1719494336650,"mc":[{"id":"1.230180134","rc":[{"atb":[[1.92,3.16]],"id":65040144}],"con":true,"img":false}]}
{"op":"mcm","clk":"11540422731","pt":1719494336754,"mc":[{"id":"1.230180134","rc":[{"atb":[[1.92,3.16]],"id":69176457}],"con":true,"img":false}]}
{"op":"mcm","clk":"11540422742","pt":1719494336858,"mc":[{"id":"1.230180134","rc":[{"atb":[[1.92,3.16]],"id":52032624}],"con":true,"img":false}]}
{"op":"mcm","clk":"11540426668","pt":1719494382012,"mc":[{"id":"1.230180134","rc":[{"atb":[[1.9,0]],"id":69176457}],"con":true,"img":false}]}
{"op":"mcm","clk":"11540426680","pt":1719494382107,"mc":[{"id":"1.230180134","rc":[{"atb":[[1.9,0]],"id":65040144}],"con":true,"img":false}]}
{"op":"mcm","clk":"11540426728","pt":1719494382579,"mc":[{"id":"1.230180134","rc":[{"atb":[[1.9,0]],"id":52032624}],"con":true,"img":false}]}
{"op":"mcm","clk":"11540426744","pt":1719494382790,"mc":[{"id":"1.230180134","rc":[{"atb":[[1.9,0]],"id":4065261}],"con":true,"img":false}]}
{"op":"mcm","clk":"11540426781","pt":1719494383301,"mc":[{"id":"1.230180134","rc":[{"atb":[[1.92,6.54]],"id":65040144}],"con":true,"img":false}]}
{"op":"mcm","clk":"11540426812","pt":1719494383670,"mc":[{"id":"1.230180134","rc":[{"atb":[[1.92,6.54]],"id":69176457}],"con":true,"img":false}]}
{"op":"mcm","clk":"11540426832","pt":1719494383876,"mc":[{"id":"1.230180134","rc":[{"atb":[[1.92,6.54]],"id":52032624}],"con":true,"img":false}]}
{"op":"mcm","clk":"11540426856","pt":1719494384208,"mc":[{"id":"1.230180134","rc":[{"atb":[[1.92,6.54]],"id":4065261}],"con":true,"img":false}]}
{"op":"mcm","clk":"11540430755","pt":1719494426451,"mc":[{"id":"1.230180134","rc":[{"atb":[[2.14,0.98]],"id":41401491},{"trd":[[2.14,2]],"ltp":2.14,"tv":2.0,"id":41401491}],"con":true,"img":false}]}
{"op":"mcm","clk":"11540431086","pt":1719494430234,"mc":[{"id":"1.230180134","rc":[{"atb":[[2.14,1.98]],"id":41401491}],"con":true,"img":false}]}
{"op":"mcm","clk":"11540432073","pt":1719494440943,"mc":[{"id":"1.230180134","rc":[{"atl":[[2.22,8]],"id":41401491}],"con":true,"img":false}]}
{"op":"mcm","clk":"11540432962","pt":1719494450859,"mc":[{"id":"1.230180134","rc":[{"spn":2.18,"spf":"NaN","id":41401491},{"atb":[[1.92,3.38]],"id":4065261},{"atb":[[1.92,3.38]],"id":69176457}],"con":true,"img":false}]}
{"op":"mcm","clk":"11540432987","pt":1719494451059,"mc":[{"id":"1.230180134","rc":[{"atb":[[1.99,3.16]],"id":69176457}],"con":true,"img":false}]}
{"op":"mcm","clk":"11540432997","pt":1719494451165,"mc":[{"id":"1.230180134","rc":[{"atb":[[1.92,3.38]],"id":52032624}],"con":true,"img":false}]}
{"op":"mcm","clk":"11540433015","pt":1719494451366,"mc":[{"id":"1.230180134","rc":[{"atb":[[2.16,3.16]],"id":4065261}],"con":true,"img":false}]}
{"op":"mcm","clk":"11540433042","pt":1719494451680,"mc":[{"id":"1.230180134","rc":[{"atb":[[2.16,3.16]],"id":52032624}],"con":true,"img":false}]}
{"op":"mcm","clk":"11540433057","pt":1719494451887,"mc":[{"id":"1.230180134","rc":[{"atb":[[1.92,3.38]],"id":65040144}],"con":true,"img":false}]}
{"op":"mcm","clk":"11540433078","pt":1719494452099,"mc":[{"id":"1.230180134","rc":[{"atb":[[2.06,3.16]],"id":65040144}],"con":true,"img":false}]}
{"op":"mcm","clk":"11540434867","pt":1719494471675,"mc":[{"id":"1.230180134","rc":[{"atb":[[1.92,0]],"id":4065261}],"con":true,"img":false}]}
{"op":"mcm","clk":"11540434877","pt":1719494471779,"mc":[{"id":"1.230180134","rc":[{"atb":[[1.92,0]],"id":65040144}],"con":true,"img":false}]}
{"op":"mcm","clk":"11540434900","pt":1719494472095,"mc":[{"id":"1.230180134","rc":[{"atb":[[1.92,0]],"id":69176457}],"con":true,"img":false}]}
{"op":"mcm","clk":"11540434921","pt":1719494472295,"mc":[{"id":"1.230180134","rc":[{"atb":[[2.06,6.54]],"id":65040144}],"con":true,"img":false}]}
{"op":"mcm","clk":"11540434942","pt":1719494472500,"mc":[{"id":"1.230180134","rc":[{"atb":[[1.92,0]],"id":52032624}],"con":true,"img":false}]}
{"op":"mcm","clk":"11540434965","pt":1719494472813,"mc":[{"id":"1.230180134","rc":[{"atb":[[2.16,6.54]],"id":52032624},{"atb":[[2.16,6.54]],"id":4065261}],"con":true,"img":false}]}
{"op":"mcm","clk":"11540434988","pt":1719494473081,"mc":[{"id":"1.230180134","rc":[{"atb":[[1.99,6.54]],"id":69176457}],"con":true,"img":false}]}
{"op":"mcm","clk":"11540445791","pt":1719494598153,"mc":[{"id":"1.230180134","rc":[{"atb":[[1.91,0]],"id":69176457}],"con":true,"img":false}]}
{"op":"mcm","clk":"11540445803","pt":1719494598253,"mc":[{"id":"1.230180134","rc":[{"atb":[[2,20.39]],"id":69176457}],"con":true,"img":false}]}
{"op":"mcm","clk":"11540446438","pt":1719494605264,"mc":[{"id":"1.230180134","rc":[{"atb":[[1.99,3.38]],"id":69176457}],"con":true,"img":false}]}
{"op":"mcm","clk":"11540446568","pt":1719494606469,"mc":[{"id":"1.230180134","rc":[{"atb":[[2.02,3.16]],"id":69176457}],"con":true,"img":false}]}
{"op":"mcm","clk":"11540451429","pt":1719494663039,"mc":[{"id":"1.230180134","rc":[{"atb":[[1.99,0]],"id":69176457}],"con":true,"img":false}]}
{"op":"mcm","clk":"11540451492","pt":1719494663831,"mc":[{"id":"1.230180134","rc":[{"atb":[[2.02,6.54]],"id":69176457}],"con":true,"img":false}]}
{"op":"mcm","clk":"11540515230","pt":1719495387000,"mc":[{"id":"1.230180134","rc":[{"atb":[[2.14,0.74]],"id":41401491},{"trd":[[2.14,4.47]],"ltp":2.14,"tv":4.47,"id":41401491}],"con":true,"img":false}]}
{"op":"mcm","clk":"11540515415","pt":1719495389209,"mc":[{"id":"1.230180134","rc":[{"atb":[[2.04,2.17],[2.14,0]],"id":41401491}],"con":true,"img":false}]}
{"op":"mcm","clk":"11540516024","pt":1719495398227,"mc":[{"id":"1.230180134","rc":[{"atl":[[44,6.36]],"id":41401491}],"con":true,"img":false}]}
{"op":"mcm","clk":"11540516907","pt":1719495410651,"mc":[{"id":"1.230180134","rc":[{"atb":[[1.75,15.8]],"id":41401491},{"atb":[[2.16,16.76]],"id":52032624}],"con":true,"img":false}]}
{"op":"mcm","clk":"11540518793","pt":1719495434542,"mc":[{"id":"1.230180134","rc":[{"atb":[[2.16,13.37]],"id":52032624}],"con":true,"img":false}]}
{"op":"mcm","clk":"11540518822","pt":1719495434953,"mc":[{"id":"1.230180134","rc":[{"atb":[[2.18,3.38]],"id":52032624}],"con":true,"img":false}]}
{"op":"mcm","clk":"11540520910","pt":1719495460985,"mc":[{"id":"1.230180134","rc":[{"atb":[[1.75,34.43]],"id":41401491},{"spn":2.13,"spf":"NaN","id":41401491}],"con":true,"img":false}]}
{"op":"mcm","clk":"11540520968","pt":1719495461656,"mc":[{"id":"1.230180134","rc":[{"atb":[[2.18,15.22]],"id":52032624}],"con":true,"img":false}]}
{"op":"mcm","clk":"11540521542","pt":1719495469013,"mc":[{"id":"1.230180134","rc":[{"atb":[[2.16,10.21]],"id":52032624}],"con":true,"img":false}]}
{"op":"mcm","clk":"11540521557","pt":1719495469185,"mc":[{"id":"1.230180134","rc":[{"atb":[[2.2,3.16]],"id":52032624}],"con":true,"img":false}]}
{"op":"mcm","clk":"11540522361","pt":1719495478903,"mc":[{"id":"1.230180134","rc":[{"atb":[[5.6,6]],"id":52032624},{"atb":[[3.3,6]],"id":4065261},{"atb":[[2.3,6]],"id":69176457},{"atb":[[3.3,6]],"id":65040144}],"con":true,"img":false}]}
{"op":"mcm","clk":"11540522370","pt":1719495479009,"mc":[{"id":"1.230180134","rc":[{"atb":[[1.67,6]],"id":41401491}],"con":true,"img":false}]}
{"op":"mcm","clk":"11540522819","pt":1719495484117,"mc":[{"id":"1.230180134","rc":[{"atb":[[2.12,89.29]],"id":52032624},{"atb":[[2.12,89.29]],"id":4065261},{"atb":[[2.12,89.29]],"id":65040144}],"con":true,"img":false}]}
{"op":"mcm","clk":"11540522962","pt":1719495485791,"mc":[{"id":"1.230180134","rc":[{"atb":[[2.2,0]],"id":52032624},{"atb":[[2.16,3.38]],"id":4065261},{"atb":[[2.06,3.38]],"id":65040144}],"con":true,"img":false}]}
{"op":"mcm","clk":"11540524301","pt":1719495502218,"mc":[{"id":"1.230180134","rc":[{"atb":[[2.16,0]],"id":52032624}],"con":true,"img":false}]}
{"op":"mcm","clk":"11540524365","pt":1719495503101,"mc":[{"id":"1.230180134","rc":[{"atb":[[2.18,11.84]],"id":52032624},{"atb":[[2.16,0]],"id":4065261},{"atb":[[2.06,0]],"id":65040144}],"con":true,"img":false}]}
{"op":"mcm","clk":"11540524974","pt":1719495511037,"mc":[{"id":"1.230180134","rc":[{"atb":[[2.16,10.21]],"id":4065261}],"con":true,"img":false}]}
{"op":"mcm","clk":"11540524985","pt":1719495511138,"mc":[{"id":"1.230180134","rc":[{"atb":[[2.14,10.39]],"id":65040144}],"con":true,"img":false}]}
{"op":"mcm","clk":"11540524990","pt":1719495511242,"mc":[{"id":"1.230180134","rc":[{"atb":[[2.2,9.87]],"id":52032624}],"con":true,"img":false}]}
{"op":"mcm","clk":"11540531023","pt":1719495582914,"mc":[{"id":"1.230180134","rc":[{"atb":[[2.18,0]],"id":52032624},{"spn":77.8,"spf":"NaN","id":52032624}],"con":true,"img":false}]}
{"op":"mcm","clk":"11540531542","pt":1719495588920,"mc":[{"id":"1.230180134","rc":[{"atb":[[2.18,11.84]],"id":4065261}],"con":true,"img":false}]}
{"op":"mcm","clk":"11540531550","pt":1719495589019,"mc":[{"id":"1.230180134","rc":[{"atb":[[2.22,11.45]],"id":52032624}],"con":true,"img":false}]}
{"op":"mcm","clk":"11540531568","pt":1719495589235,"mc":[{"id":"1.230180134","rc":[{"atb":[[2.16,12.04]],"id":65040144}],"con":true,"img":false}]}
{"op":"mcm","clk":"11540533884","pt":1719495617078,"mc":[{"id":"1.230180134","rc":[{"atb":[[2.2,0]],"id":52032624},{"atb":[[2.16,0]],"id":4065261},{"atb":[[2.14,0]],"id":65040144}],"con":true,"img":false}]}
{"op":"mcm","clk":"11540535357","pt":1719495632198,"mc":[{"id":"1.230180134","rc":[{"atb":[[2.2,9.87]],"id":4065261}],"con":true,"img":false}]}
{"op":"mcm","clk":"11540535377","pt":1719495632403,"mc":[{"id":"1.230180134","rc":[{"atb":[[2.18,10.04]],"id":65040144}],"con":true,"img":false}]}
{"op":"mcm","clk":"11540535393","pt":1719495632615,"mc":[{"id":"1.230180134","rc":[{"atb":[[2.24,9.55]],"id":52032624}],"con":true,"img":false}]}
{"op":"mcm","clk":"11540538830","pt":1719495668750,"mc":[{"id":"1.230180134","rc":[{"atb":[[2.22,0]],"id":52032624},{"atb":[[2.18,0]],"id":4065261},{"atb":[[2.16,0]],"id":65040144}],"con":true,"img":false}]}
{"op":"mcm","clk":"11540541085","pt":1719495694263,"mc":[{"id":"1.230180134","rc":[{"atb":[[2.24,0]],"id":52032624},{"atb":[[2.2,0]],"id":4065261},{"atb":[[2.18,0]],"id":65040144}],"con":true,"img":false}]}
{"op":"mcm","clk":"11540542239","pt":1719495709063,"mc":[{"id":"1.230180134","rc":[{"atb":[[2.16,10.21]],"id":4065261},{"atb":[[2.14,10.39]],"id":65040144}],"con":true,"img":false}]}
{"op":"mcm","clk":"11540542255","pt":1719495709276,"mc":[{"id":"1.230180134","rc":[{"atb":[[2.16,10.21]],"id":52032624}],"con":true,"img":false}]}
{"op":"mcm","clk":"11540545042","pt":1719495742495,"mc":[{"id":"1.230180134","rc":[{"atb":[[2.18,11.84]],"id":52032624},{"atb":[[2.16,12.04]],"id":65040144}],"con":true,"img":false}]}
{"op":"mcm","clk":"11540545064","pt":1719495742808,"mc":[{"id":"1.230180134","rc":[{"atb":[[2.18,11.84]],"id":4065261}],"con":true,"img":false}]}
{"op":"mcm","clk":"11540549087","pt":1719495786675,"mc":[{"id":"1.230180134","rc":[{"atb":[[2.16,0]],"id":52032624},{"atb":[[2.16,0]],"id":4065261},{"atb":[[2.14,0]],"id":65040144}],"con":true,"img":false}]}
{"op":"mcm","clk":"11540549347","pt":1719495789148,"mc":[{"id":"1.230180134","rc":[{"atb":[[2.2,9.87]],"id":4065261}],"con":true,"img":false}]}
{"op":"mcm","clk":"11540549357","pt":1719495789256,"mc":[{"id":"1.230180134","rc":[{"atb":[[2.2,9.87]],"id":52032624}],"con":true,"img":false}]}
{"op":"mcm","clk":"11540549372","pt":1719495789360,"mc":[{"id":"1.230180134","rc":[{"atb":[[2.18,10.04]],"id":65040144}],"con":true,"img":false}]}
{"op":"mcm","clk":"11540555199","pt":1719495851125,"mc":[{"id":"1.230180134","rc":[{"atb":[[2.18,0]],"id":52032624},{"atb":[[2.18,0]],"id":4065261},{"atb":[[2.16,0]],"id":65040144}],"con":true,"img":false}]}
{"op":"mcm","clk":"11540555707","pt":1719495857212,"mc":[{"id":"1.230180134","rc":[{"atb":[[2.22,11.45]],"id":52032624}],"con":true,"img":false}]}
{"op":"mcm","clk":"11540555736","pt":1719495857626,"mc":[{"id":"1.230180134","rc":[{"atb":[[2.2,11.64]],"id":65040144}],"con":true,"img":false}]}
{"op":"mcm","clk":"11540555763","pt":1719495858039,"mc":[{"id":"1.230180134","rc":[{"atb":[[2.22,11.45]],"id":4065261}],"con":true,"img":false}]}
{"op":"mcm","clk":"11540558468","pt":1719495887581,"mc":[{"id":"1.230180134","rc":[{"atb":[[2.2,0]],"id":52032624},{"atb":[[2.2,0]],"id":4065261},{"atb":[[2.18,0]],"id":65040144}],"con":true,"img":false}]}
{"op":"mcm","clk":"11540560083","pt":1719495904183,"mc":[{"id":"1.230180134","rc":[{"atb":[[2.24,9.55]],"id":4065261}],"con":true,"img":false}]}
{"op":"mcm","clk":"11540560102","pt":1719495904387,"mc":[{"id":"1.230180134","rc":[{"atb":[[2.22,9.71]],"id":65040144}],"con":true,"img":false}]}
{"op":"mcm","clk":"11540560123","pt":1719495904546,"mc":[{"id":"1.230180134","rc":[{"atb":[[2.24,9.55]],"id":52032624}],"con":true,"img":false}]}
{"op":"mcm","clk":"11540563950","pt":1719495941003,"mc":[{"id":"1.230180134","rc":[{"atb":[[2.22,0]],"id":52032624},{"atb":[[2.22,0]],"id":4065261},{"atb":[[2.2,0]],"id":65040144}],"con":true,"img":false}]}
{"op":"mcm","clk":"11540564627","pt":1719495947692,"mc":[{"id":"1.230180134","rc":[{"atb":[[2.26,11.08]],"id":4065261}],"con":true,"img":false}]}
{"op":"mcm","clk":"11540564634","pt":1719495947803,"mc":[{"id":"1.230180134","rc":[{"atb":[[2.26,13.08]],"id":52032624}],"con":true,"img":false}]}
{"op":"mcm","clk":"11540564662","pt":1719495948001,"mc":[{"id":"1.230180134","rc":[{"atb":[[2.24,11.27]],"id":65040144}],"con":true,"img":false}]}
{"op":"mcm","clk":"11540567674","pt":1719495980982,"mc":[{"id":"1.230180134","rc":[{"atb":[[2.24,0]],"id":52032624},{"atb":[[2.24,0]],"id":4065261},{"atb":[[2.22,0]],"id":65040144}],"con":true,"img":false}]}
{"op":"mcm","clk":"11540568077","pt":1719495985070,"mc":[{"id":"1.230180134","rc":[{"atb":[[2.28,9.25]],"id":4065261}],"con":true,"img":false}]}
{"op":"mcm","clk":"11540568087","pt":1719495985173,"mc":[{"id":"1.230180134","rc":[{"atb":[[2.28,9.25]],"id":52032624}],"con":true,"img":false}]}
{"op":"mcm","clk":"11540568096","pt":1719495985276,"mc":[{"id":"1.230180134","rc":[{"atb":[[2.26,9.4]],"id":65040144}],"con":true,"img":false}]}
{"op":"mcm","clk":"11540572169","pt":1719496032507,"mc":[{"id":"1.230180134","rc":[{"atb":[[2.26,2]],"id":52032624},{"atb":[[2.26,0]],"id":4065261},{"atb":[[2.24,0]],"id":65040144}],"con":true,"img":false}]}
{"op":"mcm","clk":"11540573905","pt":1719496051894,"mc":[{"id":"1.230180134","rc":[{"atb":[[2.28,10.91]],"id":65040144}],"con":true,"img":false}]}
{"op":"mcm","clk":"11540573916","pt":1719496051953,"mc":[{"id":"1.230180134","rc":[{"atb":[[2.3,10.74]],"id":52032624}],"con":true,"img":false}]}
{"op":"mcm","clk":"11540573935","pt":1719496052154,"mc":[{"id":"1.230180134","rc":[{"atb":[[2.3,10.74]],"id":4065261}],"con":true,"img":false}]}
{"op":"mcm","clk":"11540574805","pt":1719496061280,"mc":[{"id":"1.230180134","rc":[{"atb":[[2.28,0]],"id":52032624},{"atb":[[2.28,0]],"id":4065261},{"atb":[[2.26,0]],"id":65040144}],"con":true,"img":false}]}
{"op":"mcm","clk":"11540576338","pt":1719496077101,"mc":[{"id":"1.230180134","rc":[{"atb":[[2.32,8.97]],"id":4065261}],"con":true,"img":false}]}
{"op":"mcm","clk":"11540576360","pt":1719496077309,"mc":[{"id":"1.230180134","rc":[{"atb":[[2.3,9.11]],"id":65040144}],"con":true,"img":false}]}
{"op":"mcm","clk":"11540576383","pt":1719496077511,"mc":[{"id":"1.230180134","rc":[{"atb":[[2.32,8.97]],"id":52032624}],"con":true,"img":false}]}
{"op":"mcm","clk":"11540580603","pt":1719496120430,"mc":[{"id":"1.230180134","rc":[{"atb":[[2.3,0]],"id":52032624},{"atb":[[2.3,0]],"id":4065261},{"atb":[[2.28,0]],"id":65040144}],"con":true,"img":false}]}
{"op":"mcm","clk":"11540581162","pt":1719496126979,"mc":[{"id":"1.230180134","rc":[{"atb":[[2.34,10.42]],"id":4065261}],"con":true,"img":false}]}
{"op":"mcm","clk":"11540581172","pt":1719496127026,"mc":[{"id":"1.230180134","rc":[{"atb":[[2.34,10.42]],"id":52032624}],"con":true,"img":false}]}
{"op":"mcm","clk":"11540581186","pt":1719496127239,"mc":[{"id":"1.230180134","rc":[{"atb":[[2.32,10.58]],"id":65040144}],"con":true,"img":false}]}
{"op":"mcm","clk":"11540583756","pt":1719496151700,"mc":[{"id":"1.230180134","rc":[{"atb":[[2.32,0]],"id":52032624},{"atb":[[2.32,0]],"id":4065261},{"atb":[[2.3,0]],"id":65040144}],"con":true,"img":false}]}
{"op":"mcm","clk":"11540585380","pt":1719496168033,"mc":[{"id":"1.230180134","rc":[{"atb":[[2.36,8.71]],"id":52032624},{"atb":[[2.36,8.71]],"id":4065261}],"con":true,"img":false}]}
{"op":"mcm","clk":"11540585402","pt":1719496168200,"mc":[{"id":"1.230180134","rc":[{"atb":[[2.34,8.84]],"id":65040144}],"con":true,"img":false}]}
{"op":"mcm","clk":"11540587828","pt":1719496192067,"mc":[{"id":"1.230180134","rc":[{"atb":[[2.34,0]],"id":52032624},{"atb":[[2.34,0]],"id":4065261},{"atb":[[2.32,0]],"id":65040144}],"con":true,"img":false}]}
{"op":"mcm","clk":"11540591452","pt":1719496226774,"mc":[{"id":"1.230180134","rc":[{"atb":[[2.36,0]],"id":52032624},{"atb":[[2.36,0]],"id":4065261},{"atb":[[2.34,0]],"id":65040144}],"con":true,"img":false}]}
{"op":"mcm","clk":"11540593000","pt":1719496241675,"mc":[{"id":"1.230180134","rc":[{"atb":[[2.16,10.21]],"id":4065261}],"con":true,"img":false}]}
{"op":"mcm","clk":"11540593010","pt":1719496241778,"mc":[{"id":"1.230180134","rc":[{"atb":[[2.14,10.39]],"id":65040144}],"con":true,"img":false}]}
{"op":"mcm","clk":"11540593019","pt":1719496241878,"mc":[{"id":"1.230180134","rc":[{"atb":[[2.16,10.21]],"id":52032624}],"con":true,"img":false}]}
{"op":"mcm","clk":"11540596166","pt":1719496272051,"mc":[{"id":"1.230180134","rc":[{"atb":[[2.18,11.84]],"id":52032624},{"atb":[[2.18,11.84]],"id":4065261}],"con":true,"img":false}]}
{"op":"mcm","clk":"11540596212","pt":1719496272512,"mc":[{"id":"1.230180134","rc":[{"atb":[[2.16,12.04]],"id":65040144}],"con":true,"img":false}]}
{"op":"mcm","clk":"11540598994","pt":1719496301753,"mc":[{"id":"1.230180134","rc":[{"atb":[[2.16,0]],"id":52032624},{"atb":[[2.16,0]],"id":4065261},{"atb":[[2.14,0]],"id":65040144}],"con":true,"img":false}]}
{"op":"mcm","clk":"11540600566","pt":1719496317712,"mc":[{"id":"1.230180134","rc":[{"atb":[[2.2,9.87]],"id":4065261}],"con":true,"img":false}]}
{"op":"mcm","clk":"11540600577","pt":1719496317807,"mc":[{"id":"1.230180134","rc":[{"atb":[[2.2,9.87]],"id":52032624}],"con":true,"img":false}]}
{"op":"mcm","clk":"11540600585","pt":1719496317912,"mc":[{"id":"1.230180134","rc":[{"atb":[[2.18,10.04]],"id":65040144}],"con":true,"img":false}]}
{"op":"mcm","clk":"11540603802","pt":1719496350250,"mc":[{"id":"1.230180134","rc":[{"atb":[[2.18,0]],"id":52032624},{"atb":[[2.18,0]],"id":4065261},{"atb":[[2.16,0]],"id":65040144}],"con":true,"img":false}]}
{"op":"mcm","clk":"11540607725","pt":1719496391161,"mc":[{"id":"1.230180134","rc":[{"atb":[[2.22,11.45]],"id":4065261}],"con":true,"img":false}]}
{"op":"mcm","clk":"11540607755","pt":1719496391470,"mc":[{"id":"1.230180134","rc":[{"atb":[[2.2,11.64]],"id":65040144}],"con":true,"img":false}]}
{"op":"mcm","clk":"11540607784","pt":1719496391783,"mc":[{"id":"1.230180134","rc":[{"atb":[[2.22,11.45]],"id":52032624}],"con":true,"img":false}]}
{"op":"mcm","clk":"11540608533","pt":1719496399773,"mc":[{"id":"1.230180134","rc":[{"atb":[[2.2,0]],"id":52032624},{"atb":[[2.2,0]],"id":4065261},{"atb":[[2.18,0]],"id":65040144}],"con":true,"img":false}]}
{"op":"mcm","clk":"11540610377","pt":1719496421016,"mc":[{"id":"1.230180134","rc":[{"atb":[[2.24,9.55]],"id":52032624},{"atb":[[2.24,9.55]],"id":4065261}],"con":true,"img":false}]}
{"op":"mcm","clk":"11540610488","pt":1719496422203,"mc":[{"id":"1.230180134","rc":[{"atb":[[2.22,9.71]],"id":65040144}],"con":true,"img":false}]}
{"op":"mcm","clk":"11540612320","pt":1719496441160,"mc":[{"id":"1.230180134","rc":[{"atb":[[2.22,0]],"id":52032624},{"atb":[[2.22,0]],"id":4065261},{"atb":[[2.2,0]],"id":65040144}],"con":true,"img":false}]}
{"op":"mcm","clk":"11540612618","pt":1719496444364,"mc":[{"id":"1.230180134","rc":[{"atl":[[34,18]],"id":41401491}],"con":true,"img":false}]}
{"op":"mcm","clk":"11540617543","pt":1719496496596,"mc":[{"id":"1.230180134","rc":[{"atb":[[2.26,11.08]],"id":4065261}],"con":true,"img":false}]}
{"op":"mcm","clk":"11540617552","pt":1719496496705,"mc":[{"id":"1.230180134","rc":[{"atb":[[2.26,13.08]],"id":52032624}],"con":true,"img":false}]}
{"op":"mcm","clk":"11540617571","pt":1719496496906,"mc":[{"id":"1.230180134","rc":[{"atb":[[2.24,11.27]],"id":65040144}],"con":true,"img":false}]}
{"op":"mcm","clk":"11540617604","pt":1719496497318,"mc":[{"id":"1.230180134","rc":[{"atb":[[2.24,0]],"id":52032624},{"atb":[[2.24,0]],"id":4065261},{"atb":[[2.22,0]],"id":65040144}],"con":true,"img":false}]}
{"op":"mcm","clk":"11540619271","pt":1719496518222,"mc":[{"id":"1.230180134","rc":[{"atb":[[2.28,9.25]],"id":4065261}],"con":true,"img":false}]}
{"op":"mcm","clk":"11540619282","pt":1719496518319,"mc":[{"id":"1.230180134","rc":[{"atb":[[2.26,9.4]],"id":65040144}],"con":true,"img":false}]}
{"op":"mcm","clk":"11540619293","pt":1719496518421,"mc":[{"id":"1.230180134","rc":[{"atb":[[2.28,9.25]],"id":52032624}],"con":true,"img":false}]}
{"op":"mcm","clk":"11540620889","pt":1719496539469,"mc":[{"id":"1.230180134","rc":[{"atb":[[2.26,2]],"id":52032624},{"atb":[[2.26,0]],"id":4065261},{"atb":[[2.24,0]],"id":65040144}],"con":true,"img":false}]}
{"op":"mcm","clk":"11540623857","pt":1719496574913,"mc":[{"id":"1.230180134","rc":[{"atb":[[2.28,0]],"id":52032624},{"atb":[[2.28,0]],"id":4065261},{"atb":[[2.26,0]],"id":65040144}],"con":true,"img":false}]}
{"op":"mcm","clk":"11540625304","pt":1719496591126,"mc":[{"id":"1.230180134","rc":[{"atb":[[2.16,10.21]],"id":4065261}],"con":true,"img":false}]}
{"op":"mcm","clk":"11540625317","pt":1719496591227,"mc":[{"id":"1.230180134","rc":[{"atb":[[2.14,10.39]],"id":65040144}],"con":true,"img":false}]}
{"op":"mcm","clk":"11540625328","pt":1719496591331,"mc":[{"id":"1.230180134","rc":[{"atb":[[2.16,10.21]],"id":52032624}],"con":true,"img":false}]}
{"op":"mcm","clk":"11540629683","pt":1719496644417,"mc":[{"id":"1.230180134","rc":[{"atb":[[2.18,11.84]],"id":4065261}],"con":true,"img":false}]}
{"op":"mcm","clk":"11540629692","pt":1719496644476,"mc":[{"id":"1.230180134","rc":[{"atb":[[2.18,11.84]],"id":52032624}],"con":true,"img":false}]}
{"op":"mcm","clk":"11540629717","pt":1719496644778,"mc":[{"id":"1.230180134","rc":[{"atb":[[2.16,12.04]],"id":65040144}],"con":true,"img":false}]}
{"op":"mcm","clk":"11540631409","pt":1719496665905,"mc":[{"id":"1.230180134","rc":[{"atb":[[2.16,0]],"id":52032624},{"atb":[[2.16,0]],"id":4065261},{"atb":[[2.14,0]],"id":65040144}],"con":true,"img":false}]}
{"op":"mcm","clk":"11540632635","pt":1719496681257,"mc":[{"id":"1.230180134","rc":[{"atb":[[2.2,9.87]],"id":4065261}],"con":true,"img":false}]}
{"op":"mcm","clk":"11540632642","pt":1719496681315,"mc":[{"id":"1.230180134","rc":[{"atb":[[2.2,9.87]],"id":52032624}],"con":true,"img":false}]}
{"op":"mcm","clk":"11540632654","pt":1719496681418,"mc":[{"id":"1.230180134","rc":[{"atb":[[2.18,10.04]],"id":65040144}],"con":true,"img":false}]}
{"op":"mcm","clk":"11540634978","pt":1719496710172,"mc":[{"id":"1.230180134","rc":[{"atb":[[2.18,0]],"id":52032624},{"atb":[[2.18,0]],"id":4065261},{"atb":[[2.16,0]],"id":65040144}],"con":true,"img":false}]}
{"op":"mcm","clk":"11540637269","pt":1719496737811,"mc":[{"id":"1.230180134","rc":[{"atb":[[2.2,0]],"id":52032624},{"atb":[[2.2,0]],"id":4065261},{"atb":[[2.18,0]],"id":65040144}],"con":true,"img":false}]}
{"op":"mcm","clk":"11540638513","pt":1719496753410,"mc":[{"id":"1.230180134","rc":[{"atb":[[2.16,10.21]],"id":4065261}],"con":true,"img":false}]}
{"op":"mcm","clk":"11540638537","pt":1719496753719,"mc":[{"id":"1.230180134","rc":[{"atb":[[2.16,10.21]],"id":52032624},{"atb":[[2.14,10.39]],"id":65040144}],"con":true,"img":false}]}
{"op":"mcm","clk":"11540644548","pt":1719496827573,"mc":[{"id":"1.230180134","rc":[{"atb":[[1.74,16.29],[1.02,16.49],[1.75,34.41]],"id":41401491},{"trd":[[2.14,4.47]],"ltp":2.14,"tv":4.47,"id":41401491},{"atb":[[1.03,10.99],[1.91,21.84],[2.16,10.21]],"id":52032624},{"atb":[[1.02,16.49],[1.91,17.47],[2.18,11.83],[2.16,10.21]],"id":4065261},{"atb":[[2,20.38],[2.02,6.54],[1.03,10.99]],"id":69176457},{"atb":[[1.02,16.49],[1.91,14.56],[2.14,10.39]],"id":65040144},{"spb":[[1000,100.28]],"id":65040144}],"con":true,"img":false}]}
{"op":"mcm","clk":"11540644572","pt":1719496827884,"mc":[{"id":"1.230180134","rc":[{"atb":[[2.18,11.83]],"id":52032624}],"con":true,"img":false}]}
{"op":"mcm","clk":"11540644599","pt":1719496828195,"mc":[{"id":"1.230180134","rc":[{"atb":[[2.16,12.03]],"id":65040144}],"con":true,"img":false}]}
{"op":"mcm","clk":"11540646693","pt":1719496853045,"mc":[{"id":"1.230180134","rc":[{"atb":[[2.16,0]],"id":52032624},{"atb":[[2.16,0]],"id":4065261},{"atb":[[2.14,0]],"id":65040144}],"con":true,"img":false}]}
{"op":"mcm","clk":"11540648325","pt":1719496871408,"mc":[{"id":"1.230180134","rc":[{"atb":[[2.2,9.87]],"id":4065261}],"con":true,"img":false}]}
{"op":"mcm","clk":"11540648334","pt":1719496871515,"mc":[{"id":"1.230180134","rc":[{"atb":[[2.18,10.03]],"id":65040144}],"con":true,"img":false}]}
{"op":"mcm","clk":"11540648347","pt":1719496871617,"mc":[{"id":"1.230180134","rc":[{"atb":[[2.2,9.87]],"id":52032624}],"con":true,"img":false}]}
{"op":"mcm","clk":"11540649599","pt":1719496887773,"mc":[{"id":"1.230180134","rc":[{"atb":[[2.18,0]],"id":52032624},{"atb":[[2.18,0]],"id":4065261},{"atb":[[2.16,0]],"id":65040144}],"con":true,"img":false}]}
{"op":"mcm","clk":"11540652060","pt":1719496921985,"mc":[{"id":"1.230180134","rc":[{"atb":[[2.2,0]],"id":52032624},{"atb":[[2.2,0]],"id":4065261},{"atb":[[2.18,0]],"id":65040144}],"con":true,"img":false}]}
{"op":"mcm","clk":"11540652352","pt":1719496925903,"mc":[{"id":"1.230180134","rc":[{"atb":[[2.16,10.21]],"id":4065261}],"con":true,"img":false}]}
{"op":"mcm","clk":"11540652361","pt":1719496926111,"mc":[{"id":"1.230180134","rc":[{"atb":[[2.14,10.39]],"id":65040144}],"con":true,"img":false}]}
{"op":"mcm","clk":"11540652378","pt":1719496926318,"mc":[{"id":"1.230180134","rc":[{"atb":[[2.16,10.21]],"id":52032624}],"con":true,"img":false}]}
{"op":"mcm","clk":"11540656078","pt":1719496977575,"mc":[{"id":"1.230180134","rc":[{"atb":[[2.18,11.83]],"id":4065261}],"con":true,"img":false}]}
{"op":"mcm","clk":"11540656087","pt":1719496977677,"mc":[{"id":"1.230180134","rc":[{"atb":[[2.18,11.83]],"id":52032624}],"con":true,"img":false}]}
{"op":"mcm","clk":"11540656099","pt":1719496977828,"mc":[{"id":"1.230180134","rc":[{"atb":[[2.16,12.03]],"id":65040144}],"con":true,"img":false}]}
{"op":"mcm","clk":"11540658114","pt":1719496999473,"mc":[{"id":"1.230180134","rc":[{"atb":[[2.16,0]],"id":52032624},{"atb":[[2.16,0]],"id":4065261},{"atb":[[2.14,0]],"id":65040144}],"con":true,"img":false}]}
{"op":"mcm","clk":"11540659609","pt":1719497017769,"mc":[{"id":"1.230180134","rc":[{"atb":[[2.2,9.87]],"id":4065261}],"con":true,"img":false}]}
{"op":"mcm","clk":"11540659619","pt":1719497017878,"mc":[{"id":"1.230180134","rc":[{"atb":[[2.18,10.03]],"id":65040144}],"con":true,"img":false}]}
{"op":"mcm","clk":"11540659626","pt":1719497017979,"mc":[{"id":"1.230180134","rc":[{"atb":[[2.2,9.87]],"id":52032624}],"con":true,"img":false}]}
{"op":"mcm","clk":"11540661616","pt":1719497043199,"mc":[{"id":"1.230180134","rc":[{"atb":[[2.18,0]],"id":52032624},{"atb":[[2.18,0]],"id":4065261},{"atb":[[2.16,0]],"id":65040144}],"con":true,"img":false}]}
{"op":"mcm","clk":"11540664009","pt":1719497071330,"mc":[{"id":"1.230180134","rc":[{"atb":[[2.2,0]],"id":52032624},{"atb":[[2.2,0]],"id":4065261},{"atb":[[2.18,0]],"id":65040144}],"con":true,"img":false}]}
{"op":"mcm","clk":"11540665341","pt":1719497086070,"mc":[{"id":"1.230180134","rc":[{"atb":[[2.14,10.39]],"id":65040144}],"con":true,"img":false}]}
{"op":"mcm","clk":"11540665351","pt":1719497086176,"mc":[{"id":"1.230180134","rc":[{"atb":[[2.16,10.21]],"id":4065261}],"con":true,"img":false}]}
{"op":"mcm","clk":"11540665367","pt":1719497086380,"mc":[{"id":"1.230180134","rc":[{"atb":[[2.16,10.21]],"id":52032624}],"con":true,"img":false}]}
{"op":"mcm","clk":"11540668639","pt":1719497124707,"mc":[{"id":"1.230180134","rc":[{"atb":[[2.18,11.83]],"id":52032624}],"con":true,"img":false}]}
{"op":"mcm","clk":"11540668648","pt":1719497124806,"mc":[{"id":"1.230180134","rc":[{"atb":[[2.16,12.03]],"id":65040144}],"con":true,"img":false}]}
{"op":"mcm","clk":"11540668683","pt":1719497125223,"mc":[{"id":"1.230180134","rc":[{"atb":[[2.18,11.83]],"id":4065261}],"con":true,"img":false}]}
{"op":"mcm","clk":"11540671637","pt":1719497161348,"mc":[{"id":"1.230180134","rc":[{"atb":[[2.16,0]],"id":52032624},{"atb":[[2.16,0]],"id":4065261},{"atb":[[2.14,0]],"id":65040144}],"con":true,"img":false}]}
{"op":"mcm","clk":"11540673339","pt":1719497179664,"mc":[{"id":"1.230180134","rc":[{"atb":[[2.2,9.87]],"id":4065261}],"con":true,"img":false}]}
{"op":"mcm","clk":"11540673360","pt":1719497179873,"mc":[{"id":"1.230180134","rc":[{"atb":[[2.2,9.87]],"id":52032624},{"atb":[[2.18,10.03]],"id":65040144}],"con":true,"img":false}]}
{"op":"mcm","clk":"11540674617","pt":1719497193990,"mc":[{"id":"1.230180134","rc":[{"atb":[[2.18,0]],"id":52032624},{"atb":[[2.18,0]],"id":4065261},{"atb":[[2.16,0]],"id":65040144}],"con":true,"img":false}]}
{"op":"mcm","clk":"11540677476","pt":1719497226839,"mc":[{"id":"1.230180134","rc":[{"atb":[[2.2,0]],"id":52032624},{"atb":[[2.2,0]],"id":4065261},{"atb":[[2.18,0]],"id":65040144}],"con":true,"img":false}]}
{"op":"mcm","clk":"11540679176","pt":1719497247346,"mc":[{"id":"1.230180134","rc":[{"atb":[[2.16,10.21]],"id":4065261},{"atb":[[2.14,10.39]],"id":65040144}],"con":true,"img":false}]}
{"op":"mcm","clk":"11540679193","pt":1719497247555,"mc":[{"id":"1.230180134","rc":[{"atb":[[2.16,10.21]],"id":52032624}],"con":true,"img":false}]}
{"op":"mcm","clk":"11540690131","pt":1719497310747,"mc":[{"id":"1.230180134","rc":[{"atb":[[2.18,11.83]],"id":4065261}],"con":true,"img":false}]}
{"op":"mcm","clk":"11540690147","pt":1719497310957,"mc":[{"id":"1.230180134","rc":[{"atb":[[2.18,11.83]],"id":52032624}],"con":true,"img":false}]}
{"op":"mcm","clk":"11540690158","pt":1719497311061,"mc":[{"id":"1.230180134","rc":[{"atb":[[2.16,12.03]],"id":65040144}],"con":true,"img":false}]}
{"op":"mcm","clk":"11540693012","pt":1719497344991,"mc":[{"id":"1.230180134","rc":[{"atb":[[2.16,0]],"id":52032624},{"atb":[[2.16,0]],"id":4065261},{"atb":[[2.14,0]],"id":65040144}],"con":true,"img":false}]}
{"op":"mcm","clk":"11540693942","pt":1719497355188,"mc":[{"id":"1.230180134","rc":[{"atb":[[2.2,9.87]],"id":52032624},{"atb":[[2.2,9.87]],"id":4065261}],"con":true,"img":false}]}
{"op":"mcm","clk":"11540693958","pt":1719497355397,"mc":[{"id":"1.230180134","rc":[{"atb":[[2.18,10.03]],"id":65040144}],"con":true,"img":false}]}
{"op":"mcm","clk":"11540695275","pt":1719497369229,"mc":[{"id":"1.230180134","rc":[{"atb":[[2.18,0]],"id":52032624},{"atb":[[2.18,0]],"id":4065261},{"atb":[[2.16,0]],"id":65040144}],"con":true,"img":false}]}
{"op":"mcm","clk":"11540697580","pt":1719497395629,"mc":[{"id":"1.230180134","rc":[{"atb":[[2.2,0]],"id":52032624},{"atb":[[2.2,0]],"id":4065261},{"atb":[[2.18,0]],"id":65040144}],"con":true,"img":false}]}
{"op":"mcm","clk":"11540699589","pt":1719497415026,"mc":[{"id":"1.230180134","rc":[{"atb":[[2.16,10.21]],"id":52032624},{"atb":[[2.16,10.21]],"id":4065261}],"con":true,"img":false}]}
{"op":"mcm","clk":"11540699610","pt":1719497415233,"mc":[{"id":"1.230180134","rc":[{"atb":[[2.14,10.39]],"id":65040144}],"con":true,"img":false}]}
{"op":"mcm","clk":"11540704321","pt":1719497464084,"mc":[{"id":"1.230180134","rc":[{"atb":[[2.16,12.03]],"id":65040144}],"con":true,"img":false}]}
{"op":"mcm","clk":"11540704345","pt":1719497464393,"mc":[{"id":"1.230180134","rc":[{"atb":[[2.18,11.83]],"id":52032624}],"con":true,"img":false}]}
{"op":"mcm","clk":"11540704384","pt":1719497464706,"mc":[{"id":"1.230180134","rc":[{"atb":[[2.18,11.83]],"id":4065261}],"con":true,"img":false}]}
{"op":"mcm","clk":"11540707573","pt":1719497500048,"mc":[{"id":"1.230180134","rc":[{"atb":[[2.16,0]],"id":52032624},{"atb":[[2.16,0]],"id":4065261},{"atb":[[2.14,0]],"id":65040144}],"con":true,"img":false}]}
{"op":"mcm","clk":"11540709197","pt":1719497518761,"mc":[{"id":"1.230180134","rc":[{"atb":[[2.2,9.87]],"id":4065261}],"con":true,"img":false}]}
{"op":"mcm","clk":"11540709218","pt":1719497518965,"mc":[{"id":"1.230180134","rc":[{"atb":[[2.18,10.03]],"id":65040144}],"con":true,"img":false}]}
{"op":"mcm","clk":"11540709230","pt":1719497519071,"mc":[{"id":"1.230180134","rc":[{"atb":[[2.2,9.87]],"id":52032624}],"con":true,"img":false}]}
{"op":"mcm","clk":"11540712040","pt":1719497549626,"mc":[{"id":"1.230180134","rc":[{"atb":[[2.18,0]],"id":52032624},{"atb":[[2.18,0]],"id":4065261},{"atb":[[2.16,0]],"id":65040144}],"con":true,"img":false}]}
{"op":"mcm","clk":"11540712783","pt":1719497558103,"mc":[{"id":"1.230180134","rc":[{"atb":[[2.22,11.45]],"id":4065261}],"con":true,"img":false}]}
{"op":"mcm","clk":"11540712800","pt":1719497558312,"mc":[{"id":"1.230180134","rc":[{"atb":[[2.2,11.64]],"id":65040144}],"con":true,"img":false}]}
{"op":"mcm","clk":"11540712809","pt":1719497558413,"mc":[{"id":"1.230180134","rc":[{"atb":[[2.22,11.45]],"id":52032624}],"con":true,"img":false}]}
{"op":"mcm","clk":"11540713009","pt":1719497560490,"mc":[{"id":"1.230180134","rc":[{"atb":[[2.2,0]],"id":52032624},{"atb":[[2.2,0]],"id":4065261},{"atb":[[2.18,0]],"id":65040144}],"con":true,"img":false}]}
{"op":"mcm","clk":"11540714162","pt":1719497574641,"mc":[{"id":"1.230180134","rc":[{"atb":[[2.24,9.55]],"id":4065261}],"con":true,"img":false}]}
{"op":"mcm","clk":"11540714170","pt":1719497574750,"mc":[{"id":"1.230180134","rc":[{"atb":[[2.22,9.71]],"id":65040144}],"con":true,"img":false}]}
{"op":"mcm","clk":"11540714182","pt":1719497574848,"mc":[{"id":"1.230180134","rc":[{"atb":[[2.24,9.55]],"id":52032624}],"con":true,"img":false}]}
{"op":"mcm","clk":"11540715729","pt":1719497593556,"mc":[{"id":"1.230180134","rc":[{"atb":[[1.74,0]],"id":41401491}],"con":true,"img":false}]}
{"op":"mcm","clk":"11540715733","pt":1719497593659,"mc":[{"id":"1.230180134","rc":[{"atb":[[1.76,16.29]],"id":41401491}],"con":true,"img":false}]}
{"op":"mcm","clk":"11540718192","pt":1719497624274,"mc":[{"id":"1.230180134","rc":[{"atb":[[1.75,15.79]],"id":41401491},{"atb":[[2.22,0]],"id":52032624},{"atb":[[2.22,0]],"id":4065261},{"atb":[[2.2,0]],"id":65040144}],"con":true,"img":false}]}
{"op":"mcm","clk":"11540719389","pt":1719497638378,"mc":[{"id":"1.230180134","rc":[{"atb":[[1.75,0]],"id":41401491}],"con":true,"img":false}]}
{"op":"mcm","clk":"11540720057","pt":1719497645501,"mc":[{"id":"1.230180134","rc":[{"atb":[[2.26,11.08]],"id":4065261}],"con":true,"img":false}]}
{"op":"mcm","clk":"11540720073","pt":1719497645718,"mc":[{"id":"1.230180134","rc":[{"atb":[[2.26,13.08]],"id":52032624}],"con":true,"img":false}]}
{"op":"mcm","clk":"11540720080","pt":1719497645814,"mc":[{"id":"1.230180134","rc":[{"atb":[[1.68,20.54]],"id":41401491}],"con":true,"img":false}]}
{"op":"mcm","clk":"11540720127","pt":1719497646426,"mc":[{"id":"1.230180134","rc":[{"atb":[[2.24,11.26]],"id":65040144}],"con":true,"img":false}]}
{"op":"mcm","clk":"11540721106","pt":1719497658643,"mc":[{"id":"1.230180134","rc":[{"atb":[[2.24,0]],"id":52032624},{"atb":[[2.24,0]],"id":4065261},{"atb":[[2.22,0]],"id":65040144}],"con":true,"img":false}]}
{"op":"mcm","clk":"11540722802","pt":1719497679648,"mc":[{"id":"1.230180134","rc":[{"atb":[[2.28,9.25]],"id":4065261}],"con":true,"img":false}]}
{"op":"mcm","clk":"11540722812","pt":1719497679750,"mc":[{"id":"1.230180134","rc":[{"atb":[[1.69,17.16]],"id":41401491}],"con":true,"img":false}]}
{"op":"mcm","clk":"11540722820","pt":1719497679854,"mc":[{"id":"1.230180134","rc":[{"atb":[[2.26,9.39]],"id":65040144}],"con":true,"img":false}]}
{"op":"mcm","clk":"11540722833","pt":1719497680062,"mc":[{"id":"1.230180134","rc":[{"atb":[[2.28,9.25]],"id":52032624}],"con":true,"img":false}]}
{"op":"mcm","clk":"11540725565","pt":1719497708959,"mc":[{"id":"1.230180134","rc":[{"atb":[[1.68,0]],"id":41401491},{"atb":[[2.26,2]],"id":52032624},{"atb":[[2.26,0]],"id":4065261},{"atb":[[2.24,0]],"id":65040144}],"con":true,"img":false}]}
{"op":"mcm","clk":"11540726584","pt":1719497719306,"mc":[{"id":"1.230180134","rc":[{"atb":[[1.7,19.95]],"id":41401491}],"con":true,"img":false}]}
{"op":"mcm","clk":"11540726602","pt":1719497719511,"mc":[{"id":"1.230180134","rc":[{"atb":[[2.3,10.74]],"id":4065261}],"con":true,"img":false}]}
{"op":"mcm","clk":"11540726920","pt":1719497723387,"mc":[{"id":"1.230180134","rc":[{"spl":[[1.01,1]],"id":41401491}],"con":true,"img":false}]}
{"op":"mcm","clk":"11540728235","pt":1719497739615,"mc":[{"id":"1.230180134","rc":[{"atb":[[1.69,0]],"id":41401491},{"atb":[[2.28,0]],"id":52032624},{"atb":[[2.28,0]],"id":4065261},{"atb":[[2.26,0]],"id":65040144}],"con":true,"img":false}]}
{"op":"mcm","clk":"11540729946","pt":1719497758404,"mc":[{"id":"1.230180134","rc":[{"atb":[[2.32,8.97]],"id":4065261}],"con":true,"img":false}]}
{"op":"mcm","clk":"11540729952","pt":1719497758509,"mc":[{"id":"1.230180134","rc":[{"atb":[[2.14,10.39]],"id":65040144}],"con":true,"img":false}]}
{"op":"mcm","clk":"11540729959","pt":1719497758609,"mc":[{"id":"1.230180134","rc":[{"atb":[[2.16,10.21]],"id":52032624}],"con":true,"img":false}]}
{"op":"mcm","clk":"11540729987","pt":1719497758817,"mc":[{"id":"1.230180134","rc":[{"atb":[[1.71,16.68]],"id":41401491}],"con":true,"img":false}]}
{"op":"mcm","clk":"11540732569","pt":1719497788251,"mc":[{"id":"1.230180134","rc":[{"atb":[[1.7,0]],"id":41401491},{"spn":2.04,"spf":1.0,"id":41401491},{"atb":[[2.3,0]],"id":4065261}],"con":true,"img":false}]}
{"op":"mcm","clk":"11540735912","pt":1719497825414,"mc":[{"id":"1.230180134","rc":[{"atb":[[1.71,0]],"id":41401491},{"atb":[[2.32,0]],"id":4065261}],"con":true,"img":false}]}
{"op":"mcm","clk":"11540736877","pt":1719497835196,"mc":[{"id":"1.230180134","rc":[{"atb":[[2.16,12.03]],"id":65040144}],"con":true,"img":false}]}
{"op":"mcm","clk":"11540736925","pt":1719497835611,"mc":[{"id":"1.230180134","rc":[{"atb":[[2.18,11.83]],"id":52032624}],"con":true,"img":false}]}
{"op":"mcm","clk":"11540737412","pt":1719497841135,"mc":[{"id":"1.230180134","rc":[{"atb":[[2.16,10.21]],"id":4065261}],"con":true,"img":false}]}
{"op":"mcm","clk":"11540737426","pt":1719497841293,"mc":[{"id":"1.230180134","rc":[{"atb":[[1.68,17.42]],"id":41401491}],"con":true,"img":false}]}
{"op":"mcm","clk":"11540740108","pt":1719497873569,"mc":[{"id":"1.230180134","rc":[{"atb":[[2.16,0]],"id":52032624},{"atb":[[2.14,0]],"id":65040144}],"con":true,"img":false}]}
{"op":"mcm","clk":"11540740518","pt":1719497877975,"mc":[{"id":"1.230180134","rc":[{"atb":[[2.18,10.03]],"id":65040144}],"con":true,"img":false}]}
{"op":"mcm","clk":"11540740535","pt":1719497878179,"mc":[{"id":"1.230180134","rc":[{"atb":[[2.2,9.87]],"id":52032624}],"con":true,"img":false}]}
{"op":"mcm","clk":"11540744753","pt":1719497923008,"mc":[{"id":"1.230180134","rc":[{"atb":[[2.18,0]],"id":52032624},{"atb":[[2.16,0]],"id":65040144}],"con":true,"img":false}]}
{"op":"mcm","clk":"11540746290","pt":1719497940238,"mc":[{"id":"1.230180134","rc":[{"atb":[[1.69,20.24]],"id":41401491}],"con":true,"img":false}]}
{"op":"mcm","clk":"11540746299","pt":1719497940337,"mc":[{"id":"1.230180134","rc":[{"atb":[[2.18,11.83]],"id":4065261}],"con":true,"img":false}]}
{"op":"mcm","clk":"11540746324","pt":1719497940647,"mc":[{"id":"1.230180134","rc":[{"atb":[[2.22,11.45]],"id":52032624},{"atb":[[2.2,11.64]],"id":65040144}],"con":true,"img":false}]}
{"op":"mcm","clk":"11540748102","pt":1719497962050,"mc":[{"id":"1.230180134","rc":[{"atb":[[2.2,0]],"id":52032624},{"atb":[[2.18,0]],"id":65040144}],"con":true,"img":false}]}
{"op":"mcm","clk":"11540749676","pt":1719497983484,"mc":[{"id":"1.230180134","rc":[{"atb":[[2.22,9.71]],"id":65040144}],"con":true,"img":false}]}
{"op":"mcm","clk":"11540749693","pt":1719497983682,"mc":[{"id":"1.230180134","rc":[{"atb":[[2.24,9.55]],"id":52032624}],"con":true,"img":false}]}
{"op":"mcm","clk":"11540750320","pt":1719497990612,"mc":[{"id":"1.230180134","rc":[{"atb":[[1.68,0]],"id":41401491},{"atb":[[2.16,0]],"id":4065261}],"con":true,"img":false}]}
{"op":"mcm","clk":"11540751219","pt":1719498001188,"mc":[{"id":"1.230180134","rc":[{"atb":[[2.2,9.87]],"id":4065261}],"con":true,"img":false}]}
{"op":"mcm","clk":"11540751229","pt":1719498001293,"mc":[{"id":"1.230180134","rc":[{"atb":[[1.7,16.92]],"id":41401491}],"con":true,"img":false}]}
{"op":"mcm","clk":"11540752459","pt":1719498013996,"mc":[{"id":"1.230180134","rc":[{"atb":[[2.22,0]],"id":52032624},{"atb":[[2.2,0]],"id":65040144}],"con":true,"img":false}]}
{"op":"mcm","clk":"11540754658","pt":1719498039843,"mc":[{"id":"1.230180134","rc":[{"atb":[[2.24,0]],"id":52032624},{"atb":[[2.22,0]],"id":65040144}],"con":true,"img":false}]}
{"op":"mcm","clk":"11540755083","pt":1719498044124,"mc":[{"id":"1.230180134","rc":[{"atb":[[1.69,0]],"id":41401491},{"atb":[[2.18,0]],"id":4065261}],"con":true,"img":false}]}
{"op":"mcm","clk":"11540755726","pt":1719498051861,"mc":[{"id":"1.230180134","rc":[{"atb":[[2.22,11.45]],"id":4065261}],"con":true,"img":false}]}
{"op":"mcm","clk":"11540755748","pt":1719498052165,"mc":[{"id":"1.230180134","rc":[{"atb":[[1.71,19.67]],"id":41401491}],"con":true,"img":false}]}
{"op":"mcm","clk":"11540756066","pt":1719498055633,"mc":[{"id":"1.230180134","rc":[{"atb":[[2.14,10.39]],"id":65040144}],"con":true,"img":false}]}
{"op":"mcm","clk":"11540756080","pt":1719498055834,"mc":[{"id":"1.230180134","rc":[{"atb":[[2.16,10.21]],"id":52032624}],"con":true,"img":false}]}
{"op":"mcm","clk":"11540757973","pt":1719498076068,"mc":[{"id":"1.230180134","rc":[{"atb":[[1.7,0]],"id":41401491},{"atb":[[2.2,0]],"id":4065261}],"con":true,"img":false}]}
{"op":"mcm","clk":"11540759423","pt":1719498091890,"mc":[{"id":"1.230180134","rc":[{"atb":[[2.24,9.55]],"id":4065261}],"con":true,"img":false}]}
{"op":"mcm","clk":"11540759433","pt":1719498091991,"mc":[{"id":"1.230180134","rc":[{"atb":[[1.72,16.44]],"id":41401491}],"con":true,"img":false}]}
{"op":"mcm","clk":"11540761958","pt":1719498119718,"mc":[{"id":"1.230180134","rc":[{"atb":[[1.71,0]],"id":41401491},{"atb":[[2.22,0]],"id":4065261}],"con":true,"img":false}]}
{"op":"mcm","clk":"11540762825","pt":1719498129026,"mc":[{"id":"1.230180134","rc":[{"atb":[[2.16,12.03]],"id":65040144}],"con":true,"img":false}]}
{"op":"mcm","clk":"11540762854","pt":1719498129332,"mc":[{"id":"1.230180134","rc":[{"atb":[[2.18,11.83]],"id":52032624}],"con":true,"img":false}]}
{"op":"mcm","clk":"11540765695","pt":1719498160379,"mc":[{"id":"1.230180134","rc":[{"atb":[[1.72,0]],"id":41401491},{"atb":[[2.16,0]],"id":52032624},{"atb":[[2.24,0]],"id":4065261},{"atb":[[2.14,0]],"id":65040144}],"con":true,"img":false}]}
{"op":"mcm","clk":"11540765999","pt":1719498163794,"mc":[{"id":"1.230180134","rc":[{"atb":[[2.16,10.21]],"id":4065261}],"con":true,"img":false}]}
{"op":"mcm","clk":"11540766011","pt":1719498163844,"mc":[{"id":"1.230180134","rc":[{"atb":[[2.18,10.03]],"id":65040144}],"con":true,"img":false}]}
{"op":"mcm","clk":"11540766016","pt":1719498163947,"mc":[{"id":"1.230180134","rc":[{"atb":[[1.68,17.42]],"id":41401491}],"con":true,"img":false}]}
{"op":"mcm","clk":"11540766033","pt":1719498164149,"mc":[{"id":"1.230180134","rc":[{"atb":[[2.2,9.87]],"id":52032624}],"con":true,"img":false}]}
{"op":"mcm","clk":"11540768849","pt":1719498192514,"mc":[{"id":"1.230180134","rc":[{"atb":[[2.18,0]],"id":52032624},{"atb":[[2.16,0]],"id":65040144}],"con":true,"img":false}]}
{"op":"mcm","clk":"11540771452","pt":1719498217334,"mc":[{"id":"1.230180134","rc":[{"atb":[[2.2,0]],"id":52032624},{"atb":[[2.18,0]],"id":65040144}],"con":true,"img":false}]}
{"op":"mcm","clk":"11540771810","pt":1719498221161,"mc":[{"id":"1.230180134","rc":[{"atb":[[2.14,10.39]],"id":65040144}],"con":true,"img":false}]}
{"op":"mcm","clk":"11540771817","pt":1719498221217,"mc":[{"id":"1.230180134","rc":[{"atb":[[2.16,10.21]],"id":52032624}],"con":true,"img":false}]}
{"op":"mcm","clk":"11540774398","pt":1719498246776,"mc":[{"id":"1.230180134","rc":[{"atb":[[2.18,11.83]],"id":4065261}],"con":true,"img":false}]}
{"op":"mcm","clk":"11540774436","pt":1719498247053,"mc":[{"id":"1.230180134","rc":[{"atb":[[1.69,20.24]],"id":41401491}],"con":true,"img":false}]}
{"op":"mcm","clk":"11540778225","pt":1719498283094,"mc":[{"id":"1.230180134","rc":[{"atb":[[2.16,12.03]],"id":65040144}],"con":true,"img":false}]}
{"op":"mcm","clk":"11540778253","pt":1719498283398,"mc":[{"id":"1.230180134","rc":[{"atb":[[2.18,11.83]],"id":52032624}],"con":true,"img":false}]}
{"op":"mcm","clk":"11540778325","pt":1719498284014,"mc":[{"id":"1.230180134","rc":[{"atb":[[1.68,0]],"id":41401491},{"atb":[[2.16,0]],"id":4065261}],"con":true,"img":false}]}
{"op":"mcm","clk":"11540780360","pt":1719498303427,"mc":[{"id":"1.230180134","rc":[{"atb":[[1.7,16.92]],"id":41401491},{"atb":[[2.2,9.87]],"id":4065261}],"con":true,"img":false}]}
{"op":"mcm","clk":"11540782497","pt":1719498324638,"mc":[{"id":"1.230180134","rc":[{"atb":[[2.16,0]],"id":52032624},{"atb":[[2.14,0]],"id":65040144}],"con":true,"img":false}]}
{"op":"mcm","clk":"11540784227","pt":1719498341964,"mc":[{"id":"1.230180134","rc":[{"atb":[[2.18,10.03]],"id":65040144}],"con":true,"img":false}]}
{"op":"mcm","clk":"11540784235","pt":1719498342068,"mc":[{"id":"1.230180134","rc":[{"atb":[[2.2,9.87]],"id":52032624}],"con":true,"img":false}]}
{"op":"mcm","clk":"11540785659","pt":1719498357359,"mc":[{"id":"1.230180134","rc":[{"atb":[[1.69,0]],"id":41401491},{"atb":[[2.18,0]],"id":4065261}],"con":true,"img":false}]}
{"op":"mcm","clk":"11540785802","pt":1719498358666,"mc":[{"id":"1.230180134","rc":[{"atb":[[1.71,19.67]],"id":41401491},{"atb":[[2.22,11.45]],"id":4065261}],"con":true,"img":false}]}
{"op":"mcm","clk":"11540788190","pt":1719498385576,"mc":[{"id":"1.230180134","rc":[{"atb":[[1.7,0]],"id":41401491},{"atb":[[2.2,0]],"id":4065261}],"con":true,"img":false}]}
{"op":"mcm","clk":"11540788766","pt":1719498392527,"mc":[{"id":"1.230180134","rc":[{"atb":[[2.18,0]],"id":52032624},{"atb":[[2.16,0]],"id":65040144}],"con":true,"img":false}]}
{"op":"mcm","clk":"11540788846","pt":1719498393409,"mc":[{"id":"1.230180134","rc":[{"atb":[[2.22,11.45]],"id":52032624}],"con":true,"img":false}]}
{"op":"mcm","clk":"11540788854","pt":1719498393522,"mc":[{"id":"1.230180134","rc":[{"atb":[[2.24,9.55]],"id":4065261}],"con":true,"img":false}]}
{"op":"mcm","clk":"11540788867","pt":1719498393619,"mc":[{"id":"1.230180134","rc":[{"atb":[[2.2,11.64]],"id":65040144}],"con":true,"img":false}]}
{"op":"mcm","clk":"11540788877","pt":1719498393690,"mc":[{"id":"1.230180134","rc":[{"atb":[[1.72,16.44]],"id":41401491}],"con":true,"img":false}]}
{"op":"mcm","clk":"11540788896","pt":1719498393990,"mc":[{"id":"1.230180134","rc":[{"atb":[[2.2,0]],"id":52032624},{"atb":[[2.18,0]],"id":65040144}],"con":true,"img":false}]}
{"op":"mcm","clk":"11540790580","pt":1719498413654,"mc":[{"id":"1.230180134","rc":[{"atb":[[1.71,0]],"id":41401491},{"atb":[[2.22,0]],"id":4065261}],"con":true,"img":false}]}
{"op":"mcm","clk":"11540791605","pt":1719498424944,"mc":[{"id":"1.230180134","rc":[{"atb":[[2.22,9.71]],"id":65040144}],"con":true,"img":false}]}
{"op":"mcm","clk":"11540791627","pt":1719498425152,"mc":[{"id":"1.230180134","rc":[{"atb":[[2.24,9.55]],"id":52032624}],"con":true,"img":false}]}
{"op":"mcm","clk":"11540793567","pt":1719498445240,"mc":[{"id":"1.230180134","rc":[{"atb":[[1.72,0]],"id":41401491},{"atb":[[2.24,0]],"id":4065261}],"con":true,"img":false}]}
{"op":"mcm","clk":"11540794880","pt":1719498460093,"mc":[{"id":"1.230180134","rc":[{"atb":[[2.22,0]],"id":52032624},{"atb":[[2.2,0]],"id":65040144}],"con":true,"img":false}]}
{"op":"mcm","clk":"11540794978","pt":1719498461071,"mc":[{"id":"1.230180134","rc":[{"atb":[[2.16,10.21]],"id":4065261}],"con":true,"img":false}]}
{"op":"mcm","clk":"11540794986","pt":1719498461174,"mc":[{"id":"1.230180134","rc":[{"atb":[[1.68,17.42]],"id":41401491}],"con":true,"img":false}]}
{"op":"mcm","clk":"11540796414","pt":1719498476189,"mc":[{"id":"1.230180134","rc":[{"atb":[[2.26,13.08]],"id":52032624}],"con":true,"img":false}]}
{"op":"mcm","clk":"11540796429","pt":1719498476399,"mc":[{"id":"1.230180134","rc":[{"atb":[[2.24,11.26]],"id":65040144}],"con":true,"img":false}]}
{"op":"mcm","clk":"11540797962","pt":1719498493225,"mc":[{"id":"1.230180134","rc":[{"atb":[[2.24,0]],"id":52032624},{"atb":[[2.22,0]],"id":65040144}],"con":true,"img":false}]}
{"op":"mcm","clk":"11540798458","pt":1719498497905,"mc":[{"id":"1.230180134","rc":[{"atb":[[2.28,9.25]],"id":52032624}],"con":true,"img":false}]}
{"op":"mcm","clk":"11540798480","pt":1719498498107,"mc":[{"id":"1.230180134","rc":[{"atb":[[2.26,9.39]],"id":65040144}],"con":true,"img":false}]}
{"op":"mcm","clk":"11540799150","pt":1719498505614,"mc":[{"id":"1.230180134","rc":[{"atb":[[2.18,11.83]],"id":4065261}],"con":true,"img":false}]}
{"op":"mcm","clk":"11540799156","pt":1719498505718,"mc":[{"id":"1.230180134","rc":[{"atb":[[1.69,20.24]],"id":41401491}],"con":true,"img":false}]}
{"op":"mcm","clk":"11540801108","pt":1719498528067,"mc":[{"id":"1.230180134","rc":[{"atb":[[2.26,2]],"id":52032624},{"atb":[[2.24,0]],"id":65040144}],"con":true,"img":false}]}
{"op":"mcm","clk":"11540803526","pt":1719498553897,"mc":[{"id":"1.230180134","rc":[{"atb":[[1.68,0]],"id":41401491},{"atb":[[2.16,0]],"id":4065261}],"con":true,"img":false}]}
{"op":"mcm","clk":"11540803935","pt":1719498557897,"mc":[{"id":"1.230180134","rc":[{"atb":[[2.2,9.87]],"id":4065261}],"con":true,"img":false}]}
{"op":"mcm","clk":"11540803946","pt":1719498558003,"mc":[{"id":"1.230180134","rc":[{"atb":[[1.7,16.92]],"id":41401491}],"con":true,"img":false}]}
{"op":"mcm","clk":"11540804167","pt":1719498560235,"mc":[{"id":"1.230180134","rc":[{"atb":[[2.28,0]],"id":52032624},{"atb":[[2.26,0]],"id":65040144}],"con":true,"img":false}]}
{"op":"mcm","clk":"11540804221","pt":1719498560900,"mc":[{"id":"1.230180134","rc":[{"atb":[[2.28,10.91]],"id":65040144}],"con":true,"img":false}]}
{"op":"mcm","clk":"11540804230","pt":1719498560994,"mc":[{"id":"1.230180134","rc":[{"atb":[[2.3,10.74]],"id":52032624}],"con":true,"img":false}]}
{"op":"mcm","clk":"11540806782","pt":1719498588243,"mc":[{"id":"1.230180134","rc":[{"atb":[[1.69,0]],"id":41401491},{"atb":[[2.18,0]],"id":4065261}],"con":true,"img":false}]}
{"op":"mcm","clk":"11540807246","pt":1719498593118,"mc":[{"id":"1.230180134","rc":[{"atb":[[2.3,9.11]],"id":65040144}],"con":true,"img":false}]}
{"op":"mcm","clk":"11540807256","pt":1719498593211,"mc":[{"id":"1.230180134","rc":[{"atb":[[2.32,8.97]],"id":52032624}],"con":true,"img":false}]}
{"op":"mcm","clk":"11540807720","pt":1719498598111,"mc":[{"id":"1.230180134","rc":[{"atb":[[2.22,11.45]],"id":4065261}],"con":true,"img":false}]}
{"op":"mcm","clk":"11540807753","pt":1719498598525,"mc":[{"id":"1.230180134","rc":[{"atb":[[1.71,19.67]],"id":41401491}],"con":true,"img":false}]}
{"op":"mcm","clk":"11540810478","pt":1719498625643,"mc":[{"id":"1.230180134","rc":[{"atb":[[1.7,0]],"id":41401491},{"atb":[[2.2,0]],"id":4065261}],"con":true,"img":false}]}
{"op":"mcm","clk":"11540810856","pt":1719498629571,"mc":[{"id":"1.230180134","rc":[{"atb":[[2.24,9.55]],"id":4065261}],"con":true,"img":false}]}
{"op":"mcm","clk":"11540810864","pt":1719498629669,"mc":[{"id":"1.230180134","rc":[{"atb":[[1.72,16.44]],"id":41401491}],"con":true,"img":false}]}
{"op":"mcm","clk":"11540810970","pt":1719498630756,"mc":[{"id":"1.230180134","rc":[{"atb":[[2.3,0]],"id":52032624},{"atb":[[2.28,0]],"id":65040144}],"con":true,"img":false}]}
{"op":"mcm","clk":"11540811953","pt":1719498640288,"mc":[{"id":"1.230180134","rc":[{"atb":[[2.32,10.58]],"id":65040144}],"con":true,"img":false}]}
{"op":"mcm","clk":"11540811982","pt":1719498640592,"mc":[{"id":"1.230180134","rc":[{"atb":[[2.34,10.42]],"id":52032624}],"con":true,"img":false}]}
{"op":"mcm","clk":"11540814645","pt":1719498669653,"mc":[{"id":"1.230180134","rc":[{"atb":[[1.71,0]],"id":41401491},{"atb":[[2.22,0]],"id":4065261}],"con":true,"img":false}]}
{"op":"mcm","clk":"11540815064","pt":1719498674219,"mc":[{"id":"1.230180134","rc":[{"atb":[[2.32,0]],"id":52032624},{"atb":[[2.3,0]],"id":65040144}],"con":true,"img":false}]}
{"op":"mcm","clk":"11540815552","pt":1719498679110,"mc":[{"id":"1.230180134","rc":[{"atb":[[1.73,19.13]],"id":41401491},{"atb":[[2.26,11.08]],"id":4065261}],"con":true,"img":false}]}
{"op":"mcm","clk":"11540816678","pt":1719498690958,"mc":[{"id":"1.230180134","rc":[{"atb":[[2.34,8.83]],"id":65040144}],"con":true,"img":false}]}
{"op":"mcm","clk":"11540816692","pt":1719498691165,"mc":[{"id":"1.230180134","rc":[{"atb":[[2.36,8.71]],"id":52032624}],"con":true,"img":false}]}
{"op":"mcm","clk":"11540816863","pt":1719498693050,"mc":[{"id":"1.230180134","rc":[{"atb":[[1.72,0]],"id":41401491},{"atb":[[2.24,0]],"id":4065261}],"con":true,"img":false}]}
{"op":"mcm","clk":"11540818166","pt":1719498708156,"mc":[{"id":"1.230180134","rc":[{"atb":[[2.34,0]],"id":52032624},{"atb":[[2.32,0]],"id":65040144}],"con":true,"img":false}]}
{"op":"mcm","clk":"11540818260","pt":1719498709169,"mc":[{"id":"1.230180134","rc":[{"atb":[[2.28,9.25]],"id":4065261}],"con":true,"img":false}]}
{"op":"mcm","clk":"11540818270","pt":1719498709263,"mc":[{"id":"1.230180134","rc":[{"atb":[[1.74,16]],"id":41401491}],"con":true,"img":false}]}
{"op":"mcm","clk":"11540820804","pt":1719498738199,"mc":[{"id":"1.230180134","rc":[{"atb":[[2.36,0]],"id":52032624},{"atb":[[2.34,0]],"id":65040144}],"con":true,"img":false}]}
{"op":"mcm","clk":"11540821206","pt":1719498744312,"mc":[{"id":"1.230180134","rc":[{"atb":[[2.16,10.21]],"id":52032624},{"atb":[[2.14,10.39]],"id":65040144}],"con":true,"img":false}]}
{"op":"mcm","clk":"11540821561","pt":1719498749740,"mc":[{"id":"1.230180134","rc":[{"atb":[[1.73,0]],"id":41401491},{"atb":[[2.26,0]],"id":4065261}],"con":true,"img":false}]}
{"op":"mcm","clk":"11540822195","pt":1719498759056,"mc":[{"id":"1.230180134","rc":[{"atb":[[2.3,10.74]],"id":4065261}],"con":true,"img":false}]}
{"op":"mcm","clk":"11540822222","pt":1719498759366,"mc":[{"id":"1.230180134","rc":[{"atb":[[1.75,18.62]],"id":41401491}],"con":true,"img":false}]}
{"op":"mcm","clk":"11540823380","pt":1719498777169,"mc":[{"id":"1.230180134","rc":[{"atb":[[2.16,12.03]],"id":65040144}],"con":true,"img":false}]}
{"op":"mcm","clk":"11540823403","pt":1719498777494,"mc":[{"id":"1.230180134","rc":[{"atb":[[2.18,11.83]],"id":52032624}],"con":true,"img":false}]}
{"op":"mcm","clk":"11540823948","pt":1719498783478,"mc":[{"id":"1.230180134","rc":[{"atb":[[1.74,0]],"id":41401491},{"atb":[[2.28,0]],"id":4065261}],"con":true,"img":false}]}
{"op":"mcm","clk":"11540825256","pt":1719498799698,"mc":[{"id":"1.230180134","rc":[{"atb":[[2.32,8.97]],"id":4065261}],"con":true,"img":false}]}
{"op":"mcm","clk":"11540825276","pt":1719498799905,"mc":[{"id":"1.230180134","rc":[{"atb":[[1.68,17.42]],"id":41401491}],"con":true,"img":false}]}
{"op":"mcm","clk":"11540826046","pt":1719498810221,"mc":[{"id":"1.230180134","rc":[{"atb":[[2.16,0]],"id":52032624},{"atb":[[2.14,0]],"id":65040144}],"con":true,"img":false}]}
{"op":"mcm","clk":"11540826736","pt":1719498819087,"mc":[{"id":"1.230180134","rc":[{"atb":[[2.18,10.03]],"id":65040144}],"con":true,"img":false}]}
{"op":"mcm","clk":"11540826754","pt":1719498819292,"mc":[{"id":"1.230180134","rc":[{"atb":[[2.2,9.87]],"id":52032624}],"con":true,"img":false}]}
{"op":"mcm","clk":"11540828582","pt":1719498843036,"mc":[{"id":"1.230180134","rc":[{"atb":[[1.75,0]],"id":41401491},{"atb":[[2.18,0]],"id":52032624},{"atb":[[2.3,0]],"id":4065261},{"atb":[[2.16,0]],"id":65040144}],"con":true,"img":false}]}
{"op":"mcm","clk":"11540829456","pt":1719498853850,"mc":[{"id":"1.230180134","rc":[{"atb":[[2.34,10.42]],"id":4065261}],"con":true,"img":false}]}
{"op":"mcm","clk":"11540829469","pt":1719498854060,"mc":[{"id":"1.230180134","rc":[{"atb":[[1.69,20.24]],"id":41401491}],"con":true,"img":false}]}
{"op":"mcm","clk":"11540832140","pt":1719498882343,"mc":[{"id":"1.230180134","rc":[{"atb":[[2.2,0]],"id":52032624},{"atb":[[2.32,0]],"id":4065261},{"atb":[[2.18,0]],"id":65040144}],"con":true,"img":false}]}
{"op":"mcm","clk":"11540832792","pt":1719498890180,"mc":[{"id":"1.230180134","rc":[{"atb":[[1.68,0]],"id":41401491}],"con":true,"img":false}]}
{"op":"mcm","clk":"11540833163","pt":1719498894370,"mc":[{"id":"1.230180134","rc":[{"atb":[[2.36,8.71]],"id":4065261},{"atb":[[2.14,10.39]],"id":65040144}],"con":true,"img":false}]}
{"op":"mcm","clk":"11540833180","pt":1719498894581,"mc":[{"id":"1.230180134","rc":[{"atb":[[1.7,16.92]],"id":41401491}],"con":true,"img":false}]}
{"op":"mcm","clk":"11540833195","pt":1719498894795,"mc":[{"id":"1.230180134","rc":[{"atb":[[2.16,10.21]],"id":52032624}],"con":true,"img":false}]}
{"op":"mcm","clk":"11540836463","pt":1719498932587,"mc":[{"id":"1.230180134","rc":[{"atb":[[1.69,0]],"id":41401491},{"atb":[[2.34,0]],"id":4065261}],"con":true,"img":false}]}
{"op":"mcm","clk":"11540840336","pt":1719498970342,"mc":[{"id":"1.230180134","rc":[{"atb":[[1.71,19.67]],"id":41401491}],"con":true,"img":false}]}
{"op":"mcm","clk":"11540840354","pt":1719498970435,"mc":[{"id":"1.230180134","rc":[{"atb":[[2.38,10.12]],"id":4065261}],"con":true,"img":false}]}
{"op":"mcm","clk":"11540840364","pt":1719498970639,"mc":[{"id":"1.230180134","rc":[{"atb":[[2.18,11.83]],"id":52032624}],"con":true,"img":false}]}
{"op":"mcm","clk":"11540840385","pt":1719498970956,"mc":[{"id":"1.230180134","rc":[{"atb":[[2.16,12.03]],"id":65040144}],"con":true,"img":false}]}
{"op":"mcm","clk":"11540840992","pt":1719498977941,"mc":[{"id":"1.230180134","rc":[{"atb":[[1.7,0]],"id":41401491},{"atb":[[2.36,0]],"id":4065261}],"con":true,"img":false}]}
{"op":"mcm","clk":"11540843237","pt":1719499004871,"mc":[{"id":"1.230180134","rc":[{"atb":[[2.4,8.45]],"id":4065261}],"con":true,"img":false}]}
{"op":"mcm","clk":"11540843248","pt":1719499005080,"mc":[{"id":"1.230180134","rc":[{"atb":[[1.72,16.44]],"id":41401491}],"con":true,"img":false}]}
{"op":"mcm","clk":"11540843489","pt":1719499008176,"mc":[{"id":"1.230180134","rc":[{"atb":[[2.16,0]],"id":52032624},{"atb":[[2.14,0]],"id":65040144}],"con":true,"img":false}]}
{"op":"mcm","clk":"11540844385","pt":1719499020075,"mc":[{"id":"1.230180134","rc":[{"atb":[[2.18,10.03]],"id":65040144}],"con":true,"img":false}]}
{"op":"mcm","clk":"11540844404","pt":1719499020288,"mc":[{"id":"1.230180134","rc":[{"atb":[[2.2,9.87]],"id":52032624}],"con":true,"img":false}]}
{"op":"mcm","clk":"11540846500","pt":1719499046012,"mc":[{"id":"1.230180134","rc":[{"atb":[[1.71,0]],"id":41401491},{"atb":[[2.18,0]],"id":52032624},{"atb":[[2.38,0]],"id":4065261},{"atb":[[2.16,0]],"id":65040144}],"con":true,"img":false}]}
{"op":"mcm","clk":"11540847299","pt":1719499056453,"mc":[{"id":"1.230180134","rc":[{"atb":[[2.42,9.83]],"id":4065261}],"con":true,"img":false}]}
{"op":"mcm","clk":"11540847321","pt":1719499056711,"mc":[{"id":"1.230180134","rc":[{"atb":[[1.73,19.13]],"id":41401491}],"con":true,"img":false}]}
{"op":"mcm","clk":"11540850174","pt":1719499093317,"mc":[{"id":"1.230180134","rc":[{"atb":[[1.72,0]],"id":41401491},{"atb":[[2.2,0]],"id":52032624},{"atb":[[2.4,0]],"id":4065261},{"atb":[[2.18,0]],"id":65040144}],"con":true,"img":false}]}
{"op":"mcm","clk":"11540850701","pt":1719499100136,"mc":[{"id":"1.230180134","rc":[{"atb":[[2.44,8.22]],"id":4065261}],"con":true,"img":false}]}
{"op":"mcm","clk":"11540850710","pt":1719499100336,"mc":[{"id":"1.230180134","rc":[{"atb":[[1.74,16]],"id":41401491}],"con":true,"img":false}]}
{"op":"mcm","clk":"11540850726","pt":1719499100446,"mc":[{"id":"1.230180134","rc":[{"atb":[[2.16,10.21]],"id":52032624}],"con":true,"img":false}]}
{"op":"mcm","clk":"11540850732","pt":1719499100488,"mc":[{"id":"1.230180134","rc":[{"atb":[[2.14,10.39]],"id":65040144}],"con":true,"img":false}]}
{"op":"mcm","clk":"11540852545","pt":1719499125743,"mc":[{"id":"1.230180134","rc":[{"atb":[[1.73,0]],"id":41401491},{"atb":[[2.42,0]],"id":4065261}],"con":true,"img":false}]}
{"op":"mcm","clk":"11540855036","pt":1719499161499,"mc":[{"id":"1.230180134","rc":[{"atb":[[1.74,0]],"id":41401491},{"atb":[[2.44,0]],"id":4065261}],"con":true,"img":false}]}
{"op":"mcm","clk":"11540855450","pt":1719499166408,"mc":[{"id":"1.230180134","rc":[{"atb":[[1.68,17.42]],"id":41401491},{"atb":[[2.16,10.21]],"id":4065261}],"con":true,"img":false}]}
{"op":"mcm","clk":"11540857075","pt":1719499188329,"mc":[{"id":"1.230180134","rc":[{"atb":[[2.16,12.03]],"id":65040144}],"con":true,"img":false}]}
{"op":"mcm","clk":"11540857100","pt":1719499188586,"mc":[{"id":"1.230180134","rc":[{"atb":[[2.18,11.83]],"id":52032624}],"con":true,"img":false}]}
{"op":"mcm","clk":"11540859863","pt":1719499225456,"mc":[{"id":"1.230180134","rc":[{"atb":[[2.16,0]],"id":52032624},{"atb":[[2.14,0]],"id":65040144}],"con":true,"img":false}]}
{"op":"mcm","clk":"11540860197","pt":1719499229477,"mc":[{"id":"1.230180134","rc":[{"atb":[[2.18,11.83]],"id":4065261}],"con":true,"img":false}]}
{"op":"mcm","clk":"11540860231","pt":1719499229850,"mc":[{"id":"1.230180134","rc":[{"atb":[[1.69,20.24]],"id":41401491}],"con":true,"img":false}]}
{"op":"mcm","clk":"11540861166","pt":1719499241349,"mc":[{"id":"1.230180134","rc":[{"atb":[[2.18,10.03]],"id":65040144}],"con":true,"img":false}]}
{"op":"mcm","clk":"11540861178","pt":1719499241560,"mc":[{"id":"1.230180134","rc":[{"atb":[[2.2,9.87]],"id":52032624}],"con":true,"img":false}]}
{"op":"mcm","clk":"11540863070","pt":1719499267411,"mc":[{"id":"1.230180134","rc":[{"atb":[[2.18,0]],"id":52032624},{"atb":[[2.16,0]],"id":65040144}],"con":true,"img":false}]}
{"op":"mcm","clk":"11540863421","pt":1719499272619,"mc":[{"id":"1.230180134","rc":[{"atb":[[1.68,0]],"id":41401491},{"atb":[[2.16,0]],"id":4065261}],"con":true,"img":false}]}
{"op":"mcm","clk":"11540863689","pt":1719499276623,"mc":[{"id":"1.230180134","rc":[{"atb":[[2.2,9.87]],"id":4065261}],"con":true,"img":false}]}
{"op":"mcm","clk":"11540863708","pt":1719499276833,"mc":[{"id":"1.230180134","rc":[{"atb":[[1.7,16.92]],"id":41401491}],"con":true,"img":false}]}
{"op":"mcm","clk":"11540866216","pt":1719499309231,"mc":[{"id":"1.230180134","rc":[{"atb":[[2.2,0]],"id":52032624},{"atb":[[2.18,0]],"id":65040144}],"con":true,"img":false}]}
{"op":"mcm","clk":"11540866556","pt":1719499313845,"mc":[{"id":"1.230180134","rc":[{"atb":[[2.14,10.39]],"id":65040144}],"con":true,"img":false}]}
{"op":"mcm","clk":"11540866569","pt":1719499314059,"mc":[{"id":"1.230180134","rc":[{"atb":[[2.16,10.21]],"id":52032624}],"con":true,"img":false}]}
{"op":"mcm","clk":"11540869177","pt":1719499347208,"mc":[{"id":"1.230180134","rc":[{"atb":[[1.69,0]],"id":41401491},{"atb":[[2.18,0]],"id":4065261}],"con":true,"img":false}]}
{"op":"mcm","clk":"11540869274","pt":1719499348715,"mc":[{"id":"1.230180134","rc":[{"atb":[[2.22,10.41]],"id":4065261}],"con":true,"img":false}]}
{"op":"mcm","clk":"11540869288","pt":1719499348906,"mc":[{"id":"1.230180134","rc":[{"atb":[[1.71,17.88]],"id":41401491}],"con":true,"img":false}]}
{"op":"mcm","clk":"11540872301","pt":1719499385812,"mc":[{"id":"1.230180134","rc":[{"atb":[[2.16,10.94]],"id":65040144}],"con":true,"img":false}]}
{"op":"mcm","clk":"11540872320","pt":1719499386124,"mc":[{"id":"1.230180134","rc":[{"atb":[[2.18,10.76]],"id":52032624}],"con":true,"img":false}]}
{"op":"mcm","clk":"11540872536","pt":1719499388623,"mc":[{"id":"1.230180134","rc":[{"atb":[[1.7,0]],"id":41401491},{"atb":[[2.2,0]],"id":4065261}],"con":true,"img":false}]}
{"op":"mcm","clk":"11540872844","pt":1719499392745,"mc":[{"id":"1.230180134","rc":[{"atb":[[2.24,9.55]],"id":4065261}],"con":true,"img":false}]}
{"op":"mcm","clk":"11540872866","pt":1719499392948,"mc":[{"id":"1.230180134","rc":[{"atb":[[1.72,16.44]],"id":41401491}],"con":true,"img":false}]}
{"op":"mcm","clk":"11540875413","pt":1719499423992,"mc":[{"id":"1.230180134","rc":[{"atb":[[2.16,0]],"id":52032624},{"atb":[[2.14,0]],"id":65040144}],"con":true,"img":false}]}
{"op":"mcm","clk":"11540875757","pt":1719499428459,"mc":[{"id":"1.230180134","rc":[{"atb":[[2.18,10.03]],"id":65040144}],"con":true,"img":false}]}
{"op":"mcm","clk":"11540875761","pt":1719499428562,"mc":[{"id":"1.230180134","rc":[{"atb":[[2.2,9.87]],"id":52032624}],"con":true,"img":false}]}
{"op":"mcm","clk":"11540877034","pt":1719499444907,"mc":[{"id":"1.230180134","rc":[{"atb":[[1.71,0]],"id":41401491},{"atb":[[2.22,0]],"id":4065261}],"con":true,"img":false}]}
{"op":"mcm","clk":"11540878222","pt":1719499460910,"mc":[{"id":"1.230180134","rc":[{"atb":[[2.26,10.07]],"id":4065261}],"con":true,"img":false}]}
{"op":"mcm","clk":"11540878242","pt":1719499461229,"mc":[{"id":"1.230180134","rc":[{"atb":[[1.73,17.39]],"id":41401491}],"con":true,"img":false}]}
{"op":"mcm","clk":"11540879571","pt":1719499478022,"mc":[{"id":"1.230180134","rc":[{"atb":[[1.72,0]],"id":41401491},{"atb":[[2.24,0]],"id":4065261}],"con":true,"img":false}]}
{"op":"mcm","clk":"11540879888","pt":1719499481512,"mc":[{"id":"1.230180134","rc":[{"atb":[[2.28,9.25]],"id":4065261}],"con":true,"img":false}]}
{"op":"mcm","clk":"11540879897","pt":1719499481619,"mc":[{"id":"1.230180134","rc":[{"atb":[[1.74,16]],"id":41401491}],"con":true,"img":false}]}
{"op":"mcm","clk":"11540881263","pt":1719499497656,"mc":[{"id":"1.230180134","rc":[{"atb":[[2.18,0]],"id":52032624},{"atb":[[2.16,0]],"id":65040144}],"con":true,"img":false}]}
{"op":"mcm","clk":"11540881363","pt":1719499498841,"mc":[{"id":"1.230180134","rc":[{"atb":[[2.22,10.41]],"id":52032624}],"con":true,"img":false}]}
{"op":"mcm","clk":"11540881368","pt":1719499498945,"mc":[{"id":"1.230180134","rc":[{"atb":[[2.2,10.58]],"id":65040144}],"con":true,"img":false}]}
{"op":"mcm","clk":"11540883076","pt":1719499519601,"mc":[{"id":"1.230180134","rc":[{"atb":[[2.2,0]],"id":52032624},{"atb":[[2.18,0]],"id":65040144}],"con":true,"img":false}]}
{"op":"mcm","clk":"11540884439","pt":1719499538214,"mc":[{"id":"1.230180134","rc":[{"atb":[[1.73,0]],"id":41401491},{"atb":[[2.26,0]],"id":4065261}],"con":true,"img":false}]}
{"op":"mcm","clk":"11540884501","pt":1719499538997,"mc":[{"id":"1.230180134","rc":[{"atb":[[2.22,9.71]],"id":65040144}],"con":true,"img":false}]}
{"op":"mcm","clk":"11540884509","pt":1719499539208,"mc":[{"id":"1.230180134","rc":[{"atb":[[2.24,9.55]],"id":52032624}],"con":true,"img":false}]}
{"op":"mcm","clk":"11540884530","pt":1719499539517,"mc":[{"id":"1.230180134","rc":[{"atb":[[2.3,9.76]],"id":4065261}],"con":true,"img":false}]}
{"op":"mcm","clk":"11540884543","pt":1719499539673,"mc":[{"id":"1.230180134","rc":[{"atb":[[1.75,16.93]],"id":41401491}],"con":true,"img":false}]}
{"op":"mcm","clk":"11540885908","pt":1719499559629,"mc":[{"id":"1.230180134","rc":[{"atb":[[1.74,0]],"id":41401491},{"atb":[[2.28,0]],"id":4065261}],"con":true,"img":false}]}
{"op":"mcm","clk":"11540887067","pt":1719499575121,"mc":[{"id":"1.230180134","rc":[{"atb":[[1.68,17.42]],"id":41401491}],"con":true,"img":false}]}
{"op":"mcm","clk":"11540887072","pt":1719499575230,"mc":[{"id":"1.230180134","rc":[{"atb":[[2.32,8.97]],"id":4065261}],"con":true,"img":false}]}
{"op":"mcm","clk":"11540887301","pt":1719499578839,"mc":[{"id":"1.230180134","rc":[{"atb":[[2.22,0]],"id":52032624},{"atb":[[2.2,0]],"id":65040144}],"con":true,"img":false}]}
{"op":"mcm","clk":"11540889850","pt":1719499613662,"mc":[{"id":"1.230180134","rc":[{"atb":[[2.24,0]],"id":52032624},{"atb":[[2.22,0]],"id":65040144}],"con":true,"img":false}]}
{"op":"mcm","clk":"11540890034","pt":1719499616101,"mc":[{"id":"1.230180134","rc":[{"atb":[[1.75,0]],"id":41401491},{"atb":[[2.3,0]],"id":4065261}],"con":true,"img":false}]}
{"op":"mcm","clk":"11540890249","pt":1719499618867,"mc":[{"id":"1.230180134","rc":[{"atb":[[2.34,9.47]],"id":4065261}],"con":true,"img":false}]}
{"op":"mcm","clk":"11540890266","pt":1719499619178,"mc":[{"id":"1.230180134","rc":[{"atb":[[1.69,18.4]],"id":41401491}],"con":true,"img":false}]}
{"op":"mcm","clk":"11540891111","pt":1719499630212,"mc":[{"id":"1.230180134","rc":[{"atb":[[2.16,10.21]],"id":52032624},{"atb":[[2.14,10.39]],"id":65040144}],"con":true,"img":false}]}
{"op":"mcm","clk":"11540893708","pt":1719499662566,"mc":[{"id":"1.230180134","rc":[{"atb":[[1.68,0]],"id":41401491},{"atb":[[2.32,0]],"id":4065261}],"con":true,"img":false}]}
{"op":"mcm","clk":"11540893986","pt":1719499666229,"mc":[{"id":"1.230180134","rc":[{"atb":[[2.36,8.71]],"id":4065261}],"con":true,"img":false}]}
{"op":"mcm","clk":"11540893993","pt":1719499666334,"mc":[{"id":"1.230180134","rc":[{"atb":[[1.7,16.92]],"id":41401491}],"con":true,"img":false}]}
{"op":"mcm","clk":"11540894145","pt":1719499668234,"mc":[{"id":"1.230180134","rc":[{"atl":[[2.22,0]],"id":41401491}],"con":true,"img":false}]}
{"op":"mcm","clk":"11540894152","pt":1719499668336,"mc":[{"id":"1.230180134","rc":[{"atl":[[2.16,8]],"id":41401491}],"con":true,"img":false}]}
{"op":"mcm","clk":"11540896349","pt":1719499693579,"mc":[{"id":"1.230180134","rc":[{"atb":[[2.02,3.38]],"id":69176457}],"con":true,"img":false}]}
{"op":"mcm","clk":"11540896363","pt":1719499693793,"mc":[{"id":"1.230180134","rc":[{"atb":[[2.04,3.15]],"id":69176457}],"con":true,"img":false}]}
{"op":"mcm","clk":"11540896428","pt":1719499694601,"mc":[{"id":"1.230180134","rc":[{"atb":[[2.02,0]],"id":69176457}],"con":true,"img":false}]}
{"op":"mcm","clk":"11540896450","pt":1719499694902,"mc":[{"id":"1.230180134","rc":[{"atb":[[2.16,10.94]],"id":65040144}],"con":true,"img":false}]}
{"op":"mcm","clk":"11540896467","pt":1719499695113,"mc":[{"id":"1.230180134","rc":[{"atb":[[2.04,6.54]],"id":69176457}],"con":true,"img":false}]}
{"op":"mcm","clk":"11540898164","pt":1719499714613,"mc":[{"id":"1.230180134","rc":[{"atb":[[2.16,0]],"id":52032624}],"con":true,"img":false}]}
{"op":"mcm","clk":"11540899476","pt":1719499729850,"mc":[{"id":"1.230180134","rc":[{"atb":[[2.22,9.71]],"id":52032624}],"con":true,"img":false}]}
{"op":"mcm","clk":"11540899694","pt":1719499732050,"mc":[{"id":"1.230180134","rc":[{"atb":[[1.69,0]],"id":41401491},{"atb":[[2.34,0]],"id":4065261}],"con":true,"img":false}]}
{"op":"mcm","clk":"11540899957","pt":1719499734828,"mc":[{"id":"1.230180134","rc":[{"atb":[[2.38,9.2]],"id":4065261}],"con":true,"img":false}]}
{"op":"mcm","clk":"11540899978","pt":1719499735138,"mc":[{"id":"1.230180134","rc":[{"atb":[[1.71,17.88]],"id":41401491}],"con":true,"img":false}]}
{"op":"mcm","clk":"11540900690","pt":1719499743743,"mc":[{"id":"1.230180134","rc":[{"atb":[[2.14,0]],"id":65040144}],"con":true,"img":false}]}
{"op":"mcm","clk":"11540900996","pt":1719499746945,"mc":[{"id":"1.230180134","rc":[{"atb":[[2.18,10.03]],"id":65040144}],"con":true,"img":false}]}
{"op":"mcm","clk":"11540902717","pt":1719499767366,"mc":[{"id":"1.230180134","rc":[{"atb":[[1.7,0]],"id":41401491},{"atb":[[2.36,0]],"id":4065261}],"con":true,"img":false}]}
{"op":"mcm","clk":"11540903127","pt":1719499771869,"mc":[{"id":"1.230180134","rc":[{"atb":[[2.24,10.24]],"id":52032624}],"con":true,"img":false}]}
{"op":"mcm","clk":"11540904147","pt":1719499783773,"mc":[{"id":"1.230180134","rc":[{"atb":[[2.4,8.45]],"id":4065261}],"con":true,"img":false}]}
{"op":"mcm","clk":"11540904166","pt":1719499783980,"mc":[{"id":"1.230180134","rc":[{"atb":[[1.72,16.44]],"id":41401491}],"con":true,"img":false}]}
{"op":"mcm","clk":"11540905958","pt":1719499804325,"mc":[{"id":"1.230180134","rc":[{"atb":[[2.22,0]],"id":52032624}],"con":true,"img":false}]}
{"op":"mcm","clk":"11540906445","pt":1719499809899,"mc":[{"id":"1.230180134","rc":[{"atb":[[1.71,0]],"id":41401491},{"atb":[[2.38,0]],"id":4065261},{"atb":[[2.16,0]],"id":65040144}],"con":true,"img":false}]}
{"op":"mcm","clk":"11540906588","pt":1719499811437,"mc":[{"id":"1.230180134","rc":[{"atb":[[2.2,10.58]],"id":65040144}],"con":true,"img":false}]}
{"op":"mcm","clk":"11540907020","pt":1719499816544,"mc":[{"id":"1.230180134","rc":[{"atb":[[2.26,11.39]],"id":52032624}],"con":true,"img":false}]}
{"op":"mcm","clk":"11540908795","pt":1719499836864,"mc":[{"id":"1.230180134","rc":[{"atb":[[1.72,0]],"id":41401491},{"atb":[[2.4,0]],"id":4065261},{"atb":[[2.18,0]],"id":65040144}],"con":true,"img":false}]}
{"op":"mcm","clk":"11540909558","pt":1719499845758,"mc":[{"id":"1.230180134","rc":[{"atb":[[2.24,0]],"id":52032624}],"con":true,"img":false}]}
{"op":"mcm","clk":"11540910146","pt":1719499852359,"mc":[{"id":"1.230180134","rc":[{"atb":[[1.68,17.42]],"id":41401491},{"atb":[[2.22,9.71]],"id":4065261}],"con":true,"img":false}]}
{"op":"mcm","clk":"11540910160","pt":1719499852567,"mc":[{"id":"1.230180134","rc":[{"atb":[[2.22,9.71]],"id":65040144}],"con":true,"img":false}]}
{"op":"mcm","clk":"11540912225","pt":1719499877279,"mc":[{"id":"1.230180134","rc":[{"atb":[[2.2,0]],"id":65040144}],"con":true,"img":false}]}
{"op":"mcm","clk":"11540912919","pt":1719499885588,"mc":[{"id":"1.230180134","rc":[{"atb":[[2.26,2]],"id":52032624}],"con":true,"img":false}]}
{"op":"mcm","clk":"11540913220","pt":1719499889605,"mc":[{"id":"1.230180134","rc":[{"atb":[[2.22,9.71]],"id":52032624}],"con":true,"img":false}]}
{"op":"mcm","clk":"11540914924","pt":1719499910047,"mc":[{"id":"1.230180134","rc":[{"atb":[[2.22,0]],"id":65040144}],"con":true,"img":false}]}
{"op":"mcm","clk":"11540914969","pt":1719499910529,"mc":[{"id":"1.230180134","rc":[{"atb":[[2.14,10.39]],"id":65040144}],"con":true,"img":false}]}
{"op":"mcm","clk":"11540916091","pt":1719499923450,"mc":[{"id":"1.230180134","rc":[{"atb":[[2.24,10.24]],"id":4065261}],"con":true,"img":false}]}
{"op":"mcm","clk":"11540916115","pt":1719499923757,"mc":[{"id":"1.230180134","rc":[{"atb":[[1.69,18.4]],"id":41401491}],"con":true,"img":false}]}
{"op":"mcm","clk":"11540918782","pt":1719499959400,"mc":[{"id":"1.230180134","rc":[{"atb":[[2.16,10.94]],"id":65040144}],"con":true,"img":false}]}
{"op":"mcm","clk":"11540918800","pt":1719499959563,"mc":[{"id":"1.230180134","rc":[{"atb":[[2.24,10.24]],"id":52032624}],"con":true,"img":false}]}
{"op":"mcm","clk":"11540918850","pt":1719499960290,"mc":[{"id":"1.230180134","rc":[{"atb":[[1.68,0]],"id":41401491},{"atb":[[2.22,0]],"id":4065261}],"con":true,"img":false}]}
{"op":"mcm","clk":"11540919229","pt":1719499965077,"mc":[{"id":"1.230180134","rc":[{"atb":[[2.26,9.39]],"id":4065261}],"con":true,"img":false}]}
{"op":"mcm","clk":"11540919244","pt":1719499965284,"mc":[{"id":"1.230180134","rc":[{"atb":[[1.7,16.92]],"id":41401491}],"con":true,"img":false}]}
{"op":"mcm","clk":"11540920899","pt":1719499985829,"mc":[{"id":"1.230180134","rc":[{"atb":[[2.22,0]],"id":52032624},{"atb":[[2.14,0]],"id":65040144}],"con":true,"img":false}]}
{"op":"mcm","clk":"11540921295","pt":1719499991434,"mc":[{"id":"1.230180134","rc":[{"atb":[[2.18,10.03]],"id":65040144}],"con":true,"img":false}]}
{"op":"mcm","clk":"11540921307","pt":1719499991637,"mc":[{"id":"1.230180134","rc":[{"atb":[[2.26,11.39]],"id":52032624}],"con":true,"img":false}]}
{"op":"mcm","clk":"11540923027","pt":1719500015636,"mc":[{"id":"1.230180134","rc":[{"atb":[[1.69,0]],"id":41401491},{"atb":[[2.24,0]],"id":52032624},{"atb":[[2.24,0]],"id":4065261},{"atb":[[2.16,0]],"id":65040144}],"con":true,"img":false}]}
{"op":"mcm","clk":"11540924389","pt":1719500033582,"mc":[{"id":"1.230180134","rc":[{"atb":[[2.28,9.92]],"id":4065261}],"con":true,"img":false}]}
{"op":"mcm","clk":"11540924412","pt":1719500033873,"mc":[{"id":"1.230180134","rc":[{"atb":[[2.28,9.92]],"id":52032624},{"atb":[[2.2,10.58]],"id":65040144}],"con":true,"img":false}]}
{"op":"mcm","clk":"11540924433","pt":1719500034171,"mc":[{"id":"1.230180134","rc":[{"atb":[[1.71,17.88]],"id":41401491}],"con":true,"img":false}]}
{"op":"mcm","clk":"11540926234","pt":1719500056790,"mc":[{"id":"1.230180134","rc":[{"atb":[[1.7,0]],"id":41401491},{"atb":[[2.26,2]],"id":52032624},{"atb":[[2.26,0]],"id":4065261},{"atb":[[2.18,0]],"id":65040144}],"con":true,"img":false}]}
{"op":"mcm","clk":"11540926586","pt":1719500061212,"mc":[{"id":"1.230180134","rc":[{"atb":[[2.3,9.11]],"id":4065261}],"con":true,"img":false}]}
{"op":"mcm","clk":"11540926597","pt":1719500061308,"mc":[{"id":"1.230180134","rc":[{"atb":[[1.72,16.44]],"id":41401491}],"con":true,"img":false}]}
{"op":"mcm","clk":"11540926604","pt":1719500061410,"mc":[{"id":"1.230180134","rc":[{"atb":[[2.22,9.71]],"id":65040144}],"con":true,"img":false}]}
{"op":"mcm","clk":"11540926613","pt":1719500061513,"mc":[{"id":"1.230180134","rc":[{"atb":[[2.3,9.11]],"id":52032624}],"con":true,"img":false}]}
{"op":"mcm","clk":"11540929402","pt":1719500096555,"mc":[{"id":"1.230180134","rc":[{"atb":[[1.71,0]],"id":41401491},{"atb":[[2.28,0]],"id":52032624},{"atb":[[2.28,0]],"id":4065261},{"atb":[[2.2,0]],"id":65040144}],"con":true,"img":false}]}
{"op":"mcm","clk":"11540930401","pt":1719500107771,"mc":[{"id":"1.230180134","rc":[{"atb":[[1.73,17.39]],"id":41401491},{"atb":[[2.24,10.24]],"id":65040144}],"con":true,"img":false}]}
{"op":"mcm","clk":"11540930427","pt":1719500108076,"mc":[{"id":"1.230180134","rc":[{"atb":[[2.32,9.61]],"id":52032624},{"atb":[[2.32,9.61]],"id":4065261}],"con":true,"img":false}]}
{"op":"mcm","clk":"11540933352","pt":1719500143280,"mc":[{"id":"1.230180134","rc":[{"atb":[[1.72,0]],"id":41401491},{"atb":[[2.3,0]],"id":52032624},{"atb":[[2.3,0]],"id":4065261},{"atb":[[2.22,0]],"id":65040144}],"con":true,"img":false}]}
{"op":"mcm","clk":"11540933715","pt":1719500147874,"mc":[{"id":"1.230180134","rc":[{"atb":[[2.34,8.83]],"id":4065261},{"atb":[[2.26,9.39]],"id":65040144}],"con":true,"img":false}]}
{"op":"mcm","clk":"11540933733","pt":1719500148087,"mc":[{"id":"1.230180134","rc":[{"atb":[[1.74,16]],"id":41401491}],"con":true,"img":false}]}
{"op":"mcm","clk":"11540933749","pt":1719500148288,"mc":[{"id":"1.230180134","rc":[{"atb":[[2.34,8.83]],"id":52032624}],"con":true,"img":false}]}
{"op":"mcm","clk":"11540935472","pt":1719500169137,"mc":[{"id":"1.230180134","rc":[{"atb":[[1.73,0]],"id":41401491},{"atb":[[2.32,0]],"id":52032624},{"atb":[[2.32,0]],"id":4065261},{"atb":[[2.24,0]],"id":65040144}],"con":true,"img":false}]}
{"op":"mcm","clk":"11540939282","pt":1719500215785,"mc":[{"id":"1.230180134","rc":[{"atb":[[2.36,9.33]],"id":4065261}],"con":true,"img":false}]}
{"op":"mcm","clk":"11540939295","pt":1719500215994,"mc":[{"id":"1.230180134","rc":[{"atb":[[1.75,16.93]],"id":41401491}],"con":true,"img":false}]}
{"op":"mcm","clk":"11540939304","pt":1719500216058,"mc":[{"id":"1.230180134","rc":[{"atb":[[1.74,0]],"id":41401491},{"atb":[[2.34,0]],"id":52032624},{"atb":[[2.34,0]],"id":4065261},{"atb":[[2.28,9.92],[2.26,0]],"id":65040144}],"con":true,"img":false}]}
{"op":"mcm","clk":"11540939324","pt":1719500216264,"mc":[{"id":"1.230180134","rc":[{"atb":[[2.36,9.33]],"id":52032624}],"con":true,"img":false}]}
{"op":"mcm","clk":"11540939757","pt":1719500221585,"mc":[{"id":"1.230180134","rc":[{"atb":[[1.68,17.42]],"id":41401491}],"con":true,"img":false}]}
{"op":"mcm","clk":"11540941048","pt":1719500240717,"mc":[{"id":"1.230180134","rc":[{"atb":[[2.38,8.58]],"id":4065261}],"con":true,"img":false}]}
{"op":"mcm","clk":"11540941064","pt":1719500240924,"mc":[{"id":"1.230180134","rc":[{"atb":[[2.38,8.58]],"id":52032624}],"con":true,"img":false}]}
{"op":"mcm","clk":"11540941078","pt":1719500241088,"mc":[{"id":"1.230180134","rc":[{"atb":[[2.3,9.11]],"id":65040144}],"con":true,"img":false}]}
{"op":"mcm","clk":"11540943029","pt":1719500268760,"mc":[{"id":"1.230180134","rc":[{"atl":[[2.16,0]],"id":41401491}],"con":true,"img":false}]}
{"op":"mcm","clk":"11540943588","pt":1719500276226,"mc":[{"id":"1.230180134","rc":[{"atb":[[2.04,3.38]],"id":69176457}],"con":true,"img":false}]}
{"op":"mcm","clk":"11540943811","pt":1719500278849,"mc":[{"id":"1.230180134","rc":[{"atb":[[1.75,0]],"id":41401491},{"atb":[[2.36,0]],"id":52032624},{"atb":[[2.36,0]],"id":4065261},{"atb":[[2.28,0]],"id":65040144}],"con":true,"img":false}]}
{"op":"mcm","clk":"11540944508","pt":1719500287675,"mc":[{"id":"1.230180134","rc":[{"atb":[[2.04,0]],"id":69176457}],"con":true,"img":false}]}
{"op":"mcm","clk":"11540944513","pt":1719500287779,"mc":[{"id":"1.230180134","rc":[{"atb":[[1.69,18.4]],"id":41401491}],"con":true,"img":false}]}
{"op":"mcm","clk":"11540944531","pt":1719500288084,"mc":[{"id":"1.230180134","rc":[{"atb":[[2.4,9.06]],"id":4065261}],"con":true,"img":false}]}
{"op":"mcm","clk":"11540944555","pt":1719500288359,"mc":[{"id":"1.230180134","rc":[{"atb":[[2.4,9.06]],"id":52032624},{"atb":[[2.32,9.61]],"id":65040144}],"con":true,"img":false}]}
{"op":"mcm","clk":"11540945102","pt":1719500294678,"mc":[{"id":"1.230180134","rc":[{"atb":[[2.02,3.15]],"id":69176457}],"con":true,"img":false}]}
{"op":"mcm","clk":"11540947721","pt":1719500327120,"mc":[{"id":"1.230180134","rc":[{"atb":[[2.02,6.54]],"id":69176457}],"con":true,"img":false}]}
{"op":"mcm","clk":"11540947802","pt":1719500328002,"mc":[{"id":"1.230180134","rc":[{"atb":[[1.68,0]],"id":41401491},{"atb":[[2.38,0]],"id":52032624},{"atb":[[2.38,0]],"id":4065261},{"atb":[[2.3,0]],"id":65040144}],"con":true,"img":false}]}
{"op":"mcm","clk":"11540948146","pt":1719500332297,"mc":[{"id":"1.230180134","rc":[{"atb":[[2.42,8.33]],"id":4065261}],"con":true,"img":false}]}
{"op":"mcm","clk":"11540948153","pt":1719500332398,"mc":[{"id":"1.230180134","rc":[{"atb":[[2.34,8.83]],"id":65040144}],"con":true,"img":false}]}
{"op":"mcm","clk":"11540948162","pt":1719500332500,"mc":[{"id":"1.230180134","rc":[{"atb":[[1.7,16.92]],"id":41401491}],"con":true,"img":false}]}
{"op":"mcm","clk":"11540948182","pt":1719500332706,"mc":[{"id":"1.230180134","rc":[{"atb":[[2.42,8.33]],"id":52032624}],"con":true,"img":false}]}
{"op":"mcm","clk":"11540952336","pt":1719500384167,"mc":[{"id":"1.230180134","rc":[{"atb":[[1.69,0]],"id":41401491},{"atb":[[2.4,0]],"id":52032624},{"atb":[[2.4,0]],"id":4065261},{"atb":[[2.32,0]],"id":65040144}],"con":true,"img":false}]}
{"op":"mcm","clk":"11540954650","pt":1719500409123,"mc":[{"id":"1.230180134","rc":[{"atb":[[1.02,16.49],[1.7,0],[1.76,16.29]],"id":41401491},{"trd":[[2.14,4.47]],"ltp":2.14,"tv":4.47,"id":41401491},{"atb":[[1.03,10.99],[2.42,0],[1.91,21.84]],"id":52032624},{"atb":[[2.42,0],[1.02,16.49],[1.91,17.47]],"id":4065261},{"atb":[[2,20.38],[2.02,6.54],[1.03,10.99]],"id":69176457},{"atb":[[1.02,16.49],[1.91,14.56],[2.34,0]],"id":65040144},{"spb":[[1000,100.12]],"id":65040144}],"con":true,"img":false}]}
{"op":"mcm","clk":"11540955173","pt":1719500414306,"mc":[{"id":"1.230180134","rc":[{"atb":[[2.14,10.4]],"id":4065261}],"con":true,"img":false}]}
{"op":"mcm","clk":"11540955189","pt":1719500414512,"mc":[{"id":"1.230180134","rc":[{"atb":[[1.68,17.44]],"id":41401491}],"con":true,"img":false}]}
{"op":"mcm","clk":"11540955205","pt":1719500414720,"mc":[{"id":"1.230180134","rc":[{"atb":[[2.14,10.4]],"id":65040144}],"con":true,"img":false}]}
{"op":"mcm","clk":"11540955212","pt":1719500414827,"mc":[{"id":"1.230180134","rc":[{"atb":[[2.14,10.4]],"id":52032624}],"con":true,"img":false}]}
{"op":"mcm","clk":"11540959305","pt":1719500467657,"mc":[{"id":"1.230180134","rc":[{"atb":[[2.16,10.94]],"id":4065261}],"con":true,"img":false}]}
{"op":"mcm","clk":"11540959320","pt":1719500467865,"mc":[{"id":"1.230180134","rc":[{"atb":[[2.16,10.94]],"id":65040144}],"con":true,"img":false}]}
{"op":"mcm","clk":"11540959327","pt":1719500467988,"mc":[{"id":"1.230180134","rc":[{"atb":[[1.69,18.4]],"id":41401491}],"con":true,"img":false}]}
{"op":"mcm","clk":"11540959353","pt":1719500468281,"mc":[{"id":"1.230180134","rc":[{"atb":[[2.16,10.94]],"id":52032624}],"con":true,"img":false}]}
{"op":"mcm","clk":"11540962582","pt":1719500511212,"mc":[{"id":"1.230180134","rc":[{"atb":[[1.68,0]],"id":41401491},{"atb":[[2.14,0]],"id":52032624},{"atb":[[2.14,0]],"id":4065261},{"atb":[[2.14,0]],"id":65040144}],"con":true,"img":false}]}
{"op":"mcm","clk":"11540962876","pt":1719500514939,"mc":[{"id":"1.230180134","rc":[{"atb":[[2.18,10.04]],"id":4065261}],"con":true,"img":false}]}
{"op":"mcm","clk":"11540962888","pt":1719500515146,"mc":[{"id":"1.230180134","rc":[{"atb":[[2.18,10.04]],"id":52032624},{"atb":[[2.18,10.04]],"id":65040144}],"con":true,"img":false}]}
{"op":"mcm","clk":"11540962904","pt":1719500515306,"mc":[{"id":"1.230180134","rc":[{"atb":[[1.7,16.94]],"id":41401491}],"con":true,"img":false}]}
{"op":"mcm","clk":"11540966325","pt":1719500558891,"mc":[{"id":"1.230180134","rc":[{"atb":[[1.69,0]],"id":41401491},{"atb":[[2.16,0]],"id":52032624},{"atb":[[2.16,0]],"id":4065261},{"atb":[[2.16,0]],"id":65040144}],"con":true,"img":false}]}
{"op":"mcm","clk":"11540966535","pt":1719500561590,"mc":[{"id":"1.230180134","rc":[{"atb":[[2.2,10.58]],"id":4065261}],"con":true,"img":false}]}
{"op":"mcm","clk":"11540966540","pt":1719500561693,"mc":[{"id":"1.230180134","rc":[{"atb":[[2.2,10.58]],"id":65040144}],"con":true,"img":false}]}
{"op":"mcm","clk":"11540966551","pt":1719500561901,"mc":[{"id":"1.230180134","rc":[{"atb":[[1.71,17.89]],"id":41401491}],"con":true,"img":false}]}
{"op":"mcm","clk":"11540966577","pt":1719500562209,"mc":[{"id":"1.230180134","rc":[{"atb":[[2.2,10.58]],"id":52032624}],"con":true,"img":false}]}
{"op":"mcm","clk":"11540968630","pt":1719500588797,"mc":[{"id":"1.230180134","rc":[{"atb":[[1.7,0]],"id":41401491},{"atb":[[2.18,0]],"id":52032624},{"atb":[[2.18,0]],"id":4065261},{"atb":[[2.18,0]],"id":65040144}],"con":true,"img":false}]}
{"op":"mcm","clk":"11540969960","pt":1719500605062,"mc":[{"id":"1.230180134","rc":[{"atb":[[2.22,9.72]],"id":4065261}],"con":true,"img":false}]}
{"op":"mcm","clk":"11540969980","pt":1719500605217,"mc":[{"id":"1.230180134","rc":[{"atb":[[1.72,16.46]],"id":41401491},{"atb":[[2.22,9.72]],"id":65040144}],"con":true,"img":false}]}
{"op":"mcm","clk":"11540969998","pt":1719500605422,"mc":[{"id":"1.230180134","rc":[{"atb":[[2.22,9.72]],"id":52032624}],"con":true,"img":false}]}
{"op":"mcm","clk":"11540971415","pt":1719500620608,"mc":[{"id":"1.230180134","rc":[{"atb":[[1.71,0]],"id":41401491},{"atb":[[2.2,0]],"id":52032624},{"atb":[[2.2,0]],"id":4065261},{"atb":[[2.2,0]],"id":65040144}],"con":true,"img":false}]}
{"op":"mcm","clk":"11540974662","pt":1719500658190,"mc":[{"id":"1.230180134","rc":[{"atb":[[1.72,0]],"id":41401491},{"atb":[[2.22,0]],"id":52032624},{"atb":[[2.22,0]],"id":4065261},{"atb":[[2.22,0]],"id":65040144}],"con":true,"img":false}]}
{"op":"mcm","clk":"11540975424","pt":1719500666603,"mc":[{"id":"1.230180134","rc":[{"atb":[[2.14,10.4]],"id":4065261}],"con":true,"img":false}]}
{"op":"mcm","clk":"11540975433","pt":1719500666713,"mc":[{"id":"1.230180134","rc":[{"atb":[[1.68,17.44]],"id":41401491}],"con":true,"img":false}]}
{"op":"mcm","clk":"11540975443","pt":1719500666810,"mc":[{"id":"1.230180134","rc":[{"atb":[[2.14,10.4]],"id":52032624}],"con":true,"img":false}]}
{"op":"mcm","clk":"11540975459","pt":1719500667017,"mc":[{"id":"1.230180134","rc":[{"atb":[[2.14,10.4]],"id":65040144}],"con":true,"img":false}]}
{"op":"mcm","clk":"11540979151","pt":1719500709960,"mc":[{"id":"1.230180134","rc":[{"atb":[[1.69,18.4]],"id":41401491}],"con":true,"img":false}]}
{"op":"mcm","clk":"11540979159","pt":1719500710060,"mc":[{"id":"1.230180134","rc":[{"atb":[[2.16,10.94]],"id":4065261}],"con":true,"img":false}]}
{"op":"mcm","clk":"11540979180","pt":1719500710268,"mc":[{"id":"1.230180134","rc":[{"atb":[[2.16,10.94]],"id":52032624}],"con":true,"img":false}]}
{"op":"mcm","clk":"11540979198","pt":1719500710473,"mc":[{"id":"1.230180134","rc":[{"atb":[[2.16,10.94]],"id":65040144}],"con":true,"img":false}]}
{"op":"mcm","clk":"11540982514","pt":1719500752387,"mc":[{"id":"1.230180134","rc":[{"atb":[[1.68,0]],"id":41401491},{"atb":[[2.14,0]],"id":52032624},{"atb":[[2.14,0]],"id":4065261},{"atb":[[2.14,0]],"id":65040144}],"con":true,"img":false}]}
{"op":"mcm","clk":"11540982851","pt":1719500756521,"mc":[{"id":"1.230180134","rc":[{"atb":[[2.18,10.04]],"id":4065261}],"con":true,"img":false}]}
{"op":"mcm","clk":"11540982858","pt":1719500756623,"mc":[{"id":"1.230180134","rc":[{"atb":[[2.18,10.04]],"id":65040144}],"con":true,"img":false}]}
{"op":"mcm","clk":"11540982863","pt":1719500756725,"mc":[{"id":"1.230180134","rc":[{"atb":[[1.7,16.94]],"id":41401491}],"con":true,"img":false}]}
{"op":"mcm","clk":"11540982873","pt":1719500756828,"mc":[{"id":"1.230180134","rc":[{"atb":[[2.18,10.04]],"id":52032624}],"con":true,"img":false}]}
{"op":"mcm","clk":"11540984561","pt":1719500776017,"mc":[{"id":"1.230180134","rc":[{"atb":[[1.69,0]],"id":41401491},{"atb":[[2.16,0]],"id":52032624},{"atb":[[2.16,0]],"id":4065261},{"atb":[[2.16,0]],"id":65040144}],"con":true,"img":false}]}
{"op":"mcm","clk":"11540987709","pt":1719500813195,"mc":[{"id":"1.230180134","rc":[{"atb":[[1.7,0]],"id":41401491},{"atb":[[2.18,0]],"id":52032624},{"atb":[[2.18,0]],"id":4065261},{"atb":[[2.18,0]],"id":65040144}],"con":true,"img":false}]}
{"op":"mcm","clk":"11540989090","pt":1719500828831,"mc":[{"id":"1.230180134","rc":[{"atb":[[2.14,10.4]],"id":4065261}],"con":true,"img":false}]}
{"op":"mcm","clk":"11540989100","pt":1719500828878,"mc":[{"id":"1.230180134","rc":[{"atb":[[2.14,10.4]],"id":65040144}],"con":true,"img":false}]}
{"op":"mcm","clk":"11540989110","pt":1719500828989,"mc":[{"id":"1.230180134","rc":[{"atb":[[1.68,17.44]],"id":41401491}],"con":true,"img":false}]}
{"op":"mcm","clk":"11540989139","pt":1719500829297,"mc":[{"id":"1.230180134","rc":[{"atb":[[2.14,10.4]],"id":52032624}],"con":true,"img":false}]}
{"op":"mcm","clk":"11540994989","pt":1719500897364,"mc":[{"id":"1.230180134","rc":[{"atb":[[2.16,10.94]],"id":4065261}],"con":true,"img":false}]}
{"op":"mcm","clk":"11540994996","pt":1719500897470,"mc":[{"id":"1.230180134","rc":[{"atb":[[2.16,10.94]],"id":65040144}],"con":true,"img":false}]}
{"op":"mcm","clk":"11540995012","pt":1719500897676,"mc":[{"id":"1.230180134","rc":[{"atb":[[1.69,18.4]],"id":41401491}],"con":true,"img":false}]}
{"op":"mcm","clk":"11540995037","pt":1719500897985,"mc":[{"id":"1.230180134","rc":[{"atb":[[2.16,10.94]],"id":52032624}],"con":true,"img":false}]}
{"op":"mcm","clk":"11540997602","pt":1719500933458,"mc":[{"id":"1.230180134","rc":[{"atb":[[1.68,0]],"id":41401491},{"atb":[[2.14,0]],"id":52032624},{"atb":[[2.14,0]],"id":4065261},{"atb":[[2.14,0]],"id":65040144}],"con":true,"img":false}]}
{"op":"mcm","clk":"11540997910","pt":1719500937127,"mc":[{"id":"1.230180134","rc":[{"atb":[[1.7,16.94]],"id":41401491}],"con":true,"img":false}]}
{"op":"mcm","clk":"11540997928","pt":1719500937338,"mc":[{"id":"1.230180134","rc":[{"atb":[[2.18,10.04]],"id":65040144}],"con":true,"img":false}]}
{"op":"mcm","clk":"11540997942","pt":1719500937543,"mc":[{"id":"1.230180134","rc":[{"atb":[[2.18,10.04]],"id":4065261}],"con":true,"img":false}]}
{"op":"mcm","clk":"11540997956","pt":1719500937752,"mc":[{"id":"1.230180134","rc":[{"atb":[[2.18,10.04]],"id":52032624}],"con":true,"img":false}]}
{"op":"mcm","clk":"11541002058","pt":1719500995042,"mc":[{"id":"1.230180134","rc":[{"atb":[[1.69,0]],"id":41401491},{"atb":[[2.16,0]],"id":52032624},{"atb":[[2.16,0]],"id":4065261},{"atb":[[2.16,0]],"id":65040144}],"con":true,"img":false}]}
{"op":"mcm","clk":"11541002681","pt":1719501003120,"mc":[{"id":"1.230180134","rc":[{"atb":[[2.2,10.58]],"id":4065261}],"con":true,"img":false}]}
{"op":"mcm","clk":"11541002691","pt":1719501003226,"mc":[{"id":"1.230180134","rc":[{"atb":[[2.2,10.58]],"id":52032624}],"con":true,"img":false}]}
{"op":"mcm","clk":"11541002708","pt":1719501003438,"mc":[{"id":"1.230180134","rc":[{"atb":[[2.2,10.58]],"id":65040144}],"con":true,"img":false}]}
{"op":"mcm","clk":"11541002790","pt":1719501003854,"mc":[{"id":"1.230180134","rc":[{"atb":[[1.71,17.89]],"id":41401491}],"con":true,"img":false}]}
{"op":"mcm","clk":"11541005943","pt":1719501044887,"mc":[{"id":"1.230180134","rc":[{"atb":[[1.7,0]],"id":41401491},{"atb":[[2.18,0]],"id":52032624},{"atb":[[2.18,0]],"id":4065261},{"atb":[[2.18,0]],"id":65040144}],"con":true,"img":false}]}
{"op":"mcm","clk":"11541006200","pt":1719501049074,"mc":[{"id":"1.230180134","rc":[{"atb":[[2.22,9.72]],"id":4065261}],"con":true,"img":false}]}
{"op":"mcm","clk":"11541006208","pt":1719501049172,"mc":[{"id":"1.230180134","rc":[{"atb":[[2.22,9.72]],"id":65040144}],"con":true,"img":false}]}
{"op":"mcm","clk":"11541006215","pt":1719501049297,"mc":[{"id":"1.230180134","rc":[{"atb":[[2.22,9.72]],"id":52032624}],"con":true,"img":false}]}
{"op":"mcm","clk":"11541006232","pt":1719501049485,"mc":[{"id":"1.230180134","rc":[{"atb":[[1.72,16.46]],"id":41401491}],"con":true,"img":false}]}
{"op":"mcm","clk":"11541008603","pt":1719501084214,"mc":[{"id":"1.230180134","rc":[{"atb":[[1.71,0]],"id":41401491},{"atb":[[2.2,0]],"id":52032624},{"atb":[[2.2,0]],"id":4065261},{"atb":[[2.2,0]],"id":65040144}],"con":true,"img":false}]}
{"op":"mcm","clk":"11541009576","pt":1719501097935,"mc":[{"id":"1.230180134","rc":[{"atb":[[2.24,10.24]],"id":4065261}],"con":true,"img":false}]}
{"op":"mcm","clk":"11541009586","pt":1719501098041,"mc":[{"id":"1.230180134","rc":[{"atb":[[2.24,10.24]],"id":65040144}],"con":true,"img":false}]}
{"op":"mcm","clk":"11541009604","pt":1719501098247,"mc":[{"id":"1.230180134","rc":[{"atb":[[1.73,17.4]],"id":41401491}],"con":true,"img":false}]}
{"op":"mcm","clk":"11541009621","pt":1719501098561,"mc":[{"id":"1.230180134","rc":[{"atb":[[2.24,10.24]],"id":52032624}],"con":true,"img":false}]}
{"op":"mcm","clk":"11541010983","pt":1719501116953,"mc":[{"id":"1.230180134","rc":[{"atb":[[1.72,0]],"id":41401491},{"atb":[[2.22,0]],"id":52032624},{"atb":[[2.22,0]],"id":4065261},{"atb":[[2.22,0]],"id":65040144}],"con":true,"img":false}]}
{"op":"mcm","clk":"11541011252","pt":1719501120869,"mc":[{"id":"1.230180134","rc":[{"atb":[[2.26,11.4]],"id":52032624}],"con":true,"img":false}]}
{"op":"mcm","clk":"11541011259","pt":1719501120978,"mc":[{"id":"1.230180134","rc":[{"atb":[[2.26,9.4]],"id":65040144}],"con":true,"img":false}]}
{"op":"mcm","clk":"11541011278","pt":1719501121186,"mc":[{"id":"1.230180134","rc":[{"atb":[[2.26,9.4]],"id":4065261}],"con":true,"img":false}]}
{"op":"mcm","clk":"11541011292","pt":1719501121397,"mc":[{"id":"1.230180134","rc":[{"atb":[[1.74,16.02]],"id":41401491}],"con":true,"img":false}]}
{"op":"mcm","clk":"11541015097","pt":1719501168251,"mc":[{"id":"1.230180134","rc":[{"atb":[[1.73,0]],"id":41401491},{"atb":[[2.24,0]],"id":52032624},{"atb":[[2.24,0]],"id":4065261},{"atb":[[2.24,0]],"id":65040144}],"con":true,"img":false}]}
{"op":"mcm","clk":"11541015500","pt":1719501172531,"mc":[{"id":"1.230180134","rc":[{"atb":[[2.28,9.92]],"id":4065261}],"con":true,"img":false}]}
{"op":"mcm","clk":"11541015510","pt":1719501172637,"mc":[{"id":"1.230180134","rc":[{"atb":[[2.28,9.92]],"id":65040144}],"con":true,"img":false}]}
{"op":"mcm","clk":"11541015533","pt":1719501172845,"mc":[{"id":"1.230180134","rc":[{"atb":[[1.75,16.93]],"id":41401491}],"con":true,"img":false}]}
{"op":"mcm","clk":"11541015566","pt":1719501173154,"mc":[{"id":"1.230180134","rc":[{"atb":[[2.28,9.92]],"id":52032624}],"con":true,"img":false}]}
{"op":"mcm","clk":"11541018769","pt":1719501207896,"mc":[{"id":"1.230180134","rc":[{"atb":[[1.74,0]],"id":41401491},{"atb":[[2.26,2]],"id":52032624},{"atb":[[2.26,0]],"id":4065261},{"atb":[[2.26,0]],"id":65040144}],"con":true,"img":false}]}
{"op":"mcm","clk":"11541019109","pt":1719501211784,"mc":[{"id":"1.230180134","rc":[{"atb":[[2.3,9.12]],"id":4065261}],"con":true,"img":false}]}
{"op":"mcm","clk":"11541019119","pt":1719501211883,"mc":[{"id":"1.230180134","rc":[{"atb":[[2.3,9.12]],"id":65040144}],"con":true,"img":false}]}
{"op":"mcm","clk":"11541019126","pt":1719501211987,"mc":[{"id":"1.230180134","rc":[{"atb":[[1.68,17.44]],"id":41401491}],"con":true,"img":false}]}
{"op":"mcm","clk":"11541019143","pt":1719501212200,"mc":[{"id":"1.230180134","rc":[{"atb":[[2.3,9.12]],"id":52032624}],"con":true,"img":false}]}
{"op":"mcm","clk":"11541023954","pt":1719501267654,"mc":[{"id":"1.230180134","rc":[{"atb":[[1.75,0]],"id":41401491},{"atb":[[2.28,0]],"id":52032624},{"atb":[[2.28,0]],"id":4065261},{"atb":[[2.28,0]],"id":65040144}],"con":true,"img":false}]}
{"op":"mcm","clk":"11541024661","pt":1719501275946,"mc":[{"id":"1.230180134","rc":[{"atb":[[2.32,9.61]],"id":4065261}],"con":true,"img":false}]}
{"op":"mcm","clk":"11541024672","pt":1719501276054,"mc":[{"id":"1.230180134","rc":[{"atb":[[2.32,9.61]],"id":65040144}],"con":true,"img":false}]}
{"op":"mcm","clk":"11541024709","pt":1719501276511,"mc":[{"id":"1.230180134","rc":[{"atb":[[1.69,18.4]],"id":41401491}],"con":true,"img":false}]}
{"op":"mcm","clk":"11541024741","pt":1719501276870,"mc":[{"id":"1.230180134","rc":[{"atb":[[2.32,9.61]],"id":52032624}],"con":true,"img":false}]}
{"op":"mcm","clk":"11541028506","pt":1719501316098,"mc":[{"id":"1.230180134","rc":[{"atb":[[1.68,0]],"id":41401491},{"atb":[[2.3,0]],"id":52032624},{"atb":[[2.3,0]],"id":4065261},{"atb":[[2.3,0]],"id":65040144}],"con":true,"img":false}]}
{"op":"mcm","clk":"11541028876","pt":1719501320093,"mc":[{"id":"1.230180134","rc":[{"atb":[[2.34,8.84]],"id":4065261}],"con":true,"img":false}]}
{"op":"mcm","clk":"11541028900","pt":1719501320305,"mc":[{"id":"1.230180134","rc":[{"atb":[[1.7,16.94]],"id":41401491}],"con":true,"img":false}]}
{"op":"mcm","clk":"11541028932","pt":1719501320511,"mc":[{"id":"1.230180134","rc":[{"atb":[[2.34,8.84]],"id":65040144}],"con":true,"img":false}]}
{"op":"mcm","clk":"11541028956","pt":1719501320719,"mc":[{"id":"1.230180134","rc":[{"atb":[[2.34,8.84]],"id":52032624}],"con":true,"img":false}]}
{"op":"mcm","clk":"11541031882","pt":1719501353082,"mc":[{"id":"1.230180134","rc":[{"atb":[[1.69,0]],"id":41401491},{"atb":[[2.32,0]],"id":52032624},{"atb":[[2.32,0]],"id":4065261},{"atb":[[2.32,0]],"id":65040144}],"con":true,"img":false}]}
{"op":"mcm","clk":"11541032588","pt":1719501361061,"mc":[{"id":"1.230180134","rc":[{"atb":[[2.36,9.33]],"id":4065261}],"con":true,"img":false}]}
{"op":"mcm","clk":"11541032609","pt":1719501361264,"mc":[{"id":"1.230180134","rc":[{"atb":[[1.71,17.89]],"id":41401491}],"con":true,"img":false}]}
{"op":"mcm","clk":"11541032621","pt":1719501361367,"mc":[{"id":"1.230180134","rc":[{"atb":[[2.36,9.33]],"id":65040144}],"con":true,"img":false}]}
{"op":"mcm","clk":"11541032640","pt":1719501361579,"mc":[{"id":"1.230180134","rc":[{"atb":[[2.36,9.33]],"id":52032624}],"con":true,"img":false}]}
{"op":"mcm","clk":"11541034943","pt":1719501387408,"mc":[{"id":"1.230180134","rc":[{"atb":[[1.7,0]],"id":41401491},{"atb":[[2.34,0]],"id":52032624},{"atb":[[2.34,0]],"id":4065261},{"atb":[[2.34,0]],"id":65040144}],"con":true,"img":false}]}
{"op":"mcm","clk":"11541035337","pt":1719501392091,"mc":[{"id":"1.230180134","rc":[{"atb":[[2.38,8.59]],"id":4065261}],"con":true,"img":false}]}
{"op":"mcm","clk":"11541035349","pt":1719501392191,"mc":[{"id":"1.230180134","rc":[{"atb":[[1.72,16.46]],"id":41401491}],"con":true,"img":false}]}
{"op":"mcm","clk":"11541035358","pt":1719501392295,"mc":[{"id":"1.230180134","rc":[{"atb":[[2.38,8.59]],"id":65040144}],"con":true,"img":false}]}
{"op":"mcm","clk":"11541035373","pt":1719501392502,"mc":[{"id":"1.230180134","rc":[{"atb":[[2.38,8.59]],"id":52032624}],"con":true,"img":false}]}
{"op":"mcm","clk":"11541039373","pt":1719501444387,"mc":[{"id":"1.230180134","rc":[{"atb":[[1.71,0]],"id":41401491},{"atb":[[2.36,0]],"id":52032624},{"atb":[[2.36,0]],"id":4065261},{"atb":[[2.36,0]],"id":65040144}],"con":true,"img":false}]}
{"op":"mcm","clk":"11541041655","pt":1719501473683,"mc":[{"id":"1.230180134","rc":[{"atb":[[1.72,0]],"id":41401491},{"atb":[[2.38,0]],"id":52032624},{"atb":[[2.38,0]],"id":4065261},{"atb":[[2.38,0]],"id":65040144}],"con":true,"img":false}]}
{"op":"mcm","clk":"11541041981","pt":1719501477904,"mc":[{"id":"1.230180134","rc":[{"atb":[[1.68,17.44]],"id":41401491},{"atb":[[2.14,10.4]],"id":65040144}],"con":true,"img":false}]}
{"op":"mcm","clk":"11541041992","pt":1719501478102,"mc":[{"id":"1.230180134","rc":[{"atb":[[2.14,10.4]],"id":52032624}],"con":true,"img":false}]}
{"op":"mcm","clk":"11541042001","pt":1719501478216,"mc":[{"id":"1.230180134","rc":[{"atb":[[2.14,10.4]],"id":4065261}],"con":true,"img":false}]}
{"op":"mcm","clk":"11541046304","pt":1719501531751,"mc":[{"id":"1.230180134","rc":[{"atb":[[2.16,10.94]],"id":4065261}],"con":true,"img":false}]}
{"op":"mcm","clk":"11541046321","pt":1719501531954,"mc":[{"id":"1.230180134","rc":[{"atb":[[1.69,18.4]],"id":41401491}],"con":true,"img":false}]}
{"op":"mcm","clk":"11541046332","pt":1719501532054,"mc":[{"id":"1.230180134","rc":[{"atb":[[2.16,10.94]],"id":65040144}],"con":true,"img":false}]}
{"op":"mcm","clk":"11541046368","pt":1719501532463,"mc":[{"id":"1.230180134","rc":[{"atb":[[2.16,10.94]],"id":52032624}],"con":true,"img":false}]}
{"op":"mcm","clk":"11541049202","pt":1719501565908,"mc":[{"id":"1.230180134","rc":[{"atb":[[1.68,0]],"id":41401491},{"atb":[[2.14,0]],"id":52032624},{"atb":[[2.14,0]],"id":4065261},{"atb":[[2.14,0]],"id":65040144}],"con":true,"img":false}]}
{"op":"mcm","clk":"11541049585","pt":1719501570529,"mc":[{"id":"1.230180134","rc":[{"atb":[[2.18,10.04]],"id":4065261}],"con":true,"img":false}]}
{"op":"mcm","clk":"11541049593","pt":1719501570625,"mc":[{"id":"1.230180134","rc":[{"atb":[[2.18,10.04]],"id":65040144}],"con":true,"img":false}]}
{"op":"mcm","clk":"11541049605","pt":1719501570721,"mc":[{"id":"1.230180134","rc":[{"atb":[[2.18,10.04]],"id":52032624}],"con":true,"img":false}]}
{"op":"mcm","clk":"11541049624","pt":1719501570926,"mc":[{"id":"1.230180134","rc":[{"atb":[[1.7,16.94]],"id":41401491}],"con":true,"img":false}]}
{"op":"mcm","clk":"11541052590","pt":1719501606253,"mc":[{"id":"1.230180134","rc":[{"atb":[[1.69,0]],"id":41401491},{"atb":[[2.16,0]],"id":52032624},{"atb":[[2.16,0]],"id":4065261},{"atb":[[2.16,0]],"id":65040144}],"con":true,"img":false}]}
{"op":"mcm","clk":"11541054537","pt":1719501627505,"mc":[{"id":"1.230180134","rc":[{"atb":[[1.7,0]],"id":41401491},{"atb":[[2.18,0]],"id":52032624},{"atb":[[2.18,0]],"id":4065261},{"atb":[[2.18,0]],"id":65040144}],"con":true,"img":false}]}
{"op":"mcm","clk":"11541055935","pt":1719501644225,"mc":[{"id":"1.230180134","rc":[{"atb":[[2.14,10.4]],"id":4065261}],"con":true,"img":false}]}
{"op":"mcm","clk":"11541055942","pt":1719501644321,"mc":[{"id":"1.230180134","rc":[{"atb":[[2.14,10.4]],"id":65040144}],"con":true,"img":false}]}
{"op":"mcm","clk":"11541055947","pt":1719501644432,"mc":[{"id":"1.230180134","rc":[{"atb":[[2.14,10.4]],"id":52032624}],"con":true,"img":false}]}
{"op":"mcm","clk":"11541055966","pt":1719501644630,"mc":[{"id":"1.230180134","rc":[{"atb":[[1.68,17.44]],"id":41401491}],"con":true,"img":false}]}
{"op":"mcm","clk":"11541062573","pt":1719501724456,"mc":[{"id":"1.230180134","rc":[{"atb":[[2.16,10.94]],"id":4065261}],"con":true,"img":false}]}
{"op":"mcm","clk":"11541062585","pt":1719501724659,"mc":[{"id":"1.230180134","rc":[{"atb":[[2.16,10.94]],"id":65040144}],"con":true,"img":false}]}
{"op":"mcm","clk":"11541062596","pt":1719501724805,"mc":[{"id":"1.230180134","rc":[{"atb":[[1.69,18.4]],"id":41401491}],"con":true,"img":false}]}
{"op":"mcm","clk":"11541062616","pt":1719501725018,"mc":[{"id":"1.230180134","rc":[{"atb":[[2.16,10.94]],"id":52032624}],"con":true,"img":false}]}
{"op":"mcm","clk":"11541066074","pt":1719501767337,"mc":[{"id":"1.230180134","rc":[{"atb":[[1.68,0]],"id":41401491},{"atb":[[2.14,0]],"id":52032624},{"atb":[[2.14,0]],"id":4065261},{"atb":[[2.14,0]],"id":65040144}],"con":true,"img":false}]}
{"op":"mcm","clk":"11541066449","pt":1719501772081,"mc":[{"id":"1.230180134","rc":[{"atb":[[2.18,10.04]],"id":4065261}],"con":true,"img":false}]}
{"op":"mcm","clk":"11541066456","pt":1719501772181,"mc":[{"id":"1.230180134","rc":[{"atb":[[2.18,10.04]],"id":65040144}],"con":true,"img":false}]}
{"op":"mcm","clk":"11541066472","pt":1719501772388,"mc":[{"id":"1.230180134","rc":[{"atb":[[2.18,10.04]],"id":52032624}],"con":true,"img":false}]}
{"op":"mcm","clk":"11541066486","pt":1719501772542,"mc":[{"id":"1.230180134","rc":[{"atb":[[1.7,16.94]],"id":41401491}],"con":true,"img":false}]}
{"op":"mcm","clk":"11541070310","pt":1719501818611,"mc":[{"id":"1.230180134","rc":[{"atb":[[1.69,0]],"id":41401491},{"atb":[[2.16,0]],"id":52032624},{"atb":[[2.16,0]],"id":4065261},{"atb":[[2.16,0]],"id":65040144}],"con":true,"img":false}]}
{"op":"mcm","clk":"11541071191","pt":1719501829338,"mc":[{"id":"1.230180134","rc":[{"atb":[[2.2,10.58]],"id":4065261}],"con":true,"img":false}]}
{"op":"mcm","clk":"11541071201","pt":1719501829548,"mc":[{"id":"1.230180134","rc":[{"atb":[[2.2,10.58]],"id":65040144}],"con":true,"img":false}]}
{"op":"mcm","clk":"11541071210","pt":1719501829647,"mc":[{"id":"1.230180134","rc":[{"atb":[[1.71,17.89]],"id":41401491}],"con":true,"img":false}]}
{"op":"mcm","clk":"11541071238","pt":1719501829956,"mc":[{"id":"1.230180134","rc":[{"atb":[[2.2,10.58]],"id":52032624}],"con":true,"img":false}]}
{"op":"mcm","clk":"11541072256","pt":1719501841964,"mc":[{"id":"1.230180134","rc":[{"atb":[[1.7,0]],"id":41401491},{"atb":[[2.18,0]],"id":52032624},{"atb":[[2.18,0]],"id":4065261},{"atb":[[2.18,0]],"id":65040144}],"con":true,"img":false}]}
{"op":"mcm","clk":"11541073967","pt":1719501862092,"mc":[{"id":"1.230180134","rc":[{"atb":[[2.22,9.72]],"id":4065261}],"con":true,"img":false}]}
{"op":"mcm","clk":"11541073977","pt":1719501862205,"mc":[{"id":"1.230180134","rc":[{"atb":[[1.72,16.46]],"id":41401491}],"con":true,"img":false}]}
{"op":"mcm","clk":"11541073986","pt":1719501862264,"mc":[{"id":"1.230180134","rc":[{"atb":[[2.22,9.72]],"id":52032624}],"con":true,"img":false}]}
{"op":"mcm","clk":"11541074007","pt":1719501862462,"mc":[{"id":"1.230180134","rc":[{"atb":[[2.22,9.72]],"id":65040144}],"con":true,"img":false}]}
{"op":"mcm","clk":"11541078821","pt":1719501919227,"mc":[{"id":"1.230180134","rc":[{"atb":[[1.71,0]],"id":41401491},{"atb":[[2.2,0]],"id":52032624},{"atb":[[2.2,0]],"id":4065261},{"atb":[[2.2,0]],"id":65040144}],"con":true,"img":false}]}
{"op":"mcm","clk":"11541079536","pt":1719501927143,"mc":[{"id":"1.230180134","rc":[{"atb":[[2.24,10.24]],"id":4065261}],"con":true,"img":false}]}
{"op":"mcm","clk":"11541079545","pt":1719501927244,"mc":[{"id":"1.230180134","rc":[{"atb":[[2.24,10.24]],"id":65040144}],"con":true,"img":false}]}
{"op":"mcm","clk":"11541079557","pt":1719501927450,"mc":[{"id":"1.230180134","rc":[{"atb":[[2.24,10.24]],"id":52032624}],"con":true,"img":false}]}
{"op":"mcm","clk":"11541079584","pt":1719501927758,"mc":[{"id":"1.230180134","rc":[{"atb":[[1.73,17.4]],"id":41401491}],"con":true,"img":false}]}
{"op":"mcm","clk":"11541083173","pt":1719501965784,"mc":[{"id":"1.230180134","rc":[{"atb":[[1.72,0]],"id":41401491},{"atb":[[2.22,0]],"id":52032624},{"atb":[[2.22,0]],"id":4065261},{"atb":[[2.22,0]],"id":65040144}],"con":true,"img":false}]}
{"op":"mcm","clk":"11541083582","pt":1719501970292,"mc":[{"id":"1.230180134","rc":[{"atb":[[2.26,9.4]],"id":4065261}],"con":true,"img":false}]}
{"op":"mcm","clk":"11541083596","pt":1719501970394,"mc":[{"id":"1.230180134","rc":[{"atb":[[1.74,16.02]],"id":41401491}],"con":true,"img":false}]}
{"op":"mcm","clk":"11541083607","pt":1719501970493,"mc":[{"id":"1.230180134","rc":[{"atb":[[2.26,9.4]],"id":65040144}],"con":true,"img":false}]}
{"op":"mcm","clk":"11541083628","pt":1719501970708,"mc":[{"id":"1.230180134","rc":[{"atb":[[2.26,11.4]],"id":52032624}],"con":true,"img":false}]}
{"op":"mcm","clk":"11541087102","pt":1719502015238,"mc":[{"id":"1.230180134","rc":[{"atb":[[1.73,0]],"id":41401491},{"atb":[[2.24,0]],"id":52032624},{"atb":[[2.24,0]],"id":4065261},{"atb":[[2.24,0]],"id":65040144}],"con":true,"img":false}]}
{"op":"mcm","clk":"11541087708","pt":1719502023865,"mc":[{"id":"1.230180134","rc":[{"atb":[[2.28,9.92]],"id":4065261}],"con":true,"img":false}]}
{"op":"mcm","clk":"11541087718","pt":1719502024070,"mc":[{"id":"1.230180134","rc":[{"atb":[[1.75,16.93]],"id":41401491}],"con":true,"img":false}]}
{"op":"mcm","clk":"11541087725","pt":1719502024172,"mc":[{"id":"1.230180134","rc":[{"atb":[[2.28,9.92]],"id":65040144}],"con":true,"img":false}]}
{"op":"mcm","clk":"11541087736","pt":1719502024382,"mc":[{"id":"1.230180134","rc":[{"atb":[[2.28,9.92]],"id":52032624}],"con":true,"img":false}]}
{"op":"mcm","clk":"11541090084","pt":1719502055829,"mc":[{"id":"1.230180134","rc":[{"atb":[[1.74,0]],"id":41401491},{"atb":[[2.26,2]],"id":52032624},{"atb":[[2.26,0]],"id":4065261},{"atb":[[2.26,0]],"id":65040144}],"con":true,"img":false}]}
{"op":"mcm","clk":"11541090417","pt":1719502060129,"mc":[{"id":"1.230180134","rc":[{"atb":[[2.3,9.12]],"id":4065261}],"con":true,"img":false}]}
{"op":"mcm","clk":"11541090426","pt":1719502060227,"mc":[{"id":"1.230180134","rc":[{"atb":[[1.68,17.44]],"id":41401491}],"con":true,"img":false}]}
{"op":"mcm","clk":"11541090435","pt":1719502060331,"mc":[{"id":"1.230180134","rc":[{"atb":[[2.3,9.12]],"id":65040144}],"con":true,"img":false}]}
{"op":"mcm","clk":"11541090457","pt":1719502060542,"mc":[{"id":"1.230180134","rc":[{"atb":[[2.3,9.12]],"id":52032624}],"con":true,"img":false}]}
{"op":"mcm","clk":"11541094467","pt":1719502115201,"mc":[{"id":"1.230180134","rc":[{"atb":[[1.75,0]],"id":41401491},{"atb":[[2.28,0]],"id":52032624},{"atb":[[2.28,0]],"id":4065261},{"atb":[[2.28,0]],"id":65040144}],"con":true,"img":false}]}
{"op":"mcm","clk":"11541094924","pt":1719502123093,"mc":[{"id":"1.230180134","rc":[{"atb":[[2.32,9.61]],"id":4065261}],"con":true,"img":false}]}
{"op":"mcm","clk":"11541094932","pt":1719502123197,"mc":[{"id":"1.230180134","rc":[{"atb":[[2.32,9.61]],"id":65040144}],"con":true,"img":false}]}
{"op":"mcm","clk":"11541094942","pt":1719502123406,"mc":[{"id":"1.230180134","rc":[{"atb":[[1.69,18.4]],"id":41401491}],"con":true,"img":false}]}
{"op":"mcm","clk":"11541094970","pt":1719502123711,"mc":[{"id":"1.230180134","rc":[{"atb":[[2.32,9.61]],"id":52032624}],"con":true,"img":false}]}
{"op":"mcm","clk":"11541097866","pt":1719502164389,"mc":[{"id":"1.230180134","rc":[{"atb":[[1.68,0]],"id":41401491},{"atb":[[2.3,0]],"id":52032624},{"atb":[[2.3,0]],"id":4065261},{"atb":[[2.3,0]],"id":65040144}],"con":true,"img":false}]}
{"op":"mcm","clk":"11541098155","pt":1719502168578,"mc":[{"id":"1.230180134","rc":[{"atb":[[2.34,8.84]],"id":4065261}],"con":true,"img":false}]}
{"op":"mcm","clk":"11541098163","pt":1719502168681,"mc":[{"id":"1.230180134","rc":[{"atb":[[2.34,8.84]],"id":65040144}],"con":true,"img":false}]}
{"op":"mcm","clk":"11541098172","pt":1719502168789,"mc":[{"id":"1.230180134","rc":[{"atb":[[2.34,8.84]],"id":52032624}],"con":true,"img":false}]}
{"op":"mcm","clk":"11541098185","pt":1719502168944,"mc":[{"id":"1.230180134","rc":[{"atb":[[1.7,16.94]],"id":41401491}],"con":true,"img":false}]}
{"op":"mcm","clk":"11541102075","pt":1719502218726,"mc":[{"id":"1.230180134","rc":[{"atb":[[1.69,0]],"id":41401491},{"atb":[[2.32,0]],"id":52032624},{"atb":[[2.32,0]],"id":4065261},{"atb":[[2.32,0]],"id":65040144}],"con":true,"img":false}]}
{"op":"mcm","clk":"11541102787","pt":1719502226819,"mc":[{"id":"1.230180134","rc":[{"atb":[[2.36,9.33]],"id":4065261}],"con":true,"img":false}]}
{"op":"mcm","clk":"11541102801","pt":1719502226925,"mc":[{"id":"1.230180134","rc":[{"atb":[[2.36,9.33]],"id":52032624}],"con":true,"img":false}]}
{"op":"mcm","clk":"11541102823","pt":1719502227134,"mc":[{"id":"1.230180134","rc":[{"atb":[[2.36,9.33]],"id":65040144}],"con":true,"img":false}]}
{"op":"mcm","clk":"11541102855","pt":1719502227432,"mc":[{"id":"1.230180134","rc":[{"atb":[[1.71,17.89]],"id":41401491}],"con":true,"img":false}]}
{"op":"mcm","clk":"11541105517","pt":1719502260076,"mc":[{"id":"1.230180134","rc":[{"atb":[[1.7,0]],"id":41401491},{"atb":[[2.34,0]],"id":52032624},{"atb":[[2.34,0]],"id":4065261},{"atb":[[2.34,0]],"id":65040144}],"con":true,"img":false}]}
{"op":"mcm","clk":"11541105922","pt":1719502264756,"mc":[{"id":"1.230180134","rc":[{"atb":[[2.38,8.59]],"id":4065261}],"con":true,"img":false}]}
{"op":"mcm","clk":"11541105931","pt":1719502264862,"mc":[{"id":"1.230180134","rc":[{"atb":[[1.72,16.46]],"id":41401491}],"con":true,"img":false}]}
{"op":"mcm","clk":"11541105941","pt":1719502264965,"mc":[{"id":"1.230180134","rc":[{"atb":[[2.38,8.59]],"id":65040144}],"con":true,"img":false}]}
{"op":"mcm","clk":"11541105955","pt":1719502265175,"mc":[{"id":"1.230180134","rc":[{"atb":[[2.38,8.59]],"id":52032624}],"con":true,"img":false}]}
{"op":"mcm","clk":"11541109988","pt":1719502317206,"mc":[{"id":"1.230180134","rc":[{"atb":[[1.71,0]],"id":41401491},{"atb":[[2.36,0]],"id":52032624},{"atb":[[2.36,0]],"id":4065261},{"atb":[[2.36,0]],"id":65040144}],"con":true,"img":false}]}
{"op":"mcm","clk":"11541110612","pt":1719502324518,"mc":[{"id":"1.230180134","rc":[{"atb":[[2.4,9.06]],"id":4065261},{"atb":[[2.4,9.06]],"id":65040144}],"con":true,"img":false}]}
{"op":"mcm","clk":"11541110631","pt":1719502324829,"mc":[{"id":"1.230180134","rc":[{"atb":[[1.73,17.4]],"id":41401491}],"con":true,"img":false}]}
{"op":"mcm","clk":"11541110651","pt":1719502325042,"mc":[{"id":"1.230180134","rc":[{"atb":[[2.4,9.06]],"id":52032624}],"con":true,"img":false}]}
{"op":"mcm","clk":"11541112689","pt":1719502351169,"mc":[{"id":"1.230180134","rc":[{"atb":[[1.72,0]],"id":41401491},{"atb":[[2.38,0]],"id":52032624},{"atb":[[2.38,0]],"id":4065261},{"atb":[[2.38,0]],"id":65040144}],"con":true,"img":false}]}
{"op":"mcm","clk":"11541112957","pt":1719502354953,"mc":[{"id":"1.230180134","rc":[{"atb":[[2.42,8.34]],"id":4065261}],"con":true,"img":false}]}
{"op":"mcm","clk":"11541112964","pt":1719502355054,"mc":[{"id":"1.230180134","rc":[{"atb":[[1.74,16.02]],"id":41401491}],"con":true,"img":false}]}
{"op":"mcm","clk":"11541112973","pt":1719502355158,"mc":[{"id":"1.230180134","rc":[{"atb":[[2.42,8.34]],"id":65040144}],"con":true,"img":false}]}
{"op":"mcm","clk":"11541112991","pt":1719502355374,"mc":[{"id":"1.230180134","rc":[{"atb":[[2.42,8.34]],"id":52032624}],"con":true,"img":false}]}
{"op":"mcm","clk":"11541115541","pt":1719502387623,"mc":[{"id":"1.230180134","rc":[{"atb":[[1.73,0]],"id":41401491},{"atb":[[2.4,0]],"id":52032624},{"atb":[[2.4,0]],"id":4065261},{"atb":[[2.4,0]],"id":65040144}],"con":true,"img":false}]}
{"op":"mcm","clk":"11541115708","pt":1719502389796,"mc":[{"id":"1.230180134","rc":[{"atb":[[2.44,8.82]],"id":4065261}],"con":true,"img":false}]}
{"op":"mcm","clk":"11541115716","pt":1719502389897,"mc":[{"id":"1.230180134","rc":[{"atb":[[2.44,8.82]],"id":65040144}],"con":true,"img":false}]}
{"op":"mcm","clk":"11541115726","pt":1719502390104,"mc":[{"id":"1.230180134","rc":[{"atb":[[1.75,16.93]],"id":41401491}],"con":true,"img":false}]}
{"op":"mcm","clk":"11541115752","pt":1719502390411,"mc":[{"id":"1.230180134","rc":[{"atb":[[2.44,8.82]],"id":52032624}],"con":true,"img":false}]}
{"op":"mcm","clk":"11541117819","pt":1719502419753,"mc":[{"id":"1.230180134","rc":[{"atb":[[1.74,0]],"id":41401491},{"atb":[[2.42,0]],"id":52032624},{"atb":[[2.42,0]],"id":4065261},{"atb":[[2.42,0]],"id":65040144}],"con":true,"img":false}]}
{"op":"mcm","clk":"11541118116","pt":1719502424039,"mc":[{"id":"1.230180134","rc":[{"atb":[[2.46,8.11]],"id":4065261},{"atb":[[2.46,8.11]],"id":65040144}],"con":true,"img":false}]}
{"op":"mcm","clk":"11541118130","pt":1719502424240,"mc":[{"id":"1.230180134","rc":[{"atb":[[1.68,17.44]],"id":41401491}],"con":true,"img":false}]}
{"op":"mcm","clk":"11541118138","pt":1719502424347,"mc":[{"id":"1.230180134","rc":[{"atb":[[2.46,8.11]],"id":52032624}],"con":true,"img":false}]}
{"op":"mcm","clk":"11541120819","pt":1719502457599,"mc":[{"id":"1.230180134","rc":[{"atb":[[1.75,0]],"id":41401491},{"atb":[[2.44,0]],"id":52032624},{"atb":[[2.44,0]],"id":4065261},{"atb":[[2.44,0]],"id":65040144}],"con":true,"img":false}]}
{"op":"mcm","clk":"11541121456","pt":1719502466609,"mc":[{"id":"1.230180134","rc":[{"atb":[[2.48,8.58]],"id":4065261}],"con":true,"img":false}]}
{"op":"mcm","clk":"11541121469","pt":1719502466707,"mc":[{"id":"1.230180134","rc":[{"atb":[[2.48,8.58]],"id":65040144}],"con":true,"img":false}]}
{"op":"mcm","clk":"11541121490","pt":1719502466859,"mc":[{"id":"1.230180134","rc":[{"atb":[[2.48,8.58]],"id":52032624}],"con":true,"img":false}]}
{"op":"mcm","clk":"11541121505","pt":1719502467170,"mc":[{"id":"1.230180134","rc":[{"atb":[[1.69,18.4]],"id":41401491}],"con":true,"img":false}]}
{"op":"mcm","clk":"11541123351","pt":1719502492210,"mc":[{"id":"1.230180134","rc":[{"atb":[[2.46,0]],"id":52032624},{"atb":[[2.46,0]],"id":4065261},{"atb":[[2.46,0]],"id":65040144}],"con":true,"img":false}]}
{"op":"mcm","clk":"11541123676","pt":1719502496134,"mc":[{"id":"1.230180134","rc":[{"atb":[[2.5,7.9]],"id":4065261}],"con":true,"img":false}]}
{"op":"mcm","clk":"11541123692","pt":1719502496340,"mc":[{"id":"1.230180134","rc":[{"atb":[[2.5,7.9]],"id":65040144}],"con":true,"img":false}]}
{"op":"mcm","clk":"11541123714","pt":1719502496505,"mc":[{"id":"1.230180134","rc":[{"atb":[[2.5,7.9]],"id":52032624}],"con":true,"img":false}]}
{"op":"mcm","clk":"11541124903","pt":1719502511517,"mc":[{"id":"1.230180134","rc":[{"atb":[[1.68,0]],"id":41401491}],"con":true,"img":false}]}
{"op":"mcm","clk":"11541125171","pt":1719502515433,"mc":[{"id":"1.230180134","rc":[{"atb":[[1.7,16.94]],"id":41401491}],"con":true,"img":false}]}
{"op":"mcm","clk":"11541125680","pt":1719502522334,"mc":[{"id":"1.230180134","rc":[{"atb":[[2.48,0]],"id":52032624},{"atb":[[2.48,0]],"id":4065261},{"atb":[[2.48,0]],"id":65040144}],"con":true,"img":false}]}
{"op":"mcm","clk":"11541126244","pt":1719502530468,"mc":[{"id":"1.230180134","rc":[{"atb":[[2.52,8.35]],"id":4065261}],"con":true,"img":false}]}
{"op":"mcm","clk":"11541126250","pt":1719502530575,"mc":[{"id":"1.230180134","rc":[{"atb":[[2.52,8.35]],"id":65040144}],"con":true,"img":false}]}
{"op":"mcm","clk":"11541126270","pt":1719502530783,"mc":[{"id":"1.230180134","rc":[{"atb":[[2.52,8.35]],"id":52032624}],"con":true,"img":false}]}
{"op":"mcm","clk":"11541127944","pt":1719502555165,"mc":[{"id":"1.230180134","rc":[{"atb":[[1.69,0]],"id":41401491}],"con":true,"img":false}]}
{"op":"mcm","clk":"11541128720","pt":1719502565489,"mc":[{"id":"1.230180134","rc":[{"atb":[[2.5,0]],"id":52032624},{"atb":[[2.5,0]],"id":4065261},{"atb":[[2.5,0]],"id":65040144}],"con":true,"img":false}]}
{"op":"mcm","clk":"11541129137","pt":1719502569696,"mc":[{"id":"1.230180134","rc":[{"atb":[[2.54,7.7]],"id":65040144}],"con":true,"img":false}]}
{"op":"mcm","clk":"11541129146","pt":1719502569786,"mc":[{"id":"1.230180134","rc":[{"atb":[[2.54,7.7]],"id":4065261}],"con":true,"img":false}]}
{"op":"mcm","clk":"11541129153","pt":1719502569895,"mc":[{"id":"1.230180134","rc":[{"atb":[[2.54,7.7]],"id":52032624}],"con":true,"img":false}]}
{"op":"mcm","clk":"11541129951","pt":1719502579592,"mc":[{"id":"1.230180134","rc":[{"atb":[[1.71,17.89]],"id":41401491}],"con":true,"img":false}]}
{"op":"mcm","clk":"11541131331","pt":1719502597320,"mc":[{"id":"1.230180134","rc":[{"atb":[[1.7,0]],"id":41401491}],"con":true,"img":false}]}
{"op":"mcm","clk":"11541131611","pt":1719502600824,"mc":[{"id":"1.230180134","rc":[{"atb":[[2.52,0]],"id":52032624},{"atb":[[2.52,0]],"id":4065261},{"atb":[[2.52,0]],"id":65040144}],"con":true,"img":false}]}
{"op":"mcm","clk":"11541131636","pt":1719502601131,"mc":[{"id":"1.230180134","rc":[{"atb":[[1.72,16.46]],"id":41401491}],"con":true,"img":false}]}
{"op":"mcm","clk":"11541132993","pt":1719502619820,"mc":[{"id":"1.230180134","rc":[{"atb":[[1.71,0]],"id":41401491}],"con":true,"img":false}]}
{"op":"mcm","clk":"11541133502","pt":1719502626830,"mc":[{"id":"1.230180134","rc":[{"atb":[[2.56,8.14]],"id":4065261}],"con":true,"img":false}]}
{"op":"mcm","clk":"11541133517","pt":1719502626929,"mc":[{"id":"1.230180134","rc":[{"atb":[[2.56,8.14]],"id":52032624}],"con":true,"img":false}]}
{"op":"mcm","clk":"11541133536","pt":1719502627137,"mc":[{"id":"1.230180134","rc":[{"atb":[[2.56,8.14]],"id":65040144}],"con":true,"img":false}]}
{"op":"mcm","clk":"11541135609","pt":1719502655387,"mc":[{"id":"1.230180134","rc":[{"atb":[[1.72,0]],"id":41401491},{"atb":[[2.54,0]],"id":52032624},{"atb":[[2.54,0]],"id":4065261},{"atb":[[2.54,0]],"id":65040144}],"con":true,"img":false}]}
{"op":"mcm","clk":"11541135858","pt":1719502659154,"mc":[{"id":"1.230180134","rc":[{"atb":[[2.58,7.5]],"id":4065261}],"con":true,"img":false}]}
{"op":"mcm","clk":"11541135874","pt":1719502659361,"mc":[{"id":"1.230180134","rc":[{"atb":[[1.68,17.44]],"id":41401491},{"atb":[[2.58,7.5]],"id":65040144}],"con":true,"img":false}]}
{"op":"mcm","clk":"11541135894","pt":1719502659577,"mc":[{"id":"1.230180134","rc":[{"atb":[[2.58,7.5]],"id":52032624}],"con":true,"img":false}]}
{"op":"mcm","clk":"11541145046","pt":1719502704821,"mc":[{"id":"1.230180134","rc":[{"atb":[[2.56,0]],"id":52032624},{"atb":[[2.56,0]],"id":4065261},{"atb":[[2.56,0]],"id":65040144}],"con":true,"img":false}]}
{"op":"mcm","clk":"11541145591","pt":1719502711603,"mc":[{"id":"1.230180134","rc":[{"atb":[[2.6,7.94]],"id":4065261}],"con":true,"img":false}]}
{"op":"mcm","clk":"11541145597","pt":1719502711710,"mc":[{"id":"1.230180134","rc":[{"atb":[[2.6,7.94]],"id":65040144}],"con":true,"img":false}]}
{"op":"mcm","clk":"11541145612","pt":1719502711922,"mc":[{"id":"1.230180134","rc":[{"atb":[[1.69,18.4]],"id":41401491}],"con":true,"img":false}]}
{"op":"mcm","clk":"11541145641","pt":1719502712229,"mc":[{"id":"1.230180134","rc":[{"atb":[[2.6,7.94]],"id":52032624}],"con":true,"img":false}]}
{"op":"mcm","clk":"11541148625","pt":1719502746949,"mc":[{"id":"1.230180134","rc":[{"atb":[[1.68,0]],"id":41401491},{"atb":[[2.58,0]],"id":52032624},{"atb":[[2.58,0]],"id":4065261},{"atb":[[2.58,0]],"id":65040144}],"con":true,"img":false}]}
{"op":"mcm","clk":"11541149054","pt":1719502751066,"mc":[{"id":"1.230180134","rc":[{"atb":[[2.62,7.32]],"id":4065261}],"con":true,"img":false}]}
{"op":"mcm","clk":"11541149068","pt":1719502751168,"mc":[{"id":"1.230180134","rc":[{"atb":[[2.62,7.32]],"id":65040144}],"con":true,"img":false}]}
{"op":"mcm","clk":"11541149076","pt":1719502751278,"mc":[{"id":"1.230180134","rc":[{"atb":[[2.62,7.32]],"id":52032624}],"con":true,"img":false}]}
{"op":"mcm","clk":"11541149101","pt":1719502751478,"mc":[{"id":"1.230180134","rc":[{"atb":[[1.7,16.94]],"id":41401491}],"con":true,"img":false}]}
{"op":"mcm","clk":"11541154967","pt":1719502812036,"mc":[{"id":"1.230180134","rc":[{"atb":[[1.69,0]],"id":41401491},{"atb":[[2.6,0]],"id":52032624},{"atb":[[2.6,0]],"id":4065261},{"atb":[[2.6,0]],"id":65040144}],"con":true,"img":false}]}
{"op":"mcm","clk":"11541155305","pt":1719502815610,"mc":[{"id":"1.230180134","rc":[{"atb":[[2.64,7.74]],"id":4065261}],"con":true,"img":false}]}
{"op":"mcm","clk":"11541155317","pt":1719502815813,"mc":[{"id":"1.230180134","rc":[{"atb":[[1.71,17.89]],"id":41401491}],"con":true,"img":false}]}
{"op":"mcm","clk":"11541155323","pt":1719502815917,"mc":[{"id":"1.230180134","rc":[{"atb":[[2.64,7.74]],"id":65040144}],"con":true,"img":false}]}
{"op":"mcm","clk":"11541155367","pt":1719502816331,"mc":[{"id":"1.230180134","rc":[{"atb":[[2.64,7.74]],"id":52032624}],"con":true,"img":false}]}
{"op":"mcm","clk":"11541159080","pt":1719502858073,"mc":[{"id":"1.230180134","rc":[{"atb":[[1.7,0]],"id":41401491},{"atb":[[2.62,0]],"id":52032624},{"atb":[[2.62,0]],"id":4065261},{"atb":[[2.62,0]],"id":65040144}],"con":true,"img":false}]}
{"op":"mcm","clk":"11541159511","pt":1719502862152,"mc":[{"id":"1.230180134","rc":[{"atb":[[2.66,7.14]],"id":4065261}],"con":true,"img":false}]}
{"op":"mcm","clk":"11541159525","pt":1719502862259,"mc":[{"id":"1.230180134","rc":[{"atb":[[2.66,7.14]],"id":65040144}],"con":true,"img":false}]}
{"op":"mcm","clk":"11541159536","pt":1719502862364,"mc":[{"id":"1.230180134","rc":[{"atb":[[2.66,7.14]],"id":52032624}],"con":true,"img":false}]}
{"op":"mcm","clk":"11541159559","pt":1719502862590,"mc":[{"id":"1.230180134","rc":[{"atb":[[1.72,16.46]],"id":41401491}],"con":true,"img":false}]}
{"op":"mcm","clk":"11541163212","pt":1719502906201,"mc":[{"id":"1.230180134","rc":[{"atb":[[1.71,0]],"id":41401491},{"atb":[[2.64,0]],"id":52032624},{"atb":[[2.64,0]],"id":4065261},{"atb":[[2.64,0]],"id":65040144}],"con":true,"img":false}]}
{"op":"mcm","clk":"11541166628","pt":1719502948042,"mc":[{"id":"1.230180134","rc":[{"atb":[[1.72,0]],"id":41401491},{"atb":[[2.66,0]],"id":52032624},{"atb":[[2.66,0]],"id":4065261},{"atb":[[2.66,0]],"id":65040144}],"con":true,"img":false}]}
{"op":"mcm","clk":"11541167102","pt":1719502952851,"mc":[{"id":"1.230180134","rc":[{"atb":[[2.14,10.4]],"id":65040144}],"con":true,"img":false}]}
{"op":"mcm","clk":"11541167115","pt":1719502952904,"mc":[{"id":"1.230180134","rc":[{"atb":[[2.14,10.4]],"id":4065261}],"con":true,"img":false}]}
{"op":"mcm","clk":"11541167125","pt":1719502953112,"mc":[{"id":"1.230180134","rc":[{"atb":[[2.14,10.4]],"id":52032624}],"con":true,"img":false}]}
{"op":"mcm","clk":"11541167140","pt":1719502953317,"mc":[{"id":"1.230180134","rc":[{"atb":[[1.68,17.44]],"id":41401491}],"con":true,"img":false}]}
{"op":"mcm","clk":"11541173557","pt":1719503022056,"mc":[{"id":"1.230180134","rc":[{"atb":[[2.16,10.94]],"id":65040144}],"con":true,"img":false}]}
{"op":"mcm","clk":"11541173574","pt":1719503022251,"mc":[{"id":"1.230180134","rc":[{"atb":[[1.69,18.4]],"id":41401491}],"con":true,"img":false}]}
{"op":"mcm","clk":"11541173581","pt":1719503022304,"mc":[{"id":"1.230180134","rc":[{"atb":[[2.16,10.94]],"id":4065261}],"con":true,"img":false}]}
{"op":"mcm","clk":"11541173603","pt":1719503022624,"mc":[{"id":"1.230180134","rc":[{"atb":[[2.16,10.94]],"id":52032624}],"con":true,"img":false}]}
{"op":"mcm","clk":"11541177502","pt":1719503062506,"mc":[{"id":"1.230180134","rc":[{"atb":[[1.68,0]],"id":41401491},{"atb":[[2.14,0]],"id":52032624},{"atb":[[2.14,0]],"id":4065261},{"atb":[[2.14,0]],"id":65040144}],"con":true,"img":false}]}
{"op":"mcm","clk":"11541177948","pt":1719503067205,"mc":[{"id":"1.230180134","rc":[{"atb":[[2.18,10.04]],"id":4065261},{"atb":[[2.18,10.04]],"id":65040144}],"con":true,"img":false}]}
{"op":"mcm","clk":"11541177967","pt":1719503067367,"mc":[{"id":"1.230180134","rc":[{"atb":[[2.18,10.04]],"id":52032624}],"con":true,"img":false}]}
{"op":"mcm","clk":"11541177975","pt":1719503067467,"mc":[{"id":"1.230180134","rc":[{"atb":[[1.7,16.94]],"id":41401491}],"con":true,"img":false}]}
{"op":"mcm","clk":"11541181512","pt":1719503103746,"mc":[{"id":"1.230180134","rc":[{"atb":[[1.69,0]],"id":41401491},{"atb":[[2.16,0]],"id":52032624},{"atb":[[2.16,0]],"id":4065261},{"atb":[[2.16,0]],"id":65040144}],"con":true,"img":false}]}
{"op":"mcm","clk":"11541183737","pt":1719503126753,"mc":[{"id":"1.230180134","rc":[{"atb":[[1.71,17.89]],"id":41401491}],"con":true,"img":false}]}
{"op":"mcm","clk":"11541183762","pt":1719503127060,"mc":[{"id":"1.230180134","rc":[{"atb":[[2.2,10.58]],"id":52032624},{"atb":[[2.2,10.58]],"id":4065261}],"con":true,"img":false}]}
{"op":"mcm","clk":"11541183788","pt":1719503127397,"mc":[{"id":"1.230180134","rc":[{"atb":[[2.2,10.58]],"id":65040144}],"con":true,"img":false}]}
{"op":"mcm","clk":"11541185835","pt":1719503147897,"mc":[{"id":"1.230180134","rc":[{"atb":[[1.7,0]],"id":41401491},{"atb":[[2.18,0]],"id":52032624},{"atb":[[2.18,0]],"id":4065261},{"atb":[[2.18,0]],"id":65040144}],"con":true,"img":false}]}
{"op":"mcm","clk":"11541186253","pt":1719503152095,"mc":[{"id":"1.230180134","rc":[{"atb":[[2.22,9.72]],"id":4065261}],"con":true,"img":false}]}
{"op":"mcm","clk":"11541186275","pt":1719503152295,"mc":[{"id":"1.230180134","rc":[{"atb":[[1.72,16.46]],"id":41401491}],"con":true,"img":false}]}
{"op":"mcm","clk":"11541186289","pt":1719503152452,"mc":[{"id":"1.230180134","rc":[{"atb":[[2.22,9.72]],"id":65040144}],"con":true,"img":false}]}
{"op":"mcm","clk":"11541186307","pt":1719503152672,"mc":[{"id":"1.230180134","rc":[{"atb":[[2.22,9.72]],"id":52032624}],"con":true,"img":false}]}
{"op":"mcm","clk":"11541190849","pt":1719503193826,"mc":[{"id":"1.230180134","rc":[{"atb":[[1.71,0]],"id":41401491},{"atb":[[2.2,0]],"id":52032624},{"atb":[[2.2,0]],"id":4065261},{"atb":[[2.2,0]],"id":65040144}],"con":true,"img":false}]}
{"op":"mcm","clk":"11541191236","pt":1719503197042,"mc":[{"id":"1.230180134","rc":[{"atb":[[1.73,17.4]],"id":41401491}],"con":true,"img":false}]}
{"op":"mcm","clk":"11541191269","pt":1719503197251,"mc":[{"id":"1.230180134","rc":[{"atb":[[2.24,10.24]],"id":4065261}],"con":true,"img":false}]}
{"op":"mcm","clk":"11541191285","pt":1719503197358,"mc":[{"id":"1.230180134","rc":[{"atb":[[2.24,10.24]],"id":52032624}],"con":true,"img":false}]}
{"op":"mcm","clk":"11541191315","pt":1719503197551,"mc":[{"id":"1.230180134","rc":[{"atb":[[2.24,10.24]],"id":65040144}],"con":true,"img":false}]}
{"op":"mcm","clk":"11541195884","pt":1719503240423,"mc":[{"id":"1.230180134","rc":[{"atb":[[1.72,0]],"id":41401491},{"atb":[[2.22,0]],"id":52032624},{"atb":[[2.22,0]],"id":4065261},{"atb":[[2.22,0]],"id":65040144}],"con":true,"img":false}]}
{"op":"mcm","clk":"11541196584","pt":1719503248130,"mc":[{"id":"1.230180134","rc":[{"atb":[[1.74,16.02]],"id":41401491},{"atb":[[2.26,9.4]],"id":65040144}],"con":true,"img":false}]}
{"op":"mcm","clk":"11541196607","pt":1719503248343,"mc":[{"id":"1.230180134","rc":[{"atb":[[2.26,9.4]],"id":4065261}],"con":true,"img":false}]}
{"op":"mcm","clk":"11541196623","pt":1719503248498,"mc":[{"id":"1.230180134","rc":[{"atb":[[2.26,11.4]],"id":52032624}],"con":true,"img":false}]}
{"op":"mcm","clk":"11541201382","pt":1719503297297,"mc":[{"id":"1.230180134","rc":[{"atb":[[1.73,0]],"id":41401491},{"atb":[[2.24,0]],"id":52032624},{"atb":[[2.24,0]],"id":4065261},{"atb":[[2.24,0]],"id":65040144}],"con":true,"img":false}]}
{"op":"mcm","clk":"11541201753","pt":1719503301761,"mc":[{"id":"1.230180134","rc":[{"atb":[[2.28,9.92]],"id":65040144}],"con":true,"img":false}]}
{"op":"mcm","clk":"11541201770","pt":1719503301973,"mc":[{"id":"1.230180134","rc":[{"atb":[[1.75,16.93]],"id":41401491}],"con":true,"img":false}]}
{"op":"mcm","clk":"11541201781","pt":1719503302072,"mc":[{"id":"1.230180134","rc":[{"atb":[[2.28,9.92]],"id":4065261}],"con":true,"img":false}]}
{"op":"mcm","clk":"11541201803","pt":1719503302284,"mc":[{"id":"1.230180134","rc":[{"atb":[[2.28,9.92]],"id":52032624}],"con":true,"img":false}]}
{"op":"mcm","clk":"11541204397","pt":1719503330605,"mc":[{"id":"1.230180134","rc":[{"atb":[[1.74,0]],"id":41401491},{"atb":[[2.26,2]],"id":52032624},{"atb":[[2.26,0]],"id":4065261},{"atb":[[2.26,0]],"id":65040144}],"con":true,"img":false}]}
{"op":"mcm","clk":"11541205201","pt":1719503339164,"mc":[{"id":"1.230180134","rc":[{"atb":[[2.3,9.12]],"id":4065261}],"con":true,"img":false}]}
{"op":"mcm","clk":"11541205210","pt":1719503339218,"mc":[{"id":"1.230180134","rc":[{"atb":[[2.3,9.12]],"id":65040144}],"con":true,"img":false}]}
{"op":"mcm","clk":"11541205218","pt":1719503339322,"mc":[{"id":"1.230180134","rc":[{"atb":[[2.3,9.12]],"id":52032624}],"con":true,"img":false}]}
{"op":"mcm","clk":"11541205238","pt":1719503339525,"mc":[{"id":"1.230180134","rc":[{"atb":[[1.68,17.44]],"id":41401491}],"con":true,"img":false}]}
{"op":"mcm","clk":"11541211551","pt":1719503398816,"mc":[{"id":"1.230180134","rc":[{"atb":[[1.75,0]],"id":41401491},{"atb":[[2.28,0]],"id":52032624},{"atb":[[2.28,0]],"id":4065261},{"atb":[[2.28,0]],"id":65040144}],"con":true,"img":false}]}
{"op":"mcm","clk":"11541212580","pt":1719503408510,"mc":[{"id":"1.230180134","rc":[{"atb":[[2.32,9.61]],"id":4065261}],"con":true,"img":false}]}
{"op":"mcm","clk":"11541212590","pt":1719503408613,"mc":[{"id":"1.230180134","rc":[{"atb":[[2.32,9.61]],"id":65040144}],"con":true,"img":false}]}
{"op":"mcm","clk":"11541212610","pt":1719503408819,"mc":[{"id":"1.230180134","rc":[{"atb":[[1.69,18.4]],"id":41401491}],"con":true,"img":false}]}
{"op":"mcm","clk":"11541212649","pt":1719503409184,"mc":[{"id":"1.230180134","rc":[{"atb":[[2.32,9.61]],"id":52032624}],"con":true,"img":false}]}
{"op":"mcm","clk":"11541214512","pt":1719503430268,"mc":[{"id":"1.230180134","rc":[{"atb":[[2.3,0]],"id":52032624},{"atb":[[2.3,0]],"id":4065261},{"atb":[[2.3,0]],"id":65040144}],"con":true,"img":false}]}
{"op":"mcm","clk":"11541214924","pt":1719503434558,"mc":[{"id":"1.230180134","rc":[{"atb":[[2.34,8.84]],"id":4065261}],"con":true,"img":false}]}
{"op":"mcm","clk":"11541214936","pt":1719503434664,"mc":[{"id":"1.230180134","rc":[{"atb":[[2.34,8.84]],"id":52032624}],"con":true,"img":false}]}
{"op":"mcm","clk":"11541214946","pt":1719503434724,"mc":[{"id":"1.230180134","rc":[{"atb":[[2.34,8.84]],"id":65040144}],"con":true,"img":false}]}
{"op":"mcm","clk":"11541215687","pt":1719503443664,"mc":[{"id":"1.230180134","rc":[{"atb":[[1.68,0]],"id":41401491}],"con":true,"img":false}]}
{"op":"mcm","clk":"11541216717","pt":1719503456262,"mc":[{"id":"1.230180134","rc":[{"atb":[[1.7,16.94]],"id":41401491}],"con":true,"img":false}]}
{"op":"mcm","clk":"11541217416","pt":1719503464565,"mc":[{"id":"1.230180134","rc":[{"atb":[[2.32,0]],"id":52032624},{"atb":[[2.32,0]],"id":4065261},{"atb":[[2.32,0]],"id":65040144}],"con":true,"img":false}]}
{"op":"mcm","clk":"11541217575","pt":1719503466493,"mc":[{"id":"1.230180134","rc":[{"atb":[[2.36,9.33]],"id":4065261}],"con":true,"img":false}]}
{"op":"mcm","clk":"11541217593","pt":1719503466703,"mc":[{"id":"1.230180134","rc":[{"atb":[[2.36,9.33]],"id":65040144}],"con":true,"img":false}]}
{"op":"mcm","clk":"11541217605","pt":1719503466804,"mc":[{"id":"1.230180134","rc":[{"atb":[[2.36,9.33]],"id":52032624}],"con":true,"img":false}]}
{"op":"mcm","clk":"11541219537","pt":1719503489015,"mc":[{"id":"1.230180134","rc":[{"atb":[[1.69,0]],"id":41401491}],"con":true,"img":false}]}
{"op":"mcm","clk":"11541220475","pt":1719503499617,"mc":[{"id":"1.230180134","rc":[{"atb":[[2.34,0]],"id":52032624},{"atb":[[2.34,0]],"id":4065261},{"atb":[[2.34,0]],"id":65040144}],"con":true,"img":false}]}
{"op":"mcm","clk":"11541220502","pt":1719503499924,"mc":[{"id":"1.230180134","rc":[{"atb":[[1.71,17.89]],"id":41401491}],"con":true,"img":false}]}
{"op":"mcm","clk":"11541220932","pt":1719503504416,"mc":[{"id":"1.230180134","rc":[{"atb":[[2.38,8.59]],"id":52032624}],"con":true,"img":false}]}
{"op":"mcm","clk":"11541220942","pt":1719503504516,"mc":[{"id":"1.230180134","rc":[{"atb":[[2.38,8.59]],"id":4065261}],"con":true,"img":false}]}
{"op":"mcm","clk":"11541220962","pt":1719503504724,"mc":[{"id":"1.230180134","rc":[{"atb":[[2.38,8.59]],"id":65040144}],"con":true,"img":false}]}
{"op":"mcm","clk":"11541222251","pt":1719503517845,"mc":[{"id":"1.230180134","rc":[{"atb":[[1.7,0]],"id":41401491}],"con":true,"img":false}]}
{"op":"mcm","clk":"11541222839","pt":1719503523751,"mc":[{"id":"1.230180134","rc":[{"atb":[[1.72,16.46]],"id":41401491}],"con":true,"img":false}]}
{"op":"mcm","clk":"11541226002","pt":1719503555105,"mc":[{"id":"1.230180134","rc":[{"atb":[[1.71,0]],"id":41401491},{"atb":[[2.36,0]],"id":52032624},{"atb":[[2.36,0]],"id":4065261},{"atb":[[2.36,0]],"id":65040144}],"con":true,"img":false}]}
{"op":"mcm","clk":"11541228469","pt":1719503579657,"mc":[{"id":"1.230180134","rc":[{"atb":[[2.4,9.06]],"id":65040144}],"con":true,"img":false}]}
{"op":"mcm","clk":"11541228475","pt":1719503579759,"mc":[{"id":"1.230180134","rc":[{"atb":[[1.73,17.4]],"id":41401491}],"con":true,"img":false}]}
{"op":"mcm","clk":"11541228493","pt":1719503579959,"mc":[{"id":"1.230180134","rc":[{"atb":[[2.4,9.06]],"id":4065261}],"con":true,"img":false}]}
{"op":"mcm","clk":"11541228521","pt":1719503580277,"mc":[{"id":"1.230180134","rc":[{"atb":[[2.4,9.06]],"id":52032624}],"con":true,"img":false}]}
{"op":"mcm","clk":"11541229522","pt":1719503589784,"mc":[{"id":"1.230180134","rc":[{"atb":[[1.72,0]],"id":41401491},{"atb":[[2.38,0]],"id":52032624},{"atb":[[2.38,0]],"id":4065261},{"atb":[[2.38,0]],"id":65040144}],"con":true,"img":false}]}
{"op":"mcm","clk":"11541231668","pt":1719503611476,"mc":[{"id":"1.230180134","rc":[{"atb":[[1.74,16.02]],"id":41401491}],"con":true,"img":false}]}
{"op":"mcm","clk":"11541231694","pt":1719503611784,"mc":[{"id":"1.230180134","rc":[{"atb":[[2.42,8.34]],"id":4065261},{"atb":[[2.42,8.34]],"id":65040144}],"con":true,"img":false}]}
{"op":"mcm","clk":"11541231711","pt":1719503611993,"mc":[{"id":"1.230180134","rc":[{"atb":[[2.42,8.34]],"id":52032624}],"con":true,"img":false}]}
{"op":"mcm","clk":"11541233241","pt":1719503629421,"mc":[{"id":"1.230180134","rc":[{"atl":[[2.22,9]],"id":41401491}],"con":true,"img":false}]}
{"op":"mcm","clk":"11541234432","pt":1719503641403,"mc":[{"id":"1.230180134","rc":[{"atb":[[1.73,0]],"id":41401491},{"atb":[[2.4,0]],"id":52032624},{"atb":[[2.4,0]],"id":4065261},{"atb":[[2.4,0]],"id":65040144}],"con":true,"img":false}]}
{"op":"mcm","clk":"11541235325","pt":1719503650413,"mc":[{"id":"1.230180134","rc":[{"atb":[[2.44,8.82]],"id":4065261}],"con":true,"img":false}]}
{"op":"mcm","clk":"11541235334","pt":1719503650515,"mc":[{"id":"1.230180134","rc":[{"atb":[[2.44,8.82]],"id":65040144}],"con":true,"img":false}]}
{"op":"mcm","clk":"11541235357","pt":1719503650722,"mc":[{"id":"1.230180134","rc":[{"atb":[[2.44,8.82]],"id":52032624}],"con":true,"img":false}]}
{"op":"mcm","clk":"11541235391","pt":1719503651036,"mc":[{"id":"1.230180134","rc":[{"atb":[[1.75,16.93]],"id":41401491}],"con":true,"img":false}]}
{"op":"mcm","clk":"11541237800","pt":1719503674873,"mc":[{"id":"1.230180134","rc":[{"atb":[[1.74,0]],"id":41401491},{"atb":[[2.42,0]],"id":52032624},{"atb":[[2.42,0]],"id":4065261},{"atb":[[2.42,0]],"id":65040144}],"con":true,"img":false}]}
{"op":"mcm","clk":"11541237963","pt":1719503676788,"mc":[{"id":"1.230180134","rc":[{"atb":[[1.68,17.44]],"id":41401491}],"con":true,"img":false}]}
{"op":"mcm","clk":"11541239665","pt":1719503694070,"mc":[{"id":"1.230180134","rc":[{"atb":[[2.46,8.11]],"id":4065261}],"con":true,"img":false}]}
{"op":"mcm","clk":"11541239680","pt":1719503694281,"mc":[{"id":"1.230180134","rc":[{"atb":[[2.46,8.11]],"id":65040144}],"con":true,"img":false}]}
{"op":"mcm","clk":"11541239698","pt":1719503694483,"mc":[{"id":"1.230180134","rc":[{"atb":[[2.46,8.11]],"id":52032624}],"con":true,"img":false}]}
{"op":"mcm","clk":"11541241411","pt":1719503712231,"mc":[{"id":"1.230180134","rc":[{"atb":[[1.75,0]],"id":41401491},{"atb":[[2.44,0]],"id":52032624},{"atb":[[2.44,0]],"id":4065261},{"atb":[[2.44,0]],"id":65040144}],"con":true,"img":false}]}
{"op":"mcm","clk":"11541242401","pt":1719503721104,"mc":[{"id":"1.230180134","rc":[{"atb":[[1.69,18.4]],"id":41401491}],"con":true,"img":false}]}
{"op":"mcm","clk":"11541245805","pt":1719503755575,"mc":[{"id":"1.230180134","rc":[{"atb":[[1.68,0]],"id":41401491},{"atb":[[2.46,0]],"id":52032624},{"atb":[[2.46,0]],"id":4065261},{"atb":[[2.46,0]],"id":65040144}],"con":true,"img":false}]}
{"op":"mcm","clk":"11541246982","pt":1719503767563,"mc":[{"id":"1.230180134","rc":[{"atb":[[2.16,10.22]],"id":4065261},{"atb":[[2.14,10.4]],"id":65040144}],"con":true,"img":false}]}
{"op":"mcm","clk":"11541247003","pt":1719503767777,"mc":[{"id":"1.230180134","rc":[{"atb":[[2.16,10.22]],"id":52032624}],"con":true,"img":false}]}
{"op":"mcm","clk":"11541247012","pt":1719503767868,"mc":[{"id":"1.230180134","rc":[{"atb":[[1.7,16.94]],"id":41401491}],"con":true,"img":false}]}
{"op":"mcm","clk":"11541248540","pt":1719503784174,"mc":[{"id":"1.230180134","rc":[{"atb":[[1.69,0]],"id":41401491}],"con":true,"img":false}]}
{"op":"mcm","clk":"11541251155","pt":1719503810207,"mc":[{"id":"1.230180134","rc":[{"atb":[[1.7,0]],"id":41401491}],"con":true,"img":false}]}
{"op":"mcm","clk":"11541252239","pt":1719503820933,"mc":[{"id":"1.230180134","rc":[{"atb":[[1.68,17.44]],"id":41401491}],"con":true,"img":false}]}
{"op":"mcm","clk":"11541252853","pt":1719503826956,"mc":[{"id":"1.230180134","rc":[{"atb":[[2.18,10.76]],"id":4065261}],"con":true,"img":false}]}
{"op":"mcm","clk":"11541252861","pt":1719503827063,"mc":[{"id":"1.230180134","rc":[{"atb":[[2.18,10.76]],"id":52032624}],"con":true,"img":false}]}
{"op":"mcm","clk":"11541252880","pt":1719503827367,"mc":[{"id":"1.230180134","rc":[{"atb":[[2.16,10.94]],"id":65040144}],"con":true,"img":false}]}
{"op":"mcm","clk":"11541254588","pt":1719503843754,"mc":[{"id":"1.230180134","rc":[{"atb":[[1.69,18.4]],"id":41401491}],"con":true,"img":false}]}
{"op":"mcm","clk":"11541256969","pt":1719503864842,"mc":[{"id":"1.230180134","rc":[{"atb":[[2.16,0]],"id":52032624},{"atb":[[2.16,0]],"id":4065261},{"atb":[[2.14,0]],"id":65040144}],"con":true,"img":false}]}
{"op":"mcm","clk":"11541258254","pt":1719503877241,"mc":[{"id":"1.230180134","rc":[{"atb":[[2.2,9.88]],"id":4065261}],"con":true,"img":false}]}
{"op":"mcm","clk":"11541258265","pt":1719503877352,"mc":[{"id":"1.230180134","rc":[{"atb":[[2.18,10.04]],"id":65040144}],"con":true,"img":false}]}
{"op":"mcm","clk":"11541258288","pt":1719503877662,"mc":[{"id":"1.230180134","rc":[{"atb":[[2.2,9.88]],"id":52032624}],"con":true,"img":false}]}
{"op":"mcm","clk":"11541258343","pt":1719503878279,"mc":[{"id":"1.230180134","rc":[{"atb":[[1.68,0]],"id":41401491}],"con":true,"img":false}]}
{"op":"mcm","clk":"11541260500","pt":1719503896597,"mc":[{"id":"1.230180134","rc":[{"atb":[[1.7,16.94]],"id":41401491}],"con":true,"img":false}]}
{"op":"mcm","clk":"11541263301","pt":1719503922826,"mc":[{"id":"1.230180134","rc":[{"atb":[[1.69,0]],"id":41401491},{"atb":[[2.18,0]],"id":52032624},{"atb":[[2.18,0]],"id":4065261},{"atb":[[2.16,0]],"id":65040144}],"con":true,"img":false}]}
{"op":"mcm","clk":"11541264225","pt":1719503931611,"mc":[{"id":"1.230180134","rc":[{"atb":[[2.22,10.41]],"id":4065261}],"con":true,"img":false}]}
{"op":"mcm","clk":"11541264256","pt":1719503931926,"mc":[{"id":"1.230180134","rc":[{"atb":[[2.2,10.58]],"id":65040144}],"con":true,"img":false}]}
{"op":"mcm","clk":"11541264275","pt":1719503932131,"mc":[{"id":"1.230180134","rc":[{"atb":[[2.22,10.41]],"id":52032624}],"con":true,"img":false}]}
{"op":"mcm","clk":"11541267652","pt":1719503963601,"mc":[{"id":"1.230180134","rc":[{"atb":[[1.7,0]],"id":41401491},{"atb":[[2.2,0]],"id":52032624},{"atb":[[2.2,0]],"id":4065261},{"atb":[[2.18,0]],"id":65040144}],"con":true,"img":false}]}
{"op":"mcm","clk":"11541268082","pt":1719503968329,"mc":[{"id":"1.230180134","rc":[{"atb":[[2.24,9.56]],"id":4065261}],"con":true,"img":false}]}
{"op":"mcm","clk":"11541268093","pt":1719503968391,"mc":[{"id":"1.230180134","rc":[{"atb":[[2.22,9.72]],"id":65040144}],"con":true,"img":false}]}
{"op":"mcm","clk":"11541268106","pt":1719503968493,"mc":[{"id":"1.230180134","rc":[{"atb":[[2.24,9.56]],"id":52032624}],"con":true,"img":false}]}
{"op":"mcm","clk":"11541268126","pt":1719503968702,"mc":[{"id":"1.230180134","rc":[{"atb":[[1.68,17.44]],"id":41401491}],"con":true,"img":false}]}
{"op":"mcm","clk":"11541270763","pt":1719503996164,"mc":[{"id":"1.230180134","rc":[{"atb":[[2.22,0]],"id":52032624},{"atb":[[2.22,0]],"id":4065261},{"atb":[[2.2,0]],"id":65040144}],"con":true,"img":false}]}
{"op":"mcm","clk":"11541274556","pt":1719504032887,"mc":[{"id":"1.230180134","rc":[{"atb":[[1.02,16.48],[1.68,17.43],[1.76,16.29]],"id":41401491},{"trd":[[2.14,4.47]],"ltp":2.14,"tv":4.47,"id":41401491},{"atb":[[2.24,9.56],[1.03,10.99],[1.91,21.83]],"id":52032624},{"atb":[[2.24,9.56],[1.02,16.48],[1.91,17.46],[2.26,10.07]],"id":4065261},{"atb":[[2,20.37],[2.02,6.54],[1.03,10.99]],"id":69176457},{"atb":[[2.22,9.72],[1.02,16.48],[1.91,14.55]],"id":65040144},{"spb":[[1000,100.06]],"id":65040144}],"con":true,"img":false}]}
{"op":"mcm","clk":"11541274581","pt":1719504033087,"mc":[{"id":"1.230180134","rc":[{"atb":[[1.69,18.39]],"id":41401491}],"con":true,"img":false}]}
{"op":"mcm","clk":"11541274595","pt":1719504033194,"mc":[{"id":"1.230180134","rc":[{"atb":[[2.24,10.24]],"id":65040144}],"con":true,"img":false}]}
{"op":"mcm","clk":"11541274616","pt":1719504033393,"mc":[{"id":"1.230180134","rc":[{"atb":[[2.26,12.07]],"id":52032624}],"con":true,"img":false}]}
{"op":"mcm","clk":"11541274943","pt":1719504036193,"mc":[{"id":"1.230180134","rc":[{"atb":[[2.24,0]],"id":52032624},{"atb":[[2.24,0]],"id":4065261},{"atb":[[2.22,0]],"id":65040144}],"con":true,"img":false}]}
{"op":"mcm","clk":"11541277525","pt":1719504059099,"mc":[{"id":"1.230180134","rc":[{"atb":[[2.28,9.26]],"id":4065261}],"con":true,"img":false}]}
{"op":"mcm","clk":"11541277534","pt":1719504059206,"mc":[{"id":"1.230180134","rc":[{"atb":[[2.26,9.4]],"id":65040144}],"con":true,"img":false}]}
{"op":"mcm","clk":"11541277544","pt":1719504059309,"mc":[{"id":"1.230180134","rc":[{"atb":[[2.28,9.26]],"id":52032624}],"con":true,"img":false}]}
{"op":"mcm","clk":"11541279130","pt":1719504072860,"mc":[{"id":"1.230180134","rc":[{"atb":[[1.68,0]],"id":41401491}],"con":true,"img":false}]}
{"op":"mcm","clk":"11541279636","pt":1719504077860,"mc":[{"id":"1.230180134","rc":[{"atb":[[1.7,16.93]],"id":41401491}],"con":true,"img":false}]}
{"op":"mcm","clk":"11541281137","pt":1719504091661,"mc":[{"id":"1.230180134","rc":[{"atb":[[2.26,2]],"id":52032624},{"atb":[[2.26,0]],"id":4065261},{"atb":[[2.24,0]],"id":65040144}],"con":true,"img":false}]}
{"op":"mcm","clk":"11541282177","pt":1719504101663,"mc":[{"id":"1.230180134","rc":[{"atb":[[2.3,9.76]],"id":4065261}],"con":true,"img":false}]}
{"op":"mcm","clk":"11541282191","pt":1719504101773,"mc":[{"id":"1.230180134","rc":[{"atb":[[2.3,9.76]],"id":52032624}],"con":true,"img":false}]}
{"op":"mcm","clk":"11541282214","pt":1719504101985,"mc":[{"id":"1.230180134","rc":[{"atb":[[2.28,9.91]],"id":65040144}],"con":true,"img":false}]}
{"op":"mcm","clk":"11541284638","pt":1719504126815,"mc":[{"id":"1.230180134","rc":[{"atb":[[2.28,0]],"id":52032624},{"atb":[[2.28,0]],"id":4065261},{"atb":[[2.26,0]],"id":65040144}],"con":true,"img":false}]}
{"op":"mcm","clk":"11541284766","pt":1719504128004,"mc":[{"id":"1.230180134","rc":[{"atb":[[1.69,0]],"id":41401491}],"con":true,"img":false}]}
{"op":"mcm","clk":"11541285079","pt":1719504131221,"mc":[{"id":"1.230180134","rc":[{"atb":[[2.32,8.97]],"id":4065261}],"con":true,"img":false}]}
{"op":"mcm","clk":"11541285100","pt":1719504131433,"mc":[{"id":"1.230180134","rc":[{"atb":[[2.32,8.97]],"id":52032624}],"con":true,"img":false}]}
{"op":"mcm","clk":"11541285121","pt":1719504131637,"mc":[{"id":"1.230180134","rc":[{"atb":[[2.3,9.12]],"id":65040144}],"con":true,"img":false}]}
{"op":"mcm","clk":"11541285765","pt":1719504137421,"mc":[{"id":"1.230180134","rc":[{"atb":[[1.71,17.88]],"id":41401491}],"con":true,"img":false}]}
{"op":"mcm","clk":"11541288328","pt":1719504162685,"mc":[{"id":"1.230180134","rc":[{"atb":[[1.7,0]],"id":41401491}],"con":true,"img":false}]}
{"op":"mcm","clk":"11541288353","pt":1719504162988,"mc":[{"id":"1.230180134","rc":[{"atb":[[2.3,0]],"id":52032624},{"atb":[[2.3,0]],"id":4065261},{"atb":[[2.28,0]],"id":65040144}],"con":true,"img":false}]}
{"op":"mcm","clk":"11541288744","pt":1719504166579,"mc":[{"id":"1.230180134","rc":[{"atb":[[1.72,16.46]],"id":41401491}],"con":true,"img":false}]}
{"op":"mcm","clk":"11541289308","pt":1719504171606,"mc":[{"id":"1.230180134","rc":[{"atb":[[2.34,9.47]],"id":4065261}],"con":true,"img":false}]}
{"op":"mcm","clk":"11541289318","pt":1719504171717,"mc":[{"id":"1.230180134","rc":[{"atb":[[2.34,9.47]],"id":52032624}],"con":true,"img":false}]}
{"op":"mcm","clk":"11541289344","pt":1719504171923,"mc":[{"id":"1.230180134","rc":[{"atb":[[2.32,9.61]],"id":65040144}],"con":true,"img":false}]}
{"op":"mcm","clk":"11541291354","pt":1719504188127,"mc":[{"id":"1.230180134","rc":[{"atb":[[2.32,0]],"id":52032624},{"atb":[[2.32,0]],"id":4065261},{"atb":[[2.3,0]],"id":65040144}],"con":true,"img":false}]}
{"op":"mcm","clk":"11541292307","pt":1719504196239,"mc":[{"id":"1.230180134","rc":[{"atb":[[1.71,0]],"id":41401491}],"con":true,"img":false}]}
{"op":"mcm","clk":"11541293337","pt":1719504205613,"mc":[{"id":"1.230180134","rc":[{"atb":[[2.36,8.71]],"id":4065261}],"con":true,"img":false}]}
{"op":"mcm","clk":"11541293345","pt":1719504205715,"mc":[{"id":"1.230180134","rc":[{"atb":[[2.36,8.71]],"id":52032624}],"con":true,"img":false}]}
{"op":"mcm","clk":"11541293356","pt":1719504205820,"mc":[{"id":"1.230180134","rc":[{"atb":[[2.34,8.84]],"id":65040144}],"con":true,"img":false}]}
{"op":"mcm","clk":"11541293380","pt":1719504206033,"mc":[{"id":"1.230180134","rc":[{"atb":[[1.73,17.39]],"id":41401491}],"con":true,"img":false}]}
{"op":"mcm","clk":"11541296385","pt":1719504232745,"mc":[{"id":"1.230180134","rc":[{"atb":[[2.34,0]],"id":52032624},{"atb":[[2.34,0]],"id":4065261},{"atb":[[2.32,0]],"id":65040144}],"con":true,"img":false}]}
{"op":"mcm","clk":"11541296956","pt":1719504237886,"mc":[{"id":"1.230180134","rc":[{"atb":[[1.72,0]],"id":41401491}],"con":true,"img":false}]}
{"op":"mcm","clk":"11541297423","pt":1719504241677,"mc":[{"id":"1.230180134","rc":[{"atb":[[1.74,16.02]],"id":41401491}],"con":true,"img":false}]}
{"op":"mcm","clk":"11541300272","pt":1719504268537,"mc":[{"id":"1.230180134","rc":[{"atb":[[1.73,0]],"id":41401491}],"con":true,"img":false}]}
{"op":"mcm","clk":"11541300284","pt":1719504268593,"mc":[{"id":"1.230180134","rc":[{"atb":[[2.36,0]],"id":52032624},{"atb":[[2.36,0]],"id":4065261},{"atb":[[2.34,0]],"id":65040144}],"con":true,"img":false}]}
{"op":"mcm","clk":"11541301107","pt":1719504276604,"mc":[{"id":"1.230180134","rc":[{"atb":[[2.16,10.21]],"id":52032624},{"atb":[[2.16,10.21]],"id":4065261}],"con":true,"img":false}]}
{"op":"mcm","clk":"11541301127","pt":1719504276806,"mc":[{"id":"1.230180134","rc":[{"atb":[[2.14,10.4]],"id":65040144}],"con":true,"img":false}]}
{"op":"mcm","clk":"11541303422","pt":1719504297561,"mc":[{"id":"1.230180134","rc":[{"atb":[[1.74,0]],"id":41401491}],"con":true,"img":false}]}
{"op":"mcm","clk":"11541303604","pt":1719504299433,"mc":[{"id":"1.230180134","rc":[{"atb":[[1.68,17.43]],"id":41401491}],"con":true,"img":false}]}
{"op":"mcm","clk":"11541308161","pt":1719504343226,"mc":[{"id":"1.230180134","rc":[{"atb":[[1.69,18.39]],"id":41401491},{"atb":[[2.18,10.75]],"id":4065261}],"con":true,"img":false}]}
{"op":"mcm","clk":"11541308192","pt":1719504343490,"mc":[{"id":"1.230180134","rc":[{"atb":[[2.18,10.75]],"id":52032624},{"atb":[[2.16,10.94]],"id":65040144}],"con":true,"img":false}]}
{"op":"mcm","clk":"11541311951","pt":1719504381676,"mc":[{"id":"1.230180134","rc":[{"atb":[[1.68,0]],"id":41401491},{"atb":[[2.16,0]],"id":52032624},{"atb":[[2.16,0]],"id":4065261},{"atb":[[2.14,0]],"id":65040144}],"con":true,"img":false}]}
{"op":"mcm","clk":"11541312685","pt":1719504389969,"mc":[{"id":"1.230180134","rc":[{"atb":[[2.2,9.87]],"id":4065261}],"con":true,"img":false}]}
{"op":"mcm","clk":"11541312699","pt":1719504390171,"mc":[{"id":"1.230180134","rc":[{"atb":[[2.18,10.04]],"id":65040144}],"con":true,"img":false}]}
{"op":"mcm","clk":"11541312710","pt":1719504390272,"mc":[{"id":"1.230180134","rc":[{"atb":[[1.7,16.93]],"id":41401491}],"con":true,"img":false}]}
{"op":"mcm","clk":"11541312719","pt":1719504390377,"mc":[{"id":"1.230180134","rc":[{"atb":[[2.2,9.87]],"id":52032624}],"con":true,"img":false}]}
{"op":"mcm","clk":"11541317939","pt":1719504447331,"mc":[{"id":"1.230180134","rc":[{"atb":[[1.69,0]],"id":41401491},{"atb":[[2.18,0]],"id":52032624},{"atb":[[2.18,0]],"id":4065261},{"atb":[[2.16,0]],"id":65040144}],"con":true,"img":false}]}
{"op":"mcm","clk":"11541318278","pt":1719504451463,"mc":[{"id":"1.230180134","rc":[{"atb":[[2.22,10.4]],"id":4065261}],"con":true,"img":false}]}
{"op":"mcm","clk":"11541318296","pt":1719504451669,"mc":[{"id":"1.230180134","rc":[{"atb":[[1.71,17.88]],"id":41401491}],"con":true,"img":false}]}
{"op":"mcm","clk":"11541318308","pt":1719504451772,"mc":[{"id":"1.230180134","rc":[{"atb":[[2.2,10.57]],"id":65040144}],"con":true,"img":false}]}
{"op":"mcm","clk":"11541318325","pt":1719504451935,"mc":[{"id":"1.230180134","rc":[{"atb":[[2.22,10.4]],"id":52032624}],"con":true,"img":false}]}
