{"op":"mcm","clk":"11536380637","pt":1719425245567,"mc":[{"id":"1.230178307","marketDefinition":{"bspMarket":true,"turnInPlayEnabled":false,"persistenceEnabled":false,"marketBaseRate":5.0,"eventId":"33376062","eventTypeId":"4339","numberOfWinners":2,"bettingType":"ODDS","marketType":"PLACE","marketTime":"2024-06-27T13:36:00.000Z","suspendTime":"2024-06-27T13:36:00.000Z","bspReconciled":false,"complete":true,"inPlay":false,"crossMatching":false,"runnersVoidable":false,"numberOfActiveRunners":6,"betDelay":0,"status":"OPEN","runners":[{"status":"ACTIVE","sortPriority":1,"id":61496663,"name":"1. Glory Bomber"},{"status":"ACTIVE","sortPriority":2,"id":47801105,"name":"2. Lady Casey"},{"status":"ACTIVE","sortPriority":3,"id":47095746,"name":"3. Zipping Rush"},{"status":"ACTIVE","sortPriority":4,"id":53893973,"name":"4. Marinas Ollie"},{"status":"ACTIVE","sortPriority":5,"id":53987475,"name":"5. Brynoffa Alice"},{"status":"ACTIVE","sortPriority":6,"id":66596720,"name":"6. Ashville Bucko"}],"regulators":["MR_INT"],"venue":"Kinsley","countryCode":"GB","discountAllowed":false,"timezone":"Europe/London","openDate":"2024-06-27T13:36:00.000Z","version":5994643731,"name":"To Be Placed","eventName":"Kinsley 27th Jun"},"rc":[],"con":true,"img":false}]}
{"op":"mcm","clk":"11536380883","pt":1719425247541,"mc":[{"id":"1.230178307","marketDefinition":{"bspMarket":true,"turnInPlayEnabled":false,"persistenceEnabled":false,"marketBaseRate":5.0,"eventId":"33376062","eventTypeId":"4339","numberOfWinners":2,"bettingType":"ODDS","marketType":"PLACE","marketTime":"2024-06-27T13:36:00.000Z","suspendTime":"2024-06-27T13:36:00.000Z","bspReconciled":false,"complete":true,"inPlay":false,"crossMatching":false,"runnersVoidable":false,"numberOfActiveRunners":6,"betDelay":0,"status":"OPEN","runners":[{"status":"ACTIVE","sortPriority":1,"id":61496663,"name":"1. Glory Bomber"},{"status":"ACTIVE","sortPriority":2,"id":47801105,"name":"2. Lady Casey"},{"status":"ACTIVE","sortPriority":3,"id":47095746,"name":"3. Zipping Rush"},{"status":"ACTIVE","sortPriority":4,"id":53893973,"name":"4. Marinas Ollie"},{"status":"ACTIVE","sortPriority":5,"id":53987475,"name":"5. Brynoffa Alice"},{"status":"ACTIVE","sortPriority":6,"id":66596720,"name":"6. Ashville Bucko"}],"regulators":["MR_INT"],"venue":"Kinsley","countryCode":"GB","discountAllowed":true,"timezone":"Europe/London","openDate":"2024-06-27T13:36:00.000Z","version":5994643731,"name":"To Be Placed","eventName":"Kinsley 27th Jun"},"rc":[],"con":true,"img":false}]}
{"op":"mcm","clk":"11536837207","pt":1719431856220,"mc":[{"id":"1.230178307","rc":[{"atb":[[1.01,22.45]],"id":47801105},{"atl":[[1000,0.84]],"id":47801105},{"spn":500.5,"spf":"NaN","id":47801105},{"atb":[[1.02,11.22]],"id":53893973},{"atl":[[990,0.84]],"id":53893973},{"spn":495.51,"spf":"NaN","id":53893973},{"atb":[[1.03,7.48]],"id":47095746},{"atl":[[1000,0.84]],"id":47095746},{"spn":500.51,"spf":"NaN","id":47095746},{"atb":[[1.03,7.48]],"id":61496663},{"atl":[[990,0.84]],"id":61496663},{"spn":495.51,"spf":"NaN","id":61496663},{"atb":[[1.03,7.48]],"id":66596720},{"atl":[[990,0.84]],"id":66596720},{"spn":495.51,"spf":"NaN","id":66596720},{"atb":[[1.01,22.45]],"id":53987475},{"atl":[[1000,0.84]],"id":53987475},{"spn":500.5,"spf":"NaN","id":53987475}],"con":true,"img":false}]}
{"op":"mcm","clk":"11537084061","pt":1719435436494,"mc":[{"id":"1.230178307","rc":[{"atl":[[1000,0.32]],"id":47801105},{"atl":[[990,0.32]],"id":53893973},{"atl":[[1000,0.32]],"id":47095746},{"atl":[[990,0.32]],"id":61496663},{"atl":[[990,0.32]],"id":66596720},{"atl":[[1000,0.32]],"id":53987475}],"con":true,"img":false}]}
{"op":"mcm","clk":"11537232226","pt":1719437882514,"mc":[{"id":"1.230178307","marketDefinition":{"bspMarket":true,"turnInPlayEnabled":false,"persistenceEnabled":false,"marketBaseRate":5.0,"eventId":"33376062","eventTypeId":"4339","numberOfWinners":2,"bettingType":"ODDS","marketType":"PLACE","marketTime":"2024-06-27T13:36:00.000Z","suspendTime":"2024-06-27T13:36:00.000Z","bspReconciled":false,"complete":true,"inPlay":false,"crossMatching":false,"runnersVoidable":false,"numberOfActiveRunners":6,"betDelay":0,"status":"OPEN","runners":[{"status":"ACTIVE","sortPriority":1,"id":61496663,"name":"1. Glory Bomber"},{"status":"ACTIVE","sortPriority":2,"id":47801105,"name":"2. Lady Casey"},{"status":"ACTIVE","sortPriority":3,"id":47095746,"name":"3. Zipping Rush"},{"status":"ACTIVE","sortPriority":4,"id":53893973,"name":"4. Marinas Ollie"},{"status":"ACTIVE","sortPriority":5,"id":53987475,"name":"5. Brynoffa Alice"},{"status":"ACTIVE","sortPriority":6,"id":66596720,"name":"6. Ashville Bucko"}],"regulators":["MR_INT"],"venue":"Kinsley","countryCode":"GB","discountAllowed":true,"timezone":"Europe/London","openDate":"2024-06-27T13:36:00.000Z","version":5994643731,"name":"To Be Placed","eventName":"Kinsley 27th Jun"},"rc":[{"atb":[[1.01,22.45]],"id":47801105},{"atl":[[1000,0.33]],"id":47801105},{"spn":500.5,"spf":"NaN","id":47801105},{"atb":[[1.02,11.22]],"id":53893973},{"atl":[[990,0.33]],"id":53893973},{"spn":495.51,"spf":"NaN","id":53893973},{"atb":[[1.03,7.48]],"id":47095746},{"atl":[[1000,0.33]],"id":47095746},{"spn":500.51,"spf":"NaN","id":47095746},{"atb":[[1.03,7.48]],"id":61496663},{"atl":[[990,0.33]],"id":61496663},{"spn":495.51,"spf":"NaN","id":61496663},{"atb":[[1.03,7.48]],"id":66596720},{"atl":[[990,0.33]],"id":66596720},{"spn":495.51,"spf":"NaN","id":66596720},{"atb":[[1.01,22.45]],"id":53987475},{"atl":[[1000,0.33]],"id":53987475},{"spn":500.5,"spf":"NaN","id":53987475}],"con":true,"img":true}]}
{"op":"mcm","clk":"11537302330","pt":1719439034859,"mc":[{"id":"1.230178307","rc":[{"atb":[[1.01,22.45]],"id":47801105},{"atl":[[1000,0.17]],"id":47801105},{"atb":[[1.02,11.22]],"id":53893973},{"atl":[[990,0.17]],"id":53893973},{"atb":[[1.03,7.48]],"id":47095746},{"atl":[[1000,0.17]],"id":47095746},{"atb":[[1.03,7.48]],"id":61496663},{"atl":[[990,0.17]],"id":61496663},{"atb":[[1.03,7.48]],"id":66596720},{"atl":[[990,0.17]],"id":66596720},{"atb":[[1.01,22.45]],"id":53987475},{"atl":[[1000,0.17]],"id":53987475}],"con":true,"img":false}]}
{"op":"mcm","clk":"11537573353","pt":1719443282535,"mc":[{"id":"1.230178307","marketDefinition":{"bspMarket":true,"turnInPlayEnabled":false,"persistenceEnabled":false,"marketBaseRate":5.0,"eventId":"33376062","eventTypeId":"4339","numberOfWinners":2,"bettingType":"ODDS","marketType":"PLACE","marketTime":"2024-06-27T13:36:00.000Z","suspendTime":"2024-06-27T13:36:00.000Z","bspReconciled":false,"complete":true,"inPlay":false,"crossMatching":false,"runnersVoidable":false,"numberOfActiveRunners":6,"betDelay":0,"status":"OPEN","runners":[{"status":"ACTIVE","sortPriority":1,"id":61496663,"name":"1. Glory Bomber"},{"status":"ACTIVE","sortPriority":2,"id":47801105,"name":"2. Lady Casey"},{"status":"ACTIVE","sortPriority":3,"id":47095746,"name":"3. Zipping Rush"},{"status":"ACTIVE","sortPriority":4,"id":53893973,"name":"4. Marinas Ollie"},{"status":"ACTIVE","sortPriority":5,"id":53987475,"name":"5. Brynoffa Alice"},{"status":"ACTIVE","sortPriority":6,"id":66596720,"name":"6. Ashville Bucko"}],"regulators":["MR_INT"],"venue":"Kinsley","countryCode":"GB","discountAllowed":true,"timezone":"Europe/London","openDate":"2024-06-27T13:36:00.000Z","version":5994643731,"name":"To Be Placed","eventName":"Kinsley 27th Jun"},"rc":[{"atb":[[1.01,22.45]],"id":47801105},{"atl":[[1000,0.17]],"id":47801105},{"spn":500.5,"spf":"NaN","id":47801105},{"atb":[[1.02,11.22]],"id":53893973},{"atl":[[990,0.17]],"id":53893973},{"spn":495.51,"spf":"NaN","id":53893973},{"atb":[[1.03,7.48]],"id":47095746},{"atl":[[1000,0.17]],"id":47095746},{"spn":500.51,"spf":"NaN","id":47095746},{"atb":[[1.03,7.48]],"id":61496663},{"atl":[[990,0.17]],"id":61496663},{"spn":495.51,"spf":"NaN","id":61496663},{"atb":[[1.03,7.48]],"id":66596720},{"atl":[[990,0.17]],"id":66596720},{"spn":495.51,"spf":"NaN","id":66596720},{"atb":[[1.01,22.45]],"id":53987475},{"atl":[[1000,0.17]],"id":53987475},{"spn":500.5,"spf":"NaN","id":53987475}],"con":true,"img":true}]}
{"op":"mcm","clk":"11537954913","pt":1719448682555,"mc":[{"id":"1.230178307","marketDefinition":{"bspMarket":true,"turnInPlayEnabled":false,"persistenceEnabled":false,"marketBaseRate":5.0,"eventId":"33376062","eventTypeId":"4339","numberOfWinners":2,"bettingType":"ODDS","marketType":"PLACE","marketTime":"2024-06-27T13:36:00.000Z","suspendTime":"2024-06-27T13:36:00.000Z","bspReconciled":false,"complete":true,"inPlay":false,"crossMatching":false,"runnersVoidable":false,"numberOfActiveRunners":6,"betDelay":0,"status":"OPEN","runners":[{"status":"ACTIVE","sortPriority":1,"id":61496663,"name":"1. Glory Bomber"},{"status":"ACTIVE","sortPriority":2,"id":47801105,"name":"2. Lady Casey"},{"status":"ACTIVE","sortPriority":3,"id":47095746,"name":"3. Zipping Rush"},{"status":"ACTIVE","sortPriority":4,"id":53893973,"name":"4. Marinas Ollie"},{"status":"ACTIVE","sortPriority":5,"id":53987475,"name":"5. Brynoffa Alice"},{"status":"ACTIVE","sortPriority":6,"id":66596720,"name":"6. Ashville Bucko"}],"regulators":["MR_INT"],"venue":"Kinsley","countryCode":"GB","discountAllowed":true,"timezone":"Europe/London","openDate":"2024-06-27T13:36:00.000Z","version":5994643731,"name":"To Be Placed","eventName":"Kinsley 27th Jun"},"rc":[{"atb":[[1.01,22.45]],"id":47801105},{"atl":[[1000,0.17]],"id":47801105},{"spn":500.5,"spf":"NaN","id":47801105},{"atb":[[1.02,11.22]],"id":53893973},{"atl":[[990,0.17]],"id":53893973},{"spn":495.51,"spf":"NaN","id":53893973},{"atb":[[1.03,7.48]],"id":47095746},{"atl":[[1000,0.17]],"id":47095746},{"spn":500.51,"spf":"NaN","id":47095746},{"atb":[[1.03,7.48]],"id":61496663},{"atl":[[990,0.17]],"id":61496663},{"spn":495.51,"spf":"NaN","id":61496663},{"atb":[[1.03,7.48]],"id":66596720},{"atl":[[990,0.17]],"id":66596720},{"spn":495.51,"spf":"NaN","id":66596720},{"atb":[[1.01,22.45]],"id":53987475},{"atl":[[1000,0.17]],"id":53987475},{"spn":500.5,"spf":"NaN","id":53987475}],"con":true,"img":true}]}
{"op":"mcm","clk":"11538170576","pt":1719454082534,"mc":[{"id":"1.230178307","marketDefinition":{"bspMarket":true,"turnInPlayEnabled":false,"persistenceEnabled":false,"marketBaseRate":5.0,"eventId":"33376062","eventTypeId":"4339","numberOfWinners":2,"bettingType":"ODDS","marketType":"PLACE","marketTime":"2024-06-27T13:36:00.000Z","suspendTime":"2024-06-27T13:36:00.000Z","bspReconciled":false,"complete":true,"inPlay":false,"crossMatching":false,"runnersVoidable":false,"numberOfActiveRunners":6,"betDelay":0,"status":"OPEN","runners":[{"status":"ACTIVE","sortPriority":1,"id":61496663,"name":"1. Glory Bomber"},{"status":"ACTIVE","sortPriority":2,"id":47801105,"name":"2. Lady Casey"},{"status":"ACTIVE","sortPriority":3,"id":47095746,"name":"3. Zipping Rush"},{"status":"ACTIVE","sortPriority":4,"id":53893973,"name":"4. Marinas Ollie"},{"status":"ACTIVE","sortPriority":5,"id":53987475,"name":"5. Brynoffa Alice"},{"status":"ACTIVE","sortPriority":6,"id":66596720,"name":"6. Ashville Bucko"}],"regulators":["MR_INT"],"venue":"Kinsley","countryCode":"GB","discountAllowed":true,"timezone":"Europe/London","openDate":"2024-06-27T13:36:00.000Z","version":5994643731,"name":"To Be Placed","eventName":"Kinsley 27th Jun"},"rc":[{"atb":[[1.01,22.46]],"id":47801105},{"atl":[[1000,0.17]],"id":47801105},{"spn":500.5,"spf":"NaN","id":47801105},{"atb":[[1.02,11.23]],"id":53893973},{"atl":[[990,0.17]],"id":53893973},{"spn":495.51,"spf":"NaN","id":53893973},{"atb":[[1.03,7.49]],"id":47095746},{"atl":[[1000,0.17]],"id":47095746},{"spn":500.51,"spf":"NaN","id":47095746},{"atb":[[1.03,7.49]],"id":61496663},{"atl":[[990,0.17]],"id":61496663},{"spn":495.51,"spf":"NaN","id":61496663},{"atb":[[1.03,7.49]],"id":66596720},{"atl":[[990,0.17]],"id":66596720},{"spn":495.51,"spf":"NaN","id":66596720},{"atb":[[1.01,22.46]],"id":53987475},{"atl":[[1000,0.17]],"id":53987475},{"spn":500.5,"spf":"NaN","id":53987475}],"con":true,"img":true}]}
{"op":"mcm","clk":"11538368234","pt":1719459482561,"mc":[{"id":"1.230178307","marketDefinition":{"bspMarket":true,"turnInPlayEnabled":false,"persistenceEnabled":false,"marketBaseRate":5.0,"eventId":"33376062","eventTypeId":"4339","numberOfWinners":2,"bettingType":"ODDS","marketType":"PLACE","marketTime":"2024-06-27T13:36:00.000Z","suspendTime":"2024-06-27T13:36:00.000Z","bspReconciled":false,"complete":true,"inPlay":false,"crossMatching":false,"runnersVoidable":false,"numberOfActiveRunners":6,"betDelay":0,"status":"OPEN","runners":[{"status":"ACTIVE","sortPriority":1,"id":61496663,"name":"1. Glory Bomber"},{"status":"ACTIVE","sortPriority":2,"id":47801105,"name":"2. Lady Casey"},{"status":"ACTIVE","sortPriority":3,"id":47095746,"name":"3. Zipping Rush"},{"status":"ACTIVE","sortPriority":4,"id":53893973,"name":"4. Marinas Ollie"},{"status":"ACTIVE","sortPriority":5,"id":53987475,"name":"5. Brynoffa Alice"},{"status":"ACTIVE","sortPriority":6,"id":66596720,"name":"6. Ashville Bucko"}],"regulators":["MR_INT"],"venue":"Kinsley","countryCode":"GB","discountAllowed":true,"timezone":"Europe/London","openDate":"2024-06-27T13:36:00.000Z","version":5994643731,"name":"To Be Placed","eventName":"Kinsley 27th Jun"},"rc":[{"atb":[[1.01,22.46]],"id":47801105},{"atl":[[1000,0.17]],"id":47801105},{"spn":500.5,"spf":"NaN","id":47801105},{"atb":[[1.02,11.23]],"id":53893973},{"atl":[[990,0.17]],"id":53893973},{"spn":495.51,"spf":"NaN","id":53893973},{"atb":[[1.03,7.49]],"id":47095746},{"atl":[[1000,0.17]],"id":47095746},{"spn":500.51,"spf":"NaN","id":47095746},{"atb":[[1.03,7.49]],"id":61496663},{"atl":[[990,0.17]],"id":61496663},{"spn":495.51,"spf":"NaN","id":61496663},{"atb":[[1.03,7.49]],"id":66596720},{"atl":[[990,0.17]],"id":66596720},{"spn":495.51,"spf":"NaN","id":66596720},{"atb":[[1.01,22.46]],"id":53987475},{"atl":[[1000,0.17]],"id":53987475},{"spn":500.5,"spf":"NaN","id":53987475}],"con":true,"img":true}]}
{"op":"mcm","clk":"11538595360","pt":1719464882536,"mc":[{"id":"1.230178307","marketDefinition":{"bspMarket":true,"turnInPlayEnabled":false,"persistenceEnabled":false,"marketBaseRate":5.0,"eventId":"33376062","eventTypeId":"4339","numberOfWinners":2,"bettingType":"ODDS","marketType":"PLACE","marketTime":"2024-06-27T13:36:00.000Z","suspendTime":"2024-06-27T13:36:00.000Z","bspReconciled":false,"complete":true,"inPlay":false,"crossMatching":false,"runnersVoidable":false,"numberOfActiveRunners":6,"betDelay":0,"status":"OPEN","runners":[{"status":"ACTIVE","sortPriority":1,"id":61496663,"name":"1. Glory Bomber"},{"status":"ACTIVE","sortPriority":2,"id":47801105,"name":"2. Lady Casey"},{"status":"ACTIVE","sortPriority":3,"id":47095746,"name":"3. Zipping Rush"},{"status":"ACTIVE","sortPriority":4,"id":53893973,"name":"4. Marinas Ollie"},{"status":"ACTIVE","sortPriority":5,"id":53987475,"name":"5. Brynoffa Alice"},{"status":"ACTIVE","sortPriority":6,"id":66596720,"name":"6. Ashville Bucko"}],"regulators":["MR_INT"],"venue":"Kinsley","countryCode":"GB","discountAllowed":true,"timezone":"Europe/London","openDate":"2024-06-27T13:36:00.000Z","version":5994643731,"name":"To Be Placed","eventName":"Kinsley 27th Jun"},"rc":[{"atb":[[1.01,22.46]],"id":47801105},{"atl":[[1000,0.17]],"id":47801105},{"spn":500.5,"spf":"NaN","id":47801105},{"atb":[[1.02,11.23]],"id":53893973},{"atl":[[990,0.17]],"id":53893973},{"spn":495.51,"spf":"NaN","id":53893973},{"atb":[[1.03,7.48]],"id":47095746},{"atl":[[1000,0.17]],"id":47095746},{"spn":500.51,"spf":"NaN","id":47095746},{"atb":[[1.03,7.48]],"id":61496663},{"atl":[[990,0.17]],"id":61496663},{"spn":495.51,"spf":"NaN","id":61496663},{"atb":[[1.03,7.48]],"id":66596720},{"atl":[[990,0.17]],"id":66596720},{"spn":495.51,"spf":"NaN","id":66596720},{"atb":[[1.01,22.46]],"id":53987475},{"atl":[[1000,0.17]],"id":53987475},{"spn":500.5,"spf":"NaN","id":53987475}],"con":true,"img":true}]}
{"op":"mcm","clk":"11538907374","pt":1719471509350,"mc":[{"id":"1.230178307","rc":[{"atb":[[1.01,22.46]],"id":47801105},{"atl":[[1000,1.17]],"id":47801105},{"atb":[[1.02,11.23]],"id":53893973},{"atl":[[1000,1]],"id":53893973},{"atb":[[1.03,7.48]],"id":47095746},{"atl":[[1000,1.17]],"id":47095746},{"atb":[[1.03,7.48]],"id":61496663},{"atl":[[1000,1]],"id":61496663},{"atb":[[1.03,7.48]],"id":66596720},{"atl":[[1000,1]],"id":66596720},{"atb":[[1.01,22.46]],"id":53987475},{"atl":[[1000,1.17]],"id":53987475}],"con":true,"img":false}]}
{"op":"mcm","clk":"11538907381","pt":1719471509499,"mc":[{"id":"1.230178307","rc":[{"atb":[[1.07,2.48]],"id":47801105},{"atb":[[1.07,2.48]],"id":53893973},{"atb":[[1.07,2.48]],"id":47095746},{"atb":[[1.07,2.48]],"id":61496663},{"atb":[[1.07,2.48]],"id":66596720},{"atb":[[1.07,2.48]],"id":53987475}],"con":true,"img":false}]}
{"op":"mcm","clk":"11538907388","pt":1719471509554,"mc":[{"id":"1.230178307","rc":[{"atl":[[1000,0.65]],"id":47801105},{"atl":[[1000,0.48]],"id":53893973},{"atl":[[1000,0.65]],"id":47095746},{"atl":[[1000,0.48]],"id":61496663},{"atl":[[1000,0.48]],"id":66596720},{"atl":[[1000,0.65]],"id":53987475}],"con":true,"img":false}]}
{"op":"mcm","clk":"11538907392","pt":1719471509653,"mc":[{"id":"1.230178307","rc":[{"atl":[[1000,0.17]],"id":47801105},{"atl":[[1000,0]],"id":53893973},{"atl":[[1000,0.17]],"id":47095746},{"atl":[[1000,0]],"id":61496663},{"atl":[[1000,0]],"id":66596720},{"atl":[[1000,0.17]],"id":53987475}],"con":true,"img":false}]}
{"op":"mcm","clk":"11538907404","pt":1719471509760,"mc":[{"id":"1.230178307","rc":[{"atl":[[75,0.48]],"id":47801105},{"atl":[[75,0.48]],"id":53893973},{"atl":[[75,0.48]],"id":47095746},{"atl":[[75,0.48]],"id":61496663},{"atl":[[75,0.48]],"id":66596720},{"atl":[[75,0.48]],"id":53987475}],"con":true,"img":false}]}
{"op":"mcm","clk":"11539122507","pt":1719475682543,"mc":[{"id":"1.230178307","marketDefinition":{"bspMarket":true,"turnInPlayEnabled":false,"persistenceEnabled":false,"marketBaseRate":5.0,"eventId":"33376062","eventTypeId":"4339","numberOfWinners":2,"bettingType":"ODDS","marketType":"PLACE","marketTime":"2024-06-27T13:36:00.000Z","suspendTime":"2024-06-27T13:36:00.000Z","bspReconciled":false,"complete":true,"inPlay":false,"crossMatching":false,"runnersVoidable":false,"numberOfActiveRunners":6,"betDelay":0,"status":"OPEN","runners":[{"status":"ACTIVE","sortPriority":1,"id":61496663,"name":"1. Glory Bomber"},{"status":"ACTIVE","sortPriority":2,"id":47801105,"name":"2. Lady Casey"},{"status":"ACTIVE","sortPriority":3,"id":47095746,"name":"3. Zipping Rush"},{"status":"ACTIVE","sortPriority":4,"id":53893973,"name":"4. Marinas Ollie"},{"status":"ACTIVE","sortPriority":5,"id":53987475,"name":"5. Brynoffa Alice"},{"status":"ACTIVE","sortPriority":6,"id":66596720,"name":"6. Ashville Bucko"}],"regulators":["MR_INT"],"venue":"Kinsley","countryCode":"GB","discountAllowed":true,"timezone":"Europe/London","openDate":"2024-06-27T13:36:00.000Z","version":5994643731,"name":"To Be Placed","eventName":"Kinsley 27th Jun"},"rc":[{"atb":[[1.01,22.45],[1.07,2.48]],"id":47801105},{"atl":[[75,0.48],[1000,0.17]],"id":47801105},{"spn":38.03,"spf":"NaN","id":47801105},{"atb":[[1.02,11.22],[1.07,2.48]],"id":53893973},{"atl":[[75,0.48],[990,0.17]],"id":53893973},{"spn":38.03,"spf":"NaN","id":53893973},{"atb":[[1.03,7.48],[1.07,2.48]],"id":47095746},{"atl":[[75,0.48],[1000,0.17]],"id":47095746},{"spn":38.03,"spf":"NaN","id":47095746},{"atb":[[1.03,7.48],[1.07,2.48]],"id":61496663},{"atl":[[75,0.48],[990,0.17]],"id":61496663},{"spn":38.03,"spf":"NaN","id":61496663},{"atb":[[1.03,7.48],[1.07,2.48]],"id":66596720},{"atl":[[75,0.48],[990,0.17]],"id":66596720},{"spn":38.03,"spf":"NaN","id":66596720},{"atb":[[1.01,22.45],[1.07,2.48]],"id":53987475},{"atl":[[75,0.48],[1000,0.17]],"id":53987475},{"spn":38.03,"spf":"NaN","id":53987475}],"con":true,"img":true}]}
{"op":"mcm","clk":"11539438483","pt":1719481082544,"mc":[{"id":"1.230178307","marketDefinition":{"bspMarket":true,"turnInPlayEnabled":false,"persistenceEnabled":false,"marketBaseRate":5.0,"eventId":"33376062","eventTypeId":"4339","numberOfWinners":2,"bettingType":"ODDS","marketType":"PLACE","marketTime":"2024-06-27T13:36:00.000Z","suspendTime":"2024-06-27T13:36:00.000Z","bspReconciled":false,"complete":true,"inPlay":false,"crossMatching":false,"runnersVoidable":false,"numberOfActiveRunners":6,"betDelay":0,"status":"OPEN","runners":[{"status":"ACTIVE","sortPriority":1,"id":61496663,"name":"1. Glory Bomber"},{"status":"ACTIVE","sortPriority":2,"id":47801105,"name":"2. Lady Casey"},{"status":"ACTIVE","sortPriority":3,"id":47095746,"name":"3. Zipping Rush"},{"status":"ACTIVE","sortPriority":4,"id":53893973,"name":"4. Marinas Ollie"},{"status":"ACTIVE","sortPriority":5,"id":53987475,"name":"5. Brynoffa Alice"},{"status":"ACTIVE","sortPriority":6,"id":66596720,"name":"6. Ashville Bucko"}],"regulators":["MR_INT"],"venue":"Kinsley","countryCode":"GB","discountAllowed":true,"timezone":"Europe/London","openDate":"2024-06-27T13:36:00.000Z","version":5994643731,"name":"To Be Placed","eventName":"Kinsley 27th Jun"},"rc":[{"atb":[[1.01,22.45],[1.07,2.48]],"id":47801105},{"atl":[[75,0.48],[1000,0.17]],"id":47801105},{"spn":38.03,"spf":"NaN","id":47801105},{"atb":[[1.02,11.22],[1.07,2.48]],"id":53893973},{"atl":[[75,0.48],[990,0.17]],"id":53893973},{"spn":38.03,"spf":"NaN","id":53893973},{"atb":[[1.03,7.48],[1.07,2.48]],"id":47095746},{"atl":[[75,0.48],[1000,0.17]],"id":47095746},{"spn":38.03,"spf":"NaN","id":47095746},{"atb":[[1.03,7.48],[1.07,2.48]],"id":61496663},{"atl":[[75,0.48],[990,0.17]],"id":61496663},{"spn":38.03,"spf":"NaN","id":61496663},{"atb":[[1.03,7.48],[1.07,2.48]],"id":66596720},{"atl":[[75,0.48],[990,0.17]],"id":66596720},{"spn":38.03,"spf":"NaN","id":66596720},{"atb":[[1.01,22.45],[1.07,2.48]],"id":53987475},{"atl":[[75,0.48],[1000,0.17]],"id":53987475},{"spn":38.03,"spf":"NaN","id":53987475}],"con":true,"img":true}]}
{"op":"mcm","clk":"11540042037","pt":1719489333017,"mc":[{"id":"1.230178307","rc":[{"atb":[[1.01,22.45]],"id":47801105},{"atl":[[980,0.87]],"id":47801105},{"spn":38.03,"spf":"NaN","id":47801105},{"atb":[[1.02,11.22]],"id":53893973},{"atl":[[960,1.7]],"id":53893973},{"spn":38.03,"spf":"NaN","id":53893973},{"atb":[[1.03,7.48]],"id":47095746},{"atl":[[970,0.87]],"id":47095746},{"spn":38.03,"spf":"NaN","id":47095746},{"atb":[[1.03,7.48]],"id":61496663},{"atl":[[990,1.05]],"id":61496663},{"spn":38.03,"spf":"NaN","id":61496663},{"atb":[[1.03,7.48]],"id":66596720},{"atl":[[960,2.02]],"id":66596720},{"spn":38.03,"spf":"NaN","id":66596720},{"atb":[[1.01,22.45]],"id":53987475},{"atl":[[970,0.87]],"id":53987475},{"spn":38.03,"spf":"NaN","id":53987475}],"con":true,"img":false}]}
{"op":"mcm","clk":"11540341538","pt":1719493264549,"mc":[{"id":"1.230178307","rc":[{"atb":[[1.01,22.47],[1.04,1]],"id":47801105},{"atl":[[980,0.88],[1000,0.17]],"id":47801105},{"atb":[[1.02,11.23],[1.04,1]],"id":53893973},{"atl":[[960,1.71],[990,0.17]],"id":53893973},{"atb":[[1.03,7.49],[1.04,1]],"id":47095746},{"atl":[[970,0.88],[1000,0.17]],"id":47095746},{"atb":[[1.03,7.49],[1.04,1]],"id":61496663},{"atl":[[990,1.05]],"id":61496663},{"atb":[[1.03,7.49],[1.04,1]],"id":66596720},{"atl":[[960,2.02],[990,0.17]],"id":66596720},{"atb":[[1.01,22.47],[1.04,1]],"id":53987475},{"atl":[[970,0.88],[1000,0.17]],"id":53987475}],"con":true,"img":false}]}
{"op":"mcm","clk":"11540341555","pt":1719493264856,"mc":[{"id":"1.230178307","rc":[{"atb":[[1.04,0.25]],"id":47801105},{"atb":[[1.04,0.25]],"id":53893973},{"atb":[[1.04,0.25]],"id":47095746},{"atb":[[1.04,0.25]],"id":61496663},{"atb":[[1.04,0.25]],"id":66596720},{"atb":[[1.04,0.25]],"id":53987475}],"con":true,"img":false}]}
{"op":"mcm","clk":"11540341566","pt":1719493265062,"mc":[{"id":"1.230178307","rc":[{"atb":[[1.04,0]],"id":47801105},{"atb":[[1.04,0]],"id":53893973},{"atb":[[1.04,0]],"id":47095746},{"atb":[[1.04,0]],"id":61496663},{"atb":[[1.04,0]],"id":66596720},{"atb":[[1.04,0]],"id":53987475}],"con":true,"img":false}]}
{"op":"mcm","clk":"11540341577","pt":1719493265166,"mc":[{"id":"1.230178307","rc":[{"atb":[[1.2,0.25]],"id":47801105},{"atb":[[1.2,0.25]],"id":53893973},{"atb":[[1.2,0.25]],"id":47095746},{"atb":[[1.2,0.25]],"id":61496663},{"atb":[[1.2,0.25]],"id":66596720},{"atb":[[1.2,0.25]],"id":53987475}],"con":true,"img":false}]}
{"op":"mcm","clk":"11540373591","pt":1719493690386,"mc":[{"id":"1.230178307","rc":[{"spn":38.1,"spf":"NaN","id":47801105},{"spn":38.1,"spf":"NaN","id":53893973},{"atb":[[1.09,47.05]],"id":47095746},{"spn":38.1,"spf":"NaN","id":47095746},{"spn":38.1,"spf":"NaN","id":61496663},{"spn":38.1,"spf":"NaN","id":66596720},{"spn":38.1,"spf":"NaN","id":53987475}],"con":true,"img":false}]}
{"op":"mcm","clk":"11540373614","pt":1719493690696,"mc":[{"id":"1.230178307","rc":[{"atb":[[1.09,47.05]],"id":66596720}],"con":true,"img":false}]}
{"op":"mcm","clk":"11540373722","pt":1719493692353,"mc":[{"id":"1.230178307","marketDefinition":{"bspMarket":true,"turnInPlayEnabled":false,"persistenceEnabled":false,"marketBaseRate":5.0,"eventId":"33376062","eventTypeId":"4339","numberOfWinners":2,"bettingType":"ODDS","marketType":"PLACE","marketTime":"2024-06-27T13:36:00.000Z","suspendTime":"2024-06-27T13:36:00.000Z","bspReconciled":false,"complete":true,"inPlay":false,"crossMatching":true,"runnersVoidable":false,"numberOfActiveRunners":6,"betDelay":0,"status":"OPEN","runners":[{"status":"ACTIVE","sortPriority":1,"id":61496663,"name":"1. Glory Bomber"},{"status":"ACTIVE","sortPriority":2,"id":47801105,"name":"2. Lady Casey"},{"status":"ACTIVE","sortPriority":3,"id":47095746,"name":"3. Zipping Rush"},{"status":"ACTIVE","sortPriority":4,"id":53893973,"name":"4. Marinas Ollie"},{"status":"ACTIVE","sortPriority":5,"id":53987475,"name":"5. Brynoffa Alice"},{"status":"ACTIVE","sortPriority":6,"id":66596720,"name":"6. Ashville Bucko"}],"regulators":["MR_INT"],"venue":"Kinsley","countryCode":"GB","discountAllowed":true,"timezone":"Europe/London","openDate":"2024-06-27T13:36:00.000Z","version":5994643731,"name":"To Be Placed","eventName":"Kinsley 27th Jun"},"rc":[],"con":true,"img":false}]}
{"op":"mcm","clk":"11540378531","pt":1719493756568,"mc":[{"id":"1.230178307","rc":[{"atb":[[1.11,35.9]],"id":66596720}],"con":true,"img":false}]}
{"op":"mcm","clk":"11540378549","pt":1719493756738,"mc":[{"id":"1.230178307","rc":[{"atb":[[1.11,35.9]],"id":47095746}],"con":true,"img":false}]}
{"op":"mcm","clk":"11540379781","pt":1719493770378,"mc":[{"id":"1.230178307","rc":[{"atb":[[1.09,0]],"id":47095746},{"atb":[[1.09,0]],"id":66596720}],"con":true,"img":false}]}
{"op":"mcm","clk":"11540379843","pt":1719493771065,"mc":[{"id":"1.230178307","rc":[{"atb":[[1.13,32.57]],"id":47095746}],"con":true,"img":false}]}
{"op":"mcm","clk":"11540379870","pt":1719493771368,"mc":[{"id":"1.230178307","rc":[{"atb":[[1.13,32.57]],"id":66596720}],"con":true,"img":false}]}
{"op":"mcm","clk":"11540380432","pt":1719493777365,"mc":[{"id":"1.230178307","rc":[{"atb":[[1.11,0]],"id":47095746},{"atb":[[1.11,0]],"id":66596720}],"con":true,"img":false}]}
{"op":"mcm","clk":"11540380468","pt":1719493777773,"mc":[{"id":"1.230178307","rc":[{"atb":[[1.15,26.33]],"id":47095746}],"con":true,"img":false}]}
{"op":"mcm","clk":"11540380483","pt":1719493777981,"mc":[{"id":"1.230178307","rc":[{"atb":[[1.15,26.33]],"id":66596720}],"con":true,"img":false}]}
{"op":"mcm","clk":"11540383270","pt":1719493810620,"mc":[{"id":"1.230178307","rc":[{"atb":[[1.13,0]],"id":47095746}],"con":true,"img":false}]}
{"op":"mcm","clk":"11540383342","pt":1719493811439,"mc":[{"id":"1.230178307","rc":[{"atb":[[1.13,0]],"id":66596720}],"con":true,"img":false}]}
{"op":"mcm","clk":"11540383366","pt":1719493811712,"mc":[{"id":"1.230178307","rc":[{"atb":[[1.17,24.9]],"id":47095746}],"con":true,"img":false}]}
{"op":"mcm","clk":"11540383434","pt":1719493812533,"mc":[{"id":"1.230178307","rc":[{"atb":[[1.17,24.9]],"id":66596720}],"con":true,"img":false}]}
{"op":"mcm","clk":"11540384048","pt":1719493819846,"mc":[{"id":"1.230178307","rc":[{"atb":[[1.15,0]],"id":47095746},{"atb":[[1.15,0]],"id":66596720}],"con":true,"img":false}]}
{"op":"mcm","clk":"11540384095","pt":1719493820323,"mc":[{"id":"1.230178307","rc":[{"atb":[[1.19,20.79]],"id":47095746}],"con":true,"img":false}]}
{"op":"mcm","clk":"11540384134","pt":1719493820743,"mc":[{"id":"1.230178307","rc":[{"atb":[[1.19,20.79]],"id":66596720}],"con":true,"img":false}]}
{"op":"mcm","clk":"11540386766","pt":1719493851768,"mc":[{"id":"1.230178307","rc":[{"atb":[[1.17,0]],"id":47095746},{"atb":[[1.17,0]],"id":66596720}],"con":true,"img":false}]}
{"op":"mcm","clk":"11540386827","pt":1719493852487,"mc":[{"id":"1.230178307","rc":[{"atb":[[1.21,20.16]],"id":66596720}],"con":true,"img":false}]}
{"op":"mcm","clk":"11540386848","pt":1719493852764,"mc":[{"id":"1.230178307","rc":[{"atb":[[1.21,20.16]],"id":47095746}],"con":true,"img":false}]}
{"op":"mcm","clk":"11540387259","pt":1719493857664,"mc":[{"id":"1.230178307","rc":[{"atb":[[1.19,0]],"id":47095746},{"atb":[[1.19,0]],"id":66596720}],"con":true,"img":false}]}
{"op":"mcm","clk":"11540387311","pt":1719493858173,"mc":[{"id":"1.230178307","rc":[{"atb":[[1.23,17.17]],"id":66596720}],"con":true,"img":false}]}
{"op":"mcm","clk":"11540387330","pt":1719493858383,"mc":[{"id":"1.230178307","rc":[{"atb":[[1.23,17.17]],"id":47095746}],"con":true,"img":false}]}
{"op":"mcm","clk":"11540390194","pt":1719493893191,"mc":[{"id":"1.230178307","rc":[{"atb":[[1.21,0]],"id":47095746},{"spn":38.11,"spf":"NaN","id":47095746},{"atb":[[1.21,0]],"id":66596720},{"spn":38.11,"spf":"NaN","id":66596720}],"con":true,"img":false}]}
{"op":"mcm","clk":"11540390253","pt":1719493893907,"mc":[{"id":"1.230178307","rc":[{"atb":[[1.25,16.93]],"id":47095746},{"atb":[[1.25,16.93]],"id":66596720}],"con":true,"img":false}]}
{"op":"mcm","clk":"11540390672","pt":1719493900425,"mc":[{"id":"1.230178307","rc":[{"atb":[[1.23,0]],"id":47095746},{"atb":[[1.23,0]],"id":66596720}],"con":true,"img":false}]}
{"op":"mcm","clk":"11540390706","pt":1719493900995,"mc":[{"id":"1.230178307","rc":[{"atb":[[1.27,14.63]],"id":47095746},{"atb":[[1.27,14.63]],"id":66596720}],"con":true,"img":false}]}
{"op":"mcm","clk":"11540393344","pt":1719493937468,"mc":[{"id":"1.230178307","rc":[{"atb":[[1.25,0]],"id":66596720}],"con":true,"img":false}]}
{"op":"mcm","clk":"11540393351","pt":1719493937560,"mc":[{"id":"1.230178307","rc":[{"atb":[[1.25,0]],"id":47095746}],"con":true,"img":false}]}
{"op":"mcm","clk":"11540393397","pt":1719493938132,"mc":[{"id":"1.230178307","rc":[{"atb":[[1.29,14.6]],"id":66596720}],"con":true,"img":false}]}
{"op":"mcm","clk":"11540393420","pt":1719493938441,"mc":[{"id":"1.230178307","rc":[{"atb":[[1.29,14.6]],"id":47095746}],"con":true,"img":false}]}
{"op":"mcm","clk":"11540394942","pt":1719493957961,"mc":[{"id":"1.230178307","rc":[{"atb":[[1.27,0]],"id":47095746},{"spn":38.14,"spf":"NaN","id":47095746},{"atb":[[1.27,0]],"id":66596720},{"spn":38.14,"spf":"NaN","id":66596720}],"con":true,"img":false}]}
{"op":"mcm","clk":"11540394984","pt":1719493958378,"mc":[{"id":"1.230178307","rc":[{"atb":[[1.31,12.74]],"id":47095746}],"con":true,"img":false}]}
{"op":"mcm","clk":"11540394996","pt":1719493958487,"mc":[{"id":"1.230178307","rc":[{"atb":[[1.31,12.74]],"id":66596720}],"con":true,"img":false}]}
{"op":"mcm","clk":"11540396332","pt":1719493975902,"mc":[{"id":"1.230178307","rc":[{"atb":[[1.29,0]],"id":47095746},{"atb":[[1.29,0]],"id":66596720}],"con":true,"img":false}]}
{"op":"mcm","clk":"11540396377","pt":1719493976477,"mc":[{"id":"1.230178307","rc":[{"atb":[[1.33,12.83]],"id":47095746},{"atb":[[1.33,12.83]],"id":66596720}],"con":true,"img":false}]}
{"op":"mcm","clk":"11540396638","pt":1719493980321,"mc":[{"id":"1.230178307","rc":[{"atb":[[1.31,0]],"id":47095746}],"con":true,"img":false}]}
{"op":"mcm","clk":"11540396655","pt":1719493980484,"mc":[{"id":"1.230178307","rc":[{"atb":[[1.31,0]],"id":66596720}],"con":true,"img":false}]}
{"op":"mcm","clk":"11540396700","pt":1719493981104,"mc":[{"id":"1.230178307","rc":[{"atb":[[1.35,11.29]],"id":66596720}],"con":true,"img":false}]}
{"op":"mcm","clk":"11540396716","pt":1719493981310,"mc":[{"id":"1.230178307","rc":[{"atb":[[1.35,11.29]],"id":47095746}],"con":true,"img":false}]}
{"op":"mcm","clk":"11540400634","pt":1719494029628,"mc":[{"id":"1.230178307","rc":[{"spn":38.17,"spf":"NaN","id":47095746},{"atb":[[1.33,0]],"id":66596720},{"spn":38.17,"spf":"NaN","id":66596720}],"con":true,"img":false}]}
{"op":"mcm","clk":"11540400681","pt":1719494030251,"mc":[{"id":"1.230178307","rc":[{"atb":[[1.33,0]],"id":47095746}],"con":true,"img":false}]}
{"op":"mcm","clk":"11540400719","pt":1719494030666,"mc":[{"id":"1.230178307","rc":[{"atb":[[1.37,11.44]],"id":66596720}],"con":true,"img":false}]}
{"op":"mcm","clk":"11540400727","pt":1719494030762,"mc":[{"id":"1.230178307","rc":[{"atb":[[1.37,11.44]],"id":47095746}],"con":true,"img":false}]}
{"op":"mcm","clk":"11540402958","pt":1719494057169,"mc":[{"id":"1.230178307","rc":[{"atb":[[1.35,0]],"id":47095746}],"con":true,"img":false}]}
{"op":"mcm","clk":"11540402978","pt":1719494057481,"mc":[{"id":"1.230178307","rc":[{"atb":[[1.35,0]],"id":66596720}],"con":true,"img":false}]}
{"op":"mcm","clk":"11540402993","pt":1719494057687,"mc":[{"id":"1.230178307","rc":[{"atb":[[1.39,10.12]],"id":47095746}],"con":true,"img":false}]}
{"op":"mcm","clk":"11540403013","pt":1719494057992,"mc":[{"id":"1.230178307","rc":[{"atb":[[1.39,10.12]],"id":66596720}],"con":true,"img":false}]}
{"op":"mcm","clk":"11540406563","pt":1719494108767,"mc":[{"id":"1.230178307","rc":[{"spn":38.19,"spf":"NaN","id":47095746},{"atb":[[1.37,0]],"id":66596720},{"spn":38.19,"spf":"NaN","id":66596720}],"con":true,"img":false}]}
{"op":"mcm","clk":"11540406581","pt":1719494108926,"mc":[{"id":"1.230178307","rc":[{"atb":[[1.37,0]],"id":47095746}],"con":true,"img":false}]}
{"op":"mcm","clk":"11540406646","pt":1719494109956,"mc":[{"id":"1.230178307","rc":[{"atb":[[1.41,10.33]],"id":47095746}],"con":true,"img":false}]}
{"op":"mcm","clk":"11540406661","pt":1719494110214,"mc":[{"id":"1.230178307","rc":[{"atb":[[1.41,10.33]],"id":66596720}],"con":true,"img":false}]}
{"op":"mcm","clk":"11540407202","pt":1719494119533,"mc":[{"id":"1.230178307","rc":[{"atb":[[1.39,0]],"id":66596720}],"con":true,"img":false}]}
{"op":"mcm","clk":"11540407263","pt":1719494120565,"mc":[{"id":"1.230178307","rc":[{"atb":[[1.39,0]],"id":47095746}],"con":true,"img":false}]}
{"op":"mcm","clk":"11540407308","pt":1719494121344,"mc":[{"id":"1.230178307","rc":[{"atb":[[1.43,9.18]],"id":66596720}],"con":true,"img":false}]}
{"op":"mcm","clk":"11540407356","pt":1719494122169,"mc":[{"id":"1.230178307","rc":[{"atb":[[1.43,9.18]],"id":47095746}],"con":true,"img":false}]}
{"op":"mcm","clk":"11540409101","pt":1719494150898,"mc":[{"id":"1.230178307","rc":[{"atb":[[1.41,0]],"id":47095746}],"con":true,"img":false}]}
{"op":"mcm","clk":"11540409146","pt":1719494151583,"mc":[{"id":"1.230178307","rc":[{"atb":[[1.41,0]],"id":66596720}],"con":true,"img":false}]}
{"op":"mcm","clk":"11540409176","pt":1719494152104,"mc":[{"id":"1.230178307","rc":[{"atb":[[1.45,9.4]],"id":47095746}],"con":true,"img":false}]}
{"op":"mcm","clk":"11540409234","pt":1719494152786,"mc":[{"id":"1.230178307","rc":[{"atb":[[1.45,9.4]],"id":66596720}],"con":true,"img":false}]}
{"op":"mcm","clk":"11540409604","pt":1719494158318,"mc":[{"id":"1.230178307","rc":[{"atb":[[1.43,0]],"id":47095746}],"con":true,"img":false}]}
{"op":"mcm","clk":"11540409623","pt":1719494158586,"mc":[{"id":"1.230178307","rc":[{"atb":[[1.43,0]],"id":66596720}],"con":true,"img":false}]}
{"op":"mcm","clk":"11540409690","pt":1719494159521,"mc":[{"id":"1.230178307","rc":[{"atb":[[1.47,8.4]],"id":66596720}],"con":true,"img":false}]}
{"op":"mcm","clk":"11540409701","pt":1719494159724,"mc":[{"id":"1.230178307","rc":[{"atb":[[1.47,8.4]],"id":47095746}],"con":true,"img":false}]}
{"op":"mcm","clk":"11540409849","pt":1719494161905,"mc":[{"id":"1.230178307","rc":[{"atb":[[1.48,2.11]],"id":47095746},{"atb":[[1.48,2.11]],"id":66596720}],"con":true,"img":false}]}
{"op":"mcm","clk":"11540410825","pt":1719494177725,"mc":[{"id":"1.230178307","rc":[{"atb":[[1.47,0]],"id":47095746},{"spn":38.24,"spf":"NaN","id":47095746},{"spn":38.24,"spf":"NaN","id":66596720}],"con":true,"img":false}]}
{"op":"mcm","clk":"11540410834","pt":1719494177932,"mc":[{"id":"1.230178307","rc":[{"atb":[[1.47,0]],"id":66596720}],"con":true,"img":false}]}
{"op":"mcm","clk":"11540410849","pt":1719494178093,"mc":[{"id":"1.230178307","rc":[{"atb":[[1.5,7.9]],"id":47095746}],"con":true,"img":false}]}
{"op":"mcm","clk":"11540410861","pt":1719494178302,"mc":[{"id":"1.230178307","rc":[{"atb":[[1.5,7.9]],"id":66596720}],"con":true,"img":false}]}
{"op":"mcm","clk":"11540411803","pt":1719494191532,"mc":[{"id":"1.230178307","rc":[{"atb":[[1.45,0]],"id":47095746}],"con":true,"img":false}]}
{"op":"mcm","clk":"11540411828","pt":1719494191845,"mc":[{"id":"1.230178307","rc":[{"atb":[[1.45,0]],"id":66596720}],"con":true,"img":false}]}
{"op":"mcm","clk":"11540411884","pt":1719494192630,"mc":[{"id":"1.230178307","rc":[{"atb":[[1.52,8.14]],"id":66596720}],"con":true,"img":false}]}
{"op":"mcm","clk":"11540411892","pt":1719494192733,"mc":[{"id":"1.230178307","rc":[{"atb":[[1.52,8.14]],"id":47095746}],"con":true,"img":false}]}
{"op":"mcm","clk":"11540412342","pt":1719494199323,"mc":[{"id":"1.230178307","rc":[{"atb":[[1.5,0]],"id":66596720}],"con":true,"img":false}]}
{"op":"mcm","clk":"11540412362","pt":1719494199635,"mc":[{"id":"1.230178307","rc":[{"atb":[[1.5,0]],"id":47095746}],"con":true,"img":false}]}
{"op":"mcm","clk":"11540412407","pt":1719494200321,"mc":[{"id":"1.230178307","rc":[{"atb":[[1.54,7.31]],"id":47095746}],"con":true,"img":false}]}
{"op":"mcm","clk":"11540412452","pt":1719494200940,"mc":[{"id":"1.230178307","rc":[{"atb":[[1.54,7.31]],"id":66596720}],"con":true,"img":false}]}
{"op":"mcm","clk":"11540414600","pt":1719494232382,"mc":[{"id":"1.230178307","rc":[{"atb":[[1.52,0]],"id":47095746}],"con":true,"img":false}]}
{"op":"mcm","clk":"11540414619","pt":1719494232641,"mc":[{"id":"1.230178307","rc":[{"atb":[[1.52,0]],"id":66596720}],"con":true,"img":false}]}
{"op":"mcm","clk":"11540414662","pt":1719494233264,"mc":[{"id":"1.230178307","rc":[{"atb":[[1.56,7.56]],"id":47095746}],"con":true,"img":false}]}
{"op":"mcm","clk":"11540414703","pt":1719494233783,"mc":[{"id":"1.230178307","rc":[{"atb":[[1.56,7.56]],"id":66596720}],"con":true,"img":false}]}
{"op":"mcm","clk":"11540415080","pt":1719494238855,"mc":[{"id":"1.230178307","rc":[{"atb":[[1.54,0]],"id":47095746},{"spn":38.28,"spf":"NaN","id":47095746},{"spn":38.28,"spf":"NaN","id":66596720}],"con":true,"img":false}]}
{"op":"mcm","clk":"11540415113","pt":1719494239275,"mc":[{"id":"1.230178307","rc":[{"atb":[[1.58,6.81]],"id":47095746}],"con":true,"img":false}]}
{"op":"mcm","clk":"11540415172","pt":1719494239889,"mc":[{"id":"1.230178307","rc":[{"atb":[[1.54,0]],"id":66596720}],"con":true,"img":false}]}
{"op":"mcm","clk":"11540415206","pt":1719494240355,"mc":[{"id":"1.230178307","rc":[{"atb":[[1.58,6.81]],"id":66596720}],"con":true,"img":false}]}
{"op":"mcm","clk":"11540417101","pt":1719494268194,"mc":[{"id":"1.230178307","rc":[{"atb":[[1.56,0]],"id":47095746}],"con":true,"img":false}]}
{"op":"mcm","clk":"11540417132","pt":1719494268607,"mc":[{"id":"1.230178307","rc":[{"atb":[[1.56,0]],"id":66596720}],"con":true,"img":false}]}
{"op":"mcm","clk":"11540417210","pt":1719494269894,"mc":[{"id":"1.230178307","rc":[{"atb":[[1.6,7.05]],"id":47095746}],"con":true,"img":false}]}
{"op":"mcm","clk":"11540417239","pt":1719494270413,"mc":[{"id":"1.230178307","rc":[{"atb":[[1.6,7.05]],"id":66596720}],"con":true,"img":false}]}
{"op":"mcm","clk":"11540417729","pt":1719494276797,"mc":[{"id":"1.230178307","rc":[{"atb":[[1.58,0]],"id":47095746}],"con":true,"img":false}]}
{"op":"mcm","clk":"11540417807","pt":1719494277878,"mc":[{"id":"1.230178307","rc":[{"atb":[[1.58,0]],"id":66596720}],"con":true,"img":false}]}
{"op":"mcm","clk":"11540417864","pt":1719494278602,"mc":[{"id":"1.230178307","rc":[{"atb":[[1.62,6.36]],"id":66596720}],"con":true,"img":false}]}
{"op":"mcm","clk":"11540417896","pt":1719494279014,"mc":[{"id":"1.230178307","rc":[{"atb":[[1.62,6.36]],"id":47095746}],"con":true,"img":false}]}
{"op":"mcm","clk":"11540420745","pt":1719494312869,"mc":[{"id":"1.230178307","rc":[{"atb":[[1.6,0]],"id":47095746},{"spn":38.31,"spf":"NaN","id":47095746},{"spn":38.31,"spf":"NaN","id":66596720}],"con":true,"img":false}]}
{"op":"mcm","clk":"11540420823","pt":1719494313762,"mc":[{"id":"1.230178307","rc":[{"atb":[[1.64,6.61]],"id":47095746}],"con":true,"img":false}]}
{"op":"mcm","clk":"11540423798","pt":1719494347993,"mc":[{"id":"1.230178307","rc":[{"atb":[[1.62,0]],"id":47095746}],"con":true,"img":false}]}
{"op":"mcm","clk":"11540423834","pt":1719494348389,"mc":[{"id":"1.230178307","rc":[{"atb":[[1.66,5.98]],"id":47095746}],"con":true,"img":false}]}
{"op":"mcm","clk":"11540427882","pt":1719494395732,"mc":[{"id":"1.230178307","rc":[{"atb":[[1.64,0]],"id":47095746},{"spn":38.33,"spf":"NaN","id":47095746}],"con":true,"img":false}]}
{"op":"mcm","clk":"11540427927","pt":1719494396353,"mc":[{"id":"1.230178307","rc":[{"atb":[[1.68,6.22]],"id":47095746}],"con":true,"img":false}]}
{"op":"mcm","clk":"11540429750","pt":1719494415868,"mc":[{"id":"1.230178307","rc":[{"atb":[[1.66,0]],"id":47095746}],"con":true,"img":false}]}
{"op":"mcm","clk":"11540429764","pt":1719494416083,"mc":[{"id":"1.230178307","rc":[{"atb":[[1.7,5.64]],"id":47095746}],"con":true,"img":false}]}
{"op":"mcm","clk":"11540432007","pt":1719494440214,"mc":[{"id":"1.230178307","rc":[{"atb":[[1.68,0]],"id":47095746}],"con":true,"img":false}]}
{"op":"mcm","clk":"11540432200","pt":1719494442302,"mc":[{"id":"1.230178307","rc":[{"atb":[[1.72,5.87]],"id":47095746}],"con":true,"img":false}]}
{"op":"mcm","clk":"11540433550","pt":1719494457431,"mc":[{"id":"1.230178307","rc":[{"atb":[[1.7,0]],"id":47095746},{"spn":38.36,"spf":"NaN","id":47095746}],"con":true,"img":false}]}
{"op":"mcm","clk":"11540433562","pt":1719494457632,"mc":[{"id":"1.230178307","rc":[{"atb":[[1.09,43.89]],"id":47801105}],"con":true,"img":false}]}
{"op":"mcm","clk":"11540433599","pt":1719494458040,"mc":[{"id":"1.230178307","rc":[{"atb":[[1.74,5.34]],"id":47095746}],"con":true,"img":false}]}
{"op":"mcm","clk":"11540433797","pt":1719494460226,"mc":[{"id":"1.230178307","rc":[{"atb":[[1.93,1]],"id":47801105},{"atl":[[6.2,1]],"id":47801105},{"atb":[[1.93,1],[1.75,5.34]],"id":47095746},{"atl":[[5,1],[20,2]],"id":47095746},{"atb":[[1.86,1],[1.49,2.48]],"id":61496663},{"atl":[[14,2],[4.7,1]],"id":61496663},{"atb":[[1.86,1]],"id":53987475},{"atl":[[5.5,1]],"id":53987475}],"con":true,"img":false}]}
{"op":"mcm","clk":"11540433805","pt":1719494460320,"mc":[{"id":"1.230178307","rc":[{"atb":[[1.72,2.48]],"id":47801105},{"atl":[[28,2]],"id":47801105},{"atb":[[1.07,9.34]],"id":53893973},{"atl":[[5.7,2]],"id":53893973},{"atb":[[1.84,6.37],[2.46,1]],"id":66596720},{"atl":[[7.6,1],[48,2]],"id":66596720},{"atb":[[1.56,2.48]],"id":53987475},{"atl":[[16,2]],"id":53987475}],"con":true,"img":false}]}
{"op":"mcm","clk":"11540433815","pt":1719494460425,"mc":[{"id":"1.230178307","rc":[{"atb":[[1.35,1]],"id":53893973},{"atl":[[3.3,1]],"id":53893973}],"con":true,"img":false}]}
{"op":"mcm","clk":"11540434042","pt":1719494462823,"mc":[{"id":"1.230178307","rc":[{"atb":[[2.46,0],[2.44,1]],"id":66596720}],"con":true,"img":false}]}
{"op":"mcm","clk":"11540434181","pt":1719494464432,"mc":[{"id":"1.230178307","rc":[{"atb":[[2.44,0],[2.66,1]],"id":66596720}],"con":true,"img":false}]}
{"op":"mcm","clk":"11540434231","pt":1719494464852,"mc":[{"id":"1.230178307","rc":[{"atb":[[2.48,1]],"id":47801105},{"atb":[[1.37,1]],"id":53893973},{"atb":[[2.94,1]],"id":66596720},{"atb":[[1.87,1]],"id":53987475}],"con":true,"img":false}]}
{"op":"mcm","clk":"11540434242","pt":1719494464955,"mc":[{"id":"1.230178307","rc":[{"atb":[[1.93,0]],"id":47801105},{"atb":[[1.35,0]],"id":53893973},{"atb":[[1.86,0],[1.87,1]],"id":61496663},{"atb":[[2.66,0]],"id":66596720},{"atb":[[1.86,0]],"id":53987475}],"con":true,"img":false}]}
{"op":"mcm","clk":"11540434254","pt":1719494465057,"mc":[{"id":"1.230178307","rc":[{"atl":[[3,1],[3.3,0]],"id":53893973},{"atl":[[4.8,1],[5,0]],"id":47095746},{"atl":[[4.6,1],[4.7,0]],"id":61496663},{"atl":[[5.5,0],[4.4,1]],"id":53987475}],"con":true,"img":false}]}
{"op":"mcm","clk":"11540434391","pt":1719494466445,"mc":[{"id":"1.230178307","rc":[{"atb":[[1.01,24.18]],"id":47801105},{"atl":[[1000,1.88]],"id":47801105},{"atb":[[1.01,1.7]],"id":47095746},{"atl":[[1000,1.88]],"id":47095746},{"atb":[[1.01,1.7]],"id":61496663},{"atl":[[1000,1.7]],"id":61496663}],"con":true,"img":false}]}
{"op":"mcm","clk":"11540434402","pt":1719494466548,"mc":[{"id":"1.230178307","rc":[{"atb":[[1.01,22.91]],"id":47801105},{"atl":[[1000,0.19]],"id":47801105},{"atb":[[1.01,0.41]],"id":47095746},{"atl":[[1000,0.19]],"id":47095746},{"atl":[[1000,0.02]],"id":61496663}],"con":true,"img":false}]}
{"op":"mcm","clk":"11540434413","pt":1719494466614,"mc":[{"id":"1.230178307","rc":[{"atb":[[1.01,0.63]],"id":61496663}],"con":true,"img":false}]}
{"op":"mcm","clk":"11540434423","pt":1719494466717,"mc":[{"id":"1.230178307","rc":[{"atb":[[1.01,22.47]],"id":47801105},{"atl":[[1000,0.17]],"id":47801105},{"atb":[[1.01,0]],"id":47095746},{"atl":[[1000,0.17]],"id":47095746},{"atl":[[1000,0]],"id":61496663}],"con":true,"img":false}]}
{"op":"mcm","clk":"11540434430","pt":1719494466817,"mc":[{"id":"1.230178307","rc":[{"atb":[[1.73,0.43]],"id":47801105},{"atl":[[27,0.01]],"id":47801105},{"atb":[[1.76,0.41]],"id":47095746},{"atl":[[19.5,0.01]],"id":47095746},{"atb":[[1.01,0]],"id":61496663},{"atl":[[13.5,0.02]],"id":61496663}],"con":true,"img":false}]}
{"op":"mcm","clk":"11540434440","pt":1719494466930,"mc":[{"id":"1.230178307","rc":[{"atb":[[1.5,0.63]],"id":61496663}],"con":true,"img":false}]}
{"op":"mcm","clk":"11540434746","pt":1719494470338,"mc":[{"id":"1.230178307","rc":[{"atb":[[1.49,0],[1.61,2]],"id":61496663}],"con":true,"img":false}]}
{"op":"mcm","clk":"11540434754","pt":1719494470431,"mc":[{"id":"1.230178307","rc":[{"atb":[[1.82,2]],"id":47801105},{"atb":[[1.84,0],[1.96,6.37]],"id":66596720},{"atb":[[1.56,0],[1.64,2.48]],"id":53987475}],"con":true,"img":false}]}
{"op":"mcm","clk":"11540434767","pt":1719494470534,"mc":[{"id":"1.230178307","rc":[{"atb":[[1.72,0]],"id":47801105}],"con":true,"img":false}]}
{"op":"mcm","clk":"11540435253","pt":1719494476234,"mc":[{"id":"1.230178307","rc":[{"atb":[[1.74,0]],"id":47095746},{"atb":[[1.62,0]],"id":66596720}],"con":true,"img":false}]}
{"op":"mcm","clk":"11540435274","pt":1719494476441,"mc":[{"id":"1.230178307","rc":[{"atb":[[1.77,5.12]],"id":47095746}],"con":true,"img":false}]}
{"op":"mcm","clk":"11540435280","pt":1719494476544,"mc":[{"id":"1.230178307","rc":[{"atb":[[1.78,5.13]],"id":47095746}],"con":true,"img":false}]}
{"op":"mcm","clk":"11540435286","pt":1719494476647,"mc":[{"id":"1.230178307","rc":[{"atb":[[1.75,0]],"id":47095746}],"con":true,"img":false}]}
{"op":"mcm","clk":"11540435609","pt":1719494480341,"mc":[{"id":"1.230178307","rc":[{"atb":[[2.4,1],[2.48,0]],"id":47801105},{"atl":[[6.2,0],[6.6,1]],"id":47801105},{"atb":[[1.44,1],[1.37,0]],"id":53893973},{"atl":[[3,0],[3.05,1]],"id":53893973},{"atb":[[1.46,3.75],[1.92,1]],"id":47095746},{"atl":[[4.8,0],[4.9,1]],"id":47095746},{"atb":[[1.88,1],[1.87,0]],"id":61496663},{"atl":[[4.6,0],[4.7,1]],"id":61496663},{"atb":[[2.94,0],[2.7,1]],"id":66596720},{"atl":[[8.2,1],[7.6,0]],"id":66596720},{"atb":[[1.88,1],[1.87,0]],"id":53987475},{"atl":[[4.6,1],[4.4,0]],"id":53987475}],"con":true,"img":false}]}
{"op":"mcm","clk":"11540435620","pt":1719494480446,"mc":[{"id":"1.230178307","rc":[{"atb":[[1.2,9.59],[1.07,2.48]],"id":53893973},{"atb":[[1.93,0]],"id":47095746}],"con":true,"img":false}]}
{"op":"mcm","clk":"11540435630","pt":1719494480550,"mc":[{"id":"1.230178307","rc":[{"atl":[[4.9,0]],"id":47095746},{"atl":[[4.7,0]],"id":61496663},{"atl":[[7.4,1]],"id":66596720},{"atl":[[4.5,1],[4.6,0]],"id":53987475}],"con":true,"img":false}]}
{"op":"mcm","clk":"11540435637","pt":1719494480652,"mc":[{"id":"1.230178307","rc":[{"atl":[[6.2,1],[6.6,0]],"id":47801105},{"atl":[[4.7,1]],"id":47095746},{"atl":[[4.5,1]],"id":61496663},{"atl":[[8.2,0]],"id":66596720}],"con":true,"img":false}]}
{"op":"mcm","clk":"11540435663","pt":1719494481063,"mc":[{"id":"1.230178307","rc":[{"atb":[[1.6,0]],"id":66596720}],"con":true,"img":false}]}
{"op":"mcm","clk":"11540435694","pt":1719494481430,"mc":[{"id":"1.230178307","rc":[{"atb":[[1.46,0]],"id":47095746}],"con":true,"img":false}]}
{"op":"mcm","clk":"11540436048","pt":1719494485530,"mc":[{"id":"1.230178307","rc":[{"atb":[[1.2,0.25],[1.08,10.59]],"id":53893973}],"con":true,"img":false}]}
{"op":"mcm","clk":"11540438181","pt":1719494509584,"mc":[{"id":"1.230178307","rc":[{"atb":[[1.73,0]],"id":47801105},{"atl":[[27,0]],"id":47801105},{"atb":[[1.76,0]],"id":47095746},{"atl":[[19.5,0]],"id":47095746},{"atb":[[1.5,0]],"id":61496663},{"atl":[[13.5,0]],"id":61496663}],"con":true,"img":false}]}
{"op":"mcm","clk":"11540438314","pt":1719494511189,"mc":[{"id":"1.230178307","rc":[{"atb":[[1.02,2]],"id":61496663}],"con":true,"img":false}]}
{"op":"mcm","clk":"11540438343","pt":1719494511499,"mc":[{"id":"1.230178307","rc":[{"atb":[[1.02,2]],"id":47801105}],"con":true,"img":false}]}
{"op":"mcm","clk":"11540438379","pt":1719494511772,"mc":[{"id":"1.230178307","rc":[{"atb":[[1.79,2]],"id":47095746}],"con":true,"img":false}]}
{"op":"mcm","clk":"11540438400","pt":1719494511973,"mc":[{"id":"1.230178307","rc":[{"atb":[[1.09,2]],"id":53893973}],"con":true,"img":false}]}
{"op":"mcm","clk":"11540438418","pt":1719494512182,"mc":[{"id":"1.230178307","rc":[{"atb":[[1.02,2]],"id":53987475}],"con":true,"img":false}]}
{"op":"mcm","clk":"11540438430","pt":1719494512385,"mc":[{"id":"1.230178307","rc":[{"atb":[[1.02,2]],"id":66596720}],"con":true,"img":false}]}
{"op":"mcm","clk":"11540440761","pt":1719494540987,"mc":[{"id":"1.230178307","rc":[{"atb":[[1.09,0]],"id":47801105},{"spn":4.3,"spf":"NaN","id":47801105},{"spn":2.24,"spf":"NaN","id":53893973},{"spn":3.31,"spf":"NaN","id":47095746},{"spn":3.19,"spf":"NaN","id":61496663},{"spn":5.05,"spf":"NaN","id":66596720},{"spn":3.19,"spf":"NaN","id":53987475}],"con":true,"img":false}]}
{"op":"mcm","clk":"11540441898","pt":1719494554112,"mc":[{"id":"1.230178307","rc":[{"atb":[[1.72,0]],"id":47095746}],"con":true,"img":false}]}
{"op":"mcm","clk":"11540442621","pt":1719494562343,"mc":[{"id":"1.230178307","rc":[{"atb":[[1.77,0]],"id":47095746}],"con":true,"img":false}]}
{"op":"mcm","clk":"11540442839","pt":1719494564835,"mc":[{"id":"1.230178307","rc":[{"atb":[[1.79,0]],"id":47095746}],"con":true,"img":false}]}
{"op":"mcm","clk":"11540442848","pt":1719494564935,"mc":[{"id":"1.230178307","rc":[{"atb":[[1.02,2]],"id":47095746}],"con":true,"img":false}]}
{"op":"mcm","clk":"11540442861","pt":1719494565039,"mc":[{"id":"1.230178307","rc":[{"atb":[[1.72,6.13],[1.78,0]],"id":47095746}],"con":true,"img":false}]}
{"op":"mcm","clk":"11540443027","pt":1719494566950,"mc":[{"id":"1.230178307","rc":[{"atb":[[1.73,2.5]],"id":47095746}],"con":true,"img":false}]}
{"op":"mcm","clk":"11540443063","pt":1719494567466,"mc":[{"id":"1.230178307","rc":[{"atb":[[1.73,0]],"id":47095746}],"con":true,"img":false}]}
{"op":"mcm","clk":"11540444610","pt":1719494584662,"mc":[{"id":"1.230178307","rc":[{"atl":[[1000,1.88]],"id":47801105},{"atl":[[1000,1.88]],"id":47095746},{"atl":[[1000,1.7]],"id":61496663}],"con":true,"img":false}]}
{"op":"mcm","clk":"11540444619","pt":1719494584759,"mc":[{"id":"1.230178307","rc":[{"atb":[[1.01,24.18]],"id":47801105},{"atb":[[1.01,1.7]],"id":47095746},{"atb":[[1.01,1.7]],"id":61496663}],"con":true,"img":false}]}
{"op":"mcm","clk":"11540444628","pt":1719494584863,"mc":[{"id":"1.230178307","rc":[{"atl":[[1000,0.18]],"id":47801105},{"atl":[[1000,0.19]],"id":47095746},{"atl":[[1000,0.02]],"id":61496663}],"con":true,"img":false}]}
{"op":"mcm","clk":"11540444638","pt":1719494584969,"mc":[{"id":"1.230178307","rc":[{"atb":[[1.01,22.84]],"id":47801105},{"atb":[[1.01,0.42]],"id":47095746},{"atb":[[1.01,0.49]],"id":61496663}],"con":true,"img":false}]}
{"op":"mcm","clk":"11540444646","pt":1719494585070,"mc":[{"id":"1.230178307","rc":[{"atl":[[1000,0.17]],"id":47801105},{"atl":[[1000,0.17]],"id":47095746},{"atl":[[1000,0]],"id":61496663}],"con":true,"img":false}]}
{"op":"mcm","clk":"11540444656","pt":1719494585173,"mc":[{"id":"1.230178307","rc":[{"atb":[[1.01,22.47]],"id":47801105},{"atl":[[27,0.01]],"id":47801105},{"atb":[[1.01,0]],"id":47095746},{"atl":[[19.5,0.01]],"id":47095746},{"atb":[[1.01,0]],"id":61496663},{"atl":[[13.5,0.02]],"id":61496663}],"con":true,"img":false}]}
{"op":"mcm","clk":"11540444664","pt":1719494585278,"mc":[{"id":"1.230178307","rc":[{"atb":[[1.83,0.36]],"id":47801105},{"atb":[[1.73,0.42]],"id":47095746},{"atb":[[1.62,0.49]],"id":61496663}],"con":true,"img":false}]}
{"op":"mcm","clk":"11540445137","pt":1719494590933,"mc":[{"id":"1.230178307","rc":[{"atb":[[1.03,2.5]],"id":47801105}],"con":true,"img":false}]}
{"op":"mcm","clk":"11540445147","pt":1719494591038,"mc":[{"id":"1.230178307","rc":[{"atb":[[1.03,0]],"id":47801105}],"con":true,"img":false}]}
{"op":"mcm","clk":"11540448515","pt":1719494628104,"mc":[{"id":"1.230178307","rc":[{"atb":[[1.83,0]],"id":47801105},{"atl":[[27,0]],"id":47801105},{"atb":[[1.73,0]],"id":47095746},{"atl":[[19.5,0]],"id":47095746},{"atb":[[1.62,0]],"id":61496663},{"atl":[[13.5,0]],"id":61496663}],"con":true,"img":false}]}
{"op":"mcm","clk":"11540450539","pt":1719494652680,"mc":[{"id":"1.230178307","rc":[{"atb":[[2.4,2.5],[1.87,2]],"id":47801105},{"atl":[[6,1.5]],"id":47801105},{"atb":[[1.44,2.5],[1.45,10],[1.49,5],[1.53,2.5]],"id":53893973},{"atl":[[4.3,10],[3.95,5],[3,1.5],[4.4,2],[3.75,2.5]],"id":53893973},{"atb":[[1.62,7.13],[1.93,2.25]],"id":47095746},{"atl":[[5.3,1],[4.7,3.25]],"id":47095746},{"atb":[[1.89,1.5],[2.42,2.5],[2.26,10],[1.53,3],[1.61,0],[2.34,5]],"id":61496663},{"atl":[[6.2,5],[4.4,1.5],[5.7,2.5],[7,10]],"id":61496663},{"atb":[[1.96,0],[2.18,5],[2.26,2.5],[2.1,10],[1.71,7.37]],"id":66596720},{"atl":[[7.2,2.25],[6.2,10],[5.3,2.5],[48,0],[24,2],[5.7,5]],"id":66596720},{"atb":[[1.64,0]],"id":53987475},{"atl":[[16,0],[4.5,0]],"id":53987475}],"con":true,"img":false}]}
{"op":"mcm","clk":"11540450554","pt":1719494652734,"mc":[{"id":"1.230178307","rc":[{"atb":[[1.82,0],[2.5,2.5],[2.42,5],[2.34,10]],"id":47801105},{"atl":[[6.2,3.5],[22,2],[28,0],[7,5],[7.8,10]],"id":47801105},{"atb":[[1.38,2]],"id":53893973},{"atl":[[5.7,0]],"id":53893973},{"atb":[[1.72,0],[2.54,5],[2.46,10],[2.62,2.5]],"id":47095746},{"atl":[[6.8,2.5],[7.6,5],[8.4,10],[4.7,2.25]],"id":47095746},{"atl":[[6.2,7],[14,0]],"id":61496663},{"atb":[[2.36,5],[1.89,1.5],[1.57,3.48],[2.28,10],[2.44,2.5]],"id":53987475},{"atl":[[4.5,1.5],[19,3],[6.2,5],[5.7,2.5],[7,10],[4.7,1]],"id":53987475}],"con":true,"img":false}]}
{"op":"mcm","clk":"11540450560","pt":1719494652840,"mc":[{"id":"1.230178307","rc":[{"atb":[[1.08,0]],"id":53893973},{"atl":[[6.6,5],[4.7,0]],"id":47095746}],"con":true,"img":false}]}
{"op":"mcm","clk":"11540450570","pt":1719494652946,"mc":[{"id":"1.230178307","rc":[{"atl":[[20,0]],"id":47095746},{"atl":[[4.5,0]],"id":53987475}],"con":true,"img":false}]}
{"op":"mcm","clk":"11540450582","pt":1719494653058,"mc":[{"id":"1.230178307","rc":[{"atl":[[6.4,5.62],[4.6,0.84]],"id":47095746},{"atl":[[5.2,0.84]],"id":66596720},{"atl":[[5.6,3.75]],"id":53987475}],"con":true,"img":false}]}
{"op":"mcm","clk":"11540450631","pt":1719494653521,"mc":[{"id":"1.230178307","rc":[{"atl":[[4.6,0]],"id":47095746}],"con":true,"img":false}]}
{"op":"mcm","clk":"11540450705","pt":1719494654453,"mc":[{"id":"1.230178307","rc":[{"atb":[[2.4,4.61]],"id":47801105},{"atb":[[1.48,2.11]],"id":53893973},{"atb":[[2.32,2.11]],"id":61496663},{"atb":[[2.34,2.11]],"id":53987475}],"con":true,"img":false}]}
{"op":"mcm","clk":"11540450828","pt":1719494655854,"mc":[{"id":"1.230178307","rc":[{"atb":[[1.02,0]],"id":47801105}],"con":true,"img":false}]}
{"op":"mcm","clk":"11540450836","pt":1719494655958,"mc":[{"id":"1.230178307","rc":[{"atb":[[2.52,2]],"id":47801105}],"con":true,"img":false}]}
{"op":"mcm","clk":"11540450856","pt":1719494656113,"mc":[{"id":"1.230178307","rc":[{"atb":[[1.02,0]],"id":47095746}],"con":true,"img":false}]}
{"op":"mcm","clk":"11540450862","pt":1719494656217,"mc":[{"id":"1.230178307","rc":[{"atb":[[2.64,2]],"id":47095746}],"con":true,"img":false}]}
{"op":"mcm","clk":"11540450888","pt":1719494656528,"mc":[{"id":"1.230178307","rc":[{"atb":[[1.09,0]],"id":53893973}],"con":true,"img":false}]}
{"op":"mcm","clk":"11540450900","pt":1719494656637,"mc":[{"id":"1.230178307","rc":[{"atb":[[1.54,2]],"id":53893973}],"con":true,"img":false}]}
{"op":"mcm","clk":"11540450925","pt":1719494657047,"mc":[{"id":"1.230178307","rc":[{"atb":[[1.02,0]],"id":53987475}],"con":true,"img":false}]}
{"op":"mcm","clk":"11540450933","pt":1719494657151,"mc":[{"id":"1.230178307","rc":[{"atb":[[2.46,2]],"id":53987475}],"con":true,"img":false}]}
{"op":"mcm","clk":"11540450958","pt":1719494657515,"mc":[{"id":"1.230178307","rc":[{"atb":[[1.02,0]],"id":66596720}],"con":true,"img":false}]}
{"op":"mcm","clk":"11540450967","pt":1719494657620,"mc":[{"id":"1.230178307","rc":[{"atb":[[2.28,2]],"id":66596720}],"con":true,"img":false}]}
{"op":"mcm","clk":"11540450992","pt":1719494657937,"mc":[{"id":"1.230178307","rc":[{"atl":[[4.6,1]],"id":53987475}],"con":true,"img":false}]}
{"op":"mcm","clk":"11540450998","pt":1719494658034,"mc":[{"id":"1.230178307","rc":[{"atl":[[4.7,0]],"id":53987475}],"con":true,"img":false}]}
{"op":"mcm","clk":"11540451220","pt":1719494660842,"mc":[{"id":"1.230178307","rc":[{"atb":[[2.52,4.5]],"id":47801105},{"atl":[[4.4,0],[3.75,7.5]],"id":53893973},{"atb":[[1.62,0],[2.28,7.5]],"id":47095746},{"atb":[[1.53,0],[2.1,7.5]],"id":61496663},{"atb":[[2.28,4.5]],"id":66596720},{"atl":[[5.8,5],[24,0]],"id":66596720}],"con":true,"img":false}]}
{"op":"mcm","clk":"11540451231","pt":1719494660946,"mc":[{"id":"1.230178307","rc":[{"atb":[[2.42,10],[1.87,0]],"id":47801105},{"atl":[[22,0],[7,10]],"id":47801105},{"atl":[[6.2,5],[5.7,9.5]],"id":61496663},{"atb":[[1.71,0]],"id":66596720},{"atb":[[1.57,0],[2.16,5]],"id":53987475},{"atl":[[19,0],[5.7,7.5]],"id":53987475}],"con":true,"img":false}]}
{"op":"mcm","clk":"11540451242","pt":1719494661047,"mc":[{"id":"1.230178307","rc":[{"atb":[[2.52,2]],"id":47801105}],"con":true,"img":false}]}
{"op":"mcm","clk":"11540451253","pt":1719494661156,"mc":[{"id":"1.230178307","rc":[{"atb":[[2.42,5],[2.52,6.5]],"id":47801105}],"con":true,"img":false}]}
{"op":"mcm","clk":"11540451262","pt":1719494661256,"mc":[{"id":"1.230178307","rc":[{"atb":[[2.42,15],[2.52,2]],"id":47801105}],"con":true,"img":false}]}
{"op":"mcm","clk":"11540451270","pt":1719494661360,"mc":[{"id":"1.230178307","rc":[{"atb":[[2.42,5],[2.52,7]],"id":47801105}],"con":true,"img":false}]}
{"op":"mcm","clk":"11540451281","pt":1719494661466,"mc":[{"id":"1.230178307","rc":[{"atb":[[2.42,15],[2.52,2]],"id":47801105}],"con":true,"img":false}]}
{"op":"mcm","clk":"11540451297","pt":1719494661624,"mc":[{"id":"1.230178307","rc":[{"atb":[[2.42,5],[2.52,7]],"id":47801105}],"con":true,"img":false}]}
{"op":"mcm","clk":"11540451392","pt":1719494662671,"mc":[{"id":"1.230178307","rc":[{"atb":[[2.4,2.5],[2.48,2.11]],"id":47801105}],"con":true,"img":false}]}
{"op":"mcm","clk":"11540451876","pt":1719494668670,"mc":[{"id":"1.230178307","rc":[{"atl":[[5.2,1]],"id":47095746}],"con":true,"img":false}]}
{"op":"mcm","clk":"11540451887","pt":1719494668772,"mc":[{"id":"1.230178307","rc":[{"atl":[[5.3,0]],"id":47095746}],"con":true,"img":false}]}
{"op":"mcm","clk":"11540452007","pt":1719494669962,"mc":[{"id":"1.230178307","rc":[{"atb":[[2.52,11.5]],"id":47801105},{"atl":[[5.8,4.5]],"id":47801105},{"atb":[[1.54,5.38]],"id":53893973},{"atl":[[2.94,3.38]],"id":53893973},{"atb":[[2.64,7.62]],"id":47095746},{"atl":[[5.1,5.62]],"id":47095746},{"atb":[[2.42,5.96]],"id":61496663},{"atl":[[5.2,4.59]],"id":66596720}],"con":true,"img":false}]}
{"op":"mcm","clk":"11540452017","pt":1719494670067,"mc":[{"id":"1.230178307","rc":[{"atl":[[5.7,3.5],[7,5]],"id":47801105},{"atl":[[2.92,2]],"id":53893973},{"atl":[[5.5,6.62],[6.6,0]],"id":47095746},{"atb":[[2.5,4.69]],"id":53987475},{"atl":[[4.5,4.69]],"id":53987475}],"con":true,"img":false}]}
{"op":"mcm","clk":"11540452026","pt":1719494670172,"mc":[{"id":"1.230178307","rc":[{"atb":[[2.4,1]],"id":47801105},{"atl":[[6,0]],"id":47801105},{"atb":[[1.44,1]],"id":53893973},{"atl":[[3,0],[3.75,2.5]],"id":53893973},{"atb":[[1.93,0]],"id":47095746},{"atl":[[6.4,0]],"id":47095746},{"atb":[[1.89,0]],"id":61496663},{"atl":[[7.2,0]],"id":66596720},{"atl":[[5.7,2.5],[4.7,5.69]],"id":53987475}],"con":true,"img":false}]}
{"op":"mcm","clk":"11540452038","pt":1719494670278,"mc":[{"id":"1.230178307","rc":[{"atb":[[1.89,0]],"id":53987475},{"atl":[[5.6,5.69],[4.7,0]],"id":53987475}],"con":true,"img":false}]}
{"op":"mcm","clk":"11540452045","pt":1719494670378,"mc":[{"id":"1.230178307","rc":[{"atl":[[5.6,0],[4.7,5.69]],"id":53987475}],"con":true,"img":false}]}
{"op":"mcm","clk":"11540452055","pt":1719494670481,"mc":[{"id":"1.230178307","rc":[{"atl":[[5.6,0.84]],"id":47801105},{"atl":[[2.9,0.84]],"id":53893973},{"atl":[[5,0.84]],"id":47095746},{"atl":[[5.6,5.69],[4.4,0.84]],"id":53987475}],"con":true,"img":false}]}
{"op":"mcm","clk":"11540452065","pt":1719494670585,"mc":[{"id":"1.230178307","rc":[{"atb":[[2.46,0]],"id":53987475},{"atl":[[4.7,0]],"id":53987475}],"con":true,"img":false}]}
{"op":"mcm","clk":"11540452074","pt":1719494670638,"mc":[{"id":"1.230178307","rc":[{"atb":[[2.52,2]],"id":53987475},{"atl":[[5.6,0],[4.7,5.69]],"id":53987475}],"con":true,"img":false}]}
{"op":"mcm","clk":"11540452093","pt":1719494670950,"mc":[{"id":"1.230178307","rc":[{"atb":[[2.14,3.75]],"id":66596720}],"con":true,"img":false}]}
{"op":"mcm","clk":"11540452226","pt":1719494672252,"mc":[{"id":"1.230178307","rc":[{"atb":[[2.14,0]],"id":66596720}],"con":true,"img":false}]}
{"op":"mcm","clk":"11540452261","pt":1719494672670,"mc":[{"id":"1.230178307","rc":[{"atb":[[2.7,6.25]],"id":66596720}],"con":true,"img":false}]}
{"op":"mcm","clk":"11540452274","pt":1719494672775,"mc":[{"id":"1.230178307","rc":[{"atb":[[2.38,12.5],[2.28,2]],"id":66596720}],"con":true,"img":false}]}
{"op":"mcm","clk":"11540452363","pt":1719494673866,"mc":[{"id":"1.230178307","rc":[{"atb":[[2.28,0]],"id":66596720}],"con":true,"img":false}]}
{"op":"mcm","clk":"11540452379","pt":1719494673972,"mc":[{"id":"1.230178307","rc":[{"atb":[[2.32,4.5]],"id":47801105},{"atb":[[2.72,2]],"id":66596720}],"con":true,"img":false}]}
{"op":"mcm","clk":"11540452386","pt":1719494674074,"mc":[{"id":"1.230178307","rc":[{"atb":[[2.38,0],[2.26,21.25]],"id":66596720}],"con":true,"img":false}]}
{"op":"mcm","clk":"11540452395","pt":1719494674177,"mc":[{"id":"1.230178307","rc":[{"atb":[[2.38,10],[2.26,2.5]],"id":66596720}],"con":true,"img":false}]}
{"op":"mcm","clk":"11540452441","pt":1719494674852,"mc":[{"id":"1.230178307","rc":[{"atb":[[2.58,2.11],[2.48,0]],"id":47801105},{"atb":[[1.48,0],[1.52,2.11]],"id":53893973},{"atb":[[2.4,2.11],[2.32,0]],"id":61496663},{"atb":[[2.42,2.11],[2.34,0]],"id":53987475}],"con":true,"img":false}]}
{"op":"mcm","clk":"11540452454","pt":1719494674961,"mc":[{"id":"1.230178307","rc":[{"atb":[[2.58,4.61]],"id":47801105}],"con":true,"img":false}]}
{"op":"mcm","clk":"11540452460","pt":1719494675061,"mc":[{"id":"1.230178307","rc":[{"atb":[[2.52,6.5]],"id":47801105}],"con":true,"img":false}]}
{"op":"mcm","clk":"11540452479","pt":1719494675268,"mc":[{"id":"1.230178307","rc":[{"atl":[[5.8,9],[5.7,0]],"id":47801105},{"atl":[[2.92,0],[2.94,6.23]],"id":53893973}],"con":true,"img":false}]}
{"op":"mcm","clk":"11540452500","pt":1719494675477,"mc":[{"id":"1.230178307","rc":[{"atl":[[2.94,3.38],[3.05,8.08]],"id":53893973}],"con":true,"img":false}]}
{"op":"mcm","clk":"11540452554","pt":1719494676060,"mc":[{"id":"1.230178307","rc":[{"atl":[[5.6,0]],"id":47801105},{"atl":[[2.9,0]],"id":53893973}],"con":true,"img":false}]}
{"op":"mcm","clk":"11540452575","pt":1719494676261,"mc":[{"id":"1.230178307","rc":[{"atb":[[2.32,0]],"id":47801105}],"con":true,"img":false}]}
{"op":"mcm","clk":"11540452695","pt":1719494677552,"mc":[{"id":"1.230178307","rc":[{"atl":[[5.7,0.84]],"id":47801105},{"atl":[[2.92,0.84]],"id":53893973}],"con":true,"img":false}]}
{"op":"mcm","clk":"11540452707","pt":1719494677759,"mc":[{"id":"1.230178307","rc":[{"atb":[[2.52,4.5]],"id":47801105}],"con":true,"img":false}]}
{"op":"mcm","clk":"11540452717","pt":1719494677861,"mc":[{"id":"1.230178307","rc":[{"atb":[[2.6,2]],"id":47801105}],"con":true,"img":false}]}
{"op":"mcm","clk":"11540452912","pt":1719494680373,"mc":[{"id":"1.230178307","rc":[{"atl":[[5.8,4.5],[6.2,13.35]],"id":47801105}],"con":true,"img":false}]}
{"op":"mcm","clk":"11540453234","pt":1719494684367,"mc":[{"id":"1.230178307","rc":[{"atb":[[2.58,2.11],[2.48,7]],"id":47801105},{"atb":[[2.02,15]],"id":47095746},{"atl":[[6.4,6.62],[6,1],[5.2,0]],"id":47095746},{"atb":[[2.7,1]],"id":66596720}],"con":true,"img":false}]}
{"op":"mcm","clk":"11540453243","pt":1719494684472,"mc":[{"id":"1.230178307","rc":[{"atb":[[2.28,0]],"id":47095746},{"atl":[[5.5,0]],"id":47095746}],"con":true,"img":false}]}
{"op":"mcm","clk":"11540453381","pt":1719494685971,"mc":[{"id":"1.230178307","rc":[{"atb":[[2.72,0]],"id":66596720}],"con":true,"img":false}]}
{"op":"mcm","clk":"11540453391","pt":1719494686076,"mc":[{"id":"1.230178307","rc":[{"atb":[[2.4,2],[2.38,0],[2.26,13.5],[2.7,6.32]],"id":66596720}],"con":true,"img":false}]}
{"op":"mcm","clk":"11540453398","pt":1719494686180,"mc":[{"id":"1.230178307","rc":[{"atb":[[2.38,10],[2.26,2.5]],"id":66596720}],"con":true,"img":false}]}
{"op":"mcm","clk":"11540453416","pt":1719494686432,"mc":[{"id":"1.230178307","rc":[{"atb":[[1.44,0],[1.48,1]],"id":53893973},{"atl":[[3.15,1],[3.05,7.08]],"id":53893973},{"atl":[[4.5,0],[4.6,1]],"id":61496663}],"con":true,"img":false}]}
{"op":"mcm","clk":"11540453441","pt":1719494686622,"mc":[{"id":"1.230178307","rc":[{"atl":[[6.2,12.35],[6,1]],"id":47801105},{"atl":[[3.1,1]],"id":53893973},{"atl":[[4.6,10.5],[4.4,0],[5.7,2.5]],"id":61496663},{"atl":[[7.2,1],[7.4,0]],"id":66596720}],"con":true,"img":false}]}
{"op":"mcm","clk":"11540453445","pt":1719494686647,"mc":[{"id":"1.230178307","rc":[{"atl":[[3.15,0]],"id":53893973},{"atb":[[2.54,1],[2.7,5.32]],"id":66596720},{"atb":[[1.88,0]],"id":53987475}],"con":true,"img":false}]}
{"op":"mcm","clk":"11540453451","pt":1719494686754,"mc":[{"id":"1.230178307","rc":[{"atl":[[6.2,13.35]],"id":47801105},{"atl":[[4.5,5.34],[4.6,1],[5.7,12]],"id":61496663}],"con":true,"img":false}]}
{"op":"mcm","clk":"11540453459","pt":1719494686855,"mc":[{"id":"1.230178307","rc":[{"atb":[[2.6,5.09]],"id":47801105},{"atl":[[6,0],[5.7,3.93]],"id":47801105},{"atl":[[2.9,4.41],[3.1,0]],"id":53893973},{"atb":[[2.16,10.96]],"id":61496663},{"atl":[[6.2,18],[5.7,2.5]],"id":61496663},{"atb":[[2.7,0]],"id":66596720}],"con":true,"img":false}]}
{"op":"mcm","clk":"11540453468","pt":1719494686958,"mc":[{"id":"1.230178307","rc":[{"atb":[[2.52,0]],"id":47801105},{"atl":[[5.8,0]],"id":47801105},{"atl":[[3.05,0]],"id":53893973},{"atb":[[2.1,0]],"id":61496663},{"atl":[[6.2,5],[5.7,12.5],[4.4,0.84]],"id":61496663},{"atb":[[2.66,5.32]],"id":66596720},{"atb":[[2.22,7.19],[2.52,5.38],[2.16,0]],"id":53987475}],"con":true,"img":false}]}
{"op":"mcm","clk":"11540453482","pt":1719494687064,"mc":[{"id":"1.230178307","rc":[{"atl":[[6.2,3.5],[7,21.67]],"id":47801105},{"atl":[[3.15,1]],"id":53893973},{"atl":[[4.6,7.19],[5.7,2.5]],"id":61496663},{"atb":[[2.66,0]],"id":66596720},{"atb":[[2.5,0]],"id":53987475}],"con":true,"img":false}]}
{"op":"mcm","clk":"11540453488","pt":1719494687167,"mc":[{"id":"1.230178307","rc":[{"atb":[[2.54,6.32]],"id":66596720}],"con":true,"img":false}]}
{"op":"mcm","clk":"11540453534","pt":1719494687480,"mc":[{"id":"1.230178307","rc":[{"atl":[[2.88,0.84]],"id":53893973}],"con":true,"img":false}]}
{"op":"mcm","clk":"11540453666","pt":1719494688793,"mc":[{"id":"1.230178307","rc":[{"spn":4.15,"spf":"NaN","id":47801105},{"spn":2.21,"spf":"NaN","id":53893973},{"spn":3.82,"spf":"NaN","id":47095746},{"atl":[[4.5,6.34],[4.6,6.19]],"id":61496663},{"spn":3.41,"spf":"NaN","id":61496663},{"atb":[[2.54,5.32],[2.46,1]],"id":66596720},{"atl":[[7.2,0],[6.8,1],[6.6,1]],"id":66596720},{"spn":3.87,"spf":"NaN","id":66596720},{"spn":3.46,"spf":"NaN","id":53987475}],"con":true,"img":false}]}
{"op":"mcm","clk":"11540453673","pt":1719494688897,"mc":[{"id":"1.230178307","rc":[{"atb":[[2.02,0],[2.2,12.62]],"id":47095746},{"atb":[[2.54,0]],"id":66596720}],"con":true,"img":false}]}
{"op":"mcm","clk":"11540453680","pt":1719494688950,"mc":[{"id":"1.230178307","rc":[{"atb":[[2.4,0],[2.5,3.38]],"id":66596720}],"con":true,"img":false}]}
{"op":"mcm","clk":"11540453691","pt":1719494689055,"mc":[{"id":"1.230178307","rc":[{"atb":[[2.56,2]],"id":66596720}],"con":true,"img":false}]}
{"op":"mcm","clk":"11540453699","pt":1719494689158,"mc":[{"id":"1.230178307","rc":[{"atb":[[2.5,0]],"id":66596720}],"con":true,"img":false}]}
{"op":"mcm","clk":"11540453708","pt":1719494689261,"mc":[{"id":"1.230178307","rc":[{"atb":[[2.56,6.41]],"id":66596720}],"con":true,"img":false}]}
{"op":"mcm","clk":"11540454005","pt":1719494692476,"mc":[{"id":"1.230178307","rc":[{"atl":[[6.8,0]],"id":66596720}],"con":true,"img":false}]}
{"op":"mcm","clk":"11540454727","pt":1719494701581,"mc":[{"id":"1.230178307","rc":[{"atl":[[4.5,5.34],[4.6,7.19]],"id":61496663},{"atb":[[2.4,1],[2.46,0]],"id":66596720},{"atl":[[6.4,1],[6.6,0]],"id":66596720}],"con":true,"img":false}]}
{"op":"mcm","clk":"11540454734","pt":1719494701686,"mc":[{"id":"1.230178307","rc":[{"atb":[[2.4,0],[2.46,1]],"id":47801105},{"atl":[[6.2,2.5],[6.6,1]],"id":47801105},{"atl":[[6.2,11]],"id":66596720}],"con":true,"img":false}]}
{"op":"mcm","clk":"11540454743","pt":1719494701790,"mc":[{"id":"1.230178307","rc":[{"atl":[[6.4,10],[7,4.99]],"id":47801105}],"con":true,"img":false}]}
{"op":"mcm","clk":"11540454753","pt":1719494701894,"mc":[{"id":"1.230178307","rc":[{"atl":[[4.5,6.34],[4.6,6.19]],"id":61496663},{"atl":[[6.4,0]],"id":66596720}],"con":true,"img":false}]}
{"op":"mcm","clk":"11540454764","pt":1719494702000,"mc":[{"id":"1.230178307","rc":[{"atb":[[2.6,7.59],[2.48,0]],"id":47801105},{"atb":[[1.42,7.5],[1.38,0]],"id":53893973},{"atb":[[2.2,0],[2.34,12.62]],"id":47095746},{"atl":[[5.6,1],[6.4,0],[6,6.47]],"id":47095746},{"atb":[[2.22,10.96],[2.16,0]],"id":61496663},{"atb":[[2.56,12.82],[2.38,0]],"id":66596720},{"atb":[[2.3,7.5],[2.22,0]],"id":53987475},{"atl":[[4.6,0],[4.4,5.3]],"id":53987475}],"con":true,"img":false}]}
{"op":"mcm","clk":"11540454778","pt":1719494702104,"mc":[{"id":"1.230178307","rc":[{"atb":[[2.6,5.09],[2.58,12.29]],"id":47801105},{"atb":[[2.64,12.62]],"id":47095746},{"atl":[[6.8,9.12]],"id":47095746},{"atb":[[2.22,0],[2.12,11.92]],"id":61496663},{"atb":[[2.56,6.41],[2.38,7.41]],"id":66596720},{"atb":[[2.3,0],[2.18,10.38]],"id":53987475}],"con":true,"img":false}]}
{"op":"mcm","clk":"11540454788","pt":1719494702209,"mc":[{"id":"1.230178307","rc":[{"atb":[[2.54,15.12],[2.64,7.62],[2.34,0]],"id":47095746},{"atl":[[6,0]],"id":47095746},{"atb":[[2.56,8.91],[2.38,0]],"id":66596720},{"atl":[[4.5,0]],"id":53987475}],"con":true,"img":false}]}
{"op":"mcm","clk":"11540454834","pt":1719494702676,"mc":[{"id":"1.230178307","rc":[{"atb":[[1.92,0],[2.08,1]],"id":47095746}],"con":true,"img":false}]}
{"op":"mcm","clk":"11540454911","pt":1719494703402,"mc":[{"id":"1.230178307","rc":[{"atl":[[4.4,9.06]],"id":61496663}],"con":true,"img":false}]}
{"op":"mcm","clk":"11540454916","pt":1719494703505,"mc":[{"id":"1.230178307","rc":[{"atl":[[2.76,3.46]],"id":53893973},{"atl":[[4.3,6.34]],"id":61496663}],"con":true,"img":false}]}
{"op":"mcm","clk":"11540454923","pt":1719494703609,"mc":[{"id":"1.230178307","rc":[{"atl":[[4.5,1],[4.6,0]],"id":61496663}],"con":true,"img":false}]}
{"op":"mcm","clk":"11540454934","pt":1719494703663,"mc":[{"id":"1.230178307","rc":[{"atl":[[2.94,0],[2.9,0],[2.74,3.46]],"id":53893973},{"atl":[[4.3,0],[4.5,16.41]],"id":61496663}],"con":true,"img":false}]}
{"op":"mcm","clk":"11540454954","pt":1719494703874,"mc":[{"id":"1.230178307","rc":[{"atl":[[2.88,7.76],[2.74,0]],"id":53893973}],"con":true,"img":false}]}
{"op":"mcm","clk":"11540454979","pt":1719494704080,"mc":[{"id":"1.230178307","rc":[{"atl":[[2.92,0],[2.72,0.85],[2.88,6.92]],"id":53893973}],"con":true,"img":false}]}
{"op":"mcm","clk":"11540455022","pt":1719494704600,"mc":[{"id":"1.230178307","rc":[{"atl":[[2.72,0]],"id":53893973}],"con":true,"img":false}]}
{"op":"mcm","clk":"11540455031","pt":1719494704702,"mc":[{"id":"1.230178307","rc":[{"atl":[[2.88,0],[3.15,11.38]],"id":53893973}],"con":true,"img":false}]}
{"op":"mcm","clk":"11540455228","pt":1719494707084,"mc":[{"id":"1.230178307","rc":[{"atl":[[2.76,0]],"id":53893973}],"con":true,"img":false}]}
{"op":"mcm","clk":"11540455237","pt":1719494707191,"mc":[{"id":"1.230178307","rc":[{"atl":[[2.92,4.47]],"id":53893973}],"con":true,"img":false}]}
{"op":"mcm","clk":"11540455256","pt":1719494707397,"mc":[{"id":"1.230178307","rc":[{"atl":[[2.92,0]],"id":53893973}],"con":true,"img":false}]}
{"op":"mcm","clk":"11540455266","pt":1719494707501,"mc":[{"id":"1.230178307","rc":[{"atl":[[2.96,5.23]],"id":53893973}],"con":true,"img":false}]}
{"op":"mcm","clk":"11540455475","pt":1719494709883,"mc":[{"id":"1.230178307","rc":[{"atl":[[3.15,1],[3.75,19.11]],"id":53893973},{"atb":[[2.54,5],[2.64,15.24]],"id":47095746}],"con":true,"img":false}]}
{"op":"mcm","clk":"11540455560","pt":1719494711181,"mc":[{"id":"1.230178307","rc":[{"atb":[[1.02,1.7]],"id":47801105},{"atl":[[1000,1.88]],"id":47801105},{"atb":[[1.02,1.7]],"id":47095746},{"atl":[[1000,1.88]],"id":47095746},{"atb":[[1.02,3.7]],"id":61496663},{"atl":[[1000,1.7]],"id":61496663}],"con":true,"img":false}]}
{"op":"mcm","clk":"11540455565","pt":1719494711282,"mc":[{"id":"1.230178307","rc":[{"atl":[[4.5,1],[5.7,23.78]],"id":61496663}],"con":true,"img":false}]}
{"op":"mcm","clk":"11540455575","pt":1719494711489,"mc":[{"id":"1.230178307","rc":[{"atb":[[1.02,0.18]],"id":47801105},{"atl":[[1000,0.24]],"id":47801105},{"atl":[[2.94,0.84]],"id":53893973},{"atb":[[1.02,0.17]],"id":47095746},{"atl":[[1000,0.25]],"id":47095746},{"atb":[[1.02,2.2]],"id":61496663},{"atl":[[1000,0.08]],"id":61496663}],"con":true,"img":false}]}
{"op":"mcm","clk":"11540455594","pt":1719494711799,"mc":[{"id":"1.230178307","rc":[{"atb":[[1.02,0]],"id":47801105},{"atl":[[1000,0.17]],"id":47801105},{"atb":[[1.02,0]],"id":47095746},{"atl":[[1000,0.17]],"id":47095746},{"atb":[[1.02,2]],"id":61496663},{"atl":[[1000,0]],"id":61496663}],"con":true,"img":false}]}
{"op":"mcm","clk":"11540455606","pt":1719494711903,"mc":[{"id":"1.230178307","rc":[{"atb":[[2.62,0.18]],"id":47801105},{"atl":[[5.6,0.06]],"id":47801105},{"atb":[[2.66,0.17]],"id":47095746},{"atl":[[5,0.92]],"id":47095746},{"atb":[[2.44,0.2]],"id":61496663},{"atl":[[4.3,0.08]],"id":61496663}],"con":true,"img":false}]}
{"op":"mcm","clk":"11540455617","pt":1719494712006,"mc":[{"id":"1.230178307","rc":[{"atb":[[2.62,5.01]],"id":47801105},{"atl":[[5.6,4.89]],"id":47801105},{"atb":[[2.66,2.79]],"id":47095746}],"con":true,"img":false}]}
{"op":"mcm","clk":"11540455628","pt":1719494712109,"mc":[{"id":"1.230178307","rc":[{"atb":[[2.6,2],[2.64,5.09],[2.58,2.11]],"id":47801105},{"atl":[[5.7,0.84]],"id":47801105},{"atb":[[2.64,9.62]],"id":47095746}],"con":true,"img":false}]}
{"op":"mcm","clk":"11540455638","pt":1719494712213,"mc":[{"id":"1.230178307","rc":[{"atb":[[2.64,0],[2.6,12.02]],"id":47801105}],"con":true,"img":false}]}
{"op":"mcm","clk":"11540455665","pt":1719494712577,"mc":[{"id":"1.230178307","rc":[{"atl":[[5.5,0.84]],"id":47801105}],"con":true,"img":false}]}
{"op":"mcm","clk":"11540455688","pt":1719494712887,"mc":[{"id":"1.230178307","rc":[{"atb":[[2.6,10.02]],"id":47801105}],"con":true,"img":false}]}
{"op":"mcm","clk":"11540455696","pt":1719494712991,"mc":[{"id":"1.230178307","rc":[{"atb":[[2.64,2]],"id":47801105}],"con":true,"img":false}]}
{"op":"mcm","clk":"11540455714","pt":1719494713197,"mc":[{"id":"1.230178307","rc":[{"atb":[[2.64,7.01],[2.6,0]],"id":47801105}],"con":true,"img":false}]}
{"op":"mcm","clk":"11540455730","pt":1719494713404,"mc":[{"id":"1.230178307","rc":[{"atb":[[2.64,7.62]],"id":47095746}],"con":true,"img":false}]}
{"op":"mcm","clk":"11540455738","pt":1719494713507,"mc":[{"id":"1.230178307","rc":[{"atb":[[2.68,2]],"id":47095746}],"con":true,"img":false}]}
{"op":"mcm","clk":"11540455827","pt":1719494714389,"mc":[{"id":"1.230178307","rc":[{"atb":[[2.46,0],[2.62,6.01]],"id":47801105},{"atl":[[6.6,0]],"id":47801105},{"atb":[[1.48,0]],"id":53893973},{"atl":[[3.15,0],[3.05,1]],"id":53893973},{"atl":[[4.5,0],[4.6,1]],"id":61496663},{"atb":[[2.4,0]],"id":66596720},{"atl":[[5.6,1],[6.2,10]],"id":66596720},{"atl":[[4.5,1],[4.4,4.3]],"id":53987475}],"con":true,"img":false}]}
{"op":"mcm","clk":"11540455840","pt":1719494714492,"mc":[{"id":"1.230178307","rc":[{"atb":[[2.64,2],[2.6,12.02]],"id":47801105},{"atl":[[6.4,0],[7.4,5]],"id":47801105}],"con":true,"img":false}]}
{"op":"mcm","clk":"11540455849","pt":1719494714596,"mc":[{"id":"1.230178307","rc":[{"atb":[[2.64,8.01],[2.6,0]],"id":47801105},{"atl":[[4.5,1],[4.6,0]],"id":61496663},{"atb":[[2.56,6.41],[2.46,17.82]],"id":66596720},{"atl":[[5.8,0],[5.7,10]],"id":66596720},{"atl":[[4.5,0],[4.4,5.3]],"id":53987475}],"con":true,"img":false}]}
{"op":"mcm","clk":"11540455855","pt":1719494714700,"mc":[{"id":"1.230178307","rc":[{"atb":[[2.64,2],[2.6,8.01]],"id":47801105},{"atl":[[5.7,13.5]],"id":53987475}],"con":true,"img":false}]}
{"op":"mcm","clk":"11540455869","pt":1719494714804,"mc":[{"id":"1.230178307","rc":[{"atl":[[7.2,1]],"id":47801105},{"atl":[[4.7,0]],"id":53987475}],"con":true,"img":false}]}
{"op":"mcm","clk":"11540456112","pt":1719494717503,"mc":[{"id":"1.230178307","rc":[{"atl":[[3.05,7.08],[3.75,2.5]],"id":53893973},{"atb":[[2.64,0],[2.68,4.8]],"id":47095746}],"con":true,"img":false}]}
{"op":"mcm","clk":"11540456160","pt":1719494718022,"mc":[{"id":"1.230178307","rc":[{"atl":[[4.3,0],[3.95,0],[3.75,0]],"id":53893973},{"atb":[[2.54,0],[2.46,0],[2.62,0]],"id":47095746},{"atl":[[5.4,2.5]],"id":61496663},{"atb":[[2.28,2.5],[2.2,5]],"id":66596720},{"atl":[[6.2,0],[5.7,11],[7,0]],"id":53987475}],"con":true,"img":false}]}
{"op":"mcm","clk":"11540456172","pt":1719494718089,"mc":[{"id":"1.230178307","rc":[{"atl":[[3.65,2.5]],"id":53893973},{"atb":[[2.8,10],[2.88,5],[2.96,2.5]],"id":47095746},{"atl":[[6.2,0],[5.7,21.28],[7,0]],"id":61496663},{"atb":[[2.18,0],[2.26,0],[2.1,0]],"id":66596720},{"atl":[[6.4,10],[5.8,5],[5.4,2.5]],"id":53987475}],"con":true,"img":false}]}
{"op":"mcm","clk":"11540456179","pt":1719494718189,"mc":[{"id":"1.230178307","rc":[{"atl":[[5.4,13.12]],"id":53987475}],"con":true,"img":false}]}
{"op":"mcm","clk":"11540456193","pt":1719494718286,"mc":[{"id":"1.230178307","rc":[{"atl":[[5.7,0]],"id":53987475}],"con":true,"img":false}]}
{"op":"mcm","clk":"11540456249","pt":1719494718904,"mc":[{"id":"1.230178307","rc":[{"atl":[[4.5,10.16]],"id":61496663}],"con":true,"img":false}]}
{"op":"mcm","clk":"11540456256","pt":1719494719007,"mc":[{"id":"1.230178307","rc":[{"atl":[[5.7,0]],"id":61496663}],"con":true,"img":false}]}
{"op":"mcm","clk":"11540456311","pt":1719494719690,"mc":[{"id":"1.230178307","rc":[{"atl":[[4.3,6.14]],"id":61496663}],"con":true,"img":false}]}
{"op":"mcm","clk":"11540456318","pt":1719494719785,"mc":[{"id":"1.230178307","rc":[{"atl":[[2.92,5.8]],"id":53893973}],"con":true,"img":false}]}
{"op":"mcm","clk":"11540456329","pt":1719494719888,"mc":[{"id":"1.230178307","rc":[{"atl":[[4.4,0.84]],"id":61496663}],"con":true,"img":false}]}
{"op":"mcm","clk":"11540456337","pt":1719494719992,"mc":[{"id":"1.230178307","rc":[{"atl":[[3.05,1]],"id":53893973},{"atl":[[4.2,0.84]],"id":61496663}],"con":true,"img":false}]}
{"op":"mcm","clk":"11540456383","pt":1719494720512,"mc":[{"id":"1.230178307","rc":[{"atl":[[2.9,0.84]],"id":53893973},{"atb":[[2.68,2.8]],"id":47095746}],"con":true,"img":false}]}
{"op":"mcm","clk":"11540456391","pt":1719494720615,"mc":[{"id":"1.230178307","rc":[{"atb":[[1.02,2]],"id":47095746}],"con":true,"img":false}]}
{"op":"mcm","clk":"11540456437","pt":1719494721186,"mc":[{"id":"1.230178307","rc":[{"atb":[[2.24,1],[2.08,0]],"id":47095746}],"con":true,"img":false}]}
{"op":"mcm","clk":"11540456528","pt":1719494722316,"mc":[{"id":"1.230178307","rc":[{"atb":[[2.64,8.01],[2.6,0]],"id":47801105}],"con":true,"img":false}]}
{"op":"mcm","clk":"11540456600","pt":1719494723300,"mc":[{"id":"1.230178307","rc":[{"atl":[[5.8,23.43],[5.4,2.5]],"id":53987475}],"con":true,"img":false}]}
{"op":"mcm","clk":"11540456611","pt":1719494723404,"mc":[{"id":"1.230178307","rc":[{"atl":[[2.9,4.3]],"id":53893973}],"con":true,"img":false}]}
{"op":"mcm","clk":"11540456624","pt":1719494723610,"mc":[{"id":"1.230178307","rc":[{"atl":[[2.92,0]],"id":53893973}],"con":true,"img":false}]}
{"op":"mcm","clk":"11540456656","pt":1719494724026,"mc":[{"id":"1.230178307","rc":[{"atl":[[2.94,0]],"id":53893973},{"atb":[[1.03,10.9]],"id":47095746},{"atl":[[1000,5.28]],"id":47095746}],"con":true,"img":false}]}
{"op":"mcm","clk":"11540456670","pt":1719494724182,"mc":[{"id":"1.230178307","rc":[{"atb":[[1.03,7.69]],"id":47095746},{"atl":[[1000,0.32]],"id":47095746}],"con":true,"img":false}]}
{"op":"mcm","clk":"11540456684","pt":1719494724389,"mc":[{"id":"1.230178307","rc":[{"atb":[[1.03,7.49]],"id":47095746},{"atl":[[1000,0.17]],"id":47095746}],"con":true,"img":false}]}
{"op":"mcm","clk":"11540456693","pt":1719494724500,"mc":[{"id":"1.230178307","rc":[{"atb":[[2.98,0.2]],"id":47095746},{"atl":[[5,1.06]],"id":47095746}],"con":true,"img":false}]}
{"op":"mcm","clk":"11540456703","pt":1719494724597,"mc":[{"id":"1.230178307","rc":[{"atl":[[5,3.74]],"id":47095746}],"con":true,"img":false}]}
{"op":"mcm","clk":"11540456721","pt":1719494724802,"mc":[{"id":"1.230178307","rc":[{"atl":[[5.1,0]],"id":47095746}],"con":true,"img":false}]}
{"op":"mcm","clk":"11540456734","pt":1719494725009,"mc":[{"id":"1.230178307","rc":[{"atl":[[3.05,10.54]],"id":53893973}],"con":true,"img":false}]}
{"op":"mcm","clk":"11540456749","pt":1719494725112,"mc":[{"id":"1.230178307","rc":[{"atl":[[2.96,0]],"id":53893973}],"con":true,"img":false}]}
{"op":"mcm","clk":"11540456978","pt":1719494728121,"mc":[{"id":"1.230178307","rc":[{"atb":[[2.66,5.26]],"id":47801105},{"atb":[[2.98,4.89]],"id":47095746}],"con":true,"img":false}]}
{"op":"mcm","clk":"11540456987","pt":1719494728286,"mc":[{"id":"1.230178307","rc":[{"atb":[[2.62,1.18]],"id":47801105},{"atb":[[2.66,0.17]],"id":47095746}],"con":true,"img":false}]}
{"op":"mcm","clk":"11540457045","pt":1719494729113,"mc":[{"id":"1.230178307","rc":[{"atb":[[2.64,6.01]],"id":47801105}],"con":true,"img":false}]}
{"op":"mcm","clk":"11540457049","pt":1719494729217,"mc":[{"id":"1.230178307","rc":[{"atb":[[2.64,0],[2.62,12.45],[2.68,2]],"id":47801105}],"con":true,"img":false}]}
{"op":"mcm","clk":"11540457099","pt":1719494729809,"mc":[{"id":"1.230178307","rc":[{"atb":[[2.62,1.18],[2.68,7.26]],"id":47801105}],"con":true,"img":false}]}
{"op":"mcm","clk":"11540457131","pt":1719494730108,"mc":[{"id":"1.230178307","rc":[{"atl":[[3.65,17.35]],"id":53893973}],"con":true,"img":false}]}
{"op":"mcm","clk":"11540457137","pt":1719494730207,"mc":[{"id":"1.230178307","rc":[{"atl":[[3.05,1]],"id":53893973}],"con":true,"img":false}]}
{"op":"mcm","clk":"11540457556","pt":1719494735626,"mc":[{"id":"1.230178307","rc":[{"atl":[[4.2,3.07]],"id":61496663}],"con":true,"img":false}]}
{"op":"mcm","clk":"11540457574","pt":1719494735836,"mc":[{"id":"1.230178307","rc":[{"atl":[[4.3,0.08]],"id":61496663}],"con":true,"img":false}]}
{"op":"mcm","clk":"11540457593","pt":1719494736045,"mc":[{"id":"1.230178307","rc":[{"atl":[[4.4,0]],"id":61496663}],"con":true,"img":false}]}
{"op":"mcm","clk":"11540458251","pt":1719494743838,"mc":[{"id":"1.230178307","rc":[{"atb":[[2.7,4.55]],"id":47801105}],"con":true,"img":false}]}
{"op":"mcm","clk":"11540458266","pt":1719494744015,"mc":[{"id":"1.230178307","rc":[{"atb":[[2.66,0]],"id":47801105}],"con":true,"img":false}]}
{"op":"mcm","clk":"11540458297","pt":1719494744438,"mc":[{"id":"1.230178307","rc":[{"atl":[[7.2,0],[7,5.99]],"id":47801105},{"atb":[[1.48,1]],"id":53893973},{"atl":[[3.15,1]],"id":53893973},{"atl":[[4.6,1]],"id":61496663},{"atl":[[5.6,0],[5.5,1]],"id":66596720},{"atl":[[4.3,1]],"id":53987475}],"con":true,"img":false}]}
{"op":"mcm","clk":"11540458306","pt":1719494744530,"mc":[{"id":"1.230178307","rc":[{"atl":[[7.2,1],[7,4.99]],"id":47801105},{"atl":[[3.15,5.31],[3.05,0],[3.65,2.5]],"id":53893973},{"atl":[[4.5,9.16],[4.6,0],[4.7,1]],"id":61496663},{"atl":[[5.5,10],[5.7,5],[5.4,1]],"id":66596720},{"atl":[[4.3,3.75],[5.8,5],[4.4,4.3],[5.4,13.12]],"id":53987475}],"con":true,"img":false}]}
{"op":"mcm","clk":"11540458316","pt":1719494744635,"mc":[{"id":"1.230178307","rc":[{"atl":[[3.15,6.31]],"id":53893973},{"atl":[[5,1],[5.5,0],[5.4,7.1]],"id":66596720},{"atl":[[4.3,8.06],[4.4,0.84],[5.4,2.5]],"id":53987475}],"con":true,"img":false}]}
{"op":"mcm","clk":"11540458324","pt":1719494744738,"mc":[{"id":"1.230178307","rc":[{"atb":[[2.76,9.89],[2.68,0]],"id":47095746},{"atl":[[5.6,0],[5.8,1]],"id":47095746},{"atb":[[2.3,24.23],[2.46,0]],"id":66596720},{"atl":[[5.1,5.32]],"id":66596720},{"atl":[[4.3,3.75],[4.4,1.84],[5.4,12.5]],"id":53987475}],"con":true,"img":false}]}
{"op":"mcm","clk":"11540458336","pt":1719494744844,"mc":[{"id":"1.230178307","rc":[{"atb":[[2.62,0.18]],"id":47801105},{"atl":[[7.2,0],[7,5.99],[6.6,1]],"id":47801105},{"atb":[[1.48,0]],"id":53893973},{"atl":[[3,1],[3.15,5.31],[3.05,1]],"id":53893973},{"atl":[[4.6,1],[4.7,0]],"id":61496663},{"atl":[[5,4.6],[4.9,1],[5.4,0]],"id":66596720},{"atl":[[4.5,1],[4.6,1],[4.4,8.34],[5.4,2.5]],"id":53987475}],"con":true,"img":false}]}
{"op":"mcm","clk":"11540458344","pt":1719494744950,"mc":[{"id":"1.230178307","rc":[{"atl":[[5.8,0]],"id":47095746},{"atl":[[5.1,10.92],[5,1],[5.2,0.84]],"id":66596720},{"atl":[[4.5,13.1],[4.4,0.84]],"id":53987475}],"con":true,"img":false}]}
{"op":"mcm","clk":"11540458355","pt":1719494745053,"mc":[{"id":"1.230178307","rc":[{"atb":[[2.64,11.81],[2.68,2]],"id":47801105},{"atl":[[7,4.99]],"id":47801105},{"atl":[[3,0]],"id":53893973},{"atl":[[4.6,0],[4.7,1]],"id":61496663},{"atl":[[4.9,0]],"id":66596720},{"atb":[[2.24,10],[2.18,0]],"id":53987475},{"atl":[[4.5,12.1],[4.2,0.84]],"id":53987475}],"con":true,"img":false}]}
{"op":"mcm","clk":"11540458397","pt":1719494745524,"mc":[{"id":"1.230178307","rc":[{"atb":[[2.68,0]],"id":47801105}],"con":true,"img":false}]}
{"op":"mcm","clk":"11540458407","pt":1719494745625,"mc":[{"id":"1.230178307","rc":[{"atb":[[2.72,2]],"id":47801105}],"con":true,"img":false}]}
{"op":"mcm","clk":"11540458418","pt":1719494745729,"mc":[{"id":"1.230178307","rc":[{"atb":[[2.74,4.91],[2.64,0],[2.62,16.54],[2.7,0]],"id":47801105}],"con":true,"img":false}]}
{"op":"mcm","clk":"11540458428","pt":1719494745833,"mc":[{"id":"1.230178307","rc":[{"atb":[[2.62,0.18],[2.76,4.91]],"id":47801105}],"con":true,"img":false}]}
{"op":"mcm","clk":"11540458440","pt":1719494745937,"mc":[{"id":"1.230178307","rc":[{"atb":[[2.72,11.82],[2.76,0]],"id":47801105}],"con":true,"img":false}]}
{"op":"mcm","clk":"11540458526","pt":1719494746817,"mc":[{"id":"1.230178307","rc":[{"atl":[[5.6,5.99]],"id":66596720}],"con":true,"img":false}]}
{"op":"mcm","clk":"11540458533","pt":1719494747025,"mc":[{"id":"1.230178307","rc":[{"atl":[[5.6,0],[5.1,5.32],[5.2,12.76]],"id":66596720}],"con":true,"img":false}]}
{"op":"mcm","clk":"11540458544","pt":1719494747130,"mc":[{"id":"1.230178307","rc":[{"atb":[[2.72,9.82]],"id":47801105}],"con":true,"img":false}]}
{"op":"mcm","clk":"11540458553","pt":1719494747235,"mc":[{"id":"1.230178307","rc":[{"atb":[[2.72,0],[2.62,14.91],[2.76,2]],"id":47801105}],"con":true,"img":false}]}
{"op":"mcm","clk":"11540458562","pt":1719494747339,"mc":[{"id":"1.230178307","rc":[{"atb":[[2.46,1],[2.62,0.18],[2.76,6.91]],"id":47801105}],"con":true,"img":false}]}
{"op":"mcm","clk":"11540458752","pt":1719494749544,"mc":[{"id":"1.230178307","rc":[{"atb":[[2.62,0]],"id":47801105},{"atl":[[5.6,4.83]],"id":47801105},{"spn":4.13,"spf":"NaN","id":47801105},{"spn":2.22,"spf":"NaN","id":53893973},{"atb":[[2.66,0],[2.98,4.69]],"id":47095746},{"atl":[[5,3.52]],"id":47095746},{"spn":3.99,"spf":"NaN","id":47095746},{"atb":[[2.44,0]],"id":61496663},{"atl":[[4.3,0]],"id":61496663},{"spn":3.31,"spf":"NaN","id":61496663},{"spn":3.78,"spf":"NaN","id":66596720},{"spn":3.36,"spf":"NaN","id":53987475}],"con":true,"img":false}]}
{"op":"mcm","clk":"11540458768","pt":1719494749749,"mc":[{"id":"1.230178307","rc":[{"atb":[[2.24,0],[2.4,1]],"id":47095746},{"atl":[[6.2,1]],"id":47095746},{"atl":[[4.5,0],[4.7,13.24]],"id":61496663}],"con":true,"img":false}]}
{"op":"mcm","clk":"11540458961","pt":1719494751838,"mc":[{"id":"1.230178307","rc":[{"atl":[[3.15,0],[3.05,9.62]],"id":53893973}],"con":true,"img":false}]}
{"op":"mcm","clk":"11540458988","pt":1719494752046,"mc":[{"id":"1.230178307","rc":[{"atl":[[3.05,1],[3.65,16.43]],"id":53893973}],"con":true,"img":false}]}
{"op":"mcm","clk":"11540459587","pt":1719494758344,"mc":[{"id":"1.230178307","rc":[{"atl":[[6.4,1],[6.6,0]],"id":47801105},{"atb":[[1.48,1]],"id":53893973},{"atl":[[3.15,1],[3.05,0]],"id":53893973},{"atl":[[4.6,1],[4.7,12.24]],"id":61496663},{"atl":[[5,0],[4.9,1]],"id":66596720},{"atl":[[4.5,13.1],[4.6,0]],"id":53987475}],"con":true,"img":false}]}
{"op":"mcm","clk":"11540459598","pt":1719494758449,"mc":[{"id":"1.230178307","rc":[{"atl":[[3.1,8.62],[3.65,2.5]],"id":53893973}],"con":true,"img":false}]}
{"op":"mcm","clk":"11540459618","pt":1719494758657,"mc":[{"id":"1.230178307","rc":[{"atl":[[4.6,0],[4.7,13.24]],"id":61496663},{"atl":[[4.8,1],[4.9,0]],"id":66596720},{"atl":[[4.5,1],[4.6,5]],"id":53987475}],"con":true,"img":false}]}
{"op":"mcm","clk":"11540459629","pt":1719494758759,"mc":[{"id":"1.230178307","rc":[{"atl":[[5,5.32],[5.2,0.84]],"id":66596720}],"con":true,"img":false}]}
{"op":"mcm","clk":"11540459638","pt":1719494758861,"mc":[{"id":"1.230178307","rc":[{"atl":[[4.7,1],[5.4,18.82]],"id":61496663}],"con":true,"img":false}]}
{"op":"mcm","clk":"11540459657","pt":1719494759028,"mc":[{"id":"1.230178307","rc":[{"atl":[[5.2,0]],"id":66596720}],"con":true,"img":false}]}
{"op":"mcm","clk":"11540459679","pt":1719494759341,"mc":[{"id":"1.230178307","rc":[{"atb":[[2.78,5.21]],"id":47801105}],"con":true,"img":false}]}
{"op":"mcm","clk":"11540459696","pt":1719494759537,"mc":[{"id":"1.230178307","rc":[{"atb":[[2.74,0]],"id":47801105}],"con":true,"img":false}]}
{"op":"mcm","clk":"11540459726","pt":1719494759951,"mc":[{"id":"1.230178307","rc":[{"atl":[[4.2,4.3]],"id":53987475}],"con":true,"img":false}]}
{"op":"mcm","clk":"11540459747","pt":1719494760157,"mc":[{"id":"1.230178307","rc":[{"atl":[[4.7,7.98]],"id":66596720},{"atl":[[4.3,0]],"id":53987475}],"con":true,"img":false}]}
{"op":"mcm","clk":"11540459756","pt":1719494760261,"mc":[{"id":"1.230178307","rc":[{"atl":[[5.1,0]],"id":66596720}],"con":true,"img":false}]}
{"op":"mcm","clk":"11540459773","pt":1719494760470,"mc":[{"id":"1.230178307","rc":[{"atl":[[4.3,1.51]],"id":66596720}],"con":true,"img":false}]}
{"op":"mcm","clk":"11540459782","pt":1719494760529,"mc":[{"id":"1.230178307","rc":[{"atb":[[2.5,0],[2.42,0],[2.52,2.5],[2.34,0]],"id":47801105},{"atl":[[4.6,0.84]],"id":66596720},{"atl":[[4.4,0]],"id":53987475}],"con":true,"img":false}]}
{"op":"mcm","clk":"11540459835","pt":1719494761252,"mc":[{"id":"1.230178307","rc":[{"atb":[[2.76,4.91]],"id":47801105}],"con":true,"img":false}]}
{"op":"mcm","clk":"11540459846","pt":1719494761356,"mc":[{"id":"1.230178307","rc":[{"atb":[[2.8,2],[2.6,10.12]],"id":47801105}],"con":true,"img":false}]}
{"op":"mcm","clk":"11540459857","pt":1719494761460,"mc":[{"id":"1.230178307","rc":[{"atb":[[2.82,5.12],[2.76,0]],"id":47801105}],"con":true,"img":false}]}
{"op":"mcm","clk":"11540459873","pt":1719494761629,"mc":[{"id":"1.230178307","rc":[{"atb":[[2.78,0]],"id":47801105}],"con":true,"img":false}]}
{"op":"mcm","clk":"11540459894","pt":1719494761936,"mc":[{"id":"1.230178307","rc":[{"atl":[[3.55,6.25]],"id":53893973}],"con":true,"img":false}]}
{"op":"mcm","clk":"11540459903","pt":1719494762040,"mc":[{"id":"1.230178307","rc":[{"atb":[[2.6,0]],"id":47801105},{"atl":[[6.2,5],[5.5,5.96],[7.4,0]],"id":47801105},{"atb":[[1.44,7.5],[1.42,0]],"id":53893973},{"atb":[[2.88,14.89],[2.76,0]],"id":47095746},{"atb":[[2.12,0],[2.26,20]],"id":61496663},{"atb":[[2.3,0],[2.44,12.82]],"id":66596720},{"atb":[[2.24,0],[2.12,10.38]],"id":53987475},{"atl":[[4.5,0],[4.6,6]],"id":53987475}],"con":true,"img":false}]}
{"op":"mcm","clk":"11540459912","pt":1719494762135,"mc":[{"id":"1.230178307","rc":[{"atb":[[2.62,7.12]],"id":47801105},{"atl":[[5.6,0],[6.2,2.5],[5.7,6.52]],"id":47801105},{"atl":[[3.55,0]],"id":53893973},{"atb":[[2.32,10],[2.12,0]],"id":53987475}],"con":true,"img":false}]}
{"op":"mcm","clk":"11540459919","pt":1719494762239,"mc":[{"id":"1.230178307","rc":[{"atb":[[1.03,1.7]],"id":47801105}],"con":true,"img":false}]}
{"op":"mcm","clk":"11540459926","pt":1719494762341,"mc":[{"id":"1.230178307","rc":[{"atb":[[2.8,0]],"id":47801105}],"con":true,"img":false}]}
{"op":"mcm","clk":"11540459934","pt":1719494762445,"mc":[{"id":"1.230178307","rc":[{"atb":[[1.03,0.09],[2.84,2]],"id":47801105},{"atl":[[6.2,15],[5.7,0.84]],"id":47801105}],"con":true,"img":false}]}
{"op":"mcm","clk":"11540459942","pt":1719494762550,"mc":[{"id":"1.230178307","rc":[{"atb":[[2.82,0],[2.84,10.32]],"id":47801105},{"atl":[[5.7,0]],"id":47801105}],"con":true,"img":false}]}
{"op":"mcm","clk":"11540459958","pt":1719494762758,"mc":[{"id":"1.230178307","rc":[{"atb":[[1.03,0]],"id":47801105}],"con":true,"img":false}]}
{"op":"mcm","clk":"11540459965","pt":1719494762861,"mc":[{"id":"1.230178307","rc":[{"atb":[[2.84,10.41]],"id":47801105}],"con":true,"img":false}]}
{"op":"mcm","clk":"11540460041","pt":1719494763750,"mc":[{"id":"1.230178307","rc":[{"atl":[[4.6,1],[5.4,12.81]],"id":53987475}],"con":true,"img":false}]}
{"op":"mcm","clk":"11540460234","pt":1719494765834,"mc":[{"id":"1.230178307","rc":[{"atl":[[4.3,3.51],[5,0]],"id":66596720}],"con":true,"img":false}]}
{"op":"mcm","clk":"11540460242","pt":1719494765941,"mc":[{"id":"1.230178307","rc":[{"atl":[[2.8,5.11]],"id":53893973}],"con":true,"img":false}]}
{"op":"mcm","clk":"11540460251","pt":1719494766045,"mc":[{"id":"1.230178307","rc":[{"atl":[[3.1,0],[2.78,5.11]],"id":53893973}],"con":true,"img":false}]}
{"op":"mcm","clk":"11540460257","pt":1719494766142,"mc":[{"id":"1.230178307","rc":[{"atl":[[2.9,11.06],[2.78,0]],"id":53893973}],"con":true,"img":false}]}
{"op":"mcm","clk":"11540460282","pt":1719494766456,"mc":[{"id":"1.230178307","rc":[{"atl":[[2.78,0.84]],"id":53893973}],"con":true,"img":false}]}
{"op":"mcm","clk":"11540460291","pt":1719494766555,"mc":[{"id":"1.230178307","rc":[{"atl":[[2.9,10.22]],"id":53893973},{"atl":[[4.6,0]],"id":66596720}],"con":true,"img":false}]}
{"op":"mcm","clk":"11540460388","pt":1719494767645,"mc":[{"id":"1.230178307","rc":[{"atl":[[4.2,0.84]],"id":66596720}],"con":true,"img":false}]}
{"op":"mcm","clk":"11540460890","pt":1719494773752,"mc":[{"id":"1.230178307","rc":[{"atl":[[7.2,1],[6.4,0],[6.6,1]],"id":47801105},{"atb":[[1.48,0]],"id":53893973},{"atl":[[3.05,1]],"id":53893973},{"atl":[[6.4,1],[6.2,0]],"id":47095746},{"atl":[[4.8,0],[4.7,8.98]],"id":66596720}],"con":true,"img":false}]}
{"op":"mcm","clk":"11540460900","pt":1719494773854,"mc":[{"id":"1.230178307","rc":[{"atl":[[3.15,0]],"id":53893973}],"con":true,"img":false}]}
{"op":"mcm","clk":"11540460939","pt":1719494774371,"mc":[{"id":"1.230178307","rc":[{"atl":[[6.6,0]],"id":47801105},{"atl":[[6.4,0],[6.2,1]],"id":47095746}],"con":true,"img":false}]}
{"op":"mcm","clk":"11540460953","pt":1719494774578,"mc":[{"id":"1.230178307","rc":[{"atl":[[6.2,2.5],[7,21.67]],"id":47801105}],"con":true,"img":false}]}
{"op":"mcm","clk":"11540460998","pt":1719494775249,"mc":[{"id":"1.230178307","rc":[{"atl":[[4.2,8.28]],"id":66596720}],"con":true,"img":false}]}
{"op":"mcm","clk":"11540461016","pt":1719494775459,"mc":[{"id":"1.230178307","rc":[{"atl":[[4.7,1]],"id":66596720}],"con":true,"img":false}]}
{"op":"mcm","clk":"11540461106","pt":1719494776351,"mc":[{"id":"1.230178307","rc":[{"atb":[[1.08,50]],"id":47801105},{"atb":[[1.08,50]],"id":53893973},{"atb":[[1.08,50]],"id":47095746},{"atb":[[1.08,50]],"id":61496663},{"atb":[[1.08,50]],"id":66596720},{"atb":[[1.08,50]],"id":53987475}],"con":true,"img":false}]}
{"op":"mcm","clk":"11540461195","pt":1719494777172,"mc":[{"id":"1.230178307","rc":[{"atb":[[2.36,19.23],[2.44,0]],"id":66596720},{"atb":[[2.24,10.38]],"id":53987475}],"con":true,"img":false}]}
{"op":"mcm","clk":"11540461210","pt":1719494777275,"mc":[{"id":"1.230178307","rc":[{"atb":[[2.32,0]],"id":53987475}],"con":true,"img":false}]}
{"op":"mcm","clk":"11540461516","pt":1719494780956,"mc":[{"id":"1.230178307","rc":[{"atl":[[2.78,6.55]],"id":53893973}],"con":true,"img":false}]}
{"op":"mcm","clk":"11540461529","pt":1719494781066,"mc":[{"id":"1.230178307","rc":[{"atl":[[2.9,0],[2.76,6.56]],"id":53893973}],"con":true,"img":false}]}
{"op":"mcm","clk":"11540461541","pt":1719494781156,"mc":[{"id":"1.230178307","rc":[{"atl":[[2.8,0]],"id":53893973}],"con":true,"img":false}]}
{"op":"mcm","clk":"11540461566","pt":1719494781469,"mc":[{"id":"1.230178307","rc":[{"atl":[[2.74,0.85]],"id":53893973}],"con":true,"img":false}]}
{"op":"mcm","clk":"11540461958","pt":1719494786176,"mc":[{"id":"1.230178307","rc":[{"atl":[[2.78,13.97],[2.76,0]],"id":53893973}],"con":true,"img":false}]}
{"op":"mcm","clk":"11540461981","pt":1719494786487,"mc":[{"id":"1.230178307","rc":[{"atl":[[2.74,0]],"id":53893973},{"atl":[[4.5,1],[4.6,0]],"id":53987475}],"con":true,"img":false}]}
{"op":"mcm","clk":"11540461987","pt":1719494786589,"mc":[{"id":"1.230178307","rc":[{"atl":[[3.45,14.98]],"id":53893973},{"atl":[[4.6,8.62],[5.4,2.5]],"id":53987475}],"con":true,"img":false}]}
{"op":"mcm","clk":"11540461995","pt":1719494786647,"mc":[{"id":"1.230178307","rc":[{"atl":[[2.78,6.55]],"id":53893973}],"con":true,"img":false}]}
{"op":"mcm","clk":"11540463598","pt":1719494807415,"mc":[{"id":"1.230178307","rc":[{"atb":[[2.84,17.53],[2.62,0]],"id":47801105},{"atl":[[6.2,0],[7,0],[7.8,8.47]],"id":47801105},{"atb":[[1.46,7.5],[1.44,0]],"id":53893973},{"atl":[[3.45,0],[3.2,7.56]],"id":53893973},{"atb":[[2.88,5],[2.78,14.69]],"id":47095746},{"atb":[[2.3,10],[2.26,10]],"id":61496663},{"atb":[[2.36,0],[2.4,12.82]],"id":66596720},{"atl":[[4.5,11.8],[6.2,0],[5.3,0],[5.2,2.5],[5.7,0]],"id":66596720},{"atb":[[2.36,15],[2.24,0]],"id":53987475},{"atl":[[6.4,0],[5.8,0],[5.2,2.5],[5.4,0]],"id":53987475}],"con":true,"img":false}]}
{"op":"mcm","clk":"11540463605","pt":1719494807475,"mc":[{"id":"1.230178307","rc":[{"atb":[[2.6,17.54],[2.84,10.41]],"id":47801105},{"atl":[[9,5],[8.2,2.5],[9.8,10]],"id":47801105},{"atb":[[2.3,0],[2.16,10.96]],"id":61496663},{"atb":[[2.4,0],[2.24,12.82]],"id":66596720},{"atl":[[4.3,1.51]],"id":66596720},{"atb":[[2.36,5],[2.24,10.38]],"id":53987475}],"con":true,"img":false}]}
{"op":"mcm","clk":"11540464017","pt":1719494812498,"mc":[{"id":"1.230178307","rc":[{"spn":4.17,"spf":"NaN","id":47801105},{"atb":[[1.46,0],[1.39,10.38]],"id":53893973},{"spn":2.16,"spf":"NaN","id":53893973},{"spn":3.38,"spf":"NaN","id":66596720}],"con":true,"img":false}]}
{"op":"mcm","clk":"11540464041","pt":1719494812809,"mc":[{"id":"1.230178307","rc":[{"atb":[[2.6,0],[2.44,5]],"id":47801105},{"atb":[[2.88,15],[2.78,0]],"id":47095746},{"atl":[[4.5,0],[4.6,16.58]],"id":66596720},{"atb":[[2.24,0],[2.12,10.38]],"id":53987475},{"atl":[[4.6,0],[5,8.62]],"id":53987475}],"con":true,"img":false}]}
{"op":"mcm","clk":"11540464055","pt":1719494812911,"mc":[{"id":"1.230178307","rc":[{"atl":[[4.6,5.31]],"id":53987475}],"con":true,"img":false}]}
{"op":"mcm","clk":"11540464064","pt":1719494813014,"mc":[{"id":"1.230178307","rc":[{"atl":[[5,0]],"id":53987475}],"con":true,"img":false}]}
{"op":"mcm","clk":"11540464135","pt":1719494814108,"mc":[{"id":"1.230178307","rc":[{"atb":[[1.44,10.38],[1.39,0]],"id":53893973}],"con":true,"img":false}]}
{"op":"mcm","clk":"11540464141","pt":1719494814204,"mc":[{"id":"1.230178307","rc":[{"atb":[[2.44,0],[2.64,20.84]],"id":47801105},{"atb":[[2.26,20],[2.16,0]],"id":61496663},{"atb":[[2.38,12.82]],"id":66596720},{"atb":[[2.32,10],[2.12,0]],"id":53987475}],"con":true,"img":false}]}
{"op":"mcm","clk":"11540464149","pt":1719494814308,"mc":[{"id":"1.230178307","rc":[{"atb":[[2.24,0]],"id":66596720}],"con":true,"img":false}]}
{"op":"mcm","clk":"11540464188","pt":1719494814721,"mc":[{"id":"1.230178307","rc":[{"atl":[[3.6,2.5],[3.65,0]],"id":53893973}],"con":true,"img":false}]}
{"op":"mcm","clk":"11540464254","pt":1719494815499,"mc":[{"id":"1.230178307","rc":[{"atb":[[2.62,4.88]],"id":47801105}],"con":true,"img":false}]}
{"op":"mcm","clk":"11540464280","pt":1719494815705,"mc":[{"id":"1.230178307","rc":[{"atb":[[2.62,0]],"id":47801105}],"con":true,"img":false}]}
{"op":"mcm","clk":"11540464582","pt":1719494819387,"mc":[{"id":"1.230178307","rc":[{"atl":[[4.3,18.08],[4.6,0]],"id":66596720}],"con":true,"img":false}]}
{"op":"mcm","clk":"11540464669","pt":1719494820413,"mc":[{"id":"1.230178307","rc":[{"atb":[[2.3,5],[2.22,10],[2.38,15.32],[2.28,0],[2.2,0]],"id":66596720}],"con":true,"img":false}]}
{"op":"mcm","clk":"11540464676","pt":1719494820518,"mc":[{"id":"1.230178307","rc":[{"atl":[[4.3,16.58]],"id":66596720}],"con":true,"img":false}]}
{"op":"mcm","clk":"11540464730","pt":1719494821104,"mc":[{"id":"1.230178307","rc":[{"atb":[[2.56,2.5],[2.52,0]],"id":47801105}],"con":true,"img":false}]}
{"op":"mcm","clk":"11540464738","pt":1719494821196,"mc":[{"id":"1.230178307","rc":[{"atb":[[2.38,5],[2.46,2.5]],"id":53987475}],"con":true,"img":false}]}
{"op":"mcm","clk":"11540464750","pt":1719494821301,"mc":[{"id":"1.230178307","rc":[{"atb":[[2.36,0],[2.28,0],[2.44,0]],"id":53987475}],"con":true,"img":false}]}
{"op":"mcm","clk":"11540464762","pt":1719494821404,"mc":[{"id":"1.230178307","rc":[{"atb":[[2.98,0]],"id":47095746}],"con":true,"img":false}]}
{"op":"mcm","clk":"11540464774","pt":1719494821508,"mc":[{"id":"1.230178307","rc":[{"atb":[[2.88,19.52]],"id":47095746}],"con":true,"img":false}]}
{"op":"mcm","clk":"11540464784","pt":1719494821613,"mc":[{"id":"1.230178307","rc":[{"atb":[[2.8,32.02],[2.88,9.52]],"id":47095746}],"con":true,"img":false}]}
{"op":"mcm","clk":"11540464966","pt":1719494824005,"mc":[{"id":"1.230178307","rc":[{"atb":[[1.48,11.51]],"id":53893973}],"con":true,"img":false}]}
{"op":"mcm","clk":"11540465016","pt":1719494824514,"mc":[{"id":"1.230178307","rc":[{"atl":[[4.7,25.87]],"id":66596720}],"con":true,"img":false}]}
{"op":"mcm","clk":"11540465033","pt":1719494824720,"mc":[{"id":"1.230178307","rc":[{"atl":[[4.3,0]],"id":66596720}],"con":true,"img":false}]}
{"op":"mcm","clk":"11540465052","pt":1719494824928,"mc":[{"id":"1.230178307","rc":[{"atl":[[5.2,26.31],[4.7,1]],"id":66596720}],"con":true,"img":false}]}
{"op":"mcm","clk":"11540465156","pt":1719494826047,"mc":[{"id":"1.230178307","rc":[{"atb":[[1.02,1.7]],"id":47801105},{"atl":[[1000,1.88]],"id":47801105},{"atb":[[1.03,9.19]],"id":47095746},{"atl":[[1000,1.88]],"id":47095746},{"atb":[[1.02,3.7]],"id":61496663},{"atl":[[1000,1.7]],"id":61496663}],"con":true,"img":false}]}
{"op":"mcm","clk":"11540465172","pt":1719494826224,"mc":[{"id":"1.230178307","rc":[{"atb":[[1.02,0.15]],"id":47801105},{"atl":[[1000,0.24]],"id":47801105},{"atb":[[1.03,7.58]],"id":47095746},{"atl":[[1000,0.22]],"id":47095746},{"atb":[[1.02,2.19]],"id":61496663},{"atl":[[1000,0.09]],"id":61496663}],"con":true,"img":false}]}
{"op":"mcm","clk":"11540465191","pt":1719494826432,"mc":[{"id":"1.230178307","rc":[{"atl":[[1000,0.17]],"id":47801105},{"atb":[[1.03,7.49]],"id":47095746},{"atb":[[1.02,2]],"id":61496663}],"con":true,"img":false}]}
{"op":"mcm","clk":"11540465201","pt":1719494826535,"mc":[{"id":"1.230178307","rc":[{"atb":[[1.02,0]],"id":47801105},{"atl":[[5.4,0.06]],"id":47801105},{"atb":[[2.98,0.08]],"id":47095746},{"atl":[[1000,0.17]],"id":47095746},{"atb":[[2.44,0.19]],"id":61496663},{"atl":[[1000,0]],"id":61496663}],"con":true,"img":false}]}
{"op":"mcm","clk":"11540465210","pt":1719494826601,"mc":[{"id":"1.230178307","rc":[{"atb":[[2.86,0.15]],"id":47801105},{"atl":[[4.9,0.04]],"id":47095746},{"atl":[[4.1,0.09]],"id":61496663}],"con":true,"img":false}]}
{"op":"mcm","clk":"11540465218","pt":1719494826699,"mc":[{"id":"1.230178307","rc":[{"atl":[[7.2,7.03],[7.8,0],[5.4,6.13]],"id":47801105},{"atl":[[6.2,6]],"id":47095746},{"atl":[[4.1,2.43],[4.7,4.17]],"id":61496663}],"con":true,"img":false}]}
{"op":"mcm","clk":"11540465229","pt":1719494826804,"mc":[{"id":"1.230178307","rc":[{"atl":[[6.8,2.5]],"id":47095746},{"atl":[[5.4,2.5]],"id":61496663}],"con":true,"img":false}]}
{"op":"mcm","clk":"11540465237","pt":1719494826908,"mc":[{"id":"1.230178307","rc":[{"atl":[[5.5,0.84]],"id":47801105},{"atl":[[4.2,0.84]],"id":61496663}],"con":true,"img":false}]}
{"op":"mcm","clk":"11540465262","pt":1719494827106,"mc":[{"id":"1.230178307","rc":[{"atl":[[5.3,0.84]],"id":47801105},{"atl":[[4,0.84]],"id":61496663}],"con":true,"img":false}]}
{"op":"mcm","clk":"11540465271","pt":1719494827209,"mc":[{"id":"1.230178307","rc":[{"atl":[[5.8,5]],"id":47801105},{"atl":[[4.2,4.12]],"id":61496663}],"con":true,"img":false}]}
{"op":"mcm","clk":"11540465279","pt":1719494827310,"mc":[{"id":"1.230178307","rc":[{"atl":[[7.2,1]],"id":47801105},{"atl":[[4.7,1]],"id":61496663}],"con":true,"img":false}]}
{"op":"mcm","clk":"11540465347","pt":1719494828135,"mc":[{"id":"1.230178307","rc":[{"atb":[[2.8,10],[2.88,19.04]],"id":47095746}],"con":true,"img":false}]}
{"op":"mcm","clk":"11540466042","pt":1719494835411,"mc":[{"id":"1.230178307","rc":[{"atb":[[2.96,7.02]],"id":47095746}],"con":true,"img":false}]}
{"op":"mcm","clk":"11540466064","pt":1719494835612,"mc":[{"id":"1.230178307","rc":[{"atb":[[2.88,14.52]],"id":47095746}],"con":true,"img":false}]}
{"op":"mcm","clk":"11540466232","pt":1719494837263,"mc":[{"id":"1.230178307","rc":[{"atb":[[2.86,5.39],[2.64,0],[2.84,20.83]],"id":47801105},{"atl":[[7.2,6.85],[5.8,0]],"id":47801105},{"atb":[[1.46,10],[1.44,0]],"id":53893973},{"atb":[[2.88,5],[2.76,17.02]],"id":47095746},{"atb":[[2.3,7.12],[2.26,10]],"id":61496663},{"atb":[[2.22,22.82],[2.38,2.5]],"id":66596720},{"atb":[[2.4,5],[2.32,0]],"id":53987475}],"con":true,"img":false}]}
{"op":"mcm","clk":"11540466254","pt":1719494837421,"mc":[{"id":"1.230178307","rc":[{"atb":[[2.84,12.51]],"id":47801105},{"atl":[[7.2,1]],"id":47801105},{"atb":[[1.46,0]],"id":53893973},{"atl":[[2.7,5.91]],"id":53893973},{"atb":[[2.3,0]],"id":61496663},{"atb":[[2.4,0]],"id":53987475}],"con":true,"img":false}]}
{"op":"mcm","clk":"11540466266","pt":1719494837525,"mc":[{"id":"1.230178307","rc":[{"atl":[[8.4,5]],"id":47801105},{"atb":[[1.39,10.38]],"id":53893973},{"atl":[[3.2,0],[2.78,0.84],[2.68,5.91]],"id":53893973},{"atb":[[2.16,10]],"id":61496663},{"atb":[[2.22,7.5]],"id":53987475}],"con":true,"img":false}]}
{"op":"mcm","clk":"11540466278","pt":1719494837630,"mc":[{"id":"1.230178307","rc":[{"atl":[[2.78,12.66],[2.68,0]],"id":53893973}],"con":true,"img":false}]}
{"op":"mcm","clk":"11540466290","pt":1719494837732,"mc":[{"id":"1.230178307","rc":[{"atl":[[2.78,0.84],[3.05,19.58]],"id":53893973}],"con":true,"img":false}]}
{"op":"mcm","clk":"11540466318","pt":1719494838043,"mc":[{"id":"1.230178307","rc":[{"atl":[[2.78,0],[2.68,0.85]],"id":53893973}],"con":true,"img":false}]}
{"op":"mcm","clk":"11540466399","pt":1719494838836,"mc":[{"id":"1.230178307","rc":[{"atb":[[2.84,10.51]],"id":47801105}],"con":true,"img":false}]}
{"op":"mcm","clk":"11540466409","pt":1719494838926,"mc":[{"id":"1.230178307","rc":[{"atb":[[2.88,2]],"id":47801105}],"con":true,"img":false}]}
{"op":"mcm","clk":"11540466570","pt":1719494840537,"mc":[{"id":"1.230178307","rc":[{"atl":[[4,4.25]],"id":61496663}],"con":true,"img":false}]}
{"op":"mcm","clk":"11540466580","pt":1719494840638,"mc":[{"id":"1.230178307","rc":[{"atl":[[4.1,0.09]],"id":61496663}],"con":true,"img":false}]}
{"op":"mcm","clk":"11540466628","pt":1719494841220,"mc":[{"id":"1.230178307","rc":[{"atl":[[4.2,3.28]],"id":61496663}],"con":true,"img":false}]}
{"op":"mcm","clk":"11540466667","pt":1719494841632,"mc":[{"id":"1.230178307","rc":[{"atb":[[2.36,2.11],[1.48,0]],"id":66596720}],"con":true,"img":false}]}
{"op":"mcm","clk":"11540466876","pt":1719494843655,"mc":[{"id":"1.230178307","rc":[{"atb":[[2.88,7.39],[2.84,0.09]],"id":47801105}],"con":true,"img":false}]}
{"op":"mcm","clk":"11540466886","pt":1719494843760,"mc":[{"id":"1.230178307","rc":[{"atb":[[2.88,2],[2.84,7.48]],"id":47801105}],"con":true,"img":false}]}
{"op":"mcm","clk":"11540466896","pt":1719494843820,"mc":[{"id":"1.230178307","rc":[{"atb":[[2.88,7.39],[2.84,0.09]],"id":47801105}],"con":true,"img":false}]}
{"op":"mcm","clk":"11540466907","pt":1719494843928,"mc":[{"id":"1.230178307","rc":[{"atb":[[2.88,2],[2.84,7.48]],"id":47801105}],"con":true,"img":false}]}
{"op":"mcm","clk":"11540466920","pt":1719494844029,"mc":[{"id":"1.230178307","rc":[{"atb":[[2.88,7.39],[2.84,0.09]],"id":47801105}],"con":true,"img":false}]}
{"op":"mcm","clk":"11540466933","pt":1719494844129,"mc":[{"id":"1.230178307","rc":[{"atb":[[2.88,2],[2.84,7.48]],"id":47801105}],"con":true,"img":false}]}
{"op":"mcm","clk":"11540466942","pt":1719494844224,"mc":[{"id":"1.230178307","rc":[{"atb":[[2.88,7.39],[2.84,0.09]],"id":47801105}],"con":true,"img":false}]}
{"op":"mcm","clk":"11540466949","pt":1719494844326,"mc":[{"id":"1.230178307","rc":[{"atb":[[2.88,2],[2.84,7.48]],"id":47801105}],"con":true,"img":false}]}
{"op":"mcm","clk":"11540466959","pt":1719494844429,"mc":[{"id":"1.230178307","rc":[{"atb":[[2.88,7.39],[2.84,0.09]],"id":47801105}],"con":true,"img":false}]}
{"op":"mcm","clk":"11540466994","pt":1719494844842,"mc":[{"id":"1.230178307","rc":[{"atb":[[1.48,0]],"id":53893973}],"con":true,"img":false}]}
{"op":"mcm","clk":"11540467539","pt":1719494850836,"mc":[{"id":"1.230178307","rc":[{"atb":[[2.9,4.68]],"id":47801105}],"con":true,"img":false}]}
{"op":"mcm","clk":"11540467559","pt":1719494851043,"mc":[{"id":"1.230178307","rc":[{"atb":[[2.86,0.15]],"id":47801105},{"atb":[[1.56,7.56]],"id":53893973},{"atl":[[2.68,6.76]],"id":53893973}],"con":true,"img":false}]}
{"op":"mcm","clk":"11540467570","pt":1719494851147,"mc":[{"id":"1.230178307","rc":[{"atb":[[1.56,17.07]],"id":53893973},{"atl":[[2.7,0]],"id":53893973}],"con":true,"img":false}]}
{"op":"mcm","clk":"11540467579","pt":1719494851250,"mc":[{"id":"1.230178307","rc":[{"atb":[[1.54,2]],"id":53893973},{"atl":[[3.6,28.85],[3.05,1]],"id":53893973}],"con":true,"img":false}]}
{"op":"mcm","clk":"11540467614","pt":1719494851562,"mc":[{"id":"1.230178307","rc":[{"atb":[[1.03,5.11]],"id":47801105},{"atl":[[1000,6.99]],"id":47801105}],"con":true,"img":false}]}
{"op":"mcm","clk":"11540467627","pt":1719494851666,"mc":[{"id":"1.230178307","rc":[{"atb":[[1.03,6.81]],"id":47801105}],"con":true,"img":false}]}
{"op":"mcm","clk":"11540467647","pt":1719494851833,"mc":[{"id":"1.230178307","rc":[{"atb":[[1.03,2]],"id":47801105},{"atl":[[1000,0.35]],"id":47801105}],"con":true,"img":false}]}
{"op":"mcm","clk":"11540467655","pt":1719494851934,"mc":[{"id":"1.230178307","rc":[{"atb":[[1.03,0.39]],"id":47801105}],"con":true,"img":false}]}
{"op":"mcm","clk":"11540467671","pt":1719494852140,"mc":[{"id":"1.230178307","rc":[{"atb":[[2.88,5.39],[1.03,0]],"id":47801105},{"atl":[[1000,0.17]],"id":47801105}],"con":true,"img":false}]}
{"op":"mcm","clk":"11540467682","pt":1719494852235,"mc":[{"id":"1.230178307","rc":[{"atb":[[2.92,2.39],[2.88,0],[2.86,10.22]],"id":47801105},{"atl":[[5.3,1.02]],"id":47801105}],"con":true,"img":false}]}
{"op":"mcm","clk":"11540467692","pt":1719494852340,"mc":[{"id":"1.230178307","rc":[{"atl":[[5.3,6.32]],"id":47801105}],"con":true,"img":false}]}
{"op":"mcm","clk":"11540467709","pt":1719494852545,"mc":[{"id":"1.230178307","rc":[{"atl":[[5.4,0.06]],"id":47801105}],"con":true,"img":false}]}
{"op":"mcm","clk":"11540467742","pt":1719494852855,"mc":[{"id":"1.230178307","rc":[{"atb":[[1.54,0]],"id":53893973}],"con":true,"img":false}]}
{"op":"mcm","clk":"11540467756","pt":1719494852958,"mc":[{"id":"1.230178307","rc":[{"atb":[[1.57,2]],"id":53893973}],"con":true,"img":false}]}
{"op":"mcm","clk":"11540467781","pt":1719494853165,"mc":[{"id":"1.230178307","rc":[{"atl":[[5.5,0]],"id":47801105}],"con":true,"img":false}]}
{"op":"mcm","clk":"11540467805","pt":1719494853339,"mc":[{"id":"1.230178307","rc":[{"atb":[[2.92,4.98]],"id":47801105},{"atb":[[1.57,6]],"id":53893973},{"atb":[[2.58,3]],"id":66596720}],"con":true,"img":false}]}
{"op":"mcm","clk":"11540467819","pt":1719494853432,"mc":[{"id":"1.230178307","rc":[{"atb":[[2.58,10.06]],"id":66596720}],"con":true,"img":false}]}
{"op":"mcm","clk":"11540467839","pt":1719494853642,"mc":[{"id":"1.230178307","rc":[{"atb":[[2.56,2]],"id":66596720}],"con":true,"img":false}]}
{"op":"mcm","clk":"11540467977","pt":1719494855344,"mc":[{"id":"1.230178307","rc":[{"atb":[[2.56,0]],"id":66596720}],"con":true,"img":false}]}
{"op":"mcm","clk":"11540467988","pt":1719494855449,"mc":[{"id":"1.230178307","rc":[{"atb":[[2.6,2]],"id":66596720}],"con":true,"img":false}]}
{"op":"mcm","clk":"11540468278","pt":1719494858453,"mc":[{"id":"1.230178307","rc":[{"atb":[[2.94,4.98]],"id":47801105}],"con":true,"img":false}]}
{"op":"mcm","clk":"11540468289","pt":1719494858556,"mc":[{"id":"1.230178307","rc":[{"atb":[[2.86,0.15]],"id":47801105}],"con":true,"img":false}]}
{"op":"mcm","clk":"11540468394","pt":1719494859973,"mc":[{"id":"1.230178307","rc":[{"atb":[[2.92,2.98]],"id":47801105}],"con":true,"img":false}]}
{"op":"mcm","clk":"11540468402","pt":1719494860045,"mc":[{"id":"1.230178307","rc":[{"atb":[[2.96,2]],"id":47801105}],"con":true,"img":false}]}
{"op":"mcm","clk":"11540468710","pt":1719494864163,"mc":[{"id":"1.230178307","rc":[{"atb":[[2.98,3.74]],"id":47801105}],"con":true,"img":false}]}
{"op":"mcm","clk":"11540468734","pt":1719494864359,"mc":[{"id":"1.230178307","rc":[{"atb":[[2.84,0],[2.92,2.59],[2.9,0],[2.86,0]],"id":47801105},{"atl":[[5.3,6.14],[5.4,0]],"id":47801105},{"atb":[[2.98,0]],"id":47095746},{"atl":[[4.9,0]],"id":47095746},{"atb":[[2.44,0]],"id":61496663},{"atl":[[4.1,0]],"id":61496663}],"con":true,"img":false}]}
{"op":"mcm","clk":"11540468741","pt":1719494864464,"mc":[{"id":"1.230178307","rc":[{"atb":[[1.57,15.58]],"id":53893973},{"atl":[[6.2,1],[7,7.06]],"id":47095746},{"atl":[[4.2,0],[4.7,8.54]],"id":61496663}],"con":true,"img":false}]}
{"op":"mcm","clk":"11540468758","pt":1719494864672,"mc":[{"id":"1.230178307","rc":[{"atb":[[1.56,7.56]],"id":53893973}],"con":true,"img":false}]}
{"op":"mcm","clk":"11540468777","pt":1719494864881,"mc":[{"id":"1.230178307","rc":[{"atb":[[1.59,9.37]],"id":53893973}],"con":true,"img":false}]}
{"op":"mcm","clk":"11540468792","pt":1719494865061,"mc":[{"id":"1.230178307","rc":[{"atl":[[5.1,2.5]],"id":53987475}],"con":true,"img":false}]}
{"op":"mcm","clk":"11540468802","pt":1719494865151,"mc":[{"id":"1.230178307","rc":[{"atb":[[1.59,16.06]],"id":53893973},{"atl":[[5.2,0]],"id":53987475}],"con":true,"img":false}]}
{"op":"mcm","clk":"11540468842","pt":1719494865664,"mc":[{"id":"1.230178307","rc":[{"atb":[[2.96,0]],"id":47801105}],"con":true,"img":false}]}
{"op":"mcm","clk":"11540468850","pt":1719494865766,"mc":[{"id":"1.230178307","rc":[{"atb":[[3,2]],"id":47801105}],"con":true,"img":false}]}
{"op":"mcm","clk":"11540468856","pt":1719494865871,"mc":[{"id":"1.230178307","rc":[{"atb":[[3,5.74],[2.98,0],[2.94,0],[3.05,4.68]],"id":47801105}],"con":true,"img":false}]}
{"op":"mcm","clk":"11540468871","pt":1719494866078,"mc":[{"id":"1.230178307","rc":[{"atb":[[1.62,2.11],[1.52,0]],"id":53893973}],"con":true,"img":false}]}
{"op":"mcm","clk":"11540468929","pt":1719494866755,"mc":[{"id":"1.230178307","rc":[{"atb":[[2.6,10.09]],"id":66596720}],"con":true,"img":false}]}
{"op":"mcm","clk":"11540468940","pt":1719494866964,"mc":[{"id":"1.230178307","rc":[{"atb":[[2.58,3]],"id":66596720}],"con":true,"img":false}]}
{"op":"mcm","clk":"11540468981","pt":1719494867452,"mc":[{"id":"1.230178307","rc":[{"atb":[[2.92,0]],"id":47801105},{"atb":[[1.57,11.58]],"id":53893973},{"atb":[[2.58,0]],"id":66596720}],"con":true,"img":false}]}
{"op":"mcm","clk":"11540468993","pt":1719494867553,"mc":[{"id":"1.230178307","rc":[{"atb":[[3.1,3]],"id":47801105},{"atb":[[1.62,5.43]],"id":53893973},{"atb":[[2.62,3]],"id":66596720}],"con":true,"img":false}]}
{"op":"mcm","clk":"11540469054","pt":1719494868278,"mc":[{"id":"1.230178307","rc":[{"atb":[[3,3.74]],"id":47801105}],"con":true,"img":false}]}
{"op":"mcm","clk":"11540469070","pt":1719494868381,"mc":[{"id":"1.230178307","rc":[{"atb":[[3.15,2]],"id":47801105}],"con":true,"img":false}]}
{"op":"mcm","clk":"11540469101","pt":1719494868754,"mc":[{"id":"1.230178307","rc":[{"atb":[[1.57,9.58]],"id":53893973}],"con":true,"img":false}]}
{"op":"mcm","clk":"11540469109","pt":1719494868855,"mc":[{"id":"1.230178307","rc":[{"atb":[[1.63,2]],"id":53893973}],"con":true,"img":false}]}
{"op":"mcm","clk":"11540469135","pt":1719494869265,"mc":[{"id":"1.230178307","rc":[{"atb":[[2.6,8.09]],"id":66596720}],"con":true,"img":false}]}
{"op":"mcm","clk":"11540469145","pt":1719494869370,"mc":[{"id":"1.230178307","rc":[{"atb":[[2.64,2]],"id":66596720}],"con":true,"img":false}]}
{"op":"mcm","clk":"11540469163","pt":1719494869577,"mc":[{"id":"1.230178307","rc":[{"atl":[[4.7,1],[5.4,15.3]],"id":61496663}],"con":true,"img":false}]}
{"op":"mcm","clk":"11540469272","pt":1719494870984,"mc":[{"id":"1.230178307","rc":[{"atb":[[2.92,6.74],[3,0]],"id":47801105}],"con":true,"img":false}]}
{"op":"mcm","clk":"11540469793","pt":1719494877266,"mc":[{"id":"1.230178307","rc":[{"atb":[[3.15,6.12]],"id":47801105},{"spn":4.22,"spf":"NaN","id":47801105},{"spn":2.15,"spf":"NaN","id":53893973},{"spn":3.98,"spf":"NaN","id":47095746},{"spn":3.21,"spf":"NaN","id":61496663},{"spn":3.42,"spf":"NaN","id":66596720}],"con":true,"img":false}]}
{"op":"mcm","clk":"11540469803","pt":1719494877361,"mc":[{"id":"1.230178307","rc":[{"atb":[[3.05,0]],"id":47801105}],"con":true,"img":false}]}
{"op":"mcm","clk":"11540469855","pt":1719494878078,"mc":[{"id":"1.230178307","rc":[{"atb":[[2.56,0],[2.6,5],[2.68,2.5]],"id":47801105}],"con":true,"img":false}]}
{"op":"mcm","clk":"11540470000","pt":1719494879793,"mc":[{"id":"1.230178307","rc":[{"atb":[[2.64,10.32]],"id":66596720}],"con":true,"img":false}]}
{"op":"mcm","clk":"11540470015","pt":1719494879968,"mc":[{"id":"1.230178307","rc":[{"atb":[[2.6,0]],"id":66596720}],"con":true,"img":false}]}
{"op":"mcm","clk":"11540470047","pt":1719494880280,"mc":[{"id":"1.230178307","rc":[{"atb":[[3.15,16.83]],"id":47801105}],"con":true,"img":false}]}
{"op":"mcm","clk":"11540470199","pt":1719494881681,"mc":[{"id":"1.230178307","rc":[{"atb":[[1.6,5.33]],"id":53893973}],"con":true,"img":false}]}
{"op":"mcm","clk":"11540470219","pt":1719494881891,"mc":[{"id":"1.230178307","rc":[{"atb":[[3.1,0]],"id":47801105},{"atb":[[2.62,0]],"id":66596720}],"con":true,"img":false}]}
{"op":"mcm","clk":"11540470230","pt":1719494881996,"mc":[{"id":"1.230178307","rc":[{"atb":[[3.2,3.2]],"id":47801105},{"atb":[[2.66,2.25]],"id":66596720}],"con":true,"img":false}]}
{"op":"mcm","clk":"11540470241","pt":1719494882102,"mc":[{"id":"1.230178307","rc":[{"atb":[[3.2,10.21]],"id":47801105}],"con":true,"img":false}]}
{"op":"mcm","clk":"11540470248","pt":1719494882191,"mc":[{"id":"1.230178307","rc":[{"atb":[[2.62,3.5]],"id":66596720}],"con":true,"img":false}]}
{"op":"mcm","clk":"11540470260","pt":1719494882276,"mc":[{"id":"1.230178307","rc":[{"atb":[[3.15,12.71]],"id":47801105}],"con":true,"img":false}]}
{"op":"mcm","clk":"11540470329","pt":1719494883167,"mc":[{"id":"1.230178307","rc":[{"atb":[[3.15,0]],"id":47801105}],"con":true,"img":false}]}
{"op":"mcm","clk":"11540470338","pt":1719494883277,"mc":[{"id":"1.230178307","rc":[{"atb":[[3.25,2]],"id":47801105}],"con":true,"img":false}]}
{"op":"mcm","clk":"11540470364","pt":1719494883493,"mc":[{"id":"1.230178307","rc":[{"atb":[[2.64,8.32]],"id":66596720}],"con":true,"img":false}]}
{"op":"mcm","clk":"11540470375","pt":1719494883578,"mc":[{"id":"1.230178307","rc":[{"atb":[[2.68,2]],"id":66596720}],"con":true,"img":false}]}
{"op":"mcm","clk":"11540470403","pt":1719494883997,"mc":[{"id":"1.230178307","rc":[{"atb":[[3.25,12.16]],"id":47801105}],"con":true,"img":false}]}
{"op":"mcm","clk":"11540470434","pt":1719494884286,"mc":[{"id":"1.230178307","rc":[{"atb":[[1.59,9.37]],"id":53893973}],"con":true,"img":false}]}
{"op":"mcm","clk":"11540470455","pt":1719494884477,"mc":[{"id":"1.230178307","rc":[{"atb":[[1.59,0]],"id":53893973}],"con":true,"img":false}]}
{"op":"mcm","clk":"11540470486","pt":1719494884783,"mc":[{"id":"1.230178307","rc":[{"atb":[[1.6,14.55]],"id":53893973}],"con":true,"img":false}]}
{"op":"mcm","clk":"11540470525","pt":1719494885199,"mc":[{"id":"1.230178307","rc":[{"atb":[[3.15,3.25]],"id":47801105}],"con":true,"img":false}]}
{"op":"mcm","clk":"11540470706","pt":1719494887081,"mc":[{"id":"1.230178307","rc":[{"atb":[[3.15,0]],"id":47801105}],"con":true,"img":false}]}
{"op":"mcm","clk":"11540470964","pt":1719494890075,"mc":[{"id":"1.230178307","rc":[{"atb":[[3.3,9.67]],"id":47801105}],"con":true,"img":false}]}
{"op":"mcm","clk":"11540470981","pt":1719494890288,"mc":[{"id":"1.230178307","rc":[{"atb":[[3.2,3.2]],"id":47801105}],"con":true,"img":false}]}
{"op":"mcm","clk":"11540471000","pt":1719494890513,"mc":[{"id":"1.230178307","rc":[{"atb":[[3.25,2]],"id":47801105}],"con":true,"img":false}]}
{"op":"mcm","clk":"11540471077","pt":1719494891386,"mc":[{"id":"1.230178307","rc":[{"atb":[[3.3,18.45]],"id":47801105}],"con":true,"img":false}]}
{"op":"mcm","clk":"11540471115","pt":1719494891998,"mc":[{"id":"1.230178307","rc":[{"atb":[[1.64,9.26]],"id":53893973}],"con":true,"img":false}]}
{"op":"mcm","clk":"11540471158","pt":1719494892483,"mc":[{"id":"1.230178307","rc":[{"atb":[[1.56,0]],"id":53893973},{"atb":[[2.68,9.9]],"id":66596720}],"con":true,"img":false}]}
{"op":"mcm","clk":"11540471170","pt":1719494892691,"mc":[{"id":"1.230178307","rc":[{"atb":[[2.64,0]],"id":66596720}],"con":true,"img":false}]}
{"op":"mcm","clk":"11540471212","pt":1719494893204,"mc":[{"id":"1.230178307","rc":[{"atb":[[3.25,0]],"id":47801105}],"con":true,"img":false}]}
{"op":"mcm","clk":"11540471225","pt":1719494893309,"mc":[{"id":"1.230178307","rc":[{"atb":[[3.35,2]],"id":47801105}],"con":true,"img":false}]}
{"op":"mcm","clk":"11540471292","pt":1719494893799,"mc":[{"id":"1.230178307","rc":[{"atb":[[1.63,0]],"id":53893973},{"atl":[[6.2,10],[5.3,2.5],[5.7,5],[5.4,12.8]],"id":61496663}],"con":true,"img":false}]}
{"op":"mcm","clk":"11540471302","pt":1719494893901,"mc":[{"id":"1.230178307","rc":[{"atb":[[1.65,2]],"id":53893973}],"con":true,"img":false}]}
{"op":"mcm","clk":"11540471337","pt":1719494894315,"mc":[{"id":"1.230178307","rc":[{"atb":[[2.62,0]],"id":66596720}],"con":true,"img":false}]}
{"op":"mcm","clk":"11540471342","pt":1719494894384,"mc":[{"id":"1.230178307","rc":[{"atb":[[3.3,9.67]],"id":47801105}],"con":true,"img":false}]}
{"op":"mcm","clk":"11540471363","pt":1719494894691,"mc":[{"id":"1.230178307","rc":[{"atb":[[1.62,3.32],[1.67,2.11]],"id":53893973}],"con":true,"img":false}]}
{"op":"mcm","clk":"11540471373","pt":1719494894808,"mc":[{"id":"1.230178307","rc":[{"atb":[[3.35,6.28]],"id":47801105}],"con":true,"img":false}]}
{"op":"mcm","clk":"11540471390","pt":1719494894993,"mc":[{"id":"1.230178307","rc":[{"atb":[[3.3,0]],"id":47801105},{"atl":[[3.6,26.35],[3.95,10],[3.55,2.5],[3.75,5]],"id":53893973},{"atb":[[2.8,0],[3,2.5],[2.84,10],[2.92,5],[2.88,0],[2.96,4.52]],"id":47095746},{"atl":[[5,0.84]],"id":47095746}],"con":true,"img":false}]}
{"op":"mcm","clk":"11540471401","pt":1719494895102,"mc":[{"id":"1.230178307","rc":[{"atb":[[2.98,6.4]],"id":47095746},{"atl":[[5.1,3.75]],"id":47095746}],"con":true,"img":false}]}
{"op":"mcm","clk":"11540471410","pt":1719494895210,"mc":[{"id":"1.230178307","rc":[{"atb":[[3.35,14.99]],"id":47801105},{"atl":[[7.2,0],[7,1]],"id":47801105},{"atl":[[3.15,1],[3.05,0]],"id":53893973},{"atl":[[4.6,1],[4.7,0]],"id":61496663},{"atl":[[4.8,1],[4.6,1],[4.7,0]],"id":66596720}],"con":true,"img":false}]}
{"op":"mcm","clk":"11540471425","pt":1719494895307,"mc":[{"id":"1.230178307","rc":[{"atl":[[7.4,7.15],[8.4,0]],"id":47801105},{"atl":[[3.6,0],[3.15,8.77]],"id":53893973},{"atb":[[2.96,0]],"id":47095746},{"atl":[[5.4,0],[4.7,8.52]],"id":61496663},{"atl":[[4.8,10.29],[5.2,2.5]],"id":66596720}],"con":true,"img":false}]}
{"op":"mcm","clk":"11540471438","pt":1719494895410,"mc":[{"id":"1.230178307","rc":[{"atl":[[7.2,1],[7,0]],"id":47801105},{"atb":[[2.4,0]],"id":47095746},{"atl":[[6.2,0],[6,1]],"id":47095746},{"atl":[[4.7,9.52]],"id":61496663},{"atl":[[4.8,9.29],[4.6,0]],"id":66596720}],"con":true,"img":false}]}
{"op":"mcm","clk":"11540471448","pt":1719494895515,"mc":[{"id":"1.230178307","rc":[{"atl":[[4.6,0],[5.3,7.76],[4.7,1]],"id":61496663}],"con":true,"img":false}]}
{"op":"mcm","clk":"11540471463","pt":1719494895684,"mc":[{"id":"1.230178307","rc":[{"atl":[[5.3,2.5],[4.7,6.26]],"id":61496663}],"con":true,"img":false}]}
{"op":"mcm","clk":"11540471471","pt":1719494895790,"mc":[{"id":"1.230178307","rc":[{"atl":[[5.8,1],[6,0]],"id":47095746},{"atl":[[4.8,10.29]],"id":66596720}],"con":true,"img":false}]}
{"op":"mcm","clk":"11540471481","pt":1719494895988,"mc":[{"id":"1.230178307","rc":[{"atb":[[3.2,0]],"id":47801105},{"atb":[[1.62,0]],"id":53893973},{"atl":[[5,6.52]],"id":47095746},{"atb":[[2.66,0],[2.68,23.18]],"id":66596720},{"atl":[[4.8,1],[5.2,21.08]],"id":66596720}],"con":true,"img":false}]}
{"op":"mcm","clk":"11540471486","pt":1719494896095,"mc":[{"id":"1.230178307","rc":[{"atb":[[1.67,6.31]],"id":53893973},{"atb":[[3,4.5]],"id":47095746},{"atb":[[2.44,2.07]],"id":61496663},{"atb":[[2.7,2.8]],"id":66596720},{"atb":[[2.54,2]],"id":53987475}],"con":true,"img":false}]}
{"op":"mcm","clk":"11540471496","pt":1719494896201,"mc":[{"id":"1.230178307","rc":[{"atb":[[2.44,7.14]],"id":61496663},{"atb":[[2.54,7.11]],"id":53987475}],"con":true,"img":false}]}
{"op":"mcm","clk":"11540471517","pt":1719494896404,"mc":[{"id":"1.230178307","rc":[{"atb":[[2.42,2.5]],"id":61496663},{"atb":[[2.52,2]],"id":53987475}],"con":true,"img":false}]}
{"op":"mcm","clk":"11540471545","pt":1719494896778,"mc":[{"id":"1.230178307","rc":[{"atb":[[3.35,6.27]],"id":47801105},{"atb":[[2.68,9.9]],"id":66596720}],"con":true,"img":false}]}
{"op":"mcm","clk":"11540471588","pt":1719494897306,"mc":[{"id":"1.230178307","rc":[{"atl":[[2.7,3.18]],"id":53893973}],"con":true,"img":false}]}
{"op":"mcm","clk":"11540471612","pt":1719494897500,"mc":[{"id":"1.230178307","rc":[{"atb":[[1.65,0]],"id":53893973},{"atb":[[2.7,17.55]],"id":66596720}],"con":true,"img":false}]}
{"op":"mcm","clk":"11540471622","pt":1719494897603,"mc":[{"id":"1.230178307","rc":[{"atb":[[1.68,2]],"id":53893973}],"con":true,"img":false}]}
{"op":"mcm","clk":"11540471662","pt":1719494898085,"mc":[{"id":"1.230178307","rc":[{"atb":[[2.52,0]],"id":53987475}],"con":true,"img":false}]}
{"op":"mcm","clk":"11540471668","pt":1719494898193,"mc":[{"id":"1.230178307","rc":[{"atb":[[2.56,2]],"id":53987475}],"con":true,"img":false}]}
{"op":"mcm","clk":"11540471688","pt":1719494898513,"mc":[{"id":"1.230178307","rc":[{"atb":[[2.68,7.9]],"id":66596720}],"con":true,"img":false}]}
{"op":"mcm","clk":"11540471700","pt":1719494898616,"mc":[{"id":"1.230178307","rc":[{"atb":[[2.72,2]],"id":66596720}],"con":true,"img":false}]}
{"op":"mcm","clk":"11540471726","pt":1719494898908,"mc":[{"id":"1.230178307","rc":[{"atl":[[2.7,0]],"id":53893973}],"con":true,"img":false}]}
{"op":"mcm","clk":"11540471830","pt":1719494900515,"mc":[{"id":"1.230178307","rc":[{"atl":[[3.15,1],[3.55,18.04]],"id":53893973}],"con":true,"img":false}]}
{"op":"mcm","clk":"11540471851","pt":1719494900831,"mc":[{"id":"1.230178307","rc":[{"atb":[[2.92,0],[2.6,17.56]],"id":47801105},{"atl":[[9,0],[8.2,0],[9.8,0],[7,2.5],[7.8,5]],"id":47801105},{"atb":[[1.68,11.82]],"id":53893973},{"atb":[[2.52,12.8],[2.76,0]],"id":47095746},{"atl":[[5.6,11.28],[5.8,0],[6.8,0],[7.6,0],[7,0],[6.6,2.5],[8.4,0]],"id":47095746},{"atb":[[2.32,10],[2.16,0]],"id":61496663},{"atl":[[5.3,13.02],[4.7,1]],"id":61496663},{"atb":[[2.3,0],[2.22,0],[2.48,2.5],[2.4,5],[2.02,10],[2.38,0]],"id":66596720},{"atl":[[4.8,0],[4.9,1]],"id":66596720},{"atb":[[2.36,7.5],[2.22,0]],"id":53987475}],"con":true,"img":false}]}
{"op":"mcm","clk":"11540471861","pt":1719494900893,"mc":[{"id":"1.230178307","rc":[{"atb":[[2.24,10]],"id":66596720},{"atl":[[4.8,16.58],[5.2,2.5]],"id":66596720}],"con":true,"img":false}]}
{"op":"mcm","clk":"11540471872","pt":1719494901007,"mc":[{"id":"1.230178307","rc":[{"atb":[[2.6,5],[2.84,12.56]],"id":47801105},{"atb":[[2.52,0],[2.76,11.4]],"id":47095746},{"atb":[[2.02,0]],"id":66596720}],"con":true,"img":false}]}
{"op":"mcm","clk":"11540471878","pt":1719494901100,"mc":[{"id":"1.230178307","rc":[{"atb":[[1.57,0]],"id":53893973}],"con":true,"img":false}]}
{"op":"mcm","clk":"11540471894","pt":1719494901310,"mc":[{"id":"1.230178307","rc":[{"atb":[[1.6,9.22]],"id":53893973}],"con":true,"img":false}]}
{"op":"mcm","clk":"11540471912","pt":1719494901505,"mc":[{"id":"1.230178307","rc":[{"atl":[[7,6.41]],"id":47801105}],"con":true,"img":false}]}
{"op":"mcm","clk":"11540471918","pt":1719494901610,"mc":[{"id":"1.230178307","rc":[{"atl":[[7.4,0],[6.8,12.3]],"id":47801105}],"con":true,"img":false}]}
{"op":"mcm","clk":"11540471997","pt":1719494902609,"mc":[{"id":"1.230178307","rc":[{"atl":[[7,6.13]],"id":47801105}],"con":true,"img":false}]}
{"op":"mcm","clk":"11540472019","pt":1719494902911,"mc":[{"id":"1.230178307","rc":[{"atl":[[7,2.5]],"id":47801105}],"con":true,"img":false}]}
{"op":"mcm","clk":"11540472027","pt":1719494903016,"mc":[{"id":"1.230178307","rc":[{"atl":[[6.8,15.93]],"id":47801105}],"con":true,"img":false}]}
{"op":"mcm","clk":"11540472157","pt":1719494904593,"mc":[{"id":"1.230178307","rc":[{"atb":[[1.67,2.11]],"id":53893973},{"atb":[[2.7,14.75]],"id":66596720},{"atb":[[2.54,5.11]],"id":53987475}],"con":true,"img":false}]}
{"op":"mcm","clk":"11540472163","pt":1719494904702,"mc":[{"id":"1.230178307","rc":[{"atb":[[1.69,4.1]],"id":53893973},{"atb":[[2.72,6]],"id":66596720},{"atb":[[2.56,4]],"id":53987475}],"con":true,"img":false}]}
{"op":"mcm","clk":"11540472192","pt":1719494905012,"mc":[{"id":"1.230178307","rc":[{"atb":[[2.74,12.14]],"id":66596720}],"con":true,"img":false}]}
{"op":"mcm","clk":"11540472216","pt":1719494905213,"mc":[{"id":"1.230178307","rc":[{"atb":[[2.68,0]],"id":66596720}],"con":true,"img":false}]}
{"op":"mcm","clk":"11540472276","pt":1719494905901,"mc":[{"id":"1.230178307","rc":[{"atb":[[1.68,9.82]],"id":53893973}],"con":true,"img":false}]}
{"op":"mcm","clk":"11540472282","pt":1719494906000,"mc":[{"id":"1.230178307","rc":[{"atb":[[1.7,2]],"id":53893973}],"con":true,"img":false}]}
{"op":"mcm","clk":"11540472309","pt":1719494906417,"mc":[{"id":"1.230178307","rc":[{"atb":[[2.72,4]],"id":66596720}],"con":true,"img":false}]}
{"op":"mcm","clk":"11540472320","pt":1719494906513,"mc":[{"id":"1.230178307","rc":[{"atb":[[2.76,2]],"id":66596720}],"con":true,"img":false}]}
{"op":"mcm","clk":"11540472330","pt":1719494906608,"mc":[{"id":"1.230178307","rc":[{"atb":[[1.66,5.33]],"id":53893973}],"con":true,"img":false}]}
{"op":"mcm","clk":"11540472342","pt":1719494906718,"mc":[{"id":"1.230178307","rc":[{"atb":[[1.71,2.11]],"id":53893973},{"atb":[[2.52,2.11]],"id":53987475}],"con":true,"img":false}]}
{"op":"mcm","clk":"11540472353","pt":1719494906815,"mc":[{"id":"1.230178307","rc":[{"atb":[[1.67,0]],"id":53893973},{"atb":[[2.42,0]],"id":53987475}],"con":true,"img":false}]}
{"op":"mcm","clk":"11540472381","pt":1719494907128,"mc":[{"id":"1.230178307","rc":[{"atb":[[2.7,18.08]],"id":66596720}],"con":true,"img":false}]}
{"op":"mcm","clk":"11540472421","pt":1719494907518,"mc":[{"id":"1.230178307","rc":[{"atb":[[3,13.05]],"id":47095746},{"atl":[[4.9,8.55]],"id":47095746}],"con":true,"img":false}]}
{"op":"mcm","clk":"11540472429","pt":1719494907612,"mc":[{"id":"1.230178307","rc":[{"atb":[[2.98,0]],"id":47095746},{"atl":[[5.1,0]],"id":47095746}],"con":true,"img":false}]}
{"op":"mcm","clk":"11540472441","pt":1719494907818,"mc":[{"id":"1.230178307","rc":[{"atl":[[5,0.84]],"id":47095746}],"con":true,"img":false}]}
{"op":"mcm","clk":"11540472466","pt":1719494908120,"mc":[{"id":"1.230178307","rc":[{"atl":[[4.8,0.84]],"id":47095746}],"con":true,"img":false}]}
{"op":"mcm","clk":"11540472475","pt":1719494908224,"mc":[{"id":"1.230178307","rc":[{"atb":[[1.7,0]],"id":53893973}],"con":true,"img":false}]}
{"op":"mcm","clk":"11540472489","pt":1719494908326,"mc":[{"id":"1.230178307","rc":[{"atb":[[1.72,2]],"id":53893973}],"con":true,"img":false}]}
{"op":"mcm","clk":"11540472515","pt":1719494908599,"mc":[{"id":"1.230178307","rc":[{"atl":[[4.8,7.51]],"id":47095746},{"atb":[[2.56,10.23]],"id":53987475}],"con":true,"img":false}]}
{"op":"mcm","clk":"11540472535","pt":1719494908812,"mc":[{"id":"1.230178307","rc":[{"atb":[[2.54,0]],"id":53987475}],"con":true,"img":false}]}
{"op":"mcm","clk":"11540472560","pt":1719494909109,"mc":[{"id":"1.230178307","rc":[{"atl":[[5,0]],"id":47095746}],"con":true,"img":false}]}
{"op":"mcm","clk":"11540472897","pt":1719494913427,"mc":[{"id":"1.230178307","rc":[{"atb":[[1.69,0]],"id":53893973},{"atb":[[2.72,0]],"id":66596720},{"atb":[[2.56,8.23]],"id":53987475}],"con":true,"img":false}]}
{"op":"mcm","clk":"11540472914","pt":1719494913636,"mc":[{"id":"1.230178307","rc":[{"atb":[[1.72,4.71]],"id":53893973},{"atb":[[2.76,4.81]],"id":66596720}],"con":true,"img":false}]}
{"op":"mcm","clk":"11540472925","pt":1719494913702,"mc":[{"id":"1.230178307","rc":[{"atb":[[1.66,4.8]],"id":53893973}],"con":true,"img":false}]}
{"op":"mcm","clk":"11540472941","pt":1719494913913,"mc":[{"id":"1.230178307","rc":[{"atb":[[1.66,0]],"id":53893973}],"con":true,"img":false}]}
{"op":"mcm","clk":"11540473199","pt":1719494917227,"mc":[{"id":"1.230178307","rc":[{"atb":[[2.76,20.13]],"id":66596720}],"con":true,"img":false}]}
{"op":"mcm","clk":"11540473218","pt":1719494917438,"mc":[{"id":"1.230178307","rc":[{"atb":[[2.74,0]],"id":66596720}],"con":true,"img":false}]}
{"op":"mcm","clk":"11540473278","pt":1719494918029,"mc":[{"id":"1.230178307","rc":[{"atb":[[2.7,14.75]],"id":66596720}],"con":true,"img":false}]}
{"op":"mcm","clk":"11540473369","pt":1719494919007,"mc":[{"id":"1.230178307","rc":[{"atb":[[2.68,3.25]],"id":66596720}],"con":true,"img":false}]}
{"op":"mcm","clk":"11540473410","pt":1719494919431,"mc":[{"id":"1.230178307","rc":[{"atb":[[2.68,0]],"id":66596720}],"con":true,"img":false}]}
{"op":"mcm","clk":"11540473439","pt":1719494919725,"mc":[{"id":"1.230178307","rc":[{"atl":[[4.7,13.91]],"id":47095746}],"con":true,"img":false}]}
{"op":"mcm","clk":"11540473451","pt":1719494919829,"mc":[{"id":"1.230178307","rc":[{"atl":[[4.8,6.6],[4.9,0]],"id":47095746}],"con":true,"img":false}]}
{"op":"mcm","clk":"11540473481","pt":1719494920038,"mc":[{"id":"1.230178307","rc":[{"atl":[[4.8,0.84]],"id":47095746}],"con":true,"img":false}]}
{"op":"mcm","clk":"11540473491","pt":1719494920139,"mc":[{"id":"1.230178307","rc":[{"atl":[[4.6,0.84],[4.7,19.67]],"id":47095746}],"con":true,"img":false}]}
{"op":"mcm","clk":"11540473603","pt":1719494921441,"mc":[{"id":"1.230178307","rc":[{"atl":[[2.7,3.18]],"id":53893973},{"atb":[[2.4,5.9]],"id":61496663},{"atb":[[2.54,3.5]],"id":53987475}],"con":true,"img":false}]}
{"op":"mcm","clk":"11540473613","pt":1719494921544,"mc":[{"id":"1.230178307","rc":[{"atl":[[3.55,2.5],[2.68,9.94]],"id":53893973}],"con":true,"img":false}]}
{"op":"mcm","clk":"11540473632","pt":1719494921751,"mc":[{"id":"1.230178307","rc":[{"atl":[[3.15,14.13],[2.68,6.76]],"id":53893973}],"con":true,"img":false}]}
{"op":"mcm","clk":"11540473661","pt":1719494922026,"mc":[{"id":"1.230178307","rc":[{"atb":[[3,11.05]],"id":47095746},{"atb":[[2.76,17.32]],"id":66596720}],"con":true,"img":false}]}
{"op":"mcm","clk":"11540473680","pt":1719494922225,"mc":[{"id":"1.230178307","rc":[{"atb":[[3.05,3.46]],"id":47095746},{"atb":[[2.78,3.17]],"id":66596720}],"con":true,"img":false}]}
{"op":"mcm","clk":"11540473703","pt":1719494922433,"mc":[{"id":"1.230178307","rc":[{"atb":[[3.05,9.81]],"id":47095746}],"con":true,"img":false}]}
{"op":"mcm","clk":"11540473727","pt":1719494922638,"mc":[{"id":"1.230178307","rc":[{"atb":[[3,2.49]],"id":47095746}],"con":true,"img":false}]}
{"op":"mcm","clk":"11540473788","pt":1719494923232,"mc":[{"id":"1.230178307","rc":[{"atb":[[2.76,15.32]],"id":66596720}],"con":true,"img":false}]}
{"op":"mcm","clk":"11540473798","pt":1719494923328,"mc":[{"id":"1.230178307","rc":[{"atb":[[2.8,2]],"id":66596720}],"con":true,"img":false}]}
{"op":"mcm","clk":"11540473868","pt":1719494924150,"mc":[{"id":"1.230178307","rc":[{"atb":[[2.7,12.77]],"id":66596720}],"con":true,"img":false}]}
{"op":"mcm","clk":"11540473883","pt":1719494924318,"mc":[{"id":"1.230178307","rc":[{"atb":[[2.7,0]],"id":66596720}],"con":true,"img":false}]}
{"op":"mcm","clk":"11540473889","pt":1719494924426,"mc":[{"id":"1.230178307","rc":[{"atb":[[2.8,14.77]],"id":66596720}],"con":true,"img":false}]}
{"op":"mcm","clk":"11540474321","pt":1719494929243,"mc":[{"id":"1.230178307","rc":[{"atb":[[2.82,17.29]],"id":66596720}],"con":true,"img":false}]}
{"op":"mcm","clk":"11540474338","pt":1719494929453,"mc":[{"id":"1.230178307","rc":[{"atb":[[2.8,2],[2.76,0]],"id":66596720}],"con":true,"img":false}]}
{"op":"mcm","clk":"11540474349","pt":1719494929557,"mc":[{"id":"1.230178307","rc":[{"atb":[[2.8,0]],"id":66596720}],"con":true,"img":false}]}
{"op":"mcm","clk":"11540474356","pt":1719494929660,"mc":[{"id":"1.230178307","rc":[{"atb":[[2.84,2]],"id":66596720}],"con":true,"img":false}]}
{"op":"mcm","clk":"11540474364","pt":1719494929763,"mc":[{"id":"1.230178307","rc":[{"atb":[[2.82,0],[2.84,10.59]],"id":66596720}],"con":true,"img":false}]}
{"op":"mcm","clk":"11540474392","pt":1719494930139,"mc":[{"id":"1.230178307","rc":[{"atb":[[2.84,22.56]],"id":66596720}],"con":true,"img":false}]}
{"op":"mcm","clk":"11540474401","pt":1719494930245,"mc":[{"id":"1.230178307","rc":[{"atb":[[1.67,5.33]],"id":53893973}],"con":true,"img":false}]}
{"op":"mcm","clk":"11540474433","pt":1719494930753,"mc":[{"id":"1.230178307","rc":[{"atb":[[2.78,0]],"id":66596720}],"con":true,"img":false}]}
{"op":"mcm","clk":"11540474452","pt":1719494930958,"mc":[{"id":"1.230178307","rc":[{"atb":[[3.4,3]],"id":47801105},{"atb":[[2.86,2.61]],"id":66596720},{"atb":[[2.58,3]],"id":53987475}],"con":true,"img":false}]}
{"op":"mcm","clk":"11540474463","pt":1719494931062,"mc":[{"id":"1.230178307","rc":[{"atb":[[2.58,8.86]],"id":53987475}],"con":true,"img":false}]}
{"op":"mcm","clk":"11540474473","pt":1719494931133,"mc":[{"id":"1.230178307","rc":[{"atb":[[2.84,10.59]],"id":66596720},{"atb":[[2.56,2]],"id":53987475}],"con":true,"img":false}]}
{"op":"mcm","clk":"11540474484","pt":1719494931235,"mc":[{"id":"1.230178307","rc":[{"atb":[[3.4,13.08]],"id":47801105}],"con":true,"img":false}]}
{"op":"mcm","clk":"11540474522","pt":1719494931649,"mc":[{"id":"1.230178307","rc":[{"atl":[[4.6,6.46]],"id":47095746}],"con":true,"img":false}]}
{"op":"mcm","clk":"11540474536","pt":1719494931843,"mc":[{"id":"1.230178307","rc":[{"atl":[[4.7,5.76]],"id":47095746}],"con":true,"img":false}]}
{"op":"mcm","clk":"11540474544","pt":1719494931948,"mc":[{"id":"1.230178307","rc":[{"atb":[[2.78,3.19]],"id":66596720}],"con":true,"img":false}]}
{"op":"mcm","clk":"11540474557","pt":1719494932051,"mc":[{"id":"1.230178307","rc":[{"atl":[[4.7,0]],"id":47095746}],"con":true,"img":false}]}
{"op":"mcm","clk":"11540474565","pt":1719494932155,"mc":[{"id":"1.230178307","rc":[{"atl":[[4.8,0],[4.9,6.89]],"id":47095746}],"con":true,"img":false}]}
{"op":"mcm","clk":"11540474574","pt":1719494932260,"mc":[{"id":"1.230178307","rc":[{"atb":[[2.72,2.5],[2.6,0],[2.68,0]],"id":47801105},{"atb":[[2.86,15.2]],"id":66596720}],"con":true,"img":false}]}
{"op":"mcm","clk":"11540474596","pt":1719494932544,"mc":[{"id":"1.230178307","rc":[{"atl":[[4.9,0]],"id":47095746},{"atb":[[2.54,0]],"id":53987475}],"con":true,"img":false}]}
{"op":"mcm","clk":"11540474605","pt":1719494932645,"mc":[{"id":"1.230178307","rc":[{"atl":[[5.6,1],[6.6,20.25]],"id":47095746}],"con":true,"img":false}]}
{"op":"mcm","clk":"11540474622","pt":1719494932843,"mc":[{"id":"1.230178307","rc":[{"atb":[[3.35,4.27]],"id":47801105}],"con":true,"img":false}]}
{"op":"mcm","clk":"11540474629","pt":1719494932949,"mc":[{"id":"1.230178307","rc":[{"atb":[[3.45,2]],"id":47801105}],"con":true,"img":false}]}
{"op":"mcm","clk":"11540474663","pt":1719494933353,"mc":[{"id":"1.230178307","rc":[{"atb":[[2.56,0]],"id":53987475}],"con":true,"img":false}]}
{"op":"mcm","clk":"11540474676","pt":1719494933456,"mc":[{"id":"1.230178307","rc":[{"atb":[[2.6,2]],"id":53987475}],"con":true,"img":false}]}
{"op":"mcm","clk":"11540474684","pt":1719494933559,"mc":[{"id":"1.230178307","rc":[{"atb":[[3.4,11.47]],"id":47801105}],"con":true,"img":false}]}
{"op":"mcm","clk":"11540474699","pt":1719494933730,"mc":[{"id":"1.230178307","rc":[{"atb":[[3.4,2.99]],"id":47801105},{"atb":[[2.84,8.59]],"id":66596720}],"con":true,"img":false}]}
{"op":"mcm","clk":"11540474712","pt":1719494933838,"mc":[{"id":"1.230178307","rc":[{"atb":[[3.45,10.47]],"id":47801105},{"atb":[[2.88,2]],"id":66596720}],"con":true,"img":false}]}
{"op":"mcm","clk":"11540474824","pt":1719494935241,"mc":[{"id":"1.230178307","rc":[{"atb":[[2.86,2.61]],"id":66596720}],"con":true,"img":false}]}
{"op":"mcm","clk":"11540474949","pt":1719494936653,"mc":[{"id":"1.230178307","rc":[{"atb":[[2.88,15.69]],"id":66596720}],"con":true,"img":false}]}
{"op":"mcm","clk":"11540475188","pt":1719494939550,"mc":[{"id":"1.230178307","rc":[{"atb":[[3.4,0]],"id":47801105},{"spn":4.37,"spf":"NaN","id":47801105},{"spn":2.2,"spf":"NaN","id":53893973},{"spn":3.82,"spf":"NaN","id":47095746},{"atb":[[2.44,5.07]],"id":61496663},{"spn":3.22,"spf":"NaN","id":61496663},{"atb":[[2.86,0]],"id":66596720},{"spn":3.54,"spf":"NaN","id":66596720},{"atb":[[2.58,5.86]],"id":53987475},{"spn":3.4,"spf":"NaN","id":53987475}],"con":true,"img":false}]}
{"op":"mcm","clk":"11540475206","pt":1719494939766,"mc":[{"id":"1.230178307","rc":[{"atb":[[2.9,3.19]],"id":66596720},{"atb":[[2.6,4]],"id":53987475}],"con":true,"img":false}]}
{"op":"mcm","clk":"11540475227","pt":1719494940083,"mc":[{"id":"1.230178307","rc":[{"atb":[[2.4,2.11]],"id":61496663}],"con":true,"img":false}]}
{"op":"mcm","clk":"11540475244","pt":1719494940273,"mc":[{"id":"1.230178307","rc":[{"atb":[[2.88,14.2]],"id":66596720}],"con":true,"img":false}]}
{"op":"mcm","clk":"11540475263","pt":1719494940436,"mc":[{"id":"1.230178307","rc":[{"atb":[[2.88,2]],"id":66596720}],"con":true,"img":false}]}
{"op":"mcm","clk":"11540475275","pt":1719494940555,"mc":[{"id":"1.230178307","rc":[{"atb":[[2.9,15.39]],"id":66596720}],"con":true,"img":false}]}
{"op":"mcm","clk":"11540475314","pt":1719494941048,"mc":[{"id":"1.230178307","rc":[{"atb":[[2.92,12.66]],"id":66596720}],"con":true,"img":false}]}
{"op":"mcm","clk":"11540475322","pt":1719494941163,"mc":[{"id":"1.230178307","rc":[{"atb":[[2.78,0]],"id":66596720}],"con":true,"img":false}]}
{"op":"mcm","clk":"11540475331","pt":1719494941257,"mc":[{"id":"1.230178307","rc":[{"atb":[[2.84,0]],"id":66596720}],"con":true,"img":false}]}
{"op":"mcm","clk":"11540475370","pt":1719494941738,"mc":[{"id":"1.230178307","rc":[{"atb":[[2.88,0]],"id":66596720}],"con":true,"img":false}]}
{"op":"mcm","clk":"11540475383","pt":1719494941849,"mc":[{"id":"1.230178307","rc":[{"atb":[[2.94,2]],"id":66596720}],"con":true,"img":false}]}
{"op":"mcm","clk":"11540475392","pt":1719494941951,"mc":[{"id":"1.230178307","rc":[{"atb":[[2.9,14.91],[2.94,17.71]],"id":66596720}],"con":true,"img":false}]}
{"op":"mcm","clk":"11540475413","pt":1719494942158,"mc":[{"id":"1.230178307","rc":[{"atb":[[2.92,0]],"id":66596720}],"con":true,"img":false}]}
{"op":"mcm","clk":"11540475422","pt":1719494942266,"mc":[{"id":"1.230178307","rc":[{"atb":[[1.64,0]],"id":53893973},{"atb":[[2.9,3.19]],"id":66596720}],"con":true,"img":false}]}
{"op":"mcm","clk":"11540475429","pt":1719494942368,"mc":[{"id":"1.230178307","rc":[{"atb":[[2.92,11.72]],"id":66596720}],"con":true,"img":false}]}
{"op":"mcm","clk":"11540475470","pt":1719494942864,"mc":[{"id":"1.230178307","rc":[{"atb":[[2.6,10.23]],"id":53987475}],"con":true,"img":false}]}
{"op":"mcm","clk":"11540475487","pt":1719494943050,"mc":[{"id":"1.230178307","rc":[{"atb":[[2.92,11.57]],"id":66596720},{"atb":[[2.58,0]],"id":53987475}],"con":true,"img":false}]}
{"op":"mcm","clk":"11540475506","pt":1719494943258,"mc":[{"id":"1.230178307","rc":[{"atb":[[2.92,0]],"id":66596720}],"con":true,"img":false}]}
{"op":"mcm","clk":"11540475514","pt":1719494943360,"mc":[{"id":"1.230178307","rc":[{"atb":[[2.94,29.28]],"id":66596720}],"con":true,"img":false}]}
{"op":"mcm","clk":"11540475601","pt":1719494944349,"mc":[{"id":"1.230178307","rc":[{"atb":[[2.42,6.26]],"id":61496663}],"con":true,"img":false}]}
{"op":"mcm","clk":"11540475691","pt":1719494945352,"mc":[{"id":"1.230178307","rc":[{"atb":[[2.58,3.41]],"id":53987475}],"con":true,"img":false}]}
{"op":"mcm","clk":"11540475731","pt":1719494945867,"mc":[{"id":"1.230178307","rc":[{"atl":[[5,1]],"id":66596720}],"con":true,"img":false}]}
{"op":"mcm","clk":"11540475740","pt":1719494945967,"mc":[{"id":"1.230178307","rc":[{"atl":[[4.9,0]],"id":66596720}],"con":true,"img":false}]}
{"op":"mcm","clk":"11540475843","pt":1719494947161,"mc":[{"id":"1.230178307","rc":[{"atl":[[5.6,5],[6.2,0],[5.3,10.52],[5.2,2.5],[5.7,0]],"id":61496663}],"con":true,"img":false}]}
{"op":"mcm","clk":"11540475888","pt":1719494947673,"mc":[{"id":"1.230178307","rc":[{"atb":[[2.48,2.11],[2.4,0]],"id":61496663}],"con":true,"img":false}]}
{"op":"mcm","clk":"11540475898","pt":1719494947778,"mc":[{"id":"1.230178307","rc":[{"atb":[[2.48,7.18]],"id":61496663}],"con":true,"img":false}]}
{"op":"mcm","clk":"11540475913","pt":1719494947949,"mc":[{"id":"1.230178307","rc":[{"atb":[[2.44,0]],"id":61496663}],"con":true,"img":false}]}
{"op":"mcm","clk":"11540475948","pt":1719494948361,"mc":[{"id":"1.230178307","rc":[{"atb":[[2.9,0]],"id":66596720},{"atb":[[2.6,8.23]],"id":53987475}],"con":true,"img":false}]}
{"op":"mcm","clk":"11540475963","pt":1719494948564,"mc":[{"id":"1.230178307","rc":[{"atb":[[2.96,3.3]],"id":66596720},{"atb":[[2.62,2.3]],"id":53987475}],"con":true,"img":false}]}
{"op":"mcm","clk":"11540475972","pt":1719494948658,"mc":[{"id":"1.230178307","rc":[{"atb":[[2.42,2.5]],"id":61496663}],"con":true,"img":false}]}
{"op":"mcm","clk":"11540475981","pt":1719494948763,"mc":[{"id":"1.230178307","rc":[{"atb":[[2.94,28.65]],"id":66596720}],"con":true,"img":false}]}
{"op":"mcm","clk":"11540475997","pt":1719494948971,"mc":[{"id":"1.230178307","rc":[{"atb":[[2.94,17.71]],"id":66596720}],"con":true,"img":false}]}
{"op":"mcm","clk":"11540476009","pt":1719494949076,"mc":[{"id":"1.230178307","rc":[{"atb":[[2.96,14.24]],"id":66596720}],"con":true,"img":false}]}
{"op":"mcm","clk":"11540476041","pt":1719494949454,"mc":[{"id":"1.230178307","rc":[{"atb":[[2.6,6.23]],"id":53987475}],"con":true,"img":false}]}
{"op":"mcm","clk":"11540476053","pt":1719494949561,"mc":[{"id":"1.230178307","rc":[{"atb":[[2.64,2]],"id":53987475}],"con":true,"img":false}]}
{"op":"mcm","clk":"11540476085","pt":1719494950063,"mc":[{"id":"1.230178307","rc":[{"atb":[[2.94,15.71]],"id":66596720}],"con":true,"img":false}]}
{"op":"mcm","clk":"11540476091","pt":1719494950167,"mc":[{"id":"1.230178307","rc":[{"atb":[[2.98,2]],"id":66596720}],"con":true,"img":false}]}
{"op":"mcm","clk":"11540476115","pt":1719494950547,"mc":[{"id":"1.230178307","rc":[{"atb":[[2.96,3.3]],"id":66596720}],"con":true,"img":false}]}
{"op":"mcm","clk":"11540476142","pt":1719494950957,"mc":[{"id":"1.230178307","rc":[{"atb":[[2.32,0],[2.2,14.38]],"id":61496663}],"con":true,"img":false}]}
{"op":"mcm","clk":"11540476153","pt":1719494951070,"mc":[{"id":"1.230178307","rc":[{"atb":[[2.42,0],[2.26,0],[2.34,0]],"id":61496663}],"con":true,"img":false}]}
{"op":"mcm","clk":"11540476160","pt":1719494951160,"mc":[{"id":"1.230178307","rc":[{"atb":[[2,10],[2.16,2.5],[2.08,5]],"id":61496663}],"con":true,"img":false}]}
{"op":"mcm","clk":"11540476176","pt":1719494951465,"mc":[{"id":"1.230178307","rc":[{"atb":[[2.98,14.04]],"id":66596720}],"con":true,"img":false}]}
{"op":"mcm","clk":"11540476256","pt":1719494952578,"mc":[{"id":"1.230178307","rc":[{"atb":[[3,16.75]],"id":66596720}],"con":true,"img":false}]}
{"op":"mcm","clk":"11540476272","pt":1719494952749,"mc":[{"id":"1.230178307","rc":[{"atb":[[2.94,0]],"id":66596720}],"con":true,"img":false}]}
{"op":"mcm","clk":"11540476294","pt":1719494953164,"mc":[{"id":"1.230178307","rc":[{"atb":[[2.98,12.04]],"id":66596720}],"con":true,"img":false}]}
{"op":"mcm","clk":"11540476299","pt":1719494953266,"mc":[{"id":"1.230178307","rc":[{"atb":[[3.05,2]],"id":66596720}],"con":true,"img":false}]}
{"op":"mcm","clk":"11540476304","pt":1719494953371,"mc":[{"id":"1.230178307","rc":[{"atb":[[2.98,10.19]],"id":66596720}],"con":true,"img":false}]}
{"op":"mcm","clk":"11540476317","pt":1719494953471,"mc":[{"id":"1.230178307","rc":[{"atb":[[3.05,17.25]],"id":66596720}],"con":true,"img":false}]}
{"op":"mcm","clk":"11540476341","pt":1719494953672,"mc":[{"id":"1.230178307","rc":[{"atb":[[3,0],[2.98,0]],"id":66596720}],"con":true,"img":false}]}
{"op":"mcm","clk":"11540476349","pt":1719494953774,"mc":[{"id":"1.230178307","rc":[{"atb":[[2.54,2.5],[3,10.19],[2.48,0],[2.4,0],[2.46,5]],"id":66596720}],"con":true,"img":false}]}
{"op":"mcm","clk":"11540476384","pt":1719494954150,"mc":[{"id":"1.230178307","rc":[{"atb":[[3,0]],"id":66596720}],"con":true,"img":false}]}
{"op":"mcm","clk":"11540476408","pt":1719494954361,"mc":[{"id":"1.230178307","rc":[{"atb":[[2.64,6.96]],"id":53987475}],"con":true,"img":false}]}
{"op":"mcm","clk":"11540476425","pt":1719494954567,"mc":[{"id":"1.230178307","rc":[{"atb":[[2.6,0]],"id":53987475}],"con":true,"img":false}]}
{"op":"mcm","clk":"11540476439","pt":1719494954777,"mc":[{"id":"1.230178307","rc":[{"atb":[[2.58,0]],"id":53987475}],"con":true,"img":false}]}
{"op":"mcm","clk":"11540476459","pt":1719494954984,"mc":[{"id":"1.230178307","rc":[{"atb":[[3.05,28.06]],"id":66596720}],"con":true,"img":false}]}
{"op":"mcm","clk":"11540476506","pt":1719494955460,"mc":[{"id":"1.230178307","rc":[{"atb":[[1.6,0]],"id":53893973}],"con":true,"img":false}]}
{"op":"mcm","clk":"11540476522","pt":1719494955672,"mc":[{"id":"1.230178307","rc":[{"atb":[[1.67,6.87]],"id":53893973}],"con":true,"img":false}]}
{"op":"mcm","clk":"11540476561","pt":1719494956078,"mc":[{"id":"1.230178307","rc":[{"atb":[[2.26,14.38]],"id":61496663},{"atl":[[5,0],[4.9,1]],"id":66596720}],"con":true,"img":false}]}
{"op":"mcm","clk":"11540476574","pt":1719494956181,"mc":[{"id":"1.230178307","rc":[{"atb":[[1.67,5.33]],"id":53893973},{"atb":[[2.2,0]],"id":61496663}],"con":true,"img":false}]}
{"op":"mcm","clk":"11540476631","pt":1719494956668,"mc":[{"id":"1.230178307","rc":[{"atb":[[1.67,0]],"id":53893973}],"con":true,"img":false}]}
{"op":"mcm","clk":"11540476642","pt":1719494956871,"mc":[{"id":"1.230178307","rc":[{"atb":[[2.96,0]],"id":66596720},{"atb":[[2.62,0]],"id":53987475}],"con":true,"img":false}]}
{"op":"mcm","clk":"11540476650","pt":1719494956976,"mc":[{"id":"1.230178307","rc":[{"atb":[[3.1,3.5]],"id":66596720},{"atb":[[2.66,2.8]],"id":53987475}],"con":true,"img":false}]}
{"op":"mcm","clk":"11540476681","pt":1719494957289,"mc":[{"id":"1.230178307","rc":[{"atb":[[3.05,27.62]],"id":66596720}],"con":true,"img":false}]}
{"op":"mcm","clk":"11540476707","pt":1719494957488,"mc":[{"id":"1.230178307","rc":[{"atb":[[3.05,17.25]],"id":66596720}],"con":true,"img":false}]}
{"op":"mcm","clk":"11540476719","pt":1719494957553,"mc":[{"id":"1.230178307","rc":[{"atb":[[3.1,13.87]],"id":66596720},{"atb":[[2.64,4.96]],"id":53987475}],"con":true,"img":false}]}
{"op":"mcm","clk":"11540476729","pt":1719494957653,"mc":[{"id":"1.230178307","rc":[{"atb":[[2.68,2]],"id":53987475}],"con":true,"img":false}]}
{"op":"mcm","clk":"11540476745","pt":1719494957859,"mc":[{"id":"1.230178307","rc":[{"atb":[[3.05,15.25]],"id":66596720}],"con":true,"img":false}]}
{"op":"mcm","clk":"11540476752","pt":1719494957963,"mc":[{"id":"1.230178307","rc":[{"atb":[[1.02,2]],"id":66596720}],"con":true,"img":false}]}
{"op":"mcm","clk":"11540477152","pt":1719494963873,"mc":[{"id":"1.230178307","rc":[{"atb":[[3.15,16.62]],"id":66596720}],"con":true,"img":false}]}
{"op":"mcm","clk":"11540477164","pt":1719494963972,"mc":[{"id":"1.230178307","rc":[{"atb":[[3.05,0]],"id":66596720}],"con":true,"img":false}]}
{"op":"mcm","clk":"11540477268","pt":1719494965477,"mc":[{"id":"1.230178307","rc":[{"atb":[[3.1,9.98]],"id":66596720}],"con":true,"img":false}]}
{"op":"mcm","clk":"11540477274","pt":1719494965582,"mc":[{"id":"1.230178307","rc":[{"atb":[[2.68,7.33]],"id":53987475}],"con":true,"img":false}]}
{"op":"mcm","clk":"11540477281","pt":1719494965684,"mc":[{"id":"1.230178307","rc":[{"atb":[[3.1,0]],"id":66596720}],"con":true,"img":false}]}
{"op":"mcm","clk":"11540477287","pt":1719494965790,"mc":[{"id":"1.230178307","rc":[{"atb":[[3.15,26.6]],"id":66596720},{"atb":[[2.64,0]],"id":53987475}],"con":true,"img":false}]}
{"op":"mcm","clk":"11540477297","pt":1719494965992,"mc":[{"id":"1.230178307","rc":[{"atb":[[3.15,9.98]],"id":66596720}],"con":true,"img":false}]}
{"op":"mcm","clk":"11540477311","pt":1719494966157,"mc":[{"id":"1.230178307","rc":[{"atb":[[2.46,3.66]],"id":61496663},{"atb":[[3.1,9.97],[3.15,0]],"id":66596720}],"con":true,"img":false}]}
{"op":"mcm","clk":"11540477333","pt":1719494966474,"mc":[{"id":"1.230178307","rc":[{"atb":[[3.1,0]],"id":66596720}],"con":true,"img":false}]}
{"op":"mcm","clk":"11540477341","pt":1719494966577,"mc":[{"id":"1.230178307","rc":[{"atb":[[3.05,9.97]],"id":66596720}],"con":true,"img":false}]}
{"op":"mcm","clk":"11540477476","pt":1719494968188,"mc":[{"id":"1.230178307","rc":[{"atb":[[2.66,6.05]],"id":53987475}],"con":true,"img":false}]}
{"op":"mcm","clk":"11540477543","pt":1719494968978,"mc":[{"id":"1.230178307","rc":[{"atb":[[1.02,0]],"id":66596720}],"con":true,"img":false}]}
{"op":"mcm","clk":"11540477552","pt":1719494969082,"mc":[{"id":"1.230178307","rc":[{"atb":[[3.1,2]],"id":66596720}],"con":true,"img":false}]}
{"op":"mcm","clk":"11540477669","pt":1719494970690,"mc":[{"id":"1.230178307","rc":[{"atb":[[3.1,13.5]],"id":66596720}],"con":true,"img":false}]}
{"op":"mcm","clk":"11540477773","pt":1719494972089,"mc":[{"id":"1.230178307","rc":[{"atb":[[3.1,11.5]],"id":66596720}],"con":true,"img":false}]}
{"op":"mcm","clk":"11540477783","pt":1719494972196,"mc":[{"id":"1.230178307","rc":[{"atb":[[1.02,2]],"id":66596720}],"con":true,"img":false}]}
{"op":"mcm","clk":"11540477955","pt":1719494974178,"mc":[{"id":"1.230178307","rc":[{"atb":[[2.66,3.25]],"id":53987475}],"con":true,"img":false}]}
{"op":"mcm","clk":"11540477960","pt":1719494974276,"mc":[{"id":"1.230178307","rc":[{"atb":[[2.5,4]],"id":61496663}],"con":true,"img":false}]}
{"op":"mcm","clk":"11540477970","pt":1719494974380,"mc":[{"id":"1.230178307","rc":[{"atb":[[2.5,9.74]],"id":61496663}],"con":true,"img":false}]}
{"op":"mcm","clk":"11540477988","pt":1719494974593,"mc":[{"id":"1.230178307","rc":[{"atb":[[2.48,2.11]],"id":61496663}],"con":true,"img":false}]}
{"op":"mcm","clk":"11540478042","pt":1719494975005,"mc":[{"id":"1.230178307","rc":[{"atb":[[3.15,13.69]],"id":66596720}],"con":true,"img":false}]}
{"op":"mcm","clk":"11540478055","pt":1719494975111,"mc":[{"id":"1.230178307","rc":[{"atb":[[3.05,0]],"id":66596720}],"con":true,"img":false}]}
{"op":"mcm","clk":"11540478064","pt":1719494975172,"mc":[{"id":"1.230178307","rc":[{"atb":[[2.46,0]],"id":61496663},{"atb":[[3.1,0]],"id":66596720}],"con":true,"img":false}]}
{"op":"mcm","clk":"11540478078","pt":1719494975283,"mc":[{"id":"1.230178307","rc":[{"atb":[[3.15,0]],"id":66596720}],"con":true,"img":false}]}
{"op":"mcm","clk":"11540478088","pt":1719494975382,"mc":[{"id":"1.230178307","rc":[{"atb":[[3.05,9.97]],"id":66596720}],"con":true,"img":false}]}
{"op":"mcm","clk":"11540478315","pt":1719494977983,"mc":[{"id":"1.230178307","rc":[{"atb":[[1.7,5.33]],"id":53893973},{"atb":[[1.02,0]],"id":66596720}],"con":true,"img":false}]}
{"op":"mcm","clk":"11540478325","pt":1719494978085,"mc":[{"id":"1.230178307","rc":[{"atb":[[3.1,2]],"id":66596720}],"con":true,"img":false}]}
{"op":"mcm","clk":"11540478334","pt":1719494978192,"mc":[{"id":"1.230178307","rc":[{"atb":[[3.1,10.09]],"id":66596720}],"con":true,"img":false}]}
{"op":"mcm","clk":"11540478348","pt":1719494978395,"mc":[{"id":"1.230178307","rc":[{"atb":[[3.05,0]],"id":66596720}],"con":true,"img":false}]}
{"op":"mcm","clk":"11540478693","pt":1719494982806,"mc":[{"id":"1.230178307","rc":[{"atb":[[2.56,3.47]],"id":66596720}],"con":true,"img":false}]}
{"op":"mcm","clk":"11540478761","pt":1719494983595,"mc":[{"id":"1.230178307","rc":[{"atb":[[2.72,0],[2.74,2.5]],"id":47801105}],"con":true,"img":false}]}
{"op":"mcm","clk":"11540479026","pt":1719494986926,"mc":[{"id":"1.230178307","rc":[{"atb":[[2.48,5.72]],"id":61496663}],"con":true,"img":false}]}
{"op":"mcm","clk":"11540479084","pt":1719494987595,"mc":[{"id":"1.230178307","rc":[{"atb":[[3.2,14.75],[3.5,12.46]],"id":47801105},{"atb":[[1.46,10],[1.68,0]],"id":53893973},{"atb":[[3,22.12]],"id":47095746},{"atl":[[5.6,0],[5.8,1]],"id":47095746},{"atb":[[2.32,15.47]],"id":61496663},{"atb":[[2.24,0],[3.1,2],[2.42,8.47]],"id":66596720},{"atl":[[4.8,17.58]],"id":66596720},{"atb":[[2.36,0],[2.22,8.25]],"id":53987475}],"con":true,"img":false}]}
{"op":"mcm","clk":"11540479092","pt":1719494987700,"mc":[{"id":"1.230178307","rc":[{"atb":[[3.35,0],[2.84,0]],"id":47801105},{"atb":[[1.39,0]],"id":53893973},{"atb":[[3,2.5],[2.76,0]],"id":47095746},{"atl":[[6,7.47],[6.6,2.5]],"id":47095746},{"atb":[[2.26,0],[2.48,2.11]],"id":61496663},{"atb":[[2.42,0]],"id":66596720},{"atl":[[4.9,0]],"id":66596720}],"con":true,"img":false}]}
{"op":"mcm","clk":"11540479152","pt":1719494987827,"mc":[{"id":"1.230178307","rc":[{"atb":[[3.2,0]],"id":47801105},{"atb":[[2.76,19.81]],"id":47095746},{"atl":[[5.6,1]],"id":47095746},{"atb":[[2.32,0]],"id":61496663},{"atb":[[2.26,5.97]],"id":66596720},{"atl":[[4.8,1]],"id":66596720}],"con":true,"img":false}]}
{"op":"mcm","clk":"11540479166","pt":1719494987919,"mc":[{"id":"1.230178307","rc":[{"atb":[[2.84,24.92],[3.5,0]],"id":47801105},{"atb":[[1.46,0],[1.7,3.94]],"id":53893973},{"atl":[[5.8,0]],"id":47095746},{"atb":[[2.26,19.48]],"id":61496663},{"atb":[[3.1,6.48]],"id":66596720},{"atl":[[4.8,0],[5.2,26.31],[4.9,1]],"id":66596720}],"con":true,"img":false}]}
{"op":"mcm","clk":"11540479175","pt":1719494988025,"mc":[{"id":"1.230178307","rc":[{"atb":[[3.45,1.99]],"id":47801105},{"atb":[[1.42,10]],"id":53893973},{"atl":[[4.9,10.29],[5.2,2.5]],"id":66596720}],"con":true,"img":false}]}
{"op":"mcm","clk":"11540479182","pt":1719494988083,"mc":[{"id":"1.230178307","rc":[{"atb":[[2.36,0],[2.52,2.11]],"id":66596720},{"atl":[[4.9,1],[5.2,11.79]],"id":66596720}],"con":true,"img":false}]}
{"op":"mcm","clk":"11540479239","pt":1719494988604,"mc":[{"id":"1.230178307","rc":[{"atb":[[3.45,0]],"id":47801105}],"con":true,"img":false}]}
{"op":"mcm","clk":"11540479248","pt":1719494988719,"mc":[{"id":"1.230178307","rc":[{"atb":[[2.86,2],[3.4,6.49]],"id":47801105}],"con":true,"img":false}]}
{"op":"mcm","clk":"11540479306","pt":1719494989325,"mc":[{"id":"1.230178307","rc":[{"atb":[[3.4,0]],"id":47801105}],"con":true,"img":false}]}
{"op":"mcm","clk":"11540479320","pt":1719494989390,"mc":[{"id":"1.230178307","rc":[{"atb":[[3.35,9.48]],"id":47801105}],"con":true,"img":false}]}
{"op":"mcm","clk":"11540479590","pt":1719494992609,"mc":[{"id":"1.230178307","rc":[{"atb":[[2.86,0]],"id":47801105}],"con":true,"img":false}]}
{"op":"mcm","clk":"11540479601","pt":1719494992713,"mc":[{"id":"1.230178307","rc":[{"atb":[[3.4,2]],"id":47801105}],"con":true,"img":false}]}
{"op":"mcm","clk":"11540479611","pt":1719494992819,"mc":[{"id":"1.230178307","rc":[{"atb":[[3.4,11.72]],"id":47801105},{"atb":[[2.32,8.25],[2.22,0]],"id":53987475}],"con":true,"img":false}]}
{"op":"mcm","clk":"11540479634","pt":1719494993022,"mc":[{"id":"1.230178307","rc":[{"atl":[[6.8,18.43],[7,0],[7.8,0]],"id":47801105}],"con":true,"img":false}]}
{"op":"mcm","clk":"11540479997","pt":1719494997122,"mc":[{"id":"1.230178307","rc":[{"atb":[[1.7,5.33]],"id":53893973}],"con":true,"img":false}]}
{"op":"mcm","clk":"11540480063","pt":1719494997805,"mc":[{"id":"1.230178307","rc":[{"atl":[[5.6,0],[5.1,2.5],[5.2,0]],"id":61496663}],"con":true,"img":false}]}
{"op":"mcm","clk":"11540480381","pt":1719495001740,"mc":[{"id":"1.230178307","rc":[{"spn":4.35,"spf":"NaN","id":47801105},{"atb":[[2,0],[2.22,2.5],[2.08,0],[2.16,0]],"id":61496663},{"spn":3.25,"spf":"NaN","id":61496663},{"spn":3.65,"spf":"NaN","id":66596720},{"spn":3.44,"spf":"NaN","id":53987475}],"con":true,"img":false}]}
{"op":"mcm","clk":"11540480667","pt":1719495004708,"mc":[{"id":"1.230178307","rc":[{"atb":[[1.72,12.24]],"id":53893973}],"con":true,"img":false}]}
{"op":"mcm","clk":"11540480675","pt":1719495004807,"mc":[{"id":"1.230178307","rc":[{"atb":[[3.35,0]],"id":47801105}],"con":true,"img":false}]}
{"op":"mcm","clk":"11540480737","pt":1719495005644,"mc":[{"id":"1.230178307","rc":[{"atb":[[2.48,5.72]],"id":61496663}],"con":true,"img":false}]}
{"op":"mcm","clk":"11540480751","pt":1719495005839,"mc":[{"id":"1.230178307","rc":[{"atb":[[3.4,1.99]],"id":47801105}],"con":true,"img":false}]}
{"op":"mcm","clk":"11540480820","pt":1719495006734,"mc":[{"id":"1.230178307","rc":[{"atb":[[3.4,0]],"id":47801105}],"con":true,"img":false}]}
{"op":"mcm","clk":"11540480828","pt":1719495006836,"mc":[{"id":"1.230178307","rc":[{"atb":[[2.82,3],[2.86,2]],"id":47801105}],"con":true,"img":false}]}
{"op":"mcm","clk":"11540480839","pt":1719495006938,"mc":[{"id":"1.230178307","rc":[{"atb":[[2.6,27.42],[2.84,6.49]],"id":47801105}],"con":true,"img":false}]}
{"op":"mcm","clk":"11540480854","pt":1719495007049,"mc":[{"id":"1.230178307","rc":[{"atb":[[2.82,0]],"id":47801105}],"con":true,"img":false}]}
{"op":"mcm","clk":"11540481018","pt":1719495008850,"mc":[{"id":"1.230178307","rc":[{"atb":[[1.72,9.53]],"id":53893973}],"con":true,"img":false}]}
{"op":"mcm","clk":"11540481037","pt":1719495009016,"mc":[{"id":"1.230178307","rc":[{"atb":[[2.86,4]],"id":47801105},{"atb":[[1.73,3.85]],"id":53893973}],"con":true,"img":false}]}
{"op":"mcm","clk":"11540481103","pt":1719495009749,"mc":[{"id":"1.230178307","rc":[{"atb":[[1.72,7.53]],"id":53893973}],"con":true,"img":false}]}
{"op":"mcm","clk":"11540481114","pt":1719495009850,"mc":[{"id":"1.230178307","rc":[{"atb":[[1.74,2]],"id":53893973}],"con":true,"img":false}]}
{"op":"mcm","clk":"11540481135","pt":1719495010050,"mc":[{"id":"1.230178307","rc":[{"atb":[[1.7,0]],"id":53893973}],"con":true,"img":false}]}
{"op":"mcm","clk":"11540481288","pt":1719495012049,"mc":[{"id":"1.230178307","rc":[{"atb":[[2.8,10.49],[2.6,0]],"id":47801105}],"con":true,"img":false}]}
{"op":"mcm","clk":"11540481489","pt":1719495014545,"mc":[{"id":"1.230178307","rc":[{"atb":[[1.73,0]],"id":53893973}],"con":true,"img":false}]}
{"op":"mcm","clk":"11540481504","pt":1719495014652,"mc":[{"id":"1.230178307","rc":[{"atb":[[1.74,5.4]],"id":53893973}],"con":true,"img":false}]}
{"op":"mcm","clk":"11540481721","pt":1719495017141,"mc":[{"id":"1.230178307","rc":[{"atb":[[2.86,13.48]],"id":47801105}],"con":true,"img":false}]}
{"op":"mcm","clk":"11540481729","pt":1719495017238,"mc":[{"id":"1.230178307","rc":[{"atb":[[2.84,0]],"id":47801105}],"con":true,"img":false}]}
{"op":"mcm","clk":"11540481977","pt":1719495020349,"mc":[{"id":"1.230178307","rc":[{"atb":[[2.8,0],[2.86,11.48],[2.78,23.97]],"id":47801105}],"con":true,"img":false}]}
{"op":"mcm","clk":"11540481983","pt":1719495020454,"mc":[{"id":"1.230178307","rc":[{"atb":[[2.88,2.3]],"id":47801105}],"con":true,"img":false}]}
{"op":"mcm","clk":"11540482043","pt":1719495021546,"mc":[{"id":"1.230178307","rc":[{"atb":[[2.86,9.48]],"id":47801105}],"con":true,"img":false}]}
{"op":"mcm","clk":"11540482052","pt":1719495021653,"mc":[{"id":"1.230178307","rc":[{"atb":[[2.9,2]],"id":47801105}],"con":true,"img":false}]}
{"op":"mcm","clk":"11540482357","pt":1719495025464,"mc":[{"id":"1.230178307","rc":[{"atb":[[2.8,4.6],[2.78,0]],"id":47801105}],"con":true,"img":false}]}
{"op":"mcm","clk":"11540482404","pt":1719495026250,"mc":[{"id":"1.230178307","rc":[{"atb":[[2.88,0]],"id":47801105}],"con":true,"img":false}]}
{"op":"mcm","clk":"11540482415","pt":1719495026371,"mc":[{"id":"1.230178307","rc":[{"atb":[[2.9,4.39]],"id":47801105}],"con":true,"img":false}]}
{"op":"mcm","clk":"11540482474","pt":1719495027172,"mc":[{"id":"1.230178307","rc":[{"atb":[[2.9,12.45]],"id":47801105}],"con":true,"img":false}]}
{"op":"mcm","clk":"11540482493","pt":1719495027379,"mc":[{"id":"1.230178307","rc":[{"atb":[[2.86,0]],"id":47801105}],"con":true,"img":false}]}
{"op":"mcm","clk":"11540482530","pt":1719495027758,"mc":[{"id":"1.230178307","rc":[{"atb":[[1.71,7.44]],"id":53893973}],"con":true,"img":false}]}
{"op":"mcm","clk":"11540482891","pt":1719495031962,"mc":[{"id":"1.230178307","rc":[{"atb":[[2.9,10.06]],"id":47801105}],"con":true,"img":false}]}
{"op":"mcm","clk":"11540482911","pt":1719495032183,"mc":[{"id":"1.230178307","rc":[{"atb":[[2.92,3.88]],"id":47801105}],"con":true,"img":false}]}
{"op":"mcm","clk":"11540483029","pt":1719495033673,"mc":[{"id":"1.230178307","rc":[{"atb":[[2.9,8.06]],"id":47801105}],"con":true,"img":false}]}
{"op":"mcm","clk":"11540483034","pt":1719495033778,"mc":[{"id":"1.230178307","rc":[{"atb":[[2.94,2]],"id":47801105}],"con":true,"img":false}]}
{"op":"mcm","clk":"11540483318","pt":1719495036991,"mc":[{"id":"1.230178307","rc":[{"atb":[[2.94,9.52]],"id":47801105}],"con":true,"img":false}]}
{"op":"mcm","clk":"11540483335","pt":1719495037197,"mc":[{"id":"1.230178307","rc":[{"atb":[[2.9,0]],"id":47801105}],"con":true,"img":false}]}
{"op":"mcm","clk":"11540483384","pt":1719495037817,"mc":[{"id":"1.230178307","rc":[{"atb":[[2.92,0]],"id":47801105}],"con":true,"img":false}]}
{"op":"mcm","clk":"11540483403","pt":1719495037973,"mc":[{"id":"1.230178307","rc":[{"atb":[[2.96,4]],"id":47801105}],"con":true,"img":false}]}
{"op":"mcm","clk":"11540483523","pt":1719495039383,"mc":[{"id":"1.230178307","rc":[{"atb":[[2.94,7.52]],"id":47801105}],"con":true,"img":false}]}
{"op":"mcm","clk":"11540483531","pt":1719495039482,"mc":[{"id":"1.230178307","rc":[{"atb":[[2.98,2]],"id":47801105}],"con":true,"img":false}]}
{"op":"mcm","clk":"11540483720","pt":1719495041697,"mc":[{"id":"1.230178307","rc":[{"atb":[[1.71,2.11]],"id":53893973},{"atb":[[2.48,2.11]],"id":61496663},{"atb":[[2.66,0]],"id":53987475}],"con":true,"img":false}]}
{"op":"mcm","clk":"11540483817","pt":1719495042895,"mc":[{"id":"1.230178307","rc":[{"atb":[[2.46,3.63]],"id":61496663}],"con":true,"img":false}]}
{"op":"mcm","clk":"11540483885","pt":1719495043691,"mc":[{"id":"1.230178307","rc":[{"atb":[[2.96,0]],"id":47801105}],"con":true,"img":false}]}
{"op":"mcm","clk":"11540483901","pt":1719495043884,"mc":[{"id":"1.230178307","rc":[{"atb":[[2.98,5.4]],"id":47801105}],"con":true,"img":false}]}
{"op":"mcm","clk":"11540484032","pt":1719495045390,"mc":[{"id":"1.230178307","rc":[{"atb":[[1.7,5.33]],"id":53893973}],"con":true,"img":false}]}
{"op":"mcm","clk":"11540484133","pt":1719495046582,"mc":[{"id":"1.230178307","rc":[{"atb":[[3,8.66]],"id":47801105}],"con":true,"img":false}]}
{"op":"mcm","clk":"11540484153","pt":1719495046790,"mc":[{"id":"1.230178307","rc":[{"atb":[[2.94,0]],"id":47801105}],"con":true,"img":false}]}
{"op":"mcm","clk":"11540484293","pt":1719495048195,"mc":[{"id":"1.230178307","rc":[{"atb":[[2.98,3.4]],"id":47801105}],"con":true,"img":false}]}
{"op":"mcm","clk":"11540484302","pt":1719495048293,"mc":[{"id":"1.230178307","rc":[{"atb":[[3.05,2]],"id":47801105}],"con":true,"img":false}]}
{"op":"mcm","clk":"11540484414","pt":1719495049685,"mc":[{"id":"1.230178307","rc":[{"atb":[[2.4,5],[2.32,0]],"id":53987475}],"con":true,"img":false}]}
{"op":"mcm","clk":"11540484424","pt":1719495049797,"mc":[{"id":"1.230178307","rc":[{"atb":[[2.98,0]],"id":47801105}],"con":true,"img":false}]}
{"op":"mcm","clk":"11540484438","pt":1719495049994,"mc":[{"id":"1.230178307","rc":[{"atb":[[3.05,5.4]],"id":47801105}],"con":true,"img":false}]}
{"op":"mcm","clk":"11540484559","pt":1719495051194,"mc":[{"id":"1.230178307","rc":[{"atb":[[2.66,3.25]],"id":53987475}],"con":true,"img":false}]}
{"op":"mcm","clk":"11540484634","pt":1719495051911,"mc":[{"id":"1.230178307","rc":[{"atb":[[2.22,0]],"id":61496663}],"con":true,"img":false}]}
{"op":"mcm","clk":"11540484663","pt":1719495052119,"mc":[{"id":"1.230178307","rc":[{"atb":[[2.52,9.2]],"id":47801105},{"atb":[[1.42,0],[1.52,10.66]],"id":53893973},{"atb":[[2.26,0],[2.7,12.96]],"id":66596720},{"atb":[[2.4,0]],"id":53987475}],"con":true,"img":false}]}
{"op":"mcm","clk":"11540484673","pt":1719495052224,"mc":[{"id":"1.230178307","rc":[{"atb":[[2.8,0]],"id":47801105},{"atb":[[2.24,8.25]],"id":53987475}],"con":true,"img":false}]}
{"op":"mcm","clk":"11540484833","pt":1719495053731,"mc":[{"id":"1.230178307","rc":[{"atb":[[2.68,3.36]],"id":66596720}],"con":true,"img":false}]}
{"op":"mcm","clk":"11540484928","pt":1719495054822,"mc":[{"id":"1.230178307","rc":[{"atl":[[7.2,0],[7,1]],"id":47801105},{"atl":[[5.6,0],[5.8,1]],"id":47095746},{"atl":[[4.6,1],[4.7,0]],"id":61496663}],"con":true,"img":false}]}
{"op":"mcm","clk":"11540484944","pt":1719495054926,"mc":[{"id":"1.230178307","rc":[{"atl":[[4.6,0],[5.3,0],[4.7,9.52]],"id":61496663}],"con":true,"img":false}]}
{"op":"mcm","clk":"11540484955","pt":1719495055032,"mc":[{"id":"1.230178307","rc":[{"atl":[[5,1],[4.9,0]],"id":66596720},{"atl":[[4.5,0],[4.4,1]],"id":53987475}],"con":true,"img":false}]}
{"op":"mcm","clk":"11540484987","pt":1719495055303,"mc":[{"id":"1.230178307","rc":[{"atb":[[1.7,0]],"id":53893973}],"con":true,"img":false}]}
{"op":"mcm","clk":"11540484996","pt":1719495055403,"mc":[{"id":"1.230178307","rc":[{"atb":[[2.46,0]],"id":61496663},{"atb":[[2.68,0]],"id":66596720},{"atb":[[2.66,0]],"id":53987475}],"con":true,"img":false}]}
{"op":"mcm","clk":"11540485009","pt":1719495055517,"mc":[{"id":"1.230178307","rc":[{"atb":[[2.24,2.5],[2.16,5],[2.08,10]],"id":61496663},{"atl":[[5.1,16.28]],"id":61496663},{"atb":[[2.56,0]],"id":66596720},{"atl":[[5.1,5.92]],"id":66596720}],"con":true,"img":false}]}
{"op":"mcm","clk":"11540485017","pt":1719495055605,"mc":[{"id":"1.230178307","rc":[{"atl":[[4.7,1]],"id":61496663},{"atb":[[2.72,2.7]],"id":66596720},{"atl":[[5,17.58],[5.2,2.5]],"id":66596720}],"con":true,"img":false}]}
{"op":"mcm","clk":"11540485039","pt":1719495055806,"mc":[{"id":"1.230178307","rc":[{"atl":[[6.8,19.43],[7,0]],"id":47801105}],"con":true,"img":false}]}
{"op":"mcm","clk":"11540485062","pt":1719495056013,"mc":[{"id":"1.230178307","rc":[{"atb":[[3.1,8.66]],"id":47801105}],"con":true,"img":false}]}
{"op":"mcm","clk":"11540485077","pt":1719495056220,"mc":[{"id":"1.230178307","rc":[{"atb":[[3,0]],"id":47801105}],"con":true,"img":false}]}
{"op":"mcm","clk":"11540485133","pt":1719495056903,"mc":[{"id":"1.230178307","rc":[{"atb":[[1.72,0]],"id":53893973},{"atl":[[6.4,2.5],[6.6,0]],"id":47095746},{"atb":[[2.32,11.86],[2.26,0]],"id":61496663}],"con":true,"img":false}]}
{"op":"mcm","clk":"11540485160","pt":1719495057202,"mc":[{"id":"1.230178307","rc":[{"atb":[[3.05,3.4]],"id":47801105}],"con":true,"img":false}]}
{"op":"mcm","clk":"11540485172","pt":1719495057306,"mc":[{"id":"1.230178307","rc":[{"atb":[[3.15,2]],"id":47801105}],"con":true,"img":false}]}
{"op":"mcm","clk":"11540485376","pt":1719495059735,"mc":[{"id":"1.230178307","rc":[{"atb":[[2.48,5.72]],"id":61496663}],"con":true,"img":false}]}
{"op":"mcm","clk":"11540485508","pt":1719495061132,"mc":[{"id":"1.230178307","rc":[{"atb":[[3.05,0]],"id":47801105}],"con":true,"img":false}]}
{"op":"mcm","clk":"11540485518","pt":1719495061236,"mc":[{"id":"1.230178307","rc":[{"atb":[[3.15,5]],"id":47801105},{"atb":[[2.7,2.17]],"id":53987475}],"con":true,"img":false}]}
{"op":"mcm","clk":"11540485526","pt":1719495061338,"mc":[{"id":"1.230178307","rc":[{"atb":[[1.55,2.11],[1.71,0]],"id":53893973}],"con":true,"img":false}]}
{"op":"mcm","clk":"11540485538","pt":1719495061443,"mc":[{"id":"1.230178307","rc":[{"atb":[[2.7,7.03]],"id":53987475}],"con":true,"img":false}]}
{"op":"mcm","clk":"11540485546","pt":1719495061511,"mc":[{"id":"1.230178307","rc":[{"atb":[[2.68,2]],"id":53987475}],"con":true,"img":false}]}
{"op":"mcm","clk":"11540485574","pt":1719495061807,"mc":[{"id":"1.230178307","rc":[{"atb":[[2.52,0],[2.62,10]],"id":47801105},{"spn":4.22,"spf":"NaN","id":47801105},{"atl":[[3.2,1],[3.15,13.13]],"id":53893973},{"spn":2.21,"spf":"NaN","id":53893973},{"atb":[[2.82,14.81],[2.76,0]],"id":47095746},{"atl":[[5.6,1],[5.8,0],[5.5,1]],"id":47095746},{"atb":[[2.8,12.96],[2.7,0]],"id":66596720},{"atl":[[5.1,6.92],[5,16.58]],"id":66596720},{"atl":[[4.5,1],[4.4,0]],"id":53987475},{"spn":3.45,"spf":"NaN","id":53987475}],"con":true,"img":false}]}
{"op":"mcm","clk":"11540485592","pt":1719495061910,"mc":[{"id":"1.230178307","rc":[{"atl":[[5.5,13.94],[6,0]],"id":47095746},{"atl":[[4.6,0],[4.4,8.62]],"id":53987475}],"con":true,"img":false}]}
{"op":"mcm","clk":"11540485603","pt":1719495062014,"mc":[{"id":"1.230178307","rc":[{"atb":[[1.45,0],[1.54,2.5],[1.49,0],[1.53,0]],"id":53893973},{"atl":[[3.2,0],[3.15,14.13]],"id":53893973},{"atl":[[5.6,0]],"id":47095746}],"con":true,"img":false}]}
{"op":"mcm","clk":"11540485616","pt":1719495062117,"mc":[{"id":"1.230178307","rc":[{"atb":[[1.51,6.13]],"id":53893973},{"atl":[[6.4,21.02],[5.5,1]],"id":47095746},{"atb":[[2.32,0],[2.38,15.47]],"id":61496663},{"atl":[[4.5,13.93],[4.4,0]],"id":53987475}],"con":true,"img":false}]}
{"op":"mcm","clk":"11540485630","pt":1719495062323,"mc":[{"id":"1.230178307","rc":[{"atb":[[1.51,0]],"id":53893973},{"atl":[[5.6,1],[5.5,0]],"id":47095746},{"atb":[[2.48,2.11]],"id":61496663}],"con":true,"img":false}]}
{"op":"mcm","clk":"11540485658","pt":1719495062632,"mc":[{"id":"1.230178307","rc":[{"atl":[[6.8,18.43],[6.6,1]],"id":47801105}],"con":true,"img":false}]}
{"op":"mcm","clk":"11540485667","pt":1719495062734,"mc":[{"id":"1.230178307","rc":[{"atb":[[2.46,0]],"id":47801105},{"atl":[[6.4,1],[6.2,1]],"id":47801105},{"atl":[[3.2,1],[3.15,13.13],[3.3,1]],"id":53893973},{"atl":[[5.6,0],[5.1,1],[5.5,1],[5.2,1]],"id":47095746},{"atl":[[5.6,1],[5.1,5.92],[5.5,1],[5.2,3.5]],"id":66596720},{"atb":[[2.68,0]],"id":53987475},{"atl":[[4.5,12.93],[4.6,1]],"id":53987475}],"con":true,"img":false}]}
{"op":"mcm","clk":"11540485680","pt":1719495062841,"mc":[{"id":"1.230178307","rc":[{"atb":[[3.15,11.36]],"id":47801105},{"atl":[[6.4,13.3],[5.3,7.06],[6.8,6.13],[6.6,0]],"id":47801105},{"atl":[[4.6,10.92]],"id":47095746},{"atl":[[4,13.32]],"id":61496663},{"atl":[[4.2,13.21]],"id":66596720},{"atb":[[2.72,2],[2.7,28.77]],"id":53987475},{"atl":[[4.2,13.1]],"id":53987475}],"con":true,"img":false}]}
{"op":"mcm","clk":"11540485702","pt":1719495063044,"mc":[{"id":"1.230178307","rc":[{"atl":[[5.1,2.5],[3.95,13.33]],"id":61496663},{"atl":[[4.8,26.32],[5,0]],"id":66596720}],"con":true,"img":false}]}
{"op":"mcm","clk":"11540485715","pt":1719495063110,"mc":[{"id":"1.230178307","rc":[{"atl":[[3.2,0],[3.3,0]],"id":53893973},{"atl":[[3.9,17.3]],"id":61496663},{"atl":[[4.5,13.93]],"id":53987475}],"con":true,"img":false}]}
{"op":"mcm","clk":"11540485718","pt":1719495063200,"mc":[{"id":"1.230178307","rc":[{"atl":[[6.4,12.3]],"id":47801105},{"atl":[[5.5,0],[5.2,2.5]],"id":66596720}],"con":true,"img":false}]}
{"op":"mcm","clk":"11540485730","pt":1719495063310,"mc":[{"id":"1.230178307","rc":[{"atl":[[5.5,0],[5.2,0]],"id":47095746},{"atl":[[4,9.91]],"id":61496663},{"atb":[[2.7,25.94]],"id":53987475},{"atl":[[4.6,0]],"id":53987475}],"con":true,"img":false}]}
{"op":"mcm","clk":"11540485757","pt":1719495063513,"mc":[{"id":"1.230178307","rc":[{"atb":[[3.15,22.29]],"id":47801105}],"con":true,"img":false}]}
{"op":"mcm","clk":"11540485773","pt":1719495063619,"mc":[{"id":"1.230178307","rc":[{"atl":[[3.85,0.84]],"id":61496663},{"atb":[[2.7,13.91]],"id":53987475}],"con":true,"img":false}]}
{"op":"mcm","clk":"11540485784","pt":1719495063721,"mc":[{"id":"1.230178307","rc":[{"atl":[[2.7,0]],"id":53893973},{"atl":[[4,9.06]],"id":61496663},{"atb":[[2.72,14.03]],"id":53987475},{"atl":[[4.8,6.76]],"id":53987475}],"con":true,"img":false}]}
{"op":"mcm","clk":"11540485798","pt":1719495063823,"mc":[{"id":"1.230178307","rc":[{"atl":[[3.45,19.9]],"id":53893973},{"atl":[[4.8,0]],"id":53987475}],"con":true,"img":false}]}
{"op":"mcm","clk":"11540485810","pt":1719495063927,"mc":[{"id":"1.230178307","rc":[{"atl":[[3.15,0],[3.3,1]],"id":53893973}],"con":true,"img":false}]}
{"op":"mcm","clk":"11540485942","pt":1719495065226,"mc":[{"id":"1.230178307","rc":[{"atb":[[3.2,11.79]],"id":47801105}],"con":true,"img":false}]}
{"op":"mcm","clk":"11540485960","pt":1719495065433,"mc":[{"id":"1.230178307","rc":[{"atb":[[3.1,0]],"id":47801105}],"con":true,"img":false}]}
{"op":"mcm","clk":"11540486010","pt":1719495065907,"mc":[{"id":"1.230178307","rc":[{"atb":[[3.15,9.36]],"id":47801105}],"con":true,"img":false}]}
{"op":"mcm","clk":"11540486020","pt":1719495066013,"mc":[{"id":"1.230178307","rc":[{"atb":[[3.25,2]],"id":47801105}],"con":true,"img":false}]}
{"op":"mcm","clk":"11540486085","pt":1719495066725,"mc":[{"id":"1.230178307","rc":[{"atb":[[3.25,12.76]],"id":47801105},{"atl":[[2.7,3.18]],"id":53893973}],"con":true,"img":false}]}
{"op":"mcm","clk":"11540486120","pt":1719495067043,"mc":[{"id":"1.230178307","rc":[{"atb":[[3.15,6.36]],"id":47801105},{"atb":[[2.72,0]],"id":66596720},{"atb":[[2.7,11.74]],"id":53987475},{"atl":[[4.5,12.93],[4.6,1]],"id":53987475}],"con":true,"img":false}]}
{"op":"mcm","clk":"11540486134","pt":1719495067139,"mc":[{"id":"1.230178307","rc":[{"atb":[[2.82,3.54]],"id":66596720},{"atb":[[2.74,3.6]],"id":53987475}],"con":true,"img":false}]}
{"op":"mcm","clk":"11540486143","pt":1719495067243,"mc":[{"id":"1.230178307","rc":[{"atl":[[5.1,22.84],[6.4,2.5]],"id":47095746},{"atb":[[1.02,3.7]],"id":61496663},{"atl":[[1000,1.7]],"id":61496663},{"atl":[[4.3,26.2]],"id":53987475}],"con":true,"img":false}]}
{"op":"mcm","clk":"11540486153","pt":1719495067344,"mc":[{"id":"1.230178307","rc":[{"atl":[[4.5,0]],"id":53987475}],"con":true,"img":false}]}
{"op":"mcm","clk":"11540486163","pt":1719495067447,"mc":[{"id":"1.230178307","rc":[{"atl":[[3.25,1],[3.3,0]],"id":53893973},{"atl":[[5.1,21.84],[5,1]],"id":47095746},{"atb":[[1.02,2.17]],"id":61496663},{"atl":[[4.9,1],[4.7,0],[1000,0.09]],"id":61496663}],"con":true,"img":false}]}
{"op":"mcm","clk":"11540486180","pt":1719495067614,"mc":[{"id":"1.230178307","rc":[{"atb":[[3.15,0]],"id":47801105},{"atb":[[1.02,2]],"id":61496663},{"atl":[[4,0],[1000,0]],"id":61496663},{"atb":[[2.68,3.46],[2.7,4.86]],"id":53987475}],"con":true,"img":false}]}
{"op":"mcm","clk":"11540486189","pt":1719495067724,"mc":[{"id":"1.230178307","rc":[{"atl":[[3.3,1]],"id":53893973},{"atl":[[5,0]],"id":47095746},{"atb":[[2.52,0.17]],"id":61496663},{"atl":[[3.85,0.93]],"id":61496663},{"atb":[[2.72,2]],"id":53987475}],"con":true,"img":false}]}
{"op":"mcm","clk":"11540486199","pt":1719495067819,"mc":[{"id":"1.230178307","rc":[{"atb":[[3.25,18.47]],"id":47801105},{"atl":[[3.25,0]],"id":53893973},{"atl":[[5.1,22.84]],"id":47095746},{"atl":[[3.9,26.1]],"id":61496663},{"atb":[[2.72,8.68],[2.68,0]],"id":53987475}],"con":true,"img":false}]}
{"op":"mcm","clk":"11540486211","pt":1719495067926,"mc":[{"id":"1.230178307","rc":[{"atl":[[6.4,0],[5.3,14.12]],"id":47801105}],"con":true,"img":false}]}
{"op":"mcm","clk":"11540486222","pt":1719495068034,"mc":[{"id":"1.230178307","rc":[{"atl":[[3.25,1],[3.3,0]],"id":53893973},{"atl":[[4.6,1],[4.9,0]],"id":61496663}],"con":true,"img":false}]}
{"op":"mcm","clk":"11540486235","pt":1719495068124,"mc":[{"id":"1.230178307","rc":[{"atb":[[2.74,15.31]],"id":53987475}],"con":true,"img":false}]}
{"op":"mcm","clk":"11540486243","pt":1719495068237,"mc":[{"id":"1.230178307","rc":[{"atl":[[3.85,14.26],[3.95,0]],"id":61496663}],"con":true,"img":false}]}
{"op":"mcm","clk":"11540486299","pt":1719495068950,"mc":[{"id":"1.230178307","rc":[{"atb":[[2.36,3.79]],"id":61496663}],"con":true,"img":false}]}
{"op":"mcm","clk":"11540486309","pt":1719495069012,"mc":[{"id":"1.230178307","rc":[{"atb":[[2.36,0]],"id":61496663},{"atb":[[2.72,6.68]],"id":53987475}],"con":true,"img":false}]}
{"op":"mcm","clk":"11540486320","pt":1719495069120,"mc":[{"id":"1.230178307","rc":[{"atb":[[2.76,2]],"id":53987475}],"con":true,"img":false}]}
{"op":"mcm","clk":"11540486360","pt":1719495069736,"mc":[{"id":"1.230178307","rc":[{"atb":[[2.74,3.6]],"id":53987475}],"con":true,"img":false}]}
{"op":"mcm","clk":"11540486381","pt":1719495069942,"mc":[{"id":"1.230178307","rc":[{"atb":[[2.74,0],[2.68,5],[2.76,2.5]],"id":47801105}],"con":true,"img":false}]}
{"op":"mcm","clk":"11540486390","pt":1719495070039,"mc":[{"id":"1.230178307","rc":[{"atb":[[2.8,16.09]],"id":66596720}],"con":true,"img":false}]}
{"op":"mcm","clk":"11540486446","pt":1719495070552,"mc":[{"id":"1.230178307","rc":[{"atb":[[2.76,9.72]],"id":53987475}],"con":true,"img":false}]}
{"op":"mcm","clk":"11540486459","pt":1719495070619,"mc":[{"id":"1.230178307","rc":[{"atb":[[2.7,0]],"id":53987475}],"con":true,"img":false}]}
{"op":"mcm","clk":"11540486469","pt":1719495070722,"mc":[{"id":"1.230178307","rc":[{"atb":[[2.76,22.78]],"id":53987475}],"con":true,"img":false}]}
{"op":"mcm","clk":"11540486499","pt":1719495071131,"mc":[{"id":"1.230178307","rc":[{"atl":[[6.2,0],[6,1]],"id":47801105},{"atl":[[5.1,21.84],[5,1]],"id":47095746},{"atl":[[4.6,0]],"id":61496663}],"con":true,"img":false}]}
{"op":"mcm","clk":"11540486508","pt":1719495071234,"mc":[{"id":"1.230178307","rc":[{"atl":[[3.25,0],[3.3,1]],"id":53893973},{"atl":[[4.6,0],[4.7,1]],"id":53987475}],"con":true,"img":false}]}
{"op":"mcm","clk":"11540486539","pt":1719495071750,"mc":[{"id":"1.230178307","rc":[{"atl":[[5.5,1],[6,0]],"id":47801105},{"atl":[[5.1,22.84],[5,0]],"id":47095746},{"atb":[[2.74,0]],"id":53987475}],"con":true,"img":false}]}
{"op":"mcm","clk":"11540486550","pt":1719495071856,"mc":[{"id":"1.230178307","rc":[{"atb":[[3.3,3]],"id":47801105},{"atb":[[2.78,2.8]],"id":53987475}],"con":true,"img":false}]}
{"op":"mcm","clk":"11540486588","pt":1719495072225,"mc":[{"id":"1.230178307","rc":[{"atl":[[3.85,23.16]],"id":61496663}],"con":true,"img":false}]}
{"op":"mcm","clk":"11540486598","pt":1719495072330,"mc":[{"id":"1.230178307","rc":[{"atb":[[3.25,16.54]],"id":47801105},{"atl":[[6.8,2.5]],"id":47801105},{"atb":[[2.76,22.12]],"id":53987475}],"con":true,"img":false}]}
{"op":"mcm","clk":"11540486605","pt":1719495072429,"mc":[{"id":"1.230178307","rc":[{"atl":[[3.9,8.8]],"id":61496663},{"atl":[[4.1,13.1]],"id":53987475}],"con":true,"img":false}]}
{"op":"mcm","clk":"11540486612","pt":1719495072525,"mc":[{"id":"1.230178307","rc":[{"atb":[[3.25,5.71]],"id":47801105},{"atl":[[5.1,26.89],[3.85,9.83],[3.9,0]],"id":61496663},{"atb":[[2.72,0],[2.76,9.72]],"id":53987475},{"atl":[[4,19.65],[4.3,0]],"id":53987475}],"con":true,"img":false}]}
{"op":"mcm","clk":"11540486624","pt":1719495072733,"mc":[{"id":"1.230178307","rc":[{"atl":[[5.1,2.5],[8.6,13.16],[5,1]],"id":61496663},{"atl":[[4.2,9.64]],"id":53987475}],"con":true,"img":false}]}
{"op":"mcm","clk":"11540486631","pt":1719495072838,"mc":[{"id":"1.230178307","rc":[{"atb":[[3.35,2],[3.3,11.83]],"id":47801105},{"atl":[[3.85,18.5]],"id":61496663},{"atb":[[2.78,15.2],[2.76,16.01]],"id":53987475}],"con":true,"img":false}]}
{"op":"mcm","clk":"11540486647","pt":1719495073046,"mc":[{"id":"1.230178307","rc":[{"atl":[[5.6,1],[6.2,1],[5.5,0]],"id":47801105},{"atl":[[3.25,1],[3.3,0]],"id":53893973},{"atl":[[5.1,21.84],[5,1]],"id":47095746},{"atl":[[4.5,1],[4.7,0]],"id":53987475}],"con":true,"img":false}]}
{"op":"mcm","clk":"11540486656","pt":1719495073151,"mc":[{"id":"1.230178307","rc":[{"atl":[[3.95,0.84],[4.2,8.79]],"id":53987475}],"con":true,"img":false}]}
{"op":"mcm","clk":"11540486664","pt":1719495073255,"mc":[{"id":"1.230178307","rc":[{"atb":[[2.76,14.01]],"id":53987475}],"con":true,"img":false}]}
{"op":"mcm","clk":"11540486671","pt":1719495073358,"mc":[{"id":"1.230178307","rc":[{"atl":[[5.6,0]],"id":47801105},{"atb":[[2.8,2]],"id":53987475}],"con":true,"img":false}]}
{"op":"mcm","clk":"11540486704","pt":1719495073724,"mc":[{"id":"1.230178307","rc":[{"atb":[[3.3,3]],"id":47801105},{"atb":[[2.78,2.8]],"id":53987475},{"atl":[[4.2,1.16]],"id":53987475}],"con":true,"img":false}]}
{"op":"mcm","clk":"11540486769","pt":1719495074243,"mc":[{"id":"1.230178307","rc":[{"atb":[[3.35,6.12]],"id":47801105}],"con":true,"img":false}]}
{"op":"mcm","clk":"11540486784","pt":1719495074347,"mc":[{"id":"1.230178307","rc":[{"atb":[[3.2,0]],"id":47801105}],"con":true,"img":false}]}
{"op":"mcm","clk":"11540486797","pt":1719495074448,"mc":[{"id":"1.230178307","rc":[{"atb":[[3.35,15.15]],"id":47801105},{"atl":[[3.25,0],[3.3,1]],"id":53893973},{"atl":[[5.1,22.84],[5,0]],"id":47095746},{"atb":[[2.8,15.57]],"id":53987475},{"atl":[[3.95,8.35]],"id":53987475}],"con":true,"img":false}]}
{"op":"mcm","clk":"11540486816","pt":1719495074649,"mc":[{"id":"1.230178307","rc":[{"atl":[[6.2,0],[5.9,1]],"id":47801105}],"con":true,"img":false}]}
{"op":"mcm","clk":"11540486916","pt":1719495075738,"mc":[{"id":"1.230178307","rc":[{"atb":[[2.48,5.7]],"id":61496663}],"con":true,"img":false}]}
{"op":"mcm","clk":"11540486965","pt":1719495076558,"mc":[{"id":"1.230178307","rc":[{"atb":[[3.3,0]],"id":47801105},{"atb":[[2.78,0]],"id":53987475}],"con":true,"img":false}]}
{"op":"mcm","clk":"11540486972","pt":1719495076660,"mc":[{"id":"1.230178307","rc":[{"atb":[[3.4,2.76]],"id":47801105}],"con":true,"img":false}]}
{"op":"mcm","clk":"11540487022","pt":1719495077135,"mc":[{"id":"1.230178307","rc":[{"atb":[[3.35,6.12]],"id":47801105},{"atl":[[5.4,22.73]],"id":47801105},{"atb":[[2.82,0],[2.74,19.62]],"id":47095746},{"atl":[[4.1,0],[4.2,27.36]],"id":53987475}],"con":true,"img":false}]}
{"op":"mcm","clk":"11540487031","pt":1719495077248,"mc":[{"id":"1.230178307","rc":[{"atl":[[5.3,7.06]],"id":47801105}],"con":true,"img":false}]}
{"op":"mcm","clk":"11540487061","pt":1719495077548,"mc":[{"id":"1.230178307","rc":[{"atb":[[3.25,0]],"id":47801105},{"atb":[[2.76,7.72]],"id":53987475},{"atl":[[4.2,26.2]],"id":53987475}],"con":true,"img":false}]}
{"op":"mcm","clk":"11540487070","pt":1719495077649,"mc":[{"id":"1.230178307","rc":[{"atb":[[3.35,11.24]],"id":47801105},{"atb":[[2.8,21.5]],"id":53987475}],"con":true,"img":false}]}
{"op":"mcm","clk":"11540487078","pt":1719495077759,"mc":[{"id":"1.230178307","rc":[{"atb":[[3.4,13.02]],"id":47801105},{"atl":[[5.3,11.76]],"id":47801105},{"atb":[[2.74,3.62]],"id":53987475}],"con":true,"img":false}]}
{"op":"mcm","clk":"11540487087","pt":1719495077858,"mc":[{"id":"1.230178307","rc":[{"atb":[[2.48,2.11]],"id":61496663},{"atl":[[8.6,0],[3.8,2.5]],"id":61496663},{"atb":[[2.74,0]],"id":53987475}],"con":true,"img":false}]}
{"op":"mcm","clk":"11540487102","pt":1719495078056,"mc":[{"id":"1.230178307","rc":[{"atl":[[5.8,1],[6.2,1],[5.9,0]],"id":47801105},{"atb":[[1.53,5.33]],"id":53893973},{"atl":[[3.25,1],[3.3,0]],"id":53893973},{"atl":[[5.1,21.84],[5,1]],"id":47095746}],"con":true,"img":false}]}
{"op":"mcm","clk":"11540487137","pt":1719495078532,"mc":[{"id":"1.230178307","rc":[{"atl":[[3.75,0.84]],"id":61496663}],"con":true,"img":false}]}
{"op":"mcm","clk":"11540487153","pt":1719495078748,"mc":[{"id":"1.230178307","rc":[{"atb":[[3.35,9.24]],"id":47801105}],"con":true,"img":false}]}
{"op":"mcm","clk":"11540487162","pt":1719495078870,"mc":[{"id":"1.230178307","rc":[{"atb":[[1.02,2]],"id":47801105}],"con":true,"img":false}]}
{"op":"mcm","clk":"11540487199","pt":1719495079447,"mc":[{"id":"1.230178307","rc":[{"atb":[[2.82,21.01]],"id":53987475}],"con":true,"img":false}]}
{"op":"mcm","clk":"11540487205","pt":1719495079565,"mc":[{"id":"1.230178307","rc":[{"atb":[[2.76,0]],"id":53987475}],"con":true,"img":false}]}
{"op":"mcm","clk":"11540487253","pt":1719495080235,"mc":[{"id":"1.230178307","rc":[{"atb":[[3,22.27]],"id":47801105},{"atl":[[5.1,0],[5,22.84]],"id":47095746},{"atl":[[4.8,0],[4.7,26.42]],"id":66596720}],"con":true,"img":false}]}
{"op":"mcm","clk":"11540487260","pt":1719495080340,"mc":[{"id":"1.230178307","rc":[{"atb":[[2.62,0]],"id":47801105},{"atl":[[5.8,0]],"id":47801105}],"con":true,"img":false}]}
{"op":"mcm","clk":"11540487311","pt":1719495080956,"mc":[{"id":"1.230178307","rc":[{"atl":[[5.1,0],[5,3.5]],"id":61496663}],"con":true,"img":false}]}
{"op":"mcm","clk":"11540487333","pt":1719495081164,"mc":[{"id":"1.230178307","rc":[{"atb":[[3.05,6.35]],"id":47095746},{"atl":[[3.8,5.96]],"id":61496663}],"con":true,"img":false}]}
{"op":"mcm","clk":"11540487356","pt":1719495081364,"mc":[{"id":"1.230178307","rc":[{"atb":[[1.02,0]],"id":47801105},{"atl":[[3.85,9.6]],"id":61496663},{"atb":[[2.82,16.28]],"id":66596720}],"con":true,"img":false}]}
{"op":"mcm","clk":"11540487368","pt":1719495081467,"mc":[{"id":"1.230178307","rc":[{"atb":[[3.45,2]],"id":47801105},{"atl":[[3.85,16.41],[3.8,3.46]],"id":61496663},{"atl":[[3.9,21.83]],"id":53987475}],"con":true,"img":false}]}
{"op":"mcm","clk":"11540487380","pt":1719495081633,"mc":[{"id":"1.230178307","rc":[{"atb":[[2.8,12.96]],"id":66596720}],"con":true,"img":false}]}
{"op":"mcm","clk":"11540487386","pt":1719495081734,"mc":[{"id":"1.230178307","rc":[{"atl":[[4,0]],"id":53987475}],"con":true,"img":false}]}
{"op":"mcm","clk":"11540487401","pt":1719495081946,"mc":[{"id":"1.230178307","rc":[{"atb":[[2.8,19.5]],"id":53987475}],"con":true,"img":false}]}
{"op":"mcm","clk":"11540487411","pt":1719495082045,"mc":[{"id":"1.230178307","rc":[{"atb":[[3.4,12.87]],"id":47801105},{"atb":[[2.84,2]],"id":53987475}],"con":true,"img":false}]}
{"op":"mcm","clk":"11540487420","pt":1719495082156,"mc":[{"id":"1.230178307","rc":[{"atb":[[2.92,0],[3,0],[2.84,0],[2.08,1]],"id":47095746},{"atl":[[5,1],[4.9,21.84]],"id":47095746},{"atb":[[2.3,11.86]],"id":61496663},{"atl":[[4.5,0],[4.3,30.3],[3.85,0.84],[4.6,1],[4.2,0]],"id":53987475}],"con":true,"img":false}]}
{"op":"mcm","clk":"11540487427","pt":1719495082258,"mc":[{"id":"1.230178307","rc":[{"atb":[[3.35,4.12],[3.4,2.76]],"id":47801105},{"atb":[[2.38,0]],"id":61496663},{"atl":[[3.85,7.74]],"id":61496663},{"atb":[[2.8,13.57]],"id":53987475}],"con":true,"img":false}]}
{"op":"mcm","clk":"11540487434","pt":1719495082361,"mc":[{"id":"1.230178307","rc":[{"atb":[[3.45,12.11],[3.4,7.61]],"id":47801105},{"atb":[[2.74,0],[2.42,2.5],[2.26,10],[3.05,0],[2.08,26.97],[2.34,5]],"id":47095746},{"atl":[[3.8,11.98]],"id":61496663},{"atb":[[2.82,26.76]],"id":53987475}],"con":true,"img":false}]}
{"op":"mcm","clk":"11540487447","pt":1719495082470,"mc":[{"id":"1.230178307","rc":[{"atb":[[3,2.62],[2.44,5],[2.08,1]],"id":47095746},{"atb":[[2.24,0],[2.42,5]],"id":53987475}],"con":true,"img":false}]}
{"op":"mcm","clk":"11540487457","pt":1719495082672,"mc":[{"id":"1.230178307","rc":[{"atb":[[2.9,19.72],[3,0]],"id":47801105},{"atl":[[4.8,21.84]],"id":47095746}],"con":true,"img":false}]}
{"op":"mcm","clk":"11540487475","pt":1719495082870,"mc":[{"id":"1.230178307","rc":[{"atl":[[4.9,0]],"id":47095746}],"con":true,"img":false}]}
{"op":"mcm","clk":"11540487483","pt":1719495082930,"mc":[{"id":"1.230178307","rc":[{"atl":[[6.2,0],[6,1]],"id":47801105},{"atl":[[3.25,0],[3.3,1]],"id":53893973},{"atl":[[5.1,1],[5,0]],"id":47095746},{"atb":[[2.8,12.54]],"id":53987475}],"con":true,"img":false}]}
{"op":"mcm","clk":"11540487495","pt":1719495083033,"mc":[{"id":"1.230178307","rc":[{"atb":[[3.5,14.53]],"id":47801105}],"con":true,"img":false}]}
{"op":"mcm","clk":"11540487500","pt":1719495083134,"mc":[{"id":"1.230178307","rc":[{"atl":[[4.6,17.2]],"id":47095746}],"con":true,"img":false}]}
{"op":"mcm","clk":"11540487508","pt":1719495083243,"mc":[{"id":"1.230178307","rc":[{"atb":[[3.35,0]],"id":47801105},{"atl":[[5.8,1],[6,0],[5.7,1]],"id":47801105},{"atl":[[3.25,1],[3.3,0]],"id":53893973},{"atb":[[2.08,0],[2.24,1]],"id":47095746},{"atl":[[5.1,0],[5.5,1],[5.4,1]],"id":47095746},{"atb":[[2.8,0]],"id":53987475}],"con":true,"img":false}]}
{"op":"mcm","clk":"11540487516","pt":1719495083346,"mc":[{"id":"1.230178307","rc":[{"atb":[[2.84,14.54]],"id":53987475}],"con":true,"img":false}]}
{"op":"mcm","clk":"11540487550","pt":1719495083893,"mc":[{"id":"1.230178307","rc":[{"atl":[[5.7,0]],"id":47801105},{"atl":[[3.25,0],[3.3,1]],"id":53893973},{"atl":[[5.4,0]],"id":47095746},{"atl":[[4.5,1],[5,2.5]],"id":61496663}],"con":true,"img":false}]}
{"op":"mcm","clk":"11540487558","pt":1719495083966,"mc":[{"id":"1.230178307","rc":[{"atb":[[3.45,11]],"id":47801105}],"con":true,"img":false}]}
{"op":"mcm","clk":"11540487576","pt":1719495084165,"mc":[{"id":"1.230178307","rc":[{"atb":[[3.45,2]],"id":47801105}],"con":true,"img":false}]}
{"op":"mcm","clk":"11540487587","pt":1719495084228,"mc":[{"id":"1.230178307","rc":[{"atb":[[3.5,23.53]],"id":47801105}],"con":true,"img":false}]}
{"op":"mcm","clk":"11540487621","pt":1719495084536,"mc":[{"id":"1.230178307","rc":[{"atb":[[2.9,0],[2.96,15.22]],"id":47801105},{"atb":[[2.3,0],[2.14,7.5]],"id":61496663},{"atl":[[5,25],[4.7,0]],"id":66596720}],"con":true,"img":false}]}
{"op":"mcm","clk":"11540487630","pt":1719495084643,"mc":[{"id":"1.230178307","rc":[{"atb":[[3.45,0]],"id":47801105}],"con":true,"img":false}]}
{"op":"mcm","clk":"11540487640","pt":1719495084745,"mc":[{"id":"1.230178307","rc":[{"atb":[[3.55,2]],"id":47801105}],"con":true,"img":false}]}
{"op":"mcm","clk":"11540487709","pt":1719495085569,"mc":[{"id":"1.230178307","rc":[{"atb":[[3.5,23.45]],"id":47801105},{"atb":[[2.8,16.09]],"id":66596720}],"con":true,"img":false}]}
{"op":"mcm","clk":"11540487726","pt":1719495085766,"mc":[{"id":"1.230178307","rc":[{"atb":[[1.48,0],[2.4,2.11]],"id":47095746}],"con":true,"img":false}]}
{"op":"mcm","clk":"11540487740","pt":1719495085869,"mc":[{"id":"1.230178307","rc":[{"atb":[[3.5,14.53]],"id":47801105}],"con":true,"img":false}]}
{"op":"mcm","clk":"11540487749","pt":1719495085973,"mc":[{"id":"1.230178307","rc":[{"atb":[[3.4,4.85],[3.55,10.92]],"id":47801105},{"atb":[[2.82,12.74]],"id":66596720}],"con":true,"img":false}]}
{"op":"mcm","clk":"11540487770","pt":1719495086180,"mc":[{"id":"1.230178307","rc":[{"atb":[[3.55,14.43]],"id":47801105},{"atb":[[2.52,2.6]],"id":47095746},{"atb":[[2.84,2.93]],"id":66596720}],"con":true,"img":false}]}
{"op":"mcm","clk":"11540487811","pt":1719495086561,"mc":[{"id":"1.230178307","rc":[{"atl":[[4.8,0],[4.9,25.64]],"id":47095746}],"con":true,"img":false}]}
{"op":"mcm","clk":"11540487821","pt":1719495086652,"mc":[{"id":"1.230178307","rc":[{"atl":[[3.85,0.93],[3.75,8.59]],"id":61496663}],"con":true,"img":false}]}
{"op":"mcm","clk":"11540487840","pt":1719495086965,"mc":[{"id":"1.230178307","rc":[{"atb":[[2.66,3.09]],"id":47095746}],"con":true,"img":false}]}
{"op":"mcm","clk":"11540487857","pt":1719495087067,"mc":[{"id":"1.230178307","rc":[{"atb":[[3.4,0]],"id":47801105},{"atb":[[2.82,11.65]],"id":66596720},{"atb":[[2.82,21.01]],"id":53987475}],"con":true,"img":false}]}
{"op":"mcm","clk":"11540487863","pt":1719495087171,"mc":[{"id":"1.230178307","rc":[{"atl":[[6.2,1],[5.5,22.22],[5.4,0]],"id":47801105},{"atl":[[3.3,0]],"id":53893973},{"atl":[[3.85,0.09]],"id":61496663}],"con":true,"img":false}]}
{"op":"mcm","clk":"11540487884","pt":1719495087281,"mc":[{"id":"1.230178307","rc":[{"atb":[[3.55,18.51]],"id":47801105},{"atl":[[5.8,0],[6,1]],"id":47801105},{"atb":[[1.19,21.06]],"id":53893973},{"atl":[[3.25,1],[2.68,12.93]],"id":53893973},{"atb":[[2.26,19.69],[2.24,0]],"id":47095746},{"atl":[[5.5,0],[5.4,1]],"id":47095746},{"atl":[[4.5,0]],"id":61496663},{"atb":[[2.82,0]],"id":66596720},{"atb":[[2.84,20.11]],"id":53987475}],"con":true,"img":false}]}
{"op":"mcm","clk":"11540487899","pt":1719495087345,"mc":[{"id":"1.230178307","rc":[{"atl":[[3.45,0],[2.66,3.18]],"id":53893973},{"atb":[[2.84,14.58]],"id":66596720}],"con":true,"img":false}]}
{"op":"mcm","clk":"11540487912","pt":1719495087447,"mc":[{"id":"1.230178307","rc":[{"atb":[[1.53,0]],"id":53893973},{"atl":[[2.66,7.44]],"id":53893973},{"atb":[[2.8,12.96]],"id":66596720}],"con":true,"img":false}]}
{"op":"mcm","clk":"11540487937","pt":1719495087656,"mc":[{"id":"1.230178307","rc":[{"atl":[[2.68,7.02],[2.7,0]],"id":53893973},{"atb":[[2.54,5.71],[2.44,0]],"id":47095746}],"con":true,"img":false}]}
{"op":"mcm","clk":"11540487982","pt":1719495088177,"mc":[{"id":"1.230178307","rc":[{"atl":[[2.64,0.84]],"id":53893973},{"atb":[[2.86,21.36]],"id":53987475}],"con":true,"img":false}]}
{"op":"mcm","clk":"11540488001","pt":1719495088334,"mc":[{"id":"1.230178307","rc":[{"atb":[[2.82,0]],"id":53987475}],"con":true,"img":false}]}
{"op":"mcm","clk":"11540488012","pt":1719495088445,"mc":[{"id":"1.230178307","rc":[{"atl":[[6,0]],"id":47801105},{"atl":[[5.1,1],[5.4,0]],"id":47095746}],"con":true,"img":false}]}
{"op":"mcm","clk":"11540488043","pt":1719495088853,"mc":[{"id":"1.230178307","rc":[{"atb":[[2.54,41.48],[2.42,0]],"id":53987475}],"con":true,"img":false}]}
{"op":"mcm","clk":"11540488055","pt":1719495088961,"mc":[{"id":"1.230178307","rc":[{"atl":[[2.7,3.18]],"id":53893973},{"atb":[[2.66,0]],"id":47095746}],"con":true,"img":false}]}
{"op":"mcm","clk":"11540488081","pt":1719495089266,"mc":[{"id":"1.230178307","rc":[{"atb":[[2.84,18.11]],"id":53987475}],"con":true,"img":false}]}
{"op":"mcm","clk":"11540488092","pt":1719495089366,"mc":[{"id":"1.230178307","rc":[{"atb":[[2.88,2]],"id":53987475}],"con":true,"img":false}]}
{"op":"mcm","clk":"11540488103","pt":1719495089463,"mc":[{"id":"1.230178307","rc":[{"atl":[[2.7,0]],"id":53893973}],"con":true,"img":false}]}
{"op":"mcm","clk":"11540488131","pt":1719495089771,"mc":[{"id":"1.230178307","rc":[{"atb":[[2.96,0],[3.05,33.04]],"id":47801105},{"atb":[[2.84,16.38]],"id":53987475}],"con":true,"img":false}]}
{"op":"mcm","clk":"11540488140","pt":1719495089839,"mc":[{"id":"1.230178307","rc":[{"atl":[[3.75,16.63]],"id":61496663}],"con":true,"img":false}]}
{"op":"mcm","clk":"11540488151","pt":1719495089933,"mc":[{"id":"1.230178307","rc":[{"atb":[[2.84,5.57]],"id":53987475}],"con":true,"img":false}]}
{"op":"mcm","clk":"11540488156","pt":1719495090037,"mc":[{"id":"1.230178307","rc":[{"atl":[[3.8,8.52]],"id":61496663},{"atb":[[2.88,12.81]],"id":53987475}],"con":true,"img":false}]}
{"op":"mcm","clk":"11540488223","pt":1719495090956,"mc":[{"id":"1.230178307","rc":[{"atb":[[2.52,0]],"id":47095746},{"atb":[[2.5,13.3]],"id":61496663},{"atb":[[2.84,11.65]],"id":66596720}],"con":true,"img":false}]}
{"op":"mcm","clk":"11540488234","pt":1719495091072,"mc":[{"id":"1.230178307","rc":[{"atb":[[2.56,2.82]],"id":47095746},{"atb":[[2.86,3]],"id":66596720}],"con":true,"img":false}]}
{"op":"mcm","clk":"11540488262","pt":1719495091479,"mc":[{"id":"1.230178307","rc":[{"atb":[[2.84,11.13]],"id":66596720}],"con":true,"img":false}]}
{"op":"mcm","clk":"11540488279","pt":1719495091641,"mc":[{"id":"1.230178307","rc":[{"atl":[[4.5,17.2],[4.9,0]],"id":47095746},{"atb":[[2.84,0]],"id":66596720}],"con":true,"img":false}]}
{"op":"mcm","clk":"11540488284","pt":1719495091728,"mc":[{"id":"1.230178307","rc":[{"atb":[[3.55,35.51]],"id":47801105},{"atl":[[4.5,23.6]],"id":47095746},{"atb":[[2.86,14.13]],"id":66596720}],"con":true,"img":false}]}
{"op":"mcm","clk":"11540488298","pt":1719495091852,"mc":[{"id":"1.230178307","rc":[{"atb":[[3.5,0]],"id":47801105},{"atb":[[1.19,0]],"id":53893973},{"atl":[[2.68,0.85]],"id":53893973},{"atb":[[2.26,10]],"id":47095746},{"atl":[[4.6,11.58]],"id":47095746},{"atl":[[3.8,0]],"id":61496663},{"atb":[[2.84,0]],"id":53987475}],"con":true,"img":false}]}
{"op":"mcm","clk":"11540488307","pt":1719495091951,"mc":[{"id":"1.230178307","rc":[{"atb":[[1.2,21.31]],"id":53893973},{"atl":[[2.66,13.45],[2.68,9.14]],"id":53893973},{"atb":[[2.54,11.44]],"id":47095746},{"atl":[[5,19.23],[3.75,17.26]],"id":61496663},{"atb":[[2.88,18.05]],"id":53987475}],"con":true,"img":false}]}
{"op":"mcm","clk":"11540488314","pt":1719495092052,"mc":[{"id":"1.230178307","rc":[{"atb":[[3.55,26.59]],"id":47801105},{"atl":[[2.66,10.27],[2.68,0.85]],"id":53893973},{"atl":[[4.4,0.84]],"id":47095746},{"atl":[[3.7,17.27]],"id":61496663}],"con":true,"img":false}]}
{"op":"mcm","clk":"11540488325","pt":1719495092165,"mc":[{"id":"1.230178307","rc":[{"atb":[[1.53,5.33]],"id":53893973},{"atl":[[2.64,9.99]],"id":53893973},{"atl":[[5,2.5]],"id":61496663}],"con":true,"img":false}]}
{"op":"mcm","clk":"11540488359","pt":1719495092564,"mc":[{"id":"1.230178307","rc":[{"atl":[[3.65,0.84]],"id":61496663}],"con":true,"img":false}]}
